File: data/doubleLayers/dl_1-25/ppms/DD205_3_HYST_300K.DAT
[Header]
; VSM Data File (default extension .dat)
; Copyright (c) 2003, Quantum Design, Inc. All rights reserved.
TITLE,
FILEOPENTIME,15676740.55,04/17/2018,4:13 am
BYAPP,VSM,1.0,1.0
INFO,PPMS VSM Option Release 1.3.7 Build 2,APPNAME
INFO,291,COIL_SERIAL_NUMBER
INFO,0,MOMENT_UNITS
INFO,,SAMPLE_MATERIAL
INFO,,SAMPLE_COMMENT
INFO,,SAMPLE_MASS
INFO,,SAMPLE_VOLUME
INFO,,SAMPLE_MOLECULAR_WEIGHT
INFO,,SAMPLE_SIZE
INFO,,SAMPLE_SHAPE
INFO,36.06,SAMPLE_OFFSET
DATATYPE,COMMENT,1
DATATYPE,TIME,2
STARTUPAXIS,X,2
STARTUPAXIS,Y1,5
[Data]
Comment,Time Stamp (sec),Temperature (K),Magnetic Field (Oe),Moment (emu),M. Std. Err. (emu),Transport Action,Averaging Time (sec),Frequency (Hz),Peak Amplitude (mm),Center Position (mm),Coil Signal' (mV),Coil Signal" (mV),Range (mV),M. Quad. Signal (emu),M. Raw' (emu),M. Raw" (emu),Min. Temperature (K),Max. Temperature (K),Min. Field (Oe),Max. Field (Oe),Mass (grams),Motor Lag (deg),Pressure (Torr),VSM Status (code),Motor Status (code),Measure Status (code),PPMS Status (code),System Temp. (K),System Field (Oe),Sample Position (deg),Bridge 1 Resistance (ohms),Bridge 1 Excitation (에),Bridge 2 Resistance (ohms),Bridge 2 Excitation (에),Bridge 3 Resistance (ohms),Bridge 3 Excitation (에),Bridge 4 Resistance (ohms),Bridge 4 Excitation (에),Signal 1 Vin (V),Signal 2 Vin (V),Digital Inputs (code),Drive 1 Iout (mA),Drive 1 Ipower (W),Drive 2 Iout (mA),Drive 2 Ipower (W),Pressure (),Map 20 (),Map 21 (),Map 22 (),Map 23 (),Map 24 (),Map 25 (),Map 26 (),Map 27 (),Map 28 (),Map 29 ()
,15677223.805,300.10147095,89999.5078125,-0.000126594328466107,8.8620751222327E-7,1,0.999253354069792,40.0298881530762,1.99114450636905,15.6900031119585,-0.00138215950917315,-0.000155443007663215,0.25,7.69821250546355E-6,-0.000126594785988137,7.6167730240142E-6,300.1013489,300.101593,89999.4609375,89999.5546875,52.1799566868132,18.6316367545074,11.752636,0,0,0,4417,300.5559,89999.5078125,,,,,,,,,,,,,,,,,12.252253,,,,,,300.10147095,,,,
,15677253.895,300.09515385,87189.32421875,-0.000116291001726602,8.14880896108697E-7,1,0.999253354069792,40.0298881530762,1.99108217682296,15.6900031119585,-0.00126515372841616,-0.000168446213000057,0.25,4.69658052398315E-6,-0.000116289920504738,4.62181564634855E-6,300.0947266,300.0955811,87091.6484375,87287,52.2690623380055,18.6366562744684,11.63639405,0,0,0,4449,300.51485,87189.32421875,,,,,,,,,,,,,,,,,13.003003,,,,,,300.09515385,,,,
,15677271.945,300.0844421,83664.52734375,-0.000102974868876475,9.39637466557007E-7,1,0.999253354069792,40.0298881530762,1.99112103986028,15.6900031119585,-0.0011236060363162,-0.000130244523919618,0.25,5.90979123453242E-6,-0.000102975068713993,5.84349397875953E-6,300.0844421,300.0844421,83654.71875,83674.3359375,52.1799566868132,18.6336816944616,11.69539165,0,0,0,4449,300.4978,83664.52734375,,,,,,,,,,,,,,,,,12.252253,,,,,,300.0844421,,,,
,15677288.715,300.0744934,80383.28125,-9.64473254467406E-5,1.01538510706181E-6,1,0.999253354069792,40.0298881530762,1.99114198121919,15.6900031119585,-0.0010497570508108,-0.000137091098831199,0.25,4.13735173746645E-6,-9.64466448049952E-5,4.0752808813142E-6,300.0744934,300.0744934,80373.578125,80392.984375,52.3018907358132,18.6349319582181,11.9898119,0,0,0,4449,300.4945,80383.28125,,,,,,,,,,,,,,,,,12.252253,,,,,,300.0744934,,,,
,15677305.05,300.0634308,77190.3203125,-8.36229873728459E-5,1.27713305415471E-6,1,0.999253354069792,40.0298881530762,1.99108441874752,15.6900031119585,-0.000910074878617555,-0.000119285319529099,0.25,3.54780348708745E-6,-8.36224003847094E-5,3.49396663761363E-6,300.063324,300.0635376,77112.2734375,77268.3671875,52.2073136849863,18.6364933288207,11.8116336,0,0,0,4449,300.49125,77190.3203125,,,,,,,,,,,,,,,,,13.378378,,,,,,300.0634308,,,,
,15677322.02,300.05589295,73880.12890625,-7.25833959787039E-5,9.1023250191368E-7,1,0.999253354069792,40.0298881530762,1.99114877099341,15.6900031119585,-0.000788377636090019,-0.000112578899929162,0.25,2.24286875185643E-6,-7.2582365416146E-5,2.19615000262228E-6,300.0550537,300.0567322,73772.8046875,73987.453125,52.1447834034478,18.6377440462788,11.8706312,0,0,0,4449,300.49435,73880.12890625,,,,,,,,,,,,,,,,,12.252253,,,,,,300.05589295,,,,
,15677338.96,300.05030825,70569.93359375,-6.11392975930825E-5,9.85368141202711E-7,1,0.999253354069792,40.0298881530762,1.99105246312001,15.6900031119585,-0.000667001016335486,-7.78833264080581E-5,0.25,3.45745242618741E-6,-6.11394475161083E-5,3.41803064259281E-6,300.0498352,300.0507813,70452.8203125,70687.046875,51.8149361683324,18.6375130282905,11.8116336,0,0,0,4449,300.49185,70569.93359375,,,,,,,,,,,,,,,,,12.252253,,,,,,300.05030825,,,,
,15677355.38,300.0435333,67367.25,-4.99836953226421E-5,1.15734144596071E-6,1,0.999253354069792,40.0298881530762,1.99110020716483,15.6900031119585,-0.000545676597440382,-6.15790032940609E-5,0.25,3.02053779177682E-6,-4.99839529355302E-5,2.98829016085585E-6,300.0431213,300.0439453,67250.078125,67484.421875,52.0502063526209,18.6367455695594,11.63639405,0,0,0,4449,300.4886,67367.25,,,,,,,,,,,,,,,,,13.003003,,,,,,300.0435333,,,,
,15677373.055,300.038208,63910.435546875,-4.24531055843869E-5,9.36724896516078E-7,1,0.999253354069792,40.0298881530762,1.99108545702003,15.6900031119585,-0.000464219420950222,-4.79557636478288E-5,0.25,2.96770222127513E-6,-4.24535899785516E-5,2.94028808390025E-6,300.038208,300.038208,63890.95703125,63929.9140625,51.8555808513324,18.6369683615809,11.8706312,0,0,0,4449,300.4835,63910.435546875,,,,,,,,,,,,,,,,,13.378378,,,,,,300.038208,,,,
,15677389.81,300.0297546,60632.5859375,-3.09382253729832E-5,7.54319582278595E-7,1,0.999253354069792,40.0298881530762,1.99107173872039,15.6900031119585,-0.000335803654765785,-4.92765661580985E-5,0.25,8.36425543957403E-7,-3.09377328507212E-5,8.16484100277601E-7,300.0297546,300.0297546,60622.71875,60642.453125,52.0259758685247,18.6362272098705,11.5201521,0,0,0,4449,300.4828,60632.5859375,,,,,,,,,,,,,,,,,13.378378,,,,,,300.0297546,,,,
,15677406.385,300.02357485,57392.634765625,-2.17027600620251E-5,9.09805524032731E-7,1,0.999253354069792,40.0298881530762,1.99107180349083,15.6900031119585,-0.00023617189289233,-3.10707099093312E-5,0.25,9.10374191984606E-7,-2.17026268772279E-5,8.96369712613432E-7,300.0234375,300.0237122,57373.02734375,57412.2421875,52.1916811146017,18.6378321606163,11.63639405,0,0,0,4449,300.4848,57392.634765625,,,,,,,,,,,,,,,,,13.378378,,,,,,300.02357485,,,,
,15677423.01,300.0200195,54133.748046875,-1.3963908864195E-5,9.57132774396842E-7,1,0.999253354069792,40.0298881530762,1.99102234415245,15.6900031119585,-0.000151262628874089,-2.39495717098312E-5,0.25,2.19307156701917E-7,-1.39635885441608E-5,2.10305419350315E-7,300.0189819,300.0210571,54045.6875,54221.80859375,52.3628577603132,18.6392046213228,11.93022155,0,0,0,4449,300.4905,54133.748046875,,,,,,,,,,,,,,,,,13.378378,,,,,,300.0200195,,,,
,15677440.79,300.0145264,50649.623046875,-2.10489320607501E-6,7.12159333587511E-7,1,0.999253354069792,40.0298881530762,1.99111242571322,15.6900031119585,-2.33585415191681E-5,-4.20486512018205E-7,0.25,3.28319473737792E-7,-2.10503550810969E-6,3.26952317105002E-7,300.0145264,300.0145264,50639.74609375,50659.5,52.4785387811594,18.6381637592887,11.9898119,0,0,0,4449,300.4904,50649.623046875,,,,,,,,,,,,,,,,,13.003003,,,,,,300.0145264,,,,
,15677457.64,300.0100708,47350.833984375,5.81415776279438E-6,6.51990188069462E-7,1,0.999253354069792,40.0298881530762,1.99103078637906,15.6900031119585,6.35892166854959E-5,6.48898812639779E-6,0.25,-4.1372600664085E-7,5.81423383924702E-6,-4.09964551101761E-7,300.0100708,300.0100708,47331.2890625,47370.37890625,52.2964193361786,18.6397960667515,11.8116336,0,0,0,4449,300.493,47350.833984375,,,,,,,,,,,,,,,,,13.003003,,,,,,300.0100708,,,,
,15677475.79,300.0050964,43807.720703125,1.57267805131603E-5,6.06870645951623E-7,1,0.999253354069792,40.0298881530762,1.99108333526036,15.6900031119585,0.00017135760574025,2.12774752841104E-5,0.25,-7.74297861250253E-7,1.57267663206406E-5,-7.64130464828099E-7,300.0050964,300.0050964,43788.1484375,43827.29296875,52.453526668544,18.6387194293095,11.5201521,0,0,0,4449,300.483,43807.720703125,,,,,,,,,,,,,,,,,12.252253,,,,,,300.0050964,,,,
,15677491.88,300.00228885,40656.3359375,2.40933087816034E-5,6.52453736219496E-7,1,0.999253354069792,40.0298881530762,1.99114148587358,15.6900031119585,0.000261262653150014,3.98377370565485E-5,0.25,-5.16072676071874E-7,2.40928567087717E-5,-5.00514064460608E-7,300.0015259,300.0030518,40539.03515625,40773.63671875,52.3370640191786,18.6391940265826,11.69539165,0,0,0,4449,300.50295,40656.3359375,,,,,,,,,,,,,,,,,12.252253,,,,,,300.00228885,,,,
,15677509.11,300.00096135,37279.447265625,3.39232252856356E-5,7.52042830522505E-7,1,0.999253354069792,40.0298881530762,1.99108521156885,15.6900031119585,0.000369674587049849,4.56110980185887E-5,0.25,-1.69660296415435E-6,3.39232155357856E-5,-1.67465750471217E-6,300.0006104,300.0013123,37191.4765625,37367.41796875,52.3675475314286,18.639866945037,11.8706312,0,0,0,4449,300.50895,37279.447265625,,,,,,,,,,,,,,,,,13.003003,,,,,,300.00096135,,,,
,15677526.205,299.9986572,33932.412109375,4.31395838248061E-5,4.7747705906546E-7,1,0.999253354069792,40.0298881530762,1.99110285280823,15.6900031119585,0.000466275653006522,7.99962355303656E-5,0.25,-1.21778093209522E-7,4.31382599105101E-5,-9.39259412972121E-8,299.9983215,299.9989929,33805.3046875,34059.51953125,52.229980912044,18.6400088628465,11.69539165,0,0,0,4449,300.5008,33932.412109375,,,,,,,,,,,,,,,,,13.003003,,,,,,299.9986572,,,,
,15677543.55,299.9950256,30536.181640625,5.14197101273544E-5,4.63264033024378E-7,1,0.999253354069792,40.0298881530762,1.99109660122704,15.6900031119585,0.000557591215000611,8.49123325578409E-5,0.25,-1.11135450437008E-6,5.14187609927978E-5,-1.07811469192272E-6,299.9950256,299.9950256,30516.658203125,30555.705078125,52.290947936544,18.641568341057,11.5201521,0,0,0,4449,300.5105,30536.181640625,,,,,,,,,,,,,,,,,13.003003,,,,,,299.9950256,,,,
,15677560.64,299.99253845,27189.2177734375,5.98901149827397E-5,5.95154627783387E-7,1,0.999253354069792,40.0298881530762,1.99109472316443,15.6900031119585,0.000648904586454369,0.00010198627242659,0.25,-1.00875258162858E-6,5.98888286786764E-5,-9.70033031496986E-7,299.9924927,299.9925842,27071.69921875,27306.736328125,52.4089738429479,18.6417730179044,11.69539165,0,0,0,4449,300.5088,27189.2177734375,,,,,,,,,,,,,,,,,13.378378,,,,,,299.99253845,,,,
,15677577.88,299.98756405,23822.0830078125,6.70793879284927E-5,5.71772914672653E-7,1,0.999253354069792,40.0298881530762,1.99118018565742,15.6900031119585,0.000727579999872881,0.00010993079823412,0.25,-1.52811878536518E-6,6.70782141402091E-5,-1.48472495852837E-6,299.9873962,299.9877319,23802.216796875,23841.94921875,52.6012544586786,18.6405850303073,11.8706312,0,0,0,4449,300.5137,23822.0830078125,,,,,,,,,,,,,,,,,13.003003,,,,,,299.98756405,,,,
,15677593.85,299.9869385,20689.8271484375,7.51727284758902E-5,4.40849000578212E-7,1,0.999253354069792,40.0298881530762,1.99112334035726,15.6900031119585,0.000814756184226701,0.000126553686420736,0.25,-1.40123778247529E-6,7.51712124196173E-5,-1.35260584097298E-6,299.9864502,299.9874268,20572.5078125,20807.146484375,52.0595858948517,18.6412092196,11.75322245,0,0,0,4449,300.52505,20689.8271484375,,,,,,,,,,,,,,,,,12.252253,,,,,,299.9869385,,,,
,15677612.97,299.9862061,16941.546875,8.11974979846825E-5,3.62599660721623E-7,1,0.999253354069792,40.0298881530762,1.99115573262127,15.7000036537647,0.000880954647353505,0.000131621694680421,0.25,-1.98348288042691E-6,8.11961647270194E-5,-1.93092062224177E-6,299.9862061,299.9862061,16912.3046875,16970.7890625,52.0392635533517,18.6411391519005,11.8116336,0,0,0,4449,300.5292,16941.546875,,,,,,,,,,,,,,,,,12.252253,,,,,,299.9862061,,,,
,15677629.235,299.98834225,13759.4028320312,8.69448815087309E-5,4.3214996322211E-7,1,0.999253354069792,40.0298881530762,1.99118539885304,15.6900031119585,0.000943783717917652,0.000138306635758619,0.25,-2.36766314803011E-6,8.69436043175313E-5,-2.31135597783996E-6,299.9880981,299.9885864,13641.9609375,13876.8447265625,52.4511817829863,18.6415770248816,11.8706312,0,0,0,4449,300.5279,13759.4028320312,,,,,,,,,,,,,,,,,13.378378,,,,,,299.98834225,,,,
,15677646.28,299.98858645,10409.5771484375,9.01158016464653E-5,3.03962666254443E-7,1,0.999253354069792,40.0298881530762,1.99117442454638,15.6900031119585,0.000978686431288424,0.000140555359657252,0.25,-2.7127057562945E-6,9.01146433336206E-5,-2.65432058432718E-6,299.9884949,299.988678,10311.66015625,10507.494140625,52.4621245822556,18.6421433140379,11.9898119,0,0,0,4449,300.5309,10409.5771484375,,,,,,,,,,,,,,,,,13.003003,,,,,,299.98858645,,,,
,15677662.86,299.98799135,7177.166015625,9.06484143784497E-5,3.6029485573752E-7,1,0.999253354069792,40.0298881530762,1.99120749313711,15.6900031119585,0.000984161365608802,0.000143250109315557,0.25,-2.55642528594027E-6,9.06471382817621E-5,-2.49768421682231E-6,299.9875183,299.9884644,7039.93017578125,7314.40185546875,52.4019391862748,18.6420558070088,11.63639405,0,0,0,4449,300.52585,7177.166015625,,,,,,,,,,,,,,,,,12.252253,,,,,,299.98799135,,,,
,15677680.46,299.990448,3718.11474609375,8.32009034230841E-5,3.82954498790009E-7,1,0.999253354069792,40.0298881530762,1.99120677670423,15.6900031119585,0.000902689466565954,0.000135003375886345,0.25,-2.02036150543186E-6,8.31995137415582E-5,-1.9664454118308E-6,299.990448,299.990448,3688.71704101562,3747.51245117188,52.3644210173517,18.6434003968527,11.9898119,0,0,0,4449,300.5359,3718.11474609375,,,,,,,,,,,,,,,,,12.252253,,,,,,299.990448,,,,
,15677697,299.99142455,471.708694458008,4.81426436290409E-5,4.06120193059117E-7,1,0.999253354069792,40.0298881530762,1.99122850535556,15.6900031119585,0.000524846986619313,6.36900618183741E-5,0.25,-2.50449158064094E-6,4.81427020633369E-5,-2.47324475558152E-6,299.9909973,299.9918518,373.722686767578,569.694702148438,52.6270481998133,18.6438157363648,11.8706312,0,0,0,4449,300.53675,471.708694458008,,,,,,,,,,,,,,,,,12.252253,,,,,,299.99142455,,,,
,15677712.82,299.9944763,-2605.30822753906,-7.42961549229121E-5,4.30900237675908E-7,1,0.999253354069792,40.0298881530762,1.99127062333899,15.6900031119585,-0.000800036363863501,-0.000155320676976463,0.25,-1.41342315995076E-6,-7.42928213488879E-5,-1.46146835572052E-6,299.9944458,299.9945068,-2722.12524414062,-2488.4912109375,52.4808836667171,18.644339019859,11.69539165,0,0,0,4449,300.5328,-2605.30822753906,,,,,,,,,,,,,,,,,13.003003,,,,,,299.9944763,,,,
,15677729.65,299.9942627,-5912.80200195313,-8.83330198332495E-5,4.09883733577097E-7,1,0.999253354069792,40.0298881530762,1.99122690719673,15.6900031119585,-0.000951756157705315,-0.000181293935967134,0.25,-1.36874842347588E-6,-8.83292602819366E-5,-1.42586852071492E-6,299.9942627,299.9942627,-6000.98974609375,-5824.6142578125,52.4363308411209,18.643400458909,11.69539165,0,0,0,4449,300.5302,-5912.80200195313,,,,,,,,,,,,,,,,,13.003003,,,,,,299.9942627,,,,
,15677746.315,299.99674985,-9177.07177734375,-9.03082000040143E-5,3.67705840185437E-7,1,0.999253354069792,40.0298881530762,1.99136249738242,15.6900031119585,-0.000972947200642215,-0.00018623792531974,0.25,-1.4806553368431E-6,-9.03042983317283E-5,-1.53903483432452E-6,299.9965515,299.9969482,-9275.1337890625,-9079.009765625,52.4144452425825,18.64154129444,11.8706312,0,0,0,4449,300.53125,-9177.07177734375,,,,,,,,,,,,,,,,,13.003003,,,,,,299.99674985,,,,
,15677764.03,299.99795535,-12646.1596679688,-8.74530270605353E-5,4.78062984147421E-7,1,0.999253354069792,40.0298881530762,1.99130284810576,15.6900031119585,-0.000941716455808243,-0.000182886889618557,0.25,-1.66915019818646E-6,-8.74490950664801E-5,-1.72566006713245E-6,299.9971619,299.9987488,-12783.224609375,-12509.0947265625,52.4402389837171,18.6442868211063,11.8116336,0,0,0,4449,300.5301,-12646.1596679688,,,,,,,,,,,,,,,,,12.252253,,,,,,299.99795535,,,,
,15677779.93,300.0010071,-15762.7153320313,-8.32695428019733E-5,6.00554699270894E-7,1,0.999253354069792,40.0298881530762,1.9913244681167,15.6900031119585,-0.000896046667735612,-0.000177751208143128,0.25,-1.9235598874437E-6,-8.32655760042619E-5,-1.97734365067003E-6,300.0007935,300.0012207,-15860.7490234375,-15664.681640625,52.4808836667171,18.6397891758094,11.8116336,0,0,0,4449,300.51565,-15762.7153320313,,,,,,,,,,,,,,,,,12.252253,,,,,,300.0010071,,,,
,15677797.94,300.00486755,-19289.7451171875,-7.5088684873844E-5,4.42355593217086E-7,1,0.999253354069792,40.0298881530762,1.99131158710899,15.6900031119585,-0.000809041432680109,-0.000154370138762003,0.25,-1.18696091057729E-6,-7.50854548231003E-5,-1.23545945121425E-6,300.0043335,300.0054016,-19426.927734375,-19152.5625,52.7216252506402,18.6446780095182,11.8706312,0,0,0,4449,300.53245,-19289.7451171875,,,,,,,,,,,,,,,,,13.003003,,,,,,300.00486755,,,,
,15677814.91,300.0104065,-22621.3017578125,-6.8425677786108E-5,6.4078589165483E-7,1,0.999253354069792,40.0298881530762,1.99131363017456,15.6900031119585,-0.000735322804059717,-0.000151727239157259,0.25,-2.10485840402109E-6,-6.84220625134432E-5,-2.14900623398445E-6,300.0101624,300.0106506,-22738.916015625,-22503.6875,52.3190865632363,18.6425024970839,11.8706312,0,0,0,4449,300.5279,-22621.3017578125,,,,,,,,,,,,,,,,,12.252253,,,,,,300.0104065,,,,
,15677832.375,300.0202942,-26050.46875,-6.08578012635015E-5,8.07006109858285E-7,1,0.999253354069792,40.0298881530762,1.9912485803031,15.6900031119585,-0.000651978321835414,-0.000146390701700257,0.25,-2.93174779565496E-6,-6.0853883331657E-5,-2.9709662895324E-6,300.0202942,300.0202942,-26070.064453125,-26030.873046875,52.4441471263132,18.6411284529419,11.6358137,0,0,0,4449,300.51175,-26050.46875,,,,,,,,,,,,,,,,,12.252253,,,,,,300.0202942,,,,
,15677848.23,300.0219116,-29156.830078125,-5.31813196991321E-5,9.02842981936714E-7,1,0.999253354069792,40.0298881530762,1.99128140621971,15.6900031119585,-0.000571697549886405,-0.000116752808245083,0.25,-1.52767645213223E-6,-5.31785627016181E-5,-1.56197210214908E-6,300.0215759,300.0222473,-29264.5234375,-29049.13671875,52.504332522294,18.6464172242126,11.93022155,0,0,0,4449,300.5079,-29156.830078125,,,,,,,,,,,,,,,,,13.378378,,,,,,300.0219116,,,,
,15677866.405,300.0211334,-32715.2490234375,-4.35410025003684E-5,1.16868495233675E-6,1,0.999253354069792,40.0298881530762,1.99135630241639,15.6900031119585,-0.000466556230273341,-0.000104331818007023,0.25,-2.05965262835722E-6,-4.35382250657707E-5,-2.08769699683561E-6,300.0210571,300.0212097,-32813.296875,-32617.201171875,52.4933897230248,18.6447253629375,11.8706312,0,0,0,4449,300.48305,-32715.2490234375,,,,,,,,,,,,,,,,,13.378378,,,,,,300.0211334,,,,
,15677882.715,300.01885985,-35912.4296875,-3.570012699513E-5,1.14668972682124E-6,1,0.999253354069792,40.0298881530762,1.99137834115175,15.6900031119585,-0.000379315843448882,-0.000104039600774334,0.25,-3.40052471742342E-6,-3.56967486889962E-5,-3.42345417071301E-6,300.0188293,300.0188904,-36010.4609375,-35814.3984375,52.3159600491594,18.644019116053,11.8706312,0,0,0,4449,300.48675,-35912.4296875,,,,,,,,,,,,,,,,,13.003003,,,,,,300.01885985,,,,
,15677898.795,300.0195465,-39060.96875,-2.66869062625185E-5,1.37887336525555E-6,1,0.999253354069792,40.0298881530762,1.99134277983511,15.6900031119585,-0.000282206771412062,-8.54421609612044E-5,0.25,-3.25196504454426E-6,-2.66839234534824E-5,-3.26907565469156E-6,300.0194702,300.0196228,-39168.86328125,-38953.07421875,52.7653964477171,18.6451064149738,11.8706312,0,0,0,4449,300.4941,-39060.96875,,,,,,,,,,,,,,,,,13.378378,,,,,,300.0195465,,,,
,15677916.325,300.0230713,-42504.16796875,-1.68349852526444E-5,1.56275893701848E-6,1,0.999253354069792,40.0298881530762,1.99131338910467,15.6900031119585,-0.000176509934233132,-6.2570713849442E-5,0.25,-2.85406980855292E-6,-1.68325848466508E-5,-2.86483315537062E-6,300.0223999,300.0237427,-42621.90234375,-42386.43359375,52.3800535877363,18.644767304673,11.8706312,0,0,0,4449,300.48595,-42504.16796875,,,,,,,,,,,,,,,,,12.252253,,,,,,300.0230713,,,,
,15677932.485,300.023468,-45682.669921875,-8.55825878713142E-6,1.71137315717607E-6,1,0.999253354069792,40.0298881530762,1.99143894400037,15.6900031119585,-8.57844845912765E-5,-5.4460142535306E-5,0.25,-3.54713979579998E-6,-8.555687220562E-6,-3.55254016707448E-6,300.0230713,300.0238647,-45800.34375,-45564.99609375,52.3050172498901,18.6450886744902,11.8706312,0,0,0,4449,300.4723,-45682.669921875,,,,,,,,,,,,,,,,,13.378378,,,,,,300.023468,,,,
,15677949.515,300.024292,-49017.490234375,1.00839070412144E-6,5.98340813482023E-7,1,0.999253354069792,40.0298881530762,1.99135267081305,15.6900031119585,1.65951873023614E-5,-3.07696268767968E-5,0.25,-3.02379133478966E-6,1.01030622101608E-6,-3.02304085800471E-6,300.0231934,300.0253906,-49115.73828125,-48919.2421875,52.7396027065825,18.6450701201732,11.9898119,0,0,0,4449,300.4643,-49017.490234375,,,,,,,,,,,,,,,,,13.003003,,,,,,300.024292,,,,
,15677966.795,300.0244751,-52411.3828125,1.18908906749654E-5,1.37179994218489E-6,1,0.999253354069792,40.0298881530762,1.99133393657756,15.6900031119585,0.000133618760928814,-7.07401025488401E-6,0.25,-2.72934335222466E-6,1.18922542841854E-5,-2.72159088122339E-6,300.0241699,300.0247803,-52529.10546875,-52293.66015625,52.5293446349094,18.6467017909571,11.75322245,0,0,0,4449,300.4545,-52411.3828125,,,,,,,,,,,,,,,,,13.378378,,,,,,300.0244751,,,,
,15677984.015,300.0282288,-55795.333984375,2.07990889874932E-5,1.08697022989966E-6,1,0.999253354069792,40.0298881530762,1.99132662962314,15.6900031119585,0.000235450748346968,-2.22938181483363E-5,0.25,-5.69223073572895E-6,2.08020623087009E-5,-5.67864491211387E-6,300.0282288,300.0282288,-55805.19140625,-55785.4765625,52.3222130773132,18.644093963454,11.8128128,0,0,0,4449,300.4605,-55795.333984375,,,,,,,,,,,,,,,,,13.003003,,,,,,300.0282288,,,,
,15678000.35,300.0317078,-59003.1953125,3.14746182814366E-5,1.59693800527884E-6,1,0.999253354069792,40.0298881530762,1.9914759633171,15.6900031119585,0.000345542352321554,2.8066173969048E-5,0.25,-2.89388416475454E-6,3.14754301509289E-5,-2.87352253176307E-6,300.0313416,300.032074,-59121.046875,-58885.34375,52.0408268103901,18.6450912756721,11.93022155,0,0,0,4449,300.4542,-59003.1953125,,,,,,,,,,,,,,,,,13.003003,,,,,,300.0317078,,,,
,15678017.305,300.0337677,-62318.380859375,4.09899083856632E-5,1.5135819225845E-6,1,0.999253354069792,40.0298881530762,1.99146879199572,15.6900031119585,0.000448242362107255,4.66473218433314E-5,0.25,-2.83433056242348E-6,4.09903616172152E-5,-2.80785266551592E-6,300.0331421,300.0343933,-62436.01171875,-62200.75,52.4597796966979,18.6469363631655,11.8706312,0,0,0,4449,300.4349,-62318.380859375,,,,,,,,,,,,,,,,,12.252253,,,,,,300.0337677,,,,
,15678036.01,300.0376282,-65987.45703125,5.20308232919176E-5,1.19988581746973E-6,1,0.999253354069792,40.0298881530762,1.99134324091811,15.6900031119585,0.000569744445508763,5.46301063593451E-5,0.25,-4.02152235318126E-6,5.20316651894596E-5,-3.98791056299424E-6,300.0376282,300.0376282,-66007.0859375,-65967.828125,52.5981279446017,18.6466476537151,11.8706312,0,0,0,4449,300.4201,-65987.45703125,,,,,,,,,,,,,,,,,13.003003,,,,,,300.0376282,,,,
,15678053.54,300.0398102,-69430.671875,6.28571962695367E-5,1.31663607812902E-6,1,0.999253354069792,40.0298881530762,1.99140105401382,15.6900031119585,0.000688075591826296,6.73625831483513E-5,0.25,-4.73209941244648E-6,6.28581281285976E-5,-4.69151323813813E-6,300.0395813,300.0400391,-69460.0546875,-69401.2890625,52.5785872316209,18.6468248082896,11.8706312,0,0,0,4449,300.41165,-69430.671875,,,,,,,,,,,,,,,,,13.003003,,,,,,300.0398102,,,,
,15678069.65,300.0404205,-72588.7109375,7.13991408795656E-5,1.22685064973134E-6,1,0.999253354069792,40.0298881530762,1.99143823816606,15.6900031119585,0.00078015887264918,8.4749569815781E-5,0.25,-4.61332682042517E-6,7.13997085509526E-5,-4.56726638347765E-6,300.0394897,300.0413513,-72716.1953125,-72461.2265625,52.4754122670825,18.6453181414563,11.75322245,0,0,0,4449,300.40035,-72588.7109375,,,,,,,,,,,,,,,,,13.003003,,,,,,300.0404205,,,,
,15678087.055,300.0420837,-76012.0625,8.28173117517547E-5,1.18524020148217E-6,1,0.999253354069792,40.0298881530762,1.99141455157523,15.6900031119585,0.000904301619824681,0.000101799630723921,0.25,-5.02732637837446E-6,8.28177584400282E-5,-4.97393128383574E-6,300.0420837,300.0420837,-76031.703125,-75992.421875,52.2776602517171,18.646398746993,11.6358137,0,0,0,4449,300.39215,-76012.0625,,,,,,,,,,,,,,,,,13.003003,,,,,,300.0420837,,,,
,15678104.06,300.0428162,-79346.87109375,9.26713299817327E-5,1.11130162465234E-6,1,0.999253354069792,40.0298881530762,1.99135635398123,15.6900031119585,0.00101219427304982,0.000112062229170368,0.25,-5.79641930928286E-6,9.2671938264659E-5,-5.73668573135433E-6,300.0428162,300.0428162,-79366.5078125,-79327.234375,52.6043809727556,18.6468968121481,11.8128128,0,0,0,4449,300.3748,-79346.87109375,,,,,,,,,,,,,,,,,13.378378,,,,,,300.0428162,,,,
,15678121.71,300.0419006,-82799.8828125,0.000103911957085047,1.23438505081384E-6,1,0.999253354069792,40.0298881530762,1.99147885219143,15.6900031119585,0.0011312483850262,0.000147365353304906,0.25,-4.49087463347363E-6,0.000103911353240159,-4.42398983604538E-6,300.0419006,300.0419006,-82819.5,-82780.265625,52.443365497794,18.6455736071222,11.93022155,0,0,0,4449,300.3661,-82799.8828125,,,,,,,,,,,,,,,,,13.003003,,,,,,300.0419006,,,,
,15678137.365,300.04112245,-85880,0.000113619738536383,1.01449594879987E-6,1,0.999253354069792,40.0298881530762,1.99137194388943,15.6900031119585,0.00123889770407876,0.000149505698200382,0.25,-5.98576113595127E-6,0.000113619773001049,-5.91261872016664E-6,300.040741,300.0415039,-86017.2734375,-85742.7265625,52.4277329274094,18.6495346105622,11.8128128,0,0,0,4449,300.36115,-85880,,,,,,,,,,,,,,,,,13.378378,,,,,,300.04112245,,,,
,15678154.75,300.0411682,-89292.9453125,0.000122884434068524,1.29395747641143E-6,1,0.999253354069792,40.0298881530762,1.99132055522539,15.6900031119585,0.00133844286668021,0.000169966442438738,0.25,-5.70803054846111E-6,0.000122883981214309,-5.62898109933916E-6,300.0411682,300.0411682,-89312.3828125,-89273.5078125,52.5051141508132,18.6496263789227,11.8706312,0,0,0,4449,300.3523,-89292.9453125,,,,,,,,,,,,,,,,,13.003003,,,,,,300.0411682,,,,
,15678188.655,300.044632,-87929.55078125,0.000121615461860037,9.45030313538151E-7,1,0.999253354069792,40.0298881530762,1.99148242385868,15.6900031119585,0.0013228914107872,0.000178720899433686,0.25,-4.67764559951076E-6,0.000121614375674588,-4.59942720078084E-6,300.0440369,300.0452271,-88046.59375,-87812.5078125,52.3456619328902,18.6472619111794,11.8706312,0,0,0,4449,300.34,-87929.55078125,,,,,,,,,,,,,,,,,13.378378,,,,,,300.044632,,,,
,15678205.795,300.0430298,-84581.015625,0.000108954987386708,1.13366878209611E-6,1,0.999253354069792,40.0298881530762,1.9913537577445,15.6900031119585,0.00118747319054397,0.000146520185486986,0.25,-5.44813623526766E-6,0.000108954825192042,-5.37798260693431E-6,300.0426331,300.0434265,-84688.4765625,-84473.5546875,52.565299546794,18.6478125281829,11.93022155,0,0,0,4449,300.317,-84581.015625,,,,,,,,,,,,,,,,,12.252253,,,,,,300.0430298,,,,
,15678223.32,300.03831485,-81164.0078125,9.99227191750382E-5,1.07082619688414E-6,1,0.999253354069792,40.0298881530762,1.99141268059528,15.6900031119585,0.00108824250544892,0.000139082080632769,0.25,-4.56110757346517E-6,9.99223044956217E-5,-4.49675803393952E-6,300.038147,300.0384827,-81290.8984375,-81037.1171875,52.4894815804286,18.6469472170525,11.9898119,0,0,0,4449,300.3196,-81164.0078125,,,,,,,,,,,,,,,,,12.252253,,,,,,300.03831485,,,,
,15678240.805,300.03456115,-77746.2734375,9.00782383362594E-5,1.15243951740304E-6,1,0.999253354069792,40.0298881530762,1.99148979217015,15.6900031119585,0.00098137275031464,0.000123613092713152,0.25,-4.27567833752047E-6,9.0077979368611E-5,-4.21763840712107E-6,300.0339966,300.0351257,-77873.234375,-77619.3125,52.3847433588517,18.6469569037275,11.8128128,0,0,0,4449,300.31725,-77746.2734375,,,,,,,,,,,,,,,,,13.003003,,,,,,300.03456115,,,,
,15678257.495,300.0296478,-74494.90234375,8.02425241715896E-5,1.16404731459808E-6,1,0.999253354069792,40.0298881530762,1.991406541277,15.7000036537647,0.000874560544560409,0.000107939048466674,0.25,-4.0098861805171E-6,8.02424342956234E-5,-3.95815588772978E-6,300.029541,300.0297546,-74612.0625,-74377.7421875,51.9908025851594,18.6472819321803,11.9898119,0,0,0,4449,300.3125,-74494.90234375,,,,,,,,,,,,,,,,,13.003003,,,,,,300.0296478,,,,
,15678275.3,300.0252075,-71019.0859375,6.90616586505956E-5,9.87719868637812E-7,1,0.999253354069792,40.0298881530762,1.99143966252578,15.6900031119585,0.000752418336416118,9.45869358423438E-5,0.25,-3.29509053142195E-6,6.90614897902813E-5,-3.25055472568183E-6,300.0252075,300.0252075,-71038.5390625,-70999.6328125,52.8568469844671,18.6456970577413,11.75322245,0,0,0,4449,300.311,-71019.0859375,,,,,,,,,,,,,,,,,12.252253,,,,,,300.0252075,,,,
,15678292.485,300.01931765,-67660.5546875,5.9320816077966E-5,1.14824305492075E-6,1,0.999253354069792,40.0298881530762,1.99143879293572,15.6900031119585,0.000648653809294746,6.77138844074169E-5,0.25,-4.08273619795068E-6,5.9321487411505E-5,-4.04442513901775E-6,300.0190735,300.0195618,-67777.65625,-67543.453125,52.7458557347364,18.6450865212354,11.8128128,0,0,0,4449,300.3077,-67660.5546875,,,,,,,,,,,,,,,,,12.252253,,,,,,300.01931765,,,,
,15678309.465,300.01330565,-64340.48046875,5.01613756178972E-5,9.62297822988806E-7,1,0.999253354069792,40.0298881530762,1.99144181099238,15.6900031119585,0.000549204182815989,5.32178659420757E-5,0.25,-3.82632350052376E-6,5.01621933780203E-5,-3.79390439866505E-6,300.0130615,300.0135498,-64438.09765625,-64242.86328125,52.6833254531979,18.6465775224541,11.75322245,0,0,0,4449,300.31605,-64340.48046875,,,,,,,,,,,,,,,,,13.378378,,,,,,300.01330565,,,,
,15678325.33,300.0099182,-61240.455078125,3.9934442589427E-5,9.96112350158703E-7,1,0.999253354069792,40.0298881530762,1.99135234954384,15.6900031119585,0.000438413881423045,3.54864457216491E-5,0.25,-3.68294890927141E-6,3.99355078215937E-5,-3.65710971890117E-6,300.0097046,300.0101318,-61250.45703125,-61230.453125,52.5989095731209,18.6456542353128,12.1101885,0,0,0,4449,300.31915,-61240.455078125,,,,,,,,,,,,,,,,,13.378378,,,,,,300.0099182,,,,
,15678342.385,300.0074768,-57902.875,2.96565961417386E-5,9.42580796607799E-7,1,0.999253354069792,40.0298881530762,1.99144160319597,15.6900031119585,0.000327863525069192,1.33462705355542E-5,0.25,-3.93899620971445E-6,2.96581651296409E-5,-3.91976071246291E-6,300.0074768,300.0074768,-58020.37109375,-57785.37890625,52.5864035168132,18.6467207112489,11.8128128,0,0,0,4449,300.32155,-57902.875,,,,,,,,,,,,,,,,,13.378378,,,,,,300.0074768,,,,
,15678360.83,300.004303,-54291.771484375,1.93129724521097E-5,8.80477334026515E-7,1,0.999253354069792,40.0298881530762,1.99116298967185,15.6900031119585,0.000214194118932011,4.61538304914627E-6,0.25,-2.94233501582885E-6,1.93142394475477E-5,-2.92979126777175E-6,300.004303,300.004303,-54301.53515625,-54282.0078125,52.3683291599478,18.6504270976093,11.8706312,0,0,0,4449,300.3238,-54291.771484375,,,,,,,,,,,,,,,,,13.003003,,,,,,300.004303,,,,
,15678376.59,300.0009766,-51209.279296875,9.7006317436484E-6,7.44691619961289E-7,1,0.999253354069792,40.0298881530762,1.99129747596315,15.6900031119585,0.000113964243570716,-3.4196104444675E-5,0.25,-4.85754936912795E-6,9.70344835187543E-6,-4.85113689126199E-6,300.0009766,300.0009766,-51326.76953125,-51091.7890625,52.453526668544,18.6469399579281,12.0500002,0,0,0,4449,300.32455,-51209.279296875,,,,,,,,,,,,,,,,,13.378378,,,,,,300.0009766,,,,
,15678392.78,299.99842835,-48028.53125,1.01867901779563E-6,2.6103996196809E-7,1,0.999253354069792,40.0298881530762,1.99137888232255,15.6900031119585,1.81553076763901E-5,-3.90541721850041E-5,0.25,-3.7923083725408E-6,1.02109189258818E-6,-3.79152830628728E-6,299.9979248,299.9989319,-48155.7734375,-47901.2890625,52.5379425486209,18.6458998082615,11.6358137,0,0,0,4449,300.33285,-48028.53125,,,,,,,,,,,,,,,,,13.003003,,,,,,299.99842835,,,,
,15678410.835,299.9935913,-44505.251953125,-7.27430314115765E-6,1.1986799122588E-6,1,0.999253354069792,40.0298881530762,1.99138616642664,15.6900031119585,-7.18865625248659E-5,-5.21709945542601E-5,0.25,-3.55940432392492E-6,-7.2717713240021E-6,-3.56398304506788E-6,299.9935913,299.9935913,-44534.62109375,-44475.8828125,52.463687839294,18.646113250365,12.1101885,0,0,0,4449,300.322,-44505.251953125,,,,,,,,,,,,,,,,,13.003003,,,,,,299.9935913,,,,
,15678428.625,299.99035645,-41021.345703125,-1.72806047493184E-5,8.33151056962932E-7,1,0.999253354069792,40.0298881530762,1.99134055527947,15.6900031119585,-0.00017897816392054,-7.68743594861269E-5,0.25,-4.10010178613679E-6,-1.727740114556E-5,-4.1111237851349E-6,299.9902039,299.990509,-41050.69921875,-40991.9921875,52.4801020381979,18.644659231117,11.9898119,0,0,0,4449,300.3322,-41021.345703125,,,,,,,,,,,,,,,,,13.003003,,,,,,299.99035645,,,,
,15678445.64,299.98568725,-37693.822265625,-2.85686608445183E-5,7.06141677747411E-7,1,0.999253354069792,40.0298881530762,1.99130725401095,15.6900031119585,-0.000302611682446271,-8.85385715534258E-5,0.25,-3.21035574216475E-6,-2.85656706506245E-5,-3.2286989758708E-6,299.9850464,299.9863281,-37821.20703125,-37566.4375,52.5535751190056,18.6473445833682,11.8128128,0,0,0,4449,300.34125,-37693.822265625,,,,,,,,,,,,,,,,,12.252253,,,,,,299.98568725,,,,
,15678462.755,299.98658755,-34337.228515625,-3.77834029823046E-5,7.18178917624072E-7,1,0.999253354069792,40.0298881530762,1.9913964794486,15.6900031119585,-0.000401836589760673,-0.000107922446107535,0.25,-3.39630919442137E-6,-3.77799943095532E-5,-3.42060363283793E-6,299.9863892,299.9867859,-34474.21875,-34200.23828125,52.6481521698325,18.6449543240754,11.87122395,0,0,0,4449,300.35355,-34337.228515625,,,,,,,,,,,,,,,,,13.378378,,,,,,299.98658755,,,,
,15678479.36,299.9877472,-31087.8466796875,-4.4990718688939E-5,7.50752331863194E-7,1,0.999253354069792,40.0298881530762,1.99120710214433,15.6900031119585,-0.000478374653665032,-0.000128902801216366,0.25,-4.081672841688E-6,-4.49866320625579E-5,-4.11060964978974E-6,299.9876404,299.987854,-31205.36328125,-30970.330078125,52.6817621961594,18.647279877976,12.0500002,0,0,0,4449,300.3561,-31087.8466796875,,,,,,,,,,,,,,,,,13.003003,,,,,,299.9877472,,,,
,15678496.4,299.9888916,-27750.724609375,-5.36948404239906E-5,6.174583247205E-7,1,0.999253354069792,40.0298881530762,1.99132751232102,15.6900031119585,-0.000573482568807555,-0.000139367599001546,0.25,-3.53092497801907E-6,-5.36908251817324E-5,-3.56551531419682E-6,299.9883728,299.9894104,-27877.89453125,-27623.5546875,52.4558715541017,18.6473125944905,12.0500002,0,0,0,4449,300.3527,-27750.724609375,,,,,,,,,,,,,,,,,13.378378,,,,,,299.9888916,,,,
,15678514.32,299.98762515,-24236.69140625,-6.27007798232115E-5,5.86019399500031E-7,1,0.999253354069792,40.0298881530762,1.99126604612699,15.6900031119585,-0.000671511250095796,-0.000152071192998316,0.25,-3.13581590244113E-6,-6.26967297008654E-5,-3.17625379102948E-6,299.986908,299.9883423,-24354.017578125,-24119.365234375,52.4457103833517,18.6470170630314,11.8730011,0,0,0,4449,300.35415,-24236.69140625,,,,,,,,,,,,,,,,,13.003003,,,,,,299.98762515,,,,
,15678532.25,299.9869995,-20733.0048828125,-7.0342771305359E-5,4.41135335226709E-7,1,0.999253354069792,40.0298881530762,1.99125244583176,15.6900031119585,-0.00075432866014749,-0.00016499763145001,0.25,-2.99902530860625E-6,-7.03385624683991E-5,-3.04442274683421E-6,299.9869995,299.9869995,-20752.61328125,-20713.396484375,52.2729704806017,18.6457608026091,11.6358137,0,0,0,4449,300.361,-20733.0048828125,,,,,,,,,,,,,,,,,13.003003,,,,,,299.9869995,,,,
,15678548.685,299.9861145,-17513.25390625,-7.83641467035091E-5,4.11664184548384E-7,1,0.999253354069792,40.0298881530762,1.99127883851649,15.6900031119585,-0.00084191544185668,-0.000174884449551536,0.25,-2.51440490871252E-6,-7.83599928357791E-5,-2.56502024538229E-6,299.9855957,299.9866333,-17620.814453125,-17405.693359375,52.4480552689094,18.646530846474,12.0500002,0,0,0,4449,300.36555,-17513.25390625,,,,,,,,,,,,,,,,,12.252253,,,,,,299.9861145,,,,
,15678565.355,299.98727415,-14253.37109375,-8.37967500099483E-5,3.72976372439523E-7,1,0.999253354069792,40.0298881530762,1.99117485162542,15.6900031119585,-0.000902544878930377,-0.000173771025786029,0.25,-1.46428400090824E-6,-8.37930953441238E-5,-1.51846309159754E-6,299.9871826,299.9873657,-14390.4677734375,-14116.2744140625,52.5723342034671,18.6453665786824,11.9898119,0,0,0,4449,300.36815,-14253.37109375,,,,,,,,,,,,,,,,,13.753754,,,,,,299.98727415,,,,
,15678583.005,299.9885254,-10796.0810546875,-8.72826387681771E-5,4.01249336977185E-7,1,0.999253354069792,40.0298881530762,1.99139310577154,15.6900031119585,-0.000938545099968351,-0.00019043057609032,0.25,-2.39629145111106E-6,-8.72782626599247E-5,-2.45271314252213E-6,299.9878845,299.9891663,-10923.427734375,-10668.734375,52.6833254531979,18.6407718333462,11.99040985,0,0,0,4449,300.36715,-10796.0810546875,,,,,,,,,,,,,,,,,12.252253,,,,,,299.9885254,,,,
,15678601.06,299.9882507,-7260.00390625,-8.94960795949515E-5,4.33561924773327E-7,1,0.999253354069792,40.0298881530762,1.99124129817386,15.6900031119585,-0.000963606358103677,-0.000187625934004717,0.25,-1.75176109112344E-6,-8.9492047892244E-5,-1.80965260611181E-6,299.9882507,299.9882507,-7279.7666015625,-7240.2412109375,52.6966131380248,18.6455504652717,11.9898119,0,0,0,4449,300.36875,-7260.00390625,,,,,,,,,,,,,,,,,13.003003,,,,,,299.9882507,,,,
,15678617.525,299.9877472,-4026.9853515625,-8.22842259749497E-5,4.01291546470321E-7,1,0.999253354069792,40.0298881530762,1.99133352651344,15.6900031119585,-0.000885777852352306,-0.000173757816267401,0.25,-1.72570591195446E-6,-8.22804444840865E-5,-1.77894068689101E-6,299.9873657,299.9881287,-4144.56298828125,-3909.40771484375,52.2940744506209,18.6422894579362,11.87122395,0,0,0,4449,300.37165,-4026.9853515625,,,,,,,,,,,,,,,,,13.003003,,,,,,299.9877472,,,,
,15678634.27,299.9877472,-741.458557128906,-4.90721133808104E-5,3.61721170467374E-7,1,0.999253354069792,40.0298881530762,1.99131116126247,15.6900031119585,-0.000526285389432273,-0.00011487580051261,0.25,-2.07063398199362E-6,-4.90691828823559E-5,-2.10235374800423E-6,299.9872742,299.9882202,-869.072326660156,-613.844787597656,52.6559684550248,18.6438477416378,12.0500002,0,0,0,4449,300.377,-741.458557128906,,,,,,,,,,,,,,,,,12.252253,,,,,,299.9877472,,,,
,15678651.86,299.9892273,2687.83129882813,7.22391201377552E-5,4.18336936214547E-7,1,0.999253354069792,40.0298881530762,1.99138642097946,15.6900031119585,0.000786003035069739,0.000104749521710364,0.25,-2.90899267058727E-6,7.22386617854502E-5,-2.86210933407453E-6,299.9892273,299.9892273,2678.03002929687,2697.63256835938,52.6442440272363,18.6408240439998,11.9898119,0,0,0,4449,300.37255,2687.83129882813,,,,,,,,,,,,,,,,,13.378378,,,,,,299.9892273,,,,
,15678670.225,299.9887085,6290.36059570312,8.89182991566378E-5,3.35362781623791E-7,1,0.999253354069792,40.0298881530762,1.99133819987899,15.6900031119585,0.000966754991124513,0.000132972788390319,0.25,-3.20663928991052E-6,8.89174952205211E-5,-3.14895872658301E-6,299.9887085,299.9887085,6270.84814453125,6309.873046875,52.5699893179094,18.6412287237267,11.9898119,0,0,0,4449,300.3762,6290.36059570312,,,,,,,,,,,,,,,,,13.003003,,,,,,299.9887085,,,,
,15678686.61,299.9907074,9505.609375,8.99513557481617E-5,4.17335380703386E-7,1,0.999253354069792,40.0298881530762,1.99116825552171,15.6900031119585,0.000976239449496985,0.00014407033081215,0.25,-2.35866296578627E-6,8.99499644741634E-5,-2.30035398775484E-6,299.9900208,299.991394,9388.13671875,9623.08203125,52.6356461135248,18.644782598129,11.87122395,0,0,0,4449,300.36935,9505.609375,,,,,,,,,,,,,,,,,13.003003,,,,,,299.9907074,,,,
,15678703.855,299.9958801,12876.6088867188,8.67906438633947E-5,3.96192362858309E-7,1,0.999253354069792,40.0298881530762,1.99119820164554,15.6900031119585,0.000942646816551018,0.000135013548969676,0.25,-2.64567494457779E-6,8.67895278183474E-5,-2.58942097482452E-6,299.9958801,299.9958801,12856.8095703125,12896.408203125,52.609070743871,18.6444502271989,12.1101885,0,0,0,4449,300.38085,12876.6088867188,,,,,,,,,,,,,,,,,12.252253,,,,,,299.9958801,,,,
,15678719.805,299.9988861,16003.1020507813,8.26002698480907E-5,4.71546243694192E-7,1,0.999253354069792,40.0298881530762,1.99121281010593,15.6900031119585,0.000896797224171242,0.000130464071869417,0.25,-2.33573841451687E-6,8.25990828409189E-5,-2.28222055268215E-6,299.9988708,299.9989014,15895.390625,16110.8134765625,52.6442440272363,18.6438613139043,12.0500002,0,0,0,4449,300.37845,16003.1020507813,,,,,,,,,,,,,,,,,13.003003,,,,,,299.9988861,,,,
,15678736.43,300.006012,19266.11328125,7.54126645641001E-5,5.20389391583488E-7,1,0.999253354069792,40.0298881530762,1.99130284081105,15.6900031119585,0.000819353523012768,0.000115918791641823,0.25,-2.42845242804248E-6,7.5411755898941E-5,-2.37959349388008E-6,300.0058289,300.0061951,19148.6328125,19383.59375,52.7567985340056,18.642140256684,12.0500002,0,0,0,4449,300.36515,19266.11328125,,,,,,,,,,,,,,,,,13.003003,,,,,,300.006012,,,,
,15678752.85,300.00868225,22480.0361328125,6.77442503687334E-5,6.32852453676142E-7,1,0.999253354069792,40.0298881530762,1.99121284222458,15.6900031119585,0.00073594856508192,0.000104452159625451,0.25,-2.15140644223058E-6,6.77434096257938E-5,-2.10752829288845E-6,300.0083313,300.0090332,22362.32421875,22597.748046875,52.3339375051017,18.643370474418,12.1101885,0,0,0,4449,300.3548,22480.0361328125,,,,,,,,,,,,,,,,,13.378378,,,,,,300.00868225,,,,
,15678769.415,300.0117645,25732.951171875,6.05000036846039E-5,8.06591048843151E-7,1,0.999253354069792,40.0298881530762,1.9912686249515,15.6900031119585,0.000656438748617033,9.80324523790596E-5,0.25,-1.48191810432229E-6,6.04989637169871E-5,-1.44275975743925E-6,300.0114746,300.0120544,25615.302734375,25850.599609375,52.4418022407555,18.6414967991608,11.93141225,0,0,0,4449,300.36005,25732.951171875,,,,,,,,,,,,,,,,,13.003003,,,,,,300.0117645,,,,
,15678785.795,300.0167084,28947.173828125,5.32564275729167E-5,6.3766346082637E-7,1,0.999253354069792,40.0298881530762,1.991207791168,15.6900031119585,0.000580306249540786,7.2085983409519E-5,0.25,-2.61945840514884E-6,5.32563542438911E-5,-2.58495509776307E-6,300.0159607,300.0174561,28849.1640625,29045.18359375,52.6278298283325,18.6415768706612,12.0500002,0,0,0,4449,300.3549,28947.173828125,,,,,,,,,,,,,,,,,12.252253,,,,,,300.0167084,,,,
,15678803.385,300.02009585,32387.5087890625,4.31486600601499E-5,8.49241051095581E-7,1,0.999253354069792,40.0298881530762,1.99109093773243,15.6900031119585,0.000472242632876762,4.63575839130351E-5,0.25,-3.23712019508328E-6,4.31493166087928E-5,-3.20913643926166E-6,300.0197449,300.0204468,32259.865234375,32515.15234375,52.8169839299863,18.6443367629703,11.87122395,0,0,0,4449,300.3402,32387.5087890625,,,,,,,,,,,,,,,,,12.252253,,,,,,300.02009585,,,,
,15678821.095,300.0241089,35859.90625,3.55386769555941E-5,9.37519713966184E-7,1,0.999253354069792,40.0298881530762,1.99108706157449,15.6900031119585,0.000389130017223459,3.71729297770886E-5,0.25,-2.75955904755818E-6,3.55392736205368E-5,-2.73651491541434E-6,300.0241089,300.0241089,35850.0390625,35869.7734375,52.4801020381979,18.6407975035986,11.9898119,0,0,0,4449,300.33165,35859.90625,,,,,,,,,,,,,,,,,13.378378,,,,,,300.0241089,,,,
,15678837.635,300.02304075,39106.396484375,2.60463075223098E-5,1.08627112775385E-6,1,0.999253354069792,40.0298881530762,1.99111474981132,15.6900031119585,0.000286869325777973,1.76608388938192E-5,0.25,-2.90957617770286E-6,2.60473185751556E-5,-2.89266269263243E-6,300.022583,300.0234985,38988.6875,39224.10546875,52.463687839294,18.6458632481458,12.0500002,0,0,0,4449,300.31875,39106.396484375,,,,,,,,,,,,,,,,,13.003003,,,,,,300.02304075,,,,
,15678855.855,300.0228882,42677.50390625,1.46577944415027E-5,9.96411582098967E-7,1,0.999253354069792,40.0298881530762,1.99107431065826,15.6900031119585,0.000160504929498187,1.52705870570096E-5,0.25,-1.14382441422456E-6,1.46580449095153E-5,-1.13432629550617E-6,300.0228882,300.0228882,42657.99609375,42697.01171875,52.2073136849863,18.6446140497784,11.87122395,0,0,0,4449,300.3171,42677.50390625,,,,,,,,,,,,,,,,,13.003003,,,,,,300.0228882,,,,
,15678871.795,300.0226593,45817.322265625,7.34969936364843E-6,1.47438198752056E-6,1,0.999253354069792,40.0298881530762,1.99100741377635,15.6900031119585,8.00733413422892E-5,9.97435743996675E-6,0.25,-3.58992097799265E-7,7.3496866248152E-6,-3.54238292048948E-7,300.0226135,300.0227051,45719.12109375,45915.5234375,52.5309078919479,18.645185749884,11.87122395,0,0,0,4449,300.31355,45817.322265625,,,,,,,,,,,,,,,,,13.378378,,,,,,300.0226593,,,,
,15678889.39,300.02597045,49270.271484375,-3.14736733748848E-6,2.45116628768847E-6,1,0.999253354069792,40.0298881530762,1.99094600071774,15.6900031119585,-2.94917941352003E-5,-3.17661569448704E-5,0.25,-2.3915321846767E-6,-3.145720051035E-6,-2.39348233323744E-6,300.0259094,300.0260315,49172.2578125,49368.28515625,52.3956861581209,18.6464826833046,11.9898119,0,0,0,4449,300.31,49270.271484375,,,,,,,,,,,,,,,,,12.252253,,,,,,300.02597045,,,,
,15678908.955,300.0298767,53105.75390625,-1.38989041903663E-5,1.44256301485769E-6,1,0.999253354069792,40.0298881530762,1.99091530238908,15.6900031119585,-0.000146715992785799,-4.58164268296856E-5,0.25,-1.81642768046377E-6,-1.38972685551015E-5,-1.82532732575677E-6,300.0298767,300.0298767,53095.859375,53115.6484375,52.6184502861017,18.6452057831054,12.1101885,0,0,0,4449,300.29975,53105.75390625,,,,,,,,,,,,,,,,,12.252253,,,,,,300.0298767,,,,
,15678925.79,300.0308533,56411.515625,-2.32255872345215E-5,1.56672052048127E-6,1,0.999253354069792,40.0298881530762,1.99106545367246,15.6900031119585,-0.000247909436094526,-6.09528908824521E-5,0.25,-1.59003103807457E-6,-2.32237858915566E-5,-1.60494599572106E-6,300.0307007,300.0310059,56293.828125,56529.203125,52.5058957793325,18.644481009519,12.1101885,0,0,0,4449,300.2872,56411.515625,,,,,,,,,,,,,,,,,13.003003,,,,,,300.0308533,,,,
,15678942.725,300.0317688,59727.638671875,-3.22443064151548E-5,1.45572836714759E-6,1,0.999253354069792,40.0298881530762,1.99106362125895,15.6900031119585,-0.000344787815661387,-8.11076119176538E-5,0.25,-1.88220132770539E-6,-3.22420154262489E-5,-1.9029114501628E-6,300.0310669,300.0324707,59610.01171875,59845.265625,52.5137120645248,18.6448934271423,11.87122395,0,0,0,4449,300.27825,59727.638671875,,,,,,,,,,,,,,,,,13.378378,,,,,,300.0317688,,,,
,15678960.34,300.0320435,63190.69921875,-4.2126731764148E-5,1.28519839391551E-6,1,0.999253354069792,40.0298881530762,1.9910258281548,15.6900031119585,-0.000446860085044798,-0.000126553746062045,0.25,-4.36503572043366E-6,-4.21225123514246E-5,-4.39201972581295E-6,300.0320435,300.0320435,63181.02734375,63200.37109375,52.4167901281402,18.6451789237573,11.9898119,0,0,0,4449,300.266,63190.69921875,,,,,,,,,,,,,,,,,13.003003,,,,,,300.0320435,,,,
,15678976.805,300.0307312,66418.47265625,-5.30831991955617E-5,1.078065906773E-6,1,0.999253354069792,40.0298881530762,1.9910511559559,15.6900031119585,-0.000569810036515867,-0.000120940833077946,0.25,-1.93375904783616E-6,-5.30801832803586E-5,-1.96786759124544E-6,300.0306091,300.0308533,66300.9375,66536.0078125,52.2901663080248,18.6463196380622,12.1101885,0,0,0,4449,300.26415,66418.47265625,,,,,,,,,,,,,,,,,13.378378,,,,,,300.0307312,,,,
,15678993.72,300.03175355,69744.078125,-6.0806501314053E-5,1.31940485207052E-6,1,0.999253354069792,40.0298881530762,1.99100968065154,15.6900031119585,-0.000653605796844932,-0.000133350143581406,0.25,-1.73523027507408E-6,-6.08033554093778E-5,-1.7743028952365E-6,300.0315552,300.0319519,69616.6953125,69871.4609375,52.5066774078517,18.6441880079911,11.93141225,0,0,0,4449,300.25655,69744.078125,,,,,,,,,,,,,,,,,13.003003,,,,,,300.03175355,,,,
,15679010.49,300.0335541,73030.1015625,-7.27952226524681E-5,9.41361023661443E-7,1,0.999253354069792,40.0298881530762,1.99100532331838,15.6900031119585,-0.000784556128019187,-0.000147685981750392,0.25,-9.70667196813769E-7,-7.27921665679692E-5,-1.01746189198084E-6,300.0335083,300.0335999,72912.484375,73147.71875,52.1518180601209,18.6432690692986,12.0500002,0,0,0,4449,300.25515,73030.1015625,,,,,,,,,,,,,,,,,13.003003,,,,,,300.0335541,,,,
,15679029.39,300.036377,76738.390625,-8.40539397840685E-5,1.14350521093012E-6,1,0.999253354069792,40.0298881530762,1.99091723589974,15.6900031119585,-0.00090590896768937,-0.000170239533367153,0.25,-1.09481577896624E-6,-8.40504226704881E-5,-1.14882626159115E-6,300.036377,300.036377,76738.390625,76738.390625,52.5098039219286,18.6442546799835,11.93141225,0,0,0,4449,300.2448,76738.390625,,,,,,,,,,,,,,,,,13.378378,,,,,,300.036377,,,,
,15679044.965,300.0380249,79798.84375,-9.40603655946195E-5,1.13400126610259E-6,1,0.999253354069792,40.0298881530762,1.99109255950318,15.6900031119585,-0.00101439426663942,-0.000187342130453382,0.25,-9.30826681104079E-7,-9.4056616168242E-5,-9.91257625014113E-7,300.0375977,300.0384521,79661.3984375,79936.2890625,52.3081437639671,18.6425542886673,12.1101885,0,0,0,4449,300.22905,79798.84375,,,,,,,,,,,,,,,,,12.252253,,,,,,300.0380249,,,,
,15679061.5,300.0390167,83036.09375,-0.000103987869499295,8.75767263217709E-7,1,0.999253354069792,40.0298881530762,1.99108287649751,15.6900031119585,-0.00112264527192866,-0.000200276322404764,0.25,-3.96157995589556E-7,-0.000103984130523711,-4.62962814244278E-7,300.0384521,300.0395813,82918.546875,83153.640625,52.402720814794,18.6416961435061,12.1101885,0,0,0,4449,300.2232,83036.09375,,,,,,,,,,,,,,,,,12.252253,,,,,,300.0390167,,,,
,15679078.93,300.03771975,86459.9921875,-0.000114709120628582,9.75230834602935E-7,1,0.999253354069792,40.0298881530762,1.99093752709744,15.6900031119585,-0.00123992737919758,-0.000211616099972318,0.25,4.233115752686E-7,-0.000114705556338776,3.49617090809167E-7,300.036438,300.0390015,86371.6640625,86548.3203125,52.3988126721978,18.6443328272099,12.1101885,0,0,0,4449,300.2061,86459.9921875,,,,,,,,,,,,,,,,,12.252253,,,,,,300.03771975,,,,
,15679098.28,300.03450015,89999.58203125,-0.000126533060932279,1.17902653003569E-6,1,0.999253354069792,40.0298881530762,1.99107566948385,15.6900031119585,-0.00136411974174296,-0.000254686285353608,0.25,-1.4993831295972E-6,-0.000126527883364553,-1.58057232976224E-6,300.0343628,300.0346375,89999.5078125,89999.65625,52.2651541954094,18.6407379328493,11.93141225,0,0,0,4417,300.20475,89999.58203125,,,,,,,,,,,,,,,,,13.003003,,,,,,300.03450015,,,,