File: data/doubleLayers/dl_1-25/ppms/DD205_8_extracted.dat
#Loading data from DD205_3_HYST_300K.DAT
#
#Found columns:
#Comment
#Time Stamp (sec)
#Temperature (K)
#Magnetic Field (Oe)
#Moment (emu)
#M. Std. Err. (emu)
#Transport Action
#Averaging Time (sec)
#Frequency (Hz)
#Peak Amplitude (mm)
#Center Position (mm)
#Coil Signal' (mV)
#Coil Signal" (mV)
#Range (mV)
#M. Quad. Signal (emu)
#M. Raw' (emu)
#M. Raw" (emu)
#Min. Temperature (K)
#Max. Temperature (K)
#Min. Field (Oe)
#Max. Field (Oe)
#Mass (grams)
#Motor Lag (deg)
#Pressure (Torr)
#VSM Status (code)
#Motor Status (code)
#Measure Status (code)
#PPMS Status (code)
#System Temp. (K)
#System Field (Oe)
#Sample Position (deg)
#Bridge 1 Resistance (ohms)
#Bridge 1 Excitation (A)
#Bridge 2 Resistance (ohms)
#Bridge 2 Excitation (A)
#Bridge 3 Resistance (ohms)
#Bridge 3 Excitation (A)
#Bridge 4 Resistance (ohms)
#Bridge 4 Excitation (A)
#Signal 1 Vin (V)
#Signal 2 Vin (V)
#Digital Inputs (code)
#Drive 1 Iout (mA)
#Drive 1 Ipower (W)
#Drive 2 Iout (mA)
#Drive 2 Ipower (W)
#Pressure ()
#Map 20 ()
#Map 21 ()
#Map 22 ()
#Map 23 ()
#Map 24 ()
#Map 25 ()
#Map 26 ()
#Map 27 ()
#Map 28 ()
#Map 29 ()
#
#Transformed data from column 'Moment (emu)' from emu to memu by multiplication with 1000.
#Transformed data from column 'Magnetic Field (Oe)' from Oe to Tesla by division with 10000.
#Loaded 1405 datapoints.
#Loading Magnetic Field (Oe) and Moment (emu)
#Running linear fit between B=(6.006505078125 .. 8.999958203125) with LM algorithm.
#[[Fit Statistics]]
#    # function evals   = 9
#    # data points      = 237
#    # variables        = 2
#    chi-square         = 0.001
#    reduced chi-square = 0.000
#    Akaike info crit   = -3011.736
#    Bayesian info crit = -3004.800
#[[Variables]]
#    m:  -0.03159876 +/- 0.000129 (0.41%) (init= 8.254994)
#    b:   0.15912468 +/- 0.000976 (0.61%) (init=-74.42113)
#[[Correlations]] (unreported correlations are <  0.100)
#    C(m, b)                      = -0.993
#Running linear fit between B=(-8.999965625 .. -6.0346984375) with LM algorithm.
#[[Fit Statistics]]
#    # function evals   = 8
#    # data points      = 234
#    # variables        = 2
#    chi-square         = 0.000
#    reduced chi-square = 0.000
#    Akaike info crit   = -3136.021
#    Bayesian info crit = -3129.110
#[[Variables]]
#    m:  -0.03057150 +/- 9.21e-05 (0.30%) (init=-0.03159877)
#    b:  -0.14878967 +/- 0.000697 (0.47%) (init=-0.1591247)
#[[Correlations]] (unreported correlations are <  0.100)
#    C(m, b)                      =  0.993
#Mean diamagnetic slope: -0.03108840728310231 +/- 7.947034053141216e-05
#Exporting data to DD205_8_extracted.dat
#
#B / T	M / memu	T / K
8.99995078125	-0.126594328466107	300.10147095
8.988064453125	-0.12445304009788401	300.09977725
8.944221484375	-0.12350098077936102	300.0975647
8.901203125	-0.12182311911177801	300.09809875
8.83213125	-0.120288180559522	300.09729
8.7784859375	-0.119395454717907	300.0953064
8.740415234375	-0.116378503752423	300.0947113
8.679897265625	-0.113983084190458	300.0939636
8.638888671875	-0.11239412349745	300.0923767
8.585184765625	-0.11058099135551601	300.09028625
8.530525390625	-0.109528834400629	300.08848575
8.475798828125	-0.10765294539425001	300.0865631
8.420151953125	-0.10737144753439899	300.08578495
8.366452734375	-0.102974868876475	300.0844421
8.3254390625	-0.101831001933239	300.082428
8.272710546875	-0.10108442119962999	300.0807037
8.206333984375	-0.101045493594596	300.0790405
8.168233984375	-0.09759474419596849	300.0779724
8.12234921875	-0.0983634602903805	300.0758362
8.07742890625	-0.0934992504707576	300.07543945
8.00804921875	-0.09351929991520831	300.0717468
7.967058984375	-0.0908904589453993	300.07081605
7.919208203125	-0.0898452794096307	300.0698395
7.84892265625	-0.0878463451688896	300.0675049
7.8118046875	-0.0842171473347352	300.0667572
7.764926171875	-0.08446732851048071	300.06521605
7.71903203125	-0.0836229873728459	300.0634308
7.6673078125	-0.08258739049546	300.06190495
7.621418359375	-0.0813108381374357	300.06176755
7.570584765625	-0.0787636123629951	300.0601196
7.52764453125	-0.0777544074031373	300.0590668
7.4592765625	-0.0757119355634654	300.0573425
7.39972421875	-0.0735486945312506	300.0550537
7.36459140625	-0.0724102612821002	300.0563202
7.293321484375	-0.0696175010210411	300.0532532
7.237640625	-0.0662350981985826	300.052887
7.205434765625	-0.0660298951582125	300.0528412
7.159540625	-0.0647384546270014	300.05203245
7.1146140625	-0.064166504691632	300.0516815
7.056993359375	-0.0611392975930825	300.05030825
7.008193359375	-0.060934558477340396	300.048645
6.962307421875	-0.0593770788620872	300.04766845
6.9183453125	-0.0572550419470638	300.0472412
6.86271015625	-0.053240141087476496	300.0466156
6.816790234375	-0.053952078859177494	300.0449982
6.7601546875	-0.0519082502239761	300.04393005
6.713271875	-0.0497459813524669	300.04400635
6.65369453125	-0.0488794399427747	300.04179385
6.589238671875	-0.0444920472244218	300.0400085
6.55507265625	-0.0462183245444258	300.03987125
6.5043126953125	-0.046544958871508696	300.0381622
6.4564435546875	-0.0436691760612508	300.0380554
6.3910435546875	-0.0424531055843869	300.038208
6.356846875	-0.039498838465483306	300.03721615
6.292355078125	-0.0393176652016605	300.0370178
6.2550884765625	-0.0367007916342676	300.03419495
6.2090869140625	-0.035193682455652596	300.034256
6.164076953125	-0.033581365314625404	300.0332947
6.0936021484375	-0.0322009572626535	300.0319519
6.0505447265625	-0.0304220526603056	300.0296936
6.006505078125	-0.0287770072478784	300.0290375
5.95463984375	-0.0281491588130391	300.02882385
5.9086427734375	-0.0278252087688683	300.028183
5.8352296875	-0.0263465372791332	300.0261383
5.7960376953125	-0.022923426355048602	300.02528385
5.7392634765625	-0.021702760062025102	300.02357485
5.69618671875	-0.020853462579878797	300.0236969
5.653119921875	-0.0188389770675822	300.02323915
5.5973587890625	-0.0187552987018699	300.02183535
5.5386373046875	-0.016451873437026702	300.02075195
5.476003125	-0.015160692694567	300.0197144
5.432931640625	-0.0136487449942833	300.0207977
5.375196484375	-0.0109824415307399	300.0181885
5.3242939453125	-0.0109245733485362	300.0170593
5.2645923828125	-0.007890822574321969	300.0164185
5.225446484375	-0.00849433365651063	300.0160065
5.1804400390625	-0.00669324032890551	300.01586915
5.13051640625	-0.00425446873863097	300.0152283
5.0649623046875	-0.00210489320607501	300.0145264
5.0218853515625	-0.0010176639979832499	300.01257325
4.9749302734375	-0.000355419461488646	300.01239015
4.90536875	0.000384254878371756	300.013092
4.87308671875	0.00235683664616778	300.01101685
4.828061328125	0.00410882724236585	300.01124575
4.7752248046875	0.00583957093823635	300.01052855
4.7213880859375	0.00695188892833533	300.00993345
4.6479755859375	0.00700229593102121	300.0084686
4.601016796875	0.0104635489584416	300.00787355
4.5540423828125	0.0119429261649742	300.00764465
4.497264453125	0.0120822060302553	300.0068512
4.438505078125	0.0144490892004267	300.0056305
4.3807720703125	0.0157267805131603	300.0050964
4.341604296875	0.016639598247778	300.00517275
4.277996484375	0.0188040924719215	300.0040894
4.2388548828125	0.020123214393778902	300.0035858
4.1918869140625	0.0218237433429822	300.0037384
4.13903515625	0.023624282302626698	300.00349425
4.0861763671875	0.023519280696624602	300.00268555
4.0244890625	0.0256404091319859	300.002655
3.9774837890625	0.0277446654148326	300.00242615
3.9314916015625	0.0288058951177991	300.0021515
3.8649388671875	0.0296720528650994	300.0012817
3.8297208984375	0.0314412334556253	300.0009308
3.765124609375	0.033723737211161196	300.0000916
3.7279447265625	0.0339232252856356	300.00096135
3.6780400390625	0.0357166913708213	300.0
3.624216796875	0.0379984387304448	299.99894715
3.5782044921875	0.0379914379807486	299.99887085
3.522417578125	0.0399529767022426	299.9984894
3.4734744140625	0.0413560014336971	299.9985809
3.406926953125	0.0423982624129627	299.9989929
3.3677966796875	0.044740626249078104	299.99879455
3.324718359375	0.0459094956671532	299.99745175
3.27580478515625	0.046227672365854004	299.99693295
3.2248947265625	0.0476119938185844	299.9962616
3.16815234375	0.048493767342124405	299.9954834
3.114294140625	0.0499176549801799	299.9949646
3.0536181640625	0.0514197101273544	299.9950256
2.9997892578125	0.0525855148694432	299.9942017
2.95378212890625	0.0548224034499284	299.9936829
2.89507490234375	0.055525186263727204	299.9943237
2.83440458984375	0.0571889413857949	299.99240115
2.77860537109375	0.0586649709992609	299.9929352
2.7414345703125	0.0586367122993948	299.9929962
2.695392578125	0.06111145324090211	299.9918213
2.63468388671875	0.062333673684526594	299.9907837
2.588694921875	0.0631263481958375	299.98999025
2.54170556640625	0.0634841142360609	299.9897766
2.488870703125	0.06507233437760321	299.989563
2.4458103515625	0.0661198648719489	299.98832705
2.38220830078125	0.0670793879284927	299.98756405
2.3479384765625	0.06839903244472731	299.9888916
2.27944375	0.0696540995422461	299.9880676
2.23242158203125	0.07049047666823889	299.9875946
2.1903330078125	0.0714771228324479	299.9877014
2.13552197265625	0.07234720324549271	299.98701475
2.093443359375	0.0736950274514718	299.98721315
2.026890625	0.0750411919413345	299.9868469
1.9740337890625	0.0762685281929389	299.9871216
1.91239072265625	0.0766643653335441	299.98760985
1.8507693359375	0.079395773764825	299.9873962
1.81356396484375	0.0798575083312292	299.98698425
1.7626380859375	0.0795124864097003	299.98765565
1.6941546875	0.08119749798468251	299.9862061
1.660865234375	0.0821932727857015	299.9878845
1.60509677734375	0.0830228164245069	299.9876404
1.55124799804687	0.08429220963446081	299.98739625
1.5052055175781298	0.08470191332676999	299.9877319
1.43665551757813	0.0857602508414472	299.9875183
1.39944326171875	0.0864779969520468	299.98768615
1.33379145507813	0.08683434878929669	299.9877625
1.29658540039062	0.0882609363994145	299.9885254
1.2358970214843799	0.0883246854545611	299.9900513
1.19767690429688	0.0893427606817394	299.98913575
1.137921875	0.08960068357491151	299.9892883
1.08896616210938	0.0902157143352138	299.98820495
1.04095771484375	0.09011580164646531	299.98858645
0.983190625	0.0902564032205235	299.98876955
0.938143505859375	0.09117203568112661	299.9886932
0.875404931640625	0.0915567876559891	299.9877625
0.841108837890625	0.0906527671770095	299.98803715
0.794108447265625	0.0912212918777293	299.98831175
0.741214233398438	0.0913872104997531	299.987381
0.695175366210937	0.09051390211242881	299.98822025
0.630509130859375	0.0899715582621345	299.9886322
0.591341479492188	0.088997580260036	299.98854065
0.531590380859375	0.0881680594378571	299.9889832
0.47673388671875	0.0870588450224749	299.9894409
0.43453850097656205	0.08540495789449279	299.99072265
0.371811474609375	0.08320090342308409	299.990448
0.335554699707031	0.0795983559785807	299.99090575
0.289469702148438	0.0771464574955681	299.9906311
0.221828686523438	0.0729162943789379	299.9900818
0.174736383056641	0.0665500575127379	299.9903259
0.115860241699219	0.0596080839852946	299.9910278
0.0589345947265625	0.0521009865738155	299.9918518
0.0275743949890137	0.0333505522980956	299.9916229
-0.0184294513702393	-0.0130571579968214	299.99185185
-0.0759570037841797	-0.0446244917212764	299.99246215
-0.118728662109375	-0.0538507264826729	299.9917145
-0.166292498779297	-0.0638381916981464	299.99287415
-0.214805737304687	-0.0690488552982855	299.9928131
-0.26053082275390604	-0.0742961549229121	299.9944763
-0.31234171142578104	-0.0765073179877744	299.99386595
-0.366430419921875	-0.0805701623473386	299.99398805
-0.411716772460937	-0.08333830506137689	299.99407955
-0.4647968017578121	-0.0843271896044188	299.9936676
-0.512842358398438	-0.0869944935013309	299.9935913
-0.579516137695313	-0.0878633059761116	299.9942322
-0.628535522460937	-0.0891685819837591	299.9941406
-0.6647973388671871	-0.089102754382108	299.9940491
-0.71183173828125	-0.0904081963284503	299.99409485
-0.7686727294921879	-0.0903767126595738	299.9948883
-0.820615576171875	-0.0909835955327405	299.99681095
-0.873553369140625	-0.0897004348751335	299.99661255
-0.917707177734375	-0.09030820000401431	299.99674985
-0.983356640625	-0.09005776613063941	299.9980164
-1.0372771484375	-0.0893874903611062	299.9976501
-1.09212231445312	-0.08999337249140721	299.9980774
-1.15388110351562	-0.0888209895532656	299.9975281
-1.18523427734375	-0.0880212434500128	299.9973755
-1.23815947265625	-0.0883906440771879	299.9976807
-1.28811440429688	-0.0873657235151884	299.99816895
-1.33812778320312	-0.0864739799546363	299.9976349
-1.3871431640625	-0.0849155212552636	299.99887085
-1.4371076171875	-0.0853171747938557	299.9984283
-1.48219272460938	-0.0838636760634959	299.9993439
-1.52920634765625	-0.08289673419333	299.9997864
-1.5762715332031298	-0.0832695428019733	300.0010071
-1.628179296875	-0.0821024780654835	300.0005951
-1.68696318359375	-0.080728520194858	300.0017395
-1.74180849609375	-0.0796057181590424	300.0029755
-1.81041796875	-0.0774341972508617	300.0042572
-1.84960283203125	-0.07754886913095921	300.0041504
-1.91428310546875	-0.07606608275048861	300.0043335
-1.97502099609375	-0.0744423764196496	300.0066528
-2.0289107421875	-0.07316633583219809	300.0077515
-2.06125234375	-0.0737147652834832	300.0083313
-2.10924931640625	-0.0718754993513285	300.008316
-2.154335546875	-0.0705520942864558	300.00901795
-2.2140908203125	-0.069921010638387	300.00990295
-2.26213017578125	-0.068425677786108	300.0104065
-2.31013955078125	-0.0672308044292924	300.0131378
-2.3552169921875	-0.0656581494053833	300.01325985
-2.4237927734375	-0.0656081249442372	300.0153503
-2.46299189453125	-0.06379669172901099	300.01676945
-2.50707744140625	-0.0628007100174041	300.0173187
-2.559974609375	-0.06199680782893371	300.0190277
-2.61876279296875	-0.0612130115122918	300.01982115
-2.66579716796875	-0.0592925518086394	300.0196991
-2.72072607421875	-0.0578707187569533	300.01934815
-2.76480048828125	-0.057680794104170305	300.02023315
-2.81379267578125	-0.0562383406631671	300.0206299
-2.8588529296875	-0.0541090187488475	300.0208588
-2.9156830078125	-0.053181319699132104	300.0219116
-2.971510546875	-0.0520719437046302	300.02171325
-3.030309375	-0.049417565098675204	300.02171325
-3.08515673828125	-0.048078402978599104	300.02153015
-3.14203642578125	-0.047089899202217095	300.0215607
-3.19794130859375	-0.046575404008532204	300.0217285
-3.2499359375	-0.0446041496121016	300.02119445
-3.292112109375	-0.0427982468081977	300.0209961
-3.3538822265625	-0.042568708331617806	300.0204468
-3.38920234375	-0.0410355232024289	300.020401
-3.4460896484375	-0.039439369626944595	300.0192261
-3.5010052734375	-0.0376582872420586	300.01960755
-3.5471095703125	-0.0359876845220375	300.01878355
-3.59124296875	-0.035700126995130005	300.01885985
-3.6353849609375	-0.033705568443792695	300.01901245
-3.682460546875	-0.0326742790793076	300.01919555
-3.7324751953125	-0.0316441557712445	300.01893615
-3.790362890625	-0.0299887204143513	300.0190277
-3.8452943359375	-0.0281361818541691	300.0192261
-3.8864865234375	-0.0277211137018557	300.0187683
-3.9473076171875	-0.0246430341704448	300.0194702
-3.98650703125	-0.0232903691397473	300.02035525
-4.0522916015625	-0.022488511106147697	300.0209351
-4.096430859375	-0.0215643871756152	300.02098085
-4.13958125	-0.020645892810154103	300.02156065
-4.1925447265625	-0.0193226760594668	300.02207945
-4.250416796875	-0.016834985252644402	300.0230713
-4.2994771484375	-0.0162144895608132	300.02294925
-4.348505078125	-0.0145971249832511	300.023407
-4.40833125	-0.0129820472770636	300.02259825
-4.4632708984375	-0.012857479518489201	300.0231934
-4.50843828125	-0.0100377181558136	300.0238037
-4.5447291015625	-0.00868225635921217	300.0232849
-4.590828515625	-0.00857015034808054	300.0235901
-4.664364453125	-0.0056682147150247	300.0233154
-4.709521875	-0.00448749738000526	300.0231171
-4.770300390625	-0.0032047071501059	300.025177
-4.8095546875	-0.00126297304876334	300.0243988
-4.8575951171875	0.000884863200702809	300.0252228
-4.9017490234375	0.00100839070412144	300.024292
-4.9714365234375	0.00239215298084107	300.0247192
-5.0067376953125	0.00478866615003357	300.02456665
-5.0587306640625	0.00667891504443977	300.0233459
-5.109726953125	0.008591085679763591	300.0238953
-5.1695546875	0.00915027835042954	300.0249329
-5.227407421875	0.0107502118250409	300.0247803
-5.2833275390625	0.012783019739552	300.0238647
-5.315704296875	0.0133603050232341	300.02445985
-5.36374609375	0.0128709006810945	300.0254669
-5.41083828125	0.0168484565076946	300.0259552
-5.46771640625	0.0180452997207586	300.0269623
-5.5138142578125	0.018451293390105303	300.0271454
-5.5795333984375	0.020799088987493202	300.0282288
-5.61386484375	0.023059506503036398	300.02799985
-5.6638865234375	0.023642204666810898	300.02870175
-5.708026171875	0.024253924230950203	300.02958675
-5.7600044921875	0.0267737800998615	300.02963255
-5.8189009765625	0.0279121515794734	300.0303345
-5.877734765625	0.029872495671136298	300.0324707
-5.922887109375	0.031951910512837	300.0317078
-5.9709509765625	0.0322895616335691	300.03175355
-6.0346984375	0.034355624329955405	300.0329285
-6.071943359375	0.0367538650260398	300.032547
-6.1327609375	0.0379428444415131	300.033905
-6.1945732421875	0.0392353067710494	300.0339661
-6.2318380859375	0.0409899083856632	300.0337677
-6.2829	0.0423217625554437	300.0349884
-6.329001171875	0.043338920403778305	300.0349579
-6.4006140625	0.0468655046081606	300.0361023
-6.4584775390625	0.047099278248619404	300.0373535
-6.501627734375	0.0485567693856023	300.03726195
-6.56046171875	0.0505678515638004	300.0373535
-6.6105046875	0.052059530247502	300.0375061
-6.670317578125	0.0537747716356044	300.0381317
-6.7213875	0.0563716985467658	300.0387878
-6.78807421875	0.0557102534174944	300.038208
-6.82536484375	0.0574957977279936	300.03929135
-6.88714375	0.0616421262156681	300.0387268
-6.9430671875	0.0628571962695367	300.0398102
-6.977391015625	0.0637155262318157	300.0393219
-7.04603359375	0.0644620516436519	300.0386047
-7.089197265625	0.068116800945036	300.03910825
-7.136258984375	0.06823805889251039	300.0392609
-7.181387890625	0.0706218460735575	300.039978
-7.245145703125	0.07212264407579169	300.0394897
-7.285371484375	0.07195169595685501	300.0413513
-7.33242109375	0.07499593801096331	300.04089355
-7.384419921875	0.0764909004134579	300.0410461
-7.433458984375	0.0777260154775359	300.04240415
-7.48446796875	0.0795409556325686	300.04266355
-7.531537890625	0.0804053714211074	300.0423889
-7.60120625	0.0828173117517547	300.0420837
-7.660069140625	0.0845827465689916	300.0440369
-7.693415625	0.0851912569343321	300.04325865
-7.7650203125	0.08803037003790311	300.0430603
-7.797378515625	0.08851504319455661	300.0428009
-7.84153046875	0.0888324107592148	300.04347225
-7.8915390625	0.0916228260882774	300.04223635
-7.94941171875	0.0948579705799348	300.0423584
-8.006299609375	0.0957202477672507	300.04330445
-8.054385546875	0.09658774925725659	300.04219055
-8.105409375	0.09812667169356841	300.0420532
-8.152477734375	0.09948765157009859	300.0426178
-8.22113515625	0.101504217694741	300.042984
-8.27998828125	0.103911957085047	300.0419006
-8.315301953125	0.105854824004814	300.041687
-8.367265625	0.10713668790264601	300.040329
-8.41435859375	0.108933272432524	300.0415497
-8.456523046875	0.109098226321652	300.0404663
-8.505613671875	0.10999672567518501	300.0413208
-8.572308984375	0.111504088960967	300.0415039
-8.613501171875	0.113576249569453	300.0405884
-8.6752921875	0.116411851850081	300.0414124
-8.7155078125	0.11731536037357	300.04182435
-8.763570703125	0.11765697471817299	300.04141235
-8.820446484375	0.119488117066129	300.0421448
-8.861648828125	0.120470316084029	300.04148865
-8.92929453125	0.12288443406852399	300.0411682
-8.9675796875	0.12584364092605502	300.0412292
-8.999965625	0.126667678703421	300.0419312
-8.957983984375	0.126801404209971	300.0429993
-8.913547265625	0.124548387310948	300.0437622
-8.86412421875	0.124318141513292	300.04309085
-8.815392578125	0.12229952653497	300.04408265
-8.768580859375	0.119208127584212	300.0437317
-8.704151953125	0.11779439909126199	300.0436707
-8.663159765625	0.117187602465931	300.04510495
-8.600676171875	0.115152424510845	300.0447998
-8.563598046875	0.114395173884121	300.044281
-8.501060546875	0.111766657873236	300.04245
-8.4581015625	0.108954987386708	300.0430298
-8.3965984375	0.10922711881925501	300.0422058
-8.34974140625	0.107546524815124	300.04129025
-8.292133984375	0.105696472414075	300.04104615
-8.25014296875	0.104798790978061	300.03982545
-8.18378359375	0.10200860543220801	300.03921505
-8.131041015625	0.100764598548081	300.0384827
-8.0714921875	0.09953143302450651	300.0367432
-8.032393359375	0.09787921402167	300.0364075
-7.985537109375	0.0967657822366313	300.0365753
-7.9337828125	0.09463166426415509	300.0351868
-7.886891796875	0.0924131606662303	300.0354919
-7.81955078125	0.09076821754271751	300.0357361
-7.77462734375	0.0900782383362594	300.03456115
-7.714121484375	0.0889874394434993	300.033844
-7.653578125	0.08614535949772989	300.0344849
-7.59984375	0.0839655399884388	300.03302
-7.57054765625	0.0844387183825849	300.03198245
-7.523696875	0.0821378189605437	300.03164675
-7.47291875	0.079240517786533	300.0300293
-7.428001171875	0.0778991390702551	300.02922055
-7.367471875	0.075557426542855	300.0273132
-7.33329296875	0.0734107446307776	300.0282135
-7.261048046875	0.0726474505783574	300.0285645
-7.223953125	0.0728253884265353	300.0269623
-7.17609296875	0.07179314009840139	300.026001
-7.10190859375	0.06906165865059559	300.0252075
-7.058949609375	0.0669644809821348	300.02371215
-7.010127734375	0.0670023726392822	300.0233765
-6.954476953125	0.0640940970351663	300.02290345
-6.890044921875	0.060201931679041504	300.0215149
-6.842206640625	0.0626610574542213	300.0205231
-6.790453515625	0.0600070417978892	300.0201874
-6.741646484375	0.0565419593678559	300.019104
-6.68692734375	0.056707947224853596	300.01766965
-6.637119921875	0.0553736753836987	300.0173645
-6.57073515625	0.0540268486796947	300.0153809
-6.5131380859375	0.0517685187122689	300.0144958
-6.4789646484375	0.0501721065757351	300.0147247
-6.434048046875	0.0501613756178972	300.01330565
-6.3930615234375	0.0479923288700511	300.01260375
-6.3461689453125	0.045502734381571805	300.0117798
-6.3031705078125	0.0447748048742318	300.0118103
-6.2385390625	0.0440741457743233	300.011261
-6.2003787109375	0.042493913198542996	300.01054385
-6.1602376953125	0.040545060470944604	300.01034545
-6.1093498046875	0.039467986777845805	300.0102997
-6.0584767578125	0.0377463803282762	300.0101166
-5.998766015625	0.035978870867148	300.0098267
-5.9410662109375	0.0354960626404436	300.00878905
-5.8842947265625	0.0324847392618361	300.0077209
-5.8294681640625	0.032943111316497506	300.0078735
-5.7902875	0.0296565961417386	300.0074768
-5.7472376953125	0.0281002778866225	300.00656125
-5.666995703125	0.027597336134321998	300.0049438
-5.630787109375	0.0260524250349119	300.0064087
-5.5789115234375	0.0236450554248075	300.00642395
-5.52509453125	0.022112382276130597	300.00559995
-5.472241796875	0.0210478526838408	300.00479125
-5.400801953125	0.0179854144067033	300.0035706
-5.35774375	0.0167072420167209	300.0042267
-5.3068705078125	0.0156396029757906	300.00340275
-5.25110078125	0.014203851955146	300.00256345
-5.209976953125	0.0118295417385822	300.00338745
-5.1630119140625	0.0117265779106639	300.00198365
-5.1209279296875	0.0097006317436484	300.0009766
-5.0632236328125	0.00904267931262087	300.00169375
-5.017198046875	0.0079693459311757	300.0011902
-4.9741591796875	0.005279123297434529	300.00103755
-4.930103125	0.00432583538992364	300.0007019
-4.8821146484375	0.00240913219822291	300.0003662
-4.828304296875	0.0010453232406177901	299.99905395
-4.7813205078125	0.000116139766508869	299.9979248
-4.726530859375	-0.00201525763790605	299.9981537
-4.6776044921875	-0.00282406289609641	299.99829105
-4.6169376953125	-0.0033910895835391	299.9966125
-4.5611494140625	-0.00639600190845512	299.997467
-4.508298046875	-0.00724619013464155	299.9958191
-4.4505251953125	-0.00727430314115765	299.9935913
-4.3908310546875	-0.00985718117673738	299.9940491
-4.3546126953125	-0.011911138856240799	299.9929962
-4.290029296875	-0.0131057417329981	299.9924316
-4.256750390625	-0.0140543923509122	299.9913025
-4.206851953125	-0.0147896397985164	299.99150085
-4.1354158203125	-0.0163302219748629	299.9900818
-4.086493359375	-0.018121233163125302	299.99008175
-4.0414646484375	-0.0210359257621245	299.98927305
-3.975846875	-0.0213772252238567	299.9890747
-3.9269384765625	-0.023698166609059903	299.9874573
-3.8652990234375	-0.024871388627302298	299.9868774
-3.8065744140625	-0.025602225391957903	299.9854431
-3.7693822265625	-0.028568660844518298	299.98568725
-3.710666015625	-0.0300191105541135	299.9856873
-3.6480443359375	-0.031165193915781604	299.9859619
-3.6118322265625	-0.0324573734066595	299.9859924
-3.5638576171875	-0.0334323949809643	299.9857025
-3.5149482421875	-0.034850702527823796	299.98602295
-3.458173828125	-0.0360735877462163	299.9864807
-3.4102318359375	-0.036699794135740205	299.98629765
-3.3662068359375	-0.0391148553279194	299.9861145
-3.3251041015625	-0.0397046613431373	299.9868317
-3.24680712890625	-0.0418596397473027	299.9866943
-3.20960908203125	-0.0428183716526239	299.98713685
-3.15972646484375	-0.0443056883858049	299.98727415
-3.10878466796875	-0.044990718688939	299.9877472
-3.05202548828125	-0.0468932340636815	299.9880676
-2.9962287109375	-0.0481811283099311	299.9879456
-2.93948974609375	-0.049967067798015304	299.9883423
-2.88565927734375	-0.0511998898685838	299.9871521
-2.842614453125	-0.0525606898994245	299.9884186
-2.7995484375	-0.0528799957164663	299.98771665
-2.73103828125	-0.0557567031461073	299.9878235
-2.691869140625	-0.0572039250857886	299.9880829
-2.631164453125	-0.0578093909696224	299.98791505
-2.5871345703125	-0.0589444197425406	299.98728945
-2.53134970703125	-0.06040840598024921	299.98777775
-2.46480107421875	-0.061160532995209994	299.9868774
-2.423669140625	-0.06270077982321151	299.98762515
-2.35518798828125	-0.0634893776665402	299.9873047
-2.3160453125	-0.06536620501901749	299.9862671
-2.24851904296875	-0.06653823840852201	299.9871826
-2.2152015625	-0.06723330813410751	299.98686215
-2.16529951171875	-0.06876670690842461	299.9868164
-2.11830693359375	-0.0705722710756153	299.98641965
-2.059608203125	-0.0709988693931981	299.98687745
-2.00283369140625	-0.07225526793223	299.98687745
-1.954880078125	-0.0731910533234147	299.98660275
-1.88246806640625	-0.0747003733857321	299.9873047
-1.8482162109375	-0.0760606532881145	299.98628235
-1.786547265625	-0.0763891879934435	299.9859009
-1.751325390625	-0.07836414670350911	299.9861145
-1.7034017578125	-0.07846249900267871	299.98646545
-1.65445517578125	-0.079115613559707	299.98660275
-1.59475146484375	-0.0803733801726876	299.9865112
-1.54381879882812	-0.0815991691493142	299.9876404
-1.489014453125	-0.0821572775445821	299.9865723
-1.45276474609375	-0.08313203109516179	299.9869537
-1.40085922851562	-0.0833114772644507	299.9875641
-1.35875712890625	-0.084756686903219	299.98820495
-1.3028955566406202	-0.0853568404638795	299.98887635
-1.24413266601562	-0.0868906267454337	299.98808285
-1.18635419921875	-0.0875890561945679	299.987793
-1.12759541015625	-0.0882498118620465	299.9879761
-1.07960810546875	-0.0872826387681771	299.9885254
-1.020850390625	-0.0884268293914412	299.9882507
-0.98364443359375	-0.0893323354943404	299.9885864
-0.93271357421875	-0.0898701501460039	299.98814395
-0.8748712890625	-0.0900728005917754	299.98866275
-0.8170928955078121	-0.0892845665397812	299.98931885
-0.75538251953125	-0.08944977285173179	299.9884949
-0.7132609619140621	-0.08934815303835261	299.98854065
-0.657432275390625	-0.08842242593697351	299.9874115
-0.6114179931640621	-0.0879108966904251	299.9879303
-0.538915185546875	-0.0871584371612674	299.98788455
-0.49973762207031297	-0.0857711438741033	299.9890747
-0.436981396484375	-0.0843553997611346	299.9892883
-0.40269853515625	-0.0822842259749497	299.9877472
-0.35466300048828103	-0.0806437192743083	299.98760985
-0.28311563720703103	-0.0764609849889811	299.9885864
-0.245843713378906	-0.0726465386101672	299.98825075
-0.19877670288085902	-0.0685681801251465	299.9887543
-0.148739294433594	-0.0622287462965256	299.9877472
-0.0888665649414062	-0.0563473982501894	299.9879761
-0.0309928009033203	-0.043423319090497	299.9893188
0.0179632629394531	0.00594187387490623	299.9880676
0.0540327178955078	0.035637204753314	299.98902895
0.10658414916992198	0.0532608226648882	299.98912045
0.154155816650391	0.0596208033887065	299.98846435
0.206549639892578	0.0684375711506356	299.9872894
0.268783129882813	0.0722391201377552	299.9892273
0.322634619140625	0.077109941113625	299.98854065
0.374809814453125	0.0807012157482815	299.9894409
0.43579338378906296	0.08339762363717129	299.9878235
0.4760701171875	0.0856285501707228	299.9893799
0.538834887695313	0.08717774601324069	299.9889221
0.595700512695313	0.0880464076670838	299.9881439
0.644718041992188	0.0887194734860558	299.9884796
0.6878552978515621	0.08972788395175439	299.9891968
0.739784814453125	0.0908795096269713	299.9890442
0.792708740234375	0.0905387019021134	299.9896851
0.85836884765625	0.0897259486731523	299.9906311
0.90548193359375	0.0911604765563751	299.99061585
0.9505609375	0.0899513557481617	299.9907074
1.00251567382813	0.0897492150231937	299.99026485
1.04857329101562	0.0887795470661063	299.99047855
1.09658642578125	0.08899838827294579	299.99012755
1.1475722167968798	0.0889493702412653	299.992157
1.20535502929688	0.0878430106192891	299.9943085
1.24948159179688	0.08759756421713101	299.99497985
1.3023861816406201	0.0871808379294739	299.995224
1.35042495117188	0.0855865345305193	299.99497985
1.40922880859375	0.0849981146808914	299.9966583
1.44157143554687	0.08507019028975389	299.99697875
1.4915379394531298	0.08350346744519481	299.99771115
1.54444990234375	0.08308707703389949	299.9982605
1.60031020507813	0.08260026984809071	299.9988861
1.6483052734375	0.0804087892604411	300.0007782
1.69535498046875	0.0799708824224087	300.00140385
1.761008203125	0.0785449175799096	300.0033875
1.82274384765625	0.0776128996961932	300.0039673
1.85801005859375	0.0766685732789179	300.00506595
1.90309599609375	0.0753809601722545	300.00512695
1.948139453125	0.07531718742813931	300.00616455
2.0040017578125	0.0736694715062168	300.0055847
2.048088671875	0.0723873184840852	300.00672915
2.09415068359375	0.0719346790991938	300.00717165
2.1539041015625	0.0702348763407978	300.0068665
2.21169169921875	0.0690310545537528	300.0092163
2.24800361328125	0.0677442503687334	300.00868225
2.29210654296875	0.0675971576461902	300.0080414
2.34108779296875	0.0654151376043464	300.0090485
2.39890087890625	0.064527025895705	300.0089111
2.4469041015625	0.0638277509454541	300.00976565
2.511568359375	0.0625964827142353	300.0106812
2.54879609375	0.0607849798845431	300.0110626
2.59681708984375	0.0598635159969926	300.0132446
2.64480703125	0.058867972821976804	300.01286315
2.69483681640625	0.0572283387553656	300.01301575
2.749687890625	0.0567221109550421	300.0136566
2.8006490234375	0.055845606969183004	300.01460265
2.86237724609375	0.05411663605308	300.016449
2.8947173828125	0.0532564275729167	300.0167084
2.9671841796875	0.0508316152211509	300.0171051
3.0240427734375	0.049776524193556604	300.0173035
3.06518203125	0.0489070572546247	300.01928715
3.10535078125	0.0479923467767842	300.01901245
3.14851826171875	0.0473018852785037	300.01913455
3.224998046875	0.0450758373631411	300.0204468
3.2818966796875	0.0437102422244526	300.0215454
3.32603125	0.0414194657826692	300.0207825
3.362317578125	0.041231821526326	300.02182005
3.410381640625	0.039390731412382	300.0226288
3.4584533203125	0.038408535076305005	300.022995
3.5133927734375	0.0367140241256701	300.02227785
3.585990625	0.035538676955594095	300.0241089
3.6369720703125	0.0334892539692943	300.0227966
3.692869921875	0.0327670926431834	300.02468875
3.7488001953125	0.0295678664245398	300.0242004
3.7880322265625	0.0294098142941741	300.0232391
3.83022734375	0.028134858432947198	300.02297975
3.8870986328125	0.026477142854131698	300.0231476
3.933212109375	0.0253669786546269	300.02374265
4.0077625	0.023725631544630203	300.0228882
4.050980859375	0.0223984388698684	300.02293395
4.096085546875	0.0203001472074308	300.0232544
4.14219765625	0.019793630561046303	300.0231628
4.2069306640625	0.018692624964705497	300.0206909
4.267750390625	0.0146577944415027	300.0228882
4.3040423828125	0.0150589187822513	300.02145385
4.351127734375	0.0131620536635644	300.02134705
4.4060681640625	0.0124872911796825	300.0232849
4.4541419921875	0.0110230063964458	300.0234222
4.5208978515625	0.00856400049143788	300.022583
4.560130078125	0.00806905580841982	300.0226593
4.6219466796875	0.00598675620818801	300.0237122
4.6592224609375	0.00464180629826051	300.02496335
4.720992578125	0.00232815739981492	300.0253296
4.758270703125	0.0024992676585926603	300.02482605
4.8112546875	0.000694023478352454	300.02363585
4.872055078125	-0.000666954569135481	300.0243225
4.9270271484375	-0.0031473673374884797	300.02597045
4.97213984375	-0.00407665947769271	300.0262146
5.043769921875	-0.00594402955085134	300.026947
5.08495625	-0.00747040042333793	300.0277252
5.1526572265625	-0.00898866046176975	300.02848815
5.2134646484375	-0.0103265319705461	300.028656
5.279180078125	-0.0116726291280456	300.0296326
5.33803203125	-0.0148518557560117	300.029541
5.385148828125	-0.0152952411856694	300.03045655
5.4469162109375	-0.016757577366431298	300.031311
5.4851830078125	-0.0198637964315516	300.0312805
5.5381541015625	-0.020639807051328802	300.0321808
5.59995546875	-0.0223666490743732	300.0307312
5.6411515625	-0.0232255872345215	300.0308533
5.70098671875	-0.0237436074661154	300.0323181
5.7637708984375	-0.0271892304769174	300.0326538
5.79908515625	-0.029016552658272802	300.0329285
5.8491697265625	-0.0288774613071666	300.0321655
5.898212890625	-0.0303644599567622	300.0323181
5.9600228515625	-0.0325927216785038	300.0324707
5.996304296875	-0.033778652353266395	300.03164675
6.05124609375	-0.0351144604060389	300.03234865
6.1091078125	-0.036306454065398994	300.03237915
6.1522763671875	-0.0388879940090038	300.0330658
6.2052517578125	-0.0392056625720681	300.0320587
6.2523447265625	-0.042107891365528	300.03219605
6.319069921875	-0.042126731764147995	300.0320435
6.3760216796875	-0.0448115797670882	300.0306396
6.4338216796875	-0.0456042938533013	300.0308838
6.480963671875	-0.0471468174628594	300.03125
6.518214453125	-0.050023517854621	300.0309601
6.564326953125	-0.0509972114987198	300.0298462
6.618303125	-0.05230298575256	300.03059385
6.66536484375	-0.0538616180582543	300.03105165
6.729165625	-0.056267126110446	300.0305786
6.76937734375	-0.057481933541648794	300.0311737
6.835115234375	-0.0581364641201405	300.0307312
6.888067578125	-0.0598476321988402	300.0316162
6.92142734375	-0.0608446930952058	300.03175355
6.9744078125	-0.060806501314053	300.03175355
7.02637265625	-0.06383181972744739	300.0310974
7.070543359375	-0.0654521151835869	300.03244015
7.11958359375	-0.067272749368751	300.0326996
7.184332421875	-0.0688521329238474	300.0327454
7.24317109375	-0.0702068394484522	300.0328064
7.278484375	-0.0718124886202018	300.0339203
7.344194140625	-0.0741564073652468	300.0340271
7.38051484375	-0.07529393810161171	300.0336456
7.428572265625	-0.0767602523833808	300.0344696
7.48052890625	-0.07840434556037239	300.03466795
7.5364546875	-0.0799502769349108	300.03666685
7.608117578125	-0.0809408763425257	300.0361938
7.6738390625	-0.0840539397840685	300.036377
7.717010546875	-0.0851865995147279	300.0376892
7.75919140625	-0.0864889172896244	300.037735
7.816063671875	-0.0883887484819296	300.0381317
7.87394140625	-0.0905457494357431	300.0382385
7.912192578125	-0.0933843039453071	300.03688045
7.954376171875	-0.09261586334731821	300.03817745
8.004413671875	-0.0946128882426186	300.0378113
8.050526171875	-0.0969890859879001	300.03819275
8.099615625	-0.0985611714905202	300.0378418
8.16237578125	-0.100165679419405	300.0386047
8.222218359375	-0.101205584539053	300.0390625
8.2594671875	-0.10318560756675399	300.0391235
8.303609375	-0.103987869499295	300.0390167
8.358534765625	-0.105794587816888	300.03863525
8.416428125	-0.106999543059473	300.0384827
8.4684015625	-0.108860850485444	300.0380554
8.516526171875	-0.11007291694902899	300.03790285
8.578309375	-0.11362095481232799	300.03736875
8.635212890625	-0.114510485279692	300.036438
8.66660078125	-0.114722876078119	300.0372162
8.720547265625	-0.116814023138799	300.0361023
8.769591796875	-0.119128833089298	300.0358887
8.82254140625	-0.121209309698621	300.0359497
8.879434375	-0.12163302374137	300.0350494
8.923575390625	-0.124199296252549	300.03483585
8.999958203125	-0.12653306093227898	300.03450015