File: data/doubleLayers/dl_1-25/ppms/DD205_3_HYST_10K_1OE.DAT
[Header]
; VSM Data File (default extension .dat)
; Copyright (c) 2003, Quantum Design, Inc. All rights reserved.
TITLE,
FILEOPENTIME,15654294.59,04/16/2018,9:59 pm
BYAPP,VSM,1.0,1.0
INFO,PPMS VSM Option Release 1.3.7 Build 2,APPNAME
INFO,291,COIL_SERIAL_NUMBER
INFO,0,MOMENT_UNITS
INFO,,SAMPLE_MATERIAL
INFO,,SAMPLE_COMMENT
INFO,,SAMPLE_MASS
INFO,,SAMPLE_VOLUME
INFO,,SAMPLE_MOLECULAR_WEIGHT
INFO,,SAMPLE_SIZE
INFO,,SAMPLE_SHAPE
INFO,36.06,SAMPLE_OFFSET
DATATYPE,COMMENT,1
DATATYPE,TIME,2
STARTUPAXIS,X,2
STARTUPAXIS,Y1,5
[Data]
Comment,Time Stamp (sec),Temperature (K),Magnetic Field (Oe),Moment (emu),M. Std. Err. (emu),Transport Action,Averaging Time (sec),Frequency (Hz),Peak Amplitude (mm),Center Position (mm),Coil Signal' (mV),Coil Signal" (mV),Range (mV),M. Quad. Signal (emu),M. Raw' (emu),M. Raw" (emu),Min. Temperature (K),Max. Temperature (K),Min. Field (Oe),Max. Field (Oe),Mass (grams),Motor Lag (deg),Pressure (Torr),VSM Status (code),Motor Status (code),Measure Status (code),PPMS Status (code),System Temp. (K),System Field (Oe),Sample Position (deg),Bridge 1 Resistance (ohms),Bridge 1 Excitation (에),Bridge 2 Resistance (ohms),Bridge 2 Excitation (에),Bridge 3 Resistance (ohms),Bridge 3 Excitation (에),Bridge 4 Resistance (ohms),Bridge 4 Excitation (에),Signal 1 Vin (V),Signal 2 Vin (V),Digital Inputs (code),Drive 1 Iout (mA),Drive 1 Ipower (W),Drive 2 Iout (mA),Drive 2 Ipower (W),Pressure (),Map 20 (),Map 21 (),Map 22 (),Map 23 (),Map 24 (),Map 25 (),Map 26 (),Map 27 (),Map 28 (),Map 29 ()
,15654328.155,10.0189457,-0.229214824736118,7.36369909779293E-5,2.11819520272564E-7,1,0.999253354069792,40.0298881530762,1.9909414103055,15.6900031119585,0.000795344479938498,0.000111956633821932,0.25,-2.53876507050312E-6,7.32057114101127E-5,-2.36106433283591E-6,10.0189457,10.0189457,-0.244495809078217,-0.21393384039402,51.8360401383516,18.6519167372846,2.5234809,0,0,0,4417,9.9967,-0.229214824736118,,,,,,,,,,,,,,,,,13.003003,,,,,,10.0189457,,,,
,15654420.29,10.0082617,3861.86596679687,0.000166223057468794,2.98114419782736E-7,1,0.999253354069792,40.0298881530762,1.99098508086111,15.6900031119585,0.0017881888236623,0.000294175925049106,0.25,-1.89353939164227E-6,0.000165249502117597,-1.49344988777779E-6,10.0082102,10.0083132,3834.44580078125,3889.2861328125,52.4160084996209,18.6632095622393,2.6133063,0,0,0,4449,9.9918,3861.86596679687,,,,,,,,,,,,,,,,,13.378378,,,,,,10.0082617,,,,
,15654497.69,10.00521615,7727.46411132813,0.000194634217255683,2.55606972462284E-7,1,0.999253354069792,40.0298881530762,1.99105876039424,15.6900031119585,0.00209275944899103,0.00035181360820442,0.25,-1.56828833605503E-6,0.000193506249980118,-1.07103216413917E-6,10.0051575,10.0052748,7699.92626953125,7755.001953125,51.9509395306786,18.6617040830796,2.69281135,0,0,0,4449,9.98735,7727.46411132813,,,,,,,,,,,,,,,,,13.378378,,,,,,10.00521615,,,,
,15654577.54,10.00427535,11718.2465820312,0.000194122454202832,3.71309841767845E-7,1,0.999253354069792,40.0298881530762,1.99102127075521,15.6900031119585,0.00208744991693114,0.000350623794111481,0.25,-1.62794671799514E-6,0.000193014092326223,-1.09503725859558E-6,10.00418,10.0043707,11693.3759765625,11743.1171875,52.1041387204478,18.6649742229145,2.7471541,0,0,0,4449,9.98605,11718.2465820312,,,,,,,,,,,,,,,,,13.003003,,,,,,10.00427535,,,,
,15654656.39,10.00332545,15659.1533203125,0.000190863594477805,2.57884752453995E-7,1,0.999253354069792,40.0298881530762,1.99104464170238,15.6900031119585,0.00205146859258319,0.000351331355801706,0.25,-1.02755998722474E-6,0.000189790432811345,-4.69615700231051E-7,10.0033054,10.0033455,15631.6943359375,15686.6123046875,52.4394573551979,18.665368022334,2.816592,0,0,0,4449,9.9846,15659.1533203125,,,,,,,,,,,,,,,,,13.378378,,,,,,10.00332545,,,,
,15654736.015,10.0024261,19637.021484375,0.000186085736115672,3.51773591762168E-7,1,0.999253354069792,40.0298881530762,1.99101941613128,15.6900031119585,0.00200013591807326,0.000343538471191141,0.25,-9.49485579477944E-7,0.000185059219067842,-3.68184332616005E-7,10.0023746,10.0024776,19609.4453125,19664.59765625,52.3269028484286,18.6664026128261,2.8734326,0,0,0,4449,9.98365,19637.021484375,,,,,,,,,,,,,,,,,13.378378,,,,,,10.0024261,,,,
,15654814.775,10.00140955,23575.4130859375,0.000180729650832982,3.27603451539432E-7,1,0.999253354069792,40.0298881530762,1.99118149724241,15.6900031119585,0.00194142470205344,0.000342292462341236,0.25,-1.60425858307594E-7,0.000179751269027886,4.36615103453187E-7,10.0013237,10.0014954,23547.814453125,23603.01171875,52.3644210173517,18.66774349345,2.8735762,0,0,0,4449,9.98275,23575.4130859375,,,,,,,,,,,,,,,,,13.003003,,,,,,10.00140955,,,,
,15654892.675,10.00150585,27468.5751953125,0.000175938131771461,4.65215956998444E-7,1,0.999253354069792,40.0298881530762,1.99112344603968,15.6900031119585,0.00189358154460645,0.000313852949410532,0.25,-1.99757533866768E-6,0.0001750140691804,-1.37125612985425E-6,10.0013609,10.0016508,27436.03515625,27501.115234375,52.2151299701786,18.6685649437812,2.9314206,0,0,0,4449,9.98305,27468.5751953125,,,,,,,,,,,,,,,,,13.378378,,,,,,10.00150585,,,,
,15654969.715,10.0006924,31319.08203125,0.000169972436552648,4.72488993443547E-7,1,0.999253354069792,40.0298881530762,1.9910436481965,15.6900031119585,0.00182835570193104,0.000309988867964303,0.25,-1.3353245058189E-6,0.000169100438387062,-6.99967883308894E-7,10.0006142,10.0007706,31293.98828125,31344.17578125,52.6317379709286,18.6667518182149,2.9314206,0,0,0,4449,9.982,31319.08203125,,,,,,,,,,,,,,,,,13.378378,,,,,,10.0006924,,,,
,15655046.35,10.00055695,35149.28125,0.000161965175477382,5.93020149943188E-7,1,0.999253354069792,40.0298881530762,1.99098876144309,15.6900031119585,0.00173985601514492,0.000309887965684569,0.25,4.28078637189913E-8,0.000161152214531556,6.72891879312675E-7,10.0005074,10.0006065,35116.76953125,35181.79296875,52.1948076286786,18.6699541606586,3.0509303,0,0,0,4449,9.98155,35149.28125,,,,,,,,,,,,,,,,,12.252253,,,,,,10.00055695,,,,
,15655124.255,10.0003376,39042.5859375,0.000155743614035433,5.21291383242063E-7,1,0.999253354069792,40.0298881530762,1.9910313853511,15.6900031119585,0.00167579478293465,0.000284100024315978,0.25,-1.28611526344644E-6,0.000154990970858568,-6.43620511173794E-7,10.000329,10.0003462,39015.02734375,39070.14453125,52.4980794941402,18.6697370470477,3.0510825,0,0,0,4449,9.98105,39042.5859375,,,,,,,,,,,,,,,,,13.003003,,,,,,10.0003376,,,,
,15655202.56,10.00042725,42956.115234375,0.000149225074162513,6.6503874924427E-7,1,0.999253354069792,40.0298881530762,1.99118322635212,15.6900031119585,0.00160751611476458,0.000263963323241771,0.25,-2.03395091269242E-6,0.000148531643848981,-1.38645263658923E-6,10.0004253,10.0004292,42928.59375,42983.63671875,52.4652510963325,18.6686409125081,3.1281246,0,0,0,4449,9.9809,42956.115234375,,,,,,,,,,,,,,,,,13.378378,,,,,,10.00042725,,,,
,15655282.435,10.0003052,46949.126953125,0.000140910014247744,7.49935141918218E-7,1,0.999253354069792,40.0298881530762,1.99112562721489,15.6900031119585,0.0015144593693224,0.000270085899665887,0.25,-1.23450503912348E-8,0.000140271374442428,6.16550876099885E-7,10.0001936,10.0004168,46926.4375,46971.81640625,52.6418991416786,18.6687935743447,3.15953075,0,0,0,4449,9.98025,46949.126953125,,,,,,,,,,,,,,,,,13.753754,,,,,,10.0003052,,,,
,15655359.995,10.0002813,50827.654296875,0.000133313766890211,7.36659822152228E-7,1,0.999253354069792,40.0298881530762,1.99120888503928,15.6900031119585,0.00143539530961885,0.000242877688558466,0.25,-1.21689820749152E-6,0.000132738442291043,-5.93200798953277E-7,10.0002813,10.0002813,50825.1796875,50830.12890625,53.0428745720441,18.6694758509819,3.1125,0,0,0,4449,9.98035,50827.654296875,,,,,,,,,,,,,,,,,12.252253,,,,,,10.0002813,,,,
,15655438.33,10.0005131,54742.791015625,0.000122374798164183,7.49047279189546E-7,1,0.999253354069792,40.0298881530762,1.99109868501432,15.6900031119585,0.00131824371421512,0.000220448233825935,0.25,-1.37324343882237E-6,0.000121870488288067,-7.78993774097959E-7,10.0005131,10.0005131,54737.828125,54747.75390625,52.2581195387363,18.6668739577859,3.2393923,0,0,0,4449,9.9794,54742.791015625,,,,,,,,,,,,,,,,,13.003003,,,,,,10.0005131,,,,
,15655517.195,10.0009441,58683.556640625,0.000114346833223304,8.95598683746082E-7,1,0.999253354069792,40.0298881530762,1.99141623176172,15.6900031119585,0.00122884798561037,0.000224725128064309,0.25,4.34030114911914E-7,0.000113889010864161,1.00094561178132E-6,10.0009441,10.0009441,58680.96875,58686.14453125,52.5731158319863,18.6626905057679,3.2719154,0,0,0,4449,9.9797,58683.556640625,,,,,,,,,,,,,,,,,13.378378,,,,,,10.0009441,,,,
,15655593.7,9.99973535,62506.4765625,0.000104546649070386,7.60156441332632E-7,1,0.999253354069792,40.0298881530762,1.99141652275467,15.6900031119585,0.00112706985835147,0.000186927862659081,0.25,-1.34601870998052E-6,0.000104156739269713,-8.05205087866625E-7,9.9996481,9.9998226,62474.0390625,62538.9140625,52.1697955160632,18.6617934991125,3.27207875,0,0,0,4449,9.98005,62506.4765625,,,,,,,,,,,,,,,,,13.378378,,,,,,9.99973535,,,,
,15655670.81,9.9991822,66360.109375,9.77239305819047E-5,1.04091090438528E-6,1,0.999253354069792,40.0298881530762,1.99148340311121,15.6900031119585,0.00104929288728597,0.00019968860346276,0.25,1.04416137758003E-6,9.73666049222681E-5,1.55523147656333E-6,9.999114,9.9992504,66337.734375,66382.484375,52.4550899255825,18.6627853164689,3.3379447,0,0,0,4449,9.9808,66360.109375,,,,,,,,,,,,,,,,,12.252253,,,,,,9.9991822,,,,
,15655747.345,9.99746945,70185.70703125,8.89951864908681E-5,1.1684957841268E-6,1,0.999253354069792,40.0298881530762,1.99151878298017,15.6900031119585,0.000963801014569359,0.000137149079092115,0.25,-3.2192458993863E-6,8.87097625753949E-5,-2.72745922339472E-6,9.9973221,9.9976168,70150.78125,70220.6328125,52.4589980681786,18.662926599301,3.3883821,0,0,0,4449,9.98245,70185.70703125,,,,,,,,,,,,,,,,,13.003003,,,,,,9.99746945,,,,
,15655824.25,9.99835445,74028.86328125,7.88704248161714E-5,9.79886925522645E-7,1,0.999253354069792,40.0298881530762,1.99137496804849,15.6900031119585,0.000845429184775324,0.000170812273651263,0.25,1.71361632340364E-6,7.86084753314431E-5,2.14425751207677E-6,9.9983301,9.9983788,73998.9921875,74058.734375,52.5793688601402,18.6633449205165,3.35470115,0,0,0,4449,9.98375,74028.86328125,,,,,,,,,,,,,,,,,12.252253,,,,,,9.99835445,,,,
,15655901.05,9.999876,77869.5859375,6.90891246291476E-5,1.27261541256415E-6,1,0.999253354069792,40.0298881530762,1.99144613281735,15.6900031119585,0.000745033322600165,0.000125855982484201,0.25,-7.18911794899511E-7,6.88861005344763E-5,-3.2656609971295E-7,9.9996624,10.0000896,77847.0390625,77892.1328125,52.3839617303325,18.6627402314218,3.4394958,0,0,0,4449,9.98345,77869.5859375,,,,,,,,,,,,,,,,,13.378378,,,,,,9.999876,,,,
,15655977.895,9.9987068,81708.05078125,6.35113606403881E-5,1.11832119596848E-6,1,0.999253354069792,40.0298881530762,1.99151876369197,15.6900031119585,0.000683395937662172,0.000124927658771824,0.25,1.87201221449029E-7,6.33329640012074E-5,5.52303621340809E-7,9.9987068,9.9987068,81690.6328125,81725.46875,52.4589980681786,18.66414672646,3.4394958,0,0,0,4449,9.9841,81708.05078125,,,,,,,,,,,,,,,,,13.003003,,,,,,9.9987068,,,,
,15656055.62,9.99821235,85593.5625,5.06359260368809E-5,1.0792065789759E-6,1,0.999253354069792,40.0298881530762,1.99133012963973,15.6900031119585,0.000556926902691422,3.28537273281904E-5,0.25,-6.05624385619085E-6,5.05406244082641E-5,-5.74394963655742E-6,9.9981718,9.9982529,85568.6015625,85618.5234375,52.6145421435056,18.6625479585534,3.45710685,0,0,0,4449,9.9854,85593.5625,,,,,,,,,,,,,,,,,13.378378,,,,,,9.99821235,,,,
,15656133.11,9.99811555,89465.75,4.54302880179659E-5,1.00020473796647E-6,1,0.999253354069792,40.0298881530762,1.99121531651129,15.6900031119585,0.000494965838627141,5.60947157643709E-5,0.25,-2.96642313567351E-6,4.53400995295856E-5,-2.68902181371836E-6,9.9980936,9.9981375,89435.6484375,89495.8515625,52.5223099782363,18.6634646543346,3.52652155,0,0,0,4449,9.9863,89465.75,,,,,,,,,,,,,,,,,13.378378,,,,,,9.99811555,,,,
,15656225.33,9.9993882,86815.24609375,5.08223210571668E-5,1.04392225279049E-6,1,0.999253354069792,40.0298881530762,1.99123738852863,15.6900031119585,0.000549395684388655,8.63166694523251E-5,0.25,-1.12603852623726E-6,5.07010375546254E-5,-8.23928284130984E-7,9.9993801,9.9993963,86792.71875,86837.7734375,52.5707709464286,18.6669738663667,3.56192755,0,0,0,4449,9.9864,86815.24609375,,,,,,,,,,,,,,,,,12.252253,,,,,,9.9993882,,,,
,15656303.555,10.00082635,82907.234375,5.70931881921272E-5,7.85746281529676E-7,1,0.999253354069792,40.0298881530762,1.99124226777733,15.6900031119585,0.000618226066233898,9.04274644724619E-5,0.25,-1.86492860295899E-6,5.69482638135113E-5,-1.52931953207243E-6,10.0006332,10.0010195,82884.765625,82929.703125,52.3292477339863,18.6670893614022,3.5797191,0,0,0,4449,9.98485,82907.234375,,,,,,,,,,,,,,,,,13.378378,,,,,,10.00082635,,,,
,15656380.155,10.002048,79076.37890625,7.1700558627022E-5,9.22467171736392E-7,1,0.999253354069792,40.0298881530762,1.99122010626311,15.6900031119585,0.000774974227700669,0.000120520633223058,0.25,-1.68578590691079E-6,7.14998460609864E-5,-1.27337335059359E-6,10.0018806,10.0022154,79046.4375,79106.3203125,52.656750083544,18.6632081111644,3.615659,0,0,0,4449,9.9832,79076.37890625,,,,,,,,,,,,,,,,,13.003003,,,,,,10.002048,,,,
,15656459.89,10.0024233,75090.7421875,8.24266040991743E-5,9.44164572682177E-7,1,0.999253354069792,40.0298881530762,1.99124189360096,15.6900031119585,0.000888703097420445,0.000149771166370245,0.25,-8.8274838279517E-7,8.21722832811101E-5,-4.21420385833331E-7,10.0023937,10.0024529,75063.203125,75118.28125,52.5434139482555,18.6638743350753,3.5443131,0,0,0,4449,9.9826,75090.7421875,,,,,,,,,,,,,,,,,13.003003,,,,,,10.0024233,,,,
,15656539.195,10.00180675,71127.89453125,9.24164766095921E-5,9.66324110926797E-7,1,0.999253354069792,40.0298881530762,1.99118053156547,15.6900031119585,0.0010008467479261,0.000141829358038911,0.25,-3.39953478641057E-6,9.21250349641119E-5,-2.88587102850445E-6,10.0017605,10.001853,71100.34375,71155.4453125,52.6887968528325,18.6690436673737,3.6519601,0,0,0,4449,9.9808,71127.89453125,,,,,,,,,,,,,,,,,13.378378,,,,,,10.00180675,,,,
,15656616.54,10.0015726,67262.50390625,0.000101667296746635,6.79378123906444E-7,1,0.999253354069792,40.0298881530762,1.99118637848965,15.6900031119585,0.00109554980293552,0.000185312201609146,0.25,-1.00075554250531E-6,0.000101311286286912,-4.5828754756884E-7,10.0015669,10.0015783,67232.65625,67292.3515625,52.6981763950633,18.662746625598,3.61638065,0,0,0,4449,9.97865,67262.50390625,,,,,,,,,,,,,,,,,13.378378,,,,,,10.0015726,,,,
,15656694.695,10.0022235,63356.482421875,0.000107768536282808,6.26238603026629E-7,1,0.999253354069792,40.0298881530762,1.99119496603908,15.6900031119585,0.00116543188312668,0.000172024430821956,0.25,-3.31123928495419E-6,0.000107381179589583,-2.74309580981619E-6,10.002183,10.002264,63323.90625,63389.05859375,52.504332522294,18.6650002584138,3.6519601,0,0,0,4449,9.9775,63356.482421875,,,,,,,,,,,,,,,,,13.378378,,,,,,10.0022235,,,,
,15656773.045,10.0022769,59440.59765625,0.000116481036357091,7.20131888650575E-7,1,0.999253354069792,40.0298881530762,1.9911804228748,15.6900031119585,0.0012595208241996,0.000185154187357495,0.25,-3.62984376789114E-6,0.000116039355472177,-3.03269734499398E-6,10.0022755,10.0022783,59415.57421875,59465.62109375,52.5629546612363,18.6678770420936,3.6886253,0,0,0,4449,9.9763,59440.59765625,,,,,,,,,,,,,,,,,13.378378,,,,,,10.0022769,,,,
,15656851.265,10.0022249,55529.25390625,0.000125285073290409,6.09317087874512E-7,1,0.999253354069792,40.0298881530762,1.99117553034612,15.6900031119585,0.00135116867010622,0.000217463062333588,0.25,-2.17691880944019E-6,0.000124777245570856,-1.56122275546364E-6,10.0021877,10.0022621,55496.7578125,55561.75,52.4801020381979,18.6691321195251,3.7071421,0,0,0,4449,9.97385,55529.25390625,,,,,,,,,,,,,,,,,13.003003,,,,,,10.0022249,,,,
,15656932.85,10.00188395,51451.390625,0.000136429173104417,4.94556916179128E-7,1,0.999253354069792,40.0298881530762,1.99116454655526,15.6900031119585,0.00147074663504377,0.000238504364221253,0.25,-2.18413875092367E-6,0.000135848736672405,-1.53806475239202E-6,10.0017967,10.0019712,51418.95703125,51483.82421875,52.372237302544,18.6677037124031,3.74436165,0,0,0,4449,9.9729,51451.390625,,,,,,,,,,,,,,,,,13.378378,,,,,,10.00188395,,,,
,15657013.54,10.0008984,47418.404296875,0.000143351761305624,5.32449757941703E-7,1,0.999253354069792,40.0298881530762,1.99127910339927,15.6900031119585,0.00154518601080746,0.000250476130354358,0.25,-2.27789893250818E-6,0.00014271519215573,-1.62478264861609E-6,10.0006781,10.0011187,47390.93359375,47445.875,52.3355007621402,18.6701834739293,3.70751225,0,0,0,4449,9.97155,47418.404296875,,,,,,,,,,,,,,,,,13.378378,,,,,,10.0008984,,,,
,15657090.57,10.00208755,43569.9453125,0.000150611479264825,5.7237790941491E-7,1,0.999253354069792,40.0298881530762,1.99122646753481,15.6900031119585,0.00162383636069228,0.000259086228093975,0.25,-2.74044844583497E-6,0.000149918542290899,-2.079361732074E-6,10.0019693,10.0022058,43537.41796875,43602.47265625,52.6856703387556,18.6715623993175,3.6888095,0,0,0,4449,9.9709,43569.9453125,,,,,,,,,,,,,,,,,13.003003,,,,,,10.00208755,,,,
,15657168.825,10.0009508,39656.552734375,0.000158240880849053,4.59086837602131E-7,1,0.999253354069792,40.0298881530762,1.99119678904393,15.6900031119585,0.00170714396923746,0.000264524416639816,0.25,-3.56003725758829E-6,0.000157489397104447,-2.89159753401417E-6,10.0009508,10.0009508,39653.96875,39659.13671875,52.6887968528325,18.6693780227626,3.7447352,0,0,0,4449,9.9694,39656.552734375,,,,,,,,,,,,,,,,,12.252253,,,,,,10.0009508,,,,
,15657248.045,10.00139665,35698.666015625,0.000166599660195041,3.89410166164164E-7,1,0.999253354069792,40.0298881530762,1.99125880781137,15.6900031119585,0.00179436653378687,0.000293731171493112,0.25,-2.29405443982478E-6,0.000165776085591988,-1.62966304248696E-6,10.0012264,10.0015669,35671.02734375,35726.3046875,52.8623183841017,18.6654115758214,3.78195475,0,0,0,4449,9.969,35698.666015625,,,,,,,,,,,,,,,,,13.003003,,,,,,10.00139665,,,,
,15657326.86,10.00130605,31761.197265625,0.000171710071180745,3.77120357702845E-7,1,0.999253354069792,40.0298881530762,1.99127458138415,15.6900031119585,0.00184920863163967,0.000302335616101539,0.25,-2.3638896664271E-6,0.000170835680766193,-1.71296582062794E-6,10.0012188,10.0013933,31728.6015625,31793.79296875,52.4285145559286,18.6705913088617,3.78195475,0,0,0,4449,9.96735,31761.197265625,,,,,,,,,,,,,,,,,13.378378,,,,,,10.00130605,,,,
,15657404.11,10.0015192,27900.423828125,0.00017984994070691,3.52779533114542E-7,1,0.999253354069792,40.0298881530762,1.99132510117388,15.6900031119585,0.00193471123227285,0.000327548679931186,0.25,-1.42396462036877E-6,0.000178905793514283,-7.83008089990481E-7,10.0013971,10.0016413,27865.494140625,27935.353515625,52.6450256557556,18.6691714743619,3.8008451,0,0,0,4449,9.96585,27900.423828125,,,,,,,,,,,,,,,,,12.252253,,,,,,10.0015192,,,,
,15657481.78,10.0010986,24014.7216796875,0.0001839545233456,4.43130177922353E-7,1,0.999253354069792,40.0298881530762,1.99127284188454,15.6900031119585,0.00197972344268662,0.000328425158340714,0.25,-2.02902428969947E-6,0.000182967377331273,-1.40707455302E-6,10.0010099,10.0011873,23987.181640625,24042.26171875,52.8552837274287,18.670025306545,3.8008451,0,0,0,4449,9.96695,24014.7216796875,,,,,,,,,,,,,,,,,12.252253,,,,,,10.0010986,,,,
,15657560.69,10.0007796,20071.509765625,0.000189512319941816,3.25399430949834E-7,1,0.999253354069792,40.0298881530762,1.99128697276514,15.7000036537647,0.00203974681609253,0.000335810189596168,0.25,-2.28431154619425E-6,0.000188473351680805,-1.68081483174397E-6,10.0005884,10.0009708,20043.978515625,20099.041015625,52.7396027065825,18.6713035634677,3.8199253,0,0,0,4449,9.9661,20071.509765625,,,,,,,,,,,,,,,,,13.378378,,,,,,10.0007796,,,,
,15657642.805,10.00003765,15968.8994140625,0.000194749122510501,2.85254489262648E-7,1,0.999253354069792,40.0298881530762,1.99138125474531,15.6900031119585,0.00209584446505834,0.00034574950597534,0.25,-2.24281127701525E-6,0.000193659135841844,-1.66374650767951E-6,9.9998989,10.0001764,15961.4580078125,15976.3408203125,53.0350582868518,18.6679956376546,3.8390055,0,0,0,4449,9.9659,15968.8994140625,,,,,,,,,,,,,,,,,12.627627,,,,,,10.00003765,,,,
,15657726.615,9.99902295,11778.1733398438,0.000198184451873743,2.51905237399132E-7,1,0.999253354069792,40.0298881530762,1.99132609972848,15.6900031119585,0.00213232875706071,0.000352982138899399,0.25,-2.13104013432255E-6,0.000197054436661057,-1.58371473609746E-6,9.9988966,9.9991493,11758.396484375,11797.9501953125,53.0006666320056,18.671281564802,3.82030655,0,0,0,4449,9.9647,11778.1733398438,,,,,,,,,,,,,,,,,12.252253,,,,,,9.99902295,,,,
,15657804.145,9.9999323,7904.80834960937,0.000199332954858123,2.87454896360709E-7,1,0.999253354069792,40.0298881530762,1.99124806407604,15.6900031119585,0.00214417146311127,0.00035642844310635,0.25,-1.97209409636537E-6,0.000198179376908548,-1.45909016764671E-6,9.9998951,9.9999695,7879.6240234375,7929.99267578125,52.7122457084094,18.6695547586544,3.8582771,0,0,0,4449,9.9663,7904.80834960937,,,,,,,,,,,,,,,,,13.378378,,,,,,9.9999323,,,,
,15657882.845,9.99960375,3968.23461914063,0.000171522809594953,2.47339251499555E-7,1,0.999253354069792,40.0298881530762,1.99125719223913,15.6900031119585,0.00184504623501809,0.000305848542525661,0.25,-1.74477477800874E-6,0.000170518022780709,-1.33242096851414E-6,9.9994936,9.9997139,3940.80395507812,3995.66528320313,52.7036477946979,18.6730106175425,3.8390055,0,0,0,4449,9.96645,3968.23461914063,,,,,,,,,,,,,,,,,13.378378,,,,,,9.99960375,,,,
,15657960.545,10.00007865,87.0419940948486,8.61019351977238E-5,3.09185739656043E-7,1,0.999253354069792,40.0298881530762,1.99121839755178,15.6900031119585,0.000928375082056743,0.000140717471027263,0.25,-2.05665426239116E-6,8.55956853311702E-5,-1.85416434835725E-6,9.9999666,10.0001907,57.3899955749512,116.693992614746,52.5668628038325,18.6731145075667,3.8775487,0,0,0,4449,9.9658,87.0419940948486,,,,,,,,,,,,,,,,,12.252253,,,,,,10.00007865,,,,
,15658039.235,10.00032565,-3844.24951171875,-1.84717587042696E-5,3.14265150341978E-7,1,0.999253354069792,40.0298881530762,1.99131412839963,15.6900031119585,-0.000193361098793002,-6.32503571642306E-5,0.25,-2.63508452741911E-6,-1.83569097703074E-5,-2.66278936229048E-6,10.0001678,10.0004835,-3871.78271484375,-3816.71630859375,52.4785387811594,18.6741405425712,3.8582771,0,0,0,4449,9.9658,-3844.24951171875,,,,,,,,,,,,,,,,,13.378378,,,,,,10.00032565,,,,
,15658122.78,10.0004034,-8018.22802734375,-5.1722983738667E-5,2.16927630392273E-7,1,0.999253354069792,40.0298881530762,1.9912885701642,15.6900031119585,-0.000550404645693831,-0.000126371161702427,0.25,-2.64337618529024E-6,-5.14158148887874E-5,-2.75842874257068E-6,10.0003719,10.0004349,-8045.87353515625,-7990.58251953125,52.9428261215825,18.671664572803,3.8775487,0,0,0,4449,9.96495,-8018.22802734375,,,,,,,,,,,,,,,,,13.378378,,,,,,10.0004034,,,,
,15658204.89,10.001297,-12121.291015625,-5.73352368475907E-5,3.15622968194252E-7,1,0.999253354069792,40.0298881530762,1.99118584068052,15.7000036537647,-0.000610823419613895,-0.00013624390286612,0.25,-2.56099401751724E-6,-5.70001422226828E-5,-2.70210799228581E-6,10.0012455,10.0013485,-12153.6474609375,-12088.9345703125,52.1916811146017,18.6764490888801,3.8970139,0,0,0,4449,9.96405,-12121.291015625,,,,,,,,,,,,,,,,,13.378378,,,,,,10.001297,,,,
,15658285.445,10.000515,-16149.7666015625,-6.73617391097754E-5,2.76279102009204E-7,1,0.999253354069792,40.0298881530762,1.99112076270496,15.6900031119585,-0.000718192309420479,-0.000157200522809585,0.25,-2.7271875954869E-6,-6.69748216562297E-5,-2.90838595536944E-6,10.0005074,10.0005226,-16172.2939453125,-16127.2392578125,52.687233595794,18.6729976405123,3.8970139,0,0,0,4449,9.9638,-16149.7666015625,,,,,,,,,,,,,,,,,13.003003,,,,,,10.000515,,,,
,15658364.845,9.9998455,-20117.326171875,-8.40969653021294E-5,3.7039362839381E-7,1,0.999253354069792,40.0298881530762,1.99113166985033,15.6900031119585,-0.000897099668217478,-0.000194092370215065,0.25,-3.18428169141764E-6,-8.3622931265327E-5,-3.42911609416663E-6,9.9998455,9.9998455,-20119.81640625,-20114.8359375,52.8912386393133,18.6721692016259,3.8775487,0,0,0,4449,9.964,-20117.326171875,,,,,,,,,,,,,,,,,13.003003,,,,,,9.9998455,,,,
,15658446.78,10.00007965,-24212.5146484375,-0.000107130784149575,4.01706134809232E-7,1,0.999253354069792,40.0298881530762,1.9912427707044,15.6900031119585,-0.0011451801177177,-0.000235015493159604,0.25,-2.89044529448464E-6,-0.000106542997205805,-3.23176622065557E-6,10.0000439,10.0001154,-24242.55078125,-24182.478515625,52.4472736403902,18.6728648216179,3.9164791,0,0,0,4449,9.96405,-24212.5146484375,,,,,,,,,,,,,,,,,12.252253,,,,,,10.00007965,,,,
,15658526.46,9.9982958,-28193.1591796875,-0.00012649392403939,3.69224099927482E-7,1,0.999253354069792,40.0298881530762,1.99133384468713,15.6900031119585,-0.00135201219835422,-0.000279672103375373,0.25,-3.58529545213634E-6,-0.000125814912592409,-4.01383504805186E-6,9.9981947,9.9983969,-28200.65625,-28185.662109375,52.6067258583133,18.6728409245445,3.8390055,0,0,0,4449,9.9643,-28193.1591796875,,,,,,,,,,,,,,,,,12.252253,,,,,,9.9982958,,,,
,15658607.225,9.99875255,-32230.7783203125,-0.000139328619218794,4.45625423625737E-7,1,0.999253354069792,40.0298881530762,1.99130438423373,15.6900031119585,-0.00148797141655535,-0.000315997076443601,0.25,-4.65645007818332E-6,-0.000138596914096882,-5.15421675153484E-6,9.9985847,9.9989204,-32258.349609375,-32203.20703125,52.7372578210248,18.6720575138395,3.8586621,0,0,0,4449,9.9648,-32230.7783203125,,,,,,,,,,,,,,,,,13.003003,,,,,,9.99875255,,,,
,15658685.94,9.9996653,-36165.953125,-0.000141896035484902,5.44574890150722E-7,1,0.999253354069792,40.0298881530762,1.99118424234948,15.6900031119585,-0.0015186157361882,-0.000304440635406847,0.25,-3.09384816569395E-6,-0.00014117727214883,-3.63787119590454E-6,9.9996653,9.9996653,-36185.984375,-36145.921875,52.7575801625248,18.6758309816773,3.8390055,0,0,0,4449,9.9645,-36165.953125,,,,,,,,,,,,,,,,,13.003003,,,,,,9.9996653,,,,
,15658764.985,9.9999537,-40115.814453125,-0.000143427132023936,4.96128691158687E-7,1,0.999253354069792,40.0298881530762,1.99118714041614,15.6900031119585,-0.00153485343666625,-0.000309945690332098,0.25,-3.30133805620727E-6,-0.000142721733666809,-3.87887668525292E-6,9.9997005,10.0002069,-40148.26171875,-40083.3671875,52.8185471870248,18.6775987526612,3.9164791,0,0,0,4449,9.965,-40115.814453125,,,,,,,,,,,,,,,,,13.003003,,,,,,9.9999537,,,,
,15658845.665,10.0001459,-44146.36328125,-0.000140308221859875,6.26085494912875E-7,1,0.999253354069792,40.0298881530762,1.99123172721637,15.7000036537647,-0.00150045544555555,-0.000310564834954731,0.25,-3.88179799131694E-6,-0.000139638336387342,-4.47148481350078E-6,10.0000992,10.0001926,-44176.35546875,-44116.37109375,52.4277329274094,18.6728780729599,3.9558001,0,0,0,4449,9.9647,-44146.36328125,,,,,,,,,,,,,,,,,13.378378,,,,,,10.0001459,,,,
,15658923.885,9.999002,-48054.15625,-0.000135581093256679,5.23969620000073E-7,1,0.999253354069792,40.0298881530762,1.99123053008233,15.6900031119585,-0.00144845896618724,-0.000309602275602826,0.25,-4.60556544807581E-6,-0.000134952421116604,-5.19686258839532E-6,9.998971,9.999033,-48079.203125,-48029.109375,52.934228207871,18.67424387002,3.8974028,0,0,0,4449,9.9655,-48054.15625,,,,,,,,,,,,,,,,,12.252253,,,,,,9.999002,,,,
,15659001.7,9.99936005,-51944.689453125,-0.000129426130214827,6.34272883243657E-7,1,0.999253354069792,40.0298881530762,1.99135117479509,15.6900031119585,-0.0013819982770585,-0.000301342265331455,0.25,-4.90658845221634E-6,-0.000128845772366757,-5.49221304658311E-6,9.9993343,9.9993858,-51972.16015625,-51917.21875,52.7700862188325,18.6714559287344,3.9365324,0,0,0,4449,9.96535,-51944.689453125,,,,,,,,,,,,,,,,,13.378378,,,,,,9.99936005,,,,
,15659083.73,9.9993896,-56044.44921875,-0.000120605818391594,7.38592696598183E-7,1,0.999253354069792,40.0298881530762,1.99124869297981,15.6900031119585,-0.00128444753409719,-0.00030068790648293,0.25,-6.39645195859735E-6,-0.00012007867291289,-6.95678765053008E-6,9.9993896,9.9993896,-56069.44140625,-56019.45703125,52.9506424067748,18.6758757931354,3.8974028,0,0,0,4449,9.96665,-56044.44921875,,,,,,,,,,,,,,,,,13.378378,,,,,,9.9993896,,,,
,15659163.75,9.9987316,-60042.458984375,-0.000110695977300143,6.9875063185217E-7,1,0.999253354069792,40.0298881530762,1.99123786646263,15.6900031119585,-0.0011836564281969,-0.00025070846412973,0.25,-3.49792994364974E-6,-0.000110244670287074,-4.04075948855805E-6,9.9987316,9.9987316,-60047.4453125,-60037.47265625,53.0233338590633,18.6750505544956,3.9166744,0,0,0,4449,9.9676,-60042.458984375,,,,,,,,,,,,,,,,,13.378378,,,,,,9.9987316,,,,
,15659240.48,9.99877075,-63878.123046875,-0.000102346801337984,8.17345060039776E-7,1,0.999253354069792,40.0298881530762,1.99118862350174,15.6900031119585,-0.00109132351935447,-0.00024990518908993,0.25,-4.89883011186269E-6,-0.000101940053183106,-5.41035568140026E-6,9.9987555,9.998786,-63900.61328125,-63855.6328125,52.3870882444094,18.6730329170743,3.8775487,0,0,0,4449,9.96845,-63878.123046875,,,,,,,,,,,,,,,,,13.003003,,,,,,9.99877075,,,,
,15659321.735,9.9995165,-67938.41796875,-9.3225900458802E-5,8.18202088378104E-7,1,0.999253354069792,40.0298881530762,1.99122202814429,15.6900031119585,-0.000994394129628121,-0.000227068337468295,0.25,-4.39122577147985E-6,-9.28744477458404E-5,-4.87218177926753E-6,9.9995165,9.9995165,-67943.390625,-67933.4453125,52.893583524871,18.6766909309695,3.9558001,0,0,0,4449,9.9686,-67938.41796875,,,,,,,,,,,,,,,,,13.003003,,,,,,9.9995165,,,,
,15659400.89,9.99907925,-71895.9296875,-8.63170395096263E-5,8.59207662751308E-7,1,0.999253354069792,40.0298881530762,1.99112170495408,15.6900031119585,-0.000916281698713427,-0.000235684514837261,0.25,-6.41606592567496E-6,-8.59960116772421E-5,-6.86613164486297E-6,9.99895,9.9992085,-71925.90625,-71865.953125,52.8396511570441,18.6768810140237,3.9957154,0,0,0,4449,9.96955,-71895.9296875,,,,,,,,,,,,,,,,,13.003003,,,,,,9.99907925,,,,
,15659478.01,9.9988079,-75748.17578125,-7.95386538883913E-5,9.66658906459319E-7,1,0.999253354069792,40.0298881530762,1.99125727170782,15.6900031119585,-0.000843890204662481,-0.000220886114117112,0.25,-6.2419038875574E-6,-7.92564239348681E-5,-6.66659896112009E-6,9.998661,9.9989548,-75773.1328125,-75723.21875,52.7442924776979,18.6749885562018,3.9365324,0,0,0,4449,9.97075,-75748.17578125,,,,,,,,,,,,,,,,,13.378378,,,,,,9.9988079,,,,
,15659558.14,10.0002604,-79753.59375,-6.46418607862062E-5,8.70301645003834E-7,1,0.999253354069792,40.0298881530762,1.99128817630137,15.6900031119585,-0.000685953934771455,-0.000179751172746346,0.25,-5.08333172727828E-6,-6.44256254276925E-5,-5.43721613786058E-6,10.0002604,10.0002604,-79756.0546875,-79751.1328125,52.8967100389479,18.6777692097344,3.9955161,0,0,0,4449,9.97185,-79753.59375,,,,,,,,,,,,,,,,,13.003003,,,,,,10.0002604,,,,
,15659637.415,9.9984369,-83716.37890625,-5.61808313610506E-5,1.06219686141787E-6,1,0.999253354069792,40.0298881530762,1.99128794753431,15.6900031119585,-0.000589446015295754,-0.000194324123592765,0.25,-7.94797611512634E-6,-5.59838634111015E-5,-8.25308362350936E-6,9.9983873,9.9984865,-83723.8984375,-83708.859375,52.5989095731209,18.6781353179236,3.9955161,0,0,0,4449,9.9726,-83716.37890625,,,,,,,,,,,,,,,,,13.003003,,,,,,9.9984369,,,,
,15659719.94,9.99823,-87841.68359375,-4.74195016797982E-5,1.0100122631416E-6,1,0.999253354069792,40.0298881530762,1.99126210532354,15.6900031119585,-0.000503470315008256,-0.000131539343393423,0.25,-3.68418338587892E-6,-4.72809934002598E-5,-3.95552190454748E-6,9.99823,9.99823,-87846.5625,-87836.8046875,53.0030115175633,18.6751750836167,4.0356307,0,0,0,4449,9.9735,-87841.68359375,,,,,,,,,,,,,,,,,13.003003,,,,,,9.99823,,,,
,15659817.36,9.99856805,-88141.3125,-4.35680807368667E-5,8.47319660037459E-7,1,0.999253354069792,40.0298881530762,1.9912922185864,15.6900031119585,-0.000461172536485114,-0.000128749682321281,0.25,-4.11739320718584E-6,-4.34371666055214E-5,-4.36526579245376E-6,9.9984913,9.9986448,-88171.421875,-88111.203125,52.7122457084094,18.6784667084139,4.0356307,0,0,0,4449,9.9748,-88141.3125,,,,,,,,,,,,,,,,,13.003003,,,,,,9.99856805,,,,
,15659905.525,10.000751,-83736.53125,-5.44775272193755E-5,1.28711687021413E-6,1,0.999253354069792,40.0298881530762,1.99134028375704,15.6900031119585,-0.000576245247648465,-0.00016254721838083,0.25,-5.30218634083905E-6,-5.43005603682791E-5,-5.60453234335674E-6,10.00072,10.000782,-83738.9296875,-83734.1328125,52.9287568082364,18.6773203170547,4.0155734,0,0,0,4449,9.9743,-83736.53125,,,,,,,,,,,,,,,,,13.003003,,,,,,10.000751,,,,
,15659985.04,9.9999566,-79761.515625,-6.88631443486632E-5,9.05588223732056E-7,1,0.999253354069792,40.0298881530762,1.99121295890803,15.6900031119585,-0.0007315956723792,-0.000186625375889018,0.25,-4.96399113164024E-6,-6.86353897956125E-5,-5.3423100323981E-6,9.9998131,10.0001001,-79791.625,-79731.40625,52.8638816411402,18.6776970280084,3.9955161,0,0,0,4449,9.97405,-79761.515625,,,,,,,,,,,,,,,,,12.252253,,,,,,9.9999566,,,,
,15660062.77,10.0008769,-75876.0859375,-7.6751946166754E-5,7.30221392474909E-7,1,0.999253354069792,40.0298881530762,1.99121587431093,15.6900031119585,-0.000818447579553374,-0.000190122143498439,0.25,-3.88356184390439E-6,-7.64920564755572E-5,-4.3003607238317E-6,10.0006857,10.0010681,-75903.4296875,-75848.7421875,52.9490791497364,18.6743031215223,3.9365324,0,0,0,4449,9.97275,-75876.0859375,,,,,,,,,,,,,,,,,12.252253,,,,,,10.0008769,,,,
,15660143.905,10.00255585,-71824.0078125,-8.54857375250334E-5,1.15248771675073E-6,1,0.999253354069792,40.0298881530762,1.99151878201091,15.6900031119585,-0.00091435222991821,-0.000195967919559238,0.25,-2.87055501513556E-6,-8.51865081808138E-5,-3.32761431442153E-6,10.0018635,10.0032482,-71851.390625,-71796.625,53.4618274583518,18.6803776498207,3.9955161,0,0,0,4449,9.9708,-71824.0078125,,,,,,,,,,,,,,,,,13.378378,,,,,,10.00255585,,,,
,15660222.845,10.00064755,-67879.0234375,-9.23749170837806E-5,6.1220956961576E-7,1,0.999253354069792,40.0298881530762,1.99129737772182,15.6900031119585,-0.00098711702166125,-0.000215144941153855,0.25,-3.43496735590228E-6,-9.20312751028971E-5,-3.91455232649421E-6,10.0006399,10.0006552,-67903.78125,-67854.265625,52.3581679891978,18.6775348821037,3.9955161,0,0,0,4449,9.9718,-67879.0234375,,,,,,,,,,,,,,,,,13.003003,,,,,,10.00064755,,,,
,15660302.73,10.00124025,-63886.53515625,-0.00010350966711667,6.65411049950918E-7,1,0.999253354069792,40.0298881530762,1.9911573941664,15.6900031119585,-0.00110209683537138,-0.0002617296226724,0.25,-5.79021614886128E-6,-0.000103094013304635,-6.30447466724844E-6,10.0010891,10.0013914,-63911.6875,-63861.3828125,52.9779994049479,18.6722702731816,3.9756581,0,0,0,4449,9.97075,-63886.53515625,,,,,,,,,,,,,,,,,13.003003,,,,,,10.00124025,,,,
,15660383.4,10.00118685,-59853.1328125,-0.000113585772743776,7.35294772233304E-7,1,0.999253354069792,40.0298881530762,1.99127573744488,15.6900031119585,-0.00121265431901667,-0.000267942116285774,0.25,-4.58384275286826E-6,-0.000113116656586698,-5.13604592433147E-6,10.0011797,10.001194,-59883.171875,-59823.09375,52.8162023014671,18.6735182040607,3.9756581,0,0,0,4449,9.96965,-59853.1328125,,,,,,,,,,,,,,,,,13.378378,,,,,,10.00118685,,,,
,15660463.52,10.0020137,-55847.755859375,-0.00012060616668537,5.46410255343462E-7,1,0.999253354069792,40.0298881530762,1.99119331874095,15.6900031119585,-0.00128818400311501,-0.000279551834559367,0.25,-4.43251651499834E-6,-0.000120087471130601,-4.99989359154883E-6,10.0019732,10.0020542,-55870.1171875,-55825.39453125,53.0827376265248,18.671868436665,3.8775487,0,0,0,4449,9.96765,-55847.755859375,,,,,,,,,,,,,,,,,13.003003,,,,,,10.0020137,,,,
,15660541.435,10.0012846,-51955.298828125,-0.000130974912257235,6.16038877477683E-7,1,0.999253354069792,40.0298881530762,1.9913667233975,15.6900031119585,-0.0014039312114177,-0.000274814120638818,0.25,-2.162047871731E-6,-0.000130400814389683,-2.76681432467219E-6,10.0012846,10.0012846,-51957.78125,-51952.81640625,52.8333981288902,18.6695977226774,3.9166744,0,0,0,4449,9.9665,-51955.298828125,,,,,,,,,,,,,,,,,12.252253,,,,,,10.0012846,,,,
,15660619.54,10.00203895,-48052.365234375,-0.00014034116695667,5.91984071857329E-7,1,0.999253354069792,40.0298881530762,1.99125108093632,15.6900031119585,-0.00150446119452488,-0.000291708596051831,0.25,-2.09097285045218E-6,-0.000139702490762079,-2.71501725644861E-6,10.0020323,10.0020456,-48084.875,-48019.85546875,52.7841555321787,18.6724581501481,3.9365324,0,0,0,4449,9.9642,-48052.365234375,,,,,,,,,,,,,,,,,12.252253,,,,,,10.00203895,,,,
,15660700.31,10.0014138,-44016.93359375,-0.000148353309772956,5.37798770609295E-7,1,0.999253354069792,40.0298881530762,1.99129532342298,15.6900031119585,-0.00158740798129145,-0.000323448831471164,0.25,-3.64642681985066E-6,-0.000147646198335899,-4.27112719030801E-6,10.0014133,10.0014143,-44046.7890625,-43987.078125,52.4527450400248,18.6723574214946,3.9166744,0,0,0,4449,9.964,-44016.93359375,,,,,,,,,,,,,,,,,13.378378,,,,,,10.0014138,,,,
,15660781.1,10.00136325,-39976.48828125,-0.0001548630240029,4.69803551831605E-7,1,0.999253354069792,40.0298881530762,1.99121661937053,15.6900031119585,-0.00165756822877109,-0.000332851986969123,0.25,-3.39722717139458E-6,-0.00015410121951627,-4.02054903164208E-6,10.001358,10.0013685,-40009.08984375,-39943.88671875,52.5598281471594,18.6730702466993,3.9365324,0,0,0,4449,9.9631,-39976.48828125,,,,,,,,,,,,,,,,,13.378378,,,,,,10.00136325,,,,
,15660858.96,10.0015807,-36086.84765625,-0.000162915303106714,5.02834223326839E-7,1,0.999253354069792,40.0298881530762,1.99109602994452,15.6900031119585,-0.0017449286035098,-0.000341448802683836,0.25,-2.80132085195642E-6,-0.000162092542941299,-3.42901661924836E-6,10.0014944,10.001667,-36111.82421875,-36061.87109375,52.6755091680056,18.6710094720077,3.9756581,0,0,0,4449,9.96275,-36086.84765625,,,,,,,,,,,,,,,,,13.378378,,,,,,10.0015807,,,,
,15660938.93,10.00026085,-32089.216796875,-0.000169832490793845,4.62028210079843E-7,1,0.999253354069792,40.0298881530762,1.99115679774417,15.6900031119585,-0.00181747257727954,-0.00036337973097142,0.25,-3.65050664709973E-6,-0.000168947329626021,-4.26639245780521E-6,10.0000534,10.0004683,-32119.2265625,-32059.20703125,52.8044778736787,18.6707408421402,3.9955161,0,0,0,4449,9.9623,-32089.216796875,,,,,,,,,,,,,,,,,13.378378,,,,,,10.00026085,,,,
,15661018.12,10.00104615,-28131.255859375,-0.000175460194434459,4.16901391169274E-7,1,0.999253354069792,40.0298881530762,1.99109333246118,15.6900031119585,-0.00188009593323028,-0.000360097491882363,0.25,-2.3863291258201E-6,-0.000174527126259505,-2.99382041944653E-6,10.0007429,10.0013494,-28161.158203125,-28101.353515625,52.7145905939671,18.6690116127981,3.9166744,0,0,0,4449,9.96135,-28131.255859375,,,,,,,,,,,,,,,,,13.003003,,,,,,10.00104615,,,,
,15661096.72,10.00045825,-24202.845703125,-0.00018265381674944,3.41545495955029E-7,1,0.999253354069792,40.0298881530762,1.99093481403532,15.6900031119585,-0.00195547636272979,-0.000382162482816358,0.25,-3.20823131976143E-6,-0.000181657339386252,-3.79935961710521E-6,10.0004387,10.0004778,-24232.94140625,-24172.75,52.7184987365633,18.670203540324,3.9361396,0,0,0,4449,9.96145,-24202.845703125,,,,,,,,,,,,,,,,,13.003003,,,,,,10.00045825,,,,
,15661176.83,9.9999809,-20202.4521484375,-0.000188620756389451,4.50185364822115E-7,1,0.999253354069792,40.0298881530762,1.99099604179755,15.6900031119585,-0.00202029524976007,-0.000388316496291534,0.25,-2.76586077543297E-6,-0.000187571646108276,-3.33998170346028E-6,9.9999704,9.9999914,-20229.955078125,-20174.94921875,52.6762907965248,18.6711742896369,3.8775487,0,0,0,4449,9.961,-20202.4521484375,,,,,,,,,,,,,,,,,12.252253,,,,,,9.9999809,,,,
,15661255.885,10.00106,-16249.8295898438,-0.000193921374238697,3.77286175110916E-7,1,0.999253354069792,40.0298881530762,1.99117492367874,15.6900031119585,-0.00207626157044577,-0.000403549263991045,0.25,-3.2859725430247E-6,-0.00019282131444027,-3.83427985952848E-6,10.0010099,10.0011101,-16277.224609375,-16222.4345703125,52.842777671121,18.669637681227,3.9955161,0,0,0,4449,9.96035,-16249.8295898438,,,,,,,,,,,,,,,,,12.252253,,,,,,10.00106,,,,
,15661335.54,10.0012536,-12268.9409179688,-0.000197638651031123,2.7793945760875E-7,1,0.999253354069792,40.0298881530762,1.99117911400584,15.6900031119585,-0.00211786009613065,-0.000399957699952267,0.25,-2.33709798708013E-6,-0.000196501837731951,-2.86211364561946E-6,10.0011845,10.0013227,-12273.8212890625,-12264.060546875,52.4582164396594,18.6675512305863,3.9955161,0,0,0,4449,9.9611,-12268.9409179688,,,,,,,,,,,,,,,,,13.003003,,,,,,10.0012536,,,,
,15661414.85,10.0003877,-8303.3798828125,-0.000198837293427564,2.61554431639708E-7,1,0.999253354069792,40.0298881530762,1.99097677310143,15.6900031119585,-0.00212930700259656,-0.000408069962126447,0.25,-2.92550014685866E-6,-0.000197675773154334,-3.41247194596038E-6,10.0002556,10.0005198,-8330.8662109375,-8275.8935546875,52.5293446349094,18.6688902518307,3.9955161,0,0,0,4449,9.9602,-8303.3798828125,,,,,,,,,,,,,,,,,13.003003,,,,,,10.0003877,,,,
,15661494.93,9.999969,-4302.19604492188,-0.000175754103108175,2.32040192899215E-7,1,0.999253354069792,40.0298881530762,1.99098756745921,15.6900031119585,-0.00188176892303903,-0.000361932652577227,0.25,-2.73437054771123E-6,-0.000174714832275564,-3.13272202345893E-6,9.9999628,9.9999752,-4327.1103515625,-4277.28173828125,52.6825438246787,18.6667122415968,4.0155734,0,0,0,4449,9.9602,-4302.19604492188,,,,,,,,,,,,,,,,,13.003003,,,,,,9.999969,,,,
,15661574.35,10.00112535,-330.769744873047,-0.000100490551089111,2.57740416357573E-7,1,0.999253354069792,40.0298881530762,1.99086955177544,15.6900031119585,-0.001074553749369,-0.000214101445337737,0.25,-2.24684934169992E-6,-9.98896204335356E-5,-2.45616792558873E-6,10.0010538,10.0011969,-363.322631835937,-298.216857910156,52.5973463160825,18.6678922579277,3.9361396,0,0,0,4449,9.9606,-330.769744873047,,,,,,,,,,,,,,,,,12.252253,,,,,,10.00112535,,,,
,15661653.02,10.0006852,3595.00671386719,1.55753545051135E-5,1.96845350137965E-7,1,0.999253354069792,40.0298881530762,1.99097003835321,15.6900031119585,0.000171835730250939,3.26755006997749E-6,0.25,-2.44035683012583E-6,1.54893349947848E-5,-2.38971097733277E-6,10.0005531,10.0008173,3565.11962890625,3624.89379882812,52.5426323197363,18.6668482616753,3.8970139,0,0,0,4449,9.95965,3595.00671386719,,,,,,,,,,,,,,,,,13.378378,,,,,,10.0006852,,,,
,15661733.985,10.00070335,7644.66064453125,5.09040392994568E-5,2.14140806764429E-7,1,0.999253354069792,40.0298881530762,1.99099643430478,15.7000036537647,0.000550619336654006,7.32881717494902E-5,0.25,-2.15364077127867E-6,5.06133177219091E-5,-2.0136401233519E-6,10.0006657,10.000741,7614.61962890625,7674.70166015625,52.4003759292363,18.6689036718194,3.9559976,0,0,0,4449,9.9592,7644.66064453125,,,,,,,,,,,,,,,,,12.252253,,,,,,10.00070335,,,,
,15661813.36,10.00018735,11613.5986328125,5.72188751776561E-5,3.10094212035295E-7,1,0.999253354069792,40.0298881530762,1.99081176519831,15.6900031119585,0.00061820332610665,8.64850177832194E-5,0.25,-2.04929384001898E-6,5.68962671950309E-5,-1.883505779195E-6,10.0000381,10.0003366,11588.53125,11638.666015625,52.5895300308902,18.6696474020665,3.9164791,0,0,0,4449,9.95915,11613.5986328125,,,,,,,,,,,,,,,,,13.003003,,,,,,10.00018735,,,,
,15661893.065,10.00027515,15596.8862304687,6.58405757046928E-5,3.8945171084148E-7,1,0.999253354069792,40.0298881530762,1.99097311030336,15.6900031119585,0.000711258972772236,0.000100792505487526,0.25,-2.25400244982603E-6,6.54757612075863E-5,-2.05102639928571E-6,10.0000925,10.0004578,15566.9873046875,15626.78515625,52.4246064133325,18.6681817306946,3.9559976,0,0,0,4449,9.9586,15596.8862304687,,,,,,,,,,,,,,,,,13.003003,,,,,,10.00027515,,,,
,15661972.4,10.000721,19562.068359375,8.1234725853631E-5,4.1892734051934E-7,1,0.999253354069792,40.0298881530762,1.99090084761916,15.6900031119585,0.000876382243780153,0.000131405284706245,0.25,-2.14220903018597E-6,8.07917750294775E-5,-1.87919528872923E-6,10.0006857,10.0007563,19539.724609375,19584.412109375,52.6536235694671,18.6696683623566,3.9559976,0,0,0,4449,9.9579,19562.068359375,,,,,,,,,,,,,,,,,13.003003,,,,,,10.000721,,,,
,15662050.555,10.00006865,23467.6611328125,0.000103229414501641,3.24717245035809E-7,1,0.999253354069792,40.0298881530762,1.99079001483699,15.6900031119585,0.00111186191288663,0.000177611803110407,0.25,-1.75446036966508E-6,0.000102675715472384,-1.4050041875199E-6,9.999999,10.0001383,23442.646484375,23492.67578125,52.4074105859094,18.6661867967529,3.9164791,0,0,0,4449,9.95805,23467.6611328125,,,,,,,,,,,,,,,,,13.378378,,,,,,10.00006865,,,,
,15662129,10.00044395,27388.6171875,0.000123527649795205,3.47306988572441E-7,1,0.999253354069792,40.0298881530762,1.990918097504,15.6900031119585,0.0013320838732064,0.000205022478384202,0.25,-2.82790715447533E-6,0.00012288350670183,-2.38112180465837E-6,10.000433,10.0004549,27360.970703125,27416.263671875,52.5293446349094,18.6663574353127,3.9955161,0,0,0,4449,9.95785,27388.6171875,,,,,,,,,,,,,,,,,12.252253,,,,,,10.00044395,,,,
,15662208.335,10.0001526,31354.00390625,0.00013763898412826,3.60638425882293E-7,1,0.999253354069792,40.0298881530762,1.99091568221432,15.6900031119585,0.00148284206126721,0.000237619026734279,0.25,-2.32783724889854E-6,0.000136937648744169,-1.80666931739291E-6,10.0001345,10.0001707,31323.8828125,31384.125,52.3808352162555,18.6633645207001,3.99631355,0,0,0,4449,9.9578,31354.00390625,,,,,,,,,,,,,,,,,13.378378,,,,,,10.0001526,,,,
,15662286.765,9.99995565,35274.125,0.000144408408491355,5.07322570015109E-7,1,0.999253354069792,40.0298881530762,1.99105314887386,15.6900031119585,0.00155590374764593,0.000250493929365971,0.25,-2.36545282562238E-6,0.000143693624578296,-1.79071234156556E-6,9.9999447,9.9999666,35246.76171875,35301.48828125,52.687233595794,18.6629734063454,3.9361396,0,0,0,4449,9.958,35274.125,,,,,,,,,,,,,,,,,13.003003,,,,,,9.99995565,,,,
,15662364.365,9.9992471,39149.328125,0.000145589440833535,5.35222506963751E-7,1,0.999253354069792,40.0298881530762,1.99090350777136,15.6900031119585,0.00156836514182865,0.00025479604759118,0.25,-2.20514531238892E-6,0.000144890601364726,-1.59890548931536E-6,9.999095,9.9993992,39119.1796875,39179.4765625,52.5801504886594,18.6667545738649,3.9361396,0,0,0,4449,9.95845,39149.328125,,,,,,,,,,,,,,,,,13.378378,,,,,,9.9992471,,,,
,15662442.725,9.99948885,43067.630859375,0.000140674713545644,4.31655131869861E-7,1,0.999253354069792,40.0298881530762,1.99090975068178,15.6900031119585,0.00151853286689441,0.000230215548867019,0.25,-3.64846324577389E-6,0.000140029098036164,-3.02918834565783E-6,9.9994383,9.9995394,43042.62890625,43092.6328125,52.6880152243133,18.6653033524474,4.076148,0,0,0,4449,9.9587,43067.630859375,,,,,,,,,,,,,,,,,13.003003,,,,,,9.99948885,,,,
,15662521.855,9.9995551,47023.830078125,0.000136636330982971,5.70377290424812E-7,1,0.999253354069792,40.0298881530762,1.9909872348284,15.6900031119585,0.00147430692487498,0.00022897365948769,0.25,-3.07421640872459E-6,0.000136031188238158,-2.45005293635568E-6,9.9993906,9.9997196,46991.4453125,47056.21484375,52.4285145559286,18.6646044260663,4.0356307,0,0,0,4449,9.95865,47023.830078125,,,,,,,,,,,,,,,,,13.378378,,,,,,9.9995551,,,,
,15662603.32,9.99970195,51093.978515625,0.000130032619511671,4.84421335870942E-7,1,0.999253354069792,40.0298881530762,1.99110237166296,15.6900031119585,0.00140400185925149,0.000214564504443428,0.25,-3.26553861054837E-6,0.000129482727363399,-2.64663510510143E-6,9.9996452,9.9997587,51063.98828125,51123.96875,52.8756060689287,18.6633078484826,4.0155734,0,0,0,4449,9.959,51093.978515625,,,,,,,,,,,,,,,,,13.378378,,,,,,9.99970195,,,,
,15662687.595,9.9992657,55304.240234375,0.000121357123798681,5.32474704901822E-7,1,0.999253354069792,40.0298881530762,1.99097512166213,15.6900031119585,0.00130935779088428,0.000206765585038686,0.25,-2.46632113307921E-6,0.000120865622368589,-1.86957580845925E-6,9.9992657,9.9992657,55301.71484375,55306.765625,52.4777571526402,18.6617928030358,4.0356307,0,0,0,4449,9.9591,55304.240234375,,,,,,,,,,,,,,,,,13.003003,,,,,,9.9992657,,,,
,15662766.36,9.99917175,59242.591796875,0.000113315603611942,6.36521693712317E-7,1,0.999253354069792,40.0298881530762,1.99097053287818,15.6900031119585,0.00122566773590549,0.000177257927401023,0.25,-3.79489188211917E-6,0.000112886112511515,-3.2137973059046E-6,9.9990826,9.9992609,59210.08984375,59275.09375,52.636427742044,18.6621415640134,4.0356307,0,0,0,4449,9.9599,59242.591796875,,,,,,,,,,,,,,,,,13.003003,,,,,,9.99917175,,,,
,15662844.275,10.00018645,63138.869140625,0.000104912223602321,6.72542406000513E-7,1,0.999253354069792,40.0298881530762,1.9909620053509,15.6900031119585,0.00113561360259545,0.000160698469984759,0.25,-3.84994964663525E-6,0.000104537182643199,-3.29534020633209E-6,10.0000668,10.0003061,63108.953125,63168.78515625,52.4863550663517,18.6633125572623,4.0356307,0,0,0,4449,9.9618,63138.869140625,,,,,,,,,,,,,,,,,12.252253,,,,,,10.00018645,,,,
,15662923.415,9.999753,67094.28515625,9.46750747035866E-5,6.27543823293678E-7,1,0.999253354069792,40.0298881530762,1.99087562400024,15.6900031119585,0.00102472190721432,0.000146446688376848,0.25,-3.35750659448657E-6,9.43555679005799E-5,-2.84426869039409E-6,9.999753,9.999753,67091.8515625,67096.71875,52.4277329274094,18.6619668759011,4.01597405,0,0,0,4449,9.9612,67094.28515625,,,,,,,,,,,,,,,,,13.003003,,,,,,9.999753,,,,
,15663003.325,9.9988828,71089.63671875,8.43305410498753E-5,7.53663197318274E-7,1,0.999253354069792,40.0298881530762,1.99069761895415,15.6900031119585,0.000917477110185392,0.000104813575716274,0.25,-5.38685465102141E-6,8.40768409815348E-5,-4.91056929484296E-6,9.9988785,9.9988871,71059.6015625,71119.671875,52.4816652952363,18.6633531941495,3.9957154,0,0,0,4449,9.962,71089.63671875,,,,,,,,,,,,,,,,,13.003003,,,,,,9.9988828,,,,
,15663081.76,9.9968648,75007.515625,7.16353856364031E-5,7.69260703882841E-7,1,0.999253354069792,40.0298881530762,1.99098930891805,15.6900031119585,0.000782046279475973,7.56398915510075E-5,0.25,-5.83284933606026E-6,7.14422111757036E-5,-5.41614712926534E-6,9.9968014,9.9969282,74977.3671875,75037.6640625,52.7083375658133,18.6646096110441,4.0356307,0,0,0,4449,9.9624,75007.515625,,,,,,,,,,,,,,,,,13.003003,,,,,,9.9968648,,,,
,15663160.52,9.9992027,78943.3828125,6.4824444753797E-5,7.66402383345297E-7,1,0.999253354069792,40.0298881530762,1.99091392379432,15.6900031119585,0.000707285125640826,7.1446496418521E-5,0.25,-5.00851312389363E-6,6.46623023788684E-5,-4.62564527687092E-6,9.9992027,9.9992027,78940.796875,78945.96875,52.6333012279671,18.6638686515284,3.9558001,0,0,0,4449,9.96415,78943.3828125,,,,,,,,,,,,,,,,,13.378378,,,,,,9.9992027,,,,
,15663238.795,9.99904585,82856.70703125,5.63758249591298E-5,7.91691158293897E-7,1,0.999253354069792,40.0298881530762,1.9909955607803,15.7000036537647,0.000614697886477469,6.5293270349292E-5,0.25,-4.06992536164246E-6,5.62454637626746E-5,-3.73251992251993E-6,9.9989519,9.9991398,82829.15625,82884.2578125,52.2166932272171,18.663073298106,3.9957154,0,0,0,4449,9.9647,82856.70703125,,,,,,,,,,,,,,,,,13.378378,,,,,,9.99904585,,,,
,15663317.205,9.9991207,86774.5,4.82175272612635E-5,7.95223034221485E-7,1,0.999253354069792,40.0298881530762,1.99101088859911,15.6900031119585,0.000523057654296475,7.14486754043231E-5,0.25,-2.03753447395773E-6,4.81080592256363E-5,-1.74851219633826E-6,9.9990978,9.9991436,86741.9765625,86807.0234375,52.5090222934094,18.6629641434976,3.9957154,0,0,0,4449,9.9657,86774.5,,,,,,,,,,,,,,,,,12.252253,,,,,,9.9991207,,,,
,15663383.29,9.99819705,89999.8046875,3.93937313829587E-5,9.5564909184196E-7,1,0.999253354069792,40.0298881530762,1.99104117043478,15.6900031119585,0.000435396346673352,1.4067370665184E-5,0.25,-5.78330185358189E-6,3.93358419630309E-5,-5.53482869248208E-6,9.9980354,9.9983587,89999.8046875,89999.8046875,52.5778056031017,18.6582216593135,4.076148,0,0,0,4417,9.96715,89999.8046875,,,,,,,,,,,,,,,,,13.003003,,,,,,9.99819705,,,,