File: data/doubleLayers/dl_1-25/ppms/DD205_3_HYST_20K_1OE.DAT
[Header]
; VSM Data File (default extension .dat)
; Copyright (c) 2003, Quantum Design, Inc. All rights reserved.
TITLE,
FILEOPENTIME,15664639.97,04/17/2018,12:51 am
BYAPP,VSM,1.0,1.0
INFO,PPMS VSM Option Release 1.3.7 Build 2,APPNAME
INFO,291,COIL_SERIAL_NUMBER
INFO,0,MOMENT_UNITS
INFO,,SAMPLE_MATERIAL
INFO,,SAMPLE_COMMENT
INFO,,SAMPLE_MASS
INFO,,SAMPLE_VOLUME
INFO,,SAMPLE_MOLECULAR_WEIGHT
INFO,,SAMPLE_SIZE
INFO,,SAMPLE_SHAPE
INFO,36.06,SAMPLE_OFFSET
DATATYPE,COMMENT,1
DATATYPE,TIME,2
STARTUPAXIS,X,2
STARTUPAXIS,Y1,5
[Data]
Comment,Time Stamp (sec),Temperature (K),Magnetic Field (Oe),Moment (emu),M. Std. Err. (emu),Transport Action,Averaging Time (sec),Frequency (Hz),Peak Amplitude (mm),Center Position (mm),Coil Signal' (mV),Coil Signal" (mV),Range (mV),M. Quad. Signal (emu),M. Raw' (emu),M. Raw" (emu),Min. Temperature (K),Max. Temperature (K),Min. Field (Oe),Max. Field (Oe),Mass (grams),Motor Lag (deg),Pressure (Torr),VSM Status (code),Motor Status (code),Measure Status (code),PPMS Status (code),System Temp. (K),System Field (Oe),Sample Position (deg),Bridge 1 Resistance (ohms),Bridge 1 Excitation (에),Bridge 2 Resistance (ohms),Bridge 2 Excitation (에),Bridge 3 Resistance (ohms),Bridge 3 Excitation (에),Bridge 4 Resistance (ohms),Bridge 4 Excitation (에),Signal 1 Vin (V),Signal 2 Vin (V),Digital Inputs (code),Drive 1 Iout (mA),Drive 1 Ipower (W),Drive 2 Iout (mA),Drive 2 Ipower (W),Pressure (),Map 20 (),Map 21 (),Map 22 (),Map 23 (),Map 24 (),Map 25 (),Map 26 (),Map 27 (),Map 28 (),Map 29 ()
,15664672.91,20.0097713,0.320900768041611,7.39589232852476E-5,2.29073544392226E-7,1,0.999253354069792,40.0298881530762,1.99063258221954,15.6900031119585,0.000798090307729927,0.000115920052728162,0.25,-2.22938229905893E-6,7.35250567615163E-5,-2.04814970217471E-6,20.0097713,20.0097713,0.320900768041611,0.320900768041611,51.9399967314093,18.6408141198818,5.4458747,0,0,0,4417,20.01825,0.320900768041611,,,,,,,,,,,,,,,,,13.753754,,,,,,20.0097713,,,,
,15664763.015,20.0025396,3739.97875976562,0.000163047119162234,1.8266353478275E-7,1,0.999253354069792,40.0298881530762,1.9906988043511,15.6900031119585,0.00175349496540454,0.000290138715412752,0.25,-1.71535086287575E-6,0.000162091448002505,-1.31458867603361E-6,20.0022678,20.0028114,3714.98828125,3764.96923828125,52.0416084389094,18.6511739132753,5.5005507,0,0,0,4449,20.00685,3739.97875976562,,,,,,,,,,,,,,,,,12.252253,,,,,,20.0025396,,,,
,15664839.1,20.0080757,7540.39526367187,0.000191498659808376,2.92487897100278E-7,1,0.999253354069792,40.0298881530762,1.99082001952542,15.6900031119585,0.00205979624231435,0.000340495064933502,0.25,-2.0754103748217E-6,0.000190389641371242,-1.57335296689683E-6,20.0079174,20.008234,7510.54833984375,7570.2421875,52.054114495217,18.6485607007672,5.5557761,0,0,0,4449,20.01275,7540.39526367187,,,,,,,,,,,,,,,,,13.003003,,,,,,20.0080757,,,,
,15664923.43,19.9951801,11756.0297851562,0.000187927566584666,2.63058109874967E-7,1,0.999253354069792,40.0298881530762,1.99074348390801,15.6900031119585,0.00202215738996613,0.000330429289603141,0.25,-2.42171675492663E-6,0.000186857380568044,-1.89004306609797E-6,19.9951801,19.9951801,11753.423828125,11758.6357421875,52.013469812217,18.6536639651303,5.5016489,0,0,0,4449,19.9978,11756.0297851562,,,,,,,,,,,,,,,,,12.252253,,,,,,19.9951801,,,,
,15665009.31,20.0027809,16046.7666015625,0.000181608289400794,2.95180370827202E-7,1,0.999253354069792,40.0298881530762,1.99089553669451,15.6900031119585,0.00195177852106359,0.000334830956773199,0.25,-9.39385280548249E-7,0.000180589355352441,-3.95401089159543E-7,20.0027733,20.0027885,16016.8134765625,16076.7197265625,52.2307625405632,18.6525216831022,5.5557761,0,0,0,4449,20.0042,16046.7666015625,,,,,,,,,,,,,,,,,13.003003,,,,,,20.0027809,,,,
,15665094.94,20.0033884,20326.8427734375,0.000174903649529818,3.66701332258658E-7,1,0.999253354069792,40.0298881530762,1.99070491146269,15.6900031119585,0.001881475064838,0.00031289054567782,0.25,-1.83559346859532E-6,0.000173945916972573,-1.2689336042156E-6,20.0033073,20.0034695,20299.3125,20354.373046875,52.2682807094863,18.6541727271965,5.3917422,0,0,0,4449,20.00535,20326.8427734375,,,,,,,,,,,,,,,,,12.252253,,,,,,20.0033884,,,,
,15665180.155,20.0041809,24589.6240234375,0.000167631331909405,3.25494274049415E-7,1,0.999253354069792,40.0298881530762,1.99071983408182,15.6900031119585,0.00180334192668172,0.000300793894701881,0.25,-1.71463914974255E-6,0.000166735190084971,-1.13563539222035E-6,20.0041809,20.0041809,24587.201171875,24592.046875,52.1174264052747,18.6538466718354,5.5005507,0,0,0,4449,20.00135,24589.6240234375,,,,,,,,,,,,,,,,,13.378378,,,,,,20.0041809,,,,
,15665266.58,20.0035706,28905.1181640625,0.000159735245480482,3.49905676944909E-7,1,0.999253354069792,40.0298881530762,1.99076377913956,15.6900031119585,0.00171798323599174,0.000290620211770881,0.25,-1.30152808924185E-6,0.00015890317074249,-7.16701644691763E-7,20.0034409,20.0037003,28875.05078125,28935.185546875,52.3378456476978,18.6578502475747,5.4458747,0,0,0,4449,20.0008,28905.1181640625,,,,,,,,,,,,,,,,,13.378378,,,,,,20.0035706,,,,
,15665353.29,20.0028858,33240.796875,0.000151298286043484,3.28707814378259E-7,1,0.999253354069792,40.0298881530762,1.99068844493721,15.6900031119585,0.00162774870638469,0.000273571315728736,0.25,-1.4271859335871E-6,0.000150534520827175,-8.39429088538534E-7,20.0028858,20.0028858,33233.2734375,33248.3203125,52.4121003570248,18.6542277059283,5.6115556,0,0,0,4449,19.9973,33240.796875,,,,,,,,,,,,,,,,,13.003003,,,,,,20.0028858,,,,
,15665437.775,20.0018425,37463.37109375,0.000143200011930237,4.74646450893589E-7,1,0.999253354069792,40.0298881530762,1.99077855425451,15.6900031119585,0.0015407795530164,0.000259896981661507,0.25,-1.29558942490064E-6,0.000142500229810368,-7.09874853436547E-7,20.0017567,20.0019283,37431.05078125,37495.69140625,52.5738974605056,18.6557312971811,5.52871515,0,0,0,4449,19.9974,37463.37109375,,,,,,,,,,,,,,,,,13.378378,,,,,,20.0018425,,,,
,15665523.9,20.00333025,41766.478515625,0.000131960580358076,6.05228956352635E-7,1,0.999253354069792,40.0298881530762,1.99117905926628,15.6900031119585,0.00141989380261889,0.000242253317334486,0.25,-9.73134179316111E-7,0.000131337997938988,-4.07261439674372E-7,20.0032921,20.0033684,41734.08203125,41798.875,52.6043809727556,18.6547892665676,5.584223,0,0,0,4449,19.9961,41766.478515625,,,,,,,,,,,,,,,,,13.378378,,,,,,20.00333025,,,,
,15665606.705,20.00174615,45907.2890625,0.000121562889452146,5.84088028799786E-7,1,0.999253354069792,40.0298881530762,1.99074736145673,15.6900031119585,0.00130655658143071,0.000231150235208649,0.25,-1.76364447652483E-7,0.000121007782631616,3.65000670019355E-7,20.0016937,20.0017986,45882.20703125,45932.37109375,52.0791266078324,18.6554640553064,5.6115556,0,0,0,4449,19.99565,45907.2890625,,,,,,,,,,,,,,,,,13.378378,,,,,,20.00174615,,,,
,15665684.88,20.00352575,49812.830078125,0.000116061789458437,5.91311976927009E-7,1,0.999253354069792,40.0298881530762,1.99076299072721,15.6900031119585,0.00124704119358256,0.000224190491493894,0.25,1.33138429379251E-7,0.000115550606076879,6.6909549185346E-7,20.0034561,20.0035954,49785.26953125,49840.390625,52.4769755241209,18.6563351797541,5.584223,0,0,0,4449,19.9934,49812.830078125,,,,,,,,,,,,,,,,,13.378378,,,,,,20.00352575,,,,
,15665762.7,20.00392725,53700.7890625,0.000105363446147784,5.71411444498574E-7,1,0.999253354069792,40.0298881530762,1.99073245898061,15.6900031119585,0.00113245971744881,0.00020255312557293,0.25,9.53432032071708E-9,0.000104918812704926,5.14345025894516E-7,20.0039101,20.0039444,53668.265625,53733.3125,52.4285145559286,18.653818159035,5.6678953,0,0,0,4449,19.9945,53700.7890625,,,,,,,,,,,,,,,,,13.378378,,,,,,20.00392725,,,,
,15665841.585,19.9910822,57646.021484375,9.59865511637635E-5,7.55794948680369E-7,1,0.999253354069792,40.0298881530762,1.99086134602466,15.6900031119585,0.00103148299755663,0.000187094284887664,0.25,2.27556853282962E-7,9.55984369373117E-5,7.02237122557735E-7,19.9906483,19.9915161,57616.09765625,57675.9453125,52.4699408674479,18.6564929464538,5.7248006,0,0,0,4449,19.97655,57646.021484375,,,,,,,,,,,,,,,,,12.252253,,,,,,19.9910822,,,,
,15665925.62,19.9932308,61846.828125,8.45498557338519E-5,5.76255775075285E-7,1,0.999253354069792,40.0298881530762,1.99071659255986,15.6900031119585,0.000913721481823197,0.000136840686501181,0.25,-2.41627067568567E-6,8.4238801476952E-5,-1.97410167270949E-6,19.9932003,19.9932613,61814.25390625,61879.40234375,52.534816034544,18.6563913343155,5.584223,0,0,0,4449,19.9919,61846.828125,,,,,,,,,,,,,,,,,12.252253,,,,,,19.9932308,,,,
,15666011.86,19.99842645,66157.62890625,7.26076001261258E-5,7.51354767110207E-7,1,0.999253354069792,40.0298881530762,1.9906727068751,15.6900031119585,0.000787055476690521,0.000105075590418301,0.25,-3.24530176780346E-6,7.23627481696994E-5,-2.850214410485E-6,19.9983311,19.9985218,66122.7265625,66192.53125,52.514493693044,18.6553638235652,5.584223,0,0,0,4449,19.99715,66157.62890625,,,,,,,,,,,,,,,,,13.378378,,,,,,19.99842645,,,,
,15666097.585,19.99937725,70440.65234375,6.32307203523594E-5,7.7005322941896E-7,1,0.999253354069792,40.0298881530762,1.99069906681413,15.6900031119585,0.000689886707168745,6.75053079392167E-5,0.25,-5.06895583812755E-6,6.30439991847258E-5,-4.70853380815772E-6,19.9992924,19.9994621,70410.5625,70470.7421875,52.4769755241209,18.6545862138743,5.55605315,0,0,0,4449,19.9985,70440.65234375,,,,,,,,,,,,,,,,,12.252253,,,,,,19.99937725,,,,
,15666183.14,20.0003262,74715.50390625,5.57166673475685E-5,7.4390313874273E-7,1,0.999253354069792,40.0298881530762,1.99071811984377,15.6900031119585,0.000607196779726295,6.42631615954943E-5,0.25,-4.03130472206789E-6,5.55627635858434E-5,-3.7084235149242E-6,20.0003262,20.0003262,74712.9609375,74718.046875,52.3362823906594,18.6542797717443,5.6118357,0,0,0,4449,19.99745,74715.50390625,,,,,,,,,,,,,,,,,12.252253,,,,,,20.0003262,,,,
,15666268.305,19.9991884,78973.5546875,4.41282283364218E-5,9.28250953095651E-7,1,0.999253354069792,40.0298881530762,1.99080099668584,15.6900031119585,0.000477809331120096,6.88835486242338E-5,0.25,-1.52823301034562E-6,4.40071941301144E-5,-1.27253830527995E-6,19.9990959,19.9992809,78940.9375,79006.171875,51.952502787717,18.6534184160308,5.6115556,0,0,0,4449,19.99635,78973.5546875,,,,,,,,,,,,,,,,,12.252253,,,,,,19.9991884,,,,
,15666354.22,20.0018969,83266.65625,3.81784865179764E-5,1.14074505943227E-6,1,0.999253354069792,40.0298881530762,1.99100555239351,15.6900031119585,0.000405459672296741,0.000104463558059593,0.25,2.83981354338002E-6,3.80584837898532E-5,3.05390906523151E-6,20.001833,20.0019608,83234.2421875,83299.0703125,52.3550414751209,18.6553253483465,5.63972545,0,0,0,4449,19.9989,83266.65625,,,,,,,,,,,,,,,,,13.003003,,,,,,20.0018969,,,,
,15666439.72,20.00114535,87539.47265625,1.7535994672289E-5,1.11495253774927E-6,1,0.999253354069792,40.0298881530762,1.9908658444847,15.6900031119585,0.000195881825859351,-5.47056216520164E-6,0.25,-3.66325739992789E-6,1.75141341981664E-5,-3.55043689811318E-6,20.0009727,20.001318,87506.890625,87572.0546875,52.4152268711017,18.6589568206676,5.6678953,0,0,0,4449,19.99745,87539.47265625,,,,,,,,,,,,,,,,,13.378378,,,,,,20.00114535,,,,
,15666541.75,20.00195405,88216.69140625,1.69412065329912E-5,9.07265034230919E-7,1,0.999253354069792,40.0298881530762,1.99090390807721,15.6900031119585,0.000186406873584983,1.0508704889054E-5,0.25,-2.07228153708237E-6,1.6912059560926E-5,-1.96673624348019E-6,20.0019493,20.0019588,88191.84375,88241.5390625,52.3042356213709,18.6555199459692,5.6678953,0,0,0,4449,19.9971,88216.69140625,,,,,,,,,,,,,,,,,12.252253,,,,,,20.00195405,,,,
,15666618.21,20.00256255,84393.9296875,2.52591609469E-5,9.38230588199912E-7,1,0.999253354069792,40.0298881530762,1.99100368513748,15.6900031119585,0.000287043128604584,-3.52654918197003E-5,0.25,-7.81873288109172E-6,2.52378525105011E-5,-7.65053599888692E-6,20.002512,20.0026131,84373.9453125,84413.9140625,52.5152753215633,18.6565817945664,5.6118357,0,0,0,4449,19.99895,84393.9296875,,,,,,,,,,,,,,,,,13.003003,,,,,,20.00256255,,,,
,15666695.88,20.00254915,80513.41796875,3.31037220033115E-5,1.00839905124952E-6,1,0.999253354069792,40.0298881530762,1.99089511770156,15.6900031119585,0.000369092993578738,-7.3391767878921E-6,0.25,-6.63195606115658E-6,3.30471484822621E-5,-6.42312920153759E-6,20.0023918,20.0027065,80485.8046875,80541.03125,52.4504001544671,18.6591032424368,5.6118357,0,0,0,4449,19.9952,80513.41796875,,,,,,,,,,,,,,,,,13.003003,,,,,,20.00254915,,,,
,15666771.935,20.00307655,76712.72265625,4.80476030063416E-5,1.21365230639244E-6,1,0.999253354069792,40.0298881530762,1.99091978188491,15.6900031119585,0.000517713312116184,8.89108725314132E-5,0.25,-3.67702681568893E-7,4.79026551970776E-5,-9.62307867660505E-8,20.0028553,20.0032978,76682.703125,76742.7421875,52.6551868265056,18.6587603551835,5.7250862,0,0,0,4449,19.98995,76712.72265625,,,,,,,,,,,,,,,,,13.003003,,,,,,20.00307655,,,,
,15666853.27,19.9960127,72647.19921875,5.98352315942849E-5,1.08680106242444E-6,1,0.999253354069792,40.0298881530762,1.99079745270119,15.6900031119585,0.000639437339523584,0.000139167960250977,0.25,2.196534570361E-6,5.96272765108633E-5,2.51848043164491E-6,19.9958458,19.9961796,72614.734375,72679.6640625,52.3894331299671,18.6576425070338,5.7250862,0,0,0,4449,19.98585,72647.19921875,,,,,,,,,,,,,,,,,13.753754,,,,,,19.9960127,,,,
,15666939.265,19.99805545,68349.3359375,6.88467585061998E-5,8.453628603844E-7,1,0.999253354069792,40.0298881530762,1.99070446438579,15.6900031119585,0.000744351661929028,0.000110991747599721,0.25,-2.02757695829237E-6,6.86169142310736E-5,-1.65165695248772E-6,19.997982,19.9981289,68321.6484375,68377.0234375,52.4160084996209,18.6556255894355,5.64028835,0,0,0,4449,19.99035,68349.3359375,,,,,,,,,,,,,,,,,13.378378,,,,,,19.99805545,,,,
,15667024.165,20.0004721,64103.873046875,8.19094990652432E-5,7.08593900710027E-7,1,0.999253354069792,40.0298881530762,1.99065459887993,15.6900031119585,0.000882654169229671,0.000147145130179451,0.25,-9.93084571342853E-7,8.16105964723374E-5,-5.63034611884562E-7,20.000412,20.0005322,64068.71484375,64139.03125,52.3472251899286,18.6587646720479,5.6118357,0,0,0,4449,19.9948,64103.873046875,,,,,,,,,,,,,,,,,13.378378,,,,,,20.0004721,,,,
,15667111.16,20.00195405,59755.64453125,9.17385300940284E-5,7.20365930263616E-7,1,0.999253354069792,40.0298881530762,1.99062390283307,15.6900031119585,0.000985367967303067,0.000181363253406941,0.25,4.47019480223016E-7,9.13758727494388E-5,9.07557621363919E-7,20.0018024,20.0021057,59725.84765625,59785.44140625,52.4808836667171,18.6572957205004,5.6678953,0,0,0,4449,19.9936,59755.64453125,,,,,,,,,,,,,,,,,13.378378,,,,,,20.00195405,,,,
,15667199.075,20.0029526,55364.115234375,0.000104063281965517,7.08630223268539E-7,1,0.999253354069792,40.0298881530762,1.99066771028735,15.6900031119585,0.00112236030852817,0.000178700122611106,0.25,-1.98536611064078E-6,0.000103642008886504,-1.47125307678788E-6,20.0029526,20.0029526,55361.5625,55366.66796875,52.6215768001786,18.6599572611581,5.6678953,0,0,0,4449,19.9914,55364.115234375,,,,,,,,,,,,,,,,,13.003003,,,,,,20.0029526,,,,
,15667283.275,20.00003815,51151.216796875,0.000114281892683379,6.40697212413958E-7,1,0.999253354069792,40.0298881530762,1.99061448288225,15.6900031119585,0.00122875128902878,0.000216018820595758,0.25,-3.15898416522861E-7,0.00011378760666812,2.2049975015289E-7,20.0000095,20.0000668,51118.63671875,51183.796875,52.4730673815248,18.6580264673084,5.6118357,0,0,0,4449,19.9877,51151.216796875,,,,,,,,,,,,,,,,,13.003003,,,,,,20.00003815,,,,
,15667369.31,20.0024071,46853.271484375,0.000123849198564738,4.93746106417124E-7,1,0.999253354069792,40.0298881530762,1.99067775666009,15.6900031119585,0.00133311418053971,0.000224445888954018,0.25,-1.2137475427248E-6,0.000123293423863649,-6.52176367687508E-7,20.0024071,20.0024071,46851.01953125,46855.5234375,52.4574348111402,18.6575962215611,5.7248006,0,0,0,4449,19.98935,46853.271484375,,,,,,,,,,,,,,,,,13.003003,,,,,,20.0024071,,,,
,15667454.375,20.0025673,42602.712890625,0.000134898052125281,5.31141299564138E-7,1,0.999253354069792,40.0298881530762,1.99075497989006,15.6900031119585,0.00145300296385419,0.000237831284514384,0.25,-1.90980429416344E-6,0.000134270269037046,-1.32173887122652E-6,20.0025673,20.0025673,42597.7265625,42607.69921875,52.5621730327171,18.6585694837647,5.6118357,0,0,0,4449,19.9859,42602.712890625,,,,,,,,,,,,,,,,,12.252253,,,,,,20.0025673,,,,
,15667536.045,20.00283145,38519.4765625,0.000140139360827036,6.39296191114199E-7,1,0.999253354069792,40.0298881530762,1.99097693495413,15.6900031119585,0.00151183374307366,0.000233147345001785,0.25,-3.25108296777108E-6,0.000139468552323636,-2.66108121999205E-6,20.0027771,20.0028858,38489.53515625,38549.41796875,52.5402874341786,18.6612718681886,5.69691635,0,0,0,4449,19.9846,38519.4765625,,,,,,,,,,,,,,,,,12.252253,,,,,,20.00283145,,,,
,15667612.825,20.00287055,34681.640625,0.000150512261500655,4.3419257610288E-7,1,0.999253354069792,40.0298881530762,1.99090936389815,15.6900031119585,0.00162128993438381,0.000262413271054502,0.25,-2.34101281066505E-6,0.000149764230054303,-1.74098800437779E-6,20.0028343,20.0029068,34656.67578125,34706.60546875,52.4261696703709,18.6607354786079,5.7822771,0,0,0,4449,19.98625,34681.640625,,,,,,,,,,,,,,,,,13.378378,,,,,,20.00287055,,,,
,15667690.125,20.00266835,30818.5849609375,0.000158513971156946,4.05293685349195E-7,1,0.999253354069792,40.0298881530762,1.9907937669171,15.6900031119585,0.00170470047796208,0.000290041738567009,0.25,-1.15607441131607E-6,0.000157698411294375,-5.61235288078138E-7,20.0026283,20.0027084,30788.423828125,30848.74609375,52.5699893179094,18.6611673799631,5.7248006,0,0,0,4449,19.9838,30818.5849609375,,,,,,,,,,,,,,,,,13.378378,,,,,,20.00266835,,,,
,15667765.535,20.00278475,27050.955078125,0.000164675279236708,3.70350283565048E-7,1,0.999253354069792,40.0298881530762,1.9907747048856,15.6900031119585,0.00176979593806302,0.000306429515968008,0.25,-6.89303905413531E-7,0.000163804700775785,-1.05353916042154E-7,20.0027676,20.0028019,27021.005859375,27080.904296875,52.5207467211979,18.6607116926543,5.7825656,0,0,0,4449,19.9816,27050.955078125,,,,,,,,,,,,,,,,,13.378378,,,,,,20.00278475,,,,
,15667848.07,19.9937897,22925.41796875,0.000174041939977119,3.26923523414086E-7,1,0.999253354069792,40.0298881530762,1.99076671292761,15.7000036537647,0.00187199300923076,0.000313722064077668,0.25,-1.63163501642037E-6,0.000173101827375292,-1.04610270324548E-6,19.9937897,19.9937897,22922.970703125,22927.865234375,52.1744852871786,18.6586365185845,5.69691635,0,0,0,4449,19.9733,22925.41796875,,,,,,,,,,,,,,,,,13.378378,,,,,,19.9937897,,,,
,15667928.495,19.99477195,18907.33203125,0.000181678607632419,3.17373928060817E-7,1,0.999253354069792,40.0298881530762,1.99091389353813,15.6900031119585,0.00195415987859171,0.000326761995341452,0.25,-1.73205922699972E-6,0.000180675736812903,-1.15754685645622E-6,19.9947338,19.9948101,18874.80859375,18939.85546875,52.362076131794,18.6598133552917,5.75353885,0,0,0,4449,19.979,18907.33203125,,,,,,,,,,,,,,,,,13.378378,,,,,,19.99477195,,,,
,15668014.115,19.99561215,14624.6611328125,0.000188285725922801,2.97771587008899E-7,1,0.999253354069792,40.0298881530762,1.99080625279564,15.6900031119585,0.00202503209765066,0.000337779732451804,0.25,-1.8298856503263E-6,0.000187224906586992,-1.27443975713717E-6,19.9955788,19.9956455,14602.2685546875,14647.0537109375,52.3917780155248,18.6594327640319,5.7248006,0,0,0,4449,19.98345,14624.6611328125,,,,,,,,,,,,,,,,,13.003003,,,,,,19.99561215,,,,
,15668101.075,19.99963375,10281.55078125,0.000193061152891339,2.61070983039317E-7,1,0.999253354069792,40.0298881530762,1.99084521283841,15.6900031119585,0.00207593133385998,0.000347921430511344,0.25,-1.68605408959165E-6,0.000191953059082667,-1.15805495530085E-6,19.9994678,19.9997997,10248.908203125,10314.193359375,52.5598281471594,18.66259200424,5.7248006,0,0,0,4449,19.98605,10281.55078125,,,,,,,,,,,,,,,,,12.252253,,,,,,19.99963375,,,,
,15668186.99,20.0003252,5985.771484375,0.000191116620546577,3.02108605689751E-7,1,0.999253354069792,40.0298881530762,1.99079778279763,15.6900031119585,0.00205535401269785,0.000341209432641493,0.25,-1.92677159536395E-6,0.000190003665341806,-1.43981033121778E-6,20.0002899,20.0003605,5955.5830078125,6015.9599609375,52.4652510963325,18.6584106132074,5.7248006,0,0,0,4449,19.98605,5985.771484375,,,,,,,,,,,,,,,,,12.252253,,,,,,20.0003252,,,,
,15668272.335,20.00033095,1718.96954345703,0.000131677064230461,2.86037305687807E-7,1,0.999253354069792,40.0298881530762,1.99086784504968,15.6900031119585,0.00141662391162765,0.000231889494334886,0.25,-1.60236786643656E-6,0.000130901725288737,-1.28742490110272E-6,20.0002232,20.0004387,1686.51452636719,1751.42456054687,52.7239701361979,18.6602210579558,5.6681781,0,0,0,4449,19.98705,1718.96954345703,,,,,,,,,,,,,,,,,12.252253,,,,,,20.00033095,,,,
,15668358.405,19.9995861,-2579.10363769531,4.88907196548981E-6,1.6139649701605E-7,1,0.999253354069792,40.0298881530762,1.99071011918756,15.6900031119585,5.63217069515211E-5,-1.25363295776695E-5,0.25,-2.02951318616201E-6,4.86497474030421E-6,-2.00603822271519E-6,19.9995861,19.9995861,-2581.7265625,-2576.48071289062,52.9295384367556,18.6633783423294,5.5557761,0,0,0,4449,19.9837,-2579.10363769531,,,,,,,,,,,,,,,,,13.003003,,,,,,19.9995861,,,,
,15668444.295,19.9996719,-6873.87255859375,-4.62353355034555E-5,3.13904909441849E-7,1,0.999253354069792,40.0298881530762,1.99085725283397,15.6900031119585,-0.000492280601366358,-0.000110762164510733,0.25,-2.15994771546096E-6,-4.59602244371091E-5,-2.26422868377809E-6,19.9996719,19.9996719,-6876.32861328125,-6871.41650390625,52.5098039219286,18.6636500478559,5.7248006,0,0,0,4449,19.9834,-6873.87255859375,,,,,,,,,,,,,,,,,13.003003,,,,,,19.9996719,,,,
,15668528.775,20.0025215,-11094.455078125,-5.22466563444334E-5,2.75938118856976E-7,1,0.999253354069792,40.0298881530762,1.99086144760876,15.6900031119585,-0.000556042281981337,-0.000126800654790817,0.25,-2.58209352007226E-6,-5.19394556046051E-5,-2.70953765931204E-6,20.002346,20.002697,-11124.4794921875,-11064.4306640625,52.626266571294,18.662635171792,5.75353885,0,0,0,4449,19.98675,-11094.455078125,,,,,,,,,,,,,,,,,13.378378,,,,,,20.0025215,,,,
,15668604.785,20.00330255,-14892.8325195313,-6.0355824042736E-5,3.46285113962868E-7,1,0.999253354069792,40.0298881530762,1.99090827067257,15.6900031119585,-0.000642686003152795,-0.000144946063966282,0.25,-2.82721356677792E-6,-6.00062558216078E-5,-2.9867574781132E-6,20.0032768,20.0033283,-14922.796875,-14862.8681640625,52.595783059044,18.6604600410736,5.7822771,0,0,0,4449,19.98505,-14892.8325195313,,,,,,,,,,,,,,,,,13.003003,,,,,,20.00330255,,,,
,15668680.225,20.00185585,-18665.2724609375,-7.52128166906757E-5,3.64288481719289E-7,1,0.999253354069792,40.0298881530762,1.99087700591561,15.6900031119585,-0.000803012231732725,-0.000168983189419093,0.25,-2.42332691163406E-6,-7.47874024668954E-5,-2.64281057057568E-6,20.0018005,20.0019112,-18695.197265625,-18635.34765625,52.6137605149863,18.6606371673058,5.75353885,0,0,0,4449,19.9822,-18665.2724609375,,,,,,,,,,,,,,,,,13.378378,,,,,,20.00185585,,,,
,15668759.495,20.0015669,-22625.9951171875,-9.65616774042367E-5,3.43533143323903E-7,1,0.999253354069792,40.0298881530762,1.99089220056693,15.6900031119585,-0.00103170647666766,-0.00021335069527889,0.25,-2.75427739967315E-6,-9.60271372540859E-5,-3.05778990678056E-6,20.0015202,20.0016136,-22648.501953125,-22603.48828125,52.3331558765825,18.6620284521517,5.6678953,0,0,0,4449,19.984,-22625.9951171875,,,,,,,,,,,,,,,,,13.378378,,,,,,20.0015669,,,,
,15668839.815,20.00130845,-26638.208984375,-0.000116718450697797,4.33919135050881E-7,1,0.999253354069792,40.0298881530762,1.99087475908217,15.6900031119585,-0.00124794582816293,-0.000253781665587069,0.25,-2.92029313293017E-6,-0.000116087865194258,-3.31362572364819E-6,20.0012665,20.0013504,-26670.685546875,-26605.732421875,52.7145905939671,18.6651094057481,5.69691635,0,0,0,4449,19.983,-26638.208984375,,,,,,,,,,,,,,,,,13.003003,,,,,,20.00130845,,,,
,15668920.44,19.99988555,-30669.009765625,-0.000127727605648689,2.52753192382087E-7,1,0.999253354069792,40.0298881530762,1.99089132365068,15.6900031119585,-0.00136799172132654,-0.000265693984668012,0.25,-2.04632890214544E-6,-0.000127058713170515,-2.5092520111125E-6,19.9998398,19.9999313,-30699.0859375,-30638.93359375,52.788845303294,18.6650841654662,5.7250862,0,0,0,4449,19.9803,-30669.009765625,,,,,,,,,,,,,,,,,13.003003,,,,,,19.99988555,,,,
,15668997.78,20.0007973,-34534.099609375,-0.000131353660553481,4.5595663372651E-7,1,0.999253354069792,40.0298881530762,1.99093569424155,15.6900031119585,-0.00140802311190568,-0.000267828439451422,0.25,-1.57137628544667E-6,-0.000130685989291898,-2.07585389303376E-6,20.0007935,20.0008011,-34561.59765625,-34506.6015625,52.5457588338133,18.6642762303878,5.7250862,0,0,0,4449,19.98075,-34534.099609375,,,,,,,,,,,,,,,,,13.003003,,,,,,20.0007973,,,,
,15669075.01,20.00048635,-38394.427734375,-0.000130983055529798,4.33127055493832E-7,1,0.999253354069792,40.0298881530762,1.99092236300249,15.6900031119585,-0.00140162014758166,-0.000281884568411647,0.25,-2.91717638821738E-6,-0.000130331033971148,-3.43873325530304E-6,20.0004539,20.0005188,-38424.4765625,-38364.37890625,52.5504486049286,18.6654559462004,5.81130385,0,0,0,4449,19.981,-38394.427734375,,,,,,,,,,,,,,,,,13.003003,,,,,,20.00048635,,,,
,15669152.135,20.00101375,-42246.939453125,-0.000124347794036619,5.17410281938178E-7,1,0.999253354069792,40.0298881530762,1.99088223519534,15.6900031119585,-0.00133028001060999,-0.000270549368500744,0.25,-3.01700772219823E-6,-0.000123746791706089,-3.53441217483828E-6,20.000988,20.0010395,-42276.94140625,-42216.9375,52.7489822488133,18.6650602632938,5.75411295,0,0,0,4449,19.98245,-42246.939453125,,,,,,,,,,,,,,,,,13.378378,,,,,,20.00101375,,,,
,15669228.09,20.00060275,-46045.267578125,-0.000119855515065737,7.16435456745087E-7,1,0.999253354069792,40.0298881530762,1.9909638701182,15.6900031119585,-0.0012829257696957,-0.000258304162722738,0.25,-2.6519976427234E-6,-0.000119296312656938,-3.17357728092763E-6,20.0005417,20.0006638,-46075.21484375,-46015.3203125,52.6098523723902,18.6619383710756,5.6678953,0,0,0,4449,19.97985,-46045.267578125,,,,,,,,,,,,,,,,,12.252253,,,,,,20.00060275,,,,
,15669305.335,19.9996681,-49905.6796875,-0.000110976701639202,5.50681131545708E-7,1,0.999253354069792,40.0298881530762,1.99094111893357,15.6900031119585,-0.0011882234504798,-0.000238383592241364,0.25,-2.35959211317301E-6,-0.000110478029441412,-2.86268685012684E-6,19.999609,19.9997272,-49928.171875,-49883.1875,52.649715426871,18.6657352985175,5.86964895,0,0,0,4449,19.97955,-49905.6796875,,,,,,,,,,,,,,,,,12.252253,,,,,,19.9996681,,,,
,15669381.665,19.9999561,-53720.53125,-0.00010643102449948,6.28480745003036E-7,1,0.999253354069792,40.0298881530762,1.99105610767451,15.6900031119585,-0.00113717056058872,-0.000243457137566105,0.25,-3.62075850553813E-6,-0.000105964654513069,-4.11551442127823E-6,19.9999084,20.0000038,-53750.53125,-53690.53125,52.6841070817171,18.6625608406504,5.86964895,0,0,0,4449,19.97955,-53720.53125,,,,,,,,,,,,,,,,,13.378378,,,,,,19.9999561,,,,
,15669458.85,20.0000038,-57575.736328125,-9.28954135265394E-5,6.77177690214998E-7,1,0.999253354069792,40.0298881530762,1.99100452578829,15.6900031119585,-0.000994459414698135,-0.000202709805802282,0.25,-2.2322327605898E-6,-9.25095201801519E-5,-2.68324607867289E-6,19.9999733,20.0000343,-57598.1875,-57553.28515625,52.8435592996402,18.6665383210623,5.86964895,0,0,0,4449,19.9791,-57575.736328125,,,,,,,,,,,,,,,,,13.378378,,,,,,20.0000038,,,,
,15669535.65,19.99993325,-61415.990234375,-8.82075031437492E-5,6.68577505431983E-7,1,0.999253354069792,40.0298881530762,1.99094466595834,15.6900031119585,-0.000944485851206307,-0.000192162753730189,0.25,-2.07388593977514E-6,-8.78575950078229E-5,-2.51609263565304E-6,19.9997349,20.0001316,-61440.76171875,-61391.21875,52.8287083577748,18.6648154613988,5.8403306,0,0,0,4449,19.9804,-61415.990234375,,,,,,,,,,,,,,,,,13.003003,,,,,,19.99993325,,,,
,15669611.09,19.9991837,-65186.82421875,-7.82166084278231E-5,6.00859625217211E-7,1,0.999253354069792,40.0298881530762,1.99098902640029,15.6900031119585,-0.00083767086695972,-0.000170496510486335,0.25,-1.83390053735154E-6,-7.79208874658607E-5,-2.23742844495593E-6,19.9991589,19.9992085,-65219.35546875,-65154.29296875,52.6880152243133,18.6654216495081,5.81188395,0,0,0,4449,19.97995,-65186.82421875,,,,,,,,,,,,,,,,,13.003003,,,,,,19.9991837,,,,
,15669688.26,19.9996357,-69041.9921875,-6.71158573624227E-5,7.8178653108022E-7,1,0.999253354069792,40.0298881530762,1.99095711655142,15.6900031119585,-0.000721670866878232,-0.000130964262965291,0.25,-1.36443958482455E-7,-6.68828493467071E-5,-4.97122165392273E-7,19.9995365,19.9997349,-69066.875,-69017.109375,52.6575317120633,18.6648899642131,5.7825656,0,0,0,4449,19.97885,-69041.9921875,,,,,,,,,,,,,,,,,13.003003,,,,,,19.9996357,,,,
,15669765.145,19.9990654,-72884.89453125,-5.71843395504747E-5,9.38270583323204E-7,1,0.999253354069792,40.0298881530762,1.99097020338486,15.6900031119585,-0.000612970509783132,-0.000122960329379575,0.25,-1.16422285206565E-6,-5.69914384440666E-5,-1.47541470796499E-6,19.9989014,19.9992294,-72919.9375,-72849.8515625,52.7536720199287,18.6645255689762,5.8403306,0,0,0,4449,19.982,-72884.89453125,,,,,,,,,,,,,,,,,13.003003,,,,,,19.9990654,,,,
,15669842.875,19.99918745,-76770.140625,-4.85910969447669E-5,1.01866873756481E-6,1,0.999253354069792,40.0298881530762,1.99107787843667,15.6900031119585,-0.000521101853590156,-0.000103887955121124,0.25,-9.25733447797613E-7,-4.84373514165293E-5,-1.19638948820464E-6,19.9991226,19.9992523,-76797.6875,-76742.59375,52.6442440272363,18.667159513133,5.8989673,0,0,0,4449,19.9845,-76770.140625,,,,,,,,,,,,,,,,,13.378378,,,,,,19.99918745,,,,
,15669921.22,19.9987946,-80685.8515625,-3.87700676297205E-5,8.65857719122046E-7,1,0.999253354069792,40.0298881530762,1.99106230009189,15.6900031119585,-0.000413018655481082,-9.87255418015216E-5,0.25,-2.20402134222657E-6,-3.86469587334608E-5,-2.42029528164947E-6,19.9987946,19.9987946,-80690.8515625,-80680.8515625,52.6489337983517,18.6629061852544,5.8989673,0,0,0,4449,19.982,-80685.8515625,,,,,,,,,,,,,,,,,13.378378,,,,,,19.9987946,,,,
,15669996.54,19.99953365,-84447.68359375,-3.04406478504608E-5,1.090957456821E-6,1,0.999253354069792,40.0298881530762,1.99111100601669,15.6900031119585,-0.000327301825040368,-6.11541117129407E-5,0.25,-2.06114392344202E-7,-3.03588348269281E-5,-3.83329608374695E-7,19.999506,19.9995613,-84482.59375,-84412.7734375,52.8435592996402,18.6614063279804,5.81188395,0,0,0,4449,19.98405,-84447.68359375,,,,,,,,,,,,,,,,,13.003003,,,,,,19.99953365,,,,
,15670074.585,19.99892425,-88350.75390625,-1.82944239924977E-5,1.17003761233149E-6,1,0.999253354069792,40.0298881530762,1.99102750461569,15.6900031119585,-0.00019218623698736,-6.20521367171838E-5,0.25,-2.47131640640716E-6,-1.82351410878384E-5,-2.57384697614694E-6,19.9988537,19.9989948,-88380.796875,-88320.7109375,52.616105400544,18.6689564317186,5.86964895,0,0,0,4449,19.98455,-88350.75390625,,,,,,,,,,,,,,,,,13.378378,,,,,,19.99892425,,,,
,15670170.975,19.99947835,-87696.8125,-1.90236870634563E-5,1.04665870862778E-6,1,0.999253354069792,40.0298881530762,1.99122727075514,15.6900031119585,-0.000205490416060684,-3.32340902075846E-5,0.25,3.36345795850224E-7,-1.89786135173741E-5,2.22917580530257E-7,19.9992943,19.9996624,-87721.796875,-87671.828125,52.7849371606979,18.6645794534731,5.8989673,0,0,0,4449,19.98385,-87696.8125,,,,,,,,,,,,,,,,,12.252253,,,,,,19.99947835,,,,
,15670248.075,20.0011406,-83846.69140625,-3.29263566429295E-5,1.17508302803135E-6,1,0.999253354069792,40.0298881530762,1.99111243587865,15.6900031119585,-0.000350607768408445,-8.51056532572278E-5,0.25,-1.98471348647636E-6,-3.28265458828028E-5,-2.17116636494838E-6,20.001133,20.0011482,-83869.3046875,-83824.078125,52.8466858137171,18.6642509924734,5.9285798,0,0,0,4449,19.98305,-83846.69140625,,,,,,,,,,,,,,,,,13.003003,,,,,,20.0011406,,,,
,15670329.515,20.00032425,-79773.8984375,-4.16957500267362E-5,9.10927564793588E-7,1,0.999253354069792,40.0298881530762,1.99100817990051,15.6900031119585,-0.000450143564576013,-7.28378775788704E-5,0.25,7.25541328025932E-7,-4.15790800833803E-5,4.8514593498239E-7,20.0002975,20.000351,-79801.3828125,-79746.4140625,52.656750083544,18.6643628042814,5.8403306,0,0,0,4449,19.9827,-79773.8984375,,,,,,,,,,,,,,,,,13.378378,,,,,,20.00032425,,,,
,15670409.39,20.00156785,-75783.62109375,-4.77983307841289E-5,6.10185259149888E-7,1,0.999253354069792,40.0298881530762,1.99100467349012,15.6900031119585,-0.000513003804274571,-9.96890185913252E-5,0.25,-6.80150408687918E-7,-4.76459195612E-5,-9.45642292016698E-7,20.0014534,20.0016823,-75813.5625,-75753.6796875,52.7630515621594,18.6649002019494,5.81188395,0,0,0,4449,19.98205,-75783.62109375,,,,,,,,,,,,,,,,,13.378378,,,,,,20.00156785,,,,
,15670485.955,20.00185775,-71956.4140625,-5.98261450319572E-5,1.05704929228525E-6,1,0.999253354069792,40.0298881530762,1.99112306084945,15.6900031119585,-0.00064115750193373,-0.000129460685567643,0.25,-1.29570230918435E-6,-5.96210427560522E-5,-1.61916136724123E-6,20.0018177,20.0018978,-71986.34375,-71926.484375,52.5527934904863,18.6632588305028,5.7825656,0,0,0,4449,19.98195,-71956.4140625,,,,,,,,,,,,,,,,,12.252253,,,,,,20.00185775,,,,
,15670563.19,20.0012169,-68098.92578125,-7.01799941844589E-5,6.75564131114199E-7,1,0.999253354069792,40.0298881530762,1.99107060377163,15.6900031119585,-0.000751596152846638,-0.00015381679618122,0.25,-1.71352976779689E-6,-6.99245500627855E-5,-2.08287533720666E-6,20.0012169,20.0012169,-68104.0859375,-68093.765625,52.6645663687363,18.6633885127841,5.8989673,0,0,0,4449,19.983,-68098.92578125,,,,,,,,,,,,,,,,,13.378378,,,,,,20.0012169,,,,
,15670640.62,20.0010681,-64228.4375,-7.98357942390709E-5,6.30580048208067E-7,1,0.999253354069792,40.0298881530762,1.99099140645901,15.6900031119585,-0.000856809910463484,-0.000163760101350704,0.25,-9.20836871234936E-7,-7.95351090113389E-5,-1.33334970039997E-6,20.0010128,20.0011234,-64255.9140625,-64200.9609375,52.7028661661787,18.6634268904216,5.86964895,0,0,0,4449,19.98275,-64228.4375,,,,,,,,,,,,,,,,,13.378378,,,,,,20.0010681,,,,
,15670716.995,20.00040815,-60410.244140625,-8.88551633331775E-5,5.57483416137042E-7,1,0.999253354069792,40.0298881530762,1.99088386915882,15.6900031119585,-0.000953643393015643,-0.000180730185644517,0.25,-8.99455078933352E-7,-8.85043727685656E-5,-1.34597780937864E-6,20.0002975,20.0005188,-60442.70703125,-60377.78125,52.605944229794,18.6656925720196,5.8989673,0,0,0,4449,19.97985,-60410.244140625,,,,,,,,,,,,,,,,,13.003003,,,,,,20.00040815,,,,
,15670793.985,20.00123115,-56562.275390625,-9.9123185565544E-5,6.33474103104856E-7,1,0.999253354069792,40.0298881530762,1.99085457998748,15.6900031119585,-0.00106301042395698,-0.000205047340702196,0.25,-1.34166309076018E-6,-9.87117893094711E-5,-1.82295224119962E-6,20.0010738,20.0013885,-56594.75,-56529.80078125,52.7192803650825,18.6643550087375,5.8989673,0,0,0,4449,19.9808,-56562.275390625,,,,,,,,,,,,,,,,,13.378378,,,,,,20.00123115,,,,
,15670871.11,20.0009565,-52710.080078125,-0.000107342430045517,5.876069369085E-7,1,0.999253354069792,40.0298881530762,1.99099728215812,15.6900031119585,-0.00115165799343898,-0.00021847444304014,0.25,-1.13999476028279E-6,-0.000106879081960666,-1.64490342184745E-6,20.0008926,20.0010204,-52737.60546875,-52682.5546875,52.720843622121,18.6648815285059,5.8702347,0,0,0,4449,19.9809,-52710.080078125,,,,,,,,,,,,,,,,,13.003003,,,,,,20.0009565,,,,
,15670948,20.0011387,-48864.47265625,-0.00011711107439011,5.03956817495984E-7,1,0.999253354069792,40.0298881530762,1.99090733248595,15.6900031119585,-0.0012572279604169,-0.00023248911505099,0.25,-7.22359270373217E-7,-0.000116587536288727,-1.25557379246519E-6,20.0011158,20.0011616,-48889.44921875,-48839.49609375,52.5910932879286,18.662685253542,5.8406222,0,0,0,4449,19.978,-48864.47265625,,,,,,,,,,,,,,,,,13.003003,,,,,,20.0011387,,,,
,15671023.81,20.0014954,-45077.08984375,-0.000126067038725048,4.84783677877107E-7,1,0.999253354069792,40.0298881530762,1.99079357262488,15.6900031119585,-0.00135123699430876,-0.000260510598983353,0.25,-1.7576688031285E-6,-0.000125478221856675,-2.3052893127142E-6,20.0014706,20.0015202,-45102,-45052.1796875,52.7708678473517,18.6643994696667,5.9285798,0,0,0,4449,19.9785,-45077.08984375,,,,,,,,,,,,,,,,,13.378378,,,,,,20.0014954,,,,
,15671100.51,20.0007095,-41243.75390625,-0.000133129268829889,5.27443654136251E-7,1,0.999253354069792,40.0298881530762,1.99076730050069,15.6900031119585,-0.00142660769117773,-0.000275491605562733,0.25,-1.92064118823733E-6,-0.00013248595219181,-2.47433773649094E-6,20.0006599,20.0007591,-41268.71875,-41218.7890625,52.5332527775056,18.6626540767981,5.8406222,0,0,0,4449,19.97795,-41243.75390625,,,,,,,,,,,,,,,,,13.378378,,,,,,20.0007095,,,,
,15671178.015,20.00059605,-37368.3984375,-0.0001430964470814,4.71016373984343E-7,1,0.999253354069792,40.0298881530762,1.99108724878334,15.6900031119585,-0.00153167938610917,-0.000305841257544369,0.25,-2.99645665150623E-6,-0.000142379245982171,-3.55988560256107E-6,20.0005093,20.0006828,-37395.98828125,-37340.80859375,52.5715525749479,18.6601110783817,5.9285798,0,0,0,4449,19.9783,-37368.3984375,,,,,,,,,,,,,,,,,13.003003,,,,,,20.00059605,,,,
,15671253.87,20.00004675,-33580.650390625,-0.000151700037532499,4.08124776193323E-7,1,0.999253354069792,40.0298881530762,1.9910211132005,15.6900031119585,-0.00162583448778275,-0.000310982287253016,0.25,-1.97711933713383E-6,-0.000150922995812352,-2.55164229635443E-6,19.9998436,20.0002499,-33613.1796875,-33548.12109375,52.964711720121,18.6609728583819,5.8406222,0,0,0,4449,19.97855,-33580.650390625,,,,,,,,,,,,,,,,,13.003003,,,,,,20.00004675,,,,
,15671329.225,20.00024985,-29812.60546875,-0.000159866347524234,4.19809559236378E-7,1,0.999253354069792,40.0298881530762,1.99102210255748,15.6900031119585,-0.00171398306957367,-0.000322857501460837,0.25,-1.66501608891131E-6,-0.000159027731814145,-2.24208577387884E-6,20.0001945,20.0003052,-29844.966796875,-29780.244140625,52.741165963621,18.6593845610924,5.9581923,0,0,0,4449,19.9783,-29812.60546875,,,,,,,,,,,,,,,,,13.378378,,,,,,20.00024985,,,,
,15671406.165,20.0006361,-25969.703125,-0.00016705708330375,5.01970576222817E-7,1,0.999253354069792,40.0298881530762,1.99115997204976,15.6900031119585,-0.00179203445584026,-0.000331323876319874,0.25,-1.21082056731779E-6,-0.000166161314129983,-1.78382727359554E-6,20.0006008,20.0006714,-25997.0625,-25942.34375,52.5184018356402,18.6568084672694,5.90014455,0,0,0,4449,19.97635,-25969.703125,,,,,,,,,,,,,,,,,12.252253,,,,,,20.0006361,,,,
,15671481.69,20.0004959,-22193.8193359375,-0.00017530437025019,4.06435854506956E-7,1,0.999253354069792,40.0298881530762,1.99099073819909,15.6900031119585,-0.00187766577912719,-0.000361527497468463,0.25,-2.60023506000241E-6,-0.000174339606381575,-3.16038864246629E-6,20.0003643,20.0006275,-22218.783203125,-22168.85546875,52.6356461135248,18.66268384958,5.8406222,0,0,0,4449,19.978,-22193.8193359375,,,,,,,,,,,,,,,,,13.003003,,,,,,20.0004959,,,,
,15671558.59,20.0004816,-18351.1416015625,-0.000182307925842743,4.78336827775849E-7,1,0.999253354069792,40.0298881530762,1.99092670377594,15.6900031119585,-0.0019532986083326,-0.000370891449373506,0.25,-2.27164990430453E-6,-0.000181286371357473,-2.82073229346506E-6,20.0004368,20.0005264,-18376.158203125,-18326.125,52.4480552689094,18.6587926658192,5.8989673,0,0,0,4449,19.9772,-18351.1416015625,,,,,,,,,,,,,,,,,13.003003,,,,,,20.0004816,,,,
,15671633.945,19.9997311,-14585.748046875,-0.000187927067171938,3.19060319825037E-7,1,0.999253354069792,40.0298881530762,1.99092618317475,15.6900031119585,-0.00201332831776561,-0.00038217036732164,0.25,-2.36644253175842E-6,-0.000186855931117563,-2.89668496218054E-6,19.9996796,19.9997826,-14613.169921875,-14558.326171875,52.6067258583133,18.6589842053138,5.8702347,0,0,0,4449,19.9763,-14585.748046875,,,,,,,,,,,,,,,,,13.003003,,,,,,19.9997311,,,,
,15671711.82,19.9995613,-10692.5454101562,-0.000193271560719448,2.90258223643789E-7,1,0.999253354069792,40.0298881530762,1.99105807564701,15.6900031119585,-0.00207039598633523,-0.000393785512078254,0.25,-2.54096155762155E-6,-0.000192152565957748,-3.04890917502441E-6,19.9994602,19.9996624,-10714.9384765625,-10670.15234375,52.8693530407748,18.656949455752,5.8989673,0,0,0,4449,19.97875,-10692.5454101562,,,,,,,,,,,,,,,,,13.378378,,,,,,19.9995613,,,,
,15671789.135,19.9998064,-6826.68872070312,-0.000193411154120869,2.82708440361215E-7,1,0.999253354069792,40.0298881530762,1.99093763125851,15.6900031119585,-0.00207131794476352,-0.000395687688372698,0.25,-2.73303989327853E-6,-0.000192276065875433,-3.20558684449234E-6,19.999773,19.9998398,-6856.7490234375,-6796.62841796875,52.7388210780633,18.6579224549936,5.8702347,0,0,0,4449,19.97875,-6826.68872070312,,,,,,,,,,,,,,,,,12.252253,,,,,,19.9998064,,,,
,15671866.705,19.99836635,-2950.51354980469,-0.000151913383019299,2.46616891302972E-7,1,0.999253354069792,40.0298881530762,1.99104183365292,15.6900031119585,-0.00162631280763302,-0.000313985882423321,0.25,-2.46940868919265E-6,-0.000151011387645822,-2.81399247243399E-6,19.9982185,19.9985142,-2978.10766601562,-2922.91943359375,52.605944229794,18.65880358815,5.8989673,0,0,0,4449,19.9755,-2950.51354980469,,,,,,,,,,,,,,,,,12.252253,,,,,,19.99836635,,,,
,15671942.045,20.0008173,814.721588134766,-3.52266167227302E-5,3.02085589606224E-7,1,0.999253354069792,40.0298881530762,1.99083099455868,15.6900031119585,-0.000373126711859537,-9.51896792215385E-5,0.25,-2.66092513723944E-6,-3.5011711002397E-5,-2.72583412363904E-6,20.0008106,20.000824,789.9384765625,839.504699707031,52.4769755241209,18.6611767113813,5.90014455,0,0,0,4449,19.9794,814.721588134766,,,,,,,,,,,,,,,,,13.378378,,,,,,20.0008173,,,,
,15672020.01,20.00059035,4708.29565429687,3.02777337009303E-5,2.41811672830134E-7,1,0.999253354069792,40.0298881530762,1.99097561869957,15.6900031119585,0.000329355752254766,3.2988038762577E-5,0.25,-2.26626562584724E-6,3.01054905938055E-5,-2.17924840724489E-6,20.0005169,20.0006638,4675.8056640625,4740.78564453125,52.7474189917748,18.6576963486568,5.8702347,0,0,0,4449,19.97935,4708.29565429687,,,,,,,,,,,,,,,,,13.003003,,,,,,20.00059035,,,,
,15672097.39,20.0006199,8576.78955078125,5.01370500032251E-5,3.43034505355864E-7,1,0.999253354069792,40.0298881530762,1.99061603487099,15.6900031119585,0.000542835012773537,6.87882454768999E-5,0.25,-2.44153779195414E-6,4.98526721119512E-5,-2.29678413973688E-6,20.0006027,20.0006371,8544.25,8609.3291015625,52.372237302544,18.6584912360049,5.95848965,0,0,0,4449,19.979,8576.78955078125,,,,,,,,,,,,,,,,,12.252253,,,,,,20.0006199,,,,
,15672175.545,20.0018101,12482.81640625,5.57378914379569E-5,3.15581914090911E-7,1,0.999253354069792,40.0298881530762,1.99094867505179,15.6900031119585,0.000602823299311739,8.10459717169443E-5,0.25,-2.30052868005046E-6,5.54258353257866E-5,-2.13188383956307E-6,20.0018101,20.0018101,12477.79296875,12487.83984375,52.4652510963325,18.6546812672591,5.8989673,0,0,0,4449,19.97855,12482.81640625,,,,,,,,,,,,,,,,,13.003003,,,,,,20.0018101,,,,
,15672252.04,20.00163175,16306.091796875,6.63320596345661E-5,3.36837840238542E-7,1,0.999253354069792,40.0298881530762,1.99078229614125,15.6900031119585,0.000716765364133152,0.000100153734058903,0.25,-2.40568223990767E-6,6.59664614963911E-5,-2.19459832078279E-6,20.0015507,20.0017128,16286.1201171875,16326.0634765625,52.565299546794,18.6579056769601,5.98810215,0,0,0,4449,19.9771,16306.091796875,,,,,,,,,,,,,,,,,13.378378,,,,,,20.00163175,,,,
,15672329.245,20.00056935,20166.64453125,8.45132723220905E-5,3.60806530883566E-7,1,0.999253354069792,40.0298881530762,1.99075599484434,15.6900031119585,0.000911570624711519,0.000137489806561818,0.25,-2.16223524545053E-6,8.40541063013132E-5,-1.88214989736624E-6,20.0005417,20.000597,20134.18359375,20199.10546875,52.6043809727556,18.657433405482,5.9581923,0,0,0,4449,19.9744,20166.64453125,,,,,,,,,,,,,,,,,13.003003,,,,,,20.00056935,,,,
,15672405.93,20.00208475,23997.2548828125,0.000106563071958902,4.19225377655569E-7,1,0.999253354069792,40.0298881530762,1.99093419790207,15.6900031119585,0.00114991392936693,0.000171843478786057,0.25,-2.89190201879363E-6,0.000105997408249252,-2.51736953859505E-6,20.0020218,20.0021477,23972.205078125,24022.3046875,52.609070743871,18.6553777264219,5.98810215,0,0,0,4449,19.97625,23997.2548828125,,,,,,,,,,,,,,,,,12.252253,,,,,,20.00208475,,,,
,15672482.75,20.0014553,27837.822265625,0.000122515254532585,3.76642347439426E-7,1,0.999253354069792,40.0298881530762,1.99086658210269,15.6900031119585,0.00131949429963209,0.000212739495551443,0.25,-1.93806349588628E-6,0.000121875869656777,-1.49122214992786E-6,20.0014553,20.0014553,27835.24609375,27840.3984375,52.3253395913902,18.6571644657089,5.9581923,0,0,0,4449,19.9773,27837.822265625,,,,,,,,,,,,,,,,,13.003003,,,,,,20.0014553,,,,
,15672560.055,20.0016518,31700.9501953125,0.000130972748817876,4.10484146497888E-7,1,0.999253354069792,40.0298881530762,1.99076425175865,15.6900031119585,0.00141064787944646,0.000227792800782278,0.25,-2.06521237378138E-6,0.000130307212366565,-1.5622578928267E-6,20.0015755,20.0017281,31673.361328125,31728.5390625,52.6848887102363,18.6568824048904,5.9285798,0,0,0,4449,19.9746,31700.9501953125,,,,,,,,,,,,,,,,,12.252253,,,,,,20.0016518,,,,
,15672637.315,20.0012817,35563.505859375,0.000132339612327322,3.94702606651841E-7,1,0.999253354069792,40.0298881530762,1.99078337291263,15.6900031119585,0.00142643572151633,0.000225471994885005,0.25,-2.5530540366432E-6,0.00013168834779698,-2.01732616650745E-6,20.0012817,20.0012817,35555.95703125,35571.0546875,52.5324711489863,18.6572252891437,5.8702347,0,0,0,4449,19.9742,35563.505859375,,,,,,,,,,,,,,,,,12.252253,,,,,,20.0012817,,,,
,15672712.46,20.0005627,39319.04296875,0.000131587862395163,5.06773134599722E-7,1,0.999253354069792,40.0298881530762,1.99104305832886,15.6900031119585,0.00141685836930207,0.000234727773146688,0.25,-1.58785779648755E-6,0.000130956244193833,-1.03598719241265E-6,20.0005093,20.0006161,39289.3125,39348.7734375,52.6028177157171,18.6555837220176,5.8702347,0,0,0,4449,19.9748,39319.04296875,,,,,,,,,,,,,,,,,13.378378,,,,,,20.0005627,,,,
,15672791.26,20.0000439,43254.55078125,0.000125561631856205,5.10168838051873E-7,1,0.999253354069792,40.0298881530762,1.99100703208839,15.6900031119585,0.00135459155621131,0.000210448923388684,0.25,-2.80089191902233E-6,0.000124985196434867,-2.24495930731946E-6,20.0000439,20.0000439,43251.94921875,43257.15234375,52.1369671182555,18.6555372695456,6.018012,0,0,0,4449,19.9711,43254.55078125,,,,,,,,,,,,,,,,,13.003003,,,,,,20.0000439,,,,
,15672869.25,20.0000095,47153.09375,0.000117000302059306,4.13852245752911E-7,1,0.999253354069792,40.0298881530762,1.99086914450461,15.6900031119585,0.00126354619825885,0.00018951568605866,0.25,-3.24568333562537E-6,0.000116486246516826,-2.70413453079001E-6,20.0000095,20.0000095,47150.65234375,47155.53515625,52.4222615277748,18.6582729566638,6.018012,0,0,0,4449,19.9733,47153.09375,,,,,,,,,,,,,,,,,13.378378,,,,,,20.0000095,,,,
,15672945.42,20.000515,50963.572265625,0.000109875661855303,5.03547372554758E-7,1,0.999253354069792,40.0298881530762,1.99093414500468,15.6900031119585,0.00118824532019308,0.000170208799959077,0.25,-3.79276942880225E-6,0.000109415766442616,-3.26280635719794E-6,20.0003796,20.0006504,50933.53515625,50993.609375,52.3128335350824,18.6568103076405,5.9581923,0,0,0,4449,19.97515,50963.572265625,,,,,,,,,,,,,,,,,12.252253,,,,,,20.000515,,,,
,15673021.915,19.9992199,54784.0546875,0.000104395958797614,4.69262770311365E-7,1,0.999253354069792,40.0298881530762,1.99080498653282,15.6900031119585,0.00112885075219761,0.000163276483041417,0.25,-3.47778723415435E-6,0.000103977573265043,-2.95833700794212E-6,19.9991989,19.9992409,54781.74609375,54786.36328125,52.5707709464286,18.6533724105537,5.7822771,0,0,0,4449,19.9732,54784.0546875,,,,,,,,,,,,,,,,,13.003003,,,,,,19.9992199,,,,
,15673097.115,20.00009345,58544.9296875,9.37820272060872E-5,6.21908268901356E-7,1,0.999253354069792,40.0298881530762,1.99073198266136,15.6900031119585,0.00101455201088386,0.00014492987557887,0.25,-3.30316451947003E-6,9.34244992155958E-5,-2.82192864904841E-6,20.0000267,20.0001602,58514.8359375,58575.0234375,52.3667659029094,18.6526404619328,5.9285798,0,0,0,4449,19.9736,58544.9296875,,,,,,,,,,,,,,,,,13.003003,,,,,,20.00009345,,,,
,15673173.46,19.9996271,62357.626953125,8.52390432840411E-5,5.97820323858623E-7,1,0.999253354069792,40.0298881530762,1.99074033420458,15.6900031119585,0.000926050409381965,0.00011090350585694,0.25,-4.95408141079309E-6,8.4940584822866E-5,-4.49716000855709E-6,19.9995365,19.9997177,62327.57421875,62387.6796875,52.6137605149863,18.6545002874212,5.98810215,0,0,0,4449,19.974,62357.626953125,,,,,,,,,,,,,,,,,13.378378,,,,,,19.9996271,,,,
,15673250.71,19.99893665,66218.80859375,7.42005917518355E-5,7.58853687648918E-7,1,0.999253354069792,40.0298881530762,1.99079829511903,15.6900031119585,0.000801150671097694,0.000125364436751573,0.25,-1.64506066273664E-6,7.39417500944368E-5,-1.24719664372083E-6,19.9989338,19.9989395,66191.53125,66246.0859375,52.4425838692748,18.6566203922214,5.98810215,0,0,0,4449,19.97395,66218.80859375,,,,,,,,,,,,,,,,,13.003003,,,,,,19.99893665,,,,
,15673327.76,19.9986277,70072.22265625,6.43620455652715E-5,6.79047469820639E-7,1,0.999253354069792,40.0298881530762,1.99075572661472,15.6900031119585,0.000695714728613294,0.000105053876355198,0.25,-1.7802335050413E-6,6.41523638884994E-5,-1.42558878612059E-6,19.9985867,19.9986687,70044.6953125,70099.75,52.4457103833517,18.6528841537738,5.98810215,0,0,0,4449,19.9732,70072.22265625,,,,,,,,,,,,,,,,,13.378378,,,,,,19.9986277,,,,
,15673404.955,19.99875355,73930.10546875,5.74931243019607E-5,6.77302364417848E-7,1,0.999253354069792,40.0298881530762,1.99079101348863,15.6900031119585,0.000623908793481266,8.10270681338071E-5,0.25,-2.79056664622656E-6,5.73242336152617E-5,-2.46302734005503E-6,19.9986801,19.998827,73907.515625,73952.6953125,52.6716010254094,18.65247072177,5.98810215,0,0,0,4449,19.97445,73930.10546875,,,,,,,,,,,,,,,,,13.003003,,,,,,19.99875355,,,,
,15673481.725,19.9996262,77765.82421875,4.56204490140261E-5,6.1615140166338E-7,1,0.999253354069792,40.0298881530762,1.99075528715204,15.6900031119585,0.000502135353185172,2.54981718322873E-5,0.25,-5.82635693895214E-6,4.55163549271026E-5,-5.55075191459754E-6,19.9996014,19.999651,77741.0390625,77790.609375,52.3550414751209,18.6526965019598,5.98810215,0,0,0,4449,19.9741,77765.82421875,,,,,,,,,,,,,,,,,13.378378,,,,,,19.9996262,,,,
,15673558.345,19.99977305,81596.53515625,3.57067965934906E-5,6.71168840195866E-7,1,0.999253354069792,40.0298881530762,1.99072631094612,15.6900031119585,0.000392927302214099,2.09122119564623E-5,0.25,-4.47576015833839E-6,3.56326014930132E-5,-4.25737277725247E-6,19.9996853,19.9998608,81568.8671875,81624.203125,52.5520118619671,18.6547850155121,5.8702347,0,0,0,4449,19.9777,81596.53515625,,,,,,,,,,,,,,,,,13.378378,,,,,,19.99977305,,,,
,15673636.005,19.9988613,85477.01171875,2.72322869806646E-5,6.40589596050028E-7,1,0.999253354069792,40.0298881530762,1.99072018355698,15.6900031119585,0.000302554271492882,2.89051507771605E-7,0.25,-4.8714412528365E-6,2.71902445513265E-5,-4.6990843294243E-6,19.9987278,19.9989948,85457.0859375,85496.9375,52.3816168447748,18.649767614556,5.9291713,0,0,0,4449,19.9766,85477.01171875,,,,,,,,,,,,,,,,,12.252253,,,,,,19.9988613,,,,
,15673710.895,19.99818515,89219.73828125,1.75923501783213E-5,6.69071518921314E-7,1,0.999253354069792,40.0298881530762,1.99069595631026,15.6900031119585,0.000198691653233326,-1.75842534331197E-5,0.25,-4.79930328398414E-6,1.75788368008354E-5,-4.68308172340046E-6,19.9981556,19.9982147,89189.6640625,89249.8125,52.6114156294286,18.6542995737402,5.9581923,0,0,0,4449,19.9787,89219.73828125,,,,,,,,,,,,,,,,,13.378378,,,,,,19.99818515,,,,
,15673728.125,19.9990673,89999.56640625,1.0768401690203E-5,7.16861086073619E-7,1,0.999253354069792,40.0298881530762,1.99069436671394,15.6900031119585,0.000125713131718912,-3.34720388294404E-5,0.25,-5.04711215936699E-6,1.07732271298111E-5,-4.97094916569971E-6,19.9990158,19.9991188,89999.5546875,89999.578125,52.3183049347171,18.651685974559,5.98810215,0,0,0,4417,19.97725,89999.56640625,,,,,,,,,,,,,,,,,12.252253,,,,,,19.9990673,,,,