File: data/doubleLayers/dl_1-25/ppms/DD205_3_HYST_5K_1OE.DAT
[Header]
; VSM Data File (default extension .dat)
; Copyright (c) 2003, Quantum Design, Inc. All rights reserved.
TITLE,
FILEOPENTIME,15643993.59,04/16/2018,7:07 pm
BYAPP,VSM,1.0,1.0
INFO,PPMS VSM Option Release 1.3.7 Build 2,APPNAME
INFO,291,COIL_SERIAL_NUMBER
INFO,0,MOMENT_UNITS
INFO,,SAMPLE_MATERIAL
INFO,,SAMPLE_COMMENT
INFO,,SAMPLE_MASS
INFO,,SAMPLE_VOLUME
INFO,,SAMPLE_MOLECULAR_WEIGHT
INFO,,SAMPLE_SIZE
INFO,,SAMPLE_SHAPE
INFO,36.06,SAMPLE_OFFSET
DATATYPE,COMMENT,1
DATATYPE,TIME,2
STARTUPAXIS,X,2
STARTUPAXIS,Y1,5
[Data]
Comment,Time Stamp (sec),Temperature (K),Magnetic Field (Oe),Moment (emu),M. Std. Err. (emu),Transport Action,Averaging Time (sec),Frequency (Hz),Peak Amplitude (mm),Center Position (mm),Coil Signal' (mV),Coil Signal" (mV),Range (mV),M. Quad. Signal (emu),M. Raw' (emu),M. Raw" (emu),Min. Temperature (K),Max. Temperature (K),Min. Field (Oe),Max. Field (Oe),Mass (grams),Motor Lag (deg),Pressure (Torr),VSM Status (code),Motor Status (code),Measure Status (code),PPMS Status (code),System Temp. (K),System Field (Oe),Sample Position (deg),Bridge 1 Resistance (ohms),Bridge 1 Excitation (에),Bridge 2 Resistance (ohms),Bridge 2 Excitation (에),Bridge 3 Resistance (ohms),Bridge 3 Excitation (에),Bridge 4 Resistance (ohms),Bridge 4 Excitation (에),Signal 1 Vin (V),Signal 2 Vin (V),Digital Inputs (code),Drive 1 Iout (mA),Drive 1 Ipower (W),Drive 2 Iout (mA),Drive 2 Ipower (W),Pressure (),Map 20 (),Map 21 (),Map 22 (),Map 23 (),Map 24 (),Map 25 (),Map 26 (),Map 27 (),Map 28 (),Map 29 ()
,15644014.65,5.0100031,99.6931686401367,2.42613399927605E-5,2.11475464066455E-7,1,0.999253354069792,40.0298881530762,2.00552774233274,15.6900031119585,0.00026646122673556,2.23363101435365E-5,0.25,-2.20608432290922E-6,2.41223884741127E-5,-2.13938128293737E-6,5.0093155,5.0106907,99.6931686401367,99.6931686401367,52.670037768371,18.6663469287388,3.0815613,0,0,0,4417,4.9561,99.6931686401367,,,,,,,,,,,,,,,,,12.252253,,,,,,5.0100031,,,,
,15644112.95,5.0075488,4227.55029296875,0.000117094650732723,2.51232473302966E-7,1,0.999253354069792,40.0298881530762,2.0055336094904,15.6900031119585,0.00127040833531124,0.00019705331384622,0.25,-2.40924172869862E-6,0.000116412552598588,-2.11934667708761E-6,5.0075488,5.0075488,4222.58544921875,4232.51513671875,52.2721888520825,18.6755344819781,3.0509303,0,0,0,4449,4.954,4227.55029296875,,,,,,,,,,,,,,,,,13.378378,,,,,,5.0075488,,,,
,15644193.385,5.00297855,8243.8515625,0.000149802330085362,2.27223941265738E-7,1,0.999253354069792,40.0298881530762,2.00564345253554,15.6900031119585,0.00162329899262872,0.000264468188199947,0.25,-1.96741576693707E-6,0.000148938255274929,-1.57674013535898E-6,5.0025463,5.0034108,8218.8896484375,8268.8134765625,52.7122457084094,18.6725129343006,3.00559105,0,0,0,4449,4.95145,8243.8515625,,,,,,,,,,,,,,,,,13.378378,,,,,,5.00297855,,,,
,15644276.99,5.0056357,12422.3227539062,0.000154063199355718,2.29049183267615E-7,1,0.999253354069792,40.0298881530762,2.00538307925592,15.6900031119585,0.0016689115106281,0.00027487190681458,0.25,-1.78704049851468E-6,0.000153188047006334,-1.35599071784231E-6,5.0056357,5.0056357,12417.3515625,12427.2939453125,52.7747759899479,18.673319260965,2.9168512,0,0,0,4449,4.95185,12422.3227539062,,,,,,,,,,,,,,,,,13.378378,,,,,,5.0056357,,,,
,15644358.085,5.00724385,16475.4638671875,0.000157357425126537,2.98476781570663E-7,1,0.999253354069792,40.0298881530762,2.00554227154466,15.6900031119585,0.00170511297744155,0.000279587486679216,0.25,-1.96932700747276E-6,0.000156479913205382,-1.49655478166096E-6,5.0055213,5.0089664,16440.5625,16510.365234375,52.6825438246787,18.6710758531145,2.8448706,0,0,0,4449,4.95145,16475.4638671875,,,,,,,,,,,,,,,,,13.753754,,,,,,5.00724385,,,,
,15644444.32,4.99053025,20785.0791015625,0.000162528733829467,2.58792963633678E-7,1,0.999253354069792,40.0298881530762,2.00551783257413,15.6900031119585,0.00176137464135868,0.000288631941124658,0.25,-2.08627327872493E-6,0.00016164215366794,-1.56208295807746E-6,4.9900465,4.991014,20757.453125,20812.705078125,52.5527934904863,18.679348366881,2.8878572,0,0,0,4449,4.94075,20785.0791015625,,,,,,,,,,,,,,,,,13.003003,,,,,,4.99053025,,,,
,15644530.68,5.0013523,25103.431640625,0.000169034267322541,4.39646931563608E-7,1,0.999253354069792,40.0298881530762,2.00556033108251,15.6900031119585,0.00183258477331302,0.00029784270401578,0.25,-2.42852165770339E-6,0.00016813566011379,-1.84454737745406E-6,5.0013523,5.0013523,25095.953125,25110.91015625,52.7693045903133,18.6743363859301,2.8734326,0,0,0,4449,4.9473,25103.431640625,,,,,,,,,,,,,,,,,12.252253,,,,,,5.0013523,,,,
,15644616.935,5.005084,29413.443359375,0.000175695514806438,3.96160475937399E-7,1,0.999253354069792,40.0298881530762,2.00552906541269,15.6900031119585,0.00190455846908688,0.000312420934119988,0.25,-2.30450377552835E-6,0.000174786329888581,-1.65998419483393E-6,5.005084,5.005084,29408.44921875,29418.4375,52.4707224959671,18.6627448196195,2.9907277,0,0,0,4449,4.94795,29413.443359375,,,,,,,,,,,,,,,,,12.252253,,,,,,5.005084,,,,
,15644699.065,5.004617,33516.46484375,0.000177303862205345,3.69801810895233E-7,1,0.999253354069792,40.0298881530762,2.00549973362894,15.6900031119585,0.00192262650674673,0.000313243926234803,0.25,-2.55514194136567E-6,0.00017641370959411,-1.86678390955646E-6,5.0043092,5.0049248,33486.48046875,33546.44921875,52.4793204096786,18.6663512374451,3.1125,0,0,0,4449,4.942,33516.46484375,,,,,,,,,,,,,,,,,13.003003,,,,,,5.004617,,,,
,15644772.655,5.00269315,37196.8515625,0.000173922910358837,4.93136242917629E-7,1,0.999253354069792,40.0298881530762,2.00553903937739,15.6900031119585,0.00188539233792895,0.000312260000171845,0.25,-2.08201061553942E-6,0.000173072855734272,-1.37709939942286E-6,5.0024495,5.0029368,37164.34765625,37229.35546875,52.5074590363709,18.6659934548434,3.1284368,0,0,0,4449,4.9406,37196.8515625,,,,,,,,,,,,,,,,,13.003003,,,,,,5.00269315,,,,
,15644847.885,5.00061755,40952.673828125,0.000170059957648228,5.16716024599637E-7,1,0.999253354069792,40.0298881530762,2.00572692995695,15.6900031119585,0.00184622114221687,0.000292727479554033,0.25,-3.23832767053936E-6,0.000169259826246365,-2.51224535113709E-6,5.0002747,5.0009604,40927.66796875,40977.6796875,52.3956861581209,18.6649638581272,3.19125225,0,0,0,4449,4.9424,40952.673828125,,,,,,,,,,,,,,,,,13.378378,,,,,,5.00061755,,,,
,15644922.975,5.00140335,44708.443359375,0.000166197223803445,5.62411357181449E-7,1,0.999253354069792,40.0298881530762,2.00573225556267,15.6900031119585,0.00180110038249106,0.00030566826899168,0.25,-1.38870640949863E-6,0.000165434396792514,-6.57971033781532E-7,5.0010476,5.0017591,44675.83203125,44741.0546875,52.7528903914094,18.6658398195859,3.2071922,0,0,0,4449,4.9399,44708.443359375,,,,,,,,,,,,,,,,,13.378378,,,,,,5.00140335,,,,
,15644996.585,5.00176935,48386.515625,0.000161834771010969,4.72173760442588E-7,1,0.999253354069792,40.0298881530762,2.00540997069215,15.6900031119585,0.00175615151996494,0.000284739778114067,0.25,-2.57285491583959E-6,0.000161123898897283,-1.8284664953399E-6,5.0008717,5.002667,48354.171875,48418.859375,52.2463951109478,18.6651127636821,3.14390615,0,0,0,4449,4.93915,48386.515625,,,,,,,,,,,,,,,,,13.378378,,,,,,5.00176935,,,,
,15645070.755,5.00141095,52094.791015625,0.000151339116383909,7.59022797227699E-7,1,0.999253354069792,40.0298881530762,2.00542659776104,15.6900031119585,0.00164052173463841,0.000277704571838797,0.25,-1.37929962813761E-6,0.000150695545895443,-6.62891521550992E-7,5.0009274,5.0018945,52067.2265625,52122.35546875,52.5082406648902,18.670168608549,3.2071922,0,0,0,4449,4.9374,52094.791015625,,,,,,,,,,,,,,,,,13.378378,,,,,,5.00141095,,,,
,15645144.325,5.00179505,55770.330078125,0.000145325384011851,7.02547619238066E-7,1,0.999253354069792,40.0298881530762,2.00555449176524,15.6900031119585,0.00157802609416479,0.00025375396865292,0.25,-2.54641109623942E-6,0.000144738727251167,-1.8307026240331E-6,5.0017009,5.0018892,55740.15625,55800.50390625,52.423043156294,18.6728110219676,3.1754707,0,0,0,4449,4.93745,55770.330078125,,,,,,,,,,,,,,,,,13.003003,,,,,,5.00179505,,,,
,15645218.585,4.9995208,59484.134765625,0.000135921618481154,7.84741816287144E-7,1,0.999253354069792,40.0298881530762,2.00549953210972,15.6900031119585,0.00147246393147633,0.000257959242471479,0.25,-5.00680493407921E-7,0.000135388383586126,1.81621400778361E-7,4.9995208,4.9995208,59479.13671875,59489.1328125,52.7896269318133,18.6691751420128,3.2393923,0,0,0,4449,4.9378,59484.134765625,,,,,,,,,,,,,,,,,13.003003,,,,,,4.9995208,,,,
,15645295.995,5.0053625,63352.5234375,0.000127846872776196,8.94983646411198E-7,1,0.999253354069792,40.0298881530762,2.0054944124007,15.6900031119585,0.00138344865095107,0.000252765317372984,0.25,4.41102348674123E-7,0.000127365316853285,1.0986848812914E-6,5.0053625,5.0053625,63342.43359375,63362.61328125,52.6544051979863,18.6684336883428,3.1125,0,0,0,4449,4.9399,63352.5234375,,,,,,,,,,,,,,,,,13.753754,,,,,,5.0053625,,,,
,15645365.87,4.97027805,66845.578125,0.000118298102858756,9.10875530002505E-7,1,0.999253354069792,40.0298881530762,2.00543329314635,15.6900031119585,0.00128711514011861,0.000195973517863069,0.25,-3.11131824886799E-6,0.000117892082692818,-2.4749089877413E-6,4.9663439,4.9742122,66815.609375,66875.546875,52.7013029091402,18.664084215399,2.9907277,0,0,0,4454,4.92845,66845.578125,,,,,,,,,,,,,,,,,13.753754,,,,,,4.97027805,,,,
,15645441.72,5.00025485,70636.625,0.000110094075858271,7.97450152240569E-7,1,0.999253354069792,40.0298881530762,2.00532222565482,15.6900031119585,0.00120352210683499,0.000151806419767274,0.25,-5.73573619355979E-6,0.000109753583333831,-5.11986076112458E-6,4.9992599,5.0012498,70609.1171875,70664.1328125,52.3605128747555,18.6703871140774,2.63954365,0,0,0,4453,4.94585,70636.625,,,,,,,,,,,,,,,,,13.003003,,,,,,5.00025485,,,,
,15645521.45,5.0068908,74621.8046875,0.000102006614443845,7.45392198419433E-7,1,0.999253354069792,40.0298881530762,2.00525543758518,15.6900031119585,0.0011137355472984,0.000149502747092618,0.25,-4.5132339105303E-6,0.000101708733723717,-3.93296605047354E-6,5.0068908,5.0068908,74616.7734375,74626.8359375,52.6481521698325,18.665036791176,2.5234809,0,0,0,4453,4.9611,74621.8046875,,,,,,,,,,,,,,,,,13.003003,,,,,,5.0068908,,,,
,15645592.035,4.99704885,78148.03125,9.31755166854412E-5,6.25227566046698E-7,1,0.999253354069792,40.0298881530762,2.00530192238041,15.6900031119585,0.00102341609379693,0.000103848563819337,0.25,-7.15440332360531E-6,9.29384679759795E-5,-6.60610487477392E-6,4.9968085,4.9972892,78115.3515625,78180.7109375,52.6333012279671,18.6687873094737,2.486228,0,0,0,4449,4.94655,78148.03125,,,,,,,,,,,,,,,,,13.003003,,,,,,4.99704885,,,,
,15645666.385,4.9954591,81864.10546875,8.41906988060931E-5,6.51234287188244E-7,1,0.999253354069792,40.0298881530762,2.0053313771645,15.6900031119585,0.000924328947990418,9.72236683487404E-5,0.25,-6.16252280639641E-6,8.39921991505652E-5,-5.66036141045106E-6,4.9954591,4.9954591,81859.1015625,81869.109375,52.3292477339863,18.6715013618876,2.510939,0,0,0,4449,4.95025,81864.10546875,,,,,,,,,,,,,,,,,13.003003,,,,,,4.9954591,,,,
,15645737.665,4.99611165,85427.41796875,7.37230289538069E-5,7.80497753601148E-7,1,0.999253354069792,40.0298881530762,2.00523659060243,15.6900031119585,0.000809446765963922,8.56117297734372E-5,0.25,-5.36045040827437E-6,7.35636418782442E-5,-4.91497616584854E-6,4.9955287,4.9966946,85402.3984375,85452.4375,52.7028661661787,18.6687744625175,2.4983971,0,0,0,4449,4.9501,85427.41796875,,,,,,,,,,,,,,,,,12.252253,,,,,,4.99611165,,,,
,15645812.985,4.9988055,89192.49609375,6.30867806346285E-5,9.0500141542196E-7,1,0.999253354069792,40.0298881530762,2.00507548083196,15.6900031119585,0.000696684395599616,5.14563673999444E-5,0.25,-6.60527635791251E-6,6.29756215866069E-5,-6.21448400896526E-6,4.9988055,4.9988055,89184.8359375,89200.15625,52.3667659029094,18.668578883362,2.4985218,0,0,0,4449,4.95745,89192.49609375,,,,,,,,,,,,,,,,,13.003003,,,,,,4.9988055,,,,
,15645909.855,5.0297391,86862.6328125,7.24278544637434E-5,8.01293931898183E-7,1,0.999253354069792,40.0298881530762,2.00531187217702,15.6900031119585,0.000797685811148518,7.09572451203482E-5,0.25,-6.48298486773914E-6,7.2284227353677E-5,-6.04012180333525E-6,5.0145578,5.0449204,86832.640625,86892.625,52.4066289573901,18.667447318928,2.6133063,0,0,0,4453,4.9376,86862.6328125,,,,,,,,,,,,,,,,,12.252253,,,,,,5.0297391,,,,
,15645990.475,5.0082593,82832.20703125,8.24431724317672E-5,8.72972607381779E-7,1,0.999253354069792,40.0298881530762,2.00514129635436,15.6900031119585,0.000902612190304356,0.000109101420416804,0.25,-4.75406372026836E-6,8.22458287216573E-5,-4.26398216058129E-6,5.0082593,5.0082593,82829.7109375,82834.703125,52.3761454451402,18.666557412644,2.5234809,0,0,0,4453,4.9522,82832.20703125,,,,,,,,,,,,,,,,,13.378378,,,,,,5.0082593,,,,
,15646059.54,4.9966321,79378.52734375,9.29399832804226E-5,8.44425661056492E-7,1,0.999253354069792,40.0298881530762,2.00529335321685,15.6900031119585,0.00101511007572257,0.000135787421709209,0.25,-4.16824834649852E-6,9.26930045028764E-5,-3.62712711814198E-6,4.9965653,4.9966989,79356.0390625,79401.015625,52.6067258583133,18.6696268357609,2.52360675,0,0,0,4453,4.94465,79378.52734375,,,,,,,,,,,,,,,,,13.378378,,,,,,4.9966321,,,,
,15646133.125,5.000711,75702.62890625,0.00010133080775399,7.28332513359516E-7,1,0.999253354069792,40.0298881530762,2.00526902777122,15.6900031119585,0.00110395716186589,0.000162288346862574,0.25,-3.21593591938095E-6,0.000101033775893522,-2.64029327293137E-6,5.000711,5.000711,75682.65625,75722.6015625,52.423043156294,18.6709960082522,2.5488164,0,0,0,4449,4.94895,75702.62890625,,,,,,,,,,,,,,,,,13.378378,,,,,,5.000711,,,,
,15646212.38,5.00009775,71742.80859375,0.000112488550610386,5.9257737404555E-7,1,0.999253354069792,40.0298881530762,2.00521735281009,15.6900031119585,0.00122980566581406,0.000154583967363869,0.25,-5.91319589868134E-6,0.000112147660964577,-5.27991859144635E-6,4.9999065,5.000289,71715.21875,71770.3984375,52.6137605149863,18.6661683950942,2.4983971,0,0,0,4449,4.94885,71742.80859375,,,,,,,,,,,,,,,,,13.378378,,,,,,5.00009775,,,,
,15646291.93,5.00083755,67766.90234375,0.000120987281271782,7.20367972922228E-7,1,0.999253354069792,40.0298881530762,2.00515051038544,15.6900031119585,0.00131867026457833,0.000186987739099381,0.25,-4.42572447552683E-6,0.000120584482271396,-3.76662921064758E-6,5.0003614,5.0013137,67731.90625,67801.8984375,52.6356461135248,18.6718059984177,2.4490974,0,0,0,4449,4.94905,67766.90234375,,,,,,,,,,,,,,,,,13.378378,,,,,,5.00083755,,,,
,15646370.355,4.9983597,63846.14453125,0.000130193189635161,7.79934414923269E-7,1,0.999253354069792,40.0298881530762,2.00508165210385,15.6900031119585,0.00142286061300046,0.000177768421987083,0.25,-6.9052116685054E-6,0.000129744090619143,-6.20572829802882E-6,4.9983597,4.9983597,63843.66796875,63848.62109375,52.5864035168132,18.6677066935922,2.4005308,0,0,0,4449,4.9471,63846.14453125,,,,,,,,,,,,,,,,,12.252253,,,,,,4.9983597,,,,
,15646452.12,5.00786875,59757.8359375,0.000140739787350045,9.06147263161999E-7,1,0.999253354069792,40.0298881530762,2.00523834042978,15.6900031119585,0.0015334126843333,0.000217247859417618,0.25,-5.12293801038886E-6,0.000140212649946986,-4.39682713596925E-6,5.0058918,5.0098457,59730.296875,59785.375,52.4777571526402,18.6715080286988,2.34158385,0,0,0,4449,4.96,59757.8359375,,,,,,,,,,,,,,,,,13.378378,,,,,,5.00786875,,,,
,15646530.665,5.00548075,55831.451171875,0.000147760596225767,8.99951594471464E-7,1,0.999253354069792,40.0298881530762,2.00514611547264,15.6900031119585,0.00160923663484581,0.000229604101010737,0.25,-5.20928354376278E-6,0.000147177269671902,-4.47041727259226E-6,5.00529,5.0056715,55801.421875,55861.48046875,52.6864519672748,18.6708704435746,2.4489751,0,0,0,4453,4.9382,55831.451171875,,,,,,,,,,,,,,,,,13.378378,,,,,,5.00548075,,,,
,15646605.82,5.00486205,52078.384765625,0.000156228961657575,5.82785057448611E-7,1,0.999253354069792,40.0298881530762,2.00516725314948,15.6900031119585,0.00170124140557564,0.000242307502536741,0.25,-5.52081806906197E-6,0.000155583707673841,-4.76377311815226E-6,5.0048356,5.0048885,52048.51953125,52108.25,52.4519634115056,18.6692209578166,2.4489751,0,0,0,4453,4.94095,52078.384765625,,,,,,,,,,,,,,,,,13.378378,,,,,,5.00486205,,,,
,15646675.245,4.9996231,48605.0234375,0.000162473786876455,4.53273247936994E-7,1,0.999253354069792,40.0298881530762,2.00519028029698,15.6900031119585,0.00176731816030198,0.000261207943092482,0.25,-4.86097525845348E-6,0.00016177206586818,-4.10190830202305E-6,4.999311,4.9999352,48585.02734375,48625.01953125,52.7364761925056,18.6691784125031,2.3766694,0,0,0,4449,4.9418,48605.0234375,,,,,,,,,,,,,,,,,13.003003,,,,,,4.9996231,,,,
,15646754.825,4.99933815,44629.06640625,0.000170199770921996,4.4355290723857E-7,1,0.999253354069792,40.0298881530762,2.00500056912803,15.6900031119585,0.00185151757096437,0.000269844718040449,0.25,-5.40370223873586E-6,0.000169435322844137,-4.63756706008252E-6,4.9989133,4.999763,44596.67578125,44661.45703125,52.8333981288902,18.6691924957237,2.3650931,0,0,0,4449,4.94265,44629.06640625,,,,,,,,,,,,,,,,,13.003003,,,,,,4.99933815,,,,
,15646833.795,5.00003025,40681.333984375,0.000179129486834199,6.34377490093717E-7,1,0.999253354069792,40.0298881530762,2.00525154292747,15.6900031119585,0.00194529850262149,0.000302246253794604,0.25,-3.96523199508171E-6,0.000178286949522177,-3.20009154476163E-6,4.9996085,5.000452,40653.80859375,40708.859375,52.768522961794,18.6718263784039,2.3766694,0,0,0,4449,4.9421,40681.333984375,,,,,,,,,,,,,,,,,13.378378,,,,,,5.00003025,,,,
,15646912.3,5.00004055,36757.71875,0.000185843121291834,4.20499085188113E-7,1,0.999253354069792,40.0298881530762,2.00515910047335,15.6900031119585,0.00201849533522428,0.000309551400681293,0.25,-4.44385142860187E-6,0.000184940390868065,-3.68366052203187E-6,4.999877,5.0002041,36725.0625,36790.375,52.3448803043709,18.6715109140382,2.30661345,0,0,0,4449,4.9448,36757.71875,,,,,,,,,,,,,,,,,13.378378,,,,,,5.00004055,,,,
,15646991.64,5.000494,32792.734375,0.000191948137863942,4.72551285319922E-7,1,0.999253354069792,40.0298881530762,2.00523459199996,15.6900031119585,0.00208181852388131,0.000335067259249736,0.25,-3.12874624304788E-6,0.000190980623943631,-2.38865442266606E-6,5.0001197,5.0008683,32767.69921875,32817.76953125,52.6379909990825,18.6738614785169,2.2274964,0,0,0,4449,4.94385,32792.734375,,,,,,,,,,,,,,,,,13.003003,,,,,,5.000494,,,,
,15647075.75,4.9865725,28589.419921875,0.000197205669335899,2.86341226303959E-7,1,0.999253354069792,40.0298881530762,2.00517087359465,15.6900031119585,0.00213746263839115,0.000349736572889016,0.25,-2.65820932388505E-6,0.00019617976095457,-1.94268577710199E-6,4.9859576,4.9871874,28564.46484375,28614.375,52.5098039219286,18.6698889199405,2.3886001,0,0,0,4453,4.91775,28589.419921875,,,,,,,,,,,,,,,,,13.378378,,,,,,4.9865725,,,,
,15647156.36,5.00999925,24558.853515625,0.000201580172640285,2.8587235093834E-7,1,0.999253354069792,40.0298881530762,2.00520132754391,15.6900031119585,0.0021831352145364,0.000365776957919785,0.25,-1.9050535891237E-6,0.000200501684359697,-1.21959900331013E-6,5.0098166,5.0101819,24531.13671875,24586.5703125,52.3792719592171,18.675559808061,2.3413502,0,0,0,4453,4.9426,24558.853515625,,,,,,,,,,,,,,,,,13.378378,,,,,,5.00999925,,,,
,15647223.42,4.99924945,21207.9208984375,0.000205349185093959,3.84541626174914E-7,1,0.999253354069792,40.0298881530762,2.00523743661157,15.6900031119585,0.00222442742224125,0.000368816505408659,0.25,-2.25343552728053E-6,0.000204230380942652,-1.58879510789023E-6,4.9979291,5.0005698,21177.73046875,21238.111328125,52.4605613252171,18.6721657270012,2.31830825,0,0,0,4453,4.9419,21207.9208984375,,,,,,,,,,,,,,,,,13.378378,,,,,,4.99924945,,,,
,15647298.64,4.9982836,17447.6884765625,0.000208279532210535,3.74259831274827E-7,1,0.999253354069792,40.0298881530762,2.00527632123588,15.6900031119585,0.00225439967895466,0.000382910730895784,0.25,-1.42527641626963E-6,0.000207119958332755,-7.95888773618093E-7,4.9975147,4.9990525,17425.09765625,17470.279296875,52.2182564842555,18.6748786894457,2.3296554,0,0,0,4449,4.94135,17447.6884765625,,,,,,,,,,,,,,,,,13.003003,,,,,,4.9982836,,,,
,15647380.065,4.99917125,13379.533203125,0.000210172348776129,3.37519685018592E-7,1,0.999253354069792,40.0298881530762,2.00510241476646,15.6900031119585,0.00227494198043435,0.000383610843363312,0.25,-1.64551825854319E-6,0.000208981066430265,-1.0521156597453E-6,4.9990888,4.9992537,13356.8984375,13402.16796875,52.619231914621,18.6744422239352,2.27222195,0,0,0,4449,4.94255,13379.533203125,,,,,,,,,,,,,,,,,13.003003,,,,,,4.99917125,,,,
,15647457.54,5.00045845,9506.4208984375,0.000209542036229368,2.29971455317644E-7,1,0.999253354069792,40.0298881530762,2.00506454766276,15.6900031119585,0.00226756050018345,0.000384221637304832,0.25,-1.43429766939115E-6,0.000208335475236009,-8.83121388848541E-7,5.0000629,5.000854,9474.06640625,9538.775390625,52.5785872316209,18.6768791310047,2.2496357,0,0,0,4449,4.9418,9506.4208984375,,,,,,,,,,,,,,,,,13.003003,,,,,,5.00045845,,,,
,15647535.11,5.0015097,5630.091796875,0.0001984066260416,2.47860443072162E-7,1,0.999253354069792,40.0298881530762,2.00503753209759,15.6900031119585,0.00214782678064203,0.000358330438802965,0.25,-1.82627697669402E-6,0.000197250349700247,-1.33658110153943E-6,5.0015097,5.0015097,5625.00341796875,5635.18017578125,52.6809805676402,18.6753079986919,2.19422975,0,0,0,4449,4.9442,5630.091796875,,,,,,,,,,,,,,,,,13.378378,,,,,,5.0015097,,,,
,15647612.52,4.9959836,1758.34362792969,0.000135174679582792,2.0881141094181E-7,1,0.999253354069792,40.0298881530762,2.00505807594907,15.6900031119585,0.00146517616296754,0.000233128564518561,0.25,-2.24011307722818E-6,0.000134380865077287,-1.92139103270624E-6,4.9939852,4.997982,1730.89306640625,1785.79418945313,52.5058957793325,18.6755554539826,2.1402407,0,0,0,4449,4.94515,1758.34362792969,,,,,,,,,,,,,,,,,13.378378,,,,,,4.9959836,,,,
,15647692.785,4.9931171,-2248.06970214844,7.6966564712001E-6,2.14655117355745E-7,1,0.999253354069792,40.0298881530762,2.00490383828718,15.6900031119585,8.82750133025254E-5,-1.42881357777082E-5,0.25,-2.67803998866206E-6,7.65731919588706E-6,-2.64470185164738E-6,4.9922409,4.9939933,-2272.84228515625,-2223.29711914062,52.8279267292556,18.6714300695479,2.31807685,0,0,0,4453,4.9323,-2248.06970214844,,,,,,,,,,,,,,,,,13.378378,,,,,,4.9931171,,,,
,15647773.6,5.0090487,-6287.07861328125,-5.26545903453105E-5,2.43847137409405E-7,1,0.999253354069792,40.0298881530762,2.00493179744442,15.6900031119585,-0.000564265635553458,-0.000127523437816483,0.25,-2.51459740031858E-6,-5.23410309770611E-5,-2.62855615702449E-6,5.0085554,5.009542,-6317.078125,-6257.0791015625,52.7364761925056,18.6741986660013,2.2950349,0,0,0,4453,4.94225,-6287.07861328125,,,,,,,,,,,,,,,,,13.378378,,,,,,5.0090487,,,,
,15647842.37,5.0015321,-9725.96533203125,-6.15308101973753E-5,2.8397793643709E-7,1,0.999253354069792,40.0298881530762,2.00519113393237,15.6900031119585,-0.000660510670165383,-0.000143358693696972,0.25,-2.40237115369803E-6,-6.11694511586321E-5,-2.54856381233739E-6,5.0015202,5.001544,-9750.8837890625,-9701.046875,52.6747275394863,18.678389118816,2.2835715,0,0,0,4453,4.9419,-9725.96533203125,,,,,,,,,,,,,,,,,13.378378,,,,,,5.0015321,,,,
,15647917.9,4.9997902,-13501.8828125,-6.94898068774256E-5,2.72867398591E-7,1,0.999253354069792,40.0298881530762,2.00508904574266,15.6900031119585,-0.000745703077037119,-0.000163417895010533,0.25,-2.84005719964142E-6,-6.90867102548411E-5,-3.01743011551609E-6,4.9997902,4.9997902,-13504.33984375,-13499.42578125,52.9537689208517,18.6745353841521,2.20513475,0,0,0,4449,4.9403,-13501.8828125,,,,,,,,,,,,,,,,,13.378378,,,,,,4.9997902,,,,
,15647997.895,4.9996312,-17499.6953125,-8.30579501064169E-5,2.84672834334726E-7,1,0.999253354069792,40.0298881530762,2.00504278523513,15.6900031119585,-0.000892517472717791,-0.000188843855490776,0.25,-2.77682450376442E-6,-8.25856604609067E-5,-3.00934399285476E-6,4.9994512,4.9998112,-17532.421875,-17466.96875,52.9256302941594,18.6769329258524,2.1723104,0,0,0,4449,4.93975,-17499.6953125,,,,,,,,,,,,,,,,,12.252253,,,,,,4.9996312,,,,
,15648076.92,5.0006504,-21447.341796875,-0.000102219019593954,3.2359190114921E-7,1,0.999253354069792,40.0298881530762,2.00493626986464,15.6900031119585,-0.00110146973415315,-0.00021552468140944,0.25,-1.83349256961308E-6,-0.000101653404411141,-2.1494091082454E-6,5.0006299,5.0006709,-21474.8828125,-21419.80078125,52.5981279446017,18.6765450266962,2.1189666,0,0,0,4449,4.93945,-21447.341796875,,,,,,,,,,,,,,,,,13.378378,,,,,,5.0006504,,,,
,15648156.335,5.0006168,-25417.353515625,-0.000125962122241258,3.52563855457875E-7,1,0.999253354069792,40.0298881530762,2.00487692655166,15.6900031119585,-0.00135664942243965,-0.000270065744770829,0.25,-2.64557459938149E-6,-0.000125278658401282,-3.05891357487714E-6,5.0005074,5.0007262,-25452.37890625,-25382.328125,52.9787810334671,18.6744427652915,2.14002715,0,0,0,4449,4.9404,-25417.353515625,,,,,,,,,,,,,,,,,13.378378,,,,,,5.0006168,,,,
,15648234.67,4.99896075,-29333.3857421875,-0.000145875802975494,5.33742575256346E-7,1,0.999253354069792,40.0298881530762,2.00503240523931,15.6900031119585,-0.00157219121234467,-0.000308593042312756,0.25,-2.64298796733155E-6,-0.000145104134795143,-3.15371693512055E-6,4.9987974,4.9991241,-29360.677734375,-29306.09375,52.7044294232171,18.6742787655214,2.0665716,0,0,0,4449,4.9425,-29333.3857421875,,,,,,,,,,,,,,,,,13.378378,,,,,,4.99896075,,,,
,15648319.46,4.98455355,-33571.216796875,-0.000158564770181509,3.82117415944879E-7,1,0.999253354069792,40.0298881530762,2.00500102209745,15.6900031119585,-0.00171025936480431,-0.00032939437023864,0.25,-2.27563173862211E-6,-0.000157751639832445,-2.86853448981165E-6,4.9839444,4.9851627,-33578.703125,-33563.73046875,52.6794173106017,18.674923483403,2.16151395,0,0,0,4453,4.91925,-33571.216796875,,,,,,,,,,,,,,,,,13.378378,,,,,,4.98455355,,,,
,15648398.125,5.0112319,-37500.998046875,-0.000164835030169405,4.94880876482702E-7,1,0.999253354069792,40.0298881530762,2.00503053006156,15.6900031119585,-0.00177753355742222,-0.000346099775459305,0.25,-2.66818451236878E-6,-0.000164012779728932,-3.31587698356788E-6,5.0109816,5.0114822,-37535.89453125,-37466.1015625,52.7052110517363,18.6733116210512,2.2161491,0,0,0,4453,4.94055,-37500.998046875,,,,,,,,,,,,,,,,,12.252253,,,,,,5.0112319,,,,
,15648467.465,4.99815465,-40968.955078125,-0.000165568426666909,4.35777597262006E-7,1,0.999253354069792,40.0298881530762,2.00499688677767,15.6900031119585,-0.00178530354229483,-0.000349687700883743,0.25,-2.83724565669061E-6,-0.000164764507588266,-3.51562403311263E-6,4.9978905,4.9984188,-40994.01171875,-40943.8984375,53.1913839906979,18.6797118866754,2.1834333,0,0,0,4453,4.9377,-40968.955078125,,,,,,,,,,,,,,,,,13.003003,,,,,,4.99815465,,,,
,15648540.73,4.997963,-44626.197265625,-0.000161998976526618,4.8883980760257E-7,1,0.999253354069792,40.0298881530762,2.00493167194425,15.6900031119585,-0.00174684927194871,-0.000343190436277002,0.25,-2.84012632964066E-6,-0.000161236579383372,-3.53236306594335E-6,4.997963,4.997963,-44631.2421875,-44621.15234375,52.5269997493517,18.6779541517336,2.16151395,0,0,0,4449,4.9384,-44626.197265625,,,,,,,,,,,,,,,,,13.378378,,,,,,4.997963,,,,
,15648619.83,4.9989319,-48581.7265625,-0.000159586745657688,5.3335287363449E-7,1,0.999253354069792,40.0298881530762,2.005033324652,15.6900031119585,-0.00171959429320323,-0.000347244817474421,0.25,-3.60876825099633E-6,-0.000158859281336158,-4.31682823387486E-6,4.9984508,4.999413,-48609.171875,-48554.28125,52.7114640798902,18.6823660831944,2.07704925,0,0,0,4449,4.9404,-48581.7265625,,,,,,,,,,,,,,,,,12.252253,,,,,,4.9989319,,,,
,15648698.875,4.99787355,-52531.73828125,-0.000153381539220352,5.89405472997074E-7,1,0.999253354069792,40.0298881530762,2.00506566792652,15.6900031119585,-0.00165794237607314,-0.000306436554992567,0.25,-9.11934806736015E-7,-0.000152721540797036,-1.63104254896153E-6,4.997211,4.9985361,-52561.84375,-52501.6328125,52.7528903914094,18.6808561255802,2.0460296,0,0,0,4449,4.94105,-52531.73828125,,,,,,,,,,,,,,,,,13.378378,,,,,,4.99787355,,,,
,15648779.83,4.9989533,-56576.734375,-0.000146774212830695,5.31819803175834E-7,1,0.999253354069792,40.0298881530762,2.00503981441753,15.6900031119585,-0.00158561011006437,-0.000299986474392643,0.25,-1.46621103417126E-6,-0.000146167749034961,-2.17742217172693E-6,4.9989533,4.9989533,-56584.31640625,-56569.15234375,52.7599250480825,18.6792665925267,2.056198,0,0,0,4449,4.94205,-56576.734375,,,,,,,,,,,,,,,,,12.252253,,,,,,4.9989533,,,,
,15648860.43,4.9990685,-60607.35546875,-0.000138403186587602,7.92859637501546E-7,1,0.999253354069792,40.0298881530762,2.00493498446923,15.6900031119585,-0.00149396077592638,-0.000290949185556819,0.25,-2.10188927820235E-6,-0.00013785472642729,-2.79266132408615E-6,4.9985943,4.9995427,-60642.296875,-60572.4140625,52.7990064740441,18.6805742808419,1.9463421,0,0,0,4449,4.945,-60607.35546875,,,,,,,,,,,,,,,,,13.003003,,,,,,4.9990685,,,,
,15648942.725,5.00974535,-64717.72265625,-0.000131576173177031,6.32513334833181E-7,1,0.999253354069792,40.0298881530762,2.00499495225596,15.6900031119585,-0.00142334122175243,-0.000261365167165731,0.25,-5.64510648703124E-7,-0.000131089056474047,-1.24765819114612E-6,5.0093102,5.0101805,-64750.2578125,-64685.1875,52.7560169054864,18.6795058261817,1.96588335,0,0,0,4449,4.9501,-64717.72265625,,,,,,,,,,,,,,,,,13.003003,,,,,,5.00974535,,,,
,15649020.445,5.0029793,-68600.890625,-0.000120998505583473,6.08256201611175E-7,1,0.999253354069792,40.0298881530762,2.00486916427531,15.6900031119585,-0.00130690596362301,-0.000252623268822901,0.25,-1.63232399789603E-6,-0.000120568607755754,-2.273760399841E-6,5.0029793,5.0029793,-68603.3828125,-68598.3984375,52.727878278794,18.6788079745255,2.1941204,0,0,0,4453,4.9347,-68600.890625,,,,,,,,,,,,,,,,,13.378378,,,,,,5.0029793,,,,
,15649097.79,4.9848459,-72468.08984375,-0.000113289065286987,7.3871904149963E-7,1,0.999253354069792,40.0298881530762,2.00489810587432,15.6900031119585,-0.00121910996722107,-0.000263262437254637,0.25,-3.97762263200168E-6,-0.000112895776473429,-4.58531854630751E-6,4.9845691,4.9851227,-72495.6171875,-72440.5625,52.7747759899479,18.6781058128696,2.1941204,0,0,0,4453,4.9231,-72468.08984375,,,,,,,,,,,,,,,,,12.252253,,,,,,4.9848459,,,,
,15649166.23,4.9978786,-75888.453125,-0.00010375023111829,8.97762071832883E-7,1,0.999253354069792,40.0298881530762,2.00485666408083,15.6900031119585,-0.00111526708984755,-0.000248773418540046,0.25,-4.33681427573782E-6,-0.000103404515642483,-4.90312182096393E-6,4.9978786,4.9978786,-75893.34375,-75883.5625,52.7028661661787,18.6839204034245,2.0664685,0,0,0,4449,4.9433,-75888.453125,,,,,,,,,,,,,,,,,13.378378,,,,,,4.9978786,,,,
,15649245.8,4.9978447,-79863.67578125,-9.37865325424975E-5,8.6808547921885E-7,1,0.999253354069792,40.0298881530762,2.00505386906373,15.6900031119585,-0.00101260909203835,-0.000201892066620062,0.25,-1.78104728688687E-6,-9.35056367134393E-5,-2.31100363856994E-6,4.9978447,4.9978447,-79871.296875,-79856.0546875,53.0928987972748,18.680231160174,2.0459275,0,0,0,4449,4.94245,-79863.67578125,,,,,,,,,,,,,,,,,13.003003,,,,,,4.9978447,,,,
,15649325.825,4.9979463,-83864.140625,-8.37936652790679E-5,7.944884270392E-7,1,0.999253354069792,40.0298881530762,2.00496539816571,15.6900031119585,-0.000909058444385073,-0.000157133437799123,0.25,5.66088497168139E-7,-8.35730700996812E-5,7.73668256374841E-8,4.9979463,4.9979463,-83868.9609375,-83859.3203125,52.8607551270633,18.678879759185,2.0357591,0,0,0,4449,4.94495,-83864.140625,,,,,,,,,,,,,,,,,13.003003,,,,,,4.9979463,,,,
,15649406.67,4.9977279,-87904.51953125,-7.304686956829E-5,7.34175944661272E-7,1,0.999253354069792,40.0298881530762,2.00513243332232,15.6900031119585,-0.000789917236826203,-0.00015251707424749,0.25,-9.28917167048481E-7,-7.28621191369014E-5,-1.35869832087231E-6,4.9977279,4.9977279,-87906.9296875,-87902.109375,52.8763876974479,18.6803728952272,1.9855216,0,0,0,4449,4.9469,-87904.51953125,,,,,,,,,,,,,,,,,13.003003,,,,,,4.9977279,,,,
,15649503.32,5.0001311,-88115.79296875,-7.34121743242778E-5,1.05234583299292E-6,1,0.999253354069792,40.0298881530762,2.00510137783013,15.6900031119585,-0.000794300660356742,-0.000150858295964688,0.25,-7.09829840866106E-7,-7.32286571338591E-5,-1.14268383860688E-6,5.0001311,5.0001311,-88120.8515625,-88110.734375,52.9115609808133,18.6813004040543,1.9268991,0,0,0,4449,4.948,-88115.79296875,,,,,,,,,,,,,,,,,12.252253,,,,,,5.0001311,,,,
,15649584.345,4.998621,-84066.1484375,-8.50283247785738E-5,7.58379902791295E-7,1,0.999253354069792,40.0298881530762,2.00492850679498,15.6900031119585,-0.000917230721088323,-0.000188456055101075,0.25,-2.10227883761972E-6,-8.47898296518381E-5,-2.59151894376754E-6,4.998621,4.998621,-84068.6171875,-84063.6796875,52.9998850034864,18.6819944210886,1.833016,0,0,0,4449,4.95095,-84066.1484375,,,,,,,,,,,,,,,,,13.378378,,,,,,4.998621,,,,
,15649664.325,5.00561,-80068.1328125,-9.62160738371645E-5,7.74619092968401E-7,1,0.999253354069792,40.0298881530762,2.0049262460111,15.6900031119585,-0.00104192781381159,-0.000189650614164677,0.25,-2.14826976362087E-7,-9.59381525196855E-5,-7.63726190954613E-7,5.00561,5.00561,-80070.46875,-80065.796875,52.6927049954287,18.6770805772862,2.1293368,0,0,0,4453,4.9403,-80068.1328125,,,,,,,,,,,,,,,,,13.003003,,,,,,5.00561,,,,
,15649743.6,5.0195246,-76108.4453125,-0.000106393284321718,7.35400413186678E-7,1,0.999253354069792,40.0298881530762,2.00488128330817,15.6900031119585,-0.00114847148382719,-0.000228576621491753,0.25,-1.99620562302043E-6,-0.00010605368621756,-2.58527655033489E-6,5.0195246,5.0195246,-76113.3515625,-76103.5390625,53.0553806283518,18.6790559019127,2.10827625,0,0,0,4453,4.9559,-76108.4453125,,,,,,,,,,,,,,,,,12.252253,,,,,,5.0195246,,,,
,15649810.62,5.0013325,-72757.65625,-0.000113777441880377,6.87253133481862E-7,1,0.999253354069792,40.0298881530762,2.00478176331895,15.6900031119585,-0.0012306373452304,-0.000229172127985243,0.25,-7.41763369817576E-7,-0.000113402004888846,-1.36383432050947E-6,5.0010819,5.0015831,-72784.8828125,-72730.4296875,52.8419960426017,18.6771637478633,2.056198,0,0,0,4453,4.9444,-72757.65625,,,,,,,,,,,,,,,,,13.378378,,,,,,5.0013325,,,,
,15649886.71,5.0005295,-68955.25390625,-0.000122748704651773,7.60256419388834E-7,1,0.999253354069792,40.0298881530762,2.00486198481477,15.6900031119585,-0.00132902564669563,-0.000238461814561674,0.25,-8.64635570933274E-9,-0.000122323650013478,-6.66613927180079E-7,5.0002651,5.0007939,-68977.734375,-68932.7734375,52.7317864213902,18.6775521324817,2.01552335,0,0,0,4449,4.9427,-68955.25390625,,,,,,,,,,,,,,,,,12.252253,,,,,,5.0005295,,,,
,15649965.62,5.000351,-65012.275390625,-0.000133941346075731,6.4160172717999E-7,1,0.999253354069792,40.0298881530762,2.00484754601987,15.6900031119585,-0.00145073912008652,-0.000255497475760554,0.25,4.01505654581598E-7,-0.000133452565932256,-2.98974095568476E-7,5.000351,5.000351,-65014.7734375,-65009.77734375,52.7325680499094,18.6783101767395,1.9657851,0,0,0,4449,4.942,-65012.275390625,,,,,,,,,,,,,,,,,13.003003,,,,,,5.000351,,,,
,15650044.26,5.0004957,-61081.693359375,-0.000141149923326809,6.94462292758391E-7,1,0.999253354069792,40.0298881530762,2.00489483995844,15.6900031119585,-0.0015285141785183,-0.00026937301993012,0.25,3.860426343436E-7,-0.000140606683692941,-3.30896996798524E-7,5.0003281,5.0006633,-61106.5859375,-61056.80078125,53.0616336565056,18.6774361154466,1.9268991,0,0,0,4449,4.9418,-61081.693359375,,,,,,,,,,,,,,,,,13.378378,,,,,,5.0004957,,,,
,15650123.35,5.00015925,-57128.736328125,-0.000149983206407255,5.68345229396072E-7,1,0.999253354069792,40.0298881530762,2.00492098179391,15.6900031119585,-0.00162273000066757,-0.000292559886600994,0.25,-2.03361086359053E-7,-0.000149373803799442,-9.3885128899319E-7,4.9997334,5.0005851,-57158.6953125,-57098.77734375,52.7825922751402,18.6781886843466,1.86089915,0,0,0,4449,4.94255,-57128.736328125,,,,,,,,,,,,,,,,,12.252253,,,,,,5.00015925,,,,
,15650204.61,4.9997039,-53068.853515625,-0.000160561168124472,4.41232830493952E-7,1,0.999253354069792,40.0298881530762,2.00500808569901,15.6900031119585,-0.00173464936714402,-0.000325795317873166,0.25,-1.41436864797275E-6,-0.00015987210587385,-2.16896254201532E-6,4.9997039,4.9997039,-53076.3828125,-53061.32421875,52.8763876974479,18.679477831374,1.8147956,0,0,0,4449,4.9408,-53068.853515625,,,,,,,,,,,,,,,,,13.378378,,,,,,4.9997039,,,,
,15650289.165,5.0057783,-48844.369140625,-0.0001673094272399,5.31137107543852E-7,1,0.999253354069792,40.0298881530762,2.00492478700259,15.6900031119585,-0.00180498189844372,-0.000351462171546593,0.25,-2.61931376751041E-6,-0.000166553986784601,-3.36885290245026E-6,5.0057783,5.0057783,-48849.2109375,-48839.52734375,52.9287568082364,18.6786805509552,1.8793949,0,0,0,4449,4.9428,-48844.369140625,,,,,,,,,,,,,,,,,13.378378,,,,,,5.0057783,,,,
,15650366.83,5.0048983,-44961.798828125,-0.000175283823877131,5.04504149195913E-7,1,0.999253354069792,40.0298881530762,2.00502812637553,15.6900031119585,-0.00189658510243164,-0.000335628538351046,0.25,2.32495858934267E-7,-0.000174475839398205,-5.34579408895113E-7,5.0043893,5.0054073,-44991.83203125,-44931.765625,52.8349613859287,18.6769702442407,2.056198,0,0,0,4453,4.93395,-44961.798828125,,,,,,,,,,,,,,,,,13.003003,,,,,,5.0048983,,,,
,15650445.885,5.00433925,-41011.078125,-0.00018180961341771,3.85556500976339E-7,1,0.999253354069792,40.0298881530762,2.00495242399063,15.6900031119585,-0.00196116340380276,-0.000379655611949698,0.25,-2.71513846658284E-6,-0.000180928818144444,-3.46235313391729E-6,5.003264,5.0054145,-41043.55859375,-40978.59765625,52.5895300308902,18.6773149582336,2.0460296,0,0,0,4453,4.9314,-41011.078125,,,,,,,,,,,,,,,,,13.003003,,,,,,5.00433925,,,,
,15650511.945,5.00062325,-37710.611328125,-0.000187297420236372,5.56555953116182E-7,1,0.999253354069792,40.0298881530762,2.00492476440842,15.6900031119585,-0.00202173616117878,-0.00038168054885555,0.25,-1.96027829651463E-6,-0.000186368940350208,-2.70347148164851E-6,5.0002189,5.0010276,-37740.7578125,-37680.46484375,52.7224068791594,18.6795402429331,2.01552335,0,0,0,4453,4.9371,-37710.611328125,,,,,,,,,,,,,,,,,13.003003,,,,,,5.00062325,,,,
,15650589.825,4.9997132,-33815.572265625,-0.000193298784494057,3.97511833319256E-7,1,0.999253354069792,40.0298881530762,2.00510345524848,15.6900031119585,-0.00208660000645172,-0.000392656089375768,0.25,-1.94724789414191E-6,-0.000192312414464587,-2.67662967817082E-6,4.9996519,4.9997745,-33848.078125,-33783.06640625,52.7294415358325,18.6758812501866,1.9175137,0,0,0,4449,4.9371,-33815.572265625,,,,,,,,,,,,,,,,,12.252253,,,,,,4.9997132,,,,
,15650673.655,4.9999857,-29627.4716796875,-0.000199304098700017,3.98313937011723E-7,1,0.999253354069792,40.0298881530762,2.0049363657418,15.6900031119585,-0.00214869538667571,-0.000417374535381817,0.25,-3.21688277866398E-6,-0.000198253191559389,-3.9197716187068E-6,4.9999771,4.9999943,-29629.84765625,-29625.095703125,52.6583133405825,18.6828606782757,1.8982639,0,0,0,4449,4.93625,-29627.4716796875,,,,,,,,,,,,,,,,,13.003003,,,,,,4.9999857,,,,
,15650753.99,4.99978205,-25611.8330078125,-0.000203184727347368,3.34647838605656E-7,1,0.999253354069792,40.0298881530762,2.00473807679774,15.6900031119585,-0.002192707497109,-0.00041036000831378,0.25,-1.92987898532962E-6,-0.000202091435619088,-2.61119135949404E-6,4.9996514,4.9999127,-25616.7734375,-25606.892578125,52.883422354121,18.6739912205715,1.8887823,0,0,0,4449,4.9369,-25611.8330078125,,,,,,,,,,,,,,,,,13.378378,,,,,,4.99978205,,,,
,15650834.05,4.9974029,-21611.3857421875,-0.000206984432985713,3.95014835268977E-7,1,0.999253354069792,40.0298881530762,2.00507082130975,15.6900031119585,-0.00223260603880384,-0.000424726047312615,0.25,-2.62660636010056E-6,-0.000205843549704576,-3.27402074293301E-6,4.9968076,4.9979982,-21643.884765625,-21578.88671875,52.5645179182748,18.67416484163,1.86071345,0,0,0,4449,4.93765,-21611.3857421875,,,,,,,,,,,,,,,,,13.378378,,,,,,4.9974029,,,,
,15650912.555,4.99924395,-17688.4453125,-0.000209095742463987,2.81422308314516E-7,1,0.999253354069792,40.0298881530762,2.00488932841307,15.6900031119585,-0.00225484229401322,-0.000429538443207121,0.25,-2.74778954426549E-6,-0.000207920463035248,-3.35887747373513E-6,4.9990296,4.9994583,-17720.91015625,-17655.98046875,52.5262181208325,18.6768744190966,1.7967564,0,0,0,4449,4.9398,-17688.4453125,,,,,,,,,,,,,,,,,13.378378,,,,,,4.99924395,,,,
,15650996.015,5.0062718,-13516.07421875,-0.000210650945356385,2.12548124963625E-7,1,0.999253354069792,40.0298881530762,2.00486822548959,15.6900031119585,-0.0022704726964935,-0.000437679088112868,0.25,-3.27486167142221E-6,-0.000209443925294511,-3.84303526903309E-6,5.0062718,5.0062718,-13523.400390625,-13508.748046875,52.666911254294,18.6748774319619,1.7263746,0,0,0,4449,4.9467,-13516.07421875,,,,,,,,,,,,,,,,,12.627627,,,,,,5.0062718,,,,
,15651075.54,5.00246835,-9542.85400390625,-0.000208617235729595,3.11768435402644E-7,1,0.999253354069792,40.0298881530762,2.00491445096408,15.6900031119585,-0.00224864059822181,-0.000432102819439252,0.25,-3.16132769879164E-6,-0.000207404261664218,-3.68392654808159E-6,5.0023208,5.0026159,-9565.37890625,-9520.3291015625,52.5824953742171,18.6739023211444,1.97585055,0,0,0,4453,4.9335,-9542.85400390625,,,,,,,,,,,,,,,,,13.753754,,,,,,5.00246835,,,,
,15651156.81,5.00539805,-5479.2275390625,-0.000196046826616824,2.11100702444811E-7,1,0.999253354069792,40.0298881530762,2.0049002961854,15.6900031119585,-0.002113613586486,-0.000402398425482356,0.25,-2.67097093802846E-6,-0.000194892999498429,-3.12737292503204E-6,5.004292,5.0065041,-5506.89306640625,-5451.56201171875,52.6403358846402,18.6709176843012,1.9956879,0,0,0,4453,4.93375,-5479.2275390625,,,,,,,,,,,,,,,,,13.378378,,,,,,5.00539805,,,,
,15651222.96,4.9990008,-2172.65832519531,-0.000142695036086926,1.73852245078106E-7,1,0.999253354069792,40.0298881530762,2.00494294999523,15.6900031119585,-0.00153755660992692,-0.000297510611059882,0.25,-2.39152068689717E-6,-0.000141847064197574,-2.70198622175593E-6,4.9985714,4.9994302,-2202.68701171875,-2142.62963867187,52.5950014305248,18.6746734993987,1.96588335,0,0,0,4453,4.93575,-2172.65832519531,,,,,,,,,,,,,,,,,12.252253,,,,,,4.9990008,,,,
,15651297.315,4.999404,1541.09191894531,-2.15435984080153E-5,2.93261508388067E-7,1,0.999253354069792,40.0298881530762,2.00500921842259,15.6900031119585,-0.000228407746340638,-6.61087041353714E-5,0.25,-2.32230517221417E-6,-2.14109856277703E-5,-2.35709931601674E-6,4.999404,4.999404,1538.58276367187,1543.60107421875,52.6184502861017,18.6749036503651,1.9268991,0,0,0,4449,4.9367,1541.09191894531,,,,,,,,,,,,,,,,,12.252253,,,,,,4.999404,,,,
,15651376.265,4.99920105,5488.58374023438,4.68685509856405E-5,2.50580616104886E-7,1,0.999253354069792,40.0298881530762,2.00490558681319,15.6900031119585,0.000510834151987067,6.48053170795706E-5,0.25,-2.26654915756273E-6,4.65997110522215E-5,-2.14041687734526E-6,4.998734,4.9996681,5456.02490234375,5521.142578125,52.7544536484479,18.671790763668,1.85151175,0,0,0,4449,4.93705,5488.58374023438,,,,,,,,,,,,,,,,,13.003003,,,,,,4.99920105,,,,
,15651453.565,4.9973416,9350.07666015625,6.25584894742189E-5,2.25761705354455E-7,1,0.999253354069792,40.0298881530762,2.00491824974408,15.6900031119585,0.000679744620008418,9.87428725471677E-5,0.25,-1.90425836162787E-6,6.22018804984149E-5,-1.73163605211815E-6,4.996891,4.9977922,9319.9443359375,9380.208984375,52.6981763950633,18.6699352213126,1.8148862,0,0,0,4449,4.93695,9350.07666015625,,,,,,,,,,,,,,,,,13.003003,,,,,,4.9973416,,,,
,15651532.17,5.0003653,13280.6713867188,7.15539737387706E-5,2.1744384639399E-7,1,0.999253354069792,40.0298881530762,2.0048315193762,15.6900031119585,0.000777528982490683,0.000112944293033465,0.25,-2.19207115015494E-6,7.11527541716215E-5,-1.98110540202363E-6,5.0003653,5.0003653,13278.2568359375,13283.0859375,52.6950498809863,18.6700175697709,1.7788963,0,0,0,4449,4.9378,13280.6713867188,,,,,,,,,,,,,,,,,13.378378,,,,,,5.0003653,,,,
,15651612.945,4.9983411,17316.4375,8.42309404269092E-5,2.92119612559987E-7,1,0.999253354069792,40.0298881530762,2.00475154574423,15.6900031119585,0.0009151904863711,0.000133841950106277,0.25,-2.51635330950181E-6,8.37674721643743E-5,-2.25153493328112E-6,4.9983411,4.9983411,17311.435546875,17321.439453125,52.5285630063902,18.6693729671287,1.7967564,0,0,0,4449,4.9392,17316.4375,,,,,,,,,,,,,,,,,13.003003,,,,,,4.9983411,,,,
,15651689.385,5.0030112,21136.6005859375,0.000104145428748563,3.57403967206868E-7,1,0.999253354069792,40.0298881530762,2.00491913660377,15.6900031119585,0.00113092020713775,0.000170392823390375,0.25,-2.68078148087539E-6,0.000103582672224437,-2.3356453572934E-6,5.0030112,5.0030112,21134.341796875,21138.859375,52.5871851453325,18.6683606331242,1.7092142,0,0,0,4449,4.94375,21136.6005859375,,,,,,,,,,,,,,,,,13.378378,,,,,,5.0030112,,,,
,15651774.84,5.0060315,25409.7119140625,0.000128885060623158,3.48346755657484E-7,1,0.999253354069792,40.0298881530762,2.00481296163846,15.6900031119585,0.00139891374264393,0.00021527503056288,0.25,-2.94033676357612E-6,0.000128204870789925,-2.48721706502642E-6,5.0060315,5.0060315,25407.15234375,25412.271484375,52.1823015723709,18.6780778933379,1.7612139,0,0,0,4449,4.9477,25409.7119140625,,,,,,,,,,,,,,,,,13.003003,,,,,,5.0060315,,,,
,15651854.865,4.978879,29410.359375,0.000149701471793817,4.25341926831124E-7,1,0.999253354069792,40.0298881530762,2.00477386982673,15.6900031119585,0.00162413154793323,0.000255249666493199,0.25,-2.96753113429064E-6,0.000148930399010932,-2.4131484706861E-6,4.978632,4.979126,29380.423828125,29440.294921875,52.4504001544671,18.6700798148141,1.73521405,0,0,0,4453,4.94825,29410.359375,,,,,,,,,,,,,,,,,13.753754,,,,,,4.978879,,,,
,15651942.31,4.9887204,33780.62890625,0.000162550353409406,4.73009420222537E-7,1,0.999253354069792,40.0298881530762,2.00474284617146,15.6900031119585,0.00176226378006403,0.00028579474090765,0.25,-2.46354141497585E-6,0.000161736356211642,-1.82969902730322E-6,4.9884882,4.9889526,33748.09765625,33813.16015625,52.697394766544,18.6673172245404,1.58585265,0,0,0,4453,4.96175,33780.62890625,,,,,,,,,,,,,,,,,13.003003,,,,,,4.9887204,,,,
,15652029.47,4.9944754,38132.943359375,0.000167272569823805,4.42168839722033E-7,1,0.999253354069792,40.0298881530762,2.00485585614164,15.6900031119585,0.0018115018285069,0.00030745398442746,0.25,-1.34262977655898E-6,0.000166458611303046,-6.60216607397112E-7,4.9944754,4.9944754,38130.53515625,38135.3515625,52.5051141508132,18.6710861320549,1.4496372,0,0,0,4449,4.9668,38132.943359375,,,,,,,,,,,,,,,,,12.252253,,,,,,4.9944754,,,,
,15652114.64,4.99246955,42391.181640625,0.000169168996627193,5.6126920141155E-7,1,0.999253354069792,40.0298881530762,2.00491325399811,15.6900031119585,0.00183584313233602,0.000291756859322253,0.25,-3.17244466395453E-6,0.000168383182764679,-2.43884369372955E-6,4.9919786,4.9929605,42358.640625,42423.72265625,52.5942198020056,18.6721518342343,1.3788699,0,0,0,4449,4.9707,42391.181640625,,,,,,,,,,,,,,,,,13.003003,,,,,,4.99246955,,,,
,15652200.995,4.9944973,46709.33203125,0.000167836976130768,5.79729679297686E-7,1,0.999253354069792,40.0298881530762,2.00499366218167,15.6900031119585,0.00182383856485423,0.000278128813112296,0.25,-4.23522194665213E-6,0.000167093997958085,-3.46884945411139E-6,4.9944973,4.9944973,46706.859375,46711.8046875,52.7544536484479,18.6739607486061,1.3448428,0,0,0,4449,4.9753,46709.33203125,,,,,,,,,,,,,,,,,13.003003,,,,,,4.9944973,,,,
,15652285.51,4.995574,50932.337890625,0.00016274333093084,5.85066160453587E-7,1,0.999253354069792,40.0298881530762,2.0048041511849,15.6900031119585,0.00176950072250845,0.000265109377418886,0.25,-4.5637898565001E-6,0.000162056751679636,-3.78827404123836E-6,4.995574,4.995574,50930.03515625,50934.640625,52.7263150217556,18.6732792814012,1.3182398,0,0,0,4449,4.9764,50932.337890625,,,,,,,,,,,,,,,,,13.378378,,,,,,4.995574,,,,
,15652369.97,4.9960198,55152.58984375,0.000155058254439308,5.74665146064927E-7,1,0.999253354069792,40.0298881530762,2.00477931860196,15.6900031119585,0.00168484835995274,0.000260569387144334,0.25,-3.6437879118453E-6,0.000154432134086794,-2.88026306030107E-6,4.9960198,4.9960198,55152.58984375,55152.58984375,52.5715525749479,18.6761803927687,1.2415471,0,0,0,4449,4.9801,55152.58984375,,,,,,,,,,,,,,,,,13.003003,,,,,,4.9960198,,,,
,15652454.86,5.00122235,59396.068359375,0.000147162632872668,5.63606893023282E-7,1,0.999253354069792,40.0298881530762,2.00488496655697,15.6900031119585,0.00160023591311227,0.000243101210746618,0.25,-3.87801754406987E-6,0.000146601344425807,-3.12664261270661E-6,5.0007529,5.0016918,59391.109375,59401.02734375,52.8185471870248,18.674771466569,1.3051363,0,0,0,4449,4.9768,59396.068359375,,,,,,,,,,,,,,,,,12.252253,,,,,,5.00122235,,,,
,15652540.91,5.00505375,63696.630859375,0.000138693649627237,6.64135428498716E-7,1,0.999253354069792,40.0298881530762,2.00490908757608,15.6900031119585,0.0015091965678839,0.00022524502441781,0.25,-4.04011004369356E-6,0.000138196997529844,-3.30805788717517E-6,5.0041389,5.0059686,63664.0390625,63729.22265625,52.6458072842748,18.6730551152224,1.3051363,0,0,0,4449,4.96715,63696.630859375,,,,,,,,,,,,,,,,,13.378378,,,,,,5.00505375,,,,
,15652625.555,5.0119679,67929.76171875,0.000130772495884564,6.82233897250446E-7,1,0.999253354069792,40.0298881530762,2.00484958268778,15.6900031119585,0.00142503172844397,0.000202646695423197,0.25,-4.7324601414552E-6,0.000130337971825994,-4.01952352872241E-6,5.011642,5.0122938,67897.3828125,67962.140625,52.6020360871979,18.6744821227869,1.33829235,0,0,0,4449,4.9648,67929.76171875,,,,,,,,,,,,,,,,,13.003003,,,,,,5.0119679,,,,
,15652708.83,5.0067105,72092.49609375,0.000121552791361186,7.54776668106049E-7,1,0.999253354069792,40.0298881530762,2.00486419731665,15.6900031119585,0.0013241481031908,0.000192420604005084,0.25,-4.04505828784127E-6,0.000121173916504641,-3.36719702489106E-6,5.0067105,5.0067105,72090.1015625,72094.890625,52.4824469237556,18.6742708346374,1.3583449,0,0,0,4449,4.9598,72092.49609375,,,,,,,,,,,,,,,,,13.003003,,,,,,5.0067105,,,,
,15652792.74,5.00393895,76285.66015625,0.000109533898826243,5.41472195940902E-7,1,0.999253354069792,40.0298881530762,2.00491667453633,15.6900031119585,0.00119415256055736,0.000169913847932178,0.25,-3.9849818882096E-6,0.000109219121164766,-3.35932078643376E-6,5.0036364,5.0042415,76258.2421875,76313.078125,52.8396511570441,18.6731220846271,1.33815885,0,0,0,4449,4.9586,76285.66015625,,,,,,,,,,,,,,,,,13.378378,,,,,,5.00393895,,,,
,15652873.18,5.000546,80303.12890625,0.000100524752808896,4.54838317504623E-7,1,0.999253354069792,40.0298881530762,2.00468592003749,15.6900031119585,0.00109635914715003,0.000154268595852447,0.25,-3.82475337998875E-6,0.000100258802721526,-3.23901087361582E-6,5.0001922,5.0008998,80275.8359375,80330.421875,52.6434623987171,18.6708572624852,1.3719826,0,0,0,4449,4.956,80303.12890625,,,,,,,,,,,,,,,,,12.252253,,,,,,5.000546,,,,
,15652954.94,4.9981365,84391.4296875,9.33062624895514E-5,8.38246276026636E-7,1,0.999253354069792,40.0298881530762,2.00485594449774,15.6900031119585,0.00101543178108594,0.000157193656689996,0.25,-2.2720090554029E-6,9.30728503624588E-5,-1.72221016974976E-6,4.9981365,4.9981365,84383.9375,84398.921875,52.5129304360056,18.6682839576012,1.3719826,0,0,0,4449,4.95845,84391.4296875,,,,,,,,,,,,,,,,,12.252253,,,,,,4.9981365,,,,
,15653033.07,4.9956763,88297.140625,8.24911791989837E-5,7.12652555395393E-7,1,0.999253354069792,40.0298881530762,2.00482694211645,15.6900031119585,0.000901085024475845,0.00012137536492631,0.25,-3.64291962100094E-6,8.23120767204228E-5,-3.14537148090837E-6,4.995369,4.9959836,88272.125,88322.15625,52.4206982707363,18.6699071387293,1.3719826,0,0,0,4449,4.9551,88297.140625,,,,,,,,,,,,,,,,,13.003003,,,,,,4.9956763,,,,
,15653068.79,4.9996083,89999.56640625,7.8430473367269E-5,8.7487088252005E-7,1,0.999253354069792,40.0298881530762,2.00484051960561,15.6900031119585,0.000855571900235938,0.000122315753909538,0.25,-2.82966508184306E-6,7.82637530220349E-5,-2.3553452971054E-6,4.9995666,4.99965,89999.5390625,89999.59375,52.6223584286979,18.6734710356189,1.3583449,0,0,0,4417,4.95725,89999.56640625,,,,,,,,,,,,,,,,,13.003003,,,,,,4.9996083,,,,