File: data/doubleLayers/dl_1-25/ppms/KoelnPPMS/LowTemperatureHysVaryingSpeed/DD205_ZFC_2KMIN_HYS9T_REPRODUCE.DAT
[Header]
; VSM Data File (default extension .dat)
; Copyright (c) 2003-2013, Quantum Design, Inc. All rights reserved.
TITLE,
FILEOPENTIME,22997891.88,09/24/2018,1:16 pm
BYAPP,VSM,2.0,2.0
INFO,PPMS VSM Option Release 1.4.10 Build 1,APPNAME
INFO,Quantum Design Linear Motor Servo Controller,MOTOR_MODULE_NAME
INFO,3101-100 M1,MOTOR_HW_VERSION
INFO,MMC1014,MOTOR_SERIAL_NUMBER
INFO,SRV No X-over 01.03.11,MOTOR_SOFTWARE_VERSION
INFO,Quantum Design VSM Detection Module,VSM_MODULE_NAME
INFO,3101-150 F0,VSM_HW_VERSION
INFO,VSM707,VSM_SERIAL_NUMBER
INFO,VSM No X-over 01.02.05 May 20 2008 13:51:47,VSM_SOFTWARE_VERSION
INFO,704,PREAMP_SERIAL_NUMBER
INFO,822,COIL_SERIAL_NUMBER
INFO,0,MOMENT_UNITS
INFO,,SAMPLE_MATERIAL
INFO,,SAMPLE_COMMENT
INFO,,SAMPLE_MASS
INFO,,SAMPLE_VOLUME
INFO,,SAMPLE_MOLECULAR_WEIGHT
INFO,,SAMPLE_SIZE
INFO,,SAMPLE_SHAPE
DATATYPE,COMMENT,1
DATATYPE,TIME,2
STARTUPAXIS,X,2
STARTUPAXIS,Y1,5
[Data]
Comment,Time Stamp (sec),Temperature (K),Magnetic Field (Oe),Moment (emu),M. Std. Err. (emu),Transport Action,Averaging Time (sec),Frequency (Hz),Peak Amplitude (mm),Center Position (mm),Coil Signal' (mV),Coil Signal" (mV),Range (mV),M. Quad. Signal (emu),M. Raw' (emu),M. Raw" (emu),Min. Temperature (K),Max. Temperature (K),Min. Field (Oe),Max. Field (Oe),Mass (grams),Motor Lag (deg),Pressure (Torr),VSM Status (code),Motor Status (code),Measure Status (code),Measure Count,PPMS Status (code),System Temp. (K),System Field (Oe),Sample Position (deg),Bridge 1 Resistance (ohms),Bridge 1 Excitation (에),Bridge 2 Resistance (ohms),Bridge 2 Excitation (에),Bridge 3 Resistance (ohms),Bridge 3 Excitation (에),Bridge 4 Resistance (ohms),Bridge 4 Excitation (에),Signal 1 Vin (V),Signal 2 Vin (V),Digital Inputs (code),Drive 1 Iout (mA),Drive 1 Ipower (W),Drive 2 Iout (mA),Drive 2 Ipower (W),Pressure (),Map 20 (),Map 21 (),Map 22 (),Map 23 (),Map 24 (),Map 25 (),Map 26 (),Map 27 (),Map 28 (),Map 29 ()
,23007092.42,10.0015907,-0.106566414237022,,,2,,,,16.570000127852,,,,,,,10.0015907,10.0015907,-0.106566414237022,-0.106566414237022,,,11.899124,,,,-99999999,4417,9.9876,-0.106566414237022,,,,,,,,,,,,,,,,,,,,,,,10.0015907,,,,
,23007282.84,9.9930868,3788.19458007812,7.17661009245263E-6,3.40095384387793E-7,1,0.999253354069792,40.0298881530762,1.99747968113504,16.5599994361401,8.12507784529888E-5,1.10268571337834E-5,0.25,-2.94941420344986E-7,7.13828517333573E-6,-2.57115858745767E-7,9.9930868,9.9930868,3783.05810546875,3793.3310546875,56.648526931256,20.6250387969706,11.899124,0,0,0,40,4449,10.002,3788.19458007812,,,,,,,,,,,,,0,,,,-0.0049,,,,,,9.9930868,,,,
,23007443.245,9.9944439,7796.00073242188,4.87901812529957E-6,2.64448244619228E-7,1,0.999253354069792,40.0298881530762,1.99728105679424,16.5599994361401,5.62070291415999E-5,2.12125900941426E-6,0.25,-6.80249799858731E-7,4.85694604798472E-6,-6.50656553502298E-7,9.9944439,9.9944439,7791.0400390625,7800.96142578125,56.5641110511791,20.6291218146444,11.899124,0,0,0,40,4449,10.00945,7796.00073242188,,,,,,,,,,,,,0,,,,-0.0049,,,,,,9.9944439,,,,
,23007602.05,9.9968081,11766.0146484375,3.44616687572076E-6,3.33780734969398E-7,1,0.999253354069792,40.0298881530762,1.99745357377777,16.5599994361401,3.8794617645942E-5,6.67505548628376E-6,0.25,-2.120275435063E-8,3.42923306957348E-6,-1.71635296777691E-9,9.9968081,9.9968081,11759.7265625,11772.302734375,56.6602513590445,20.6272717058703,11.899124,0,0,0,40,4449,10.01425,11766.0146484375,,,,,,,,,,,,,0,,,,-0.00245,,,,,,9.9968081,,,,
,23007790.79,9.9976597,16482.482421875,4.54497349338832E-6,3.37091818616273E-7,1,0.999253354069792,40.0298881530762,1.99724354836228,16.5699999779463,5.19273993222941E-5,4.62962929302179E-6,0.25,-4.00814846948486E-7,4.5267744248659E-6,-3.71905558499476E-7,9.9976597,9.9976597,16477.376953125,16487.587890625,57.126101956506,20.6334459796888,11.139823,0,0,0,40,4449,10.0178,16482.482421875,,,,,,,,,,,,,0,,,,-0.00245,,,,,,9.9976597,,,,
,23007949.555,9.9976902,20450.1572265625,9.47455297029723E-6,3.48124403138704E-7,1,0.999253354069792,40.0298881530762,1.9973799361146,16.5699999779463,0.000106659984489775,1.88158159019525E-5,0.25,-2.39950220011399E-8,9.43536458273804E-6,3.50933647591155E-8,9.9976902,9.9976902,20445.28125,20455.033203125,57.0831123879483,20.6298718324313,11.139823,0,0,0,40,4449,10.0214,20450.1572265625,,,,,,,,,,,,,0,,,,0,,,,,,9.9976902,,,,
,23008109.615,9.99856,24450.322265625,1.82589031283277E-5,3.79540518801052E-7,1,0.999253354069792,40.0298881530762,1.99737640210082,16.5699999779463,0.000205263220206685,3.83352942405682E-5,0.25,1.32321420280056E-7,1.81895251606824E-5,2.49959916224975E-7,9.99856,9.99856,24448.1875,24452.45703125,57.0401228193907,20.6313204024827,11.519473,0,0,0,40,4449,10.02285,24450.322265625,,,,,,,,,,,,,0,,,,-0.0049,,,,,,9.99856,,,,
,23008266.51,9.99811265,28370.1376953125,2.68943245234288E-5,4.7061404404375E-7,1,0.999253354069792,40.0298881530762,1.99730828810943,16.5699999779463,0.000301982360078392,5.91127077290896E-5,0.25,4.22416273002537E-7,2.68014319304479E-5,6.0075177362673E-7,9.998044,9.9981813,28366.103515625,28374.171875,57.2073913225061,20.6322643472611,11.519473,0,0,0,40,4449,10.02575,28370.1376953125,,,,,,,,,,,,,0,,,,0.0049,,,,,,9.99811265,,,,
,23008456.415,9.9983039,33117.525390625,3.14812907673948E-5,4.21200750886995E-7,1,0.999253354069792,40.0298881530762,1.99754007616889,16.5899991989136,0.000355711425302564,5.80592164323557E-5,0.25,-5.0455673499789E-7,3.13950638385913E-5,-2.85708132942918E-7,9.9982243,9.9983835,33113.6875,33121.36328125,56.8947399148137,20.6338330881985,11.139823,0,0,0,40,4449,10.0294,33117.525390625,,,,,,,,,,,,,0,,,,-0.00245,,,,,,9.9983039,,,,
,23008616.62,9.9977627,37119.119140625,3.00642935538592E-5,4.51099954993482E-7,1,0.999253354069792,40.0298881530762,1.99755442533655,16.5899991989136,0.000338282378129407,6.4178346028537E-5,0.25,2.86145814644974E-7,2.99893659148629E-5,4.97765869642814E-7,9.9977627,9.9977627,37114.26953125,37123.96875,57.0026046504676,20.6320248427193,11.139823,0,0,0,40,4449,10.0307,37119.119140625,,,,,,,,,,,,,0,,,,0,,,,,,9.9977627,,,,
,23008776.4,9.9972658,41111.9921875,2.49462072094187E-5,5.98121667918216E-7,1,0.999253354069792,40.0298881530762,1.99746395386154,16.5899991989136,0.000280258964957669,5.62823400427296E-5,0.25,5.01225327608586E-7,2.48926609923829E-5,6.79563089930414E-7,9.9972658,9.9972658,41109.54296875,41114.44140625,57.0815491309099,20.6328375176454,11.519473,0,0,0,40,4449,10.0351,41111.9921875,,,,,,,,,,,,,0,,,,-0.00245,,,,,,9.9972658,,,,
,23008927.305,9.9983969,44884.220703125,1.86875842872013E-5,5.25775507496846E-7,1,0.999253354069792,40.0298881530762,1.99752442744283,16.5899991989136,0.000212153145536676,3.04209416032838E-5,0.25,-6.68708485930092E-7,1.86624410077737E-5,-5.31516493773878E-7,9.9983969,9.9983969,44880.40625,44888.03515625,57.0401228193907,20.6335143361424,11.899124,0,0,0,40,4449,10.03655,44884.220703125,,,,,,,,,,,,,0,,,,0,,,,,,9.9983969,,,,
,23009104.65,9.9976597,49315.513671875,9.31609683493659E-6,8.51911975273272E-7,1,0.999253354069792,40.0298881530762,1.99749185753184,16.610000282526,0.000106337767580562,1.22391129790601E-5,0.25,-5.94003568493634E-7,9.30976803107318E-6,-5.2470486763501E-7,9.9976597,9.9976597,49310.5625,49320.46484375,57.0033862789868,20.6313048457125,11.139823,0,0,0,40,4449,10.04015,49315.513671875,,,,,,,,,,,,,0,,,,-0.00245,,,,,,9.9976597,,,,
,23009251.43,9.9972277,52983.130859375,1.55222038224117E-6,5.3737782446755E-7,1,0.999253354069792,40.0298881530762,1.99753022516925,16.610000282526,1.92888695099603E-5,-6.63948986159356E-6,0.25,-8.67880463832076E-7,1.5574416148188E-6,-8.55702179101302E-7,9.9972277,9.9972277,52980.66796875,52985.59375,57.0870205305445,20.6309672312064,11.519473,0,0,0,40,4449,10.04425,52983.130859375,,,,,,,,,,,,,0,,,,-0.00245,,,,,,9.9972277,,,,
,23009398.22,9.9977884,56652.76171875,-6.25503429876165E-6,7.69517950064265E-7,1,0.999253354069792,40.0298881530762,1.99755724376178,16.610000282526,-7.15864942853279E-5,-7.47924406045894E-6,0.25,4.6517368801951E-7,-6.25587157979287E-6,4.18469153715163E-7,9.9977884,9.9977884,56648.9765625,56656.546875,56.7978179784291,20.6323268832939,11.139823,0,0,0,40,4449,10.04585,56652.76171875,,,,,,,,,,,,,0,,,,0,,,,,,9.9977884,,,,
,23009561.97,9.994544,60744.52734375,,,2,,,,16.629999653399,,,,,,,9.994544,9.994544,60744.52734375,60744.52734375,,,11.139823,,,,-99999999,4449,10.0495,60744.52734375,,,,,,,,,,,,,,,,,,,,,,,9.994544,,,,
,23009739.245,9.9967327,65175.0078125,-2.71103548293046E-5,7.7026471982483E-7,1,0.999253354069792,40.0298881530762,1.99776697256899,16.6200008243322,-0.000305118100697698,-6.25546483197693E-5,0.25,-6.47923624977409E-7,-2.71156924306656E-5,-8.49602103494535E-7,9.9967327,9.9967327,65170.14453125,65179.87109375,57.3543374841214,20.629488587952,11.899124,0,0,0,40,4449,10.056,65175.0078125,,,,,,,,,,,,,0,,,,0.00245,,,,,,9.9967327,,,,
,23009898.94,9.9962864,69165.68359375,-3.83965593180241E-5,6.54447627274502E-7,1,0.999253354069792,40.0298881530762,1.99768185624054,16.6200008243322,-0.00043312783768884,-8.38854652440349E-5,0.25,-4.99807809741914E-7,-3.84206340337302E-5,-7.84342201323182E-7,9.9962864,9.9962864,69160.5546875,69170.8125,57.1745629246983,20.6301171840715,11.139823,0,0,0,40,4449,10.0616,69165.68359375,,,,,,,,,,,,,0,,,,0.00245,,,,,,9.9962864,,,,
,23010056.69,9.9967594,73107.13671875,-4.76495141428196E-5,7.22282082158872E-7,1,0.999253354069792,40.0298881530762,1.99779492417501,16.6200008243322,-0.000537933863623655,-0.000102902916099827,0.25,-5.13004354717383E-7,-4.76959115748557E-5,-8.64154665131145E-7,9.9967594,9.9967594,73103.3203125,73110.953125,57.027616763083,20.6299101167786,11.519473,0,0,0,40,4449,10.0655,73107.13671875,,,,,,,,,,,,,0,,,,0,,,,,,9.9967594,,,,
,23010247.27,9.9978628,77869.87109375,-6.17938161482348E-5,8.09891369844647E-7,1,0.999253354069792,40.0298881530762,1.99785157703214,16.6299995034933,-0.000697655439412999,-0.000134843908140183,0.25,-7.88164650208259E-7,-6.18765029329838E-5,-1.23978505210191E-6,9.9978628,9.9978628,77865.875,77873.8671875,57.2605420618137,20.6320327484012,11.139823,0,0,0,40,4449,10.0708,77869.87109375,,,,,,,,,,,,,0,,,,0,,,,,,9.9978628,,,,
,23010409.75,9.9967165,81931.5390625,-7.23093333329071E-5,9.01030988810212E-7,1,0.999253354069792,40.0298881530762,1.99787833500154,16.6299995034933,-0.000817543690625651,-0.000152796312843881,0.25,-4.81858446629854E-7,-7.24313979312003E-5,-1.00481317403073E-6,9.9967165,9.9967165,81928.1640625,81934.9140625,57.3574639981984,20.6315191623493,11.139823,0,0,0,40,4449,10.07605,81931.5390625,,,,,,,,,,,,,0,,,,-0.00245,,,,,,9.9967165,,,,
,23010565.22,9.9974661,85816.890625,-8.25399376219542E-5,7.64159153219948E-7,1,0.999253354069792,40.0298881530762,1.99788849939881,16.6299995034933,-0.000935091440184453,-0.00016548306667415,0.25,2.36731340101818E-7,-8.27078070892021E-5,-3.52582166494782E-7,9.9974661,9.9974661,85813.09375,85820.6875,56.9697762526599,20.6316724280491,10.760172,0,0,0,40,4449,10.0812,85816.890625,,,,,,,,,,,,,0,,,,-0.00245,,,,,,9.9974661,,,,
,23010713.67,9.9968576,89526.79296875,-9.29933585898717E-5,1.10882003790882E-6,1,0.999253354069792,40.0298881530762,1.99794927333152,16.6299995034933,-0.00105322438543173,-0.00018975962881437,0.25,-2.91173180587932E-8,-9.32037547190953E-5,-6.86394225202025E-7,9.9968576,9.9968576,89521.4609375,89532.125,57.3254172289099,20.632517575849,11.519473,0,0,0,40,4449,10.08445,89526.79296875,,,,,,,,,,,,,0,,,,-0.00245,,,,,,9.9968576,,,,
,23010912.47,10.0010319,86027.4140625,-8.39807699395428E-5,8.7191582832504E-7,1,0.999253354069792,40.0298881530762,1.99776339727123,16.6400000452995,-0.000949143625763765,-0.000180746596746741,0.25,-8.53106758820453E-7,-8.41449827193653E-5,-1.45456297585259E-6,10.0010319,10.0010319,86024.7421875,86030.0859375,56.9033378285253,20.6335146730898,11.139823,0,0,0,40,4449,10.0841,86027.4140625,,,,,,,,,,,,,0,,,,0,,,,,,10.0010319,,,,
,23011067.94,10.0016508,82141.0078125,-7.27502444871504E-5,8.95154978784907E-7,1,0.999253354069792,40.0298881530762,1.99781253341545,16.6400000452995,-0.000821436312341486,-0.000159720423111788,0.25,-1.01468846999889E-6,-7.2870344017181E-5,-1.54148735518219E-6,10.0016508,10.0016508,82133.6875,82148.328125,57.3519925985638,20.6341622024282,11.139823,0,0,0,40,4449,10.08125,82141.0078125,,,,,,,,,,,,,0,,,,0.00245,,,,,,10.0016508,,,,
,23011232.79,10.0033979,78020.51171875,-6.10283597173646E-5,1.07727993721946E-6,1,0.999253354069792,40.0298881530762,1.99788409402535,16.6400000452995,-0.000687291391352458,-0.000142843375508889,0.25,-1.63273275675465E-6,-6.11045053206961E-5,-2.07985379091655E-6,10.0033979,10.0033979,78014.28125,78026.7421875,56.973684395256,20.6368762890967,10.760172,0,0,0,40,4449,10.0778,78020.51171875,,,,,,,,,,,,,0,,,,0,,,,,,10.0033979,,,,
,23011385.775,10.004283,74196.8828125,-5.05431092933578E-5,8.41334901597139E-7,1,0.999253354069792,40.0298881530762,1.9979195509981,16.6400000452995,-0.000571272529873255,-0.000105907653197709,0.25,-2.56705505207072E-7,-5.05989140148422E-5,-6.2818870777231E-7,10.004283,10.004283,74190.859375,74202.90625,56.9963516223137,20.6372385665848,11.139823,0,0,0,40,4449,10.0739,74196.8828125,,,,,,,,,,,,,0,,,,0,,,,,,10.004283,,,,
,23011567.57,10.0033875,69652.62890625,-3.91133312519923E-5,8.16607782031917E-7,1,0.999253354069792,40.0298881530762,1.99780174641135,16.6500005871058,-0.000441114394324533,-8.62506188338017E-5,0.25,-5.79259116383391E-7,-3.9138963112683E-5,-8.69000626013159E-7,10.0033875,10.0033875,69647.734375,69657.5234375,57.2621053188522,20.6344175177104,11.519473,0,0,0,40,4449,10.0678,69652.62890625,,,,,,,,,,,,,0,,,,0.00245,,,,,,10.0033875,,,,
,23011717.405,10.0021257,65907.75390625,-2.84849417820259E-5,8.70218744964531E-7,1,0.999253354069792,40.0298881530762,1.99791008150701,16.6500005871058,-0.000318587092087545,-7.70782083936624E-5,0.25,-1.68428540733065E-6,-2.84849573531443E-5,-1.89655542293474E-6,10.0021257,10.0021257,65906.375,65909.1328125,57.0393411908714,20.6353243528405,11.139823,0,0,0,40,4449,10.0644,65907.75390625,,,,,,,,,,,,,0,,,,0.00245,,,,,,10.0021257,,,,
,23011868.76,10.0026007,62125.6796875,-1.95721925022957E-5,7.89410736837317E-7,1,0.999253354069792,40.0298881530762,1.99784678405895,16.6500005871058,-0.000221065059338437,-4.04953304389677E-5,0.25,-5.55834434959106E-8,-1.95736943726388E-5,-2.01239034909078E-7,10.0026007,10.0026007,62123.1484375,62128.2109375,57.0354330482753,20.6385359696084,10.760172,0,0,0,40,4449,10.062,62125.6796875,,,,,,,,,,,,,0,,,,0,,,,,,10.0026007,,,,
touchdown = 10.8700003474951 mm,23012046.16,10.0033188,57691.201171875,-7.26112900892179E-6,7.89697627826088E-7,1,0.999253354069792,40.0298881530762,1.99782111333915,16.6500005871058,-8.21329012358624E-5,-1.41587185802334E-5,0.25,5.53683727792572E-8,-7.25922402044168E-6,1.33127446905896E-9,10.0033188,10.0033188,57687.43359375,57694.96875,57.0049495360253,20.6361737854557,11.139823,0,0,0,40,4449,10.062,57691.201171875,,,,,,,,,,,,,0,,,,0.00245,,,,,,10.0033188,,,,
,23012194.25,10.00223495,53991.087890625,2.25518883666598E-6,6.86189200575799E-7,1,0.999253354069792,40.0298881530762,1.99798815863469,16.6500005871058,2.41266948042791E-5,1.20268898529435E-5,0.25,6.58562954237592E-7,2.24877089244224E-6,6.74846374658013E-7,10.0021706,10.0022993,53987.39453125,53994.78125,56.9979148793522,20.6378747533616,11.519473,0,0,0,40,4449,10.05505,53991.087890625,,,,,,,,,,,,,0,,,,-0.00245,,,,,,10.00223495,,,,
,23012342.375,10.0022526,50289.146484375,9.94165212394893E-6,6.62366141445949E-7,1,0.999253354069792,40.0298881530762,1.99791784309598,16.6500005871058,0.00011280711032811,1.69798677598604E-5,0.25,-2.87199918808631E-7,9.93333268826218E-6,-2.13537614195497E-7,10.0022526,10.0022526,50286.59375,50291.69921875,57.281646031833,20.6385246331005,11.139823,0,0,0,40,4449,10.0527,50289.146484375,,,,,,,,,,,,,0,,,,-0.00245,,,,,,10.0022526,,,,
,23012490.375,10.0021553,46591.201171875,1.82284374684471E-5,5.56899842291112E-7,1,0.999253354069792,40.0298881530762,1.99789395871534,16.6500005871058,0.000205381770552247,3.87464413710492E-5,0.25,1.50231230065878E-7,1.82012928411621E-5,2.83429869920764E-7,10.0021553,10.0021553,46588.765625,46593.63671875,57.0252718775253,20.6400813181625,11.139823,0,0,0,40,4449,10.04985,46591.201171875,,,,,,,,,,,,,0,,,,0.0049,,,,,,10.0021553,,,,
,23012668.47,10.0028019,42140.9375,2.94848339220402E-5,6.16622753190193E-7,1,0.999253354069792,40.0298881530762,1.99782101566945,16.6599992662668,0.000332948374464689,5.76108608824203E-5,0.25,-2.00160148710167E-7,2.94304472197466E-5,1.30215673167185E-8,10.0028019,10.0028019,42135.93359375,42145.94140625,56.8001628639868,20.6360305382038,10.760172,0,0,0,40,4449,10.04945,42140.9375,,,,,,,,,,,,,0,,,,-0.00245,,,,,,10.0028019,,,,
,23012817.885,10.0018215,38406.505859375,3.66799973193582E-5,6.04788124800687E-7,1,0.999253354069792,40.0298881530762,1.99799563826561,16.6599992662668,0.000413848133690282,7.28668700492225E-5,0.25,-1.36836900009937E-7,3.65970311377732E-5,1.24126551595756E-7,10.0018215,10.0018215,38400.25390625,38412.7578125,57.0369963053137,20.6429246102272,11.139823,0,0,0,40,4449,10.0453,38406.505859375,,,,,,,,,,,,,0,,,,-0.0049,,,,,,10.0018215,,,,
,23012966.315,10.0020905,34698.55859375,4.38871596086841E-5,6.4135911931323E-7,1,0.999253354069792,40.0298881530762,1.99780649909742,16.6599992662668,0.000495322311697716,8.49227403985762E-5,0.25,-3.54819461574898E-7,4.37719252499057E-5,-4.79258017207525E-8,10.0020905,10.0020905,34697.4296875,34699.6875,57.3512109700445,20.6415887453218,11.139823,0,0,0,40,4449,10.0413,34698.55859375,,,,,,,,,,,,,0,,,,-0.0049,,,,,,10.0020905,,,,
,23013117.16,10.0016155,30928.0126953125,5.10016695767625E-5,5.31251091529795E-7,1,0.999253354069792,40.0298881530762,1.99796445601954,16.6599992662668,0.000575354676343418,9.9078810952175E-5,0.25,-3.6674145469959E-7,5.08470328477164E-5,-1.83689182190788E-8,10.0016155,10.0016155,30926.806640625,30929.21875,57.2167708647368,20.6410842402032,10.760172,0,0,0,40,4449,10.0399,30928.0126953125,,,,,,,,,,,,,0,,,,0,,,,,,10.0016155,,,,
,23013300.18,10.0015202,26352.7685546875,5.92366507656591E-5,4.96126134786559E-7,1,0.999253354069792,40.0298881530762,1.99792300924446,16.6599992662668,0.000667890801845992,0.000115176639460489,0.25,-3.98376039542671E-7,5.90285010631797E-5,-7.36251595703079E-9,10.0015202,10.0015202,26351.267578125,26354.26953125,57.2097362080637,20.6390149700502,10.760172,0,0,0,40,4449,10.0384,26352.7685546875,,,,,,,,,,,,,0,,,,-0.0049,,,,,,10.0015202,,,,
,23013462.105,10.0013514,22307.919921875,6.60796340633974E-5,4.51086351942333E-7,1,0.999253354069792,40.0298881530762,1.99802543841962,16.6599992662668,0.00074443499688753,0.000130318531737635,0.25,-2.61685720742678E-7,6.5819056218699E-5,1.58458359251292E-7,10.0013514,10.0013514,22304.095703125,22311.744140625,57.2300585495638,20.641954267259,11.519473,0,0,0,40,4449,10.03835,22307.919921875,,,,,,,,,,,,,0,,,,0.00245,,,,,,10.0013514,,,,
,23013622.7,10.0009632,18295.375,7.20814830759993E-5,3.4009400130743E-7,1,0.999253354069792,40.0298881530762,1.99797920073454,16.6599992662668,0.000812051378725478,0.000140193712520603,0.25,-4.35991532992573E-7,7.17698766533093E-5,4.50793141492177E-9,10.0009632,10.0009632,18291.73046875,18299.01953125,57.322290714833,20.6424976059928,11.519473,0,0,0,40,4449,10.03625,18295.375,,,,,,,,,,,,,0,,,,0.00245,,,,,,10.0009632,,,,
,23013785.915,10.0011549,14216.4892578125,7.71538938944461E-5,4.1208746044242E-7,1,0.999253354069792,40.0298881530762,1.99787835079503,16.6599992662668,0.00086801347863978,0.000154527135276843,0.25,-4.20079136989012E-8,7.67887582271267E-5,4.05811448119102E-7,10.0011549,10.0011549,14213.9775390625,14219.0009765625,57.4434431353138,20.6419285815315,10.760172,0,0,0,40,4449,10.0348,14216.4892578125,,,,,,,,,,,,,0,,,,-0.0049,,,,,,10.0011549,,,,
,23013972.705,10.0013456,9548.94140625,8.33510260874205E-5,3.72242197004153E-7,1,0.999253354069792,40.0298881530762,1.99802100342145,16.669999808073,0.000937316678497569,0.000167483417985596,0.25,3.63119491323326E-8,8.29231744138072E-5,4.91276603665219E-7,10.0013456,10.0013456,9543.775390625,9554.107421875,57.2746113751599,20.6426542379969,11.519473,0,0,0,40,4449,10.03335,9548.94140625,,,,,,,,,,,,,0,,,,0,,,,,,10.0013456,,,,
,23014134.18,10.0028629,5513.45239257812,8.75586660044837E-5,2.89058357120633E-7,1,0.999253354069792,40.0298881530762,1.99807429637876,16.669999808073,0.000984268206430582,0.000176393419623411,0.25,1.0894960307645E-7,8.70824070454473E-5,5.60543137759938E-7,10.0028629,10.0028629,5508.49072265625,5518.4140625,57.2167708647368,20.6433460880477,11.139823,0,0,0,40,4449,10.0279,5513.45239257812,,,,,,,,,,,,,0,,,,0,,,,,,10.0028629,,,,
,23014293.595,10.0050211,1528.78167724609,8.88996734960047E-5,2.84664285425152E-7,1,0.999253354069792,40.0298881530762,1.99817517627907,16.669999808073,0.000999469011788993,0.000177222502017768,0.25,-2.88879295040018E-8,8.83949606090668E-5,4.06543265758693E-7,10.0050211,10.0050211,1525.06127929687,1532.50207519531,57.1784710672945,20.6467674979716,11.519473,0,0,0,40,4449,10.02215,1528.78167724609,,,,,,,,,,,,,0,,,,0.00245,,,,,,10.0050211,,,,
,23014453.095,9.9987297,-2453.05810546875,7.28570549081112E-5,3.09485286645349E-7,1,0.999253354069792,40.0298881530762,1.99810276736154,16.669999808073,0.000819334905298608,0.000144039509811154,0.25,-1.34980859480236E-7,7.24476624242895E-5,2.26678102968031E-7,9.9987297,9.9987297,-2455.3525390625,-2450.763671875,57.3707516830253,20.6467151736042,11.139823,0,0,0,40,4449,10.0187,-2453.05810546875,,,,,,,,,,,,,0,,,,0.0049,,,,,,9.9987297,,,,
,23014636.53,9.996954,-7038.73657226563,7.36247973712143E-5,2.84002975801287E-7,1,0.999253354069792,40.0298881530762,1.99806265692256,16.669999808073,0.000827715666596175,0.000148367063179425,0.25,8.60141028148207E-8,7.32323853111233E-5,4.73950958828052E-7,9.996954,9.996954,-7043.53564453125,-7033.9375,57.6497930643907,20.6468910349474,11.139823,0,0,0,40,4449,10.0251,-7038.73657226563,,,,,,,,,,,,,0,,,,-0.00245,,,,,,9.996954,,,,
,23014781.995,9.9973793,-10675.3842773438,7.20586189890126E-5,3.17362322694923E-7,1,0.999253354069792,40.0298881530762,1.99801981753703,16.669999808073,0.000810842970855406,0.000142339840310952,0.25,-1.93870285775411E-7,7.16965621326749E-5,2.06591024132783E-7,9.9973793,9.9973793,-10677.927734375,-10672.8408203125,57.3863842534099,20.6466653240303,10.760172,0,0,0,40,4449,10.02805,-10675.3842773438,,,,,,,,,,,,,0,,,,-0.0049,,,,,,9.9973793,,,,
,23014930.69,9.9983301,-14391.2622070312,6.64060333238425E-5,4.47690180390141E-7,1,0.999253354069792,40.0298881530762,1.99810038764063,16.669999808073,0.000748274153974777,0.00012692745895515,0.25,-5.78248562809181E-7,6.60959495209643E-5,-1.89424934097742E-7,9.9983301,9.9983301,-14396.1943359375,-14386.330078125,57.2707032325638,20.6464468231526,10.760172,0,0,0,40,4449,10.0308,-14391.2622070312,,,,,,,,,,,,,0,,,,-0.00245,,,,,,9.9983301,,,,
,23015078.665,9.9988794,-18088.8984375,5.27720398718006E-5,4.02068557747046E-7,1,0.999253354069792,40.0298881530762,1.99821575634855,16.669999808073,0.000593708868340229,0.000107470804700313,0.25,1.10077029519574E-7,5.25402626007988E-5,4.29968611417085E-7,9.9988794,9.9988794,-18093.837890625,-18083.958984375,57.1761261817368,20.6486339544729,10.760172,0,0,0,40,4449,10.032,-18088.8984375,,,,,,,,,,,,,0,,,,0.00245,,,,,,9.9988794,,,,
,23015257.235,9.9990759,-22550.1240234375,2.77500099723057E-5,4.4833134942011E-7,1,0.999253354069792,40.0298881530762,1.99812382829797,16.669999808073,0.000312661342526236,5.46470343873545E-5,0.25,-1.17752537490055E-7,2.76413033901984E-5,5.91248479379548E-8,9.9990759,9.9990759,-22553.689453125,-22546.55859375,57.2034831799099,20.6477168244185,11.139823,0,0,0,40,4449,10.03405,-22550.1240234375,,,,,,,,,,,,,0,,,,0.00245,,,,,,9.9990759,,,,
,23015401.08,9.9979277,-26144.0068359375,5.75530605725585E-6,4.39733940226964E-7,1,0.999253354069792,40.0298881530762,1.99817390404847,16.669999808073,6.4833887973647E-5,1.15444202627354E-5,0.25,-7.29658592403751E-9,5.73475236026578E-6,3.05160329161901E-8,9.9979277,9.9979277,-26146.357421875,-26141.65625,57.4426615067945,20.6503153977261,11.139823,0,0,0,40,4449,10.0366,-26144.0068359375,,,,,,,,,,,,,0,,,,0.0049,,,,,,9.9979277,,,,
,23015544.985,9.99848605,-29741.3046875,-1.03244930147559E-5,4.01266254827036E-7,1,0.999253354069792,40.0298881530762,1.99809665127826,16.669999808073,-0.000115341304522543,-2.63097249209584E-5,0.25,-4.81461048708837E-7,-1.02881453999507E-5,-5.49628288564982E-7,9.9982996,9.9986725,-29742.64453125,-29739.96484375,57.3895107674868,20.6492452066543,10.760172,0,0,0,40,4449,10.0372,-29741.3046875,,,,,,,,,,,,,0,,,,0,,,,,,9.99848605,,,,
,23015690.635,9.9976244,-33380.4765625,-1.9618216192784E-5,5.37597152598323E-7,1,0.999253354069792,40.0298881530762,1.99812333019619,16.669999808073,-0.000220994861653809,-4.03207620672781E-5,0.25,-5.17144260988751E-8,-1.95624993703427E-5,-1.87270984009025E-7,9.9976244,9.9976244,-33385.42578125,-33375.52734375,57.2292769210445,20.650984321289,11.139823,0,0,0,40,4449,10.0393,-33380.4765625,,,,,,,,,,,,,0,,,,0.00245,,,,,,9.9976244,,,,
,23015868.295,9.9984827,-37820.169921875,-2.26520761100837E-5,5.03810566610445E-7,1,0.999253354069792,40.0298881530762,1.99800001629438,16.6800003498793,-0.000253238536939541,-5.79029445481889E-5,0.25,-1.06064813692695E-6,-2.2591313786016E-5,-1.21867570952803E-6,9.9984827,9.9984827,-37822.56640625,-37817.7734375,57.119067299833,20.651663161195,11.139823,0,0,0,40,4449,10.0418,-37820.169921875,,,,,,,,,,,,,0,,,,-0.00245,,,,,,9.9984827,,,,
,23016018.445,9.9979582,-41573.01171875,-2.08590814863342E-5,7.44961935437404E-7,1,0.999253354069792,40.0298881530762,1.99810856530168,16.6800003498793,-0.000234709689240879,-4.54997201616691E-5,0.25,-2.7892044010444E-7,-2.08163268655806E-5,-4.28602660631442E-7,9.9979582,9.9979582,-41575.55078125,-41570.47265625,57.0424677049483,20.6511694622542,11.139823,0,0,0,40,4449,10.04585,-41573.01171875,,,,,,,,,,,,,0,,,,0.00245,,,,,,9.9979582,,,,
,23016167.19,9.9984083,-45290.154296875,-1.5883032068072E-5,7.78286759632784E-7,1,0.999253354069792,40.0298881530762,1.9981941883677,16.6800003498793,-0.000176396798789689,-4.79778419540294E-5,0.25,-1.39118765450035E-6,-1.58480485030285E-5,-1.50484146557422E-6,9.9984083,9.9984083,-45294.0703125,-45286.23828125,57.044812590506,20.6514806400268,10.760172,0,0,0,40,4449,10.0473,-45290.154296875,,,,,,,,,,,,,0,,,,0.00245,,,,,,9.9984083,,,,
,23016315.15,9.9980583,-48986.56640625,-9.79026729592779E-6,8.49590350646006E-7,1,0.999253354069792,40.0298881530762,1.99821486695078,16.6800003498793,-0.000108363835759961,-3.18538129372E-5,0.25,-1.057883405396E-6,-9.77090361018782E-6,-1.12869225529977E-6,9.9980583,9.9980583,-48989.18359375,-48983.94921875,57.6146197810253,20.6528114662454,11.519473,0,0,0,40,4449,10.05,-48986.56640625,,,,,,,,,,,,,0,,,,0,,,,,,9.9980583,,,,
,23016491.97,9.9981117,-53405.236328125,-1.08850325138638E-6,6.21428832619933E-7,1,0.999253354069792,40.0298881530762,1.9982144983627,16.6800003498793,-1.13709047998013E-5,-7.33019031732678E-6,0.25,-4.5290100919406E-7,-1.08434284315634E-6,-4.60637034946064E-7,9.9981117,9.9981117,-53409.04296875,-53401.4296875,57.2449094914291,20.6505543212995,11.519473,0,0,0,40,4449,10.0543,-53405.236328125,,,,,,,,,,,,,0,,,,0.00245,,,,,,9.9981117,,,,
,23016641.07,9.9978971,-57131.71484375,7.43147759137882E-6,8.53941892156177E-7,1,0.999253354069792,40.0298881530762,1.99821394117343,16.6800003498793,8.44411091463633E-5,1.24395892422805E-5,0.25,-2.38401367235466E-7,7.43047980093538E-6,-1.83040441802467E-7,9.9978971,9.9978971,-57134.3203125,-57129.109375,57.2464727484676,20.6489804943345,11.139823,0,0,0,40,4449,10.05745,-57131.71484375,,,,,,,,,,,,,0,,,,0.0049,,,,,,9.9978971,,,,
,23016788.43,9.9971762,-60813.201171875,1.4744742420749E-5,7.98676227899025E-7,1,0.999253354069792,40.0298881530762,1.99820591991995,16.6800003498793,0.000167174262879323,2.70345427468734E-5,0.25,-2.65584748709079E-7,1.4746369070687E-5,-1.55826338485299E-7,9.9971762,9.9971762,-60816.97265625,-60809.4296875,57.1448610409676,20.6522762111054,11.139823,0,0,0,40,4449,10.06,-60813.201171875,,,,,,,,,,,,,0,,,,-0.00245,,,,,,9.9971762,,,,
,23016936.6,9.9973269,-64515.34765625,2.4638295659916E-5,7.60202683117642E-7,1,0.999253354069792,40.0298881530762,1.99816140653432,16.6800003498793,0.000280086040943603,4.15765386259371E-5,0.25,-7.63011111264106E-7,2.46517372466486E-5,-5.80102074867007E-7,9.9973269,9.9973269,-64520.64453125,-64510.05078125,57.187068981006,20.6538422478359,11.139823,0,0,0,40,4449,10.06275,-64515.34765625,,,,,,,,,,,,,0,,,,-0.00245,,,,,,9.9973269,,,,
,23017116.64,9.9978046,-69015.1015625,3.67600554312764E-5,7.85845994859407E-7,1,0.999253354069792,40.0298881530762,1.99820213929284,16.6800003498793,0.000418263019312446,6.09185883833512E-5,0.25,-1.23783999177825E-6,3.67953345207059E-5,-9.66607802623929E-7,9.9978046,9.9978046,-69020.171875,-69010.03125,57.2441278629099,20.6538202509304,11.139823,0,0,0,40,4449,10.06705,-69015.1015625,,,,,,,,,,,,,0,,,,0,,,,,,9.9978046,,,,
,23017261.015,9.9974203,-72621.3515625,4.60266083372913E-5,8.04989169517256E-7,1,0.999253354069792,40.0298881530762,1.99817588938469,16.6800003498793,0.000521961089165782,8.67849788031729E-5,0.25,-6.20937984371331E-7,4.60778119280316E-5,-2.82623323476612E-7,9.9974203,9.9974203,-72625.25,-72617.453125,57.6787133196022,20.6543140241028,11.519473,0,0,0,40,4449,10.06995,-72621.3515625,,,,,,,,,,,,,0,,,,0,,,,,,9.9974203,,,,
,23017408.16,9.9971066,-76297.765625,5.45270049043323E-5,9.70965258354226E-7,1,0.999253354069792,40.0298881530762,1.99813652795392,16.6800003498793,0.00061436913425732,0.000125940081929359,0.25,1.30844522158656E-6,5.45887945073799E-5,1.70899102844393E-6,9.9971066,9.9971066,-76299.90625,-76295.625,57.5114448164869,20.6550993164499,11.139823,0,0,0,40,4449,10.074,-76297.765625,,,,,,,,,,,,,0,,,,0,,,,,,9.9971066,,,,
,23017555.94,9.9972191,-79990.00390625,6.67233372141342E-5,1.01857401030029E-6,1,0.999253354069792,40.0298881530762,1.99815685279047,16.6800003498793,0.000754674865419524,0.00013934966928477,0.25,2.97258271466303E-7,6.68274270122636E-5,7.81818312862177E-7,9.9972191,9.9972191,-79991.6640625,-79988.34375,57.4926857320253,20.654687831036,11.519473,0,0,0,40,4449,10.0777,-79990.00390625,,,,,,,,,,,,,0,,,,-0.00245,,,,,,9.9972191,,,,
,23017733.075,9.9976006,-84416.37109375,7.72249487875524E-5,8.84056435558081E-7,1,0.999253354069792,40.0298881530762,1.99810196317586,16.6900008916855,0.000872364466163256,0.000168816362391924,0.25,1.01170707566053E-6,7.73655822619049E-5,1.5676141423758E-6,9.9976006,9.9976006,-84420.0390625,-84412.703125,57.4965938746215,20.652440852442,11.519473,0,0,0,40,4449,10.0824,-84416.37109375,,,,,,,,,,,,,0,,,,0.00245,,,,,,9.9976006,,,,
,23017869.235,9.9974461,-87817.96484375,8.62020671120821E-5,9.75246925001283E-7,1,0.999253354069792,40.0298881530762,1.99813760335824,16.6900008916855,0.000975648317732471,0.000179433185101387,0.25,3.35947227014668E-7,8.63850564857992E-5,9.4905241819217E-7,9.9974461,9.9974461,-87820.359375,-87815.5703125,57.4559491916215,20.6528940236905,11.519473,0,0,0,40,4449,10.0856,-87817.96484375,,,,,,,,,,,,,0,,,,-0.0049,,,,,,9.9974461,,,,
,23018027.155,9.9977722,-88769.125,9.07877647540504E-5,1.08112735581447E-6,1,0.999253354069792,40.0298881530762,1.99814525160225,16.6900008916855,0.00102976715428255,0.000177048937978097,0.25,-6.98631089217891E-7,9.09937528057858E-5,-5.70623777903186E-8,9.9977722,9.9977722,-88771.5078125,-88766.7421875,57.413741251583,20.6536405989573,11.139823,0,0,0,40,4449,10.0882,-88769.125,,,,,,,,,,,,,0,,,,-0.0049,,,,,,9.9977722,,,,
,23018166.235,10.0009279,-85294.28125,7.99209351258605E-5,8.14914665881756E-7,1,0.999253354069792,40.0298881530762,1.99810573687733,16.6999995708466,0.000908689245284451,0.000142419090420343,0.25,-1.80410238427541E-6,8.00918375452815E-5,-1.23575085059477E-6,10.0009279,10.0009279,-85296.703125,-85291.859375,57.4082698519484,20.6542010492176,11.519473,0,0,0,40,4449,10.0866,-85294.28125,,,,,,,,,,,,,0,,,,0,,,,,,10.0009279,,,,
,23018343.34,10.0022202,-80869.60546875,6.87125888673065E-5,7.91113588763568E-7,1,0.999253354069792,40.0298881530762,1.99807889048714,16.6900008916855,0.000778455370336701,0.000136514248064736,0.25,-3.10637245034067E-7,6.88287605449605E-5,1.86310650051256E-7,10.0022202,10.0022202,-80877.2265625,-80861.984375,57.3394865422561,20.651082854891,11.519473,0,0,0,40,4449,10.08325,-80869.60546875,,,,,,,,,,,,,0,,,,-0.00245,,,,,,10.0022202,,,,
,23018492.025,10.0022755,-77153.734375,5.87449997615382E-5,1.00939011582594E-6,1,0.999253354069792,40.0298881530762,1.99805854237765,16.6900008916855,0.000665707981347879,0.000114620046396482,0.25,-4.51104313548788E-7,5.88291051829661E-5,-2.28002343622073E-8,10.0022755,10.0022755,-77156.4296875,-77151.0390625,57.4082698519484,20.6515895434932,11.139823,0,0,0,40,4449,10.0789,-77153.734375,,,,,,,,,,,,,0,,,,0,,,,,,10.0022755,,,,
,23018642.76,10.0023642,-73387.2421875,4.78768741147983E-5,9.1366753822058E-7,1,0.999253354069792,40.0298881530762,1.9981255445162,16.6900008916855,0.000543149121842531,8.92534606802275E-5,0.25,-7.35911049847861E-7,4.79337915969081E-5,-3.84588676011106E-7,10.0023642,10.0023642,-73393.3046875,-73381.1796875,57.4199942797368,20.6524709212111,11.519473,0,0,0,40,4449,10.0769,-73387.2421875,,,,,,,,,,,,,0,,,,-0.0049,,,,,,10.0023642,,,,
,23018792.125,10.0024185,-69654.51953125,3.89715466253355E-5,6.92633968360751E-7,1,0.999253354069792,40.0298881530762,1.9981118982754,16.6999995708466,0.000443271180307825,6.546970227867E-5,0.25,-1.23376270081808E-6,3.90104862069531E-5,-9.46457509926688E-7,10.0024185,10.0024185,-69656.0625,-69652.9765625,57.2058280654676,20.6525764019896,11.519473,0,0,0,40,4449,10.0727,-69654.51953125,,,,,,,,,,,,,0,,,,-0.00245,,,,,,10.0024185,,,,
,23018972.42,10.0032816,-65148.693359375,2.62968328837608E-5,7.24431292445763E-7,1,0.999253354069792,40.0298881530762,1.9980469227077,16.6900008916855,0.000299211725597322,4.28717589112955E-5,0.25,-9.47284376580003E-7,2.63136566559308E-5,-7.52241950073143E-7,10.0032768,10.0032864,-65153.53515625,-65143.8515625,57.4379717356792,20.6507927041178,10.760172,0,0,0,40,4449,10.06995,-65148.693359375,,,,,,,,,,,,,0,,,,0.00245,,,,,,10.0032816,,,,
,23019122.24,10.0023384,-61405.57421875,1.63263147101063E-5,6.46553269184371E-7,1,0.999253354069792,40.0298881530762,1.99806308207026,16.6900008916855,0.000187571401922085,1.62425855424952E-5,0.25,-1.50557044064087E-6,1.63380319545379E-5,-1.38410229063955E-6,10.0023384,10.0023384,-61408.1328125,-61403.015625,57.4246840508522,20.6502290047342,11.139823,0,0,0,40,4449,10.0652,-61405.57421875,,,,,,,,,,,,,0,,,,0.0049,,,,,,10.0023384,,,,
,23019275.065,10.0020237,-57586.69921875,7.07273377904057E-6,9.16624600289891E-7,1,0.999253354069792,40.0298881530762,1.99816403501384,16.6900008916855,8.08280511441547E-5,9.27838897673589E-6,0.25,-4.53583155213362E-7,7.07378037938045E-6,-4.00818420380529E-7,10.0020237,10.0020237,-57592.94140625,-57580.45703125,57.4786164186792,20.6545170447618,11.519473,0,0,0,40,4449,10.06295,-57586.69921875,,,,,,,,,,,,,0,,,,0,,,,,,10.0020237,,,,
touchdown = 10.9099997207522 mm,23019451.895,10.0029182,-53168.03125,-2.97602140030229E-6,6.82193513988606E-7,1,0.999253354069792,40.0298881530762,1.99806914614882,16.6900008916855,-3.37868018549809E-5,-5.05210667691127E-6,0.25,8.89541162850379E-8,-2.97441603188546E-6,6.68290573547563E-8,10.0029182,10.0029182,-53170.4453125,-53165.6171875,57.2464727484676,20.6501378976898,10.760172,0,0,0,40,4449,10.06315,-53168.03125,,,,,,,,,,,,,0,,,,0.0049,,,,,,10.0029182,,,,
,23019601.345,10.00147245,-49434.154296875,-1.15101764685038E-5,8.6029283526519E-7,1,0.999253354069792,40.0298881530762,1.99814469277686,16.6900008916855,-0.0001325542515885,-8.85633061623249E-6,0.25,1.28937168306161E-6,-1.15065897392135E-5,1.20310924346174E-6,10.0013618,10.0015831,-49438.0703125,-49430.23828125,57.3136928011214,20.6519698993043,11.519473,0,0,0,40,4449,10.05715,-49434.154296875,,,,,,,,,,,,,0,,,,0,,,,,,10.00147245,,,,
,23019750.89,10.0018759,-45698.04296875,-2.04621614337566E-5,6.88964464356532E-7,1,0.999253354069792,40.0298881530762,1.9981319434624,16.6999995708466,-0.000229266787374535,-5.06431006692805E-5,0.25,-8.02423472561096E-7,-2.04251714591253E-5,-9.50600884824744E-7,10.0018759,10.0018759,-45702.94140625,-45693.14453125,57.4668919908907,20.6499725077314,11.519473,0,0,0,40,4449,10.054,-45698.04296875,,,,,,,,,,,,,0,,,,0.0049,,,,,,10.0018759,,,,
,23019900.17,10.0016937,-41967.02734375,-2.91520800685665E-5,7.49669820673005E-7,1,0.999253354069792,40.0298881530762,1.99807167677824,16.6900008916855,-0.00032826446481352,-6.22975593684961E-5,0.25,-2.74864275980745E-7,-2.90943625355317E-5,-4.84604431480923E-7,10.0016937,10.0016937,-41972.1875,-41961.8671875,57.0706063316407,20.6535773771892,10.760172,0,0,0,40,4449,10.0505,-41967.02734375,,,,,,,,,,,,,0,,,,0.0049,,,,,,10.0016937,,,,
,23020080.08,10.0020447,-37471.873046875,-3.8352463586465E-5,6.10464207912259E-7,1,0.999253354069792,40.0298881530762,1.99807444853192,16.6900008916855,-0.000431005567863689,-8.55546695852994E-5,0.25,-6.89204435123544E-7,-3.82560180834167E-5,-9.58878239488294E-7,10.0020447,10.0020447,-37474.7578125,-37468.98828125,56.831428004756,20.6487965385398,11.139823,0,0,0,40,4449,10.04815,-37471.873046875,,,,,,,,,,,,,0,,,,0,,,,,,10.0020447,,,,
,23020228.635,10.0018368,-33759.51953125,-4.56107478850357E-5,5.16071606286672E-7,1,0.999253354069792,40.0298881530762,1.99810538422793,16.6900008916855,-0.00051427033173828,-9.1191655414969E-5,0.25,1.07071914921733E-7,-4.54846166628476E-5,-2.09445244334407E-7,10.0018368,10.0018368,-33764.484375,-33754.5546875,57.3246356003907,20.6499581528746,11.139823,0,0,0,40,4449,10.04445,-33759.51953125,,,,,,,,,,,,,0,,,,0.00245,,,,,,10.0018368,,,,
,23020377.805,10.0014572,-30031.89453125,-5.22631769715484E-5,4.78337273466674E-7,1,0.999253354069792,40.0298881530762,1.9981616828672,16.6900008916855,-0.000588875117594188,-0.00010548435633933,0.25,2.25888360408799E-8,-5.20973850344857E-5,-3.31097254751358E-7,10.0014572,10.0014572,-30036.9375,-30026.8515625,57.7639108281984,20.650820068632,10.760172,0,0,0,40,4449,10.0426,-30031.89453125,,,,,,,,,,,,,0,,,,0.0049,,,,,,10.0014572,,,,
,23020527.08,10.0011549,-26301.0205078125,-5.93684352227829E-5,5.33233621688869E-7,1,0.999253354069792,40.0298881530762,1.99813185745361,16.6900008916855,-0.000668173711279966,-0.000122502168772255,0.25,-2.2762434514568E-7,-5.91553836823921E-5,-6.17108138458361E-7,10.0011549,10.0011549,-26303.763671875,-26298.27734375,57.2832092888714,20.6518656943094,11.139823,0,0,0,40,4449,10.0405,-26301.0205078125,,,,,,,,,,,,,0,,,,-0.0049,,,,,,10.0011549,,,,
,23020704.78,10.00202515,-21861.2060546875,-6.67118938984293E-5,4.47227617773742E-7,1,0.999253354069792,40.0298881530762,1.9981175490684,16.6900008916855,-0.000750195190928105,-0.000139169411843958,0.25,-4.13086239095482E-7,-6.64415740023341E-5,-8.32708644344469E-7,10.0018845,10.0021658,-21866.033203125,-21856.37890625,57.3543374841214,20.6494394727382,11.139823,0,0,0,40,4449,10.03865,-21861.2060546875,,,,,,,,,,,,,0,,,,-0.00245,,,,,,10.00202515,,,,
,23020850.93,10.0009241,-18209.923828125,-7.18914071227125E-5,3.93508553841215E-7,1,0.999253354069792,40.0298881530762,1.9980079421578,16.6900008916855,-0.000807544534676923,-0.000153074313997084,0.25,-7.42922348242998E-7,-7.15728763627308E-5,-1.17670739926026E-6,10.0009241,10.0009241,-18210.96875,-18208.87890625,57.2034831799099,20.6533420253917,11.519473,0,0,0,40,4449,10.0368,-18209.923828125,,,,,,,,,,,,,0,,,,0,,,,,,10.0009241,,,,
,23020999.325,10.0016985,-14500.7622070313,-7.73390947507637E-5,4.05082387864012E-7,1,0.999253354069792,40.0298881530762,1.99804672925007,16.6900008916855,-0.000868660541483942,-0.000163474046113643,0.25,-7.17143029519534E-7,-7.69706245551965E-5,-1.16402958184314E-6,10.0016985,10.0016985,-14506.0263671875,-14495.498046875,57.4387533641984,20.6493627634825,10.760172,0,0,0,40,4449,10.03545,-14500.7622070313,,,,,,,,,,,,,0,,,,0,,,,,,10.0016985,,,,
,23021146.575,10.0013876,-10821.4555664062,-8.19461034888633E-5,2.8721058550444E-7,1,0.999253354069792,40.0298881530762,1.99819014293054,16.6900008916855,-0.000920383497687396,-0.000172008297829987,0.25,-6.7854599214238E-7,-8.15303623321848E-5,-1.13031644741842E-6,10.0013876,10.0013876,-10825.23046875,-10817.6806640625,57.3699700545061,20.6506494895021,11.519473,0,0,0,40,4449,10.0341,-10821.4555664062,,,,,,,,,,,,,0,,,,0,,,,,,10.0013876,,,,
,23021322.04,10.002223,-6436.7177734375,-8.68256985049474E-5,3.46622873821676E-7,1,0.999253354069792,40.0298881530762,1.99793035078632,16.6900008916855,-0.000974939730411641,-0.000181018739940368,0.25,-6.44975869914915E-7,-8.63562777372387E-5,-1.09572337181841E-6,10.0021963,10.0022497,-6439.21337890625,-6434.22216796875,57.1479875550445,20.6465945593224,10.760172,0,0,0,40,4449,10.0306,-6436.7177734375,,,,,,,,,,,,,0,,,,-0.00245,,,,,,10.002223,,,,
,23021470.01,10.004859,-2738.16857910156,-8.98174172376031E-5,3.10221757217041E-7,1,0.999253354069792,40.0298881530762,1.99809466661206,16.6900008916855,-0.00100854116262037,-0.00018623416279008,0.25,-6.02373948066281E-7,-8.93103906204109E-5,-1.04557019497316E-6,10.004859,10.004859,-2740.6025390625,-2735.73461914062,57.4020168237945,20.6505287824139,11.519473,0,0,0,40,4449,10.0242,-2738.16857910156,,,,,,,,,,,,,0,,,,0,,,,,,10.004859,,,,
,23021617.065,10.0045691,937.512542724609,-7.58762160726164E-5,3.51453350795805E-7,1,0.999253354069792,40.0298881530762,1.99799690600795,16.6900008916855,-0.000851564120055742,-0.000159061229157932,0.25,-6.73449413966293E-7,-7.54398280809976E-5,-1.03855182793243E-6,10.0045691,10.0045691,934.863708496094,940.161376953125,57.3355783996599,20.6522794761714,11.519473,0,0,0,40,4449,10.0165,937.512542724609,,,,,,,,,,,,,0,,,,0,,,,,,10.0045691,,,,
,23021764.005,9.9969501,4608.15283203125,-7.41687100530973E-5,2.88746859548918E-7,1,0.999253354069792,40.0298881530762,1.99801373914526,16.6900008916855,-0.000832031070778424,-0.00015863428789155,0.25,-9.1800103186173E-7,-7.37565227860539E-5,-1.29120571016138E-6,9.9969501,9.9969501,4604.29931640625,4612.00634765625,57.2964969736984,20.6504681925533,11.139823,0,0,0,40,4449,10.0215,4608.15283203125,,,,,,,,,,,,,0,,,,0,,,,,,9.9969501,,,,
,23021938.9,9.9964237,8978.74072265625,-7.38975894315795E-5,2.92659355649051E-7,1,0.999253354069792,40.0298881530762,1.99805365005619,16.6900008916855,-0.000829927586242694,-0.000154411692564245,0.25,-5.62448421489289E-7,-7.35120543513055E-5,-9.59948325507776E-7,9.9964237,9.9964237,8974.9091796875,8982.572265625,57.1151591572368,20.6448385496151,11.139823,0,0,0,40,4449,10.02635,8978.74072265625,,,,,,,,,,,,,0,,,,0.00245,,,,,,9.9964237,,,,
,23022084.62,9.9978495,12620.7319335938,-7.07686206750667E-5,4.27940765252684E-7,1,0.999253354069792,40.0298881530762,1.99801608618404,16.6900008916855,-0.000794706965148415,-0.000149625744035923,0.25,-6.7172496706941E-7,-7.04197701308829E-5,-1.07087486467652E-6,9.9978495,9.9978495,12613.3623046875,12628.1015625,57.4160861371407,20.6473120612936,11.139823,0,0,0,40,4449,10.0296,12620.7319335938,,,,,,,,,,,,,0,,,,0.00245,,,,,,9.9978495,,,,
,23022230.085,9.9977856,16254.9462890625,-6.03018657742165E-5,4.66933918771009E-7,1,0.999253354069792,40.0298881530762,1.99801004199968,16.6900008916855,-0.000677309589077261,-0.000127971333218359,0.25,-5.95398839412675E-7,-6.0023894731857E-5,-9.51210845956575E-7,9.9977856,9.9977856,16253.69921875,16256.193359375,56.8173586914099,20.6485098522432,10.760172,0,0,0,40,4449,10.0331,16254.9462890625,,,,,,,,,,,,,0,,,,-0.0049,,,,,,9.9977856,,,,
,23022374.825,9.9990826,19873.1650390625,-4.34183383621283E-5,4.62160269931415E-7,1,0.999253354069792,40.0298881530762,1.9978991199522,16.6900008916855,-0.00048697605948032,-9.68596448285684E-5,0.25,-8.3501561913346E-7,-4.32304599221516E-5,-1.10021036949903E-6,9.9990826,9.9990826,19866.923828125,19879.40625,57.4348452216022,20.6485029820008,10.760172,0,0,0,40,4449,10.0348,19873.1650390625,,,,,,,,,,,,,0,,,,0.00245,,,,,,9.9990826,,,,
,23022551.525,9.9979534,24288.404296875,-1.62521451513086E-5,4.99367659884761E-7,1,0.999253354069792,40.0298881530762,1.99800790267379,16.6900008916855,-0.000183294401447797,-3.11268286111007E-5,0.25,1.48945695606498E-7,-1.61918493130548E-5,4.33854037508333E-8,9.9979534,9.9979534,24284.748046875,24292.060546875,57.1182856713137,20.6460396991537,11.519473,0,0,0,40,4449,10.03575,24288.404296875,,,,,,,,,,,,,0,,,,0,,,,,,9.9979534,,,,
,23022698.485,9.9990606,27960.5517578125,3.21536093364923E-6,4.8717796726909E-7,1,0.999253354069792,40.0298881530762,1.99790300574112,16.6900008916855,3.7197881244174E-5,1.0202876781462E-6,0.25,-4.86469829074067E-7,3.20769665623375E-6,-4.63397557300828E-7,9.9990606,9.9990606,27955.5078125,27965.595703125,57.332451885583,20.6492446369749,11.139823,0,0,0,40,4449,10.03875,27960.5517578125,,,,,,,,,,,,,0,,,,0,,,,,,9.9990606,,,,
,23022845.32,9.9986267,31629.9814453125,1.61392452284832E-5,5.32053443189774E-7,1,0.999253354069792,40.0298881530762,1.99795479215802,16.6999995708466,0.000183068066800186,2.58615079749122E-5,0.25,-6.04150000113381E-7,1.6094848225796E-5,-4.91929932357979E-7,9.9986267,9.9986267,31626.158203125,31633.8046875,57.2886806885061,20.647543327598,11.139823,0,0,0,40,4449,10.04155,31629.9814453125,,,,,,,,,,,,,0,,,,0,,,,,,9.9986267,,,,
,23022988.69,9.9977474,35212.923828125,2.21032859165066E-5,4.50617920802239E-7,1,0.999253354069792,40.0298881530762,1.99789256353066,16.6900008916855,0.000249462414809031,4.29147671811401E-5,0.25,-1.66696681711883E-7,2.20463760149345E-5,-1.17279326094881E-8,9.9977474,9.9977474,35209.30078125,35216.546875,57.2347483206791,20.6471508503304,10.760172,0,0,0,40,4449,10.0434,35212.923828125,,,,,,,,,,,,,0,,,,0.0049,,,,,,9.9977474,,,,
,23023164.96,9.9988728,39617.744140625,2.20579093144734E-5,6.62253798394065E-7,1,0.999253354069792,40.0298881530762,1.99794124053953,16.6900008916855,0.000247913839148173,4.92907396362616E-5,0.25,4.01697529016066E-7,2.20073937588117E-5,5.58429952993803E-7,9.9988728,9.9988728,39613.9453125,39621.54296875,57.0971817012945,20.6438940631312,11.139823,0,0,0,40,4449,10.0474,39617.744140625,,,,,,,,,,,,,0,,,,-0.0049,,,,,,9.9988728,,,,
,23023309.955,9.9971333,43242.28515625,1.95358020537431E-5,6.68398628663979E-7,1,0.999253354069792,40.0298881530762,1.99796212874216,16.6900008916855,0.000220704172299263,3.78360640097783E-5,0.25,-1.63496374272825E-7,1.95022556621208E-5,-2.1657380429953E-8,9.9971333,9.9971333,43239.76171875,43244.80859375,57.4215575367753,20.6464922901932,11.139823,0,0,0,40,4449,10.0495,43242.28515625,,,,,,,,,,,,,0,,,,0,,,,,,9.9971333,,,,
,23023456.23,9.9971466,46896.8671875,1.42716379111894E-5,7.65438260355086E-7,1,0.999253354069792,40.0298881530762,1.99800504112223,16.6900008916855,0.00016171621811593,2.53283477406054E-5,0.25,-3.26424846338073E-7,1.42540884073553E-5,-2.21432564416543E-7,9.9971466,9.9971466,46892.984375,46900.75,56.9267866841022,20.6460158216736,11.139823,0,0,0,40,4449,10.05175,46896.8671875,,,,,,,,,,,,,0,,,,0.00245,,,,,,9.9971466,,,,
,23023601.24,9.9983015,50521.333984375,7.22988373004532E-6,6.95028730524511E-7,1,0.999253354069792,40.0298881530762,1.99801446302928,16.6900008916855,8.23433968607705E-5,1.06800166889569E-5,0.25,-3.56738309830999E-7,7.22509593122241E-6,-3.02999620424288E-7,9.9983015,9.9983015,50518.67578125,50523.9921875,57.0971817012945,20.6465971490496,11.139823,0,0,0,40,4449,10.0551,50521.333984375,,,,,,,,,,,,,0,,,,-0.0049,,,,,,9.9983015,,,,
,23023778.985,9.9988899,54961.501953125,-1.21014294256485E-6,7.43146643561907E-7,1,0.999253354069792,40.0298881530762,1.99802213625744,16.6900008916855,-1.32193257705688E-5,-4.9484594241542E-6,0.25,-2.20039179540555E-7,-1.20780236092871E-6,-2.2889725648932E-7,9.9988899,9.9988899,54959.171875,54963.83203125,57.105779615006,20.6428374359371,11.519473,0,0,0,40,4449,10.06035,54961.501953125,,,,,,,,,,,,,0,,,,0,,,,,,9.9988899,,,,
,23023923.125,9.9982157,58566.240234375,-1.00753303088779E-5,9.62313316422635E-7,1,0.999253354069792,40.0298881530762,1.99791762626993,16.6999995708466,-0.000113918336185236,-1.99908825712074E-5,0.25,4.65619754247954E-8,-1.00733043849831E-5,-2.84279888556442E-8,9.9982157,9.9982157,58562.421875,58570.05859375,57.1339182416984,20.6442880228938,10.760172,0,0,0,40,4449,10.0619,58566.240234375,,,,,,,,,,,,,0,,,,-0.00245,,,,,,9.9982157,,,,
,23024070.235,9.9975424,62240.390625,-1.91445740099272E-5,6.88809036802457E-7,1,0.999253354069792,40.0298881530762,1.99794258218821,16.6900008916855,-0.000216698885671278,-3.71077421121441E-5,0.25,1.67286971846756E-7,-1.91478947922813E-5,2.48419249767536E-8,9.9975424,9.9975424,62238.08984375,62242.69140625,57.0026046504676,20.6451015622853,11.139823,0,0,0,40,4449,10.06465,62240.390625,,,,,,,,,,,,,0,,,,0.0049,,,,,,9.9975424,,,,
,23024217.235,9.9979572,65914.015625,-2.86562549100763E-5,8.76585095425576E-7,1,0.999253354069792,40.0298881530762,1.99798148596955,16.6900008916855,-0.000324469518407078,-5.55987683410206E-5,0.25,2.46774893557898E-7,-2.86707019531808E-5,3.40829079414319E-8,9.9979572,9.9979572,65911.4375,65916.59375,57.3644986548715,20.6456967936656,11.139823,0,0,0,40,4449,10.06835,65914.015625,,,,,,,,,,,,,0,,,,0,,,,,,9.9979572,,,,
,23024394.05,9.999217,70334.2421875,-4.13223372455451E-5,9.25432373232331E-7,1,0.999253354069792,40.0298881530762,1.99790166219358,16.6900008916855,-0.000468150865431697,-7.96187836133702E-5,0.25,4.0571376987832E-7,-4.135932797375E-5,1.00689862532045E-7,9.999217,9.999217,70331.671875,70336.8125,57.1143775287176,20.6409296631286,11.139823,0,0,0,40,4449,10.075,70334.2421875,,,,,,,,,,,,,0,,,,0,,,,,,9.999217,,,,
,23024541.47,9.9977207,74017.4140625,-4.90597132355974E-5,8.9283876498927E-7,1,0.999253354069792,40.0298881530762,1.9978650043056,16.6900008916855,-0.000554182496538541,-0.000104467302783544,0.25,-3.96859674698111E-7,-4.91120841573696E-5,-7.57719757117602E-7,9.9977207,9.9977207,74012.5,74022.328125,57.0893654161022,20.6454411331215,11.139823,0,0,0,40,4449,10.07495,74017.4140625,,,,,,,,,,,,,0,,,,0.00245,,,,,,9.9977207,,,,
,23024688.945,9.9969978,77703.48046875,-5.95293291168666E-5,9.68058924772473E-7,1,0.999253354069792,40.0298881530762,1.99800963633636,16.6900008916855,-0.000674670876610183,-0.000115808971399446,0.25,4.86963521686057E-7,-5.96173082635911E-5,5.35134702606748E-8,9.9969978,9.9969978,77700.984375,77705.9765625,57.1268835850253,20.6453378364492,10.760172,0,0,0,40,4449,10.0796,77703.48046875,,,,,,,,,,,,,0,,,,0.00245,,,,,,9.9969978,,,,
,23024838.75,9.997262,81448.36328125,-6.98593250528184E-5,9.69146404461489E-7,1,0.999253354069792,40.0298881530762,1.9978823504107,16.6900008916855,-0.000791208760117217,-0.000139882865496855,0.25,2.18123033187294E-7,-6.99797146243475E-5,-2.86547563798886E-7,9.997262,9.997262,81444.7421875,81451.984375,57.3488660844868,20.6449870088347,10.760172,0,0,0,40,4449,10.08225,81448.36328125,,,,,,,,,,,,,0,,,,0,,,,,,9.997262,,,,
,23025014.32,9.9980555,85835.5234375,-8.04892500971863E-5,1.13689277282341E-6,1,0.999253354069792,40.0298881530762,1.99792462031228,16.6999995708466,-0.00091132444419057,-0.000164441162928822,0.25,-3.9993671922147E-8,-8.06511177047909E-5,-6.1518072741001E-7,9.9980555,9.9980555,85832.875,85838.171875,56.9408559974483,20.6415912901398,11.139823,0,0,0,40,4449,10.0893,85835.5234375,,,,,,,,,,,,,0,,,,-0.00245,,,,,,9.9980555,,,,
,23025150.23,9.9972839,89232.56640625,-9.2161663206059E-5,7.98004029393153E-7,1,0.999253354069792,40.0298881530762,1.99790937754278,16.6999995708466,-0.00104076498717029,-0.000204733560442203,0.25,-1.5008231730045E-6,-9.23579702837347E-5,-2.15611674130925E-6,9.9972839,9.9972839,89228.78125,89236.3515625,57.7756352559869,20.6435825661668,11.139823,0,0,0,40,4449,10.0902,89232.56640625,,,,,,,,,,,,,0,,,,0.0049,,,,,,9.9972839,,,,
,23025183.525,9.9976606,89999.6015625,-9.38851879512768E-5,1.11578166120704E-6,1,0.999253354069792,40.0298881530762,1.99785279254401,16.6999995708466,-0.00106011010702871,-0.000209364483148376,0.25,-1.60088541496733E-6,-9.40894348420819E-5,-2.26710097357237E-6,9.9976606,9.9976606,89999.5859375,89999.6171875,57.3105662870445,20.6447346380731,10.760172,0,0,0,40,4417,10.0914,89999.6015625,,,,,,,,,,,,,0,,,,-0.00245,,,,,,9.9976606,,,,