File: data/doubleLayers/dl_1-25/ppms/KoelnPPMS/LowTemperatureHysVaryingSpeed/DD205_ZFC_1KMIN_HYS9T_REPRODUCE.DAT
[Header]
; VSM Data File (default extension .dat)
; Copyright (c) 2003-2013, Quantum Design, Inc. All rights reserved.
TITLE,
FILEOPENTIME,23028178.61,09/24/2018,9:41 pm
BYAPP,VSM,2.0,2.0
INFO,PPMS VSM Option Release 1.4.10 Build 1,APPNAME
INFO,Quantum Design Linear Motor Servo Controller,MOTOR_MODULE_NAME
INFO,3101-100 M1,MOTOR_HW_VERSION
INFO,MMC1014,MOTOR_SERIAL_NUMBER
INFO,SRV No X-over 01.03.11,MOTOR_SOFTWARE_VERSION
INFO,Quantum Design VSM Detection Module,VSM_MODULE_NAME
INFO,3101-150 F0,VSM_HW_VERSION
INFO,VSM707,VSM_SERIAL_NUMBER
INFO,VSM No X-over 01.02.05 May 20 2008 13:51:47,VSM_SOFTWARE_VERSION
INFO,704,PREAMP_SERIAL_NUMBER
INFO,822,COIL_SERIAL_NUMBER
INFO,0,MOMENT_UNITS
INFO,,SAMPLE_MATERIAL
INFO,,SAMPLE_COMMENT
INFO,,SAMPLE_MASS
INFO,,SAMPLE_VOLUME
INFO,,SAMPLE_MOLECULAR_WEIGHT
INFO,,SAMPLE_SIZE
INFO,,SAMPLE_SHAPE
DATATYPE,COMMENT,1
DATATYPE,TIME,2
STARTUPAXIS,X,2
STARTUPAXIS,Y1,5
[Data]
Comment,Time Stamp (sec),Temperature (K),Magnetic Field (Oe),Moment (emu),M. Std. Err. (emu),Transport Action,Averaging Time (sec),Frequency (Hz),Peak Amplitude (mm),Center Position (mm),Coil Signal' (mV),Coil Signal" (mV),Range (mV),M. Quad. Signal (emu),M. Raw' (emu),M. Raw" (emu),Min. Temperature (K),Max. Temperature (K),Min. Field (Oe),Max. Field (Oe),Mass (grams),Motor Lag (deg),Pressure (Torr),VSM Status (code),Motor Status (code),Measure Status (code),Measure Count,PPMS Status (code),System Temp. (K),System Field (Oe),Sample Position (deg),Bridge 1 Resistance (ohms),Bridge 1 Excitation (에),Bridge 2 Resistance (ohms),Bridge 2 Excitation (에),Bridge 3 Resistance (ohms),Bridge 3 Excitation (에),Bridge 4 Resistance (ohms),Bridge 4 Excitation (에),Signal 1 Vin (V),Signal 2 Vin (V),Digital Inputs (code),Drive 1 Iout (mA),Drive 1 Ipower (W),Drive 2 Iout (mA),Drive 2 Ipower (W),Pressure (),Map 20 (),Map 21 (),Map 22 (),Map 23 (),Map 24 (),Map 25 (),Map 26 (),Map 27 (),Map 28 (),Map 29 ()
,23046079.5,9.999856,0.62417471408844,,,2,,,,16.6499998056889,,,,,,,9.999856,9.999856,0.62417471408844,0.62417471408844,,,11.519473,,,,-99999999,4417,9.9878,0.62417471408844,,,,,,,,,,,,,,,,,,,,,,,9.999856,,,,
,23046282.43,9.9925737,4137.24853515625,1.00877773402129E-5,3.20200871008159E-7,1,0.999253354069792,40.0298881530762,1.99800969174364,16.6400000452995,0.000114502753450539,1.40349825003867E-5,0.25,-5.45507481366649E-7,1.0034804838182E-5,-4.91380347768331E-7,9.9925737,9.9925737,4133.4833984375,4141.013671875,56.607882248256,20.617313272226,11.899124,0,0,0,40,4449,10.00445,4137.24853515625,,,,,,,,,,,,,0,,,,0,,,,,,9.9925737,,,,
,23046455.985,9.9940462,8473.884765625,1.08980997834893E-5,2.85429436615874E-7,1,0.999253354069792,40.0298881530762,1.99801170163561,16.6400000452995,0.00012328530883092,1.77275794739364E-5,0.25,-3.65097907323964E-7,1.08432278832573E-5,-3.04549915304154E-7,9.9940462,9.9940462,8468.787109375,8478.982421875,57.0190188493714,20.6227082210323,11.139823,0,0,0,40,4449,10.0152,8473.884765625,,,,,,,,,,,,,0,,,,0,,,,,,9.9940462,,,,
,23046631.405,9.9963055,12858.0458984375,1.26627147137501E-5,3.69504463467724E-7,1,0.999253354069792,40.0298881530762,1.99800159151901,16.6400000452995,0.000143507883040013,1.94443270577439E-5,0.25,-5.31538009283429E-7,1.26042692437328E-5,-4.56732618507339E-7,9.9963055,9.9963055,12854.7080078125,12861.3837890625,56.8353361473522,20.6276442742035,11.519473,0,0,0,40,4449,10.0211,12858.0458984375,,,,,,,,,,,,,0,,,,0.0049,,,,,,9.9963055,,,,
,23046853.75,9.9973412,18415.7607421875,1.94826404429809E-5,3.0642987473527E-7,1,0.999253354069792,40.0298881530762,1.9980157079155,16.6400000452995,0.000219735748942085,3.65352690846032E-5,0.25,-2.38693055186693E-7,1.93993781002154E-5,-1.18950931397842E-7,9.9973412,9.9973412,18406.94140625,18424.580078125,56.9486722826406,20.6267595388155,11.519473,0,0,0,40,4449,10.028,18415.7607421875,,,,,,,,,,,,,0,,,,-0.0049,,,,,,9.9973412,,,,
,23047046.66,9.9979086,23235.7041015625,3.20218814414035E-5,4.53798518041736E-7,1,0.999253354069792,40.0298881530762,1.99804277068468,16.6400000452995,0.000360226288469001,6.62847597430155E-5,0.25,1.49102182941481E-7,3.1896823619387E-5,3.53418880453372E-7,9.9979086,9.9979086,23232.12109375,23239.287109375,57.0635716749676,20.6277732306563,11.519473,0,0,0,40,4449,10.0327,23235.7041015625,,,,,,,,,,,,,0,,,,-0.0049,,,,,,9.9979086,,,,
,23047238.27,9.9978399,28024.580078125,4.62899003841282E-5,5.9187282217159E-7,1,0.999253354069792,40.0298881530762,1.99793026559885,16.6400000452995,0.000522839561917755,8.53964823558543E-5,0.25,-7.25853817376412E-7,4.61380479757241E-5,-4.14837036646236E-7,9.9978399,9.9978399,28019.28515625,28029.875,57.1503324406022,20.632719164136,11.139823,0,0,0,40,4449,10.03725,28024.580078125,,,,,,,,,,,,,0,,,,-0.00245,,,,,,9.9978399,,,,
,23047460.875,9.9979906,33588.09765625,5.52673153172987E-5,5.62162876398936E-7,1,0.999253354069792,40.0298881530762,1.99788742215777,16.6500005871058,0.000623130830137147,0.000110167677307152,0.25,-1.57507038425923E-7,5.5113667519707E-5,2.25708306305699E-7,9.9979906,9.9979906,33584.3671875,33591.828125,57.1534589546791,20.6300767520561,10.760172,0,0,0,40,4449,10.04065,33588.09765625,,,,,,,,,,,,,0,,,,0.00245,,,,,,9.9979906,,,,
,23047651.1,9.9983568,38340.185546875,5.51812933152755E-5,5.24520069330276E-7,1,0.999253354069792,40.0298881530762,1.99785487167704,16.6500005871058,0.000621504645032719,0.00011539942483674,0.25,3.07540361494327E-7,5.50524437380537E-5,6.98834802555075E-7,9.9983568,9.9983568,38336.37890625,38343.9921875,56.8947399148137,20.6308574233481,10.760172,0,0,0,40,4449,10.0455,38340.185546875,,,,,,,,,,,,,0,,,,0.0049,,,,,,9.9983568,,,,
,23047846.395,9.9979115,43221.53515625,5.29650714544205E-5,6.9942209862468E-7,1,0.999253354069792,40.0298881530762,1.99793576929899,16.6500005871058,0.000600752064752126,8.92931917678382E-5,0.25,-1.62102202553081E-6,5.28825384870772E-5,-1.23440081438567E-6,9.9979115,9.9979115,43216.80859375,43226.26171875,56.9408559974483,20.6293447418036,10.760172,0,0,0,40,4449,10.0485,43221.53515625,,,,,,,,,,,,,0,,,,0,,,,,,9.9979115,,,,
,23048068.265,9.9975653,48765.1640625,4.45846253146675E-5,6.52086761728853E-7,1,0.999253354069792,40.0298881530762,1.99792978742947,16.6599992662668,0.000507368408696307,6.75540037969012E-5,0.25,-2.04750525707835E-6,4.45459570533687E-5,-1.71703286459671E-6,9.9975653,9.9975653,48758.82421875,48771.50390625,57.3402681707753,20.6314311926405,11.139823,0,0,0,40,4449,10.0523,48765.1640625,,,,,,,,,,,,,0,,,,0,,,,,,9.9975653,,,,
,23048257.125,9.9975443,53485.14453125,3.78318820776409E-5,1.10326585961258E-6,1,0.999253354069792,40.0298881530762,1.99789082816482,16.6599992662668,0.000427980512608784,7.25553354849752E-5,0.25,-3.92725066367772E-7,3.78071964284226E-5,-1.11932009181825E-7,9.9975443,9.9975443,53479.00390625,53491.28515625,56.9705578811791,20.6299577875662,11.139823,0,0,0,40,4449,10.056,53485.14453125,,,,,,,,,,,,,0,,,,-0.00245,,,,,,9.9975443,,,,
,23048447.34,9.9977846,58238.869140625,3.07366320626047E-5,9.38114455336324E-7,1,0.999253354069792,40.0298881530762,1.99781388440362,16.6599992662668,0.000348528681428338,5.52772204200189E-5,0.25,-6.46944457499103E-7,3.07332494108233E-5,-4.18057878607448E-7,9.9977846,9.9977846,58233.84375,58243.89453125,56.9674313671022,20.6314223613923,11.139823,0,0,0,40,4449,10.05995,58238.869140625,,,,,,,,,,,,,0,,,,0,,,,,,9.9977846,,,,
,23048667.485,9.9971867,63741.4296875,2.01237544802462E-5,8.3541614496922E-7,1,0.999253354069792,40.0298881530762,1.99784073687165,16.6599992662668,0.000229369746621521,3.0313470609313E-5,0.25,-9.4510131603324E-7,2.01357232444395E-5,-7.95676006295603E-7,9.9971867,9.9971867,63738.86328125,63743.99609375,56.8728543162753,20.6305278380307,11.519473,0,0,0,40,4449,10.06555,63741.4296875,,,,,,,,,,,,,0,,,,0,,,,,,9.9971867,,,,
,23048856.25,9.9975824,68457.984375,1.04663474510216E-5,9.06881606170704E-7,1,0.999253354069792,40.0298881530762,1.99789102281337,16.6599992662668,0.000119529354856867,1.47632883845049E-5,0.25,-5.80495226317453E-7,1.04775820528595E-5,-5.0335270458866E-7,9.9975824,9.9975824,68451.484375,68464.484375,56.8603482599676,20.6310205226086,10.760172,0,0,0,40,4449,10.0687,68457.984375,,,,,,,,,,,,,0,,,,0,,,,,,9.9975824,,,,
,23049033.455,9.9982615,72885.4296875,9.06979547415006E-7,8.00881415076867E-7,1,0.999253354069792,40.0298881530762,1.99785851771142,16.6599992662668,1.0145736001321E-5,2.47844709309964E-6,0.25,5.5709196823522E-8,9.07508021473089E-7,6.24429908502323E-8,9.9982615,9.9982615,72879.1328125,72891.7265625,57.1026531009291,20.630494764174,11.139823,0,0,0,40,4449,10.0732,72885.4296875,,,,,,,,,,,,,0,,,,0,,,,,,9.9982615,,,,
,23049238.775,9.9975309,78017.19140625,-9.29676343796363E-6,1.24542283467217E-6,1,0.999253354069792,40.0298881530762,1.99798704908528,16.6800003498793,-0.000102832607335879,-3.21517318572853E-5,0.25,-1.16687040489808E-6,-9.30166941354869E-6,-1.23630745335891E-6,9.9975309,9.9975309,78014.6015625,78019.78125,57.047939104583,20.6313005969094,11.139823,0,0,0,40,4449,10.07695,78017.19140625,,,,,,,,,,,,,0,,,,0.00245,,,,,,9.9975309,,,,
,23049416.265,9.9972925,82454.546875,-1.85436014044904E-5,1.18021879486118E-6,1,0.999253354069792,40.0298881530762,1.99795520471334,16.6800003498793,-0.000205866759952375,-6.0335009667561E-5,0.25,-1.99182379049318E-6,-1.8562141108262E-5,-2.12907514186595E-6,9.9972925,9.9972925,82450.8359375,82458.2578125,57.0674798175637,20.6325521589173,10.760172,0,0,0,40,4449,10.0818,82454.546875,,,,,,,,,,,,,0,,,,0.00245,,,,,,9.9972925,,,,
,23049584.95,9.9972153,86668.9609375,-2.69087837331458E-5,1.0130982111065E-6,1,0.999253354069792,40.0298881530762,1.99789757523714,16.6800003498793,-0.000304518072784599,-5.58954213387981E-5,0.25,-9.48890523248419E-8,-2.69638669392145E-5,-2.86893299876078E-7,9.9972153,9.9972153,86666.2578125,86671.6640625,57.1456426694868,20.6331689617077,11.139823,0,0,0,40,4449,10.08475,86668.9609375,,,,,,,,,,,,,0,,,,-0.00245,,,,,,9.9972153,,,,
,23049801.915,9.9999619,88476.58984375,-3.39954597404996E-5,1.23066286509705E-6,1,0.999253354069792,40.0298881530762,1.99790173014689,16.6800003498793,-0.00037992673634219,-9.7515021752697E-5,0.25,-2.49554171986341E-6,-3.40523801194668E-5,-2.74204722674922E-6,9.9999619,9.9999619,88471.640625,88481.5390625,57.3879475104484,20.62929397417,11.139823,0,0,0,40,4449,10.0901,88476.58984375,,,,,,,,,,,,,0,,,,-0.00245,,,,,,9.9999619,,,,
,23049968.005,10.0013351,84323.9296875,-2.15494234843716E-5,1.19380408736893E-6,1,0.999253354069792,40.0298881530762,1.99794968846893,16.6800003498793,-0.000240926776375481,-6.09125240987364E-5,0.25,-1.50186812652382E-6,-2.15797745057667E-5,-1.65935727363364E-6,10.0013351,10.0013351,84320.0703125,84327.7890625,57.0620084179291,20.6327432260193,10.760172,0,0,0,40,4449,10.08665,84323.9296875,,,,,,,,,,,,,0,,,,0,,,,,,10.0013351,,,,
,23050148.335,10.0019007,79816.421875,-1.26612772457165E-5,1.19516719672317E-6,1,0.999253354069792,40.0298881530762,1.99801033539968,16.6800003498793,-0.000138140549875079,-5.45054099441285E-5,0.25,-2.53589795766556E-6,-1.26628673328537E-5,-2.63179986670589E-6,10.0019007,10.0019007,79814.0859375,79818.7578125,57.1815975813714,20.6364498713127,11.139823,0,0,0,40,4449,10.0836,79816.421875,,,,,,,,,,,,,0,,,,0,,,,,,10.0019007,,,,
,23050327.485,10.0026159,75338.76171875,-4.37144718156932E-6,7.28053413941379E-7,1,0.999253354069792,40.0298881530762,1.9979496140849,16.6800003498793,-4.89129588527863E-5,-1.19441018189314E-5,0.25,-2.68267501081919E-7,-4.37487064491591E-6,-3.00633651095032E-7,10.0026159,10.0026159,75334.96875,75342.5546875,57.0409044479099,20.6377138844423,10.760172,0,0,0,40,4449,10.0803,75338.76171875,,,,,,,,,,,,,0,,,,0,,,,,,10.0026159,,,,
,23050533.415,10.0016766,70192.73828125,7.06519313642647E-6,1.0470775417545E-6,1,0.999253354069792,40.0298881530762,1.99803374982106,16.6800003498793,8.22096095487249E-5,1.61419886834142E-6,0.25,-1.13036225881258E-6,7.07927524828186E-6,-1.07905913487025E-6,10.0016766,10.0016766,70187.8125,70197.6640625,57.403580080833,20.6364965410109,11.519473,0,0,0,40,4449,10.07655,70192.73828125,,,,,,,,,,,,,0,,,,-0.0049,,,,,,10.0016766,,,,
,23050710.375,10.0023947,65769.41015625,1.69381369213542E-5,1.17550834724365E-6,1,0.999253354069792,40.0298881530762,1.99800508043703,16.6800003498793,0.000192427575463749,2.93097595670644E-5,0.25,-4.60203550669328E-7,1.69487936368989E-5,-3.34603258269023E-7,10.0023947,10.0023947,65766.953125,65771.8671875,56.8345545188329,20.638523032394,11.519473,0,0,0,40,4449,10.0729,65769.41015625,,,,,,,,,,,,,0,,,,-0.00245,,,,,,10.0023947,,,,
,23050888.89,10.0023184,61308.849609375,2.57770922817019E-5,7.38233470268798E-7,1,0.999253354069792,40.0298881530762,1.99802340850956,16.6800003498793,0.000294792825176797,3.31301475505337E-5,0.25,-1.71466954317825E-6,2.57904307740264E-5,-1.52284818015669E-6,10.0023184,10.0023184,61303.71484375,61313.984375,57.0596635323714,20.6377168696494,11.139823,0,0,0,40,4449,10.069,61308.849609375,,,,,,,,,,,,,0,,,,0.0049,,,,,,10.0023184,,,,
,23051099.62,10.0015793,56041.408203125,3.60761397080681E-5,7.68742271827805E-7,1,0.999253354069792,40.0298881530762,1.99795478321556,16.6800003498793,0.000407265950551669,7.45754208637251E-5,0.25,1.0016708179556E-7,3.60581359433531E-5,3.68256484377507E-7,10.0015793,10.0015793,56039.015625,56043.80078125,56.6844818431406,20.6355758525819,11.139823,0,0,0,40,4449,10.06505,56041.408203125,,,,,,,,,,,,,0,,,,0,,,,,,10.0015793,,,,
,23051278.655,10.0022659,51568.947265625,4.33513737037103E-5,8.20787027140326E-7,1,0.999253354069792,40.0298881530762,1.99806395536997,16.6800003498793,0.000490892942487044,8.02149895787361E-5,0.25,-7.07578793828224E-7,4.33166874247454E-5,-3.86339530451295E-7,10.0022659,10.0022659,51566.328125,51571.56640625,57.007294421583,20.6380204842271,11.519473,0,0,0,40,4449,10.06205,51568.947265625,,,,,,,,,,,,,0,,,,0.0049,,,,,,10.0022659,,,,
,23051455.735,10.0021935,47143.763671875,5.05273624132308E-5,9.22959676263085E-7,1,0.999253354069792,40.0298881530762,1.99802322962761,16.6800003498793,0.000570997794365291,9.83497750420391E-5,0.25,-3.87268692427085E-7,5.0460890889921E-5,-1.64064557712559E-8,10.0021935,10.0021935,47141.09765625,47146.4296875,57.4778347901599,20.6402539266741,11.519473,0,0,0,40,4449,10.05805,47143.763671875,,,,,,,,,,,,,0,,,,-0.00245,,,,,,10.0021935,,,,
,23051665.995,10.0013361,41888.90625,5.82701197157862E-5,6.80217333927521E-7,1,0.999253354069792,40.0298881530762,1.99809188802664,16.6800003498793,0.000658264018100788,0.000112760507912933,0.25,-4.93246265695825E-7,5.81617919204504E-5,-7.21359751411606E-8,10.0013361,10.0013361,41884.0703125,41893.7421875,57.4325003360445,20.6381589691975,10.760172,0,0,0,40,4449,10.0538,41888.90625,,,,,,,,,,,,,0,,,,0.0049,,,,,,10.0013361,,,,
,23051844.875,10.0020552,37418.732421875,6.54969749198268E-5,8.68080943750111E-7,1,0.999253354069792,40.0298881530762,1.99808563832041,16.6800003498793,0.000739238180834334,0.000128416028568171,0.25,-3.92017563218711E-7,6.53429982806017E-5,7.21490549605831E-8,10.0020552,10.0020552,37413.65234375,37423.8125,56.8939582862945,20.6423961789093,11.519473,0,0,0,40,4449,10.05145,37418.732421875,,,,,,,,,,,,,0,,,,-0.0049,,,,,,10.0020552,,,,
,23052030.445,10.0015945,32781.640625,7.07249786666987E-5,7.02853606708024E-7,1,0.999253354069792,40.0298881530762,1.99816185152931,16.6800003498793,0.000796738643336816,0.000144943378013635,0.25,1.51915649482861E-7,7.05198734981185E-5,6.38887336704401E-7,10.0015945,10.0015945,32778.69140625,32784.58984375,57.027616763083,20.6445900958757,11.139823,0,0,0,40,4449,10.0489,32781.640625,,,,,,,,,,,,,0,,,,-0.0049,,,,,,10.0015945,,,,
,23052220.055,10.0018568,28042.6064453125,7.67711143032949E-5,5.45484306289602E-7,1,0.999253354069792,40.0298881530762,1.99810391435274,16.6800003498793,0.000865324108180763,0.000152066497398025,0.25,-2.78325775871464E-7,7.6513243930923E-5,2.34429172876786E-7,10.0018568,10.0018568,28036.185546875,28049.02734375,57.3762230826599,20.6395303709028,11.139823,0,0,0,40,4449,10.0452,28042.6064453125,,,,,,,,,,,,,0,,,,0,,,,,,10.0018568,,,,
,23052442.03,10.0016947,22496.9091796875,8.15312332964869E-5,3.82511343731742E-7,1,0.999253354069792,40.0298881530762,1.99811471898425,16.6800003498793,0.000919024055381626,0.000158239627382061,0.25,-5.51339363937493E-7,8.12127167117061E-5,-3.11140159526229E-8,10.0016947,10.0016947,22491.8203125,22501.998046875,57.0635716749676,20.6415359414327,10.760172,0,0,0,40,4449,10.0435,22496.9091796875,,,,,,,,,,,,,0,,,,-0.00245,,,,,,10.0016947,,,,
,23052634.655,10.0016289,17683.021484375,8.57632267702646E-5,4.24188207735118E-7,1,0.999253354069792,40.0298881530762,1.99815676755803,16.6800003498793,0.000964134385246066,0.000178423227241286,0.25,5.16867897585397E-7,8.53812212857183E-5,1.03289339117154E-6,10.0016289,10.0016289,17681.73828125,17684.3046875,57.1081245005637,20.6442322533405,10.760172,0,0,0,40,4449,10.042,17683.021484375,,,,,,,,,,,,,0,,,,0,,,,,,10.0016289,,,,
,23052827.015,10.0013981,12875.6801757813,8.83724158674268E-5,3.48454194487349E-7,1,0.999253354069792,40.0298881530762,1.99812604333445,16.6800003498793,0.000994193813245479,0.000177175914417912,0.25,-2.35992431038323E-8,8.7943638471495E-5,4.80681371348711E-7,10.0013981,10.0013981,12869.5546875,12881.8056640625,56.9134989992753,20.6444728583459,11.139823,0,0,0,40,4449,10.03915,12875.6801757813,,,,,,,,,,,,,0,,,,0,,,,,,10.0013981,,,,
,23053049.775,10.0020828,7308.732421875,9.08770073430979E-5,3.64762309795679E-7,1,0.999253354069792,40.0298881530762,1.99820799220081,16.6800003498793,0.00102146863981294,0.000184800452975982,0.25,2.51153635792357E-7,9.03936897500565E-5,7.31029733520273E-7,10.0020828,10.0020828,7305.2685546875,7312.1962890625,57.0049495360253,20.6475197315706,11.139823,0,0,0,40,4449,10.0364,7308.732421875,,,,,,,,,,,,,0,,,,0,,,,,,10.0020828,,,,
,23053239.805,10.004447,2559.75720214844,9.10446133762966E-5,3.29174173886536E-7,1,0.999253354069792,40.0298881530762,1.99817882477776,16.6800003498793,0.00102312034202735,0.000184458140125775,0.25,2.26858721991319E-7,9.05316214368727E-5,6.77202702423061E-7,10.004447,10.004447,2554.63012695313,2564.88427734375,57.647448178833,20.6449802134692,10.760172,0,0,0,40,4449,10.0291,2559.75720214844,,,,,,,,,,,,,0,,,,0,,,,,,10.004447,,,,
,23053430.175,9.99988175,-2195.81689453125,7.15034659824693E-5,3.16188080012106E-7,1,0.999253354069792,40.0298881530762,1.99813742070693,16.6800003498793,0.000804357132536121,0.000139996280247172,0.25,-2.52930833364905E-7,7.11012286127112E-5,1.01516974788848E-7,9.9996576,10.0001059,-2198.318359375,-2193.3154296875,57.1855057239676,20.6452321061104,10.38052,0,0,0,40,4449,10.0232,-2195.81689453125,,,,,,,,,,,,,0,,,,-0.0049,,,,,,9.99988175,,,,
,23053637.385,9.9967918,-7373.83422851562,6.82451306378795E-5,3.09742289729101E-7,1,0.999253354069792,40.0298881530762,1.99817820622819,16.6800003498793,0.000767153042285025,0.000138346491887885,0.25,1.50021908718939E-7,6.78827129555941E-5,5.10922515859297E-7,9.9967918,9.9967918,-7376.66650390625,-7371.001953125,57.6091483813907,20.6445065563545,11.519473,0,0,0,40,4449,10.0304,-7373.83422851562,,,,,,,,,,,,,0,,,,0,,,,,,9.9967918,,,,
,23053810.515,9.9980392,-11700.8637695313,6.28988590655596E-5,3.29890333065679E-7,1,0.999253354069792,40.0298881530762,1.99819585717332,16.6800003498793,0.000707652233586173,0.000125617684000404,0.25,-5.39313660049079E-8,6.25875665056193E-5,2.99783011993673E-7,9.9980392,9.9980392,-11704.716796875,-11697.0107421875,56.7688977232175,20.6473330552775,10.760172,0,0,0,40,4449,10.0329,-11700.8637695313,,,,,,,,,,,,,0,,,,0,,,,,,9.9980392,,,,
,23053986.005,9.9989176,-16087.4814453125,4.97594249593753E-5,4.11170433416217E-7,1,0.999253354069792,40.0298881530762,1.99819324131861,16.6800003498793,0.000560098320495,9.91099285169542E-5,0.25,-8.54068672207812E-8,4.95327112081651E-5,2.10245502041152E-7,9.9989176,9.9989176,-16092.41796875,-16082.544921875,56.7962547213906,20.6468334892192,11.519473,0,0,0,40,4449,10.03425,-16087.4814453125,,,,,,,,,,,,,0,,,,0.00245,,,,,,9.9989176,,,,
,23054189.885,9.9988432,-21181.9638671875,2.08351047148773E-5,4.07835983078596E-7,1,0.999253354069792,40.0298881530762,1.9982359579019,16.6800003498793,0.000235267425342886,3.80305510950915E-5,0.25,-3.52765397646777E-7,2.0752307709279E-5,-2.20637959544972E-7,9.9988432,9.9988432,-21187.0078125,-21176.919921875,57.2769562607176,20.646603914312,11.139823,0,0,0,40,4449,10.0369,-21181.9638671875,,,,,,,,,,,,,0,,,,0,,,,,,9.9988432,,,,
,23054367.005,9.9983873,-25606.7373046875,-8.93348612073927E-6,5.05208984932669E-7,1,0.999253354069792,40.0298881530762,1.99828271957204,16.6800003498793,-0.000101216213613942,-1.46836671724743E-5,0.25,2.98361769735841E-7,-8.90296506936834E-6,2.38890418422762E-7,9.9983873,9.9983873,-25614.203125,-25599.271484375,57.0838940164676,20.6462265477042,11.139823,0,0,0,40,4449,10.03925,-25606.7373046875,,,,,,,,,,,,,0,,,,0.00245,,,,,,9.9983873,,,,
,23054546.655,9.99857905,-30097.2060546875,-3.2794596737844E-5,4.21658959237151E-7,1,0.999253354069792,40.0298881530762,1.998142695202,16.6800003498793,-0.000369531973727004,-6.6079940187779E-5,0.25,2.40613094403029E-8,-3.26908560247248E-5,-1.98007232903577E-7,9.9985142,9.9986439,-30099.55078125,-30094.861328125,57.6341604940061,20.6476499458598,11.519473,0,0,0,40,4449,10.0398,-30097.2060546875,,,,,,,,,,,,,0,,,,0.0049,,,,,,9.99857905,,,,
,23054753.835,9.9987259,-35273.869140625,-4.67817979644998E-5,5.70360921641742E-7,1,0.999253354069792,40.0298881530762,1.99820353668488,16.6800003498793,-0.000525534361838121,-0.00010495259171252,0.25,-8.98689650986933E-7,-4.66528985142153E-5,-1.22351038174898E-6,9.9987259,9.9987259,-35276.41796875,-35271.3203125,57.024490249006,20.6478107838473,11.139823,0,0,0,40,4449,10.04365,-35273.869140625,,,,,,,,,,,,,0,,,,0.00245,,,,,,9.9987259,,,,
,23054930.04,9.9979458,-39676.357421875,-5.0011006913238E-5,6.7126579704966E-7,1,0.999253354069792,40.0298881530762,1.99808440986235,16.6800003498793,-0.000564123213245307,-0.000100670554969356,0.25,7.29898597215252E-8,-4.99038142985079E-5,-2.84578236594228E-7,9.9979458,9.9979458,-39681.359375,-39671.35546875,57.3715333115445,20.6477902490924,11.519473,0,0,0,40,4449,10.04525,-39676.357421875,,,,,,,,,,,,,0,,,,0.0049,,,,,,9.9979458,,,,
,23055105.87,9.9975519,-44071.16015625,-4.86863051055661E-5,6.39333096383243E-7,1,0.999253354069792,40.0298881530762,1.99803217207244,16.6800003498793,-0.000549561305448516,-9.72744375640843E-5,0.25,1.45176001672306E-7,-4.86050316135042E-5,-2.08798660546915E-7,9.9975519,9.9975519,-44073.5625,-44068.7578125,57.3668435404292,20.6538381708173,11.139823,0,0,0,40,4449,10.0491,-44071.16015625,,,,,,,,,,,,,0,,,,0.00245,,,,,,9.9975519,,,,
,23055284.645,9.9977541,-48537.912109375,-4.50508004941574E-5,8.19413089194407E-7,1,0.999253354069792,40.0298881530762,1.99816863762024,16.6800003498793,-0.000508118408879939,-9.38064874590647E-5,0.25,-1.9390978791354E-7,-4.4994033495296E-5,-5.2494296794458E-7,9.9977541,9.9977541,-48539.234375,-48536.58984375,56.6360208749483,20.6487321554338,11.519473,0,0,0,40,4449,10.0523,-48537.912109375,,,,,,,,,,,,,0,,,,0.00245,,,,,,9.9977541,,,,
,23055490.9,9.9980536,-53691.146484375,-3.71339858834869E-5,7.82893886461992E-7,1,0.999253354069792,40.0298881530762,1.99815408296827,16.6900008916855,-0.00041890612462483,-7.81114355672175E-5,0.25,-2.24040763243271E-7,-3.71059939338457E-5,-4.99280036497995E-7,9.9980536,9.9980536,-53696.15234375,-53686.140625,57.180034324333,20.653866610864,11.139823,0,0,0,40,4449,10.0558,-53691.146484375,,,,,,,,,,,,,0,,,,0.00245,,,,,,9.9980536,,,,
,23055670.17,9.9978848,-58171.279296875,-3.04632686493578E-5,9.44426151762819E-7,1,0.999253354069792,40.0298881530762,1.998144035322,16.6900008916855,-0.000341368608996738,-7.76098059583768E-5,0.25,-1.37827006924178E-6,-3.04446927245063E-5,-1.60456833799693E-6,9.9978848,9.9978848,-58173.60546875,-58168.953125,57.2136443506599,20.6502527943571,11.139823,0,0,0,40,4449,10.06005,-58171.279296875,,,,,,,,,,,,,0,,,,0,,,,,,9.9978848,,,,
,23055848.68,9.9977264,-62632.919921875,-2.2463074478398E-5,9.8905574252948E-7,1,0.999253354069792,40.0298881530762,1.9980966582593,16.6900008916855,-0.000253386987038915,-4.85496672628592E-5,0.25,-2.46559293483784E-7,-2.24644852346907E-5,-4.13730909342909E-7,9.9977264,9.9977264,-62636.46484375,-62629.375,57.5067550453715,20.6504670747012,11.139823,0,0,0,40,4449,10.06355,-62632.919921875,,,,,,,,,,,,,0,,,,0.00245,,,,,,9.9977264,,,,
,23056052.025,9.9977512,-67714.76953125,-1.31147720718593E-5,1.04865547963703E-6,1,0.999253354069792,40.0298881530762,1.99818945667956,16.6900008916855,-0.000147558792512611,-3.08649740101028E-5,0.25,-3.65938161697681E-7,-1.31199050322623E-5,-4.63381832430191E-7,9.9977512,9.9977512,-67721.2421875,-67708.296875,57.0815491309099,20.6521673849665,10.760172,0,0,0,40,4449,10.06805,-67714.76953125,,,,,,,,,,,,,0,,,,0,,,,,,9.9977512,,,,
,23056229.75,9.99772215,-72154.4140625,-2.16017670097438E-6,9.04198698486251E-7,1,0.999253354069792,40.0298881530762,1.99815023697735,16.6900008916855,-2.52583791065727E-5,1.58188999934422E-7,0.25,4.03178786730147E-7,-2.16525339964176E-6,3.87651994358285E-7,9.9976482,9.9977961,-72158.203125,-72150.625,57.3457395704099,20.6509766416181,11.139823,0,0,0,40,4449,10.0713,-72154.4140625,,,,,,,,,,,,,0,,,,-0.00245,,,,,,9.99772215,,,,
,23056405.545,9.9978094,-76547.5078125,5.71882399343904E-6,8.82521721238321E-7,1,0.999253354069792,40.0298881530762,1.99823408854492,16.6900008916855,6.32248776842705E-5,1.99544133614298E-5,0.25,7.33251863198341E-7,5.7210597999183E-6,7.76034413479802E-7,9.9978094,9.9978094,-76549.5859375,-76545.4296875,57.3644986548715,20.6508138340554,11.139823,0,0,0,40,4449,10.07585,-76547.5078125,,,,,,,,,,,,,0,,,,0.0049,,,,,,9.9978094,,,,
,23056612.285,9.99759105,-81714.0234375,1.75413017550995E-5,1.02481906487445E-6,1,0.999253354069792,40.0298881530762,1.99814108536981,16.6900008916855,0.000197833270896842,3.99252976367948E-5,0.25,3.68992961864233E-7,1.75688116640366E-5,4.96356467352869E-7,9.9975758,9.9976063,-81717.9375,-81710.109375,57.4809613042369,20.6527906345333,10.760172,0,0,0,40,4449,10.07985,-81714.0234375,,,,,,,,,,,,,0,,,,0.00245,,,,,,9.99759105,,,,
,23056786.42,9.9971457,-86064.515625,2.60048404253371E-5,1.0450765987824E-6,1,0.999253354069792,40.0298881530762,1.99815387567691,16.6900008916855,0.00029497530396527,5.03368244249109E-5,0.25,-2.34046146416666E-7,2.60593139610085E-5,-4.88344294787755E-8,9.9971457,9.9971457,-86067.2734375,-86061.7578125,57.4113963660253,20.6524843568504,11.139823,0,0,0,40,4449,10.0838,-86064.515625,,,,,,,,,,,,,0,,,,-0.00245,,,,,,9.9971457,,,,
,23056967.14,9.9975338,-89890.9765625,3.49238680882907E-5,1.05038192461181E-6,1,0.999253354069792,40.0298881530762,1.99816993532489,16.6900008916855,0.000390372597786861,0.000100296375852198,0.25,2.57325139367442E-6,3.4985632750246E-5,2.82567916406553E-6,9.9975338,9.9975338,-89894.859375,-89887.09375,57.1706547821022,20.6547235918634,11.139823,0,0,0,40,4449,10.0885,-89890.9765625,,,,,,,,,,,,,0,,,,0.0049,,,,,,9.9975338,,,,
,23057131.255,10.0006819,-85795.24609375,2.58802159195711E-5,1.1363134356749E-6,1,0.999253354069792,40.0298881530762,1.99817132212443,16.6900008916855,0.000292137886063785,5.79914287741625E-5,0.25,4.64203011379972E-7,2.59289644040058E-5,6.500756431208E-7,10.0006819,10.0006819,-85798.921875,-85791.5703125,56.9181887703906,20.6535305057628,10.760172,0,0,0,40,4449,10.08625,-85795.24609375,,,,,,,,,,,,,0,,,,0,,,,,,10.0006819,,,,
,23057338.85,10.0023022,-80606.9921875,1.4087851449616E-5,1.09612458082984E-6,1,0.999253354069792,40.0298881530762,1.99820624639114,16.6900008916855,0.000160958747439475,2.04985800658802E-5,0.25,-7.25527409213794E-7,1.41161896320034E-5,-6.24658118037126E-7,10.0023022,10.0023022,-80612.0078125,-80601.9765625,57.403580080833,20.6527274697907,10.760172,0,0,0,40,4449,10.08345,-80606.9921875,,,,,,,,,,,,,0,,,,0.00245,,,,,,10.0023022,,,,
,23057519.855,10.0022402,-76084.2265625,3.68808535208838E-6,7.81853610799373E-7,1,0.999253354069792,40.0298881530762,1.99815794257898,16.6900008916855,3.88864749127029E-5,2.33302082353385E-5,0.25,1.39741924025194E-6,3.68262425285541E-6,1.42621239490154E-6,10.0022402,10.0022402,-76089.234375,-76079.21875,56.976810909333,20.6543637159523,10.760172,0,0,0,40,4449,10.0788,-76084.2265625,,,,,,,,,,,,,0,,,,-0.0049,,,,,,10.0022402,,,,
,23057697.99,10.0021515,-71633.16015625,-6.77009453508617E-6,1.03766935764221E-6,1,0.999253354069792,40.0298881530762,1.99810199725309,16.6900008916855,-7.64612885238895E-5,-1.44592224932868E-5,0.25,-5.84679858612168E-8,-6.77596918165752E-6,-1.08456360920792E-7,10.0021515,10.0021515,-71636.9453125,-71629.375,57.1284468420637,20.6533738533139,11.519473,0,0,0,40,4449,10.07545,-71633.16015625,,,,,,,,,,,,,0,,,,-0.00245,,,,,,10.0021515,,,,
,23057906.53,10.0021458,-66421.21484375,-1.56644175034385E-5,7.81637572975167E-7,1,0.999253354069792,40.0298881530762,1.99808384726949,16.6900008916855,-0.000178292261212813,-2.53438817002171E-5,0.25,5.81581073486772E-7,-1.56763319400671E-5,4.65590164297727E-7,10.0021458,10.0021458,-66422.5625,-66419.8671875,57.0534105042176,20.6494438486591,11.519473,0,0,0,40,4449,10.0704,-66421.21484375,,,,,,,,,,,,,0,,,,0,,,,,,10.0021458,,,,
,23058088.5,10.0024567,-61874.865234375,-2.39656052472885E-5,7.53894749390082E-7,1,0.999253354069792,40.0298881530762,1.99807833871049,16.6900008916855,-0.000273880137366166,-3.20117002644939E-5,0.25,1.48731078263022E-6,-2.39784653630928E-5,1.30906558670873E-6,10.0024567,10.0024567,-61877.2890625,-61872.44140625,57.2691399755253,20.6491216323735,11.139823,0,0,0,40,4449,10.0676,-61874.865234375,,,,,,,,,,,,,0,,,,0.00245,,,,,,10.0024567,,,,
,23058267.505,10.0022888,-57401.234375,-3.41919671304122E-5,7.36785473657847E-7,1,0.999253354069792,40.0298881530762,1.99806177147679,16.6900008916855,-0.000388184902298231,-5.89375696698872E-5,0.25,9.45875987276627E-7,-3.41871410028286E-5,6.91208842581782E-7,10.0022888,10.0022888,-57402.49609375,-57399.97265625,57.2464727484676,20.6496349256419,11.139823,0,0,0,40,4449,10.06335,-57401.234375,,,,,,,,,,,,,0,,,,0,,,,,,10.0022888,,,,
,23058476.355,10.0027514,-52182.30078125,-4.13313025933444E-5,9.03943614458344E-7,1,0.999253354069792,40.0298881530762,1.99827036960722,16.6900008916855,-0.000467014721011016,-8.24756505115949E-5,0.25,1.44747912341353E-7,-4.12968580206033E-5,-1.61306644747257E-7,10.0027514,10.0027514,-52186.11328125,-52178.48828125,57.3410497992945,20.6478265172044,10.760172,0,0,0,40,4449,10.0587,-52182.30078125,,,,,,,,,,,,,0,,,,-0.0049,,,,,,10.0027514,,,,
,23058655.03,10.0024986,-47718.62890625,-5.06443806361174E-5,8.43536840023213E-7,1,0.999253354069792,40.0298881530762,1.99816056652932,16.6900008916855,-0.000571862093527304,-0.000101529935275683,0.25,1.28171586020876E-7,-5.05788500655579E-5,-2.43704604142345E-7,10.0024986,10.0024986,-47723.75390625,-47713.50390625,57.1417345268907,20.6504540528751,11.139823,0,0,0,40,4449,10.0545,-47718.62890625,,,,,,,,,,,,,0,,,,0,,,,,,10.0024986,,,,
,23058831.955,10.0026054,-43296.927734375,-5.59012602516492E-5,8.28262371023524E-7,1,0.999253354069792,40.0298881530762,1.99809566143664,16.6900008916855,-0.000631360148125198,-0.000109517569062326,0.25,3.57731880913073E-7,-5.58047905945348E-5,-4.80147073031453E-8,10.0026054,10.0026054,-43300.58984375,-43293.265625,57.1448610409676,20.6499938176088,11.519473,0,0,0,40,4449,10.0507,-43296.927734375,,,,,,,,,,,,,0,,,,0.00245,,,,,,10.0026054,,,,
,23059008.45,10.0024529,-38887.234375,-6.35983688955583E-5,7.66730780112889E-7,1,0.999253354069792,40.0298881530762,1.9980902549635,16.6900008916855,-0.00071680839375815,-0.000130910699466761,0.25,-1.65873558766906E-7,-6.34548910609388E-5,-6.18434749309298E-7,10.0024529,10.0024529,-38890.9453125,-38883.5234375,56.7431039820829,20.6498732448911,11.139823,0,0,0,40,4449,10.04695,-38887.234375,,,,,,,,,,,,,0,,,,0,,,,,,10.0024529,,,,
,23059217.21,10.0018492,-33670.33984375,-6.94361142581345E-5,6.85618550530812E-7,1,0.999253354069792,40.0298881530762,1.99802994136628,16.6900008916855,-0.000782756105451734,-0.000139456688083354,0.25,1.06297171110374E-7,-6.92430468482895E-5,-3.75143075383272E-7,10.0018492,10.0018492,-33673.99609375,-33666.68359375,57.3840393678522,20.6474454623148,11.139823,0,0,0,40,4449,10.04325,-33670.33984375,,,,,,,,,,,,,0,,,,0,,,,,,10.0018492,,,,
,23059395.715,10.0019875,-29210.1474609375,-7.51156928313797E-5,5.35629994669058E-7,1,0.999253354069792,40.0298881530762,1.99814912486763,16.6900008916855,-0.000844385916900847,-0.000162184899911325,0.25,-9.1060098386783E-7,-7.48645935022298E-5,-1.41284953003197E-6,10.0019875,10.0019875,-29213.98046875,-29206.314453125,57.1448610409676,20.6477320670261,11.139823,0,0,0,40,4449,10.04135,-29210.1474609375,,,,,,,,,,,,,0,,,,0,,,,,,10.0019875,,,,
,23059575.855,10.0016594,-24707.6904296875,-7.95008498708544E-5,5.29824714367677E-7,1,0.999253354069792,40.0298881530762,1.99813193949524,16.6900008916855,-0.000894136496710418,-0.000166664736652265,0.25,-5.46987158315391E-7,-7.92010335725009E-5,-1.06049751802763E-6,10.0016594,10.0016594,-24713.8359375,-24701.544921875,56.8259566051214,20.6459104876593,11.139823,0,0,0,40,4449,10.0395,-24707.6904296875,,,,,,,,,,,,,0,,,,0.0049,,,,,,10.0016594,,,,
,23059781.52,10.0012875,-19569.345703125,-8.4456008746711E-5,4.41953691944314E-7,1,0.999253354069792,40.0298881530762,1.99803584508159,16.6900008916855,-0.000949129617953805,-0.000178107197249636,0.25,-7.10058937869423E-7,-8.40937387995115E-5,-1.22806365658422E-6,10.0012875,10.0012875,-19571.859375,-19566.83203125,57.2753930036791,20.6489707736798,10.760172,0,0,0,40,4449,10.03705,-19569.345703125,,,,,,,,,,,,,0,,,,-0.00245,,,,,,10.0012875,,,,
,23059962.37,10.0017281,-15049.6049804687,-8.75460892987522E-5,3.62911987649915E-7,1,0.999253354069792,40.0298881530762,1.99804088822477,16.6900008916855,-0.000983111790426302,-0.000186389681330398,0.25,-9.26791369937572E-7,-8.7132603793418E-5,-1.43557265116029E-6,10.0017281,10.0017281,-15054.791015625,-15044.4189453125,57.2628869473714,20.6478422598761,10.760172,0,0,0,40,4449,10.03405,-15049.6049804687,,,,,,,,,,,,,0,,,,0,,,,,,10.0017281,,,,
,23060142.405,10.001874,-10550.654296875,-8.98818939648006E-5,3.4713498829837E-7,1,0.999253354069792,40.0298881530762,1.99811586770203,16.6900008916855,-0.00100967607922036,-0.000187423598622138,0.25,-6.36573614422751E-7,-8.94244987390087E-5,-1.13082660147046E-6,10.001874,10.001874,-10554.2705078125,-10547.0380859375,57.1737812961791,20.6478284129968,10.760172,0,0,0,40,4449,10.03295,-10550.654296875,,,,,,,,,,,,,0,,,,0.00245,,,,,,10.001874,,,,
,23060351.465,10.0033236,-5326.39916992188,-9.19159177762385E-5,3.37016919158254E-7,1,0.999253354069792,40.0298881530762,1.99809098764303,16.6900008916855,-0.00103234033604696,-0.000190249122034399,0.25,-5.67293629603932E-7,-9.14124402461174E-5,-1.03765736548164E-6,10.0033236,10.0033236,-5331.353515625,-5321.44482421875,57.1847240954484,20.6449849232795,11.519473,0,0,0,40,4449,10.02865,-5326.39916992188,,,,,,,,,,,,,0,,,,-0.0049,,,,,,10.0033236,,,,
,23060527.305,10.0063267,-930.214416503906,-8.89067561971484E-5,2.84457268187546E-7,1,0.999253354069792,40.0298881530762,1.99813898232949,16.6900008916855,-0.000998366777457482,-0.000183616578062682,0.25,-5.42421564935117E-7,-8.83965946050887E-5,-9.71597308107633E-7,10.0063267,10.0063267,-932.611999511719,-927.816833496094,57.0237086204868,20.6453412580699,11.139823,0,0,0,40,4449,10.0186,-930.214416503906,,,,,,,,,,,,,0,,,,-0.0049,,,,,,10.0063267,,,,
,23060701.265,9.9978514,3414.63354492188,-7.13373899532439E-5,2.51630768144604E-7,1,0.999253354069792,40.0298881530762,1.99801391492792,16.6900008916855,-0.000800727330848079,-0.000149645691143606,0.25,-6.29012519868047E-7,-7.09368214524758E-5,-9.83420438670803E-7,9.9978514,9.9978514,3412.2099609375,3417.05712890625,57.454385934583,20.6471565198566,11.139823,0,0,0,40,4449,10.01915,3414.63354492188,,,,,,,,,,,,,0,,,,0,,,,,,9.9978514,,,,
,23060907.4,9.99848035,8565.69384765625,-6.79279175354993E-5,3.83035166636934E-7,1,0.999253354069792,40.0298881530762,1.99801722811318,16.6900008916855,-0.000762871705685512,-0.000141784037658083,0.25,-5.060373055988E-7,-6.75714113085747E-5,-8.69390757785956E-7,9.9981127,9.998848,8563.1552734375,8568.232421875,57.0643533034868,20.6399424988519,11.139823,0,0,0,40,4449,10.0267,8565.69384765625,,,,,,,,,,,,,0,,,,-0.00245,,,,,,9.99848035,,,,
,23061078.305,9.9977589,12837.77734375,-6.06634062660836E-5,3.64912092389123E-7,1,0.999253354069792,40.0298881530762,1.99803207424086,16.6900008916855,-0.000681257972662789,-0.000128201788356504,0.25,-5.69346398297595E-7,-6.03655335268384E-5,-9.12500023067496E-7,9.9977589,9.9977589,12833.9580078125,12841.5966796875,57.4215575367753,20.6443501852368,11.139823,0,0,0,40,4449,10.02915,12837.77734375,,,,,,,,,,,,,0,,,,-0.00735,,,,,,9.9977589,,,,
,23061254.395,9.9981241,17239.662109375,-4.43621159215117E-5,4.43603846766426E-7,1,0.999253354069792,40.0298881530762,1.9980071853303,16.6900008916855,-0.000497590508212192,-9.823035805599E-5,0.25,-7.9737392176233E-7,-4.41594916183329E-5,-1.06058122558537E-6,9.9981241,9.9981241,17234.265625,17245.05859375,57.7482782578138,20.6454227684041,10.760172,0,0,0,40,4449,10.0326,17239.662109375,,,,,,,,,,,,,0,,,,0.00245,,,,,,9.9981241,,,,
,23061430.065,9.9979429,21627.728515625,-1.7145271062384E-5,4.67303828973271E-7,1,0.999253354069792,40.0298881530762,1.99798330786464,16.6900008916855,-0.000191976062276705,-4.02911689361657E-5,0.25,-5.0857686600245E-7,-1.70728670289419E-5,-6.14546525029427E-7,9.9979429,9.9979429,21624.076171875,21631.380859375,56.8337728903137,20.6444295618974,10.760172,0,0,0,40,4449,10.03405,21627.728515625,,,,,,,,,,,,,0,,,,0,,,,,,9.9979429,,,,
,23061636.43,9.9987659,26785.078125,1.74368279345027E-5,5.37738318091303E-7,1,0.999253354069792,40.0298881530762,1.99786477611641,16.6900008916855,0.000197576481257325,2.8477187441569E-5,0.25,-5.99546235309146E-7,1.73795209494822E-5,-4.82349912851656E-7,9.9987659,9.9987659,26782.5390625,26787.6171875,57.0745144742368,20.6416806817215,11.139823,0,0,0,40,4449,10.0373,26785.078125,,,,,,,,,,,,,0,,,,-0.0049,,,,,,9.9987659,,,,
,23061812.105,9.9986205,31176.6572265625,3.75712319473301E-5,5.8283993527238E-7,1,0.999253354069792,40.0298881530762,1.99792467590463,16.6900008916855,0.00042440234348907,6.99013835600287E-5,0.25,-5.44608681010058E-7,3.74601753637103E-5,-2.86710296230028E-7,9.998435,9.998806,31172.8515625,31180.462890625,57.4754899046022,20.6438355733867,11.139823,0,0,0,40,4449,10.0402,31176.6572265625,,,,,,,,,,,,,0,,,,-0.00245,,,,,,9.9986205,,,,
,23061988.605,9.9982004,35586.435546875,4.76696007478019E-5,7.3366892552819E-7,1,0.999253354069792,40.0298881530762,1.99792189096646,16.6900008916855,0.000540054598698496,8.13455392802338E-5,0.25,-1.35496248551405E-6,4.75557340055377E-5,-1.01749862982089E-6,9.9982004,9.9982004,35580.21484375,35592.65625,57.3433946848522,20.642227202111,10.760172,0,0,0,40,4449,10.0422,35586.435546875,,,,,,,,,,,,,0,,,,0,,,,,,9.9982004,,,,
,23062193.345,9.9982367,40702.728515625,5.22446041801784E-5,6.88516381350639E-7,1,0.999253354069792,40.0298881530762,1.99750411465553,16.6900008916855,0.00059134256212073,9.33512784077459E-5,0.25,-1.12417598731693E-6,5.21458197322318E-5,-7.46897614780301E-7,9.9982367,9.9982367,40700.31640625,40705.140625,57.3488660844868,20.6448597760066,11.519473,0,0,0,40,4449,10.0461,40702.728515625,,,,,,,,,,,,,0,,,,0,,,,,,9.9982367,,,,
,23062367.61,9.9976697,45058.34765625,4.95950612426172E-5,6.93334326320287E-7,1,0.999253354069792,40.0298881530762,1.99739224061389,16.6900008916855,0.000561555213600003,8.88021774016473E-5,0.25,-1.05927273648258E-6,4.95240264100654E-5,-6.96158212844188E-7,9.9975185,9.9978209,45053.125,45063.5703125,57.0283983916022,20.6470884224578,11.139823,0,0,0,40,4449,10.0482,45058.34765625,,,,,,,,,,,,,0,,,,0,,,,,,9.9976697,,,,
,23062541.375,9.9978905,49401.01171875,4.43566654260677E-5,6.00037740368109E-7,1,0.999253354069792,40.0298881530762,1.99737134053526,16.6900008916855,0.000501962462976926,8.22364792837868E-5,0.25,-7.04486920979896E-7,4.43112774959564E-5,-3.76925469032944E-7,9.9978905,9.9978905,49398.65625,49403.3671875,56.7141837268714,20.6484745820087,11.139823,0,0,0,40,4449,10.0504,49401.01171875,,,,,,,,,,,,,0,,,,0.00245,,,,,,9.9978905,,,,
,23062718.46,9.9977512,53826.326171875,3.78471920207122E-5,8.74560291377124E-7,1,0.999253354069792,40.0298881530762,1.99726885776427,16.6900008916855,0.000429892536586795,6.22923914698952E-5,0.25,-1.30303643692601E-6,3.78305275475429E-5,-1.02139940144624E-6,9.9977512,9.9977512,53821.3203125,53831.33203125,57.3801312252561,20.6485573741662,10.760172,0,0,0,40,4449,10.05545,53826.326171875,,,,,,,,,,,,,0,,,,-0.00245,,,,,,9.9977512,,,,
,23062921.395,9.9976606,58897.80078125,2.99179457332258E-5,8.78823961178117E-7,1,0.999253354069792,40.0298881530762,1.9972351359022,16.6900008916855,0.000339362713546779,5.27404981007641E-5,0.25,-7.22965705748783E-7,2.99172244194719E-5,-5.00154986687502E-7,9.9976606,9.9976606,58893.9609375,58901.640625,57.1659650109868,20.6464459613574,11.139823,0,0,0,40,4449,10.06015,58897.80078125,,,,,,,,,,,,,0,,,,0,,,,,,9.9976606,,,,
,23063096.345,9.9980469,63269.578125,2.06075394290141E-5,7.63603124224832E-7,1,0.999253354069792,40.0298881530762,1.99720318195516,16.6999995708466,0.000238392010046745,1.11159182370794E-5,0.25,-2.73055598756826E-6,2.06320264465376E-5,-2.57781892759888E-6,9.9980469,9.9980469,63267.125,63272.03125,56.9252234270637,20.6460111168778,11.519473,0,0,0,40,4449,10.0627,63269.578125,,,,,,,,,,,,,0,,,,-0.0049,,,,,,9.9980469,,,,
,23063271.11,9.9975395,67637.4765625,1.40200186892185E-5,9.1458952251288E-7,1,0.999253354069792,40.0298881530762,1.99705958184484,16.6900008916855,0.000163456184133707,8.03150406523178E-7,0.25,-2.45558033146412E-6,1.40465174545302E-5,-2.35308869514107E-6,9.9975395,9.9975395,67632.4609375,67642.4921875,57.3762230826599,20.6497235227972,11.139823,0,0,0,40,4449,10.06685,67637.4765625,,,,,,,,,,,,,0,,,,0,,,,,,9.9975395,,,,
,23063477.5,9.997467,72794.71484375,2.57671836456057E-6,8.25901871240926E-7,1,0.999253354069792,40.0298881530762,2.00968176286765,16.6900008916855,2.9784567908155E-5,2.650630997607E-6,0.25,-2.31203217762495E-7,2.58106770323153E-6,-2.1247102193342E-7,9.997467,9.997467,72792.1875,72797.2421875,57.0229269919676,20.6480078454679,11.139823,0,0,0,40,4449,10.0711,72794.71484375,,,,,,,,,,,,,0,,,,-0.00245,,,,,,9.997467,,,,
,23063655.165,9.9974747,77235.32421875,-4.83198712079484E-6,8.09580742349786E-7,1,0.999253354069792,40.0298881530762,1.99697104785345,16.6900008916855,-4.81958626051607E-5,-4.56981895677506E-5,0.25,-3.17004904421662E-6,-4.81552284689111E-6,-3.20970450628408E-6,9.9974747,9.9974747,77232.8359375,77237.8125,56.8134505488137,20.6483854251856,11.139823,0,0,0,40,4449,10.0762,77235.32421875,,,,,,,,,,,,,0,,,,-0.00245,,,,,,9.9974747,,,,
,23063828.57,9.9971781,81569.02734375,-1.62790738484475E-5,9.10285841468156E-7,1,0.999253354069792,40.0298881530762,1.99724295922073,16.6900008916855,-0.000181707741574185,-4.70864760221541E-5,0.25,-1.23055253098104E-6,-1.62980113856171E-5,-1.35030884020017E-6,9.9971781,9.9971781,81566.6796875,81571.375,57.0823307594291,20.6477592568234,11.139823,0,0,0,40,4449,10.08,81569.02734375,,,,,,,,,,,,,0,,,,0,,,,,,9.9971781,,,,
,23064031.055,9.9978189,86629.2734375,-2.74301203465958E-5,1.0904621056649E-6,1,0.999253354069792,40.0298881530762,2.00978206847409,16.6900008916855,-0.000307067312141451,-8.57097514197542E-5,0.25,-2.59126597843369E-6,-2.74684125603029E-5,-2.79217468399834E-6,9.9978189,9.9978189,86623.890625,86634.65625,56.8509687177368,20.645399508147,11.139823,0,0,0,40,4449,10.08495,86629.2734375,,,,,,,,,,,,,0,,,,0.00245,,,,,,9.9978189,,,,
,23064217.925,9.9991589,89275.7265625,-3.40207720971023E-5,1.2111132198308E-6,1,0.999253354069792,40.0298881530762,2.00980702313861,16.6900008916855,-0.000382840640688286,-9.56499147804083E-5,0.25,-2.27871840875201E-6,-3.40811367321472E-5,-2.52446194435567E-6,9.9991589,9.9991589,89273.53125,89277.921875,57.1135959001984,20.6470562485199,11.139823,0,0,0,40,4449,10.08775,89275.7265625,,,,,,,,,,,,,0,,,,0,,,,,,9.9991589,,,,
,23064384.9,10.0007954,85102.73046875,-2.34616089967643E-5,1.149545449858E-6,1,0.999253354069792,40.0298881530762,1.99727343067012,16.6900008916855,-0.000259454118802211,-8.1755552365844E-5,0.25,-3.00094788747506E-6,-2.34861879272061E-5,-3.17482227849923E-6,10.0007954,10.0007954,85100.109375,85105.3515625,56.8759808303522,20.6429988525968,11.139823,0,0,0,40,4449,10.0863,85102.73046875,,,,,,,,,,,,,0,,,,0,,,,,,10.0007954,,,,
,23064560.35,10.0017776,80716.82421875,-1.26408767753183E-5,9.69170308680001E-7,1,0.999253354069792,40.0298881530762,1.99756923695925,16.6900008916855,-0.000138668372771572,-5.01342438397353E-5,0.25,-2.1542128645499E-6,-1.26460896286326E-5,-2.24931114269111E-6,10.0017776,10.0017776,80711.921875,80721.7265625,57.0917103016599,20.6431548578518,10.760172,0,0,0,40,4449,10.08315,80716.82421875,,,,,,,,,,,,,0,,,,0,,,,,,10.0017776,,,,
,23064767.18,10.0020132,75546.44921875,-3.28082097703876E-6,7.80518862009807E-7,1,0.999253354069792,40.0298881530762,1.99747641608016,16.6900008916855,-3.52296175593915E-5,-1.71370022949026E-5,0.25,-9.24011701295845E-7,-3.2781511987915E-6,-9.49199370957179E-7,10.0020132,10.0020132,75542.65625,75550.2421875,56.7954730928714,20.64178097575,11.139823,0,0,0,40,4449,10.0792,75546.44921875,,,,,,,,,,,,,0,,,,-0.0049,,,,,,10.0020132,,,,
,23064946.115,10.0020685,71074.28125,7.03975099044521E-6,8.27460685123336E-7,1,0.999253354069792,40.0298881530762,1.99759006052034,16.6900008916855,8.5235992792146E-5,-1.68945833866112E-5,0.25,-2.76243446839593E-6,7.0663717420403E-6,-2.71291229356633E-6,10.0020685,10.0020685,71072.125,71076.4375,56.9009929429675,20.6408800744496,11.139823,0,0,0,40,4449,10.075,71074.28125,,,,,,,,,,,,,0,,,,0.0049,,,,,,10.0020685,,,,
,23065125.75,10.0027142,66585.05859375,1.52048476861626E-5,6.86976896691191E-7,1,0.999253354069792,40.0298881530762,1.9975215895552,16.6900008916855,0.000174640649714441,1.55875830163854E-5,0.25,-1.3612906797787E-6,1.52225446744068E-5,-1.24912553458307E-6,10.0027142,10.0027142,66581.3984375,66588.71875,57.0268351345637,20.6414280588525,11.139823,0,0,0,40,4449,10.0697,66585.05859375,,,,,,,,,,,,,0,,,,0,,,,,,10.0027142,,,,
,23065336.04,10.0025921,61329.783203125,2.53916556286423E-5,8.35501873439334E-7,1,0.999253354069792,40.0298881530762,1.99761197488179,16.6900008916855,0.00028936707753531,3.79615305618042E-5,0.25,-1.21701117086445E-6,2.5401330707949E-5,-1.02805049833358E-6,10.0025921,10.0025921,61326.1640625,61333.40234375,57.5700669554292,20.6390082796492,10.760172,0,0,0,40,4449,10.0659,61329.783203125,,,,,,,,,,,,,0,,,,0,,,,,,10.0025921,,,,
,23065517.09,10.0025892,56805.388671875,3.37014881266954E-5,7.53205714520883E-7,1,0.999253354069792,40.0298881530762,1.99755709147357,16.6900008916855,0.000385166351090301,4.32942969427471E-5,0.25,-2.24101365683484E-6,3.37045253061011E-5,-1.98949591425285E-6,10.0025892,10.0025892,56802.79296875,56807.984375,57.1151591572368,20.6392522773636,10.760172,0,0,0,40,4449,10.0619,56805.388671875,,,,,,,,,,,,,0,,,,-0.0049,,,,,,10.0025892,,,,
,23065696.335,10.0025434,52325.818359375,4.27538633610035E-5,8.61191080620605E-7,1,0.999253354069792,40.0298881530762,1.99758032801459,16.6900008916855,0.000486887725312659,6.33620661264956E-5,0.25,-2.09204720834936E-6,4.2733227152925E-5,-1.77375504766075E-6,10.0025434,10.0025434,52323.4375,52328.19921875,57.1808159528522,20.6408664810861,11.519473,0,0,0,40,4449,10.05825,52325.818359375,,,,,,,,,,,,,0,,,,-0.0049,,,,,,10.0025434,,,,
,23065907.72,10.0019836,47043.333984375,5.07833234506582E-5,6.97542764381272E-7,1,0.999253354069792,40.0298881530762,1.99776447715773,16.6900008916855,0.000573659677124894,9.96883708766442E-5,0.25,-3.13489507793065E-7,5.07154331965579E-5,5.90570907377932E-8,10.0019836,10.0019836,47038.30078125,47048.3671875,57.1206305568714,20.6408334527386,11.519473,0,0,0,40,4449,10.05365,47043.333984375,,,,,,,,,,,,,0,,,,0,,,,,,10.0019836,,,,
,23066085.335,10.0029278,42605.47265625,5.69556010014743E-5,6.60651318771155E-7,1,0.999253354069792,40.0298881530762,1.99769678132962,16.6900008916855,0.000643757958808332,0.00010789159113366,0.25,-6.88225263164331E-7,5.68555108363488E-5,-2.75194184776142E-7,10.0029278,10.0029278,42603.19921875,42607.74609375,57.1253203279868,20.6403153074006,11.139823,0,0,0,40,4449,10.05,42605.47265625,,,,,,,,,,,,,0,,,,0,,,,,,10.0029278,,,,
,23066260.14,10.0021143,38235.1015625,6.45920330934599E-5,6.52522444120045E-7,1,0.999253354069792,40.0298881530762,1.99779175847514,16.6900008916855,0.000727385550387158,0.000135528982161026,0.25,4.00539886495406E-7,6.44402020989212E-5,8.58243016606237E-7,10.0021143,10.0021143,38230.17578125,38240.02734375,57.0416860764291,20.6394189692208,10.760172,0,0,0,40,4449,10.04705,38235.1015625,,,,,,,,,,,,,0,,,,-0.00245,,,,,,10.0021143,,,,
,23066465.31,10.0034456,33109.583984375,7.0730890410994E-5,5.87385455415233E-7,1,0.999253354069792,40.0298881530762,1.99770428948835,16.6900008916855,0.000796522562242148,0.000145687461359924,0.25,2.18272750942469E-7,7.05277630661518E-5,7.0609637369167E-7,10.0034456,10.0034456,33108.3203125,33110.84765625,57.139389641333,20.6388403776957,10.760172,0,0,0,40,4449,10.04525,33109.583984375,,,,,,,,,,,,,0,,,,0.00245,,,,,,10.0034456,,,,
,23066644.92,10.001895,28622.0966796875,7.63040472830206E-5,6.22176630117718E-7,1,0.999253354069792,40.0298881530762,1.99758440415021,16.6900008916855,0.000859159917161895,0.000155227701107342,0.25,8.64875087506605E-8,7.60499295122207E-5,5.97161817778033E-7,10.001895,10.001895,28618.314453125,28625.87890625,56.9705578811791,20.6385772191269,10.38052,0,0,0,40,4449,10.0421,28622.0966796875,,,,,,,,,,,,,0,,,,0,,,,,,10.001895,,,,
,23066824.515,10.0012789,24134.1318359375,8.01825196326319E-5,4.07638187377856E-7,1,0.999253354069792,40.0298881530762,1.99766861122169,16.6900008916855,0.000903809700523679,0.000155445416521386,0.25,-5.6503706732987E-7,7.98826834898114E-5,-4.55898716376617E-8,10.0012789,10.0012789,24130.630859375,24137.6328125,56.9799374234099,20.6393536783054,10.760172,0,0,0,40,4449,10.03835,24134.1318359375,,,,,,,,,,,,,0,,,,-0.0049,,,,,,10.0012789,,,,
,23067001.92,10.0012503,19700.3349609375,8.38503404284274E-5,4.40874006685434E-7,1,0.999253354069792,40.0298881530762,1.99770864850949,16.6900008916855,0.000944532820815883,0.000163701436701386,0.25,-4.60107522005655E-7,8.34989228566937E-5,5.98298332117739E-8,10.0012503,10.0012503,19695.30859375,19705.361328125,57.129228470583,20.6410054924275,10.760172,0,0,0,40,4449,10.03615,19700.3349609375,,,,,,,,,,,,,0,,,,0,,,,,,10.0012503,,,,
,23067210.31,10.0013828,14493.3369140625,8.79126061552812E-5,3.55858280723956E-7,1,0.999253354069792,40.0298881530762,1.99775265870903,16.6900008916855,0.000989293580850008,0.000174530269789305,0.25,-1.86385407155581E-7,8.74995327621895E-5,3.26269174207048E-7,10.0013828,10.0013828,14490.4853515625,14496.1884765625,57.2347483206791,20.6397299220985,11.139823,0,0,0,40,4449,10.0341,14493.3369140625,,,,,,,,,,,,,0,,,,-0.0049,,,,,,10.0013828,,,,
,23067387.015,10.0012093,10078.3911132813,9.0614793331685E-5,3.51446398659088E-7,1,0.999253354069792,40.0298881530762,1.99772719662421,16.6900008916855,0.00101935584560146,0.000179513091121632,0.25,-1.90676142840918E-7,9.01547798066479E-5,3.08657670431421E-7,10.0012093,10.0012093,10076.09375,10080.6884765625,57.3723149400638,20.6385088947122,11.139823,0,0,0,40,4449,10.0317,10078.3911132813,,,,,,,,,,,,,0,,,,-0.00245,,,,,,10.0012093,,,,
,23067563.745,10.0025311,5660.41455078125,9.18580882397069E-5,3.39587222039745E-7,1,0.999253354069792,40.0298881530762,1.9978128151949,16.6900008916855,0.00103323055882104,0.000180819846302354,0.25,-2.61492574675312E-7,9.1361325633686E-5,2.15287137490721E-7,10.0025311,10.0025311,5655.45751953125,5665.37158203125,56.9713395096983,20.6389175095711,11.519473,0,0,0,40,4449,10.0287,5660.41455078125,,,,,,,,,,,,,0,,,,0.00245,,,,,,10.0025311,,,,
,23067772.985,10.0074773,431.02326965332,8.6758484427735E-5,3.32695394813683E-7,1,0.999253354069792,40.0298881530762,1.9977498973395,16.6900008916855,0.000975248132446726,0.000172343548645013,0.25,-7.34185489625788E-8,8.62616890734129E-5,3.46628985163048E-7,10.0072298,10.0077248,427.209564208984,434.836975097656,57.5216059872369,20.6380937949659,10.760172,0,0,0,40,4449,10.0168,431.02326965332,,,,,,,,,,,,,0,,,,0,,,,,,10.0074773,,,,
,23067791.68,10.010251,-0.304475486278534,8.32812207981521E-5,3.36262458287648E-7,1,0.999253354069792,40.0298881530762,1.99770959514356,16.6900008916855,0.000935965422337112,0.000166350419839014,0.25,1.27786088764499E-8,8.28027423285537E-5,4.14115138098216E-7,10.010251,10.010251,-0.304475486278534,-0.304475486278534,57.1300100991022,20.6389145885438,11.139823,0,0,0,40,4417,10.0113,-0.304475486278534,,,,,,,,,,,,,0,,,,0.00245,,,,,,10.010251,,,,