File: data/monolayers/nanoparticles/Ol_CoFe_C/vsm/rawdata/DD172_6_HYST_20K.DAT
[Header]
; VSM Data File (default extension .dat)
; Copyright (c) 2003-2013, Quantum Design, Inc. All rights reserved.
TITLE,
FILEOPENTIME,26782233.17,11/07/2018,7:30 am
BYAPP,VSM,2.0,2.0
INFO,PPMS VSM Option Release 1.4.10 Build 1,APPNAME
INFO,Quantum Design Linear Motor Servo Controller,MOTOR_MODULE_NAME
INFO,3101-100 M1,MOTOR_HW_VERSION
INFO,MMC1014,MOTOR_SERIAL_NUMBER
INFO,SRV No X-over 01.03.11,MOTOR_SOFTWARE_VERSION
INFO,Quantum Design VSM Detection Module,VSM_MODULE_NAME
INFO,3101-150 F0,VSM_HW_VERSION
INFO,VSM707,VSM_SERIAL_NUMBER
INFO,VSM No X-over 01.02.05 May 20 2008 13:51:47,VSM_SOFTWARE_VERSION
INFO,704,PREAMP_SERIAL_NUMBER
INFO,822,COIL_SERIAL_NUMBER
INFO,0,MOMENT_UNITS
INFO,CoFe2O4 DD67,SAMPLE_MATERIAL
INFO,Colloidal Crystal,SAMPLE_COMMENT
INFO,31.86,SAMPLE_MASS
INFO,,SAMPLE_VOLUME
INFO,,SAMPLE_MOLECULAR_WEIGHT
INFO,,SAMPLE_SIZE
INFO,,SAMPLE_SHAPE
DATATYPE,COMMENT,1
DATATYPE,TIME,2
STARTUPAXIS,X,2
STARTUPAXIS,Y1,5
[Data]
Comment,Time Stamp (sec),Temperature (K),Magnetic Field (Oe),Moment (emu),M. Std. Err. (emu),Transport Action,Averaging Time (sec),Frequency (Hz),Peak Amplitude (mm),Center Position (mm),Coil Signal' (mV),Coil Signal" (mV),Range (mV),M. Quad. Signal (emu),M. Raw' (emu),M. Raw" (emu),Min. Temperature (K),Max. Temperature (K),Min. Field (Oe),Max. Field (Oe),Mass (grams),Motor Lag (deg),Pressure (Torr),VSM Status (code),Motor Status (code),Measure Status (code),Measure Count,PPMS Status (code),System Temp. (K),System Field (Oe),Sample Position (deg),Bridge 1 Resistance (ohms),Bridge 1 Excitation (에),Bridge 2 Resistance (ohms),Bridge 2 Excitation (에),Bridge 3 Resistance (ohms),Bridge 3 Excitation (에),Bridge 4 Resistance (ohms),Bridge 4 Excitation (에),Signal 1 Vin (V),Signal 2 Vin (V),Digital Inputs (code),Drive 1 Iout (mA),Drive 1 Ipower (W),Drive 2 Iout (mA),Drive 2 Ipower (W),Pressure (),Map 20 (),Map 21 (),Map 22 (),Map 23 (),Map 24 (),Map 25 (),Map 26 (),Map 27 (),Map 28 (),Map 29 ()
,26782248.59,20.0002117,-0.258804142475128,,,2,,,,20.3899998316169,,,,,,,20.0002117,20.0002117,-0.258804142475128,-0.258804142475128,,,12.658426,,,,-99999999,4369,20.0093,-0.258804142475128,,,,,,,,,,,,,,,,,,,,,,,20.0002117,,,,
,26782495.725,19.9973278,4700.4306640625,0.00150422753501858,3.59820892893818E-7,1,0.999253354069792,40.0298881530762,1.9970736912119,20.3799996525049,0.0168863120606558,0.00310723508174817,0.25,8.90727508761955E-6,0.0014959185673307,1.65754990368592E-5,19.9973278,19.9973278,4697.0009765625,4703.8603515625,56.7313795542945,20.5981039329489,13.417728,0,0,0,40,4449,20.00155,4700.4306640625,,,,,,,,,,,,,0,,,,0.0049,,,,,,19.9973278,,,,
,26782700.29,20.001852,9811.203125,0.00190901510012038,4.30027209379519E-7,1,0.999253354069792,40.0298881530762,1.99684974726135,20.3799996525049,0.0214366172967377,0.00394259807344941,0.25,1.04297411501174E-5,0.00189919397255208,2.08781798763308E-5,20.001852,20.001852,9806.234375,9816.171875,56.6844818431406,20.6039319560428,13.797379,0,0,0,40,4449,20.002,9811.203125,,,,,,,,,,,,,0,,,,-0.00245,,,,,,20.001852,,,,
,26782887.15,20.0014858,14480.6181640625,0.00229321712108142,5.3170860633171E-7,1,0.999253354069792,40.0298881530762,1.99666062355483,20.3799996525049,0.0257576634663569,0.00474414931698282,0.25,1.23440294920118E-5,0.00228232797389246,2.56754221593532E-5,20.0014858,20.0014858,14478.08984375,14483.146484375,57.115940785756,20.6004904623605,13.797379,0,0,0,40,4449,19.9984,14480.6181640625,,,,,,,,,,,,,0,,,,0,,,,,,20.0014858,,,,
,26783073.305,20.0015717,19133.69140625,0.002682309338624,5.75094412903931E-7,1,0.999253354069792,40.0298881530762,1.99670111321316,20.3799996525049,0.0301397453338535,0.00556234194732481,0.25,1.4544858226029E-5,0.00267072685077655,3.09947238530444E-5,20.0015717,20.0015717,19131.1171875,19136.265625,57.3770047111791,20.6025022064823,13.797379,0,0,0,40,4449,19.99535,19133.69140625,,,,,,,,,,,,,0,,,,0.00245,,,,,,20.0015717,,,,
,26783262.065,20.000885,23848.5234375,0.00307347579140588,5.7779047635207E-7,1,0.999253354069792,40.0298881530762,1.99606047863568,20.3799996525049,0.0345408900726559,0.00637319237205592,0.25,1.56553099458148E-5,0.00306163571441891,3.54123283293965E-5,20.000885,20.000885,23843.783203125,23853.263671875,56.7939098358329,20.6118226327507,13.797379,0,0,0,40,4449,19.99315,23848.5234375,,,,,,,,,,,,,0,,,,-0.0049,,,,,,20.000885,,,,
,26783449.495,20.0012722,28534.12890625,0.00344751387471219,7.23707242171423E-7,1,0.999253354069792,40.0298881530762,1.99619749643085,20.3799996525049,0.0387639294633953,0.00716279156895385,0.25,1.75854489502412E-5,0.00343588657708878,4.0632615575E-5,20.0012722,20.0012722,28531.873046875,28536.384765625,57.0612267894099,20.6094588453528,13.417728,0,0,0,40,4449,19.9904,28534.12890625,,,,,,,,,,,,,0,,,,0.0049,,,,,,20.0012722,,,,
,26783636.75,20.0019188,33213.017578125,0.00379866367618402,7.73261187639354E-7,1,0.999253354069792,40.0298881530762,1.99633942053238,20.3799996525049,0.0427349423864844,0.00790399663273406,0.25,1.92065227477224E-5,0.00378771527640423,4.54312251436438E-5,20.0019188,20.0019188,33207.0234375,33219.01171875,57.606803495833,20.6105314299366,13.797379,0,0,0,40,4449,19.988,33213.017578125,,,,,,,,,,,,,0,,,,0.00245,,,,,,20.0019188,,,,
,26783826.165,20.0012779,37946.64453125,0.00412160973949197,7.53040502926934E-7,1,0.999253354069792,40.0298881530762,1.99620701218874,20.3799996525049,0.0463876260178945,0.0085844038052006,0.25,2.05310961393655E-5,0.00411179453033431,4.97322753397552E-5,20.0012779,20.0012779,37944.1015625,37949.1875,57.5161345876022,20.6098934970762,14.177031,0,0,0,40,4449,19.9866,37946.64453125,,,,,,,,,,,,,0,,,,-0.0049,,,,,,20.0012779,,,,
,26784013.37,20.0008354,42625.25,0.00441444334106589,8.19200104926086E-7,1,0.999253354069792,40.0298881530762,1.99576298004536,20.3799996525049,0.0496956675153821,0.00920661260993528,0.25,2.22581255779548E-5,0.00440610313816311,5.41517954859502E-5,20.0008354,20.0008354,42623.9609375,42626.5390625,56.9385111118906,20.6154499649916,13.797379,0,0,0,40,4449,19.9845,42625.25,,,,,,,,,,,,,0,,,,-0.0049,,,,,,20.0008354,,,,
,26784198.765,20.0007172,47258.365234375,0.0046768086926078,8.23894821094636E-7,1,0.999253354069792,40.0298881530762,1.99570297582801,20.3799996525049,0.0526733933403013,0.00975679836254918,0.25,2.30035617819304E-5,0.00467022568657601,5.72721072094851E-5,20.0007172,20.0007172,47254.5390625,47262.19140625,56.8025077495445,20.6193268405232,13.797379,0,0,0,40,4449,19.9835,47258.365234375,,,,,,,,,,,,,0,,,,0.00245,,,,,,20.0007172,,,,
,26784389.695,20.0009251,52029.388671875,0.00492013443264258,1.04087611996058E-6,1,0.999253354069792,40.0298881530762,1.99551480362739,20.3799996525049,0.055436227149971,0.0102658836292157,0.25,2.36551016648373E-5,0.00491559182084072,6.00513008922713E-5,20.0009251,20.0009251,52026.8046875,52031.97265625,56.9455457685637,20.6224330917857,13.797379,0,0,0,40,4449,19.98195,52029.388671875,,,,,,,,,,,,,0,,,,0,,,,,,20.0009251,,,,
,26784578.765,20.000246,56753.037109375,0.00513844534231496,7.81888800863911E-7,1,0.999253354069792,40.0298881530762,1.99510800233963,20.3799996525049,0.0579100517146382,0.01073282869209,0.25,2.53016749485492E-5,0.00513607899136342,6.35024190947242E-5,20.000246,20.000246,56749.1796875,56756.89453125,57.454385934583,20.6246896737582,13.797379,0,0,0,40,4449,19.9831,56753.037109375,,,,,,,,,,,,,0,,,,-0.00245,,,,,,20.000246,,,,
,26784766.385,20.0001163,61441.740234375,0.00533453402494818,1.15390598024698E-6,1,0.999253354069792,40.0298881530762,1.99544743001543,20.3799996525049,0.0601530977706634,0.0111672328159438,0.25,2.78544380162564E-5,0.00533442704087918,6.75570567268461E-5,20.0001163,20.0001163,61436.71484375,61446.765625,56.8931766577752,20.6191290266111,13.417728,0,0,0,40,4449,19.98285,61441.740234375,,,,,,,,,,,,,0,,,,-0.00245,,,,,,20.0001163,,,,
,26784956.93,20.0003223,66205.2421875,0.00551505151947393,9.09127006598332E-7,1,0.999253354069792,40.0298881530762,1.99603066180053,20.3799996525049,0.0622291409727239,0.011573240139213,0.25,3.06856862868809E-5,0.00551729851113167,7.16384536028018E-5,20.0003223,20.0003223,66200.2109375,66210.2734375,56.8869236296214,20.6088469378381,13.797379,0,0,0,40,4449,19.9821,66205.2421875,,,,,,,,,,,,,0,,,,0,,,,,,20.0003223,,,,
,26785145.985,20.00121975,70928.95703125,0.00568436535250825,1.23851855013079E-6,1,0.999253354069792,40.0298881530762,1.99557899623919,20.3799996525049,0.0641546674063722,0.0119144509407108,0.25,3.04316874139903E-5,0.00568899590432885,7.24194737034209E-5,20.0010586,20.0013809,70925.3046875,70932.609375,57.166746639506,20.6138698975037,13.797379,0,0,0,40,4449,19.9805,70928.95703125,,,,,,,,,,,,,0,,,,0.00245,,,,,,20.00121975,,,,
,26785337.76,20.0006695,75723.5859375,0.00584201952884689,1.36662689612691E-6,1,0.999253354069792,40.0298881530762,1.99558635672756,20.3799996525049,0.0659578267280398,0.0122610239883919,0.25,3.26495738201242E-5,0.00584904622910686,7.5459975301811E-5,20.0006695,20.0006695,75718.3125,75728.859375,56.9963516223137,20.6134887223516,13.417728,0,0,0,40,4449,19.98015,75723.5859375,,,,,,,,,,,,,0,,,,0,,,,,,20.0006695,,,,
,26785526.59,20.001152,80441.66015625,0.00598482016683329,1.09205538098608E-6,1,0.999253354069792,40.0298881530762,1.9951256539537,20.3799996525049,0.0675826809402795,0.0125452767310692,0.25,3.23925586175355E-5,0.00599419302035301,7.58066800476022E-5,20.001152,20.001152,80439.3515625,80443.96875,56.9111541137176,20.6233832392207,13.797379,0,0,0,40,4449,19.97815,80441.66015625,,,,,,,,,,,,,0,,,,0,,,,,,20.001152,,,,
,26785714.745,20.001255,85144.8515625,0.00611715892746899,1.23010204319856E-6,1,0.999253354069792,40.0298881530762,1.99564881171351,20.3799996525049,0.0691136508481192,0.012853175309655,0.25,3.56915302841143E-5,0.00612879883144584,7.95414316403829E-5,20.001255,20.001255,85139.9296875,85149.7734375,57.1503324406022,20.613404806075,13.797379,0,0,0,40,4449,19.97765,85144.8515625,,,,,,,,,,,,,0,,,,0,,,,,,20.001255,,,,
,26785891.67,20.0008602,89566.24609375,0.00623331297523757,1.15344242855256E-6,1,0.999253354069792,40.0298881530762,1.99489485449012,20.3799996525049,0.0704275081501407,0.0130639951111902,0.25,3.40906889766457E-5,0.00624706369945209,7.82016711911832E-5,20.0008602,20.0008602,89562.65625,89569.8359375,57.3644986548715,20.6281845594823,13.797379,0,0,0,40,4449,19.9765,89566.24609375,,,,,,,,,,,,,0,,,,0,,,,,,20.0008602,,,,
,26786085.995,20.00058365,86053.9296875,0.00616850379191056,1.55445410026104E-6,1,0.999253354069792,40.0298881530762,1.99486798713543,20.3799996525049,0.0696668904811708,0.0129861192358005,0.25,3.86791132082725E-5,0.00618061249548531,8.27915548314274E-5,20.0005455,20.0006218,86050.140625,86057.71875,56.9244417985445,20.6317128023884,13.417728,0,0,0,40,4449,19.97565,86053.9296875,,,,,,,,,,,,,0,,,,-0.0049,,,,,,20.00058365,,,,
,26786269.275,19.9999065,81472.68359375,0.00606332890733145,1.13086700010945E-6,1,0.999253354069792,40.0298881530762,1.99524651127001,20.3799996525049,0.0684668564344777,0.0127756336495853,0.25,3.86008837248232E-5,0.00607324537516639,8.24854440666315E-5,19.9999065,19.9999065,81468.875,81476.4921875,56.7470121246791,20.6225654216953,13.797379,0,0,0,40,4449,19.97695,81472.68359375,,,,,,,,,,,,,0,,,,0.0049,,,,,,19.9999065,,,,
,26786457.65,19.9997978,76762.91015625,0.00594615971630998,1.15154706017886E-6,1,0.999253354069792,40.0298881530762,1.99559085610803,20.3799996525049,0.0671356115179175,0.0125005682880443,0.25,3.50906240746336E-5,0.00595378321020591,7.85775795577371E-5,19.9997978,19.9997978,76758.0703125,76767.75,57.3879475104484,20.6186437847326,13.797379,0,0,0,40,4449,19.978,76762.91015625,,,,,,,,,,,,,0,,,,-0.0049,,,,,,19.9997978,,,,
,26786647.125,19.9990005,72028.359375,0.0058229388983723,1.08222863230127E-6,1,0.999253354069792,40.0298881530762,1.99592010478226,20.3799996525049,0.0657308646013166,0.012232883797954,0.25,3.34510582960749E-5,0.00582819752626515,7.63953463931161E-5,19.9990005,19.9990005,72022.046875,72034.671875,57.1479875550445,20.6120640662282,13.797379,0,0,0,40,4449,19.9793,72028.359375,,,,,,,,,,,,,0,,,,0.00245,,,,,,19.9990005,,,,
,26786834.63,19.9992733,67341.58203125,0.00569309782254044,9.56570304293474E-7,1,0.999253354069792,40.0298881530762,1.99613303436155,20.3799996525049,0.0642497535406293,0.0119370111764664,0.25,3.06968306405325E-5,0.005695991059627,7.29286208778657E-5,19.9992733,19.9992733,67336.609375,67346.5546875,57.2472543769868,20.6074257259051,13.417728,0,0,0,40,4449,19.98035,67341.58203125,,,,,,,,,,,,,0,,,,-0.0049,,,,,,19.9992733,,,,
,26787023.77,19.9984932,62614.953125,0.00555308944419798,8.91667487972496E-7,1,0.999253354069792,40.0298881530762,1.99626626468363,20.3799996525049,0.0626489136798516,0.0116301670598623,0.25,2.89792086809753E-5,0.00555357689085687,7.02976415100046E-5,19.9983559,19.9986305,62611.24609375,62618.66015625,57.1948852661984,20.606260178286,13.417728,0,0,0,40,4449,19.98195,62614.953125,,,,,,,,,,,,,0,,,,-0.0049,,,,,,19.9984932,,,,
,26787212.32,19.9996777,57901.486328125,0.00539877250736845,7.93721800128304E-7,1,0.999253354069792,40.0298881530762,1.99632354768204,20.3799996525049,0.0608835715630397,0.0112979608098953,0.25,2.77693487406845E-5,0.00539687200715667,6.79294603247295E-5,19.9996777,19.9996777,57897.90625,57905.06640625,56.9557069393137,20.6069871429463,13.797379,0,0,0,40,4449,19.9834,57901.486328125,,,,,,,,,,,,,0,,,,0,,,,,,19.9996777,,,,
,26787401.175,20.0003948,53182.83203125,0.0052357570183282,8.03270715033897E-7,1,0.999253354069792,40.0298881530762,1.99642598930726,20.3799996525049,0.0590173488434676,0.0109723933698249,0.25,2.88351924374735E-5,0.00523149657914735,6.76254588534657E-5,20.0003948,20.0003948,53182.83203125,53182.83203125,57.0315249056791,20.607087837942,13.797379,0,0,0,40,4449,19.98405,53182.83203125,,,,,,,,,,,,,0,,,,0,,,,,,20.0003948,,,,
,26787586.555,20.0002508,48549.025390625,0.00505747197278578,8.93210674615342E-7,1,0.999253354069792,40.0298881530762,1.9965044084296,20.3799996525049,0.0569890422042922,0.0105620543874733,0.25,2.52737280318811E-5,0.00505101859150364,6.24440567343179E-5,19.9999828,20.0005188,48532.76171875,48565.2890625,57.4160861371407,20.606851995639,13.417728,0,0,0,40,4449,19.9853,48549.025390625,,,,,,,,,,,,,0,,,,-0.00245,,,,,,20.0002508,,,,
,26787774.145,20.0002327,43861.291015625,0.00486410706140745,8.0224302910137E-7,1,0.999253354069792,40.0298881530762,1.99645710363189,20.3799996525049,0.054781742657691,0.0101563071477532,0.25,2.50227231647028E-5,0.00485554188545662,6.03138842669743E-5,20.0002327,20.0002327,43859.90234375,43862.6796875,57.1456426694868,20.6061965171365,13.797379,0,0,0,40,4449,19.9848,43861.291015625,,,,,,,,,,,,,0,,,,0,,,,,,20.0002327,,,,
,26787964.91,19.9992599,39093.6171875,0.0046500153842134,7.44742546105765E-7,1,0.999253354069792,40.0298881530762,1.99659303613053,20.3799996525049,0.0523522852080998,0.00967922742406199,0.25,2.22220216991884E-5,0.0046395118273809,5.53450371687106E-5,19.9992599,19.9992599,39092.375,39094.859375,57.0737328457176,20.6069190076151,13.797379,0,0,0,40,4449,19.9855,39093.6171875,,,,,,,,,,,,,0,,,,-0.0049,,,,,,19.9992599,,,,
,26788152.925,19.9994125,34396.869140625,0.00441426770180194,6.63637194262685E-7,1,0.999253354069792,40.0298881530762,1.99661167160541,20.3799996525049,0.0496729129363089,0.00918878332650806,0.25,2.22446019983593E-5,0.00440209711296088,5.2935889276402E-5,19.9994125,19.9994125,34393.05078125,34400.6875,57.4926857320253,20.6089729085765,13.797379,0,0,0,40,4449,19.98655,34396.869140625,,,,,,,,,,,,,0,,,,0,,,,,,19.9994125,,,,
,26788338.49,19.9992085,29759.2041015625,0.00415959793193475,7.58913330413657E-7,1,0.999253354069792,40.0298881530762,1.99660064851896,20.3799996525049,0.0467841885227201,0.00865313105340313,0.25,2.1688311113173E-5,0.0041460963824912,4.9747803509795E-5,19.9992085,19.9992085,29755.337890625,29763.0703125,57.3926372815638,20.6082969466622,14.177031,0,0,0,40,4449,19.98845,29759.2041015625,,,,,,,,,,,,,0,,,,-0.00245,,,,,,19.9992085,,,,
,26788525.175,19.99930575,25095.3623046875,0.00387593449950205,6.63869702982391E-7,1,0.999253354069792,40.0298881530762,1.9966609585923,20.3799996525049,0.0435782322534288,0.0080351352556326,0.25,1.89911039137995E-5,0.00386149669374967,4.41881485526011E-5,19.9991665,19.999445,25092.796875,25097.927734375,57.2456911199484,20.6076607737029,13.417728,0,0,0,40,4449,19.9889,25095.3623046875,,,,,,,,,,,,,0,,,,0,,,,,,19.99930575,,,,
,26788712.235,19.9994946,20420.2119140625,0.003559798167458,5.89636946235392E-7,1,0.999253354069792,40.0298881530762,1.99658663427034,20.3799996525049,0.0400030536099377,0.00737918732176477,0.25,1.87132801717003E-5,0.00354487192438101,4.08442026648986E-5,19.9994946,19.9994946,20417.705078125,20422.71875,57.352774227083,20.6074412794093,13.797379,0,0,0,40,4449,19.9899,20420.2119140625,,,,,,,,,,,,,0,,,,0,,,,,,19.9994946,,,,
,26788899.85,19.9987793,15731.7099609375,0.00320461515797858,4.90210850029868E-7,1,0.999253354069792,40.0298881530762,1.99659281952519,20.3799996525049,0.0359961234055763,0.00663790805481839,0.25,1.7658754259138E-5,0.00318975654532059,3.65692552894718E-5,19.9987793,19.9987793,15727.9208984375,15735.4990234375,57.1573670972753,20.6086811244615,13.797379,0,0,0,40,4449,19.9925,15731.7099609375,,,,,,,,,,,,,0,,,,0.0049,,,,,,19.9987793,,,,
,26789088.375,19.9991913,11022.0561523438,0.0028058495698885,4.91618045874975E-7,1,0.999253354069792,40.0298881530762,1.99653492950483,20.3799996525049,0.031505255654048,0.0057969652884368,0.25,1.53015188816311E-5,0.00279169084321393,3.09085555048159E-5,19.9991913,19.9991913,11018.3017578125,11025.810546875,57.1769078102561,20.6105613296615,14.177031,0,0,0,40,4449,19.99375,11022.0561523438,,,,,,,,,,,,,0,,,,0.0049,,,,,,19.9991913,,,,
,26789273.695,19.9998875,6389.04345703125,0.00237018447576634,4.36446129066249E-7,1,0.999253354069792,40.0298881530762,1.99660428560747,20.3799996525049,0.0266048205806413,0.00489438343181558,0.25,1.36508073251555E-5,0.00235737018444433,2.60225972993789E-5,19.9998875,19.9998875,6385.3876953125,6392.69921875,57.3777863396984,20.6085939383019,13.797379,0,0,0,40,4449,19.9949,6389.04345703125,,,,,,,,,,,,,0,,,,0,,,,,,19.9998875,,,,
,26789461.215,20.0001278,1701.48187255859,0.00187655761886446,4.50848035412194E-7,1,0.999253354069792,40.0298881530762,1.99674862020712,20.3799996525049,0.021059435991566,0.00387217065892061,0.25,1.12300349232826E-5,0.00186585182549801,2.04210756579723E-5,20.0001278,20.0001278,1697.763671875,1705.20007324219,57.3355783996599,20.6089368495207,13.797379,0,0,0,40,4449,19.99485,1701.48187255859,,,,,,,,,,,,,0,,,,0,,,,,,20.0001278,,,,
,26789649.53,19.9997444,-3000.0419921875,0.00131678311577466,4.25292205115941E-7,1,0.999253354069792,40.0298881530762,1.99679897152025,20.3799996525049,0.0147798536253869,0.00271194056664304,0.25,7.28808258081416E-6,0.0013093703867111,1.38496173067667E-5,19.9997444,19.9997444,-3004.88549804687,-2995.19848632812,57.2386564632753,20.608629249952,13.797379,0,0,0,40,4449,19.99445,-3000.0419921875,,,,,,,,,,,,,0,,,,0,,,,,,19.9997444,,,,
,26789835.705,19.9994526,-7653.70043945313,0.000696100977247494,3.48613276191919E-7,1,0.999253354069792,40.0298881530762,1.99680211558831,20.3799996525049,0.00781534539394295,0.00143609059722809,0.25,3.80136569452935E-6,0.000692403189834744,7.50039606816333E-6,19.9994526,19.9994526,-7656.29833984375,-7651.1025390625,57.4528226775445,20.6089954845592,13.797379,0,0,0,40,4449,19.9954,-7653.70043945313,,,,,,,,,,,,,0,,,,-0.00245,,,,,,19.9994526,,,,
,26790027.055,20.0005703,-12436.7592773437,-1.2007744511826E-5,4.14330156534275E-7,1,0.999253354069792,40.0298881530762,1.99689187931939,20.3799996525049,-0.000134217722924006,-2.84545893368365E-5,0.25,-3.87938282937133E-7,-1.19467439862428E-5,-4.54393139980711E-7,20.0005703,20.0005703,-12441.7509765625,-12431.767578125,57.3191642007561,20.6088089530619,13.797379,0,0,0,40,4449,19.9943,-12436.7592773437,,,,,,,,,,,,,0,,,,-0.0049,,,,,,20.0005703,,,,
,26790214.14,20.0007458,-17111.5087890625,-0.000767220898067043,4.80271447981367E-7,1,0.999253354069792,40.0298881530762,1.99686245825843,20.3799996525049,-0.00861945019651389,-0.00159318877650013,0.25,-4.47448481729731E-6,-0.000763759541288943,-9.0740333899898E-6,20.0007458,20.0007458,-17114.1953125,-17108.822265625,57.1604936113522,20.6093822092181,13.797379,0,0,0,40,4449,19.9933,-17111.5087890625,,,,,,,,,,,,,0,,,,-0.0049,,,,,,20.0007458,,,,
,26790401.81,20.0011539,-21801.4189453125,-0.00153795882270974,5.16128195901609E-7,1,0.999253354069792,40.0298881530762,1.99679783163393,20.3799996525049,-0.0172849346695984,-0.00319946363687415,0.25,-8.89819608976014E-6,-0.00153171327091129,-1.85901520987149E-5,20.0011539,20.0011539,-21803.806640625,-21799.03125,57.180034324333,20.6102622984507,13.797379,0,0,0,40,4449,19.9915,-21801.4189453125,,,,,,,,,,,,,0,,,,0,,,,,,20.0011539,,,,
,26790591.78,20.0004787,-26547.564453125,-0.00229305046617915,5.22558758424419E-7,1,0.999253354069792,40.0298881530762,1.9967412313523,20.3799996525049,-0.0257827924608375,-0.00477391686001543,0.25,-1.27721176082396E-5,-0.00228483913513206,-2.78583008238373E-5,20.0004787,20.0004787,-26551.279296875,-26543.849609375,57.2964969736984,20.6108219359024,13.417728,0,0,0,40,4449,19.9899,-26547.564453125,,,,,,,,,,,,,0,,,,0,,,,,,20.0004787,,,,
,26790783.22,20.0007458,-31332.87109375,-0.00296644692163053,7.23095869189112E-7,1,0.999253354069792,40.0298881530762,1.99662183809937,20.3799996525049,-0.033368691901477,-0.00618134360075852,0.25,-1.60701632337795E-5,-0.00295730284457156,-3.62998704497994E-5,20.0007458,20.0007458,-31334.01953125,-31331.72265625,57.1346998702176,20.6109537343804,13.797379,0,0,0,40,4449,19.9884,-31332.87109375,,,,,,,,,,,,,0,,,,0,,,,,,20.0007458,,,,
,26790969.14,20.0009689,-35978.615234375,-0.00352416147736263,7.70027628043905E-7,1,0.999253354069792,40.0298881530762,1.99683869376185,20.3799996525049,-0.0396684476119089,-0.00733373519878844,0.25,-1.7173673820839E-5,-0.00351503842614832,-4.18948984273973E-5,20.0009689,20.0009689,-35983.7578125,-35973.47265625,57.1440794124484,20.6115919177127,13.797379,0,0,0,40,4449,19.9878,-35978.615234375,,,,,,,,,,,,,0,,,,0,,,,,,20.0009689,,,,
,26791159.5,20.0001316,-40734.830078125,-0.00400006021291294,5.89087624314168E-7,1,0.999253354069792,40.0298881530762,1.99655971023378,20.3799996525049,-0.045039602685754,-0.00834016668591282,0.25,-2.00357523174567E-5,-0.00399171019409454,-4.87276884419591E-5,20.0001316,20.0001316,-40735.87890625,-40733.78125,57.4098331089868,20.6160084345488,14.177031,0,0,0,40,4449,19.98635,-40734.830078125,,,,,,,,,,,,,0,,,,0.00245,,,,,,20.0001316,,,,
,26791350.04,20.00033,-45496.5234375,-0.00439202648115827,7.55453034053309E-7,1,0.999253354069792,40.0298881530762,1.99668297605252,20.3799996525049,-0.049479653079994,-0.00916806132515683,0.25,-2.19901158108901E-5,-0.00438504336681412,-5.40187262041001E-5,20.00033,20.00033,-45498.89453125,-45494.15234375,57.5309855294676,20.6133638867904,14.177031,0,0,0,40,4449,19.985,-45496.5234375,,,,,,,,,,,,,0,,,,0,,,,,,20.00033,,,,
,26791541.53,20.0008411,-50281.09375,-0.00472165831197095,8.88309183546094E-7,1,0.999253354069792,40.0298881530762,1.99664371225313,20.3799996525049,-0.0532188732031844,-0.00985782406820755,0.25,-2.30124473708968E-5,-0.00471646782139297,-5.78379324520307E-5,20.0008411,20.0008411,-50285.99609375,-50276.19140625,57.5348936720638,20.6141093179297,14.177031,0,0,0,40,4449,19.98445,-50281.09375,,,,,,,,,,,,,0,,,,0,,,,,,20.0008411,,,,
,26791735.285,19.9992256,-55123.0234375,-0.00500440043662518,7.65762793331587E-7,1,0.999253354069792,40.0298881530762,1.99667691586654,20.3799996525049,-0.0564295389825079,-0.0104769861418707,0.25,-2.62690437816973E-5,-0.00500129267853963,-6.34255525421782E-5,19.9992256,19.9992256,-55125.4296875,-55120.6171875,57.3441763133715,20.6126197691745,13.417728,0,0,0,40,4449,19.9846,-55123.0234375,,,,,,,,,,,,,0,,,,0,,,,,,19.9992256,,,,
,26791925.75,20.0000057,-59882.720703125,-0.00524365266964301,1.02106645322517E-6,1,0.999253354069792,40.0298881530762,1.99672257770331,20.3799996525049,-0.059159960875551,-0.010958906354843,0.25,-2.53168592713658E-5,-0.00524280190496007,-6.4344141726596E-5,20.0000057,20.0000057,-59885.34375,-59880.09765625,57.2269320354868,20.6138976347632,14.177031,0,0,0,40,4449,19.9841,-59882.720703125,,,,,,,,,,,,,0,,,,-0.0049,,,,,,20.0000057,,,,
,26792118.035,20.000246,-64687.98828125,-0.00545505405146579,1.20839213802209E-6,1,0.999253354069792,40.0298881530762,1.99669164068621,20.3799996525049,-0.0615765030055413,-0.0113763029055489,0.25,-2.38270359564029E-5,-0.00545659016075648,-6.43757998080737E-5,20.000246,20.000246,-64690.7109375,-64685.265625,57.5724118409869,20.6139665938795,13.417728,0,0,0,40,4449,19.9831,-64687.98828125,,,,,,,,,,,,,0,,,,-0.00245,,,,,,20.000246,,,,
,26792311.97,20.0007095,-69533.265625,-0.00564258528559587,1.19339117749986E-6,1,0.999253354069792,40.0298881530762,1.99675758537169,20.3799996525049,-0.0637100488567129,-0.0118404670831332,0.25,-3.08580476651864E-5,-0.00564651320984103,-7.26145670197853E-5,20.0006828,20.0007362,-69534.484375,-69532.046875,57.7076335748138,20.6143238001747,13.797379,0,0,0,40,4449,19.98145,-69533.265625,,,,,,,,,,,,,0,,,,-0.00245,,,,,,20.0007095,,,,
,26792498.445,20.00022315,-74193.078125,-0.0058106214560253,9.64158009927824E-7,1,0.999253354069792,40.0298881530762,1.99670902267388,20.3799996525049,-0.0656278766499049,-0.0122151377773112,0.25,-3.36671879781686E-5,-0.00581689241773676,-7.6368881273764E-5,20.0001564,20.0002899,-74199.359375,-74186.796875,57.3988903097176,20.6140878007946,13.417728,0,0,0,40,4449,19.98015,-74193.078125,,,,,,,,,,,,,0,,,,0.0049,,,,,,20.00022315,,,,
,26792688.32,20.0000916,-78936.21875,-0.00595870367220553,1.10370822223899E-6,1,0.999253354069792,40.0298881530762,1.99671878720007,20.3799996525049,-0.0673277927973887,-0.0125189527983528,0.25,-3.38892978828207E-5,-0.00596734921814341,-7.72658408558253E-5,20.0000916,20.0000916,-78938.6484375,-78933.7890625,57.2535074051407,20.6150075525841,13.417728,0,0,0,40,4449,19.9776,-78936.21875,,,,,,,,,,,,,0,,,,0,,,,,,20.0000916,,,,
,26792876.66,20.0011787,-83642.5390625,-0.00609575393368018,1.15336892465837E-6,1,0.999253354069792,40.0298881530762,1.99679379766103,20.3799996525049,-0.0689017461385215,-0.0128165480617295,0.25,-3.5620540324742E-5,-0.00610670490111473,-7.94929671311941E-5,20.0011787,20.0011787,-83646.359375,-83638.71875,57.3809128537753,20.6140937438842,13.797379,0,0,0,40,4449,19.9761,-83642.5390625,,,,,,,,,,,,,0,,,,0,,,,,,20.0011787,,,,
,26793057.145,19.9998779,-88153.171875,-0.00621707832027585,1.13400932554449E-6,1,0.999253354069792,40.0298881530762,1.99688174691583,20.3799996525049,-0.0702941362110583,-0.013097466148134,0.25,-3.87851725531201E-5,-0.00623017418223274,-8.29779597790521E-5,19.9998779,19.9998779,-88158.25,-88148.09375,57.4379717356792,20.6162361605586,13.417728,0,0,0,40,4449,19.9747,-88153.171875,,,,,,,,,,,,,0,,,,0.00245,,,,,,19.9998779,,,,
,26793253.93,20.000042,-87428.6328125,-0.00621916895986802,1.44018709465929E-6,1,0.999253354069792,40.0298881530762,1.9968289414283,20.3799996525049,-0.0703174682692724,-0.0130736774173706,0.25,-3.62957351850892E-5,-0.00623198244340623,-8.05915233060932E-5,20.000042,20.000042,-87429.96875,-87427.296875,57.3856026248907,20.6155891989625,13.797379,0,0,0,40,4449,19.9746,-87428.6328125,,,,,,,,,,,,,0,,,,-0.0049,,,,,,20.000042,,,,
,26793432.53,19.9998589,-82967.70703125,-0.00611888941290817,1.06403584242474E-6,1,0.999253354069792,40.0298881530762,1.99697743461266,20.3799996525049,-0.0691648680622808,-0.0128719083849067,0.25,-3.62236735762049E-5,-0.00612958225423701,-8.03404843668973E-5,19.9998589,19.9998589,-82973.015625,-82962.3984375,57.5911709254484,20.6109151345163,13.417728,0,0,0,40,4449,19.9748,-82967.70703125,,,,,,,,,,,,,0,,,,0,,,,,,19.9998589,,,,
,26793622.59,19.9994087,-78217.65234375,-0.00600578607023714,8.4064397804559E-7,1,0.999253354069792,40.0298881530762,1.99692316532385,20.3799996525049,-0.0678648213878711,-0.0126066404351461,0.25,-3.30432028412423E-5,-0.00601417889545763,-7.68297289797324E-5,19.9994087,19.9994087,-78222.6796875,-78212.625,57.4199942797368,20.6096023664914,13.417728,0,0,0,40,4449,19.97645,-78217.65234375,,,,,,,,,,,,,0,,,,0.00245,,,,,,19.9994087,,,,
,26793813.51,19.9984379,-73446.9453125,-0.00588542493073761,1.17928635185087E-6,1,0.999253354069792,40.0298881530762,1.99692426119069,20.3799996525049,-0.0664775424382351,-0.012362021626575,0.25,-3.3076766740321E-5,-0.0058914290630325,-7.63826025369618E-5,19.9984379,19.9984379,-73450.671875,-73443.21875,57.5731934695061,20.6102592661726,13.797379,0,0,0,40,4449,19.9781,-73446.9453125,,,,,,,,,,,,,0,,,,0.00245,,,,,,19.9984379,,,,
,26794003.99,19.9992485,-68687.6171875,-0.00575893195307377,9.99629524100559E-7,1,0.999253354069792,40.0298881530762,1.99701751360069,20.3799996525049,-0.0650288541557921,-0.012075515241566,0.25,-3.05858735326674E-5,-0.00576253178390895,-7.32454884453963E-5,19.9991798,19.9993172,-68691.4140625,-68683.8203125,57.5145713305638,20.6107274917745,14.177031,0,0,0,40,4449,19.97895,-68687.6171875,,,,,,,,,,,,,0,,,,0.00245,,,,,,19.9992485,,,,
,26794196.065,20.0002232,-63887.958984375,-0.00561625619856318,1.0246512542431E-6,1,0.999253354069792,40.0298881530762,1.99706167780904,20.3799996525049,-0.0633922372549915,-0.0117723464706861,0.25,-2.96972466484349E-5,-0.00561739541553746,-7.14643117798278E-5,20.0002232,20.0002232,-63891.8046875,-63884.11328125,57.3699700545061,20.6121145051153,13.797379,0,0,0,40,4449,19.98095,-63887.958984375,,,,,,,,,,,,,0,,,,-0.0049,,,,,,20.0002232,,,,
,26794386.06,19.9991131,-59140.28515625,-0.00546911602231799,1.05373473365385E-6,1,0.999253354069792,40.0298881530762,1.99702083209648,20.3799996525049,-0.0617048175577875,-0.0114495351586778,0.25,-2.80522038548333E-5,-0.00546783434279053,-6.87522649840894E-5,19.9991131,19.9991131,-59144.0078125,-59136.5625,57.4997203886984,20.6114955824753,13.797379,0,0,0,40,4449,19.9826,-59140.28515625,,,,,,,,,,,,,0,,,,-0.00245,,,,,,19.9991131,,,,
,26794575.375,20.00002005,-54409.630859375,-0.0053106801655969,8.45279503592426E-7,1,0.999253354069792,40.0298881530762,1.99700874052792,20.3799996525049,-0.0598862603333545,-0.0111313589983806,0.25,-2.89783199767497E-5,-0.00530700307350006,-6.83804029950533E-5,20.0000153,20.0000248,-54414.93359375,-54404.328125,57.3433946848522,20.6122637041418,13.797379,0,0,0,40,4449,19.98305,-54409.630859375,,,,,,,,,,,,,0,,,,-0.0049,,,,,,20.00002005,,,,
,26794761.21,20.0010586,-49766.5234375,-0.00513835401411633,8.12553911040624E-7,1,0.999253354069792,40.0298881530762,1.99705066888756,20.3799996525049,-0.0579222467238275,-0.0107378824260836,0.25,-2.58358439379028E-5,-0.00513243212581573,-6.36966779430774E-5,20.0010586,20.0010586,-49767.77734375,-49765.26953125,57.3277621144676,20.6089428601952,13.797379,0,0,0,40,4449,19.9837,-49766.5234375,,,,,,,,,,,,,0,,,,0,,,,,,20.0010586,,,,
,26794950.58,19.9993324,-45035.349609375,-0.00495045705904854,5.94075568758001E-7,1,0.999253354069792,40.0298881530762,1.99709375286658,20.3799996525049,-0.0557805974931526,-0.010326911745959,0.25,-2.40902949154466E-5,-0.00494235438048577,-6.01431721860475E-5,19.9993324,19.9993324,-45040.32421875,-45030.375,57.3082214014868,20.6095577629083,13.797379,0,0,0,40,4449,19.9838,-45035.349609375,,,,,,,,,,,,,0,,,,-0.00245,,,,,,19.9993324,,,,
,26795136.065,19.9995346,-40400.017578125,-0.00474786643416215,8.57169677341316E-7,1,0.999253354069792,40.0298881530762,1.99680793218091,20.3799996525049,-0.0534655833708146,-0.00989220903677655,0.25,-2.31195745111148E-5,-0.00473779266616817,-5.71299748655693E-5,19.9995346,19.9995346,-40405.0625,-40394.97265625,57.3301070000253,20.610653962675,14.177031,0,0,0,40,4449,19.9843,-40400.017578125,,,,,,,,,,,,,0,,,,-0.00245,,,,,,19.9995346,,,,
,26795326.15,19.9995537,-35648.5859375,-0.0045171998181444,7.96854036418475E-7,1,0.999253354069792,40.0298881530762,1.99639230191267,20.3799996525049,-0.0508327760091001,-0.00940242696632224,0.25,-2.24695224278473E-5,-0.00450534503175109,-5.40990741307918E-5,19.9995537,19.9995537,-35652.3125,-35644.859375,56.8306463762368,20.6178798629548,13.797379,0,0,0,40,4449,19.985,-35648.5859375,,,,,,,,,,,,,0,,,,0,,,,,,19.9995537,,,,
,26795515.25,19.9993629,-30924.01171875,-0.00426712507269675,7.35699262866229E-7,1,0.999253354069792,40.0298881530762,1.99623939083495,20.3799996525049,-0.0479910721813872,-0.0088769316812175,0.25,-2.20673789732009E-5,-0.00425379568249516,-5.10895403505817E-5,19.9993629,19.9993629,-30925.2734375,-30922.75,57.2558522906984,20.6188072588677,13.797379,0,0,0,40,4449,19.98675,-30924.01171875,,,,,,,,,,,,,0,,,,-0.0049,,,,,,19.9993629,,,,
,26795701.44,19.9991245,-26270.5556640625,-0.00399321780165509,6.72677392165786E-7,1,0.999253354069792,40.0298881530762,1.99612081677769,20.3799996525049,-0.0448873262414257,-0.00829602258234856,0.25,-2.0987528370137E-5,-0.00397881290125314,-4.72033307461881E-5,19.9991245,19.9991245,-26275.48828125,-26265.623046875,56.9002113144483,20.620974399541,13.797379,0,0,0,40,4449,19.98795,-26270.5556640625,,,,,,,,,,,,,0,,,,0,,,,,,19.9991245,,,,
,26795886.18,19.9992733,-21654.28125,-0.00368756503227958,5.72547021665711E-7,1,0.999253354069792,40.0298881530762,1.99584599764866,20.3799996525049,-0.0414279657814097,-0.00764916900407609,0.25,-1.9715875361996E-5,-0.00367254661085911,-4.29269854358431E-5,19.9992733,19.9992733,-21658.1640625,-21650.3984375,57.3644986548715,20.6251169002239,13.797379,0,0,0,40,4449,19.9887,-21654.28125,,,,,,,,,,,,,0,,,,-0.00245,,,,,,19.9992733,,,,
,26796073.555,19.9990807,-16971.8798828125,-0.00333862702870996,5.22213757656795E-7,1,0.999253354069792,40.0298881530762,1.99574342857869,20.3799996525049,-0.0374901054518964,-0.00691573662307025,0.25,-1.83141269363812E-5,-0.00332352815151153,-3.8302596203806E-5,19.9990807,19.9990807,-16975.806640625,-16967.953125,56.8877052581406,20.62615389331,13.797379,0,0,0,40,4449,19.991,-16971.8798828125,,,,,,,,,,,,,0,,,,-0.0049,,,,,,19.9990807,,,,
,26796261.16,19.9993343,-12284.5615234375,-0.00294918504601008,4.74205436058836E-7,1,0.999253354069792,40.0298881530762,1.99547740489209,20.3799996525049,-0.0330985427679915,-0.00610715809941377,0.25,-1.72803625622308E-5,-0.00293460856394929,-3.39512558593563E-5,19.9993343,19.9993343,-12285.7421875,-12283.380859375,57.2761746321984,20.6288789939307,13.797379,0,0,0,40,4449,19.9925,-12284.5615234375,,,,,,,,,,,,,0,,,,-0.00245,,,,,,19.9993343,,,,
,26796448.315,19.9994774,-7607.68359375,-0.00250809905282549,2.88442545822727E-7,1,0.999253354069792,40.0298881530762,1.99595551195207,20.3799996525049,-0.0281471560117654,-0.00517541861134089,0.25,-1.39898247158085E-5,-0.00249476540026264,-2.73075869983161E-5,19.9994774,19.9994774,-7612.77392578125,-7602.59326171875,57.068261446083,20.6224528777368,13.797379,0,0,0,40,4449,19.99415,-7607.68359375,,,,,,,,,,,,,0,,,,0.00245,,,,,,19.9994774,,,,
,26796633.845,19.9996738,-2969.701171875,-0.00201765918818899,3.99025551214361E-7,1,0.999253354069792,40.0298881530762,1.99618789805761,20.3799996525049,-0.0226384132608193,-0.0041629954489451,0.25,-1.19555512600565E-5,-0.00200629330118378,-2.20010525841288E-5,19.9996738,19.9996738,-2972.21362304687,-2967.18872070313,57.0432493334676,20.617288693204,13.797379,0,0,0,40,4449,19.9938,-2969.701171875,,,,,,,,,,,,,0,,,,0,,,,,,19.9996738,,,,
,26796816.875,19.9998627,1602.0888671875,-0.00146456890874068,4.07874710866968E-7,1,0.999253354069792,40.0298881530762,1.99565446892033,20.3799996525049,-0.0164270103944928,-0.00302186430966078,0.25,-8.89849228373382E-6,-0.00145620517860533,-1.60621276067456E-5,19.9998627,19.9998627,1596.88342285156,1607.29431152344,57.0924919301791,20.6277917743004,13.797379,0,0,0,40,4449,19.993,1602.0888671875,,,,,,,,,,,,,0,,,,-0.00245,,,,,,19.9998627,,,,
,26797003.14,19.9993763,6258.10424804687,-0.000843392184835357,4.21332762954363E-7,1,0.999253354069792,40.0298881530762,1.99587929320178,20.3799996525049,-0.00946286806909921,-0.00174467949979273,0.25,-5.19585385936501E-6,-0.000838822759039428,-9.58829707344036E-6,19.9993763,19.9993763,6256.99853515625,6259.2099609375,56.9674313671022,20.6211372626129,13.797379,0,0,0,40,4449,19.9943,6258.10424804687,,,,,,,,,,,,,0,,,,0,,,,,,19.9993763,,,,
,26797190.405,19.9997807,10938.0043945312,-0.000150406710072643,4.51033661547244E-7,1,0.999253354069792,40.0298881530762,1.99610725943784,20.3799996525049,-0.00168885801074009,-0.000308517586577231,0.25,-6.28818212957403E-7,-0.000149647763176748,-1.46546328876894E-6,19.9997807,19.9997807,10933.27734375,10942.7314453125,56.821266834006,20.6167044548726,13.797379,0,0,0,40,4449,19.9947,10938.0043945312,,,,,,,,,,,,,0,,,,0.00245,,,,,,19.9997807,,,,
,26797379.89,20.0011978,15672.4619140625,0.000614365217172489,4.68386105227853E-7,1,0.999253354069792,40.0298881530762,1.99630930123243,20.3799996525049,0.00690086547760925,0.00126720649984664,0.25,2.92671179288833E-6,0.000611516040776906,6.55166666400357E-6,20.0011005,20.0012951,15670.3837890625,15674.5400390625,57.2566339192176,20.612101198392,13.797379,0,0,0,40,4449,19.9932,15672.4619140625,,,,,,,,,,,,,0,,,,0,,,,,,20.0011978,,,,
,26797571.385,20.0012894,20458.4384765625,0.00141670297299513,5.232074348521E-7,1,0.999253354069792,40.0298881530762,1.99579015864844,20.3799996525049,0.0159149122254642,0.00293122261379959,0.25,7.05382444606821E-6,0.00141077047760331,1.58664511905184E-5,20.0012894,20.0012894,20454.767578125,20462.109375,57.1346998702176,20.6232282367556,13.797379,0,0,0,40,4449,19.991,20458.4384765625,,,,,,,,,,,,,0,,,,0,,,,,,20.0012894,,,,
,26797763.075,20.0006523,25247.529296875,0.00218670575032887,5.44404144077144E-7,1,0.999253354069792,40.0298881530762,1.99577772099304,20.3799996525049,0.0245740247690879,0.00454103821349474,0.25,1.15544019769943E-5,0.00217858869912033,2.57857017118218E-5,20.0006523,20.0006523,25244.763671875,25250.294921875,57.0151107067753,20.6235911554396,13.797379,0,0,0,40,4449,19.9899,25247.529296875,,,,,,,,,,,,,0,,,,-0.0049,,,,,,20.0006523,,,,
,26797951.37,20.0008488,29954.134765625,0.00286864231347073,5.97199274896275E-7,1,0.999253354069792,40.0298881530762,1.99594010445365,20.3799996525049,0.0322551457364206,0.00596452780467095,0.25,1.48159826953669E-5,0.00285939040837362,3.41946299646174E-5,20.0008488,20.0008488,29950.466796875,29957.802734375,57.1042163579676,20.6218313829789,14.177031,0,0,0,40,4449,19.9888,29954.134765625,,,,,,,,,,,,,0,,,,0,,,,,,20.0008488,,,,
,26798139.985,20.0014801,34667.833984375,0.00345042785561627,7.6091027799851E-7,1,0.999253354069792,40.0298881530762,1.99571364979483,20.3799996525049,0.0388121136485169,0.00717590722864675,0.25,1.70259930908963E-5,0.00344101596438129,4.10544356366182E-5,20.0014801,20.0014801,34665.609375,34670.05859375,56.9557069393137,20.6247277250399,13.797379,0,0,0,40,4449,19.9868,34667.833984375,,,,,,,,,,,,,0,,,,0,,,,,,20.0014801,,,,
,26798329.62,20.0010471,39406.51953125,0.00393303173993538,8.36092352343869E-7,1,0.999253354069792,40.0298881530762,1.99615558698596,20.3799996525049,0.0442694920158363,0.00820106556144973,0.25,2.01528577203904E-5,0.00392426790572092,4.82047096822276E-5,20.0010471,20.0010471,39402.82421875,39410.21484375,57.1472059265253,20.6112565046527,13.797379,0,0,0,40,4449,19.98615,39406.51953125,,,,,,,,,,,,,0,,,,0,,,,,,20.0010471,,,,
,26798520.22,20.00006485,44169.07421875,0.00433431811509603,8.97447927923716E-7,1,0.999253354069792,40.0298881530762,1.99602839851959,20.3799996525049,0.0488077240537424,0.00904223228457075,0.25,2.17079936101161E-5,0.00432682909118157,5.31877864278215E-5,20.0000381,20.0000916,44165.19921875,44172.94921875,57.159711982833,20.6098310313159,13.797379,0,0,0,40,4449,19.98425,44169.07421875,,,,,,,,,,,,,0,,,,-0.00245,,,,,,20.00006485,,,,
,26798713.155,20.0003967,48990.65625,0.00467104065864916,9.18500005459975E-7,1,0.999253354069792,40.0298881530762,1.9960612123405,20.3799996525049,0.0526245729979708,0.00976045578080675,0.25,2.39377754378526E-5,0.00466528608607507,5.83002298226205E-5,20.0003967,20.0003967,48988.30078125,48993.01171875,57.3050948874099,20.6120633100507,13.417728,0,0,0,40,4449,19.984,48990.65625,,,,,,,,,,,,,0,,,,-0.00245,,,,,,20.0003967,,,,
,26798905.065,20.0010281,53787.0625,0.00495629642439827,7.91768070387804E-7,1,0.999253354069792,40.0298881530762,1.99630268875654,20.3799996525049,0.0558740621644044,0.0103493453744457,0.25,2.39578794540419E-5,0.00495258406450954,6.07073689593469E-5,20.0010281,20.0010281,53785.90234375,53788.22265625,57.4246840508522,20.6089722907621,13.797379,0,0,0,40,4449,19.9837,53787.0625,,,,,,,,,,,,,0,,,,-0.00245,,,,,,20.0010281,,,,
,26799097.84,20.000246,58604.7421875,0.00520251196927423,1.13318735375737E-6,1,0.999253354069792,40.0298881530762,1.99629688602727,20.3799996525049,0.0586711638425343,0.0109005872916461,0.25,2.78834321126931E-5,0.00520102025408562,6.65935410875122E-5,20.000246,20.000246,58598.28515625,58611.19921875,57.3918556530445,20.6083641637778,14.177031,0,0,0,40,4449,19.98355,58604.7421875,,,,,,,,,,,,,0,,,,-0.00245,,,,,,20.000246,,,,
,26799288.665,20.0010223,63374.2265625,0.00541326440144254,9.9656296772328E-7,1,0.999253354069792,40.0298881530762,1.99627544224882,20.3799996525049,0.0610730497335989,0.0113540864810357,0.25,2.96760591901143E-5,0.00541410310831352,6.99431840378833E-5,20.0010223,20.0010223,63366.9296875,63381.5234375,57.1542405831984,20.609050700934,13.797379,0,0,0,40,4449,19.9825,63374.2265625,,,,,,,,,,,,,0,,,,0,,,,,,20.0010223,,,,
,26799483.15,20.0011845,68233.9765625,0.00560422319736604,1.40557835771946E-6,1,0.999253354069792,40.0298881530762,1.99639290589252,20.3799996525049,0.0632632519391625,0.0117321884375729,0.25,2.84163294158443E-5,0.00560751775556848,6.99499046508678E-5,20.0011845,20.0011845,68231.46875,68236.484375,57.3191642007561,20.6067887625251,13.417728,0,0,0,40,4449,19.98055,68233.9765625,,,,,,,,,,,,,0,,,,-0.0049,,,,,,20.0011845,,,,
,26799672.335,20.0008354,72962.94921875,0.0057694756283679,1.43361428579176E-6,1,0.999253354069792,40.0298881530762,1.99640356686206,20.3799996525049,0.0651512666810969,0.0121028547102923,0.25,3.13151628887499E-5,0.00577514221673121,7.38006908357778E-5,20.0008354,20.0008354,72959.5703125,72966.328125,57.1823792098907,20.6075052555241,13.797379,0,0,0,40,4449,19.97925,72962.94921875,,,,,,,,,,,,,0,,,,-0.00245,,,,,,20.0008354,,,,
,26799865.01,20.00025465,77777.58203125,0.00592454000016734,1.02541390370655E-6,1,0.999253354069792,40.0298881530762,1.99641772398765,20.3799996525049,0.0669265907661469,0.0124422783245269,0.25,3.34023086071162E-5,0.00593261317508254,7.66382701927676E-5,20.000145,20.0003643,77775.046875,77780.1171875,57.1221938139099,20.6060000973688,14.177031,0,0,0,40,4449,19.97805,77777.58203125,,,,,,,,,,,,,0,,,,0,,,,,,20.00025465,,,,
,26800055.995,20.0010529,82550.40625,0.00606569168147601,9.76357629860212E-7,1,0.999253354069792,40.0298881530762,1.99635974955344,20.3799996525049,0.0685429228018419,0.0127465372195596,0.25,3.50367370608258E-5,0.0060761149011151,7.8814929574583E-5,20.0010529,20.0010529,82548.21875,82552.59375,57.1573670972753,20.6047634012519,13.797379,0,0,0,40,4449,19.97575,82550.40625,,,,,,,,,,,,,0,,,,0,,,,,,20.0010529,,,,
,26800239.155,20.0002117,87128.71875,0.00618891812085826,1.36595779685382E-6,1,0.999253354069792,40.0298881530762,1.99644258887646,20.3799996525049,0.0699607338186701,0.0130094044398542,0.25,3.6255022132979E-5,0.00620154199981342,8.03737489924846E-5,20.0002117,20.0002117,87126.140625,87131.296875,57.0057311645445,20.6046608746064,13.797379,0,0,0,40,4449,19.9749,87128.71875,,,,,,,,,,,,,0,,,,0,,,,,,20.0002117,,,,
,26800433.72,20.0005093,88506.6484375,0.00623684066019469,1.43644658554459E-6,1,0.999253354069792,40.0298881530762,1.99643719778254,20.3799996525049,0.0705156987799206,0.0130730360020252,0.25,3.33383621208081E-5,0.00625016552009128,7.76133282574064E-5,20.0005093,20.0005093,88501.7421875,88511.5546875,56.973684395256,20.6061061218282,13.797379,0,0,0,40,4449,19.97425,88506.6484375,,,,,,,,,,,,,0,,,,0,,,,,,20.0005093,,,,
,26800609.695,19.9999313,84108.84765625,0.00613887271971616,1.18893100209399E-6,1,0.999253354069792,40.0298881530762,1.99642191939214,20.3799996525049,0.0693831807653254,0.0128826036553833,0.25,3.39196462320816E-5,0.00615011903806038,7.80445307412908E-5,19.9999313,19.9999313,84104.921875,84112.7734375,57.5341120435445,20.6042205121001,13.797379,0,0,0,40,4449,19.975,84108.84765625,,,,,,,,,,,,,0,,,,0,,,,,,19.9999313,,,,
,26800797.04,19.999361,79426.09765625,0.00603200122280387,1.20181302349079E-6,1,0.999253354069792,40.0298881530762,1.99645175259895,20.3799996525049,0.0681489402101772,0.0126766017743751,0.25,3.47819583433358E-5,0.00604097324065719,7.86445672585199E-5,19.999361,19.999361,79423.7734375,79428.421875,57.3301070000253,20.6050298360472,13.797379,0,0,0,40,4449,19.9756,79426.09765625,,,,,,,,,,,,,0,,,,0,,,,,,19.999361,,,,
,26800987.4,19.9986935,74667.84765625,0.00591328995197028,1.14538626438353E-6,1,0.999253354069792,40.0298881530762,1.99646684403167,20.3799996525049,0.0667815499952264,0.012433992627427,0.25,3.46547241246339E-5,0.00591989408350406,7.80746283617388E-5,19.9986687,19.9987183,74663.015625,74672.6796875,56.9494539111599,20.6055596140352,13.797379,0,0,0,40,4449,19.9774,74667.84765625,,,,,,,,,,,,,0,,,,0,,,,,,19.9986935,,,,
,26801178.93,19.9991074,69881.2890625,0.00578621966647933,1.17097133646549E-6,1,0.999253354069792,40.0298881530762,1.99653309818843,20.3799996525049,0.0653266455541094,0.0121413829690799,0.25,3.17048908836363E-5,0.0057904177574747,7.45056834412134E-5,19.9991074,19.9991074,69877.640625,69884.9375,57.3512109700445,20.6053673801329,13.797379,0,0,0,40,4449,19.9781,69881.2890625,,,,,,,,,,,,,0,,,,0,,,,,,19.9991074,,,,
,26801367.865,19.998724,65159.671875,0.0056509718008842,1.1384620521009E-6,1,0.999253354069792,40.0298881530762,1.9965623399671,20.3799996525049,0.0637789423013381,0.0118280081255867,0.25,2.85367090599555E-5,0.00565277227714236,7.05302569636012E-5,19.998724,19.998724,65154.66015625,65164.68359375,57.0237086204868,20.605285777978,13.417728,0,0,0,40,4449,19.97985,65159.671875,,,,,,,,,,,,,0,,,,-0.0049,,,,,,19.998724,,,,
,26801557.485,19.9990864,60420.189453125,0.0055055745901635,9.59669575512917E-7,1,0.999253354069792,40.0298881530762,1.99658691595354,20.3799996525049,0.0621184969314786,0.01148180620897,0.25,2.44285899040478E-5,0.00550497400313292,6.54068257374971E-5,19.9990864,19.9990864,60416.51953125,60423.859375,56.9854088230445,20.6050133070542,13.797379,0,0,0,40,4449,19.98155,60420.189453125,,,,,,,,,,,,,0,,,,0,,,,,,19.9990864,,,,
,26801743.745,19.99917795,55765.08203125,0.00535293066933325,1.10525229597045E-6,1,0.999253354069792,40.0298881530762,1.99666185365061,20.3799996525049,0.0603662940079512,0.0111884525707947,0.25,2.64132810386555E-5,0.00534995352298846,6.61804628964126E-5,19.9990902,19.9992657,55761.03515625,55769.12890625,57.3402681707753,20.6072819958108,13.797379,0,0,0,40,4449,19.9826,55765.08203125,,,,,,,,,,,,,0,,,,-0.0049,,,,,,19.99917795,,,,
,26801931.19,19.9995708,51081.23046875,0.00518683343378624,7.13982011447563E-7,1,0.999253354069792,40.0298881530762,1.99666976720432,20.3799996525049,0.05846554762775,0.0108403860591881,0.25,2.61491627803763E-5,0.00518154315345336,6.44590631387234E-5,19.9995708,19.9995708,51078.703125,51083.7578125,57.4168677656599,20.6062336151451,13.417728,0,0,0,40,4449,19.9833,51081.23046875,,,,,,,,,,,,,0,,,,0,,,,,,19.9995708,,,,
,26802119.925,19.9999485,46365.185546875,0.00500050240099743,8.72709005567338E-7,1,0.999253354069792,40.0298881530762,1.9967117530185,20.3799996525049,0.0563417653130442,0.010432067980165,0.25,2.43121645422553E-5,0.00499300605600494,6.0867930149662E-5,19.9999485,19.9999485,46361.40625,46368.96484375,57.2628869473714,20.6032754640526,13.797379,0,0,0,40,4449,19.98335,46365.185546875,,,,,,,,,,,,,0,,,,0,,,,,,19.9999485,,,,
,26802307.455,19.9992809,41678.4375,0.00479980978169,1.01100966340037E-6,1,0.999253354069792,40.0298881530762,1.99674512718961,20.3799996525049,0.054055979768138,0.0100026392198595,0.25,2.33070186697237E-5,0.00479027148943288,5.78651866916835E-5,19.9992809,19.9992809,41673.47265625,41683.40234375,57.014329078256,20.6042383370228,13.797379,0,0,0,40,4449,19.9839,41678.4375,,,,,,,,,,,,,0,,,,0,,,,,,19.9992809,,,,
,26802494.595,19.9988861,37002.634765625,0.00458254669653331,9.13016075807451E-7,1,0.999253354069792,40.0298881530762,1.99682663820097,20.3799996525049,0.0515841275801062,0.00955368528823694,0.25,2.36279553549007E-5,0.004571170723924,5.59420178144766E-5,19.9988861,19.9988861,36999.0703125,37006.19921875,57.3644986548715,20.607941534564,14.177031,0,0,0,40,4449,19.98475,37002.634765625,,,,,,,,,,,,,0,,,,0.00245,,,,,,19.9988861,,,,
,26802683.975,19.9990864,32269.4150390625,0.00434010086843555,8.48749546835354E-7,1,0.999253354069792,40.0298881530762,1.99690718638521,20.3799996525049,0.0488347963504705,0.00903035494358922,0.25,2.19593471263923E-5,0.00432716032281224,5.17443846024276E-5,19.9990864,19.9990864,32267.240234375,32271.58984375,57.2769562607176,20.6035919030053,13.797379,0,0,0,40,4449,19.9868,32269.4150390625,,,,,,,,,,,,,0,,,,0,,,,,,19.9990864,,,,
,26802871.97,19.9991837,27572.6123046875,0.0040701744956249,6.60094768999698E-7,1,0.999253354069792,40.0298881530762,1.99690538732132,20.3799996525049,0.0457755424199751,0.00846125075851284,0.25,2.12051917735586E-5,0.00405603866566815,4.82111263859883E-5,19.9991837,19.9991837,27571.396484375,27573.828125,56.9486722826406,20.6059718848617,13.797379,0,0,0,40,4449,19.9878,27572.6123046875,,,,,,,,,,,,,0,,,,0,,,,,,19.9991837,,,,
,26803055.97,19.9990292,22972.69140625,0.00377751473014324,5.55704803368847E-7,1,0.999253354069792,40.0298881530762,1.99686735046612,20.3799996525049,0.0424651085961513,0.00783908535981441,0.25,1.97607144763648E-5,0.00376262707888306,4.38445504484644E-5,19.9990292,19.9990292,22971.490234375,22973.892578125,57.0393411908714,20.6047213924546,13.417728,0,0,0,40,4449,19.9891,22972.69140625,,,,,,,,,,,,,0,,,,0,,,,,,19.9990292,,,,
,26803243.46,19.9987679,18287.689453125,0.00344237549541763,5.16095075277867E-7,1,0.999253354069792,40.0298881530762,1.99680807857595,20.3799996525049,0.038679593207974,0.00713527060326396,0.25,1.85894518696369E-5,0.00342723384492487,3.95072990487574E-5,19.9987679,19.9987679,18283.943359375,18291.435546875,57.3488660844868,20.6067293698447,13.797379,0,0,0,40,4449,19.9896,18287.689453125,,,,,,,,,,,,,0,,,,0.0049,,,,,,19.9987679,,,,
,26803429.465,19.9994888,13640.4658203125,0.00307068013006408,5.18414757439775E-7,1,0.999253354069792,40.0298881530762,1.9967509413951,20.3799996525049,0.0344877834749251,0.00635979416230715,0.25,1.73749348885558E-5,0.00305586618625563,3.50371136334924E-5,19.9994888,19.9994888,13636.685546875,13644.24609375,57.3230723433522,20.6071119601708,13.797379,0,0,0,40,4449,19.9919,13640.4658203125,,,,,,,,,,,,,0,,,,0,,,,,,19.9994888,,,,
,26803614.985,19.99948215,9004.43017578125,0.00265054394494683,4.37126436078636E-7,1,0.999253354069792,40.0298881530762,1.99685475435847,20.3799996525049,0.0297601858385117,0.00548108605173104,0.25,1.52952805859402E-5,0.002636733788103,2.96397581888531E-5,19.9994755,19.9994888,9001.7822265625,9007.078125,57.2800827747945,20.608007259683,13.797379,0,0,0,40,4449,19.9938,9004.43017578125,,,,,,,,,,,,,0,,,,-0.0049,,,,,,19.99948215,,,,
,26803802.825,19.9997158,4308.37915039063,0.00217224273034773,4.20709400379547E-7,1,0.999253354069792,40.0298881530762,1.9968130687682,20.3799996525049,0.024381489074475,0.00448769891991525,0.25,1.30333214027429E-5,0.00216018669579377,2.40458783723902E-5,19.9997158,19.9997158,4306.05615234375,4310.7021484375,57.4254656793715,20.6085776345947,13.417728,0,0,0,40,4449,19.994,4308.37915039063,,,,,,,,,,,,,0,,,,0,,,,,,19.9997158,,,,
,26803974.89,20.0013199,-0.494772642850876,0.00167873045811506,3.79906628114285E-7,1,0.999253354069792,40.0298881530762,1.99680267850696,20.3799996525049,0.0188383065208234,0.00346440182431759,0.25,1.02448048204875E-5,0.00166902742257856,1.83206698433745E-5,20.0013199,20.0013199,-0.502384543418884,-0.487160742282867,57.525514129833,20.606939288617,13.417728,0,0,0,40,4417,19.9933,-0.494772642850876,,,,,,,,,,,,,0,,,,0.0049,,,,,,20.0013199,,,,