File: data/monolayers/nanoparticles/Ol_CoFe_C/vsm/rawdata/DD172_6_FCW_100OE.DAT
[Header]
; VSM Data File (default extension .dat)
; Copyright (c) 2003-2013, Quantum Design, Inc. All rights reserved.
TITLE,
FILEOPENTIME,26965705.44,11/09/2018,10:28 am
BYAPP,VSM,2.0,2.0
INFO,PPMS VSM Option Release 1.4.10 Build 1,APPNAME
INFO,Quantum Design Linear Motor Servo Controller,MOTOR_MODULE_NAME
INFO,3101-100 M1,MOTOR_HW_VERSION
INFO,MMC1014,MOTOR_SERIAL_NUMBER
INFO,SRV No X-over 01.03.11,MOTOR_SOFTWARE_VERSION
INFO,Quantum Design VSM Detection Module,VSM_MODULE_NAME
INFO,3101-150 F0,VSM_HW_VERSION
INFO,VSM707,VSM_SERIAL_NUMBER
INFO,VSM No X-over 01.02.05 May 20 2008 13:51:47,VSM_SOFTWARE_VERSION
INFO,704,PREAMP_SERIAL_NUMBER
INFO,822,COIL_SERIAL_NUMBER
INFO,0,MOMENT_UNITS
INFO,CoFe2O4 DD67,SAMPLE_MATERIAL
INFO,Colloidal Crystal,SAMPLE_COMMENT
INFO,31.86,SAMPLE_MASS
INFO,,SAMPLE_VOLUME
INFO,,SAMPLE_MOLECULAR_WEIGHT
INFO,,SAMPLE_SIZE
INFO,,SAMPLE_SHAPE
DATATYPE,COMMENT,1
DATATYPE,TIME,2
STARTUPAXIS,X,2
STARTUPAXIS,Y1,5
[Data]
Comment,Time Stamp (sec),Temperature (K),Magnetic Field (Oe),Moment (emu),M. Std. Err. (emu),Transport Action,Averaging Time (sec),Frequency (Hz),Peak Amplitude (mm),Center Position (mm),Coil Signal' (mV),Coil Signal" (mV),Range (mV),M. Quad. Signal (emu),M. Raw' (emu),M. Raw" (emu),Min. Temperature (K),Max. Temperature (K),Min. Field (Oe),Max. Field (Oe),Mass (grams),Motor Lag (deg),Pressure (Torr),VSM Status (code),Motor Status (code),Measure Status (code),Measure Count,PPMS Status (code),System Temp. (K),System Field (Oe),Sample Position (deg),Bridge 1 Resistance (ohms),Bridge 1 Excitation (에),Bridge 2 Resistance (ohms),Bridge 2 Excitation (에),Bridge 3 Resistance (ohms),Bridge 3 Excitation (에),Bridge 4 Resistance (ohms),Bridge 4 Excitation (에),Signal 1 Vin (V),Signal 2 Vin (V),Digital Inputs (code),Drive 1 Iout (mA),Drive 1 Ipower (W),Drive 2 Iout (mA),Drive 2 Ipower (W),Pressure (),Map 20 (),Map 21 (),Map 22 (),Map 23 (),Map 24 (),Map 25 (),Map 26 (),Map 27 (),Map 28 (),Map 29 ()
,26965841.57,10.0051603,99.7613830566406,0.000170116429820346,3.49604495137435E-7,1,0.999253354069792,40.0298881530762,1.99822672503253,20.2099997550249,0.00191114260873178,0.000346682970976554,0.25,6.303560943225E-7,0.000169136560810921,1.44718008430977E-6,10.0051603,10.0051603,99.7613830566406,99.7613830566406,56.9244417985445,20.5947323501612,12.658426,0,0,0,40,4369,9.9891,99.7613830566406,,,,,,,,,,,,,0,,,,0,,,,,,10.0051603,,,,
,26965870.5,10.5423088,99.7613830566406,0.000169833521997678,3.08226507200765E-7,1,0.999253354069792,40.0298881530762,1.9981550390252,20.2200002968311,0.00190841766395004,0.000343164121292568,0.25,3.6864856135997E-7,0.000168856391777182,1.18560985113523E-6,10.5423088,10.5423088,99.7613830566406,99.7613830566406,56.8337728903137,20.5897279905721,12.658426,0,0,0,40,4370,10.6477,99.7613830566406,,,,,,,,,,,,,0,,,,0,,,,,,10.5423088,,,,
,26965911.565,11.5287514,99.7613830566406,0.00016967780340459,3.01802054861528E-7,1,0.999253354069792,40.0298881530762,1.99821883055718,20.2099997550249,0.00190624789946253,0.000345532057827428,0.25,6.06065001863601E-7,0.000168700118950602,1.42090925045661E-6,11.5287514,11.5287514,99.7613830566406,99.7613830566406,57.3465211989291,20.5897857245298,13.038077,0,0,0,40,4370,11.62365,99.7613830566406,,,,,,,,,,,,,0,,,,0.00245,,,,,,11.5287514,,,,
,26965952.29,12.5170965,99.7613830566406,0.000169644535138476,3.03310201337747E-7,1,0.999253354069792,40.0298881530762,1.99811952583564,20.2099997550249,0.00190542872831,0.000347424521977172,0.25,7.81845858111763E-7,0.000168665848346334,1.59551656738901E-6,12.5170965,12.5170965,99.7613830566406,99.7613830566406,56.851750346256,20.5895153450784,13.417728,0,0,0,40,4370,12.64535,99.7613830566406,,,,,,,,,,,,,0,,,,0,,,,,,12.5170965,,,,
,26965990.64,13.5039434,99.7613830566406,0.000169643061288344,3.21234639853573E-7,1,0.999253354069792,40.0298881530762,1.99817036987069,20.2099997550249,0.00190558694423838,0.000346680918101487,0.25,7.15278845737058E-7,0.000168664317375466,1.52932148966925E-6,13.5039434,13.5039434,99.7613830566406,99.7613830566406,57.3269804859484,20.5863587204173,13.417728,0,0,0,40,4370,13.612,99.7613830566406,,,,,,,,,,,,,0,,,,0,,,,,,13.5039434,,,,
,26966033.465,14.5610781,99.7613830566406,0.000170340404520698,3.33569272116015E-7,1,0.999253354069792,40.0298881530762,1.9981819011681,20.2200002968311,0.00191282804191375,0.000351471291246259,0.25,1.01749953358391E-6,0.000169355732122835,1.83316283076253E-6,14.5610781,14.5610781,99.7613830566406,99.7613830566406,56.851750346256,20.5895719104023,13.797379,0,0,0,40,4370,14.6916,99.7613830566406,,,,,,,,,,,,,0,,,,0.00245,,,,,,14.5610781,,,,
,26966073.14,15.532443,99.7613830566406,0.000170244463143697,3.6125376521327E-7,1,0.999253354069792,40.0298881530762,1.99789999720313,20.2099997550249,0.00191162526868942,0.00035045214452439,0.25,9.48159837042789E-7,0.000169260211119109,1.76375440325078E-6,15.532443,15.532443,99.7613830566406,99.7613830566406,56.9447641400445,20.5933266293753,13.797379,0,0,0,40,4370,15.685,99.7613830566406,,,,,,,,,,,,,0,,,,-0.00245,,,,,,15.532443,,,,
,26966111.79,16.5189323,99.7613830566406,0.000169786332275632,2.94461754254906E-7,1,0.999253354069792,40.0298881530762,1.9982007364003,20.2099997550249,0.00190709506979715,0.000347610132659585,0.25,7.72312699799692E-7,0.000168805052149188,1.58670490648635E-6,16.5189323,16.5189323,99.7613830566406,99.7613830566406,57.0315249056791,20.5924964811077,14.177031,0,0,0,40,4370,16.65675,99.7613830566406,,,,,,,,,,,,,0,,,,0,,,,,,16.5189323,,,,
,26966153.07,17.5181885,99.7613830566406,0.000169714046674543,3.27869821641152E-7,1,0.999253354069792,40.0298881530762,1.99787833546451,20.2099997550249,0.00190610150397759,0.000346722906720306,0.25,7.11465440834637E-7,0.000168732631310848,1.525517007026E-6,17.5181885,17.5181885,99.7613830566406,99.7613830566406,57.3418314278138,20.594210123035,14.177031,0,0,0,40,4370,17.70105,99.7613830566406,,,,,,,,,,,,,0,,,,0,,,,,,17.5181885,,,,
,26966193.325,18.5459881,99.7613830566406,0.00016968700658833,4.10708618696268E-7,1,0.999253354069792,40.0298881530762,1.99798959519499,20.2099997550249,0.0019057525657989,0.000347538127259996,0.25,7.85869235162173E-7,0.000168705791469665,1.60056918772434E-6,18.5459881,18.5459881,99.7613830566406,99.7613830566406,56.8556584888522,20.5928268219918,14.177031,0,0,0,40,4370,18.701,99.7613830566406,,,,,,,,,,,,,0,,,,-0.00245,,,,,,18.5459881,,,,
,26966232.16,19.5057869,99.7613830566406,0.000169601593687158,3.91424120835749E-7,1,0.999253354069792,40.0298881530762,1.99776604022341,20.2099997550249,0.00190465322220538,0.00034706743623312,0.25,7.59713428094652E-7,0.000168622476454253,1.57662372515229E-6,19.5057869,19.5057869,99.7613830566406,99.7613830566406,57.159711982833,20.5957088429278,14.177031,0,0,0,40,4370,19.6802,99.7613830566406,,,,,,,,,,,,,0,,,,0,,,,,,19.5057869,,,,
touchdown = 15.3099996969104 mm,26966281.635,20.7192917,99.7613830566406,0.00016956176736605,3.63776902367192E-7,1,0.999253354069792,40.0298881530762,1.99766569887555,20.2399995177984,0.00190378893433327,0.000349031353693205,0.25,9.37363937580311E-7,0.00016858546436987,1.75807872470964E-6,20.7192917,20.7192917,99.7613830566406,99.7613830566406,56.983845566006,20.5922685407036,14.556682,0,0,0,40,4370,20.9189,99.7613830566406,,,,,,,,,,,,,0,,,,-0.0049,,,,,,20.7192917,,,,
,26966312.305,21.5175266,99.7613830566406,0.000170050754115224,3.69838819688656E-7,1,0.999253354069792,40.0298881530762,1.99763076735821,20.2399995177984,0.00190906499990723,0.000351260760705406,0.25,1.04459262424649E-6,0.000169074191570449,1.87131843196303E-6,21.5175266,21.5175266,99.7613830566406,99.7613830566406,57.1847240954484,20.5931307632345,14.936333,0,0,0,40,4370,21.69195,99.7613830566406,,,,,,,,,,,,,0,,,,0,,,,,,21.5175266,,,,
,26966354.475,22.5496311,99.7613830566406,0.000169518617819311,3.58268184840714E-7,1,0.999253354069792,40.0298881530762,1.99754920203993,20.2399995177984,0.00190334906082354,0.000348640935227061,0.25,8.99013585223238E-7,0.000168551304428282,1.7311788470143E-6,22.5496311,22.5496311,99.7613830566406,99.7613830566406,56.9369478548522,20.5946618307632,14.556682,0,0,0,40,4370,22.75455,99.7613830566406,,,,,,,,,,,,,0,,,,0,,,,,,22.5496311,,,,
,26966393.61,23.5066433,99.7613830566406,0.0001696833402446,2.95354385915676E-7,1,0.999253354069792,40.0298881530762,1.99752054526355,20.2399995177984,0.0019057246997231,0.000346293673542625,0.25,6.51990784680384E-7,0.000168722770091024,1.4945133848707E-6,23.5066433,23.5066433,99.7613830566406,99.7613830566406,57.0463758475445,20.5961779528614,15.315984,0,0,0,40,4370,23.7383,99.7613830566406,,,,,,,,,,,,,0,,,,-0.00245,,,,,,23.5066433,,,,
,26966435.685,24.5325489,99.7613830566406,0.000169673869455836,3.12570119026729E-7,1,0.999253354069792,40.0298881530762,1.9975699426691,20.2399995177984,0.00190555117349374,0.000347474312282004,0.25,7.46099545249252E-7,0.000168721382648354,1.59839561436268E-6,24.5325489,24.5325489,99.7613830566406,99.7613830566406,57.1331366131791,20.596419877539,14.936333,0,0,0,40,4370,24.7976,99.7613830566406,,,,,,,,,,,,,0,,,,-0.0049,,,,,,24.5325489,,,,
,26966473.31,25.502882,99.7613830566406,0.000169366557586472,3.47601956202548E-7,1,0.999253354069792,40.0298881530762,1.99758354367116,20.2399995177984,0.00190262668741224,0.000344548487858507,0.25,5.27950868065771E-7,0.000168425904761295,1.39055540038028E-6,25.502882,25.502882,99.7613830566406,99.7613830566406,56.8642564025637,20.5942697808677,14.556682,0,0,0,40,4370,25.7473,99.7613830566406,,,,,,,,,,,,,0,,,,0,,,,,,25.502882,,,,
,26966515.4,26.5503254,99.7613830566406,0.000169664669005498,3.5219560521812E-7,1,0.999253354069792,40.0298881530762,1.99743840285224,20.2399995177984,0.00190594449489335,0.000345342871967082,0.25,5.3214943392508E-7,0.00016873417446723,1.40969315751905E-6,26.5503254,26.5503254,99.7613830566406,99.7613830566406,57.0190188493714,20.5968387644426,15.695635,0,0,0,40,4370,26.80815,99.7613830566406,,,,,,,,,,,,,0,,,,-0.00245,,,,,,26.5503254,,,,
,26966554.105,27.5247059,99.7613830566406,0.000169687656027505,2.84431100883179E-7,1,0.999253354069792,40.0298881530762,1.99749894214661,20.2399995177984,0.00190618419991253,0.000346641877850662,0.25,6.26685400419827E-7,0.000168769115261092,1.51761261131941E-6,27.5247059,27.5247059,99.7613830566406,99.7613830566406,56.9877537086022,20.5968327256041,15.315984,0,0,0,40,4370,27.78505,99.7613830566406,,,,,,,,,,,,,0,,,,0.00245,,,,,,27.5247059,,,,
,26966596.015,28.5542259,99.7613830566406,0.000169759392382025,2.95885815728238E-7,1,0.999253354069792,40.0298881530762,1.99752213924207,20.2399995177984,0.00190680319501353,0.000348970516659936,0.25,8.01780050829156E-7,0.000168854878463865,1.70832228749157E-6,28.5542259,28.5542259,99.7613830566406,99.7613830566406,57.0940551872176,20.5982629759359,15.695635,0,0,0,40,4370,28.8293,99.7613830566406,,,,,,,,,,,,,0,,,,0.00245,,,,,,28.5542259,,,,
,26966637.025,29.5553675,99.7613830566406,0.00016991745418615,3.3164388265901E-7,1,0.999253354069792,40.0298881530762,1.99760830904322,20.2399995177984,0.0019089011542286,0.00034909432534279,0.25,7.62537497766911E-7,0.000169029848072706,1.68780075951518E-6,29.5275803,29.5831547,99.7613830566406,99.7613830566406,57.1511140691214,20.6001156133098,16.075285,0,0,0,40,4370,29.8776,99.7613830566406,,,,,,,,,,,,,0,,,,0.0049,,,,,,29.5553675,,,,
,26966686.03,30.7816429,99.7613830566406,,,2,,,,20.2499996969104,,,,,,,30.7816429,30.7816429,99.7613830566406,99.7613830566406,,,15.315984,,,,-99999999,4370,31.0926,99.7613830566406,,,,,,,,,,,,,,,,,,,,,,,30.7816429,,,,
,26966716.965,31.517189,99.7613830566406,0.000169716972223415,2.76147083177311E-7,1,0.999253354069792,40.0298881530762,1.99762525343741,20.2399995177984,0.00190754111929458,0.000346391509054581,0.25,5.13084333114829E-7,0.000168871697703318,1.47592874121542E-6,31.517189,31.517189,99.7613830566406,99.7613830566406,57.0018230219483,20.5951205697155,15.695635,0,0,0,40,4370,31.8909,99.7613830566406,,,,,,,,,,,,,0,,,,-0.00245,,,,,,31.517189,,,,
,26966756.885,32.5474396,99.7613830566406,0.00016960589587579,2.69755684898539E-7,1,0.999253354069792,40.0298881530762,1.99781958630923,20.2399995177984,0.00190561359459451,0.000352503328341741,0.25,1.04922787259804E-6,0.000168781110779111,2.02892320539164E-6,32.5474396,32.5474396,99.7613830566406,99.7613830566406,56.9799374234099,20.6007471799766,16.075285,0,0,0,40,4370,32.8926,99.7613830566406,,,,,,,,,,,,,0,,,,0,,,,,,32.5474396,,,,
,26966797.235,33.5145988,99.7613830566406,0.000169415781224758,3.14495710689934E-7,1,0.999253354069792,40.0298881530762,1.99776640195872,20.2399995177984,0.00190410390861929,0.000350013433318832,0.25,8.36778081265373E-7,0.000168618936503627,1.83762301960946E-6,33.5145988,33.5145988,99.7613830566406,99.7613830566406,56.8736359447945,20.5992642003377,16.075285,0,0,0,40,4370,33.91065,99.7613830566406,,,,,,,,,,,,,0,,,,-0.00245,,,,,,33.5145988,,,,
,26966838.11,34.5334435,99.7613830566406,0.000169408414519768,3.27678636179232E-7,1,0.999253354069792,40.0298881530762,1.99781925229395,20.2399995177984,0.00190488884851814,0.000347287604714805,0.25,5.67913828898144E-7,0.000168641675301093,1.59199063712654E-6,34.5334435,34.5334435,99.7613830566406,99.7613830566406,57.0088576786214,20.5994779338172,16.075285,0,0,0,40,4370,34.93845,99.7613830566406,,,,,,,,,,,,,0,,,,0,,,,,,34.5334435,,,,
,26966879.19,35.5435333,99.7613830566406,0.000169259137375359,3.33292383436246E-7,1,0.999253354069792,40.0298881530762,1.99774671160197,20.2399995177984,0.00190267383038129,0.000351642510196413,0.25,9.54571734065234E-7,0.000168521905334285,1.9986531544325E-6,35.5092201,35.5778465,99.7613830566406,99.7613830566406,57.1143775287176,20.6001813872388,16.075285,0,0,0,40,4370,35.9737,99.7613830566406,,,,,,,,,,,,,0,,,,0.00245,,,,,,35.5435333,,,,
,26966919.82,36.5343323,99.7613830566406,0.000169399371134749,3.46362830455849E-7,1,0.999253354069792,40.0298881530762,1.99770397152338,20.2399995177984,0.00190517170715865,0.000348768247578295,0.25,6.4598767916101E-7,0.000168697175109913,1.71497957380897E-6,36.5343323,36.5343323,99.7613830566406,99.7613830566406,56.8728543162753,20.6005544859914,16.075285,0,0,0,40,4370,37.0051,99.7613830566406,,,,,,,,,,,,,0,,,,-0.0049,,,,,,36.5343323,,,,
,26966957.915,37.5024033,99.7613830566406,0.000169482028623445,3.64051956957351E-7,1,0.999253354069792,40.0298881530762,1.99773364251773,20.2399995177984,0.00190710966336976,0.000345654041673105,0.25,3.27228414693084E-7,0.000168814995849286,1.41894368243537E-6,37.5024033,37.5024033,99.7613830566406,99.7613830566406,56.9588334533906,20.5959867971373,16.075285,0,0,0,40,4370,37.9592,99.7613830566406,,,,,,,,,,,,,0,,,,0.00245,,,,,,37.5024033,,,,
,26967001.025,38.56461335,99.7613830566406,0.000169314113270131,3.25094378631642E-7,1,0.999253354069792,40.0298881530762,1.9977289955421,20.2399995177984,0.00190466293536431,0.000351062909885117,0.25,8.07148198628128E-7,0.000168685479191613,1.91945596840051E-6,38.5340462,38.5951805,99.7613830566406,99.7613830566406,56.8454973181022,20.5981881761167,16.075285,0,0,0,40,4370,39.0479,99.7613830566406,,,,,,,,,,,,,0,,,,0,,,,,,38.56461335,,,,
,26967040.545,39.5085869,99.7613830566406,0.000169367417798291,3.4945475244259E-7,1,0.999253354069792,40.0298881530762,1.9976486112468,20.2399995177984,0.00190662377652456,0.000345795706784214,0.25,3.02807353099117E-7,0.000168782244906236,1.43835921136479E-6,39.5085869,39.5085869,99.7613830566406,99.7613830566406,57.1917587521214,20.5969033022964,16.834587,0,0,0,40,4370,40.0539,99.7613830566406,,,,,,,,,,,,,0,,,,0,,,,,,39.5085869,,,,
,26967083.625,40.5635071,99.7613830566406,0.000169117987896,3.3068844035059E-7,1,0.999253354069792,40.0298881530762,1.9976693827885,20.2399995177984,0.00190407053502212,0.000346971763488423,0.25,4.21935076588681E-7,0.000168578829774661,1.57711588490598E-6,40.5635071,40.5635071,99.7613830566406,99.7613830566406,57.2753930036791,20.5964766931991,16.834587,0,0,0,40,4370,41.1397,99.7613830566406,,,,,,,,,,,,,0,,,,-0.0049,,,,,,40.5635071,,,,
touchdown = 15.3000000864267 mm,26967122.9,41.5251389,99.7613830566406,0.000169318035257626,3.64031711952003E-7,1,0.999253354069792,40.0298881530762,1.99765292516193,20.2300008386374,0.00190661855078505,0.000348496343106601,0.25,4.95421230537002E-7,0.000168821454429221,1.67024899920275E-6,41.5251389,41.5251389,99.7613830566406,99.7613830566406,56.9830639374868,20.5935001147806,17.214239,0,0,0,40,4370,42.12105,99.7613830566406,,,,,,,,,,,,,0,,,,0,,,,,,41.5251389,,,,
,26967162.005,42.553688,99.7613830566406,0.000169237140345021,3.15504331716258E-7,1,0.999253354069792,40.0298881530762,1.99764746260099,20.2300008386374,0.00190570294039428,0.000351333599905471,0.25,7.36306539805815E-7,0.000168785331150758,1.92735991847188E-6,42.553688,42.553688,99.7613830566406,99.7613830566406,57.1722180391407,20.5934914132984,16.834587,0,0,0,40,4370,43.118,99.7613830566406,,,,,,,,,,,,,0,,,,-0.00245,,,,,,42.553688,,,,
,26967202.32,43.5005226,99.7613830566406,0.000169205450647802,3.28629561828919E-7,1,0.999253354069792,40.0298881530762,1.99771817818775,20.2300008386374,0.00190626306879313,0.000349762013946465,0.25,5.76581985384993E-7,0.00016880442752008,1.78410109441754E-6,43.5005226,43.5005226,99.7613830566406,99.7613830566406,56.821266834006,20.5966337701165,17.214239,0,0,0,40,4370,44.1442,99.7613830566406,,,,,,,,,,,,,0,,,,0,,,,,,43.5005226,,,,
,26967241.915,44.5041504,99.7613830566406,0.000169267870252461,3.22078763922042E-7,1,0.999253354069792,40.0298881530762,1.99763106218051,20.2300008386374,0.00190731564107324,0.000350718341307432,0.25,6.28849337460086E-7,0.000168915970715813,1.85067230114542E-6,44.5041504,44.5041504,99.7613830566406,99.7613830566406,56.9689946241406,20.5981298148796,16.834587,0,0,0,40,4370,45.1422,99.7613830566406,,,,,,,,,,,,,0,,,,-0.00245,,,,,,44.5041504,,,,
,26967283.98,45.5161209,99.7613830566406,0.000168962398517952,3.48991371027441E-7,1,0.999253354069792,40.0298881530762,1.99750128607857,20.2300008386374,0.00190434193003742,0.000350351901748497,0.25,6.31054268720729E-7,0.000168665741826671,1.86338491697003E-6,45.5161209,45.5161209,99.7613830566406,99.7613830566406,57.1245386994676,20.5992859447925,17.593889,0,0,0,40,4370,46.21205,99.7613830566406,,,,,,,,,,,,,0,,,,0,,,,,,45.5161209,,,,
,26967323.795,46.5304413,99.7613830566406,0.000168908609644677,3.11620671470555E-7,1,0.999253354069792,40.0298881530762,1.99744654245701,20.2300008386374,0.00190371300484336,0.000353482282396283,0.25,9.00216814131654E-7,0.000168662539496467,2.14148110433335E-6,46.5304413,46.5304413,99.7613830566406,99.7613830566406,57.2324034351214,20.5989665555287,16.834587,0,0,0,40,4370,47.2216,99.7613830566406,,,,,,,,,,,,,0,,,,-0.00245,,,,,,46.5304413,,,,
,26967365.305,47.5392036,99.7613830566406,0.000169021288805998,3.64528704802169E-7,1,0.999253354069792,40.0298881530762,1.99753023723252,20.2300008386374,0.00190627843338053,0.000350594222531837,0.25,6.0529129926481E-7,0.000168833232607454,1.85547240608606E-6,47.5392036,47.5392036,99.7613830566406,99.7613830566406,57.0799858738714,20.6026029836399,17.593889,0,0,0,40,4370,48.282,99.7613830566406,,,,,,,,,,,,,0,,,,0,,,,,,47.5392036,,,,
,26967405.82,48.5376778,99.7613830566406,0.000169197240377352,3.69187504013481E-7,1,0.999253354069792,40.0298881530762,1.99767755485864,20.2300008386374,0.00190910510505969,0.000350594941596174,0.25,5.57128164087965E-7,0.000169063991858321,1.81353106757706E-6,48.5376778,48.5376778,99.7613830566406,99.7613830566406,56.7509202672752,20.6036207877033,17.973541,0,0,0,40,4370,49.3086,99.7613830566406,,,,,,,,,,,,,0,,,,-0.0049,,,,,,48.5376778,,,,
,26967447.16,49.5480728,99.7613830566406,0.000169271813574064,2.80838084695194E-7,1,0.999253354069792,40.0298881530762,1.9975766097036,20.2300008386374,0.00191035652517195,0.000351615808745123,0.25,6.23423208519047E-7,0.000169194691084882,1.88271159257159E-6,49.5480728,49.5480728,99.7613830566406,99.7613830566406,56.9783741663714,20.6043531414267,17.214239,0,0,0,40,4370,50.3709,99.7613830566406,,,,,,,,,,,,,0,,,,-0.00245,,,,,,49.5480728,,,,
,26967488.03,50.5416832,99.7613830566406,0.000168743126129647,2.9095300647216E-7,1,0.999253354069792,40.0298881530762,1.99760861625784,20.2300008386374,0.00190556435273428,0.000347733147627183,0.25,3.65306169627089E-7,0.000168723230892515,1.62038904485445E-6,50.5416832,50.5416832,99.7613830566406,99.7613830566406,57.3168193151984,20.6059787202034,17.973541,0,0,0,40,4370,51.4117,99.7613830566406,,,,,,,,,,,,,0,,,,-0.00245,,,,,,50.5416832,,,,
,26967529.75,51.5536232,99.7613830566406,,,2,,,,20.2199999341369,,,,,,,51.5536232,51.5536232,99.7613830566406,99.7613830566406,,,17.593889,,,,-99999999,4370,52.4761,99.7613830566406,,,,,,,,,,,,,,,,,,,,,,,51.5536232,,,,
,26967550.905,52.0364723,99.7613830566406,0.000168778445623429,3.07321986247519E-7,1,0.999253354069792,40.0298881530762,1.99763614468428,20.2099997550249,0.00190672394787395,0.000349179533739732,0.25,4.77548524379552E-7,0.000168841975460734,1.72734478673295E-6,52.0364723,52.0364723,99.7613830566406,99.7613830566406,56.9377294833714,20.6021715226741,17.973541,0,0,0,40,4374,53.02585,99.7613830566406,,,,,,,,,,,,,0,,,,0,,,,,,52.0364723,,,,
,26967593.545,53.0509796,99.7613830566406,0.000168638429167588,3.50983259931912E-7,1,0.999253354069792,40.0298881530762,1.99761198443697,20.2099997550249,0.00190605820813967,0.00034729158510934,0.25,3.33570490304054E-7,0.000168758810210084,1.57516727857201E-6,53.0509796,53.0509796,99.7613830566406,99.7613830566406,57.3066581444484,20.6070711398773,18.732843,0,0,0,40,4374,54.12235,99.7613830566406,,,,,,,,,,,,,0,,,,0.0049,,,,,,53.0509796,,,,
,26967632.74,54.0432777,99.7613830566406,0.000168523407930087,2.92287138532606E-7,1,0.999253354069792,40.0298881530762,1.99745242734767,20.2099997550249,0.00190505307540356,0.000347800629056487,0.25,4.01740613979197E-7,0.000168692930950868,1.63387749137652E-6,54.0432777,54.0432777,99.7613830566406,99.7613830566406,56.7259081546598,20.6048576160507,18.732843,0,0,0,40,4374,55.1265,99.7613830566406,,,,,,,,,,,,,0,,,,0,,,,,,54.0432777,,,,
,26967673.805,55.0103836,99.7613830566406,0.000168297774930461,3.51144291360823E-7,1,0.999253354069792,40.0298881530762,1.99745406666029,20.2099997550249,0.00190221619173962,0.00035225178721188,0.25,8.38223356955313E-7,0.000168515208836514,2.05801616289227E-6,54.9769287,55.0438385,99.7613830566406,99.7613830566406,57.220679007333,20.6075962554691,19.492144,0,0,0,40,4374,56.19135,99.7613830566406,,,,,,,,,,,,,0,,,,0.00245,,,,,,55.0103836,,,,
,26967715.05,56.0205612,99.7613830566406,0.00016841017831199,3.71686929385305E-7,1,0.999253354069792,40.0298881530762,1.99748417258811,20.2099997550249,0.00190485886307816,0.000348228273165096,0.25,4.66589531043081E-7,0.000168680035706613,1.67344068704764E-6,56.0205612,56.0205612,99.7613830566406,99.7613830566406,57.044812590506,20.6081537716987,19.871798,0,0,0,40,4374,57.2582,99.7613830566406,,,,,,,,,,,,,0,,,,-0.0049,,,,,,56.0205612,,,,
,26967756.585,57.0256882,99.7613830566406,0.000168532347538483,3.26284452630587E-7,1,0.999253354069792,40.0298881530762,1.99748816990352,20.2099997550249,0.00190687239686619,0.000348046845017949,0.25,4.35263471619826E-7,0.000168849875664313,1.62803308533617E-6,57.0256882,57.0256882,99.7613830566406,99.7613830566406,56.9072459711214,20.6070402849288,19.492144,0,0,0,40,4374,58.3153,99.7613830566406,,,,,,,,,,,,,0,,,,0,,,,,,57.0256882,,,,
,26967796.89,58.0028191,99.7613830566406,0.000168529399068257,3.98484338040626E-7,1,0.999253354069792,40.0298881530762,1.99745725923313,20.2099997550249,0.00190774356914485,0.000345710589055944,0.25,2.38317593142082E-7,0.00016889254406525,1.41459413208982E-6,58.0028191,58.0028191,99.7613830566406,99.7613830566406,57.2089545795445,20.6092678735406,19.871798,0,0,0,40,4374,59.3486,99.7613830566406,,,,,,,,,,,,,0,,,,0.0049,,,,,,58.0028191,,,,
,26967840.67,59.0604553,99.7613830566406,0.000168270514381085,2.97087856192149E-7,1,0.999253354069792,40.0298881530762,1.9974142932362,20.2099997550249,0.00190495674519059,0.000347105412053376,0.25,4.19561375057547E-7,0.000168677435214392,1.57565205713452E-6,59.0604553,59.0604553,99.7613830566406,99.7613830566406,57.8108085393523,20.6079722920358,19.871798,0,0,0,40,4374,60.4679,99.7613830566406,,,,,,,,,,,,,0,,,,0.0049,,,,,,59.0604553,,,,
,26967878.18,60.0056267,99.7613830566406,0.000168529707440844,3.31746416542741E-7,1,0.999253354069792,40.0298881530762,1.99768927678907,20.2099997550249,0.00190829457098456,0.000349210973897441,0.25,5.6537850963622E-7,0.000168972971172106,1.70673357557367E-6,60.0056267,60.0056267,99.7613830566406,99.7613830566406,57.1761261817368,20.6078374902898,20.251448,0,0,0,40,4374,61.4161,99.7613830566406,,,,,,,,,,,,,0,,,,0.00245,,,,,,60.0056267,,,,
,26967918.825,61.00634,99.7613830566406,0.000168202128801991,3.0556514297528E-7,1,0.999253354069792,40.0298881530762,1.99764681380208,20.2099997550249,0.00190511558764864,0.00034780407925255,0.25,5.13192651300544E-7,0.000168682681756785,1.63309588329795E-6,61.00634,61.00634,99.7613830566406,99.7613830566406,56.7642079521022,20.6085328993483,20.631098,0,0,0,40,4374,62.44415,99.7613830566406,,,,,,,,,,,,,0,,,,0,,,,,,61.00634,,,,
,26967957.67,61.9702759,99.7613830566406,,,2,,,,20.199999781847,,,,,,,61.9702759,61.9702759,99.7613830566406,99.7613830566406,,,20.631098,,,,-99999999,4374,63.4188,99.7613830566406,,,,,,,,,,,,,,,,,,,,,,,61.9702759,,,,
,26967981.28,62.525692,99.7613830566406,0.000168721651000748,2.96759314618648E-7,1,0.999253354069792,40.0298881530762,1.99766260978532,20.1799999922514,0.00191219893768085,0.000345786297271152,0.25,2.63077106803112E-7,0.000169259531343747,1.35495451341903E-6,62.525692,62.525692,99.7613830566406,99.7613830566406,57.6091483813907,20.6000415836434,20.251448,0,0,0,40,4374,64.02085,99.7613830566406,,,,,,,,,,,,,0,,,,-0.0049,,,,,,62.525692,,,,
,26968021.36,63.5195694,99.7613830566406,0.000168212610017998,3.26985884022752E-7,1,0.999253354069792,40.0298881530762,1.99771778464705,20.1799999922514,0.00190661064463828,0.000346095653892134,0.25,3.95394149207451E-7,0.000168779983279489,1.46425205597917E-6,63.5195694,63.5195694,99.7613830566406,99.7613830566406,56.9322580837368,20.6054461752103,19.871798,0,0,0,40,4374,65.02785,99.7613830566406,,,,,,,,,,,,,0,,,,0,,,,,,63.5195694,,,,
,26968062.115,64.5255432,99.7613830566406,0.0001682138218589,2.78853719623576E-7,1,0.999253354069792,40.0298881530762,1.99759890990585,20.1799999922514,0.00190720443637513,0.000344245687811975,0.25,2.49474385261505E-7,0.000168813134403754,1.29673864254786E-6,64.5255432,64.5255432,99.7613830566406,99.7613830566406,57.1339182416984,20.6063555389707,19.871798,0,0,0,40,4374,66.06565,99.7613830566406,,,,,,,,,,,,,0,,,,0,,,,,,64.5255432,,,,
,26968102.985,65.5418091,99.7613830566406,0.000168012221344122,3.13759692865354E-7,1,0.999253354069792,40.0298881530762,1.99757264958903,20.1799999922514,0.00190488367944072,0.00034576909373596,0.25,4.36408118293004E-7,0.000168638605095226,1.46190488861379E-6,65.5418091,65.5418091,99.7613830566406,99.7613830566406,57.1245386994676,20.6051392151398,21.01075,0,0,0,40,4374,67.1008,99.7613830566406,,,,,,,,,,,,,0,,,,-0.00245,,,,,,65.5418091,,,,
,26968144.175,66.5248489,99.7613830566406,0.000168052135080702,3.57670729912354E-7,1,0.999253354069792,40.0298881530762,1.99763442594688,20.1799999922514,0.00190595397120633,0.000344496878602523,0.25,3.3286304640359E-7,0.000168706653563877,1.33680232861492E-6,66.5248489,66.5248489,99.7613830566406,99.7613830566406,57.0487207331022,20.6047415186588,20.631098,0,0,0,40,4374,68.14275,99.7613830566406,,,,,,,,,,,,,0,,,,0.0049,,,,,,66.5248489,,,,
,26968184.535,67.5581589,99.7613830566406,0.000168017278352761,3.26577848783534E-7,1,0.999253354069792,40.0298881530762,1.99744547535306,20.1799999922514,0.00190525617747351,0.000346727768233656,0.25,5.54931599319765E-7,0.000168695032331018,1.53877335476678E-6,67.5581589,67.5581589,99.7613830566406,99.7613830566406,56.8963031718522,20.6081455762043,20.631098,0,0,0,40,4374,69.156,99.7613830566406,,,,,,,,,,,,,0,,,,0,,,,,,67.5581589,,,,
,26968224.745,68.5724258,99.7613830566406,0.000168089777621743,3.67132187902167E-7,1,0.999253354069792,40.0298881530762,1.99750904199109,20.1799999922514,0.00190650829421955,0.000346296647023432,0.25,5.19594900506434E-7,0.0001687910077166,1.48316825897916E-6,68.5724258,68.5724258,99.7613830566406,99.7613830566406,57.3660619119099,20.6056498394561,20.631098,0,0,0,40,4374,70.16385,99.7613830566406,,,,,,,,,,,,,0,,,,-0.00245,,,,,,68.5724258,,,,
,26968265.18,69.5427628,99.7613830566406,0.000167871271752347,3.47197439681091E-7,1,0.999253354069792,40.0298881530762,1.99739380132742,20.1799999922514,0.00190393725474727,0.000347186089807279,0.25,6.55495030628858E-7,0.000168592760914119,1.59769761797741E-6,69.5427628,69.5427628,99.7613830566406,99.7613830566406,56.6188250475252,20.6074389202368,20.631098,0,0,0,40,4374,71.1901,99.7613830566406,,,,,,,,,,,,,0,,,,0,,,,,,69.5427628,,,,
,26968305.805,70.5648117,99.7613830566406,0.000167662575731991,3.53632499337087E-7,1,0.999253354069792,40.0298881530762,1.99742238252653,20.1799999922514,0.00190294690973559,0.000340493530291533,0.25,1.19497887135165E-7,0.00016840628934486,1.03781336893058E-6,70.5648117,70.5648117,99.7613830566406,99.7613830566406,57.0870205305445,20.6060730257072,20.631098,0,0,0,40,4374,72.2125,99.7613830566406,,,,,,,,,,,,,0,,,,0.00245,,,,,,70.5648117,,,,
,26968345.025,71.5299454,99.7613830566406,0.000168048964459662,3.00628444318013E-7,1,0.999253354069792,40.0298881530762,1.9974613824154,20.1799999922514,0.00190707550776675,0.000344124122514951,0.25,3.86320360415647E-7,0.000168811358195196,1.28829812024464E-6,71.5299454,71.5299454,99.7613830566406,99.7613830566406,56.9244417985445,20.6084069017424,21.01075,0,0,0,40,4374,73.21045,99.7613830566406,,,,,,,,,,,,,0,,,,0,,,,,,71.5299454,,,,
touchdown = 15.2399996295571 mm,26968394.625,72.7377777,99.7613830566406,0.000168033676456109,3.11386762224982E-7,1,0.999253354069792,40.0298881530762,1.99751223304222,20.1699994504452,0.00190769548694025,0.000341288256920138,0.25,1.58945165902838E-7,0.000168818465756886,1.03564270765129E-6,72.7377777,72.7377777,99.7613830566406,99.7613830566406,56.966649738583,20.6011514612674,21.3904,0,0,0,40,4374,74.46095,99.7613830566406,,,,,,,,,,,,,0,,,,0,,,,,,72.7377777,,,,
,26968427.15,73.5531616,99.7613830566406,0.000167574426146158,3.9153335366082E-7,1,0.999253354069792,40.0298881530762,1.99733799726253,20.1699994504452,0.00190224866522619,0.000341591613371745,0.25,2.83242658436385E-7,0.0001683694042448,1.14247090747325E-6,73.5531616,73.5531616,99.7613830566406,99.7613830566406,56.983845566006,20.6022192324818,21.01075,0,0,0,40,4374,75.29035,99.7613830566406,,,,,,,,,,,,,0,,,,0.00245,,,,,,73.5531616,,,,
,26968467.775,74.5604324,99.7613830566406,0.000167907756567465,3.01840731413143E-7,1,0.999253354069792,40.0298881530762,1.99716474798447,20.1699994504452,0.0019060875860968,0.000342019377499829,0.25,2.80452051628567E-7,0.00016871928140891,1.12241097072274E-6,74.5604324,74.5604324,99.7613830566406,99.7613830566406,57.2269320354868,20.6031194518111,21.3904,0,0,0,40,4374,76.3126,99.7613830566406,,,,,,,,,,,,,0,,,,0.0049,,,,,,74.5604324,,,,
,26968508.415,75.5545502,99.7613830566406,0.000167740135497684,3.41727389808296E-7,1,0.999253354069792,40.0298881530762,1.99739274054451,20.1699994504452,0.00190463087721045,0.000341276389586214,0.25,2.57628110050885E-7,0.000168564838087964,1.08008636116122E-6,75.5545502,75.5545502,99.7613830566406,99.7613830566406,56.6461820456983,20.6034810880281,20.631098,0,0,0,40,4374,77.3369,99.7613830566406,,,,,,,,,,,,,0,,,,-0.00245,,,,,,75.5545502,,,,
,26968545.77,76.5045776,99.7613830566406,0.000167590515113904,3.33200461070095E-7,1,0.999253354069792,40.0298881530762,1.99742969601805,20.1699994504452,0.00190231302101498,0.000345419544172609,0.25,6.62995502273289E-7,0.000168424263162119,1.47008171847702E-6,76.5045776,76.5045776,99.7613830566406,99.7613830566406,57.1651833824676,20.6030843917555,21.01075,0,0,0,40,4374,78.27965,99.7613830566406,,,,,,,,,,,,,0,,,,-0.00245,,,,,,76.5045776,,,,
,26968588.6,77.5098038,99.7613830566406,0.00016732658901362,3.79990884992699E-7,1,0.999253354069792,40.0298881530762,1.99744599327689,20.1699994504452,0.00189915902181808,0.000346680207061117,0.25,8.3688352094598E-7,0.000168170870818609,1.62501933230997E-6,77.5098038,77.5098038,99.7613830566406,99.7613830566406,56.9697762526599,20.6035990882739,20.631098,0,0,0,40,4374,79.3605,99.7613830566406,,,,,,,,,,,,,0,,,,-0.00245,,,,,,77.5098038,,,,
,26968627.515,78.5219727,99.7613830566406,0.000167422668017974,3.71572749581649E-7,1,0.999253354069792,40.0298881530762,1.9973925029389,20.1699994504452,0.0019007764988119,0.000344318242116918,0.25,6.27595137024993E-7,0.000168279032766294,1.39832742077463E-6,78.5219727,78.5219727,99.7613830566406,99.7613830566406,57.6834030907176,20.60174290122,21.3904,0,0,0,40,4374,80.3641,99.7613830566406,,,,,,,,,,,,,0,,,,0.0049,,,,,,78.5219727,,,,
,26968670.79,79.5648041,99.7613830566406,0.000167438580319804,3.33525967001253E-7,1,0.999253354069792,40.0298881530762,1.99737823257655,20.1699994504452,0.00190120810888405,0.000343569244594105,0.25,5.75016609349286E-7,0.000168306136560601,1.32764208424405E-6,79.5648041,79.5648041,99.7613830566406,99.7613830566406,56.6039741056598,20.6010912508074,21.01075,0,0,0,40,4374,81.46495,99.7613830566406,,,,,,,,,,,,,0,,,,-0.00245,,,,,,79.5648041,,,,
,26968713.675,80.60881805,99.7613830566406,0.000167317030800277,2.6292121698925E-7,1,0.999253354069792,40.0298881530762,1.99741191581379,20.1699994504452,0.00190002681819532,0.000343010095294403,0.25,5.62193435638625E-7,0.000168193733398023,1.29712041331974E-6,80.5660248,80.6516113,99.7613830566406,99.7613830566406,57.2347483206791,20.6006586488135,21.01075,0,0,0,40,4374,82.5482,99.7613830566406,,,,,,,,,,,,,0,,,,0.00245,,,,,,80.60881805,,,,
,26968752.835,81.58074185,99.7613830566406,0.000167265540152294,2.91971612276473E-7,1,0.999253354069792,40.0298881530762,1.9974662992613,20.1699994504452,0.00189989099412685,0.000341181542529246,0.25,4.23262664030638E-7,0.000168150613482929,1.142126886052E-6,81.539978,81.6215057,99.7613830566406,99.7613830566406,57.0596635323714,20.6025636521322,21.01075,0,0,0,40,4374,83.53425,99.7613830566406,,,,,,,,,,,,,0,,,,0.00245,,,,,,81.58074185,,,,
,26968803.06,82.8015518,99.7613830566406,,,2,,,,20.1499998667836,,,,,,,82.8015518,82.8015518,99.7613830566406,99.7613830566406,,,21.3904,,,,-99999999,4374,84.8004,99.7613830566406,,,,,,,,,,,,,,,,,,,,,,,82.8015518,,,,
,26968830.68,83.5338974,99.7613830566406,0.000167647115871733,3.62885315318919E-7,1,0.999253354069792,40.0298881530762,1.99748018876511,20.1399996876717,0.00190480527019413,0.000339664005360793,0.25,2.48214314592088E-7,0.000168548878682373,9.39043507917092E-7,83.5338974,83.5338974,99.7613830566406,99.7613830566406,57.3418314278138,20.6013106684101,21.3904,0,0,0,40,4374,85.4862,99.7613830566406,,,,,,,,,,,,,0,,,,0,,,,,,83.5338974,,,,
,26968873.005,84.5592194,99.7613830566406,0.000167223182115951,3.09327433025749E-7,1,0.999253354069792,40.0298881530762,1.99742979953824,20.1399996876717,0.00190018882736147,0.000337850020923587,0.25,1.78134891073355E-7,0.000168129757076735,8.51735055289982E-7,84.5592194,84.5592194,99.7613830566406,99.7613830566406,57.014329078256,20.5997589527165,21.770052,0,0,0,40,4374,86.5619,99.7613830566406,,,,,,,,,,,,,0,,,,-0.00245,,,,,,84.5592194,,,,
,26968911.32,85.5234756,99.7613830566406,0.000167510529774569,3.53309173365912E-7,1,0.999253354069792,40.0298881530762,1.99757984014552,20.1399996876717,0.00190434521817701,0.000334535662866774,0.25,-1.54205235268706E-7,0.000168425391583173,5.05595565388954E-7,85.5234756,85.5234756,99.7613830566406,99.7613830566406,57.2863358029484,20.6016845898131,21.3904,0,0,0,40,4374,87.5249,99.7613830566406,,,,,,,,,,,,,0,,,,0.00245,,,,,,85.5234756,,,,
,26968951.195,86.526329,99.7613830566406,0.000167636640554873,3.36657126645763E-7,1,0.999253354069792,40.0298881530762,1.99748074436419,20.1399996876717,0.00190488635292315,0.000339653606753558,0.25,2.8761406984879E-7,0.000168555640382074,9.36949377128422E-7,86.526329,86.526329,99.7613830566406,99.7613830566406,57.065134932006,20.6019750057994,21.3904,0,0,0,40,4374,88.5341,99.7613830566406,,,,,,,,,,,,,0,,,,-0.00245,,,,,,86.526329,,,,
,26968994.365,87.5772324,99.7613830566406,0.000167061157963469,3.34117569423928E-7,1,0.999253354069792,40.0298881530762,1.99732353896103,20.1399996876717,0.0018979917337397,0.000339991866723092,0.25,4.33946582220474E-7,0.000167981404806329,1.06820932575716E-6,87.5772324,87.5772324,99.7613830566406,99.7613830566406,57.1941036376791,20.6040410696152,21.770052,0,0,0,40,4374,89.60125,99.7613830566406,,,,,,,,,,,,,0,,,,0,,,,,,87.5772324,,,,
,26969033.37,88.5656967,99.7613830566406,0.000167348161366616,3.30758903973187E-7,1,0.999253354069792,40.0298881530762,1.99738548568098,20.1399996876717,0.00190150080166384,0.000339761078562258,0.25,3.73547227118244E-7,0.000168274260875471,9.96376642149236E-7,88.5656967,88.5656967,99.7613830566406,99.7613830566406,57.1276652135445,20.6010130423983,22.149702,0,0,0,40,4374,90.5821,99.7613830566406,,,,,,,,,,,,,0,,,,0.00245,,,,,,88.5656967,,,,
,26969072.91,89.5694275,99.7613830566406,0.000167249741120638,3.2895314257132E-7,1,0.999253354069792,40.0298881530762,1.99731849404984,20.1399996876717,0.00190068094276724,0.000337753880778541,0.25,2.26620183176696E-7,0.00016817952333441,8.36235497827816E-7,89.5694275,89.5694275,99.7613830566406,99.7613830566406,56.7970363499099,20.6037630217135,21.770052,0,0,0,40,4374,91.58085,99.7613830566406,,,,,,,,,,,,,0,,,,0,,,,,,89.5694275,,,,
,26969111.53,90.52742,99.7613830566406,0.00016720504424299,3.22542523418525E-7,1,0.999253354069792,40.0298881530762,1.99747019257536,20.1399996876717,0.00190038004423164,0.000337506247314468,0.25,2.21280253308241E-7,0.00016813783427322,8.19374598297444E-7,90.52742,90.52742,99.7613830566406,99.7613830566406,56.8673829166406,20.6000522252409,21.770052,0,0,0,40,4374,92.55,99.7613830566406,,,,,,,,,,,,,0,,,,-0.00245,,,,,,90.52742,,,,
,26969151.83,91.5145569,99.7613830566406,0.000167047006671148,3.34266893455581E-7,1,0.999253354069792,40.0298881530762,1.99749541796159,20.1399996876717,0.00189878935550913,0.000336354022257426,0.25,1.58333024491681E-7,0.000167982187309401,7.44018864637129E-7,91.5145569,91.5145569,99.7613830566406,99.7613830566406,57.1753445532176,20.601316326418,22.149702,0,0,0,40,4374,93.56435,99.7613830566406,,,,,,,,,,,,,0,,,,-0.00245,,,,,,91.5145569,,,,
,26969191.03,92.5092316,99.7613830566406,0.000167151809771942,3.04047145294511E-7,1,0.999253354069792,40.0298881530762,1.99754214690576,20.1399996876717,0.00190001702302819,0.000336767833633331,0.25,1.85917422069842E-7,0.000168089952525217,7.6133754311723E-7,92.5092316,92.5092316,99.7613830566406,99.7613830566406,56.7790588939676,20.6001202745878,21.770052,0,0,0,40,4374,94.54525,99.7613830566406,,,,,,,,,,,,,0,,,,0.0049,,,,,,92.5092316,,,,
touchdown = 15.1800001040101 mm,26969241.545,93.7196503,99.7613830566406,0.000166802514361273,3.51344134649838E-7,1,0.999253354069792,40.0298881530762,1.9974897507112,20.1099999248981,0.00189565015044754,0.000338229586723534,0.25,3.89566396533232E-7,0.00016774094613932,9.51533139064794E-7,93.7196503,93.7196503,99.7613830566406,99.7613830566406,57.1386080128137,20.5961117366701,21.3904,0,0,0,40,4374,95.8089,99.7613830566406,,,,,,,,,,,,,0,,,,-0.00245,,,,,,93.7196503,,,,
,26969274.76,94.5577469,99.7613830566406,0.000166935464734004,3.35166088929574E-7,1,0.999253354069792,40.0298881530762,1.99746384694556,20.1099999248981,0.00189743211001586,0.00033692585627821,0.25,2.6024055735594E-7,0.000167876680055089,8.13226616162671E-7,94.5577469,94.5577469,99.7613830566406,99.7613830566406,57.0002597649099,20.5957772769913,21.770052,0,0,0,40,4374,96.65525,99.7613830566406,,,,,,,,,,,,,0,,,,0,,,,,,94.5577469,,,,
,26969313.88,95.5373917,99.7613830566406,0.000166580344999219,3.23844436568478E-7,1,0.999253354069792,40.0298881530762,1.99751370421152,20.1099999248981,0.00189364820529194,0.000335137855966456,0.25,1.74188519336456E-7,0.000167521370941254,7.1577659706277E-7,95.5373917,95.5373917,99.7613830566406,99.7613830566406,56.9932251082368,20.598231538079,22.149702,0,0,0,40,4374,97.63135,99.7613830566406,,,,,,,,,,,,,0,,,,0.00245,,,,,,95.5373917,,,,
,26969352.4,96.5117722,99.7613830566406,0.000167036842946872,3.04121714033642E-7,1,0.999253354069792,40.0298881530762,1.99745517845987,20.1099999248981,0.00189823400712956,0.000339258291910284,0.25,4.66270185824611E-7,0.000167980769406715,1.0015788431386E-6,96.5117722,96.5117722,99.7613830566406,99.7613830566406,57.098744958333,20.5961848692299,21.770052,0,0,0,40,4374,98.6003,99.7613830566406,,,,,,,,,,,,,0,,,,0,,,,,,96.5117722,,,,
,26969396.18,97.5730972,99.7613830566406,0.000166608795931754,3.48735571022823E-7,1,0.999253354069792,40.0298881530762,1.99747333246871,20.1099999248981,0.00189349425243072,0.000337860483821337,0.25,4.28433647391401E-7,0.000167551721450157,9.51794271743793E-7,97.5730972,97.5730972,99.7613830566406,99.7613830566406,57.1675282680253,20.5979398355346,22.149702,0,0,0,40,4374,99.70435,99.7613830566406,,,,,,,,,,,,,0,,,,-0.00245,,,,,,97.5730972,,,,
,26969432.75,98.5125198,99.7613830566406,0.000166407138786419,4.26765591344903E-7,1,0.999253354069792,40.0298881530762,1.99742276411208,20.1099999248981,0.00189154535768214,0.000335268847380334,0.25,2.44711995600655E-7,0.000167350068054553,7.58206891845294E-7,98.5125198,98.5125198,99.7613830566406,99.7613830566406,57.1839424669291,20.5996302350623,22.149702,0,0,0,40,4374,100.6036,99.7613830566406,,,,,,,,,,,,,0,,,,0,,,,,,98.5125198,,,,
,26969475.6,99.5503998,99.7613830566406,0.000166715775224187,3.24106536092883E-7,1,0.999253354069792,40.0298881530762,1.99749719717636,20.1099999248981,0.00189549397062285,0.000333828839439511,0.25,7.22332474867263E-8,0.000167661746873317,5.76067111343289E-7,99.5503998,99.5503998,99.7613830566406,99.7613830566406,57.0643533034868,20.59951815367,22.149702,0,0,0,40,4374,101.69025,99.7613830566406,,,,,,,,,,,,,0,,,,-0.0049,,,,,,99.5503998,,,,
,26969514.6,100.5272751,99.7613830566406,0.000166546270805903,3.1164326830328E-7,1,0.999253354069792,40.0298881530762,1.99749080769653,20.1099999248981,0.00189261807257999,0.000338876718341113,0.25,5.54349607213765E-7,0.000167490162920444,1.05200422828867E-6,100.5272751,100.5272751,99.7613830566406,99.7613830566406,57.0518472471791,20.5998080439035,22.149702,0,0,0,40,4374,102.66885,99.7613830566406,,,,,,,,,,,,,0,,,,0,,,,,,100.5272751,,,,
,26969553.465,101.5107803,99.7613830566406,0.000166681664735498,3.41222866752688E-7,1,0.999253354069792,40.0298881530762,1.99751310205083,20.1099999248981,0.00189479851805226,0.000335621294413835,0.25,2.52085202817398E-7,0.000167627327384551,7.40235305350481E-7,101.5107803,101.5107803,99.7613830566406,99.7613830566406,57.3996719382368,20.6012955152087,22.149702,0,0,0,40,4374,103.64975,99.7613830566406,,,,,,,,,,,,,0,,,,-0.00245,,,,,,101.5107803,,,,
,26969595.87,102.5322418,99.7613830566406,0.000166819252797547,3.01457306871974E-7,1,0.999253354069792,40.0298881530762,1.99760080784927,20.1099999248981,0.00189651311628512,0.000335510727214021,0.25,2.25585231670757E-7,0.000167765845628836,7.05313388554457E-7,102.5322418,102.5322418,99.7613830566406,99.7613830566406,56.5703640793329,20.6018365819243,22.149702,0,0,0,40,4374,104.7194,99.7613830566406,,,,,,,,,,,,,0,,,,-0.00245,,,,,,102.5322418,,,,
,26969637.45,103.6021805,99.7613830566406,,,2,,,,20.0900003412366,,,,,,,103.6021805,103.6021805,99.7613830566406,99.7613830566406,,,22.149702,,,,-99999999,4374,105.7579,99.7613830566406,,,,,,,,,,,,,,,,,,,,,,,103.6021805,,,,
,26969654.595,104.0246735,99.7613830566406,0.000166523480194682,3.73701305489941E-7,1,0.999253354069792,40.0298881530762,1.99765021982705,20.0800001621246,0.00189394596847219,0.000330606210863366,0.25,-1.42943616999946E-7,0.000167468874694093,3.22334286260782E-7,104.0246735,104.0246735,99.7613830566406,99.7613830566406,56.9510171681983,20.5938671276648,22.149702,0,0,0,40,4374,106.195,99.7613830566406,,,,,,,,,,,,,0,,,,0,,,,,,104.0246735,,,,
,26969696.655,105.0779724,99.7613830566406,0.000166582276467114,3.09976866289454E-7,1,0.999253354069792,40.0298881530762,1.99756661463604,20.0800001621246,0.0018938338023553,0.00033468943359018,0.25,2.14992863398223E-7,0.000167526424995625,6.74516088257742E-7,105.0779724,105.0779724,99.7613830566406,99.7613830566406,56.9471090256022,20.6014819938139,22.149702,0,0,0,40,4374,107.2519,99.7613830566406,,,,,,,,,,,,,0,,,,0,,,,,,105.0779724,,,,
,26969737.25,106.0421982,99.7613830566406,0.000166306454293937,2.97339970008799E-7,1,0.999253354069792,40.0298881530762,1.99765390045724,20.0800001621246,0.00189104349436822,0.000332591848708811,0.25,8.5199169363632E-8,0.000167248854059349,5.35771285611666E-7,106.0421982,106.0421982,99.7613830566406,99.7613830566406,57.4801796757176,20.6009609800396,22.149702,0,0,0,40,4374,108.27495,99.7613830566406,,,,,,,,,,,,,0,,,,0,,,,,,106.0421982,,,,
,26969776.47,107.0246277,99.7613830566406,0.000166419125142659,3.40472524777247E-7,1,0.999253354069792,40.0298881530762,1.99755456937951,20.0800001621246,0.00189130529671371,0.000338044083626967,0.25,5.53381194213551E-7,0.000167360035302762,9.99945452144427E-7,107.0246277,107.0246277,99.7613830566406,99.7613830566406,56.9705578811791,20.600815541199,21.770052,0,0,0,40,4374,109.2574,99.7613830566406,,,,,,,,,,,,,0,,,,0,,,,,,107.0246277,,,,
,26969817.745,108.05574035,99.7613830566406,0.000166774775531918,3.37370595441572E-7,1,0.999253354069792,40.0298881530762,1.99744104542516,20.0800001621246,0.0018956550681638,0.000336334473322879,0.25,3.49625933101869E-7,0.000167717195728601,7.8879453357265E-7,108.0237656,108.0877151,99.7613830566406,99.7613830566406,56.8978664288906,20.5989746780252,22.149702,0,0,0,40,4374,110.29865,99.7613830566406,,,,,,,,,,,,,0,,,,0,,,,,,108.05574035,,,,
,26969855.725,109.0018616,99.7613830566406,0.000166503024752823,3.3535083747081E-7,1,0.999253354069792,40.0298881530762,1.99750443611797,20.0800001621246,0.00189236457236668,0.000337200634844864,0.25,4.79099209961489E-7,0.00016744248053464,9.11872180541635E-7,109.0018616,109.0018616,99.7613830566406,99.7613830566406,56.9322580837368,20.5994291503762,22.529354,0,0,0,40,4374,111.25565,99.7613830566406,,,,,,,,,,,,,0,,,,0,,,,,,109.0018616,,,,
,26969897.98,110.05374525,99.7613830566406,0.000166717824181702,3.1199557656787E-7,1,0.999253354069792,40.0298881530762,1.99742313270022,20.0800001621246,0.0018952597300155,0.000334520425685919,0.25,2.14066207302146E-7,0.000167657817315541,6.38928223651835E-7,110.0282669,110.0792236,99.7613830566406,99.7613830566406,56.9041194570445,20.5965869362266,22.529354,0,0,0,40,4374,112.32375,99.7613830566406,,,,,,,,,,,,,0,,,,0.00245,,,,,,110.05374525,,,,
,26969937.23,111.030632,99.7613830566406,0.000166281462524221,3.33561151200927E-7,1,0.999253354069792,40.0298881530762,1.99744882421696,20.0800001621246,0.00188968912686923,0.000337169221108411,0.25,5.29520902895583E-7,0.000167216788879434,9.48836314737982E-7,111.030632,111.030632,99.7613830566406,99.7613830566406,57.2652318329291,20.602328331158,22.529354,0,0,0,40,4374,113.30625,99.7613830566406,,,,,,,,,,,,,0,,,,0,,,,,,111.030632,,,,
,26969978.375,112.0529709,99.7613830566406,0.000166664399337592,3.81030137850949E-7,1,0.999253354069792,40.0298881530762,1.99747938338045,20.0800001621246,0.00189464449977895,0.00033455587627953,0.25,2.38845567559274E-7,0.000167601022425059,6.51068770252748E-7,112.0529709,112.0529709,99.7613830566406,99.7613830566406,57.2058280654676,20.5993832700185,22.149702,0,0,0,40,4374,114.3463,99.7613830566406,,,,,,,,,,,,,0,,,,0,,,,,,112.0529709,,,,
,26970016.955,113.0175934,99.7613830566406,0.000166124644585385,3.60993755360947E-7,1,0.999253354069792,40.0298881530762,1.99742304710453,20.0800001621246,0.00188865793358754,0.000332209823152612,0.25,1.33867046810089E-7,0.000167056849601523,5.38377177447183E-7,113.0175934,113.0175934,99.7613830566406,99.7613830566406,56.5445703381983,20.5995157652865,22.529354,0,0,0,40,4374,115.31485,99.7613830566406,,,,,,,,,,,,,0,,,,-0.0049,,,,,,113.0175934,,,,
,26970056.3,113.954216,99.7613830566406,,,2,,,,20.0500000366569,,,,,,,113.954216,113.954216,99.7613830566406,99.7613830566406,,,22.529354,,,,-99999999,4374,116.2991,99.7613830566406,,,,,,,,,,,,,,,,,,,,,,,113.954216,,,,
,26970079.91,114.5537491,99.7613830566406,0.000166428483580495,3.36026851090816E-7,1,0.999253354069792,40.0298881530762,1.99747006826196,20.0399998575449,0.0018916289497436,0.000335643830804446,0.25,3.91605556415437E-7,0.000167359016915747,7.89141732245305E-7,114.5537491,114.5537491,99.7613830566406,99.7613830566406,56.6375841319868,20.5962910266582,22.909004,0,0,0,40,4374,116.8964,99.7613830566406,,,,,,,,,,,,,0,,,,0,,,,,,114.5537491,,,,
,26970118.18,115.5078659,99.7613830566406,0.000166335368898746,3.49163684654878E-7,1,0.999253354069792,40.0298881530762,1.99754896913095,20.0399998575449,0.00189065417617153,0.000335273397862476,0.25,3.7993430121486E-7,0.000167263544235485,7.7175398764642E-7,115.5078659,115.5078659,99.7613830566406,99.7613830566406,56.7579549239483,20.5979682639915,22.149702,0,0,0,40,4374,117.86705,99.7613830566406,,,,,,,,,,,,,0,,,,0.00245,,,,,,115.5078659,,,,
,26970160.25,116.5634308,99.7613830566406,0.000166353862722252,3.41282623591784E-7,1,0.999253354069792,40.0298881530762,1.99744583763734,20.0399998575449,0.00189159629217385,0.00033042944320397,0.25,-4.17831936161226E-8,0.000167280899888917,3.42001430125371E-7,116.5634308,116.5634308,99.7613830566406,99.7613830566406,56.6532167023714,20.5976006272977,22.529354,0,0,0,40,4374,118.9186,99.7613830566406,,,,,,,,,,,,,0,,,,0,,,,,,116.5634308,,,,
,26970199.69,117.5392227,99.7613830566406,0.000166193626500184,3.17997661600101E-7,1,0.999253354069792,40.0298881530762,1.99746246197006,20.0399998575449,0.00188951382637463,0.000331546395564358,0.25,8.98425119065834E-8,0.000167117349157596,4.6873507966031E-7,117.5392227,117.5392227,99.7613830566406,99.7613830566406,56.9650864815445,20.598422321975,22.529354,0,0,0,40,4374,119.91125,99.7613830566406,,,,,,,,,,,,,0,,,,-0.0049,,,,,,117.5392227,,,,
,26970219.505,118.0370865,99.7613830566406,0.000165907426986713,3.55312181479069E-7,1,0.999253354069792,40.0298881530762,1.99746016652745,20.0399998575449,0.00188625489826871,0.000330916365462966,0.25,8.72841409578301E-8,0.000166828435253944,4.6293117997905E-7,118.0370865,118.0370865,99.7613830566406,99.7613830566406,56.9729027667368,20.5997438804072,22.529354,0,0,0,40,4374,120.4089,99.7613830566406,,,,,,,,,,,,,0,,,,0,,,,,,118.0370865,,,,