File: data/monolayers/nanoparticles/Ol_CoFe_C/vsm/rawdata/DD172_6_FCC_100OE.DAT
[Header]
; VSM Data File (default extension .dat)
; Copyright (c) 2003-2013, Quantum Design, Inc. All rights reserved.
TITLE,
FILEOPENTIME,26951795.97,11/09/2018,6:36 am
BYAPP,VSM,2.0,2.0
INFO,PPMS VSM Option Release 1.4.10 Build 1,APPNAME
INFO,Quantum Design Linear Motor Servo Controller,MOTOR_MODULE_NAME
INFO,3101-100 M1,MOTOR_HW_VERSION
INFO,MMC1014,MOTOR_SERIAL_NUMBER
INFO,SRV No X-over 01.03.11,MOTOR_SOFTWARE_VERSION
INFO,Quantum Design VSM Detection Module,VSM_MODULE_NAME
INFO,3101-150 F0,VSM_HW_VERSION
INFO,VSM707,VSM_SERIAL_NUMBER
INFO,VSM No X-over 01.02.05 May 20 2008 13:51:47,VSM_SOFTWARE_VERSION
INFO,704,PREAMP_SERIAL_NUMBER
INFO,822,COIL_SERIAL_NUMBER
INFO,0,MOMENT_UNITS
INFO,CoFe2O4 DD67,SAMPLE_MATERIAL
INFO,Colloidal Crystal,SAMPLE_COMMENT
INFO,31.86,SAMPLE_MASS
INFO,,SAMPLE_VOLUME
INFO,,SAMPLE_MOLECULAR_WEIGHT
INFO,,SAMPLE_SIZE
INFO,,SAMPLE_SHAPE
DATATYPE,COMMENT,1
DATATYPE,TIME,2
STARTUPAXIS,X,2
STARTUPAXIS,Y1,5
[Data]
Comment,Time Stamp (sec),Temperature (K),Magnetic Field (Oe),Moment (emu),M. Std. Err. (emu),Transport Action,Averaging Time (sec),Frequency (Hz),Peak Amplitude (mm),Center Position (mm),Coil Signal' (mV),Coil Signal" (mV),Range (mV),M. Quad. Signal (emu),M. Raw' (emu),M. Raw" (emu),Min. Temperature (K),Max. Temperature (K),Min. Field (Oe),Max. Field (Oe),Mass (grams),Motor Lag (deg),Pressure (Torr),VSM Status (code),Motor Status (code),Measure Status (code),Measure Count,PPMS Status (code),System Temp. (K),System Field (Oe),Sample Position (deg),Bridge 1 Resistance (ohms),Bridge 1 Excitation (에),Bridge 2 Resistance (ohms),Bridge 2 Excitation (에),Bridge 3 Resistance (ohms),Bridge 3 Excitation (에),Bridge 4 Resistance (ohms),Bridge 4 Excitation (에),Signal 1 Vin (V),Signal 2 Vin (V),Digital Inputs (code),Drive 1 Iout (mA),Drive 1 Ipower (W),Drive 2 Iout (mA),Drive 2 Ipower (W),Pressure (),Map 20 (),Map 21 (),Map 22 (),Map 23 (),Map 24 (),Map 25 (),Map 26 (),Map 27 (),Map 28 (),Map 29 ()
,26951929.87,349.6222534,99.7613830566406,5.0756328766985E-5,4.58717516987923E-7,1,0.999253354069792,40.0298881530762,1.9991634566921,18.8699997961521,0.000573647343695247,9.8776882123283E-5,0.25,-4.73562964886234E-8,5.06670137283716E-5,-1.89830993030176E-8,349.6222534,349.6222534,99.7613830566406,99.7613830566406,56.922878541506,20.5756158456325,26.705515,0,0,0,40,4369,350.25545,99.7613830566406,,,,,,,,,,,,,0,,,,0,,,,,,349.6222534,,,,
,26952083.345,346.9894714,99.7613830566406,5.15208238661598E-5,4.84143735985241E-7,1,0.999253354069792,40.0298881530762,1.99912707604877,18.8699997961521,0.000582381063891534,9.99722826773673E-5,0.25,-7.49982099261457E-8,5.1434740673068E-5,-4.5731795467826E-8,346.9894714,346.9894714,99.7613830566406,99.7613830566406,56.8939582862945,20.5702030108136,26.705515,0,0,0,40,4374,345.219,99.7613830566406,,,,,,,,,,,,,0,,,,0,,,,,,346.9894714,,,,
,26952232.44,343.4841003,99.7613830566406,5.24185809069719E-5,4.77873973794609E-7,1,0.999253354069792,40.0298881530762,1.99908512806404,18.8699997961521,0.000592191455726454,0.00010401340732238,0.25,1.2588093301701E-7,5.23371147987775E-5,1.55682264596775E-7,343.4841003,343.4841003,99.7613830566406,99.7613830566406,56.8087607776983,20.5675048534012,26.705515,0,0,0,40,4374,341.40715,99.7613830566406,,,,,,,,,,,,,0,,,,0,,,,,,343.4841003,,,,
,26952379.025,339.9579468,99.7613830566406,5.44262797602828E-5,4.62410830301649E-7,1,0.999253354069792,40.0298881530762,1.99902613442933,18.8699997961521,0.000615247872102913,0.000106171177658486,0.25,-3.21191722708265E-8,5.43483351070438E-5,-5.40429052648618E-10,339.9579468,339.9579468,99.7613830566406,99.7613830566406,56.6368025034675,20.5689896252964,27.085165,0,0,0,40,4374,337.5071,99.7613830566406,,,,,,,,,,,,,0,,,,-0.00245,,,,,,339.9579468,,,,
,26952522.97,336.4649353,99.7613830566406,5.50443141055757E-5,4.38327508324513E-7,1,0.999253354069792,40.0298881530762,1.99891119791574,18.8699997961521,0.000622993263066227,0.00010323545002605,0.25,-3.99854585040119E-7,5.49722989760033E-5,-3.67051620493392E-7,336.4649353,336.4649353,99.7613830566406,99.7613830566406,56.4367056025444,20.5694010918684,26.325863,0,0,0,40,4374,333.81155,99.7613830566406,,,,,,,,,,,,,0,,,,0,,,,,,336.4649353,,,,
,26952674.58,332.7927551,99.7613830566406,,,2,,,,18.8500002124906,,,,,,,332.7927551,332.7927551,99.7613830566406,99.7613830566406,,,26.325863,,,,-99999999,4374,329.9553,99.7613830566406,,,,,,,,,,,,,,,,,,,,,,,332.7927551,,,,
,26952809.24,329.463501,99.7613830566406,5.77932144050975E-5,4.84512388468346E-7,1,0.999253354069792,40.0298881530762,1.99907302272599,18.8400000333786,0.000654438091055163,0.000107712924202638,0.25,-4.83698680815231E-7,5.77316440207427E-5,-4.48442398402953E-7,329.463501,329.463501,99.7613830566406,99.7613830566406,56.8197035769676,20.5782384226571,27.085165,0,0,0,40,4374,326.5389,99.7613830566406,,,,,,,,,,,,,0,,,,0,,,,,,329.463501,,,,
,26952951.5,325.9636536,99.7613830566406,5.97256582494089E-5,5.26304502271018E-7,1,0.999253354069792,40.0298881530762,1.99872126258466,18.8400000333786,0.000675580142901812,0.000115405998507377,0.25,-1.38021046962035E-7,5.9669094252897E-5,-1.01530315540275E-7,325.9636536,325.9636536,99.7613830566406,99.7613830566406,56.4578095725637,20.5797793837829,26.325863,0,0,0,40,4374,322.9273,99.7613830566406,,,,,,,,,,,,,0,,,,-0.0049,,,,,,325.9636536,,,,
,26953098.2,322.3413696,99.7613830566406,,,2,,,,18.8599998229742,,,,,,,322.3413696,322.3413696,99.7613830566406,99.7613830566406,,,27.085165,,,,-99999999,4374,319.2473,99.7613830566406,,,,,,,,,,,,,,,,,,,,,,,322.3413696,,,,
,26953234.705,318.9918823,99.7613830566406,6.18875994093766E-5,4.07544800783578E-7,1,0.999253354069792,40.0298881530762,1.99872442216077,18.8400000333786,0.00070024622442589,0.00011938650995514,0.25,-1.64012746503021E-7,6.18441261772428E-5,-1.25233221338025E-7,318.9918823,318.9918823,99.7613830566406,99.7613830566406,56.6782288149868,20.5787470450854,26.705515,0,0,0,40,4374,315.80635,99.7613830566406,,,,,,,,,,,,,0,,,,0.00245,,,,,,318.9918823,,,,
,26953376.42,315.4634399,99.7613830566406,6.36585515533071E-5,4.37582580370725E-7,1,0.999253354069792,40.0298881530762,1.99884518462557,18.8400000333786,0.000720155776884039,0.000124323876863386,0.25,-3.67440948977384E-8,6.36216682139576E-5,3.58028849129416E-9,315.4634399,315.4634399,99.7613830566406,99.7613830566406,56.7259081546598,20.5775258640178,26.325863,0,0,0,40,4374,312.24975,99.7613830566406,,,,,,,,,,,,,0,,,,0,,,,,,315.4634399,,,,
,26953518.09,311.9692383,99.7613830566406,,,2,,,,18.8700003647804,,,,,,,311.9692383,311.9692383,99.7613830566406,99.7613830566406,,,26.705515,,,,-99999999,4374,308.6879,99.7613830566406,,,,,,,,,,,,,,,,,,,,,,,311.9692383,,,,
,26953638.76,308.9384766,99.7613830566406,6.65229838614971E-5,4.98878971797724E-7,1,0.999253354069792,40.0298881530762,1.99880955692483,18.8599992543459,0.000753331607952172,0.000126424922968398,0.25,-3.50668964727399E-7,6.65000083719129E-5,-3.0735064638187E-7,308.9384766,308.9384766,99.7613830566406,99.7613830566406,56.5492601093137,20.5726953152788,27.085165,0,0,0,40,4374,305.64895,99.7613830566406,,,,,,,,,,,,,0,,,,-0.0049,,,,,,308.9384766,,,,
,26953780.235,305.447937,99.7613830566406,6.79869310868867E-5,4.35604988943647E-7,1,0.999253354069792,40.0298881530762,1.99899291300432,18.8599992543459,0.00077000766542045,0.000129610740636026,0.25,-3.25748541802063E-7,6.79718626258545E-5,-2.80909811426736E-7,305.447937,305.447937,99.7613830566406,99.7613830566406,56.7063674416791,20.5747081245471,27.085165,0,0,0,40,4374,302.0998,99.7613830566406,,,,,,,,,,,,,0,,,,-0.00245,,,,,,305.447937,,,,
,26953919.54,301.9953613,99.7613830566406,6.96458435412825E-5,5.22749515888088E-7,1,0.999253354069792,40.0298881530762,1.9986743711268,18.8599992543459,0.000789251087513001,0.00013001164991937,0.25,-5.78044733862761E-7,6.96391343505473E-5,-5.31480187178853E-7,301.9953613,301.9953613,99.7613830566406,99.7613830566406,56.8181403199291,20.5774241071504,27.085165,0,0,0,40,4374,298.57675,99.7613830566406,,,,,,,,,,,,,0,,,,0,,,,,,301.9953613,,,,
,26954041.055,298.987915,99.7613830566406,7.11259750360892E-5,4.70363711899765E-7,1,0.999253354069792,40.0298881530762,1.99859123037862,18.8699997961521,0.000805166165429337,0.000138051720575021,0.25,-1.2540496447376E-7,7.11264426334232E-5,-7.73252537095103E-8,298.987915,298.987915,99.7613830566406,99.7613830566406,56.7774956369291,20.5790873481451,27.085165,0,0,0,40,4374,295.5365,99.7613830566406,,,,,,,,,,,,,0,,,,0,,,,,,298.987915,,,,
,26954183.2,295.4553528,99.7613830566406,7.30268041689494E-5,4.79891084691098E-7,1,0.999253354069792,40.0298881530762,1.99850074783049,18.8699997961521,0.000827221894896573,0.000139045116481437,0.25,-3.6872661388211E-7,7.30366633572716E-5,-3.18683465977327E-7,295.4553528,295.4553528,99.7613830566406,99.7613830566406,56.7610814380252,20.5794899978846,27.464817,0,0,0,40,4374,291.9646,99.7613830566406,,,,,,,,,,,,,0,,,,0.00245,,,,,,295.4553528,,,,
,26954323.02,291.9832764,99.7613830566406,7.51557533917792E-5,4.58087649448439E-7,1,0.999253354069792,40.0298881530762,1.99849857001218,18.8699997961521,0.00085060511106478,0.000147949814521254,0.25,4.67963905842451E-8,7.51749376873059E-5,9.91148816506323E-8,291.9832764,291.9832764,99.7613830566406,99.7613830566406,56.8556584888522,20.5803640385399,26.705515,0,0,0,40,4374,288.4591,99.7613830566406,,,,,,,,,,,,,0,,,,-0.0049,,,,,,291.9832764,,,,
,26954464.495,288.4610291,99.7613830566406,7.66924974397227E-5,4.19013444014938E-7,1,0.999253354069792,40.0298881530762,1.99852399809562,18.8900008797646,0.000869551683147322,0.000142721778553443,0.25,-6.8392389590307E-7,7.67222576672402E-5,-6.30008900123493E-7,288.4610291,288.4610291,99.7613830566406,99.7613830566406,56.9197520274291,20.5838705451751,26.705515,0,0,0,40,4374,284.9171,99.7613830566406,,,,,,,,,,,,,0,,,,-0.00245,,,,,,288.4610291,,,,
,26954604.235,284.9680481,99.7613830566406,7.84954199573302E-5,4.2173131301169E-7,1,0.999253354069792,40.0298881530762,1.99867203474724,18.8900008797646,0.000889419577646971,0.000150422590440984,0.25,-3.19559249353355E-7,7.85354319598113E-5,-2.6343939173052E-7,284.9680481,284.9680481,99.7613830566406,99.7613830566406,56.8658196596022,20.5843812485965,27.464817,0,0,0,40,4374,281.4163,99.7613830566406,,,,,,,,,,,,,0,,,,0.0049,,,,,,284.9680481,,,,
,26954745.26,281.47406005,99.7613830566406,8.07082366349782E-5,3.88317280612107E-7,1,0.999253354069792,40.0298881530762,1.99862014857045,18.8900008797646,0.000915443454574529,0.000149722396904138,0.25,-7.67115277781544E-7,8.07597978418737E-5,-7.08848134820482E-7,281.4473572,281.5007629,99.7613830566406,99.7613830566406,56.8728543162753,20.5864858926984,26.705515,0,0,0,40,4374,277.90005,99.7613830566406,,,,,,,,,,,,,0,,,,-0.0049,,,,,,281.47406005,,,,
,26954885.64,277.9682922,99.7613830566406,8.27110351412102E-5,5.48536561334618E-7,1,0.999253354069792,40.0298881530762,1.99871236717459,18.9100001007318,0.000936441383362622,0.000164299191124718,0.25,1.69615313684566E-7,8.27735602104374E-5,2.3088689176845E-7,277.9682922,277.9682922,99.7613830566406,99.7613830566406,56.9455457685637,20.5815889271307,26.705515,0,0,0,40,4374,274.3755,99.7613830566406,,,,,,,,,,,,,0,,,,0.0049,,,,,,277.9682922,,,,
,26955026,274.4834137,99.7613830566406,8.47236701967009E-5,3.91844096519311E-7,1,0.999253354069792,40.0298881530762,1.99876625242753,18.9100001007318,0.000960096927168188,0.000164142387478207,0.25,-1.96245260200904E-7,8.47985578254725E-5,-1.32807158892074E-7,274.4531555,274.5136719,99.7613830566406,99.7613830566406,56.6782288149868,20.5838067797349,27.085165,0,0,0,40,4374,270.8611,99.7613830566406,,,,,,,,,,,,,0,,,,-0.0049,,,,,,274.4834137,,,,
,26955168.235,270.9537964,99.7613830566406,8.63578634212514E-5,4.89415178076802E-7,1,0.999253354069792,40.0298881530762,1.99869297385401,18.9100001007318,0.000978659304748173,0.000167586958489641,0.25,-1.77822715753985E-7,8.64450787934562E-5,-1.1212360065432E-7,270.9537964,270.9537964,99.7613830566406,99.7613830566406,56.8939582862945,20.5841813676945,26.705515,0,0,0,40,4374,267.30505,99.7613830566406,,,,,,,,,,,,,0,,,,-0.0049,,,,,,270.9537964,,,,
,26955305.96,267.4947815,99.7613830566406,8.85494255673674E-5,4.0113340225191E-7,1,0.999253354069792,40.0298881530762,1.99869189779827,18.9399998635054,0.00100370758856565,0.000171348745923377,0.25,-2.28601830957863E-7,8.86498313958823E-5,-1.60251404614972E-7,267.4947815,267.4947815,99.7613830566406,99.7613830566406,56.9869720800829,20.5848865268444,27.085165,0,0,0,40,4374,263.8741,99.7613830566406,,,,,,,,,,,,,0,,,,-0.00245,,,,,,267.4947815,,,,
,26955448.14,263.9747925,99.7613830566406,9.12594147918905E-5,4.33384167438227E-7,1,0.999253354069792,40.0298881530762,1.9987399947305,18.9399998635054,0.00103480082417534,0.000175338277986372,0.25,-3.49774137215664E-7,9.13744382011824E-5,-2.78336080218844E-7,263.9747925,263.9747925,99.7613830566406,99.7613830566406,57.1010898438907,20.5850586149391,26.705515,0,0,0,40,4374,260.3031,99.7613830566406,,,,,,,,,,,,,0,,,,0.0049,,,,,,263.9747925,,,,
,26955588.99,260.4616089,99.7613830566406,9.33424296944561E-5,3.71965854331788E-7,1,0.999253354069792,40.0298881530762,1.99876599012901,18.9399998635054,0.00105858293892803,0.000179265743132328,0.25,-3.67721597204278E-7,9.34717605106067E-5,-2.93498443080268E-7,260.4616089,260.4616089,99.7613830566406,99.7613830566406,56.8228300910445,20.5851766238091,27.085165,0,0,0,40,4374,256.78655,99.7613830566406,,,,,,,,,,,,,0,,,,0,,,,,,260.4616089,,,,
,26955727.36,256.9745789,99.7613830566406,9.63434955064512E-5,3.88583213511273E-7,1,0.999253354069792,40.0298881530762,1.99854615764479,18.9599990844727,0.00109223744918783,0.00018734293707208,0.25,-1.76966898917892E-7,9.64887530753409E-5,-9.88296402277924E-8,256.9745789,256.9745789,99.7613830566406,99.7613830566406,56.5641110511791,20.5878850106452,26.705515,0,0,0,40,4374,253.32535,99.7613830566406,,,,,,,,,,,,,0,,,,-0.00245,,,,,,256.9745789,,,,
,26955868.89,253.474472,99.7613830566406,9.85652336241453E-5,3.99450789574921E-7,1,0.999253354069792,40.0298881530762,1.99867119316761,18.9599990844727,0.00111700354330059,0.000195311241192968,0.25,1.36327180641175E-7,9.8725795015266E-5,2.18126720330492E-7,253.474472,253.474472,99.7613830566406,99.7613830566406,57.0729512171983,20.5875826395026,27.464817,0,0,0,40,4374,249.79535,99.7613830566406,,,,,,,,,,,,,0,,,,-0.00245,,,,,,253.474472,,,,
,26956008.72,249.9766388,99.7613830566406,0.000101250813495978,3.80486332826417E-7,1,0.999253354069792,40.0298881530762,1.99881232719807,18.9599990844727,0.00114873641615855,0.000194447569934251,0.25,-4.10318992080991E-7,0.000101428712168459,-3.25797573052928E-7,249.9766388,249.9766388,99.7613830566406,99.7613830566406,57.044812590506,20.5856322847419,27.085165,0,0,0,40,4374,246.28095,99.7613830566406,,,,,,,,,,,,,0,,,,0.00245,,,,,,249.9766388,,,,
,26956148.13,246.4747162,99.7613830566406,0.000103705235179118,3.9256713590341E-7,1,0.999253354069792,40.0298881530762,1.99877948684512,18.9800001680851,0.00117583568426534,0.000204218959990222,0.25,2.24175136289113E-8,0.000103899850249,1.11276240841233E-7,246.4747162,246.4747162,99.7613830566406,99.7613830566406,56.9713395096983,20.5816968559551,26.705515,0,0,0,40,4374,242.7996,99.7613830566406,,,,,,,,,,,,,0,,,,-0.00245,,,,,,246.4747162,,,,
,26956287.625,242.9588013,99.7613830566406,0.000106255680056069,4.0203097542437E-7,1,0.999253354069792,40.0298881530762,1.99885048251678,18.9800001680851,0.00120536023450949,0.0002068649634541,0.25,-1.91059730150228E-7,0.000106468361561578,-9.884412099296E-8,242.9588013,242.9588013,99.7613830566406,99.7613830566406,56.892395029256,20.5820714852232,26.705515,0,0,0,40,4374,239.3199,99.7613830566406,,,,,,,,,,,,,0,,,,0,,,,,,242.9588013,,,,
,26956427.39,239.4914246,99.7613830566406,0.000109151090476065,3.99492717555639E-7,1,0.999253354069792,40.0298881530762,1.99870530150686,18.9800001680851,0.00123834245218488,0.000212091661889621,0.25,-2.3509370192435E-7,0.000109382810624854,-1.38768038499284E-7,239.4914246,239.4914246,99.7613830566406,99.7613830566406,57.2050464369484,20.5825465349494,26.705515,0,0,0,40,4374,235.8246,99.7613830566406,,,,,,,,,,,,,0,,,,0,,,,,,239.4914246,,,,
,26956547.975,236.4894714,99.7613830566406,0.00011140787969098,3.82137351750682E-7,1,0.999253354069792,40.0298881530762,1.99854619682345,19.0399996936321,0.00126349203449249,0.000219305703132012,0.25,7.40845729340731E-9,0.000111655791958426,1.0779613377421E-7,236.4894714,236.4894714,99.7613830566406,99.7613830566406,57.024490249006,20.5884614062883,27.085165,0,0,0,40,4374,232.8161,99.7613830566406,,,,,,,,,,,,,0,,,,-0.00245,,,,,,236.4894714,,,,
,26956688.685,232.9475403,99.7613830566406,0.000114564905876072,3.33588118500854E-7,1,0.999253354069792,40.0298881530762,1.99841451959654,19.0399996936321,0.00129869589175145,0.00022943837232869,0.25,3.49983489039023E-7,0.000114833564011152,4.55944106446487E-7,232.9475403,232.9475403,99.7613830566406,99.7613830566406,56.8884868866599,20.5869350514165,27.464817,0,0,0,40,4374,229.2919,99.7613830566406,,,,,,,,,,,,,0,,,,0,,,,,,232.9475403,,,,
,26956827.355,229.4931641,99.7613830566406,0.000117445383933753,4.09985326631333E-7,1,0.999253354069792,40.0298881530762,1.99867575443532,19.0399996936321,0.00133244759890029,0.000230798169107421,0.25,-3.68868922944952E-8,0.0001177351146959,7.28140194801708E-8,229.4931641,229.4931641,99.7613830566406,99.7613830566406,56.8267382336406,20.5882417205288,27.085165,0,0,0,40,4374,225.8277,99.7613830566406,,,,,,,,,,,,,0,,,,-0.00245,,,,,,229.4931641,,,,
,26956946.82,226.4726715,99.7613830566406,0.000119684312097738,3.95618661056265E-7,1,0.999253354069792,40.0298881530762,1.99846416081766,19.0699994564056,0.0013573060761825,0.0002383419490271,0.25,2.37688724300668E-7,0.000119991675362436,3.52009285238491E-7,226.4726715,226.4726715,99.7613830566406,99.7613830566406,56.7141837268714,20.5845422014782,27.085165,0,0,0,40,4374,222.8451,99.7613830566406,,,,,,,,,,,,,0,,,,0,,,,,,226.4726715,,,,
,26957087.72,222.9527893,99.7613830566406,0.00012260153883459,3.4759318437601E-7,1,0.999253354069792,40.0298881530762,1.99843749055242,19.0699994564056,0.00139123292786437,0.000240172488276577,0.25,-1.11780472615652E-7,0.000122931408508738,6.69555713623959E-9,222.9527893,222.9527893,99.7613830566406,99.7613830566406,56.7923465787945,20.5864722742032,27.464817,0,0,0,40,4374,219.3105,99.7613830566406,,,,,,,,,,,,,0,,,,0,,,,,,222.9527893,,,,
,26957227.35,219.459549,99.7613830566406,0.00012653606971978,3.11931597942441E-7,1,0.999253354069792,40.0298881530762,1.9984697540527,19.0699994564056,0.00143609595837449,0.000247772591965615,0.25,-1.30155251883044E-7,0.000126891474410413,-5.50690296460607E-9,219.459549,219.459549,99.7613830566406,99.7613830566406,56.7321611828137,20.5852413439173,27.085165,0,0,0,40,4374,215.83215,99.7613830566406,,,,,,,,,,,,,0,,,,-0.00245,,,,,,219.459549,,,,
,26957367.285,215.9484406,99.7613830566406,0.000129539696588499,3.71053885025703E-7,1,0.999253354069792,40.0298881530762,1.99842720429613,19.1099997609854,0.00147109980886347,0.000249232127369057,0.25,-5.27646559477708E-7,0.0001299191907373,-3.98609364181783E-7,215.9484406,215.9484406,99.7613830566406,99.7613830566406,56.7696793517368,20.5826638288435,27.085165,0,0,0,40,4374,212.3348,99.7613830566406,,,,,,,,,,,,,0,,,,0.00245,,,,,,215.9484406,,,,
,26957505.305,212.4881439,99.7613830566406,0.000132190889591874,4.18304543624616E-7,1,0.999253354069792,40.0298881530762,1.99848515421407,19.1099997609854,0.00150069062242248,0.000258580132486016,0.25,-1.70140249809587E-7,0.000132593003650808,-3.46796572602657E-8,212.4881439,212.4881439,99.7613830566406,99.7613830566406,56.8736359447945,20.581702233912,27.085165,0,0,0,40,4374,208.8887,99.7613830566406,,,,,,,,,,,,,0,,,,-0.00245,,,,,,212.4881439,,,,
,26957646,208.9707184,99.7613830566406,0.000135747560828411,3.89446318534314E-7,1,0.999253354069792,40.0298881530762,1.99854316781695,19.1099997609854,0.00154136823613046,0.000265117201683447,0.25,-2.1803798329616E-7,0.000136176298804449,-7.61154396242572E-8,208.9707184,208.9707184,99.7613830566406,99.7613830566406,56.8916134007368,20.5829814827258,26.705515,0,0,0,40,4374,205.379,99.7613830566406,,,,,,,,,,,,,0,,,,0,,,,,,208.9707184,,,,
,26957785.885,205.4876404,99.7613830566406,0.000138508973805353,3.51712105265188E-7,1,0.999253354069792,40.0298881530762,1.99843875793982,19.1500000655651,0.00157220995276248,0.000274059517067795,0.25,8.5524634789782E-8,0.00013896188217492,2.34473932743407E-7,205.4876404,205.4876404,99.7613830566406,99.7613830566406,56.8603482599676,20.5827292780511,26.705515,0,0,0,40,4374,201.88595,99.7613830566406,,,,,,,,,,,,,0,,,,-0.0049,,,,,,205.4876404,,,,
,26957925.52,201.9861755,99.7613830566406,0.000141879559175823,4.16330057775158E-7,1,0.999253354069792,40.0298881530762,1.99841498977628,19.1500000655651,0.00161124254415553,0.000277248932242766,0.25,-2.2475761801811E-7,0.000142359921784432,-6.9851997848604E-8,201.9861755,201.9861755,99.7613830566406,99.7613830566406,56.9369478548522,20.5827131944484,26.705515,0,0,0,40,4374,198.40035,99.7613830566406,,,,,,,,,,,,,0,,,,0.0049,,,,,,201.9861755,,,,
,26958064.75,198.47966,99.7613830566406,0.000144181174864596,3.62343976353329E-7,1,0.999253354069792,40.0298881530762,1.99838863126549,19.1500000655651,0.00163633898717894,0.000288708609595039,0.25,3.78728640962554E-7,0.000144684866402847,5.41833209491719E-7,198.47966,198.47966,99.7613830566406,99.7613830566406,56.7681160946983,20.5834131967936,26.705515,0,0,0,40,4374,194.9244,99.7613830566406,,,,,,,,,,,,,0,,,,0,,,,,,198.47966,,,,
,26958204.645,194.9793854,99.7613830566406,0.000147006485757638,2.97991292406507E-7,1,0.999253354069792,40.0298881530762,1.99856146091908,19.1799998283386,0.0016693510218341,0.000290826476599088,0.25,6.56336816363676E-8,0.000147536720234937,2.3468924755128E-7,194.9793854,194.9793854,99.7613830566406,99.7613830566406,56.7282530402175,20.5866523842475,26.705515,0,0,0,40,4374,191.4239,99.7613830566406,,,,,,,,,,,,,0,,,,0,,,,,,194.9793854,,,,
,26958345.28,191.4490662,99.7613830566406,0.000150435394380802,3.63160316020169E-7,1,0.999253354069792,40.0298881530762,1.99849797837563,19.1799998283386,0.00170787092144147,0.000300822146121597,0.25,3.43756297016924E-7,0.000150994313995604,5.21966298365524E-7,191.4490662,191.4490662,99.7613830566406,99.7613830566406,56.7102755842752,20.5885133893088,26.705515,0,0,0,40,4374,187.91275,99.7613830566406,,,,,,,,,,,,,0,,,,0.00245,,,,,,191.4490662,,,,
,26958485.46,187.9692383,99.7613830566406,0.000152494761068183,3.18893724851203E-7,1,0.999253354069792,40.0298881530762,1.99840237296973,19.1799998283386,0.00173276006636502,0.000296887734778599,0.25,-3.66566683958679E-7,0.000153078598512123,-1.84172221646946E-7,187.9692383,187.9692383,99.7613830566406,99.7613830566406,56.8165770628906,20.5920239724926,26.705515,0,0,0,40,4374,184.41315,99.7613830566406,,,,,,,,,,,,,0,,,,-0.0049,,,,,,187.9692383,,,,
,26958604.11,184.9839554,99.7613830566406,0.000154662758423937,3.44387212789488E-7,1,0.999253354069792,40.0298881530762,1.99813925061944,19.2499998956919,0.00175701318044641,0.000302941000379243,0.25,-2.13501636164621E-7,0.000155268823450952,-2.39106672703282E-8,184.9557495,185.0121613,99.7613830566406,99.7613830566406,56.7751507513714,20.5916526361522,26.325863,0,0,0,40,4374,181.4429,99.7613830566406,,,,,,,,,,,,,0,,,,0,,,,,,184.9839554,,,,
,26958746.42,181.4465332,99.7613830566406,0.000157026687874946,3.53779349999343E-7,1,0.999253354069792,40.0298881530762,1.99774784397458,19.2499998956919,0.00178351694914633,0.000308737835944937,0.25,-1.17003752828376E-7,0.000157658631986966,8.10506542992914E-8,181.4465332,181.4465332,99.7613830566406,99.7613830566406,56.6969878994483,20.5938340671493,26.325863,0,0,0,40,4374,177.85425,99.7613830566406,,,,,,,,,,,,,0,,,,-0.00245,,,,,,181.4465332,,,,
,26958885.07,177.9818573,99.7613830566406,0.000158326153953194,4.04642315137583E-7,1,0.999253354069792,40.0298881530762,1.99781312551604,19.2499998956919,0.00179820956641907,0.00031310133892856,0.25,3.23288620083546E-8,0.000158979427423696,2.37938028841469E-7,177.9818573,177.9818573,99.7613830566406,99.7613830566406,56.8751992018329,20.5955410479808,25.946213,0,0,0,40,4374,174.41315,99.7613830566406,,,,,,,,,,,,,0,,,,0,,,,,,177.9818573,,,,
,26959002.43,174.9949799,99.7613830566406,0.000160044016588865,3.35724698980985E-7,1,0.999253354069792,40.0298881530762,1.99800606603778,19.3000007420778,0.00181819734463216,0.000315686984920291,0.25,-4.8523361328754E-8,0.000160718479767754,1.63784078589492E-7,174.9949799,174.9949799,99.7613830566406,99.7613830566406,56.6704125297944,20.5912360991809,25.946213,0,0,0,40,4374,171.48865,99.7613830566406,,,,,,,,,,,,,0,,,,-0.00245,,,,,,174.9949799,,,,
,26959143.475,171.4642181,99.7613830566406,0.000161527711329656,3.22750940739988E-7,1,0.999253354069792,40.0298881530762,1.99807165154243,19.3000007420778,0.00183550587083543,0.000317451095981982,0.25,-1.61092914192733E-7,0.000162224992696088,5.8826231274666E-8,171.4642181,171.4642181,99.7613830566406,99.7613830566406,56.5781803645252,20.5938507483551,26.325863,0,0,0,40,4374,167.9886,99.7613830566406,,,,,,,,,,,,,0,,,,0,,,,,,171.4642181,,,,
,26959280.485,167.9920959,99.7613830566406,0.000162305009458921,4.09165929347167E-7,1,0.999253354069792,40.0298881530762,1.99793169689567,19.3000007420778,0.00184375502021806,0.000322669847006788,0.25,1.55811156230714E-7,0.000163021125925658,3.8455133885245E-7,167.9920959,167.9920959,99.7613830566406,99.7613830566406,56.4593728296021,20.5984959944532,25.946213,0,0,0,40,4374,164.57915,99.7613830566406,,,,,,,,,,,,,0,,,,-0.00245,,,,,,167.9920959,,,,
,26959400.055,164.9761353,99.7613830566406,0.000163727631355412,2.93800276863943E-7,1,0.999253354069792,40.0298881530762,1.99788624695428,19.3600002676249,0.00186023678141314,0.0003243308850397,0.25,4.6803028934031E-8,0.000164463860545397,2.82997088566547E-7,164.9761353,164.9761353,99.7613830566406,99.7613830566406,56.4156016325252,20.5939294810806,25.946213,0,0,0,40,4374,161.61,99.7613830566406,,,,,,,,,,,,,0,,,,0,,,,,,164.9761353,,,,
,26959539.745,161.4704132,99.7613830566406,0.000164723357457984,3.36014799977585E-7,1,0.999253354069792,40.0298881530762,1.99781215683777,19.3600002676249,0.00187147419508485,0.000327395557181527,0.25,1.34148646555374E-7,0.000165479592439751,3.79597266360492E-7,161.4704132,161.4704132,99.7613830566406,99.7613830566406,56.9674313671022,20.5952921773088,25.566563,0,0,0,40,4374,158.135,99.7613830566406,,,,,,,,,,,,,0,,,,-0.0049,,,,,,161.4704132,,,,
,26959680.21,157.9661255,99.7613830566406,0.000165217527528334,3.02634783678087E-7,1,0.999253354069792,40.0298881530762,1.99797101851464,19.3600002676249,0.00187712924621875,0.000330011902475034,0.25,2.6553791966832E-7,0.000165991127494795,5.20355863642335E-7,157.9661255,157.9661255,99.7613830566406,99.7613830566406,56.4195097751214,20.5925558876494,26.325863,0,0,0,40,4374,154.63315,99.7613830566406,,,,,,,,,,,,,0,,,,0.00245,,,,,,157.9661255,,,,
,26959818.275,154.4951324,99.7613830566406,0.000165802830842832,3.41174465363166E-7,1,0.999253354069792,40.0298881530762,1.99808262793993,19.4099992513657,0.00188426494246058,0.000329977961552226,0.25,1.4808422236169E-7,0.000166594159371854,4.11732220773605E-7,154.4951324,154.4951324,99.7613830566406,99.7613830566406,56.4195097751214,20.5904897827529,25.946213,0,0,0,40,4374,151.1849,99.7613830566406,,,,,,,,,,,,,0,,,,0,,,,,,154.4951324,,,,
,26959958.985,150.9539642,99.7613830566406,0.000165903048485755,3.86298193619305E-7,1,0.999253354069792,40.0298881530762,1.99827778147911,19.4099992513657,0.00188561077654513,0.000331011951609549,0.25,2.07163656858786E-7,0.000166709433358033,4.80491684544009E-7,150.9539642,150.9539642,99.7613830566406,99.7613830566406,56.6274229612368,20.5928075156561,25.946213,0,0,0,40,4374,147.6862,99.7613830566406,,,,,,,,,,,,,0,,,,0.0049,,,,,,150.9539642,,,,
,26960097.695,147.4725952,99.7613830566406,0.000166454079607071,3.64421511845247E-7,1,0.999253354069792,40.0298881530762,1.99809389155905,19.4099992513657,0.00189189296078966,0.000331954090885345,0.25,1.84384106227752E-7,0.000167277161022375,4.68345868860644E-7,147.4725952,147.4725952,99.7613830566406,99.7613830566406,56.8751992018329,20.5932349922443,25.186911,0,0,0,40,4374,144.22895,99.7613830566406,,,,,,,,,,,,,0,,,,0.00245,,,,,,147.4725952,,,,
,26960238.985,143.9325409,99.7613830566406,0.000166602573244714,3.76195457674685E-7,1,0.999253354069792,40.0298881530762,1.99822341072239,19.4600000977516,0.0018935631219762,0.000333959679048939,0.25,3.19994059153768E-7,0.000167439838507586,6.15690042973635E-7,143.9325409,143.9325409,99.7613830566406,99.7613830566406,56.9275683126214,20.5885898617913,25.186911,0,0,0,40,4374,140.7091,99.7613830566406,,,,,,,,,,,,,0,,,,0,,,,,,143.9325409,,,,
,26960375.315,140.4870453,99.7613830566406,0.000166865234344636,3.8244844661426E-7,1,0.999253354069792,40.0298881530762,1.99815286358953,19.4600000977516,0.0018969287678154,0.000332784611022617,0.25,1.58416573170281E-7,0.000167716906432322,4.6502503446218E-7,140.4870453,140.4870453,99.7613830566406,99.7613830566406,56.8744175733137,20.5904561658477,25.566563,0,0,0,40,4374,137.31135,99.7613830566406,,,,,,,,,,,,,0,,,,0.00245,,,,,,140.4870453,,,,
,26960516.22,136.9468231,99.7613830566406,0.000166667893450105,2.58338139944033E-7,1,0.999253354069792,40.0298881530762,1.99821735184385,19.4600000977516,0.00189468431556042,0.000333577481805612,0.25,2.47050314243195E-7,0.000167530877151637,5.66289537933295E-7,136.9468231,136.9468231,99.7613830566406,99.7613830566406,57.2042648084291,20.5904698576468,25.186911,0,0,0,40,4374,133.8088,99.7613830566406,,,,,,,,,,,,,0,,,,-0.00245,,,,,,136.9468231,,,,
,26960655.14,133.4614716,99.7613830566406,0.000166577725092654,3.48169488659418E-7,1,0.999253354069792,40.0298881530762,1.99794978253815,19.5300001651049,0.00189404459151261,0.000330536118208707,0.25,-1.62740235865853E-8,0.00016745233737517,3.14811703903528E-7,133.4614716,133.4614716,99.7613830566406,99.7613830566406,57.0690430746022,20.5867353762174,25.566563,0,0,0,40,4374,130.3539,99.7613830566406,,,,,,,,,,,,,0,,,,0,,,,,,133.4614716,,,,
,26960794.835,129.9500427,99.7613830566406,0.000166589542915078,3.69717365008663E-7,1,0.999253354069792,40.0298881530762,1.99794585483799,19.5300001651049,0.0018938605173233,0.0003330904559002,0.25,1.89919064902289E-7,0.000167474686760386,5.36765481388793E-7,129.9500427,129.9500427,99.7613830566406,99.7613830566406,56.9150622563137,20.5899255741857,24.427608,0,0,0,40,4374,126.8753,99.7613830566406,,,,,,,,,,,,,0,,,,0.0049,,,,,,129.9500427,,,,
,26960931.375,126.4993668,99.7613830566406,0.000166634823581652,3.01303168194414E-7,1,0.999253354069792,40.0298881530762,1.99768736652177,19.5300001651049,0.00189474864432717,0.000330325290741486,0.25,-7.47800810106123E-8,0.000167530639790151,2.86325275429786E-7,126.4993668,126.4993668,99.7613830566406,99.7613830566406,56.6844818431406,20.5964399138074,25.186911,0,0,0,40,4374,123.47605,99.7613830566406,,,,,,,,,,,,,0,,,,0.0049,,,,,,126.4993668,,,,
,26961070.76,122.9931564,99.7613830566406,0.000166866467344484,3.04714530947397E-7,1,0.999253354069792,40.0298881530762,1.99746464818951,19.6000002324581,0.00189691068004818,0.000332898790712173,0.25,9.53763290335187E-8,0.000167772193223615,4.75247668095399E-7,122.9931564,122.9931564,99.7613830566406,99.7613830566406,56.8814522299868,20.5939622904662,24.427608,0,0,0,40,4374,120.01105,99.7613830566406,,,,,,,,,,,,,0,,,,-0.0049,,,,,,122.9931564,,,,
,26961212.535,119.4453659,99.7613830566406,0.000166592289329324,3.29768098154971E-7,1,0.999253354069792,40.0298881530762,1.99781575203528,19.6000002324581,0.00189416804719887,0.000332617589379288,0.25,9.31975252392202E-8,0.000167504486477066,4.91657164670208E-7,119.4453659,119.4453659,99.7613830566406,99.7613830566406,57.1331366131791,20.5929908803609,24.427608,0,0,0,40,4374,116.49915,99.7613830566406,,,,,,,,,,,,,0,,,,0,,,,,,119.4453659,,,,
,26961349,115.9692459,99.7613830566406,0.000166474238436338,3.24981002866477E-7,1,0.999253354069792,40.0298881530762,1.99799479745012,19.6000002324581,0.00189327101669218,0.000331235712324507,0.25,-3.14953678533861E-8,0.000167392707929769,3.86303898403903E-7,115.9692459,115.9692459,99.7613830566406,99.7613830566406,56.8705094307176,20.5927379022863,24.427608,0,0,0,40,4374,113.11355,99.7613830566406,,,,,,,,,,,,,0,,,,0,,,,,,115.9692459,,,,
,26961469.155,112.946312,99.7613830566406,0.000166712173315367,3.44542138861468E-7,1,0.999253354069792,40.0298881530762,1.99800461307347,19.6599997580051,0.00189566400095511,0.000333848147111019,0.25,1.36164216486948E-7,0.000167635988795382,5.75066203678338E-7,112.946312,112.946312,99.7613830566406,99.7613830566406,57.187068981006,20.5877131928587,24.807261,0,0,0,40,4374,110.127,99.7613830566406,,,,,,,,,,,,,0,,,,-0.0049,,,,,,112.946312,,,,
,26961608.015,109.4723434,99.7613830566406,0.000166641529723301,3.31329977190136E-7,1,0.999253354069792,40.0298881530762,1.99789254865658,19.6599997580051,0.00189449239112437,0.000335443533323691,0.25,2.65187926552073E-7,0.000167568036711502,7.29378645639092E-7,109.4723434,109.4723434,99.7613830566406,99.7613830566406,56.7571732954291,20.5902113694926,24.047956,0,0,0,40,4374,106.67665,99.7613830566406,,,,,,,,,,,,,0,,,,0.0049,,,,,,109.4723434,,,,
,26961746.655,105.9433441,99.7613830566406,0.000166980559683737,3.31145314179179E-7,1,0.999253354069792,40.0298881530762,1.99789218200443,19.6599997580051,0.0018983867327124,0.000336009161878207,0.25,2.28048603543896E-7,0.000167910685631244,7.202429295778E-7,105.9433441,105.9433441,99.7613830566406,99.7613830566406,56.9682129956214,20.5916706438955,23.668306,0,0,0,40,4374,103.242,99.7613830566406,,,,,,,,,,,,,0,,,,0,,,,,,105.9433441,,,,
,26961884.095,102.482254,99.7613830566406,0.000167166474812199,2.93432164884406E-7,1,0.999253354069792,40.0298881530762,1.99785562468223,19.7299998253584,0.00190012262066101,0.000338278923480889,0.25,3.65836391257161E-7,0.000168096227280194,8.89354732569757E-7,102.482254,102.482254,99.7613830566406,99.7613830566406,57.0221453634483,20.5912519535818,24.047956,0,0,0,40,4374,99.8279,99.7613830566406,,,,,,,,,,,,,0,,,,0.00245,,,,,,102.482254,,,,
,26962023.96,98.9325638,99.7613830566406,0.000167170694894681,3.55089939130528E-7,1,0.999253354069792,40.0298881530762,1.99776538532467,19.7299998253584,0.00189969561837118,0.000340258436523251,0.25,5.0759474489701E-7,0.00016809614486989,1.06562507351575E-6,98.9325638,98.9325638,99.7613830566406,99.7613830566406,57.0776409883137,20.5904876495853,23.668306,0,0,0,40,4374,96.36405,99.7613830566406,,,,,,,,,,,,,0,,,,0.00245,,,,,,98.9325638,,,,
,26962160.555,95.4855423,99.7613830566406,0.00016745095968476,3.31281140567352E-7,1,0.999253354069792,40.0298881530762,1.99781944671712,19.7299998253584,0.00190301768234226,0.00033985676590419,0.25,3.87045169537669E-7,0.000168370988411147,9.81914417366266E-7,95.4855423,95.4855423,99.7613830566406,99.7613830566406,57.0487207331022,20.592242544745,23.668306,0,0,0,40,4374,92.9814,99.7613830566406,,,,,,,,,,,,,0,,,,-0.00245,,,,,,95.4855423,,,,
,26962302.44,91.9483109,99.7613830566406,0.000167507326607968,3.50793940576276E-7,1,0.999253354069792,40.0298881530762,1.99769483290093,19.7999998927116,0.00190350807252716,0.00033935258343611,0.25,2.94595366454033E-7,0.000168415636195226,9.314318144398E-7,91.9483109,91.9483109,99.7613830566406,99.7613830566406,56.9603967104291,20.5900498818147,22.909004,0,0,0,40,4374,89.46415,99.7613830566406,,,,,,,,,,,,,0,,,,-0.00245,,,,,,91.9483109,,,,
,26962440.61,88.3959579,99.7613830566406,0.000167768259130712,3.31448084751558E-7,1,0.999253354069792,40.0298881530762,1.9975987838548,19.7999998927116,0.00190576252850877,0.000342274991214126,0.25,4.64563900649913E-7,0.000168660178170661,1.14893535006195E-6,88.3959579,88.3959579,99.7613830566406,99.7613830566406,57.2621053188522,20.5903488558709,23.288654,0,0,0,40,4374,86.05225,99.7613830566406,,,,,,,,,,,,,0,,,,0,,,,,,88.3959579,,,,
,26962578.08,84.9301453,99.7613830566406,0.000167979654477981,3.59342337509951E-7,1,0.999253354069792,40.0298881530762,1.99755588515656,19.7999998927116,0.00190799184294255,0.000341878184292145,0.25,3.46882384635742E-7,0.000168849123810216,1.08187095139052E-6,84.9301453,84.9301453,99.7613830566406,99.7613830566406,56.9963516223137,20.5915653871726,23.288654,0,0,0,40,4374,82.6525,99.7613830566406,,,,,,,,,,,,,0,,,,-0.00245,,,,,,84.9301453,,,,
,26962714.785,81.4588852,99.7613830566406,0.000167763631393547,4.04737850010546E-7,1,0.999253354069792,40.0298881530762,1.9975452962756,19.8699999600649,0.00190538484604879,0.0003401710961868,0.25,1.85944989043602E-7,0.00016860089965155,9.73957843251642E-7,81.4588852,81.4588852,99.7613830566406,99.7613830566406,56.6922981283329,20.5925652696939,22.529354,0,0,0,40,4374,79.2903,99.7613830566406,,,,,,,,,,,,,0,,,,0,,,,,,81.4588852,,,,
,26962852.28,77.9855576,99.7613830566406,0.000167884512927958,3.16777730296069E-7,1,0.999253354069792,40.0298881530762,1.99773142189455,19.8699999600649,0.00190587972777728,0.000343568387363507,0.25,4.08032127978671E-7,0.000168678709810041,1.25814395426434E-6,77.9855576,77.9855576,99.7613830566406,99.7613830566406,56.9416376259676,20.5947287366721,22.529354,0,0,0,40,4374,75.8928,99.7613830566406,,,,,,,,,,,,,0,,,,0.00245,,,,,,77.9855576,,,,
,26962992.235,74.3860931,99.7613830566406,0.000168211541994044,3.67002540400907E-7,1,0.999253354069792,40.0298881530762,1.99765279067651,19.8699999600649,0.00190931595368793,0.000341724746132694,0.25,1.32490226756221E-7,0.000168952691870362,1.04903539998176E-6,74.3860931,74.3860931,99.7613830566406,99.7613830566406,57.1472059265253,20.5957935278354,22.149702,0,0,0,40,4374,72.4531,99.7613830566406,,,,,,,,,,,,,0,,,,-0.0049,,,,,,74.3860931,,,,
,26963126.53,70.9955368,99.7613830566406,0.000168223477431217,3.23433240140196E-7,1,0.999253354069792,40.0298881530762,1.99759595220613,19.9400000274181,0.00190783019407081,0.000346069131271885,0.25,4.59553136783513E-7,0.000168894100120609,1.4439942773689E-6,70.9955368,70.9955368,99.7613830566406,99.7613830566406,56.9861904515637,20.5923298336075,22.529354,0,0,0,40,4374,69.16305,99.7613830566406,,,,,,,,,,,,,0,,,,0.00245,,,,,,70.9955368,,,,
,26963263.785,67.4786606,99.7613830566406,0.000168421186199726,4.05993958921096E-7,1,0.999253354069792,40.0298881530762,1.99779414309082,19.9400000274181,0.00190911351744991,0.000347133125532947,0.25,4.61273804364932E-7,0.000169004019624937,1.51617254284936E-6,67.4786606,67.4786606,99.7613830566406,99.7613830566406,57.2449094914291,20.5958223271669,21.770052,0,0,0,40,4374,65.78845,99.7613830566406,,,,,,,,,,,,,0,,,,0,,,,,,67.4786606,,,,
,26963400.235,63.9962311,99.7613830566406,0.000168791808026952,3.02481574308783E-7,1,0.999253354069792,40.0298881530762,1.99751379301781,19.9400000274181,0.00191195320831809,0.000346971860153601,0.25,3.37058175183037E-7,0.000169268035333039,1.46046349841621E-6,63.9962311,63.9962311,99.7613830566406,99.7613830566406,56.8283014906791,20.5938545030789,22.149702,0,0,0,40,4374,62.4364,99.7613830566406,,,,,,,,,,,,,0,,,,0,,,,,,63.9962311,,,,
,26963538.125,60.4805145,99.7613830566406,0.000168724817174683,3.36340472442912E-7,1,0.999253354069792,40.0298881530762,1.99736579059391,20.0100000947714,0.00190863438470636,0.000351786341397919,0.25,7.39701063102936E-7,0.000169066416952271,1.92305578260646E-6,60.4805145,60.4805145,99.7613830566406,99.7613830566406,56.8040710065829,20.5895647970321,21.770052,0,0,0,40,4374,59.0538,99.7613830566406,,,,,,,,,,,,,0,,,,0,,,,,,60.4805145,,,,
,26963675.75,56.97015,99.7613830566406,0.000169129619668979,3.31694981761914E-7,1,0.999253354069792,40.0298881530762,1.99752743017012,20.0100000947714,0.00191160122286696,0.000352527410520711,0.25,7.1122290936814E-7,0.000169319019373428,1.9425704974135E-6,56.97015,56.97015,99.7613830566406,99.7613830566406,57.1073428720445,20.5925623947218,21.3904,0,0,0,40,4374,55.6704,99.7613830566406,,,,,,,,,,,,,0,,,,-0.00245,,,,,,56.97015,,,,
,26963811.725,53.488945,99.7613830566406,0.000168981174398898,3.77981468982824E-7,1,0.999253354069792,40.0298881530762,1.99725973699245,20.0100000947714,0.00190812604308272,0.000350005907121573,0.25,5.23494254506956E-7,0.000169004962499073,1.77782859196468E-6,53.488945,53.488945,99.7613830566406,99.7613830566406,57.1221938139099,20.5918128083215,21.3904,0,0,0,40,4374,52.34345,99.7613830566406,,,,,,,,,,,,,0,,,,0.00245,,,,,,53.488945,,,,
,26963950.85,49.9576378,99.7613830566406,0.000169366068795067,3.50552200822598E-7,1,0.999253354069792,40.0298881530762,1.99735730208636,20.0599990785122,0.0019106278211986,0.00034989595081658,0.25,4.75014588690765E-7,0.000169210230772792,1.73124064280996E-6,49.9576378,49.9576378,99.7613830566406,99.7613830566406,57.200356665833,20.5925823150225,20.631098,0,0,0,40,4374,48.9371,99.7613830566406,,,,,,,,,,,,,0,,,,0,,,,,,49.9576378,,,,
,26964085.305,46.480423,99.7613830566406,0.000169655619402894,3.14926842250969E-7,1,0.999253354069792,40.0298881530762,1.99737617969811,20.0599990785122,0.00191158743381398,0.000352300235190768,0.25,6.92365065229793E-7,0.000169326706562711,1.92341248192174E-6,46.480423,46.480423,99.7613830566406,99.7613830566406,57.1784710672945,20.5928957513855,19.871798,0,0,0,40,4370,45.66735,99.7613830566406,,,,,,,,,,,,,0,,,,0,,,,,,46.480423,,,,
,26964222.57,42.9839516,99.7613830566406,0.000169412434327369,3.58172985826317E-7,1,0.999253354069792,40.0298881530762,1.99720593463116,20.0599990785122,0.00190709166459172,0.000350048455813945,0.25,6.18411927518953E-7,0.000168921130862768,1.79685340785163E-6,42.9839516,42.9839516,99.7613830566406,99.7613830566406,56.8666012881214,20.5979330363943,18.353191,0,0,0,40,4370,42.3051,99.7613830566406,,,,,,,,,,,,,0,,,,-0.00245,,,,,,42.9839516,,,,
,26964340.805,39.9767723,99.7613830566406,0.000169575673104139,3.58675489823337E-7,1,0.999253354069792,40.0298881530762,1.99728878039227,20.1099999248981,0.00190829115372744,0.000346226568645594,0.25,3.28025031691914E-7,0.000168960797072769,1.45089295041881E-6,39.9767723,39.9767723,99.7613830566406,99.7613830566406,56.9111541137176,20.5986089209529,18.353191,0,0,0,40,4370,39.38245,99.7613830566406,,,,,,,,,,,,,0,,,,-0.00245,,,,,,39.9767723,,,,
,26964479.135,36.4443932,99.7613830566406,0.00016968455722309,3.28921229708802E-7,1,0.999253354069792,40.0298881530762,1.99743178268261,20.1099999248981,0.00190746556921697,0.000350722387798416,0.25,8.01781402210344E-7,0.000168944984913438,1.84897469221955E-6,36.4443932,36.4443932,99.7613830566406,99.7613830566406,56.9979148793522,20.5985010158823,17.593889,0,0,0,40,4370,35.966,99.7613830566406,,,,,,,,,,,,,0,,,,0.0049,,,,,,36.4443932,,,,
,26964616.22,32.9615326,99.7613830566406,0.00016975722788298,3.15941209669929E-7,1,0.999253354069792,40.0298881530762,1.9976026477563,20.1099999248981,0.00190754357881713,0.000349840260220128,0.25,7.96575659338372E-7,0.000168924822028373,1.77194685873496E-6,32.9615326,32.9615326,99.7613830566406,99.7613830566406,57.024490249006,20.5964472295649,17.214239,0,0,0,40,4370,32.57805,99.7613830566406,,,,,,,,,,,,,0,,,,-0.0049,,,,,,32.9615326,,,,
,26964736.045,29.9357224,99.7613830566406,0.000169915989476359,2.77618126759171E-7,1,0.999253354069792,40.0298881530762,1.99763488602664,20.1600007712841,0.00190883901284872,0.000349124204830354,0.25,7.70856814138332E-7,0.000169022810405662,1.69126466670233E-6,29.9357224,29.9357224,99.7613830566406,99.7613830566406,56.668849272756,20.5932507407448,17.214239,0,0,0,40,4370,29.60075,99.7613830566406,,,,,,,,,,,,,0,,,,-0.0049,,,,,,29.9357224,,,,
,26964874.5,26.4778156,99.7613830566406,0.000169630982192607,3.42407822375204E-7,1,0.999253354069792,40.0298881530762,1.99752629886139,20.1600007712841,0.00190529672433577,0.000346746326695453,0.25,6.71196348462068E-7,0.000168692273598677,1.53970636015222E-6,26.4778156,26.4778156,99.7613830566406,99.7613830566406,57.2910255740638,20.598871994991,16.075285,0,0,0,40,4370,26.1849,99.7613830566406,,,,,,,,,,,,,0,,,,0,,,,,,26.4778156,,,,
,26965011.76,22.9982548,99.7613830566406,0.000169825179771998,3.13764183725778E-7,1,0.999253354069792,40.0298881530762,1.99737522416959,20.1600007712841,0.00190822643400322,0.000340260708478265,0.25,1.01231790564309E-7,0.000168859874960396,9.39630574761465E-7,22.9982548,22.9982548,99.7613830566406,99.7613830566406,57.0369963053137,20.5992094279505,15.315984,0,0,0,40,4370,22.77965,99.7613830566406,,,,,,,,,,,,,0,,,,-0.00245,,,,,,22.9982548,,,,
,26965153.5,19.4484425,99.7613830566406,0.000170039705751479,3.71927072846506E-7,1,0.999253354069792,40.0298881530762,1.99739628653013,20.1799999922514,0.00190984109860992,0.000344427882349801,0.25,4.53895378097089E-7,0.000169058529118417,1.27344214666113E-6,19.4484425,19.4484425,99.7613830566406,99.7613830566406,57.1987934087945,20.5989896479862,14.936333,0,0,0,40,4370,19.25215,99.7613830566406,,,,,,,,,,,,,0,,,,0,,,,,,19.4484425,,,,
,26965293.915,15.9352579,99.7613830566406,0.000170193359538235,3.24830399112544E-7,1,0.999253354069792,40.0298881530762,1.99743006023664,20.1799999922514,0.0019114813401794,0.000345418066639593,0.25,5.16293369159132E-7,0.000169211279562047,1.33412505386139E-6,15.9352579,15.9352579,99.7613830566406,99.7613830566406,56.8408075469868,20.6026457409695,14.936333,0,0,0,40,4370,15.76675,99.7613830566406,,,,,,,,,,,,,0,,,,0,,,,,,15.9352579,,,,
,26965431.28,12.4481535,99.7613830566406,0.000169864366217526,3.17690430927031E-7,1,0.999253354069792,40.0298881530762,1.9975259777208,20.1799999922514,0.00190789976127885,0.000344721077594572,0.25,5.11004051860286E-7,0.000168885747813405,1.32729164395928E-6,12.4481535,12.4481535,99.7613830566406,99.7613830566406,57.0416860764291,20.601461707469,13.797379,0,0,0,40,4370,12.3098,99.7613830566406,,,,,,,,,,,,,0,,,,-0.00245,,,,,,12.4481535,,,,
,26965668.905,10.0063915,99.7613830566406,0.000170283942150752,3.08512002018289E-7,1,0.999253354069792,40.0298881530762,1.99790213712714,20.2099997550249,0.00191240521409073,0.000348787900395227,0.25,7.92663128769341E-7,0.000169302328159705,1.6093630136656E-6,10.0063915,10.0063915,99.7613830566406,99.7613830566406,56.9158438848329,20.5913515656649,12.658426,0,0,0,40,4369,9.98885,99.7613830566406,,,,,,,,,,,,,0,,,,0,,,,,,10.0063915,,,,