File: data/monolayers/nanoparticles/Ol_CoFe_C/vsm/rawdata/DD172_6_HYST_10K_FC_1T.DAT
[Header]
; VSM Data File (default extension .dat)
; Copyright (c) 2003-2013, Quantum Design, Inc. All rights reserved.
TITLE,
FILEOPENTIME,26985172.02,11/09/2018,3:52 pm
BYAPP,VSM,2.0,2.0
INFO,PPMS VSM Option Release 1.4.10 Build 1,APPNAME
INFO,Quantum Design Linear Motor Servo Controller,MOTOR_MODULE_NAME
INFO,3101-100 M1,MOTOR_HW_VERSION
INFO,MMC1014,MOTOR_SERIAL_NUMBER
INFO,SRV No X-over 01.03.11,MOTOR_SOFTWARE_VERSION
INFO,Quantum Design VSM Detection Module,VSM_MODULE_NAME
INFO,3101-150 F0,VSM_HW_VERSION
INFO,VSM707,VSM_SERIAL_NUMBER
INFO,VSM No X-over 01.02.05 May 20 2008 13:51:47,VSM_SOFTWARE_VERSION
INFO,704,PREAMP_SERIAL_NUMBER
INFO,822,COIL_SERIAL_NUMBER
INFO,0,MOMENT_UNITS
INFO,CoFe2O4 DD67,SAMPLE_MATERIAL
INFO,Colloidal Crystal,SAMPLE_COMMENT
INFO,31.86,SAMPLE_MASS
INFO,,SAMPLE_VOLUME
INFO,,SAMPLE_MOLECULAR_WEIGHT
INFO,,SAMPLE_SIZE
INFO,,SAMPLE_SHAPE
DATATYPE,COMMENT,1
DATATYPE,TIME,2
STARTUPAXIS,X,2
STARTUPAXIS,Y1,5
[Data]
Comment,Time Stamp (sec),Temperature (K),Magnetic Field (Oe),Moment (emu),M. Std. Err. (emu),Transport Action,Averaging Time (sec),Frequency (Hz),Peak Amplitude (mm),Center Position (mm),Coil Signal' (mV),Coil Signal" (mV),Range (mV),M. Quad. Signal (emu),M. Raw' (emu),M. Raw" (emu),Min. Temperature (K),Max. Temperature (K),Min. Field (Oe),Max. Field (Oe),Mass (grams),Motor Lag (deg),Pressure (Torr),VSM Status (code),Motor Status (code),Measure Status (code),Measure Count,PPMS Status (code),System Temp. (K),System Field (Oe),Sample Position (deg),Bridge 1 Resistance (ohms),Bridge 1 Excitation (에),Bridge 2 Resistance (ohms),Bridge 2 Excitation (에),Bridge 3 Resistance (ohms),Bridge 3 Excitation (에),Bridge 4 Resistance (ohms),Bridge 4 Excitation (에),Signal 1 Vin (V),Signal 2 Vin (V),Digital Inputs (code),Drive 1 Iout (mA),Drive 1 Ipower (W),Drive 2 Iout (mA),Drive 2 Ipower (W),Pressure (),Map 20 (),Map 21 (),Map 22 (),Map 23 (),Map 24 (),Map 25 (),Map 26 (),Map 27 (),Map 28 (),Map 29 ()
,26985254.215,10.0029945,-0.334923021495342,0.0018194288346144,5.95414573381627E-7,1,0.999253354069792,40.0298881530762,1.99798040757156,19.9699997901917,0.020432287391943,0.00373727370132599,0.25,9.40500821172132E-6,0.00180893164249596,1.81205068679674E-5,10.0029945,10.0029945,-0.502384543418884,-0.1674614995718,55.7824825319482,20.5553926391652,12.658426,0,0,0,40,4417,9.99835,-0.334923021495342,,,,,,,,,,,,,0,,,,0.0049,,,,,,10.0029945,,,,
,26985358.39,10.0039644,4226.81518554687,0.00204998466891765,4.57450611287642E-7,1,0.999253354069792,40.0298881530762,1.99800913289545,19.9699997901917,0.0230228581977019,0.00423500476286175,0.25,1.21351753974916E-5,0.00203860849762693,2.24679308887009E-5,10.0039644,10.0039644,4221.6748046875,4231.95556640625,56.4140383754867,20.5621740259298,13.417728,0,0,0,40,4449,9.9977,4226.81518554687,,,,,,,,,,,,,0,,,,-0.0049,,,,,,10.0039644,,,,
,26985449.575,10.0054569,8782.205078125,0.0023073747651249,4.23847786730129E-7,1,0.999253354069792,40.0298881530762,1.99822883770072,19.9699997901917,0.0259248131136149,0.00476876664650689,0.25,1.2891361050078E-5,0.00229532677726754,2.52933008384416E-5,10.0054569,10.0054569,8782.205078125,8782.205078125,56.4750053999867,20.5712871390163,13.038077,0,0,0,40,4449,9.99465,8782.205078125,,,,,,,,,,,,,0,,,,-0.0049,,,,,,10.0054569,,,,
,26985539.325,10.00574685,13267.8588867188,0.00254867324281321,4.9457612383251E-7,1,0.999253354069792,40.0298881530762,1.99802283755333,19.9699997901917,0.0286413733272906,0.00528276335808387,0.25,1.46312460714341E-5,0.00253630638350886,2.91733693667871E-5,10.0056629,10.0058308,13260.0107421875,13275.70703125,56.5531682519098,20.5705101117342,13.038077,0,0,0,40,4449,9.98995,13267.8588867188,,,,,,,,,,,,,0,,,,0,,,,,,10.00574685,,,,
,26985626.7,10.0042744,17635.3125,0.00278767452674649,4.140075424661E-7,1,0.999253354069792,40.0298881530762,1.99808310184613,19.9699997901917,0.0313388446260245,0.00579053817850969,0.25,1.60313952251469E-5,0.00277524985562932,3.27987532051575E-5,10.0042744,10.0042744,17628.13671875,17642.48828125,56.7462304961599,20.5743945500417,13.417728,0,0,0,40,4449,9.98625,17635.3125,,,,,,,,,,,,,0,,,,0,,,,,,10.0042744,,,,
,26985714.58,10.00373125,22027.5654296875,0.00303127584563869,6.65115370397637E-7,1,0.999253354069792,40.0298881530762,1.99813299141138,19.9699997901917,0.0340937491833551,0.00629402372084714,0.25,1.60963212296519E-5,0.00301905976967291,3.52054193770694E-5,10.0036449,10.0038176,22020.205078125,22034.92578125,56.6696309012752,20.5752486629575,13.038077,0,0,0,40,4449,9.984,22027.5654296875,,,,,,,,,,,,,0,,,,0.0049,,,,,,10.00373125,,,,
,26985795.32,10.003006,26063.7861328125,0.00325682819236228,5.6761583659542E-7,1,0.999253354069792,40.0298881530762,1.99818533178212,19.9699997901917,0.0366442279495801,0.00677831947149783,0.25,1.76877526501496E-5,0.00324502715327438,3.89926418073817E-5,10.003006,10.003006,26058.93359375,26068.638671875,56.7696793517368,20.5750741296644,12.658426,0,0,0,40,4449,9.9825,26063.7861328125,,,,,,,,,,,,,0,,,,0,,,,,,10.003006,,,,
,26985874.01,10.0022936,29997.1953125,0.00348358317568876,6.52817588725543E-7,1,0.999253354069792,40.0298881530762,1.99828869899432,19.9699997901917,0.0392121365420853,0.0072617398466201,0.25,1.8941393260132E-5,0.00347238136728196,4.24453966120138E-5,10.0022936,10.0022936,29987.013671875,30007.376953125,56.9705578811791,20.5757432272685,12.278775,0,0,0,40,4449,9.98055,29997.1953125,,,,,,,,,,,,,0,,,,-0.00245,,,,,,10.0022936,,,,
,26985952.5,10.0013523,33917.21875,0.00371108199500454,6.63383220153729E-7,1,0.999253354069792,40.0298881530762,1.998251478156,19.9699997901917,0.0417884440918932,0.00774512513625658,0.25,2.00759140715774E-5,0.00370068176094375,4.57734988628921E-5,10.0013523,10.0013523,33909.6328125,33924.8046875,56.8118872917752,20.577733874607,13.038077,0,0,0,40,4449,9.97915,33917.21875,,,,,,,,,,,,,0,,,,0.00245,,,,,,10.0013523,,,,
,26986030.185,10.0010643,37803.046875,0.00393190749466104,6.93639803005601E-7,1,0.999253354069792,40.0298881530762,1.99826037344028,19.9699997901917,0.044293321658578,0.00821070235549405,0.25,2.08186726487062E-5,0.00392251043673107,4.86303074424737E-5,10.0010643,10.0010643,37797.54296875,37808.55078125,56.8978664288906,20.5788119251821,13.038077,0,0,0,40,4449,9.97875,37803.046875,,,,,,,,,,,,,0,,,,0.00245,,,,,,10.0010643,,,,
,26986106.63,9.9997482,41623.267578125,0.00414811171794298,6.35863491756639E-7,1,0.999253354069792,40.0298881530762,1.99831800565006,19.9699997901917,0.0467487758468241,0.00866784413528916,0.25,2.16557133543277E-5,0.00413987482726899,5.14939497942471E-5,9.9997482,9.9997482,41615.5859375,41630.94921875,57.0440309619868,20.5794401362654,13.038077,0,0,0,40,4449,9.9806,41623.267578125,,,,,,,,,,,,,0,,,,0,,,,,,9.9997482,,,,
,26986181.03,9.9986925,45341.814453125,0.00435256191278079,8.40599297569263E-7,1,0.999253354069792,40.0298881530762,1.9982107512139,19.9699997901917,0.0490674973949083,0.00910956560863935,0.25,2.33532962189502E-5,0.00434560837443013,5.50633826415944E-5,9.9986925,9.9986925,45334.17578125,45349.453125,56.9947883652753,20.5811680705105,13.038077,0,0,0,40,4449,9.98195,45341.814453125,,,,,,,,,,,,,0,,,,-0.00245,,,,,,9.9986925,,,,
,26986257.39,9.9968681,49159.873046875,0.00455521626786155,8.33853692563849E-7,1,0.999253354069792,40.0298881530762,1.99825180010701,19.9699997901917,0.0513717540119861,0.00954638491187034,0.25,2.49115309299486E-5,0.00454972676735571,5.84225749661889E-5,9.9968681,9.9968681,49157.31640625,49162.4296875,56.8001628639868,20.5821244891373,13.038077,0,0,0,40,4449,9.9833,49159.873046875,,,,,,,,,,,,,0,,,,0.0049,,,,,,9.9968681,,,,
,26986338.44,9.995739,53207.744140625,0.00475832327427768,8.90501536256721E-7,1,0.999253354069792,40.0298881530762,1.99818229153856,19.9699997901917,0.0536812171647052,0.00998256140108884,0.25,2.64036260726407E-5,0.0047545254519064,6.16526266789598E-5,9.995739,9.995739,53205.22265625,53210.265625,57.0792042453522,20.5784987596982,13.417728,0,0,0,40,4449,9.9859,53207.744140625,,,,,,,,,,,,,0,,,,-0.0049,,,,,,9.995739,,,,
,26986424.675,9.9957876,57518.08984375,0.00496345632401493,9.44329317211865E-7,1,0.999253354069792,40.0298881530762,1.9982840859669,19.9699997901917,0.0560240681126572,0.0104050626880526,0.25,2.62954974401986E-5,0.00496159454817652,6.32096543448097E-5,9.9957876,9.9957876,57513.1171875,57523.0625,56.9252234270637,20.57884325896,13.038077,0,0,0,40,4449,9.9915,57518.08984375,,,,,,,,,,,,,0,,,,0,,,,,,9.9957876,,,,
,26986508.215,9.9953766,61693.525390625,0.00515421781471648,1.33437674354472E-6,1,0.999253354069792,40.0298881530762,1.9982476035418,19.9699997901917,0.0582019309834876,0.0107935979592937,0.25,2.59377123874074E-5,0.00515432371975905,6.42994450782187E-5,9.9953766,9.9953766,61686.0625,61700.98828125,56.9189703989099,20.5823193717434,13.417728,0,0,0,40,4449,9.994,61693.525390625,,,,,,,,,,,,,0,,,,0,,,,,,9.9953766,,,,
,26986596.455,9.9952822,66104.36328125,0.00533419076198946,8.16696454782783E-7,1,0.999253354069792,40.0298881530762,1.99811523212675,19.9699997901917,0.0602552604150843,0.0111696051221169,0.25,2.65441063904803E-5,0.00533643169456851,6.61614985092856E-5,9.9952822,9.9952822,66099.3359375,66109.390625,57.0026046504676,20.5815557523132,13.038077,0,0,0,40,4449,9.9981,66104.36328125,,,,,,,,,,,,,0,,,,-0.0049,,,,,,9.9952822,,,,
,26986681.55,9.9944048,70359.65625,0.00550136565272233,9.29246064901431E-7,1,0.999253354069792,40.0298881530762,1.99807103690623,19.9699997901917,0.0621648753232199,0.0115254471151527,0.25,2.77442121828138E-5,0.00550569802176931,6.84188376680646E-5,9.9944048,9.9944048,70357.171875,70362.140625,57.0401228193907,20.5805728891947,12.658426,0,0,0,40,4449,10.0019,70359.65625,,,,,,,,,,,,,0,,,,0,,,,,,9.9944048,,,,
,26986767.51,9.9946566,74655.171875,0.00565875622849733,1.13397140545664E-6,1,0.999253354069792,40.0298881530762,1.99807240962508,19.9699997901917,0.0639631629288736,0.011875084902672,0.25,3.02324069223598E-5,0.00566520197322557,7.17911074317142E-5,9.9946566,9.9946566,74645.2421875,74665.1015625,57.1581487257945,20.5835559600571,12.278775,0,0,0,40,4449,10.00685,74655.171875,,,,,,,,,,,,,0,,,,-0.0049,,,,,,9.9946566,,,,
,26986856.295,9.99487975,79093.58203125,0.00580849546285522,1.08233949524755E-6,1,0.999253354069792,40.0298881530762,1.99809313888911,19.9699997901917,0.0656783367561236,0.0121978046397552,0.25,3.1805411666095E-5,0.00581712043521468,7.40835398058505E-5,9.9948559,9.9949036,79088.6640625,79098.5,57.1448610409676,20.5815800396724,12.658426,0,0,0,40,4449,10.0106,79093.58203125,,,,,,,,,,,,,0,,,,0,,,,,,9.99487975,,,,
,26986944.21,9.9943266,83487.140625,0.00594812377370934,1.26825023898546E-6,1,0.999253354069792,40.0298881530762,1.99820162009815,19.9699997901917,0.0672830553482839,0.0124920749726009,0.25,3.27309092495978E-5,0.00595888570598287,7.55671480272408E-5,9.9943266,9.9943266,83477.265625,83497.015625,56.7024592990829,20.5761529534882,12.658426,0,0,0,40,4449,10.0165,83487.140625,,,,,,,,,,,,,0,,,,0,,,,,,9.9943266,,,,
,26987023.845,9.9951038,87467.8828125,0.00606425344610152,1.1544029227353E-6,1,0.999253354069792,40.0298881530762,1.99801244315432,19.9699997901917,0.0686130380753162,0.0127186296413026,0.25,3.21253619359562E-5,0.00607692216795809,7.53191323658524E-5,9.9951038,9.9951038,87460.4921875,87475.2734375,56.8892685151791,20.581893952491,12.658426,0,0,0,40,4449,10.0197,87467.8828125,,,,,,,,,,,,,0,,,,0.00245,,,,,,9.9951038,,,,
,26987119.05,9.9964037,88729.94140625,0.00611532742463731,1.10507919202137E-6,1,0.999253354069792,40.0298881530762,1.99797880645753,19.9699997901917,0.0691968005950373,0.012820295307588,0.25,3.20041996700052E-5,0.00612862639731516,7.53994574364916E-5,9.9964037,9.9964037,88722.3203125,88737.5625,56.9877537086022,20.5849748421342,13.038077,0,0,0,40,4449,10.0216,88729.94140625,,,,,,,,,,,,,0,,,,-0.00245,,,,,,9.9964037,,,,
,26987203.495,9.9993172,84508.90625,0.00601799309192608,9.41857007202593E-7,1,0.999253354069792,40.0298881530762,1.99808852568464,19.9699997901917,0.068081215394713,0.0126025929771074,0.25,3.00181801034305E-5,0.00602934205672014,7.32347215710466E-5,9.9993172,9.9993172,84504.0703125,84513.7421875,57.1049979864868,20.5852337114995,13.038077,0,0,0,40,4449,10.0224,84508.90625,,,,,,,,,,,,,0,,,,0,,,,,,9.9993172,,,,
,26987289.53,10.000639,80207.72265625,0.00590963520188945,9.1983295980087E-7,1,0.999253354069792,40.0298881530762,1.99802817034982,19.9699997901917,0.0668330089396029,0.0123690247564694,0.25,2.87793258244057E-5,0.00591893305073046,7.16785806768484E-5,10.000639,10.000639,80200.4140625,80215.03125,56.9721211382176,20.5861576264637,12.658426,0,0,0,40,4449,10.0196,80207.72265625,,,,,,,,,,,,,0,,,,0,,,,,,10.000639,,,,
,26987377.65,10.0023956,75804.26953125,0.00579593066459449,8.00714475354736E-7,1,0.999253354069792,40.0298881530762,1.99807685824019,19.9699997901917,0.0655258888837753,0.0121304221963407,0.25,2.80876963526041E-5,0.00580308463584924,7.05591925546332E-5,10.0023956,10.0023956,75796.4140625,75812.125,56.9220969129868,20.5858304181545,12.658426,0,0,0,40,4449,10.0166,75804.26953125,,,,,,,,,,,,,0,,,,0.0049,,,,,,10.0023956,,,,
,26987464.35,10.0030861,71468.1640625,0.00567537224259329,1.24794881767208E-6,1,0.999253354069792,40.0298881530762,1.99821009124505,19.9699997901917,0.0641417317605582,0.0118897380153924,0.25,2.8503001611613E-5,0.00568037024591026,7.03993061487527E-5,10.0030861,10.0030861,71458.2890625,71478.0390625,56.8580033744099,20.5847442569092,12.278775,0,0,0,40,4449,10.0131,71468.1640625,,,,,,,,,,,,,0,,,,0,,,,,,10.0030861,,,,
,26987549.84,10.0036497,67194.9765625,0.00554948126069528,1.06712348645911E-6,1,0.999253354069792,40.0298881530762,1.9980938143913,19.9699997901917,0.0626976561153142,0.0115931128121921,0.25,2.51581421079665E-5,0.00555236311724948,6.63344127663122E-5,10.0036497,10.0036497,67184.8359375,67205.1171875,57.1776894387753,20.5879026210606,12.658426,0,0,0,40,4449,10.01145,67194.9765625,,,,,,,,,,,,,0,,,,-0.0049,,,,,,10.0036497,,,,
,26987636.345,10.0030642,62871.935546875,0.0054114359972148,1.02568735410909E-6,1,0.999253354069792,40.0298881530762,1.99794755702149,19.9699997901917,0.0611106190821268,0.0112969340032462,0.25,2.41616714276213E-5,0.00541215637140284,6.44257352552629E-5,10.0030642,10.0030642,62861.73828125,62882.1328125,56.9088092281599,20.588189036398,12.278775,0,0,0,40,4449,10.0091,62871.935546875,,,,,,,,,,,,,0,,,,0,,,,,,10.0030642,,,,
,26987725.055,10.0029302,58436.16796875,0.00526177934096829,9.65058311556273E-7,1,0.999253354069792,40.0298881530762,1.99795700613005,19.9699997901917,0.0593974100127393,0.0109734502033257,0.25,2.28873112145611E-5,0.00526030481769267,6.20374758689879E-5,10.0027571,10.0031033,58424,58448.3359375,57.0588819038522,20.5900866315837,13.038077,0,0,0,40,4449,10.0071,58436.16796875,,,,,,,,,,,,,0,,,,-0.0049,,,,,,10.0029302,,,,
,26987815.275,10.0037088,53927.8671875,0.00510008033869471,9.04335054116249E-7,1,0.999253354069792,40.0298881530762,1.99801834065834,19.9699997901917,0.0575478526856359,0.010635739470274,0.25,2.26277529850189E-5,0.00509641559434746,6.04462168250291E-5,10.0037088,10.0037088,53920.4140625,53935.3203125,56.8931766577752,20.5907441562838,12.278775,0,0,0,40,4449,10.0038,53927.8671875,,,,,,,,,,,,,0,,,,0,,,,,,10.0037088,,,,
,26987901.945,10.0033484,49595.072265625,0.00493144035350131,9.11275787760041E-7,1,0.999253354069792,40.0298881530762,1.99817553880283,19.9699997901917,0.0556255683276841,0.0102767684367794,0.25,2.17873883974611E-5,0.00492575414326457,5.81049596197261E-5,10.0033484,10.0033484,49587.41796875,49602.7265625,57.2136443506599,20.587812902283,13.038077,0,0,0,40,4449,10.00025,49595.072265625,,,,,,,,,,,,,0,,,,0,,,,,,10.0033484,,,,
,26987986.125,10.0033255,45387.1328125,0.00476021983893848,9.11706026281849E-7,1,0.999253354069792,40.0298881530762,1.99803363620036,19.9699997901917,0.0536667037720328,0.00991829824322326,0.25,2.16660497966503E-5,0.00475266568466616,5.63567864895654E-5,10.0033255,10.0033255,45379.62890625,45394.63671875,56.9830639374868,20.5918921777532,12.658426,0,0,0,40,4449,9.99745,45387.1328125,,,,,,,,,,,,,0,,,,0.0049,,,,,,10.0033255,,,,
,26988071.055,10.0033121,41144.173828125,0.00457272556692288,7.58412659781871E-7,1,0.999253354069792,40.0298881530762,1.99799081226881,19.9699997901917,0.0515317309503197,0.00950721539906326,0.25,1.98604203594218E-5,0.00456344356425355,5.26987556387885E-5,10.0033121,10.0033121,41131.984375,41156.36328125,57.2832092888714,20.5913840079248,13.038077,0,0,0,40,4449,9.9951,41144.173828125,,,,,,,,,,,,,0,,,,0.00245,,,,,,10.0033121,,,,
,26988157.97,10.0026817,36798.57421875,0.00436758731477874,8.09850132587336E-7,1,0.999253354069792,40.0298881530762,1.99800441415538,19.9699997901917,0.0491974297807683,0.00907721787219611,0.25,1.96224910821158E-5,0.00435670872867042,5.03681999239689E-5,10.0024509,10.0029125,36788.06640625,36809.08203125,57.1065612435253,20.594715849235,13.038077,0,0,0,40,4449,9.99375,36798.57421875,,,,,,,,,,,,,0,,,,0,,,,,,10.0026817,,,,
,26988241.76,10.0018072,32611.0595703125,0.00415523658701805,8.0708848246892E-7,1,0.999253354069792,40.0298881530762,1.99787705955568,19.9699997901917,0.0467833307425981,0.00862276655764704,0.25,1.85723641973029E-5,0.00414304489768349,4.71240474946684E-5,10.0018072,10.0018072,32606.05859375,32616.060546875,57.200356665833,20.5968534155064,13.038077,0,0,0,40,4449,9.992,32611.0595703125,,,,,,,,,,,,,0,,,,0,,,,,,10.0018072,,,,
,26988329.21,10.0015144,28240.978515625,0.00392083309391849,6.29608047810192E-7,1,0.999253354069792,40.0298881530762,1.99792185275716,19.9699997901917,0.0441248621803839,0.00813243795334311,0.25,1.82984730835307E-5,0.00390752723063132,4.44161864101686E-5,10.0015144,10.0015144,28233.529296875,28248.427734375,56.8548768603329,20.5962483156994,12.658426,0,0,0,40,4449,9.9921,28240.978515625,,,,,,,,,,,,,0,,,,0,,,,,,10.0015144,,,,
,26988416.905,10.0008965,23857.9140625,0.00366831756361364,5.58807767437305E-7,1,0.999253354069792,40.0298881530762,1.99782596842283,19.9699997901917,0.0412633418500572,0.00760020171747023,0.25,1.75816739814718E-5,0.00365421768108887,4.11219666666988E-5,10.0008965,10.0008965,23850.515625,23865.3125,57.1972301517561,20.5952382870024,12.278775,0,0,0,40,4449,9.99105,23857.9140625,,,,,,,,,,,,,0,,,,-0.0049,,,,,,10.0008965,,,,
,26988505.1,10.0001469,19450.142578125,0.0034004207067735,6.21801789458595E-7,1,0.999253354069792,40.0298881530762,1.99787492017729,19.9699997901917,0.0382356275974916,0.00703321497770687,0.25,1.64228166614846E-5,0.00338587078397298,3.73039111606891E-5,10.0001469,10.0001469,19442.322265625,19457.962890625,57.2675767184868,20.5985948330155,12.658426,0,0,0,40,4449,9.99185,19450.142578125,,,,,,,,,,,,,0,,,,-0.0049,,,,,,10.0001469,,,,
,26988587.945,9.9993372,15307.7241210938,0.00313471837106376,5.83921987286038E-7,1,0.999253354069792,40.0298881530762,1.99775661575992,19.9699997901917,0.0352330533537141,0.00647605664409556,0.25,1.56027913468556E-5,0.00312008895873473,3.39599182070533E-5,9.9993372,9.9993372,15295.3955078125,15320.052734375,57.119067299833,20.5990519294516,12.658426,0,0,0,40,4449,9.9913,15307.7241210938,,,,,,,,,,,,,0,,,,0,,,,,,9.9993372,,,,
,26988673.815,9.9987965,11017.3359375,0.00284795587155392,4.65954463485107E-7,1,0.999253354069792,40.0298881530762,1.99777499902706,19.9699997901917,0.031998610161675,0.00587925479490533,0.25,1.48594305088261E-5,0.00283360164378599,3.06454497659454E-5,9.9987965,9.9987965,11007.353515625,11027.318359375,57.1432977839291,20.5996189490628,12.658426,0,0,0,40,4449,9.9933,11017.3359375,,,,,,,,,,,,,0,,,,0.00245,,,,,,9.9987965,,,,
,26988754.9,9.9988165,6964.296875,0.00256881724923669,4.97068688303179E-7,1,0.999253354069792,40.0298881530762,1.99784406166168,19.9699997901917,0.0288543949303065,0.00529945536018445,0.25,1.39904515854779E-5,0.00255505375729403,2.74532141187746E-5,9.9988165,9.9988165,6954.37548828125,6974.21826171875,57.1972301517561,20.5995538208321,12.278775,0,0,0,40,4449,9.994,6964.296875,,,,,,,,,,,,,0,,,,-0.0049,,,,,,9.9988165,,,,
,26988837.74,9.999403,2823.57763671875,0.00226906298043679,3.77555752181806E-7,1,0.999253354069792,40.0298881530762,1.99789399657882,19.9699997901917,0.025481461514521,0.00467664378152197,0.25,1.27342941790023E-5,0.00225627767057405,2.39575213546234E-5,9.999403,9.999403,2811.03686523438,2836.11840820313,57.095618444256,20.5987288697603,11.899124,0,0,0,40,4449,9.99495,2823.57763671875,,,,,,,,,,,,,0,,,,0.0049,,,,,,9.999403,,,,
,26988921.09,9.9985781,-1340.36578369141,0.00194143752506156,3.81515445448689E-7,1,0.999253354069792,40.0298881530762,1.99785408250236,19.9699997901917,0.0218000740790208,0.0040007692752289,0.25,1.10561411913517E-5,0.00193033956261049,2.04773842142015E-5,9.9985781,9.9985781,-1350.41040039062,-1330.32116699219,57.2230238928907,20.5999297304732,12.278775,0,0,0,40,4449,9.9928,-1340.36578369141,,,,,,,,,,,,,0,,,,-0.00245,,,,,,9.9985781,,,,
,26989002.96,9.9992981,-5432.30322265625,0.00159413565786199,4.10602255027376E-7,1,0.999253354069792,40.0298881530762,1.99784176553754,19.9699997901917,0.0179042046488954,0.00328851858655818,0.25,8.87655272128545E-6,0.00158542016876464,1.70516858601593E-5,9.9992981,9.9992981,-5442.0078125,-5422.5986328125,56.8712910592368,20.6003017296961,12.278775,0,0,0,40,4449,9.9967,-5432.30322265625,,,,,,,,,,,,,0,,,,-0.00245,,,,,,9.9992981,,,,
,26989090.845,9.999815,-9823.45458984375,0.00117834163288879,4.14132502265026E-7,1,0.999253354069792,40.0298881530762,1.99788308898362,19.9699997901917,0.0132384042056167,0.00243469422306938,0.25,6.45329629940022E-6,0.0011722864203016,1.28787682996627E-5,9.999815,9.999815,-9830.96484375,-9815.9443359375,57.1925403806407,20.5993833157058,12.278775,0,0,0,40,4449,9.9951,-9823.45458984375,,,,,,,,,,,,,0,,,,0,,,,,,9.999815,,,,
,26989176.485,10.0007496,-14106.5361328125,0.000715444753643855,5.15236037560749E-7,1,0.999253354069792,40.0298881530762,1.99785717129818,19.9699997901917,0.00803870920539849,0.00148991063846274,0.25,4.68454580917518E-6,0.000712022473317735,8.80745017310018E-6,10.0007496,10.0007496,-14108.9697265625,-14104.1025390625,56.8626931455252,20.6011564778212,11.899124,0,0,0,40,4449,9.9934,-14106.5361328125,,,,,,,,,,,,,0,,,,0,,,,,,10.0007496,,,,
,26989264.595,10.0005808,-18508.849609375,0.000145941007172877,4.87802441280319E-7,1,0.999253354069792,40.0298881530762,1.99803218011054,19.9699997901917,0.00164042260299623,0.000305025492252427,0.25,9.96009664495679E-7,0.000145301629236765,1.88178717542526E-6,10.0005808,10.0005808,-18516.2578125,-18501.44140625,57.2222422643714,20.6025476765186,12.278775,0,0,0,40,4449,9.9938,-18508.849609375,,,,,,,,,,,,,0,,,,0,,,,,,10.0005808,,,,
,26989349.835,10.0004873,-22769.017578125,-0.00048730703971951,5.00266507572379E-7,1,0.999253354069792,40.0298881530762,1.99792682494258,19.9699997901917,-0.00548200641997892,-0.0010048950803298,0.25,-1.95226116982954E-6,-0.000485383173503007,-5.04899623228763E-6,10.0004873,10.0004873,-22774.029296875,-22764.005859375,57.1198489283522,20.6025257212878,12.658426,0,0,0,40,4449,9.9935,-22769.017578125,,,,,,,,,,,,,0,,,,0.00245,,,,,,10.0004873,,,,
,26989437.495,9.9995518,-27149.328125,-0.00120599357292273,7.67087841658926E-7,1,0.999253354069792,40.0298881530762,1.99789445551015,19.9699997901917,-0.0135702209524657,-0.0025024913441945,0.25,-5.81942277321386E-6,-0.00120176322242464,-1.3782741177805E-5,9.9995518,9.9995518,-27156.6875,-27141.96875,57.0659165605253,20.6012804758881,12.278775,0,0,0,40,4449,9.9947,-27149.328125,,,,,,,,,,,,,0,,,,0.0049,,,,,,9.9995518,,,,
,26989524.67,10.000186,-31506.8154296875,-0.00195116838910183,6.39845781453082E-7,1,0.999253354069792,40.0298881530762,1.99806109312377,19.9699997901917,-0.0219655811736512,-0.00405864481372732,0.25,-9.6838376206332E-6,-0.00194520978466955,-2.29910060016853E-5,10.000186,10.000186,-31514.21875,-31499.412109375,56.9713395096983,20.601430739698,11.899124,0,0,0,40,4449,9.99365,-31506.8154296875,,,,,,,,,,,,,0,,,,-0.00245,,,,,,10.000186,,,,
,26989613.18,9.9997683,-35931.474609375,-0.00265592389301212,8.64572195504724E-7,1,0.999253354069792,40.0298881530762,1.99788453944541,19.9699997901917,-0.0299096539091641,-0.00553436181378446,0.25,-1.33767590583661E-5,-0.00264905432500038,-3.19838155450284E-5,9.9997683,9.9997683,-35936.5234375,-35926.42578125,57.2753930036791,20.5990955908219,12.278775,0,0,0,40,4449,9.99355,-35931.474609375,,,,,,,,,,,,,0,,,,-0.00245,,,,,,9.9997683,,,,
,26989695.22,9.99861095,-40028.951171875,-0.00323828724989249,7.86769974223377E-7,1,0.999253354069792,40.0298881530762,1.99795739733479,19.9699997901917,-0.0364878865994783,-0.00673559458645078,0.25,-1.44985992275623E-5,-0.00323132967137603,-3.76456608782257E-5,9.9984808,9.9987411,-40033.8515625,-40024.05078125,57.139389641333,20.6008649314506,12.278775,0,0,0,40,4449,9.9946,-40028.951171875,,,,,,,,,,,,,0,,,,0,,,,,,9.99861095,,,,
,26989780.86,9.9983521,-44309.09765625,-0.00376606360375902,9.22681101391431E-7,1,0.999253354069792,40.0298881530762,1.99785143320046,19.9699997901917,-0.042448374904388,-0.00785497782546661,0.25,-1.8083018700237E-5,-0.00375965740056932,-4.54358372441188E-5,9.9983521,9.9983521,-44316.625,-44301.5703125,57.291807202583,20.6007672745034,11.899124,0,0,0,40,4449,9.9966,-44309.09765625,,,,,,,,,,,,,0,,,,0.00245,,,,,,9.9983521,,,,
,26989864.265,9.9970303,-48477.052734375,-0.00419421499686593,7.27336923473168E-7,1,0.999253354069792,40.0298881530762,1.99775245025024,19.9699997901917,-0.0472933130141612,-0.00874626329308737,0.25,-1.9359466088411E-5,-0.00418889428013698,-5.01727006223726E-5,9.9970303,9.9970303,-48479.69140625,-48474.4140625,57.2605420618137,20.6043016709446,12.658426,0,0,0,40,4449,9.9988,-48477.052734375,,,,,,,,,,,,,0,,,,0,,,,,,9.9970303,,,,
,26989949.685,9.9963474,-52749.78125,-0.00456440085757261,1.08547310491566E-6,1,0.999253354069792,40.0298881530762,1.99785916508169,19.9699997901917,-0.0514894006718341,-0.00953928326216563,0.25,-2.22875500575577E-5,-0.00456057237288096,-5.60814161429442E-5,9.9963474,9.9963474,-52757.27734375,-52742.28515625,57.2425646058714,20.6030962874217,12.278775,0,0,0,40,4449,10.00125,-52749.78125,,,,,,,,,,,,,0,,,,0,,,,,,9.9963474,,,,
,26990038.76,9.9964256,-57201.837890625,-0.00488748422705033,8.82239084824373E-7,1,0.999253354069792,40.0298881530762,1.99792198886939,19.9699997901917,-0.055163105001198,-0.0102005765749116,0.25,-2.2078386963412E-5,-0.00488553068376783,-5.84225639744646E-5,9.9964046,9.9964466,-57209.24609375,-57194.4296875,57.3473028274484,20.6048769533463,12.658426,0,0,0,40,4449,10.00435,-57201.837890625,,,,,,,,,,,,,0,,,,-0.0049,,,,,,9.9964256,,,,
,26990128.555,9.9963932,-61686.962890625,-0.00516262774056273,8.2226428646646E-7,1,0.999253354069792,40.0298881530762,1.99787006688849,19.9699997901917,-0.0582927832528416,-0.0107735618783963,0.25,-2.28214900441483E-5,-0.00516275418433394,-6.12456735373249E-5,9.9963932,9.9963932,-61691.80078125,-61682.125,57.1933220091599,20.6037530488217,12.278775,0,0,0,40,4449,10.0073,-61686.962890625,,,,,,,,,,,,,0,,,,-0.00245,,,,,,9.9963932,,,,
,26990218.6,9.9959316,-66186.80859375,-0.00539931741767813,1.06683422865691E-6,1,0.999253354069792,40.0298881530762,1.997916981924,19.9699997901917,-0.0609879245328436,-0.0112921087031813,0.25,-2.57319108840197E-5,-0.00540163350363792,-6.58298469375587E-5,9.9959316,9.9959316,-66194.1484375,-66179.46875,57.3598088837561,20.605641311546,11.899124,0,0,0,40,4449,10.0105,-66186.80859375,,,,,,,,,,,,,0,,,,0,,,,,,9.9959316,,,,
,26990306.735,9.9957657,-70591.75390625,-0.00560283061186799,1.20264647919382E-6,1,0.999253354069792,40.0298881530762,1.9979182658951,19.9699997901917,-0.0633129555462811,-0.0117100878542211,0.25,-2.58560382798692E-5,-0.00560737024768402,-6.7265927829302E-5,9.9957657,9.9957657,-70596.7578125,-70586.75,57.4207759082561,20.6074682422881,12.278775,0,0,0,40,4449,10.01385,-70591.75390625,,,,,,,,,,,,,0,,,,0.00245,,,,,,9.9957657,,,,
,26990396.355,9.9956541,-75071.5390625,-0.0057807012072854,1.30936425665236E-6,1,0.999253354069792,40.0298881530762,1.99778549234429,19.9699997901917,-0.065345704816905,-0.0120690459705057,0.25,-2.55543821790502E-5,-0.005787517668664,-6.79699690621431E-5,9.9956541,9.9956541,-75079.09375,-75063.984375,57.159711982833,20.6069386603286,12.658426,0,0,0,40,4449,10.0181,-75071.5390625,,,,,,,,,,,,,0,,,,0,,,,,,9.9956541,,,,
,26990483.42,9.9947529,-79421.1328125,-0.00593675287623721,1.1352307746111E-6,1,0.999253354069792,40.0298881530762,1.99792842439919,19.9699997901917,-0.0671291026162491,-0.0124434718169152,0.25,-3.05091084152684E-5,-0.00594573027678332,-7.3685876585209E-5,9.9947529,9.9947529,-79426.453125,-79415.8125,57.3488660844868,20.6083886596908,12.658426,0,0,0,40,4449,10.02185,-79421.1328125,,,,,,,,,,,,,0,,,,0.00245,,,,,,9.9947529,,,,
,26990573.125,9.9950447,-83903.45703125,-0.00608278821929133,1.15446204152537E-6,1,0.999253354069792,40.0298881530762,1.99777178409775,19.9699997901917,-0.0688042836027535,-0.0127168907790092,0.25,-2.85965603187479E-5,-0.00609401010910277,-7.23456814797009E-5,9.9950447,9.9950447,-83913.40625,-83893.5078125,57.3738781971022,20.6064856367001,12.278775,0,0,0,40,4449,10.0261,-83903.45703125,,,,,,,,,,,,,0,,,,0,,,,,,9.9950447,,,,
,26990656.255,9.9971561,-88058.609375,-0.00620520018885525,9.09390102630516E-7,1,0.999253354069792,40.0298881530762,1.99791329311269,19.9699997901917,-0.0702106424888114,-0.0129951792803725,0.25,-3.12767403946346E-5,-0.00621842314257731,-7.53948164866725E-5,9.9971561,9.9971561,-88061.0078125,-88056.2109375,57.1065612435253,20.6088275922693,12.658426,0,0,0,40,4449,10.0325,-88058.609375,,,,,,,,,,,,,0,,,,0,,,,,,9.9971561,,,,
,26990754.055,9.99788375,-88058.4609375,-0.00622294559041293,1.07632582195166E-6,1,0.999253354069792,40.0298881530762,1.99784693037187,19.9699997901917,-0.0704044122544972,-0.0130585202595878,0.25,-3.37142246204107E-5,-0.00623618962061908,-7.79635747280421E-5,9.9976501,9.9981174,-88093.1953125,-88023.7265625,57.2832092888714,20.6062140467747,12.278775,0,0,0,40,4449,10.03205,-88058.4609375,,,,,,,,,,,,,0,,,,0,,,,,,9.99788375,,,,
,26990839.75,9.9998369,-83776.17578125,-0.00612793646269095,1.16402275137818E-6,1,0.999253354069792,40.0298881530762,1.99780379573798,19.9699997901917,-0.0693111284644869,-0.0128350981593466,0.25,-3.08902856134567E-5,-0.00613917092132787,-7.49828298813743E-5,9.9998369,9.9998369,-83781.2109375,-83771.140625,57.065134932006,20.6061879200338,12.658426,0,0,0,40,4449,10.0314,-83776.17578125,,,,,,,,,,,,,0,,,,-0.0049,,,,,,9.9998369,,,,
,26990928.75,10.002634,-79328.4296875,-0.00602301778923285,1.25836161060926E-6,1,0.999253354069792,40.0298881530762,1.99790223923,19.9699997901917,-0.0681002551589151,-0.0126404108074819,0.25,-3.23894618022964E-5,-0.00603207284711746,-7.62050198904428E-5,10.002634,10.002634,-79333.71875,-79323.140625,57.1675282680253,20.6048762356781,12.278775,0,0,0,40,4449,10.0278,-79328.4296875,,,,,,,,,,,,,0,,,,0.00245,,,,,,10.002634,,,,
,26991016.415,10.0030718,-74948.671875,-0.00591012197359686,9.45636009831185E-7,1,0.999253354069792,40.0298881530762,1.99794327735906,19.9699997901917,-0.0668056310372305,-0.0123813726908946,0.25,-2.97673233338625E-5,-0.00591700623680203,-7.31467605943855E-5,10.0030718,10.0030718,-74951.171875,-74946.171875,57.3105662870445,20.6097058598784,12.278775,0,0,0,40,4449,10.0261,-74948.671875,,,,,,,,,,,,,0,,,,-0.00245,,,,,,10.0030718,,,,
,26991101.33,10.0036478,-70703.59375,-0.00579708045422857,1.14950306424967E-6,1,0.999253354069792,40.0298881530762,1.99782622149234,19.9699997901917,-0.065501621334167,-0.0121385522466165,0.25,-2.87841491854193E-5,-0.00580181695846822,-7.16249023675303E-5,10.0036478,10.0036478,-70708.1953125,-70698.9921875,57.3144744296407,20.6078983628991,12.278775,0,0,0,40,4449,10.0225,-70703.59375,,,,,,,,,,,,,0,,,,-0.00245,,,,,,10.0036478,,,,
,26991190.235,10.0034227,-66258.7265625,-0.00566858183301074,8.29290711358687E-7,1,0.999253354069792,40.0298881530762,1.99772257668453,19.9699997901917,-0.0640301287444902,-0.0118194232930126,0.25,-2.393972594262E-5,-0.00567107220639552,-6.60334551076027E-5,10.0034227,10.0034227,-66266.265625,-66251.1875,57.187068981006,20.6083568381173,12.278775,0,0,0,40,4449,10.0198,-66258.7265625,,,,,,,,,,,,,0,,,,-0.0049,,,,,,10.0034227,,,,
,26991278.25,10.0030622,-61863.681640625,-0.00553521329051332,1.10034158431521E-6,1,0.999253354069792,40.0298881530762,1.99785979410075,19.9699997901917,-0.0624964669764938,-0.0115734375126229,0.25,-2.64370275196753E-5,-0.0055354245436997,-6.76331457450178E-5,10.0030622,10.0030622,-61868.57421875,-61858.7890625,57.2519441481022,20.6075545759034,12.278775,0,0,0,40,4449,10.0171,-61863.681640625,,,,,,,,,,,,,0,,,,-0.00245,,,,,,10.0030622,,,,
,26991367.32,10.0028801,-57411.130859375,-0.00538935410992316,1.05775268840233E-6,1,0.999253354069792,40.0298881530762,1.99788040885492,19.9699997901917,-0.0608243324177878,-0.0112657572118803,0.25,-2.59121566018683E-5,-0.0053872967755441,-6.59924140322686E-5,10.0028801,10.0028801,-57416.15234375,-57406.109375,57.3637170263522,20.6048139487094,11.899124,0,0,0,40,4449,10.0145,-57411.130859375,,,,,,,,,,,,,0,,,,-0.0049,,,,,,10.0028801,,,,
,26991455.78,10.0037565,-52988.7421875,-0.00523096241796791,1.08692001904519E-6,1,0.999253354069792,40.0298881530762,1.99789064389577,19.9699997901917,-0.0590099103163982,-0.010938488829561,0.25,-2.60371313512947E-5,-0.00522669557384118,-6.477837693904E-5,10.0037565,10.0037565,-52993.88671875,-52983.59765625,57.2605420618137,20.6062357564273,12.278775,0,0,0,40,4449,10.0113,-52988.7421875,,,,,,,,,,,,,0,,,,0,,,,,,10.0037565,,,,
,26991545.61,10.0034847,-48501.513671875,-0.0050610430186123,8.26234370691586E-7,1,0.999253354069792,40.0298881530762,1.99779671501595,19.9699997901917,-0.0570679060831242,-0.0105595274007753,0.25,-2.38374894330975E-5,-0.00505463177097264,-6.10204387023927E-5,10.0034847,10.0034847,-48506.43359375,-48496.59375,57.352774227083,20.6052689588125,12.278775,0,0,0,40,4449,10.00715,-48501.513671875,,,,,,,,,,,,,0,,,,-0.0049,,,,,,10.0034847,,,,
,26991636.305,10.0034246,-43968.978515625,-0.00486959121207161,9.15360597053144E-7,1,0.999253354069792,40.0298881530762,1.99781646614214,19.9699997901917,-0.0548829037524316,-0.0101603873085967,0.25,-2.3798722198012E-5,-0.00486113181451757,-5.91264835096169E-5,10.0034246,10.0034246,-43979.34375,-43958.61328125,57.1808159528522,20.6062412212654,12.658426,0,0,0,40,4449,10.0055,-43968.978515625,,,,,,,,,,,,,0,,,,0.00245,,,,,,10.0034246,,,,
,26991724.87,10.0032768,-39541.26953125,-0.00466430728448498,8.82277143610989E-7,1,0.999253354069792,40.0298881530762,1.99770069736267,19.9699997901917,-0.0525419223447548,-0.00972608531432229,0.25,-2.32644833446029E-5,-0.00465402832253489,-5.65286822884421E-5,10.0032768,10.0032768,-39551.32421875,-39531.21484375,57.2066096939868,20.6037054720845,12.278775,0,0,0,40,4449,10.00215,-39541.26953125,,,,,,,,,,,,,0,,,,0.0049,,,,,,10.0032768,,,,
,26991813.72,10.0023775,-35103.94921875,-0.00443841724363602,7.63019596022162E-7,1,0.999253354069792,40.0298881530762,1.99784681149253,19.9699997901917,-0.0499803539508651,-0.00923390893070143,0.25,-2.12685186502281E-5,-0.00442655553028411,-5.22238932587518E-5,10.0023775,10.0023775,-35108.94921875,-35098.94921875,57.383257739333,20.6052821294662,12.278775,0,0,0,40,4449,10.0007,-35103.94921875,,,,,,,,,,,,,0,,,,0.00245,,,,,,10.0023775,,,,
,26991902.66,10.0013046,-30656.9296875,-0.00418909290295694,6.58457351296467E-7,1,0.999253354069792,40.0298881530762,1.99782448747137,19.9699997901917,-0.047149333772255,-0.00871457861183123,0.25,-2.11818682000484E-5,-0.00417592303103926,-4.95841343513803E-5,10.0013046,10.0013046,-30662.06640625,-30651.79296875,57.2800827747945,20.6036180889792,12.278775,0,0,0,40,4449,10.0008,-30656.9296875,,,,,,,,,,,,,0,,,,0,,,,,,10.0013046,,,,
,26991992.6,10.0019989,-26159.33984375,-0.00390663995593818,6.27320982831123E-7,1,0.999253354069792,40.0298881530762,1.99784632596313,19.9699997901917,-0.0439504759704575,-0.00812076614266241,0.25,-2.04197405170849E-5,-0.00389252786413202,-4.59990401230165E-5,10.0019989,10.0019989,-26169.333984375,-26149.345703125,57.3754414541407,20.6017573292407,11.519473,0,0,0,40,4449,9.9992,-26159.33984375,,,,,,,,,,,,,0,,,,-0.00245,,,,,,10.0019989,,,,
,26992078.535,10.0008059,-21866.4453125,-0.00360551857475801,7.10306146162141E-7,1,0.999253354069792,40.0298881530762,1.99784306166852,19.9699997901917,-0.0405470109465219,-0.00748054774092474,0.25,-1.8767791889667E-5,-0.00359093317866452,-4.14622094318717E-5,10.0008059,10.0008059,-21871.705078125,-21861.185546875,57.2339666921599,20.6030142381908,12.278775,0,0,0,40,4449,9.99855,-21866.4453125,,,,,,,,,,,,,0,,,,-0.00245,,,,,,10.0008059,,,,
,26992165.51,10.0009212,-17521.892578125,-0.00326402496006782,5.38219298454209E-7,1,0.999253354069792,40.0298881530762,1.99767626844561,19.9699997901917,-0.0366877931069406,-0.00677093947383205,0.25,-1.81132163515941E-5,-0.0032494464732809,-3.77233062582711E-5,10.0009212,10.0009212,-17529.400390625,-17514.384765625,57.2253687784484,20.6018028384595,12.278775,0,0,0,40,4449,9.9961,-17521.892578125,,,,,,,,,,,,,0,,,,0,,,,,,10.0009212,,,,
,26992248.2,10.0000925,-13388.994140625,-0.00290609726840177,4.75634799376944E-7,1,0.999253354069792,40.0298881530762,1.99762680227571,19.9699997901917,-0.0326519969060894,-0.00602360936860186,0.25,-1.67529236406398E-5,-0.00289202634776511,-3.33597012602989E-5,10.0000925,10.0000925,-13396.4970703125,-13381.4912109375,57.3441763133715,20.603110564371,12.278775,0,0,0,40,4449,9.9976,-13388.994140625,,,,,,,,,,,,,0,,,,0,,,,,,10.0000925,,,,
,26992332.46,9.9988699,-9173.92431640625,-0.00249073962026737,4.51945021768633E-7,1,0.999253354069792,40.0298881530762,1.99769447519053,19.9699997901917,-0.0279771009854079,-0.00515587204480726,0.25,-1.46699301920492E-5,-0.00247780636165738,-2.81261718996053E-5,9.9988699,9.9988699,-9178.8583984375,-9168.990234375,57.2284952925253,20.6004906706916,11.899124,0,0,0,40,4449,9.99895,-9173.92431640625,,,,,,,,,,,,,0,,,,0.00245,,,,,,9.9988699,,,,
,26992418.395,9.9990935,-4880.39013671875,-0.00202063228446879,4.74365037913205E-7,1,0.999253354069792,40.0298881530762,1.99772492413175,19.9699997901917,-0.0226899892258063,-0.00418030503827213,0.25,-1.2430896424192E-5,-0.00200950342309045,-2.27066585390474E-5,9.9989223,9.9992647,-4885.30126953125,-4875.47900390625,57.2277136640061,20.6001514562894,11.899124,0,0,0,40,4449,9.9993,-4880.39013671875,,,,,,,,,,,,,0,,,,0.00245,,,,,,9.9990935,,,,
,26992502.07,10.00128175,-695.541412353516,-0.00150951501078795,4.3409709164126E-7,1,0.999253354069792,40.0298881530762,1.99768736878743,19.9699997901917,-0.0169470663596739,-0.0031168372884359,0.25,-9.22694375180375E-6,-0.00150083712842753,-1.64948829578646E-5,10.001256,10.0013075,-705.495910644531,-685.5869140625,57.4653287338522,20.6020959084013,11.899124,0,0,0,40,4449,9.9982,-695.541412353516,,,,,,,,,,,,,0,,,,0,,,,,,10.00128175,,,,
,26992589.13,9.9992752,3649.57604980469,-0.000926035159195944,4.71363324740191E-7,1,0.999253354069792,40.0298881530762,1.99775099615467,19.9699997901917,-0.0103984508402131,-0.0019124683120798,0.25,-5.49258193363725E-6,-0.000920862232646617,-1.01229600502262E-5,9.9992752,9.9992752,3641.9599609375,3657.19213867188,57.2832092888714,20.5994394020929,11.519473,0,0,0,40,4449,9.9989,3649.57604980469,,,,,,,,,,,,,0,,,,0,,,,,,9.9992752,,,,
,26992673.44,9.9991074,7863.82006835938,-0.000321116329877408,5.72513409029103E-7,1,0.999253354069792,40.0298881530762,1.99765397284536,19.9699997901917,-0.00360615249551029,-0.000666500412296266,0.25,-2.0882702833578E-6,-0.000319415466731861,-3.79077406640567E-6,9.9991074,9.9991074,7856.53466796875,7871.10546875,57.2753930036791,20.6002862814719,12.278775,0,0,0,40,4449,9.99995,7863.82006835938,,,,,,,,,,,,,0,,,,0.00245,,,,,,9.9991074,,,,
,26992758.965,9.9998989,12140.1186523437,0.000331611580540793,5.89055014323249E-7,1,0.999253354069792,40.0298881530762,1.99769063736363,19.9699997901917,0.00372581938784043,0.000686026894384075,0.25,1.82903061371471E-6,0.00032997082099041,3.69412173818912E-6,9.9998989,9.9998989,12130.130859375,12150.1064453125,57.1034347294484,20.600197832534,11.899124,0,0,0,40,4449,9.9991,12140.1186523437,,,,,,,,,,,,,0,,,,-0.00245,,,,,,9.9998989,,,,
,26992844.58,10.0002518,16417.73828125,0.00099019387771204,5.55951297315284E-7,1,0.999253354069792,40.0298881530762,1.99778043861166,19.9699997901917,0.0111295236733651,0.00205230533054122,0.25,5.42247903183895E-6,0.000985670131756835,1.12962147037837E-5,10.0002518,10.0002518,16407.849609375,16427.626953125,57.1604936113522,20.5987513035265,11.519473,0,0,0,40,4449,9.99915,16417.73828125,,,,,,,,,,,,,0,,,,-0.0049,,,,,,10.0002518,,,,
,26992935.49,10.0004768,20965.3779296875,0.00167949338459654,6.9547419040858E-7,1,0.999253354069792,40.0298881530762,1.9977303874847,19.9699997901917,0.0188843247776624,0.00348541912049202,0.25,8.95998012967661E-6,0.00167254896379792,1.94348840009163E-5,10.0004768,10.0004768,20955.216796875,20975.5390625,57.2535074051407,20.5994022346332,11.899124,0,0,0,40,4449,9.99945,20965.3779296875,,,,,,,,,,,,,0,,,,0.00245,,,,,,10.0004768,,,,
,26993022.985,9.9999743,25335.6513671875,0.00230114991761491,5.93523339320449E-7,1,0.999253354069792,40.0298881530762,1.99775837024614,19.9699997901917,0.0258855370620463,0.00478042684421177,0.25,1.19205573510365E-5,0.00229264417945115,2.68816022732394E-5,9.9999743,9.9999743,25328.390625,25342.912109375,56.9760292808137,20.5983792307928,11.519473,0,0,0,40,4449,9.99805,25335.6513671875,,,,,,,,,,,,,0,,,,0,,,,,,9.9999743,,,,
,26993109.535,9.9995432,29661.49609375,0.00284518891394274,6.62517397522896E-7,1,0.999253354069792,40.0298881530762,1.99768827225428,19.9699997901917,0.0320189193354922,0.00591216533668546,0.25,1.40162705876117E-5,0.00283594981431428,3.31707786157784E-5,9.9995432,9.9995432,29656.322265625,29666.669921875,57.4379717356792,20.5994051495315,11.899124,0,0,0,40,4449,10.0005,29661.49609375,,,,,,,,,,,,,0,,,,0,,,,,,9.9995432,,,,
,26993192.69,9.9994402,33816.8828125,0.0033091727663296,6.54403291129445E-7,1,0.999253354069792,40.0298881530762,1.99771356500257,19.9699997901917,0.0372565101750309,0.00688381797377374,0.25,1.60813658117526E-5,0.00329987638121684,3.89870802934344E-5,9.9994402,9.9994402,33809.3984375,33824.3671875,57.3246356003907,20.5987599360712,11.899124,0,0,0,40,4449,9.99965,33816.8828125,,,,,,,,,,,,,0,,,,-0.00245,,,,,,9.9994402,,,,
,26993279.465,9.9991045,38154.40625,0.00372350339947996,8.11094029696699E-7,1,0.999253354069792,40.0298881530762,1.9976227275862,19.9699997901917,0.0419365442560738,0.00776164291543622,0.25,1.86261354643097E-5,0.00371475075853743,4.50111935055765E-5,9.9991045,9.9991045,38146.87109375,38161.94140625,57.2746113751599,20.5976589758227,11.519473,0,0,0,40,4449,10.00005,38154.40625,,,,,,,,,,,,,0,,,,0,,,,,,9.9991045,,,,
,26993358.405,9.9988518,42100.02734375,0.00405127326148736,8.33377589770771E-7,1,0.999253354069792,40.0298881530762,1.99762572439595,19.9699997901917,0.0456467490507506,0.00845129168372152,0.25,2.00505300011717E-5,0.00404343981553397,4.92475714320654E-5,9.9988518,9.9988518,42094.9765625,42105.078125,57.2433462343907,20.5994329191759,11.899124,0,0,0,40,4449,10,42100.02734375,,,,,,,,,,,,,0,,,,0,,,,,,9.9988518,,,,
,26993438.6,9.9980974,46110.9609375,0.00434169211982087,8.68539711979016E-7,1,0.999253354069792,40.0298881530762,1.99753610736924,19.9699997901917,0.0489355736780862,0.00907091167460719,0.25,2.20140040621082E-5,0.00433511180437394,5.37173600054951E-5,9.9980974,9.9980974,46103.51953125,46118.40234375,57.1581487257945,20.6009616276875,11.519473,0,0,0,40,4449,10.00195,46110.9609375,,,,,,,,,,,,,0,,,,-0.00245,,,,,,9.9980974,,,,
,26993517.62,9.9978266,50059.083984375,0.00459487990457385,1.01464746910086E-6,1,0.999253354069792,40.0298881530762,1.99761477959106,19.9699997901917,0.0518103786694982,0.00961451106976398,0.25,2.39243728254241E-5,0.00458977163969712,5.779053222782E-5,9.9978266,9.9978266,50051.5703125,50066.59765625,57.1628384969099,20.5992002498265,11.519473,0,0,0,40,4449,10.00325,50059.083984375,,,,,,,,,,,,,0,,,,0.00245,,,,,,9.9978266,,,,
,26993599.25,9.99627255,54139.53515625,0.00482624543769287,9.1280773533755E-7,1,0.999253354069792,40.0298881530762,1.99757981193645,19.9699997901917,0.0544417330969789,0.0100959506269191,0.25,2.43428181875179E-5,0.00482285664194508,6.01374242125045E-5,9.9962587,9.9962864,54134.3671875,54144.703125,56.9088092281599,20.5990877512114,12.278775,0,0,0,40,4449,10.00615,54139.53515625,,,,,,,,,,,,,0,,,,-0.0049,,,,,,9.99627255,,,,
,26993678.84,9.9966564,58114.9296875,0.00503260243161234,1.20383660199128E-6,1,0.999253354069792,40.0298881530762,1.99757617986278,19.9699997901917,0.0567915400056418,0.0105306579436878,0.25,2.52033802751733E-5,0.00503101327904622,6.2642806091296E-5,9.9966564,9.9966564,58107.48046875,58122.37890625,57.0643533034868,20.597002830759,11.899124,0,0,0,40,4449,10.00945,58114.9296875,,,,,,,,,,,,,0,,,,0,,,,,,9.9966564,,,,
,26993760.515,9.9955854,62197.671875,0.00522214904998687,1.03092189668052E-6,1,0.999253354069792,40.0298881530762,1.99762529943941,19.9699997901917,0.0589521277246493,0.0109447884173357,0.25,2.73196570635781E-5,0.00522249150065207,6.61833105239812E-5,9.9955854,9.9955854,62190.2578125,62205.0859375,56.8423708040252,20.5964459710704,12.278775,0,0,0,40,4449,10.0128,62197.671875,,,,,,,,,,,,,0,,,,0.00245,,,,,,9.9955854,,,,
,26993842.535,9.9964581,66298.8671875,0.00539738783921704,8.71613923664069E-7,1,0.999253354069792,40.0298881530762,1.99763747339919,19.9699997901917,0.0609536512647752,0.0113140905423649,0.25,2.8152107502747E-5,0.00539973848457515,6.82332247253986E-5,9.9964581,9.9964581,66293.9453125,66303.7890625,57.0323065341983,20.5938273510578,12.278775,0,0,0,40,4449,10.0154,66298.8671875,,,,,,,,,,,,,0,,,,0.00245,,,,,,9.9964581,,,,
,26993920.345,9.996048,70186.96875,0.00554924028232303,1.10452238691151E-6,1,0.999253354069792,40.0298881530762,1.99755216124792,19.9699997901917,0.0626837392965295,0.0116541066591553,0.25,3.07533787224135E-5,0.00555350889604189,7.17935452569443E-5,9.996048,9.996048,70182.15625,70191.78125,56.8345545188329,20.5999903899554,11.899124,0,0,0,40,4449,10.0187,70186.96875,,,,,,,,,,,,,0,,,,0,,,,,,9.996048,,,,
,26993998.58,9.9954433,74097.65234375,0.0056888657757519,1.17258040710123E-6,1,0.999253354069792,40.0298881530762,1.99758554895336,19.9699997901917,0.0642849574187722,0.0119389120254593,0.25,3.06981591466936E-5,0.00569508808709248,7.2519666959358E-5,9.9954433,9.9954433,74095.09375,74100.2109375,57.065134932006,20.5944034058879,11.899124,0,0,0,40,4449,10.0234,74097.65234375,,,,,,,,,,,,,0,,,,-0.0049,,,,,,9.9954433,,,,
,26994077.96,9.9952669,78066.07421875,0.00582332711447033,1.08094533184761E-6,1,0.999253354069792,40.0298881530762,1.99748230014128,19.9699997901917,0.0658184494756471,0.0122423315804757,0.25,3.33682690358439E-5,0.005831505665407,7.58518126560304E-5,9.9952669,9.9952669,78053.5703125,78078.578125,57.0706063316407,20.5958249351962,11.519473,0,0,0,40,4449,10.02475,78066.07421875,,,,,,,,,,,,,0,,,,0,,,,,,9.9952669,,,,
,26994157.97,9.99576,82065.16015625,0.00594787243386064,9.48444623695246E-7,1,0.999253354069792,40.0298881530762,1.99751445391426,19.9699997901917,0.0672472188993606,0.0125084286993126,0.25,3.4533687713205E-5,0.00595800800433734,7.75267089780981E-5,9.99576,9.99576,82057.7109375,82072.609375,56.9705578811791,20.5978125085969,12.278775,0,0,0,40,4449,10.0285,82065.16015625,,,,,,,,,,,,,0,,,,-0.0049,,,,,,9.99576,,,,
,26994233.54,9.9955215,85841.234375,0.00605420383074271,1.25054569645153E-6,1,0.999253354069792,40.0298881530762,1.99750852875452,19.9699997901917,0.0684698651028163,0.0127228018730974,0.25,3.44895730019555E-5,0.00606615660617302,7.78164661916813E-5,9.9955215,9.9955215,85836.1796875,85846.2890625,57.1175040427945,20.5957467730466,12.278775,0,0,0,40,4449,10.0317,85841.234375,,,,,,,,,,,,,0,,,,-0.00245,,,,,,9.9955215,,,,
,26994305.315,9.995368,89431.93359375,0.00615321667209336,1.0606509654897E-6,1,0.999253354069792,40.0298881530762,1.9974932377162,19.9699997901917,0.0696077650151382,0.0129243235055504,0.25,3.46812096411862E-5,0.00616686811046496,7.82588356426115E-5,9.995368,9.995368,89429.1953125,89434.671875,57.2847725459099,20.5960668433969,11.899124,0,0,0,40,4449,10.0353,89431.93359375,,,,,,,,,,,,,0,,,,0,,,,,,9.995368,,,,
,26994397.055,9.9981861,86940.734375,0.00610765972642965,1.4387993280924E-6,1,0.999253354069792,40.0298881530762,1.9974624964177,19.9699997901917,0.0690782136247907,0.0128353470176527,0.25,3.48926602385623E-5,0.00612018111520636,7.84670237493939E-5,9.9981861,9.9981861,86938.2578125,86943.2109375,57.2011382943522,20.5984055122364,12.278775,0,0,0,40,4449,10.0369,86940.734375,,,,,,,,,,,,,0,,,,-0.0049,,,,,,9.9981861,,,,
,26994473.375,10.000288,83124.5625,0.00602021424072083,1.21270809495108E-6,1,0.999253354069792,40.0298881530762,1.99749410061307,19.9699997901917,0.068072616384492,0.0126450918632962,0.25,3.36341166138806E-5,0.00603094583086277,7.70311782468925E-5,10.000288,10.000288,83119.671875,83129.453125,57.1049979864868,20.5982127421091,11.899124,0,0,0,40,4449,10.0355,83124.5625,,,,,,,,,,,,,0,,,,0.00245,,,,,,10.000288,,,,
,26994556.22,10.0019064,78982.94140625,0.00592096099172444,1.1285775578255E-6,1,0.999253354069792,40.0298881530762,1.99752168716857,19.9699997901917,0.0669314667280073,0.0124288972126427,0.25,3.22698166701516E-5,0.00592970418413789,7.5376939905079E-5,10.0019064,10.0019064,78980.484375,78985.3984375,57.2167708647368,20.5991226207018,11.899124,0,0,0,40,4449,10.0343,78982.94140625,,,,,,,,,,,,,0,,,,0,,,,,,10.0019064,,,,
,26994642.195,10.0031767,74684.42578125,0.00580875202427155,1.09150118114965E-6,1,0.999253354069792,40.0298881530762,1.99750318659492,19.9699997901917,0.0656448787490177,0.0121646271912412,0.25,2.90962705813987E-5,0.00581539640419702,7.1752021136695E-5,10.0031767,10.0031767,74671.96875,74696.8828125,56.841589175506,20.5988672878395,11.519473,0,0,0,40,4449,10.03175,74684.42578125,,,,,,,,,,,,,0,,,,0,,,,,,10.0031767,,,,
,26994721.735,10.0033951,70710.5234375,0.00570325624082861,1.06944173435743E-6,1,0.999253354069792,40.0298881530762,1.99744918340946,19.9699997901917,0.0644264279340504,0.0119593608472634,0.25,3.00354999190848E-5,0.00570790672888757,7.21839538590769E-5,10.0033951,10.0033951,70703.15625,70717.890625,56.9517987967176,20.5969325952986,11.519473,0,0,0,40,4449,10.02775,70710.5234375,,,,,,,,,,,,,0,,,,0.0049,,,,,,10.0033951,,,,
,26994804.555,10.0035515,66569.84375,0.00558574786251767,8.45473482894313E-7,1,0.999253354069792,40.0298881530762,1.99749212712798,19.9699997901917,0.0630760397445448,0.0117190459387771,0.25,3.00874287864011E-5,0.00558830684336041,7.15584473490949E-5,10.0035515,10.0035515,66564.9296875,66574.7578125,56.9752476522945,20.6016385688839,11.899124,0,0,0,40,4449,10.024,66569.84375,,,,,,,,,,,,,0,,,,0,,,,,,10.0035515,,,,
,26994887.225,10.0034809,62436.666015625,0.00545946744132273,1.13968071555043E-6,1,0.999253354069792,40.0298881530762,1.99750283159939,19.9699997901917,0.0616301386969445,0.011435042585937,0.25,2.79713521834478E-5,0.00545994972254271,6.85986752933285E-5,10.0034809,10.0034809,62431.5546875,62441.77734375,57.2394380917945,20.6017459800757,11.899124,0,0,0,40,4449,10.02185,62436.666015625,,,,,,,,,,,,,0,,,,0,,,,,,10.0034809,,,,
,26994972.35,10.0039539,58180.9375,0.00532272879957924,8.76899722083218E-7,1,0.999253354069792,40.0298881530762,1.99754503474325,19.9699997901917,0.0600625469726039,0.0111513736651637,0.25,2.7870876156417E-5,0.00532107249451344,6.74694144668377E-5,10.0039539,10.0039539,58168.54296875,58193.33203125,57.0776409883137,20.6011375140451,12.278775,0,0,0,40,4449,10.01975,58180.9375,,,,,,,,,,,,,0,,,,0,,,,,,10.0039539,,,,
,26995008.945,10.0040245,56354.060546875,0.00526123257498756,8.04517790489031E-7,1,0.999253354069792,40.0298881530762,1.9974907135011,19.9699997901917,0.059359356749386,0.0110051832243449,0.25,2.62381668822239E-5,0.0052586802034213,6.53391315034712E-5,10.0040245,10.0040245,56344.15234375,56363.96875,57.0557553897753,20.6032118220937,12.278775,0,0,0,40,4449,10.0176,56354.060546875,,,,,,,,,,,,,0,,,,-0.0049,,,,,,10.0040245,,,,