File: data/monolayers/nanoparticles/Ac_CoFe_C/vsm/data_disorderedWafer/DD226_2_HYST_10K_REPEAT_2.DAT
[Header]
; VSM Data File (default extension .dat)
; Copyright (c) 2003-2013, Quantum Design, Inc. All rights reserved.
TITLE,
FILEOPENTIME,27450155.59,11/15/2018,1:02 am
BYAPP,VSM,2.0,2.0
INFO,PPMS VSM Option Release 1.4.10 Build 1,APPNAME
INFO,Quantum Design Linear Motor Servo Controller,MOTOR_MODULE_NAME
INFO,3101-100 M1,MOTOR_HW_VERSION
INFO,MMC1014,MOTOR_SERIAL_NUMBER
INFO,SRV No X-over 01.03.11,MOTOR_SOFTWARE_VERSION
INFO,Quantum Design VSM Detection Module,VSM_MODULE_NAME
INFO,3101-150 F0,VSM_HW_VERSION
INFO,VSM707,VSM_SERIAL_NUMBER
INFO,VSM No X-over 01.02.05 May 20 2008 13:51:47,VSM_SOFTWARE_VERSION
INFO,704,PREAMP_SERIAL_NUMBER
INFO,822,COIL_SERIAL_NUMBER
INFO,0,MOMENT_UNITS
INFO,CoFe2O4 AH11,SAMPLE_MATERIAL
INFO,Quick Dry Monolayer Conc,SAMPLE_COMMENT
INFO,27.96,SAMPLE_MASS
INFO,,SAMPLE_VOLUME
INFO,,SAMPLE_MOLECULAR_WEIGHT
INFO,,SAMPLE_SIZE
INFO,,SAMPLE_SHAPE
DATATYPE,COMMENT,1
DATATYPE,TIME,2
STARTUPAXIS,X,2
STARTUPAXIS,Y1,5
[Data]
Comment,Time Stamp (sec),Temperature (K),Magnetic Field (Oe),Moment (emu),M. Std. Err. (emu),Transport Action,Averaging Time (sec),Frequency (Hz),Peak Amplitude (mm),Center Position (mm),Coil Signal' (mV),Coil Signal" (mV),Range (mV),M. Quad. Signal (emu),M. Raw' (emu),M. Raw" (emu),Min. Temperature (K),Max. Temperature (K),Min. Field (Oe),Max. Field (Oe),Mass (grams),Motor Lag (deg),Pressure (Torr),VSM Status (code),Motor Status (code),Measure Status (code),Measure Count,PPMS Status (code),System Temp. (K),System Field (Oe),Sample Position (deg),Bridge 1 Resistance (ohms),Bridge 1 Excitation (에),Bridge 2 Resistance (ohms),Bridge 2 Excitation (에),Bridge 3 Resistance (ohms),Bridge 3 Excitation (에),Bridge 4 Resistance (ohms),Bridge 4 Excitation (에),Signal 1 Vin (V),Signal 2 Vin (V),Digital Inputs (code),Drive 1 Iout (mA),Drive 1 Ipower (W),Drive 2 Iout (mA),Drive 2 Ipower (W),Pressure (),Map 20 (),Map 21 (),Map 22 (),Map 23 (),Map 24 (),Map 25 (),Map 26 (),Map 27 (),Map 28 (),Map 29 ()
sample offset = 36.12 mm touchdown = 12.0400004088879 mm,27450195.475,10.000998,-0.274027913808823,-3.676264130417E-5,3.52643105623254E-7,1,0.999253354069792,40.0298881530762,1.99703233930493,17.0799996703863,-0.000411420599885473,-8.24567659344671E-5,0.25,-8.11035211757548E-7,-3.65475462043634E-5,-9.83569627279321E-7,10.0009098,10.0010862,-0.289251685142517,-0.258804142475128,55.4221517845828,20.4604361870936,11.139823,0,0,0,40,4417,9.99415,-0.274027913808823,,,,,,,,,,,,,0,,,,-0.0049,,,,,,10.000998,,,,
,27450303.94,9.9971352,4503.1171875,-4.60040869072724E-5,2.79039180480244E-7,1,0.999253354069792,40.0298881530762,1.99678148078738,17.0799996703863,-0.000515860205372512,-9.78320666290264E-5,0.25,-5.24863111754386E-7,-4.57483337998806E-5,-7.5624874239364E-7,9.9971352,9.9971352,4498.0517578125,4508.1826171875,55.9184858942944,20.4767168730809,10.760172,0,0,0,40,4449,9.9967,4503.1171875,,,,,,,,,,,,,0,,,,0,,,,,,9.9971352,,,,
,27450393.91,9.9983273,9002.2216796875,-5.73069391928452E-5,3.49542777897839E-7,1,0.999253354069792,40.0298881530762,1.99671162190041,17.0799996703863,-0.000643332078429198,-0.000118872484381402,0.25,-3.65257184551962E-7,-5.70084492884544E-5,-6.73982212717229E-7,9.9983273,9.9983273,8992.197265625,9012.24609375,56.2045619323329,20.481009215775,10.760172,0,0,0,40,4449,9.99875,9002.2216796875,,,,,,,,,,,,,0,,,,0,,,,,,9.9983273,,,,
,27450486.305,9.9995899,13619.8549804687,-6.74859888374641E-5,4.25302433168864E-7,1,0.999253354069792,40.0298881530762,1.99659831024666,17.0799996703863,-0.000758404223675519,-0.000136959135315757,0.25,-1.33827953535535E-7,-6.71620613813858E-5,-5.21827533925689E-7,9.9995899,9.9995899,13614.7109375,13624.9990234375,56.2553677860829,20.4826473485551,11.139823,0,0,0,40,4449,9.9991,13619.8549804687,,,,,,,,,,,,,0,,,,0.0049,,,,,,9.9995899,,,,
,27450575.925,10.0000391,18097.49609375,-7.33658907925829E-5,5.31308992855808E-7,1,0.999253354069792,40.0298881530762,1.99667653087857,17.0799996703863,-0.000825757083531718,-0.000143908913689191,0.25,3.26430647675292E-7,-7.30466350174604E-5,-1.20437896927077E-7,10.0000324,10.0000458,18062.58984375,18132.40234375,56.5445703381983,20.4915480955018,10.760172,0,0,0,40,4449,9.9982,18097.49609375,,,,,,,,,,,,,0,,,,-0.00245,,,,,,10.0000391,,,,
,27450668.4,10.000248,22720.2783203125,-7.37288599281761E-5,5.74578683992461E-7,1,0.999253354069792,40.0298881530762,1.99655973335706,17.0799996703863,-0.000829858664738473,-0.000146443502827329,0.25,1.92900139037961E-7,-7.34405319518176E-5,-2.77329992434299E-7,10.000248,10.000248,22714.939453125,22725.6171875,56.7321611828137,20.4900160125248,10.760172,0,0,0,40,4449,9.9972,22720.2783203125,,,,,,,,,,,,,0,,,,-0.0049,,,,,,10.000248,,,,
,27450761.85,10.0005484,27390.5546875,-7.41246941980562E-5,5.77474782284606E-7,1,0.999253354069792,40.0298881530762,1.99654598558668,17.0799996703863,-0.000833786849124659,-0.00015244221220087,0.25,-2.43491121117002E-7,-7.38672868206722E-5,-7.34296275625162E-7,10.0005484,10.0005484,27382.9609375,27398.1484375,56.4304525743906,20.4937096328517,10.760172,0,0,0,40,4449,9.9989,27390.5546875,,,,,,,,,,,,,0,,,,0,,,,,,10.0005484,,,,
,27450855.385,9.9998503,32065.400390625,-7.69388161439654E-5,6.06097723461727E-7,1,0.999253354069792,40.0298881530762,1.99658467366571,17.0799996703863,-0.000868659420287001,-0.000142860175564631,0.25,1.13666597391143E-6,-7.6718800507854E-5,6.05482909258311E-7,9.9998503,9.9998503,32060.3984375,32070.40234375,56.4695340003521,20.4943154304742,10.38052,0,0,0,40,4449,9.9977,32065.400390625,,,,,,,,,,,,,0,,,,0.00245,,,,,,9.9998503,,,,
,27450945.89,9.9992228,36588.197265625,-8.87162290766186E-5,6.69734209719458E-7,1,0.999253354069792,40.0298881530762,1.99660480513106,17.0799996703863,-0.00100008294623914,-0.000176162908529599,0.25,3.18865242496053E-7,-8.84983331924956E-5,-3.06751124520036E-7,9.9992228,9.9992228,36578.16015625,36598.234375,56.4992358840829,20.4958707537022,10.38052,0,0,0,40,4449,9.99805,36588.197265625,,,,,,,,,,,,,0,,,,-0.0049,,,,,,9.9992228,,,,
,27451040.515,9.9985313,41318.541015625,-0.0001001799849566,8.23164036296334E-7,1,0.999253354069792,40.0298881530762,1.99662184634182,17.0799996703863,-0.00112744774953754,-0.000212597453590418,0.25,-8.28934927201434E-7,-9.99756418127269E-5,-1.54808181459406E-6,9.9985313,9.9985313,41316.28515625,41320.796875,56.7782772654483,20.498448933542,10.760172,0,0,0,40,4449,9.9999,41318.541015625,,,,,,,,,,,,,0,,,,0.0049,,,,,,9.9985313,,,,
,27451135.405,9.9976711,46061.32421875,-0.000117045148600421,6.60877016636886E-7,1,0.999253354069792,40.0298881530762,1.99652628838144,17.0799996703863,-0.00131838960443141,-0.000245488036912905,0.25,-6.88454972177966E-7,-0.000116866457652676,-1.54286714938658E-6,9.9976711,9.9976711,46053.52734375,46069.12109375,56.5906864208329,20.4954803974583,11.139823,0,0,0,40,4449,10.00135,46061.32421875,,,,,,,,,,,,,0,,,,-0.0049,,,,,,9.9976711,,,,
,27451228.04,9.9969625,50691.603515625,-0.000132053891955681,9.08575820495222E-7,1,0.999253354069792,40.0298881530762,1.99657109822428,17.0799996703863,-0.00149239065341883,-0.000253771142507555,0.25,1.30115400628657E-6,-0.000131930224342611,3.24700223757794E-7,9.9969625,9.9969625,50681.88671875,50701.3203125,56.7626446950637,20.4971618068572,10.760172,0,0,0,40,4449,10.00455,50691.603515625,,,,,,,,,,,,,0,,,,0.0049,,,,,,9.9969625,,,,
,27451323.855,9.9967012,55481.794921875,-0.000148027141995523,7.41815020625817E-7,1,0.999253354069792,40.0298881530762,1.99600909334373,17.0799996703863,-0.00167445622306243,-0.0002778872119326,0.25,2.05309518368007E-6,-0.000147963505240301,9.52254389394992E-7,9.9967012,9.9967012,55474.19921875,55489.390625,56.6414922745829,20.5029661811532,10.760172,0,0,0,40,4449,10.00795,55481.794921875,,,,,,,,,,,,,0,,,,0,,,,,,9.9967012,,,,
,27451415.955,9.9964666,60084.583984375,-0.000163671350714058,7.79235787735826E-7,1,0.999253354069792,40.0298881530762,1.99609400098597,17.0799996703863,-0.00184749285949088,-0.000334146225919257,0.25,-9.70170902391151E-8,-0.000163655582654856,-1.31531308114494E-6,9.9964666,9.9964666,60072.22265625,60096.9453125,56.5711457078521,20.5031726883172,10.760172,0,0,0,40,4449,10.0108,60084.583984375,,,,,,,,,,,,,0,,,,-0.0049,,,,,,9.9964666,,,,
,27451510.49,9.9958782,64809.88671875,-0.000180114969280637,7.55288250401164E-7,1,0.999253354069792,40.0298881530762,1.99615331774877,17.0799996703863,-0.00203228225801405,-0.000377666176505936,0.25,-9.75277135621929E-7,-0.000180169283530507,-2.31424475672327E-6,9.9958782,9.9958782,64804.6953125,64815.078125,56.8095424062176,20.5054493693178,10.38052,0,0,0,40,4449,10.0151,64809.88671875,,,,,,,,,,,,,0,,,,0,,,,,,9.9958782,,,,
,27451604.25,9.9962778,69492.5546875,-0.000199164304959505,7.36727739607746E-7,1,0.999253354069792,40.0298881530762,1.99613225574884,17.0799996703863,-0.00224688304626594,-0.0004246271342943,0.25,-1.69221793998656E-6,-0.000199301407259077,-3.16689585220808E-6,9.9962778,9.9962778,69487.5390625,69497.5703125,56.5758354789675,20.5059330172576,10.760172,0,0,0,40,4449,10.0179,69492.5546875,,,,,,,,,,,,,0,,,,0,,,,,,9.9962778,,,,
,27451699.495,9.9951334,74255.06640625,-0.000217569228427247,9.69433670828601E-7,1,0.999253354069792,40.0298881530762,1.99602726132874,17.0799996703863,-0.00245948589358598,-0.000441148442925806,0.25,1.63022924651232E-7,-0.00021781978312553,-1.43445657585468E-6,9.9951334,9.9951334,74250.0390625,74260.09375,56.6711941583137,20.5044389107385,10.38052,0,0,0,40,4449,10.0215,74255.06640625,,,,,,,,,,,,,0,,,,0.0049,,,,,,9.9951334,,,,
,27451794.26,9.9954748,78993.69140625,-0.000233550833897449,8.00684518048074E-7,1,0.999253354069792,40.0298881530762,1.99617375553308,17.0799996703863,-0.00264194305239476,-0.000470245354458902,0.25,4.68688891195788E-7,-0.000233908564956039,-1.22897809714867E-6,9.9954748,9.9954748,78988.8515625,78998.53125,56.9471090256022,20.5041851939199,11.139823,0,0,0,40,4449,10.0253,78993.69140625,,,,,,,,,,,,,0,,,,0,,,,,,9.9954748,,,,
,27451889.44,9.9953766,83749.45703125,-0.000252011126411317,1.05509665245411E-6,1,0.999253354069792,40.0298881530762,1.99614854007603,17.0799996703863,-0.00284961378966176,-0.000519334135730142,0.25,-5.55028877512712E-7,-0.000252477803925429,-2.36712437780659E-6,9.9953766,9.9953766,83746.8046875,83752.109375,56.3835548632367,20.5047408027109,10.38052,0,0,0,40,4449,10.0299,83749.45703125,,,,,,,,,,,,,0,,,,-0.0049,,,,,,9.9953766,,,,
,27451976.645,9.9953527,88110.171875,-0.000267174980160093,9.82833161817059E-7,1,0.999253354069792,40.0298881530762,1.99618228247284,17.0799996703863,-0.00302104873392158,-0.000556261802574397,0.25,-1.0989955474177E-6,-0.00026774700433441,-2.99774520526116E-6,9.9953527,9.9953527,88105.2890625,88115.0546875,56.7712426087752,20.4996717044455,10.760172,0,0,0,40,4449,10.0329,88110.171875,,,,,,,,,,,,,0,,,,-0.00245,,,,,,9.9953527,,,,
,27452081.89,9.997489,87583.2265625,-0.000263980934452457,1.35352537642746E-6,1,0.999253354069792,40.0298881530762,1.99606575195493,17.0799996703863,-0.00298524856914947,-0.000546290557692885,0.25,-7.93754049011121E-7,-0.000264538780625075,-2.67208694860574E-6,9.997489,9.997489,87573.234375,87593.21875,56.8759808303522,20.5043453891566,11.139823,0,0,0,40,4449,10.0358,87583.2265625,,,,,,,,,,,,,0,,,,-0.0049,,,,,,9.997489,,,,
,27452174.785,10.0007048,82937.34375,-0.000246877717090449,8.11510240636226E-7,1,0.999253354069792,40.0298881530762,1.99628007018844,17.0799996703863,-0.00279371058095741,-0.000496926333338391,0.25,5.06121792774374E-7,-0.000247328039697547,-1.27095473757921E-6,10.0007048,10.0007048,82929.640625,82945.046875,57.0018230219483,20.5020979989796,10.38052,0,0,0,40,4449,10.035,82937.34375,,,,,,,,,,,,,0,,,,0.00245,,,,,,10.0007048,,,,
,27452272.105,10.0020628,78070.80078125,-0.000229566685707412,9.99235122502664E-7,1,0.999253354069792,40.0298881530762,1.9962549527832,17.0799996703863,-0.00259131296269741,-0.000492636407338659,0.25,-2.22663020926186E-6,-0.00022988254103369,-3.90271384844492E-6,10.0020628,10.0020628,78065.3125,78076.2890625,56.7329428113329,20.5021922284224,11.139823,0,0,0,40,4449,10.0323,78070.80078125,,,,,,,,,,,,,0,,,,0,,,,,,10.0020628,,,,
,27452368.1,10.0031948,73272.73828125,-0.000212379709123756,1.08767355040476E-6,1,0.999253354069792,40.0298881530762,1.99625778946753,17.0799996703863,-0.00240095747613406,-0.000430295003151008,0.25,1.92427915707625E-7,-0.000212607617117127,-1.36963740885774E-6,10.0031948,10.0031948,73262.859375,73282.6171875,56.9705578811791,20.5037873214139,11.139823,0,0,0,40,4449,10.0285,73272.73828125,,,,,,,,,,,,,0,,,,-0.00245,,,,,,10.0031948,,,,
,27452464.555,10.0039959,68451.81640625,-0.000195397759924005,1.08469492857501E-6,1,0.999253354069792,40.0298881530762,1.99617060546586,17.0799996703863,-0.00220849987589616,-0.000392897856117103,0.25,4.36741821238112E-7,-0.000195530354315934,-1.01034479502275E-6,10.0039959,10.0039959,68449.4140625,68454.21875,56.8001628639868,20.5068054103834,10.760172,0,0,0,40,4449,10.02495,68451.81640625,,,,,,,,,,,,,0,,,,-0.0049,,,,,,10.0039959,,,,
,27452563.335,10.0042524,63516.439453125,-0.00017699841224427,9.0102751939652E-7,1,0.999253354069792,40.0298881530762,1.9962112424805,17.0799996703863,-0.00199948949206891,-0.000356951758828283,0.25,2.95396798410449E-7,-0.00017704044573994,-1.02099653882114E-6,10.0042524,10.0042524,63511.37109375,63521.5078125,56.8572217458906,20.5063198473372,11.139823,0,0,0,40,4449,10.021,63516.439453125,,,,,,,,,,,,,0,,,,0.0049,,,,,,10.0042524,,,,
,27452661.16,10.0039368,58623.736328125,-0.000160295864379327,1.02045553832081E-6,1,0.999253354069792,40.0298881530762,1.99622974671685,17.0799996703863,-0.00180871420947869,-0.000330250783164014,0.25,-3.62633435221581E-7,-0.000160256296492704,-1.55546517808642E-6,10.0039368,10.0039368,58618.828125,58628.64453125,56.8978664288906,20.5078472685614,10.38052,0,0,0,40,4449,10.01785,58623.736328125,,,,,,,,,,,,,0,,,,0.00245,,,,,,10.0039368,,,,
,27452753.54,10.0042801,54007.771484375,-0.000142676150807687,9.57764452954844E-7,1,0.999253354069792,40.0298881530762,1.99621151903331,17.0799996703863,-0.00161067274708758,-0.000285451147323166,0.25,4.15728124179689E-7,-0.000142582535234208,-6.43062158715578E-7,10.0042801,10.0042801,54000.40625,54015.13671875,56.7978179784291,20.5075717087926,10.38052,0,0,0,40,4449,10.0144,54007.771484375,,,,,,,,,,,,,0,,,,-0.00245,,,,,,10.0042801,,,,
,27452851.75,10.0045252,49097.8359375,-0.000124985403251242,8.63737455836042E-7,1,0.999253354069792,40.0298881530762,1.99626495524876,17.0799996703863,-0.00140823289488748,-0.000261414379300859,0.25,-6.59885575314715E-7,-0.0001248341648855,-1.57926258761574E-6,10.0045252,10.0045252,49092.9296875,49102.7421875,56.9986965078714,20.5080976018461,10.760172,0,0,0,40,4449,10.0105,49097.8359375,,,,,,,,,,,,,0,,,,0,,,,,,10.0045252,,,,
,27452946.21,10.0033855,44377.26953125,-0.000108718319416308,7.70935126790645E-7,1,0.999253354069792,40.0298881530762,1.99619615727056,17.0799996703863,-0.00122669427774997,-0.000214032706497352,0.25,5.91171816360147E-7,-0.000108542254200629,-2.00466257263242E-7,10.0033092,10.0034618,44369.7421875,44384.796875,56.9549253107945,20.5087759446716,11.139823,0,0,0,40,4449,10.00705,44377.26953125,,,,,,,,,,,,,0,,,,0,,,,,,10.0033855,,,,
,27453038.57,10.0033569,39762.173828125,-9.19240122356921E-5,7.72618998348719E-7,1,0.999253354069792,40.0298881530762,1.99624051025966,17.0799996703863,-0.00103635997752419,-0.000182863504539996,0.25,3.13262266564642E-7,-9.17290993130392E-5,-3.44600522148298E-7,10.0033569,10.0033569,39757.12109375,39767.2265625,57.0065127930637,20.5083509060187,10.760172,0,0,0,40,4449,10.00435,39762.173828125,,,,,,,,,,,,,0,,,,0,,,,,,10.0033569,,,,
,27453135.33,10.0032654,34924.64453125,-7.44141069479364E-5,6.28237243955896E-7,1,0.999253354069792,40.0298881530762,1.99635993778835,17.0799996703863,-0.000837786974210626,-0.000152298980717773,0.25,-1.43735297740943E-7,-7.4215306283972E-5,-6.62766813061675E-7,10.0032654,10.0032654,34919.66015625,34929.62890625,56.7743691228522,20.5090084713104,10.760172,0,0,0,40,4449,10.0022,34924.64453125,,,,,,,,,,,,,0,,,,0.00245,,,,,,10.0032654,,,,
,27453234.04,10.0017471,29990.10546875,-5.76294617910143E-5,6.3360352411227E-7,1,0.999253354069792,40.0298881530762,1.99637319308328,17.0799996703863,-0.000650712687869102,-0.000105464605391823,0.25,9.79830976135761E-7,-5.74528528956172E-5,5.86908749102068E-7,10.0017471,10.0017471,29982.7109375,29997.5,57.166746639506,20.5089903637078,10.760172,0,0,0,40,4449,10.0009,29990.10546875,,,,,,,,,,,,,0,,,,0,,,,,,10.0017471,,,,
,27453332.73,10.0023661,25059.7666015625,-4.07732392433383E-5,5.97145878683115E-7,1,0.999253354069792,40.0298881530762,1.99626243071881,17.0799996703863,-0.000459874899170418,-7.59437785677198E-5,0.25,5.61050623197695E-7,-4.06264062173414E-5,2.93753289866879E-7,10.0023661,10.0023661,25049.51171875,25070.021484375,57.1245386994676,20.5107749839059,10.38052,0,0,0,40,4449,10.0005,25059.7666015625,,,,,,,,,,,,,0,,,,-0.0049,,,,,,10.0023661,,,,
,27453424.84,10.001091,20457.095703125,-2.49945162158657E-5,4.24325046770266E-7,1,0.999253354069792,40.0298881530762,1.99634121100636,17.0799996703863,-0.000281464395850477,-4.83416799265285E-5,0.25,1.76331787023494E-7,-2.48918552116485E-5,1.99723115065149E-8,10.001091,10.001091,20447.1875,20467.00390625,56.9564885678329,20.5095930718713,10.760172,0,0,0,40,4449,9.9981,20457.095703125,,,,,,,,,,,,,0,,,,-0.00245,,,,,,10.001091,,,,
,27453519.145,10.0003366,15742.681640625,-8.92948898167059E-6,3.85595361271883E-7,1,0.999253354069792,40.0298881530762,1.99624760603232,17.0799996703863,-0.000100830072385288,-1.54447807612873E-5,0.25,2.21813681197507E-7,-8.88974197916074E-6,1.68023058628038E-7,10.0003366,10.0003366,15735.2548828125,15750.1083984375,56.9338213407753,20.5115515363313,10.38052,0,0,0,40,4449,9.9996,15742.681640625,,,,,,,,,,,,,0,,,,-0.00245,,,,,,10.0003366,,,,
,27453612.185,9.9996071,11092.5405273438,7.03239989394537E-6,3.3260677050316E-7,1,0.999253354069792,40.0298881530762,1.99640682945447,17.0799996703863,7.80713467197417E-5,1.95040112633366E-5,0.25,4.81173757192342E-7,6.99452120793263E-6,5.17968433414522E-7,9.9996071,9.9996071,11087.5546875,11097.5263671875,56.9955699937945,20.5134454965584,10.760172,0,0,0,40,4449,9.9992,11092.5405273438,,,,,,,,,,,,,0,,,,0.00245,,,,,,9.9996071,,,,
,27453703.49,9.9985867,6529.55688476563,2.18391381606133E-5,3.38000560275041E-7,1,0.999253354069792,40.0298881530762,1.99636585193556,17.0799996703863,0.000245154750462156,4.48727148089332E-5,0.25,1.06458951062468E-7,2.17215029522441E-5,2.20282812528573E-7,9.9985867,9.9985867,6524.68505859375,6534.4287109375,56.8751992018329,20.5145101778649,10.760172,0,0,0,40,4449,10.0004,6529.55688476563,,,,,,,,,,,,,0,,,,0,,,,,,9.9985867,,,,
,27453797,9.9999151,1853.64434814453,3.3211739744003E-5,3.03792925731391E-7,1,0.999253354069792,40.0298881530762,1.99625586658702,17.0799996703863,0.000373458489629727,6.38637563570629E-5,0.25,-2.14855003673578E-7,3.30247604074288E-5,-5.03768409185017E-8,9.9999151,9.9999151,1846.18115234375,1861.10754394531,56.8540952318137,20.5112673964101,10.760172,0,0,0,40,4449,10.0002,1853.64434814453,,,,,,,,,,,,,0,,,,0,,,,,,9.9999151,,,,
,27453889.36,9.9990749,-2756.83032226562,4.26510290212221E-5,2.71486620658629E-7,1,0.999253354069792,40.0298881530762,1.99634036241531,17.0799996703863,0.000479557136609861,8.2519549059186E-5,0.25,-2.34116720532899E-7,4.24128942933826E-5,-2.06879751272194E-8,9.9990749,9.9990749,-2761.92260742187,-2751.73803710938,57.1096877576022,20.5141756810594,10.38052,0,0,0,40,4449,9.9998,-2756.83032226562,,,,,,,,,,,,,0,,,,0,,,,,,9.9990749,,,,
,27453982.58,9.9992886,-7419.12451171875,5.32593148742318E-5,4.21697481572674E-7,1,0.999253354069792,40.0298881530762,1.99631196588625,17.0799996703863,0.000599169496500998,0.000102223451727605,0.25,-3.85782363478338E-7,5.29793260875472E-5,-1.01290443462353E-7,9.9992886,9.9992886,-7426.5859375,-7411.6630859375,56.9408559974483,20.5116458740517,10.760172,0,0,0,40,4449,10.0007,-7419.12451171875,,,,,,,,,,,,,0,,,,0,,,,,,9.9992886,,,,
,27454076.235,10.0003071,-12099.7045898438,6.56484002823776E-5,3.90835285983422E-7,1,0.999253354069792,40.0298881530762,1.99626053269065,17.0799996703863,0.000738043457042789,0.000130349557585011,0.25,-1.1538071938871E-7,6.53260547715757E-5,2.56001260467843E-7,10.0003071,10.0003071,-12109.640625,-12089.7685546875,57.0338697912368,20.5113031416103,10.760172,0,0,0,40,4449,10.00025,-12099.7045898438,,,,,,,,,,,,,0,,,,-0.0049,,,,,,10.0003071,,,,
,27454170.3,10.0007772,-16802.341796875,7.30352316897432E-5,5.11603107812902E-7,1,0.999253354069792,40.0298881530762,1.99639186111814,17.0799996703863,0.000822189639748117,0.000141168618862326,0.25,-5.01277150848319E-7,7.27095540565274E-5,-6.20287678773511E-8,10.0007772,10.0007772,-16807.435546875,-16797.248046875,56.7860935506406,20.5136153595261,10.760172,0,0,0,40,4449,9.9986,-16802.341796875,,,,,,,,,,,,,0,,,,-0.0049,,,,,,10.0007772,,,,
,27454264.98,10.0006762,-21531.7587890625,7.36983794110059E-5,5.92998141185753E-7,1,0.999253354069792,40.0298881530762,1.99638797926906,17.0799996703863,0.000829725841052578,0.000144246238264052,0.25,-3.748053348205E-7,7.34025853380803E-5,9.06002206395827E-8,10.0006762,10.0006762,-21534.080078125,-21529.4375,56.966649738583,20.51653921594,10.760172,0,0,0,40,4449,9.9999,-21531.7587890625,,,,,,,,,,,,,0,,,,0,,,,,,10.0006762,,,,
,27454360.09,10.0008373,-26284.8056640625,7.27854418474419E-5,5.33087498217962E-7,1,0.999253354069792,40.0298881530762,1.99636104000695,17.0799996703863,0.000821618992219409,0.000132581586337567,0.25,-1.27409166939293E-6,7.25343295995035E-5,-7.91114112359371E-7,10.0008373,10.0008373,-26292.76953125,-26276.841796875,57.0604451608906,20.5150002105284,10.38052,0,0,0,40,4449,9.9985,-26284.8056640625,,,,,,,,,,,,,0,,,,0.0049,,,,,,10.0008373,,,,
,27454454.94,9.9999828,-31026.9638671875,7.76216835733413E-5,7.41962022568422E-7,1,0.999253354069792,40.0298881530762,1.99636213192328,17.0799996703863,0.000875943503479548,0.000145406601946152,0.25,-1.0267969779071E-6,7.73903397261626E-5,-4.94803591270577E-7,9.9999828,9.9999828,-31039.484375,-31014.443359375,57.0182372208522,20.5154158845647,10.760172,0,0,0,40,4449,9.99845,-31026.9638671875,,,,,,,,,,,,,0,,,,0,,,,,,9.9999828,,,,
,27454549.285,9.9996119,-35744.0546875,8.48003877322772E-5,7.89367111955999E-7,1,0.999253354069792,40.0298881530762,1.99628148291121,17.0799996703863,0.000955863831620026,0.000167470436316223,0.25,-3.79926782193153E-7,8.45850247549967E-5,2.15641300228944E-7,9.9996119,9.9996119,-35746.6796875,-35741.4296875,57.159711982833,20.5164446041653,10.760172,0,0,0,40,4449,9.9987,-35744.0546875,,,,,,,,,,,,,0,,,,0,,,,,,9.9996119,,,,
,27454642.885,9.9988174,-40419.146484375,9.87393383791606E-5,7.92362751393238E-7,1,0.999253354069792,40.0298881530762,1.99637852953891,17.0799996703863,0.00111710540945438,0.000175570640082092,0.25,-2.19107252037465E-6,9.85501404393814E-5,-1.47865645493003E-6,9.9988174,9.9988174,-40429.28125,-40409.01171875,57.3465211989291,20.5136178792069,11.139823,0,0,0,40,4449,9.9992,-40419.146484375,,,,,,,,,,,,,0,,,,0,,,,,,9.9988174,,,,
,27454734.34,9.9983263,-44989.744140625,0.000113163539730432,6.64356358749984E-7,1,0.999253354069792,40.0298881530762,1.99634814345239,17.0799996703863,0.00127582279098078,0.000229492349460538,0.25,-2.4495783053529E-8,0.000112983211236022,8.00073204335714E-7,9.9983263,9.9983263,-44992.140625,-44987.34765625,57.024490249006,20.5151825450392,11.139823,0,0,0,40,4449,10.0013,-44989.744140625,,,,,,,,,,,,,0,,,,-0.00245,,,,,,9.9983263,,,,
,27454825.415,9.9972792,-49544.330078125,0.000128311376697381,7.21139492553772E-7,1,0.999253354069792,40.0298881530762,1.99627523592134,17.0799996703863,0.00144580044523848,0.000268272363279048,0.25,6.66700299810481E-7,0.000128162030300663,1.61143909787639E-6,9.9972792,9.9972792,-49549.29296875,-49539.3671875,56.9205336559483,20.5168733648461,10.38052,0,0,0,40,4449,10.0035,-49544.330078125,,,,,,,,,,,,,0,,,,0,,,,,,9.9972792,,,,
,27454923.4,9.9973259,-54439.0625,0.000144112448768492,7.67767587441025E-7,1,0.999253354069792,40.0298881530762,1.99618567035768,17.0799996703863,0.00162930014359914,0.000275218351295438,0.25,-1.58268501712207E-6,0.000144032654525425,-5.12032628958441E-7,9.9973259,9.9973259,-54446.5390625,-54431.5859375,56.9893169656406,20.5145236490191,10.760172,0,0,0,40,4449,10.0076,-54439.0625,,,,,,,,,,,,,0,,,,-0.0049,,,,,,9.9973259,,,,
,27455020.1,9.9964972,-59273.5703125,0.000160430182548101,8.12604612828819E-7,1,0.999253354069792,40.0298881530762,1.99630593732402,17.0799996703863,0.00181365916746321,0.000312519817402783,0.25,-1.23514072885025E-6,0.00016041236672194,-4.08493077658539E-8,9.9964972,9.9964972,-59278.53125,-59268.609375,57.1268835850253,20.515469602024,10.760172,0,0,0,40,4449,10.00995,-59273.5703125,,,,,,,,,,,,,0,,,,0,,,,,,9.9964972,,,,
,27455113.36,9.9966736,-63931.240234375,0.00018068780497647,9.69121743476561E-7,1,0.999253354069792,40.0298881530762,1.99639218731733,17.0799996703863,0.00204101999797735,0.000366659898892338,0.25,-1.04437109030318E-7,0.000180736043966502,1.23914713913194E-6,9.9966736,9.9966736,-63936.4296875,-63926.05078125,57.241001348833,20.5131424597682,10.760172,0,0,0,40,4449,10.0134,-63931.240234375,,,,,,,,,,,,,0,,,,-0.0049,,,,,,9.9966736,,,,
,27455207.53,9.9964552,-68638.57421875,0.000196491017750877,1.01742602747686E-6,1,0.999253354069792,40.0298881530762,1.99632466608173,17.0799996703863,0.00221851992900682,0.000409203521094109,0.25,8.06562811615418E-7,0.000196618290227911,2.26226693387144E-6,9.9964552,9.9964552,-68673.4765625,-68603.671875,57.1612752398714,20.5175991357973,10.760172,0,0,0,40,4449,10.01685,-68638.57421875,,,,,,,,,,,,,0,,,,0,,,,,,9.9964552,,,,
,27455303.4,9.9957647,-73430.48828125,0.000211604981916192,8.70529970843201E-7,1,0.999253354069792,40.0298881530762,1.99636085768551,17.0799996703863,0.00239278202545759,0.000426341397190634,0.25,-4.04536140588131E-7,0.000211836345390898,1.15117544903671E-6,9.9957647,9.9957647,-73435.46875,-73425.5078125,57.1542405831984,20.5156012601797,10.38052,0,0,0,40,4449,10.0215,-73430.48828125,,,,,,,,,,,,,0,,,,0.00245,,,,,,9.9957647,,,,
,27455400.16,9.9959831,-78267.36328125,0.000232556528994511,7.8485724383753E-7,1,0.999253354069792,40.0298881530762,1.99630319162462,17.0799996703863,0.00262706373145373,0.000488510792793257,0.25,1.32247969251581E-6,0.000232886814609598,3.01832712427402E-6,9.9959831,9.9959831,-78272.421875,-78262.3046875,57.1042163579676,20.5182754774287,10.38052,0,0,0,40,4449,10.0251,-78267.36328125,,,,,,,,,,,,,0,,,,-0.0049,,,,,,9.9959831,,,,
,27455496.14,9.9956217,-83062.22265625,0.000249366368982906,1.21322821133384E-6,1,0.999253354069792,40.0298881530762,1.99629858068455,17.0799996703863,0.00281686352201802,0.000530054341897255,0.25,1.97428815924544E-6,0.000249805583928354,3.77320494338671E-6,9.9956217,9.9956217,-83064.8828125,-83059.5625,57.2027015513907,20.5185661152834,10.760172,0,0,0,40,4449,10.0291,-83062.22265625,,,,,,,,,,,,,0,,,,-0.00245,,,,,,9.9956217,,,,
,27455586.18,9.9954324,-87561.6484375,0.000264809808831569,1.09239715844464E-6,1,0.999253354069792,40.0298881530762,1.99628766186603,17.0799996703863,0.00299706419704353,0.000536229190778863,0.25,-2.49664973981446E-7,0.000265376455219746,1.63245380361179E-6,9.995307,9.9955578,-87566.7265625,-87556.5703125,57.2292769210445,20.5174066075997,10.38052,0,0,0,40,4449,10.0326,-87561.6484375,,,,,,,,,,,,,0,,,,0,,,,,,9.9954324,,,,
,27455694.295,9.9971218,-88051.32421875,0.000266756408083122,9.84105910008285E-7,1,0.999253354069792,40.0298881530762,1.99639265268454,17.0799996703863,0.00301497505850692,0.000564517748074497,0.25,1.89872491607382E-6,0.000267320786647978,3.79656550475339E-6,9.9971218,9.9971218,-88053.828125,-88048.8203125,57.1354814987368,20.5165657367299,10.38052,0,0,0,40,4449,10.0366,-88051.32421875,,,,,,,,,,,,,0,,,,-0.0049,,,,,,9.9971218,,,,
,27455784.42,10.0005083,-83548.53125,0.000250895626088649,9.32784529878123E-7,1,0.999253354069792,40.0298881530762,1.99628195572702,17.0799996703863,0.00284148786501065,0.000492906280853876,0.25,-1.5836338412689E-6,0.000251371987825982,2.17443171682484E-7,10.0005083,10.0005083,-83555.75,-83541.3125,57.0291800201214,20.519526485393,10.38052,0,0,0,40,4449,10.0351,-83548.53125,,,,,,,,,,,,,0,,,,-0.0049,,,,,,10.0005083,,,,
,27455880.93,10.0022221,-78725.921875,0.000233649477246618,7.4361029837973E-7,1,0.999253354069792,40.0298881530762,1.9964998516584,17.0799996703863,0.00264067748111222,0.000485723217687926,0.25,8.75415286248235E-7,0.000233992814711332,2.57685477875016E-6,10.0022221,10.0022221,-78738.28125,-78713.5625,57.2988418592561,20.5170363332067,11.139823,0,0,0,40,4449,10.0314,-78725.921875,,,,,,,,,,,,,0,,,,-0.00245,,,,,,10.0022221,,,,
,27455978.89,10.0031376,-73829.0625,0.000214025156418867,7.01052976420129E-7,1,0.999253354069792,40.0298881530762,1.99637009973608,17.0799996703863,0.00242298617822254,0.000415975930639098,0.25,-1.75771519024526E-6,0.000214275999174952,-1.86823301142056E-7,10.0031376,10.0031376,-73836.46875,-73821.65625,57.2011382943522,20.5179988424685,11.139823,0,0,0,40,4449,10.02925,-73829.0625,,,,,,,,,,,,,0,,,,0,,,,,,10.0031376,,,,
,27456075.09,10.0034895,-69022.703125,0.000196086703564716,7.4847206226516E-7,1,0.999253354069792,40.0298881530762,1.9963193192565,17.0799996703863,0.00221507639373169,0.000402523848548653,0.25,2.87887536228172E-7,0.00019622400804644,1.73958548755495E-6,10.0034895,10.0034895,-69025.0078125,-69020.3984375,56.892395029256,20.5195708172401,10.38052,0,0,0,40,4449,10.0261,-69022.703125,,,,,,,,,,,,,0,,,,0,,,,,,10.0034895,,,,
,27456172.375,10.0036821,-64157.5703125,0.000178969677506687,7.19665375801701E-7,1,0.999253354069792,40.0298881530762,1.99644077249663,17.0799996703863,0.0020240033009192,0.000350413329696103,0.25,-1.23434434247727E-6,0.000179029523758306,9.59718597324402E-8,10.0036821,10.0036821,-64162.46875,-64152.671875,57.5200427301984,20.5187429670253,10.760172,0,0,0,40,4449,10.02155,-64157.5703125,,,,,,,,,,,,,0,,,,0,,,,,,10.0036821,,,,
,27456270.05,10.0036669,-59277.4921875,0.000162181489943248,7.42613735976752E-7,1,0.999253354069792,40.0298881530762,1.99638909861899,17.0799996703863,0.00183011953970356,0.000334871232887153,0.25,4.27865954534633E-7,0.000162151059844707,1.63491331742464E-6,10.0036669,10.0036669,-59280.03125,-59274.953125,57.1143775287176,20.5191043903192,10.760172,0,0,0,40,4449,10.0183,-59277.4921875,,,,,,,,,,,,,0,,,,0,,,,,,10.0036669,,,,
,27456368.49,10.003334,-54355.515625,0.000143152394434288,7.12935235280279E-7,1,0.999253354069792,40.0298881530762,1.99646741508636,17.0799996703863,0.00161634631745917,0.000286204771865864,0.25,-4.39097689091526E-7,0.000143063542286224,6.23616053258405E-7,10.003334,10.003334,-54363.02734375,-54348.00390625,56.9252234270637,20.5181116116496,10.760172,0,0,0,40,4449,10.01405,-54355.515625,,,,,,,,,,,,,0,,,,0.0049,,,,,,10.003334,,,,
,27456466.89,10.0040641,-49441.267578125,0.000125640184238561,7.35125481764609E-7,1,0.999253354069792,40.0298881530762,1.99637518544708,17.0799996703863,0.00141846389881022,0.000247659975355252,0.25,-6.80221932279535E-7,0.000125502448671368,2.46167436864523E-7,10.0039015,10.0042267,-49451.01953125,-49431.515625,57.4504777919868,20.5176958120461,10.760172,0,0,0,40,4449,10.0105,-49441.267578125,,,,,,,,,,,,,0,,,,-0.00245,,,,,,10.0040641,,,,
,27456562.995,10.0039616,-44638.9453125,0.000109769274779042,6.7837684518213E-7,1,0.999253354069792,40.0298881530762,1.99643325913592,17.0799996703863,0.00124085074034686,0.000204338895735915,0.25,-1.6435922664099E-6,0.000109602128385771,-8.41961559743352E-7,10.0039616,10.0039616,-44648.9765625,-44628.9140625,56.8603482599676,20.5175323546423,10.760172,0,0,0,40,4449,10.00635,-44638.9453125,,,,,,,,,,,,,0,,,,0.0049,,,,,,10.0039616,,,,
,27456658.83,10.0035467,-39846.171875,9.31466933941941E-5,6.44445241785911E-7,1,0.999253354069792,40.0298881530762,1.99639215137187,17.0799996703863,0.00105182564777508,0.000176445198316419,0.25,-1.10445647207081E-6,9.29556456636209E-5,-4.35925766551141E-7,10.0035467,10.0035467,-39855.97265625,-39836.37109375,56.7939098358329,20.5174058269097,10.38052,0,0,0,40,4449,10.00395,-39846.171875,,,,,,,,,,,,,0,,,,0,,,,,,10.0035467,,,,
,27456755.7,10.0030546,-35006.240234375,7.61506300571917E-5,6.59804421681074E-7,1,0.999253354069792,40.0298881530762,1.99632130310248,17.0799996703863,0.0008605949417785,0.00013768756875744,0.25,-1.46596743137256E-6,7.59591136675618E-5,-9.30305043377546E-7,10.0030546,10.0030546,-35013.79296875,-34998.6875,56.9611783389483,20.5158671540325,11.139823,0,0,0,40,4449,10.0016,-35006.240234375,,,,,,,,,,,,,0,,,,-0.0049,,,,,,10.0030546,,,,
,27456851.545,10.0023155,-30213.9755859375,5.77535553853037E-5,6.86818179395839E-7,1,0.999253354069792,40.0298881530762,1.99630307521047,17.0799996703863,0.000653687106018263,9.68950182998756E-5,0.25,-1.76391745326972E-6,5.75832320499742E-5,-1.36708342673933E-6,10.0023155,10.0023155,-30221.9765625,-30205.974609375,57.1237570709483,20.5166949113531,10.760172,0,0,0,40,4449,10.00045,-30213.9755859375,,,,,,,,,,,,,0,,,,0,,,,,,10.0023155,,,,
,27456946.845,10.0010891,-25454.1552734375,4.12617452248774E-5,5.57161804861213E-7,1,0.999253354069792,40.0298881530762,1.99641101335045,17.0799996703863,0.000465422783569395,7.69403645295564E-5,0.25,-5.61743639079982E-7,4.11147901969396E-5,-2.90369888267906E-7,10.0010891,10.0010891,-25463.8125,-25444.498046875,56.6266413327175,20.516304622132,10.760172,0,0,0,40,4449,9.9996,-25454.1552734375,,,,,,,,,,,,,0,,,,0,,,,,,10.0010891,,,,
,27457037.11,10.000906,-20942.2138671875,2.65161561000356E-5,5.03972075918056E-7,1,0.999253354069792,40.0298881530762,1.99639929168927,17.0799996703863,0.000301047285257226,3.77453862345142E-5,0.25,-1.39197290071481E-6,2.64160513462983E-5,-1.2203395790925E-6,10.000906,10.000906,-20952.326171875,-20932.1015625,57.1409528983714,20.517846035028,10.760172,0,0,0,40,4449,9.9993,-20942.2138671875,,,,,,,,,,,,,0,,,,0,,,,,,10.000906,,,,
,27457133.11,10.00065185,-16144.982421875,1.04505855638117E-5,4.60122132201329E-7,1,0.999253354069792,40.0298881530762,1.99640884736671,17.0799996703863,0.000118616900656272,1.47356890616192E-5,0.25,-5.57149835087011E-7,1.04062277136223E-5,-4.92555117762073E-7,10.0006266,10.0006771,-16149.736328125,-16140.228515625,56.9603967104291,20.514742518427,11.139823,0,0,0,40,4449,9.9993,-16144.982421875,,,,,,,,,,,,,0,,,,-0.00245,,,,,,10.00065185,,,,
,27457223.35,9.9991541,-11631.9521484375,-4.91265847851512E-6,6.40949610706522E-7,1,0.999253354069792,40.0298881530762,1.99637458522263,17.0799996703863,-5.34117301938811E-5,-1.99510769533607E-5,0.25,-8.98770625838701E-7,-4.88324711701876E-6,-9.21893819603887E-7,9.9991541,9.9991541,-11637.0771484375,-11626.8271484375,57.0745144742368,20.5168200545365,11.139823,0,0,0,40,4449,9.9998,-11631.9521484375,,,,,,,,,,,,,0,,,,0,,,,,,9.9991541,,,,
,27457318.025,9.9988565,-6901.41137695313,-2.00207613929707E-5,3.74014257037959E-7,1,0.999253354069792,40.0298881530762,1.99645871962209,17.0799996703863,-0.000223244512585499,-4.96445750879376E-5,0.25,-8.54004280092934E-7,-1.99094775787745E-5,-9.54863588009594E-7,9.9988565,9.9988565,-6908.9951171875,-6893.82763671875,56.7212183835445,20.5139403163174,10.38052,0,0,0,40,4449,10.0006,-6901.41137695313,,,,,,,,,,,,,0,,,,0,,,,,,9.9988565,,,,
,27457412.095,10.0003309,-2200.46887207031,-3.21340997207372E-5,3.18958333619031E-7,1,0.999253354069792,40.0298881530762,1.99641795461834,17.0799996703863,-0.000359679515904497,-7.13430436957256E-5,0.25,-6.41202598072587E-7,-3.1949613041686E-5,-7.9624359704982E-7,10.0003309,10.0003309,-2205.36840820313,-2195.5693359375,56.8705094307176,20.513517810244,10.760172,0,0,0,40,4449,10.0009,-2200.46887207031,,,,,,,,,,,,,0,,,,0.00245,,,,,,10.0003309,,,,
,27457504.07,9.99929525,2395.52551269531,-4.17139748241743E-5,2.70766487302725E-7,1,0.999253354069792,40.0298881530762,1.99647870350537,17.0799996703863,-0.000467795609582196,-8.77248140789866E-5,0.25,-3.96453216405948E-7,-4.1477096390592E-5,-6.00697559087395E-7,9.9991207,9.9994698,2357.98364257813,2433.0673828125,56.8963031718522,20.5127102726666,10.760172,0,0,0,40,4449,9.99895,2395.52551269531,,,,,,,,,,,,,0,,,,0.00245,,,,,,9.99929525,,,,
,27457598.63,9.9993296,7122.55712890625,-5.22927431054033E-5,3.42949097000516E-7,1,0.999253354069792,40.0298881530762,1.9964939419277,17.0799996703863,-0.000586556222038642,-0.000110356715722044,0.25,-5.10725993278733E-7,-5.20119768183264E-5,-7.84193162038866E-7,9.9993296,9.9993296,7112.58984375,7132.5244140625,57.2128627221407,20.5115750445405,10.760172,0,0,0,40,4449,10.0012,7122.55712890625,,,,,,,,,,,,,0,,,,0,,,,,,9.9993296,,,,
,27457692.345,10.0003281,11805.474609375,-6.3972784399458E-5,4.47963276159831E-7,1,0.999253354069792,40.0298881530762,1.99631357600533,17.0799996703863,-0.000718326987992441,-0.000131947552574943,0.25,-3.27153046288984E-7,-6.36545929420204E-5,-6.85507562309793E-7,10.0003281,10.0003281,11805.474609375,11805.474609375,56.8673829166406,20.5135464209189,10.760172,0,0,0,40,4449,9.9998,11805.474609375,,,,,,,,,,,,,0,,,,0.0049,,,,,,10.0003281,,,,
,27457785.845,10.0010538,16478.06640625,-7.20184697341208E-5,4.97220510610185E-7,1,0.999253354069792,40.0298881530762,1.9963582719074,17.0799996703863,-0.000810394554764744,-0.000140937779517212,0.25,3.37848845741456E-7,-7.16942150911588E-5,-9.29782502502206E-8,10.0010443,10.0010633,16443.126953125,16513.005859375,57.2042648084291,20.512766922962,10.38052,0,0,0,40,4449,9.99935,16478.06640625,,,,,,,,,,,,,0,,,,0,,,,,,10.0010538,,,,
,27457878.78,10.0005512,21122.9794921875,-7.42554967524811E-5,5.30342151506469E-7,1,0.999253354069792,40.0298881530762,1.99626353771279,17.0799996703863,-0.000835189014685728,-0.000149372172681794,0.25,1.56435853617582E-8,-7.39521918184693E-5,-4.49911666147094E-7,10.0005512,10.0005512,21090.9375,21155.021484375,57.0049495360253,20.5137403771518,10.760172,0,0,0,40,4449,9.99825,21122.9794921875,,,,,,,,,,,,,0,,,,-0.00245,,,,,,10.0005512,,,,
,27457970.905,10.0005922,25728.146484375,-7.32237353452068E-5,5.92603782635587E-7,1,0.999253354069792,40.0298881530762,1.99634863620803,17.0799996703863,-0.00082439306636159,-0.000145194994354618,0.25,2.28757388258102E-7,-7.29599927840876E-5,-2.51137807976635E-7,10.0005922,10.0005922,25718.109375,25738.18359375,57.1589303543137,20.5120375168823,10.38052,0,0,0,40,4449,9.999,25728.146484375,,,,,,,,,,,,,0,,,,0,,,,,,10.0005922,,,,
,27458066.105,10.0009184,30484.076171875,-7.51888911720074E-5,7.23347190743549E-7,1,0.999253354069792,40.0298881530762,1.99633361668031,17.0799996703863,-0.000847517616292237,-0.000145915841714436,0.25,5.41765920602535E-7,-7.49574027056104E-5,2.97178767973096E-8,10.0009184,10.0009184,30481.611328125,30486.541015625,57.2480360055061,20.5141659290009,10.760172,0,0,0,40,4449,9.9983,30484.076171875,,,,,,,,,,,,,0,,,,-0.0049,,,,,,10.0009184,,,,
,27458159.96,9.99953555,35176.92578125,-8.42252424366435E-5,8.39085712352326E-7,1,0.999253354069792,40.0298881530762,1.99617153747982,17.0799996703863,-0.000949533106859577,-0.000164871275041654,0.25,5.03815714261332E-7,-8.40071441403987E-5,-8.62363791179157E-8,9.9994869,9.9995842,35169.8359375,35184.015625,56.7087123272368,20.5128633932358,10.760172,0,0,0,40,4449,9.9993,35176.92578125,,,,,,,,,,,,,0,,,,0,,,,,,9.99953555,,,,
,27458254.14,9.9990349,39883.994140625,-9.63252969752897E-5,9.40628909356884E-7,1,0.999253354069792,40.0298881530762,1.99631421811679,17.0799996703863,-0.00108773966604945,-0.000182144057360526,0.25,1.17031861668795E-6,-9.61283189287348E-5,4.78807861738491E-7,9.9990349,9.9990349,39881.68359375,39886.3046875,57.1362631272561,20.5114280822345,10.38052,0,0,0,40,4449,10.0002,39883.994140625,,,,,,,,,,,,,0,,,,0,,,,,,9.9990349,,,,
,27458351.21,9.9980965,44737.046875,-0.000110745051519298,7.57109892251553E-7,1,0.999253354069792,40.0298881530762,1.99636769981593,17.0799996703863,-0.0012473985655291,-0.000230894432327151,0.25,-5.36388987361385E-7,-0.000110561579434887,-1.34181230729614E-6,9.9980965,9.9980965,44734.56640625,44739.52734375,56.8814522299868,20.513451068529,11.139823,0,0,0,40,4449,10.0004,44737.046875,,,,,,,,,,,,,0,,,,0,,,,,,9.9980965,,,,
,27458444.645,9.9970627,49407.396484375,-0.000126297841426266,8.05759059098077E-7,1,0.999253354069792,40.0298881530762,1.99638834496588,17.0799996703863,-0.0014219976964357,-0.000270574905757709,0.25,-1.23293767285483E-6,-0.000126144830181159,-2.16193120849765E-6,9.9970627,9.9970627,49397.3515625,49417.44140625,57.0596635323714,20.5138923822206,10.760172,0,0,0,40,4449,10.0046,49407.396484375,,,,,,,,,,,,,0,,,,-0.00245,,,,,,9.9970627,,,,
,27458541.205,9.9972286,54232.095703125,-0.000142862314672604,8.62919348594309E-7,1,0.999253354069792,40.0298881530762,1.99629778889167,17.0799996703863,-0.00161363973683144,-0.000281607901721213,0.25,7.91714150645781E-7,-0.000142774528656196,-2.68948020986879E-7,9.9972286,9.9972286,54229.48828125,54234.703125,56.841589175506,20.5130090841011,10.760172,0,0,0,40,4449,10.0062,54232.095703125,,,,,,,,,,,,,0,,,,-0.0049,,,,,,9.9972286,,,,
,27458635.915,9.9965305,58965.32421875,-0.000160274360373224,8.3886966158858E-7,1,0.999253354069792,40.0298881530762,1.9962886938829,17.0799996703863,-0.0018078188506852,-0.000334456164973839,0.25,-7.37199051432553E-7,-0.000160237211730368,-1.92990748153966E-6,9.9964933,9.9965677,58962.81640625,58967.83203125,57.0205821064099,20.5111103555203,10.760172,0,0,0,40,4449,10.0108,58965.32421875,,,,,,,,,,,,,0,,,,0.00245,,,,,,9.9965305,,,,
,27458731.07,9.9970589,63723.1796875,-0.000177905925992811,1.06657232014546E-6,1,0.999253354069792,40.0298881530762,1.99633134172282,17.0799996703863,-0.00200998467955527,-0.000358308755725596,0.25,3.410653445124E-7,-0.000177951842434253,-9.81923533863156E-7,9.9970589,9.9970589,63715.52734375,63730.83203125,57.0612267894099,20.5080643579175,10.38052,0,0,0,40,4449,10.01585,63723.1796875,,,,,,,,,,,,,0,,,,0,,,,,,9.9970589,,,,
,27458825.21,9.995862,68428.2734375,-0.000194544512408243,6.9708484297414E-7,1,0.999253354069792,40.0298881530762,1.99626469128961,17.0799996703863,-0.00219648399989344,-0.00040488563098687,0.25,-7.76489092278201E-7,-0.000194667162535352,-2.21809615953925E-6,9.995862,9.995862,68428.2734375,68428.2734375,57.1284468420637,20.5090246479888,10.38052,0,0,0,40,4449,10.0176,68428.2734375,,,,,,,,,,,,,0,,,,0.0049,,,,,,9.995862,,,,
,27458922.95,9.9966116,73313.76953125,-0.000212158198615001,8.32889677685441E-7,1,0.999253354069792,40.0298881530762,1.99639957303996,17.0799996703863,-0.00239518196496926,-0.00044898250812313,0.25,-1.49806394146835E-6,-0.000212374147799835,-3.06019766730337E-6,9.9966116,9.9966116,73311.21875,73316.3203125,56.8775440873906,20.506053448705,11.139823,0,0,0,40,4449,10.0213,73313.76953125,,,,,,,,,,,,,0,,,,0,,,,,,9.9966116,,,,
,27459017.325,9.9955568,78031.8671875,-0.000229571319468817,8.03081260836431E-7,1,0.999253354069792,40.0298881530762,1.99635749032468,17.0799996703863,-0.00259347713481097,-0.000481604233380334,0.25,-1.24804388561808E-6,-0.000229893626659748,-2.92288512388318E-6,9.9955568,9.9955568,78024.0703125,78039.6640625,56.9166255133522,20.508967168735,10.760172,0,0,0,40,4449,10.0237,78031.8671875,,,,,,,,,,,,,0,,,,0,,,,,,9.9955568,,,,
,27459114.205,9.9954405,82872.81640625,-0.000247682717142262,8.2644737270207E-7,1,0.999253354069792,40.0298881530762,1.99633718559781,17.0799996703863,-0.00279997491150124,-0.000514718525364743,0.25,-9.20507082870152E-7,-0.000248123068202493,-2.70625931075014E-6,9.9954405,9.9954405,82867.7109375,82877.921875,56.7649895806214,20.5100947296341,10.760172,0,0,0,40,4449,10.0281,82872.81640625,,,,,,,,,,,,,0,,,,-0.00245,,,,,,9.9954405,,,,
,27459203.65,9.9951353,87346.1796875,-0.000262614313888831,7.64794153348619E-7,1,0.999253354069792,40.0298881530762,1.99627961693279,17.0799996703863,-0.00297151615899269,-0.000535359656129219,0.25,-6.81020941249767E-8,-0.000263170172112661,-1.9364774939062E-6,9.9951353,9.9951353,87341.0859375,87351.2734375,56.8220484625252,20.5076991041583,10.760172,0,0,0,40,4449,10.0307,87346.1796875,,,,,,,,,,,,,0,,,,0,,,,,,9.9951353,,,,
,27459309.8,9.9974103,88315.640625,-0.000267663332388917,6.97315118236828E-7,1,0.999253354069792,40.0298881530762,1.99643682761373,17.0799996703863,-0.00302842822142306,-0.000549307031839864,0.25,-3.91162258276711E-7,-0.000268245140393132,-2.29067481772153E-6,9.9973984,9.9974222,88283.03125,88348.25,56.9205336559483,20.5083455854834,10.760172,0,0,0,40,4449,10.0347,88315.640625,,,,,,,,,,,,,0,,,,0,,,,,,9.9974103,,,,
,27459402.15,10.0009747,83699.65234375,-0.000250704463117407,5.8595610777146E-7,1,0.999253354069792,40.0298881530762,1.99643117945112,17.0799996703863,-0.00283457446173113,-0.000520250310366594,0.25,-8.64886491292092E-7,-0.000251165578229908,-2.66840795931005E-6,10.0009747,10.0009747,83694.546875,83704.7578125,57.0307432771599,20.5073067578245,11.139823,0,0,0,40,4449,10.0338,83699.65234375,,,,,,,,,,,,,0,,,,0,,,,,,10.0009747,,,,
,27459501.985,10.0018148,78708.20703125,-0.00023260466426362,6.02202918038784E-7,1,0.999253354069792,40.0298881530762,1.99633232376514,17.0799996703863,-0.00262894837680826,-0.000481882851215855,0.25,-7.27383210529906E-7,-0.000232947200776019,-2.42106539787504E-6,10.0018148,10.0018148,78700.9296875,78715.484375,56.6657227586791,20.5088428389604,11.139823,0,0,0,40,4449,10.02995,78708.20703125,,,,,,,,,,,,,0,,,,-0.00245,,,,,,10.0018148,,,,
,27459599.055,10.002449,73857.7109375,-0.000214539655661808,7.31335116999817E-7,1,0.999253354069792,40.0298881530762,1.99631140743786,17.0799996703863,-0.00242305208730765,-0.000448585303956857,0.25,-1.03539035821203E-6,-0.000214771042621719,-2.61309038106354E-6,10.002449,10.002449,73852.3828125,73863.0390625,56.861911517006,20.5108902214451,10.760172,0,0,0,40,4449,10.02695,73857.7109375,,,,,,,,,,,,,0,,,,0,,,,,,10.002449,,,,
,27459694.54,10.0037155,69084.421875,-0.000196772463330547,8.5085594827634E-7,1,0.999253354069792,40.0298881530762,1.99649475911643,17.0799996703863,-0.00222259594391187,-0.000406327437108027,0.25,-4.97841775834694E-7,-0.000196909741490307,-1.95465743249887E-6,10.0036287,10.0038023,69079.6015625,69089.2421875,56.7774956369291,20.5120575549504,10.760172,0,0,0,40,4449,10.02455,69084.421875,,,,,,,,,,,,,0,,,,0,,,,,,10.0037155,,,,
,27459795.855,10.0037365,64019.2578125,-0.000178913815958831,8.27941984083833E-7,1,0.999253354069792,40.0298881530762,1.99640669339188,17.0799996703863,-0.00201962414173817,-0.000370761941572526,0.25,-5.78081758793949E-7,-0.000178957935667103,-1.90859343782343E-6,10.0037365,10.0037365,64011.734375,64026.78125,56.9986965078714,20.5114725941095,10.38052,0,0,0,40,4449,10.0202,64019.2578125,,,,,,,,,,,,,0,,,,-0.0049,,,,,,10.0037365,,,,
,27459891.85,10.0035877,59218.369140625,-0.000161543973709856,6.1288637257726E-7,1,0.999253354069792,40.0298881530762,1.99644262059191,17.0799996703863,-0.00182584344222996,-0.000317575999209902,0.25,9.89717009705888E-7,-0.000161523298185333,-2.12817023304209E-7,10.0035877,10.0035877,59213.44140625,59223.296875,56.902556200006,20.5117388739713,10.760172,0,0,0,40,4449,10.0172,59218.369140625,,,,,,,,,,,,,0,,,,0,,,,,,10.0035877,,,,
,27459991.165,10.0043707,54255.689453125,-0.000143100683847227,9.21755679759395E-7,1,0.999253354069792,40.0298881530762,1.99645251732667,17.0799996703863,-0.00161597335343828,-0.000284774157768736,0.25,5.56023299630173E-7,-0.000143011324016937,-5.06278050699181E-7,10.0043707,10.0043707,54250.3671875,54261.01171875,56.6571248449675,20.5103011963464,10.760172,0,0,0,40,4449,10.0119,54255.689453125,,,,,,,,,,,,,0,,,,0,,,,,,10.0043707,,,,
,27460093.015,10.0038948,49168.16796875,-0.000125402172587212,5.63411381703649E-7,1,0.999253354069792,40.0298881530762,1.99643295499061,17.0799996703863,-0.00141481645153241,-0.000252518187516239,0.25,2.06109233005573E-7,-0.000125257722080613,-7.1748273293686E-7,10.0038948,10.0038948,49158.18359375,49178.15234375,56.5859966497175,20.5116125268916,10.760172,0,0,0,40,4449,10.0095,49168.16796875,,,,,,,,,,,,,0,,,,-0.00245,,,,,,10.0038948,,,,
,27460192.67,10.0039873,44184.771484375,-0.000107074557148996,6.5499948552373E-7,1,0.999253354069792,40.0298881530762,1.99641967278754,17.0799996703863,-0.00120850131735278,-0.000209430600631763,0.25,7.04572673048229E-7,-0.000106899886512233,-7.48403031007816E-8,10.0039873,10.0039873,44175.1484375,44194.39453125,56.9799374234099,20.5139815372809,10.760172,0,0,0,40,4449,10.005,44184.771484375,,,,,,,,,,,,,0,,,,-0.0049,,,,,,10.0039873,,,,
,27460289.04,10.0030403,39367.59765625,-8.95866850578032E-5,6.23654820678406E-7,1,0.999253354069792,40.0298881530762,1.99643050281967,17.0799996703863,-0.00100870439842634,-0.000185744920279373,0.25,-3.63373570543243E-7,-8.93882086635198E-5,-1.00196267574604E-6,10.0030403,10.0030403,39357.7265625,39377.46875,56.9119357422368,20.5127913127895,10.38052,0,0,0,40,4449,10.0025,39367.59765625,,,,,,,,,,,,,0,,,,0,,,,,,10.0030403,,,,
,27460385.83,10.0029116,34530.4296875,-7.24878421715268E-5,5.48408046714207E-7,1,0.999253354069792,40.0298881530762,1.9965001455916,17.0799996703863,-0.00081732705451625,-0.000141649679214284,0.25,4.54700136215563E-7,-7.22952990478626E-5,-5.13618338040717E-8,10.0029116,10.0029116,34520.91015625,34539.94921875,56.9205336559483,20.5152725444908,10.760172,0,0,0,40,4449,10.0004,34530.4296875,,,,,,,,,,,,,0,,,,0,,,,,,10.0029116,,,,
,27460482.36,10.0018148,29708.3466796875,-5.6542394779565E-5,5.771326015841E-7,1,0.999253354069792,40.0298881530762,1.99633520613765,17.0799996703863,-0.000638350187966265,-0.000103789627134198,0.25,9.32211299507018E-7,-5.63672362143869E-5,5.475380576564E-7,10.0018148,10.0018148,29703.33203125,29713.361328125,56.8056342636214,20.5173434573372,10.760172,0,0,0,40,4449,9.9992,29708.3466796875,,,,,,,,,,,,,0,,,,-0.00245,,,,,,10.0018148,,,,
,27460577.25,10.0010471,24965.1875,-4.02155667387797E-5,3.66888215515E-7,1,0.999253354069792,40.0298881530762,1.99640243285301,17.0799996703863,-0.000453671703072658,-7.45703376059116E-5,0.25,5.83291570480136E-7,-4.00705453583678E-5,3.19750453683092E-7,10.0010471,10.0010471,24960.19140625,24970.18359375,57.027616763083,20.5160077349456,11.139823,0,0,0,40,4449,9.99845,24965.1875,,,,,,,,,,,,,0,,,,0,,,,,,10.0010471,,,,
,27460673.025,10.0008383,20175.4794921875,-2.38312098285885E-5,4.27290513227166E-7,1,0.999253354069792,40.0298881530762,1.99637525232373,17.0799996703863,-0.000268998589203392,-4.25307094759868E-5,0.25,4.84276126961606E-7,-2.37346317586533E-5,3.34299387810419E-7,10.0008383,10.0008383,20173.109375,20177.849609375,56.8931766577752,20.5169297861255,11.139823,0,0,0,40,4449,9.99805,20175.4794921875,,,,,,,,,,,,,0,,,,0.0049,,,,,,10.0008383,,,,
,27460767.275,10.0001383,15468.2934570313,-7.33808181846718E-6,3.75222431418978E-7,1,0.999253354069792,40.0298881530762,1.99639133800317,17.0799996703863,-8.36800237950257E-5,-8.12444933776942E-6,0.25,5.88487395156691E-7,-7.30762402045233E-6,5.42542136991556E-7,10.0001383,10.0001383,15460.84765625,15475.7392578125,57.0330881627176,20.5172848815531,10.38052,0,0,0,40,4449,9.99785,15468.2934570313,,,,,,,,,,,,,0,,,,0,,,,,,10.0001383,,,,
,27460861.55,9.9992399,10755.7524414062,8.48603448261383E-6,4.36919543341932E-7,1,0.999253354069792,40.0298881530762,1.99640860677633,17.0799996703863,9.49222168602215E-5,1.95225693399022E-5,0.25,2.23823291486439E-7,8.44208401476013E-6,2.69792678288008E-7,9.9992399,9.9992399,10748.3408203125,10763.1640625,57.1511140691214,20.5162957648606,10.760172,0,0,0,40,4449,9.99855,10755.7524414062,,,,,,,,,,,,,0,,,,0,,,,,,9.9992399,,,,
,27460952.6,9.9987574,6202.94848632813,2.28174736674813E-5,2.90454131628689E-7,1,0.999253354069792,40.0298881530762,1.99647569234709,17.0799996703863,0.000256063424787354,4.73394355503412E-5,0.25,1.52284045536869E-7,2.26938218689481E-5,2.70440223873432E-7,9.9987574,9.9987574,6195.57958984375,6210.3173828125,56.9713395096983,20.5170674937301,10.38052,0,0,0,40,4449,9.9998,6202.94848632813,,,,,,,,,,,,,0,,,,0,,,,,,9.9987574,,,,
,27461046.08,10.0007343,1531.72021484375,3.42343611869913E-5,3.82292152196973E-7,1,0.999253354069792,40.0298881530762,1.99643638671173,17.0799996703863,0.000385583488045787,6.2461210701462E-5,0.25,-5.21133967210164E-7,3.40425040027832E-5,-3.50551644207524E-7,10.0007343,10.0007343,1521.67687988281,1541.76354980469,56.8298647477175,20.5180357431023,10.38052,0,0,0,40,4449,9.9999,1531.72021484375,,,,,,,,,,,,,0,,,,-0.00245,,,,,,10.0007343,,,,
,27461078.27,10.0026045,-0.380594328045845,3.77477057474714E-5,3.01076887774814E-7,1,0.999253354069792,40.0298881530762,1.99644643109644,17.0799996703863,0.000424432566261858,7.27818184231155E-5,0.25,-2.23193114391455E-7,3.75319367208957E-5,-3.99695012753852E-8,10.0026045,10.0026045,-0.395818114280701,-0.365370541810989,57.1683098965445,20.516033843646,10.38052,0,0,0,40,4417,9.9953,-0.380594328045845,,,,,,,,,,,,,0,,,,0,,,,,,10.0026045,,,,