File: data/monolayers/nanoparticles/Ac_CoFe_C/vsm/data_disorderedWafer/DD226_2_HYST_300K_INIT.DAT
[Header]
; VSM Data File (default extension .dat)
; Copyright (c) 2003-2013, Quantum Design, Inc. All rights reserved.
TITLE,
FILEOPENTIME,27265680.19,11/12/2018,9:48 pm
BYAPP,VSM,2.0,2.0
INFO,PPMS VSM Option Release 1.4.10 Build 1,APPNAME
INFO,Quantum Design Linear Motor Servo Controller,MOTOR_MODULE_NAME
INFO,3101-100 M1,MOTOR_HW_VERSION
INFO,MMC1014,MOTOR_SERIAL_NUMBER
INFO,SRV No X-over 01.03.11,MOTOR_SOFTWARE_VERSION
INFO,Quantum Design VSM Detection Module,VSM_MODULE_NAME
INFO,3101-150 F0,VSM_HW_VERSION
INFO,VSM707,VSM_SERIAL_NUMBER
INFO,VSM No X-over 01.02.05 May 20 2008 13:51:47,VSM_SOFTWARE_VERSION
INFO,704,PREAMP_SERIAL_NUMBER
INFO,822,COIL_SERIAL_NUMBER
INFO,0,MOMENT_UNITS
INFO,CoFe2O4 AH11,SAMPLE_MATERIAL
INFO,Quick Dry Monolayer Conc,SAMPLE_COMMENT
INFO,27.96,SAMPLE_MASS
INFO,,SAMPLE_VOLUME
INFO,,SAMPLE_MOLECULAR_WEIGHT
INFO,,SAMPLE_SIZE
INFO,,SAMPLE_SHAPE
DATATYPE,COMMENT,1
DATATYPE,TIME,2
STARTUPAXIS,X,2
STARTUPAXIS,Y1,5
[Data]
Comment,Time Stamp (sec),Temperature (K),Magnetic Field (Oe),Moment (emu),M. Std. Err. (emu),Transport Action,Averaging Time (sec),Frequency (Hz),Peak Amplitude (mm),Center Position (mm),Coil Signal' (mV),Coil Signal" (mV),Range (mV),M. Quad. Signal (emu),M. Raw' (emu),M. Raw" (emu),Min. Temperature (K),Max. Temperature (K),Min. Field (Oe),Max. Field (Oe),Mass (grams),Motor Lag (deg),Pressure (Torr),VSM Status (code),Motor Status (code),Measure Status (code),Measure Count,PPMS Status (code),System Temp. (K),System Field (Oe),Sample Position (deg),Bridge 1 Resistance (ohms),Bridge 1 Excitation (�A),Bridge 2 Resistance (ohms),Bridge 2 Excitation (�A),Bridge 3 Resistance (ohms),Bridge 3 Excitation (�A),Bridge 4 Resistance (ohms),Bridge 4 Excitation (�A),Signal 1 Vin (V),Signal 2 Vin (V),Digital Inputs (code),Drive 1 Iout (mA),Drive 1 Ipower (W),Drive 2 Iout (mA),Drive 2 Ipower (W),Pressure (),Map 20 (),Map 21 (),Map 22 (),Map 23 (),Map 24 (),Map 25 (),Map 26 (),Map 27 (),Map 28 (),Map 29 ()
,27265696.95,300.0825195,0.121790185570717,,,2,,,,20.9299998873472,,,,,,,300.0825195,300.0825195,0.121790185570717,0.121790185570717,,,24.427608,,,,-99999999,4369,300.4826,0.121790185570717,,,,,,,,,,,,,,,,,,,,,,,300.0825195,,,,
,27265842.49,300.0222168,4348.60986328125,1.68518502771275E-5,5.00886326941713E-7,1,0.999253354069792,40.0298881530762,1.99834486282789,20.9199991077185,0.000190561845996359,3.37226015586317E-5,0.25,6.05794455717137E-8,1.68512952630372E-5,7.17412192596227E-8,300.0222168,300.0222168,4341.169921875,4356.0498046875,56.5602029085829,20.5773000203102,24.427608,0,0,0,40,4449,300.4696,4348.60986328125,,,,,,,,,,,,,0,,,,0,,,,,,300.0222168,,,,
,27265934.165,299.9961548,8929.57470703125,4.33230617950037E-6,1.07518528523868E-6,1,0.999253354069792,40.0298881530762,1.99812126693597,20.9199991077185,4.96541426585575E-5,4.8054328318727E-6,0.25,-3.2587246522678E-7,4.33239377823269E-6,-3.22995111625701E-7,299.9961548,299.9961548,8927.041015625,8932.1083984375,56.5156500829868,20.5824638624338,24.807261,0,0,0,40,4449,300.4841,8929.57470703125,,,,,,,,,,,,,0,,,,0,,,,,,299.9961548,,,,
,27266027.985,299.9773254,13617.5478515625,-1.08557676856265E-5,9.19910204597755E-7,1,0.999253354069792,40.0298881530762,1.99807232798382,20.9199991077185,-0.000121523801223712,-2.87519255767089E-5,0.25,-6.60498228780344E-7,-1.08550178093989E-5,-6.67658389767854E-7,299.9773254,299.9773254,13610.0693359375,13625.0263671875,56.6719757868329,20.5882746493638,24.427608,0,0,0,40,4449,300.50835,13617.5478515625,,,,,,,,,,,,,0,,,,0.0049,,,,,,299.9773254,,,,
,27266123.595,299.9878235,18397.4658203125,-2.58760222776297E-5,7.9719598565721E-7,1,0.999253354069792,40.0298881530762,1.99802725174349,20.9199991077185,-0.000289229433371382,-7.10185272066324E-5,0.25,-1.79416395584898E-6,-2.58740822883982E-5,-1.81120817765212E-6,299.9878235,299.9878235,18387.4921875,18407.439453125,56.5633294226598,20.5898593775343,24.047956,0,0,0,40,4449,300.51515,18397.4658203125,,,,,,,,,,,,,0,,,,-0.0049,,,,,,299.9878235,,,,
,27266221.215,299.9779358,23274.8232421875,-4.37980422707196E-5,1.0457604882308E-6,1,0.999253354069792,40.0298881530762,1.99760607856418,20.9199991077185,-0.000494087868937173,-9.34408848941761E-5,0.25,-6.72659481755058E-7,-4.37963394172369E-5,-7.01547386604567E-7,299.9779358,299.9779358,23264.845703125,23284.80078125,56.8963031718522,20.5949400608664,24.807261,0,0,0,40,4449,300.53625,23274.8232421875,,,,,,,,,,,,,0,,,,0.0049,,,,,,299.9779358,,,,
,27266314.31,299.9872131,27930.4208984375,-5.99292346531562E-5,1.1192587186327E-6,1,0.999253354069792,40.0298881530762,1.99741872134551,20.9199991077185,-0.000674251569660947,-0.000137958901955482,0.25,-1.81472709074662E-6,-5.99262994063425E-5,-1.8541866092002E-6,299.9872131,299.9872131,27923.15625,27937.685546875,56.6946430138906,20.5935477305966,24.807261,0,0,0,40,4449,300.5593,27930.4208984375,,,,,,,,,,,,,0,,,,0,,,,,,299.9872131,,,,
,27266409.115,299.9867554,32667.837890625,-7.72817258877181E-5,1.29356520408909E-6,1,0.999253354069792,40.0298881530762,1.99741239351252,20.9199991077185,-0.000870297981040599,-0.000173173602911735,0.25,-1.92195762605465E-6,-7.72782237108674E-5,-1.97280283395796E-6,299.9867554,299.9867554,32665.302734375,32670.373046875,57.0635716749676,20.6000050715039,24.807261,0,0,0,40,4449,300.5606,32667.837890625,,,,,,,,,,,,,0,,,,0.0049,,,,,,299.9867554,,,,
,27266504.89,299.9876709,37455.185546875,-9.26081687282597E-5,1.28690561721303E-6,1,0.999253354069792,40.0298881530762,1.99766128107735,20.9199991077185,-0.00104090149924857,-0.000219762511073526,0.25,-3.38355739576629E-6,-9.26032655871467E-5,-3.44438952997288E-6,299.9876709,299.9876709,37452.828125,37457.54296875,56.8673829166406,20.5999207601614,24.807261,0,0,0,40,4449,300.5648,37455.185546875,,,,,,,,,,,,,0,,,,0,,,,,,299.9876709,,,,
,27266600.85,299.9934692,42250.21484375,-0.000109521696632379,1.82780610734E-6,1,0.999253354069792,40.0298881530762,1.99758116196875,20.9199991077185,-0.00123635080524221,-0.000228771950092831,0.25,-1.25055852272796E-6,-0.000109517693023024,-1.32250181272726E-6,299.9934692,299.9934692,42240.625,42259.8046875,56.9322580837368,20.5950405936864,25.186911,0,0,0,40,4449,300.56505,42250.21484375,,,,,,,,,,,,,0,,,,0,,,,,,299.9934692,,,,
,27266697.58,300.0012512,47085.6015625,-0.000126594833712076,1.66710792491417E-6,1,0.999253354069792,40.0298881530762,1.99764409051306,20.9199991077185,-0.00143133457610081,-0.000251694672992569,0.25,-3.18591189994978E-7,-0.000126590920025377,-4.01686349567603E-7,300.0012512,300.0012512,47078.2265625,47092.9765625,56.9353845978137,20.5898314479999,24.807261,0,0,0,40,4449,300.5738,47085.6015625,,,,,,,,,,,,,0,,,,0,,,,,,300.0012512,,,,
,27266792.825,300.0082703,51845.95703125,-0.000144506188344116,1.85617586077314E-6,1,0.999253354069792,40.0298881530762,1.99807383175564,20.9199991077185,-0.00163118910894369,-0.000304645501632586,0.25,-1.89118386342717E-6,-0.000144500691828677,-1.98589200279996E-6,300.0082703,300.0082703,51835.88671875,51856.02734375,57.1128142716791,20.5905279431277,24.807261,0,0,0,40,4449,300.55275,51845.95703125,,,,,,,,,,,,,0,,,,0.00245,,,,,,300.0082703,,,,
,27266888.765,300.0057678,56640.55078125,-0.000162060404047341,2.33377716070079E-6,1,0.999253354069792,40.0298881530762,1.99805410057577,20.9199991077185,-0.00182119855570249,-0.000388552753401349,0.25,-6.266759606894E-6,-0.000162051550793973,-6.37273294044096E-6,300.0057678,300.0057678,56628.1015625,56653,56.8001628639868,20.5837622615426,25.186911,0,0,0,40,4449,300.5438,56640.55078125,,,,,,,,,,,,,0,,,,0.00245,,,,,,300.0057678,,,,
,27266985.57,300.0073547,61480.64453125,-0.000180514474430059,1.74642132898796E-6,1,0.999253354069792,40.0298881530762,1.99811831294789,20.9199991077185,-0.00203697685761572,-0.000384711529346908,0.25,-2.72913830655222E-6,-0.000180507402006892,-2.84716417119234E-6,300.0073547,300.0073547,61470.7890625,61490.5,57.0917103016599,20.5943503694426,24.807261,0,0,0,40,4449,300.54355,61480.64453125,,,,,,,,,,,,,0,,,,0,,,,,,300.0073547,,,,
,27267082.765,300.0176697,66336.3125,-0.000195016560864747,2.19927779369295E-6,1,0.999253354069792,40.0298881530762,1.99820367848844,20.9199991077185,-0.00219412266466472,-0.000453666672225975,0.25,-6.30988604168052E-6,-0.000195006666768126,-6.43714403779431E-6,300.0176697,300.0176697,66323.578125,66349.046875,56.5719273363714,20.5830004614979,24.807261,0,0,0,40,4449,300.5357,66336.3125,,,,,,,,,,,,,0,,,,0,,,,,,300.0176697,,,,
,27267180.17,300.0141907,71206.40625,-0.00021649285128656,2.44606744913238E-6,1,0.999253354069792,40.0298881530762,1.9983209464792,20.9199991077185,-0.00243008450976172,-0.000537155492269614,0.25,-9.96561699779018E-6,-0.000216479981583537,-1.01066413895961E-5,300.0141907,300.0141907,71196.234375,71216.578125,56.5109603118714,20.5879574063057,24.807261,0,0,0,40,4449,300.51655,71206.40625,,,,,,,,,,,,,0,,,,-0.00245,,,,,,300.0141907,,,,
,27267277.005,300.0112305,76044.625,-0.000232105441148657,2.08742937621152E-6,1,0.999253354069792,40.0298881530762,1.998212004928,20.9199991077185,-0.00262341889187454,-0.000470687468705604,0.25,-1.3887713598445E-6,-0.000232097753074716,-1.54005619928276E-6,300.0112305,300.0112305,76039.4375,76049.8125,56.7712426087752,20.5896438169517,24.807261,0,0,0,40,4449,300.5116,76044.625,,,,,,,,,,,,,0,,,,0.00245,,,,,,300.0112305,,,,
,27267373.01,300.0192566,80845.49609375,-0.000250588204042045,2.85142665810733E-6,1,0.999253354069792,40.0298881530762,1.9982729858842,20.9199991077185,-0.00283160774424849,-0.000512790674632227,0.25,-1.906733451917E-6,-0.000250579583522105,-2.06986974786935E-6,300.0192566,300.0192566,80837.9140625,80853.078125,56.9017745714868,20.5872708827291,24.807261,0,0,0,40,4449,300.48255,80845.49609375,,,,,,,,,,,,,0,,,,-0.0049,,,,,,300.0192566,,,,
,27267468.71,300.0274963,85628.45703125,-0.000265476758955018,2.49037608460769E-6,1,0.999253354069792,40.0298881530762,1.99808382406411,20.9199991077185,-0.00298905667460463,-0.000603918410685284,0.25,-7.38625858532332E-6,-0.000265464077983385,-7.558712726318E-6,300.0274963,300.0274963,85620.90625,85636.0078125,56.6563432164483,20.5903089214616,24.427608,0,0,0,40,4449,300.4832,85628.45703125,,,,,,,,,,,,,0,,,,0.00245,,,,,,300.0274963,,,,
,27267574.82,300.0164795,89965.765625,-0.000279379599802225,2.39904770203191E-6,1,0.999253354069792,40.0298881530762,1.99806572495041,20.9199991077185,-0.00315512113351487,-0.000580385757622227,0.25,-2.89824241436225E-6,-0.000279369554935574,-3.0796822366599E-6,300.0164795,300.0164795,89961.7265625,89969.8046875,56.841589175506,20.5901715996331,24.807261,0,0,0,40,4449,300.4619,89965.765625,,,,,,,,,,,,,0,,,,0.0049,,,,,,300.0164795,,,,
,27267668.585,300.010498,85294.10546875,-0.000265215148458998,2.44263320764973E-6,1,0.999253354069792,40.0298881530762,1.99798919071711,20.9199991077185,-0.00299465961224059,-0.000553184876139505,0.25,-2.9494861889181E-6,-0.000265205519560771,-3.12193813476866E-6,300.010498,300.010498,85284.2578125,85303.953125,56.8134505488137,20.5912407976067,24.807261,0,0,0,40,4449,300.45405,85294.10546875,,,,,,,,,,,,,0,,,,0.00245,,,,,,300.010498,,,,
,27267765.62,300.0125122,80445.1953125,-0.000250387027595663,2.61578371139011E-6,1,0.999253354069792,40.0298881530762,1.9984710114937,20.9199991077185,-0.00282707412890157,-0.00052702269063117,0.25,-3.19495987515719E-6,-0.000250377630747738,-3.35796721966058E-6,300.0125122,300.0125122,80435.25,80455.140625,56.790783321756,20.5868633760321,24.427608,0,0,0,40,4449,300.44705,80445.1953125,,,,,,,,,,,,,0,,,,0.00245,,,,,,300.0125122,,,,
,27267862.745,300.008728,75591.1640625,-0.00022766626513042,2.43293319124156E-6,1,0.999253354069792,40.0298881530762,1.99810375922566,20.9199991077185,-0.00256523749412772,-0.000507109729681857,0.25,-5.37920820303946E-6,-0.000227656119483791,-5.52753716659607E-6,300.008728,300.008728,75586.1796875,75596.1484375,56.7853119221214,20.5908390936344,25.186911,0,0,0,40,4449,300.44655,75591.1640625,,,,,,,,,,,,,0,,,,-0.00245,,,,,,300.008728,,,,
,27267957.185,300.0006409,70867.9296875,-0.000211527843151798,2.40294496494026E-6,1,0.999253354069792,40.0298881530762,1.99821488941297,20.9199991077185,-0.00237606274784622,-0.00051425574750372,0.25,-8.8041947838534E-6,-0.000211515974003826,-8.94206635291875E-6,300.0006409,300.0006409,70862.953125,70872.90625,56.7266897831791,20.5911372063881,24.807261,0,0,0,40,4449,300.4455,70867.9296875,,,,,,,,,,,,,0,,,,0,,,,,,300.0006409,,,,
,27268055.595,299.9972229,65950.03125,-0.000196551827593956,2.42967790477834E-6,1,0.999253354069792,40.0298881530762,1.99810165634984,20.9199991077185,-0.00221465035305253,-0.000437818387822829,0.25,-4.64498330249697E-6,-0.000196543114183415,-4.77335306199801E-6,299.9972229,299.9972229,65939.9140625,65960.1484375,56.8931766577752,20.5923114482622,24.427608,0,0,0,40,4449,300.44855,65950.03125,,,,,,,,,,,,,0,,,,0.00245,,,,,,299.9972229,,,,
,27268152.155,299.9959412,61122.13671875,-0.000176920245223981,2.54653338627252E-6,1,0.999253354069792,40.0298881530762,1.99805439071523,20.9199991077185,-0.00198568006845208,-0.000438674960124613,0.25,-8.12260619254694E-6,-0.000176909814645252,-8.23817871363257E-6,299.9959412,299.9959412,61117.0390625,61127.234375,56.997133250833,20.594078729512,25.186911,0,0,0,40,4449,300.44825,61122.13671875,,,,,,,,,,,,,0,,,,-0.0049,,,,,,299.9959412,,,,
,27268247.23,299.9866943,56371.267578125,-0.000158384489562348,1.89828612022369E-6,1,0.999253354069792,40.0298881530762,1.99814844348897,20.9199991077185,-0.00177713350996816,-0.000396133618037961,0.25,-7.57204480702845E-6,-0.000158374992066982,-7.67561683946544E-6,299.9866943,299.9866943,56368.58203125,56373.953125,56.8540952318137,20.5949587091178,24.807261,0,0,0,40,4449,300.4621,56371.267578125,,,,,,,,,,,,,0,,,,-0.0049,,,,,,299.9866943,,,,
,27268343.995,299.9906616,51533.966796875,-0.000143257507977527,2.23725247413009E-6,1,0.999253354069792,40.0298881530762,1.99791423258153,20.9199991077185,-0.00160621740859934,-0.000364063068938956,0.25,-7.36175005012444E-6,-0.000143248545691112,-7.45552324053364E-6,299.9906616,299.9906616,51526.28125,51541.65234375,56.628204589756,20.5970079043338,25.566563,0,0,0,40,4449,300.46115,51533.966796875,,,,,,,,,,,,,0,,,,0.00245,,,,,,299.9906616,,,,
,27268442.25,300.0043945,46623.990234375,-0.000126314000526315,1.93496761782374E-6,1,0.999253354069792,40.0298881530762,1.99803434147509,20.9199991077185,-0.0014122499977326,-0.000344545939257836,0.25,-8.57020509162085E-6,-0.000126304656559975,-8.65292014505679E-6,300.0043945,300.0043945,46619.22265625,46628.7578125,56.8767624588714,20.5940939148552,24.807261,0,0,0,40,4449,300.45625,46623.990234375,,,,,,,,,,,,,0,,,,0.00245,,,,,,300.0043945,,,,
,27268540.04,299.9940186,41733.591796875,-0.000106481395479589,1.14855551359953E-6,1,0.999253354069792,40.0298881530762,1.99783332687458,20.9199991077185,-0.00119164108330066,-0.000283246755370531,0.25,-6.59033774031499E-6,-0.000106473963565058,-6.66016136556513E-6,299.9940186,299.9940186,41726.0546875,41741.12890625,56.9580518248714,20.5966162253959,25.186911,0,0,0,40,4449,300.47125,41733.591796875,,,,,,,,,,,,,0,,,,-0.00245,,,,,,299.9940186,,,,
,27268637.28,299.9961243,36875.896484375,-9.11967438790221E-5,1.83894722741036E-6,1,0.999253354069792,40.0298881530762,1.99793515298251,20.9199991077185,-0.00101862671316898,-0.000254214392574519,0.25,-6.67088473396487E-6,-9.11896862160264E-5,-6.73072044397214E-6,299.9961243,299.9961243,36873.26953125,36878.5234375,56.8681645451599,20.5955334341449,25.186911,0,0,0,40,4449,300.4724,36875.896484375,,,,,,,,,,,,,0,,,,-0.00245,,,,,,299.9961243,,,,
,27268733.835,299.9961548,32051.365234375,-7.20823688053979E-5,1.64217870965974E-6,1,0.999253354069792,40.0298881530762,1.99803217430977,20.9199991077185,-0.000803845945261581,-0.000208554655702353,0.25,-5.94556979348641E-6,-7.20763389566822E-5,-5.99289326387997E-6,299.9961548,299.9961548,32046.392578125,32056.337890625,56.8705094307176,20.5979225163661,25.186911,0,0,0,40,4449,300.4799,32051.365234375,,,,,,,,,,,,,0,,,,0.0049,,,,,,299.9961548,,,,
,27268829.055,299.9955139,27291.3115234375,-5.57576496476007E-5,1.37532695312321E-6,1,0.999253354069792,40.0298881530762,1.99779362719546,20.9199991077185,-0.000620996211388454,-0.000165513769987777,0.25,-4.97114550550204E-6,-5.5752734854938E-5,-5.00777757178864E-6,299.9955139,299.9955139,27288.638671875,27293.984375,56.9721211382176,20.5991551712185,25.186911,0,0,0,40,4449,300.4818,27291.3115234375,,,,,,,,,,,,,0,,,,0.00245,,,,,,299.9955139,,,,
,27268927,299.9996948,22396.419921875,-4.03035731110943E-5,1.04233246434587E-6,1,0.999253354069792,40.0298881530762,1.99790512396181,20.9199991077185,-0.000448681291818817,-0.00012091644618647,0.25,-3.70563905310865E-6,-4.02999353773081E-5,-3.73214148947973E-6,299.9993896,300,22391.42578125,22401.4140625,57.146424298006,20.59874223631,25.186911,0,0,0,40,4449,300.4754,22396.419921875,,,,,,,,,,,,,0,,,,-0.0049,,,,,,299.9996948,,,,
,27269023.125,299.9901123,17591.5439453125,-2.27915334631051E-5,9.51788652255806E-7,1,0.999253354069792,40.0298881530762,1.99778613709158,20.9199991077185,-0.000251549960267177,-8.0860713190445E-5,0.25,-3.1993505390612E-6,-2.27887521027353E-5,-3.21431995801793E-6,299.9901123,299.9901123,17583.83203125,17599.255859375,57.1972301517561,20.5987099662991,25.186911,0,0,0,40,4449,300.47985,17591.5439453125,,,,,,,,,,,,,0,,,,-0.00245,,,,,,299.9901123,,,,
,27269117.83,299.9993896,12858.896484375,-7.38128660494118E-6,1.00915976939048E-6,1,0.999253354069792,40.0298881530762,1.99809372010866,20.9199991077185,-7.80059637995625E-5,-4.62376625543275E-5,0.25,-2.80798149522468E-6,-7.37921035228419E-6,-2.81278083802745E-6,299.9993896,299.9993896,12851.2939453125,12866.4990234375,57.0557553897753,20.6003833682552,25.566563,0,0,0,40,4449,300.48375,12858.896484375,,,,,,,,,,,,,0,,,,0,,,,,,299.9993896,,,,
,27269214.15,300.0022583,8045.857421875,7.3156552986717E-6,5.05386129397543E-7,1,0.999253354069792,40.0298881530762,1.99787438547986,20.9199991077185,8.67336681448742E-5,-8.60229126488928E-6,0.25,-2.02791836216078E-6,7.31677987107402E-6,-2.02301462978249E-6,300.0022583,300.0022583,8043.5048828125,8048.2099609375,57.0502839901407,20.6020519846291,25.186911,0,0,0,40,4449,300.48005,8045.857421875,,,,,,,,,,,,,0,,,,0,,,,,,300.0022583,,,,
,27269309.38,299.9997559,3285.9248046875,1.72749605183671E-5,4.74014584662096E-7,1,0.999253354069792,40.0298881530762,1.99773693718044,20.9199991077185,0.000197065525292376,2.43106000391791E-5,0.25,-8.43915185526031E-7,1.72750056522415E-5,-8.32444891231509E-7,299.9997559,299.9997559,3276.01245117188,3295.83715820313,57.0096393071407,20.603652586769,25.186911,0,0,0,40,4449,300.48015,3285.9248046875,,,,,,,,,,,,,0,,,,-0.0049,,,,,,299.9997559,,,,
,27269400.085,300.0010834,-1248.09741210938,-1.67317366865106E-5,5.35909182116183E-7,1,0.999253354069792,40.0298881530762,1.99785594493271,20.9199991077185,-0.000188477004136263,-3.74139236666918E-5,0.25,-4.08385009203324E-7,-1.67309671405977E-5,-4.19461240127689E-7,300.0004578,300.001709,-1255.56945800781,-1240.62536621094,56.8947399148137,20.6017138945005,25.186911,0,0,0,40,4449,300.47475,-1248.09741210938,,,,,,,,,,,,,0,,,,0,,,,,,300.0010834,,,,
,27269494.555,300.0043335,-5969.6279296875,-1.24787239141897E-5,4.22751270071303E-7,1,0.999253354069792,40.0298881530762,1.99749415593009,20.9199991077185,-0.000142814103310583,-1.47967640852095E-5,0.25,8.53819654576808E-7,-1.24789163302305E-5,8.45529784783383E-7,300.0043335,300.0043335,-5977.20458984375,-5962.05126953125,56.8501870892175,20.6003162348796,25.186911,0,0,0,40,4449,300.4772,-5969.6279296875,,,,,,,,,,,,,0,,,,0,,,,,,300.0043335,,,,
,27269591.33,300.0039673,-10805.3784179688,1.3349627173134E-6,5.99477893415274E-7,1,0.999253354069792,40.0298881530762,1.99745709505285,20.9199991077185,1.2489302897198E-5,1.76776830950276E-5,0.25,1.33167507188362E-6,1.3340416601368E-6,1.33251874845661E-6,300.0039673,300.0039673,-10815.296875,-10795.4599609375,57.1362631272561,20.6012199425998,25.186911,0,0,0,40,4449,300.4757,-10805.3784179688,,,,,,,,,,,,,0,,,,0,,,,,,300.0039673,,,,
,27269688.39,300.011261,-15657.9677734375,1.54512251689721E-5,9.06957235715902E-7,1,0.999253354069792,40.0298881530762,1.99741248692105,20.9199991077185,0.000170122679535977,5.70121849973532E-5,0.25,2.36378384044465E-6,1.54491980800493E-5,2.37392873538992E-6,300.011261,300.011261,-15668.0185546875,-15647.9169921875,57.0057311645445,20.60263614535,25.186911,0,0,0,40,4449,300.47095,-15657.9677734375,,,,,,,,,,,,,0,,,,0.00245,,,,,,300.011261,,,,
,27269788.335,300.0127411,-20649.673828125,3.40609472651481E-5,1.0120998310088E-6,1,0.999253354069792,40.0298881530762,1.99764305928544,20.9199991077185,0.000379377233077126,0.000100790120515388,0.25,3.00924380005147E-6,3.40579361143026E-5,3.0316531730564E-6,300.0121765,300.0133057,-20659.783203125,-20639.564453125,57.1995750373137,20.6036804354586,25.566563,0,0,0,40,4449,300.4541,-20649.673828125,,,,,,,,,,,,,0,,,,-0.00245,,,,,,300.0127411,,,,
,27269886.725,300.0180664,-25569.6220703125,5.03277218635574E-5,1.34688940776323E-6,1,0.999253354069792,40.0298881530762,1.9974518787782,20.9199991077185,0.000560290974906453,0.000150166527198075,0.25,4.55737183334672E-6,5.03231954699894E-5,4.5904475671622E-6,300.0180664,300.0180664,-25577.0390625,-25562.205078125,57.0377779338329,20.603756633507,25.186911,0,0,0,40,4449,300.4433,-25569.6220703125,,,,,,,,,,,,,0,,,,-0.0049,,,,,,300.0180664,,,,
,27269985.41,300.0151672,-30501.859375,6.82523980900218E-5,1.34440073819848E-6,1,0.999253354069792,40.0298881530762,1.9976400883909,20.9199991077185,0.00076200113741348,0.000191611120985899,0.25,5.11464797161702E-6,6.8246977431159E-5,5.15949238371558E-6,300.0151672,300.0151672,-30509.21484375,-30494.50390625,56.8243933480829,20.6049014521964,25.186911,0,0,0,40,4449,300.42935,-30501.859375,,,,,,,,,,,,,0,,,,-0.00245,,,,,,300.0151672,,,,
,27270082.11,300.0207214,-35333.9453125,8.33187252358622E-5,1.52246055121149E-6,1,0.999253354069792,40.0298881530762,1.99771086032399,20.9199991077185,0.000930116121353767,0.000234630499998782,0.25,6.30688943564296E-6,8.33120584860335E-5,6.36157701512339E-6,300.0207214,300.0207214,-35336.296875,-35331.59375,57.0596635323714,20.6071426448507,25.186911,0,0,0,40,4449,300.40715,-35333.9453125,,,,,,,,,,,,,0,,,,0,,,,,,300.0207214,,,,
,27270180.195,300.0104065,-40236.326171875,0.000101225067610925,1.58665191927656E-6,1,0.999253354069792,40.0298881530762,1.99741458103874,20.9199991077185,0.00112988004051488,0.000284850902607694,0.25,7.64783658041388E-6,0.000101217027176899,7.71420807346846E-6,300.0101013,300.0107117,-40248.828125,-40223.82421875,57.0080760501022,20.6038940008411,25.186911,0,0,0,40,4449,300.40605,-40236.326171875,,,,,,,,,,,,,0,,,,0,,,,,,300.0104065,,,,
,27270278.15,300.0149536,-45131.751953125,0.000118549378161645,2.08503293871696E-6,1,0.999253354069792,40.0298881530762,1.99795962860738,20.9199991077185,0.00132562368566542,0.000322005830569865,0.25,7.92410666230346E-6,0.000118540634819504,8.00178309279115E-6,300.0149536,300.0149536,-45136.59375,-45126.91015625,57.210517836583,20.6063684620866,25.186911,0,0,0,40,4449,300.3948,-45131.751953125,,,,,,,,,,,,,0,,,,0,,,,,,300.0149536,,,,
,27270375.85,300.0187378,-50016.59765625,0.000135355529373232,1.91696830412568E-6,1,0.999253354069792,40.0298881530762,1.99758711177577,20.9199991077185,0.0015153008190401,0.000355933387010165,0.25,8.01705263710846E-6,0.000135346219769165,8.10567382234061E-6,300.0187378,300.0187378,-50019.21484375,-50013.98046875,57.1214121853907,20.6076608542437,25.186911,0,0,0,40,4449,300.3815,-50016.59765625,,,,,,,,,,,,,0,,,,0,,,,,,300.0187378,,,,
,27270475.32,300.0218811,-54985.73046875,0.000152000455453945,2.16905192082793E-6,1,0.999253354069792,40.0298881530762,1.99741982488452,20.9199991077185,0.00170223099692051,0.000395476365432916,0.25,8.63214198764865E-6,0.000151990243664684,8.73155953037546E-6,300.0218811,300.0218811,-54995.70703125,-54975.75390625,57.2425646058714,20.6042940982745,25.566563,0,0,0,40,4449,300.36575,-54985.73046875,,,,,,,,,,,,,0,,,,0,,,,,,300.0218811,,,,
,27270575.135,300.0163879,-59975.310546875,0.000171961594378153,2.06948104336647E-6,1,0.999253354069792,40.0298881530762,1.99728646937275,20.9199991077185,0.00192639931170515,0.000443062586499022,0.25,9.38384609324831E-6,0.000171950345043173,9.4962001616286E-6,300.0163879,300.0163879,-59977.88671875,-59972.734375,57.0940551872176,20.6080048335403,25.186911,0,0,0,40,4449,300.3581,-59975.310546875,,,,,,,,,,,,,0,,,,-0.0049,,,,,,300.0163879,,,,
,27270676.015,300.015564,-65017.63671875,0.000188064325837317,2.02397410077611E-6,1,0.999253354069792,40.0298881530762,1.99741703778387,20.9199991077185,0.00210556487058616,0.000492414393682442,0.25,1.09552259091991E-5,0.000188051595950731,1.10779390085669E-5,300.015564,300.015564,-65020.1875,-65015.0859375,57.0182372208522,20.6067243234086,25.186911,0,0,0,40,4449,300.3358,-65017.63671875,,,,,,,,,,,,,0,,,,0.0049,,,,,,300.015564,,,,
,27270775.675,300.0162659,-69996.94921875,0.000204020180978213,2.65040801258871E-6,1,0.999253354069792,40.0298881530762,1.99730589510124,20.9199991077185,0.00228822099317599,0.000510292161994309,0.25,9.77410469633918E-6,0.000204007768605276,9.9071319075134E-6,300.0162659,300.0162659,-70007.078125,-69986.8203125,56.9095908566791,20.608787209177,25.186911,0,0,0,40,4449,300.32385,-69996.94921875,,,,,,,,,,,,,0,,,,-0.00245,,,,,,300.0162659,,,,
,27270876.465,300.0179443,-75033.8046875,0.000221995406372136,2.72826030707446E-6,1,0.999253354069792,40.0298881530762,1.99739798222137,20.9199991077185,0.0024894632398663,0.000557997172450031,0.25,1.08760273886116E-5,0.000221981753575729,1.10205945140519E-5,300.0179443,300.0179443,-75043.7109375,-75023.8984375,57.126101956506,20.6068348694444,25.186911,0,0,0,40,4449,300.303,-75033.8046875,,,,,,,,,,,,,0,,,,0,,,,,,300.0179443,,,,
,27270977.06,300.0129395,-80060.734375,0.000240129919680868,2.92849054649308E-6,1,0.999253354069792,40.0298881530762,1.99748921108274,20.9199991077185,0.00268512581305464,0.000648723499139374,0.25,1.57536776473684E-5,0.000240112620875397,1.59097478531085E-5,300.0129395,300.0129395,-80065.6796875,-80055.7890625,57.2191157502945,20.6097232606583,25.566563,0,0,0,40,4449,300.28735,-80060.734375,,,,,,,,,,,,,0,,,,0,,,,,,300.0129395,,,,
,27271074.895,300.0159912,-84950.78125,0.000257387599788142,2.65781898520262E-6,1,0.999253354069792,40.0298881530762,1.99698817971366,20.9199991077185,0.00287894139634209,0.000686350219013722,0.25,1.61052534445587E-5,0.000257369569557935,1.6272356003779E-5,300.0159912,300.0159912,-84953.4765625,-84948.0859375,57.0713879601599,20.608402095963,25.186911,0,0,0,40,4449,300.2773,-84950.78125,,,,,,,,,,,,,0,,,,0,,,,,,300.0159912,,,,
,27271169.76,300.0144653,-89692.57421875,0.000273032203538573,2.71282772499023E-6,1,0.999253354069792,40.0298881530762,1.99726801065348,20.9199991077185,0.00305873388468709,0.000702797548284095,0.25,1.48412710236498E-5,0.000273014583150234,1.50183841524575E-5,300.0144653,300.0144653,-89695.28125,-89689.8671875,57.0299616486406,20.6134651719406,25.566563,0,0,0,40,4449,300.2671,-89692.57421875,,,,,,,,,,,,,0,,,,0,,,,,,300.0144653,,,,
,27271285.69,300.0080261,-85493.3203125,0.000261211706370126,2.98155005481182E-6,1,0.999253354069792,40.0298881530762,1.99718950755607,20.9199991077185,0.00292827054980494,0.00066040281283412,0.25,1.31424731730758E-5,0.000261195569767016,1.33121414736164E-5,300.0080261,300.0080261,-85495.703125,-85490.9375,57.1518956976407,20.6132672943026,25.946213,0,0,0,40,4449,300.263,-85493.3203125,,,,,,,,,,,,,0,,,,0,,,,,,300.0080261,,,,
,27271384.805,300.0046997,-80538.7578125,0.000242825419866168,2.50776167256636E-6,1,0.999253354069792,40.0298881530762,1.99713412325791,20.9199991077185,0.00272014422105767,0.000625087361328578,0.25,1.32063042197708E-5,0.000242809774906698,1.33642076155324E-5,300.0046997,300.0046997,-80543.9375,-80533.578125,56.912717370756,20.6124527095219,25.186911,0,0,0,40,4449,300.2594,-80538.7578125,,,,,,,,,,,,,0,,,,0,,,,,,300.0046997,,,,
,27271486.155,299.9984436,-75473.296875,0.000225504315114375,1.92362612109459E-6,1,0.999253354069792,40.0298881530762,1.99758775584326,20.9199991077185,0.00252591986024394,0.000584897481233247,0.25,1.26418287081402E-5,0.000225489563246385,1.27886493830275E-5,299.9984436,299.9984436,-75475.7265625,-75470.8671875,57.2019199228714,20.6145965209649,25.566563,0,0,0,40,4449,300.2624,-75473.296875,,,,,,,,,,,,,0,,,,-0.0049,,,,,,299.9984436,,,,
,27271588.055,299.9951782,-70381.21484375,0.000208510748635397,2.39582940072161E-6,1,0.999253354069792,40.0298881530762,1.99693546674472,20.9199991077185,0.0023376223051247,0.000524613279399928,0.25,1.02705601522227E-5,0.000208498034381331,1.04065350819321E-5,299.9951782,299.9951782,-70383.7890625,-70378.640625,56.8697278021983,20.6121829006971,25.566563,0,0,0,40,4449,300.26055,-70381.21484375,,,,,,,,,,,,,0,,,,0.00245,,,,,,299.9951782,,,,
,27271688.895,299.9906921,-65341.869140625,0.000188479669065101,2.3797928626237E-6,1,0.999253354069792,40.0298881530762,1.99700216198106,20.9199991077185,0.00210831206149447,0.000501984648276029,0.25,1.17381739115663E-5,0.000188466579803033,1.18611675829185E-5,299.9906921,299.9906921,-65346.91015625,-65336.828125,57.1276652135445,20.6097603706136,25.946213,0,0,0,40,4449,300.2701,-65341.869140625,,,,,,,,,,,,,0,,,,0.0049,,,,,,299.9906921,,,,
,27271786.63,299.9891357,-60457.126953125,0.000171960373280078,2.25795571817542E-6,1,0.999253354069792,40.0298881530762,1.99674320552878,20.9199991077185,0.00193032907638212,0.000417307599605276,0.25,7.11627498790238E-6,0.000171950774337719,7.22872715037552E-6,299.9891357,299.9891357,-60464.546875,-60449.70703125,57.0698247031214,20.6084653704015,25.566563,0,0,0,40,4449,300.27155,-60457.126953125,,,,,,,,,,,,,0,,,,0,,,,,,299.9891357,,,,
,27271886.095,299.9857788,-55487.58203125,0.000155800154516348,2.12339852616351E-6,1,0.999253354069792,40.0298881530762,1.99712582973194,20.9199991077185,0.0017466241403504,0.000393278889051021,0.25,7.78436652638225E-6,0.000155790584505216,7.88632881807925E-6,299.9857788,299.9857788,-55497.6015625,-55477.5625,57.0065127930637,20.609352359313,25.566563,0,0,0,40,4449,300.29065,-55487.58203125,,,,,,,,,,,,,0,,,,0.00245,,,,,,299.9857788,,,,
,27271984.735,299.9905396,-50555.734375,0.000139512396434421,1.91857993742784E-6,1,0.999253354069792,40.0298881530762,1.99683284995296,20.9199991077185,0.00156041842474979,0.000371679619908686,0.25,8.70077063029545E-6,0.000139502652276226,8.79212722039005E-6,299.9905396,299.9905396,-50560.6484375,-50550.8203125,57.1823792098907,20.6124772336672,25.186911,0,0,0,40,4449,300.2982,-50555.734375,,,,,,,,,,,,,0,,,,0.00245,,,,,,299.9905396,,,,
,27272084.525,299.9957275,-45571.23828125,0.000121245740226944,2.07587057317341E-6,1,0.999253354069792,40.0298881530762,1.99725166320804,20.9199991077185,0.00135588304845707,0.000325950931151082,0.25,7.81537999130172E-6,0.000121237068439186,7.89485805559755E-6,299.9957275,299.9957275,-45578.91015625,-45563.56640625,57.0354330482753,20.6096828149419,25.566563,0,0,0,40,4449,300.3013,-45571.23828125,,,,,,,,,,,,,0,,,,0,,,,,,299.9957275,,,,
,27272184.14,299.9924927,-40591.34375,0.000102807847425281,1.99255074212594E-6,1,0.999253354069792,40.0298881530762,1.99700475296265,20.9199991077185,0.00115034440883249,0.000271809910862897,0.25,6.2252470078008E-6,0.000102800759169852,6.29272537341198E-6,299.9924927,299.9924927,-40596.0234375,-40586.6640625,57.1933220091599,20.6113182929515,25.566563,0,0,0,40,4449,300.3125,-40591.34375,,,,,,,,,,,,,0,,,,0,,,,,,299.9924927,,,,
,27272284,299.9912415,-35598.654296875,8.56616440874163E-5,1.732896883998E-6,1,0.999253354069792,40.0298881530762,1.99698810637291,20.9199991077185,0.000956228913689502,0.000239487705403547,0.25,6.33763774949837E-6,8.56549744091595E-5,6.3938909081987E-6,299.9912415,299.9912415,-35603.6953125,-35593.61328125,57.271484861083,20.6082896108884,25.566563,0,0,0,40,4449,300.31665,-35598.654296875,,,,,,,,,,,,,0,,,,0,,,,,,299.9912415,,,,
,27272384.5,299.994751,-30579.5595703125,6.88259089823086E-5,1.43950845534422E-6,1,0.999253354069792,40.0298881530762,1.99694731054517,20.9199991077185,0.000768894795544714,0.000188860150558951,0.25,4.77757638079199E-6,6.88207408045663E-5,4.82283134011801E-6,299.994751,299.994751,-30586.90625,-30572.212890625,57.1268835850253,20.6102590407357,25.566563,0,0,0,40,4449,300.31885,-30579.5595703125,,,,,,,,,,,,,0,,,,0.0049,,,,,,299.994751,,,,
,27272481.735,299.9926453,-25717.1015625,5.10582542462378E-5,1.51085208381456E-6,1,0.999253354069792,40.0298881530762,1.99706095035255,20.9199991077185,0.000570029003100697,0.00014244352371954,0.25,3.75029827138266E-6,5.10542823239994E-5,3.78390052024445E-6,299.9926453,299.9926453,-25724.19921875,-25710.00390625,57.0666981890445,20.6101839026754,25.186911,0,0,0,40,4449,300.3092,-25717.1015625,,,,,,,,,,,,,0,,,,0.00245,,,,,,299.9926453,,,,
,27272580.87,299.9961548,-20765.1845703125,3.43963922508891E-5,1.17228770036277E-6,1,0.999253354069792,40.0298881530762,1.99674318887382,20.9199991077185,0.00038279517296376,0.000102626755313634,0.25,3.11738296854582E-6,3.43933180507494E-5,3.14002371006989E-6,299.9961548,299.9961548,-20772.537109375,-20757.83203125,57.2269320354868,20.6094650665248,25.946213,0,0,0,40,4449,300.32225,-20765.1845703125,,,,,,,,,,,,,0,,,,-0.00245,,,,,,299.9961548,,,,
,27272677.515,299.9980469,-15935.2958984375,1.79583245109027E-5,8.86251330624129E-7,1,0.999253354069792,40.0298881530762,1.99685589504329,20.9199991077185,0.000198283079091032,6.27304316030922E-5,0.25,2.43646469725803E-6,1.79561811337057E-5,2.44827247134125E-6,299.9980469,299.9980469,-15940.2919921875,-15930.2998046875,57.0518472471791,20.6096394003083,25.946213,0,0,0,40,4449,300.3216,-15935.2958984375,,,,,,,,,,,,,0,,,,-0.00245,,,,,,299.9980469,,,,
,27272773.525,299.9960632,-11135.1826171875,3.01666649548722E-6,7.33855989379156E-7,1,0.999253354069792,40.0298881530762,1.99678548149095,20.9199991077185,3.0131447403302E-5,2.88642533552081E-5,0.25,2.03018172426454E-6,3.01523309438695E-6,2.0321189771578E-6,299.9960632,299.9960632,-11143.333984375,-11127.03125,57.1104693861214,20.6093394261525,25.186911,0,0,0,40,4449,300.3285,-11135.1826171875,,,,,,,,,,,,,0,,,,0,,,,,,299.9960632,,,,
,27272867.405,299.9889832,-6442.29565429688,-1.14459605102037E-5,6.47481007801213E-7,1,0.999253354069792,40.0298881530762,1.99667626480453,20.9199991077185,-0.000130624195547424,-1.5409272546213E-5,0.25,6.20202167994281E-7,-1.14460352630587E-5,6.12599945813619E-7,299.9889832,299.9889832,-6449.9853515625,-6434.60595703125,57.105779615006,20.610063011138,25.566563,0,0,0,40,4449,300.3369,-6442.29565429688,,,,,,,,,,,,,0,,,,-0.0049,,,,,,299.9889832,,,,
,27272959.465,299.9884949,-1841.03112792969,-1.77503238260971E-5,4.38485096605024E-7,1,0.999253354069792,40.0298881530762,1.99692292404175,20.9199991077185,-0.000200748176768472,-3.45591008695202E-5,0.25,1.90991208052788E-8,-1.77498148009299E-5,7.33022085337064E-9,299.9884949,299.9884949,-1851.1708984375,-1830.89135742187,57.0049495360253,20.6096908442736,25.186911,0,0,0,40,4449,300.3515,-1841.03112792969,,,,,,,,,,,,,0,,,,0,,,,,,299.9884949,,,,
,27273046.13,299.9937744,2487.21801757813,1.77997304971388E-5,4.59686462258703E-7,1,0.999253354069792,40.0298881530762,1.99685902395318,20.9199991077185,0.000203350945616432,2.28211895408689E-5,0.25,-1.06566561064772E-6,1.77999105468301E-5,-1.05383421606596E-6,299.9937744,299.9937744,2482.23364257813,2492.20239257813,57.1206305568714,20.6080123529412,25.566563,0,0,0,40,4449,300.3567,2487.21801757813,,,,,,,,,,,,,0,,,,0.00245,,,,,,299.9937744,,,,
,27273137.975,299.9988708,7079.40112304687,1.0112975757905E-5,5.22208487401869E-7,1,0.999253354069792,40.0298881530762,1.99689028423506,20.9199991077185,0.000117139890488822,3.71020843438329E-6,0.25,-1.42403852989913E-6,1.01136186290394E-5,-1.41729656356662E-6,299.9988708,299.9988708,7071.84375,7086.95849609375,57.058100275333,20.6082305194993,25.566563,0,0,0,40,4449,300.3538,7079.40112304687,,,,,,,,,,,,,0,,,,-0.00245,,,,,,299.9988708,,,,
,27273232.09,300.0056458,11782.4990234375,-3.61425489032126E-6,6.48929465766884E-7,1,0.999253354069792,40.0298881530762,1.99694049518706,20.9199991077185,-3.59054692568195E-5,-3.57248969779734E-5,0.25,-2.53318855345921E-6,-3.61246983067577E-6,-2.53550535825148E-6,300.0056458,300.0056458,11779.9306640625,11785.0673828125,57.075296102756,20.6058617199873,25.946213,0,0,0,40,4449,300.33935,11782.4990234375,,,,,,,,,,,,,0,,,,0.00245,,,,,,300.0056458,,,,
,27273325.61,300.0027466,16457.69140625,-2.00997922112852E-5,1.26388562593893E-6,1,0.999253354069792,40.0298881530762,1.99679632002384,20.9199991077185,-0.000220862670955171,-7.63189129536171E-5,0.25,-3.26740113362643E-6,-2.00970329537686E-5,-3.28059809339471E-6,300.0027466,300.0027466,16452.591796875,16462.791015625,57.0698247031214,20.6025952742499,25.946213,0,0,0,40,4449,300.34095,16457.69140625,,,,,,,,,,,,,0,,,,0,,,,,,300.0027466,,,,
,27273420.4,300.0075073,21194.998046875,-3.54535037260341E-5,7.88085906211166E-7,1,0.999253354069792,40.0298881530762,1.9970339449569,20.9199991077185,-0.000395083576912822,-0.000103087366908384,0.25,-2.9737102347372E-6,-3.5450479614353E-5,-2.99704833176354E-6,300.0075073,300.0075073,21179.955078125,21210.041015625,56.9510171681983,20.6050527835671,25.186911,0,0,0,40,4449,300.34745,21194.998046875,,,,,,,,,,,,,0,,,,-0.0049,,,,,,300.0075073,,,,
,27273516.43,300.0150757,25995.177734375,-5.20358666067361E-5,1.14609199410956E-6,1,0.999253354069792,40.0298881530762,1.99743255423591,20.9199991077185,-0.000581075184189788,-0.000145028435056687,0.25,-3.80724492536438E-6,-5.20317871983883E-5,-3.84148375961316E-6,300.0150757,300.0150757,25982.5703125,26007.78515625,57.0018230219483,20.6017768041002,25.186911,0,0,0,40,4449,300.3253,25995.177734375,,,,,,,,,,,,,0,,,,0.00245,,,,,,300.0150757,,,,
,27273611.435,300.0164185,30742.9111328125,-6.79122065738123E-5,1.19606614317543E-6,1,0.999253354069792,40.0298881530762,1.99704970135308,20.9199991077185,-0.000757194037749568,-0.000195191547149931,0.25,-5.4949761786156E-6,-6.79065394437885E-5,-5.53960143488841E-6,300.0164185,300.0164185,30735.322265625,30750.5,56.6625962446021,20.6044863766211,25.566563,0,0,0,40,4449,300.31975,30742.9111328125,,,,,,,,,,,,,0,,,,0,,,,,,300.0164185,,,,
,27273706.56,300.0097351,35498.3125,-8.57243202937673E-5,1.66255112496433E-6,1,0.999253354069792,40.0298881530762,1.9970742138463,20.9199991077185,-0.000959331429755002,-0.000226027278137707,0.25,-5.13560083860143E-6,-8.57183833894635E-5,-5.19192956538971E-6,300.0097351,300.0097351,35493.18359375,35503.44140625,57.0831123879483,20.6044229361508,25.566563,0,0,0,40,4449,300.30995,35498.3125,,,,,,,,,,,,,0,,,,0,,,,,,300.0097351,,,,
,27273807.86,300.0145874,40560.876953125,-0.000102842763614294,1.89871334305129E-6,1,0.999253354069792,40.0298881530762,1.99710470064027,20.9199991077185,-0.00114688369166112,-0.000294456657896982,0.25,-8.22070606614813E-6,-0.000102834278477628,-8.28814863906188E-6,300.0145874,300.0145874,40550.89453125,40570.859375,56.976810909333,20.6042128479561,25.186911,0,0,0,40,4449,300.29195,40560.876953125,,,,,,,,,,,,,0,,,,0,,,,,,300.0145874,,,,
,27273905.88,300.0101624,45461.197265625,-0.000119495579420845,1.85857769728528E-6,1,0.999253354069792,40.0298881530762,1.99731033654453,20.9199991077185,-0.00133411009978793,-0.000334170923017273,0.25,-8.84462287052884E-6,-0.00011948621920711,-8.92292102641533E-6,300.0101624,300.0101624,45458.72265625,45463.671875,57.1135959001984,20.6031988711729,25.566563,0,0,0,40,4449,300.2906,45461.197265625,,,,,,,,,,,,,0,,,,0.0049,,,,,,300.0101624,,,,
,27274004.555,300.0130615,50391.212890625,-0.00013584494950096,1.8077668953586E-6,1,0.999253354069792,40.0298881530762,1.99712262804081,20.9199991077185,-0.00152000701559054,-0.000359655546968841,0.25,-8.26835802257841E-6,-0.000135835483993319,-8.35732113685734E-6,300.0130615,300.0130615,50381.296875,50401.12890625,56.9611783389483,20.6022182076383,25.566563,0,0,0,40,4449,300.28235,50391.212890625,,,,,,,,,,,,,0,,,,-0.00245,,,,,,300.0130615,,,,
,27274103.795,300.0149841,55351.126953125,-0.000156085522398652,2.07077390086762E-6,1,0.999253354069792,40.0298881530762,1.99718054015619,20.9199991077185,-0.00174711320188599,-0.000409905009592159,0.25,-9.20423010938102E-6,-0.000156074847623267,-9.30633978953547E-6,300.0149841,300.0149841,55348.65625,55353.59765625,56.8642564025637,20.6015644270492,25.186911,0,0,0,40,4449,300.2722,55351.126953125,,,,,,,,,,,,,0,,,,-0.00245,,,,,,300.0149841,,,,
,27274203.985,300.0105591,60358.685546875,-0.000173758302801037,2.69747033861839E-6,1,0.999253354069792,40.0298881530762,1.99722640682537,20.9199991077185,-0.00194920867651375,-0.00043187977375343,0.25,-8.08481586062741E-6,-0.000173747883068087,-8.1984186680238E-6,300.0105591,300.0105591,60356.1953125,60361.17578125,57.0635716749676,20.6012451735651,25.566563,0,0,0,40,4449,300.26215,60358.685546875,,,,,,,,,,,,,0,,,,0,,,,,,300.0105591,,,,
,27274303.88,300.0157776,65354.267578125,-0.000189901040691534,2.70288496229001E-6,1,0.999253354069792,40.0298881530762,1.99722711909076,20.9199991077185,-0.00212514317722268,-0.00050175271414626,0.25,-1.14666647848536E-5,-0.000189887914911508,-1.15906010178636E-5,300.0157776,300.0157776,65349.4453125,65359.08984375,56.9564885678329,20.6012703739296,25.946213,0,0,0,40,4449,300.23775,65354.267578125,,,,,,,,,,,,,0,,,,-0.0049,,,,,,300.0157776,,,,
,27274402.61,300.0166931,70288.88671875,-0.000205974595792923,2.37653464485157E-6,1,0.999253354069792,40.0298881530762,1.99713655571726,20.9199991077185,-0.0023034322931995,-0.000552782244957274,0.25,-1.3196435989669E-5,-0.000205959880050842,-1.33306792400551E-5,300.0166931,300.0166931,70286.328125,70291.4453125,56.8204852054868,20.6028243095466,25.566563,0,0,0,40,4449,300.2274,70288.88671875,,,,,,,,,,,,,0,,,,0,,,,,,300.0166931,,,,
,27274502.615,300.0139771,75286.84765625,-0.000223287686154737,2.28356428133701E-6,1,0.999253354069792,40.0298881530762,1.99704582451078,20.9199991077185,-0.00249893415534066,-0.000587700780599039,0.25,-1.3287156608578E-5,-0.000223272448837018,-1.34325282955532E-5,300.0139771,300.0139771,75274.1640625,75299.53125,57.3691884259868,20.6018773283046,25.946213,0,0,0,40,4449,300.23215,75286.84765625,,,,,,,,,,,,,0,,,,-0.0049,,,,,,300.0139771,,,,
,27274601.915,300.0148621,80250.578125,-0.000242746638730857,2.46961935603822E-6,1,0.999253354069792,40.0298881530762,1.99718782837584,20.9199991077185,-0.00271750218664864,-0.000635453128224775,0.25,-1.41351147166404E-5,-0.000242730295535392,-1.42929784051776E-5,300.0148621,300.0148621,80238.078125,80263.078125,56.933039712256,20.6049001072595,25.946213,0,0,0,40,4449,300.20675,80250.578125,,,,,,,,,,,,,0,,,,0.00245,,,,,,300.0148621,,,,
,27274700.43,300.0205383,85176.1484375,-0.000259774750565134,2.50111847161286E-6,1,0.999253354069792,40.0298881530762,1.99717475811689,20.9199991077185,-0.002908611493106,-0.000677131014155281,0.25,-1.4871018586971E-5,-0.000259757404975679,-1.50397535338028E-5,300.0205383,300.0205383,85166.28125,85186.015625,57.1245386994676,20.6013564173162,25.186911,0,0,0,40,4449,300.1936,85176.1484375,,,,,,,,,,,,,0,,,,0.0049,,,,,,300.0205383,,,,
,27274795.705,300.0181885,89936.7109375,-0.000278617704417237,2.89802010380781E-6,1,0.999253354069792,40.0298881530762,1.99720898766839,20.9199991077185,-0.00311823516033713,-0.000734376328730578,0.25,-1.66676677400235E-5,-0.000278598688289787,-1.68484096558778E-5,300.0181885,300.0181885,89934.203125,89939.21875,56.9588334533906,20.6025108063651,25.186911,0,0,0,40,4449,300.17525,89936.7109375,,,,,,,,,,,,,0,,,,0,,,,,,300.0181885,,,,
,27274907.665,300.0115356,85476.72265625,-0.000263586501438955,2.90454868769798E-6,1,0.999253354069792,40.0298881530762,1.99716907728291,20.9199991077185,-0.00294846110344525,-0.000703355294308323,0.25,-1.65297093990038E-5,-0.000263568047940103,-1.67008867318844E-5,300.0115356,300.0115356,85469.3046875,85484.140625,56.8939582862945,20.6025265450211,25.186911,0,0,0,40,4449,300.16785,85476.72265625,,,,,,,,,,,,,0,,,,-0.00245,,,,,,300.0115356,,,,
,27275006.845,299.998291,80518.1953125,-0.0002419828093842,2.13040342651032E-6,1,0.999253354069792,40.0298881530762,1.99718843844081,20.9199991077185,-0.00270846354503887,-0.000636283038390165,0.25,-1.43407694497936E-5,-0.000241966496559271,-1.4498151144434E-5,299.998291,299.998291,80516.015625,80520.375,56.7282530402175,20.602604547226,25.566563,0,0,0,40,4449,300.1667,80518.1953125,,,,,,,,,,,,,0,,,,-0.0049,,,,,,299.998291,,,,
,27275107.225,299.9950867,75499.2421875,-0.000225531431530658,1.94466692307257E-6,1,0.999253354069792,40.0298881530762,1.99747109456859,20.9199991077185,-0.00252715815479232,-0.000578729541930386,0.25,-1.2094627224564E-5,-0.000225517056224487,-1.22415318444958E-5,299.9950867,299.9950867,75492.046875,75506.4375,57.2027015513907,20.5996059681471,25.566563,0,0,0,40,4449,300.17435,75499.2421875,,,,,,,,,,,,,0,,,,0,,,,,,299.9950867,,,,
,27275207.48,299.9916077,70488.1328125,-0.000207494901673097,1.72447424349712E-6,1,0.999253354069792,40.0298881530762,1.99727005037234,20.9199991077185,-0.00232196488080905,-0.000548928518732206,0.25,-1.25891087774303E-5,-0.000207480722436407,-1.27243917427271E-5,299.9916077,299.9916077,70478.0703125,70498.1953125,57.065134932006,20.602758343169,25.186911,0,0,0,40,4449,300.1828,70488.1328125,,,,,,,,,,,,,0,,,,-0.00245,,,,,,299.9916077,,,,
,27275303.755,299.9934692,65678.16796875,-0.000192978129538674,1.88614566812107E-6,1,0.999253354069792,40.0298881530762,1.99737565565087,20.9199991077185,-0.00216015503012539,-0.000507484938706039,0.25,-1.14371917084124E-5,-0.000192965084675573,-1.15631646770319E-5,299.9934692,299.9934692,65670.546875,65685.7890625,56.9002113144483,20.60395576858,25.186911,0,0,0,40,4449,300.1906,65678.16796875,,,,,,,,,,,,,0,,,,-0.00245,,,,,,299.9934692,,,,
,27275402.97,299.986969,60720.056640625,-0.000175440098435461,2.46550458528824E-6,1,0.999253354069792,40.0298881530762,1.99736315382339,20.9199991077185,-0.00196109001089721,-0.000477157253031951,0.25,-1.17942674680613E-5,-0.000175427344918439,-1.19088890468841E-5,299.986969,299.986969,60712.87109375,60727.2421875,56.7931282073137,20.6032156348129,25.566563,0,0,0,40,4449,300.20295,60720.056640625,,,,,,,,,,,,,0,,,,-0.00245,,,,,,299.986969,,,,
,27275500.99,299.9868164,55817.068359375,-0.000155097649182008,1.69834074819528E-6,1,0.999253354069792,40.0298881530762,1.99733488626635,20.9199991077185,-0.001736574940514,-0.000405092824579205,0.25,-8.94716516864501E-6,-0.000155087327163084,-9.04865816981444E-6,299.9868164,299.9868164,55809.58984375,55824.546875,56.9744660237753,20.6041780792845,25.566563,0,0,0,40,4449,300.2065,55817.068359375,,,,,,,,,,,,,0,,,,0,,,,,,299.9868164,,,,
,27275599.805,299.9912262,50879.6484375,-0.000137273453221317,1.78454584920698E-6,1,0.999253354069792,40.0298881530762,1.99739401829713,20.9199991077185,-0.00153658503821348,-0.00036121250929215,0.25,-8.15436135676368E-6,-0.000137264125166357,-8.24429007800699E-6,299.9910889,299.9913635,50872.296875,50887,56.8150138058522,20.6032773415199,25.186911,0,0,0,40,4449,300.20215,50879.6484375,,,,,,,,,,,,,0,,,,0,,,,,,299.9912262,,,,
,27275698.9,299.9863281,45927.119140625,-0.000121834362877725,1.47866984791169E-6,1,0.999253354069792,40.0298881530762,1.99739707434556,20.9199991077185,-0.00136630977473049,-0.000305916891676557,0.25,-5.94001607437673E-6,-0.000121826945400049,-6.01995593239433E-6,299.9863281,299.9863281,45919.640625,45934.59765625,57.095618444256,20.6044919600464,25.946213,0,0,0,40,4449,300.22185,45927.119140625,,,,,,,,,,,,,0,,,,-0.0049,,,,,,299.9863281,,,,
,27275795.295,299.9928894,41109.431640625,-0.000103406505065056,1.18091191651886E-6,1,0.999253354069792,40.0298881530762,1.9972859712784,20.9199991077185,-0.0011535968207818,-0.00029421726054419,0.25,-8.09958351900082E-6,-0.000103398161996344,-8.16741536595696E-6,299.9928894,299.9928894,41101.609375,41117.25390625,56.9471090256022,20.6058875245769,25.946213,0,0,0,40,4449,300.2288,41109.431640625,,,,,,,,,,,,,0,,,,0,,,,,,299.9928894,,,,
,27275891.665,299.9919739,36292.033203125,-8.80040118680912E-5,1.92234785188926E-6,1,0.999253354069792,40.0298881530762,1.99736267772908,20.9199991077185,-0.000980968463699223,-0.000255221743182422,0.25,-7.31919347254943E-6,-8.79966233497849E-5,-7.37697048757933E-6,299.9919739,299.9919739,36279.80078125,36304.265625,56.9596150819099,20.6052976659423,25.946213,0,0,0,40,4449,300.2357,36292.033203125,,,,,,,,,,,,,0,,,,0,,,,,,299.9919739,,,,
,27275987.965,299.9949036,31479.685546875,-7.03358854235204E-5,1.16965833823398E-6,1,0.999253354069792,40.0298881530762,1.9974603072466,20.9199991077185,-0.000783249988410914,-0.000208670968532716,0.25,-6.26342817349418E-6,-7.03296913575064E-5,-6.30964235129202E-6,299.9949036,299.9949036,31476.818359375,31482.552734375,57.0205821064099,20.6056822664936,25.566563,0,0,0,40,4449,300.23115,31479.685546875,,,,,,,,,,,,,0,,,,0,,,,,,299.9949036,,,,
,27276085.69,299.9933472,26594.0595703125,-5.30001277215965E-5,1.24160092894179E-6,1,0.999253354069792,40.0298881530762,1.99741524476828,20.9199991077185,-0.000592308105524826,-0.000145004172441152,0.25,-3.63812462061268E-6,-5.29961712586228E-5,-3.67301462292962E-6,299.9933472,299.9933472,26589.2265625,26598.892578125,57.1221938139099,20.6051106658145,26.325863,0,0,0,40,4449,300.2449,26594.0595703125,,,,,,,,,,,,,0,,,,0,,,,,,299.9933472,,,,
,27276181.805,299.9845734,21791.7373046875,-3.71920846272035E-5,1.15782684811703E-6,1,0.999253354069792,40.0298881530762,1.99734275311855,20.9199991077185,-0.000412916026929798,-0.00011741243098501,0.25,-3.93774501609978E-6,-3.71884009653899E-5,-3.96221264925509E-6,299.9839783,299.9851685,21781.5625,21801.912109375,57.1784710672945,20.6082178972001,26.325863,0,0,0,40,4449,300.25155,21791.7373046875,,,,,,,,,,,,,0,,,,0,,,,,,299.9845734,,,,
,27276276.63,299.9901123,17052.140625,-2.13435664862263E-5,7.94663485434482E-7,1,0.999253354069792,40.0298881530762,1.99741149824922,20.9199991077185,-0.000236911806036336,-6.77147549224688E-5,0.25,-2.28916637967008E-6,-2.13414263063737E-5,-2.30321919510683E-6,299.9901123,299.9901123,17039.65625,17064.625,57.004167907506,20.6089248995941,25.566563,0,0,0,40,4449,300.2565,17052.140625,,,,,,,,,,,,,0,,,,-0.00245,,,,,,299.9901123,,,,
,27276370.065,299.9909668,12382.3681640625,-5.91901278384476E-6,8.15452204136295E-7,1,0.999253354069792,40.0298881530762,1.9977482122095,20.9199991077185,-6.40491728554899E-5,-2.83739430600739E-5,0.25,-1.48280571669069E-6,-5.9178569699561E-6,-1.4866812078168E-6,299.9909668,299.9909668,12372.2080078125,12392.5283203125,57.1894138665637,20.6032205483964,25.566563,0,0,0,40,4449,300.26155,12382.3681640625,,,,,,,,,,,,,0,,,,-0.0049,,,,,,299.9909668,,,,
,27276465.985,299.9883118,7589.03735351562,8.28163115438857E-6,4.36727012331928E-7,1,0.999253354069792,40.0298881530762,1.99751394953946,20.9199991077185,9.71164249878156E-5,-3.6594095519912E-6,0.25,-1.75840591408014E-6,8.28255325607498E-6,-1.7528666137533E-6,299.9883118,299.9883118,7584.525390625,7593.54931640625,57.393418910083,20.6077924109173,25.946213,0,0,0,40,4449,300.27415,7589.03735351562,,,,,,,,,,,,,0,,,,0,,,,,,299.9883118,,,,
,27276560.015,299.9957886,2886.16979980469,1.75911257403783E-5,4.53186556543848E-7,1,0.999253354069792,40.0298881530762,1.99751610754375,20.9199991077185,0.000199586655702383,3.08963219022925E-5,0.25,-3.16219103582145E-7,1.75908135923448E-5,-3.04544422938974E-7,299.9957886,299.9957886,2876.19067382813,2896.14892578125,57.126101956506,20.6071992530095,25.946213,0,0,0,40,4449,300.2626,2886.16979980469,,,,,,,,,,,,,0,,,,0.00245,,,,,,299.9957886,,,,
,27281181.36,10.0115948,-0.213132828474045,,,2,,,,25.4899992191792,,,,,,,10.0115948,10.0115948,-0.213132828474045,-0.213132828474045,,,13.417728,,,,-99999999,4369,10.0114,-0.213132828474045,,,,,,,,,,,,,,,,,,,,,,,10.0115948,,,,