File: data/monolayers/nanoparticles/Ac_CoFe_C/vsm/data_disorderedWafer/DD226_2_HYST_150K.DAT
[Header]
; VSM Data File (default extension .dat)
; Copyright (c) 2003-2013, Quantum Design, Inc. All rights reserved.
TITLE,
FILEOPENTIME,27327205.42,11/13/2018,2:53 pm
BYAPP,VSM,2.0,2.0
INFO,PPMS VSM Option Release 1.4.10 Build 1,APPNAME
INFO,Quantum Design Linear Motor Servo Controller,MOTOR_MODULE_NAME
INFO,3101-100 M1,MOTOR_HW_VERSION
INFO,MMC1014,MOTOR_SERIAL_NUMBER
INFO,SRV No X-over 01.03.11,MOTOR_SOFTWARE_VERSION
INFO,Quantum Design VSM Detection Module,VSM_MODULE_NAME
INFO,3101-150 F0,VSM_HW_VERSION
INFO,VSM707,VSM_SERIAL_NUMBER
INFO,VSM No X-over 01.02.05 May 20 2008 13:51:47,VSM_SOFTWARE_VERSION
INFO,704,PREAMP_SERIAL_NUMBER
INFO,822,COIL_SERIAL_NUMBER
INFO,0,MOMENT_UNITS
INFO,CoFe2O4 AH11,SAMPLE_MATERIAL
INFO,Quick Dry Monolayer Conc,SAMPLE_COMMENT
INFO,27.96,SAMPLE_MASS
INFO,,SAMPLE_VOLUME
INFO,,SAMPLE_MOLECULAR_WEIGHT
INFO,,SAMPLE_SIZE
INFO,,SAMPLE_SHAPE
DATATYPE,COMMENT,1
DATATYPE,TIME,2
STARTUPAXIS,X,2
STARTUPAXIS,Y1,5
[Data]
Comment,Time Stamp (sec),Temperature (K),Magnetic Field (Oe),Moment (emu),M. Std. Err. (emu),Transport Action,Averaging Time (sec),Frequency (Hz),Peak Amplitude (mm),Center Position (mm),Coil Signal' (mV),Coil Signal" (mV),Range (mV),M. Quad. Signal (emu),M. Raw' (emu),M. Raw" (emu),Min. Temperature (K),Max. Temperature (K),Min. Field (Oe),Max. Field (Oe),Mass (grams),Motor Lag (deg),Pressure (Torr),VSM Status (code),Motor Status (code),Measure Status (code),Measure Count,PPMS Status (code),System Temp. (K),System Field (Oe),Sample Position (deg),Bridge 1 Resistance (ohms),Bridge 1 Excitation (에),Bridge 2 Resistance (ohms),Bridge 2 Excitation (에),Bridge 3 Resistance (ohms),Bridge 3 Excitation (에),Bridge 4 Resistance (ohms),Bridge 4 Excitation (에),Signal 1 Vin (V),Signal 2 Vin (V),Digital Inputs (code),Drive 1 Iout (mA),Drive 1 Ipower (W),Drive 2 Iout (mA),Drive 2 Ipower (W),Pressure (),Map 20 (),Map 21 (),Map 22 (),Map 23 (),Map 24 (),Map 25 (),Map 26 (),Map 27 (),Map 28 (),Map 29 ()
,27327221.88,150.2576294,-0.411041855812073,,,2,,,,21.3800000542402,,,,,,,150.2576294,150.2576294,-0.411041855812073,-0.411041855812073,,,22.909004,,,,-99999999,4369,149.982,-0.411041855812073,,,,,,,,,,,,,,,,,,,,,,,150.2576294,,,,
,27327375.485,150.1170959,4700.59643554687,1.45565506055229E-5,5.3166812109957E-7,1,0.999253354069792,40.0298881530762,1.98490188304555,21.3699992746115,0.00016554041155208,2.2276512762406E-5,0.25,-5.6399315137854E-7,1.46287020169162E-5,-5.43392999735275E-7,150.1170959,150.1170959,4695.62255859375,4705.5703125,56.0669953129482,20.5728236576885,23.288654,0,0,0,40,4449,149.8042,4700.59643554687,,,,,,,,,,,,,0,,,,0,,,,,,150.1170959,,,,
,27327473.735,150.0453949,9609.298828125,2.51870154180444E-6,7.0904583903426E-7,1,0.999253354069792,40.0298881530762,1.98509723629694,21.3699992746115,2.88953079546033E-5,2.42392893778903E-6,0.25,-2.24241602518149E-7,2.53139525105322E-6,-2.21306020682E-7,150.0453949,150.0453949,9596.9482421875,9621.6494140625,56.2366087016213,20.5810199198656,23.288654,0,0,0,40,4449,149.78425,9609.298828125,,,,,,,,,,,,,0,,,,-0.00245,,,,,,150.0453949,,,,
,27327574.695,150.0041656,14656.5107421875,-1.17714646337777E-5,1.58752617299157E-6,1,0.999253354069792,40.0298881530762,1.98488658115711,21.3699992746115,-0.00013250385325476,-2.58411775250094E-5,0.25,-2.36893662203894E-7,-1.18287583480791E-5,-2.56855629704704E-7,150.0041656,150.0041656,14649.259765625,14663.76171875,56.3155531820637,20.595294020831,23.668306,0,0,0,40,4449,149.79695,14656.5107421875,,,,,,,,,,,,,0,,,,0,,,,,,150.0041656,,,,
,27327673.335,149.9860382,19586.58984375,-2.91036420295533E-5,1.76053926872619E-6,1,0.999253354069792,40.0298881530762,1.98473346517026,21.3699992746115,-0.000328202760066084,-6.02956089708854E-5,0.25,-2.680599586425E-7,-2.92458474183462E-5,-3.157232668809E-7,149.9860382,149.9860382,19576.798828125,19596.380859375,56.8767624588714,20.5954863559269,23.668306,0,0,0,40,4449,149.8187,19586.58984375,,,,,,,,,,,,,0,,,,0.00245,,,,,,149.9860382,,,,
,27327773.76,149.9830627,24603.943359375,-4.53433346464111E-5,1.94947065984082E-6,1,0.999253354069792,40.0298881530762,1.98460301945977,21.3699992746115,-0.000510261246711324,-9.99365243976541E-5,0.25,-9.49269950267328E-7,-4.5564100081691E-5,-1.02591503896903E-6,149.9830627,149.9830627,24594.033203125,24613.853515625,56.587559906756,20.601802556394,23.288654,0,0,0,40,4449,149.838,24603.943359375,,,,,,,,,,,,,0,,,,-0.00245,,,,,,149.9830627,,,,
,27327872.49,149.9860077,29539.251953125,-6.31219233176025E-5,2.48100408556236E-6,1,0.999253354069792,40.0298881530762,1.98450683279136,21.3699992746115,-0.000711784664161133,-0.000130571620553421,0.25,-5.65391724434917E-7,-6.34305132866789E-5,-6.68075804204521E-7,149.9860077,149.9860077,29531.94921875,29546.5546875,57.2050464369484,20.6082056995065,22.909004,0,0,0,40,4449,149.85165,29539.251953125,,,,,,,,,,,,,0,,,,-0.0049,,,,,,149.9860077,,,,
,27327969.055,149.9889374,34366.58203125,-8.06317946511629E-5,2.35964987004689E-6,1,0.999253354069792,40.0298881530762,1.98426471837374,21.3699992746115,-0.000911966457924584,-0.000150471959453352,0.25,7.20855368764369E-7,-8.10283451740885E-5,5.97150448704076E-7,149.9889374,149.9889374,34359.53125,34373.6328125,57.3379232852176,20.6059950349685,23.288654,0,0,0,40,4449,149.86,34366.58203125,,,,,,,,,,,,,0,,,,0.0049,,,,,,149.9889374,,,,
,27328064.475,149.9914856,39136.419921875,-9.81179994540769E-5,3.06572872862507E-6,1,0.999253354069792,40.0298881530762,1.98406743361891,21.3699992746115,-0.00110385763347817,-0.000216257314417863,0.25,-2.06090705340511E-6,-9.85960168986674E-5,-2.22537698485447E-6,149.9914856,149.9914856,39131.25390625,39141.5859375,56.4109118614098,20.6087623971971,23.668306,0,0,0,40,4449,149.866,39136.419921875,,,,,,,,,,,,,0,,,,0,,,,,,149.9914856,,,,
,27328161.515,149.9954987,43984.193359375,-0.000117142754103114,3.06696813097219E-6,1,0.999253354069792,40.0298881530762,1.98396678501645,21.3699992746115,-0.00132218711531292,-0.00023315926327111,0.25,-2.4541039362119E-7,-0.000117717055216186,-4.30328905815493E-7,149.9954987,149.9954987,43979.40234375,43988.984375,56.8392442899483,20.6110287713888,23.668306,0,0,0,40,4449,149.86825,43984.193359375,,,,,,,,,,,,,0,,,,0,,,,,,149.9954987,,,,
,27328259.395,150.0000153,48877.193359375,-0.00013340228315829,2.54829699767377E-6,1,0.999253354069792,40.0298881530762,1.98378116335644,21.3699992746115,-0.00149984278007585,-0.000298407478391695,0.25,-3.19498624167052E-6,-0.000134051868017291,-3.41921198660928E-6,150.0000153,150.0000153,48867.26953125,48887.1171875,56.8462789466214,20.6137237721125,22.909004,0,0,0,40,4449,149.8665,48877.193359375,,,,,,,,,,,,,0,,,,0,,,,,,150.0000153,,,,
,27328354,150.0009613,53604.9453125,-0.00015035629490434,2.65877067213771E-6,1,0.999253354069792,40.0298881530762,1.98378406679908,21.3699992746115,-0.00169468138321929,-0.000312102737699094,0.25,-1.45565404674374E-6,-0.000151091951933823,-1.69710782838354E-6,150.0009613,150.0009613,53595.03515625,53614.85546875,56.7634263235829,20.6111007293959,23.288654,0,0,0,40,4449,149.86855,53604.9453125,,,,,,,,,,,,,0,,,,0.0049,,,,,,150.0009613,,,,
,27328450.72,150.0011139,58437.537109375,-0.000169494079365896,3.34334054571032E-6,1,0.999253354069792,40.0298881530762,1.98385103066895,21.3799998164177,-0.00190802445888454,-0.00036576069237917,0.25,-2.87474850075347E-6,-0.00017032164564463,-3.15214529674821E-6,150.0011139,150.0011139,58427.5546875,58447.51953125,56.7860935506406,20.6129371767208,23.288654,0,0,0,40,4449,149.86345,58437.537109375,,,,,,,,,,,,,0,,,,-0.00245,,,,,,150.0011139,,,,
,27328548.025,150.0038605,63303.23828125,-0.000185255119192907,3.05733692054555E-6,1,0.999253354069792,40.0298881530762,1.98359413332271,21.3699992746115,-0.00208201540180459,-0.000417971186523261,0.25,-4.75941688147814E-6,-0.000186157338967103,-5.0696087616234E-6,150.0038605,150.0038605,63290.4921875,63315.984375,56.7235632691022,20.6143744338352,22.909004,0,0,0,40,4449,149.8585,63303.23828125,,,,,,,,,,,,,0,,,,-0.00245,,,,,,150.0038605,,,,
,27328645.405,150.0051575,68170.73046875,-0.000207391290431352,3.24812326113392E-6,1,0.999253354069792,40.0298881530762,1.98369328922644,21.3799998164177,-0.00233400651639826,-0.00045015701298572,0.25,-3.75425309554222E-6,-0.000208403992561404,-4.09271758563246E-6,150.0051575,150.0051575,68168.140625,68173.3203125,57.0057311645445,20.6184768033416,22.909004,0,0,0,40,4449,149.8542,68170.73046875,,,,,,,,,,,,,0,,,,-0.00245,,,,,,150.0051575,,,,
,27328742.085,150.0068665,73003.5625,-0.000221171161763978,3.77571730183714E-6,1,0.999253354069792,40.0298881530762,1.98355651319832,21.3699992746115,-0.00249318598703042,-0.000455573092304308,0.25,-1.83785012518423E-6,-0.000222254732788114,-2.18703629839627E-6,150.0068665,150.0068665,72996.0703125,73011.0546875,56.4124751184483,20.6186443315538,23.668306,0,0,0,40,4449,149.84745,73003.5625,,,,,,,,,,,,,0,,,,-0.00245,,,,,,150.0068665,,,,
,27328836.68,150.0069122,77731.76953125,-0.00023817964199875,3.68889570039178E-6,1,0.999253354069792,40.0298881530762,1.98344934319228,21.3699992746115,-0.00268804924346576,-0.000471815804706188,0.25,-3.17871725456411E-7,-0.000239349348453046,-6.84565900635189E-7,150.0069122,150.0069122,77724.1484375,77739.390625,56.2108149604867,20.6109330850028,22.909004,0,0,0,40,4449,149.83595,77731.76953125,,,,,,,,,,,,,0,,,,0,,,,,,150.0069122,,,,
,27328933.25,150.0079651,82559.80859375,-0.000257600212051715,3.9007436681715E-6,1,0.999253354069792,40.0298881530762,1.9837034633787,21.3699992746115,-0.00289832705852836,-0.000563512083889284,0.25,-5.05402182113286E-6,-0.000258858374776454,-5.47241659108434E-6,150.0079651,150.0079651,82557.2890625,82562.328125,56.9713395096983,20.6112976108421,23.668306,0,0,0,40,4449,149.8322,82559.80859375,,,,,,,,,,,,,0,,,,-0.00245,,,,,,150.0079651,,,,
,27329026.195,150.008461,87205.60546875,-0.000274391455115587,3.24107492926249E-6,1,0.999253354069792,40.0298881530762,1.9836419450311,21.3699992746115,-0.00309088878002639,-0.000578823516394222,0.25,-3.48899035465735E-6,-0.000275734824633042,-3.92398095098972E-6,150.0081787,150.0087433,87200.625,87210.5859375,57.0401228193907,20.6103877317186,23.288654,0,0,0,40,4449,149.82445,87205.60546875,,,,,,,,,,,,,0,,,,0,,,,,,150.008461,,,,
,27329135.19,150.0058594,88325.26953125,-0.000277261882820537,3.11023698133661E-6,1,0.999253354069792,40.0298881530762,1.98345459310047,21.3799998164177,-0.00312114992000205,-0.000595117303614425,0.25,-4.43746454945795E-6,-0.00027861800894581,-4.88117025767382E-6,150.0058594,150.0058594,88322.7109375,88327.828125,56.5523866233906,20.6108374190035,23.288654,0,0,0,40,4449,149.8186,88325.26953125,,,,,,,,,,,,,0,,,,0,,,,,,150.0058594,,,,
,27329227.36,149.9997559,83716.64453125,-0.000260141699250673,3.15617538075858E-6,1,0.999253354069792,40.0298881530762,1.98342825408797,21.3799998164177,-0.00292947042697051,-0.000552142799981626,0.25,-3.61114639675082E-6,-0.000261414679663281,-4.02604984560268E-6,149.9997559,149.9997559,83714.171875,83719.1171875,56.6493085597752,20.6121794849258,23.668306,0,0,0,40,4449,149.82,83716.64453125,,,,,,,,,,,,,0,,,,0.00245,,,,,,149.9997559,,,,
,27329325.695,149.9957886,78800.48828125,-0.000237605821683666,3.12200778784453E-6,1,0.999253354069792,40.0298881530762,1.98333037475828,21.3699992746115,-0.00267565516184677,-0.000503761340281823,0.25,-3.25051677073339E-6,-0.000238768343045909,-3.63049417364344E-6,149.9957886,149.9957886,78790.375,78810.6015625,57.1214121853907,20.619431805459,23.288654,0,0,0,40,4449,149.8271,78800.48828125,,,,,,,,,,,,,0,,,,-0.00245,,,,,,149.9957886,,,,
,27329423.565,149.9921875,73907.23046875,-0.000223137561075847,2.45441687730207E-6,1,0.999253354069792,40.0298881530762,1.98347540447997,21.3699992746115,-0.00252117559049142,-0.000425613207220458,0.25,1.15689915513642E-6,-0.000224235521630318,8.19556678391813E-7,149.9921875,149.9921875,73896.96875,73917.4921875,57.4051433378714,20.6260474543145,23.668306,0,0,0,40,4449,149.82815,73907.23046875,,,,,,,,,,,,,0,,,,0.0049,,,,,,149.9921875,,,,
,27329518.94,149.990387,69139.04296875,-0.000205042367297546,2.22582751567638E-6,1,0.999253354069792,40.0298881530762,1.98334417780326,21.3699992746115,-0.00231602923476269,-0.000394200328314505,0.25,7.87078205257749E-7,-0.000206050661262299,4.74705821636371E-7,149.990387,149.990387,69134.1796875,69143.90625,57.2949337166599,20.6193572006354,23.668306,0,0,0,40,4449,149.83755,69139.04296875,,,,,,,,,,,,,0,,,,-0.0049,,,,,,149.990387,,,,
,27329614.895,149.993515,64343.751953125,-0.000186363690046502,3.68395106460357E-6,1,0.999253354069792,40.0298881530762,1.98319251835659,21.3699992746115,-0.00209631150472409,-0.000407522156616939,0.25,-3.64790133852112E-6,-0.000187273168561874,-3.95417965818743E-6,149.993515,149.993515,64336.4609375,64351.04296875,57.0065127930637,20.6268402488698,23.668306,0,0,0,40,4449,149.84635,64343.751953125,,,,,,,,,,,,,0,,,,-0.00245,,,,,,149.993515,,,,
,27329712.13,149.990509,59483.095703125,-0.000168646372423704,2.54050569765015E-6,1,0.999253354069792,40.0298881530762,1.98297489802545,21.3799998164177,-0.00189671261593382,-0.00036934213779292,0.25,-3.35355353106963E-6,-0.000169469122191299,-3.63182214340938E-6,149.990509,149.990509,59478.2421875,59487.94921875,56.8548768603329,20.6302376079679,23.668306,0,0,0,40,4449,149.8541,59483.095703125,,,,,,,,,,,,,0,,,,-0.0049,,,,,,149.990509,,,,
,27329807.69,149.9923706,54707.330078125,-0.000150883293059291,2.6118083602165E-6,1,0.999253354069792,40.0298881530762,1.98245193076378,21.3799998164177,-0.00170206166499162,-0.000298466845905191,0.25,-1.73220507910386E-7,-0.000151623607991469,-4.09032469478632E-7,149.9923706,149.9923706,54699.8203125,54714.83984375,56.5844333926791,20.6304757385932,24.047956,0,0,0,40,4449,149.86635,54707.330078125,,,,,,,,,,,,,0,,,,-0.00245,,,,,,149.9923706,,,,
,27329904.72,149.991745,49857.71875,-0.000136436500290385,2.52647694293846E-6,1,0.999253354069792,40.0298881530762,1.98231435577261,21.3699992746115,-0.0015407147047931,-0.000259962116888846,0.25,7.22328989290701E-7,-0.000137107159316865,5.12725108117906E-7,149.991745,149.991745,49847.6484375,49867.7890625,56.4437402592175,20.6383459381438,24.047956,0,0,0,40,4449,149.86905,49857.71875,,,,,,,,,,,,,0,,,,0,,,,,,149.991745,,,,
,27330002.065,149.9914322,44992.8671875,-0.000115065776456824,2.74782336226592E-6,1,0.999253354069792,40.0298881530762,1.98229637471477,21.3699992746115,-0.00129649468042632,-0.000235761928312101,0.25,-8.54626844777508E-7,-0.000115628975750736,-1.03914367627769E-6,149.991272,149.9915924,44990.5703125,44995.1640625,56.6454004171791,20.6400844041491,23.288654,0,0,0,40,4449,149.8771,44992.8671875,,,,,,,,,,,,,0,,,,0,,,,,,149.9914322,,,,
,27330097.575,149.9900055,40219.896484375,-9.99446956651794E-5,2.46451568122106E-6,1,0.999253354069792,40.0298881530762,1.9824600576467,21.3699992746115,-0.00112144314672376,-0.000232143512434737,0.25,-3.16567005403361E-6,-0.000100429973040684,-3.33829659043164E-6,149.9900055,149.9900055,40212.4609375,40227.33203125,56.9236601700253,20.6393996131656,23.668306,0,0,0,40,4449,149.88505,40219.896484375,,,,,,,,,,,,,0,,,,0,,,,,,149.9900055,,,,
,27330191.73,149.9925385,35512.10546875,-8.37302358903269E-5,2.13010866677086E-6,1,0.999253354069792,40.0298881530762,1.98239858775273,21.3799998164177,-0.000938992942956093,-0.000197258363822964,0.25,-2.89832919485412E-6,-8.4136295769181E-5,-3.04453560990557E-6,149.9925385,149.9925385,35504.625,35519.5859375,56.8666012881214,20.6408603713425,23.668306,0,0,0,40,4449,149.8938,35512.10546875,,,,,,,,,,,,,0,,,,-0.00245,,,,,,149.9925385,,,,
,27330283.015,149.9914246,30949.5576171875,-6.68512457079361E-5,1.46010193679752E-6,1,0.999253354069792,40.0298881530762,1.98236761229497,21.3699992746115,-0.000750742354802331,-0.00015145834047806,0.25,-1.77907597057813E-6,-6.7176223658994E-5,-1.89347317148132E-6,149.9914246,149.9914246,30911.89453125,30987.220703125,57.220679007333,20.6402918870462,24.047956,0,0,0,40,4449,149.9014,30949.5576171875,,,,,,,,,,,,,0,,,,0,,,,,,149.9914246,,,,
,27330378.66,149.9921722,26169.3916015625,-4.9143890045779E-5,1.71170935338005E-6,1,0.999253354069792,40.0298881530762,1.98231426129783,21.3699992746115,-0.000552687775327029,-0.000106661479497091,0.25,-8.93154685570723E-7,-4.93833919533983E-5,-9.75433738600382E-7,149.9921722,149.9921722,26159.220703125,26179.5625,57.1198489283522,20.6426492694632,23.668306,0,0,0,40,4449,149.90945,26169.3916015625,,,,,,,,,,,,,0,,,,0,,,,,,149.9921722,,,,
,27330474.445,149.9904938,21381.6171875,-3.32520378773473E-5,1.61485855450682E-6,1,0.999253354069792,40.0298881530762,1.98214370743157,21.3699992746115,-0.000372126490024047,-8.2527395491811E-5,0.25,-1.52284664089349E-6,-3.34125988123269E-5,-1.58316345899091E-6,149.9904938,149.9904938,21376.873046875,21386.361328125,56.7595181809868,20.6431882810596,23.668306,0,0,0,40,4449,149.9162,21381.6171875,,,,,,,,,,,,,0,,,,0,,,,,,149.9904938,,,,
,27330568.46,149.9900665,16682.3017578125,-1.79708091082886E-5,1.53009086605862E-6,1,0.999253354069792,40.0298881530762,1.98234358495153,21.3699992746115,-0.000201050730790544,-4.50724956001087E-5,0.25,-8.64327434964905E-7,-1.80574984391424E-5,-8.97198523364006E-7,149.9900665,149.9900665,16674.9375,16689.666015625,57.1675282680253,20.6391617438449,23.288654,0,0,0,40,4449,149.9278,16682.3017578125,,,,,,,,,,,,,0,,,,0.00245,,,,,,149.9900665,,,,
,27330665.22,149.9936218,11847.3510742187,-2.23664501010785E-6,8.22128937070137E-7,1,0.999253354069792,40.0298881530762,1.982381826469,21.3699992746115,-2.50668216787358E-5,-5.35933765979622E-6,0.25,-8.53643841736653E-8,-2.2474672169327E-6,-8.93555198243591E-8,149.9936218,149.9936218,11842.013671875,11852.6884765625,57.1784710672945,20.6415877618622,23.668306,0,0,0,40,4449,149.9322,11847.3510742187,,,,,,,,,,,,,0,,,,0,,,,,,149.9936218,,,,
,27330763.075,149.99188235,6957.04565429688,1.16494759995911E-5,6.12120110510829E-7,1,0.999253354069792,40.0298881530762,1.9824116594304,21.3699992746115,0.000132550239482406,1.64978733607333E-5,0.25,-5.67293990055727E-7,1.1707452695464E-5,-5.51420941446738E-7,149.9915619,149.9922028,6949.599609375,6964.49169921875,56.760299809506,20.6391754230706,24.047956,0,0,0,40,4449,149.9394,6957.04565429688,,,,,,,,,,,,,0,,,,0,,,,,,149.99188235,,,,
,27330857.88,149.99386595,2216.39172363281,2.30112241480792E-5,3.94520395044562E-7,1,0.999253354069792,40.0298881530762,1.9823189008507,21.3699992746115,0.000260314230770242,4.11997671223377E-5,0.25,-3.57220118622359E-7,2.3124507398163E-5,-3.22054811448446E-7,149.9938049,149.993927,2206.35961914062,2226.423828125,57.1628384969099,20.6385578705942,24.047956,0,0,0,40,4449,149.94405,2216.39172363281,,,,,,,,,,,,,0,,,,0,,,,,,149.99386595,,,,
,27330954.75,149.9948578,-2619.46838378906,2.90416457340929E-5,4.42137439141728E-7,1,0.999253354069792,40.0298881530762,1.98251334148012,21.3699992746115,0.000328030280194456,5.50657139946335E-5,0.25,-1.79261184076583E-7,2.9184181769837E-5,-1.33558302186973E-7,149.9948578,149.9948578,-2631.92456054687,-2607.01220703125,57.0229269919676,20.6374279848546,23.668306,0,0,0,40,4449,149.9467,-2619.46838378906,,,,,,,,,,,,,0,,,,0,,,,,,149.9948578,,,,
,27331051.89,149.9987488,-7478.83666992188,2.13317886077171E-5,6.33921960900181E-7,1,0.999253354069792,40.0298881530762,1.98252948958367,21.3799998164177,0.000238945384080602,5.19432893006257E-5,0.25,8.87251560889302E-7,2.14348666617329E-5,9.25742196022366E-7,149.9987488,149.9987488,-7486.33203125,-7471.34130859375,56.8564401173714,20.6399083919478,23.668306,0,0,0,40,4449,149.9457,-7478.83666992188,,,,,,,,,,,,,0,,,,-0.00245,,,,,,149.9987488,,,,
,27331148.89,150.0014496,-12324.3842773437,1.47833500781977E-5,8.35460013070266E-7,1,0.999253354069792,40.0298881530762,1.98283863473916,21.3799998164177,0.000166312106260159,3.20227937154888E-5,0.25,2.6222370674054E-7,1.48553617974404E-5,2.87115494395986E-7,150.0014496,150.0014496,-12334.6044921875,-12314.1640625,56.7798405224868,20.6357044016724,24.047956,0,0,0,40,4449,149.9436,-12324.3842773437,,,,,,,,,,,,,0,,,,-0.00245,,,,,,150.0014496,,,,
,27331246.03,150.0054321,-17179.369140625,2.242648471594E-5,1.0251946197403E-6,1,0.999253354069792,40.0298881530762,1.98277197337954,21.3699992746115,0.000253818277585269,3.97999832977782E-5,0.25,-3.79943025020168E-7,2.25369846647524E-5,-3.46081653980783E-7,150.0054321,150.0054321,-17181.837890625,-17176.900390625,57.085457273506,20.638056812783,23.288654,0,0,0,40,4449,149.9348,-17179.369140625,,,,,,,,,,,,,0,,,,0,,,,,,150.0054321,,,,
,27331341.98,150.0119171,-21974.0400390625,3.75349455108476E-5,1.49021068921596E-6,1,0.999253354069792,40.0298881530762,1.98254821736059,21.3799998164177,0.000424441135431487,6.84771029575651E-5,0.25,-4.69891084791918E-7,3.77196483592296E-5,-4.12557703962889E-7,150.0119171,150.0119171,-21984.064453125,-21964.015625,56.9510171681983,20.6395664709623,24.047956,0,0,0,40,4449,149.92275,-21974.0400390625,,,,,,,,,,,,,0,,,,-0.00245,,,,,,150.0119171,,,,
,27331439.72,150.0128479,-26861.82421875,5.42441788583884E-5,2.01604450079203E-6,1,0.999253354069792,40.0298881530762,1.98272794624503,21.3699992746115,0.000613897850123084,9.63467953849885E-5,0.25,-9.11244596376674E-7,5.45115196099565E-5,-8.29761158647448E-7,150.0128479,150.0128479,-26871.880859375,-26851.767578125,57.2027015513907,20.6388912190655,23.668306,0,0,0,40,4449,149.90915,-26861.82421875,,,,,,,,,,,,,0,,,,-0.00245,,,,,,150.0128479,,,,
,27331533.915,150.01155855,-31566.6376953125,7.06241996093398E-5,2.08016226174151E-6,1,0.999253354069792,40.0298881530762,1.98262703599203,21.3699992746115,0.000795576414907881,0.00014645079562629,0.25,6.7642426688837E-7,7.09693899236755E-5,7.91336537277559E-7,150.0115204,150.0115967,-31578.88671875,-31554.388671875,56.8666012881214,20.6383422323019,23.668306,0,0,0,40,4449,149.90135,-31566.6376953125,,,,,,,,,,,,,0,,,,0.00245,,,,,,150.01155855,,,,
,27331632.455,150.0111237,-36493.4296875,8.79896928963542E-5,1.96144734655481E-6,1,0.999253354069792,40.0298881530762,1.98306924383917,21.3699992746115,0.000987763784667204,0.000203430344770801,0.25,2.69766246470183E-6,8.8416932342683E-5,2.84951739890618E-6,150.0111237,150.0111237,-36500.87109375,-36485.98828125,57.0862389020253,20.6353464397864,23.668306,0,0,0,40,4449,149.89065,-36493.4296875,,,,,,,,,,,,,0,,,,0.00245,,,,,,150.0111237,,,,
,27331728.145,150.0107269,-41273.244140625,0.000104385137299394,2.56470394591527E-6,1,0.999253354069792,40.0298881530762,1.98261462026594,21.3699992746115,0.00117616332536428,0.000214868583543344,0.25,8.59818603247427E-7,0.000104895783388535,1.02800830746828E-6,150.0107269,150.0107269,-41277.953125,-41268.53515625,57.034651419756,20.6407321820383,23.288654,0,0,0,40,4449,149.8817,-41273.244140625,,,,,,,,,,,,,0,,,,0,,,,,,150.0107269,,,,
,27331828.305,150.0087891,-46280.87109375,0.000123803682871129,3.11310656606773E-6,1,0.999253354069792,40.0298881530762,1.98292831966775,21.3699992746115,0.00139527602690537,0.000254298686275423,0.25,9.68962205762155E-7,0.000124409547073035,1.16757920994344E-6,150.0087891,150.0087891,-46286,-46275.7421875,57.718576374083,20.6369755533762,23.668306,0,0,0,40,4449,149.87215,-46280.87109375,,,,,,,,,,,,,0,,,,0.0049,,,,,,150.0087891,,,,
,27331926.425,150.0093689,-51183.15625,0.000139233818999581,2.5953703349907E-6,1,0.999253354069792,40.0298881530762,1.98279198941467,21.3699992746115,0.0015714999887961,0.000272042306438603,0.25,-1.44191784884615E-7,0.000139917270941243,7.24417666082939E-8,150.0093689,150.0093689,-51188.01171875,-51178.30078125,57.2519441481022,20.6405794630823,23.668306,0,0,0,40,4449,149.86225,-51183.15625,,,,,,,,,,,,,0,,,,-0.0049,,,,,,150.0093689,,,,
,27332023.36,150.0089111,-56027.412109375,0.00015878110909924,2.78541879381336E-6,1,0.999253354069792,40.0298881530762,1.98288466301942,21.3699992746115,0.00178655815435737,0.000342685298455032,0.25,2.71055917196816E-6,0.000159556206975143,2.97093736982853E-6,150.0089111,150.0089111,-56029.8203125,-56025.00390625,56.9119357422368,20.6382585683922,23.668306,0,0,0,40,4449,149.8517,-56027.412109375,,,,,,,,,,,,,0,,,,-0.00245,,,,,,150.0089111,,,,
,27332120.39,150.0106201,-60877.228515625,0.000174283486728922,2.62783859757514E-6,1,0.999253354069792,40.0298881530762,1.98312217370944,21.3699992746115,0.00196407770174938,0.000359737585260545,0.25,1.51869524244748E-6,0.000175136712894697,1.7964737817665E-6,150.0106201,150.0106201,-60892.26953125,-60862.1875,57.566158812833,20.6390746919571,23.668306,0,0,0,40,4449,149.8441,-60877.228515625,,,,,,,,,,,,,0,,,,0,,,,,,150.0106201,,,,
,27332220.345,150.0135193,-65874.27734375,0.000193019582835662,3.41875858698259E-6,1,0.999253354069792,40.0298881530762,1.98310533099858,21.3699992746115,0.00217198756706598,0.000416897012113242,0.25,3.32110855123123E-6,0.000193962202799772,3.63581370603013E-6,150.0135193,150.0135193,-65879.3203125,-65869.234375,56.8071975206598,20.6401375978797,23.288654,0,0,0,40,4449,149.8284,-65874.27734375,,,,,,,,,,,,,0,,,,0.0049,,,,,,150.0135193,,,,
,27332321.46,150.0119629,-70926.25,0.000211714500186096,2.76157305772782E-6,1,0.999253354069792,40.0298881530762,1.98273858012321,21.3799998164177,0.0023792251397459,0.000472769935332015,0.25,5.02405885565137E-6,0.000212746555774851,5.37491405847049E-6,150.0119629,150.0119629,-70931.203125,-70921.296875,57.1948852661984,20.6431468147744,23.668306,0,0,0,40,4449,149.81765,-70926.25,,,,,,,,,,,,,0,,,,0.0049,,,,,,150.0119629,,,,
,27332418.64,150.0112305,-75783.41015625,0.000231992549660129,2.55392403072733E-6,1,0.999253354069792,40.0298881530762,1.9825953891141,21.3699992746115,0.00261159229249288,0.000491251163812036,0.25,3.13441426566089E-6,0.000233127383921283,3.5060316727385E-6,150.0112305,150.0112305,-75788.4375,-75778.3828125,57.027616763083,20.6446413757386,23.288654,0,0,0,40,4449,149.81165,-75783.41015625,,,,,,,,,,,,,0,,,,0,,,,,,150.0112305,,,,
,27332516.61,150.0096893,-80678.50390625,0.000250058015502719,3.20292027343082E-6,1,0.999253354069792,40.0298881530762,1.98268014033756,21.3699992746115,0.00281331872130569,0.00053962775427075,0.25,4.27485100634522E-6,0.000251280150256216,4.67851924076964E-6,150.0096893,150.0096893,-80691.0703125,-80665.9375,56.9549253107945,20.6422111386929,23.668306,0,0,0,40,4449,149.80025,-80678.50390625,,,,,,,,,,,,,0,,,,-0.0049,,,,,,150.0096893,,,,
,27332610.29,150.0095825,-85360.3671875,0.000266038430369426,2.99291920782375E-6,1,0.999253354069792,40.0298881530762,1.9830249527037,21.3699992746115,0.00299753786541665,0.000551651972829689,0.25,2.5506639125769E-6,0.000267342018290603,2.96898461456837E-6,150.0095825,150.0095825,-85367.7734375,-85352.9609375,56.729816297256,20.6368055206669,23.668306,0,0,0,40,4449,149.7913,-85360.3671875,,,,,,,,,,,,,0,,,,0,,,,,,150.0095825,,,,
,27332703.96,150.01107025,-89999.453125,0.000284749724253041,3.18384833231482E-6,1,0.999253354069792,40.0298881530762,1.98295253150169,21.3699992746115,0.00320427172351831,0.000613307346673513,0.25,4.75844842986646E-6,0.000286142212916435,5.21474435102904E-6,150.0107269,150.0114136,-89999.4921875,-89999.4140625,56.4523381729291,20.6409632649579,24.047956,0,0,0,40,4417,149.7823,-89999.453125,,,,,,,,,,,,,0,,,,0.0049,,,,,,150.01107025,,,,
,27332815.245,150.0046387,-85358.2265625,0.000267073074553547,2.70721341337812E-6,1,0.999253354069792,40.0298881530762,1.98301897737311,21.3699992746115,0.00300595921390536,0.000572332285884402,0.25,4.20294333415374E-6,0.000268379253033438,4.63101300488982E-6,150.0046387,150.0046387,-85360.3671875,-85356.0859375,57.3441763133715,20.6388488257081,24.047956,0,0,0,40,4449,149.7781,-85358.2265625,,,,,,,,,,,,,0,,,,-0.00245,,,,,,150.0046387,,,,
,27332913.14,149.9972382,-80465.6796875,0.000248864399348034,3.78390189063912E-6,1,0.999253354069792,40.0298881530762,1.98292991434039,21.3799998164177,0.00280911697422961,0.000486069764585265,0.25,-2.68864664073762E-7,0.000250087682811928,1.10779273277342E-7,149.9972382,149.9972382,-80468.25,-80463.109375,56.9291315696599,20.6408211160196,23.288654,0,0,0,40,4449,149.7803,-80465.6796875,,,,,,,,,,,,,0,,,,0.00245,,,,,,149.9972382,,,,
,27333010.73,149.9949341,-75587.59765625,0.000231673409879769,2.92206247046166E-6,1,0.999253354069792,40.0298881530762,1.98295341751058,21.3699992746115,0.00261225089852179,0.000468837325026362,0.25,1.19629166528187E-6,0.000232809727501452,1.55804232485653E-6,149.9949341,149.9949341,-75595.25,-75579.9453125,56.8650380310829,20.6419106133904,23.288654,0,0,0,40,4449,149.78305,-75587.59765625,,,,,,,,,,,,,0,,,,0,,,,,,149.9949341,,,,
,27333107.58,149.9936066,-70748.64453125,0.000209144950069643,2.56597918611486E-6,1,0.999253354069792,40.0298881530762,1.98288629632482,21.3699992746115,0.00236101010264038,0.00040681436383345,0.25,-3.75913156107848E-7,0.000210172788676611,-5.54202117272621E-8,149.9936066,149.9936066,-70758.46875,-70738.8203125,56.7642079521022,20.6426541189873,23.668306,0,0,0,40,4449,149.79185,-70748.64453125,,,,,,,,,,,,,0,,,,-0.0049,,,,,,149.9936066,,,,
,27333203.815,149.9913483,-65938.6640625,0.000196262379052081,3.5057508850787E-6,1,0.999253354069792,40.0298881530762,1.98303303840081,21.3699992746115,0.00220599365030614,0.000437714921996382,0.25,4.60210808040327E-6,0.000197219050428423,4.92817538063466E-6,149.9913483,149.9913483,-65945.984375,-65931.34375,57.2394380917945,20.6390675396226,23.288654,0,0,0,40,4449,149.80375,-65938.6640625,,,,,,,,,,,,,0,,,,0,,,,,,149.9913483,,,,
,27333302.29,149.9924622,-61016.501953125,0.000176560128198191,3.01987728046536E-6,1,0.999253354069792,40.0298881530762,1.98291951399978,21.3699992746115,0.00198912671526715,0.000366778702760249,0.25,1.74911849009556E-6,0.000177424247812377,2.03163068284827E-6,149.9924622,149.9924622,-61018.96875,-61014.03515625,57.4504777919868,20.6408441370678,24.047956,0,0,0,40,4449,149.8065,-61016.501953125,,,,,,,,,,,,,0,,,,-0.0049,,,,,,149.9924622,,,,
,27333400.595,149.9934998,-56102.0625,0.00015910782806119,2.84392132936183E-6,1,0.999253354069792,40.0298881530762,1.98306889400955,21.3699992746115,0.00179572262593503,0.000312825706215363,0.25,5.2136586941332E-9,0.000159888791505343,2.52900252304236E-7,149.9934998,149.9934998,-56111.92578125,-56092.19921875,57.2644502044099,20.6380461458341,23.668306,0,0,0,40,4449,149.81285,-56102.0625,,,,,,,,,,,,,0,,,,0,,,,,,149.9934998,,,,
,27333499.455,149.9914093,-51162.650390625,0.000141154688495871,2.70434344552576E-6,1,0.999253354069792,40.0298881530762,1.98307299991037,21.3699992746115,0.00159449042891022,0.000269553374590008,0.25,-7.02653394322857E-7,0.000141848490158945,-4.85670670989591E-7,149.9914093,149.9914093,-51170.14453125,-51155.15625,57.098744958333,20.6391037597809,24.047956,0,0,0,40,4449,149.81985,-51162.650390625,,,,,,,,,,,,,0,,,,0.00245,,,,,,149.9914093,,,,
,27333599.375,149.9904938,-46170.486328125,0.000123344516540568,2.95687185287332E-6,1,0.999253354069792,40.0298881530762,1.98321589482832,21.3699992746115,0.00138693932246545,0.000272651844194064,0.25,2.67176438226094E-6,0.000123945504206441,2.87810572656992E-6,149.9904938,149.9904938,-46177.96484375,-46163.0078125,56.6962062709291,20.6347040971059,23.668306,0,0,0,40,4449,149.83155,-46170.486328125,,,,,,,,,,,,,0,,,,0.00245,,,,,,149.9904938,,,,
,27333695.445,149.9912567,-41367.73046875,0.000104279011978263,2.64340645278411E-6,1,0.999253354069792,40.0298881530762,1.9832724149016,21.3699992746115,0.00117279493848879,0.000229331974829824,0.25,2.15359155358818E-6,0.000104787148900312,2.32801816867833E-6,149.9912567,149.9912567,-41375.22265625,-41360.23828125,56.5242479966983,20.6336457905107,24.047956,0,0,0,40,4449,149.8389,-41367.73046875,,,,,,,,,,,,,0,,,,0,,,,,,149.9912567,,,,
,27333795.18,149.9906616,-36383.103515625,8.6623716790944E-5,2.94421409273285E-6,1,0.999253354069792,40.0298881530762,1.98321992018459,21.3799998164177,0.000975602165804315,0.000182480503186772,0.25,1.07812152791896E-6,8.70468444486161E-5,1.21994679820633E-6,149.9906616,149.9906616,-36388.26171875,-36377.9453125,56.8994296859291,20.6380128943366,23.668306,0,0,0,40,4449,149.8489,-36383.103515625,,,,,,,,,,,,,0,,,,0,,,,,,149.9906616,,,,
,27333891.3,149.9896088,-31581.833984375,7.05242683476877E-5,2.18786693635667E-6,1,0.999253354069792,40.0298881530762,1.98314122062319,21.3699992746115,0.000794417805939994,0.000147600727019545,0.25,7.92448741337279E-7,7.08688180284416E-5,9.07820075832627E-7,149.9896088,149.9896088,-31592.404296875,-31571.263671875,57.7099784603715,20.6354153142719,23.668306,0,0,0,40,4449,149.85575,-31581.833984375,,,,,,,,,,,,,0,,,,-0.00245,,,,,,149.9896088,,,,
,27333983.375,149.99018095,-26979.326171875,5.3672724112341E-5,1.94286317711011E-6,1,0.999253354069792,40.0298881530762,1.98320094573597,21.3699992746115,0.000603462948636851,0.000118925833788618,0.25,1.18679444590066E-6,5.39339661580718E-5,1.2776881330046E-6,149.9897766,149.9905853,-26984.234375,-26974.41796875,57.0940551872176,20.6333910107638,23.668306,0,0,0,40,4449,149.86425,-26979.326171875,,,,,,,,,,,,,0,,,,-0.00245,,,,,,149.99018095,,,,
,27334081.89,149.99006655,-22056.630859375,3.8149215553003E-5,1.86990665865397E-6,1,0.999253354069792,40.0298881530762,1.98333629095616,21.3799998164177,0.00042991459877473,7.90191202031201E-5,0.25,3.54713917352615E-7,3.83356357387912E-5,4.1709313281092E-7,149.9894257,149.9907074,-22066.265625,-22046.99609375,56.9799374234099,20.633239822978,23.668306,0,0,0,40,4449,149.8694,-22056.630859375,,,,,,,,,,,,,0,,,,-0.0049,,,,,,149.99006655,,,,
,27334177,149.9915771,-17301.5,2.0890865258115E-5,1.46026327183483E-6,1,0.999253354069792,40.0298881530762,1.98331854114604,21.3699992746115,0.000235194157781818,4.45847454779707E-5,0.25,3.10532117837454E-7,2.09927448950166E-5,3.45346842574827E-7,149.9915771,149.9915771,-17309.015625,-17293.984375,57.241001348833,20.6336371335748,24.047956,0,0,0,40,4449,149.8786,-17301.5,,,,,,,,,,,,,0,,,,0,,,,,,149.9915771,,,,
,27334271.28,149.990799,-12589.140625,6.41642444301896E-6,1.04521735145764E-6,1,0.999253354069792,40.0298881530762,1.98338882365625,21.3699992746115,7.26826955410255E-5,1.1152903246652E-5,0.25,-1.29785496989005E-7,6.44806981197801E-6,-1.20171074246819E-7,149.990799,149.990799,-12591.3701171875,-12586.9111328125,57.187068981006,20.6314651444743,23.288654,0,0,0,40,4449,149.8879,-12589.140625,,,,,,,,,,,,,0,,,,-0.00245,,,,,,149.990799,,,,
,27334365.275,149.9914398,-7890.97045898438,-8.55206401803779E-6,7.24547287924924E-7,1,0.999253354069792,40.0298881530762,1.98333730660159,21.3799998164177,-9.59304907383072E-5,-2.02682413515213E-5,0.25,-3.05708155468798E-7,-8.59346940226359E-6,-3.20898791269773E-7,149.9914398,149.9914398,-7893.4716796875,-7888.46923828125,57.187068981006,20.6312067235082,24.047956,0,0,0,40,4449,149.8932,-7890.97045898438,,,,,,,,,,,,,0,,,,-0.0049,,,,,,149.9914398,,,,
,27334458.9,149.9918365,-3213.14147949219,-2.05910323020039E-5,4.74007915979134E-7,1,0.999253354069792,40.0298881530762,1.98332292707991,21.3699992746115,-0.000231104350992716,-4.80438387907862E-5,0.25,-6.69005016095792E-7,-2.06908158481123E-5,-7.05315784280552E-7,149.9918365,149.9918365,-3220.607421875,-3205.67553710937,56.8572217458906,20.6317844617232,23.668306,0,0,0,40,4449,149.9008,-3213.14147949219,,,,,,,,,,,,,0,,,,-0.0049,,,,,,149.9918365,,,,
,27334553.95,149.9947662,1538.02819824219,-2.75148439118024E-5,3.9566858834374E-7,1,0.999253354069792,40.0298881530762,1.98342047457374,21.3699992746115,-0.000309849675752942,-5.83402146385527E-5,0.25,-3.74661322942692E-7,-2.76490048758273E-5,-4.20663611527322E-7,149.9947662,149.9947662,1535.50415039062,1540.55224609375,56.7970363499099,20.6299158331883,24.427608,0,0,0,40,4449,149.90475,1538.02819824219,,,,,,,,,,,,,0,,,,0,,,,,,149.9947662,,,,
,27334647.72,149.9986877,6225.00415039063,-2.2741374360985E-5,6.16374816393285E-7,1,0.999253354069792,40.0298881530762,1.98346629932756,21.3699992746115,-0.000256121947132806,-4.80973288308536E-5,0.25,-2.98861036890152E-7,-2.28522911713167E-5,-3.36760599977934E-7,149.9986877,149.9986877,6217.39599609375,6232.6123046875,57.2073913225061,20.6287698994413,24.047956,0,0,0,40,4449,149.9053,6225.00415039063,,,,,,,,,,,,,0,,,,0,,,,,,149.9986877,,,,
,27334743.9,150.0042267,11030.818359375,-1.4129938508724E-5,1.33821345374015E-6,1,0.999253354069792,40.0298881530762,1.98355201299469,21.3699992746115,-0.000158078394309987,-3.59986933668447E-5,0.25,-7.27260533068604E-7,-1.41979984795313E-5,-7.53411574120436E-7,150.0042267,150.0042267,11025.8291015625,11035.8076171875,57.119067299833,20.6285442890581,23.668306,0,0,0,40,4449,149.899,11030.818359375,,,,,,,,,,,,,0,,,,-0.0049,,,,,,150.0042267,,,,
,27334837.265,150.0059509,15695.9809570313,-1.82465750283388E-5,1.6288540185153E-6,1,0.999253354069792,40.0298881530762,1.98339823617517,21.3699992746115,-0.000204516507944623,-4.41972021485179E-5,0.25,-7.36692105579365E-7,-1.83348044190525E-5,-7.6940179196255E-7,150.005722,150.0061798,15688.2802734375,15703.681640625,56.7946914643522,20.6318061721334,24.047956,0,0,0,40,4449,149.8932,15695.9809570313,,,,,,,,,,,,,0,,,,0,,,,,,150.0059509,,,,
,27334929.45,150.0088654,20305.84765625,-3.02513268985881E-5,2.00808824999489E-6,1,0.999253354069792,40.0298881530762,1.98345833459717,21.3699992746115,-0.000339788204188072,-6.92222519501408E-5,0.25,-8.62243729450137E-7,-3.03982033807413E-5,-9.14597372305631E-7,150.0088654,150.0088654,20295.630859375,20316.064453125,56.943200883006,20.6303871895454,23.288654,0,0,0,40,4449,149.8825,20305.84765625,,,,,,,,,,,,,0,,,,0.00245,,,,,,150.0088654,,,,
,27335027.01,150.0107422,25180.9638671875,-4.54695200707913E-5,1.9315817730877E-6,1,0.999253354069792,40.0298881530762,1.98356533222067,21.3699992746115,-0.000512873202030117,-9.18536080551717E-5,0.25,-2.15754295773248E-7,-4.56920445892931E-5,-2.88953134367044E-7,150.0107422,150.0107422,25178.49609375,25183.431640625,57.4410982497561,20.6290580540379,23.668306,0,0,0,40,4449,149.8759,25180.9638671875,,,,,,,,,,,,,0,,,,-0.0049,,,,,,150.0107422,,,,
,27335120.93,150.010437,29874.166015625,-6.32061295014658E-5,2.79075824640193E-6,1,0.999253354069792,40.0298881530762,1.98353939772414,21.3699992746115,-0.000713769302458794,-0.000122835129024101,0.25,1.2918061309356E-7,-6.35161956066078E-5,2.98026658351178E-8,150.010437,150.010437,29866.533203125,29881.798828125,57.4551675631022,20.6299122103194,24.047956,0,0,0,40,4449,149.8659,29874.166015625,,,,,,,,,,,,,0,,,,0,,,,,,150.010437,,,,
,27335216.185,150.0107727,34636.583984375,-7.95786458149629E-5,2.53556259890208E-6,1,0.999253354069792,40.0298881530762,1.98358212288842,21.3699992746115,-0.000894416274151207,-0.000179127624874145,0.25,-2.00538176289941E-6,-7.99656847367778E-5,-2.14077644765924E-6,150.0107727,150.0107727,34629.26953125,34643.8984375,56.943200883006,20.6280789150052,23.668306,0,0,0,40,4449,149.8561,34636.583984375,,,,,,,,,,,,,0,,,,-0.00245,,,,,,150.0107727,,,,
,27335312.045,150.0104523,39428.9375,-9.66308034911126E-5,2.14478809144649E-6,1,0.999253354069792,40.0298881530762,1.98349700524739,21.3699992746115,-0.00109023779008519,-0.00019334033869106,0.25,-2.95118740559717E-7,-9.71042530005718E-5,-4.485866675066E-7,150.0104523,150.0104523,39421.32421875,39436.55078125,56.350726465429,20.6316536805683,23.288654,0,0,0,40,4449,149.8472,39428.9375,,,,,,,,,,,,,0,,,,0,,,,,,150.0104523,,,,
,27335406.455,150.0106659,44146.564453125,-0.000114488603022851,3.0024701518712E-6,1,0.999253354069792,40.0298881530762,1.98356982993327,21.3699992746115,-0.00128899720165061,-0.000244969601142791,0.25,-1.75783363118102E-6,-0.000115047454644045,-1.94604213559265E-6,150.0106659,150.0106659,44143.96484375,44149.1640625,56.7634263235829,20.6278980034487,24.047956,0,0,0,40,4449,149.8374,44146.564453125,,,,,,,,,,,,,0,,,,0,,,,,,150.0106659,,,,
,27335501.925,150.01145175,48919.6953125,-0.000131123178371506,3.44830143442959E-6,1,0.999253354069792,40.0298881530762,1.98343838307253,21.3699992746115,-0.00148026400802987,-0.000257153112281013,0.25,5.83734835315805E-8,-0.000131766607923575,-1.46399938063982E-7,150.0112305,150.011673,48912.3203125,48927.0703125,57.312129544083,20.6255816324451,24.047956,0,0,0,40,4449,149.82525,48919.6953125,,,,,,,,,,,,,0,,,,0.00245,,,,,,150.01145175,,,,
,27335597.51,150.0106506,53697.384765625,-0.000146232755001909,2.6964270789636E-6,1,0.999253354069792,40.0298881530762,1.98361949979996,21.3699992746115,-0.00164936560162767,-0.000296099111493377,0.25,-7.58370875653966E-7,-0.000146949199026994,-9.90076435478657E-7,150.0106506,150.0106506,53689.90234375,53704.8671875,56.6946430138906,20.6240853642064,24.047956,0,0,0,40,4449,149.8153,53697.384765625,,,,,,,,,,,,,0,,,,0,,,,,,150.0106506,,,,
,27335695.005,150.0097961,58567.5703125,-0.000166699018992479,3.07153470519027E-6,1,0.999253354069792,40.0298881530762,1.98326756913004,21.3799998164177,-0.00187712168143892,-0.000353371516735865,0.25,-2.27295509655569E-6,-0.000167513734145707,-2.54316265273714E-6,150.0097961,150.0097961,58562.6171875,58572.5234375,56.5508233663521,20.6266956859872,24.047956,0,0,0,40,4449,149.8098,58567.5703125,,,,,,,,,,,,,0,,,,-0.00245,,,,,,150.0097961,,,,
,27335791.42,150.0109863,63388.107421875,-0.000181095983200726,3.7015168507305E-6,1,0.999253354069792,40.0298881530762,1.98328845717617,21.3699992746115,-0.00203701107498396,-0.00039681918255382,0.25,-3.61517826057229E-6,-0.000181979484281749,-3.91345234498363E-6,150.0109863,150.0109863,63385.71484375,63390.5,56.5828701356406,20.6281814821256,23.288654,0,0,0,40,4449,149.79845,63388.107421875,,,,,,,,,,,,,0,,,,0.0049,,,,,,150.0109863,,,,
,27335887.7,150.0123291,68200.80078125,-0.000202420344964615,2.48590067729703E-6,1,0.999253354069792,40.0298881530762,1.98321758377833,21.3699992746115,-0.00227854570090057,-0.000433492350055117,0.25,-3.15252314562696E-6,-0.000203409480538836,-3.48054468318517E-6,150.0123291,150.0123291,68193.359375,68208.2421875,56.3186796961406,20.6290865770063,23.668306,0,0,0,40,4449,149.7887,68200.80078125,,,,,,,,,,,,,0,,,,0,,,,,,150.0123291,,,,
,27335987.285,150.0103455,73175.8125,-0.000219513877397257,3.22269552951289E-6,1,0.999253354069792,40.0298881530762,1.98331358506044,21.3699992746115,-0.00247421377457037,-0.000452106563701748,0.25,-1.82391948528206E-6,-0.000220589268512899,-2.17066606338642E-6,150.0103455,150.0103455,73170.8984375,73180.7265625,56.310081782429,20.6275292073923,24.047956,0,0,0,40,4449,149.7775,73175.8125,,,,,,,,,,,,,0,,,,-0.0049,,,,,,150.0103455,,,,
,27336082.865,150.0107422,77954.328125,-0.000238688873960512,3.73303753457735E-6,1,0.999253354069792,40.0298881530762,1.98334352295157,21.3799998164177,-0.0026914592647722,-0.000485428101183979,0.25,-1.43709536450264E-6,-0.000239859305933003,-1.81022924806906E-6,150.0107422,150.0107422,77949.265625,77959.390625,57.0268351345637,20.6272754074201,24.047956,0,0,0,40,4449,149.77135,77954.328125,,,,,,,,,,,,,0,,,,0.00245,,,,,,150.0107422,,,,
,27336179.055,150.008255,82765.12109375,-0.000253733958863375,3.50649696411763E-6,1,0.999253354069792,40.0298881530762,1.98337306823788,21.3699992746115,-0.0028572143366991,-0.000538644865272667,0.25,-3.53209265354889E-6,-0.000254975402766737,-3.93729113578681E-6,150.008255,150.008255,82757.515625,82772.7265625,57.0666981890445,20.6271381128366,24.047956,0,0,0,40,4449,149.76295,82765.12109375,,,,,,,,,,,,,0,,,,0,,,,,,150.008255,,,,
,27336273.06,150.0102234,87463.140625,-0.000272588213584025,3.4113916581323E-6,1,0.999253354069792,40.0298881530762,1.983300932086,21.3699992746115,-0.0030741319691898,-0.000551606097052809,0.25,-1.39999476475335E-6,-0.00027392584739292,-1.82215785560094E-6,150.0102234,150.0102234,87455.7265625,87470.5546875,56.7626446950637,20.6232437951765,24.047956,0,0,0,40,4449,149.75515,87463.140625,,,,,,,,,,,,,0,,,,0,,,,,,150.0102234,,,,
,27336384.62,150.0102081,87928.05078125,-0.000271989688098718,3.23060045179868E-6,1,0.999253354069792,40.0298881530762,1.98325423301336,21.3799998164177,-0.00306360826593387,-0.000571658988994873,0.25,-3.28198470125162E-6,-0.000273321534632189,-3.71238904899893E-6,150.0102081,150.0102081,87918.4375,87937.6640625,56.7438856106022,20.6240882215742,23.668306,0,0,0,40,4449,149.744,87928.05078125,,,,,,,,,,,,,0,,,,0.0049,,,,,,150.0102081,,,,
,27336476.5,149.9999695,83334.91015625,-0.000257215739742015,3.12244069132406E-6,1,0.999253354069792,40.0298881530762,1.98317384938304,21.3799998164177,-0.00289979285432587,-0.00052503379462136,0.25,-1.72451429201055E-6,-0.000258477137503291,-2.12605381380342E-6,149.9999695,149.9999695,83325,83344.8203125,56.8947399148137,20.628437990363,24.047956,0,0,0,40,4449,149.7459,83334.91015625,,,,,,,,,,,,,0,,,,-0.00245,,,,,,149.9999695,,,,
,27336573.1,149.9973602,78505.953125,-0.000241995920341188,3.05962873380491E-6,1,0.999253354069792,40.0298881530762,1.98317151625024,21.3699992746115,-0.00272380349844218,-0.000519223304781578,0.25,-3.85898346776411E-6,-0.000243178991981268,-4.24901894354459E-6,149.9973602,149.9973602,78500.9375,78510.96875,56.0505811140444,20.6257659344797,23.668306,0,0,0,40,4449,149.7494,78505.953125,,,,,,,,,,,,,0,,,,0,,,,,,149.9973602,,,,
,27336667.69,149.9947662,73777.2890625,-0.000223620679686378,2.88092455436725E-6,1,0.999253354069792,40.0298881530762,1.98330446757677,21.3699992746115,-0.00251920956402632,-0.000467933266049849,0.25,-2.51105890144092E-6,-0.000224715298985957,-2.86743018578534E-6,149.9947662,149.9947662,73767.328125,73787.25,57.1120326431599,20.6230360935075,23.288654,0,0,0,40,4449,149.7541,73777.2890625,,,,,,,,,,,,,0,,,,0,,,,,,149.9947662,,,,
,27336763.5,149.9914398,68986.9765625,-0.000206173353779848,3.1122496217644E-6,1,0.999253354069792,40.0298881530762,1.98326416486561,21.3699992746115,-0.00231900687533305,-0.000452095001274504,0.25,-4.14620787590038E-6,-0.000207179529702859,-4.48480395172398E-6,149.9914398,149.9914398,68974.578125,68999.375,56.5133051974291,20.6271871615747,24.047956,0,0,0,40,4449,149.76445,68986.9765625,,,,,,,,,,,,,0,,,,0.0049,,,,,,149.9914398,,,,
,27336856.93,149.9919281,64316.43359375,-0.000189337086823187,4.15758542746516E-6,1,0.999253354069792,40.0298881530762,1.98317640820298,21.3799998164177,-0.00213119865978651,-0.000405649878940623,0.25,-2.96423437762725E-6,-0.000190262181914815,-3.27197592544704E-6,149.9919281,149.9919281,64311.578125,64321.2890625,56.7016776705637,20.6296705696871,23.668306,0,0,0,40,4449,149.76805,64316.43359375,,,,,,,,,,,,,0,,,,-0.00245,,,,,,149.9919281,,,,
,27336954.165,149.9912109,59455.75,-0.000170569283503536,3.46848669320211E-6,1,0.999253354069792,40.0298881530762,1.98317032735412,21.3699992746115,-0.00192512023245316,-0.000335687543502075,0.25,-3.36225804396363E-8,-0.000171406582946148,-2.98769629607823E-7,149.9912109,149.9912109,59453.390625,59458.109375,56.6938613853714,20.6292527818512,23.668306,0,0,0,40,4449,149.77875,59455.75,,,,,,,,,,,,,0,,,,-0.00245,,,,,,149.9912109,,,,
,27337048.765,149.988739,54727.6484375,-0.000151342062767029,3.15116135595842E-6,1,0.999253354069792,40.0298881530762,1.98332674092594,21.3799998164177,-0.00170855342581609,-0.000296072443194476,0.25,1.30124686683541E-7,-0.000152085080609336,-1.05084724374548E-7,149.988739,149.988739,54715.23828125,54740.05859375,56.5836517641598,20.6314320353847,24.047956,0,0,0,40,4449,149.7875,54727.6484375,,,,,,,,,,,,,0,,,,0,,,,,,149.988739,,,,
,27337145.05,149.9928284,49918.095703125,-0.000135299676938918,3.05106273893607E-6,1,0.999253354069792,40.0298881530762,1.98323387475323,21.3799998164177,-0.00152564204278283,-0.000274627068863388,0.25,-7.64605760431489E-7,-0.000135962399687619,-9.79868226132735E-7,149.9928284,149.9928284,49913.484375,49922.70703125,56.320242953179,20.6302194548878,24.047956,0,0,0,40,4449,149.7958,49918.095703125,,,,,,,,,,,,,0,,,,-0.0049,,,,,,149.9928284,,,,
,27337241.995,149.9917145,45070.392578125,-0.000119058981846218,3.34586047027621E-6,1,0.999253354069792,40.0298881530762,1.98330810911019,21.3699992746115,-0.00134173383300799,-0.000246403433790249,0.25,-1.09154007919992E-6,-0.000119641371856026,-1.28360406353059E-6,149.9917145,149.9917145,45065.359375,45075.42578125,57.2081729510253,20.6329833575344,23.288654,0,0,0,40,4449,149.8,45070.392578125,,,,,,,,,,,,,0,,,,0.0049,,,,,,149.9917145,,,,
,27337336.255,149.9919434,40359.900390625,-0.000101296936380457,2.26186481959037E-6,1,0.999253354069792,40.0298881530762,1.98317284097258,21.3699992746115,-0.00114240449727622,-0.000204374174780894,0.25,-4.62620230998293E-7,-0.000101793067759463,-6.24214009323407E-7,149.9919434,149.9919434,40357.23046875,40362.5703125,57.1370447557753,20.6346259912623,23.668306,0,0,0,40,4449,149.8091,40359.900390625,,,,,,,,,,,,,0,,,,0.0049,,,,,,149.9919434,,,,
,27337433.32,149.9890747,35509.708984375,-8.30006651397294E-5,2.3832244710895E-6,1,0.999253354069792,40.0298881530762,1.98327847512027,21.3699992746115,-0.000933420805210847,-0.000182905967543373,0.25,-1.74636123631783E-6,-8.34049482174403E-5,-1.88586393145602E-6,149.9890747,149.9890747,35504.53125,35514.88671875,56.7821854080445,20.6331529933164,23.668306,0,0,0,40,4449,149.81715,35509.708984375,,,,,,,,,,,,,0,,,,-0.0049,,,,,,149.9890747,,,,
,27337528.32,149.9899139,30759.4482421875,-6.55106343418465E-5,2.06634243406179E-6,1,0.999253354069792,40.0298881530762,1.98321101803562,21.3699992746115,-0.000737364845976932,-0.000140566200185724,0.25,-1.04204689632796E-6,-6.58301863979206E-5,-1.1507978066254E-6,149.9899139,149.9899139,30751.94140625,30766.955078125,57.0049495360253,20.6333624015925,23.668306,0,0,0,40,4449,149.82595,30759.4482421875,,,,,,,,,,,,,0,,,,-0.00245,,,,,,149.9899139,,,,
,27337624.095,149.9910431,25972.15234375,-4.86148764002656E-5,1.55941485548566E-6,1,0.999253354069792,40.0298881530762,1.98321519864574,21.3699992746115,-0.000544128408690695,-0.000121902972268958,0.25,-2.33151457596479E-6,-4.88494900517959E-5,-2.42006729370523E-6,149.9910431,149.9910431,25969.853515625,25974.451171875,56.6977695279675,20.6357549799867,24.047956,0,0,0,40,4449,149.8386,25972.15234375,,,,,,,,,,,,,0,,,,0,,,,,,149.9910431,,,,
,27337719.835,149.9878387,21189.263671875,-3.33285560377833E-5,1.55840755275251E-6,1,0.999253354069792,40.0298881530762,1.98317546724531,21.3699992746115,-0.000375764615645198,-6.7854202896317E-5,0.25,-2.05798306259429E-7,-3.34915786588435E-5,-2.59822353533679E-7,149.9878387,149.9878387,21176.673828125,21201.853515625,56.8837971155445,20.6341042784799,24.047956,0,0,0,40,4449,149.84735,21189.263671875,,,,,,,,,,,,,0,,,,0,,,,,,149.9878387,,,,
,27337815.245,149.9922028,16419.80859375,-1.73052856165799E-5,1.45309566884063E-6,1,0.999253354069792,40.0298881530762,1.98312417687673,21.3799998164177,-0.000194547056541218,-3.84302304117752E-5,0.25,-3.90224442492524E-7,-1.73894621607033E-5,-4.1973540920388E-7,149.9922028,149.9922028,16414.78515625,16424.83203125,56.902556200006,20.6343715426514,23.668306,0,0,0,40,4449,149.8532,16419.80859375,,,,,,,,,,,,,0,,,,0,,,,,,149.9922028,,,,
,27337911.795,149.991745,11595.021484375,-1.36347187284355E-6,7.32836008479947E-7,1,0.999253354069792,40.0298881530762,1.98306508730023,21.3699992746115,-1.39571480386929E-5,-1.08952648143162E-5,0.25,-7.27835803159515E-7,-1.36898835488696E-6,-7.3358152515243E-7,149.991745,149.991745,11587.517578125,11602.525390625,57.0088576786214,20.6407246352839,23.668306,0,0,0,40,4449,149.862,11595.021484375,,,,,,,,,,,,,0,,,,-0.00245,,,,,,149.991745,,,,
,27338008.045,149.9913025,6784.88305664062,1.26238744485035E-5,7.42828139570199E-7,1,0.999253354069792,40.0298881530762,1.98312904514898,21.3699992746115,0.000143733577446618,1.76153902402741E-5,0.25,-6.38557629544826E-7,1.26867362036092E-5,-6.21457982966988E-7,149.9913025,149.9913025,6780.09912109375,6789.6669921875,56.0857543974098,20.6386539632364,23.668306,0,0,0,40,4449,149.86915,6784.88305664062,,,,,,,,,,,,,0,,,,0,,,,,,149.9913025,,,,
,27338103.035,149.9921417,2034.42150878906,2.43976735937098E-5,4.18714711877371E-7,1,0.999253354069792,40.0298881530762,1.98313211922257,21.3699992746115,0.000276231899431274,4.29796528688658E-5,0.25,-4.42526269883747E-7,2.4517879801833E-5,-4.05525109974967E-7,149.9921417,149.9921417,2031.72021484375,2037.12280273438,56.9361662263329,20.6379028472558,23.668306,0,0,0,40,4449,149.8738,2034.42150878906,,,,,,,,,,,,,0,,,,0,,,,,,149.9921417,,,,
,27338143.925,149.9927292,-0.342534884810448,2.82464967733389E-5,3.51031115449022E-7,1,0.999253354069792,40.0298881530762,1.98325190667104,21.3699992746115,0.000320445763518991,4.62105419217422E-5,0.25,-8.27074559294335E-7,2.83861658055838E-5,-7.85751823761746E-7,149.9927063,149.9927521,-0.365370541810989,-0.319699227809906,57.2394380917945,20.6368901970369,24.047956,0,0,0,40,4417,149.87775,-0.342534884810448,,,,,,,,,,,,,0,,,,-0.0049,,,,,,149.9927292,,,,