File: data/monolayers/nanoparticles/Ac_CoFe_C/vsm/data_disorderedWafer/DD226_2_FCC_100OE.DAT
[Header]
; VSM Data File (default extension .dat)
; Copyright (c) 2003-2013, Quantum Design, Inc. All rights reserved.
TITLE,
FILEOPENTIME,27393661.97,11/14/2018,9:21 am
BYAPP,VSM,2.0,2.0
INFO,PPMS VSM Option Release 1.4.10 Build 1,APPNAME
INFO,Quantum Design Linear Motor Servo Controller,MOTOR_MODULE_NAME
INFO,3101-100 M1,MOTOR_HW_VERSION
INFO,MMC1014,MOTOR_SERIAL_NUMBER
INFO,SRV No X-over 01.03.11,MOTOR_SOFTWARE_VERSION
INFO,Quantum Design VSM Detection Module,VSM_MODULE_NAME
INFO,3101-150 F0,VSM_HW_VERSION
INFO,VSM707,VSM_SERIAL_NUMBER
INFO,VSM No X-over 01.02.05 May 20 2008 13:51:47,VSM_SOFTWARE_VERSION
INFO,704,PREAMP_SERIAL_NUMBER
INFO,822,COIL_SERIAL_NUMBER
INFO,0,MOMENT_UNITS
INFO,CoFe2O4 AH11,SAMPLE_MATERIAL
INFO,Quick Dry Monolayer Conc,SAMPLE_COMMENT
INFO,27.96,SAMPLE_MASS
INFO,,SAMPLE_VOLUME
INFO,,SAMPLE_MOLECULAR_WEIGHT
INFO,,SAMPLE_SIZE
INFO,,SAMPLE_SHAPE
DATATYPE,COMMENT,1
DATATYPE,TIME,2
STARTUPAXIS,X,2
STARTUPAXIS,Y1,5
[Data]
Comment,Time Stamp (sec),Temperature (K),Magnetic Field (Oe),Moment (emu),M. Std. Err. (emu),Transport Action,Averaging Time (sec),Frequency (Hz),Peak Amplitude (mm),Center Position (mm),Coil Signal' (mV),Coil Signal" (mV),Range (mV),M. Quad. Signal (emu),M. Raw' (emu),M. Raw" (emu),Min. Temperature (K),Max. Temperature (K),Min. Field (Oe),Max. Field (Oe),Mass (grams),Motor Lag (deg),Pressure (Torr),VSM Status (code),Motor Status (code),Measure Status (code),Measure Count,PPMS Status (code),System Temp. (K),System Field (Oe),Sample Position (deg),Bridge 1 Resistance (ohms),Bridge 1 Excitation (에),Bridge 2 Resistance (ohms),Bridge 2 Excitation (에),Bridge 3 Resistance (ohms),Bridge 3 Excitation (에),Bridge 4 Resistance (ohms),Bridge 4 Excitation (에),Signal 1 Vin (V),Signal 2 Vin (V),Digital Inputs (code),Drive 1 Iout (mA),Drive 1 Ipower (W),Drive 2 Iout (mA),Drive 2 Ipower (W),Pressure (),Map 20 (),Map 21 (),Map 22 (),Map 23 (),Map 24 (),Map 25 (),Map 26 (),Map 27 (),Map 28 (),Map 29 ()
,27393825.87,349.6410828,99.7004928588867,7.17461432902045E-6,4.89534507512048E-7,1,0.999253354069792,40.0298881530762,2.00904311523434,20.3200001269579,8.15156755290242E-5,1.37620467918047E-5,0.25,-3.01474942965062E-8,7.16199778363728E-6,-2.60954043870416E-8,349.6410828,349.6410828,99.7004928588867,99.7004928588867,56.7454488676406,20.5918982726947,27.464817,0,0,0,40,4369,350.24455,99.7004928588867,,,,,,,,,,,,,0,,,,0.0049,,,,,,349.6410828,,,,
,27393979.81,346.9811401,99.7004928588867,6.94202206354118E-6,4.42728641393766E-7,1,0.999253354069792,40.0298881530762,2.00896156162807,20.3200001269579,7.92911984453798E-5,1.09248917600492E-5,0.25,-2.39875334112293E-7,6.93055491664845E-6,-2.35546811658249E-7,346.9811401,346.9811401,99.7004928588867,99.7004928588867,56.7821854080445,20.5924452814824,27.844467,0,0,0,40,4374,345.1274,99.7004928588867,,,,,,,,,,,,,0,,,,0.00245,,,,,,346.9811401,,,,
,27394130.68,343.4445496,99.7004928588867,6.67102357355925E-6,5.06120684931897E-7,1,0.999253354069792,40.0298881530762,2.00891501117719,20.3200001269579,7.67787577529593E-5,7.17669131214306E-6,0.25,-5.23178259650873E-7,6.66097340810261E-6,-5.18547495564884E-7,343.4445496,343.4445496,99.7004928588867,99.7004928588867,56.8978664288906,20.5999013977904,27.085165,0,0,0,40,4374,341.27525,99.7004928588867,,,,,,,,,,,,,0,,,,-0.00245,,,,,,343.4445496,,,,
,27394273.665,339.9959412,99.7004928588867,7.65839077440697E-6,4.09352471324826E-7,1,0.999253354069792,40.0298881530762,2.00911700351956,20.3200001269579,8.76228005191046E-5,1.13516570069225E-5,0.25,-3.26749209717657E-7,7.64759981225618E-6,-3.21844939177307E-7,339.9959412,339.9959412,99.7004928588867,99.7004928588867,56.8048526351022,20.6091857991733,27.464817,0,0,0,40,4374,337.5928,99.7004928588867,,,,,,,,,,,,,0,,,,0,,,,,,339.9959412,,,,
,27394418.61,336.4953003,99.7004928588867,6.68259118758588E-6,4.89807453729465E-7,1,0.999253354069792,40.0298881530762,2.00946848765234,20.3300006687641,7.62953010510603E-5,1.09761003117522E-5,0.25,-1.91157605898298E-7,6.67392491637702E-6,-1.86988383922188E-7,336.4953003,336.4953003,99.7004928588867,99.7004928588867,56.9306948266983,20.6036014077172,27.464817,0,0,0,40,4374,333.8559,99.7004928588867,,,,,,,,,,,,,0,,,,0.0049,,,,,,336.4953003,,,,
touchdown = 13.9100002124906 mm,27394562.26,332.9389343,99.7004928588867,7.12652813547884E-6,5.12820960953707E-7,1,0.999253354069792,40.0298881530762,2.00959404823385,20.2900003641844,8.11070154134837E-5,1.32755652943102E-5,0.25,-6.58987771259016E-8,7.11808033995813E-6,-6.15907241808513E-8,332.9389343,332.9389343,99.7004928588867,99.7004928588867,56.5836517641598,20.6051168331816,28.224119,0,0,0,40,4374,330.22985,99.7004928588867,,,,,,,,,,,,,0,,,,0.00245,,,,,,332.9389343,,,,
,27394703.125,329.4597473,99.7004928588867,7.23695764313165E-6,4.52805373783771E-7,1,0.999253354069792,40.0298881530762,2.00965431143514,20.2900003641844,8.26615238570336E-5,1.18354524618396E-5,0.25,-2.11971942990463E-7,7.22933973546442E-6,-2.07396569345233E-7,329.4597473,329.4597473,99.7004928588867,99.7004928588867,57.0729512171983,20.6040369623309,27.844467,0,0,0,40,4374,326.63905,99.7004928588867,,,,,,,,,,,,,0,,,,0.0049,,,,,,329.4597473,,,,
,27394846.36,325.9359741,99.7004928588867,7.74477486153163E-6,4.94636584345237E-7,1,0.999253354069792,40.0298881530762,2.00939499233178,20.2900003641844,8.80488335495242E-5,1.50507226578764E-5,0.25,-1.70603012917589E-8,7.73744720603094E-6,-1.23308198478152E-8,325.9359741,325.9359741,99.7004928588867,99.7004928588867,56.9986965078714,20.5990311943117,27.844467,0,0,0,40,4374,323.0209,99.7004928588867,,,,,,,,,,,,,0,,,,0,,,,,,325.9359741,,,,
touchdown = 13.9199998229742 mm,27394982.1,322.6124268,99.7004928588867,7.67406376679625E-6,3.46519248490761E-7,1,0.999253354069792,40.0298881530762,2.00924633908064,20.3000009059906,8.83649525946581E-5,8.47089051127991E-6,0.25,-5.83887803869975E-7,7.66804462665811E-6,-5.78674445032466E-7,322.6124268,322.6124268,99.7004928588867,99.7004928588867,56.7618630665445,20.6105717313112,27.464817,0,0,0,40,4374,319.60415,99.7004928588867,,,,,,,,,,,,,0,,,,0.0049,,,,,,322.6124268,,,,
,27395107.51,319.4801941,99.7004928588867,7.14350131663141E-6,4.70965574412369E-7,1,0.999253354069792,40.0298881530762,2.00925147358862,20.3000009059906,8.17383622037452E-5,1.09261684040122E-5,0.25,-2.76108243438207E-7,7.13852110751058E-6,-2.71456877177801E-7,319.4801941,319.4801941,99.7004928588867,99.7004928588867,56.9799374234099,20.6077837425632,28.224119,0,0,0,40,4374,316.4537,99.7004928588867,,,,,,,,,,,,,0,,,,-0.0049,,,,,,319.4801941,,,,
,27395247.75,315.9786377,99.7004928588867,7.11480236948543E-6,4.2308099103844E-7,1,0.999253354069792,40.0298881530762,2.00909682430009,20.3000009059906,8.07829465532711E-5,1.45261909772391E-5,0.25,4.54707873940569E-8,7.11051968904881E-6,4.99361718501525E-8,315.9786377,315.9786377,99.7004928588867,99.7004928588867,56.8071975206598,20.6055014092691,27.464817,0,0,0,40,4374,312.9539,99.7004928588867,,,,,,,,,,,,,0,,,,0,,,,,,315.9786377,,,,
touchdown = 13.9300003647804 mm,27395403.625,312.1374512,99.7004928588867,8.10744881816966E-6,3.97112760529338E-7,1,0.999253354069792,40.0298881530762,2.00954704417167,20.3099995851517,9.30207991155426E-5,1.11616216278642E-5,0.25,-4.22902754906564E-7,8.10397298952818E-6,-4.17511074673297E-7,312.1374512,312.1374512,99.7004928588867,99.7004928588867,56.7345060683714,20.6007985841332,27.464817,0,0,0,40,4374,309.0286,99.7004928588867,,,,,,,,,,,,,0,,,,0,,,,,,312.1374512,,,,
,27395529.47,308.9875488,99.7004928588867,8.13096740119681E-6,4.94343368856728E-7,1,0.999253354069792,40.0298881530762,1.996734760033,20.3099995851517,9.21353113240093E-5,1.45800678288855E-5,0.25,-1.18701900449213E-7,8.12819444856039E-6,-1.13384566504779E-7,308.9875488,308.9875488,99.7004928588867,99.7004928588867,56.912717370756,20.6020277973398,27.464817,0,0,0,40,4374,305.8466,99.7004928588867,,,,,,,,,,,,,0,,,,-0.0049,,,,,,308.9875488,,,,
,27395671.69,305.4876709,99.7004928588867,7.86787008166694E-6,4.36417566367476E-7,1,0.999253354069792,40.0298881530762,1.99656901768054,20.3099995851517,8.89346611328962E-5,1.53985057581604E-5,0.25,-8.4404757479269E-10,7.86609115184041E-6,4.33282529488378E-9,305.4876709,305.4876709,99.7004928588867,99.7004928588867,56.7681160946983,20.6106356728916,27.844467,0,0,0,40,4374,302.2898,99.7004928588867,,,,,,,,,,,,,0,,,,-0.0049,,,,,,305.4876709,,,,
touchdown = 13.9499995857477 mm,27395820.975,301.7775574,99.7004928588867,7.88863467402246E-6,4.61031521425841E-7,1,0.999253354069792,40.0298881530762,2.00934039858418,20.3300006687641,9.04625063884141E-5,1.12806581072364E-5,0.25,-3.75007682328065E-7,7.88814304863039E-6,-3.69703944536686E-7,301.7775574,301.7775574,99.7004928588867,99.7004928588867,56.5953761919483,20.6036326865311,27.844467,0,0,0,40,4374,298.5374,99.7004928588867,,,,,,,,,,,,,0,,,,0,,,,,,301.7775574,,,,
,27395954.47,298.4802551,99.7004928588867,8.60054734840645E-6,4.06128889039201E-7,1,0.999253354069792,40.0298881530762,1.99634571303096,20.3200001269579,9.75011142468588E-5,1.52725099963404E-5,0.25,-1.3928638989696E-7,8.60084410558028E-6,-1.33467261068261E-7,298.4802551,298.4802551,99.7004928588867,99.7004928588867,56.7102755842752,20.6134024017883,27.844467,0,0,0,40,4374,295.177,99.7004928588867,,,,,,,,,,,,,0,,,,0.00245,,,,,,298.4802551,,,,
,27396096.155,294.9669495,99.7004928588867,8.05571311129908E-6,4.22135167487536E-7,1,0.999253354069792,40.0298881530762,1.9964733782398,20.3200001269579,9.10118863668972E-5,1.62103524178554E-5,0.25,3.77318483774017E-8,8.05688784649806E-6,4.32706717039491E-8,294.9669495,294.9669495,99.7004928588867,99.7004928588867,56.8939582862945,20.6101309649609,28.224119,0,0,0,40,4374,291.6367,99.7004928588867,,,,,,,,,,,,,0,,,,0.0049,,,,,,294.9669495,,,,
touchdown = 13.9699997380376 mm,27396241.8,291.3273315,99.7004928588867,8.67384744124854E-6,3.76646971784391E-7,1,0.999253354069792,40.0298881530762,1.97148569934407,20.3600004315376,9.71374581460012E-5,1.55085125615613E-5,0.25,-1.15121646846354E-7,8.67634954098898E-6,-1.09104645336857E-7,291.3273315,291.3273315,99.7004928588867,99.7004928588867,56.4077853473329,20.611999690859,27.464817,0,0,0,40,4374,287.9707,99.7004928588867,,,,,,,,,,,,,0,,,,-0.0049,,,,,,291.3273315,,,,
,27396377.69,287.9761047,99.7004928588867,8.45600585910015E-6,3.76556682547205E-7,1,0.999253354069792,40.0298881530762,1.98527012573908,20.3499998897314,9.61938694553366E-5,1.03063064624221E-5,0.25,-5.49284654633876E-7,8.45976963801183E-6,-5.43521704276573E-7,287.9761047,287.9761047,99.7004928588867,99.7004928588867,56.4101302328906,20.6107687885044,27.464817,0,0,0,40,4374,284.5696,99.7004928588867,,,,,,,,,,,,,0,,,,-0.00245,,,,,,287.9761047,,,,
,27396517.22,284.4960632,99.7004928588867,8.87769753236594E-6,4.19321349879666E-7,1,0.999253354069792,40.0298881530762,1.98544110180228,20.3499998897314,0.000100696107183607,1.26446365962201E-5,0.25,-4.14825549615373E-7,8.88264518270549E-6,-4.08668116455247E-7,284.4960632,284.4960632,99.7004928588867,99.7004928588867,56.5656743082175,20.6131380282176,27.844467,0,0,0,40,4374,281.07575,99.7004928588867,,,,,,,,,,,,,0,,,,0.00245,,,,,,284.4960632,,,,
touchdown = 13.9899998903275 mm,27396660.865,280.9087219,99.7004928588867,8.36811319864765E-6,3.6525735348862E-7,1,0.999253354069792,40.0298881530762,2.00929398353963,20.3699991106987,9.535608550176E-5,1.58670959093313E-5,0.25,-5.63572596359162E-8,8.37361224084745E-6,-5.02912764933261E-8,280.9087219,280.9087219,99.7004928588867,99.7004928588867,56.5312826533714,20.6030680319021,27.844467,0,0,0,40,4374,277.4804,99.7004928588867,,,,,,,,,,,,,0,,,,0,,,,,,280.9087219,,,,
,27396798,277.4763184,99.7004928588867,8.61849964712976E-6,3.67976548010537E-7,1,0.999253354069792,40.0298881530762,2.00909392019851,20.3699991106987,9.82005605541455E-5,1.64084645005985E-5,0.25,-5.2326018221912E-8,8.6252188529646E-6,-4.59866702799703E-8,277.4763184,277.4763184,99.7004928588867,99.7004928588867,56.8744175733137,20.6052038534181,28.224119,0,0,0,40,4374,274.06325,99.7004928588867,,,,,,,,,,,,,0,,,,0,,,,,,277.4763184,,,,
,27396940.315,273.9516296,99.7004928588867,8.55087430674676E-6,4.68461951318312E-7,1,0.999253354069792,40.0298881530762,2.00886389725773,20.3699991106987,9.77564112915442E-5,1.44066881078961E-5,0.25,-2.16594616718737E-7,8.55874363533109E-6,-2.10359465964353E-7,273.9516296,273.9516296,99.7004928588867,99.7004928588867,56.9002113144483,20.6057725717285,27.844467,0,0,0,40,4374,270.50265,99.7004928588867,,,,,,,,,,,,,0,,,,0,,,,,,273.9516296,,,,
touchdown = 14.019999653101 mm,27397078.28,270.500824,99.7004928588867,8.4372103281646E-6,4.51048136602868E-7,1,0.999253354069792,40.0298881530762,1.98464498251014,20.4000007361174,9.58904451806088E-5,1.09852089165537E-5,0.25,-4.86468406573947E-7,8.44622673063428E-6,-4.80522542222479E-7,270.500824,270.500824,99.7004928588867,99.7004928588867,56.933039712256,20.6077630174726,28.224119,0,0,0,40,4374,267.03275,99.7004928588867,,,,,,,,,,,,,0,,,,0,,,,,,270.500824,,,,
,27397199.5,267.4868164,99.7004928588867,9.08090459899412E-6,3.50885202507065E-7,1,0.999253354069792,40.0298881530762,1.9848002453564,20.4000007361174,0.000101766740100041,2.02366757059999E-5,0.25,2.23671826471729E-7,9.09101310468035E-6,2.3095671961449E-7,267.4868164,267.4868164,99.7004928588867,99.7004928588867,56.8673829166406,20.6101788004046,27.844467,0,0,0,40,4374,264.0109,99.7004928588867,,,,,,,,,,,,,0,,,,-0.00245,,,,,,267.4868164,,,,
,27397340.305,263.9543457,99.7004928588867,8.76036052050134E-6,4.0737827238652E-7,1,0.999253354069792,40.0298881530762,1.98458558380502,20.4000007361174,9.9795792229999E-5,1.01846323495384E-5,0.25,-6.14024716953352E-7,8.77186591890662E-6,-6.07903165509419E-7,263.9543457,263.9543457,99.7004928588867,99.7004928588867,57.1354814987368,20.6161277342081,27.844467,0,0,0,40,4374,260.48465,99.7004928588867,,,,,,,,,,,,,0,,,,0,,,,,,263.9543457,,,,
,27397479.67,260.5359802,99.7004928588867,,,2,,,,20.4400003471971,,,,,,,260.5359802,260.5359802,99.7004928588867,99.7004928588867,,,28.224119,,,,-99999999,4374,257.0121,99.7004928588867,,,,,,,,,,,,,,,,,,,,,,,260.5359802,,,,
,27397602.295,257.4403381,99.7004928588867,8.90776729538692E-6,3.48522140107598E-7,1,0.999253354069792,40.0298881530762,2.00898729960699,20.4300004988909,0.00010226754919349,1.29127988853452E-5,0.25,-4.10970447530659E-7,8.92137114410925E-6,-4.04354419362106E-7,257.4403381,257.4403381,99.7004928588867,99.7004928588867,57.1573670972753,20.6082449690717,28.224119,0,0,0,40,4374,253.93285,99.7004928588867,,,,,,,,,,,,,0,,,,0,,,,,,257.4403381,,,,
,27397742.34,253.9324188,99.7004928588867,9.26188201889991E-6,3.80379693173728E-7,1,0.999253354069792,40.0298881530762,2.00900611019283,20.4300004988909,0.0001057319633901,1.69757782466652E-5,0.25,-1.15974190248524E-7,9.27692656295491E-6,-1.08519526029531E-7,253.9324188,253.9324188,99.7004928588867,99.7004928588867,56.9095908566791,20.6096232555353,28.224119,0,0,0,40,4374,250.4413,99.7004928588867,,,,,,,,,,,,,0,,,,0,,,,,,253.9324188,,,,
,27397896.94,250.11409,99.7004928588867,,,2,,,,20.4700001099706,,,,,,,250.11409,250.11409,99.7004928588867,99.7004928588867,,,28.224119,,,,-99999999,4374,246.5665,99.7004928588867,,,,,,,,,,,,,,,,,,,,,,,250.11409,,,,
,27398020.795,246.9910126,99.7004928588867,9.09658496276163E-6,3.73888086750616E-7,1,0.999253354069792,40.0298881530762,1.98497889662493,20.4600002616644,0.000103418712402702,1.22531301360024E-5,0.25,-4.90001127566902E-7,9.113911434504E-6,-4.83146916654389E-7,246.9593201,247.0227051,99.7004928588867,99.7004928588867,57.0018230219483,20.6109580465342,27.844467,0,0,0,40,4374,243.46585,99.7004928588867,,,,,,,,,,,,,0,,,,0.00245,,,,,,246.9910126,,,,
,27398160.325,243.4939423,99.7004928588867,9.1872253023497E-6,3.52936630252298E-7,1,0.999253354069792,40.0298881530762,1.98503977492352,20.4600002616644,0.00010486206952207,1.00888685568267E-5,0.25,-6.98141518935189E-7,9.20603504653921E-6,-6.91544927232669E-7,243.4939423,243.4939423,99.7004928588867,99.7004928588867,56.8666012881214,20.6114956033893,27.844467,0,0,0,40,4374,239.9784,99.7004928588867,,,,,,,,,,,,,0,,,,0,,,,,,243.4939423,,,,
,27398311.22,239.7477417,99.7004928588867,,,2,,,,20.5100004145503,,,,,,,239.7477417,239.7477417,99.7004928588867,99.7004928588867,,,28.224119,,,,-99999999,4374,236.2105,99.7004928588867,,,,,,,,,,,,,,,,,,,,,,,239.7477417,,,,
,27398441.145,236.4478912,99.7004928588867,9.39741377879792E-6,3.34536527773784E-7,1,0.999253354069792,40.0298881530762,2.00911414097085,20.5000005662441,0.000107701118232128,1.52143459121385E-5,0.25,-2.95700878025656E-7,9.4186068271693E-6,-2.8789897091966E-7,236.4478912,236.4478912,99.7004928588867,99.7004928588867,57.1323549846599,20.6084664833871,27.844467,0,0,0,40,4374,232.9552,99.7004928588867,,,,,,,,,,,,,0,,,,-0.0049,,,,,,236.4478912,,,,
,27398581.925,232.9790039,99.7004928588867,9.33957303289147E-6,3.24243375426116E-7,1,0.999253354069792,40.0298881530762,2.00910174575854,20.5000005662441,0.000107046142106131,1.51473116298405E-5,0.25,-2.91853527877436E-7,9.36175891766105E-6,-2.839736708519E-7,232.9790039,232.9790039,99.7004928588867,99.7004928588867,57.2644502044099,20.6122878020293,27.844467,0,0,0,40,4374,229.4332,99.7004928588867,,,,,,,,,,,,,0,,,,0,,,,,,232.9790039,,,,
,27398730.2,229.2518311,99.7004928588867,,,2,,,,20.5499997878075,,,,,,,229.2518311,229.2518311,99.7004928588867,99.7004928588867,,,28.224119,,,,-99999999,4374,225.7284,99.7004928588867,,,,,,,,,,,,,,,,,,,,,,,229.2518311,,,,
,27398861.71,225.9621887,99.7004928588867,9.60325381754515E-6,4.20851512370236E-7,1,0.999253354069792,40.0298881530762,2.00921079114154,20.5400008708239,0.00011001666255577,1.60630862043786E-5,0.25,-2.58021435121543E-7,9.62834779003939E-6,-2.49545148455773E-7,225.9621887,225.9621887,99.7004928588867,99.7004928588867,57.241001348833,20.6125019890182,27.844467,0,0,0,40,4374,222.4447,99.7004928588867,,,,,,,,,,,,,0,,,,0.0049,,,,,,225.9621887,,,,
,27398999.54,222.4747162,99.7004928588867,9.73712978863884E-6,4.1123503638538E-7,1,0.999253354069792,40.0298881530762,2.00919319706189,20.5400008708239,0.000111459460020578,1.68835069806922E-5,0.25,-2.09648956512062E-7,9.76368205693731E-6,-2.00766240363005E-7,222.4747162,222.4747162,99.7004928588867,99.7004928588867,57.251162519583,20.6112742343428,27.464817,0,0,0,40,4374,218.9951,99.7004928588867,,,,,,,,,,,,,0,,,,0,,,,,,222.4747162,,,,
,27399144.81,218.8847656,99.7004928588867,,,2,,,,20.5900000923872,,,,,,,218.8847656,218.8847656,99.7004928588867,99.7004928588867,,,28.224119,,,,-99999999,4374,215.3633,99.7004928588867,,,,,,,,,,,,,,,,,,,,,,,218.8847656,,,,
,27399280.095,215.489151,99.7004928588867,9.87699551365892E-6,3.4126562717645E-7,1,0.999253354069792,40.0298881530762,2.00888247597573,20.5799993127584,0.000112502549676666,2.03982141065263E-5,0.25,7.37258745232712E-8,9.90596816346433E-6,8.39186303221608E-8,215.489151,215.489151,99.7004928588867,99.7004928588867,57.0385595623522,20.6165598518397,27.464817,0,0,0,40,4374,211.9981,99.7004928588867,,,,,,,,,,,,,0,,,,0,,,,,,215.489151,,,,
,27399420.43,211.9510803,99.7004928588867,9.84964361992097E-6,4.03923303947444E-7,1,0.999253354069792,40.0298881530762,2.00883609071087,20.5799993127584,0.000112684420288833,1.75634256992988E-5,0.25,-1.70431973988075E-7,9.8799445028296E-6,-1.60797475536522E-7,211.9510803,211.9510803,99.7004928588867,99.7004928588867,57.3269804859484,20.620381556393,27.464817,0,0,0,40,4374,208.4924,99.7004928588867,,,,,,,,,,,,,0,,,,0.00245,,,,,,211.9510803,,,,
,27399560.25,208.4770813,99.7004928588867,,,2,,,,20.6300003969669,,,,,,,208.4770813,208.4770813,99.7004928588867,99.7004928588867,,,27.844467,,,,-99999999,4374,204.9993,99.7004928588867,,,,,,,,,,,,,,,,,,,,,,,208.4770813,,,,
,27399677.88,205.4877777,99.7004928588867,9.82274056009222E-6,3.89479653162743E-7,1,0.999253354069792,40.0298881530762,2.00884193095195,20.6199996173382,0.000112381520802154,1.76302696026515E-5,0.25,-1.60633262184418E-7,9.85504014080327E-6,-1.50626658560131E-7,205.4877777,205.4877777,99.7004928588867,99.7004928588867,57.1018714724099,20.618796742319,27.844467,0,0,0,40,4374,202.0597,99.7004928588867,,,,,,,,,,,,,0,,,,0.00245,,,,,,205.4877777,,,,
,27399820.96,201.9455261,99.7004928588867,9.52973138648401E-6,3.66035043955511E-7,1,0.999253354069792,40.0298881530762,2.00879931106929,20.6199996173382,0.000108341425834148,2.11248973709135E-5,0.25,1.96168747081656E-7,9.56177834619001E-6,2.07282801924289E-7,201.9455261,201.9455261,99.7004928588867,99.7004928588867,57.1604936113522,20.6221023021238,27.464817,0,0,0,40,4374,198.4882,99.7004928588867,,,,,,,,,,,,,0,,,,-0.0049,,,,,,201.9455261,,,,
,27399958.5,198.4552155,99.7004928588867,1.00291124475177E-5,4.07798661033204E-7,1,0.999253354069792,40.0298881530762,2.0085255698945,20.6199996173382,0.000114919428656189,1.70348285144878E-5,0.25,-2.49268968336523E-7,1.00644674147309E-5,-2.38897533458808E-7,198.4552155,198.4552155,99.7004928588867,99.7004928588867,57.0127658212176,20.6239254356462,27.085165,0,0,0,40,4374,195.06235,99.7004928588867,,,,,,,,,,,,,0,,,,0,,,,,,198.4552155,,,,
,27400077.945,195.4835968,99.7004928588867,9.22385654688671E-6,3.25990988103787E-7,1,0.999253354069792,40.0298881530762,2.00859109697404,20.6599999219179,0.000106083855319272,1.34921243000658E-5,0.25,-4.20237746794357E-7,9.25746593421161E-6,-4.11200328909153E-7,195.4835968,195.4835968,99.7004928588867,99.7004928588867,56.7868751791599,20.6225588866006,27.464817,0,0,0,40,4374,192.0705,99.7004928588867,,,,,,,,,,,,,0,,,,0,,,,,,195.4835968,,,,
,27400220.665,191.9340515,99.7004928588867,9.57720922803032E-6,3.62398558007277E-7,1,0.999253354069792,40.0298881530762,2.00838444276602,20.6599999219179,0.000109880764532899,1.55546552915614E-5,0.25,-3.01164516446972E-7,9.61302675905722E-6,-2.91060035277807E-7,191.9340515,191.9340515,99.7004928588867,99.7004928588867,57.0893654161022,20.6226027481288,27.464817,0,0,0,40,4374,188.48675,99.7004928588867,,,,,,,,,,,,,0,,,,0.00245,,,,,,191.9340515,,,,
,27400360.82,188.4317474,99.7004928588867,9.91271778769436E-6,3.82933082917599E-7,1,0.999253354069792,40.0298881530762,2.00855185244744,20.6599999219179,0.000113067712171317,2.00370573651783E-5,0.25,3.27384256324197E-8,9.95046172351301E-6,4.47628821536757E-8,188.4317474,188.4317474,99.7004928588867,99.7004928588867,57.1651833824676,20.6241701165143,27.085165,0,0,0,40,4374,184.9802,99.7004928588867,,,,,,,,,,,,,0,,,,0,,,,,,188.4317474,,,,
,27400499.94,184.9646912,99.7004928588867,9.81090992978999E-6,3.41410726031522E-7,1,0.999253354069792,40.0298881530762,2.0082474103431,20.7199994474649,0.000111480583628472,2.22552270082428E-5,0.25,2.44574168768768E-7,9.84904468999023E-6,2.57605282396234E-7,184.9646912,184.9646912,99.7004928588867,99.7004928588867,57.3684067974676,20.6170897061067,27.085165,0,0,0,40,4374,181.51905,99.7004928588867,,,,,,,,,,,,,0,,,,-0.0049,,,,,,184.9646912,,,,
,27400640.665,181.4978943,99.7004928588867,9.8183541209822E-6,4.06766016561606E-7,1,0.999253354069792,40.0298881530762,2.00841915502674,20.7199994474649,0.000113138170771642,1.33479181948197E-5,0.25,-5.37758472715598E-7,9.8585228273495E-6,-5.27513635975932E-7,181.4978943,181.4978943,99.7004928588867,99.7004928588867,57.1432977839291,20.6185038655785,27.464817,0,0,0,40,4374,177.9127,99.7004928588867,,,,,,,,,,,,,0,,,,-0.00245,,,,,,181.4978943,,,,
,27400779.135,177.9469681,99.7004928588867,9.65694735362815E-6,3.39619232696127E-7,1,0.999253354069792,40.0298881530762,2.00858052050455,20.7199994474649,0.000110611612921555,1.70818300684485E-5,0.25,-1.83160962727634E-7,9.69704563567885E-6,-1.71395081567418E-7,177.9181824,177.9757538,99.7004928588867,99.7004928588867,57.0424677049483,20.6242383960681,27.464817,0,0,0,40,4374,174.5263,99.7004928588867,,,,,,,,,,,,,0,,,,0,,,,,,177.9469681,,,,
,27400916.165,174.4939804,99.7004928588867,9.921905725308E-6,3.60040290191276E-7,1,0.999253354069792,40.0298881530762,1.9844130246859,20.7700002938509,0.000113374140231975,1.14764988350895E-5,0.25,-7.08994386198107E-7,9.96480602390872E-6,-6.98781348663459E-7,174.4655304,174.5224304,99.7004928588867,99.7004928588867,57.1831608384099,20.6296931728347,26.705515,0,0,0,40,4374,171.1409,99.7004928588867,,,,,,,,,,,,,0,,,,-0.00245,,,,,,174.4939804,,,,
,27401056.67,170.9671936,99.7004928588867,9.80788870079394E-6,3.24348597347556E-7,1,0.999253354069792,40.0298881530762,1.98425470974881,20.7700002938509,0.00011140242868948,1.52070897021765E-5,0.25,-3.59029307686657E-7,9.85084751930736E-6,-3.47150277337519E-7,170.9671936,170.9671936,99.7004928588867,99.7004928588867,57.3652802833907,20.6243983749401,26.705515,0,0,0,40,4374,167.64375,99.7004928588867,,,,,,,,,,,,,0,,,,0.00245,,,,,,170.9671936,,,,
,27401195.7,167.4588165,99.7004928588867,9.7335996266237E-6,3.31967502313968E-7,1,0.999253354069792,40.0298881530762,1.98412162833896,20.7700002938509,0.00010970464584227,2.00224729411946E-5,0.25,8.00950389392824E-8,9.77659396976632E-6,9.41719625955535E-8,167.4588165,167.4588165,99.7004928588867,99.7004928588867,57.2730481181214,20.626315552601,26.325863,0,0,0,40,4374,164.18605,99.7004928588867,,,,,,,,,,,,,0,,,,0.00245,,,,,,167.4588165,,,,
,27401335.32,163.9454651,99.7004928588867,9.78451131121985E-6,3.72055624262394E-7,1,0.999253354069792,40.0298881530762,1.98435255051746,20.8299998193979,0.000110760884693888,1.74912362570114E-5,0.25,-1.53766218782463E-7,9.82901554811106E-6,-1.40250048120725E-7,163.9454651,163.9454651,99.7004928588867,99.7004928588867,57.3519925985638,20.6245561481997,26.325863,0,0,0,40,4374,160.7254,99.7004928588867,,,,,,,,,,,,,0,,,,0,,,,,,163.9454651,,,,
,27401474.335,160.4423676,99.7004928588867,9.82062862638339E-6,3.15831000763036E-7,1,0.999253354069792,40.0298881530762,1.98439979946683,20.8299998193979,0.000112089094851894,1.23526041800077E-5,0.25,-6.15815398229867E-7,9.86692230184748E-6,-6.0394638058048E-7,160.4423676,160.4423676,99.7004928588867,99.7004928588867,56.8548768603329,20.6240279931205,26.705515,0,0,0,40,4374,157.2494,99.7004928588867,,,,,,,,,,,,,0,,,,0,,,,,,160.4423676,,,,
,27401612.445,156.9777374,99.7004928588867,9.98300475867249E-6,4.10409808235866E-7,1,0.999253354069792,40.0298881530762,1.98399458144017,20.8299998193979,0.000112839193198701,1.88235597816336E-5,0.25,-7.12538868444453E-8,1.00301445585877E-5,-5.61489578518254E-8,156.9777374,156.9777374,99.7004928588867,99.7004928588867,57.1472059265253,20.6366483950163,25.946213,0,0,0,40,4374,153.80895,99.7004928588867,,,,,,,,,,,,,0,,,,-0.0049,,,,,,156.9777374,,,,
,27401753.71,153.4759979,99.7004928588867,1.00437568162212E-5,3.62928601153266E-7,1,0.999253354069792,40.0298881530762,1.99532039443026,20.889999344945,0.000114747716633153,1.56398907260672E-5,0.25,-3.72013584343918E-7,1.0092564373888E-5,-3.57730552028836E-7,153.4759979,153.4759979,99.7004928588867,99.7004928588867,56.9932251082368,20.6297276808748,25.946213,0,0,0,40,4374,150.27935,99.7004928588867,,,,,,,,,,,,,0,,,,0,,,,,,153.4759979,,,,
,27401891.36,149.9691772,99.7004928588867,9.96405609756225E-6,3.54758144849029E-7,1,0.999253354069792,40.0298881530762,1.9952979835905,20.889999344945,0.000114045982796516,1.43696606841584E-5,0.25,-4.70677277883287E-7,1.00135320064892E-5,-4.56483469634974E-7,149.9691772,149.9691772,99.7004928588867,99.7004928588867,57.4653287338522,20.6254820315301,25.946213,0,0,0,40,4374,146.8485,99.7004928588867,,,,,,,,,,,,,0,,,,0,,,,,,149.9691772,,,,
,27402030.86,146.4919434,99.7004928588867,9.54234077453604E-6,3.10786281663943E-7,1,0.999253354069792,40.0298881530762,1.9953261530372,20.889999344945,0.000108745118193091,1.65439297007032E-5,0.25,-2.06371264861783E-7,9.59012316388407E-6,-1.91024339651653E-7,146.4919434,146.4919434,99.7004928588867,99.7004928588867,56.9220969129868,20.6285443688961,25.566563,0,0,0,40,4374,143.3716,99.7004928588867,,,,,,,,,,,,,0,,,,0.0049,,,,,,146.4919434,,,,
,27402149.96,143.481308,99.7004928588867,9.76079522358339E-6,2.96877647154261E-7,1,0.999253354069792,40.0298881530762,1.98374778487351,20.9500007331371,0.000110139797514353,1.96180425449818E-5,0.25,3.52857126324576E-8,9.80992502262233E-6,5.2752128974469E-8,143.481308,143.481308,99.7004928588867,99.7004928588867,57.017455592333,20.6331464378212,25.946213,0,0,0,40,4374,140.395,99.7004928588867,,,,,,,,,,,,,0,,,,0,,,,,,143.481308,,,,
,27402290.13,139.976944,99.7004928588867,9.66975440636204E-6,3.11673766909615E-7,1,0.999253354069792,40.0298881530762,1.98350367124826,20.9500007331371,0.000109186038152499,1.89874284108858E-5,0.25,-5.28878855465303E-9,9.71924744933267E-6,1.2484233398413E-8,139.976944,139.976944,99.7004928588867,99.7004928588867,57.0604451608906,20.6284610164209,26.325863,0,0,0,40,4374,136.9161,99.7004928588867,,,,,,,,,,,,,0,,,,0,,,,,,139.976944,,,,
,27402430.25,136.4470673,99.7004928588867,9.77852416925357E-6,3.98016913595356E-7,1,0.999253354069792,40.0298881530762,1.98369666448222,20.9500007331371,0.000111522194071886,1.29619130068438E-5,0.25,-5.58880273236303E-7,9.830361722178E-6,-5.43043957402032E-7,136.4470673,136.4470673,99.7004928588867,99.7004928588867,57.484869446833,20.6331726042617,25.566563,0,0,0,40,4374,133.4309,99.7004928588867,,,,,,,,,,,,,0,,,,0.00245,,,,,,136.4470673,,,,
,27402549.615,133.4452667,99.7004928588867,9.92739360992477E-6,2.9354517245007E-7,1,0.999253354069792,40.0298881530762,1.99534474481829,21.0100002586842,0.00011261487194102,2.03761635483566E-5,0.25,6.08696976674403E-8,9.97940539173737E-6,8.09011822110482E-8,133.4452667,133.4452667,99.7004928588867,99.7004928588867,57.1143775287176,20.6226066177865,25.566563,0,0,0,40,4374,130.457,99.7004928588867,,,,,,,,,,,,,0,,,,0,,,,,,133.4452667,,,,
,27402687.07,129.9835739,99.7004928588867,1.00669297988662E-5,3.14735700838124E-7,1,0.999253354069792,40.0298881530762,1.9951854232385,21.0100002586842,0.000114695871336828,1.7803057760029E-5,0.25,-1.90923661047072E-7,1.01208425047406E-5,-1.71085137834325E-7,129.9532776,130.0138702,99.7004928588867,99.7004928588867,57.2863358029484,20.6261554708145,25.186911,0,0,0,40,4374,127.04655,99.7004928588867,,,,,,,,,,,,,0,,,,0.0049,,,,,,129.9835739,,,,
,27402826.12,126.4998932,99.7004928588867,9.66659724543467E-6,3.21288749828213E-7,1,0.999253354069792,40.0298881530762,1.99528864165417,21.0100002586842,0.000110186918225689,1.68683486264785E-5,0.25,-2.04373297796716E-7,9.71900667092913E-6,-1.84531320738861E-7,126.4998932,126.4998932,99.7004928588867,99.7004928588867,57.0080760501022,20.6247984459172,25.566563,0,0,0,40,4374,123.5868,99.7004928588867,,,,,,,,,,,,,0,,,,-0.0049,,,,,,126.4998932,,,,
,27402966.045,122.9844971,99.7004928588867,9.68557527449765E-6,3.53824849058258E-7,1,0.999253354069792,40.0298881530762,2.00767791963395,21.0699997842312,0.000111256456343497,1.58993144333198E-5,0.25,-3.02344658181327E-7,9.73885734934779E-6,-2.819958083697E-7,122.9844971,122.9844971,99.7004928588867,99.7004928588867,57.3770047111791,20.6283205181809,25.566563,0,0,0,40,4374,120.1051,99.7004928588867,,,,,,,,,,,,,0,,,,-0.00245,,,,,,122.9844971,,,,
,27403105.065,119.45544435,99.7004928588867,9.8966376964457E-6,3.01902683267233E-7,1,0.999253354069792,40.0298881530762,2.00768910511676,21.0699997842312,0.00011296779010346,2.03581757062844E-5,0.25,4.9824977325233E-8,9.95073763167665E-6,7.36868261343021E-8,119.4267273,119.4841614,99.7004928588867,99.7004928588867,57.2488176340253,20.6282221641919,25.186911,0,0,0,40,4374,116.6519,99.7004928588867,,,,,,,,,,,,,0,,,,0.0049,,,,,,119.45544435,,,,
,27403243.21,115.9966354,99.7004928588867,1.01994602341754E-5,3.80029459787314E-7,1,0.999253354069792,40.0298881530762,2.00779167770814,21.0699997842312,0.000117199790938175,1.66140290984911E-5,0.25,-3.32276705212802E-7,1.02565693213382E-5,-3.0854450467458E-7,115.9966354,115.9966354,99.7004928588867,99.7004928588867,57.119067299833,20.6274619809398,25.186911,0,0,0,40,4374,113.2246,99.7004928588867,,,,,,,,,,,,,0,,,,0,,,,,,115.9966354,,,,
,27403381.62,112.4666061,99.7004928588867,9.63486217322352E-6,3.03015843599476E-7,1,0.999253354069792,40.0298881530762,1.99525127015191,21.1399998515844,0.000109731481751515,1.74542484441024E-5,0.25,-1.52039293044422E-7,9.68873129216844E-6,-1.27430413354942E-7,112.4666061,112.4666061,99.7004928588867,99.7004928588867,57.4715817620061,20.6239587521591,24.807261,0,0,0,40,4374,109.798,99.7004928588867,,,,,,,,,,,,,0,,,,-0.0049,,,,,,112.4666061,,,,
,27403523.03,108.9378204,99.7004928588867,1.0034942615491E-5,3.30275049509667E-7,1,0.999253354069792,40.0298881530762,1.9951971149981,21.1399998515844,0.000114788989349922,1.53209896658209E-5,0.25,-4.11522689860032E-7,1.00919769167809E-5,-3.85769527459566E-7,108.9378204,108.9378204,99.7004928588867,99.7004928588867,57.3707516830253,20.6296613151453,24.807261,0,0,0,40,4374,106.2806,99.7004928588867,,,,,,,,,,,,,0,,,,0,,,,,,108.9378204,,,,
,27403660.665,105.4594421,99.7004928588867,1.00885207785575E-5,3.0716190007867E-7,1,0.999253354069792,40.0298881530762,1.9952431006939,21.1399998515844,0.000115260515371572,1.62325155224571E-5,0.25,-3.42361049981806E-7,1.01457945504547E-5,-3.14420938828972E-7,105.4594421,105.4594421,99.7004928588867,99.7004928588867,57.322290714833,20.6278931091452,24.427608,0,0,0,40,4374,102.8691,99.7004928588867,,,,,,,,,,,,,0,,,,-0.0049,,,,,,105.4594421,,,,
,27403798.635,101.95755,99.7004928588867,9.80799658542425E-6,3.25895766687895E-7,1,0.999253354069792,40.0298881530762,1.99523358282939,21.2099999189377,0.000111960805843097,1.63168123988236E-5,0.25,-2.87454729398869E-7,9.8635249681422E-6,-2.582412886051E-7,101.95755,101.95755,99.7004928588867,99.7004928588867,57.0354330482753,20.6330840253209,24.427608,0,0,0,40,4374,99.4281,99.7004928588867,,,,,,,,,,,,,0,,,,0,,,,,,101.95755,,,,
,27403937.29,98.438736,99.7004928588867,9.97049373771656E-6,3.44384687311188E-7,1,0.999253354069792,40.0298881530762,1.99490450569151,21.2099999189377,0.000113325387302235,1.92573348462721E-5,0.25,-5.87874656823386E-8,1.00259808519507E-5,-2.57843735144915E-8,98.438736,98.438736,99.7004928588867,99.7004928588867,57.1620568683907,20.6363831032203,24.047956,0,0,0,40,4374,96.0151,99.7004928588867,,,,,,,,,,,,,0,,,,-0.00245,,,,,,98.438736,,,,
,27404074.11,94.9812393,99.7004928588867,9.91428687968769E-6,3.07963961275858E-7,1,0.999253354069792,40.0298881530762,1.99486996787048,21.2099999189377,0.000113297659218941,1.56413818657901E-5,0.25,-3.69472086100412E-7,9.97012694915949E-6,-3.36170426727152E-7,94.9812393,94.9812393,99.7004928588867,99.7004928588867,56.7673344661791,20.6364109426382,24.047956,0,0,0,40,4374,92.6287,99.7004928588867,,,,,,,,,,,,,0,,,,-0.0049,,,,,,94.9812393,,,,
,27404213.855,91.4823685,99.7004928588867,9.6794990395253E-6,2.79749970769469E-7,1,0.999253354069792,40.0298881530762,1.98338372783675,21.2799999862909,0.00010944263548724,1.83397621784955E-5,0.25,-8.37929269299155E-8,9.73232571830358E-6,-4.7318021464952E-8,91.4823685,91.4823685,99.7004928588867,99.7004928588867,57.2136443506599,20.6374358008983,23.668306,0,0,0,40,4374,89.1629,99.7004928588867,,,,,,,,,,,,,0,,,,0,,,,,,91.4823685,,,,
,27404351.86,87.9711609,99.7004928588867,9.98030069149153E-6,3.45369959532753E-7,1,0.999253354069792,40.0298881530762,1.9833671951562,21.2799999862909,0.000112951529385516,1.82271585405408E-5,0.25,-1.49422815330471E-7,1.00339887847893E-5,-1.09386958766553E-7,87.9711609,87.9711609,99.7004928588867,99.7004928588867,56.7587365524675,20.6418733529765,23.668306,0,0,0,40,4374,85.73705,99.7004928588867,,,,,,,,,,,,,0,,,,-0.0049,,,,,,87.9711609,,,,
,27404491.245,84.4307327,99.7004928588867,9.31412144361462E-6,2.90382553799553E-7,1,0.999253354069792,40.0298881530762,1.98329489690849,21.2799999862909,0.000105591531565628,1.58897335562562E-5,0.25,-2.41337340473051E-7,9.36334468477594E-6,-2.01634686781267E-7,84.4307327,84.4307327,99.7004928588867,99.7004928588867,57.4403166212368,20.6403048972801,23.668306,0,0,0,40,4374,82.3108,99.7004928588867,,,,,,,,,,,,,0,,,,0.00245,,,,,,84.4307327,,,,
,27404626.16,80.9906998,99.7004928588867,9.96343651900762E-6,3.11906804669886E-7,1,0.999253354069792,40.0298881530762,1.98358589576143,21.3500000536442,0.00011290203681671,1.72552167439629E-5,0.25,-2.38509051487978E-7,1.00141595211491E-5,-1.92631012954061E-7,80.9906998,80.9906998,99.7004928588867,99.7004928588867,56.8564401173714,20.6394881189906,23.288654,0,0,0,40,4374,78.9753,99.7004928588867,,,,,,,,,,,,,0,,,,0.00245,,,,,,80.9906998,,,,
,27404765.435,77.4636765,99.7004928588867,9.71970140268394E-6,3.56461120763632E-7,1,0.999253354069792,40.0298881530762,1.98356928379008,21.3500000536442,0.000110152709815418,1.65979916635871E-5,0.25,-2.56696025133379E-7,9.76684336156507E-6,-2.08426097418743E-7,77.4636765,77.4636765,99.7004928588867,99.7004928588867,57.3519925985638,20.6360647774627,23.288654,0,0,0,40,4374,75.5447,99.7004928588867,,,,,,,,,,,,,0,,,,0,,,,,,77.4636765,,,,
,27404904.155,73.9378891,99.7004928588867,9.73788889497951E-6,3.75557730228761E-7,1,0.999253354069792,40.0298881530762,1.98369731580954,21.3500000536442,0.000110155418457938,1.76043154202365E-5,0.25,-1.74106468037419E-7,9.78148256599628E-6,-1.21493373090163E-7,73.9378891,73.9378891,99.7004928588867,99.7004928588867,57.3402681707753,20.634414599914,23.288654,0,0,0,40,4374,72.14905,99.7004928588867,,,,,,,,,,,,,0,,,,0,,,,,,73.9378891,,,,
,27405040.705,70.4688034,99.7004928588867,1.01437772126484E-5,3.52470450404301E-7,1,0.999253354069792,40.0298881530762,1.98370211482063,21.4099995791912,0.00011477564961616,1.79030731965591E-5,0.25,-2.23420948428501E-7,1.01851661743139E-5,-1.64577767842754E-7,70.4688034,70.4688034,99.7004928588867,99.7004928588867,57.2667950899676,20.6335125166704,22.909004,0,0,0,40,4374,68.7797,99.7004928588867,,,,,,,,,,,,,0,,,,-0.00245,,,,,,70.4688034,,,,
,27405178.805,66.9547958,99.7004928588867,1.00442395782066E-5,3.76049621466911E-7,1,0.999253354069792,40.0298881530762,1.9837802499867,21.4099995791912,0.000113023765491082,2.09017556367095E-5,0.25,5.7171100516411E-8,1.00781196307884E-5,1.20670473230774E-7,66.9547958,66.9547958,99.7004928588867,99.7004928588867,57.3152560581599,20.6308196072197,22.149702,0,0,0,40,4374,65.38745,99.7004928588867,,,,,,,,,,,,,0,,,,-0.0049,,,,,,66.9547958,,,,
,27405313.62,63.4830208,99.7004928588867,1.0376189283715E-5,3.44742256717023E-7,1,0.999253354069792,40.0298881530762,1.98392840648741,21.4099995791912,0.00011663383720095,2.19032177780653E-5,0.25,8.37055714400324E-8,1.04042591721467E-5,1.53361332933304E-7,63.4830208,63.4830208,99.7004928588867,99.7004928588867,57.1823792098907,20.6333122817134,22.149702,0,0,0,40,4374,62.07325,99.7004928588867,,,,,,,,,,,,,0,,,,0.0049,,,,,,63.4830208,,,,
,27405451.355,59.9752693,99.7004928588867,1.03192293194536E-5,3.01954458372629E-7,1,0.999253354069792,40.0298881530762,1.98372805716579,21.4799996465445,0.000116288553640313,1.95508821629982E-5,0.25,-1.17142895957214E-7,1.03403462317669E-5,-4.47459973605694E-8,59.9752693,59.9752693,99.7004928588867,99.7004928588867,56.9924434797176,20.6290141841561,22.149702,0,0,0,40,4374,58.6939,99.7004928588867,,,,,,,,,,,,,0,,,,-0.0098,,,,,,59.9752693,,,,
,27405588.78,56.4920349,99.7004928588867,1.0310244404086E-5,3.63940683952982E-7,1,0.999253354069792,40.0298881530762,1.98403832871642,21.4799996465445,0.000116799966710678,1.56265979850176E-5,0.25,-4.66172638087911E-7,1.0324474111295E-5,-3.91421431310336E-7,56.4920349,56.4920349,99.7004928588867,99.7004928588867,57.0065127930637,20.630224434234,21.770052,0,0,0,40,4374,55.31455,99.7004928588867,,,,,,,,,,,,,0,,,,-0.0049,,,,,,56.4920349,,,,
,27405727.71,52.973114,99.7004928588867,1.03158594196227E-5,3.36936186901434E-7,1,0.999253354069792,40.0298881530762,1.98369274869068,21.4799996465445,0.000116651184115709,1.60325928508137E-5,0.25,-4.30828072410225E-7,1.03193899864456E-5,-3.54184128656817E-7,52.973114,52.973114,99.7004928588867,99.7004928588867,57.2730481181214,20.6320709742024,21.01075,0,0,0,40,4374,51.9128,99.7004928588867,,,,,,,,,,,,,0,,,,0,,,,,,52.973114,,,,
,27405864.07,49.4888535,99.7004928588867,9.88077587084724E-6,3.11949775979788E-7,1,0.999253354069792,40.0298881530762,2.00791830227658,21.5399991720915,0.000112934736452816,1.5407729436796E-5,0.25,-4.22333165545846E-7,9.87385514872193E-6,-3.48694075263559E-7,49.4888535,49.4888535,99.7004928588867,99.7004928588867,57.4817429327561,20.6269705634411,21.01075,0,0,0,40,4370,48.5588,99.7004928588867,,,,,,,,,,,,,0,,,,0,,,,,,49.4888535,,,,
,27405999.93,45.9972534,99.7004928588867,1.0127484202418E-5,3.56977183773087E-7,1,0.999253354069792,40.0298881530762,2.0079634102279,21.5399991720915,0.000116119190904605,1.3100912323478E-5,0.25,-6.67275449865889E-7,1.01116447171611E-5,-5.92669317344471E-7,45.9972534,45.9972534,99.7004928588867,99.7004928588867,57.3863842534099,20.6256683065893,20.631098,0,0,0,40,4370,45.22785,99.7004928588867,,,,,,,,,,,,,0,,,,0.0049,,,,,,45.9972534,,,,
,27406138.095,42.47538565,99.7004928588867,9.95755419632453E-6,3.15512055133782E-7,1,0.999253354069792,40.0298881530762,2.00796270661908,21.5399991720915,0.000113775689967745,1.44421598644163E-5,0.25,-5.13973025428045E-7,9.93124504101521E-6,-4.43559026570862E-7,42.4442253,42.506546,99.7004928588867,99.7004928588867,57.2167708647368,20.6293613091307,19.871798,0,0,0,40,4370,41.8393,99.7004928588867,,,,,,,,,,,,,0,,,,-0.0049,,,,,,42.47538565,,,,
,27406278.13,38.9482956,99.7004928588867,1.00105423750546E-5,3.62609595479046E-7,1,0.999253354069792,40.0298881530762,1.98373363877468,21.6000005602837,0.000112689627339148,1.58773704585342E-5,0.25,-3.75052903066986E-7,9.97454477922719E-6,-3.0851255939775E-7,38.9482956,38.9482956,99.7004928588867,99.7004928588867,57.4199942797368,20.639369068713,19.112494,0,0,0,40,4370,38.38365,99.7004928588867,,,,,,,,,,,,,0,,,,-0.00245,,,,,,38.9482956,,,,
,27406415.465,35.4227829,99.7004928588867,1.0154879760412E-5,3.16502435692739E-7,1,0.999253354069792,40.0298881530762,1.98393511116543,21.6000005602837,0.000113812814400483,1.85245688683138E-5,0.25,-1.58812929604485E-7,1.01100981045636E-5,-9.6502514872671E-8,35.4227829,35.4227829,99.7004928588867,99.7004928588867,57.3207274577945,20.638945172128,18.732843,0,0,0,40,4370,34.98145,99.7004928588867,,,,,,,,,,,,,0,,,,0,,,,,,35.4227829,,,,
,27406552.495,31.9532394,99.7004928588867,9.86747981434144E-6,3.27297432645004E-7,1,0.999253354069792,40.0298881530762,1.98389220037206,21.6000005602837,0.000109932906720384,2.1352285034934E-5,0.25,1.50644932653681E-7,9.81722667668679E-6,2.05681970816327E-7,31.9532394,31.9532394,99.7004928588867,99.7004928588867,57.6818398336792,20.6430192018256,18.353191,0,0,0,40,4370,31.592,99.7004928588867,,,,,,,,,,,,,0,,,,-0.00245,,,,,,31.9532394,,,,
,27406690.22,28.4769192,99.7004928588867,9.78072756549827E-6,3.14098499090643E-7,1,0.999253354069792,40.0298881530762,1.98388606329783,21.6400008648634,0.000109544864243671,1.76895007247537E-5,0.25,-1.57760503247055E-7,9.72910831717808E-6,-1.05017437673111E-7,28.4769192,28.4769192,99.7004928588867,99.7004928588867,57.7435884866984,20.6400875803538,18.353191,0,0,0,40,4370,28.1895,99.7004928588867,,,,,,,,,,,,,0,,,,0,,,,,,28.4769192,,,,
,27406830.85,24.9666405,99.7004928588867,9.92486393734866E-6,3.05145157892492E-7,1,0.999253354069792,40.0298881530762,1.98362262159554,21.6400008648634,0.000111035048396411,1.84106131603631E-5,0.25,-1.15622755068792E-7,9.86987408654083E-6,-6.49383845731263E-8,24.9666405,24.9666405,99.7004928588867,99.7004928588867,57.0018230219483,20.6472166542792,16.834587,0,0,0,40,4370,24.6978,99.7004928588867,,,,,,,,,,,,,0,,,,-0.0049,,,,,,24.9666405,,,,
,27406968.78,21.4965363,99.7004928588867,9.9614395440115E-6,2.86958430096846E-7,1,0.999253354069792,40.0298881530762,1.98369041569589,21.6400008648634,0.000111440017165192,1.84398890637254E-5,0.25,-1.1775462524973E-7,9.90498346583678E-6,-6.84457388284106E-8,21.4965363,21.4965363,99.7004928588867,99.7004928588867,57.1487691835637,20.6452848119602,16.834587,0,0,0,40,4370,21.2623,99.7004928588867,,,,,,,,,,,,,0,,,,-0.00245,,,,,,21.4965363,,,,
,27407108.43,17.9781342,99.7004928588867,1.054894977126E-5,2.69446267129882E-7,1,0.999253354069792,40.0298881530762,1.98380114470586,21.679999306798,0.000118077736208266,1.91696522843986E-5,0.25,-1.56124341318788E-7,1.04888996587172E-5,-1.04367071692731E-7,17.9781342,17.9781342,99.7004928588867,99.7004928588867,56.7485753817175,20.646107130187,15.315984,0,0,0,40,4370,17.7919,99.7004928588867,,,,,,,,,,,,,0,,,,-0.00245,,,,,,17.9781342,,,,
,27407248.65,14.4622374,99.7004928588867,1.0101315389583E-5,3.2360008123853E-7,1,0.999253354069792,40.0298881530762,1.9837779709663,21.6700006276369,0.000113737212311323,1.45840694354732E-5,0.25,-4.874025588417E-7,1.00455678689825E-5,-4.35882741512719E-7,14.4622374,14.4622374,99.7004928588867,99.7004928588867,57.0260535060445,20.6480315849563,14.556682,0,0,0,40,4370,14.31015,99.7004928588867,,,,,,,,,,,,,0,,,,0,,,,,,14.4622374,,,,
,27407387.235,10.9651623,99.7004928588867,1.01208607893808E-5,2.90709665973037E-7,1,0.999253354069792,40.0298881530762,1.98372433741053,21.6700006276369,0.000113375397249023,1.78773411783911E-5,0.25,-1.95853946917708E-7,1.00636738776518E-5,-1.45917867876012E-7,10.9651623,10.9651623,99.7004928588867,99.7004928588867,56.9142806277945,20.6498866011465,13.797379,0,0,0,40,4370,10.8493,99.7004928588867,,,,,,,,,,,,,0,,,,0.00245,,,,,,10.9651623,,,,
,27407563.835,10.0044737,99.7004928588867,1.03068241832003E-5,3.42704051397632E-7,1,0.999253354069792,40.0298881530762,2.00779937461919,21.7000003904104,0.000116720634246913,1.88404092699029E-5,0.25,-1.61932541362594E-7,1.0248422130874E-5,-1.11294608704665E-7,10.0041113,10.0048361,99.7004928588867,99.7004928588867,57.1511140691214,20.6471560121846,13.038077,0,0,0,40,4369,9.9899,99.7004928588867,,,,,,,,,,,,,0,,,,0.0049,,,,,,10.0044737,,,,