File: data/monolayers/nanoparticles/Ac_CoFe_C/vsm/data_disorderedWafer/DD226_2_HYST_10K_REPEAT_3.DAT
[Header]
; VSM Data File (default extension .dat)
; Copyright (c) 2003-2013, Quantum Design, Inc. All rights reserved.
TITLE,
FILEOPENTIME,27461100.77,11/15/2018,4:05 am
BYAPP,VSM,2.0,2.0
INFO,PPMS VSM Option Release 1.4.10 Build 1,APPNAME
INFO,Quantum Design Linear Motor Servo Controller,MOTOR_MODULE_NAME
INFO,3101-100 M1,MOTOR_HW_VERSION
INFO,MMC1014,MOTOR_SERIAL_NUMBER
INFO,SRV No X-over 01.03.11,MOTOR_SOFTWARE_VERSION
INFO,Quantum Design VSM Detection Module,VSM_MODULE_NAME
INFO,3101-150 F0,VSM_HW_VERSION
INFO,VSM707,VSM_SERIAL_NUMBER
INFO,VSM No X-over 01.02.05 May 20 2008 13:51:47,VSM_SOFTWARE_VERSION
INFO,704,PREAMP_SERIAL_NUMBER
INFO,822,COIL_SERIAL_NUMBER
INFO,0,MOMENT_UNITS
INFO,CoFe2O4 AH11,SAMPLE_MATERIAL
INFO,Quick Dry Monolayer Conc,SAMPLE_COMMENT
INFO,27.96,SAMPLE_MASS
INFO,,SAMPLE_VOLUME
INFO,,SAMPLE_MOLECULAR_WEIGHT
INFO,,SAMPLE_SIZE
INFO,,SAMPLE_SHAPE
DATATYPE,COMMENT,1
DATATYPE,TIME,2
STARTUPAXIS,X,2
STARTUPAXIS,Y1,5
[Data]
Comment,Time Stamp (sec),Temperature (K),Magnetic Field (Oe),Moment (emu),M. Std. Err. (emu),Transport Action,Averaging Time (sec),Frequency (Hz),Peak Amplitude (mm),Center Position (mm),Coil Signal' (mV),Coil Signal" (mV),Range (mV),M. Quad. Signal (emu),M. Raw' (emu),M. Raw" (emu),Min. Temperature (K),Max. Temperature (K),Min. Field (Oe),Max. Field (Oe),Mass (grams),Motor Lag (deg),Pressure (Torr),VSM Status (code),Motor Status (code),Measure Status (code),Measure Count,PPMS Status (code),System Temp. (K),System Field (Oe),Sample Position (deg),Bridge 1 Resistance (ohms),Bridge 1 Excitation (에),Bridge 2 Resistance (ohms),Bridge 2 Excitation (에),Bridge 3 Resistance (ohms),Bridge 3 Excitation (에),Bridge 4 Resistance (ohms),Bridge 4 Excitation (에),Signal 1 Vin (V),Signal 2 Vin (V),Digital Inputs (code),Drive 1 Iout (mA),Drive 1 Ipower (W),Drive 2 Iout (mA),Drive 2 Ipower (W),Pressure (),Map 20 (),Map 21 (),Map 22 (),Map 23 (),Map 24 (),Map 25 (),Map 26 (),Map 27 (),Map 28 (),Map 29 ()
sample offset = 36.12 mm,27461117.595,10.0031996,-0.350146800279617,3.72375661285255E-5,3.71908981746533E-7,1,0.999253354069792,40.0298881530762,1.99651319042708,17.0799996703863,0.000418660202269304,7.20806822149976E-5,0.25,-1.95233166065648E-7,3.70245928304299E-5,-1.46290234581703E-8,10.0031996,10.0031996,-0.350146800279617,-0.350146800279617,56.8322096332752,20.5170245816839,10.38052,0,0,0,40,4417,9.99485,-0.350146800279617,,,,,,,,,,,,,0,,,,0,,,,,,10.0031996,,,,
,27461227.43,9.9988861,4566.10546875,2.61220086851653E-5,3.28361534064761E-7,1,0.999253354069792,40.0298881530762,1.99645833469556,17.0799996703863,0.000293096759066566,5.42752792607961E-5,0.25,1.85106103331052E-7,2.59774700336297E-5,3.17229151011526E-7,9.9988861,9.9988861,4561.01318359375,4571.19775390625,56.8204852054868,20.5142622424739,10.760172,0,0,0,40,4449,9.9985,4566.10546875,,,,,,,,,,,,,0,,,,0.00245,,,,,,9.9988861,,,,
,27461319.145,9.9993324,9147.2314453125,1.26095704698648E-5,4.11007793556604E-7,1,0.999253354069792,40.0298881530762,1.99644256256188,17.0799996703863,0.000141749442243987,2.49745687755693E-5,0.25,-2.46424144819519E-8,1.25446055311226E-5,4.39664696285852E-8,9.9993324,9.9993324,9142.1796875,9152.283203125,57.3473028274484,20.5179529739678,11.139823,0,0,0,40,4449,9.9985,9147.2314453125,,,,,,,,,,,,,0,,,,-0.0049,,,,,,9.9993324,,,,
,27461412.65,10.0007362,13819.8569335938,-3.16678578377634E-6,3.87228762822741E-7,1,0.999253354069792,40.0298881530762,1.99641977222183,17.0799996703863,-3.63450091908053E-5,-2.17433010076906E-6,0.25,3.72023790106725E-7,-3.15382520914507E-6,3.51966357333322E-7,10.0007362,10.0007362,13809.78125,13829.9326171875,56.8978664288906,20.5158635298008,10.760172,0,0,0,40,4449,9.99755,13819.8569335938,,,,,,,,,,,,,0,,,,0.0049,,,,,,10.0007362,,,,
,27461510.31,10.000577,18702.197265625,-1.96097412612184E-5,4.24081074118248E-7,1,0.999253354069792,40.0298881530762,1.99638416251277,17.0799996703863,-0.000221550085318334,-3.36882038719442E-5,0.25,5.12537098856833E-7,-1.95281405219929E-5,3.90469356839019E-7,10.000577,10.000577,18697.376953125,18707.017578125,56.8994296859291,20.5180523677447,10.760172,0,0,0,40,4449,9.99815,18702.197265625,,,,,,,,,,,,,0,,,,-0.00245,,,,,,10.000577,,,,
,27461605.565,10.0007448,23462.130859375,-3.5625555390737E-5,5.87234911036156E-7,1,0.999253354069792,40.0298881530762,1.99633072597924,17.0799996703863,-0.000402696862732765,-6.11304660683761E-5,0.25,9.50635032353708E-7,-3.54943927276936E-5,7.18538701845576E-7,10.0007448,10.0007448,23454.564453125,23469.697265625,57.0924919301791,20.5142663791405,11.139823,0,0,0,40,4449,9.9971,23462.130859375,,,,,,,,,,,,,0,,,,0,,,,,,10.0007448,,,,
,27461698.955,10.0009079,28132.666015625,-5.16709445591067E-5,5.59178830788258E-7,1,0.999253354069792,40.0298881530762,1.99637586427122,17.0799996703863,-0.000583163955040367,-9.54055325829369E-5,0.25,7.97039258385701E-7,-5.15019372434371E-5,4.49633233151354E-7,10.0009079,10.0009079,28127.6953125,28137.63671875,57.0917103016599,20.5179040498755,10.760172,0,0,0,40,4449,9.9972,28132.666015625,,,,,,,,,,,,,0,,,,-0.0049,,,,,,10.0009079,,,,
,27461795.655,10.0000601,32965.404296875,-6.86969221381006E-5,5.40996308107299E-7,1,0.999253354069792,40.0298881530762,1.9964499509415,17.0799996703863,-0.000773828697216447,-0.000137589681699671,0.25,1.26942507540982E-7,-6.85009275131392E-5,-3.47397881129405E-7,10.0000601,10.0000601,32955.484375,32975.32421875,56.9486722826406,20.5125843179003,10.760172,0,0,0,40,4449,9.9975,32965.404296875,,,,,,,,,,,,,0,,,,0.0049,,,,,,10.0000601,,,,
,27461888.23,9.9995956,37587.873046875,-8.41331468379375E-5,5.75815115794957E-7,1,0.999253354069792,40.0298881530762,1.99637875545668,17.0799996703863,-0.000949665857307948,-0.000160122177913368,0.25,9.21353039650336E-7,-8.39398297281296E-5,3.23637870271712E-7,9.9995956,9.9995956,37582.87109375,37592.875,56.9197520274291,20.5148848499859,10.38052,0,0,0,40,4449,9.99725,37587.873046875,,,,,,,,,,,,,0,,,,0,,,,,,9.9995956,,,,
,27461985.025,9.9986305,42427.869140625,-0.00010136801106595,6.85814274378812E-7,1,0.999253354069792,40.0298881530762,1.99640990712262,17.0799996703863,-0.00114373532360012,-0.000199018328043262,0.25,5.9294919267053E-7,-0.000101183409693609,-1.4053078777863E-7,9.9986305,9.9986305,42425.4375,42430.30078125,56.9682129956214,20.5105376723323,10.38052,0,0,0,40,4449,9.9979,42427.869140625,,,,,,,,,,,,,0,,,,0,,,,,,9.9986305,,,,
,27462075.93,9.9974442,46973.142578125,-0.000116649633651574,6.06220616503608E-7,1,0.999253354069792,40.0298881530762,1.99638696782123,17.0799996703863,-0.00131644467595082,-0.000230934720885662,0.25,5.33511338078559E-7,-0.000116491476985101,-3.2182515226892E-7,9.9974442,9.9974442,46967.66796875,46978.6171875,56.9291315696599,20.5111017558672,11.139823,0,0,0,40,4449,10.00115,46973.142578125,,,,,,,,,,,,,0,,,,-0.0049,,,,,,9.9974442,,,,
,27462172.315,9.9969873,51788.576171875,-0.000133899022589887,9.46873256837546E-7,1,0.999253354069792,40.0298881530762,1.99637008750404,17.0799996703863,-0.001511141840977,-0.000269104739309706,0.25,2.76450637739286E-7,-0.000133780725343652,-7.14328878884189E-7,9.9969873,9.9969873,51781.03515625,51796.1171875,57.0049495360253,20.5112811704798,10.760172,0,0,0,40,4449,10.0037,51788.576171875,,,,,,,,,,,,,0,,,,-0.0049,,,,,,9.9969873,,,,
,27462267.625,9.9966335,56551.150390625,-0.000151810133353024,5.39808534807966E-7,1,0.999253354069792,40.0298881530762,1.99637825494613,17.0799996703863,-0.00171646172955972,-0.000292109554249151,0.25,1.48251961792422E-6,-0.000151756038290347,3.53163587525599E-7,9.9966335,9.9966335,56543.609375,56558.69140625,56.9142806277945,20.5105797970265,10.38052,0,0,0,40,4449,10.0066,56551.150390625,,,,,,,,,,,,,0,,,,-0.0049,,,,,,9.9966335,,,,
,27462361.86,9.9964762,61264.00390625,-0.000168784009528281,7.88100831657221E-7,1,0.999253354069792,40.0298881530762,1.99638630860238,17.0799996703863,-0.00190553239730226,-0.000345487766649135,0.25,-1.7267896212927E-7,-0.000168785795676086,-1.42895540475681E-6,9.9964762,9.9964762,61256.34375,61271.6640625,56.9775925378522,20.5089810625151,10.760172,0,0,0,40,4449,10.0101,61264.00390625,,,,,,,,,,,,,0,,,,-0.0049,,,,,,9.9964762,,,,
,27462456.335,9.9965086,65984.51953125,-0.000187094133921794,7.3611445212909E-7,1,0.999253354069792,40.0298881530762,1.99625527953182,17.0799996703863,-0.00211353587867203,-0.000380252344202166,0.25,5.74362205668628E-8,-0.000187178088205843,-1.3318132779035E-6,9.9965086,9.9965086,65979.4609375,65989.578125,57.0518472471791,20.5167680536505,10.760172,0,0,0,40,4449,10.0136,65984.51953125,,,,,,,,,,,,,0,,,,0.0049,,,,,,9.9965086,,,,
,27462550.28,9.9961977,70682.1171875,-0.000202460002357494,7.86334853887819E-7,1,0.999253354069792,40.0298881530762,1.99645942038111,17.0799996703863,-0.00228892898158514,-0.00040802156663385,0.25,3.78050060462502E-7,-0.000202635276206885,-1.11700633057858E-6,9.9961977,9.9961977,70677.0234375,70687.2109375,56.8431524325445,20.5124808164118,10.760172,0,0,0,40,4449,10.01735,70682.1171875,,,,,,,,,,,,,0,,,,0,,,,,,9.9961977,,,,
,27462645.235,9.99584055,75427.7578125,-0.000220197845234907,9.0195177159182E-7,1,0.999253354069792,40.0298881530762,1.99643286970023,17.0799996703863,-0.00249073901205959,-0.000442040911197443,0.25,5.65112408940604E-7,-0.000220475020959239,-1.0475913537436E-6,9.9957991,9.995882,75420.2734375,75435.2421875,57.0799858738714,20.5111568460249,10.760172,0,0,0,40,4449,10.02065,75427.7578125,,,,,,,,,,,,,0,,,,-0.00245,,,,,,9.99584055,,,,
,27462738.83,9.9954691,80105.8203125,-0.000238303212109503,7.47344263980232E-7,1,0.999253354069792,40.0298881530762,1.9961756969851,17.0799996703863,-0.00269543982186862,-0.00048257815683958,0.25,2.32769029189616E-7,-0.000238686430824209,-1.495303813277E-6,9.9954691,9.9954691,80073.109375,80138.53125,57.0393411908714,20.5136023549108,11.139823,0,0,0,40,4449,10.0245,80105.8203125,,,,,,,,,,,,,0,,,,0,,,,,,9.9954691,,,,
,27462834.855,9.9957151,84906.95703125,-0.000254444667362487,7.58904661343745E-7,1,0.999253354069792,40.0298881530762,1.99639575699343,17.0799996703863,-0.00287895229517572,-0.000517530637321736,0.25,4.56184377688685E-8,-0.000254941082504787,-1.77707630077277E-6,9.9957151,9.9957151,84896.9296875,84916.984375,56.8423708040252,20.5108777138657,11.139823,0,0,0,40,4449,10.0283,84906.95703125,,,,,,,,,,,,,0,,,,0,,,,,,9.9957151,,,,
,27462926.205,9.9956684,89472.46875,-0.000270950632904066,8.19288157955176E-7,1,0.999253354069792,40.0298881530762,1.99646402007507,17.0799996703863,-0.00306487640887121,-0.000561778071215481,0.25,-9.04248455687443E-7,-0.000271556890546848,-2.82150091596376E-6,9.9956684,9.9956684,89464.8828125,89480.0546875,57.2652318329291,20.5078929657758,10.760172,0,0,0,40,4449,10.03195,89472.46875,,,,,,,,,,,,,0,,,,-0.00245,,,,,,9.9956684,,,,
,27463034.735,9.9990807,86093.7734375,-0.000260490630288328,6.41563195644446E-7,1,0.999253354069792,40.0298881530762,1.99638806271374,17.0799996703863,-0.00294691116016056,-0.000533656389740363,0.25,-2.94322137140421E-7,-0.000261017977057562,-2.1547920033014E-6,9.9990807,9.9990807,86083.7109375,86103.8359375,56.953362053756,20.5103557796553,10.760172,0,0,0,40,4449,10.03395,86093.7734375,,,,,,,,,,,,,0,,,,-0.00245,,,,,,9.9990807,,,,
,27463127.2,10.0020761,81472.87109375,-0.00024228392070506,8.251916043393E-7,1,0.999253354069792,40.0298881530762,1.99635724529433,17.0799996703863,-0.00273952966224537,-0.000498791403345298,0.25,-4.81924468844465E-7,-0.000242692934571889,-2.23420702275746E-6,10.0020761,10.0020761,81465.3515625,81480.390625,57.0846756449868,20.5117606049131,10.760172,0,0,0,40,4449,10.03175,81472.87109375,,,,,,,,,,,,,0,,,,-0.00245,,,,,,10.0020761,,,,
,27463227.685,10.0025539,76448.91015625,-0.000224638932046007,8.66608930998621E-7,1,0.999253354069792,40.0298881530762,1.99652932273113,17.0799996703863,-0.00253827004015556,-0.000467809676846504,0.25,-9.12369585561083E-7,-0.000224928912859996,-2.55617231081437E-6,10.0025539,10.0025539,76436.7421875,76461.078125,56.9549253107945,20.5114088651608,10.760172,0,0,0,40,4449,10.02835,76448.91015625,,,,,,,,,,,,,0,,,,0.00245,,,,,,10.0025539,,,,
,27463327.505,10.0034227,71458.5625,-0.00020520105268025,7.29283790293724E-7,1,0.999253354069792,40.0298881530762,1.99638250934302,17.0799996703863,-0.00231835374037407,-0.000422601272788873,0.25,-4.18861038481391E-7,-0.000205386111076791,-1.93314107698036E-6,10.0034227,10.0034227,71448.484375,71468.640625,56.8228300910445,20.5143039020437,11.139823,0,0,0,40,4449,10.02505,71458.5625,,,,,,,,,,,,,0,,,,0,,,,,,10.0034227,,,,
,27463426.18,10.0040188,66525.28125,-0.000188381495265957,7.99337574675269E-7,1,0.999253354069792,40.0298881530762,1.99636756289506,17.0799996703863,-0.00212837419633959,-0.000382465203985122,0.25,9.62680352459191E-8,-0.000188475304300318,-1.30186159296567E-6,10.0040188,10.0040188,66520.34375,66530.21875,56.8767624588714,20.5125520913306,11.139823,0,0,0,40,4449,10.02105,66525.28125,,,,,,,,,,,,,0,,,,0,,,,,,10.0040188,,,,
,27463524.155,10.0036907,61629.654296875,-0.000169404799293368,7.23780684904598E-7,1,0.999253354069792,40.0298881530762,1.99639551234548,17.0799996703863,-0.00191368335155652,-0.000340840137464093,0.25,3.51840327832899E-7,-0.000169416240353027,-9.08952420082766E-7,10.0036907,10.0036907,61622.12890625,61637.1796875,56.9564885678329,20.5119232268281,10.38052,0,0,0,40,4449,10.018,61629.654296875,,,,,,,,,,,,,0,,,,0,,,,,,10.0036907,,,,
,27463624.975,10.0041227,56589.291015625,-0.000151526889368187,7.18069800341786E-7,1,0.999253354069792,40.0298881530762,1.99652508572715,17.0799996703863,-0.00171097713619268,-0.000304949105607045,0.25,2.9590889325069E-7,-0.000151464651076706,-8.3085781507612E-7,10.0041227,10.0041227,56584.34765625,56594.234375,56.9775925378522,20.511757520916,10.760172,0,0,0,40,4449,10.0136,56589.291015625,,,,,,,,,,,,,0,,,,-0.0049,,,,,,10.0041227,,,,
,27463721.55,10.0041113,51764.32421875,-0.000134185401225092,6.98320744422857E-7,1,0.999253354069792,40.0298881530762,1.99656538386161,17.0799996703863,-0.00151536524738382,-0.000264967347215736,0.25,6.96902125518526E-7,-0.000134069628603929,-2.96338929479414E-7,10.0041113,10.0041113,51756.984375,51771.6640625,56.9697762526599,20.5108555256375,10.760172,0,0,0,40,4449,10.0105,51764.32421875,,,,,,,,,,,,,0,,,,0,,,,,,10.0041113,,,,
,27463819.15,10.0038424,46884.072265625,-0.000116389276072927,7.0965047544762E-7,1,0.999253354069792,40.0298881530762,1.99653337826235,17.0799996703863,-0.00131346848802587,-0.00023108686079563,0.25,4.74177483962226E-7,-0.00011622997380679,-3.78980318163935E-7,10.0038424,10.0038424,46878.9296875,46889.21484375,56.9275683126214,20.5108119583418,10.38052,0,0,0,40,4449,10.0061,46884.072265625,,,,,,,,,,,,,0,,,,-0.00245,,,,,,10.0038424,,,,
,27463920.125,10.0036974,41838.97265625,-9.82959497957048E-5,8.38550759028733E-7,1,0.999253354069792,40.0298881530762,1.99651247828941,17.0799996703863,-0.00110928714384737,-0.000191714376667156,0.25,6.86154597811914E-7,-9.81116410476293E-5,-2.38077064978313E-8,10.0036974,10.0036974,41836.67578125,41841.26953125,56.9760292808137,20.5123330235207,10.760172,0,0,0,40,4449,10.0029,41838.97265625,,,,,,,,,,,,,0,,,,0,,,,,,10.0036974,,,,
,27464016.615,10.0029621,37016.66015625,-8.2154226655498E-5,5.01306516960818E-7,1,0.999253354069792,40.0298881530762,1.99650162072733,17.0799996703863,-0.000925938095988365,-0.00016407299420183,0.25,2.13012895470246E-7,-8.19556090817625E-5,-3.67380381928796E-7,10.0029621,10.0029621,37009.3203125,37024,57.1815975813714,20.5140385199949,10.760172,0,0,0,40,4449,10.0002,37016.66015625,,,,,,,,,,,,,0,,,,0.0049,,,,,,10.0029621,,,,
,27464113.745,10.0021687,32162.4150390625,-6.48592156289243E-5,5.10690007167733E-7,1,0.999253354069792,40.0298881530762,1.99648937789505,17.0799996703863,-0.000732217562145165,-0.000120617037549179,0.25,9.41561015920045E-7,-6.46742975411603E-5,4.93554667361709E-7,10.0021687,10.0021687,32152.421875,32172.408203125,56.6985511564868,20.5126796728253,10.760172,0,0,0,40,4449,9.9991,32162.4150390625,,,,,,,,,,,,,0,,,,0,,,,,,10.0021687,,,,
,27464209.86,10.0016336,27357.0576171875,-4.83457572033873E-5,5.91877625099233E-7,1,0.999253354069792,40.0298881530762,1.99650187600047,17.0799996703863,-0.000544790644417856,-9.39071587976041E-5,0.25,3.31257239198598E-7,-4.81809523656596E-5,9.53658823309432E-9,10.0016336,10.0016336,27349.43359375,27364.681640625,56.9783741663714,20.5164009268206,10.760172,0,0,0,40,4449,9.9989,27357.0576171875,,,,,,,,,,,,,0,,,,0.0049,,,,,,10.0016336,,,,
,27464307.195,10.00110865,22494.30078125,-3.13737909580415E-5,5.01108064404779E-7,1,0.999253354069792,40.0298881530762,1.99648825403143,17.0799996703863,-0.000354503258495272,-5.4530314620354E-5,0.25,7.73423057613324E-7,-3.12547815303594E-5,5.71024683511438E-7,10.0010147,10.0012026,22486.90234375,22501.69921875,56.9650864815445,20.5148778980265,10.38052,0,0,0,40,4449,9.9972,22494.30078125,,,,,,,,,,,,,0,,,,-0.0049,,,,,,10.00110865,,,,
,27464400.475,10.0012627,17831.931640625,-1.47679500780617E-5,5.38976347144768E-7,1,0.999253354069792,40.0298881530762,1.99673948139546,17.0799996703863,-0.000168075504053552,-1.85866032815101E-5,0.25,9.88508776430212E-7,-1.47089003061377E-5,8.94756890272921E-7,10.0012627,10.0012627,17824.453125,17839.41015625,57.0627900464484,20.5239319998987,10.38052,0,0,0,40,4449,9.9972,17831.931640625,,,,,,,,,,,,,0,,,,-0.00245,,,,,,10.0012627,,,,
,27464496.555,9.9996319,13029.3676757813,1.38018331124748E-6,3.35717055485015E-7,1,0.999253354069792,40.0298881530762,1.99681450146385,17.0799996703863,1.48351406074336E-5,6.58880462390207E-6,0.25,3.39697929661834E-7,1.37156128277659E-6,3.45943103492629E-7,9.9996319,9.9996319,12996.908203125,13061.8271484375,56.9994781363906,20.5286668772741,10.38052,0,0,0,40,4449,9.99645,13029.3676757813,,,,,,,,,,,,,0,,,,0.00245,,,,,,9.9996319,,,,
,27464591.175,9.9990425,8298.87939453125,1.63248787263283E-5,3.8555751909373E-7,1,0.999253354069792,40.0298881530762,1.99660373542751,17.0799996703863,0.000183279039578962,3.36671745069784E-5,0.25,8.78032362666427E-8,1.62390481908363E-5,1.74978956073729E-7,9.9988575,9.9992275,8293.9267578125,8303.83203125,57.2370932062368,20.515261447143,10.760172,0,0,0,40,4449,9.9977,8298.87939453125,,,,,,,,,,,,,0,,,,0,,,,,,9.9990425,,,,
,27464683.2,9.99898005,3700.9755859375,2.91254132325971E-5,3.48608100857884E-7,1,0.999253354069792,40.0298881530762,1.99634241395927,17.0799996703863,0.000327207275670063,5.79899280211818E-5,0.25,-1.6096755773953E-8,2.89637604506986E-5,1.30688439938535E-7,9.9989328,9.9990273,3695.998046875,3705.953125,57.1823792098907,20.5203657101453,11.139823,0,0,0,40,4449,9.999,3700.9755859375,,,,,,,,,,,,,0,,,,0,,,,,,9.99898005,,,,
,27464777.175,9.9992428,-995.947143554687,3.89039009371801E-5,3.11137631155848E-7,1,0.999253354069792,40.0298881530762,1.99635186961551,17.0799996703863,0.000437164745339523,7.65064624774067E-5,0.25,-9.86409564813588E-8,3.86824186385895E-5,9.12152159610015E-8,9.9992428,9.9992428,-1000.96337890625,-990.930908203125,56.780622151006,20.5189727584974,10.760172,0,0,0,40,4449,9.9965,-995.947143554687,,,,,,,,,,,,,0,,,,-0.0049,,,,,,9.9992428,,,,
,27464868.045,9.9989901,-5536.8759765625,4.90234502014264E-5,3.35239224605602E-7,1,0.999253354069792,40.0298881530762,1.99652981331757,17.0799996703863,0.000551286488439786,9.52736113040988E-5,0.25,-2.43036803016586E-7,4.87584468220295E-5,1.1541114158577E-8,9.9989901,9.9989901,-5542.04736328125,-5531.70458984375,56.9783741663714,20.5147950710579,10.760172,0,0,0,40,4449,9.9989,-5536.8759765625,,,,,,,,,,,,,0,,,,-0.00245,,,,,,9.9989901,,,,
,27464965.37,9.9998159,-10402.4697265625,6.10794969074241E-5,3.55759833322201E-7,1,0.999253354069792,40.0298881530762,1.99654919051729,17.0799996703863,0.000687179479419096,0.000118445018233658,0.25,-3.51722297282978E-7,6.07722687690538E-5,-1.25545307066617E-8,9.9998159,9.9998159,-10405.0400390625,-10399.8994140625,57.3355783996599,20.5187017497066,11.139823,0,0,0,40,4449,9.998,-10402.4697265625,,,,,,,,,,,,,0,,,,0.00245,,,,,,9.9998159,,,,
,27465063.595,10.0012398,-15310.2568359375,7.12686673555702E-5,4.09747134493814E-7,1,0.999253354069792,40.0298881530762,1.996484304632,17.0799996703863,0.000802559825693678,0.00013587535962294,0.25,-6.47705558510957E-7,7.09419735041845E-5,-2.25689807613763E-7,10.0012398,10.0012398,-15317.7099609375,-15302.8037109375,56.8337728903137,20.5187137495885,10.38052,0,0,0,40,4449,9.997,-15310.2568359375,,,,,,,,,,,,,0,,,,0,,,,,,10.0012398,,,,
,27465156.89,10.0007372,-19972.7001953125,7.4498099050148E-5,3.57484219991131E-7,1,0.999253354069792,40.0298881530762,1.99649183991927,17.0799996703863,0.000839190674869916,0.00014272718376885,0.25,-6.44395436874756E-7,7.41893124752223E-5,-1.80153545327917E-7,10.0007372,10.0007372,-19975.365234375,-19970.03515625,57.1534589546791,20.5183643334102,11.139823,0,0,0,40,4449,9.99785,-19972.7001953125,,,,,,,,,,,,,0,,,,0,,,,,,10.0007372,,,,
,27465251.43,10.0005341,-24699.7265625,7.32223378532389E-5,4.43067542861405E-7,1,0.999253354069792,40.0298881530762,1.9963842437893,17.0799996703863,0.000825227110649869,0.000140030162036339,0.25,-6.82176305907801E-7,7.29538305092227E-5,-2.04833262344127E-7,10.0005341,10.0005341,-24706.96875,-24692.484375,57.2284952925253,20.520020485696,11.139823,0,0,0,40,4449,9.99695,-24699.7265625,,,,,,,,,,,,,0,,,,-0.00245,,,,,,10.0005341,,,,
,27465345.07,10.0012684,-29379.978515625,7.41102707534218E-5,4.85191657859699E-7,1,0.999253354069792,40.0298881530762,1.99638848135819,17.0799996703863,0.000837120295995001,0.000133580693111741,0.25,-1.43880420709653E-6,7.3879581668631E-5,-9.35058985182565E-7,10.0012684,10.0012684,-29385.064453125,-29374.892578125,57.2011382943522,20.5211750011154,10.38052,0,0,0,40,4449,9.9978,-29379.978515625,,,,,,,,,,,,,0,,,,0,,,,,,10.0012684,,,,
,27465438.715,10.000473,-34059.658203125,8.14957370542374E-5,6.2390777138589E-7,1,0.999253354069792,40.0298881530762,1.99647176359923,17.0799996703863,0.000919566198606633,0.000155178033649567,0.25,-8.70531837112308E-7,8.12776834640153E-5,-3.02121376922116E-7,10.000473,10.000473,-34067.37109375,-34051.9453125,57.0878021590637,20.5231881307983,10.760172,0,0,0,40,4449,9.99695,-34059.658203125,,,,,,,,,,,,,0,,,,0,,,,,,10.000473,,,,
,27465532.875,9.9990416,-38764.41015625,9.31668435689404E-5,6.98155524151544E-7,1,0.999253354069792,40.0298881530762,1.99645606805662,17.0799996703863,0.00105233625306805,0.000174398659675935,0.25,-1.28528480668741E-6,9.29663255099446E-5,-6.19250505289385E-7,9.9990416,9.9990416,-38769.15234375,-38759.66796875,57.0487207331022,20.5185786817542,10.760172,0,0,0,40,4449,9.99725,-38764.41015625,,,,,,,,,,,,,0,,,,0.0049,,,,,,9.9990416,,,,
,27465631.235,9.99827,-43679.01171875,0.000108188667751883,5.63808304848149E-7,1,0.999253354069792,40.0298881530762,1.9964820286975,17.0799996703863,0.00122113699923958,0.000211106408569921,0.25,-7.54865379777315E-7,0.000108006758286682,3.14816903707978E-8,9.99827,9.99827,-43681.55078125,-43676.47265625,57.0924919301791,20.5244531979852,10.760172,0,0,0,40,4449,10.0007,-43679.01171875,,,,,,,,,,,,,0,,,,-0.0049,,,,,,9.99827,,,,
,27465728.73,9.997694,-48553.89453125,0.000123577236330341,5.34644316594969E-7,1,0.999253354069792,40.0298881530762,1.99637567826061,17.0799996703863,0.00139521425820462,0.000242642883338973,0.25,-7.49780100189578E-7,0.000123431147871415,1.5987014829482E-7,9.997694,9.997694,-48563.84765625,-48543.94140625,56.7524835243137,20.5226039203897,10.38052,0,0,0,40,4449,10.0014,-48553.89453125,,,,,,,,,,,,,0,,,,0.00245,,,,,,9.997694,,,,
,27465825.965,9.9970808,-53411.3046875,0.000141375508411195,6.60171387087883E-7,1,0.999253354069792,40.0298881530762,1.99648595781155,17.0799996703863,0.00159592458049511,0.000283869386073019,0.25,-3.22659808820092E-7,0.000141273734772205,7.25722104159193E-7,9.9970808,9.9970808,-53421.50390625,-53401.10546875,57.0674798175637,20.5209388599657,10.760172,0,0,0,40,4449,10.0048,-53411.3046875,,,,,,,,,,,,,0,,,,0.00245,,,,,,9.9970808,,,,
,27465923.455,9.9962473,-58283.7265625,0.000157961425005437,9.03055085260269E-7,1,0.999253354069792,40.0298881530762,1.99643749321881,17.0799996703863,0.00178558495923022,0.00030830739267926,0.25,-1.1622481263803E-6,0.000157928626121238,1.34795531758442E-8,9.9962473,9.9962473,-58293.60546875,-58273.84765625,57.444224763833,20.5216439480427,10.760172,0,0,0,40,4449,10.0072,-58283.7265625,,,,,,,,,,,,,0,,,,0,,,,,,9.9962473,,,,
,27466021.15,9.9965696,-63166.396484375,0.000176282468792117,9.85443576025167E-7,1,0.999253354069792,40.0298881530762,1.99657061991215,17.0799996703863,0.00199366601051139,0.00034454229643867,0.25,-1.26971573510129E-6,0.000176325976826835,4.13861593009434E-8,9.9965696,9.9965696,-63171.359375,-63161.43359375,56.9056827140829,20.5190761177875,10.760172,0,0,0,40,4449,10.0118,-63166.396484375,,,,,,,,,,,,,0,,,,0,,,,,,9.9965696,,,,
,27466117.985,9.9959641,-68008.44921875,0.000192660481782546,8.39029060743499E-7,1,0.999253354069792,40.0298881530762,1.99653286596132,17.0799996703863,0.00217848812978993,0.000383935407831085,0.25,-7.42086195834477E-7,0.000192786148976752,6.85263245800548E-7,9.9959641,9.9959641,-68013.390625,-68003.5078125,57.3191642007561,20.5222614077637,10.38052,0,0,0,40,4449,10.0143,-68008.44921875,,,,,,,,,,,,,0,,,,0,,,,,,9.9959641,,,,
,27466213.86,9.9960022,-72797.71875,0.000211346710770621,7.08650906180308E-7,1,0.999253354069792,40.0298881530762,1.99663709541332,17.0799996703863,0.00239040545333489,0.000423904025407278,0.25,-5.78399266664515E-7,0.000211568151432227,9.76926926496079E-7,9.9960022,9.9960022,-72800.3203125,-72795.1171875,57.0979633298137,20.5233918422306,11.139823,0,0,0,40,4449,10.0189,-72797.71875,,,,,,,,,,,,,0,,,,0,,,,,,9.9960022,,,,
,27466313.23,9.9955368,-77764.74609375,0.000228904610110266,8.85027200503007E-7,1,0.999253354069792,40.0298881530762,1.99654899819071,17.0799996703863,0.00258781755749345,0.000470862779718111,0.25,4.14252741917218E-7,0.000229227317930845,2.08399608287844E-6,9.9955368,9.9955368,-77772.2890625,-77757.203125,57.1565854687561,20.5227858011223,10.38052,0,0,0,40,4449,10.0229,-77764.74609375,,,,,,,,,,,,,0,,,,-0.00245,,,,,,9.9955368,,,,
,27466410.35,9.9956179,-82616.7734375,0.000247187277687669,7.25997304283717E-7,1,0.999253354069792,40.0298881530762,1.99640485137173,17.0799996703863,0.00279335741942809,0.000519559834158369,0.25,1.43579717175531E-6,0.000247618434458329,3.22007146268138E-6,9.9956179,9.9956179,-82619.1640625,-82614.3828125,57.129228470583,20.5230156470273,10.760172,0,0,0,40,4449,10.0264,-82616.7734375,,,,,,,,,,,,,0,,,,0,,,,,,9.9956179,,,,
,27466502.195,9.9955339,-87206.3359375,0.000264056036665804,7.9039021506456E-7,1,0.999253354069792,40.0298881530762,1.99639176491603,17.0799996703863,0.00298571925599584,0.000550785285734334,0.25,1.16901595922888E-6,0.00026460459805377,3.05074167833109E-6,9.9955339,9.9955339,-87211.53125,-87201.140625,56.9580518248714,20.5212803713169,10.760172,0,0,0,40,4449,10.02995,-87206.3359375,,,,,,,,,,,,,0,,,,-0.00245,,,,,,9.9955339,,,,
,27466609.915,9.9974852,-88325.1875,0.000267423911340454,7.4062454230364E-7,1,0.999253354069792,40.0298881530762,1.99640790582941,17.0799996703863,0.00302565986412418,0.000548917228931244,0.25,4.00480180976511E-7,0.000268005301864493,2.29826047766551E-6,9.9974852,9.9974852,-88327.7734375,-88322.6015625,57.281646031833,20.5217079067659,10.38052,0,0,0,40,4449,10.0329,-88325.1875,,,,,,,,,,,,,0,,,,0,,,,,,9.9974852,,,,
,27466702.09,9.9999628,-83718.421875,0.000251230657499766,8.10886917419705E-7,1,0.999253354069792,40.0298881530762,1.99650452917047,17.0799996703863,0.00284161661448268,0.00051586397949049,0.25,3.80909574839403E-7,0.000251696569564339,2.18722052245625E-6,9.9999628,9.9999628,-83720.90625,-83715.9375,57.1948852661984,20.5236215094119,10.760172,0,0,0,40,4449,10.03175,-83718.421875,,,,,,,,,,,,,0,,,,0,,,,,,9.9999628,,,,
,27466800.275,10.0024271,-78811.12890625,0.000232677681155031,7.04076569247336E-7,1,0.999253354069792,40.0298881530762,1.99649593653059,17.0799996703863,0.00263128336016236,0.000474947999878044,0.25,9.77908349973628E-8,0.000233026733450256,1.79066939661402E-6,10.0024271,10.0024271,-78818.9296875,-78803.328125,57.3011867448138,20.5231677073959,11.139823,0,0,0,40,4449,10.0299,-78811.12890625,,,,,,,,,,,,,0,,,,0,,,,,,10.0024271,,,,
,27466900.04,10.0027905,-73826.375,0.000214581645871989,8.10127431886783E-7,1,0.999253354069792,40.0298881530762,1.99642699970879,17.0799996703863,0.00242485179463249,0.000442048430767985,0.25,4.47393686082925E-7,0.000214816855554191,2.0248339356919E-6,10.0027905,10.0027905,-73831.40625,-73821.34375,57.1972301517561,20.5223813445717,10.760172,0,0,0,40,4449,10.02645,-73826.375,,,,,,,,,,,,,0,,,,0,,,,,,10.0027905,,,,
,27466999.135,10.0039711,-68874.87890625,0.000196448180433836,7.802888512291E-7,1,0.999253354069792,40.0298881530762,1.99633114894668,17.0799996703863,0.00222006268190018,0.000398166469687747,0.25,-1.62914037473559E-7,0.000196586589313892,1.29140247627174E-6,10.0039711,10.0039711,-68879.765625,-68869.9921875,57.1644017539484,20.5247427319619,11.139823,0,0,0,40,4449,10.023,-68874.87890625,,,,,,,,,,,,,0,,,,-0.00245,,,,,,10.0039711,,,,
,27467098.095,10.0038462,-63930.267578125,0.00017879231324799,6.53683769621206E-7,1,0.999253354069792,40.0298881530762,1.99632519700998,17.0799996703863,0.00201963119658512,0.000362317770502262,0.25,-1.46200663549559E-7,0.000178840347163962,1.18327826565856E-6,10.0038462,10.0038462,-63937.67578125,-63922.859375,57.2253687784484,20.5216612341575,10.760172,0,0,0,40,4449,10.01955,-63930.267578125,,,,,,,,,,,,,0,,,,0,,,,,,10.0038462,,,,
,27467197.135,10.0040779,-58980.408203125,0.000161133509419148,1.10076135043005E-6,1,0.999253354069792,40.0298881530762,1.9964248528949,17.0799996703863,0.00182197102186919,0.000312191370102408,0.25,-1.39178185992215E-6,0.000161112264796214,-1.9225669917489E-7,10.0040779,10.0040779,-58985.46875,-58975.34765625,57.1636201254291,20.5209578065816,10.760172,0,0,0,40,4449,10.0158,-58980.408203125,,,,,,,,,,,,,0,,,,-0.00245,,,,,,10.0040779,,,,
,27467296.06,10.003933,-54035.486328125,0.000142475818863674,6.41032319403808E-7,1,0.999253354069792,40.0298881530762,1.99628588648855,17.0799996703863,0.00160910327064531,0.000281563150356606,0.25,-7.25192879810842E-7,0.000142385025265985,3.32350670113524E-7,10.003933,10.003933,-54043.0546875,-54027.91796875,57.3050948874099,20.5203354669591,10.38052,0,0,0,40,4449,10.0116,-54035.486328125,,,,,,,,,,,,,0,,,,0.00245,,,,,,10.003933,,,,
,27467394.195,10.003686,-49131.216796875,0.000125642042803731,5.36910221058871E-7,1,0.999253354069792,40.0298881530762,1.99638521651818,17.0799996703863,0.00141929353140208,0.000242957032981157,0.25,-1.09639172896042E-6,0.000125503394011001,-1.70063518824096E-7,10.003686,10.003686,-49136.328125,-49126.10546875,57.0557553897753,20.5253746579994,10.760172,0,0,0,40,4449,10.009,-49131.216796875,,,,,,,,,,,,,0,,,,0,,,,,,10.003686,,,,
,27467492.825,10.0038071,-44200.8125,0.000107638904059957,6.83170235591765E-7,1,0.999253354069792,40.0298881530762,1.99636371003453,17.0799996703863,0.00121553946925256,0.000206647151015154,0.25,-1.05269020867648E-6,0.000107465996888586,-2.68552843807233E-7,10.0038071,10.0038071,-44208.33984375,-44193.28515625,57.2081729510253,20.5242138678422,10.760172,0,0,0,40,4449,10.0044,-44200.8125,,,,,,,,,,,,,0,,,,0,,,,,,10.0038071,,,,
,27467588.98,10.0037069,-39396.21875,8.98054498060716E-5,6.59291130889817E-7,1,0.999253354069792,40.0298881530762,1.99638951550013,17.0799996703863,0.00101551444590789,0.00016194679951028,0.25,-1.78788913532924E-6,8.96221225172028E-5,-1.14295974107696E-6,10.0037069,10.0037069,-39401.125,-39391.3125,57.220679007333,20.5224351709147,11.139823,0,0,0,40,4449,10.00245,-39396.21875,,,,,,,,,,,,,0,,,,0,,,,,,10.0037069,,,,
,27467685.82,10.0029936,-34556.724609375,7.32251167038566E-5,6.02334724700357E-7,1,0.999253354069792,40.0298881530762,1.9963707436039,17.0799996703863,0.000827162121063907,0.000134344604513662,0.25,-1.23522612990259E-6,7.30362245038395E-5,-7.21848552013415E-7,10.0029936,10.0029936,-34564.328125,-34549.12109375,56.9064643426022,20.5213765096763,11.139823,0,0,0,40,4449,9.9995,-34556.724609375,,,,,,,,,,,,,0,,,,0.0049,,,,,,10.0029936,,,,
,27467781.915,10.0019045,-29754.5361328125,5.56701440849819E-5,4.9936139909982E-7,1,0.999253354069792,40.0298881530762,1.99636510189546,17.0799996703863,0.000629781155304473,9.51377190118303E-5,0.25,-1.54449603639685E-6,5.55021909026701E-5,-1.16362821348477E-6,10.0019045,10.0019045,-29756.884765625,-29752.1875,56.8728543162753,20.5243888798759,10.760172,0,0,0,40,4449,9.9971,-29754.5361328125,,,,,,,,,,,,,0,,,,0,,,,,,10.0019045,,,,
,27467877.265,10.0013046,-24987.466796875,4.01489032277928E-5,4.44549814788444E-7,1,0.999253354069792,40.0298881530762,1.99643321672767,17.0799996703863,0.00045286119705964,7.4817121755166E-5,0.25,-5.49569386693543E-7,4.00040012955651E-5,-2.86536660237479E-7,10.0013046,10.0013046,-24994.9296875,-24980.00390625,57.1284468420637,20.5216478785606,10.760172,0,0,0,40,4449,9.9981,-24987.466796875,,,,,,,,,,,,,0,,,,0,,,,,,10.0013046,,,,
,27467973.915,10.0011702,-20159.6904296875,2.38009865311534E-5,4.08141283371905E-7,1,0.999253354069792,40.0298881530762,1.99642284376076,17.0799996703863,0.000268777960658292,4.18361648305871E-5,0.25,-5.40675864341702E-7,2.37048477372834E-5,-3.90674471386025E-7,10.0011702,10.0011702,-20162.345703125,-20157.03515625,57.2738297466407,20.5243950009585,10.760172,0,0,0,40,4449,9.9969,-20159.6904296875,,,,,,,,,,,,,0,,,,-0.0049,,,,,,10.0011702,,,,
,27468066.43,10.0000248,-15532.6694335938,7.67036906503268E-6,3.31350438914687E-7,1,0.999253354069792,40.0298881530762,1.99636091356149,17.0799996703863,8.77559561806266E-5,6.88378103563259E-6,0.25,-7.58245283312703E-7,7.63942344390772E-6,-7.09527641496918E-7,9.9999981,10.0000515,-15565.232421875,-15500.1064453125,57.2996234877753,20.5191587284138,10.760172,0,0,0,40,4449,9.9969,-15532.6694335938,,,,,,,,,,,,,0,,,,0,,,,,,10.0000248,,,,
,27468164.415,9.9988995,-10637.7221679688,-8.38338339290663E-6,3.26991158949259E-7,1,0.999253354069792,40.0298881530762,1.99641374895494,17.0799996703863,-9.30937984251368E-5,-2.30970451948236E-5,0.25,-5.60270484208094E-7,-8.3380057254228E-6,-6.03898508740127E-7,9.9988995,9.9988995,-10642.7275390625,-10632.716796875,56.8908317722176,20.5198916809373,10.38052,0,0,0,40,4449,9.9977,-10637.7221679688,,,,,,,,,,,,,0,,,,-0.00245,,,,,,9.9988995,,,,
,27468255.24,9.9993458,-6094.38598632813,-2.2892848921132E-5,3.3597728677942E-7,1,0.999253354069792,40.0298881530762,1.99640475452406,17.0799996703863,-0.000255939393888251,-5.28834684369282E-5,0.25,-6.32679526115955E-7,-2.27661143415117E-5,-7.48456620601971E-7,9.9993458,9.9993458,-6099.52734375,-6089.24462890625,56.7165286124291,20.5178257178027,10.760172,0,0,0,40,4449,9.9993,-6094.38598632813,,,,,,,,,,,,,0,,,,-0.00245,,,,,,9.9993458,,,,
,27468348.07,10.0006399,-1455.28698730469,-3.38972532946204E-5,3.36662512184534E-7,1,0.999253354069792,40.0298881530762,1.99635991652352,17.0799996703863,-0.000379855856924438,-7.26248919542847E-5,0.25,-4.44000541113092E-7,-3.37024532669359E-5,-6.07296662182288E-7,10.0006399,10.0006399,-1460.29602050781,-1450.27795410156,56.9916618511983,20.5179109530267,10.760172,0,0,0,40,4449,9.9983,-1455.28698730469,,,,,,,,,,,,,0,,,,0,,,,,,10.0006399,,,,
,27468439.61,9.9997702,3114.77844238281,-4.24664140161676E-5,3.7269358396495E-7,1,0.999253354069792,40.0298881530762,1.9964091128498,17.0799996703863,-0.000476356208612812,-8.86434096784262E-5,0.25,-3.42436054502613E-7,-4.2227347732082E-5,-5.52726165133759E-7,9.9997702,9.9997702,3107.12060546875,3122.43627929687,56.9564885678329,20.5176035650205,10.760172,0,0,0,40,4449,9.99845,3114.77844238281,,,,,,,,,,,,,0,,,,-0.0049,,,,,,9.9997702,,,,
,27468532.565,9.9986734,7761.97778320312,-5.36444854833357E-5,3.54024483594044E-7,1,0.999253354069792,40.0298881530762,1.99634563683182,17.0799996703863,-0.000602256228542549,-0.000110109193885704,0.25,-2.45719393416769E-7,-5.33604841982109E-5,-5.30271121130993E-7,9.9986734,9.9986734,7756.9169921875,7767.03857421875,57.0471574760637,20.5161227230033,10.38052,0,0,0,40,4449,9.9988,7761.97778320312,,,,,,,,,,,,,0,,,,0,,,,,,9.9986734,,,,
,27468627.105,10.0006495,12487.5966796875,-6.54674308328455E-5,4.35984196609081E-7,1,0.999253354069792,40.0298881530762,1.99630590287987,17.0799996703863,-0.000735542901779539,-0.000132836689174333,0.25,-1.3570579427895E-7,-6.51467254774913E-5,-5.06687748106775E-7,10.0006495,10.0006495,12485.3447265625,12489.8486328125,57.1042163579676,20.513250728167,10.760172,0,0,0,40,4449,9.9987,12487.5966796875,,,,,,,,,,,,,0,,,,-0.00245,,,,,,10.0006495,,,,
,27468722.595,10.0004263,17260.234375,-7.27959207534643E-5,5.10443446797061E-7,1,0.999253354069792,40.0298881530762,1.99634814327423,17.0799996703863,-0.000817721834239764,-0.0001507322844236,0.25,-3.89516048694604E-7,-7.24690901388842E-5,-8.25626496883439E-7,10.0004263,10.0004263,17252.568359375,17267.900390625,57.2042648084291,20.5181013365491,10.760172,0,0,0,40,4449,9.99735,17260.234375,,,,,,,,,,,,,0,,,,0,,,,,,10.0004263,,,,
,27468817.61,10.0005541,22010.1591796875,-7.37412950883433E-5,3.96187884630198E-7,1,0.999253354069792,40.0298881530762,1.99632728463498,17.0799996703863,-0.00082927502633846,-0.000149634975719182,0.25,-9.4160294273678E-8,-7.3445870889227E-5,-5.6013307762252E-7,10.0005541,10.0005541,22000.125,22020.193359375,56.7634263235829,20.5160330574216,10.760172,0,0,0,40,4449,9.99695,22010.1591796875,,,,,,,,,,,,,0,,,,0.00245,,,,,,10.0005541,,,,
,27468912.69,10.0002775,26763.443359375,-7.26843979970061E-5,5.18356824939935E-7,1,0.999253354069792,40.0298881530762,1.99640945693804,17.0799996703863,-0.000818477183316492,-0.000143897221264026,0.25,2.53196525707179E-7,-7.24305299652564E-5,-2.27354105779944E-7,10.0002775,10.0002775,26753.646484375,26773.240234375,56.8587850029291,20.5184108295522,10.760172,0,0,0,40,4449,9.9962,26763.443359375,,,,,,,,,,,,,0,,,,0,,,,,,10.0002775,,,,
,27469009.725,10.0005941,31613.56640625,-7.70874062018948E-5,5.75757393354889E-7,1,0.999253354069792,40.0298881530762,1.9962973029709,17.0799996703863,-0.00086815961607223,-0.000154330454071554,0.25,1.40637705386095E-7,-7.68564369026597E-5,-3.87058447572877E-7,10.0005941,10.0005941,31606.37890625,31620.75390625,56.8220484625252,20.5151002134174,11.139823,0,0,0,40,4449,9.9971,31613.56640625,,,,,,,,,,,,,0,,,,0,,,,,,10.0005941,,,,
,27469105.41,10.0002346,36393.705078125,-8.72333160338639E-5,6.29740893563742E-7,1,0.999253354069792,40.0298881530762,1.9963265167196,17.0799996703863,-0.000983547758095601,-0.000171341829067734,0.25,4.77154832127895E-7,-8.70184093787748E-5,-1.3780076905229E-7,10.0002346,10.0002346,36383.68359375,36403.7265625,56.9729027667368,20.5157691506239,11.139823,0,0,0,40,4449,9.9975,36393.705078125,,,,,,,,,,,,,0,,,,-0.00245,,,,,,10.0002346,,,,
,27469201.64,9.9993773,41206.09375,-9.96646500019671E-5,6.36655630219068E-7,1,0.999253354069792,40.0298881530762,1.99636949730319,17.0799996703863,-0.00112508296245081,-0.000191567978068856,0.25,9.41541677861721E-7,-9.9472880126321E-5,2.22900125901099E-7,9.9993773,9.9993773,41196.0546875,41216.1328125,56.8197035769676,20.5138134992744,10.760172,0,0,0,40,4449,9.998,41206.09375,,,,,,,,,,,,,0,,,,0,,,,,,9.9993773,,,,
,27469296.82,9.997921,45961.33203125,-0.000114714972107114,6.89665707696754E-7,1,0.999253354069792,40.0298881530762,1.99632249695174,17.0799996703863,-0.0012939503180147,-0.000229765509056817,0.25,2.83754748727352E-7,-0.000114545653382823,-5.54841875880002E-7,9.997921,9.997921,45953.73828125,45968.92578125,56.7876568076791,20.5122780073566,10.38052,0,0,0,40,4449,10.0004,45961.33203125,,,,,,,,,,,,,0,,,,-0.0049,,,,,,9.997921,,,,
,27469394.91,9.9973021,50864.0078125,-0.000132185189239497,6.96088040191617E-7,1,0.999253354069792,40.0298881530762,1.99646016456289,17.0799996703863,-0.00149321397016795,-0.000257385118375796,0.25,1.00392508774369E-6,-0.000132061498907321,2.6529793693907E-8,9.9973021,9.9973021,50861.52734375,50866.48828125,56.9377294833714,20.5158571352791,10.760172,0,0,0,40,4449,10.0025,50864.0078125,,,,,,,,,,,,,0,,,,-0.00245,,,,,,9.9973021,,,,
,27469494.94,9.9963255,55864.134765625,-0.000148566179480008,7.62606705453841E-7,1,0.999253354069792,40.0298881530762,1.99629854051144,17.0799996703863,-0.00167840594761942,-0.000292502892389139,0.25,8.59793959991777E-7,-0.000148498931691107,-2.44713122342519E-7,9.9963255,9.9963255,55859.07421875,55869.1953125,56.9963516223137,20.5138868819241,11.139823,0,0,0,40,4449,10.0051,55864.134765625,,,,,,,,,,,,,0,,,,-0.00245,,,,,,9.9963255,,,,
,27469592.5,9.9967203,60739.361328125,-0.000166735211728789,7.37689991531062E-7,1,0.999253354069792,40.0298881530762,1.99633461968534,17.0799996703863,-0.00188265908322765,-0.000339074376844748,0.25,2.3913251890446E-8,-0.000166730281002928,-1.21718358267853E-6,9.9967203,9.9967203,60731.80859375,60746.9140625,57.0948368157368,20.5147798254462,10.760172,0,0,0,40,4449,10.00905,60739.361328125,,,,,,,,,,,,,0,,,,-0.00245,,,,,,9.9967203,,,,
,27469688.46,9.9959908,65537.478515625,-0.000184379386321424,9.22166855538673E-7,1,0.999253354069792,40.0298881530762,1.99637280922647,17.0799996703863,-0.00208182753900633,-0.000380707149595831,0.25,-4.71001676958818E-7,-0.000184450887953891,-1.84080127098136E-6,9.9959908,9.9959908,65529.94921875,65545.0078125,56.8564401173714,20.5149852360504,10.38052,0,0,0,40,4449,10.013,65537.478515625,,,,,,,,,,,,,0,,,,0,,,,,,9.9959908,,,,
,27469781.675,9.9960117,70195.16015625,-0.00020127524903309,7.5260989773753E-7,1,0.999253354069792,40.0298881530762,1.99628856701464,17.0799996703863,-0.00227463493426994,-0.000409028483944366,0.25,7.21114960802407E-8,-0.000201438991784923,-1.41546833372572E-6,9.9960117,9.9960117,70187.5703125,70202.75,57.1300100991022,20.5103975519596,10.760172,0,0,0,40,4449,10.0166,70195.16015625,,,,,,,,,,,,,0,,,,-0.00245,,,,,,9.9960117,,,,
,27469877.86,9.9955006,75002.86328125,-0.000218390679043621,9.08812009008324E-7,1,0.999253354069792,40.0298881530762,1.99637749993328,17.0799996703863,-0.00246849561767464,-0.000447564133177378,0.25,-2.49939670764851E-7,-0.000218652248400213,-1.85171058316146E-6,9.9955006,9.9955006,74990.28125,75015.4453125,57.1175040427945,20.5103851698814,10.760172,0,0,0,40,4449,10.01895,75002.86328125,,,,,,,,,,,,,0,,,,0.00245,,,,,,9.9955006,,,,
,27469972.845,9.9950843,79751.29296875,-0.000235567081693115,8.23724500062461E-7,1,0.999253354069792,40.0298881530762,1.99630621657603,17.0799996703863,-0.00266447847175362,-0.000477657981609695,0.25,1.78208030212508E-7,-0.000235939254082363,-1.53154597225982E-6,9.9950562,9.9951124,79743.859375,79758.7265625,57.1948852661984,20.5135286446098,11.139823,0,0,0,40,4449,10.0233,79751.29296875,,,,,,,,,,,,,0,,,,0.00245,,,,,,9.9950843,,,,
,27470067.6,9.9956255,84489.7734375,-0.00025324341499007,8.66361365778915E-7,1,0.999253354069792,40.0298881530762,1.9964236013894,17.0799996703863,-0.0028663424792006,-0.000509367925138548,0.25,5.52323080826614E-7,-0.000253733670482293,-1.26288124495818E-6,9.9956255,9.9956255,84482.2265625,84497.3203125,56.8712910592368,20.5153274408434,11.139823,0,0,0,40,4449,10.0275,84489.7734375,,,,,,,,,,,,,0,,,,0,,,,,,9.9956255,,,,
,27470155.15,9.9952316,88862.84765625,-0.000269059596181657,1.00542578947849E-6,1,0.999253354069792,40.0298881530762,1.99633132638583,17.0799996703863,-0.00304363047654769,-0.00055523934782341,0.25,-6.6810028965037E-7,-0.000269652349846712,-2.57498486306186E-6,9.9952316,9.9952316,88860.359375,88865.3359375,56.7165286124291,20.5123695015363,10.38052,0,0,0,40,4449,10.0311,88862.84765625,,,,,,,,,,,,,0,,,,0.00245,,,,,,9.9952316,,,,
,27470262.795,9.9986544,86746.14453125,-0.000261151527320329,7.98680687993676E-7,1,0.999253354069792,40.0298881530762,1.99633511064723,17.0799996703863,-0.00295318356695193,-0.000542034314246548,0.25,-9.18466215471296E-7,-0.000261687515564489,-2.78146309297864E-6,9.9986544,9.9986544,86743.765625,86748.5234375,56.760299809506,20.5125133424636,10.38052,0,0,0,40,4449,10.0321,86746.14453125,,,,,,,,,,,,,0,,,,0,,,,,,9.9986544,,,,
,27470355.07,10.0008068,82135,-0.000244971429261235,8.71492247743435E-7,1,0.999253354069792,40.0298881530762,1.99634729593696,17.0799996703863,-0.0027701992850203,-0.000503452618355718,0.25,-4.11315367689338E-7,-0.000245397422075746,-2.17996477872376E-6,10.0008068,10.0008068,82130.1953125,82139.8046875,56.9807190519291,20.5144829624494,10.760172,0,0,0,40,4449,10.03135,82135,,,,,,,,,,,,,0,,,,0.0049,,,,,,10.0008068,,,,
,27470451.72,10.0020494,77301.2578125,-0.000227015901143008,9.41890379480173E-7,1,0.999253354069792,40.0298881530762,1.99638876897972,17.0799996703863,-0.00256753206904527,-0.000459399952322362,0.25,2.56371126058357E-7,-0.000227332666030286,-1.40030404071969E-6,10.0020494,10.0020494,77291.234375,77311.28125,56.9471090256022,20.5118257733695,11.139823,0,0,0,40,4449,10.02875,77301.2578125,,,,,,,,,,,,,0,,,,0.00245,,,,,,10.0020494,,,,
,27470549.955,10.0031147,72390.5390625,-0.000208391317020287,8.73337771172271E-7,1,0.999253354069792,40.0298881530762,1.9963714787444,17.0799996703863,-0.00235596112160172,-0.00042146051118887,0.25,2.57201097797624E-7,-0.000208600378960455,-1.27773229656177E-6,10.0031147,10.0031147,72388.28125,72392.796875,57.1300100991022,20.5104114607592,10.38052,0,0,0,40,4449,10.02535,72390.5390625,,,,,,,,,,,,,0,,,,-0.0049,,,,,,10.0031147,,,,
,27470649.22,10.0034161,67430.109375,-0.000189947357698751,1.0927952480787E-6,1,0.999253354069792,40.0298881530762,1.99635118647838,17.0799996703863,-0.00214490043528556,-0.000392986984683762,0.25,-5.51745449837961E-7,-0.000190052192210484,-1.96063095979881E-6,10.0034161,10.0034161,67425.171875,67435.046875,56.739977468006,20.5053582791834,11.139823,0,0,0,40,4449,10.02095,67430.109375,,,,,,,,,,,,,0,,,,-0.0049,,,,,,10.0034161,,,,
,27470747.28,10.0041389,62527.126953125,-0.000172975582591794,6.49116764592862E-7,1,0.999253354069792,40.0298881530762,1.9963557799944,17.0799996703863,-0.00195361052076318,-0.000351012670722472,0.25,9.61904924806784E-8,-0.000172999608936869,-1.19086518274077E-6,10.0041389,10.0041389,62517.23046875,62537.0234375,57.108906129083,20.5041382661393,11.139823,0,0,0,40,4449,10.01815,62527.126953125,,,,,,,,,,,,,0,,,,-0.0049,,,,,,10.0041389,,,,
,27470843.805,10.0036936,57703.259765625,-0.000155659124969286,6.50821453988022E-7,1,0.999253354069792,40.0298881530762,1.99644127438746,17.0799996703863,-0.00175769384912993,-0.000313625304967952,0.25,2.74500807656214E-7,-0.000155611678864883,-8.83624098010266E-7,10.0036936,10.0036936,57698.07421875,57708.4453125,57.044812590506,20.5089699452846,10.760172,0,0,0,40,4449,10.0144,57703.259765625,,,,,,,,,,,,,0,,,,0,,,,,,10.0036936,,,,
,27470941.47,10.0036831,52820.669921875,-0.000137401413870728,6.99714987979435E-7,1,0.999253354069792,40.0298881530762,1.99641815738597,17.0799996703863,-0.00155006175873689,-0.000280633858089365,0.25,-1.09806077386214E-7,-0.000137291291384502,-1.12764368205509E-6,10.0036831,10.0036831,52810.23046875,52831.109375,57.0205821064099,20.5113951678337,10.38052,0,0,0,40,4449,10.0112,52820.669921875,,,,,,,,,,,,,0,,,,-0.0049,,,,,,10.0036831,,,,
,27471037.255,10.0038414,48035.763671875,-0.000121221070804297,6.7246696181169E-7,1,0.999253354069792,40.0298881530762,1.99644723344873,17.0799996703863,-0.00136680768420779,-0.000247885456169544,0.25,-1.40987630758845E-7,-0.000121064882066365,-1.03117634361642E-6,10.0038414,10.0038414,48028.46875,48043.05859375,57.0229269919676,20.5106574473075,10.38052,0,0,0,40,4449,10.00765,48035.763671875,,,,,,,,,,,,,0,,,,0,,,,,,10.0038414,,,,
,27471133.955,10.0037184,43200.599609375,-0.000102843593132741,6.13077389413151E-7,1,0.999253354069792,40.0298881530762,1.99648560647281,17.0799996703863,-0.00115974480845723,-0.000206249699618732,0.25,2.21145862575958E-7,-0.000102661907677777,-5.24304308292322E-7,10.0037184,10.0037184,43195.59375,43205.60546875,57.0635716749676,20.5112773540151,11.139823,0,0,0,40,4449,10.0054,43200.599609375,,,,,,,,,,,,,0,,,,0,,,,,,10.0037184,,,,
,27471228.72,10.003417,38465.38671875,-8.6572077610366E-5,6.74725791243942E-7,1,0.999253354069792,40.0298881530762,1.99642421543967,17.0799996703863,-0.000975871613213832,-0.000172769821282525,0.25,2.41687561722527E-7,-8.63762243468666E-5,-3.74218873146363E-7,10.003417,10.003417,38457.9296875,38472.84375,57.0565370182945,20.5110397280331,10.38052,0,0,0,40,4449,10.0015,38465.38671875,,,,,,,,,,,,,0,,,,0,,,,,,10.003417,,,,
,27471325.995,10.0029144,33603.109375,-6.96791033609836E-5,6.66340802199504E-7,1,0.999253354069792,40.0298881530762,1.99641373019291,17.0799996703863,-0.000785934360440382,-0.000133987823629317,0.25,6.25770043704904E-7,-6.94884589577928E-5,1.41386797138594E-7,10.0029144,10.0029144,33595.6484375,33610.5703125,57.1620568683907,20.5156051342602,11.139823,0,0,0,40,4449,9.99945,33603.109375,,,,,,,,,,,,,0,,,,-0.0049,,,,,,10.0029144,,,,
,27471423.095,10.0025311,28750.71484375,-5.23989819222253E-5,5.15489325594542E-7,1,0.999253354069792,40.0298881530762,1.99634721578768,17.0799996703863,-0.000589998900854169,-0.000104622313243395,0.25,1.10906412027632E-7,-5.2226320420567E-5,-2.40685231117378E-7,10.0025311,10.0025311,28743.45703125,28757.97265625,56.8759808303522,20.5101514222702,10.38052,0,0,0,40,4449,9.99765,28750.71484375,,,,,,,,,,,,,0,,,,0,,,,,,10.0025311,,,,
,27471519.695,10.0013285,23923.201171875,-3.62350052950446E-5,4.25901806382646E-7,1,0.999253354069792,40.0298881530762,1.99634229085881,17.0799996703863,-0.000408174618493584,-7.01743437232144E-5,0.25,2.5724912555697E-7,-3.60987425048433E-5,2.29419447847231E-8,10.0013285,10.0013285,23915.59375,23930.80859375,56.9385111118906,20.5124490283473,10.38052,0,0,0,40,4449,9.99745,23923.201171875,,,,,,,,,,,,,0,,,,-0.00245,,,,,,10.0013285,,,,
,27471615.315,10.0006437,19143.2333984375,-1.96540817578128E-5,3.64519947112562E-7,1,0.999253354069792,40.0298881530762,1.99641990261812,17.0799996703863,-0.000221340229587764,-3.7813981300117E-5,0.25,1.54355991782497E-7,-1.95709361073736E-5,3.29977881445898E-8,10.0006437,10.0006437,19138.359375,19148.107421875,56.7993812354675,20.515102327417,10.760172,0,0,0,40,4449,9.9965,19143.2333984375,,,,,,,,,,,,,0,,,,0.00245,,,,,,10.0006437,,,,
,27471711.93,9.9996166,14313.66796875,-3.35747773893673E-6,4.18945704763727E-7,1,0.999253354069792,40.0298881530762,1.99643973969192,17.0799996703863,-3.80792871910888E-5,-4.86156596555857E-6,0.25,1.67162248708798E-7,-3.34257770353418E-6,1.46869805811548E-7,9.9996166,9.9996166,14310.8369140625,14316.4990234375,56.9471090256022,20.5166627685485,11.139823,0,0,0,40,4449,9.9976,14313.66796875,,,,,,,,,,,,,0,,,,-0.00245,,,,,,9.9996166,,,,
,27471804.985,9.9990158,9663.72900390625,1.18029908003071E-5,3.47976217979296E-7,1,0.999253354069792,40.0298881530762,1.99643133468614,17.0799996703863,0.000131463724610851,3.02416914011821E-5,0.25,5.87258458721253E-7,1.17393292083694E-5,6.48803031099935E-7,9.9990158,9.9990158,9658.6884765625,9668.76953125,57.0964000727753,20.5157448374279,10.760172,0,0,0,40,4449,9.9976,9663.72900390625,,,,,,,,,,,,,0,,,,0.0049,,,,,,9.9990158,,,,
,27471899.35,9.9994373,4948.21411132812,2.63120538980518E-5,2.76453175076584E-7,1,0.999253354069792,40.0298881530762,1.99646126553519,17.0799996703863,0.000295687310977405,5.21407713914945E-5,0.25,-3.95305037086202E-8,2.61682887072347E-5,9.55068710146848E-8,9.9994373,9.9994373,4940.67431640625,4955.75390625,56.790783321756,20.5179621399518,10.760172,0,0,0,40,4449,9.99885,4948.21411132812,,,,,,,,,,,,,0,,,,0,,,,,,9.9994373,,,,
,27471992.77,10.0019226,279.183212280273,3.70703872803537E-5,3.52854196224477E-7,1,0.999253354069792,40.0298881530762,1.99640735551578,17.0799996703863,0.000416641574639949,7.24385834045941E-5,0.25,-1.3378344703087E-7,3.68583943920166E-5,4.60305948818798E-8,10.0019226,10.0019226,276.651550292969,281.714874267578,57.1206305568714,20.5138763661504,11.139823,0,0,0,40,4449,9.99705,279.183212280273,,,,,,,,,,,,,0,,,,-0.0049,,,,,,10.0019226,,,,
,27471998.76,10.0031099,0.228356599807739,3.76596574685382E-5,3.04175520234605E-7,1,0.999253354069792,40.0298881530762,1.99644667324752,17.0799996703863,0.000424173619014617,6.8495369641564E-5,0.25,-5.89182358874794E-7,3.7446158202754E-5,-4.0428073900088E-7,10.0031099,10.0031099,0.213132828474045,0.243580371141434,57.065134932006,20.5147052612535,10.38052,0,0,0,40,4417,9.9941,0.228356599807739,,,,,,,,,,,,,0,,,,0.0049,,,,,,10.0031099,,,,