File: data/monolayers/nanoparticles/Ac_CoFe_C/vsm/data_disorderedWafer/DD226_2_HYST_300K.DAT
[Header]
; VSM Data File (default extension .dat)
; Copyright (c) 2003-2013, Quantum Design, Inc. All rights reserved.
TITLE,
FILEOPENTIME,27350848.08,11/13/2018,9:27 pm
BYAPP,VSM,2.0,2.0
INFO,PPMS VSM Option Release 1.4.10 Build 1,APPNAME
INFO,Quantum Design Linear Motor Servo Controller,MOTOR_MODULE_NAME
INFO,3101-100 M1,MOTOR_HW_VERSION
INFO,MMC1014,MOTOR_SERIAL_NUMBER
INFO,SRV No X-over 01.03.11,MOTOR_SOFTWARE_VERSION
INFO,Quantum Design VSM Detection Module,VSM_MODULE_NAME
INFO,3101-150 F0,VSM_HW_VERSION
INFO,VSM707,VSM_SERIAL_NUMBER
INFO,VSM No X-over 01.02.05 May 20 2008 13:51:47,VSM_SOFTWARE_VERSION
INFO,704,PREAMP_SERIAL_NUMBER
INFO,822,COIL_SERIAL_NUMBER
INFO,0,MOMENT_UNITS
INFO,CoFe2O4 AH11,SAMPLE_MATERIAL
INFO,Quick Dry Monolayer Conc,SAMPLE_COMMENT
INFO,27.96,SAMPLE_MASS
INFO,,SAMPLE_VOLUME
INFO,,SAMPLE_MOLECULAR_WEIGHT
INFO,,SAMPLE_SIZE
INFO,,SAMPLE_SHAPE
DATATYPE,COMMENT,1
DATATYPE,TIME,2
STARTUPAXIS,X,2
STARTUPAXIS,Y1,5
[Data]
Comment,Time Stamp (sec),Temperature (K),Magnetic Field (Oe),Moment (emu),M. Std. Err. (emu),Transport Action,Averaging Time (sec),Frequency (Hz),Peak Amplitude (mm),Center Position (mm),Coil Signal' (mV),Coil Signal" (mV),Range (mV),M. Quad. Signal (emu),M. Raw' (emu),M. Raw" (emu),Min. Temperature (K),Max. Temperature (K),Min. Field (Oe),Max. Field (Oe),Mass (grams),Motor Lag (deg),Pressure (Torr),VSM Status (code),Motor Status (code),Measure Status (code),Measure Count,PPMS Status (code),System Temp. (K),System Field (Oe),Sample Position (deg),Bridge 1 Resistance (ohms),Bridge 1 Excitation (에),Bridge 2 Resistance (ohms),Bridge 2 Excitation (에),Bridge 3 Resistance (ohms),Bridge 3 Excitation (에),Bridge 4 Resistance (ohms),Bridge 4 Excitation (에),Signal 1 Vin (V),Signal 2 Vin (V),Digital Inputs (code),Drive 1 Iout (mA),Drive 1 Ipower (W),Drive 2 Iout (mA),Drive 2 Ipower (W),Pressure (),Map 20 (),Map 21 (),Map 22 (),Map 23 (),Map 24 (),Map 25 (),Map 26 (),Map 27 (),Map 28 (),Map 29 ()
,27350864.89,300.196991,-0.243580371141434,,,2,,,,20.5900000923872,,,,,,,300.196991,300.196991,-0.243580371141434,-0.243580371141434,,,25.566563,,,,-99999999,4369,300.5102,-0.243580371141434,,,,,,,,,,,,,,,,,,,,,,,300.196991,,,,
,27351013.2,300.1488342,4461.31079101562,1.63084454844055E-5,4.62016326175274E-7,1,0.999253354069792,40.0298881530762,2.0094218305626,20.5799993127584,0.000186447749413629,2.67094286171119E-5,0.25,-4.7748707096642E-7,1.63081889529661E-5,-4.66660260819985E-7,300.1488342,300.1488342,4451.296875,4471.32470703125,56.0795013692559,20.5835457854115,26.325863,0,0,0,40,4449,300.3143,4461.31079101562,,,,,,,,,,,,,0,,,,0.00245,,,,,,300.1488342,,,,
,27351110.775,300.1069336,9337.30517578125,4.11969240625271E-6,5.54382152295789E-7,1,0.999253354069792,40.0298881530762,2.00943782377319,20.5799993127584,4.94586795915358E-5,-6.8711838336101E-6,0.25,-1.31783484100932E-6,4.12042707312296E-6,-1.31506114988727E-6,300.1069336,300.1069336,9327.45703125,9347.1533203125,56.5078337977944,20.5883270771424,25.946213,0,0,0,40,4449,300.2397,9337.30517578125,,,,,,,,,,,,,0,,,,0.0049,,,,,,300.1069336,,,,
,27351207.415,300.0511475,14167.0776367188,-1.15730834873526E-5,8.96059046658598E-7,1,0.999253354069792,40.0298881530762,2.0094528125764,20.5799993127584,-0.000127581029034734,-4.62643481229201E-5,0.25,-2.06202499030216E-6,-1.1571353205076E-5,-2.06962157409885E-6,300.0511475,300.0511475,14154.4375,14179.7177734375,56.455464687006,20.5908952033764,26.705515,0,0,0,40,4449,300.21455,14167.0776367188,,,,,,,,,,,,,0,,,,0.00245,,,,,,300.0511475,,,,
,27351307.26,300.0269165,19156.9951171875,-2.71159793302369E-5,8.37082088804091E-7,1,0.999253354069792,40.0298881530762,2.00943018394836,20.5799993127584,-0.000304743404921845,-7.47984980291263E-5,0.25,-1.87764031480461E-6,-2.7113906768528E-5,-1.89551857991195E-6,300.0269165,300.0269165,19146.7421875,19167.248046875,56.5093970548329,20.5916423243435,25.946213,0,0,0,40,4449,300.1934,19156.9951171875,,,,,,,,,,,,,0,,,,0,,,,,,300.0269165,,,,
,27351405.045,299.9998779,24044.439453125,-4.67227835532063E-5,1.09171858016146E-6,1,0.999253354069792,40.0298881530762,2.00933226724193,20.5799993127584,-0.000525456462075804,-0.000126652460011554,0.25,-3.03973955910751E-6,-4.67193922979212E-5,-3.07052082261197E-6,299.9998779,299.9998779,24039.611328125,24049.267578125,56.3616692646983,20.5935664714186,26.325863,0,0,0,40,4449,300.2184,24044.439453125,,,,,,,,,,,,,0,,,,0.0049,,,,,,299.9998779,,,,
,27351502.955,299.9898376,28937.486328125,-6.24166312578073E-5,1.48198399602486E-6,1,0.999253354069792,40.0298881530762,2.00923156850881,20.5799993127584,-0.000701315832708145,-0.000172674960122846,0.25,-4.36755158850645E-6,-6.24119277232466E-5,-4.40862094360087E-6,299.9898376,299.9898376,28932.404296875,28942.568359375,56.7345060683714,20.5939845241307,26.325863,0,0,0,40,4449,300.22845,28937.486328125,,,,,,,,,,,,,0,,,,0,,,,,,299.9898376,,,,
,27351601.02,299.9870605,33839.923828125,-8.06800611261201E-5,1.09416893656167E-6,1,0.999253354069792,40.0298881530762,2.00904025717131,20.5799993127584,-0.000908996744828167,-0.00020843692670048,0.25,-4.34921704259939E-6,-8.06748534662244E-5,-4.40228277298772E-6,299.9870605,299.9870605,33835.06640625,33844.78125,56.7165286124291,20.5967555876521,26.705515,0,0,0,40,4449,300.24165,33839.923828125,,,,,,,,,,,,,0,,,,0,,,,,,299.9870605,,,,
,27351697.74,299.9831085,38672.287109375,-9.8648433027907E-5,2.04167280451379E-6,1,0.999253354069792,40.0298881530762,2.00893642630578,20.5799993127584,-0.00111217930471238,-0.000250268097740461,0.25,-4.91538923631304E-6,-9.86423551350921E-5,-4.98021256475277E-6,299.9824829,299.9837341,38667.4375,38677.13671875,56.7251265261406,20.5976995888883,26.325863,0,0,0,40,4449,300.2554,38672.287109375,,,,,,,,,,,,,0,,,,0,,,,,,299.9831085,,,,
,27351796.015,299.9873047,43584.84765625,-0.000116787213755753,1.55986717418958E-6,1,0.999253354069792,40.0298881530762,2.00885780095707,20.5799993127584,-0.00131601489235089,-0.000299823822172308,0.25,-6.13139107429317E-6,-0.00011677980749681,-6.20803682366888E-6,299.9873047,299.9873047,43574.640625,43595.0546875,56.7360693254098,20.5991744087966,26.325863,0,0,0,40,4449,300.2593,43584.84765625,,,,,,,,,,,,,0,,,,-0.00245,,,,,,299.9873047,,,,
,27351891.735,299.9924622,48367.443359375,-0.000132765672489143,1.65134159319766E-6,1,0.999253354069792,40.0298881530762,2.00918197378071,20.5799993127584,-0.00150009952792249,-0.000318955267432252,0.25,-5.0411831175407E-6,-0.000132758510037319,-5.12827024878378E-6,299.9924622,299.9924622,48362.69921875,48372.1875,56.5305010248521,20.5965605401141,25.946213,0,0,0,40,4449,300.26775,48367.443359375,,,,,,,,,,,,,0,,,,-0.00245,,,,,,299.9924622,,,,
,27351988.17,299.9966431,53187.388671875,-0.000154092218989204,2.14703759399093E-6,1,0.999253354069792,40.0298881530762,2.00883512247415,20.5799993127584,-0.0017415432292303,-0.000365713778187258,0.25,-5.46281591977569E-6,-0.000154084152423376,-5.56378641833018E-6,299.9966431,299.9966431,53179.83984375,53194.9375,56.4898563418521,20.6027683728924,25.946213,0,0,0,40,4449,300.2695,53187.388671875,,,,,,,,,,,,,0,,,,-0.00245,,,,,,299.9966431,,,,
,27352085.59,300.0026245,58058.228515625,-0.000168347208216664,2.75310366007168E-6,1,0.999253354069792,40.0298881530762,2.00862258587045,20.5799993127584,-0.00189896556241019,-0.000419676644736396,0.25,-7.74228083363955E-6,-0.00016833721232602,-7.85241046158992E-6,300.0026245,300.0026245,58053.265625,58063.19140625,56.6719757868329,20.6051564861143,26.705515,0,0,0,40,4449,300.26705,58058.228515625,,,,,,,,,,,,,0,,,,0,,,,,,300.0026245,,,,
,27352184.485,300.0050049,63001.037109375,-0.000185514371492634,2.35434706733835E-6,1,0.999253354069792,40.0298881530762,2.00843271974323,20.5799993127584,-0.00209469133395536,-0.000449341469205937,0.25,-7.38063974781378E-6,-0.000185504113913202,-7.50188668712486E-6,300.0050049,300.0050049,62996.078125,63005.99609375,56.6829185861022,20.6031964601585,25.946213,0,0,0,40,4449,300.2655,63001.037109375,,,,,,,,,,,,,0,,,,-0.00245,,,,,,300.0050049,,,,
,27352282.59,300.0070496,67903.83203125,-0.000205959911066144,2.4294997798031E-6,1,0.999253354069792,40.0298881530762,2.00840513036935,20.5799993127584,-0.00232686790263538,-0.000491058686289305,0.25,-7.50833007949874E-6,-0.000205948976543125,-7.64280249824335E-6,300.0070496,300.0070496,67894,67913.6640625,56.6539983308906,20.6053743536673,25.946213,0,0,0,40,4449,300.2515,67903.83203125,,,,,,,,,,,,,0,,,,0.0049,,,,,,300.0070496,,,,
,27352381.43,300.0088501,72846.12890625,-0.000225227918324177,3.01832809471604E-6,1,0.999253354069792,40.0298881530762,2.00822245628942,20.5799993127584,-0.00254647996651944,-0.000524547514088688,0.25,-7.11982590343183E-6,-0.000225216681536078,-7.26672928064507E-6,300.0088501,300.0088501,72835.9140625,72856.34375,56.5664559367368,20.6045978271115,26.705515,0,0,0,40,4449,300.2474,72846.12890625,,,,,,,,,,,,,0,,,,0,,,,,,300.0088501,,,,
,27352477.94,300.0176392,77669.40625,-0.000240637479475509,2.88308358563156E-6,1,0.999253354069792,40.0298881530762,2.00816329313016,20.5799993127584,-0.00271875545944953,-0.000571222885813615,0.25,-8.55741525203621E-6,-0.00024062480049866,-8.71415118494956E-6,300.0176392,300.0176392,77659.5703125,77679.2421875,56.9557069393137,20.6065060698736,26.705515,0,0,0,40,4449,300.23885,77669.40625,,,,,,,,,,,,,0,,,,0.00245,,,,,,300.0176392,,,,
,27352579.38,300.0084229,82739.96484375,-0.000257824036941003,2.87432701400779E-6,1,0.999253354069792,40.0298881530762,2.00782607160864,20.5799993127584,-0.00290403026377414,-0.000660615976028649,0.25,-1.34528130849424E-5,-0.000257807772861862,-1.36204089277465E-5,300.0084229,300.0084229,82732.46875,82747.4609375,56.963523224506,20.6121033595259,26.325863,0,0,0,40,4449,300.22855,82739.96484375,,,,,,,,,,,,,0,,,,0,,,,,,300.0084229,,,,
,27352674.985,300.0145569,87518.04296875,-0.000276379116036038,2.98134159449829E-6,1,0.999253354069792,40.0298881530762,2.0076315065466,20.5799993127584,-0.00311461793589158,-0.000697250949808969,0.25,-1.34671917873783E-5,-0.000276362272752045,-1.3646650845534E-5,300.013855,300.0152588,87510.3515625,87525.734375,56.8361177758714,20.6119327934472,26.325863,0,0,0,40,4449,300.22785,87518.04296875,,,,,,,,,,,,,0,,,,0,,,,,,300.0145569,,,,
,27352789.07,300.0126648,87806.12109375,-0.000277313001791841,2.57630149151946E-6,1,0.999253354069792,40.0298881530762,2.00808646935637,20.5799993127584,-0.0031321192304088,-0.000663386058359478,0.25,-1.03131113179745E-5,-0.000277298202517921,-1.04932713662405E-5,300.0126648,300.0126648,87793.6953125,87818.546875,56.8361177758714,20.6082241971709,26.325863,0,0,0,40,4449,300.20775,87806.12109375,,,,,,,,,,,,,0,,,,0,,,,,,300.0126648,,,,
,27352883.24,300.0052795,83097.48046875,-0.000257825375652089,3.14249042877298E-6,1,0.999253354069792,40.0298881530762,2.00804120577339,20.5799993127584,-0.00290934124030221,-0.000631833467650417,0.25,-1.09146471762652E-5,-0.000257810795111177,-1.10823136006475E-5,300.0052795,300.0052795,83090.2265625,83104.734375,56.8845787440637,20.6085972044699,25.946213,0,0,0,40,4449,300.2128,83097.48046875,,,,,,,,,,,,,0,,,,-0.00245,,,,,,300.0052795,,,,
,27352981,299.9953613,78210.734375,-0.000242919251854316,3.20419531172393E-6,1,0.999253354069792,40.0298881530762,2.00789278763316,20.5799993127584,-0.00274374084135182,-0.000579128662980921,0.25,-8.86404278887101E-6,-0.00024290650079039,-9.02225876935282E-6,299.9953613,299.9953613,78205.546875,78215.921875,56.7180918694675,20.6111547304874,26.325863,0,0,0,40,4449,300.2139,78210.734375,,,,,,,,,,,,,0,,,,0.0049,,,,,,299.9953613,,,,
,27353072.935,299.993988,73614.62890625,-0.000226818912814407,3.04106583352393E-6,1,0.999253354069792,40.0298881530762,2.0080211940441,20.5799993127584,-0.00255549138609732,-0.000578609894632152,0.25,-1.16044921137289E-5,-0.000226804823118325,-1.17522972370923E-5,299.993988,299.993988,73612,73617.2578125,56.9377294833714,20.6110214225158,26.325863,0,0,0,40,4449,300.219,73614.62890625,,,,,,,,,,,,,0,,,,0,,,,,,299.993988,,,,
,27353168.655,299.9909363,68829.44140625,-0.000209001115303324,1.94676560798157E-6,1,0.999253354069792,40.0298881530762,2.00822026209375,20.5799993127584,-0.00235697191719166,-0.000521634919748928,0.25,-9.67478312229998E-6,-0.000208988798251862,-9.81117010047629E-6,299.9909363,299.9909363,68819.75,68839.1328125,56.8712910592368,20.6051754806168,26.325863,0,0,0,40,4449,300.2231,68829.44140625,,,,,,,,,,,,,0,,,,-0.0049,,,,,,299.9909363,,,,
,27353266.735,299.99247745,63929.21484375,-0.000190299698479877,2.46879095863794E-6,1,0.999253354069792,40.0298881530762,2.00800724022724,20.5799993127584,-0.00214539400004075,-0.000477558283217737,0.25,-9.04182861747567E-6,-0.000190288300695851,-9.16615151052081E-6,299.9917908,299.9931641,63921.93359375,63936.49609375,56.7220000120637,20.6079913693887,26.705515,0,0,0,40,4449,300.23275,63929.21484375,,,,,,,,,,,,,0,,,,0.00245,,,,,,299.99247745,,,,
,27353364.435,299.9919739,59046.03125,-0.000173815366358125,1.99269053577009E-6,1,0.999253354069792,40.0298881530762,2.00792495474647,20.5799993127584,-0.00196235726188684,-0.000419547630985963,0.25,-6.79579360233623E-6,-0.000173805899723335,-6.9095214235341E-6,299.9919739,299.9919739,59038.734375,59053.328125,56.9236601700253,20.6107350157168,26.325863,0,0,0,40,4449,300.2428,59046.03125,,,,,,,,,,,,,0,,,,-0.0049,,,,,,299.9919739,,,,
,27353458.39,299.9938354,54347.5,-0.000156723455034778,2.39043030540973E-6,1,0.999253354069792,40.0298881530762,2.00792360321723,20.5799993127584,-0.00176437157975898,-0.000407257282409838,0.25,-8.67566754821353E-6,-0.000156713221590142,-8.77825580169306E-6,299.9938354,299.9938354,54340.1015625,54354.8984375,56.9908802226791,20.6128355835975,26.325863,0,0,0,40,4449,300.23955,54347.5,,,,,,,,,,,,,0,,,,-0.00245,,,,,,299.9938354,,,,
,27353554.7,299.9903259,49533.1015625,-0.000137999732296025,1.81463171408546E-6,1,0.999253354069792,40.0298881530762,2.0080050644496,20.5799993127584,-0.00155689447810261,-0.00033984652870395,0.25,-5.98788836600974E-6,-0.000137991808903337,-6.07837037500431E-6,299.9898376,299.9908142,49522.9140625,49543.2890625,57.0620084179291,20.6118268492399,25.946213,0,0,0,40,4449,300.246,49533.1015625,,,,,,,,,,,,,0,,,,0,,,,,,299.9903259,,,,
,27353649.285,299.9942932,44807.66015625,-0.00012030609685506,1.8756411773765E-6,1,0.999253354069792,40.0298881530762,2.00788889597113,20.5799993127584,-0.00135357534733481,-0.000317189542235025,0.25,-7.06166219989152E-6,-0.000120297949893954,-7.14057342944559E-6,299.9942932,299.9942932,44795.27734375,44820.04296875,57.0971817012945,20.6149853071992,26.325863,0,0,0,40,4449,300.25385,44807.66015625,,,,,,,,,,,,,0,,,,-0.00245,,,,,,299.9942932,,,,
,27353746.88,299.9875793,39927.19921875,-0.000103845449003771,1.62829317656645E-6,1,0.999253354069792,40.0298881530762,2.00803382457254,20.5799993127584,-0.00117170324480362,-0.000255064779551206,0.25,-4.44640336586072E-6,-0.000103839516429117,-4.51464082098531E-6,299.9875793,299.9875793,39922.25390625,39932.14453125,57.0823307594291,20.6125593645353,26.325863,0,0,0,40,4449,300.2622,39927.19921875,,,,,,,,,,,,,0,,,,0,,,,,,299.9875793,,,,
,27353844.755,299.9913635,35037.546875,-8.48616458288077E-5,1.7422319397223E-6,1,0.999253354069792,40.0298881530762,2.00807200762893,20.5799993127584,-0.000954531070252219,-0.000225711694558099,0.25,-5.15282312992324E-6,-8.48557770361256E-5,-5.20860119030178E-6,299.9913635,299.9913635,35034.95703125,35040.13671875,56.9557069393137,20.6134269442444,26.325863,0,0,0,40,4449,300.26805,35037.546875,,,,,,,,,,,,,0,,,,0,,,,,,299.9913635,,,,
,27353940.205,299.9890137,30264.79296875,-6.72606077043591E-5,1.54572217944589E-6,1,0.999253354069792,40.0298881530762,2.00835714456411,20.5799993127584,-0.000756663540983003,-0.000178875089332833,0.25,-4.07996871893458E-6,-6.72559579102566E-5,-4.12422227240095E-6,299.9890137,299.9890137,30252.537109375,30277.048828125,56.9095908566791,20.6077438910566,26.705515,0,0,0,40,4449,300.28,30264.79296875,,,,,,,,,,,,,0,,,,-0.00245,,,,,,299.9890137,,,,
,27354037.72,299.9946289,25391.802734375,-5.13505817305415E-5,1.07480190227636E-6,1,0.999253354069792,40.0298881530762,2.00862853765216,20.5799993127584,-0.000576384882892193,-0.000144485248631742,0.25,-3.80999076653737E-6,-5.13465574125166E-5,-3.84378861508955E-6,299.9946289,299.9946289,25379.294921875,25404.310546875,56.7618630665445,20.605192557655,26.325863,0,0,0,40,4449,300.2916,25391.802734375,,,,,,,,,,,,,0,,,,-0.0049,,,,,,299.9946289,,,,
,27354134.57,299.9881897,20552.294921875,-3.26613273943713E-5,9.97033527687883E-7,1,0.999253354069792,40.0298881530762,2.00858312451501,20.5799993127584,-0.000367488632371987,-8.67647842817847E-5,0.25,-1.97191826488548E-6,-3.26590702731782E-5,-1.99344961941801E-6,299.9881897,299.9881897,20542.3671875,20562.22265625,57.0283983916022,20.6086168557527,26.325863,0,0,0,40,4449,300.2977,20552.294921875,,,,,,,,,,,,,0,,,,-0.00245,,,,,,299.9881897,,,,
,27354230.77,299.9921265,15742.6484375,-1.72628828174469E-5,7.13203106290943E-7,1,0.999253354069792,40.0298881530762,2.00907711404993,20.5799993127584,-0.000191609644719004,-6.12745417517442E-5,0.25,-2.39674079423389E-6,-1.72607896778874E-5,-2.40809148971323E-6,299.9921265,299.9921265,15734.8662109375,15750.4306640625,56.7532651528329,20.6072327631464,26.325863,0,0,0,40,4449,300.3019,15742.6484375,,,,,,,,,,,,,0,,,,0,,,,,,299.9921265,,,,
,27354328.29,299.9918518,10870.3212890625,-7.44661343201694E-7,6.2563248025639E-7,1,0.999253354069792,40.0298881530762,2.00877707488676,20.5799993127584,-5.78363892715349E-6,-1.69599012712811E-5,0.25,-1.36242382435086E-6,-7.43737276222239E-7,-1.36287680710274E-6,299.9918518,299.9918518,10862.8359375,10877.806640625,57.014329078256,20.6092047407215,26.705515,0,0,0,40,4449,300.3127,10870.3212890625,,,,,,,,,,,,,0,,,,0.00245,,,,,,299.9918518,,,,
,27354424.9,299.9919434,6040.123046875,1.31492342627726E-5,4.18660486428906E-7,1,0.999253354069792,40.0298881530762,2.00862083663738,20.5799993127584,0.000150670435955059,1.9236257481381E-5,0.25,-5.86477304839215E-7,1.31492351639535E-5,-5.7774568256917E-7,299.9919434,299.9919434,6035.21142578125,6045.03466796875,56.8181403199291,20.6085792535182,26.705515,0,0,0,40,4449,300.30215,6040.123046875,,,,,,,,,,,,,0,,,,-0.00245,,,,,,299.9919434,,,,
,27354516.52,299.99533085,1461.36975097656,1.94252789392714E-5,4.04585729892319E-7,1,0.999253354069792,40.0298881530762,2.00870313731925,20.5799993127584,0.000221219248598469,3.6348306244924E-5,0.25,-1.69058345096204E-7,1.9424815113224E-5,-1.56171747835183E-7,299.9947205,299.9959412,1431.5068359375,1491.23266601562,56.8970848003714,20.608001629329,25.946213,0,0,0,40,4449,300.3087,1461.36975097656,,,,,,,,,,,,,0,,,,0,,,,,,299.99533085,,,,
,27354609.305,300.0000916,-3171.14306640625,-1.86268938317112E-5,4.36645506284505E-7,1,0.999253354069792,40.0298881530762,2.00879704274974,20.5799993127584,-0.0002126676423174,-3.17902873656996E-5,0.25,4.31695345258337E-7,-1.86266248347564E-5,4.19333018017985E-7,300.0000916,300.0000916,-3180.93115234375,-3161.35498046875,56.8650380310829,20.6113663091413,26.325863,0,0,0,40,4449,300.308,-3171.14306640625,,,,,,,,,,,,,0,,,,0,,,,,,300.0000916,,,,
,27354704.49,300.0016785,-7931.04541015625,-7.4188072927845E-6,4.7890897627596E-7,1,0.999253354069792,40.0298881530762,2.00876638902298,20.5799993127584,-8.68098442812977E-5,-4.90002299075105E-7,0.25,1.24228509218385E-6,-7.41940908893539E-6,1.23733298624082E-6,300.0016785,300.0016785,-7941.0654296875,-7921.025390625,56.9095908566791,20.6090414609581,25.946213,0,0,0,40,4449,300.3058,-7931.04541015625,,,,,,,,,,,,,0,,,,0,,,,,,300.0016785,,,,
,27354802.125,300.0062561,-12811.267578125,7.20567190473315E-6,6.52586869121155E-7,1,0.999253354069792,40.0298881530762,2.00903146744711,20.5799993127584,7.94815006506747E-5,2.84398100045569E-5,0.25,1.25223386366597E-6,7.20462727521983E-6,1.25696622950716E-6,300.0062561,300.0062561,-12818.7587890625,-12803.7763671875,57.1339182416984,20.6071901560754,26.325863,0,0,0,40,4449,300.30315,-12811.267578125,,,,,,,,,,,,,0,,,,-0.00245,,,,,,300.0062561,,,,
,27354897.7,300.0063477,-17586.5849609375,2.30461321724438E-5,9.97670786491076E-7,1,0.999253354069792,40.0298881530762,2.00892676806982,20.5799993127584,0.00025711637187945,7.40977663025232E-5,0.25,2.52272450833673E-6,2.30437749656161E-5,2.53789115482523E-6,300.0063477,300.0063477,-17591.65234375,-17581.517578125,57.2284952925253,20.6062716121984,26.325863,0,0,0,40,4449,300.3007,-17586.5849609375,,,,,,,,,,,,,0,,,,0.00245,,,,,,300.0063477,,,,
,27354994.82,300.0117798,-22441.3935546875,3.96547700221642E-5,1.00960057091053E-6,1,0.999253354069792,40.0298881530762,2.00894638904864,20.5799993127584,0.000447222083281963,9.97611444980696E-5,0.25,1.90175079651224E-6,3.96523226425688E-5,1.92789673652917E-6,300.0117798,300.0117798,-22443.75390625,-22439.033203125,57.0573186468137,20.607296180932,26.325863,0,0,0,40,4449,300.2834,-22441.3935546875,,,,,,,,,,,,,0,,,,0,,,,,,300.0117798,,,,
,27355093.86,300.0142822,-27391.509765625,5.77408843158708E-5,1.39818226811644E-6,1,0.999253354069792,40.0298881530762,2.00899527729988,20.5799993127584,0.000651876795512954,0.000141418104509541,0.25,2.43094349964019E-6,5.77375441593244E-5,2.46898513113296E-6,300.0142822,300.0142822,-27396.52734375,-27386.4921875,57.1425161554099,20.6072658858106,26.705515,0,0,0,40,4449,300.28465,-27391.509765625,,,,,,,,,,,,,0,,,,0,,,,,,300.0142822,,,,
,27355191.47,300.0165405,-32271.296875,7.50485113721757E-5,1.28003452422324E-6,1,0.999253354069792,40.0298881530762,2.00898439708536,20.5799993127584,0.000845838212719485,0.000192071908470863,0.25,3.88642317788366E-6,7.50436912632167E-5,3.93579549302339E-6,300.0165405,300.0165405,-32278.7421875,-32263.8515625,57.2480360055061,20.6077930082541,26.705515,0,0,0,40,4449,300.2765,-32271.296875,,,,,,,,,,,,,0,,,,0.0049,,,,,,300.0165405,,,,
,27355286.76,300.0141602,-37032.990234375,9.17947059532343E-5,1.63693588840744E-6,1,0.999253354069792,40.0298881530762,2.00894187842349,20.5799993127584,0.00103607815433318,0.000226142414006936,0.25,3.98134812243414E-6,9.17893353862155E-5,4.04170109073502E-6,300.0141602,300.0141602,-37035.67578125,-37030.3046875,57.1776894387753,20.6078331003899,26.705515,0,0,0,40,4449,300.26135,-37032.990234375,,,,,,,,,,,,,0,,,,0,,,,,,300.0141602,,,,
,27355381.905,300.0144348,-41787.779296875,0.000109061274540722,1.62094933658773E-6,1,0.999253354069792,40.0298881530762,2.00898490434891,20.5799993127584,0.00123091913503832,0.000269091509841989,0.25,4.76603321910923E-6,0.000109054878878213,4.8376644202815E-6,300.0144348,300.0144348,-41792.8125,-41782.74609375,57.1175040427945,20.6092513687739,26.325863,0,0,0,40,4449,300.2473,-41787.779296875,,,,,,,,,,,,,0,,,,0,,,,,,300.0144348,,,,
,27355479.065,300.019165,-46643.041015625,0.000125971030158109,1.78718177236648E-6,1,0.999253354069792,40.0298881530762,2.00872773583981,20.5799993127584,0.00142562687770395,0.000287517295334659,0.25,3.45970627603381E-6,0.000125964977353478,3.54241989540623E-6,300.019165,300.019165,-46650.45703125,-46635.625,56.9924434797176,20.6086695827903,25.946213,0,0,0,40,4449,300.22115,-46643.041015625,,,,,,,,,,,,,0,,,,-0.0049,,,,,,300.019165,,,,
,27355577.08,300.0138855,-51542.740234375,0.00014565220614615,2.37386695018642E-6,1,0.999253354069792,40.0298881530762,2.00882311137606,20.5799993127584,0.00165097994570721,0.000317768530047789,0.25,2.70904123817518E-6,0.000145646096205234,2.80460557972439E-6,300.0138855,300.0138855,-51552.76953125,-51532.7109375,57.0487207331022,20.613150004401,26.325863,0,0,0,40,4449,300.22355,-51542.740234375,,,,,,,,,,,,,0,,,,0.00245,,,,,,300.0138855,,,,
,27355677.355,300.0105591,-56554.69921875,0.000164180792301803,2.48029974038308E-6,1,0.999253354069792,40.0298881530762,2.00889003233654,20.5799993127584,0.00185290057534346,0.000405313833870071,0.25,7.19639679090145E-6,0.000164171220944224,7.30387125000883E-6,300.0105591,300.0105591,-56564.73828125,-56544.66015625,57.0385595623522,20.6118890264554,25.946213,0,0,0,40,4449,300.212,-56554.69921875,,,,,,,,,,,,,0,,,,0,,,,,,300.0105591,,,,
,27355777.24,300.00839235,-61544.1796875,0.000183185685773041,2.35183413463245E-6,1,0.999253354069792,40.0298881530762,2.00882008541953,20.5799993127584,0.00206770336644585,0.000449983164207078,0.25,7.83318717793741E-6,0.000183175168780344,7.95296272915799E-6,300.0083008,300.0084839,-61556.671875,-61531.6875,56.9174071418714,20.6135965923437,26.705515,0,0,0,40,4449,300.2127,-61544.1796875,,,,,,,,,,,,,0,,,,0.00245,,,,,,300.00839235,,,,
,27355876.095,300.0130005,-66486.6484375,0.000198744078602618,2.1622821620568E-6,1,0.999253354069792,40.0298881530762,2.00897079886464,20.5799993127584,0.00224184043396801,0.000497691896522654,0.25,9.33007487688682E-6,0.000198732110435533,9.45985259425351E-6,300.0130005,300.0130005,-66494.171875,-66479.125,57.2191157502945,20.6117745673829,26.705515,0,0,0,40,4449,300.18455,-66486.6484375,,,,,,,,,,,,,0,,,,-0.00245,,,,,,300.0130005,,,,
,27355972.305,300.0164185,-71293.67578125,0.000218569057371593,2.7875682162035E-6,1,0.999253354069792,40.0298881530762,2.00890339201563,20.5799993127584,0.00246992285665517,0.00052114444797533,0.25,7.95922973663894E-6,0.000218557395709993,8.1018518104358E-6,300.0164185,300.0164185,-71301.1640625,-71286.1875,56.7728058658137,20.6123033036555,26.705515,0,0,0,40,4449,300.1771,-71293.67578125,,,,,,,,,,,,,0,,,,-0.00245,,,,,,300.0164185,,,,
,27356072.36,300.0143433,-76293.53515625,0.000232742694414619,2.90796406578859E-6,1,0.999253354069792,40.0298881530762,2.00907785775091,20.5799993127584,0.00262878448859542,0.00056378626856042,0.25,9.24938744190381E-6,0.000232729812194371,9.40104815089736E-6,300.0143433,300.0143433,-76303.375,-76283.6953125,56.8642564025637,20.6120409764977,26.705515,0,0,0,40,4449,300.1687,-76293.53515625,,,,,,,,,,,,,0,,,,-0.0049,,,,,,300.0143433,,,,
,27356172.01,300.026947,-81275.58984375,0.000250588929775094,3.01114677498348E-6,1,0.999253354069792,40.0298881530762,2.00885146598283,20.5799993127584,0.00283380499521254,0.000585272040522511,0.25,8.05246654673289E-6,0.000250576214989366,8.21560757061635E-6,300.026947,300.026947,-81280.5859375,-81270.59375,56.9658681100637,20.6126442054302,27.085165,0,0,0,40,4449,300.1558,-81275.58984375,,,,,,,,,,,,,0,,,,0,,,,,,300.026947,,,,
,27356266.045,300.0145264,-85972.49609375,0.000267764281371268,2.85502830897006E-6,1,0.999253354069792,40.0298881530762,2.00898548220158,20.5799993127584,0.0030275700364778,0.000629225129056892,0.25,8.93858898680455E-6,0.000267750621911972,9.11269945483805E-6,300.0145264,300.0145264,-85977.4765625,-85967.515625,57.0893654161022,20.6127430929122,27.085165,0,0,0,40,4449,300.1463,-85972.49609375,,,,,,,,,,,,,0,,,,0,,,,,,300.0145264,,,,
,27356379.165,300.0130615,-89398.81640625,0.000284389664291142,3.13770063075683E-6,1,0.999253354069792,40.0298881530762,2.00886809987743,20.5799993127584,0.00320879571226328,0.000706214998866724,0.25,1.2831652503523E-5,0.000284373019216338,1.30163173074174E-5,300.0130615,300.0130615,-89411.2265625,-89386.40625,57.4348452216022,20.6135192098155,26.705515,0,0,0,40,4449,300.13675,-89398.81640625,,,,,,,,,,,,,0,,,,-0.0049,,,,,,300.0130615,,,,
,27356474.24,300.0040588,-84648.0546875,0.000264630196971879,2.75709357148107E-6,1,0.999253354069792,40.0298881530762,2.00894337958477,20.5799993127584,0.00298800404213957,0.000645343958026555,0.25,1.08999433024215E-5,0.000264615442580366,1.10720280763465E-5,300.0040588,300.0040588,-84655.4921875,-84640.6171875,56.9142806277945,20.6133073484032,26.705515,0,0,0,40,4449,300.1326,-84648.0546875,,,,,,,,,,,,,0,,,,0.00245,,,,,,300.0040588,,,,
,27356574.075,299.99668885,-79658.26953125,0.000247886824602456,3.14875010439949E-6,1,0.999253354069792,40.0298881530762,2.0089153069414,20.5799993127584,0.00280132812990014,0.000590568254924586,0.25,8.98462293430419E-6,0.000247873842134195,9.14606303302683E-6,299.9961548,299.9972229,-79663.453125,-79653.0859375,56.7759323798906,20.6126949339282,25.946213,0,0,0,40,4449,300.13775,-79658.26953125,,,,,,,,,,,,,0,,,,-0.00245,,,,,,299.99668885,,,,
,27356674.875,300.0013428,-74621.515625,0.000229957601076591,2.79569156292608E-6,1,0.999253354069792,40.0298881530762,2.00890760433522,20.5799993127584,0.00259900917969433,0.000546082440227556,0.25,8.17904090556613E-6,0.000229945596546681,8.32900161956957E-6,300.0013428,300.0013428,-74626.6015625,-74616.4296875,57.4356268501215,20.6140616580949,26.705515,0,0,0,40,4449,300.13635,-74621.515625,,,,,,,,,,,,,0,,,,0.0049,,,,,,300.0013428,,,,
,27356772.88,299.997345,-69721.96875,0.000212939109264206,1.97260064779994E-6,1,0.999253354069792,40.0298881530762,2.00901983836531,20.5799993127584,0.00240762100405219,0.000500912813853525,0.25,7.15303233260411E-6,0.000212928277698014,7.292077725957E-6,299.997345,299.997345,-69729.484375,-69714.453125,56.9893169656406,20.6100172204243,26.325863,0,0,0,40,4449,300.1415,-69721.96875,,,,,,,,,,,,,0,,,,0.00245,,,,,,299.997345,,,,
,27356874.305,299.9897156,-64654.978515625,0.000192487660885234,2.43039631566787E-6,1,0.999253354069792,40.0298881530762,2.00897479030404,20.5799993127584,0.0021767720054357,0.000450289537893263,0.25,6.24568095762157E-6,0.000192478047916417,6.37153250935091E-6,299.9891663,299.9902649,-64667.59765625,-64642.359375,56.9306948266983,20.6111887167331,26.705515,0,0,0,40,4449,300.1554,-64654.978515625,,,,,,,,,,,,,0,,,,0,,,,,,299.9897156,,,,
,27356973.765,299.9838562,-59682.375,0.000174531538360865,2.51104353073571E-6,1,0.999253354069792,40.0298881530762,2.00881080312093,20.5799993127584,0.00197302198515067,0.000411354809638306,0.25,5.93570540094025E-6,0.000174522663370058,6.04994801884582E-6,299.9838562,299.9838562,-59689.89453125,-59674.85546875,56.7900016932368,20.6130858858001,26.705515,0,0,0,40,4449,300.1604,-59682.375,,,,,,,,,,,,,0,,,,0.00245,,,,,,299.9838562,,,,
,27357073.225,299.9855652,-54712.68359375,0.000156325345342074,1.84587897063636E-6,1,0.999253354069792,40.0298881530762,2.00881855443675,20.5799993127584,0.001761128673592,0.000403564894084559,0.25,8.40469103510588E-6,0.000156315345094104,8.50704645673345E-6,299.9855652,299.9855652,-54722.70703125,-54702.66015625,56.8197035769676,20.6125050535822,26.705515,0,0,0,40,4449,300.1717,-54712.68359375,,,,,,,,,,,,,0,,,,-0.0049,,,,,,299.9855652,,,,
,27357168.765,299.9887695,-49938.68359375,0.000138219164712561,2.12062262622654E-6,1,0.999253354069792,40.0298881530762,2.00878090384506,20.5799993127584,0.0015645088967477,0.000314168462872839,0.25,3.68073809105904E-6,0.000138212756662448,3.77144545269285E-6,299.9887695,299.9887695,-49946.20703125,-49931.16015625,57.1862873524868,20.6114849475881,26.705515,0,0,0,40,4449,300.181,-49938.68359375,,,,,,,,,,,,,0,,,,0.00245,,,,,,299.9887695,,,,
,27357263.515,299.9865417,-45203.7734375,0.000122497658430459,2.17787450603634E-6,1,0.999253354069792,40.0298881530762,2.00879500776194,20.5799993127584,0.00138286103271971,0.000299818886849078,0.25,5.14239233328191E-6,0.000122490742351844,5.22281413942057E-6,299.9865417,299.9865417,-45213.94140625,-45193.60546875,56.8290831191983,20.6132498945493,27.085165,0,0,0,40,4449,300.19205,-45203.7734375,,,,,,,,,,,,,0,,,,-0.0049,,,,,,299.9865417,,,,
,27357360.425,299.9916077,-40361.0859375,0.000104419328307813,1.68250964270875E-6,1,0.999253354069792,40.0298881530762,2.0088285685119,20.5799993127584,0.00117911524652267,0.000253729432289406,0.25,4.22107737401929E-6,0.000104413511093677,4.28970823244991E-6,299.9916077,299.9916077,-40370.953125,-40351.21875,56.983845566006,20.6092754070154,26.705515,0,0,0,40,4449,300.20085,-40361.0859375,,,,,,,,,,,,,0,,,,0,,,,,,299.9916077,,,,
,27357456.785,299.9911499,-35546.091796875,8.68582961457553E-5,1.41228700065965E-6,1,0.999253354069792,40.0298881530762,2.00885426677975,20.5799993127584,0.000982212558169861,0.000203056828735598,0.25,2.80733168598949E-6,8.68539147422508E-5,2.86450134240432E-6,299.9911499,299.9911499,-35553.90234375,-35538.28125,57.1511140691214,20.6111084566781,26.705515,0,0,0,40,4449,300.2065,-35546.091796875,,,,,,,,,,,,,0,,,,0,,,,,,299.9911499,,,,
,27357553.57,299.9847107,-30706.552734375,6.9156756936212E-5,1.47082852440117E-6,1,0.999253354069792,40.0298881530762,2.00883168720102,20.5799993127584,0.000779428011064037,0.0001766989364132,0.25,3.55653038162027E-6,6.91524068508728E-5,3.60205834736843E-6,299.9847107,299.9847107,-30716.59765625,-30696.5078125,57.0096393071407,20.6105551299103,26.325863,0,0,0,40,4449,300.21245,-30706.552734375,,,,,,,,,,,,,0,,,,0.00245,,,,,,299.9847107,,,,
,27357651.525,299.9852295,-25811.8662109375,5.14734736612414E-5,1.18589184045501E-6,1,0.999253354069792,40.0298881530762,2.00881454858948,20.5799993127584,0.000581819002310248,0.000121736526637347,0.25,1.78709693686189E-6,5.1470798373254E-5,1.82104056798642E-6,299.9852295,299.9852295,-25819.4609375,-25804.271484375,56.8939582862945,20.6091297298155,26.705515,0,0,0,40,4449,300.2348,-25811.8662109375,,,,,,,,,,,,,0,,,,-0.00245,,,,,,299.9852295,,,,
,27357749.44,299.98535155,-20919.6455078125,3.57903844247779E-5,9.42096792055816E-7,1,0.999253354069792,40.0298881530762,2.00880327943405,20.5799993127584,0.000403527536733117,9.05261108333935E-5,0.25,1.75974791664443E-6,3.57881792956079E-5,1.78335775386611E-6,299.985321,299.9853821,-20927.15625,-20912.134765625,56.6852634716598,20.6084005759112,26.325863,0,0,0,40,4449,300.2378,-20919.6455078125,,,,,,,,,,,,,0,,,,0,,,,,,299.98535155,,,,
,27357847.015,299.9870605,-16042.43359375,1.79087237547768E-5,8.14482417357565E-7,1,0.999253354069792,40.0298881530762,2.00879695405037,20.5799993127584,0.000200935458930689,5.09548093876637E-5,0.25,1.37805535317305E-6,1.79072885109956E-5,1.38986557175345E-6,299.9870605,299.9870605,-16044.904296875,-16039.962890625,57.1425161554099,20.6080270597556,27.085165,0,0,0,40,4449,300.2435,-16042.43359375,,,,,,,,,,,,,0,,,,0.00245,,,,,,299.9870605,,,,
,27357945.94,299.9921875,-11097.6909179688,1.09948719251687E-6,7.11496721296132E-7,1,0.999253354069792,40.0298881530762,2.00882964519339,20.5799993127584,1.10922041928976E-5,1.03095503148802E-5,0.25,7.16096784704247E-7,1.09898052729031E-6,7.16803881977298E-7,299.9921875,299.9921875,-11102.630859375,-11092.7509765625,56.9072459711214,20.6093474074141,26.325863,0,0,0,40,4449,300.2488,-11097.6909179688,,,,,,,,,,,,,0,,,,0.00245,,,,,,299.9921875,,,,
,27358042.955,299.9942932,-6249.56030273437,-1.30144384094907E-5,6.30511640595773E-7,1,0.999253354069792,40.0298881530762,2.00881331565954,20.5799993127584,-0.000148391599368316,-2.33574103794867E-5,0.25,2.00873101357918E-7,-1.30141865320463E-5,1.9224074941486E-7,299.9942932,299.9942932,-6254.611328125,-6244.50927734375,56.6727574153522,20.6056357341317,26.705515,0,0,0,40,4449,300.2522,-6249.56030273437,,,,,,,,,,,,,0,,,,-0.0049,,,,,,299.9942932,,,,
,27358137.875,299.9909973,-1500.57330322266,-1.9173698064961E-5,4.58585960285407E-7,1,0.999253354069792,40.0298881530762,2.00873210556809,20.5799993127584,-0.000217876959948833,-3.86499926282069E-5,0.25,-7.68968230749914E-8,-1.91730813507994E-5,-8.96117571487751E-8,299.9909973,299.9909973,-1505.66760253906,-1495.47900390625,57.1894138665637,20.6076582285787,26.705515,0,0,0,40,4449,300.25875,-1500.57330322266,,,,,,,,,,,,,0,,,,0.00245,,,,,,299.9909973,,,,
,27358227.68,299.9989929,2979.56787109375,1.87578885064792E-5,4.78369202527167E-7,1,0.999253354069792,40.0298881530762,2.00885963143291,20.5799993127584,0.000215153831510138,2.6334188536523E-5,0.25,-9.3426466691246E-7,1.87579494314998E-5,-9.2179773800704E-7,299.9988708,299.999115,2972.04296875,2987.0927734375,57.2761746321984,20.604734043701,26.705515,0,0,0,40,4449,300.25765,2979.56787109375,,,,,,,,,,,,,0,,,,0,,,,,,299.9989929,,,,
,27358322.585,300.0016174,7727.0732421875,8.98633025142292E-6,5.40521454054639E-7,1,0.999253354069792,40.0298881530762,2.00866767595122,20.5799993127584,0.000104559631276061,3.98366282744862E-6,0.25,-1.20662575140937E-6,8.98686176047892E-6,-1.2006347717744E-6,300.0016174,300.0016174,7722.1328125,7732.013671875,56.9682129956214,20.6061714315911,26.325863,0,0,0,40,4449,300.25395,7727.0732421875,,,,,,,,,,,,,0,,,,0,,,,,,300.0016174,,,,
,27358420.02,300.0016174,12597.1840820312,-6.27560466607621E-6,6.98809953053951E-7,1,0.999253354069792,40.0298881530762,2.00901807675831,20.5799993127584,-6.76788222258769E-5,-3.36758721713119E-5,0.25,-1.87379403766728E-6,-6.2741771308708E-6,-1.87789331178176E-6,300.0016174,300.0016174,12589.6123046875,12604.755859375,56.8384626614291,20.6036144570328,26.325863,0,0,0,40,4449,300.25855,12597.1840820312,,,,,,,,,,,,,0,,,,-0.00245,,,,,,300.0016174,,,,
,27358516.595,300.0038757,17425.0654296875,-2.09505275232806E-5,8.28073496088296E-7,1,0.999253354069792,40.0298881530762,2.00896860560987,20.5799993127584,-0.000236161562504306,-5.33917221653571E-5,0.25,-1.06496035243903E-6,-2.09491984798489E-5,-1.07878786080661E-6,300.0038757,300.0038757,17422.548828125,17427.58203125,56.9205336559483,20.601300914326,26.705515,0,0,0,40,4449,300.2502,17425.0654296875,,,,,,,,,,,,,0,,,,0,,,,,,300.0038757,,,,
,27358614.895,300.0142517,22337.560546875,-3.79495440651072E-5,1.12042111495362E-6,1,0.999253354069792,40.0298881530762,2.00869722520395,20.5799993127584,-0.0004276754310602,-9.69873485367437E-5,0.25,-1.95429166752693E-6,-3.79471090400836E-5,-1.9793144440129E-6,300.0142517,300.0142517,22330.298828125,22344.822265625,56.8908317722176,20.606335854282,27.085165,0,0,0,40,4449,300.23405,22337.560546875,,,,,,,,,,,,,0,,,,0,,,,,,300.0142517,,,,
,27358711.36,300.0110779,27157.8916015625,-5.62141601631539E-5,1.48490607702974E-6,1,0.999253354069792,40.0298881530762,2.00897391773808,20.5799993127584,-0.000630956517574712,-0.000158904116479688,0.25,-4.23313914118064E-6,-5.62096811401386E-5,-4.27012892213369E-6,300.0109253,300.0112305,27147.640625,27168.142578125,56.7642079521022,20.6033851062323,27.085165,0,0,0,40,4449,300.23075,27157.8916015625,,,,,,,,,,,,,0,,,,-0.0049,,,,,,300.0110779,,,,
,27358807.39,300.0099792,31958.51171875,-7.45223156609023E-5,1.37634936531409E-6,1,0.999253354069792,40.0298881530762,2.00879871032354,20.5799993127584,-0.000840260784564451,-0.0001882442126247,0.25,-3.64246003484072E-6,-7.45176879948321E-5,-3.69150668415054E-6,300.0099792,300.0099792,31945.80859375,31971.21484375,56.689171614256,20.6059576431277,27.085165,0,0,0,40,4449,300.2255,31958.51171875,,,,,,,,,,,,,0,,,,-0.00245,,,,,,300.0099792,,,,
,27358904.28,300.0193787,36797.91015625,-9.13550856587625E-5,1.62489295270176E-6,1,0.999253354069792,40.0298881530762,2.00873866531466,20.5799993127584,-0.00103104204384046,-0.000224890292625516,0.25,-3.94930823626787E-6,-9.13497300832061E-5,-4.00938793584983E-6,300.0193787,300.0193787,36788.2421875,36807.578125,57.1323549846599,20.6054700325755,26.705515,0,0,0,40,4449,300.20605,36797.91015625,,,,,,,,,,,,,0,,,,0,,,,,,300.0193787,,,,
,27359003.305,300.011322,41748.044921875,-0.000107132411546416,1.87401261618568E-6,1,0.999253354069792,40.0298881530762,2.00883019374665,20.5799993127584,-0.00121320542596892,-0.000240388223746851,0.25,-2.57785353547038E-6,-0.000107127523812035,-2.64829633879829E-6,300.011322,300.011322,41740.60546875,41755.484375,57.0878021590637,20.6043268587061,26.705515,0,0,0,40,4449,300.194,41748.044921875,,,,,,,,,,,,,0,,,,0,,,,,,300.011322,,,,
,27359100.235,300.0107117,46593.443359375,-0.000126707276182685,1.81062091299666E-6,1,0.999253354069792,40.0298881530762,2.00864349247024,20.5799993127584,-0.00143276930050903,-0.000295724720881993,0.25,-4.05494391382419E-6,-0.000126700847243289,-4.138134821983E-6,300.0107117,300.0107117,46583.5625,46603.32421875,57.0596635323714,20.6062691438617,26.705515,0,0,0,40,4449,300.19375,46593.443359375,,,,,,,,,,,,,0,,,,0.0049,,,,,,300.0107117,,,,
,27359198.35,300.006134,51498.5078125,-0.000143423676936972,2.15306515894367E-6,1,0.999253354069792,40.0298881530762,2.00835580179867,20.5799993127584,-0.00161845804423887,-0.000352669733365714,0.25,-6.17111930908606E-6,-0.000143415397733393,-6.26513436686436E-6,300.006134,300.006134,51490.95703125,51506.05859375,57.0127658212176,20.6065211351925,26.705515,0,0,0,40,4449,300.1844,51498.5078125,,,,,,,,,,,,,0,,,,0.0049,,,,,,300.006134,,,,
,27359295.555,300.0114746,56356.029296875,-0.000162770052283813,2.42086673975827E-6,1,0.999253354069792,40.0298881530762,2.00872605494301,20.5799993127584,-0.00183849891798542,-0.000392203060352558,0.25,-6.29058509124701E-6,-0.00016276110857042,-6.39718274293355E-6,300.0114746,300.0114746,56348.59375,56363.46484375,56.8017261210252,20.6050930669343,26.325863,0,0,0,40,4449,300.1714,56356.029296875,,,,,,,,,,,,,0,,,,0,,,,,,300.0114746,,,,
,27359393.69,300.0158691,61260.86328125,-0.000176288364031603,2.31311628348037E-6,1,0.999253354069792,40.0298881530762,2.00866847889717,20.5799993127584,-0.00199040394875398,-0.00042898194985965,0.25,-7.18405945991538E-6,-0.000176278423611883,-7.29936514688698E-6,300.0158691,300.0158691,61255.87109375,61265.85546875,56.9846271945253,20.606193698534,26.705515,0,0,0,40,4449,300.1603,61260.86328125,,,,,,,,,,,,,0,,,,0,,,,,,300.0158691,,,,
,27359492.96,300.0125122,66224.015625,-0.000195100884093408,2.6503530188724E-6,1,0.999253354069792,40.0298881530762,2.00855048556208,20.5799993127584,-0.00220055267667933,-0.00048704722949702,0.25,-9.03378397721409E-6,-0.000195089217272679,-9.16121186367934E-6,300.0125122,300.0125122,66224.015625,66224.015625,56.9134989992753,20.6044111933538,27.085165,0,0,0,40,4449,300.15025,66224.015625,,,,,,,,,,,,,0,,,,-0.00245,,,,,,300.0125122,,,,
,27359593.555,300.015564,71251.5625,-0.000212995398005818,2.73764628946338E-6,1,0.999253354069792,40.0298881530762,2.00856012272628,20.5799993127584,-0.00240603333492288,-0.000510731104869662,0.25,-8.01647590993593E-6,-0.000212983867414955,-8.15547543444066E-6,300.015564,300.015564,71246.625,71256.5,57.0620084179291,20.6040408182681,27.085165,0,0,0,40,4449,300.13925,71251.5625,,,,,,,,,,,,,0,,,,0.0049,,,,,,300.015564,,,,
,27359692.055,300.0140381,76174.87109375,-0.00023185457148326,2.03700318795351E-6,1,0.999253354069792,40.0298881530762,2.00854790111496,20.5799993127584,-0.00262386985019096,-0.000528158345449671,0.25,-6.28226316368866E-6,-0.000231843651200194,-6.43346278414273E-6,300.0140381,300.0140381,76169.828125,76179.9140625,56.8439340610637,20.6035869858419,26.325863,0,0,0,40,4449,300.12295,76174.87109375,,,,,,,,,,,,,0,,,,-0.0049,,,,,,300.0140381,,,,
,27359793.555,300.0201111,81248.40625,-0.00025243901359958,2.62613230619902E-6,1,0.999253354069792,40.0298881530762,2.00852929548297,20.5799993127584,-0.0028493564470156,-0.000617984821402562,0.25,-1.06168486810279E-5,-0.00025242462987879,-1.07811516670521E-5,300.0201111,300.0201111,81238.4375,81258.375,57.1081245005637,20.6045330964723,26.705515,0,0,0,40,4449,300.11115,81248.40625,,,,,,,,,,,,,0,,,,0,,,,,,300.0201111,,,,
,27359889.82,300.0131531,86061.09375,-0.000267659739473667,3.07448673011095E-6,1,0.999253354069792,40.0298881530762,2.00835432541767,20.5799993127584,-0.00302352857772567,-0.000640062861906447,0.25,-9.92651116110306E-6,-0.000267645450232646,-1.01005465281844E-5,300.0131531,300.0131531,86051.1171875,86071.0703125,56.8642564025637,20.6056940367711,26.325863,0,0,0,40,4449,300.1084,86061.09375,,,,,,,,,,,,,0,,,,0,,,,,,300.0131531,,,,
,27360003.82,300.0122986,89277.171875,-0.000282131986324793,3.59686448411287E-6,1,0.999253354069792,40.0298881530762,2.00830486596317,20.5799993127584,-0.00319126644956632,-0.000649652927296346,0.25,-8.26422092425001E-6,-0.0002821183820631,-8.44758916320075E-6,300.0122986,300.0122986,89272.203125,89282.140625,56.8095424062176,20.6043570024784,27.085165,0,0,0,40,4449,300.08995,89277.171875,,,,,,,,,,,,,0,,,,0.00245,,,,,,300.0122986,,,,
,27360096.81,300.007019,84629.51171875,-0.000261708586388735,3.27280804179382E-6,1,0.999253354069792,40.0298881530762,2.00844297622406,20.5799993127584,-0.00295638156833216,-0.00062612823338349,0.25,-9.72948195823991E-6,-0.000261694647344243,-9.89972667557818E-6,300.007019,300.007019,84624.5625,84634.4609375,56.7063674416791,20.6065161581508,27.085165,0,0,0,40,4449,300.0874,84629.51171875,,,,,,,,,,,,,0,,,,0,,,,,,300.007019,,,,
,27360194.93,300.0016174,79725.5625,-0.000242936335644619,2.85819007227575E-6,1,0.999253354069792,40.0298881530762,2.00850367353197,20.5799993127584,-0.00274687440961749,-0.000566955658028538,0.25,-7.77567853872254E-6,-0.000242924237702728,-7.93394994751498E-6,300.0016174,300.0016174,79720.59375,79730.53125,56.658688102006,20.6041157998602,26.705515,0,0,0,40,4449,300.08875,79725.5625,,,,,,,,,,,,,0,,,,0,,,,,,300.0016174,,,,
,27360291.7,299.9900208,74887.2890625,-0.000229665789233366,2.91608595110762E-6,1,0.999253354069792,40.0298881530762,2.00844229802018,20.5799993127584,-0.00258890979427803,-0.000581222940784258,0.25,-1.13308857182712E-5,-0.000229651825378662,-1.14805875360937E-5,299.9900208,299.9900208,74882.28125,74892.296875,56.7626446950637,20.6071410769798,26.705515,0,0,0,40,4449,300.08715,74887.2890625,,,,,,,,,,,,,0,,,,0,,,,,,299.9900208,,,,
,27360392.845,299.9917908,69832.01171875,-0.000209397118209486,2.31809013505832E-6,1,0.999253354069792,40.0298881530762,2.00853650190453,20.5799993127584,-0.00236837384376959,-0.000484713004242964,0.25,-6.35200538179863E-6,-0.000209386952658833,-6.48877530592208E-6,299.9917908,299.9917908,69824.515625,69839.5078125,57.0229269919676,20.6061524168034,27.085165,0,0,0,40,4449,300.10345,69832.01171875,,,,,,,,,,,,,0,,,,0,,,,,,299.9917908,,,,
,27360491.81,299.9900818,64883.6171875,-0.000193374333162073,2.75076866965597E-6,1,0.999253354069792,40.0298881530762,2.00864094687271,20.5799993127584,-0.00218242061189695,-0.000475563716808057,0.25,-8.32105764666792E-6,-0.000193363331073094,-8.44744732481858E-6,299.9900818,299.9900818,64876.25,64890.984375,56.8150138058522,20.6039696372311,26.325863,0,0,0,40,4449,300.1056,64883.6171875,,,,,,,,,,,,,0,,,,-0.0049,,,,,,299.9900818,,,,
,27360592.61,299.98138425,59845.548828125,-0.000173492777591754,1.95113794010961E-6,1,0.999253354069792,40.0298881530762,2.00869783808673,20.5799993127584,-0.00196360813135954,-0.000394835658011812,0.25,-4.66486471277218E-6,-0.000173484779623101,-4.7784728283708E-6,299.9809265,299.981842,59842.9765625,59848.12109375,56.9986965078714,20.6032614745887,27.085165,0,0,0,40,4449,300.1281,59845.548828125,,,,,,,,,,,,,0,,,,-0.00245,,,,,,299.98138425,,,,
,27360692.46,299.9867859,54855.2578125,-0.000155256685013388,2.10842736429449E-6,1,0.999253354069792,40.0298881530762,2.00861810627103,20.5799993127584,-0.00175730571955097,-0.000352382628032109,0.25,-4.09194045839156E-6,-0.000155249537899264,-4.19372820431481E-6,299.9867859,299.9867859,54850.46484375,54860.05078125,57.088583787583,20.6055896106858,27.085165,0,0,0,40,4449,300.13725,54855.2578125,,,,,,,,,,,,,0,,,,0.0049,,,,,,299.9867859,,,,
,27360789.38,299.9841919,50008.060546875,-0.000136509584171616,2.31602979978443E-6,1,0.999253354069792,40.0298881530762,2.00865088413821,20.5799993127584,-0.00153824923304499,-0.000349591507228708,0.25,-7.09388127273749E-6,-0.000136501003947632,-7.18337822777866E-6,299.9841919,299.9841919,50003.26953125,50012.8515625,57.1683098965445,20.6045496626575,26.705515,0,0,0,40,4449,300.1476,50008.060546875,,,,,,,,,,,,,0,,,,-0.0049,,,,,,299.9841919,,,,
,27360887.535,299.9951477,45105.396484375,-0.000120194320324606,1.77115824859592E-6,1,0.999253354069792,40.0298881530762,2.00870611185881,20.5799993127584,-0.00135929450610798,-0.000279777989229368,0.25,-3.7801205005173E-6,-0.000120188327766164,-3.85908007778532E-6,299.9951477,299.9951477,45100.12109375,45110.671875,56.6242964471598,20.6053868609791,26.705515,0,0,0,40,4449,300.1504,45105.396484375,,,,,,,,,,,,,0,,,,0,,,,,,299.9951477,,,,
,27360987.38,299.9898682,40115.05078125,-0.000101820408485511,1.78017603153881E-6,1,0.999253354069792,40.0298881530762,2.00866629740743,20.5799993127584,-0.00114994823259226,-0.00024584369542971,0.25,-3.97955330474333E-6,-0.000101814830323816,-4.04649532599493E-6,299.9898682,299.9898682,40107.32421875,40122.77734375,56.9541436822753,20.6084821508313,27.085165,0,0,0,40,4449,300.15735,40115.05078125,,,,,,,,,,,,,0,,,,0,,,,,,299.9898682,,,,
,27361085.955,299.9809265,35187.509765625,-8.54447795649904E-5,1.78574922004264E-6,1,0.999253354069792,40.0298881530762,2.00848140907472,20.5799993127584,-0.000965067962334349,-0.000205428543896422,0.25,-3.26396953898917E-6,-8.54401680944406E-5,-3.32020826322619E-6,299.9809265,299.9809265,35184.91015625,35190.109375,56.8783257159099,20.609615361372,26.705515,0,0,0,40,4449,300.16835,35187.509765625,,,,,,,,,,,,,0,,,,0,,,,,,299.9809265,,,,
,27361183.41,299.9878845,30314.8486328125,-6.78456467970987E-5,1.46684865133058E-6,1,0.999253354069792,40.0298881530762,2.00871909469295,20.5799993127584,-0.00076415175788993,-0.000175985912265726,0.25,-3.72180689103519E-6,-6.78412165081655E-5,-3.76647416782612E-6,299.9878845,299.9878845,30307.353515625,30322.34375,56.8275198621599,20.6085261413585,27.085165,0,0,0,40,4449,300.1789,30314.8486328125,,,,,,,,,,,,,0,,,,0,,,,,,299.9878845,,,,
,27361282.375,299.9894714,25370.1201171875,-4.98636459031242E-5,1.10631456478537E-6,1,0.999253354069792,40.0298881530762,2.00868185913759,20.5799993127584,-0.000561496819648574,-0.00012998620362821,0.25,-2.79218083172526E-6,-4.98603445061896E-5,-2.82504161278513E-6,299.9894714,299.9894714,25359.96484375,25380.275390625,56.7954730928714,20.6090635901187,27.085165,0,0,0,40,4449,300.1807,25370.1201171875,,,,,,,,,,,,,0,,,,0,,,,,,299.9894714,,,,
,27361378.22,299.98493955,20580.0419921875,-3.25169410329976E-5,1.18127300862759E-6,1,0.999253354069792,40.0298881530762,2.00869019155858,20.5799993127584,-0.000364761711553832,-9.28556688552919E-5,0.25,-2.53218799140509E-6,-3.25143202277375E-5,-2.55361590796129E-6,299.9840698,299.9858093,20572.2578125,20587.826171875,56.6008475915829,20.6087199155994,26.705515,0,0,0,40,4449,300.20025,20580.0419921875,,,,,,,,,,,,,0,,,,-0.0049,,,,,,299.98493955,,,,
,27361479.93,299.9923096,15498.126953125,-1.58037496648435E-5,1.00248763451216E-6,1,0.999253354069792,40.0298881530762,2.00898587546283,20.5799993127584,-0.000174919875380895,-5.89008033689924E-5,0.25,-2.44105268344565E-6,-1.58016689941467E-5,-2.45144074062049E-6,299.9923096,299.9923096,15490.7666015625,15505.4873046875,57.1573670972753,20.6045917124926,27.085165,0,0,0,40,4449,300.214,15498.126953125,,,,,,,,,,,,,0,,,,-0.0049,,,,,,299.9923096,,,,
,27361576.83,299.9951782,10655.76953125,8.6300180796185E-8,7.59511352929373E-7,1,0.999253354069792,40.0298881530762,2.00889692200792,20.5799993127584,4.12445301438349E-6,-1.79706418902986E-5,0.25,-1.59518948915043E-6,8.73544068019121E-8,-1.59508512484573E-6,299.9951782,299.9951782,10653.26953125,10658.26953125,56.9549253107945,20.6062102803094,26.325863,0,0,0,40,4449,300.20135,10655.76953125,,,,,,,,,,,,,0,,,,-0.00245,,,,,,299.9951782,,,,
,27361673.73,299.9872437,5810.5576171875,1.41927452852419E-5,5.22498508905362E-7,1,0.999253354069792,40.0298881530762,2.00908773854911,20.5799993127584,0.000163343172744909,1.6845021791586E-5,0.25,-9.7790667147397E-7,1.41929771471523E-5,-9.68468672340171E-7,299.9872437,299.9872437,5800.60595703125,5820.50927734375,56.872072687756,20.60517933495,26.325863,0,0,0,40,4449,300.2192,5810.5576171875,,,,,,,,,,,,,0,,,,0.00245,,,,,,299.9872437,,,,
,27361769.795,299.9921875,1009.52157592773,1.87418727380112E-5,4.60900545677496E-7,1,0.999253354069792,40.0298881530762,2.00923457445105,20.5799993127584,0.000214483825497295,2.93443094333508E-5,0.25,-6.67256587498084E-7,1.87417613919998E-5,-6.54803494850919E-7,299.9919739,299.9924011,1001.91717529297,1017.1259765625,56.8908317722176,20.6049760136353,27.085165,0,0,0,40,4449,300.2204,1009.52157592773,,,,,,,,,,,,,0,,,,0,,,,,,299.9921875,,,,
,27361791.76,299.9932251,-0.388206213712692,3.01617774111832E-6,3.35225450830814E-7,1,0.999253354069792,40.0298881530762,2.0089186413196,20.5799993127584,3.56530453789566E-5,-1.86251366315157E-6,0.25,-6.86360470096025E-7,3.01654382663179E-6,-6.84339048285239E-7,299.9932251,299.9932251,-0.395818114280701,-0.380594313144684,56.7587365524675,20.6065149519766,27.085165,0,0,0,40,4417,300.2222,-0.388206213712692,,,,,,,,,,,,,0,,,,0.0049,,,,,,299.9932251,,,,