File: data/monolayers/nanoparticles/Ac_CoFe_C/vsm/data_disorderedWafer/DD226_2_HYST_200K.DAT
[Header]
; VSM Data File (default extension .dat)
; Copyright (c) 2003-2013, Quantum Design, Inc. All rights reserved.
TITLE,
FILEOPENTIME,27338840.58,11/13/2018,6:07 pm
BYAPP,VSM,2.0,2.0
INFO,PPMS VSM Option Release 1.4.10 Build 1,APPNAME
INFO,Quantum Design Linear Motor Servo Controller,MOTOR_MODULE_NAME
INFO,3101-100 M1,MOTOR_HW_VERSION
INFO,MMC1014,MOTOR_SERIAL_NUMBER
INFO,SRV No X-over 01.03.11,MOTOR_SOFTWARE_VERSION
INFO,Quantum Design VSM Detection Module,VSM_MODULE_NAME
INFO,3101-150 F0,VSM_HW_VERSION
INFO,VSM707,VSM_SERIAL_NUMBER
INFO,VSM No X-over 01.02.05 May 20 2008 13:51:47,VSM_SOFTWARE_VERSION
INFO,704,PREAMP_SERIAL_NUMBER
INFO,822,COIL_SERIAL_NUMBER
INFO,0,MOMENT_UNITS
INFO,CoFe2O4 AH11,SAMPLE_MATERIAL
INFO,Quick Dry Monolayer Conc,SAMPLE_COMMENT
INFO,27.96,SAMPLE_MASS
INFO,,SAMPLE_VOLUME
INFO,,SAMPLE_MOLECULAR_WEIGHT
INFO,,SAMPLE_SIZE
INFO,,SAMPLE_SHAPE
DATATYPE,COMMENT,1
DATATYPE,TIME,2
STARTUPAXIS,X,2
STARTUPAXIS,Y1,5
[Data]
Comment,Time Stamp (sec),Temperature (K),Magnetic Field (Oe),Moment (emu),M. Std. Err. (emu),Transport Action,Averaging Time (sec),Frequency (Hz),Peak Amplitude (mm),Center Position (mm),Coil Signal' (mV),Coil Signal" (mV),Range (mV),M. Quad. Signal (emu),M. Raw' (emu),M. Raw" (emu),Min. Temperature (K),Max. Temperature (K),Min. Field (Oe),Max. Field (Oe),Mass (grams),Motor Lag (deg),Pressure (Torr),VSM Status (code),Motor Status (code),Measure Status (code),Measure Count,PPMS Status (code),System Temp. (K),System Field (Oe),Sample Position (deg),Bridge 1 Resistance (ohms),Bridge 1 Excitation (에),Bridge 2 Resistance (ohms),Bridge 2 Excitation (에),Bridge 3 Resistance (ohms),Bridge 3 Excitation (에),Bridge 4 Resistance (ohms),Bridge 4 Excitation (에),Signal 1 Vin (V),Signal 2 Vin (V),Digital Inputs (code),Drive 1 Iout (mA),Drive 1 Ipower (W),Drive 2 Iout (mA),Drive 2 Ipower (W),Pressure (),Map 20 (),Map 21 (),Map 22 (),Map 23 (),Map 24 (),Map 25 (),Map 26 (),Map 27 (),Map 28 (),Map 29 ()
,27338856.77,200.2265625,-0.0456713177263737,,,2,,,,21.0799996325374,,,,,,,200.2265625,200.2265625,-0.0456713177263737,-0.0456713177263737,,,24.427608,,,,-99999999,4433,200.0613,-0.0456713177263737,,,,,,,,,,,,,,,,,,,,,,,200.2265625,,,,
,27339003.095,200.1372833,4820.2607421875,1.5183594535856E-5,5.91694304615831E-7,1,0.999253354069792,40.0298881530762,1.98368474914723,21.0699997842312,0.000172103765425822,2.44223291819209E-5,0.25,-4.710259916182E-7,1.52364444567838E-5,-4.5616217115199E-7,200.1372833,200.1372833,4815.291015625,4825.23046875,56.2233210167944,20.5983833766617,25.186911,0,0,0,40,4449,199.88165,4820.2607421875,,,,,,,,,,,,,0,,,,0,,,,,,200.1372833,,,,
,27339103.58,200.0707855,9841.9189453125,3.53260957621288E-6,8.85590349450156E-7,1,0.999253354069792,40.0298881530762,1.98363174369395,21.0699997842312,4.04271493064834E-5,3.45685697142646E-6,0.25,-3.06952340505806E-7,3.5451280128126E-6,-3.04180076583676E-7,200.0707855,200.0707855,9831.70703125,9852.130859375,55.9888324610252,20.5961300983885,24.427608,0,0,0,40,4449,199.85215,9841.9189453125,,,,,,,,,,,,,0,,,,-0.00245,,,,,,200.0707855,,,,
,27339205.025,200.0265045,14909.201171875,-1.17212245819459E-5,1.05852615870011E-6,1,0.999253354069792,40.0298881530762,1.98346473490423,21.0800003260374,-0.000132136362003708,-2.29299649922291E-5,0.25,1.76980438162713E-9,-1.17616784276428E-5,-1.09153883030011E-8,200.0265045,200.0265045,14904.4873046875,14913.9150390625,56.4578095725637,20.6033196568199,24.047956,0,0,0,40,4449,199.8452,14909.201171875,,,,,,,,,,,,,0,,,,-0.00245,,,,,,200.0265045,,,,
,27339305.645,200.0019989,19938.912109375,-2.87481375101841E-5,1.49634743196407E-6,1,0.999253354069792,40.0298881530762,1.9829354539531,21.0800003260374,-0.000322005099122124,-6.77270763351942E-5,0.25,-1.0162925316594E-6,-2.88462851643658E-5,-1.05087355361762E-6,200.0019989,200.0019989,19931.529296875,19946.294921875,56.7462304961599,20.6039172407609,24.427608,0,0,0,40,4449,199.84925,19938.912109375,,,,,,,,,,,,,0,,,,0,,,,,,200.0019989,,,,
,27339404.275,199.9929657,24869.0439453125,-4.64339586202126E-5,1.73160224876552E-6,1,0.999253354069792,40.0298881530762,1.98314456012897,21.0699997842312,-0.000522837282602705,-9.39603855724226E-5,0.25,-2.71450890076962E-7,-4.65939959682103E-5,-3.22480804734833E-7,199.9929657,199.9929657,24864.38671875,24873.701171875,56.6954246424098,20.607008837858,24.807261,0,0,0,40,4449,199.86805,24869.0439453125,,,,,,,,,,,,,0,,,,0.0049,,,,,,199.9929657,,,,
,27339505.365,199.9878387,29921.7763671875,-6.35481095202905E-5,1.64792680988579E-6,1,0.999253354069792,40.0298881530762,1.98325354591698,21.0699997842312,-0.000712745064501428,-0.000144904520654169,0.25,-1.81827830769012E-6,-6.37656053099913E-5,-1.89297878469643E-6,199.9878387,199.9878387,29916.630859375,29926.921875,56.4843849422175,20.6104112727445,24.427608,0,0,0,40,4449,199.8758,29921.7763671875,,,,,,,,,,,,,0,,,,0.0049,,,,,,199.9878387,,,,
,27339605.84,199.98909,34944.11328125,-8.16775283171395E-5,2.27182848102843E-6,1,0.999253354069792,40.0298881530762,1.98318108559702,21.0699997842312,-0.000917565042854812,-0.000177513916866953,0.25,-1.56324174487078E-6,-8.195793172754E-5,-1.6564049120371E-6,199.98909,199.98909,34939.15234375,34949.07421875,57.0002597649099,20.6071731688231,25.186911,0,0,0,40,4449,199.8845,34944.11328125,,,,,,,,,,,,,0,,,,0.0049,,,,,,199.98909,,,,
,27339707.965,199.9942322,40048.779296875,-0.000101046337271442,2.15052492498239E-6,1,0.999253354069792,40.0298881530762,1.9831827757432,21.0699997842312,-0.00113520577708816,-0.000219318753350958,0.25,-1.90838325438609E-6,-0.000101393281563796,-2.02333026307568E-6,199.9942322,199.9942322,40046.1171875,40051.44140625,56.7329428113329,20.6037310866579,24.807261,0,0,0,40,4449,199.8829,40048.779296875,,,,,,,,,,,,,0,,,,0,,,,,,199.9942322,,,,
,27339809.875,199.9934235,45141.791015625,-0.000118403656940791,2.59139448595099E-6,1,0.999253354069792,40.0298881530762,1.98342744540703,21.0699997842312,-0.00133526715748306,-0.000228791111572645,0.25,2.6793523233244E-7,-0.000118812925611723,1.42165202870331E-7,199.9934235,199.9934235,45134.3984375,45149.18359375,56.8791073444291,20.6079205152265,24.427608,0,0,0,40,4449,199.8938,45141.791015625,,,,,,,,,,,,,0,,,,-0.00245,,,,,,199.9934235,,,,
,27339909.735,199.9952011,50134.501953125,-0.000137033783655872,2.35872846533386E-6,1,0.999253354069792,40.0298881530762,1.98352798551948,21.0699997842312,-0.00154480172252045,-0.000268471858515797,0.25,-1.56623245425489E-8,-0.000137507136597096,-1.62039015463744E-7,199.9949188,199.9954834,50127.05078125,50141.953125,56.648526931256,20.6121702140864,25.186911,0,0,0,40,4449,199.8958,50134.501953125,,,,,,,,,,,,,0,,,,-0.00245,,,,,,199.9952011,,,,
,27340011.445,200.0023651,55214.423828125,-0.000155198113007121,2.61193495579818E-6,1,0.999253354069792,40.0298881530762,1.9834385257227,21.0699997842312,-0.00174385466046136,-0.000336526638952647,0.25,-2.8994290254152E-6,-0.000155731155948502,-3.07480245747366E-6,200.0023651,200.0023651,55209.40234375,55219.4453125,56.8392442899483,20.6138780259035,24.807261,0,0,0,40,4449,199.8984,55214.423828125,,,,,,,,,,,,,0,,,,0.00245,,,,,,200.0023651,,,,
,27340112.905,200.0024719,60289.169921875,-0.000176941038075224,2.64131762411365E-6,1,0.999253354069792,40.0298881530762,1.98340999264837,21.0699997842312,-0.00199079397745226,-0.000368377022706319,0.25,-1.94956619039765E-6,-0.000177550266724868,-2.14441941275547E-6,200.0024719,200.0024719,60281.3359375,60297.00390625,56.3014838687175,20.6118333786901,24.427608,0,0,0,40,4449,199.8915,60289.169921875,,,,,,,,,,,,,0,,,,0,,,,,,200.0024719,,,,
,27340212.475,200.0059814,65265.099609375,-0.00019573149544706,3.05400801013385E-6,1,0.999253354069792,40.0298881530762,1.98346602575641,21.0699997842312,-0.00219660989638903,-0.000440092171816706,0.25,-5.04746573478997E-6,-0.000196402401785005,-5.27255338743527E-6,200.0059814,200.0059814,65260.05859375,65270.140625,56.5742722219291,20.6124589308786,24.807261,0,0,0,40,4449,199.8855,65265.099609375,,,,,,,,,,,,,0,,,,-0.00245,,,,,,200.0059814,,,,
,27340313.955,200.0059052,70337.203125,-0.000212949189325834,3.90470601015324E-6,1,0.999253354069792,40.0298881530762,1.98352805925137,21.0699997842312,-0.00240044504990446,-0.000418150149400238,0.25,-1.10300904767043E-7,-0.000213684893329501,-3.36103301911072E-7,200.0059052,200.0059052,70332.2265625,70342.1796875,56.5414438241214,20.6128996892289,24.807261,0,0,0,40,4449,199.8736,70337.203125,,,,,,,,,,,,,0,,,,0,,,,,,200.0059052,,,,
,27340415.025,200.0123062,75387.48046875,-0.000230320999206701,2.89037035345888E-6,1,0.999253354069792,40.0298881530762,1.98339098663494,21.0699997842312,-0.00259352914503588,-0.000467011030673646,0.25,-1.4309049392854E-6,-0.000231115364922519,-1.6791125883359E-6,200.0122986,200.0123138,75385.0546875,75389.90625,56.6711941583137,20.6104909375667,24.807261,0,0,0,40,4449,199.86895,75387.48046875,,,,,,,,,,,,,0,,,,0,,,,,,200.0123062,,,,
,27340516.975,200.009491,80483.58203125,-0.000250606369237912,3.76451781100976E-6,1,0.999253354069792,40.0298881530762,1.98342131195162,21.0699997842312,-0.00281365225354706,-0.000556191413348242,0.25,-5.81918840874102E-6,-0.00025146631897645,-6.10339355857966E-6,200.009491,200.009491,80478.5234375,80488.640625,56.1381235081982,20.6157446391393,24.807261,0,0,0,40,4449,199.8565,80483.58203125,,,,,,,,,,,,,0,,,,-0.0049,,,,,,200.009491,,,,
,27340617.64,200.0114441,85516.671875,-0.000269476292757571,3.07379361580786E-6,1,0.999253354069792,40.0298881530762,1.98344700777608,21.0699997842312,-0.00302717901380938,-0.000588700461829769,0.25,-5.42608610410777E-6,-0.000270401958059214,-5.72817589716604E-6,200.0114441,200.0114441,85506.7265625,85526.6171875,56.472660514429,20.6160062464487,24.427608,0,0,0,40,4449,199.8486,85516.671875,,,,,,,,,,,,,0,,,,-0.0049,,,,,,200.0114441,,,,
,27340730.31,200.0154724,89834.09765625,-0.00028385280711697,3.58150659962487E-6,1,0.999253354069792,40.0298881530762,1.98352467602644,21.0699997842312,-0.00319830085484793,-0.000565410159649662,0.25,-8.62176796197208E-7,-0.000284833005340896,-1.16303599879845E-6,200.0154724,200.0154724,89826.890625,89841.3046875,56.320242953179,20.6177743953581,24.427608,0,0,0,40,4449,199.8345,89834.09765625,,,,,,,,,,,,,0,,,,0.00245,,,,,,200.0154724,,,,
,27340825.205,200.0047302,85094.18359375,-0.000267589538174746,2.63016701975118E-6,1,0.999253354069792,40.0298881530762,1.98350293735795,21.0699997842312,-0.00301589312823329,-0.000528002262091733,0.25,-3.67987980091643E-7,-0.000268514048873915,-6.50690333977359E-7,200.0047302,200.0047302,85088.921875,85099.4453125,56.5617661656214,20.6168094090617,25.186911,0,0,0,40,4449,199.83495,85094.18359375,,,,,,,,,,,,,0,,,,-0.0049,,,,,,200.0047302,,,,
,27340925.81,199.9972839,80065.13671875,-0.000247883712606867,2.99759083082746E-6,1,0.999253354069792,40.0298881530762,1.98337412187695,21.0699997842312,-0.00278942433420128,-0.000513267367210414,0.25,-2.48520382594342E-6,-0.000248737855346184,-2.75509215945362E-6,199.9972839,199.9972839,80055.328125,80074.9453125,56.8236117195637,20.6197786489616,24.807261,0,0,0,40,4449,199.8417,80065.13671875,,,,,,,,,,,,,0,,,,-0.00245,,,,,,199.9972839,,,,
,27341024.98,199.9923401,75106.515625,-0.000229560105179739,2.51480902596145E-6,1,0.999253354069792,40.0298881530762,1.9835713947771,21.0699997842312,-0.00258475485657072,-0.000467999165738157,0.25,-1.64700619060399E-6,-0.000230351755905518,-1.89521941367151E-6,199.9923401,199.9923401,75096.609375,75116.421875,56.8509687177368,20.6152689948699,24.807261,0,0,0,40,4449,199.84825,75106.515625,,,,,,,,,,,,,0,,,,0.00245,,,,,,199.9923401,,,,
,27341125.13,199.9915161,70101.484375,-0.000212804414972963,2.49803167842175E-6,1,0.999253354069792,40.0298881530762,1.98361841958052,21.0699997842312,-0.00239411865151474,-0.00044552334712808,0.25,-2.56178384035322E-6,-0.000213537118038463,-2.7959500510309E-6,199.9915161,199.9915161,70098.9765625,70103.9921875,56.5109603118714,20.613637827545,25.186911,0,0,0,40,4449,199.8581,70101.484375,,,,,,,,,,,,,0,,,,-0.00245,,,,,,199.9915161,,,,
,27341221.02,199.9923248,65308.041015625,-0.000193105006588346,3.03490287748257E-6,1,0.999253354069792,40.0298881530762,1.9836800035296,21.0699997842312,-0.00217010701089807,-0.000418403512970899,0.25,-3.57579470220504E-6,-0.000193768483124414,-3.79303605144466E-6,199.9923248,199.9923248,65300.7890625,65315.29296875,57.098744958333,20.6141808891184,24.807261,0,0,0,40,4449,199.86385,65308.041015625,,,,,,,,,,,,,0,,,,0,,,,,,199.9923248,,,,
,27341315.76,199.9862366,60572.32421875,-0.000174272492065553,3.39145510843598E-6,1,0.999253354069792,40.0298881530762,1.983650926972,21.0699997842312,-0.00196071076044913,-0.000364519232800519,0.25,-2.0670128700252E-6,-0.000174872469808117,-2.25943829544069E-6,199.9862366,199.9862366,60567.58984375,60577.05859375,56.5891231637945,20.6141877862944,24.807261,0,0,0,40,4449,199.8692,60572.32421875,,,,,,,,,,,,,0,,,,0,,,,,,199.9862366,,,,
,27341416.975,199.9903717,55514.84375,-0.000157855977767656,1.91576100936353E-6,1,0.999253354069792,40.0298881530762,1.98391697264613,21.0699997842312,-0.00177243825804008,-0.000352102428413148,0.25,-3.81233409402815E-6,-0.000158397292696176,-3.99369250562411E-6,199.9903717,199.9903717,55509.50390625,55520.18359375,56.4359239740252,20.6142255223251,24.807261,0,0,0,40,4449,199.87935,55514.84375,,,,,,,,,,,,,0,,,,0,,,,,,199.9903717,,,,
,27341517.06,199.9899597,50512.6640625,-0.000139638540641146,2.54752383911684E-6,1,0.999253354069792,40.0298881530762,1.9837589918065,21.0699997842312,-0.00157238495463124,-0.000284868062760795,0.25,-1.01490591433415E-6,-0.000140119851086102,-1.16750044165105E-6,199.9899597,199.9899597,50507.70703125,50517.62109375,56.6172617904868,20.6186806579732,24.427608,0,0,0,40,4449,199.8867,50512.6640625,,,,,,,,,,,,,0,,,,0,,,,,,199.9899597,,,,
,27341617.475,199.9862518,45494.958984375,-0.000121220999150675,2.53940624443519E-6,1,0.999253354069792,40.0298881530762,1.98377501166673,21.0699997842312,-0.00136554840125492,-0.000244176772173505,0.25,-6.03994824094662E-7,-0.000121639097628089,-7.3577464873728E-7,199.9862518,199.9862518,45484.8984375,45505.01953125,56.8134505488137,20.6198419318901,25.186911,0,0,0,40,4449,199.89105,45494.958984375,,,,,,,,,,,,,0,,,,0.00245,,,,,,199.9862518,,,,
,27341718.395,199.9837646,40447.30859375,-0.00010195616817254,2.24350598136897E-6,1,0.999253354069792,40.0298881530762,1.98326719441132,21.0699997842312,-0.00114813319617602,-0.000205993309603174,0.25,-5.67426743819886E-7,-0.000102307733869952,-6.78680365789801E-7,199.9837646,199.9837646,40437.30078125,40457.31640625,56.7548284098714,20.6205950958065,24.807261,0,0,0,40,4449,199.91295,40447.30859375,,,,,,,,,,,,,0,,,,0.00245,,,,,,199.9837646,,,,
,27341817.86,199.9887695,35477.341796875,-8.36357398027423E-5,1.6894592550492E-6,1,0.999253354069792,40.0298881530762,1.9834914914164,21.0699997842312,-0.000943377687897691,-0.000160645693566942,0.25,2.75496409919072E-7,-8.39248881790906E-5,1.86617115452923E-7,199.9887695,199.9887695,35474.61328125,35480.0703125,56.8470605751406,20.6210839307236,24.807261,0,0,0,40,4449,199.9182,35477.341796875,,,,,,,,,,,,,0,,,,0,,,,,,199.9887695,,,,
,27341913.32,199.9902954,30707.3955078125,-6.66142611324495E-5,1.53683461531386E-6,1,0.999253354069792,40.0298881530762,1.98363596421044,21.0800003260374,-0.000748807114775698,-0.000143086296260764,0.25,-1.1221436837838E-6,-6.68430969218978E-5,-1.19769607281266E-6,199.9902954,199.9902954,30702.16796875,30712.623046875,57.1714364106214,20.6206173509525,24.807261,0,0,0,40,4449,199.92915,30707.3955078125,,,,,,,,,,,,,0,,,,0.00245,,,,,,199.9902954,,,,
,27342009.26,199.9920807,25911.890625,-4.94756160532697E-5,1.43560526726802E-6,1,0.999253354069792,40.0298881530762,1.98356398138125,21.0699997842312,-0.000555879653248225,-0.000107728271725237,0.25,-9.62777946636054E-7,-4.96454184486514E-5,-1.01943455051487E-6,199.9920807,199.9920807,25899.40625,25924.375,56.8837971155445,20.6226690451703,24.807261,0,0,0,40,4449,199.9318,25911.890625,,,,,,,,,,,,,0,,,,-0.00245,,,,,,199.9920807,,,,
,27342104.29,199.9879913,21162.080078125,-3.41317893285071E-5,1.51668572066264E-6,1,0.999253354069792,40.0298881530762,1.9835828472468,21.0699997842312,-0.000381713674156115,-8.45386861604249E-5,0.25,-1.57061956402985E-6,-3.42479465799729E-5,-1.61289730478666E-6,199.9879913,199.9879913,21157.25,21166.91015625,56.7829670365637,20.6234131833063,24.427608,0,0,0,40,4449,199.93975,21162.080078125,,,,,,,,,,,,,0,,,,0.0049,,,,,,199.9879913,,,,
,27342196.14,199.9883423,16572.4677734375,-1.78071894687335E-5,1.06311387216632E-6,1,0.999253354069792,40.0298881530762,1.98380434808856,21.0699997842312,-0.000198552594153834,-4.76550287133246E-5,0.25,-1.13380305996234E-6,-1.78674449004091E-5,-1.15697523468437E-6,199.9883423,199.9883423,16569.998046875,16574.9375,56.1592274782175,20.6182319292141,24.427608,0,0,0,40,4449,199.9494,16572.4677734375,,,,,,,,,,,,,0,,,,0,,,,,,199.9883423,,,,
,27342292.995,199.9900208,11732.23828125,-1.87749443569395E-6,5.1637058358015E-7,1,0.999253354069792,40.0298881530762,1.98370254841292,21.0699997842312,-2.03614260883339E-5,-8.31667854440236E-6,0.25,-4.11570110643398E-7,-1.88353035910071E-6,-4.15024582502068E-7,199.9900208,199.9900208,11727.2705078125,11737.2060546875,56.8142321773329,20.6207030355213,24.427608,0,0,0,40,4449,199.95575,11732.23828125,,,,,,,,,,,,,0,,,,0.00245,,,,,,199.9900208,,,,
,27342387.89,199.9917145,6987.1142578125,1.17799295819693E-5,5.40356401210119E-7,1,0.999253354069792,40.0298881530762,1.98364182729368,21.0699997842312,0.000134011965930189,1.61243172275657E-5,0.25,-6.15826510630887E-7,1.18212623188465E-5,-6.05174851069251E-7,199.9917145,199.9917145,6979.7919921875,6994.4365234375,56.7665528376599,20.6201581396367,25.186911,0,0,0,40,4449,199.9606,6987.1142578125,,,,,,,,,,,,,0,,,,0,,,,,,199.9917145,,,,
,27342485.33,199.995575,2116.33837890625,2.01365463303161E-5,3.59280463803941E-7,1,0.999253354069792,40.0298881530762,1.98389754296685,21.0699997842312,0.000227080335114421,3.9237057207329E-5,0.25,-1.76376141675268E-8,2.02060709448413E-5,4.1708918784245E-9,199.995575,199.995575,2110.97802734375,2121.69873046875,56.7415407250445,20.6232243926663,24.807261,0,0,0,40,4449,199.96395,2116.33837890625,,,,,,,,,,,,,0,,,,-0.00245,,,,,,199.995575,,,,
,27342579.635,199.9939117,-2594.072265625,9.03288791302665E-6,4.41428191205178E-7,1,0.999253354069792,40.0298881530762,1.98384767074168,21.0699997842312,0.000102049492813045,1.65192147909337E-5,0.25,-1.03820754806861E-7,9.06418025631081E-6,-9.43704344937018E-8,199.9939117,199.9939117,-2601.47631835938,-2586.66821289062,57.0909286731407,20.6220264658846,24.807261,0,0,0,40,4449,199.97095,-2594.072265625,,,,,,,,,,,,,0,,,,0,,,,,,199.9939117,,,,
,27342672.855,199.9980774,-7253.673828125,-4.64632370472271E-6,7.13730459124144E-7,1,0.999253354069792,40.0298881530762,1.98396399049724,21.0699997842312,-5.16369763489271E-5,-1.34376482145564E-5,0.25,-3.84718238751322E-7,-4.66194490811002E-6,-3.91085174338371E-7,199.9980774,199.9980774,-7261.2080078125,-7246.1396484375,56.6297678467945,20.6203963412419,25.186911,0,0,0,40,4449,199.9753,-7253.673828125,,,,,,,,,,,,,0,,,,-0.00245,,,,,,199.9980774,,,,
,27342770.155,200.0006104,-12116.7392578125,4.52982495848408E-6,7.51864308593218E-7,1,0.999253354069792,40.0298881530762,1.98393904357916,21.0699997842312,5.08495979864453E-5,1.01762341029179E-5,0.25,1.15727364620409E-7,4.54533660974715E-6,1.21032280369925E-7,200.0006104,200.0006104,-12119.1259765625,-12114.3525390625,57.115940785756,20.6218151056702,25.186911,0,0,0,40,4449,199.9697,-12116.7392578125,,,,,,,,,,,,,0,,,,0,,,,,,200.0006104,,,,
,27342866.34,200.0057678,-16924.345703125,1.98144545988603E-5,1.19614052004424E-6,1,0.999253354069792,40.0298881530762,1.98398295092497,21.0699997842312,0.000220850791798304,5.36184150074498E-5,0.25,1.31367753241455E-6,1.9881435390323E-5,1.33963618495211E-6,200.0057678,200.0057678,-16931.740234375,-16916.951171875,56.7079306987175,20.6219687796186,24.807261,0,0,0,40,4449,199.9644,-16924.345703125,,,,,,,,,,,,,0,,,,0,,,,,,200.0057678,,,,
,27342962.18,200.00979615,-21713.9794921875,3.6158690988777E-5,1.36753710113099E-6,1,0.999253354069792,40.0298881530762,1.98392002104689,21.0699997842312,0.000408064873997274,6.87431886426383E-5,0.25,-1.83498921112875E-7,3.62837164970078E-5,-1.4510094355927E-7,200.0097656,200.0098267,-21718.919921875,-21709.0390625,56.8486238321791,20.6223786526114,24.807261,0,0,0,40,4449,199.9559,-21713.9794921875,,,,,,,,,,,,,0,,,,0.00245,,,,,,200.00979615,,,,
,27343056.865,200.0101776,-26446.2890625,5.30291799903567E-5,1.7030393695313E-6,1,0.999253354069792,40.0298881530762,1.98401093625649,21.0699997842312,0.000596221647808239,0.000113830867022384,0.25,8.84753700777668E-7,5.32113079754809E-5,9.44954147523847E-7,200.0101776,200.0101776,-26451.509765625,-26441.068359375,56.8642564025637,20.6239599261756,24.807261,0,0,0,40,4449,199.94685,-26446.2890625,,,,,,,,,,,,,0,,,,0,,,,,,200.0101776,,,,
,27343154.025,200.0085297,-31301.8779296875,6.88658096142736E-5,1.54416735425508E-6,1,0.999253354069792,40.0298881530762,1.98404897579925,21.0699997842312,0.000771720580739151,0.000162631717107695,0.25,2.4619349535927E-6,6.91009412928518E-5,2.54451519302832E-6,200.0085297,200.0085297,-31304.337890625,-31299.41796875,57.1128142716791,20.6252661006702,24.427608,0,0,0,40,4449,199.93605,-31301.8779296875,,,,,,,,,,,,,0,,,,0,,,,,,200.0085297,,,,
,27343248.28,200.0104523,-36013.599609375,8.51112272876122E-5,2.03281029367948E-6,1,0.999253354069792,40.0298881530762,1.98407068249646,21.0699997842312,0.000953968322743172,0.000199910898536048,0.25,2.94640676275E-6,8.54019544585126E-5,3.04797096022954E-6,200.0104523,200.0104523,-36021.125,-36006.07421875,57.1214121853907,20.6229832273719,24.427608,0,0,0,40,4449,199.92855,-36013.599609375,,,,,,,,,,,,,0,,,,-0.00245,,,,,,200.0104523,,,,
,27343345.055,200.0128021,-40848.728515625,0.00010428546862913,2.34510448168371E-6,1,0.999253354069792,40.0298881530762,1.98411076490996,21.0699997842312,0.00117322689199396,0.00022007073155857,0.25,1.40388209850917E-6,0.000104644086768212,1.52049805896619E-6,200.0128021,200.0128021,-40858.77734375,-40838.6796875,57.044812590506,20.6242800440882,25.186911,0,0,0,40,4449,199.91905,-40848.728515625,,,,,,,,,,,,,0,,,,0,,,,,,200.0128021,,,,
,27343442.845,200.0135345,-45736.208984375,0.000120328182395837,2.09155659762845E-6,1,0.999253354069792,40.0298881530762,1.98418313286037,21.0699997842312,0.00134778237252589,0.000288337504454606,0.25,4.67087595962182E-6,0.000120738741941576,4.8157176327433E-6,200.0135345,200.0135345,-45746.11328125,-45726.3046875,57.5223876157561,20.6242034230633,25.186911,0,0,0,40,4449,199.9093,-45736.208984375,,,,,,,,,,,,,0,,,,-0.0049,,,,,,200.0135345,,,,
,27343536.845,200.0115814,-50433.501953125,0.000139447359239996,2.22044471858443E-6,1,0.999253354069792,40.0298881530762,1.98417949532726,21.0699997842312,0.00156539785845986,0.000314195626866299,0.25,3.64369412170198E-6,0.00013992510380461,3.80515673620245E-6,200.0115814,200.0115814,-50438.7109375,-50428.29296875,56.9103724851983,20.6277647270042,24.807261,0,0,0,40,4449,199.89925,-50433.501953125,,,,,,,,,,,,,0,,,,-0.0049,,,,,,200.0115814,,,,
,27343637.29,200.0081482,-55452.76171875,0.000158056246064617,2.74166488095406E-6,1,0.999253354069792,40.0298881530762,1.98437065330225,21.0699997842312,0.00176797079170586,0.000393523822868188,0.25,7.44353191677642E-6,0.000158594291459009,7.63764230323899E-6,200.0081482,200.0081482,-55460.2265625,-55445.296875,56.9596150819099,20.6233554180037,24.807261,0,0,0,40,4449,199.886,-55452.76171875,,,,,,,,,,,,,0,,,,0,,,,,,200.0081482,,,,
,27343735.045,200.0125961,-60339.86328125,0.000175890288837191,2.22737568555587E-6,1,0.999253354069792,40.0298881530762,1.98442125302255,21.0699997842312,0.00197264712545083,0.000408332005649825,0.25,5.65881109425806E-6,0.000176491884021466,5.86536446149926E-6,200.0123138,200.0128784,-60347.265625,-60332.4609375,56.1185827952175,20.6247455304034,25.186911,0,0,0,40,4449,199.884,-60339.86328125,,,,,,,,,,,,,0,,,,0.00245,,,,,,200.0125961,,,,
,27343833.86,200.0134888,-65277.462890625,0.000194892050503366,2.77797320301205E-6,1,0.999253354069792,40.0298881530762,1.98433967109748,21.0699997842312,0.00218637520901971,0.00044837167412834,0.25,5.91096535542666E-6,0.000195559089104981,6.13816080042689E-6,200.0134888,200.0134888,-65284.7578125,-65270.16796875,57.0057311645445,20.6236755351203,24.807261,0,0,0,40,4449,199.8715,-65277.462890625,,,,,,,,,,,,,0,,,,0.0049,,,,,,200.0134888,,,,
,27343932.33,200.013916,-70199.1484375,0.000212072709013519,3.07121623344461E-6,1,0.999253354069792,40.0298881530762,1.98425084611149,21.0699997842312,0.00237629000035769,0.000503560938900123,0.25,7.82326232531933E-6,0.000212797157347963,8.07481969343449E-6,200.013916,200.013916,-70206.6875,-70191.609375,56.4914195988906,20.6250987123967,24.807261,0,0,0,40,4449,199.85895,-70199.1484375,,,,,,,,,,,,,0,,,,0,,,,,,200.013916,,,,
,27344032.125,200.0134735,-75186.15234375,0.000228261620289829,2.89996329151134E-6,1,0.999253354069792,40.0298881530762,1.98423655914177,21.0699997842312,0.00255818206469843,0.000539057078969541,0.25,8.16023933543187E-6,0.000229041743394534,8.42958084043995E-6,200.0134735,200.0134735,-75188.734375,-75183.5703125,56.7962547213906,20.6256052297495,25.186911,0,0,0,40,4449,199.8455,-75186.15234375,,,,,,,,,,,,,0,,,,0.0049,,,,,,200.0134735,,,,
,27344130.1,200.0120087,-80083.26953125,0.000250949167561077,3.49328563886907E-6,1,0.999253354069792,40.0298881530762,1.98447498856728,21.0699997842312,0.00282558603427858,0.000518908764133254,0.25,2.42894073133144E-6,0.000251813842146883,2.70186620159818E-6,200.0120087,200.0120087,-80095.796875,-80070.7421875,57.0362146767945,20.6219496144573,24.807261,0,0,0,40,4449,199.83935,-80083.26953125,,,,,,,,,,,,,0,,,,0,,,,,,200.0120087,,,,
,27344227.925,200.0123138,-84970.71875,0.000267314824169499,3.00490898902009E-6,1,0.999253354069792,40.0298881530762,1.98446072249253,21.0699997842312,0.00299593923201521,0.000632776413553287,0.25,9.68382509418608E-6,0.000268228516067991,9.99845997678822E-6,200.0123138,200.0123138,-84978.3515625,-84963.0859375,56.9502355396791,20.6255357382665,25.186911,0,0,0,40,4449,199.8298,-84970.71875,,,,,,,,,,,,,0,,,,-0.0049,,,,,,200.0123138,,,,
,27344320.81,200.0146942,-89615.015625,0.000283390606656334,2.89093585760704E-6,1,0.999253354069792,40.0298881530762,1.98433010428731,21.0699997842312,0.00317978827622883,0.000648457087209431,0.25,8.28669797620618E-6,0.00028436141285139,8.61279442375302E-6,200.0146942,200.0146942,-89625.15625,-89604.875,56.8337728903137,20.6277588806887,24.807261,0,0,0,40,4449,199.81775,-89615.015625,,,,,,,,,,,,,0,,,,0,,,,,,200.0146942,,,,
,27344432.87,200.006012,-85757.41796875,0.000268461217820361,3.21579695680148E-6,1,0.999253354069792,40.0298881530762,1.98436707150542,21.0699997842312,0.00300833852886135,0.000637270369142721,0.25,9.88581352698467E-6,0.000269378729940679,1.02022740575212E-5,200.006012,200.006012,-85760.0859375,-85754.75,56.5359724244868,20.6279271470141,24.427608,0,0,0,40,4449,199.8169,-85757.41796875,,,,,,,,,,,,,0,,,,0.00245,,,,,,200.006012,,,,
,27344530.5,199.9978027,-80877.73828125,0.000250023802643042,3.18614679757016E-6,1,0.999253354069792,40.0298881530762,1.98442696625741,21.0699997842312,0.00280780465270444,0.000559011523323085,0.25,6.14648713986504E-6,0.00025088148882441,6.43122445414894E-6,199.9978027,199.9978027,-80887.796875,-80867.6796875,57.3965454241599,20.6244021098462,24.807261,0,0,0,40,4449,199.81875,-80877.73828125,,,,,,,,,,,,,0,,,,0,,,,,,199.9978027,,,,
,27344628.775,199.9938202,-75967.83984375,0.000235186768328925,2.58155249732019E-6,1,0.999253354069792,40.0298881530762,1.98447099102638,21.0699997842312,0.00264237092347362,0.000519324721942622,0.25,5.20269343421406E-6,0.00023599410845402,5.46907447467375E-6,199.9938202,199.9938202,-75975.4765625,-75960.203125,57.2957153451791,20.6248578107414,24.807261,0,0,0,40,4449,199.82725,-75967.83984375,,,,,,,,,,,,,0,,,,0.0049,,,,,,199.9938202,,,,
,27344729.18,199.9906006,-70948.20703125,0.000214599287671243,2.78996168317412E-6,1,0.999253354069792,40.0298881530762,1.98458648606398,21.0699997842312,0.00241103085756317,0.0004748637202951,0.25,4.83301811850591E-6,0.000215335805716529,5.07687144978287E-6,199.9906006,199.9906006,-70958.3203125,-70938.09375,56.8228300910445,20.6247869394539,24.427608,0,0,0,40,4449,199.841,-70948.20703125,,,,,,,,,,,,,0,,,,-0.00245,,,,,,199.9906006,,,,
,27344827.32,199.989502,-66043.65234375,0.000197327907295868,3.02967860019726E-6,1,0.999253354069792,40.0298881530762,1.98444006472393,21.0699997842312,0.00221294743400202,0.000458967146636157,0.25,6.42547621465429E-6,0.000198002978743576,6.65700165437878E-6,199.989502,199.989502,-66051.0390625,-66036.265625,56.9752476522945,20.6231399607736,24.427608,0,0,0,40,4449,199.8451,-66043.65234375,,,,,,,,,,,,,0,,,,-0.00245,,,,,,199.989502,,,,
,27344926.725,199.9911957,-61073.8046875,0.000178005109295439,2.82600998975336E-6,1,0.999253354069792,40.0298881530762,1.98429420284437,21.0699997842312,0.00199646928846479,0.000411923173060333,0.25,5.61218376680271E-6,0.000178614190505217,5.82080230441363E-6,199.9911957,199.9911957,-61078.5625,-61069.046875,56.770460980256,20.6232262726429,25.186911,0,0,0,40,4449,199.8544,-61073.8046875,,,,,,,,,,,,,0,,,,0,,,,,,199.9911957,,,,
,27345024.765,199.9896545,-56174.2109375,0.000159351757412736,2.15262599021303E-6,1,0.999253354069792,40.0298881530762,1.98447450726912,21.0699997842312,0.00179208162215064,0.000341898951874112,0.25,2.63952569143453E-6,0.000159899498127284,2.81839713068499E-6,199.9896545,199.9896545,-56186.7578125,-56161.6640625,56.7110572127945,20.6215999705737,24.807261,0,0,0,40,4449,199.86075,-56174.2109375,,,,,,,,,,,,,0,,,,0,,,,,,199.9896545,,,,
,27345123.57,199.9880981,-51239.7890625,0.000143390496969789,2.80812226610814E-6,1,0.999253354069792,40.0298881530762,1.98444747556516,21.0699997842312,0.00161220081289498,0.000309709378502901,0.25,2.55751289891463E-6,0.000143883135891219,2.71941100138786E-6,199.9880981,199.9880981,-51250.19140625,-51229.38671875,56.5203398541021,20.6216270481096,24.427608,0,0,0,40,4449,199.8702,-51239.7890625,,,,,,,,,,,,,0,,,,-0.00245,,,,,,199.9880981,,,,
,27345217.94,199.98895265,-46522.46484375,0.000125473656341515,2.02650609531703E-6,1,0.999253354069792,40.0298881530762,1.98426339223148,21.0699997842312,0.00140721814911493,0.000290623536455657,0.25,3.97895596779074E-6,0.00012590283134768,4.12689744176069E-6,199.9887848,199.9891205,-46527.5546875,-46517.375,57.159711982833,20.6239895587454,25.186911,0,0,0,40,4449,199.87795,-46522.46484375,,,,,,,,,,,,,0,,,,-0.0049,,,,,,199.98895265,,,,
,27345315,199.9896393,-41670.248046875,0.000108413532851949,2.11149121216886E-6,1,0.999253354069792,40.0298881530762,1.98427874517936,21.0699997842312,0.00121392689943241,0.000262431765987745,0.25,4.44162092213871E-6,0.000108783236623361,4.57313887624054E-6,199.9896393,199.9896393,-41675.23046875,-41665.265625,56.8642564025637,20.624287965333,24.427608,0,0,0,40,4449,199.88695,-41670.248046875,,,,,,,,,,,,,0,,,,-0.0049,,,,,,199.9896393,,,,
,27345412.5,199.9914703,-36797.951171875,8.99406258243666E-5,1.78305768327128E-6,1,0.999253354069792,40.0298881530762,1.98426837702043,21.0699997842312,0.00101065765790049,0.000197096235129666,0.25,1.85636783025401E-6,9.02492575972682E-5,1.95934553058882E-6,199.9914703,199.9914703,-36807.86328125,-36788.0390625,56.8447156895829,20.622710660241,24.807261,0,0,0,40,4449,199.89395,-36797.951171875,,,,,,,,,,,,,0,,,,0.00245,,,,,,199.9914703,,,,
,27345509.925,199.9912872,-31931.1220703125,7.33014181398656E-5,1.75264706079807E-6,1,0.999253354069792,40.0298881530762,1.98430619897723,21.0699997842312,0.000819542793294105,0.00018456349913746,0.25,3.63448865407536E-6,7.35506460065864E-5,3.7258891052842E-6,199.9912872,199.9912872,-31941.1015625,-31921.142578125,57.1753445532176,20.6233257777954,24.427608,0,0,0,40,4449,199.90065,-31931.1220703125,,,,,,,,,,,,,0,,,,-0.0049,,,,,,199.9912872,,,,
,27345607.135,199.9857635,-27071.4521484375,5.51742913302217E-5,1.37951534484917E-6,1,0.999253354069792,40.0298881530762,1.98431500220143,21.0699997842312,0.000619777943088244,0.000122213242503617,0.25,1.25397649606745E-6,5.53634722779784E-5,1.31776251882913E-6,199.9857635,199.9857635,-27073.935546875,-27068.96875,56.8580033744099,20.6220955283835,24.807261,0,0,0,40,4449,199.91405,-27071.4521484375,,,,,,,,,,,,,0,,,,0,,,,,,199.9857635,,,,
,27345703.93,199.9898834,-22233.861328125,3.73239876326468E-5,1.30162937385851E-6,1,0.999253354069792,40.0298881530762,1.98414047229625,21.0699997842312,0.000418729471614297,8.55397797583486E-5,0.25,1.10295602624875E-6,3.74516717531383E-5,1.14705481365259E-6,199.9898834,199.9898834,-22241.44140625,-22226.28125,57.0369963053137,20.6221126195842,24.807261,0,0,0,40,4449,199.9214,-22233.861328125,,,,,,,,,,,,,0,,,,-0.0049,,,,,,199.9898834,,,,
,27345801.5,199.9890594,-17358.9560546875,2.13267488332808E-5,1.16650908094818E-6,1,0.999253354069792,40.0298881530762,1.98407678997631,21.0699997842312,0.000236608427760973,6.40994532189893E-5,0.25,1.98026865800291E-6,2.13982410111343E-5,2.01016569478789E-6,199.9890594,199.9890594,-17369.11328125,-17348.798828125,56.9557069393137,20.623236857587,25.186911,0,0,0,40,4449,199.9331,-17358.9560546875,,,,,,,,,,,,,0,,,,0.00245,,,,,,199.9890594,,,,
,27345899.085,199.9919128,-12478.87109375,5.60207653965295E-6,7.25379917510393E-7,1,0.999253354069792,40.0298881530762,1.98414172440594,21.0699997842312,6.22457398382415E-5,1.63089395299268E-5,0.25,4.73242178778506E-7,5.62090394141782E-6,4.80943049511223E-7,199.9919128,199.9919128,-12486.353515625,-12471.388671875,56.8806706014676,20.6218470657938,24.807261,0,0,0,40,4449,199.9372,-12478.87109375,,,,,,,,,,,,,0,,,,0,,,,,,199.9919128,,,,
,27345994.865,199.9938965,-7691.11352539063,-8.3914462328292E-6,5.52296571746252E-7,1,0.999253354069792,40.0298881530762,1.98437661487956,21.0699997842312,-9.48436640109041E-5,-1.52537565655568E-5,0.25,1.04977247767636E-7,-8.42052717230035E-6,9.62382242568771E-8,199.9938965,199.9938965,-7693.52001953125,-7688.70703125,56.8165770628906,20.6208321422878,24.807261,0,0,0,40,4449,199.9396,-7691.11352539063,,,,,,,,,,,,,0,,,,0,,,,,,199.9938965,,,,
,27346091.26,199.9947052,-2875.08837890625,-1.88528587102986E-5,3.65863538338839E-7,1,0.999253354069792,40.0298881530762,1.98449040188301,21.0699997842312,-0.000213137179037201,-3.40268916169406E-5,0.25,2.57618152090906E-7,-1.89182137760296E-5,2.38033565321148E-7,199.9947052,199.9947052,-2879.98461914062,-2870.19213867187,57.3277621144676,20.6195260758399,25.186911,0,0,0,40,4449,199.94645,-2875.08837890625,,,,,,,,,,,,,0,,,,0,,,,,,199.9947052,,,,
,27346185.69,199.9957581,1842.38415527344,-1.21861926247769E-5,3.7674299055104E-7,1,0.999253354069792,40.0298881530762,1.98455479185534,21.0699997842312,-0.000136174474678222,-3.11971855414875E-5,0.25,-6.49342902576573E-7,-1.22275500655956E-5,-6.64821230711544E-7,199.9957581,199.9957581,1835.10534667969,1849.66296386719,56.8470605751406,20.6171075132345,25.186911,0,0,0,40,4449,199.948,1842.38415527344,,,,,,,,,,,,,0,,,,-0.0049,,,,,,199.9957581,,,,
,27346282.19,199.9998779,6665.19262695313,4.47002078703275E-6,5.19495254450842E-7,1,0.999253354069792,40.0298881530762,1.98466277856155,21.0699997842312,5.28229448578652E-5,-5.0804481937578E-6,0.25,-1.22681484352331E-6,4.48678106743143E-6,-1.22620012153644E-6,199.9998779,199.9998779,6662.67919921875,6667.7060546875,57.0510656186599,20.6160210731747,24.807261,0,0,0,40,4449,199.9489,6665.19262695313,,,,,,,,,,,,,0,,,,-0.00245,,,,,,199.9998779,,,,
,27346377.91,200.00121305,11450.6694335938,-2.21395402332889E-6,6.16589495855186E-7,1,0.999253354069792,40.0298881530762,1.98453207797599,21.0699997842312,-2.17750310734433E-5,-2.27357273726488E-5,0.25,-1.63126108144443E-6,-2.21982925988307E-6,-1.63929048051467E-6,200.0010223,200.0014038,11440.8759765625,11460.462890625,57.0002597649099,20.6182477962114,24.807261,0,0,0,40,4449,199.9452,11450.6694335938,,,,,,,,,,,,,0,,,,0.0049,,,,,,200.00121305,,,,
,27346474.925,200.0079651,16298.5029296875,-1.87080775649335E-5,9.60407768051924E-7,1,0.999253354069792,40.0298881530762,1.98457267476816,21.0699997842312,-0.000206659790474539,-6.16849650945091E-5,0.25,-2.21966770479144E-6,-1.87702560994014E-5,-2.24756496385623E-6,200.0079651,200.0079651,16293.6904296875,16303.3154296875,56.5390989385637,20.6158505861958,25.186911,0,0,0,40,4449,199.9387,16298.5029296875,,,,,,,,,,,,,0,,,,0.0049,,,,,,200.0079651,,,,
,27346571.785,200.0071259,21140.6455078125,-3.32888424987717E-5,1.16856220315492E-6,1,0.999253354069792,40.0298881530762,1.98463009758361,21.0699997842312,-0.00037172781354266,-8.67889918302445E-5,0.25,-1.91275708413526E-6,-3.34016981877984E-5,-1.95530688756157E-6,200.0071259,200.0071259,21130.65625,21150.634765625,57.2988418592561,20.6158979976842,25.186911,0,0,0,40,4449,199.9314,21140.6455078125,,,,,,,,,,,,,0,,,,-0.0049,,,,,,200.0071259,,,,
,27346666.94,200.0057373,25895.79296875,-5.02039905130211E-5,1.37498695249851E-6,1,0.999253354069792,40.0298881530762,1.98468109953172,21.0699997842312,-0.000562133470734003,-0.000122229574497551,0.25,-2.11675872642373E-6,-5.03750408819717E-5,-2.17818674306195E-6,200.0057373,200.0057373,25888.275390625,25903.310546875,57.5161345876022,20.6154819866619,25.186911,0,0,0,40,4449,199.9252,25895.79296875,,,,,,,,,,,,,0,,,,-0.00245,,,,,,200.0057373,,,,
,27346763.825,200.0086975,30738.5361328125,-6.87658498239301E-5,1.42956106728879E-6,1,0.999253354069792,40.0298881530762,1.98470224714963,21.0699997842312,-0.000768729432290892,-0.00017461440620847,0.25,-3.53706112292288E-6,-6.89994747525818E-5,-3.62326957163387E-6,200.0086975,200.0086975,30726.283203125,30750.7890625,57.362935397833,20.615169595684,24.807261,0,0,0,40,4449,199.9194,30738.5361328125,,,,,,,,,,,,,0,,,,0,,,,,,200.0086975,,,,
,27346859.985,200.0097961,35543.927734375,-8.4838663039477E-5,1.94908742562891E-6,1,0.999253354069792,40.0298881530762,1.98451483004456,21.0699997842312,-0.000947974903388308,-0.00021740235955147,0.25,-4.54077119572429E-6,-8.5126733886413E-5,-4.6475730683972E-6,200.0097961,200.0097961,35533.92578125,35553.9296875,56.4804767996214,20.6166700656198,25.186911,0,0,0,40,4449,199.9142,35543.927734375,,,,,,,,,,,,,0,,,,-0.00245,,,,,,200.0097961,,,,
,27346957.345,200.013504,40411.478515625,-0.000103437570494691,1.94178656125815E-6,1,0.999253354069792,40.0298881530762,1.98436489174209,21.0699997842312,-0.00116135335786664,-0.000232569326237229,0.25,-2.65696278102423E-6,-0.000103791909679828,-2.77702939785159E-6,200.013504,200.013504,40401.33984375,40421.6171875,57.0033862789868,20.6198543902043,24.807261,0,0,0,40,4449,199.9005,40411.478515625,,,,,,,,,,,,,0,,,,-0.0098,,,,,,200.013504,,,,
,27347054.78,200.0127258,45282.099609375,-0.000120963849257287,2.17393024289297E-6,1,0.999253354069792,40.0298881530762,1.98449044719014,21.0699997842312,-0.00135498326030553,-0.000290591993869914,0.25,-4.75654807646989E-6,-0.000121376508567324,-4.90240395989655E-6,200.0127258,200.0127258,45279.51171875,45284.6875,56.6883899857368,20.6168319427695,24.427608,0,0,0,40,4449,199.8916,45282.099609375,,,,,,,,,,,,,0,,,,-0.0049,,,,,,200.0127258,,,,
,27347150.39,200.0126038,50062.17578125,-0.000138463775897487,1.90479436071739E-6,1,0.999253354069792,40.0298881530762,1.9844833919595,21.0699997842312,-0.0015469325171896,-0.000356080216911231,0.25,-7.52405323500287E-6,-0.000138933967881591,-7.69790719002636E-6,200.0126038,200.0126038,50052.30078125,50072.05078125,56.4562463155252,20.6163882378984,24.807261,0,0,0,40,4449,199.88105,50062.17578125,,,,,,,,,,,,,0,,,,-0.00245,,,,,,200.0126038,,,,
,27347250.435,200.0101776,55059.244140625,-0.000156571350604702,2.06691831331112E-6,1,0.999253354069792,40.0298881530762,1.98450612770895,21.0699997842312,-0.00175032564775188,-0.000396471251972776,0.25,-7.96042794179684E-6,-0.000157103697118398,-8.15478350005658E-6,200.0101776,200.0101776,55054.140625,55064.34765625,57.108906129083,20.618093923839,24.807261,0,0,0,40,4449,199.87195,55059.244140625,,,,,,,,,,,,,0,,,,0.0049,,,,,,200.0101776,,,,
,27347346.78,200.0104599,59874.63671875,-0.000174704977896392,2.57336678840729E-6,1,0.999253354069792,40.0298881530762,1.98445308594126,21.0699997842312,-0.00195542734008201,-0.000428367412422405,0.25,-7.64049125774412E-6,-0.000175300373385698,-7.85268598691754E-6,200.0104218,200.010498,59867.26171875,59882.01171875,56.6907348712945,20.6163496812916,24.807261,0,0,0,40,4449,199.86815,59874.63671875,,,,,,,,,,,,,0,,,,0,,,,,,200.0104599,,,,
,27347446.79,200.0130615,64872.462890625,-0.000193656726838325,2.45013228275027E-6,1,0.999253354069792,40.0298881530762,1.98444250209108,21.0699997842312,-0.0021666903612041,-0.000479720443556266,0.25,-8.90302124020258E-6,-0.000194316313688034,-9.13930687843345E-6,200.0130615,200.0130615,64865.00390625,64879.921875,57.2300585495638,20.6187630169931,25.186911,0,0,0,40,4449,199.8496,64872.462890625,,,,,,,,,,,,,0,,,,-0.0049,,,,,,200.0130615,,,,
,27347544.235,200.0140991,69745.28125,-0.000208278232147414,2.60103871714498E-6,1,0.999253354069792,40.0298881530762,1.98422760891762,21.0699997842312,-0.00232362705584375,-0.000552814887003337,0.25,-1.28502247868904E-5,-0.000208984231387261,-1.31152073605897E-5,200.0140991,200.0140991,69737.8203125,69752.7421875,57.0495023616214,20.6178814500525,25.566563,0,0,0,40,4449,199.8367,69745.28125,,,,,,,,,,,,,0,,,,0,,,,,,200.0140991,,,,
,27347641.6,200.012619,74610.390625,-0.00022988989381304,2.67929466762248E-6,1,0.999253354069792,40.0298881530762,1.98445207708647,21.0699997842312,-0.00257604890826555,-0.000546694752837026,0.25,-8.54962151292877E-6,-0.000230675222722236,-8.82211535329554E-6,200.012619,200.012619,74600.4453125,74620.3359375,56.9517987967176,20.616614376818,24.807261,0,0,0,40,4449,199.8295,74610.390625,,,,,,,,,,,,,0,,,,0.00245,,,,,,200.012619,,,,
,27347740.5,200.0121994,79555.85546875,-0.000249226550105053,2.96254845291307E-6,1,0.999253354069792,40.0298881530762,1.98437919241364,21.0699997842312,-0.00279568261184353,-0.000575083004000631,0.25,-7.71097589565223E-6,-0.000250079686022235,-8.00043115341614E-6,200.0120544,200.0123444,79543.453125,79568.2578125,56.811105663256,20.6161134377591,24.807261,0,0,0,40,4449,199.82115,79555.85546875,,,,,,,,,,,,,0,,,,-0.0049,,,,,,200.0121994,,,,
,27347838.22,200.0117493,84439.515625,-0.00026406323480966,2.59435899653995E-6,1,0.999253354069792,40.0298881530762,1.98417788464874,21.0699997842312,-0.00296031163930295,-0.000617981796757751,0.25,-8.9440936562336E-6,-0.000264966454331369,-9.25284989215729E-6,200.0117493,200.0117493,84436.9140625,84442.1171875,56.6954246424098,20.6177504475213,24.807261,0,0,0,40,4449,199.8118,84439.515625,,,,,,,,,,,,,0,,,,-0.0049,,,,,,200.0117493,,,,
,27347933.595,200.0118713,89207.54296875,-0.00027720182066533,2.74231330089567E-6,1,0.999253354069792,40.0298881530762,1.98447159755575,21.0699997842312,-0.0030993659701521,-0.000698794245848554,0.25,-1.38204902848022E-5,-0.000278145437056068,-1.4159304119969E-5,200.0118713,200.0118713,89195.3046875,89219.78125,56.3960609195444,20.6127066893503,24.427608,0,0,0,40,4449,199.80035,89207.54296875,,,,,,,,,,,,,0,,,,-0.00245,,,,,,200.0118713,,,,
,27348045.83,200.003273,86169.01953125,-0.00027460708855606,3.34082037826979E-6,1,0.999253354069792,40.0298881530762,1.98446932644822,21.0699997842312,-0.00307590485667433,-0.000660271458159912,0.25,-1.08551499197377E-5,-0.000275544852995742,-1.11814018030001E-5,200.0031128,200.0034332,86163.9609375,86174.078125,56.6594697305252,20.6142040916592,24.807261,0,0,0,40,4449,199.7983,86169.01953125,,,,,,,,,,,,,0,,,,-0.00245,,,,,,200.003273,,,,
,27348140.985,200.000061,81412.94140625,-0.000255532601612763,2.94686145218932E-6,1,0.999253354069792,40.0298881530762,1.98445004729233,21.0699997842312,-0.00286656175776549,-0.000589411892969787,0.25,-7.88477338066548E-6,-0.000256407483780925,-8.18128479331319E-6,200.000061,200.000061,81405.6328125,81420.25,56.5789619930445,20.6120692079408,24.427608,0,0,0,40,4449,199.80215,81412.94140625,,,,,,,,,,,,,0,,,,-0.0049,,,,,,200.000061,,,,
,27348240.375,199.9937286,76444.00390625,-0.000236885908170465,2.51719818125725E-6,1,0.999253354069792,40.0298881530762,1.98442558332054,21.0699997842312,-0.00264710627658973,-0.000605390657572735,0.25,-1.25397623781894E-5,-0.000237691375666912,-1.28332783132771E-5,199.9937286,199.9937286,76436.0390625,76451.96875,56.6774471864675,20.6157051612404,24.427608,0,0,0,40,4449,199.80325,76444.00390625,,,,,,,,,,,,,0,,,,-0.00245,,,,,,199.9937286,,,,
,27348339.9,199.992981,71468.3046875,-0.000218076928979972,2.16537015615488E-6,1,0.999253354069792,40.0298881530762,1.98446002879073,21.0699997842312,-0.00243734574611172,-0.000555125582464742,0.25,-1.13480420597626E-5,-0.000218818554871164,-1.16180769700161E-5,199.992981,199.992981,71463.5234375,71473.0859375,56.9689946241406,20.6128451926979,24.807261,0,0,0,40,4449,199.8125,71468.3046875,,,,,,,,,,,,,0,,,,0,,,,,,199.992981,,,,
,27348437.07,199.993042,66610.19921875,-0.000199794107362962,2.33841563570348E-6,1,0.999253354069792,40.0298881530762,1.98471101899577,21.0699997842312,-0.0022336504902178,-0.000506489579457979,0.25,-1.02049462901907E-5,-0.000200473671764769,-1.04521299770334E-5,199.993042,199.993042,66604.90625,66615.4921875,56.8564401173714,20.611835072841,25.566563,0,0,0,40,4449,199.8171,66610.19921875,,,,,,,,,,,,,0,,,,0,,,,,,199.993042,,,,
,27348536.575,199.9885101,61634.572265625,-0.000179957392611665,2.19426110885896E-6,1,0.999253354069792,40.0298881530762,1.98466408715501,21.0699997842312,-0.00200901751705071,-0.000472413848837992,0.25,-1.0629511443094E-5,-0.000180567906652331,-1.08575185023294E-5,199.9885101,199.9885101,61627.015625,61642.12890625,57.0362146767945,20.6131793119803,24.807261,0,0,0,40,4449,199.83475,61634.572265625,,,,,,,,,,,,,0,,,,0,,,,,,199.9885101,,,,
,27348635.115,199.9889069,56711.5078125,-0.000164695840111199,2.53310627617316E-6,1,0.999253354069792,40.0298881530762,1.98458585574822,21.0699997842312,-0.00184235443203739,-0.00041054114017019,0.25,-7.79558399117105E-6,-0.000165256559522484,-7.99794359911956E-6,199.9889069,199.9889069,56703.73046875,56719.28515625,57.2535074051407,20.613773293956,25.186911,0,0,0,40,4449,199.84055,56711.5078125,,,,,,,,,,,,,0,,,,-0.0049,,,,,,199.9889069,,,,
,27348733.045,199.9890137,51816.892578125,-0.000145033363032766,1.84977836210773E-6,1,0.999253354069792,40.0298881530762,1.98465758248767,21.0699997842312,-0.00161797928646762,-0.000387324718043404,0.25,-9.1505250589492E-6,-0.000145524638537579,-9.33693846424734E-6,199.9890137,199.9890137,51811.7734375,51822.01171875,56.7055858131598,20.6150847277748,24.427608,0,0,0,40,4449,199.8461,51816.892578125,,,,,,,,,,,,,0,,,,0,,,,,,199.9890137,,,,
,27348832.85,199.9841995,46829.26171875,-0.000127199201746159,1.92163714414182E-6,1,0.999253354069792,40.0298881530762,1.98457163691425,21.0699997842312,-0.00141815018414458,-0.000344367969528043,0.25,-8.44043656191761E-6,-0.000127629586985685,-8.60563076498711E-6,199.983963,199.984436,46819.0625,46839.4609375,57.1456426694868,20.6162792117689,25.186911,0,0,0,40,4449,199.864,46829.26171875,,,,,,,,,,,,,0,,,,-0.00245,,,,,,199.9841995,,,,
,27348932.52,199.9898834,41849.041015625,-0.000109347487873622,1.95400576904038E-6,1,0.999253354069792,40.0298881530762,1.98462457467984,21.0699997842312,-0.001220038103869,-0.00029093631639993,0.25,-6.80268894873049E-6,-0.000109717885195731,-6.94336925301026E-6,199.9898834,199.9898834,41841.58984375,41856.4921875,56.9525804252368,20.61439892985,25.186911,0,0,0,40,4449,199.8662,41849.041015625,,,,,,,,,,,,,0,,,,0,,,,,,199.9898834,,,,
,27349032.545,199.9893188,36849.013671875,-9.05687827548947E-5,1.65541470183059E-6,1,0.999253354069792,40.0298881530762,1.98471732603776,21.0699997842312,-0.00100891468205734,-0.000250459521643395,0.25,-6.47435407318189E-6,-9.0874630541902E-5,-6.59396336231265E-6,199.9893188,199.9893188,36844.0859375,36853.94140625,57.1276652135445,20.6146749297675,24.427608,0,0,0,40,4449,199.8777,36849.013671875,,,,,,,,,,,,,0,,,,-0.0049,,,,,,199.9893188,,,,
,27349130.9,199.9901123,31932.2724609375,-7.25450985200902E-5,1.25485057740528E-6,1,0.999253354069792,40.0298881530762,1.98457034578317,21.0699997842312,-0.000809573447119455,-0.000191989736164871,0.25,-4.4221715452214E-6,-7.27908686113392E-5,-4.5154856659307E-6,199.9901123,199.9901123,31926.77734375,31937.767578125,57.0901470446214,20.6160726071424,24.807261,0,0,0,40,4449,199.8862,31932.2724609375,,,,,,,,,,,,,0,,,,0,,,,,,199.9901123,,,,
,27349227.125,199.9898682,27124.4453125,-5.51879014339026E-5,1.21532243116905E-6,1,0.999253354069792,40.0298881530762,1.98463002990002,21.0699997842312,-0.000613111352952918,-0.000162066527719793,0.25,-4.7832688326602E-6,-5.53733166924345E-5,-4.85926507533296E-6,199.9898682,199.9898682,27119.513671875,27129.376953125,57.4637654768138,20.6153747594934,25.186911,0,0,0,40,4449,199.8873,27124.4453125,,,,,,,,,,,,,0,,,,-0.00245,,,,,,199.9898682,,,,
,27349322.9,199.9885101,22336.8916015625,-3.83257031086346E-5,1.22405667491297E-6,1,0.999253354069792,40.0298881530762,1.98450465008793,21.0699997842312,-0.000427177807518657,-0.000104346808673116,0.25,-2.59513222889547E-6,-3.84552362936936E-5,-2.6454679597351E-6,199.9885101,199.9885101,22332.091796875,22341.69140625,57.2042648084291,20.619417259383,25.186911,0,0,0,40,4449,199.9028,22336.8916015625,,,,,,,,,,,,,0,,,,0,,,,,,199.9885101,,,,
,27349417.86,199.9912872,17589.4052734375,-2.2529588030288E-5,8.75834882391745E-7,1,0.999253354069792,40.0298881530762,1.98462840062601,21.0699997842312,-0.000250140515700401,-6.70366055898284E-5,0.25,-2.03024365422244E-6,-2.26051771512169E-5,-2.06161499337072E-6,199.9912872,199.9912872,17584.333984375,17594.4765625,57.4903408464676,20.6192276158074,25.186911,0,0,0,40,4449,199.9115,17589.4052734375,,,,,,,,,,,,,0,,,,-0.0049,,,,,,199.9912872,,,,
,27349515.48,199.9869537,12711.974609375,-5.69687749564409E-6,8.33113115372566E-7,1,0.999253354069792,40.0298881530762,1.98458146987949,21.0699997842312,-6.00050487954301E-5,-3.56308945490948E-5,0.25,-2.16955547092674E-6,-5.71419592842616E-6,-2.18321561986552E-6,199.9869537,199.9869537,12702.111328125,12721.837890625,57.1276652135445,20.6188126020941,24.807261,0,0,0,40,4449,199.9222,12711.974609375,,,,,,,,,,,,,0,,,,0.00245,,,,,,199.9869537,,,,
,27349610.93,199.9889221,7938.9951171875,8.48711310646562E-6,5.13207865096838E-7,1,0.999253354069792,40.0298881530762,1.9845715959529,21.0699997842312,9.87961036541361E-5,-1.04940507154561E-6,0.25,-1.56716754138504E-6,8.51811157832539E-6,-1.56337258627664E-6,199.9889221,199.9889221,7933.94873046875,7944.04150390625,57.3207274577945,20.6200193429808,24.427608,0,0,0,40,4449,199.93,7938.9951171875,,,,,,,,,,,,,0,,,,0,,,,,,199.9889221,,,,
,27349706.835,199.9919128,3146.47302246094,1.87751382978846E-5,4.04503853027467E-7,1,0.999253354069792,40.0298881530762,1.98462652794728,21.0699997842312,0.000213068831492249,2.93038296169324E-5,0.25,-6.63054696746914E-7,1.88406671640774E-5,-6.44954388819719E-7,199.9919128,199.9919128,3141.65454101562,3151.29150390625,57.1972301517561,20.6209504641933,25.186911,0,0,0,40,4449,199.9386,3146.47302246094,,,,,,,,,,,,,0,,,,-0.0049,,,,,,199.9919128,,,,
,27349769.955,199.9945068,-0.403429985046387,2.07863701107017E-5,3.24115376618422E-7,1,0.999253354069792,40.0298881530762,1.98481563211632,21.0699997842312,0.000236266856104267,3.04180397034716E-5,0.25,-9.13863906750119E-7,2.08591105138064E-5,-8.94430646505927E-7,199.9945068,199.9945068,-0.42626565694809,-0.380594313144684,56.8087607776983,20.6174881564705,24.807261,0,0,0,40,4417,199.94,-0.403429985046387,,,,,,,,,,,,,0,,,,-0.00245,,,,,,199.9945068,,,,