File: data/monolayers/nanoparticles/Ac_CoFe_C/vsm/data_disorderedWafer/DD226_2_HYST_10K_REPEAT.DAT
[Header]
; VSM Data File (default extension .dat)
; Copyright (c) 2003-2013, Quantum Design, Inc. All rights reserved.
TITLE,
FILEOPENTIME,27429873.94,11/14/2018,7:24 pm
BYAPP,VSM,2.0,2.0
INFO,PPMS VSM Option Release 1.4.10 Build 1,APPNAME
INFO,Quantum Design Linear Motor Servo Controller,MOTOR_MODULE_NAME
INFO,3101-100 M1,MOTOR_HW_VERSION
INFO,MMC1014,MOTOR_SERIAL_NUMBER
INFO,SRV No X-over 01.03.11,MOTOR_SOFTWARE_VERSION
INFO,Quantum Design VSM Detection Module,VSM_MODULE_NAME
INFO,3101-150 F0,VSM_HW_VERSION
INFO,VSM707,VSM_SERIAL_NUMBER
INFO,VSM No X-over 01.02.05 May 20 2008 13:51:47,VSM_SOFTWARE_VERSION
INFO,704,PREAMP_SERIAL_NUMBER
INFO,822,COIL_SERIAL_NUMBER
INFO,0,MOMENT_UNITS
INFO,CoFe2O4 AH11,SAMPLE_MATERIAL
INFO,Quick Dry Monolayer Conc,SAMPLE_COMMENT
INFO,27.96,SAMPLE_MASS
INFO,,SAMPLE_VOLUME
INFO,,SAMPLE_MOLECULAR_WEIGHT
INFO,,SAMPLE_SIZE
INFO,,SAMPLE_SHAPE
DATATYPE,COMMENT,1
DATATYPE,TIME,2
STARTUPAXIS,X,2
STARTUPAXIS,Y1,5
[Data]
Comment,Time Stamp (sec),Temperature (K),Magnetic Field (Oe),Moment (emu),M. Std. Err. (emu),Transport Action,Averaging Time (sec),Frequency (Hz),Peak Amplitude (mm),Center Position (mm),Coil Signal' (mV),Coil Signal" (mV),Range (mV),M. Quad. Signal (emu),M. Raw' (emu),M. Raw" (emu),Min. Temperature (K),Max. Temperature (K),Min. Field (Oe),Max. Field (Oe),Mass (grams),Motor Lag (deg),Pressure (Torr),VSM Status (code),Motor Status (code),Measure Status (code),Measure Count,PPMS Status (code),System Temp. (K),System Field (Oe),Sample Position (deg),Bridge 1 Resistance (ohms),Bridge 1 Excitation (에),Bridge 2 Resistance (ohms),Bridge 2 Excitation (에),Bridge 3 Resistance (ohms),Bridge 3 Excitation (에),Bridge 4 Resistance (ohms),Bridge 4 Excitation (에),Signal 1 Vin (V),Signal 2 Vin (V),Digital Inputs (code),Drive 1 Iout (mA),Drive 1 Ipower (W),Drive 2 Iout (mA),Drive 2 Ipower (W),Pressure (),Map 20 (),Map 21 (),Map 22 (),Map 23 (),Map 24 (),Map 25 (),Map 26 (),Map 27 (),Map 28 (),Map 29 ()
,27430009.615,10.0003872,0.0456713177263737,1.03128052522794E-5,2.45752520794096E-7,1,0.999253354069792,40.0298881530762,1.99811697076859,16.7999994009733,0.000118747140804204,4.70593973963329E-6,0.25,-1.4126399911852E-6,1.02603713269906E-5,-1.35481795590689E-6,10.0003872,10.0003872,0.0456713177263737,0.0456713177263737,56.4241995462367,20.4772840016346,11.519473,0,0,0,40,4417,9.98945,0.0456713177263737,,,,,,,,,,,,,0,,,,0.00245,,,,,,10.0003872,,,,
,27430089.025,9.999465,3067.39721679687,2.55825109101217E-6,1.52327116877512E-7,1,0.999253354069792,40.0298881530762,1.99803812994346,16.7999994009733,2.92372794457508E-5,2.42729920956081E-6,0.25,-2.38823913548392E-7,2.54513772017701E-6,-2.24712934723388E-7,9.999465,9.999465,3059.80053710937,3074.99389648438,56.3757385780444,20.4853188907299,11.519473,0,0,0,40,4449,9.9982,3067.39721679687,,,,,,,,,,,,,0,,,,0.00245,,,,,,9.999465,,,,
,27430149.36,9.9985962,6078.84765625,-5.39053724638936E-6,2.32437229493132E-7,1,0.999253354069792,40.0298881530762,1.99755776283116,16.7999994009733,-6.0803928608381E-5,-9.62058957217643E-6,0.25,1.03535745042203E-7,-5.36200389445442E-6,7.49183223832933E-8,9.9985962,9.9985962,6068.9453125,6088.75,56.607882248256,20.4833961512648,11.519473,0,0,0,40,4449,9.99685,6078.84765625,,,,,,,,,,,,,0,,,,0.00245,,,,,,9.9985962,,,,
,27430211.79,10.0009837,9200.1298828125,-1.4583307342375E-5,2.48978220320829E-7,1,0.999253354069792,40.0298881530762,1.99738281577376,16.7999994009733,-0.000163900938885424,-2.95168415369024E-5,0.25,-2.65886153495107E-8,-1.4507935274091E-5,-1.05709431362846E-7,10.0006952,10.0012722,9192.4482421875,9207.8115234375,56.9205336559483,20.4865740229895,11.519473,0,0,0,40,4449,9.9969,9200.1298828125,,,,,,,,,,,,,0,,,,0,,,,,,10.0009837,,,,
,27430276.615,10.0014076,12440.8481445313,-2.47475304946581E-5,1.89781996426058E-7,1,0.999253354069792,40.0298881530762,1.99721969613307,16.7999994009733,-0.000277994885632422,-5.11890824447826E-5,0.25,-1.36169994162456E-7,-2.46257190636093E-5,-2.75906335476954E-7,10.0014076,10.0014076,12436.1884765625,12445.5078125,56.7227816405829,20.4905329569501,11.519473,0,0,0,40,4449,9.9935,12440.8481445313,,,,,,,,,,,,,0,,,,-0.0049,,,,,,10.0014076,,,,
,27430341.78,10.00319,15696.5615234375,-3.53501517381527E-5,3.34306415634807E-7,1,0.999253354069792,40.0298881530762,1.99728337592592,16.7999994009733,-0.000397049078361218,-7.41223676432278E-5,0.25,-2.73316306967276E-7,-3.51858479401944E-5,-4.80853489244322E-7,10.00319,10.00319,15689.119140625,15704.00390625,56.7384142109675,20.4849675607189,11.519473,0,0,0,40,4449,9.994,15696.5615234375,,,,,,,,,,,,,0,,,,0.00245,,,,,,10.00319,,,,
,27430405.425,10.0021162,18877.505859375,-4.60222153979043E-5,3.16794333716112E-7,1,0.999253354069792,40.0298881530762,1.99712433831363,16.7999994009733,-0.00051798881190307,-9.11724154544965E-5,0.25,1.29583237641757E-7,-4.58249201179135E-5,-1.5279380559748E-7,10.0021162,10.0021162,18872.90234375,18882.109375,56.8040710065829,20.4884683745585,11.899124,0,0,0,40,4449,9.9926,18877.505859375,,,,,,,,,,,,,0,,,,0.0049,,,,,,10.0021162,,,,
,27430467.82,10.0016289,21998.0205078125,-5.28345248982623E-5,2.90144036150564E-7,1,0.999253354069792,40.0298881530762,1.99703152977832,16.7999994009733,-0.000594192642431889,-0.000108194701600048,0.25,-1.5171336606295E-7,-5.26222613957658E-5,-4.85199226258564E-7,10.0016289,10.0016289,21990.458984375,22005.58203125,56.607882248256,20.4857391841075,11.519473,0,0,0,40,4449,9.99185,21998.0205078125,,,,,,,,,,,,,0,,,,0.00245,,,,,,10.0016289,,,,
,27430531.74,10.0004473,25191.435546875,-5.81312346833391E-5,3.6528816308442E-7,1,0.999253354069792,40.0298881530762,1.99731031320847,16.7999994009733,-0.000654840643685314,-0.000114742284495547,0.25,2.30725486531662E-7,-5.79189731420099E-5,-1.48695830305718E-7,10.0004473,10.0004473,25183.91015625,25198.9609375,56.851750346256,20.4882181096909,11.519473,0,0,0,40,4449,9.9909,25191.435546875,,,,,,,,,,,,,0,,,,0.0049,,,,,,10.0004473,,,,
,27430596.065,10.0004463,28405.123046875,-6.32171540248606E-5,5.01972171988472E-7,1,0.999253354069792,40.0298881530762,1.99708104917854,16.7999994009733,-0.000712103335841792,-0.00012586781743739,0.25,1.67725648751215E-7,-6.30067907709914E-5,-2.55464840869287E-7,10.0004463,10.0004463,28397.744140625,28412.501953125,56.7540467813522,20.4870010437874,11.139823,0,0,0,40,4449,9.99,28405.123046875,,,,,,,,,,,,,0,,,,-0.0049,,,,,,10.0004463,,,,
,27430658.73,10.0011835,31536.271484375,-7.03609905048853E-5,4.85332785622789E-7,1,0.999253354069792,40.0298881530762,1.99704617885089,16.7999994009733,-0.00079292738502634,-0.000139557483241395,0.25,2.48509944022053E-7,-7.0150421888405E-5,-2.33257762251331E-7,10.0011835,10.0011835,31530.974609375,31541.568359375,57.1167224142753,20.4869129735257,11.899124,0,0,0,40,4449,9.9906,31536.271484375,,,,,,,,,,,,,0,,,,0,,,,,,10.0011835,,,,
,27430723.82,10.0008717,34792.2890625,-7.93038567880923E-5,4.81835432439557E-7,1,0.999253354069792,40.0298881530762,1.99702513835486,16.7999994009733,-0.000893839931229505,-0.000158291916472479,0.25,2.07146747110383E-7,-7.90933931913425E-5,-3.4653701023197E-7,10.0008717,10.0008717,34789.84765625,34794.73046875,57.0205821064099,20.4870855760496,11.519473,0,0,0,40,4449,9.9903,34792.2890625,,,,,,,,,,,,,0,,,,0,,,,,,10.0008717,,,,
,27430788.775,10.0006032,38037.837890625,-8.88551873311457E-5,5.33673859139888E-7,1,0.999253354069792,40.0298881530762,1.9973373233447,16.7999994009733,-0.00100166467312112,-0.000179254799477763,0.25,8.18576471872536E-8,-8.86489563920157E-5,-5.48648876948848E-7,10.000535,10.0006714,38032.94921875,38042.7265625,56.8611298884868,20.4849570730717,11.139823,0,0,0,40,4449,9.99105,38037.837890625,,,,,,,,,,,,,0,,,,-0.0049,,,,,,10.0006032,,,,
,27430849.89,9.9991655,41093.94140625,-9.94398228973171E-5,4.76164347935649E-7,1,0.999253354069792,40.0298881530762,1.99715194844163,16.7999994009733,-0.00112408949842581,-0.000184882932757837,0.25,1.49989961005043E-6,-9.92513346231527E-5,7.82060191825362E-7,9.9991655,9.9991655,41086.48046875,41101.40234375,56.9815006804483,20.491105932468,11.519473,0,0,0,40,4449,9.991,41093.94140625,,,,,,,,,,,,,0,,,,0,,,,,,9.9991655,,,,
,27430908.29,9.9986811,44009.43359375,-0.00010798416351194,4.49210414448078E-7,1,0.999253354069792,40.0298881530762,1.99691314008239,16.7999994009733,-0.0012191876609026,-0.000210395155094906,0.25,7.86447300530038E-7,-0.000107806578303664,7.11685247258082E-10,9.9986811,9.9986811,43999.453125,44019.4140625,57.2011382943522,20.4864788193193,11.519473,0,0,0,40,4449,9.99075,44009.43359375,,,,,,,,,,,,,0,,,,-0.00245,,,,,,9.9986811,,,,
,27430970.95,9.99858425,47143.65625,-0.000118481862964136,3.57009928475907E-7,1,0.999253354069792,40.0298881530762,1.99697070259941,16.7999994009733,-0.00133769478360478,-0.000233655805465639,0.25,6.28762795326646E-7,-0.00011832394550003,-2.40490493248776E-7,9.9985838,9.9985847,47138.5546875,47148.7578125,57.1339182416984,20.486599317278,11.139823,0,0,0,40,4449,9.9928,47143.65625,,,,,,,,,,,,,0,,,,-0.0049,,,,,,9.99858425,,,,
,27431033.295,9.9973946,50259.23046875,-0.000129480663979169,5.15235458898621E-7,1,0.999253354069792,40.0298881530762,1.99691572949087,16.7999994009733,-0.00146021426261504,-0.000267015526668738,0.25,-3.34379205750097E-7,-0.000129341850531356,-1.28942967077897E-6,9.9973946,9.9973946,50246.76171875,50271.69921875,57.0768593597945,20.4848207665084,11.519473,0,0,0,40,4449,9.9943,50259.23046875,,,,,,,,,,,,,0,,,,0,,,,,,9.9973946,,,,
,27431094.775,9.9963684,53332.783203125,-0.000139611318396135,5.98665399473445E-7,1,0.999253354069792,40.0298881530762,1.99670501017216,16.7999994009733,-0.00157814995689965,-0.000269324817034415,0.25,1.29589349176869E-6,-0.000139516971233006,2.59962046820544E-7,9.9963684,9.9963684,53330.3359375,53335.23046875,56.8986480574099,20.4871874232136,11.139823,0,0,0,40,4449,9.9975,53332.783203125,,,,,,,,,,,,,0,,,,0.0049,,,,,,9.9963684,,,,
,27431158.7,9.9963598,56526.142578125,-0.000151339293994084,5.94295980231578E-7,1,0.999253354069792,40.0298881530762,1.99664089979705,16.7999994009733,-0.00170721517386039,-0.000314172835416237,0.25,-5.53726903723101E-7,-0.000151269894857229,-1.67868978958719E-6,9.9963598,9.9963598,56518.77734375,56533.5078125,56.7384142109675,20.491997771605,11.139823,0,0,0,40,4449,9.99905,56526.142578125,,,,,,,,,,,,,0,,,,0,,,,,,9.9963598,,,,
,27431222.64,9.9957829,59722.251953125,-0.000163421520517578,4.3591906063326E-7,1,0.999253354069792,40.0298881530762,1.99665773861007,16.7999994009733,-0.00184511440683471,-0.000333674675218574,0.25,-9.33067475361247E-8,-0.000163400234712244,-1.30971275591234E-6,9.9957829,9.9957829,59712.2734375,59732.23046875,56.973684395256,20.4878768418779,11.899124,0,0,0,40,4449,10.0006,59722.251953125,,,,,,,,,,,,,0,,,,0,,,,,,9.9957829,,,,
,27431290.955,9.9958248,63138.51953125,-0.000175475103487167,6.24179663167133E-7,1,0.999253354069792,40.0298881530762,1.9965522543371,16.7999994009733,-0.00197997929234224,-0.000368111449597072,0.25,-9.62877938724989E-7,-0.000175501401660511,-2.26841871597457E-6,9.9958248,9.9958248,63131.140625,63145.8984375,56.7071490701983,20.4895100636578,11.139823,0,0,0,40,4449,10.0048,63138.51953125,,,,,,,,,,,,,0,,,,0,,,,,,9.9958248,,,,
,27431358.18,9.9953346,66496.6484375,-0.000187960523486742,5.5859803226752E-7,1,0.999253354069792,40.0298881530762,1.99660586862138,16.7999994009733,-0.00212334658491555,-0.000384471774526593,0.25,-1.53387765732574E-7,-0.000188051800171419,-1.54855201005786E-6,9.9953346,9.9953346,66489.3515625,66503.9453125,56.6375841319868,20.4875875935229,11.899124,0,0,0,40,4449,10.0074,66496.6484375,,,,,,,,,,,,,0,,,,0,,,,,,9.9953346,,,,
,27431423.575,9.9960165,69767.72265625,-0.000198940526492214,5.00678283893699E-7,1,0.999253354069792,40.0298881530762,1.9965154634763,16.7999994009733,-0.00224935537284489,-0.000399080974080567,0.25,5.35144652293162E-7,-0.000199098594681445,-9.35666070382432E-7,9.9960165,9.9960165,69762.890625,69772.5546875,56.9408559974483,20.4894699983447,11.519473,0,0,0,40,4449,10.0098,69767.72265625,,,,,,,,,,,,,0,,,,0.00245,,,,,,9.9960165,,,,
,27431488.04,9.9951334,72988.5703125,-0.000210776092340913,4.35481112279733E-7,1,0.999253354069792,40.0298881530762,1.99635747988021,16.7999994009733,-0.00238451492260754,-0.000418020159615976,0.25,9.9118664393773E-7,-0.000211003279006627,-5.59003113797709E-7,9.9951334,9.9951334,72980.9765625,72996.1640625,56.9197520274291,20.4926618120203,11.139823,0,0,0,40,4449,10.01235,72988.5703125,,,,,,,,,,,,,0,,,,0.00245,,,,,,9.9951334,,,,
,27431554.665,9.9954014,76320.0390625,-0.000223752616651435,5.77312005875291E-7,1,0.999253354069792,40.0298881530762,1.99646599206828,16.7999994009733,-0.00252953690043792,-0.000458262616748072,0.25,-2.28886167056004E-7,-0.00022404416250806,-1.86573278920421E-6,9.9954014,9.9954014,76315.078125,76325,56.780622151006,20.4871755757834,11.899124,0,0,0,40,4449,10.0158,76320.0390625,,,,,,,,,,,,,0,,,,0,,,,,,9.9954014,,,,
,27431620.095,9.9956274,79588.3671875,-0.000235570401700609,4.97967378190058E-7,1,0.999253354069792,40.0298881530762,1.99644556277789,16.7999994009733,-0.00266272963736015,-0.000488417021443502,0.25,-7.69511222732006E-7,-0.000235932805677053,-2.48142530270708E-6,9.9956274,9.9956274,79583.3828125,79593.3515625,57.0815491309099,20.4875808954169,11.519473,0,0,0,40,4449,10.0194,79588.3671875,,,,,,,,,,,,,0,,,,0,,,,,,9.9956274,,,,
,27431684.915,9.9954157,82829.9140625,-0.000246694017090601,5.54895295974666E-7,1,0.999253354069792,40.0298881530762,1.99652481733718,16.7999994009733,-0.0027884587902643,-0.000515934691829104,0.25,-1.2018180259898E-6,-0.000247129791539612,-2.98115163032134E-6,9.9954157,9.9954157,82817.1015625,82842.7265625,56.9846271945253,20.4869629891469,11.519473,0,0,0,40,4449,10.0207,82829.9140625,,,,,,,,,,,,,0,,,,0.00245,,,,,,9.9954157,,,,
,27431749.695,9.9951029,86068.82421875,-0.000259197660372348,6.22880629502772E-7,1,0.999253354069792,40.0298881530762,1.99654219841572,16.7999994009733,-0.00293071812540403,-0.00054092111664651,0.25,-1.16541349894206E-6,-0.000259715712961468,-3.01855214600057E-6,9.9951029,9.9951029,86066.3984375,86071.25,56.8681645451599,20.4850821150044,11.519473,0,0,0,40,4449,10.0248,86068.82421875,,,,,,,,,,,,,0,,,,0,,,,,,9.9951029,,,,
,27431811.145,9.9950829,89137.4609375,-0.000270578425188758,5.66844530301231E-7,1,0.999253354069792,40.0298881530762,1.99647902106035,16.7999994009733,-0.00305907270366073,-0.000569603210554982,0.25,-1.66129945026431E-6,-0.000271172472057921,-3.57956804261257E-6,9.9950829,9.9950829,89129.671875,89145.25,56.933039712256,20.4857521608525,11.899124,0,0,0,40,4449,10.02705,89137.4609375,,,,,,,,,,,,,0,,,,0,,,,,,9.9950829,,,,
,27431890.56,9.9962177,87913.11328125,-0.000267101520044834,7.67642207860813E-7,1,0.999253354069792,40.0298881530762,1.996536176992,16.7999994009733,-0.00302105040878716,-0.000554187109436496,0.25,-9.20086459581289E-7,-0.000267671100480446,-2.81903208571552E-6,9.9962177,9.9962177,87908.296875,87917.9296875,57.0706063316407,20.4874054241724,10.760172,0,0,0,40,4449,10.02855,87913.11328125,,,,,,,,,,,,,0,,,,0,,,,,,9.9962177,,,,
,27431951.47,9.9987087,84869.2734375,-0.000254912583072136,5.19611017049386E-7,1,0.999253354069792,40.0298881530762,1.99665158704769,16.7999994009733,-0.00288122404380872,-0.000537259039874073,0.25,-1.60797657424956E-6,-0.000255397386277406,-3.43743368983233E-6,9.9987087,9.9987087,84859.3671875,84879.1796875,57.1034347294484,20.4860164794174,11.519473,0,0,0,40,4449,10.0286,84869.2734375,,,,,,,,,,,,,0,,,,0,,,,,,9.9987087,,,,
,27432016.055,10.0004654,81640.05859375,-0.000242799889999374,5.06681754206819E-7,1,0.999253354069792,40.0298881530762,1.99677781804981,16.7999994009733,-0.00274443477226451,-0.000508374479003459,0.25,-1.22743355922225E-6,-0.000243207381994134,-2.98399496722511E-6,10.0004654,10.0004654,81635.078125,81645.0390625,56.7728058658137,20.488429823711,11.519473,0,0,0,40,4449,10.0269,81640.05859375,,,,,,,,,,,,,0,,,,0,,,,,,10.0004654,,,,
,27432080.7,10.0021849,78405.6484375,-0.000232289316984279,5.77580445768376E-7,1,0.999253354069792,40.0298881530762,1.99673691304944,16.7999994009733,-0.00262485199977035,-0.000486751084372293,0.25,-1.20614091532972E-6,-0.00023262252140753,-2.89936448734072E-6,10.002162,10.0022078,78400.3671875,78410.9296875,56.9189703989099,20.4852003351833,11.139823,0,0,0,40,4449,10.02405,78405.6484375,,,,,,,,,,,,,0,,,,0.0049,,,,,,10.0021849,,,,
,27432143.035,10.0029621,75289.01171875,-0.000219119633408027,4.96380679380066E-7,1,0.999253354069792,40.0298881530762,1.99672905721717,16.7999994009733,-0.00247465566185863,-0.000463311953023699,0.25,-1.50466995337581E-6,-0.000219377883661336,-3.11245447203242E-6,10.0029621,10.0029621,75281.3828125,75296.640625,57.0065127930637,20.4865224510438,11.519473,0,0,0,40,4449,10.02345,75289.01171875,,,,,,,,,,,,,0,,,,-0.00245,,,,,,10.0029621,,,,
,27432210.52,10.0029879,71917.9609375,-0.000205924736230264,5.25240817326152E-7,1,0.999253354069792,40.0298881530762,1.99680964879865,16.7999994009733,-0.0023275611839104,-0.000421599559505045,0.25,-1.9193394110677E-7,-0.000206119994146464,-1.71027772423865E-6,10.0029879,10.0029879,71913.1484375,71922.7734375,56.8580033744099,20.4894962208863,11.139823,0,0,0,40,4449,10.02075,71917.9609375,,,,,,,,,,,,,0,,,,-0.00245,,,,,,10.0029879,,,,
,27432275.6,10.0033493,68664.34765625,-0.000194292982394512,7.20821558258697E-7,1,0.999253354069792,40.0298881530762,1.99655173021371,16.7999994009733,-0.00219529805865193,-0.000397165611988125,0.25,-1.33428377521688E-7,-0.0001944241780532,-1.57235457104336E-6,10.0033493,10.0033493,68659.453125,68669.2421875,56.8642564025637,20.4883360815978,10.760172,0,0,0,40,4449,10.0186,68664.34765625,,,,,,,,,,,,,0,,,,-0.0049,,,,,,10.0033493,,,,
,27432340.435,10.003686,65423.087890625,-0.000183485179534234,4.59859878187727E-7,1,0.999253354069792,40.0298881530762,1.9966651539023,16.7999994009733,-0.0020720498788817,-0.000378630362094632,0.25,-4.43843157362801E-7,-0.000183554648298589,-1.80710399660305E-6,10.003686,10.003686,65420.5546875,65425.62109375,56.8470605751406,20.4904595102722,11.139823,0,0,0,40,4449,10.0162,65423.087890625,,,,,,,,,,,,,0,,,,0.00245,,,,,,10.003686,,,,
,27432406.82,10.0037889,62106.2421875,-0.000171495458902849,3.55012502661665E-7,1,0.999253354069792,40.0298881530762,1.99680398315357,16.7999994009733,-0.00193638248294545,-0.000352793874823685,0.25,-3.22623653862238E-7,-0.000171509534745103,-1.59887733865666E-6,10.0037889,10.0037889,62101.49609375,62110.98828125,56.6328943608714,20.4855037754545,11.519473,0,0,0,40,4449,10.0137,62106.2421875,,,,,,,,,,,,,0,,,,0,,,,,,10.0037889,,,,
,27432471.99,10.0036516,58845.96484375,-0.000160518101208829,3.69563333604674E-7,1,0.999253354069792,40.0298881530762,1.99673192387935,16.7999994009733,-0.00181078684418251,-0.000335833245219731,0.25,-8.09302646272567E-7,-0.000160478548038231,-2.00376969690092E-6,10.0036516,10.0036516,58838.47265625,58853.45703125,57.0643533034868,20.487700413161,11.139823,0,0,0,40,4449,10.0124,58845.96484375,,,,,,,,,,,,,0,,,,-0.0049,,,,,,10.0036516,,,,
,27432537.97,10.00381135,55549.783203125,-0.000148779979880832,4.22583445316016E-7,1,0.999253354069792,40.0298881530762,1.99685617926666,16.7999994009733,-0.00167838627815697,-0.000308702729517932,0.25,-5.30898148529403E-7,-0.000148697730363673,-1.63601924540162E-6,10.0036821,10.0039406,55544.82421875,55554.7421875,56.8736359447945,20.4907336092828,11.519473,0,0,0,40,4449,10.01005,55549.783203125,,,,,,,,,,,,,0,,,,0,,,,,,10.00381135,,,,
,27432602.985,10.0034924,52301.38671875,-0.000136204728185057,3.59152940478377E-7,1,0.999253354069792,40.0298881530762,1.99700695977524,16.7999994009733,-0.0015346814551456,-0.000290643681563711,0.25,-1.20739275346505E-6,-0.00013608037170101,-2.21471467696598E-6,10.0034924,10.0034924,52296.22265625,52306.55078125,56.7868751791599,20.4878883623374,11.139823,0,0,0,40,4449,10.0077,52301.38671875,,,,,,,,,,,,,0,,,,0.00245,,,,,,10.0034924,,,,
,27432667.62,10.0033369,49070.373046875,-0.000124810587468112,4.0895824007176E-7,1,0.999253354069792,40.0298881530762,1.99677437386939,16.7999994009733,-0.00140627249419913,-0.000262939137075374,0.25,-8.21020038447314E-7,-0.000124658018220341,-1.73886672893576E-6,10.0033369,10.0033369,49062.7421875,49078.00390625,56.6704125297944,20.4918591269945,11.519473,0,0,0,40,4449,10.00645,49070.373046875,,,,,,,,,,,,,0,,,,-0.0049,,,,,,10.0033369,,,,
,27432734.125,10.0028439,45746.982421875,-0.00011292524826487,3.71473177305476E-7,1,0.999253354069792,40.0298881530762,1.99685173142248,16.7999994009733,-0.00127385926993336,-0.000227328621802831,0.25,1.8169972698344E-7,-0.000112755343415401,-6.43178758760623E-7,10.0028439,10.0028439,45739.33984375,45754.625,56.9056827140829,20.4950134668361,10.760172,0,0,0,40,4449,10.00405,45746.982421875,,,,,,,,,,,,,0,,,,0.0049,,,,,,10.0028439,,,,
,27432801.575,10.0027485,42376.046875,-0.000101134413388762,4.20720655633967E-7,1,0.999253354069792,40.0298881530762,1.99688118930753,16.7999994009733,-0.00114027937757726,-0.000204552628382746,0.25,6.37321982452703E-8,-0.00010094587173406,-6.66937388265224E-7,10.0027294,10.0027676,42370.984375,42381.109375,56.8939582862945,20.4916083501227,11.519473,0,0,0,40,4449,10.0014,42376.046875,,,,,,,,,,,,,0,,,,-0.0049,,,,,,10.0027485,,,,
,27432865.75,10.0024748,39167.04296875,-8.98350930820225E-5,3.23175362896139E-7,1,0.999253354069792,40.0298881530762,1.99669856828255,16.7999994009733,-0.00101145727655014,-0.000187125376390665,0.25,-4.3996796807117E-7,-8.96336208244154E-5,-1.07958454492883E-6,10.0024748,10.0024748,39167.04296875,39167.04296875,57.1432977839291,20.4894584873659,11.519473,0,0,0,40,4449,10.0003,39167.04296875,,,,,,,,,,,,,0,,,,-0.0049,,,,,,10.0024748,,,,
,27432930.535,10.0026512,35929.40625,-7.79338621118629E-5,3.63149635608456E-7,1,0.999253354069792,40.0298881530762,1.99672344868303,16.7999994009733,-0.000877346735202537,-0.000161292030487257,0.25,-3.02435792803455E-7,-7.77329003944239E-5,-8.4865397059335E-7,10.0026512,10.0026512,35924.44140625,35934.37109375,57.1808159528522,20.4921897910435,11.139823,0,0,0,40,4449,9.9994,35929.40625,,,,,,,,,,,,,0,,,,-0.0049,,,,,,10.0026512,,,,
,27432993.49,10.0026321,32781.119140625,-6.70464312631647E-5,3.96454376395653E-7,1,0.999253354069792,40.0298881530762,1.99667281409119,16.7999994009733,-0.000756139300661475,-0.000129639443682695,0.25,5.36827010793479E-7,-6.68566823057781E-5,7.3220786917766E-8,10.0026321,10.0026321,32776.1484375,32786.08984375,56.9564885678329,20.4931290479939,11.139823,0,0,0,40,4449,9.9977,32781.119140625,,,,,,,,,,,,,0,,,,-0.00245,,,,,,10.0026321,,,,
,27433056.805,10.0018864,29620.2138671875,-5.61991126486012E-5,3.76851538409094E-7,1,0.999253354069792,40.0298881530762,1.99702241252773,16.7999994009733,-0.000632352052484094,-0.000116141540651341,0.25,-2.23693743803712E-7,-5.60167346994958E-5,-6.0209649804024E-7,10.0018864,10.0018864,29617.849609375,29622.578125,57.0627900464484,20.4949758506897,11.139823,0,0,0,40,4449,9.99745,29620.2138671875,,,,,,,,,,,,,0,,,,-0.00245,,,,,,10.0018864,,,,
,27433119.685,10.0005798,26476.6435546875,-4.52650912241066E-5,2.99389691779918E-7,1,0.999253354069792,40.0298881530762,1.99674839595262,16.7999994009733,-0.000509947533015201,-8.87138318909254E-5,0.25,2.37992241678331E-7,-4.5106178419753E-5,-6.08630060527478E-8,10.0005798,10.0005798,26469.00390625,26484.283203125,57.0917103016599,20.4951212074149,11.139823,0,0,0,40,4449,9.99645,26476.6435546875,,,,,,,,,,,,,0,,,,0,,,,,,10.0005798,,,,
,27433182.605,10.0002699,23333.8564453125,-3.45850018905775E-5,2.7499140809607E-7,1,0.999253354069792,40.0298881530762,1.99675825303742,16.7999994009733,-0.00038933151303685,-6.87204021691375E-5,0.25,9.03880074710641E-8,-3.44518848132429E-5,-1.31458962758705E-7,10.0002699,10.0002699,23331.318359375,23336.39453125,56.8791073444291,20.4955066503896,11.139823,0,0,0,40,4449,9.9966,23333.8564453125,,,,,,,,,,,,,0,,,,0,,,,,,10.0002699,,,,
,27433245.78,10.00050025,20172.5087890625,-2.39038418260176E-5,2.99239015603885E-7,1,0.999253354069792,40.0298881530762,1.99699546177964,16.7999994009733,-0.000269493475641422,-4.49348389890935E-5,0.25,2.84693941060666E-7,-2.38057142043532E-5,1.35104772931016E-7,10.0004807,10.0005198,20167.462890625,20177.5546875,56.9134989992753,20.4979084848246,11.139823,0,0,0,40,4449,9.9963,20172.5087890625,,,,,,,,,,,,,0,,,,0.00245,,,,,,10.00050025,,,,
,27433309.415,10.000226,16994.7890625,-1.32939791010892E-5,2.81915090806835E-7,1,0.999253354069792,40.0298881530762,1.99700091978105,16.7999994009733,-0.000149905839106525,-2.45660682081349E-5,0.25,1.92564410916743E-7,-1.32355459612727E-5,1.1198339681228E-7,10.000226,10.000226,16989.6484375,16999.9296875,56.9197520274291,20.4964715413174,10.760172,0,0,0,40,4449,9.996,16994.7890625,,,,,,,,,,,,,0,,,,-0.0049,,,,,,10.000226,,,,
,27433371.895,9.9999943,13871.5922851562,-2.5083533024418E-6,2.98859086896859E-7,1,0.999253354069792,40.0298881530762,1.99676332617767,16.7999994009733,-2.80506630531969E-5,-5.88040778943513E-6,0.25,-7.5134667142142E-8,-2.49596367269434E-6,-8.92671518539766E-8,9.9999943,9.9999943,13866.4912109375,13876.693359375,56.8978664288906,20.4983773474661,11.139823,0,0,0,40,4449,9.9964,13871.5922851562,,,,,,,,,,,,,0,,,,0,,,,,,9.9999943,,,,
,27433434.37,9.9985666,10747.927734375,7.86360876655157E-6,2.76080027364806E-7,1,0.999253354069792,40.0298881530762,1.996804870692,16.7999994009733,8.80389249709434E-5,1.77443280895331E-5,0.25,1.76297824205777E-7,7.82304961952319E-6,2.19047405058869E-7,9.9984722,9.998661,10738.169921875,10757.685546875,56.9932251082368,20.5001592878999,11.519473,0,0,0,40,4449,9.9978,10747.927734375,,,,,,,,,,,,,0,,,,0,,,,,,9.9985666,,,,
,27433497.7,9.9984264,7584.240234375,1.78040592200596E-5,2.01739320116672E-7,1,0.999253354069792,40.0298881530762,1.99678418843176,16.7999994009733,0.000200381713251519,3.39694801548303E-5,0.25,-1.4795028958336E-7,1.77107845471181E-5,-5.2532304639799E-8,9.9984264,9.9984264,7579.0732421875,7589.4072265625,57.2230238928907,20.5003008334741,11.139823,0,0,0,40,4449,9.99815,7584.240234375,,,,,,,,,,,,,0,,,,-0.0049,,,,,,9.9984264,,,,
,27433559.355,9.9987621,4500.83764648438,2.64050195140045E-5,2.16364613638151E-7,1,0.999253354069792,40.0298881530762,1.99697766762007,16.7999994009733,0.00029685243525602,5.20207778007144E-5,0.25,-6.69149774516294E-8,2.62600954454017E-5,6.79148837745354E-8,9.9987621,9.9987621,4495.90283203125,4505.7724609375,57.034651419756,20.5004691611943,11.139823,0,0,0,40,4449,9.99905,4500.83764648438,,,,,,,,,,,,,0,,,,-0.0049,,,,,,9.9987621,,,,
,27433621.565,9.9999733,1389.01336669922,3.35086350243454E-5,1.80360011254226E-7,1,0.999253354069792,40.0298881530762,1.996912355671,16.7999994009733,0.000376153706529453,6.86876944420492E-5,0.25,1.61047168668223E-7,3.33173148941719E-5,3.23919574117519E-7,9.9999733,9.9999733,1381.548828125,1396.47790527344,57.0807675023906,20.5028112451926,11.519473,0,0,0,40,4449,9.9987,1389.01336669922,,,,,,,,,,,,,0,,,,0.00245,,,,,,9.9999733,,,,
,27433684.665,9.999815,-1761.45654296875,3.88774556471317E-5,1.9589988817812E-7,1,0.999253354069792,40.0298881530762,1.99704965463583,16.7999994009733,0.000437309272574189,7.49138014170738E-5,0.25,-2.39959756874909E-7,3.86583282050787E-5,-4.77059227342681E-8,9.999815,9.999815,-1768.99865722656,-1753.91442871094,57.1003082153714,20.498453666183,11.139823,0,0,0,40,4449,9.9981,-1761.45654296875,,,,,,,,,,,,,0,,,,-0.0049,,,,,,9.999815,,,,
,27433747.77,9.9997997,-4912.37719726562,4.59437129336023E-5,2.10572414376812E-7,1,0.999253354069792,40.0298881530762,1.99686626875153,16.7999994009733,0.00051608611898459,9.28308016474222E-5,0.25,8.86035290779277E-8,4.56917647354746E-5,3.23413754259804E-7,9.9997997,9.9997997,-4917.486328125,-4907.26806640625,57.1417345268907,20.5037475988638,11.139823,0,0,0,40,4449,9.9989,-4912.37719726562,,,,,,,,,,,,,0,,,,0,,,,,,9.9997997,,,,
,27433809.845,9.9991598,-8018.47802734375,5.3537037671349E-5,2.0273334983214E-7,1,0.999253354069792,40.0298881530762,1.99690956556727,16.7999994009733,0.0006012645392589,0.000109691479142991,0.25,2.23843487719799E-7,5.32547574993695E-5,5.08955579890194E-7,9.9991598,9.9991598,-8025.935546875,-8011.0205078125,57.0932735586983,20.5047747666252,10.760172,0,0,0,40,4449,9.9991,-8018.47802734375,,,,,,,,,,,,,0,,,,-0.0049,,,,,,9.9991598,,,,
,27433871.815,10.0004025,-11112.7397460938,6.19327072724727E-5,2.03258408228902E-7,1,0.999253354069792,40.0298881530762,1.99681192850813,16.7999994009733,0.000695729334712994,0.000126727823175451,0.25,2.27799004732362E-7,6.1621575158701E-5,5.72002085912872E-7,10.0004025,10.0004025,-11115.4140625,-11110.0654296875,56.8798889729483,20.4986009425499,10.760172,0,0,0,40,4449,9.9979,-11112.7397460938,,,,,,,,,,,,,0,,,,0,,,,,,10.0004025,,,,
,27433937.485,10.0005388,-14396.4008789062,6.80928570561653E-5,2.32508963030831E-7,1,0.999253354069792,40.0298881530762,1.99683213960232,16.7999994009733,0.000766000960632979,0.0001346426020924,0.25,-1.86539368795366E-7,6.77725648278128E-5,2.10267657287082E-7,10.0005388,10.0005388,-14403.85546875,-14388.9462890625,57.0862389020253,20.5053572762966,10.760172,0,0,0,40,4449,9.9983,-14396.4008789062,,,,,,,,,,,,,0,,,,-0.00245,,,,,,10.0005388,,,,
,27434004.645,10.0005932,-17754.10546875,7.26063132472366E-5,3.15468873134933E-7,1,0.999253354069792,40.0298881530762,1.99686463990299,16.7999994009733,0.000817291038629716,0.000142222258966656,0.25,-3.39589036450902E-7,7.2288096492397E-5,1.0105382807775E-7,10.0005932,10.0005932,-17756.544921875,-17751.666015625,57.2769562607176,20.5099203112663,10.760172,0,0,0,40,4449,9.9981,-17754.10546875,,,,,,,,,,,,,0,,,,-0.0049,,,,,,10.0005932,,,,
,27434070.065,10.0007935,-21022.3310546875,7.34589580360463E-5,3.03890058890493E-7,1,0.999253354069792,40.0298881530762,1.99689405231112,16.7999994009733,0.00082789875021228,0.00013983795279664,0.25,-7.23874940543126E-7,7.31626151102958E-5,-2.6087880544954E-7,10.0007935,10.0007935,-21029.861328125,-21014.80078125,56.811105663256,20.5072363882272,11.139823,0,0,0,40,4449,9.9972,-21022.3310546875,,,,,,,,,,,,,0,,,,0,,,,,,10.0007935,,,,
,27434133.795,10.0006161,-24205.4091796875,7.30293812292497E-5,2.92792840564626E-7,1,0.999253354069792,40.0298881530762,1.99687020457143,16.7999994009733,0.000822084611601183,0.000145918812601532,0.25,-1.24494548011427E-7,7.27543050034346E-5,3.47438190489772E-7,10.0006161,10.0006161,-24207.923828125,-24202.89453125,57.2386564632753,20.5057193430944,11.139823,0,0,0,40,4449,9.9978,-24205.4091796875,,,,,,,,,,,,,0,,,,0,,,,,,10.0006161,,,,
,27434201.91,10.0005808,-27611.5419921875,7.34220485478098E-5,3.45865442614276E-7,1,0.999253354069792,40.0298881530762,1.9968615410102,16.7999994009733,0.000827636831607006,0.000142051421628426,0.25,-5.56678343968237E-7,7.3174062771197E-5,-6.69313936556317E-8,10.0005808,10.0005808,-27616.46875,-27606.615234375,57.0831123879483,20.5061482838263,11.139823,0,0,0,40,4449,9.99755,-27611.5419921875,,,,,,,,,,,,,0,,,,0,,,,,,10.0005808,,,,
,27434266.445,10.0002136,-30836.654296875,7.57748730892984E-5,3.07317849906655E-7,1,0.999253354069792,40.0298881530762,1.99688204841424,16.7999994009733,0.000853612407093137,0.000151363190207079,0.25,-1.6837823772532E-7,7.55418313119635E-5,3.47729307081502E-7,10.0002136,10.0002136,-30844.21875,-30829.08984375,57.3543374841214,20.5081120186919,10.760172,0,0,0,40,4449,9.99755,-30836.654296875,,,,,,,,,,,,,0,,,,0,,,,,,10.0002136,,,,
,27434331.25,9.9998264,-34077.474609375,8.1018170653618E-5,3.37645337944214E-7,1,0.999253354069792,40.0298881530762,1.99693361728644,16.7999994009733,0.000913480691259222,0.000159312118321787,0.25,-4.20810350509193E-7,8.07984602840095E-5,1.43104780574888E-7,9.9998264,9.9998264,-34087.32421875,-34067.625,57.1026531009291,20.506903087651,11.139823,0,0,0,40,4449,9.9975,-34077.474609375,,,,,,,,,,,,,0,,,,0.0049,,,,,,9.9998264,,,,
,27434397.425,9.9988041,-37382.986328125,8.89389639544176E-5,4.03602993513382E-7,1,0.999253354069792,40.0298881530762,1.99690098690574,16.7999994009733,0.00100312531866357,0.000174952795511256,0.25,-4.72330521647608E-7,8.87291156446932E-5,1.57713082216462E-7,9.9988041,9.9988041,-37395.453125,-37370.51953125,56.9908802226791,20.509144916709,11.139823,0,0,0,40,4449,9.9975,-37382.986328125,,,,,,,,,,,,,0,,,,0,,,,,,9.9988041,,,,
,27434460.68,9.9980745,-40546.361328125,9.80744999915694E-5,3.0815287649642E-7,1,0.999253354069792,40.0298881530762,1.99675805352653,16.7999994009733,0.00110603808073622,0.000195323712872567,0.25,-3.2223060417968E-7,9.78746041357817E-5,3.8190377173419E-7,9.9980745,9.9980745,-40548.69140625,-40544.03125,57.0674798175637,20.5081098428418,11.139823,0,0,0,40,4449,9.9987,-40546.361328125,,,,,,,,,,,,,0,,,,0.0049,,,,,,9.9980745,,,,
,27434525.67,9.9983034,-43791.7578125,0.000107348345107753,4.64961741541197E-7,1,0.999253354069792,40.0298881530762,1.99672353845911,16.7999994009733,0.0012102808461964,0.000217965498104756,0.25,2.16750775968159E-9,0.000107163665300772,7.81394663911728E-7,9.9982443,9.9983625,-43796.74609375,-43786.76953125,57.2441278629099,20.5122475624599,11.139823,0,0,0,40,4449,10.0003,-43791.7578125,,,,,,,,,,,,,0,,,,0,,,,,,9.9983034,,,,
,27434591.465,9.9977455,-47080.212890625,0.000118427913306944,4.13827757408436E-7,1,0.999253354069792,40.0298881530762,1.99692410366808,16.7999994009733,0.00133661198349796,0.000235958158010931,0.25,-4.14190336603338E-7,0.00011826772157405,4.5423809394725E-7,9.9977455,9.9977455,-47085.09765625,-47075.328125,57.1135959001984,20.5104689254679,10.760172,0,0,0,40,4449,10.0024,-47080.212890625,,,,,,,,,,,,,0,,,,0.0049,,,,,,9.9977455,,,,
,27434656.615,9.9970579,-50338.8203125,0.000128380592240983,4.72539444781676E-7,1,0.999253354069792,40.0298881530762,1.99679663109829,16.7999994009733,0.00144864328941295,0.000259707393193309,0.25,-1.14128886499241E-7,0.000128247282293383,8.33412886167635E-7,9.9970579,9.9970579,-50343.9453125,-50333.6953125,57.1206305568714,20.5134606185154,11.519473,0,0,0,40,4449,10.00535,-50338.8203125,,,,,,,,,,,,,0,,,,0,,,,,,9.9970579,,,,
,27434721.49,9.9965429,-53576.55078125,0.000139567921148843,4.8411292043306E-7,1,0.999253354069792,40.0298881530762,1.99680416121055,16.7999994009733,0.00157580335388584,0.000280185686708169,0.25,-3.27709667003297E-7,0.000139469804474006,7.07471797978111E-7,9.9965429,9.9965429,-53581.68359375,-53571.41796875,56.9517987967176,20.5125543948058,11.139823,0,0,0,40,4449,10.0053,-53576.55078125,,,,,,,,,,,,,0,,,,0,,,,,,9.9965429,,,,
,27434788.515,9.9959121,-56929.271484375,0.000151380575581723,5.09448904958936E-7,1,0.999253354069792,40.0298881530762,1.99701507208772,16.7999994009733,0.00171080641103739,0.000299050793292998,0.25,-7.99348374662346E-7,0.000151327120859815,3.26743496550779E-7,9.9958048,9.9960194,-56939.41015625,-56919.1328125,57.2331850636407,20.5102612421916,10.760172,0,0,0,40,4449,10.00935,-56929.271484375,,,,,,,,,,,,,0,,,,-0.00245,,,,,,9.9959121,,,,
,27434853.925,9.9969749,-60197.748046875,0.00016331693119273,4.00984923004237E-7,1,0.999253354069792,40.0298881530762,1.99701293534983,16.7999994009733,0.00184753412011259,0.000315751623128139,0.25,-1.48109257014625E-6,0.000163314676699407,-2.65302033401937E-7,9.9969749,9.9969749,-60207.79296875,-60187.703125,56.8963031718522,20.5105854399161,11.519473,0,0,0,40,4449,10.01205,-60197.748046875,,,,,,,,,,,,,0,,,,-0.00245,,,,,,9.9969749,,,,
,27434917.995,9.9971094,-63398.935546875,0.000174774445469833,5.00280882419659E-7,1,0.999253354069792,40.0298881530762,1.99695418221907,16.7999994009733,0.00197448482955142,0.000355703630570838,0.25,-1.59953939512184E-8,0.000174812035826134,1.28399308775561E-6,9.9970026,9.9972162,-63406.51953125,-63391.3515625,57.4090514804676,20.5108234916091,11.139823,0,0,0,40,4449,10.0135,-63398.935546875,,,,,,,,,,,,,0,,,,0.00245,,,,,,9.9971094,,,,
,27434978.265,9.99676275,-66409.25,0.000185583485855499,4.67212314893851E-7,1,0.999253354069792,40.0298881530762,1.99699747484499,16.7999994009733,0.00210119313156573,0.000355690857335736,0.25,-1.97131416293442E-6,0.000185687935559792,-5.94714531217092E-7,9.996726,9.9967995,-66414.2109375,-66404.2890625,57.3637170263522,20.5121719076014,11.519473,0,0,0,40,4449,10.0157,-66409.25,,,,,,,,,,,,,0,,,,0.0049,,,,,,9.99676275,,,,
,27435037.365,9.9961462,-69364.84765625,0.000195662180500828,6.71581059522781E-7,1,0.999253354069792,40.0298881530762,1.99691561733142,16.7999994009733,0.00221279032126588,0.000391707720445166,0.25,-6.03075223708992E-7,0.000195811502309065,8.44211982320141E-7,9.9961462,9.9961462,-69372.5234375,-69357.171875,56.841589175506,20.5113506457479,10.760172,0,0,0,40,4449,10.01755,-69364.84765625,,,,,,,,,,,,,0,,,,0,,,,,,9.9961462,,,,
,27435096.365,9.9961863,-72313.29296875,0.000207372180145114,4.49338866539162E-7,1,0.999253354069792,40.0298881530762,1.99693644319655,16.7999994009733,0.00234611636417492,0.000413633695455756,0.25,-7.75895506592046E-7,0.000207582732321522,7.51209941341616E-7,9.9961863,9.9961863,-72320.7578125,-72305.828125,57.1894138665637,20.5110248511354,11.519473,0,0,0,40,4449,10.02025,-72313.29296875,,,,,,,,,,,,,0,,,,0,,,,,,9.9961863,,,,
,27435156.23,9.9958086,-75303.64453125,0.000217518688879462,6.72530031526415E-7,1,0.999253354069792,40.0298881530762,1.99703260936673,16.7999994009733,0.00246284357411328,0.000427188636330895,0.25,-1.40704016332137E-6,0.000217796567194882,1.85386123853277E-7,9.9958086,9.9958086,-75338.765625,-75268.5234375,57.0924919301791,20.5131386048931,11.139823,0,0,0,40,4449,10.02265,-75303.64453125,,,,,,,,,,,,,0,,,,0,,,,,,9.9958086,,,,
,27435216.425,9.9960823,-78314.1875,0.000228314210120858,5.82020274120603E-7,1,0.999253354069792,40.0298881530762,1.99696056206503,16.7999994009733,0.002585602415076,0.000448420426615819,0.25,-1.4713026507638E-6,0.00022865946304546,1.8938256383392E-7,9.9960823,9.9960823,-78321.875,-78306.5,56.9650864815445,20.5096923456606,11.519473,0,0,0,40,4449,10.0249,-78314.1875,,,,,,,,,,,,,0,,,,0,,,,,,9.9960823,,,,
,27435276.155,9.9951181,-81298.40625,0.000239889459815059,5.47749659561533E-7,1,0.999253354069792,40.0298881530762,1.99693007307152,16.7999994009733,0.00271652271965269,0.000475329723063782,0.25,-1.17298103642683E-6,0.000240303282534606,5.59943826236634E-7,9.9951181,9.9951181,-81306.15625,-81290.65625,57.3168193151984,20.5153385685401,11.139823,0,0,0,40,4449,10.02735,-81298.40625,,,,,,,,,,,,,0,,,,0,,,,,,9.9951181,,,,
,27435334.795,9.9951525,-84231,0.000249726517884944,5.24811544311299E-7,1,0.999253354069792,40.0298881530762,1.99685711862475,16.7999994009733,0.00282988266232832,0.000486763180956848,0.25,-1.92678781641794E-6,0.000250215308785161,-1.38144977284356E-7,9.9951525,9.9951525,-84233.5546875,-84228.4453125,57.3613721407945,20.5130431572109,11.519473,0,0,0,40,4449,10.0304,-84231,,,,,,,,,,,,,0,,,,-0.0049,,,,,,9.9951525,,,,
,27435389.61,9.995285,-86969.390625,0.000259957855464063,5.53498733107683E-7,1,0.999253354069792,40.0298881530762,1.99688003714873,16.7999994009733,0.00294443180080384,0.000517827607655746,0.25,-1.0174237990469E-6,0.000260509132789025,8.31825054182073E-7,9.995285,9.995285,-86976.6640625,-86962.1171875,57.1862873524868,20.5124483582414,11.139823,0,0,0,40,4449,10.03235,-86969.390625,,,,,,,,,,,,,0,,,,-0.00735,,,,,,9.995285,,,,
,27435444.195,9.9948082,-89697.38671875,0.000270375014159838,5.86675037535872E-7,1,0.999253354069792,40.0298881530762,1.99696740322711,16.7999994009733,0.00306399193766007,0.000533785202265941,0.25,-1.47614092476832E-6,0.000271000802931253,4.30308906616222E-7,9.9948082,9.9948082,-89709.796875,-89684.9765625,57.1612752398714,20.5118081624018,11.139823,0,0,0,40,4449,10.0339,-89697.38671875,,,,,,,,,,,,,0,,,,0,,,,,,9.9948082,,,,
,27435515.125,9.9971838,-87673.4453125,0.000263921400014152,5.94394384875513E-7,1,0.999253354069792,40.0298881530762,1.99706100444279,16.7999994009733,0.00298909363907885,0.000529310002967885,0.25,-7.18312295648378E-7,0.000264491481482772,1.15586346253315E-6,9.9971838,9.9971838,-87683.1171875,-87663.7734375,57.1112510146407,20.5141447558222,11.139823,0,0,0,40,4449,10.03545,-87673.4453125,,,,,,,,,,,,,0,,,,0,,,,,,9.9971838,,,,
,27435572,9.9996309,-84833.17578125,0.0002520908143247,5.87142980856288E-7,1,0.999253354069792,40.0298881530762,1.99710206539418,16.7999994009733,0.00285706036876615,0.000491836862390635,0.25,-1.90778702552769E-6,0.00025259467264944,-1.05206582517449E-7,9.9996309,9.9996309,-84840.3125,-84826.0390625,57.3285437429868,20.5152924386863,11.139823,0,0,0,40,4449,10.03425,-84833.17578125,,,,,,,,,,,,,0,,,,-0.00245,,,,,,9.9996309,,,,
,27435633.415,10.0008307,-81762.26953125,0.000241350213840763,5.92835971148191E-7,1,0.999253354069792,40.0298881530762,1.99708464314447,16.7999994009733,0.00273356867868021,0.000477111316166129,0.25,-1.2809445952179E-6,0.000241775506847707,4.60291863878606E-7,10.0008307,10.0008307,-81767.3359375,-81757.203125,57.0909286731407,20.5156839672541,10.760172,0,0,0,40,4449,10.0342,-81762.26953125,,,,,,,,,,,,,0,,,,0.00245,,,,,,10.0008307,,,,
,27435692.83,10.0018234,-78793.4921875,0.00023156911427951,5.25975373360353E-7,1,0.999253354069792,40.0298881530762,1.99710663065193,16.7999994009733,0.00262213200971962,0.000458249628366509,0.25,-1.19091694723904E-6,0.000231925564961811,4.92028528415914E-7,10.0018234,10.0018234,-78798.5390625,-78788.4453125,57.108906129083,20.5140712599314,10.760172,0,0,0,40,4449,10.0315,-78793.4921875,,,,,,,,,,,,,0,,,,-0.00245,,,,,,10.0018234,,,,
,27435752.77,10.0021982,-75798.0078125,0.000219622661228264,5.9795787956245E-7,1,0.999253354069792,40.0298881530762,1.99699794395594,16.7999994009733,0.00248560575087205,0.000437525642508189,0.25,-8.71242302675079E-7,0.000219907806392405,7.35674106266911E-7,10.0021982,10.0021982,-75805.609375,-75790.40625,57.1128142716791,20.5156433851464,11.139823,0,0,0,40,4449,10.0299,-75798.0078125,,,,,,,,,,,,,0,,,,-0.00245,,,,,,10.0021982,,,,
,27435812.03,10.0025473,-72837.13671875,0.000208740490297478,4.81870057031244E-7,1,0.999253354069792,40.0298881530762,1.99704119554841,16.7999994009733,0.0023639763795683,0.000404412911283613,0.25,-1.83992951659349E-6,0.000208969211730769,-3.05193397101951E-7,10.0025473,10.0025473,-72847.15625,-72827.1171875,57.2144259791791,20.5126648354653,11.519473,0,0,0,40,4449,10.02785,-72837.13671875,,,,,,,,,,,,,0,,,,-0.00245,,,,,,10.0025473,,,,
,27435870.79,10.0035772,-69899,0.000198333661915494,5.73246891670213E-7,1,0.999253354069792,40.0298881530762,1.99703286478901,16.7999994009733,0.00224691992890128,0.000376619511196576,0.25,-2.42165947573988E-6,0.000198507415988893,-9.57079845819332E-7,10.0035772,10.0035772,-69903.921875,-69894.078125,57.3004051162945,20.5154419398442,10.760172,0,0,0,40,4449,10.0266,-69899,,,,,,,,,,,,,0,,,,-0.0049,,,,,,10.0035772,,,,
,27435931.1,10.0038157,-66885.89453125,0.00018769840305193,5.61397501639878E-7,1,0.999253354069792,40.0298881530762,1.99693450379014,16.7999994009733,0.00212467158669344,0.000362476972156865,0.25,-1.75166815889152E-6,0.000187810104108469,-3.59948676356977E-7,10.0038157,10.0038157,-66895.65625,-66876.1328125,57.3230723433522,20.5150244074387,10.760172,0,0,0,40,4449,10.0239,-66885.89453125,,,,,,,,,,,,,0,,,,0.00245,,,,,,10.0038157,,,,
,27435988.445,10.00389765,-64022.755859375,0.000177548660140985,7.03118053373554E-7,1,0.999253354069792,40.0298881530762,1.99693611616555,16.7999994009733,0.00200791341036648,0.00035031891335662,0.25,-9.93660960431757E-7,0.000177604153531101,3.26271532822374E-7,10.0038509,10.0039444,-64032.94140625,-64012.5703125,56.9416376259676,20.5136157146174,10.760172,0,0,0,40,4449,10.02315,-64022.755859375,,,,,,,,,,,,,0,,,,-0.0049,,,,,,10.00389765,,,,
,27436048.36,10.0032415,-61023.90234375,0.000166889471245711,4.97431957714605E-7,1,0.999253354069792,40.0298881530762,1.99692442278863,16.7999994009733,0.00188845688952631,0.00032021587295228,0.25,-1.73062100146876E-6,0.000166901663022492,-4.88402114369777E-7,10.0032415,10.0032415,-61033.859375,-61013.9453125,57.017455592333,20.5118112134965,11.519473,0,0,0,40,4449,10.02,-61023.90234375,,,,,,,,,,,,,0,,,,-0.00245,,,,,,10.0032415,,,,
,27436111.83,10.00376795,-57853.306640625,0.000155638053211126,5.70022406781587E-7,1,0.999253354069792,40.0298881530762,1.99691506527127,16.7999994009733,0.00175977837988772,0.000303122426275525,0.25,-1.20764204683624E-6,0.000155599794574709,-4.93228451942411E-8,10.0037479,10.003788,-57860.80078125,-57845.8125,57.1276652135445,20.5140316044887,10.760172,0,0,0,40,4449,10.0185,-57853.306640625,,,,,,,,,,,,,0,,,,-0.00245,,,,,,10.00376795,,,,
,27436175.96,10.0043831,-54650.509765625,0.000142664072811322,4.1755283935472E-7,1,0.999253354069792,40.0298881530762,1.99690498893189,16.7999994009733,0.00161340196153599,0.000273170536440943,0.25,-1.51215285215527E-6,0.000142587643875611,-4.52106059607342E-7,10.0043831,10.0043831,-54657.953125,-54643.06640625,57.0635716749676,20.5149669548186,10.38052,0,0,0,40,4449,10.0153,-54650.509765625,,,,,,,,,,,,,0,,,,-0.0049,,,,,,10.0043831,,,,
,27436241.945,10.0032845,-51352.05859375,0.000131481279449521,5.09364560139997E-7,1,0.999253354069792,40.0298881530762,1.99687153022768,16.7999994009733,0.00148640599739101,0.000251758589583697,0.25,-1.38206973257613E-6,0.000131367557042962,-4.08783283541351E-7,10.0032845,10.0032845,-51359.265625,-51344.8515625,56.9783741663714,20.5133577288986,10.760172,0,0,0,40,4449,10.01415,-51352.05859375,,,,,,,,,,,,,0,,,,0,,,,,,10.0032845,,,,
,27436305.64,10.0037642,-48168.888671875,0.00012114748920343,5.03228116565074E-7,1,0.999253354069792,40.0298881530762,1.99697455125089,16.7999994009733,0.00136950640561326,0.00023023156297514,0.25,-1.41682134895194E-6,0.000121004495462065,-5.24927953646263E-7,10.0037642,10.0037642,-48176.34375,-48161.43359375,57.0229269919676,20.5137618445938,11.139823,0,0,0,40,4449,10.01145,-48168.888671875,,,,,,,,,,,,,0,,,,0,,,,,,10.0037642,,,,
,27436368.83,10.0037889,-45010.810546875,0.000109363162662061,5.50427397640525E-7,1,0.999253354069792,40.0298881530762,1.99684558189998,16.7999994009733,0.00123597411723866,0.000206839132560686,0.25,-1.35387780548084E-6,0.000109198822008997,-5.54831383596476E-7,10.0037889,10.0037889,-45013.390625,-45008.23046875,57.0151107067753,20.5145986226764,10.760172,0,0,0,40,4449,10.0084,-45010.810546875,,,,,,,,,,,,,0,,,,-0.0049,,,,,,10.0037889,,,,
,27436431.79,10.0034323,-41862.609375,9.81910550139846E-5,4.66101041820663E-7,1,0.999253354069792,40.0298881530762,1.9968783329866,16.7999994009733,0.00110994247371559,0.00018241998638183,0.25,-1.4948307231866E-6,9.80130237012479E-5,-7.84008550748609E-7,10.0034323,10.0034323,-41870.05859375,-41855.16015625,57.088583787583,20.5160949410806,10.760172,0,0,0,40,4449,10.0071,-41862.609375,,,,,,,,,,,,,0,,,,0,,,,,,10.0034323,,,,
,27436494.55,10.0028191,-38726.931640625,8.7172364007262E-5,3.97949345378108E-7,1,0.999253354069792,40.0298881530762,1.99694782343048,16.7999994009733,0.000984405173758105,0.000165715592980682,0.25,-9.80628494206508E-7,8.69828195701768E-5,-3.58049457271888E-7,10.0028191,10.0028191,-38736.890625,-38716.97265625,56.9674313671022,20.516650771165,11.139823,0,0,0,40,4449,10.00545,-38726.931640625,,,,,,,,,,,,,0,,,,0.00245,,,,,,10.0028191,,,,
,27436559.805,10.0025997,-35465.939453125,7.58987558431553E-5,4.65087051695706E-7,1,0.999253354069792,40.0298881530762,1.99673812895663,16.7999994009733,0.000857293644836542,0.000140981921474093,0.25,-1.13260985701027E-6,7.57093032731736E-5,-5.98292465796113E-7,10.0025997,10.0025997,-35473.40234375,-35458.4765625,56.8877052581406,20.5108382161008,11.139823,0,0,0,40,4449,10.0048,-35465.939453125,,,,,,,,,,,,,0,,,,0,,,,,,10.0025997,,,,
,27436622.96,10.002409,-32308.1591796875,6.51955153970105E-5,5.62707982721051E-7,1,0.999253354069792,40.0298881530762,1.9968047694458,16.7999994009733,0.000737038537230882,0.000116243023048044,0.25,-1.39257471885073E-6,6.50137142283047E-5,-9.40530652277682E-7,10.002409,10.002409,-32315.681640625,-32300.63671875,57.1894138665637,20.5160758540505,10.38052,0,0,0,40,4449,10.0026,-32308.1591796875,,,,,,,,,,,,,0,,,,0.00245,,,,,,10.002409,,,,
,27436688.225,10.0018921,-29047.71484375,5.40177818694468E-5,3.91488253193807E-7,1,0.999253354069792,40.0298881530762,1.99691919980317,16.7999994009733,0.000609690817053931,0.000100761317694401,0.25,-7.48055491065263E-7,5.38457213431229E-5,-3.82723176722291E-7,10.0018921,10.0018921,-29062.693359375,-29032.736328125,56.7876568076791,20.5112154166316,10.38052,0,0,0,40,4449,10.0028,-29047.71484375,,,,,,,,,,,,,0,,,,-0.00245,,,,,,10.0018921,,,,
,27436752.83,10.0012035,-25819.1376953125,4.26037330400059E-5,4.16915144986327E-7,1,0.999253354069792,40.0298881530762,1.99693201143242,16.7999994009733,0.000482215370150742,7.10054318598447E-5,0.25,-1.3325197411763E-6,4.24585315653143E-5,-1.04875479759428E-6,10.0012035,10.0012035,-25823.98046875,-25814.294921875,56.841589175506,20.5156628678828,11.139823,0,0,0,40,4449,10.00255,-25819.1376953125,,,,,,,,,,,,,0,,,,0.00245,,,,,,10.0012035,,,,
,27436815.605,10.0004864,-22681.0751953125,3.21568110848906E-5,3.31993795919972E-7,1,0.999253354069792,40.0298881530762,1.99683732311917,16.7999994009733,0.000364196765694643,5.155750561602E-5,0.25,-1.17917720247978E-6,3.20379007349474E-5,-9.69857758675965E-7,10.0004864,10.0004864,-22686.1484375,-22676.001953125,57.1167224142753,20.5121399647188,10.760172,0,0,0,40,4449,10.0009,-22681.0751953125,,,,,,,,,,,,,0,,,,-0.00245,,,,,,10.0004864,,,,
,27436880.24,10.0011721,-19450.2578125,2.13475153256967E-5,3.24821830440146E-7,1,0.999253354069792,40.0298881530762,1.99683871308195,16.7999994009733,0.000240589767286296,4.03937470568024E-5,0.25,-2.29231087931125E-7,2.12582200936246E-5,-9.67293064266194E-8,10.0011721,10.0011721,-19457.728515625,-19442.787109375,56.7782772654483,20.5105382369261,11.139823,0,0,0,40,4449,10.00165,-19450.2578125,,,,,,,,,,,,,0,,,,0,,,,,,10.0011721,,,,
,27436944.32,10.0000849,-16249.9877929687,1.08816517245787E-5,2.82670148324272E-7,1,0.999253354069792,40.0298881530762,1.99683374999706,16.7999994009733,0.000123352040062736,1.63757903489594E-5,0.25,-4.88706508260438E-7,1.08350302038364E-5,-4.21789650011882E-7,10.0000849,10.0000849,-16254.990234375,-16244.9853515625,57.095618444256,20.5127151754433,10.760172,0,0,0,40,4449,10.0015,-16249.9877929687,,,,,,,,,,,,,0,,,,0,,,,,,10.0000849,,,,
,27437007.865,9.9994965,-13071.486328125,1.55273676271382E-7,2.53471073373779E-7,1,0.999253354069792,40.0298881530762,1.99687513617708,16.7999994009733,3.54600190062642E-6,-9.77387014461748E-6,0.25,-8.97049430874284E-7,1.59653120436142E-7,-8.91822840734442E-7,9.9994965,9.9994965,-13076.2998046875,-13066.6728515625,57.0721695886791,20.5120627313354,10.760172,0,0,0,40,4449,10.0028,-13071.486328125,,,,,,,,,,,,,0,,,,0,,,,,,9.9994965,,,,
,27437069.225,9.9990921,-10005.740234375,-1.00811154431484E-5,3.15212162438241E-7,1,0.999253354069792,40.0298881530762,1.99675902151859,16.7999994009733,-0.000111702461281502,-2.9218801046597E-5,0.25,-8.02418259050847E-7,-1.00253530628691E-5,-8.53720742041405E-7,9.9990921,9.9990921,-10013.1083984375,-9998.3720703125,56.9885353371214,20.5151445122212,10.38052,0,0,0,40,4449,10.00265,-10005.740234375,,,,,,,,,,,,,0,,,,-0.00245,,,,,,9.9990921,,,,
,27437132.65,9.9987974,-6836.65844726563,-2.00975589968963E-5,2.27577115976121E-7,1,0.999253354069792,40.0298881530762,1.99681586153043,16.7999994009733,-0.000224821980471285,-4.60018022443709E-5,0.25,-5.1554130228863E-7,-1.99875547756119E-5,-6.18512482953724E-7,9.9987793,9.9988155,-6839.3310546875,-6833.98583984375,56.902556200006,20.5133052947836,10.38052,0,0,0,40,4449,10.0037,-6836.65844726563,,,,,,,,,,,,,0,,,,-0.0049,,,,,,9.9987974,,,,
,27450154.38,10.0010605,-0.517608284950256,,,2,,,,17.0900004088879,,,,,,,10.0010605,10.0010605,-0.517608284950256,-0.517608284950256,,,10.760172,,,,-99999999,4369,9.9941,-0.517608284950256,,,,,,,,,,,,,,,,,,,,,,,10.0010605,,,,