File: data/monolayers/nanoparticles/Ac_CoFe_C/vsm/data_disorderedWafer/DD226_2_ZFCW_100OE.DAT
[Header]
; VSM Data File (default extension .dat)
; Copyright (c) 2003-2013, Quantum Design, Inc. All rights reserved.
TITLE,
FILEOPENTIME,27374372.50,11/14/2018,3:59 am
BYAPP,VSM,2.0,2.0
INFO,PPMS VSM Option Release 1.4.10 Build 1,APPNAME
INFO,Quantum Design Linear Motor Servo Controller,MOTOR_MODULE_NAME
INFO,3101-100 M1,MOTOR_HW_VERSION
INFO,MMC1014,MOTOR_SERIAL_NUMBER
INFO,SRV No X-over 01.03.11,MOTOR_SOFTWARE_VERSION
INFO,Quantum Design VSM Detection Module,VSM_MODULE_NAME
INFO,3101-150 F0,VSM_HW_VERSION
INFO,VSM707,VSM_SERIAL_NUMBER
INFO,VSM No X-over 01.02.05 May 20 2008 13:51:47,VSM_SOFTWARE_VERSION
INFO,704,PREAMP_SERIAL_NUMBER
INFO,822,COIL_SERIAL_NUMBER
INFO,0,MOMENT_UNITS
INFO,CoFe2O4 AH11,SAMPLE_MATERIAL
INFO,Quick Dry Monolayer Conc,SAMPLE_COMMENT
INFO,27.96,SAMPLE_MASS
INFO,,SAMPLE_VOLUME
INFO,,SAMPLE_MOLECULAR_WEIGHT
INFO,,SAMPLE_SIZE
INFO,,SAMPLE_SHAPE
DATATYPE,COMMENT,1
DATATYPE,TIME,2
STARTUPAXIS,X,2
STARTUPAXIS,Y1,5
[Data]
Comment,Time Stamp (sec),Temperature (K),Magnetic Field (Oe),Moment (emu),M. Std. Err. (emu),Transport Action,Averaging Time (sec),Frequency (Hz),Peak Amplitude (mm),Center Position (mm),Coil Signal' (mV),Coil Signal" (mV),Range (mV),M. Quad. Signal (emu),M. Raw' (emu),M. Raw" (emu),Min. Temperature (K),Max. Temperature (K),Min. Field (Oe),Max. Field (Oe),Mass (grams),Motor Lag (deg),Pressure (Torr),VSM Status (code),Motor Status (code),Measure Status (code),Measure Count,PPMS Status (code),System Temp. (K),System Field (Oe),Sample Position (deg),Bridge 1 Resistance (ohms),Bridge 1 Excitation (에),Bridge 2 Resistance (ohms),Bridge 2 Excitation (에),Bridge 3 Resistance (ohms),Bridge 3 Excitation (에),Bridge 4 Resistance (ohms),Bridge 4 Excitation (에),Signal 1 Vin (V),Signal 2 Vin (V),Digital Inputs (code),Drive 1 Iout (mA),Drive 1 Ipower (W),Drive 2 Iout (mA),Drive 2 Ipower (W),Pressure (),Map 20 (),Map 21 (),Map 22 (),Map 23 (),Map 24 (),Map 25 (),Map 26 (),Map 27 (),Map 28 (),Map 29 ()
,27379638.17,10.0020571,99.7004928588867,,,2,,,,21.4299999693036,,,,,,,10.0020571,10.0020571,99.7004928588867,99.7004928588867,,,13.797379,,,,-99999999,4373,10.0016,99.7004928588867,,,,,,,,,,,,,,,,,,,,,,,10.0020571,,,,
,27379842.74,12.54279135,99.7004928588867,-2.68427402727796E-7,2.8392768541834E-7,1,0.999253354069792,40.0298881530762,1.99738599743549,21.4200001209974,-2.87773895765756E-6,-1.3162572768124E-6,0.25,-6.94681473557455E-8,-2.66549752282901E-7,-7.03634970610938E-8,12.5103464,12.5752363,99.7004928588867,99.7004928588867,56.729816297256,20.5849910325927,15.315984,0,0,0,40,4370,12.6554,99.7004928588867,,,,,,,,,,,,,0,,,,-0.00245,,,,,,12.54279135,,,,
,27379981.425,16.019949,99.7004928588867,-5.70802365014034E-8,2.6953966814815E-7,1,0.999253354069792,40.0298881530762,1.99704968415643,21.4200001209974,8.78523824664987E-8,-4.22007963222714E-6,0.25,-3.65474856301414E-7,-5.49890824862698E-8,-3.63646464914678E-7,16.019949,16.019949,99.7004928588867,99.7004928588867,56.7915649502752,20.5924694550959,16.075285,0,0,0,40,4370,16.1285,99.7004928588867,,,,,,,,,,,,,0,,,,0.00245,,,,,,16.019949,,,,
,27380122.915,19.5251579,99.7004928588867,3.71857762609536E-8,2.22760096547484E-7,1,0.999253354069792,40.0298881530762,1.99689407321174,21.4200001209974,1.26358839007045E-6,-4.68845401910293E-6,0.25,-4.23933569376024E-7,3.90246481489485E-8,-4.21315195461011E-7,19.5251579,19.5251579,99.7004928588867,99.7004928588867,56.7415407250445,20.5991109390301,16.454937,0,0,0,40,4370,19.66685,99.7004928588867,,,,,,,,,,,,,0,,,,-0.0049,,,,,,19.5251579,,,,
,27380265.61,23.0383453,99.7004928588867,-1.9614328945247E-7,3.10975337955459E-7,1,0.999253354069792,40.0298881530762,2.00964120700668,21.4600004255772,-1.25989833162739E-6,-5.78019094467006E-6,0.25,-4.76499530526353E-7,-1.92668395434202E-7,-4.74774770985628E-7,23.0383453,23.0383453,99.7004928588867,99.7004928588867,56.7837486650829,20.6004738802088,17.593889,0,0,0,40,4370,23.2432,99.7004928588867,,,,,,,,,,,,,0,,,,0.00245,,,,,,23.0383453,,,,
,27380405.75,26.5238304,99.7004928588867,-7.4529371303948E-8,3.11017016557621E-7,1,0.999253354069792,40.0298881530762,2.00984133890539,21.4600004255772,7.42047511074258E-8,-5.30224712441497E-6,0.25,-4.55696006341173E-7,-7.17578143183047E-8,-4.53590073327495E-7,26.5238304,26.5238304,99.7004928588867,99.7004928588867,57.047939104583,20.6026805457644,17.973541,0,0,0,40,4370,26.7837,99.7004928588867,,,,,,,,,,,,,0,,,,-0.0049,,,,,,26.5238304,,,,
,27380547.555,30.0502148,99.7004928588867,-1.68040877585098E-7,3.28214601064655E-7,1,0.999253354069792,40.0298881530762,2.00984244316321,21.4600004255772,-9.39587723939883E-7,-5.7280440831129E-6,0.25,-4.76523272737747E-7,-1.64546491090259E-7,-4.7499666798551E-7,30.0502148,30.0502148,99.7004928588867,99.7004928588867,57.0182372208522,20.6051302581728,18.353191,0,0,0,40,4370,30.3442,99.7004928588867,,,,,,,,,,,,,0,,,,0,,,,,,30.0502148,,,,
,27380688.275,33.5507545,99.7004928588867,-3.86308668430541E-7,2.81314589084376E-7,1,0.999253354069792,40.0298881530762,2.00967993234854,21.4699991047382,-3.71903046724138E-6,-4.42550565287463E-6,0.25,-3.22144275364061E-7,-3.82591777544553E-7,-3.2292706567762E-7,33.5507545,33.5507545,99.7004928588867,99.7004928588867,57.2746113751599,20.6041835296434,18.732843,0,0,0,40,4370,33.8864,99.7004928588867,,,,,,,,,,,,,0,,,,0,,,,,,33.5507545,,,,
,27380830.715,37.0787392,99.7004928588867,-4.60845101447754E-7,3.49820386766023E-7,1,0.999253354069792,40.0298881530762,2.00943021560571,21.4699991047382,-4.08724632865431E-6,-7.23382172147586E-6,0.25,-5.56547415507292E-7,-4.55435445717792E-7,-5.57251530298096E-7,37.0787392,37.0787392,99.7004928588867,99.7004928588867,57.1487691835637,20.6081550905728,19.112494,0,0,0,40,4370,37.48245,99.7004928588867,,,,,,,,,,,,,0,,,,0,,,,,,37.0787392,,,,
,27380972.525,40.57061,99.7004928588867,-3.21642381273938E-7,3.51552452019047E-7,1,0.999253354069792,40.0298881530762,2.00933710311742,21.4799996465445,-3.37916746079182E-6,-2.12342613441407E-6,0.25,-1.2969529552223E-7,-3.19730249130843E-7,-1.31478273733845E-7,40.57061,40.57061,99.7004928588867,99.7004928588867,57.2011382943522,20.6056526457363,19.112494,0,0,0,40,4370,41.0652,99.7004928588867,,,,,,,,,,,,,0,,,,0,,,,,,40.57061,,,,
,27381113.855,44.0541,99.7004928588867,-2.22855242358696E-7,2.49957206956791E-7,1,0.999253354069792,40.0298881530762,1.9966360395205,21.4699991047382,-1.39801328576468E-6,-6.63669071481557E-6,0.25,-5.48839179459806E-7,-2.18420576953285E-7,-5.49232971648663E-7,44.0541,44.0541,99.7004928588867,99.7004928588867,56.9502355396791,20.6044467654926,19.492144,0,0,0,40,4370,44.6427,99.7004928588867,,,,,,,,,,,,,0,,,,-0.00245,,,,,,44.0541,,,,
,27381256.96,47.5466805,99.7004928588867,-3.01172952555387E-7,3.04319838007798E-7,1,0.999253354069792,40.0298881530762,1.99640977783589,21.4699991047382,-2.65083389609332E-6,-4.75312883391646E-6,0.25,-3.67117990683962E-7,-2.98128087509305E-7,-3.68946707711114E-7,47.5466805,47.5466805,99.7004928588867,99.7004928588867,57.1276652135445,20.608892970426,20.251448,0,0,0,40,4370,48.2716,99.7004928588867,,,,,,,,,,,,,0,,,,0,,,,,,47.5466805,,,,
,27381397.165,51.0262489,99.7004928588867,-9.22502676163767E-8,3.34571625889653E-7,1,0.999253354069792,40.0298881530762,1.99620861433653,21.4699991047382,-9.66828219693089E-8,-5.43027224282465E-6,0.25,-4.64310360094374E-7,-8.88017330213706E-8,-4.65008597588673E-7,51.0262489,51.0262489,99.7004928588867,99.7004928588867,56.926005055583,20.607196716378,20.631098,0,0,0,40,4370,51.8286,99.7004928588867,,,,,,,,,,,,,0,,,,0,,,,,,51.0262489,,,,
,27381543.74,54.5820446,99.7004928588867,-6.48719599480679E-8,2.8149153994908E-7,1,0.999253354069792,40.0298881530762,2.00906366285263,21.4799996465445,1.96371973184629E-8,-4.33915406205765E-6,0.25,-3.69834506136205E-7,-6.22533619807158E-8,-3.70732220969115E-7,54.5533524,54.6107368,99.7004928588867,99.7004928588867,57.3183825722368,20.6056136385709,20.631098,0,0,0,40,4374,55.57055,99.7004928588867,,,,,,,,,,,,,0,,,,-0.00245,,,,,,54.5820446,,,,
,27381682.36,58.0263176,99.7004928588867,-7.78041194560786E-8,3.10722617286513E-7,1,0.999253354069792,40.0298881530762,2.00917383028191,21.4799996465445,-2.94487787597942E-7,-3.44846883249095E-6,0.25,-2.88899296184873E-7,-7.59442291964341E-8,-2.90049261659114E-7,58.0263176,58.0263176,99.7004928588867,99.7004928588867,57.0932735586983,20.6060485904829,21.770052,0,0,0,40,4374,59.0827,99.7004928588867,,,,,,,,,,,,,0,,,,0,,,,,,58.0263176,,,,
,27381826.925,61.5567589,99.7004928588867,-1.23234692752207E-7,3.36123180570225E-7,1,0.999253354069792,40.0298881530762,2.00883322338342,21.4799996465445,-8.31033460683068E-7,-3.44670696712217E-6,0.25,-2.80401157038474E-7,-1.21741615127413E-7,-2.8203980415029E-7,61.5567589,61.5567589,99.7004928588867,99.7004928588867,57.2347483206791,20.6093290068087,22.149702,0,0,0,40,4374,62.742,99.7004928588867,,,,,,,,,,,,,0,,,,-0.0049,,,,,,61.5567589,,,,
,27381968.315,65.0550308,99.7004928588867,-2.98304392985535E-7,2.7818884294333E-7,1,0.999253354069792,40.0298881530762,1.98464258037841,21.4699991047382,-2.44616196360824E-6,-5.72136472363578E-6,0.25,-4.54230297857523E-7,-2.96569968780004E-7,-4.57716919152638E-7,65.0550308,65.0550308,99.7004928588867,99.7004928588867,57.3605905122753,20.6138062847645,21.770052,0,0,0,40,4374,66.3175,99.7004928588867,,,,,,,,,,,,,0,,,,0,,,,,,65.0550308,,,,
,27382109.545,68.5289688,99.7004928588867,-2.35001624806362E-7,2.76126178293388E-7,1,0.999253354069792,40.0298881530762,1.98455341934352,21.4699991047382,-2.31478277832279E-6,-2.35268213774024E-6,0.25,-1.66670700673E-7,-2.35017889852493E-7,-1.68714281610726E-7,68.5289688,68.5289688,99.7004928588867,99.7004928588867,56.9494539111599,20.6163961790679,22.149702,0,0,0,40,4374,69.88735,99.7004928588867,,,,,,,,,,,,,0,,,,-0.00245,,,,,,68.5289688,,,,
,27382250.25,72.022522,99.7004928588867,-3.76696048055997E-7,2.90818987856078E-7,1,0.999253354069792,40.0298881530762,1.98451384930689,21.4699991047382,-3.27983334543485E-6,-6.20716337103603E-6,0.25,-4.83065836648087E-7,-3.75842623188214E-7,-4.87280825136912E-7,72.022522,72.022522,99.7004928588867,99.7004928588867,57.7607843141215,20.6155977729832,22.149702,0,0,0,40,4374,73.4433,99.7004928588867,,,,,,,,,,,,,0,,,,0.0049,,,,,,72.022522,,,,
,27382354.325,74.5720901,99.7004928588867,-2.93733894445128E-7,3.14231840364232E-7,1,0.999253354069792,40.0298881530762,1.99580515959749,21.4600004255772,-2.823878271137E-6,-3.45792701567491E-6,0.25,-2.52518099120593E-7,-2.93877623187567E-7,-2.55212857125033E-7,74.5720901,74.5720901,99.7004928588867,99.7004928588867,57.108906129083,20.6093856311481,22.529354,0,0,0,40,4374,76.0649,99.7004928588867,,,,,,,,,,,,,0,,,,0,,,,,,74.5720901,,,,
,27382492.325,78.0134201,99.7004928588867,-1.558248991049E-7,2.7715689649182E-7,1,0.999253354069792,40.0298881530762,1.99572707880428,21.4600004255772,-1.42322897458272E-6,-2.26186324308895E-6,0.25,-1.71630386651356E-7,-1.55815673477353E-7,-1.73228602561586E-7,78.0134201,78.0134201,99.7004928588867,99.7004928588867,57.2394380917945,20.6124279878489,22.529354,0,0,0,40,4374,79.5678,99.7004928588867,,,,,,,,,,,,,0,,,,0,,,,,,78.0134201,,,,
,27382637.065,81.5259933,99.7004928588867,-3.83794361516203E-7,3.4737179723243E-7,1,0.999253354069792,40.0298881530762,1.9957345392019,21.4600004255772,-3.89984740452871E-6,-3.35742575076019E-6,0.25,-2.27775065864641E-7,-3.8484042603078E-7,-2.30633289033255E-7,81.5259933,81.5259933,99.7004928588867,99.7004928588867,56.9150622563137,20.610440593644,22.529354,0,0,0,40,4374,83.23815,99.7004928588867,,,,,,,,,,,,,0,,,,0.00245,,,,,,81.5259933,,,,
,27382779.16,85.1126556,99.7004928588867,-2.10961202684169E-7,2.93918758748399E-7,1,0.999253354069792,40.0298881530762,2.00864074203422,21.4399993419647,-1.74724785747406E-6,-4.17992141470293E-6,0.25,-3.2854489465399E-7,-2.10792435674291E-7,-3.31172714610725E-7,85.1126556,85.1126556,99.7004928588867,99.7004928588867,57.3230723433522,20.6111903256511,22.149702,0,0,0,40,4374,86.8309,99.7004928588867,,,,,,,,,,,,,0,,,,-0.00245,,,,,,85.1126556,,,,
,27382919.635,88.5532837,99.7004928588867,-1.98597312482592E-7,2.91061919943809E-7,1,0.999253354069792,40.0298881530762,2.00836773335767,21.4399993419647,-1.78964568519942E-6,-3.11931095225917E-6,0.25,-2.37957639998731E-7,-1.98809151201611E-7,-2.40014268209771E-7,88.5532837,88.5532837,99.7004928588867,99.7004928588867,57.3668435404292,20.6141504931718,22.529354,0,0,0,40,4374,90.34225,99.7004928588867,,,,,,,,,,,,,0,,,,-0.00245,,,,,,88.5532837,,,,
,27383060.34,92.103241,99.7004928588867,-1.94766531885824E-7,2.4770745636353E-7,1,0.999253354069792,40.0298881530762,2.00834562590047,21.4399993419647,-1.66963688255239E-6,-3.54904661902529E-6,0.25,-2.76260255136151E-7,-1.94895896584677E-7,-2.78485475464898E-7,92.103241,92.103241,99.7004928588867,99.7004928588867,57.362935397833,20.6127635450616,22.909004,0,0,0,40,4374,93.86945,99.7004928588867,,,,,,,,,,,,,0,,,,0,,,,,,92.103241,,,,
,27383200.39,95.5475464,99.7004928588867,-5.05991065559273E-7,3.49340092126289E-7,1,0.999253354069792,40.0298881530762,1.98420239178438,21.4200001209974,-4.67260848729061E-6,-6.93896387055293E-6,0.25,-5.25196459453128E-7,-5.07135412526169E-7,-5.29810754336336E-7,95.5475464,95.5475464,99.7004928588867,99.7004928588867,57.1417345268907,20.6197681601341,22.909004,0,0,0,40,4374,97.3853,99.7004928588867,,,,,,,,,,,,,0,,,,0,,,,,,95.5475464,,,,
,27383339.865,99.0411072,99.7004928588867,-1.93427485977253E-7,3.01835528687247E-7,1,0.999253354069792,40.0298881530762,1.98427168822268,21.4200001209974,-1.85439179976852E-6,-2.2679255413356E-6,0.25,-1.66741723959516E-7,-1.94013000424698E-7,-1.68278967010241E-7,99.0411072,99.0411072,99.7004928588867,99.7004928588867,57.3144744296407,20.6181657148422,23.288654,0,0,0,40,4374,100.88415,99.7004928588867,,,,,,,,,,,,,0,,,,-0.0049,,,,,,99.0411072,,,,
,27383480.4,102.5245285,99.7004928588867,4.24371112355217E-8,3.29514118034014E-7,1,0.999253354069792,40.0298881530762,1.98421828579833,21.4200001209974,7.82059771863242E-7,-1.63966515397638E-6,0.25,-1.52570989834885E-7,4.31175963363136E-8,-1.53314115557923E-7,102.5245285,102.5245285,99.7004928588867,99.7004928588867,57.4739266475638,20.6194630679217,22.909004,0,0,0,40,4374,104.42145,99.7004928588867,,,,,,,,,,,,,0,,,,-0.0049,,,,,,102.5245285,,,,
,27383600.58,105.539505,99.7004928588867,2.26975747670531E-8,3.11374610142222E-7,1,0.999253354069792,40.0298881530762,1.9842870235349,21.3900003582239,1.60216129454646E-6,-7.62779815415315E-6,0.25,-6.79061715050992E-7,2.46883863799932E-8,-6.8284622823974E-7,105.539505,105.539505,99.7004928588867,99.7004928588867,57.159711982833,20.6180230209422,23.668306,0,0,0,40,4374,107.4512,99.7004928588867,,,,,,,,,,,,,0,,,,0,,,,,,105.539505,,,,
,27383742.14,109.0479355,99.7004928588867,-3.18942959609246E-7,3.60646033647423E-7,1,0.999253354069792,40.0298881530762,1.98407373785745,21.3900003582239,-3.25162177504627E-6,-2.63902055503573E-6,0.25,-1.77693787085638E-7,-3.20282713154821E-7,-1.79523792173991E-7,109.0479355,109.0479355,99.7004928588867,99.7004928588867,57.5341120435445,20.6175872825025,23.668306,0,0,0,40,4374,111.011,99.7004928588867,,,,,,,,,,,,,0,,,,-0.0049,,,,,,109.0479355,,,,
,27383882.085,112.5145721,99.7004928588867,-1.91113488096057E-7,3.16515010178877E-7,1,0.999253354069792,40.0298881530762,1.98442281040415,21.3900003582239,-1.44863583167366E-6,-4.43826745426616E-6,0.25,-3.59310214552339E-7,-1.91303249905127E-7,-3.61797667406326E-7,112.5145721,112.5145721,99.7004928588867,99.7004928588867,56.8048526351022,20.6167631140011,23.668306,0,0,0,40,4374,114.5323,99.7004928588867,,,,,,,,,,,,,0,,,,-0.0049,,,,,,112.5145721,,,,
,27384004.09,115.5516129,99.7004928588867,1.75150192588879E-7,2.61885014972866E-7,1,0.999253354069792,40.0298881530762,1.98427076722998,21.3699992746115,2.40631236833504E-6,-2.09573756361325E-6,0.25,-2.1613168458005E-7,1.76636073779976E-7,-2.16926130286393E-7,115.5516129,115.5516129,99.7004928588867,99.7004928588867,57.1362631272561,20.6114860718986,24.047956,0,0,0,40,4374,117.6007,99.7004928588867,,,,,,,,,,,,,0,,,,0.0049,,,,,,115.5516129,,,,
,27384146.14,119.0652313,99.7004928588867,-5.70376700705738E-8,2.85318534332546E-7,1,0.999253354069792,40.0298881530762,1.98402885980294,21.3699992746115,3.50830217942342E-9,-3.81757904393107E-6,0.25,-3.27948211582396E-7,-5.66194045235476E-8,-3.29891192100525E-7,119.0652313,119.0652313,99.7004928588867,99.7004928588867,57.3762230826599,20.6186983283717,23.288654,0,0,0,40,4374,121.1614,99.7004928588867,,,,,,,,,,,,,0,,,,0,,,,,,119.0652313,,,,
,27384284.655,122.5079956,99.7004928588867,-1.67112060283804E-7,3.06830672256493E-7,1,0.999253354069792,40.0298881530762,1.98397107566362,21.3699992746115,-1.58141723263538E-6,-2.08292395707885E-6,0.25,-1.55181081919475E-7,-1.67696851547868E-7,-1.56389076332401E-7,122.5079956,122.5079956,99.7004928588867,99.7004928588867,57.1815975813714,20.6177629237138,23.668306,0,0,0,40,4374,124.6464,99.7004928588867,,,,,,,,,,,,,0,,,,-0.0049,,,,,,122.5079956,,,,
,27384426.54,126.055748,99.7004928588867,-8.08021405452039E-9,3.20216683944596E-7,1,0.999253354069792,40.0298881530762,1.99570002501537,21.3300008326769,2.56558734233154E-7,-2.01037286219686E-6,0.25,-1.75561525906738E-7,-7.76564021837606E-9,-1.76530239950081E-7,126.055748,126.055748,99.7004928588867,99.7004928588867,57.2761746321984,20.6118114768949,23.668306,0,0,0,40,4374,128.2178,99.7004928588867,,,,,,,,,,,,,0,,,,0,,,,,,126.055748,,,,
,27384566.075,129.5444031,99.7004928588867,-2.97198914367703E-7,3.33672231230998E-7,1,0.999253354069792,40.0298881530762,1.99547868551881,21.3300008326769,-2.50476925485766E-6,-5.57738930400057E-6,0.25,-4.39167714041151E-7,-2.97932926260402E-7,-4.4210287499425E-7,129.5444031,129.5444031,99.7004928588867,99.7004928588867,57.6200911806599,20.615050204264,24.047956,0,0,0,40,4374,131.7184,99.7004928588867,,,,,,,,,,,,,0,,,,0,,,,,,129.5444031,,,,
,27384707.285,133.0587311,99.7004928588867,1.70827153676887E-7,2.98171428074839E-7,1,0.999253354069792,40.0298881530762,1.9955933263243,21.3300008326769,2.59952968194847E-6,-3.4395001906328E-6,0.25,-3.32634978569536E-7,1.72355111178246E-7,-3.34074362507333E-7,133.0587311,133.0587311,99.7004928588867,99.7004928588867,57.3574639981984,20.6142929052962,24.047956,0,0,0,40,4374,135.2504,99.7004928588867,,,,,,,,,,,,,0,,,,0.0049,,,,,,133.0587311,,,,
,27384849.115,136.5584869,99.7004928588867,-9.42511431718228E-8,2.97160952212799E-7,1,0.999253354069792,40.0298881530762,2.00829956737714,21.2999992072582,-8.62132483453187E-8,-5.86787148635165E-6,0.25,-4.97100076853782E-7,-9.38470524442388E-8,-4.99863889131234E-7,136.5584869,136.5584869,99.7004928588867,99.7004928588867,56.9338213407753,20.6060906590031,24.427608,0,0,0,40,4374,138.8222,99.7004928588867,,,,,,,,,,,,,0,,,,0,,,,,,136.5584869,,,,
,27384988.6,140.0296936,99.7004928588867,-2.35797954313017E-7,3.36995885186849E-7,1,0.999253354069792,40.0298881530762,2.00840522418092,21.2999992072582,-1.89411225141074E-6,-5.05898333968223E-6,0.25,-4.01641720427156E-7,-2.36313543739044E-7,-4.04116151390193E-7,140.0296936,140.0296936,99.7004928588867,99.7004928588867,57.0964000727753,20.6137772467234,24.047956,0,0,0,40,4374,142.32375,99.7004928588867,,,,,,,,,,,,,0,,,,-0.0049,,,,,,140.0296936,,,,
,27385128.4,143.524231,99.7004928588867,-2.81857941956029E-7,3.18847057878622E-7,1,0.999253354069792,40.0298881530762,2.00813638704276,21.2999992072582,-3.1973558175478E-6,-6.90679604819379E-7,0.25,-1.1333728482516E-8,-2.83265768479571E-7,-1.18625873138325E-8,143.524231,143.524231,99.7004928588867,99.7004928588867,56.7259081546598,20.613711727478,24.427608,0,0,0,40,4374,145.8344,99.7004928588867,,,,,,,,,,,,,0,,,,0.00245,,,,,,143.524231,,,,
,27385268.42,147.0033264,99.7004928588867,1.92783287984923E-8,3.33178448005476E-7,1,0.999253354069792,40.0298881530762,1.98413186949364,21.2600007653236,3.72006338069967E-7,-8.47678563612907E-7,0.25,-7.84230183266368E-8,1.95009611161298E-8,-7.87823822575158E-8,146.967453,147.0391998,99.7004928588867,99.7004928588867,57.4817429327561,20.6197712308559,24.427608,0,0,0,40,4374,149.34715,99.7004928588867,,,,,,,,,,,,,0,,,,0,,,,,,147.0033264,,,,
,27385410.735,150.5305481,99.7004928588867,-6.80791193144591E-8,3.34554518153115E-7,1,0.999253354069792,40.0298881530762,1.9841702729091,21.2600007653236,-3.01370293283273E-7,-2.81729964836606E-6,0.25,-2.37635986464752E-7,-6.8041487212574E-8,-2.38904839794155E-7,150.5305481,150.5305481,99.7004928588867,99.7004928588867,57.0799858738714,20.6206559650962,24.047956,0,0,0,40,4374,152.9183,99.7004928588867,,,,,,,,,,,,,0,,,,0.00245,,,,,,150.5305481,,,,
,27385549.545,154.0256195,99.7004928588867,-5.27560942024243E-9,3.25908700107471E-7,1,0.999253354069792,40.0298881530762,1.98395323568001,21.2600007653236,7.02778282966844E-7,-4.38849094272533E-6,0.25,-3.87787947371932E-7,-4.71529847051066E-9,-3.89658734067356E-7,154.0256195,154.0256195,99.7004928588867,99.7004928588867,57.2019199228714,20.6213500456116,24.047956,0,0,0,40,4374,156.3953,99.7004928588867,,,,,,,,,,,,,0,,,,0.0049,,,,,,154.0256195,,,,
,27385690.09,157.5185089,99.7004928588867,-1.12548963523768E-8,2.89245384203072E-7,1,0.999253354069792,40.0298881530762,2.00811213106397,21.229999139905,2.58135458716825E-7,-2.24363007141853E-6,0.25,-1.94501893140787E-7,-1.10233580873182E-8,-1.95434964037328E-7,157.5185089,157.5185089,99.7004928588867,99.7004928588867,57.2355299491984,20.6127219708886,24.807261,0,0,0,40,4374,159.9182,99.7004928588867,,,,,,,,,,,,,0,,,,0,,,,,,157.5185089,,,,
,27385831.2,161.04788205,99.7004928588867,-6.15049371094911E-8,3.04561012317297E-7,1,0.999253354069792,40.0298881530762,2.00805042319955,21.229999139905,5.41147172289987E-7,-7.26728840707546E-6,0.25,-6.25722362487343E-7,-6.09011554140038E-8,-6.28699256956122E-7,161.0183105,161.0774536,99.7004928588867,99.7004928588867,57.1565854687561,20.6142146133121,24.427608,0,0,0,40,4374,163.4511,99.7004928588867,,,,,,,,,,,,,0,,,,0,,,,,,161.04788205,,,,
,27385970.365,164.540863,99.7004928588867,-1.6959586962212E-7,3.39602382470727E-7,1,0.999253354069792,40.0298881530762,2.00819888938343,21.229999139905,-1.34813982176839E-6,-3.71889185323121E-6,0.25,-2.9617642012869E-7,-1.6995471132216E-7,-2.97749529256873E-7,164.540863,164.540863,99.7004928588867,99.7004928588867,57.2847725459099,20.6166747946556,25.186911,0,0,0,40,4374,166.9299,99.7004928588867,,,,,,,,,,,,,0,,,,-0.0049,,,,,,164.540863,,,,
,27386110.955,168.0437622,99.7004928588867,-3.28692640374872E-7,3.56559838769974E-7,1,0.999253354069792,40.0298881530762,2.00832504043234,21.1800001561642,-3.81427404546917E-6,-3.01331522211604E-7,0.25,3.0785921610448E-8,-3.3018812475231E-7,3.04820123381526E-8,168.0437622,168.0437622,99.7004928588867,99.7004928588867,57.2566339192176,20.6151627751349,25.186911,0,0,0,40,4374,170.46005,99.7004928588867,,,,,,,,,,,,,0,,,,0,,,,,,168.0437622,,,,
,27386251.22,171.5223846,99.7004928588867,-1.36752967947709E-7,3.09712512117568E-7,1,0.999253354069792,40.0298881530762,2.00822544039044,21.1800001561642,-3.9101274173816E-7,-7.00054575672382E-6,0.25,-5.89398935183852E-7,-1.36576714156822E-7,-5.92126336611326E-7,171.5223846,171.5223846,99.7004928588867,99.7004928588867,57.2699216040445,20.6159065147597,24.427608,0,0,0,40,4374,173.96205,99.7004928588867,,,,,,,,,,,,,0,,,,-0.00245,,,,,,171.5223846,,,,
,27386390.485,175.0331726,99.7004928588867,1.9267063671468E-7,3.35175716688778E-7,1,0.999253354069792,40.0298881530762,2.00813431799963,21.1800001561642,3.04661108984182E-6,-4.49022392063748E-6,0.25,-4.26857197186828E-7,1.94025743095157E-7,-4.28415526917631E-7,175.0331726,175.0331726,99.7004928588867,99.7004928588867,56.6094455052945,20.6222575363186,25.186911,0,0,0,40,4374,177.4474,99.7004928588867,,,,,,,,,,,,,0,,,,0.0049,,,,,,175.0331726,,,,
,27386512.25,178.0395203,99.7004928588867,4.61642476517629E-7,2.87510278212004E-7,1,0.999253354069792,40.0298881530762,1.98404091080736,21.1500003933907,5.63149773673368E-6,-1.52511705197868E-6,0.25,-2.15419890698854E-7,4.63818328187774E-7,-2.1573808084914E-7,178.0395203,178.0395203,99.7004928588867,99.7004928588867,56.7931282073137,20.6250870817527,24.807261,0,0,0,40,4374,180.4855,99.7004928588867,,,,,,,,,,,,,0,,,,0.0049,,,,,,178.0395203,,,,
,27386651.52,181.5386047,99.7004928588867,-2.30061948327148E-7,3.5920611810834E-7,1,0.999253354069792,40.0298881530762,1.98391882000284,21.1399998515844,-8.05495398153731E-7,-1.07492657912108E-5,0.25,-9.12818083148321E-7,-2.29885355198809E-7,-9.16774834985343E-7,181.5386047,181.5386047,99.7004928588867,99.7004928588867,57.3144744296407,20.6244075298774,24.807261,0,0,0,40,4374,183.9886,99.7004928588867,,,,,,,,,,,,,0,,,,0,,,,,,181.5386047,,,,
,27386791.215,185.0082855,99.7004928588867,2.7334799407841E-7,3.34633240427668E-7,1,0.999253354069792,40.0298881530762,1.98382817887419,21.1399998515844,2.6570720582086E-6,2.98891654881633E-6,0.25,2.17468932200534E-7,2.74164191411704E-7,2.18644928764324E-7,185.0082855,185.0082855,99.7004928588867,99.7004928588867,57.0229269919676,20.6259262055445,25.566563,0,0,0,40,4374,187.4806,99.7004928588867,,,,,,,,,,,,,0,,,,0.0049,,,,,,185.0082855,,,,
,27386910.765,188.0252075,99.7004928588867,3.65331151477137E-7,3.80178438170171E-7,1,0.999253354069792,40.0298881530762,2.00809173058816,21.0999995470047,5.62731627530033E-6,-7.67001762575621E-6,0.25,-7.35658396388681E-7,3.67581392444792E-7,-7.38055028669815E-7,188.0252075,188.0252075,99.7004928588867,99.7004928588867,57.0033862789868,20.611850716135,25.566563,0,0,0,40,4374,190.48215,99.7004928588867,,,,,,,,,,,,,0,,,,0,,,,,,188.0252075,,,,
,27387052.225,191.5046082,99.7004928588867,-6.44124339076036E-9,2.99058668696281E-7,1,0.999253354069792,40.0298881530762,2.00826823994127,21.0999995470047,5.20305460967293E-7,-3.4306344526492E-6,0.25,-2.99537289687153E-7,-6.12710598870162E-9,-3.0065993994771E-7,191.5046082,191.5046082,99.7004928588867,99.7004928588867,57.0135474497368,20.615539818859,25.186911,0,0,0,40,4374,194.0396,99.7004928588867,,,,,,,,,,,,,0,,,,0.0049,,,,,,191.5046082,,,,
,27387193.125,195.0263214,99.7004928588867,3.38826276360899E-7,3.60735244821479E-7,1,0.999253354069792,40.0298881530762,2.00826891892571,21.0999995470047,5.2145286111966E-6,-7.09299894029491E-6,0.25,-6.80544142254861E-7,3.40801161950683E-7,-6.82629013670206E-7,195.0263214,195.0263214,99.7004928588867,99.7004928588867,57.2644502044099,20.6167407489038,24.807261,0,0,0,40,4374,197.57455,99.7004928588867,,,,,,,,,,,,,0,,,,-0.00245,,,,,,195.0263214,,,,
,27387332.63,198.5275269,99.7004928588867,3.65021630208037E-7,3.58472594217858E-7,1,0.999253354069792,40.0298881530762,1.99550946056533,21.0500005632639,4.42233196627419E-6,-9.12774280728183E-7,0.25,-1.43897925080397E-7,3.66454946783969E-7,-1.44007881469165E-7,198.5275269,198.5275269,99.7004928588867,99.7004928588867,56.8408075469868,20.6153285168502,25.186911,0,0,0,40,4374,201.0725,99.7004928588867,,,,,,,,,,,,,0,,,,-0.00245,,,,,,198.5275269,,,,
,27387475.51,202.0672455,99.7004928588867,3.6338794448892E-7,3.29331183350895E-7,1,0.999253354069792,40.0298881530762,1.99562657288168,21.0500005632639,4.01859671534847E-6,1.30056570743131E-6,0.25,5.15996697050337E-8,3.64564426605798E-7,5.21579771443275E-8,202.0672455,202.0672455,99.7004928588867,99.7004928588867,57.4309370790061,20.6180550094285,24.807261,0,0,0,40,4374,204.65825,99.7004928588867,,,,,,,,,,,,,0,,,,-0.0049,,,,,,202.0672455,,,,
,27387614.335,205.5440979,99.7004928588867,3.82413331792721E-7,3.15462827470835E-7,1,0.999253354069792,40.0298881530762,1.9957302720793,21.0500005632639,4.35309936576214E-6,6.52369730171304E-7,0.25,-8.86107275660946E-9,3.83674656913676E-7,-8.49488177484572E-9,205.5440979,205.5440979,99.7004928588867,99.7004928588867,57.616964666583,20.6165016125746,25.186911,0,0,0,40,4374,208.141,99.7004928588867,,,,,,,,,,,,,0,,,,-0.00245,,,,,,205.5440979,,,,
,27387753.15,209.00816345,99.7004928588867,2.4039165397E-7,3.25128140787161E-7,1,0.999253354069792,40.0298881530762,1.98457802562082,21.0100002586842,3.32924302875913E-6,-3.09251559729402E-6,0.25,-3.15995394635353E-7,2.41471431131948E-7,-3.16750763116525E-7,208.9770355,209.0392914,99.7004928588867,99.7004928588867,56.9721211382176,20.6160461920128,25.566563,0,0,0,40,4374,211.6031,99.7004928588867,,,,,,,,,,,,,0,,,,0.0049,,,,,,209.00816345,,,,
,27387894.315,212.525589,99.7004928588867,9.28185611753661E-7,3.24757866982318E-7,1,0.999253354069792,40.0298881530762,1.98438618433848,21.0100002586842,1.13780201834806E-5,-3.44895870112382E-6,0.25,-4.67062029035977E-7,9.31474689753797E-7,-4.67563128424983E-7,212.525589,212.525589,99.7004928588867,99.7004928588867,57.1729996676599,20.6195237698524,25.566563,0,0,0,40,4374,215.14685,99.7004928588867,,,,,,,,,,,,,0,,,,0,,,,,,212.525589,,,,
,27388034.525,216.0083313,99.7004928588867,6.84358350314698E-7,3.02576984894122E-7,1,0.999253354069792,40.0298881530762,1.98401531880094,21.0100002586842,8.3885169482306E-6,-2.55350030956125E-6,0.25,-3.45357090312236E-7,6.86698147718527E-7,-3.45702816762784E-7,216.0083313,216.0083313,99.7004928588867,99.7004928588867,57.0096393071407,20.6256742314245,25.946213,0,0,0,40,4374,218.66525,99.7004928588867,,,,,,,,,,,,,0,,,,-0.00245,,,,,,216.0083313,,,,
,27388174.15,219.5061417,99.7004928588867,1.1093040938848E-6,3.02532840321123E-7,1,0.999253354069792,40.0298881530762,1.98449831220904,20.9599994122982,1.35371265871498E-5,-3.78458288475839E-6,0.25,-5.28289001449454E-7,1.11292584623094E-6,-5.28715643831341E-7,219.4732819,219.5390015,99.7004928588867,99.7004928588867,57.0721695886791,20.6147865386657,25.186911,0,0,0,40,4374,222.1514,99.7004928588867,,,,,,,,,,,,,0,,,,-0.0049,,,,,,219.5061417,,,,
,27388315.38,223.0388031,99.7004928588867,1.79540099817882E-6,3.42298357751394E-7,1,0.999253354069792,40.0298881530762,1.98442904167095,20.9599994122982,2.0974558816243E-5,-7.55736969574379E-7,0.25,-3.78627865774574E-7,1.800586726376E-6,-3.77966819601337E-7,223.0388031,223.0388031,99.7004928588867,99.7004928588867,57.5028469027753,20.6192255035095,25.566563,0,0,0,40,4374,225.6983,99.7004928588867,,,,,,,,,,,,,0,,,,-0.00245,,,,,,223.0388031,,,,
,27388455.78,226.5213776,99.7004928588867,1.29466220045331E-6,3.29689216772236E-7,1,0.999253354069792,40.0298881530762,1.9844426504855,20.9599994122982,1.51290557728415E-5,-5.79848605662722E-7,0.25,-2.76106476300914E-7,1.29824607201743E-6,-2.75627821167007E-7,226.5213776,226.5213776,99.7004928588867,99.7004928588867,56.6860451001791,20.6169466050074,25.946213,0,0,0,40,4374,229.2136,99.7004928588867,,,,,,,,,,,,,0,,,,0,,,,,,226.5213776,,,,
,27388595.74,230.0219574,99.7004928588867,1.9115509452982E-6,2.96014389986845E-7,1,0.999253354069792,40.0298881530762,1.98459563626235,20.9100004285574,2.26458851083862E-5,-2.63791508783832E-6,0.25,-5.65762076904349E-7,1.91674875531183E-6,-5.65426099160172E-7,230.0219574,230.0219574,99.7004928588867,99.7004928588867,56.8228300910445,20.6163127221623,25.566563,0,0,0,40,4374,232.7222,99.7004928588867,,,,,,,,,,,,,0,,,,-0.00245,,,,,,230.0219574,,,,
,27388736.365,233.5414581,99.7004928588867,2.435112232902E-6,4.13026276279546E-7,1,0.999253354069792,40.0298881530762,1.98448830686108,20.9100004285574,2.80720939407728E-5,1.08565135021544E-6,0.25,-3.26096292360901E-7,2.44107706716577E-6,-3.24700586775136E-7,233.5414581,233.5414581,99.7004928588867,99.7004928588867,56.8603482599676,20.6179969959104,25.946213,0,0,0,40,4374,236.2568,99.7004928588867,,,,,,,,,,,,,0,,,,-0.00245,,,,,,233.5414581,,,,
,27388877.19,237.0396729,99.7004928588867,2.12964678895174E-6,4.16858556308378E-7,1,0.999253354069792,40.0298881530762,1.98443541176521,20.9100004285574,2.42362529212371E-5,2.74083329345424E-6,0.25,-1.26118681675096E-7,2.13446234420926E-6,-1.24545472026351E-7,237.0396729,237.0396729,99.7004928588867,99.7004928588867,57.6161830380638,20.6197925020478,25.946213,0,0,0,40,4374,239.7947,99.7004928588867,,,,,,,,,,,,,0,,,,0,,,,,,237.0396729,,,,
,27389018.515,240.5277863,99.7004928588867,2.02900044841319E-6,4.17628265316372E-7,1,0.999253354069792,40.0298881530762,1.98436266726982,20.8599995821714,2.32841163696357E-5,1.47579349271906E-6,0.25,-2.20909316016488E-7,2.03342618201455E-6,-2.19637048062328E-7,240.5277863,240.5277863,99.7004928588867,99.7004928588867,57.2527257766214,20.6187844745163,25.946213,0,0,0,40,4374,243.3262,99.7004928588867,,,,,,,,,,,,,0,,,,-0.0049,,,,,,240.5277863,,,,
,27389156.47,244.0017395,99.7004928588867,3.11731040922366E-6,3.65912278159363E-7,1,0.999253354069792,40.0298881530762,1.98444601736549,20.8599995821714,3.55938510998762E-5,3.28413008752355E-6,0.25,-2.49057046318087E-7,3.12365030795318E-6,-2.46928389321164E-7,243.9720001,244.0314789,99.7004928588867,99.7004928588867,57.3090030300061,20.6216226650631,26.325863,0,0,0,40,4374,246.79165,99.7004928588867,,,,,,,,,,,,,0,,,,0,,,,,,244.0017395,,,,
,27389299.23,247.5483398,99.7004928588867,3.33688859950658E-6,4.26607401867374E-7,1,0.999253354069792,40.0298881530762,1.9846439477101,20.8599995821714,3.83085946775236E-5,2.31182016022071E-6,0.25,-3.73421044386297E-7,3.34334371136313E-6,-3.71354148945838E-7,247.5483398,247.5483398,99.7004928588867,99.7004928588867,57.3770047111791,20.618045709829,26.705515,0,0,0,40,4374,250.3711,99.7004928588867,,,,,,,,,,,,,0,,,,0,,,,,,247.5483398,,,,
,27389420.12,250.5540161,99.7004928588867,2.91184407734733E-6,3.62031878353155E-7,1,0.999253354069792,40.0298881530762,1.99577541773562,20.8100005984306,3.34003536773698E-5,3.20429969836666E-6,0.25,-2.21909884352321E-7,2.91708002667629E-6,-2.19925739347556E-7,250.5540161,250.5540161,99.7004928588867,99.7004928588867,56.8025077495445,20.6124526581587,25.946213,0,0,0,40,4374,253.3947,99.7004928588867,,,,,,,,,,,,,0,,,,-0.0049,,,,,,250.5540161,,,,
,27389557.34,254.0331116,99.7004928588867,3.71223181909953E-6,3.26400447910879E-7,1,0.999253354069792,40.0298881530762,1.99574261616614,20.8100005984306,4.24895790251583E-5,4.57870845009797E-6,0.25,-2.39198911690928E-7,3.71841157105849E-6,-2.36612322368875E-7,254.0331116,254.0331116,99.7004928588867,99.7004928588867,57.0760777312753,20.6118543483256,25.946213,0,0,0,40,4374,256.80945,99.7004928588867,,,,,,,,,,,,,0,,,,0,,,,,,254.0331116,,,,
,27389699.125,257.53105165,99.7004928588867,3.93095667779282E-6,4.28993271119355E-7,1,0.999253354069792,40.0298881530762,1.99596167408612,20.8100005984306,4.4606202852442E-5,7.07444607184562E-6,0.25,-5.65782205461536E-8,3.93685482337179E-6,-5.35669134134951E-8,257.5010071,257.5610962,99.7004928588867,99.7004928588867,57.210517836583,20.6107652293825,26.325863,0,0,0,40,4374,260.3921,99.7004928588867,,,,,,,,,,,,,0,,,,-0.0049,,,,,,257.53105165,,,,
,27389840.365,261.0407257,99.7004928588867,4.37273248541177E-6,3.12494514606073E-7,1,0.999253354069792,40.0298881530762,2.00857798218927,20.7499992102385,5.08145890709721E-5,2.71095232093399E-6,0.25,-5.2002193044602E-7,4.37910128138087E-6,-5.17343373906095E-7,261.006958,261.0744934,99.7004928588867,99.7004928588867,56.9783741663714,20.6088064382217,26.325863,0,0,0,40,4374,263.92575,99.7004928588867,,,,,,,,,,,,,0,,,,-0.0049,,,,,,261.0407257,,,,
,27389981.265,264.52948,99.7004928588867,4.46559657743687E-6,3.62621217660717E-7,1,0.999253354069792,40.0298881530762,2.00854040135049,20.7499992102385,5.10457368912746E-5,7.61675622880252E-6,0.25,-1.0511061595328E-7,4.47121428855413E-6,-1.01835942913712E-7,264.52948,264.52948,99.7004928588867,99.7004928588867,57.2894623170253,20.616272448679,26.705515,0,0,0,40,4374,267.4608,99.7004928588867,,,,,,,,,,,,,0,,,,0,,,,,,264.52948,,,,
,27390123.11,268.039978,99.7004928588867,5.39845947488492E-6,4.18275251717218E-7,1,0.999253354069792,40.0298881530762,2.00835408249404,20.7499992102385,6.20595531115534E-5,7.10863704058804E-6,0.25,-3.11267009789391E-7,5.40471105442088E-6,-3.07562751467014E-7,268.039978,268.039978,99.7004928588867,99.7004928588867,57.1847240954484,20.6192677458606,26.325863,0,0,0,40,4374,271.0235,99.7004928588867,,,,,,,,,,,,,0,,,,-0.0049,,,,,,268.039978,,,,
,27390263.16,271.5508728,99.7004928588867,5.58880739286061E-6,5.21945119956935E-7,1,0.999253354069792,40.0298881530762,1.99600013802321,20.7000002264977,6.32484960500234E-5,1.08579683810421E-5,0.25,-9.03878903417827E-9,5.59434281592457E-6,-4.91819497325631E-9,271.5508728,271.5508728,99.7004928588867,99.7004928588867,56.5992843345444,20.6149254506552,25.946213,0,0,0,40,4374,274.53545,99.7004928588867,,,,,,,,,,,,,0,,,,0,,,,,,271.5508728,,,,
,27390402.39,275.030304,99.7004928588867,5.83793121560946E-6,3.5225278536334E-7,1,0.999253354069792,40.0298881530762,1.99574300188983,20.7000002264977,6.78991987488988E-5,6.78802350908375E-7,0.25,-9.51850643421708E-7,5.84367215971457E-6,-9.48425240037442E-7,275.030304,275.030304,99.7004928588867,99.7004928588867,57.1026531009291,20.6190571965521,26.705515,0,0,0,40,4374,278.0225,99.7004928588867,,,,,,,,,,,,,0,,,,0,,,,,,275.030304,,,,
,27390544.91,278.5441589,99.7004928588867,6.16431101780184E-6,3.55041750667032E-7,1,0.999253354069792,40.0298881530762,1.99573340687191,20.7000002264977,7.18920626212575E-5,-4.73736480643009E-7,0.25,-1.11025103644153E-6,6.16966143166367E-6,-1.10665390902319E-6,278.5441589,278.5441589,99.7004928588867,99.7004928588867,56.5656743082175,20.6195301618893,26.705515,0,0,0,40,4374,281.59735,99.7004928588867,,,,,,,,,,,,,0,,,,-0.00245,,,,,,278.5441589,,,,
,27390687.115,282.0121765,99.7004928588867,6.51512576925799E-6,5.26632793278806E-7,1,0.999253354069792,40.0298881530762,1.99582156210738,20.6499993801117,7.40441347563174E-5,1.06530510142399E-5,0.25,-1.87067713406762E-7,6.51926243823238E-6,-1.82585067557405E-7,282.0121765,282.0121765,99.7004928588867,99.7004928588867,56.6860451001791,20.6133693999407,26.705515,0,0,0,40,4374,285.21635,99.7004928588867,,,,,,,,,,,,,0,,,,-0.0049,,,,,,282.0121765,,,,
,27390827.475,285.5606079,99.7004928588867,7.23680048799101E-6,4.31758812060501E-7,1,0.999253354069792,40.0298881530762,1.99558901761131,20.6499993801117,8.22660048779457E-5,1.16012173932529E-5,0.25,-2.27973843547834E-7,7.24048689263519E-6,-2.23052076258027E-7,285.5606079,285.5606079,99.7004928588867,99.7004928588867,57.0541921327368,20.6164914706308,26.325863,0,0,0,40,4374,288.6943,99.7004928588867,,,,,,,,,,,,,0,,,,0,,,,,,285.5606079,,,,
,27390965.27,289.0054016,99.7004928588867,6.8734376300631E-6,3.76592418992828E-7,1,0.999253354069792,40.0298881530762,1.99562098577164,20.6499993801117,7.83205457042555E-5,9.90015004081224E-6,0.25,-3.15300541484738E-7,6.87615620707262E-6,-3.10702649002813E-7,289.0054016,289.0054016,99.7004928588867,99.7004928588867,57.4684552479292,20.6193586830743,26.325863,0,0,0,40,4374,292.1281,99.7004928588867,,,,,,,,,,,,,0,,,,0.0049,,,,,,289.0054016,,,,
,27391105.615,292.5229187,99.7004928588867,7.38969538646163E-6,4.63959790216831E-7,1,0.999253354069792,40.0298881530762,1.98442819737713,20.6000003963709,8.31239911872674E-5,1.41494269261985E-5,0.25,-2.19070418390332E-8,7.39146975916293E-6,-1.69174347603558E-8,292.5229187,292.5229187,99.7004928588867,99.7004928588867,56.8611298884868,20.6148695856474,26.705515,0,0,0,40,4374,295.6207,99.7004928588867,,,,,,,,,,,,,0,,,,-0.0049,,,,,,292.5229187,,,,
,27391247.145,296.04092405,99.7004928588867,7.27473013177778E-6,3.30694455786013E-7,1,0.999253354069792,40.0298881530762,1.98416288833687,20.6000003963709,8.25439773764794E-5,9.68979739638566E-6,0.25,-3.98361728210027E-7,7.27581227050428E-6,-3.93558969361807E-7,296.0101318,296.0717163,99.7004928588867,99.7004928588867,57.0409044479099,20.6200208366716,27.085165,0,0,0,40,4374,299.1591,99.7004928588867,,,,,,,,,,,,,0,,,,-0.0049,,,,,,296.04092405,,,,
,27391386.965,299.5064697,99.7004928588867,7.45894328072584E-6,5.16729757150065E-7,1,0.999253354069792,40.0298881530762,1.98426750243469,20.6000003963709,8.37401093913022E-5,1.50588041550165E-5,0.25,4.7555617959186E-8,7.45882589124094E-6,5.24567775965509E-8,299.5064697,299.5064697,99.7004928588867,99.7004928588867,56.6727574153522,20.6199949027086,26.705515,0,0,0,40,4374,302.6532,99.7004928588867,,,,,,,,,,,,,0,,,,0.0049,,,,,,299.5064697,,,,
,27391528.16,303.0406494,99.7004928588867,6.81320232716758E-6,4.02558931557375E-7,1,0.999253354069792,40.0298881530762,2.00886359030834,20.5499995499849,7.81399520826542E-5,9.56084318237621E-6,0.25,-3.39519980118094E-7,6.8124847595325E-6,-3.35057374389209E-7,303.0406494,303.0406494,99.7004928588867,99.7004928588867,56.8431524325445,20.6101638819839,26.325863,0,0,0,40,4374,306.18535,99.7004928588867,,,,,,,,,,,,,0,,,,0.00245,,,,,,303.0406494,,,,
,27391670.225,306.5819397,99.7004928588867,7.82625346400854E-6,4.56843401688858E-7,1,0.999253354069792,40.0298881530762,2.00860097580691,20.5499995499849,8.89314604232959E-5,1.56238300518808E-5,0.25,1.85977587730606E-8,7.82417789939173E-6,2.35958718195975E-8,306.5819397,306.5819397,99.7004928588867,99.7004928588867,56.8791073444291,20.6135642648408,27.085165,0,0,0,40,4374,309.76515,99.7004928588867,,,,,,,,,,,,,0,,,,0,,,,,,306.5819397,,,,
,27391810.87,310.0426331,99.7004928588867,6.9699433452686E-6,4.40831066307458E-7,1,0.999253354069792,40.0298881530762,2.00846484165869,20.5499995499849,7.98016821550793E-5,1.03584792179748E-5,0.25,-2.96006279964293E-7,6.96743548107134E-6,-2.91495190005891E-7,310.0426331,310.0426331,99.7004928588867,99.7004928588867,57.1214121853907,20.6154973770922,26.325863,0,0,0,40,4374,313.2823,99.7004928588867,,,,,,,,,,,,,0,,,,-0.00245,,,,,,310.0426331,,,,
,27391931.46,313.0636292,99.7004928588867,7.63690230660633E-6,3.79994602329436E-7,1,0.999253354069792,40.0298881530762,1.98467320175915,20.4900000244379,8.68523173808921E-5,8.8388919152724E-6,0.25,-5.3620594648938E-7,7.63346680631765E-6,-5.31177906535866E-7,313.0636292,313.0636292,99.7004928588867,99.7004928588867,56.8032893780637,20.6088832564898,26.705515,0,0,0,40,4374,316.309,99.7004928588867,,,,,,,,,,,,,0,,,,-0.0049,,,,,,313.0636292,,,,
,27392070.3,316.5115662,99.7004928588867,7.79564458148782E-6,3.84758765677602E-7,1,0.999253354069792,40.0298881530762,1.98422337615191,20.4900000244379,8.90217756080865E-5,6.74386567513591E-6,0.25,-7.49893513597715E-7,7.79130824902394E-6,-7.44631244731153E-7,316.5115662,316.5115662,99.7004928588867,99.7004928588867,56.7556100383906,20.6169895947954,26.705515,0,0,0,40,4374,319.79195,99.7004928588867,,,,,,,,,,,,,0,,,,-0.0049,,,,,,316.5115662,,,,
,27392211.825,320.0401306,99.7004928588867,7.39711600476665E-6,4.45220026193353E-7,1,0.999253354069792,40.0298881530762,1.98439342764859,20.4900000244379,8.30385085196747E-5,1.46472020047868E-5,0.25,2.28764203217831E-8,7.39162990227383E-6,2.7356885029759E-8,320.0401306,320.0401306,99.7004928588867,99.7004928588867,56.8345545188329,20.6152509070809,27.085165,0,0,0,40,4374,323.3544,99.7004928588867,,,,,,,,,,,,,0,,,,0,,,,,,320.0401306,,,,
,27392352.175,323.5083008,99.7004928588867,7.10050222384449E-6,4.37749354828792E-7,1,0.999253354069792,40.0298881530762,2.00869301342027,20.4399991780519,8.09901643922513E-5,1.21445988186066E-5,0.25,-1.60867737080278E-7,7.09448182357442E-6,-1.56465199014548E-7,323.4779663,323.5386353,99.7004928588867,99.7004928588867,56.9689946241406,20.6088276933536,26.705515,0,0,0,40,4374,326.87445,99.7004928588867,,,,,,,,,,,,,0,,,,0,,,,,,323.5083008,,,,
,27392492.75,327.0033264,99.7004928588867,7.21880580494503E-6,4.65555548059428E-7,1,0.999253354069792,40.0298881530762,2.00849204283198,20.4399991780519,8.30109498319658E-5,8.36406665697356E-6,0.25,-5.13889091799336E-7,7.21200977813089E-6,-5.09100688800161E-7,327.0033264,327.0033264,99.7004928588867,99.7004928588867,57.0971817012945,20.6123733340639,27.464817,0,0,0,40,4374,330.3911,99.7004928588867,,,,,,,,,,,,,0,,,,-0.0049,,,,,,327.0033264,,,,
,27392634.22,330.5125122,99.7004928588867,7.34956909269794E-6,3.96519791516737E-7,1,0.999253354069792,40.0298881530762,2.00847899464941,20.4399991780519,8.42457188503E-5,1.00043250596454E-5,0.25,-3.9197216731286E-7,7.3416716484014E-6,-3.87229795065397E-7,330.5125122,330.5125122,99.7004928588867,99.7004928588867,56.8705094307176,20.6106494800774,27.085165,0,0,0,40,4374,333.9371,99.7004928588867,,,,,,,,,,,,,0,,,,0.00245,,,,,,330.5125122,,,,
,27392773.9,334.0119934,99.7004928588867,7.01831130681554E-6,3.96619830000586E-7,1,0.999253354069792,40.0298881530762,1.98492386729404,20.3799996525049,7.95786224758016E-5,9.21187862591794E-6,0.25,-3.95045805320293E-7,7.00992841720774E-6,-3.90492970044269E-7,334.0119934,334.0119934,99.7004928588867,99.7004928588867,57.105779615006,20.6092173041421,26.705515,0,0,0,40,4374,337.4235,99.7004928588867,,,,,,,,,,,,,0,,,,-0.0098,,,,,,334.0119934,,,,
,27392915.79,337.5491943,99.7004928588867,7.52736821810437E-6,4.43048854046332E-7,1,0.999253354069792,40.0298881530762,1.98463665864514,20.3799996525049,8.46514737141443E-5,1.37867013673878E-5,0.25,-7.54308094623106E-8,7.51725716185964E-6,-7.10151316289029E-8,337.5491943,337.5491943,99.7004928588867,99.7004928588867,57.1386080128137,20.6132344797288,27.464817,0,0,0,40,4374,340.9964,99.7004928588867,,,,,,,,,,,,,0,,,,0,,,,,,337.5491943,,,,
,27393056.885,341.0089111,99.7004928588867,7.10848914163629E-6,3.80322682984227E-7,1,0.999253354069792,40.0298881530762,1.98473287620431,20.3799996525049,8.13235913700748E-5,4.99970642065072E-6,0.25,-7.85529915854712E-7,7.09850213646983E-6,-7.80347061269014E-7,341.0089111,341.0089111,99.7004928588867,99.7004928588867,57.0190188493714,20.6108146158621,27.085165,0,0,0,40,4374,344.51045,99.7004928588867,,,,,,,,,,,,,0,,,,0.00245,,,,,,341.0089111,,,,
,27393197.125,344.52770995,99.7004928588867,7.04494918074836E-6,3.85037499209385E-7,1,0.999253354069792,40.0298881530762,2.00870234612125,20.3200001269579,8.09573001662135E-5,8.23562708379075E-6,0.25,-4.94492098281202E-7,7.03404249093029E-6,-4.89754782043565E-7,344.4967041,344.5587158,99.7004928588867,99.7004928588867,56.760299809506,20.6076904332712,27.464817,0,0,0,40,4374,348.0348,99.7004928588867,,,,,,,,,,,,,0,,,,-0.0049,,,,,,344.52770995,,,,
,27393338.71,348.053894,99.7004928588867,6.55576017868842E-6,3.8189466409606E-7,1,0.999253354069792,40.0298881530762,2.0088673120477,20.3200001269579,7.54953655992596E-5,6.72354077319471E-6,0.25,-5.42906292137255E-7,6.54487107595946E-6,-5.38338980861695E-7,348.053894,348.053894,99.7004928588867,99.7004928588867,57.2027015513907,20.6074613547616,27.844467,0,0,0,40,4374,351.5836,99.7004928588867,,,,,,,,,,,,,0,,,,0,,,,,,348.053894,,,,
,27393654.605,349.7511597,99.7004928588867,6.55291567356805E-6,3.65275010154567E-7,1,0.999253354069792,40.0298881530762,2.00896954028567,20.3200001269579,7.61667802129474E-5,2.64984897116074E-6,0.25,-9.0123938517854E-7,6.54185475377707E-6,-8.96000773251532E-7,349.7511597,349.7511597,99.7004928588867,99.7004928588867,56.966649738583,20.6063087433735,27.844467,0,0,0,40,4369,350.64345,99.7004928588867,,,,,,,,,,,,,0,,,,0,,,,,,349.7511597,,,,