File: data/doubleLayers/dl_0-25/ppms/DD205_10_HYST_50K_1OE.DAT
[Header]
; VSM Data File (default extension .dat)
; Copyright (c) 2003, Quantum Design, Inc. All rights reserved.
TITLE,
FILEOPENTIME,15761660.88,04/18/2018,3:48 am
BYAPP,VSM,1.0,1.0
INFO,PPMS VSM Option Release 1.3.7 Build 2,APPNAME
INFO,291,COIL_SERIAL_NUMBER
INFO,0,MOMENT_UNITS
INFO,,SAMPLE_MATERIAL
INFO,,SAMPLE_COMMENT
INFO,,SAMPLE_MASS
INFO,,SAMPLE_VOLUME
INFO,,SAMPLE_MOLECULAR_WEIGHT
INFO,,SAMPLE_SIZE
INFO,,SAMPLE_SHAPE
INFO,35.28,SAMPLE_OFFSET
DATATYPE,COMMENT,1
DATATYPE,TIME,2
STARTUPAXIS,X,2
STARTUPAXIS,Y1,5
[Data]
Comment,Time Stamp (sec),Temperature (K),Magnetic Field (Oe),Moment (emu),M. Std. Err. (emu),Transport Action,Averaging Time (sec),Frequency (Hz),Peak Amplitude (mm),Center Position (mm),Coil Signal' (mV),Coil Signal" (mV),Range (mV),M. Quad. Signal (emu),M. Raw' (emu),M. Raw" (emu),Min. Temperature (K),Max. Temperature (K),Min. Field (Oe),Max. Field (Oe),Mass (grams),Motor Lag (deg),Pressure (Torr),VSM Status (code),Motor Status (code),Measure Status (code),PPMS Status (code),System Temp. (K),System Field (Oe),Sample Position (deg),Bridge 1 Resistance (ohms),Bridge 1 Excitation (에),Bridge 2 Resistance (ohms),Bridge 2 Excitation (에),Bridge 3 Resistance (ohms),Bridge 3 Excitation (에),Bridge 4 Resistance (ohms),Bridge 4 Excitation (에),Signal 1 Vin (V),Signal 2 Vin (V),Digital Inputs (code),Drive 1 Iout (mA),Drive 1 Ipower (W),Drive 2 Iout (mA),Drive 2 Ipower (W),Pressure (),Map 20 (),Map 21 (),Map 22 (),Map 23 (),Map 24 (),Map 25 (),Map 26 (),Map 27 (),Map 28 (),Map 29 ()
,15761694.925,50.0111084,0.31326025724411,6.09185438511813E-5,1.83636867772273E-7,1,0.999253354069792,40.0298881530762,1.99095110290778,16.4700025320053,0.000661064009523042,9.25176334938917E-5,0.25,-2.39729487489786E-6,6.08374994203285E-5,-2.01067725049434E-6,50.0111084,50.0111084,0.290338784456253,0.336181730031967,51.6703348922747,18.6652888041543,7.648531,0,0,0,4417,50.0498,0.31326025724411,,,,,,,,,,,,,,,,,13.378378,,,,,,50.0111084,,,,
,15761788.94,50.0138474,3944.91284179687,6.13220455036252E-5,2.14381809748635E-7,1,0.999253354069792,40.0298881530762,1.99096676734843,16.4800030738115,0.000664953214891656,9.61021648744776E-5,0.25,-2.138813838913E-6,6.12424419585978E-5,-1.74934672982714E-6,50.0138474,50.0138474,3939.791015625,3950.03466796875,52.0205044688901,18.6771352553922,7.5725036,0,0,0,4449,50.0315,3944.91284179687,,,,,,,,,,,,,,,,,13.003003,,,,,,50.0138474,,,,
,15761867.865,50.01115795,7887.95922851562,5.26722237861597E-5,2.56040045858903E-7,1,0.999253354069792,40.0298881530762,1.9910235939795,16.4700025320053,0.00057114773370802,8.29606618361657E-5,0.25,-1.80045664871095E-6,5.26079970534689E-5,-1.46517702821909E-6,50.0109634,50.0113525,7855.474609375,7920.44384765625,52.5066774078517,18.679798100794,7.7641027,0,0,0,4449,50.0246,7887.95922851562,,,,,,,,,,,,,,,,,13.378378,,,,,,50.01115795,,,,
,15761944.085,50.0085831,11698.86328125,4.36315860147134E-5,2.1254630773709E-7,1,0.999253354069792,40.0298881530762,1.99098893311088,16.4700025320053,0.000474372196619388,6.19536716047975E-5,0.25,-2.12059268369493E-6,4.35862636163382E-5,-1.84135169659982E-6,50.0085831,50.0085831,11673.9462890625,11723.7802734375,52.2284176550055,18.6825887890702,7.7641027,0,0,0,4449,50.0203,11698.86328125,,,,,,,,,,,,,,,,,13.378378,,,,,,50.0085831,,,,
,15762021.68,50.00842285,15577.1323242187,3.45176727592942E-5,2.56834494407328E-7,1,0.999253354069792,40.0298881530762,1.99103697669778,16.4800030738115,0.00037656891797333,4.21408368482415E-5,0.25,-2.31629700714948E-6,3.44891935741063E-5,-2.09412016839401E-6,50.0083923,50.0084534,15547.083984375,15607.1806640625,52.7255333932363,18.6815690497609,7.7253218,0,0,0,4449,50.0147,15577.1323242187,,,,,,,,,,,,,,,,,12.252253,,,,,,50.00842285,,,,
,15762099.68,50.00647925,19475.150390625,2.54234312370364E-5,3.01089661079328E-7,1,0.999253354069792,40.0298881530762,1.99109134601351,16.4700025320053,0.000280029313280838,1.64150778134185E-5,0.25,-3.06328378654782E-6,2.54136605561143E-5,-2.89780856972096E-6,50.0064049,50.0065536,19455.099609375,19495.201171875,52.3151784206402,18.6815053639747,7.7641027,0,0,0,4449,50.00805,19475.150390625,,,,,,,,,,,,,,,,,12.252253,,,,,,50.00647925,,,,
,15762177.195,50.0055809,23348.1611328125,1.5779472635685E-5,2.73031714438663E-7,1,0.999253354069792,40.0298881530762,1.99118673711502,16.4700025320053,0.000175864878864106,-1.08346704760238E-6,0.25,-2.94710804003413E-6,1.57817648169E-5,-2.84324607342991E-6,50.0055809,50.0055809,23343.083984375,23353.23828125,52.1987157712748,18.6816128733572,7.76487735,0,0,0,4449,50.0096,23348.1611328125,,,,,,,,,,,,,,,,,13.378378,,,,,,50.0055809,,,,
,15762257.64,50.0040092,27371.521484375,5.28354244596007E-6,2.90230881924284E-7,1,0.999253354069792,40.0298881530762,1.9912884315029,16.4700025320053,6.28783298288674E-5,-2.24392259277643E-5,0.25,-3.03410460124176E-6,5.29800877915378E-6,-2.99743342589658E-6,50.0040092,50.0040092,27366.404296875,27376.638671875,52.5660811753133,18.6816463752358,7.8812237,0,0,0,4449,50.006,27371.521484375,,,,,,,,,,,,,,,,,12.252253,,,,,,50.0040092,,,,
,15762334.775,50.0041847,31226.4267578125,-4.25378978009656E-6,5.61465208505135E-7,1,0.999253354069792,40.0298881530762,1.99119662605916,16.4700025320053,-4.12569823907271E-5,-3.3864955490472E-5,0.25,-2.37273049073202E-6,-4.23502804195888E-6,-2.39804315783159E-6,50.0040779,50.0042915,31193.81640625,31259.037109375,52.8881121252364,18.6821974038383,7.9207871,0,0,0,4449,50.0007,31226.4267578125,,,,,,,,,,,,,,,,,13.378378,,,,,,50.0041847,,,,
,15762413.47,50.004673,35157.05078125,-1.57240291369754E-5,4.63891006049317E-7,1,0.999253354069792,40.0298881530762,1.99119028256411,16.4800030738115,-0.000162387278553224,-7.05137252594144E-5,0.25,-3.70067982456193E-6,-1.56888909971481E-5,-3.79906064034572E-6,50.004631,50.004715,35127.11328125,35186.98828125,52.8591918700248,18.6821287684258,7.84205365,0,0,0,4449,49.99865,35157.05078125,,,,,,,,,,,,,,,,,13.378378,,,,,,50.004673,,,,
,15762493.205,50.0041008,39142,-2.63317493354806E-5,6.66063105551823E-7,1,0.999253354069792,40.0298881530762,1.99113150898508,16.4800030738115,-0.00027558152544487,-9.80175597770978E-5,0.25,-4.33574206532326E-6,-2.62877588369687E-5,-4.50258107042835E-6,50.0041008,50.0041008,39139.4296875,39144.5703125,52.7763392469864,18.6834882279166,7.76487735,0,0,0,4449,49.9915,39142,,,,,,,,,,,,,,,,,12.252253,,,,,,50.0041008,,,,
,15762569.5,50.00317765,42955.69921875,-3.66410979951662E-5,5.91185944416431E-7,1,0.999253354069792,40.0298881530762,1.99117961047761,16.4800030738115,-0.000387703183253492,-0.00011326746399732,0.25,-3.88761654593236E-6,-3.65976633747112E-5,-4.12179853443711E-6,50.003109,50.0032463,42923.1953125,42988.203125,52.9201588945248,18.6836085962638,7.7253218,0,0,0,4449,49.99165,42955.69921875,,,,,,,,,,,,,,,,,13.378378,,,,,,50.00317765,,,,
,15762650.89,50.004612,47023.8671875,-4.86275749662119E-5,7.42804066997724E-7,1,0.999253354069792,40.0298881530762,1.99112805308136,16.4700025320053,-0.000515877930951723,-0.000143144318349636,0.25,-4.4926353595702E-6,-4.85798571515213E-5,-4.80459070443316E-6,50.004612,50.004612,47016.3203125,47031.4140625,52.5793688601402,18.6843185082986,7.8812237,0,0,0,4449,49.9903,47023.8671875,,,,,,,,,,,,,,,,,13.378378,,,,,,50.004612,,,,
,15762729.525,50.00177765,50954.498046875,-5.88214261474445E-5,6.45338196100914E-7,1,0.999253354069792,40.0298881530762,1.99106302909433,16.4800030738115,-0.000626122981230628,-0.000161807876820396,0.25,-4.38152539557234E-6,-5.87771358733223E-5,-4.76002122936724E-6,50.0017548,50.0018005,50924.5234375,50984.47265625,52.5074590363709,18.6865808780567,7.9207871,0,0,0,4449,49.99135,50954.498046875,,,,,,,,,,,,,,,,,13.378378,,,,,,50.00177765,,,,
,15762808.805,50.0022812,54917.53515625,-7.01188795542823E-5,5.82302729833296E-7,1,0.999253354069792,40.0298881530762,1.99124030136017,16.4800030738115,-0.00074941224871567,-0.000176923169303354,0.25,-3.74033142965873E-6,-7.00835142004817E-5,-4.19249607529029E-6,50.0022812,50.0022812,54912.49609375,54922.57421875,52.7388210780633,18.6824658696604,7.9603505,0,0,0,4449,49.98565,54917.53515625,,,,,,,,,,,,,,,,,13.378378,,,,,,50.0022812,,,,
,15762885.78,50.0034332,58763.240234375,-8.29295289437364E-5,6.49379605055614E-7,1,0.999253354069792,40.0298881530762,1.99126258138351,16.4700025320053,-0.000889000540150985,-0.000195058523923485,0.25,-3.10680463457012E-6,-8.29052786971721E-5,-3.64214739472515E-6,50.0034332,50.0034332,58760.70703125,58765.7734375,52.7224068791594,18.6834729527115,7.7253218,0,0,0,4449,49.9832,58763.240234375,,,,,,,,,,,,,,,,,13.003003,,,,,,50.0034332,,,,
,15762965.915,50.003521,62769.318359375,-9.3528144191368E-5,6.76376938209318E-7,1,0.999253354069792,40.0298881530762,1.99129582039019,16.4700025320053,-0.00100257381879334,-0.000220988024978368,0.25,-3.59410582828495E-6,-9.35110481990869E-5,-4.19811049534086E-6,50.003521,50.003521,62764.3359375,62774.30078125,52.5996912016402,18.6827784064309,7.9603505,0,0,0,4449,49.98995,62769.318359375,,,,,,,,,,,,,,,,,13.003003,,,,,,50.003521,,,,
,15763047.475,50.0022411,66846.953125,-0.000102734616035283,7.86996974308573E-7,1,0.999253354069792,40.0298881530762,1.99124750162961,16.4700025320053,-0.00110298334850481,-0.000233783378509704,0.25,-3.11653673234365E-6,-0.000102732916901665,-3.77990778776859E-6,50.0021667,50.0023155,66817.09375,66876.8125,52.7700862188325,18.6843420563408,7.8812237,0,0,0,4449,49.9832,66846.953125,,,,,,,,,,,,,,,,,13.378378,,,,,,50.0022411,,,,
,15763125.61,50.00270275,70750.421875,-0.00011323501080659,4.97471280041175E-7,1,0.999253354069792,40.0298881530762,1.99115302907167,16.4800030738115,-0.00121560121317523,-0.000258788093097979,0.25,-3.53702685598749E-6,-0.000113245035843487,-4.26797402814115E-6,50.0025063,50.0028992,70725.46875,70775.375,52.3323742480632,18.6856941057255,7.9603505,0,0,0,4449,49.98705,70750.421875,,,,,,,,,,,,,,,,,12.252253,,,,,,50.00270275,,,,
,15763204.485,50.0032921,74693.0234375,-0.000126773771456549,7.31638076127743E-7,1,0.999253354069792,40.0298881530762,1.99119997725235,16.4700025320053,-0.00136354519274441,-0.000276335024477716,0.25,-2.71689477983742E-6,-0.000126806836409784,-3.5342351943022E-6,50.0031815,50.0034027,74668.0546875,74717.9921875,52.4863550663517,18.6841744517724,7.9603505,0,0,0,4449,49.98225,74693.0234375,,,,,,,,,,,,,,,,,13.753754,,,,,,50.0032921,,,,
,15763281.655,50.0031815,78551.62109375,-0.00014072399205931,8.53128311197282E-7,1,0.999253354069792,40.0298881530762,1.9911937500016,16.4800030738115,-0.00151463320916935,-0.000301861470636486,0.25,-2.56223465263264E-6,-0.000140778600099763,-3.46834041572036E-6,50.0031815,50.0031815,78526.65625,78576.5859375,52.5434139482555,18.6857432145384,8.00031115,0,0,0,4449,49.98035,78551.62109375,,,,,,,,,,,,,,,,,12.252253,,,,,,50.0031815,,,,
,15763363.935,50.0013237,82662.28515625,-0.000151214617415064,9.95202498474345E-7,1,0.999253354069792,40.0298881530762,1.99116821775128,16.4800030738115,-0.001628338178434,-0.0003209044399853,0.25,-2.43168804777743E-6,-0.000151292322936928,-3.4037286552277E-6,50.0013237,50.0013237,82659.7890625,82664.78125,52.656750083544,18.6848021571519,8.0402718,0,0,0,4449,49.9775,82662.28515625,,,,,,,,,,,,,,,,,13.378378,,,,,,50.0013237,,,,
,15763441.02,50.0016136,86515.3984375,-0.000162353939851473,9.81615317860694E-7,1,0.999253354069792,40.0298881530762,1.99108948900762,16.4700025320053,-0.00174563780449394,-0.000359927120222027,0.25,-4.03508856686129E-6,-0.000162445288051169,-5.07801488544672E-6,50.0013466,50.0018806,86483.0546875,86547.7421875,52.6590949691017,18.6871725420249,7.9215777,0,0,0,4449,49.97945,86515.3984375,,,,,,,,,,,,,,,,,13.753754,,,,,,50.0016136,,,,
,15763536.305,50.00175095,89660.4140625,-0.000170941409308698,8.53105778243071E-7,1,0.999253354069792,40.0298881530762,1.99109934960027,16.4800030738115,-0.00184139612712368,-0.000360913740430522,0.25,-2.57623575844405E-6,-0.000171062663826109,-3.67141682308182E-6,50.0016937,50.0018082,89633.296875,89687.53125,52.944389378621,18.6847137108194,8.1209955,0,0,0,4449,49.9773,89660.4140625,,,,,,,,,,,,,,,,,13.003003,,,,,,50.00175095,,,,
,15763614.24,50.0015106,85768.21875,-0.000158764769349881,9.18162033339804E-7,1,0.999253354069792,40.0298881530762,1.9911661417229,16.4700025320053,-0.00171520282715132,-0.00030693143120059,0.25,2.25076186390542E-7,-0.000158877791133018,-7.921677749903E-7,50.0015106,50.0015106,85763.2265625,85773.2109375,52.6739459109671,18.6867668987132,7.8028836,0,0,0,4449,49.9846,85768.21875,,,,,,,,,,,,,,,,,12.252253,,,,,,50.0015106,,,,
,15763693.835,50.0018616,81789.92578125,-0.000147337802206687,9.29208948223047E-7,1,0.999253354069792,40.0298881530762,1.99112350182651,16.4800030738115,-0.00158035632377441,-0.000346823690866829,0.25,-5.53218513558117E-6,-0.000147389695626879,-6.48150587101745E-6,50.0018616,50.0018616,81784.953125,81794.8984375,52.4355492126017,18.6878500131062,7.9215777,0,0,0,4449,49.9775,81789.92578125,,,,,,,,,,,,,,,,,12.252253,,,,,,50.0018616,,,,
,15763771.055,50.0025654,77929.24609375,-0.000135405667127115,1.07748981121342E-6,1,0.999253354069792,40.0298881530762,1.99103893879251,16.4800030738115,-0.00145427995835641,-0.000306937069147003,0.25,-3.99421596817593E-6,-0.000135446012058553,-4.86699674373445E-6,50.0025597,50.0025711,77901.8828125,77956.609375,52.5731158319863,18.6881715549428,8.08063365,0,0,0,4449,49.97895,77929.24609375,,,,,,,,,,,,,,,,,13.378378,,,,,,50.0025654,,,,
,15763851.68,50.0023918,73898.5859375,-0.000125405383216678,9.26777175941055E-7,1,0.999253354069792,40.0298881530762,1.99110984318509,16.4800030738115,-0.00134991054576796,-0.000266827450233764,0.25,-2.08469002572533E-6,-0.000125438893247608,-2.89314557126746E-6,50.0023918,50.0023918,73893.578125,73903.59375,52.7700862188325,18.6862918341601,8.00031115,0,0,0,4449,49.9715,73898.5859375,,,,,,,,,,,,,,,,,13.378378,,,,,,50.0023918,,,,
,15763932.835,50.0021324,69843.35546875,-0.000112254439321616,8.14637428025719E-7,1,0.999253354069792,40.0298881530762,1.99107421178503,16.4700025320053,-0.00120410719739794,-0.000261456962780671,0.25,-3.96255868111441E-6,-0.000112258326081783,-4.68737640825544E-6,50.0021057,50.0021591,69810.9375,69875.7734375,52.5699893179094,18.6872325140889,8.1209955,0,0,0,4449,49.9775,69843.35546875,,,,,,,,,,,,,,,,,12.252253,,,,,,50.0021324,,,,
,15764013.69,50.0011101,65804.71875,-0.00010189283595083,6.54228879065219E-7,1,0.999253354069792,40.0298881530762,1.99120255740862,16.4800030738115,-0.00109681967569719,-0.000215607147988495,0.25,-1.58564625587444E-6,-0.000101897601885587,-2.24339068525137E-6,50.0011101,50.0011101,65802.2890625,65807.1484375,52.5230916067556,18.6868886643593,8.0402718,0,0,0,4449,49.97255,65804.71875,,,,,,,,,,,,,,,,,12.627627,,,,,,50.0011101,,,,
,15764091.725,50.00141335,61901.61328125,-8.78257543932222E-5,6.56416125416443E-7,1,0.999253354069792,40.0298881530762,1.9910771287321,16.4700025320053,-0.000943307277952817,-0.000196485276691797,0.25,-2.35556808840156E-6,-8.7813695256291E-5,-2.92266827466232E-6,50.0012512,50.0015755,61869.2265625,61934,53.1546474502941,18.6872023125447,8.1209955,0,0,0,4449,49.97035,61901.61328125,,,,,,,,,,,,,,,,,13.378378,,,,,,50.00141335,,,,
,15764172.565,50.00069045,57862.947265625,-7.85992632875987E-5,6.31373424301684E-7,1,0.999253354069792,40.0298881530762,1.99122289065822,16.4800030738115,-0.000842411594951873,-0.000185581559167948,0.25,-3.0109798994982E-6,-7.8573659306456E-5,-3.51829142372342E-6,50.0005684,50.0008125,57830.6328125,57895.26171875,52.6028177157171,18.6864879999845,8.08063365,0,0,0,4449,49.9745,57862.947265625,,,,,,,,,,,,,,,,,12.252253,,,,,,50.00069045,,,,
,15764253.275,50.0013542,53827.927734375,-6.67019751584931E-5,6.19539844720582E-7,1,0.999253354069792,40.0298881530762,1.99111396313055,16.4800030738115,-0.000715463940880349,-0.000153666251564602,0.25,-2.2032482376862E-6,-6.66747428870024E-5,-2.63348751156502E-6,50.0011024,50.001606,53797.890625,53857.96484375,52.4832285522748,18.6891903831073,8.08063365,0,0,0,4449,49.9706,53827.927734375,,,,,,,,,,,,,,,,,13.003003,,,,,,50.0013542,,,,
,15764331.835,50.0013485,49902.16796875,-5.41765246888606E-5,5.66857383444125E-7,1,0.999253354069792,40.0298881530762,1.99117293432603,16.4800030738115,-0.000577566967575473,-0.000144175225397553,0.25,-3.58534881866062E-6,-5.41367428013226E-5,-3.93389520210211E-6,50.0013428,50.0013542,49869.69140625,49934.64453125,52.5074590363709,18.6887793278833,7.8812237,0,0,0,4449,49.9728,49902.16796875,,,,,,,,,,,,,,,,,13.003003,,,,,,50.0013485,,,,
,15764409.96,50.00162315,45996.576171875,-4.39012330403163E-5,4.86205531456437E-7,1,0.999253354069792,40.0298881530762,1.99113099342066,16.4700025320053,-0.000467810867245731,-0.000117649818222355,0.25,-2.98290439961621E-6,-4.38635332095639E-5,-3.26477322375412E-6,50.0016098,50.0016365,45966.58203125,46026.5703125,52.6286114568517,18.6899860560042,8.1209955,0,0,0,4449,49.9686,45996.576171875,,,,,,,,,,,,,,,,,12.252253,,,,,,50.00162315,,,,
,15764491.545,50.0005417,41920.81640625,-3.180431235009E-5,5.35144899790873E-7,1,0.999253354069792,40.0298881530762,1.99108471362573,16.4700025320053,-0.000337702006784014,-9.16306945501956E-5,0.25,-2.7555134622918E-6,-3.17694274579288E-5,-2.95891243053218E-6,50.0005417,50.0005417,41913.3203125,41928.3125,52.5066774078517,18.6895819318571,8.1209955,0,0,0,4449,49.9642,41920.81640625,,,,,,,,,,,,,,,,,12.252253,,,,,,50.0005417,,,,
,15764569.54,50.0004349,38019.99609375,-2.02248920436287E-5,5.37501531486801E-7,1,0.999253354069792,40.0298881530762,1.99114720439524,16.4800030738115,-0.000211960597415606,-7.36317483917782E-5,0.25,-3.17714630307713E-6,-2.01913592547002E-5,-3.30520766865813E-6,50.0004349,50.0004349,38014.93359375,38025.05859375,52.4769755241209,18.6897485866787,8.0402718,0,0,0,4449,49.9749,38019.99609375,,,,,,,,,,,,,,,,,13.003003,,,,,,50.0004349,,,,
,15764647.26,50.001112,34137.0703125,-1.05464273091321E-5,4.2986736339182E-7,1,0.999253354069792,40.0298881530762,1.99107680516062,16.4700025320053,-0.000108599947240742,-4.89902973659601E-5,0.25,-2.63975746946697E-6,-1.05214611047831E-5,-2.7054908141807E-6,50.0010605,50.0011635,34132.15625,34141.984375,52.5512302334479,18.6926664828776,8.0011096,0,0,0,4449,49.968,34137.0703125,,,,,,,,,,,,,,,,,13.753754,,,,,,50.001112,,,,
,15764726.945,50.0000954,30154.162109375,-1.46211498375881E-7,4.41181599030757E-8,1,0.999253354069792,40.0298881530762,1.99128003677966,16.4700025320053,3.93041317920502E-6,-3.08081586071945E-5,0.25,-2.83039763490187E-6,-1.27940283103523E-7,-2.82887003810218E-6,50.0000954,50.0000954,30154.162109375,30154.162109375,52.7403843351017,18.6888014700236,8.2025299,0,0,0,4449,49.9712,30154.162109375,,,,,,,,,,,,,,,,,12.252253,,,,,,50.0000954,,,,
,15764806.045,50.00095175,26198.15234375,1.06057556968538E-5,2.98394251288173E-7,1,0.999253354069792,40.0298881530762,1.99131298640367,16.4800030738115,0.000119854167606627,-9.79782907143273E-6,0.25,-2.82199573335721E-6,1.06133883576484E-5,-2.75139101924849E-6,50.0008888,50.0010147,26175.52734375,26220.77734375,53.2625121859479,18.6899128523092,8.0011096,0,0,0,4449,49.96655,26198.15234375,,,,,,,,,,,,,,,,,13.003003,,,,,,50.00095175,,,,
,15764887.04,50.0007744,22149.970703125,2.11205451321495E-5,3.58080064827766E-7,1,0.999253354069792,40.0298881530762,1.99110692381736,16.4800030738115,0.000233261241961489,1.02549923314216E-5,0.25,-2.85880493343311E-6,2.11157558546574E-5,-2.72094101094613E-6,50.0007744,50.0007744,22147.380859375,22152.560546875,52.9537689208517,18.6915674968971,8.1209955,0,0,0,4449,49.9744,22149.970703125,,,,,,,,,,,,,,,,,13.378378,,,,,,50.0007744,,,,
,15764963.595,50.0006752,18327.703125,3.11560474785055E-5,2.77414444851659E-7,1,0.999253354069792,40.0298881530762,1.99113358914175,16.4800030738115,0.000341176265265478,3.11353804888945E-5,0.25,-2.73159050158828E-6,3.11362234524975E-5,-2.53008903641785E-6,50.0006752,50.0006752,18325.353515625,18330.052734375,52.9217221515633,18.6924975027486,8.1209955,0,0,0,4449,49.9678,18327.703125,,,,,,,,,,,,,,,,,13.378378,,,,,,50.0006752,,,,
,15765040.92,50.00024415,14459.306640625,4.07485384691979E-5,2.70035317014349E-7,1,0.999253354069792,40.0298881530762,1.9912934499888,16.4700025320053,0.000443554773473814,5.54310331442294E-5,0.25,-2.20725503317858E-6,4.07098208754397E-5,-1.94586074825815E-6,50.0002213,50.000267,14426.8720703125,14491.7412109375,53.0717948272556,18.6896105585858,8.0418768,0,0,0,4449,49.96835,14459.306640625,,,,,,,,,,,,,,,,,13.003003,,,,,,50.00024415,,,,
,15765121.075,50.0007629,10453.748046875,5.07421075017208E-5,2.87441267820712E-7,1,0.999253354069792,40.0298881530762,1.9911207649839,16.4700025320053,0.000551793692787908,7.14591837268986E-5,0.25,-2.52061834551411E-6,5.06872794895348E-5,-2.19616906166392E-6,50.0007629,50.0007629,10448.7099609375,10458.7861328125,52.6661296257748,18.6917278868104,8.1617627,0,0,0,4449,49.9618,10453.748046875,,,,,,,,,,,,,,,,,13.378378,,,,,,50.0007629,,,,
,15765198.76,50.00056075,6570.21704101562,5.9707135883182E-5,2.15812018870367E-7,1,0.999253354069792,40.0298881530762,1.99104865805893,16.4700025320053,0.000647663846461383,9.26110082450407E-5,0.25,-2.17268593501735E-6,5.96322744549041E-5,-1.79295480300269E-6,50.0004883,50.0006332,6540.19921875,6600.23486328125,53.0194257164671,18.6946716080636,8.1617627,0,0,0,4449,49.965,6570.21704101562,,,,,,,,,,,,,,,,,13.753754,,,,,,50.00056075,,,,
,15765277.12,50.0004654,2653.8828125,6.61577814076192E-5,2.5963912095841E-7,1,0.999253354069792,40.0298881530762,1.99119850155062,16.4700025320053,0.000717377840931142,0.000104011534203498,0.25,-2.27671835697802E-6,6.60687129903736E-5,-1.85716823239315E-6,50.0004044,50.0005264,2626.08349609375,2681.68212890625,52.9154691234094,18.6904188953096,8.040673,0,0,0,4449,49.9676,2653.8828125,,,,,,,,,,,,,,,,,13.378378,,,,,,50.0004654,,,,
,15765354.01,49.99907305,-1185.5810546875,5.7890797970053E-5,2.7326052869621E-7,1,0.999253354069792,40.0298881530762,1.99111168121154,16.4800030738115,0.000627888797554457,8.99240965005283E-5,0.25,-2.09249773905647E-6,5.78120010771695E-5,-1.72551241565711E-6,49.9989624,49.9991837,-1215.42224121094,-1155.73986816406,52.2901663080248,18.6917366517423,8.040673,0,0,0,4449,49.9672,-1185.5810546875,,,,,,,,,,,,,,,,,12.252253,,,,,,49.99907305,,,,
,15765432.995,50.0000076,-5131.7685546875,5.82355042998021E-5,2.93819022676838E-7,1,0.999253354069792,40.0298881530762,1.99119699489206,16.4800030738115,0.000631106613684451,9.37673601310604E-5,0.25,-1.79999724886637E-6,5.81587411618085E-5,-1.43042982717114E-6,49.9999275,50.0000877,-5161.8544921875,-5101.6826171875,53.0108278027556,18.6920033411443,8.1209955,0,0,0,4449,49.96945,-5131.7685546875,,,,,,,,,,,,,,,,,13.003003,,,,,,50.0000076,,,,
,15765509.955,50.00045205,-8980.77587890625,6.17138025791387E-5,2.89411828914853E-7,1,0.999253354069792,40.0298881530762,1.99113240890658,16.4800030738115,0.000668278778607826,0.000102477140421799,0.25,-1.62064665794777E-6,6.16359341406415E-5,-1.22842979866607E-6,50.0004044,50.0004997,-9010.9306640625,-8950.62109375,52.670037768371,18.6931463468601,8.1617627,0,0,0,4449,49.9678,-8980.77587890625,,,,,,,,,,,,,,,,,13.753754,,,,,,50.00045205,,,,
,15765590.895,50.0008125,-13026.009765625,5.78365914726208E-5,2.91286167760021E-7,1,0.999253354069792,40.0298881530762,1.9912435087609,16.4800030738115,0.000626319139317473,9.64354827641603E-5,0.25,-1.48449297354058E-6,5.77690508816849E-5,-1.11596756972698E-6,50.0008125,50.0008125,-13028.453125,-13023.56640625,52.8029146166402,18.6936580241365,8.2025299,0,0,0,4449,49.9663,-13026.009765625,,,,,,,,,,,,,,,,,13.753754,,,,,,50.0008125,,,,
,15765670.29,49.999485,-16994.392578125,4.66742136850053E-5,3.67343971690466E-7,1,0.999253354069792,40.0298881530762,1.99136282578927,16.4700025320053,0.000507202171901669,6.8513762942019E-5,0.25,-2.06354005543637E-6,4.66299737545445E-5,-1.76431110870107E-6,49.999485,49.999485,-17001.767578125,-16987.017578125,53.1671535066018,18.6917541597956,8.2025299,0,0,0,4449,49.96805,-16994.392578125,,,,,,,,,,,,,,,,,12.252253,,,,,,49.999485,,,,
,15765748,50.0004997,-20876.5224609375,3.10439338648195E-5,3.38750090782179E-7,1,0.999253354069792,40.0298881530762,1.99141717451088,16.4700025320053,0.000338458508802155,3.96726782601516E-5,0.25,-1.92050358501428E-6,3.10212059205635E-5,-1.72046178361168E-6,50.0004997,50.0004997,-20883.93359375,-20869.111328125,53.1929472477364,18.6904683923688,8.2025299,0,0,0,4449,49.968,-20876.5224609375,,,,,,,,,,,,,,,,,12.252253,,,,,,50.0004997,,,,
,15765824.775,50.001297,-24712.1279296875,1.89795977450106E-5,3.58314230600064E-7,1,0.999253354069792,40.0298881530762,1.99128050373693,16.4800030738115,0.000206686551749089,2.56301509430629E-5,0.25,-1.0470019288488E-6,1.89668632875092E-5,-9.24650832029831E-7,50.0012512,50.0013428,-24747.0859375,-24677.169921875,52.6950498809863,18.6914529288586,8.1209955,0,0,0,4449,49.96495,-24712.1279296875,,,,,,,,,,,,,,,,,13.003003,,,,,,50.001297,,,,
,15765902.18,50.0008831,-28585.240234375,1.47179946972238E-5,3.87802178226967E-7,1,0.999253354069792,40.0298881530762,1.99121878600579,16.4700025320053,0.000160372666545714,1.94223270554929E-5,0.25,-8.54268160744494E-7,1.47099836730943E-5,-7.59220978486306E-7,50.0008278,50.0009384,-28615.123046875,-28555.357421875,53.1335434802748,18.69394217909,8.040673,0,0,0,4449,49.9664,-28585.240234375,,,,,,,,,,,,,,,,,13.378378,,,,,,50.0008831,,,,
,15765979.505,50.00133895,-32446.0205078125,1.73299770302462E-5,4.99492106839206E-7,1,0.999253354069792,40.0298881530762,1.99129320308499,16.4700025320053,0.000188779446781477,2.33246282335572E-5,0.25,-9.64163793514073E-7,1.73221636783093E-5,-8.52166320156167E-7,50.0013008,50.0013771,-32478.66015625,-32413.380859375,53.0178624594287,18.6940740509701,8.0814402,0,0,0,4449,49.9662,-32446.0205078125,,,,,,,,,,,,,,,,,13.378378,,,,,,50.00133895,,,,
,15766057.405,50.0005722,-36340.7265625,2.39773870269291E-5,5.19738548090471E-7,1,0.999253354069792,40.0298881530762,1.9912424804707,16.4800030738115,0.000260145820508064,3.81921264014444E-5,0.25,-7.85578531080278E-7,2.39656836508693E-5,-6.30880840843057E-7,50.0004463,50.0006981,-36370.7578125,-36310.6953125,53.1866942195826,18.6931103799971,8.1209955,0,0,0,4449,49.9621,-36340.7265625,,,,,,,,,,,,,,,,,13.378378,,,,,,50.0005722,,,,
,15766135.5,50.00188825,-40243.365234375,3.1611184660089E-5,4.40316695456683E-7,1,0.999253354069792,40.0298881530762,1.99125612298241,16.4700025320053,0.00034487862472929,4.00042238031306E-5,0.25,-1.9957481817556E-6,3.16054756236213E-5,-1.79104877495993E-6,50.001873,50.0019035,-40268.3984375,-40218.33203125,52.9131242378518,18.6940457929128,8.040673,0,0,0,4449,49.9631,-40243.365234375,,,,,,,,,,,,,,,,,13.003003,,,,,,50.00188825,,,,
,15766214.78,50.0007744,-44203.517578125,4.1605323863764E-5,5.87873385583532E-7,1,0.999253354069792,40.0298881530762,1.99133285137544,16.4700025320053,0.00045103654143383,6.89879690673108E-5,0.25,-1.1135653351014E-6,4.15927936304307E-5,-8.44842650408099E-7,50.0006371,50.0009117,-44231.05078125,-44175.984375,52.8013513596017,18.6944919087462,8.040673,0,0,0,4449,49.96245,-44203.517578125,,,,,,,,,,,,,,,,,13.378378,,,,,,50.0007744,,,,
,15766293.96,50.0012512,-48161.421875,5.18719526341225E-5,4.80132375664639E-7,1,0.999253354069792,40.0298881530762,1.991278145487,16.4700025320053,0.000562514707438058,8.52990642450682E-5,0.25,-1.4553486059798E-6,5.18626569279799E-5,-1.12015271223591E-6,50.0012512,50.0012512,-48163.96484375,-48158.87890625,52.7356945639863,18.6939707955952,8.2025299,0,0,0,4449,49.9614,-48161.421875,,,,,,,,,,,,,,,,,13.003003,,,,,,50.0012512,,,,
,15766372.44,50.00115775,-52084.173828125,6.24494929541037E-5,4.55736434558096E-7,1,0.999253354069792,40.0298881530762,1.99124670952349,16.4700025320053,0.000676517797250039,0.000106967533687917,0.25,-1.35710527035322E-6,6.2442832160503E-5,-9.53622324223164E-7,50.001152,50.0011635,-52111.6953125,-52056.65234375,53.178096305871,18.6933951094033,8.0814402,0,0,0,4449,49.9633,-52084.173828125,,,,,,,,,,,,,,,,,13.003003,,,,,,50.00115775,,,,
,15766452.235,50.0014477,-56071.70703125,7.46882752967074E-5,6.25422944364864E-7,1,0.999253354069792,40.0298881530762,1.99127851374905,16.4800030738115,0.000808105427717587,0.000134039087449991,0.25,-1.05867749200934E-6,7.46851187734658E-5,-5.76251738754323E-7,50.0014267,50.0014687,-56074.234375,-56069.1796875,52.8888937537556,18.6934349114279,8.0814402,0,0,0,4449,49.95815,-56071.70703125,,,,,,,,,,,,,,,,,13.753754,,,,,,50.0014477,,,,
,15766530.985,50.001152,-60007.21484375,8.65366163429162E-5,6.5199990784934E-7,1,0.999253354069792,40.0298881530762,1.99146114213735,16.4700025320053,0.000935905781827598,0.000158559468603456,0.25,-9.27693179756522E-7,8.65408169622605E-5,-3.68905125318515E-7,50.001152,50.001152,-60007.21484375,-60007.21484375,52.7099008228517,18.6924844250929,7.9603505,0,0,0,4449,49.9601,-60007.21484375,,,,,,,,,,,,,,,,,12.252253,,,,,,50.001152,,,,
,15766611.36,50.0003929,-64025.408203125,9.79769374559294E-5,6.12945528668903E-7,1,0.999253354069792,40.0298881530762,1.9913164334771,16.4800030738115,0.00106006485971681,0.000177409068899589,0.25,-1.24646893037398E-6,9.79940901499844E-5,-6.14167675820868E-7,50.0003929,50.0003929,-64030.69140625,-64020.125,52.7356945639863,18.695086277482,7.9603505,0,0,0,4449,49.9567,-64025.408203125,,,,,,,,,,,,,,,,,13.378378,,,,,,50.0003929,,,,
,15766690.13,50.000412,-67962.86328125,0.00010928925015538,7.00641113025832E-7,1,0.999253354069792,40.0298881530762,1.9913725625107,16.4700025320053,0.00117877437855155,0.000219241073692516,0.25,5.85023875280066E-7,0.000109307820053269,1.29012294636793E-6,50.000412,50.000412,-67967.8515625,-67957.875,52.7560169054864,18.6948294785056,8.2025299,0,0,0,4449,49.95675,-67962.86328125,,,,,,,,,,,,,,,,,13.378378,,,,,,50.000412,,,,
,15766771.01,50.0008583,-72003.05859375,0.00012145366591056,6.24117394295753E-7,1,0.999253354069792,40.0298881530762,1.99137366772689,16.4700025320053,0.00130936982328018,0.000247875789922244,0.25,1.04035158070278E-6,0.000121485718660402,1.82336490403352E-6,50.0008583,50.0008583,-72010.7421875,-71995.375,53.0889906546787,18.6963358952371,8.2025299,0,0,0,4449,49.9616,-72003.05859375,,,,,,,,,,,,,,,,,13.378378,,,,,,50.0008583,,,,
,15766851.89,50.0013313,-76045.42578125,0.000134010259337499,7.66630318403409E-7,1,0.999253354069792,40.0298881530762,1.99127744886333,16.4700025320053,0.00144705693472544,0.000261214649174669,0.25,9.44863235706878E-9,0.000134067996589593,8.71959894572537E-7,50.0013313,50.0013313,-76048.0390625,-76042.8125,52.9600219490056,18.6952920379654,8.1209955,0,0,0,4449,49.9597,-76045.42578125,,,,,,,,,,,,,,,,,12.252253,,,,,,50.0013313,,,,
,15766930.74,50.0006981,-79985.27734375,0.000143916745275684,8.3356463353221E-7,1,0.999253354069792,40.0298881530762,1.99138220653879,16.4700025320053,0.00155263439152707,0.000289656198083095,0.25,8.53073690109821E-7,0.000143988973120245,1.77839462107525E-6,50.0005264,50.0008698,-80015.28125,-79955.2734375,52.9991033749671,18.6933487814058,8.0814402,0,0,0,4449,49.9594,-79985.27734375,,,,,,,,,,,,,,,,,13.378378,,,,,,50.0006981,,,,
,15767011.11,50.0010071,-84000.84765625,0.00015841737231257,7.17546516348872E-7,1,0.999253354069792,40.0298881530762,1.99132750193105,16.4700025320053,0.00171185068249224,0.000304259898897049,0.25,-4.1146651403081E-7,0.000158522822737003,6.04464377827404E-7,50.0010071,50.0010071,-84003.265625,-83998.4296875,53.0311501442556,18.6964233048027,8.1209955,0,0,0,4449,49.9564,-84000.84765625,,,,,,,,,,,,,,,,,13.378378,,,,,,50.0010071,,,,
,15767092.205,50.0006638,-88056.0390625,0.000169985370594341,8.72335331239253E-7,1,0.999253354069792,40.0298881530762,1.99127458252877,16.4800030738115,0.00183709234539001,0.000326048386057577,0.25,-4.81372344200636E-7,0.000170117499317598,6.06336453530215E-7,50.0006638,50.0006638,-88056.0390625,-88056.0390625,53.2804896418903,18.6952837351897,8.202939,0,0,0,4449,49.9597,-88056.0390625,,,,,,,,,,,,,,,,,13.378378,,,,,,50.0006638,,,,
,15767184.555,49.99971775,-88228.48828125,0.000170317037001729,9.60172496402423E-7,1,0.999253354069792,40.0298881530762,1.99128666425174,16.4700025320053,0.00183869902947782,0.000337754881412842,0.25,5.4233193904294E-7,0.000170443628148521,1.63284172618367E-6,49.9996758,49.9997597,-88256.015625,-88200.9609375,52.8709162978133,18.6980123068062,8.2025299,0,0,0,4449,49.95895,-88228.48828125,,,,,,,,,,,,,,,,,12.627627,,,,,,49.99971775,,,,
,15767263.575,50.0002441,-84281.29296875,0.000158894232535526,6.70511585801782E-7,1,0.999253354069792,40.0298881530762,1.99145292139837,16.4700025320053,0.00171829313628477,0.000298684560783878,0.25,-1.01539602267169E-6,0.000159005046258285,3.0572290450749E-9,50.0002441,50.0002441,-84313.7890625,-84248.796875,52.8888937537556,18.6935511015595,8.040673,0,0,0,4449,49.9555,-84281.29296875,,,,,,,,,,,,,,,,,13.753754,,,,,,50.0002441,,,,
,15767343.17,50.0011215,-80301.046875,0.000146260771960095,8.28953128537773E-7,1,0.999253354069792,40.0298881530762,1.9913214760999,16.4700025320053,0.00157939945075432,0.000285995002213248,0.25,9.1820240338292E-8,0.000146340217423886,1.03168933553366E-6,50.0011215,50.0011215,-80305.984375,-80296.109375,53.1382332513902,18.695268927204,8.2848825,0,0,0,4449,49.9529,-80301.046875,,,,,,,,,,,,,,,,,13.003003,,,,,,50.0011215,,,,
,15767420.86,50.0004463,-76418.61328125,0.000132672113771921,8.09569701887206E-7,1,0.999253354069792,40.0298881530762,1.99123475789292,16.4800030738115,0.00143598629325474,0.000239796636488422,0.25,-1.73222062192169E-6,0.000132741799337049,-8.79198374847206E-7,50.0004463,50.0004463,-76423.6796875,-76413.546875,52.8849856111594,18.6944656449544,8.2025299,0,0,0,4449,49.9578,-76418.61328125,,,,,,,,,,,,,,,,,12.252253,,,,,,50.0004463,,,,
,15767499.18,50.0007095,-72505.75390625,0.00012232549677349,6.15855336373948E-7,1,0.999253354069792,40.0298881530762,1.99123872693747,16.4700025320053,0.00132483220858845,0.000215659170072025,0.25,-2.09953452128392E-6,0.000122379489146354,-1.31202195346456E-6,50.0005836,50.0008354,-72535.703125,-72475.8046875,53.2414082159287,18.697628143976,8.2025299,0,0,0,4449,49.9512,-72505.75390625,,,,,,,,,,,,,,,,,13.378378,,,,,,50.0007095,,,,
,15767577.39,50.00046155,-68598.3984375,0.000110128366801026,7.84756365508977E-7,1,0.999253354069792,40.0298881530762,1.99131484692699,16.4800030738115,0.00119319201050272,0.00019112246311947,0.25,-2.17061336158244E-6,0.000110166914899785,-1.46080151904712E-6,50.00037,50.0005531,-68628.265625,-68568.53125,53.1468311651018,18.6953045032393,8.12140085,0,0,0,4449,49.95905,-68598.3984375,,,,,,,,,,,,,,,,,13.378378,,,,,,50.00046155,,,,
,15767656.71,49.9999523,-64632.671875,9.75002782046176E-5,7.35390338278627E-7,1,0.999253354069792,40.0298881530762,1.99124178525808,16.4800030738115,0.00105530321924707,0.000174244310627782,0.25,-1.45327029012252E-6,9.75203950949067E-5,-8.24140306587187E-7,49.9998932,50.0000114,-64634.98828125,-64630.35546875,52.9475158926979,18.6937255000072,8.2848825,0,0,0,4449,49.9564,-64632.671875,,,,,,,,,,,,,,,,,13.378378,,,,,,49.9999523,,,,
,15767735.49,49.9997692,-60697.658203125,8.73613294148092E-5,6.88363211339386E-7,1,0.999253354069792,40.0298881530762,1.99111620606658,16.4700025320053,0.000944362536345905,0.000161854232518718,0.25,-7.69094026262243E-7,8.73661321771146E-5,-2.05019232182168E-7,49.9996109,49.9999275,-60732.640625,-60662.67578125,52.6841070817171,18.6957068951771,8.2437062,0,0,0,4449,49.9564,-60697.658203125,,,,,,,,,,,,,,,,,13.378378,,,,,,49.9997692,,,,
,15767813.92,50.0006866,-56776.9296875,7.50671851738075E-5,4.27323442494055E-7,1,0.999253354069792,40.0298881530762,1.99104192790655,16.4700025320053,0.000811769353069117,0.000136704276588183,0.25,-8.78924819499463E-7,7.50642730419182E-5,-3.94086350773896E-7,50.0006866,50.0006866,-56779.33984375,-56774.51953125,52.8201104440633,18.6983478491132,8.2848825,0,0,0,4449,49.95485,-56776.9296875,,,,,,,,,,,,,,,,,13.003003,,,,,,50.0006866,,,,
,15767891.43,49.99993515,-52902.10546875,6.5450703123344E-5,5.41589200267427E-7,1,0.999253354069792,40.0298881530762,1.99135902590594,16.4700025320053,0.000708519732296204,0.000115240980455983,0.25,-1.13283298272255E-6,6.54433137728762E-5,-7.1002378453352E-7,49.9998283,50.000042,-52932.140625,-52872.0703125,53.1194741669287,18.6927687927341,8.12140085,0,0,0,4449,49.9586,-52902.10546875,,,,,,,,,,,,,,,,,12.252253,,,,,,49.99993515,,,,
,15767971.715,49.9999142,-48889.36328125,5.24790586188952E-5,6.15118890974602E-7,1,0.999253354069792,40.0298881530762,1.99130335209725,16.4800030738115,0.000568018611075398,9.23810958169799E-5,0.25,-9.08836406691669E-7,5.24670204132844E-5,-5.69897727604709E-7,49.9998627,49.9999657,-48919.453125,-48859.2734375,52.8709162978133,18.6934067396719,8.2437062,0,0,0,4449,49.9543,-48889.36328125,,,,,,,,,,,,,,,,,13.378378,,,,,,49.9999142,,,,
,15768052.545,50.0008068,-44852.021484375,4.20044058435816E-5,5.8960221350464E-7,1,0.999253354069792,40.0298881530762,1.99126480812178,16.4800030738115,0.000456263307871894,6.46227433195557E-5,0.25,-1.59014424456141E-6,4.19955039277081E-5,-1.31860847552605E-6,50.0007057,50.0009079,-44857.078125,-44846.96484375,52.7591434195633,18.6914880339276,8.2848825,0,0,0,4449,49.959,-44852.021484375,,,,,,,,,,,,,,,,,13.378378,,,,,,50.0008068,,,,
,15768129.5,49.99952125,-41006.625,3.04126479900404E-5,4.59801924119071E-7,1,0.999253354069792,40.0298881530762,1.99136087221516,16.4800030738115,0.000329496874982408,5.13950335979241E-5,0.25,-7.23879369176393E-7,3.04000532429103E-5,-5.27612667648054E-7,49.9993782,49.9996643,-41009.08203125,-41004.16796875,52.5504486049286,18.6892440039763,8.2848825,0,0,0,4449,49.95505,-41006.625,,,,,,,,,,,,,,,,,13.003003,,,,,,49.99952125,,,,
,15768211.07,49.9997883,-36928.01953125,1.984020091485E-5,4.76007841516538E-7,1,0.999253354069792,40.0298881530762,1.99124260815067,16.4800030738115,0.000217377233236568,1.988023040828E-5,0.25,-1.73687705078763E-6,1.98377916168079E-5,-1.60811072601064E-6,49.9997025,49.9998741,-36955.53515625,-36900.50390625,52.6856703387556,18.6919974527745,8.16257715,0,0,0,4449,49.95365,-36928.01953125,,,,,,,,,,,,,,,,,13.378378,,,,,,49.9997883,,,,
,15768290.515,49.9996071,-32958.087890625,9.50353905393492E-6,3.73102676470809E-7,1,0.999253354069792,40.0298881530762,1.99133720924449,16.4700025320053,0.000106139503306918,-1.68370009138961E-6,0.25,-1.8708545219885E-6,9.50799153096694E-6,-1.80836271750033E-6,49.9996071,49.9996071,-32963.046875,-32953.12890625,53.2038900470056,18.6906565369007,8.2848825,0,0,0,4449,49.9602,-32958.087890625,,,,,,,,,,,,,,,,,13.753754,,,,,,49.9996071,,,,
,15768372.305,49.9996719,-28869.9111328125,-2.0000417600477E-6,6.35481201297201E-7,1,0.999253354069792,40.0298881530762,1.99128264930461,16.4800030738115,-1.89168831972482E-5,-1.85860552324964E-5,0.25,-1.3626677609343E-6,-1.98949119463407E-6,-1.37423724186566E-6,49.9996719,49.9996719,-28874.978515625,-28864.84375,53.0381848009287,18.6891200346965,8.16257715,0,0,0,4449,49.9561,-28869.9111328125,,,,,,,,,,,,,,,,,12.252253,,,,,,49.9996719,,,,
,15768451.28,49.9997139,-24924.3955078125,-1.32657340099931E-5,3.31918947508406E-7,1,0.999253354069792,40.0298881530762,1.99128714022687,16.4700025320053,-0.000140054278226224,-4.23570478556028E-5,0.25,-1.53505203660667E-6,-1.32423883909301E-5,-1.61825961525072E-6,49.9997139,49.9997139,-24926.90234375,-24921.888671875,53.2242123885056,18.6887848365449,8.2848825,0,0,0,4449,49.9556,-24924.3955078125,,,,,,,,,,,,,,,,,13.003003,,,,,,49.9997139,,,,
,15768528.925,49.9996948,-21041.37890625,-2.21241736255293E-5,2.96050564782003E-7,1,0.999253354069792,40.0298881530762,1.9913593894432,16.4700025320053,-0.000236128373184513,-5.64090844823862E-5,0.25,-1.24087042486051E-6,-2.20913569875386E-5,-1.38049847326828E-6,49.9996109,49.9997787,-21068.751953125,-21014.005859375,52.7161538510056,18.6894068899819,8.2025299,0,0,0,4449,49.9554,-21041.37890625,,,,,,,,,,,,,,,,,13.753754,,,,,,49.9996948,,,,
,15768609.57,49.9990444,-17011.3359375,-3.28930417756116E-5,3.92920020408827E-7,1,0.999253354069792,40.0298881530762,1.99118402236706,16.4700025320053,-0.000350451193698784,-8.6875078192764E-5,0.25,-2.12604201763599E-6,-3.28389945230434E-5,-2.33249256390165E-6,49.9988708,49.999218,-17041.365234375,-16981.306640625,52.944389378621,18.6936614141356,8.2848825,0,0,0,4449,49.9553,-17011.3359375,,,,,,,,,,,,,,,,,13.753754,,,,,,49.9990444,,,,
,15768687.75,49.99827005,-13105.583984375,-4.32900798165269E-5,3.59857935766078E-7,1,0.999253354069792,40.0298881530762,1.9912344611123,16.4700025320053,-0.000462605224055045,-0.000106477890093754,0.25,-2.07069926477874E-6,-4.32193174898215E-5,-2.34229249916977E-6,49.9982109,49.9983292,-13133.0439453125,-13078.1240234375,53.0100461742364,18.6923320536262,8.2848825,0,0,0,4449,49.95645,-13105.583984375,,,,,,,,,,,,,,,,,13.003003,,,,,,49.99827005,,,,
,15768764.415,49.99931525,-9272.89111328125,-5.2781070057591E-5,2.96323713704422E-7,1,0.999253354069792,40.0298881530762,1.9913523197791,16.4800030738115,-0.000564419482419905,-0.000127530869923954,0.25,-2.31350082435908E-6,-5.26912816090158E-5,-2.64371149188543E-6,49.9992714,49.9993591,-9300.3349609375,-9245.447265625,52.7067743087748,18.6881740060608,8.28529595,0,0,0,4449,49.957,-9272.89111328125,,,,,,,,,,,,,,,,,13.003003,,,,,,49.99931525,,,,
,15768843.28,49.99986265,-5331.7060546875,-6.1613388064382E-5,2.34662775444864E-7,1,0.999253354069792,40.0298881530762,1.99121247406993,16.4700025320053,-0.000659842437362019,-0.000142886874552935,0.25,-2.14858950353271E-6,-6.15066746558366E-5,-2.53347041084479E-6,49.9998283,49.999897,-5361.5283203125,-5301.8837890625,52.9146874948902,18.6891132638716,8.16257715,0,0,0,4449,49.95775,-5331.7060546875,,,,,,,,,,,,,,,,,12.252253,,,,,,49.99986265,,,,
,15768920.815,49.9994011,-1455.61273193359,-6.55551329216802E-5,2.0607952077073E-7,1,0.999253354069792,40.0298881530762,1.99128276792565,16.4700025320053,-0.000702651945190286,-0.000148560020102374,0.25,-1.96590054025828E-6,-6.54387854226584E-5,-2.37461803223258E-6,49.9994011,49.9994011,-1458.04565429687,-1453.17980957031,52.9498607782556,18.6874387562283,8.0402718,0,0,0,4449,49.9591,-1455.61273193359,,,,,,,,,,,,,,,,,13.753754,,,,,,49.9994011,,,,
,15769001.02,49.9996338,2547.6572265625,-5.57387028230643E-5,2.38616062385036E-7,1,0.999253354069792,40.0298881530762,1.99123204994895,16.4700025320053,-0.000595533586314768,-0.000136843391688427,0.25,-2.64835024309744E-6,-5.5634734262371E-5,-2.99462911056301E-6,49.9996338,49.9996338,2545.1162109375,2550.1982421875,52.9217221515633,18.6880808295236,8.2025299,0,0,0,4449,49.9615,2547.6572265625,,,,,,,,,,,,,,,,,13.378378,,,,,,49.9996338,,,,
,15769077.235,49.9995537,6360.48510742188,-5.84256530816814E-5,2.67252381918716E-7,1,0.999253354069792,40.0298881530762,1.99129102475982,16.4800030738115,-0.000624389837030932,-0.000142994942640661,0.25,-2.73233542218033E-6,-5.8321374856687E-5,-3.09660528012662E-6,49.9994431,49.9996643,6340.5625,6380.40771484375,52.7317864213902,18.68695285668,8.16257715,0,0,0,4449,49.9583,6360.48510742188,,,,,,,,,,,,,,,,,13.378378,,,,,,49.9995537,,,,
,15769156.39,50.0006371,10319.13671875,-5.98029308723093E-5,2.32558659109055E-7,1,0.999253354069792,40.0298881530762,1.99121972755621,16.4700025320053,-0.000639217396300951,-0.000145976100948643,0.25,-2.75865776698994E-6,-5.97018918265173E-5,-3.13300517676274E-6,50.0006371,50.0006371,10314.2919921875,10323.9814453125,52.9764361479095,18.6895803948847,8.2848825,0,0,0,4449,49.9622,10319.13671875,,,,,,,,,,,,,,,,,13.378378,,,,,,50.0006371,,,,
,15769236.575,50.00125885,14327.158203125,-5.37413614199847E-5,2.90993304736622E-7,1,0.999253354069792,40.0298881530762,1.99121917233161,16.4700025320053,-0.000573072098481247,-0.000139012924198575,0.25,-3.20350047716905E-6,-5.36511687075938E-5,-3.54024571701094E-6,50.0009956,50.0015221,14297.3359375,14356.98046875,52.9248486656402,18.6897686649406,8.2437062,0,0,0,4449,49.9587,14327.158203125,,,,,,,,,,,,,,,,,13.378378,,,,,,50.00125885,,,,
,15769314.02,50.00014495,18195.4638671875,-3.95365569181898E-5,2.65856914679357E-7,1,0.999253354069792,40.0298881530762,1.99115324762026,16.4700025320053,-0.00041955403635708,-0.000113769679412839,0.25,-3.42224106894464E-6,-3.94673034458763E-5,-3.66964707484226E-6,50.0000877,50.0002022,18165.3984375,18225.529296875,52.944389378621,18.6881109155944,8.2848825,0,0,0,4449,49.9566,18195.4638671875,,,,,,,,,,,,,,,,,13.378378,,,,,,50.00014495,,,,
,15769393.67,50.0013123,22175.291015625,-2.4283763967172E-5,3.38178132287185E-7,1,0.999253354069792,40.0298881530762,1.99106489325749,16.4800030738115,-0.000256052266291434,-7.90766286074139E-5,0.25,-2.95434692859537E-6,-2.42383351553744E-5,-3.10602436957661E-6,50.0013123,50.0013123,22172.7578125,22177.82421875,52.8279267292556,18.6918245888075,8.2848825,0,0,0,4449,49.9575,22175.291015625,,,,,,,,,,,,,,,,,13.378378,,,,,,50.0013123,,,,
,15769470.665,50.0005112,26023.3857421875,-1.49319512407603E-5,3.3470113029851E-7,1,0.999253354069792,40.0298881530762,1.99101936917679,16.4700025320053,-0.000154445641200563,-6.53260841347516E-5,0.25,-3.36514994657524E-6,-1.48956688183133E-5,-3.45731235628677E-6,50.0005112,50.0005112,26020.8828125,26025.888671875,53.0757029698518,18.6909495804585,8.2025299,0,0,0,4449,49.9608,26023.3857421875,,,,,,,,,,,,,,,,,13.378378,,,,,,50.0005112,,,,
,15769548.175,50.00117875,29899.30078125,-1.25914381576015E-5,5.76740645072455E-7,1,0.999253354069792,40.0298881530762,1.99088831434028,16.4700025320053,-0.000127839045975199,-6.84090479226266E-5,0.25,-4.07290920667231E-6,-1.25542168095506E-5,-4.15000972054015E-6,50.0011406,50.0012169,29869.5546875,29929.046875,52.5910932879286,18.6905921415218,8.32647225,0,0,0,4449,49.9537,29899.30078125,,,,,,,,,,,,,,,,,12.252253,,,,,,50.00117875,,,,
,15769628.525,50.0011158,33912.125,-1.83484777575576E-5,4.03904370020694E-7,1,0.999253354069792,40.0298881530762,1.99099160157956,16.4800030738115,-0.000191613171778598,-7.03614981649272E-5,0.25,-3.21401518612294E-6,-1.83137180364841E-5,-3.32937317190845E-6,50.0010185,50.0012131,33882.0234375,33942.2265625,52.9334465793518,18.6897115459343,8.32647225,0,0,0,4449,49.95545,33912.125,,,,,,,,,,,,,,,,,13.378378,,,,,,50.0011158,,,,
,15769709.39,50.00048255,37954.78515625,-2.55885646305674E-5,4.3264981851634E-7,1,0.999253354069792,40.0298881530762,1.99102585366562,16.4800030738115,-0.000270353696822497,-8.09714083522686E-5,0.25,-2.89027617062286E-6,-2.55532258477521E-5,-3.05299455671757E-6,50.0003395,50.0006256,37924.8515625,37984.71875,52.4605613252171,18.6903450409255,8.28529595,0,0,0,4449,49.95605,37954.78515625,,,,,,,,,,,,,,,,,12.252253,,,,,,50.00048255,,,,
,15769787.94,50.0006256,41880.6015625,-3.44367228934992E-5,4.84570266357455E-7,1,0.999253354069792,40.0298881530762,1.99100755592682,16.4700025320053,-0.000364774350598336,-0.000103999193337985,0.25,-3.42752049987055E-6,-3.43959527787541E-5,-3.64749193879374E-6,50.0003738,50.0008774,41848.30078125,41912.90234375,52.8505939563133,18.6893986989249,8.0402718,0,0,0,4449,49.9536,41880.6015625,,,,,,,,,,,,,,,,,12.252253,,,,,,50.0006256,,,,
,15769866.47,50.0003014,45806.4921875,-4.50028142331734E-5,7.03389704798639E-7,1,0.999253354069792,40.0298881530762,1.99108557068967,16.4700025320053,-0.000478914639378443,-0.000124030764920503,0.25,-3.37596864331776E-6,-4.4961658683678E-5,-3.66471816942842E-6,50.0001984,50.0004044,45776.49609375,45836.48828125,52.7184987365633,18.6875565128426,8.16257715,0,0,0,4449,49.95075,45806.4921875,,,,,,,,,,,,,,,,,13.003003,,,,,,50.0003014,,,,
,15769944.28,50.0022507,49697.109375,-5.44386497621053E-5,4.78662506146041E-7,1,0.999253354069792,40.0298881530762,1.99112104595237,16.4800030738115,-0.00057996618105566,-0.000146944753563027,0.25,-3.79522246317945E-6,-5.43968555701998E-5,-4.14533605867134E-6,50.0021248,50.0023766,49669.671875,49724.546875,53.106968110621,18.6863348957364,8.2848825,0,0,0,4449,49.9547,49697.109375,,,,,,,,,,,,,,,,,13.378378,,,,,,50.0022507,,,,
,15770023.54,50.0021763,53657.359375,-6.59068442719327E-5,7.27070669380421E-7,1,0.999253354069792,40.0298881530762,1.99120717267825,16.4800030738115,-0.000704544477506313,-0.000165223224666432,0.25,-3.41723845553052E-6,-6.58713137676715E-5,-3.84206504381351E-6,50.0021553,50.0021973,53632.4375,53682.28125,52.6129788864671,18.6847652696783,8.368062,0,0,0,4449,49.95325,53657.359375,,,,,,,,,,,,,,,,,13.378378,,,,,,50.0021763,,,,
,15770103.625,50.0013504,57660.072265625,-7.71431333400819E-5,5.90694727425283E-7,1,0.999253354069792,40.0298881530762,1.99133518155283,16.4700025320053,-0.000827526424495685,-0.000178343481219092,0.25,-2.60240912396972E-6,-7.7119371570502E-5,-3.10032032605497E-6,50.0013237,50.0013771,57655.00390625,57665.140625,52.8490306992748,18.6840609956826,8.32647225,0,0,0,4449,49.95055,57660.072265625,,,,,,,,,,,,,,,,,13.378378,,,,,,50.0013504,,,,
,15770181.67,50.0004158,61561.181640625,-8.9392800821854E-5,7.98947064648282E-7,1,0.999253354069792,40.0298881530762,1.99125452034391,16.4700025320053,-0.000960110419508885,-0.000200526986858429,0.25,-2.44593398525617E-6,-8.93788702906082E-5,-3.02314293926944E-6,50.0004158,50.0004158,61558.59375,61563.76953125,52.8920202678325,18.6855066886408,8.2848825,0,0,0,4449,49.9485,61561.181640625,,,,,,,,,,,,,,,,,13.003003,,,,,,50.0004158,,,,
,15770259.525,49.9990177,65451.96484375,-0.000100109640625008,5.84258462789367E-7,1,0.999253354069792,40.0298881530762,1.99126881964379,16.4700025320053,-0.00107657875639382,-0.000217734672956761,0.25,-2.10412664783269E-6,-0.000100109365264021,-2.75046213094838E-6,49.9988289,49.9992065,65422.0234375,65481.90625,52.9537689208517,18.6838431392139,8.2437062,0,0,0,4449,49.9544,65451.96484375,,,,,,,,,,,,,,,,,13.378378,,,,,,49.9990177,,,,
,15770338.51,49.9996834,69397.890625,-0.000114024657474089,6.48021359564492E-7,1,0.999253354069792,40.0298881530762,1.99113636221932,16.4800030738115,-0.00122275278626982,-0.000267553868583405,0.25,-4.20749550280985E-6,-0.000114025271100264,-4.9438273150954E-6,49.9996834,49.9996834,69390.34375,69405.4375,52.3980310436786,18.6842973994958,8.2437062,0,0,0,4449,49.9501,69397.890625,,,,,,,,,,,,,,,,,13.753754,,,,,,49.9996834,,,,
,15770417.075,50.0006638,73325.7109375,-0.00012295032780895,8.64796462654388E-7,1,0.999253354069792,40.0298881530762,1.99110319208846,16.4700025320053,-0.00132120195452855,-0.000274061563504455,0.25,-3.19814046351885E-6,-0.000122973129100821,-3.99131828845282E-6,50.0006638,50.0006638,73323.1953125,73328.2265625,52.7255333932363,18.6835736637452,8.2025299,0,0,0,4449,49.9482,73325.7109375,,,,,,,,,,,,,,,,,13.378378,,,,,,50.0006638,,,,
,15770494.51,50.00105475,77196.578125,-0.0001346338478763,7.88936830210055E-7,1,0.999253354069792,40.0298881530762,1.99125157847739,16.4800030738115,-0.0014462325649506,-0.000304462002882685,0.25,-3.90182993801445E-6,-0.000134670818395092,-4.76981409073131E-6,50.0010185,50.001091,77166.5859375,77226.5703125,52.6129788864671,18.6843784256261,8.2848825,0,0,0,4449,49.95015,77196.578125,,,,,,,,,,,,,,,,,13.378378,,,,,,50.00105475,,,,
,15770574.615,50.0009079,81199.72265625,-0.00014702160675233,6.95033482019624E-7,1,0.999253354069792,40.0298881530762,1.99112455647938,16.4700025320053,-0.00157713827516073,-0.000344924176487889,0.25,-5.41366483127209E-6,-0.000147070863190362,-6.36110358983203E-6,50.0009079,50.0009079,81194.75,81204.6953125,52.6075074868325,18.6854986356858,8.1617627,0,0,0,4449,49.9515,81199.72265625,,,,,,,,,,,,,,,,,12.252253,,,,,,50.0009079,,,,
,15770655.795,50.000309,85257.76171875,-0.000160149328071267,9.96061657463206E-7,1,0.999253354069792,40.0298881530762,1.99119666840115,16.4800030738115,-0.001719798688417,-0.000366969201525652,0.25,-5.08365113030341E-6,-0.000160225769138021,-6.113818021257E-6,50.000309,50.000309,85252.7109375,85262.8125,52.812294158871,18.6859700984633,8.368062,0,0,0,4449,49.9457,85257.76171875,,,,,,,,,,,,,,,,,13.003003,,,,,,50.000309,,,,
,15770733.68,49.99990655,89147.93359375,-0.000170990158615236,8.87731581937396E-7,1,0.999253354069792,40.0298881530762,1.99108032410261,16.4700025320053,-0.00183773137722517,-0.000383938669767134,0.25,-4.69962441721672E-6,-0.000171094492939702,-5.79720386147879E-6,49.9998627,49.9999504,89120.5703125,89175.296875,52.7184987365633,18.6864034977265,8.32647225,0,0,0,4449,49.94795,89147.93359375,,,,,,,,,,,,,,,,,13.003003,,,,,,49.99990655,,,,
,15770752.82,50.0001068,89999.6875,-0.000173512257754484,9.78408944420472E-7,1,0.999253354069792,40.0298881530762,1.99103526774954,16.4800030738115,-0.00186518409587532,-0.000387698048361564,0.25,-4.59321571920657E-6,-0.000173623216834087,-5.70640143462895E-6,50.0001068,50.0001068,89999.671875,89999.703125,52.4691592389286,18.6869705828066,8.2848825,0,0,0,4417,49.9479,89999.6875,,,,,,,,,,,,,,,,,13.753754,,,,,,50.0001068,,,,