File: data/doubleLayers/dl_0-25/ppms/DD205_10_HYST_20K_1OE.DAT
[Header]
; VSM Data File (default extension .dat)
; Copyright (c) 2003, Quantum Design, Inc. All rights reserved.
TITLE,
FILEOPENTIME,15751224.86,04/18/2018,12:54 am
BYAPP,VSM,1.0,1.0
INFO,PPMS VSM Option Release 1.3.7 Build 2,APPNAME
INFO,291,COIL_SERIAL_NUMBER
INFO,0,MOMENT_UNITS
INFO,,SAMPLE_MATERIAL
INFO,,SAMPLE_COMMENT
INFO,,SAMPLE_MASS
INFO,,SAMPLE_VOLUME
INFO,,SAMPLE_MOLECULAR_WEIGHT
INFO,,SAMPLE_SIZE
INFO,,SAMPLE_SHAPE
INFO,35.28,SAMPLE_OFFSET
DATATYPE,COMMENT,1
DATATYPE,TIME,2
STARTUPAXIS,X,2
STARTUPAXIS,Y1,5
[Data]
Comment,Time Stamp (sec),Temperature (K),Magnetic Field (Oe),Moment (emu),M. Std. Err. (emu),Transport Action,Averaging Time (sec),Frequency (Hz),Peak Amplitude (mm),Center Position (mm),Coil Signal' (mV),Coil Signal" (mV),Range (mV),M. Quad. Signal (emu),M. Raw' (emu),M. Raw" (emu),Min. Temperature (K),Max. Temperature (K),Min. Field (Oe),Max. Field (Oe),Mass (grams),Motor Lag (deg),Pressure (Torr),VSM Status (code),Motor Status (code),Measure Status (code),PPMS Status (code),System Temp. (K),System Field (Oe),Sample Position (deg),Bridge 1 Resistance (ohms),Bridge 1 Excitation (에),Bridge 2 Resistance (ohms),Bridge 2 Excitation (에),Bridge 3 Resistance (ohms),Bridge 3 Excitation (에),Bridge 4 Resistance (ohms),Bridge 4 Excitation (에),Signal 1 Vin (V),Signal 2 Vin (V),Digital Inputs (code),Drive 1 Iout (mA),Drive 1 Ipower (W),Drive 2 Iout (mA),Drive 2 Ipower (W),Pressure (),Map 20 (),Map 21 (),Map 22 (),Map 23 (),Map 24 (),Map 25 (),Map 26 (),Map 27 (),Map 28 (),Map 29 ()
,15751259.865,20.0087795,0.152809884399176,6.35449139915174E-5,1.99453859071214E-7,1,0.999253354069792,40.0298881530762,1.99104239777362,16.4700025320053,0.000686740592362785,9.45384190283049E-5,0.25,-2.38850322340545E-6,6.31732159470368E-5,-2.22997787880878E-6,20.0087795,20.0087795,0.10696692019701,0.198652848601341,51.2904634319285,18.6679100041111,5.58366585,0,0,0,4417,20.0203,0.152809884399176,,,,,,,,,,,,,,,,,13.753754,,,,,,20.0087795,,,,
,15751354.09,20.0014496,3969.5615234375,6.40024195941675E-5,1.78005642267308E-7,1,0.999253354069792,40.0298881530762,1.99113585722679,16.4700025320053,0.00069191251675034,9.43377357807182E-5,0.25,-2.4973003207511E-6,6.36319128964787E-5,-2.32866300069344E-6,20.0014477,20.0014515,3939.64721679687,3999.47583007812,52.8685714122556,18.6815665653248,5.55605315,0,0,0,4449,20.00985,3969.5615234375,,,,,,,,,,,,,,,,,13.378378,,,,,,20.0014496,,,,
,15751432.415,20.0090284,7885.36450195313,5.51217207880348E-5,2.7551684412097E-7,1,0.999253354069792,40.0298881530762,1.9911549924599,16.4700025320053,0.000596787113050062,7.65545553612748E-5,0.25,-2.59790873258362E-6,5.48080259019194E-5,-2.44091536219577E-6,20.0084152,20.0096416,7855.3095703125,7915.41943359375,52.761488305121,18.6817171457503,5.55605315,0,0,0,4449,20.0104,7885.36450195313,,,,,,,,,,,,,,,,,13.003003,,,,,,20.0090284,,,,
,15751516.305,20.00165465,12073.5185546875,4.45968611711192E-5,2.99406813355598E-7,1,0.999253354069792,40.0298881530762,1.99114022202213,16.4800030738115,0.000483313156211718,5.95043160412602E-5,0.25,-2.33781475909674E-6,4.43481175207847E-5,-2.20086566801045E-6,20.0016289,20.0016804,12043.5693359375,12103.4677734375,52.0845980074671,18.6845187502382,5.6678953,0,0,0,4449,20.0045,12073.5185546875,,,,,,,,,,,,,,,,,13.003003,,,,,,20.00165465,,,,
,15751606.74,20.0024414,16596.662109375,3.46678056169625E-5,3.16412941369299E-7,1,0.999253354069792,40.0298881530762,1.99101523611108,16.4800030738115,0.000376462759578031,4.21322708389327E-5,0.25,-2.20944157757075E-6,3.44798775563076E-5,-2.09325364950301E-6,20.0024414,20.0024414,16591.56640625,16601.7578125,52.4605613252171,18.6890885403217,5.64028835,0,0,0,4449,20.0065,16596.662109375,,,,,,,,,,,,,,,,,13.003003,,,,,,20.0024414,,,,
,15751694.475,20.00259685,20982.0244140625,2.37897116411706E-5,4.27221182039908E-7,1,0.999253354069792,40.0298881530762,1.99107929586362,16.4700025320053,0.000259119993370825,2.47346758867476E-5,0.25,-1.91089365639783E-6,2.36652447549161E-5,-1.82391267009973E-6,20.0025482,20.0026455,20954.580078125,21009.46875,52.6927049954287,18.6857164088885,5.5557761,0,0,0,4449,20.00305,20982.0244140625,,,,,,,,,,,,,,,,,13.378378,,,,,,20.00259685,,,,
,15751785.085,20.001524,25509.8837890625,1.18059502679236E-5,4.46487682444336E-7,1,0.999253354069792,40.0298881530762,1.99112212169982,16.4700025320053,0.000131854817260588,-5.98970947853651E-6,0.25,-2.65178414675164E-6,1.17519105760672E-5,-2.59691098910012E-6,20.001524,20.001524,25507.25,25512.517578125,52.588748402371,18.6896595907199,5.63972545,0,0,0,4449,20.0026,25509.8837890625,,,,,,,,,,,,,,,,,13.003003,,,,,,20.001524,,,,
,15751870.8,20.0036001,29792.7158203125,1.78786681926871E-6,2.94568353912762E-7,1,0.999253354069792,40.0298881530762,1.99114573078754,16.4700025320053,2.35743760747495E-5,-2.11911485195076E-5,0.25,-2.29029645544774E-6,1.78694636404571E-6,-2.27181900498245E-6,20.0035343,20.0036659,29760.181640625,29825.25,52.3878698729286,18.6911860833824,5.6681781,0,0,0,4449,20.0021,29792.7158203125,,,,,,,,,,,,,,,,,13.378378,,,,,,20.0036001,,,,
,15751959.32,20.0030117,34218.095703125,-1.11469025001079E-5,5.87939482427341E-7,1,0.999253354069792,40.0298881530762,1.99114210394391,16.4700025320053,-0.000117559328549772,-3.36299381367287E-5,0.25,-1.14808248314064E-6,-1.10861734398456E-5,-1.18559961457443E-6,20.0029755,20.0030479,34187.99609375,34248.1953125,52.8130757873902,18.6904066056249,5.7248006,0,0,0,4449,20.0012,34218.095703125,,,,,,,,,,,,,,,,,13.378378,,,,,,20.0030117,,,,
,15752044.775,20.00306225,38490.845703125,-1.97438157822596E-5,7.19160869754444E-7,1,0.999253354069792,40.0298881530762,1.99116096911886,16.4700025320053,-0.000206786120270929,-6.78404450008951E-5,0.25,-2.79851425011749E-6,-1.96359517171036E-5,-2.86571670604784E-6,20.0030479,20.0030766,38460.87890625,38520.8125,52.7145905939671,18.6908765950268,5.75353885,0,0,0,4449,20.0003,38490.845703125,,,,,,,,,,,,,,,,,12.252253,,,,,,20.00306225,,,,
,15752123.19,20.0018053,42408.876953125,-3.10254199036554E-5,7.37187897840799E-7,1,0.999253354069792,40.0298881530762,1.9910505535489,16.4700025320053,-0.000328705777294398,-8.56571974281412E-5,0.25,-2.44140280108011E-6,-3.08684454123722E-5,-2.56277543271843E-6,20.0017872,20.0018234,42383.6328125,42434.12109375,52.7083375658133,18.6899090323402,5.75353885,0,0,0,4449,19.99745,42408.876953125,,,,,,,,,,,,,,,,,12.252253,,,,,,20.0018053,,,,
,15752203.145,20.0011301,46404.5703125,-4.15856776513487E-5,6.02147729298948E-7,1,0.999253354069792,40.0298881530762,1.99116305971397,16.4800030738115,-0.000444108669358448,-9.56334227836853E-5,0.25,-1.4778166032381E-6,-4.1389812227685E-5,-1.65696085074539E-6,20.0010757,20.0011845,46382.02734375,46427.11328125,52.9201588945248,18.6883032961422,5.7250862,0,0,0,4449,19.99735,46404.5703125,,,,,,,,,,,,,,,,,13.378378,,,,,,20.0011301,,,,
,15752283.335,20.0018692,50412.962890625,-5.38598490071227E-5,7.38969918312537E-7,1,0.999253354069792,40.0298881530762,1.99133426425542,16.4700025320053,-0.000576519515445977,-0.000117266497441266,0.25,-1.28800596130305E-6,-5.36183987340576E-5,-1.53279284025175E-6,20.0018635,20.0018749,50380.30859375,50445.6171875,52.9404812360248,18.686584566624,5.81130385,0,0,0,4449,19.99605,50412.962890625,,,,,,,,,,,,,,,,,13.003003,,,,,,20.0018692,,,,
,15752360.66,20.00150585,54278.2421875,-6.07549786466162E-5,7.25327613352487E-7,1,0.999253354069792,40.0298881530762,1.99122844214953,16.4700025320053,-0.000650826878987039,-0.000129952746949534,0.25,-1.2248522935415E-6,-6.04943734640476E-5,-1.51231118250254E-6,20.00144,20.0015717,54253.3203125,54303.1640625,52.7622699336402,18.6880308488878,5.7250862,0,0,0,4449,19.99595,54278.2421875,,,,,,,,,,,,,,,,,13.378378,,,,,,20.00150585,,,,
,15752439.32,20.0008955,58206.892578125,-7.24311584589487E-5,7.11538621017255E-7,1,0.999253354069792,40.0298881530762,1.99129224538709,16.4800030738115,-0.000777619779871474,-0.000146323793716366,0.25,-6.45298729691655E-7,-7.21379169286834E-5,-1.00325579336924E-6,20.0008316,20.0009594,58181.828125,58231.95703125,52.717717108044,18.686799762221,5.81130385,0,0,0,4449,19.9955,58206.892578125,,,,,,,,,,,,,,,,,12.252253,,,,,,20.0008955,,,,
,15752517.955,20.00028135,62139.6171875,-8.25370419190322E-5,6.28926019836465E-7,1,0.999253354069792,40.0298881530762,1.99114600283078,16.4800030738115,-0.000889683387575966,-0.000147461639691406,0.25,1.07185328190498E-6,-8.22280195133565E-5,6.44224344631407E-7,20.0001698,20.0003929,62104.578125,62174.65625,52.5441955767748,18.6874517599797,5.75411295,0,0,0,4449,19.9946,62139.6171875,,,,,,,,,,,,,,,,,13.378378,,,,,,20.00028135,,,,
,15752598.045,20.00058175,66143.26953125,-9.66363129401494E-5,8.04556721497305E-7,1,0.999253354069792,40.0298881530762,1.99120733505518,16.4700025320053,-0.001037859342478,-0.000195266129951784,0.25,-8.29460450778347E-7,-9.62831713740948E-5,-1.33666829143795E-6,20.0005474,20.0006161,66118.3359375,66168.203125,52.5473220908517,18.6873165270271,5.75411295,0,0,0,4449,19.9962,66143.26953125,,,,,,,,,,,,,,,,,13.378378,,,,,,20.00058175,,,,
,15752676.875,19.9999685,70084.16796875,-0.000108324466381823,8.07455936738283E-7,1,0.999253354069792,40.0298881530762,1.9910487278216,16.4700025320053,-0.00116150304084917,-0.000230246423462743,0.25,-1.96869570945222E-6,-0.000107944774340453,-2.54873063870438E-6,19.9997978,20.0001392,70056.7578125,70111.578125,53.1280720806402,18.6912631136446,5.86964895,0,0,0,4449,19.99615,70084.16796875,,,,,,,,,,,,,,,,,12.252253,,,,,,19.9999685,,,,
,15752755.545,19.99967575,74014.42578125,-0.00011746816754405,9.90105088076794E-7,1,0.999253354069792,40.0298881530762,1.9911457779674,16.4700025320053,-0.0012600483073718,-0.000248698772370235,0.25,-2.02281634028343E-6,-0.000117080836284224,-2.66760483805598E-6,19.9995632,19.9997883,73984.21875,74044.6328125,52.9795626619864,18.6880749834602,5.8403306,0,0,0,4449,19.9933,74014.42578125,,,,,,,,,,,,,,,,,13.378378,,,,,,19.99967575,,,,
,15752835.335,20.00007535,78002.5703125,-0.000132144837681866,9.3634762926445E-7,1,0.999253354069792,40.0298881530762,1.9911041282673,16.4800030738115,-0.0014164838220594,-0.000286873008471891,0.25,-2.91466792693893E-6,-0.000131733023213996,-3.65450022003172E-6,19.9999657,20.000185,77977.6484375,78027.4921875,52.2659358239286,18.6887284364087,5.8989673,0,0,0,4449,19.99655,78002.5703125,,,,,,,,,,,,,,,,,13.753754,,,,,,20.00007535,,,,
,15752913.07,20.000453,81888.578125,-0.000147351543960084,1.09457241045514E-6,1,0.999253354069792,40.0298881530762,1.99137937661039,16.4700025320053,-0.00158312195379605,-0.000302726073012546,0.25,-1.6303041357933E-6,-0.000146931793584847,-2.47642939067074E-6,20.0003967,20.0005093,81861.09375,81916.0625,52.768522961794,18.6901863567787,5.86964895,0,0,0,4449,19.99325,81888.578125,,,,,,,,,,,,,,,,,13.378378,,,,,,20.000453,,,,
,15752993.235,19.9985647,85893.828125,-0.000156001656163018,1.14990027538363E-6,1,0.999253354069792,40.0298881530762,1.99116414443159,16.4800030738115,-0.00167535032768386,-0.000325511345147497,0.25,-2.17252848007839E-6,-0.000155587891055023,-3.08355260563821E-6,19.9985294,19.9986,85864.03125,85923.625,52.7396027065825,18.6887381431362,5.89926145,0,0,0,4449,19.9962,85893.828125,,,,,,,,,,,,,,,,,12.252253,,,,,,19.9985647,,,,
,15753073.185,19.998209,89891.6796875,-0.000164634878839383,1.26591397726923E-6,1,0.999253354069792,40.0298881530762,1.99110958237385,16.4800030738115,-0.00176690456173143,-0.000351889108763993,0.25,-3.04828976185664E-6,-0.000164228785849021,-4.02378540944816E-6,19.9981155,19.9983025,89861.734375,89921.625,52.8388695285248,18.6903592510686,5.89926145,0,0,0,4449,19.996,89891.6796875,,,,,,,,,,,,,,,,,12.252253,,,,,,19.998209,,,,
,15753165.405,20.0004282,86317.484375,-0.00015619837985332,1.09058813494436E-6,1,0.999253354069792,40.0298881530762,1.99125635932862,16.4700025320053,-0.00167584344826393,-0.000335565213218398,0.25,-3.06730933328513E-6,-0.000155782367135852,-3.97887019494318E-6,20.0002632,20.0005932,86292.796875,86342.171875,52.6317379709286,18.6871834038151,5.8989673,0,0,0,4449,19.9973,86317.484375,,,,,,,,,,,,,,,,,13.003003,,,,,,20.0004282,,,,
,15753244.845,20.0021219,82347.00390625,-0.000144882716801239,1.03406618116271E-6,1,0.999253354069792,40.0298881530762,1.99117412871051,16.4700025320053,-0.00155538309179019,-0.00030375625608671,0.25,-2.17013269832546E-6,-0.000144470248539203,-3.00232714009895E-6,20.0020542,20.0021896,82314.5546875,82379.453125,52.6426807701979,18.689801548054,5.9285798,0,0,0,4449,19.9961,82347.00390625,,,,,,,,,,,,,,,,,13.378378,,,,,,20.0021219,,,,
,15753325.085,20.0020943,78336.41796875,-0.000129744518164887,1.2766928339167E-6,1,0.999253354069792,40.0298881530762,1.991095422731,16.4800030738115,-0.00139184576644097,-0.000275695671330548,0.25,-2.30572558030819E-6,-0.000129345602588465,-3.03507420702688E-6,20.002039,20.0021496,78306.5078125,78366.328125,52.6708193968902,18.693596991193,5.8989673,0,0,0,4449,19.994,78336.41796875,,,,,,,,,,,,,,,,,13.378378,,,,,,20.0020943,,,,
,15753404.445,20.0016346,74367.8671875,-0.000120368198860417,8.34942243450572E-7,1,0.999253354069792,40.0298881530762,1.99115460398225,16.4700025320053,-0.0012901084690635,-0.000260841974899576,0.25,-2.62882273400181E-6,-0.00011997042276475,-3.28912567386847E-6,20.0016346,20.0016346,74362.9140625,74372.8203125,52.649715426871,18.6905492744562,5.8989673,0,0,0,4449,19.9916,74367.8671875,,,,,,,,,,,,,,,,,13.378378,,,,,,20.0016346,,,,
,15753481.945,20.0016994,70497.6484375,-0.000109156204302679,8.58899680094482E-7,1,0.999253354069792,40.0298881530762,1.99113429699273,16.4800030738115,-0.0011718089386853,-0.000224697811687435,0.25,-1.30089205267895E-6,-0.000108779607638353,-1.88924191447932E-6,20.0016994,20.0016994,70475.1796875,70520.1171875,52.5332527775056,18.6911127058642,5.9285798,0,0,0,4449,19.9913,70497.6484375,,,,,,,,,,,,,,,,,13.003003,,,,,,20.0016994,,,,
,15753562.165,20.00183675,66486.71875,-9.69567445837942E-5,8.35632074513415E-7,1,0.999253354069792,40.0298881530762,1.99116811524384,16.4700025320053,-0.00103605650118297,-0.000225157801131007,0.25,-3.54983254446746E-6,-9.65897274440049E-5,-4.05016075940123E-6,20.0017433,20.0019302,66461.6953125,66511.7421875,52.8560653559479,18.6913773727989,5.9285798,0,0,0,4449,19.99035,66486.71875,,,,,,,,,,,,,,,,,13.753754,,,,,,20.00183675,,,,
,15753640.205,20.00253865,62585.849609375,-8.56743329147468E-5,9.02932120565752E-7,1,0.999253354069792,40.0298881530762,1.99119787499939,16.4800030738115,-0.000912701403932262,-0.000213603331611611,0.25,-4.51416649570183E-6,-8.53265093325589E-5,-4.93815043600313E-6,20.0024471,20.0026302,62563.33203125,62608.3671875,52.6114156294286,18.690997138101,5.9291713,0,0,0,4449,19.98645,62585.849609375,,,,,,,,,,,,,,,,,13.753754,,,,,,20.00253865,,,,
,15753719.57,20.0011778,58620.322265625,-7.00569650720162E-5,8.34830395412953E-7,1,0.999253354069792,40.0298881530762,1.99134430324389,16.4700025320053,-0.000747005989518882,-0.00017035358229437,0.25,-3.30301294854279E-6,-6.97613456942415E-5,-3.6397279555861E-6,20.0010605,20.0012951,58595.3828125,58645.26171875,53.0858641406018,18.6886267832436,5.86964895,0,0,0,4449,19.98675,58620.322265625,,,,,,,,,,,,,,,,,13.003003,,,,,,20.0011778,,,,
,15753804.305,20.00176335,54384.287109375,-6.29756669589251E-5,8.03196179325609E-7,1,0.999253354069792,40.0298881530762,1.99115812186454,16.4800030738115,-0.00067433426037746,-0.000136164852465508,0.25,-1.40571050541942E-6,-6.2705179568653E-5,-1.70338487648095E-6,20.0014839,20.0020428,54351.77734375,54416.796875,52.7036477946979,18.6924433460626,5.89926145,0,0,0,4449,19.9861,54384.287109375,,,,,,,,,,,,,,,,,13.378378,,,,,,20.00176335,,,,
,15753885.555,20.00061895,50324.142578125,-5.2098934661544E-5,7.10003146901E-7,1,0.999253354069792,40.0298881530762,1.99116549633495,16.4800030738115,-0.000560028616126156,-9.99587956850304E-5,0.25,6.48293744175105E-9,-5.18709817006279E-5,-2.35563758484794E-7,20.000618,20.0006199,50294.234375,50354.05078125,52.2479583679863,18.6919895091785,5.98810215,0,0,0,4449,19.9861,50324.142578125,,,,,,,,,,,,,,,,,13.378378,,,,,,20.00061895,,,,
,15753963.385,20.00042725,46433.306640625,-4.21795047486416E-5,5.86443311970316E-7,1,0.999253354069792,40.0298881530762,1.99110800761462,16.4700025320053,-0.000453310652452445,-8.09038119978175E-5,0.25,-1.48310333978238E-9,-4.19875818357462E-5,-1.90048818200068E-7,20.0001831,20.0006714,46405.890625,46460.72265625,53.2077981896018,18.6945174208384,5.98810215,0,0,0,4449,19.988,46433.306640625,,,,,,,,,,,,,,,,,13.378378,,,,,,20.00042725,,,,
,15754042.445,20.0007296,42479.91796875,-3.14976349999262E-5,5.779500987101E-7,1,0.999253354069792,40.0298881530762,1.99117243592701,16.4700025320053,-0.000337581757276565,-6.53508135905271E-5,0.25,-4.66999578925074E-7,-3.13469741144759E-5,-5.99818812487294E-7,20.0007153,20.0007439,42452.41796875,42507.41796875,52.8584102415056,18.6953730226618,5.9291713,0,0,0,4449,19.98545,42479.91796875,,,,,,,,,,,,,,,,,13.003003,,,,,,20.0007296,,,,
,15754121.18,20.000905,38544.154296875,-1.99819124243982E-5,6.40829547285833E-7,1,0.999253354069792,40.0298881530762,1.99103849482593,16.4700025320053,-0.000216205589347385,-2.96909110673474E-5,0.25,7.94339068894207E-7,-1.98876409338238E-5,7.08574542183365E-7,20.0007362,20.0010738,38514.20703125,38574.1015625,52.8912386393133,18.6967932139805,5.89926145,0,0,0,4449,19.986,38544.154296875,,,,,,,,,,,,,,,,,13.378378,,,,,,20.000905,,,,
,15754199.5,20.0004673,34631.177734375,-1.01370936997473E-5,4.91512891398969E-7,1,0.999253354069792,40.0298881530762,1.99102007930682,16.4800030738115,-0.000108955512295833,-1.90514329195725E-5,0.25,2.94766027859514E-8,-1.00861928101053E-5,-1.026491870871E-8,20.0004673,20.0004673,34626.23828125,34636.1171875,52.8638816411402,18.6941676358292,5.9581923,0,0,0,4449,19.985,34631.177734375,,,,,,,,,,,,,,,,,13.378378,,,,,,20.0004673,,,,
,15754276.13,20.0005045,30800.515625,1.01091904026307E-6,3.10575183207959E-7,1,0.999253354069792,40.0298881530762,1.99098755809736,16.4800030738115,1.27225624649236E-5,-8.56288250135859E-6,0.25,-9.76785442706459E-7,1.00931764615745E-6,-9.67978228099466E-7,20.000309,20.0007,30773.080078125,30827.951171875,52.7646148191979,18.6961538862496,5.9291713,0,0,0,4449,19.9863,30800.515625,,,,,,,,,,,,,,,,,13.003003,,,,,,20.0005045,,,,
,15754354.75,20.0001564,26870.1103515625,9.72759209711207E-6,3.54218751573043E-7,1,0.999253354069792,40.0298881530762,1.99097194577626,16.4700025320053,0.000106193938213763,8.85756550911344E-6,0.25,-9.01436995603847E-7,9.67913283242697E-6,-8.62463040051954E-7,19.9999886,20.0003242,26844.810546875,26895.41015625,52.7200619936017,18.6977799640909,5.9581923,0,0,0,4449,19.9832,26870.1103515625,,,,,,,,,,,,,,,,,13.753754,,,,,,20.0001564,,,,
,15754431.43,19.99862865,23039.65234375,2.00197282594914E-5,4.25771618036033E-7,1,0.999253354069792,40.0298881530762,1.99107142384223,16.4700025320053,0.000217666438901702,2.31013994768795E-5,0.25,-1.39741338093368E-6,1.99156794350542E-5,-1.3233699809485E-6,19.9985104,19.9987469,23011.9921875,23067.3125,52.9092160952556,18.696318621874,5.9291713,0,0,0,4449,19.9865,23039.65234375,,,,,,,,,,,,,,,,,13.003003,,,,,,19.99862865,,,,
,15754510.025,20.00027465,19111.587890625,3.03369012210175E-5,3.52201367203241E-7,1,0.999253354069792,40.0298881530762,1.99113712267882,16.4700025320053,0.000328689024053325,4.13251035130591E-5,0.25,-1.52278897825507E-6,3.01734673011632E-5,-1.41970012288452E-6,20.0001907,20.0003586,19089.005859375,19134.169921875,52.9522056638133,18.6961478252292,5.98810215,0,0,0,4449,19.9854,19111.587890625,,,,,,,,,,,,,,,,,13.378378,,,,,,20.00027465,,,,
,15754589.615,19.9995899,15133.6630859375,3.95069882611167E-5,3.98907993527502E-7,1,0.999253354069792,40.0298881530762,1.99101876925848,16.4800030738115,0.000426993617214523,5.93260246443141E-5,0.25,-1.46120677944007E-6,3.9288061173791E-5,-1.33757996174345E-6,19.999485,19.9996948,15101.2138671875,15166.1123046875,53.0999334539479,18.695661617857,5.9581923,0,0,0,4449,19.98625,15133.6630859375,,,,,,,,,,,,,,,,,13.003003,,,,,,19.9995899,,,,
,15754667.88,19.99944975,11222.810546875,4.94283779914345E-5,2.89330463260703E-7,1,0.999253354069792,40.0298881530762,1.99112946947473,16.4700025320053,0.000534176824037217,7.43439989713036E-5,0.25,-1.80720864172285E-6,4.91494742255524E-5,-1.66192470182303E-6,19.9993935,19.999506,11193.01171875,11252.609375,52.9764361479095,18.6967384018096,5.9291713,0,0,0,4449,19.98595,11222.810546875,,,,,,,,,,,,,,,,,13.003003,,,,,,19.99944975,,,,
,15754746.21,20,7306.55834960937,5.88953898898168E-5,2.63985727410999E-7,1,0.999253354069792,40.0298881530762,1.9909610035012,16.4800030738115,0.000636351786007319,8.87289504175423E-5,0.25,-2.12758079667628E-6,5.85578117865224E-5,-1.96516533284026E-6,19.9998722,20.0001278,7274.07275390625,7339.0439453125,53.2351551877748,18.6974809018093,5.9291713,0,0,0,4449,19.98685,7306.55834960937,,,,,,,,,,,,,,,,,13.003003,,,,,,20,,,,
,15754826.745,19.9984169,3280.67211914063,6.72448790799103E-5,2.36877230549625E-7,1,0.999253354069792,40.0298881530762,1.99102119104948,16.4800030738115,0.000726200910400526,0.000103174820030616,0.25,-2.24334774360019E-6,6.6853872201435E-5,-2.07026783273277E-6,19.9983368,19.998497,3245.7900390625,3315.55419921875,53.1296353376787,18.698682007863,5.9291713,0,0,0,4449,19.98605,3280.67211914063,,,,,,,,,,,,,,,,,13.003003,,,,,,19.9984169,,,,
,15754906.11,19.9994755,-684.828765869141,6.10967969312069E-5,2.16642601959709E-7,1,0.999253354069792,40.0298881530762,1.99102587540443,16.4800030738115,0.00066009358715046,9.19681356332454E-5,0.25,-2.19756898387218E-6,6.07395805218819E-5,-2.04482039603387E-6,19.9993725,19.9995785,-707.29052734375,-662.367004394531,52.6286114568517,18.700738761671,5.9291713,0,0,0,4449,19.98725,-684.828765869141,,,,,,,,,,,,,,,,,13.753754,,,,,,19.9994755,,,,
,15754984.98,20.0000515,-4625.1376953125,6.1320874676039E-5,2.94391080775996E-7,1,0.999253354069792,40.0298881530762,1.99101946706416,16.4700025320053,0.000662468340290454,9.27967136897777E-5,0.25,-2.16929624295997E-6,6.09660541139155E-5,-2.0074678391854E-6,19.9999981,20.0001049,-4657.66162109375,-4592.61376953125,52.7724311043902,18.7008573212676,5.98810215,0,0,0,4449,19.9861,-4625.1376953125,,,,,,,,,,,,,,,,,13.378378,,,,,,20.0000515,,,,
,15755064.835,20.0004692,-8616.3310546875,6.69723346126217E-5,2.15364763723176E-7,1,0.999253354069792,40.0298881530762,1.99108618630609,16.4700025320053,0.000723919610941355,9.95760735787092E-5,0.25,-2.54724321827709E-6,6.659067290142E-5,-2.35788864658201E-6,20.0004692,20.0004692,-8646.337890625,-8586.32421875,52.7771208755056,18.6980019112631,6.018012,0,0,0,4449,19.9866,-8616.3310546875,,,,,,,,,,,,,,,,,12.627627,,,,,,20.0004692,,,,
,15755144.315,20.000597,-12589.9326171875,6.92436552161369E-5,3.17949690752497E-7,1,0.999253354069792,40.0298881530762,1.99096570893198,16.4800030738115,0.000748563228157954,0.000102594936219572,0.25,-2.68048197631412E-6,6.88556854882614E-5,-2.4716177281171E-6,20.0005703,20.0006237,-12619.673828125,-12560.19140625,53.0600703994672,18.7014335101186,5.9285798,0,0,0,4449,19.98615,-12589.9326171875,,,,,,,,,,,,,,,,,12.252253,,,,,,20.000597,,,,
,15755223.755,20.0005493,-16560.57421875,6.53603917979871E-5,3.72380106641342E-7,1,0.999253354069792,40.0298881530762,1.9910734699333,16.4800030738115,0.000707040563127978,9.49014010896087E-5,0.25,-2.72512669759911E-6,6.50016836046093E-5,-2.51431117177284E-6,20.0004978,20.0006008,-16593.146484375,-16528.001953125,52.6176686575825,18.6983973740349,5.9291713,0,0,0,4449,19.98585,-16560.57421875,,,,,,,,,,,,,,,,,13.378378,,,,,,20.0005493,,,,
,15755303.635,20.00052355,-20550.6953125,5.44753328085701E-5,3.72314617554177E-7,1,0.999253354069792,40.0298881530762,1.99120533506863,16.4700025320053,0.000590377386947796,7.35812226730947E-5,0.25,-2.79720977626212E-6,5.41844869776403E-5,-2.6078826877084E-6,20.0005169,20.0005302,-20575.71875,-20525.671875,52.9131242378518,18.6973250283876,5.98810215,0,0,0,4449,19.98775,-20550.6953125,,,,,,,,,,,,,,,,,13.378378,,,,,,20.00052355,,,,
,15755383.43,20.00124645,-24538.5380859375,3.92874003919544E-5,4.31379885519024E-7,1,0.999253354069792,40.0298881530762,1.9912189958564,16.4700025320053,0.00042699704067656,4.65319114254356E-5,0.25,-2.63443765744515E-6,3.90848816453302E-5,-2.48683801503165E-6,20.0011463,20.0013466,-24568.5390625,-24508.537109375,52.5918749164479,18.7016425902085,5.9291713,0,0,0,4449,19.9864,-24538.5380859375,,,,,,,,,,,,,,,,,13.003003,,,,,,20.00124645,,,,
,15755461.195,20.00035385,-28429.1044921875,2.78512167697117E-5,4.78968610295664E-7,1,0.999253354069792,40.0298881530762,1.99106522806537,16.4800030738115,0.000305488342970742,1.7414279137478E-5,0.25,-3.32317246142577E-6,2.77168005066775E-5,-3.20561109277415E-6,20.0003014,20.0004063,-28461.62109375,-28396.587890625,52.9162507519287,18.7009493847099,6.0482223,0,0,0,4449,19.9858,-28429.1044921875,,,,,,,,,,,,,,,,,12.252253,,,,,,20.00035385,,,,
,15755540.565,20.00087455,-32392.263671875,2.46502562701833E-5,4.48447659104509E-7,1,0.999253354069792,40.0298881530762,1.99100098697985,16.4700025320053,0.000271617360690143,8.64854164782978E-6,0.25,-3.57615966498526E-6,2.45377251432087E-5,-3.46434075517723E-6,20.0007668,20.0009823,-32414.6640625,-32369.86328125,53.0913355402364,18.7009232525722,5.98869995,0,0,0,4449,19.98655,-32392.263671875,,,,,,,,,,,,,,,,,13.378378,,,,,,20.00087455,,,,
,15755618.9,20.00051785,-36307.04296875,2.68576650200925E-5,4.89401424345894E-7,1,0.999253354069792,40.0298881530762,1.99112924085413,16.4700025320053,0.000295166180339011,1.41716183940944E-5,0.25,-3.4599683180592E-6,2.67380200706944E-5,-3.33565143113462E-6,20.0004425,20.0005932,-36336.9140625,-36277.171875,53.0585071424287,18.7025929389462,6.0482223,0,0,0,4449,19.9853,-36307.04296875,,,,,,,,,,,,,,,,,12.252253,,,,,,20.00051785,,,,
,15755698.21,19.999815,-40272.189453125,3.25438412122284E-5,4.80565155286697E-7,1,0.999253354069792,40.0298881530762,1.99103686265159,16.4800030738115,0.000357823668942984,1.65224100371079E-5,0.25,-4.25956641696143E-6,3.24050827157251E-5,-4.10298992696976E-6,19.9997616,19.9998684,-40299.74609375,-40244.6328125,52.7700862188325,18.7002605160945,6.018012,0,0,0,4449,19.98455,-40272.189453125,,,,,,,,,,,,,,,,,12.627627,,,,,,19.999815,,,,
,15755775.15,19.99982455,-44114.9296875,4.3765747809314E-5,4.89691320272123E-7,1,0.999253354069792,40.0298881530762,1.9910366301407,16.4700025320053,0.000477164900234806,4.54090352496677E-5,0.25,-3.578915840359E-6,4.35778345257705E-5,-3.37129777789143E-6,19.999754,19.9998951,-44142.40625,-44087.453125,52.568426060871,18.7018563190719,6.018012,0,0,0,4449,19.9853,-44114.9296875,,,,,,,,,,,,,,,,,13.753754,,,,,,19.99982455,,,,
,15755852.305,19.99902535,-47972.80078125,4.89793427989183E-5,7.33355488935874E-7,1,0.999253354069792,40.0298881530762,1.9911602398167,16.4700025320053,0.00053362236472492,5.37137017014425E-5,0.25,-3.74575540018468E-6,4.87768271366377E-5,-3.50657281402601E-6,19.9990177,19.999033,-48000.3828125,-47945.21875,52.6880152243133,18.7009166239827,6.0482223,0,0,0,4449,19.9856,-47972.80078125,,,,,,,,,,,,,,,,,13.753754,,,,,,19.99902535,,,,
,15755931.285,19.9997883,-51918.150390625,6.12842526681249E-5,5.86479790576662E-7,1,0.999253354069792,40.0298881530762,1.99104281819595,16.4700025320053,0.000665618635100307,7.92846792768678E-5,0.25,-3.57489674258393E-6,6.10374151377261E-5,-3.27056260000595E-6,19.9997368,19.9998398,-51948.0234375,-51888.27734375,52.8638816411402,18.7040940114826,6.018012,0,0,0,4449,19.98495,-51918.150390625,,,,,,,,,,,,,,,,,12.627627,,,,,,19.9997883,,,,
,15756008.56,20.00079155,-55780.53125,7.17913524341306E-5,7.0640246446229E-7,1,0.999253354069792,40.0298881530762,1.99121202143846,16.4800030738115,0.000781509023516731,8.41908689728737E-5,0.25,-5.00991240790276E-6,7.1519923240355E-5,-4.63902625598003E-6,20.0006962,20.0008869,-55810.546875,-55750.515625,52.7247517647171,18.7005897133605,6.018012,0,0,0,4449,19.98415,-55780.53125,,,,,,,,,,,,,,,,,13.378378,,,,,,20.00079155,,,,
,15756088.725,19.99863245,-59788.599609375,8.19799050797265E-5,8.54410964565554E-7,1,0.999253354069792,40.0298881530762,1.99111221808763,16.4700025320053,0.000888545333816664,0.000118593906145444,0.25,-3.64740560994081E-6,8.16763455263574E-5,-3.21986618319713E-6,19.9984684,19.9987965,-59818.703125,-59758.49609375,53.1624637354864,18.7032748419414,5.95848965,0,0,0,4449,19.9854,-59788.599609375,,,,,,,,,,,,,,,,,12.627627,,,,,,19.99863245,,,,
,15756167.7,20.0000086,-63733.5390625,9.19746597995039E-5,6.59640339075587E-7,1,0.999253354069792,40.0298881530762,1.99092913644019,16.4800030738115,0.00099511761150642,0.000143526003848185,0.25,-3.1334890184207E-6,9.16477646825736E-5,-2.64431493245899E-6,19.9999981,20.0000191,-63760.99609375,-63706.08203125,52.8787325830056,18.705449749118,5.95848965,0,0,0,4449,19.9863,-63733.5390625,,,,,,,,,,,,,,,,,13.378378,,,,,,20.0000086,,,,
,15756248.135,19.99922565,-67753.83984375,0.000107081677775574,6.77275893485549E-7,1,0.999253354069792,40.0298881530762,1.99110881722982,16.4700025320053,0.00116259759913952,0.000146588016581385,0.25,-5.57520326276118E-6,0.00010673376318498,-4.98409667008039E-6,19.9990807,19.9993706,-67783.890625,-67723.7890625,52.8255818436979,18.7046117518375,6.0784326,0,0,0,4449,19.98605,-67753.83984375,,,,,,,,,,,,,,,,,13.378378,,,,,,19.99922565,,,,
,15756329.68,19.9991302,-71831.30859375,0.000116452911095278,1.02820552989814E-6,1,0.999253354069792,40.0298881530762,1.99111357689866,16.4800030738115,0.00125850016034424,0.000193565071815713,0.25,-2.9083889508494E-6,0.000116082665903635,-2.26124508940049E-6,19.9991302,19.9991302,-71836.3828125,-71826.234375,53.0178624594287,18.7034010356342,5.95848965,0,0,0,4449,19.9882,-71831.30859375,,,,,,,,,,,,,,,,,12.252253,,,,,,19.9991302,,,,
,15756406.6,19.99963285,-75676.34765625,0.000127357795646237,1.05256346313044E-6,1,0.999253354069792,40.0298881530762,1.99109569645521,16.4700025320053,0.00137745116697759,0.000207106894145472,0.25,-3.6259648528288E-6,0.000126981427104809,-2.90204660093742E-6,19.9996014,19.9996643,-75708.7265625,-75643.96875,52.8810774685633,18.7028653909601,5.95848965,0,0,0,4449,19.98925,-75676.34765625,,,,,,,,,,,,,,,,,13.378378,,,,,,19.99963285,,,,
,15756486.875,19.9978447,-79686.73828125,0.000140091917260702,9.80137578652886E-7,1,0.999253354069792,40.0298881530762,1.99111793305898,16.4800030738115,0.00151793313382204,0.000214456779130546,0.25,-5.25078181144835E-6,0.000139715350115494,-4.43524795626322E-6,19.9978447,19.9978447,-79691.7265625,-79681.75,52.8154206729479,18.7043382381647,6.0784326,0,0,0,4449,19.989,-79686.73828125,,,,,,,,,,,,,,,,,13.003003,,,,,,19.9978447,,,,
,15756565.68,19.99851705,-83624.58203125,0.000150975244607955,9.73581978484842E-7,1,0.999253354069792,40.0298881530762,1.9911015928773,16.4700025320053,0.00163433479131984,0.000241517237832348,0.25,-4.71292631023117E-6,0.00015059623648766,-3.82177135311937E-6,19.9985142,19.9985199,-83654.6796875,-83594.484375,53.0905539117171,18.7068750519464,6.0784326,0,0,0,4449,19.9907,-83624.58203125,,,,,,,,,,,,,,,,,12.252253,,,,,,19.99851705,,,,
,15756645.78,19.99798105,-87627.37109375,0.000161385073382171,8.70783666078785E-7,1,0.999253354069792,40.0298881530762,1.99124462952904,16.4700025320053,0.00175018101911941,0.000243472920170418,0.25,-6.42543265620731E-6,0.000161023237737841,-5.45457679174013E-6,19.9978962,19.9980659,-87652.359375,-87602.3828125,53.0069196601595,18.7058000973495,5.95848965,0,0,0,4449,19.9883,-87627.37109375,,,,,,,,,,,,,,,,,12.252253,,,,,,19.99798105,,,,
,15756740.69,19.9996662,-88465.9375,0.000167446236013059,1.10742830218305E-6,1,0.999253354069792,40.0298881530762,1.99108836375943,16.4700025320053,0.00181125754522242,0.00027819808503037,0.25,-4.29351608518905E-6,0.000167064388862982,-3.28900676739225E-6,19.9996662,19.9996662,-88471.140625,-88460.734375,53.0288052586979,18.7067776000743,6.0482223,0,0,0,4449,19.9921,-88465.9375,,,,,,,,,,,,,,,,,13.378378,,,,,,19.9996662,,,,
,15756821.485,20.0012074,-84425.98828125,0.000154456907704392,1.01288194918596E-6,1,0.999253354069792,40.0298881530762,1.99107687068761,16.4700025320053,0.00167109476088441,0.000252561919037588,0.25,-4.31688918601204E-6,0.000154072932576039,-3.40356586017671E-6,20.0012074,20.0012074,-84428.390625,-84423.5859375,53.1429230225056,18.7068062891552,6.018012,0,0,0,4449,19.9911,-84425.98828125,,,,,,,,,,,,,,,,,12.627627,,,,,,20.0012074,,,,
,15756905.08,20.0000801,-80250.9140625,0.000140397242633732,1.07129739047281E-6,1,0.999253354069792,40.0298881530762,1.99114377835579,16.4700025320053,0.00152129842585975,0.00021498042335623,0.25,-5.26005465568731E-6,0.000140024140518344,-4.44069750504786E-6,20.0000591,20.0001011,-80285.8046875,-80216.0234375,52.7872820462556,18.7009936714791,5.98869995,0,0,0,4449,19.99005,-80250.9140625,,,,,,,,,,,,,,,,,12.252253,,,,,,20.0000801,,,,
,15756983.86,20.0012894,-76313.85546875,0.000129626017729376,8.7391906634563E-7,1,0.999253354069792,40.0298881530762,1.99098484914391,16.4800030738115,0.00140257780839533,0.000207340448805221,0.25,-4.01375284764333E-6,0.00012924918922792,-3.2735748771749E-6,20.001236,20.0013428,-76343.75,-76283.9609375,52.6372093705633,18.7048471396682,5.98810215,0,0,0,4449,19.98845,-76313.85546875,,,,,,,,,,,,,,,,,13.753754,,,,,,20.0012894,,,,
,15757063.065,20.00013635,-72355.94921875,0.000118123809535942,1.00800555873403E-6,1,0.999253354069792,40.0298881530762,1.99110016908485,16.4700025320053,0.00127833059327731,0.000186621532138029,0.25,-3.85603284776164E-6,0.000117756508081313,-3.1946929058969E-6,20.0000095,20.0002632,-72385.953125,-72325.9453125,53.1007150824672,18.7049784962919,6.0784326,0,0,0,4449,19.98825,-72355.94921875,,,,,,,,,,,,,,,,,12.252253,,,,,,20.00013635,,,,
,15757141.1,20.0008192,-68456.34375,0.000108600274071282,7.81611532839383E-7,1,0.999253354069792,40.0298881530762,1.99105833804801,16.4700025320053,0.0011765397502156,0.000162951242741472,0.25,-4.32916558354666E-6,0.000108244380638018,-3.73185177604071E-6,20.0006504,20.000988,-68478.8046875,-68433.8828125,52.8740428118902,18.7034448246036,6.1089461,0,0,0,4449,19.9886,-68456.34375,,,,,,,,,,,,,,,,,13.378378,,,,,,20.0008192,,,,
,15757219.705,20.0014343,-64525.51171875,9.38542288111943E-5,8.01481042266599E-7,1,0.999253354069792,40.0298881530762,1.99105449481765,16.4700025320053,0.00101934644119422,0.000125321298831629,0.25,-5.16705589791913E-6,9.35347749173366E-5,-4.65799263983811E-6,20.0013103,20.0015583,-64555.4453125,-64495.578125,52.9764361479095,18.7032251261017,6.01831245,0,0,0,4449,19.9876,-64525.51171875,,,,,,,,,,,,,,,,,13.378378,,,,,,20.0014343,,,,
,15757298.985,20.0005579,-60565.138671875,8.32410634215049E-5,7.02401166892111E-7,1,0.999253354069792,40.0298881530762,1.99096016933424,16.4700025320053,0.000905417987273539,0.000102361619850157,0.25,-5.38498939013387E-6,8.29446579013246E-5,-4.94194314060596E-6,20.0004673,20.0006485,-60592.56640625,-60537.7109375,52.8943651533902,18.7058409654797,6.1089461,0,0,0,4449,19.98815,-60565.138671875,,,,,,,,,,,,,,,,,13.003003,,,,,,20.0005579,,,,
,15757376.745,20.0009241,-56679.478515625,7.2355217276757E-5,8.16319469096634E-7,1,0.999253354069792,40.0298881530762,1.99110329466104,16.4700025320053,0.000789254962600039,7.58402812107038E-5,0.25,-5.89010343026768E-6,7.20890948876571E-5,-5.51041131818579E-6,20.000515,20.0013332,-56709.6171875,-56649.33984375,52.8662265266979,18.7034577459957,6.0482223,0,0,0,4449,19.9867,-56679.478515625,,,,,,,,,,,,,,,,,13.378378,,,,,,20.0009241,,,,
,15757455.855,20.0007906,-52724.791015625,6.02300529498475E-5,6.98930759151539E-7,1,0.999253354069792,40.0298881530762,1.99103044543615,16.4800030738115,0.000655484862649734,7.06841724873393E-5,0.25,-4.18896614890837E-6,5.99930497851374E-5,-3.88502056671923E-6,20.0006256,20.0009556,-52752.05078125,-52697.53125,53.0725764557748,18.7054278490123,6.01831245,0,0,0,4449,19.9876,-52724.791015625,,,,,,,,,,,,,,,,,13.378378,,,,,,20.0007906,,,,
,15757533.28,20.001564,-48856.62109375,4.92171146033226E-5,6.04475387186587E-7,1,0.999253354069792,40.0298881530762,1.99094907412806,16.4800030738115,0.000538983915238285,3.82801934726993E-5,0.25,-5.22590277239478E-6,4.90224086370711E-5,-4.97726005318492E-6,20.0014858,20.0016422,-48884.20703125,-48829.03515625,52.585621888294,18.7045021191318,5.98810215,0,0,0,4449,19.98655,-48856.62109375,,,,,,,,,,,,,,,,,13.378378,,,,,,20.001564,,,,
,15757612.46,20.0028067,-44899.205078125,3.87179502499834E-5,5.95839347930554E-7,1,0.999253354069792,40.0298881530762,1.99103552610348,16.4800030738115,0.000425800173285266,1.96840659846888E-5,0.25,-5.0741794186489E-6,3.856152483201E-5,-4.88039281408519E-6,20.0027943,20.0028191,-44926.6875,-44871.72265625,53.0835192550441,18.704800674005,6.1089461,0,0,0,4449,19.98535,-44899.205078125,,,,,,,,,,,,,,,,,13.378378,,,,,,20.0028067,,,,
,15757690.75,20.00111675,-40983.576171875,2.81381102286864E-5,4.74258923369634E-7,1,0.999253354069792,40.0298881530762,1.99111058807917,16.4800030738115,0.000310313146400431,9.18062499385079E-6,0.25,-4.15907702636269E-6,2.80210900204665E-5,-4.02056876972129E-6,20.0008945,20.001339,-41003.48828125,-40963.6640625,52.9803442905056,18.7022911651814,6.1394596,0,0,0,4449,19.98475,-40983.576171875,,,,,,,,,,,,,,,,,12.252253,,,,,,20.00111675,,,,
,15757770.11,20.00047305,-37018.27734375,1.67709948696723E-5,5.22545977783921E-7,1,0.999253354069792,40.0298881530762,1.99104455896943,16.4700025320053,0.000184879086757866,5.66341256536824E-6,0.25,-2.45767375799971E-6,1.66980177017228E-5,-2.37805140038738E-6,20.0004292,20.0005169,-37045.765625,-36990.7890625,53.1741881632749,18.7028619663498,6.01831245,0,0,0,4449,19.98365,-37018.27734375,,,,,,,,,,,,,,,,,13.753754,,,,,,20.00047305,,,,
,15757850.635,20.00042155,-32995.763671875,5.45534389093106E-6,4.01395289677499E-7,1,0.999253354069792,40.0298881530762,1.99090523097793,16.4800030738115,6.69105452187915E-5,-3.63383223926494E-5,0.25,-4.35275825876818E-6,5.44420342629625E-6,-4.30972480318249E-6,20.0000973,20.0007458,-33028.3515625,-32963.17578125,53.0624152850248,18.7039205855972,6.01831245,0,0,0,4449,19.986,-32995.763671875,,,,,,,,,,,,,,,,,13.378378,,,,,,20.00042155,,,,
,15757928.825,20.0002394,-29087.49609375,-2.97002186198453E-6,4.49403374370592E-6,1,0.999253354069792,40.0298881530762,1.99092939239673,16.4700025320053,-2.26954782435693E-5,-5.74996731855015E-5,0.25,-4.82614203669867E-6,-2.93697489819597E-6,-4.81166202652111E-6,20.000145,20.0003338,-29110.04296875,-29064.94921875,52.822455329621,18.7020480734903,6.1089461,0,0,0,4449,19.98265,-29087.49609375,,,,,,,,,,,,,,,,,13.003003,,,,,,20.0002394,,,,
,15758009.21,19.9998102,-25069.640625,-1.5322652845163E-5,5.77087931400524E-7,1,0.999253354069792,40.0298881530762,1.99102822514316,16.4700025320053,-0.000156123367779727,-7.67850032633735E-5,0.25,-4.43191128871515E-6,-1.52252652399848E-5,-4.46058044630216E-6,19.999609,20.0000114,-25102.291015625,-25036.990234375,53.1038415965441,18.7044154654485,6.1089461,0,0,0,4449,19.98395,-25069.640625,,,,,,,,,,,,,,,,,13.753754,,,,,,19.9998102,,,,
,15758088.46,19.9991703,-21106.81640625,-2.50126578342756E-5,4.21088947347289E-7,1,0.999253354069792,40.0298881530762,1.99093808141416,16.4800030738115,-0.000260665204663833,-9.23799284628863E-5,0.25,-4.17173295823719E-6,-2.48619787507981E-5,-4.22940925975816E-6,19.9990311,19.9993095,-21134.2734375,-21079.359375,52.8842039826402,18.7040170409262,6.01831245,0,0,0,4449,19.9824,-21106.81640625,,,,,,,,,,,,,,,,,13.003003,,,,,,19.9991703,,,,
,15758167.775,19.9993315,-17146.853515625,-3.45241087030973E-5,3.63434399188596E-7,1,0.999253354069792,40.0298881530762,1.99110451407974,16.4700025320053,-0.000363152974805873,-0.0001084876968789,0.25,-3.99394373446883E-6,-3.43187976610824E-5,-4.07587805909172E-6,19.9993191,19.9993439,-17171.875,-17121.83203125,53.0374031724095,18.7027269792571,6.1089461,0,0,0,4449,19.98545,-17146.853515625,,,,,,,,,,,,,,,,,12.627627,,,,,,19.9993315,,,,
,15758248.245,19.9988451,-13121.1157226563,-4.49743717275507E-5,2.98596466311311E-7,1,0.999253354069792,40.0298881530762,1.99103489129938,16.4800030738115,-0.000476591671080102,-0.000121125552242155,0.25,-3.33218327841345E-6,-4.47086763979467E-5,-3.44007279575167E-6,19.9987831,19.9989071,-13148.70703125,-13093.5244140625,53.1444862795441,18.7034523257685,6.1089461,0,0,0,4449,19.9852,-13121.1157226563,,,,,,,,,,,,,,,,,13.378378,,,,,,19.9988451,,,,
,15758327.65,19.9992771,-9153.6337890625,-5.43891843694303E-5,2.39577809464975E-7,1,0.999253354069792,40.0298881530762,1.99092923388363,16.4800030738115,-0.000578770305733326,-0.00013240159691717,0.25,-2.73041982830871E-6,-5.40672533035947E-5,-2.85775480997032E-6,19.9992237,19.9993305,-9186.072265625,-9121.1953125,53.015517573871,18.7004831557273,6.01831245,0,0,0,4449,19.9868,-9153.6337890625,,,,,,,,,,,,,,,,,12.252253,,,,,,19.9992771,,,,
,15758407.09,19.99932865,-5185.03784179687,-6.31871802356162E-5,2.95591656578143E-7,1,0.999253354069792,40.0298881530762,1.99093460198613,16.4800030738115,-0.000673104240237968,-0.000149522632368253,0.25,-2.78411332841185E-6,-6.28098979248564E-5,-2.92290165213903E-6,19.9992371,19.9994202,-5212.5146484375,-5157.56103515625,53.1038415965441,18.7006934482987,6.01831245,0,0,0,4449,19.9876,-5185.03784179687,,,,,,,,,,,,,,,,,13.378378,,,,,,19.99932865,,,,
,15758486,19.9994316,-1238.21948242188,-6.69723545431278E-5,2.85809518937953E-7,1,0.999253354069792,40.0298881530762,1.99102028117064,16.4800030738115,-0.000715175039193232,-0.000148496916068715,0.25,-2.03143911804079E-6,-6.65710270816958E-5,-2.17369580551362E-6,19.9993515,19.9995117,-1263.38696289062,-1213.05200195312,53.0413113150056,18.7001775665031,6.1089461,0,0,0,4449,19.9868,-1238.21948242188,,,,,,,,,,,,,,,,,13.378378,,,,,,19.9994316,,,,
,15758565.68,19.9995146,2737.45703125,-5.83691905830325E-5,2.41689434865548E-7,1,0.999253354069792,40.0298881530762,1.99091171818127,16.4700025320053,-0.000623141735716348,-0.000130227562529806,0.25,-1.84288425567863E-6,-5.80203441116963E-5,-1.96955489100559E-6,19.9994755,19.9995537,2709.95288085938,2764.96118164062,53.0209889735056,18.7008022795259,6.1089461,0,0,0,4449,19.987,2737.45703125,,,,,,,,,,,,,,,,,13.378378,,,,,,19.9995146,,,,
,15758645.15,19.99991035,6712.93701171875,-6.31472097808121E-5,2.62350119996436E-7,1,0.999253354069792,40.0298881530762,1.99092854207518,16.4800030738115,-0.00067458631572221,-0.000138701352307728,0.25,-1.77871987752019E-6,-6.27742539488282E-5,-1.92752642533441E-6,19.9998379,19.9999828,6685.47998046875,6740.39404296875,52.6153237720248,18.6999321289423,6.01831245,0,0,0,4449,19.9864,6712.93701171875,,,,,,,,,,,,,,,,,13.003003,,,,,,19.99991035,,,,
,15758722.995,20.0009327,10603.9223632813,-6.76301746998772E-5,2.6431293288949E-7,1,0.999253354069792,40.0298881530762,1.99099433416985,16.4700025320053,-0.000722833160254693,-0.000146979976403919,0.25,-1.74530678118977E-6,-6.72361819056698E-5,-1.91785399719894E-6,20.0009327,20.0009327,10573.9775390625,10633.8671875,52.8670081552171,18.6988168315624,6.01831245,0,0,0,4449,19.98775,10603.9223632813,,,,,,,,,,,,,,,,,12.252253,,,,,,20.0009327,,,,
,15758801.75,19.9998455,14542.2861328125,-6.73412996821312E-5,3.01087236294353E-7,1,0.999253354069792,40.0298881530762,1.99098089878514,16.4700025320053,-0.00071931122018037,-0.0001491532480304,0.25,-1.98467365699477E-6,-6.6954124539054E-5,-2.16811549224163E-6,19.9998226,19.9998684,14512.26953125,14572.302734375,52.9920687182941,18.6990762643934,5.9581923,0,0,0,4449,19.9862,14542.2861328125,,,,,,,,,,,,,,,,,13.378378,,,,,,19.9998455,,,,
,15758880.11,19.9999294,18457.580078125,-5.99855206033676E-5,3.27853981867219E-7,1,0.999253354069792,40.0298881530762,1.99088737298068,16.4800030738115,-0.000643213810949372,-0.000119084831309473,0.25,-4.72454711719837E-7,-5.96504231882042E-5,-6.54992038828722E-7,19.9998531,20.0000057,18430.1640625,18484.99609375,52.5496669764094,18.7004979606307,5.9581923,0,0,0,4449,19.9867,18457.580078125,,,,,,,,,,,,,,,,,13.378378,,,,,,19.9999294,,,,
,15758959.385,20.0015163,22420.8134765625,-4.65640973998339E-5,4.35060493546202E-7,1,0.999253354069792,40.0298881530762,1.99092892422878,16.4800030738115,-0.000498832422231898,-9.5458017204339E-5,0.25,-6.37205762472861E-7,-4.63083289338611E-5,-7.86836868259607E-7,20.0015163,20.0015163,22418.462890625,22423.1640625,52.6176686575825,18.6980812732878,6.01831245,0,0,0,4449,19.98535,22420.8134765625,,,,,,,,,,,,,,,,,13.753754,,,,,,20.0015163,,,,
,15759039.15,20.00082685,26405.8818359375,-3.21544209750196E-5,4.09983083075161E-7,1,0.999253354069792,40.0298881530762,1.99088649501851,16.4700025320053,-0.000345279293442894,-6.15323324044814E-5,0.25,-2.44921967644763E-8,-3.19831911622102E-5,-1.36616395483201E-7,20.0006714,20.0009823,26375.85546875,26435.908203125,52.6966131380248,18.6987861009762,5.9581923,0,0,0,4449,19.9842,26405.8818359375,,,,,,,,,,,,,,,,,13.378378,,,,,,20.00082685,,,,
,15759118.195,19.99999905,30356.677734375,-2.57430370791365E-5,5.09467908517098E-7,1,0.999253354069792,40.0298881530762,1.99106623321124,16.4700025320053,-0.000275074452260365,-5.726457916761E-5,0.25,-7.58318532368924E-7,-2.56066725388269E-5,-8.49417426669462E-7,19.9997177,20.0002804,30324.09765625,30389.2578125,52.9326649508325,18.6962731990614,6.1394596,0,0,0,4449,19.9857,30356.677734375,,,,,,,,,,,,,,,,,13.378378,,,,,,19.99999905,,,,
,15759196.54,20.00081065,34272.126953125,-2.61412307837328E-5,5.65984224728122E-7,1,0.999253354069792,40.0298881530762,1.9908432929865,16.4700025320053,-0.000280302573340991,-5.27302327119685E-5,0.25,-2.60135247876614E-7,-2.60083076563839E-5,-3.60457489283539E-7,20.0006409,20.0009804,34242.26953125,34301.984375,52.8591918700248,18.6989008614822,6.01831245,0,0,0,4449,19.98445,34272.126953125,,,,,,,,,,,,,,,,,13.378378,,,,,,20.00081065,,,,
,15759275.66,20.00004575,38224.88671875,-2.90046976104366E-5,6.87102391411686E-7,1,0.999253354069792,40.0298881530762,1.99100555160324,16.4800030738115,-0.000308378799821877,-7.36789143062193E-5,0.25,-1.69396506418343E-6,-2.88558466104213E-5,-1.80408613165081E-6,19.9998207,20.0002708,38199.9609375,38249.8125,52.8208920725825,18.6977695611717,6.0784326,0,0,0,4449,19.98145,38224.88671875,,,,,,,,,,,,,,,,,13.003003,,,,,,20.00004575,,,,
,15759354.05,19.9988594,42143.34765625,-3.62192703430224E-5,5.81116582786986E-7,1,0.999253354069792,40.0298881530762,1.99112341599497,16.4700025320053,-0.000391808833448204,-5.47409279274632E-5,0.25,1.3611703770849E-6,-3.60536291088638E-5,1.20004096356654E-6,19.9985924,19.9991264,42113.44921875,42173.24609375,52.6958315095056,18.6954103501928,6.1394596,0,0,0,4449,19.98395,42143.34765625,,,,,,,,,,,,,,,,,12.252253,,,,,,19.9988594,,,,
,15759432.815,19.99877355,46079.03515625,-4.20654471201281E-5,6.20360782740767E-7,1,0.999253354069792,40.0298881530762,1.99129528415412,16.4700025320053,-0.000448289452397688,-0.000102148231117747,0.25,-1.99855112801366E-6,-4.1864493829845E-5,-2.17680521199391E-6,19.998661,19.9988861,46056.6484375,46101.421875,52.9905054612556,18.6909867821372,6.1089461,0,0,0,4449,19.98605,46079.03515625,,,,,,,,,,,,,,,,,13.753754,,,,,,19.99877355,,,,
,15759510.1,19.99895475,49942.220703125,-5.33477959781988E-5,6.51195520636776E-7,1,0.999253354069792,40.0298881530762,1.99107400856028,16.4800030738115,-0.000573230874843315,-0.000103397140894174,0.25,-9.18065382547573E-8,-5.31129956326011E-5,-3.38323441794462E-7,19.9988613,19.9990482,49909.671875,49974.76953125,52.7403843351017,18.6964527978275,6.1702795,0,0,0,4449,19.9855,49942.220703125,,,,,,,,,,,,,,,,,13.003003,,,,,,19.99895475,,,,
,15759587.925,19.9984369,53832.748046875,-6.56323818781431E-5,6.48232559829671E-7,1,0.999253354069792,40.0298881530762,1.99127426938974,16.4700025320053,-0.000704826629683768,-0.000130591584244239,0.25,-4.13464217382601E-7,-6.53538583823258E-5,-7.265607174243E-7,19.9983444,19.9985294,53802.80859375,53862.6875,52.9232854086018,18.6909976194142,6.1089461,0,0,0,4449,19.98695,53832.748046875,,,,,,,,,,,,,,,,,13.378378,,,,,,19.9984369,,,,
,15759667.265,19.9992924,57797.8515625,-7.60934724819247E-5,7.22853540957099E-7,1,0.999253354069792,40.0298881530762,1.99103456744979,16.4700025320053,-0.000819683108273782,-0.000137713123314195,0.25,8.07783236912918E-7,-7.57912649452305E-5,4.27024702773892E-7,19.9992676,19.9993172,57770.2421875,57825.4609375,52.7630515621594,18.6965127615961,6.04882595,0,0,0,4449,19.9863,57797.8515625,,,,,,,,,,,,,,,,,13.378378,,,,,,19.9992924,,,,
,15759745.635,19.9986382,61713.98046875,-8.55239978314367E-5,8.31655838724822E-7,1,0.999253354069792,40.0298881530762,1.9908869113576,16.4800030738115,-0.000920773478651025,-0.000158213337259209,0.25,6.03586257737702E-7,-8.51993603487212E-5,1.63798472208417E-7,19.9986382,19.9986382,61709.1015625,61718.859375,52.5981279446017,18.6970236216718,5.9581923,0,0,0,4449,19.9877,61713.98046875,,,,,,,,,,,,,,,,,13.003003,,,,,,19.9986382,,,,
,15759822.895,19.999506,65577.11328125,-9.61720285782799E-5,8.82348698382942E-7,1,0.999253354069792,40.0298881530762,1.99082910750602,16.4700025320053,-0.00103619001087835,-0.000174583502627521,0.25,1.00478002461612E-6,-9.5827445832947E-5,4.95345426450837E-7,19.9993649,19.9996471,65547.2734375,65606.953125,52.4801020381979,18.6978872439882,6.1394596,0,0,0,4449,19.9869,65577.11328125,,,,,,,,,,,,,,,,,13.378378,,,,,,19.999506,,,,
,15759899.695,19.99885845,69415.8046875,-0.000107719230275987,6.44587620066016E-7,1,0.999253354069792,40.0298881530762,1.99083202562058,16.4800030738115,-0.00115838526873653,-0.000209249183359604,0.25,-1.30522116582173E-7,-0.000107347824829924,-7.11093280793659E-7,19.9988384,19.9988785,69390.8515625,69440.7578125,52.4980794941402,18.6991627391674,6.1089461,0,0,0,4449,19.98785,69415.8046875,,,,,,,,,,,,,,,,,13.378378,,,,,,19.99885845,,,,
,15759979.955,19.9993372,73426.10546875,-0.000119595038132203,1.0695634871055E-6,1,0.999253354069792,40.0298881530762,1.99079363952607,16.4700025320053,-0.00128825849534418,-0.000221683158657318,0.25,8.63502246741789E-7,-0.000119213185236318,1.99877715217819E-7,19.9990883,19.9995861,73398.40625,73453.8046875,52.8349613859287,18.7016773313105,6.0784326,0,0,0,4449,19.9875,73426.10546875,,,,,,,,,,,,,,,,,13.003003,,,,,,19.9993372,,,,
,15760061.275,19.9991112,77494.20703125,-0.000131787103681079,9.8711529990074E-7,1,0.999253354069792,40.0298881530762,1.99077254972225,16.4700025320053,-0.00141711664846125,-0.000259730055644756,0.25,-4.63183804333576E-7,-0.00013138668964318,-1.20634745918143E-6,19.9991112,19.9991112,77491.6328125,77496.78125,52.7755576184671,18.6994668282557,6.1394596,0,0,0,4449,19.9883,77494.20703125,,,,,,,,,,,,,,,,,13.378378,,,,,,19.9991112,,,,
,15760140.7,19.998765,81462.37109375,-0.000142335320138428,1.01745754160417E-6,1,0.999253354069792,40.0298881530762,1.99093703410937,16.4800030738115,-0.0015323275390239,-0.000273136896933402,0.25,2.08957991697619E-7,-0.000141936911575855,-6.11699811926524E-7,19.9986477,19.9988823,81429.703125,81495.0390625,52.8349613859287,18.6933447220226,6.1394596,0,0,0,4449,19.9893,81462.37109375,,,,,,,,,,,,,,,,,12.252253,,,,,,19.998765,,,,
,15760220,19.9990616,85425.44921875,-0.000152990785502721,9.48421092375741E-7,1,0.999253354069792,40.0298881530762,1.99076471014656,16.4800030738115,-0.00164597180250773,-0.000300767604325485,0.25,-4.23608695162663E-7,-0.000152591188039952,-1.3196585953026E-6,19.9988766,19.9992466,85397.890625,85453.0078125,52.7552352769671,18.6978263115709,6.01831245,0,0,0,4449,19.9889,85425.44921875,,,,,,,,,,,,,,,,,13.378378,,,,,,19.9990616,,,,
,15760299.585,19.9986601,89403.1875,-0.000167282890518795,1.0092896412606E-6,1,0.999253354069792,40.0298881530762,1.99098638996988,16.4700025320053,-0.00180142917288693,-0.000322749550283523,0.25,1.30032851730902E-7,-0.000166885133123496,-8.66932204395781E-7,19.9986496,19.9986706,89370.671875,89435.703125,52.7036477946979,18.6936464132453,6.01831245,0,0,0,4449,19.99005,89403.1875,,,,,,,,,,,,,,,,,12.252253,,,,,,19.9986601,,,,
,15760312.515,19.9993935,89999.4375,-0.000167229795568328,1.12605704649138E-6,1,0.999253354069792,40.0298881530762,1.99089177002455,16.4700025320053,-0.00179819156475852,-0.000337328303057019,0.25,-1.23171622998805E-6,-0.000166829385823759,-2.22738307463295E-6,19.9993935,19.9993935,89999.4296875,89999.4453125,52.8552837274287,18.6972334526481,5.9581923,0,0,0,4417,19.9914,89999.4375,,,,,,,,,,,,,,,,,13.003003,,,,,,19.9993935,,,,