File: data/doubleLayers/dl_0-25/ppms/DD205_10_HYST_300K.DAT
[Header]
; VSM Data File (default extension .dat)
; Copyright (c) 2003, Quantum Design, Inc. All rights reserved.
TITLE,
FILEOPENTIME,15773636.39,04/18/2018,7:08 am
BYAPP,VSM,1.0,1.0
INFO,PPMS VSM Option Release 1.3.7 Build 2,APPNAME
INFO,291,COIL_SERIAL_NUMBER
INFO,0,MOMENT_UNITS
INFO,,SAMPLE_MATERIAL
INFO,,SAMPLE_COMMENT
INFO,,SAMPLE_MASS
INFO,,SAMPLE_VOLUME
INFO,,SAMPLE_MOLECULAR_WEIGHT
INFO,,SAMPLE_SIZE
INFO,,SAMPLE_SHAPE
INFO,35.28,SAMPLE_OFFSET
DATATYPE,COMMENT,1
DATATYPE,TIME,2
STARTUPAXIS,X,2
STARTUPAXIS,Y1,5
[Data]
Comment,Time Stamp (sec),Temperature (K),Magnetic Field (Oe),Moment (emu),M. Std. Err. (emu),Transport Action,Averaging Time (sec),Frequency (Hz),Peak Amplitude (mm),Center Position (mm),Coil Signal' (mV),Coil Signal" (mV),Range (mV),M. Quad. Signal (emu),M. Raw' (emu),M. Raw" (emu),Min. Temperature (K),Max. Temperature (K),Min. Field (Oe),Max. Field (Oe),Mass (grams),Motor Lag (deg),Pressure (Torr),VSM Status (code),Motor Status (code),Measure Status (code),PPMS Status (code),System Temp. (K),System Field (Oe),Sample Position (deg),Bridge 1 Resistance (ohms),Bridge 1 Excitation (에),Bridge 2 Resistance (ohms),Bridge 2 Excitation (에),Bridge 3 Resistance (ohms),Bridge 3 Excitation (에),Bridge 4 Resistance (ohms),Bridge 4 Excitation (에),Signal 1 Vin (V),Signal 2 Vin (V),Digital Inputs (code),Drive 1 Iout (mA),Drive 1 Ipower (W),Drive 2 Iout (mA),Drive 2 Ipower (W),Pressure (),Map 20 (),Map 21 (),Map 22 (),Map 23 (),Map 24 (),Map 25 (),Map 26 (),Map 27 (),Map 28 (),Map 29 ()
,15774120.37,300.09140015,89999.77734375,-0.000178922569387208,7.42480094926588E-7,1,0.999253354069792,40.0298881530762,1.99059861065022,16.4800030738115,-0.00192665626978492,-0.000370496032040712,0.25,-3.08710831032013E-6,-0.000178914315766529,-3.20174210914513E-6,300.0906067,300.0921936,89999.75,89999.8046875,52.3761454451402,18.6785314871833,11.8706312,0,0,0,4417,300.50195,89999.77734375,,,,,,,,,,,,,,,,,13.003003,,,,,,300.09140015,,,,
,15774152.44,300.0823364,86866.33984375,-0.000168926620272265,9.40056044107986E-7,1,0.999253354069792,40.0298881530762,1.99056377206637,16.4800030738115,-0.00181991161631127,-0.000344505315909911,0.25,-2.42512742678008E-6,-0.000168919184683866,-2.53342879863732E-6,300.0820007,300.0826721,86856.5234375,86876.15625,52.7442924776979,18.6816613150463,11.63639405,0,0,0,4449,300.47565,86866.33984375,,,,,,,,,,,,,,,,,13.003003,,,,,,300.0823364,,,,
,15774169.915,300.0762787,83449.01171875,-0.000158580165354465,8.88979696211692E-7,1,0.999253354069792,40.0298881530762,1.99061629301119,16.4800030738115,-0.00170649516496365,-0.00033483574950336,0.25,-3.33412932619723E-6,-0.000158572531582323,-3.43581008493619E-6,300.0761414,300.076416,83322.1953125,83575.828125,52.4363308411209,18.6803261636952,11.69539165,0,0,0,4449,300.4625,83449.01171875,,,,,,,,,,,,,,,,,13.003003,,,,,,300.0762787,,,,
,15774187.085,300.06744385,80089.328125,-0.000149230394948634,1.00437271557932E-6,1,0.999253354069792,40.0298881530762,1.99067062252672,16.4800030738115,-0.00160423725778209,-0.000324765561575952,0.25,-4.03217514384869E-6,-0.00014922267374378,-4.1278748926286E-6,300.0674133,300.0674744,79962.6171875,80216.0390625,52.3175233061978,18.6780843280309,11.69539165,0,0,0,4449,300.45225,80089.328125,,,,,,,,,,,,,,,,,12.252253,,,,,,300.06744385,,,,
,15774204.24,300.0587769,76740.5703125,-0.00013993518219375,8.20328769454854E-7,1,0.999253354069792,40.0298881530762,1.99069718285487,16.4700025320053,-0.00150485635047456,-0.000301537253648779,0.25,-3.50292685484167E-6,-0.000139928154891982,-3.59271283643769E-6,300.0587769,300.0587769,76721.15625,76759.984375,52.5012060082171,18.6787385966362,11.8706312,0,0,0,4449,300.4538,76740.5703125,,,,,,,,,,,,,,,,,13.378378,,,,,,300.0587769,,,,
,15774220.92,300.05038455,73488.58984375,-0.000128917290694904,8.68106276612098E-7,1,0.999253354069792,40.0298881530762,1.9907085204356,16.4800030738115,-0.00138681305216482,-0.000275304851111431,0.25,-2.99635010016487E-6,-0.000128910995314489,-3.07911099040502E-6,300.0488892,300.0518799,73381.1953125,73595.984375,52.4808836667171,18.6796930915675,11.63639405,0,0,0,4449,300.44575,73488.58984375,,,,,,,,,,,,,,,,,13.003003,,,,,,300.05038455,,,,
,15774237.965,300.04148865,70158.92578125,-0.000119616166747542,8.53573034577922E-7,1,0.999253354069792,40.0298881530762,1.99061226974844,16.4700025320053,-0.00128417111599494,-0.000269919135492739,0.25,-4.1215850587203E-6,-0.000119609493317019,-4.19836194813188E-6,300.0413513,300.041626,70041.796875,70276.0546875,52.3136151636017,18.6846646931083,11.63639405,0,0,0,4449,300.44485,70158.92578125,,,,,,,,,,,,,,,,,13.378378,,,,,,300.04148865,,,,
,15774254.68,300.0335388,66897.2734375,-0.000111076603567396,8.66727250438911E-7,1,0.999253354069792,40.0298881530762,1.99051192369093,16.4800030738115,-0.00119451849637937,-0.000238700843802944,0.25,-2.72209662912933E-6,-0.000111071142228927,-2.79345733010154E-6,300.0333557,300.0337219,66780,67014.546875,52.5535751190056,18.6841998353797,11.8706312,0,0,0,4449,300.448,66897.2734375,,,,,,,,,,,,,,,,,13.378378,,,,,,300.0335388,,,,
,15774272.435,300.02944945,63430.80078125,-9.97962246634611E-5,7.43738197823562E-7,1,0.999253354069792,40.0298881530762,1.990672420985,16.4800030738115,-0.00107144580942043,-0.000225051641414842,0.25,-3.42477051144721E-6,-9.97906977479326E-5,-3.48887766644581E-6,300.0289001,300.0299988,63401.578125,63460.0234375,52.3589496177171,18.6813120365625,11.8706312,0,0,0,4449,300.45095,63430.80078125,,,,,,,,,,,,,,,,,12.252253,,,,,,300.02944945,,,,
,15774288.49,300.0260925,60279.25390625,-9.04549199909191E-5,7.86997020658173E-7,1,0.999253354069792,40.0298881530762,1.99071504572288,16.4800030738115,-0.000970579243670969,-0.000207399645229589,0.25,-3.41984091830402E-6,-9.04497140245506E-5,-3.47795902148E-6,300.0257263,300.0264587,60171.55859375,60386.94921875,52.3159600491594,18.681362638688,11.8706312,0,0,0,4449,300.45025,60279.25390625,,,,,,,,,,,,,,,,,13.003003,,,,,,300.0260925,,,,
,15774305.48,300.0205841,56960.603515625,-8.1165730167008E-5,9.04902076872191E-7,1,0.999253354069792,40.0298881530762,1.99071655853269,16.4800030738115,-0.000871162079383288,-0.000184640172293674,0.25,-2.93336914407743E-6,-8.11611574607236E-5,-2.98554436284441E-6,300.0205688,300.0205994,56843.3203125,57077.88671875,52.2878214224671,18.6801309833437,11.69539165,0,0,0,4449,300.4489,56960.603515625,,,,,,,,,,,,,,,,,13.003003,,,,,,300.0205841,,,,
,15774322.19,300.01504515,53692.21484375,-7.19497453009996E-5,8.20493634570864E-7,1,0.999253354069792,40.0298881530762,1.9907193957647,16.4700025320053,-0.000770759015504922,-0.000172203383422995,0.25,-3.38981931789671E-6,-7.19451936914022E-5,-3.43606130641853E-6,300.0142822,300.0158081,53594.23046875,53790.19921875,52.7489822488133,18.6799440152244,11.69539165,0,0,0,4449,300.454,53692.21484375,,,,,,,,,,,,,,,,,13.003003,,,,,,300.01504515,,,,
,15774338.925,300.01185605,50413.462890625,-6.2269018417769E-5,6.13960391817168E-7,1,0.999253354069792,40.0298881530762,1.99071521394747,16.4800030738115,-0.000666141973833116,-0.00015425681034289,0.25,-3.41730315938299E-6,-6.22647716635872E-5,-3.45732307922426E-6,300.0110168,300.0126953,50305.62109375,50521.3046875,52.738039449544,18.6812269935291,11.69539165,0,0,0,4449,300.4519,50413.462890625,,,,,,,,,,,,,,,,,13.003003,,,,,,300.01185605,,,,
,15774355.585,300.00805665,47144.146484375,-5.32421853323567E-5,6.85983517903449E-7,1,0.999253354069792,40.0298881530762,1.99072539808836,16.4800030738115,-0.000570795964079561,-0.000124911540439237,0.25,-2.2753050464089E-6,-5.3238975686566E-5,-2.30955718388314E-6,300.0073853,300.008728,47016.90625,47271.38671875,52.5137120645248,18.68214743191,11.8706312,0,0,0,4449,300.45495,47144.146484375,,,,,,,,,,,,,,,,,13.378378,,,,,,300.00805665,,,,
,15774372.315,300.00257875,43875.03515625,-4.35645724308525E-5,4.99825338010653E-7,1,0.999253354069792,40.0298881530762,1.99083695464336,16.4800030738115,-0.000465526865965673,-0.000111053974750052,0.25,-2.68025568156728E-6,-4.356142456905E-5,-2.70826521403259E-6,300.0024109,300.0027466,43787.01953125,43963.05078125,52.3855249873709,18.6806960499894,11.752636,0,0,0,4449,300.46025,43875.03515625,,,,,,,,,,,,,,,,,12.627627,,,,,,300.00257875,,,,
,15774389.47,300.0005035,40508.552734375,-3.44480720296838E-5,6.18615674393854E-7,1,0.999253354069792,40.0298881530762,1.9908631289645,16.4700025320053,-0.000367330639804045,-9.23018565340835E-5,0.25,-2.53469740722939E-6,-3.44453159634939E-5,-2.55684000629726E-6,300.000061,300.000946,40400.7890625,40616.31640625,52.893583524871,18.6805246574033,11.8128128,0,0,0,4449,300.46405,40508.552734375,,,,,,,,,,,,,,,,,13.753754,,,,,,300.0005035,,,,
,15774405.55,300.000885,37366.453125,-2.48563305433349E-5,6.56659754906984E-7,1,0.999253354069792,40.0298881530762,1.99086169583913,16.4700025320053,-0.000264275612202294,-7.10436410552018E-5,0.25,-2.24018908935683E-6,-2.48540752590387E-5,-2.25615797529648E-6,300.0007019,300.0010681,37229.515625,37503.390625,52.3753638166209,18.6797599692762,11.8706312,0,0,0,4449,300.46885,37366.453125,,,,,,,,,,,,,,,,,13.378378,,,,,,300.000885,,,,
,15774422.36,300.00039675,34077.986328125,-1.6232065183207E-5,6.18349301949762E-7,1,0.999253354069792,40.0298881530762,1.99075111933596,16.4700025320053,-0.000170258066445339,-5.96558164442612E-5,0.25,-2.69092797751824E-6,-1.62297990897243E-5,-2.70132008680809E-6,299.9998169,300.0009766,33980.19140625,34175.78125,52.4910448374671,18.6820981265466,11.87122395,0,0,0,4449,300.46355,34077.986328125,,,,,,,,,,,,,,,,,13.378378,,,,,,300.00039675,,,,
,15774440.165,299.9976044,30593.63671875,-5.99755549742242E-6,6.77000075304171E-7,1,0.999253354069792,40.0298881530762,1.99085967451093,16.4800030738115,-6.05034918930231E-5,-3.58453550470131E-5,0.25,-2.27200425434646E-6,-5.99589310806871E-6,-2.27580399417337E-6,299.9971619,299.9980469,30495.70703125,30691.56640625,52.7216252506402,18.6789666019283,11.75322245,0,0,0,4449,300.46035,30593.63671875,,,,,,,,,,,,,,,,,13.378378,,,,,,299.9976044,,,,
,15774458.18,299.9951477,27060.494140625,2.68402827193801E-6,3.06121300327973E-7,1,0.999253354069792,40.0298881530762,1.99084755749794,16.4800030738115,3.46429959244026E-5,-2.73271199202353E-5,0.25,-2.99813060938099E-6,2.68587817875247E-6,-2.99629923373346E-6,299.9951172,299.9951782,26972.4375,27148.55078125,52.8896753822748,18.682776707641,11.8706312,0,0,0,4449,300.4695,27060.494140625,,,,,,,,,,,,,,,,,13.753754,,,,,,299.9951477,,,,
,15774474.99,299.9952393,23771.8662109375,1.18747179330666E-5,4.51558562460299E-7,1,0.999253354069792,40.0298881530762,1.99092296139065,16.4800030738115,0.000133785028227662,-9.205566178805E-6,0.25,-2.9239969310696E-6,1.18762219915261E-5,-2.916227653091E-6,299.9950562,299.9954224,23664.251953125,23879.48046875,52.209658570544,18.68018693078,11.8706312,0,0,0,4449,300.4735,23771.8662109375,,,,,,,,,,,,,,,,,13.378378,,,,,,299.9952393,,,,
,15774492.15,299.99479675,20414.6552734375,1.92483679116929E-5,4.60152950210647E-7,1,0.999253354069792,40.0298881530762,1.99085421918781,16.4800030738115,0.000212700202327019,8.87658682287071E-6,0.25,-2.53655443735566E-6,1.92493825058844E-5,-2.52402830461881E-6,299.9942017,299.9953918,20297.380859375,20531.9296875,52.6575317120633,18.6808159722486,11.93022155,0,0,0,4449,300.4737,20414.6552734375,,,,,,,,,,,,,,,,,12.252253,,,,,,299.99479675,,,,
,15774508.28,299.99440005,17253.6123046875,2.85353765559493E-5,3.53680068284103E-7,1,0.999253354069792,40.0298881530762,1.99095159170977,16.4800030738115,0.000313356946072286,2.45200506570645E-5,0.25,-2.70878450923124E-6,2.85362011534439E-5,-2.69024343881339E-6,299.9938965,299.9949036,17165.466796875,17341.7578125,52.3128335350824,18.6800532202882,11.754982,0,0,0,4449,300.474,17253.6123046875,,,,,,,,,,,,,,,,,13.378378,,,,,,299.99440005,,,,
,15774526.53,299.9942932,13689.6362304687,3.63657196814809E-5,3.91736783843031E-7,1,0.999253354069792,40.0298881530762,1.99092542634041,16.4800030738115,0.000397441304327468,4.21290967485677E-5,0.25,-2.44482584325954E-6,3.63661190644535E-5,-2.42122258611039E-6,299.9942932,299.9942932,13679.732421875,13699.5400390625,52.7974432170056,18.6812964594733,11.9898119,0,0,0,4449,300.4793,13689.6362304687,,,,,,,,,,,,,,,,,12.252253,,,,,,299.9942932,,,,
,15774542.17,299.9929047,10614.1352539062,4.29047762373807E-5,3.20459967503244E-7,1,0.999253354069792,40.0298881530762,1.99098516348848,16.4800030738115,0.000468714456267104,5.08840028083279E-5,0.25,-2.77538886569453E-6,4.29051785418336E-5,-2.74753775771448E-6,299.9924927,299.9933167,10506.4775390625,10721.79296875,52.2940744506209,18.6810791500551,11.63639405,0,0,0,4449,300.47965,10614.1352539062,,,,,,,,,,,,,,,,,13.753754,,,,,,299.9929047,,,,
,15774559.1,299.99266055,7303.02099609375,4.89107090345338E-5,3.97385234757256E-7,1,0.999253354069792,40.0298881530762,1.99094611297724,16.4800030738115,0.000533474903536611,6.2829788958934E-5,0.25,-2.71733979438774E-6,4.89108787112855E-5,-2.6855959908826E-6,299.9920044,299.9933167,7175.638671875,7430.4033203125,52.6278298283325,18.6826179823196,11.75322245,0,0,0,4449,300.4793,7303.02099609375,,,,,,,,,,,,,,,,,12.252253,,,,,,299.99266055,,,,
,15774577.045,299.9927673,3785.60095214844,5.0578229344208E-5,3.38070500087871E-7,1,0.999253354069792,40.0298881530762,1.99091507916252,16.4700025320053,0.000550927111209538,6.91406913815959E-5,0.25,-2.42397899137697E-6,5.05781543780857E-5,-2.3911574180292E-6,299.9926147,299.9929199,3687.62548828125,3883.57641601562,52.8255818436979,18.6845605341359,11.8706312,0,0,0,4449,300.48245,3785.60095214844,,,,,,,,,,,,,,,,,13.378378,,,,,,299.9927673,,,,
,15774593.195,299.9945831,617.270492553711,3.70995843850513E-5,4.24418055595245E-7,1,0.999253354069792,40.0298881530762,1.99095361772192,16.4800030738115,0.000405272399947255,4.40958897188798E-5,0.25,-2.39087136913418E-6,3.70999238130096E-5,-2.36677188003719E-6,299.9942932,299.994873,489.796966552734,744.744018554687,52.3222130773132,18.6822606706385,11.75322245,0,0,0,4449,300.48335,617.270492553711,,,,,,,,,,,,,,,,,13.753754,,,,,,299.9945831,,,,
,15774609.32,299.995636,-2528.63391113281,-4.54756758866232E-5,4.44471066990813E-7,1,0.999253354069792,40.0298881530762,1.99090649756812,16.4700025320053,-0.000487231983841333,-0.000108665804513191,0.25,-2.12529124527733E-6,-4.54728171048796E-5,-2.15466444206524E-6,299.995575,299.995697,-2606.46606445313,-2450.8017578125,52.3698924169863,18.683776691664,11.87122395,0,0,0,4449,300.47785,-2528.63391113281,,,,,,,,,,,,,,,,,13.003003,,,,,,299.995636,,,,
,15774626.68,299.99804685,-5933.79809570312,-4.84510898074912E-5,3.75055845495876E-7,1,0.999253354069792,40.0298881530762,1.99099870393601,16.4800030738115,-0.000519574782773119,-0.000113251945268061,0.25,-2.03026577297087E-6,-4.84481927746467E-5,-2.06156135928929E-6,299.9979553,299.9981384,-6041.673828125,-5825.92236328125,52.7036477946979,18.6837629982899,11.6358137,0,0,0,4449,300.4744,-5933.79809570312,,,,,,,,,,,,,,,,,13.378378,,,,,,299.99804685,,,,
,15774643.98,299.9979248,-9325.376953125,-4.47986444715421E-5,4.06344336215433E-7,1,0.999253354069792,40.0298881530762,1.99100720976087,16.4800030738115,-0.000480863896241344,-0.000102107813367341,0.25,-1.63588203317619E-6,-4.47961233787886E-5,-1.66481793072089E-6,299.9979248,299.9979248,-9335.1123046875,-9315.6416015625,52.4722857530055,18.6846688580493,11.8706312,0,0,0,4449,300.4809,-9325.376953125,,,,,,,,,,,,,,,,,13.378378,,,,,,299.9979248,,,,
,15774660.22,300.0013733,-12500.431640625,-3.79267224806309E-5,5.07139100763507E-7,1,0.999253354069792,40.0298881530762,1.99096970504655,16.4800030738115,-0.000405993262042324,-9.27531340541979E-5,0.25,-1.96905240271141E-6,-3.79242069248644E-5,-1.99352392144602E-6,300.0012207,300.0015259,-12627.7021484375,-12373.1611328125,52.7739943614286,18.6849469459422,11.93022155,0,0,0,4449,300.4803,-12500.431640625,,,,,,,,,,,,,,,,,13.003003,,,,,,300.0013733,,,,
,15774678.2,300.00590515,-16038.2294921875,-2.96240104526491E-5,4.47105786204005E-7,1,0.999253354069792,40.0298881530762,1.99109239690636,16.4700025320053,-0.000315866175858081,-7.97178661599133E-5,0.25,-2.21054283358424E-6,-2.96216071790772E-5,-2.22962922211731E-6,300.0056763,300.006134,-16136.2001953125,-15940.2587890625,52.9553321778902,18.682355166181,11.63639405,0,0,0,4449,300.47575,-16038.2294921875,,,,,,,,,,,,,,,,,13.378378,,,,,,300.00590515,,,,
,15774695.07,300.0097351,-19330.1533203125,-2.19260346657501E-5,5.22425535397153E-7,1,0.999253354069792,40.0298881530762,1.99103686578036,16.4700025320053,-0.000233082453982863,-6.30008644094234E-5,0.25,-2.0063700171853E-6,-2.19240145009722E-5,-2.02048038014727E-6,300.0091858,300.0102844,-19447.7890625,-19212.517578125,52.7325680499094,18.6830910652428,11.93022155,0,0,0,4449,300.46895,-19330.1533203125,,,,,,,,,,,,,,,,,13.753754,,,,,,300.0097351,,,,
,15774712.245,300.011261,-22701.15234375,-1.38001302172964E-5,5.76943305388431E-7,1,0.999253354069792,40.0298881530762,1.99117277247324,16.4700025320053,-0.000145061294850398,-4.91063675740781E-5,0.25,-2.1376425748915E-6,-1.37982930623867E-5,-2.14649214351891E-6,300.011261,300.011261,-22720.732421875,-22681.572265625,52.5543567475248,18.6799853158195,11.8706312,0,0,0,4449,300.4585,-22701.15234375,,,,,,,,,,,,,,,,,13.378378,,,,,,300.011261,,,,
,15774729.07,300.0113525,-26002.931640625,-4.68986564662148E-6,7.51951720891116E-7,1,0.999253354069792,40.0298881530762,1.99109174771604,16.4800030738115,-4.55579158386017E-5,-3.81131457508845E-5,0.25,-2.70971433663849E-6,-4.68795999510197E-6,-2.712655449256E-6,300.0113525,300.0113525,-26032.3203125,-25973.54296875,52.9287568082364,18.681796580221,11.93022155,0,0,0,4449,300.4547,-26002.931640625,,,,,,,,,,,,,,,,,13.003003,,,,,,300.0113525,,,,
,15774745.595,300.0131683,-29246.62109375,3.90356980209301E-6,3.50942105797071E-7,1,0.999253354069792,40.0298881530762,1.99114901301904,16.4800030738115,4.63732425033484E-5,-1.67219382721534E-5,0.25,-2.22889817654462E-6,3.90488071800619E-6,-2.22630294825071E-6,300.0130615,300.0132751,-29344.46484375,-29148.77734375,52.5215283497171,18.67953752272,11.8128128,0,0,0,4449,300.44995,-29246.62109375,,,,,,,,,,,,,,,,,13.378378,,,,,,300.0131683,,,,
,15774762.93,300.0180359,-32638.1162109375,1.24658184138368E-5,4.7389222049319E-7,1,0.999253354069792,40.0298881530762,1.99104923637357,16.4700025320053,0.000137968682419307,4.57398699419009E-6,0.25,-1.75153208295011E-6,1.24665361500228E-5,-1.74342424595256E-6,300.0180359,300.0180359,-32657.669921875,-32618.5625,52.9350098363902,18.6836297602908,11.93022155,0,0,0,4449,300.4523,-32638.1162109375,,,,,,,,,,,,,,,,,12.252253,,,,,,300.0180359,,,,
,15774780.18,300.0226288,-36022.08203125,2.16015259214968E-5,5.25035656217678E-7,1,0.999253354069792,40.0298881530762,1.99103516687027,16.4700025320053,0.000237186788192061,1.87706489971059E-5,0.25,-2.03129055575517E-6,2.16021182546781E-5,-2.01727828710159E-6,300.0224915,300.0227661,-36110.31640625,-35933.84765625,52.8333981288902,18.6834498101513,11.75322245,0,0,0,4449,300.44285,-36022.08203125,,,,,,,,,,,,,,,,,13.003003,,,,,,300.0226288,,,,
,15774796.69,300.0258484,-39268.767578125,3.12282562939524E-5,5.50414729929746E-7,1,0.999253354069792,40.0298881530762,1.99112748262543,16.4700025320053,0.000342647644184615,2.86071835139324E-5,0.25,-2.80044228011498E-6,3.12290215832359E-5,-2.78019571323688E-6,300.0258484,300.0258484,-39288.39453125,-39249.140625,52.5426323197363,18.6820318841876,11.8128128,0,0,0,4449,300.4297,-39268.767578125,,,,,,,,,,,,,,,,,13.753754,,,,,,300.0258484,,,,
,15774813.36,300.02648925,-42535.27734375,3.98633759790195E-5,6.08552229780429E-7,1,0.999253354069792,40.0298881530762,1.99097659567188,16.4800030738115,0.000434254216813947,5.43390342970676E-5,0.25,-1.92481153087595E-6,3.98632876959378E-5,-1.899030209654E-6,300.026123,300.0268555,-42643.1953125,-42427.359375,52.7630515621594,18.6858866479,11.6358137,0,0,0,4449,300.42505,-42535.27734375,,,,,,,,,,,,,,,,,13.378378,,,,,,300.02648925,,,,
,15774830.015,300.02691655,-45811.724609375,4.89310055076222E-5,5.92169915836836E-7,1,0.999253354069792,40.0298881530762,1.99113536394979,16.4700025320053,0.000533402456609564,6.48166803976923E-5,0.25,-2.53737106270429E-6,4.89310096548051E-5,-2.50572890184167E-6,300.026825,300.0270081,-45939.33984375,-45684.109375,52.8920202678325,18.6829274651399,11.8128128,0,0,0,4449,300.40845,-45811.724609375,,,,,,,,,,,,,,,,,13.003003,,,,,,300.02691655,,,,
,15774848.445,300.0251465,-49421.837890625,5.89727572751914E-5,6.9527532646517E-7,1,0.999253354069792,40.0298881530762,1.99117076273036,16.4700025320053,0.000642216503055421,8.19202273964057E-5,0.25,-2.70631045989461E-6,5.89725395970314E-5,-2.66820198233708E-6,300.0251465,300.0251465,-49451.09765625,-49392.578125,52.954550549371,18.6825558698646,11.8706312,0,0,0,4449,300.4084,-49421.837890625,,,,,,,,,,,,,,,,,13.378378,,,,,,300.0251465,,,,
,15774866.73,300.0238037,-53001.572265625,6.96319862872969E-5,6.70574895612771E-7,1,0.999253354069792,40.0298881530762,1.99117782998839,16.4700025320053,0.000757001236392124,0.000104163864845959,0.25,-2.50713147996986E-6,6.96312896158351E-5,-2.46217502636558E-6,300.0238037,300.0238037,-53021.171875,-52981.97265625,52.791971817371,18.6821720768606,11.8128128,0,0,0,4449,300.40095,-53001.572265625,,,,,,,,,,,,,,,,,12.252253,,,,,,300.0238037,,,,
,15774883.015,300.02764895,-56209.001953125,7.90740147861637E-5,8.53876777198376E-7,1,0.999253354069792,40.0298881530762,1.99103239814087,16.4700025320053,0.000858608303263201,0.000123910097001215,0.25,-2.32592874627176E-6,7.90728794342525E-5,-2.27491315678014E-6,300.0270691,300.0282288,-56336.49609375,-56081.5078125,52.7661780762363,18.686940571015,11.93022155,0,0,0,4449,300.40585,-56209.001953125,,,,,,,,,,,,,,,,,13.378378,,,,,,300.02764895,,,,
,15774899.765,300.0339508,-59485.587890625,8.87822718046725E-5,9.48341176953991E-7,1,0.999253354069792,40.0298881530762,1.99115429188446,16.4800030738115,0.00096332015717268,0.00014347945680404,0.25,-2.20897535258061E-6,8.87807212565442E-5,-2.15172876337187E-6,300.0331726,300.034729,-59593.5859375,-59377.58984375,52.4707224959671,18.683702877598,11.93022155,0,0,0,4449,300.3948,-59485.587890625,,,,,,,,,,,,,,,,,12.252253,,,,,,300.0339508,,,,
,15774916.26,300.03631595,-62722.689453125,9.79828082959572E-5,9.36960368372038E-7,1,0.999253354069792,40.0298881530762,1.991104103993,16.4800030738115,0.00106255466343419,0.000161607803030811,0.25,-2.13580534425147E-6,9.79808966357254E-5,-2.07265592164643E-6,300.0362549,300.036377,-62830.6875,-62614.69140625,52.7997881025633,18.686231810782,11.6358137,0,0,0,4449,300.37685,-62722.689453125,,,,,,,,,,,,,,,,,13.378378,,,,,,300.03631595,,,,
,15774933.415,300.0375214,-66096.91796875,0.000109171809675166,8.24904398492102E-7,1,0.999253354069792,40.0298881530762,1.99117308526803,16.4700025320053,0.0011817422974308,0.000192608396524055,0.25,-1.21893428157146E-6,0.000109168930399217,-1.14863675345274E-6,300.0368958,300.038147,-66185.125,-66008.7109375,52.8459041851979,18.683460258655,11.75322245,0,0,0,4449,300.36225,-66096.91796875,,,,,,,,,,,,,,,,,12.252253,,,,,,300.0375214,,,,
,15774949.185,300.03681945,-69186.796875,0.000117137097778654,1.04530865627319E-6,1,0.999253354069792,40.0298881530762,1.99122074814063,16.4700025320053,0.00126828159527175,0.000205006767259043,0.25,-1.46142035903705E-6,0.000117134112102701,-1.38601384841031E-6,300.0366211,300.0370178,-69304.4765625,-69069.1171875,52.7317864213902,18.6850423394213,11.9898119,0,0,0,4449,300.35235,-69186.796875,,,,,,,,,,,,,,,,,13.753754,,,,,,300.03681945,,,,
,15774966.04,300.03599545,-72482.58203125,0.000127260536688058,1.05092888548805E-6,1,0.999253354069792,40.0298881530762,1.99117434503024,16.4700025320053,0.00137889290469378,0.000216805717152993,0.25,-2.13506812885466E-6,0.000127257651154405,-2.05315840857756E-6,300.0358276,300.0361633,-72580.578125,-72384.5859375,53.2976854693133,18.6851843032106,11.8706312,0,0,0,4449,300.3499,-72482.58203125,,,,,,,,,,,,,,,,,13.378378,,,,,,300.03599545,,,,
,15774983.33,300.0368958,-75876.12890625,0.000137387411568925,9.49060535241292E-7,1,0.999253354069792,40.0298881530762,1.99117337342051,16.4800030738115,0.00148693420990748,0.00024371413309837,0.25,-1.41115670234353E-6,0.000137383720520469,-1.32279056893286E-6,300.0368958,300.0368958,-75895.8203125,-75856.4375,52.6075074868325,18.6861080860158,11.9898119,0,0,0,4449,300.3355,-75876.12890625,,,,,,,,,,,,,,,,,13.378378,,,,,,300.0368958,,,,
,15774999.995,300.03843685,-79152.42578125,0.000147134055697416,9.98438864267645E-7,1,0.999253354069792,40.0298881530762,1.99109378511698,16.4800030738115,0.00159225168392215,0.00026162277926102,0.25,-1.45303077943043E-6,0.000147130061531424,-1.35843574356355E-6,300.038269,300.0386047,-79270.2421875,-79034.609375,52.670037768371,18.6890047487444,11.75322245,0,0,0,4449,300.33515,-79152.42578125,,,,,,,,,,,,,,,,,13.003003,,,,,,300.03843685,,,,
,15775017.945,300.0415344,-82674.04296875,0.000157203921697941,9.99349707340837E-7,1,0.999253354069792,40.0298881530762,1.99112461795484,16.4800030738115,0.00170145787911528,0.000278342109543575,0.25,-1.66260807859684E-6,0.000157199712830377,-1.56157446842563E-6,300.0412292,300.0418396,-82683.8828125,-82664.203125,53.0452194576018,18.6882447284044,11.8706312,0,0,0,4449,300.3226,-82674.04296875,,,,,,,,,,,,,,,,,13.378378,,,,,,300.0415344,,,,
,15775034.155,300.0428772,-85852.578125,0.000167155438380179,1.08051488042319E-6,1,0.999253354069792,40.0298881530762,1.99113001072346,16.4800030738115,0.0018092480279371,0.000295516984318706,0.25,-1.80908712606505E-6,0.000167150985685747,-1.70169353106765E-6,300.0428772,300.0428772,-85980.265625,-85724.890625,52.9694014912364,18.6876436226192,11.8128128,0,0,0,4449,300.3092,-85852.578125,,,,,,,,,,,,,,,,,12.252253,,,,,,300.0428772,,,,
,15775051.555,300.0433655,-89275.01171875,0.000177290104515114,1.04684550740047E-6,1,0.999253354069792,40.0298881530762,1.99112096118705,16.4700025320053,0.00191940966807201,0.000310711492322354,0.25,-2.17063049392091E-6,0.00017728554490731,-2.05676376888751E-6,300.0432129,300.0435181,-89392.78125,-89157.2421875,52.6942682524671,18.6882441088206,11.93022155,0,0,0,4449,300.3033,-89275.01171875,,,,,,,,,,,,,,,,,12.252253,,,,,,300.0433655,,,,
,15775083.265,300.0392456,-87773.765625,0.00017370633654817,9.75568861183694E-7,1,0.999253354069792,40.0298881530762,1.99119000141412,16.4800030738115,0.0018800645256354,0.000307923499217418,0.25,-1.80441171076851E-6,0.000173701682557257,-1.6928282416189E-6,300.0390015,300.0394897,-87890.734375,-87656.796875,52.8795142115248,18.6883470541595,11.93022155,0,0,0,4449,300.28425,-87773.765625,,,,,,,,,,,,,,,,,13.003003,,,,,,300.0392456,,,,
,15775101.015,300.03598025,-84317.859375,0.000162983124493277,1.09930148628278E-6,1,0.999253354069792,40.0298881530762,1.99113498106215,16.4800030738115,0.00176449160859233,0.000285853701352864,0.25,-1.9757222614762E-6,0.00016297895223912,-1.87097061822674E-6,300.0359192,300.0360413,-84434.9375,-84200.78125,52.4253880418517,18.6871136258021,11.8128128,0,0,0,4449,300.28045,-84317.859375,,,,,,,,,,,,,,,,,13.003003,,,,,,300.03598025,,,,
,15775116.82,300.0314331,-81232.6796875,0.000153127200226606,1.07529415322262E-6,1,0.999253354069792,40.0298881530762,1.99111501247137,16.4800030738115,0.00165791297008891,0.000267766791435815,0.25,-1.93017541052087E-6,0.000153123346605632,-1.83171588930279E-6,300.0300903,300.0327759,-81349.7578125,-81115.6015625,52.8802958400441,18.6873097874918,11.9898119,0,0,0,4449,300.27465,-81232.6796875,,,,,,,,,,,,,,,,,13.378378,,,,,,300.0314331,,,,
,15775134.825,300.0280762,-77717.30859375,0.000142971140915626,1.09539957821319E-6,1,0.999253354069792,40.0298881530762,1.99114866659084,16.4800030738115,0.00154764344265533,0.000251927797619265,0.25,-1.62480402118132E-6,0.00014296744086187,-1.53284176493909E-6,300.0279236,300.0282288,-77834.421875,-77600.1953125,52.9498607782556,18.6868754151624,11.8128128,0,0,0,4449,300.2776,-77717.30859375,,,,,,,,,,,,,,,,,13.378378,,,,,,300.0280762,,,,
,15775152.215,300.02333065,-74309.7109375,0.000132344944472381,9.21370807982563E-7,1,0.999253354069792,40.0298881530762,1.99115348808351,16.4800030738115,0.00143242273595793,0.000234333254313196,0.25,-1.39955713131139E-6,0.000132341469158629,-1.31439710988602E-6,300.0228271,300.0238342,-74397.515625,-74221.90625,52.9576770634479,18.6858616427602,11.75322245,0,0,0,4449,300.2754,-74309.7109375,,,,,,,,,,,,,,,,,12.252253,,,,,,300.02333065,,,,
,15775167.755,300.0211029,-71282.89453125,0.0001230367763749,7.91666203352799E-7,1,0.999253354069792,40.0298881530762,1.99105874883921,16.4700025320053,0.00133180196898275,0.000216781961820288,0.25,-1.39929735232342E-6,0.00012303361473192,-1.32009341001004E-6,300.0205688,300.021637,-71409.6796875,-71156.109375,53.0303685157364,18.6882937884121,11.9898119,0,0,0,4449,300.27205,-71282.89453125,,,,,,,,,,,,,,,,,12.627627,,,,,,300.0211029,,,,
,15775185.175,300.0159912,-67875.8046875,0.000113839322754918,7.84260644558761E-7,1,0.999253354069792,40.0298881530762,1.99125401079227,16.4700025320053,0.00123333315909567,0.00019501170294644,0.25,-1.81153211801496E-6,0.000113836746171327,-1.73820263686722E-6,300.0158081,300.0161743,-67973.40625,-67778.203125,52.8451225566787,18.6825080959374,11.75322245,0,0,0,4449,300.27445,-67875.8046875,,,,,,,,,,,,,,,,,13.753754,,,,,,300.0159912,,,,
,15775202.58,300.0137482,-64477.376953125,0.000103339569327626,8.62197900219896E-7,1,0.999253354069792,40.0298881530762,1.99111651498608,16.4800030738115,0.00111994020178657,0.000174525934973029,0.25,-1.87474963406484E-6,0.000103337383860391,-1.80814937484433E-6,300.0133362,300.0141602,-64594.59375,-64360.16015625,52.6817621961594,18.6852962520193,11.93022155,0,0,0,4449,300.27595,-64477.376953125,,,,,,,,,,,,,,,,,13.003003,,,,,,300.0137482,,,,
,15775220.33,300.00930785,-61005.765625,9.31122314253578E-5,8.42247308544177E-7,1,0.999253354069792,40.0298881530762,1.99127401731632,16.4700025320053,0.00100966730282345,0.000154455286377966,0.25,-1.94930796513102E-6,9.31104410625608E-5,-1.88926630614394E-6,300.0092773,300.0093384,-61132.8359375,-60878.6953125,52.8959284104287,18.6815548776504,11.75322245,0,0,0,4449,300.2772,-61005.765625,,,,,,,,,,,,,,,,,13.003003,,,,,,300.00930785,,,,
,15775237.555,300.0062866,-57638.876953125,8.36587997875026E-5,8.16306290235801E-7,1,0.999253354069792,40.0298881530762,1.99110326080985,16.4800030738115,0.000906377105320038,0.000142821377522644,0.25,-1.37572493689035E-6,8.36569555366691E-5,-1.32177030370458E-6,300.0062866,300.0062866,-57648.64453125,-57629.109375,52.8842039826402,18.6850250954553,11.8128128,0,0,0,4449,300.2775,-57638.876953125,,,,,,,,,,,,,,,,,12.252253,,,,,,300.0062866,,,,
,15775253.93,300.0054474,-54429.248046875,7.40814661046867E-5,6.44635824091061E-7,1,0.999253354069792,40.0298881530762,1.9912041287615,16.4700025320053,0.00080566267942649,0.000109224478507089,0.25,-2.815160477164E-6,7.40808630176375E-5,-2.76731418451133E-6,300.0048218,300.006073,-54556.6171875,-54301.87890625,52.6442440272363,18.6838317003108,11.93022155,0,0,0,4449,300.2853,-54429.248046875,,,,,,,,,,,,,,,,,13.378378,,,,,,300.0054474,,,,
,15775271.05,300.0038452,-51082.517578125,6.49041781777845E-5,7.38865253188526E-7,1,0.999253354069792,40.0298881530762,1.99119382120149,16.4800030738115,0.000705345105300061,9.86038896251128E-5,0.25,-2.19701296683197E-6,6.49034783859945E-5,-2.15508644885561E-6,300.0038452,300.0038452,-51111.87890625,-51053.15625,52.6035993442363,18.6824727321861,11.6358137,0,0,0,4449,300.2837,-51082.517578125,,,,,,,,,,,,,,,,,12.252253,,,,,,300.0038452,,,,
,15775287.91,300.0015869,-47774.453125,5.55489626380138E-5,6.96013241378848E-7,1,0.999253354069792,40.0298881530762,1.99129114624448,16.4700025320053,0.000603190963924758,8.7343176793808E-5,0.25,-1.60748926666859E-6,5.55481908549723E-5,-1.57160195229007E-6,300.0015869,300.0015869,-47784.2421875,-47764.6640625,52.5582648901209,18.6802603591242,11.6358137,0,0,0,4449,300.2866,-47774.453125,,,,,,,,,,,,,,,,,12.252253,,,,,,300.0015869,,,,
,15775304.89,299.9985352,-44456.427734375,4.53913321228948E-5,7.59495749341752E-7,1,0.999253354069792,40.0298881530762,1.99084608606138,16.4800030738115,0.000493985915785927,6.44917213298364E-5,0.25,-1.94908643305811E-6,4.53911152396735E-5,-1.91972933250275E-6,299.9985352,299.9985352,-44476.05078125,-44436.8046875,52.5457588338133,18.6932089767188,11.6358137,0,0,0,4449,300.28055,-44456.427734375,,,,,,,,,,,,,,,,,12.627627,,,,,,299.9985352,,,,
,15775322.275,299.9937439,-41050.888671875,3.49129641151324E-5,5.44668122539125E-7,1,0.999253354069792,40.0298881530762,1.99059725779142,16.4800030738115,0.00038105190301016,4.30358111850365E-5,0.25,-2.10675804412395E-6,3.49131944797677E-5,-2.08415052073595E-6,299.9933472,299.9941406,-41187.74609375,-40914.03125,52.710682451371,18.6978310644521,11.8128128,0,0,0,4449,300.28675,-41050.888671875,,,,,,,,,,,,,,,,,13.378378,,,,,,299.9937439,,,,
,15775339.24,299.99186705,-37733.0859375,2.73957222203224E-5,5.58316899370425E-7,1,0.999253354069792,40.0298881530762,1.99071392118111,16.4700025320053,0.000301106063081212,2.18306512456487E-5,0.25,-2.75865650172498E-6,2.73966183387738E-5,-2.74087522551113E-6,299.9911499,299.9925842,-37860.18359375,-37605.98828125,52.9178140089671,18.6937100313028,11.87122395,0,0,0,4449,300.2948,-37733.0859375,,,,,,,,,,,,,,,,,13.378378,,,,,,299.99186705,,,,
,15775356.555,299.9918823,-34337.1640625,1.76152748868696E-5,5.42058717842237E-7,1,0.999253354069792,40.0298881530762,1.99082091881689,16.4800030738115,0.000193348620829332,1.55879232770785E-5,0.25,-1.63028493577299E-6,1.76157583636448E-5,-1.61885256313812E-6,299.9918823,299.9918823,-34356.85546875,-34317.47265625,53.0936804257941,18.6912501312248,11.6358137,0,0,0,4449,300.3034,-34337.1640625,,,,,,,,,,,,,,,,,13.003003,,,,,,299.9918823,,,,
,15775372.73,299.9893799,-31176.248046875,8.79609659773463E-6,4.357331886015E-7,1,0.999253354069792,40.0298881530762,1.99077192038741,16.4800030738115,9.97767251505484E-5,-1.07369745362852E-5,0.25,-2.52869997428319E-6,8.79744674852801E-6,-2.52293406075709E-6,299.9891968,299.989563,-31283.9140625,-31068.58203125,52.8271451007364,18.6927558607291,12.0500002,0,0,0,4449,300.30185,-31176.248046875,,,,,,,,,,,,,,,,,13.753754,,,,,,299.9893799,,,,
,15775391.7,299.9894714,-27457.267578125,-9.96316749357688E-7,5.30198708730581E-6,1,0.999253354069792,40.0298881530762,1.99083644476696,16.4800030738115,-7.00294220625035E-6,-2.34233164964452E-5,0.25,-1.99462411354759E-6,-9.94995100737438E-7,-1.99520375222654E-6,299.9894714,299.9894714,-27467.154296875,-27447.380859375,52.9834708045825,18.6897552695676,11.8116336,0,0,0,4449,300.3045,-27457.267578125,,,,,,,,,,,,,,,,,13.753754,,,,,,299.9894714,,,,
,15775407.48,299.9897003,-24374.1728515625,-9.15036270715787E-6,5.96532942750073E-7,1,0.999253354069792,40.0298881530762,1.99092878069063,16.4800030738115,-9.56311798046701E-5,-3.56669263718877E-5,0.25,-1.70529400917431E-6,-9.14896410683439E-6,-1.71115589681315E-6,299.9895935,299.9898071,-24471.955078125,-24276.390625,52.802132988121,18.6866580564948,11.8128128,0,0,0,4449,300.31275,-24374.1728515625,,,,,,,,,,,,,,,,,13.378378,,,,,,299.9897003,,,,
,15775425.97,299.9879761,-20752.7119140625,-1.82784107636625E-5,4.26700587988748E-7,1,0.999253354069792,40.0298881530762,1.99092773019145,16.4700025320053,-0.000193631026822231,-5.63334892286326E-5,0.25,-2.0258555565824E-6,-1.82765098123468E-5,-2.03761405282524E-6,299.9879761,299.9879761,-20772.388671875,-20733.03515625,52.8881121252364,18.6875537572109,11.9898119,0,0,0,4449,300.3094,-20752.7119140625,,,,,,,,,,,,,,,,,13.003003,,,,,,299.9879761,,,,
,15775442.115,299.9864807,-17591.755859375,-2.64855787755655E-5,3.82892321926247E-7,1,0.999253354069792,40.0298881530762,1.99097808445279,16.4800030738115,-0.000282462683206791,-7.08376493767731E-5,0.25,-1.93645439820152E-6,-2.64834709380424E-5,-1.95352986042916E-6,299.9859009,299.9870605,-17719.001953125,-17464.509765625,53.0553806283518,18.6858848329789,11.8128128,0,0,0,4449,300.3112,-17591.755859375,,,,,,,,,,,,,,,,,13.378378,,,,,,299.9864807,,,,
,15775459.36,299.98539735,-14214.4165039062,-3.48720316554173E-5,5.87723455513339E-7,1,0.999253354069792,40.0298881530762,1.99099997730234,16.4800030738115,-0.000372384459776961,-9.05274008604263E-5,0.25,-2.29584051745156E-6,-3.48694207823669E-5,-2.31833718421213E-6,299.9851074,299.9856873,-14332.0693359375,-14096.763671875,52.6426807701979,18.6832074012395,11.9898119,0,0,0,4449,300.3195,-14214.4165039062,,,,,,,,,,,,,,,,,13.003003,,,,,,299.98539735,,,,
,15775475.6,299.986084,-11031.2509765625,-4.13462610543588E-5,3.67413435846272E-7,1,0.999253354069792,40.0298881530762,1.991007857626,16.4800030738115,-0.000443537974031874,-9.57790017983376E-5,0.25,-1.65235856419922E-6,-4.13438559411744E-5,-1.67907320652971E-6,299.9851685,299.9869995,-11138.994140625,-10923.5078125,52.9131242378518,18.6840921867426,11.93022155,0,0,0,4449,300.32415,-11031.2509765625,,,,,,,,,,,,,,,,,12.627627,,,,,,299.986084,,,,
,15775492.465,299.98905945,-7730.32006835938,-4.75991822241848E-5,3.64251747074168E-7,1,0.999253354069792,40.0298881530762,1.99092408947203,16.4700025320053,-0.0005110764649979,-0.000107501484360168,0.25,-1.64691813758234E-6,-4.75965730193536E-5,-1.67768914500314E-6,299.9883423,299.9897766,-7867.619140625,-7593.02099609375,52.9146874948902,18.6854343611168,11.9898119,0,0,0,4449,300.3251,-7730.32006835938,,,,,,,,,,,,,,,,,12.252253,,,,,,299.98905945,,,,
,15775509.62,299.9873657,-4360.25439453125,-4.98735118923838E-5,4.21071109404708E-7,1,0.999253354069792,40.0298881530762,1.99092149333469,16.4800030738115,-0.000534857181929257,-0.000116296363294508,0.25,-2.06427976986323E-6,-4.98705602703922E-5,-2.09651816312734E-6,299.9871826,299.9875488,-4497.388671875,-4223.1201171875,52.4035024433132,18.6859630255901,11.93141225,0,0,0,4449,300.32585,-4360.25439453125,,,,,,,,,,,,,,,,,13.003003,,,,,,299.9873657,,,,
,15775526.515,299.98695375,-1055.62475585938,-4.06477900991915E-5,3.93996496449119E-7,1,0.999253354069792,40.0298881530762,1.99097104454646,16.4800030738115,-0.000434387017890175,-0.000103619382636612,0.25,-2.50015038743136E-6,-4.06448544271977E-5,-2.52640435589777E-6,299.9862061,299.9877014,-1183.1318359375,-928.11767578125,52.8498123277941,18.6843327495085,11.6358137,0,0,0,4449,300.3248,-1055.62475585938,,,,,,,,,,,,,,,,,13.003003,,,,,,299.98695375,,,,
,15775543.57,299.9877319,2278.99145507813,4.61765609244851E-5,3.18001442569452E-7,1,0.999253354069792,40.0298881530762,1.99097584967449,16.4800030738115,0.000504198892457599,5.62319414045225E-5,0.25,-2.85118165229E-6,4.61769122514451E-5,-2.82117521927492E-6,299.9873657,299.9880981,2152.69165039062,2405.29125976562,52.3917780155248,18.6843240112314,11.9898119,0,0,0,4449,300.33075,2278.99145507813,,,,,,,,,,,,,,,,,13.003003,,,,,,299.9877319,,,,
,15775560.665,299.990509,5623.7734375,4.97205328525725E-5,3.73295983034063E-7,1,0.999253354069792,40.0298881530762,1.99102297243175,16.4700025320053,0.000542433510796088,6.32649058523242E-5,0.25,-2.81858913869803E-6,4.97207441724983E-5,-2.78629528301884E-6,299.990509,299.990509,5604.11279296875,5643.43408203125,52.903744695621,18.6832045339829,12.1101885,0,0,0,4449,300.33255,5623.7734375,,,,,,,,,,,,,,,,,13.378378,,,,,,299.990509,,,,
,15775577.235,299.99424745,8877.8427734375,4.62405963391114E-5,4.35523968570735E-7,1,0.999253354069792,40.0298881530762,1.99108679269265,16.4800030738115,0.000505336131065699,5.39537387765657E-5,0.25,-3.07349583495309E-6,4.62410804321372E-5,-3.0434546037102E-6,299.9940796,299.9944153,8760.0703125,8995.615234375,52.514493693044,18.6816854609301,11.9898119,0,0,0,4449,300.3312,8877.8427734375,,,,,,,,,,,,,,,,,12.252253,,,,,,299.99424745,,,,
,15775593.745,299.9962311,12112.2939453125,3.99199474810532E-5,4.02320148039691E-7,1,0.999253354069792,40.0298881530762,1.99109923182603,16.4700025320053,0.000435682227508003,4.99137401481188E-5,0.25,-2.3446948932387E-6,3.99201632716994E-5,-2.31877671822078E-6,299.9961243,299.9963379,11994.68359375,12229.904296875,52.548103719371,18.6807949378132,11.87122395,0,0,0,4449,300.3292,12112.2939453125,,,,,,,,,,,,,,,,,13.378378,,,,,,299.9962311,,,,
,15775611.515,299.99823,15591.5795898438,3.17961240803266E-5,4.11077293003517E-7,1,0.999253354069792,40.0298881530762,1.9910257999056,16.4700025320053,0.000348066502572309,3.36853962834518E-5,0.25,-2.42936948460218E-6,3.17966577454835E-5,-2.40871288423327E-6,299.9978943,299.9985657,15444.5517578125,15738.607421875,52.7779025040248,18.6838306682234,11.87122395,0,0,0,4449,300.32035,15591.5795898438,,,,,,,,,,,,,,,,,13.378378,,,,,,299.99823,,,,
,15775629.22,300.0006714,19070.10546875,2.38190584047668E-5,4.33797413757711E-7,1,0.999253354069792,40.0298881530762,1.99115192770661,16.4700025320053,0.000263790099394498,7.86036936529255E-6,0.25,-3.42820599454507E-6,2.38204969463785E-5,-3.41268401280038E-6,300.0006714,300.0006714,19050.625,19089.5859375,52.6489337983517,18.678982311708,11.9898119,0,0,0,4449,300.3211,19070.10546875,,,,,,,,,,,,,,,,,12.252253,,,,,,300.0006714,,,,
,15775646.245,300.00361635,22401.533203125,1.55928938357457E-5,4.80176066734311E-7,1,0.999253354069792,40.0298881530762,1.99080998802724,16.4700025320053,0.000174345588366313,-4.51958003959827E-6,0.25,-3.13895069834669E-6,1.55944126100856E-5,-3.12876301370624E-6,300.0028992,300.0043335,22283.95703125,22519.109375,52.8560653559479,18.6879647014838,11.93141225,0,0,0,4449,300.319,22401.533203125,,,,,,,,,,,,,,,,,13.003003,,,,,,300.00361635,,,,
,15775664.61,300.0085449,25997.396484375,5.85456621519989E-6,3.88624512458879E-7,1,0.999253354069792,40.0298881530762,1.99092106427119,16.4800030738115,6.85121597516119E-5,-1.91684223841803E-5,0.25,-2.79594158457424E-6,5.85618106886073E-6,-2.7920644111024E-6,300.0085449,300.0085449,25987.73046875,26007.0625,52.7528903914094,18.6845022849615,11.6358137,0,0,0,4449,300.3197,25997.396484375,,,,,,,,,,,,,,,,,13.378378,,,,,,300.0085449,,,,
,15775681.735,300.0117493,29358.6064453125,-2.90875343869779E-6,1.27080530336247E-6,1,0.999253354069792,40.0298881530762,1.99094278373006,16.4700025320053,-2.52857023044436E-5,-4.06497916909955E-5,0.25,-3.25554051382722E-6,-2.9065533127734E-6,-3.25731301695353E-6,300.0117493,300.0117493,29338.984375,29378.228515625,52.7419475921402,18.6837911418341,11.9898119,0,0,0,4449,300.3147,29358.6064453125,,,,,,,,,,,,,,,,,12.252253,,,,,,300.0117493,,,,
,15775698.245,300.01582335,32593.57421875,-1.21948643925358E-5,5.96732264383612E-7,1,0.999253354069792,40.0298881530762,1.99102129939529,16.4800030738115,-0.000127133675787665,-4.93778010080741E-5,0.25,-2.44317321216067E-6,-1.21928818650864E-5,-2.45097171493135E-6,300.0158081,300.0158386,32495.529296875,32691.619140625,52.4308594414863,18.6828586824503,11.9898119,0,0,0,4449,300.30385,32593.57421875,,,,,,,,,,,,,,,,,13.003003,,,,,,300.01582335,,,,
,15775715.505,300.01779175,35987.26953125,-2.20301282281664E-5,5.67402814803621E-7,1,0.999253354069792,40.0298881530762,1.99100776562756,16.4800030738115,-0.00023262048936072,-7.22704940060172E-5,0.25,-2.84638710569346E-6,-2.20275590904181E-5,-2.86052226356016E-6,300.0177002,300.0178833,35850.015625,36124.5234375,52.619231914621,18.681599788954,12.0500002,0,0,0,4449,300.2968,35987.26953125,,,,,,,,,,,,,,,,,13.378378,,,,,,300.01779175,,,,
,15775732.54,300.020401,39322.439453125,-3.07299447043978E-5,7.04175827244654E-7,1,0.999253354069792,40.0298881530762,1.99095856225373,16.4800030738115,-0.000326269723643906,-9.05272708967582E-5,0.25,-3.01873110448539E-6,-3.07269743439666E-5,-3.03847366954546E-6,300.0198669,300.0209351,39224.5,39420.37890625,52.9959768608902,18.6848018886959,11.9898119,0,0,0,4449,300.28275,39322.439453125,,,,,,,,,,,,,,,,,12.627627,,,,,,300.020401,,,,
,15775749.05,300.01976015,42559.947265625,-3.94452941868001E-5,6.61465733109708E-7,1,0.999253354069792,40.0298881530762,1.99094534203546,16.4800030738115,-0.000420421666719962,-0.0001069109395811,0.25,-3.01487830282684E-6,-3.9442039080469E-5,-3.04024003969661E-6,300.0197144,300.0198059,42422.67578125,42697.21875,52.4511817829863,18.6846299686449,11.87122395,0,0,0,4449,300.2802,42559.947265625,,,,,,,,,,,,,,,,,13.378378,,,,,,300.01976015,,,,
,15775767.28,300.0226135,46141.03515625,-4.88218456059131E-5,6.44725089946772E-7,1,0.999253354069792,40.0298881530762,1.99096661790198,16.4700025320053,-0.000520883651543466,-0.000129355874390202,0.25,-3.45660160725842E-6,-4.88179918332369E-5,-3.48798872051055E-6,300.0219116,300.0233154,46131.296875,46150.7734375,52.7661780762363,18.6836026521882,12.0500002,0,0,0,4449,300.2782,46141.03515625,,,,,,,,,,,,,,,,,13.378378,,,,,,300.0226135,,,,
,15775783.205,300.0235596,49270.2265625,-5.91232023422216E-5,8.34292471917609E-7,1,0.999253354069792,40.0298881530762,1.99101843818823,16.4800030738115,-0.000632412258749617,-0.000147441649979308,0.25,-3.33320744699416E-6,-5.91190858022427E-5,-3.37123314157067E-6,300.0228882,300.024231,49132.87890625,49407.57421875,52.788845303294,18.6815013745725,11.87122395,0,0,0,4449,300.2713,49270.2265625,,,,,,,,,,,,,,,,,13.378378,,,,,,300.0235596,,,,
,15775800.265,300.0249939,52615.435546875,-6.7767095618876E-5,6.80974586326444E-7,1,0.999253354069792,40.0298881530762,1.9908476308893,16.4700025320053,-0.000725784742229008,-0.000163415304303267,0.25,-3.3049989205936E-6,-6.77627088492771E-5,-3.34858637374108E-6,300.0249329,300.0250549,52487.84765625,52743.0234375,52.761488305121,18.6836397544933,11.93141225,0,0,0,4449,300.26,52615.435546875,,,,,,,,,,,,,,,,,13.378378,,,,,,300.0249939,,,,
,15775817.47,300.0255432,55979.984375,-7.77372623323077E-5,8.32387680340965E-7,1,0.999253354069792,40.0298881530762,1.99090170117765,16.4700025320053,-0.000833221643986634,-0.00018382168533637,0.25,-3.45422411118E-6,-7.77324487110463E-5,-3.50421765792245E-6,300.0248413,300.0262451,55881.796875,56078.171875,52.6794173106017,18.6823403500916,11.87122395,0,0,0,4449,300.25215,55979.984375,,,,,,,,,,,,,,,,,13.753754,,,,,,300.0255432,,,,
,15775834.345,300.02542115,59296.330078125,-8.7653857339204E-5,7.1607812404281E-7,1,0.999253354069792,40.0298881530762,1.99089171616881,16.4700025320053,-0.000939630038771465,-0.000206568197081153,0.25,-3.8299106345371E-6,-8.76484744214935E-5,-3.88626630329737E-6,300.025177,300.0256653,59159.0390625,59433.62109375,52.8396511570441,18.6841251642397,11.8128128,0,0,0,4449,300.23285,59296.330078125,,,,,,,,,,,,,,,,,13.378378,,,,,,300.02542115,,,,
,15775851.01,300.0284729,62572.935546875,-9.73060847404405E-5,9.68965069866835E-7,1,0.999253354069792,40.0298881530762,1.99091512985981,16.4700025320053,-0.00104350144134225,-0.000227081374889595,0.25,-4.04467397721691E-6,-9.73002370946651E-5,-4.10721254608955E-6,300.0279236,300.0290222,62474.6875,62671.18359375,52.7661780762363,18.6821444868697,11.93141225,0,0,0,4449,300.25415,62572.935546875,,,,,,,,,,,,,,,,,12.627627,,,,,,300.0284729,,,,
,15775869.09,300.03707885,66124.39453125,-0.000107464386532822,7.33617327983369E-7,1,0.999253354069792,40.0298881530762,1.9909615228315,16.4800030738115,-0.00115315802112457,-0.00024681046312924,0.25,-4.09827119229051E-6,-0.000107458139833433,-4.1673231373054E-6,300.0370483,300.0371094,66026.2578125,66222.53125,53.1132211387749,18.6811769979109,11.9898119,0,0,0,4449,300.2442,66124.39453125,,,,,,,,,,,,,,,,,13.378378,,,,,,300.03707885,,,,
,15775885.535,300.0412445,69342.19921875,-0.000116706644179298,9.56877759119188E-7,1,0.999253354069792,40.0298881530762,1.99100805542922,16.4700025320053,-0.00125382033698362,-0.000259675600950161,0.25,-3.67621315230177E-6,-0.00011670034619889,-3.7512073295803E-6,300.0407715,300.0417175,69224.5546875,69459.84375,52.9623668345633,18.6797501092894,12.0500002,0,0,0,4449,300.2201,69342.19921875,,,,,,,,,,,,,,,,,13.003003,,,,,,300.0412445,,,,
,15775902.135,300.04286195,72598.91796875,-0.000126843486013962,1.24888185592631E-6,1,0.999253354069792,40.0298881530762,1.99095671576004,16.4800030738115,-0.001361734297989,-0.000287705868436575,0.25,-4.5030586764499E-6,-0.000126836311410761,-4.58452246057689E-6,300.0422058,300.0435181,72481.2890625,72716.546875,53.0725764557748,18.6785077446806,11.87122395,0,0,0,4449,300.2034,72598.91796875,,,,,,,,,,,,,,,,,12.252253,,,,,,300.04286195,,,,
,15775920.525,300.0396729,76219.09375,-0.000137729368826422,9.56641762272465E-7,1,0.999253354069792,40.0298881530762,1.99096273408479,16.4800030738115,-0.00148070558920083,-0.000300356090863473,0.25,-3.77480444586558E-6,-0.000137722314002643,-3.86326525104999E-6,300.0396729,300.0396729,76209.3046875,76228.8828125,52.6481521698325,18.6801983046187,12.1101885,0,0,0,4449,300.1834,76219.09375,,,,,,,,,,,,,,,,,13.753754,,,,,,300.0396729,,,,
,15775937.445,300.0359955,79534.51953125,-0.000147686550642657,1.11141496360384E-6,1,0.999253354069792,40.0298881530762,1.99092763613416,16.4700025320053,-0.00158736879785743,-0.000324120756220092,0.25,-4.23804239402918E-6,-0.000147678886063414,-4.33285220576029E-6,300.0359192,300.0360718,79407.140625,79661.8984375,52.8951467819094,18.6801885247095,11.87122395,0,0,0,4449,300.1877,79534.51953125,,,,,,,,,,,,,,,,,13.378378,,,,,,300.0359955,,,,
,15775954.66,300.03627015,82909.28125,-0.000158383952315291,1.01382708333087E-6,1,0.999253354069792,40.0298881530762,1.99091897985882,16.4800030738115,-0.00170302570594002,-0.000343666054739374,0.25,-4.1812129072455E-6,-0.000158375970484149,-4.28285971435745E-6,300.0362549,300.0362854,82820.9921875,82997.5703125,52.4965162371017,18.6791410510797,11.9898119,0,0,0,4449,300.1872,82909.28125,,,,,,,,,,,,,,,,,12.252253,,,,,,300.03627015,,,,
,15775971.86,300.0367737,86283.8671875,-0.00016737045399879,1.17332464447161E-6,1,0.999253354069792,40.0298881530762,1.99092749237909,16.4700025320053,-0.00179922039237189,-0.000365689132440204,0.25,-4.65200046179382E-6,-0.000167361871855996,-4.75936500721048E-6,300.0367737,300.0367737,86274.203125,86293.53125,52.8287083577748,18.6812473842753,12.1101885,0,0,0,4449,300.1782,86283.8671875,,,,,,,,,,,,,,,,,12.252253,,,,,,300.0367737,,,,
,15775988.735,300.0379639,89589.671875,-0.000177198671032396,1.38065856866258E-6,1,0.999253354069792,40.0298881530762,1.99088900391773,16.4800030738115,-0.00190515560001296,-0.000385337026679383,0.25,-4.7568405918879E-6,-0.000177189691744221,-4.87047251645926E-6,300.0379639,300.0379639,89570.1015625,89609.2421875,52.5035508937748,18.680874058188,12.0500002,0,0,0,4449,300.1673,89589.671875,,,,,,,,,,,,,,,,,13.378378,,,,,,300.0379639,,,,
,15775992.59,300.0380249,89999.484375,-0.000179026094687201,9.82161124121338E-7,1,0.999253354069792,40.0298881530762,1.99091865393679,16.4700025320053,-0.00192659052491322,-0.000379226906683538,0.25,-3.87188470151445E-6,-0.000179017622919165,-3.98671414678119E-6,300.0380249,300.0380249,89999.4765625,89999.4921875,52.7059926802556,18.6801201985775,11.752636,0,0,0,4417,300.1664,89999.484375,,,,,,,,,,,,,,,,,12.252253,,,,,,300.0380249,,,,