File: data/doubleLayers/dl_0-25/ppms/DD205_10_HYST_10K_1OE.DAT
[Header]
; VSM Data File (default extension .dat)
; Copyright (c) 2003, Quantum Design, Inc. All rights reserved.
TITLE,
FILEOPENTIME,15740877.88,04/17/2018,10:02 pm
BYAPP,VSM,1.0,1.0
INFO,PPMS VSM Option Release 1.3.7 Build 2,APPNAME
INFO,291,COIL_SERIAL_NUMBER
INFO,0,MOMENT_UNITS
INFO,,SAMPLE_MATERIAL
INFO,,SAMPLE_COMMENT
INFO,,SAMPLE_MASS
INFO,,SAMPLE_VOLUME
INFO,,SAMPLE_MOLECULAR_WEIGHT
INFO,,SAMPLE_SIZE
INFO,,SAMPLE_SHAPE
INFO,35.28,SAMPLE_OFFSET
DATATYPE,COMMENT,1
DATATYPE,TIME,2
STARTUPAXIS,X,2
STARTUPAXIS,Y1,5
[Data]
Comment,Time Stamp (sec),Temperature (K),Magnetic Field (Oe),Moment (emu),M. Std. Err. (emu),Transport Action,Averaging Time (sec),Frequency (Hz),Peak Amplitude (mm),Center Position (mm),Coil Signal' (mV),Coil Signal" (mV),Range (mV),M. Quad. Signal (emu),M. Raw' (emu),M. Raw" (emu),Min. Temperature (K),Max. Temperature (K),Min. Field (Oe),Max. Field (Oe),Mass (grams),Motor Lag (deg),Pressure (Torr),VSM Status (code),Motor Status (code),Measure Status (code),PPMS Status (code),System Temp. (K),System Field (Oe),Sample Position (deg),Bridge 1 Resistance (ohms),Bridge 1 Excitation (에),Bridge 2 Resistance (ohms),Bridge 2 Excitation (에),Bridge 3 Resistance (ohms),Bridge 3 Excitation (에),Bridge 4 Resistance (ohms),Bridge 4 Excitation (에),Signal 1 Vin (V),Signal 2 Vin (V),Digital Inputs (code),Drive 1 Iout (mA),Drive 1 Ipower (W),Drive 2 Iout (mA),Drive 2 Ipower (W),Pressure (),Map 20 (),Map 21 (),Map 22 (),Map 23 (),Map 24 (),Map 25 (),Map 26 (),Map 27 (),Map 28 (),Map 29 ()
,15740911.51,10.017642,0.076404944062233,6.26740615856525E-5,2.25488050660047E-7,1,0.999253354069792,40.0298881530762,2.00477797490685,16.4700025320053,0.000681666945711667,9.42159969430472E-5,0.25,-2.31781910509158E-6,6.23073369619856E-5,-2.16564255735385E-6,10.0168781,10.0184059,0.0611239522695541,0.0916859358549118,51.8477645661401,18.6620388265235,2.5234809,0,0,0,4417,10.0024,0.076404944062233,,,,,,,,,,,,,,,,,12.627627,,,,,,10.017642,,,,
,15741003.84,10.0061712,3874.74084472656,6.19845533016487E-5,2.28491934749612E-7,1,0.999253354069792,40.0298881530762,2.00484161042259,16.4700025320053,0.000674798304901056,8.99337528322186E-5,0.25,-2.60162074457011E-6,6.16259641422481E-5,-2.44124316188055E-6,10.0061407,10.0062017,3844.88354492188,3904.59814453125,52.6114156294286,18.6703282790557,2.63954365,0,0,0,4449,9.99365,3874.74084472656,,,,,,,,,,,,,,,,,13.378378,,,,,,10.0061712,,,,
,15741082.215,10.0065622,7789.96704101562,5.32778138442857E-5,3.08911897971384E-7,1,0.999253354069792,40.0298881530762,2.00490001405215,16.4700025320053,0.000580337612856854,7.58064641394899E-5,0.25,-2.38436414887206E-6,5.29740262700145E-5,-2.23672921040424E-6,10.0064058,10.0067186,7754.91064453125,7825.0234375,52.4597796966979,18.6715748811703,2.6794947,0,0,0,4449,9.99225,7789.96704101562,,,,,,,,,,,,,,,,,13.753754,,,,,,10.0065622,,,,
,15741162.14,10.00500015,11783.2866210938,4.4617313973942E-5,2.60981688642818E-7,1,0.999253354069792,40.0298881530762,2.00473507610896,16.4700025320053,0.000486719094807545,5.94653402759753E-5,0.25,-2.37722110545012E-6,4.43680419986129E-5,-2.24311663766761E-6,10.0048056,10.0051947,11758.2578125,11808.3154296875,52.9428261215825,18.6798338154489,2.73356875,0,0,0,4449,9.98945,11783.2866210938,,,,,,,,,,,,,,,,,12.252253,,,,,,10.00500015,,,,
,15741240.445,10.0028305,15701.759765625,3.45669596061258E-5,4.20438729293903E-7,1,0.999253354069792,40.0298881530762,2.00478193514882,16.4700025320053,0.000377811396479987,4.22237195206457E-5,0.25,-2.20496684629424E-6,3.43784836394612E-5,-2.0924637903993E-6,10.0027847,10.0028763,15676.8095703125,15726.7099609375,52.9115609808133,18.6773059414482,2.7610135,0,0,0,4449,9.9878,15701.759765625,,,,,,,,,,,,,,,,,13.378378,,,,,,10.0028305,,,,
,15741319.95,10.00199125,19672.15625,2.46578514912694E-5,4.34421301773737E-7,1,0.999253354069792,40.0298881530762,2.00478423294257,16.4700025320053,0.00027042518151864,2.51176792212759E-5,0.25,-2.04102535931489E-6,2.45277865046681E-5,-1.95336054500582E-6,10.0017929,10.0021896,19644.765625,19699.546875,52.5332527775056,18.6810851138478,2.816592,0,0,0,4449,9.9889,19672.15625,,,,,,,,,,,,,,,,,13.753754,,,,,,10.00199125,,,,
,15741396.905,10.00260925,23520.521484375,1.73874417004468E-5,3.94728429208248E-7,1,0.999253354069792,40.0298881530762,2.00465340232198,16.4700025320053,0.000193340851972424,2.82893865456585E-6,0.25,-2.81972135971594E-6,1.73025277804924E-5,-2.74713721974792E-6,10.0025682,10.0026503,23493.0546875,23547.98828125,52.6708193968902,18.6838222799062,2.8734326,0,0,0,4449,9.98525,23520.521484375,,,,,,,,,,,,,,,,,13.378378,,,,,,10.00260925,,,,
,15741476.775,10.00173375,27510.93359375,6.18059721929565E-6,4.47665173933286E-7,1,0.999253354069792,40.0298881530762,2.00493020316365,16.4700025320053,7.23860263086769E-5,-1.95105109663973E-5,0.25,-2.9012953745039E-6,6.15805887235856E-6,-2.86430163723276E-6,10.0016794,10.0017881,27485.95703125,27535.91015625,52.6004728301594,18.6817442779749,2.9314206,0,0,0,4449,9.9856,27510.93359375,,,,,,,,,,,,,,,,,13.378378,,,,,,10.00173375,,,,
,15741555.79,10.0008397,31458.9853515625,-2.73314434960073E-6,2.32152392772381E-6,1,0.999253354069792,40.0298881530762,2.00474864245911,16.4700025320053,-2.22650459116356E-5,-4.62542892856274E-5,0.25,-3.79271925492796E-6,-2.70500640167833E-6,-3.78329571609176E-6,10.0006571,10.0010223,31429.0546875,31488.916015625,52.8060411307171,18.6839268157147,2.9608517,0,0,0,4449,9.98325,31458.9853515625,,,,,,,,,,,,,,,,,13.003003,,,,,,10.0008397,,,,
,15741633.695,10.0004506,35351.818359375,-1.22426716346815E-5,7.82296887115878E-7,1,0.999253354069792,40.0298881530762,2.00497047922397,16.4700025320053,-0.000124190495103458,-6.96491106229965E-5,0.25,-4.26340439561257E-6,-1.21646933980416E-5,-4.28980979152085E-6,10.0003967,10.0005045,35321.890625,35381.74609375,52.4472736403902,18.6814683842606,2.9907277,0,0,0,4449,9.9845,35351.818359375,,,,,,,,,,,,,,,,,12.627627,,,,,,10.0004506,,,,
,15741712.76,10.00099135,39304.6171875,-2.57405848419014E-5,7.23967571484338E-7,1,0.999253354069792,40.0298881530762,2.00488729726983,16.4700025320053,-0.000269704978132206,-9.82697430106047E-5,0.25,-4.50351575278549E-6,-2.55971387703618E-5,-4.58713307599886E-6,10.0008373,10.0011454,39269.6328125,39339.6015625,52.7880636747748,18.6866578538688,3.02075435,0,0,0,4449,9.984,39304.6171875,,,,,,,,,,,,,,,,,12.252253,,,,,,10.00099135,,,,
,15741791.095,9.9998131,43220.384765625,-3.08569527829364E-5,6.47973361468054E-7,1,0.999253354069792,40.0298881530762,2.00460622870064,16.4700025320053,-0.00032695085158647,-9.73916998568712E-5,0.25,-3.50532766931173E-6,-3.06970818565162E-5,-3.62117479724687E-6,9.9998131,9.9998131,43217.9453125,43222.82421875,52.6504970553902,18.6863230333537,3.1125,0,0,0,4449,9.9839,43220.384765625,,,,,,,,,,,,,,,,,13.378378,,,,,,9.9998131,,,,
,15741869.79,10.00043535,47153.822265625,-4.67470918552245E-5,7.77965254700354E-7,1,0.999253354069792,40.0298881530762,2.00489760704473,16.4700025320053,-0.0004955213934552,-0.000147246135161713,0.25,-5.27016696520097E-6,-4.65120580073586E-5,-5.45538716889092E-6,10.0004158,10.0004549,47126.31640625,47181.328125,52.7349129354671,18.6841900355733,3.11265525,0,0,0,4449,9.98415,47153.822265625,,,,,,,,,,,,,,,,,13.378378,,,,,,10.00043535,,,,
,15741949.095,10.0007496,51116.90234375,-5.60424748547821E-5,8.49412137055474E-7,1,0.999253354069792,40.0298881530762,2.00471045022007,16.4700025320053,-0.000600500209096755,-0.000140684513494,0.25,-2.9937914690084E-6,-5.57850664103964E-5,-3.24146533191649E-6,10.0007496,10.0007496,51114.51953125,51119.28515625,52.5895300308902,18.6841448883196,3.2393923,0,0,0,4449,9.9831,51116.90234375,,,,,,,,,,,,,,,,,13.753754,,,,,,10.0007496,,,,
,15742026.415,9.9994736,54980.05078125,-6.76047419402308E-5,8.25186165611688E-7,1,0.999253354069792,40.0298881530762,2.00471560020696,16.4700025320053,-0.000728803416585166,-0.000145773563317388,0.25,-1.38513222461001E-6,-6.73165800843146E-5,-1.70516711146213E-6,9.9994307,9.9995165,54957.546875,55002.5546875,52.7349129354671,18.6867602183653,3.22361385,0,0,0,4449,9.98385,54980.05078125,,,,,,,,,,,,,,,,,13.378378,,,,,,9.9994736,,,,
,15742106.215,9.99784135,58970.658203125,-7.9550636610184E-5,8.23154585919499E-7,1,0.999253354069792,40.0298881530762,2.00464736049266,16.4700025320053,-0.000854089479724239,-0.00019185001383915,0.25,-3.49179454875324E-6,-7.92173467642794E-5,-3.87445765380399E-6,9.997817,9.9978657,58940.80078125,59000.515625,53.0671050561402,18.6867149175461,3.2559787,0,0,0,4449,9.98405,58970.658203125,,,,,,,,,,,,,,,,,12.252253,,,,,,9.99784135,,,,
,15742185.395,9.999516,62929.3359375,-8.86717720405408E-5,8.28083471956792E-7,1,0.999253354069792,40.0298881530762,2.00469495090421,16.4700025320053,-0.000952867963384465,-0.000210283035285541,0.25,-3.54484083664927E-6,-8.83188791924707E-5,-3.98726076774834E-6,9.9994287,9.9996033,62899.48828125,62959.18359375,53.1429230225056,18.6864508964884,3.27207875,0,0,0,4449,9.9852,62929.3359375,,,,,,,,,,,,,,,,,13.378378,,,,,,9.999516,,,,
,15742263.705,9.9992857,66842.0859375,-9.89038920599808E-5,1.01126074343001E-6,1,0.999253354069792,40.0298881530762,2.00466549843277,16.4700025320053,-0.00106961839656252,-0.000197754106995029,0.25,-5.3671167590163E-7,-9.85474254563004E-5,-1.05756260017334E-6,9.9991331,9.9994383,66812.125,66872.046875,52.7442924776979,18.6862590353547,3.338611,0,0,0,4449,9.98535,66842.0859375,,,,,,,,,,,,,,,,,13.003003,,,,,,9.9992857,,,,
,15742342.01,9.99949025,70755.61328125,-0.000110791515907383,8.06426047677015E-7,1,0.999253354069792,40.0298881530762,2.00461534376179,16.4700025320053,-0.00119719573198584,-0.000228247656454482,0.25,-1.20358899588434E-6,-0.000110411298568347,-1.80026868396242E-6,9.9992924,9.9996881,70725.65625,70785.5703125,53.1616821069672,18.6870082398128,3.3883821,0,0,0,4449,9.98595,70755.61328125,,,,,,,,,,,,,,,,,12.252253,,,,,,9.99949025,,,,
,15742420.215,9.99848845,74665.7421875,-0.000122454420964352,9.42762138512417E-7,1,0.999253354069792,40.0298881530762,2.00496946931211,16.4700025320053,-0.00132190840715854,-0.000262432699790147,0.25,-2.24394535935767E-6,-0.000122054095588206,-2.91643863803585E-6,9.9984751,9.9985018,74638.078125,74693.40625,52.5723342034671,18.6820211535836,3.4224012,0,0,0,4449,9.9872,74665.7421875,,,,,,,,,,,,,,,,,13.378378,,,,,,9.99848845,,,,
,15742497.18,9.99870445,78511.96875,-0.000133917350322252,1.10183035288482E-6,1,0.999253354069792,40.0298881530762,2.00506328564168,16.4700025320053,-0.00145051655478774,-0.000261987175573027,0.25,-1.23108373129014E-7,-0.000133519845423053,-8.81589933735814E-7,9.9986315,9.9987774,78492.1953125,78531.7421875,52.9170323804479,18.6862695021966,3.4740279,0,0,0,4449,9.98885,78511.96875,,,,,,,,,,,,,,,,,13.378378,,,,,,9.99870445,,,,
,15742575.17,9.9987707,82409.95703125,-0.000144461633064874,9.16738769332689E-7,1,0.999253354069792,40.0298881530762,2.00496637200777,16.4700025320053,-0.00156535344673274,-0.000280604482277289,0.25,7.2746855138812E-8,-0.000144064174471287,-7.61845372372654E-7,9.9987478,9.9987936,82380.1015625,82439.8125,52.6544051979863,18.6881501978541,3.5089071,0,0,0,4449,9.9895,82409.95703125,,,,,,,,,,,,,,,,,13.378378,,,,,,9.9987707,,,,
,15742652.385,9.99885225,86268.1796875,-0.000158647004846798,1.1070503788017E-6,1,0.999253354069792,40.0298881530762,2.00506954264448,16.4700025320053,-0.00171782871662623,-0.00031755961351156,0.25,-7.64651155775154E-7,-0.00015823853179698,-1.69480032369401E-6,9.9988327,9.9988718,86233.1328125,86303.2265625,52.8154206729479,18.68724468616,3.45710685,0,0,0,4449,9.9901,86268.1796875,,,,,,,,,,,,,,,,,13.378378,,,,,,9.99885225,,,,
,15742746.76,9.99840305,89894.66015625,-0.000164645620901062,1.17047775751977E-6,1,0.999253354069792,40.0298881530762,2.00485987396321,16.4700025320053,-0.00178147094862946,-0.000337851853874297,0.25,-1.54108024862272E-6,-0.00016424941446352,-2.51887842097567E-6,9.9984016,9.9984045,89868.46875,89920.8515625,52.8083860162748,18.684946709922,3.544136,0,0,0,4449,9.99175,89894.66015625,,,,,,,,,,,,,,,,,12.627627,,,,,,9.99840305,,,,
,15742825.41,9.99979495,85970.44140625,-0.000155645724467307,1.04381919188705E-6,1,0.999253354069792,40.0298881530762,2.00504914641246,16.4700025320053,-0.0016801255459967,-0.00034024213157763,0.25,-3.39944872233272E-6,-0.00015522693869712,-4.30405491980597E-6,9.9995327,10.0000572,85948.0234375,85992.859375,52.7388210780633,18.6824163768773,3.544136,0,0,0,4449,9.9915,85970.44140625,,,,,,,,,,,,,,,,,12.252253,,,,,,9.99979495,,,,
,15742905.195,10.00112915,81982.50390625,-0.000139034004550772,1.13977071676824E-6,1,0.999253354069792,40.0298881530762,2.00498061878387,16.4700025320053,-0.00150171475164453,-0.000296766380899955,0.25,-2.39673171510094E-6,-0.000138634065355371,-3.19151191879211E-6,10.0010843,10.001174,81950,82015.0078125,52.995195232371,18.6835802125979,3.5797191,0,0,0,4449,9.9896,81982.50390625,,,,,,,,,,,,,,,,,13.003003,,,,,,10.00112915,,,,
,15742984.195,10.00148535,78033.89453125,-0.000130856194648291,1.06279648056221E-6,1,0.999253354069792,40.0298881530762,2.00504464293482,16.4700025320053,-0.00141619484346634,-0.000262203024208698,0.25,-6.95676556293084E-7,-0.0001304611867817,-1.43326186165091E-6,10.0014696,10.0015011,78011.4765625,78056.3125,52.5832770027363,18.6855236951322,3.59768905,0,0,0,4449,9.9878,78033.89453125,,,,,,,,,,,,,,,,,13.378378,,,,,,10.00148535,,,,
,15743066.03,10.0023289,73943.75,-0.00011980132073988,9.13300135981252E-7,1,0.999253354069792,40.0298881530762,2.00498870122394,16.4700025320053,-0.00129453522634588,-0.000249471654580623,0.25,-1.52700700350613E-6,-0.000119408843847289,-2.18424759294102E-6,10.0022917,10.0023661,73913.71875,73973.78125,52.7020845376594,18.6865174667755,3.544136,0,0,0,4449,9.98575,73943.75,,,,,,,,,,,,,,,,,13.753754,,,,,,10.0023289,,,,
,15743145.71,10.0022526,69960.42578125,-0.000109880330245423,1.18274429455222E-6,1,0.999253354069792,40.0298881530762,2.00509584388057,16.4700025320053,-0.00119152384657949,-0.000204363020900107,0.25,8.39477957665232E-7,-0.00010950968893762,2.43784251873265E-7,10.0022526,10.0022526,69955.546875,69965.3046875,52.809167644794,18.685203288856,3.6519601,0,0,0,4449,9.9855,69960.42578125,,,,,,,,,,,,,,,,,13.003003,,,,,,10.0022526,,,,
,15743224.755,10.0024614,66012.02734375,-9.87576863236202E-5,7.42061528105966E-7,1,0.999253354069792,40.0298881530762,2.00505243432941,16.4700025320053,-0.00107061131018072,-0.000183957582860814,0.25,7.10948154218461E-7,-9.8404117474562E-5,1.89352273221168E-7,10.0024614,10.0024614,66007.140625,66016.9140625,52.6606582261402,18.6859374575677,3.6886253,0,0,0,4449,9.9841,66012.02734375,,,,,,,,,,,,,,,,,12.252253,,,,,,10.0024614,,,,
,15743304.78,10.00304745,62011.1953125,-8.66884837200207E-5,7.65355914279645E-7,1,0.999253354069792,40.0298881530762,2.00488103314167,16.4700025320053,-0.000943331866951253,-0.000140052856784835,0.25,2.58602217715106E-6,-8.63705089030704E-5,2.13360248093599E-6,10.0029049,10.00319,61983.6875,62038.703125,52.8881121252364,18.6875959165121,3.6886253,0,0,0,4449,9.98235,62011.1953125,,,,,,,,,,,,,,,,,12.252253,,,,,,10.00304745,,,,
,15743384.21,10.0023713,58037.447265625,-7.40129372238141E-5,9.65825153841211E-7,1,0.999253354069792,40.0298881530762,2.00489659621925,16.4700025320053,-0.00080637694758154,-0.000113203646379127,0.25,2.7827128133073E-6,-7.37294314556842E-5,2.40541828404108E-6,10.0023031,10.0024395,58004.9140625,58069.98046875,52.6426807701979,18.6864546888031,3.7256589,0,0,0,4449,9.98045,58037.447265625,,,,,,,,,,,,,,,,,12.627627,,,,,,10.0023713,,,,
,15743463.035,10.0020819,54099.677734375,-6.03710903537652E-5,7.48933517434778E-7,1,0.999253354069792,40.0298881530762,2.00480817090686,16.4700025320053,-0.000652610387235462,-0.000120179777901889,0.25,-3.15315448552232E-7,-6.0115694127883E-5,-6.0266213319096E-7,10.0020247,10.0021391,54067.16796875,54132.1875,52.7302231643517,18.6840761798266,3.6888095,0,0,0,4449,9.97955,54099.677734375,,,,,,,,,,,,,,,,,13.003003,,,,,,10.0020819,,,,
,15743541.385,10.001462,50184.005859375,-5.40837099686089E-5,7.79465644329576E-7,1,0.999253354069792,40.0298881530762,2.00480869322923,16.4700025320053,-0.000586067727235038,-9.90741262955645E-5,0.25,5.00393013318945E-7,-5.38487313886664E-5,2.48876559318447E-7,10.0013914,10.0015326,50159.0078125,50209.00390625,53.0452194576018,18.6873637024871,3.7630644,0,0,0,4449,9.977,50184.005859375,,,,,,,,,,,,,,,,,13.378378,,,,,,10.001462,,,,
,15743619.75,10.00292825,46268.732421875,-4.19711937555375E-5,6.99060107448883E-7,1,0.999253354069792,40.0298881530762,2.00478257315375,16.4700025320053,-0.000455998648353522,-6.97373239709053E-5,0.25,1.04032240850004E-6,-4.17843063051902E-5,8.49594465310492E-7,10.0028725,10.002984,46241.40625,46296.05859375,53.3328587526787,18.690430526938,3.72584485,0,0,0,4449,9.97625,46268.732421875,,,,,,,,,,,,,,,,,13.378378,,,,,,10.00292825,,,,
,15743700.23,10.00177955,42244.70703125,-2.99276114194025E-5,6.33914877404692E-7,1,0.999253354069792,40.0298881530762,2.00481993689623,16.4700025320053,-0.000326443293627467,-4.21687653488214E-5,0.25,1.43413194481372E-6,-2.97919848585201E-5,1.30042308475952E-6,10.00177,10.0017891,42212.2578125,42277.15625,53.1132211387749,18.6865698872729,3.8008451,0,0,0,4449,9.97515,42244.70703125,,,,,,,,,,,,,,,,,13.378378,,,,,,10.00177955,,,,
,15743780.5,10.00157405,38231.810546875,-1.81669979894703E-5,5.47139474539631E-7,1,0.999253354069792,40.0298881530762,2.00470795116399,16.4700025320053,-0.000196367436473155,-3.54170979067403E-5,0.25,-4.16105627907273E-8,-1.80778354737788E-5,-1.14895838436035E-7,10.0014973,10.0016508,38199.23828125,38264.3828125,53.1640269925249,18.6877621041854,3.8199253,0,0,0,4449,9.9734,38231.810546875,,,,,,,,,,,,,,,,,12.252253,,,,,,10.00157405,,,,
,15743862.92,10.00160025,34111.30078125,-7.75450153479124E-6,4.88868790861277E-7,1,0.999253354069792,40.0298881530762,2.00483954515159,16.4700025320053,-8.24963238118644E-5,-2.25072316823127E-5,0.25,-7.02913162708785E-7,-7.71258531962774E-6,-7.29129980320908E-7,10.0015402,10.0016603,34081.40625,34141.1953125,52.7653964477171,18.686482854218,3.8775487,0,0,0,4449,9.9735,34111.30078125,,,,,,,,,,,,,,,,,13.003003,,,,,,10.00160025,,,,
,15743942.545,10.0005765,30133.416015625,2.94345632602644E-6,3.48122906300028E-7,1,0.999253354069792,40.0298881530762,2.00518292527777,16.4700025320053,3.51796264699669E-5,-1.32193761338891E-5,0.25,-1.74519287744275E-6,2.93449401495108E-6,-1.72541112816857E-6,10.0005684,10.0005846,30098.59765625,30168.234375,52.9819075475441,18.6899658853358,3.80103495,0,0,0,4449,9.9738,30133.416015625,,,,,,,,,,,,,,,,,13.003003,,,,,,10.0005765,,,,
,15744022.12,10.00100755,26157.666015625,1.4118938346259E-5,3.91540564780352E-7,1,0.999253354069792,40.0298881530762,2.00485241683871,16.4700025320053,0.000154331693704871,1.74990338958946E-5,0.25,-8.85487627010981E-7,1.4046653513597E-5,-8.32305267774503E-7,10.0009956,10.0010195,26135.19921875,26180.1328125,52.7779025040248,18.6891546693889,3.8582771,0,0,0,4449,9.9732,26157.666015625,,,,,,,,,,,,,,,,,12.252253,,,,,,10.00100755,,,,
,15744104.18,10.0013924,22054.4345703125,2.36014033826515E-5,3.87165553885078E-7,1,0.999253354069792,40.0298881530762,2.00476643867368,16.4700025320053,0.000257866497375468,2.96375476482288E-5,0.25,-1.43895385535686E-6,2.3477117444501E-5,-1.35509436383669E-6,10.0013123,10.0014725,22027.103515625,22081.765625,52.7607066766017,18.6930754230111,3.8775487,0,0,0,4449,9.97095,22054.4345703125,,,,,,,,,,,,,,,,,13.378378,,,,,,10.0013924,,,,
,15744184.12,10.00112105,18059.5361328125,3.34963749851879E-5,3.93469665799754E-7,1,0.999253354069792,40.0298881530762,2.00479251053778,16.4700025320053,0.000365307290900459,4.56114524837263E-5,0.25,-1.70657877439844E-6,3.33147594222902E-5,-1.59607878948063E-6,10.0010862,10.0011559,18034.5546875,18084.517578125,53.188257476621,18.6885163781921,3.8586621,0,0,0,4449,9.9717,18059.5361328125,,,,,,,,,,,,,,,,,13.378378,,,,,,10.00112105,,,,
,15744262.615,10.0008698,14139.0307617188,4.28247171380656E-5,3.41692937352324E-7,1,0.999253354069792,40.0298881530762,2.00489870144369,16.4700025320053,0.000468496452017057,4.99116950451908E-5,0.25,-2.95033230467713E-6,4.25899617066946E-5,-2.81296548611783E-6,10.0008698,10.0008698,14136.619140625,14141.4423828125,53.0280236301787,18.6887378033849,3.8008451,0,0,0,4449,9.97145,14139.0307617188,,,,,,,,,,,,,,,,,13.378378,,,,,,10.0008698,,,,
,15744343.915,10.0009012,10073.29296875,5.23537119402751E-5,2.19314591580347E-7,1,0.999253354069792,40.0298881530762,2.00480763574152,16.4700025320053,0.000569774824532206,7.73335207778916E-5,0.25,-2.08573520655111E-6,5.20571932010438E-5,-1.93665423427568E-6,10.0009012,10.0009012,10068.2705078125,10078.3154296875,52.8740428118902,18.6926752630034,3.8390055,0,0,0,4449,9.9706,10073.29296875,,,,,,,,,,,,,,,,,13.753754,,,,,,10.0009012,,,,
,15744423.545,10.00001955,6092.20581054687,6.15400983673354E-5,2.37326521579776E-7,1,0.999253354069792,40.0298881530762,2.0047641361539,16.4700025320053,0.00066898733487186,9.48246168171252E-5,0.25,-2.07657595262187E-6,6.11853933560622E-5,-1.91461818309131E-6,9.9999981,10.000041,6064.72900390625,6119.6826171875,52.727878278794,18.6876181901003,3.9164791,0,0,0,4449,9.97065,6092.20581054687,,,,,,,,,,,,,,,,,13.753754,,,,,,10.00001955,,,,
,15744505.965,9.9998198,1973.25390625,6.78215064529121E-5,2.06151697959287E-7,1,0.999253354069792,40.0298881530762,2.00477738691017,16.4700025320053,0.000736822510098499,0.000106768393339909,0.25,-2.06690003905231E-6,6.74252854331346E-5,-1.90089753040899E-6,9.9998198,9.9998198,1970.73693847656,1975.77087402344,53.1702800206787,18.6929371854402,3.9164791,0,0,0,4449,9.9711,1973.25390625,,,,,,,,,,,,,,,,,13.378378,,,,,,9.9998198,,,,
,15744584.795,10.0002975,-1966.50109863281,6.01893652627307E-5,2.00360567300633E-7,1,0.999253354069792,40.0298881530762,2.00484610105872,16.4700025320053,0.000654568383202797,9.11148802391977E-5,0.25,-2.1712764710351E-6,5.98384901649409E-5,-2.02197708025712E-6,10.0002975,10.0002975,-1968.88732910156,-1964.11486816406,53.1507393076979,18.6925227214861,3.9558001,0,0,0,4449,9.97165,-1966.50109863281,,,,,,,,,,,,,,,,,13.378378,,,,,,10.0002975,,,,
,15744662.51,9.99998335,-5847.638671875,6.39937243544892E-5,2.98030998185231E-7,1,0.999253354069792,40.0298881530762,2.00474148147654,16.4700025320053,0.000696139962383515,9.58214400473361E-5,0.25,-2.41615379353174E-6,6.36251978295927E-5,-2.24691326312561E-6,9.9999638,10.0000029,-5872.69482421875,-5822.58251953125,53.2875242985633,18.6933059688127,3.9361396,0,0,0,4449,9.9711,-5847.638671875,,,,,,,,,,,,,,,,,13.003003,,,,,,9.99998335,,,,
,15744744.44,10.00015545,-9943.015625,6.94039895632869E-5,3.02123010835223E-7,1,0.999253354069792,40.0298881530762,2.00472345797045,16.4700025320053,0.000754578288163632,0.000106625457822669,0.25,-2.38418621756535E-6,6.90096997000675E-5,-2.18917446217482E-6,10.0001278,10.0001831,-9975.421875,-9910.609375,53.086645769121,18.6951851471827,3.9558001,0,0,0,4449,9.9707,-9943.015625,,,,,,,,,,,,,,,,,13.378378,,,,,,10.00015545,,,,
,15744824.335,9.999815,-13936.3686523437,7.12257142900907E-5,3.29277758972273E-7,1,0.999253354069792,40.0298881530762,2.00468563190634,16.4700025320053,0.000773906793280431,0.000112487604322821,0.25,-2.17807965418121E-6,7.08272148694407E-5,-1.96581001071341E-6,9.999815,9.999815,-13943.8720703125,-13928.865234375,53.0788294839287,18.6947326865739,3.8775487,0,0,0,4449,9.97055,-13936.3686523437,,,,,,,,,,,,,,,,,12.252253,,,,,,9.999815,,,,
,15744902.525,10.00058175,-17843.83984375,6.67757824676325E-5,3.63390225398398E-7,1,0.999253354069792,40.0298881530762,2.0045920931297,16.4700025320053,0.00072551122198204,0.000105975327901174,0.25,-2.00814828339435E-6,6.6409115977884E-5,-1.79635980117023E-6,10.000536,10.0006275,-17876.3515625,-17811.328125,52.6129788864671,18.6935924387321,3.9558001,0,0,0,4449,9.97065,-17843.83984375,,,,,,,,,,,,,,,,,13.378378,,,,,,10.00058175,,,,
,15744982.75,10.0003557,-21853.994140625,5.50676261010856E-5,4.1784023275253E-7,1,0.999253354069792,40.0298881530762,2.00476553426976,16.4700025320053,0.000598538644782602,8.67664676209308E-5,0.25,-1.72714520701543E-6,5.47720433536234E-5,-1.54094588210572E-6,10.0002718,10.0004396,-21884.048828125,-21823.939453125,52.8490306992748,18.6945084702595,3.9756581,0,0,0,4449,9.97075,-21853.994140625,,,,,,,,,,,,,,,,,12.252253,,,,,,10.0003557,,,,
,15745060.615,10.0006523,-25747.0400390625,4.11422389207713E-5,3.11992959013534E-7,1,0.999253354069792,40.0298881530762,2.00468232133746,16.4700025320053,0.000449776277632075,5.04225947517929E-5,0.25,-2.63161692995739E-6,4.09311780125989E-5,-2.47720881901648E-6,10.0006523,10.0006523,-25751.994140625,-25742.0859375,52.8662265266979,18.6939428160282,3.9955161,0,0,0,4449,9.9712,-25747.0400390625,,,,,,,,,,,,,,,,,12.252253,,,,,,10.0006523,,,,
,15745137.285,9.9996829,-29577.7109375,3.03142075390093E-5,4.73465820229462E-7,1,0.999253354069792,40.0298881530762,2.0046820560989,16.4700025320053,0.000331614562615067,3.62234905006646E-5,0.25,-2.03142585535598E-6,3.01632846552323E-5,-1.91143779699689E-6,9.9996233,9.9997425,-29610.232421875,-29545.189453125,53.1327618517556,18.6950046639675,3.9559976,0,0,0,4449,9.9708,-29577.7109375,,,,,,,,,,,,,,,,,12.252253,,,,,,9.9996829,,,,
,15745220.905,9.9994164,-33755.796875,2.54925860925062E-5,4.50582995043137E-7,1,0.999253354069792,40.0298881530762,2.00465140273804,16.4700025320053,0.000279610739878211,2.65351098529218E-5,0.25,-2.07741706835655E-6,2.53712613860085E-5,-1.96946803354581E-6,9.9994164,9.9994164,-33758.23046875,-33753.36328125,52.9475158926979,18.6953281053644,3.9565897,0,0,0,4449,9.9716,-33755.796875,,,,,,,,,,,,,,,,,13.753754,,,,,,9.9994164,,,,
,15745298.095,9.9989076,-37615.3828125,2.73903117809073E-5,4.71924711231089E-7,1,0.999253354069792,40.0298881530762,2.00455109130772,16.4700025320053,0.000298770901812629,3.80104323027274E-5,0.25,-1.35909977401614E-6,2.72609248676417E-5,-1.24244527566084E-6,9.9988766,9.9989386,-37635.2734375,-37595.4921875,53.0780478554095,18.6933181161427,3.9760549,0,0,0,4449,9.97165,-37615.3828125,,,,,,,,,,,,,,,,,13.378378,,,,,,9.9989076,,,,
,15745379.825,9.99917365,-41698.3359375,3.28555940398674E-5,4.78167384113603E-7,1,0.999253354069792,40.0298881530762,2.00458127547273,16.4700025320053,0.00035982200507284,3.79262087158934E-5,0.25,-2.34681626401546E-6,3.27091637136858E-5,-2.19717983290609E-6,9.9990196,9.9993277,-41723.30078125,-41673.37109375,53.0327134012941,18.6956232882007,3.9559976,0,0,0,4449,9.9726,-41698.3359375,,,,,,,,,,,,,,,,,12.252253,,,,,,9.99917365,,,,
,15745457.79,9.9975457,-45593.861328125,4.13210570163304E-5,6.89340987015131E-7,1,0.999253354069792,40.0298881530762,2.00483277159457,16.4700025320053,0.00045097067070578,5.72271964636706E-5,0.25,-2.07954858336147E-6,4.11404575761791E-5,-1.88819913977072E-6,9.9974813,9.9976101,-45626.3125,-45561.41015625,53.0319317727748,18.6953616496204,3.9559976,0,0,0,4449,9.9752,-45593.861328125,,,,,,,,,,,,,,,,,13.003003,,,,,,9.9975457,,,,
,15745538.78,9.9985895,-49641.814453125,5.0219123094633E-5,8.1421661145334E-7,1,0.999253354069792,40.0298881530762,2.004865299034,16.4700025320053,0.000543608391968297,9.52559450007801E-5,0.25,-1.61978246118435E-7,4.99982968390542E-5,6.90193656494317E-8,9.9985895,9.9985895,-49644.26953125,-49639.359375,52.9271935511979,18.6938997862234,3.9955161,0,0,0,4449,9.97395,-49641.814453125,,,,,,,,,,,,,,,,,12.252253,,,,,,9.9985895,,,,
,15745616.65,9.9997034,-53533.81640625,6.01412557759035E-5,7.97041349569076E-7,1,0.999253354069792,40.0298881530762,2.00466651820652,16.4700025320053,0.000650120647773826,0.000119400893304325,0.25,2.86908577342367E-7,5.98853648480779E-5,5.71803086045733E-7,9.9997034,9.9997034,-53556.23046875,-53511.40234375,52.8568469844671,18.6973274961614,4.0155734,0,0,0,4449,9.97505,-53533.81640625,,,,,,,,,,,,,,,,,12.252253,,,,,,9.9997034,,,,
,15745699.835,9.9988079,-57691.32421875,7.31854885713173E-5,8.03181205010295E-7,1,0.999253354069792,40.0298881530762,2.00478928128283,16.4700025320053,0.000797981040053911,0.000108166788677135,0.25,-3.09835752156568E-6,7.2905591734743E-5,-2.72487435458304E-6,9.9987602,9.9988556,-57723.75390625,-57658.89453125,52.9936319753325,18.6975662294805,4.0356307,0,0,0,4449,9.9761,-57691.32421875,,,,,,,,,,,,,,,,,13.378378,,,,,,9.9988079,,,,
,15745780.515,9.99870685,-61724.423828125,8.31975145269002E-5,7.11120585756381E-7,1,0.999253354069792,40.0298881530762,2.004785296453,16.4700025320053,0.000905523214735782,0.000133100040225398,0.25,-2.60151300786874E-6,8.28917351105678E-5,-2.16774453680674E-6,9.9986954,9.9987183,-61752.01171875,-61696.8359375,52.687233595794,18.6972828615137,3.9760549,0,0,0,4449,9.9763,-61724.423828125,,,,,,,,,,,,,,,,,13.003003,,,,,,9.99870685,,,,
,15745859.245,9.9988823,-65657.53125,9.15734477602283E-5,6.80268365068811E-7,1,0.999253354069792,40.0298881530762,2.00467602713543,16.4700025320053,0.00099460012962276,0.000159018717353793,0.25,-1.72258707696012E-6,9.12495087629039E-5,-1.23624533362877E-6,9.9987965,9.9989681,-65690.0625,-65625,53.1405781369479,18.6963236937259,4.01597405,0,0,0,4449,9.97865,-65657.53125,,,,,,,,,,,,,,,,,12.252253,,,,,,9.9988823,,,,
,15745939.605,9.9976816,-69675.2421875,0.000102872310518081,7.08255060068035E-7,1,0.999253354069792,40.0298881530762,2.00473284774739,16.4700025320053,0.00111785940951888,0.000177154215578393,0.25,-2.09086576711992E-6,0.000102530803570996,-1.5296849666325E-6,9.9976816,9.9976816,-69677.625,-69672.859375,52.8709162978133,18.6969772761256,3.9558001,0,0,0,4449,9.978,-69675.2421875,,,,,,,,,,,,,,,,,12.252253,,,,,,9.9976816,,,,
,15746019.51,9.99861385,-73667.6875,0.000115676830425746,1.093258900624E-6,1,0.999253354069792,40.0298881530762,2.00469784060885,16.4700025320053,0.00125143585988992,0.000231613096474806,0.25,6.22784472748477E-7,0.000115300894711348,1.25909735832782E-6,9.9985476,9.9986801,-73695.1875,-73640.1875,53.0960253113518,18.6984740900334,4.05588935,0,0,0,4449,9.97955,-73667.6875,,,,,,,,,,,,,,,,,12.252253,,,,,,9.99861385,,,,
,15746096.445,9.99768785,-77513.12890625,0.000126725829061459,8.41435167103729E-7,1,0.999253354069792,40.0298881530762,2.00464342294347,16.4700025320053,0.00137067573255726,0.000256774627029364,0.25,9.43674742383493E-7,0.000126338260988017,1.65518967877387E-6,9.9975615,9.9978142,-77537.9921875,-77488.265625,52.5895300308902,18.7011479515592,4.05588935,0,0,0,4449,9.9806,-77513.12890625,,,,,,,,,,,,,,,,,12.252253,,,,,,9.99768785,,,,
,15746176.635,9.9990692,-81520.9453125,0.000138359382102153,9.43293815708391E-7,1,0.999253354069792,40.0298881530762,2.00469977401782,16.4700025320053,0.00149872930332411,0.000270049779887375,0.25,5.77933924357209E-8,0.000137971370772252,8.53436416501465E-7,9.9989853,9.9991531,-81545.8203125,-81496.0703125,52.8740428118902,18.6988924163993,4.03643635,0,0,0,4449,9.9826,-81520.9453125,,,,,,,,,,,,,,,,,13.003003,,,,,,9.9990692,,,,
,15746256.47,9.99774555,-85511.4296875,0.000149829646960893,8.88742252805598E-7,1,0.999253354069792,40.0298881530762,2.0047149449413,16.4700025320053,0.00162464830548312,0.000285222627672559,0.25,-6.24853283319969E-7,0.000149445663343339,2.54236749917778E-7,9.997716,9.9977751,-85538.734375,-85484.125,53.1093129961787,18.6984093512946,4.05629435,0,0,0,4449,9.98275,-85511.4296875,,,,,,,,,,,,,,,,,13.378378,,,,,,9.99774555,,,,
,15746335.67,9.99802015,-89468.55078125,0.000163487068332811,9.28624809910586E-7,1,0.999253354069792,40.0298881530762,2.0046684336597,16.4700025320053,0.00177071081711818,0.000324460278877267,0.25,5.18946445055161E-7,0.000163095920889385,1.49065107463767E-6,9.9978828,9.9981575,-89486.078125,-89451.0234375,53.1233823095249,18.6997423365676,4.07635165,0,0,0,4449,9.9838,-89468.55078125,,,,,,,,,,,,,,,,,12.252253,,,,,,9.99802015,,,,
,15746436.265,10.0018787,-86415.171875,0.000151331195991465,1.05996842121684E-6,1,0.999253354069792,40.0298881530762,2.00453827533882,16.4700025320053,0.00163591527054539,0.000315639630913675,0.25,1.90996116602944E-6,0.000150935815552891,2.79477364690162E-6,10.0018787,10.0018787,-86417.6953125,-86412.6484375,53.1382332513902,18.7000483040342,4.1170726,0,0,0,4449,9.9851,-86415.171875,,,,,,,,,,,,,,,,,13.003003,,,,,,10.0018787,,,,
,15746521.09,10.00039385,-82174.91796875,0.000138994872681268,1.05911444574188E-6,1,0.999253354069792,40.0298881530762,2.00451624403503,16.4700025320053,0.0015017605045084,0.00029227982087372,0.25,1.99456146904267E-6,0.000138598786945925,2.7909782928071E-6,10.0002966,10.0004911,-82199.734375,-82150.1015625,53.1687167636402,18.699133704274,4.0966103,0,0,0,4449,9.98325,-82174.91796875,,,,,,,,,,,,,,,,,13.378378,,,,,,10.00039385,,,,
,15746606.605,10.0008216,-77902.28125,0.000127772924994882,1.11669232862494E-6,1,0.999253354069792,40.0298881530762,2.00450642563548,16.4700025320053,0.00138210689449374,0.00025796127818055,0.25,8.64715467119853E-7,0.000127385282999042,1.58386481767604E-6,10.0006237,10.0010195,-77932.3203125,-77872.2421875,53.0444378290825,18.6997287180666,3.9558001,0,0,0,4449,9.98215,-77902.28125,,,,,,,,,,,,,,,,,12.252253,,,,,,10.0008216,,,,
,15746687.24,10.00029755,-73872.16796875,0.000117465736142289,8.73947237956496E-7,1,0.999253354069792,40.0298881530762,2.00454480825454,16.4700025320053,0.00126870934536231,0.000246332098027029,0.25,1.6615155593965E-6,0.000117079563386031,2.30514161183167E-6,10.0002928,10.0003023,-73899.65625,-73844.6796875,53.1898207336595,18.7011632024883,4.05588935,0,0,0,4449,9.98165,-73872.16796875,,,,,,,,,,,,,,,,,13.378378,,,,,,10.00029755,,,,
,15746767.5,10.00079775,-69862.2578125,0.000102184721830517,8.68809878116366E-7,1,0.999253354069792,40.0298881530762,2.00444639539743,16.4700025320053,0.0011079943273646,0.000188518769821174,0.25,-9.16358497491337E-7,0.000101840246271502,-3.62260758496794E-7,10.0007458,10.0008497,-69892.1640625,-69832.3515625,52.9998850034864,18.699399370483,4.0966103,0,0,0,4449,9.98135,-69862.2578125,,,,,,,,,,,,,,,,,13.753754,,,,,,10.00079775,,,,
,15746847.285,10.00136995,-65874.21875,9.10135435945222E-5,7.99738326791635E-7,1,0.999253354069792,40.0298881530762,2.00450624141285,16.4700025320053,0.000984866892780208,0.000178032724939641,0.25,1.34708498680751E-7,9.06829087362466E-5,6.12085885665598E-7,10.0012684,10.0014715,-65904.2421875,-65844.1953125,52.8802958400441,18.6995218563636,3.9957154,0,0,0,4449,9.9798,-65874.21875,,,,,,,,,,,,,,,,,13.003003,,,,,,10.00136995,,,,
,15746927.04,10.001585,-61889.005859375,8.10169863107741E-5,5.9961097919361E-7,1,0.999253354069792,40.0298881530762,2.00442652210255,16.4700025320053,0.000873779797324629,0.000173532666415332,0.25,1.52669341713464E-6,8.06991957950546E-5,1.93405531741289E-6,10.001585,10.001585,-61891.5234375,-61886.48828125,53.0897722831979,18.6983055606673,4.01597405,0,0,0,4449,9.9792,-61889.005859375,,,,,,,,,,,,,,,,,13.378378,,,,,,10.001585,,,,
,15747006.585,10.0010428,-57913.36328125,7.03463058092612E-5,6.8007565004554E-7,1,0.999253354069792,40.0298881530762,2.00446683346782,16.4700025320053,0.000763082606034622,0.000125382710180085,0.25,-9.98513822936556E-7,7.00682712018266E-5,-6.46874313871765E-7,10.0008535,10.0012321,-57938.38671875,-57888.33984375,52.9185956374864,18.6982663214198,4.0966103,0,0,0,4449,9.9785,-57913.36328125,,,,,,,,,,,,,,,,,13.753754,,,,,,10.0010428,,,,
,15747088.62,10.0011587,-53813.408203125,5.94970837337741E-5,6.49501604846722E-7,1,0.999253354069792,40.0298881530762,2.00457362721878,16.4700025320053,0.000647071879582704,9.6108065549254E-5,0.25,-1.75133938517856E-6,5.92544197818264E-5,-1.46018901168425E-6,10.0011587,10.0011587,-53815.96875,-53810.84765625,53.1022783395056,18.6976558995433,3.9558001,0,0,0,4449,9.978,-53813.408203125,,,,,,,,,,,,,,,,,13.378378,,,,,,10.0011587,,,,
,15747167.975,10.00067615,-49848.61328125,4.93097059048349E-5,6.0407834693076E-7,1,0.999253354069792,40.0298881530762,2.0045288699781,16.4700025320053,0.00053293154967062,9.77360156771632E-5,0.25,2.30530883013228E-7,4.90915532321473E-5,4.56087386880955E-7,10.0004368,10.0009155,-49878.5703125,-49818.65625,52.8310532433325,18.6984144124461,4.076148,0,0,0,4449,9.9784,-49848.61328125,,,,,,,,,,,,,,,,,13.753754,,,,,,10.00067615,,,,
,15747247.75,10.00132035,-45858.3515625,3.6909243514455E-5,6.00538434691125E-7,1,0.999253354069792,40.0298881530762,2.0045641735934,16.4700025320053,0.000401778288645141,5.66991025563471E-5,0.25,-1.34132262631473E-6,3.67460972724699E-5,-1.1723331664705E-6,10.0013046,10.0013361,-45885.859375,-45830.84375,52.8490306992748,18.6961771921442,4.01597405,0,0,0,4449,9.9771,-45858.3515625,,,,,,,,,,,,,,,,,12.252253,,,,,,10.00132035,,,,
,15747327.58,10.00047635,-41870.490234375,2.6256646605035E-5,6.63502131096969E-7,1,0.999253354069792,40.0298881530762,2.00465305864022,16.4700025320053,0.000285061432844818,4.43595964051084E-5,0.25,-5.76540559161182E-7,2.61343448079546E-5,-4.62924326607469E-7,10.0003328,10.0006199,-41893.1015625,-41847.87890625,52.6473705413133,18.6972005022738,3.9957154,0,0,0,4449,9.97675,-41870.490234375,,,,,,,,,,,,,,,,,13.003003,,,,,,10.00047635,,,,
,15747409.425,10.0010796,-37782.419921875,1.55407885133271E-5,6.36519314219814E-7,1,0.999253354069792,40.0298881530762,2.00431507177045,16.4700025320053,0.000169304191629729,2.26634748439645E-5,0.25,-6.69582322432547E-7,1.54670766862353E-5,-6.0377025572913E-7,10.0010262,10.001133,-37809.90625,-37754.93359375,52.6997396521017,18.6976192038067,4.076148,0,0,0,4449,9.9754,-37782.419921875,,,,,,,,,,,,,,,,,13.378378,,,,,,10.0010796,,,,
,15747488.19,10.0018425,-33845.0703125,4.49403738738958E-6,4.20459227917985E-7,1,0.999253354069792,40.0298881530762,2.00456671017886,16.4700025320053,5.10856492275205E-5,-5.42190840475548E-6,0.25,-1.3004121003856E-6,4.47623988189405E-6,-1.2766290870919E-6,10.0016508,10.0020342,-33872.44140625,-33817.69921875,53.1132211387749,18.6960087717953,3.9558001,0,0,0,4449,9.9743,-33845.0703125,,,,,,,,,,,,,,,,,13.378378,,,,,,10.0018425,,,,
,15747569.455,10.0008831,-29784.5703125,-5.92851951606414E-6,5.78931986961222E-7,1,0.999253354069792,40.0298881530762,2.00442878180464,16.4700025320053,-6.2918633577286E-5,-1.79401966253389E-5,0.25,-6.07037411556872E-7,-5.89541579390581E-6,-6.25327651970959E-7,10.0008507,10.0009155,-29809.474609375,-29759.666015625,53.374285064198,18.6967637957277,4.076148,0,0,0,4449,9.9736,-29784.5703125,,,,,,,,,,,,,,,,,13.003003,,,,,,10.0008831,,,,
,15747648.15,10.00055645,-25849.5498046875,-1.43824915623504E-5,4.55676968406464E-7,1,0.999253354069792,40.0298881530762,2.00459928176067,16.4700025320053,-0.000152927612781637,-4.18694536268399E-5,0.25,-1.32280591631098E-6,-1.43010994310058E-5,-1.36486961228564E-6,10.0005369,10.000576,-25877.17578125,-25821.923828125,53.2351551877748,18.6963681798366,3.9957154,0,0,0,4449,9.97375,-25849.5498046875,,,,,,,,,,,,,,,,,13.753754,,,,,,10.00055645,,,,
,15747730.375,10.0008059,-21739.029296875,-2.59769106701654E-5,3.98282202960873E-7,1,0.999253354069792,40.0298881530762,2.00462521498172,16.4700025320053,-0.00027704683575801,-7.07399593862909E-5,0.25,-1.94370961879128E-6,-2.58285455331277E-5,-2.01630019833418E-6,10.0008059,10.0008059,-21744.09375,-21733.96484375,53.0350582868518,18.6933818302839,4.076148,0,0,0,4449,9.97465,-21739.029296875,,,,,,,,,,,,,,,,,13.378378,,,,,,10.0008059,,,,
,15747809.055,9.9999599,-17808.6416015625,-3.47711832891878E-5,4.15289217349969E-7,1,0.999253354069792,40.0298881530762,2.00447801685905,16.4700025320053,-0.000371538178855267,-9.03720180770216E-5,0.25,-2.21086106392213E-6,-3.45704436391151E-5,-2.30290223366482E-6,9.9999599,9.9999599,-17811.056640625,-17806.2265625,52.8138574159094,18.695830675,4.076148,0,0,0,4449,9.97405,-17808.6416015625,,,,,,,,,,,,,,,,,13.753754,,,,,,9.9999599,,,,
,15747889.02,10.00078205,-13811.4497070312,-4.42554983886792E-5,2.89706076578251E-7,1,0.999253354069792,40.0298881530762,2.00465769996128,16.4700025320053,-0.000475902129191129,-9.79069375254319E-5,0.25,-1.23923555841273E-6,-4.40004930618575E-5,-1.35612094014514E-6,10.0007277,10.0008364,-13843.921875,-13778.9775390625,52.5457588338133,18.6940316542753,4.0966103,0,0,0,4449,9.9732,-13811.4497070312,,,,,,,,,,,,,,,,,13.378378,,,,,,10.00078205,,,,
,15747969.52,10.0001559,-9787.92626953125,-5.35152573477974E-5,2.8472886455901E-7,1,0.999253354069792,40.0298881530762,2.00446858389906,16.4700025320053,-0.00057402784347899,-0.000126012750303294,0.25,-2.21622457121108E-6,-5.32004859396862E-5,-2.34279174284937E-6,10.0001001,10.0002117,-9820.3740234375,-9755.478515625,52.7575801625248,18.6932797225665,4.03583205,0,0,0,4449,9.9735,-9787.92626953125,,,,,,,,,,,,,,,,,12.252253,,,,,,10.0001559,,,,
,15748050.59,9.99998805,-5737.20239257812,-6.22027177234824E-5,2.98875791434162E-7,1,0.999253354069792,40.0298881530762,2.00457227172949,16.4700025320053,-0.000668071184998432,-0.000141514426087942,0.25,-2.12936119485214E-6,-6.18335410005832E-5,-2.26736435218951E-6,9.9999704,10.0000057,-5762.2568359375,-5712.14794921875,52.8380879000056,18.6948308835654,3.9957154,0,0,0,4449,9.97375,-5737.20239257812,,,,,,,,,,,,,,,,,13.378378,,,,,,9.99998805,,,,
,15748129.545,9.9994955,-1790.41625976562,-6.78254347668099E-5,2.41804335701304E-7,1,0.999253354069792,40.0298881530762,2.00453158844368,16.4700025320053,-0.000728538525525476,-0.000153537937398086,0.25,-2.26257875691242E-6,-6.74192239962903E-5,-2.40255371261643E-6,9.9994583,9.9995327,-1817.87268066406,-1762.95983886719,52.6372093705633,18.6949024253995,4.03643635,0,0,0,4449,9.9737,-1790.41625976562,,,,,,,,,,,,,,,,,13.753754,,,,,,9.9994955,,,,
,15748207.985,10.0007277,2128.76086425781,-5.87396792868608E-5,2.97054814993386E-7,1,0.999253354069792,40.0298881530762,2.00457940709046,16.4700025320053,-0.000630834309682092,-0.000133697631486914,0.25,-2.0257604048537E-6,-5.83879747650879E-5,-2.14731002373037E-6,10.0007277,10.0007277,2126.18627929687,2131.33544921875,52.8959284104287,18.693945337843,4.076148,0,0,0,4449,9.9744,2128.76086425781,,,,,,,,,,,,,,,,,13.378378,,,,,,10.0007277,,,,
,15748284.725,10.0013051,5965.6337890625,-6.24672229981478E-5,2.97352682935166E-7,1,0.999253354069792,40.0298881530762,2.00441014214313,16.4700025320053,-0.000669942780127508,-0.000147327238733079,0.25,-2.62103856916596E-6,-6.20955351421142E-5,-2.75743819084781E-6,10.0012035,10.0014067,5935.64306640625,5995.62451171875,53.0514724857556,18.6910534262075,4.07635165,0,0,0,4449,9.97325,5965.6337890625,,,,,,,,,,,,,,,,,13.753754,,,,,,10.0013051,,,,
,15748364.695,10.0008335,9961.9052734375,-6.79615412563019E-5,2.39839926254039E-7,1,0.999253354069792,40.0298881530762,2.00467885758811,16.4700025320053,-0.000728037941834789,-0.000165832787341485,0.25,-3.34942504095587E-6,-6.75606257281674E-5,-3.50764472617247E-6,10.0008039,10.0008631,9929.529296875,9994.28125,52.7270966502748,18.6924170724464,4.01597405,0,0,0,4449,9.97355,9961.9052734375,,,,,,,,,,,,,,,,,13.003003,,,,,,10.0008335,,,,
,15748443.295,9.9998717,13890.5209960938,-7.04797042382097E-5,3.06199659052823E-7,1,0.999253354069792,40.0298881530762,2.00451574991286,16.4700025320053,-0.000757115649399263,-0.000160098627794729,0.25,-2.3606225457234E-6,-7.00726324873992E-5,-2.54485192967921E-6,9.999855,9.9998884,13863.091796875,13917.9501953125,52.6997396521017,18.6920016248997,4.03583205,0,0,0,4449,9.97355,13890.5209960938,,,,,,,,,,,,,,,,,13.378378,,,,,,9.9998717,,,,
,15748522.125,9.9986863,17830.822265625,-6.52949850215077E-5,3.74839266540763E-7,1,0.999253354069792,40.0298881530762,2.00458484579574,16.4700025320053,-0.000700882972199591,-0.000151877791980212,0.25,-2.50125453256006E-6,-6.49230171302721E-5,-2.68338225090947E-6,9.9985819,9.9987907,17810.662109375,17850.982421875,52.6739459109671,18.6935330344675,4.05629435,0,0,0,4449,9.9749,17830.822265625,,,,,,,,,,,,,,,,,13.378378,,,,,,9.9986863,,,,
,15748600.465,9.99953315,21745.9931640625,-5.38724777266408E-5,3.48777734868958E-7,1,0.999253354069792,40.0298881530762,2.00450583291672,16.4700025320053,-0.000577430991812371,-0.000130286101196299,0.25,-2.51256525767367E-6,-5.35696642148104E-5,-2.67143615562531E-6,9.9994411,9.9996252,21723.58203125,21768.404296875,52.9842524331018,18.6918655114356,4.03583205,0,0,0,4449,9.9737,21745.9931640625,,,,,,,,,,,,,,,,,13.378378,,,,,,9.99953315,,,,
,15748678.29,10.0000019,25634.70703125,-4.02821538496846E-5,4.57621862668022E-7,1,0.999253354069792,40.0298881530762,2.00453220334092,16.4700025320053,-0.000431134631479259,-0.000101278696176468,0.25,-2.22655179907226E-6,-4.00589896729141E-5,-2.35180190510503E-6,9.9999361,10.0000677,25602.21484375,25667.19921875,52.9803442905056,18.691871290464,4.03583205,0,0,0,4449,9.9739,25634.70703125,,,,,,,,,,,,,,,,,13.003003,,,,,,10.0000019,,,,
,15748758.295,9.99957465,29635.3583984375,-2.87226145228657E-5,4.98968385031964E-7,1,0.999253354069792,40.0298881530762,2.00434757268298,16.4700025320053,-0.000304215200037738,-9.03001090214518E-5,0.25,-3.25454109941358E-6,-2.85609746456662E-5,-3.34128268880255E-6,9.9995203,9.999629,29610.23828125,29660.478515625,52.8998365530248,18.6917106847099,4.0966103,0,0,0,4449,9.9747,29635.3583984375,,,,,,,,,,,,,,,,,13.003003,,,,,,9.99957465,,,,
,15748838.74,9.9999018,33655.890625,-2.55901883868885E-5,5.62735810248955E-7,1,0.999253354069792,40.0298881530762,2.0045208981014,16.4700025320053,-0.00027072576262657,-8.25366859380854E-5,0.25,-3.08557866445682E-6,-2.54485600971963E-5,-3.16758032039576E-6,9.9997988,10.0000048,33628.30078125,33683.48046875,52.8036962451594,18.6930957280374,4.0966103,0,0,0,4449,9.9745,33655.890625,,,,,,,,,,,,,,,,,13.378378,,,,,,9.9999018,,,,
,15748917.15,9.9988036,37573.482421875,-2.66821523975659E-5,5.54099378814508E-7,1,0.999253354069792,40.0298881530762,2.00439393806626,16.4700025320053,-0.000283902122382117,-7.70456295864361E-5,0.25,-2.37773819139584E-6,-2.65412104989608E-5,-2.47309373205269E-6,9.9986658,9.9989414,37545.81640625,37601.1484375,52.8412144140825,18.6930124022038,4.0966103,0,0,0,4449,9.97535,37573.482421875,,,,,,,,,,,,,,,,,12.252253,,,,,,9.9988036,,,,
,15748996.76,9.998332,41554.3984375,-3.41060144092829E-5,5.89252211315823E-7,1,0.999253354069792,40.0298881530762,2.00438034457956,16.4700025320053,-0.000364465383735759,-8.99537965348801E-5,0.25,-2.242597920175E-6,-3.39341044127398E-5,-2.3754182238579E-6,9.998332,9.998332,41549.203125,41559.59375,53.0217706020248,18.6940648110131,4.0966103,0,0,0,4449,9.97545,41554.3984375,,,,,,,,,,,,,,,,,13.378378,,,,,,9.998332,,,,
,15749074.385,9.999084,45432.6484375,-4.24172894890419E-5,8.42762252646089E-7,1,0.999253354069792,40.0298881530762,2.00452070207778,16.4700025320053,-0.00045338481924277,-0.000111880786568835,0.25,-2.7795221260001E-6,-4.22100012087869E-5,-2.953041946527E-6,9.9990158,9.9991522,45402.65234375,45462.64453125,52.7349129354671,18.6877307668299,4.05629435,0,0,0,4449,9.976,45432.6484375,,,,,,,,,,,,,,,,,12.252253,,,,,,9.999084,,,,
,15749152.07,9.99894855,49313.509765625,-4.96373633638804E-5,5.97847486133395E-7,1,0.999253354069792,40.0298881530762,2.00445740725663,16.4700025320053,-0.000534374950448661,-0.000109955741274472,0.25,-1.30349507694969E-6,-4.94116645487977E-5,-1.52460486050025E-6,9.9988708,9.9990263,49281.0390625,49345.98046875,52.7755576184671,18.690400314279,4.05629435,0,0,0,4449,9.9773,49313.509765625,,,,,,,,,,,,,,,,,12.252253,,,,,,9.99894855,,,,
,15749232.165,9.99939155,53318.6015625,-6.00091679400844E-5,7.26880947199983E-7,1,0.999253354069792,40.0298881530762,2.0044708707994,16.4700025320053,-0.000646807092000605,-0.000129306956889337,0.25,-1.22790066889006E-6,-5.97487641004783E-5,-1.50761353048077E-6,9.9992409,9.9995422,53293.6953125,53343.5078125,52.9225037800825,18.6926011101814,4.0966103,0,0,0,4449,9.97685,53318.6015625,,,,,,,,,,,,,,,,,12.252253,,,,,,9.99939155,,,,
,15749313.055,9.99922515,57359.18359375,-7.06854633671903E-5,7.79957887601163E-7,1,0.999253354069792,40.0298881530762,2.00452924281706,16.4700025320053,-0.000762383796717144,-0.000150466412302932,0.25,-1.2606391429214E-6,-7.03930270658015E-5,-1.60322309969687E-6,9.9991055,9.9993448,57326.62890625,57391.73828125,53.0788294839287,18.687623015501,4.13774015,0,0,0,4449,9.9789,57359.18359375,,,,,,,,,,,,,,,,,12.252253,,,,,,9.99922515,,,,
,15749390.135,9.99902345,61212.521484375,-7.91243003544309E-5,7.99612994077928E-7,1,0.999253354069792,40.0298881530762,2.00445745424982,16.4700025320053,-0.000853558257394069,-0.00016831647720141,0.25,-1.38601079442447E-6,-7.88118378461677E-5,-1.78212341855181E-6,9.9989357,9.9991112,61190.109375,61234.93359375,52.8162023014671,18.6875437053049,4.07635165,0,0,0,4449,9.979,61212.521484375,,,,,,,,,,,,,,,,,12.252253,,,,,,9.99902345,,,,
,15749469.29,9.9985371,65171.1796875,-8.9150608156337E-5,8.61277572160515E-7,1,0.999253354069792,40.0298881530762,2.00457783213501,16.4700025320053,-0.000961621419068273,-0.000191597365376645,0.25,-1.72415772290155E-6,-8.88152309009344E-5,-2.1836244814079E-6,9.9984818,9.9985924,65143.79296875,65198.56640625,53.0499092287172,18.6880920648026,4.1170726,0,0,0,4449,9.97955,65171.1796875,,,,,,,,,,,,,,,,,13.003003,,,,,,9.9985371,,,,
,15749548.475,9.9989915,69129.50390625,-9.79643236023901E-5,9.31902008814482E-7,1,0.999253354069792,40.0298881530762,2.0045762336081,16.4700025320053,-0.0010608435554817,-0.000188612754716385,0.25,1.48527972437518E-7,-9.76264090076585E-5,-3.77717132540859E-7,9.9989853,9.9989977,69097.0390625,69161.96875,52.8052595021979,18.687627328517,4.07635165,0,0,0,4449,9.97945,69129.50390625,,,,,,,,,,,,,,,,,13.378378,,,,,,9.9989915,,,,
,15749625.875,9.9981871,72997.43359375,-0.000111042851229914,1.07379663658438E-6,1,0.999253354069792,40.0298881530762,2.00457321785445,16.4700025320053,-0.0011994891647547,-0.000231794302132299,0.25,-1.47578314301225E-6,-0.00011067324374217,-2.08132506908209E-6,9.9980536,9.9983206,72965.015625,73029.8515625,52.5207467211979,18.6876277086583,4.0970192,0,0,0,4449,9.98115,72997.43359375,,,,,,,,,,,,,,,,,13.003003,,,,,,9.9981871,,,,
,15749704.245,9.99864435,76912.9609375,-0.000124293861183737,1.04147912022016E-6,1,0.999253354069792,40.0298881530762,2.00471675677592,16.4700025320053,-0.00133596365987226,-0.000298674585830075,0.25,-5.25136495695592E-6,-0.000123885469382804,-5.93377362688102E-6,9.9985313,9.9987574,76882.84375,76943.078125,52.6880152243133,18.6870493596108,4.13774015,0,0,0,4449,9.9817,76912.9609375,,,,,,,,,,,,,,,,,13.378378,,,,,,9.99864435,,,,
,15749782.875,9.9986863,80843.9921875,-0.000135473491525599,1.02961781317902E-6,1,0.999253354069792,40.0298881530762,2.00479605989967,16.4700025320053,-0.00145416023322868,-0.000338536498335434,0.25,-6.90083041302723E-6,-0.00013504941591553,-7.65791652351988E-6,9.9984922,9.9988804,80811.5859375,80876.3984375,52.9381363504671,18.6867215617748,4.0970192,0,0,0,4449,9.98205,80843.9921875,,,,,,,,,,,,,,,,,13.378378,,,,,,9.9986863,,,,
,15749862.46,9.99890515,84824.23828125,-0.000146780411495471,9.81307686099853E-7,1,0.999253354069792,40.0298881530762,2.00485198441946,16.4700025320053,-0.00157930607468782,-0.000347937856135342,0.25,-5.7133363220172E-6,-0.00014636185916696,-6.55540874937097E-6,9.9987974,9.9990129,84799.203125,84849.2734375,52.8654448981787,18.6835142871032,4.07635165,0,0,0,4449,9.9831,84824.23828125,,,,,,,,,,,,,,,,,13.003003,,,,,,9.99890515,,,,
,15749941.665,9.9985633,88779.79296875,-0.000161936418280362,1.12411557423727E-6,1,0.999253354069792,40.0298881530762,2.00474040291938,16.4700025320053,-0.00175042468598477,-0.000340749261354758,0.25,-2.30371566020616E-6,-0.000161532343170276,-3.25930717959359E-6,9.9984665,9.9986601,88747.2265625,88812.359375,53.1687167636402,18.6868675368879,4.1584077,0,0,0,4449,9.9852,88779.79296875,,,,,,,,,,,,,,,,,13.753754,,,,,,9.9985633,,,,
,15749967.38,9.9987912,89999.546875,-0.000164602986767787,9.96228068419611E-7,1,0.999253354069792,40.0298881530762,2.00472563736269,16.4700025320053,-0.00177741203491167,-0.000357166971975801,0.25,-3.33238010349019E-6,-0.000164197127375603,-4.30612086293398E-6,9.9986658,9.9989166,89999.5390625,89999.5546875,52.771649475871,18.6854709111034,4.0970192,0,0,0,4417,9.985,89999.546875,,,,,,,,,,,,,,,,,13.378378,,,,,,9.9987912,,,,