File: data/doubleLayers/dl_0-25/ppms/DD205_10_HYST_5K_1OE.DAT
[Header]
; VSM Data File (default extension .dat)
; Copyright (c) 2003, Quantum Design, Inc. All rights reserved.
TITLE,
FILEOPENTIME,15730546.81,04/17/2018,7:10 pm
BYAPP,VSM,1.0,1.0
INFO,PPMS VSM Option Release 1.3.7 Build 2,APPNAME
INFO,291,COIL_SERIAL_NUMBER
INFO,0,MOMENT_UNITS
INFO,,SAMPLE_MATERIAL
INFO,,SAMPLE_COMMENT
INFO,,SAMPLE_MASS
INFO,,SAMPLE_VOLUME
INFO,,SAMPLE_MOLECULAR_WEIGHT
INFO,,SAMPLE_SIZE
INFO,,SAMPLE_SHAPE
INFO,35.28,SAMPLE_OFFSET
DATATYPE,COMMENT,1
DATATYPE,TIME,2
STARTUPAXIS,X,2
STARTUPAXIS,Y1,5
[Data]
Comment,Time Stamp (sec),Temperature (K),Magnetic Field (Oe),Moment (emu),M. Std. Err. (emu),Transport Action,Averaging Time (sec),Frequency (Hz),Peak Amplitude (mm),Center Position (mm),Coil Signal' (mV),Coil Signal" (mV),Range (mV),M. Quad. Signal (emu),M. Raw' (emu),M. Raw" (emu),Min. Temperature (K),Max. Temperature (K),Min. Field (Oe),Max. Field (Oe),Mass (grams),Motor Lag (deg),Pressure (Torr),VSM Status (code),Motor Status (code),Measure Status (code),PPMS Status (code),System Temp. (K),System Field (Oe),Sample Position (deg),Bridge 1 Resistance (ohms),Bridge 1 Excitation (에),Bridge 2 Resistance (ohms),Bridge 2 Excitation (에),Bridge 3 Resistance (ohms),Bridge 3 Excitation (에),Bridge 4 Resistance (ohms),Bridge 4 Excitation (에),Signal 1 Vin (V),Signal 2 Vin (V),Digital Inputs (code),Drive 1 Iout (mA),Drive 1 Ipower (W),Drive 2 Iout (mA),Drive 2 Ipower (W),Pressure (),Map 20 (),Map 21 (),Map 22 (),Map 23 (),Map 24 (),Map 25 (),Map 26 (),Map 27 (),Map 28 (),Map 29 ()
,15730573.03,5.0040784,-0.0993264205753803,1.77841838380822E-5,2.29307233334115E-7,1,0.999253354069792,40.0298881530762,1.99178338673841,16.4700025320053,0.000195543009624561,7.8515472103254E-6,0.25,-2.40067513783201E-6,1.76840461832018E-5,-2.34716269565835E-6,5.0033522,5.0048046,-0.122247904539108,-0.0764049366116524,52.588748402371,18.6772268163946,2.97571505,0,0,0,4417,4.9595,-0.0993264205753803,,,,,,,,,,,,,,,,,13.378378,,,,,,5.0040784,,,,
,15730673.005,4.9932981,4172.79638671875,2.15273938650163E-5,2.68095105950393E-7,1,0.999253354069792,40.0298881530762,1.99162831022369,16.4800030738115,0.000236109277413322,1.28621573447973E-5,0.25,-2.59646379433971E-6,2.14070393372986E-5,-2.53056489133615E-6,4.9932981,4.9932981,4170.337890625,4175.2548828125,52.6786356820825,18.6848783728085,2.9022818,0,0,0,4449,4.9416,4172.79638671875,,,,,,,,,,,,,,,,,13.753754,,,,,,4.9932981,,,,
,15730757.7,5.0071981,8406.67431640625,1.47592073128408E-5,1.85136335569735E-7,1,0.999253354069792,40.0298881530762,1.99154927562862,16.4700025320053,0.00016344892303801,-3.4039548542707E-8,0.25,-2.60726834595971E-6,1.46802521310688E-5,-2.5546730661453E-6,5.006814,5.0075822,8379.0966796875,8434.251953125,53.0264603731402,18.6842462433111,2.9168512,0,0,0,4449,4.96075,8406.67431640625,,,,,,,,,,,,,,,,,13.378378,,,,,,5.0071981,,,,
,15730844.21,5.0014548,12730.1391601562,6.56989900314246E-6,2.20110261084025E-7,1,0.999253354069792,40.0298881530762,1.99130918781385,16.4700025320053,7.50035600006249E-5,-1.27225396557872E-5,0.25,-2.3452993999692E-6,6.53885926102634E-6,-2.31387335124608E-6,5.0014548,5.0014548,12727.6494140625,12732.62890625,53.0913355402364,18.6886263756947,2.9608517,0,0,0,4449,4.9501,12730.1391601562,,,,,,,,,,,,,,,,,13.753754,,,,,,5.0014548,,,,
,15730930.615,5.0081966,17048.1904296875,4.89310340207271E-7,1.03675857198121E-7,1,0.999253354069792,40.0298881530762,1.99145924134778,16.4700025320053,1.04038434948911E-5,-2.81774158232412E-5,0.25,-2.71001295735992E-6,4.94601514493951E-7,-2.69339138304879E-6,5.0081201,5.0082731,17015.81640625,17080.564453125,53.401642062371,18.6862753932083,3.09703065,0,0,0,4449,4.948,17048.1904296875,,,,,,,,,,,,,,,,,13.378378,,,,,,5.0081966,,,,
,15731008.93,5.0063567,20960.73046875,-2.42428673758912E-6,1.35044446428022E-6,1,0.999253354069792,40.0298881530762,1.9914674280379,16.4800030738115,-2.02551191964672E-5,-3.72793606427354E-5,0.25,-3.04132804003161E-6,-2.40135466174558E-6,-3.0322998997316E-6,5.0063567,5.0063567,20958.291015625,20963.169921875,53.0545989998325,18.6873036314912,3.2071922,0,0,0,4449,4.9379,20960.73046875,,,,,,,,,,,,,,,,,13.753754,,,,,,5.0063567,,,,
,15731081.93,5.0057094,24611.5703125,-4.6958142261472E-6,8.26326602420954E-7,1,0.999253354069792,40.0298881530762,1.99133961898797,16.4800030738115,-4.41438521970507E-5,-4.4459160661934E-5,0.25,-3.30651016290389E-6,-4.65946562726565E-6,-3.30446221237959E-6,5.0051646,5.0062542,24581.6015625,24641.5390625,53.2523510151979,18.6867189295054,3.2071922,0,0,0,4449,4.93455,24611.5703125,,,,,,,,,,,,,,,,,13.378378,,,,,,5.0057094,,,,
,15731155.62,5.00466445,28294.8046875,-5.90893193207184E-6,7.01726977223912E-7,1,0.999253354069792,40.0298881530762,1.99141076222955,16.4700025320053,-5.90597573658921E-5,-3.61652602348221E-5,0.25,-2.31774519182002E-6,-5.86963967898434E-6,-2.3264851692694E-6,5.0039287,5.0054002,28264.841796875,28324.767578125,52.7396027065825,18.6902013148703,3.2719154,0,0,0,4449,4.93425,28294.8046875,,,,,,,,,,,,,,,,,13.378378,,,,,,5.00466445,,,,
,15731230.955,5.00356965,32060.4873046875,-8.95305293711779E-6,6.3462087141352E-7,1,0.999253354069792,40.0298881530762,1.9912914930177,16.4700025320053,-8.87938749295332E-5,-5.86909101388454E-5,0.25,-3.87226848144171E-6,-8.89267241345934E-6,-3.8858514459833E-6,5.0031343,5.004005,32027.939453125,32093.03515625,52.9889422042171,18.6873031494376,3.2719154,0,0,0,4449,4.9332,32060.4873046875,,,,,,,,,,,,,,,,,13.378378,,,,,,5.00356965,,,,
,15731305.845,4.9996748,35801.390625,-1.46389196188943E-5,5.06674518797925E-7,1,0.999253354069792,40.0298881530762,1.99136579012844,16.4800030738115,-0.000152881914442843,-5.27760330747695E-5,0.25,-2.3078978995433E-6,-1.45568237927878E-5,-2.35383046970529E-6,4.9993534,4.9999962,35771.2578125,35831.5234375,53.3883543775441,18.6849199981463,3.22361385,0,0,0,4449,4.9322,35801.390625,,,,,,,,,,,,,,,,,13.003003,,,,,,4.9996748,,,,
,15731380.625,4.99920515,39541.091796875,-2.2024046852027E-5,7.98927053915986E-7,1,0.999253354069792,40.0298881530762,1.99138243455691,16.4800030738115,-0.000231824836797424,-6.93758861761633E-5,0.25,-2.53418618032416E-6,-2.19069888345356E-5,-2.61242598661831E-6,4.9987698,4.9996405,39513.59375,39568.58984375,52.4292961844479,18.6859184813682,3.22361385,0,0,0,4449,4.93195,39541.091796875,,,,,,,,,,,,,,,,,13.378378,,,,,,4.99920515,,,,
,15731455.44,5.00283575,43276.98828125,-3.01304012899873E-5,6.50426706952222E-7,1,0.999253354069792,40.0298881530762,1.99127716724052,16.4700025320053,-0.000319586475455652,-8.14148716010951E-5,0.25,-2.20485874906305E-6,-2.99797063912246E-5,-2.32379130534829E-6,5.0028119,5.0028596,43247,43306.9765625,53.1906023621787,18.6858167717486,3.25565385,0,0,0,4449,4.92985,43276.98828125,,,,,,,,,,,,,,,,,13.378378,,,,,,5.00283575,,,,
,15731528.96,4.999197,46953.099609375,-4.02269038792907E-5,8.09133355718128E-7,1,0.999253354069792,40.0298881530762,1.99131965362239,16.4700025320053,-0.000426920871590945,-0.000107754667921601,0.25,-2.8473863142062E-6,-4.00320341055781E-5,-3.01402127745436E-6,4.9990182,4.9993758,46920.7109375,46985.48828125,53.0936804257941,18.6871829791228,3.22361385,0,0,0,4449,4.92965,46953.099609375,,,,,,,,,,,,,,,,,13.753754,,,,,,4.999197,,,,
,15731602.68,5.0003221,50638.962890625,-5.10482056043307E-5,7.32442166011799E-7,1,0.999253354069792,40.0298881530762,1.99134483196174,16.4800030738115,-0.000541269410373091,-0.000140049473043518,0.25,-3.91036086027214E-6,-5.0807403764943E-5,-4.1296682663077E-6,4.9999933,5.0006509,50614.0703125,50663.85546875,53.0334950298133,18.685428076827,3.25565385,0,0,0,4449,4.9298,50638.962890625,,,,,,,,,,,,,,,,,13.378378,,,,,,5.0003221,,,,
,15731675.61,5.001646,54284.306640625,-6.02195323270536E-5,9.06134719686108E-7,1,0.999253354069792,40.0298881530762,1.99123614435615,16.4800030738115,-0.000639633555184056,-0.000159350080150273,0.25,-4.05647737374018E-6,-5.9947625399093E-5,-4.32789585388773E-6,5.0009174,5.0023746,54251.7734375,54316.83984375,53.1093129961787,18.6892105783528,3.2719154,0,0,0,4449,4.9304,54284.306640625,,,,,,,,,,,,,,,,,13.378378,,,,,,5.001646,,,,
,15731754.985,5.00505735,58250.3671875,-7.12443502550656E-5,1.05266473564362E-6,1,0.999253354069792,40.0298881530762,1.99138098431646,16.4700025320053,-0.000759302491071808,-0.000175282564145139,0.25,-3.55160811292402E-6,-7.09416316016497E-5,-3.89043809059597E-6,5.0046773,5.0054374,58220.23046875,58280.50390625,53.0428745720441,18.6880217663844,3.22361385,0,0,0,4449,4.93095,58250.3671875,,,,,,,,,,,,,,,,,13.378378,,,,,,5.00505735,,,,
,15731826.25,4.98430775,61813.75,-8.24702197726204E-5,8.95448573383155E-7,1,0.999253354069792,40.0298881530762,1.99142477551343,16.4800030738115,-0.000881289872275491,-0.000190782476343875,0.25,-2.96913858325507E-6,-8.21395494381972E-5,-3.37815462366855E-6,4.9837246,4.9848909,61788.79296875,61838.70703125,52.6661296257748,18.688792238814,2.8307313,0,0,0,4453,4.92735,61813.75,,,,,,,,,,,,,,,,,13.378378,,,,,,4.98430775,,,,
,15731906.77,4.9976764,65836.95703125,-8.76690780839892E-5,9.63335143153478E-7,1,0.999253354069792,40.0298881530762,1.99136725832764,16.4700025320053,-0.000936272686131937,-0.000206940652931948,0.25,-3.52384225424479E-6,-8.73329704637191E-5,-3.97126392938956E-6,4.9974108,4.997942,65807.1640625,65866.75,53.1483944221402,18.6883635453998,2.53640175,0,0,0,4453,4.93965,65836.95703125,,,,,,,,,,,,,,,,,12.627627,,,,,,4.9976764,,,,
,15731987.15,4.9962325,69855.28515625,-0.000104446835686815,9.00908470270673E-7,1,0.999253354069792,40.0298881530762,1.99140548517466,16.4700025320053,-0.00111886870358648,-0.000228930899635903,0.25,-2.54128868977243E-6,-0.000104076373587155,-3.09574698067986E-6,4.9962325,4.9962325,69850.3359375,69860.234375,52.859973498544,18.6886179048281,2.4735627,0,0,0,4453,4.9395,69855.28515625,,,,,,,,,,,,,,,,,12.252253,,,,,,4.9962325,,,,
,15732057.83,5.0000236,73386.0390625,-0.000114644995099597,9.36308134332085E-7,1,0.999253354069792,40.0298881530762,1.99125554568264,16.4800030738115,-0.00122482403546137,-0.000270411582393262,0.25,-4.55103624852445E-6,-0.00011424951592918,-5.1679213843066E-6,5.0000191,5.0000281,73358.640625,73413.4375,52.7325680499094,18.6914387886406,2.3766694,0,0,0,4449,4.9379,73386.0390625,,,,,,,,,,,,,,,,,12.252253,,,,,,5.0000236,,,,
,15732131.625,5.0008738,77076.91796875,-0.000124878677482356,8.95433369047381E-7,1,0.999253354069792,40.0298881530762,1.9912339101523,16.4800030738115,-0.00133586042677436,-0.000286470422441864,0.25,-4.18730609151079E-6,-0.000124476063291339,-4.87691738011815E-6,5.0008359,5.0009117,77046.9921875,77106.84375,53.0397480579671,18.6938691632192,2.4612689,0,0,0,4449,4.9365,77076.91796875,,,,,,,,,,,,,,,,,13.378378,,,,,,5.0008738,,,,
,15732204.97,4.99788405,80740.50390625,-0.000135953445974421,9.93784600422508E-7,1,0.999253354069792,40.0298881530762,1.99115554265702,16.4700025320053,-0.00145567137922545,-0.000305726864366254,0.25,-3.9685168793443E-6,-0.000135544634485441,-4.73628290915515E-6,4.9974923,4.9982758,80710.59375,80770.4140625,52.748200620294,18.691132210062,2.40065075,0,0,0,4449,4.94,80740.50390625,,,,,,,,,,,,,,,,,13.378378,,,,,,4.99788405,,,,
,15732279.58,4.9977846,84470.4140625,-0.00014786513676807,1.11460870277851E-6,1,0.999253354069792,40.0298881530762,1.99126129931622,16.4700025320053,-0.00158599821451285,-0.000319290628529785,0.25,-3.06569781761282E-6,-0.000147457013775477,-3.91967134164728E-6,4.9977846,4.9977846,84467.9609375,84472.8671875,52.9060895811787,18.693640526957,2.4005308,0,0,0,4449,4.9398,84470.4140625,,,,,,,,,,,,,,,,,13.378378,,,,,,4.9977846,,,,
,15732356.97,5.002624,88338.96875,-0.000158523188501845,1.14440849082411E-6,1,0.999253354069792,40.0298881530762,1.99110625371081,16.4800030738115,-0.00169589927610368,-0.000368169137253911,0.25,-5.66957134139045E-6,-0.000158104300433334,-6.59505336648958E-6,5.002624,5.002624,88336.3984375,88341.5390625,53.1788779343902,18.6931909603072,2.4246321,0,0,0,4449,4.9443,88338.96875,,,,,,,,,,,,,,,,,12.252253,,,,,,5.002624,,,,
,15732452.77,5.0060873,87749.734375,-0.000160342600001636,1.01512901606217E-6,1,0.999253354069792,40.0298881530762,1.99092769059711,16.4800030738115,-0.00171973224410839,-0.000346963335723248,0.25,-3.37871026845385E-6,-0.000159927809040214,-4.31820296581379E-6,5.0057282,5.0064464,87717.296875,87782.171875,52.7255333932363,18.6992069997002,2.486228,0,0,0,4453,4.93055,87749.734375,,,,,,,,,,,,,,,,,13.003003,,,,,,5.0060873,,,,
,15732525.57,4.99842835,84111.4140625,-0.000147674871589177,1.07232324081635E-6,1,0.999253354069792,40.0298881530762,1.99090430468832,16.4800030738115,-0.00158500814243011,-0.000311317934214254,0.25,-2.36618130534197E-6,-0.00014726849522393,-3.21947852602604E-6,4.9983373,4.9985194,84083.9375,84138.890625,52.8279267292556,18.6994764450683,2.51118955,0,0,0,4453,4.9296,84111.4140625,,,,,,,,,,,,,,,,,13.753754,,,,,,4.99842835,,,,
,15732596.93,4.9984467,80543.21875,-0.000138681477871098,9.50087787468573E-7,1,0.999253354069792,40.0298881530762,1.99118047435602,16.4800030738115,-0.00148157363396462,-0.000330273895425509,0.25,-5.75947674752701E-6,-0.000138253222135065,-6.53696354299141E-6,4.998301,4.9985924,80510.71875,80575.71875,52.8521572133517,18.6944727199471,2.4983971,0,0,0,4449,4.93525,80543.21875,,,,,,,,,,,,,,,,,13.003003,,,,,,4.9984467,,,,
,15732677.445,5.0013571,76520.21875,-0.000123196929240377,8.24513440105751E-7,1,0.999253354069792,40.0298881530762,1.99108242032183,16.4700025320053,-0.0013167665790813,-0.000287988382281544,0.25,-4.63519657953475E-6,-0.000122793331759855,-5.31178043884222E-6,5.0013571,5.0013571,76517.796875,76522.640625,52.8576286129864,18.6976710036412,2.4489751,0,0,0,4449,4.9356,76520.21875,,,,,,,,,,,,,,,,,13.003003,,,,,,5.0013571,,,,
,15732757.955,4.9957347,72494.234375,-0.000115089625740569,1.07026514792683E-6,1,0.999253354069792,40.0298881530762,1.9911534483146,16.4800030738115,-0.00122958271825215,-0.000270740965232903,0.25,-4.50753071930284E-6,-0.000114687682904556,-5.12345945416647E-6,4.9957347,4.9957347,72489.25,72499.21875,52.5950014305248,18.6964016863077,2.4246321,0,0,0,4449,4.9389,72494.234375,,,,,,,,,,,,,,,,,13.378378,,,,,,4.9957347,,,,
,15732837.29,4.9980123,68531.4296875,-0.000100780483209046,6.74016057244462E-7,1,0.999253354069792,40.0298881530762,1.99126086506678,16.4800030738115,-0.00107841717429764,-0.000226602434004033,0.25,-2.990043758424E-6,-0.000100413343741377,-3.51836917553029E-6,4.9973578,4.9986668,68501.5625,68561.296875,52.7419475921402,18.6987505985792,2.34158385,0,0,0,4449,4.94195,68531.4296875,,,,,,,,,,,,,,,,,13.378378,,,,,,4.9980123,,,,
,15732920.375,5.00698945,64378.224609375,-8.87093932037511E-5,9.61108586751142E-7,1,0.999253354069792,40.0298881530762,1.9912078875314,16.4800030738115,-0.000950158348619724,-0.000193092772818319,0.25,-2.05750623061458E-6,-8.83707419635797E-5,-2.51075746477498E-6,5.0060844,5.0078945,64348.2109375,64408.23828125,52.707555937294,18.7021853572821,2.30661345,0,0,0,4449,4.9525,64378.224609375,,,,,,,,,,,,,,,,,12.627627,,,,,,5.00698945,,,,
,15732996.73,5.0026228,60562.228515625,-7.72231921184438E-5,7.0457316485837E-7,1,0.999253354069792,40.0298881530762,1.99116894023593,16.4700025320053,-0.000829471247413791,-0.000154022596542727,0.25,-4.97424893287168E-7,-7.69204129031636E-5,-8.85332372691176E-7,5.0020761,5.0031695,60534.72265625,60589.734375,53.046001086121,18.6989922018065,2.40065075,0,0,0,4453,4.93105,60562.228515625,,,,,,,,,,,,,,,,,13.378378,,,,,,5.0026228,,,,
,15733071.085,5.01191685,56845.8046875,-6.75112202871176E-5,6.51739123694086E-7,1,0.999253354069792,40.0298881530762,1.99127661808613,16.4700025320053,-0.000722156089154318,-0.000150854902274869,0.25,-1.9535637667081E-6,-6.72268709629674E-5,-2.27625484783237E-6,5.0111241,5.0127096,56820.7890625,56870.8203125,52.8943651533902,18.6998971986649,2.40065075,0,0,0,4453,4.94355,56845.8046875,,,,,,,,,,,,,,,,,13.378378,,,,,,5.01191685,,,,
,15733140.895,4.9989667,53355.279296875,-5.63450761655222E-5,7.42364320552483E-7,1,0.999253354069792,40.0298881530762,1.99119374831914,16.4800030738115,-0.00060314480354979,-0.000122783288101646,0.25,-1.35087740972566E-6,-5.60999584145422E-5,-1.61276998567866E-6,4.9984493,4.9994841,53322.72265625,53387.8359375,53.1843493340249,18.7028662994792,2.3767879,0,0,0,4449,4.93625,53355.279296875,,,,,,,,,,,,,,,,,13.753754,,,,,,4.9989667,,,,
,15733218.32,4.99772455,49484.861328125,-4.53727069520511E-5,7.58521427948067E-7,1,0.999253354069792,40.0298881530762,1.99128735525307,16.4800030738115,-0.000487151782938616,-9.03217527833384E-5,0.25,-3.01273961801739E-7,-4.51710041868348E-5,-5.07683164848671E-7,4.9975257,4.9979234,49449.78515625,49519.9375,52.8787325830056,18.6948823592214,2.3648572,0,0,0,4449,4.93775,49484.861328125,,,,,,,,,,,,,,,,,13.003003,,,,,,4.99772455,,,,
,15733299.57,4.999186,45424.05859375,-3.54184067052932E-5,5.54153793328616E-7,1,0.999253354069792,40.0298881530762,1.99119315303502,16.4800030738115,-0.000379067857916876,-7.67822759117024E-5,0.25,-8.27245889667064E-7,-3.52520138078998E-5,-9.78993709668232E-7,4.9991221,4.9992499,45396.59375,45451.5234375,52.7950983314479,18.7023343165351,2.31830825,0,0,0,4449,4.9368,45424.05859375,,,,,,,,,,,,,,,,,12.252253,,,,,,4.999186,,,,
,15733378.715,5.0005307,41468.328125,-2.40966622221922E-5,5.38430203520365E-7,1,0.999253354069792,40.0298881530762,1.99121431389189,16.4800030738115,-0.000257034820838524,-5.68401718068754E-5,0.25,-9.96352231600089E-7,-2.39776953017096E-5,-1.09289501942603E-6,5.0005307,5.0005307,41463.23828125,41473.41796875,53.0303685157364,18.7014799662637,2.28368535,0,0,0,4449,4.94025,41468.328125,,,,,,,,,,,,,,,,,13.003003,,,,,,5.0005307,,,,
,15733457.03,4.99650095,37554.890625,-1.29813336125436E-5,5.73481536008996E-7,1,0.999253354069792,40.0298881530762,1.99118529189971,16.4700025320053,-0.000137014477864947,-3.86636048157499E-5,0.25,-1.2882653482047E-6,-1.29122803302515E-5,-1.33400270000008E-6,4.9961233,4.9968786,37524.984375,37584.796875,53.2093614466402,18.701045615992,2.2053547,0,0,0,4449,4.93845,37554.890625,,,,,,,,,,,,,,,,,13.378378,,,,,,4.99650095,,,,
,15733540.7,4.996727,33372.251953125,-1.63482485323671E-6,6.0733242558154E-7,1,0.999253354069792,40.0298881530762,1.99133323738564,16.4700025320053,-1.64254626718877E-5,-9.52976673756223E-6,0.25,-5.96408751647131E-7,-1.62425128363048E-6,-5.99594041201336E-7,4.996727,4.996727,33367.2890625,33377.21484375,53.1671535066018,18.704185460151,2.3766694,0,0,0,4453,4.94115,33372.251953125,,,,,,,,,,,,,,,,,13.753754,,,,,,4.996727,,,,
,15733617.745,5.00355335,29521.7158203125,7.74766784871753E-6,4.03699811894702E-7,1,0.999253354069792,40.0298881530762,1.9912990525229,16.4800030738115,8.82674392032536E-5,-1.3594680869396E-5,0.25,-2.64103198628161E-6,7.7167606402523E-6,-2.59931653975264E-6,5.002984,5.0041227,29489.26953125,29554.162109375,52.8240185866594,18.7054944081926,2.28368535,0,0,0,4453,4.93605,29521.7158203125,,,,,,,,,,,,,,,,,12.627627,,,,,,5.00355335,,,,
,15733691.14,4.9988859,25853.3486328125,1.74033373962089E-5,5.06887669181684E-7,1,0.999253354069792,40.0298881530762,1.99129171525642,16.4800030738115,0.000189602471913094,1.8140390807041E-5,0.25,-1.39763740583772E-6,1.73151665542236E-5,-1.3307155065289E-6,4.9986768,4.999095,25825.92578125,25880.771484375,52.8076043877556,18.7041970400299,2.2950349,0,0,0,4453,4.93395,25853.3486328125,,,,,,,,,,,,,,,,,13.378378,,,,,,4.9988859,,,,
,15733764.97,4.9985099,22164.689453125,2.77011451711083E-5,3.08169975165373E-7,1,0.999253354069792,40.0298881530762,1.99134973343284,16.4800030738115,0.000301261959750164,3.16929014355393E-5,0.25,-1.95661723724605E-6,2.7556347399495E-5,-1.85658480592363E-6,4.997788,4.9992318,22132.09765625,22197.28125,53.0202073449864,18.703512373246,2.2835715,0,0,0,4449,4.9391,22164.689453125,,,,,,,,,,,,,,,,,13.378378,,,,,,4.9985099,,,,
,15733844,4.9975066,18212.2119140625,3.72662151478696E-5,3.04473196409573E-7,1,0.999253354069792,40.0298881530762,1.9912006336416,16.4800030738115,0.000404556514310209,4.62971530644951E-5,0.25,-2.28292104296308E-6,3.70656425112648E-5,-2.15756993612323E-6,4.9975066,4.9975066,18209.759765625,18214.6640625,52.974872890871,18.7044035231418,2.2162597,0,0,0,4449,4.9387,18212.2119140625,,,,,,,,,,,,,,,,,13.753754,,,,,,4.9975066,,,,
,15733923.235,4.9963598,14254.0947265625,4.62590604873609E-5,3.61538703808395E-7,1,0.999253354069792,40.0298881530762,1.99126416712776,16.4700025320053,0.000500394381019928,6.73350190753878E-5,0.25,-1.90535189661161E-6,4.60021985209254E-5,-1.7639898036736E-6,4.9963598,4.9963598,14251.72265625,14256.466796875,53.0499092287172,18.7060913929014,2.2161491,0,0,0,4449,4.9407,14254.0947265625,,,,,,,,,,,,,,,,,12.252253,,,,,,4.9963598,,,,
,15733997.855,4.9984763,10523.4780273438,5.43936077909853E-5,2.44709011440248E-7,1,0.999253354069792,40.0298881530762,1.99133026025872,16.4700025320053,0.000588144829501655,8.0336833427575E-5,0.25,-2.12180129244032E-6,5.40862082172832E-5,-1.96602844849107E-6,4.9983869,4.9985657,10493.427734375,10553.5283203125,53.3031568689479,18.7061463885325,2.1941204,0,0,0,4449,4.93845,10523.4780273438,,,,,,,,,,,,,,,,,13.003003,,,,,,4.9984763,,,,
,15734076.375,4.9987683,6599.81469726563,6.27576005032829E-5,2.88559573299613E-7,1,0.999253354069792,40.0298881530762,1.99121172996729,16.4700025320053,0.000677789216007074,9.66276640201301E-5,0.25,-2.06861236112783E-6,6.23966397664859E-5,-1.90235251762401E-6,4.9987683,4.9987683,6594.88330078125,6604.74609375,52.5238732352748,18.7081486661061,2.1507175,0,0,0,4449,4.9447,6599.81469726563,,,,,,,,,,,,,,,,,13.003003,,,,,,4.9987683,,,,
,15734158.15,4.9994228,2510.93811035156,6.86074676117687E-5,2.68181635039806E-7,1,0.999253354069792,40.0298881530762,1.99140199963496,16.4800030738115,0.000741577357683382,0.00010225016692206,0.25,-2.56506068161412E-6,6.82085698474112E-5,-2.39301131252566E-6,4.9992337,4.9996119,2481.08178710938,2540.79443359375,52.9396996075056,18.7050021034787,2.0665716,0,0,0,4449,4.9453,2510.93811035156,,,,,,,,,,,,,,,,,13.378378,,,,,,4.9994228,,,,
,15734237.21,5.0033698,-1437.67041015625,6.00828692527874E-5,2.17555470504037E-7,1,0.999253354069792,40.0298881530762,1.991382181512,16.4800030738115,0.000648888220089514,9.25543941033866E-5,0.25,-1.96360747967773E-6,5.97319520433763E-5,-1.81687233757957E-6,5.0033698,5.0033698,-1440.04541015625,-1435.29541015625,53.1140027672941,18.7062163265257,2.2835715,0,0,0,4453,4.9362,-1437.67041015625,,,,,,,,,,,,,,,,,13.378378,,,,,,5.0033698,,,,
,15734313.805,5.0116668,-5265.01000976562,6.15021699994103E-5,2.24666738719706E-7,1,0.999253354069792,40.0298881530762,1.9915313030993,16.4800030738115,0.000664167559211985,9.55357231688592E-5,0.25,-1.94640599555868E-6,6.11466596470738E-5,-1.78749156201624E-6,5.0111771,5.0121565,-5292.4697265625,-5237.55029296875,53.1483944221402,18.7058082870386,2.3064983,0,0,0,4453,4.94695,-5265.01000976562,,,,,,,,,,,,,,,,,13.378378,,,,,,5.0116668,,,,
,15734382.78,4.9991117,-8716.02294921875,6.66416595475771E-5,2.47864094919201E-7,1,0.999253354069792,40.0298881530762,1.99140370935074,16.4700025320053,0.000718958889877081,0.000107586303856303,0.25,-1.74083322050747E-6,6.62601199509955E-5,-1.56056775108086E-6,4.9991117,4.9991117,-8720.8671875,-8711.1787109375,53.1960737618133,18.7055430978079,2.238399,0,0,0,4453,4.9423,-8716.02294921875,,,,,,,,,,,,,,,,,13.378378,,,,,,4.9991117,,,,
,15734459.285,4.99791885,-12539.3999023437,7.04927779866621E-5,2.83752627510682E-7,1,0.999253354069792,40.0298881530762,1.99155314994799,16.4700025320053,0.000760331746800989,0.000115495269755215,0.25,-1.6986223626993E-6,7.00949513240731E-5,-1.4959590857813E-6,4.9978886,4.9979491,-12574.52734375,-12504.2724609375,53.2249940170249,18.705814534347,2.1293368,0,0,0,4449,4.94245,-12539.3999023437,,,,,,,,,,,,,,,,,13.753754,,,,,,4.99791885,,,,
,15734541.11,4.9982295,-16627.2763671875,6.99506664179514E-5,2.73912383592581E-7,1,0.999253354069792,40.0298881530762,1.99162534867633,16.4800030738115,0.00075575340141059,0.000108047914901018,0.25,-2.31208268528198E-6,6.95650912899797E-5,-2.09332582431417E-6,4.9982295,4.9982295,-16632.361328125,-16622.19140625,52.3448803043709,18.7052868658817,2.1507175,0,0,0,4449,4.9447,-16627.2763671875,,,,,,,,,,,,,,,,,13.003003,,,,,,4.9982295,,,,
,15734616.705,4.9989705,-20405.0859375,6.24258792481416E-5,3.21957486194794E-7,1,0.999253354069792,40.0298881530762,1.99159203734211,16.4700025320053,0.000676578797147979,8.47998139006233E-5,0.25,-3.15856002682678E-6,6.2092045045643E-5,-2.94545596379927E-6,4.9989705,4.9989705,-20410.087890625,-20400.083984375,53.0983701969095,18.7059426412921,2.1293368,0,0,0,4449,4.94385,-20405.0859375,,,,,,,,,,,,,,,,,12.252253,,,,,,4.9989705,,,,
,15734694.96,4.9984002,-24318.0615234375,5.00884080310863E-5,5.04910959485997E-7,1,0.999253354069792,40.0298881530762,1.99167133477909,16.4700025320053,0.000544659608553047,5.84302681710042E-5,0.25,-3.44009566393356E-6,4.98299438382395E-5,-3.25440585612613E-6,4.9981303,4.9986701,-24348.095703125,-24288.02734375,52.9170323804479,18.7041039676833,2.07704925,0,0,0,4449,4.94245,-24318.0615234375,,,,,,,,,,,,,,,,,13.003003,,,,,,4.9984002,,,,
,15734774.895,4.9962049,-28311.2265625,3.78927143174106E-5,3.93666897635134E-7,1,0.999253354069792,40.0298881530762,1.99177288734527,16.4800030738115,0.000408948123097082,6.2105250925377E-5,0.25,-9.45055129901867E-7,3.76967622732445E-5,-8.05822076494829E-7,4.995997,4.9964128,-28341.248046875,-28281.205078125,52.9873789471787,18.7036109305948,2.0357591,0,0,0,4449,4.9483,-28311.2265625,,,,,,,,,,,,,,,,,13.003003,,,,,,4.9962049,,,,
,15734856.245,4.98067595,-32376.611328125,2.97668074830404E-5,4.83813296980255E-7,1,0.999253354069792,40.0298881530762,1.9917440961591,16.4800030738115,0.000322773091536472,4.04741302844473E-5,0.25,-1.52283182791732E-6,2.96201993635299E-5,-1.40337280920187E-6,4.9801803,4.9811716,-32399.15625,-32354.06640625,52.809167644794,18.7058590549296,2.1834333,0,0,0,4453,4.9219,-32376.611328125,,,,,,,,,,,,,,,,,12.627627,,,,,,4.98067595,,,,
,15734934.265,5.0099163,-36276.7109375,2.86795893727579E-5,5.32564474727918E-7,1,0.999253354069792,40.0298881530762,1.99137283108497,16.4800030738115,0.00031121766957643,3.76496688901664E-5,0.25,-1.59809613957164E-6,2.85433298415511E-5,-1.4769226397E-6,5.0097256,5.010107,-36301.80859375,-36251.61328125,52.5058957793325,18.7098489705594,2.20513475,0,0,0,4453,4.9462,-36276.7109375,,,,,,,,,,,,,,,,,13.003003,,,,,,5.0099163,,,,
,15735003.625,4.99545095,-39742.298828125,3.20693939884834E-5,4.88176129118521E-7,1,0.999253354069792,40.0298881530762,1.99151598488011,16.4700025320053,0.000347183243800015,4.71299727695384E-5,0.25,-1.3252860430463E-6,3.19198301910137E-5,-1.1867703593767E-6,4.995141,4.9957609,-39764.80859375,-39719.7890625,53.1562107073326,18.7102809296977,2.20513475,0,0,0,4453,4.94175,-39742.298828125,,,,,,,,,,,,,,,,,12.252253,,,,,,4.99545095,,,,
,15735076.165,4.9971991,-43365.416015625,3.81077156377181E-5,5.85303721598892E-7,1,0.999253354069792,40.0298881530762,1.99141188770037,16.4800030738115,0.000410144125142007,6.97839554342927E-5,0.25,-2.99953353065461E-7,3.79305178033907E-5,-1.34895168207791E-7,4.9971991,4.9971991,-43367.89453125,-43362.9375,53.2359368162941,18.7066764961462,2.12944425,0,0,0,4449,4.9445,-43365.416015625,,,,,,,,,,,,,,,,,13.003003,,,,,,4.9971991,,,,
,15735153.175,4.99864435,-47216.107421875,4.62045496293E-5,6.33678853885315E-7,1,0.999253354069792,40.0298881530762,1.99146146741368,16.4800030738115,0.000497495545883728,8.40058052220882E-5,0.25,-4.29866235754244E-7,4.59977796805151E-5,-2.21157131261741E-7,4.9985719,4.9987168,-47245.9609375,-47186.25390625,53.1616821069672,18.7046545625504,2.07704925,0,0,0,4449,4.94625,-47216.107421875,,,,,,,,,,,,,,,,,13.378378,,,,,,4.99864435,,,,
,15735231.37,4.9981654,-51126.439453125,5.47310952770771E-5,6.30305514846305E-7,1,0.999253354069792,40.0298881530762,1.99149100082773,16.4800030738115,0.000589012865583052,0.00010179108145075,0.25,-3.08325731841278E-7,5.44949927883063E-5,-5.23825135399967E-8,4.9977956,4.9985352,-51158.89453125,-51093.984375,52.9576770634479,18.7059021613171,2.0768421,0,0,0,4449,4.9489,-51126.439453125,,,,,,,,,,,,,,,,,13.378378,,,,,,4.9981654,,,,
,15735310.82,4.9978123,-55093.8203125,6.45487808574389E-5,4.95695011320515E-7,1,0.999253354069792,40.0298881530762,1.99134603025078,16.4800030738115,0.00069145785268973,0.000138496519505069,0.25,1.33951411775949E-6,6.42741709926168E-5,1.64533729358519E-6,4.9978123,4.9978123,-55096.45703125,-55091.18359375,52.9185956374864,18.7104269943842,2.0459275,0,0,0,4449,4.9484,-55093.8203125,,,,,,,,,,,,,,,,,13.378378,,,,,,4.9978123,,,,
,15735389.245,4.9991407,-59014.2265625,7.69373025283255E-5,8.21609285420666E-7,1,0.999253354069792,40.0298881530762,1.99150730838487,16.4700025320053,0.000828048322471451,0.000144644208527829,0.25,-3.19875031428662E-7,7.66338699967461E-5,6.50322139682318E-8,4.9991407,4.9991407,-59019.15625,-59009.296875,53.0647601705825,18.7029244381968,1.9462451,0,0,0,4449,4.9499,-59014.2265625,,,,,,,,,,,,,,,,,13.378378,,,,,,4.9991407,,,,
,15735470.92,4.9971211,-63094.875,8.75452178160432E-5,8.62063185805094E-7,1,0.999253354069792,40.0298881530762,1.99164240715849,16.4700025320053,0.000940748165948589,0.000174249226416283,0.25,5.16085517427207E-7,8.72132304696527E-5,9.64707806948424E-7,4.9963517,4.9978905,-63127.3984375,-63062.3515625,53.2828345274479,18.7074632942749,1.9173223,0,0,0,4449,4.95285,-63094.875,,,,,,,,,,,,,,,,,13.003003,,,,,,4.9971211,,,,
,15735552.45,4.9987025,-67170.25,9.8682436114026E-5,9.32821890838818E-7,1,0.999253354069792,40.0298881530762,1.99150526057011,16.4700025320053,0.00106095041441069,0.000194371968285601,0.25,3.7424600556032E-7,9.83296836855032E-5,8.95681233404784E-7,4.9987025,4.9987025,-67175.3515625,-67165.1484375,53.1147843958133,18.7079050422853,2.14002715,0,0,0,4453,4.94295,-67170.25,,,,,,,,,,,,,,,,,12.252253,,,,,,4.9987025,,,,
,15735629.335,5.0111575,-71012.48828125,0.000110269052992112,8.79703562059582E-7,1,0.999253354069792,40.0298881530762,1.99153393867489,16.4800030738115,0.00118655581272685,0.000212878583119171,0.25,-1.79788829808191E-9,0.000109899064965308,5.97071498321669E-7,5.0111575,5.0111575,-71017.578125,-71007.3984375,52.8380879000056,18.7086413177118,2.16151395,0,0,0,4453,4.9522,-71012.48828125,,,,,,,,,,,,,,,,,13.003003,,,,,,5.0111575,,,,
,15735699.345,4.9982195,-74512.97265625,0.000120789042353708,8.95414083053752E-7,1,0.999253354069792,40.0298881530762,1.99156424530768,16.4800030738115,0.0012999261227419,0.000233735425393563,0.25,3.08829199351198E-8,0.000120405794748472,7.00564415671946E-7,4.9982195,4.9982195,-74515.4375,-74510.5078125,53.1999819044095,18.7116754765121,2.1941204,0,0,0,4453,4.95225,-74512.97265625,,,,,,,,,,,,,,,,,13.003003,,,,,,4.9982195,,,,
,15735771.11,4.9960492,-78098.48828125,0.00013316072236738,9.3413172844789E-7,1,0.999253354069792,40.0298881530762,1.99159434784179,16.4800030738115,0.00143561699010475,0.00024519121929819,0.25,-1.14511998608143E-6,0.000132770240698102,-3.88759041306812E-7,4.9958792,4.9962192,-78123.4609375,-78073.515625,52.859973498544,18.7103302869261,2.07704925,0,0,0,4449,4.95245,-78098.48828125,,,,,,,,,,,,,,,,,13.753754,,,,,,4.9960492,,,,
,15735850.22,4.995451,-82054.26953125,0.000143971090650797,1.0684842797372E-6,1,0.999253354069792,40.0298881530762,1.99169414557176,16.4800030738115,0.00155157008951607,0.000270728411032399,0.25,-7.37429654456254E-7,0.000143576654956052,9.47915209516913E-8,4.995451,4.995451,-82056.625,-82051.9140625,52.8552837274287,18.7092710651358,2.0459275,0,0,0,4449,4.954,-82054.26953125,,,,,,,,,,,,,,,,,13.753754,,,,,,4.995451,,,,
,15735928.095,4.9983091,-85944.25,0.000153720580771646,1.21058153303268E-6,1,0.999253354069792,40.0298881530762,1.99169353852657,16.4700025320053,0.00165579239752549,0.000295776263508426,0.25,-1.84904766970814E-7,0.000153328175318054,7.17492943406213E-7,4.9983091,4.9983091,-85949.421875,-85939.078125,52.7865004177364,18.708567331541,2.0255907,0,0,0,4449,4.95595,-85944.25,,,,,,,,,,,,,,,,,13.003003,,,,,,4.9983091,,,,
,15736008.71,4.9974108,-89992.21875,0.000166642827216637,1.14020984877368E-6,1,0.999253354069792,40.0298881530762,1.99162256411882,16.4700025320053,0.00179630424225243,0.000315218602632565,0.25,-7.25116368242667E-7,0.000166256998767073,2.70276930759024E-7,4.9969788,4.9978428,-89999.34375,-89985.09375,53.1546474502941,18.70885688412,1.9657851,0,0,0,4433,4.9586,-89992.21875,,,,,,,,,,,,,,,,,13.378378,,,,,,4.9974108,,,,
,15736100.885,4.9979582,-86238.2578125,0.000154548487718552,8.97576442225017E-7,1,0.999253354069792,40.0298881530762,1.99173025743531,16.4700025320053,0.00166409653461871,0.000301098933009718,0.25,1.58386511121293E-7,0.000154154398767898,1.06588969124575E-6,4.9974103,4.9985061,-86268.3359375,-86208.1796875,52.964711720121,18.7107241266317,1.8514194,0,0,0,4449,4.9593,-86238.2578125,,,,,,,,,,,,,,,,,13.753754,,,,,,4.9979582,,,,
,15736184.875,4.99983955,-82040.4609375,0.000144994275267002,1.01650292690599E-6,1,0.999253354069792,40.0298881530762,1.99162096869603,16.4700025320053,0.0015636575669642,0.000266434976738749,0.25,-1.31919431286038E-6,0.000144600252561755,-4.79515431035788E-7,4.9990797,5.0005994,-82070.4765625,-82010.4453125,53.0475643431594,18.7084433654178,1.8793949,0,0,0,4449,4.9598,-82040.4609375,,,,,,,,,,,,,,,,,13.003003,,,,,,4.99983955,,,,
,15736264.02,5.00725245,-78085.03125,0.000132369527551795,8.11072764238895E-7,1,0.999253354069792,40.0298881530762,1.991576967145,16.4700025320053,0.00142938382491715,0.000230876647241726,0.25,-2.33253374700698E-6,0.000131988022298598,-1.57715761836995E-6,5.0071545,5.0073504,-78112.46875,-78057.59375,53.3320771241595,18.7089607627505,2.108171,0,0,0,4453,4.9509,-78085.03125,,,,,,,,,,,,,,,,,12.252253,,,,,,5.00725245,,,,
,15736343.79,5.0087755,-74099.96484375,0.000120412794379798,1.12714580910302E-6,1,0.999253354069792,40.0298881530762,1.99170515032549,16.4700025320053,0.00130033191043501,0.00020852629745475,0.25,-2.24318299073183E-6,0.000120040693488028,-1.56990275100376E-6,5.0079408,5.0096102,-74130.015625,-74069.9140625,52.6684745113325,18.7083455913895,2.1189666,0,0,0,4453,4.95115,-74099.96484375,,,,,,,,,,,,,,,,,12.252253,,,,,,5.0087755,,,,
,15736412.74,5.0006516,-70652.4140625,0.000112223541002988,7.71493112183862E-7,1,0.999253354069792,40.0298881530762,1.99146950909615,16.4700025320053,0.00121242498139613,0.000189343814402693,0.25,-2.5373923756439E-6,0.000111858625820676,-1.9207155890102E-6,5.0003567,5.0009465,-70682.359375,-70622.46875,53.2015451614479,18.7090699073128,2.0872157,0,0,0,4453,4.95265,-70652.4140625,,,,,,,,,,,,,,,,,13.378378,,,,,,5.0006516,,,,
,15736486.055,5.0000851,-66989.1015625,0.000100435544709382,1.03401348566833E-6,1,0.999253354069792,40.0298881530762,1.99175340079467,16.4700025320053,0.00108674108950681,0.000159772579787615,0.25,-3.15703075871108E-6,0.000100094312398302,-2.61438026385919E-6,4.9997401,5.0004301,-67024.0859375,-66954.1171875,53.0014482605248,18.7027037214938,2.02569175,0,0,0,4449,4.9505,-66989.1015625,,,,,,,,,,,,,,,,,13.378378,,,,,,5.0000851,,,,
,15736564.82,4.99898025,-63051.73828125,8.85448979523741E-5,9.32292558306409E-7,1,0.999253354069792,40.0298881530762,1.99165759506503,16.4700025320053,0.00095948856677415,0.000131617881361459,0.25,-3.62595245226501E-6,8.82302693837487E-5,-3.15674137577144E-6,4.9987516,4.9992089,-63081.71484375,-63021.76171875,53.0045747746017,18.7050325154691,1.96617755,0,0,0,4449,4.9517,-63051.73828125,,,,,,,,,,,,,,,,,13.378378,,,,,,4.99898025,,,,
,15736644.935,5.00160145,-59048.5625,7.72335999406575E-5,7.33967062934332E-7,1,0.999253354069792,40.0298881530762,1.99148202754479,16.4700025320053,0.00083832001976265,0.000105576947465647,0.25,-4.0055072755077E-6,7.69475062567643E-5,-3.60441012215699E-6,5.0013766,5.0018263,-59078.50390625,-59018.62109375,52.771649475871,18.7023161376347,1.9462451,0,0,0,4449,4.9505,-59048.5625,,,,,,,,,,,,,,,,,13.378378,,,,,,5.00160145,,,,
,15736723.65,5.00087855,-55113.03515625,6.74736934175962E-5,5.55382192964043E-7,1,0.999253354069792,40.0298881530762,1.99162351297022,16.4700025320053,0.000731942227374176,9.41400664507978E-5,0.25,-3.31006482671663E-6,6.72094272092836E-5,-2.97076448042912E-6,5.0007391,5.001018,-55140.4921875,-55085.578125,53.7611911812172,18.7032807866884,1.8982639,0,0,0,4449,4.9509,-55113.03515625,,,,,,,,,,,,,,,,,13.378378,,,,,,5.00087855,,,,
,15736804.485,4.9995365,-51073.396484375,5.69499606153386E-5,6.79524921691274E-7,1,0.999253354069792,40.0298881530762,1.99169859106589,16.4800030738115,0.000618199030551766,7.65466202714589E-5,0.25,-3.05329149911132E-6,5.67168512366731E-5,-2.77523947288077E-6,4.9989686,5.0001044,-51103.34375,-51043.44921875,52.3652026458709,18.7077776918329,1.86071345,0,0,0,4449,4.9554,-51073.396484375,,,,,,,,,,,,,,,,,12.627627,,,,,,4.9995365,,,,
,15736885.32,4.9994235,-47035.46875,4.30540079559289E-5,7.77513590253664E-7,1,0.999253354069792,40.0298881530762,1.99175185386652,16.4800030738115,0.000466227077713363,6.37489956478241E-5,0.25,-1.75254587583229E-6,4.28670284639821E-5,-1.55230619882596E-6,4.9994235,4.9994235,-47040.39453125,-47030.54296875,53.1515209362172,18.7012995903512,1.7967564,0,0,0,4449,4.95255,-47035.46875,,,,,,,,,,,,,,,,,13.003003,,,,,,4.9994235,,,,
,15736966.97,4.9549124,-42952.67578125,3.27024984843632E-5,4.47687010915425E-7,1,0.999253354069792,40.0298881530762,1.99168611976561,16.4800030738115,0.000355959116268067,3.77273865989127E-5,0.25,-2.31883863126545E-6,3.25586708377954E-5,-2.16814094144809E-6,4.9533486,4.9564762,-42982.66015625,-42922.69140625,53.2398449588903,18.7050714838108,1.9954888,0,0,0,4453,4.9168,-42952.67578125,,,,,,,,,,,,,,,,,13.003003,,,,,,4.9549124,,,,
,15737046.9,5.007381,-38959.58984375,2.0776634239113E-5,5.4029711543561E-7,1,0.999253354069792,40.0298881530762,1.99149606346091,16.4800030738115,0.00022778414285883,1.44347848404284E-5,0.25,-2.35575389872066E-6,2.06851586645945E-5,-2.25950062485441E-6,5.007381,5.007381,-38964.4375,-38954.7421875,52.7950983314479,18.7020436527618,2.0664685,0,0,0,4453,4.94725,-38959.58984375,,,,,,,,,,,,,,,,,13.378378,,,,,,5.007381,,,,
,15737124.935,4.9990978,-35059.880859375,9.89222250869495E-6,4.81613683600062E-7,1,0.999253354069792,40.0298881530762,1.99155263550981,16.4800030738115,0.000109985730040522,-1.83709893237699E-6,0.25,-1.93013668556478E-6,9.85008975154293E-6,-1.88200001228386E-6,4.9985752,4.9996204,-35092.16796875,-35027.59375,53.0264603731402,18.705321680643,2.03596225,0,0,0,4453,4.9508,-35059.880859375,,,,,,,,,,,,,,,,,13.003003,,,,,,4.9990978,,,,
,15737199.455,4.99979875,-31334.4091796875,-1.748921148229E-7,8.67617067441455E-8,1,0.999253354069792,40.0298881530762,1.9916675014095,16.4700025320053,1.72913762877418E-6,-2.06467096610286E-5,0.25,-1.89044852901524E-6,-1.66999232579767E-7,-1.8813507556656E-6,4.9996161,4.9999814,-31364.66796875,-31304.150390625,53.3297322386018,18.7061308327674,1.97585055,0,0,0,4449,4.95015,-31334.4091796875,,,,,,,,,,,,,,,,,12.252253,,,,,,4.99979875,,,,
,15737280.525,4.9977431,-27284.134765625,-1.12011449157167E-5,5.37822348391378E-7,1,0.999253354069792,40.0298881530762,1.99157342257197,16.4700025320053,-0.000115372753674373,-4.93393223187209E-5,0.25,-2.60516980504921E-6,-1.1132753705768E-5,-2.63047354117236E-6,4.9977431,4.9977431,-27286.6015625,-27281.66796875,52.8607551270633,18.7088414099255,1.9462451,0,0,0,4449,4.9502,-27284.134765625,,,,,,,,,,,,,,,,,12.252253,,,,,,4.9977431,,,,
,15737357.65,4.9999423,-23428.1484375,-2.03946395090522E-5,3.71594821798319E-7,1,0.999253354069792,40.0298881530762,1.99132463523858,16.4700025320053,-0.000213661223306206,-6.93018697395103E-5,0.25,-2.83768324423532E-6,-2.02748256558358E-5,-2.88943267486793E-6,4.9998689,5.0000157,-23458.19140625,-23398.10546875,53.279708013371,18.7094006069947,1.9173223,0,0,0,4449,4.9497,-23428.1484375,,,,,,,,,,,,,,,,,13.378378,,,,,,4.9999423,,,,
,15737437.235,5.00045085,-19450.12890625,-2.95872260402772E-5,4.06169652922428E-7,1,0.999253354069792,40.0298881530762,1.99155033809239,16.4700025320053,-0.000313098145351365,-8.28758950009928E-5,0.25,-2.47841471085295E-6,-2.94158628802381E-5,-2.55600783694194E-6,5.0004263,5.0004754,-19475.18359375,-19425.07421875,53.2320286736979,18.7063669485747,1.8422177,0,0,0,4449,4.9506,-19450.12890625,,,,,,,,,,,,,,,,,13.378378,,,,,,5.00045085,,,,
,15737516.925,4.99915405,-15469.84765625,-3.99029694819329E-5,3.44842807119898E-7,1,0.999253354069792,40.0298881530762,1.99142582731023,16.4800030738115,-0.00042408982172349,-0.000101057627666687,0.25,-2.35473579047151E-6,-3.96711707701328E-5,-2.45651291013727E-6,4.9990458,4.9992623,-15502.2265625,-15437.46875,52.7294415358325,18.7035189226016,1.86071345,0,0,0,4449,4.95085,-15469.84765625,,,,,,,,,,,,,,,,,13.378378,,,,,,4.99915405,,,,
,15737594.905,4.99625345,-11571.5678710938,-4.93609134342623E-5,3.50722985577328E-7,1,0.999253354069792,40.0298881530762,1.99146862508541,16.4800030738115,-0.000525448923149779,-0.000120063677722779,0.25,-2.4625744571786E-6,-4.90713821700128E-5,-2.58124224816106E-6,4.996098,4.9964089,-11604.251953125,-11538.8837890625,53.3328587526787,18.7061183269298,1.8147956,0,0,0,4449,4.9491,-11571.5678710938,,,,,,,,,,,,,,,,,13.378378,,,,,,4.99625345,,,,
,15737674.77,4.9989579,-7578.08862304687,-5.8437525973166E-5,2.00855582064981E-7,1,0.999253354069792,40.0298881530762,1.99151768444233,16.4800030738115,-0.000623542332232075,-0.000133606070241571,0.25,-2.13243172845499E-6,-5.80924193643326E-5,-2.26619386596999E-6,4.9987283,4.9991875,-7600.52197265625,-7555.6552734375,52.605944229794,18.7028650180759,1.7612139,0,0,0,4449,4.9526,-7578.08862304687,,,,,,,,,,,,,,,,,13.378378,,,,,,4.9989579,,,,
,15737755.72,4.98215725,-3532.32421875,-6.59263363275912E-5,2.49855674077351E-7,1,0.999253354069792,40.0298881530762,1.99131833423999,16.4800030738115,-0.000703227627761921,-0.000151328945665239,0.25,-2.47549667242489E-6,-6.55326266108987E-5,-2.61431874735094E-6,4.9745784,4.9897361,-3562.25439453125,-3502.39404296875,53.0717948272556,18.7075499464689,1.9463421,0,0,0,4454,4.9522,-3532.32421875,,,,,,,,,,,,,,,,,13.753754,,,,,,4.98215725,,,,
,15737832.86,5.0045047,323.858413696289,-6.21489144740517E-5,2.25468120643576E-7,1,0.999253354069792,40.0298881530762,1.99138180057324,16.4800030738115,-0.000662973449631412,-0.000142404768720137,0.25,-2.31712670268691E-6,-6.17754617006452E-5,-2.44107927186081E-6,5.0045047,5.0045047,321.459075927734,326.257751464844,52.8888937537556,18.7072212915176,1.9855216,0,0,0,4453,4.9466,323.858413696289,,,,,,,,,,,,,,,,,13.378378,,,,,,5.0045047,,,,
,15737904.56,4.99920365,3903.16943359375,-6.04509954651982E-5,2.55023871617585E-7,1,0.999253354069792,40.0298881530762,1.99124846324736,16.4700025320053,-0.00064486164982018,-0.000138435143057431,0.25,-2.23903130833784E-6,-6.00903721858882E-5,-2.36742087808591E-6,4.9983587,5.0000486,3875.6484375,3930.6904296875,52.8756060689287,18.7082434192438,2.0459275,0,0,0,4453,4.94915,3903.16943359375,,,,,,,,,,,,,,,,,12.252253,,,,,,4.99920365,,,,
,15737975,5.00021025,7425.28540039063,-6.58934156166612E-5,2.64746677683079E-7,1,0.999253354069792,40.0298881530762,1.99119938918102,16.4700025320053,-0.000703437506814318,-0.000148095681858072,0.25,-2.16900053131514E-6,-6.55046894599402E-5,-2.32073309377291E-6,4.999711,5.0007095,7395.2216796875,7455.34912109375,52.9881605756979,18.7052069362339,1.9657851,0,0,0,4449,4.94785,7425.28540039063,,,,,,,,,,,,,,,,,13.378378,,,,,,5.00021025,,,,
,15738052.71,5.00006055,11309.3603515625,-7.00213345724941E-5,2.75993793919347E-7,1,0.999253354069792,40.0298881530762,1.99109674496735,16.4700025320053,-0.000747749192989237,-0.000156103617786499,0.25,-2.17336368321151E-6,-6.96137883731083E-5,-2.34836121242513E-6,4.9998989,5.0002222,11279.2783203125,11339.4423828125,53.445413259448,18.7044414478303,1.8888765,0,0,0,4449,4.94855,11309.3603515625,,,,,,,,,,,,,,,,,13.378378,,,,,,5.00006055,,,,
,15738130.655,4.9994164,15204.861328125,-7.14879884326825E-5,2.8393723953028E-7,1,0.999253354069792,40.0298881530762,1.99122518758949,16.4800030738115,-0.000762947761124417,-0.000162656940479492,0.25,-2.50860682795069E-6,-7.10772001888314E-5,-2.69961755914259E-6,4.9994164,4.9994164,15202.3076171875,15207.4150390625,53.3992971768133,18.7034418514504,1.8700075,0,0,0,4449,4.9483,15204.861328125,,,,,,,,,,,,,,,,,13.003003,,,,,,4.9994164,,,,
,15738207.735,4.9985032,19058.0458984375,-6.59447404318857E-5,4.16132646715922E-7,1,0.999253354069792,40.0298881530762,1.99128666496404,16.4700025320053,-0.000704536597766992,-0.000146329739640628,0.25,-1.95349232839172E-6,-6.5573141465322E-5,-2.14484251817187E-6,4.9984174,4.998589,19035.630859375,19080.4609375,52.9131242378518,18.706388244999,1.8239058,0,0,0,4449,4.9487,19058.0458984375,,,,,,,,,,,,,,,,,13.378378,,,,,,4.9985032,,,,
,15738287.955,4.9987721,23066.103515625,-5.46909796626462E-5,4.20874435689239E-7,1,0.999253354069792,40.0298881530762,1.99124334540802,16.4700025320053,-0.000581998231523713,-0.000134683105107359,0.25,-2.8483734943915E-6,-5.43848020665304E-5,-3.01188290568081E-6,4.9987721,4.9987721,23063.6796875,23068.52734375,53.0147359453518,18.7061294812072,1.833016,0,0,0,4449,4.94855,23066.103515625,,,,,,,,,,,,,,,,,13.378378,,,,,,4.9987721,,,,
,15738365.53,4.99695945,26944.4482421875,-4.16978662133867E-5,4.29995543897232E-7,1,0.999253354069792,40.0298881530762,1.99117635321288,16.4800030738115,-0.000442189793309533,-0.000111586844495448,0.25,-2.99114246272181E-6,-4.14662643465355E-5,-3.12008148060583E-6,4.9969192,4.9969997,26912.009765625,26976.88671875,52.9068712096979,18.7049605714287,1.7524606,0,0,0,4449,4.94905,26944.4482421875,,,,,,,,,,,,,,,,,13.378378,,,,,,4.99695945,,,,
,15738443.615,4.9985323,30847.04296875,-3.28392708724778E-5,5.86132694578385E-7,1,0.999253354069792,40.0298881530762,1.99106672343215,16.4700025320053,-0.000349255750565065,-8.23455434070958E-5,0.25,-1.83320904007093E-6,-3.26626941284112E-5,-1.94435829758965E-6,4.9980865,4.9989781,30819.533203125,30874.552734375,53.340675037871,18.7092701829884,1.73521405,0,0,0,4449,4.95125,30847.04296875,,,,,,,,,,,,,,,,,13.378378,,,,,,4.9985323,,,,
,15738526.49,5.0024209,34989.994140625,-3.1391002943146E-5,5.3834538379828E-7,1,0.999253354069792,40.0298881530762,1.99132975952035,16.4800030738115,-0.000333818489631911,-7.94284591054411E-5,0.25,-1.81027600910234E-6,-3.12263814949845E-5,-1.92309738688804E-6,5.0024209,5.0024209,34982.59765625,34997.390625,52.6614398546594,18.7047027717332,1.8514194,0,0,0,4449,4.95035,34989.994140625,,,,,,,,,,,,,,,,,13.378378,,,,,,5.0024209,,,,
,15738607.8,4.9800041,39052.58984375,-3.4145411162469E-5,5.76931161046978E-7,1,0.999253354069792,40.0298881530762,1.99118389404669,16.4700025320053,-0.000361191585373091,-9.73386568296292E-5,0.25,-2.97976355084981E-6,-3.39672285046493E-5,-3.1047830289657E-6,4.9799023,4.9801059,39020.0390625,39085.140625,53.1319802232364,18.7038151468173,1.78782635,0,0,0,4453,4.95955,39052.58984375,,,,,,,,,,,,,,,,,13.003003,,,,,,4.9800041,,,,
,15738690.99,4.9882398,43210.794921875,-4.12793318762681E-5,6.84059456513366E-7,1,0.999253354069792,40.0298881530762,1.99121462837348,16.4700025320053,-0.000432399302873107,-0.000141984769350125,0.25,-5.85411468700213E-6,-4.10606232479828E-5,-6.00362674233013E-6,4.9877911,4.9886885,43188.203125,43233.38671875,53.3586524938133,18.6998056523729,1.6097752,0,0,0,4453,4.9738,43210.794921875,,,,,,,,,,,,,,,,,13.003003,,,,,,4.9882398,,,,
,15738776.275,4.9897184,47473.970703125,-5.05122860358953E-5,8.2631696643166E-7,1,0.999253354069792,40.0298881530762,1.99134780703618,16.4700025320053,-0.000533151168684657,-0.000151815281572069,0.25,-5.1096766308998E-6,-5.02617866203611E-5,-5.31330057762381E-6,4.9897184,4.9897184,47466.5546875,47481.38671875,52.9834708045825,18.700931161792,1.4713581,0,0,0,4449,4.98085,47473.970703125,,,,,,,,,,,,,,,,,12.252253,,,,,,4.9897184,,,,
,15738860.915,4.9935427,51704.744140625,-5.99264751795796E-5,7.83564847830966E-7,1,0.999253354069792,40.0298881530762,1.99124854611366,16.4700025320053,-0.000638547128337772,-0.000146828834709319,0.25,-2.9524593547037E-6,-5.96541797369684E-5,-3.2200299361729E-6,4.9935427,4.9935427,51699.6953125,51709.79296875,52.7935350744094,18.7020790229926,1.4137226,0,0,0,4449,4.9835,51704.744140625,,,,,,,,,,,,,,,,,13.378378,,,,,,4.9935427,,,,
,15738942.415,4.99393965,55777.29296875,-7.11483658569215E-5,8.64208090987545E-7,1,0.999253354069792,40.0298881530762,1.99117361812378,16.4800030738115,-0.000759896564431567,-0.000165060861923791,0.25,-2.62883646395582E-6,-7.08423672144023E-5,-2.963280191715E-6,4.9934335,4.9944458,55747.2421875,55807.34375,52.3972494151594,18.7011231083255,1.36516375,0,0,0,4449,4.98435,55777.29296875,,,,,,,,,,,,,,,,,13.003003,,,,,,4.99393965,,,,
,15739025.54,4.99514415,59933.2421875,-8.51249263073165E-5,8.85767052972224E-7,1,0.999253354069792,40.0298881530762,1.99124243299711,16.4800030738115,-0.000908634466882742,-0.000201705924701162,0.25,-3.51896599024079E-6,-8.47736097678374E-5,-3.93277885245255E-6,4.9945388,4.9957495,59900.8046875,59965.6796875,52.9944136038518,18.6969909310381,1.3183056,0,0,0,4449,4.9851,59933.2421875,,,,,,,,,,,,,,,,,13.378378,,,,,,4.99514415,,,,
,15739112.295,4.9957314,64269.015625,-9.73560331631188E-5,1.01082638309977E-6,1,0.999253354069792,40.0298881530762,1.99124980168987,16.4700025320053,-0.00104295358151383,-0.000210985624560924,0.25,-2.17187104478207E-6,-9.69842913438149E-5,-2.66920965383303E-6,4.9957314,4.9957314,64263.93359375,64274.09765625,53.3688136645633,18.6934012162916,1.3051363,0,0,0,4449,4.9886,64269.015625,,,,,,,,,,,,,,,,,13.753754,,,,,,4.9957314,,,,
,15739196,4.9946842,68452.36328125,-0.000111095493500163,1.29018637221486E-6,1,0.999253354069792,40.0298881530762,1.99110131709599,16.4700025320053,-0.00118625163986139,-0.000263427540221206,0.25,-4.56550229222545E-6,-0.000110683549495613,-5.14315249025362E-6,4.9934177,4.9959507,68422.3671875,68482.359375,53.1866942195826,18.6917542601651,1.23537655,0,0,0,4449,4.99115,68452.36328125,,,,,,,,,,,,,,,,,12.252253,,,,,,4.9946842,,,,
,15739281.845,4.99364875,72742.57421875,-0.000120783890285494,9.74463089847692E-7,1,0.999253354069792,40.0298881530762,1.99100458956526,16.4800030738115,-0.00128844152324557,-0.000294720047509381,0.25,-5.71482977247214E-6,-0.000120358196039059,-6.35906129506816E-6,4.9932179,4.9940796,72715.046875,72770.1015625,52.6333012279671,18.6871442431456,1.2415471,0,0,0,4449,4.99255,72742.57421875,,,,,,,,,,,,,,,,,12.252253,,,,,,4.99364875,,,,
,15739366.555,4.9950857,76978.13671875,-0.000135931737926188,1.18275166738853E-6,1,0.999253354069792,40.0298881530762,1.99121232480198,16.4700025320053,-0.00144837932776386,-0.000343533693532027,0.25,-7.5050561167437E-6,-0.000135476221478735,-8.24631589866096E-6,4.9950857,4.9950857,76973.234375,76983.0390625,53.1147843958133,18.6848074698934,1.21105985,0,0,0,4449,4.9954,76978.13671875,,,,,,,,,,,,,,,,,13.378378,,,,,,4.9950857,,,,
,15739454.47,4.99825695,81371.07421875,-0.00014766316917296,9.53662710008262E-7,1,0.999253354069792,40.0298881530762,1.99156467804839,16.4700025320053,-0.001575129705772,-0.000367064181935912,0.25,-7.55218481026777E-6,-0.000147205432892427,-8.37970744735096E-6,4.9977651,4.9987488,81346.125,81396.0234375,53.0342766583325,18.6808779279325,1.23537655,0,0,0,4449,4.9972,81371.07421875,,,,,,,,,,,,,,,,,13.378378,,,,,,4.99825695,,,,
,15739541.095,5.0020156,85701.421875,-0.000158875289035999,7.93868162323258E-7,1,0.999253354069792,40.0298881530762,1.99144718716365,16.4700025320053,-0.00169679878246752,-0.000385130970969425,0.25,-7.1908034661083E-6,-0.000158424375814098,-8.10351054710618E-6,5.0017014,5.0023298,85668.9140625,85733.9296875,52.8263634722171,18.6869520757036,1.2921631,0,0,0,4449,4.9953,85701.421875,,,,,,,,,,,,,,,,,13.753754,,,,,,5.0020156,,,,
,15739629.68,5.0119553,89999.671875,-0.000172815243691191,1.02503662627218E-6,1,0.999253354069792,40.0298881530762,1.99160156930906,16.4800030738115,-0.00184789081458733,-0.000409851314392688,0.25,-6.95030038459045E-6,-0.000172369263136226,-7.96456162466377E-6,5.0119553,5.0119553,89999.65625,89999.6875,52.433204327044,18.6805263286934,1.3314749,0,0,0,4417,4.9922,89999.671875,,,,,,,,,,,,,,,,,13.753754,,,,,,5.0119553,,,,