File: data/doubleLayers/dl_0-25/ppms/DD205_8_extracted.dat
#Loading data from DD205_10_HYST_300K.DAT
#
#Found columns:
#Comment
#Time Stamp (sec)
#Temperature (K)
#Magnetic Field (Oe)
#Moment (emu)
#M. Std. Err. (emu)
#Transport Action
#Averaging Time (sec)
#Frequency (Hz)
#Peak Amplitude (mm)
#Center Position (mm)
#Coil Signal' (mV)
#Coil Signal" (mV)
#Range (mV)
#M. Quad. Signal (emu)
#M. Raw' (emu)
#M. Raw" (emu)
#Min. Temperature (K)
#Max. Temperature (K)
#Min. Field (Oe)
#Max. Field (Oe)
#Mass (grams)
#Motor Lag (deg)
#Pressure (Torr)
#VSM Status (code)
#Motor Status (code)
#Measure Status (code)
#PPMS Status (code)
#System Temp. (K)
#System Field (Oe)
#Sample Position (deg)
#Bridge 1 Resistance (ohms)
#Bridge 1 Excitation (A)
#Bridge 2 Resistance (ohms)
#Bridge 2 Excitation (A)
#Bridge 3 Resistance (ohms)
#Bridge 3 Excitation (A)
#Bridge 4 Resistance (ohms)
#Bridge 4 Excitation (A)
#Signal 1 Vin (V)
#Signal 2 Vin (V)
#Digital Inputs (code)
#Drive 1 Iout (mA)
#Drive 1 Ipower (W)
#Drive 2 Iout (mA)
#Drive 2 Ipower (W)
#Pressure ()
#Map 20 ()
#Map 21 ()
#Map 22 ()
#Map 23 ()
#Map 24 ()
#Map 25 ()
#Map 26 ()
#Map 27 ()
#Map 28 ()
#Map 29 ()
#
#Transformed data from column 'Moment (emu)' from emu to memu by multiplication with 1000.
#Transformed data from column 'Magnetic Field (Oe)' from Oe to Tesla by division with 10000.
#Loaded 1407 datapoints.
#Loading Magnetic Field (Oe) and Moment (emu)
#Running linear fit between B=(6.005159375 .. 8.999977734375) with LM algorithm.
#[[Fit Statistics]]
#    # function evals   = 9
#    # data points      = 236
#    # variables        = 2
#    chi-square         = 0.000
#    reduced chi-square = 0.000
#    Akaike info crit   = -3494.206
#    Bayesian info crit = -3487.279
#[[Variables]]
#    m:  -0.02985149 +/- 4.51e-05 (0.15%) (init= 3.533664)
#    b:   0.08983836 +/- 0.000341 (0.38%) (init=-31.98182)
#[[Correlations]] (unreported correlations are <  0.100)
#    C(m, b)                      = -0.993
#Running linear fit between B=(-8.99996328125 .. -6.002492578125) with LM algorithm.
#[[Fit Statistics]]
#    # function evals   = 8
#    # data points      = 237
#    # variables        = 2
#    chi-square         = 0.000
#    reduced chi-square = 0.000
#    Akaike info crit   = -3552.065
#    Bayesian info crit = -3545.129
#[[Variables]]
#    m:  -0.02988845 +/- 4.12e-05 (0.14%) (init=-0.0298515)
#    b:  -0.08936093 +/- 0.000311 (0.35%) (init=-0.08983837)
#[[Correlations]] (unreported correlations are <  0.100)
#    C(m, b)                      =  0.993
#Mean diamagnetic slope: -0.029870014616176853 +/- 3.053389528000393e-05
#Exporting data to DD205_8_extracted.dat
#
#B / T	M / memu	T / K
8.999977734375	-0.178922569387208	300.09140015
8.978120703125	-0.178307963813727	300.0866699
8.92612890625	-0.176334678599098	300.08618165
8.872018359375	-0.17603082179734	300.0862274
8.82519921875	-0.173569796140995	300.0849304
8.776457421875	-0.172102535089803	300.0837555
8.71495546875	-0.171005016545692	300.0817871
8.6573546875	-0.169420032935339	300.0815125
8.61830703125	-0.167541811678802	300.08187865
8.569490625	-0.16606568716914602	300.07991025
8.494285546875	-0.163550950600466	300.0802307
8.42886328125	-0.161141326478924	300.0778198
8.39078671875	-0.160930607107444	300.0774689
8.344901171875	-0.158580165354465	300.0762787
8.2931484375	-0.158427415150774	300.07568355
8.250184375	-0.157138700588232	300.07391355
8.197475	-0.154935896552708	300.0720825
8.132036328125	-0.15314234957895	300.0702515
8.06956953125	-0.15069081892372302	300.0686951
8.034332421875	-0.15039488626956202	300.06776425
7.984545703125	-0.14897271903539	300.06710815
7.9406125	-0.14702304668886498	300.0656128
7.893737890625	-0.145537215471543	300.0646515
7.8488375	-0.144536378610584	300.06321715
7.779523828125	-0.14266744251830402	300.059906
7.74241875	-0.14212354421915502	300.06089785
7.67405703125	-0.13993518219374998	300.0587769
7.63208984375	-0.138335769403136	300.05729675
7.589061328125	-0.135971766108104	300.05693055
7.5314515625	-0.135344035223265	300.05505375
7.478705859375	-0.13322771314185702	300.05381775
7.4152734375	-0.13161038835352798	300.0526123
7.371312109375	-0.130465863880638	300.0519104
7.3059	-0.128987055766388	300.0489197
7.256078515625	-0.127047903587051	300.0479126
7.21508515625	-0.125336979560654	300.046051
7.164328515625	-0.12334516975813999	300.04496765
7.116503125	-0.12222607600788798	300.04370115
7.068624609375	-0.121597227778062	300.0428772
7.015892578125	-0.11961616674754201	300.04148865
6.96806953125	-0.118369818018317	300.0404358
6.905578125	-0.11642011996288901	300.0392456
6.849914453125	-0.115317611677387	300.0374756
6.81085859375	-0.11341598328352401	300.0368042
6.748360546875	-0.112175743599789	300.035614
6.713198046875	-0.11151247080481701	300.0345764
6.666295703125	-0.108973841938678	300.03359985
6.616496484375	-0.10817705583480501	300.03334045
6.553990234375	-0.106134957886445	300.0332336
6.4973759765625	-0.104597815547558	300.0310669
6.45930859375	-0.103353457448844	300.0319672
6.3938748046875	-0.101595572207251	300.0314941
6.343080078125	-0.0997962246634611	300.02944945
6.3039908203125	-0.09848162814204599	300.0289612
6.25303828125	-0.0969009877579234	300.02783205
6.208032421875	-0.0954582651753291	300.027298
6.14342109375	-0.0946158907118641	300.0275879
6.1052615234375	-0.0931971563129906	300.0262451
6.0426177734375	-0.0912425388473927	300.0264587
6.0063919921875	-0.0901664136658116	300.0257263
5.952580859375	-0.08816701435015391	300.0235596
5.9065591796875	-0.0874323451701146	300.02334595
5.8557029296875	-0.0855037247080523	300.0223389
5.800840234375	-0.08409844977314901	300.02264405
5.75677890625	-0.08256397407875031	300.02104185
5.6960603515625	-0.08116573016700801	300.0205841
5.6510720703125	-0.07982926731427631	300.0197296
5.599216796875	-0.078291450484217	300.019577
5.54440625	-0.0763089805565618	300.0185547
5.4984166015625	-0.0758751653926527	300.01945495
5.440653125	-0.0735096953035911	300.0182953
5.390758203125	-0.07188868644174719	300.0165405
5.3310236328125	-0.0710746187009284	300.0165405
5.282104296875	-0.0704575308078564	300.01441955
5.2400279296875	-0.0682449301282658	300.0131836
5.171525390625	-0.0659540971762116	300.0134125
5.1353005859375	-0.06547175967400991	300.01254275
5.0893111328125	-0.0634862566578608	300.01205445
5.0413462890625	-0.062269018417769	300.01185605
4.994387109375	-0.0610036133065801	300.0109253
4.950334375	-0.0598432310804593	300.00991825
4.87199921875	-0.0572100655727358	300.0089417
4.8328580078125	-0.0564899289753901	300.0089722
4.7721708984375	-0.054654978404912805	300.0098267
4.7369474609375	-0.054241778167954904	300.0089569
4.6909427734375	-0.0523975779897911	300.0070343
4.6371201171875	-0.051092486963133704	300.00704955
4.59504765625	-0.0490400925388631	300.00502015
4.5236087890625	-0.047678730911177594	300.0045776
4.478552734375	-0.0460485860420525	300.00457765
4.418826171875	-0.045017607106648996	300.0032349
4.387503515625	-0.0435645724308525	300.00257875
4.337566796875	-0.0420055110149083	300.002594
4.285716015625	-0.0405435495837477	300.00247195
4.232845703125	-0.0398849182671405	300.00219725
4.166334375	-0.038176037552776	300.0023804
4.1340470703125	-0.0362246140744359	300.00155635
4.06456953125	-0.0350789882926262	300.000946
4.02830625	-0.0338254410011991	300.00074765
3.96365234375	-0.0321495887293037	300.0005798
3.93138203125	-0.0309836225797149	300.00042725
3.879519921875	-0.0291638089658405	300.0002899
3.8344994140625	-0.0282757159459006	299.9985657
3.77184921875	-0.026264799972475102	300.0006104
3.7366453125	-0.0248563305433349	300.000885
3.666163671875	-0.0236385104354817	300.0004578
3.606471875	-0.022061165968277802	300.0014343
3.572205859375	-0.020479280110584898	300.0015564
3.5281705078125	-0.0200162855554672	300.0010834
3.4782701171875	-0.019027042206739602	299.99960325
3.4303064453125	-0.0168918589227702	300.0000305
3.3686755859375	-0.015530455467308501	300.0002136
3.3138509765625	-0.013500066703041	300.0001831
3.2541505859375	-0.0124897403041074	299.9989319
3.200316796875	-0.0109161702951036	299.9993896
3.1690103515625	-0.010169667894129101	299.99792485
3.11222001953125	-0.00823365536146486	299.99810795
3.059363671875	-0.00599755549742242	299.9976044
3.003576171875	-0.004792264939961001	299.99786375
2.9517169921875	-0.00430170666909937	299.9975128
2.90279072265625	-0.0021765795848511698	299.9971619
2.837206640625	-0.00105337090025074	299.9976501
2.770651171875	0.00126881891709978	299.9975891
2.7295458984375	0.0027070491612668298	299.9957886
2.68548154296875	0.00360549098689638	299.995636
2.6375052734375	0.00447869644055327	299.9958954
2.58857919921875	0.00644121880333327	299.9957428
2.53769208984375	0.0067701544500081996	299.9955139
2.48481943359375	0.0081636875564262	299.99487305
2.42807138671875	0.01090045162973	299.9954224
2.37718662109375	0.0118747179330666	299.9952393
2.31553623046875	0.012311296397742	299.9938965
2.27737177734375	0.014210784531865	299.9932404
2.2156607421875	0.015393030809039202	299.9940796
2.1706509765625	0.0168767076682267	299.99356075
2.12268037109375	0.018140352861509	299.99414065
2.06591455078125	0.0196412241255142	299.99568175
2.0199419921875	0.0212933749399811	299.99362185
1.9680603515625	0.0217930125709714	299.99427795
1.92109052734375	0.0231454468705873	299.99403385
1.8584513671875	0.0249671797220788	299.993866
1.8222439453125	0.0248630932402879	299.9945984
1.77821201171875	0.026835099740392897	299.9942474
1.72536123046875	0.0285353765559493	299.99440005
1.6705322265625	0.0301615063687029	299.9931183
1.59812290039062	0.030834480158751797	299.9926758
1.56092607421875	0.0319622562560013	299.9932709
1.4982354003906202	0.0329590760306962	299.9923706
1.46298583984375	0.0343590768680844	299.9937744
1.41008325195313	0.0350775932503136	299.99223325
1.35621494140625	0.0364040923429007	299.9940033
1.30919174804687	0.0376835769124479	299.99417115
1.2533655761718798	0.0393388408549975	299.9928131
1.19950356445313	0.0398054823141754	299.99267575
1.15249370117187	0.0418099943250176	299.9914551
1.11136440429688	0.0422316704824499	299.9924927
1.06141352539062	0.042904776237380704	299.9929047
1.01341284179688	0.0434979398267767	299.9925537
0.95856640625	0.0452072891946577	299.9932861
0.908610986328125	0.0462800769957768	299.99343875
0.857624072265625	0.046204495389986	299.99295045
0.807688818359375	0.0470556260438774	299.9942017
0.7440228759765629	0.0485852038673463	299.9920044
0.688195068359375	0.0497190337331089	299.9919434
0.6490075439453129	0.048986386759962405	299.9923248
0.602972924804687	0.0506520048397269	299.992157
0.549084375	0.0504855544005681	299.99305725
0.484443798828125	0.0502245113750112	299.9926147
0.4196994140625	0.049931640934794595	299.9928284
0.37856009521484396	0.050578229344208005	299.9927673
0.332462683105469	0.049627821848196904	299.9935913
0.284435388183594	0.048076910264058095	299.99447635
0.22463673095703102	0.047574329774961406	299.994873
0.18736626586914099	0.045939509021581705	299.99499515
0.141284918212891	0.042838956600398194	299.994812
0.0872441650390625	0.038714658147703	299.9950714
0.0401641098022461	0.0332888792906252	299.9955902
-0.0107483939170837	-0.0034618653851410104	299.99468995
-0.05369337921142581	-0.024546877566351998	299.99595645
-0.10235718688964801	-0.0349009761520099	299.99583435
-0.15088270874023402	-0.040264247611089	299.99728395
-0.199421343994141	-0.0439642612121735	299.9968262
-0.25286339111328104	-0.0454756758866232	299.995636
-0.319345751953125	-0.046521361865863003	299.995697
-0.366581945800781	-0.0482201584503803	299.9967651
-0.421686328125	-0.0484124403393879	299.99723815
-0.4855294921875	-0.049016684906663194	299.9975281
-0.525711083984375	-0.0484841299077918	299.9974823
-0.569850659179687	-0.0492219596581582	299.9980316
-0.616903637695313	-0.048406534206530696	299.9977722
-0.661991479492188	-0.0482514636907579	299.99591065
-0.706085620117187	-0.0475434731976766	299.99668885
-0.7629123779296879	-0.046298459528509	299.9975586
-0.811932543945313	-0.0457714016043566	299.9976501
-0.878566796875	-0.0445507175103804	299.9986572
-0.9325376953125	-0.044798644471542096	299.9979248
-0.96587060546875	-0.043238822341922806	299.99879455
-1.01289755859375	-0.042468939677921695	299.9988098
-1.0599435546875	-0.042813401795855195	299.9996033
-1.1324537597656201	-0.0402517045200678	300.000061
-1.17949291992187	-0.0395154704048626	300.00039675
-1.2294625488281201	-0.038062029409450304	300.00086975
-1.29117651367188	-0.0365866225452256	300.0016785
-1.34511220703125	-0.036377620697886505	300.0032349
-1.3990259765625	-0.0347658913020895	300.0047913
-1.4597942871093799	-0.033043546151284096	300.0049438
-1.5156349609375	-0.032208334724282396	300.0047302
-1.56657836914062	-0.0313084917611661	300.0049133
-1.60382294921875	-0.0296240104526491	300.00590515
-1.64496479492187	-0.028963340766720202	300.0073242
-1.7027712890625	-0.028114957709344	300.0070801
-1.75175927734375	-0.026679370185934703	300.0076294
-1.80663525390625	-0.0254761270759014	300.00805665
-1.86933095703125	-0.0239002305025459	300.0095215
-1.91929931640625	-0.0229967106484199	300.0091858
-1.95653642578125	-0.021445736443801298	300.00993345
-2.001614453125	-0.0200476360347089	300.00982665
-2.0604169921875	-0.0183681748498666	300.0112915
-2.118219921875	-0.0175661728287893	300.0117645
-2.16524833984375	-0.015971479584511398	300.01138305
-2.2083359375	-0.014485671149688099	300.01182555
-2.270115234375	-0.0138001302172964	300.011261
-2.30831669921875	-0.0126422591802123	300.0112305
-2.36123251953125	-0.0109288552950783	300.011734
-2.4160998046875	-0.00955764597406527	300.01138305
-2.4611666015625	-0.00868454285681973	300.01161195
-2.51210986328125	-0.00672177540783045	300.0113525
-2.55913642578125	-0.005819257598215	300.01185605
-2.6306603515625	-0.003962192022872271	300.0114441
-2.69344248046875	-0.00292321924944063	300.0108643
-2.74045927734375	-0.00136150750165213	300.012085
-2.79435009765625	-0.00016803122880559	300.0125732
-2.82766630859375	0.0011532698720578402	300.012207
-2.87762412109375	0.0026504587902268497	300.0137787
-2.924662109375	0.00390356980209301	300.0131683
-2.97754677734375	0.004957091250660061	300.0150757
-3.02361591796875	0.00647947896524463	300.0151062
-3.07455498046875	0.00820779834790702	300.0159302
-3.13533076171875	0.010285473018168501	300.0170593
-3.1902494140625	0.0104811054931012	300.0170288
-3.22457509765625	0.0127161387956734	300.0171051
-3.27851435546875	0.0139353826285164	300.01797485
-3.3216765625	0.014695567551724001	300.01852415
-3.3726892578125	0.015911158783146803	300.01916505
-3.4227162109375	0.017944568497688298	300.0204468
-3.4943166015625	0.0190754033159013	300.0210266
-3.559994921875	0.0200988560320019	300.021698
-3.602208203125	0.021601525921496802	300.0226288
-3.661075	0.0238056492301518	300.0233459
-3.6953740234375	0.025615828631803103	300.02311705
-3.7561873046875	0.026494041465605602	300.0220337
-3.795422265625	0.0278595589793249	300.0233002
-3.838570703125	0.0288213602987486	300.02430725
-3.8866380859375	0.030551111239311	300.02430725
-3.957267578125	0.031688021235509005	300.0248108
-4.0063119140625	0.0338925731314519	300.02526855
-4.054424609375	0.034683242176044	300.02508545
-4.117180078125	0.0366260829317541	300.0259705
-4.1554392578125	0.037213035474009004	300.02586365
-4.2015310546875	0.0392848743093848	300.0258331
-4.253527734375	0.0398633759790195	300.02648925
-4.2976703125	0.0414243736232308	300.02738955
-4.36434453125	0.043330905401724795	300.0257263
-4.423195703125	0.0450351890790995	300.0284729
-4.463437109375	0.0461978827623538	300.02737425
-4.5095765625	0.0477391064641492	300.0261841
-4.5566388671875	0.049377284292901905	300.0269318
-4.6057142578125	0.0494319578778149	300.02586365
-4.6606203125	0.0517810978202824	300.02545165
-4.71457421875	0.0536029208301272	300.0249176
-4.7743880859375	0.055121464855970304	300.0251465
-4.823430078125	0.057495715105733404	300.0255737
-4.889148828125	0.0583722813219447	300.0244141
-4.9421837890625	0.0589727572751914	300.0251465
-4.996119140625	0.061738562502969996	300.024292
-5.052027734375	0.06268656521330271	300.0238342
-5.1108662109375	0.0651849636776493	300.0242004
-5.16676484375	0.0658195388283014	300.023468
-5.2059951171875	0.0674011815094977	300.02442935
-5.269759765625	0.0698233605190373	300.0256348
-5.3354419921875	0.07089433522638479	300.0254211
-5.3688123046875	0.0714293891788969	300.02641295
-5.430609765625	0.07356494645139	300.0258789
-5.4669021484375	0.0750717430939758	300.0267334
-5.51396875	0.076460087951743	300.02789305
-5.584597265625	0.07765029848841469	300.02832035
-5.6209001953125	0.0790740147861637	300.02764895
-5.6885728515625	0.0807070659986628	300.0290527
-5.7238939453125	0.0832389568455881	300.02859495
-5.774891796875	0.0835156817636044	300.03189085
-5.81908125	0.0851867908663215	300.03167725
-5.8720333984375	0.0861572758527866	300.03175355
-5.926958203125	0.0880565061987687	300.0331726
-5.9887767578125	0.0894977520708814	300.0351257
-6.0260228515625	0.0910744242801885	300.03471375
-6.085850390625	0.09299867069399691	300.0334778
-6.12116640625	0.09439860569859171	300.0367432
-6.16629140625	0.0949572857084566	300.03593445
-6.2212060546875	0.0965176159513073	300.0350952
-6.2722689453125	0.0979828082959572	300.03631595
-6.3262271484375	0.100022241557654	300.03701785
-6.3723294921875	0.100792294895428	300.0375061
-6.4252900390625	0.101961633186636	300.03713985
-6.4900111328125	0.104413023957863	300.03749085
-6.523379296875	0.10567353961728801	300.03756715
-6.598909765625	0.106720854067487	300.038147
-6.626365625	0.10867917817593001	300.0361176
-6.6694984375	0.110661171566479	300.0378876
-6.71763125	0.11019869525639099	300.03796385
-6.787259375	0.11240509433963701	300.0379028
-6.823559765625	0.115224307834301	300.0371399
-6.890243359375	0.116410345498402	300.0374756
-6.9186796875	0.117137097778654	300.03681945
-6.972645703125	0.118922755295126	300.0377045
-7.01873046875	0.119486945108888	300.03611755
-7.070712890625	0.12120508206722401	300.0355377
-7.121707421875	0.12334051578015201	300.03604125
-7.184508984375	0.125294381697794	300.0357971
-7.23746796875	0.126297668156031	300.0361633
-7.266886328125	0.12745415643170602	300.0362854
-7.3188828125	0.130276800953536	300.0369568
-7.364965234375	0.130258278559397	300.03544615
-7.419894140625	0.13244770599513297	300.03578185
-7.466969140625	0.13367595607803098	300.03565975
-7.522880859375	0.13541980946886	300.03639225
-7.587612890625	0.137387411568925	300.0368958
-7.64357421875	0.138753581921644	300.0380249
-7.699459375	0.14040167647426	300.0376587
-7.752443359375	0.141760164898278	300.0381165
-7.80539765625	0.143219318544938	300.0380249
-7.842680859375	0.14393829443968	300.03730775
-7.891709765625	0.14720828717477802	300.03811645
-7.93683125	0.14777642327003	300.0388336
-8.007457421875	0.148913791555662	300.0384521
-8.054574609375	0.151191838957384	300.03919985
-8.106564453125	0.152752553269301	300.0401001
-8.159511328125	0.154338300720337	300.0413361
-8.203653515625	0.155306416160276	300.04173275
-8.267404296875	0.157203921697941	300.0415344
-8.304678515625	0.15881544776673598	300.0425568
-8.35470390625	0.16072383131484302	300.0423889
-8.411597265625	0.161930337676125	300.04234315
-8.45865390625	0.163136836295853	300.0427399
-8.515621875	0.16522328535236	300.0429535
-8.560725390625	0.165791254184093	300.04249575
-8.63036328125	0.16725135610539102	300.0418701
-8.68624296875	0.169541611922931	300.0433044
-8.722532421875	0.170928895099558	300.04359435
-8.771596484375	0.173250636944067	300.04354855
-8.817689453125	0.173446869093516	300.04484555
-8.8755453125	0.17608453803047702	300.0435028
-8.927501171875	0.17729010451511398	300.0433655
-8.9856421875	0.181398288320936	300.04414365
-8.993065625	0.181480545924543	300.0412598
-8.9551625	0.17861383266512001	300.04240415
-8.896240234375	0.17649072183113199	300.0409088
-8.85736875	0.17532516909489	300.04074095
-8.7900734375	0.174028875714777	300.0394897
-8.736394921875	0.171789168983096	300.0384827
-8.695399609375	0.169946675601507	300.0380707
-8.64952734375	0.169287345109616	300.0385132
-8.596816796875	0.167472036162222	300.0373535
-8.548003125	0.166040553926022	300.03689575
-8.475693359375	0.164745700796047	300.0362549
-8.4317859375	0.162983124493277	300.03598025
-8.3732140625	0.16031660585552301	300.0360718
-8.33609375	0.159683855541353	300.0350037
-8.289241796875	0.157992594546415	300.035202
-8.23065625	0.15764456132569798	300.03411865
-8.1857625	0.155270848222697	300.0332794
-8.143772265625	0.15426708831861402	300.0333252
-8.081325390625	0.152651744888858	300.0307007
-8.026569140625	0.150705273406614	300.0299683
-7.97969921875	0.149063858526687	300.028656
-7.915248046875	0.147932588202805	300.0286865
-7.853753515625	0.146069287591045	300.0288086
-7.815679296875	0.144662284658173	300.02886965
-7.771730859375	0.142971140915626	300.0280762
-7.714144921875	0.141394023545635	300.02688595
-7.659480859375	0.13983394836972002	300.02584835
-7.5969390625	0.138923203291019	300.0257874
-7.55496328125	0.13564675837388598	300.0241394
-7.492478125	0.13503129183023801	300.0242004
-7.45243984375	0.13401432463826	300.02400205
-7.395813671875	0.13226863406147402	300.0235596
-7.35968515625	0.130173230958069	300.02218625
-7.31381015625	0.129315964591135	300.0221863
-7.265956640625	0.12723456361608299	300.02119445
-7.210315234375	0.126839119645066	300.02005
-7.17419296875	0.125589638187843	300.02133175
-7.128289453125	0.1230367763749	300.0211029
-7.07167421875	0.121215361378819	300.0200653
-7.0150421875	0.120221278075922	300.01956175
-6.97111796875	0.11928405054177	300.01811215
-6.914469140625	0.11756304762823701	300.01805115
-6.85494921875	0.117092959328809	300.0171814
-6.79929296875	0.114930956862575	300.0158081
-6.7661015625	0.11281801482946	300.0157776
-6.69085	0.110700624982117	300.0148315
-6.647901171875	0.10882943745251901	300.0145569
-6.603003515625	0.108831164823012	300.0143738
-6.5571017578125	0.106789772216446	300.01475525
-6.5053732421875	0.10542177252091	300.01332095
-6.4477376953125	0.103339569327626	300.0137482
-6.3989478515625	0.102788891199454	300.0119934
-6.3364396484375	0.100444567661777	300.0130615
-6.2758015625	0.0986757477485974	300.0116272
-6.2375896484375	0.0968862383209607	300.01139835
-6.1739888671875	0.0954235965995348	300.0101318
-6.1152361328125	0.0943338570802064	300.0093384
-6.077087890625	0.0923465907330569	300.0092163
-6.0330501953125	0.09061844563552121	300.00897215
-5.9822017578125	0.089530092904303	300.00863645
-5.9185466796875	0.08802619857123359	300.0073853
-5.8745205078125	0.08594636730482809	300.00888065
-5.827541796875	0.0842858427714452	300.007431
-5.7638876953125	0.0836587997875026	300.0062866
-5.725738671875	0.0819049643001223	300.0062866
-5.6817052734375	0.0806590044248993	300.00630185
-5.6357251953125	0.0795659997726383	300.00656125
-5.5622919921875	0.0782362334657984	300.0056458
-5.5221755859375	0.0758751636525256	300.0053711
-5.4566314453125	0.0749832512016072	300.006073
-5.4174697265625	0.0731123922280552	300.0052948
-5.37146484375	0.0722737231850184	300.0052795
-5.3225501953125	0.07100310675464659	300.00517275
-5.276558203125	0.0696583890741413	300.0046082
-5.2227341796875	0.0670818901679929	300.0039673
-5.1747994140625	0.0665374499097429	300.00486755
-5.1082517578125	0.0649041781777845	300.0038452
-5.072053125	0.0640440546095354	300.0043182
-5.022137890625	0.06148512246580099	300.0037842
-4.9780953125	0.0607893040902531	300.00323485
-4.903680859375	0.059525910883802005	300.0036926
-4.8645447265625	0.0574532458742284	300.0028229
-4.8195380859375	0.0555089802308047	300.00341795
-4.7657064453125	0.0546934056409486	300.00157165
-4.70405	0.053996677770305306	300.0005798
-4.6570763671875	0.051390308951136096	300.00065615
-4.6110953125	0.0500356584679786	300.00009155
-4.5464890625	0.048706013798694096	299.9984131
-4.5093126953125	0.047554346853258	299.999588
-4.4456427734375	0.0453913321228948	299.9985352
-4.3967265625	0.0438270643931611	299.9974823
-4.3487650390625	0.043478293801390996	299.99671935
-4.2753849609375	0.0412244174853553	299.9962158
-4.2323099609375	0.0398063620267339	299.9966736
-4.18242734375	0.0380012499729112	299.9957428
-4.1305419921875	0.0370048333056373	299.99475095
-4.0786908203125	0.035374777034882204	299.99375915
-4.019930078125	0.0332902306617185	299.9930725
-3.963190234375	0.0331225407886463	299.9923401
-3.928921875	0.030739784269460196	299.99250795
-3.8790162109375	0.029821256350928003	299.9924469
-3.829109765625	0.0272042885998195	299.9917755
-3.77330859375	0.0273957222203224	299.99186705
-3.724382421875	0.0256169689271519	299.9911652
-3.665678125	0.0232825853441699	299.9906311
-3.628480859375	0.022862114474758	299.9911041
-3.5844521484375	0.0214962339547347	299.99134825
-3.5316029296875	0.0201104167795615	299.9901886
-3.4758232421875	0.0182671438053875	299.99098205
-3.42001640625	0.0166046578434946	299.9918518
-3.3750197265625	0.0165131365405581	299.9907074
-3.3250953125	0.0143263700899359	299.99075315
-3.27815595703125	0.0128583479961945	299.9901123
-3.21454775390625	0.0122566554184321	299.9916077
-3.15389755859375	0.0101400020871367	299.9900818
-3.1176248046875	0.008796096597734629	299.9893799
-3.0461751953125	0.00761320483053946	299.9884949
-2.98353837890625	0.0052695695072538	299.9897156
-2.949290234375	0.0043315176629666104	299.98876955
-2.8944728515625	0.00248956601995072	299.9885254
-2.8387056640625	0.00169509079584811	299.98861695
-2.7897869140625	-0.00024800888293523195	299.98886105
-2.73301376953125	-0.000504452385377772	299.9894104
-2.68210185546875	-0.0025845520196842897	299.98928835
-2.63216435546875	-0.00438170510535288	299.990036
-2.56756005859375	-0.00550516377704738	299.9906311
-2.5303779296875	-0.00631568081198557	299.98957825
-2.48537470703125	-0.00788673669021128	299.9887085
-2.43741728515625	-0.00915036270715787	299.9897003
-2.37381376953125	-0.010512970054131699	299.9884644
-2.3229146484375	-0.012248471919833	299.98703
-2.27008447265625	-0.0132685595419896	299.9877625
-2.21328037109375	-0.0147929594573628	299.9881897
-2.15750498046875	-0.0161216210036229	299.9888306
-2.107564453125	-0.0181466056477721	299.98825075
-2.05961923828125	-0.0196065346153009	299.98828125
-2.00872705078125	-0.0205617322696173	299.9878998
-1.96370498046875	-0.0217359231881908	299.98753355
-1.90988388671875	-0.023105774691114103	299.9867401
-1.8521376953125	-0.0247034100000673	299.98738095
-1.80224931640625	-0.0254021353564555	299.9871521
-1.7591755859375	-0.0264855787755655	299.9864807
-1.6906732421875	-0.028640148538216198	299.9863281
-1.63586025390625	-0.0300179418863831	299.98703
-1.59674208984375	-0.0306691853737366	299.98812865
-1.5497183105468701	-0.031477788614988206	299.98564145
-1.50371508789062	-0.0333002147805365	299.9860382
-1.44495874023438	-0.0342396642215792	299.98516845
-1.39892958984375	-0.0353100185618389	299.98544315
-1.3519142578125	-0.0365977834211208	299.98446655
-1.3038853027343702	-0.0365331848488928	299.9848938
-1.2343552246093799	-0.0380365515436481	299.9862976
-1.1990783203125	-0.0403513789127579	299.9859314
-1.14915649414062	-0.041061086378172906	299.98565675
-1.10312509765625	-0.041346261054358804	299.986084
-1.04438784179688	-0.0423431664115502	299.9861298
-0.979725537109375	-0.044071841410529305	299.9865723
-0.945441796875	-0.044194207436884396	299.98693845
-0.879802392578125	-0.045207776820425795	299.9867859
-0.8455	-0.0464114095192089	299.9877319
-0.799490087890625	-0.0476458108296061	299.98802185
-0.7495164794921879	-0.0473395861092484	299.98876955
-0.6819384765625	-0.0485800747492148	299.9870605
-0.63393466796875	-0.0489483424733104	299.98745725
-0.5898651123046871	-0.0491162505985841	299.98698425
-0.527159692382812	-0.0499392240173747	299.9864197
-0.49385231933593704	-0.0499827462022195	299.98773195
-0.436025439453125	-0.0498735118923838	299.9873657
-0.376239306640625	-0.0488178745254221	299.9884949
-0.339984716796875	-0.048949587894712605	299.98753355
-0.277223010253906	-0.0480726954322734	299.9875183
-0.231143725585938	-0.047166082608312704	299.98716735
-0.18503353881835902	-0.0448566239057618	299.98768615
-0.13009674682617198	-0.0414614493953867	299.986908
-0.0800429321289063	-0.0367066636328197	299.9872589
-0.013373171997070301	-0.0288593036286977	299.9872437
0.0189072681427002	0.0145671912894603	299.98713685
0.0686497772216797	0.029725884770886998	299.9867096
0.125036584472656	0.037980684069503	299.98750305
0.172576623535156	0.041963139565894196	299.98669435
0.227899145507813	0.046176560924485105	299.9877319
0.27172921142578105	0.046893441721118895	299.9873352
0.319686450195313	0.048028322646850696	299.9878845
0.383654846191406	0.0495341898165587	299.9892273
0.423015283203125	0.0496481317341207	299.9892578
0.46821506347656205	0.0497096887663672	299.98968505
0.522150927734375	0.0499174454087003	299.99073795
0.5751212646484379	0.0499545265566602	299.99113465
0.622173046875	0.0492631857548571	299.9914246
0.6829320068359379	0.0486877418894699	299.9918213
0.720194799804687	0.0486380032260636	299.9930725
0.788797265625	0.0474958168025002	299.9933167
0.843667431640625	0.0465907325519176	299.9942017
0.88778427734375	0.046240596339111394	299.99424745
0.928007080078125	0.045178917608055806	299.99476625
0.98484091796875	0.0444861199949062	299.99507145
1.0495361328125	0.0428730182907831	299.9964294
1.08972416992187	0.042577426143962	299.9964142
1.1553961425781298	0.0413071227725583	299.9957275
1.1877072265625	0.0408077482522238	299.99584965
1.2367072265625	0.0389849864006053	299.99613955
1.2866921875	0.0380091242751833	299.9968262
1.3612004394531299	0.036730270686764196	299.9982605
1.40823681640625	0.035681982155473205	299.99789425
1.4562672363281202	0.034337534705922095	299.99891665
1.5052686035156202	0.0337638442033603	299.9983063
1.5591579589843798	0.0317961240803266	299.99823
1.6081572753906201	0.030488768954740002	299.9980316
1.6845673828125	0.0291742020258333	299.9989929
1.71888486328125	0.0293901892621201	299.99795535
1.783569921875	0.0271076675571113	299.9992676
1.83645390625	0.0257741604142578	300.0003662
1.86682080078125	0.024940423143547802	300.0011902
1.9197365234375	0.0238987552254568	300.0009308
1.9696923828125	0.022000781826359103	300.00039675
2.025538671875	0.0209560566036672	300.00076295
2.092144140625	0.019660703679361298	300.0025635
2.1421314453125	0.0182482869754741	300.0028992
2.20286533203125	0.0160663894007436	300.0038147
2.2401533203125	0.0155928938357457	300.00361635
2.3038509765625	0.0136270656977578	300.00415035
2.3597107421875	0.0127003583651298	300.0055084
2.39596904296875	0.0108206025319831	300.00486755
2.442959375	0.0104618068013344	300.00593565
2.49981962890625	0.0088102422308274	300.0067139
2.56446533203125	0.00719206032990193	300.0075073
2.6124640625	0.005013492836421171	300.00819395
2.6604927734375	0.0045936724319727	300.00813295
2.7065953125	0.0034366252860254	300.008667
2.773211328125	0.00202467624051601	300.0097809
2.82712080078125	-0.000644222975255373	300.009552
2.87020927734375	-0.00135049118335609	300.01086425
2.93586064453125	-0.00290875343869779	300.0117493
2.9731046875	-0.004224763701848679	300.01226805
3.01521474609375	-0.00635406180495332	300.01245115
3.0632529296875	-0.00645661185359075	300.0142212
3.13086875	-0.00798605879667538	300.0150757
3.191651953125	-0.009896228289589791	300.0158691
3.23875029296875	-0.012176495960147	300.01585385
3.28093076171875	-0.0126323600675429	300.0157776
3.351559375	-0.0138448988732076	300.0169373
3.4153173828125	-0.0157116828496626	300.0179443
3.445716796875	-0.0176785776846052	300.017334
3.515362890625	-0.019263454592761797	300.0177307
3.5516361328125	-0.0196637785140269	300.0189667
3.598726953125	-0.022030128228166402	300.01779175
3.64876328125	-0.0224915448592132	300.0199585
3.6958419921875	-0.023719553145933	300.01986695
3.7733080078125	-0.0262660179599854	300.0193176
3.81747265625	-0.0276743507921902	300.01927185
3.8645490234375	-0.029859348363341198	300.02082825
3.9106634765625	-0.0299430731771186	300.0198669
3.95380234375	-0.0307908235513721	300.02075195
4.0077720703125	-0.0328431409684758	300.01976015
4.0529458984375	-0.033502995358435095	300.0192871
4.1049330078125	-0.0356339897259964	300.0206299
4.152021484375	-0.037880336152417995	300.01992795
4.2108685546875	-0.038797781968149696	300.0206451
4.2559947265625	-0.0394452941868001	300.01976015
4.3217166015625	-0.0418057111415569	300.0209351
4.35703515625	-0.042435226263899395	300.02075195
4.4051158203125	-0.0432507334066121	300.0218811
4.4590654296875	-0.046000181372184805	300.02174375
4.5110931640625	-0.0473919115036555	300.0223389
4.584670703125	-0.0484258680060121	300.022583
4.6268462890625	-0.0505148568696038	300.02171325
4.675884375	-0.0510241411463263	300.02209475
4.7249369140625	-0.0530901182111446	300.0237732
4.7857349609375	-0.055024305155734504	300.022583
4.8230326171875	-0.055541932201809	300.0229492
4.86814296875	-0.056595468633428396	300.0227661
4.92702265625	-0.0591232023422216	300.0235596
4.9790353515625	-0.060482183451793896	300.02398685
5.0280658203125	-0.06148916431437129	300.0235901
5.0722142578125	-0.06288786118862699	300.0235138
5.1389146484375	-0.0640487024638874	300.0256042
5.1938626953125	-0.0654448550605115	300.0249023
5.2468232421875	-0.0679603190605572	300.0249329
5.3086076171875	-0.0694900751526525	300.0250549
5.3478662109375	-0.07153348676519171	300.02494815
5.411636328125	-0.0715008317425072	300.0249634
5.444980078125	-0.0736658077139328	300.02656555
5.498948046875	-0.0753387737188164	300.0261078
5.5538427734375	-0.0767859855982181	300.0268555
5.5979984375	-0.0777372623323077	300.0255432
5.664693359375	-0.0796080598567463	300.0268555
5.71179765625	-0.081491971446174	300.02642825
5.766744140625	-0.08136468283715799	300.0247803
5.8050080078125	-0.0831185219477737	300.02565
5.8511392578125	-0.0853644829518278	300.0256653
5.9060802734375	-0.0867737802374704	300.0253601
5.9551353515625	-0.0873912280490556	300.02493285
6.005159375	-0.0899780580913805	300.02487185
6.0659693359375	-0.09056303580939741	300.0260925
6.119923828125	-0.0919533122716172	300.026947
6.155251953125	-0.09372668035414959	300.02752685
6.205266796875	-0.0959955972186529	300.0275879
6.2572935546875	-0.0973060847404405	300.0284729
6.3240341796875	-0.0981531210752045	300.0300293
6.364258984375	-0.10046945976432299	300.03155515
6.418203515625	-0.10224925469079299	300.03244015
6.4888279296875	-0.103558766274371	300.0334167
6.534937890625	-0.104879421222375	300.0355835
6.6006546875	-0.10607239812736	300.0371094
6.652640234375	-0.107971222840359	300.0373535
6.690919140625	-0.10957379470574999	300.03889465
6.758603125	-0.111662362603378	300.0391846
6.795883984375	-0.112311217859712	300.0395355
6.841027734375	-0.114908100723748	300.0409241
6.888108984375	-0.115046310400574	300.041687
6.934219921875	-0.116706644179298	300.0412445
7.001889453125	-0.11854373359197201	300.0417786
7.048040234375	-0.120791311382246	300.0437622
7.08823203125	-0.121585175872794	300.04341125
7.133369921875	-0.12316356300678	300.04426575
7.186340625	-0.124368999045055	300.04325865
7.23635	-0.126203293862271	300.0432892
7.30013515625	-0.127109956957899	300.0416565
7.3628703125	-0.12909162904470597	300.0420227
7.40114375	-0.130867646590213	300.0423126
7.451153515625	-0.132115233351285	300.04200745
7.5158984375	-0.133595484957498	300.0399475
7.5512125	-0.135060606539298	300.04136655
7.621909375	-0.137729368826422	300.0396729
7.666022265625	-0.139452504539449	300.03877255
7.717036328125	-0.140055583437761	300.03814695
7.7660796875	-0.142021673241408	300.0375824
7.8200359375	-0.14393738882417398	300.0374603
7.86809609375	-0.143772152387149	300.03765865
7.927944921875	-0.14660042695282802	300.03590395
7.9799234375	-0.148372516676321	300.0358734
8.049597265625	-0.149747334142693	300.0343628
8.087870703125	-0.151453070276267	300.0354767
8.148684765625	-0.153336785277996	300.0336609
8.18204921875	-0.154338410133242	300.0359192
8.2369609375	-0.15535281724469002	300.0341339
8.290928125	-0.158383952315291	300.03627015
8.338001171875	-0.159359348641266	300.03570555
8.388037890625	-0.164616952244479	300.03486635
8.436083984375	-0.16121182268162002	300.03573605
8.5008625	-0.164076362906486	300.0354614
8.553833203125	-0.16570138876377	300.0359192
8.584246484375	-0.166952195269047	300.035614
8.640144140625	-0.16744109150544598	300.03637695
8.68917578125	-0.16927911385782402	300.0356903
8.742162890625	-0.171432489415243	300.0377655
8.791209765625	-0.172232715474895	300.0379791
8.85889375	-0.173636425105905	300.0380859
8.892234375	-0.176181257822597	300.03840635
8.9589671875	-0.177198671032396	300.0379639
8.9999484375	-0.179026094687201	300.0380249