File: data/doubleLayers/monolayer/ppms/DD205_4/plots/DD205_8_extracted.dat
#Loading data from ../rawdata/DD205_4_HYST_100OE_300K.DAT
#
#Found columns:
#Comment
#Time Stamp (sec)
#Temperature (K)
#Magnetic Field (Oe)
#Moment (emu)
#M. Std. Err. (emu)
#Transport Action
#Averaging Time (sec)
#Frequency (Hz)
#Peak Amplitude (mm)
#Center Position (mm)
#Coil Signal' (mV)
#Coil Signal" (mV)
#Range (mV)
#M. Quad. Signal (emu)
#M. Raw' (emu)
#M. Raw" (emu)
#Min. Temperature (K)
#Max. Temperature (K)
#Min. Field (Oe)
#Max. Field (Oe)
#Mass (grams)
#Motor Lag (deg)
#Pressure (Torr)
#VSM Status (code)
#Motor Status (code)
#Measure Status (code)
#Measure Count
#System Temp. (K)
#Temp. Status (code)
#Field Status (code)
#Chamber Status (code)
#Motor Current (amps)
#Motor Heatsink Temp. (C)
#Map 01
#Map 02
#Map 03
#Map 04
#Map 05
#Map 06
#Map 07
#Map 08
#Map 09
#Map 10
#Map 11
#Map 12
#Map 13
#Map 14
#Map 15
#Map 16
#
#Transformed data from column 'Moment (emu)' from emu to memu by multiplication with 1000.
#Transformed data from column 'Magnetic Field (Oe)' from Oe to Tesla by division with 10000.
#Loaded 8970 datapoints.
#Loading Magnetic Field (Oe) and Moment (emu)
#Running linear fit between B=(6.001591015625 .. 8.9994171875) with LM algorithm.
#[[Fit Statistics]]
#    # fitting method   = leastsq
#    # function evals   = 6
#    # data points      = 1791
#    # variables        = 2
#    chi-square         = 9.9737e-04
#    reduced chi-square = 5.5750e-07
#    Akaike info crit   = -25788.0509
#    Bayesian info crit = -25777.0698
#[[Variables]]
#    m: -0.03751714 +/- 2.0360e-05 (0.05%) (init = -0.0384681)
#    b:  0.04813220 +/- 1.5373e-04 (0.32%) (init = 0.05490392)
#[[Correlations]] (unreported correlations are < 0.100)
#    C(m, b) = -0.993
#Running linear fit between B=(-8.99919296875 .. -6.0018357421875) with LM algorithm.
#[[Fit Statistics]]
#    # fitting method   = leastsq
#    # function evals   = 6
#    # data points      = 1197
#    # variables        = 2
#    chi-square         = 4.4933e-04
#    reduced chi-square = 3.7601e-07
#    Akaike info crit   = -17706.0095
#    Bayesian info crit = -17695.8344
#[[Variables]]
#    m: -0.03751104 +/- 2.0459e-05 (0.05%) (init = -0.03751714)
#    b: -0.04791005 +/- 1.5449e-04 (0.32%) (init = -0.0481322)
#[[Correlations]] (unreported correlations are < 0.100)
#    C(m, b) =  0.993
#Mean diamagnetic slope: -0.03751469660050949 +/- 1.4700337799239137e-05
#Exporting data to DD205_8_extracted.dat
#
#B / T	M / memu	T / K
1.33077308535576e-05	0.000298242143938216	300.254486083984
0.0419248657226562	0.0159869403786552	300.297958374023
0.0921234802246094	0.0199111700414438	300.323120117188
0.141836956787109	0.0204489255672806	300.342971801758
0.192101239013672	0.0207721847790923	300.359115600586
0.241549877929687	0.021175216437335703	300.370758056641
0.291991357421875	0.0195440470359822	300.372787475586
0.34145899658203105	0.0195982286863513	300.374969482422
0.39198311767578103	0.019078741345894	300.385162353516
0.44143674316406295	0.0183816395147877	300.396697998047
0.49189890136718795	0.017768872864031	300.407104492188
0.5411742919921879	0.015874723668183	300.416458129883
0.59189892578125	0.0149430700020167	300.422668457031
0.6416268310546871	0.013473771103317699	300.426406860352
0.6913689697265629	0.0124353442870726	300.430648803711
0.7411603515625	0.0111248151259484	300.435943603516
0.790901318359375	0.00917711085666623	300.439865112305
0.84114462890625	0.00816987389425108	300.442520141602
0.890922265625	0.00681244326029889	300.443618774414
0.941669140625	0.0048616211389031294	300.447616577148
0.99115869140625	0.00390850192042086	300.449996948242
1.04089194335938	0.00180798645854548	300.451965332031
1.09089755859375	0.00067712884241936	300.4541015625
1.1408854003906201	-0.00136533750853172	300.455627441406
1.1908715332031201	-0.00316876000297998	300.456604003906
1.24165791015625	-0.00431828289555382	300.456619262695
1.29090170898438	-0.0062644710362795	300.457138061523
1.3411453613281201	-0.00733182877005802	300.457366943359
1.3913751953125	-0.009550238659981522	300.458602905273
1.4408819824218702	-0.0114207801650269	300.456893920898
1.49112138671875	-0.0125079503579412	300.456924438477
1.54111318359375	-0.0147240227490191	300.45686340332
1.59112265625	-0.0167044975985946	300.45491027832
1.64113994140625	-0.0182863114919771	300.453750610352
1.69087939453125	-0.0202704335034299	300.453811645508
1.74037841796875	-0.0217328243506705	300.454971313477
1.79042392578125	-0.0234769063737605	300.452972412109
1.8409087890625	-0.0252849337480015	300.452514648438
1.89089814453125	-0.0263924381245986	300.449569702148
1.94039697265625	-0.0288510887784462	300.448059082031
1.99068310546875	-0.0304358795851456	300.446334838867
2.0404212890625	-0.0316296186952666	300.445404052734
2.0904298828125	-0.035060147048006904	300.444412231445
2.14023251953125	-0.035611067098847	300.441192626953
2.190959375	-0.0368912094038523	300.438400268555
2.24019482421875	-0.0393378895174216	300.437866210937
2.2909439453125	-0.0413212996618537	300.436157226562
2.3399947265625	-0.0433293051496451	300.434020996094
2.39097041015625	-0.0439922840853988	300.430923461914
2.44071787109375	-0.0458992298217374	300.427764892578
2.49047353515625	-0.0489402723206124	300.426116943359
2.54070537109375	-0.050547051877659704	300.422500610352
2.59094931640625	-0.0513534747132038	300.423233032227
2.6400927734375	-0.053016093571014	300.421508789063
2.69032607421875	-0.0555150763919703	300.417373657227
2.74124453125	-0.057895218331742	300.415176391602
2.7904109375	-0.0588264037765252	300.413635253906
2.8408572265625	-0.0608936218306784	300.409255981445
2.89053408203125	-0.0629481876976007	300.408203125
2.94097080078125	-0.06475008559669711	300.404891967773
2.99114384765625	-0.0666114235804497	300.403350830078
3.04138076171875	-0.0674952532448158	300.400543212891
3.0915705078125	-0.0704013265987483	300.398529052734
3.14224599609375	-0.07157117276827109	300.395538330078
3.1919828125	-0.0739140295119572	300.391342163086
3.24291318359375	-0.0750159228731743	300.38948059082
3.29310390625	-0.0762068299116335	300.387603759766
3.3422708984375	-0.0791728704073329	300.386016845703
3.39300625	-0.0797677051312662	300.382720947266
3.4429357421875	-0.0828791866877145	300.38117980957
3.4926134765625	-0.0839161621613118	300.376983642578
3.5438568359375	-0.0858966010613999	300.372970581055
3.5937939453125	-0.0882627747064262	300.372924804687
3.6432298828125	-0.0895980041540653	300.367980957031
3.693905859375	-0.0917471591409529	300.366165161133
3.7443849609375	-0.093141809347256	300.363784790039
3.7938076171875	-0.0955613048170533	300.361968994141
3.8437484375	-0.0974073293153296	300.358276367188
3.894691015625	-0.098429849397614	300.359039306641
3.9441197265625	-0.100190304194813	300.354904174805
3.994801953125	-0.10224373586609001	300.351181030273
4.0444927734375	-0.10476845648363299	300.347549438477
4.0947150390625	-0.106456494705073	300.346832275391
4.1453884765625	-0.107298741745879	300.34228515625
4.19508828125	-0.109696620342579	300.342208862305
4.245505078125	-0.11182155350515499	300.339538574219
4.2951951171875	-0.11388192416605501	300.336761474609
4.3453716796875	-0.11505278059660899	300.333892822266
4.3958111328125	-0.117032769403973	300.330993652344
4.4457828125	-0.119075571557531	300.329650878906
4.4957068359375	-0.121085757769013	300.326126098633
4.54614453125	-0.123204726768159	300.324157714844
4.596078515625	-0.12450122471512799	300.322052001953
4.646817578125	-0.126811434861411	300.320938110352
4.696741015625	-0.128483192045311	300.316513061523
4.747176171875	-0.13110392526091	300.31462097168
4.7974158203125	-0.131262316285855	300.313385009766
4.847574609375	-0.133333883309445	300.310974121094
4.8977654296875	-0.136142777976751	300.307388305664
4.9471970703125	-0.13751226369893402	300.306396484375
4.99819296875	-0.13946216728946	300.302856445313
5.04811953125	-0.141275238163754	300.30241394043
5.0983001953125	-0.14362643041245102	300.297668457031
5.1477814453125	-0.14452157916980202	300.295806884766
5.198709765625	-0.14686839604922	300.293762207031
5.2487447265625	-0.14895569275964599	300.293014526367
5.300560546875	-0.150670308207452	300.291870117188
5.349863671875	-0.152521586398047	300.289749145508
5.4006677734375	-0.153987391142948	300.285614013672
5.4507134765625	-0.156131194849947	300.282150268555
5.5018203125	-0.158579799889376	300.281555175781
5.5521224609375	-0.159948462206146	300.279907226562
5.6024203125	-0.16223692059223	300.278244018555
5.6527126953125	-0.163663772792713	300.275192260742
5.704301953125	-0.16598357148655	300.27360534668
5.75408671875	-0.167222552657177	300.270401000977
5.8048875	-0.168687148096868	300.268112182617
5.8552509765625	-0.17063463907903	300.267639160156
5.9055419921875	-0.17320636603254	300.265197753906
5.956602734375	-0.175964718024288	300.263000488281
6.00740546875	-0.17755680432313298	300.260711669922
6.058280078125	-0.179088193193501	300.258193969727
6.1075708984375	-0.180721811217265	300.257202148438
6.1588791015625	-0.182256861017475	300.256729125977
6.208984375	-0.184233171698063	300.254165649414
6.2595328125	-0.18677086560877898	300.251815795898
6.3098267578125	-0.18760764263781401	300.249099731445
6.3603755859375	-0.190701174899715	300.247161865234
6.41099921875	-0.192672253626989	300.246856689453
6.4623109375	-0.193359156667889	300.244247436523
6.5121111328125	-0.195039509206964	300.243041992188
6.562715234375	-0.197292324520567	300.239685058594
6.613009765625	-0.199602261433654	300.23974609375
6.66406796875	-0.201896913140117	300.238128662109
6.714112109375	-0.20240312706491	300.234680175781
6.764423046875	-0.205421573461657	300.232574462891
6.814984765625	-0.207310281276531	300.232986450195
6.865539453125	-0.209416458426466	300.231475830078
6.916137109375	-0.21229398171627	300.227478027344
6.9666921875	-0.213021885996238	300.22575378418
7.01723515625	-0.21498659216786	300.224838256836
7.067787109375	-0.216043099592443	300.223220825195
7.119129296875	-0.218871402927742	300.223266601562
7.16941953125	-0.219560729228177	300.221298217773
7.219465625	-0.22141932875008	300.217514038086
7.2708390625	-0.22443751343418097	300.218185424805
7.3208875	-0.226027604687283	300.215469360352
7.37093203125	-0.228149594712495	300.214599609375
7.422490234375	-0.230064051859257	300.211563110352
7.472860546875	-0.23132378241017099	300.209594726562
7.522404296875	-0.23411353240928498	300.208435058594
7.57320234375	-0.234509981433591	300.207992553711
7.623560546875	-0.235879341277074	300.205169677734
7.67436875	-0.239175523801647	300.203659057617
7.72541640625	-0.241189509778233	300.202133178711
7.7752171875	-0.24250029246211802	300.199752807617
7.826854296875	-0.244636510063286	300.197799682617
7.87640078125	-0.248040448305962	300.197708129883
7.926944140625	-0.24884175502981598	300.195556640625
7.978058984375	-0.252044591833804	300.195129394531
8.02811640625	-0.25220895163907103	300.195266723633
8.078409765625	-0.254591192324167	300.192489624023
8.12946171875	-0.256934170625703	300.190307617188
8.179782421875	-0.25794240031386	300.188323974609
8.22983046875	-0.25997725633095903	300.187286376953
8.281646875	-0.262710235546168	300.186401367188
8.331233203125	-0.26464367878663897	300.185668945313
8.381542578125	-0.266548458162997	300.182601928711
8.432592578125	-0.268303376848811	300.181045532227
8.482637109375	-0.268752018947644	300.179931640625
8.534226171875	-0.271087431663849	300.177749633789
8.5837640625	-0.27339166996862596	300.17822265625
8.63481484375	-0.27494454250676903	300.176483154297
8.685425	-0.27730156339554096	300.174209594727
8.735725	-0.27860138035986104	300.171966552734
8.786525	-0.281595140412997	300.1728515625
8.836054296875	-0.282731632881419	300.170745849609
8.8869265625	-0.28499699221163804	300.170303344727
8.93723203125	-0.286127429904527	300.168807983398
8.988026953125	-0.289320998877992	300.166152954102
8.9711828125	-0.288835778471788	300.165634155273
8.921707421875	-0.285630264056785	300.163833618164
8.8716546875	-0.285198641106471	300.162490844727
8.821026953125	-0.282515528373919	300.16064453125
8.771471484375	-0.281111474950668	300.160079956055
8.722646484375	-0.278542219304317	300.15885925293
8.672321875	-0.276520504125798	300.158477783203
8.622742578125	-0.274532655392677	300.155166625977
8.573427734375	-0.27264655093876705	300.154647827148
8.52261953125	-0.271373457555436	300.15380859375
8.473294140625	-0.26964160360802497	300.153427124023
8.42373515625	-0.26688399021857295	300.150695800781
8.37416796875	-0.265554587421717	300.148864746094
8.32434140625	-0.262809002939512	300.148818969727
8.27424140625	-0.26239366413702303	300.148010253906
8.224171875	-0.26013356388730197	300.146011352539
8.174613671875	-0.2579085497484	300.145629882812
8.124541015625	-0.256655327595675	300.144332885742
8.074984765625	-0.253939205477578	300.144119262695
8.02541953125	-0.252652782736052	300.14436340332
7.97585546875	-0.250168650035047	300.141708374023
7.92573671875	-0.24925419717127603	300.140533447266
7.8751828125	-0.24788293036613201	300.139221191406
7.826616015625	-0.24578308213933597	300.137817382812
7.776475	-0.24335691269785098	300.137176513672
7.72667578125	-0.241908742550824	300.136688232422
7.676612890625	-0.23977185510072402	300.135894775391
7.62730078125	-0.237708367805776	300.134490966797
7.57693515625	-0.23570669015467902	300.132720947266
7.52736484375	-0.23361413433478698	300.130950927734
7.477563671875	-0.232113266679374	300.129760742188
7.427942578125	-0.230000364863082	300.128768920898
7.377875390625	-0.228700225382663	300.129241943359
7.32806015625	-0.22666262054691202	300.127517700195
7.278247265625	-0.225096735648579	300.127105712891
7.228888671875	-0.223648641849314	300.125854492188
7.17907265625	-0.221021041847229	300.12532043457
7.12950078125	-0.218777194246455	300.125305175781
7.079183984375	-0.218627433311602	300.12419128418
7.029126953125	-0.21587690634892398	300.1220703125
6.980056640625	-0.21286315742981698	300.121490478516
6.930486328125	-0.210877052780646	300.119842529297
6.879903515625	-0.209208558438714	300.121017456055
6.830587109375	-0.209080004699276	300.119827270508
6.78077265625	-0.206087732744865	300.117706298828
6.730712109375	-0.20488768033351898	300.116577148438
6.681391015625	-0.20141970299221498	300.116104125977
6.631080859375	-0.200643343586074	300.114471435547
6.581516796875	-0.198473447146465	300.113052368164
6.531904296875	-0.196509412554814	300.112411499023
6.4820939453125	-0.19522019126719098	300.11296081543
6.4322771484375	-0.191861344381508	300.110870361328
6.382466015625	-0.190744282813781	300.110549926758
6.3318541015625	-0.188611940093394	300.110076904297
6.282787890625	-0.187249012031092	300.109878540039
6.232733203125	-0.18545183720186598	300.109268188477
6.1823744140625	-0.183334868047417	300.106918334961
6.1328078125	-0.181805983449098	300.106170654297
6.0829984375	-0.179394896996516	300.105697631836
6.03344375	-0.17744537791631998	300.10710144043
5.9835642578125	-0.176388720521166	300.104705810547
5.9337525390625	-0.174149094221145	300.102844238281
5.8846880859375	-0.173033183715602	300.101638793945
5.834586328125	-0.170459565568934	300.100692749023
5.7845236328125	-0.16871105520513802	300.100082397461
5.7344591796875	-0.167091611688658	300.099792480469
5.685150390625	-0.164649173783771	300.099594116211
5.6353287109375	-0.163423982469219	300.097930908203
5.585028515625	-0.16118716771926397	300.098648071289
5.5362095703125	-0.160018051735348	300.096908569336
5.4861296875	-0.158698618808398	300.096710205078
5.436545703125	-0.156109084347928	300.096099853516
5.386733984375	-0.154832758536988	300.094955444336
5.3371748046875	-0.152791716978288	300.093078613281
5.287109375	-0.151502677178212	300.094314575195
5.237309765625	-0.14942284780508	300.093612670898
5.1877359375	-0.147183096098036	300.094085693359
5.1376748046875	-0.145294505240123	300.092041015625
5.087826171875	-0.14416632156085002	300.091293334961
5.0382673828125	-0.141651001329142	300.0888671875
4.9877060546875	-0.139345502560706	300.088165283203
4.937837109375	-0.13779588931578302	300.086441040039
4.88778984375	-0.136026288717564	300.088470458984
4.8389630859375	-0.134970341462651	300.086868286133
4.7891595703125	-0.132243881537782	300.087066650391
4.738543359375	-0.13014007129377	300.085205078125
4.689489453125	-0.128213526241637	300.084991455078
4.639434765625	-0.12720838862452	300.084350585937
4.58981171875	-0.12426336304108	300.082717895508
4.540502734375	-0.12259675565332	300.08203125
4.4901982421875	-0.121091147219035	300.082901000977
4.440891015625	-0.119582954681417	300.082656860352
4.390776953125	-0.117591509471516	300.081787109375
4.34021640625	-0.11559101356971099	300.080383300781
4.2909205078125	-0.114120248895034	300.079895019531
4.2415869140625	-0.112349967136572	300.080825805664
4.1907923828125	-0.11109701134953301	300.078323364258
4.141480078125	-0.108758603407454	300.077423095703
4.0921669921875	-0.106870576370826	300.076644897461
4.0425619140625	-0.104653206056704	300.077423095703
3.9927470703125	-0.102801632259051	300.075531005859
3.9431990234375	-0.100838459155869	300.075744628906
3.8921328125	-0.099530421427517	300.074783325195
3.842816015625	-0.09726672314745119	300.073425292969
3.7922595703125	-0.0954478879144362	300.073455810547
3.7434470703125	-0.0934839734128377	300.073104858398
3.694085546875	-0.0920982159401096	300.071731567383
3.643283203125	-0.0905565305812467	300.072738647461
3.5937166015625	-0.0882029253809463	300.072631835937
3.544656640625	-0.08738302008937121	300.070922851562
3.494291015625	-0.0838275646559831	300.06982421875
3.4444869140625	-0.0821576853604276	300.067687988281
3.395178125	-0.0813680939721774	300.067443847656
3.345312890625	-0.0790244584104268	300.068466186523
3.2955046875	-0.0775301409473291	300.067886352539
3.24520283203125	-0.0759294796665629	300.067520141602
3.19613232421875	-0.073016745233252	300.066741943359
3.1465126953125	-0.07206665525580859	300.066787719727
3.0964603515625	-0.06993687859302819	300.065307617188
3.046165625	-0.0681736082172836	300.06462097168
2.9960546875	-0.0661032994509777	300.063995361328
2.9472322265625	-0.0640710510562465	300.063171386719
2.89718271484375	-0.0625928260451106	300.061248779297
2.84687666015625	-0.061088880051090796	300.061218261719
2.7970646484375	-0.0589295416151866	300.061065673828
2.74700361328125	-0.0576287964067776	300.061111450195
2.69744638671875	-0.0563500564798997	300.061706542969
2.64760146484375	-0.053540715340302296	300.058654785156
2.59780283203125	-0.0521170482172622	300.058563232422
2.54848505859375	-0.049544586193270096	300.058532714844
2.49867548828125	-0.048932296880504496	300.058181762695
2.4488685546875	-0.0467632882335298	300.057632446289
2.3990744140625	-0.0445483633342834	300.055145263672
2.34975322265625	-0.0431026140935426	300.056045532227
2.30018486328125	-0.041665599265771104	300.055419921875
2.25010224609375	-0.0400103408120957	300.054489135742
2.20054296875	-0.0370948960431816	300.052871704102
2.149985546875	-0.0348973738592999	300.051742553711
2.10062197265625	-0.035034997405181206	300.052886962891
2.05107294921875	-0.0326229050349994	300.050582885742
2.0005177734375	-0.0303727264441836	300.051391601562
1.95071748046875	-0.0282330773134735	300.05158996582
1.90061103515625	-0.0267247610481023	300.050872802734
1.85205947265625	-0.0258527165289612	300.048919677734
1.80125263671875	-0.0240954354771645	300.050170898438
1.7518853515625	-0.0215739402050229	300.050247192383
1.70283046875	-0.0201341286493574	300.048355102539
1.652784765625	-0.0186322106629581	300.047897338867
1.60298115234375	-0.016277903519188803	300.047561645508
1.55236875	-0.014510665416544501	300.046005249023
1.50331655273438	-0.0131127540405908	300.044311523438
1.453265625	-0.0117583549292957	300.044586181641
1.40320200195313	-0.0100720461145376	300.045928955078
1.3536416503906201	-0.0080698448197021	300.046005249023
1.30359350585938	-0.00603256151028529	300.045379638672
1.25446274414062	-0.0045676430912672495	300.044876098633
1.204516015625	-0.00318177844029031	300.043151855469
1.15463090820312	-0.00105240909218945	300.04231262207
1.1047244140625	0.00035157842179464203	300.041137695313
1.05506845703125	0.0018039091340777	300.042770385742
1.00442797851562	0.00302709198853845	300.042617797852
0.954522265625	0.004626811947680169	300.041961669922
0.904887646484375	0.0062593709094843596	300.043563842773
0.855442822265625	0.00873460915885609	300.041656494141
0.805044189453125	0.00909308309633391	300.038864135742
0.7558927490234371	0.0108255771327942	300.039367675781
0.70597041015625	0.012329345207698	300.04069519043
0.656051220703125	0.0141714638016644	300.040435791016
0.605351123046875	0.0146944059068453	300.039215087891
0.5561608154296871	0.016033887967524002	300.03874206543
0.506165185546875	0.017469576058104	300.038330078125
0.45648483886718794	0.0185218922734237	300.040435791016
0.40628021240234397	0.019950477869101303	300.038818359375
0.356338647460937	0.0200753416738826	300.036972045898
0.291332275390625	0.020683762110451802	300.036987304687
0.240875439453125	0.0212617852392369	300.037551879883
0.19090542602539098	0.0207144594037568	300.03630065918
0.141880395507812	0.021109596789089902	300.037063598633
0.09113980712890629	0.0194071996544321	300.037033081055
0.0411696655273438	0.0173660293746543	300.036468505859
-0.0238488586425781	-0.00942897054942923	300.036499023438
-0.0732574615478516	-0.0170722279709446	300.035858154297
-0.12297355346679699	-0.0197946404583393	300.035202026367
-0.173174920654297	-0.0204826064514542	300.033782958984
-0.2229130859375	-0.0205932399345669	300.033203125
-0.273373571777344	-0.021618759593769	300.034896850586
-0.322860424804687	-0.0204725347364398	300.034210205078
-0.372900695800781	-0.0199912925819167	300.033248901367
-0.4379150390625	-0.018101978604763203	300.033004760742
-0.487891918945313	-0.0178210105203164	300.034210205078
-0.538681884765625	-0.016977327847150402	300.035079956055
-0.588420849609375	-0.015517887748737	300.033584594727
-0.637913916015625	-0.014605452958797099	300.031555175781
-0.687641772460937	-0.013276847066167	300.030670166016
-0.737695458984375	-0.011818909632271	300.030044555664
-0.787686767578125	-0.00986020817317567	300.031234741211
-0.837423974609375	-0.009050709270584389	300.03141784668
-0.887430322265625	-0.007649882389710341	300.030883789063
-0.952455810546875	-0.00455618256987844	300.031814575195
-1.0029339355468798	-0.00417784040274197	300.032073974609
-1.052915625	-0.0020357076576608	300.030502319336
-1.10295864257813	-0.000838292912195624	300.029479980469
-1.15270322265625	0.000710214823829804	300.030517578125
-1.20217158203125	0.0029309385808285703	300.030120849609
-1.2529610839843799	0.00407486366718684	300.027648925781
-1.30320620117188	0.00560887168894668	300.027984619141
-1.35243681640625	0.00728799358610081	300.028259277344
-1.4021623046875	0.0097421990585884	300.028869628906
-1.4526640136718798	0.011274116798014	300.028457641602
-1.50265166015625	0.012952924625243402	300.028701782227
-1.55188129882812	0.0145318410384889	300.027694702148
-1.6019162109375	0.0167406075283064	300.026916503906
-1.6523984375	0.0237100976972298	300.028335571289
-1.702391015625	0.019167429606567702	300.027770996094
-1.75186923828125	0.0215968654444488	300.028686523438
-1.801871484375	0.0229546326692889	300.02702331543
-1.85210703125	0.0254149505970763	300.026626586914
-1.9023474609375	0.0266348311561895	300.025909423828
-1.951859375	0.028450732395089	300.02717590332
-2.00185380859375	0.030137622458831	300.027313232422
-2.0520970703125	0.0324342096060483	300.025329589844
-2.10133330078125	0.034132054291433	300.026000976562
-2.151620703125	0.034755858019574204	300.027893066406
-2.20160341796875	0.0373286851491821	300.026138305664
-2.251846875	0.038892280760644	300.025421142578
-2.3015912109375	0.040676938754047605	300.025085449219
-2.3516123046875	0.042830561237979396	300.024765014648
-2.4015845703125	0.0443947527844727	300.024658203125
-2.45157705078125	0.046918211511932796	300.025283813477
-2.5013734375	0.0482597495870732	300.02409362793
-2.551346875	0.0496479744937329	300.024444580078
-2.60184951171875	0.0517496628519405	300.023422241211
-2.65226962890625	0.0539503789221371	300.023406982422
-2.70198095703125	0.055573129715638596	300.023590087891
-2.7518943359375	0.0573806520843259	300.023818969727
-2.80181396484375	0.0593417258116508	300.023010253906
-2.852	0.0601924393135399	300.023178100586
-2.9021626953125	0.063371463758231	300.022521972656
-2.9530802734375	0.0653171298330918	300.021987915039
-3.00224814453125	0.065498659748714	300.021347045898
-3.05322001953125	0.06748235349758999	300.022933959961
-3.10363271484375	0.0696748626629386	300.023574829102
-3.1535515625	0.0725979159314048	300.022567749023
-3.20398173828125	0.0730681391752169	300.020874023438
-3.25339404296875	0.0753234236712355	300.021606445313
-3.3043083984375	0.0774330383555913	300.021224975586
-3.3534810546875	0.07931908275293979	300.021865844727
-3.404454296875	0.08125520672044981	300.023071289063
-3.4538634765625	0.0820424409150057	300.020889282227
-3.5040291015625	0.08514937451519379	300.021682739258
-3.5547654296875	0.0860208635812955	300.019866943359
-3.604182421875	0.0889644618280929	300.019805908203
-3.6545916015625	0.089900017298073	300.021942138672
-3.7047572265625	0.09197231393428959	300.021911621094
-3.75523125	0.0937269899518111	300.022338867188
-3.8051521484375	0.09634103734799901	300.0205078125
-3.855807421875	0.0971499641387694	300.020568847656
-3.905026953125	0.0992146433267635	300.019653320313
-3.9549564453125	0.10173658258446401	300.020416259766
-4.0063693359375	0.103491780094801	300.019409179687
-4.055528515625	0.10463655170231301	300.019470214844
-4.106259765625	0.106232013292934	300.020080566406
-4.155918359375	0.10856850935306399	300.020797729492
-4.2060826171875	0.110635653778236	300.018936157227
-4.2562541015625	0.11242038419941	300.019287109375
-4.3066765625	0.11400182642576501	300.019226074219
-4.3573486328125	0.115525606997187	300.018417358398
-4.406760546875	0.11809512225908601	300.018264770508
-4.457473828125	0.120841323972448	300.018447875977
-4.507133984375	0.120841552262198	300.017974853516
-4.5568185546875	0.12400174792587601	300.018615722656
-4.6069794921875	0.12480505325742801	300.019897460937
-4.657161328125	0.128394809533555	300.019927978516
-4.7083201171875	0.12877024980315702	300.017501831055
-4.7582439453125	0.130252094352224	300.016815185547
-4.808210546875	0.133307421935907	300.016220092773
-4.85786953125	0.13519893390602902	300.017440795898
-4.90778515625	0.136456885061395	300.018493652344
-4.9587390625	0.137249242390627	300.017700195313
-5.0089244140625	0.139961170105002	300.015182495117
-5.0583505859375	0.14189264187141898	300.015853881836
-5.1085111328125	0.14407785656229	300.018585205078
-5.1587298828125	0.144881126792826	300.018753051758
-5.2092224609375	0.147125501811095	300.017700195313
-5.2600138671875	0.15037575822253998	300.015228271484
-5.310811328125	0.151717637855679	300.016738891602
-5.360633984375	0.153433237033577	300.016036987305
-5.41168125	0.154858003450414	300.016021728516
-5.46171015625	0.158040317024422	300.017181396484
-5.512045703125	0.15992197362836502	300.017105102539
-5.56256796875	0.161734242512897	300.015533447266
-5.614387890625	0.16296011819106798	300.015594482422
-5.6636494140625	0.164383254210448	300.015853881836
-5.7147025390625	0.166399630116786	300.015167236328
-5.7644880859375	0.168976602014534	300.016265869141
-5.8152939453125	0.171130257939222	300.015228271484
-5.86587734375	0.172246105143004	300.015426635742
-5.916416015625	0.17343984945552499	300.013198852539
-5.9664646484375	0.175949515668569	300.014175415039
-6.0172599609375	0.17675792077602298	300.015243530273
-6.06806875	0.17980538615319602	300.01481628418
-6.11937734375	0.181368070264018	300.01448059082
-6.1686564453125	0.183577199498351	300.014739990234
-6.22000703125	0.185596998866374	300.015884399414
-6.269531640625	0.187235438603637	300.01530456543
-6.3208369140625	0.189301815948424	300.014175415039
-6.3711306640625	0.190266863063217	300.014221191406
-6.4219857421875	0.19382067374418202	300.013320922852
-6.47278828125	0.195058463655917	300.013565063477
-6.52256484375	0.19609876490060602	300.014419555664
-6.57315859375	0.197781835240114	300.01432800293
-6.623442578125	0.20109285786379902	300.013916015625
-6.674998046875	0.20256552625044	300.012496948242
-6.724524609375	0.20444652995853402	300.013595581055
-6.776134765625	0.206914064181469	300.014389038086
-6.826182421875	0.20813417426698	300.012878417969
-6.875956640625	0.209785613512976	300.012893676758
-6.92730546875	0.2124756666339	300.013931274414
-6.977832421875	0.212607982570088	300.014862060547
-7.02762734375	0.21638578384398502	300.013381958008
-7.07841953125	0.217498901594375	300.013442993164
-7.128718359375	0.218419967601234	300.012222290039
-7.17924609375	0.22179046176140202	300.012969970703
-7.23029765625	0.22334495473941202	300.012878417969
-7.28037578125	0.22561132069827	300.013137817383
-7.33116171875	0.226532762028827	300.012451171875
-7.38145234375	0.22883309154898301	300.012359619141
-7.43248046875	0.231878398652019	300.011978149414
-7.482273828125	0.232370201985136	300.012054443359
-7.5330734375	0.235566799097319	300.01301574707
-7.584121484375	0.236869209482073	300.01335144043
-7.634209375	0.238550243850886	300.011810302734
-7.68422578125	0.24021710587356399	300.011138916016
-7.73476171875	0.24247176422300398	300.010528564453
-7.785301953125	0.244722832885231	300.010726928711
-7.835906640625	0.24681984903417203	300.012756347656
-7.886441015625	0.24721707870759901	300.011779785156
-7.9369796875	0.250937475506628	300.0107421875
-7.98756796875	0.251973215425354	300.009475708008
-8.038855859375	0.25497161158853704	300.009902954102
-8.088633203125	0.25579148419027703	300.010498046875
-8.1394234375	0.25706827040583	300.010604858398
-8.19001484375	0.259823407290734	300.011734008789
-8.2405453125	0.260896194598181	300.010314941406
-8.2908203125	0.26241695999579	300.009994506836
-8.340912890625	0.266883501373079	300.011260986328
-8.391441015625	0.268141112783707	300.011199951172
-8.44197578125	0.269097579090437	300.010223388672
-8.492513671875	0.26980903581144805	300.009719848633
-8.54305625	0.27275226860814	300.008087158203
-8.5935953125	0.274809682260897	300.00993347168
-8.64387421875	0.276808336720319	300.010757446289
-8.6947171875	0.27762372278264996	300.011047363281
-8.745244921875	0.279792588803359	300.00944519043
-8.796793359375	0.28146912069761204	300.009658813477
-8.846327734375	0.284066539037932	300.010131835937
-8.897619140625	0.286192949171021	300.009719848633
-8.947162109375	0.287559038247328	300.009292602539
-8.99870078125	0.287001395494977	300.010772705078
-8.959780078125	0.288095501051217	300.009552001953
-8.910512109375	0.287017238117578	300.007263183594
-8.86172421875	0.283737771943059	300.009063720703
-8.81141875	0.283976879709423	300.01025390625
-8.76163046875	0.27997863175103704	300.010131835937
-8.7120828125	0.278044931454097	300.008148193359
-8.662233203125	0.27616184722820997	300.009033203125
-8.612691015625	0.275297980568598	300.008743286133
-8.56315234375	0.273478779905699	300.010543823242
-8.51286015625	0.27044839708075097	300.009613037109
-8.46328203125	0.268166930126319	300.007202148438
-8.413254296875	0.26651226685597	300.008377075195
-8.3642171875	0.266640555810279	300.00862121582
-8.313623046875	0.264021307701936	300.007965087891
-8.26457734375	0.261819343877073	300.007934570313
-8.214525390625	0.259873188846146	300.008880615234
-8.164251171875	0.258616224499492	300.009414672852
-8.11514609375	0.25628458576944396	300.007125854492
-8.064601171875	0.254096689643122	300.007125854492
-8.015062109375	0.253806479049512	300.00749206543
-7.9654703125	0.25083333717280804	300.008041381836
-7.915665625	0.24936519481151997	300.008453369141
-7.865867578125	0.246596662605516	300.008728027344
-7.816340625	0.245071316078837	300.007171630859
-7.76673203125	0.243134199026433	300.006866455078
-7.71718515625	0.241521977747291	300.006881713867
-7.666892578125	0.23973287699613	300.007675170898
-7.617580859375	0.23671232894486502	300.008590698242
-7.566514453125	0.236993541704411	300.007019042969
-7.517451171875	0.234230308824793	300.00553894043
-7.4679109375	0.231400204254867	300.007141113281
-7.41760234375	0.229778847051776	300.006683349609
-7.3683125	0.227841217965962	300.007415771484
-7.318265234375	0.2260246459316	300.006484985352
-7.2689703125	0.22552362411948298	300.006774902344
-7.219125390625	0.222400481824759	300.007263183594
-7.169323046875	0.22132837971131603	300.007095336914
-7.11927578125	0.218214193863912	300.00862121582
-7.0699765625	0.217484836255459	300.007873535156
-7.020173828125	0.215194984580214	300.007690429687
-6.97013203125	0.21337556495703702	300.006927490234
-6.9200828125	0.211073758984365	300.006362915039
-6.870986328125	0.210201152897077	300.005004882812
-6.820938671875	0.207283161418255	300.007186889648
-6.771146484375	0.20596324198636798	300.008010864258
-6.721292578125	0.204386588756999	300.006622314453
-6.671723828125	0.202062619078626	300.006927490234
-6.621928125	0.199279171949452	300.005432128906
-6.57140078125	0.198083703614481	300.006378173828
-6.522291796875	0.197121958033383	300.005966186523
-6.47274453125	0.194539641793832	300.006256103516
-6.42269296875	0.19284459926721	300.006484985352
-6.3728416015625	0.190828931878435	300.005767822266
-6.3220369140625	0.189298495214897	300.006683349609
-6.2724771484375	0.186798934889338	300.00651550293
-6.2226828125	0.185647489012047	300.006942749023
-6.1730853515625	0.184058050514803	300.005569458008
-6.1240404296875	0.181432224462502	300.003967285156
-6.0737416015625	0.17960516449264602	300.004989624023
-6.0246705078125	0.177997600004913	300.007110595703
-5.9743626953125	0.17608295225314702	300.006378173828
-5.925058984375	0.174004796429927	300.006637573242
-5.8750076171875	0.171223492765096	300.004638671875
-5.8251634765625	0.17010880159383301	300.005813598633
-5.7753705078125	0.168589126554602	300.005004882812
-5.725569140625	0.167068635631137	300.004180908203
-5.6755193359375	0.165018565575396	300.004913330078
-5.6262013671875	0.16300034027492	300.004577636719
-5.576669921875	0.16239153647574	300.005767822266
-5.5256328125	0.15861443381093202	300.005935668945
-5.476278125	0.157870887236172	300.004058837891
-5.42648984375	0.155663763850936	300.006195068359
-5.3776884765625	0.15344677342943	300.006225585937
-5.3271587890625	0.153075513715094	300.004302978516
-5.277553515625	0.150256123954967	300.004745483398
-5.2282544921875	0.148494658005879	300.005554199219
-5.1784666015625	0.146036056050088	300.005111694336
-5.127629296875	0.145205446516789	300.004180908203
-5.07833125	0.143060796384986	300.005844116211
-5.029033203125	0.140617983497208	300.005935668945
-4.9787501953125	0.139023765799171	300.005111694336
-4.9291369140625	0.137109254179569	300.00553894043
-4.878841796875	0.136302342416741	300.004440307617
-4.8295412109375	0.133310105792635	300.003204345703
-4.779458984375	0.132106050806595	300.004730224609
-4.730153125	0.130771479709491	300.005187988281
-4.6801001953125	0.128637621825709	300.004837036133
-4.6303091796875	0.12530304323647098	300.005126953125
-4.5810083984375	0.124323992960301	300.004867553711
-4.5312234375	0.121867080033049	300.004287719727
-4.4816630859375	0.121018953064824	300.003921508789
-4.43187265625	0.118565746748077	300.003860473633
-4.382033984375	0.117338304646934	300.004730224609
-4.331492578125	0.115677736873112	300.00390625
-4.2824328125	0.113691550963493	300.003723144531
-4.2326181640625	0.11077919756791099	300.005264282227
-4.1828369140625	0.11020751290735299	300.00520324707
-4.13330078125	0.108068868030224	300.00456237793
-4.082508203125	0.106585256242934	300.003402709961
-4.0336560546875	0.103988794155435	300.004165649414
-3.9826298828125	0.100866706255311	300.004196166992
-3.9338255859375	0.100510986010692	300.00422668457
-3.883219921875	0.0991338665392912	300.004409790039
-3.83392265625	0.0970797745776542	300.004440307617
-3.7843787109375	0.0942467992350791	300.003875732422
-3.7343361328125	0.09320289539968349	300.002456665039
-3.6849888671875	0.0915404072092027	300.004501342773
-3.63545078125	0.09000123878966179	300.004989624023
-3.5848990234375	0.0871869339143782	300.005737304687
-3.5357974609375	0.0854833043505654	300.003890991211
-3.4859994140625	0.0839027278287095	300.002853393555
-3.4364505859375	0.0833746351714926	300.003128051758
-3.38642109375	0.08067705628098651	300.003799438477
-3.335816015625	0.07854953156439419	300.004211425781
-3.2867662109375	0.0772087386380054	300.004837036133
-3.23671865234375	0.0741567370222395	300.003982543945
-3.1876646484375	0.07343552547314461	300.004348754883
-3.13761865234375	0.0708047211212083	300.003753662109
-3.08781826171875	0.0692114974353461	300.004684448242
-3.0375134765625	0.06822220698536391	300.003875732422
-2.9884337890625	0.06565423589280979	300.003509521484
-2.9386359375	0.0643376758216876	300.003555297852
-2.8888455078125	0.0624745261727831	300.002731323242
-2.8390419921875	0.060763513149761396	300.002243041992
-2.7887408203125	0.0584632882054301	300.004608154297
-2.7394439453125	0.0576810325067578	300.005126953125
-2.68964951171875	0.054082222725355296	300.003921508789
-2.6397884765625	0.05262112962131189	300.002807617188
-2.5900048828125	0.051478210393627495	300.003326416016
-2.53945498046875	0.0493345537087952	300.004852294922
-2.49065126953125	0.047301121624338506	300.003402709961
-2.440794140625	0.0459523678268252	300.003005981445
-2.39026572265625	0.0438557247701431	300.002029418945
-2.34021376953125	0.0419394542437586	300.002960205078
-2.2916041015625	0.0400820196017224	300.003173828125
-2.2418125	0.038698518482032804	300.002700805664
-2.1920033203125	0.0368754384018404	300.002838134766
-2.1419642578125	0.034873714464237995	300.003692626953
-2.0918595703125	0.0328880241215616	300.002670288086
-2.04205	0.031094747965103302	300.002899169922
-1.99250087890625	0.0300678921584661	300.002380371094
-1.942408203125	0.028329177196932	300.001892089844
-1.89310693359375	0.026440885075503802	300.003372192383
-1.84306162109375	0.0235493327962456	300.004287719727
-1.79351181640625	0.0229787019181432	300.002151489258
-1.743459765625	0.0206482438015812	300.0029296875
-1.69415830078125	0.019674226544785	300.003448486328
-1.64334619140625	0.0172133608865771	300.003173828125
-1.5935208984375	0.0155019992884913	300.002426147461
-1.54395595703125	0.0137346981187549	300.002777099609
-1.4951544921875	0.012512336592918	300.002822875977
-1.4446158691406201	0.010598438086790899	300.001907348633
-1.3945544921875	0.008482564352911639	300.002670288086
-1.3452574707031202	0.00676422157429812	300.003616333008
-1.29593491210938	0.00571762228550549	300.001281738281
-1.24629169921875	0.0039109424210491805	300.001541137695
-1.1961020996093799	0.0017832009588247002	300.002899169922
-1.14621884765625	0.0005289489387617911	300.002914428711
-1.09556708984375	-0.00018197076470373102	300.003021240234
-1.04561865234375	-0.0023098031680894603	300.001708984375
-0.9967259765625	-0.0046848783919897	300.001724243164
-0.9460888671875	-0.00608011455611792	300.001754760742
-0.896689892578125	-0.00710393986962669	300.003494262695
-0.846741015625	-0.008577420410368089	300.001251220703
-0.79735166015625	-0.0100640126882667	300.001922607422
-0.747208764648438	-0.0118933464485832	300.002822875977
-0.696743896484375	-0.0134184596449222	300.002563476562
-0.646845385742188	-0.0140534201133338	300.002456665039
-0.5976601318359379	-0.0160907457139719	300.001098632812
-0.547732006835937	-0.016991063629652702	300.001525878906
-0.497225415039063	-0.018148835029152603	300.002838134766
-0.44703503417968704	-0.019132122265769002	300.001266479492
-0.382338330078125	-0.0202789078109609	300.001342773438
-0.333141064453125	-0.0216436291274029	300.002288818359
-0.282686437988281	-0.0212306453589426	300.000625610352
-0.23321922607421897	-0.0213629626080628	300.001663208008
-0.182495037841797	-0.0217410363979997	299.999969482422
-0.13271891479492198	-0.0221370066800823	300.001251220703
-0.0832491546630859	-0.020125398977328297	300.003143310547
-0.0184772254943848	-0.0128742933232478	300.002807617188
0.0314628112792969	0.010991212604087	300.001754760742
0.0821778228759766	0.017607638693176702	300.001251220703
0.131614331054688	0.0194482217988181	300.002090454102
0.181366809082031	0.0201292506853351	300.001205444336
0.23132183837890602	0.0204563313101435	300.001907348633
0.281528698730469	0.0205293044463315	300.001022338867
0.331034643554687	0.019878269461944098	300.002090454102
0.380715795898438	0.0	300.001022338867
0.446109155273438	0.0176372049078953	300.001235961914
0.49660285644531293	0.0165033922490837	300.001449584961
0.5464055908203129	0.0157517667609405	300.003219604492
0.596133227539063	0.015331365649283701	300.002212524414
0.64612294921875	0.0132338168558408	300.001205444336
0.696101904296875	0.0122918963164911	300.000396728516
0.746665771484375	0.010065019771922201	300.000717163086
0.813924365234375	0.00883985068305191	300.002319335937
0.861144873046875	0.007277902633797	300.002182006836
0.910923291015625	0.0064102059950042695	300.001815795898
0.960910302734375	0.00461682600062645	300.001373291016
1.0116539550781298	0.0028891773912319402	300.001937866211
1.06090346679688	0.0011376853301869598	300.000457763672
1.11088681640625	-0.000132094562162482	300.002151489258
1.16064331054687	-0.00182018028571839	300.000381469727
1.21136025390625	-0.00362508599696224	300.0009765625
1.260898828125	-0.00498164255080745	300.002456665039
1.31113725585938	-0.006879667424038219	300.002151489258
1.36088505859375	-0.00822827485489016	300.002075195313
1.4106306640625	-0.0103668879911285	300.001663208008
1.4608760253906201	-0.011362835681204601	300.00129699707
1.5108658203125	-0.0140582312711626	300.000183105469
1.56085297851562	-0.016053371792426597	300.001647949219
1.61090830078125	-0.0167158644203705	300.003890991211
1.6603849609375	-0.019025468577800502	300.0029296875
1.71012470703125	-0.020067682587699302	300.001892089844
1.76012373046875	-0.0222213691776147	300.001983642578
1.81066748046875	-0.0235207793641734	300.00146484375
1.86090927734375	-0.0256964914921854	300.003112792969
1.91039873046875	-0.0277490935101384	300.001907348633
1.96045048828125	-0.029426145534754	300.002136230469
2.01068056640625	-0.0307248408815672	300.001510620117
2.06042744140625	-0.0324270652682751	300.002075195313
2.11016357421875	-0.035107655335493204	300.002059936523
2.1602212890625	-0.0367832547296942	300.001754760742
2.2109583984375	-0.0385763909140427	300.00212097168
2.2599525390625	-0.0398314060393411	300.001708984375
2.31124169921875	-0.0412034804407128	300.001251220703
2.3609802734375	-0.0442033215165358	300.001327514648
2.41072802734375	-0.0458015813652409	300.002258300781
2.46046064453125	-0.0469646332265006	300.00146484375
2.50996884765625	-0.0488693559383122	300.001968383789
2.55996259765625	-0.0511070267819992	300.000534057617
2.61074013671875	-0.0535536750355104	300.000747680664
2.66072001953125	-0.053680259750776796	300.001037597656
2.71089169921875	-0.056637249958967	300.000549316406
2.76082578125	-0.058347696961403996	300.002304077148
2.8114943359375	-0.059663676861991304	300.001190185547
2.861182421875	-0.0618369623659963	300.002212524414
2.910866796875	-0.0633816206968703	300.002090454102
2.96079951171875	-0.06593598634613719	300.000961303711
3.01177236328125	-0.0675013804548326	300.001968383789
3.0612005859375	-0.0702554959968472	300.003143310547
3.11189775390625	-0.07038588739799191	300.00276184082
3.16181767578125	-0.0723789162140789	300.001037597656
3.21230478515625	-0.0749753412371337	300.001968383789
3.26274619140625	-0.07613084606600709	299.999771118164
3.3126798828125	-0.0780467462187463	300.002685546875
3.362373828125	-0.0796519665300581	300.002593994141
3.4128341796875	-0.0818926194220542	300.002655029297
3.4627625	-0.0831961712950372	300.000762939453
3.5132033203125	-0.0856358241732955	300.001892089844
3.563187109375	-0.0868425330276858	300.000839233398
3.613114453125	-0.0894985195033355	300.000457763672
3.6633095703125	-0.0914886925831077	300.000961303711
3.71348984375	-0.0929715203692168	300.003036499023
3.7642208984375	-0.0945109279631296	300.001708984375
3.81364375	-0.0961897688287557	300.000595092773
3.8640833984375	-0.0975952613713824	300.000427246094
3.914021484375	-0.100787409351649	300.001342773438
3.96470234375	-0.102191283557169	300.001434326172
4.015393359375	-0.104911861089127	300.002655029297
4.064573046875	-0.105280799681536	300.00178527832
4.1155576171875	-0.108348055599915	300.001983642578
4.16471953125	-0.10947506853724101	300.001235961914
4.21541484375	-0.111412554111661	300.000152587891
4.2656126953125	-0.11364267786202499	300.000274658203
4.3155328125	-0.114609735940441	300.002380371094
4.3657150390625	-0.116712809484751	300.002716064453
4.41564296875	-0.11824819709821	300.000534057617
4.465871484375	-0.120287562314505	299.999984741211
4.515803125	-0.123121394516406	300.000350952148
4.5659798828125	-0.124841251968	300.001266479492
4.616217578125	-0.125722741632569	300.001266479492
4.66639375	-0.127951039142015	300.002349853516
4.7168232421875	-0.129464159850338	300.001571655273
4.7677650390625	-0.131368661562735	300.001129150391
4.8167408203125	-0.133808386785937	300.001892089844
4.86717890625	-0.135369645455852	300.001998901367
4.91760390625	-0.137397420123356	300.001678466797
4.967849609375	-0.14043459701948002	300.001647949219
5.0182806640625	-0.14160366677894698	299.999816894531
5.06846328125	-0.142332268954114	300.000518798828
5.118141015625	-0.14376445400527002	300.000259399414
5.1681236328125	-0.145743322108223	300.001281738281
5.218181640625	-0.14894104470402	300.000915527344
5.26923359375	-0.150133871628673	300.002227783203
5.32006484375	-0.152808016231929	300.00390625
5.3698623046875	-0.153851358983312	300.001113891602
5.4204125	-0.156762339360505	300.001525878906
5.4709498046875	-0.157774392017243	300.001312255859
5.5220623046875	-0.160458793965611	300.000961303711
5.5718615234375	-0.161889511503517	300.001419067383
5.62265859375	-0.163137485388626	300.000473022461
5.6742310546875	-0.16497880684066502	300.000946044922
5.7242923828125	-0.16696710210212898	300.000854492188
5.7740853515625	-0.168239985873293	300.001708984375
5.8251400390625	-0.17097640072746897	300.00163269043
5.8749873046875	-0.172585268957373	300.001037597656
5.9260541015625	-0.17539755030130902	300.002090454102
5.97634296875	-0.17643342449402502	300.000778198242
6.0274583984375	-0.17928038803024202	300.002136230469
6.078271484375	-0.181307530565711	300.001480102539
6.1278146484375	-0.18251748861239198	300.000030517578
6.1788751953125	-0.184039675107932	300.000396728516
6.2297357421875	-0.186103970376404	300.001373291016
6.2800345703125	-0.18876146603915	300.001342773438
6.33033515625	-0.189293568850861	300.001388549805
6.380951171875	-0.19140542527817198	300.000457763672
6.431249609375	-0.193926656583922	300.002182006836
6.4815482421875	-0.19584397763714198	300.000152587891
6.5323552734375	-0.197252133165737	300.000289916992
6.58295859375	-0.199911493840872	300.000274658203
6.633516796875	-0.201142026713198	300.001708984375
6.684320703125	-0.204283688630023	300.001098632812
6.734380859375	-0.20577495044613098	300.001022338867
6.78544375	-0.20674661555395898	300.001052856445
6.8352359375	-0.209435015920526	300.001388549805
6.885780078125	-0.210801989626775	300.001174926758
6.9371421875	-0.21265887877093	300.00146484375
6.987687890625	-0.214663495522873	300.001815795898
7.0382453125	-0.216188288761475	300.001266479492
7.0883015625	-0.218730118036048	300.001953125
7.138364453125	-0.220438999652634	300.001663208008
7.188925	-0.222286348917322	300.002563476562
7.239711328125	-0.223153181426399	300.002593994141
7.290836328125	-0.22606471313913798	300.001831054687
7.34089765625	-0.226744952287852	300.001022338867
7.390930859375	-0.22997962412251	299.999618530273
7.442305078125	-0.231595365782198	300.000885009766
7.492859375	-0.232906072901752	300.00129699707
7.543158984375	-0.235238398534749	300.00178527832
7.593458203125	-0.23885137723234398	300.001113891602
7.643808984375	-0.238004572654833	300.000473022461
7.6946234375	-0.240823761558626	300.001831054687
7.744920703125	-0.24312845321756102	300.001129150391
7.795535546875	-0.24484478381244798	299.999435424805
7.84636015625	-0.24652738000710703	300.000854492188
7.896666015625	-0.24873757955805997	300.001373291016
7.94746484375	-0.250389297870086	300.001434326172
7.997559765625	-0.252047273317918	300.00048828125
8.04836171875	-0.255214105629206	300.00016784668
8.09916953125	-0.25615537782723297	300.001571655273
8.150249609375	-0.257970072570242	300.000305175781
8.20003984375	-0.26012180565834697	300.000869750977
8.250340234375	-0.262082569642434	300.000762939453
8.301903125	-0.263804054711221	300.000778198242
8.351237890625	-0.265479604660242	300.000823974609
8.402294921875	-0.267382713222687	300.0029296875
8.452857421875	-0.270966265079388	299.999481201172
8.5036640625	-0.272179228852837	299.998596191406
8.553471875	-0.273679054229818	299.999877929687
8.605290625	-0.272920143261262	300.001480102539
8.654821484375	-0.27786686278667	300.00163269043
8.705176171875	-0.27939720685770697	300.000457763672
8.755726953125	-0.28114870414383497	300.001586914063
8.806527734375	-0.282069320491471	300.002593994141
8.856883984375	-0.28535327449783704	300.001022338867
8.90743671875	-0.287195909120581	300.000137329102
8.958251171875	-0.288361535299732	300.000579833984
9.00012890625	-0.292418963657456	300.000152587891