File: data/doubleLayers/dl_1-25/ppms/KoelnPPMS/DD205_3_FCW_100OE.DAT
[Header]
; VSM Data File (default extension .dat)
; Copyright (c) 2003-2013, Quantum Design, Inc. All rights reserved.
TITLE,
FILEOPENTIME,22771454.53,09/21/2018,10:22 pm
BYAPP,VSM,2.0,2.0
INFO,PPMS VSM Option Release 1.4.10 Build 1,APPNAME
INFO,Quantum Design Linear Motor Servo Controller,MOTOR_MODULE_NAME
INFO,3101-100 M1,MOTOR_HW_VERSION
INFO,MMC1014,MOTOR_SERIAL_NUMBER
INFO,SRV No X-over 01.03.11,MOTOR_SOFTWARE_VERSION
INFO,Quantum Design VSM Detection Module,VSM_MODULE_NAME
INFO,3101-150 F0,VSM_HW_VERSION
INFO,VSM707,VSM_SERIAL_NUMBER
INFO,VSM No X-over 01.02.05 May 20 2008 13:51:47,VSM_SOFTWARE_VERSION
INFO,704,PREAMP_SERIAL_NUMBER
INFO,822,COIL_SERIAL_NUMBER
INFO,0,MOMENT_UNITS
INFO,,SAMPLE_MATERIAL
INFO,,SAMPLE_COMMENT
INFO,,SAMPLE_MASS
INFO,,SAMPLE_VOLUME
INFO,,SAMPLE_MOLECULAR_WEIGHT
INFO,,SAMPLE_SIZE
INFO,,SAMPLE_SHAPE
DATATYPE,COMMENT,1
DATATYPE,TIME,2
STARTUPAXIS,X,2
STARTUPAXIS,Y1,5
[Data]
Comment,Time Stamp (sec),Temperature (K),Magnetic Field (Oe),Moment (emu),M. Std. Err. (emu),Transport Action,Averaging Time (sec),Frequency (Hz),Peak Amplitude (mm),Center Position (mm),Coil Signal' (mV),Coil Signal" (mV),Range (mV),M. Quad. Signal (emu),M. Raw' (emu),M. Raw" (emu),Min. Temperature (K),Max. Temperature (K),Min. Field (Oe),Max. Field (Oe),Mass (grams),Motor Lag (deg),Pressure (Torr),VSM Status (code),Motor Status (code),Measure Status (code),Measure Count,PPMS Status (code),System Temp. (K),System Field (Oe),Sample Position (deg),Bridge 1 Resistance (ohms),Bridge 1 Excitation (에),Bridge 2 Resistance (ohms),Bridge 2 Excitation (에),Bridge 3 Resistance (ohms),Bridge 3 Excitation (에),Bridge 4 Resistance (ohms),Bridge 4 Excitation (에),Signal 1 Vin (V),Signal 2 Vin (V),Digital Inputs (code),Drive 1 Iout (mA),Drive 1 Ipower (W),Drive 2 Iout (mA),Drive 2 Ipower (W),Pressure (),Map 20 (),Map 21 (),Map 22 (),Map 23 (),Map 24 (),Map 25 (),Map 26 (),Map 27 (),Map 28 (),Map 29 ()
,22771583.69,10.0057755,99.5330276489258,2.07380745365763E-5,3.72476252722283E-7,1,0.999253354069792,40.0298881530762,1.99873136181005,16.5599994361401,0.000233641906865014,3.88511706049241E-5,0.25,-2.27437151097416E-7,2.06200907595919E-5,-1.26115019775635E-7,10.0057755,10.0057755,99.5330276489258,99.5330276489258,56.8689461736791,20.6781155923436,11.519473,0,0,0,40,4369,9.9893,99.5330276489258,,,,,,,,,,,,,0,,,,-0.0049,,,,,,10.0057755,,,,
,22771714.15,13.0184307,99.5330276489258,2.0691324786505E-5,3.14848436353933E-7,1,0.999253354069792,40.0298881530762,1.9990080382369,16.5599994361401,0.000232647932014078,4.15656230895308E-5,0.25,2.18021360950086E-8,2.05722869152478E-5,1.21466926203275E-7,13.0184307,13.0184307,99.5330276489258,99.5330276489258,57.166746639506,20.6752649643028,12.278775,0,0,0,40,4370,13.182,99.5330276489258,,,,,,,,,,,,,0,,,,0.0049,,,,,,13.0184307,,,,
,22771855.265,16.5026073,99.5330276489258,2.05148126362671E-5,2.84712064218444E-7,1,0.999253354069792,40.0298881530762,1.99880437832593,16.5599994361401,0.000231115612532724,3.85205594731462E-5,0.25,-2.17259795235812E-7,2.03977460331531E-5,-1.17071045076932E-7,16.5026073,16.5026073,99.5330276489258,99.5330276489258,57.1120326431599,20.6791901890093,12.658426,0,0,0,40,4370,16.7484,99.5330276489258,,,,,,,,,,,,,0,,,,-0.0049,,,,,,16.5026073,,,,
,22771995.485,20.0262623,99.5330276489258,2.07866120045284E-5,2.7734923724481E-7,1,0.999253354069792,40.0298881530762,1.99871104167164,16.5599994361401,0.000234443574090898,3.74940539757065E-5,0.25,-3.5738675025793E-7,2.06689754809901E-5,-2.54418136945658E-7,20.0262623,20.0262623,99.5330276489258,99.5330276489258,56.8994296859291,20.6788851666728,13.797379,0,0,0,40,4370,20.26985,99.5330276489258,,,,,,,,,,,,,0,,,,0,,,,,,20.0262623,,,,
,22772137.31,23.5053539,99.5330276489258,2.07228014472796E-5,2.59054973402529E-7,1,0.999253354069792,40.0298881530762,1.99867607377744,16.5599994361401,0.000233827985000795,3.69193046463965E-5,0.25,-4.00339642220164E-7,2.06079959736583E-5,-2.94618627318329E-7,23.5053539,23.5053539,99.5330276489258,99.5330276489258,56.7610814380252,20.6804196096501,13.417728,0,0,0,40,4370,23.848,99.5330276489258,,,,,,,,,,,,,0,,,,0.0049,,,,,,23.5053539,,,,
,22772278.265,27.0093803,99.5330276489258,2.06766182307699E-5,2.82598187467953E-7,1,0.999253354069792,40.0298881530762,1.9987844322935,16.5599994361401,0.00023302807063739,3.87713092565011E-5,0.25,-2.33455567183953E-7,2.05657243207194E-5,-1.23875039206357E-7,27.0093803,27.0093803,99.5330276489258,99.5330276489258,57.1386080128137,20.6818458901153,14.556682,0,0,0,40,4370,27.4122,99.5330276489258,,,,,,,,,,,,,0,,,,-0.00245,,,,,,27.0093803,,,,
,22772419.56,30.5058193,99.5330276489258,2.04483509433488E-5,2.91081433995906E-7,1,0.999253354069792,40.0298881530762,1.9987393566273,16.5999997407198,0.000230750590517621,3.71333168018992E-5,0.25,-3.46682939217771E-7,2.03465237271504E-5,-2.30685622916076E-7,30.5058193,30.5058193,99.5330276489258,99.5330276489258,56.6774471864675,20.673622358272,14.177031,0,0,0,40,4370,30.9882,99.5330276489258,,,,,,,,,,,,,0,,,,0,,,,,,30.5058193,,,,
,22772562.165,34.011837,99.5330276489258,2.09320251540052E-5,2.94594392511603E-7,1,0.999253354069792,40.0298881530762,1.99878607993584,16.5999997407198,0.000235881191648601,4.05850441214425E-5,0.25,-1.37065425637244E-7,2.08373331220591E-5,-1.05149695610574E-8,34.011837,34.011837,99.5330276489258,99.5330276489258,57.0745144742368,20.6780714556539,15.315984,0,0,0,40,4370,34.5899,99.5330276489258,,,,,,,,,,,,,0,,,,0,,,,,,34.011837,,,,
,22772705.375,37.5190086,99.5330276489258,2.04817525184868E-5,3.17377856848582E-7,1,0.999253354069792,40.0298881530762,1.998942377684,16.5999997407198,0.0002308003726917,4.07862774395317E-5,0.25,-5.0989266737414E-8,2.04029021427217E-5,8.19670005845455E-8,37.5190086,37.5190086,99.5330276489258,99.5330276489258,56.9119357422368,20.6759295464849,14.936333,0,0,0,40,4370,38.2155,99.5330276489258,,,,,,,,,,,,,0,,,,0,,,,,,37.5190086,,,,
,22772827.555,40.5253181,99.5330276489258,2.0503216846775E-5,2.34351844186626E-7,1,0.999253354069792,40.0298881530762,1.99869170911106,16.5899991989136,0.000231380113720406,3.97816788304404E-5,0.25,-1.53891024580466E-7,2.04402084917579E-5,-1.27962013074776E-8,40.5253181,40.5253181,99.5330276489258,99.5330276489258,56.8986480574099,20.6751714416972,15.315984,0,0,0,40,4370,41.3122,99.5330276489258,,,,,,,,,,,,,0,,,,0.00245,,,,,,40.5253181,,,,
,22772967.925,44.0046387,99.5330276489258,2.06730645722107E-5,2.68939942579518E-7,1,0.999253354069792,40.0298881530762,1.9987979312846,16.5899991989136,0.000233663301569883,3.94819140047445E-5,0.25,-2.21733866203605E-7,2.06306092835055E-5,-7.23160549868328E-8,44.0046387,44.0046387,99.5330276489258,99.5330276489258,56.7720242372945,20.6722838869114,16.075285,0,0,0,40,4374,44.8696,99.5330276489258,,,,,,,,,,,,,0,,,,-0.0049,,,,,,44.0046387,,,,
,22773113.305,47.5518341,99.5330276489258,2.03029721043111E-5,2.99370249475666E-7,1,0.999253354069792,40.0298881530762,1.99890589287373,16.5899991989136,0.000229743847248121,3.88835996384701E-5,0.25,-2.16271468520922E-7,2.0284453974598E-5,-6.56131034658492E-8,47.5518341,47.5518341,99.5330276489258,99.5330276489258,56.8509687177368,20.672054849925,15.695635,0,0,0,40,4374,48.5756,99.5330276489258,,,,,,,,,,,,,0,,,,-0.0049,,,,,,47.5518341,,,,
,22773234.905,50.531353,99.5330276489258,2.03067474921664E-5,2.65636777383416E-7,1,0.999253354069792,40.0298881530762,1.99878400694422,16.5800005197525,0.000230247316953211,3.75381945760889E-5,0.25,-3.39480599112498E-7,2.03089080960343E-5,-1.88494629057893E-7,50.531353,50.531353,99.5330276489258,99.5330276489258,56.7728058658137,20.6680700177859,16.075285,0,0,0,40,4374,51.6716,99.5330276489258,,,,,,,,,,,,,0,,,,-0.0049,,,,,,50.531353,,,,
,22773377.505,54.0120659,99.5330276489258,2.0387771065552E-5,3.14794301313712E-7,1,0.999253354069792,40.0298881530762,1.99876702169568,16.5800005197525,0.000231628840751004,3.65481482499957E-5,0.25,-4.42217059817933E-7,2.04129377147771E-5,-2.93888206928411E-7,54.0120659,54.0120659,99.5330276489258,99.5330276489258,56.8634747740445,20.6712230067675,16.075285,0,0,0,40,4374,55.3006,99.5330276489258,,,,,,,,,,,,,0,,,,-0.0049,,,,,,54.0120659,,,,
,22773521.515,57.5236702,99.5330276489258,2.03506292288339E-5,2.38883849184072E-7,1,0.999253354069792,40.0298881530762,1.99884906588355,16.5800005197525,0.000230791279809736,4.01482476386523E-5,0.25,-1.15106189253627E-7,2.03935849307839E-5,2.73697917593852E-8,57.4935417,57.5537987,99.5330276489258,99.5330276489258,57.3418314278138,20.670080056972,16.454937,0,0,0,40,4374,58.9688,99.5330276489258,,,,,,,,,,,,,0,,,,0,,,,,,57.5236702,,,,
,22773664.37,61.0199127,99.5330276489258,2.05770720695233E-5,2.77874767288702E-7,1,0.999253354069792,40.0298881530762,1.99875863694452,16.5599994361401,0.000233884982992127,3.87281052957704E-5,0.25,-2.75910208669331E-7,2.06388541528369E-5,-1.40270307577356E-7,60.9889297,61.0508957,99.5330276489258,99.5330276489258,56.6602513590445,20.6691241228553,17.214239,0,0,0,40,4374,62.6066,99.5330276489258,,,,,,,,,,,,,0,,,,-0.00735,,,,,,61.0199127,,,,
,22773805.7,64.5157242,99.5330276489258,2.04450320329613E-5,2.7425328175051E-7,1,0.999253354069792,40.0298881530762,1.99859103243999,16.5599994361401,0.000233210359920788,3.46551543142986E-5,0.25,-6.04421017025086E-7,2.05223162442431E-5,-4.79746986380942E-7,64.5157242,64.5157242,99.5330276489258,99.5330276489258,57.3363600281791,20.6722079226051,16.834587,0,0,0,40,4374,66.1983,99.5330276489258,,,,,,,,,,,,,0,,,,-0.00245,,,,,,64.5157242,,,,
,22773950.625,68.0363998,99.5330276489258,2.05422869420621E-5,3.02990686829876E-7,1,0.999253354069792,40.0298881530762,1.99871990348249,16.5599994361401,0.00023363709335555,3.94602582963551E-5,0.25,-1.91149787261666E-7,2.06288087380894E-5,-7.37886315051059E-8,68.0363998,68.0363998,99.5330276489258,99.5330276489258,57.1073428720445,20.6707117690413,16.834587,0,0,0,40,4374,69.8979,99.5330276489258,,,,,,,,,,,,,0,,,,-0.0049,,,,,,68.0363998,,,,
,22774095,71.5401306,99.5330276489258,2.02472635448953E-5,3.26292533149858E-7,1,0.999253354069792,40.0298881530762,1.99878386442582,16.5400002151728,0.000230489914831279,3.83348143097561E-5,0.25,-2.30246877360463E-7,2.0341516553652E-5,-1.23743664094703E-7,71.5401306,71.5401306,99.5330276489258,99.5330276489258,56.6172617904868,20.6674105073256,17.214239,0,0,0,40,4374,73.59445,99.5330276489258,,,,,,,,,,,,,0,,,,0.0049,,,,,,71.5401306,,,,
,22774235.405,75.00647735,99.5330276489258,2.05162374455767E-5,3.19499428092231E-7,1,0.999253354069792,40.0298881530762,1.99875136634295,16.5400002151728,0.000233906854496854,3.7248275891519E-5,0.25,-3.66593573469017E-7,2.06188922137144E-5,-2.67552563947108E-7,74.979805,75.0331497,99.5330276489258,99.5330276489258,56.5695824508137,20.6684942018587,17.214239,0,0,0,40,4374,77.15335,99.5330276489258,,,,,,,,,,,,,0,,,,0,,,,,,75.00647735,,,,
,22774378.955,78.5435257,99.5330276489258,2.04358056945057E-5,2.72213572835091E-7,1,0.999253354069792,40.0298881530762,1.9988619667919,16.5400002151728,0.000232896539624887,3.8022303157283E-5,0.25,-2.7759093114791E-7,2.05425902886868E-5,-1.86178692227418E-7,78.5435257,78.5435257,99.5330276489258,99.5330276489258,57.058100275333,20.6705084511796,17.214239,0,0,0,40,4374,80.7815,99.5330276489258,,,,,,,,,,,,,0,,,,-0.0049,,,,,,78.5435257,,,,
,22774520.53,82.0310822,99.5330276489258,2.04673730479091E-5,2.48534779294836E-7,1,0.999253354069792,40.0298881530762,1.99860149357869,16.5199991315603,0.00023309000559989,3.90902052658659E-5,0.25,-1.82641018704922E-7,2.05775564936266E-5,-9.74421440895527E-8,82.0310822,82.0310822,99.5330276489258,99.5330276489258,57.1198489283522,20.6708729576419,17.593889,0,0,0,40,4374,84.3623,99.5330276489258,,,,,,,,,,,,,0,,,,0.0049,,,,,,82.0310822,,,,
,22774659.68,85.5084839,99.5330276489258,2.04279052845673E-5,2.74465450458927E-7,1,0.999253354069792,40.0298881530762,1.99855744074788,16.5199991315603,0.000232696284957278,3.88409220398292E-5,0.25,-1.91936667094529E-7,2.0540516856016E-5,-1.13002881020841E-7,85.5084839,85.5084839,99.5330276489258,99.5330276489258,56.8673829166406,20.6717950793025,18.353191,0,0,0,40,4374,87.88095,99.5330276489258,,,,,,,,,,,,,0,,,,-0.00245,,,,,,85.5084839,,,,
,22774803.315,89.0522385,99.5330276489258,2.05603809499554E-5,3.80372025208391E-7,1,0.999253354069792,40.0298881530762,1.99879226448823,16.5199991315603,0.000235037064967363,3.46537609739187E-5,0.25,-5.78522876222056E-7,2.06770380509122E-5,-5.06865646380835E-7,89.0522385,89.0522385,99.5330276489258,99.5330276489258,56.963523224506,20.6610672510151,18.353191,0,0,0,40,4374,91.5169,99.5330276489258,,,,,,,,,,,,,0,,,,0.00245,,,,,,89.0522385,,,,
,22774947.845,92.5391541,99.5330276489258,2.05744379017798E-5,2.92404707907517E-7,1,0.999253354069792,40.0298881530762,1.99893937739492,16.4899993687868,0.000234868129453881,3.67255119961417E-5,0.25,-3.94214892545946E-7,2.06917648924337E-5,-3.26604755490196E-7,92.5391541,92.5391541,99.5330276489258,99.5330276489258,57.1714364106214,20.6694394328866,17.593889,0,0,0,40,4374,95.20205,99.5330276489258,,,,,,,,,,,,,0,,,,0,,,,,,92.5391541,,,,
,22775091.695,96.0301056,99.5330276489258,2.06859278158162E-5,2.73408844456938E-7,1,0.999253354069792,40.0298881530762,1.99890305185394,16.4899993687868,0.000235912198064781,3.82489072562439E-5,0.25,-2.75444477259025E-7,2.08042436544363E-5,-2.11381427402317E-7,96.0301056,96.0301056,99.5330276489258,99.5330276489258,56.9916618511983,20.6681121371848,18.353191,0,0,0,40,4374,98.88845,99.5330276489258,,,,,,,,,,,,,0,,,,0,,,,,,96.0301056,,,,
,22775231.905,99.5262604,99.5330276489258,2.05617807168897E-5,3.78724569690036E-7,1,0.999253354069792,40.0298881530762,1.9988551737558,16.4899993687868,0.000234142219018786,4.00213756081544E-5,0.25,-9.3888685700299E-8,2.06791176024909E-5,-3.31251113273443E-8,99.5262604,99.5262604,99.5330276489258,99.5330276489258,57.004167907506,20.6664586854055,18.353191,0,0,0,40,4374,102.43495,99.5330276489258,,,,,,,,,,,,,0,,,,0,,,,,,99.5262604,,,,
,22775353.35,102.50812535,99.5330276489258,2.06311326612177E-5,2.63562052025873E-7,1,0.999253354069792,40.0298881530762,1.99847113202292,16.4599996060133,0.000235174057132792,3.85239282975587E-5,0.25,-2.3397075607111E-7,2.07492716380883E-5,-1.76896988242502E-7,102.4788361,102.5374146,99.5330276489258,99.5330276489258,56.7923465787945,20.6690027861593,18.353191,0,0,0,40,4374,105.50445,99.5330276489258,,,,,,,,,,,,,0,,,,-0.00245,,,,,,102.50812535,,,,
,22775495.045,106.0303116,99.5330276489258,2.03118739394013E-5,3.23341104848268E-7,1,0.999253354069792,40.0298881530762,1.99861843240238,16.4599996060133,0.000231463639359693,3.84091846399207E-5,0.25,-1.85025832902002E-7,2.0427767867339E-5,-1.31790273619001E-7,106.0303116,106.0303116,99.5330276489258,99.5330276489258,57.0495023616214,20.6697784290492,18.353191,0,0,0,40,4374,109.0657,99.5330276489258,,,,,,,,,,,,,0,,,,-0.0049,,,,,,106.0303116,,,,
,22775634.505,109.5012436,99.5330276489258,2.03447414461875E-5,2.85909695283354E-7,1,0.999253354069792,40.0298881530762,1.99886514174239,16.4599996060133,0.000231890278087963,3.82996215591609E-5,0.25,-1.97874667936413E-7,2.04603400489227E-5,-1.4749027201622E-7,109.5012436,109.5012436,99.5330276489258,99.5330276489258,56.8877052581406,20.6661317884343,18.353191,0,0,0,40,4374,112.5746,99.5330276489258,,,,,,,,,,,,,0,,,,0.0049,,,,,,109.5012436,,,,
,22775756.115,112.5251312,99.5330276489258,2.02111810533377E-5,3.0399593554074E-7,1,0.999253354069792,40.0298881530762,1.99877326823567,16.4199993014336,0.000230291845103975,3.83829666357603E-5,0.25,-1.64650144493477E-7,2.03253397095426E-5,-1.16680694354374E-7,112.5251312,112.5251312,99.5330276489258,99.5330276489258,56.9236601700253,20.6686481513169,18.732843,0,0,0,40,4374,115.63255,99.5330276489258,,,,,,,,,,,,,0,,,,-0.0049,,,,,,112.5251312,,,,
,22775896.015,116.0283356,99.5330276489258,2.0256093499168E-5,2.9019262081793E-7,1,0.999253354069792,40.0298881530762,1.99875567823534,16.4199993014336,0.000231006523452527,3.72390112194843E-5,0.25,-2.70507622244121E-7,2.03698870816313E-5,-2.25405350543751E-7,116.0283356,116.0283356,99.5330276489258,99.5330276489258,57.2628869473714,20.6706225262209,18.732843,0,0,0,40,4374,119.1444,99.5330276489258,,,,,,,,,,,,,0,,,,0,,,,,,116.0283356,,,,
,22776038.45,119.5509415,99.5330276489258,2.06059559257379E-5,2.77059814336727E-7,1,0.999253354069792,40.0298881530762,1.99875900577327,16.4199993014336,0.00023489243429608,3.84101222457559E-5,0.25,-2.26373621615582E-7,2.07205737906188E-5,-1.82466697028068E-7,119.5509415,119.5509415,99.5330276489258,99.5330276489258,57.6544828355061,20.6651921393609,18.732843,0,0,0,40,4374,122.7219,99.5330276489258,,,,,,,,,,,,,0,,,,-0.0049,,,,,,119.5509415,,,,
,22776177.03,123.0112457,99.5330276489258,2.04469040420581E-5,2.83183766127558E-7,1,0.999253354069792,40.0298881530762,1.99886377817413,16.380000859499,0.000233162184615157,3.76322287153296E-5,0.25,-2.64938373048806E-7,2.05595865552104E-5,-2.23574975931431E-7,123.0112457,123.0112457,99.5330276489258,99.5330276489258,56.6508718168137,20.6685550669669,19.112494,0,0,0,40,4374,126.2086,99.5330276489258,,,,,,,,,,,,,0,,,,-0.0049,,,,,,123.0112457,,,,
,22776318.705,126.5183792,99.5330276489258,2.01703325633706E-5,3.32722413492902E-7,1,0.999253354069792,40.0298881530762,1.9988257302102,16.380000859499,0.000230116913823241,3.63935386455567E-5,0.25,-3.23398966449606E-7,2.02803694695128E-5,-2.84759387005447E-7,126.5183792,126.5183792,99.5330276489258,99.5330276489258,57.0792042453522,20.6676389413845,19.112494,0,0,0,40,4374,129.7714,99.5330276489258,,,,,,,,,,,,,0,,,,0.00245,,,,,,126.5183792,,,,
,22776460.845,130.0434113,99.5330276489258,2.06169570003601E-5,3.50596381084192E-7,1,0.999253354069792,40.0298881530762,1.99902865743084,16.380000859499,0.000234938950416537,3.88067433233875E-5,0.25,-1.87654190284814E-7,2.07277682198664E-5,-1.49109299872276E-7,130.0434113,130.0434113,99.5330276489258,99.5330276489258,57.2597604332945,20.6714210796755,19.492144,0,0,0,40,4374,133.3511,99.5330276489258,,,,,,,,,,,,,0,,,,0,,,,,,130.0434113,,,,
,22776601.75,133.5330505,99.5330276489258,2.01662871869529E-5,3.32956950885135E-7,1,0.999253354069792,40.0298881530762,1.99897985038134,16.3400005549192,0.000230683931803025,3.2784454157379E-5,0.25,-6.36503704931042E-7,2.02740884160257E-5,-6.02730478700503E-7,133.5330505,133.5330505,99.5330276489258,99.5330276489258,56.8509687177368,20.6683809711407,19.112494,0,0,0,40,4374,136.8914,99.5330276489258,,,,,,,,,,,,,0,,,,0,,,,,,133.5330505,,,,
,22776742.025,137.0410004,99.5330276489258,2.01906478992773E-5,2.93402163588425E-7,1,0.999253354069792,40.0298881530762,1.9990779774013,16.3400005549192,0.000230450249162753,3.57220161585338E-5,0.25,-3.81032073328036E-7,2.0296579736407E-5,-3.47262075528388E-7,137.0410004,137.0410004,99.5330276489258,99.5330276489258,56.6156985334483,20.6737544009099,18.732843,0,0,0,40,4374,140.426,99.5330276489258,,,,,,,,,,,,,0,,,,-0.0049,,,,,,137.0410004,,,,
,22776882.32,140.5189972,99.5330276489258,2.05545393877885E-5,2.79483543584554E-7,1,0.999253354069792,40.0298881530762,1.999054663548,16.3400005549192,0.000234246784665729,3.82893516763353E-5,0.25,-2.17183686642418E-7,2.06604777498445E-5,-1.83242681650868E-7,140.4920197,140.5459747,99.5330276489258,99.5330276489258,56.8861420011022,20.6696024494652,19.112494,0,0,0,40,4374,143.96105,99.5330276489258,,,,,,,,,,,,,0,,,,0,,,,,,140.5189972,,,,
,22777003.775,143.5136871,99.5330276489258,2.038394921922E-5,3.08402086928265E-7,1,0.999253354069792,40.0298881530762,1.99893906517628,16.3000002503395,0.000232594161643025,3.61282380813539E-5,0.25,-3.75966363222678E-7,2.0487854266464E-5,-3.44176916038613E-7,143.5136871,143.5136871,99.5330276489258,99.5330276489258,56.9111541137176,20.6645072436325,19.112494,0,0,0,40,4374,147.0085,99.5330276489258,,,,,,,,,,,,,0,,,,0,,,,,,143.5136871,,,,
,22777143.875,147.0319824,99.5330276489258,2.01394351703967E-5,3.07560933296515E-7,1,0.999253354069792,40.0298881530762,1.99912590212862,16.3000002503395,0.000230223223272846,3.32947694776313E-5,0.25,-5.81346055127285E-7,2.02407110401163E-5,-5.52095250700882E-7,147.0319824,147.0319824,99.5330276489258,99.5330276489258,56.8032893780637,20.6720620768402,19.492144,0,0,0,40,4374,150.532,99.5330276489258,,,,,,,,,,,,,0,,,,0,,,,,,147.0319824,,,,
,22777284.5,150.5227661,99.5330276489258,2.03806376791294E-5,2.96171983737461E-7,1,0.999253354069792,40.0298881530762,1.99910545932013,16.3000002503395,0.000232266476135754,3.76601227874741E-5,0.25,-2.38186313029525E-7,2.04807956779792E-5,-2.07897093501223E-7,150.5227661,150.5227661,99.5330276489258,99.5330276489258,56.6344576179098,20.6727158776192,19.492144,0,0,0,40,4374,154.05595,99.5330276489258,,,,,,,,,,,,,0,,,,0,,,,,,150.5227661,,,,
,22777405.65,153.5353851,99.5330276489258,2.01047449870189E-5,2.74475804116985E-7,1,0.999253354069792,40.0298881530762,1.99918113267722,16.2499994039536,0.000229410237694278,3.54414514132103E-5,0.25,-3.84234891807771E-7,2.02022205716433E-5,-3.55915334506932E-7,153.5353851,153.5353851,99.5330276489258,99.5330276489258,57.1167224142753,20.6704697838676,19.871798,0,0,0,40,4374,157.0924,99.5330276489258,,,,,,,,,,,,,0,,,,0.0049,,,,,,153.5353851,,,,
,22777546.305,157.0450897,99.5330276489258,2.01902781409223E-5,3.15451217202786E-7,1,0.999253354069792,40.0298881530762,1.99922831225148,16.2499994039536,0.000230286928210446,3.60681699589029E-5,0.25,-3.42866511381278E-7,2.02862387121583E-5,-3.15129053022124E-7,157.0450897,157.0450897,99.5330276489258,99.5330276489258,57.0182372208522,20.6680335255545,19.492144,0,0,0,40,4374,160.6235,99.5330276489258,,,,,,,,,,,,,0,,,,0,,,,,,157.0450897,,,,
,22777686.04,160.5121765,99.5330276489258,1.99727708463095E-5,3.05952980048325E-7,1,0.999253354069792,40.0298881530762,1.99934444227006,16.2499994039536,0.000227604466916216,3.6787509173175E-5,0.25,-2.4077177381683E-7,2.006569230541E-5,-2.13710682840505E-7,160.5121765,160.5121765,99.5330276489258,99.5330276489258,56.8830154870253,20.6701189754484,19.492144,0,0,0,40,4374,164.1264,99.5330276489258,,,,,,,,,,,,,0,,,,0.0049,,,,,,160.5121765,,,,
,22777824.4,164.0000153,99.5330276489258,2.0277787548814E-5,2.8165401661511E-7,1,0.999253354069792,40.0298881530762,1.99923860168293,16.2099990993738,0.000231274254090215,3.60352863520232E-5,0.25,-3.58725431389213E-7,2.03703375703009E-5,-3.32562712933532E-7,164.0000153,164.0000153,99.5330276489258,99.5330276489258,56.8736359447945,20.6667921849429,19.871798,0,0,0,40,4374,167.5929,99.5330276489258,,,,,,,,,,,,,0,,,,0.0049,,,,,,164.0000153,,,,
,22777966.155,167.5320435,99.5330276489258,2.04435743341071E-5,3.20994047218899E-7,1,0.999253354069792,40.0298881530762,1.99915437774268,16.2099990993738,0.000233001626326299,3.70781219312073E-5,0.25,-2.94611339813507E-7,2.05347602167017E-5,-2.68696175171297E-7,167.5320435,167.5320435,99.5330276489258,99.5330276489258,57.2636685758907,20.6713506435712,19.871798,0,0,0,40,4374,171.1549,99.5330276489258,,,,,,,,,,,,,0,,,,0,,,,,,167.5320435,,,,
,22778106.705,171.0134125,99.5330276489258,2.00091269773223E-5,3.14854882446829E-7,1,0.999253354069792,40.0298881530762,1.99908068607072,16.2099990993738,0.000228925303487988,3.10763173189289E-5,0.25,-7.4587255977249E-7,2.00969732274299E-5,-7.23189666262296E-7,171.0134125,171.0134125,99.5330276489258,99.5330276489258,57.3129111726022,20.6715212487994,19.871798,0,0,0,40,4374,174.67375,99.5330276489258,,,,,,,,,,,,,0,,,,-0.0049,,,,,,171.0134125,,,,
,22778227.75,174.048233,99.5330276489258,2.04267305572043E-5,3.1789488873791E-7,1,0.999253354069792,40.0298881530762,1.99917955267849,16.160000115633,0.000233141812126359,3.48960292767323E-5,0.25,-4.81746595082225E-7,2.05142369345551E-5,-4.57936529247545E-7,174.048233,174.048233,99.5330276489258,99.5330276489258,57.0104209356599,20.6659261356891,19.492144,0,0,0,40,4374,177.7067,99.5330276489258,,,,,,,,,,,,,0,,,,0,,,,,,174.048233,,,,
,22778365.945,177.5019836,99.5330276489258,2.06241792015048E-5,2.66564490475102E-7,1,0.999253354069792,40.0298881530762,1.99903767127158,16.160000115633,0.000234695780736275,3.9022043157351E-5,0.25,-1.5185754584579E-7,2.07100070394148E-5,-1.27040299880492E-7,177.5019836,177.5019836,99.5330276489258,99.5330276489258,56.9924434797176,20.6710314569165,19.492144,0,0,0,40,4374,181.1795,99.5330276489258,,,,,,,,,,,,,0,,,,0,,,,,,177.5019836,,,,
,22778508.295,181.0135498,99.5330276489258,2.06054378397476E-5,2.79065138097422E-7,1,0.999253354069792,40.0298881530762,1.99909057298151,16.160000115633,0.000235210152541949,3.46898498121597E-5,0.25,-5.28902095831747E-7,2.06894750374622E-5,-5.06260102867778E-7,181.0135498,181.0135498,99.5330276489258,99.5330276489258,56.9072459711214,20.6712463536745,19.871798,0,0,0,40,4374,184.7435,99.5330276489258,,,,,,,,,,,,,0,,,,0,,,,,,181.0135498,,,,
,22778629.335,184.0491791,99.5330276489258,2.04361992110307E-5,3.31249530648143E-7,1,0.999253354069792,40.0298881530762,1.99918727766129,16.1099992692471,0.00023204263136439,4.14517644769916E-5,0.25,9.62075952518219E-8,2.05169220880415E-5,1.20650443442737E-7,184.0491791,184.0491791,99.5330276489258,99.5330276489258,56.7040225561214,20.6689427290069,19.871798,0,0,0,40,4374,187.786,99.5330276489258,,,,,,,,,,,,,0,,,,0.0049,,,,,,184.0491791,,,,
,22778770.23,187.5418396,99.5330276489258,2.04034541478677E-5,3.18040964230213E-7,1,0.999253354069792,40.0298881530762,1.99921015523295,16.1099992692471,0.000232251496364829,3.79119102797486E-5,0.25,-2.08717170923155E-7,2.04822143939478E-5,-1.86068272264884E-7,187.5418396,187.5418396,99.5330276489258,99.5330276489258,56.7720242372945,20.6721807458976,20.251448,0,0,0,40,4374,191.324,99.5330276489258,,,,,,,,,,,,,0,,,,-0.00245,,,,,,187.5418396,,,,
,22778910.955,191.0414429,99.5330276489258,2.06330951451032E-5,3.00533754167691E-7,1,0.999253354069792,40.0298881530762,1.99919902651403,16.1099992692471,0.000235492488629008,3.45711008093146E-5,0.25,-5.41739800420433E-7,2.07108632787013E-5,-5.20598771491971E-7,191.0414429,191.0414429,99.5330276489258,99.5330276489258,56.8329912617945,20.6703675932247,20.251448,0,0,0,40,4374,194.86015,99.5330276489258,,,,,,,,,,,,,0,,,,-0.0049,,,,,,191.0414429,,,,
touchdown = 10.2800000458956 mm,22779042.07,194.3044281,99.5330276489258,2.07612506966656E-5,3.73726386590493E-7,1,0.999253354069792,40.0298881530762,1.99936448175733,16.0600002855062,0.000236224664049116,3.89578573294782E-5,0.25,-1.77329213073563E-7,2.08369546124631E-5,-1.55155166618685E-7,194.3044281,194.3044281,99.5330276489258,99.5330276489258,56.7008960420445,20.6695700589282,20.631098,0,0,0,40,4374,198.16125,99.5330276489258,,,,,,,,,,,,,0,,,,0,,,,,,194.3044281,,,,
,22779171.42,197.5107193,99.5330276489258,2.00832896486968E-5,3.35065211493494E-7,1,0.999253354069792,40.0298881530762,1.99942305796233,16.0600002855062,0.000228780145126339,3.60345945007054E-5,0.25,-3.16185902418002E-7,2.01546273185063E-5,-2.95677447778949E-7,197.4810944,197.5403442,99.5330276489258,99.5330276489258,56.4476484018137,20.6666640203083,20.251448,0,0,0,40,4374,201.4078,99.5330276489258,,,,,,,,,,,,,0,,,,0.0049,,,,,,197.5107193,,,,
,22779310.9,201.005249,99.5330276489258,2.06423944138765E-5,3.44925462220854E-7,1,0.999253354069792,40.0298881530762,1.9996300491049,16.0600002855062,0.000235928257924971,3.25330848956308E-5,0.25,-7.20999989759325E-7,2.07138114939816E-5,-7.01713599096189E-7,201.005249,201.005249,99.5330276489258,99.5330276489258,57.0385595623522,20.6725149629362,19.871798,0,0,0,40,4374,204.9035,99.5330276489258,,,,,,,,,,,,,0,,,,0,,,,,,201.005249,,,,
touchdown = 10.2300001308322 mm,22779460.87,204.752243,99.5330276489258,2.04098888784512E-5,3.30341166538935E-7,1,0.999253354069792,40.0298881530762,1.99968881070219,16.0099994391203,0.000232662107187789,3.55434855932568E-5,0.25,-4.14860761767061E-7,2.04776967990647E-5,-3.95204118906017E-7,204.752243,204.752243,99.5330276489258,99.5330276489258,56.8032893780637,20.6675044264252,20.251448,0,0,0,40,4374,208.6777,99.5330276489258,,,,,,,,,,,,,0,,,,0,,,,,,204.752243,,,,
,22779593.58,208.0365829,99.5330276489258,2.09410625215662E-5,3.27241891525514E-7,1,0.999253354069792,40.0298881530762,1.99972592145795,16.0099994391203,0.000238827124371019,3.57085286351126E-5,0.25,-4.91864587179538E-7,2.10084415510635E-5,-4.72279561356888E-7,208.0110168,208.062149,99.5330276489258,99.5330276489258,57.139389641333,20.6708067919037,20.251448,0,0,0,40,4374,211.99985,99.5330276489258,,,,,,,,,,,,,0,,,,0.0049,,,,,,208.0365829,,,,
,22779733.08,211.523819,99.5330276489258,2.05698409483879E-5,3.38279789828144E-7,1,0.999253354069792,40.0298881530762,1.99991004908743,16.0099994391203,0.000234959773545769,3.29271837031242E-5,0.25,-6.71794872043857E-7,2.06338333134289E-5,-6.53496693829898E-7,211.523819,211.523819,99.5330276489258,99.5330276489258,57.0502839901407,20.6691633479465,20.631098,0,0,0,40,4374,215.4977,99.5330276489258,,,,,,,,,,,,,0,,,,0.00245,,,,,,211.523819,,,,
touchdown = 10.1800002157688 mm,22779877.775,215.1084747,99.5330276489258,2.1293829615872E-5,3.40292304900954E-7,1,0.999253354069792,40.0298881530762,1.99992170948402,15.9600004553795,0.000242129610577825,4.0259445497121E-5,0.25,-1.51096062212212E-7,2.13569907518309E-5,-1.30888411255238E-7,215.1084747,215.1084747,99.5330276489258,99.5330276489258,57.0283983916022,20.6642428979702,20.631098,0,0,0,40,4374,219.1382,99.5330276489258,,,,,,,,,,,,,0,,,,0,,,,,,215.1084747,,,,
,22780013.365,218.50564575,99.5330276489258,2.04538946675774E-5,2.8430423456996E-7,1,0.999253354069792,40.0298881530762,1.99984425530864,15.9600004553795,0.000233648003579174,3.2302945287463E-5,0.25,-7.05098235337327E-7,2.05127625254394E-5,-6.8763250587853E-7,218.4798431,218.5314484,99.5330276489258,99.5330276489258,56.689171614256,20.6680274150469,21.01075,0,0,0,40,4374,222.5262,99.5330276489258,,,,,,,,,,,,,0,,,,0,,,,,,218.50564575,,,,
,22780155.135,222.0467529,99.5330276489258,2.05730197648098E-5,3.84147085228298E-7,1,0.999253354069792,40.0298881530762,1.99985642912926,15.9600004553795,0.000234049310175087,3.78617254966844E-5,0.25,-2.3548740110539E-7,2.06293127601841E-5,-2.16918042673298E-7,222.0467529,222.0467529,99.5330276489258,99.5330276489258,56.668849272756,20.6675198680688,20.251448,0,0,0,40,4374,226.08205,99.5330276489258,,,,,,,,,,,,,0,,,,-0.00245,,,,,,222.0467529,,,,
touchdown = 10.1199997588992 mm,22780292.155,225.4730377,99.5330276489258,2.08357124140915E-5,3.02497693702823E-7,1,0.999253354069792,40.0298881530762,1.99974782965328,15.9000009298325,0.000237304270339607,3.65733460461216E-5,0.25,-3.93656282487632E-7,2.08904331109033E-5,-3.75578962755563E-7,225.4730377,225.4730377,99.5330276489258,99.5330276489258,56.8447156895829,20.6613800468936,21.01075,0,0,0,40,4374,229.5117,99.5330276489258,,,,,,,,,,,,,0,,,,0,,,,,,225.4730377,,,,
,22780415.435,228.566803,99.5330276489258,2.07969724238302E-5,3.50878705059286E-7,1,0.999253354069792,40.0298881530762,1.99981876544089,15.9000009298325,0.000236735020249262,3.71422264624154E-5,0.25,-3.3628349854695E-7,2.0849332042984E-5,-3.1836167468997E-7,228.566803,228.566803,99.5330276489258,99.5330276489258,56.8103240347368,20.6652494254366,21.01075,0,0,0,40,4374,232.5923,99.5330276489258,,,,,,,,,,,,,0,,,,0,,,,,,228.566803,,,,
,22780556.235,232.0316467,99.5330276489258,2.07540972543152E-5,3.2902817226035E-7,1,0.999253354069792,40.0298881530762,1.99980806688794,15.9000009298325,0.00023669302727796,3.43206433515562E-5,0.25,-5.76701999599025E-7,2.08040830212649E-5,-5.59689875874013E-7,232.0316467,232.0316467,99.5330276489258,99.5330276489258,56.8361177758714,20.6690044212853,20.631098,0,0,0,40,4374,236.1262,99.5330276489258,,,,,,,,,,,,,0,,,,0,,,,,,232.0316467,,,,
,22780695.66,235.514801,99.5330276489258,,,2,,,,15.8599998438358,,,,,,,235.514801,235.514801,99.5330276489258,99.5330276489258,,,21.01075,,,,-99999999,4374,239.6356,99.5330276489258,,,,,,,,,,,,,,,,,,,,,,,235.514801,,,,
,22780816.265,238.5383301,99.5330276489258,2.04557324784691E-5,4.20031330337072E-7,1,0.999253354069792,40.0298881530762,1.97413763868651,15.8500000834465,0.000229794983110409,3.67621875995454E-5,0.25,-2.68290704492494E-7,2.0500110841716E-5,-2.51332746711899E-7,238.5383301,238.5383301,99.5330276489258,99.5330276489258,56.963523224506,20.6626627180092,21.01075,0,0,0,40,4374,242.648,99.5330276489258,,,,,,,,,,,,,0,,,,0,,,,,,238.5383301,,,,
,22780954.77,242.0102997,99.5330276489258,2.05689473853023E-5,4.74013463384261E-7,1,0.999253354069792,40.0298881530762,1.97379763101976,15.8500000834465,0.000230622308996451,3.91371736570262E-5,0.25,-7.47391589187989E-8,2.06109098259191E-5,-5.75560464391542E-8,242.0102997,242.0102997,99.5330276489258,99.5330276489258,56.7946914643522,20.662969453598,21.01075,0,0,0,40,4374,246.1158,99.5330276489258,,,,,,,,,,,,,0,,,,0,,,,,,242.0102997,,,,
,22781111.2,245.8916321,99.5330276489258,,,2,,,,15.7899997764826,,,,,,,245.8916321,245.8916321,99.5330276489258,99.5330276489258,,,21.01075,,,,-99999999,4374,250.0314,99.5330276489258,,,,,,,,,,,,,,,,,,,,,,,245.8916321,,,,
,22781235.135,249.00260925,99.5330276489258,2.10168967298362E-5,4.14321258350725E-7,1,0.999253354069792,40.0298881530762,1.99959742276746,15.7900005578995,0.000239276628673974,3.61572361415787E-5,0.25,-4.56787006416766E-7,2.10549190166797E-5,-4.40480986138798E-7,248.9724731,249.0327454,99.5330276489258,99.5330276489258,56.8392442899483,20.6711499885605,20.631098,0,0,0,40,4374,253.12695,99.5330276489258,,,,,,,,,,,,,0,,,,0,,,,,,249.00260925,,,,
,22781374.965,252.50093075,99.5330276489258,2.09947872514676E-5,3.78464551936706E-7,1,0.999253354069792,40.0298881530762,1.99970890345539,15.7800000160933,0.000238299348188718,4.02039005719555E-5,0.25,-9.56472135914433E-8,2.10298806770801E-5,-7.89808432717503E-8,252.4752197,252.5266418,99.5330276489258,99.5330276489258,56.7735874943329,20.6605230013991,21.01075,0,0,0,40,4374,256.6289,99.5330276489258,,,,,,,,,,,,,0,,,,0.00245,,,,,,252.50093075,,,,
,22781527.78,256.2922363,99.5330276489258,,,2,,,,15.7300002509356,,,,,,,256.2922363,256.2922363,99.5330276489258,99.5330276489258,,,21.3904,,,,-99999999,4374,260.4693,99.5330276489258,,,,,,,,,,,,,,,,,,,,,,,256.2922363,,,,
,22781659.285,259.5379639,99.5330276489258,2.09575213758216E-5,4.3928467533077E-7,1,0.999253354069792,40.0298881530762,1.99962513194616,15.7200004905462,0.000238107440674336,3.83912363110535E-5,0.25,-2.4749053764615E-7,2.09874373867003E-5,-2.31591611672825E-7,259.5379639,259.5379639,99.5330276489258,99.5330276489258,56.9377294833714,20.6576133661397,21.01075,0,0,0,40,4374,263.77685,99.5330276489258,,,,,,,,,,,,,0,,,,0,,,,,,259.5379639,,,,
,22781800.065,263.0083313,99.5330276489258,2.11081919578048E-5,3.85442444201289E-7,1,0.999253354069792,40.0298881530762,1.99979624698061,15.7200004905462,0.000239929237694462,3.7973419925453E-5,0.25,-3.10062888208822E-7,2.11357589532217E-5,-2.94359880751449E-7,263.0083313,263.0083313,99.5330276489258,99.5330276489258,56.7837486650829,20.6592216557882,21.01075,0,0,0,40,4374,267.3412,99.5330276489258,,,,,,,,,,,,,0,,,,-0.0049,,,,,,263.0083313,,,,
,22781950.16,266.6541748,99.5330276489258,,,2,,,,15.6600001835823,,,,,,,266.6541748,266.6541748,99.5330276489258,99.5330276489258,,,20.631098,,,,-99999999,4374,271.1631,99.5330276489258,,,,,,,,,,,,,,,,,,,,,,,266.6541748,,,,
,22782087.235,270.0553894,99.5330276489258,2.03218560863396E-5,3.66145776464578E-7,1,0.999253354069792,40.0298881530762,1.99983561371645,15.650000423193,0.000231302398411486,3.44449609168316E-5,0.25,-4.8375812134155E-7,2.03434141422182E-5,-4.69251519771605E-7,270.0553894,270.0553894,99.5330276489258,99.5330276489258,56.8439340610637,20.6592216234598,21.01075,0,0,0,40,4374,274.6154,99.5330276489258,,,,,,,,,,,,,0,,,,0.0049,,,,,,270.0553894,,,,
,22782226.635,273.546051,99.5330276489258,2.04602403518184E-5,3.9592481560208E-7,1,0.999253354069792,40.0298881530762,2.00032486626641,15.650000423193,0.000233228633352675,3.28029185954806E-5,0.25,-6.52695977818037E-7,2.04795048573776E-5,-6.38408769664434E-7,273.546051,273.546051,99.5330276489258,99.5330276489258,56.9799374234099,20.6548682618301,21.770052,0,0,0,40,4374,278.08395,99.5330276489258,,,,,,,,,,,,,0,,,,0,,,,,,273.546051,,,,
,22782369.42,277.0623474,99.5330276489258,,,2,,,,15.5999997267127,,,,,,,277.0623474,277.0623474,99.5330276489258,99.5330276489258,,,21.770052,,,,-99999999,4374,281.6802,99.5330276489258,,,,,,,,,,,,,,,,,,,,,,,277.0623474,,,,
,22782489.665,280.0135193,99.5330276489258,1.95376513885262E-5,3.88347626392168E-7,1,0.999253354069792,40.0298881530762,1.99993894606944,15.5899999663234,0.000220992801056047,4.06957224021262E-5,0.25,2.05332191060391E-7,1.9550923237878E-5,2.19289709389281E-7,280.0135193,280.0135193,99.5330276489258,99.5330276489258,57.2222422643714,20.6537621212853,21.3904,0,0,0,40,4374,284.731,99.5330276489258,,,,,,,,,,,,,0,,,,-0.00245,,,,,,280.0135193,,,,
,22782632.305,283.5449524,99.5330276489258,1.94977503640456E-5,3.22739524645517E-7,1,0.999253354069792,40.0298881530762,1.99996802761553,15.5899999663234,0.000221711940520183,3.37106595144245E-5,0.25,-4.03626463031388E-7,1.9508953681759E-5,-3.90271171532197E-7,283.5449524,283.5449524,99.5330276489258,99.5330276489258,57.058100275333,20.6525447717568,21.770052,0,0,0,40,4374,288.3289,99.5330276489258,,,,,,,,,,,,,0,,,,0,,,,,,283.5449524,,,,
,22782769.36,287.0007935,99.5330276489258,1.93489094064857E-5,4.22759516309971E-7,1,0.999253354069792,40.0298881530762,1.99997137156701,15.5899999663234,0.00021910421976928,3.857546290996E-5,0.25,5.21238906097415E-8,1.93573156198876E-5,6.54358910992004E-8,287.0007935,287.0007935,99.5330276489258,99.5330276489258,57.0213637349291,20.6546966646051,21.770052,0,0,0,40,4374,291.7228,99.5330276489258,,,,,,,,,,,,,0,,,,0,,,,,,287.0007935,,,,
,22782891.36,290.0431213,99.5330276489258,1.92945966815966E-5,3.62977529552346E-7,1,0.999253354069792,40.0298881530762,1.99996179429718,15.5300004407763,0.000219822976520775,3.06221931210127E-5,0.25,-6.40012646406405E-7,1.93013460987521E-5,-6.27134505991082E-7,290.0431213,290.0431213,99.5330276489258,99.5330276489258,56.709493955756,20.6547143247574,21.770052,0,0,0,40,4374,294.768,99.5330276489258,,,,,,,,,,,,,0,,,,-0.00245,,,,,,290.0431213,,,,
,22783033.1,293.5388489,99.5330276489258,1.94205644162021E-5,3.69855373673295E-7,1,0.999253354069792,40.0298881530762,2.0001267761021,15.5300004407763,0.00022022044053172,3.67500056095089E-5,0.25,-1.20552153024486E-7,1.94245712256922E-5,-1.07591987731653E-7,293.5388489,293.5388489,99.5330276489258,99.5330276489258,56.9564885678329,20.6528652514317,21.3904,0,0,0,40,4374,298.3325,99.5330276489258,,,,,,,,,,,,,0,,,,-0.0049,,,,,,293.5388489,,,,
,22783172.755,297.0267029,99.5330276489258,1.9040206796472E-5,4.99848291555474E-7,1,0.999253354069792,40.0298881530762,2.00013232408705,15.54000005126,0.000216602564125577,3.18610328278146E-5,0.25,-4.85737286039925E-7,1.90420011957717E-5,-4.73221404066788E-7,297.0267029,297.0267029,99.5330276489258,99.5330276489258,56.9400743689291,20.6503821663597,22.149702,0,0,0,40,4374,301.8393,99.5330276489258,,,,,,,,,,,,,0,,,,-0.00245,,,,,,297.0267029,,,,
,22783314.575,300.5129547,99.5330276489258,1.85184855105904E-5,4.01751760853395E-7,1,0.999253354069792,40.0298881530762,2.00005551308444,15.4699999839067,0.000208976520635676,4.05469308705047E-5,0.25,3.72298342131846E-7,1.85173716584559E-5,3.84319676396305E-7,300.4849548,300.5409546,99.5330276489258,99.5330276489258,56.9189703989099,20.6482426192425,21.3904,0,0,0,40,4374,305.424,99.5330276489258,,,,,,,,,,,,,0,,,,0.00245,,,,,,300.5129547,,,,
,22783456.835,304.0090332,99.5330276489258,1.84990372848277E-5,4.51172858406814E-7,1,0.999253354069792,40.0298881530762,1.99998266326584,15.4699999839067,0.000210192045550621,3.20226187745264E-5,0.25,-3.76469103948875E-7,1.84961019506571E-5,-3.64543713783175E-7,304.0090332,304.0090332,99.5330276489258,99.5330276489258,56.8408075469868,20.6498903868811,22.149702,0,0,0,40,4374,309.0092,99.5330276489258,,,,,,,,,,,,,0,,,,0,,,,,,304.0090332,,,,
,22783600.565,307.5439758,99.5330276489258,1.80440298873992E-5,4.045781127051E-7,1,0.999253354069792,40.0298881530762,2.00002204209578,15.4699999839067,0.000204601353275259,3.35336538182004E-5,0.25,-1.63714850280354E-7,1.80387654306451E-5,-1.52256083044628E-7,307.5439758,307.5439758,99.5330276489258,99.5330276489258,56.872072687756,20.6493685259098,21.770052,0,0,0,40,4374,312.6502,99.5330276489258,,,,,,,,,,,,,0,,,,-0.00245,,,,,,307.5439758,,,,
,22783740.345,311.0030823,99.5330276489258,1.76430271288167E-5,4.75749081793334E-7,1,0.999253354069792,40.0298881530762,2.00009661721867,15.4100004583597,0.000201844429002355,2.23507205933374E-5,0.25,-1.08171820748174E-6,1.76362871308744E-5,-1.07025213200282E-6,311.0030823,311.0030823,99.5330276489258,99.5330276489258,56.9986965078714,20.6492367464896,21.770052,0,0,0,40,4374,316.1552,99.5330276489258,,,,,,,,,,,,,0,,,,0.0049,,,,,,311.0030823,,,,
,22783883.27,314.5392151,99.5330276489258,1.71918177371087E-5,4.15561695271271E-7,1,0.999253354069792,40.0298881530762,2.00017097705108,15.4100004583597,0.000195108022113754,3.07638996429604E-5,0.25,-2.59977776531743E-7,1.71826002748225E-5,-2.49247139154111E-7,314.5392151,314.5392151,99.5330276489258,99.5330276489258,57.004167907506,20.6488755746418,22.149702,0,0,0,40,4374,319.76535,99.5330276489258,,,,,,,,,,,,,0,,,,0,,,,,,314.5392151,,,,
,22784023.24,318.0100403,99.5330276489258,1.75664886609865E-5,3.91707364647455E-7,1,0.999253354069792,40.0298881530762,2.00021309433458,15.4100004583597,0.000200089908747425,2.70995700259137E-5,0.25,-6.482195005956E-7,1.75551490914257E-5,-6.37103257637542E-7,318.0100403,318.0100403,99.5330276489258,99.5330276489258,56.9361662263329,20.6470415578112,21.770052,0,0,0,40,4374,323.29585,99.5330276489258,,,,,,,,,,,,,0,,,,0.0049,,,,,,318.0100403,,,,
,22784166.345,321.52087405,99.5330276489258,1.69445037699006E-5,4.20123048553756E-7,1,0.999253354069792,40.0298881530762,2.00015756106003,15.3500000014901,0.000192341102370013,2.98031407286903E-5,0.25,-3.01093531825321E-7,1.69312739216417E-5,-2.90680290053675E-7,321.4934998,321.5482483,99.5330276489258,99.5330276489258,56.7462304961599,20.6422092087953,21.3904,0,0,0,40,4374,326.9083,99.5330276489258,,,,,,,,,,,,,0,,,,0.0049,,,,,,321.52087405,,,,
,22784308.19,325.0361328,99.5330276489258,1.64628359795049E-5,4.28296447895374E-7,1,0.999253354069792,40.0298881530762,2.00020264802766,15.3500000014901,0.000186250331202647,3.24417036879687E-5,0.25,1.59030384461E-8,1.64477692387801E-5,2.56535917946081E-8,325.0361328,325.0361328,99.5330276489258,99.5330276489258,57.0190188493714,20.6453370553915,21.770052,0,0,0,40,4374,330.481,99.5330276489258,,,,,,,,,,,,,0,,,,0.0049,,,,,,325.0361328,,,,
,22784449.525,328.5331726,99.5330276489258,1.6774798445152E-5,4.63122300062602E-7,1,0.999253354069792,40.0298881530762,2.00030052161515,15.3500000014901,0.000190458859597046,2.90494887432644E-5,0.25,-3.37604900017809E-7,1.67576065663721E-5,-3.2742278077406E-7,328.5331726,328.5331726,99.5330276489258,99.5330276489258,56.9283499411406,20.6426862239025,22.149702,0,0,0,40,4374,334.04,99.5330276489258,,,,,,,,,,,,,0,,,,0,,,,,,328.5331726,,,,
,22784570.75,331.5238647,99.5330276489258,1.6718447132308E-5,3.87914612330397E-7,1,0.999253354069792,40.0298881530762,2.00022715484632,15.2899995446205,0.000190434360265134,2.52422567321246E-5,0.25,-6.63932210127071E-7,1.66997634432985E-5,-6.53472926905772E-7,331.5238647,331.5238647,99.5330276489258,99.5330276489258,57.0964000727753,20.647355052253,22.149702,0,0,0,40,4374,337.0847,99.5330276489258,,,,,,,,,,,,,0,,,,0.00245,,,,,,331.5238647,,,,
,22784709.93,335.0022278,99.5330276489258,1.58267146023277E-5,3.88434424771138E-7,1,0.999253354069792,40.0298881530762,2.00039796872806,15.2899995446205,0.000179402776309421,2.89020307791999E-5,0.25,-1.85800325089607E-7,1.58068645331633E-5,-1.76483314503306E-7,335.0022278,335.0022278,99.5330276489258,99.5330276489258,57.088583787583,20.6450973521221,22.529354,0,0,0,40,4374,340.582,99.5330276489258,,,,,,,,,,,,,0,,,,0,,,,,,335.0022278,,,,
,22784853.995,338.5471497,99.5330276489258,1.60821948703968E-5,3.80393705090812E-7,1,0.999253354069792,40.0298881530762,2.00036149870076,15.2899995446205,0.000182888213255322,2.58133934641363E-5,0.25,-5.02650909813868E-7,1.60602389564388E-5,-4.92828985795663E-7,338.5471497,338.5471497,99.5330276489258,99.5330276489258,56.9447641400445,20.6455109992161,21.770052,0,0,0,40,4374,344.19935,99.5330276489258,,,,,,,,,,,,,0,,,,0.0049,,,,,,338.5471497,,,,
,22784973.23,341.5061646,99.5330276489258,1.6455000772747E-5,4.69915645868712E-7,1,0.999253354069792,40.0298881530762,2.0002905238735,15.2300000190735,0.000187137038926536,2.62084070317812E-5,0.25,-5.31886975486264E-7,1.6430875691659E-5,-5.21842313841978E-7,341.5061646,341.5061646,99.5330276489258,99.5330276489258,56.8548768603329,20.6416064057391,22.529354,0,0,0,40,4374,347.1859,99.5330276489258,,,,,,,,,,,,,0,,,,-0.0049,,,,,,341.5061646,,,,
,22785115.51,345.0481262,99.5330276489258,1.55652281967653E-5,4.10646866369157E-7,1,0.999253354069792,40.0298881530762,2.00036081044118,15.2300000190735,0.000177223391520484,2.35132166959531E-5,0.25,-6.15860090225147E-7,1.55405896654063E-5,-6.06207496656928E-7,345.0481262,345.0481262,99.5330276489258,99.5330276489258,57.0393411908714,20.642562922875,22.149702,0,0,0,40,4374,350.77595,99.5330276489258,,,,,,,,,,,,,0,,,,0,,,,,,345.0481262,,,,
,22785316.175,348.5050049,99.5330276489258,1.51420974182819E-5,3.17808483251238E-7,1,0.999253354069792,40.0298881530762,2.00045029034103,15.2300000190735,0.000171385743229411,2.8688261413558E-5,0.25,-8.47617021568782E-8,1.5116065420798E-5,-7.62017889956664E-8,348.5050049,348.5050049,99.5330276489258,99.5330276489258,56.8376810329099,20.6424895195752,22.149702,0,0,0,40,4374,351.3585,99.5330276489258,,,,,,,,,,,,,0,,,,0.00245,,,,,,348.5050049,,,,
,22785695.655,349.8659668,99.5330276489258,1.51199761178112E-5,3.8186068840461E-7,1,0.999253354069792,40.0298881530762,2.00069407279555,15.1699995622039,0.000172583589770069,2.03537501505683E-5,0.25,-8.18117975170903E-7,1.50936943295493E-5,-8.08285728798886E-7,349.8659668,349.8659668,99.5330276489258,99.5330276489258,56.946327397083,20.6440456940637,22.149702,0,0,0,40,4369,352.0286,99.5330276489258,,,,,,,,,,,,,0,,,,0,,,,,,349.8659668,,,,