File: data/doubleLayers/dl_1-25/ppms/KoelnPPMS/DD205_3_HYST_100OE_100K.DAT
[Header]
; VSM Data File (default extension .dat)
; Copyright (c) 2003-2013, Quantum Design, Inc. All rights reserved.
TITLE,
FILEOPENTIME,22216493.63,09/15/2018,12:13 pm
BYAPP,VSM,2.0,2.0
INFO,PPMS VSM Option Release 1.4.10 Build 1,APPNAME
INFO,Quantum Design Linear Motor Servo Controller,MOTOR_MODULE_NAME
INFO,3101-100 M1,MOTOR_HW_VERSION
INFO,MMC1014,MOTOR_SERIAL_NUMBER
INFO,SRV No X-over 01.03.11,MOTOR_SOFTWARE_VERSION
INFO,Quantum Design VSM Detection Module,VSM_MODULE_NAME
INFO,3101-150 F0,VSM_HW_VERSION
INFO,VSM707,VSM_SERIAL_NUMBER
INFO,VSM No X-over 01.02.05 May 20 2008 13:51:47,VSM_SOFTWARE_VERSION
INFO,704,PREAMP_SERIAL_NUMBER
INFO,822,COIL_SERIAL_NUMBER
INFO,0,MOMENT_UNITS
INFO,CoFe2O4,SAMPLE_MATERIAL
INFO,Double Layer blue,SAMPLE_COMMENT
INFO,,SAMPLE_MASS
INFO,,SAMPLE_VOLUME
INFO,,SAMPLE_MOLECULAR_WEIGHT
INFO,,SAMPLE_SIZE
INFO,,SAMPLE_SHAPE
DATATYPE,COMMENT,1
DATATYPE,TIME,2
STARTUPAXIS,X,2
STARTUPAXIS,Y1,5
[Data]
Comment,Time Stamp (sec),Temperature (K),Magnetic Field (Oe),Moment (emu),M. Std. Err. (emu),Transport Action,Averaging Time (sec),Frequency (Hz),Peak Amplitude (mm),Center Position (mm),Coil Signal' (mV),Coil Signal" (mV),Range (mV),M. Quad. Signal (emu),M. Raw' (emu),M. Raw" (emu),Min. Temperature (K),Max. Temperature (K),Min. Field (Oe),Max. Field (Oe),Mass (grams),Motor Lag (deg),Pressure (Torr),VSM Status (code),Motor Status (code),Measure Status (code),Measure Count,PPMS Status (code),System Temp. (K),System Field (Oe),Sample Position (deg),Bridge 1 Resistance (ohms),Bridge 1 Excitation (에),Bridge 2 Resistance (ohms),Bridge 2 Excitation (에),Bridge 3 Resistance (ohms),Bridge 3 Excitation (에),Bridge 4 Resistance (ohms),Bridge 4 Excitation (에),Signal 1 Vin (V),Signal 2 Vin (V),Digital Inputs (code),Drive 1 Iout (mA),Drive 1 Ipower (W),Drive 2 Iout (mA),Drive 2 Ipower (W),Pressure (),Map 20 (),Map 21 (),Map 22 (),Map 23 (),Map 24 (),Map 25 (),Map 26 (),Map 27 (),Map 28 (),Map 29 ()
,22216509.3,100.2544479,0.121790185570717,,,2,,,,16.9800000751019,,,,,,,100.2544479,100.2544479,0.121790185570717,0.121790185570717,,,22.909004,,,,-99999999,4369,100.5863,0.121790185570717,,,,,,,,,,,,,,,,,,,,,,,100.2544479,,,,
,22216657.275,100.1420517,4416.6611328125,6.51890015938295E-5,4.80286961964897E-7,1,0.999253354069792,40.0298881530762,1.99789812432635,16.9699992984533,0.000738873867176874,0.000144284684517453,0.25,1.23181435562329E-6,6.55526262092553E-5,1.4395147545102E-6,100.1420517,100.1420517,4411.77587890625,4421.54638671875,56.1498479359867,20.5320283901538,22.909004,0,0,0,40,4449,100.3767,4416.6611328125,,,,,,,,,,,,,0,,,,0,,,,,,100.1420517,,,,
,22216750.82,100.0805588,9090.140625,5.56703667540505E-5,5.24416798291319E-7,1,0.999253354069792,40.0298881530762,1.99791655530247,16.9699992984533,0.000631675970014688,0.00011934998174334,0.25,7.12383773494133E-7,5.59823050976767E-5,8.87222480710045E-7,100.0805588,100.0805588,9082.7509765625,9097.5302734375,56.1099848815059,20.5280685899588,22.909004,0,0,0,40,4449,100.32825,9090.140625,,,,,,,,,,,,,0,,,,0.0049,,,,,,100.0805588,,,,
,22216841.095,100.0419388,13602.9506835938,4.47532552000175E-5,7.78701496304828E-7,1,0.999253354069792,40.0298881530762,1.99788691922907,16.9699992984533,0.000508609746103392,9.13300232102295E-5,0.25,1.67527080035307E-7,4.50055776182788E-5,3.05186733990043E-7,100.0419388,100.0419388,13600.451171875,13605.4501953125,56.262402442756,20.5326032413681,22.909004,0,0,0,40,4449,100.30655,13602.9506835938,,,,,,,,,,,,,0,,,,-0.0049,,,,,,100.0419388,,,,
,22216941.495,100.0216675,18620.1572265625,3.31955020402928E-5,8.91287034454606E-7,1,0.999253354069792,40.0298881530762,1.99793844784389,16.9699992984533,0.000376727363983029,7.08400252825707E-5,0.25,3.96892549656524E-7,3.33820980607985E-5,4.99989154096784E-7,100.0216675,100.0216675,18607.59375,18632.720703125,56.4077853473329,20.5344627990734,23.288654,0,0,0,40,4449,100.29335,18620.1572265625,,,,,,,,,,,,,0,,,,0.00245,,,,,,100.0216675,,,,
,22217039.015,100.0117264,23494.8154296875,2.00096808608257E-5,9.89587483549679E-7,1,0.999253354069792,40.0298881530762,1.99800095509504,16.9699992984533,0.00022596826423922,4.91076062595961E-5,0.25,8.02740302631876E-7,2.01206178195003E-5,8.67734195820431E-7,100.0117264,100.0117264,23489.798828125,23499.83203125,56.6719757868329,20.5323969240259,22.909004,0,0,0,40,4449,100.28535,23494.8154296875,,,,,,,,,,,,,0,,,,-0.0049,,,,,,100.0117264,,,,
,22217130.695,100.0082626,28077.7060546875,2.91843038808838E-6,8.95157344101107E-7,1,0.999253354069792,40.0298881530762,1.99806339845193,16.9699992984533,3.29854789848707E-5,7.0115162101802E-6,0.25,1.03840209573761E-7,2.93467435559507E-6,1.13196302749538E-7,100.0082626,100.0082626,28072.763671875,28082.6484375,57.0674798175637,20.5350042756852,23.668306,0,0,0,40,4449,100.27955,28077.7060546875,,,,,,,,,,,,,0,,,,-0.00245,,,,,,100.0082626,,,,
,22217228.21,100.0026321,32947.794921875,-1.15624303628794E-5,1.12970318071856E-6,1,0.999253354069792,40.0298881530762,1.99797234948147,16.9699992984533,-0.000136228243821907,3.81455927664564E-6,0.25,2.36617024656227E-6,-1.16351825581913E-5,2.3450938249578E-6,100.0026321,100.0026321,32940.41796875,32955.171875,56.6446187886598,20.5321365124724,23.288654,0,0,0,40,4449,100.2788,32947.794921875,,,,,,,,,,,,,0,,,,0.00245,,,,,,100.0026321,,,,
,22217332.72,100.0042267,38172.2578125,-2.702414306946E-5,1.42608035562728E-6,1,0.999253354069792,40.0298881530762,1.99804991950658,16.9699992984533,-0.000311074407016857,-3.28606602145036E-5,0.25,1.85666660816471E-6,-2.71834149771264E-5,1.78709842718379E-6,100.0042267,100.0042267,38162.16796875,38182.34765625,56.6837002146214,20.5345376209594,23.288654,0,0,0,40,4449,100.2767,38172.2578125,,,,,,,,,,,,,0,,,,0,,,,,,100.0042267,,,,
,22217437.6,100.0084763,43414.712890625,-4.56516956128869E-5,1.38026839344406E-6,1,0.999253354069792,40.0298881530762,1.99802191563791,16.9699992984533,-0.000533037765374688,-1.25413143035164E-5,0.25,6.91349744192529E-6,-4.59322087443374E-5,6.81845256102223E-6,100.0084763,100.0084763,43404.79296875,43424.6328125,56.9619599674676,20.5330953506936,23.288654,0,0,0,40,4449,100.26775,43414.712890625,,,,,,,,,,,,,0,,,,-0.00245,,,,,,100.0084763,,,,
,22217541.455,100.0145798,48607.361328125,-6.5886431617582E-5,1.35525208554848E-6,1,0.999253354069792,40.0298881530762,1.99794243987101,16.9699992984533,-0.000760927262908128,-6.56579692199202E-5,0.25,5.79497367954222E-6,-6.62794032592886E-5,5.63533091833575E-6,100.0145798,100.0145798,48597.49609375,48617.2265625,56.6602513590445,20.5333065004495,23.288654,0,0,0,40,4449,100.25265,48607.361328125,,,,,,,,,,,,,0,,,,-0.00245,,,,,,100.0145798,,,,
,22217651.32,100.0206299,54097.255859375,-7.78195091141226E-5,1.6047650408427E-6,1,0.999253354069792,40.0298881530762,1.99811844694051,16.9699992984533,-0.000879565559333614,-0.000187264613078296,0.25,-2.80214123577156E-6,-7.82561809721221E-5,-3.0441479646558E-6,100.0206299,100.0206299,54084.7890625,54109.72265625,56.770460980256,20.5350572662401,23.288654,0,0,0,40,4449,100.2281,54097.255859375,,,,,,,,,,,,,0,,,,0,,,,,,100.0206299,,,,
,22217752.525,100.0232162,59154.638671875,-9.84137841078247E-5,1.46495238489198E-6,1,0.999253354069792,40.0298881530762,1.99816287189519,16.9699992984533,-0.00111992083577598,-0.000193804485739492,0.25,2.36845880574621E-7,-9.89777994367124E-5,-4.56704972214233E-8,100.0232162,100.0232162,59147.25390625,59162.0234375,56.6149169049291,20.5334394330856,22.909004,0,0,0,40,4449,100.208,59154.638671875,,,,,,,,,,,,,0,,,,-0.00245,,,,,,100.0232162,,,,
,22217856.095,100.0233994,64329.650390625,-0.000117811039858104,1.86103156614676E-6,1,0.999253354069792,40.0298881530762,1.99785734644526,16.9699992984533,-0.00134882485687073,-0.000184376435550717,0.25,4.46593982718364E-6,-0.0001184991809801,4.15406604894627E-6,100.0233994,100.0233994,64324.7421875,64334.55859375,56.780622151006,20.5336528493899,23.668306,0,0,0,40,4449,100.1836,64329.650390625,,,,,,,,,,,,,0,,,,0,,,,,,100.0233994,,,,
,22217949.805,100.0200882,69015.28515625,-0.000131539109500463,1.90384039747607E-6,1,0.999253354069792,40.0298881530762,1.99820883151831,16.9699992984533,-0.00150319790063089,-0.000223354013635434,0.25,3.44932882279287E-6,-0.000132303978198131,3.09472825520746E-6,100.0200882,100.0200882,69012.75,69017.8203125,56.6696309012752,20.5324165869821,23.668306,0,0,0,40,4449,100.1642,69015.28515625,,,,,,,,,,,,,0,,,,0,,,,,,100.0200882,,,,
,22218042.835,100.0183487,73664.48046875,-0.000150482656350502,1.78232099800819E-6,1,0.999253354069792,40.0298881530762,1.99790952795254,16.9699992984533,-0.00171480439795273,-0.000281940781552197,0.25,1.61736299983007E-6,-0.000151352168252744,1.20111037945286E-6,100.0183487,100.0183487,73659.4453125,73669.515625,56.739977468006,20.5312542856535,23.668306,0,0,0,40,4449,100.15105,73664.48046875,,,,,,,,,,,,,0,,,,0,,,,,,100.0183487,,,,
,22218138.65,100.0150909,78455.90234375,-0.000160884476625341,2.2698132423478E-6,1,0.999253354069792,40.0298881530762,1.99815758887136,16.9699992984533,-0.00181947010260347,-0.000381817881866211,0.25,-5.33741444746049E-6,-0.000161795467956523,-5.820052392969E-6,100.0150909,100.0150909,78443.2421875,78468.5625,56.8048526351022,20.53308370649,23.288654,0,0,0,40,4449,100.1363,78455.90234375,,,,,,,,,,,,,0,,,,-0.00245,,,,,,100.0150909,,,,
,22218239.21,100.0086899,83481.8984375,-0.000176569652027869,1.98701473680053E-6,1,0.999253354069792,40.0298881530762,1.99816193838383,16.9699992984533,-0.00200473467562748,-0.000374264765494577,0.25,-1.92459531037021E-6,-0.00017758201610032,-2.42810499445781E-6,100.0086899,100.0086899,83476.828125,83486.96875,56.6704125297944,20.5360283032959,23.668306,0,0,0,40,4449,100.1279,83481.8984375,,,,,,,,,,,,,0,,,,0,,,,,,100.0086899,,,,
,22218327.62,100.0024643,87902.125,-0.00019447478314501,1.89617771642783E-6,1,0.999253354069792,40.0298881530762,1.99814421004176,16.9699992984533,-0.00220759045857645,-0.000414686482625582,0.25,-2.34035522865014E-6,-0.000195590674902552,-2.89269895366563E-6,100.0024643,100.0024643,87894.609375,87909.640625,56.6930797568522,20.5329755317286,23.668306,0,0,0,40,4449,100.1288,87902.125,,,,,,,,,,,,,0,,,,0.00245,,,,,,100.0024643,,,,
,22218440.785,99.9943924,87495.58203125,-0.000197153549632387,2.47422606504356E-6,1,0.999253354069792,40.0298881530762,1.99807455408841,16.9699992984533,-0.00223304899026274,-0.000448170884831467,0.25,-4.81504015686916E-6,-0.000198277955832991,-5.38937258016717E-6,99.9943924,99.9943924,87488.265625,87502.8984375,56.7837486650829,20.5300788630193,24.047956,0,0,0,40,4449,100.13355,87495.58203125,,,,,,,,,,,,,0,,,,0.0049,,,,,,99.9943924,,,,
,22218537.445,99.9928436,82662.41015625,-0.00017959658071721,2.46250633436857E-6,1,0.999253354069792,40.0298881530762,1.99814512337572,16.9699992984533,-0.0020460007626662,-0.00034125061868704,0.25,1.50884297977196E-6,-0.000180635838359145,1.01620708160973E-6,99.9928436,99.9928436,82649.765625,82675.0546875,56.4679707433137,20.5306478903828,23.288654,0,0,0,40,4449,100.14415,82662.41015625,,,,,,,,,,,,,0,,,,-0.0049,,,,,,99.9928436,,,,
,22218635.745,99.9981308,77748.91796875,-0.000165362354688779,2.40680818152124E-6,1,0.999253354069792,40.0298881530762,1.99815150943104,16.9699992984533,-0.00188449715689774,-0.000310413195699334,0.25,1.72568622080431E-6,-0.000166318852497203,1.270707252227E-6,99.9981308,99.9981308,77736.3203125,77761.515625,56.7735874943329,20.5328131849897,23.288654,0,0,0,40,4449,100.14505,77748.91796875,,,,,,,,,,,,,0,,,,0.00245,,,,,,99.9981308,,,,
,22218738.155,99.9999619,72627.65625,-0.000144021647489395,1.93410494477744E-6,1,0.999253354069792,40.0298881530762,1.99830680697504,16.9699992984533,-0.00164235049032793,-0.000264971195967118,0.25,1.9806390419455E-6,-0.000144854845338268,1.58408864339802E-6,99.9999619,99.9999619,72622.6953125,72632.6171875,57.1182856713137,20.5332806431832,23.668306,0,0,0,40,4449,100.1444,72627.65625,,,,,,,,,,,,,0,,,,-0.0049,,,,,,99.9999619,,,,
,22218838.16,100.0005875,67630.29296875,-0.000125797311892805,2.13820746204262E-6,1,0.999253354069792,40.0298881530762,1.99804924166026,16.9699992984533,-0.00142934953666855,-0.000259854417618942,0.25,-7.6798313370758E-7,-0.000126516915834083,-1.13128636851398E-6,100.0005875,100.0005875,67625.265625,67635.3203125,56.8243933480829,20.5302557769783,23.668306,0,0,0,40,4449,100.14205,67630.29296875,,,,,,,,,,,,,0,,,,-0.00245,,,,,,100.0005875,,,,
,22218940.95,100.0035706,62490.00390625,-0.000107286259792886,1.49125745229295E-6,1,0.999253354069792,40.0298881530762,1.99833843756568,16.9699992984533,-0.00121986298401307,-0.00021774617863661,0.25,-3.09951089803271E-7,-0.000107900001512184,-6.2007362582351E-7,100.0035706,100.0035706,62482.5078125,62497.5,56.6375841319868,20.5370853740153,23.288654,0,0,0,40,4449,100.14025,62490.00390625,,,,,,,,,,,,,0,,,,0,,,,,,100.0035706,,,,
,22219042.67,100.0014114,57406.416015625,-8.89402557550245E-5,2.0962752235147E-6,1,0.999253354069792,40.0298881530762,1.99823367614448,16.9699992984533,-0.0010126047605584,-0.000172535176316496,0.25,4.45161901051308E-7,-8.94502989287558E-5,1.90236638497394E-7,100.0014114,100.0014114,57403.8125,57409.01953125,56.7728058658137,20.5353417189536,23.288654,0,0,0,40,4449,100.1379,57406.416015625,,,,,,,,,,,,,0,,,,0.0049,,,,,,100.0014114,,,,
,22219142.86,100.00152205,52398.994140625,-7.44981756492509E-5,1.34316956519485E-6,1,0.999253354069792,40.0298881530762,1.99813702846606,16.9699992984533,-0.00084679771202047,-0.000152111966874072,0.25,-2.93848469095724E-7,-7.49228190250772E-5,-5.12705277101578E-7,100.0014877,100.0015564,52391.66796875,52406.3203125,56.9588334533906,20.5337023928785,23.668306,0,0,0,40,4449,100.13765,52398.994140625,,,,,,,,,,,,,0,,,,0,,,,,,100.00152205,,,,
,22219236.075,99.9983139,47741.63671875,-6.05028932257981E-5,1.76276518750019E-6,1,0.999253354069792,40.0298881530762,1.9981220767494,16.9699992984533,-0.000695835930702825,-7.72390980890396E-5,0.25,3.83261250610768E-6,-6.08592230048143E-5,3.67696142127022E-6,99.9983139,99.9983139,47739.265625,47744.0078125,56.6454004171791,20.5328208444235,23.668306,0,0,0,40,4449,100.13955,47741.63671875,,,,,,,,,,,,,0,,,,0,,,,,,99.9983139,,,,
,22219329.77,99.9968529,43058.681640625,-4.39233052944012E-5,1.49523578206752E-6,1,0.999253354069792,40.0298881530762,1.99818670830871,16.9699992984533,-0.000505237560082944,-5.56809728078797E-5,0.25,2.81779219446267E-6,-4.41817947217165E-5,2.70415399210876E-6,99.9966202,99.9970856,43056.1796875,43061.18359375,56.8556584888522,20.5362385878296,23.668306,0,0,0,40,4449,100.14155,43058.681640625,,,,,,,,,,,,,0,,,,-0.0049,,,,,,99.9968529,,,,
,22219422.815,99.9948578,38406.109375,-2.95194238201528E-5,1.5385462969608E-6,1,0.999253354069792,40.0298881530762,1.99811883466799,16.9699992984533,-0.000331183933567933,-8.5002872840835E-5,0.25,-2.28916795919583E-6,-2.96805216221394E-5,-2.38988470966038E-6,99.9948578,99.9948578,38398.625,38413.59375,57.0198004778906,20.5336933876123,23.668306,0,0,0,40,4449,100.14615,38406.109375,,,,,,,,,,,,,0,,,,0,,,,,,99.9948578,,,,
,22219516.86,99.99472425,33709.115234375,-1.26454562452354E-5,1.43509229906527E-6,1,0.999253354069792,40.0298881530762,1.99823933110087,16.9699992984533,-0.00014135696780366,-3.93849938518816E-5,0.25,-1.24149993054096E-6,-1.27135698667373E-5,-1.28634664690702E-6,99.994606,99.9948425,33701.61328125,33716.6171875,57.0323065341983,20.5355602096483,24.047956,0,0,0,40,4449,100.15345,33709.115234375,,,,,,,,,,,,,0,,,,0,,,,,,99.99472425,,,,
,22219612.885,99.9936981,28908.9482421875,1.64240458561205E-6,1.0092485513462E-6,1,0.999253354069792,40.0298881530762,1.99802227666734,16.9699992984533,9.93956202414493E-6,5.30372598584501E-5,0.25,4.37480625778288E-6,1.63856473827809E-6,4.4045582651379E-6,99.9936981,99.9936981,28903.931640625,28913.96484375,56.6289862182752,20.5353255248536,24.047956,0,0,0,40,4449,100.15855,28908.9482421875,,,,,,,,,,,,,0,,,,-0.00245,,,,,,99.9936981,,,,
,22219705.725,99.990799,24266.2470703125,1.61818861933511E-5,1.0144729669454E-6,1,0.999253354069792,40.0298881530762,1.99799197220006,16.9699992984533,0.000181320896880494,4.7792341747209E-5,0.25,1.35949881290918E-6,1.62694346221356E-5,1.41613512984505E-6,99.990799,99.990799,24256.19140625,24276.302734375,56.976810909333,20.5353152078802,24.047956,0,0,0,40,4449,100.16735,24266.2470703125,,,,,,,,,,,,,0,,,,0,,,,,,99.990799,,,,
,22219799.93,99.9931641,19559.0478515625,3.07000068055389E-5,6.93989247729669E-7,1,0.999253354069792,40.0298881530762,1.99822016592437,16.9699992984533,0.000345345339917302,8.32128304797063E-5,0.25,1.92220230538688E-6,3.08678232037694E-5,2.0264347838812E-6,99.9931641,99.9931641,19554.23828125,19563.857421875,56.6899532427752,20.5380784074494,23.288654,0,0,0,40,4449,100.17375,19559.0478515625,,,,,,,,,,,,,0,,,,0.0049,,,,,,99.9931641,,,,
,22219890.47,99.9917145,15033.9125976562,4.44498764179866E-5,7.83039613264267E-7,1,0.999253354069792,40.0298881530762,1.99802121743956,16.9699992984533,0.000504160999092336,9.65983477422413E-5,0.25,6.83468784549017E-7,4.46989180832848E-5,8.23196400898212E-7,99.9917145,99.9917145,15026.48828125,15041.3369140625,56.9236601700253,20.540243173283,24.047956,0,0,0,40,4449,100.1807,15033.9125976562,,,,,,,,,,,,,0,,,,0,,,,,,99.9917145,,,,
,22219984.375,99.9924088,10341.8193359375,5.63709996448802E-5,4.18998898087672E-7,1,0.999253354069792,40.0298881530762,1.99785217501097,16.9699992984533,0.000638231352699319,0.000128672726809801,0.25,1.40918918901361E-6,5.66847591330482E-5,1.59031383148421E-6,99.9924088,99.9924088,10334.685546875,10348.953125,56.9424192544868,20.5332958698206,23.668306,0,0,0,40,4449,100.18635,10341.8193359375,,,,,,,,,,,,,0,,,,-0.0049,,,,,,99.9924088,,,,
,22220077.04,99.9933395,5708.5556640625,6.85055909242035E-5,3.14413393706039E-7,1,0.999253354069792,40.0298881530762,1.99818202110873,16.9699992984533,0.000778671018087396,0.000139693821811496,0.25,2.43186649172355E-7,6.88909650818284E-5,4.55964846325246E-7,99.9933395,99.9933395,5701.01611328125,5716.09521484375,56.946327397083,20.5400012022325,23.288654,0,0,0,40,4449,100.1918,5708.5556640625,,,,,,,,,,,,,0,,,,-0.00245,,,,,,99.9933395,,,,
,22220170.86,99.9950714,1017.70471191406,7.3128083564251E-5,3.01973064468652E-7,1,0.999253354069792,40.0298881530762,1.9982417193533,16.9699992984533,0.000831748698770889,0.000146182692364328,0.25,1.91120722257424E-10,7.35398607477207E-5,2.267360382875E-7,99.9949951,99.9951477,1007.68872070312,1027.720703125,57.1550222117176,20.5390167379894,24.047956,0,0,0,40,4449,100.1947,1017.70471191406,,,,,,,,,,,,,0,,,,-0.00245,,,,,,99.9950714,,,,
,22220261.995,99.9969482,-3530.18017578125,5.76900109749073E-5,3.955206717976E-7,1,0.999253354069792,40.0298881530762,1.9981590912137,16.9699992984533,0.000657323682315862,0.000108549212050148,0.25,-5.94613404948197E-7,5.80168596923674E-5,-4.19606233599873E-7,99.9969482,99.9969482,-3534.90698242188,-3525.45336914063,56.8243933480829,20.5414028804041,24.047956,0,0,0,40,4449,100.19895,-3530.18017578125,,,,,,,,,,,,,0,,,,-0.0049,,,,,,99.9969482,,,,
,22220353.33,100.001442,-8096.89794921875,4.58728231680302E-5,4.82165481654287E-7,1,0.999253354069792,40.0298881530762,1.99836799934609,16.9699992984533,0.000522257014631849,8.90316641651706E-5,0.25,-2.34101160083155E-7,4.61322473445345E-5,-9.4196039421659E-8,100.001442,100.001442,-8104.681640625,-8089.1142578125,57.0995265868522,20.5415200206502,23.668306,0,0,0,40,4449,100.19555,-8096.89794921875,,,,,,,,,,,,,0,,,,-0.0049,,,,,,100.001442,,,,
,22220447.75,100.0077209,-12815.248046875,2.00509357796612E-5,7.21449775759683E-7,1,0.999253354069792,40.0298881530762,1.99807880175038,16.9699992984533,0.000230441282825235,2.64263778899854E-5,0.25,-1.19970251578137E-6,2.01678229004467E-5,-1.14504521691357E-6,100.0077209,100.0077209,-12822.8837890625,-12807.6123046875,57.0604451608906,20.540684928991,24.047956,0,0,0,40,4449,100.18855,-12815.248046875,,,,,,,,,,,,,0,,,,0.00245,,,,,,100.0077209,,,,
,22220542.285,100.0080719,-17542.4189453125,-3.06747832322146E-6,6.5944913872661E-7,1,0.999253354069792,40.0298881530762,1.99831343048539,16.9699992984533,-3.45143839768487E-5,-8.27597390854129E-6,0.25,-1.88628921054853E-7,-3.08424478129739E-6,-1.9904486364263E-7,100.0080719,100.0080719,-17554.638671875,-17530.19921875,57.2480360055061,20.5424585271569,23.288654,0,0,0,40,4449,100.17845,-17542.4189453125,,,,,,,,,,,,,0,,,,0,,,,,,100.0080719,,,,
,22220633.1,100.0110397,-22079.994140625,-8.14086345016254E-6,8.38767680071087E-7,1,0.999253354069792,40.0298881530762,1.99810820092856,16.9699992984533,-8.80234063558653E-5,-4.22654077150137E-5,0.25,-2.28588340206682E-6,-8.18001230159887E-6,-2.3235065372366E-6,100.0110397,100.0110397,-22087.51171875,-22072.4765625,57.0127658212176,20.5378101438578,23.288654,0,0,0,40,4449,100.168,-22079.994140625,,,,,,,,,,,,,0,,,,-0.0049,,,,,,100.0110397,,,,
,22220727.855,100.0117416,-26815.2529296875,-4.56375440810872E-6,8.0357314472762E-7,1,0.999253354069792,40.0298881530762,1.9982595079158,16.9699992984533,-5.26090658537538E-5,-5.14294936637868E-6,0.25,3.4954973143103E-7,-4.59067526773012E-6,3.37770812068826E-7,100.0117416,100.0117416,-26820.30859375,-26810.197265625,57.0424677049483,20.5437971437522,23.668306,0,0,0,40,4449,100.1568,-26815.2529296875,,,,,,,,,,,,,0,,,,0.0049,,,,,,100.0117416,,,,
,22220824.075,100.0127029,-31624.8955078125,8.24472092006998E-6,1.03391090392162E-6,1,0.999253354069792,40.0298881530762,1.9981081250358,16.9699992984533,9.6861732377954E-5,-1.10692771409863E-6,0.25,-1.54548602977892E-6,8.29614833644583E-6,-1.52954655560778E-6,100.0127029,100.0127029,-31632.447265625,-31617.34375,56.8986480574099,20.5390320029457,23.288654,0,0,0,40,4449,100.14705,-31624.8955078125,,,,,,,,,,,,,0,,,,0,,,,,,100.0127029,,,,
,22220919.15,100.0105209,-36374.42578125,2.16101381832511E-5,1.30528405845905E-6,1,0.999253354069792,40.0298881530762,1.99824258158795,16.9699992984533,0.000243315521995533,5.73677407489547E-5,0.25,1.2480844645806E-6,2.17292456616364E-5,1.3195604289813E-6,100.0105209,100.0105209,-36384.6015625,-36364.25,57.0706063316407,20.5407193927756,24.047956,0,0,0,40,4449,100.13695,-36374.42578125,,,,,,,,,,,,,0,,,,0.00245,,,,,,100.0105209,,,,
,22221010.93,100.01171875,-40961.611328125,3.71052181308567E-5,1.3332441410894E-6,1,0.999253354069792,40.0298881530762,1.99830372040964,16.9699992984533,0.000423302383914601,6.71467013180104E-5,0.25,-6.13156036024504E-7,3.7318212147228E-5,-5.06750188035731E-7,100.0114899,100.0119476,-40971.69140625,-40951.53125,57.0260535060445,20.5415499569098,23.668306,0,0,0,40,4449,100.1254,-40961.611328125,,,,,,,,,,,,,0,,,,0,,,,,,100.01171875,,,,
,22221106.375,100.0112686,-45731.861328125,5.20040171605249E-5,1.84907093093224E-6,1,0.999253354069792,40.0298881530762,1.99823265426379,16.9699992984533,0.000594095513619091,8.93172326589928E-5,0.25,-1.27934423982953E-6,5.23041740911831E-5,-1.13358308419405E-6,100.0111465,100.0113907,-45739.44140625,-45724.28125,56.679010443506,20.5415086352605,23.668306,0,0,0,40,4449,100.11705,-45731.861328125,,,,,,,,,,,,,0,,,,0,,,,,,100.0112686,,,,
,22221200.96,100.01235965,-50461.556640625,6.58691611345357E-5,1.55002406987909E-6,1,0.999253354069792,40.0298881530762,1.99829939081742,16.9699992984533,0.000749990112683648,0.000127549497421345,0.25,-3.52071648373693E-7,6.62461273884275E-5,-1.61440857100432E-7,100.0120621,100.0126572,-50471.4140625,-50451.69921875,57.0979633298137,20.5470333664181,24.047956,0,0,0,40,4449,100.1058,-50461.556640625,,,,,,,,,,,,,0,,,,-0.00245,,,,,,100.01235965,,,,
,22221298.405,100.0098495,-55330.77734375,8.26342803256081E-5,1.31968360845353E-6,1,0.999253354069792,40.0298881530762,1.99832852133084,16.9699992984533,0.000938047176142001,0.000176264257742612,0.25,9.88141166007041E-7,8.31037131912528E-5,1.23386712524516E-6,100.0098495,100.0098495,-55338.40234375,-55323.15234375,57.1206305568714,20.5474211374419,24.047956,0,0,0,40,4449,100.09605,-55330.77734375,,,,,,,,,,,,,0,,,,-0.00245,,,,,,100.0098495,,,,
,22221391.01,100.0081863,-59958.150390625,9.60187776410807E-5,1.77787033512295E-6,1,0.999253354069792,40.0298881530762,1.99838554848074,16.9699992984533,0.00108955978580157,0.000207464108409425,0.25,1.38227150389299E-6,9.65643516860076E-5,1.6673573465052E-6,100.0081863,100.0081863,-59965.5546875,-59950.74609375,56.9478906541214,20.546738933205,23.668306,0,0,0,40,4449,100.0915,-59958.150390625,,,,,,,,,,,,,0,,,,0,,,,,,100.0081863,,,,
,22221480.785,100.0101013,-64443.513671875,0.00011528992287143,2.11001085042939E-6,1,0.999253354069792,40.0298881530762,1.99847233264564,16.9699992984533,0.00130736914408775,0.00025442190974563,0.25,2.12824071952825E-6,0.000115944540457892,2.47118071548154E-6,100.0101013,100.0101013,-64448.47265625,-64438.5546875,57.0518472471791,20.5444960692663,24.047956,0,0,0,40,4449,100.0816,-64443.513671875,,,,,,,,,,,,,0,,,,0,,,,,,100.0101013,,,,
,22221577.85,100.0106506,-69295.40234375,0.000134473208694855,1.77890364336806E-6,1,0.999253354069792,40.0298881530762,1.99831811545475,16.9699992984533,0.00153146520058935,0.000258784993589708,0.25,-8.51117956888225E-7,0.000135247382110604,-4.72838378489267E-7,100.0106506,100.0106506,-69300.625,-69290.1796875,56.8392442899483,20.5446967996545,24.047956,0,0,0,40,4449,100.07175,-69295.40234375,,,,,,,,,,,,,0,,,,0,,,,,,100.0106506,,,,
,22221675.07,100.0085068,-74154.5625,0.00015041516897734,1.76205834335623E-6,1,0.999253354069792,40.0298881530762,1.9982917792368,16.9699992984533,0.00170513755991451,0.000334350368744517,0.25,2.99671757936693E-6,0.000151271149726806,3.43959020177733E-6,100.0085068,100.0085068,-74161.9921875,-74147.1328125,57.0182372208522,20.5448538690641,24.047956,0,0,0,40,4449,100.0632,-74154.5625,,,,,,,,,,,,,0,,,,-0.00245,,,,,,100.0085068,,,,
,22221766.645,100.0072708,-78729.2265625,0.000162222956145233,1.47340670020843E-6,1,0.999253354069792,40.0298881530762,1.99838506074256,16.9699992984533,0.00184141592896168,0.000347356931657459,0.25,2.06946475765498E-6,0.000163150694571667,2.53743802249968E-6,100.0072708,100.0072708,-78734.4140625,-78724.0390625,57.1479875550445,20.5444519616736,24.047956,0,0,0,40,4449,100.0573,-78729.2265625,,,,,,,,,,,,,0,,,,0,,,,,,100.0072708,,,,
,22221865.345,100.006897,-83664.38671875,0.000179852791200286,1.93559539105883E-6,1,0.999253354069792,40.0298881530762,1.99839134124402,16.9699992984533,0.00203753920722249,0.000408016414355916,0.25,4.31129532848521E-6,0.000180877225888622,4.838188573E-6,100.006897,100.006897,-83671.9609375,-83656.8125,57.1323549846599,20.5475618184918,23.668306,0,0,0,40,4449,100.0502,-83664.38671875,,,,,,,,,,,,,0,,,,-0.00245,,,,,,100.006897,,,,
,22221959.03,100.0054703,-88345.76171875,0.000194196350433939,1.73606178314582E-6,1,0.999253354069792,40.0298881530762,1.99835582450387,16.9699992984533,0.00219940851836719,0.000444019618544803,0.25,4.9635546937819E-6,0.000195303210152585,5.53060138856065E-6,100.0054703,100.0054703,-88353.3203125,-88338.203125,57.2363115777176,20.5464615702091,24.427608,0,0,0,40,4449,100.0461,-88345.76171875,,,,,,,,,,,,,0,,,,0,,,,,,100.0054703,,,,
,22222068.43,100.0017853,-87203.98828125,0.000189578154343523,1.8469536138512E-6,1,0.999253354069792,40.0298881530762,1.99845257142125,16.9699992984533,0.00215874745512195,0.000367649325005793,0.25,-9.41511737146356E-7,0.000190674402932355,-4.20467339306979E-7,100.0017853,100.0017853,-87213.90625,-87194.0703125,56.9893169656406,20.5451755824086,24.047956,0,0,0,40,4449,100.0472,-87203.98828125,,,,,,,,,,,,,0,,,,0,,,,,,100.0017853,,,,
,22222161.865,99.9996872,-82531.53515625,0.000173053210370775,1.93966472609061E-6,1,0.999253354069792,40.0298881530762,1.99844335354674,16.9699992984533,0.00196675969411462,0.000357217635423325,0.25,1.03749893330939E-6,0.000174047279262465,1.52738226264046E-6,99.9996872,99.9996872,-82541.6875,-82521.3828125,56.9893169656406,20.5455319482551,24.047956,0,0,0,40,4449,100.0454,-82531.53515625,,,,,,,,,,,,,0,,,,-0.00245,,,,,,99.9996872,,,,
,22222254.29,99.9995651,-77911.87890625,0.000162849517682899,1.77011956694069E-6,1,0.999253354069792,40.0298881530762,1.99848613604718,16.9699992984533,0.00185389930241555,0.000318596770982769,0.25,-5.70398002040582E-7,0.00016378806300909,-1.15245993945203E-7,99.9995651,99.9995651,-77919.4453125,-77904.3125,57.126101956506,20.5459317826825,23.668306,0,0,0,40,4449,100.04865,-77911.87890625,,,,,,,,,,,,,0,,,,-0.0049,,,,,,99.9995651,,,,
,22222349.485,99.9967575,-73154.75,0.000141966768097765,1.75815594483991E-6,1,0.999253354069792,40.0298881530762,1.99832174783852,16.9699992984533,0.00162197994122584,0.000243800334834453,0.25,-3.48149158630508E-6,0.000142792302407427,-3.09908331630788E-6,99.9967575,99.9967575,-73162.171875,-73147.328125,57.2800827747945,20.5406791956158,23.668306,0,0,0,40,4449,100.0497,-73154.75,,,,,,,,,,,,,0,,,,0,,,,,,99.9967575,,,,
,22222443.76,99.996994,-68445.4453125,0.000125160146123367,2.13307657300288E-6,1,0.999253354069792,40.0298881530762,1.99839633410022,16.9699992984533,0.00142859354833076,0.000222978057799206,0.25,-2.36556252526489E-6,0.000125885001331253,-2.02194980229997E-6,99.996994,99.996994,-68450.421875,-68440.46875,57.054973761256,20.5444768287693,23.668306,0,0,0,40,4449,100.0506,-68445.4453125,,,,,,,,,,,,,0,,,,0.0049,,,,,,99.996994,,,,
,22222536.86,99.9965439,-63790.685546875,0.000112948489390998,1.88219555679527E-6,1,0.999253354069792,40.0298881530762,1.99842053960265,16.9699992984533,0.00128384177115476,0.000231828265693828,0.25,5.53337784825816E-7,0.000113594053388629,8.80970791519994E-7,99.9965439,99.9965439,-63798.1484375,-63783.22265625,57.1221938139099,20.5437769295029,23.668306,0,0,0,40,4449,100.0559,-63790.685546875,,,,,,,,,,,,,0,,,,-0.0049,,,,,,99.9965439,,,,
,22222633.265,99.9958115,-58973.26171875,9.75721603424542E-5,1.75232860016996E-6,1,0.999253354069792,40.0298881530762,1.99838711169876,16.9699992984533,0.00110792030129922,0.000206631771390256,0.25,1.03592618098685E-6,9.81274186463332E-5,1.32404703284645E-6,99.9958115,99.9958115,-58980.6015625,-58965.921875,56.9603967104291,20.5435083046935,24.047956,0,0,0,40,4449,100.06035,-58973.26171875,,,,,,,,,,,,,0,,,,0,,,,,,99.9958115,,,,
,22222726.07,99.9937439,-54336.033203125,7.80133568879555E-5,1.06057677447608E-6,1,0.999253354069792,40.0298881530762,1.99857397639842,16.9699992984533,0.000887521167683831,0.000156015837795431,0.25,1.73822479439305E-8,7.84590456845985E-5,2.44556157819266E-7,99.9937439,99.9937439,-54343.6875,-54328.37890625,57.0815491309099,20.5434678777359,24.427608,0,0,0,40,4449,100.06755,-54336.033203125,,,,,,,,,,,,,0,,,,-0.0049,,,,,,99.9937439,,,,
,22222819.11,99.9933167,-49686.833984375,6.291251586201E-5,1.58785715638482E-6,1,0.999253354069792,40.0298881530762,1.99854439470624,16.9699992984533,0.000719470285922269,0.000104398490040201,0.25,-1.8695090151884E-6,6.32769507594035E-5,-1.69588238189E-6,99.9933167,99.9933167,-49691.9140625,-49681.75390625,57.1518956976407,20.543814889589,24.047956,0,0,0,40,4449,100.0719,-49686.833984375,,,,,,,,,,,,,0,,,,0.0049,,,,,,99.9933167,,,,
,22222915.785,99.9929428,-44856.931640625,4.83416593095001E-5,1.05703963132526E-6,1,0.999253354069792,40.0298881530762,1.99850105095461,16.9699992984533,0.000551692655907083,8.66468752966632E-5,0.25,-8.72243149878137E-7,4.86196563060953E-5,-7.34679938256359E-7,99.9929428,99.9929428,-44864.45703125,-44849.40625,56.8892685151791,20.5429922111934,24.047956,0,0,0,40,4449,100.07945,-44856.931640625,,,,,,,,,,,,,0,,,,0,,,,,,99.9929428,,,,
,22223009.34,99.9933548,-40179.37890625,2.98709733798204E-5,1.29532746063734E-6,1,0.999253354069792,40.0298881530762,1.99841164568539,16.9699992984533,0.000340806124007779,5.39657589746384E-5,0.25,-5.01881039078878E-7,3.00424125986831E-5,-4.16113234401624E-7,99.9933548,99.9933548,-40187.1484375,-40171.609375,56.8978664288906,20.5427848146685,24.427608,0,0,0,40,4449,100.08445,-40179.37890625,,,,,,,,,,,,,0,,,,0.00245,,,,,,99.9933548,,,,
,22223105.785,99.9918976,-35359.529296875,1.69559510120962E-5,1.45163089996274E-6,1,0.999253354069792,40.0298881530762,1.9984658874761,16.9699992984533,0.000190775373981142,4.5910966545167E-5,0.25,1.0577526949151E-6,1.7049125465527E-5,1.11438542314389E-6,99.9918976,99.9918976,-35364.59765625,-35354.4609375,57.1628384969099,20.5395030643494,24.047956,0,0,0,40,4449,100.0905,-35359.529296875,,,,,,,,,,,,,0,,,,-0.00245,,,,,,99.9918976,,,,
,22223197.435,99.9900818,-30779.87890625,2.61170165106521E-6,9.55482482816866E-7,1,0.999253354069792,40.0298881530762,1.99829953702151,16.9699992984533,3.37176113022001E-5,-1.76102054274319E-5,0.25,-2.00692426317874E-6,2.63254645648935E-6,-2.01046811454978E-6,99.9900818,99.9900818,-30792.1171875,-30767.640625,57.1956668947176,20.5412882960007,24.427608,0,0,0,40,4449,100.09825,-30779.87890625,,,,,,,,,,,,,0,,,,-0.00245,,,,,,99.9900818,,,,
,22223288.875,99.9916763,-26209.86328125,-1.18642824156406E-5,7.912629124045E-7,1,0.999253354069792,40.0298881530762,1.99839006795711,16.9699992984533,-0.000135444048768473,-2.0946410942806E-5,0.25,2.42801795169333E-7,-1.19322401220496E-5,2.08346702454228E-7,99.9916763,99.9916763,-26219.7734375,-26199.953125,56.922878541506,20.5428286746354,23.668306,0,0,0,40,4449,100.1048,-26209.86328125,,,,,,,,,,,,,0,,,,0,,,,,,99.9916763,,,,
,22223383.89,99.9923706,-21460.2255859375,-2.71069994147025E-5,6.90922562619374E-7,1,0.999253354069792,40.0298881530762,1.99831216063952,16.9699992984533,-0.000306196667923333,-6.63328073689088E-5,0.25,-1.06923163672067E-6,-2.72571347161627E-5,-1.15761342557348E-6,99.9923706,99.9923706,-21462.498046875,-21457.953125,56.9783741663714,20.5416600302898,24.047956,0,0,0,40,4449,100.11315,-21460.2255859375,,,,,,,,,,,,,0,,,,-0.0049,,,,,,99.9923706,,,,
,22223475.79,99.9917526,-16867.9638671875,-4.09931358582259E-5,6.33016157256248E-7,1,0.999253354069792,40.0298881530762,1.99820892442036,16.9699992984533,-0.000464661939869675,-9.09967566781768E-5,0.25,-7.9771464007563E-7,-4.12223612276328E-5,-9.27389650118104E-7,99.9917526,99.9917526,-16875.51953125,-16860.408203125,57.2277136640061,20.5411540051517,23.668306,0,0,0,40,4449,100.12135,-16867.9638671875,,,,,,,,,,,,,0,,,,0,,,,,,99.9917526,,,,
,22223566.085,99.9905243,-12352.63671875,-5.1380346418739E-5,5.24140363010623E-7,1,0.999253354069792,40.0298881530762,1.99825067579645,16.9699992984533,-0.000585504253099927,-9.64451999416984E-5,0.25,5.49230794014298E-7,-5.16720439732747E-5,3.94672003783782E-7,99.9905243,99.9905243,-12362.4755859375,-12342.7978515625,57.0862389020253,20.5429265666463,24.047956,0,0,0,40,4449,100.12925,-12352.63671875,,,,,,,,,,,,,0,,,,0,,,,,,99.9905243,,,,
,22223658.88,99.9914093,-7714.85107421875,-6.37691447185644E-5,4.56768002487431E-7,1,0.999253354069792,40.0298881530762,1.99839264296742,16.9699992984533,-0.00072465166725459,-0.000131507098463927,0.25,-3.547716235779E-7,-6.41275671041857E-5,-5.53375174137871E-7,99.9914093,99.9914093,-7719.63818359375,-7710.06396484375,56.8595666314483,20.5418958261517,24.047956,0,0,0,40,4449,100.1354,-7714.85107421875,,,,,,,,,,,,,0,,,,0.0049,,,,,,99.9914093,,,,
,22223751.28,99.9921112,-3099.12890625,-7.20725789440334E-5,2.9697403836603E-7,1,0.999253354069792,40.0298881530762,1.99830445227863,16.9699992984533,-0.000819282991899989,-0.000146842219515707,0.25,-2.43436384135396E-7,-7.24777347040982E-5,-4.67927237829809E-7,99.9921112,99.9921112,-3111.24584960937,-3087.01196289063,57.0745144742368,20.5374558939815,24.427608,0,0,0,40,4449,100.1439,-3099.12890625,,,,,,,,,,,,,0,,,,0,,,,,,99.9921112,,,,
,22223843.805,99.9942017,1524.27136230469,-5.87851515873249E-5,6.34478550338429E-7,1,0.999253354069792,40.0298881530762,1.99834819943579,16.9699992984533,-0.000667937951945125,-0.000121555688529759,0.25,-3.55121196596884E-7,-5.91150256899469E-5,-5.39319311857484E-7,99.9942017,99.9942017,1519.12951660156,1529.41320800781,56.8736359447945,20.5425083681364,24.047956,0,0,0,40,4449,100.1473,1524.27136230469,,,,,,,,,,,,,0,,,,0,,,,,,99.9942017,,,,
,22223934.275,99.9986725,6046.46337890625,-5.1802344070836E-5,3.63247910214499E-7,1,0.999253354069792,40.0298881530762,1.99834481802301,16.9699992984533,-0.000588138594892018,-0.000109737101994657,0.25,-5.4390229687395E-7,-5.20926057931267E-5,-7.06898788508937E-7,99.9986725,99.9986725,6036.9697265625,6055.95703125,56.9447641400445,20.539960505317,24.047956,0,0,0,40,4449,100.14875,6046.46337890625,,,,,,,,,,,,,0,,,,0,,,,,,99.9986725,,,,
,22224028.735,100.0036774,10767.0068359375,-3.2291182233939E-5,4.81706002154175E-7,1,0.999253354069792,40.0298881530762,1.99828660484862,16.9699992984533,-0.000366907483954649,-6.67138626986758E-5,0.25,-1.90951257300987E-7,-3.24727860932104E-5,-2.91257529161874E-7,100.0036774,100.0036774,10764.58984375,10769.423828125,56.8736359447945,20.5389543127387,23.668306,0,0,0,40,4449,100.14345,10767.0068359375,,,,,,,,,,,,,0,,,,0.00245,,,,,,100.0036774,,,,
,22224123.03,100.0079269,15479.361328125,-3.44619734195986E-6,5.92017119314629E-7,1,0.999253354069792,40.0298881530762,1.99842377584429,16.9699992984533,-3.70665616577113E-5,-1.90353928095652E-5,0.25,-1.06789179960635E-6,-3.46239989108718E-6,-1.08446107807323E-6,100.0079269,100.0079269,15476.4033203125,15482.3193359375,56.8689461736791,20.5413168149238,24.047956,0,0,0,40,4449,100.135,15479.361328125,,,,,,,,,,,,,0,,,,0,,,,,,100.0079269,,,,
,22224218.04,100.009346,20226.8291015625,1.18488314891602E-5,7.13215854152089E-7,1,0.999253354069792,40.0298881530762,1.998462445631,16.9699992984533,0.000134617865994471,2.46376274868374E-5,0.25,8.41060405272301E-8,1.19155966133048E-5,1.20616035163459E-7,100.009346,100.009346,20219.40625,20234.251953125,57.0416860764291,20.5371549529232,23.668306,0,0,0,40,4449,100.1248,20226.8291015625,,,,,,,,,,,,,0,,,,0.00245,,,,,,100.009346,,,,
,22224311.93,100.0096893,24922.1748046875,9.09434783972313E-6,8.879965456937E-7,1,0.999253354069792,40.0298881530762,1.99828185068877,16.9699992984533,0.000104051398887752,1.47184607782949E-5,0.25,-3.0367472870797E-7,9.14677558596036E-6,-2.77891292062773E-7,100.0096893,100.0096893,24917.26953125,24927.080078125,56.7517018957945,20.5361547202044,24.427608,0,0,0,40,4449,100.1176,24922.1748046875,,,,,,,,,,,,,0,,,,0.0049,,,,,,100.0096893,,,,
,22224406.325,100.0110168,29639.97265625,-5.3146412150153E-7,1.14921131367639E-6,1,0.999253354069792,40.0298881530762,1.9984788930391,16.9699992984533,-6.13243223267617E-6,-5.68950948857481E-7,0.25,4.33413948300956E-8,-5.34608667426871E-7,4.19891412692858E-8,100.0110168,100.0110168,29629.96875,29649.9765625,56.6743206723906,20.5415112263798,24.427608,0,0,0,40,4449,100.10685,29639.97265625,,,,,,,,,,,,,0,,,,-0.00245,,,,,,100.0110168,,,,
,22224504.26,100.0116272,34532.412109375,-1.39767826612338E-5,1.20221923642299E-6,1,0.999253354069792,40.0298881530762,1.9983856502115,16.9699992984533,-0.0001564154786161,-4.259266080848E-5,0.25,-1.28941157146381E-6,-1.40523114002662E-5,-1.33850636349371E-6,100.0116272,100.0116272,34522.38671875,34542.4375,56.7540467813522,20.538545529602,24.427608,0,0,0,40,4449,100.094,34532.412109375,,,,,,,,,,,,,0,,,,0,,,,,,100.0116272,,,,
,22224599.25,100.0075455,39282.134765625,-2.67286708528525E-5,1.50968189423371E-6,1,0.999253354069792,40.0298881530762,1.9983999257585,16.9699992984533,-0.000305492810450005,-4.52119043008941E-5,0.25,7.19624473618183E-7,-2.68828332833329E-5,6.44326828819188E-7,100.0075455,100.0075455,39274.5078125,39289.76171875,56.6360208749483,20.5370855573587,24.047956,0,0,0,40,4449,100.0881,39282.134765625,,,,,,,,,,,,,0,,,,-0.0049,,,,,,100.0075455,,,,
,22224697.495,100.0062866,44192.09375,-4.20313996183958E-5,1.62008093166999E-6,1,0.999253354069792,40.0298881530762,1.99847938203632,16.9699992984533,-0.000478199629857125,-8.37210717284902E-5,0.25,2.13737404877011E-8,-4.22708815460214E-5,-1.02529441528456E-7,100.0062866,100.0062866,44182.1953125,44201.9921875,56.6235148186406,20.5406720074174,23.668306,0,0,0,40,4449,100.0864,44192.09375,,,,,,,,,,,,,0,,,,0.0049,,,,,,100.0062866,,,,
,22224791.945,100.0066605,48912.609375,-5.71229809396675E-5,1.56463846031223E-6,1,0.999253354069792,40.0298881530762,1.9983614317055,16.9699992984533,-0.000653343788587274,-9.39805899454088E-5,0.25,1.76814529121877E-6,-5.74540062337386E-5,1.61073750241158E-6,100.0066605,100.0066605,48910.09765625,48915.12109375,57.0455942190253,20.5342269466747,24.047956,0,0,0,40,4449,100.0787,48912.609375,,,,,,,,,,,,,0,,,,-0.0049,,,,,,100.0066605,,,,
,22224886.25,100.0075073,53625.296875,-7.15980690507638E-5,2.25730072643605E-6,1,0.999253354069792,40.0298881530762,1.99840932967662,16.9699992984533,-0.000816235063173526,-0.000133133817647884,0.25,8.6687152027051E-7,-7.20095769335768E-5,6.63229151052818E-7,100.0075073,100.0075073,53607.89453125,53642.69921875,57.0330881627176,20.5364900097031,23.668306,0,0,0,40,4449,100.0717,53625.296875,,,,,,,,,,,,,0,,,,-0.00245,,,,,,100.0075073,,,,
,22224977.885,100.00946425,58205.91796875,-9.30979402716887E-5,2.05642635354385E-6,1,0.999253354069792,40.0298881530762,1.99834557288153,16.9699992984533,-0.00105776704400826,-0.00019331515460751,0.25,-6.50836731950347E-7,-9.36285681197682E-5,-9.24089594404472E-7,100.009201,100.0097275,58201.00390625,58210.83203125,56.4281076888329,20.5384595706113,24.047956,0,0,0,40,4449,100.0638,58205.91796875,,,,,,,,,,,,,0,,,,-0.00245,,,,,,100.00946425,,,,
,22225072.96,100.0092697,62958.841796875,-0.00010705086952868,2.37059259514629E-6,1,0.999253354069792,40.0298881530762,1.9982281606056,16.9699992984533,-0.00122042849315347,-0.000198414886541918,0.25,1.34732384112005E-6,-0.000107667926827796,1.04715871485859E-6,100.0092697,100.0092697,62953.80078125,62963.8828125,57.0838940164676,20.5356893148474,24.047956,0,0,0,40,4449,100.05645,62958.841796875,,,,,,,,,,,,,0,,,,0,,,,,,100.0092697,,,,
,22225168.985,100.0096359,67758.87109375,-0.000119017608054592,1.63741633276491E-6,1,0.999253354069792,40.0298881530762,1.99828995547057,16.9699992984533,-0.00135762624995563,-0.000216494759954959,0.25,1.85679105783119E-6,-0.000119705597163662,1.52743615954133E-6,100.0096359,100.0096359,67751.421875,67766.3203125,56.9049010855637,20.5394347998314,24.047956,0,0,0,40,4449,100.04785,67758.87109375,,,,,,,,,,,,,0,,,,0,,,,,,100.0096359,,,,
,22225263.985,100.0095596,72506.5,-0.000135805231769671,2.15722215399467E-6,1,0.999253354069792,40.0298881530762,1.99834170397095,16.9699992984533,-0.00154379876266123,-0.000277656372710029,0.25,-5.75176364888002E-7,-0.000136583649686952,-9.63859004725698E-7,100.0095596,100.0095596,72498.5234375,72514.4765625,56.8611298884868,20.5381927110196,23.668306,0,0,0,40,4449,100.038,72506.5,,,,,,,,,,,,,0,,,,0.0049,,,,,,100.0095596,,,,
,22225357.875,100.0096054,77199.640625,-0.000154720982230734,1.80324837878941E-6,1,0.999253354069792,40.0298881530762,1.99825666392855,16.9699992984533,-0.0017549636667079,-0.000338014699351328,0.25,-2.56532907517319E-6,-0.000155603658039872,-3.01620610349017E-6,100.0096054,100.0096054,77191.84375,77207.4375,56.7563916669098,20.5382119540344,24.427608,0,0,0,40,4449,100.0314,77199.640625,,,,,,,,,,,,,0,,,,-0.00245,,,,,,100.0096054,,,,
,22225450.74,100.0085373,81840.59765625,-0.000168358947777018,2.27444235661125E-6,1,0.999253354069792,40.0298881530762,1.99818745856317,16.9699992984533,-0.00191678165891984,-0.000326910883596505,0.25,7.99848321990986E-7,-0.000169330830525809,3.33055032101024E-7,100.0085373,100.0085373,81835.6328125,81845.5625,56.7610814380252,20.5359257411651,24.047956,0,0,0,40,4449,100.02595,81840.59765625,,,,,,,,,,,,,0,,,,0,,,,,,100.0085373,,,,
,22225543.085,100.0065231,86458.46484375,-0.000185537329765364,1.78505890373977E-6,1,0.999253354069792,40.0298881530762,1.99823498279814,16.9699992984533,-0.00210639891525961,-0.000394615506452864,0.25,-2.14040949955976E-6,-0.000186601361818486,-2.66880053361443E-6,100.0065231,100.0065231,86453.6484375,86463.28125,56.9525804252368,20.536893563945,23.668306,0,0,0,40,4449,100.0188,86458.46484375,,,,,,,,,,,,,0,,,,0,,,,,,100.0065231,,,,
,22225653.595,100.0056381,89037.75390625,-0.00019320144157835,1.66209287894242E-6,1,0.999253354069792,40.0298881530762,1.99828365067913,16.9699992984533,-0.00219390755846856,-0.000408431028000077,0.25,-2.01138177352764E-6,-0.000194310862966097,-2.55834760054357E-6,100.0056076,100.0056686,89032.84375,89042.6640625,56.9322580837368,20.5334472002068,23.668306,0,0,0,40,4449,100.015,89037.75390625,,,,,,,,,,,,,0,,,,0,,,,,,100.0056381,,,,
,22225744.85,100.0007172,84474.625,-0.000180236888716767,2.29670292818448E-6,1,0.999253354069792,40.0298881530762,1.99837351800057,16.9699992984533,-0.00205090926792204,-0.000357388227193663,0.25,2.05669354484521E-7,-0.000181276296722638,-2.95948638255729E-7,100.0007172,100.0007172,84469.796875,84479.453125,56.8345545188329,20.5373345267075,23.668306,0,0,0,40,4449,100.0144,84474.625,,,,,,,,,,,,,0,,,,0,,,,,,100.0007172,,,,
,22225839.275,99.9986343,79755.99609375,-0.000159158005957619,2.07150399559814E-6,1,0.999253354069792,40.0298881530762,1.99835218463492,16.9699992984533,-0.00181487282389938,-0.00029363245257547,0.25,2.11438286996065E-6,-0.000160080045306726,1.6794809784405E-6,99.9986343,99.9986343,79741,79770.9921875,56.8345545188329,20.537348328229,24.427608,0,0,0,40,4449,100.01545,79755.99609375,,,,,,,,,,,,,0,,,,0.00245,,,,,,99.9986343,,,,
,22225935.595,99.9967041,74942.40625,-0.000145337145286388,1.96589233925122E-6,1,0.999253354069792,40.0298881530762,1.99830357685941,16.9699992984533,-0.00164858846905989,-0.000317332672309992,0.25,-2.39186452809138E-6,-0.000146165770580804,-2.81670250298119E-6,99.9967041,99.9967041,74932.2109375,74952.6015625,56.8204852054868,20.5397465488339,24.047956,0,0,0,40,4449,100.0204,74942.40625,,,,,,,,,,,,,0,,,,-0.00245,,,,,,99.9967041,,,,
,22226034.79,99.995224,69984.5625,-0.000127122542566081,1.79512855653224E-6,1,0.999253354069792,40.0298881530762,1.99841516512914,16.9699992984533,-0.0014436659153298,-0.000268316143764066,0.25,-1.27568908638335E-6,-0.000127848542004294,-1.64515724299545E-6,99.995224,99.995224,69979.578125,69989.546875,56.8806706014676,20.5356408167066,23.668306,0,0,0,40,4449,100.0224,69984.5625,,,,,,,,,,,,,0,,,,0.0049,,,,,,99.995224,,,,
,22226127.93,99.99507905,65326.623046875,-0.000113256768704902,1.10820217861269E-6,1,0.999253354069792,40.0298881530762,1.99825412912764,16.9699992984533,-0.00128462051201005,-0.00024740361572092,0.25,-1.87057075643565E-6,-0.000113900566524396,-2.20607039626525E-6,99.9946823,99.9954758,65321.625,65331.62109375,56.9306948266983,20.5348902678221,24.047956,0,0,0,40,4449,100.0287,65326.623046875,,,,,,,,,,,,,0,,,,0,,,,,,99.99507905,,,,
,22226223.485,99.9946899,60550.7421875,-9.6104110778598E-5,1.38270671879266E-6,1,0.999253354069792,40.0298881530762,1.99843035976696,16.9699992984533,-0.0010933126641591,-0.000191923367068022,0.25,-8.1259202647337E-10,-9.66541750184325E-5,-2.78268877494698E-7,99.9946899,99.9946899,60543.20703125,60558.27734375,57.0151107067753,20.5407296332858,23.668306,0,0,0,40,4449,100.03305,60550.7421875,,,,,,,,,,,,,0,,,,0,,,,,,99.9946899,,,,
,22226315.935,99.9935379,55927.65625,-8.02955231349206E-5,1.89922953745114E-6,1,0.999253354069792,40.0298881530762,1.99836298925778,16.9699992984533,-0.000919754124047062,-0.000124336322556749,0.25,3.16631212746986E-6,-8.07636766772466E-5,2.95110297958637E-6,99.9935379,99.9935379,55920.44140625,55934.87109375,56.8447156895829,20.5387597494033,24.047956,0,0,0,40,4449,100.03875,55927.65625,,,,,,,,,,,,,0,,,,0,,,,,,99.9935379,,,,
,22226407.58,99.9931107,51347.7578125,-6.39875814200375E-5,1.0748079114986E-6,1,0.999253354069792,40.0298881530762,1.99841468999386,16.9699992984533,-0.000728370337674012,-0.000125260541654852,0.25,2.23508659887964E-7,-6.43534766234589E-5,3.76897601637803E-8,99.9931107,99.9931107,51337.58203125,51357.93359375,56.7149653553906,20.5368612841416,24.427608,0,0,0,40,4449,100.04525,51347.7578125,,,,,,,,,,,,,0,,,,-0.0049,,,,,,99.9931107,,,,
,22226501.66,99.9925461,46647.857421875,-5.00051417767369E-5,1.47546287510098E-6,1,0.999253354069792,40.0298881530762,1.99837365043747,16.9699992984533,-0.000566515653509896,-0.000113131807929591,0.25,-1.16459598533812E-6,-5.02867426315991E-5,-1.31838285263009E-6,99.9925461,99.9925461,46640.42578125,46655.2890625,57.2347483206791,20.5350355445727,24.047956,0,0,0,40,4449,100.0504,46647.857421875,,,,,,,,,,,,,0,,,,-0.0049,,,,,,99.9925461,,,,
,22226596.17,99.9917603,41924.943359375,-3.47015904861533E-5,1.20875515397974E-6,1,0.999253354069792,40.0298881530762,1.9982351070445,16.9799998402596,-0.000389643739870807,-9.82424045658612E-5,0.25,-2.54289233636226E-6,-3.48915799221717E-5,-2.66012683028515E-6,99.9917603,99.9917603,41917.56640625,41932.3203125,56.8142321773329,20.5342039641435,23.668306,0,0,0,40,4449,100.05745,41924.943359375,,,,,,,,,,,,,0,,,,0.00245,,,,,,99.9917603,,,,
,22226691.645,99.9922791,37150.052734375,-2.07844015920436E-5,1.06366604914473E-6,1,0.999253354069792,40.0298881530762,1.99846132273982,16.9699992984533,-0.000235132742878448,-4.8975303273398E-5,0.25,-6.54829963773671E-7,-2.0900585810274E-5,-7.20485479091099E-7,99.9922791,99.9922791,37145.203125,37154.90234375,56.7782772654483,20.5383841864216,23.668306,0,0,0,40,4449,100.0653,37150.052734375,,,,,,,,,,,,,0,,,,0,,,,,,99.9922791,,,,
,22226786.745,99.9919968,32397.501953125,-4.30874934112603E-6,7.19744673175643E-7,1,0.999253354069792,40.0298881530762,1.99831198972673,16.9699992984533,-4.81172023099671E-5,-1.37020455274613E-5,0.25,-4.47755937334039E-7,-4.33186257213019E-6,-4.63215523117236E-7,99.9919968,99.9919968,32387.578125,32407.42578125,57.0010413934291,20.5365810673252,24.047956,0,0,0,40,4449,100.07055,32397.501953125,,,,,,,,,,,,,0,,,,0,,,,,,99.9919968,,,,
,22226876.62,99.9908447,27907.521484375,9.4465933583474E-6,7.77974661743175E-7,1,0.999253354069792,40.0298881530762,1.99837370752747,16.9699992984533,0.000105798148065558,2.83174217122118E-5,0.25,8.29965026587593E-7,9.49763815607262E-6,8.63150630648278E-7,99.9906082,99.9910812,27904.99609375,27910.046875,57.2222422643714,20.5372321203172,23.668306,0,0,0,40,4449,100.07915,27907.521484375,,,,,,,,,,,,,0,,,,-0.0049,,,,,,99.9908447,,,,
,22226970.075,99.9914017,23237.515625,2.31691844355274E-5,8.44606137412812E-7,1,0.999253354069792,40.0298881530762,1.99830730285952,16.9699992984533,0.00026115767105607,5.98732693437298E-5,0.25,1.19329162398316E-6,2.32967214844119E-5,1.27029776673181E-6,99.9914017,99.9914017,23232.5234375,23242.5078125,56.7149653553906,20.5389892936934,24.427608,0,0,0,40,4449,100.08705,23237.515625,,,,,,,,,,,,,0,,,,-0.0049,,,,,,99.9914017,,,,
,22227060.815,99.9909592,18702.6484375,3.70933647518667E-5,4.58299226478413E-7,1,0.999253354069792,40.0298881530762,1.99827842657027,16.9699992984533,0.000420980682873024,7.94508044660166E-5,0.25,4.67745214008507E-7,3.73016465794723E-5,5.83461522453634E-7,99.9909592,99.9909592,18695.125,18710.171875,57.0612267894099,20.5398579579178,24.047956,0,0,0,40,4449,100.0936,18702.6484375,,,,,,,,,,,,,0,,,,0,,,,,,99.9909592,,,,
,22227153.845,99.9910049,14052.8515625,4.90417862905628E-5,5.07163336980533E-7,1,0.999253354069792,40.0298881530762,1.99852421095711,16.9699992984533,0.000556804679828114,0.000104158838327064,0.25,5.38875944341125E-7,4.93170443311226E-5,6.92186886244532E-7,99.9910049,99.9910049,14047.7490234375,14057.9541015625,57.0158923352945,20.5440335670315,23.668306,0,0,0,40,4449,100.1036,14052.8515625,,,,,,,,,,,,,0,,,,0,,,,,,99.9910049,,,,
,22227248.5,99.9902344,9320.29345703125,6.0341534678722E-5,4.97470590289844E-7,1,0.999253354069792,40.0298881530762,1.99839048261806,16.9699992984533,0.000686082858543784,0.00012227087040209,0.25,1.45351974587194E-7,6.06813839267183E-5,3.31980769079544E-7,99.9902344,99.9902344,9310.4794921875,9330.107421875,57.0870205305445,20.540123284447,24.047956,0,0,0,40,4449,100.11205,9320.29345703125,,,,,,,,,,,,,0,,,,-0.00245,,,,,,99.9902344,,,,
,22227340.46,99.9914322,4724.65283203125,7.04836405028235E-5,3.18272612685069E-7,1,0.999253354069792,40.0298881530762,1.99832116225778,16.9699992984533,0.000802277676011493,0.000137635263790289,0.25,-2.86665589841874E-7,7.08815877745873E-5,-7.02962971922245E-8,99.9914322,99.9914322,4722.064453125,4727.2412109375,56.9627415959868,20.5406343863636,24.427608,0,0,0,40,4449,100.1199,4724.65283203125,,,,,,,,,,,,,0,,,,0,,,,,,99.9914322,,,,
,22227435.265,99.9933167,-0.464325100183487,6.93934049620427E-5,2.72852727809174E-7,1,0.999253354069792,40.0298881530762,1.99854695177147,16.9699992984533,0.000790854988326402,0.000130367915629524,0.25,-7.35912119202276E-7,6.97862624173617E-5,-5.2469396934959E-7,99.9933167,99.9933167,-0.502384543418884,-0.42626565694809,56.8290831191983,20.5408549259046,23.668306,0,0,0,40,4417,100.12505,-0.464325100183487,,,,,,,,,,,,,0,,,,-0.0049,,,,,,99.9933167,,,,