File: data/doubleLayers/dl_1-25/ppms/KoelnPPMS/DD205_3_HYST_INIT_300K.DAT
[Header]
; VSM Data File (default extension .dat)
; Copyright (c) 2003-2013, Quantum Design, Inc. All rights reserved.
TITLE,
FILEOPENTIME,22140475.31,09/14/2018,3:06 pm
BYAPP,VSM,2.0,2.0
INFO,PPMS VSM Option Release 1.4.10 Build 1,APPNAME
INFO,Quantum Design Linear Motor Servo Controller,MOTOR_MODULE_NAME
INFO,3101-100 M1,MOTOR_HW_VERSION
INFO,MMC1014,MOTOR_SERIAL_NUMBER
INFO,SRV No X-over 01.03.11,MOTOR_SOFTWARE_VERSION
INFO,Quantum Design VSM Detection Module,VSM_MODULE_NAME
INFO,3101-150 F0,VSM_HW_VERSION
INFO,VSM707,VSM_SERIAL_NUMBER
INFO,VSM No X-over 01.02.05 May 20 2008 13:51:47,VSM_SOFTWARE_VERSION
INFO,704,PREAMP_SERIAL_NUMBER
INFO,822,COIL_SERIAL_NUMBER
INFO,0,MOMENT_UNITS
INFO,CoFe2O4,SAMPLE_MATERIAL
INFO,Double Layer blue,SAMPLE_COMMENT
INFO,,SAMPLE_MASS
INFO,,SAMPLE_VOLUME
INFO,,SAMPLE_MOLECULAR_WEIGHT
INFO,,SAMPLE_SIZE
INFO,,SAMPLE_SHAPE
DATATYPE,COMMENT,1
DATATYPE,TIME,2
STARTUPAXIS,X,2
STARTUPAXIS,Y1,5
[Data]
Comment,Time Stamp (sec),Temperature (K),Magnetic Field (Oe),Moment (emu),M. Std. Err. (emu),Transport Action,Averaging Time (sec),Frequency (Hz),Peak Amplitude (mm),Center Position (mm),Coil Signal' (mV),Coil Signal" (mV),Range (mV),M. Quad. Signal (emu),M. Raw' (emu),M. Raw" (emu),Min. Temperature (K),Max. Temperature (K),Min. Field (Oe),Max. Field (Oe),Mass (grams),Motor Lag (deg),Pressure (Torr),VSM Status (code),Motor Status (code),Measure Status (code),Measure Count,PPMS Status (code),System Temp. (K),System Field (Oe),Sample Position (deg),Bridge 1 Resistance (ohms),Bridge 1 Excitation (에),Bridge 2 Resistance (ohms),Bridge 2 Excitation (에),Bridge 3 Resistance (ohms),Bridge 3 Excitation (에),Bridge 4 Resistance (ohms),Bridge 4 Excitation (에),Signal 1 Vin (V),Signal 2 Vin (V),Digital Inputs (code),Drive 1 Iout (mA),Drive 1 Ipower (W),Drive 2 Iout (mA),Drive 2 Ipower (W),Pressure (),Map 20 (),Map 21 (),Map 22 (),Map 23 (),Map 24 (),Map 25 (),Map 26 (),Map 27 (),Map 28 (),Map 29 ()
,22140491.05,300.0780945,0.0608950927853584,,,2,,,,16.1299996563792,,,,,,,300.0780945,300.0780945,0.0608950927853584,0.0608950927853584,,,26.705515,,,,-99999999,4369,301.5994,0.0608950927853584,,,,,,,,,,,,,,,,,,,,,,,300.0780945,,,,
,22140626.755,300.0774536,3642.06616210937,5.81991328876235E-5,5.08262182330828E-7,1,0.999253354069792,40.0298881530762,1.99975884797762,16.1199998110533,0.000658151279796886,0.000118917753909084,0.25,4.1919176149166E-7,5.81969763303621E-5,4.57580020658722E-7,300.0771179,300.0777893,3632.04443359375,3652.087890625,55.8864391250059,20.5104311945833,26.325863,0,0,0,40,4449,301.50315,3642.06616210937,,,,,,,,,,,,,0,,,,0,,,,,,300.0774536,,,,
,22140702.49,300.067276,7424.82958984375,5.70369817554372E-5,6.99112270774986E-7,1,0.999253354069792,40.0298881530762,1.99982028616607,16.1300003528595,0.000645682177905611,0.000112771560712772,0.25,7.74434225394109E-8,5.70351105476954E-5,1.15059890998879E-7,300.0672302,300.0673218,7417.45703125,7432.2021484375,56.1193644237367,20.5166757761354,26.325863,0,0,0,40,4449,301.46485,7424.82958984375,,,,,,,,,,,,,0,,,,0,,,,,,300.067276,,,,
,22140781.885,300.0567322,11393.357421875,4.78910991948228E-5,1.05229203030236E-6,1,0.999253354069792,40.0298881530762,1.99969206764532,16.1199998110533,0.000541364794909538,9.90075414186122E-5,0.25,4.46999648765151E-7,4.78892960051899E-5,4.78554490117281E-7,300.0567322,300.0567322,11385.9501953125,11400.7646484375,56.1936191330636,20.5176858647289,26.325863,0,0,0,40,4449,301.437,11393.357421875,,,,,,,,,,,,,0,,,,-0.0049,,,,,,300.0567322,,,,
,22140861.86,300.0445557,15391.34375,3.66453413283549E-5,1.49071099983418E-6,1,0.999253354069792,40.0298881530762,1.99964273899608,16.1199998110533,0.000416841451586862,6.06973227430151E-5,0.25,-9.88051743867076E-7,3.66448552665697E-5,-9.6387963637383E-7,300.0445557,300.0445557,15378.9248046875,15403.7626953125,56.4312342029098,20.5214516275374,26.705515,0,0,0,40,4449,301.40415,15391.34375,,,,,,,,,,,,,0,,,,-0.00245,,,,,,300.0445557,,,,
,22140941.415,300.0345459,19366.6064453125,2.46401287438548E-5,1.86758307976482E-6,1,0.999253354069792,40.0298881530762,1.99961554715855,16.1199998110533,0.000277143524017192,5.89060734229131E-5,0.25,9.3378293083277E-7,2.46387593405878E-5,9.49975945877772E-7,300.0345459,300.0345459,19361.65625,19371.556640625,56.5594212800637,20.5248653082298,25.946213,0,0,0,40,4449,301.382,19366.6064453125,,,,,,,,,,,,,0,,,,-0.00245,,,,,,300.0345459,,,,
,22141022.35,300.0365295,23409.7109375,1.28375387297706E-5,2.0108183738107E-6,1,0.999253354069792,40.0298881530762,1.99951589552597,16.1199998110533,0.000147256271862588,1.4117617128648E-5,0.25,-9.77179359371253E-7,1.28377880351179E-5,-9.68703863146742E-7,300.0365295,300.0365295,23404.56640625,23414.85546875,56.4836033136983,20.5273605266213,25.946213,0,0,0,40,4449,301.35515,23409.7109375,,,,,,,,,,,,,0,,,,-0.0049,,,,,,300.0365295,,,,
,22141101.335,300.0359192,27358.103515625,6.80562753353462E-7,2.29401392079157E-6,1,0.999253354069792,40.0298881530762,1.99946797725542,16.1199998110533,4.79139106113007E-6,1.81506190685378E-5,0.25,1.48533264202674E-6,6.79565477635878E-7,1.4857346035791E-6,300.0359192,300.0359192,27353.26953125,27362.9375,56.5351907959675,20.5257389972929,26.705515,0,0,0,40,4449,301.33285,27358.103515625,,,,,,,,,,,,,0,,,,0,,,,,,300.0359192,,,,
,22141181.515,300.0305786,31368.318359375,-1.27153961219168E-5,9.8587372935481E-7,1,0.999253354069792,40.0298881530762,1.99946570133422,16.1199998110533,-0.000144051807558328,-2.43720047537505E-5,0.25,5.02051159167072E-8,-1.27150431565009E-5,4.18513253021788E-8,300.0305786,300.0305786,31360.7109375,31375.92578125,56.5234663681791,20.5273865940274,26.325863,0,0,0,40,4449,301.3234,31368.318359375,,,,,,,,,,,,,0,,,,0,,,,,,300.0305786,,,,
,22141264.22,300.0290527,35500.857421875,-2.76273384136767E-5,1.31415403651573E-6,1,0.999253354069792,40.0298881530762,1.99948500092867,16.1199998110533,-0.000315492058170328,-3.8519042561208E-5,0.25,1.38415757288426E-6,-2.76274111285575E-5,1.36598256174562E-6,300.0290527,300.0290527,35493.21875,35508.49609375,56.5805252500829,20.528824585921,26.325863,0,0,0,40,4449,301.2933,35500.857421875,,,,,,,,,,,,,0,,,,0,,,,,,300.0290527,,,,
,22141343.545,300.0320129,39463.486328125,-3.97460707588055E-5,1.5853974154724E-6,1,0.999253354069792,40.0298881530762,1.99951635279065,16.1199998110533,-0.00045410141556676,-5.41925398855569E-5,0.25,2.09938398259789E-6,-3.97462428543092E-5,2.07325464830071E-6,300.0320129,300.0320129,39460.97265625,39466,56.5500417378329,20.529197629422,26.325863,0,0,0,40,4449,301.2784,39463.486328125,,,,,,,,,,,,,0,,,,0.0049,,,,,,300.0320129,,,,
,22141424.575,300.0324402,43516.669921875,-5.48412061900028E-5,1.99961957338118E-6,1,0.999253354069792,40.0298881530762,1.99942984201299,16.1199998110533,-0.000626458092363563,-7.52349834936733E-5,0.25,2.85571156937659E-6,-5.48414170182236E-5,2.81968966234633E-6,300.0324402,300.0324402,43514.19140625,43519.1484375,56.506270540756,20.527886255634,26.325863,0,0,0,40,4449,301.25405,43516.669921875,,,,,,,,,,,,,0,,,,-0.0049,,,,,,300.0324402,,,,
,22141504.49,300.0321655,47509.9140625,-6.9457839902437E-5,1.70016174956719E-6,1,0.999253354069792,40.0298881530762,1.9995384542257,16.1199998110533,-0.000784398436030529,-0.000147635061846834,0.25,-1.00650323961779E-6,-6.9455082452644E-5,-1.05194398575942E-6,300.0321655,300.0321655,47502.48046875,47517.34765625,56.5703640793329,20.528307574034,26.705515,0,0,0,40,4449,301.25395,47509.9140625,,,,,,,,,,,,,0,,,,-0.00245,,,,,,300.0321655,,,,
,22141583.35,300.0241089,51450.521484375,-8.34172027450928E-5,1.3922234496955E-6,1,0.999253354069792,40.0298881530762,1.99952567411444,16.1199998110533,-0.000945448861208713,-0.000157619539616877,0.25,5.29948366391048E-7,-8.34150571641627E-5,4.7536673543077E-7,300.0241089,300.0241089,51445.51171875,51455.53125,56.567237565256,20.5266866016453,26.705515,0,0,0,40,4449,301.2228,51450.521484375,,,,,,,,,,,,,0,,,,-0.0049,,,,,,300.0241089,,,,
,22141662.555,300.0282898,55408.29296875,-9.62216814492343E-5,2.85490668913953E-6,1,0.999253354069792,40.0298881530762,1.99961339733626,16.1199998110533,-0.00109792893221175,-0.000139634976602082,0.25,4.33732014138382E-6,-9.62216317411379E-5,4.27430245340301E-6,300.0282898,300.0282898,55403.4375,55413.1484375,56.5562947659868,20.5264348263895,26.705515,0,0,0,40,4449,301.2003,55408.29296875,,,,,,,,,,,,,0,,,,-0.0049,,,,,,300.0282898,,,,
,22141745.905,300.0289001,59576.181640625,-0.000110104362899379,2.94839889616075E-6,1,0.999253354069792,40.0298881530762,1.99962997656007,16.1199998110533,-0.00124259660958919,-0.000239144275156533,0.25,-2.04643130547412E-6,-0.000110099729364322,-2.11826594923309E-6,300.0289001,300.0289001,59566.03125,59586.33203125,56.5766171074867,20.5266125744823,25.946213,0,0,0,40,4449,301.17345,59576.181640625,,,,,,,,,,,,,0,,,,0,,,,,,300.0289001,,,,
,22141826.87,300.0322876,63622.080078125,-0.000127301817280231,3.2914747058919E-6,1,0.999253354069792,40.0298881530762,1.99949743009398,16.1199998110533,-0.00144260710765799,-0.000241746389432041,0.25,7.0175987689674E-7,-0.000127298454135238,6.1868994386888E-7,300.0322876,300.0322876,63614.72265625,63629.4375,56.5602029085829,20.5277300832873,26.705515,0,0,0,40,4449,301.15555,63622.080078125,,,,,,,,,,,,,0,,,,-0.00245,,,,,,300.0322876,,,,
,22141907.49,300.0289917,67652.97265625,-0.000138390361295968,1.70371773876539E-6,1,0.999253354069792,40.0298881530762,1.99939155660595,16.1199998110533,-0.00156830493638644,-0.000262100964568313,0.25,8.23696097300463E-7,-0.000138386768120705,7.33471708870454E-7,300.0289917,300.0289917,67642.875,67663.0703125,56.5516049948714,20.5278885152291,26.325863,0,0,0,40,4449,301.13485,67652.97265625,,,,,,,,,,,,,0,,,,0,,,,,,300.0289917,,,,
,22141988.12,300.0281372,71680.9765625,-0.000155106501313443,1.8290470069263E-6,1,0.999253354069792,40.0298881530762,1.99947821114078,16.1199998110533,-0.00175694049301746,-0.000298808302071201,0.25,4.78257180540586E-7,-0.000155102197619715,3.77250203736049E-7,300.0281372,300.0281372,71670.8125,71691.140625,56.7180918694675,20.5273016135994,26.325863,0,0,0,40,4449,301.1354,71680.9765625,,,,,,,,,,,,,0,,,,-0.0049,,,,,,300.0281372,,,,
,22142065.445,300.0205078,75546.3515625,-0.000171778859896524,2.61437178049075E-6,1,0.999253354069792,40.0298881530762,1.99955848828203,16.1199998110533,-0.00194468963087649,-0.000337745985005372,0.25,-7.15887287591451E-8,-0.00017177375821114,-1.83333541670514E-7,300.0205078,300.0205078,75538.703125,75554,56.638365760506,20.5264020296787,25.946213,0,0,0,40,4449,301.11705,75546.3515625,,,,,,,,,,,,,0,,,,-0.0049,,,,,,300.0205078,,,,
,22142147.57,300.0266418,79649.734375,-0.000180167484749757,1.88745434654951E-6,1,0.999253354069792,40.0298881530762,1.99961105459836,16.1199998110533,-0.00204285653551623,-0.000336069618855504,0.25,1.53041144142587E-6,-0.00018016314725853,1.41327003310735E-6,300.0266418,300.0266418,79642.265625,79657.203125,56.5906864208329,20.5256028403823,26.705515,0,0,0,40,4449,301.08355,79649.734375,,,,,,,,,,,,,0,,,,-0.00245,,,,,,300.0266418,,,,
,22142226.28,300.0297852,83588.63671875,-0.000197966536681866,3.21107573829509E-6,1,0.999253354069792,40.0298881530762,1.99957245399617,16.1199998110533,-0.00224999804346142,-0.000338291840808707,0.25,4.41707812379066E-6,-0.000197963534285174,4.28840561927592E-6,300.0297852,300.0297852,83581.2109375,83596.0625,56.6250780756791,20.5249282032114,26.325863,0,0,0,40,4449,301.0673,83588.63671875,,,,,,,,,,,,,0,,,,-0.0098,,,,,,300.0297852,,,,
,22142306.15,300.026413,87577.02734375,-0.000210324529434272,3.23084377327011E-6,1,0.999253354069792,40.0298881530762,1.99963442973772,16.1199998110533,-0.00237699615342743,-0.000437508190476945,0.25,-2.20425091272667E-6,-0.000210316899644907,-2.34062106228879E-6,300.0263367,300.0264893,87569.46875,87584.5859375,56.6211699330829,20.5260961246363,27.085165,0,0,0,40,4449,301.04605,87577.02734375,,,,,,,,,,,,,0,,,,-0.0049,,,,,,300.026413,,,,
,22142402.445,300.0257568,88627.67578125,-0.00021996185655122,2.8015526333483E-6,1,0.999253354069792,40.0298881530762,1.99958246355779,16.1199998110533,-0.00249712745152232,-0.000392456992216784,0.25,3.44352044755818E-6,-0.000219957613659076,3.30076204810961E-6,300.0257568,300.0257568,88622.7265625,88632.625,56.4562463155252,20.526122931821,26.325863,0,0,0,40,4449,301.02875,88627.67578125,,,,,,,,,,,,,0,,,,-0.00245,,,,,,300.0257568,,,,
,22142480.505,300.021698,84727.0078125,-0.000205668558593267,3.12024749525563E-6,1,0.999253354069792,40.0298881530762,1.99949954429897,16.1199998110533,-0.00232760618574086,-0.000408290638489664,0.25,-4.32503117310795E-7,-0.000205662239768646,-5.66020836398846E-7,300.021698,300.021698,84719.5078125,84734.5078125,56.6117903908521,20.5265182991745,26.705515,0,0,0,40,4449,301.01415,84727.0078125,,,,,,,,,,,,,0,,,,-0.00245,,,,,,300.021698,,,,
,22142561.555,300.0166931,80675.8515625,-0.00018729952196948,2.5788117228025E-6,1,0.999253354069792,40.0298881530762,1.99948494850035,16.1199998110533,-0.00212549637662853,-0.000338389810102921,0.25,2.55929707871027E-6,-0.000187295708761742,2.43748701825375E-6,300.0166931,300.0166931,80671.078125,80680.625,56.5664559367368,20.5282068793823,26.705515,0,0,0,40,4449,301.00705,80675.8515625,,,,,,,,,,,,,0,,,,-0.0049,,,,,,300.0166931,,,,
,22142643.78,300.0088806,76564.1796875,-0.000173454018564953,2.89435427103749E-6,1,0.999253354069792,40.0298881530762,1.99945613633466,16.1199998110533,-0.00197350202949986,-0.00028362970527769,0.25,4.99730394845183E-6,-0.000173452236216066,4.88430089208168E-6,300.0088806,300.0088806,76556.8125,76571.546875,56.6547799594098,20.5294990812763,26.705515,0,0,0,40,4449,301.00085,76564.1796875,,,,,,,,,,,,,0,,,,0,,,,,,300.0088806,,,,
,22142724.755,300.008728,72518.015625,-0.000161480057381754,3.04454876051386E-6,1,0.999253354069792,40.0298881530762,1.99925145189218,16.1199998110533,-0.00183592122977078,-0.000270751714319814,0.25,4.0581387252749E-6,-0.000161478005501202,3.95284542718139E-6,300.008728,300.008728,72513.015625,72523.015625,56.6094455052945,20.5296746993719,27.085165,0,0,0,40,4449,301.0006,72518.015625,,,,,,,,,,,,,0,,,,0.0049,,,,,,300.008728,,,,
,22142804.64,300.0021973,68524.3125,-0.00014387945573263,3.31545662397052E-6,1,0.999253354069792,40.0298881530762,1.9993513189399,16.1199998110533,-0.00163103670787394,-0.000269279596350617,0.25,1.14015412637731E-6,-0.000143876041272989,1.04631611849551E-6,300.0021973,300.0021973,68519.46875,68529.15625,56.5852150211983,20.531754765549,27.085165,0,0,0,40,4449,301.0028,68524.3125,,,,,,,,,,,,,0,,,,-0.0049,,,,,,300.0021973,,,,
,22142886.61,300.0018005,64426.388671875,-0.000131365099965065,3.05339222016825E-6,1,0.999253354069792,40.0298881530762,1.99924169954133,16.1199998110533,-0.00149147911865747,-0.000232080198681703,0.25,2.25707401296727E-6,-0.000131362770851774,2.17127355584416E-6,300.0018005,300.0018005,64421.4765625,64431.30078125,56.6414922745829,20.5319189749987,27.085165,0,0,0,40,4449,300.9977,64426.388671875,,,,,,,,,,,,,0,,,,-0.0049,,,,,,300.0018005,,,,
,22142966.725,300.0012512,60420.103515625,-0.000113912444528103,2.66532989994455E-6,1,0.999253354069792,40.0298881530762,1.99927381428202,16.1199998110533,-0.00129348066714853,-0.000200477353647262,0.25,2.02553531448503E-6,-0.000113910466534016,1.95105918586116E-6,300.0012512,300.0012512,60412.7578125,60427.44921875,56.6844818431406,20.5336555190777,26.705515,0,0,0,40,4449,300.9996,60420.103515625,,,,,,,,,,,,,0,,,,-0.00245,,,,,,300.0012512,,,,
,22143045.305,300.0027771,56494.400390625,-0.000100796114191323,2.77254414529975E-6,1,0.999253354069792,40.0298881530762,1.99926018734024,16.1199998110533,-0.00114162389228544,-0.000194204671020179,0.25,3.0720312961007E-7,-0.000100793382699916,2.41281018367132E-7,300.0027466,300.0028076,56489.3984375,56499.40234375,56.770460980256,20.5343563114543,26.705515,0,0,0,40,4449,300.9932,56494.400390625,,,,,,,,,,,,,0,,,,0.0049,,,,,,300.0027771,,,,
,22143125.41,300.0061035,52488.865234375,-8.75838844543153E-5,1.48685877696086E-6,1,0.999253354069792,40.0298881530762,1.99903914610128,16.1199998110533,-0.000993121654681423,-0.000161543242411747,0.25,9.01989284276964E-7,-8.75819115003425E-5,8.44634622872023E-7,300.0061035,300.0061035,52481.29296875,52496.4375,56.7204367550252,20.5366217389617,27.085165,0,0,0,40,4449,300.99375,52488.865234375,,,,,,,,,,,,,0,,,,-0.0049,,,,,,300.0061035,,,,
,22143205.275,300.0024414,48496.11328125,-7.3804067130383E-5,2.32602652930406E-6,1,0.999253354069792,40.0298881530762,1.99899472145225,16.1199998110533,-0.000836415638458197,-0.00013865088714851,0.25,5.36901515287658E-7,-7.38022644183072E-5,4.88530708447914E-7,300.0024414,300.0024414,48488.625,48503.6015625,56.7837486650829,20.5385016729244,26.325863,0,0,0,40,4449,300.98915,48496.11328125,,,,,,,,,,,,,0,,,,-0.0049,,,,,,300.0024414,,,,
,22143286.63,300.0040588,44432.658203125,-6.09410530914828E-5,1.89965320397579E-6,1,0.999253354069792,40.0298881530762,1.99901980629484,16.1199998110533,-0.000693032202216381,-0.000100727709546705,0.25,1.65901010705446E-6,-6.09403551836005E-5,1.61899619216792E-6,300.0040588,300.0040588,44430.2265625,44435.08984375,56.7634263235829,20.5386482574216,27.085165,0,0,0,40,4449,300.98905,44432.658203125,,,,,,,,,,,,,0,,,,-0.0049,,,,,,300.0040588,,,,
,22143369.1,300.0000305,40310.193359375,-4.52935690358792E-5,2.14111886385289E-6,1,0.999253354069792,40.0298881530762,1.99913875009685,16.1199998110533,-0.000510814878342082,-9.96921247827659E-5,0.25,-9.59929637970628E-7,-4.5291615676458E-5,-9.89632889228097E-7,300.0000305,300.0000305,40302.7109375,40317.67578125,56.7915649502752,20.5386808829233,26.705515,0,0,0,40,4449,300.99215,40310.193359375,,,,,,,,,,,,,0,,,,-0.00245,,,,,,300.0000305,,,,
,22143447.78,299.9994202,36377.251953125,-3.1643127542418E-5,1.50110234030784E-6,1,0.999253354069792,40.0298881530762,1.99904437573726,16.1199998110533,-0.000358500146502218,-6.01248738577376E-5,0.25,1.70388173306039E-7,-3.16423140687254E-5,1.49593613486189E-7,299.9994202,299.9994202,36369.921875,36384.58203125,56.780622151006,20.5387164538466,26.325863,0,0,0,40,4449,300.98875,36377.251953125,,,,,,,,,,,,,0,,,,0,,,,,,299.9994202,,,,
,22143527.38,300.0038757,32399.4033203125,-1.94344737329309E-5,1.06755800376434E-6,1,0.999253354069792,40.0298881530762,1.99894710122639,16.1199998110533,-0.000221608602235602,-2.86347926919737E-5,0.25,8.37165236403618E-7,-1.94344517584793E-5,8.24361034969937E-7,300.0038757,300.0038757,32396.8125,32401.994140625,56.8556584888522,20.5399325584396,26.325863,0,0,0,40,4449,300.99065,32399.4033203125,,,,,,,,,,,,,0,,,,-0.00245,,,,,,300.0038757,,,,
,22143609.43,300.0018921,28299.0498046875,-3.83802805402721E-6,1.21255384351259E-6,1,0.999253354069792,40.0298881530762,1.99896053590318,16.1199998110533,-4.1788673137165E-5,-1.70608085979137E-5,0.25,-8.42387325158731E-7,-3.83736064218999E-6,-8.44888573214744E-7,300.0018921,300.0018921,28294.2578125,28303.841796875,56.8673829166406,20.5400838343929,26.705515,0,0,0,40,4449,300.9855,28299.0498046875,,,,,,,,,,,,,0,,,,-0.00245,,,,,,300.0018921,,,,
,22143689.955,300.004425,24273.6767578125,7.0514913617494E-6,1.13070320355871E-6,1,0.999253354069792,40.0298881530762,1.99909382338397,16.1199998110533,8.10940555440556E-5,6.45832632669772E-6,0.25,-6.51142509009949E-7,7.05171170676866E-6,-6.46478332619737E-7,300.004425,300.004425,24266.345703125,24281.0078125,56.8853603725829,20.5386816923485,26.325863,0,0,0,40,4449,300.98595,24273.6767578125,,,,,,,,,,,,,0,,,,0.00245,,,,,,300.004425,,,,
,22143769.95,299.9992676,20275.541015625,2.17602400833751E-5,1.03233438153606E-6,1,0.999253354069792,40.0298881530762,1.99888949541379,16.1199998110533,0.00024569354635835,4.60783903556862E-5,0.25,3.01135038150361E-7,2.17594009295379E-5,3.1547146861886E-7,299.9992676,299.9992676,20262.95703125,20288.125,56.9486722826406,20.5426348119923,26.325863,0,0,0,40,4449,300.987,20275.541015625,,,,,,,,,,,,,0,,,,-0.00245,,,,,,299.9992676,,,,
,22143851.47,299.9978943,16203.0087890625,3.34628597085432E-5,7.37896872075375E-7,1,0.999253354069792,40.0298881530762,1.9989356342539,16.1199998110533,0.000376724885225069,7.7270684116534E-5,0.25,1.02939255731081E-6,3.34611954360351E-5,1.05144019844913E-6,299.9978943,299.9978943,16200.6884765625,16205.3291015625,57.0205821064099,20.5420060482644,26.705515,0,0,0,40,4449,300.98325,16203.0087890625,,,,,,,,,,,,,0,,,,0,,,,,,299.9978943,,,,
,22143931.245,300.0039673,12215.4599609375,4.55097225679271E-5,6.38917878325014E-7,1,0.999253354069792,40.0298881530762,1.99904043846313,16.1199998110533,0.000513972733852554,9.58661500884544E-5,0.25,5.84706845459616E-7,4.55079848686384E-5,6.14737540458856E-7,300.0039673,300.0039673,12208.0546875,12222.865234375,56.8439340610637,20.5419112085668,26.705515,0,0,0,40,4449,300.98515,12215.4599609375,,,,,,,,,,,,,0,,,,0,,,,,,300.0039673,,,,
,22144013.135,299.9991455,8122.2041015625,5.46468898328739E-5,4.39131075565665E-7,1,0.999253354069792,40.0298881530762,1.99905122818305,16.1199998110533,0.000617675910544489,0.000112184556494918,0.25,4.43249659939234E-7,5.46449810821623E-5,4.79343443845849E-7,299.9991455,299.9991455,8114.8076171875,8129.6005859375,56.9705578811791,20.5406332162585,26.325863,0,0,0,40,4449,300.9822,8122.2041015625,,,,,,,,,,,,,0,,,,-0.0049,,,,,,299.9991455,,,,
,22144093.17,299.9989319,4121.58203125,5.87790875646405E-5,4.20920726015285E-7,1,0.999253354069792,40.0298881530762,1.99903790751814,16.1199998110533,0.00066549978115833,0.000114192453465213,0.25,-9.52500440098862E-8,5.87774108114535E-5,-5.63865918258025E-8,299.9989319,299.9989319,4116.662109375,4126.501953125,56.8275198621599,20.5409678289996,26.705515,0,0,0,40,4449,300.98725,4121.58203125,,,,,,,,,,,,,0,,,,0,,,,,,299.9989319,,,,
,22144171.265,300.0032959,217.630516052246,3.20136949327307E-5,3.93110168429633E-7,1,0.999253354069792,40.0298881530762,1.99884375989467,16.1199998110533,0.000362814194883207,5.99537127395817E-5,0.25,-2.49344698309728E-7,3.20129063669566E-5,-2.28161516558693E-7,300.0032959,300.0032959,212.552398681641,222.708633422852,56.9986965078714,20.5409767629164,27.464817,0,0,0,40,4449,300.9833,217.630516052246,,,,,,,,,,,,,0,,,,0.00245,,,,,,300.0032959,,,,
,22144250.035,300.0050049,-3715.71618652344,-5.6750474691654E-5,4.53443221734448E-7,1,0.999253354069792,40.0298881530762,1.99911532005439,16.1199998110533,-0.000640908875497853,-0.000119758329918762,0.25,-7.47565026280671E-7,-5.67482880559067E-5,-7.850654229934E-7,300.0050049,300.0050049,-3725.67333984375,-3705.75903320313,56.9205336559483,20.5412219389776,27.085165,0,0,0,40,4449,300.98005,-3715.71618652344,,,,,,,,,,,,,0,,,,0,,,,,,300.0050049,,,,
,22144329.295,300.0066528,-7677.52075195313,-5.49004996077582E-5,5.56316181970706E-7,1,0.999253354069792,40.0298881530762,1.99893838043879,16.1199998110533,-0.000619867381519432,-0.000116401617929831,0.25,-7.72429713190424E-7,-5.48983506678374E-5,-8.08684818686001E-7,300.0066528,300.0066528,-7679.98779296875,-7675.0537109375,56.9963516223137,20.5422940091457,26.705515,0,0,0,40,4449,300.9748,-7677.52075195313,,,,,,,,,,,,,0,,,,0,,,,,,300.0066528,,,,
,22144410.335,300.0115051,-11728.8818359375,-4.52021369365524E-5,5.47319249390336E-7,1,0.999253354069792,40.0298881530762,1.99888309973627,16.1199998110533,-0.000508919075781927,-0.000104107621075367,0.25,-1.36680290887823E-6,-4.51998790917333E-5,-1.39661238304211E-6,300.0115051,300.0115051,-11738.3095703125,-11719.4541015625,57.0119841926983,20.5433238483695,26.705515,0,0,0,40,4449,300.9605,-11728.8818359375,,,,,,,,,,,,,0,,,,0,,,,,,300.0115051,,,,
,22144490.195,300.0144653,-15719.3671875,-3.44043709865168E-5,6.94454039844567E-7,1,0.999253354069792,40.0298881530762,1.99884256064188,16.1199998110533,-0.00038585329378053,-8.78315231021277E-5,0.25,-1.79968885990385E-6,-3.44021495876468E-5,-1.82233889201093E-6,300.0144653,300.0144653,-15732.0234375,-15706.7109375,56.9510171681983,20.5433779819385,27.464817,0,0,0,40,4449,300.95055,-15719.3671875,,,,,,,,,,,,,0,,,,0.00245,,,,,,300.0144653,,,,
,22144573.075,300.0170288,-19861.88671875,-2.11058611846649E-5,1.20837549112862E-6,1,0.999253354069792,40.0298881530762,1.99894869770249,16.1199998110533,-0.000232391218235976,-7.88651036647568E-5,0.25,-3.31115920218633E-6,-2.11030426068669E-5,-3.32497704346062E-6,300.0170288,300.0170288,-19869.169921875,-19854.603515625,57.0495023616214,20.5415446360056,27.085165,0,0,0,40,4449,300.942,-19861.88671875,,,,,,,,,,,,,0,,,,0,,,,,,300.0170288,,,,
,22144654.355,300.017395,-23924.4638671875,-7.52913559783734E-6,1.33703167539567E-6,1,0.999253354069792,40.0298881530762,1.99901997705615,16.1199998110533,-8.45673636067073E-5,-1.85352264401389E-5,0.25,-3.33101682099564E-7,-7.52868979688719E-6,-3.38052520815437E-7,300.017395,300.017395,-23926.96875,-23921.958984375,56.953362053756,20.5446304012678,26.705515,0,0,0,40,4449,300.937,-23924.4638671875,,,,,,,,,,,,,0,,,,-0.00245,,,,,,300.017395,,,,
,22144735.765,300.0116272,-27992.3125,5.47734489158221E-6,1.06599234277468E-6,1,0.999253354069792,40.0298881530762,1.99883779329355,16.1199998110533,6.44495126706834E-5,-3.44717075149597E-6,0.25,-1.25355608470326E-6,5.47800692492801E-6,-1.24991268051328E-6,300.0116272,300.0116272,-27999.736328125,-27984.888671875,56.953362053756,20.5446881518992,27.085165,0,0,0,40,4449,300.92695,-27992.3125,,,,,,,,,,,,,0,,,,0.0049,,,,,,300.0116272,,,,
,22144817.915,300.0164795,-32100.498046875,2.0613197021849E-5,1.54525337246818E-6,1,0.999253354069792,40.0298881530762,1.99883625826541,16.1199998110533,0.000239901883846759,2.28972409196772E-6,0.25,-3.36901200420294E-6,2.06147962328994E-5,-3.35535151847723E-6,300.0164795,300.0164795,-32112.943359375,-32088.052734375,57.0659165605253,20.5447265373511,26.705515,0,0,0,40,4449,300.91255,-32100.498046875,,,,,,,,,,,,,0,,,,0.00245,,,,,,300.0164795,,,,
,22144899.065,300.0169373,-36152.390625,3.1794584895392E-5,1.52324207146166E-6,1,0.999253354069792,40.0298881530762,1.99873763733818,16.1199998110533,0.000367075249767817,2.05076449990923E-5,0.25,-3.69645979003092E-6,3.17960638371154E-5,-3.67545207011516E-6,300.0169373,300.0169373,-36159.79296875,-36144.98828125,56.9447641400445,20.5466965770652,27.464817,0,0,0,40,4449,300.90185,-36152.390625,,,,,,,,,,,,,0,,,,0,,,,,,300.0169373,,,,
,22144980.535,300.0167847,-40225.052734375,4.66766787294067E-5,1.50503555141469E-6,1,0.999253354069792,40.0298881530762,1.99879548144877,16.1199998110533,0.000537037139302741,4.09005376592964E-5,0.25,-4.47298123760104E-6,4.66782231901217E-5,-4.44219541861171E-6,300.0167847,300.0167847,-40227.69140625,-40222.4140625,57.0471574760637,20.5471479883508,27.085165,0,0,0,40,4449,300.88695,-40225.052734375,,,,,,,,,,,,,0,,,,0,,,,,,300.0167847,,,,
,22145060.465,300.0179138,-44220.04296875,6.09147577703505E-5,1.81829271239303E-6,1,0.999253354069792,40.0298881530762,1.99894090724815,16.1199998110533,0.000695602004275419,8.39690333475736E-5,0.25,-3.13479741160882E-6,6.09149974145061E-5,-3.09473660499185E-6,300.0179138,300.0179138,-44224.8203125,-44215.265625,57.0924919301791,20.5448631021553,27.085165,0,0,0,40,4449,300.87795,-44220.04296875,,,,,,,,,,,,,0,,,,0,,,,,,300.0179138,,,,
,22145141.79,300.0239563,-48285.6171875,7.45625687469276E-5,1.72485637460188E-6,1,0.999253354069792,40.0298881530762,1.99880029680417,16.1199998110533,0.000851625461198537,0.000101431738642561,0.25,-3.95580200681192E-6,7.45629253172422E-5,-3.90680486734741E-6,300.0239563,300.0239563,-48298.11328125,-48273.12109375,56.9916618511983,20.5456566092785,26.705515,0,0,0,40,4449,300.8629,-48285.6171875,,,,,,,,,,,,,0,,,,0,,,,,,300.0239563,,,,
,22145224.755,300.0230103,-52433.244140625,9.10294951119794E-5,1.97099167440568E-6,1,0.999253354069792,40.0298881530762,1.99891854878039,16.1199998110533,0.00104282697102768,0.000106155796722547,0.25,-6.39179633739995E-6,9.10309587165292E-5,-6.33198542129175E-6,300.0230103,300.0230103,-52440.51171875,-52425.9765625,57.0534105042176,20.5448277838699,26.705515,0,0,0,40,4449,300.84105,-52433.244140625,,,,,,,,,,,,,0,,,,0.00245,,,,,,300.0230103,,,,
,22145306.335,300.0196533,-56508.443359375,0.000104092181798378,2.166150699153E-6,1,0.999253354069792,40.0298881530762,1.99913596123118,16.1199998110533,0.0011864471673625,0.000156892920925768,0.25,-4.17352262829761E-6,0.000104091817571073,-4.10528846595441E-6,300.0196533,300.0196533,-56518.3359375,-56498.55078125,57.0495023616214,20.5472302792975,26.705515,0,0,0,40,4449,300.8352,-56508.443359375,,,,,,,,,,,,,0,,,,0,,,,,,300.0196533,,,,
,22145384.075,300.0195465,-60393.443359375,0.000120645464783669,1.92236100432738E-6,1,0.999253354069792,40.0298881530762,1.99889802483457,16.1199998110533,0.00137939624226794,0.000156251169803878,0.25,-7.09644724643035E-6,0.000120646523449538,-7.01736466741587E-6,300.019104,300.019989,-60401.0859375,-60385.80078125,57.1026531009291,20.5458966734301,27.085165,0,0,0,40,4449,300.8182,-60393.443359375,,,,,,,,,,,,,0,,,,-0.00245,,,,,,300.0195465,,,,
,22145467.34,300.0201721,-64556.583984375,0.000134208051286566,2.48488797264328E-6,1,0.999253354069792,40.0298881530762,1.99916440617534,16.1199998110533,0.00152767175132113,0.000214167927125191,0.25,-4.33132140281176E-6,0.000134206901482483,-4.24353892720696E-6,300.0201721,300.0201721,-64564.09375,-64549.07421875,57.0534105042176,20.5466893756595,26.705515,0,0,0,40,4449,300.8022,-64556.583984375,,,,,,,,,,,,,0,,,,0,,,,,,300.0201721,,,,
,22145548.08,300.0179138,-68591.5,0.000147887543270458,2.66087776515391E-6,1,0.999253354069792,40.0298881530762,1.99908050937516,16.1199998110533,0.00168738224294997,0.000212519320285373,0.25,-6.84608425846278E-6,0.000147887646324486,-6.74938704861419E-6,300.0179138,300.0179138,-68601.3984375,-68581.6015625,56.9893169656406,20.54822736154,26.705515,0,0,0,40,4449,300.7921,-68591.5,,,,,,,,,,,,,0,,,,-0.00245,,,,,,300.0179138,,,,
,22145627.71,300.0179138,-72568.7578125,0.000160455237355054,2.60951791101986E-6,1,0.999253354069792,40.0298881530762,1.9990726421646,16.1199998110533,0.00182697180302079,0.000252511124751929,0.25,-5.49011809661183E-6,0.000160454090297461,-5.38536198709375E-6,300.0179138,300.0179138,-72573.859375,-72563.65625,56.7696793517368,20.547830238004,27.085165,0,0,0,40,4449,300.78295,-72568.7578125,,,,,,,,,,,,,0,,,,0.00245,,,,,,300.0179138,,,,
,22145710.28,300.0174561,-76696.24609375,0.000177364931258258,2.36067086316517E-6,1,0.999253354069792,40.0298881530762,1.9991385341542,16.1199998110533,0.00202280777165111,0.000260455000740414,0.25,-7.71848596998007E-6,0.000177364746905844,-7.60275851194173E-6,300.0174561,300.0174561,-76701.265625,-76691.2265625,56.9346029692945,20.5489357738646,26.705515,0,0,0,40,4449,300.7721,-76696.24609375,,,,,,,,,,,,,0,,,,0,,,,,,300.0174561,,,,
,22145790.585,300.017334,-80709.08984375,0.000194032522350296,3.20504532875251E-6,1,0.999253354069792,40.0298881530762,1.99922519029246,16.1199998110533,0.00221525426188981,0.000271870555353205,0.25,-9.59848414273131E-6,0.000194033078196276,-9.47196991900968E-6,300.017334,300.017334,-80719.171875,-80699.0078125,56.9510171681983,20.5479008405995,27.464817,0,0,0,40,4449,300.75515,-80709.08984375,,,,,,,,,,,,,0,,,,-0.00245,,,,,,300.017334,,,,
,22145871.445,300.0212097,-84751.49609375,0.000208056387418522,2.7933514690073E-6,1,0.999253354069792,40.0298881530762,1.99918218338743,16.1199998110533,0.00237105779340233,0.000316085115762472,0.25,-8.12145339627962E-6,0.000208055548749103,-7.98599059765967E-6,300.0212097,300.0212097,-84756.2265625,-84746.765625,57.0080760501022,20.5491290663479,27.085165,0,0,0,40,4449,300.7372,-84751.49609375,,,,,,,,,,,,,0,,,,-0.0049,,,,,,300.0212097,,,,
,22145951.705,300.0192566,-88761.14453125,0.000225588612375152,4.06168568557207E-6,1,0.999253354069792,40.0298881530762,1.9992569528412,16.1199998110533,0.00256819939777159,0.00035861564483765,0.25,-7.40260567452564E-6,0.000225586815196555,-7.25592051275207E-6,300.0192566,300.0192566,-88768.609375,-88753.6796875,57.0409044479099,20.547915364776,27.464817,0,0,0,40,4449,300.73165,-88761.14453125,,,,,,,,,,,,,0,,,,-0.00245,,,,,,300.0192566,,,,
,22146047.645,300.01553345,-87499,0.000221432549221937,4.00363994107472E-6,1,0.999253354069792,40.0298881530762,1.99934005263586,16.1199998110533,0.002514702206906,0.000388289450273635,0.25,-4.06266591694395E-6,0.000221428730832282,-3.91872080655147E-6,300.0153503,300.0157166,-87504.0390625,-87493.9609375,57.108906129083,20.5467253833817,26.705515,0,0,0,40,4449,300.7154,-87499,,,,,,,,,,,,,0,,,,0.00245,,,,,,300.01553345,,,,
,22146127.265,300.010437,-83521.33984375,0.00020810831231563,6.25436967738756E-6,1,0.999253354069792,40.0298881530762,1.99936752929583,16.1199998110533,0.00237372815882407,0.000305410279024484,0.25,-9.07593585349947E-6,0.0002081081705109,-8.94035858102094E-6,300.010437,300.010437,-83526.390625,-83516.2890625,57.0119841926983,20.5471909171132,27.085165,0,0,0,40,4449,300.71295,-83521.33984375,,,,,,,,,,,,,0,,,,-0.00245,,,,,,300.010437,,,,
,22146209.41,300.0047302,-79415.94921875,0.000185770440063932,4.97801775979236E-6,1,0.999253354069792,40.0298881530762,1.99935489292915,16.1199998110533,0.00212514762504503,0.000236710024239635,0.25,-1.12745491671864E-5,0.000185772410964912,-1.11533045505683E-5,300.0047302,300.0047302,-79418.5390625,-79413.359375,56.9205336559483,20.5452708507821,27.464817,0,0,0,40,4449,300.71055,-79415.94921875,,,,,,,,,,,,,0,,,,-0.0049,,,,,,300.0047302,,,,
,22146292.585,299.9994202,-75255.984375,0.000171331053199052,6.60536512576116E-6,1,0.999253354069792,40.0298881530762,1.99939373040018,16.1199998110533,0.00195517263578935,0.000246195732153573,0.25,-7.93557622932331E-6,0.000171331295705498,-7.82371052761705E-6,299.9994202,299.9994202,-75260.921875,-75251.046875,57.1487691835637,20.5474713124285,27.085165,0,0,0,40,4449,300.7143,-75255.984375,,,,,,,,,,,,,0,,,,0,,,,,,299.9994202,,,,
,22146372.455,299.995575,-71266.12109375,0.000153530737332895,7.34689878461381E-6,1,0.999253354069792,40.0298881530762,1.9991889491712,16.1199998110533,0.00175329535019431,0.000212370649733776,0.25,-7.83784321375306E-6,0.000153531445619112,-7.73747919676967E-6,299.995575,299.995575,-71268.71875,-71263.5234375,57.1034347294484,20.5465607327787,27.085165,0,0,0,40,4449,300.71695,-71266.12109375,,,,,,,,,,,,,0,,,,0,,,,,,299.995575,,,,
,22146453.945,299.99194335,-67193.87109375,0.000137985356151105,6.06216106501814E-6,1,0.999253354069792,40.0298881530762,1.99917094517179,16.1199998110533,0.00157948809901739,0.00016932601720173,0.25,-8.94721687344858E-6,0.000137987249791511,-8.85687149705617E-6,299.9916992,299.9921875,-67206.5078125,-67181.234375,56.9791557948906,20.5475495316879,27.085165,0,0,0,40,4449,300.7241,-67193.87109375,,,,,,,,,,,,,0,,,,0,,,,,,299.99194335,,,,
,22146535.79,299.992218,-63104.103515625,0.000123112394059214,5.97808494146888E-6,1,0.999253354069792,40.0298881530762,1.99918700487413,16.1199998110533,0.00141279551550278,0.000130619047318048,0.25,-9.79011594186906E-6,0.000123115261601193,-9.70937633549964E-6,299.992218,299.992218,-63114.22265625,-63093.984375,57.1135959001984,20.5474536313416,27.464817,0,0,0,40,4449,300.7297,-63104.103515625,,,,,,,,,,,,,0,,,,0,,,,,,299.992218,,,,
,22146617.555,299.9921875,-59015.982421875,0.000105975652278893,4.92461309810034E-6,1,0.999253354069792,40.0298881530762,1.99915757664887,16.1199998110533,0.00120475126461026,0.000178073759369957,0.25,-2.62880177309397E-6,0.000105974326862831,-2.55939934412017E-6,299.9921875,299.9921875,-59026.01171875,-59005.953125,56.8376810329099,20.5444732362999,26.705515,0,0,0,40,4449,300.73665,-59015.982421875,,,,,,,,,,,,,0,,,,0.0049,,,,,,299.9921875,,,,
,22146698.76,299.9937134,-54958.322265625,9.50097050530397E-5,5.23426689020468E-6,1,0.999253354069792,40.0298881530762,1.99914065498926,16.1199998110533,0.00108865301167998,0.000110159903473432,0.25,-6.72862771857704E-6,9.50113704363482E-5,-6.66621944981731E-6,299.9937134,299.9937134,-54963.44921875,-54953.1953125,57.0112025641791,20.5462166082245,27.085165,0,0,0,40,4449,300.73715,-54958.322265625,,,,,,,,,,,,,0,,,,-0.00245,,,,,,299.9937134,,,,
,22146778.79,299.9916687,-50958.443359375,8.0798770397508E-5,4.94755413593978E-6,1,0.999253354069792,40.0298881530762,1.99918742561961,16.1199998110533,0.00092655546706932,8.95558903502488E-5,0.25,-6.08702436271355E-6,8.08004308401878E-5,-6.03389129591556E-6,299.9916687,299.9916687,-50966.078125,-50950.80859375,56.9713395096983,20.5470477660595,27.464817,0,0,0,40,4449,300.74465,-50958.443359375,,,,,,,,,,,,,0,,,,0,,,,,,299.9916687,,,,
,22146857.775,299.9918213,-47013.15625,6.88221806658927E-5,4.60371101180426E-6,1,0.999253354069792,40.0298881530762,1.9991214971416,16.1199998110533,0.000781586146523952,0.000120166194642189,0.25,-1.30760402312255E-6,6.88210504769415E-5,-1.26241643531356E-6,299.9918213,299.9918213,-47018.1484375,-47008.1640625,56.9009929429675,20.545296784876,26.705515,0,0,0,40,4449,300.74415,-47013.15625,,,,,,,,,,,,,0,,,,-0.0049,,,,,,299.9918213,,,,
,22146940.32,299.9932251,-42885.34765625,5.37333148672209E-5,4.12836550815308E-6,1,0.999253354069792,40.0298881530762,1.99912879658215,16.1199998110533,0.000617050621173532,5.44525977502281E-5,0.25,-4.49889649654495E-6,5.37347112550624E-5,-4.46348236564315E-6,299.9932251,299.9932251,-42890.29296875,-42880.40234375,56.9682129956214,20.5460302054785,27.085165,0,0,0,40,4449,300.75125,-42885.34765625,,,,,,,,,,,,,0,,,,-0.0049,,,,,,299.9932251,,,,
,22147023.595,299.9971924,-38725.22265625,3.78822412402046E-5,3.96399703037141E-6,1,0.999253354069792,40.0298881530762,1.99924001859777,16.1199998110533,0.000437388541348419,2.48741922575759E-5,0.25,-4.36586665858566E-6,3.78840050288443E-5,-4.34084046438863E-6,299.9971924,299.9971924,-38732.734375,-38717.7109375,57.0026046504676,20.544868373867,27.085165,0,0,0,40,4449,300.7507,-38725.22265625,,,,,,,,,,,,,0,,,,-0.0049,,,,,,299.9971924,,,,
,22147104.68,299.9912109,-34672.685546875,2.64397871540576E-5,3.51600359269962E-6,1,0.999253354069792,40.0298881530762,1.99912440277615,16.1199998110533,0.000306322879012753,1.12085757285284E-5,0.25,-3.59059262998525E-6,2.64413817566075E-5,-3.57309536988249E-6,299.9912109,299.9912109,-34680.24609375,-34665.125,56.963523224506,20.5447693565848,27.085165,0,0,0,40,4449,300.7604,-34672.685546875,,,,,,,,,,,,,0,,,,0,,,,,,299.9912109,,,,
,22147187.205,299.9926758,-30550.4228515625,1.39075769399651E-5,2.8451589397246E-6,1,0.999253354069792,40.0298881530762,1.99920400944765,16.1199998110533,0.000155790951109784,3.67401120384752E-5,0.25,8.36100464209438E-7,1.39066213196114E-5,8.45233052647973E-7,299.9926758,299.9926758,-30552.86328125,-30547.982421875,56.8650380310829,20.5456291170554,27.464817,0,0,0,40,4449,300.76525,-30550.4228515625,,,,,,,,,,,,,0,,,,0,,,,,,299.9926758,,,,
,22147267.67,299.9883728,-26527.509765625,-3.65800602874727E-7,2.67510110793339E-6,1,0.999253354069792,40.0298881530762,1.9992443888365,16.1199998110533,-3.75177766611914E-7,-2.24522992440983E-5,0.25,-1.92004194054426E-6,-3.64524763492709E-7,-1.92022726089486E-6,299.9883728,299.9883728,-26535.052734375,-26519.966796875,56.9174071418714,20.5434696961866,26.705515,0,0,0,40,4449,300.7732,-26527.509765625,,,,,,,,,,,,,0,,,,0.00245,,,,,,299.9883728,,,,
,22147350.21,299.9962463,-22402.681640625,-1.3572668908804E-5,2.352033464544E-6,1,0.999253354069792,40.0298881530762,1.99919013102691,16.1199998110533,-0.0001489705546065,-5.35615643924161E-5,0.25,-2.3801656957472E-6,-1.35707007140781E-5,-2.38904718837842E-6,299.9962463,299.9962463,-22412.708984375,-22392.654296875,57.065134932006,20.5430782834771,27.085165,0,0,0,40,4449,300.7737,-22402.681640625,,,,,,,,,,,,,0,,,,0,,,,,,299.9962463,,,,
,22147431.225,299.9937744,-18352.5888671875,-2.46438354148823E-5,1.69205443061077E-6,1,0.999253354069792,40.0298881530762,1.99916829535719,16.1199998110533,-0.000278867619898114,-4.88524718694605E-5,0.25,-4.60415376533569E-8,-2.46430824743525E-5,-6.23075033378354E-8,299.9937744,299.9937744,-18359.94921875,-18345.228515625,56.9549253107945,20.5414374633893,27.085165,0,0,0,40,4449,300.75365,-18352.5888671875,,,,,,,,,,,,,0,,,,0.0049,,,,,,299.9937744,,,,
,22147512.805,299.9989014,-14277.5161132812,-3.88439177110218E-5,1.6816657744712E-6,1,0.999253354069792,40.0298881530762,1.99924522515259,16.1199998110533,-0.000434960081225077,-0.000103615688640984,0.25,-2.42334990736218E-6,-3.88411692237228E-5,-2.44893744020849E-6,299.9989014,299.9989014,-14287.689453125,-14267.3427734375,56.9189703989099,20.5418590754367,27.085165,0,0,0,40,4449,300.7683,-14277.5161132812,,,,,,,,,,,,,0,,,,-0.00245,,,,,,299.9989014,,,,
,22147592.59,299.9962769,-10289.4184570312,-4.87677777469226E-5,1.29675461622353E-6,1,0.999253354069792,40.0298881530762,1.99925451638693,16.1199998110533,-0.000552042886355495,-9.57080822837357E-5,0.25,-5.35907445236942E-9,-4.87663359549367E-5,-3.75950572184944E-8,299.9962769,299.9962769,-10294.2333984375,-10284.603515625,56.9033378285253,20.5437184700983,27.085165,0,0,0,40,4449,300.7801,-10289.4184570312,,,,,,,,,,,,,0,,,,0.0049,,,,,,299.9962769,,,,
,22147671.65,299.9984741,-6338.30810546875,-5.64984103330449E-5,8.33296290474154E-7,1,0.999253354069792,40.0298881530762,1.99927814292203,16.1199998110533,-0.000638431737450332,-0.000117389819831585,0.25,-5.81169873827674E-7,-5.64963531267863E-5,-6.18522285148958E-7,299.9984741,299.9984741,-6345.861328125,-6330.7548828125,56.9064643426022,20.543052464145,26.705515,0,0,0,40,4449,300.78755,-6338.30810546875,,,,,,,,,,,,,0,,,,0.00245,,,,,,299.9984741,,,,
,22147752.215,299.9931641,-2309.45239257813,-5.47690124264364E-5,3.96000635242707E-7,1,0.999253354069792,40.0298881530762,1.99926285639736,16.1199998110533,-0.000620364205893745,-0.000105258911223459,0.25,1.90772457390298E-7,-5.47675255783307E-5,1.54519364756434E-7,299.9931641,299.9931641,-2311.86572265625,-2307.0390625,56.8759808303522,20.5423994032623,27.085165,0,0,0,40,4449,300.7839,-2309.45239257813,,,,,,,,,,,,,0,,,,-0.0049,,,,,,299.9931641,,,,
,22147830.175,299.9916077,1586.36706542969,4.93875204356919E-5,4.24991546276089E-7,1,0.999253354069792,40.0298881530762,1.99920592149373,16.1199998110533,0.000559717323110223,9.30436723287932E-5,0.25,-3.37238550749963E-7,4.93862916755462E-5,-3.04541456226299E-7,299.9916077,299.9916077,1578.87475585938,1593.859375,56.9517987967176,20.5418324054283,27.085165,0,0,0,40,4449,300.7966,1586.36706542969,,,,,,,,,,,,,0,,,,0,,,,,,299.9916077,,,,
,22147908.765,299.9997253,5511.095703125,5.75841710555606E-5,8.16216133195555E-7,1,0.999253354069792,40.0298881530762,1.99925409148663,16.1199998110533,0.000652739873114784,0.000107832238861729,0.25,-4.51137908495876E-7,5.75827615580707E-5,-4.13032457283927E-7,299.9997253,299.9997253,5501.42041015625,5520.77099609375,56.9064643426022,20.5427416199401,26.705515,0,0,0,40,4449,300.79155,5511.095703125,,,,,,,,,,,,,0,,,,0,,,,,,299.9997253,,,,
,22147987.85,300.0089722,9467.61767578125,5.59239168247264E-5,3.28902179239547E-6,1,0.999253354069792,40.0298881530762,1.99916428798025,16.1199998110533,0.000637279581503842,8.51713942365638E-5,0.25,-2.1649725412881E-6,5.59236728524475E-5,-2.12793644517885E-6,300.0089722,300.0089722,9454.947265625,9480.2880859375,56.9557069393137,20.5417833248498,27.085165,0,0,0,40,4449,300.78295,9467.61767578125,,,,,,,,,,,,,0,,,,0,,,,,,300.0089722,,,,
,22148067.505,300.0095215,13445.4448242187,4.17718282050876E-5,1.63960903143453E-6,1,0.999253354069792,40.0298881530762,1.99913878115245,16.1199998110533,0.000470210213762603,9.70576667587154E-5,0.25,1.33717349831291E-6,4.17696943677736E-5,1.36472997973164E-6,300.0095215,300.0095215,13438.4541015625,13452.435546875,57.0690430746022,20.5412053180284,27.464817,0,0,0,40,4449,300.7769,13445.4448242187,,,,,,,,,,,,,0,,,,0.00245,,,,,,300.0095215,,,,
,22148148.495,300.0119019,17495.4248046875,3.17069059279363E-5,1.95956475794741E-6,1,0.999253354069792,40.0298881530762,1.99918711585559,16.1199998110533,0.000361090772380887,4.96079390635572E-5,0.25,-1.11098110100993E-6,3.17066888699533E-5,-1.09001580181694E-6,300.0119019,300.0119019,17490.486328125,17500.36328125,56.7946914643522,20.5415819536617,27.085165,0,0,0,40,4449,300.76695,17495.4248046875,,,,,,,,,,,,,0,,,,0.0049,,,,,,300.0119019,,,,
,22148229.36,300.013916,21535.8408203125,1.65201782732388E-5,2.26156581278295E-6,1,0.999253354069792,40.0298881530762,1.99921102327741,16.1199998110533,0.000183792363780957,5.09437270461171E-5,0.25,1.63818366253043E-6,1.65186019229098E-5,1.64903238765722E-6,300.013916,300.013916,21533.37890625,21538.302734375,56.9861904515637,20.5408107883015,27.085165,0,0,0,40,4449,300.7575,21535.8408203125,,,,,,,,,,,,,0,,,,0.0049,,,,,,300.013916,,,,
,22148311.765,300.0111084,25656.501953125,3.56575668800256E-6,2.72203190418219E-6,1,0.999253354069792,40.0298881530762,1.99915280197647,16.1199998110533,3.77114159583652E-5,2.2294973737879E-5,0.25,1.35182130655556E-6,3.56475919321584E-6,1.35413126598633E-6,300.0111084,300.0111084,25646.759765625,25666.244140625,56.8345545188329,20.5405932119671,27.085165,0,0,0,40,4449,300.7494,25656.501953125,,,,,,,,,,,,,0,,,,0.00245,,,,,,300.0111084,,,,
,22148393.645,300.0136414,29747.302734375,-9.15496318986943E-6,2.88502720952025E-6,1,0.999253354069792,40.0298881530762,1.99915252630073,16.1199998110533,-0.000102948517829039,-2.18851117062236E-5,0.25,-3.47256645990326E-7,-9.15446076506467E-6,-3.5327568214863E-7,300.0136414,300.0136414,29739.91015625,29754.6953125,57.0870205305445,20.5409810895994,27.464817,0,0,0,40,4449,300.7386,29747.302734375,,,,,,,,,,,,,0,,,,-0.0049,,,,,,300.0136414,,,,
,22148473.3,300.013031,33727.712890625,-2.35153632244845E-5,3.61767999466332E-6,1,0.999253354069792,40.0298881530762,1.99919959808234,16.1199998110533,-0.000272334461003514,-1.06418903533358E-5,0.25,3.13402526810291E-6,-2.35167241511996E-5,3.11845747930553E-6,300.013031,300.013031,33722.49609375,33732.9296875,56.9150622563137,20.539196839517,27.844467,0,0,0,40,4449,300.72975,33727.712890625,,,,,,,,,,,,,0,,,,0,,,,,,300.013031,,,,
,22148551.495,300.0105896,37635.8125,-3.53298602465576E-5,3.58932420332791E-6,1,0.999253354069792,40.0298881530762,1.99907843358535,16.1199998110533,-0.000405530785056197,-3.67967054504667E-5,0.25,2.8701849180421E-6,-3.53306984090332E-5,2.84687089603522E-6,300.0105896,300.0105896,37630.8046875,37640.8203125,56.9541436822753,20.5415943637476,27.844467,0,0,0,40,4449,300.7289,37635.8125,,,,,,,,,,,,,0,,,,0.00245,,,,,,300.0105896,,,,
,22148631.665,300.0161133,41643.4453125,-4.5055453341849E-5,3.83149309459386E-6,1,0.999253354069792,40.0298881530762,1.99923703863598,16.1199998110533,-0.000521574511102171,-2.17048308449212E-5,0.25,5.88861184378349E-6,-4.50579773350636E-5,5.85883813043802E-6,300.0161133,300.0161133,41638.43359375,41648.45703125,56.9541436822753,20.5373282133961,27.085165,0,0,0,40,4449,300.71495,41643.4453125,,,,,,,,,,,,,0,,,,0.00245,,,,,,300.0161133,,,,
,22148713.245,300.0157776,45721.740234375,-5.82222510866996E-5,4.96372634309098E-6,1,0.999253354069792,40.0298881530762,1.99926386687812,16.1199998110533,-0.000671900703802204,-4.01977448699728E-5,0.25,6.53615792694212E-6,-5.82248075067512E-5,6.49774997876777E-6,300.0157776,300.0157776,45716.78125,45726.69921875,56.8603482599676,20.5401886186423,26.705515,0,0,0,40,4449,300.70385,45721.740234375,,,,,,,,,,,,,0,,,,-0.0049,,,,,,300.0157776,,,,
,22148794.41,300.0172119,49777.076171875,-7.58438167786147E-5,4.93912747374081E-6,1,0.999253354069792,40.0298881530762,1.9992464765994,16.1199998110533,-0.000861198832857258,-0.000133472167373868,0.25,1.34928298508884E-6,-7.58424434781768E-5,1.29950835766348E-6,300.0172119,300.0172119,49774.35546875,49779.796875,56.8322096332752,20.5386734215731,27.844467,0,0,0,40,4449,300.68985,49777.076171875,,,,,,,,,,,,,0,,,,-0.0049,,,,,,300.0172119,,,,
,22148874.235,300.0170593,53767.5078125,-9.23719477405645E-5,5.33045799705158E-6,1,0.999253354069792,40.0298881530762,1.99923277665437,16.1199998110533,-0.00106173691308497,-8.82748031299876E-5,0.25,8.20540742117703E-6,-9.23745787606047E-5,8.14464608835541E-6,300.0170593,300.0170593,53762.703125,53772.3125,56.8087607776983,20.5385505455118,27.464817,0,0,0,40,4449,300.6804,53767.5078125,,,,,,,,,,,,,0,,,,-0.0049,,,,,,300.0170593,,,,
,22148952.96,300.0123291,57700.521484375,-0.000104656752535025,6.34262336316255E-6,1,0.999253354069792,40.0298881530762,1.99916215418307,16.1199998110533,-0.00120058877876061,-0.000113351337650899,0.25,8.11811483637282E-6,-0.00010465897983724,8.0493727092969E-6,300.0123291,300.0123291,57690.36328125,57710.6796875,56.8298647477175,20.5375010576665,27.085165,0,0,0,40,4449,300.67365,57700.521484375,,,,,,,,,,,,,0,,,,0.00245,,,,,,300.0123291,,,,
,22149035.29,300.0152588,61818.685546875,-0.000120783175082872,6.21461249874932E-6,1,0.999253354069792,40.0298881530762,1.99916789563779,16.1199998110533,-0.00137410862022909,-0.000197086032348676,0.25,3.51465456790736E-6,-0.000120781905515168,3.43556943508262E-6,300.014801,300.0157166,61813.6953125,61823.67578125,56.922878541506,20.5381253126399,27.085165,0,0,0,40,4449,300.66515,61818.685546875,,,,,,,,,,,,,0,,,,-0.0049,,,,,,300.0152588,,,,
,22149115.205,300.023468,65812.03515625,-0.000132389135198838,5.91668820119159E-6,1,0.999253354069792,40.0298881530762,1.99913663771452,16.1199998110533,-0.00152466322801353,-0.000109004733768971,0.25,1.3306478897043E-5,-0.000132393885801779,1.32195912577798E-5,300.023468,300.023468,65806.9453125,65817.125,56.8454973181022,20.5385485045512,27.844467,0,0,0,40,4449,300.64645,65812.03515625,,,,,,,,,,,,,0,,,,-0.0049,,,,,,300.023468,,,,
,22149193.765,300.0186157,69737.98828125,-0.000148056459637795,7.36031947081405E-6,1,0.999253354069792,40.0298881530762,1.99914927461124,16.1199998110533,-0.00168892703553947,-0.000215296732735401,0.25,6.63063092057771E-6,-0.00014805641199397,6.53379767828576E-6,300.0186157,300.0186157,69730.0390625,69745.9375,56.8329912617945,20.5382687014606,27.464817,0,0,0,40,4449,300.6326,69737.98828125,,,,,,,,,,,,,0,,,,0,,,,,,300.0186157,,,,
,22149272.28,300.0145569,73663.4296875,-0.000163887815586206,7.10307066193317E-6,1,0.999253354069792,40.0298881530762,1.99916327858246,16.1199998110533,-0.00185944689310812,-0.000296538117411583,0.25,2.19635167493018E-6,-0.000163884437396196,2.08941903501211E-6,300.0145569,300.0145569,73658.2421875,73668.6171875,56.9291315696599,20.5373923023954,27.085165,0,0,0,40,4449,300.62365,73663.4296875,,,,,,,,,,,,,0,,,,0,,,,,,300.0145569,,,,
,22149352.875,300.0150146,77689.51953125,-0.000182188951357086,6.24522731253566E-6,1,0.999253354069792,40.0298881530762,1.99914856201361,16.1199998110533,-0.0020847602632791,-0.000227565649937446,0.25,1.14599374713852E-5,-0.000182191076677485,1.13409190907226E-5,300.0150146,300.0150146,77677.2109375,77701.828125,56.8189219484483,20.5377272618788,27.085165,0,0,0,40,4449,300.61825,77689.51953125,,,,,,,,,,,,,0,,,,0.00245,,,,,,300.0150146,,,,
,22149433.71,300.0155334,81733.6015625,-0.000191856208048052,8.38845820758655E-6,1,0.999253354069792,40.0298881530762,1.99914127051102,16.1199998110533,-0.00218380031529131,-0.000306441794368786,0.25,6.16637930644773E-6,-0.000191854605085641,6.04134308932944E-6,300.0155334,300.0155334,81726.0078125,81741.1953125,56.7610814380252,20.537851157341,27.085165,0,0,0,40,4449,300.6061,81733.6015625,,,,,,,,,,,,,0,,,,0.00245,,,,,,300.0155334,,,,
,22149513.435,300.0137634,85716.5703125,-0.000207707348421659,7.66757748243688E-6,1,0.999253354069792,40.0298881530762,1.99912956775421,16.1199998110533,-0.00236352449121789,-0.000335730607432741,0.25,6.32477023007456E-6,-0.000207705405472742,6.18954775931302E-6,300.0137634,300.0137634,85709.1796875,85723.9609375,56.679010443506,20.5369461209376,27.085165,0,0,0,40,4449,300.59335,85716.5703125,,,,,,,,,,,,,0,,,,-0.0049,,,,,,300.0137634,,,,
,22149589.6,300.0121765,89522.21875,-0.000218475538853244,7.9684949343792E-6,1,0.999253354069792,40.0298881530762,1.99907259666831,16.1199998110533,-0.00249187714429858,-0.000319142132296112,0.25,9.6549062265739E-6,-0.000218475465686353,9.5127273765218E-6,300.0121765,300.0121765,89517.1328125,89527.3046875,56.7821854080445,20.5378661281126,27.085165,0,0,0,40,4449,300.59125,89522.21875,,,,,,,,,,,,,0,,,,0,,,,,,300.0121765,,,,
,22149600.395,300.0128784,89999.421875,-0.000218877423519534,7.98349294971851E-6,1,0.999253354069792,40.0298881530762,1.99908480568966,16.1199998110533,-0.00248700398987686,-0.000374401670365094,0.25,4.84272906113549E-6,-0.000218874208772888,4.70044528938612E-6,300.0128784,300.0128784,89999.3984375,89999.4453125,56.7454488676406,20.5365893916517,27.844467,0,0,0,40,4417,300.5887,89999.421875,,,,,,,,,,,,,0,,,,0.0049,,,,,,300.0128784,,,,