File: data/doubleLayers/dl_1-25/ppms/KoelnPPMS/DD205_3_FCC_100OE.DAT
[Header]
; VSM Data File (default extension .dat)
; Copyright (c) 2003-2013, Quantum Design, Inc. All rights reserved.
TITLE,
FILEOPENTIME,22167863.83,09/14/2018,10:43 pm
BYAPP,VSM,2.0,2.0
INFO,PPMS VSM Option Release 1.4.10 Build 1,APPNAME
INFO,Quantum Design Linear Motor Servo Controller,MOTOR_MODULE_NAME
INFO,3101-100 M1,MOTOR_HW_VERSION
INFO,MMC1014,MOTOR_SERIAL_NUMBER
INFO,SRV No X-over 01.03.11,MOTOR_SOFTWARE_VERSION
INFO,Quantum Design VSM Detection Module,VSM_MODULE_NAME
INFO,3101-150 F0,VSM_HW_VERSION
INFO,VSM707,VSM_SERIAL_NUMBER
INFO,VSM No X-over 01.02.05 May 20 2008 13:51:47,VSM_SOFTWARE_VERSION
INFO,704,PREAMP_SERIAL_NUMBER
INFO,822,COIL_SERIAL_NUMBER
INFO,0,MOMENT_UNITS
INFO,CoFe2O4,SAMPLE_MATERIAL
INFO,Double Layer blue,SAMPLE_COMMENT
INFO,,SAMPLE_MASS
INFO,,SAMPLE_VOLUME
INFO,,SAMPLE_MOLECULAR_WEIGHT
INFO,,SAMPLE_SIZE
INFO,,SAMPLE_SHAPE
DATATYPE,COMMENT,1
DATATYPE,TIME,2
STARTUPAXIS,X,2
STARTUPAXIS,Y1,5
[Data]
Comment,Time Stamp (sec),Temperature (K),Magnetic Field (Oe),Moment (emu),M. Std. Err. (emu),Transport Action,Averaging Time (sec),Frequency (Hz),Peak Amplitude (mm),Center Position (mm),Coil Signal' (mV),Coil Signal" (mV),Range (mV),M. Quad. Signal (emu),M. Raw' (emu),M. Raw" (emu),Min. Temperature (K),Max. Temperature (K),Min. Field (Oe),Max. Field (Oe),Mass (grams),Motor Lag (deg),Pressure (Torr),VSM Status (code),Motor Status (code),Measure Status (code),Measure Count,PPMS Status (code),System Temp. (K),System Field (Oe),Sample Position (deg),Bridge 1 Resistance (ohms),Bridge 1 Excitation (에),Bridge 2 Resistance (ohms),Bridge 2 Excitation (에),Bridge 3 Resistance (ohms),Bridge 3 Excitation (에),Bridge 4 Resistance (ohms),Bridge 4 Excitation (에),Signal 1 Vin (V),Signal 2 Vin (V),Digital Inputs (code),Drive 1 Iout (mA),Drive 1 Ipower (W),Drive 2 Iout (mA),Drive 2 Ipower (W),Pressure (),Map 20 (),Map 21 (),Map 22 (),Map 23 (),Map 24 (),Map 25 (),Map 26 (),Map 27 (),Map 28 (),Map 29 ()
,22168337.805,349.9136963,99.5939254760742,1.35347928509067E-5,4.48748703227503E-7,1,0.999253354069792,40.0298881530762,1.99898749514137,15.6100001186132,0.000153300962556054,2.43436612090967E-5,0.25,-1.89066377545648E-7,1.35109428606877E-5,-1.8121753564702E-7,349.9136963,349.9136963,99.5939254760742,99.5939254760742,57.0362146767945,20.5428666168663,28.224119,0,0,0,40,4369,351.6563,99.5939254760742,,,,,,,,,,,,,0,,,,0,,,,,,349.9136963,,,,
,22168479.865,347.4337158,99.5939254760742,1.31068921730131E-5,4.65075619713324E-7,1,0.999253354069792,40.0298881530762,1.99901515880524,15.6100001186132,0.000149117565158025,1.98292683922788E-5,0.25,-5.14805697979069E-7,1.30850758418351E-5,-5.0653589205846E-7,347.4337158,347.4337158,99.5939254760742,99.5939254760742,57.0299616486406,20.5416718875217,28.224119,0,0,0,40,4374,345.759,99.5939254760742,,,,,,,,,,,,,0,,,,0,,,,,,347.4337158,,,,
,22168599.41,344.4839783,99.5939254760742,1.34982499440647E-5,5.35670365455375E-7,1,0.999253354069792,40.0298881530762,1.99915631606988,15.6100001186132,0.000152638225860087,2.59547168626256E-5,0.25,-4.0955189128475E-8,1.34768556600689E-5,-3.32030849774583E-8,344.4839783,344.4839783,99.5939254760742,99.5939254760742,57.004167907506,20.5393624229923,28.603769,0,0,0,40,4374,342.9781,99.5939254760742,,,,,,,,,,,,,0,,,,0,,,,,,344.4839783,,,,
,22168731.08,341.4915771,99.5939254760742,1.40714293763981E-5,3.57059038207842E-7,1,0.999253354069792,40.0298881530762,1.99925326739285,15.6100001186132,0.000160169873190705,2.11329800405079E-5,0.25,-5.6720225042975E-7,1.40508620929186E-5,-5.58255264320807E-7,341.4915771,341.4915771,99.5939254760742,99.5939254760742,57.1346998702176,20.5412181635048,28.603769,0,0,0,40,4374,339.34695,99.5939254760742,,,,,,,,,,,,,0,,,,-0.00245,,,,,,341.4915771,,,,
,22168858.335,338.49383545,99.5939254760742,1.37866673734038E-5,4.17610227922098E-7,1,0.999253354069792,40.0298881530762,1.999196164031,15.6100001186132,0.000156161048304322,2.52072846294732E-5,0.25,-1.57703877217972E-7,1.37677021927182E-5,-1.49459724596353E-7,338.4585266,338.5291443,99.5939254760742,99.5939254760742,56.8298647477175,20.5380479917648,28.603769,0,0,0,40,4374,336.0178,99.5939254760742,,,,,,,,,,,,,0,,,,0.0049,,,,,,338.49383545,,,,
,22168986.345,335.4316101,99.5939254760742,1.38399889377242E-5,4.33690337872688E-7,1,0.999253354069792,40.0298881530762,1.99922704799423,15.6100001186132,0.000157677244735148,2.01492906849789E-5,0.25,-6.14669709171995E-7,1.38226772491137E-5,-6.05739182916281E-7,335.4316101,335.4316101,99.5939254760742,99.5939254760742,56.912717370756,20.5367879074533,28.603769,0,0,0,40,4374,332.70975,99.5939254760742,,,,,,,,,,,,,0,,,,0,,,,,,335.4316101,,,,
,22169106.915,332.4861145,99.5939254760742,1.44650762768777E-5,5.20573609482089E-7,1,0.999253354069792,40.0298881530762,1.99923724244434,15.5499996617436,0.000165073499422421,1.95772232647075E-5,0.25,-7.737985867326E-7,1.44485364871367E-5,-7.6428555124789E-7,332.4861145,332.4861145,99.5939254760742,99.5939254760742,56.8908317722176,20.5354544755179,28.603769,0,0,0,40,4374,329.5913,99.5939254760742,,,,,,,,,,,,,0,,,,0,,,,,,332.4861145,,,,
,22169233.345,329.4441528,99.5939254760742,1.41905913690383E-5,3.77309526207037E-7,1,0.999253354069792,40.0298881530762,1.99948714231045,15.5499996617436,0.00015949156953505,3.35638215806504E-5,0.25,5.09952214636236E-7,1.41751043378476E-5,5.17942111665953E-7,329.4441528,329.4441528,99.5939254760742,99.5939254760742,57.0252718775253,20.5361371243296,28.983419,0,0,0,40,4374,326.346,99.5939254760742,,,,,,,,,,,,,0,,,,0,,,,,,329.4441528,,,,
,22169353.57,326.4497986,99.5939254760742,1.43948167108859E-5,3.69864600940111E-7,1,0.999253354069792,40.0298881530762,1.99920826699497,15.5499996617436,0.000164215376191234,1.99979516842246E-5,0.25,-7.24957418204546E-7,1.43813598654528E-5,-7.15506351424583E-7,326.4497986,326.4497986,99.5939254760742,99.5939254760742,56.8963031718522,20.5368800953387,28.603769,0,0,0,40,4374,323.31565,99.5939254760742,,,,,,,,,,,,,0,,,,-0.00245,,,,,,326.4497986,,,,
,22169475.705,323.4353943,99.5939254760742,1.50349422886581E-5,3.96301027547288E-7,1,0.999253354069792,40.0298881530762,1.99942017278648,15.5499996617436,0.000169330314438019,3.37261447336994E-5,0.25,3.77339688810355E-7,1.50217789161998E-5,3.8625676135909E-7,323.4353943,323.4353943,99.5939254760742,99.5939254760742,57.0424677049483,20.5365550717028,28.603769,0,0,0,40,4374,320.2421,99.5939254760742,,,,,,,,,,,,,0,,,,0.0049,,,,,,323.4353943,,,,
,22169596.97,320.4973145,99.5939254760742,1.46813815449684E-5,3.91794198485084E-7,1,0.999253354069792,40.0298881530762,1.99938498652197,15.5600002035499,0.000165661222716167,3.12118989247302E-5,0.25,2.1597060670675E-7,1.46701325719588E-5,2.24932828128808E-7,320.4973145,320.4973145,99.5939254760742,99.5939254760742,56.8157954343714,20.5326847783321,28.603769,0,0,0,40,4374,317.1785,99.5939254760742,,,,,,,,,,,,,0,,,,0,,,,,,320.4973145,,,,
,22169718.43,317.48995975,99.5939254760742,1.53790471130398E-5,4.69476015782382E-7,1,0.999253354069792,40.0298881530762,1.99929609834829,15.5600002035499,0.0001748607816297,2.50985233340633E-5,0.25,-4.45532326346162E-7,1.53693113341421E-5,-4.35572706906414E-7,317.4523926,317.5275269,99.5939254760742,99.5939254760742,56.9252234270637,20.5340164309372,28.603769,0,0,0,40,4374,314.09195,99.5939254760742,,,,,,,,,,,,,0,,,,-0.0049,,,,,,317.48995975,,,,
,22169840.97,314.4568176,99.5939254760742,1.53190726847363E-5,4.38381811346332E-7,1,0.999253354069792,40.0298881530762,1.99915607166484,15.5600002035499,0.000174076300706464,2.56344169616349E-5,0.25,-3.87978219985453E-7,1.53109819763632E-5,-3.78022576019479E-7,314.4568176,314.4568176,99.5939254760742,99.5939254760742,56.719655126506,20.5368312100459,28.603769,0,0,0,40,4374,311.0038,99.5939254760742,,,,,,,,,,,,,0,,,,0,,,,,,314.4568176,,,,
,22169963.9,311.4551239,99.5939254760742,1.5900803533047E-5,3.77343903499843E-7,1,0.999253354069792,40.0298881530762,1.99916453104157,15.5800003558397,0.00018032969668714,2.87868965824607E-5,0.25,-2.10511865005833E-7,1.58939731021757E-5,-2.00183940997851E-7,311.4169006,311.4933472,99.5939254760742,99.5939254760742,56.6868267286983,20.5353357638859,28.603769,0,0,0,40,4374,307.88965,99.5939254760742,,,,,,,,,,,,,0,,,,0,,,,,,311.4551239,,,,
,22170085.72,308.4335938,99.5939254760742,1.56016014367048E-5,3.82532019186016E-7,1,0.999253354069792,40.0298881530762,1.99909788159592,15.5899999663234,0.000177121659371172,2.72555018830526E-5,0.25,-2.9432249608361E-7,1.55966297443496E-5,-2.84060874196894E-7,308.4335938,308.4335938,99.5939254760742,99.5939254760742,56.8501870892175,20.5375800389663,28.983419,0,0,0,40,4374,304.7999,99.5939254760742,,,,,,,,,,,,,0,,,,0,,,,,,308.4335938,,,,
,22170208.55,305.4385986,99.5939254760742,1.56850300460209E-5,3.33455476665977E-7,1,0.999253354069792,40.0298881530762,1.99905599544688,15.5800003558397,0.000177943495996307,2.82158913242536E-5,0.25,-2.24245466135442E-7,1.56816558069093E-5,-2.13850672621806E-7,305.4385986,305.4385986,99.5939254760742,99.5939254760742,56.8181403199291,20.5347843834745,28.983419,0,0,0,40,4374,301.68675,99.5939254760742,,,,,,,,,,,,,0,,,,0,,,,,,305.4385986,,,,
,22170329.915,302.4521179,99.5939254760742,1.5506504699121E-5,3.58272937335133E-7,1,0.999253354069792,40.0298881530762,1.99906118172562,15.5800003558397,0.000176219905751914,2.62668457566568E-5,0.25,-3.65919519374657E-7,1.5504915287607E-5,-3.55523206698462E-7,302.4521179,302.4521179,99.5939254760742,99.5939254760742,56.699332785006,20.5335155739196,28.983419,0,0,0,40,4374,298.6054,99.5939254760742,,,,,,,,,,,,,0,,,,0.0049,,,,,,302.4521179,,,,
,22170451.025,299.48205565,99.5939254760742,1.62861420612935E-5,4.88078765122901E-7,1,0.999253354069792,40.0298881530762,1.999025798181,15.599999576807,0.00018501653418824,2.80509636404303E-5,0.25,-3.43721948625627E-7,1.62861729120418E-5,-3.32709365630079E-7,299.4515991,299.5125122,99.5939254760742,99.5939254760742,56.8126689202945,20.536243302539,28.983419,0,0,0,40,4374,295.55295,99.5939254760742,,,,,,,,,,,,,0,,,,0,,,,,,299.48205565,,,,
,22170574.075,296.4452209,99.5939254760742,1.69258296423264E-5,3.2569813076094E-7,1,0.999253354069792,40.0298881530762,1.99897129949841,15.599999576807,0.000193186217900389,2.40379432691618E-5,0.25,-8.09422821880903E-7,1.69280093143983E-5,-7.97913683221034E-7,296.4452209,296.4452209,99.5939254760742,99.5939254760742,56.6876083572175,20.5368850218358,28.983419,0,0,0,40,4374,292.4452,99.5939254760742,,,,,,,,,,,,,0,,,,0,,,,,,296.4452209,,,,
,22170694.635,293.4914551,99.5939254760742,1.60482681396735E-5,4.26412470099744E-7,1,0.999253354069792,40.0298881530762,1.99873339474693,15.599999576807,0.000181470403792306,3.25911891431007E-5,0.25,9.81222720973539E-8,1.60514353640779E-5,1.09267429844565E-7,293.4914551,293.4914551,99.5939254760742,99.5939254760742,57.115940785756,20.537100719389,28.224119,0,0,0,40,4374,289.3978,99.5939254760742,,,,,,,,,,,,,0,,,,-0.0049,,,,,,293.4914551,,,,
,22170797.725,290.9447632,99.5939254760742,1.66451250302775E-5,4.57106126138579E-7,1,0.999253354069792,40.0298881530762,1.99853518387819,15.6100001186132,0.000188814964192041,3.03633803470963E-5,0.25,-2.02229931430889E-7,1.66501384309927E-5,-1.90623740810534E-7,290.9447632,290.9447632,99.5939254760742,99.5939254760742,56.8634747740445,20.5386492388472,28.983419,0,0,0,40,4374,286.79345,99.5939254760742,,,,,,,,,,,,,0,,,,0.0049,,,,,,290.9447632,,,,
,22170919.835,287.9078979,99.5939254760742,1.70354723422796E-5,3.17417408410685E-7,1,0.999253354069792,40.0298881530762,1.99875477615438,15.6100001186132,0.000192244756773707,3.70796082070386E-5,0.25,3.22590300644692E-7,1.7042080674144E-5,3.34815257496119E-7,287.9078979,287.9078979,99.5939254760742,99.5939254760742,56.8791073444291,20.5377724475416,28.983419,0,0,0,40,4374,283.70825,99.5939254760742,,,,,,,,,,,,,0,,,,0,,,,,,287.9078979,,,,
,22171039.605,284.975708,99.5939254760742,1.67197249660907E-5,4.16554976246845E-7,1,0.999253354069792,40.0298881530762,1.99895138384094,15.6100001186132,0.000189994544088894,2.9040193786153E-5,0.25,-3.33412814573141E-7,1.67284304335951E-5,-3.21557124905158E-7,284.975708,284.975708,99.5939254760742,99.5939254760742,57.0182372208522,20.5334811433642,28.603769,0,0,0,40,4374,280.7044,99.5939254760742,,,,,,,,,,,,,0,,,,-0.00245,,,,,,284.975708,,,,
,22171159.445,281.953125,99.5939254760742,1.69362719588178E-5,3.40459735884295E-7,1,0.999253354069792,40.0298881530762,1.99876330683697,15.6199997290969,0.000193595723535666,2.28577307486282E-5,0.25,-9.17084011447354E-7,1.69473487146637E-5,-9.05308475062022E-7,281.953125,281.953125,99.5939254760742,99.5939254760742,56.8298647477175,20.5314500538621,28.983419,0,0,0,40,4374,277.70155,99.5939254760742,,,,,,,,,,,,,0,,,,0,,,,,,281.953125,,,,
,22171261.315,279.4412537,99.5939254760742,1.68594965314213E-5,3.82545742526618E-7,1,0.999253354069792,40.0298881530762,1.99844028859174,15.650000423193,0.000191303095319482,3.08450935615487E-5,0.25,-1.98423990582568E-7,1.68715202845798E-5,-1.86143091369874E-7,279.4412537,279.4412537,99.5939254760742,99.5939254760742,56.7290346687368,20.5384696045069,28.983419,0,0,0,40,4374,275.1483,99.5939254760742,,,,,,,,,,,,,0,,,,0,,,,,,279.4412537,,,,
,22171381.195,276.4588623,99.5939254760742,1.70866396498743E-5,3.98023153088697E-7,1,0.999253354069792,40.0298881530762,1.99839114089672,15.6399998813868,0.00019412933079911,2.99208016873382E-5,0.25,-3.19805882259414E-7,1.71007399775558E-5,-3.07309956578487E-7,276.4588623,276.4588623,99.5939254760742,99.5939254760742,56.7814037795252,20.535497361239,28.983419,0,0,0,40,4374,272.149,99.5939254760742,,,,,,,,,,,,,0,,,,0,,,,,,276.4588623,,,,
,22171501.68,273.4653015,99.5939254760742,1.73002590318831E-5,3.09583472190784E-7,1,0.999253354069792,40.0298881530762,1.99847047441996,15.6399998813868,0.000197005026512727,2.78756367406959E-5,0.25,-5.37960035887297E-7,1.73165534659275E-5,-5.25363775003518E-7,273.4653015,273.4653015,99.5939254760742,99.5939254760742,56.770460980256,20.5360449940553,28.983419,0,0,0,40,4374,269.1172,99.5939254760742,,,,,,,,,,,,,0,,,,-0.00245,,,,,,273.4653015,,,,
touchdown = 9.84000042080879 mm,22171634.765,270.186554,99.5939254760742,1.75577449624459E-5,4.21413392543788E-7,1,0.999253354069792,40.0298881530762,1.99880787820859,15.6800001859665,0.000199671256656476,3.01531982848473E-5,0.25,-3.82450957036981E-7,1.75762198622601E-5,-3.69361689761065E-7,270.186554,270.186554,99.5939254760742,99.5939254760742,56.679010443506,20.530506332122,28.603769,0,0,0,40,4374,265.7952,99.5939254760742,,,,,,,,,,,,,0,,,,0,,,,,,270.186554,,,,
,22171743.065,267.4696655,99.5939254760742,1.76401877758316E-5,4.5151148751424E-7,1,0.999253354069792,40.0298881530762,1.99882750056743,15.6699996441603,0.000200024516336804,3.37913438923462E-5,0.25,-7.61057196009709E-8,1.76602245872341E-5,-6.24748372421048E-8,267.4385681,267.5007629,99.5939254760742,99.5939254760742,57.0182372208522,20.5334793449474,28.983419,0,0,0,40,4374,263.0809,99.5939254760742,,,,,,,,,,,,,0,,,,0,,,,,,267.4696655,,,,
,22171863.86,264.4399414,99.5939254760742,1.80211844622422E-5,3.99727399845832E-7,1,0.999253354069792,40.0298881530762,1.99870084505088,15.6699996441603,0.000203157866645371,4.14236859523437E-5,0.25,5.31071922842504E-7,1.80431216131852E-5,5.45940509828445E-7,264.4399414,264.4399414,99.5939254760742,99.5939254760742,57.0205821064099,20.53316794099,28.983419,0,0,0,40,4374,260.0554,99.5939254760742,,,,,,,,,,,,,0,,,,0,,,,,,264.4399414,,,,
,22171982.65,261.4668579,99.5939254760742,1.75813454779089E-5,3.78294046089845E-7,1,0.999253354069792,40.0298881530762,1.99883496501119,15.6699996441603,0.000200215259073798,2.89878615555262E-5,0.25,-4.9077802622778E-7,1.76054089162435E-5,-4.77383867482545E-7,261.4668579,261.4668579,99.5939254760742,99.5939254760742,56.7376325824483,20.5272399715148,28.983419,0,0,0,40,4374,257.0999,99.5939254760742,,,,,,,,,,,,,0,,,,0,,,,,,261.4668579,,,,
,22172104.2,258.4506836,99.5939254760742,1.8111156256975E-5,3.81735247420529E-7,1,0.999253354069792,40.0298881530762,1.99887626959425,15.70999994874,0.000206048828332206,3.11689816994109E-5,0.25,-3.90745802490094E-7,1.81377983410232E-5,-3.76627570652656E-7,258.4506836,258.4506836,99.5939254760742,99.5939254760742,56.9385111118906,20.52982692273,28.603769,0,0,0,40,4374,254.07335,99.5939254760742,,,,,,,,,,,,,0,,,,0.00245,,,,,,258.4506836,,,,
,22172222.72,255.47826385,99.5939254760742,1.78194008152827E-5,3.99525745792433E-7,1,0.999253354069792,40.0298881530762,1.99856706400165,15.6999994069338,0.00020241456524967,3.24326328808714E-5,0.25,-2.2874761522147E-7,1.78473680312575E-5,-2.14449375662138E-7,255.4486694,255.5078583,99.5939254760742,99.5939254760742,56.9947883652753,20.5374747363399,28.603769,0,0,0,40,4374,251.11215,99.5939254760742,,,,,,,,,,,,,0,,,,0.00245,,,,,,255.47826385,,,,
,22172341.32,252.4988403,99.5939254760742,1.80975069130884E-5,3.67282811725435E-7,1,0.999253354069792,40.0298881530762,1.99876949135136,15.6999994069338,0.000205063648053294,3.61254581532208E-5,0.25,4.79849855089349E-8,1.81275866056133E-5,6.31631976065507E-8,252.4988403,252.4988403,99.5939254760742,99.5939254760742,56.6516534453329,20.5352260833296,28.983419,0,0,0,40,4374,248.1393,99.5939254760742,,,,,,,,,,,,,0,,,,0,,,,,,252.4988403,,,,
touchdown = 9.90999955683947 mm,22172471.085,249.2460556,99.5939254760742,1.7800045126321E-5,3.32908428957812E-7,1,0.999253354069792,40.0298881530762,1.99893080291368,15.7399997115135,0.000203339326460435,2.62700108630457E-5,0.25,-7.70478786576583E-7,1.78323649550674E-5,-7.56762881210861E-7,249.2177277,249.2743835,99.5939254760742,99.5939254760742,56.7438856106022,20.5357052683819,28.983419,0,0,0,40,4374,244.90405,99.5939254760742,,,,,,,,,,,,,0,,,,0.0049,,,,,,249.2460556,,,,
,22172582.98,246.4453888,99.5939254760742,1.83275568186334E-5,3.65146627739573E-7,1,0.999253354069792,40.0298881530762,1.99868743959881,15.7399997115135,0.00020839560232791,3.26178228748766E-5,0.25,-3.02287340403417E-7,1.83622267075024E-5,-2.87105156553414E-7,246.4453888,246.4453888,99.5939254760742,99.5939254760742,56.485948199256,20.5339833245656,28.603769,0,0,0,40,4374,242.1113,99.5939254760742,,,,,,,,,,,,,0,,,,0,,,,,,246.4453888,,,,
,22172702.205,243.4695435,99.5939254760742,1.82905565154131E-5,3.83410367163476E-7,1,0.999253354069792,40.0298881530762,1.99860078738707,15.7399997115135,0.000207454864485536,3.56272024473344E-5,0.25,-3.08794888742124E-8,1.83268319313014E-5,-1.49875898631565E-8,243.4695435,243.4695435,99.5939254760742,99.5939254760742,56.648526931256,20.5351163296238,28.603769,0,0,0,40,4374,239.1461,99.5939254760742,,,,,,,,,,,,,0,,,,0,,,,,,243.4695435,,,,
,22172821.675,240.46315,99.5939254760742,1.83323991959658E-5,4.74491864849278E-7,1,0.999253354069792,40.0298881530762,1.99866509829062,15.7399997115135,0.000208194896125939,3.43459453449855E-5,0.25,-1.51787887057998E-7,1.83707900389843E-5,-1.35870808679408E-7,240.46315,240.46315,99.5939254760742,99.5939254760742,56.8712910592368,20.5370568748899,28.603769,0,0,0,40,4374,236.15985,99.5939254760742,,,,,,,,,,,,,0,,,,0,,,,,,240.46315,,,,
,22172941.475,237.4600067,99.5939254760742,1.80486564020235E-5,3.44030956759868E-7,1,0.999253354069792,40.0298881530762,1.99897073372284,15.7999992370605,0.000205029649776067,3.37893072374858E-5,0.25,-1.52638330572328E-7,1.80883437289189E-5,-1.36742288097181E-7,237.4600067,237.4600067,99.5939254760742,99.5939254760742,56.8603482599676,20.536354732545,28.983419,0,0,0,40,4374,233.1694,99.5939254760742,,,,,,,,,,,,,0,,,,0.00245,,,,,,237.4600067,,,,
,22173060.32,234.4991608,99.5939254760742,1.81586574389036E-5,4.23499165818947E-7,1,0.999253354069792,40.0298881530762,1.99924080313234,15.7999992370605,0.000207025952782179,2.9974797890514E-5,0.25,-5.08870454130016E-7,1.82007758670541E-5,-4.93453544056231E-7,234.4991608,234.4991608,99.5939254760742,99.5939254760742,56.882233858506,20.5352301916282,28.603769,0,0,0,40,4374,230.2052,99.5939254760742,,,,,,,,,,,,,0,,,,-0.0049,,,,,,234.4991608,,,,
,22173180.6,231.4895325,99.5939254760742,1.82773022090573E-5,2.8996176523447E-7,1,0.999253354069792,40.0298881530762,1.99887676524437,15.7999992370605,0.000208170863067068,3.12819304571034E-5,0.25,-4.143228495588E-7,1.83215095491624E-5,-3.98354372136512E-7,231.4895325,231.4895325,99.5939254760742,99.5939254760742,56.557076394506,20.5368693182242,28.603769,0,0,0,40,4374,227.18595,99.5939254760742,,,,,,,,,,,,,0,,,,-0.0049,,,,,,231.4895325,,,,
touchdown = 9.99999977648258 mm,22173307.125,228.3415833,99.5939254760742,1.83105572040457E-5,3.04973253437146E-7,1,0.999253354069792,40.0298881530762,1.99897982493756,15.8300008624792,0.000208705231367702,3.06362138573476E-5,0.25,-4.77725241761771E-7,1.83568885434723E-5,-4.61637096308264E-7,228.3415833,228.3415833,99.5939254760742,99.5939254760742,56.8189219484483,20.5345860174979,28.603769,0,0,0,40,4374,224.01865,99.5939254760742,,,,,,,,,,,,,0,,,,0,,,,,,228.3415833,,,,
,22173419.485,225.4678955,99.5939254760742,1.82905726014765E-5,3.34716495744053E-7,1,0.999253354069792,40.0298881530762,1.99857600048268,15.8300008624792,0.000207546334702038,3.58511037137023E-5,0.25,-1.46260119931686E-8,1.83382122403622E-5,2.86844349204065E-9,225.4678955,225.4678955,99.5939254760742,99.5939254760742,57.1432977839291,20.5401359621601,28.983419,0,0,0,40,4374,221.22395,99.5939254760742,,,,,,,,,,,,,0,,,,-0.00245,,,,,,225.4678955,,,,
,22173540.315,222.4473724,99.5939254760742,1.86970536691419E-5,3.9485328009604E-7,1,0.999253354069792,40.0298881530762,1.99855836651109,15.8300008624792,0.000213174114910737,3.09164277391545E-5,0.25,-5.20673964834124E-7,1.87481629379008E-5,-5.03858878509159E-7,222.4473724,222.4473724,99.5939254760742,99.5939254760742,56.5609845371021,20.5399458241971,28.224119,0,0,0,40,4374,218.2197,99.5939254760742,,,,,,,,,,,,,0,,,,-0.0049,,,,,,222.4473724,,,,
,22173658.385,219.4745789,99.5939254760742,1.85129352036497E-5,2.91706994388845E-7,1,0.999253354069792,40.0298881530762,1.99842800582872,15.8300008624792,0.000210215321517874,3.56113204458942E-5,0.25,-7.53655262677646E-8,1.85649713512341E-5,-5.72285476060922E-8,219.4745789,219.4745789,99.5939254760742,99.5939254760742,56.8204852054868,20.5418352733356,28.983419,0,0,0,40,4374,215.2703,99.5939254760742,,,,,,,,,,,,,0,,,,0,,,,,,219.4745789,,,,
,22173780.085,216.44391635,99.5939254760742,1.850093276281E-5,3.56105444298461E-7,1,0.999253354069792,40.0298881530762,1.99867000107073,15.8699993044138,0.000209862401063507,3.7106358133077E-5,0.25,5.744369935875E-8,1.85546832295197E-5,7.62712027891706E-8,216.416626,216.4712067,99.5939254760742,99.5939254760742,56.7493570102368,20.5438212578199,28.603769,0,0,0,40,4374,212.2316,99.5939254760742,,,,,,,,,,,,,0,,,,-0.0049,,,,,,216.44391635,,,,
,22173899.96,213.4342804,99.5939254760742,1.86259859186972E-5,3.87136823630614E-7,1,0.999253354069792,40.0298881530762,1.99852380597282,15.8699993044138,0.000212507967256366,3.03280069291661E-5,0.25,-5.61919681921673E-7,1.86826028376143E-5,-5.44490754893324E-7,213.4342804,213.4342804,99.5939254760742,99.5939254760742,56.7134020983521,20.546183974465,28.603769,0,0,0,40,4374,209.23775,99.5939254760742,,,,,,,,,,,,,0,,,,-0.0049,,,,,,213.4342804,,,,
,22174019.275,210.4619904,99.5939254760742,1.88792599389748E-5,3.51837028825904E-7,1,0.999253354069792,40.0298881530762,1.99817511103034,15.8699993044138,0.000215155639280376,3.20476072533156E-5,0.25,-4.54539444399151E-7,1.89383934748369E-5,-4.36223957569572E-7,210.4619904,210.4619904,99.5939254760742,99.5939254760742,56.7454488676406,20.5468267690184,28.983419,0,0,0,40,4374,206.2605,99.5939254760742,,,,,,,,,,,,,0,,,,0,,,,,,210.4619904,,,,
touchdown = 10.0800003856421 mm,22174140.13,207.4160156,99.5939254760742,1.81964485753417E-5,3.19173170956282E-7,1,0.999253354069792,40.0298881530762,1.99823810111156,15.9099996089935,0.000206862093836753,3.39960100725006E-5,0.25,-1.65027584213983E-7,1.82549817696217E-5,-1.46189642116004E-7,207.4160156,207.4160156,99.5939254760742,99.5939254760742,56.7001144135252,20.5477595971958,28.224119,0,0,0,40,4374,203.2457,99.5939254760742,,,,,,,,,,,,,0,,,,0,,,,,,207.4160156,,,,
,22174258.565,204.442627,99.5939254760742,1.82744474186543E-5,3.46147251520453E-7,1,0.999253354069792,40.0298881530762,1.99829208932103,15.9099996089935,0.000208184620947625,3.17833383667658E-5,0.25,-3.74218227331313E-7,1.83352311477934E-5,-3.5564297467662E-7,204.442627,204.442627,99.5939254760742,99.5939254760742,56.8220484625252,20.551470268234,28.224119,0,0,0,40,4374,200.28795,99.5939254760742,,,,,,,,,,,,,0,,,,-0.00245,,,,,,204.442627,,,,
,22174376.595,201.4965515,99.5939254760742,1.85292594132907E-5,3.65353284275582E-7,1,0.999253354069792,40.0298881530762,1.99832062175357,15.9099996089935,0.000211666756299936,2.90276050725298E-5,0.25,-6.61891144506719E-7,1.85929740090697E-5,-6.43673659308124E-7,201.4965515,201.4965515,99.5939254760742,99.5939254760742,56.7728058658137,20.5494753216023,28.224119,0,0,0,40,4374,197.3432,99.5939254760742,,,,,,,,,,,,,0,,,,0,,,,,,201.4965515,,,,
,22174496.36,198.4764557,99.5939254760742,1.85018040466733E-5,3.59993989169765E-7,1,0.999253354069792,40.0298881530762,1.99839319643344,15.9099996089935,0.000210638438590545,3.32625653880496E-5,0.25,-2.84873140909255E-7,1.85668053085883E-5,-2.65034664959252E-7,198.4764557,198.4764557,99.5939254760742,99.5939254760742,56.8243933480829,20.5476550328856,28.603769,0,0,0,40,4374,194.3771,99.5939254760742,,,,,,,,,,,,,0,,,,0,,,,,,198.4764557,,,,
,22174596.03,195.9902496,99.5939254760742,1.82108022502914E-5,3.77368789299619E-7,1,0.999253354069792,40.0298881530762,1.99839115544461,15.9600004553795,0.000206941020144999,3.50475517714266E-5,0.25,-7.76885886370556E-8,1.82759914796338E-5,-5.71180387831474E-8,195.9902496,195.9902496,99.5939254760742,99.5939254760742,56.9213152844676,20.5470801835282,28.224119,0,0,0,40,4374,191.883,99.5939254760742,,,,,,,,,,,,,0,,,,0,,,,,,195.9902496,,,,
,22174715.71,192.9884644,99.5939254760742,1.79320550216723E-5,3.81102065591418E-7,1,0.999253354069792,40.0298881530762,1.99833836546045,15.9600004553795,0.00020464891116343,2.95564491505505E-5,0.25,-5.13427939617833E-7,1.79984522245387E-5,-4.94363536380085E-7,192.9884644,192.9884644,99.5939254760742,99.5939254760742,56.9549253107945,20.5487097053872,28.603769,0,0,0,40,4374,188.8948,99.5939254760742,,,,,,,,,,,,,0,,,,0,,,,,,192.9884644,,,,
,22174836.555,189.9428101,99.5939254760742,1.82483380827329E-5,3.27694006039015E-7,1,0.999253354069792,40.0298881530762,1.99817054850311,15.9600004553795,0.000208301502468073,2.98487212744958E-5,0.25,-5.43140304263599E-7,1.83176743763317E-5,-5.23415878572171E-7,189.9428101,189.9428101,99.5939254760742,99.5939254760742,56.8494054606983,20.5520576965275,27.844467,0,0,0,40,4374,185.8711,99.5939254760742,,,,,,,,,,,,,0,,,,-0.00245,,,,,,189.9428101,,,,
,22174955.27,187.0061646,99.5939254760742,,,2,,,,16.0299998262525,,,,,,,187.0061646,187.0061646,99.5939254760742,99.5939254760742,,,27.464817,,,,-99999999,4374,182.9047,99.5939254760742,,,,,,,,,,,,,,,,,,,,,,,187.0061646,,,,
,22175056.35,184.4445953,99.5939254760742,1.85344049676916E-5,3.49250399020245E-7,1,0.999253354069792,40.0298881530762,1.99836095374643,16.0199999809265,0.00021148645072899,3.11039611565229E-5,0.25,-4.83916117350614E-7,1.86078919333929E-5,-4.62822660813944E-7,184.4445953,184.4445953,99.5939254760742,99.5939254760742,56.9643048530253,20.5536210109644,27.844467,0,0,0,40,4374,180.3874,99.5939254760742,,,,,,,,,,,,,0,,,,-0.00245,,,,,,184.4445953,,,,
,22175174.78,181.473877,99.5939254760742,1.80949979835486E-5,3.26391275043103E-7,1,0.999253354069792,40.0298881530762,1.99766438762755,16.0199999809265,0.000205872563416686,3.35217845848895E-5,0.25,-1.9444215035209E-7,1.81680220137971E-5,-1.72277372815001E-7,181.473877,181.473877,99.5939254760742,99.5939254760742,56.9471090256022,20.5535697437533,27.844467,0,0,0,40,4374,177.4469,99.5939254760742,,,,,,,,,,,,,0,,,,0,,,,,,181.473877,,,,
,22175294.255,178.4779053,99.5939254760742,1.8012067764588E-5,3.70212958636545E-7,1,0.999253354069792,40.0298881530762,1.99734336278105,16.0199999809265,0.000205495060025807,3.00354363270234E-5,0.25,-4.87375715997386E-7,1.80867474479405E-5,-4.6601381640056E-7,178.4779053,178.4779053,99.5939254760742,99.5939254760742,56.9455457685637,20.5546067633778,27.844467,0,0,0,40,4374,174.47,99.5939254760742,,,,,,,,,,,,,0,,,,-0.00245,,,,,,178.4779053,,,,
,22175413.89,175.4832306,99.5939254760742,1.82556234459989E-5,3.19380951635009E-7,1,0.999253354069792,40.0298881530762,1.99774376106347,16.0700008273125,0.000208014272152022,3.22763900515498E-5,0.25,-3.33737834594063E-7,1.83327157579228E-5,-3.10892384994872E-7,175.4832306,175.4832306,99.5939254760742,99.5939254760742,57.0502839901407,20.5567290896295,27.844467,0,0,0,40,4374,171.45405,99.5939254760742,,,,,,,,,,,,,0,,,,-0.0049,,,,,,175.4832306,,,,
,22175534.055,172.4666748,99.5939254760742,1.81469571324717E-5,3.50527602706236E-7,1,0.999253354069792,40.0298881530762,1.99759977464991,16.0700008273125,0.0002072379997142,2.9451742707417E-5,0.25,-5.64147035017783E-7,1.82254980054882E-5,-5.41880419038599E-7,172.4666748,172.4666748,99.5939254760742,99.5939254760742,57.1206305568714,20.5588621348734,27.464817,0,0,0,40,4374,168.48515,99.5939254760742,,,,,,,,,,,,,0,,,,0,,,,,,172.4666748,,,,
,22175653.37,169.43090055,99.5939254760742,1.85340226755749E-5,3.42234085849607E-7,1,0.999253354069792,40.0298881530762,1.99740266224514,16.0700008273125,0.000211210701191836,3.26432609377473E-5,0.25,-3.5110171767273E-7,1.86155445592885E-5,-3.26804117153801E-7,169.3943481,169.467453,99.5939254760742,99.5939254760742,57.0151107067753,20.5588700171595,27.464817,0,0,0,40,4374,165.53625,99.5939254760742,,,,,,,,,,,,,0,,,,0,,,,,,169.43090055,,,,
,22175782.91,166.1963348,99.5939254760742,,,2,,,,16.1499998086691,,,,,,,166.1963348,166.1963348,99.5939254760742,99.5939254760742,,,27.464817,,,,-99999999,4374,162.3235,99.5939254760742,,,,,,,,,,,,,,,,,,,,,,,166.1963348,,,,
,22175891.405,163.3959656,99.5939254760742,1.81898073375044E-5,2.89816602009342E-7,1,0.999253354069792,40.0298881530762,1.99733029835417,16.1400008946657,0.000207944969498668,2.84264108106436E-5,0.25,-6.6411173374794E-7,1.82733473880298E-5,-6.40449814002096E-7,163.3959656,163.3959656,99.5939254760742,99.5939254760742,56.6938613853714,20.5616609989566,27.844467,0,0,0,40,4374,159.63205,99.5939254760742,,,,,,,,,,,,,0,,,,-0.00245,,,,,,163.3959656,,,,
,22176008.03,160.4914322,99.5939254760742,1.82165087119663E-5,3.35110594774773E-7,1,0.999253354069792,40.0298881530762,1.99704964014142,16.1400008946657,0.000207670894249744,3.17278485546391E-5,0.25,-3.78679686990498E-7,1.83011857006516E-5,-3.53006308117382E-7,160.4549713,160.5278931,99.5939254760742,99.5939254760742,56.7790588939676,20.5636732811104,26.705515,0,0,0,40,4374,156.7325,99.5939254760742,,,,,,,,,,,,,0,,,,-0.00245,,,,,,160.4914322,,,,
,22176130.225,157.4511719,99.5939254760742,1.82741106602411E-5,2.84357065407009E-7,1,0.999253354069792,40.0298881530762,1.99699312716203,16.1400008946657,0.000208596114479617,3.03517425848747E-5,0.25,-5.10783673605995E-7,1.83607320414535E-5,-4.84884407857816E-7,157.4511719,157.4511719,99.5939254760742,99.5939254760742,56.9267866841022,20.5600715217383,26.705515,0,0,0,40,4374,153.6795,99.5939254760742,,,,,,,,,,,,,0,,,,0,,,,,,157.4511719,,,,
,22176248.055,154.4959869,99.5939254760742,1.8119330893618E-5,3.49923373582842E-7,1,0.999253354069792,40.0298881530762,1.9972004689002,16.2000004202127,0.000206807254328433,3.04354388689568E-5,0.25,-4.77720767073545E-7,1.82065687827408E-5,-4.51145497337211E-7,154.4959869,154.4959869,99.5939254760742,99.5939254760742,56.7102755842752,20.5552947192063,27.085165,0,0,0,40,4374,150.75185,99.5939254760742,,,,,,,,,,,,,0,,,,-0.0049,,,,,,154.4959869,,,,
,22176366.075,151.4959564,99.5939254760742,1.81381949427321E-5,3.18879146472437E-7,1,0.999253354069792,40.0298881530762,1.99714390136335,16.2000004202127,0.000206980618164747,3.07675356555247E-5,0.25,-4.52755397602907E-7,1.82268663772531E-5,-4.2521321992974E-7,151.4959564,151.4959564,99.5939254760742,99.5939254760742,56.9267866841022,20.5589732546545,27.085165,0,0,0,40,4374,147.80515,99.5939254760742,,,,,,,,,,,,,0,,,,0,,,,,,151.4959564,,,,
,22176486,148.4750519,99.5939254760742,1.82360885104529E-5,2.92968307819395E-7,1,0.999253354069792,40.0298881530762,1.99728958968899,16.2000004202127,0.000208566305998861,2.8421733177176E-5,0.25,-6.77552449678073E-7,1.83269766521834E-5,-6.50069637819813E-7,148.4750519,148.4750519,99.5939254760742,99.5939254760742,57.0612267894099,20.5643507867678,26.325863,0,0,0,40,4374,144.8286,99.5939254760742,,,,,,,,,,,,,0,,,,-0.0049,,,,,,148.4750519,,,,
,22176611.47,145.3374329,99.5939254760742,,,2,,,,16.2699997910857,,,,,,,145.3374329,145.3374329,99.5939254760742,99.5939254760742,,,26.325863,,,,-99999999,4374,141.7027,99.5939254760742,,,,,,,,,,,,,,,,,,,,,,,145.3374329,,,,
,22176724.57,142.499115,99.5939254760742,1.7915040912455E-5,3.43684736408098E-7,1,0.999253354069792,40.0298881530762,1.99747354948505,16.2599999457598,0.000204127823466242,3.25928828833249E-5,0.25,-2.57146901070246E-7,1.80061404857215E-5,-2.26186372046156E-7,142.499115,142.499115,99.5939254760742,99.5939254760742,56.9244417985445,20.5621976809173,27.085165,0,0,0,40,4374,138.88155,99.5939254760742,,,,,,,,,,,,,0,,,,0,,,,,,142.499115,,,,
,22176846.3,139.4672089,99.5939254760742,1.82465594194161E-5,3.29271754951404E-7,1,0.999253354069792,40.0298881530762,1.99743450758969,16.2599999457598,0.000207751315022394,3.41368257296124E-5,0.25,-1.80405127676923E-7,1.83404132024244E-5,-1.47331146297905E-7,139.4672089,139.4672089,99.5939254760742,99.5939254760742,56.6422739031022,20.5582188142338,26.705515,0,0,0,40,4374,135.84615,99.5939254760742,,,,,,,,,,,,,0,,,,0,,,,,,139.4672089,,,,
,22176965.09,136.4551544,99.5939254760742,1.79545173826014E-5,2.92085290564345E-7,1,0.999253354069792,40.0298881530762,1.99763737562708,16.2599999457598,0.000203911859777221,3.67301473081994E-5,0.25,9.70375058292514E-8,1.80474812140726E-5,1.32164799743627E-7,136.4551544,136.4551544,99.5939254760742,99.5939254760742,57.1339182416984,20.5536849619256,26.705515,0,0,0,40,4374,132.8915,99.5939254760742,,,,,,,,,,,,,0,,,,0,,,,,,136.4551544,,,,
,22177082.475,133.499939,99.5939254760742,1.80473513835147E-5,3.34775306532872E-7,1,0.999253354069792,40.0298881530762,1.99758133643666,16.330000013113,0.000205955964978589,3.12898922281891E-5,0.25,-3.99054115730291E-7,1.81428387880232E-5,-3.65105896633877E-7,133.499939,133.499939,99.5939254760742,99.5939254760742,56.9650864815445,20.5533035141164,26.325863,0,0,0,40,4374,129.9835,99.5939254760742,,,,,,,,,,,,,0,,,,0.0049,,,,,,133.499939,,,,
,22177201.955,130.4876251,99.5939254760742,1.80149496627943E-5,3.33958629645814E-7,1,0.999253354069792,40.0298881530762,1.99756192638126,16.330000013113,0.000205448363685743,3.20812964097534E-5,0.25,-3.25260469345297E-7,1.81111580088148E-5,-2.89654637544727E-7,130.4876251,130.4876251,99.5939254760742,99.5939254760742,56.7141837268714,20.5512536915506,26.705515,0,0,0,40,4374,127.018,99.5939254760742,,,,,,,,,,,,,0,,,,-0.00245,,,,,,130.4876251,,,,
,22177322.46,127.4349365,99.5939254760742,1.84456949609104E-5,2.91072436106385E-7,1,0.999253354069792,40.0298881530762,1.99755828572857,16.330000013113,0.000209987259352392,3.5050473312075E-5,0.25,-1.40986914760358E-7,1.85447996527976E-5,-1.02017552361106E-7,127.4349365,127.4349365,99.5939254760742,99.5939254760742,56.8955215433329,20.5542963666941,26.325863,0,0,0,40,4374,124.03225,99.5939254760742,,,,,,,,,,,,,0,,,,-0.00245,,,,,,127.4349365,,,,
,22177439.23,124.4889297,99.5939254760742,,,2,,,,16.4000003153086,,,,,,,124.4889297,124.4889297,99.5939254760742,99.5939254760742,,,25.946213,,,,-99999999,4374,121.1438,99.5939254760742,,,,,,,,,,,,,,,,,,,,,,,124.4889297,,,,
,22177537.915,121.9607468,99.5939254760742,1.8440770642922E-5,3.5494717703841E-7,1,0.999253354069792,40.0298881530762,1.99736398356399,16.38999953866,0.000209951785302593,3.49144666443837E-5,0.25,-1.55030538471727E-7,1.85414609407166E-5,-1.13177513040648E-7,121.9607468,121.9607468,99.5939254760742,99.5939254760742,56.8298647477175,20.5513336637548,25.946213,0,0,0,40,4374,118.696,99.5939254760742,,,,,,,,,,,,,0,,,,0,,,,,,121.9607468,,,,
,22177657,118.9630966,99.5939254760742,1.83398805794565E-5,3.1515383164575E-7,1,0.999253354069792,40.0298881530762,1.99725476715707,16.38999953866,0.000209072170433347,3.31712667599117E-5,0.25,-2.92493852105117E-7,1.84410826240681E-5,-2.49810792274773E-7,118.9630966,118.9630966,99.5939254760742,99.5939254760742,56.9009929429675,20.5530689160706,25.946213,0,0,0,40,4374,115.7515,99.5939254760742,,,,,,,,,,,,,0,,,,0,,,,,,118.9630966,,,,
,22177773.76,115.9957428,99.5939254760742,1.82685008718951E-5,3.27534791884321E-7,1,0.999253354069792,40.0298881530762,1.99716558077372,16.38999953866,0.000208212926598581,3.32927088455775E-5,0.25,-2.71200632819634E-7,1.83698956350662E-5,-2.26663357867986E-7,115.9957428,115.9957428,99.5939254760742,99.5939254760742,56.9854088230445,20.5559859790522,25.946213,0,0,0,40,4374,112.8745,99.5939254760742,,,,,,,,,,,,,0,,,,0,,,,,,115.9957428,,,,
,22177893.16,112.9427872,99.5939254760742,1.87831382317074E-5,2.96893974628229E-7,1,0.999253354069792,40.0298881530762,1.9971386596627,16.4599996060133,0.000214642465947065,3.10335454121361E-5,0.25,-5.62309127899742E-7,1.8888687525689E-5,-5.15901963402733E-7,112.9427872,112.9427872,99.5939254760742,99.5939254760742,56.8361177758714,20.5563614401954,25.566563,0,0,0,40,4374,109.9228,99.5939254760742,,,,,,,,,,,,,0,,,,0,,,,,,112.9427872,,,,
,22178012.405,109.939476,99.5939254760742,1.82745400844682E-5,2.8643278320769E-7,1,0.999253354069792,40.0298881530762,1.99702281329037,16.4599996060133,0.000208510944440879,3.19755583815528E-5,0.25,-3.9249595965467E-7,1.83772202568867E-5,-3.44189537456375E-7,109.939476,109.939476,99.5939254760742,99.5939254760742,56.8236117195637,20.5609593327802,25.186911,0,0,0,40,4374,106.986,99.5939254760742,,,,,,,,,,,,,0,,,,0.0049,,,,,,109.939476,,,,
,22178129.735,106.9429245,99.5939254760742,1.81263842922848E-5,3.60910060273263E-7,1,0.999253354069792,40.0298881530762,1.99725167122008,16.4599996060133,0.000207247365776404,2.94340035335074E-5,0.25,-5.92863632360713E-7,1.82290709118652E-5,-5.43632301085698E-7,106.9429245,106.9429245,99.5939254760742,99.5939254760742,56.8103240347368,20.562103503589,25.566563,0,0,0,40,4374,104.089,99.5939254760742,,,,,,,,,,,,,0,,,,-0.0049,,,,,,106.9429245,,,,
,22178259.75,103.6648865,99.5939254760742,,,2,,,,16.5400004500151,,,,,,,103.6648865,103.6648865,99.5939254760742,99.5939254760742,,,25.566563,,,,-99999999,4374,100.8754,99.5939254760742,,,,,,,,,,,,,,,,,,,,,,,103.6648865,,,,
,22178346.17,101.4795227,99.5939254760742,1.82024207440304E-5,3.11056703312501E-7,1,0.999253354069792,40.0298881530762,1.99681161255251,16.5299996733665,0.000207672673828743,3.18284743960538E-5,0.25,-4.0012559201358E-7,1.83049118561738E-5,-3.44431917787868E-7,101.4795227,101.4795227,99.5939254760742,99.5939254760742,57.1534589546791,20.5596559294742,25.186911,0,0,0,40,4374,98.71735,99.5939254760742,,,,,,,,,,,,,0,,,,-0.00245,,,,,,101.4795227,,,,
,22178464.985,98.4874039,99.5939254760742,1.81661381928469E-5,2.90943701810375E-7,1,0.999253354069792,40.0298881530762,1.99666609194618,16.5299996733665,0.000207552358399202,2.99902721662201E-5,0.25,-5.58411205140743E-7,1.8268609631085E-5,-5.00533491242133E-7,98.4874039,98.4874039,99.5939254760742,99.5939254760742,57.0354330482753,20.5607764390647,24.807261,0,0,0,40,4374,95.7982,99.5939254760742,,,,,,,,,,,,,0,,,,-0.0049,,,,,,98.4874039,,,,
,22178583.14,95.4820786,99.5939254760742,1.82449424609769E-5,2.55213694601693E-7,1,0.999253354069792,40.0298881530762,1.99686197656921,16.5299996733665,0.00020799850381477,3.27719520099592E-5,0.25,-3.3114533967834E-7,1.8346431671177E-5,-2.68235951780502E-7,95.4820786,95.4820786,99.5939254760742,99.5939254760742,57.2707032325638,20.560781579636,24.807261,0,0,0,40,4374,92.863,99.5939254760742,,,,,,,,,,,,,0,,,,-0.00245,,,,,,95.4820786,,,,
,22178703.945,92.404129,99.5939254760742,1.82527482519436E-5,3.15401048079799E-7,1,0.999253354069792,40.0298881530762,1.99693520636439,16.5999997407198,0.00020743274830791,3.64734756294325E-5,0.25,-1.05942120788694E-8,1.83520613828923E-5,5.79949365982093E-8,92.404129,92.404129,99.5939254760742,99.5939254760742,56.851750346256,20.5610071864503,24.807261,0,0,0,40,4374,89.88135,99.5939254760742,,,,,,,,,,,,,0,,,,0.00245,,,,,,92.404129,,,,
,22178818.555,89.4770279,99.5939254760742,1.78971196304737E-5,2.92087063291992E-7,1,0.999253354069792,40.0298881530762,1.9967985825654,16.5999997407198,0.000204158604249654,3.12509431319926E-5,0.25,-4.10988360612773E-7,1.79947056644189E-5,-3.41951025949971E-7,89.4770279,89.4770279,99.5939254760742,99.5939254760742,56.8501870892175,20.5653693112141,24.807261,0,0,0,40,4374,87.06735,99.5939254760742,,,,,,,,,,,,,0,,,,-0.00245,,,,,,89.4770279,,,,
,22178935.505,86.4476395,99.5939254760742,1.81293643090493E-5,2.8193015467035E-7,1,0.999253354069792,40.0298881530762,1.99676360826902,16.5999997407198,0.000206743924990695,3.18820316020298E-5,0.25,-4.00532962039041E-7,1.82263703936452E-5,-3.26076770427071E-7,86.4476395,86.4476395,99.5939254760742,99.5939254760742,56.5828701356406,20.5617398611461,24.427608,0,0,0,40,4374,84.2146,99.5939254760742,,,,,,,,,,,,,0,,,,0.00245,,,,,,86.4476395,,,,
,22179051.395,83.4944763,99.5939254760742,1.83438969527036E-5,2.96793668915153E-7,1,0.999253354069792,40.0298881530762,1.9967924203434,16.5999997407198,0.000209016899779843,3.30993159984833E-5,0.25,-3.35796626372154E-7,1.84393453468232E-5,-2.55225506895115E-7,83.4944763,83.4944763,99.5939254760742,99.5939254760742,56.8400259184676,20.5618498748601,24.807261,0,0,0,40,4374,81.36885,99.5939254760742,,,,,,,,,,,,,0,,,,0.00245,,,,,,83.4944763,,,,
,22179169.12,80.4827728,99.5939254760742,1.85327806340162E-5,2.68135897538037E-7,1,0.999253354069792,40.0298881530762,1.99632082383804,16.669999808073,0.000210125535087064,3.88407405675159E-5,0.25,1.32339397718512E-7,1.86238305967905E-5,2.21425956431511E-7,80.4827728,80.4827728,99.5939254760742,99.5939254760742,56.7579549239483,20.5693006917866,24.047956,0,0,0,40,4374,78.51145,99.5939254760742,,,,,,,,,,,,,0,,,,-0.00245,,,,,,80.4827728,,,,
,22179285.775,77.4954529,99.5939254760742,1.79674309626437E-5,3.27904395368378E-7,1,0.999253354069792,40.0298881530762,1.9962586314131,16.669999808073,0.000205078910854157,2.96913646776835E-5,0.25,-5.78167209789801E-7,1.80552821682819E-5,-4.89640621403831E-7,77.4954529,77.4954529,99.5939254760742,99.5939254760742,56.9783741663714,20.5600818131862,23.668306,0,0,0,40,4374,75.64915,99.5939254760742,,,,,,,,,,,,,0,,,,-0.00245,,,,,,77.4954529,,,,
,22179404.565,74.4996033,99.5939254760742,1.86832710357767E-5,3.13212337232406E-7,1,0.999253354069792,40.0298881530762,1.99636556083372,16.669999808073,0.000212614886260482,3.41696814695065E-5,0.25,-3.16390103062007E-7,1.87680055346769E-5,-2.16675417980703E-7,74.4996033,74.4996033,99.5939254760742,99.5939254760742,57.1221938139099,20.5593107610163,23.668306,0,0,0,40,4374,72.7333,99.5939254760742,,,,,,,,,,,,,0,,,,0,,,,,,74.4996033,,,,
,22179525.42,71.4579926,99.5939254760742,1.80123119715482E-5,2.76640865516209E-7,1,0.999253354069792,40.0298881530762,1.9968050566022,16.7399998754263,0.000204572620621398,3.50536806356006E-5,0.25,-1.24987567925978E-7,1.80865571989489E-5,-2.15364811220688E-8,71.4579926,71.4579926,99.5939254760742,99.5939254760742,56.8423708040252,20.5685420241188,23.288654,0,0,0,40,4374,69.7322,99.5939254760742,,,,,,,,,,,,,0,,,,-0.0049,,,,,,71.4579926,,,,
,22179643.69,68.434639,99.5939254760742,1.84178207764755E-5,3.25102797008604E-7,1,0.999253354069792,40.0298881530762,1.99645708553271,16.7399998754263,0.000209112538444077,3.54944777880621E-5,0.25,-1.63292855764097E-7,1.84860164994986E-5,-5.09722167763465E-8,68.434639,68.434639,99.5939254760742,99.5939254760742,56.5609845371021,20.5569517611985,22.909004,0,0,0,40,4374,66.7976,99.5939254760742,,,,,,,,,,,,,0,,,,0.00245,,,,,,68.434639,,,,
,22179761.455,65.4185104,99.5939254760742,1.80886617802359E-5,3.1129248749457E-7,1,0.999253354069792,40.0298881530762,1.99659803235509,16.7399998754263,0.000205517069698129,3.35503527479618E-5,0.25,-2.80967715401892E-7,1.81471761303753E-5,-1.64642966741087E-7,65.4185104,65.4185104,99.5939254760742,99.5939254760742,56.8423708040252,20.555880660263,22.909004,0,0,0,40,4374,63.90845,99.5939254760742,,,,,,,,,,,,,0,,,,-0.0049,,,,,,65.4185104,,,,
,22179894.34,62.0225906,99.5939254760742,,,2,,,,16.8199997881055,,,,,,,62.0225906,62.0225906,99.5939254760742,99.5939254760742,,,22.909004,,,,-99999999,4374,60.6629,99.5939254760742,,,,,,,,,,,,,,,,,,,,,,,62.0225906,,,,
,22179996.3,59.449173,99.5939254760742,1.83579247850786E-5,3.55042146019246E-7,1,0.999253354069792,40.0298881530762,1.99706368702954,16.8099999427795,0.000207984895320361,3.60658551750822E-5,0.25,-1.1506721415041E-7,1.83923026941738E-5,1.48109365685823E-8,59.449173,59.449173,99.5939254760742,99.5939254760742,56.9682129956214,20.5491341387766,22.149702,0,0,0,40,4374,58.1567,99.5939254760742,,,,,,,,,,,,,0,,,,0,,,,,,59.449173,,,,
,22180113.635,56.4662361,99.5939254760742,1.82433125876488E-5,3.25050001376887E-7,1,0.999253354069792,40.0298881530762,1.99669396118853,16.8099999427795,0.000207059256885929,3.26302607925934E-5,0.25,-3.99274093813284E-7,1.82651458149637E-5,-2.66505527775183E-7,56.4662361,56.4662361,99.5939254760742,99.5939254760742,56.760299809506,20.5515494827619,22.149702,0,0,0,40,4374,55.26955,99.5939254760742,,,,,,,,,,,,,0,,,,-0.0049,,,,,,56.4662361,,,,
,22180232.72,53.4355354,99.5939254760742,1.82972939414179E-5,3.51383115478122E-7,1,0.999253354069792,40.0298881530762,1.99662023435458,16.8099999427795,0.000207257267529739,3.3956771422522E-5,0.25,-2.91292453049074E-7,1.83024546216933E-5,-1.55529300785267E-7,53.4355354,53.4355354,99.5939254760742,99.5939254760742,56.7970363499099,20.5525326578669,21.770052,0,0,0,40,4374,52.34185,99.5939254760742,,,,,,,,,,,,,0,,,,-0.00245,,,,,,53.4355354,,,,
,22180345.93,50.4946327,99.5939254760742,1.83209118378471E-5,3.2873515529991E-7,1,0.999253354069792,40.0298881530762,1.99673043828307,16.8699994683266,0.000207377888345161,3.38518313525045E-5,0.25,-3.02704079511249E-7,1.83102936129135E-5,-1.66320459434004E-7,50.4946327,50.4946327,99.5939254760742,99.5939254760742,56.9729027667368,20.5599815698299,21.3904,0,0,0,40,4374,49.56045,99.5939254760742,,,,,,,,,,,,,0,,,,0,,,,,,50.4946327,,,,
,22180466.4,47.4530983,99.5939254760742,1.84380651567486E-5,5.71458933032357E-7,1,0.999253354069792,40.0298881530762,1.99671427626714,16.8699994683266,0.000209233813559555,3.00197462133803E-5,0.25,-6.59020005394078E-7,1.84130220089793E-5,-5.22910304737717E-7,47.4530983,47.4530983,99.5939254760742,99.5939254760742,56.9517987967176,20.5606834403667,20.631098,0,0,0,40,4370,46.61725,99.5939254760742,,,,,,,,,,,,,0,,,,0,,,,,,47.4530983,,,,
,22180582.965,44.4316635,99.5939254760742,1.85547882760787E-5,3.00446317134977E-7,1,0.999253354069792,40.0298881530762,1.99671615603376,16.8699994683266,0.0002092607010993,3.6391823176793E-5,0.25,-1.08294102322898E-7,1.85097496244537E-5,2.38984993316712E-8,44.4316635,44.4316635,99.5939254760742,99.5939254760742,56.7180918694675,20.5590447463311,20.251448,0,0,0,40,4370,43.76075,99.5939254760742,,,,,,,,,,,,,0,,,,0,,,,,,44.4316635,,,,
,22180714.63,41.1105118,99.5939254760742,,,2,,,,16.9300001600385,,,,,,,41.1105118,41.1105118,99.5939254760742,99.5939254760742,,,20.251448,,,,-99999999,4370,40.5278,99.5939254760742,,,,,,,,,,,,,,,,,,,,,,,41.1105118,,,,
,22180820.85,38.4350243,99.5939254760742,1.83065554063934E-5,3.4198967702626E-7,1,0.999253354069792,40.0298881530762,1.99712940027888,16.9200003147125,0.000206787789664705,3.25528472226261E-5,0.25,-3.88546340392431E-7,1.82368900377161E-5,-2.69074312014873E-7,38.4350243,38.4350243,99.5939254760742,99.5939254760742,57.0057311645445,20.5601136768035,19.871798,0,0,0,40,4370,37.9086,99.5939254760742,,,,,,,,,,,,,0,,,,-0.00245,,,,,,38.4350243,,,,
,22180936.72,35.4643936,99.5939254760742,1.83346158333816E-5,3.02019897649081E-7,1,0.999253354069792,40.0298881530762,1.99702245846314,16.9200003147125,0.000206577543662307,3.48200000054953E-5,0.25,-1.83506408295491E-7,1.82533643565408E-5,-7.13077243208178E-8,35.4643936,35.4643936,99.5939254760742,99.5939254760742,56.9064643426022,20.5631329764942,18.732843,0,0,0,40,4370,35.0519,99.5939254760742,,,,,,,,,,,,,0,,,,-0.00245,,,,,,35.4643936,,,,
,22181054.25,32.4906807,99.5939254760742,1.82928556192983E-5,3.38641410528768E-7,1,0.999253354069792,40.0298881530762,1.99728302660407,16.9200003147125,0.000206866710081083,3.00963514243623E-5,0.25,-5.88603974551654E-7,1.82059309911926E-5,-4.81120101104925E-7,32.4906807,32.4906807,99.5939254760742,99.5939254760742,56.994006736756,20.558318241167,18.353191,0,0,0,40,4370,32.1388,99.5939254760742,,,,,,,,,,,,,0,,,,0.00245,,,,,,32.4906807,,,,
,22181175.81,29.3995209,99.5939254760742,1.84599143268951E-5,3.03557042713106E-7,1,0.999253354069792,40.0298881530762,1.99722853861441,16.9600006192923,0.000207852985792272,3.49809322697246E-5,0.25,-1.76903007668968E-7,1.83634539689106E-5,-7.63815316962463E-8,29.3995209,29.3995209,99.5939254760742,99.5939254760742,57.0862389020253,20.5599545711401,17.973541,0,0,0,40,4370,29.13795,99.5939254760742,,,,,,,,,,,,,0,,,,0,,,,,,29.3995209,,,,
,22181292.505,26.4938297,99.5939254760742,1.79846324146091E-5,2.49380373936637E-7,1,0.999253354069792,40.0298881530762,1.99700727945334,16.9600006192923,0.000203070329296176,3.04798832172464E-5,0.25,-4.87219970360741E-7,1.78880417990172E-5,-3.91996885387326E-7,26.4938297,26.4938297,99.5939254760742,99.5939254760742,57.1237570709483,20.558923817078,17.214239,0,0,0,40,4370,26.23375,99.5939254760742,,,,,,,,,,,,,0,,,,-0.0049,,,,,,26.4938297,,,,
,22181413.01,23.477602,99.5939254760742,1.86356000210538E-5,2.84760801682976E-7,1,0.999253354069792,40.0298881530762,1.99689207459837,16.9600006192923,0.000210631520280063,3.01333247435174E-5,0.25,-6.29849589537391E-7,1.85331593916716E-5,-5.33825537580318E-7,23.4420357,23.5131683,99.5939254760742,99.5939254760742,56.8673829166406,20.5634148703449,17.214239,0,0,0,40,4370,23.2318,99.5939254760742,,,,,,,,,,,,,0,,,,0.0049,,,,,,23.477602,,,,
,22181543,20.2316723,99.5939254760742,,,2,,,,17.0200003796816,,,,,,,20.2316723,20.2316723,99.5939254760742,99.5939254760742,,,16.075285,,,,-99999999,4370,20.0109,99.5939254760742,,,,,,,,,,,,,,,,,,,,,,,20.2316723,,,,
,22181652.71,17.4394226,99.5939254760742,1.84057354059353E-5,2.60503760675669E-7,1,0.999253354069792,40.0298881530762,1.99668515234095,17.0099996030331,0.000207829446202785,3.06664604376982E-5,0.25,-5.38385409821012E-7,1.83022600217081E-5,-4.46566448722736E-7,17.4394226,17.4394226,99.5939254760742,99.5939254760742,57.4207759082561,20.5658378736455,15.695635,0,0,0,40,4370,17.28065,99.5939254760742,,,,,,,,,,,,,0,,,,0,,,,,,17.4394226,,,,
,22181772.35,14.4639063,99.5939254760742,1.84579030857528E-5,2.82883856099913E-7,1,0.999253354069792,40.0298881530762,1.99698387293849,17.0099996030331,0.000207653042690367,3.52498120959428E-5,0.25,-1.4016500115141E-7,1.83524174892122E-5,-5.03403551932742E-8,14.4639063,14.4639063,99.5939254760742,99.5939254760742,56.8877052581406,20.5645638224019,15.315984,0,0,0,40,4370,14.3012,99.5939254760742,,,,,,,,,,,,,0,,,,0,,,,,,14.4639063,,,,
,22181891.27,11.4490347,99.5939254760742,1.85236274778132E-5,2.53558578697893E-7,1,0.999253354069792,40.0298881530762,1.99693214448917,17.0099996030331,0.000208687184815627,3.36940784574429E-5,0.25,-2.90255635198439E-7,1.84186159327816E-5,-1.99252147683322E-7,11.4490347,11.4490347,99.5939254760742,99.5939254760742,56.9760292808137,20.563100470754,14.177031,0,0,0,40,4370,11.3333,99.5939254760742,,,,,,,,,,,,,0,,,,0.0049,,,,,,11.4490347,,,,
,22182108.755,10.0078983,99.5939254760742,1.83488537466143E-5,3.00753461593876E-7,1,0.999253354069792,40.0298881530762,1.99693855291738,17.0200001448393,0.000206600723803498,3.40443133572593E-5,0.25,-2.28062625528758E-7,1.82445921696389E-5,-1.38259663554081E-7,10.0078983,10.0078983,99.5939254760742,99.5939254760742,56.8392442899483,20.5624415224313,13.797379,0,0,0,40,4369,9.9831,99.5939254760742,,,,,,,,,,,,,0,,,,-0.00245,,,,,,10.0078983,,,,