File: data/doubleLayers/dl_1-25/ppms/KoelnPPMS/DD205_3_HYST_100OE_20K.DAT
[Header]
; VSM Data File (default extension .dat)
; Copyright (c) 2003-2013, Quantum Design, Inc. All rights reserved.
TITLE,
FILEOPENTIME,22193365.48,09/15/2018,5:48 am
BYAPP,VSM,2.0,2.0
INFO,PPMS VSM Option Release 1.4.10 Build 1,APPNAME
INFO,Quantum Design Linear Motor Servo Controller,MOTOR_MODULE_NAME
INFO,3101-100 M1,MOTOR_HW_VERSION
INFO,MMC1014,MOTOR_SERIAL_NUMBER
INFO,SRV No X-over 01.03.11,MOTOR_SOFTWARE_VERSION
INFO,Quantum Design VSM Detection Module,VSM_MODULE_NAME
INFO,3101-150 F0,VSM_HW_VERSION
INFO,VSM707,VSM_SERIAL_NUMBER
INFO,VSM No X-over 01.02.05 May 20 2008 13:51:47,VSM_SOFTWARE_VERSION
INFO,704,PREAMP_SERIAL_NUMBER
INFO,822,COIL_SERIAL_NUMBER
INFO,0,MOMENT_UNITS
INFO,CoFe2O4,SAMPLE_MATERIAL
INFO,Double Layer blue,SAMPLE_COMMENT
INFO,,SAMPLE_MASS
INFO,,SAMPLE_VOLUME
INFO,,SAMPLE_MOLECULAR_WEIGHT
INFO,,SAMPLE_SIZE
INFO,,SAMPLE_SHAPE
DATATYPE,COMMENT,1
DATATYPE,TIME,2
STARTUPAXIS,X,2
STARTUPAXIS,Y1,5
[Data]
Comment,Time Stamp (sec),Temperature (K),Magnetic Field (Oe),Moment (emu),M. Std. Err. (emu),Transport Action,Averaging Time (sec),Frequency (Hz),Peak Amplitude (mm),Center Position (mm),Coil Signal' (mV),Coil Signal" (mV),Range (mV),M. Quad. Signal (emu),M. Raw' (emu),M. Raw" (emu),Min. Temperature (K),Max. Temperature (K),Min. Field (Oe),Max. Field (Oe),Mass (grams),Motor Lag (deg),Pressure (Torr),VSM Status (code),Motor Status (code),Measure Status (code),Measure Count,PPMS Status (code),System Temp. (K),System Field (Oe),Sample Position (deg),Bridge 1 Resistance (ohms),Bridge 1 Excitation (에),Bridge 2 Resistance (ohms),Bridge 2 Excitation (에),Bridge 3 Resistance (ohms),Bridge 3 Excitation (에),Bridge 4 Resistance (ohms),Bridge 4 Excitation (에),Signal 1 Vin (V),Signal 2 Vin (V),Digital Inputs (code),Drive 1 Iout (mA),Drive 1 Ipower (W),Drive 2 Iout (mA),Drive 2 Ipower (W),Pressure (),Map 20 (),Map 21 (),Map 22 (),Map 23 (),Map 24 (),Map 25 (),Map 26 (),Map 27 (),Map 28 (),Map 29 ()
,22193380.94,19.9849243,-0.380594313144684,,,2,,,,17.1999998876452,,,,,,,19.9849243,19.9849243,-0.380594313144684,-0.380594313144684,,,14.556682,,,,-99999999,4369,20.0672,-0.380594313144684,,,,,,,,,,,,,,,,,,,,,,,19.9849243,,,,
,22193531.855,20.00537015,4562.88134765625,7.92285623361625E-5,3.51949925452198E-7,1,0.999253354069792,40.0298881530762,1.99761967852529,17.1900000423193,0.000891388839244833,0.000153850685963779,0.25,-4.06475482096251E-7,7.87947368323404E-5,1.51915195968774E-9,20.0033779,20.0073624,4555.400390625,4570.3623046875,56.5015807696406,20.5438756584167,14.936333,0,0,0,40,4449,20.0362,4562.88134765625,,,,,,,,,,,,,0,,,,-0.0049,,,,,,20.00537015,,,,
,22193632.235,19.99284935,9579.169921875,6.99222677074606E-5,3.02739328454811E-7,1,0.999253354069792,40.0298881530762,1.99764234116072,17.1900000423193,0.000787306924586363,0.000134048889163259,0.25,-5.42704264524574E-7,6.9566391757588E-5,-1.56394689214407E-7,19.9928341,19.9928646,9571.7314453125,9586.6083984375,57.0995265868522,20.5464381383701,14.556682,0,0,0,40,4449,20.05215,9579.169921875,,,,,,,,,,,,,0,,,,0.00245,,,,,,19.99284935,,,,
,22193735.135,19.9961338,14721.2944335938,5.94928143593257E-5,3.43083379028943E-7,1,0.999253354069792,40.0298881530762,1.99746144681074,17.1900000423193,0.000672039373461095,0.000103319446440558,0.25,-1.44191046252075E-6,5.92219904234057E-5,-1.08670731689036E-6,19.9961338,19.9961338,14713.650390625,14728.9384765625,56.5969394489868,20.5496245772075,14.556682,0,0,0,40,4449,20.0625,14721.2944335938,,,,,,,,,,,,,0,,,,0,,,,,,19.9961338,,,,
,22193840.355,20.0019083,19978.5966796875,4.87647139849151E-5,3.51925998936548E-7,1,0.999253354069792,40.0298881530762,1.99749634196908,17.1900000423193,0.000551763520743311,8.12540926617971E-5,0.25,-1.50826078637237E-6,4.8569185674044E-5,-1.19901898453906E-6,20.0017014,20.0021152,19971.19140625,19986.001953125,56.6086638767752,20.5495670594807,14.556682,0,0,0,40,4449,20.06665,19978.5966796875,,,,,,,,,,,,,0,,,,-0.0049,,,,,,20.0019083,,,,
,22193936.265,20.0023937,24770.916015625,3.82203930096461E-5,4.60391489608519E-7,1,0.999253354069792,40.0298881530762,1.99769932684088,17.1900000423193,0.00043368847919381,5.82664319012819E-5,0.25,-1.67772398105786E-6,3.80889365299227E-5,-1.42298923813519E-6,20.0023937,20.0023937,24763.462890625,24778.369140625,56.8775440873906,20.5499606816347,14.936333,0,0,0,40,4449,20.0581,24770.916015625,,,,,,,,,,,,,0,,,,0,,,,,,20.0023937,,,,
,22194030.525,20.0026016,29483.9140625,2.97152748107882E-5,4.59529585957764E-7,1,0.999253354069792,40.0298881530762,1.99783416057491,17.1900000423193,0.000337352074825955,4.54323126421835E-5,0.25,-1.30227671461685E-6,2.9627839874571E-5,-1.09749042430117E-6,20.0026016,20.0026016,29476.486328125,29491.341796875,56.4898563418521,20.5461141471718,14.556682,0,0,0,40,4449,20.05565,29483.9140625,,,,,,,,,,,,,0,,,,-0.0049,,,,,,20.0026016,,,,
,22194127.75,20.0030251,34343.611328125,1.9186866287893E-5,4.7201505341605E-7,1,0.999253354069792,40.0298881530762,1.99780595961275,17.1900000423193,0.000220799721370489,1.34221093355443E-5,0.25,-2.25833850954656E-6,1.91502814054403E-5,-2.11854915481129E-6,20.0030251,20.0030251,34338.625,34348.59765625,56.8204852054868,20.5466546036387,14.936333,0,0,0,40,4449,20.0525,34343.611328125,,,,,,,,,,,,,0,,,,0,,,,,,20.0030251,,,,
,22194219.63,20.0026913,38935.96484375,6.62632583308048E-6,4.60621533047077E-7,1,0.999253354069792,40.0298881530762,1.99773369084066,17.1900000423193,7.75393284917774E-5,-2.30030725089067E-6,0.25,-1.3963994907135E-6,6.62143575711202E-6,-1.3460308511424E-6,20.0026913,20.0026913,38925.859375,38946.0703125,56.4922012274098,20.5501644677549,14.936333,0,0,0,40,4449,20.05265,38935.96484375,,,,,,,,,,,,,0,,,,0.0049,,,,,,20.0026913,,,,
,22194314.91,20.0027237,43696.15234375,-2.84496782092613E-6,4.16650559299765E-7,1,0.999253354069792,40.0298881530762,1.99785611039116,17.1900000423193,-2.54788413375271E-5,-4.25029658611369E-5,0.25,-3.25559912779211E-6,-2.81638031728051E-6,-3.27059112146469E-6,20.0027237,20.0027237,43688.52734375,43703.77734375,56.8345545188329,20.5481929602872,14.936333,0,0,0,40,4449,20.0476,43696.15234375,,,,,,,,,,,,,0,,,,-0.00245,,,,,,20.0027237,,,,
,22194407.02,20.0025539,48299.005859375,-1.47697380607283E-5,5.36044549874761E-7,1,0.999253354069792,40.0298881530762,1.99796699043425,17.1900000423193,-0.000163260633914939,-4.90782495752981E-5,0.25,-1.6875574690192E-6,-1.47386630135687E-5,-1.79401031345557E-6,20.0025539,20.0025539,48291.703125,48306.30859375,56.8439340610637,20.5467801958502,14.556682,0,0,0,40,4449,20.04775,48299.005859375,,,,,,,,,,,,,0,,,,0,,,,,,20.0025539,,,,
,22194500.54,20.0013218,52974.140625,-2.71787176738257E-5,4.62657936239785E-7,1,0.999253354069792,40.0298881530762,1.99784680167207,17.1900000423193,-0.000302970439415018,-7.69118331550746E-5,0.25,-1.91374095837974E-6,-2.71429868133607E-5,-2.11364908937722E-6,20.0013218,20.0013218,52969.10546875,52979.17578125,56.7642079521022,20.5430775674051,14.936333,0,0,0,40,4449,20.0462,52974.140625,,,,,,,,,,,,,0,,,,0,,,,,,20.0013218,,,,
,22194596.69,20.0009251,57779.478515625,-4.00417278373567E-5,5.40526096325938E-7,1,0.999253354069792,40.0298881530762,1.99788394223212,17.1900000423193,-0.000447823298732966,-0.000106442565509653,0.25,-2.20542996835203E-6,-4.00123179491022E-5,-2.5026259590355E-6,20.0009251,20.0009251,57777.08984375,57781.8671875,56.4773502855444,20.5450916624902,15.315984,0,0,0,40,4449,20.047,57779.478515625,,,,,,,,,,,,,0,,,,-0.00245,,,,,,20.0009251,,,,
,22194693.71,20.0037422,62629.966796875,-5.01761328841838E-5,4.72013967594913E-7,1,0.999253354069792,40.0298881530762,1.99777382229791,17.1900000423193,-0.000559156267994344,-0.00014583236025997,0.25,-3.86073613371491E-6,-5.01538607158791E-5,-4.23453788196916E-6,20.0037422,20.0037422,62625.046875,62634.88671875,56.4288893173521,20.5475659988265,14.556682,0,0,0,40,4449,20.0436,62629.966796875,,,,,,,,,,,,,0,,,,0,,,,,,20.0037422,,,,
,22194789.08,20.0019836,67397.69921875,-6.57357404336592E-5,5.35204762734097E-7,1,0.999253354069792,40.0298881530762,1.99794651204189,17.1900000423193,-0.000736463995132965,-0.000171507834181277,0.25,-3.32236338256727E-6,-6.57474973683854E-5,-3.81160923816554E-6,20.0019836,20.0019836,67392.6171875,67402.78125,56.6438371601406,20.5431286293687,14.936333,0,0,0,40,4449,20.0414,67397.69921875,,,,,,,,,,,,,0,,,,0,,,,,,20.0019836,,,,
,22194880.73,20.0024281,71977.7421875,-7.74627120393427E-5,4.91679951169825E-7,1,0.999253354069792,40.0298881530762,1.99790924159684,17.1900000423193,-0.000869375609515388,-0.000195481965080047,0.25,-3.32661027457124E-6,-7.7511143502778E-5,-3.90065172151208E-6,20.0024281,20.0024281,71970.28125,71985.203125,56.8705094307176,20.5445532331085,15.315984,0,0,0,40,4449,20.0421,71977.7421875,,,,,,,,,,,,,0,,,,0.00245,,,,,,20.0024281,,,,
,22194974.095,20.0023479,76643.8515625,-8.94202574217918E-5,5.59077518319281E-7,1,0.999253354069792,40.0298881530762,1.99784198302244,17.1900000423193,-0.00100766035316908,-0.000204981631946521,0.25,-2.01175608708273E-6,-8.95232622223E-5,-2.66782998473389E-6,20.0023479,20.0023479,76633.71875,76653.984375,56.7446672391214,20.5419975627165,14.936333,0,0,0,40,4449,20.03715,76643.8515625,,,,,,,,,,,,,0,,,,-0.00245,,,,,,20.0023479,,,,
,22195070.065,20.0024967,81441.96875,-0.000101790068636976,5.55221655802673E-7,1,0.999253354069792,40.0298881530762,1.99771635579095,17.1900000423193,-0.00114512801303864,-0.000246041559099872,0.25,-3.4146189692736E-6,-0.000101936354439729,-4.15603812263212E-6,20.0024967,20.0024967,81431.8046875,81452.1328125,56.5961578204675,20.5457502130723,14.556682,0,0,0,40,4449,20.0358,81441.96875,,,,,,,,,,,,,0,,,,0,,,,,,20.0024967,,,,
,22195160.665,20.0023155,85969.80078125,-0.000113809529929829,4.78353302222902E-7,1,0.999253354069792,40.0298881530762,1.99772630390172,17.1900000423193,-0.00128054985179373,-0.00027639329207687,0.25,-3.93472436943647E-6,-0.000114009308355771,-4.75523378634957E-6,20.0023155,20.0023155,85965.2578125,85974.34375,56.7579549239483,20.5437154430161,14.556682,0,0,0,40,4449,20.03345,85969.80078125,,,,,,,,,,,,,0,,,,0.0049,,,,,,20.0023155,,,,
,22195269.75,20.0021896,89585.1015625,-0.000125017050079947,4.10277694606241E-7,1,0.999253354069792,40.0298881530762,1.99781196832216,17.1900000423193,-0.00140937163455516,-0.000290825001780122,0.25,-3.19528293755498E-6,-0.000125275285463145,-4.08556468612508E-6,20.0021896,20.0021896,89575.203125,89595,56.5922496778714,20.5451660948685,14.936333,0,0,0,40,4449,20.03345,89585.1015625,,,,,,,,,,,,,0,,,,0.00245,,,,,,20.0021896,,,,
,22195358.735,20.0009861,85139.01171875,-0.000114007474469964,5.11901533402206E-7,1,0.999253354069792,40.0298881530762,1.99760414568783,17.1900000423193,-0.00128273211778066,-0.000276261243920805,0.25,-3.88833281880972E-6,-0.000114201330180759,-4.7118485874736E-6,20.0009861,20.0009861,85129.09375,85148.9296875,56.6837002146214,20.541751376542,14.556682,0,0,0,40,4449,20.0321,85139.01171875,,,,,,,,,,,,,0,,,,-0.00245,,,,,,20.0009861,,,,
,22195450.775,19.9999523,80538.0859375,-0.000100349910194482,5.78545112151206E-7,1,0.999253354069792,40.0298881530762,1.99788604400735,17.1900000423193,-0.00112871775492535,-0.000243810306539777,0.25,-3.47476764637416E-6,-0.000100486587256281,-4.20726453197619E-6,19.9999523,19.9999523,80530.546875,80545.625,56.7798405224868,20.5448043810154,14.556682,0,0,0,40,4449,20.03175,80538.0859375,,,,,,,,,,,,,0,,,,0.00245,,,,,,19.9999523,,,,
,22195548.03,20.0006943,75676.46875,-8.63218305634599E-5,5.61380735888808E-7,1,0.999253354069792,40.0298881530762,1.99795354509098,17.1900000423193,-0.000969893261409021,-0.000213582690792613,0.25,-3.32910698413359E-6,-8.64045254613095E-5,-3.9652568433492E-6,20.0006943,20.0006943,75666.2265625,75686.7109375,56.7165286124291,20.5485858570175,14.936333,0,0,0,40,4449,20.03215,75676.46875,,,,,,,,,,,,,0,,,,0.00245,,,,,,20.0006943,,,,
,22195644.035,20.0004158,70878.24609375,-7.36337697851488E-5,5.64801540454603E-7,1,0.999253354069792,40.0298881530762,1.99787188160262,17.1900000423193,-0.000828526903248118,-0.000173507672343781,0.25,-2.0743923850666E-6,-7.36810680741047E-5,-2.61975452968884E-6,20.0001507,20.0006809,70868.25,70888.2421875,56.7642079521022,20.5439252105352,14.936333,0,0,0,40,4449,20.03285,70878.24609375,,,,,,,,,,,,,0,,,,0,,,,,,20.0004158,,,,
,22195738.695,19.9985924,66145.5546875,-6.00633471490139E-5,7.04325526407907E-7,1,0.999253354069792,40.0298881530762,1.99797279982861,17.1900000423193,-0.000672972414309959,-0.000156004354850824,0.25,-2.97417790964144E-6,-6.00679323469748E-5,-3.42137812183379E-6,19.9985924,19.9985924,66135.5390625,66155.5703125,56.780622151006,20.5458999760652,14.936333,0,0,0,40,4449,20.0312,66145.5546875,,,,,,,,,,,,,0,,,,-0.00245,,,,,,19.9985924,,,,
,22195830.68,19.9981556,61547.001953125,-4.8951181132498E-5,5.11096496626693E-7,1,0.999253354069792,40.0298881530762,1.99780340883245,17.1900000423193,-0.000549925429529911,-0.000117480229715346,0.25,-1.57335904008641E-6,-4.89408937926552E-5,-1.93771394425948E-6,19.9981556,19.9981556,61542.0234375,61551.98046875,56.6407106460637,20.5462256350593,14.936333,0,0,0,40,4449,20.033,61547.001953125,,,,,,,,,,,,,0,,,,0,,,,,,19.9981556,,,,
,22195926.485,19.9982872,56759.15625,-3.54392274155531E-5,5.37408473915932E-7,1,0.999253354069792,40.0298881530762,1.99788011445114,17.1900000423193,-0.000394834396848077,-0.00010238377193097,0.25,-2.67672938309057E-6,-3.54043417516161E-5,-2.93913956946291E-6,19.9982872,19.9982872,56754.28515625,56764.02734375,56.8900501436983,20.5420514483452,14.936333,0,0,0,40,4449,20.03555,56759.15625,,,,,,,,,,,,,0,,,,-0.00245,,,,,,19.9982872,,,,
,22196025.915,19.9996567,51789.521484375,-2.27410633864547E-5,5.51591291369129E-7,1,0.999253354069792,40.0298881530762,1.99792374875335,17.1900000423193,-0.000253014483813938,-6.69424603632126E-5,0.25,-1.83126964844778E-6,-2.27067969250058E-5,-1.99786598040287E-6,19.9996567,19.9996567,51782.40234375,51796.640625,56.9275683126214,20.5450398648719,14.936333,0,0,0,40,4449,20.03575,51789.521484375,,,,,,,,,,,,,0,,,,0,,,,,,19.9996567,,,,
,22196121.75,20.0009022,46999.3515625,-1.15386718939664E-5,5.48621197160003E-7,1,0.999253354069792,40.0298881530762,1.99794397512049,17.1900000423193,-0.000126703182343412,-4.29102653489674E-5,0.25,-1.72396586060189E-6,-1.15099113566966E-5,-1.80612986218803E-6,20.0007,20.0011044,46989.578125,47009.125,56.7438856106022,20.5457497854776,15.315984,0,0,0,40,4449,20.03485,46999.3515625,,,,,,,,,,,,,0,,,,0,,,,,,20.0009022,,,,
,22196220.695,20.0016499,42054.517578125,1.39439023190274E-6,4.43485027523701E-7,1,0.999253354069792,40.0298881530762,1.99779151561891,17.1900000423193,1.81665055207273E-5,-1.07246048458771E-5,0.25,-1.20196740312844E-6,1.40040195414801E-6,-1.18960234578416E-6,20.0016499,20.0016499,42046.80078125,42062.234375,56.6203883045637,20.5460267028195,14.936333,0,0,0,40,4449,20.0342,42054.517578125,,,,,,,,,,,,,0,,,,0,,,,,,20.0016499,,,,
,22196314.195,19.9984322,37379.271484375,1.18787207050024E-5,4.83426163546375E-7,1,0.999253354069792,40.0298881530762,1.99784220913686,17.1900000423193,0.000137148764680645,6.07878857566124E-6,0.25,-1.59764809547618E-6,1.18614558466941E-5,-1.50973301648356E-6,19.9984322,19.9984322,37374.24609375,37384.296875,56.8830154870253,20.5453175118213,14.936333,0,0,0,40,4449,20.0347,37379.271484375,,,,,,,,,,,,,0,,,,0.0049,,,,,,19.9984322,,,,
,22196407.54,19.9971943,32714.5166015625,2.44698729554583E-5,4.24312721964422E-7,1,0.999253354069792,40.0298881530762,1.99795463352745,17.1900000423193,0.000277952965635271,3.72140901173027E-5,0.25,-1.09492173226932E-6,2.44064870548376E-5,-9.22972415794842E-7,19.9971943,19.9971943,32706.9921875,32722.041015625,56.7079306987175,20.5438865011783,14.936333,0,0,0,40,4449,20.03695,32714.5166015625,,,,,,,,,,,,,0,,,,-0.00245,,,,,,19.9971943,,,,
,22196502.22,19.9979248,27981.921875,3.45578054030021E-5,4.61258760445618E-7,1,0.999253354069792,40.0298881530762,1.99800535801052,17.1900000423193,0.000392444422918193,5.20124313918571E-5,0.25,-1.58468876048059E-6,3.44510579914824E-5,-1.3486504820733E-6,19.9979248,19.9979248,27974.48046875,27989.36328125,56.6102271338137,20.5501244565823,14.936333,0,0,0,40,4449,20.0374,27981.921875,,,,,,,,,,,,,0,,,,-0.00245,,,,,,19.9979248,,,,
,22196599.545,19.9978275,23117.017578125,4.43967227049342E-5,4.2457046637977E-7,1,0.999253354069792,40.0298881530762,1.99791598912014,17.1900000423193,0.00050149538191326,8.01840354530491E-5,0.25,-8.33677431574191E-7,4.42292609751296E-5,-5.4606326411537E-7,19.9978275,19.9978275,23111.900390625,23122.134765625,56.719655126506,20.5477774672838,15.315984,0,0,0,40,4449,20.0413,23117.017578125,,,,,,,,,,,,,0,,,,0,,,,,,19.9978275,,,,
,22196696.345,19.999383,18281.9755859375,5.59489624859706E-5,3.18506864163324E-7,1,0.999253354069792,40.0298881530762,1.997929388048,17.1900000423193,0.000631189431384235,0.000103776216808914,0.25,-7.86958780594645E-7,5.57095324312074E-5,-4.42210012936554E-7,19.9991055,19.9996605,18274.353515625,18289.59765625,56.5547315089483,20.5469032586951,14.936333,0,0,0,40,4449,20.0402,18281.9755859375,,,,,,,,,,,,,0,,,,-0.00245,,,,,,19.999383,,,,
,22196790.695,20.0019417,13567.6123046875,6.49504313741117E-5,3.41448926685755E-7,1,0.999253354069792,40.0298881530762,1.99780750241478,17.1900000423193,0.000731298349366789,0.000126439179488116,0.25,-3.56676253707232E-7,6.4640914706474E-5,2.0091965845452E-8,20.0019417,20.0019417,13562.8701171875,13572.3544921875,56.8728543162753,20.5492759624283,14.556682,0,0,0,40,4449,20.0385,13567.6123046875,,,,,,,,,,,,,0,,,,0.00245,,,,,,20.0019417,,,,
,22196885.9,20.0027332,8809.140625,7.40599547784073E-5,3.38565822239743E-7,1,0.999253354069792,40.0298881530762,1.99798240701272,17.1900000423193,0.000834408373164847,0.000139590186293065,0.25,-7.84511551237015E-7,7.36795898965434E-5,-3.78422712522262E-7,20.0027332,20.0027332,8799.078125,8819.203125,56.7454488676406,20.5499367368768,14.556682,0,0,0,40,4449,20.0375,8809.140625,,,,,,,,,,,,,0,,,,0,,,,,,20.0027332,,,,
,22196981.29,20.0057144,4039.26721191406,8.2658851178307E-5,2.60946516568501E-7,1,0.999253354069792,40.0298881530762,1.99791854157341,17.1900000423193,0.000929794171571312,0.000162152340192715,0.25,-2.76671782627943E-7,8.22026411091162E-5,1.45174053946303E-7,20.0057144,20.0057144,4036.72119140625,4041.81323242188,56.8869236296214,20.5495116109763,14.556682,0,0,0,40,4449,20.0314,4039.26721191406,,,,,,,,,,,,,0,,,,-0.00245,,,,,,20.0057144,,,,
,22197073.9,19.9939728,-588.746337890625,7.47521339118162E-5,3.44374919403449E-7,1,0.999253354069792,40.0298881530762,1.99793047480454,17.1900000423193,0.000840577744768664,0.00014727560114868,0.25,-1.75306488527181E-7,7.43247426087383E-5,1.89797718061424E-7,19.9939728,19.9939728,-601.4853515625,-576.00732421875,56.9056827140829,20.5503270958241,14.936333,0,0,0,40,4449,20.02865,-588.746337890625,,,,,,,,,,,,,0,,,,0.00245,,,,,,19.9939728,,,,
,22197167.885,20.0017071,-5283.4677734375,7.48184819316693E-5,2.74433733500874E-7,1,0.999253354069792,40.0298881530762,1.99799751092913,17.1900000423193,0.00084105995302723,0.000150407171635515,0.25,6.48044216697527E-8,7.44101293341171E-5,4.51410937005329E-7,20.0017071,20.0017071,-5295.99267578125,-5270.94287109375,56.8736359447945,20.5498163507882,15.315984,0,0,0,40,4449,20.02595,-5283.4677734375,,,,,,,,,,,,,0,,,,0.0049,,,,,,20.0017071,,,,
,22197264.405,19.9967308,-10109.2783203125,7.67731250696636E-5,3.02740082336253E-7,1,0.999253354069792,40.0298881530762,1.99809422584404,17.1900000423193,0.000862604801578422,0.000158801763880954,0.25,4.30852964172563E-7,7.63799812399825E-5,8.52719533261177E-7,19.9967308,19.9967308,-10114.40234375,-10104.154296875,56.7782772654483,20.5488588420244,14.936333,0,0,0,40,4449,20.0325,-10109.2783203125,,,,,,,,,,,,,0,,,,0,,,,,,19.9967308,,,,
,22197360.445,19.997221,-14907.13671875,6.98335390520256E-5,3.89370227517339E-7,1,0.999253354069792,40.0298881530762,1.99803379017115,17.1900000423193,0.000784212392603456,0.000148550444671389,0.25,7.27538685425983E-7,6.95025866422848E-5,1.1340151110582E-6,19.997221,19.997221,-14912.220703125,-14902.052734375,56.7431039820829,20.5509651507882,14.936333,0,0,0,40,4449,20.0335,-14907.13671875,,,,,,,,,,,,,0,,,,0,,,,,,19.997221,,,,
,22197456.595,19.9963608,-19714.0712890625,4.95416327833926E-5,3.1169568312946E-7,1,0.999253354069792,40.0298881530762,1.99803644885646,17.1900000423193,0.000555820649775273,0.000109737613662509,0.25,8.82563032734604E-7,4.93267088638351E-5,1.18570173625958E-6,19.9963608,19.9963608,-19718.9765625,-19709.166015625,57.1472059265253,20.5537294442798,14.556682,0,0,0,40,4449,20.03885,-19714.0712890625,,,,,,,,,,,,,0,,,,0.0049,,,,,,19.9963608,,,,
,22197551.67,19.9978123,-24463.8876953125,2.36424449020445E-5,4.19552960778276E-7,1,0.999253354069792,40.0298881530762,1.99799366105273,17.1900000423193,0.000265258874180619,5.30136321411865E-5,0.25,4.69500862771993E-7,2.35505916210002E-5,6.21027760619076E-7,19.9978123,19.9978123,-24471.41015625,-24456.365234375,57.1112510146407,20.5516740400713,14.936333,0,0,0,40,4449,20.03915,-24463.8876953125,,,,,,,,,,,,,0,,,,-0.00245,,,,,,19.9978123,,,,
,22197646.94,19.9990234,-29226.21484375,5.15303436112513E-6,3.33103737467182E-7,1,0.999253354069792,40.0298881530762,1.99785044359132,17.1900000423193,5.82188315306174E-5,9.44596851797817E-6,0.25,-8.66033311702398E-8,5.13679088272481E-6,-5.16046526153492E-8,19.9990234,19.9990234,-29238.646484375,-29213.783203125,57.0033862789868,20.5530770059409,14.936333,0,0,0,40,4449,20.03895,-29226.21484375,,,,,,,,,,,,,0,,,,0.00245,,,,,,19.9990234,,,,
,22197744.375,20.0006924,-34096.0234375,-1.4557815744368E-6,3.48956089526296E-7,1,0.999253354069792,40.0298881530762,1.99800838713214,17.1900000423193,-1.81490541330638E-5,6.74142763246869E-6,0.25,8.59865246884129E-7,-1.45775403029011E-6,8.47373501924889E-7,20.0006924,20.0006924,-34101.44921875,-34090.59765625,57.1636201254291,20.5519337404441,14.936333,0,0,0,40,4449,20.0396,-34096.0234375,,,,,,,,,,,,,0,,,,0,,,,,,20.0006924,,,,
,22197838.57,20.0000305,-38803.103515625,5.63438775365368E-7,3.91625933155013E-7,1,0.999253354069792,40.0298881530762,1.99790629764867,17.1900000423193,5.49483223638269E-6,5.91092810235249E-6,0.25,4.22867714395401E-7,5.59155569448238E-7,4.25928751712312E-7,20.0000305,20.0000305,-38807.984375,-38798.22265625,56.8454973181022,20.5518667094029,14.936333,0,0,0,40,4449,20.03935,-38803.103515625,,,,,,,,,,,,,0,,,,0,,,,,,20.0000305,,,,
,22197933.785,20.0013447,-43562.4765625,8.10610578547276E-6,4.36520018841981E-7,1,0.999253354069792,40.0298881530762,1.99786350765718,17.1900000423193,9.09956650102802E-5,1.89218442659756E-5,0.25,2.17758392779781E-7,8.0903078055862E-6,2.76205944220443E-7,20.0013447,20.0013447,-43569.7578125,-43555.1953125,56.8533136032945,20.5550012699,15.315984,0,0,0,40,4449,20.0387,-43562.4765625,,,,,,,,,,,,,0,,,,-0.00245,,,,,,20.0013447,,,,
,22198028.53,20.0010567,-48297.666015625,1.70401504135338E-5,4.9004929989762E-7,1,0.999253354069792,40.0298881530762,1.99791366818906,17.1900000423193,0.000192175180781091,3.54025588664484E-5,0.25,6.68524312427753E-8,1.70181161058528E-5,1.92044845676128E-7,20.0010567,20.0010567,-48307.796875,-48287.53515625,56.7235632691022,20.5534724223673,14.936333,0,0,0,40,4449,20.03655,-48297.666015625,,,,,,,,,,,,,0,,,,0,,,,,,20.0010567,,,,
,22198122.21,19.9995365,-52979.908203125,2.73679418031112E-5,4.5641993889748E-7,1,0.999253354069792,40.0298881530762,1.9979640632171,17.1900000423193,0.000307049986761474,6.66153410479344E-5,0.25,9.67353047133502E-7,2.73390871453508E-5,1.16941544682276E-6,19.9995365,19.9995365,-52984.75,-52975.06640625,57.007294421583,20.5542303029722,14.936333,0,0,0,40,4449,20.03625,-52979.908203125,,,,,,,,,,,,,0,,,,-0.00245,,,,,,19.9995365,,,,
,22198215.37,19.9998646,-57632.296875,3.90647399282861E-5,5.03802592833945E-7,1,0.999253354069792,40.0298881530762,1.99788680895346,17.1900000423193,0.000438078649020024,9.72561219632743E-5,0.25,1.5684130010695E-6,3.90398337620558E-5,1.85850754775604E-6,19.9998646,19.9998646,-57636.9453125,-57627.6484375,56.9744660237753,20.5541153956658,14.556682,0,0,0,40,4449,20.03745,-57632.296875,,,,,,,,,,,,,0,,,,-0.0049,,,,,,19.9998646,,,,
,22198316.845,20.002161,-62707.21875,5.31423772397237E-5,6.01653687820555E-7,1,0.999253354069792,40.0298881530762,1.99793783939042,17.1900000423193,0.000596008018278886,0.000133685366465703,0.25,2.25018551232767E-6,5.31328404555443E-5,2.6458528773732E-6,20.002161,20.002161,-62719.72265625,-62694.71484375,56.8791073444291,20.5545323691037,14.556682,0,0,0,40,4449,20.0362,-62707.21875,,,,,,,,,,,,,0,,,,0,,,,,,20.002161,,,,
,22198413.695,20.0020523,-67546.8671875,6.57773325460495E-5,4.69258221249274E-7,1,0.999253354069792,40.0298881530762,1.99796388878411,17.1900000423193,0.000739387420047265,0.000158070738613983,0.25,2.12620115785961E-6,6.57988321354358E-5,2.61504507981689E-6,20.0020523,20.0020523,-67551.859375,-67541.875,56.8642564025637,20.554255910105,14.936333,0,0,0,40,4449,20.0344,-67546.8671875,,,,,,,,,,,,,0,,,,0,,,,,,20.0020523,,,,
,22198508.35,20.0019951,-72278.78125,7.8325295959532E-5,5.36117045976449E-7,1,0.999253354069792,40.0298881530762,1.99804486064547,17.1900000423193,0.000883352048638939,0.000174271571239155,0.25,1.29485511251144E-6,7.8391455975954E-5,1.87309532229304E-6,20.0019951,20.0019951,-72284,-72273.5625,57.0565370182945,20.5553950608024,15.315984,0,0,0,40,4449,20.03305,-72278.78125,,,,,,,,,,,,,0,,,,-0.0049,,,,,,20.0019951,,,,
,22198605.115,20.0026436,-77113.1875,9.10853578038964E-5,4.0120638217248E-7,1,0.999253354069792,40.0298881530762,1.99788313845189,17.1900000423193,0.00102763912175099,0.000202383847429822,0.25,1.48194661029332E-6,9.11977591947913E-5,2.14889184117466E-6,20.0026436,20.0026436,-77120.8828125,-77105.4921875,57.0080760501022,20.5566486157713,14.936333,0,0,0,40,4449,20.0322,-77113.1875,,,,,,,,,,,,,0,,,,0,,,,,,20.0026436,,,,
,22198702.305,20.00240325,-81970.46875,0.000104405044108575,5.39214743153857E-7,1,0.999253354069792,40.0298881530762,1.99796034390243,17.1900000423193,0.00117803173877751,0.000234052184113799,0.25,1.88240755819121E-6,0.000104570847846864,2.63922073752788E-6,20.0023346,20.0024719,-81978.0546875,-81962.8828125,57.2011382943522,20.5560684262324,14.936333,0,0,0,40,4449,20.0312,-81970.46875,,,,,,,,,,,,,0,,,,0,,,,,,20.00240325,,,,
,22198796.53,20.0025196,-86677.50390625,0.000117630184558263,6.58028467063129E-7,1,0.999253354069792,40.0298881530762,1.99792895103088,17.1900000423193,0.00132706814392332,0.000267168226225141,0.25,2.43082467753282E-6,0.000117854112936144,3.27401418375818E-6,20.0025196,20.0025196,-86685.0078125,-86670,57.1237570709483,20.5558583631124,14.936333,0,0,0,40,4449,20.0314,-86677.50390625,,,,,,,,,,,,,0,,,,-0.0049,,,,,,20.0025196,,,,
,22198908.535,20.0005131,-88797.25,0.000124593764871435,6.86223599502165E-7,1,0.999253354069792,40.0298881530762,1.99780375625639,17.1900000423193,0.001405932489242,0.00028197478836661,0.25,2.48919136170086E-6,0.000124849497826119,3.37689917958092E-6,20.0005131,20.0005131,-88802.171875,-88792.328125,56.8204852054868,20.5564489668945,15.315984,0,0,0,40,4449,20.02955,-88797.25,,,,,,,,,,,,,0,,,,-0.00245,,,,,,20.0005131,,,,
,22198999.655,20.0003529,-84243.36328125,0.00011211395566664,6.12591073321243E-7,1,0.999253354069792,40.0298881530762,1.99799358610827,17.1900000423193,0.00126472657430274,0.00025423432702719,0.25,2.2785561311847E-6,0.000112308547471076,3.08723071801858E-6,20.0003529,20.0003529,-84250.828125,-84235.8984375,56.9619599674676,20.5510450701621,14.556682,0,0,0,40,4449,20.03065,-84243.36328125,,,,,,,,,,,,,0,,,,-0.00245,,,,,,20.0003529,,,,
,22199096.91,19.9997997,-79383.5390625,9.75724568917847E-5,5.36589573342536E-7,1,0.999253354069792,40.0298881530762,1.99784410914856,17.1900000423193,0.00110213219617139,0.000210533764569345,0.25,1.03473647638098E-6,9.77138781281327E-5,1.74503084854878E-6,19.9997997,19.9997997,-79388.609375,-79378.46875,56.8572217458906,20.5531086074251,14.936333,0,0,0,40,4449,20.0304,-79383.5390625,,,,,,,,,,,,,0,,,,0,,,,,,19.9997997,,,,
,22199194.51,19.999094,-74506.5390625,8.39821156999662E-5,5.8295460805252E-7,1,0.999253354069792,40.0298881530762,1.99784629070102,17.1900000423193,0.000947213573063758,0.000186971405310267,0.25,1.39948947882153E-6,8.40681983847233E-5,2.01736504637675E-6,19.999012,19.999176,-74511.6015625,-74501.4765625,56.7118388413137,20.5546095263126,15.315984,0,0,0,40,4449,20.02975,-74506.5390625,,,,,,,,,,,,,0,,,,0,,,,,,19.999094,,,,
,22199291.38,19.9980335,-69667.14453125,7.08949553479201E-5,4.12825209513194E-7,1,0.999253354069792,40.0298881530762,1.99794017612146,17.1900000423193,0.000799107800289875,0.000158976236469982,0.25,1.28302214035878E-6,7.0938522238241E-5,1.80824169835023E-6,19.9980335,19.9980335,-69669.9609375,-69664.328125,57.0745144742368,20.5548960787488,14.936333,0,0,0,40,4449,20.0311,-69667.14453125,,,,,,,,,,,,,0,,,,-0.0049,,,,,,19.9980335,,,,
,22199388.725,19.9983902,-64800.158203125,5.67562208901472E-5,4.94227523059271E-7,1,0.999253354069792,40.0298881530762,1.99789792923328,17.1900000423193,0.000638557383184919,0.000132199971305657,0.25,1.46593639284821E-6,5.67637473457631E-5,1.88818370225412E-6,19.9983902,19.9983902,-64807.70703125,-64792.609375,56.9643048530253,20.5539337486874,14.936333,0,0,0,40,4449,20.03125,-64800.158203125,,,,,,,,,,,,,0,,,,0,,,,,,19.9983902,,,,
,22199484.295,19.9979362,-60022.7734375,4.46358241178208E-5,5.5030317910517E-7,1,0.999253354069792,40.0298881530762,1.99792149507019,17.1900000423193,0.000500991210227351,0.000109400250778827,0.25,1.63686674588861E-6,4.46186130149957E-5,1.96892519496567E-6,19.9979362,19.9979362,-60025.27734375,-60020.26953125,57.1784710672945,20.553749717281,15.315984,0,0,0,40,4449,20.03575,-60022.7734375,,,,,,,,,,,,,0,,,,0,,,,,,19.9979362,,,,
,22199581.205,19.9980717,-55180.484375,3.12241122238016E-5,4.69180900010047E-7,1,0.999253354069792,40.0298881530762,1.99784693497624,17.1900000423193,0.000350750144970095,7.39035231619942E-5,0.25,9.16315484644034E-7,3.11993265528714E-5,1.14772750273331E-6,19.9980717,19.9980717,-55182.90625,-55178.0625,56.8666012881214,20.5528573253233,14.936333,0,0,0,40,4449,20.03475,-55180.484375,,,,,,,,,,,,,0,,,,0,,,,,,19.9980717,,,,
,22199677.695,20.0005665,-50358.6015625,1.98748412495207E-5,4.47465387186246E-7,1,0.999253354069792,40.0298881530762,1.99789982895506,17.1900000423193,0.000222666593537276,4.97531173125396E-5,0.25,8.26238007183103E-7,1.98477778336205E-5,9.72082111449897E-7,20.0005665,20.0005665,-50366.03515625,-50351.16796875,56.9377294833714,20.552628137091,14.936333,0,0,0,40,4449,20.0367,-50358.6015625,,,,,,,,,,,,,0,,,,-0.00245,,,,,,20.0005665,,,,
,22199772.27,20.0000153,-45634.27734375,7.12357515366494E-6,4.39432043616437E-7,1,0.999253354069792,40.0298881530762,1.99781595313783,17.1900000423193,7.94579661419572E-5,1.95385963675879E-5,0.25,4.48714522757217E-7,7.10933931596913E-6,5.00049088708219E-7,20.0000153,20.0000153,-45644.22265625,-45624.33203125,56.790783321756,20.5531557829777,15.315984,0,0,0,40,4449,20.037,-45634.27734375,,,,,,,,,,,,,0,,,,-0.0049,,,,,,20.0000153,,,,
,22199865.405,19.9998703,-40979.080078125,-4.14315690509384E-6,4.12304358098688E-7,1,0.999253354069792,40.0298881530762,1.99795162538244,17.1900000423193,-4.79689532267068E-5,-1.50115762271247E-6,0.25,6.1268206470071E-7,-4.13917238511199E-6,5.81650860641003E-7,19.9998703,19.9998703,-40981.70703125,-40976.453125,56.5007991411214,20.5488675317856,14.936333,0,0,0,40,4449,20.0362,-40979.080078125,,,,,,,,,,,,,0,,,,0,,,,,,19.9998703,,,,
,22199962.375,19.999897,-36132.201171875,-1.57753309621097E-5,3.74387662364854E-7,1,0.999253354069792,40.0298881530762,1.99785731218344,17.1900000423193,-0.000178906216328941,-2.59087667992889E-5,0.25,5.38568138199944E-7,-1.57390905373313E-5,4.26251017207601E-7,19.999815,19.999979,-36134.50390625,-36129.8984375,57.088583787583,20.5478076347414,14.936333,0,0,0,40,4449,20.0364,-36132.201171875,,,,,,,,,,,,,0,,,,0.00245,,,,,,19.999897,,,,
,22200058.645,19.9984512,-31322.650390625,-2.7018782399051E-5,3.97118164252182E-7,1,0.999253354069792,40.0298881530762,1.99794033273409,17.1900000423193,-0.000303766118940229,-5.82938187905928E-5,0.25,-3.20145824173101E-7,-2.69343032417618E-5,-5.03868703990197E-7,19.9984512,19.9984512,-31327.658203125,-31317.642578125,56.7352876968906,20.5458802053882,14.556682,0,0,0,40,4449,20.03725,-31322.650390625,,,,,,,,,,,,,0,,,,-0.00245,,,,,,19.9984512,,,,
,22200157.225,19.99883935,-26395.033203125,-3.82644217489183E-5,4.06401784106204E-7,1,0.999253354069792,40.0298881530762,1.99796026371178,17.1900000423193,-0.0004299276812973,-8.28147320799698E-5,0.25,-4.89278754328001E-7,-3.81250131551145E-5,-7.39741170036423E-7,19.9987316,19.9989471,-26405.162109375,-26384.904296875,56.7524835243137,20.5501711363642,15.695635,0,0,0,40,4449,20.0384,-26395.033203125,,,,,,,,,,,,,0,,,,-0.00245,,,,,,19.99883935,,,,
,22200254.135,19.9978638,-21550.3447265625,-4.78682290858756E-5,3.38198962785742E-7,1,0.999253354069792,40.0298881530762,1.99804403506184,17.1900000423193,-0.000538028820542214,-0.000101112534830836,0.25,-4.08587762239827E-7,-4.76718688446936E-5,-7.0899266755305E-7,19.9978638,19.9978638,-21552.595703125,-21548.09375,56.946327397083,20.5482137037201,14.556682,0,0,0,40,4449,20.041,-21550.3447265625,,,,,,,,,,,,,0,,,,0,,,,,,19.9978638,,,,
,22200350.825,20.0017986,-16718.359375,-5.79290595056366E-5,3.37240695657643E-7,1,0.999253354069792,40.0298881530762,1.99781102765809,17.1900000423193,-0.000652182919804455,-0.000114196001903469,0.25,2.0708071585628E-7,-5.76689126932764E-5,-1.41139659326123E-7,20.0017986,20.0017986,-16730.5078125,-16706.2109375,57.2050464369484,20.5487469832863,14.936333,0,0,0,40,4449,20.03755,-16718.359375,,,,,,,,,,,,,0,,,,0,,,,,,20.0017986,,,,
,22200443.75,20.0025654,-12075.9541015625,-6.77410260159512E-5,3.14937796331392E-7,1,0.999253354069792,40.0298881530762,1.99779649759174,17.1900000423193,-0.000760950789394345,-0.000141178086446385,0.25,-4.6432110074738E-7,-6.74046856225487E-5,-8.45926363857017E-7,20.0025654,20.0025654,-12083.455078125,-12068.453125,56.9830639374868,20.5501482465884,14.936333,0,0,0,40,4449,20.03525,-12075.9541015625,,,,,,,,,,,,,0,,,,0,,,,,,20.0025654,,,,
,22200540.19,20.0040646,-7255.29638671875,-7.65349519935845E-5,3.01002484989029E-7,1,0.999253354069792,40.0298881530762,1.99787130658319,17.1900000423193,-0.000859720657521478,-0.000157833038351421,0.25,-4.07815595128028E-7,-7.61262244279551E-5,-8.12386098062757E-7,20.0040646,20.0040646,-7260.3134765625,-7250.279296875,56.7368509539291,20.5477776825074,14.556682,0,0,0,40,4449,20.0338,-7255.29638671875,,,,,,,,,,,,,0,,,,0,,,,,,20.0040646,,,,
,22200637.705,20.0056076,-2376.75463867187,-8.37508980727996E-5,2.85423686197482E-7,1,0.999253354069792,40.0298881530762,1.99781357007011,17.1900000423193,-0.000940199228957356,-0.000174029341198016,0.25,-5.97242731483693E-7,-8.3275763393142E-5,-1.01046911443905E-6,20.0056076,20.0056076,-2386.865234375,-2366.64404296875,56.9080275996406,20.548084354052,14.936333,0,0,0,40,4449,20.0238,-2376.75463867187,,,,,,,,,,,,,0,,,,0,,,,,,20.0056076,,,,
,22200733.225,20.0030575,2391.48828125,-7.12969626311645E-5,3.53828459729524E-7,1,0.999253354069792,40.0298881530762,1.99769103177494,17.1900000423193,-0.000800236050343521,-0.000148746550334768,0.25,-5.62127624958547E-7,-7.08922748278325E-5,-9.13671175965824E-7,20.0030575,20.0030575,2381.794921875,2401.181640625,56.9846271945253,20.5483811909878,14.936333,0,0,0,40,4449,20.02395,2391.48828125,,,,,,,,,,,,,0,,,,0,,,,,,20.0030575,,,,
,22200826.4,19.99823,7048.21166992188,-7.4805321463576E-5,2.8962146470683E-7,1,0.999253354069792,40.0298881530762,1.99766340422495,17.1900000423193,-0.000838983693281445,-0.0001610517697081,0.25,-1.00488417374408E-6,-7.44014698070819E-5,-1.39593858076027E-6,19.99823,19.99823,7045.95166015625,7050.4716796875,56.8454973181022,20.5487804587605,14.936333,0,0,0,40,4449,20.028,7048.21166992188,,,,,,,,,,,,,0,,,,0.00245,,,,,,19.99823,,,,
,22200922.375,19.9972935,11846.33984375,-7.44425945133077E-5,2.95431934772707E-7,1,0.999253354069792,40.0298881530762,1.99785693780518,17.1900000423193,-0.000834600950941405,-0.000164325342986198,0.25,-1.32763585123572E-6,-7.40669137213797E-5,-1.74169437311464E-6,19.9972935,19.9972935,11833.580078125,11859.099609375,57.0721695886791,20.5487919661566,15.315984,0,0,0,40,4449,20.0305,11846.33984375,,,,,,,,,,,,,0,,,,-0.00245,,,,,,19.9972935,,,,
,22201015.56,19.9962692,16504.0146484375,-6.31591499325526E-5,3.5436035747055E-7,1,0.999253354069792,40.0298881530762,1.99778843804592,17.1900000423193,-0.00070878882203189,-0.000137110726746967,0.25,-8.95825170590612E-7,-6.28675443212189E-5,-1.26947350628151E-6,19.9962692,19.9962692,16496.69140625,16511.337890625,56.9314764552176,20.5474472165865,14.936333,0,0,0,40,4449,20.0317,16504.0146484375,,,,,,,,,,,,,0,,,,0.00245,,,,,,19.9962692,,,,
,22201112.025,19.9966774,21323.486328125,-3.94549460755878E-5,3.00520890515512E-7,1,0.999253354069792,40.0298881530762,1.99772206321488,17.1900000423193,-0.000441443303273874,-9.4179822426024E-5,0.25,-1.30164746789167E-6,-3.92861402822354E-5,-1.54476054432197E-6,19.9966774,19.9966774,21313.513671875,21333.458984375,56.6594697305252,20.5467714568432,14.936333,0,0,0,40,4449,20.03525,21323.486328125,,,,,,,,,,,,,0,,,,0,,,,,,19.9966774,,,,
,22201206.88,19.9971886,26066.3349609375,-1.47209090758184E-5,3.99852410153698E-7,1,0.999253354069792,40.0298881530762,1.99772325893595,17.1900000423193,-0.000163100535594839,-4.453764119218E-5,0.25,-1.31481024013618E-6,-1.46593770228516E-5,-1.4068502545268E-6,19.9971886,19.9971886,26056.353515625,26076.31640625,56.7345060683714,20.5451776166422,14.936333,0,0,0,40,4449,20.03685,26066.3349609375,,,,,,,,,,,,,0,,,,-0.00245,,,,,,19.9971886,,,,
,22201302.025,19.9996738,30821.595703125,1.18272052530017E-7,3.78922549309276E-7,1,0.999253354069792,40.0298881530762,1.99778591744273,17.1900000423193,2.89071103071014E-6,-8.43625640467845E-6,0.25,-7.70110262427897E-7,1.23152339362051E-7,-7.66918391507927E-7,19.9996738,19.9996738,30813.982421875,30829.208984375,56.5695824508137,20.5478777666804,14.556682,0,0,0,40,4449,20.0368,30821.595703125,,,,,,,,,,,,,0,,,,-0.0049,,,,,,19.9996738,,,,
,22201398.77,20.0009613,35656.94921875,2.78409209396876E-6,2.80654011759139E-7,1,0.999253354069792,40.0298881530762,1.99773356378708,17.1900000423193,3.49671756373292E-5,-1.43159404841985E-5,0.25,-1.77087594798E-6,2.78931111167483E-6,-1.7467614960507E-6,20.0009613,20.0009613,35646.953125,35666.9453125,56.6579064734868,20.5431116462832,15.315984,0,0,0,40,4449,20.0348,35656.94921875,,,,,,,,,,,,,0,,,,-0.0049,,,,,,20.0009613,,,,
,22201492.915,20.0012798,40364.341796875,-1.30233175601004E-6,3.58524757940215E-7,1,0.999253354069792,40.0298881530762,1.99776072473362,17.1900000423193,-1.20378042537805E-5,-1.73509237159794E-5,0.25,-1.30435135887466E-6,-1.29025451810215E-6,-1.31096670736552E-6,20.0012798,20.0012798,40359.21875,40369.46484375,57.0166739638137,20.5456968209982,14.556682,0,0,0,40,4449,20.036,40364.341796875,,,,,,,,,,,,,0,,,,0,,,,,,20.0012798,,,,
,22201588.415,20.000946,45137.1875,-8.32069254469753E-6,4.73227224156736E-7,1,0.999253354069792,40.0298881530762,1.99776995716536,17.1900000423193,-9.04584480774039E-5,-3.58439467866566E-5,0.25,-1.67862989782061E-6,-8.29522062464011E-6,-1.73664236528049E-6,20.000946,20.000946,45132.2109375,45142.1640625,56.8048526351022,20.5432955520187,14.556682,0,0,0,40,4449,20.0327,45137.1875,,,,,,,,,,,,,0,,,,0.00245,,,,,,20.000946,,,,
,22201683.225,19.9998207,49874.908203125,-1.88444328023632E-5,5.56364274332513E-7,1,0.999253354069792,40.0298881530762,1.99796461237096,17.1900000423193,-0.000208614038671634,-6.10729753109288E-5,0.25,-2.01494754625598E-6,-1.88087718285679E-5,-2.15171030766165E-6,19.9998207,19.9998207,49869.87890625,49879.9375,57.1120326431599,20.5454878172895,15.315984,0,0,0,40,4449,20.03395,49874.908203125,,,,,,,,,,,,,0,,,,-0.0049,,,,,,19.9998207,,,,
,22201778.76,20.0000572,54649.40625,-3.05076121078997E-5,3.4005062847231E-7,1,0.999253354069792,40.0298881530762,1.9978681985106,17.1900000423193,-0.000340912564250702,-8.20505824627807E-5,0.25,-1.76727885424786E-6,-3.04753393214231E-5,-1.99267977660816E-6,20.0000572,20.0000572,54636.59375,54662.21875,56.780622151006,20.5448610995091,14.936333,0,0,0,40,4449,20.03465,54649.40625,,,,,,,,,,,,,0,,,,0,,,,,,20.0000572,,,,
,22201875.89,19.999361,59504.921875,-4.31966451925928E-5,5.89507196853989E-7,1,0.999253354069792,40.0298881530762,1.99785046086706,17.1900000423193,-0.000484158858193824,-0.000109409310155365,0.25,-1.89787839671147E-6,-4.31755538359403E-5,-2.2190924670696E-6,19.999361,19.999361,59495.125,59514.71875,57.2120810936214,20.5435037366912,14.936333,0,0,0,40,4449,20.03525,59504.921875,,,,,,,,,,,,,0,,,,-0.00245,,,,,,19.999361,,,,
,22201974.19,20.000515,64417.89453125,-5.58336139355263E-5,6.12348822014674E-7,1,0.999253354069792,40.0298881530762,1.99800378181402,17.1900000423193,-0.00062716216215396,-0.000135741937283748,0.25,-1.94526023782417E-6,-5.58353664110236E-5,-2.36084516959339E-6,20.000515,20.000515,64412.875,64422.9140625,56.9009929429675,20.5428545269232,14.936333,0,0,0,40,4449,20.0359,64417.89453125,,,,,,,,,,,,,0,,,,-0.00245,,,,,,20.000515,,,,
,22202071.195,20.0016308,69265.50390625,-6.88680979489039E-5,5.63172887135608E-7,1,0.999253354069792,40.0298881530762,1.99789135631586,17.1900000423193,-0.000774019130750251,-0.000166619316671619,0.25,-2.32468427696372E-6,-6.8900086111522E-5,-2.83587979312196E-6,20.0016308,20.0016308,69260.96875,69270.0390625,56.6211699330829,20.544314653669,15.315984,0,0,0,40,4449,20.03285,69265.50390625,,,,,,,,,,,,,0,,,,-0.0049,,,,,,20.0016308,,,,
,22202165.185,20.0009956,73965.87890625,-8.23835807136235E-5,5.51453789842557E-7,1,0.999253354069792,40.0298881530762,1.99792600686757,17.1900000423193,-0.000927243355625329,-0.000194157125145343,0.25,-2.32210074845607E-6,-8.24574631462283E-5,-2.92980127046526E-6,20.0009212,20.00107,73958.75,73973.0078125,56.6117903908521,20.5401856029841,14.936333,0,0,0,40,4449,20.0311,73965.87890625,,,,,,,,,,,,,0,,,,-0.0049,,,,,,20.0009956,,,,
,22202258.1,20.0014935,78606.38671875,-9.4123154791294E-5,4.79685712014857E-7,1,0.999253354069792,40.0298881530762,1.99789300723116,17.1900000423193,-0.00106127567700973,-0.000213397337947981,0.25,-1.90824383701571E-6,-9.42473992538872E-5,-2.59592288866909E-6,20.0014935,20.0014935,78601.40625,78611.3671875,56.5805252500829,20.5390141659674,14.936333,0,0,0,40,4449,20.0301,78606.38671875,,,,,,,,,,,,,0,,,,-0.00245,,,,,,20.0014935,,,,
,22202355.735,20.0012474,83487.30859375,-0.000107768621927473,5.12546647678074E-7,1,0.999253354069792,40.0298881530762,1.99783493628895,17.1900000423193,-0.00121374239526114,-0.000254395124610789,0.25,-3.07604530095068E-6,-0.000107943476658114,-3.8564555519544E-6,20.0012474,20.0012474,83479.703125,83494.9140625,56.8142321773329,20.5405326014868,14.936333,0,0,0,40,4449,20.03,83487.30859375,,,,,,,,,,,,,0,,,,-0.00245,,,,,,20.0012474,,,,
,22202445.65,20.0016766,87982.89453125,-0.000121505644165236,6.24543011845142E-7,1,0.999253354069792,40.0298881530762,1.99783660191806,17.1900000423193,-0.00136959410971154,-0.000282970823526298,0.25,-3.13139118632197E-6,-0.000121743377564887,-4.00058785083278E-6,20.0016766,20.0016766,87978.125,87987.6640625,57.0526288756983,20.5414785440377,14.936333,0,0,0,40,4449,20.02645,87982.89453125,,,,,,,,,,,,,0,,,,-0.0049,,,,,,20.0016766,,,,
,22202552.1,20.0015469,87693.4453125,-0.000121385419052955,4.11667622184109E-7,1,0.999253354069792,40.0298881530762,1.99807381605,17.1900000423193,-0.00136846684938017,-0.00028216330036195,0.25,-3.07861413266433E-6,-0.000121620882429136,-3.94752824032528E-6,20.0015469,20.0015469,87688.2734375,87698.6171875,56.8322096332752,20.5419887902517,15.315984,0,0,0,40,4449,20.026,87693.4453125,,,,,,,,,,,,,0,,,,-0.00245,,,,,,20.0015469,,,,
,22202643.03,20.00042915,83147.51953125,-0.000107823014337978,5.40520214574648E-7,1,0.999253354069792,40.0298881530762,1.99782468525231,17.1900000423193,-0.00121555446099154,-0.000247653679311476,0.25,-2.47067934322706E-6,-0.000107999678960015,-3.25101355304225E-6,20.0002289,20.0006294,83140.0859375,83154.953125,56.5742722219291,20.5416285103319,14.936333,0,0,0,40,4449,20.027,83147.51953125,,,,,,,,,,,,,0,,,,0,,,,,,20.00042915,,,,
,22202738.83,20.0000725,78360.87109375,-9.45938655582898E-5,4.56100538284701E-7,1,0.999253354069792,40.0298881530762,1.99789398797995,17.1900000423193,-0.00106474055987047,-0.000224584659201505,0.25,-2.81202208193029E-6,-9.47104416113143E-5,-3.50477937611917E-6,20.0000725,20.0000725,78350.8984375,78370.84375,56.6055373626983,20.5440873964544,14.936333,0,0,0,40,4449,20.02795,78360.87109375,,,,,,,,,,,,,0,,,,0.00245,,,,,,20.0000725,,,,
,22202832.33,20.0000477,73687.16796875,-8.02769118642504E-5,6.89860684681607E-7,1,0.999253354069792,40.0298881530762,1.99791846310634,17.1900000423193,-0.000903125791799903,-0.000191312910061192,0.25,-2.45031738838441E-6,-8.03457087074584E-5,-3.04292380747738E-6,20.0000477,20.0000477,73677.34375,73696.9921875,56.6743206723906,20.5428331572327,15.315984,0,0,0,40,4449,20.0265,73687.16796875,,,,,,,,,,,,,0,,,,0,,,,,,20.0000477,,,,
,22202926.03,19.9981861,69004.71484375,-6.90982475963509E-5,4.5610257810661E-7,1,0.999253354069792,40.0298881530762,1.99777661828109,17.1900000423193,-0.000776581356123428,-0.000166966590563952,0.25,-2.31488221024546E-6,-6.91289281822477E-5,-2.82788918321015E-6,19.9981861,19.9981861,68999.4140625,69010.015625,56.7892200647175,20.5434448510175,15.315984,0,0,0,40,4449,20.0276,69004.71484375,,,,,,,,,,,,,0,,,,-0.0049,,,,,,19.9981861,,,,
,22203024.18,19.9981346,64096.59765625,-5.53526249661069E-5,5.04073608461491E-7,1,0.999253354069792,40.0298881530762,1.99781162097264,17.1900000423193,-0.000622178982764792,-0.000131811684695127,0.25,-1.68557145074457E-6,-5.53545650697023E-5,-2.097538017873E-6,19.9981346,19.9981346,64091.65234375,64101.54296875,56.9510171681983,20.5430449273507,14.936333,0,0,0,40,4449,20.0303,64096.59765625,,,,,,,,,,,,,0,,,,-0.0049,,,,,,19.9981346,,,,
,22203119.39,19.9979973,59338.662109375,-4.1169482588691E-5,4.61010413693441E-7,1,0.999253354069792,40.0298881530762,1.99783009758928,17.1900000423193,-0.000461699037852186,-0.000102758478561518,0.25,-1.67482454631389E-6,-4.11497326608306E-5,-1.98095382139605E-6,19.9979973,19.9979973,59333.71484375,59343.609375,56.6368025034675,20.5444199311315,14.936333,0,0,0,40,4449,20.03145,59338.662109375,,,,,,,,,,,,,0,,,,0,,,,,,19.9979973,,,,
,22203215.265,19.999136,54545.955078125,-3.00152488823948E-5,6.35793171042929E-7,1,0.999253354069792,40.0298881530762,1.99780050477747,17.1900000423193,-0.000333516329526831,-9.11536384107603E-5,0.25,-2.66249309606455E-6,-2.99763355487542E-5,-2.88362747489133E-6,19.999136,19.999136,54540.90625,54551.00390625,56.800944492506,20.5454189251294,15.315984,0,0,0,40,4449,20.0331,54545.955078125,,,,,,,,,,,,,0,,,,-0.00245,,,,,,19.999136,,,,
,22203311.81,19.99975205,49720.77734375,-1.67866636178237E-5,5.48375521854556E-7,1,0.999253354069792,40.0298881530762,1.99788503778083,17.1900000423193,-0.000186288121675564,-5.18248643004677E-5,0.25,-1.56671601979043E-6,-1.67563208207232E-5,-1.68873601160466E-6,19.9995079,19.9999962,49713.19140625,49728.36328125,56.9557069393137,20.545048854616,14.936333,0,0,0,40,4449,20.03305,49720.77734375,,,,,,,,,,,,,0,,,,0.00245,,,,,,19.99975205,,,,
,22203406.17,19.9994831,45003.30859375,-3.60304122594902E-6,4.70075220577906E-7,1,0.999253354069792,40.0298881530762,1.99800006107383,17.1900000423193,-3.84756113458466E-5,-1.94018184315295E-5,0.25,-1.07071003110044E-6,-3.58945674915658E-6,-1.09525879841172E-6,19.9994831,19.9994831,45000.796875,45005.8203125,56.8744175733137,20.5450830966301,15.315984,0,0,0,40,4449,20.03095,45003.30859375,,,,,,,,,,,,,0,,,,-0.00245,,,,,,19.9994831,,,,
,22203499.75,20.0010834,40327.931640625,6.15043527820324E-6,4.11453524004953E-7,1,0.999253354069792,40.0298881530762,1.99784579413255,17.1900000423193,7.11980645870862E-5,2.24041883425248E-6,0.25,-9.08313131507368E-7,6.14407227717599E-6,-8.62303191782922E-7,20.0010834,20.0010834,40322.76953125,40333.09375,56.912717370756,20.5454359717964,14.936333,0,0,0,40,4449,20.0325,40327.931640625,,,,,,,,,,,,,0,,,,0,,,,,,20.0010834,,,,
,22203595.04,19.9984379,35565.572265625,1.73855600318698E-5,3.91199072614272E-7,1,0.999253354069792,40.0298881530762,1.99784277485278,17.1900000423193,0.00019834834860121,2.19109306207082E-5,0.25,-1.18234636658677E-6,1.73486920342209E-5,-1.0573666858665E-6,19.9984379,19.9984379,35560.45703125,35570.6875,56.9119357422368,20.543276009811,15.315984,0,0,0,40,4449,20.0321,35565.572265625,,,,,,,,,,,,,0,,,,0.0049,,,,,,19.9984379,,,,
,22203692.765,19.99889565,30680.4892578125,2.86630053846396E-5,3.81664749803462E-7,1,0.999253354069792,40.0298881530762,1.99788059685895,17.1900000423193,0.000325066888424662,4.59897276742286E-5,0.25,-1.0660680620979E-6,2.85810264647777E-5,-8.67657182594698E-7,19.9986115,19.9991798,30673.0078125,30687.970703125,56.946327397083,20.5456734340616,15.315984,0,0,0,40,4449,20.0334,30680.4892578125,,,,,,,,,,,,,0,,,,0,,,,,,19.99889565,,,,
,22203785.655,19.9979172,26037.7099609375,3.97302253905708E-5,4.94736924402856E-7,1,0.999253354069792,40.0298881530762,1.99815627453933,17.1900000423193,0.000448743518201552,7.30520029097595E-5,0.25,-6.40189737922399E-7,3.95915707840109E-5,-3.76794789691548E-7,19.9979172,19.9979172,26030.11328125,26045.306640625,56.8986480574099,20.5469635079061,15.315984,0,0,0,40,4449,20.0348,26037.7099609375,,,,,,,,,,,,,0,,,,-0.0049,,,,,,19.9979172,,,,
,22203881.98,19.9988327,21222.75390625,5.01305167873222E-5,4.48524378842435E-7,1,0.999253354069792,40.0298881530762,1.99815815748153,17.1900000423193,0.000564105959328013,0.000102335911757061,0.25,1.12888622030474E-7,4.99252397370317E-5,4.2773898435453E-7,19.9988327,19.9988327,21212.9375,21232.5703125,56.5179949685444,20.5470783379979,14.936333,0,0,0,40,4449,20.03405,21222.75390625,,,,,,,,,,,,,0,,,,-0.00245,,,,,,19.9988327,,,,
,22203976.235,19.9993935,16513.373046875,5.91062901693164E-5,2.84009388679215E-7,1,0.999253354069792,40.0298881530762,1.99797822934597,17.1900000423193,0.00066516520256959,0.000118267156113509,0.25,-5.5516205320966E-8,5.88387966971644E-5,2.98247527661554E-7,19.9993935,19.9993935,16505.982421875,16520.763671875,57.0792042453522,20.5467342351954,14.936333,0,0,0,40,4449,20.0353,16513.373046875,,,,,,,,,,,,,0,,,,0,,,,,,19.9993935,,,,
,22204075.96,20.0027237,11530.9174804687,6.95086826158476E-5,3.35585559835345E-7,1,0.999253354069792,40.0298881530762,1.99795635473147,17.1900000423193,0.000782390845882358,0.000136121673572339,0.25,-2.98299647834649E-7,6.91647361947258E-5,9.43390956564281E-8,20.0027237,20.0027237,11518.7236328125,11543.111328125,56.9799374234099,20.5475151585928,14.556682,0,0,0,40,4449,20.03305,11530.9174804687,,,,,,,,,,,,,0,,,,-0.00245,,,,,,20.0027237,,,,
,22204170.27,20.0031948,6815.82470703125,7.8014696928006E-5,2.80426905140445E-7,1,0.999253354069792,40.0298881530762,1.99794992946522,17.1900000423193,0.000878252175502296,0.000150185077718862,0.25,-5.33459222531864E-7,7.76005581765853E-5,-1.18509716821982E-7,20.0031948,20.0031948,6810.9697265625,6820.6796875,56.6516534453329,20.5490299730833,15.315984,0,0,0,40,4449,20.02935,6815.82470703125,,,,,,,,,,,,,0,,,,-0.0049,,,,,,20.0031948,,,,
,22204266.73,20.0058823,1993.10211181641,8.46743073274288E-5,3.01668651900903E-7,1,0.999253354069792,40.0298881530762,1.99800327820655,17.1900000423193,0.000951983312013942,0.00016835152383276,0.25,-7.09961714452404E-8,8.41954676257431E-5,3.48556006225385E-7,20.0058823,20.0058823,1983.09301757813,2003.11120605469,56.6860451001791,20.5460013576542,15.315984,0,0,0,40,4449,20.0237,1993.10211181641,,,,,,,,,,,,,0,,,,-0.00245,,,,,,20.0058823,,,,
,22204307.075,19.9978161,-0.144625842571259,8.05288137697847E-5,3.04330179092135E-7,1,0.999253354069792,40.0298881530762,1.99817380121295,17.1900000423193,0.000906893063307362,0.000151514386726307,0.25,-8.2361914273314E-7,8.00697927340868E-5,-4.28588027679639E-7,19.9978161,19.9978161,-0.1674614995718,-0.121790185570717,56.7282530402175,20.5493560175104,14.936333,0,0,0,40,4417,20.0338,-0.144625842571259,,,,,,,,,,,,,0,,,,-0.00245,,,,,,19.9978161,,,,