File: data/doubleLayers/dl_1-25/ppms/KoelnPPMS/DD205_3_FCW_100OE_2_SLOWER.DAT
[Header]
; VSM Data File (default extension .dat)
; Copyright (c) 2003-2013, Quantum Design, Inc. All rights reserved.
TITLE,
FILEOPENTIME,22807985.63,09/22/2018,8:31 am
BYAPP,VSM,2.0,2.0
INFO,PPMS VSM Option Release 1.4.10 Build 1,APPNAME
INFO,Quantum Design Linear Motor Servo Controller,MOTOR_MODULE_NAME
INFO,3101-100 M1,MOTOR_HW_VERSION
INFO,MMC1014,MOTOR_SERIAL_NUMBER
INFO,SRV No X-over 01.03.11,MOTOR_SOFTWARE_VERSION
INFO,Quantum Design VSM Detection Module,VSM_MODULE_NAME
INFO,3101-150 F0,VSM_HW_VERSION
INFO,VSM707,VSM_SERIAL_NUMBER
INFO,VSM No X-over 01.02.05 May 20 2008 13:51:47,VSM_SOFTWARE_VERSION
INFO,704,PREAMP_SERIAL_NUMBER
INFO,822,COIL_SERIAL_NUMBER
INFO,0,MOMENT_UNITS
INFO,,SAMPLE_MATERIAL
INFO,,SAMPLE_COMMENT
INFO,,SAMPLE_MASS
INFO,,SAMPLE_VOLUME
INFO,,SAMPLE_MOLECULAR_WEIGHT
INFO,,SAMPLE_SIZE
INFO,,SAMPLE_SHAPE
DATATYPE,COMMENT,1
DATATYPE,TIME,2
STARTUPAXIS,X,2
STARTUPAXIS,Y1,5
[Data]
Comment,Time Stamp (sec),Temperature (K),Magnetic Field (Oe),Moment (emu),M. Std. Err. (emu),Transport Action,Averaging Time (sec),Frequency (Hz),Peak Amplitude (mm),Center Position (mm),Coil Signal' (mV),Coil Signal" (mV),Range (mV),M. Quad. Signal (emu),M. Raw' (emu),M. Raw" (emu),Min. Temperature (K),Max. Temperature (K),Min. Field (Oe),Max. Field (Oe),Mass (grams),Motor Lag (deg),Pressure (Torr),VSM Status (code),Motor Status (code),Measure Status (code),Measure Count,PPMS Status (code),System Temp. (K),System Field (Oe),Sample Position (deg),Bridge 1 Resistance (ohms),Bridge 1 Excitation (에),Bridge 2 Resistance (ohms),Bridge 2 Excitation (에),Bridge 3 Resistance (ohms),Bridge 3 Excitation (에),Bridge 4 Resistance (ohms),Bridge 4 Excitation (에),Signal 1 Vin (V),Signal 2 Vin (V),Digital Inputs (code),Drive 1 Iout (mA),Drive 1 Ipower (W),Drive 2 Iout (mA),Drive 2 Ipower (W),Pressure (),Map 20 (),Map 21 (),Map 22 (),Map 23 (),Map 24 (),Map 25 (),Map 26 (),Map 27 (),Map 28 (),Map 29 ()
,22808117.42,10.0038443,99.6852722167969,2.12447721627827E-5,2.58018885030494E-7,1,0.999253354069792,40.0298881530762,1.99795487926851,16.610000282526,0.000239457094354515,3.86858451699381E-5,0.25,-3.30841543094851E-7,2.11243777265556E-5,-2.26481824509843E-7,10.0038443,10.0038443,99.6852722167969,99.6852722167969,57.0291800201214,20.6649839949326,11.899124,0,0,0,40,4369,9.991,99.6852722167969,,,,,,,,,,,,,0,,,,-0.0049,,,,,,10.0038443,,,,
,22808305.84,13.00322245,99.6852722167969,2.11897535989971E-5,3.21917383101822E-7,1,0.999253354069792,40.0298881530762,1.99793397598617,16.610000282526,0.000238939970158272,3.79837019543265E-5,0.25,-3.83484956179923E-7,2.1069806243829E-5,-2.7908667245268E-7,12.9841919,13.022253,99.6852722167969,99.6852722167969,57.1550222117176,20.667133782614,11.899124,0,0,0,40,4370,13.1166,99.6852722167969,,,,,,,,,,,,,0,,,,0.0049,,,,,,13.00322245,,,,
,22808517.465,16.5086193,99.6852722167969,2.12388896174386E-5,2.94585486787455E-7,1,0.999253354069792,40.0298881530762,1.99795649375628,16.610000282526,0.000239211361487107,3.96651387309405E-5,0.25,-2.42621206210573E-7,2.11177761316673E-5,-1.38794278403129E-7,16.4908981,16.5263405,99.6852722167969,99.6852722167969,57.4465696493907,20.6679351636261,12.658426,0,0,0,40,4370,16.6703,99.6852722167969,,,,,,,,,,,,,0,,,,0,,,,,,16.5086193,,,,
,22808728.68,20.0171432,99.6852722167969,2.10532250140869E-5,3.49739211893453E-7,1,0.999253354069792,40.0298881530762,1.99794281231278,16.610000282526,0.000237698280332966,3.60740656155521E-5,0.25,-5.29808426696321E-7,2.09348642395956E-5,-4.24589577654876E-7,20.0171432,20.0171432,99.6852722167969,99.6852722167969,57.4153045086215,20.6654323859091,13.417728,0,0,0,40,4370,20.1981,99.6852722167969,,,,,,,,,,,,,0,,,,0,,,,,,20.0171432,,,,
,22808911.065,23.0239544,99.6852722167969,2.13138377098333E-5,3.12026598470149E-7,1,0.999253354069792,40.0298881530762,1.99804432397317,16.6200008243322,0.000240999056370023,3.46916505900991E-5,0.25,-7.01837490769822E-7,2.11966513298373E-5,-5.92096565701809E-7,23.0239544,23.0239544,99.6852722167969,99.6852722167969,57.065134932006,20.6630082328059,13.797379,0,0,0,40,4370,23.25455,99.6852722167969,,,,,,,,,,,,,0,,,,0,,,,,,23.0239544,,,,
,22809121.33,26.5075493,99.6852722167969,2.1000960204662E-5,3.40022522339299E-7,1,0.999253354069792,40.0298881530762,1.99812447803565,16.6200008243322,0.000236924794522635,3.75262215678829E-5,0.25,-3.99613943130473E-7,2.08881754976013E-5,-2.88476190636381E-7,26.5075493,26.5075493,99.6852722167969,99.6852722167969,56.9220969129868,20.6615660456672,13.797379,0,0,0,40,4370,26.79025,99.6852722167969,,,,,,,,,,,,,0,,,,-0.00245,,,,,,26.5075493,,,,
,22809334.085,30.0270081,99.6852722167969,2.08308717577969E-5,3.04288924010818E-7,1,0.999253354069792,40.0298881530762,1.99831964084476,16.6200008243322,0.000235089420563178,3.7331693750127E-5,0.25,-3.94980575355747E-7,2.07258545350328E-5,-2.77962033263803E-7,30.0270081,30.0270081,99.6852722167969,99.6852722167969,56.9557069393137,20.6618357704897,14.556682,0,0,0,40,4370,30.36985,99.6852722167969,,,,,,,,,,,,,0,,,,0,,,,,,30.0270081,,,,
,22809515.43,33.0176849,99.6852722167969,2.11687083768454E-5,2.6082237061515E-7,1,0.999253354069792,40.0298881530762,1.9984638070903,16.610000282526,0.000239116853081596,3.738829039843E-5,0.25,-4.59146781620723E-7,2.10708358520338E-5,-3.32724036332903E-7,33.0176849,33.0176849,99.6852722167969,99.6852722167969,57.1792526958137,20.6599136694768,14.177031,0,0,0,40,4370,33.4114,99.6852722167969,,,,,,,,,,,,,0,,,,0.0049,,,,,,33.0176849,,,,
,22809728.67,36.53442,99.6852722167969,2.11145233791253E-5,2.78733941094951E-7,1,0.999253354069792,40.0298881530762,1.99854666085607,16.610000282526,0.000237913109728477,4.15335986369558E-5,0.25,-9.31768307313271E-8,2.1028100652408E-5,4.0783422725847E-8,36.53442,36.53442,99.6852722167969,99.6852722167969,57.3129111726022,20.663452145096,14.936333,0,0,0,40,4370,37.0057,99.6852722167969,,,,,,,,,,,,,0,,,,0.0049,,,,,,36.53442,,,,
,22809940.365,40.0213127,99.6852722167969,2.12362780758077E-5,3.12968452544815E-7,1,0.999253354069792,40.0298881530762,1.99851925594121,16.610000282526,0.00024002239091157,3.8763254443752E-5,0.25,-3.73182640388802E-7,2.1168334356102E-5,-2.2814950189986E-7,40.0213127,40.0213127,99.6852722167969,99.6852722167969,57.4199942797368,20.6619112046945,14.936333,0,0,0,40,4370,40.5597,99.6852722167969,,,,,,,,,,,,,0,,,,0.0049,,,,,,40.0213127,,,,
,22810121.605,43.0055923,99.6852722167969,2.114578994474E-5,3.24035188595079E-7,1,0.999253354069792,40.0298881530762,1.99845006962867,16.5999997407198,0.000239107954195329,3.90859550214888E-5,0.25,-3.37832437730538E-7,2.10953493318071E-5,-1.86926963944591E-7,43.0055923,43.0055923,99.6852722167969,99.6852722167969,57.3848209963715,20.6619688721091,15.695635,0,0,0,40,4370,43.61305,99.6852722167969,,,,,,,,,,,,,0,,,,0.0049,,,,,,43.0055923,,,,
,22810335.375,46.5099258,99.6852722167969,2.09711287976803E-5,3.61243147067989E-7,1,0.999253354069792,40.0298881530762,1.99833994670043,16.5999997407198,0.000236687600506523,4.26439686829864E-5,0.25,-6.27159903799465E-11,2.09414596855544E-5,1.5421550039958E-7,46.5099258,46.5099258,99.6852722167969,99.6852722167969,57.5958606965638,20.6641641245178,15.695635,0,0,0,40,4370,47.2298,99.6852722167969,,,,,,,,,,,,,0,,,,-0.0049,,,,,,46.5099258,,,,
,22810550.58,50.0086021,99.6852722167969,2.09691898216997E-5,2.75623982008563E-7,1,0.999253354069792,40.0298881530762,1.99836945314677,16.5999997407198,0.000236976561654544,4.24893800512916E-5,0.25,-1.9378069967358E-8,2.09636705431296E-5,1.36669328868588E-7,50.0086021,50.0086021,99.6852722167969,99.6852722167969,57.1964485232368,20.6621939636356,15.695635,0,0,0,40,4370,50.8734,99.6852722167969,,,,,,,,,,,,,0,,,,0,,,,,,50.0086021,,,,
,22810734.985,53.0297394,99.6852722167969,2.06737959751938E-5,2.81398045644126E-7,1,0.999253354069792,40.0298881530762,1.99827954336,16.5800005197525,0.000234954560680095,3.58113130113981E-5,0.25,-5.58350010119101E-7,2.06921634252155E-5,-4.06436531726831E-7,53.0297394,53.0297394,99.6852722167969,99.6852722167969,57.1386080128137,20.6611021987607,16.454937,0,0,0,40,4374,53.9958,99.6852722167969,,,,,,,,,,,,,0,,,,0,,,,,,53.0297394,,,,
,22810946.17,56.5165558,99.6852722167969,2.08450697191272E-5,3.02077498508896E-7,1,0.999253354069792,40.0298881530762,1.9982901457411,16.5800005197525,0.000236196526463991,4.13847469610173E-5,0.25,-9.51862172074329E-8,2.08811702689768E-5,5.34361874805404E-8,56.5165558,56.5165558,99.6852722167969,99.6852722167969,57.1135959001984,20.6646204749613,17.214239,0,0,0,40,4374,57.5545,99.6852722167969,,,,,,,,,,,,,0,,,,0,,,,,,56.5165558,,,,
,22811159.8,60.0244331,99.6852722167969,2.08718890102694E-5,3.00499202625717E-7,1,0.999253354069792,40.0298881530762,1.99833036979924,16.5800005197525,0.000237599090516354,3.65516227947121E-5,0.25,-5.22443647942068E-7,2.09295500874442E-5,-3.82063158667499E-7,60.0244331,60.0244331,99.6852722167969,99.6852722167969,57.0878021590637,20.6673197682575,16.834587,0,0,0,40,4374,61.16455,99.6852722167969,,,,,,,,,,,,,0,,,,0.0049,,,,,,60.0244331,,,,
,22811343.305,63.0251122,99.6852722167969,2.09620402041729E-5,2.97675748397837E-7,1,0.999253354069792,40.0298881530762,1.99824517747915,16.5599994361401,0.000238338148015962,3.91246979011643E-5,0.25,-3.06191071446572E-7,2.10319279173867E-5,-1.72220295621731E-7,63.0251122,63.0251122,99.6852722167969,99.6852722167969,57.0104209356599,20.6638848107343,16.834587,0,0,0,40,4374,64.2572,99.6852722167969,,,,,,,,,,,,,0,,,,-0.00245,,,,,,63.0251122,,,,
,22811554.985,66.5016479,99.6852722167969,2.09638919608504E-5,2.98486410907303E-7,1,0.999253354069792,40.0298881530762,1.99817244431762,16.5599994361401,0.000238317898648672,4.01412669430632E-5,0.25,-2.09752087338272E-7,2.10459760256941E-5,-8.46884940402203E-8,66.5016479,66.5016479,99.6852722167969,99.6852722167969,57.0080760501022,20.6651645685043,17.214239,0,0,0,40,4374,67.8326,99.6852722167969,,,,,,,,,,,,,0,,,,0,,,,,,66.5016479,,,,
,22811770.18,70.0191116,99.6852722167969,2.08598855809571E-5,3.33028373134098E-7,1,0.999253354069792,40.0298881530762,1.99825314066579,16.5599994361401,0.000237173114739349,4.04529362325676E-5,0.25,-1.56299866033347E-7,2.09515435316449E-5,-4.09866263020714E-8,70.0191116,70.0191116,99.6852722167969,99.6852722167969,57.3582456267176,20.6678993504689,17.973541,0,0,0,40,4374,71.4839,99.6852722167969,,,,,,,,,,,,,0,,,,0.0049,,,,,,70.0191116,,,,
,22811952.3,73.0004272,99.6852722167969,2.05605084042477E-5,2.96317597880725E-7,1,0.999253354069792,40.0298881530762,1.99826162871994,16.5299996733665,0.000234044736503259,3.87681152472599E-5,0.25,-2.45036243293712E-7,2.0658054233581E-5,-1.39236077830993E-7,73.0004272,73.0004272,99.6852722167969,99.6852722167969,57.058100275333,20.6633726526052,17.593889,0,0,0,40,4374,74.5609,99.6852722167969,,,,,,,,,,,,,0,,,,0,,,,,,73.0004272,,,,
,22812165.645,76.5456238,99.6852722167969,2.07048032478771E-5,2.64733279480736E-7,1,0.999253354069792,40.0298881530762,1.99809669533472,16.5299996733665,0.000235448506498157,4.067474182667E-5,0.25,-9.55414492526413E-8,2.08083897433732E-5,3.58757833394082E-9,76.5456238,76.5456238,99.6852722167969,99.6852722167969,56.9502355396791,20.6654595693053,17.973541,0,0,0,40,4374,78.1394,99.6852722167969,,,,,,,,,,,,,0,,,,0,,,,,,76.5456238,,,,
,22812376.875,80.0237274,99.6852722167969,2.0907889457344E-5,2.82589899642439E-7,1,0.999253354069792,40.0298881530762,1.99817289547959,16.5299996733665,0.000238193796110442,3.89672612483632E-5,0.25,-2.75331802119644E-7,2.10179346678411E-5,-1.83598993489068E-7,80.0237274,80.0237274,99.6852722167969,99.6852722167969,57.1518956976407,20.663649068137,17.973541,0,0,0,40,4374,81.6852,99.6852722167969,,,,,,,,,,,,,0,,,,0,,,,,,80.0237274,,,,
,22812588.61,83.5450211,99.6852722167969,2.06067435333555E-5,2.86384640940147E-7,1,0.999253354069792,40.0298881530762,1.99829972394816,16.499999910593,0.000234575465137218,3.97674452770247E-5,0.25,-1.45743115488495E-7,2.07180196673389E-5,-6.13397788375644E-8,83.5450211,83.5450211,99.6852722167969,99.6852722167969,56.9346029692945,20.663130578102,17.973541,0,0,0,40,4374,85.2394,99.6852722167969,,,,,,,,,,,,,0,,,,0,,,,,,83.5450211,,,,
,22812798.955,87.0272827,99.6852722167969,2.09432882510436E-5,2.90580269089523E-7,1,0.999253354069792,40.0298881530762,1.99844080137053,16.499999910593,0.000238387901406263,4.07764885231313E-5,0.25,-1.11165110616183E-7,2.10586918963732E-5,-3.12090458963257E-8,87.0272827,87.0272827,99.6852722167969,99.6852722167969,56.8869236296214,20.6656323387095,17.593889,0,0,0,40,4374,88.755,99.6852722167969,,,,,,,,,,,,,0,,,,0,,,,,,87.0272827,,,,
,22813012.705,90.5429764,99.6852722167969,2.07752994209157E-5,2.72047247732084E-7,1,0.999253354069792,40.0298881530762,1.99838144622002,16.499999910593,0.00023688611318735,3.81965147501151E-5,0.25,-3.03110127685096E-7,2.08922189939286E-5,-2.30351840690437E-7,90.5429764,90.5429764,99.6852722167969,99.6852722167969,57.5348936720638,20.6627473695481,18.353191,0,0,0,40,4374,92.349,99.6852722167969,,,,,,,,,,,,,0,,,,0.00245,,,,,,90.5429764,,,,
,22813193.665,93.5071716,99.6852722167969,2.10284001149093E-5,3.35890041873392E-7,1,0.999253354069792,40.0298881530762,1.99830806833656,16.4599996060133,0.000239988583508884,3.74471432343286E-5,0.25,-4.09395260785073E-7,2.11480781189454E-5,-3.40607952782781E-7,93.5071716,93.5071716,99.6852722167969,99.6852722167969,57.0166739638137,20.6576523055009,18.353191,0,0,0,40,4374,95.41375,99.6852722167969,,,,,,,,,,,,,0,,,,-0.0049,,,,,,93.5071716,,,,
,22813409.865,97.0291138,99.6852722167969,2.08100600003339E-5,2.97084300891591E-7,1,0.999253354069792,40.0298881530762,1.99867455640919,16.4599996060133,0.000237035043393737,3.99715890229845E-5,0.25,-1.45197443438541E-7,2.09283548884441E-5,-8.02314451120948E-8,97.0291138,97.0291138,99.6852722167969,99.6852722167969,57.1432977839291,20.6577652651241,18.353191,0,0,0,40,4374,99.0847,99.6852722167969,,,,,,,,,,,,,0,,,,-0.00245,,,,,,97.0291138,,,,
,22813621.355,100.5250092,99.6852722167969,2.11027086032746E-5,3.06524292792121E-7,1,0.999253354069792,40.0298881530762,1.99842802455576,16.4700001478195,0.000241134487640208,3.60231127002702E-5,0.25,-5.39376078373226E-7,2.1224104496214E-5,-4.79746731891214E-7,100.5250092,100.5250092,99.6852722167969,99.6852722167969,57.0385595623522,20.6576578071271,18.732843,0,0,0,40,4374,102.6378,99.6852722167969,,,,,,,,,,,,,0,,,,-0.0049,,,,,,100.5250092,,,,
touchdown = 10.6399999931455 mm,22813803.74,103.5439453,99.6852722167969,2.07757356624151E-5,2.87010108752908E-7,1,0.999253354069792,40.0298881530762,1.99842256609881,16.4199993014336,0.000236672838721571,3.958841730655E-5,0.25,-1.65446545571446E-7,2.08941199750417E-5,-1.07755882852391E-7,103.5439453,103.5439453,99.6852722167969,99.6852722167969,57.3097846585253,20.6578336946453,19.112494,0,0,0,40,4374,105.695,99.6852722167969,,,,,,,,,,,,,0,,,,0,,,,,,103.5439453,,,,
,22814011.835,107.0082817,99.6852722167969,2.07715501387172E-5,2.51366715700738E-7,1,0.999253354069792,40.0298881530762,1.99845611549341,16.4199993014336,0.000236906171378538,3.79780695924699E-5,0.25,-3.03091192774589E-7,2.08899604269781E-5,-2.49384196991052E-7,106.9899597,107.0266037,99.6852722167969,99.6852722167969,56.8884868866599,20.6622541631297,18.353191,0,0,0,40,4374,109.1699,99.6852722167969,,,,,,,,,,,,,0,,,,0,,,,,,107.0082817,,,,
,22814223.735,110.5306473,99.6852722167969,2.12057633079074E-5,3.52887418134868E-7,1,0.999253354069792,40.0298881530762,1.99834334637767,16.4199993014336,0.000241569643202751,4.03051965511091E-5,0.25,-1.71374862731513E-7,2.13257148623952E-5,-1.18768855669816E-7,110.5306473,110.5306473,99.6852722167969,99.6852722167969,56.9713395096983,20.6633474616815,19.112494,0,0,0,40,4374,112.7111,99.6852722167969,,,,,,,,,,,,,0,,,,0.00245,,,,,,110.5306473,,,,
touchdown = 10.5999996885657 mm,22814421.71,113.8329849,99.6852722167969,2.06872585984072E-5,2.59337798501444E-7,1,0.999253354069792,40.0298881530762,1.99830028732745,16.380000859499,0.000235896044637362,3.79127323823851E-5,0.25,-2.88199284186167E-7,2.08038676935933E-5,-2.40050482387238E-7,113.8329849,113.8329849,99.6852722167969,99.6852722167969,56.8431524325445,20.6595117205288,19.112494,0,0,0,40,4374,116.0234,99.6852722167969,,,,,,,,,,,,,0,,,,0.0049,,,,,,113.8329849,,,,
,22814613.49,117.023407,99.6852722167969,2.06239701488307E-5,2.65067163483547E-7,1,0.999253354069792,40.0298881530762,1.99837972397565,16.380000859499,0.000234592490802738,4.1119747735334E-5,0.25,6.99919892036874E-9,2.07387144985281E-5,5.44481493167599E-8,117.023407,117.023407,99.6852722167969,99.6852722167969,57.2495992625445,20.6597104235563,19.112494,0,0,0,40,4374,119.21875,99.6852722167969,,,,,,,,,,,,,0,,,,0,,,,,,117.023407,,,,
,22814824.015,120.5096054,99.6852722167969,2.03449082725923E-5,2.72831451066925E-7,1,0.999253354069792,40.0298881530762,1.99857109945002,16.380000859499,0.000231707553041924,3.89662387530502E-5,0.25,-1.31466490843954E-7,2.04574055883324E-5,-8.76098303295535E-8,120.4944305,120.5247803,99.6852722167969,99.6852722167969,57.3660619119099,20.6578809287812,19.492144,0,0,0,40,4374,122.7316,99.6852722167969,,,,,,,,,,,,,0,,,,0,,,,,,120.5096054,,,,
,22815023.84,123.8264236,99.6852722167969,,,2,,,,16.3500003153086,,,,,,,123.8264236,123.8264236,99.6852722167969,99.6852722167969,,,19.112494,,,,-99999999,4374,126.0773,99.6852722167969,,,,,,,,,,,,,,,,,,,,,,,123.8264236,,,,
,22815215.305,127.0050049,99.6852722167969,2.0206109352372E-5,2.88411355422692E-7,1,0.999253354069792,40.0298881530762,1.99876974765652,16.3400005549192,0.000230558822786074,3.62078755404949E-5,0.25,-3.46077492655995E-7,2.03160747178717E-5,-3.0723805807858E-7,127.0050049,127.0050049,99.6852722167969,99.6852722167969,57.3613721407945,20.6519834966249,19.492144,0,0,0,40,4374,129.2771,99.6852722167969,,,,,,,,,,,,,0,,,,0,,,,,,127.0050049,,,,
,22815426.88,130.5151215,99.6852722167969,2.0223822170659E-5,2.84546858162165E-7,1,0.999253354069792,40.0298881530762,1.99857030076678,16.3400005549192,0.000230400790417768,3.80826723099603E-5,0.25,-1.82134406131216E-7,2.0332210548445E-5,-1.44070323037957E-7,130.5151215,130.5151215,99.6852722167969,99.6852722167969,57.1683098965445,20.6543906293998,19.492144,0,0,0,40,4374,132.8241,99.6852722167969,,,,,,,,,,,,,0,,,,-0.0049,,,,,,130.5151215,,,,
,22815643.08,134.084549,99.6852722167969,,,2,,,,16.3000004002452,,,,,,,134.084549,134.084549,99.6852722167969,99.6852722167969,,,19.492144,,,,-99999999,4374,136.4469,99.6852722167969,,,,,,,,,,,,,,,,,,,,,,,134.084549,,,,
,22815817.14,137.00592805,99.6852722167969,2.08063824866128E-5,3.2344708675202E-7,1,0.999253354069792,40.0298881530762,1.99862130316465,16.2899997085333,0.000236694456054107,4.09942001936012E-5,0.25,-2.46004973090947E-8,2.09148069299843E-5,1.254707710582E-8,136.9910736,137.0207825,99.6852722167969,99.6852722167969,57.0252718775253,20.6563412363211,19.871798,0,0,0,40,4374,139.3637,99.6852722167969,,,,,,,,,,,,,0,,,,-0.00245,,,,,,137.00592805,,,,
,22816030.01,140.5279236,99.6852722167969,2.06494487397791E-5,3.03105751524193E-7,1,0.999253354069792,40.0298881530762,1.99858744149535,16.2899997085333,0.000236317997105391,3.24743200378428E-5,0.25,-7.44655880354751E-7,2.07566921722566E-5,-7.12875720100805E-7,140.5279236,140.5279236,99.6852722167969,99.6852722167969,57.5348936720638,20.6579416945078,19.871798,0,0,0,40,4374,142.9284,99.6852722167969,,,,,,,,,,,,,0,,,,-0.0049,,,,,,140.5279236,,,,
,22816240.93,144.0308075,99.6852722167969,2.05553438734862E-5,3.21868167860374E-7,1,0.999253354069792,40.0298881530762,1.99862372940158,16.2899997085333,0.000234461582771961,3.67085457061522E-5,0.25,-3.54463536044376E-7,2.06597515146947E-5,-3.2209004793211E-7,144.0308075,144.0308075,99.6852722167969,99.6852722167969,57.9812035565446,20.6559735307037,20.251448,0,0,0,40,4374,146.4667,99.6852722167969,,,,,,,,,,,,,0,,,,0,,,,,,144.0308075,,,,
,22816419.885,147.0248108,99.6852722167969,2.02500008585476E-5,2.83443100808028E-7,1,0.999253354069792,40.0298881530762,1.99851907773657,16.2400007247925,0.00023084600412666,3.67587976626988E-5,0.25,-2.95450847789111E-7,2.03513048640253E-5,-2.64257130921603E-7,147.0248108,147.0248108,99.6852722167969,99.6852722167969,57.5231692442753,20.6564051670246,20.251448,0,0,0,40,4374,149.457,99.6852722167969,,,,,,,,,,,,,0,,,,-0.0049,,,,,,147.0248108,,,,
,22816630.265,150.5274048,99.6852722167969,2.07088335253538E-5,2.78200166425519E-7,1,0.999253354069792,40.0298881530762,1.99857165438859,16.2400007247925,0.000236770516342397,3.35218507385968E-5,0.25,-6.5876959154643E-7,2.0811185444332E-5,-6.29703793398327E-7,150.5274048,150.5274048,99.6852722167969,99.6852722167969,57.0502839901407,20.6569253175204,19.871798,0,0,0,40,4374,152.9735,99.6852722167969,,,,,,,,,,,,,0,,,,-0.0049,,,,,,150.5274048,,,,
,22816840.4,154.0138702,99.6852722167969,2.06470989077742E-5,3.14878558959408E-7,1,0.999253354069792,40.0298881530762,1.99862382646689,16.2400007247925,0.00023493047216148,3.98456627183862E-5,0.25,-9.05979530910429E-8,2.07464303087989E-5,-5.98758911751281E-8,154.0138702,154.0138702,99.6852722167969,99.6852722167969,57.2902439455445,20.6592357826199,19.871798,0,0,0,40,4374,156.48245,99.6852722167969,,,,,,,,,,,,,0,,,,0,,,,,,154.0138702,,,,
,22817020.1,157.0271301,99.6852722167969,2.02132305332631E-5,3.2576787893901E-7,1,0.999253354069792,40.0298881530762,1.99851930620942,16.2000004202127,0.000230683358135584,3.48724267532418E-5,0.25,-4.51257409590791E-7,2.030941508872E-5,-4.23702741612525E-7,157.0271301,157.0271301,99.6852722167969,99.6852722167969,57.1831608384099,20.6559187514906,20.251448,0,0,0,40,4374,159.4881,99.6852722167969,,,,,,,,,,,,,0,,,,-0.0049,,,,,,157.0271301,,,,
,22817230.52,160.5313873,99.6852722167969,2.08030712582169E-5,2.88454418240547E-7,1,0.999253354069792,40.0298881530762,1.998368725864,16.2000004202127,0.000237788488664026,3.35110640173881E-5,0.25,-6.72282442909762E-7,2.09003926005866E-5,-6.45765004396374E-7,160.5313873,160.5313873,99.6852722167969,99.6852722167969,57.085457273506,20.6607534814649,20.251448,0,0,0,40,4374,162.99785,99.6852722167969,,,,,,,,,,,,,0,,,,0,,,,,,160.5313873,,,,
,22817439.245,164.0060577,99.6852722167969,2.09852618848317E-5,3.04876132763336E-7,1,0.999253354069792,40.0298881530762,1.9985349825718,16.2000004202127,0.000239248472587069,3.73592563877123E-5,0.25,-3.64522335261104E-7,2.10809829131137E-5,-3.3715280691916E-7,164.0060577,164.0060577,99.6852722167969,99.6852722167969,57.4606389627369,20.6618379715762,20.251448,0,0,0,40,4374,166.4882,99.6852722167969,,,,,,,,,,,,,0,,,,0,,,,,,164.0060577,,,,
,22817618.805,167.0083923,99.6852722167969,2.06685889493499E-5,3.15627951937422E-7,1,0.999253354069792,40.0298881530762,1.99866277939587,16.1499995738268,0.000234997482371758,4.04465140929633E-5,0.25,-3.70447127119605E-8,2.07606900841735E-5,-9.31636370923039E-9,167.0083923,167.0083923,99.6852722167969,99.6852722167969,57.3746598256215,20.6616160206709,19.871798,0,0,0,40,4374,169.483,99.6852722167969,,,,,,,,,,,,,0,,,,-0.0049,,,,,,167.0083923,,,,
,22817829.745,170.515213,99.6852722167969,2.09560318347095E-5,3.62195241487548E-7,1,0.999253354069792,40.0298881530762,1.99856464970264,16.1499995738268,0.00023882915113547,3.75630686233884E-5,0.25,-3.39474547019152E-7,2.10477243906194E-5,-3.13452030972801E-7,170.4971771,170.5332489,99.6852722167969,99.6852722167969,57.0229269919676,20.6613620078856,20.631098,0,0,0,40,4374,173.0067,99.6852722167969,,,,,,,,,,,,,0,,,,-0.00245,,,,,,170.515213,,,,
,22818040.665,174.0165558,99.6852722167969,2.04632500976058E-5,2.84179903660682E-7,1,0.999253354069792,40.0298881530762,1.9985276368369,16.1499995738268,0.000233466464686558,3.50586424448753E-5,0.25,-4.73056963275013E-7,2.05508862345958E-5,-4.48933871692236E-7,174.0165558,174.0165558,99.6852722167969,99.6852722167969,57.0065127930637,20.6625967637403,20.631098,0,0,0,40,4374,176.5328,99.6852722167969,,,,,,,,,,,,,0,,,,-0.0049,,,,,,174.0165558,,,,
,22818219.125,177.0068512,99.6852722167969,2.08909141991936E-5,3.84208782738763E-7,1,0.999253354069792,40.0298881530762,1.9983373170409,16.0900000482798,0.000237108127740632,4.26579337976454E-5,0.25,1.22583563056042E-7,2.09777779148912E-5,1.49186576349034E-7,177.0068512,177.0068512,99.6852722167969,99.6852722167969,57.0862389020253,20.6591789703447,20.631098,0,0,0,40,4374,179.5159,99.6852722167969,,,,,,,,,,,,,0,,,,0.0049,,,,,,177.0068512,,,,
,22818432.265,180.5314789,99.6852722167969,2.041840011675E-5,2.67356402684447E-7,1,0.999253354069792,40.0298881530762,1.99838404363705,16.0900000482798,0.000233184544915691,3.32997309290992E-5,0.25,-6.18057639002601E-7,2.05020580847491E-5,-5.95717395972565E-7,180.5314789,180.5314789,99.6852722167969,99.6852722167969,57.169873153583,20.6618115595425,20.631098,0,0,0,40,4374,183.0782,99.6852722167969,,,,,,,,,,,,,0,,,,0,,,,,,180.5314789,,,,
,22818641.175,184.0320892,99.6852722167969,2.10369971942114E-5,3.13176955753234E-7,1,0.999253354069792,40.0298881530762,1.99817478227392,16.0900000482798,0.000239344974434671,3.92187061585356E-5,0.25,-2.03243571655554E-7,2.11204289989124E-5,-1.79069610482728E-7,184.0320892,184.0320892,99.6852722167969,99.6852722167969,57.4168677656599,20.6619810647302,20.631098,0,0,0,40,4374,186.57475,99.6852722167969,,,,,,,,,,,,,0,,,,0,,,,,,184.0320892,,,,
,22818821.465,187.0214233,99.6852722167969,2.11142870484693E-5,3.24296850153763E-7,1,0.999253354069792,40.0298881530762,1.99821102961508,16.0399992018938,0.000240235062821551,3.91956258992608E-5,0.25,-2.17941235237675E-7,2.11961039858733E-5,-1.94228959740778E-7,187.0214233,187.0214233,99.6852722167969,99.6852722167969,57.3504293415253,20.6620731583669,20.631098,0,0,0,40,4374,189.591,99.6852722167969,,,,,,,,,,,,,0,,,,0.0049,,,,,,187.0214233,,,,
,22819031.555,190.517746,99.6852722167969,2.0535959511025E-5,3.33938951293832E-7,1,0.999253354069792,40.0298881530762,1.99856438181605,16.0399992018938,0.000233506557947946,3.90597197561046E-5,0.25,-1.29067590915078E-7,2.06132099096577E-5,-1.06227447940814E-7,190.517746,190.517746,99.6852722167969,99.6852722167969,57.4567308201407,20.6590072551586,21.01075,0,0,0,40,4374,193.10555,99.6852722167969,,,,,,,,,,,,,0,,,,-0.00245,,,,,,190.517746,,,,
,22819243.275,194.0140991,99.6852722167969,2.05071306594772E-5,3.40307699752639E-7,1,0.999253354069792,40.0298881530762,1.99872737389926,16.0399992018938,0.000234270521240286,3.26764043645519E-5,0.25,-6.85434837113631E-7,2.05826377875246E-5,-6.6517584677102E-7,194.0140991,194.0140991,99.6852722167969,99.6852722167969,57.3449579418907,20.6564147061479,20.631098,0,0,0,40,4374,196.6578,99.6852722167969,,,,,,,,,,,,,0,,,,-0.00245,,,,,,194.0140991,,,,
,22819423.78,197.0232849,99.6852722167969,2.10671546700533E-5,3.4507716982791E-7,1,0.999253354069792,40.0298881530762,1.99886946423935,15.9799996763468,0.000240406374374256,3.50361714951088E-5,0.25,-5.74426128773846E-7,2.11425568757344E-5,-5.5353313247916E-7,197.0232849,197.0232849,99.6852722167969,99.6852722167969,57.2957153451791,20.6593234849479,21.01075,0,0,0,40,4374,199.6815,99.6852722167969,,,,,,,,,,,,,0,,,,-0.0049,,,,,,197.0232849,,,,
,22819634.455,200.5132446,99.6852722167969,2.09408569194923E-5,3.54783246820543E-7,1,0.999253354069792,40.0298881530762,1.99885810269144,15.9799996763468,0.000238702170870564,3.61745447382166E-5,0.25,-4.51393772683942E-7,2.10133251103962E-5,-4.30646739140418E-7,200.5132446,200.5132446,99.6852722167969,99.6852722167969,57.3277621144676,20.6629630860379,21.01075,0,0,0,40,4374,203.2057,99.6852722167969,,,,,,,,,,,,,0,,,,-0.0049,,,,,,200.5132446,,,,
,22819843.29,204.0027008,99.6852722167969,2.05572026477376E-5,2.93543356061642E-7,1,0.999253354069792,40.0298881530762,1.99887299679679,15.9799996763468,0.000234589703224654,3.38633918487058E-5,0.25,-5.87502603220435E-7,2.06261618120303E-5,-5.68026602683294E-7,204.0027008,204.0027008,99.6852722167969,99.6852722167969,57.4879959609099,20.6630686714492,21.3904,0,0,0,40,4374,206.6995,99.6852722167969,,,,,,,,,,,,,0,,,,0,,,,,,204.0027008,,,,
,22820024.77,207.0176239,99.6852722167969,2.09803666157346E-5,3.4731363145224E-7,1,0.999253354069792,40.0298881530762,1.99893804912785,15.930000692606,0.000239325510292659,3.50013931328678E-5,0.25,-5.60168571830537E-7,2.10486282133785E-5,-5.40496876799338E-7,207.0176239,207.0176239,99.6852722167969,99.6852722167969,57.4293738219676,20.6619802065887,21.01075,0,0,0,40,4374,209.7284,99.6852722167969,,,,,,,,,,,,,0,,,,0.00245,,,,,,207.0176239,,,,
,22820235.41,210.5123749,99.6852722167969,2.07454349023827E-5,3.47793461421583E-7,1,0.999253354069792,40.0298881530762,1.99894306149943,15.930000692606,0.000236054105056909,3.78588881014496E-5,0.25,-2.66910860880074E-7,2.08102456970501E-5,-2.46935809776593E-7,210.5123749,210.5123749,99.6852722167969,99.6852722167969,56.882233858506,20.6644914299657,21.3904,0,0,0,40,4374,213.2549,99.6852722167969,,,,,,,,,,,,,0,,,,-0.0049,,,,,,210.5123749,,,,
,22820445.47,214.0328979,99.6852722167969,2.09280903448321E-5,3.9124152945338E-7,1,0.999253354069792,40.0298881530762,1.9991304982664,15.930000692606,0.00023812737698706,3.81829681079844E-5,0.25,-2.69569693326914E-7,2.0991019679489E-5,-2.49805981468891E-7,214.0328979,214.0328979,99.6852722167969,99.6852722167969,57.0917103016599,20.6657516845779,21.3904,0,0,0,40,4374,216.7716,99.6852722167969,,,,,,,,,,,,,0,,,,0,,,,,,214.0328979,,,,
,22820625.02,217.0070648,99.6852722167969,2.05102050492369E-5,3.49854165727166E-7,1,0.999253354069792,40.0298881530762,1.99899970884098,15.8699993044138,0.000232653780084964,4.13378668618092E-5,0.25,8.17832500374626E-8,2.05694986733479E-5,1.01843423786993E-7,217.0070648,217.0070648,99.6852722167969,99.6852722167969,56.9314764552176,20.6612826999547,21.3904,0,0,0,40,4374,219.7745,99.6852722167969,,,,,,,,,,,,,0,,,,-0.00245,,,,,,217.0070648,,,,
,22820834.32,220.5019531,99.6852722167969,2.09345604275532E-5,3.24722646066931E-7,1,0.999253354069792,40.0298881530762,1.99896571543406,15.8699993044138,0.000238709363933453,3.48484278565791E-5,0.25,-5.62774660593196E-7,2.09932304830686E-5,-5.44490058105787E-7,220.5019531,220.5019531,99.6852722167969,99.6852722167969,57.1346998702176,20.6565195137303,21.01075,0,0,0,40,4374,223.27315,99.6852722167969,,,,,,,,,,,,,0,,,,0,,,,,,220.5019531,,,,
,22821046.895,224.0383911,99.6852722167969,2.08176829867516E-5,3.53516142403462E-7,1,0.999253354069792,40.0298881530762,1.99892676919268,15.8699993044138,0.000236370936855373,4.02548803228798E-5,0.25,-6.52756255141148E-8,2.08730585048713E-5,-4.60878376256006E-8,224.0383911,224.0383911,99.6852722167969,99.6852722167969,57.2152076076984,20.6573457101851,21.3904,0,0,0,40,4374,226.8279,99.6852722167969,,,,,,,,,,,,,0,,,,-0.0049,,,,,,224.0383911,,,,
,22821225.61,227.01337435,99.6852722167969,2.13996095928352E-5,3.28663168776861E-7,1,0.999253354069792,40.0298881530762,1.99879586635984,15.8099997788668,0.000243451197410054,3.84187791329637E-5,0.25,-3.27190925370333E-7,2.14545975483705E-5,-3.08437052893427E-7,226.9946747,227.032074,99.6852722167969,99.6852722167969,56.9322580837368,20.6539891818182,21.770052,0,0,0,40,4374,229.80675,99.6852722167969,,,,,,,,,,,,,0,,,,-0.00245,,,,,,227.01337435,,,,
,22821435.015,230.5021667,99.6852722167969,2.08500315012949E-5,3.96590367189806E-7,1,0.999253354069792,40.0298881530762,1.9989233290652,15.8099997788668,0.000236269619609411,4.27058984307691E-5,0.25,1.46575107941248E-7,2.09006874515299E-5,1.65673221748313E-7,230.5021667,230.5021667,99.6852722167969,99.6852722167969,57.027616763083,20.6581205344243,21.01075,0,0,0,40,4374,233.3061,99.6852722167969,,,,,,,,,,,,,0,,,,0,,,,,,230.5021667,,,,
,22821646.905,234.0268707,99.6852722167969,2.11250236308168E-5,3.26051744672586E-7,1,0.999253354069792,40.0298881530762,1.99882963895571,15.8099997788668,0.000239965664773561,3.96904477685214E-5,0.25,-1.65993019172479E-7,2.11740582924453E-5,-1.47732790401271E-7,234.0268707,234.0268707,99.6852722167969,99.6852722167969,57.2675767184868,20.6567703179917,21.01075,0,0,0,40,4374,236.8639,99.6852722167969,,,,,,,,,,,,,0,,,,0.0049,,,,,,234.0268707,,,,
,22821827.44,237.0224762,99.6852722167969,2.09590238036629E-5,3.5856971608722E-7,1,0.999253354069792,40.0298881530762,1.99891676685304,15.760000795126,0.000238533711756254,3.66754231898831E-5,0.25,-4.02500089007404E-7,2.100570054902E-5,-3.85172597592118E-7,237.0224762,237.0224762,99.6852722167969,99.6852722167969,57.1042163579676,20.6511893904743,21.770052,0,0,0,40,4374,239.88665,99.6852722167969,,,,,,,,,,,,,0,,,,0,,,,,,237.0224762,,,,
,22822038.655,240.5345001,99.6852722167969,2.09842346640374E-5,3.4020054904292E-7,1,0.999253354069792,40.0298881530762,1.99894171666037,15.760000795126,0.000238496486440833,3.84321839105306E-5,0.25,-2.51310442914259E-7,2.10282648001399E-5,-2.33914091490699E-7,240.5345001,240.5345001,99.6852722167969,99.6852722167969,57.0893654161022,20.6552469785945,21.770052,0,0,0,40,4374,243.4147,99.6852722167969,,,,,,,,,,,,,0,,,,0.0049,,,,,,240.5345001,,,,
,22822248.65,244.0312958,99.6852722167969,2.09080254539835E-5,4.21678786072224E-7,1,0.999253354069792,40.0298881530762,1.99890024970439,15.760000795126,0.000238136509145174,3.51740422830567E-5,0.25,-5.24612616974463E-7,2.09495641937259E-5,-5.0809291145759E-7,244.0312958,244.0312958,99.6852722167969,99.6852722167969,57.3066581444484,20.6548935013382,21.770052,0,0,0,40,4374,246.9248,99.6852722167969,,,,,,,,,,,,,0,,,,0,,,,,,244.0312958,,,,
touchdown = 9.92000009864569 mm,22822441.42,247.25,99.6852722167969,2.06779495517749E-5,4.13994182709799E-7,1,0.999253354069792,40.0298881530762,1.99889091880324,15.6999994069338,0.000234772786707287,3.89086825479961E-5,0.25,-1.54716140062571E-7,2.07163857900294E-5,-1.37914073543776E-7,247.2324371,247.2675629,99.6852722167969,99.6852722167969,57.2316218066022,20.6522464331577,22.149702,0,0,0,40,4374,250.1523,99.6852722167969,,,,,,,,,,,,,0,,,,0.0049,,,,,,247.25,,,,
,22822638.455,250.52565,99.6852722167969,2.11772468831431E-5,3.89336418830273E-7,1,0.999253354069792,40.0298881530762,1.99888226693659,15.6999994069338,0.000241379634709883,3.4269085984785E-5,0.25,-6.49845150629394E-7,2.12145640896504E-5,-6.33744607046195E-7,250.52565,250.52565,99.6852722167969,99.6852722167969,57.1808159528522,20.6529351302224,21.770052,0,0,0,40,4374,253.4296,99.6852722167969,,,,,,,,,,,,,0,,,,0,,,,,,250.52565,,,,
,22822847.785,254.0286407,99.6852722167969,2.10262318579927E-5,4.16010897753598E-7,1,0.999253354069792,40.0298881530762,1.99890999061956,15.6999994069338,0.00023809459082186,4.28860468481005E-5,0.25,1.37063321968804E-7,2.10600441670868E-5,1.54110422719609E-7,254.0286407,254.0286407,99.6852722167969,99.6852722167969,57.4403166212368,20.6521079410522,21.770052,0,0,0,40,4374,256.9381,99.6852722167969,,,,,,,,,,,,,0,,,,0.0049,,,,,,254.0286407,,,,
,22823045.66,257.2854614,99.6852722167969,,,2,,,,15.6499996417761,,,,,,,257.2854614,257.2854614,99.6852722167969,99.6852722167969,,,21.770052,,,,-99999999,4374,260.2376,99.6852722167969,,,,,,,,,,,,,,,,,,,,,,,257.2854614,,,,
,22823239,260.512207,99.6852722167969,2.04956391951828E-5,2.7834272332277E-7,1,0.999253354069792,40.0298881530762,1.99909348832475,15.6399998813868,0.00023312964660785,3.55900055466146E-5,0.25,-4.13587920401359E-7,2.0524309345694E-5,-3.982471661933E-7,260.512207,260.512207,99.6852722167969,99.6852722167969,57.70138054666,20.6493698851708,21.770052,0,0,0,40,4374,263.4775,99.6852722167969,,,,,,,,,,,,,0,,,,0,,,,,,260.512207,,,,
,22823450.525,264.0088196,99.6852722167969,2.07293989733691E-5,3.79693984087363E-7,1,0.999253354069792,40.0298881530762,1.99896209638187,15.6399998813868,0.00023512028833389,3.9589212130064E-5,0.25,-1.00387564620847E-7,2.07555665568731E-5,-8.46755791151784E-8,264.0088196,264.0088196,99.6852722167969,99.6852722167969,57.088583787583,20.6487169600694,22.149702,0,0,0,40,4374,267.01,99.6852722167969,,,,,,,,,,,,,0,,,,0,,,,,,264.0088196,,,,
,22823664,267.5480042,99.6852722167969,,,2,,,,15.5900001162291,,,,,,,267.5480042,267.5480042,99.6852722167969,99.6852722167969,,,22.149702,,,,-99999999,4374,270.5623,99.6852722167969,,,,,,,,,,,,,,,,,,,,,,,267.5480042,,,,
,22823840.845,270.5108948,99.6852722167969,2.04158517451066E-5,3.23299424405946E-7,1,0.999253354069792,40.0298881530762,1.99879476378478,15.5800003558397,0.000232334719802824,3.41148706516245E-5,0.25,-5.27699034546752E-7,2.04371993043352E-5,-5.13087287918217E-7,270.5108948,270.5108948,99.6852722167969,99.6852722167969,57.1003082153714,20.6511344058002,22.149702,0,0,0,40,4374,273.5089,99.6852722167969,,,,,,,,,,,,,0,,,,0,,,,,,270.5108948,,,,
,22824052.6,274.00149535,99.6852722167969,1.98691619308131E-5,3.76584136998528E-7,1,0.999253354069792,40.0298881530762,1.99879483633232,15.5800003558397,0.000226937509515852,2.82791021857982E-5,0.25,-9.47499063998782E-7,1.98877680490508E-5,-9.33832681045922E-7,273.9842224,274.0187683,99.6852722167969,99.6852722167969,57.3050948874099,20.6503357059226,22.149702,0,0,0,40,4374,277.0529,99.6852722167969,,,,,,,,,,,,,0,,,,0,,,,,,274.00149535,,,,
,22824264.295,277.506897,99.6852722167969,2.00166914421644E-5,3.60549819864609E-7,1,0.999253354069792,40.0298881530762,1.99883971569293,15.5800003558397,0.000227253043451567,3.62498563537523E-5,0.25,-2.68881498640678E-7,2.003241920473E-5,-2.54683827291852E-7,277.506897,277.506897,99.6852722167969,99.6852722167969,57.0182372208522,20.6534679121116,22.529354,0,0,0,40,4374,280.5929,99.6852722167969,,,,,,,,,,,,,0,,,,0,,,,,,277.506897,,,,
,22824445.9,280.519165,99.6852722167969,2.0130619403027E-5,3.5060317557075E-7,1,0.999253354069792,40.0298881530762,1.99876247394795,15.5199998989701,0.000228441298864411,3.68668464244843E-5,0.25,-2.33498712780895E-7,2.01442355284906E-5,-2.19353436156842E-7,280.519165,280.519165,99.6852722167969,99.6852722167969,57.0659165605253,20.6507035910225,22.149702,0,0,0,40,4374,283.6354,99.6852722167969,,,,,,,,,,,,,0,,,,0,,,,,,280.519165,,,,
,22824657.935,284.0160828,99.6852722167969,1.91687854583256E-5,4.02186531452459E-7,1,0.999253354069792,40.0298881530762,1.99882219035751,15.5199998989701,0.000218055029678517,3.19302943612772E-5,0.25,-5.02222278780871E-7,1.91795426770198E-5,-4.89079598586264E-7,284.0160828,284.0160828,99.6852722167969,99.6852722167969,57.1456426694868,20.6538015186212,22.149702,0,0,0,40,4374,287.1888,99.6852722167969,,,,,,,,,,,,,0,,,,0.00245,,,,,,284.0160828,,,,
,22824870.83,287.5348206,99.6852722167969,1.9259615514731E-5,4.27708728951618E-7,1,0.999253354069792,40.0298881530762,1.9988180412944,15.5199998989701,0.000218739043668195,3.39306257943662E-5,0.25,-3.40737971001385E-7,1.9267877395662E-5,-3.27600046967897E-7,287.5348206,287.5348206,99.6852722167969,99.6852722167969,57.1815975813714,20.6532438003227,22.149702,0,0,0,40,4374,290.7595,99.6852722167969,,,,,,,,,,,,,0,,,,-0.0049,,,,,,287.5348206,,,,
,22825051.4,290.5027771,99.6852722167969,1.82844905330153E-5,3.86954982798591E-7,1,0.999253354069792,40.0298881530762,1.9988064103587,15.4600003734231,0.000207460868462532,3.32481577412217E-5,0.25,-2.31552974172739E-7,1.8290325212581E-5,-2.19173326161671E-7,290.5027771,290.5027771,99.6852722167969,99.6852722167969,57.2183341217753,20.6510706602973,22.529354,0,0,0,40,4374,293.7876,99.6852722167969,,,,,,,,,,,,,0,,,,0.0049,,,,,,290.5027771,,,,
,22825263.625,294.0040436,99.6852722167969,1.86972085816692E-5,4.08683715403209E-7,1,0.999253354069792,40.0298881530762,1.99880043875808,15.4600003734231,0.000211469161817083,3.77301753056666E-5,0.25,9.34281797116967E-8,1.8700608039147E-5,1.05995153031761E-7,293.9863892,294.021698,99.6852722167969,99.6852722167969,56.9541436822753,20.653687797635,22.149702,0,0,0,40,4374,297.3519,99.6852722167969,,,,,,,,,,,,,0,,,,0,,,,,,294.0040436,,,,
,22825476.68,297.5323486,99.6852722167969,1.89770177092416E-5,3.36451646318628E-7,1,0.999253354069792,40.0298881530762,1.99891119068487,15.4600003734231,0.000215987135844709,3.03905597108555E-5,0.25,-6.03052929330698E-7,1.89785367624578E-5,-5.90531701656655E-7,297.5323486,297.5323486,99.6852722167969,99.6852722167969,57.3637170263522,20.6504261993396,22.909004,0,0,0,40,4374,300.9212,99.6852722167969,,,,,,,,,,,,,0,,,,0.00245,,,,,,297.5323486,,,,
,22825658.005,300.5203552,99.6852722167969,1.84276801705805E-5,4.19985633897089E-7,1,0.999253354069792,40.0298881530762,1.99900011112536,15.3999999165535,0.000209154773538155,3.2779020367876E-5,0.25,-2.96535668148493E-7,1.84269955396556E-5,-2.84473210031727E-7,300.5203552,300.5203552,99.6852722167969,99.6852722167969,57.0260535060445,20.6482461067832,22.529354,0,0,0,40,4374,303.95215,99.6852722167969,,,,,,,,,,,,,0,,,,0,,,,,,300.5203552,,,,
,22825870.23,304.0061035,99.6852722167969,1.87190328893805E-5,5.08965233824944E-7,1,0.999253354069792,40.0298881530762,1.99907356904181,15.3999999165535,0.000213727820945099,2.58759104892654E-5,0.25,-9.5653674506722E-7,1.87164311976876E-5,-9.44302710255133E-7,304.0061035,304.0061035,99.6852722167969,99.6852722167969,57.2269320354868,20.6494535928001,22.909004,0,0,0,40,4374,307.5315,99.6852722167969,,,,,,,,,,,,,0,,,,0.0049,,,,,,304.0061035,,,,
,22826082.855,307.526947,99.6852722167969,1.80271847101482E-5,4.3047893121644E-7,1,0.999253354069792,40.0298881530762,1.99912084357055,15.3999999165535,0.000203764766867362,3.67076434726005E-5,0.25,1.20888438111761E-7,1.80217501042655E-5,1.32318326280583E-7,307.526947,307.526947,99.6852722167969,99.6852722167969,57.1346998702176,20.6497644922201,22.529354,0,0,0,40,4374,311.0997,99.6852722167969,,,,,,,,,,,,,0,,,,0,,,,,,307.526947,,,,
,22826264.985,310.5066528,99.6852722167969,1.80730693404341E-5,4.50006355927154E-7,1,0.999253354069792,40.0298881530762,1.99914979276041,15.3400003910065,0.000204714719052752,3.41993742252843E-5,0.25,-1.08301885868904E-7,1.80658543844124E-5,-9.68948077359414E-8,310.5066528,310.5066528,99.6852722167969,99.6852722167969,57.3152560581599,20.648991772153,22.529354,0,0,0,40,4374,314.1559,99.6852722167969,,,,,,,,,,,,,0,,,,0.00245,,,,,,310.5066528,,,,
,22826477.325,314.00634765,99.6852722167969,1.78319220508225E-5,3.24965501187314E-7,1,0.999253354069792,40.0298881530762,1.99918566980144,15.3400003910065,0.000203295906721535,2.60365181076726E-5,0.25,-7.87535152976047E-7,1.78230149057923E-5,-7.76055811506748E-7,313.9883423,314.024353,99.6852722167969,99.6852722167969,57.1831608384099,20.6504316352652,22.529354,0,0,0,40,4374,317.7298,99.6852722167969,,,,,,,,,,,,,0,,,,-0.00245,,,,,,314.00634765,,,,
,22826691.9,317.5302429,99.6852722167969,1.73155168146206E-5,3.70676654989563E-7,1,0.999253354069792,40.0298881530762,1.99933273680768,15.3400003910065,0.000196111792000185,3.27055067304211E-5,0.25,-1.08350093568102E-7,1.73043052570627E-5,-9.76756152233476E-8,317.5302429,317.5302429,99.6852722167969,99.6852722167969,57.0268351345637,20.6484982607595,22.149702,0,0,0,40,4374,321.342,99.6852722167969,,,,,,,,,,,,,0,,,,0,,,,,,317.5302429,,,,
,22826872.745,320.5151367,99.6852722167969,1.7043177770256E-5,4.17961367053966E-7,1,0.999253354069792,40.0298881530762,1.99927297147238,15.2799999341369,0.000193653668610994,2.84216157711865E-5,0.25,-4.39383050200915E-7,1.70305529236177E-5,-4.28726382888553E-7,320.5151367,320.5151367,99.6852722167969,99.6852722167969,56.997133250833,20.6466173196184,22.909004,0,0,0,40,4374,324.3911,99.6852722167969,,,,,,,,,,,,,0,,,,0.0049,,,,,,320.5151367,,,,
,22827086.385,324.0239868,99.6852722167969,1.71113006340274E-5,4.72984218202086E-7,1,0.999253354069792,40.0298881530762,1.99942742499225,15.2799999341369,0.000193285106658727,3.50753680110443E-5,0.25,1.37301023011277E-7,1.70961699696358E-5,1.47416711427527E-7,324.0239868,324.0239868,99.6852722167969,99.6852722167969,57.4192126512176,20.6445772304881,22.909004,0,0,0,40,4374,327.9818,99.6852722167969,,,,,,,,,,,,,0,,,,-0.0049,,,,,,324.0239868,,,,
,22827298.79,327.5151367,99.6852722167969,1.70999022625135E-5,4.08884001161545E-7,1,0.999253354069792,40.0298881530762,1.99959541812773,15.2799999341369,0.000193693042941974,3.19049362233254E-5,0.25,-1.40768438532053E-7,1.70828613383401E-5,-1.30521500122353E-7,327.4981079,327.5321655,99.6852722167969,99.6852722167969,57.4012351952753,20.6446909283381,22.529354,0,0,0,40,4374,331.547,99.6852722167969,,,,,,,,,,,,,0,,,,0,,,,,,327.5151367,,,,
,22827479.98,330.5266113,99.6852722167969,1.63400589533243E-5,4.05097455415168E-7,1,0.999253354069792,40.0298881530762,1.99950578638032,15.2200004085898,0.000185767010206577,2.6393552818159E-5,0.25,-4.95990833901818E-7,1.63222736441684E-5,-4.85882376400582E-7,330.5266113,330.5266113,99.6852722167969,99.6852722167969,57.3144744296407,20.6413713160813,22.909004,0,0,0,40,4374,334.5795,99.6852722167969,,,,,,,,,,,,,0,,,,-0.0049,,,,,,330.5266113,,,,
,22827691.36,334.0049744,99.6852722167969,1.62762151499278E-5,4.06115012191836E-7,1,0.999253354069792,40.0298881530762,1.99967503965411,15.2200004085898,0.000183809425893714,3.33594087532966E-5,0.25,1.31228569870418E-7,1.6256173019421E-5,1.40480872803247E-7,334.0049744,334.0049744,99.6852722167969,99.6852722167969,57.4285921934484,20.6407672344712,22.909004,0,0,0,40,4374,338.1262,99.6852722167969,,,,,,,,,,,,,0,,,,-0.00245,,,,,,334.0049744,,,,
,22827903.62,337.5310974,99.6852722167969,1.57984890000899E-5,3.73817202952582E-7,1,0.999253354069792,40.0298881530762,1.99962227314347,15.2200004085898,0.000180127392943329,2.23320775486342E-5,0.25,-7.60750364097656E-7,1.57776235412604E-5,-7.50689708653859E-7,337.5310974,337.5310974,99.6852722167969,99.6852722167969,57.4473512779099,20.6424025818044,22.529354,0,0,0,40,4374,341.6821,99.6852722167969,,,,,,,,,,,,,0,,,,0,,,,,,337.5310974,,,,
,22828084.175,340.5029602,99.6852722167969,1.64145539058158E-5,4.27918860977509E-7,1,0.999253354069792,40.0298881530762,1.99963249784811,15.1599999517202,0.000186385334732563,2.75198824349337E-5,0.25,-4.08307010392566E-7,1.63909809839903E-5,-3.98414149086348E-7,340.4863281,340.5195923,99.6852722167969,99.6852722167969,57.3097846585253,20.6399342952735,22.529354,0,0,0,40,4374,344.70205,99.6852722167969,,,,,,,,,,,,,0,,,,-0.0049,,,,,,340.5029602,,,,
,22828295.895,344.0227051,99.6852722167969,1.57163715377029E-5,4.16222021864001E-7,1,0.999253354069792,40.0298881530762,1.99979281517833,15.1599999517202,0.000178712753730929,2.48291166080747E-5,0.25,-5.25210474020888E-7,1.56919869614271E-5,-5.15574006586912E-7,344.0227051,344.0227051,99.6852722167969,99.6852722167969,57.5794464976599,20.642700625075,22.909004,0,0,0,40,4374,348.24945,99.6852722167969,,,,,,,,,,,,,0,,,,0,,,,,,344.0227051,,,,
,22828507.2,347.5170593,99.6852722167969,1.45289139094381E-5,4.09615590580146E-7,1,0.999253354069792,40.0298881530762,1.99972586033181,15.1599999517202,0.00016363491432592,3.19026486031608E-5,0.25,3.06570439457991E-7,1.45042078402269E-5,3.14116746342946E-7,347.5170593,347.5170593,99.6852722167969,99.6852722167969,57.4121779945445,20.642355733675,23.288654,0,0,0,40,4374,351.7793,99.6852722167969,,,,,,,,,,,,,0,,,,-0.0049,,,,,,347.5170593,,,,
,22829009.195,349.8352051,99.6852722167969,1.54059007267319E-5,4.20904985774431E-7,1,0.999253354069792,40.0298881530762,1.99979769220739,15.089999884367,0.000174623762255673,2.73625426582888E-5,0.25,-2.46807597293917E-7,1.53788122308277E-5,-2.37822545418986E-7,349.8352051,349.8352051,99.6852722167969,99.6852722167969,57.2331850636407,20.6423158566681,22.909004,0,0,0,40,4369,351.831,99.6852722167969,,,,,,,,,,,,,0,,,,-0.00245,,,,,,349.8352051,,,,