File: data/doubleLayers/dl_0-125/ppms/data/DD213_7_HYST_100OE_300K.DAT
[Header]
; VSM Data File (default extension .dat)
; Copyright (c) 2003-2013, Quantum Design, Inc. All rights reserved.
TITLE,
FILEOPENTIME,31294532.72,12/29/2018,12:57 pm
BYAPP,VSM,2.0,2.0
INFO,PPMS VSM Option Release 1.4.10 Build 1,APPNAME
INFO,Quantum Design Linear Motor Servo Controller,MOTOR_MODULE_NAME
INFO,3101-100 M1,MOTOR_HW_VERSION
INFO,MMC1014,MOTOR_SERIAL_NUMBER
INFO,SRV No X-over 01.03.11,MOTOR_SOFTWARE_VERSION
INFO,Quantum Design VSM Detection Module,VSM_MODULE_NAME
INFO,3101-150 F0,VSM_HW_VERSION
INFO,VSM707,VSM_SERIAL_NUMBER
INFO,VSM No X-over 01.02.05 May 20 2008 13:51:47,VSM_SOFTWARE_VERSION
INFO,704,PREAMP_SERIAL_NUMBER
INFO,822,COIL_SERIAL_NUMBER
INFO,0,MOMENT_UNITS
INFO,CoFe2O4,SAMPLE_MATERIAL
INFO,Double Layer thin concentration,SAMPLE_COMMENT
INFO,29.55,SAMPLE_MASS
INFO,,SAMPLE_VOLUME
INFO,,SAMPLE_MOLECULAR_WEIGHT
INFO,,SAMPLE_SIZE
INFO,,SAMPLE_SHAPE
DATATYPE,COMMENT,1
DATATYPE,TIME,2
STARTUPAXIS,X,2
STARTUPAXIS,Y1,5
[Data]
Comment,Time Stamp (sec),Temperature (K),Magnetic Field (Oe),Moment (emu),M. Std. Err. (emu),Transport Action,Averaging Time (sec),Frequency (Hz),Peak Amplitude (mm),Center Position (mm),Coil Signal' (mV),Coil Signal" (mV),Range (mV),M. Quad. Signal (emu),M. Raw' (emu),M. Raw" (emu),Min. Temperature (K),Max. Temperature (K),Min. Field (Oe),Max. Field (Oe),Mass (grams),Motor Lag (deg),Pressure (Torr),VSM Status (code),Motor Status (code),Measure Status (code),Measure Count,PPMS Status (code),System Temp. (K),System Field (Oe),Sample Position (deg),Bridge 1 Resistance (ohms),Bridge 1 Excitation (에),Bridge 2 Resistance (ohms),Bridge 2 Excitation (에),Bridge 3 Resistance (ohms),Bridge 3 Excitation (에),Bridge 4 Resistance (ohms),Bridge 4 Excitation (에),Signal 1 Vin (V),Signal 2 Vin (V),Digital Inputs (code),Drive 1 Iout (mA),Drive 1 Ipower (W),Drive 2 Iout (mA),Drive 2 Ipower (W),Pressure (),Map 20 (),Map 21 (),Map 22 (),Map 23 (),Map 24 (),Map 25 (),Map 26 (),Map 27 (),Map 28 (),Map 29 ()
,31294548.69,300.0066528,-0.243580371141434,,,2,,,,19.6100003266335,,,,,,,300.0066528,300.0066528,-0.243580371141434,-0.243580371141434,,,28.983419,,,,-99999999,4369,300.1868,-0.243580371141434,,,,,,,,,,,,,,,,,,,,,,,300.0066528,,,,
,31294687.08,299.9943237,4409.03247070313,4.61499567239079E-5,5.62935664341554E-7,1,0.999253354069792,40.0298881530762,1.99626458638229,19.6000002324581,0.000520928950227421,9.46831109650804E-5,0.25,3.8022851173144E-7,4.61483378019499E-5,4.10822554615765E-7,299.9937744,299.994873,4381.74853515625,4436.31640625,55.8090579016021,20.5001181329431,28.603769,0,0,0,40,4449,300.19455,4409.03247070313,,,,,,,,,,,,,0,,,,0,,,,,,299.9943237,,,,
,31294782.62,299.990448,9182.73291015625,3.94941399605107E-5,7.61239607038586E-7,1,0.999253354069792,40.0298881530762,1.99613307852875,19.6000002324581,0.000444069676670923,9.08470787914845E-5,0.25,1.19458410248651E-6,3.94921862314174E-5,1.22071842024248E-6,299.990448,299.990448,9177.6884765625,9187.77734375,56.2303556734675,20.508291470806,28.224119,0,0,0,40,4449,300.2132,9182.73291015625,,,,,,,,,,,,,0,,,,-0.0049,,,,,,299.990448,,,,
,31294880.91,299.9863892,14092.5073242187,2.63857096851743E-5,7.26686279039362E-7,1,0.999253354069792,40.0298881530762,1.99605895758843,19.6000002324581,0.000295974109349162,6.47018660527048E-5,0.25,1.15287225313485E-6,2.6384175371941E-5,1.17030576305717E-6,299.9863892,299.9863892,14059.9482421875,14125.06640625,56.4570279440444,20.5119990905794,28.983419,0,0,0,40,4449,300.2295,14092.5073242187,,,,,,,,,,,,,0,,,,0.00245,,,,,,299.9863892,,,,
,31294978.015,299.99005125,18950.0830078125,1.21893357574243E-5,1.28029212773385E-6,1,0.999253354069792,40.0298881530762,1.99604695902874,19.6000002324581,0.000130497629387542,6.58591680033996E-5,0.25,3.71494753086208E-6,1.21865216415686E-5,3.72290036998887E-6,299.9897461,299.9903564,18917.578125,18982.587890625,56.5414438241214,20.5125042546629,28.603769,0,0,0,40,4449,300.23275,18950.0830078125,,,,,,,,,,,,,0,,,,0.00245,,,,,,299.99005125,,,,
,31295075.31,299.9908142,23809.9189453125,-4.54847243943665E-6,9.08618229128901E-7,1,0.999253354069792,40.0298881530762,1.99587892054306,19.6000002324581,-5.66483387939692E-5,2.13513761978063E-5,0.25,2.67725618458858E-6,-4.55010819215309E-6,2.67417262772826E-6,299.9903564,299.991272,23779.783203125,23840.0546875,56.3647957787752,20.5134101970316,28.603769,0,0,0,40,4449,300.241,23809.9189453125,,,,,,,,,,,,,0,,,,0,,,,,,299.9908142,,,,
,31295172.665,299.9899597,28677.900390625,-2.16228839547475E-5,1.30986519937757E-6,1,0.999253354069792,40.0298881530762,1.99584930936465,19.6000002324581,-0.000248566709091867,-1.81412759642557E-5,0.25,2.14111753185115E-6,-2.16236662753588E-5,2.12678314090103E-6,299.9898071,299.9901123,28653.01171875,28702.7890625,56.5242479966983,20.5138433470842,28.983419,0,0,0,40,4449,300.23905,28677.900390625,,,,,,,,,,,,,0,,,,0,,,,,,299.9899597,,,,
,31295268.225,299.99006655,33452.90234375,-3.79888184584576E-5,1.3282794833668E-6,1,0.999253354069792,40.0298881530762,1.9958985283417,19.6000002324581,-0.000434598922804188,-4.40703794873468E-5,0.25,2.68241099079599E-6,-3.79894809085154E-5,2.65728591508638E-6,299.9891663,299.9909668,33420.4296875,33485.375,56.5930313063906,20.5151489077103,28.603769,0,0,0,40,4449,300.2514,33452.90234375,,,,,,,,,,,,,0,,,,-0.00245,,,,,,299.99006655,,,,
,31295366.18,300.0006714,38350.166015625,-5.42951055321338E-5,1.73286844956781E-6,1,0.999253354069792,40.0298881530762,1.99589402581823,19.6000002324581,-0.000620685127573253,-6.56367409589551E-5,0.25,3.59931148646826E-6,-5.4295877959422E-5,3.56344707035897E-6,300.0006714,300.0006714,38347.640625,38352.69140625,56.6000659630637,20.5147058304099,28.224119,0,0,0,40,4449,300.2562,38350.166015625,,,,,,,,,,,,,0,,,,-0.0049,,,,,,300.0006714,,,,
,31295462.43,300.00057985,43160.595703125,-6.85220193788207E-5,2.08381841833769E-6,1,0.999253354069792,40.0298881530762,1.9958073086281,19.6000002324581,-0.000776055911105498,-0.000124588581798623,0.25,8.47586317514966E-7,-6.85205647573547E-5,8.02481664594114E-7,300.0000916,300.0010681,43130.86328125,43190.328125,56.6735390438714,20.5183157608165,28.603769,0,0,0,40,4449,300.25095,43160.595703125,,,,,,,,,,,,,0,,,,-0.00245,,,,,,300.00057985,,,,
,31295560.055,300.0012207,48040.490234375,-8.89052693272018E-5,1.78774681685524E-6,1,0.999253354069792,40.0298881530762,1.99573165129851,19.6000002324581,-0.00101513499656925,-0.000113956330869558,0.25,5.3194308032986E-6,-8.89061579760476E-5,5.26085052266359E-6,300.0012207,300.0012207,48008.0390625,48072.94140625,56.7071490701983,20.5211823511094,28.603769,0,0,0,40,4449,300.24645,48040.490234375,,,,,,,,,,,,,0,,,,-0.00245,,,,,,300.0012207,,,,
,31295660.195,300.0063477,53042.955078125,-0.000102989257206396,2.19752228318218E-6,1,0.999253354069792,40.0298881530762,1.99567057935648,19.6000002324581,-0.00116848230839701,-0.000174898560053944,0.25,2.36636467760732E-6,-0.000102987778601547,2.29869573566151E-6,300.0063477,300.0063477,53040.80078125,53045.109375,56.6899532427752,20.5187433921209,28.603769,0,0,0,40,4449,300.24665,53042.955078125,,,,,,,,,,,,,0,,,,0,,,,,,300.0063477,,,,
,31295758.865,300.0084534,57976.1328125,-0.000123337130000876,3.36843285182659E-6,1,0.999253354069792,40.0298881530762,1.99560435118037,19.6000002324581,-0.00139893124769795,-0.000211565320970083,0.25,2.64635514954834E-6,-0.000123335233072304,2.56541427370822E-6,300.0084534,300.0084534,57973.4609375,57978.8046875,56.3053920113137,20.5185743081919,28.603769,0,0,0,40,4449,300.2331,57976.1328125,,,,,,,,,,,,,0,,,,-0.0049,,,,,,300.0084534,,,,
,31295855.625,300.0108643,62813.943359375,-0.000138054899279986,2.81938595975465E-6,1,0.999253354069792,40.0298881530762,1.99572005114117,19.6000002324581,-0.00156881328254209,-0.00022030769264508,0.25,4.4235718557935E-6,-0.000138053728191368,4.33303463710976E-6,300.0108643,300.0108643,62806.5390625,62821.34765625,56.5899047923137,20.5182812649598,28.983419,0,0,0,40,4449,300.2276,62813.943359375,,,,,,,,,,,,,0,,,,0,,,,,,300.0108643,,,,
,31295953.57,300.0110779,67709.34375,-0.000158388881865377,2.80811163984686E-6,1,0.999253354069792,40.0298881530762,1.99550427244204,19.6000002324581,-0.00179722753033988,-0.000266982589330286,0.25,3.81372296360083E-6,-0.000158386719217131,3.71001419589244E-6,300.0110779,300.0110779,67704.1953125,67714.4921875,56.7032409276022,20.5172924889846,28.603769,0,0,0,40,4449,300.2274,67709.34375,,,,,,,,,,,,,0,,,,-0.0049,,,,,,300.0110779,,,,
,31296051.455,300.0116882,72601.73828125,-0.000174659620567007,3.00452866469609E-6,1,0.999253354069792,40.0298881530762,1.99559290495424,19.6000002324581,-0.00197980638043658,-0.000306705021326107,0.25,3.11832909771745E-6,-0.000174656530290244,3.00413180722169E-6,300.0116882,300.0116882,72596.5859375,72606.890625,56.5258112537367,20.5172958125111,28.603769,0,0,0,40,4449,300.2097,72601.73828125,,,,,,,,,,,,,0,,,,0.00245,,,,,,300.0116882,,,,
,31296147.695,300.0105591,77412.19921875,-0.000194034035737844,3.32171968168866E-6,1,0.999253354069792,40.0298881530762,1.99553623992391,19.6000002324581,-0.00219542375514908,-0.000363439873812338,0.25,1.45325971348701E-6,-0.00019402930883405,1.32660274870213E-6,300.0105591,300.0105591,77379.359375,77445.0390625,56.658688102006,20.5186904052662,28.224119,0,0,0,40,4449,300.19565,77412.19921875,,,,,,,,,,,,,0,,,,-0.0049,,,,,,300.0105591,,,,
,31296245.025,300.0114136,82278.41015625,-0.000207290278360044,3.52747955325799E-6,1,0.999253354069792,40.0298881530762,1.99543086140604,19.6000002324581,-0.00234779629416526,-0.000373813285322157,0.25,2.83005243343231E-6,-0.000207286068181318,2.69487063360541E-6,300.0114136,300.0114136,82248.3828125,82308.4375,56.8853603725829,20.5204002900159,28.603769,0,0,0,40,4449,300.1874,82278.41015625,,,,,,,,,,,,,0,,,,-0.00245,,,,,,300.0114136,,,,
,31296340.34,300.0186157,87041.1015625,-0.000225483369297735,3.88627418073226E-6,1,0.999253354069792,40.0298881530762,1.99549432419066,19.6000002324581,-0.00255389676283927,-0.000406829012053868,0.25,3.06097665571729E-6,-0.000225478733200917,2.91410806210556E-6,300.0186157,300.0186157,87011.0625,87071.140625,56.8587850029291,20.5173007085813,28.603769,0,0,0,40,4449,300.17885,87041.1015625,,,,,,,,,,,,,0,,,,0.0049,,,,,,300.0186157,,,,
,31296446.785,300.0112457,88430.41796875,-0.000233592326971555,3.27490273174724E-6,1,0.999253354069792,40.0298881530762,1.9954782318146,19.6000002324581,-0.00263955943009357,-0.000457026256607318,0.25,2.31511991342684E-8,-0.00023358554084027,-1.28861581185554E-7,300.0102844,300.012207,88403.0625,88457.7734375,56.780622151006,20.5184293219147,28.983419,0,0,0,40,4449,300.16115,88430.41796875,,,,,,,,,,,,,0,,,,0.00245,,,,,,300.0112457,,,,
,31296540.625,300.00379945,83739.34375,-0.000215507473359545,3.07494119419789E-6,1,0.999253354069792,40.0298881530762,1.99550097747185,19.6000002324581,-0.0024470208272064,-0.000353591162113277,0.25,6.04434560650991E-6,-0.00021550517946941,5.90375708490916E-6,300.0034485,300.0041504,83714.453125,83764.234375,56.8189219484483,20.5176842194738,28.603769,0,0,0,40,4449,300.1645,83739.34375,,,,,,,,,,,,,0,,,,0,,,,,,300.00379945,,,,
,31296637.775,299.9969482,78883.05859375,-0.000196762722381512,3.3718293250662E-6,1,0.999253354069792,40.0298881530762,1.99517418598796,19.6000002324581,-0.0022261328257964,-0.000367220787826649,0.25,1.58575774649961E-6,-0.000196758101240168,1.45735316575644E-6,299.9969482,299.9969482,78850.5859375,78915.53125,56.976810909333,20.5223970682392,28.983419,0,0,0,40,4449,300.17055,78883.05859375,,,,,,,,,,,,,0,,,,-0.0049,,,,,,299.9969482,,,,
,31296735.43,299.9927979,73999.46484375,-0.000178484836919788,3.72965785798128E-6,1,0.999253354069792,40.0298881530762,1.99535752693345,19.6000002324581,-0.002016297963378,-0.000351723321872365,0.25,-2.06288509299419E-7,-0.000178479585967184,-3.22859759109029E-7,299.9927979,299.9927979,73996.8828125,74002.046875,56.8384626614291,20.5210824660753,28.603769,0,0,0,40,4449,300.1793,73999.46484375,,,,,,,,,,,,,0,,,,-0.0049,,,,,,299.9927979,,,,
,31296832.345,299.9897156,69156.19140625,-0.000162516738982126,2.03874123900222E-6,1,0.999253354069792,40.0298881530762,1.99543023100217,19.6000002324581,-0.00184020047926659,-0.000295874349396549,0.25,1.97110644179175E-6,-0.000162513376203554,1.86477581071617E-6,299.9897156,299.9897156,69123.796875,69188.5859375,56.8322096332752,20.5192484903812,28.603769,0,0,0,40,4449,300.1881,69156.19140625,,,,,,,,,,,,,0,,,,-0.00245,,,,,,299.9897156,,,,
,31296927.1,299.9886475,64420.669921875,-0.000145622978071171,2.72719794116222E-6,1,0.999253354069792,40.0298881530762,1.99542456031544,19.6000002324581,-0.00165210772880944,-0.000246633931694241,0.25,3.40210307472659E-6,-0.000145621032716653,3.30666447422946E-6,299.9886475,299.9886475,64390.64453125,64450.6953125,56.7634263235829,20.5204734914991,28.983419,0,0,0,40,4449,300.18425,64420.669921875,,,,,,,,,,,,,0,,,,0.00245,,,,,,299.9886475,,,,
,31297020.675,299.993927,59742.298828125,-0.000129603764070021,2.8528415324571E-6,1,0.999253354069792,40.0298881530762,1.99519118395496,19.6000002324581,-0.00146726745263537,-0.000236425742877587,0.25,1.52793936253395E-6,-0.000129601018922638,1.44294884525112E-6,299.993927,299.993927,59717.29296875,59767.3046875,56.8955215433329,20.5239451432219,28.603769,0,0,0,40,4449,300.19855,59742.298828125,,,,,,,,,,,,,0,,,,-0.00245,,,,,,299.993927,,,,
,31297121.1,299.9811401,54724.814453125,-0.000111612359913745,3.32049399731225E-6,1,0.999253354069792,40.0298881530762,1.99540049846355,19.6000002324581,-0.00126005196264324,-0.000224743148109922,0.25,-5.5298233032963E-7,-0.000111608813723644,-6.26211259234773E-7,299.9811401,299.9811401,54719.94921875,54729.6796875,56.8791073444291,20.5228555972949,28.983419,0,0,0,40,4449,300.1942,54724.814453125,,,,,,,,,,,,,0,,,,0,,,,,,299.9811401,,,,
,31297221.305,299.9863281,49712.515625,-9.37618122862471E-5,1.87552137333489E-6,1,0.999253354069792,40.0298881530762,1.9953400655255,19.6000002324581,-0.00108457087754512,-3.82960943286633E-5,0.25,1.28551862021927E-5,-9.37675599228543E-5,1.27932194335792E-5,299.9863281,299.9863281,49687.59765625,49737.43359375,56.6454004171791,20.5268020992389,28.224119,0,0,0,40,4449,300.22405,49712.515625,,,,,,,,,,,,,0,,,,0.00245,,,,,,299.9863281,,,,
,31297318.61,299.9899597,44852.1328125,-8.00014598849972E-5,1.84775202859866E-6,1,0.999253354069792,40.0298881530762,1.9953658445977,19.6000002324581,-0.000920423831115377,-6.14678280910196E-5,0.25,8.42048990439749E-6,-8.00046805314053E-5,8.36763058722137E-6,299.9899597,299.9899597,44824.74609375,44879.51953125,56.7485753817175,20.5255380731592,28.603769,0,0,0,40,4449,300.2314,44852.1328125,,,,,,,,,,,,,0,,,,0,,,,,,299.9899597,,,,
,31297417.58,299.9898987,39904.2890625,-6.33811288689368E-5,1.6567968412107E-6,1,0.999253354069792,40.0298881530762,1.99526568513165,19.6000002324581,-0.000730367883254194,-4.17846151849776E-5,0.25,7.28284408408259E-6,-6.33840840597527E-5,7.24090170349517E-6,299.9898987,299.9898987,39901.97265625,39906.60546875,56.719655126506,20.5260373605659,28.983419,0,0,0,40,4449,300.2371,39904.2890625,,,,,,,,,,,,,0,,,,0,,,,,,299.9898987,,,,
,31297512.71,299.9905701,35149.458984375,-4.56250242362641E-5,1.34506543958692E-6,1,0.999253354069792,40.0298881530762,1.99541559552711,19.6000002324581,-0.000531263389857441,1.48519965689292E-6,0.25,8.03623084679576E-6,-4.56289924771085E-5,8.00592608434334E-6,299.9905701,299.9905701,35124.640625,35174.27734375,56.8486238321791,20.5264835074293,28.603769,0,0,0,40,4449,300.2486,35149.458984375,,,,,,,,,,,,,0,,,,0,,,,,,299.9905701,,,,
,31297610.975,299.9844055,30239.5634765625,-2.69226150521163E-5,1.00786038878436E-6,1,0.999253354069792,40.0298881530762,1.99544876932429,19.6000002324581,-0.000315875234764471,1.4612898835428E-5,0.25,5.95774749906071E-6,-2.6925766287658E-5,5.93981223569809E-6,299.9844055,299.9844055,30237.099609375,30242.02734375,56.8939582862945,20.5267628292174,28.603769,0,0,0,40,4449,300.2569,30239.5634765625,,,,,,,,,,,,,0,,,,0,,,,,,299.9844055,,,,
,31297710.77,299.9897156,25249.4296875,-9.28780505586628E-6,9.53129470061763E-7,1,0.999253354069792,40.0298881530762,1.99550335714735,19.6000002324581,-0.000118001018147962,5.71434613667596E-5,0.25,6.6662202676176E-6,-9.29193650900978E-6,6.65989144071057E-6,299.9897156,299.9897156,25219.443359375,25279.416015625,56.7868751791599,20.5276105141509,28.224119,0,0,0,40,4449,300.26345,25249.4296875,,,,,,,,,,,,,0,,,,0.00245,,,,,,299.9897156,,,,
,31297808.03,299.9907837,20389.40625,5.85018656758849E-6,1.10857810375671E-6,1,0.999253354069792,40.0298881530762,1.99545888201722,19.6000002324581,5.68665520969479E-5,6.47715622796574E-5,0.25,4.71864362343318E-6,5.84689580932426E-6,4.72237274849794E-6,299.9907837,299.9907837,20361.8515625,20416.9609375,56.9885353371214,20.526142423023,28.983419,0,0,0,40,4449,300.27685,20389.40625,,,,,,,,,,,,,0,,,,0.00245,,,,,,299.9907837,,,,
,31297903.835,299.9894867,15602.2290039062,2.06604120178878E-5,8.50037756404552E-7,1,0.999253354069792,40.0298881530762,1.99550383104598,19.6000002324581,0.000226327844839005,8.16020206556903E-5,0.25,3.64197478572328E-6,2.06573967712154E-5,3.65553830980749E-6,299.9894409,299.9895325,15574.7431640625,15629.71484375,57.1558038402368,20.5245719149761,28.224119,0,0,0,40,4449,300.28455,15602.2290039062,,,,,,,,,,,,,0,,,,0,,,,,,299.9894867,,,,
,31297999.375,299.9940491,10827.3315429688,3.53642291331648E-5,7.30041862481898E-7,1,0.999253354069792,40.0298881530762,1.99565707556635,19.6000002324581,0.000395509407277548,9.30640923383804E-5,0.25,2.10815808737879E-6,3.53617889617423E-5,2.1315157212268E-6,299.9940491,299.9940491,10797.22265625,10857.4404296875,56.6641595016406,20.5202168606809,28.603769,0,0,0,40,4449,300.2823,10827.3315429688,,,,,,,,,,,,,0,,,,0.00245,,,,,,299.9940491,,,,
,31298093.615,299.9929199,6116.93505859375,4.57961059758576E-5,5.38747374468602E-7,1,0.999253354069792,40.0298881530762,1.99553699634206,19.6000002324581,0.000516450724150671,9.56805577746852E-5,0.25,5.32739923306053E-7,4.57944006426323E-5,5.63075752837151E-7,299.9929199,299.9929199,6094.4814453125,6139.388671875,57.2066096939868,20.5256608698495,28.983419,0,0,0,40,4449,300.28795,6116.93505859375,,,,,,,,,,,,,0,,,,0.00245,,,,,,299.9929199,,,,
,31298183.815,299.99343875,1608.31097412109,4.30426551809224E-5,4.48148240277163E-7,1,0.999253354069792,40.0298881530762,1.99557039932938,19.6000002324581,0.000486765825651973,8.208831842371E-5,0.25,-1.93190540348739E-7,4.30415099599134E-5,-1.64640575471407E-7,299.9933167,299.9935608,1581.11804199219,1635.50390625,56.8275198621599,20.5217111221172,28.983419,0,0,0,40,4449,300.29405,1608.31097412109,,,,,,,,,,,,,0,,,,0.00245,,,,,,299.99343875,,,,
,31298272.235,299.99784855,-2806.84460449219,-4.49263034035561E-5,4.75774839642581E-7,1,0.999253354069792,40.0298881530762,1.99547635078627,19.6000002324581,-0.000506077631713454,-9.70313747994307E-5,0.25,-8.03220378847339E-7,-4.49244350576628E-5,-8.32985295614563E-7,299.997345,299.9983521,-2836.79858398438,-2776.890625,57.0565370182945,20.523547915931,28.603769,0,0,0,40,4449,300.29445,-2806.84460449219,,,,,,,,,,,,,0,,,,0.00245,,,,,,299.99784855,,,,
,31298363.66,299.999176,-7379.46899414062,-4.24944561880133E-5,6.01218391807258E-7,1,0.999253354069792,40.0298881530762,1.99557922518451,19.6000002324581,-0.000476816670770875,-0.000102696090716268,0.25,-1.72545232503924E-6,-4.24920491150858E-5,-1.75355830000607E-6,299.999176,299.999176,-7411.83935546875,-7347.0986328125,56.4679707433137,20.5240867852307,28.603769,0,0,0,40,4449,300.2915,-7379.46899414062,,,,,,,,,,,,,0,,,,-0.00245,,,,,,299.999176,,,,
,31298457.76,299.9977417,-12082.9282226563,-3.00436844261093E-5,6.08132303016919E-7,1,0.999253354069792,40.0298881530762,1.99550163268338,19.6000002324581,-0.000335757860655299,-8.03390831282557E-5,0.25,-1.90447717219872E-6,-3.00415330920642E-5,-1.9243114829024E-6,299.9977417,299.9977417,-12090.43359375,-12075.4228515625,57.0018230219483,20.5228412550739,28.603769,0,0,0,40,4449,300.29705,-12082.9282226563,,,,,,,,,,,,,0,,,,0,,,,,,299.9977417,,,,
,31298550.665,300.0021057,-16727.568359375,-1.7971028820149E-5,8.64853756809513E-7,1,0.999253354069792,40.0298881530762,1.99561013474671,19.6000002324581,-0.000197665730947954,-6.64280965249958E-5,0.25,-2.76478724301167E-6,-1.79686653520496E-5,-2.77659289724552E-6,300.0021057,300.0021057,-16757.373046875,-16697.763671875,57.0151107067753,20.5224352639245,28.603769,0,0,0,40,4449,300.2919,-16727.568359375,,,,,,,,,,,,,0,,,,0,,,,,,300.0021057,,,,
,31298645.22,300.0084839,-21449.8017578125,-2.36679049904873E-6,1.10817388453722E-6,1,0.999253354069792,40.0298881530762,1.9955164494262,19.6000002324581,-1.98031821057073E-5,-4.46964055412997E-5,0.25,-3.54542653985218E-6,-2.36437651312433E-6,-3.54688467125228E-6,300.0084839,300.0084839,-21474.76953125,-21424.833984375,56.6743206723906,20.5242900882742,28.603769,0,0,0,40,4449,300.288,-21449.8017578125,,,,,,,,,,,,,0,,,,0,,,,,,300.0084839,,,,
,31298741.025,300.0112,-26239.7919921875,1.45224249056556E-5,1.0885454788856E-6,1,0.999253354069792,40.0298881530762,1.99559176063263,19.6000002324581,0.000172321168644814,-1.89778331721995E-5,0.25,-4.19552614006311E-6,1.45247599601178E-5,-4.18581179999154E-6,300.0112,300.0112,-26242.447265625,-26237.13671875,56.926005055583,20.5237693184284,28.983419,0,0,0,40,4449,300.2825,-26239.7919921875,,,,,,,,,,,,,0,,,,0.00245,,,,,,300.0112,,,,
,31298836.545,300.012207,-31014.75390625,2.94310573108386E-5,1.15830959385667E-6,1,0.999253354069792,40.0298881530762,1.99566447005553,19.6000002324581,0.000343852646342501,-7.38362080037602E-6,0.25,-5.75249156367873E-6,2.94339706601184E-5,-5.73290573987863E-6,300.012207,300.012207,-31039.69921875,-30989.80859375,56.8048526351022,20.5239471479353,28.224119,0,0,0,40,4449,300.26875,-31014.75390625,,,,,,,,,,,,,0,,,,-0.00245,,,,,,300.012207,,,,
,31298932.745,300.009613,-35822.072265625,4.90103828006524E-5,1.47456327709702E-6,1,0.999253354069792,40.0298881530762,1.99561015764056,19.6000002324581,0.000563502839811788,4.01508901806467E-5,0.25,-4.93824932367969E-6,4.90121770503155E-5,-4.90580616346016E-6,300.009613,300.009613,-35851.99609375,-35792.1484375,57.2144259791791,20.5240868800085,28.224119,0,0,0,40,4449,300.25755,-35822.072265625,,,,,,,,,,,,,0,,,,0,,,,,,300.009613,,,,
,31299027.245,300.01669315,-40544.61328125,6.28611463971486E-5,1.46835285334933E-6,1,0.999253354069792,40.0298881530762,1.99585339664753,19.6000002324581,0.000725451924546878,3.64142351016441E-5,0.25,-7.66896808087992E-6,6.286431016793E-5,-7.62735679462751E-6,300.0166321,300.0167542,-40569.42578125,-40519.80078125,56.9799374234099,20.5255599448567,28.603769,0,0,0,40,4449,300.2444,-40544.61328125,,,,,,,,,,,,,0,,,,0.0049,,,,,,300.01669315,,,,
,31299121.98,300.014801,-45279.642578125,7.87621779403878E-5,1.49286005305178E-6,1,0.999253354069792,40.0298881530762,1.99569070636884,19.6000002324581,0.000906697515728916,5.82640180966323E-5,0.25,-8.49011663498501E-6,7.87654098742605E-5,-8.43806903548138E-6,300.014801,300.014801,-45307.19140625,-45252.09375,57.1776894387753,20.5240068542332,28.224119,0,0,0,40,4449,300.2364,-45279.642578125,,,,,,,,,,,,,0,,,,0.00245,,,,,,300.014801,,,,
,31299218.145,300.01469425,-50084.578125,9.58584265781758E-5,2.01219302635037E-6,1,0.999253354069792,40.0298881530762,1.99543657035634,19.6000002324581,0.00110592920297544,5.61460524949883E-5,0.25,-1.16388550474817E-5,9.58632169584252E-5,-1.15755397733434E-5,300.014679,300.0147095,-50109.58203125,-50059.57421875,56.8368994043906,20.5286483720209,28.603769,0,0,0,40,4449,300.2243,-50084.578125,,,,,,,,,,,,,0,,,,0,,,,,,300.01469425,,,,
,31299314.655,300.0077515,-54908.95703125,0.00011313999039632,1.81243003558921E-6,1,0.999253354069792,40.0298881530762,1.99540188866004,19.6000002324581,0.00130334306814099,7.74881450060942E-5,0.25,-1.27439671927564E-5,0.000113145018237982,-1.26693551641969E-5,300.0077515,300.0077515,-54911.37109375,-54906.54296875,56.8806706014676,20.5279996802226,28.603769,0,0,0,40,4449,300.2196,-54908.95703125,,,,,,,,,,,,,0,,,,0,,,,,,300.0077515,,,,
,31299408.29,300.01179505,-59586.203125,0.00013100264153256,1.58268848300001E-6,1,0.999253354069792,40.0298881530762,1.99555552696392,19.6000002324581,0.00150561846563514,0.000110555721695973,0.25,-1.2912805378458E-5,0.00013100723383713,-1.28265621890859E-5,300.0116882,300.0119019,-59618.66796875,-59553.73828125,56.7305979257752,20.528321515747,28.603769,0,0,0,40,4449,300.21295,-59586.203125,,,,,,,,,,,,,0,,,,0.00245,,,,,,300.01179505,,,,
,31299504.705,300.0192871,-64406.232421875,0.000150621399510567,2.18316033026166E-6,1,0.999253354069792,40.0298881530762,1.9954135161262,19.6000002324581,0.00172638052348295,0.000153649160574853,0.25,-1.2497191791306E-5,0.000150625099845689,-1.23982134396141E-5,300.0192871,300.0192871,-64441.18359375,-64371.28125,56.9908802226791,20.5293695817678,28.603769,0,0,0,40,4449,300.2034,-64406.232421875,,,,,,,,,,,,,0,,,,-0.0049,,,,,,300.0192871,,,,
,31299602.32,300.0130615,-69283.359375,0.00016689695080523,2.43377948975804E-6,1,0.999253354069792,40.0298881530762,1.99559444792994,19.6000002324581,0.00191200028456914,0.000176570083402883,0.25,-1.3289650382652E-5,0.000166900724211845,-1.31801229187038E-5,300.0130615,300.0130615,-69313.3125,-69253.40625,57.014329078256,20.5266696266417,28.603769,0,0,0,40,4449,300.1858,-69283.359375,,,,,,,,,,,,,0,,,,0,,,,,,300.0130615,,,,
,31299700.38,300.0154419,-74185.2109375,0.000189394641780029,1.85413553968575E-6,1,0.999253354069792,40.0298881530762,1.99557567978924,19.6000002324581,0.00216408708687858,0.000232872057940478,0.25,-1.22046949868879E-5,0.000189397030289776,-1.20806338052362E-5,300.0154419,300.0154419,-74215.2421875,-74155.1796875,56.8157954343714,20.5264017543664,28.603769,0,0,0,40,4449,300.16995,-74185.2109375,,,,,,,,,,,,,0,,,,0,,,,,,300.0154419,,,,
,31299796.56,300.0147095,-78992.53125,0.000201322180362783,2.80088173978524E-6,1,0.999253354069792,40.0298881530762,1.99562066642062,19.6000002324581,0.00230814479021092,0.000202982659115409,0.25,-1.69164000026618E-5,0.000201327300719275,-1.67845690828173E-5,300.0147095,300.0147095,-79017.625,-78967.4375,56.9400743689291,20.5277527905458,28.603769,0,0,0,40,4449,300.1621,-78992.53125,,,,,,,,,,,,,0,,,,0.00245,,,,,,300.0147095,,,,
,31299893.995,300.01293945,-83862.015625,0.000222334805973011,3.46095549012982E-6,1,0.999253354069792,40.0298881530762,1.99559336094758,19.6000002324581,0.00254955494703741,0.000221077693212316,0.25,-1.8955103870446E-5,0.000222340653638872,-1.88096868080824E-5,300.0126038,300.0132751,-83894.5390625,-83829.4921875,56.7892200647175,20.5273866654261,28.983419,0,0,0,40,4449,300.15505,-83862.015625,,,,,,,,,,,,,0,,,,0.00245,,,,,,300.01293945,,,,
,31299985.5,300.0110321,-88434.1015625,0.000241004233009466,1.99487462180086E-6,1,0.999253354069792,40.0298881530762,1.99566171782068,19.6000002324581,0.00275777207357214,0.000274046829704556,0.25,-1.75027335353135E-5,0.00024100860778004,-1.73453806226031E-5,300.0109863,300.0110779,-88461.6015625,-88406.6015625,56.9205336559483,20.5271525092162,28.224119,0,0,0,40,4449,300.1478,-88434.1015625,,,,,,,,,,,,,0,,,,-0.00245,,,,,,300.0110321,,,,
,31300091,300.0090637,-87061.5078125,0.00023262309008719,3.24842647051754E-6,1,0.999253354069792,40.0298881530762,1.9956370224278,19.6000002324581,0.00265857727860615,0.000283327539678825,0.25,-1.52292381607081E-5,0.000232626244313329,-1.5077345303282E-5,300.0090637,300.0090637,-87088.9453125,-87034.0703125,56.7493570102368,20.5271329238137,28.224119,0,0,0,40,4449,300.13645,-87061.5078125,,,,,,,,,,,,,0,,,,-0.00245,,,,,,300.0090637,,,,
,31300185.05,300.0021667,-82359.59765625,0.000216172568050059,2.1342099194292E-6,1,0.999253354069792,40.0298881530762,1.99580803320095,19.6000002324581,0.00247758244881981,0.000224002526742939,0.25,-1.76307925356873E-5,0.000216177816267427,-1.74893674911941E-5,300.0021667,300.0021667,-82392.125,-82327.0703125,56.8798889729483,20.525038942453,28.983419,0,0,0,40,4449,300.13125,-82359.59765625,,,,,,,,,,,,,0,,,,0,,,,,,300.0021667,,,,
,31300280.04,300.00039675,-77612.015625,0.000198585554030687,2.03959493496267E-6,1,0.999253354069792,40.0298881530762,1.99579090882319,19.6000002324581,0.00227442884659779,0.00021482736809541,0.25,-1.53957352709809E-5,0.00019858986422722,-1.52656826605127E-5,299.9996033,300.0011902,-77639.5703125,-77584.4609375,56.8454973181022,20.5241943178061,28.603769,0,0,0,40,4449,300.1361,-77612.015625,,,,,,,,,,,,,0,,,,-0.00245,,,,,,300.00039675,,,,
,31300380.365,299.9917603,-72599.59375,0.00018418610969596,3.3292583299229E-6,1,0.999253354069792,40.0298881530762,1.99566748122392,19.6000002324581,0.00210247409686555,0.000239134466563155,0.25,-1.07491339234628E-5,0.000184187856113058,-1.06284726219511E-5,299.9917603,299.9917603,-72627.171875,-72572.015625,56.7579549239483,20.5251737551684,28.983419,0,0,0,40,4449,300.15885,-72599.59375,,,,,,,,,,,,,0,,,,-0.00245,,,,,,299.9917603,,,,
,31300475.53,299.99258425,-67843.11328125,0.000166300657339185,2.05935010770028E-6,1,0.999253354069792,40.0298881530762,1.9955677285536,19.6000002324581,0.00190724961588729,0.000163795596480892,0.25,-1.43166772833257E-5,0.000166305242090853,-1.42074681003777E-5,299.9923096,299.9928589,-67870.4375,-67815.7890625,56.7790588939676,20.5237224607854,28.224119,0,0,0,40,4449,300.15715,-67843.11328125,,,,,,,,,,,,,0,,,,-0.00245,,,,,,299.99258425,,,,
,31300572.53,299.9930725,-62995.892578125,0.000147544480218691,1.90986064379709E-6,1,0.999253354069792,40.0298881530762,1.99568234760498,19.6000002324581,0.00169177931573472,0.000147952557252808,0.25,-1.24700128442102E-5,0.000147548393033621,-1.23730123594379E-5,299.9930725,299.9930725,-62998.2265625,-62993.55859375,56.8400259184676,20.5263039970803,28.603769,0,0,0,40,4449,300.16395,-62995.892578125,,,,,,,,,,,,,0,,,,0,,,,,,299.9930725,,,,
,31300668.755,299.9901123,-58188.328125,0.000130351070539619,2.6142133987255E-6,1,0.999253354069792,40.0298881530762,1.99570511364492,19.6000002324581,0.00149066686504943,0.00015371561650517,0.25,-8.98150791656993E-6,0.000130353206131655,-8.89577235466054E-6,299.9901123,299.9901123,-58190.41796875,-58186.23828125,56.7759323798906,20.5225346017895,28.603769,0,0,0,40,4449,300.1736,-58188.328125,,,,,,,,,,,,,0,,,,0,,,,,,299.9901123,,,,
,31300764.985,299.9885559,-53376.072265625,0.000110740969855728,1.54380168783069E-6,1,0.999253354069792,40.0298881530762,1.99546554998369,19.6000002324581,0.0012721875065304,9.63908990120476E-5,0.25,-1.0655710900246E-5,0.000110744774820698,-1.05827039189708E-5,299.9885559,299.9885559,-53378.578125,-53373.56640625,56.8126689202945,20.5254530646541,28.603769,0,0,0,40,4449,300.1815,-53376.072265625,,,,,,,,,,,,,0,,,,0,,,,,,299.9885559,,,,
,31300860.25,299.9906921,-48616.076171875,9.34834077365147E-5,1.2926447340549E-6,1,0.999253354069792,40.0298881530762,1.99557207176584,19.6000002324581,0.00107881689444824,5.35020333468228E-5,0.25,-1.14617127906353E-5,9.34882341022874E-5,-1.13999423760225E-5,299.9906921,299.9906921,-48620.88671875,-48611.265625,56.6837002146214,20.5235186290156,28.224119,0,0,0,40,4449,300.18785,-48616.076171875,,,,,,,,,,,,,0,,,,0,,,,,,299.9906921,,,,
,31300958.075,299.9816589,-43725.880859375,7.61279413591469E-5,1.95701480332288E-6,1,0.999253354069792,40.0298881530762,1.9956561965875,19.6000002324581,0.00087546199243953,6.14930011072984E-5,0.25,-7.74793525546008E-6,7.61308548136566E-5,-7.69762645207723E-6,299.9816589,299.9816589,-43728.38671875,-43723.375,56.9017745714868,20.5232247751376,28.603769,0,0,0,40,4449,300.2029,-43725.880859375,,,,,,,,,,,,,0,,,,0.0049,,,,,,299.9816589,,,,
,31301057.36,299.9843903,-38766.458984375,5.90475791376106E-5,1.49966292317739E-6,1,0.999253354069792,40.0298881530762,1.99551755028559,19.6000002324581,0.000681792276967108,3.15466266218689E-5,0.25,-7.4385229962751E-6,5.90507747982599E-5,-7.39941745561761E-6,299.9836121,299.9851685,-38796.37890625,-38736.5390625,56.976810909333,20.5247259634812,28.983419,0,0,0,40,4449,300.216,-38766.458984375,,,,,,,,,,,,,0,,,,0,,,,,,299.9843903,,,,
,31301156.24,299.9882202,-33824.6171875,4.53745247854822E-5,1.12729775381417E-6,1,0.999253354069792,40.0298881530762,1.99552570538523,19.6000002324581,0.000522857337416977,3.03664882590593E-5,0.25,-5.1740779429945E-6,4.53766180416721E-5,-5.14400983723363E-6,299.9882202,299.9882202,-33854.703125,-33794.53125,57.0354330482753,20.5199621222041,28.983419,0,0,0,40,4449,300.2201,-33824.6171875,,,,,,,,,,,,,0,,,,-0.0049,,,,,,299.9882202,,,,
,31301251.255,299.99157715,-29075.1220703125,2.3284010313042E-5,1.09217450466614E-6,1,0.999253354069792,40.0298881530762,1.99567016396141,19.6000002324581,0.00027546427935593,-2.563083861484E-5,0.25,-6.30218600083927E-6,2.32874891654606E-5,-6.28663405229571E-6,299.9912415,299.9919128,-29107.58203125,-29042.662109375,56.973684395256,20.5231733308142,28.983419,0,0,0,40,4449,300.22755,-29075.1220703125,,,,,,,,,,,,,0,,,,0.00245,,,,,,299.99157715,,,,
,31301345.055,299.9925842,-24387.5224609375,8.01846106091912E-6,8.48432234663568E-7,1,0.999253354069792,40.0298881530762,1.99572797977668,19.6000002324581,9.9138358620377E-5,-3.34859743190584E-5,0.25,-4.35235700970183E-6,8.02110127138407E-6,-4.34693202129358E-6,299.9925842,299.9925842,-24414.84765625,-24360.197265625,56.7563916669098,20.5219453580882,28.983419,0,0,0,40,4449,300.23415,-24387.5224609375,,,,,,,,,,,,,0,,,,0,,,,,,299.9925842,,,,
,31301439.615,299.9947205,-19662.59765625,-7.43888814387083E-6,8.64718270506169E-7,1,0.999253354069792,40.0298881530762,1.9955631729213,19.6000002324581,-7.77108650767774E-5,-5.12105298651212E-5,0.25,-3.24302157841822E-6,-7.43652458189076E-6,-3.24784498626914E-6,299.9947205,299.9947205,-19687.58203125,-19637.61328125,56.7446672391214,20.5203561843157,28.224119,0,0,0,40,4449,300.24545,-19662.59765625,,,,,,,,,,,,,0,,,,-0.00245,,,,,,299.9947205,,,,
,31301534.295,299.9888153,-14930.24609375,-2.25478626731035E-5,7.93467773981462E-7,1,0.999253354069792,40.0298881530762,1.99566475145435,19.6000002324581,-0.000249654435656118,-7.38771403140366E-5,0.25,-2.63081986347267E-6,-2.25454608470312E-5,-2.6456660334156E-6,299.988739,299.9888916,-14960.3720703125,-14900.1201171875,57.0080760501022,20.5207665873333,28.603769,0,0,0,40,4449,300.2463,-14930.24609375,,,,,,,,,,,,,0,,,,0,,,,,,299.9888153,,,,
,31301627.955,299.9894409,-10247.548828125,-3.64711518488012E-5,6.19922501800167E-7,1,0.999253354069792,40.0298881530762,1.99564883916696,19.6000002324581,-0.00040791040575955,-9.58448015935926E-5,0.25,-2.1624687348677E-6,-3.64686483556879E-5,-2.18656292999466E-6,299.9894409,299.9894409,-10267.4697265625,-10227.6279296875,57.2441278629099,20.5185402932118,28.983419,0,0,0,40,4449,300.2579,-10247.548828125,,,,,,,,,,,,,0,,,,0,,,,,,299.9894409,,,,
,31301719.035,299.9886475,-5694.33081054687,-4.50516495011767E-5,5.49743519658879E-7,1,0.999253354069792,40.0298881530762,1.99556603883178,19.6000002324581,-0.000506210344883253,-0.000104816504469716,0.25,-1.4700834506461E-6,-4.50493512543062E-5,-1.49990316741939E-6,299.9886475,299.9886475,-5724.0771484375,-5664.58447265625,56.7470121246791,20.5194629092144,28.983419,0,0,0,40,4449,300.2644,-5694.33081054687,,,,,,,,,,,,,0,,,,-0.00245,,,,,,299.9886475,,,,
,31301807.945,300.0005798,-1249.91107177734,-4.10286370335893E-5,5.31645599302707E-7,1,0.999253354069792,40.0298881530762,1.99566660584132,19.6000002324581,-0.000463198326920131,-8.29395776968143E-5,0.25,-2.30749460524469E-7,-4.10272593124853E-5,-2.57955535354209E-7,300.0005798,300.0005798,-1274.91662597656,-1224.90551757812,56.7853119221214,20.5177062302136,28.603769,0,0,0,40,4449,300.2643,-1249.91107177734,,,,,,,,,,,,,0,,,,0,,,,,,300.0005798,,,,
,31301898.305,299.99780275,3262.35375976562,4.56315899019993E-5,4.89562849643374E-7,1,0.999253354069792,40.0298881530762,1.99575854509712,19.6000002324581,0.000514955138424826,9.35850150808806E-5,0.25,3.74905252249248E-7,4.56299844812221E-5,4.05152364753121E-7,299.9976807,299.9979248,3232.56787109375,3292.1396484375,57.3410497992945,20.5168207645163,28.983419,0,0,0,40,4449,300.2635,3262.35375976562,,,,,,,,,,,,,0,,,,0,,,,,,299.99780275,,,,
,31301988.63,299.99699405,7780.07836914062,4.19112482881066E-5,5.1073105409348E-7,1,0.999253354069792,40.0298881530762,1.99572699433977,19.6000002324581,0.000471679051865048,9.33687240012677E-5,0.25,1.00049509209266E-6,4.19093420935813E-5,1.02823727959857E-6,299.9961243,299.9978638,7752.5322265625,7807.62451171875,56.790783321756,20.5173004188284,29.363071,0,0,0,40,4449,300.2656,7780.07836914062,,,,,,,,,,,,,0,,,,-0.0049,,,,,,299.99699405,,,,
,31302081.27,299.9976501,12407.8813476563,2.8477063335647E-5,9.43014824803724E-7,1,0.999253354069792,40.0298881530762,1.99561080638167,19.6000002324581,0.000319032426165773,7.17328640112733E-5,0.25,1.4139464130172E-6,2.84752830953544E-5,1.43275945012946E-6,299.9976501,299.9976501,12380.3310546875,12435.431640625,57.0455942190253,20.5166868690991,28.603769,0,0,0,40,4449,300.2635,12407.8813476563,,,,,,,,,,,,,0,,,,0,,,,,,299.9976501,,,,
,31302174.67,300.0030823,17075.9677734375,1.61001256828379E-5,9.72040696697263E-7,1,0.999253354069792,40.0298881530762,1.99556767883713,19.6000002324581,0.000176880940897224,6.06822176762471E-5,0.25,2.58057567424628E-6,1.60979390116977E-5,2.59114968089011E-6,300.0030823,300.0030823,17043.74609375,17108.189453125,56.4914195988906,20.5173037351606,28.603769,0,0,0,40,4449,300.26105,17075.9677734375,,,,,,,,,,,,,0,,,,0,,,,,,300.0030823,,,,
,31302267.82,300.0075989,21732.96484375,2.95181483951906E-7,8.56690578985635E-7,1,0.999253354069792,40.0298881530762,1.99559246714633,19.6000002324581,-4.43985545556906E-6,4.54560987082077E-5,0.25,3.97143228329612E-6,2.92547738569014E-7,3.97150866595158E-6,300.0075989,300.0075989,21705.62890625,21760.30078125,57.1964485232368,20.5166372348939,28.603769,0,0,0,40,4449,300.2538,21732.96484375,,,,,,,,,,,,,0,,,,-0.0049,,,,,,300.0075989,,,,
,31302364.555,300.0068054,26565.6591796875,-1.55672103736919E-5,1.02617364839995E-6,1,0.999253354069792,40.0298881530762,1.99561133703229,19.6000002324581,-0.000184690728200295,2.01731550845764E-5,0.25,4.48230456609433E-6,-1.55697060956944E-5,4.47189166426932E-6,300.0068054,300.0068054,26563.033203125,26568.28515625,56.8884868866599,20.5172549100857,28.603769,0,0,0,40,4449,300.2448,26565.6591796875,,,,,,,,,,,,,0,,,,0.0049,,,,,,300.0068054,,,,
,31302461.065,300.0176697,31388.7412109375,-3.11909957478324E-5,1.29754061600755E-6,1,0.999253354069792,40.0298881530762,1.99556667580965,19.6000002324581,-0.000361594235561765,-8.3549034247706E-6,0.25,4.66466708619508E-6,-3.11931327745777E-5,4.64395112871739E-6,300.0176697,300.0176697,31386.080078125,31391.40234375,56.8798889729483,20.5169435810858,28.603769,0,0,0,40,4449,300.2373,31388.7412109375,,,,,,,,,,,,,0,,,,0.00245,,,,,,300.0176697,,,,
,31302555.455,300.0133057,36109.197265625,-4.93362960935066E-5,1.43223244238978E-6,1,0.999253354069792,40.0298881530762,1.99546580445029,19.6000002324581,-0.000568091432829507,-3.53323910375543E-5,0.25,5.42090326717994E-6,-4.9338392169285E-5,5.38822888098307E-6,300.0133057,300.0133057,36104.09375,36114.30078125,57.0698247031214,20.5185500733522,28.983419,0,0,0,40,4449,300.2306,36109.197265625,,,,,,,,,,,,,0,,,,-0.00245,,,,,,300.0133057,,,,
,31302651.17,300.0123596,40891.658203125,-6.54984708720335E-5,1.1680287426843E-6,1,0.999253354069792,40.0298881530762,1.99544359249387,19.6000002324581,-0.000751538628071382,-6.21845922838E-5,0.25,5.84459295143163E-6,-6.55003647853557E-5,5.80130077358136E-6,300.0123596,300.0123596,40886.62109375,40896.6953125,56.8525319747752,20.5173341768156,28.603769,0,0,0,40,4449,300.22215,40891.658203125,,,,,,,,,,,,,0,,,,-0.00245,,,,,,300.0123596,,,,
,31302746.665,300.0105286,45666.84375,-8.24289947607426E-5,1.45492800341572E-6,1,0.999253354069792,40.0298881530762,1.99548724491449,19.6000002324581,-0.00094651466074542,-7.42601412117713E-5,0.25,7.70928104852746E-6,-8.24316164046456E-5,7.65484706539831E-6,300.0105286,300.0105286,45664.23046875,45669.45703125,56.8064158921406,20.516357133142,29.363071,0,0,0,40,4449,300.2154,45666.84375,,,,,,,,,,,,,0,,,,-0.0049,,,,,,300.0105286,,,,
,31302840.395,300.0138245,50349.845703125,-0.000101120138174462,2.06461478341737E-6,1,0.999253354069792,40.0298881530762,1.99542508953237,19.6000002324581,-0.00116196666324796,-8.61310776223263E-5,0.25,9.89674545959192E-6,-0.000101123630638763,9.83002375944224E-6,300.0138245,300.0138245,50322.51953125,50377.171875,56.9471090256022,20.5177212203839,28.983419,0,0,0,40,4449,300.1996,50349.845703125,,,,,,,,,,,,,0,,,,0,,,,,,300.0138245,,,,
,31302936.045,300.007782,55132.36328125,-0.000116397950407608,1.85085603106938E-6,1,0.999253354069792,40.0298881530762,1.9954792436546,19.6000002324581,-0.00133591546151433,-0.000108628605584219,0.25,1.05527955197972E-5,-0.000116401444387101,1.0476107745933E-5,300.0076599,300.0079041,55105.04296875,55159.68359375,56.7634263235829,20.5163389464551,28.983419,0,0,0,40,4449,300.1971,55132.36328125,,,,,,,,,,,,,0,,,,0.00245,,,,,,300.007782,,,,
,31303031.95,300.01205445,59924.8203125,-0.000143404768061813,2.24998760033597E-6,1,0.999253354069792,40.0298881530762,1.99568002871717,19.6000002324581,-0.00163118901322845,-0.000219531670601445,0.25,5.41882336984622E-6,-0.000143404080616582,5.32466819247463E-6,300.0112305,300.0128784,59897.2265625,59952.4140625,56.8001628639868,20.5083443209151,28.224119,0,0,0,40,4449,300.1786,59924.8203125,,,,,,,,,,,,,0,,,,-0.00245,,,,,,300.01205445,,,,
,31303127.185,300.0129089,64685.396484375,-0.000152952195309527,1.74604905958596E-6,1,0.999253354069792,40.0298881530762,1.99550899873918,19.6000002324581,-0.00174900969913055,-0.000180081328340849,0.25,1.05624638560879E-5,-0.000152954594681887,1.04620162204999E-5,300.0127258,300.013092,64650.60546875,64720.1875,56.7720242372945,20.51348481836,28.983419,0,0,0,40,4449,300.177,64685.396484375,,,,,,,,,,,,,0,,,,0,,,,,,300.0129089,,,,
,31303225.23,300.0126343,69585.7734375,-0.000169945405250017,2.11880905087837E-6,1,0.999253354069792,40.0298881530762,1.99558684287654,19.6000002324581,-0.00194913765325302,-0.000166976115680134,0.25,1.46667469278313E-5,-0.000169949991951298,1.45551837912384E-5,300.0126343,300.0126343,69558.125,69613.421875,56.7329428113329,20.5122794989759,28.603769,0,0,0,40,4449,300.1618,69585.7734375,,,,,,,,,,,,,0,,,,-0.00245,,,,,,300.0126343,,,,
,31303323.61,300.0155182,74501.2109375,-0.000192896802572089,3.61382313932715E-6,1,0.999253354069792,40.0298881530762,1.99551526044968,19.6000002324581,-0.00220582591792478,-0.000226864433244003,0.25,1.33424986774872E-5,-0.000192899830527455,1.32161197500293E-5,300.0151062,300.0159302,74471.15625,74531.265625,56.2600575571983,20.5112303469205,28.603769,0,0,0,40,4449,300.15575,74501.2109375,,,,,,,,,,,,,0,,,,0,,,,,,300.0155182,,,,
,31303424.235,300.0154419,79533.796875,-0.000205269487541589,2.63433905176578E-6,1,0.999253354069792,40.0298881530762,1.99580605895891,19.6000002324581,-0.00234598343867628,-0.000250996080508728,0.25,1.33534088023608E-5,-0.00020527216241,1.32191170813256E-5,300.0154419,300.0154419,79503.703125,79563.890625,56.6063189912175,20.5084050118293,28.603769,0,0,0,40,4449,300.14505,79533.796875,,,,,,,,,,,,,0,,,,-0.0049,,,,,,300.0154419,,,,
,31303519.48,300.012207,84294.9296875,-0.000224962765317821,2.52465380389235E-6,1,0.999253354069792,40.0298881530762,1.99579390695653,19.6000002324581,-0.00257140035546514,-0.000272990868727074,0.25,1.48187300852952E-5,-0.000224965847144608,1.46717293954262E-5,300.012207,300.012207,84262.6015625,84327.2578125,56.3116450394675,20.5081463675875,29.363071,0,0,0,40,4449,300.1386,84294.9296875,,,,,,,,,,,,,0,,,,-0.00245,,,,,,300.012207,,,,
,31303612.705,300.0176544,88953.27734375,-0.00024534798418617,2.66291586186473E-6,1,0.999253354069792,40.0298881530762,1.99572554608148,19.6000002324581,-0.00280355356922063,-0.000302131367100958,0.25,1.577086607753E-5,-0.00024535104718683,1.56107384790564E-5,300.0175781,300.0177307,88925.8125,88980.7421875,56.5375356815252,20.5081843825962,29.363071,0,0,0,40,4449,300.12125,88953.27734375,,,,,,,,,,,,,0,,,,0,,,,,,300.0176544,,,,
,31303718.79,300.0093994,86560.9375,-0.00024580956504004,2.29891243659599E-6,1,0.999253354069792,40.0298881530762,1.99561336906413,19.6000002324581,-0.00279013258522419,-0.000409729970095332,0.25,6.32784192258497E-6,-0.000245806535543513,6.16758707544844E-6,300.0093994,300.0093994,86533.2890625,86588.5859375,56.6696309012752,20.5079365340248,28.983419,0,0,0,40,4449,300.1131,86560.9375,,,,,,,,,,,,,0,,,,0.00245,,,,,,300.0093994,,,,
,31303811.505,299.9958191,81927.59375,-0.00021755323634565,2.92285911725193E-6,1,0.999253354069792,40.0298881530762,1.99560922089169,19.6000002324581,-0.00249000033930587,-0.000243707081550183,0.25,1.61244173318434E-5,-0.000217557512110483,1.5982124035636E-5,299.9958191,299.9958191,81895.0234375,81960.1640625,56.6156985334483,20.5110469855769,28.603769,0,0,0,40,4449,300.13235,81927.59375,,,,,,,,,,,,,0,,,,0.00245,,,,,,299.9958191,,,,
,31303909.325,299.9966431,77036.3359375,-0.000200620210412631,2.19352690787571E-6,1,0.999253354069792,40.0298881530762,1.99569126432975,19.6000002324581,-0.00229537916498249,-0.000229968843672779,0.25,1.44075028649529E-5,-0.000200623843459601,1.42761266166788E-5,299.9966431,299.9966431,77031.3359375,77041.3359375,56.6055373626983,20.5111798217546,28.983419,0,0,0,40,4449,300.12295,77036.3359375,,,,,,,,,,,,,0,,,,-0.00245,,,,,,299.9966431,,,,
,31304008.125,299.9915466,72098.01171875,-0.000180201969504002,2.82447085264584E-6,1,0.999253354069792,40.0298881530762,1.99567406586331,19.6000002324581,-0.00205750563961353,-0.000231054565913913,0.25,1.07739666867255E-5,-0.000180203846896492,1.06558807122333E-5,299.9915466,299.9915466,72067.984375,72128.0390625,56.333530638006,20.5110027823566,28.983419,0,0,0,40,4449,300.13195,72098.01171875,,,,,,,,,,,,,0,,,,-0.00245,,,,,,299.9915466,,,,
,31304107.65,299.9879761,67122.4765625,-0.000163649487979926,2.91687340853247E-6,1,0.999253354069792,40.0298881530762,1.99568809899941,19.6000002324581,-0.00186719854851556,-0.000217493661094243,0.25,9.10651423332797E-6,-0.000163650766660888,8.9991670514904E-6,299.9872437,299.9887085,67089.8125,67155.140625,56.976810909333,20.5118843537844,28.983419,0,0,0,40,4449,300.1468,67122.4765625,,,,,,,,,,,,,0,,,,-0.00245,,,,,,299.9879761,,,,
,31304208.09,299.9895935,62101.234375,-0.000142284254782882,2.47601310316749E-6,1,0.999253354069792,40.0298881530762,1.99568174422858,19.6000002324581,-0.00162417385300826,-0.000184756622228195,0.25,8.30191467805724E-6,-0.000142285606266712,8.20845695164692E-6,299.9895935,299.9895935,62101.234375,62101.234375,56.6391473890252,20.5137212344633,28.983419,0,0,0,40,4449,300.1552,62101.234375,,,,,,,,,,,,,0,,,,0,,,,,,299.9895935,,,,
,31304304.8,299.9950256,57267.416015625,-0.00013410190856776,1.74035828780779E-6,1,0.999253354069792,40.0298881530762,1.99557537652936,19.6000002324581,-0.0015242660639653,-0.000211225753447267,0.25,4.54121056776693E-6,-0.000134100999605873,4.45312131546169E-6,299.9950256,299.9950256,57237.1953125,57297.63671875,56.6242964471598,20.5140562777689,28.603769,0,0,0,40,4449,300.16945,57267.416015625,,,,,,,,,,,,,0,,,,-0.0049,,,,,,299.9950256,,,,
,31304400.65,299.9870453,52476.04296875,-0.000116077626929762,1.3899434597405E-6,1,0.999253354069792,40.0298881530762,1.99547776931581,19.6000002324581,-0.00131799674640016,-0.000190535269342143,0.25,3.24875520460195E-6,-0.000116076420646097,3.17243815234191E-6,299.9867554,299.9873352,52445.9140625,52506.171875,56.7634263235829,20.5144580413384,28.983419,0,0,0,40,4449,300.169,52476.04296875,,,,,,,,,,,,,0,,,,-0.00245,,,,,,299.9870453,,,,
,31304498.455,299.9874878,47585.93359375,-9.9263232227597E-5,1.83016636281684E-6,1,0.999253354069792,40.0298881530762,1.99553752498474,19.6000002324581,-0.00112875417277659,-0.000153454718458903,0.25,3.61763642245284E-6,-9.92627464975361E-5,3.55227679966524E-6,299.9874878,299.9874878,47583.44140625,47588.42578125,56.7837486650829,20.5105946932588,28.603769,0,0,0,40,4449,300.17895,47585.93359375,,,,,,,,,,,,,0,,,,0,,,,,,299.9874878,,,,
,31304594.895,299.98272705,42768.330078125,-7.90220881421726E-5,1.42811812246093E-6,1,0.999253354069792,40.0298881530762,1.99539820707845,19.6000002324581,-0.000901555518768712,-0.00010466823093452,0.25,4.42761917265944E-6,-7.90227305752397E-5,4.37548821475546E-6,299.9825439,299.9829102,42735.69140625,42800.96875,57.0198004778906,20.5130505777261,28.983419,0,0,0,40,4449,300.19515,42768.330078125,,,,,,,,,,,,,0,,,,0.00245,,,,,,299.98272705,,,,
,31304689.85,299.98654175,38022.826171875,-6.04577177471421E-5,1.35652952896938E-6,1,0.999253354069792,40.0298881530762,1.99552460331519,19.6000002324581,-0.000690081529218807,-7.84470751001384E-5,0.25,3.53233536923309E-6,-6.04582950117893E-5,3.49240448827233E-6,299.9864197,299.9866638,37992.97265625,38052.6796875,56.8236117195637,20.5099057621461,28.983419,0,0,0,40,4449,300.20135,38022.826171875,,,,,,,,,,,,,0,,,,0.00245,,,,,,299.98654175,,,,
,31304784.575,299.9870605,33288.23046875,-4.35688535152886E-5,1.7581023503271E-6,1,0.999253354069792,40.0298881530762,1.99551522007155,19.6000002324581,-0.000496114154425842,-6.34059238895741E-5,0.25,1.93734183055566E-6,-4.35688667081079E-5,1.90855416597304E-6,299.9870605,299.9870605,33260.7734375,33315.6875,56.8759808303522,20.5094200118922,29.363071,0,0,0,40,4449,300.21255,33288.23046875,,,,,,,,,,,,,0,,,,0.00245,,,,,,299.9870605,,,,
,31304878.235,299.9906464,28608.083984375,-2.76137472273195E-5,1.09391425952331E-6,1,0.999253354069792,40.0298881530762,1.99552404787607,19.6000002324581,-0.000318483294434469,-1.68278362118968E-5,0.25,3.29506083440021E-6,-2.76151157761045E-5,3.27673643108662E-6,299.9900208,299.991272,28577.953125,28638.21484375,56.8118872917752,20.5123638508536,28.983419,0,0,0,40,4449,300.21425,28608.083984375,,,,,,,,,,,,,0,,,,-0.00245,,,,,,299.9906464,,,,
,31304972.515,299.98483275,23895.01171875,-1.0189744667695E-5,9.7650329290801E-7,1,0.999253354069792,40.0298881530762,1.99553318243884,19.6000002324581,-0.000119433208631779,4.80976711117325E-6,0.25,2.19109231390454E-6,-1.01908962898421E-5,2.18429624713229E-6,299.9838562,299.9858093,23864.95703125,23925.06640625,57.1253203279868,20.5130550882359,28.603769,0,0,0,40,4449,300.2369,23895.01171875,,,,,,,,,,,,,0,,,,0,,,,,,299.98483275,,,,
,31305069.04,299.9916077,19070.638671875,6.25586071666307E-6,9.92113861814361E-7,1,0.999253354069792,40.0298881530762,1.99567180104135,19.6000002324581,6.74745523197651E-5,3.08390619353267E-5,0.25,1.64507814204796E-6,6.25458911842513E-6,1.6491671355491E-6,299.9916077,299.9916077,19068.015625,19073.26171875,56.9244417985445,20.5119424768817,29.363071,0,0,0,40,4449,300.23715,19070.638671875,,,,,,,,,,,,,0,,,,0,,,,,,299.9916077,,,,
,31305166.405,299.9919434,14203.5166015625,2.30474575761781E-5,9.54444732506679E-7,1,0.999253354069792,40.0298881530762,1.99584781663757,19.6000002324581,0.000255792649311013,7.21482847028303E-5,0.25,2.39071304225235E-6,2.3045196984458E-5,2.4058989477557E-6,299.9919434,299.9919434,14201.1318359375,14205.9013671875,56.8540952318137,20.5124983080636,28.983419,0,0,0,40,4449,300.2418,14203.5166015625,,,,,,,,,,,,,0,,,,0,,,,,,299.9919434,,,,
,31305260.83,299.993866,9485.94287109375,3.7391080294412E-5,6.27240453797144E-7,1,0.999253354069792,40.0298881530762,1.99577127224858,19.6000002324581,0.00042125154357939,8.07924356132826E-5,0.25,6.7065892305121E-7,3.73895314960819E-5,6.95410664512595E-7,299.9933167,299.9944153,9458.4541015625,9513.431640625,56.6141352764098,20.5167132657352,28.603769,0,0,0,40,4449,300.24505,9485.94287109375,,,,,,,,,,,,,0,,,,0,,,,,,299.993866,,,,
,31305354.445,299.9945068,4805.48754882812,4.60814581270653E-5,5.38884449328776E-7,1,0.999253354069792,40.0298881530762,1.99562432544367,19.6000002324581,0.000519214454342412,9.9027504009085E-5,0.25,7.79115214922147E-7,4.60795773129148E-5,8.09643500528748E-7,299.9934692,299.9955444,4775.52587890625,4835.44921875,56.6915164998137,20.5210438773357,28.983419,0,0,0,40,4449,300.25035,4805.48754882812,,,,,,,,,,,,,0,,,,-0.00245,,,,,,299.9945068,,,,
,31305446.125,299.9932251,223.939323425293,2.68265312925554E-5,5.14111881740931E-7,1,0.999253354069792,40.0298881530762,1.99560991916388,19.6000002324581,0.000302880287938588,5.40745005910502E-5,0.25,1.37244855746501E-7,2.6825646348015E-5,1.55036602514772E-7,299.9932251,299.9932251,221.54084777832,226.337799072266,57.1573670972753,20.517624623386,29.363071,0,0,0,40,4449,300.2531,223.939323425293,,,,,,,,,,,,,0,,,,-0.00245,,,,,,299.9932251,,,,
,31305450.52,299.9927673,-0.540443949401379,8.99381961402202E-6,4.51928901066342E-7,1,0.999253354069792,40.0298881530762,1.99563626072953,19.6000002324581,0.000102103117012449,1.49046442338317E-5,0.25,-2.39330651098778E-7,8.99371235446232E-6,-2.33357231118525E-7,299.9925842,299.9929504,-0.943873941898346,-0.137013956904411,56.9369478548522,20.517350732747,28.983419,0,0,0,40,4417,300.2507,-0.540443949401379,,,,,,,,,,,,,0,,,,0,,,,,,299.9927673,,,,