File: data/doubleLayers/dl_0-125/ppms/data/DD213_7_HYST_INIT_300K.DAT
[Header]
; VSM Data File (default extension .dat)
; Copyright (c) 2003-2013, Quantum Design, Inc. All rights reserved.
TITLE,
FILEOPENTIME,31138724.83,12/27/2018,5:40 pm
BYAPP,VSM,2.0,2.0
INFO,PPMS VSM Option Release 1.4.10 Build 1,APPNAME
INFO,Quantum Design Linear Motor Servo Controller,MOTOR_MODULE_NAME
INFO,3101-100 M1,MOTOR_HW_VERSION
INFO,MMC1014,MOTOR_SERIAL_NUMBER
INFO,SRV No X-over 01.03.11,MOTOR_SOFTWARE_VERSION
INFO,Quantum Design VSM Detection Module,VSM_MODULE_NAME
INFO,3101-150 F0,VSM_HW_VERSION
INFO,VSM707,VSM_SERIAL_NUMBER
INFO,VSM No X-over 01.02.05 May 20 2008 13:51:47,VSM_SOFTWARE_VERSION
INFO,704,PREAMP_SERIAL_NUMBER
INFO,822,COIL_SERIAL_NUMBER
INFO,0,MOMENT_UNITS
INFO,CoFe2O4,SAMPLE_MATERIAL
INFO,Double Layer thin concentration,SAMPLE_COMMENT
INFO,29.55,SAMPLE_MASS
INFO,,SAMPLE_VOLUME
INFO,,SAMPLE_MOLECULAR_WEIGHT
INFO,,SAMPLE_SIZE
INFO,,SAMPLE_SHAPE
DATATYPE,COMMENT,1
DATATYPE,TIME,2
STARTUPAXIS,X,2
STARTUPAXIS,Y1,5
[Data]
Comment,Time Stamp (sec),Temperature (K),Magnetic Field (Oe),Moment (emu),M. Std. Err. (emu),Transport Action,Averaging Time (sec),Frequency (Hz),Peak Amplitude (mm),Center Position (mm),Coil Signal' (mV),Coil Signal" (mV),Range (mV),M. Quad. Signal (emu),M. Raw' (emu),M. Raw" (emu),Min. Temperature (K),Max. Temperature (K),Min. Field (Oe),Max. Field (Oe),Mass (grams),Motor Lag (deg),Pressure (Torr),VSM Status (code),Motor Status (code),Measure Status (code),Measure Count,PPMS Status (code),System Temp. (K),System Field (Oe),Sample Position (deg),Bridge 1 Resistance (ohms),Bridge 1 Excitation (에),Bridge 2 Resistance (ohms),Bridge 2 Excitation (에),Bridge 3 Resistance (ohms),Bridge 3 Excitation (에),Bridge 4 Resistance (ohms),Bridge 4 Excitation (에),Signal 1 Vin (V),Signal 2 Vin (V),Digital Inputs (code),Drive 1 Iout (mA),Drive 1 Ipower (W),Drive 2 Iout (mA),Drive 2 Ipower (W),Pressure (),Map 20 (),Map 21 (),Map 22 (),Map 23 (),Map 24 (),Map 25 (),Map 26 (),Map 27 (),Map 28 (),Map 29 ()
,31138740.33,300.0075073,-0.106566414237022,,,2,,,,19.4799998024106,,,,,,,300.0075073,300.0075073,-0.106566414237022,-0.106566414237022,,,25.946213,,,,-99999999,4369,300.1414,-0.106566414237022,,,,,,,,,,,,,,,,,,,,,,,300.0075073,,,,
,31138862.235,300.0183411,3632.84008789063,4.56873955456873E-5,5.00104717386573E-7,1,0.999253354069792,40.0298881530762,2.000294708232,19.4600000977516,0.000518823560032202,8.16624163558624E-5,0.25,-7.05404845310641E-7,4.56864698435469E-5,-6.75071120625154E-7,300.0183411,300.0183411,3613.04418945313,3652.63598632812,56.2311373019867,20.4443835820012,26.705515,0,0,0,40,4449,300.10855,3632.84008789063,,,,,,,,,,,,,0,,,,0.00245,,,,,,300.0183411,,,,
,31138938.835,300.0189056,7460.11157226563,4.24775707099635E-5,6.0442271012695E-7,1,0.999253354069792,40.0298881530762,2.0003336554027,19.4600000977516,0.000480585082321474,8.62973719661569E-5,0.25,2.59848166424976E-7,4.2476103187437E-5,2.88006827649282E-7,300.0188293,300.0189819,7432.576171875,7487.64697265625,56.3858997487944,20.4473075289313,27.085165,0,0,0,40,4449,300.10355,7460.11157226563,,,,,,,,,,,,,0,,,,-0.00245,,,,,,300.0189056,,,,
,31139014.31,300.01055905,11231.3276367187,3.41491776320077E-5,7.18168822892937E-7,1,0.999253354069792,40.0298881530762,2.00038988248248,19.4700006395578,0.000386561304428523,6.82713670743577E-5,0.25,1.11094718381677E-7,3.4148074326713E-5,1.33720531819842E-7,300.0099792,300.0111389,11201.4912109375,11261.1640625,56.2850696698137,20.4518415831827,27.085165,0,0,0,40,4449,300.10755,11231.3276367187,,,,,,,,,,,,,0,,,,-0.00245,,,,,,300.01055905,,,,
,31139092.385,300.0143433,15134.0126953125,2.23382240765572E-5,1.35827849552432E-6,1,0.999253354069792,40.0298881530762,2.0002984674327,19.4600000977516,0.00025242574578554,4.71217641499481E-5,0.25,2.90321544140214E-7,2.23373561577253E-5,3.05105057151791E-7,300.0143433,300.0143433,15103.859375,15164.166015625,56.6227331901214,20.4530385613329,27.085165,0,0,0,40,4449,300.10255,15134.0126953125,,,,,,,,,,,,,0,,,,0.00245,,,,,,300.0143433,,,,
,31139171.935,300.00642395,19111.9775390625,7.64238479071622E-6,1.19526443347794E-6,1,0.999253354069792,40.0298881530762,2.00025050833061,19.4700006395578,8.33389738244749E-5,3.35477753236981E-5,0.25,1.63806011097307E-6,7.64107225763681E-6,1.643068016033E-6,300.0062866,300.0065613,19082.083984375,19141.87109375,56.3819916061983,20.454006459193,27.085165,0,0,0,40,4449,300.10135,19111.9775390625,,,,,,,,,,,,,0,,,,-0.00245,,,,,,300.00642395,,,,
,31139253.915,300.0050049,23207.86328125,-2.9716685438772E-6,1.6976330787765E-6,1,0.999253354069792,40.0298881530762,2.00019790045987,19.4600000977516,-3.52880978075506E-5,3.59749569136752E-6,0.25,8.32520210387027E-7,-2.97213035178458E-6,8.30530693130935E-7,300.0050049,300.0050049,23205.728515625,23209.998046875,56.668849272756,20.4555944527409,27.085165,0,0,0,40,4449,300.1042,23207.86328125,,,,,,,,,,,,,0,,,,0.0049,,,,,,300.0050049,,,,
,31139331.795,300.0011139,27100.962890625,-1.89272205862207E-5,1.89876806339346E-6,1,0.999253354069792,40.0298881530762,2.00016263754491,19.4600000977516,-0.000217012035662574,-2.17719718692427E-5,0.25,1.35679788530013E-6,-1.89275560923258E-5,1.34425381052509E-6,300.0007019,300.0015259,27068.37890625,27133.546875,56.4851665707367,20.4586901605792,27.085165,0,0,0,40,4449,300.09595,27100.962890625,,,,,,,,,,,,,0,,,,-0.00245,,,,,,300.0011139,,,,
,31139411.385,300.0024414,31078.8193359375,-3.16381513031415E-5,2.43635517744174E-6,1,0.999253354069792,40.0298881530762,2.00006153931935,19.4600000977516,-0.000355683898287691,-7.70777225114665E-5,0.25,-1.32482016320097E-6,-3.16363394697047E-5,-1.34566404003773E-6,300.0024414,300.0024414,31076.1484375,31081.490234375,56.6274229612368,20.4611757381367,27.085165,0,0,0,40,4449,300.0984,31078.8193359375,,,,,,,,,,,,,0,,,,0,,,,,,300.0024414,,,,
,31139493.015,300.0002747,35156.6796875,-4.57209019073854E-5,1.03698690827874E-6,1,0.999253354069792,40.0298881530762,1.99996897587169,19.4700006395578,-0.000518690919458214,-8.42085918858222E-5,0.25,4.85063678617574E-7,-4.57198731807216E-5,4.54898023840091E-7,300.0002747,300.0002747,35124.19921875,35189.16015625,56.7204367550252,20.4620794960298,27.085165,0,0,0,40,4449,300.10115,35156.6796875,,,,,,,,,,,,,0,,,,-0.00245,,,,,,300.0002747,,,,
,31139574.21,300.00209045,39216.763671875,-5.88689476499286E-5,1.41993299820813E-6,1,0.999253354069792,40.0298881530762,1.99986456737916,19.4700006395578,-0.000666749183898221,-0.000114591467205886,0.25,7.94289872782733E-8,-5.88672627708419E-5,4.06387564371667E-8,300.0015564,300.0026245,39186.71484375,39246.8125,56.689171614256,20.4629823866265,27.464817,0,0,0,40,4449,300.0936,39216.763671875,,,,,,,,,,,,,0,,,,0,,,,,,300.00209045,,,,
,31139653.475,300.0046082,43177.720703125,-7.3094586711437E-5,2.21911172727634E-6,1,0.999253354069792,40.0298881530762,1.99996199361319,19.4600000977516,-0.000828026869431825,-0.000141597726724571,0.25,1.59627329037115E-7,-7.30925320389143E-5,1.11504875918592E-7,300.0046082,300.0046082,43175.37109375,43180.0703125,56.8243933480829,20.4607325290543,27.085165,0,0,0,40,4449,300.0918,43177.720703125,,,,,,,,,,,,,0,,,,0,,,,,,300.0046082,,,,
,31139734.105,300.00564575,47206.044921875,-8.95770107546885E-5,2.47796519843046E-6,1,0.999253354069792,40.0298881530762,1.9999297818875,19.4700006395578,-0.00101830679644435,-0.000152861060430839,0.25,2.02036791713485E-6,-8.95756944010559E-5,1.96139642289554E-6,300.0055847,300.0057068,47173.33203125,47238.7578125,56.780622151006,20.4623526626745,26.705515,0,0,0,40,4449,300.0961,47206.044921875,,,,,,,,,,,,,0,,,,-0.00245,,,,,,300.00564575,,,,
,31139814.67,300.0048065,51234.015625,-0.000102228078166246,2.4625658444218E-6,1,0.999253354069792,40.0298881530762,1.99989960897012,19.4600000977516,-0.00116304838231727,-0.000169012732229828,0.25,2.7855824627107E-6,-0.000102226898353121,2.71832915910998E-6,300.0045776,300.0050354,51201.765625,51266.265625,56.6516534453329,20.4631035356712,26.705515,0,0,0,40,4449,300.0839,51234.015625,,,,,,,,,,,,,0,,,,0,,,,,,300.0048065,,,,
,31139896.23,300.0032043,55309.39453125,-0.000120111666523248,2.80766068499949E-6,1,0.999253354069792,40.0298881530762,1.9998033463029,19.4600000977516,-0.00136482325737092,-0.000207943980146863,0.25,2.44497320502577E-6,-0.000120109748738714,2.36605938469859E-6,300.0032043,300.0032043,55284.359375,55334.4296875,56.6774471864675,20.4649346973323,27.085165,0,0,0,40,4449,300.09335,55309.39453125,,,,,,,,,,,,,0,,,,0,,,,,,300.0032043,,,,
,31139977.835,299.9998474,59387.193359375,-0.000131436060127857,2.33275781576758E-6,1,0.999253354069792,40.0298881530762,1.9997493525553,19.4600000977516,-0.0014912438180517,-0.000240355894970149,0.25,1.54384890918626E-6,-0.000131433241086507,1.45761266432503E-6,299.9998474,299.9998474,59361.82421875,59412.5625,56.8204852054868,20.4660351673998,27.085165,0,0,0,40,4449,300.0898,59387.193359375,,,,,,,,,,,,,0,,,,0,,,,,,299.9998474,,,,
,31140055.995,300.01074215,63296.115234375,-0.000149042026983103,2.82376204071028E-6,1,0.999253354069792,40.0298881530762,1.99972536674883,19.4700006395578,-0.00168971430920375,-0.000279837905705617,0.25,1.10676810456049E-6,-0.000149038357301179,1.00909120823339E-6,300.010498,300.0109863,63266.46875,63325.76171875,56.7024592990829,20.4649263473186,27.085165,0,0,0,40,4449,300.0854,63296.115234375,,,,,,,,,,,,,0,,,,0,,,,,,300.01074215,,,,
,31140132.985,300.0111389,67144.3984375,-0.000158797316239122,1.78279395189669E-6,1,0.999253354069792,40.0298881530762,1.99965279592915,19.4700006395578,-0.001805241174511,-0.000269331317055298,0.25,3.72389695804785E-6,-0.000158795077612749,3.61984912976611E-6,300.0111389,300.0111389,67114.453125,67174.34375,56.7352876968906,20.4655091127938,27.085165,0,0,0,40,4449,300.07945,67144.3984375,,,,,,,,,,,,,0,,,,-0.00245,,,,,,300.0111389,,,,
,31140212.425,300.0070648,71117.1484375,-0.000175796703931848,2.20792201313786E-6,1,0.999253354069792,40.0298881530762,1.99965146840047,19.4600000977516,-0.00199056607516754,-0.000343916855068179,0.25,8.13902770800168E-8,-0.000175791615997582,-3.35674739841694E-8,300.0067749,300.0073547,71087.125,71147.171875,56.7134020983521,20.4646647241734,26.705515,0,0,0,40,4449,300.06715,71117.1484375,,,,,,,,,,,,,0,,,,0,,,,,,300.0070648,,,,
,31140291.19,300.0061035,75050.1171875,-0.000192141468001804,3.25918506326722E-6,1,0.999253354069792,40.0298881530762,1.99960924696485,19.4600000977516,-0.00217737841954957,-0.000365597300263629,0.25,9.97492714937686E-7,-0.000192136518063844,8.71943587369302E-7,300.0061035,300.0061035,75025.375,75074.859375,56.2498963864483,20.4665909586795,26.705515,0,0,0,40,4449,300.0626,75050.1171875,,,,,,,,,,,,,0,,,,-0.00245,,,,,,300.0061035,,,,
,31140373.695,300.0042419,79176.08203125,-0.000205158745085962,2.87553766270416E-6,1,0.999253354069792,40.0298881530762,1.99960825356507,19.4600000977516,-0.00232623910445024,-0.000382587416513806,0.25,1.75194719328879E-6,-0.000205153933456629,1.61801251358228E-6,300.0042419,300.0042419,79148.7890625,79203.375,56.6962062709291,20.4651177050749,26.705515,0,0,0,40,4449,300.059,79176.08203125,,,,,,,,,,,,,0,,,,0,,,,,,300.0042419,,,,
,31140455.52,300.00679015,83264.95703125,-0.000218749117034495,2.97194810162295E-6,1,0.999253354069792,40.0298881530762,1.99950177389563,19.4600000977516,-0.00248214302226909,-0.000396755844017853,0.25,2.85312295968528E-6,-0.000218744620800352,2.71043661057044E-6,300.0065613,300.007019,83232.5078125,83297.40625,56.7735874943329,20.4660376157573,27.464817,0,0,0,40,4449,300.05555,83264.95703125,,,,,,,,,,,,,0,,,,0,,,,,,300.00679015,,,,
,31140534.28,300.0100098,87203.52734375,-0.000235715474358819,3.35146043635983E-6,1,0.999253354069792,40.0298881530762,1.99952999338816,19.4600000977516,-0.00267242670116516,-0.000440632155662995,0.25,1.91735798199381E-6,-0.000235709860539227,1.76379624410595E-6,300.0100098,300.0100098,87201.015625,87206.0390625,56.7266897831791,20.4673054557008,27.464817,0,0,0,40,4449,300.0553,87203.52734375,,,,,,,,,,,,,0,,,,-0.0049,,,,,,300.0100098,,,,
,31140627.19,300.0085449,88939.96875,-0.000239259918285235,2.49485260389001E-6,1,0.999253354069792,40.0298881530762,1.99925727822614,19.4600000977516,-0.00271077478611127,-0.000455766904645106,0.25,1.18931630008538E-6,-0.000239253744941717,1.03352988199139E-6,300.0085449,300.0085449,88937.546875,88942.390625,56.6844818431406,20.4696864862958,27.085165,0,0,0,40,4449,300.04065,88939.96875,,,,,,,,,,,,,0,,,,-0.0049,,,,,,300.0085449,,,,
,31140704.445,300.00642395,85076.96484375,-0.00022792834454339,1.93778939270942E-6,1,0.999253354069792,40.0298881530762,1.99914394767066,19.4700006395578,-0.00258627632293255,-0.000410919443611181,0.25,3.18610701290884E-6,-0.00022792380581013,3.03748276787338E-6,300.0059204,300.0069275,85049.3984375,85104.53125,56.7868751791599,20.4699926958936,27.085165,0,0,0,40,4449,300.0302,85076.96484375,,,,,,,,,,,,,0,,,,-0.00245,,,,,,300.00642395,,,,
,31140785.165,299.997345,81040.578125,-0.000215135711358598,3.22896340376008E-6,1,0.999253354069792,40.0298881530762,1.99920716303579,19.4600000977516,-0.00244524156396866,-0.000364506216577889,0.25,5.07123124372677E-6,-0.000215132833415346,4.93074998662638E-6,299.997345,299.997345,81010.5078125,81070.6484375,56.7931282073137,20.4722082728013,26.705515,0,0,0,40,4449,300.04355,81040.578125,,,,,,,,,,,,,0,,,,0,,,,,,299.997345,,,,
,31140866.39,299.9909973,76981.38671875,-0.00019545589118621,1.73508804011131E-6,1,0.999253354069792,40.0298881530762,1.9990372270347,19.4600000977516,-0.00221354506741287,-0.000376359812096729,0.25,6.12016435369645E-7,-0.000195450703573648,4.84368605311678E-7,299.9909973,299.9909973,76956.265625,77006.5078125,56.7110572127945,20.475182796633,27.085165,0,0,0,40,4449,300.04615,76981.38671875,,,,,,,,,,,,,0,,,,-0.00245,,,,,,299.9909973,,,,
,31140948.815,299.98957825,72860.00390625,-0.000179696196829175,1.40752582859222E-6,1,0.999253354069792,40.0298881530762,1.99909744558472,19.4600000977516,-0.00204183712927204,-0.000307278037591442,0.25,3.98578784100886E-6,-0.000179693663853455,3.86821339771465E-6,299.9893494,299.9898071,72827.5234375,72892.484375,56.7055858131598,20.476181352059,27.464817,0,0,0,40,4449,300.05175,72860.00390625,,,,,,,,,,,,,0,,,,0.00245,,,,,,299.98957825,,,,
,31141026.62,299.9834595,68971.375,-0.000166783330443277,1.2581246700909E-6,1,0.999253354069792,40.0298881530762,1.9989843254784,19.4600000977516,-0.00189395841221605,-0.000291250946179083,0.25,3.16326762546626E-6,-0.00016678065872354,3.05405780586127E-6,299.9834595,299.9834595,68968.7734375,68973.9765625,56.7931282073137,20.4767774975705,26.705515,0,0,0,40,4449,300.06875,68971.375,,,,,,,,,,,,,0,,,,0.00245,,,,,,299.9834595,,,,
,31141106.26,299.98576355,64990.93359375,-0.000152646617087848,1.00240843315773E-6,1,0.999253354069792,40.0298881530762,1.99893249564416,19.4600000977516,-0.00173136590426726,-0.000278192094629585,0.25,1.86730683617268E-6,-0.000152643479509267,1.76728875956878E-6,299.9850159,299.9865112,64960.71484375,65021.15234375,56.8533136032945,20.4768526268984,27.085165,0,0,0,40,4449,300.08305,64990.93359375,,,,,,,,,,,,,0,,,,-0.00245,,,,,,299.98576355,,,,
,31141183.855,299.9834595,61114.52734375,-0.000138875410382131,1.20198409742391E-6,1,0.999253354069792,40.0298881530762,1.99894401179266,19.4600000977516,-0.00157527774597369,-0.000252516096623695,0.25,1.75016761816718E-6,-0.000138872594651565,1.65908871315647E-6,299.9834595,299.9834595,61087.12890625,61141.92578125,56.7884384361983,20.478937856266,27.085165,0,0,0,40,4449,300.09605,61114.52734375,,,,,,,,,,,,,0,,,,0,,,,,,299.9834595,,,,
,31141262.375,299.98532105,57185.919921875,-0.000125359585133689,1.74864871992362E-6,1,0.999253354069792,40.0298881530762,1.99890228102288,19.4600000977516,-0.00142393026491382,-0.000216435968561417,0.25,2.59596675693645E-6,-0.000125357695675275,2.51364329921723E-6,299.9849854,299.9856567,57158.3515625,57213.48828125,56.7790588939676,20.4814873772774,27.085165,0,0,0,40,4449,300.09485,57185.919921875,,,,,,,,,,,,,0,,,,0.0049,,,,,,299.98532105,,,,
,31141340.24,299.9831543,53295.486328125,-0.000112049427260243,1.94102826816249E-6,1,0.999253354069792,40.0298881530762,1.99880068082544,19.4600000977516,-0.00127368902767971,-0.000187631571405656,0.25,2.83418181678145E-6,-0.000112048080137337,2.76051971984568E-6,299.9831543,299.9831543,53275.671875,53315.30078125,56.8908317722176,20.4834853209375,27.464817,0,0,0,40,4449,300.10995,53295.486328125,,,,,,,,,,,,,0,,,,0,,,,,,299.9831543,,,,
,31141416.715,299.98802185,49472.642578125,-9.76476494694417E-5,1.88710487200932E-6,1,0.999253354069792,40.0298881530762,1.99875084356542,19.4600000977516,-0.00110592353524805,-0.000186776880984358,0.25,4.14210474194878E-7,-9.7645103474725E-5,3.50016107191542E-7,299.9875793,299.9884644,49447.62109375,49497.6640625,56.851750346256,20.4845825927467,27.464817,0,0,0,40,4449,300.10805,49472.642578125,,,,,,,,,,,,,0,,,,0.00245,,,,,,299.98802185,,,,
,31141495.64,299.98703,45529.3359375,-8.2333551699814E-5,1.19177469698521E-6,1,0.999253354069792,40.0298881530762,1.99875932757598,19.4600000977516,-0.000935657180631602,-0.000139176586007619,0.25,1.967043046349E-6,-8.233246836974E-5,1.91282511108973E-6,299.98703,299.98703,45504.140625,45554.53125,56.7548284098714,20.484882062423,26.705515,0,0,0,40,4449,300.13465,45529.3359375,,,,,,,,,,,,,0,,,,0,,,,,,299.98703,,,,
,31141571.61,299.981369,41731.078125,-6.85268319367431E-5,1.48781551606862E-6,1,0.999253354069792,40.0298881530762,1.99917750681873,19.4600000977516,-0.000778509301379995,-0.000118174155945385,0.25,1.43286421077583E-6,-6.85258070200499E-5,1.38770372689234E-6,299.9810791,299.9816589,41701.26171875,41760.89453125,56.8759808303522,20.485742276039,27.085165,0,0,0,40,4449,300.1287,41731.078125,,,,,,,,,,,,,0,,,,0.00245,,,,,,299.981369,,,,
,31141647.89,299.9893494,37917.703125,-5.38210426019487E-5,1.40319944284609E-6,1,0.999253354069792,40.0298881530762,1.99904192414303,19.4600000977516,-0.000611005321233188,-9.50988796561072E-5,0.25,9.23013999091726E-7,-5.38200868333467E-5,8.875209578132E-7,299.9893494,299.9893494,37912.44921875,37922.95703125,56.7642079521022,20.4846153927423,27.464817,0,0,0,40,4449,300.1374,37917.703125,,,,,,,,,,,,,0,,,,-0.00245,,,,,,299.9893494,,,,
,31141727.225,299.987793,33955.02734375,-4.12071472701276E-5,1.02523684528387E-6,1,0.999253354069792,40.0298881530762,1.9990497548718,19.4600000977516,-0.000466773719147621,-7.87771519972789E-5,0.25,1.79625558199633E-7,-4.12060685175615E-5,1.52443105458726E-7,299.987793,299.987793,33925.12890625,33984.92578125,56.7985996069483,20.4843765342031,27.085165,0,0,0,40,4449,300.145,33955.02734375,,,,,,,,,,,,,0,,,,-0.00245,,,,,,299.987793,,,,
,31141806.265,299.9849548,30001.955078125,-2.84367619961949E-5,9.09399742196729E-7,1,0.999253354069792,40.0298881530762,1.9988939382478,19.4600000977516,-0.000321726142871819,-5.64787433159865E-5,0.25,-6.32680604150501E-8,-2.84358955236663E-5,-8.20368419253944E-8,299.9849548,299.9849548,29996.9609375,30006.94921875,56.8400259184676,20.4872232344557,26.705515,0,0,0,40,4449,300.14955,30001.955078125,,,,,,,,,,,,,0,,,,-0.0049,,,,,,299.9849548,,,,
,31141886.3,299.9870758,26003.8349609375,-1.34957959698045E-5,1.6358790650401E-6,1,0.999253354069792,40.0298881530762,1.99884731514562,19.4600000977516,-0.0001536668203392,-2.11339900643755E-5,0.25,4.70928140177706E-7,-1.34957139849161E-5,4.61998621777417E-7,299.9870605,299.9870911,25978.806640625,26028.86328125,56.8900501436983,20.4885962139284,26.705515,0,0,0,40,4449,300.1522,26003.8349609375,,,,,,,,,,,,,0,,,,0,,,,,,299.9870758,,,,
,31141965.445,299.99064635,22045.8779296875,2.30089671903068E-7,9.36279170675301E-7,1,0.999253354069792,40.0298881530762,1.99875883997507,19.4600000977516,6.38421852344561E-7,1.17960450231935E-5,0.25,1.00243100838322E-6,2.29420186419927E-7,1.0025537572229E-6,299.990448,299.9908447,22016.015625,22075.740234375,56.8525319747752,20.4909173671449,27.085165,0,0,0,40,4449,300.16645,22045.8779296875,,,,,,,,,,,,,0,,,,-0.00245,,,,,,299.99064635,,,,
,31142044.895,299.99157715,18078.337890625,1.24862551037597E-5,1.46805183041998E-6,1,0.999253354069792,40.0298881530762,1.99869275697992,19.4600000977516,0.000138494652675724,4.0715065210246E-5,0.25,1.43434181210688E-6,1.24849392382219E-5,1.44256112743744E-6,299.9910889,299.9920654,18048.32421875,18108.3515625,57.0674798175637,20.4931794341643,27.085165,0,0,0,40,4449,300.17165,18078.337890625,,,,,,,,,,,,,0,,,,-0.00245,,,,,,299.99157715,,,,
,31142121.86,299.9855194,14230.6108398438,2.4728669198542E-5,1.0309417853547E-6,1,0.999253354069792,40.0298881530762,1.9986077648836,19.4600000977516,0.00027781685734356,6.01809620910186E-5,0.25,1.03350337494308E-6,2.47272627332807E-5,1.04984627413657E-6,299.9850464,299.9859924,14200.51953125,14260.7021484375,57.0487207331022,20.4930247663537,27.085165,0,0,0,40,4449,300.1791,14230.6108398438,,,,,,,,,,,,,0,,,,-0.00245,,,,,,299.9855194,,,,
,31142200.94,299.9864349,10277.7509765625,3.64164804774514E-5,9.06786198967921E-7,1,0.999253354069792,40.0298881530762,1.99851317575661,19.4600000977516,0.000409409010629143,8.6873839841382E-5,0.25,1.36756657573605E-6,3.64145082195188E-5,1.39165452808092E-6,299.9863586,299.9865112,10247.8486328125,10307.6533203125,56.8728543162753,20.4926317795159,27.464817,0,0,0,40,4449,300.18825,10277.7509765625,,,,,,,,,,,,,0,,,,-0.00245,,,,,,299.9864349,,,,
,31142283.275,299.9849854,6161.89111328125,4.50202586211542E-5,5.49561625951005E-7,1,0.999253354069792,40.0298881530762,1.99846748940784,19.4600000977516,0.000510010176025217,8.49733177108607E-5,0.25,-2.90922922821627E-7,4.50191339354859E-5,-2.61065321212156E-7,299.9849854,299.9849854,6154.19970703125,6169.58251953125,57.0198004778906,20.4922511171876,27.464817,0,0,0,40,4449,300.18665,6161.89111328125,,,,,,,,,,,,,0,,,,0,,,,,,299.9849854,,,,
,31142360.335,299.9918213,2310.56127929687,4.46764340076758E-5,3.45100778415251E-7,1,0.999253354069792,40.0298881530762,1.9983498563434,19.4600000977516,0.000504622700876953,9.27687838288957E-5,0.25,4.57997646591699E-7,4.46748103848439E-5,4.87620017964689E-7,299.9918213,299.9918213,2285.67041015625,2335.4521484375,56.9314764552176,20.4942687483309,27.085165,0,0,0,40,4449,300.2018,2310.56127929687,,,,,,,,,,,,,0,,,,0,,,,,,299.9918213,,,,
,31142436.43,299.987915,-1490.49633789062,-3.90733737446938E-5,4.3523116473354E-7,1,0.999253354069792,40.0298881530762,1.9984501315488,19.4600000977516,-0.000441526118362857,-8.01622340072546E-5,0.25,-3.1431096370601E-7,-3.90720162108147E-5,-3.40223215453938E-7,299.987915,299.987915,-1495.61083984375,-1485.3818359375,56.8025077495445,20.4961715278413,27.085165,0,0,0,40,4449,300.2046,-1490.49633789062,,,,,,,,,,,,,0,,,,-0.0049,,,,,,299.987915,,,,
,31142516.135,299.9960938,-5473.13818359375,-4.54634050033448E-5,5.58888313180959E-7,1,0.999253354069792,40.0298881530762,1.99822689825345,19.4600000977516,-0.000513349081853151,-9.5160834426929E-5,0.25,-5.33558708669106E-7,-4.54617024856795E-5,-5.63686532407026E-7,299.9960938,299.9960938,-5498.29345703125,-5447.98291015625,56.933039712256,20.4952727018979,26.705515,0,0,0,40,4449,300.20735,-5473.13818359375,,,,,,,,,,,,,0,,,,0,,,,,,299.9960938,,,,
,31142592.775,299.9971924,-9306.9501953125,-3.79380969984876E-5,8.75274456504135E-7,1,0.999253354069792,40.0298881530762,1.9982388264634,19.4600000977516,-0.000428162993222762,-8.06604077188845E-5,0.25,-5.55785209705905E-7,-3.79366031548239E-5,-5.80907038573621E-7,299.9971924,299.9971924,-9331.6396484375,-9282.2607421875,56.9455457685637,20.4951138411493,27.085165,0,0,0,40,4449,300.2087,-9306.9501953125,,,,,,,,,,,,,0,,,,0.00245,,,,,,299.9971924,,,,
,31142673.005,300.0018311,-13314.2724609375,-2.80577835858342E-5,1.19100290437974E-6,1,0.999253354069792,40.0298881530762,1.99821305401827,19.4600000977516,-0.000315935454108552,-6.3785885693957E-5,0.25,-7.7632319858146E-7,-2.80564335858231E-5,-7.94878675968255E-7,300.0018311,300.0018311,-13344.2255859375,-13284.3193359375,56.9791557948906,20.497090572876,27.085165,0,0,0,40,4449,300.20425,-13314.2724609375,,,,,,,,,,,,,0,,,,0.00245,,,,,,300.0018311,,,,
,31142752.46,300.0045776,-17287.4990234375,-1.4116645741007E-5,1.09547160888925E-6,1,0.999253354069792,40.0298881530762,1.99829195670868,19.4600000977516,-0.0001574936099936,-4.05678491855759E-5,0.25,-1.13954237825862E-6,-1.411547037986E-5,-1.14884887854844E-6,300.0045776,300.0045776,-17317.4609375,-17257.537109375,57.0713879601599,20.4960751774397,26.705515,0,0,0,40,4449,300.20175,-17287.4990234375,,,,,,,,,,,,,0,,,,0,,,,,,300.0045776,,,,
,31142831.97,300.00537105,-21257.697265625,-3.07918821019403E-6,8.71755649613263E-7,1,0.999253354069792,40.0298881530762,1.99828598234016,19.4600000977516,-3.44698659445494E-5,-8.1751114854905E-6,0.25,-1.89021423867876E-7,-3.07897138237581E-6,-1.91051601444946E-7,300.0047607,300.0059814,-21290.181640625,-21225.212890625,57.1268835850253,20.4986917228634,27.085165,0,0,0,40,4449,300.20015,-21257.697265625,,,,,,,,,,,,,0,,,,-0.00245,,,,,,300.00537105,,,,
,31142913.75,300.00862125,-25348.23046875,1.15307983773476E-5,1.08717302867409E-6,1,0.999253354069792,40.0298881530762,1.99824193265727,19.4600000977516,0.00013303230754337,7.7921092598765E-6,0.25,-1.30911357721153E-6,1.15313184262808E-5,-1.30145726567712E-6,300.0079041,300.0093384,-25373.09765625,-25323.36328125,56.9713395096983,20.4991493255938,26.705515,0,0,0,40,4449,300.2029,-25348.23046875,,,,,,,,,,,,,0,,,,-0.00245,,,,,,300.00862125,,,,
,31142996.03,300.0048218,-29458.3056640625,2.47880117700622E-5,1.1256359986496E-6,1,0.999253354069792,40.0298881530762,1.99830225450148,19.4600000977516,0.000282819693461361,3.50540881591558E-5,0.25,-1.19663742449712E-6,2.47880651389965E-5,-1.18024146318781E-6,300.0048218,300.0048218,-29460.720703125,-29455.890625,57.1198489283522,20.4983877545992,26.705515,0,0,0,40,4449,300.206,-29458.3056640625,,,,,,,,,,,,,0,,,,0,,,,,,300.0048218,,,,
,31143076.9,300.0073242,-33501.14453125,4.02220312756069E-5,1.18942114369254E-6,1,0.999253354069792,40.0298881530762,1.99836359300268,19.4600000977516,0.000459333861950369,5.4539832199397E-5,0.25,-2.14867000144774E-6,4.02222516155754E-5,-2.12208005793791E-6,300.0073242,300.0073242,-33533.24609375,-33469.04296875,57.0706063316407,20.4998904522814,27.464817,0,0,0,40,4449,300.18475,-33501.14453125,,,,,,,,,,,,,0,,,,0.00245,,,,,,300.0073242,,,,
,31143156.585,300.0107727,-37481.244140625,5.21887846791177E-5,1.51914709779556E-6,1,0.999253354069792,40.0298881530762,1.99835555977095,19.4600000977516,0.000592674390346885,8.9910846397612E-5,0.25,-1.09595654071766E-6,5.21879502387473E-5,-1.06153466650219E-6,300.0107727,300.0107727,-37511.6640625,-37450.82421875,57.034651419756,20.499996636039,27.085165,0,0,0,40,4449,300.17285,-37481.244140625,,,,,,,,,,,,,0,,,,0.0049,,,,,,300.0107727,,,,
,31143237.565,300.01187135,-41531.734375,6.67236030893987E-5,1.58398478664204E-6,1,0.999253354069792,40.0298881530762,1.99829167482118,19.4600000977516,0.000759928512899432,0.00010216516279472,0.25,-2.53088060152288E-6,6.67232800300202E-5,-2.486877408348E-6,300.0118103,300.0119324,-41554.2265625,-41509.2421875,56.9893169656406,20.5007289331442,27.085165,0,0,0,40,4449,300.16515,-41531.734375,,,,,,,,,,,,,0,,,,-0.0049,,,,,,300.01187135,,,,
,31143318.61,300.0128784,-45582.560546875,8.07829500003758E-5,1.22346890027862E-6,1,0.999253354069792,40.0298881530762,1.99838359042164,19.4600000977516,0.00091994786313108,0.000124539135314761,0.25,-2.98976098892051E-6,8.07825096844373E-5,-2.93654007781323E-6,300.0128784,300.0128784,-45587.5078125,-45577.61328125,56.9064643426022,20.5012287148041,27.085165,0,0,0,40,4449,300.1759,-45582.560546875,,,,,,,,,,,,,0,,,,0.0049,,,,,,300.0128784,,,,
,31143398.2,300.0153503,-49560.0546875,9.65297694935366E-5,1.74299807034868E-6,1,0.999253354069792,40.0298881530762,1.99836998579257,19.4600000977516,0.00109295232074968,0.000185243434544223,0.25,-3.53022609519405E-7,9.65271219393342E-5,-2.89578017438473E-7,300.0153503,300.0153503,-49589.89453125,-49530.21484375,57.1354814987368,20.5004294761127,27.085165,0,0,0,40,4449,300.15735,-49560.0546875,,,,,,,,,,,,,0,,,,0,,,,,,300.0153503,,,,
,31143477.365,300.01116945,-53514.994140625,0.000108868873832524,1.86340123507135E-6,1,0.999253354069792,40.0298881530762,1.99832991997757,19.4600000977516,0.00123672263436304,0.000185340866505058,0.25,-2.48183017023075E-6,0.000108867277815618,-2.41027921309408E-6,300.0110779,300.011261,-53542.671875,-53487.31640625,57.0799858738714,20.5021489366058,26.705515,0,0,0,40,4449,300.14965,-53514.994140625,,,,,,,,,,,,,0,,,,0,,,,,,300.01116945,,,,
,31143559.035,300.00709535,-57597.544921875,0.000126693009316862,2.30436972415074E-6,1,0.999253354069792,40.0298881530762,1.99827845036679,19.4600000977516,0.00144156797013247,0.000201810975972663,0.25,-4.11380765531939E-6,0.000126691979699997,-4.0305855506782E-6,300.0058594,300.0083313,-57630.02734375,-57565.0625,57.078422616833,20.5014910645106,26.705515,0,0,0,40,4449,300.1396,-57597.544921875,,,,,,,,,,,,,0,,,,-0.00245,,,,,,300.00709535,,,,
,31143641.27,300.0089722,-61707.705078125,0.000143127632290254,1.84703944407119E-6,1,0.999253354069792,40.0298881530762,1.99835569298273,19.4600000977516,0.00162539794776649,0.000246643504213087,0.25,-2.9995574214049E-6,0.000143125384869381,-2.90568071703159E-6,300.0089722,300.0089722,-61732.890625,-61682.51953125,57.0323065341983,20.5003874746235,26.705515,0,0,0,40,4449,300.13435,-61707.705078125,,,,,,,,,,,,,0,,,,-0.00245,,,,,,300.0089722,,,,
,31143723.575,300.0108643,-65818.19921875,0.000155867449923286,2.22155989653748E-6,1,0.999253354069792,40.0298881530762,1.99849566219557,19.4600000977516,0.00176792406581262,0.000281712622663058,0.25,-2.10901990047797E-6,0.000155864241082874,-2.00692359871269E-6,300.0108643,300.0108643,-65820.8125,-65815.5859375,56.9807190519291,20.504044642498,27.085165,0,0,0,40,4449,300.1301,-65818.19921875,,,,,,,,,,,,,0,,,,-0.0049,,,,,,300.0108643,,,,
,31143805.375,300.01397705,-69908.484375,0.000171700454466406,2.32901314700352E-6,1,0.999253354069792,40.0298881530762,1.99833826965384,19.4600000977516,0.00194568123449241,0.000320013767694502,0.25,-1.46516293181162E-6,0.000171696347637888,-1.3528315098775E-6,300.013916,300.0140381,-69943.6015625,-69873.3671875,56.8431524325445,20.5021743642673,26.705515,0,0,0,40,4449,300.11955,-69908.484375,,,,,,,,,,,,,0,,,,0.0049,,,,,,300.01397705,,,,
,31143888.305,300.0111389,-74053.15625,0.000187710661144325,2.83601090419801E-6,1,0.999253354069792,40.0298881530762,1.99835860991763,19.4600000977516,0.00212626066464527,0.000354858841296652,0.25,-1.15960155046323E-6,0.000187705911764322,-1.03693520833548E-6,300.0111389,300.0111389,-74085.515625,-74020.796875,57.0948368157368,20.5059976476172,27.085165,0,0,0,40,4449,300.1139,-74053.15625,,,,,,,,,,,,,0,,,,0,,,,,,300.0111389,,,,
,31143973.415,300.0101318,-78308.14453125,0.000201486799828577,2.59351317974664E-6,1,0.999253354069792,40.0298881530762,1.99820701250399,19.4600000977516,0.00228254147934011,0.000378571666449902,0.25,-1.44809830618012E-6,0.000201481853236006,-1.31656072933784E-6,300.0101318,300.0101318,-78313.203125,-78303.0859375,57.2433462343907,20.502815331016,27.085165,0,0,0,40,4449,300.10165,-78308.14453125,,,,,,,,,,,,,0,,,,-0.0049,,,,,,300.0101318,,,,
,31144054.445,300.0173035,-82356.12109375,0.000221598369917072,1.89849324049068E-6,1,0.999253354069792,40.0298881530762,1.99818697589658,19.4600000977516,0.00251489337581644,0.000390134382238478,0.25,-3.90997434870568E-6,0.000221594395311664,-3.76538633658539E-6,300.0173035,300.0173035,-82385.8125,-82326.4296875,56.9994781363906,20.5039333913702,27.464817,0,0,0,40,4449,300.09505,-82356.12109375,,,,,,,,,,,,,0,,,,0,,,,,,300.0173035,,,,
,31144134.45,300.01364135,-86353.6171875,0.000229982506630543,2.47925719220772E-6,1,0.999253354069792,40.0298881530762,1.99817774241444,19.4600000977516,0.00261398778593731,0.000382065357983826,0.25,-6.07538606651215E-6,0.000229979736694756,-5.92542197330983E-6,300.0130005,300.0142822,-86383.703125,-86323.53125,57.0002597649099,20.5065432154748,27.085165,0,0,0,40,4449,300.0888,-86353.6171875,,,,,,,,,,,,,0,,,,0,,,,,,300.01364135,,,,
,31144227.405,300.0080872,-89809.01171875,0.000243835622972049,2.44143446197128E-6,1,0.999253354069792,40.0298881530762,1.99815135218932,19.4600000977516,0.00276299606221348,0.000453631302627176,0.25,-2.14947615751959E-6,0.000243829950591282,-1.99074335477367E-6,300.0080872,300.0080872,-89840.5625,-89777.4609375,57.1284468420637,20.5086473643167,27.085165,0,0,0,40,4449,300.0794,-89809.01171875,,,,,,,,,,,,,0,,,,0,,,,,,300.0080872,,,,
,31144304.58,300.0109558,-85954.59375,0.000231465476445838,2.12149675292951E-6,1,0.999253354069792,40.0298881530762,1.99824419471501,19.4600000977516,0.00262206209889831,0.000435710169660984,0.25,-1.59220546536626E-6,0.000231459763691194,-1.44138348421278E-6,300.0106506,300.011261,-85984.546875,-85924.640625,56.9549253107945,20.507578611414,27.085165,0,0,0,40,4449,300.07585,-85954.59375,,,,,,,,,,,,,0,,,,0.00245,,,,,,300.0109558,,,,
,31144384.765,300.0037842,-81949.4453125,0.000218632880512095,2.48765808802355E-6,1,0.999253354069792,40.0298881530762,1.99833778806411,19.4600000977516,0.00247910920500026,0.00039826961419465,0.25,-2.67976160727392E-6,0.00021862829554705,-2.53712090973145E-6,300.0037842,300.0037842,-81956.8359375,-81942.0546875,57.166746639506,20.5080309254824,27.464817,0,0,0,40,4449,300.07975,-81949.4453125,,,,,,,,,,,,,0,,,,0,,,,,,300.0037842,,,,
,31144465.655,299.9972839,-77906.67578125,0.00020089208247255,2.36973039612253E-6,1,0.999253354069792,40.0298881530762,1.99836524978264,19.4600000977516,0.00227856687230298,0.000362535521365198,0.25,-2.76484708208712E-6,0.000200888103398859,-2.63363453567312E-6,299.9969482,299.9976196,-77938.9921875,-77874.359375,57.1010898438907,20.5065066567951,27.085165,0,0,0,40,4449,300.07755,-77906.67578125,,,,,,,,,,,,,0,,,,0.00245,,,,,,299.9972839,,,,
,31144547.405,299.98811345,-73821.27734375,0.000184007355951291,2.19169258425686E-6,1,0.999253354069792,40.0298881530762,1.99835148835873,19.4600000977516,0.00209146405196906,0.000306544774439586,0.25,-4.78778662106579E-6,0.000184005236406671,-4.66741597756077E-6,299.9877625,299.9884644,-73846.34375,-73796.2109375,56.9041194570445,20.5075884142953,27.464817,0,0,0,40,4449,300.08395,-73821.27734375,,,,,,,,,,,,,0,,,,0,,,,,,299.98811345,,,,
,31144629.38,299.9898376,-69723.41796875,0.000173638777385197,2.23727680302293E-6,1,0.999253354069792,40.0298881530762,1.99825929714188,19.4600000977516,0.00197024275162348,0.000308207409091693,0.25,-2.84340754727799E-6,0.000173635663990132,-2.72975226368087E-6,299.9898376,299.9898376,-69743.4375,-69703.3984375,56.994006736756,20.504853003438,27.085165,0,0,0,40,4449,300.0909,-69723.41796875,,,,,,,,,,,,,0,,,,0,,,,,,299.9898376,,,,
,31144710.72,299.9844055,-65661.203125,0.000154750448302287,1.63242490832839E-6,1,0.999253354069792,40.0298881530762,1.9982989545761,19.4600000977516,0.00175827733088974,0.000261277943388373,0.25,-3.71919306655216E-6,0.00015474847262897,-3.61777068206856E-6,299.9842834,299.9845276,-65691.34375,-65631.0625,57.0369963053137,20.5060589609209,27.085165,0,0,0,40,4449,300.1064,-65661.203125,,,,,,,,,,,,,0,,,,0.00245,,,,,,299.9844055,,,,
,31144791.715,299.9860535,-61610.607421875,0.000141074517820055,1.75192019471015E-6,1,0.999253354069792,40.0298881530762,1.99823621129025,19.4600000977516,0.00159867645375455,0.000262229528799495,0.25,-1.26511829127456E-6,0.000141071309537273,-1.17262770011536E-6,299.9860535,299.9860535,-61633.1484375,-61588.06640625,57.0643533034868,20.5064982570083,26.705515,0,0,0,40,4449,300.1092,-61610.607421875,,,,,,,,,,,,,0,,,,0.0049,,,,,,299.9860535,,,,
,31144873.305,299.989624,-57533.146484375,0.000125226302216937,1.82272628829494E-6,1,0.999253354069792,40.0298881530762,1.99819617895529,19.4600000977516,0.00142255006260949,0.000212592180535627,0.25,-2.90613795830252E-6,0.000125224601566576,-2.82390539288573E-6,299.989624,299.989624,-57560.34375,-57505.94921875,57.0620084179291,20.5038876236093,27.464817,0,0,0,40,4449,300.113,-57533.146484375,,,,,,,,,,,,,0,,,,0,,,,,,299.989624,,,,
,31144953.76,299.9847412,-53512.744140625,0.000110163198994103,1.79615793849512E-6,1,0.999253354069792,40.0298881530762,1.99815149735317,19.4600000977516,0.00124780572242679,0.000207814886119335,0.25,-7.18328114185771E-7,0.000110160510980307,-6.45975213193059E-7,299.9847412,299.9847412,-53542.703125,-53482.78515625,56.9643048530253,20.5038576517787,27.464817,0,0,0,40,4449,300.132,-53512.744140625,,,,,,,,,,,,,0,,,,0.00245,,,,,,299.9847412,,,,
,31145035.87,299.9882202,-49410.53515625,9.80141753674737E-5,1.85666475373026E-6,1,0.999253354069792,40.0298881530762,1.99824070514623,19.4600000977516,0.00111469178119352,0.000159222317383793,0.25,-2.90899853741091E-6,9.80132583471223E-5,-2.84449901198695E-6,299.9882202,299.9882202,-49435.5859375,-49385.484375,56.9689946241406,20.5031054709521,26.705515,0,0,0,40,4449,300.14265,-49410.53515625,,,,,,,,,,,,,0,,,,0,,,,,,299.9882202,,,,
,31145115.28,299.986908,-45440.138671875,8.34858559088188E-5,1.93812625047309E-6,1,0.999253354069792,40.0298881530762,1.99829199832721,19.4600000977516,0.000950274731118012,0.000131083435706762,0.25,-2.87920532626897E-6,8.34853398516711E-5,-2.82420551307053E-6,299.986908,299.986908,-45462.58203125,-45417.6953125,57.0620084179291,20.5038473194215,26.705515,0,0,0,40,4449,300.1514,-45440.138671875,,,,,,,,,,,,,0,,,,-0.0049,,,,,,299.986908,,,,
,31145196.095,299.9857178,-41399.458984375,6.87925943510326E-5,1.30236831400959E-6,1,0.999253354069792,40.0298881530762,1.99824556895754,19.4600000977516,0.000778010347513742,0.000136878693635406,0.25,1.78872744834501E-7,6.87904899857588E-5,2.24160479618615E-7,299.9857178,299.9857178,-41404.375,-41394.54296875,56.8853603725829,20.5043761830375,27.085165,0,0,0,40,4449,300.156,-41399.458984375,,,,,,,,,,,,,0,,,,0.00245,,,,,,299.9857178,,,,
,31145277.25,299.9868164,-37344.474609375,5.2617620152124E-5,1.80252654449699E-6,1,0.999253354069792,40.0298881530762,1.99822673731928,19.4600000977516,0.000600978025694364,7.06166350735891E-5,0.25,-2.87503800628064E-6,5.26179904605674E-5,-2.84028156130033E-6,299.9868164,299.9868164,-37347.00390625,-37341.9453125,57.1026531009291,20.5040252422615,27.085165,0,0,0,40,4449,300.1706,-37344.474609375,,,,,,,,,,,,,0,,,,0,,,,,,299.9868164,,,,
,31145358,299.9883118,-33306.96484375,3.88621644359488E-5,9.42615307863202E-7,1,0.999253354069792,40.0298881530762,1.99817416448317,19.4600000977516,0.000444048011019004,5.10541933380928E-5,0.25,-2.2207098619153E-6,3.88624992344229E-5,-2.19501447014322E-6,299.9883118,299.9883118,-33329.65234375,-33284.27734375,56.9439825115252,20.5029412787904,26.705515,0,0,0,40,4449,300.17955,-33306.96484375,,,,,,,,,,,,,0,,,,0,,,,,,299.9883118,,,,
,31145439.115,299.9937439,-29256.849609375,2.51802799882904E-5,1.10545936902268E-6,1,0.999253354069792,40.0298881530762,1.99819353613425,19.4600000977516,0.000287205255251803,3.60412092810949E-5,0.25,-1.17719800098301E-6,2.51803187857535E-5,-1.16054165309687E-6,299.9937439,299.9937439,-29261.8203125,-29251.87890625,57.0385595623522,20.501489146272,27.085165,0,0,0,40,4449,300.17845,-29256.849609375,,,,,,,,,,,,,0,,,,0.0049,,,,,,299.9937439,,,,
,31145521.185,299.986908,-25154.0283203125,9.6672255857406E-6,8.45321116991996E-7,1,0.999253354069792,40.0298881530762,1.99820213062709,19.4600000977516,0.000111277081886952,7.99240879700001E-6,0.25,-9.6852133375236E-7,9.66758390576015E-6,-9.62106343514072E-7,299.986908,299.986908,-25183.94140625,-25124.115234375,57.0229269919676,20.5021286870321,27.464817,0,0,0,40,4449,300.18645,-25154.0283203125,,,,,,,,,,,,,0,,,,0.00245,,,,,,299.986908,,,,
,31145602.84,299.98835755,-21073.912109375,-2.69898202494961E-6,7.42806131502268E-7,1,0.999253354069792,40.0298881530762,1.99815727133185,19.4600000977516,-2.72776328395843E-5,-2.41006449692082E-5,0.25,-1.66251958273514E-6,-2.69780389700859E-6,-1.66425555693578E-6,299.9873047,299.9894104,-21106.24609375,-21041.578125,57.0416860764291,20.5019874502045,27.085165,0,0,0,40,4449,300.1929,-21073.912109375,,,,,,,,,,,,,0,,,,-0.00245,,,,,,299.98835755,,,,
,31145685.22,299.98980715,-16956.1591796875,-1.63083506605606E-5,8.87784145095701E-7,1,0.999253354069792,40.0298881530762,1.99808130720059,19.4600000977516,-0.000182794130297084,-4.18587789058017E-5,0.25,-8.74272765580827E-7,-1.630729394617E-5,-8.85038569393617E-7,299.9888306,299.9907837,-16983.640625,-16928.677734375,57.146424298006,20.5013640543148,27.464817,0,0,0,40,4449,300.2005,-16956.1591796875,,,,,,,,,,,,,0,,,,0,,,,,,299.98980715,,,,
,31145768.435,299.9905396,-12795.6899414062,-2.86787954845401E-5,6.89219446338738E-7,1,0.999253354069792,40.0298881530762,1.99804879695729,19.4600000977516,-0.000323407586175413,-6.22799760147918E-5,0.25,-5.36058856712613E-7,-2.8677597526168E-5,-5.55034583538918E-7,299.9905396,299.9905396,-12825.63671875,-12765.7431640625,57.034651419756,20.5013987732399,26.705515,0,0,0,40,4449,300.20605,-12795.6899414062,,,,,,,,,,,,,0,,,,-0.00245,,,,,,299.9905396,,,,
,31145848.79,299.98960875,-8780.12646484375,-3.94254849756846E-5,6.3153121166819E-7,1,0.999253354069792,40.0298881530762,1.99810577557392,19.4600000977516,-0.000444952065384067,-8.36395895129997E-5,0.25,-5.61852975797271E-7,-3.94239535438155E-5,-5.87962064036452E-7,299.9895935,299.989624,-8812.58984375,-8747.6630859375,56.9611783389483,20.5012787055041,27.085165,0,0,0,40,4449,300.2147,-8780.12646484375,,,,,,,,,,,,,0,,,,0,,,,,,299.98960875,,,,
,31145926.2,299.9917908,-4909.37426757812,-4.55300143300202E-5,5.52292191509102E-7,1,0.999253354069792,40.0298881530762,1.99802872130907,19.4600000977516,-0.000515025938783772,-8.96735565499817E-5,0.25,-3.77875206759521E-8,-4.55286454611086E-5,-6.79755974711401E-8,299.9917908,299.9917908,-4939.4052734375,-4879.34326171875,57.0627900464484,20.5007180522504,26.705515,0,0,0,40,4449,300.21755,-4909.37426757812,,,,,,,,,,,,,0,,,,0.00245,,,,,,299.9917908,,,,
,31146004.67,299.9891052,-987.245422363281,-3.94814228354146E-5,3.54688311136622E-7,1,0.999253354069792,40.0298881530762,1.99804952544091,19.4600000977516,-0.000445774982135396,-8.25808581929034E-5,0.25,-4.58749376285259E-7,-3.9479955753626E-5,-4.84928447485337E-7,299.9891052,299.9891052,-994.651184082031,-979.839660644531,56.9205336559483,20.5004785701504,27.464817,0,0,0,40,4449,300.2154,-987.245422363281,,,,,,,,,,,,,0,,,,0,,,,,,299.9891052,,,,
,31146079.08,299.9940186,2725.63781738281,4.44492441738396E-5,3.69498169279654E-7,1,0.999253354069792,40.0298881530762,1.99823426999549,19.4600000977516,0.000502272062132148,9.08880802914304E-5,0.25,3.31597023457509E-7,4.44477079515066E-5,3.61068809569263E-7,299.9940186,299.9940186,2693.21630859375,2758.05932617187,56.9557069393137,20.5006601339543,27.085165,0,0,0,40,4449,300.2188,2725.63781738281,,,,,,,,,,,,,0,,,,-0.00245,,,,,,299.9940186,,,,
,31146156.26,299.9931946,6585.78540039063,4.39175153259384E-5,4.44819243674073E-7,1,0.999253354069792,40.0298881530762,1.99811370254098,19.4600000977516,0.000497469465658656,8.26709196737378E-5,0.25,-3.02086077283429E-7,4.39164179590603E-5,-2.72966364202678E-7,299.9931946,299.9931946,6558.3994140625,6613.17138671875,57.0182372208522,20.5033505582585,27.085165,0,0,0,40,4449,300.23195,6585.78540039063,,,,,,,,,,,,,0,,,,-0.00245,,,,,,299.9931946,,,,
,31146234.415,299.99446105,10494.5639648438,3.58732421623693E-5,5.98828980092172E-7,1,0.999253354069792,40.0298881530762,1.99809396810103,19.4600000977516,0.000405873022702308,7.02532552142324E-5,0.25,-5.82641161089207E-9,3.58721858558833E-5,1.79369332996893E-8,299.9944458,299.9944763,10467.017578125,10522.1103515625,57.088583787583,20.5005586234426,27.085165,0,0,0,40,4449,300.2308,10494.5639648438,,,,,,,,,,,,,0,,,,-0.0049,,,,,,299.99446105,,,,
,31146311.3,300.0021667,14335.2138671875,2.45559677917057E-5,6.21111000069052E-7,1,0.999253354069792,40.0298881530762,1.9981974245028,19.4600000977516,0.000276790388075625,5.41620295612228E-5,0.25,5.32499518291596E-7,2.45548837703531E-5,5.4873910560482E-7,300.0021667,300.0021667,14310.4951171875,14359.9326171875,56.994006736756,20.5022557814629,27.085165,0,0,0,40,4449,300.2253,14335.2138671875,,,,,,,,,,,,,0,,,,0.00245,,,,,,300.0021667,,,,
,31146391.335,300.00645445,18335.5361328125,1.07176071223764E-5,8.16057126756808E-7,1,0.999253354069792,40.0298881530762,1.99810194929794,19.4600000977516,0.000120220613521823,2.69903755748426E-5,0.25,5.28701619005303E-7,1.07169369419803E-5,5.35775330687303E-7,300.006073,300.0068359,18307.912109375,18363.16015625,57.0690430746022,20.5005460423107,26.705515,0,0,0,40,4449,300.22045,18335.5361328125,,,,,,,,,,,,,0,,,,0,,,,,,300.00645445,,,,
,31146471.625,300.00572205,22348.5224609375,-1.18108767349138E-6,8.36477147391805E-7,1,0.999253354069792,40.0298881530762,1.99814603519555,19.4600000977516,-1.5907068057333E-5,1.23691778596074E-5,0.25,1.29789040753717E-6,-1.1819103065031E-6,1.29707103700541E-6,300.0052185,300.0062256,22316.056640625,22380.98828125,56.8494054606983,20.5023360139154,26.705515,0,0,0,40,4449,300.2164,22348.5224609375,,,,,,,,,,,,,0,,,,0.00245,,,,,,300.00572205,,,,
,31146551.89,300.00715635,26358.66796875,-1.40690266169524E-5,1.03329392313749E-6,1,0.999253354069792,40.0298881530762,1.99805875796454,19.4600000977516,-0.000160727879311364,-1.85918906875454E-5,0.25,7.94231121796695E-7,-1.40691314792654E-5,7.84916164907513E-7,300.006958,300.0073547,26328.6953125,26388.640625,56.8540952318137,20.5018503529542,27.085165,0,0,0,40,4449,300.22165,26358.66796875,,,,,,,,,,,,,0,,,,0,,,,,,300.00715635,,,,
,31146632.16,300.007782,30371.6953125,-2.83181902379895E-5,1.16581660380395E-6,1,0.999253354069792,40.0298881530762,1.99798203842555,19.4600000977516,-0.000321842648950037,-4.69969124654764E-5,0.25,7.52127092673491E-7,-2.83178426857303E-5,7.33419868217119E-7,300.0074768,300.0080872,30347.07421875,30396.31640625,56.9689946241406,20.49863098357,27.085165,0,0,0,40,4449,300.23185,30371.6953125,,,,,,,,,,,,,0,,,,-0.00245,,,,,,300.007782,,,,
,31146711.365,300.0143433,34330.0390625,-4.25095562668213E-5,1.32672974398938E-6,1,0.999253354069792,40.0298881530762,1.99801824703892,19.4600000977516,-0.00048549617816899,-5.69449199525008E-5,0.25,2.33160614853865E-6,-4.25098187068737E-5,2.30350831352703E-6,300.0143433,300.0143433,34300.14453125,34359.93359375,56.926005055583,20.5001880255318,27.085165,0,0,0,40,4449,300.1992,34330.0390625,,,,,,,,,,,,,0,,,,0,,,,,,300.0143433,,,,
,31146790.415,300.0107269,38280.7109375,-5.7522707490965E-5,9.57159760068427E-7,1,0.999253354069792,40.0298881530762,1.99803095729782,19.4600000977516,-0.000652757738000037,-0.000101331857359436,0.25,1.0093367436753E-6,-5.75216577004E-5,9.71412809933643E-7,300.0103149,300.0111389,38253.15625,38308.265625,56.9095908566791,20.5010261916912,27.464817,0,0,0,40,4449,300.1948,38280.7109375,,,,,,,,,,,,,0,,,,0.0049,,,,,,300.0107269,,,,
,31146870.665,300.01091005,42291.375,-7.04572860189884E-5,1.82737687633967E-6,1,0.999253354069792,40.0298881530762,1.99795649048128,19.4600000977516,-0.000802074990446237,-0.000109300650989823,0.25,2.5455702322737E-6,-7.0456864385702E-5,2.49912058577995E-6,300.0105896,300.0112305,42261.4609375,42321.2890625,56.9963516223137,20.5000782677816,26.705515,0,0,0,40,4449,300.1865,42291.375,,,,,,,,,,,,,0,,,,-0.00245,,,,,,300.01091005,,,,
,31146952.04,300.0081329,46359.11328125,-8.49586707297788E-5,1.54642033774936E-6,1,0.999253354069792,40.0298881530762,1.99798976548538,19.4600000977516,-0.000965067858797753,-0.000143943880945793,0.25,1.99591416347006E-6,-8.49574675633764E-5,1.9399879606384E-6,300.0080566,300.0082092,46328.98828125,46389.23828125,56.7180918694675,20.4999167556412,27.085165,0,0,0,40,4449,300.1807,46359.11328125,,,,,,,,,,,,,0,,,,0.00245,,,,,,300.0081329,,,,
,31147033.44,300.0152283,50427.583984375,-0.000100214447285117,1.1755360071401E-6,1,0.999253354069792,40.0298881530762,1.99805342130719,19.4600000977516,-0.00113841926406092,-0.000169665772381381,0.25,2.36581416712628E-6,-0.000100213014202988,2.29990729606403E-6,300.0152283,300.0152283,50397.375,50457.79296875,56.8572217458906,20.5005919057164,26.705515,0,0,0,40,4449,300.17895,50427.583984375,,,,,,,,,,,,,0,,,,-0.00245,,,,,,300.0152283,,,,
,31147114.745,300.00871275,54492.943359375,-0.000116446320415096,1.92210224839126E-6,1,0.999253354069792,40.0298881530762,1.9979807203866,19.4600000977516,-0.00132137331122239,-0.000205172921018408,0.25,2.03888554428671E-6,-0.000116444221020799,1.96239608330252E-6,300.0085449,300.0088806,54460.5703125,54525.31640625,56.9596150819099,20.4986177420397,27.085165,0,0,0,40,4449,300.1669,54492.943359375,,,,,,,,,,,,,0,,,,0.00245,,,,,,300.00871275,,,,
,31147193.89,300.0142822,58448.82421875,-0.000130807944146072,1.92773510022864E-6,1,0.999253354069792,40.0298881530762,1.9979858603718,19.4600000977516,-0.00148474058992239,-0.000228195131003437,0.25,2.49205140945398E-6,-0.000130805697593675,2.40620115944845E-6,300.0142822,300.0142822,58443.76953125,58453.87890625,56.9439825115252,20.499060811243,27.085165,0,0,0,40,4449,300.1576,58448.82421875,,,,,,,,,,,,,0,,,,0,,,,,,300.0142822,,,,
,31147273,300.01641845,62402.0078125,-0.000143292572193019,2.89973715555301E-6,1,0.999253354069792,40.0298881530762,1.99787916699064,19.4600000977516,-0.00162765768569742,-0.000242499956300329,0.25,3.38942097244969E-6,-0.000143290538485247,3.29544572235204E-6,300.0163269,300.01651,62371.97265625,62432.04296875,56.8392442899483,20.4974564434354,26.705515,0,0,0,40,4449,300.15015,62402.0078125,,,,,,,,,,,,,0,,,,-0.00245,,,,,,300.01641845,,,,
,31147352.23,300.0129089,66362.6015625,-0.000156527052240902,2.57190962397893E-6,1,0.999253354069792,40.0298881530762,1.997912702454,19.4600000977516,-0.00177741243306516,-0.000268389184767384,0.25,3.39407671059251E-6,-0.000156524654827667,3.29152721599659E-6,300.0129089,300.0129089,66329.9921875,66395.2109375,56.8173586914099,20.4984181255064,26.705515,0,0,0,40,4449,300.13695,66362.6015625,,,,,,,,,,,,,0,,,,0.00245,,,,,,300.0129089,,,,
,31147436.335,300.0084534,70568.16796875,-0.000176077989553892,2.24796291338338E-6,1,0.999253354069792,40.0298881530762,1.99786870119581,19.4600000977516,-0.00199614655124977,-0.000320555989435006,0.25,2.16927784255174E-6,-0.000176074250970666,2.05408896546123E-6,300.0084534,300.0084534,70563.1015625,70573.234375,56.8580033744099,20.4980887471028,27.085165,0,0,0,40,4449,300.13415,70568.16796875,,,,,,,,,,,,,0,,,,0.00245,,,,,,300.0084534,,,,
,31147514.145,300.006958,74456.39453125,-0.000190381996756072,1.96315683634267E-6,1,0.999253354069792,40.0298881530762,1.99787356617183,19.4600000977516,-0.00215542297459617,-0.000363274928215995,0.25,8.71171587795878E-7,-0.000190377010830416,7.46788403079394E-7,300.006958,300.006958,74436.5,74476.2890625,56.6899532427752,20.4976223340611,27.085165,0,0,0,40,4449,300.1284,74456.39453125,,,,,,,,,,,,,0,,,,-0.0049,,,,,,300.006958,,,,
,31147595.055,300.0100708,78500.0546875,-0.000201453380307148,2.29406468328816E-6,1,0.999253354069792,40.0298881530762,1.99784156317224,19.4600000977516,-0.00228112117515836,-0.000382156581205644,0.25,1.11954939092472E-6,-0.000201448222194892,9.88061060354021E-7,300.0094299,300.0107117,78470.0546875,78530.0546875,56.8337728903137,20.4981059660792,27.464817,0,0,0,40,4449,300.1239,78500.0546875,,,,,,,,,,,,,0,,,,-0.00245,,,,,,300.0100708,,,,
,31147675.18,300.0082092,82506.21484375,-0.000222476054066502,2.15640380129592E-6,1,0.999253354069792,40.0298881530762,1.99785185677257,19.4600000977516,-0.00252000978628543,-0.000417251034346387,0.25,1.65945158287115E-6,-0.000222470660412396,1.51437484706066E-6,300.0082092,300.0082092,82503.5625,82508.8671875,56.8220484625252,20.4991982372845,27.085165,0,0,0,40,4449,300.1148,82506.21484375,,,,,,,,,,,,,0,,,,0,,,,,,300.0082092,,,,
,31147751.76,300.015625,86332.44140625,-0.000232730466962238,2.45533952147908E-6,1,0.999253354069792,40.0298881530762,1.99787413593739,19.4600000977516,-0.00263585082163684,-0.000438445898692208,0.25,1.56268718587377E-6,-0.000232724661640964,1.41107346059344E-6,300.015625,300.015625,86302.546875,86362.3359375,56.7884384361983,20.4972950426563,26.705515,0,0,0,40,4449,300.10425,86332.44140625,,,,,,,,,,,,,0,,,,0,,,,,,300.015625,,,,
,31147825.47,300.0132751,89999.578125,-0.000250323060994104,2.51019200868718E-6,1,0.999253354069792,40.0298881530762,1.99779430536977,19.4600000977516,-0.00283377519049319,-0.000478598598629137,0.25,1.05942230893437E-6,-0.000250316446210431,8.96519689099487E-7,300.0132751,300.0132751,89999.5546875,89999.6015625,56.9400743689291,20.4985323538379,27.085165,0,0,0,40,4417,300.09865,89999.578125,,,,,,,,,,,,,0,,,,0.0049,,,,,,300.0132751,,,,