File: data/doubleLayers/dl_0-125/ppms/data/DD213_7_HYST_100OE_200K.DAT
[Header]
; VSM Data File (default extension .dat)
; Copyright (c) 2003-2013, Quantum Design, Inc. All rights reserved.
TITLE,
FILEOPENTIME,31270043.55,12/29/2018,6:09 am
BYAPP,VSM,2.0,2.0
INFO,PPMS VSM Option Release 1.4.10 Build 1,APPNAME
INFO,Quantum Design Linear Motor Servo Controller,MOTOR_MODULE_NAME
INFO,3101-100 M1,MOTOR_HW_VERSION
INFO,MMC1014,MOTOR_SERIAL_NUMBER
INFO,SRV No X-over 01.03.11,MOTOR_SOFTWARE_VERSION
INFO,Quantum Design VSM Detection Module,VSM_MODULE_NAME
INFO,3101-150 F0,VSM_HW_VERSION
INFO,VSM707,VSM_SERIAL_NUMBER
INFO,VSM No X-over 01.02.05 May 20 2008 13:51:47,VSM_SOFTWARE_VERSION
INFO,704,PREAMP_SERIAL_NUMBER
INFO,822,COIL_SERIAL_NUMBER
INFO,0,MOMENT_UNITS
INFO,CoFe2O4,SAMPLE_MATERIAL
INFO,Double Layer thin concentration,SAMPLE_COMMENT
INFO,29.55,SAMPLE_MASS
INFO,,SAMPLE_VOLUME
INFO,,SAMPLE_MOLECULAR_WEIGHT
INFO,,SAMPLE_SIZE
INFO,,SAMPLE_SHAPE
DATATYPE,COMMENT,1
DATATYPE,TIME,2
STARTUPAXIS,X,2
STARTUPAXIS,Y1,5
[Data]
Comment,Time Stamp (sec),Temperature (K),Magnetic Field (Oe),Moment (emu),M. Std. Err. (emu),Transport Action,Averaging Time (sec),Frequency (Hz),Peak Amplitude (mm),Center Position (mm),Coil Signal' (mV),Coil Signal" (mV),Range (mV),M. Quad. Signal (emu),M. Raw' (emu),M. Raw" (emu),Min. Temperature (K),Max. Temperature (K),Min. Field (Oe),Max. Field (Oe),Mass (grams),Motor Lag (deg),Pressure (Torr),VSM Status (code),Motor Status (code),Measure Status (code),Measure Count,PPMS Status (code),System Temp. (K),System Field (Oe),Sample Position (deg),Bridge 1 Resistance (ohms),Bridge 1 Excitation (에),Bridge 2 Resistance (ohms),Bridge 2 Excitation (에),Bridge 3 Resistance (ohms),Bridge 3 Excitation (에),Bridge 4 Resistance (ohms),Bridge 4 Excitation (에),Signal 1 Vin (V),Signal 2 Vin (V),Digital Inputs (code),Drive 1 Iout (mA),Drive 1 Ipower (W),Drive 2 Iout (mA),Drive 2 Ipower (W),Pressure (),Map 20 (),Map 21 (),Map 22 (),Map 23 (),Map 24 (),Map 25 (),Map 26 (),Map 27 (),Map 28 (),Map 29 ()
,31270058.72,200.0061493,-0.365370541810989,,,2,,,,20.1999996969104,,,,,,,200.0061493,200.0061493,-0.365370541810989,-0.365370541810989,,,26.325863,,,,-99999999,4369,199.9051,-0.365370541810989,,,,,,,,,,,,,,,,,,,,,,,200.0061493,,,,
,31270197.555,199.9916382,4368.50708007812,4.68163448336499E-5,5.31432185392767E-7,1,0.999253354069792,40.0298881530762,1.98480952885775,20.1799999922514,0.000528383151829679,9.01002245671737E-5,0.25,-1.44164457781582E-7,4.69781059366776E-5,-9.38316205739237E-8,199.9911957,199.9920807,4336.03857421875,4400.9755859375,56.1795498197175,20.5162209534153,26.705515,0,0,0,40,4449,199.92095,4368.50708007812,,,,,,,,,,,,,0,,,,0.0049,,,,,,199.9916382,,,,
,31270291.39,199.9892578,9054.8955078125,4.34979738262756E-5,5.41366629921539E-7,1,0.999253354069792,40.0298881530762,1.98500974584687,20.1799999922514,0.000490173543996804,8.83562996378453E-5,0.25,2.76916413623652E-7,4.36478367290292E-5,3.25033936453731E-7,199.9892578,199.9892578,9027.34765625,9082.443359375,56.1834579623136,20.5170948566129,26.325863,0,0,0,40,4449,199.9304,9054.8955078125,,,,,,,,,,,,,0,,,,-0.00245,,,,,,199.9892578,,,,
,31270386.105,199.99221805,13789.7250976563,3.21145565137771E-5,8.06890309324815E-7,1,0.999253354069792,40.0298881530762,1.98495818831248,20.1799999922514,0.000361312044735788,6.85377138048328E-5,0.25,4.97545297546307E-7,3.22248880803146E-5,5.3402899461995E-7,199.9919739,199.9924622,13759.6357421875,13819.814453125,56.6000659630637,20.518449050252,26.325863,0,0,0,40,4449,199.93475,13789.7250976563,,,,,,,,,,,,,0,,,,0.00245,,,,,,199.99221805,,,,
,31270480.88,199.99362185,18529.9658203125,1.83177455888899E-5,9.73075237467142E-7,1,0.999253354069792,40.0298881530762,1.9848168237816,20.1799999922514,0.000206935993532806,3.41271796023922E-5,0.25,-1.56164405182593E-7,1.83811573029263E-5,-1.36906034556236E-7,199.9935303,199.9937134,18497.75390625,18562.177734375,56.313208296506,20.5174906128646,26.325863,0,0,0,40,4449,199.93925,18529.9658203125,,,,,,,,,,,,,0,,,,0.00245,,,,,,199.99362185,,,,
,31270577.485,199.9986572,23357.5126953125,2.63366039409421E-6,1.30661830676525E-6,1,0.999253354069792,40.0298881530762,1.98478633233175,20.1799999922514,2.66478855714942E-5,2.27792957509245E-5,0.25,1.56198742119523E-6,2.641068239488E-6,1.57022196649557E-6,199.9986572,199.9986572,23354.92578125,23360.099609375,56.6321127323521,20.5192622106892,25.946213,0,0,0,40,4449,199.9369,23357.5126953125,,,,,,,,,,,,,0,,,,0,,,,,,199.9986572,,,,
,31270673.615,200.0003204,28160.388671875,-1.09221671508067E-5,1.22741933951191E-6,1,0.999253354069792,40.0298881530762,1.98489297395982,20.1799999922514,-0.00013115581037172,2.4348700734107E-5,0.25,4.05541639683221E-6,-1.09642478015013E-5,4.0576561892715E-6,200.0003204,200.0003204,28157.5859375,28163.19140625,56.5664559367368,20.520055588382,26.705515,0,0,0,40,4449,199.9381,28160.388671875,,,,,,,,,,,,,0,,,,-0.0049,,,,,,200.0003204,,,,
,31270769.785,200.0036163,32967.76953125,-2.89133526832775E-5,1.71503256677795E-6,1,0.999253354069792,40.0298881530762,1.98485627119265,20.1799999922514,-0.00032686304170163,-5.25910292411571E-5,0.25,3.59578554010137E-7,-2.90135789849293E-5,3.29738018224708E-7,200.0036163,200.0036163,32960.32421875,32975.21484375,56.5945945634291,20.5201012398559,26.705515,0,0,0,40,4449,199.9364,32967.76953125,,,,,,,,,,,,,0,,,,0.0049,,,,,,200.0036163,,,,
,31270864.245,200.0056839,37690.3671875,-4.42779280031166E-5,1.56585497313989E-6,1,0.999253354069792,40.0298881530762,1.98486436324589,20.1799999922514,-0.000503914427662593,-6.12261238358818E-5,0.25,2.26255022562443E-6,-4.44332601967633E-5,2.22285125283355E-6,200.0054932,200.0058746,37657.94140625,37722.79296875,56.9596150819099,20.5201166910715,25.946213,0,0,0,40,4449,199.93015,37690.3671875,,,,,,,,,,,,,0,,,,0.00245,,,,,,200.0056839,,,,
,31270960.82,200.00421905,42517.51953125,-6.15535156701886E-5,1.50203753558162E-6,1,0.999253354069792,40.0298881530762,1.98488768087893,20.1799999922514,-0.000708095403071036,-4.15604346947011E-5,0.25,7.00617395504553E-6,-6.17736026648326E-5,6.96444923741174E-6,200.0041199,200.0043182,42485.1796875,42549.859375,56.6203883045637,20.5209431532049,26.325863,0,0,0,40,4449,199.9279,42517.51953125,,,,,,,,,,,,,0,,,,0.00245,,,,,,200.00421905,,,,
,31271056.015,200.0089111,47273.224609375,-7.8217577914262E-5,2.03660674809452E-6,1,0.999253354069792,40.0298881530762,1.98509002302131,20.1799999922514,-0.000894963061903552,-8.11393398262004E-5,0.25,6.39232176979299E-6,-7.84945572815165E-5,6.33079176936716E-6,200.0089111,200.0089111,47248.22265625,47298.2265625,56.5312826533714,20.5191337359194,26.325863,0,0,0,40,4449,199.9196,47273.224609375,,,,,,,,,,,,,0,,,,0.00245,,,,,,200.0089111,,,,
,31271152.58,200.01013945,52100.9140625,-9.73666891184382E-5,1.76387297839699E-6,1,0.999253354069792,40.0298881530762,1.98494749612322,20.1799999922514,-0.00110508041884978,-0.000152299756839,0.25,3.40937561510128E-6,-9.77066356026854E-5,3.3172808734554E-6,200.0095825,200.0106964,52071.0078125,52130.8203125,56.7595181809868,20.5222184732779,26.705515,0,0,0,40,4449,199.91015,52100.9140625,,,,,,,,,,,,,0,,,,-0.0049,,,,,,200.01013945,,,,
,31271248.64,200.0081177,56900.5859375,-0.000114986060900161,1.99807355554503E-6,1,0.999253354069792,40.0298881530762,1.98487533446889,20.1799999922514,-0.00130376665821585,-0.000187010868922785,0.25,3.39161037428832E-6,-0.000115386883117608,3.28090807920527E-6,200.0081177,200.0081177,56898.17578125,56902.99609375,56.7180918694675,20.5208744669516,26.705515,0,0,0,40,4449,199.906,56900.5859375,,,,,,,,,,,,,0,,,,0,,,,,,200.0081177,,,,
,31271343.235,200.0076294,61631.31640625,-0.000132382494303233,2.73718553704848E-6,1,0.999253354069792,40.0298881530762,1.98465313901163,20.1799999922514,-0.00149911876938839,-0.000225281884594945,0.25,3.01781644461763E-6,-0.000132843049888854,2.88758472261724E-6,200.0076294,200.0076294,61601.4296875,61661.203125,56.8071975206598,20.5220462952464,26.325863,0,0,0,40,4449,199.8968,61631.31640625,,,,,,,,,,,,,0,,,,0.00245,,,,,,200.0076294,,,,
,31271438,200.0116577,66367.12109375,-0.000150311210299956,2.85130700369672E-6,1,0.999253354069792,40.0298881530762,1.98461420340454,20.1799999922514,-0.00169956805885684,-0.000270450231121311,0.25,2.12621240272102E-6,-0.000150832780230507,1.97417639950636E-6,200.0116577,200.0116577,66334.828125,66399.4140625,56.9275683126214,20.5204569637223,25.946213,0,0,0,40,4449,199.8886,66367.12109375,,,,,,,,,,,,,0,,,,-0.00245,,,,,,200.0116577,,,,
,31271533.375,200.0109406,71131.87890625,-0.000167914676704877,3.19087593502537E-6,1,0.999253354069792,40.0298881530762,1.98475708371117,20.1799999922514,-0.00189816213810093,-0.000305480636038091,0.25,2.0790948183352E-6,-0.000168497068136261,1.90859965698594E-6,200.0109406,200.0109406,71102.03125,71161.7265625,56.7446672391214,20.51946064018,26.705515,0,0,0,40,4449,199.8799,71131.87890625,,,,,,,,,,,,,0,,,,-0.0049,,,,,,200.0109406,,,,
,31271628.795,200.01475525,75902.7734375,-0.000186158926787075,2.14278601561095E-6,1,0.999253354069792,40.0298881530762,1.98480334022961,20.1799999922514,-0.00210010949601523,-0.000363663438514534,0.25,8.97429235511137E-8,-0.000186802287104422,-1.06523343503418E-7,200.0137177,200.0157928,75875.125,75930.421875,56.8900501436983,20.5180312670746,25.946213,0,0,0,40,4449,199.8666,75902.7734375,,,,,,,,,,,,,0,,,,0,,,,,,200.01475525,,,,
,31271724.64,200.0128021,80693.66796875,-0.000205591162783758,4.28235393679622E-6,1,0.999253354069792,40.0298881530762,1.98498895451853,20.1799999922514,-0.00232531655146752,-0.000368384542836248,0.25,3.04830409002891E-6,-0.000206304866829001,2.84219955079277E-6,200.0128021,200.0128021,80663.703125,80723.6328125,56.8275198621599,20.5168950975951,25.946213,0,0,0,40,4449,199.8538,80693.66796875,,,,,,,,,,,,,0,,,,0,,,,,,200.0128021,,,,
,31271819.2,200.0114441,85422.0625,-0.000222940346672484,2.80988457204863E-6,1,0.999253354069792,40.0298881530762,1.98495915398261,20.1799999922514,-0.00252319646217402,-0.00038973862445088,0.25,4.16728310225591E-6,-0.000223715258566726,3.94726725872096E-6,200.0113068,200.0115814,85387.1484375,85456.9765625,56.7204367550252,20.5162360374097,26.325863,0,0,0,40,4449,199.8472,85422.0625,,,,,,,,,,,,,0,,,,0,,,,,,200.0114441,,,,
,31271926.44,200.0134735,89977.09765625,-0.000236525920779479,3.10645760623511E-6,1,0.999253354069792,40.0298881530762,1.9848259477154,20.1799999922514,-0.00268022502919187,-0.000393648698256362,0.25,6.17715564521133E-6,-0.00023734994492464,5.95031668424633E-6,200.0134735,200.0134735,89973.5390625,89980.65625,56.7939098358329,20.5172322166022,25.946213,0,0,0,40,4449,199.83925,89977.09765625,,,,,,,,,,,,,0,,,,-0.00245,,,,,,200.0134735,,,,
,31272017.83,200.0084839,85426.8046875,-0.000223955087373362,3.37462038000302E-6,1,0.999253354069792,40.0298881530762,1.98503416505673,20.1799999922514,-0.00252910661502811,-0.000424155590004433,0.25,1.29405277127016E-6,-0.000224730504336916,1.06301852835374E-6,200.0084839,200.0084839,85419.2265625,85434.3828125,57.0534105042176,20.5141381612675,26.325863,0,0,0,40,4449,199.83205,85426.8046875,,,,,,,,,,,,,0,,,,0.00245,,,,,,200.0084839,,,,
,31272112.765,199.9965515,80683.01953125,-0.000203367828497776,3.1726405522924E-6,1,0.999253354069792,40.0298881530762,1.98487074032614,20.1799999922514,-0.00229652728631994,-0.000384608636433559,0.25,1.22216560757595E-6,-0.000204072031670051,1.0120750128524E-6,199.9965515,199.9965515,80655.59375,80710.4453125,56.7665528376599,20.5158371493393,26.325863,0,0,0,40,4449,199.8403,80683.01953125,,,,,,,,,,,,,0,,,,-0.00245,,,,,,199.9965515,,,,
,31272208.39,199.994812,75899.3828125,-0.000187057966672329,2.42269602816794E-6,1,0.999253354069792,40.0298881530762,1.98507419882965,20.1799999922514,-0.00211557374264032,-0.000336413774376322,0.25,2.66547955198818E-6,-0.000187707274091565,2.47714331577956E-6,199.994812,199.994812,75896.8125,75901.953125,56.9455457685637,20.5153608349114,26.325863,0,0,0,40,4449,199.848,75899.3828125,,,,,,,,,,,,,0,,,,0.0049,,,,,,199.994812,,,,
,31272305.075,199.9932709,71065.53125,-0.000168352155518157,2.46457588843142E-6,1,0.999253354069792,40.0298881530762,1.98503343975776,20.1799999922514,-0.00190635245368533,-0.000289095900051489,0.25,3.61106637979625E-6,-0.000168937773606098,3.44536666754333E-6,199.9932709,199.9932709,71037.5703125,71093.4921875,56.7173102409483,20.5169785326339,26.705515,0,0,0,40,4449,199.8507,71065.53125,,,,,,,,,,,,,0,,,,0.00245,,,,,,199.9932709,,,,
,31272400.47,199.990097,66300.13671875,-0.000152080648470957,2.69250566811143E-6,1,0.999253354069792,40.0298881530762,1.98508094496404,20.1799999922514,-0.001718865266926,-0.000280013963258212,0.25,1.59122575463157E-6,-0.000152607868532324,1.43543268816072E-6,199.990097,199.990097,66270.1640625,66330.109375,56.7696793517368,20.5179918822688,26.325863,0,0,0,40,4449,199.8594,66300.13671875,,,,,,,,,,,,,0,,,,0.00245,,,,,,199.990097,,,,
,31272496.58,199.98617555,61494.064453125,-0.000133494224617347,2.99533784891665E-6,1,0.999253354069792,40.0298881530762,1.98495956084417,20.1799999922514,-0.00151499747403077,-0.000209556834627863,0.25,4.60779867779124E-6,-0.00013396040172936,4.48185044700117E-6,199.9859619,199.9863892,61466.640625,61521.48828125,56.9705578811791,20.5182211280502,26.325863,0,0,0,40,4449,199.8705,61494.064453125,,,,,,,,,,,,,0,,,,-0.00245,,,,,,199.98617555,,,,
,31272589.71,199.9917755,56840.9921875,-0.000116894891063542,2.2467145778768E-6,1,0.999253354069792,40.0298881530762,1.98499859276016,20.1799999922514,-0.00131951934376818,-0.000224501373457169,0.25,4.00910386582255E-7,-0.000117299182639877,2.77817882360552E-7,199.9917755,199.9917755,56818.34375,56863.640625,56.8798889729483,20.5179133826026,26.705515,0,0,0,40,4449,199.8748,56840.9921875,,,,,,,,,,,,,0,,,,0,,,,,,199.9917755,,,,
,31272686.925,199.9909973,51981.380859375,-9.64614705325073E-5,3.07492663954522E-6,1,0.999253354069792,40.0298881530762,1.98505151824077,20.1799999922514,-0.00109160521092393,-0.000169643686176962,0.25,1.7155140334558E-6,-9.6796541458907E-5,1.61851153053082E-6,199.9909973,199.9909973,51951.5390625,52011.22265625,56.9158438848329,20.5195901033555,26.325863,0,0,0,40,4449,199.88085,51981.380859375,,,,,,,,,,,,,0,,,,-0.00245,,,,,,199.9909973,,,,
,31272784.01,199.9885406,47128.630859375,-8.23848992436871E-5,2.42882508372978E-6,1,0.999253354069792,40.0298881530762,1.98497642443907,20.1799999922514,-0.000930446251210903,-0.000155406309905347,0.25,5.32474667119429E-7,-8.26700608197031E-5,4.46232165201083E-7,199.9885406,199.9885406,47123.65234375,47133.609375,56.8454973181022,20.5230063071064,26.705515,0,0,0,40,4449,199.89315,47128.630859375,,,,,,,,,,,,,0,,,,0,,,,,,199.9885406,,,,
,31272879.59,199.9915466,42353.23046875,-6.36677267586698E-5,1.76019142212049E-6,1,0.999253354069792,40.0298881530762,1.98486197169689,20.1799999922514,-0.000718314900528166,-0.000124133042872764,0.25,5.34557422471959E-8,-6.38876938978207E-5,-1.45605447411516E-8,199.9915466,199.9915466,42350.8671875,42355.59375,56.973684395256,20.5223765067652,26.325863,0,0,0,40,4449,199.9028,42353.23046875,,,,,,,,,,,,,0,,,,0.0049,,,,,,199.9915466,,,,
,31272975.165,199.98725125,37575.47265625,-4.57689789775412E-5,1.85489280779094E-6,1,0.999253354069792,40.0298881530762,1.98496640175331,20.1799999922514,-0.000519135216269157,-7.35071784258762E-5,0.25,1.43315812860773E-6,-4.5928597116797E-5,1.3889867623005E-6,199.9868011,199.9877014,37548.0078125,37602.9375,56.9752476522945,20.5215365641817,26.705515,0,0,0,40,4449,199.9076,37575.47265625,,,,,,,,,,,,,0,,,,-0.00245,,,,,,199.98725125,,,,
,31273071.11,199.9870911,32778.486328125,-2.89845771452457E-5,1.85874509974192E-6,1,0.999253354069792,40.0298881530762,1.98494191897622,20.1799999922514,-0.000327960438069896,-5.11190607090302E-5,0.25,5.02631404026681E-7,-2.90852182374378E-5,4.73202332310203E-7,199.9870911,199.9870911,32776.07421875,32780.8984375,57.0463758475445,20.5234177346563,26.705515,0,0,0,40,4449,199.9163,32778.486328125,,,,,,,,,,,,,0,,,,0.0049,,,,,,199.9870911,,,,
,31273165.545,199.9894409,28058.35546875,-1.33165278790418E-5,1.1758641663038E-6,1,0.999253354069792,40.0298881530762,1.98497735315674,20.1799999922514,-0.00015189348430258,-1.6493774103341E-5,0.25,8.50787796439303E-7,-1.33634292962513E-5,8.39382460610191E-7,199.9892883,199.9895935,28028.421875,28088.2890625,56.9111541137176,20.5212620915452,26.325863,0,0,0,40,4449,199.9276,28058.35546875,,,,,,,,,,,,,0,,,,0,,,,,,199.9894409,,,,
,31273261.035,199.99102785,23288.353515625,1.53860975605889E-6,1.17136440216768E-6,1,0.999253354069792,40.0298881530762,1.9850310646858,20.1799999922514,1.68063249348655E-5,6.19000172711463E-6,0.25,2.8145423836328E-7,1.54361873853257E-6,2.8408620767576E-7,199.990799,199.9912567,23260.978515625,23315.728515625,57.007294421583,20.5221844579317,26.325863,0,0,0,40,4449,199.9332,23288.353515625,,,,,,,,,,,,,0,,,,-0.00245,,,,,,199.99102785,,,,
,31273357.725,199.9889145,18455.9033203125,1.70140088697226E-5,7.98039222860373E-7,1,0.999253354069792,40.0298881530762,1.98499940372528,20.1799999922514,0.000191199048509987,3.76054660297215E-5,0.25,3.78333204053236E-7,1.70723443603305E-5,3.98027856215672E-7,199.988678,199.989151,18423.267578125,18488.5390625,57.0643533034868,20.5237279740446,26.325863,0,0,0,40,4449,199.9443,18455.9033203125,,,,,,,,,,,,,0,,,,0.00245,,,,,,199.9889145,,,,
,31273453.79,199.99263,13650.880859375,3.22688555679463E-5,9.1152748648161E-7,1,0.999253354069792,40.0298881530762,1.98493993186611,20.1799999922514,0.000363983230003063,6.34636056458962E-5,0.25,2.10069212765411E-8,3.2380235446548E-5,5.60112856868287E-8,199.99263,199.99263,13620.8154296875,13680.9462890625,56.8197035769676,20.5259340170677,25.946213,0,0,0,40,4449,199.9476,13650.880859375,,,,,,,,,,,,,0,,,,0.00245,,,,,,199.99263,,,,
,31273549.655,199.9953918,8860.5703125,4.27347624442395E-5,8.58757626709856E-7,1,0.999253354069792,40.0298881530762,1.98502425348727,20.1799999922514,0.000481728060871198,8.5932707891028E-5,0.25,1.94598539615762E-7,4.28820717096908E-5,2.41600793625719E-7,199.9953918,199.9953918,8833.1826171875,8887.9580078125,56.9830639374868,20.5263013706154,26.705515,0,0,0,40,4449,199.9521,8860.5703125,,,,,,,,,,,,,0,,,,0,,,,,,199.9953918,,,,
,31273644.005,199.9906006,4145.26635742188,4.82093982788281E-5,4.36874644243686E-7,1,0.999253354069792,40.0298881530762,1.98493276894764,20.1799999922514,0.000543858398805871,9.43957421370762E-5,0.25,-5.81403446172294E-9,4.83758208081514E-5,4.64999168133178E-8,199.9906006,199.9906006,4115.1142578125,4175.41845703125,57.047939104583,20.5274131751245,25.946213,0,0,0,40,4449,199.9576,4145.26635742188,,,,,,,,,,,,,0,,,,-0.00245,,,,,,199.9906006,,,,
,31273737.07,199.99372865,-505.416427612305,2.9444139623195E-5,3.28488224785076E-7,1,0.999253354069792,40.0298881530762,1.98498768219323,20.1799999922514,0.000331924012665187,5.90878937268532E-5,0.25,1.23510227098326E-7,2.95456381458488E-5,1.55925545383762E-7,199.9935913,199.993866,-532.753112792969,-478.079742431641,57.0932735586983,20.5268086646336,25.946213,0,0,0,40,4449,199.96145,-505.416427612305,,,,,,,,,,,,,0,,,,-0.00245,,,,,,199.99372865,,,,
,31273831.98,199.9942169,-5245.07788085937,-2.93210912588659E-5,6.01169964793964E-7,1,0.999253354069792,40.0298881530762,1.98499106973666,20.1799999922514,-0.000329911522119816,-6.2444959941256E-5,0.25,-4.42489589366216E-7,-2.94218240920463E-5,-4.75835166749286E-7,199.9942169,199.9942169,-5272.67236328125,-5217.4833984375,56.9588334533906,20.5281884637486,26.325863,0,0,0,40,4449,199.9686,-5245.07788085937,,,,,,,,,,,,,0,,,,-0.0049,,,,,,199.9942169,,,,
,31273926.945,200.0024872,-9993.78271484375,-3.7958574513084E-5,7.92658001529745E-7,1,0.999253354069792,40.0298881530762,1.98501721249252,20.1799999922514,-0.000426705442951669,-8.31304935433794E-5,0.25,-7.75823787324048E-7,-3.80887601952065E-5,-8.19637290376972E-7,200.0023651,200.0026093,-10026.330078125,-9961.2353515625,57.0666981890445,20.5248949542813,26.325863,0,0,0,40,4449,199.96235,-9993.78271484375,,,,,,,,,,,,,0,,,,0,,,,,,200.0024872,,,,
,31274021.345,200.00595855,-14713.6201171875,-2.72049640894796E-5,1.10455466761578E-6,1,0.999253354069792,40.0298881530762,1.98510970352467,20.1799999922514,-0.000306007507798956,-5.85837407070067E-5,0.25,-4.67558591168636E-7,-2.72983683072083E-5,-4.98610740507374E-7,200.0059204,200.0059967,-14743.65234375,-14683.587890625,57.1284468420637,20.5252346777159,26.705515,0,0,0,40,4449,199.95565,-14713.6201171875,,,,,,,,,,,,,0,,,,-0.00245,,,,,,200.00595855,,,,
,31274116.29,200.0068817,-19458.271484375,-1.27948757400821E-5,1.06183381446867E-6,1,0.999253354069792,40.0298881530762,1.98503267421744,20.1799999922514,-0.000143659764547045,-2.90173483207158E-5,0.25,-3.49834098544463E-7,-1.28386679226211E-5,-3.64864860430456E-7,200.0068817,200.0068817,-19460.8125,-19455.73046875,57.0151107067753,20.525890721916,26.325863,0,0,0,40,4449,199.9498,-19458.271484375,,,,,,,,,,,,,0,,,,-0.00245,,,,,,200.0068817,,,,
,31274210.625,200.0086365,-24173.4677734375,2.62141911202526E-6,1.10383684254993E-6,1,0.999253354069792,40.0298881530762,1.98491638357067,20.1799999922514,2.95302919022949E-5,5.37554036395623E-6,0.25,2.12203900532783E-8,2.63044634648819E-6,2.41210944179798E-8,200.0086365,200.0086365,-24178.193359375,-24168.7421875,57.065134932006,20.5293980642055,25.946213,0,0,0,40,4449,199.9392,-24173.4677734375,,,,,,,,,,,,,0,,,,-0.00245,,,,,,200.0086365,,,,
,31274305.11,200.0116577,-28893.5986328125,1.74065208390217E-5,1.38031859613288E-6,1,0.999253354069792,40.0298881530762,1.98503332285239,20.1799999922514,0.000198071007122188,2.4322307567354E-5,0.25,-8.67252948539141E-7,1.7467551465446E-5,-8.51504701063287E-7,200.0116577,200.0116577,-28921.087890625,-28866.109375,57.0205821064099,20.5262841895369,25.946213,0,0,0,40,4449,199.9294,-28893.5986328125,,,,,,,,,,,,,0,,,,0,,,,,,200.0116577,,,,
,31274401.365,200.0132294,-33705.759765625,3.36463575634683E-5,1.4741571721872E-6,1,0.999253354069792,40.0298881530762,1.98500465529897,20.1799999922514,0.000381492190171454,5.48946114519917E-5,0.25,-9.77738624914479E-7,3.37635818623723E-5,-9.44951114333079E-7,200.0132294,200.0132294,-33733.19140625,-33678.328125,56.9791557948906,20.5284310955413,26.325863,0,0,0,40,4449,199.92,-33705.759765625,,,,,,,,,,,,,0,,,,-0.00245,,,,,,200.0132294,,,,
,31274498.945,200.0139084,-38582.529296875,5.09616061076451E-5,1.61321762300209E-6,1,0.999253354069792,40.0298881530762,1.98497716841795,20.1799999922514,0.000575169861695964,9.83449722293465E-5,0.25,-1.33315045924148E-7,5.11377221254201E-5,-7.91039443767447E-8,200.0135193,200.0142975,-38610.11328125,-38554.9453125,57.1198489283522,20.5284709863279,26.705515,0,0,0,40,4449,199.90955,-38582.529296875,,,,,,,,,,,,,0,,,,-0.0049,,,,,,200.0139084,,,,
,31274594.625,200.0136871,-43362.916015625,6.89869618718884E-5,1.48707673665989E-6,1,0.999253354069792,40.0298881530762,1.98492092709276,20.1799999922514,0.000779265037410156,0.000129235447652521,0.25,-5.25251562712922E-7,6.92257606870911E-5,-4.53196282686848E-7,200.0136871,200.0136871,-43368.14453125,-43357.6875,57.0338697912368,20.5288455616289,26.325863,0,0,0,40,4449,199.90075,-43362.916015625,,,,,,,,,,,,,0,,,,0,,,,,,200.0136871,,,,
,31274691.09,200.0128174,-48182.578125,8.36761221092481E-5,1.98253887651065E-6,1,0.999253354069792,40.0298881530762,1.98489429834614,20.1799999922514,0.000947314210140044,0.00014445955786558,0.25,-1.72652634213416E-6,8.39669579265682E-5,-1.64306260727025E-6,200.0128174,200.0128174,-48185.1640625,-48179.9921875,57.1253203279868,20.5301879603268,26.325863,0,0,0,40,4449,199.8864,-48182.578125,,,,,,,,,,,,,0,,,,0,,,,,,200.0128174,,,,
,31274788.235,200.0097046,-53039.9453125,0.000101612276431582,2.10922739665001E-6,1,0.999253354069792,40.0298881530762,1.98486345606559,20.1799999922514,0.00115142318867986,0.000169279504941188,0.25,-2.64092989949748E-6,0.000101966071992372,-2.54167632968637E-6,200.0097046,200.0097046,-53042.22265625,-53037.66796875,57.0541921327368,20.5315980057921,26.705515,0,0,0,40,4449,199.8818,-53039.9453125,,,,,,,,,,,,,0,,,,-0.0049,,,,,,200.0097046,,,,
,31274883,200.00967405,-57774.5625,0.000117389387466714,1.98099180149906E-6,1,0.999253354069792,40.0298881530762,1.98485771305154,20.1799999922514,0.00133075380719417,0.000192366613075729,0.25,-3.3340553086083E-6,0.000117798447240442,-3.22061909094758E-6,200.0093231,200.010025,-57799.7890625,-57749.3359375,56.9908802226791,20.5321855559823,26.705515,0,0,0,40,4449,199.87515,-57774.5625,,,,,,,,,,,,,0,,,,0,,,,,,200.00967405,,,,
,31274977.685,200.0149384,-62507.603515625,0.000134941646419386,2.15965949560957E-6,1,0.999253354069792,40.0298881530762,1.98496042234688,20.1799999922514,0.00152629891307683,0.000241335263601453,0.25,-2.04215691887671E-6,0.000135409977027659,-1.90585884236374E-6,200.0149384,200.0149384,-62532.66796875,-62482.5390625,57.0964000727753,20.5317917074316,26.325863,0,0,0,40,4449,199.8611,-62507.603515625,,,,,,,,,,,,,0,,,,-0.0049,,,,,,200.0149384,,,,
,31275073.595,200.01519015,-67300.140625,0.000155167042199195,2.0931681452918E-6,1,0.999253354069792,40.0298881530762,1.98494838401462,20.1799999922514,0.00175927325455763,0.000253214711794217,0.25,-4.50114816967484E-6,0.000155707892188709,-4.3521974126254E-6,200.0147858,200.0155945,-67330.1015625,-67270.1796875,57.1714364106214,20.5311483884709,25.946213,0,0,0,40,4449,199.84975,-67300.140625,,,,,,,,,,,,,0,,,,-0.00245,,,,,,200.01519015,,,,
,31275171.5,200.0116272,-72194.39453125,0.00017409093697621,2.07638455941885E-6,1,0.999253354069792,40.0298881530762,1.98493016011314,20.1799999922514,0.00196704479491473,0.000323075960401677,0.25,-1.59415703547558E-6,0.000174694158940213,-1.41550237843709E-6,200.0116272,200.0116272,-72196.8046875,-72191.984375,57.0112025641791,20.5332267074591,26.325863,0,0,0,40,4449,199.8473,-72194.39453125,,,,,,,,,,,,,0,,,,-0.0049,,,,,,200.0116272,,,,
,31275268.3,200.0116425,-77031.29296875,0.000191053439129181,2.22891030682268E-6,1,0.999253354069792,40.0298881530762,1.98497031215061,20.1799999922514,0.00216242852402111,0.000333354100849473,0.25,-3.62896789042589E-6,0.000191717476449864,-3.4398211682371E-6,200.0116425,200.0116425,-77058.6953125,-77003.890625,57.0487207331022,20.5314845429151,26.705515,0,0,0,40,4449,199.82925,-77031.29296875,,,,,,,,,,,,,0,,,,0,,,,,,200.0116425,,,,
,31275365.875,200.0111694,-81906.109375,0.000208824033476536,2.7955016618634E-6,1,0.999253354069792,40.0298881530762,1.98481164368152,20.1799999922514,0.00236324205511942,0.000365152132201765,0.25,-3.89340911849632E-6,0.00020954982144604,-3.68689743243589E-6,200.0111694,200.0111694,-81936.1015625,-81876.1171875,57.1964485232368,20.5346293847254,26.705515,0,0,0,40,4449,199.82075,-81906.109375,,,,,,,,,,,,,0,,,,-0.00245,,,,,,200.0111694,,,,
,31275461.04,200.0118713,-86663.17578125,0.000224757840003298,2.75628717939874E-6,1,0.999253354069792,40.0298881530762,1.98499839484403,20.1799999922514,0.00254584236037606,0.000381246618951937,0.25,-5.23620927272125E-6,0.000225540165111622,-5.01806693704439E-6,200.0118713,200.0118713,-86693.03125,-86633.3203125,57.1690915250637,20.5326874344079,25.946213,0,0,0,40,4449,199.81495,-86663.17578125,,,,,,,,,,,,,0,,,,0,,,,,,200.0118713,,,,
,31275566.97,200.0126953,-88790.26171875,0.000235398174989997,1.64926379762715E-6,1,0.999253354069792,40.0298881530762,1.98490523403035,20.1799999922514,0.00266722406769196,0.000393648772628041,0.25,-5.98283445837047E-6,0.000236218080452045,-5.75631241325305E-6,200.0126953,200.0126953,-88817.6484375,-88762.875,57.0666981890445,20.5348080056211,25.946213,0,0,0,40,4449,199.80055,-88790.26171875,,,,,,,,,,,,,0,,,,-0.00245,,,,,,200.0126953,,,,
,31275659.025,200.00252535,-84188.26953125,0.000219264529460704,3.18032951536283E-6,1,0.999253354069792,40.0298881530762,1.98499431205028,20.1799999922514,0.00248129745149913,0.000385272824729435,0.25,-3.92559302312915E-6,0.000220026523530613,-3.70841583411636E-6,200.0014191,200.0036316,-84215.7578125,-84160.78125,57.0440309619868,20.5338246908771,26.705515,0,0,0,40,4449,199.80395,-84188.26953125,,,,,,,,,,,,,0,,,,0.00245,,,,,,200.00252535,,,,
,31275754.425,199.9982452,-79423.33203125,0.000200114354678387,2.47071153543263E-6,1,0.999253354069792,40.0298881530762,1.9849708261544,20.1799999922514,0.00227101644476062,0.000314437551885282,0.25,-6.87913283698107E-6,0.000200813244091601,-6.69185026562255E-6,199.9979095,199.9985809,-79453.40625,-79393.2578125,56.9150622563137,20.5321128127487,26.325863,0,0,0,40,4449,199.8009,-79423.33203125,,,,,,,,,,,,,0,,,,0.00245,,,,,,199.9982452,,,,
,31275849.295,199.9954529,-74681.140625,0.000180684360444097,2.04179766184625E-6,1,0.999253354069792,40.0298881530762,1.98498701796871,20.1799999922514,0.00204691391577613,0.00030472648589486,0.25,-4.36635560271854E-6,0.000181313414377657,-4.19047755754067E-6,199.9954529,199.9954529,-74711.2734375,-74651.0078125,57.1120326431599,20.5325954781602,26.705515,0,0,0,40,4449,199.8089,-74681.140625,,,,,,,,,,,,,0,,,,-0.00245,,,,,,199.9954529,,,,
,31275946.275,199.9902039,-69833.95703125,0.000166402346207352,2.82336600556095E-6,1,0.999253354069792,40.0298881530762,1.98491218986682,20.1799999922514,0.00188134041129083,0.000301987998355906,0.25,-2.12826893653663E-6,0.000166979656336264,-1.9593768809084E-6,199.9902039,199.9902039,-69864.015625,-69803.8984375,56.9885353371214,20.5337057672905,26.325863,0,0,0,40,4449,199.8186,-69833.95703125,,,,,,,,,,,,,0,,,,0.00245,,,,,,199.9902039,,,,
,31276042.14,199.9890289,-65041.95703125,0.000147856657289841,1.27778724831776E-6,1,0.999253354069792,40.0298881530762,1.98486873891674,20.1799999922514,0.00167275995036633,0.000261807421263254,0.25,-2.4692079070799E-6,0.000148370201759844,-2.32080732255683E-6,199.9890289,199.9890289,-65076.95703125,-65006.95703125,57.007294421583,20.533427780953,26.705515,0,0,0,40,4449,199.82415,-65041.95703125,,,,,,,,,,,,,0,,,,-0.0049,,,,,,199.9890289,,,,
,31276138.015,199.9885712,-60251.87109375,0.000127734953473414,2.32687888444065E-6,1,0.999253354069792,40.0298881530762,1.98484957903639,20.1799999922514,0.00144816826767463,0.000208517799477664,0.25,-3.69882511078333E-6,0.000128180241706464,-3.57575263741975E-6,199.9885712,199.9885712,-60274.3984375,-60229.34375,57.027616763083,20.5341879689585,26.705515,0,0,0,40,4449,199.8349,-60251.87109375,,,,,,,,,,,,,0,,,,-0.00245,,,,,,199.9885712,,,,
,31276233.755,199.9860382,-55465.203125,0.000110212807440649,1.61487499528516E-6,1,0.999253354069792,40.0298881530762,1.98499772289232,20.1799999922514,0.00124778442296446,0.000190401230971744,0.25,-2.26321542990718E-6,0.000110596005655607,-2.15358269502418E-6,199.9860382,199.9860382,-55472.7109375,-55457.6953125,57.1690915250637,20.5313995038339,26.705515,0,0,0,40,4449,199.84635,-55465.203125,,,,,,,,,,,,,0,,,,0,,,,,,199.9860382,,,,
,31276330.465,199.9873962,-50632.875,9.33150223568628E-5,2.13365640118432E-6,1,0.999253354069792,40.0298881530762,1.98497939786285,20.1799999922514,0.00105829378645686,0.000150677192909725,0.25,-2.84985424017561E-6,9.36404366914677E-5,-2.76005614945997E-6,199.9873962,199.9873962,-50665.37109375,-50600.37890625,57.0229269919676,20.5327439959722,26.705515,0,0,0,40,4449,199.85665,-50632.875,,,,,,,,,,,,,0,,,,0,,,,,,199.9873962,,,,
,31276426.395,199.98969265,-45840.107421875,7.71515432980396E-5,1.55393710066053E-6,1,0.999253354069792,40.0298881530762,1.98506853383445,20.1799999922514,0.00087702493164268,0.000113036732633742,0.25,-3.37983594281154E-6,7.74216620107587E-5,-3.30896577656667E-6,199.9895782,199.9898071,-45872.359375,-45807.85546875,56.9189703989099,20.5298716837731,26.325863,0,0,0,40,4449,199.86535,-45840.107421875,,,,,,,,,,,,,0,,,,0,,,,,,199.98969265,,,,
,31276522.405,199.9901352,-41040.869140625,6.04738123670003E-5,1.9056691824518E-6,1,0.999253354069792,40.0298881530762,1.98508303774327,20.1799999922514,0.000684690613556586,0.000104458376966588,0.25,-1.24389450397737E-6,6.06840198696687E-5,-1.18336500314245E-6,199.9896393,199.9906311,-41070.72265625,-41011.015625,57.068261446083,20.5294099663667,26.705515,0,0,0,40,4449,199.87395,-41040.869140625,,,,,,,,,,,,,0,,,,0.00245,,,,,,199.9901352,,,,
,31276616.78,199.99017335,-36325.521484375,4.28014105137919E-5,1.4176233735205E-6,1,0.999253354069792,40.0298881530762,1.98508006578033,20.1799999922514,0.000487032213817191,5.99342945105717E-5,0.25,-2.12122193752323E-6,4.2951510423058E-5,-2.08258097909445E-6,199.9901581,199.9901886,-36358.13671875,-36292.90625,57.0737328457176,20.5294163698631,26.705515,0,0,0,40,4449,199.8807,-36325.521484375,,,,,,,,,,,,,0,,,,0.0049,,,,,,199.99017335,,,,
,31276710.9,199.9878845,-31621.3193359375,2.55685225157408E-5,1.45674664198109E-6,1,0.999253354069792,40.0298881530762,1.98504632828009,20.1799999922514,0.000292094846468558,2.91330549786074E-5,0.25,-1.85841372232764E-6,2.56588218268627E-5,-1.83732282395787E-6,199.9878845,199.9878845,-31626.322265625,-31616.31640625,57.1237570709483,20.5307895873006,26.705515,0,0,0,40,4449,199.8896,-31621.3193359375,,,,,,,,,,,,,0,,,,-0.0049,,,,,,199.9878845,,,,
,31276805.48,199.98748015,-26893.87109375,1.05154150609453E-5,1.03313049795216E-6,1,0.999253354069792,40.0298881530762,1.98514988390845,20.1799999922514,0.000120497618865252,9.88892276200189E-6,0.25,-9.49837792272155E-7,1.0552750562025E-5,-9.41784476696844E-7,199.9871826,199.9877777,-26923.8515625,-26863.890625,57.1409528983714,20.5273116054608,26.325863,0,0,0,40,4449,199.89775,-26893.87109375,,,,,,,,,,,,,0,,,,0.00245,,,,,,199.98748015,,,,
,31276900.005,199.9864578,-22168.490234375,-5.09037557879047E-6,9.28688707127466E-7,1,0.999253354069792,40.0298881530762,1.98494951646727,20.1799999922514,-5.67170128001707E-5,-1.4048748542578E-5,0.25,-3.61219574983821E-7,-5.10756248867974E-6,-3.67962375545644E-7,199.9862213,199.9866943,-22191.119140625,-22145.861328125,57.1081245005637,20.5305390611063,26.705515,0,0,0,40,4449,199.90845,-22168.490234375,,,,,,,,,,,,,0,,,,0,,,,,,199.9864578,,,,
,31276995.95,199.9917603,-17373.9931640625,-1.99593650276126E-5,1.15373481073056E-6,1,0.999253354069792,40.0298881530762,1.98507520752813,20.1799999922514,-0.000222921586517421,-5.20897954500972E-5,0.25,-1.15050884561199E-6,-2.00270311090924E-5,-1.17606450728293E-6,199.9917603,199.9917603,-17403.814453125,-17344.171875,56.9236601700253,20.5259215714108,26.325863,0,0,0,40,4449,199.9166,-17373.9931640625,,,,,,,,,,,,,0,,,,-0.00245,,,,,,199.9917603,,,,
,31277092.26,199.9920807,-12561.3149414062,-3.38610896718317E-5,8.85897083079106E-7,1,0.999253354069792,40.0298881530762,1.98520113605846,20.1799999922514,-0.00038108905071615,-7.17972010071781E-5,0.25,-4.82365970204679E-7,-3.39774645044993E-5,-5.20706104423708E-7,199.9920807,199.9920807,-12591.224609375,-12531.4052734375,57.0635716749676,20.5258558309663,26.705515,0,0,0,40,4449,199.91995,-12561.3149414062,,,,,,,,,,,,,0,,,,0.00245,,,,,,199.9920807,,,,
,31277188.15,199.9920197,-7765.74340820312,-4.43158311040407E-5,6.26663004633978E-7,1,0.999253354069792,40.0298881530762,1.98520864784449,20.1799999922514,-0.000499027526361239,-9.23871313240013E-5,0.25,-4.91360779895126E-7,-4.44682776280253E-5,-5.41125498592117E-7,199.9920197,199.9920197,-7768.142578125,-7763.34423828125,56.9088092281599,20.5255615826323,26.325863,0,0,0,40,4449,199.9249,-7765.74340820312,,,,,,,,,,,,,0,,,,0,,,,,,199.9920197,,,,
,31277281.95,199.9924927,-3079.96374511719,-4.79137399703346E-5,3.88582937047345E-7,1,0.999253354069792,40.0298881530762,1.98522011759631,20.1799999922514,-0.000539470371765904,-0.000100320178169791,0.25,-5.69460128211907E-7,-4.80785106764276E-5,-6.23462199059318E-7,199.9924927,199.9924927,-3104.837890625,-3055.08959960937,57.0065127930637,20.5262789361844,26.705515,0,0,0,40,4449,199.9291,-3079.96374511719,,,,,,,,,,,,,0,,,,0.00245,,,,,,199.9924927,,,,
,31277372.215,199.9954376,1431.03057861328,-1.50568488555127E-5,4.36118090266618E-7,1,0.999253354069792,40.0298881530762,1.98511856728779,20.1799999922514,-0.00017018609747728,-2.76876595389107E-5,0.25,1.61094131704233E-7,-1.51089949598701E-5,1.45292137266686E-7,199.9954376,199.9954376,1396.22741699219,1465.83374023438,56.760299809506,20.5265460163946,25.946213,0,0,0,40,4449,199.93455,1431.03057861328,,,,,,,,,,,,,0,,,,-0.00245,,,,,,199.9954376,,,,
,31277466.45,199.99653625,6140.43725585938,3.47692572117621E-5,5.40454481108388E-7,1,0.999253354069792,40.0298881530762,1.98513507981944,20.1799999922514,0.000392497144093807,6.68130044895679E-5,0.25,-1.17018706913035E-7,3.48894012265016E-5,-7.9694118362304E-8,199.9962158,199.9968567,6108.052734375,6172.82177734375,57.0463758475445,20.5265531076663,26.705515,0,0,0,40,4449,199.93645,6140.43725585938,,,,,,,,,,,,,0,,,,0.0049,,,,,,199.99653625,,,,
,31277560.555,200.00169375,10844.0751953125,3.73582858806484E-5,8.54653258406378E-7,1,0.999253354069792,40.0298881530762,1.98499027701249,20.1799999922514,0.000420653550264451,7.77754681587953E-5,0.25,4.05502227051533E-7,3.74868023093756E-5,4.47383513160142E-7,200.0010529,200.0023346,10816.9189453125,10871.2314453125,57.058100275333,20.5288730920256,26.325863,0,0,0,40,4449,199.9333,10844.0751953125,,,,,,,,,,,,,0,,,,0,,,,,,200.00169375,,,,
,31277654.5,200.00608825,15539.42578125,2.56472198412556E-5,7.36683959368164E-7,1,0.999253354069792,40.0298881530762,1.98524117789648,20.1799999922514,0.00028962682268606,4.87675960938686E-5,0.25,-1.32230739042924E-7,2.57358960804397E-5,-1.04937186312229E-7,200.0057068,200.0064697,15509.7578125,15569.09375,56.946327397083,20.5248114900196,26.325863,0,0,0,40,4449,199.92575,15539.42578125,,,,,,,,,,,,,0,,,,0,,,,,,200.00608825,,,,
,31277748.805,200.00589755,20251.3583984375,1.07757162541948E-5,1.12055380323394E-6,1,0.999253354069792,40.0298881530762,1.98507879243229,20.1799999922514,0.000122539410562531,1.55265584160795E-5,0.25,-4.95330524613609E-7,1.08134514986035E-5,-4.85400016309795E-7,200.0054932,200.0063019,20221.4140625,20281.302734375,56.9252234270637,20.5263549429667,26.705515,0,0,0,40,4449,199.92055,20251.3583984375,,,,,,,,,,,,,0,,,,0,,,,,,200.00589755,,,,
,31277845.245,200.0070801,25074.193359375,-3.78036618641796E-6,1.41076048068779E-6,1,0.999253354069792,40.0298881530762,1.98508837128516,20.1799999922514,-4.56307473941021E-5,9.75832283464453E-6,0.25,1.52154948062078E-6,-3.79505856547997E-6,1.52272583499755E-6,200.0070801,200.0070801,25044.375,25104.01171875,56.983845566006,20.5244438285134,26.705515,0,0,0,40,4449,199.9151,25074.193359375,,,,,,,,,,,,,0,,,,0.00245,,,,,,200.0070801,,,,
,31277940.09,200.01071165,29814.6904296875,-1.94157734718105E-5,1.4790490506644E-6,1,0.999253354069792,40.0298881530762,1.98495497585097,20.1799999922514,-0.000223602840862454,-1.17178242378671E-5,0.25,2.33345033504208E-6,-1.94853205847277E-5,2.32060512404366E-6,200.0104065,200.0110168,29782.240234375,29847.140625,56.9893169656406,20.5265246565943,25.946213,0,0,0,40,4449,199.9053,29814.6904296875,,,,,,,,,,,,,0,,,,0.00245,,,,,,200.01071165,,,,
,31278034.445,200.0113525,34529.98828125,-3.53860274599421E-5,1.61369937083267E-6,1,0.999253354069792,40.0298881530762,1.98507976600781,20.1799999922514,-0.000402848951144035,-4.84227969202449E-5,0.25,1.85370622836068E-6,-3.55102028346484E-5,1.82208085445827E-6,200.0113525,200.0113525,34525.046875,34534.9296875,56.9009929429675,20.5246341737868,26.705515,0,0,0,40,4449,199.89845,34529.98828125,,,,,,,,,,,,,0,,,,-0.00245,,,,,,200.0113525,,,,
,31278130.925,200.0114136,39351.998046875,-5.23376478823072E-5,1.46765800754526E-6,1,0.999253354069792,40.0298881530762,1.98494931258737,20.1799999922514,-0.000593524281413323,-8.4694174149204E-5,0.25,1.58223993428899E-6,-5.25200753865213E-5,1.53156650816681E-6,200.0114136,200.0114136,39322.3125,39381.68359375,57.0205821064099,20.5260586052215,26.705515,0,0,0,40,4449,199.8896,39351.998046875,,,,,,,,,,,,,0,,,,-0.0049,,,,,,200.0114136,,,,
,31278226.875,200.0122375,44147.421875,-7.08513684213249E-5,1.67065196547616E-6,1,0.999253354069792,40.0298881530762,1.9848909080139,20.1799999922514,-0.000802786376064656,-0.000118488048170677,0.25,1.80159455950002E-6,-7.10979775572756E-5,1.73196562010161E-6,200.0122375,200.0122375,44120.0625,44174.78125,56.9392927404099,20.5260504733919,27.085165,0,0,0,40,4449,199.88015,44147.421875,,,,,,,,,,,,,0,,,,0,,,,,,200.0122375,,,,
,31278322.915,200.0104065,48950.275390625,-8.77936809610005E-5,2.1427754445853E-6,1,0.999253354069792,40.0298881530762,1.98481841854911,20.1799999922514,-0.000996296374491944,-0.000137728431383711,0.25,3.03786119595197E-6,-8.81001484640846E-5,2.9545486070693E-6,200.0104065,200.0104065,48947.80859375,48952.7421875,56.9049010855637,20.5280281571424,25.946213,0,0,0,40,4449,199.8728,48950.275390625,,,,,,,,,,,,,0,,,,0,,,,,,200.0104065,,,,
,31278418.72,200.0110168,53738.0078125,-0.000105202378232431,1.44354680062704E-6,1,0.999253354069792,40.0298881530762,1.98478844435952,20.1799999922514,-0.00119271697916146,-0.000171479793066792,0.25,3.06880905771008E-6,-0.000105569028449239,2.96722414398743E-6,200.0110168,200.0110168,53735.30078125,53740.71484375,56.9213152844676,20.5270715580102,26.705515,0,0,0,40,4449,199.862,53738.0078125,,,,,,,,,,,,,0,,,,-0.0049,,,,,,200.0110168,,,,
,31278514.92,200.0127563,58545.884765625,-0.000123929959109752,1.89092144366136E-6,1,0.999253354069792,40.0298881530762,1.98482855781619,20.1799999922514,-0.00140297736406828,-0.000214034175519446,0.25,2.5488765922604E-6,-0.000124360767471426,2.42579161429139E-6,200.0127563,200.0127563,58523.15625,58568.61328125,56.8556584888522,20.5255025805178,26.705515,0,0,0,40,4449,199.8524,58545.884765625,,,,,,,,,,,,,0,,,,-0.00245,,,,,,200.0127563,,,,
,31278609.325,200.0128937,63264.080078125,-0.000140988327312538,2.31657432234006E-6,1,0.999253354069792,40.0298881530762,1.98485901187429,20.1799999922514,-0.00159443076546263,-0.00025319275074668,0.25,2.04004882560658E-6,-0.000141477558572418,1.89735731727343E-6,200.0128937,200.0128937,63236.359375,63291.80078125,56.8040710065829,20.5257209399751,26.325863,0,0,0,40,4449,199.84735,63264.080078125,,,,,,,,,,,,,0,,,,0,,,,,,200.0128937,,,,
,31278711.075,200.0115509,68349.296875,-0.000157863546706755,2.37639014880729E-6,1,0.999253354069792,40.0298881530762,1.98491093893895,20.1799999922514,-0.00178936652208343,-0.000260187622710816,0.25,4.35085956320567E-6,-0.000158413579362627,4.19859118810511E-6,200.0115509,200.0115509,68319.3125,68379.28125,56.7790588939676,20.5247978358682,26.705515,0,0,0,40,4449,199.8315,68349.296875,,,,,,,,,,,,,0,,,,0,,,,,,200.0115509,,,,
,31278812.145,200.0115814,73401.94921875,-0.000175813372864806,1.92093085687596E-6,1,0.999253354069792,40.0298881530762,1.98505091744274,20.1799999922514,-0.00199502634206114,-0.000277896960555984,0.25,5.89951448778801E-6,-0.000176427108749469,5.73398389699309E-6,200.0115814,200.0115814,73372.0625,73431.8359375,56.8478422036599,20.5243727568248,26.705515,0,0,0,40,4449,199.81925,73401.94921875,,,,,,,,,,,,,0,,,,0,,,,,,200.0115814,,,,
,31278911.685,200.0133057,78377.22265625,-0.000192723547856527,2.57844440273366E-6,1,0.999253354069792,40.0298881530762,1.98480132705579,20.1799999922514,-0.00218225778793516,-0.000329885909383437,0.25,4.22395404089722E-6,-0.000193393985838292,4.03519826581539E-6,200.0133057,200.0133057,78344.484375,78409.9609375,56.8478422036599,20.5264160407329,26.705515,0,0,0,40,4449,199.80745,78377.22265625,,,,,,,,,,,,,0,,,,-0.00245,,,,,,200.0133057,,,,
,31279013.47,200.01677705,83465.66015625,-0.000214371439085634,2.90291513253139E-6,1,0.999253354069792,40.0298881530762,1.98477622513073,20.1799999922514,-0.00242196182807707,-0.000397983872440521,0.25,1.94551516923078E-6,-0.000215114323639103,1.72655188600416E-6,200.0166321,200.016922,83433.1484375,83498.171875,56.8322096332752,20.5276997047297,27.085165,0,0,0,40,4449,199.7927,83465.66015625,,,,,,,,,,,,,0,,,,-0.0049,,,,,,200.01677705,,,,
,31279104.93,200.0123901,88038.90234375,-0.000229562397641563,2.60178646702571E-6,1,0.999253354069792,40.0298881530762,1.98482432919429,20.1799999922514,-0.00260581996754396,-0.00035611477330093,0.25,8.29551550226914E-6,-0.00023036455220822,8.08300956263481E-6,200.0123901,200.0123901,88006.359375,88071.4453125,56.8580033744099,20.5255593049941,27.085165,0,0,0,40,4449,199.7861,88038.90234375,,,,,,,,,,,,,0,,,,-0.00245,,,,,,200.0123901,,,,
,31279211.815,200.0113525,87398.38671875,-0.00022701678574933,2.69805272438739E-6,1,0.999253354069792,40.0298881530762,1.98470059344007,20.1799999922514,-0.00257669049402107,-0.000352606328772943,0.25,8.16269648081849E-6,-0.000227810001396272,7.95232409271859E-6,200.0113525,200.0113525,87393.390625,87403.3828125,56.933039712256,20.5258824541519,25.946213,0,0,0,40,4449,199.7787,87398.38671875,,,,,,,,,,,,,0,,,,-0.0049,,,,,,200.0113525,,,,
,31279304.54,200.00456235,82762.078125,-0.00021057840670338,2.11695209183709E-6,1,0.999253354069792,40.0298881530762,1.98492510708718,20.1799999922514,-0.00238321087898062,-0.000368331865378336,0.25,3.91794719764427E-6,-0.000211310333608876,3.70970501805814E-6,200.0042419,200.0048828,82739.5,82784.65625,56.9220969129868,20.5244573389252,26.325863,0,0,0,40,4449,199.7793,82762.078125,,,,,,,,,,,,,0,,,,0,,,,,,200.00456235,,,,
,31279401.71,199.9961395,77906.203125,-0.000191173692343031,2.27103682232082E-6,1,0.999253354069792,40.0298881530762,1.98487635310582,20.1799999922514,-0.00216606371807296,-0.000319897009056796,0.25,4.84143513164221E-6,-0.00019183952599837,4.65637634013618E-6,199.9961395,199.9961395,77881.21875,77931.1875,57.014329078256,20.525428806822,26.705515,0,0,0,40,4449,199.78195,77906.203125,,,,,,,,,,,,,0,,,,-0.00245,,,,,,199.9961395,,,,
,31279497.85,199.99194335,73097.1328125,-0.000174663833545689,2.66704384503938E-6,1,0.999253354069792,40.0298881530762,1.98487838518383,20.1799999922514,-0.00198305702157385,-0.000268926685673496,0.25,6.49309365796548E-6,-0.00017527433269946,6.33077780226119E-6,199.9913177,199.992569,73067.015625,73127.25,56.8533136032945,20.5264687432411,26.705515,0,0,0,40,4449,199.79225,73097.1328125,,,,,,,,,,,,,0,,,,-0.00245,,,,,,199.99194335,,,,
,31279594.02,199.99124145,68291.49609375,-0.000157129571357673,1.72650502741067E-6,1,0.999253354069792,40.0298881530762,1.98481997828317,20.1799999922514,-0.00178241060977121,-0.000250672360809979,0.25,5.06595934787449E-6,-0.000157677927226889,4.91690315391074E-6,199.9906006,199.9918823,68263.84375,68319.1484375,56.8642564025637,20.5286194361459,26.325863,0,0,0,40,4449,199.7968,68291.49609375,,,,,,,,,,,,,0,,,,0.00245,,,,,,199.99124145,,,,
,31279690.595,199.98754885,63463.44921875,-0.000137671653723557,1.46665996795877E-6,1,0.999253354069792,40.0298881530762,1.98496246222375,20.1799999922514,-0.00156034293447805,-0.000228008180397744,0.25,3.69765116072039E-6,-0.000138151300528593,3.56418967489826E-6,199.9870911,199.9880066,63431.0625,63495.8359375,56.6876083572175,20.5268662869662,26.705515,0,0,0,40,4449,199.8085,63463.44921875,,,,,,,,,,,,,0,,,,0.00245,,,,,,199.98754885,,,,
,31279788.865,199.9899139,58550.8125,-0.00012074824424445,1.90305580074965E-6,1,0.999253354069792,40.0298881530762,1.9850768696968,20.1799999922514,-0.00137005374852264,-0.000191685201041172,0.25,3.97959724915756E-6,-0.000121169672712874,3.8648152822566E-6,199.9899139,199.9899139,58548.35546875,58553.26953125,56.8337728903137,20.5239692512578,26.705515,0,0,0,40,4449,199.8164,58550.8125,,,,,,,,,,,,,0,,,,0,,,,,,199.9899139,,,,
,31279885.22,199.99183655,53735.576171875,-0.00010207583485086,1.41787207534455E-6,1,0.999253354069792,40.0298881530762,1.98504883132988,20.1799999922514,-0.00115455113392992,-0.000182900120341222,0.25,1.5154644659015E-6,-0.000102430090675489,1.41182261661965E-6,199.9915466,199.9921265,53705.71484375,53765.4375,56.7696793517368,20.5254975126606,26.325863,0,0,0,40,4449,199.82255,53735.576171875,,,,,,,,,,,,,0,,,,-0.0049,,,,,,199.99183655,,,,
,31279981.04,199.9870148,48947.78125,-8.64026124200426E-5,1.59822321494168E-6,1,0.999253354069792,40.0298881530762,1.98494824030374,20.1799999922514,-0.000978463761496168,-0.000147695529745822,0.25,1.91354054705124E-6,-8.67031382813048E-5,1.82780969132044E-6,199.9870148,199.9870148,48947.78125,48947.78125,56.709493955756,20.5283409029645,27.085165,0,0,0,40,4449,199.8329,48947.78125,,,,,,,,,,,,,0,,,,0,,,,,,199.9870148,,,,
,31280077.35,199.98982235,44132.28515625,-6.77611165672137E-5,1.5678553453908E-6,1,0.999253354069792,40.0298881530762,1.98493090752279,20.1799999922514,-0.00077081973977933,-9.5862481117867E-5,0.25,3.27076011049086E-6,-6.79986750757242E-5,3.20949709201404E-6,199.9897308,199.9899139,44099.7421875,44164.828125,56.8025077495445,20.5294284647683,27.085165,0,0,0,40,4449,199.84025,44132.28515625,,,,,,,,,,,,,0,,,,-0.00245,,,,,,199.98982235,,,,
,31280172.225,199.9894333,39389.619140625,-5.15862632217383E-5,1.46445331996297E-6,1,0.999253354069792,40.0298881530762,1.98481001094156,20.1799999922514,-0.000585181564712879,-8.22232074276758E-5,0.25,1.67030730432546E-6,-5.17662266093559E-5,1.6207320549751E-6,199.9892578,199.9896088,39357.1171875,39422.12109375,56.8744175733137,20.5293720673912,26.325863,0,0,0,40,4449,199.84915,39389.619140625,,,,,,,,,,,,,0,,,,-0.00245,,,,,,199.9894333,,,,
,31280268.68,199.99044035,34570.07421875,-3.71912814625292E-5,1.6247286631431E-6,1,0.999253354069792,40.0298881530762,1.98467057950441,20.1799999922514,-0.000420199933864513,-6.88338626165294E-5,0.25,3.56845322900812E-7,-3.73201060702207E-5,3.18102256429645E-7,199.9903564,199.9905243,34535.3125,34604.8359375,56.861911517006,20.5305854227714,26.705515,0,0,0,40,4449,199.8575,34570.07421875,,,,,,,,,,,,,0,,,,-0.00245,,,,,,199.99044035,,,,
,31280364.705,199.988266,29772.1875,-1.87540456386199E-5,1.36715158405358E-6,1,0.999253354069792,40.0298881530762,1.98486287780681,20.1799999922514,-0.000213501061542502,-2.55482253883001E-5,0.25,9.92444244758498E-7,-1.88198779156871E-5,9.75677282690526E-7,199.988266,199.988266,29747.162109375,29797.212890625,56.983845566006,20.5280307984756,27.085165,0,0,0,40,4449,199.8693,29772.1875,,,,,,,,,,,,,0,,,,0.00245,,,,,,199.988266,,,,
,31280458.86,199.9914856,25067.173828125,-4.64957700431474E-6,1.43511818321288E-6,1,0.999253354069792,40.0298881530762,1.98487205235946,20.1799999922514,-5.34624255473531E-5,-3.2814808066697E-6,0.25,5.166616938564E-7,-4.666188981109E-6,5.13430215685836E-7,199.9911957,199.9917755,25064.451171875,25069.896484375,56.9775925378522,20.5283946139679,26.705515,0,0,0,40,4449,199.8709,25067.173828125,,,,,,,,,,,,,0,,,,0,,,,,,199.9914856,,,,
,31280553.23,199.98910525,20349.259765625,1.11226809509054E-5,1.5912627697618E-6,1,0.999253354069792,40.0298881530762,1.98483236751813,20.1799999922514,0.000123515190454432,3.3037546774766E-5,0.25,9.96903369335618E-7,1.11600076248223E-5,1.01236312235821E-6,199.9890137,199.9891968,20316.853515625,20381.666015625,56.9095908566791,20.5303889368358,26.705515,0,0,0,40,4449,199.8831,20349.259765625,,,,,,,,,,,,,0,,,,-0.00245,,,,,,199.98910525,,,,
,31280649.85,199.98518375,15522.5595703125,2.53651649329871E-5,9.02598818598324E-7,1,0.999253354069792,40.0298881530762,1.98476363886169,20.1799999922514,0.000285366029537502,5.40352437840108E-5,0.25,3.84730213963767E-7,2.54523244663687E-5,4.13511237958004E-7,199.9851685,199.985199,15490.015625,15555.103515625,57.1081245005637,20.5331861265875,26.705515,0,0,0,40,4449,199.8808,15522.5595703125,,,,,,,,,,,,,0,,,,-0.00245,,,,,,199.98518375,,,,
,31280746.49,199.9927673,10692.3618164062,3.9105541323977E-5,7.04325007655693E-7,1,0.999253354069792,40.0298881530762,1.98495057685624,20.1799999922514,0.000440357610564462,8.11909830195347E-5,0.25,4.04907038608521E-7,3.92400993104069E-5,4.48691992409051E-7,199.9927673,199.9927673,10662.5078125,10722.2158203125,56.9158438848329,20.5296494284569,26.705515,0,0,0,40,4449,199.8946,10692.3618164062,,,,,,,,,,,,,0,,,,0.00245,,,,,,199.9927673,,,,
,31280841.255,199.9905014,5952.4921875,4.80919628681842E-5,4.87511647887835E-7,1,0.999253354069792,40.0298881530762,1.98489995267944,20.1799999922514,0.00054150718959103,0.000100024431918387,0.25,5.13687641759E-7,4.82574175657721E-5,5.67658975654296E-7,199.9899139,199.9910889,5919.98974609375,5984.99462890625,57.0534105042176,20.5317913712995,27.085165,0,0,0,40,4449,199.90525,5952.4921875,,,,,,,,,,,,,0,,,,-0.00245,,,,,,199.9905014,,,,
,31280935.515,199.99031065,1243.60925292969,4.42563411951212E-5,3.63061305150202E-7,1,0.999253354069792,40.0298881530762,1.98484973687677,20.1799999922514,0.000499076885342111,8.76099594639877E-5,0.25,7.9533815623105E-8,4.4409018640376E-5,1.27898624606971E-7,199.9897308,199.9908905,1216.203125,1271.01538085938,57.0205821064099,20.5343865301729,27.085165,0,0,0,40,4449,199.9097,1243.60925292969,,,,,,,,,,,,,0,,,,0,,,,,,199.99031065,,,,
,31280960.27,199.99160765,-0.593727141618729,3.74801503362008E-5,3.43604234661842E-7,1,0.999253354069792,40.0298881530762,1.98488905518374,20.1799999922514,0.000423986589952847,6.66173782396697E-5,0.25,-6.04580002981916E-7,3.7610178477148E-5,-5.65931882311456E-7,199.991394,199.9918213,-0.669845998287201,-0.517608284950256,56.8384626614291,20.5309023697984,27.085165,0,0,0,40,4417,199.91265,-0.593727141618729,,,,,,,,,,,,,0,,,,0,,,,,,199.99160765,,,,