File: data/doubleLayers/dl_0-125/ppms/data/DD213_7_HYST_100OE_50K.DAT
[Header]
; VSM Data File (default extension .dat)
; Copyright (c) 2003-2013, Quantum Design, Inc. All rights reserved.
TITLE,
FILEOPENTIME,31233533.83,12/28/2018,8:00 pm
BYAPP,VSM,2.0,2.0
INFO,PPMS VSM Option Release 1.4.10 Build 1,APPNAME
INFO,Quantum Design Linear Motor Servo Controller,MOTOR_MODULE_NAME
INFO,3101-100 M1,MOTOR_HW_VERSION
INFO,MMC1014,MOTOR_SERIAL_NUMBER
INFO,SRV No X-over 01.03.11,MOTOR_SOFTWARE_VERSION
INFO,Quantum Design VSM Detection Module,VSM_MODULE_NAME
INFO,3101-150 F0,VSM_HW_VERSION
INFO,VSM707,VSM_SERIAL_NUMBER
INFO,VSM No X-over 01.02.05 May 20 2008 13:51:47,VSM_SOFTWARE_VERSION
INFO,704,PREAMP_SERIAL_NUMBER
INFO,822,COIL_SERIAL_NUMBER
INFO,0,MOMENT_UNITS
INFO,CoFe2O4,SAMPLE_MATERIAL
INFO,Double Layer thin concentration,SAMPLE_COMMENT
INFO,29.55,SAMPLE_MASS
INFO,,SAMPLE_VOLUME
INFO,,SAMPLE_MOLECULAR_WEIGHT
INFO,,SAMPLE_SIZE
INFO,,SAMPLE_SHAPE
DATATYPE,COMMENT,1
DATATYPE,TIME,2
STARTUPAXIS,X,2
STARTUPAXIS,Y1,5
[Data]
Comment,Time Stamp (sec),Temperature (K),Magnetic Field (Oe),Moment (emu),M. Std. Err. (emu),Transport Action,Averaging Time (sec),Frequency (Hz),Peak Amplitude (mm),Center Position (mm),Coil Signal' (mV),Coil Signal" (mV),Range (mV),M. Quad. Signal (emu),M. Raw' (emu),M. Raw" (emu),Min. Temperature (K),Max. Temperature (K),Min. Field (Oe),Max. Field (Oe),Mass (grams),Motor Lag (deg),Pressure (Torr),VSM Status (code),Motor Status (code),Measure Status (code),Measure Count,PPMS Status (code),System Temp. (K),System Field (Oe),Sample Position (deg),Bridge 1 Resistance (ohms),Bridge 1 Excitation (에),Bridge 2 Resistance (ohms),Bridge 2 Excitation (에),Bridge 3 Resistance (ohms),Bridge 3 Excitation (에),Bridge 4 Resistance (ohms),Bridge 4 Excitation (에),Signal 1 Vin (V),Signal 2 Vin (V),Digital Inputs (code),Drive 1 Iout (mA),Drive 1 Ipower (W),Drive 2 Iout (mA),Drive 2 Ipower (W),Pressure (),Map 20 (),Map 21 (),Map 22 (),Map 23 (),Map 24 (),Map 25 (),Map 26 (),Map 27 (),Map 28 (),Map 29 ()
,31233548.39,50.0002708,-0.3349229991436,,,2,,,,20.9800000482798,,,,,,,50.0002708,50.0002708,-0.3349229991436,-0.3349229991436,,,16.454937,,,,-99999999,4369,50.0369,-0.3349229991436,,,,,,,,,,,,,,,,,,,,,,,50.0002708,,,,
,31233690.805,50.0003815,4543.70532226562,5.7752442504645E-5,4.25337892146728E-7,1,0.999253354069792,40.0298881530762,1.99482428066013,20.9699999541044,0.000650525127324156,0.000122240469487361,0.25,4.27766106046176E-7,5.77281570789278E-5,8.57382263795457E-7,50.0003815,50.0003815,4541.31298828125,4546.09765625,56.0482362284867,20.5367109407718,16.454937,0,0,0,40,4449,50.04065,4543.70532226562,,,,,,,,,,,,,0,,,,0.0049,,,,,,50.0003815,,,,
,31233783.475,50.0019035,9172.19482421875,4.37076298039057E-5,4.88268359689087E-7,1,0.999253354069792,40.0298881530762,1.99431076083471,20.9699999541044,0.000492098702575932,9.37050926737284E-5,0.25,4.29786669427139E-7,4.36983120944496E-5,7.54882634607029E-7,50.0019035,50.0019035,9167.2841796875,9177.10546875,56.435142345506,20.5408992213764,16.834587,0,0,0,40,4449,50.03215,9172.19482421875,,,,,,,,,,,,,0,,,,0,,,,,,50.0019035,,,,
,31233876.765,50.0005379,13835.173828125,3.0384940083045E-5,6.14295441559391E-7,1,0.999253354069792,40.0298881530762,1.99421171415969,20.9699999541044,0.000340692562513923,7.33449465663937E-5,0.25,1.0250933832671E-6,3.03805821242217E-5,1.25093227831149E-6,50.0005379,50.0005379,13835.173828125,13835.173828125,56.709493955756,20.5451348290824,16.834587,0,0,0,40,4449,50.0333,13835.173828125,,,,,,,,,,,,,0,,,,0,,,,,,50.0005379,,,,
,31233969.605,50.0022545,18475.0302734375,1.62132081602222E-5,7.93741466834596E-7,1,0.999253354069792,40.0298881530762,1.9947322335257,20.9699999541044,0.000182261796503175,3.70527215346841E-5,0.25,3.60971104203009E-7,1.62163729672793E-5,4.8123800885021E-7,50.0022545,50.0022545,18467.625,18482.435546875,56.2194128741983,20.5395698874226,16.454937,0,0,0,40,4449,50.0321,18475.0302734375,,,,,,,,,,,,,0,,,,0,,,,,,50.0022545,,,,
,31234063.735,50.0022049,23180.244140625,1.99966140608988E-6,7.44870304374077E-7,1,0.999253354069792,40.0298881530762,1.99477164646891,20.9699999541044,1.70720892752067E-5,3.46154125061009E-5,0.25,2.705711203725E-6,1.98092544919778E-6,2.72214345760444E-6,50.0022049,50.0022049,23180.244140625,23180.244140625,56.6446187886598,20.542112998626,16.834587,0,0,0,40,4449,50.026,23180.244140625,,,,,,,,,,,,,0,,,,0,,,,,,50.0022049,,,,
,31234157.62,50.0025826,27872.9267578125,-1.36094427755232E-5,7.54884679066381E-7,1,0.999253354069792,40.0298881530762,1.99463339368878,20.9699999541044,-0.000156811877139629,-1.03085277156434E-5,0.25,1.53874765319937E-6,-1.36326830759796E-5,1.44015790693551E-6,50.0025826,50.0025826,27848.26171875,27897.591796875,56.9275683126214,20.5436742812576,16.834587,0,0,0,40,4449,50.0319,27872.9267578125,,,,,,,,,,,,,0,,,,-0.0049,,,,,,50.0025826,,,,
,31234251.195,50.0023651,32548.3447265625,-2.87807086394417E-5,9.60054483944439E-7,1,0.999253354069792,40.0298881530762,1.99457431269481,20.9699999541044,-0.000329629434490975,-3.3256906394311E-5,0.25,2.23877580297724E-6,-2.88295620291373E-5,2.0312779861933E-6,50.0023651,50.0023651,32520.962890625,32575.7265625,56.6610329875637,20.5445809113879,16.454937,0,0,0,40,4449,50.02695,32548.3447265625,,,,,,,,,,,,,0,,,,-0.0049,,,,,,50.0023651,,,,
,31234344.04,50.0024109,37190.8671875,-4.38963265918081E-5,1.05194609430416E-6,1,0.999253354069792,40.0298881530762,1.99463951677868,20.9699999541044,-0.000500283037703936,-6.52063808635831E-5,0.25,2.13147169760664E-6,-4.39721960880788E-5,1.81642965130804E-6,50.0024109,50.0024109,37158.68359375,37223.05078125,56.3390020376406,20.5449339732432,17.214239,0,0,0,40,4449,50.02685,37190.8671875,,,,,,,,,,,,,0,,,,-0.0049,,,,,,50.0024109,,,,
,31234438.435,50.0020924,41905.974609375,-5.9800215246605E-5,9.39534913979206E-7,1,0.999253354069792,40.0298881530762,1.99469108583655,20.9699999541044,-0.000681154312956328,-9.19897723304849E-5,0.25,2.62249523094791E-6,-5.99159349129658E-5,2.19725048280444E-6,50.0019341,50.0022507,41875.69921875,41936.25,56.7040225561214,20.5470519314142,16.834587,0,0,0,40,4449,50.0225,41905.974609375,,,,,,,,,,,,,0,,,,0.00245,,,,,,50.0020924,,,,
,31234530.725,50.0021439,46521.626953125,-7.42533347628239E-5,1.02262916762871E-6,1,0.999253354069792,40.0298881530762,1.99452276752076,20.9699999541044,-0.00084174794617188,-0.000137365417749395,0.25,1.20525728281513E-6,-7.43995139727977E-5,6.79191161728732E-7,50.0021439,50.0021439,46489.171875,46554.08203125,57.0260535060445,20.5477433613933,16.834587,0,0,0,40,4449,50.0266,46521.626953125,,,,,,,,,,,,,0,,,,0,,,,,,50.0021439,,,,
,31234625.605,50.00145725,51263.73828125,-9.36026100053159E-5,1.02787324514101E-6,1,0.999253354069792,40.0298881530762,1.99450965737209,20.9699999541044,-0.00105413200408991,-0.000213225852623875,0.25,-2.02816148376897E-6,-9.37833277066687E-5,-2.6913659000139E-6,50.001339,50.0015755,51231.2890625,51296.1875,57.0409044479099,20.548124073356,16.834587,0,0,0,40,4449,50.0237,51263.73828125,,,,,,,,,,,,,0,,,,0.00245,,,,,,50.00145725,,,,
,31234719.64,50.00156215,55961.658203125,-0.000107011088926289,1.12243432450333E-6,1,0.999253354069792,40.0298881530762,1.99466476876402,20.9699999541044,-0.00121376781284132,-0.000197789992143077,0.25,1.74474059123596E-6,-0.000107269679429516,1.00385085987492E-6,50.0014191,50.0017052,55929.07421875,55994.2421875,56.3694855498906,20.5452106491494,16.834587,0,0,0,40,4449,50.0216,55961.658203125,,,,,,,,,,,,,0,,,,-0.0049,,,,,,50.00156215,,,,
,31234818.705,50.0017738,60914.283203125,-0.00012369212224346,9.18755125986041E-7,1,0.999253354069792,40.0298881530762,1.99457930076052,20.9699999541044,-0.00140228404299139,-0.000233884971456312,0.25,1.54396915347363E-6,-0.000124015071869351,6.97736075212083E-7,50.0017738,50.0017738,60911.859375,60916.70703125,56.8626931455252,20.5456169896636,17.214239,0,0,0,40,4449,50.0176,60914.283203125,,,,,,,,,,,,,0,,,,-0.0049,,,,,,50.0017738,,,,
,31234916.82,50.0019493,65817.23828125,-0.000143215844971321,8.00187026871845E-7,1,0.999253354069792,40.0298881530762,1.99468242136562,20.9699999541044,-0.00162436895518316,-0.000269049512026169,0.25,1.93542392036188E-6,-0.000143620868522784,9.69518011538113E-7,50.0019493,50.0019493,65789.7578125,65844.71875,56.8681645451599,20.5438120501781,16.834587,0,0,0,40,4449,50.01915,65817.23828125,,,,,,,,,,,,,0,,,,0,,,,,,50.0019493,,,,
,31235016.885,50.0015831,70819.95703125,-0.000160189981949468,1.28931568718771E-6,1,0.999253354069792,40.0298881530762,1.99458672586988,20.9699999541044,-0.00180925080872855,-0.000345155878807596,0.25,-1.7540450002883E-6,-0.000160649547723588,-2.8300179796516E-6,50.0015831,50.0015831,70817.375,70822.5390625,56.6352392464291,20.542419514745,16.834587,0,0,0,40,4449,50.0197,70819.95703125,,,,,,,,,,,,,0,,,,-0.0049,,,,,,50.0015831,,,,
,31235112.095,50.0024185,75580.41015625,-0.000176900625500429,1.2702670543971E-6,1,0.999253354069792,40.0298881530762,1.99453327637102,20.9699999541044,-0.00199844140685127,-0.00038048402478151,0.25,-1.88862140203655E-6,-0.000177441626623651,-3.06032711471809E-6,50.0024185,50.0024185,75575.203125,75585.6171875,56.6039741056598,20.5398736552197,16.454937,0,0,0,40,4449,50.0194,75580.41015625,,,,,,,,,,,,,0,,,,0.0049,,,,,,50.0024185,,,,
,31235207.945,50.0022697,80371.51171875,-0.000194242919541779,1.60246658684389E-6,1,0.999253354069792,40.0298881530762,1.9946338042036,20.9699999541044,-0.00218993509764632,-0.000445318097777774,0.25,-4.51636907127583E-6,-0.00019485594677762,-5.79260744805118E-6,50.0022697,50.0022697,80369.109375,80373.9140625,56.6977695279675,20.5420663466774,17.214239,0,0,0,40,4449,50.01425,80371.51171875,,,,,,,,,,,,,0,,,,0,,,,,,50.0022697,,,,
,31235301.48,50.0020218,85044.73046875,-0.000208892488766921,1.2803328277692E-6,1,0.999253354069792,40.0298881530762,1.99444954540328,20.9699999541044,-0.00235873411512781,-0.000459685610520949,0.25,-3.17654289240052E-6,-0.000209597754657136,-4.5239361063617E-6,50.0020218,50.0020218,85017.265625,85072.1953125,56.7774956369291,20.5433605021151,16.834587,0,0,0,40,4449,50.01555,85044.73046875,,,,,,,,,,,,,0,,,,0,,,,,,50.0020218,,,,
,31235395.095,50.0014076,89725.3515625,-0.000226018265314649,1.26575342535533E-6,1,0.999253354069792,40.0298881530762,1.99466145328121,20.9699999541044,-0.00255706084914549,-0.000473575061478397,0.25,-1.34642276216486E-6,-0.000226830745326318,-2.77529397006663E-6,50.0014076,50.0014076,89725.3515625,89725.3515625,56.9072459711214,20.541785195426,17.214239,0,0,0,40,4449,50.0162,89725.3515625,,,,,,,,,,,,,0,,,,0,,,,,,50.0014076,,,,
,31235500.88,49.9989548,85819.0625,-0.000214986838319683,1.1291220832798E-6,1,0.999253354069792,40.0298881530762,1.99466545514137,20.9699999541044,-0.00242896999677512,-0.000466985457316046,0.25,-2.72752737343334E-6,-0.000215721865602731,-4.10903541513273E-6,49.9989548,49.9989548,85813.84375,85824.28125,56.8384626614291,20.5429214227966,16.834587,0,0,0,40,4449,50.0117,85819.0625,,,,,,,,,,,,,0,,,,0,,,,,,49.9989548,,,,
,31235595.83,50.00079345,81073.08984375,-0.000198842095258205,1.27128137591017E-6,1,0.999253354069792,40.0298881530762,1.99476093329608,20.9699999541044,-0.00225073023569835,-0.000407082987812862,0.25,-3.14475046206159E-7,-0.000199502623888598,-1.60387857272354E-6,50.0003395,50.0012474,81065.515625,81080.6640625,56.6727574153522,20.5418480238238,17.214239,0,0,0,40,4449,50.0113,81073.08984375,,,,,,,,,,,,,0,,,,-0.0049,,,,,,50.00079345,,,,
,31235689.315,50.0006657,76399.48828125,-0.000178362062799411,1.07287882219423E-6,1,0.999253354069792,40.0298881530762,1.99471260327984,20.9699999541044,-0.0020166952141649,-0.00037525944654991,0.25,-1.16399453751929E-6,-0.000178917957890356,-2.3401862225709E-6,50.0005646,50.0007668,76371.9765625,76427,56.946327397083,20.5409439522706,16.454937,0,0,0,40,4449,50.01745,76399.48828125,,,,,,,,,,,,,0,,,,-0.00245,,,,,,50.0006657,,,,
,31235784,49.9997101,71665.49609375,-0.000160276345336082,1.04967275758181E-6,1,0.999253354069792,40.0298881530762,1.99469740190683,20.9699999541044,-0.00181022289258562,-0.000346256551310182,0.25,-1.83580525989756E-6,-0.000160740926013787,-2.91006010894402E-6,49.9995308,49.9998894,71628.078125,71702.9140625,56.9181887703906,20.5425793761247,16.834587,0,0,0,40,4449,50.01335,71665.49609375,,,,,,,,,,,,,0,,,,-0.00245,,,,,,49.9997101,,,,
,31235879.185,50.00001145,66910.05859375,-0.000146889243169132,1.0874113449768E-6,1,0.999253354069792,40.0298881530762,1.99466485091291,20.9699999541044,-0.00166166585964992,-0.000300624007137044,0.25,-1.97702549028697E-7,-0.000147296517488803,-1.19132993813159E-6,49.9999619,50.000061,66880.0625,66940.0546875,56.7431039820829,20.5454511150121,17.214239,0,0,0,40,4449,50.01625,66910.05859375,,,,,,,,,,,,,0,,,,-0.00245,,,,,,50.00001145,,,,
,31235974.58,49.9988861,62138.759765625,-0.000129704319417781,8.62271546548791E-7,1,0.999253354069792,40.0298881530762,1.99467847177475,20.9699999541044,-0.00146267994544316,-0.000289321062047525,0.25,-2.27718215568118E-6,-0.000130023158660722,-3.1716046483941E-6,49.9988861,49.9988861,62136.2421875,62141.27734375,56.9064643426022,20.5430409387806,16.834587,0,0,0,40,4449,50.0158,62138.759765625,,,,,,,,,,,,,0,,,,0,,,,,,49.9988861,,,,
,31236068.92,50.00048065,57423.923828125,-0.000109750851140717,1.23895375597339E-6,1,0.999253354069792,40.0298881530762,1.99448930219813,20.9699999541044,-0.00124223549568773,-0.000217227310650464,0.25,5.15319252157762E-7,-0.00011001434736513,-2.44692633495884E-7,50.0003204,50.0006409,57393.87890625,57453.96875,56.6508718168137,20.5434316985057,16.834587,0,0,0,40,4449,50.0128,57423.923828125,,,,,,,,,,,,,0,,,,-0.00245,,,,,,50.00048065,,,,
,31236166.205,50.0002289,52563.583984375,-9.39972094905857E-5,9.77240395074807E-7,1,0.999253354069792,40.0298881530762,1.99441635015519,20.9699999541044,-0.00106344421569948,-0.000187146611900402,0.25,3.47746747664197E-7,-9.4201165385841E-5,-3.11286786175924E-7,50.0002289,50.0002289,52561.02734375,52566.140625,57.1042163579676,20.5457147407465,17.214239,0,0,0,40,4449,50.0173,52563.583984375,,,,,,,,,,,,,0,,,,-0.0049,,,,,,50.0002289,,,,
,31236261.275,50.0007782,47808.4375,-7.6407370651473E-5,9.82285945066284E-7,1,0.999253354069792,40.0298881530762,1.99438544054204,20.9699999541044,-0.000866358708179006,-0.000140255162097691,0.25,1.3355607961748E-6,-7.65631031987112E-5,7.95942234638892E-7,50.0007782,50.0007782,47803.47265625,47813.40234375,57.2073913225061,20.546555926676,17.214239,0,0,0,40,4449,50.0141,47808.4375,,,,,,,,,,,,,0,,,,0,,,,,,50.0007782,,,,
,31236352.65,50.00040625,43242.92578125,-6.06468854800725E-5,1.10144038643207E-6,1,0.999253354069792,40.0298881530762,1.99439838564712,20.9699999541044,-0.000687311469543233,-0.000112376769970493,0.25,9.69038550011836E-7,-6.0756139228617E-5,5.36219076170764E-7,50.0003853,50.0004272,43215.453125,43270.3984375,57.0119841926983,20.5501141494062,17.214239,0,0,0,40,4449,50.01685,43242.92578125,,,,,,,,,,,,,0,,,,-0.00245,,,,,,50.00040625,,,,
,31236445.65,50.0004921,38592.431640625,-4.65511199385493E-5,9.2168519418978E-7,1,0.999253354069792,40.0298881530762,1.99430329704265,20.9699999541044,-0.000529803828196275,-7.29604848824218E-5,0.25,1.92170989001892E-6,-4.66323695506748E-5,1.58807153630302E-6,50.0004921,50.0004921,38567.390625,38617.47265625,56.7266897831791,20.5491101423499,16.834587,0,0,0,40,4449,50.01325,38592.431640625,,,,,,,,,,,,,0,,,,-0.0049,,,,,,50.0004921,,,,
,31236540.055,49.9995842,33877.57421875,-3.10874008951219E-5,1.17625432895998E-6,1,0.999253354069792,40.0298881530762,1.99431900481756,20.9699999541044,-0.000353443173668125,-5.02783361715319E-5,0.25,1.14650019768103E-6,-3.11330033444824E-5,9.21449587221555E-7,49.9995575,49.9996109,33845.375,33909.7734375,56.9181887703906,20.5519822527565,16.834587,0,0,0,40,4449,50.01505,33877.57421875,,,,,,,,,,,,,0,,,,0,,,,,,49.9995842,,,,
,31236636.77,50.0001373,29040.275390625,-1.36783185684264E-5,7.05017259751204E-7,1,0.999253354069792,40.0298881530762,1.99424136273244,20.9699999541044,-0.000156932615951594,-1.39826790571005E-5,0.25,1.22548128662058E-6,-1.37001380734432E-5,1.12632545522462E-6,50.0001373,50.0001373,29037.484375,29043.06640625,57.3942005386022,20.5542176952235,17.593889,0,0,0,40,4449,50.0201,29040.275390625,,,,,,,,,,,,,0,,,,0,,,,,,50.0001373,,,,
,31236727.54,49.9996033,24505.015625,6.30737098384676E-7,5.66398314585844E-7,1,0.999253354069792,40.0298881530762,1.99415647617197,20.9699999541044,4.37727781695901E-6,1.65025248205325E-5,0.25,1.34837184697234E-6,6.21232131327115E-7,1.3539513440463E-6,49.9996033,49.9996033,24475.1796875,24534.8515625,57.0010413934291,20.554415250214,16.834587,0,0,0,40,4449,50.02045,24505.015625,,,,,,,,,,,,,0,,,,-0.0049,,,,,,49.9996033,,,,
,31236822.155,50.00003435,19777.6083984375,1.54314740438168E-5,6.89770240230531E-7,1,0.999253354069792,40.0298881530762,1.9941516138648,20.9699999541044,0.000172517031108264,4.03662622921691E-5,0.25,7.96286746225375E-7,1.54321813766791E-5,9.10870020660847E-7,50.0000229,50.0000458,19747.61328125,19807.603515625,56.9275683126214,20.5543158282885,17.214239,0,0,0,40,4449,50.01725,19777.6083984375,,,,,,,,,,,,,0,,,,0,,,,,,50.00003435,,,,
,31236914.115,49.9999504,15182.6352539062,3.07507395364643E-5,5.9233909163185E-7,1,0.999253354069792,40.0298881530762,1.9941174995857,20.9699999541044,0.000344597530713465,7.53655464855951E-5,0.25,1.13826758779609E-6,3.07476943105182E-5,1.36678081781759E-6,49.9999504,49.9999504,15155.064453125,15210.2060546875,56.8150138058522,20.5569111326807,16.834587,0,0,0,40,4449,50.0178,15182.6352539062,,,,,,,,,,,,,0,,,,0,,,,,,49.9999504,,,,
,31237008.79,49.9997044,10450.0678710938,4.47437927756396E-5,4.50764129030129E-7,1,0.999253354069792,40.0298881530762,1.99421831373226,20.9699999541044,0.000502623765626625,0.000102307225631118,0.25,1.00563968874652E-6,4.47328113405627E-5,1.33834415517888E-6,49.9995232,49.9998856,10417.4599609375,10482.67578125,57.0721695886791,20.5539246414737,16.834587,0,0,0,40,4449,50.01645,10450.0678710938,,,,,,,,,,,,,0,,,,-0.0049,,,,,,49.9997044,,,,
,31237100.625,49.9986,5859.87744140625,5.77293743435307E-5,4.12170963262991E-7,1,0.999253354069792,40.0298881530762,1.99432460973569,20.9699999541044,0.000650210051378488,0.000121808471579142,0.25,3.95639610204266E-7,5.77084655147066E-5,8.25121535047718E-7,49.9985771,49.9986229,5834.67333984375,5885.08154296875,57.0831123879483,20.5541676660002,16.834587,0,0,0,40,4449,50.01505,5859.87744140625,,,,,,,,,,,,,0,,,,0,,,,,,49.9986,,,,
,31237195.35,49.9996948,1123.619140625,7.03275959434412E-5,3.71224976759746E-7,1,0.999253354069792,40.0298881530762,1.99428025427636,20.9699999541044,0.000791917441327367,0.000148404175811742,0.25,4.86211503545764E-7,7.02877168590378E-5,1.00915348094936E-6,49.9996948,49.9996948,1116.04235839844,1131.19592285156,57.149550812083,20.5551100295891,17.214239,0,0,0,40,4449,50.0202,1123.619140625,,,,,,,,,,,,,0,,,,0,,,,,,49.9996948,,,,
,31237289.28,49.9995499,-3566.82153320313,7.97146269522562E-5,3.65633763304686E-7,1,0.999253354069792,40.0298881530762,1.99457378756784,20.9699999541044,0.000898517473474228,0.000164459821508544,0.25,2.14684530967382E-7,7.96797753073977E-5,8.07766957392251E-7,49.9995499,49.9995499,-3571.82788085937,-3561.81518554687,57.1276652135445,20.5528332565887,16.834587,0,0,0,40,4449,50.017,-3566.82153320313,,,,,,,,,,,,,0,,,,0,,,,,,49.9995499,,,,
,31237383.39,50.0003738,-8271.37548828125,8.56811666225503E-5,4.43098466428913E-7,1,0.999253354069792,40.0298881530762,1.99443439474242,20.9699999541044,0.000966557990200409,0.000173280885212414,0.25,-8.08321148401232E-8,8.56653735803654E-5,5.56691221296283E-7,50.0003738,50.0003738,-8276.41015625,-8266.3408203125,57.4528226775445,20.5536927952852,17.593889,0,0,0,40,4449,50.01525,-8271.37548828125,,,,,,,,,,,,,0,,,,0,,,,,,50.0003738,,,,
,31237477.435,50.0008049,-12974.3154296875,8.1454214770905E-5,4.23636816787263E-7,1,0.999253354069792,40.0298881530762,1.99461634611303,20.9699999541044,0.000919913752271227,0.000160720022985738,0.25,-4.36476546293832E-7,8.14619398510891E-5,1.68855038989187E-7,50.0008049,50.0008049,-12979.4052734375,-12969.2255859375,57.108906129083,20.5512850909898,16.834587,0,0,0,40,4449,50.0135,-12974.3154296875,,,,,,,,,,,,,0,,,,-0.00245,,,,,,50.0008049,,,,
,31237572.945,50.0010605,-17746.8984375,6.13761041263031E-5,5.4375154636996E-7,1,0.999253354069792,40.0298881530762,1.99464962962967,20.9699999541044,0.000693629689858013,0.000119586655217507,0.25,-4.65003705989972E-7,6.13989097453217E-5,-1.01177284523945E-8,50.0010605,50.0010605,-17751.90234375,-17741.89453125,56.9596150819099,20.5492700548771,17.593889,0,0,0,40,4449,50.01515,-17746.8984375,,,,,,,,,,,,,0,,,,0.00245,,,,,,50.0010605,,,,
,31237666.19,50.0003662,-22406.9677734375,4.13379506372201E-5,7.31042566115527E-7,1,0.999253354069792,40.0298881530762,1.99447232436329,20.9699999541044,0.000468320854622129,7.4627725405999E-5,0.25,-8.37337822851306E-7,4.13677670094208E-5,-5.32448125708245E-7,50.0003662,50.0003662,-22434.419921875,-22379.515625,57.1659650109868,20.5536627789441,16.834587,0,0,0,40,4449,50.01215,-22406.9677734375,,,,,,,,,,,,,0,,,,0,,,,,,50.0003662,,,,
,31237759.75,50.001255,-27082.18359375,3.10340500060363E-5,6.92555811780092E-7,1,0.999253354069792,40.0298881530762,1.99433487804041,20.9699999541044,0.000354791558308806,3.86218987917705E-5,0.25,-2.16992942579043E-6,3.10757452032726E-5,-1.94359460786487E-6,50.001255,50.001255,-27112.466796875,-27051.900390625,57.2050464369484,20.5548763643189,16.834587,0,0,0,40,4449,50.01375,-27082.18359375,,,,,,,,,,,,,0,,,,-0.0049,,,,,,50.001255,,,,
,31237853.82,50.001564,-31784.6982421875,3.4893504478334E-5,7.78326082868653E-7,1,0.999253354069792,40.0298881530762,1.99442218472068,20.9699999541044,0.000397255954217919,5.32961962110179E-5,0.25,-1.56522179395453E-6,3.49428255259285E-5,-1.3119836747239E-6,50.001564,50.001564,-31814.021484375,-31755.375,57.2832092888714,20.5561321984892,17.593889,0,0,0,40,4449,50.0147,-31784.6982421875,,,,,,,,,,,,,0,,,,0,,,,,,50.001564,,,,
,31237949.25,50.001255,-36551.392578125,4.45976453272725E-5,8.39369894774413E-7,1,0.999253354069792,40.0298881530762,1.99454014800351,20.9699999541044,0.000506075918191623,7.82265074538996E-5,0.25,-1.105132132507E-6,4.46654344101712E-5,-7.83179535868589E-7,50.001255,50.001255,-36556.33203125,-36546.453125,56.9088092281599,20.5530163683567,17.214239,0,0,0,40,4449,50.0149,-36551.392578125,,,,,,,,,,,,,0,,,,0,,,,,,50.001255,,,,
,31238042.27,50.0004253,-41201.4921875,5.65852194434999E-5,9.14748643939796E-7,1,0.999253354069792,40.0298881530762,1.99444095217052,20.9699999541044,0.000640893114706436,0.000106695690682651,0.25,-7.41741222342391E-7,5.66800644490922E-5,-3.35929947856731E-7,50.0002937,50.0005569,-41234.10546875,-41168.87890625,57.146424298006,20.5538342927194,17.214239,0,0,0,40,4449,50.01205,-41201.4921875,,,,,,,,,,,,,0,,,,-0.00245,,,,,,50.0004253,,,,
,31238139.055,50.001667,-46039.25,7.38420000417485E-5,1.19056686821796E-6,1,0.999253354069792,40.0298881530762,1.9942931669504,20.9699999541044,0.000838084157486666,0.000130394068787603,0.25,-1.74706991960388E-6,7.3989258707868E-5,-1.22426890702126E-6,50.001667,50.001667,-46041.51171875,-46036.98828125,57.1182856713137,20.5560993343849,17.214239,0,0,0,40,4449,50.0087,-46039.25,,,,,,,,,,,,,0,,,,0,,,,,,50.001667,,,,
,31238234.195,50.00177955,-50794.1484375,8.94209933348012E-5,9.11520643441195E-7,1,0.999253354069792,40.0298881530762,1.9943549076889,20.9699999541044,0.00101134369364181,0.000179186148619759,0.25,-2.29926333397007E-7,8.96066001962922E-5,3.99923172904949E-7,50.001564,50.0019951,-50824.1953125,-50764.1015625,57.2417829773522,20.5581957153021,17.593889,0,0,0,40,4449,50.00625,-50794.1484375,,,,,,,,,,,,,0,,,,0.0049,,,,,,50.00177955,,,,
,31238329.525,50.0001106,-55558.69140625,0.000105347950552939,9.24373244445875E-7,1,0.999253354069792,40.0298881530762,1.99442916831904,20.9699999541044,0.00119497903589344,0.000193387432921418,0.25,-1.83364946976284E-6,0.000105601191333841,-1.10369351210109E-6,50.0001106,50.0001106,-55561.16796875,-55556.21484375,57.1042163579676,20.5572328582714,16.834587,0,0,0,40,4449,50.01065,-55558.69140625,,,,,,,,,,,,,0,,,,-0.0049,,,,,,50.0001106,,,,
,31238423.33,50.0013313,-60245.98046875,0.000120232320545196,8.10113956660673E-7,1,0.999253354069792,40.0298881530762,1.99438279049877,20.9699999541044,0.00136504230738208,0.000215332448511374,0.25,-2.56178790553005E-6,0.000120549744925758,-1.74024779211753E-6,50.0011978,50.0014648,-60273.1640625,-60218.796875,56.8259566051214,20.5571326777971,17.214239,0,0,0,40,4449,50.0037,-60245.98046875,,,,,,,,,,,,,0,,,,-0.00245,,,,,,50.0013313,,,,
,31238518.19,50.002346,-64988.435546875,0.000139651189604957,8.66838743786356E-7,1,0.999253354069792,40.0298881530762,1.99441632709215,20.9699999541044,0.00158469600506148,0.000256641865560855,0.25,-2.39063456739838E-6,0.000140044380437022,-1.44772360442418E-6,50.002346,50.002346,-64990.90625,-64985.96484375,57.2183341217753,20.5588433832909,16.834587,0,0,0,40,4449,50.0042,-64988.435546875,,,,,,,,,,,,,0,,,,0.00245,,,,,,50.002346,,,,
,31238612.55,50.0009422,-69705.67578125,0.000153184840057111,9.66302357802735E-7,1,0.999253354069792,40.0298881530762,1.99435732725623,20.9699999541044,0.00173352724604957,0.00030958287341909,0.25,-1.31556921311562E-7,0.000153629236229155,8.95523849654754E-7,50.0009422,50.0009422,-69712.96875,-69698.3828125,57.1143775287176,20.5609165975493,17.214239,0,0,0,40,4449,50.0065,-69705.67578125,,,,,,,,,,,,,0,,,,0,,,,,,50.0009422,,,,
,31238709.13,50.0002747,-74530.19921875,0.000170126739478101,1.13624063272451E-6,1,0.999253354069792,40.0298881530762,1.99436556011634,20.9699999541044,0.00192601578638196,0.000341708192598314,0.25,-3.22403070364723E-7,0.000170653959935139,8.01490012632099E-7,50.0002747,50.0002747,-74535.046875,-74525.3515625,57.108906129083,20.5580169310351,17.214239,0,0,0,40,4449,50.0061,-74530.19921875,,,,,,,,,,,,,0,,,,0,,,,,,50.0002747,,,,
,31238806.46,50.0009842,-79394.64453125,0.000187002376547005,9.51797717735624E-7,1,0.999253354069792,40.0298881530762,1.99433502412355,20.9699999541044,0.00211877723427637,0.000368098036854469,0.25,-1.0045372925809E-6,0.000187620397486966,2.10321465250434E-7,50.0009804,50.000988,-79427.0859375,-79362.203125,57.1354814987368,20.5608368844751,17.214239,0,0,0,40,4449,50.0037,-79394.64453125,,,,,,,,,,,,,0,,,,-0.00245,,,,,,50.0009842,,,,
,31238905.28,50.00147055,-84334.42578125,0.000207771183176944,1.12395432865459E-6,1,0.999253354069792,40.0298881530762,1.99431214316809,20.9699999541044,0.00235260044250858,0.000419537758545152,0.25,-1.68275874219819E-7,0.000208488517706956,1.16354696136861E-6,50.0013466,50.0015945,-84364.3828125,-84304.46875,57.5200427301984,20.563053220131,17.214239,0,0,0,40,4449,50.0031,-84334.42578125,,,,,,,,,,,,,0,,,,-0.00245,,,,,,50.00147055,,,,
,31238996.985,50.000658,-88913.84765625,0.000225444674787817,1.20387527655935E-6,1,0.999253354069792,40.0298881530762,1.99486836420012,20.9699999541044,0.0025511796081648,0.000470021009421684,0.25,1.12836837249001E-6,0.000226250066620069,2.55678048309588E-6,50.0004997,50.0008163,-88946.4296875,-88881.265625,57.2066096939868,20.5529483410434,17.214239,0,0,0,40,4449,50.00425,-88913.84765625,,,,,,,,,,,,,0,,,,0,,,,,,50.000658,,,,
,31239102.97,49.99961665,-86582.31640625,0.00021615095811074,1.18642938083055E-6,1,0.999253354069792,40.0298881530762,1.99533018808176,20.9699999541044,0.00244764082873575,0.000443546835804527,0.25,4.39034671322861E-7,0.000216910105769148,1.81669729323259E-6,49.9995766,49.9996567,-86600.140625,-86564.4921875,57.1104693861214,20.5531089140012,17.214239,0,0,0,40,4449,50.002,-86582.31640625,,,,,,,,,,,,,0,,,,0,,,,,,49.99961665,,,,
,31239197.43,49.9986973,-81856.828125,0.00019905122144941,9.45374693020883E-7,1,0.999253354069792,40.0298881530762,1.99508697573198,20.9699999541044,0.00225614084039621,0.000392903471956298,0.25,-9.78612979385881E-7,0.000199726197905434,3.04754414890846E-7,49.998497,49.9988976,-81882.359375,-81831.296875,57.2347483206791,20.5539051295392,17.214239,0,0,0,40,4449,50.00085,-81856.828125,,,,,,,,,,,,,0,,,,0,,,,,,49.9986973,,,,
,31239293.245,49.99991225,-77072.0703125,0.00018296688395576,1.03488765438275E-6,1,0.999253354069792,40.0298881530762,1.99503052398205,20.9699999541044,0.00207498750737279,0.000352314613726688,0.25,-1.69188566167251E-6,0.000183560352432837,-4.96760768175843E-7,49.9998703,49.9999542,-77099.59375,-77044.546875,57.1346998702176,20.5542132089964,16.834587,0,0,0,40,4449,50.0007,-77072.0703125,,,,,,,,,,,,,0,,,,-0.00245,,,,,,49.99991225,,,,
,31239389.39,49.9992943,-72265.02734375,0.000165141506366778,7.63186725876561E-7,1,0.999253354069792,40.0298881530762,1.99494256756929,20.9699999541044,0.00187281032764942,0.000315697135308085,0.25,-1.73934027314469E-6,0.000165648093080939,-6.45163178048153E-7,49.9992943,49.9992943,-72272.3984375,-72257.65625,56.9369478548522,20.5547801468751,17.593889,0,0,0,40,4449,50.0036,-72265.02734375,,,,,,,,,,,,,0,,,,0,,,,,,49.9992943,,,,
,31239483.885,49.99921415,-67543.16015625,0.000149831994018295,9.11680268785607E-7,1,0.999253354069792,40.0298881530762,1.99482885509112,20.9699999541044,0.00170156389306891,0.000270836657133985,0.25,-2.9638688832666E-6,0.000150272473105193,-1.96091317374226E-6,49.9990005,49.9994278,-67575.1953125,-67511.125,57.1808159528522,20.5561438022969,16.834587,0,0,0,40,4449,50.0042,-67543.16015625,,,,,,,,,,,,,0,,,,0.00245,,,,,,49.99921415,,,,
,31239579.365,49.9995232,-62770.802734375,0.000130863972645366,8.64573259618818E-7,1,0.999253354069792,40.0298881530762,1.9948821671787,20.9699999541044,0.00148407666721066,0.00024663383878443,0.25,-1.70574442637577E-6,0.000131216370659475,-8.15098975924591E-7,49.9995232,49.9995232,-62778.328125,-62763.27734375,57.2495992625445,20.5560925059627,17.214239,0,0,0,40,4449,50.0017,-62770.802734375,,,,,,,,,,,,,0,,,,0,,,,,,49.9995232,,,,
,31239675.03,49.9997711,-57990.48828125,0.000112685297019846,7.18619051644116E-7,1,0.999253354069792,40.0298881530762,1.99482911075994,20.9699999541044,0.00127651941695102,0.000218446441016242,0.25,-9.37400710362957E-7,0.000112961357786444,-1.59110714431143E-7,49.9997711,49.9997711,-57990.48828125,-57990.48828125,57.2675767184868,20.5521844645433,17.593889,0,0,0,40,4449,50.0024,-57990.48828125,,,,,,,,,,,,,0,,,,0,,,,,,49.9997711,,,,
,31239770.6,49.9988976,-53213.390625,9.92772358456216E-5,1.00883530448935E-6,1,0.999253354069792,40.0298881530762,1.99484325869075,20.9699999541044,0.00112418492943265,0.000193565363121152,0.25,-7.32334263416689E-7,9.949796170979E-5,-3.80613627121846E-8,49.9988976,49.9988976,-53218.53515625,-53208.24609375,57.1112510146407,20.5520979321183,17.593889,0,0,0,40,4449,50.0013,-53213.390625,,,,,,,,,,,,,0,,,,0,,,,,,49.9988976,,,,
,31239864.75,50.0001564,-48508.267578125,8.13448379588921E-5,9.38632411600859E-7,1,0.999253354069792,40.0298881530762,1.9948411337712,20.9699999541044,0.000925444698824383,0.000133393407636107,0.25,-2.83286986183158E-6,8.15232296837438E-5,-2.26200472142212E-6,50.0001564,50.0001564,-48540.8359375,-48475.69921875,57.0409044479099,20.5546658715715,17.593889,0,0,0,40,4449,50.00295,-48508.267578125,,,,,,,,,,,,,0,,,,-0.00245,,,,,,50.0001564,,,,
,31239960.59,49.9990921,-43718.2421875,6.46048636117292E-5,7.93236479438021E-7,1,0.999253354069792,40.0298881530762,1.99486636461781,20.9699999541044,0.000737521672173122,9.09847431884175E-5,0.25,-3.57585513005245E-6,6.47408745326597E-5,-3.1195625928487E-6,49.9990921,49.9990921,-43743.0546875,-43693.4296875,57.0721695886791,20.5517906139376,17.214239,0,0,0,40,4449,50.0073,-43718.2421875,,,,,,,,,,,,,0,,,,-0.0049,,,,,,49.9990921,,,,
,31240055.275,49.9992905,-38986.197265625,4.78108995394641E-5,8.09302811373196E-7,1,0.999253354069792,40.0298881530762,1.99491058500962,20.9699999541044,0.000544966378808875,7.13109697422789E-5,0.25,-2.29622547687479E-6,4.7897571558015E-5,-1.95429124452244E-6,49.9992905,49.9992905,-39011.21875,-38961.17578125,57.5856995258138,20.552515622161,16.834587,0,0,0,40,4449,50.00575,-38986.197265625,,,,,,,,,,,,,0,,,,0.00245,,,,,,49.9992905,,,,
,31240151.305,49.9992104,-34188.9765625,3.03644201058132E-5,6.42049410404871E-7,1,0.999253354069792,40.0298881530762,1.9950584461029,20.9699999541044,0.00034730499082067,3.82744745110725E-5,0.25,-2.08027846716638E-6,3.04164093471969E-5,-1.86174061948052E-6,49.9992104,49.9992104,-34194.046875,-34183.90625,56.9955699937945,20.5499253800948,17.214239,0,0,0,40,4449,50.0084,-34188.9765625,,,,,,,,,,,,,0,,,,0,,,,,,49.9992104,,,,
,31240246.76,49.9995193,-29416.96875,1.57508656569655E-5,6.56799797258842E-7,1,0.999253354069792,40.0298881530762,1.99491625839949,20.9699999541044,0.000181380078759434,1.27338570216298E-5,0.25,-1.70974951426241E-6,1.57784419447161E-5,-1.59592480440791E-6,49.9995193,49.9995193,-29422.212890625,-29411.724609375,57.2441278629099,20.5517799007674,16.834587,0,0,0,40,4449,50.00535,-29416.96875,,,,,,,,,,,,,0,,,,-0.00245,,,,,,49.9995193,,,,
,31240343.375,49.9984951,-24586.8359375,-7.40189556844586E-7,5.76521891590184E-7,1,0.999253354069792,40.0298881530762,1.99487558872436,20.9699999541044,-4.40987950021144E-6,-2.3417772760239E-5,0.25,-1.94057955751878E-6,-7.26395823774716E-7,-1.94737684165399E-6,49.9983864,49.9986038,-24619.099609375,-24554.572265625,57.2839909173907,20.551219588586,17.593889,0,0,0,40,4449,50.0084,-24586.8359375,,,,,,,,,,,,,0,,,,-0.00245,,,,,,49.9984951,,,,
,31240439.74,49.9987984,-19772.111328125,-1.58355662346612E-5,5.8669522704887E-7,1,0.999253354069792,40.0298881530762,1.99486782541515,20.9699999541044,-0.00017623027562854,-4.62341414123152E-5,0.25,-1.24206552780137E-6,-1.58330918643636E-5,-1.35983240279746E-6,49.9987984,49.9987984,-19801.908203125,-19742.314453125,57.0026046504676,20.5539798318632,17.214239,0,0,0,40,4449,50.0059,-19772.111328125,,,,,,,,,,,,,0,,,,-0.00245,,,,,,49.9987984,,,,
,31240535.2,50.0001183,-15002.5625,-3.03154427229756E-5,4.99429247098349E-7,1,0.999253354069792,40.0298881530762,1.99462020444247,20.9699999541044,-0.000339499438545604,-7.59656518265381E-5,0.25,-1.26835432603692E-6,-3.03109579320648E-5,-1.4936684655312E-6,50.0001183,50.0001183,-15005.1484375,-14999.9765625,56.9486722826406,20.5548969715389,17.214239,0,0,0,40,4449,50.0065,-15002.5625,,,,,,,,,,,,,0,,,,-0.0049,,,,,,50.0001183,,,,
,31240627.485,49.9993477,-10389.7470703125,-4.48447212954982E-5,4.59279825096539E-7,1,0.999253354069792,40.0298881530762,1.99470723196992,20.9699999541044,-0.000503045069110613,-0.000107155997956091,0.25,-1.41514997204804E-6,-4.48304881451174E-5,-1.74857339955676E-6,49.9993477,49.9993477,-10417.16015625,-10362.333984375,57.129228470583,20.5512937239886,17.593889,0,0,0,40,4449,50.0123,-10389.7470703125,,,,,,,,,,,,,0,,,,-0.00245,,,,,,49.9993477,,,,
,31240721.46,49.9991112,-5691.38037109375,-5.79612689877437E-5,3.31118607308829E-7,1,0.999253354069792,40.0298881530762,1.99457276234024,20.9699999541044,-0.000651922459714884,-0.000127697690901221,0.25,-8.74827847498068E-7,-5.79361857244628E-5,-1.30587914236267E-6,49.9991112,49.9991112,-5699.0712890625,-5683.689453125,57.0909286731407,20.5526961833243,17.593889,0,0,0,40,4449,50.01145,-5691.38037109375,,,,,,,,,,,,,0,,,,-0.0049,,,,,,49.9991112,,,,
,31240815.465,50.0003662,-992.583221435547,-7.01424646945448E-5,3.17654858996235E-7,1,0.999253354069792,40.0298881530762,1.99442471423565,20.9699999541044,-0.000788811082388278,-0.000153955723408701,0.25,-1.01116732344818E-6,-7.00981686271514E-5,-1.53243696789694E-6,50.0003662,50.0003662,-995.215393066406,-989.951049804687,57.065134932006,20.5523560360185,16.834587,0,0,0,40,4449,50.00775,-992.583221435547,,,,,,,,,,,,,0,,,,-0.00245,,,,,,50.0003662,,,,
,31240908.9,49.9999161,3673.16931152344,-7.9058961128316E-5,3.03991956463445E-7,1,0.999253354069792,40.0298881530762,1.99445278823744,20.9699999541044,-0.000890801251130584,-0.000164628810147963,0.25,-3.48670820083973E-7,-7.90235428208175E-5,-9.36820962987043E-7,49.9999161,49.9999161,3638.169921875,3708.16870117188,57.1729996676599,20.5516294043679,16.834587,0,0,0,40,4449,50.0084,3673.16931152344,,,,,,,,,,,,,0,,,,0,,,,,,49.9999161,,,,
,31241000.705,50.0005894,8264.787109375,-8.50570678063788E-5,4.20657306401651E-7,1,0.999253354069792,40.0298881530762,1.99439255307787,20.9699999541044,-0.000959371018002976,-0.0001727113991052,0.25,1.84973981486653E-8,-8.50407670445978E-5,-6.1437343811097E-7,50.0003281,50.0008507,8237.3564453125,8292.2177734375,56.9900985941599,20.5527792534367,17.214239,0,0,0,40,4449,50.0101,8264.787109375,,,,,,,,,,,,,0,,,,0.00245,,,,,,50.0005894,,,,
,31241091.935,49.9994469,12823.0517578125,-8.0808683069645E-5,4.94094264286466E-7,1,0.999253354069792,40.0298881530762,1.99428123563625,20.9699999541044,-0.000910972901307268,-0.000167719050972799,0.25,-3.02679564458151E-7,-8.08101571381022E-5,-9.03288483135166E-7,49.9994469,49.9994469,12820.431640625,12825.671875,56.8540952318137,20.5520050244175,17.214239,0,0,0,40,4449,50.0107,12823.0517578125,,,,,,,,,,,,,0,,,,0,,,,,,49.9994469,,,,
,31241185.525,50.0007057,17500.7138671875,-6.29374004331192E-5,4.83979658201639E-7,1,0.999253354069792,40.0298881530762,1.99416389162662,20.9699999541044,-0.000710521665678185,-0.000125800849513853,0.25,1.93094701701011E-7,-6.29577767001144E-5,-2.7353281940281E-7,50.0007057,50.0007057,17498.322265625,17503.10546875,57.088583787583,20.5546810373065,17.593889,0,0,0,40,4449,50.01205,17500.7138671875,,,,,,,,,,,,,0,,,,0,,,,,,50.0007057,,,,
,31241278.93,50.00115015,22170.8818359375,-4.20757456418351E-5,5.9739621170502E-7,1,0.999253354069792,40.0298881530762,1.99443254111268,20.9699999541044,-0.000475916437789427,-8.01050743174139E-5,0.25,4.84880781110179E-7,-4.21028077375054E-5,1.74263575695232E-7,50.0009079,50.0013924,22140.880859375,22200.8828125,56.8900501436983,20.5525460402995,16.834587,0,0,0,40,4449,50.01,22170.8818359375,,,,,,,,,,,,,0,,,,0,,,,,,50.00115015,,,,
,31241373.14,50.0003166,26879.5,-3.0999361499787E-5,6.45125825365331E-7,1,0.999253354069792,40.0298881530762,1.99426660284675,20.9699999541044,-0.000351424576402588,-5.49771917261392E-5,0.25,7.14886314462961E-7,-3.10299519048624E-5,4.87530933678015E-7,50.0003166,50.0003166,26874.623046875,26884.376953125,56.6743206723906,20.5540152862142,17.593889,0,0,0,40,4449,50.00905,26879.5,,,,,,,,,,,,,0,,,,0,,,,,,50.0003166,,,,
,31241466.04,50.00111775,31521.896484375,-3.3565002784384E-5,9.14693199784935E-7,1,0.999253354069792,40.0298881530762,1.9943408581921,20.9699999541044,-0.00038051386001872,-6.0128907740231E-5,0.25,7.20762179232508E-7,-3.36061885674358E-5,4.76201058104443E-7,50.0010529,50.0011826,31491.71875,31552.07421875,57.0354330482753,20.553500682213,16.834587,0,0,0,40,4449,50.0086,31521.896484375,,,,,,,,,,,,,0,,,,-0.00245,,,,,,50.00111775,,,,
,31241563.265,50.0009079,36381.890625,-4.2627953643705E-5,9.27856078321741E-7,1,0.999253354069792,40.0298881530762,1.99442872142691,20.9699999541044,-0.000482640910403522,-8.06159432240483E-5,0.25,5.3864275435887E-7,-4.26885653590395E-5,2.30111450655001E-7,50.0009079,50.0009079,36379.1796875,36384.6015625,56.8611298884868,20.5512485691011,16.834587,0,0,0,40,4449,50.0098,36381.890625,,,,,,,,,,,,,0,,,,-0.0049,,,,,,50.0009079,,,,
,31241658.115,50.001503,41121.880859375,-5.57849271684787E-5,9.29469821422977E-7,1,0.999253354069792,40.0298881530762,1.9945623194906,20.9699999541044,-0.000631113849682571,-0.000109349653621136,0.25,3.63422082584402E-7,-5.5875477695096E-5,-3.73151059979992E-8,50.001503,50.001503,41092.0546875,41151.70703125,56.9486722826406,20.5483743793835,17.593889,0,0,0,40,4449,50.00535,41121.880859375,,,,,,,,,,,,,0,,,,-0.0049,,,,,,50.001503,,,,
,31241750.4,49.9999695,45734.97265625,-7.13628713559714E-5,1.12764912820342E-6,1,0.999253354069792,40.0298881530762,1.99499392096236,20.9699999541044,-0.000807703655663596,-0.000139964240536831,0.25,4.58562129694603E-7,-7.1495300785167E-5,-4.92790806510523E-8,49.9999695,49.9999695,45709.72265625,45760.22265625,57.0971817012945,20.5422399730023,16.834587,0,0,0,40,4449,50.00535,45734.97265625,,,,,,,,,,,,,0,,,,0.0049,,,,,,49.9999695,,,,
,31241845.595,50.0016937,50492.4296875,-8.65296926726114E-5,9.03972789958561E-7,1,0.999253354069792,40.0298881530762,1.99495637627182,20.9699999541044,-0.000979146723059783,-0.00017212595005348,0.25,3.39123525559075E-7,-8.67088237718641E-5,-2.70563705470542E-7,50.0014572,50.0019302,50467.77734375,50517.08203125,57.0518472471791,20.5448359594806,17.214239,0,0,0,40,4449,50.0035,50492.4296875,,,,,,,,,,,,,0,,,,-0.00245,,,,,,50.0016937,,,,
,31241940.86,50.0010433,55255.234375,-0.000103506558785699,7.84943495469529E-7,1,0.999253354069792,40.0298881530762,1.99502162785233,20.9699999541044,-0.00117198846069764,-0.000203514606644838,0.25,6.12499190139058E-7,-0.000103745530696635,-1.08003055250699E-7,50.0008392,50.0012474,55220.15625,55290.3125,56.9213152844676,20.5443731122537,17.214239,0,0,0,40,4449,50.0047,55255.234375,,,,,,,,,,,,,0,,,,-0.00735,,,,,,50.0010433,,,,
,31242037.31,50.0018044,60075.384765625,-0.000121111380416926,7.26755989178663E-7,1,0.999253354069792,40.0298881530762,1.99488122437725,20.9699999541044,-0.00137155431587139,-0.00023802721339587,0.25,7.18374460454492E-7,-0.000121417342913642,-1.14214281143661E-7,50.0018044,50.0018044,60067.859375,60082.91015625,57.0338697912368,20.546637630011,17.593889,0,0,0,40,4449,50.0014,60075.384765625,,,,,,,,,,,,,0,,,,0,,,,,,50.0018044,,,,
,31242131.045,50.0008507,64761.0703125,-0.000138570024800366,9.84762297013972E-7,1,0.999253354069792,40.0298881530762,1.99481908015216,20.9699999541044,-0.00156727091165628,-0.000285020116978656,0.25,-3.06800026316234E-7,-0.000138940590917834,-1.25024777111033E-6,50.0008507,50.0008507,64731.109375,64791.03125,57.0354330482753,20.5466850255582,17.214239,0,0,0,40,4449,50.0027,64761.0703125,,,,,,,,,,,,,0,,,,0,,,,,,50.0008507,,,,
,31242230.79,50.0010529,69746.0859375,-0.000153799020705277,9.13219116550418E-7,1,0.999253354069792,40.0298881530762,1.99489542089264,20.9699999541044,-0.00173755478816557,-0.00032969587223454,0.25,-1.5283281599775E-6,-0.000154234186483623,-2.56427573587262E-6,50.0010529,50.0010529,69743.46875,69748.703125,57.1792526958137,20.5444573284456,16.834587,0,0,0,40,4449,50.0006,69746.0859375,,,,,,,,,,,,,0,,,,0.00245,,,,,,50.0010529,,,,
,31242324.25,50.0010605,74416.4296875,-0.000169885686070472,1.06188101290786E-6,1,0.999253354069792,40.0298881530762,1.99478150557114,20.9699999541044,-0.00192522706035574,-0.000332549974731845,0.25,1.09456528022367E-6,-0.000170416345248243,-2.58335928656081E-8,50.0010605,50.0010605,74411.46875,74421.390625,56.8548768603329,20.5436395328447,17.593889,0,0,0,40,4449,49.9982,74416.4296875,,,,,,,,,,,,,0,,,,-0.0049,,,,,,50.0010605,,,,
,31242419.985,50.0015755,79202.15234375,-0.000186822634144789,9.95471140715139E-7,1,0.999253354069792,40.0298881530762,1.99486481106219,20.9699999541044,-0.0021104688454646,-0.00040572472979376,0.25,-2.34219670803988E-6,-0.000187416840078774,-3.5675910693253E-6,50.0015755,50.0015755,79199.75,79204.5546875,56.8251749766022,20.5432821940829,16.834587,0,0,0,40,4449,49.9998,79202.15234375,,,,,,,,,,,,,0,,,,-0.0049,,,,,,50.0015755,,,,
,31242514.18,50.0012169,83910.76171875,-0.000204357786621181,1.14390402300873E-6,1,0.999253354069792,40.0298881530762,1.9948763188781,20.9699999541044,-0.0023068558189224,-0.000455636744884497,0.25,-3.61974559368455E-6,-0.000205035885283489,-4.94452808265603E-6,50.0011139,50.0013199,83908.171875,83913.3515625,56.8994296859291,20.5419297931128,16.834587,0,0,0,40,4449,49.99855,83910.76171875,,,,,,,,,,,,,0,,,,0,,,,,,50.0012169,,,,
,31242605.08,50.00226785,88456.55078125,-0.000217223709115799,1.17151093207371E-6,1,0.999253354069792,40.0298881530762,1.99479368584239,20.9699999541044,-0.00245730106314947,-0.000456888479344118,0.25,-1.44093325721107E-6,-0.000217994041347361,-2.82064320310308E-6,50.0020714,50.0024643,88426.484375,88486.6171875,57.0455942190253,20.5419288076406,17.593889,0,0,0,40,4449,49.9993,88456.55078125,,,,,,,,,,,,,0,,,,0.00245,,,,,,50.00226785,,,,
,31242710.1,49.9996033,87108.50390625,-0.000215974546921088,1.03825106976262E-6,1,0.999253354069792,40.0298881530762,1.99488927474566,20.9699999541044,-0.00244542596376224,-0.000441668013180838,0.25,-3.14624644148848E-7,-0.000216737629345373,-1.68844759063437E-6,49.9996033,49.9996033,87103.328125,87113.6796875,56.8650380310829,20.5444741234295,17.214239,0,0,0,40,4449,49.997,87108.50390625,,,,,,,,,,,,,0,,,,0,,,,,,49.9996033,,,,
,31242802.555,49.998703,82487.69921875,-0.000200751658695194,1.17474980563679E-6,1,0.999253354069792,40.0298881530762,1.99482744300172,20.9699999541044,-0.00227243233884191,-0.00041156520959456,0.25,-3.70847913930625E-7,-0.000201428130128209,-1.66717027450091E-6,49.998703,49.998703,82484.84375,82490.5546875,56.943200883006,20.5447210232203,16.834587,0,0,0,40,4449,49.9993,82487.69921875,,,,,,,,,,,,,0,,,,-0.0049,,,,,,49.998703,,,,
,31242897.79,49.9997597,77726.171875,-0.000183003589160406,1.10676522796707E-6,1,0.999253354069792,40.0298881530762,1.9948841901995,20.9699999541044,-0.00207059989223568,-0.000378632938291953,0.25,-6.30031480021647E-7,-0.000183586468906907,-1.83037315251222E-6,49.9997597,49.9997597,77721.3046875,77731.0390625,56.8861420011022,20.5443186100648,17.214239,0,0,0,40,4449,50.0015,77726.171875,,,,,,,,,,,,,0,,,,0.0049,,,,,,49.9997597,,,,
,31242994.03,49.9987144,72915.08984375,-0.000164599879412098,1.12558545959464E-6,1,0.999253354069792,40.0298881530762,1.99489596041223,20.9699999541044,-0.00186742072761627,-0.00031049500347363,0.25,2.09970479745762E-6,-0.000165111384734163,1.01235925817417E-6,49.9987144,49.9987144,72912.3828125,72917.796875,56.7431039820829,20.5441279321234,16.834587,0,0,0,40,4449,50.0012,72915.08984375,,,,,,,,,,,,,0,,,,-0.0049,,,,,,49.9987144,,,,
,31243089.84,50.0000916,68124.546875,-0.000148423772844487,9.32383249708211E-7,1,0.999253354069792,40.0298881530762,1.99490476376767,20.9699999541044,-0.00168249520222507,-0.00028600249233336,0.25,1.37075547798176E-6,-0.000148853012669651,3.74490046666801E-7,50.0000916,50.0000916,68099.671875,68149.421875,56.9752476522945,20.5463440077651,17.593889,0,0,0,40,4449,50.0003,68124.546875,,,,,,,,,,,,,0,,,,0,,,,,,50.0000916,,,,
,31243186.295,49.99845695,63304.748046875,-0.000129013158733663,8.04340840926754E-7,1,0.999253354069792,40.0298881530762,1.99495791636179,20.9699999541044,-0.00146140059281234,-0.000253030075292855,0.25,8.08022013948643E-7,-0.000129357525027205,-7.10198121736927E-8,49.9983101,49.9986038,63272.08203125,63337.4140625,56.8900501436983,20.5461831780783,16.834587,0,0,0,40,4449,49.99955,63304.748046875,,,,,,,,,,,,,0,,,,-0.0049,,,,,,49.99845695,,,,
,31243279.47,49.9987488,58645.71484375,-0.000113436816027499,9.10470209650896E-7,1,0.999253354069792,40.0298881530762,1.99482724993807,20.9699999541044,-0.00128468045862725,-0.000222071910563573,0.25,7.51150320564589E-7,-0.000113716705838106,-3.14531826142373E-8,49.9987488,49.9987488,58618.2890625,58673.140625,57.1651833824676,20.54656964989,16.834587,0,0,0,40,4449,50.00125,58645.71484375,,,,,,,,,,,,,0,,,,-0.00245,,,,,,49.9987488,,,,
,31243373.525,49.9989243,53945.248046875,-9.75073596662377E-5,7.55866312369789E-7,1,0.999253354069792,40.0298881530762,1.9949597969098,20.9699999541044,-0.00110050902601516,-0.000210902759923999,0.25,-1.11852388616241E-6,-9.77146782344357E-5,-1.80322903457342E-6,49.9989243,49.9989243,53920.16015625,53970.3359375,57.1229754424291,20.5445029833371,17.214239,0,0,0,40,4449,50.004,53945.248046875,,,,,,,,,,,,,0,,,,-0.00245,,,,,,49.9989243,,,,
,31243467.085,50.0000153,49270.455078125,-8.04158155591584E-5,7.10260082457306E-7,1,0.999253354069792,40.0298881530762,1.99496159102688,20.9699999541044,-0.000909664845761701,-0.000161331721818422,0.25,1.95025260067462E-7,-8.0576684655512E-5,-3.73419225082053E-7,50.0000153,50.0000153,49237.70703125,49303.203125,56.8666012881214,20.5443282815055,17.214239,0,0,0,40,4449,50.00255,49270.455078125,,,,,,,,,,,,,0,,,,0,,,,,,50.0000153,,,,
,31243561.21,49.9988441,44561.88671875,-6.50062951654909E-5,7.18455039179656E-7,1,0.999253354069792,40.0298881530762,1.99492610041764,20.9699999541044,-0.000734530747443651,-0.000133932515196554,0.25,-1.51449010685673E-7,-6.51189940004834E-5,-6.16220846755276E-7,49.9988441,49.9988441,44559.21875,44564.5546875,56.7696793517368,20.5483300957394,17.214239,0,0,0,40,4449,50.0008,44561.88671875,,,,,,,,,,,,,0,,,,0,,,,,,49.9988441,,,,
,31243656.07,49.9987602,39824.455078125,-4.90787390436402E-5,8.73352721455914E-7,1,0.999253354069792,40.0298881530762,1.99496242837807,20.9699999541044,-0.000559077857826971,-7.5302293773747E-5,0.25,2.17116238283695E-6,-4.91684355557496E-5,1.82050706918875E-6,49.9987602,49.9987602,39821.8515625,39827.05859375,56.9885353371214,20.5464508786121,17.214239,0,0,0,40,4449,50.0015,39824.455078125,,,,,,,,,,,,,0,,,,0,,,,,,49.9987602,,,,
,31243750.38,49.99873735,35109.509765625,-3.25090172002431E-5,9.73300387329365E-7,1,0.999253354069792,40.0298881530762,1.99499331404751,20.9699999541044,-0.00036936958954863,-5.47016042549903E-5,0.25,1.01227632075098E-6,-3.25573860364134E-5,7.7721429343883E-7,49.9985504,49.9989243,35079.34765625,35139.671875,56.8345545188329,20.5461056153797,17.214239,0,0,0,40,4449,50.0041,35109.509765625,,,,,,,,,,,,,0,,,,0,,,,,,49.99873735,,,,
,31243841.365,50.0009613,30561.9912109375,-1.70148885864415E-5,5.87275359628956E-7,1,0.999253354069792,40.0298881530762,1.99496506027287,20.9699999541044,-0.000192849958639862,-3.09813814003145E-5,0.25,3.21891320572577E-7,-1.70345408356287E-5,1.9768290072818E-7,50.0009613,50.0009613,30532.056640625,30591.92578125,57.0924919301791,20.5461355282634,17.214239,0,0,0,40,4449,50.0021,30561.9912109375,,,,,,,,,,,,,0,,,,-0.00245,,,,,,50.0009613,,,,
,31243936.97,49.9993858,25784.2509765625,-2.31268785486747E-6,6.39802747803377E-7,1,0.999253354069792,40.0298881530762,1.99520917600466,20.9699999541044,-2.793984641416E-5,5.39819601004123E-6,0.25,8.94628885328451E-7,-2.32102485448255E-6,8.78279639157272E-7,49.9993858,49.9993858,25779.37890625,25789.123046875,57.0026046504676,20.5478183374113,17.214239,0,0,0,40,4449,50.00855,25784.2509765625,,,,,,,,,,,,,0,,,,-0.00245,,,,,,49.9993858,,,,
,31244031.095,49.9993763,21081.771484375,1.30344534404114E-5,4.54716297203498E-7,1,0.999253354069792,40.0298881530762,1.99497098813147,20.9699999541044,0.000146311752120485,3.11977108402572E-5,0.25,4.14582980782074E-7,1.30378615185685E-5,5.11189957015742E-7,49.9991188,49.9996338,21051.662109375,21111.880859375,56.9439825115252,20.5477408187593,17.214239,0,0,0,40,4449,50.00565,21081.771484375,,,,,,,,,,,,,0,,,,0.00245,,,,,,49.9993763,,,,
,31244125.51,49.9990425,16359.4956054687,2.76770077878069E-5,5.34242332677473E-7,1,0.999253354069792,40.0298881530762,1.99500566581042,20.9699999541044,0.000311489704411076,6.12828404831995E-5,0.25,4.41436053161267E-7,2.76802629708861E-5,6.46912198081033E-7,49.9990425,49.9990425,16329.5048828125,16389.486328125,57.3035316303714,20.5479397138921,17.214239,0,0,0,40,4449,50.0034,16359.4956054687,,,,,,,,,,,,,0,,,,-0.00245,,,,,,49.9990425,,,,
,31244218.22,49.9987221,11729.8193359375,4.07217594966729E-5,4.84055122081931E-7,1,0.999253354069792,40.0298881530762,1.99521999627678,20.9699999541044,0.000459064572204831,8.55453208784846E-5,0.25,2.40482010579424E-7,4.07194268987127E-5,5.43247661249026E-7,49.9987221,49.9987221,11697.2802734375,11762.3583984375,57.1948852661984,20.5493104554312,17.593889,0,0,0,40,4449,50.00725,11729.8193359375,,,,,,,,,,,,,0,,,,0,,,,,,49.9987221,,,,
,31244312.28,49.99938395,7026.78076171875,5.51669169494839E-5,3.55129260067919E-7,1,0.999253354069792,40.0298881530762,1.99529429888967,20.9699999541044,0.000621399295534568,0.000117970104804053,0.25,5.11775547040053E-7,5.51489426060334E-5,9.221622819869E-7,49.9992104,49.9995575,6994.22900390625,7059.33251953125,56.8494054606983,20.5479513032901,17.214239,0,0,0,40,4449,50.0061,7026.78076171875,,,,,,,,,,,,,0,,,,-0.0049,,,,,,49.99938395,,,,
,31244404.105,49.99908065,2436.0400390625,6.72487718706933E-5,3.21425246943906E-7,1,0.999253354069792,40.0298881530762,1.99527753748776,20.9699999541044,0.000757956407202227,0.000140255480220694,0.25,3.11858637188621E-7,6.7214897784248E-5,8.12069363047868E-7,49.9987869,49.9993744,2405.91381835938,2466.16625976562,56.9471090256022,20.5508022793711,16.834587,0,0,0,40,4449,50.0061,2436.0400390625,,,,,,,,,,,,,0,,,,0,,,,,,49.99908065,,,,
,31244452.385,50.0002632,25.4464123547077,7.36258573660887E-5,3.06106492828039E-7,1,0.999253354069792,40.0298881530762,1.99539142421684,20.9699999541044,0.00083087653066682,0.000147620612079062,0.25,-1.84215115360576E-7,7.35864949835926E-5,3.63539665116071E-7,50.0002632,50.0002632,-0.563279569149017,51.4561042785645,57.0260535060445,20.5488671362568,17.214239,0,0,0,40,4417,50.0063,25.4464123547077,,,,,,,,,,,,,0,,,,-0.00245,,,,,,50.0002632,,,,