File: data/doubleLayers/dl_0-125/ppms/data/DD213_7_HYST_100OE_100K.DAT
[Header]
; VSM Data File (default extension .dat)
; Copyright (c) 2003-2013, Quantum Design, Inc. All rights reserved.
TITLE,
FILEOPENTIME,31245675.03,12/28/2018,11:23 pm
BYAPP,VSM,2.0,2.0
INFO,PPMS VSM Option Release 1.4.10 Build 1,APPNAME
INFO,Quantum Design Linear Motor Servo Controller,MOTOR_MODULE_NAME
INFO,3101-100 M1,MOTOR_HW_VERSION
INFO,MMC1014,MOTOR_SERIAL_NUMBER
INFO,SRV No X-over 01.03.11,MOTOR_SOFTWARE_VERSION
INFO,Quantum Design VSM Detection Module,VSM_MODULE_NAME
INFO,3101-150 F0,VSM_HW_VERSION
INFO,VSM707,VSM_SERIAL_NUMBER
INFO,VSM No X-over 01.02.05 May 20 2008 13:51:47,VSM_SOFTWARE_VERSION
INFO,704,PREAMP_SERIAL_NUMBER
INFO,822,COIL_SERIAL_NUMBER
INFO,0,MOMENT_UNITS
INFO,CoFe2O4,SAMPLE_MATERIAL
INFO,Double Layer thin concentration,SAMPLE_COMMENT
INFO,29.55,SAMPLE_MASS
INFO,,SAMPLE_VOLUME
INFO,,SAMPLE_MOLECULAR_WEIGHT
INFO,,SAMPLE_SIZE
INFO,,SAMPLE_SHAPE
DATATYPE,COMMENT,1
DATATYPE,TIME,2
STARTUPAXIS,X,2
STARTUPAXIS,Y1,5
[Data]
Comment,Time Stamp (sec),Temperature (K),Magnetic Field (Oe),Moment (emu),M. Std. Err. (emu),Transport Action,Averaging Time (sec),Frequency (Hz),Peak Amplitude (mm),Center Position (mm),Coil Signal' (mV),Coil Signal" (mV),Range (mV),M. Quad. Signal (emu),M. Raw' (emu),M. Raw" (emu),Min. Temperature (K),Max. Temperature (K),Min. Field (Oe),Max. Field (Oe),Mass (grams),Motor Lag (deg),Pressure (Torr),VSM Status (code),Motor Status (code),Measure Status (code),Measure Count,PPMS Status (code),System Temp. (K),System Field (Oe),Sample Position (deg),Bridge 1 Resistance (ohms),Bridge 1 Excitation (에),Bridge 2 Resistance (ohms),Bridge 2 Excitation (에),Bridge 3 Resistance (ohms),Bridge 3 Excitation (에),Bridge 4 Resistance (ohms),Bridge 4 Excitation (에),Signal 1 Vin (V),Signal 2 Vin (V),Digital Inputs (code),Drive 1 Iout (mA),Drive 1 Ipower (W),Drive 2 Iout (mA),Drive 2 Ipower (W),Pressure (),Map 20 (),Map 21 (),Map 22 (),Map 23 (),Map 24 (),Map 25 (),Map 26 (),Map 27 (),Map 28 (),Map 29 ()
,31245690.08,100.0047531,-0.42626565694809,,,2,,,,20.7900009298325,,,,,,,100.0047531,100.0047531,-0.42626565694809,-0.42626565694809,,,22.529354,,,,-99999999,4369,99.9157,-0.42626565694809,,,,,,,,,,,,,,,,,,,,,,,100.0047531,,,,
,31245854.73,99.9953079,5341.849609375,5.00973578424626E-5,4.66612436350731E-7,1,0.999253354069792,40.0298881530762,1.98349021337764,20.7800008356571,0.000564230948926314,0.000108266069621386,0.25,7.81611812495123E-7,5.03769424728407E-5,9.4139315618723E-7,99.9953079,99.9953079,5334.279296875,5349.419921875,56.709493955756,20.530175701838,22.529354,0,0,0,40,4449,99.9243,5341.849609375,,,,,,,,,,,,,0,,,,0,,,,,,99.9953079,,,,
,31245961.72,99.9960556,10691.1157226562,3.71192738652144E-5,7.07252129339715E-7,1,0.999253354069792,40.0298881530762,1.98367068395196,20.7800008356571,0.000418321732761252,7.89788220785063E-5,0.25,4.6928308028756E-7,3.7327064826799E-5,5.8643039796509E-7,99.9960556,99.9960556,10686.119140625,10696.1123046875,56.4210730321598,20.5359650916371,22.149702,0,0,0,40,4449,99.9294,10691.1157226562,,,,,,,,,,,,,0,,,,0.0049,,,,,,99.9960556,,,,
,31246054.43,99.99973675,15321.3046875,2.60810773344426E-5,1.08825865232291E-6,1,0.999253354069792,40.0298881530762,1.98334286122239,20.7800008356571,0.000293301347153159,5.87812305586403E-5,0.25,6.22067026591358E-7,2.62263682548409E-5,7.05623297290865E-7,99.9997253,99.9997482,15288.9560546875,15353.6533203125,56.6274229612368,20.5434716526456,22.529354,0,0,0,40,4449,99.9274,15321.3046875,,,,,,,,,,,,,0,,,,-0.0049,,,,,,99.99973675,,,,
,31246118.39,100.0016632,18519.708984375,1.45811174177975E-5,9.67055132700545E-7,1,0.999253354069792,40.0298881530762,1.98347697534024,20.7800008356571,0.000161877625143684,4.48704757908421E-5,0.25,1.4109433363266E-6,1.4659171488659E-5,1.46350066438345E-6,100.0016632,100.0016632,18517.150390625,18522.267578125,56.5805252500829,20.5448992512676,22.529354,0,0,0,40,4449,99.9253,18519.708984375,,,,,,,,,,,,,0,,,,0,,,,,,100.0016632,,,,
,31246193.21,100.0024872,22260.169921875,3.29079082775469E-6,1.07950135515622E-6,1,0.999253354069792,40.0298881530762,1.98355854062483,20.7800008356571,3.21008100616665E-5,3.53686799564618E-5,0.25,2.5533373837751E-6,3.30162749788288E-6,2.57779475348019E-6,100.0024872,100.0024872,22255.2734375,22265.06640625,56.5750538504483,20.5430417887204,22.529354,0,0,0,40,4449,99.92365,22260.169921875,,,,,,,,,,,,,0,,,,0.0049,,,,,,100.0024872,,,,
,31246272.23,100.0030289,26208.158203125,-9.16695121740241E-6,1.08557532252918E-6,1,0.999253354069792,40.0298881530762,1.98328047132971,20.7800008356571,-0.000109433620035714,1.54596938408832E-5,0.25,2.97941579586853E-6,-9.22787758233102E-6,2.96851202380929E-6,100.0030289,100.0030289,26203.26171875,26213.0546875,56.4875114562944,20.5483085747826,22.909004,0,0,0,40,4449,99.92085,26208.158203125,,,,,,,,,,,,,0,,,,-0.00245,,,,,,100.0030289,,,,
,31246336.97,100.0036697,29444.3017578125,-2.02136250783358E-5,1.72435679018909E-6,1,0.999253354069792,40.0298881530762,1.98337592488587,20.7800008356571,-0.000234518553357922,-4.61802336705361E-6,0.25,3.14198312880661E-6,-2.03376575404744E-5,3.09879710226054E-6,100.0036697,100.0036697,29441.6328125,29446.970703125,56.5602029085829,20.548689029699,22.529354,0,0,0,40,4449,99.91795,29444.3017578125,,,,,,,,,,,,,0,,,,-0.0049,,,,,,100.0036697,,,,
,31246398.44,100.00511555,32517.9482421875,-2.98941759731286E-5,1.48995950808166E-6,1,0.999253354069792,40.0298881530762,1.983320997344,20.7800008356571,-0.000346823710724096,-6.83289788451235E-6,0.25,4.64605673876059E-6,-3.00777073734854E-5,4.58256061188574E-6,100.0051041,100.005127,32490.34375,32545.552734375,56.922878541506,20.5480370650516,22.529354,0,0,0,40,4449,99.91495,32517.9482421875,,,,,,,,,,,,,0,,,,-0.0049,,,,,,100.00511555,,,,
,31246461.22,100.0056305,35655.87890625,-4.14462445340725E-5,1.3783989487416E-6,1,0.999253354069792,40.0298881530762,1.98332216051031,20.7800008356571,-0.000478937498303142,-2.035866318966E-5,0.25,5.47707375495868E-6,-4.16979552556308E-5,5.3841047405411E-6,100.0055771,100.0056839,35623.7421875,35688.015625,56.5039256551983,20.5484308669314,22.149702,0,0,0,40,4449,99.9123,35655.87890625,,,,,,,,,,,,,0,,,,0.00245,,,,,,100.0056305,,,,
,31246525.645,100.0062714,38874.390625,-5.23393311829906E-5,1.92329002391102E-6,1,0.999253354069792,40.0298881530762,1.98338138049784,20.7800008356571,-0.000603322469159819,-3.43138271839753E-5,0.25,6.15412717788721E-6,-5.2655125671537E-5,6.03308588848361E-6,100.0062714,100.0062714,38872.078125,38876.703125,56.9697762526599,20.5472158813253,22.909004,0,0,0,40,4449,99.90835,38874.390625,,,,,,,,,,,,,0,,,,0,,,,,,100.0062714,,,,
,31246588.5,100.0076141,42018.142578125,-6.23002264607608E-5,1.60584128198507E-6,1,0.999253354069792,40.0298881530762,1.98322787349847,20.7800008356571,-0.000714075641963587,-6.37152421445692E-5,0.25,5.29910172622119E-6,-6.26703494754819E-5,5.1443063608206E-6,100.0076141,100.0076141,41985.5703125,42050.71484375,56.9338213407753,20.5492882738589,22.529354,0,0,0,40,4449,99.90375,42018.142578125,,,,,,,,,,,,,0,,,,-0.00245,,,,,,100.0076141,,,,
,31246653.015,100.0084534,45241.603515625,-7.21804976824309E-5,1.52575009614858E-6,1,0.999253354069792,40.0298881530762,1.98296069136386,20.7800008356571,-0.000822645874030231,-9.98523727152357E-5,0.25,3.83233046020557E-6,-7.26028175169954E-5,3.6407972684251E-6,100.0084534,100.0084534,45238.8828125,45244.32421875,56.8587850029291,20.5494877246184,22.909004,0,0,0,40,4449,99.8975,45241.603515625,,,,,,,,,,,,,0,,,,0.00245,,,,,,100.0084534,,,,
,31246715.515,100.0085869,48367.236328125,-8.68314701848338E-5,2.18011233337201E-6,1,0.999253354069792,40.0298881530762,1.98315139369189,20.7800008356571,-0.000982467779854364,-0.000161430158631757,0.25,9.52104217131392E-7,-8.7329151085155E-5,7.01945637743671E-7,100.0084839,100.0086899,48337.62890625,48396.84375,57.0635716749676,20.5492319820384,22.909004,0,0,0,40,4449,99.89185,48367.236328125,,,,,,,,,,,,,0,,,,0,,,,,,100.0085869,,,,
,31246778.49,100.0082092,51511.03515625,-9.6518846909471E-5,2.00054757268222E-6,1,0.999253354069792,40.0298881530762,1.98295180964081,20.7800008356571,-0.00109594741475412,-0.000156815110378636,0.25,3.05931815421058E-6,-9.70784281914723E-5,2.79389143644776E-6,100.0082092,100.0082092,51486.32421875,51535.74609375,57.0362146767945,20.5519823442501,22.909004,0,0,0,40,4449,99.8886,51511.03515625,,,,,,,,,,,,,0,,,,0,,,,,,100.0082092,,,,
,31246842.91,100.0093079,54731.666015625,-0.000107418018303425,1.32420022340367E-6,1,0.999253354069792,40.0298881530762,1.98306888225617,20.7800008356571,-0.00122791044168319,-0.000128222230878559,0.25,7.50444873744361E-6,-0.00010805329785135,7.23386368473605E-6,100.0093079,100.0093079,54729.296875,54734.03515625,56.8322096332752,20.5448344740738,22.909004,0,0,0,40,4449,99.8831,54731.666015625,,,,,,,,,,,,,0,,,,0,,,,,,100.0093079,,,,
,31246907.395,100.0094528,57955.439453125,-0.000119115107289149,1.83395791158231E-6,1,0.999253354069792,40.0298881530762,1.98312114122641,20.7800008356571,-0.00135455991742948,-0.000182644074857036,0.25,4.73778377959836E-6,-0.000119809697683703,4.41882718297154E-6,100.0094528,100.0094528,57952.97265625,57957.90625,56.750138638756,20.5470768595357,22.909004,0,0,0,40,4449,99.87555,57955.439453125,,,,,,,,,,,,,0,,,,0,,,,,,100.0094528,,,,
,31246969.915,100.0093079,61081.236328125,-0.000129769232750822,2.21559324181913E-6,1,0.999253354069792,40.0298881530762,1.98322616208597,20.7800008356571,-0.00147633228726312,-0.000195952222412787,0.25,5.42903952475678E-6,-0.000130527348680851,5.08474014308263E-6,100.0093079,100.0093079,61051.28125,61111.19140625,56.5461335952368,20.5482144435903,22.909004,0,0,0,40,4449,99.86905,61081.236328125,,,,,,,,,,,,,0,,,,0.00245,,,,,,100.0093079,,,,
,31247033.235,100.0080452,64245.2265625,-0.000148240657606423,2.45417485625332E-6,1,0.999253354069792,40.0298881530762,1.98330512846972,20.7800008356571,-0.00168135463034065,-0.000253433055209042,0.25,3.58091852990854E-6,-0.000149099866439754,3.17454945172878E-6,100.0080185,100.0080719,64215.359375,64275.09375,57.0729512171983,20.5463626431961,22.529354,0,0,0,40,4449,99.8662,64245.2265625,,,,,,,,,,,,,0,,,,0.00245,,,,,,100.0080452,,,,
,31247096.415,100.0082703,67403.95703125,-0.000156011552117554,1.99472891481098E-6,1,0.999253354069792,40.0298881530762,1.9832413920796,20.7800008356571,-0.00177339186284436,-0.000244235938091984,0.25,5.75668419313055E-6,-0.0001569222914011,5.3424333235205E-6,100.0082703,100.0082703,67374.125,67433.7890625,56.5258112537367,20.5480145739839,22.909004,0,0,0,40,4449,99.8623,67403.95703125,,,,,,,,,,,,,0,,,,-0.00245,,,,,,100.0082703,,,,
,31247159.285,100.0079613,70542.2421875,-0.000167505588003868,2.2385028046746E-6,1,0.999253354069792,40.0298881530762,1.98316871923111,20.7800008356571,-0.00189895510458455,-0.000290897477271596,0.25,3.63957244575848E-6,-0.000168476986722329,3.18239555204118E-6,100.0077591,100.0081635,70507.3515625,70577.1328125,56.6625962446021,20.5500962856584,22.529354,0,0,0,40,4449,99.85835,70542.2421875,,,,,,,,,,,,,0,,,,0,,,,,,100.0079613,,,,
,31247222.845,100.006218,73723.3125,-0.000177573462954598,1.36729032376191E-6,1,0.999253354069792,40.0298881530762,1.98318795351234,20.7800008356571,-0.00202210725940318,-0.000257173425675498,0.25,8.39063487169894E-6,-0.000178617032819129,7.93432522480736E-6,100.006218,100.006218,73695.796875,73750.828125,56.3210245816983,20.5482034091553,22.909004,0,0,0,40,4449,99.85395,73723.3125,,,,,,,,,,,,,0,,,,0.00245,,,,,,100.006218,,,,
,31247281.22,100.0067825,76639.71484375,-0.000188011175622223,1.89796186729962E-6,1,0.999253354069792,40.0298881530762,1.98281936616546,20.7800008356571,-0.00213767369467983,-0.000288891351610168,0.25,7.40722232338431E-6,-0.000189112722024194,6.91788099353725E-6,100.0067825,100.0067825,76609.59375,76669.8359375,56.9017745714868,20.5521461630364,22.909004,0,0,0,40,4449,99.85025,76639.71484375,,,,,,,,,,,,,0,,,,0,,,,,,100.0067825,,,,
,31247341.29,100.00600815,79643.44921875,-0.000202160045671937,2.36344800508147E-6,1,0.999253354069792,40.0298881530762,1.98280596182199,20.7800008356571,-0.00229836431569771,-0.000311637706946963,0.25,7.87305934737493E-6,-0.000203345157397052,7.3488929770161E-6,100.0056839,100.0063324,79613.546875,79673.3515625,56.5375356815252,20.5538015636679,23.288654,0,0,0,40,4449,99.84805,79643.44921875,,,,,,,,,,,,,0,,,,-0.00245,,,,,,100.00600815,,,,
,31247403.4,100.00634765,82747.62109375,-0.000214362456648703,2.348017835808E-6,1,0.999253354069792,40.0298881530762,1.98326175202,20.7800008356571,-0.00243418370287536,-0.000350223413661976,0.25,6.60127200846786E-6,-0.000215615195684928,6.0381435157183E-6,100.005928,100.0067673,82722.6484375,82772.59375,56.6547799594098,20.5487889731406,23.288654,0,0,0,40,4449,99.8425,82747.62109375,,,,,,,,,,,,,0,,,,-0.00245,,,,,,100.00634765,,,,
,31247462.815,100.0056534,85719.10546875,-0.000226524579909149,2.38966186466884E-6,1,0.999253354069792,40.0298881530762,1.98351603903923,20.7800008356571,-0.00256973015050027,-0.000386595217599027,0.25,5.51638437929528E-6,-0.000227845357425668,4.91568611150544E-6,100.0056534,100.0056534,85686.34375,85751.8671875,56.997133250833,20.5433768296778,22.529354,0,0,0,40,4449,99.84065,85719.10546875,,,,,,,,,,,,,0,,,,0,,,,,,100.0056534,,,,
,31247519.14,100.0061646,88532.5234375,-0.000235256290402283,1.87694819960325E-6,1,0.999253354069792,40.0298881530762,1.98341736734562,20.7800008356571,-0.00266789550868922,-0.000405886220308197,0.25,5.33624980204006E-6,-0.00023662789744418,4.71282470815517E-6,100.0061646,100.0061646,88510.0078125,88555.0390625,56.485948199256,20.5425418892581,22.909004,0,0,0,40,4449,99.83505,88532.5234375,,,,,,,,,,,,,0,,,,0.00245,,,,,,100.0061646,,,,
,31247590.345,100.0034637,88660.265625,-0.000240044673809346,2.13172606237274E-6,1,0.999253354069792,40.0298881530762,1.98360818300974,20.7800008356571,-0.00272043709850755,-0.000425651481557954,0.25,4.42975261615489E-6,-0.000241441438583517,3.78791392232598E-6,100.0034637,100.0034637,88632.765625,88687.765625,56.8853603725829,20.5430707278318,22.529354,0,0,0,40,4449,99.8353,88660.265625,,,,,,,,,,,,,0,,,,-0.00245,,,,,,100.0034637,,,,
,31247647.275,100.0013504,85814.35546875,-0.000226438014090443,2.43885638969872E-6,1,0.999253354069792,40.0298881530762,1.98308039555127,20.7800008356571,-0.00256389328883503,-0.000410969458082878,0.25,3.33573505702456E-6,-0.000227752238821006,2.7227497653517E-6,100.0013504,100.0013504,85789.390625,85839.3203125,56.432015831429,20.5479889287688,22.529354,0,0,0,40,4449,99.8354,85814.35546875,,,,,,,,,,,,,0,,,,0.00245,,,,,,100.0013504,,,,
,31247705.545,99.9997787,82899.91796875,-0.000216033146469697,2.54321465195526E-6,1,0.999253354069792,40.0298881530762,1.98333727482248,20.7800008356571,-0.00245928824933359,-0.000318521907439624,0.25,9.70216771162554E-6,-0.000217304261039588,9.15229617404779E-6,99.9997787,99.9997787,82869.734375,82930.1015625,56.533627538929,20.5452293822747,22.909004,0,0,0,40,4449,99.8372,82899.91796875,,,,,,,,,,,,,0,,,,0,,,,,,99.9997787,,,,
,31247766.745,99.9998474,79840.0703125,-0.000204466489055893,2.36988316267588E-6,1,0.999253354069792,40.0298881530762,1.98339646106395,20.7800008356571,-0.00232763319826628,-0.000301690528105318,0.25,9.16621020962218E-6,-0.000205668560619354,8.64305148280339E-6,99.9997787,99.9999161,79810.1953125,79869.9453125,56.902556200006,20.5475932057319,22.909004,0,0,0,40,4449,99.83675,79840.0703125,,,,,,,,,,,,,0,,,,0,,,,,,99.9998474,,,,
,31247831.51,99.9990005,76601.796875,-0.000193760586151398,1.74715141825316E-6,1,0.999253354069792,40.0298881530762,1.98343712221078,20.7800008356571,-0.00220160188542467,-0.000309768584096714,0.25,6.57551726850901E-6,-0.000194892805666968,6.0649968921238E-6,99.9990005,99.9990005,76571.8046875,76631.7890625,56.9009929429675,20.5456837547247,22.529354,0,0,0,40,4449,99.83855,76601.796875,,,,,,,,,,,,,0,,,,0,,,,,,99.9990005,,,,
,31247894.48,99.9971085,73454.984375,-0.0001828331018183,2.35322631724664E-6,1,0.999253354069792,40.0298881530762,1.98343888672874,20.7800008356571,-0.00207649921959058,-0.000297602748613989,0.25,5.73735427482092E-6,-0.00018389924490094,5.2505287338513E-6,99.9971085,99.9971085,73452.453125,73457.515625,56.8853603725829,20.5483216870657,23.288654,0,0,0,40,4449,99.8382,73454.984375,,,,,,,,,,,,,0,,,,0,,,,,,99.9971085,,,,
,31247956.475,99.9970932,70356.04296875,-0.000169521910086692,1.92488693974774E-6,1,0.999253354069792,40.0298881530762,1.98372008853028,20.7800008356571,-0.00193243456297653,-0.000236863628379967,0.25,8.78370442203055E-6,-0.00017051950960893,8.35004414771141E-6,99.9970932,99.9970932,70323.7421875,70388.34375,56.9729027667368,20.5439443293586,23.288654,0,0,0,40,4449,99.8444,70356.04296875,,,,,,,,,,,,,0,,,,0,,,,,,99.9970932,,,,
,31248029.13,99.9965439,66725.09765625,-0.000155275724903052,1.91390401077996E-6,1,0.999253354069792,40.0298881530762,1.98329672629644,20.7800008356571,-0.00177020168222458,-0.000213868446205042,0.25,8.3174158773455E-6,-0.000156189421898784,7.91938348304419E-6,99.9965439,99.9965439,66720.0703125,66730.125,56.8071975206598,20.548217140641,22.529354,0,0,0,40,4449,99.84515,66725.09765625,,,,,,,,,,,,,0,,,,-0.0049,,,,,,99.9965439,,,,
,31248094.21,99.9961014,63471.525390625,-0.00014341656279651,2.09603940567443E-6,1,0.999253354069792,40.0298881530762,1.98352615585576,20.7800008356571,-0.00163688735018043,-0.000187803310517679,0.25,8.5474328336915E-6,-0.000144262273088309,8.18279932529847E-6,99.9960022,99.9962006,63441.43359375,63501.6171875,56.6610329875637,20.5441370018812,22.909004,0,0,0,40,4449,99.8473,63471.525390625,,,,,,,,,,,,,0,,,,0.00245,,,,,,99.9961014,,,,
,31248164.36,99.99599455,59964.998046875,-0.000124790576637919,2.09455887521486E-6,1,0.999253354069792,40.0298881530762,1.98329306065412,20.7800008356571,-0.00142693510012815,-0.000147426613391855,0.25,8.85287961029623E-6,-0.000125529908470953,8.54187105911662E-6,99.9958267,99.9961624,59937.46484375,59992.53125,56.9486722826406,20.547444030901,23.288654,0,0,0,40,4449,99.85095,59964.998046875,,,,,,,,,,,,,0,,,,0,,,,,,99.99599455,,,,
,31248229.615,99.9948883,56701.66796875,-0.000116279956530379,2.39326601239378E-6,1,0.999253354069792,40.0298881530762,1.98322492561162,20.7800008356571,-0.00132455366502609,-0.000165937473545395,0.25,5.72086910274999E-6,-0.000116960961128794,5.41503032367035E-6,99.9948883,99.9948883,56699.1796875,56704.15625,56.8134505488137,20.5529559569865,22.529354,0,0,0,40,4449,99.8529,56701.66796875,,,,,,,,,,,,,0,,,,0,,,,,,99.9948883,,,,
,31248307.895,99.9938812,52788.505859375,-0.000101517001791145,1.58766959484751E-6,1,0.999253354069792,40.0298881530762,1.98341177944322,20.7800008356571,-0.00115074763759031,-0.000177559908951929,0.25,2.10288574069792E-6,-0.000102102478226011,1.81773778101286E-6,99.9938812,99.9938812,52755.7890625,52821.22265625,57.0033862789868,20.547861298946,22.909004,0,0,0,40,4449,99.858,52788.505859375,,,,,,,,,,,,,0,,,,-0.00245,,,,,,99.9938812,,,,
,31248389.425,99.9941559,48715.23828125,-8.53695960495878E-5,1.91688131183252E-6,1,0.999253354069792,40.0298881530762,1.98332764892752,20.7800008356571,-0.000975488837887144,-0.000104740708922029,0.25,5.71612152375241E-6,-8.58729917569502E-5,5.49741389905337E-6,99.9941559,99.9941559,48707.93359375,48722.54296875,56.8970848003714,20.5488440312936,22.909004,0,0,0,40,4449,99.86165,48715.23828125,,,,,,,,,,,,,0,,,,-0.00245,,,,,,99.9941559,,,,
,31248495.265,99.9948425,43425.111328125,-6.60430433667987E-5,1.86924435660295E-6,1,0.999253354069792,40.0298881530762,1.9834984444227,20.7800008356571,-0.000749520978124006,-0.000110567641960627,0.25,1.80869758746569E-6,-6.64242199852032E-5,1.62320136376364E-6,99.9948425,99.9948425,43415.05078125,43435.171875,57.1143775287176,20.5494971600497,22.909004,0,0,0,40,4449,99.86945,43425.111328125,,,,,,,,,,,,,0,,,,0.0049,,,,,,99.9948425,,,,
,31248601.045,99.99144745,38140.48046875,-4.88057148638409E-5,1.6537206161701E-6,1,0.999253354069792,40.0298881530762,1.98347169493266,20.7800008356571,-0.000555992634942785,-6.96973442508098E-5,0.25,2.40101470043655E-6,-4.90901718968404E-5,2.2689595878757E-6,99.9911652,99.9917297,38132.96875,38147.9921875,56.9416376259676,20.5485051968151,23.288654,0,0,0,40,4449,99.8793,38140.48046875,,,,,,,,,,,,,0,,,,0.00245,,,,,,99.99144745,,,,
,31248706.33,99.9933014,32875.787109375,-3.16942079657489E-5,1.39453020810287E-6,1,0.999253354069792,40.0298881530762,1.98341284807722,20.7800008356571,-0.000364325527473318,-2.65891307736978E-5,0.25,3.2129943253704E-6,-3.18836479500094E-5,3.1359532669295E-6,99.9933014,99.9933014,32870.6171875,32880.95703125,57.0878021590637,20.5510437807133,22.909004,0,0,0,40,4449,99.8835,32875.787109375,,,,,,,,,,,,,0,,,,0,,,,,,99.9933014,,,,
,31248814.875,99.9927521,27451.533203125,-1.39687623018982E-5,1.65582403424286E-6,1,0.999253354069792,40.0298881530762,1.98354765003369,20.7800008356571,-0.000161206847554199,-8.15417797281407E-6,0.25,1.73203264174307E-6,-1.40531137762301E-5,1.69956890789506E-6,99.9927521,99.9927521,27443.80859375,27459.2578125,56.953362053756,20.5507478995012,22.909004,0,0,0,40,4449,99.8942,27451.533203125,,,,,,,,,,,,,0,,,,-0.00245,,,,,,99.9927521,,,,
,31248925.05,99.991066,21943.6025390625,5.89292025498581E-6,1.18219684816474E-6,1,0.999253354069792,40.0298881530762,1.98367737321372,20.7800008356571,6.33259230673818E-5,3.0106823350749E-5,0.25,1.63011074924859E-6,5.9212744920383E-6,1.65728078313989E-6,99.991066,99.991066,21941.083984375,21946.12109375,56.6922981283329,20.5487070733917,22.909004,0,0,0,40,4449,99.90305,21943.6025390625,,,,,,,,,,,,,0,,,,0.0049,,,,,,99.991066,,,,
,31249033.535,99.9911194,16522.0009765625,2.19378313193339E-5,1.0763104133255E-6,1,0.999253354069792,40.0298881530762,1.98362653742642,20.7800008356571,0.000246081381533414,5.32071414920282E-5,0.25,8.55959328219308E-7,2.2059059929898E-5,9.28048232488198E-7,99.9911194,99.9911194,16519.568359375,16524.43359375,57.0979633298137,20.5487629031509,22.529354,0,0,0,40,4449,99.9105,16522.0009765625,,,,,,,,,,,,,0,,,,0,,,,,,99.9911194,,,,
,31249140.85,99.9930496,11157.3510742187,3.91108549222802E-5,7.11119826066206E-7,1,0.999253354069792,40.0298881530762,1.98353764085621,20.7800008356571,0.000439955551992581,8.76642436937776E-5,0.25,8.88793491571464E-7,3.93285967469055E-5,1.01441578362288E-6,99.9930496,99.9930496,11152.3251953125,11162.376953125,57.108906129083,20.5502513472609,22.529354,0,0,0,40,4449,99.91685,11157.3510742187,,,,,,,,,,,,,0,,,,-0.0049,,,,,,99.9930496,,,,
,31249250.28,99.9914169,5689.81103515625,5.40740981178531E-5,5.31666719642337E-7,1,0.999253354069792,40.0298881530762,1.98345877393206,20.7800008356571,0.000609655564785122,0.000113190470964146,0.25,5.18920647725413E-7,5.4376916378822E-5,6.89496809843065E-7,99.9914169,99.9914169,5679.71923828125,5699.90283203125,56.5641110511791,20.5533855587829,22.529354,0,0,0,40,4449,99.92645,5689.81103515625,,,,,,,,,,,,,0,,,,-0.00245,,,,,,99.9914169,,,,
,31249357.07,99.9931641,351.380813598633,6.47107781702959E-5,3.2774942477795E-7,1,0.999253354069792,40.0298881530762,1.98354031188053,20.7800008356571,0.000730823847126419,0.000128511221290236,0.25,4.86655378793201E-9,6.50746812674865E-5,2.06373286088517E-7,99.9931641,99.9931641,341.305206298828,361.456420898438,56.9885353371214,20.5532820910984,22.909004,0,0,0,40,4449,99.93265,351.380813598633,,,,,,,,,,,,,0,,,,0.0049,,,,,,99.9931641,,,,
,31249464.82,99.997612,-5030.00610351562,6.51219654753952E-5,4.37956563594863E-7,1,0.999253354069792,40.0298881530762,1.98352843609326,20.7800008356571,0.000736012706810758,0.000126224489239857,0.25,-2.69120075686357E-7,6.54893742112871E-5,-6.86346604240251E-8,99.997612,99.997612,-5037.5625,-5022.44970703125,57.0198004778906,20.5561725757428,23.288654,0,0,0,40,4449,99.93545,-5030.00610351562,,,,,,,,,,,,,0,,,,-0.0049,,,,,,99.997612,,,,
,31249556.225,100.002388,-9601.65673828125,5.12497908535494E-5,7.37307651103525E-7,1,0.999253354069792,40.0298881530762,1.98370301752358,20.7800008356571,0.000579239316623797,9.95808036044528E-5,0.25,-1.90240000035182E-7,5.15391834092345E-5,-3.30475482426049E-8,100.002388,100.002388,-9606.8408203125,-9596.47265625,57.4106147375061,20.5533899161574,22.909004,0,0,0,40,4449,99.9321,-9601.65673828125,,,,,,,,,,,,,0,,,,-0.00245,,,,,,100.002388,,,,
,31249653.54,100.0055771,-14464.1909179687,2.29082044063409E-5,7.67024088697847E-7,1,0.999253354069792,40.0298881530762,1.98355019033072,20.7800008356571,0.000261755270563376,2.82466311225671E-5,0.25,-1.52454407944509E-6,2.30421446006826E-5,-1.46276471049515E-6,100.0055771,100.0055771,-14469.0244140625,-14459.357421875,57.1135959001984,20.5531898129585,23.288654,0,0,0,40,4449,99.9228,-14464.1909179687,,,,,,,,,,,,,0,,,,0,,,,,,100.0055771,,,,
,31249746.59,100.0104523,-19113.21484375,6.90751466374684E-6,7.89992295917053E-7,1,0.999253354069792,40.0298881530762,1.98356463269525,20.7800008356571,8.24896110925341E-5,-1.17519807483035E-5,0.25,-2.25422216287325E-6,6.95342823924628E-6,-2.24584563421231E-6,100.0104523,100.0104523,-19115.4375,-19110.9921875,56.6016292201021,20.5523604217438,22.909004,0,0,0,40,4449,99.91335,-19113.21484375,,,,,,,,,,,,,0,,,,-0.0049,,,,,,100.0104523,,,,
,31249849.87,100.0089111,-24278.4287109375,8.31476539118E-6,9.32034658170073E-7,1,0.999253354069792,40.0298881530762,1.98361133426083,20.7800008356571,9.82131275989288E-5,-7.97457859285929E-6,0.25,-2.16685370618451E-6,8.36839183020909E-6,-2.15385663517113E-6,100.0089111,100.0089111,-24283.6875,-24273.169921875,56.966649738583,20.5557030649614,23.288654,0,0,0,40,4449,99.9069,-24278.4287109375,,,,,,,,,,,,,0,,,,0,,,,,,100.0089111,,,,
,31249950.325,100.0112839,-29295.8896484375,2.13609746112101E-5,1.45749062950737E-6,1,0.999253354069792,40.0298881530762,1.98360045853453,20.7800008356571,0.000244025056209653,2.66926033976242E-5,0.25,-1.3892193784161E-6,2.14862036620979E-5,-1.33260174697813E-6,100.0112839,100.0112839,-29301.03515625,-29290.744140625,57.2238055214099,20.5568560780924,22.909004,0,0,0,40,4449,99.8969,-29295.8896484375,,,,,,,,,,,,,0,,,,0,,,,,,100.0112839,,,,
,31250054.535,100.0102615,-34505.30078125,3.769069401711E-5,1.32075269411233E-6,1,0.999253354069792,40.0298881530762,1.98364823847025,20.7800008356571,0.000431942388777762,3.93816330225919E-5,0.25,-3.13378942466525E-6,3.79139814772653E-5,-3.03851785503663E-6,100.0102615,100.0102615,-34512.94140625,-34497.66015625,56.9674313671022,20.5552996668453,22.529354,0,0,0,40,4449,99.8806,-34505.30078125,,,,,,,,,,,,,0,,,,-0.00245,,,,,,100.0102615,,,,
,31250163.83,100.0098038,-39966.650390625,5.69847965328174E-5,1.56621689888475E-6,1,0.999253354069792,40.0298881530762,1.98374991651557,20.7800008356571,0.000650805722145023,7.25697654550664E-5,0.25,-3.58369820179616E-6,5.73193826231006E-5,-3.43435811643094E-6,100.0098038,100.0098038,-39974.01171875,-39959.2890625,56.7008960420445,20.5553254958317,22.909004,0,0,0,40,4449,99.87485,-39966.650390625,,,,,,,,,,,,,0,,,,0.00245,,,,,,100.0098038,,,,
,31250276.045,100.0099792,-45574.61328125,7.55276282662685E-5,1.34503530050438E-6,1,0.999253354069792,40.0298881530762,1.98377913387597,20.7800008356571,0.000864993544154531,8.25374555912629E-5,0.25,-5.95641329900495E-6,7.59752746971387E-5,-5.76705782517202E-6,100.0099792,100.0099792,-45576.9609375,-45572.265625,57.0221453634483,20.5540456581845,23.288654,0,0,0,40,4449,99.8642,-45574.61328125,,,,,,,,,,,,,0,,,,-0.0049,,,,,,100.0099792,,,,
,31250381.39,100.0099869,-50838.716796875,9.43116828835175E-5,1.67025966203005E-6,1,0.999253354069792,40.0298881530762,1.98364212877244,20.7800008356571,0.00107475794843838,0.000133243507541527,0.25,-4.76357274726229E-6,9.48635102174694E-5,-4.51392148879545E-6,100.0099869,100.0099869,-50848.76171875,-50828.671875,57.0831123879483,20.5583592612099,23.668306,0,0,0,40,4449,99.8562,-50838.716796875,,,,,,,,,,,,,0,,,,-0.00245,,,,,,100.0099869,,,,
,31250483.205,100.0105438,-55928.2890625,0.000110429725496053,1.77380308959912E-6,1,0.999253354069792,40.0298881530762,1.98364171555907,20.7800008356571,0.00125346432805622,0.000184387622923382,0.25,-3.06376256909207E-6,0.000111069374664288,-2.75936840001289E-6,100.0105438,100.0105438,-55935.953125,-55920.625,56.8947399148137,20.556052473634,23.288654,0,0,0,40,4449,99.84345,-55928.2890625,,,,,,,,,,,,,0,,,,-0.00245,,,,,,100.0105438,,,,
,31250590.945,100.0089569,-61315.390625,0.000135685734900952,1.96109311216005E-6,1,0.999253354069792,40.0298881530762,1.98366650203612,20.7800008356571,0.0015473686805362,0.000185563016039597,0.25,-7.39109043029017E-6,0.000136483348916316,-7.04082853732753E-6,100.0089569,100.0089569,-61322.89453125,-61307.88671875,57.1034347294484,20.5556277138941,23.288654,0,0,0,40,4449,99.8372,-61315.390625,,,,,,,,,,,,,0,,,,-0.00245,,,,,,100.0089569,,,,
,31250702.455,100.0088806,-66887.5,0.000154897188164953,2.28005724466033E-6,1,0.999253354069792,40.0298881530762,1.98363022233577,20.7800008356571,0.00175585137745947,0.000272166833074263,0.25,-3.09307439917823E-6,0.000155793664969956,-2.66614998764909E-6,100.0088806,100.0088806,-66895.1796875,-66879.8203125,56.7978179784291,20.5594719722933,23.288654,0,0,0,40,4449,99.8252,-66887.5,,,,,,,,,,,,,0,,,,0.0049,,,,,,100.0088806,,,,
,31250814.785,100.008461,-72501.37109375,0.000174702156484342,1.87718595209452E-6,1,0.999253354069792,40.0298881530762,1.98358532922576,20.7800008356571,0.00198251426962381,0.000294500464984415,0.25,-4.58774866734246E-6,0.00017571797292617,-4.11657856535127E-6,100.008461,100.008461,-72511.484375,-72491.2578125,56.9134989992753,20.5587796713469,22.909004,0,0,0,40,4449,99.81805,-72501.37109375,,,,,,,,,,,,,0,,,,-0.00245,,,,,,100.008461,,,,
,31250927.03,100.0069504,-78107.59375,0.000196374335749484,2.23761084387086E-6,1,0.999253354069792,40.0298881530762,1.98371813778864,20.7800008356571,0.00222688919535635,0.000340872948036317,0.25,-4.28357208959722E-6,0.000197515437569895,-3.75346278893217E-6,100.0069504,100.0069504,-78112.4375,-78102.75,57.1417345268907,20.5601045104552,23.288654,0,0,0,40,4449,99.8101,-78107.59375,,,,,,,,,,,,,0,,,,-0.00245,,,,,,100.0069504,,,,
,31251041.46,100.0059738,-83829.44140625,0.00021839515522682,1.6484470079666E-6,1,0.999253354069792,40.0298881530762,1.98362980325456,20.7800008356571,0.00247527251426152,0.000386210243925949,0.25,-4.12803329199434E-6,0.00021966442380248,-3.53999106466885E-6,100.0059738,100.0059738,-83834.4765625,-83824.40625,57.3574639981984,20.5618025522436,23.288654,0,0,0,40,4449,99.8066,-83829.44140625,,,,,,,,,,,,,0,,,,0,,,,,,100.0059738,,,,
,31251150.49,100.0060959,-89278.62109375,0.000244576317329684,2.0994782814024E-6,1,0.999253354069792,40.0298881530762,1.98383003110157,20.7800008356571,0.00277557468052759,0.000413877699799031,0.25,-6.2706407143118E-6,0.000246004418868524,-5.62707655633707E-6,100.0060959,100.0060959,-89286.1328125,-89271.109375,56.9119357422368,20.5566420100822,22.909004,0,0,0,40,4449,99.8004,-89278.62109375,,,,,,,,,,,,,0,,,,0,,,,,,100.0060959,,,,
,31251281.02,100.0012741,-85157.90625,0.000232694326032644,2.22448749336788E-6,1,0.999253354069792,40.0298881530762,1.98404281480952,20.7800008356571,0.00264304154122466,0.000382090940135739,0.25,-7.00705148847394E-6,0.000234054470325447,-6.39671829499496E-6,100.0012741,100.0012741,-85165.53125,-85150.28125,57.1284468420637,20.5529681093605,23.668306,0,0,0,40,4449,99.79645,-85157.90625,,,,,,,,,,,,,0,,,,-0.00245,,,,,,100.0012741,,,,
,31251393.635,99.9970016,-79527.9453125,0.000205953009436039,2.53007814924161E-6,1,0.999253354069792,40.0298881530762,1.98434034576864,20.7800008356571,0.00234670999089787,0.000297804846920904,0.25,-9.78360882264496E-6,0.000207165165584124,-9.25920114359857E-6,99.9970016,99.9970016,-79532.875,-79523.015625,57.2871174314676,20.5515758805395,23.288654,0,0,0,40,4449,99.7999,-79527.9453125,,,,,,,,,,,,,0,,,,0.00245,,,,,,99.9970016,,,,
,31251507.59,99.9964905,-73831.59765625,0.000184965283939401,1.43409248177167E-6,1,0.999253354069792,40.0298881530762,1.98395734008719,20.7800008356571,0.00210819101734383,0.000261537558701683,0.25,-9.31029027399162E-6,0.000186053829826592,-8.83791926859484E-6,99.9964905,99.9964905,-73836.4296875,-73826.765625,57.1331366131791,20.5547687098064,23.288654,0,0,0,40,4449,99.8038,-73831.59765625,,,,,,,,,,,,,0,,,,0,,,,,,99.9964905,,,,
,31251620.015,99.9954834,-68215.1640625,0.000164324406900632,1.92283490698553E-6,1,0.999253354069792,40.0298881530762,1.98369831353067,20.7800008356571,0.00187140464524873,0.000239598699309575,0.25,-7.63084455018283E-6,0.000165288260753557,-7.20364434269651E-6,99.9953842,99.9955826,-68225.09375,-68205.234375,57.3605905122753,20.5554890915798,22.909004,0,0,0,40,4449,99.80735,-68215.1640625,,,,,,,,,,,,,0,,,,0,,,,,,99.9954834,,,,
,31251732.055,99.9959869,-62616.14453125,0.000140121110855102,1.50291624413103E-6,1,0.999253354069792,40.0298881530762,1.98381023297355,20.7800008356571,0.00159535492883115,0.000207072540820373,0.25,-6.26622569831472E-6,0.000140941106121749,-5.89730304142017E-6,99.9959869,99.9959869,-62623.953125,-62608.3359375,56.7126204698329,20.5510963625488,23.288654,0,0,0,40,4449,99.8131,-62616.14453125,,,,,,,,,,,,,0,,,,-0.00245,,,,,,99.9959869,,,,
,31251846.715,99.9957962,-56883.419921875,0.00011461675584706,1.36259586946976E-6,1,0.999253354069792,40.0298881530762,1.98371729661432,20.7800008356571,0.00131337277947946,0.000121135603427139,0.25,-9.39855175565143E-6,0.000115298930538088,-9.11847021618062E-6,99.9957962,99.9957962,-56885.546875,-56881.29296875,56.926005055583,20.5542740897379,23.288654,0,0,0,40,4449,99.82015,-56883.419921875,,,,,,,,,,,,,0,,,,-0.0049,,,,,,99.9957962,,,,
,31251958.945,99.994751,-51277.2578125,9.5222789112784E-5,1.22675964299766E-6,1,0.999253354069792,40.0298881530762,1.98385722828141,20.7800008356571,0.00108919526805909,0.000112095637705134,0.25,-6.79677391387001E-6,9.57858182319586E-5,-6.55606857426434E-6,99.994751,99.994751,-51279.83203125,-51274.68359375,57.0924919301791,20.5523726510199,23.288654,0,0,0,40,4449,99.8241,-51277.2578125,,,,,,,,,,,,,0,,,,0,,,,,,99.994751,,,,
,31252071.375,99.9920197,-45658.001953125,7.6347322295163E-5,1.61633518669469E-6,1,0.999253354069792,40.0298881530762,1.9837540055522,20.7800008356571,0.000874891895924381,8.04637845516482E-5,0.25,-6.28393115854938E-6,7.68006011053852E-5,-6.0939267572002E-6,99.9920197,99.9920197,-45663.0390625,-45652.96484375,57.0323065341983,20.554100841115,23.288654,0,0,0,40,4449,99.8335,-45658.001953125,,,,,,,,,,,,,0,,,,-0.0049,,,,,,99.9920197,,,,
,31252184.355,99.991333,-40010.53515625,5.34611283319155E-5,1.80561879218209E-6,1,0.999253354069792,40.0298881530762,1.98405934629199,20.7800008356571,0.000611059211243252,6.57846021988566E-5,0.25,-3.56646366552964E-6,5.37756248834643E-5,-3.42743909954422E-6,99.991333,99.991333,-40015.51953125,-40005.55078125,57.1558038402368,20.5509857785526,23.288654,0,0,0,40,4449,99.8416,-40010.53515625,,,,,,,,,,,,,0,,,,0,,,,,,99.991333,,,,
,31252295.785,99.9927521,-34441.34765625,3.56460355141941E-5,1.31332309464324E-6,1,0.999253354069792,40.0298881530762,1.98420623041865,20.7800008356571,0.000410381023083854,2.72288879230451E-5,0.25,-3.85127624586055E-6,3.58598635641351E-5,-3.76614311378391E-6,99.9927521,99.9927521,-34448.859375,-34433.8359375,57.0377779338329,20.5475116456614,23.668306,0,0,0,40,4449,99.84995,-34441.34765625,,,,,,,,,,,,,0,,,,0.0049,,,,,,99.9927521,,,,
,31252407.12,99.9912949,-28879.8447265625,1.65440639750244E-5,1.39330048040627E-6,1,0.999253354069792,40.0298881530762,1.98447183634264,20.7800008356571,0.000194172711467657,-8.32796585424408E-6,0.25,-3.64336824277862E-6,1.6648798874193E-5,-3.61400371561742E-6,99.9912949,99.9912949,-28892.228515625,-28867.4609375,57.1104693861214,20.544955193275,23.288654,0,0,0,40,4449,99.8606,-28879.8447265625,,,,,,,,,,,,,0,,,,0.00245,,,,,,99.9912949,,,,
,31252518.125,99.9896393,-23330.41015625,-2.48001703025806E-6,1.08209242540209E-6,1,0.999253354069792,40.0298881530762,1.98440237556483,20.7800008356571,-2.20840667405169E-5,-3.87189728308813E-5,0.25,-2.99102612326567E-6,-2.48494120233532E-6,-3.01549006628803E-6,99.9896393,99.9896393,-23335.40234375,-23325.41796875,57.4199942797368,20.5404763401191,23.288654,0,0,0,40,4449,99.8675,-23330.41015625,,,,,,,,,,,,,0,,,,-0.00245,,,,,,99.9896393,,,,
,31252630.075,99.9916191,-17735.7568359375,-1.93289663807212E-5,9.66699539978657E-7,1,0.999253354069792,40.0298881530762,1.98445083453576,20.7800008356571,-0.000214063736339017,-6.30596323018205E-5,0.25,-2.18452452131376E-6,-1.94314210157773E-5,-2.25606882018054E-6,99.991539,99.9916992,-17748.314453125,-17723.19921875,56.9627415959868,20.5388347505517,22.909004,0,0,0,40,4449,99.87735,-17735.7568359375,,,,,,,,,,,,,0,,,,-0.00245,,,,,,99.9916191,,,,
,31252740.11,99.9899216,-12234.150390625,-3.6957091994694E-5,6.86983128398598E-7,1,0.999253354069792,40.0298881530762,1.98407564168447,20.7800008356571,-0.000413825142250179,-9.43018101159085E-5,0.25,-1.85289817357563E-6,-3.7159760634439E-5,-1.97723811759902E-6,99.9899216,99.9899216,-12241.85546875,-12226.4453125,57.1534589546791,20.5433646890872,23.288654,0,0,0,40,4449,99.889,-12234.150390625,,,,,,,,,,,,,0,,,,0.00245,,,,,,99.9899216,,,,
,31252851.98,99.9896088,-6643.72900390625,-5.24201707933952E-5,6.07330560670101E-7,1,0.999253354069792,40.0298881530762,1.983908104527,20.7800008356571,-0.000589795159389989,-0.000117385451148296,0.25,-1.17886625984864E-6,-5.27116658670092E-5,-1.34796349383349E-6,99.9896088,99.9896088,-6653.6591796875,-6633.798828125,56.9314764552176,20.5459445046655,22.909004,0,0,0,40,4449,99.898,-6643.72900390625,,,,,,,,,,,,,0,,,,0,,,,,,99.9896088,,,,
,31252962.71,99.99258045,-1107.68658447266,-6.3283694700415E-5,3.94318264256432E-7,1,0.999253354069792,40.0298881530762,1.98377600759799,20.7800008356571,-0.000713489797733874,-0.00013307675900334,0.25,-6.58606805826916E-7,-6.36375343239162E-5,-8.593535384655E-7,99.9924927,99.9926682,-1115.31396484375,-1100.05920410156,57.1565854687561,20.5491853672232,22.909004,0,0,0,40,4449,99.90405,-1107.68658447266,,,,,,,,,,,,,0,,,,0.00245,,,,,,99.99258045,,,,
,31253074.525,99.9963226,4476.28686523438,-6.50598003302441E-5,3.86767377273968E-7,1,0.999253354069792,40.0298881530762,1.9839035414238,20.7800008356571,-0.000734956597303197,-0.000128888056211724,0.25,2.45980131574865E-8,-6.54260101544324E-5,-1.77272057028804E-7,99.9963226,99.9963226,4473.76953125,4478.80419921875,56.7423223535637,20.548722013189,23.288654,0,0,0,40,4449,99.9075,4476.28686523438,,,,,,,,,,,,,0,,,,0,,,,,,99.9963226,,,,
,31253187.595,100.0019455,10129.3901367187,-4.75323259560747E-5,8.30448385648645E-7,1,0.999253354069792,40.0298881530762,1.98372262320085,20.7800008356571,-0.000538181949965008,-8.69337854428704E-5,0.25,6.56705952484081E-7,-4.78022138021365E-5,5.13629290739613E-7,100.0019455,100.0019455,10116.9072265625,10141.873046875,56.5758354789675,20.5498295578236,23.288654,0,0,0,40,4449,99.9033,10129.3901367187,,,,,,,,,,,,,0,,,,0,,,,,,100.0019455,,,,
,31253298.485,100.0060577,15671.6616210938,-1.71859439896204E-5,9.13659726186175E-7,1,0.999253354069792,40.0298881530762,1.98377716744397,20.7800008356571,-0.00019512055515238,-2.84336890296618E-5,0.25,5.02671402984828E-7,-1.72844775172633E-5,4.52754830213688E-7,100.0060577,100.0060577,15659.048828125,15684.2744140625,56.8689461736791,20.5487646650297,22.909004,0,0,0,40,4449,99.89555,15671.6616210938,,,,,,,,,,,,,0,,,,0,,,,,,100.0060577,,,,
,31253410.515,100.0090027,21271.03125,-5.57813375496732E-6,1.25337274687649E-6,1,0.999253354069792,40.0298881530762,1.98414042123504,20.7800008356571,-6.28250565114041E-5,-1.2177937320573E-5,0.25,-9.78403873325573E-8,-5.60936519651282E-6,-1.15406359989475E-7,100.0090027,100.0090027,21266.03125,21276.03125,56.9150622563137,20.5435496319867,23.668306,0,0,0,40,4449,99.8853,21271.03125,,,,,,,,,,,,,0,,,,0.00245,,,,,,100.0090027,,,,
,31253522.94,100.0101471,26891.3623046875,-1.40480813751751E-5,1.63498595077133E-6,1,0.999253354069792,40.0298881530762,1.98443394957086,20.7800008356571,-0.000159893148495014,-2.12848827432224E-5,0.25,5.8423715829994E-7,-1.4129385558489E-5,5.4498768328692E-7,100.0101471,100.0101471,26884.009765625,26898.71484375,57.0182372208522,20.5390835604285,23.288654,0,0,0,40,4449,99.8746,26891.3623046875,,,,,,,,,,,,,0,,,,0,,,,,,100.0101471,,,,
,31253637.335,100.0098267,32608.365234375,-2.94812618212145E-5,1.79560946458757E-6,1,0.999253354069792,40.0298881530762,1.98459480443784,20.7800008356571,-0.000339935690720156,-1.98766623525704E-5,0.25,3.41968116546408E-6,-2.96587405507397E-5,3.35039968178506E-6,100.0098267,100.0098267,32601.158203125,32615.572265625,57.0690430746022,20.5367446132491,23.288654,0,0,0,40,4449,99.86395,32608.365234375,,,,,,,,,,,,,0,,,,0.00245,,,,,,100.0098267,,,,
,31253750.42,100.0103912,38258.123046875,-5.08349328255421E-5,1.94184125440336E-6,1,0.999253354069792,40.0298881530762,1.98437172090312,20.7800008356571,-0.000580555088723779,-6.58221774903158E-5,0.25,3.10308990581959E-6,-5.11329771346753E-5,2.9689170197039E-6,100.0103912,100.0103912,38252.7578125,38263.48828125,57.0104209356599,20.5398798748539,23.288654,0,0,0,40,4449,99.8518,38258.123046875,,,,,,,,,,,,,0,,,,0,,,,,,100.0103912,,,,
,31253864.99,100.0112534,43985.021484375,-7.09421147185036E-5,1.58624973488275E-6,1,0.999253354069792,40.0298881530762,1.98413162212117,20.7800008356571,-0.000804609530068347,-0.000123113157501836,0.25,1.56155284632242E-6,-7.13504392775824E-5,1.36019201883145E-6,100.0112534,100.0112534,43975.03515625,43995.0078125,57.4176493941791,20.5405072536705,23.668306,0,0,0,40,4449,99.8424,43985.021484375,,,,,,,,,,,,,0,,,,-0.0049,,,,,,100.0112534,,,,
,31253979.545,100.0089645,49710.494140625,-9.3759444914116E-5,1.77771620495535E-6,1,0.999253354069792,40.0298881530762,1.98379019388006,20.7800008356571,-0.0010666197827088,-0.000143400716684822,0.25,3.7688057484647E-6,-9.43049959327344E-5,3.51455663512154E-6,100.0089645,100.0089645,49707.71875,49713.26953125,56.9385111118906,20.5469726934788,23.288654,0,0,0,40,4449,99.83315,49710.494140625,,,,,,,,,,,,,0,,,,0.00245,,,,,,100.0089645,,,,
,31254093.095,100.0089188,55387.595703125,-0.00011327480156271,1.76854319529094E-6,1,0.999253354069792,40.0298881530762,1.98384943397496,20.7800008356571,-0.00128601919813883,-0.000188393822070062,0.25,3.21059334711043E-6,-0.000113930989719729,2.89838251265728E-6,100.0089188,100.0089188,55379.90625,55395.28515625,56.7368509539291,20.5430517546358,23.288654,0,0,0,40,4449,99.8238,55387.595703125,,,,,,,,,,,,,0,,,,0,,,,,,100.0089188,,,,
,31254206.02,100.0087738,61032.212890625,-0.000132975191739746,1.9824064414029E-6,1,0.999253354069792,40.0298881530762,1.9839324935384,20.7800008356571,-0.00150452432152948,-0.000250957524664161,0.25,1.12924919063302E-6,-0.000133739062595108,7.50712011812815E-7,100.0087738,100.0087738,61022.23046875,61042.1953125,57.1276652135445,20.5429285948908,23.288654,0,0,0,40,4449,99.81515,61032.212890625,,,,,,,,,,,,,0,,,,0,,,,,,100.0087738,,,,
,31254319.85,100.0075874,66719.6953125,-0.000159704455819402,1.66702131571755E-6,1,0.999253354069792,40.0298881530762,1.98411599813987,20.7800008356571,-0.00180642154828014,-0.000305437178218986,0.25,9.98063843100834E-7,-0.00016062236925086,5.45090401480554E-7,100.0073318,100.007843,66709.6640625,66729.7265625,56.8736359447945,20.5395091319471,23.288654,0,0,0,40,4449,99.8072,66719.6953125,,,,,,,,,,,,,0,,,,-0.00245,,,,,,100.0075874,,,,
,31254433.855,100.0082092,72419.875,-0.000178940012161681,2.29736911949567E-6,1,0.999253354069792,40.0298881530762,1.98396697151362,20.7800008356571,-0.00202302161144002,-0.000347033782653484,0.25,6.86674320100086E-7,-0.000179968950767264,1.80815623826964E-7,100.0082092,100.0082092,72412.578125,72427.171875,56.7118388413137,20.5436234857858,22.909004,0,0,0,40,4449,99.79735,72419.875,,,,,,,,,,,,,0,,,,0.00245,,,,,,100.0082092,,,,
,31254550.04,100.0069504,78227.3671875,-0.000197216875825127,1.72188536502519E-6,1,0.999253354069792,40.0298881530762,1.98402586453802,20.7800008356571,-0.00223424369342621,-0.000356810064506586,0.25,3.02540203229541E-6,-0.000198359235518745,2.48559798200725E-6,100.0069504,100.0069504,78215.0234375,78239.7109375,56.8970848003714,20.5403428379615,23.668306,0,0,0,40,4449,99.78985,78227.3671875,,,,,,,,,,,,,0,,,,0,,,,,,100.0069504,,,,
,31254665.735,100.007309,84010.48828125,-0.000221555938126766,2.09866078893349E-6,1,0.999253354069792,40.0298881530762,1.98414946814768,20.7800008356571,-0.00250715533023823,-0.000417941294745709,0.25,1.88296729730783E-6,-0.000222837084034823,1.27306673845665E-6,100.007309,100.007309,84003.1171875,84017.859375,57.495030617583,20.5376931390698,23.288654,0,0,0,40,4449,99.7819,84010.48828125,,,,,,,,,,,,,0,,,,0.00245,,,,,,100.007309,,,,
,31254773.895,100.0056,89416.0625,-0.000242751313605319,2.06244792293576E-6,1,0.999253354069792,40.0298881530762,1.98390575918235,20.7800008356571,-0.00275566956702686,-0.000406780928805778,0.25,6.58004196208922E-6,-0.000244169721062482,5.94325338380876E-6,100.0056,100.0056,89411.015625,89421.109375,56.8587850029291,20.5399457882938,22.909004,0,0,0,40,4449,99.7796,89416.0625,,,,,,,,,,,,,0,,,,-0.00245,,,,,,100.0056,,,,
,31254904.07,100.0001297,85069.3984375,-0.000226724713056033,2.07240357024271E-6,1,0.999253354069792,40.0298881530762,1.98374051239683,20.7800008356571,-0.00256169190505505,-0.000447292551417256,0.25,1.83506241182269E-7,-0.00022803128867693,-4.49695864139633E-7,100.0001297,100.0001297,85059.5078125,85079.2890625,56.8361177758714,20.5442821534837,23.288654,0,0,0,40,4449,99.7794,85069.3984375,,,,,,,,,,,,,0,,,,0,,,,,,100.0001297,,,,
,31255018.1,99.9970551,79367.61328125,-0.000202483622452702,1.71216859747043E-6,1,0.999253354069792,40.0298881530762,1.98388152229864,20.7800008356571,-0.0022966461583581,-0.00034983677391423,0.25,4.56377211622207E-6,-0.00020366099459686,4.01883217333829E-6,99.9970551,99.9970551,79360.0546875,79375.171875,56.8587850029291,20.540108788022,22.909004,0,0,0,40,4449,99.78275,79367.61328125,,,,,,,,,,,,,0,,,,0,,,,,,99.9970551,,,,
,31255131.985,99.9971619,73674.578125,-0.000182959984939732,1.87777570253486E-6,1,0.999253354069792,40.0298881530762,1.9839748868568,20.7800008356571,-0.00206931621719387,-0.00035007823556258,0.25,1.12204081918198E-6,-0.000184013619294578,6.08067163072773E-7,99.9971619,99.9971619,73672.2421875,73676.9140625,56.5109603118714,20.5391904429142,22.909004,0,0,0,40,4449,99.7837,73674.578125,,,,,,,,,,,,,0,,,,-0.0049,,,,,,99.9971619,,,,
,31255245.84,99.9967575,67984.90234375,-0.000161171129566449,1.5807228981041E-6,1,0.999253354069792,40.0298881530762,1.98400522671289,20.7800008356571,-0.00182598843937342,-0.000290730177758451,0.25,2.55512424928644E-6,-0.000162102241509541,2.10757703193534E-6,99.9967575,99.9967575,67974.65625,67995.1484375,56.9213152844676,20.5398511012652,23.668306,0,0,0,40,4449,99.78955,67984.90234375,,,,,,,,,,,,,0,,,,0,,,,,,99.9967575,,,,
,31255356.85,99.9956284,62437.0625,-0.000140497067679009,1.75121773042988E-6,1,0.999253354069792,40.0298881530762,1.98392145676456,20.7800008356571,-0.00159773420155765,-0.00021895263913532,0.25,5.2818386092011E-6,-0.000141316286882599,4.90597177616689E-6,99.9956284,99.9956284,62432.01953125,62442.10546875,56.5219031111406,20.5405571847541,22.909004,0,0,0,40,4449,99.7953,62437.0625,,,,,,,,,,,,,0,,,,0,,,,,,99.9956284,,,,
,31255470.795,99.99640655,56739,-0.000118008308054829,1.94198217355502E-6,1,0.999253354069792,40.0298881530762,1.98401051138874,20.7800008356571,-0.00133639185289971,-0.000216069322805862,0.25,1.59279790587821E-6,-0.00011868705317103,1.2580677929091E-6,99.9963531,99.99646,56733.77734375,56744.22265625,56.445303516256,20.5409354234023,23.288654,0,0,0,40,4449,99.8012,56739,,,,,,,,,,,,,0,,,,-0.00245,,,,,,99.99640655,,,,
,31255581.8,99.993988,51191.705078125,-9.92147727079821E-5,1.79607235818305E-6,1,0.999253354069792,40.0298881530762,1.98386372927618,20.7800008356571,-0.00112441176587634,-0.000176301950322297,0.25,1.81427948746201E-6,-9.97858991273189E-5,1.53332272693252E-6,99.993988,99.993988,51186.77734375,51196.6328125,56.9744660237753,20.544810758687,22.909004,0,0,0,40,4449,99.8068,51191.705078125,,,,,,,,,,,,,0,,,,0,,,,,,99.993988,,,,
,31255695.35,99.9920731,45514.595703125,-7.62731798607271E-5,1.58135834448785E-6,1,0.999253354069792,40.0298881530762,1.98387531407341,20.7800008356571,-0.000868366655780899,-0.000112998153340014,0.25,3.39146494823009E-6,-7.67174364397652E-5,3.18509041364079E-6,99.9920731,99.9920731,45504.42578125,45524.765625,57.0627900464484,20.5441926907675,23.668306,0,0,0,40,4449,99.8138,45514.595703125,,,,,,,,,,,,,0,,,,0,,,,,,99.9920731,,,,
,31255807.99,99.9923325,39886.787109375,-5.62711814975331E-5,1.30636195192856E-6,1,0.999253354069792,40.0298881530762,1.9838553922267,20.7800008356571,-0.000640990120645996,-8.13313862027556E-5,0.25,2.6832504512014E-6,-5.65989847401668E-5,2.53074724764218E-6,99.9923325,99.9923325,39877.0625,39896.51171875,56.8220484625252,20.5438935758642,22.909004,0,0,0,40,4449,99.8218,39886.787109375,,,,,,,,,,,,,0,,,,-0.0049,,,,,,99.9923325,,,,
,31255920.8,99.9917603,34245.3203125,-3.6344503184421E-5,1.63014175863791E-6,1,0.999253354069792,40.0298881530762,1.9839040673829,20.7800008356571,-0.00041219875765941,-6.2841117404664E-5,0.25,8.21199303605289E-7,-3.65531753760985E-5,7.16714261971201E-7,99.9917603,99.9917603,34240.3828125,34250.2578125,57.0205821064099,20.5435928707127,22.909004,0,0,0,40,4449,99.83205,34245.3203125,,,,,,,,,,,,,0,,,,0.00245,,,,,,99.9917603,,,,
,31256033.37,99.9907913,28623.244140625,-1.72262278755293E-5,1.51220224054299E-6,1,0.999253354069792,40.0298881530762,1.98387450815283,20.7800008356571,-0.000199527885771651,-6.09110472535486E-6,0.25,2.48701053488443E-6,-1.73313222592709E-5,2.44899764168798E-6,99.9907913,99.9907913,28613.38671875,28633.1015625,56.7001144135252,20.5437381521205,23.288654,0,0,0,40,4449,99.842,28623.244140625,,,,,,,,,,,,,0,,,,0.0049,,,,,,99.9907913,,,,
,31256145.385,99.9894714,23023.609375,2.5117113678245E-6,1.2100561593723E-6,1,0.999253354069792,40.0298881530762,1.98412247022685,20.7800008356571,2.50220466347645E-5,2.40752886732469E-5,0.25,1.68972979141052E-6,2.52076936125095E-6,1.7069337691332E-6,99.9894714,99.9894714,23020.9765625,23026.2421875,57.0112025641791,20.5428138140992,23.288654,0,0,0,40,4449,99.8516,23023.609375,,,,,,,,,,,,,0,,,,0,,,,,,99.9894714,,,,
,31256255.56,99.991703,17516.2734375,1.97027868456905E-5,1.37867448157357E-6,1,0.999253354069792,40.0298881530762,1.98428427174775,20.7800008356571,0.000220461936157027,5.13218143376479E-5,0.25,1.08035259819108E-6,1.98107188756695E-5,1.14683730045491E-6,99.9916992,99.9917068,17508.8125,17523.734375,57.0010413934291,20.541665901164,23.288654,0,0,0,40,4449,99.86245,17516.2734375,,,,,,,,,,,,,0,,,,0,,,,,,99.991703,,,,
,31256365.79,99.9907379,12006.9243164062,3.5993305923752E-5,5.98376633303188E-7,1,0.999253354069792,40.0298881530762,1.98429472610725,20.7800008356571,0.000404780057768594,8.21516424383204E-5,0.25,9.45917977130857E-7,3.61933025795519E-5,1.06223996847105E-6,99.9907379,99.9907379,12001.9541015625,12011.89453125,57.3129111726022,20.5420104309378,23.668306,0,0,0,40,4449,99.86865,12006.9243164062,,,,,,,,,,,,,0,,,,0,,,,,,99.9907379,,,,
,31256477.985,99.9920731,6399.4716796875,5.24124575565105E-5,5.2716210938458E-7,1,0.999253354069792,40.0298881530762,1.98414223481957,20.7800008356571,0.000590736528860941,0.000111906725053719,0.25,6.94008119570194E-7,5.27053672611985E-5,8.60439730688552E-7,99.9920731,99.9920731,6394.31591796875,6404.62744140625,57.0737328457176,20.5445427947496,23.668306,0,0,0,40,4449,99.88035,6399.4716796875,,,,,,,,,,,,,0,,,,-0.00245,,,,,,99.9920731,,,,
,31256589.205,99.9917526,841.320190429688,6.39433260062103E-5,3.06918789217393E-7,1,0.999253354069792,40.0298881530762,1.98427304972294,20.7800008356571,0.000722493530672836,0.000126561237620456,0.25,-3.69449465496674E-8,6.43029990403466E-5,1.62037371070594E-7,99.9917526,99.9917526,831.310546875,851.329833984375,56.8056342636214,20.5430279388436,23.288654,0,0,0,40,4449,99.88755,841.320190429688,,,,,,,,,,,,,0,,,,0,,,,,,99.9917526,,,,
,31256606.89,99.9926987,-0.342534899711609,6.56513426181776E-5,2.99831455418674E-7,1,0.999253354069792,40.0298881530762,1.98421505138687,20.7800008356571,0.000742288293067812,0.000126996225385605,0.25,-2.9842253916673E-7,6.60213942669093E-5,-9.55045148857776E-8,99.9926987,99.9926987,-0.380594313144684,-0.304475486278534,56.5133051974291,20.5437088391987,23.288654,0,0,0,40,4417,99.8896,-0.342534899711609,,,,,,,,,,,,,0,,,,-0.0049,,,,,,99.9926987,,,,