File: data/doubleLayers/dl_0-125/ppms/data/DD213_7_HYST_100OE_250K.DAT
[Header]
; VSM Data File (default extension .dat)
; Copyright (c) 2003-2013, Quantum Design, Inc. All rights reserved.
TITLE,
FILEOPENTIME,31282269.83,12/29/2018,9:33 am
BYAPP,VSM,2.0,2.0
INFO,PPMS VSM Option Release 1.4.10 Build 1,APPNAME
INFO,Quantum Design Linear Motor Servo Controller,MOTOR_MODULE_NAME
INFO,3101-100 M1,MOTOR_HW_VERSION
INFO,MMC1014,MOTOR_SERIAL_NUMBER
INFO,SRV No X-over 01.03.11,MOTOR_SOFTWARE_VERSION
INFO,Quantum Design VSM Detection Module,VSM_MODULE_NAME
INFO,3101-150 F0,VSM_HW_VERSION
INFO,VSM707,VSM_SERIAL_NUMBER
INFO,VSM No X-over 01.02.05 May 20 2008 13:51:47,VSM_SOFTWARE_VERSION
INFO,704,PREAMP_SERIAL_NUMBER
INFO,822,COIL_SERIAL_NUMBER
INFO,0,MOMENT_UNITS
INFO,CoFe2O4,SAMPLE_MATERIAL
INFO,Double Layer thin concentration,SAMPLE_COMMENT
INFO,29.55,SAMPLE_MASS
INFO,,SAMPLE_VOLUME
INFO,,SAMPLE_MOLECULAR_WEIGHT
INFO,,SAMPLE_SIZE
INFO,,SAMPLE_SHAPE
DATATYPE,COMMENT,1
DATATYPE,TIME,2
STARTUPAXIS,X,2
STARTUPAXIS,Y1,5
[Data]
Comment,Time Stamp (sec),Temperature (K),Magnetic Field (Oe),Moment (emu),M. Std. Err. (emu),Transport Action,Averaging Time (sec),Frequency (Hz),Peak Amplitude (mm),Center Position (mm),Coil Signal' (mV),Coil Signal" (mV),Range (mV),M. Quad. Signal (emu),M. Raw' (emu),M. Raw" (emu),Min. Temperature (K),Max. Temperature (K),Min. Field (Oe),Max. Field (Oe),Mass (grams),Motor Lag (deg),Pressure (Torr),VSM Status (code),Motor Status (code),Measure Status (code),Measure Count,PPMS Status (code),System Temp. (K),System Field (Oe),Sample Position (deg),Bridge 1 Resistance (ohms),Bridge 1 Excitation (에),Bridge 2 Resistance (ohms),Bridge 2 Excitation (에),Bridge 3 Resistance (ohms),Bridge 3 Excitation (에),Bridge 4 Resistance (ohms),Bridge 4 Excitation (에),Signal 1 Vin (V),Signal 2 Vin (V),Digital Inputs (code),Drive 1 Iout (mA),Drive 1 Ipower (W),Drive 2 Iout (mA),Drive 2 Ipower (W),Pressure (),Map 20 (),Map 21 (),Map 22 (),Map 23 (),Map 24 (),Map 25 (),Map 26 (),Map 27 (),Map 28 (),Map 29 ()
,31282285.06,250.0021515,-0.411041855812073,,,2,,,,19.9099998170137,,,,,,,250.0021515,250.0021515,-0.411041855812073,-0.411041855812073,,,27.464817,,,,-99999999,4369,250.0464,-0.411041855812073,,,,,,,,,,,,,,,,,,,,,,,250.0021515,,,,
,31282424.405,249.99035645,4463.46997070313,4.72528339869077E-5,5.1424915528446E-7,1,0.999253354069792,40.0298881530762,1.99654222545035,19.8999997228384,0.00053480292810863,9.4808742950361E-5,0.25,1.76579962388721E-7,4.7335611911103E-5,2.15926055797681E-7,249.9902344,249.9904785,4431.09423828125,4495.845703125,55.8106211586405,20.5013539339549,27.464817,0,0,0,40,4449,250.06225,4463.46997070313,,,,,,,,,,,,,0,,,,0,,,,,,249.99035645,,,,
,31282519.475,249.98892975,9212.0986328125,4.13364432955553E-5,6.90519953442507E-7,1,0.999253354069792,40.0298881530762,1.99644328427565,19.8999997228384,0.000467010057887343,8.76028775686383E-5,0.25,5.66770116055269E-7,4.14085227349319E-5,6.01878493996773E-7,249.9888916,249.9889679,9182.1748046875,9242.0224609375,56.1639172493329,20.507034368118,27.464817,0,0,0,40,4449,250.07015,9212.0986328125,,,,,,,,,,,,,0,,,,0.00245,,,,,,249.98892975,,,,
,31282615.665,249.9884338,14022.2299804687,2.96020794115341E-5,8.42649361687745E-7,1,0.999253354069792,40.0298881530762,1.99645695228714,19.8999997228384,0.000335678081525632,5.5596168023043E-5,0.25,-2.24471746520129E-7,2.96542210190456E-5,-2.00464313483668E-7,249.9884338,249.9884338,13994.69140625,14049.7685546875,56.4820400566598,20.5098700498628,27.464817,0,0,0,40,4449,250.07975,14022.2299804687,,,,,,,,,,,,,0,,,,0.00245,,,,,,249.9884338,,,,
,31282712.51,249.9933167,18862.375,1.49023367478539E-5,1.19476357874008E-6,1,0.999253354069792,40.0298881530762,1.99641623242342,19.8999997228384,0.000164879131779948,5.16598345196333E-5,0.25,1.97733791164687E-6,1.49268639032632E-5,1.99307774647923E-6,249.9933167,249.9933167,18832.4921875,18892.2578125,56.5226847396598,20.5129463682057,27.464817,0,0,0,40,4449,250.0814,18862.375,,,,,,,,,,,,,0,,,,0.0049,,,,,,249.9933167,,,,
,31282810.22,249.9940338,23744.6591796875,1.13080458469612E-6,9.52982116471384E-7,1,0.999253354069792,40.0298881530762,1.99631614924199,19.8999997228384,1.02378523362546E-5,1.70251164500052E-5,0.25,1.30734400241317E-6,1.13171439235645E-6,1.3105684627455E-6,249.9940338,249.9940338,23739.75390625,23749.564453125,56.8243933480829,20.5158037801099,27.085165,0,0,0,40,4449,250.0852,23744.6591796875,,,,,,,,,,,,,0,,,,0,,,,,,249.9940338,,,,
,31282907.375,249.9966583,28599.98046875,-1.68543133893293E-5,1.1124790578829E-6,1,0.999253354069792,40.0298881530762,1.99645171173888,19.8999997228384,-0.000197545381123198,5.38475043181888E-6,0.25,3.39837651934915E-6,-1.68866871222865E-5,3.39050130216137E-6,249.9966583,249.9966583,28597.462890625,28602.498046875,56.6266413327175,20.5132758765609,27.464817,0,0,0,40,4449,250.0892,28599.98046875,,,,,,,,,,,,,0,,,,-0.0049,,,,,,249.9966583,,,,
,31283001.345,249.9994812,33297.765625,-3.50027739223267E-5,1.52250813474654E-6,1,0.999253354069792,40.0298881530762,1.99637257200336,19.8999997228384,-0.000405671658672308,-1.51805816124706E-5,0.25,4.72965094364093E-6,-3.50680910733777E-5,4.70924692146582E-6,249.9994812,249.9994812,33295.26171875,33300.26953125,56.6899532427752,20.5141567353697,27.464817,0,0,0,40,4449,250.0854,33297.765625,,,,,,,,,,,,,0,,,,0,,,,,,249.9994812,,,,
,31283095.065,250.0035553,37979.90234375,-5.1012810182814E-5,1.57832618797671E-6,1,0.999253354069792,40.0298881530762,1.99630643477233,19.8999997228384,-0.000581572075021977,-7.76670092241787E-5,0.25,1.98794886857169E-6,-5.11039770183331E-5,1.94965881024153E-6,250.0035553,250.0035553,37977.28125,37982.5234375,56.3866813773137,20.5180068393798,27.464817,0,0,0,40,4449,250.0847,37979.90234375,,,,,,,,,,,,,0,,,,0,,,,,,250.0035553,,,,
,31283189.115,250.003418,42682.61328125,-6.51978365776979E-5,1.83644003137323E-6,1,0.999253354069792,40.0298881530762,1.99631444013265,19.8999997228384,-0.000747943954832947,-7.24362046761927E-5,0.25,4.90977270209022E-6,-6.53162971767822E-5,4.86506754000109E-6,250.003418,250.003418,42660.265625,42704.9609375,56.5015807696406,20.5163755805703,27.464817,0,0,0,40,4449,250.08245,42682.61328125,,,,,,,,,,,,,0,,,,0.0049,,,,,,250.003418,,,,
,31283283.63,250.0053711,47405.869140625,-8.02213282448731E-5,1.99764073170782E-6,1,0.999253354069792,40.0298881530762,1.99612348148508,19.8999997228384,-0.000916510175726915,-0.000110443468444526,0.25,4.15779170511223E-6,-8.0365545109745E-5,4.09957057925474E-6,250.0046997,250.0060425,47373.18359375,47438.5546875,56.4710972573906,20.5175151643227,27.464817,0,0,0,40,4449,250.076,47405.869140625,,,,,,,,,,,,,0,,,,-0.00245,,,,,,250.0053711,,,,
,31283377.11,250.0065155,52078.30859375,-0.000103939216572934,2.24571858622194E-6,1,0.999253354069792,40.0298881530762,1.99608624391633,19.8999997228384,-0.00119513009164814,-9.88672354986533E-5,0.25,9.29295245910825E-6,-0.000104129260376864,9.22449478203806E-6,250.0065155,250.0065155,52076.16015625,52080.45703125,56.4695340003521,20.5183590797599,27.085165,0,0,0,40,4449,250.07165,52078.30859375,,,,,,,,,,,,,0,,,,0,,,,,,250.0065155,,,,
,31283471.07,250.00938415,56773.51171875,-0.00012089771747818,2.41070335620712E-6,1,0.999253354069792,40.0298881530762,1.99618218966134,19.8999997228384,-0.00138522330869614,-0.000143636251065102,0.25,8.28037360741782E-6,-0.000121116699533758,8.19644812980324E-6,250.00914,250.0096283,56743.4765625,56803.546875,56.7173102409483,20.5147838828688,27.464817,0,0,0,40,4449,250.0644,56773.51171875,,,,,,,,,,,,,0,,,,0,,,,,,250.00938415,,,,
,31283565.615,250.0080414,61500.91796875,-0.000140015463181571,2.77220409471669E-6,1,0.999253354069792,40.0298881530762,1.99614230529158,19.8999997228384,-0.00159853370424294,-0.000199254683849556,0.25,6.68331450876611E-6,-0.000140266723163655,6.58118063473656E-6,250.0080414,250.0080414,61470.97265625,61530.86328125,56.8431524325445,20.5165475695741,26.705515,0,0,0,40,4449,250.0527,61500.91796875,,,,,,,,,,,,,0,,,,0.00245,,,,,,250.0080414,,,,
,31283660.77,250.0107269,66254.30078125,-0.000156615912128207,2.19840909126912E-6,1,0.999253354069792,40.0298881530762,1.99604124784057,19.8999997228384,-0.00179003528593928,-0.00021096898995001,0.25,8.52640409002967E-6,-0.000156897812121076,8.41419849532822E-6,250.0107269,250.0107269,66229.421875,66279.1796875,56.6860451001791,20.5171435154845,27.464817,0,0,0,40,4449,250.0501,66254.30078125,,,,,,,,,,,,,0,,,,-0.00245,,,,,,250.0107269,,,,
,31283756.54,250.00949095,71041.9609375,-0.000171225949176817,3.29056607516184E-6,1,0.999253354069792,40.0298881530762,1.99607469371596,19.8999997228384,-0.00196189757001694,-0.000202708210975757,0.25,1.17896172926887E-5,-0.000171536166596257,1.16714890429659E-5,250.0092468,250.0097351,71011.9296875,71071.9921875,56.7595181809868,20.513675099401,27.464817,0,0,0,40,4449,250.04025,71041.9609375,,,,,,,,,,,,,0,,,,-0.00245,,,,,,250.00949095,,,,
,31283851,250.01145935,75762.74609375,-0.000191448012112695,2.40001427611382E-6,1,0.999253354069792,40.0298881530762,1.99606299903744,19.8999997228384,-0.00219111816842492,-0.000240893081991801,0.25,1.19235762070182E-5,-0.00019179384413597,1.17895221231025E-5,250.0102234,250.0126953,75730.1015625,75795.390625,56.7055858131598,20.514047311576,27.464817,0,0,0,40,4449,250.0314,75762.74609375,,,,,,,,,,,,,0,,,,0.00245,,,,,,250.01145935,,,,
,31283945.93,250.0086212,80511.32421875,-0.000207394164143099,3.23334307447227E-6,1,0.999253354069792,40.0298881530762,1.99576558310914,19.8999997228384,-0.00236561682923051,-0.000305137086142852,0.25,9.01078178660595E-6,-0.000207765677302639,8.858962727948E-6,250.0086212,250.0086212,80478.9375,80543.7109375,56.5922496778714,20.5165697550182,27.464817,0,0,0,40,4449,250.022,80511.32421875,,,,,,,,,,,,,0,,,,0,,,,,,250.0086212,,,,
,31284041.52,250.0131149,85286.84765625,-0.000223987393267164,3.41942992025446E-6,1,0.999253354069792,40.0298881530762,1.99586398279572,19.8999997228384,-0.00255184478362956,-0.000347793564218308,0.25,8.12145867110938E-6,-0.000224387313803479,7.95494850503034E-6,250.0128021,250.0134277,85256.7578125,85316.9375,56.4922012274098,20.5151253693587,27.464817,0,0,0,40,4449,250.0146,85286.84765625,,,,,,,,,,,,,0,,,,0.00245,,,,,,250.0131149,,,,
,31284131.875,250.0123596,89805.05859375,-0.000240721139594567,3.07675391804374E-6,1,0.999253354069792,40.0298881530762,1.99585328388685,19.8999997228384,-0.00274315496755314,-0.000369855706055005,0.25,9.07407850977474E-6,-0.000241151243618583,8.89602135434467E-6,250.0123596,250.0123596,89780.1015625,89830.015625,56.7681160946983,20.5170289030418,27.085165,0,0,0,40,4449,249.9998,89805.05859375,,,,,,,,,,,,,0,,,,-0.00245,,,,,,250.0123596,,,,
,31284238.805,250.0036392,85594.28125,-0.000223258899454643,3.07050877459519E-6,1,0.999253354069792,40.0298881530762,1.99572533343701,19.8999997228384,-0.00255666062835466,-0.000270037881905029,0.25,1.48614472951685E-5,-0.000223663056019489,1.47073721016702E-5,250.0032806,250.0039978,85564.3203125,85624.2421875,56.5242479966983,20.5194578178818,27.464817,0,0,0,40,4449,249.99855,85594.28125,,,,,,,,,,,,,0,,,,0,,,,,,250.0036392,,,,
,31284334.575,249.9944153,80805.92578125,-0.000208766789643153,2.69296464130748E-6,1,0.999253354069792,40.0298881530762,1.99575913750279,19.8999997228384,-0.00238451187080001,-0.000288445667716036,0.25,1.07231064501008E-5,-0.000209142203426529,1.05731895720787E-5,249.9944153,249.9944153,80781.171875,80830.6796875,56.6368025034675,20.5215136905181,27.464817,0,0,0,40,4449,249.99975,80805.92578125,,,,,,,,,,,,,0,,,,0,,,,,,249.9944153,,,,
,31284430.23,249.9935608,76021.390625,-0.000190766649830909,2.92042375995542E-6,1,0.999253354069792,40.0298881530762,1.99570353597641,19.8999997228384,-0.00217715927731341,-0.000273365534675892,0.25,8.93337865547468E-6,-0.000191108986442437,8.79462952045331E-6,249.9934082,249.9937134,75991.4453125,76051.3359375,56.7524835243137,20.5202657628342,27.844467,0,0,0,40,4449,250.0109,76021.390625,,,,,,,,,,,,,0,,,,-0.00245,,,,,,249.9935608,,,,
,31284525.59,249.9937897,71255.83984375,-0.000174374421716994,2.75752644083648E-6,1,0.999253354069792,40.0298881530762,1.99570452753752,19.8999997228384,-0.00199073911944688,-0.000246079218920713,0.25,8.50133765844653E-6,-0.000174687598726013,8.3748791057603E-6,249.9937134,249.993866,71223.5546875,71288.125,56.7821854080445,20.5208690344783,27.464817,0,0,0,40,4449,250.0128,71255.83984375,,,,,,,,,,,,,0,,,,0,,,,,,249.9937897,,,,
,31284621.46,249.9893036,66462.01953125,-0.000154040895034975,2.10166066384085E-6,1,0.999253354069792,40.0298881530762,1.9955647749297,19.8999997228384,-0.00176036375028987,-0.000206534428747868,0.25,8.46738710442458E-6,-0.000154318343507906,8.35716806695026E-6,249.9893036,249.9893036,66429.53125,66494.5078125,56.7642079521022,20.5242183495734,27.464817,0,0,0,40,4449,250.02355,66462.01953125,,,,,,,,,,,,,0,,,,-0.00245,,,,,,249.9893036,,,,
,31284717.825,249.9907227,61646.6640625,-0.000132800602617282,2.90861666638353E-6,1,0.999253354069792,40.0298881530762,1.99587488018026,19.8999997228384,-0.0015158887399584,-0.000189431091140654,0.25,6.29761468332187E-6,-0.000133038963387174,6.20066596716191E-6,249.9907227,249.9907227,61641.76171875,61651.56640625,56.8376810329099,20.5218192968839,27.464817,0,0,0,40,4449,250.0251,61646.6640625,,,,,,,,,,,,,0,,,,0.0049,,,,,,249.9907227,,,,
,31284813.35,249.9922409,56868.501953125,-0.000118722663883878,2.06105339273582E-6,1,0.999253354069792,40.0298881530762,1.99586031744521,19.8999997228384,-0.00135762770026307,-0.000155249206686744,0.25,6.87551398397956E-6,-0.000118936755814789,6.7908919014344E-6,249.9919586,249.9925232,56838.2109375,56898.79296875,56.7634263235829,20.5200190396815,27.085165,0,0,0,40,4449,250.0451,56868.501953125,,,,,,,,,,,,,0,,,,0.0049,,,,,,249.9922409,,,,
,31284909.125,249.988678,52083.419921875,-0.00010278096897462,2.7031358185513E-6,1,0.999253354069792,40.0298881530762,1.99589816284716,19.8999997228384,-0.0011744774694505,-0.00013944363292744,0.25,5.50740322846991E-6,-0.00010296595696685,5.4332385556732E-6,249.988678,249.988678,52076.18359375,52090.65625,56.861911517006,20.5226872400202,27.844467,0,0,0,40,4449,250.0471,52083.419921875,,,,,,,,,,,,,0,,,,0,,,,,,249.988678,,,,
,31285005.935,249.9884796,47245.57421875,-8.13061177128604E-5,2.13473107812999E-6,1,0.999253354069792,40.0298881530762,1.99604210480536,19.8999997228384,-0.000926512504133429,-0.000125515832840502,0.25,3.01436798704016E-6,-8.14513533205459E-5,2.95324634989875E-6,249.9884796,249.9884796,47213.10546875,47278.04296875,56.9103724851983,20.5205870246452,27.464817,0,0,0,40,4449,250.05725,47245.57421875,,,,,,,,,,,,,0,,,,-0.00245,,,,,,249.9884796,,,,
,31285100.61,249.98825075,42513.009765625,-6.48821379700006E-5,1.78106163648329E-6,1,0.999253354069792,40.0298881530762,1.99605584486445,19.8999997228384,-0.000740588427949435,-9.30792373725686E-5,0.25,3.03107944361379E-6,-6.4998542565395E-5,2.98332926361977E-6,249.9879303,249.9885712,42490.7265625,42535.29296875,56.8290831191983,20.5223923063195,27.464817,0,0,0,40,4449,250.06505,42513.009765625,,,,,,,,,,,,,0,,,,-0.0049,,,,,,249.98825075,,,,
,31285196.445,249.9890289,37722.93359375,-4.81373056045957E-5,1.87978046064967E-6,1,0.999253354069792,40.0298881530762,1.99600644941763,19.8999997228384,-0.000547739799568939,-7.88813326293797E-5,0.25,1.38105739525297E-6,-4.82229527803714E-5,1.34405243078819E-6,249.9890289,249.9890289,37722.93359375,37722.93359375,56.6446187886598,20.5225869206185,27.464817,0,0,0,40,4449,250.0716,37722.93359375,,,,,,,,,,,,,0,,,,0.00245,,,,,,249.9890289,,,,
,31285293.635,249.9862366,32865.935546875,-3.03605687793213E-5,1.61345277718771E-6,1,0.999253354069792,40.0298881530762,1.99606941361639,19.8999997228384,-0.000348484425704516,-3.23940263471503E-5,0.25,2.40415038963664E-6,-3.04158448467732E-5,2.38346938251258E-6,249.9862366,249.9862366,32835.78125,32896.08984375,56.7024592990829,20.5217148996649,27.844467,0,0,0,40,4449,250.08305,32865.935546875,,,,,,,,,,,,,0,,,,-0.0049,,,,,,249.9862366,,,,
,31285389.86,249.9906006,28058.4287109375,-1.4793791503774E-5,1.22003313434477E-6,1,0.999253354069792,40.0298881530762,1.99605875355628,19.8999997228384,-0.00016880530048403,-2.154956628891E-5,0.25,6.62327477365504E-7,-1.48203049208213E-5,6.5134061009125E-7,249.9901276,249.9910736,28028.400390625,28088.45703125,56.9158438848329,20.52107312191,27.085165,0,0,0,40,4449,250.0959,28058.4287109375,,,,,,,,,,,,,0,,,,0.00245,,,,,,249.9906006,,,,
,31285484.16,249.9928284,23343.10546875,1.15297317029351E-6,7.34930464581616E-7,1,0.999253354069792,40.0298881530762,1.99602525450435,19.8999997228384,1.15370690452297E-5,1.10137769432776E-5,0.25,7.72786535225675E-7,1.15436144773971E-6,7.7509104546273E-7,249.9928284,249.9928284,23310.587890625,23375.623046875,56.9775925378522,20.5223793749863,27.085165,0,0,0,40,4449,250.0977,23343.10546875,,,,,,,,,,,,,0,,,,-0.00245,,,,,,249.9928284,,,,
,31285579.98,249.9932556,18553.087890625,1.46900908781579E-5,1.3387787529837E-6,1,0.999253354069792,40.0298881530762,1.99618448904008,19.8999997228384,0.000165414736474925,3.41854058967924E-5,0.25,4.71426088778245E-7,1.47154854359734E-5,4.84347903105556E-7,249.9925079,249.9940033,18523.10546875,18583.0703125,56.8642564025637,20.5215691050552,27.464817,0,0,0,40,4449,250.1022,18553.087890625,,,,,,,,,,,,,0,,,,-0.00245,,,,,,249.9932556,,,,
,31285674.915,249.9940567,13810.8681640625,2.96065030474607E-5,8.0627569195438E-7,1,0.999253354069792,40.0298881530762,1.99620958149918,19.8999997228384,0.000335453241018368,5.69542931807703E-5,0.25,-1.04717017878614E-7,2.96585478742117E-5,-8.04967964260747E-8,249.9939728,249.9941406,13785.87109375,13835.865234375,56.9541436822753,20.518124733038,27.464817,0,0,0,40,4449,250.09955,13810.8681640625,,,,,,,,,,,,,0,,,,0,,,,,,249.9940567,,,,
,31285770.97,249.9925308,9010.86865234375,4.21378313614817E-5,6.30607780220935E-7,1,0.999253354069792,40.0298881530762,1.99607384217799,19.8999997228384,0.000477609509733369,7.98884044808732E-5,0.25,-2.521658363185E-7,4.22119882408403E-5,-2.17838491653635E-7,249.9919281,249.9931335,8978.345703125,9043.3916015625,57.0416860764291,20.5224546861388,27.844467,0,0,0,40,4449,250.11055,9010.86865234375,,,,,,,,,,,,,0,,,,-0.0049,,,,,,249.9925308,,,,
,31285865.33,249.9914703,4292.52001953125,4.77517537867676E-5,4.82298718271619E-7,1,0.999253354069792,40.0298881530762,1.99596827817653,19.8999997228384,0.000541140933322433,9.0942362475925E-5,0.25,-2.49126709567249E-7,4.78357581162504E-5,-2.1012551607834E-7,249.9914703,249.9914703,4269.9482421875,4315.091796875,57.014329078256,20.5231542096586,27.464817,0,0,0,40,4449,250.1222,4292.52001953125,,,,,,,,,,,,,0,,,,0.00245,,,,,,249.9914703,,,,
,31285957.585,249.9933243,-318.41731262207,7.70657447659135E-6,4.01445179467205E-7,1,0.999253354069792,40.0298881530762,1.99582713052724,19.8999997228384,8.73321034120079E-5,1.46518665001952E-5,0.25,-4.23456219960823E-8,7.72013260164052E-6,-3.60508423287794E-8,249.9928894,249.9937592,-348.467376708984,-288.367248535156,56.9854088230445,20.5237703209617,27.844467,0,0,0,40,4449,250.12025,-318.41731262207,,,,,,,,,,,,,0,,,,0.00245,,,,,,249.9933243,,,,
,31286050.475,249.99617,-4957.95703125,-4.56227720025686E-5,5.5019083841766E-7,1,0.999253354069792,40.0298881530762,1.99564897861881,19.8999997228384,-0.000516562761212784,-8.90236270719746E-5,0.25,4.8168542385396E-8,-4.57028669578014E-5,1.05762734293551E-8,249.99617,249.99617,-4992.91650390625,-4922.99755859375,56.9494539111599,20.5275909577994,27.085165,0,0,0,40,4449,250.1134,-4957.95703125,,,,,,,,,,,,,0,,,,0,,,,,,249.99617,,,,
,31286146.905,250.00086215,-9779.02734375,-3.95596018071166E-5,6.16471984516414E-7,1,0.999253354069792,40.0298881530762,1.99577864816886,19.8999997228384,-0.000446499908078974,-8.55035346988236E-5,0.25,-6.9195664266126E-7,-3.96284441793176E-5,-7.2580625178193E-7,250.0007935,250.0009308,-9806.7294921875,-9751.3251953125,56.8181403199291,20.5262409432732,27.464817,0,0,0,40,4449,250.1197,-9779.02734375,,,,,,,,,,,,,0,,,,-0.00245,,,,,,250.00086215,,,,
,31286240.625,250.0020752,-14464.5498046875,-2.78708541720665E-5,8.08401777809385E-7,1,0.999253354069792,40.0298881530762,1.99572321982699,19.8999997228384,-0.000313795705576161,-6.46650335920847E-5,0.25,-8.78575225294009E-7,-2.79190352601901E-5,-9.03084910079183E-7,250.0020752,250.0020752,-14494.4951171875,-14434.6044921875,56.9979148793522,20.5259925674428,27.464817,0,0,0,40,4449,250.1149,-14464.5498046875,,,,,,,,,,,,,0,,,,0,,,,,,250.0020752,,,,
,31286336.535,250.00809475,-19254.130859375,-1.26651515638834E-5,9.47360380015449E-7,1,0.999253354069792,40.0298881530762,1.99589853196711,19.8999997228384,-0.000142514662271863,-2.99251724132489E-5,0.25,-4.4672681185514E-7,-1.26870060751977E-5,-4.57935759338831E-7,250.0079803,250.0082092,-19286.919921875,-19221.341796875,57.0659165605253,20.5259755812808,27.464817,0,0,0,40,4449,250.1079,-19254.130859375,,,,,,,,,,,,,0,,,,-0.00245,,,,,,250.00809475,,,,
,31286433.19,250.00566105,-24086.2646484375,3.54229720938074E-6,9.26876503242299E-7,1,0.999253354069792,40.0298881530762,1.9958883078488,19.8999997228384,4.27366603294504E-5,-8.22067826010656E-6,0.25,-1.34041098007673E-6,3.54961518627622E-6,-1.33985098579625E-6,250.0053101,250.006012,-24118.849609375,-24053.6796875,56.7790588939676,20.5285976975921,27.085165,0,0,0,40,4449,250.10525,-24086.2646484375,,,,,,,,,,,,,0,,,,-0.0049,,,,,,250.00566105,,,,
,31286529.425,250.0091324,-28896.853515625,1.84666817959093E-5,1.25317571776776E-6,1,0.999253354069792,40.0298881530762,1.99575972982689,19.8999997228384,0.000207193109603284,4.70296731531567E-5,0.25,9.51683977582024E-7,1.84983055237374E-5,9.68516541235151E-7,250.0089722,250.0092926,-28926.875,-28866.83203125,56.9979148793522,20.528167334491,27.464817,0,0,0,40,4449,250.09395,-28896.853515625,,,,,,,,,,,,,0,,,,-0.0049,,,,,,250.0091324,,,,
,31286624.455,250.0133209,-33645.892578125,3.45515622717589E-5,1.19689553368341E-6,1,0.999253354069792,40.0298881530762,1.99574512229237,19.8999997228384,0.000391283154909894,6.71011307661824E-5,0.25,-6.47544127277605E-8,3.46122449869082E-5,-3.65351137873221E-8,250.0130157,250.0136261,-33678.5703125,-33613.21484375,57.1143775287176,20.5281306795925,27.844467,0,0,0,40,4449,250.08485,-33645.892578125,,,,,,,,,,,,,0,,,,-0.00245,,,,,,250.0133209,,,,
,31286721.57,250.0133209,-38500.72265625,5.32454493866966E-5,1.43678620868889E-6,1,0.999253354069792,40.0298881530762,1.99575605005896,19.8999997228384,0.00060563040154858,8.81660617504462E-5,0.25,-1.44592231695295E-6,5.33400728540964E-5,-1.40485598902889E-6,250.0133209,250.0133209,-38530.97265625,-38470.47265625,57.065134932006,20.5305201525731,27.085165,0,0,0,40,4449,250.0725,-38500.72265625,,,,,,,,,,,,,0,,,,0.00245,,,,,,250.0133209,,,,
,31286818.39,250.0120544,-43340.3046875,6.86962102216956E-5,1.6244081569827E-6,1,0.999253354069792,40.0298881530762,1.99595521395422,19.8999997228384,0.00078122672082784,0.00011502958038796,0.25,-1.75337058270097E-6,6.88182095594811E-5,-1.70026999514355E-6,250.0120544,250.0120544,-43342.5703125,-43338.0390625,57.0729512171983,20.5275204268675,27.464817,0,0,0,40,4449,250.0669,-43340.3046875,,,,,,,,,,,,,0,,,,0.0049,,,,,,250.0120544,,,,
,31286917.795,250.0084839,-48308.56640625,8.66946016047054E-5,1.64484181629854E-6,1,0.999253354069792,40.0298881530762,1.99566335787348,19.8999997228384,0.000985569393456373,0.000146307133480318,0.25,-2.11017552100656E-6,8.68485009220433E-5,-2.0430870111406E-6,250.0084839,250.0084839,-48311.078125,-48306.0546875,57.0768593597945,20.5300402796464,27.464817,0,0,0,40,4449,250.0602,-48308.56640625,,,,,,,,,,,,,0,,,,0,,,,,,250.0084839,,,,
,31287015.95,250.01422885,-53212.248046875,0.000102281499531632,2.31993526882763E-6,1,0.999253354069792,40.0298881530762,1.99573219551431,19.8999997228384,0.00116357104683141,0.000168193943030918,0.25,-2.88018440769987E-6,0.000102463376744465,-2.80184295773233E-6,250.0140381,250.0144196,-53247.10546875,-53177.390625,56.9189703989099,20.5321068716814,27.085165,0,0,0,40,4449,250.05435,-53212.248046875,,,,,,,,,,,,,0,,,,0.00245,,,,,,250.01422885,,,,
,31287115.55,250.0114288,-58190.173828125,0.000122960093421596,1.72815045918323E-6,1,0.999253354069792,40.0298881530762,1.99563202217436,19.8999997228384,0.0013954485680268,0.000221211333171997,0.25,-1.78193449677771E-6,0.000123177397509476,-1.6849517756216E-6,250.0114288,250.0114288,-58195.109375,-58185.23828125,56.8955215433329,20.5322538852156,27.464817,0,0,0,40,4449,250.0346,-58190.173828125,,,,,,,,,,,,,0,,,,0,,,,,,250.0114288,,,,
,31287213.32,250.01399235,-63077.74609375,0.000138663236732028,2.48162489975976E-6,1,0.999253354069792,40.0298881530762,1.9955753635222,19.8999997228384,0.00157161753429802,0.000260989315327723,0.25,-9.90433569459584E-7,0.000138907467726431,-8.79446087065053E-7,250.0139771,250.0140076,-63107.7265625,-63047.765625,57.1206305568714,20.5335996023293,27.464817,0,0,0,40,4449,250.02445,-63077.74609375,,,,,,,,,,,,,0,,,,0,,,,,,250.01399235,,,,
,31287312.39,250.0139008,-68027.17578125,0.00015702618503168,1.88714955552312E-6,1,0.999253354069792,40.0298881530762,1.99549198241584,19.8999997228384,0.00178267218390692,0.00027824796669004,0.25,-2.64901544453988E-6,0.000157304019730996,-2.5262081512303E-6,250.0139008,250.0139008,-68054.53125,-67999.8203125,57.1346998702176,20.5353168789934,27.464817,0,0,0,40,4449,250.01265,-68027.17578125,,,,,,,,,,,,,0,,,,0.00245,,,,,,250.0139008,,,,
,31287408.61,250.0153656,-72836.21875,0.000173865632867462,2.8481295341114E-6,1,0.999253354069792,40.0298881530762,1.99580222584,19.8999997228384,0.00197505604596384,0.000302841910790078,0.25,-3.40023396120538E-6,0.00017417365204666,-3.26529206675405E-6,250.0153656,250.0153656,-72866.1484375,-72806.2890625,56.7563916669098,20.5338645122127,27.085165,0,0,0,40,4449,250.00285,-72836.21875,,,,,,,,,,,,,0,,,,0,,,,,,250.0153656,,,,
,31287505.33,250.0074997,-77668.515625,0.000191611601944159,3.28185132189369E-6,1,0.999253354069792,40.0298881530762,1.99583437604606,19.8999997228384,0.00217557562751243,0.000340118511610903,0.25,-3.18518227132283E-6,0.000191950680381677,-3.03572093139011E-6,250.0072937,250.0077057,-77693.5234375,-77643.5078125,56.9564885678329,20.534094379432,27.085165,0,0,0,40,4449,249.9915,-77668.515625,,,,,,,,,,,,,0,,,,0,,,,,,250.0074997,,,,
,31287602.805,250.0161896,-82540.859375,0.000212239692914431,2.67162266379848E-6,1,0.999253354069792,40.0298881530762,1.99562470366349,19.8999997228384,0.00241058178494625,0.00037072758445089,0.25,-4.05507957630084E-6,0.000212615660168913,-3.89072242088022E-6,250.0161896,250.0161896,-82575.84375,-82505.875,56.8408075469868,20.533273682171,27.844467,0,0,0,40,4449,249.9798,-82540.859375,,,,,,,,,,,,,0,,,,0,,,,,,250.0161896,,,,
,31287697.82,250.0140839,-87290.5703125,0.000229995102188242,2.64591125429531E-6,1,0.999253354069792,40.0298881530762,1.99554919626467,19.8999997228384,0.00261440909822382,0.000388704093556658,0.25,-5.54449208591107E-6,0.000230403493071511,-5.36869385876978E-6,250.0140839,250.0140839,-87317.9921875,-87263.1484375,57.0260535060445,20.5368725951299,27.464817,0,0,0,40,4449,249.9687,-87290.5703125,,,,,,,,,,,,,0,,,,0,,,,,,250.0140839,,,,
,31287805.41,250.0134125,-88135.91796875,0.000229914798432076,2.82329472248761E-6,1,0.999253354069792,40.0298881530762,1.99555752650398,19.8999997228384,0.00260104261238595,0.000460448530807264,0.25,8.07208401177688E-7,0.000230317935051946,9.94051442461111E-7,250.0126343,250.0141907,-88163.3828125,-88108.453125,56.9947883652753,20.5356572655912,27.085165,0,0,0,40,4449,249.9596,-88135.91796875,,,,,,,,,,,,,0,,,,0.00245,,,,,,250.0134125,,,,
,31287899.66,250.0018616,-83426.29296875,0.000213628718917928,2.96128939477222E-6,1,0.999253354069792,40.0298881530762,1.99553950851053,19.8999997228384,0.00242641641103321,0.00037223977989297,0.25,-4.16100644318891E-6,0.00021400732338779,-3.99575067926764E-6,250.0018616,250.0018616,-83451.3515625,-83401.234375,56.9791557948906,20.5366862230306,27.844467,0,0,0,40,4449,249.9601,-83426.29296875,,,,,,,,,,,,,0,,,,-0.0049,,,,,,250.0018616,,,,
,31287999.27,249.9928894,-78449.0546875,0.000195542308372907,2.92444806815099E-6,1,0.999253354069792,40.0298881530762,1.99529056319896,19.8999997228384,0.00221921545999145,0.00034939023717231,0.25,-3.03981504303114E-6,0.00019588827627135,-2.88694157309706E-6,249.9928894,249.9928894,-78478.9765625,-78419.1328125,57.1135959001984,20.5372659521682,27.464817,0,0,0,40,4449,249.9662,-78449.0546875,,,,,,,,,,,,,0,,,,0.00245,,,,,,249.9928894,,,,
,31288094.585,249.9891586,-73686.89453125,0.000177018206752554,2.37101301446323E-6,1,0.999253354069792,40.0298881530762,1.99545586322751,19.8999997228384,0.00200668702386885,0.000330484186347225,0.25,-1.50046715171467E-6,0.000177330389442328,-1.35965987539449E-6,249.9884338,249.9898834,-73712.0859375,-73661.703125,56.953362053756,20.535036472622,27.085165,0,0,0,40,4449,249.9786,-73686.89453125,,,,,,,,,,,,,0,,,,-0.0049,,,,,,249.9891586,,,,
,31288191.455,249.990448,-68842.328125,0.000163040513546067,2.55760903917377E-6,1,0.999253354069792,40.0298881530762,1.99550277744537,19.8999997228384,0.00185264000304514,0.000279231799807026,0.25,-3.6051825649913E-6,0.000163329821734219,-3.47919444989015E-6,249.9903412,249.9905548,-68874.7890625,-68809.8671875,57.129228470583,20.5356466910372,27.085165,0,0,0,40,4449,249.9873,-68842.328125,,,,,,,,,,,,,0,,,,0,,,,,,249.990448,,,,
,31288288.29,249.9885101,-64002.91796875,0.000142396312140279,1.73253559056849E-6,1,0.999253354069792,40.0298881530762,1.99552866910445,19.8999997228384,0.00161861617122503,0.000240778314817485,0.25,-3.42274237535117E-6,0.00014264920489959,-3.31300882708382E-6,249.9885101,249.9885101,-64027.890625,-63977.9453125,57.0323065341983,20.5323035294908,27.844467,0,0,0,40,4449,249.99015,-64002.91796875,,,,,,,,,,,,,0,,,,0,,,,,,249.9885101,,,,
,31288387.905,249.9910507,-59025.236328125,0.000123481260473985,1.71526244030647E-6,1,0.999253354069792,40.0298881530762,1.99542765626218,19.8999997228384,0.00140612894273948,0.000193861405330165,0.25,-4.28663848626751E-6,0.000123701609353982,-4.19364164082596E-6,249.9909668,249.9911346,-59055.09765625,-58995.375,57.0799858738714,20.5369335238275,27.844467,0,0,0,40,4449,249.99995,-59025.236328125,,,,,,,,,,,,,0,,,,-0.00245,,,,,,249.9910507,,,,
,31288487.83,249.9884338,-54030.630859375,0.000105756562019086,2.0675160907159E-6,1,0.999253354069792,40.0298881530762,1.99543676926151,19.8999997228384,0.0012067057969325,0.000152139900077127,0.25,-4.89901272288386E-6,0.000105946282601381,-4.82139027242675E-6,249.9884338,249.9884338,-54062.8515625,-53998.41015625,57.0737328457176,20.5334654379099,27.844467,0,0,0,40,4449,250.01125,-54030.630859375,,,,,,,,,,,,,0,,,,-0.00245,,,,,,249.9884338,,,,
,31288585.785,249.9902649,-49138.6953125,8.98571579795132E-5,2.45337998789934E-6,1,0.999253354069792,40.0298881530762,1.99553837141756,19.8999997228384,0.00102122626145233,0.000152993886978648,0.25,-2.06713386099978E-6,9.00166323439922E-5,-1.99739380289998E-6,249.9901581,249.9903717,-49171.0703125,-49106.3203125,57.017455592333,20.5324130088013,27.464817,0,0,0,40,4449,250.0213,-49138.6953125,,,,,,,,,,,,,0,,,,0.00245,,,,,,249.9902649,,,,
,31288685.035,249.9881287,-44175.837890625,7.12938106573375E-5,1.4861662811679E-6,1,0.999253354069792,40.0298881530762,1.99546541771879,19.8999997228384,0.000810741585852827,0.000118407607931683,0.25,-1.90303800823117E-6,7.14205525103013E-5,-1.84808076321975E-6,249.9881287,249.9881287,-44178.45703125,-44173.21875,57.1112510146407,20.5326657340659,27.844467,0,0,0,40,4449,250.026,-44175.837890625,,,,,,,,,,,,,0,,,,0,,,,,,249.9881287,,,,
,31288781.78,249.9878769,-39338.71484375,5.36759736103486E-5,1.69041628983556E-6,1,0.999253354069792,40.0298881530762,1.9955165006406,19.8999997228384,0.000610516552955694,8.85307893956927E-5,0.25,-1.48747410386483E-6,5.37714356758637E-5,-1.44613280674977E-6,249.9875183,249.9882355,-39366.31640625,-39311.11328125,57.0018230219483,20.53148775359,27.464817,0,0,0,40,4449,250.03675,-39338.71484375,,,,,,,,,,,,,0,,,,-0.00245,,,,,,249.9878769,,,,
,31288879.44,249.9918671,-34461.70703125,3.80315000264017E-5,1.16455246186022E-6,1,0.999253354069792,40.0298881530762,1.99547949612217,19.8999997228384,0.000436976848191334,3.72964253184653E-5,0.25,-3.30053457852047E-6,3.810097174774E-5,-3.275142998518E-6,249.9918671,249.9918671,-34464.04296875,-34459.37109375,57.0205821064099,20.5312076709397,27.464817,0,0,0,40,4449,250.04115,-34461.70703125,,,,,,,,,,,,,0,,,,0,,,,,,249.9918671,,,,
,31288975.83,249.99020385,-29642.15234375,2.11737008726387E-5,1.45566932015874E-6,1,0.999253354069792,40.0298881530762,1.99552361471718,19.8999997228384,0.000241944924250546,2.85102627286598E-5,0.25,-1.15333059137457E-6,2.12118175578944E-5,-1.13797031316219E-6,249.9895477,249.99086,-29667.5703125,-29616.734375,56.7587365524675,20.53067661955,27.464817,0,0,0,40,4449,250.05435,-29642.15234375,,,,,,,,,,,,,0,,,,0,,,,,,249.99020385,,,,
,31289073.235,249.98765565,-24774.59765625,5.04275605599486E-6,1.11679489730478E-6,1,0.999253354069792,40.0298881530762,1.99552217371464,19.8999997228384,5.96916271594173E-5,-5.14471455594386E-6,0.25,-1.32901554165201E-6,5.05270090898226E-6,-1.32720287328896E-6,249.987381,249.9879303,-24804.568359375,-24744.626953125,57.0643533034868,20.5304783024766,27.844467,0,0,0,40,4449,250.0668,-24774.59765625,,,,,,,,,,,,,0,,,,0.00245,,,,,,249.98765565,,,,
,31289169.715,249.9851227,-19955.0537109375,-9.06020186840538E-6,1.03807458790001E-6,1,0.999253354069792,40.0298881530762,1.99563040969717,19.8999997228384,-0.00010150927229363,-2.38708604808745E-5,0.25,-5.37426589847397E-7,-9.07566391158618E-6,-5.45827830349759E-7,249.9851227,249.9851227,-19957.58984375,-19952.517578125,56.9510171681983,20.528724339602,28.224119,0,0,0,40,4449,250.0683,-19955.0537109375,,,,,,,,,,,,,0,,,,0,,,,,,249.9851227,,,,
,31289263.865,249.99121855,-15247.5693359375,-2.44851168657893E-5,6.05721882097253E-7,1,0.999253354069792,40.0298881530762,1.99574330113685,19.8999997228384,-0.000276367475946418,-5.28385929943466E-5,0.25,-4.21033428998244E-7,-2.45277436130938E-5,-4.41949669139393E-7,249.9910583,249.9913788,-15279.9443359375,-15215.1943359375,56.9815006804483,20.5285668630502,27.844467,0,0,0,40,4449,250.0814,-15247.5693359375,,,,,,,,,,,,,0,,,,-0.00245,,,,,,249.99121855,,,,
,31289359.315,249.9948654,-10477.4755859375,-3.8395697121247E-5,6.0858132307583E-7,1,0.999253354069792,40.0298881530762,1.99577976367569,19.8999997228384,-0.000432281654615053,-8.92261438791487E-5,0.25,-1.22262048135263E-6,-3.84620675996855E-5,-1.25644192525824E-6,249.9946289,249.9951019,-10507.3974609375,-10447.5537109375,57.2097362080637,20.5274586375608,27.844467,0,0,0,40,4449,250.08255,-10477.4755859375,,,,,,,,,,,,,0,,,,-0.00245,,,,,,249.9948654,,,,
,31289455.72,249.9926834,-5656.9716796875,-4.73022207607016E-5,3.77407418187476E-7,1,0.999253354069792,40.0298881530762,1.99581209745582,19.8999997228384,-0.000534641033431451,-9.79535817081236E-5,0.25,-4.48733675290895E-7,-4.73848583272209E-5,-4.88583902227786E-7,249.9923706,249.9929962,-5689.26953125,-5624.673828125,57.0588819038522,20.5291666255449,27.464817,0,0,0,40,4449,250.0896,-5656.9716796875,,,,,,,,,,,,,0,,,,-0.00245,,,,,,249.9926834,,,,
,31289550.39,249.9948578,-925.353118896484,-4.09461813921639E-5,4.55861059926002E-7,1,0.999253354069792,40.0298881530762,1.99574621767804,19.8999997228384,-0.000462662907003634,-8.54997730602995E-5,0.25,-4.51211094781393E-7,-4.10176563633821E-5,-4.8584505184656E-7,249.9948578,249.9948578,-950.468078613281,-900.238159179688,56.8955215433329,20.5269166018515,27.464817,0,0,0,40,4449,250.0896,-925.353118896484,,,,,,,,,,,,,0,,,,0,,,,,,249.9948578,,,,
,31289642.07,249.9920959,3652.59704589844,4.38666127719484E-5,4.10115534865135E-7,1,0.999253354069792,40.0298881530762,1.9958419046314,19.8999997228384,0.000497250132638533,8.25743221684374E-5,0.25,-3.1399649520682E-7,4.39438508979639E-5,-2.78309841589029E-7,249.9920959,249.9920959,3627.37036132812,3677.82373046875,57.0033862789868,20.5264453618999,27.844467,0,0,0,40,4449,250.10075,3652.59704589844,,,,,,,,,,,,,0,,,,0,,,,,,249.9920959,,,,
,31289736.14,250.0003052,8356.9140625,4.31748868657852E-5,5.67862331895935E-7,1,0.999253354069792,40.0298881530762,1.99577083298475,19.8999997228384,0.000488249620743339,8.78585104329529E-5,0.25,2.7300615201185E-7,4.32504174305251E-5,3.09118706303509E-7,250.0003052,250.0003052,8326.86328125,8386.96484375,56.9611783389483,20.5275254020995,27.464817,0,0,0,40,4449,250.09375,8356.9140625,,,,,,,,,,,,,0,,,,-0.00245,,,,,,250.0003052,,,,
,31289833.15,250.0029297,13205.212890625,3.13279610601997E-5,8.746886450607E-7,1,0.999253354069792,40.0298881530762,1.99568612263324,19.8999997228384,0.000355621649477404,5.59112543281337E-5,0.25,-4.94140192020643E-7,3.13833375517954E-5,-4.69179002569178E-7,250.0023804,250.003479,13175.138671875,13235.287109375,57.0635716749676,20.5274328614195,27.464817,0,0,0,40,4449,250.08695,13205.212890625,,,,,,,,,,,,,0,,,,0,,,,,,250.0029297,,,,
,31289927.14,250.0050049,17903.1474609375,1.7026301289907E-5,9.26880306172439E-7,1,0.999253354069792,40.0298881530762,1.99550533519524,19.8999997228384,0.000192715643115125,3.35151599919083E-5,0.25,8.04068789381845E-9,1.70561701258622E-5,2.20760384959595E-8,250.0050049,250.0050049,17898.080078125,17908.21484375,56.8658196596022,20.5303486907005,27.464817,0,0,0,40,4449,250.08535,17903.1474609375,,,,,,,,,,,,,0,,,,0,,,,,,250.0050049,,,,
,31290024.26,250.01018525,22755.642578125,2.74767947706124E-6,9.57698166251625E-7,1,0.999253354069792,40.0298881530762,1.99559322434781,19.8999997228384,2.94154900941764E-5,1.51306804545104E-5,0.25,8.60110804958186E-7,2.75179308872694E-6,8.63879927058164E-7,250.0097656,250.0106049,22726.091796875,22785.193359375,56.9275683126214,20.5276202070212,27.844467,0,0,0,40,4449,250.0776,22755.642578125,,,,,,,,,,,,,0,,,,0,,,,,,250.01018525,,,,
,31290119.165,250.0075531,27500.8447265625,-1.39164967666077E-5,1.10833095260996E-6,1,0.999253354069792,40.0298881530762,1.99565236488342,19.8999997228384,-0.000157934582492632,-2.50499507493071E-5,0.25,2.00608402765992E-7,-1.39410822545691E-5,1.89528474387528E-7,250.0075531,250.0075531,27468.404296875,27533.28515625,56.9134989992753,20.5295097719051,27.844467,0,0,0,40,4449,250.0744,27500.8447265625,,,,,,,,,,,,,0,,,,0.00245,,,,,,250.0075531,,,,
,31290215.375,250.0064392,32308.439453125,-3.10621246215425E-5,1.28786896677914E-6,1,0.999253354069792,40.0298881530762,1.99564767062742,19.8999997228384,-0.00035305979461556,-5.27706050673854E-5,0.25,7.25255149821125E-7,-3.11172324294829E-5,7.01044539579861E-7,250.0061493,250.0067291,32276.0078125,32340.87109375,57.230840178083,20.5254506489425,27.464817,0,0,0,40,4449,250.06645,32308.439453125,,,,,,,,,,,,,0,,,,0,,,,,,250.0064392,,,,
,31290313.29,250.0140152,37203.25390625,-4.72489207390441E-5,1.44015579662803E-6,1,0.999253354069792,40.0298881530762,1.99549435210782,19.8999997228384,-0.000535076408735641,-9.13760590523708E-5,0.25,1.21475471762153E-7,-4.73319332822876E-5,8.29776480171976E-8,250.013916,250.0141144,37173.33203125,37233.17578125,56.9056827140829,20.5279448944646,27.464817,0,0,0,40,4449,250.0544,37203.25390625,,,,,,,,,,,,,0,,,,0,,,,,,250.0140152,,,,
,31290409.51,250.0126038,42011.013671875,-6.31488929648851E-5,1.78418685986427E-6,1,0.999253354069792,40.0298881530762,1.99529799342889,19.8999997228384,-0.000714430000945107,-0.000125808103533626,0.25,-1.64092910186829E-7,-6.32595844440121E-5,-2.16046346281811E-7,250.0126038,250.0126038,41980.921875,42041.10546875,56.8595666314483,20.5296084264501,27.844467,0,0,0,40,4449,250.05205,42011.013671875,,,,,,,,,,,,,0,,,,-0.0049,,,,,,250.0126038,,,,
,31290506.235,250.0126038,46846.400390625,-8.03230417245215E-5,1.51589184806213E-6,1,0.999253354069792,40.0298881530762,1.99544297832666,19.8999997228384,-0.000911159044920062,-0.000146382100328323,0.25,9.97291210543781E-7,-8.04648328581822E-5,9.33416110571748E-7,250.0126038,250.0126038,46819.046875,46873.75390625,56.8525319747752,20.5280074688796,27.464817,0,0,0,40,4449,250.03865,46846.400390625,,,,,,,,,,,,,0,,,,0.00245,,,,,,250.0126038,,,,
,31290603.845,250.0119171,51724.2265625,-9.76037715218755E-5,1.86338214762612E-6,1,0.999253354069792,40.0298881530762,1.99549230392854,19.8999997228384,-0.0011042026959765,-0.000195234622119101,0.25,-3.21502521700009E-7,-9.77748303667452E-5,-4.01696379280566E-7,250.011261,250.0125732,51692.03125,51756.421875,56.7665528376599,20.5265871998523,27.844467,0,0,0,40,4449,250.0274,51724.2265625,,,,,,,,,,,,,0,,,,-0.00245,,,,,,250.0119171,,,,
,31290700.69,250.0129852,56566.2109375,-0.000115374791958523,2.0097416597373E-6,1,0.999253354069792,40.0298881530762,1.99552843137578,19.8999997228384,-0.0013118471885567,-0.000192863617733857,0.25,2.96989040866888E-6,-0.000115579736050501,2.88110987254621E-6,250.0129852,250.0129852,56564.01171875,56568.41015625,56.8298647477175,20.5279129255708,27.464817,0,0,0,40,4449,250.01035,56566.2109375,,,,,,,,,,,,,0,,,,0.00245,,,,,,250.0129852,,,,
,31290798.22,250.0134888,61441.775390625,-0.000134833186258,2.31326902882423E-6,1,0.999253354069792,40.0298881530762,1.99545253885303,19.8999997228384,-0.00152906521907862,-0.000248301497365059,0.25,1.44585917065074E-6,-0.000135071059621206,1.33871893927888E-6,250.0134888,250.0134888,61411.66015625,61471.890625,56.7423223535637,20.5262416811173,27.844467,0,0,0,40,4449,250.0077,61441.775390625,,,,,,,,,,,,,0,,,,-0.00245,,,,,,250.0134888,,,,
,31290895.66,250.0116272,66309.921875,-0.000151102261646433,2.39665651864709E-6,1,0.999253354069792,40.0298881530762,1.99543920591112,19.8999997228384,-0.00171646657312329,-0.000261457340841387,0.25,3.10456057064432E-6,-0.000151370070955595,2.98728326101891E-6,250.0116272,250.0116272,66285.3125,66334.53125,56.8939582862945,20.5271032160584,28.224119,0,0,0,40,4449,249.99495,66309.921875,,,,,,,,,,,,,0,,,,-0.00245,,,,,,250.0116272,,,,
,31290992.83,250.014946,71167.6796875,-0.000170202378159526,3.00053134317721E-6,1,0.999253354069792,40.0298881530762,1.99542325151203,19.8999997228384,-0.00193197564419475,-0.000302846225853655,0.25,2.75984460462476E-6,-0.000170503440960777,2.62666010816415E-6,250.0148468,250.0150452,71132.6640625,71202.6953125,56.946327397083,20.5248058099654,27.844467,0,0,0,40,4449,249.98475,71167.6796875,,,,,,,,,,,,,0,,,,-0.00245,,,,,,250.014946,,,,
,31291089.1,250.0106049,75978.4296875,-0.000187522207760917,1.78243870143138E-6,1,0.999253354069792,40.0298881530762,1.99534112507842,19.8999997228384,-0.0021282195086713,-0.000335215620400704,0.25,2.90221178018734E-6,-0.000187853845769185,2.75546688128188E-6,250.0106049,250.0106049,75955.859375,76001,56.7728058658137,20.5256923422231,27.844467,0,0,0,40,4449,249.97685,75978.4296875,,,,,,,,,,,,,0,,,,-0.00245,,,,,,250.0106049,,,,
,31291185.515,250.01068115,80799.11328125,-0.000204858932910154,2.85458968869146E-6,1,0.999253354069792,40.0298881530762,1.99562015602414,19.8999997228384,-0.00232293441081336,-0.000379824753420112,0.25,1.97162076638249E-6,-0.000205220286383661,1.80946665193382E-6,250.0102539,250.0111084,80769.1328125,80829.09375,56.821266834006,20.5233014950987,27.844467,0,0,0,40,4449,249.97285,80799.11328125,,,,,,,,,,,,,0,,,,0,,,,,,250.01068115,,,,
,31291282.155,250.0122223,85629.94921875,-0.000226196777123116,2.43705729041377E-6,1,0.999253354069792,40.0298881530762,1.99531608677389,19.8999997228384,-0.00256780338209042,-0.00040036493736792,0.25,3.85188869109587E-6,-0.000226597136787667,3.67607177522192E-6,250.0122223,250.0122223,85597.453125,85662.4453125,56.8048526351022,20.5272865281771,27.085165,0,0,0,40,4449,249.95955,85629.94921875,,,,,,,,,,,,,0,,,,0,,,,,,250.0122223,,,,
,31291390.135,250.01332855,89730.84765625,-0.000236498756378003,2.82989538903775E-6,1,0.999253354069792,40.0298881530762,1.99542172920376,19.8999997228384,-0.0026803911503047,-0.000444553565180507,0.25,1.73599736377991E-6,-0.000236915517660363,1.54840681542327E-6,250.0131226,250.0135345,89698.90625,89762.7890625,56.7774956369291,20.5252552859563,27.464817,0,0,0,40,4449,249.9511,89730.84765625,,,,,,,,,,,,,0,,,,0,,,,,,250.01332855,,,,
,31291483.225,250.0105591,85081.82421875,-0.000222171442215911,2.43584638712867E-6,1,0.999253354069792,40.0298881530762,1.9955754102161,19.8999997228384,-0.00252276005207597,-0.000391330494513338,0.25,3.95639902323569E-6,-0.000222564825500607,3.78396516810325E-6,250.0105591,250.0105591,85054.171875,85109.4765625,56.953362053756,20.5233255976609,27.844467,0,0,0,40,4449,249.9396,85081.82421875,,,,,,,,,,,,,0,,,,-0.00245,,,,,,250.0105591,,,,
,31291578.34,249.9988403,80328.0390625,-0.000200291600666066,2.41680148946464E-6,1,0.999253354069792,40.0298881530762,1.99576813316766,19.8999997228384,-0.00227196942760125,-0.000367558399932633,0.25,2.26553723737544E-6,-0.000200645251105527,2.10754690481883E-6,249.9985809,249.9990997,80295.6015625,80360.4765625,56.8103240347368,20.520055828841,27.844467,0,0,0,40,4449,249.9461,80328.0390625,,,,,,,,,,,,,0,,,,-0.00245,,,,,,249.9988403,,,,
,31291673.325,249.9956207,75576.33203125,-0.00018317393455922,2.43643550030757E-6,1,0.999253354069792,40.0298881530762,1.99555006886005,19.8999997228384,-0.00207881024398227,-0.000329026067685286,0.25,2.69797441034444E-6,-0.000183497866409604,2.55435895769931E-6,249.9956207,249.9956207,75546.2109375,75606.453125,56.638365760506,20.5245938759192,27.844467,0,0,0,40,4449,249.956,75576.33203125,,,,,,,,,,,,,0,,,,-0.00245,,,,,,249.9956207,,,,
,31291770.86,249.9887238,70703.265625,-0.000170188508401618,1.7701420592807E-6,1,0.999253354069792,40.0298881530762,1.99551850092839,19.8999997228384,-0.00192928102223218,-0.000317984476242578,0.25,1.42138569606431E-6,-0.000170488617300896,1.2858297264778E-6,249.9887238,249.9887238,70698.125,70708.40625,56.5945945634291,20.5272978579871,27.844467,0,0,0,40,4449,249.96455,70703.265625,,,,,,,,,,,,,0,,,,-0.00245,,,,,,249.9887238,,,,
,31291868.395,249.99036405,65827.71875,-0.000150498946654859,2.69848972078916E-6,1,0.999253354069792,40.0298881530762,1.99547478451612,19.8999997228384,-0.00170354795595353,-0.00029556863317997,0.25,-1.31153227880118E-8,-0.000150763275183212,-1.3540889923936E-7,249.9895172,249.9912109,65805.1328125,65850.3046875,56.9049010855637,20.5300266050008,27.844467,0,0,0,40,4449,249.9713,65827.71875,,,,,,,,,,,,,0,,,,0,,,,,,249.99036405,,,,
,31291965.375,249.987854,60979.537109375,-0.000133129979815521,1.87994540039939E-6,1,0.999253354069792,40.0298881530762,1.99570880538349,19.8999997228384,-0.00150737267721868,-0.000259980007227719,0.25,1.21639061666475E-7,-0.000133363904603536,1.3529310087101E-8,249.987854,249.987854,60976.76171875,60982.3125,56.9244417985445,20.5235108433839,27.844467,0,0,0,40,4449,249.9793,60979.537109375,,,,,,,,,,,,,0,,,,0,,,,,,249.987854,,,,
,31292061.08,249.9871368,56196.490234375,-0.000114223080463463,2.16370726862638E-6,1,0.999253354069792,40.0298881530762,1.99566594661382,19.8999997228384,-0.00129463186946698,-0.000215208648244293,0.25,7.97472543805229E-7,-0.000114424336536299,7.05798720713271E-7,249.9871368,249.9871368,56168.83984375,56224.140625,56.9314764552176,20.524070148119,27.464817,0,0,0,40,4449,249.99195,56196.490234375,,,,,,,,,,,,,0,,,,0.00245,,,,,,249.9871368,,,,
,31292157.7,249.9866486,51366.70703125,-9.90947535015524E-5,1.89227135599212E-6,1,0.999253354069792,40.0298881530762,1.99572242027158,19.8999997228384,-0.00112675518590226,-0.000166174655981725,0.25,2.50593831237044E-6,-9.92708236318079E-5,2.42947013812614E-6,249.9866486,249.9866486,51336.90234375,51396.51171875,56.7860935506406,20.5229442681597,27.464817,0,0,0,40,4449,249.99045,51366.70703125,,,,,,,,,,,,,0,,,,0,,,,,,249.9866486,,,,
,31292252.675,249.9887238,46621.638671875,-8.12240186092547E-5,2.09067746750019E-6,1,0.999253354069792,40.0298881530762,1.99552947350115,19.8999997228384,-0.000923220734671913,-0.000137636840797799,0.25,1.9266578384591E-6,-8.13682185581121E-5,1.86366694824298E-6,249.9887238,249.9887238,46594.08984375,46649.1875,56.9455457685637,20.5257965594154,27.844467,0,0,0,40,4449,250.0135,46621.638671875,,,,,,,,,,,,,0,,,,-0.00245,,,,,,249.9887238,,,,
,31292349.875,249.9888153,41763.603515625,-6.36158879569E-5,1.39771527725873E-6,1,0.999253354069792,40.0298881530762,1.99577158357149,19.8999997228384,-0.000723071347190326,-0.000108347148182769,0.25,1.46176875363669E-6,-6.37287822419087E-5,1.41227631700508E-6,249.9888153,249.9888153,41761.09765625,41766.109375,56.9064643426022,20.5253576173112,27.464817,0,0,0,40,4449,250.0209,41763.603515625,,,,,,,,,,,,,0,,,,-0.0049,,,,,,249.9888153,,,,
,31292444.375,249.9884491,37038.451171875,-4.72565456458657E-5,9.08182776192502E-7,1,0.999253354069792,40.0298881530762,1.99569868255029,19.8999997228384,-0.000536632375081777,-8.32298386735458E-5,0.25,8.4318649949686E-7,-4.73402054410366E-5,8.05943524790717E-7,249.9884491,249.9884491,37033.5234375,37043.37890625,56.8908317722176,20.5280835641214,27.464817,0,0,0,40,4449,250.0312,37038.451171875,,,,,,,,,,,,,0,,,,0,,,,,,249.9884491,,,,
,31292540.71,249.9932251,32223.716796875,-3.07532662710049E-5,1.41218178411266E-6,1,0.999253354069792,40.0298881530762,1.99564701398664,19.8999997228384,-0.000352606733270321,-3.46156276027722E-5,0.25,2.27543639949824E-6,-3.0809118158052E-5,2.25419618275184E-6,249.9928284,249.9936218,32191.333984375,32256.099609375,56.9963516223137,20.5254979071389,27.844467,0,0,0,40,4449,250.0336,32223.716796875,,,,,,,,,,,,,0,,,,0.00245,,,,,,249.9932251,,,,
,31292635.625,249.9902725,27478.89453125,-1.44540837224072E-5,1.19439645303936E-6,1,0.999253354069792,40.0298881530762,1.99575448206999,19.8999997228384,-0.000166742013457788,-1.04591773796999E-5,0.25,1.58277330289087E-6,-1.44807568898148E-5,1.57367644325955E-6,249.990036,249.990509,27448.873046875,27508.916015625,57.0807675023906,20.5255103670985,27.085165,0,0,0,40,4449,250.04555,27478.89453125,,,,,,,,,,,,,0,,,,0,,,,,,249.9902725,,,,
,31292732.68,249.9896088,22626.310546875,1.58814464526904E-6,8.90376930068012E-7,1,0.999253354069792,40.0298881530762,1.99543423673372,19.8999997228384,1.37573595776313E-5,2.7446874926895E-5,0.25,2.14937537809991E-6,1.58916419327877E-6,2.15445466101098E-6,249.9896088,249.9896088,22596.3515625,22656.26953125,56.9392927404099,20.5292893339063,27.844467,0,0,0,40,4449,250.05255,22626.310546875,,,,,,,,,,,,,0,,,,0,,,,,,249.9896088,,,,
,31292829.675,249.9877777,17781.2939453125,1.77834474613492E-5,8.82551104985276E-7,1,0.999253354069792,40.0298881530762,1.9955556546318,19.8999997228384,0.00019684522493784,6.06390073658776E-5,0.25,2.27277695980679E-6,1.78127900968814E-5,2.29141378216046E-6,249.9877777,249.9877777,17778.859375,17783.728515625,56.7657712091406,20.5307907963566,27.464817,0,0,0,40,4449,250.0525,17781.2939453125,,,,,,,,,,,,,0,,,,-0.0049,,,,,,249.9877777,,,,
,31292924.68,249.9876556,13033.5546875,3.13378895518878E-5,8.57568166502426E-7,1,0.999253354069792,40.0298881530762,1.99559926386873,19.8999997228384,0.000350914484549329,8.36348807568598E-5,0.25,1.95338999323487E-6,3.13912821048652E-5,1.98265834936838E-6,249.9876556,249.9876556,13000.9462890625,13066.1630859375,56.7728058658137,20.5289714766279,27.464817,0,0,0,40,4449,250.0678,13033.5546875,,,,,,,,,,,,,0,,,,0,,,,,,249.9876556,,,,
,31293019.345,249.9922791,8300.8349609375,4.29277889254822E-5,6.56584627264056E-7,1,0.999253354069792,40.0298881530762,1.99578607201491,19.8999997228384,0.00048394848259457,9.60659472592539E-5,0.25,1.0407620598701E-6,4.30022641077003E-5,1.07802153858917E-6,249.9922791,249.9922791,8273.140625,8328.529296875,56.9979148793522,20.5307528558707,27.464817,0,0,0,40,4449,250.07595,8300.8349609375,,,,,,,,,,,,,0,,,,-0.00245,,,,,,249.9922791,,,,
,31293113.165,249.99321745,3612.78527832031,4.74030331572616E-5,3.75599676592532E-7,1,0.999253354069792,40.0298881530762,1.99583043789009,19.8999997228384,0.000535982376733491,9.70259482575023E-5,0.25,3.49221291375144E-7,4.74859268492831E-5,3.88997330965917E-7,249.9928589,249.993576,3580.5498046875,3645.02075195313,57.1683098965445,20.5263274325835,27.464817,0,0,0,40,4449,250.07995,3612.78527832031,,,,,,,,,,,,,0,,,,0,,,,,,249.99321745,,,,
,31293185.415,249.9936829,-0.715517356991768,2.53967584244655E-5,4.22254958057745E-7,1,0.999253354069792,40.0298881530762,1.99594252275766,19.8999997228384,0.000288755081799874,4.28719516903747E-5,0.25,-6.17865241309083E-7,2.54418333633754E-5,-5.97955911187574E-7,249.9936829,249.9936829,-1.08088791370392,-0.350146800279617,57.1972301517561,20.5268109260115,27.844467,0,0,0,40,4417,250.0826,-0.715517356991768,,,,,,,,,,,,,0,,,,0.00245,,,,,,249.9936829,,,,