File: data/doubleLayers/dl_0-125/ppms/data/DD213_7_HYST_100OE_10K.DAT
[Header]
; VSM Data File (default extension .dat)
; Copyright (c) 2003-2013, Quantum Design, Inc. All rights reserved.
TITLE,
FILEOPENTIME,31209666.06,12/28/2018,1:22 pm
BYAPP,VSM,2.0,2.0
INFO,PPMS VSM Option Release 1.4.10 Build 1,APPNAME
INFO,Quantum Design Linear Motor Servo Controller,MOTOR_MODULE_NAME
INFO,3101-100 M1,MOTOR_HW_VERSION
INFO,MMC1014,MOTOR_SERIAL_NUMBER
INFO,SRV No X-over 01.03.11,MOTOR_SOFTWARE_VERSION
INFO,Quantum Design VSM Detection Module,VSM_MODULE_NAME
INFO,3101-150 F0,VSM_HW_VERSION
INFO,VSM707,VSM_SERIAL_NUMBER
INFO,VSM No X-over 01.02.05 May 20 2008 13:51:47,VSM_SOFTWARE_VERSION
INFO,704,PREAMP_SERIAL_NUMBER
INFO,822,COIL_SERIAL_NUMBER
INFO,0,MOMENT_UNITS
INFO,CoFe2O4,SAMPLE_MATERIAL
INFO,Double Layer thin concentration,SAMPLE_COMMENT
INFO,29.55,SAMPLE_MASS
INFO,,SAMPLE_VOLUME
INFO,,SAMPLE_MOLECULAR_WEIGHT
INFO,,SAMPLE_SIZE
INFO,,SAMPLE_SHAPE
DATATYPE,COMMENT,1
DATATYPE,TIME,2
STARTUPAXIS,X,2
STARTUPAXIS,Y1,5
[Data]
Comment,Time Stamp (sec),Temperature (K),Magnetic Field (Oe),Moment (emu),M. Std. Err. (emu),Transport Action,Averaging Time (sec),Frequency (Hz),Peak Amplitude (mm),Center Position (mm),Coil Signal' (mV),Coil Signal" (mV),Range (mV),M. Quad. Signal (emu),M. Raw' (emu),M. Raw" (emu),Min. Temperature (K),Max. Temperature (K),Min. Field (Oe),Max. Field (Oe),Mass (grams),Motor Lag (deg),Pressure (Torr),VSM Status (code),Motor Status (code),Measure Status (code),Measure Count,PPMS Status (code),System Temp. (K),System Field (Oe),Sample Position (deg),Bridge 1 Resistance (ohms),Bridge 1 Excitation (에),Bridge 2 Resistance (ohms),Bridge 2 Excitation (에),Bridge 3 Resistance (ohms),Bridge 3 Excitation (에),Bridge 4 Resistance (ohms),Bridge 4 Excitation (에),Signal 1 Vin (V),Signal 2 Vin (V),Digital Inputs (code),Drive 1 Iout (mA),Drive 1 Ipower (W),Drive 2 Iout (mA),Drive 2 Ipower (W),Pressure (),Map 20 (),Map 21 (),Map 22 (),Map 23 (),Map 24 (),Map 25 (),Map 26 (),Map 27 (),Map 28 (),Map 29 ()
,31209680.7,10.0046129,99.4873580932617,,,2,,,,20.6800005578995,,,,,,,10.0046129,10.0046129,99.4873580932617,99.4873580932617,,,11.899124,,,,-99999999,4369,9.989,99.4873580932617,,,,,,,,,,,,,,,,,,,,,,,10.0046129,,,,
,31209816.375,10.00012635,4138.84326171875,8.58595029901027E-6,3.97507757157715E-7,1,0.999253354069792,40.0298881530762,1.99574469616464,20.6700004637241,9.61083306662684E-5,1.89184598163837E-5,0.25,1.57756381448171E-7,8.53771306324062E-6,2.00389329808515E-7,10.0000877,10.000165,4113.7861328125,4163.900390625,56.0818462548136,20.5067528434831,11.519473,0,0,0,40,4449,9.9884,4138.84326171875,,,,,,,,,,,,,0,,,,-0.0049,,,,,,10.00012635,,,,
,31209901.74,10.0002675,8407.17919921875,-2.60669234287794E-6,3.13577150308094E-7,1,0.999253354069792,40.0298881530762,1.99589063803542,20.6700004637241,-2.94815744837087E-5,-4.10527194963907E-6,0.25,9.89421471918529E-8,-2.59361620626651E-6,8.44115756699505E-8,10.0001287,10.0004063,8376.958984375,8437.3994140625,56.404658833256,20.5106371799214,11.899124,0,0,0,40,4449,9.9886,8407.17919921875,,,,,,,,,,,,,0,,,,-0.0049,,,,,,10.0002675,,,,
,31209986.305,10.0016317,12630.505859375,-1.36462139607508E-5,4.55424951426092E-7,1,0.999253354069792,40.0298881530762,1.99559784204731,20.6700004637241,-0.000153069488848392,-2.87955402267962E-5,0.25,-1.27446422300719E-7,-1.35789687546523E-5,-2.04433896000598E-7,10.0016317,10.0016317,12605.4375,12655.57421875,56.4820400566598,20.5136998261762,11.899124,0,0,0,40,4449,9.98675,12630.505859375,,,,,,,,,,,,,0,,,,-0.00245,,,,,,10.0016317,,,,
,31210071.485,10.00163885,16888.62109375,-2.06348612609319E-5,4.90256598691932E-7,1,0.999253354069792,40.0298881530762,1.99639809463364,20.6700004637241,-0.000236363568665307,-1.71459401690248E-5,0.25,2.16414247652305E-6,-2.05551264986037E-5,2.03083338268784E-6,10.001605,10.0016727,16858.55078125,16918.69140625,56.8580033744099,20.5101001358379,11.519473,0,0,0,40,4449,9.985,16888.62109375,,,,,,,,,,,,,0,,,,-0.00245,,,,,,10.00163885,,,,
,31210157.38,10.0010815,21181.119140625,-2.46938903881024E-5,5.04215813571136E-7,1,0.999253354069792,40.0298881530762,1.99642744843434,20.6700004637241,-0.000280273356976578,-3.56874145215005E-5,0.25,1.24914984568339E-6,-2.46009694343257E-5,1.0891620391688E-6,10.0010815,10.0010815,21151.22265625,21211.015625,57.0112025641791,20.5072646224301,11.899124,0,0,0,40,4449,9.9842,21181.119140625,,,,,,,,,,,,,0,,,,0,,,,,,10.0010815,,,,
,31210244.15,10.0008292,25519.20703125,-2.66370228697086E-5,8.41580775150692E-7,1,0.999253354069792,40.0298881530762,1.99635179900683,20.6700004637241,-0.000298664748225172,-5.96396576983383E-5,0.25,-5.23407808424329E-7,-2.65365464198481E-5,-6.95462672022376E-7,10.0006828,10.0009756,25489.123046875,25549.291015625,56.8775440873906,20.5106592819424,11.519473,0,0,0,40,4449,9.9842,25519.20703125,,,,,,,,,,,,,0,,,,-0.00245,,,,,,10.0008292,,,,
,31210329.705,10.0003119,29794.89453125,-3.05856787837163E-5,9.0138766598486E-7,1,0.999253354069792,40.0298881530762,1.99622713093194,20.6700004637241,-0.000345511172146435,-5.49112665271455E-5,0.25,6.13635368465258E-7,-3.04919481686333E-5,4.05078521908593E-7,10.0003119,10.0003119,29762.3359375,29827.453125,56.6352392464291,20.5131248962133,11.899124,0,0,0,40,4449,9.98485,29794.89453125,,,,,,,,,,,,,0,,,,-0.00245,,,,,,10.0003119,,,,
,31210413.13,9.9997044,33967.830078125,-3.82812621834513E-5,6.89584855558712E-7,1,0.999253354069792,40.0298881530762,1.99601757783593,20.6700004637241,-0.00043300812369197,-6.64486828565639E-5,0.25,9.7959171915533E-7,-3.81824222691741E-5,7.11155611298198E-7,9.9997044,9.9997044,33940.33203125,33995.328125,57.1933220091599,20.5165483054718,12.278775,0,0,0,40,4449,9.9847,33967.830078125,,,,,,,,,,,,,0,,,,0.00245,,,,,,9.9997044,,,,
,31210498.325,9.9982014,38225.33984375,-4.97395216375298E-5,6.70927121873343E-7,1,0.999253354069792,40.0298881530762,1.99561481781188,20.6700004637241,-0.000566603931247825,-6.50208557735047E-5,0.25,3.17540662797704E-6,-4.96472875033309E-5,2.81492646854567E-6,9.9982014,9.9982014,38222.7109375,38227.96875,56.6907348712945,20.5135960342844,12.278775,0,0,0,40,4449,9.985,38225.33984375,,,,,,,,,,,,,0,,,,-0.0049,,,,,,9.9982014,,,,
,31210582.88,9.99807505,42451.01953125,-6.00848686728699E-5,7.35934777022743E-7,1,0.999253354069792,40.0298881530762,1.99613663035383,20.6700004637241,-0.000684722656067384,-7.97820323650775E-5,0.25,3.73836992709292E-6,-6.0000066765518E-5,3.29726887773511E-6,9.9980183,9.9981318,42420.8125,42481.2265625,57.017455592333,20.5099703692939,11.899124,0,0,0,40,4449,9.9879,42451.01953125,,,,,,,,,,,,,0,,,,0,,,,,,9.99807505,,,,
,31210668.21,9.9972305,46714.025390625,-7.69438323690271E-5,9.77803176355085E-7,1,0.999253354069792,40.0298881530762,1.99608321836055,20.6700004637241,-0.000862606692339734,-0.000183335793970718,0.25,-2.40109769766445E-6,-7.68172925557097E-5,-2.961026981759E-6,9.9972305,9.9972305,46684.01953125,46744.03125,56.9072459711214,20.5159108211659,12.278775,0,0,0,40,4449,9.99095,46714.025390625,,,,,,,,,,,,,0,,,,-0.0049,,,,,,9.9972305,,,,
,31210753.43,9.99624965,50974.4375,-9.02498889747997E-5,1.0073708882534E-6,1,0.999253354069792,40.0298881530762,1.995640721343,20.6700004637241,-0.00102565826525378,-0.000139319231502282,0.25,3.90853559750975E-6,-9.01902583265251E-5,3.23793793241793E-6,9.996232,9.9962673,50941.8515625,51007.0234375,56.8877052581406,20.5154957341679,11.519473,0,0,0,40,4449,9.99415,50974.4375,,,,,,,,,,,,,0,,,,0.00245,,,,,,9.99624965,,,,
,31210846.71,9.9954901,55637.48828125,-0.000106213496041613,1.02434626196121E-6,1,0.999253354069792,40.0298881530762,1.9957348439996,20.6700004637241,-0.00120717126650901,-0.000166952609453603,0.25,4.34640201092052E-6,-0.00010619079978728,3.55495516688085E-6,9.9954901,9.9954901,55610.26171875,55664.71484375,56.892395029256,20.5181369423894,12.278775,0,0,0,40,4449,9.9975,55637.48828125,,,,,,,,,,,,,0,,,,0,,,,,,9.9954901,,,,
,31210943.945,9.99552015,60497.19140625,-0.000122283606913417,1.23104774201444E-6,1,0.999253354069792,40.0298881530762,1.99545753491239,20.6700004637241,-0.00138890627304941,-0.000199889309217646,0.25,4.33068487170442E-6,-0.000122309329781196,3.42022306877141E-6,9.9954453,9.995595,60467.2421875,60527.140625,56.8509687177368,20.5183648331114,11.519473,0,0,0,40,4449,10.00215,60497.19140625,,,,,,,,,,,,,0,,,,0,,,,,,9.99552015,,,,
,31211042.44,9.99541285,65420.349609375,-0.000140437692326076,1.1181930721994E-6,1,0.999253354069792,40.0298881530762,1.99557376528689,20.6700004637241,-0.00159763972968265,-0.000220063430365824,0.25,5.8227569625968E-6,-0.000140536610760466,4.78177134088139E-6,9.995348,9.9954777,65390.484375,65450.21484375,56.7368509539291,20.5218814321471,11.519473,0,0,0,40,4449,10.006,65420.349609375,,,,,,,,,,,,,0,,,,0.0049,,,,,,9.99541285,,,,
,31211141.54,9.9946728,70372.91015625,-0.000159167810001928,9.25468848643704E-7,1,0.999253354069792,40.0298881530762,1.99538942181371,20.6700004637241,-0.00180891930681034,-0.000262877836746895,0.25,5.40798947081998E-6,-0.000159339226366979,4.23632429284695E-6,9.9946728,9.9946728,70368.0390625,70377.78125,57.1581487257945,20.5224355525801,11.519473,0,0,0,40,4449,10.0118,70372.91015625,,,,,,,,,,,,,0,,,,-0.00245,,,,,,9.9946728,,,,
,31211239.015,9.99519585,75245.69921875,-0.000182308621961806,1.2096769950909E-6,1,0.999253354069792,40.0298881530762,1.99527064193704,20.6700004637241,-0.00205764621577635,-0.000384303437214369,0.25,-1.17174436474975E-6,-0.000182523447715699,-2.5094380044815E-6,9.995162,9.9952297,75210.46875,75280.9296875,56.8689461736791,20.5193188669417,11.139823,0,0,0,40,4449,10.0159,75245.69921875,,,,,,,,,,,,,0,,,,0,,,,,,9.99519585,,,,
,31211339.685,9.9950905,80279.3125,-0.000196845084301982,8.96567456806401E-7,1,0.999253354069792,40.0298881530762,1.99519080765586,20.6700004637241,-0.00222628727074002,-0.000394003971557637,0.25,5.84137448038612E-7,-0.000197167029954763,-8.42071846633575E-7,9.9950905,9.9950905,80274.046875,80284.578125,56.760299809506,20.5211821161161,11.899124,0,0,0,40,4449,10.0217,80279.3125,,,,,,,,,,,,,0,,,,-0.00245,,,,,,9.9950905,,,,
,31211439.135,9.9938765,85250.1484375,-0.000213319488343447,9.66575868188205E-7,1,0.999253354069792,40.0298881530762,1.99512512435811,20.6700004637241,-0.00241366654853774,-0.000425629573230066,0.25,7.44310177304428E-7,-0.000213745860605359,-7.80933599377713E-7,9.9938765,9.9938765,85247.546875,85252.75,56.6766655579483,20.5229884507177,11.519473,0,0,0,40,4449,10.0262,85250.1484375,,,,,,,,,,,,,0,,,,-0.0049,,,,,,9.9938765,,,,
,31211531.305,9.9950485,89855.49609375,-0.000230767579477673,9.50693446276103E-7,1,0.999253354069792,40.0298881530762,1.995352618432,20.6700004637241,-0.00261169746535492,-0.0004633434744987,0.25,5.4309105295615E-7,-0.000231299032692163,-1.0849068832713E-6,9.9950485,9.9950485,89850.421875,89860.5703125,57.065134932006,20.5203055437189,11.519473,0,0,0,40,4449,10.0314,89855.49609375,,,,,,,,,,,,,0,,,,-0.0049,,,,,,9.9950485,,,,
,31211640.9,9.9983311,85556.84765625,-0.000214680894900901,1.2924147634148E-6,1,0.999253354069792,40.0298881530762,1.99521120655922,20.6700004637241,-0.00243647867006803,-0.000388045520936055,0.25,4.31382976289992E-6,-0.000215140073602961,2.78730299636154E-6,9.9983311,9.9983311,85524.390625,85589.3046875,56.8775440873906,20.5198662846842,11.899124,0,0,0,40,4449,10.0301,85556.84765625,,,,,,,,,,,,,0,,,,-0.00245,,,,,,9.9983311,,,,
,31211740.445,10.00173,80581.0234375,-0.000195140113545353,7.3434556043147E-7,1,0.999253354069792,40.0298881530762,1.99520475345446,20.6700004637241,-0.00221042695944336,-0.000371948115562737,0.25,2.2282593563491E-6,-0.000195475606234123,8.18143898499762E-7,10.00173,10.00173,80576.0234375,80586.0234375,56.8087607776983,20.524263491372,11.139823,0,0,0,40,4449,10.02805,80581.0234375,,,,,,,,,,,,,0,,,,0,,,,,,10.00173,,,,
,31211841.81,10.00241755,75514.53515625,-0.000178097124130702,9.96836506429383E-7,1,0.999253354069792,40.0298881530762,1.99500273871215,20.6700004637241,-0.00201635511304187,-0.000339536428111656,0.25,2.02753075587614E-6,-0.000178334035153179,7.25349504923468E-7,10.0023861,10.002449,75482.1484375,75546.921875,56.7055858131598,20.5288227328591,11.139823,0,0,0,40,4449,10.0248,75514.53515625,,,,,,,,,,,,,0,,,,0,,,,,,10.00241755,,,,
,31211943.36,10.0048904,70438.60546875,-0.000159933746610928,1.03261145515361E-6,1,0.999253354069792,40.0298881530762,1.9948799453547,20.6700004637241,-0.00180762838909421,-0.000317150175269455,0.25,7.34509400923674E-7,-0.000160072145043163,-4.46563159922628E-7,10.0048904,10.0048904,70433.890625,70443.3203125,57.0666981890445,20.5230160457742,11.139823,0,0,0,40,4449,10.0235,70438.60546875,,,,,,,,,,,,,0,,,,0.0049,,,,,,10.0048904,,,,
,31212044.68,10.0035143,65373.3671875,-0.000143988180237486,9.53661840515736E-7,1,0.999253354069792,40.0298881530762,1.9947611591558,20.6700004637241,-0.0016264790184025,-0.000286059918776258,0.25,6.08103414773626E-7,-0.000144049162527108,-4.61365512305006E-7,10.0035143,10.0035143,65370.5625,65376.171875,57.1221938139099,20.5272328414956,11.139823,0,0,0,40,4449,10.0183,65373.3671875,,,,,,,,,,,,,0,,,,-0.0049,,,,,,10.0035143,,,,
,31212146.235,10.0030508,60297.392578125,-0.000124546449499914,9.40116852489588E-7,1,0.999253354069792,40.0298881530762,1.9948196029487,20.6700004637241,-0.00140808567516107,-0.000237163965355177,0.25,1.42905411309058E-6,-0.000124548122288219,5.01873412087511E-7,10.0030508,10.0030508,60292.34765625,60302.4375,56.8048526351022,20.5342146571841,11.139823,0,0,0,40,4449,10.0148,60297.392578125,,,,,,,,,,,,,0,,,,0.0049,,,,,,10.0030508,,,,
,31212246.195,10.0034723,55302.234375,-0.000107382065899249,1.06899899171555E-6,1,0.999253354069792,40.0298881530762,1.99491193885349,20.6700004637241,-0.00121261263217643,-0.000209327649168417,0.25,7.93034536647796E-7,-0.00010732884252048,-5.06270447382039E-9,10.0034723,10.0034723,55299.7265625,55304.7421875,57.0299616486406,20.5332615388361,11.899124,0,0,0,40,4449,10.0124,55302.234375,,,,,,,,,,,,,0,,,,0.0049,,,,,,10.0034723,,,,
,31212345.25,10.0036755,50349.833984375,-8.92734705344046E-5,8.56175583601538E-7,1,0.999253354069792,40.0298881530762,1.99475769727005,20.6700004637241,-0.00100824120761802,-0.000170084440021221,0.25,9.96353010199309E-7,-8.91876353194E-5,3.36479896237777E-7,10.0036755,10.0036755,50347.53515625,50352.1328125,56.8814522299868,20.5363395951324,11.139823,0,0,0,40,4449,10.0088,50349.833984375,,,,,,,,,,,,,0,,,,0,,,,,,10.0036755,,,,
,31212445.415,10.0044022,45344.884765625,-7.0629250528201E-5,8.13691717611981E-7,1,0.999253354069792,40.0298881530762,1.99466519687437,20.6700004637241,-0.000795854860639301,-0.000142117498685319,0.25,1.05166005413713E-7,-7.05199680943261E-5,-4.10154264194374E-7,10.0044022,10.0044022,45339.7734375,45349.99609375,56.8134505488137,20.5412914666126,11.519473,0,0,0,40,4449,10.00695,45344.884765625,,,,,,,,,,,,,0,,,,0,,,,,,10.0044022,,,,
,31212546.095,10.003314,40309.470703125,-5.45614551768035E-5,7.78221217438534E-7,1,0.999253354069792,40.0298881530762,1.99459872457815,20.6700004637241,-0.00061509752195697,-0.000106161279282312,0.25,3.90955329689469E-7,-5.44503965100805E-5,-8.38004751387939E-10,10.003314,10.003314,40307.05078125,40311.890625,56.8494054606983,20.5416412645013,11.899124,0,0,0,40,4449,10.0031,40309.470703125,,,,,,,,,,,,,0,,,,0,,,,,,10.003314,,,,
,31212649.43,10.0024686,35146.8125,-3.52074193316989E-5,6.78001554859337E-7,1,0.999253354069792,40.0298881530762,1.99464710526639,20.6700004637241,-0.00039749562577239,-6.40456333497453E-5,0.25,6.39107118269903E-7,-3.5119132703708E-5,3.91368137309489E-7,10.0024166,10.0025206,35139.40625,35154.21875,57.108906129083,20.5415538432139,11.139823,0,0,0,40,4449,10.00155,35146.8125,,,,,,,,,,,,,0,,,,0,,,,,,10.0024686,,,,
,31212749.205,10.00102995,30159.6796875,-1.75764678281081E-5,7.17711774667247E-7,1,0.999253354069792,40.0298881530762,1.99476269812029,20.6700004637241,-0.000198095925210811,-3.33463515859089E-5,0.25,1.918748548516E-7,-1.75221947103832E-5,7.22373616968304E-8,10.0008726,10.0011873,30127.197265625,30192.162109375,57.2277136640061,20.5364302154019,11.899124,0,0,0,40,4449,10.00055,30159.6796875,,,,,,,,,,,,,0,,,,0,,,,,,10.00102995,,,,
,31212851.48,10.0012579,25047.259765625,-1.75123734193259E-6,6.2887668166642E-7,1,0.999253354069792,40.0298881530762,1.99477344215666,20.6700004637241,-2.02490858778941E-5,-4.08277502526987E-7,0.25,2.77695503245015E-7,-1.74657797168682E-6,2.6527983837009E-7,10.0011549,10.0013609,25019.822265625,25074.697265625,56.7720242372945,20.5375760764268,11.519473,0,0,0,40,4449,9.999,25047.259765625,,,,,,,,,,,,,0,,,,0,,,,,,10.0012579,,,,
,31212949.99,10.00035,20121.9736328125,1.52081371118502E-5,4.92476735646732E-7,1,0.999253354069792,40.0298881530762,1.99481820906739,20.6700004637241,0.000169730146408215,3.7207206371596E-5,0.25,5.88483269882354E-7,1.51408553955375E-5,6.80386419645812E-7,10.00035,10.00035,20116.873046875,20127.07421875,56.8728543162753,20.5409299241716,11.519473,0,0,0,40,4449,9.9983,20121.9736328125,,,,,,,,,,,,,0,,,,0.0049,,,,,,10.00035,,,,
,31213047.695,9.9996543,15242.4409179687,3.06696865843479E-5,4.56675388520002E-7,1,0.999253354069792,40.0298881530762,1.99470987166065,20.6700004637241,0.000343981700346722,6.455664294851E-5,0.25,2.67486673587297E-7,3.05256987443711E-5,4.46415149300937E-7,9.9993582,9.9999504,15214.9248046875,15269.95703125,57.1346998702176,20.5430375365887,11.139823,0,0,0,40,4449,9.9981,15242.4409179687,,,,,,,,,,,,,0,,,,0.00245,,,,,,9.9996543,,,,
,31213146.17,9.998908,10319.8891601562,4.59466891203505E-5,3.03058919240648E-7,1,0.999253354069792,40.0298881530762,1.99483852403786,20.6700004637241,0.000515753825870852,9.32133613901158E-5,0.25,1.08571472002145E-7,4.57132083351176E-5,3.61538707077356E-7,9.998908,9.998908,10287.3388671875,10352.439453125,56.8470605751406,20.5433749977646,11.519473,0,0,0,40,4449,10.0003,10319.8891601562,,,,,,,,,,,,,0,,,,0,,,,,,9.998908,,,,
,31213247.89,9.9987297,5234.82666015625,6.13724376848151E-5,3.78090596924059E-7,1,0.999253354069792,40.0298881530762,1.99483371046545,20.6700004637241,0.000688565175843143,0.000124884232966742,0.25,2.05749559192917E-7,6.10367724245231E-5,5.20350807174621E-7,9.9987297,9.9987297,5229.83251953125,5239.82080078125,57.0573186468137,20.5408983830288,11.519473,0,0,0,40,4449,10.0036,5234.82666015625,,,,,,,,,,,,,0,,,,-0.0049,,,,,,9.9987297,,,,
,31213346.15,10.0025659,323.521728515625,7.47903931793533E-5,2.92562294618461E-7,1,0.999253354069792,40.0298881530762,1.99470642072908,20.6700004637241,0.000838697936283179,0.000152808953906959,0.25,3.3415513630534E-7,7.435989718466E-5,6.93614067079525E-7,10.0023108,10.002821,290.953125,356.09033203125,57.0182372208522,20.541123850004,11.519473,0,0,0,40,4449,10.00065,323.521728515625,,,,,,,,,,,,,0,,,,-0.0049,,,,,,10.0025659,,,,
,31213444.605,9.998951,-4595.1640625,8.6344979690145E-5,3.57930674100447E-7,1,0.999253354069792,40.0298881530762,1.99480903322938,20.6700004637241,0.000968358672178737,0.000177552604241312,0.25,4.59310069226169E-7,8.58681572859695E-5,8.97052449750223E-7,9.998951,9.998951,-4597.3994140625,-4592.9287109375,56.8931766577752,20.5390066710609,11.519473,0,0,0,40,4449,10.0011,-4595.1640625,,,,,,,,,,,,,0,,,,0.0049,,,,,,9.998951,,,,
,31213541.2,10.0000267,-9424.40380859375,9.66145362196064E-5,3.65479721246957E-7,1,0.999253354069792,40.0298881530762,1.9947579378401,20.6700004637241,0.0010844895315677,0.000195380553395481,0.25,1.81049721840645E-7,9.61168850274375E-5,7.06807144757317E-7,9.9999542,10.0000992,-9451.4677734375,-9397.33984375,57.0455942190253,20.5430138046053,11.519473,0,0,0,40,4449,10.00145,-9424.40380859375,,,,,,,,,,,,,0,,,,-0.00245,,,,,,10.0000267,,,,
,31213642.43,10.0009117,-14481.7265625,0.000100706949974065,4.65478099859198E-7,1,0.999253354069792,40.0298881530762,1.99483497339573,20.6700004637241,0.00112959396791322,0.000211382924299626,0.25,8.30917847848904E-7,0.000100227576155158,1.41317697941437E-6,10.0009117,10.0009117,-14504.189453125,-14459.263671875,57.0354330482753,20.5416489814882,11.519473,0,0,0,40,4449,10.00175,-14481.7265625,,,,,,,,,,,,,0,,,,0,,,,,,10.0009117,,,,
,31213741.06,10.0003605,-19411.330078125,9.15943965594429E-5,5.49085501074185E-7,1,0.999253354069792,40.0298881530762,1.99487590780678,20.6700004637241,0.00102720072597759,0.000196116775357773,0.25,1.06022799237422E-6,9.11983296675774E-5,1.61982309413926E-6,10.0003386,10.0003824,-19441.099609375,-19381.560546875,57.0393411908714,20.544552188888,10.760172,0,0,0,40,4449,10.001,-19411.330078125,,,,,,,,,,,,,0,,,,0.00245,,,,,,10.0003605,,,,
,31213844.415,10.0003014,-24578.244140625,7.02860416010452E-5,7.32566886983647E-7,1,0.999253354069792,40.0298881530762,1.99479216802358,20.6700004637241,0.000790615848666957,0.000139363568781002,0.25,-2.0490534206719E-7,7.00245139365768E-5,2.51130315396351E-7,10.0003014,10.0003014,-24583.201171875,-24573.287109375,57.0518472471791,20.5442030538188,11.139823,0,0,0,40,4449,10.00155,-24578.244140625,,,,,,,,,,,,,0,,,,0.00245,,,,,,10.0003014,,,,
,31213944.505,10.0003681,-29578.3310546875,5.58871512291433E-5,6.8196254794667E-7,1,0.999253354069792,40.0298881530762,1.99491754471873,20.6700004637241,0.00062688169728849,0.000122758241860746,0.25,8.78474625354917E-7,5.57011167242297E-5,1.2525471989744E-6,10.0003681,10.0003681,-29580.900390625,-29575.76171875,57.1456426694868,20.5432063937238,11.139823,0,0,0,40,4449,10.00075,-29578.3310546875,,,,,,,,,,,,,0,,,,0,,,,,,10.0003681,,,,
,31214047.93,9.9996243,-34750.248046875,5.32257065103433E-5,7.60489369074515E-7,1,0.999253354069792,40.0298881530762,1.99498294278627,20.6700004637241,0.00059757938015452,0.000115832610077673,0.25,7.22679204703583E-7,5.30782049802213E-5,1.09189609398723E-6,9.9996243,9.9996243,-34757.8046875,-34742.69140625,57.1362631272561,20.5446670083739,11.899124,0,0,0,40,4449,10.00095,-34750.248046875,,,,,,,,,,,,,0,,,,0,,,,,,9.9996243,,,,
,31214146.245,9.9990697,-39660.0078125,6.04105400004758E-5,8.56915490317271E-7,1,0.999253354069792,40.0298881530762,1.99488238470309,20.6700004637241,0.000678336885315419,0.000132806123447491,0.25,9.23239519314215E-7,6.02737248434913E-5,1.352951617451E-6,9.9989767,9.9991627,-39690.25390625,-39629.76171875,57.2793011462753,20.5415262989129,11.139823,0,0,0,40,4449,10.00195,-39660.0078125,,,,,,,,,,,,,0,,,,0,,,,,,9.9990697,,,,
,31214246.21,9.9984894,-44657.802734375,7.32958376215076E-5,6.70244129939501E-7,1,0.999253354069792,40.0298881530762,1.99495285692757,20.6700004637241,0.000824521097517145,0.000155463111261669,0.25,5.9939923640596E-7,7.31720236132328E-5,1.1319324959505E-6,9.9984894,9.9984894,-44687.65234375,-44627.953125,56.9064643426022,20.5408976847863,11.139823,0,0,0,40,4449,10.0034,-44657.802734375,,,,,,,,,,,,,0,,,,0.0049,,,,,,9.9984894,,,,
,31214348.775,9.9974918,-49785.37890625,8.82296589791418E-5,8.76717775242335E-7,1,0.999253354069792,40.0298881530762,1.99498899770407,20.6700004637241,0.000990536786999805,0.000201230299620572,0.25,1.95474829642644E-6,8.81180962030002E-5,2.60304025958085E-6,9.9974918,9.9974918,-49790.40234375,-49780.35546875,56.9338213407753,20.543755426344,10.760172,0,0,0,40,4449,10.0066,-49785.37890625,,,,,,,,,,,,,0,,,,0,,,,,,9.9974918,,,,
,31214447.825,9.99707365,-54734.53125,0.000105660138388502,7.66227616036025E-7,1,0.999253354069792,40.0298881530762,1.99493917279621,20.6700004637241,0.00119248493059005,0.000209468039753028,0.25,-4.69075038660679E-7,0.000105599575539103,3.15678312083311E-7,9.997056,9.9970913,-54767.12109375,-54701.94140625,57.2034831799099,20.5438785413389,10.760172,0,0,0,40,4449,10.00975,-54734.53125,,,,,,,,,,,,,0,,,,-0.00245,,,,,,9.99707365,,,,
,31214547.8,9.9959879,-59731.619140625,0.000123545770872047,1.01370258150729E-6,1,0.999253354069792,40.0298881530762,1.99499209489293,20.6700004637241,0.00139370426996012,0.000252513830793504,0.25,1.11154776835582E-7,0.000123529485571024,1.03074679198956E-6,9.995966,9.9960098,-59764.0390625,-59699.19921875,56.9729027667368,20.5437879029302,10.760172,0,0,0,40,4449,10.01455,-59731.619140625,,,,,,,,,,,,,0,,,,-0.0049,,,,,,9.9959879,,,,
,31214645.295,9.99652,-64601.3671875,0.000140554308591971,8.29610281634655E-7,1,0.999253354069792,40.0298881530762,1.9949410762988,20.6700004637241,0.00157769464921909,0.000334851082002472,0.25,4.33230938819942E-6,0.000140567516730794,5.37846735476284E-6,9.99652,9.99652,-64606.0078125,-64596.7265625,57.1808159528522,20.5450097860801,11.139823,0,0,0,40,4449,10.01795,-64601.3671875,,,,,,,,,,,,,0,,,,-0.00245,,,,,,9.99652,,,,
,31214745.94,9.9960442,-69633.6875,0.000158264271065192,7.77954737006843E-7,1,0.999253354069792,40.0298881530762,1.99481660810846,20.6700004637241,0.00178174124503732,0.000351779842150364,0.25,2.63449998843809E-6,0.00015836558186511,3.8071279830383E-6,9.9960442,9.9960442,-69638.6640625,-69628.7109375,57.3191642007561,20.5448467957072,10.760172,0,0,0,40,4449,10.0223,-69633.6875,,,,,,,,,,,,,0,,,,0.0049,,,,,,9.9960442,,,,
,31214846.835,9.9959679,-74675.16796875,0.000178212536588515,9.09484329207019E-7,1,0.999253354069792,40.0298881530762,1.99478505698096,20.6700004637241,0.00200430001464253,0.000411962393084547,0.25,4.36597993864862E-6,0.00017839077015844,5.67877857063325E-6,9.9959679,9.9959679,-74680.21875,-74670.1171875,57.0018230219483,20.546731353089,11.519473,0,0,0,40,4449,10.0247,-74675.16796875,,,,,,,,,,,,,0,,,,-0.00245,,,,,,9.9959679,,,,
,31214947.67,9.99524215,-79714.79296875,0.000198527909732409,1.16815290508849E-6,1,0.999253354069792,40.0298881530762,1.99486193844459,20.6700004637241,0.00223508660427993,0.000451639949990017,0.25,4.2176931776735E-6,0.000198809308339413,5.66560445475801E-6,9.9951878,9.9952965,-79742.3828125,-79687.203125,57.2425646058714,20.5439986918522,11.519473,0,0,0,40,4449,10.0292,-79714.79296875,,,,,,,,,,,,,0,,,,0.00245,,,,,,9.99524215,,,,
,31215047.685,9.9949341,-84714.6875,0.000215229091038054,9.41140748740229E-7,1,0.999253354069792,40.0298881530762,1.99492421325253,20.6700004637241,0.00242920726837815,0.000461284098533503,0.25,2.0683026997351E-6,0.000215630982139278,3.61497908378779E-6,9.9949341,9.9949341,-84719.765625,-84709.609375,56.8830154870253,20.5476392409793,11.519473,0,0,0,40,4449,10.0337,-84714.6875,,,,,,,,,,,,,0,,,,0,,,,,,9.9949341,,,,
,31215140.465,9.994873,-89348.86328125,0.000230240978354706,1.02256651137194E-6,1,0.999253354069792,40.0298881530762,1.99504429907708,20.6700004637241,0.00260152625028507,0.000483000293012503,0.25,1.29433139517909E-6,0.000230750543555414,2.92532045310279E-6,9.994873,9.994873,-89351.4296875,-89346.296875,57.0377779338329,20.5456226258366,11.139823,0,0,0,40,4449,10.038,-89348.86328125,,,,,,,,,,,,,0,,,,0,,,,,,9.994873,,,,
,31215248.955,9.9979811,-86114.9296875,0.000217088556942731,1.20123370736976E-6,1,0.999253354069792,40.0298881530762,1.99502991731337,20.6700004637241,0.00244706591734043,0.000484745252860946,0.25,3.8086450642917E-6,0.00021750291690439,5.36628408230692E-6,9.9978762,9.998086,-86145.03125,-86084.828125,57.0706063316407,20.5441303351228,11.139823,0,0,0,40,4449,10.0388,-86114.9296875,,,,,,,,,,,,,0,,,,-0.00245,,,,,,9.9979811,,,,
,31215348.94,10.00104285,-81120.5390625,0.000199682690568522,1.07955322145838E-6,1,0.999253354069792,40.0298881530762,1.99503171678337,20.6700004637241,0.00225468870265599,0.00042000986811313,0.25,1.2091675506008E-6,0.000200008719316215,2.65595838830012E-6,10.0009356,10.0011501,-81147.9921875,-81093.0859375,57.1808159528522,20.5451950110742,11.139823,0,0,0,40,4449,10.0365,-81120.5390625,,,,,,,,,,,,,0,,,,0,,,,,,10.00104285,,,,
,31215451.875,10.0024686,-75972.98046875,0.000181718234263074,8.5584022245105E-7,1,0.999253354069792,40.0298881530762,1.99497437556958,20.6700004637241,0.00205174091953092,0.00037785871866527,0.25,7.12530861161027E-7,0.000181946185469123,2.04347790360973E-6,10.0024023,10.0025349,-76005.6875,-75940.2734375,57.0917103016599,20.5469858886065,11.519473,0,0,0,40,4449,10.0341,-75972.98046875,,,,,,,,,,,,,0,,,,-0.00245,,,,,,10.0024686,,,,
,31215555.025,10.0031252,-70818.05078125,0.000163659117102091,9.60595261685623E-7,1,0.999253354069792,40.0298881530762,1.99495145109466,20.6700004637241,0.00184781785587319,0.000335870785239828,0.25,2.50659854310009E-7,0.000163798558991378,1.4594343885016E-6,10.0030718,10.0031786,-70843.15625,-70792.9453125,57.0127658212176,20.548506910467,11.139823,0,0,0,40,4449,10.03175,-70818.05078125,,,,,,,,,,,,,0,,,,0,,,,,,10.0031252,,,,
,31215654.915,10.0043745,-65826.30078125,0.000143785851976593,1.00465104333148E-6,1,0.999253354069792,40.0298881530762,1.99491792881211,20.6700004637241,0.00162507625092291,0.000281831677835299,0.25,-9.48694069515867E-7,0.00014385507252975,1.18722311601887E-7,10.0043745,10.0043745,-65851.734375,-65800.8671875,57.3918556530445,20.5450797848824,10.760172,0,0,0,40,4449,10.0281,-65826.30078125,,,,,,,,,,,,,0,,,,-0.0049,,,,,,10.0043745,,,,
,31215744.52,10.0042076,-61350.828125,0.000129252633346348,8.1429110609757E-7,1,0.999253354069792,40.0298881530762,1.99486625428025,20.6700004637241,0.00146032578017757,0.000252495055702068,0.25,-9.21020563539604E-7,0.000129262880578545,4.09800478447585E-8,10.0042076,10.0042076,-61353.16796875,-61348.48828125,57.0831123879483,20.546495298407,11.139823,0,0,0,40,4449,10.02285,-61350.828125,,,,,,,,,,,,,0,,,,0,,,,,,10.0042076,,,,
,31215834.085,10.0035782,-56873.546875,0.000110289669974175,8.74202636539979E-7,1,0.999253354069792,40.0298881530762,1.99498519415619,20.6700004637241,0.00124067955805261,0.000242783024535943,0.25,1.64463035957479E-6,0.000110233569092793,2.46414616581627E-6,10.0035782,10.0035782,-56890.89453125,-56856.19921875,57.3488660844868,20.5460394575531,10.760172,0,0,0,40,4449,10.01985,-56873.546875,,,,,,,,,,,,,0,,,,-0.00245,,,,,,10.0035782,,,,
,31215923.845,10.0042038,-52389.12109375,9.70997992738223E-5,8.1147823831201E-7,1,0.999253354069792,40.0298881530762,1.99501399171336,20.6700004637241,0.00109195154823563,0.000213018491342914,0.25,1.39418206842455E-6,9.70080472985423E-5,2.11194666679787E-6,10.0042038,10.0042038,-52414.30859375,-52363.93359375,57.3457395704099,20.5449781329677,11.139823,0,0,0,40,4449,10.0164,-52389.12109375,,,,,,,,,,,,,0,,,,0,,,,,,10.0042038,,,,
,31216013.435,10.0038309,-47908.923828125,8.00861496994902E-5,8.43602059769426E-7,1,0.999253354069792,40.0298881530762,1.99511531458458,20.6700004637241,0.000898850742477095,0.00018342413598045,0.25,1.84676378424853E-6,7.99690419164113E-5,2.4324365226094E-6,10.0037985,10.0038633,-47941.23046875,-47876.6171875,56.9947883652753,20.5439040572903,11.139823,0,0,0,40,4449,10.01375,-47908.923828125,,,,,,,,,,,,,0,,,,-0.0049,,,,,,10.0038309,,,,
,31216104.445,10.0029907,-43361.16015625,6.30112005096092E-5,6.63745057311424E-7,1,0.999253354069792,40.0298881530762,1.99492314253843,20.6700004637241,0.000711858977659836,0.000116199576604124,0.25,-1.03018234946936E-6,6.29074306181904E-5,-5.71626449672965E-7,10.0029907,10.0029907,-43383.4140625,-43338.90625,56.9275683126214,20.5419962438503,11.139823,0,0,0,40,4449,10.0103,-43361.16015625,,,,,,,,,,,,,0,,,,0,,,,,,10.0029907,,,,
,31216193.845,10.0027857,-38894.046875,4.64522789511362E-5,5.99113661361677E-7,1,0.999253354069792,40.0298881530762,1.99501024581656,20.6700004637241,0.000523028260727711,9.41372746981639E-5,0.25,2.19197177389022E-9,4.63483634153471E-5,3.33019248824191E-7,10.0027857,10.0027857,-38921.33984375,-38866.75390625,57.2112994651022,20.5421739694268,11.139823,0,0,0,40,4449,10.00765,-38894.046875,,,,,,,,,,,,,0,,,,-0.00245,,,,,,10.0027857,,,,
,31216284.97,10.0027981,-34341.59375,3.267321943944E-5,7.39442725795828E-7,1,0.999253354069792,40.0298881530762,1.99502367453444,20.6700004637241,0.000368068179348297,6.41730203211327E-5,0.25,-1.71645012928961E-7,3.25855445626561E-5,5.61231592998411E-8,10.0027981,10.0027981,-34369.328125,-34313.859375,56.668849272756,20.5430860642229,11.519473,0,0,0,40,4449,10.00605,-34341.59375,,,,,,,,,,,,,0,,,,0,,,,,,10.0027981,,,,
,31216373.195,10.00208425,-29929.2392578125,1.69167666130737E-5,7.25303392485437E-7,1,0.999253354069792,40.0298881530762,1.99491375381337,20.6700004637241,0.000191119957595924,2.95897933571536E-5,0.25,-4.07306755564305E-7,1.68656244565485E-5,-2.91633464322207E-7,10.0019684,10.0022001,-29961.33984375,-29897.138671875,56.8603482599676,20.5418523172067,11.519473,0,0,0,40,4449,10.0057,-29929.2392578125,,,,,,,,,,,,,0,,,,-0.00245,,,,,,10.00208425,,,,
,31216463.06,10.0013285,-25439.0927734375,3.04091862298987E-6,4.30917602271644E-7,1,0.999253354069792,40.0298881530762,1.99497691746941,20.6700004637241,3.81360162490741E-5,-1.58511049668994E-5,0.25,-1.95499561773332E-6,3.04257235112126E-6,-1.92801002171592E-6,10.0013285,10.0013285,-25469.109375,-25409.076171875,57.2191157502945,20.540936736636,10.760172,0,0,0,40,4449,10.00375,-25439.0927734375,,,,,,,,,,,,,0,,,,0,,,,,,10.0013285,,,,
,31216551.485,10.0001583,-21019.1201171875,-1.20172001497669E-5,5.31976553691019E-7,1,0.999253354069792,40.0298881530762,1.99495284615001,20.6700004637241,-0.00013306389245001,-3.54033609394921E-5,0.25,-9.97996938106106E-7,-1.19617261577943E-5,-1.06916337106912E-6,10.0001583,10.0001583,-21051.642578125,-20986.59765625,57.0792042453522,20.5413164348514,10.760172,0,0,0,40,4449,10.0044,-21019.1201171875,,,,,,,,,,,,,0,,,,0.00245,,,,,,10.0001583,,,,
,31216639.925,10.00029035,-16599.166015625,-2.68541285362295E-5,5.15310319268015E-7,1,0.999253354069792,40.0298881530762,1.99488993920741,20.6700004637241,-0.000299201683127799,-6.80020305938572E-5,0.25,-1.25209520314891E-6,-2.67252972720048E-5,-1.40673711619712E-6,10.000246,10.0003347,-16624.22265625,-16574.109375,57.0307432771599,20.5416077021824,11.519473,0,0,0,40,4449,10.00395,-16599.166015625,,,,,,,,,,,,,0,,,,-0.00245,,,,,,10.00029035,,,,
,31216728.93,9.9991627,-12151.3032226563,-4.08684245444661E-5,3.9779113447317E-7,1,0.999253354069792,40.0298881530762,1.99489084573518,20.6700004637241,-0.000457933852748944,-8.79605191865861E-5,0.25,-5.39345675266697E-7,-4.06644787023172E-5,-7.6769336509862E-7,9.9991627,9.9991627,-12176.046875,-12126.5595703125,57.2238055214099,20.5433456760355,11.139823,0,0,0,40,4449,10.0046,-12151.3032226563,,,,,,,,,,,,,0,,,,-0.00245,,,,,,9.9991627,,,,
,31216817.98,9.9984732,-7700.69897460937,-5.44145949035241E-5,4.1575210695509E-7,1,0.999253354069792,40.0298881530762,1.99490980421671,20.6700004637241,-0.000608175332295343,-0.000124552698079153,0.25,-1.40194616388226E-6,-5.41201288798989E-5,-1.68425611086996E-6,9.9984732,9.9984732,-7733.232421875,-7668.16552734375,57.3050948874099,20.5428180399421,10.760172,0,0,0,40,4449,10.00485,-7700.69897460937,,,,,,,,,,,,,0,,,,-0.00245,,,,,,9.9984732,,,,
,31216908.03,9.9986057,-3197.41955566406,-6.77274323146983E-5,2.9645406542493E-7,1,0.999253354069792,40.0298881530762,1.99484897241286,20.6700004637241,-0.000759153063803244,-0.00014126413900032,0.25,-5.45419889716239E-7,-6.73464987865059E-5,-8.81182112553489E-7,9.9986057,9.9986057,-3224.642578125,-3170.19653320313,57.1675282680253,20.5445953134837,10.760172,0,0,0,40,4449,10.0052,-3197.41955566406,,,,,,,,,,,,,0,,,,-0.00245,,,,,,9.9986057,,,,
,31217004.89,9.9995613,1640.77587890625,-7.97660761319308E-5,2.73592081877914E-7,1,0.999253354069792,40.0298881530762,1.99481419676816,20.6700004637241,-0.00089378747314488,-0.000167547547015316,0.25,-7.56449492418144E-7,-7.93098491565003E-5,-1.14323917922398E-6,9.9995613,9.9995613,1635.52770996094,1646.02404785156,56.9588334533906,20.5444961296917,11.519473,0,0,0,40,4449,10.0057,1640.77587890625,,,,,,,,,,,,,0,,,,0,,,,,,9.9995613,,,,
,31217101.09,9.9990711,6448.0634765625,-9.11323277672451E-5,3.50000817577632E-7,1,0.999253354069792,40.0298881530762,1.99497538809403,20.6700004637241,-0.00102143983295052,-0.000192055318915812,0.25,-8.84053836266293E-7,-9.06386142215006E-5,-1.35612338098859E-6,9.9990711,9.9990711,6418.0283203125,6478.0986328125,56.6500901882945,20.5403609000173,10.760172,0,0,0,40,4449,10.00655,6448.0634765625,,,,,,,,,,,,,0,,,,-0.00245,,,,,,9.9990711,,,,
,31217200.54,10.0001411,11419.2900390625,-9.93565753976116E-5,3.6456728307374E-7,1,0.999253354069792,40.0298881530762,1.99493251302155,20.6700004637241,-0.00111440826094332,-0.000207349850211365,0.25,-7.39136952252764E-7,-9.88578799333951E-5,-1.29171884763863E-6,10.0001411,10.0001411,11416.7890625,11421.791015625,57.088583787583,20.5369961015804,11.139823,0,0,0,40,4449,10.0061,11419.2900390625,,,,,,,,,,,,,0,,,,0.0049,,,,,,10.0001411,,,,
,31217298.595,10.0007868,16318.90625,-9.80271205686598E-5,4.71621259624743E-7,1,0.999253354069792,40.0298881530762,1.99500421764994,20.6700004637241,-0.00110080310336097,-0.000200244592855662,0.25,-3.00918357742766E-7,-9.7579791151119E-5,-8.82801256718228E-7,10.0006533,10.0009203,16288.859375,16348.953125,57.1761261817368,20.5399556106519,11.139823,0,0,0,40,4449,10.0057,16318.90625,,,,,,,,,,,,,0,,,,-0.00245,,,,,,10.0007868,,,,
,31217397.375,10.0006666,21256.2548828125,-8.3294013990897E-5,4.95796248362135E-7,1,0.999253354069792,40.0298881530762,1.99498316587594,20.6700004637241,-0.000935167303692152,-0.000173715438545814,0.25,-5.38838068793005E-7,-8.29513918467347E-5,-1.05949415613113E-6,10.0006666,10.0006666,21251.26953125,21261.240234375,56.7376325824483,20.5390249881691,11.139823,0,0,0,40,4449,10.0061,21256.2548828125,,,,,,,,,,,,,0,,,,0.0049,,,,,,10.0006666,,,,
,31217496.425,9.9999714,26208.736328125,-6.37862140867956E-5,7.18924486228827E-7,1,0.999253354069792,40.0298881530762,1.99495934729854,20.6700004637241,-0.000716853736380968,-0.000131115897493671,0.25,-2.18088581226549E-7,-6.35568779847905E-5,-6.36324868404577E-7,9.9999266,10.0000162,26183.6328125,26233.83984375,57.0307432771599,20.5378919592901,11.139823,0,0,0,40,4449,10.00575,26208.736328125,,,,,,,,,,,,,0,,,,0.00245,,,,,,9.9999714,,,,
,31217593.755,9.99955175,31071.568359375,-5.25073184088909E-5,7.84309052958674E-7,1,0.999253354069792,40.0298881530762,1.99492062319894,20.6700004637241,-0.000588501714124871,-0.000118480689018389,0.25,-1.09970566607678E-6,-5.23388454206292E-5,-1.4541777408923E-6,9.9994907,9.9996128,31041.384765625,31101.751953125,57.0799858738714,20.5391294443404,11.519473,0,0,0,40,4449,10.0052,31071.568359375,,,,,,,,,,,,,0,,,,0.0049,,,,,,9.99955175,,,,
,31217692.47,9.9990411,36007.09375,-5.37410842094159E-5,6.5454671980165E-7,1,0.999253354069792,40.0298881530762,1.99498814499084,20.6700004637241,-0.000604773575317764,-0.000109597409770857,0.25,-7.2128762693174E-8,-5.36039074098574E-5,-4.49291032620264E-7,9.9989653,9.9991169,35974.8046875,36039.3828125,57.0323065341983,20.5360886221919,10.760172,0,0,0,40,4449,10.006,36007.09375,,,,,,,,,,,,,0,,,,-0.00245,,,,,,9.9990411,,,,
,31217794,9.9982586,41081.689453125,-6.24046132491105E-5,6.1796947452983E-7,1,0.999253354069792,40.0298881530762,1.99505114757411,20.6700004637241,-0.000703192948397803,-0.000124426681656773,0.25,1.84937064838041E-7,-6.22808075114063E-5,-2.64014266081263E-7,9.9982586,9.9982586,41076.94140625,41086.4375,56.7829670365637,20.53492642649,10.760172,0,0,0,40,4449,10.0079,41081.689453125,,,,,,,,,,,,,0,,,,0,,,,,,9.9982586,,,,
,31217893.205,9.9983091,46039.5,-7.71238457346035E-5,6.59497655429612E-7,1,0.999253354069792,40.0298881530762,1.99496173965601,20.6700004637241,-0.000867676655686821,-0.000163801783967736,0.25,-6.45837258789448E-7,-7.70045229395135E-5,-1.20850949334048E-6,9.9983091,9.9983091,46009.30859375,46069.69140625,57.1425161554099,20.5367090672346,10.760172,0,0,0,40,4449,10.0098,46039.5,,,,,,,,,,,,,0,,,,-0.00245,,,,,,9.9983091,,,,
,31217989.55,9.99737025,50857.19921875,-9.30765582051655E-5,8.76608385416845E-7,1,0.999253354069792,40.0298881530762,1.99504483614898,20.6700004637241,-0.00104807578887645,-0.000195762553034637,0.25,-5.92706318602806E-7,-9.29797995550829E-5,-1.27962969311566E-6,9.9973021,9.9974384,50832.11328125,50882.28515625,57.3582456267176,20.5376631364268,11.139823,0,0,0,40,4449,10.0122,50857.19921875,,,,,,,,,,,,,0,,,,0,,,,,,9.99737025,,,,
,31218078.31,9.9970713,55292.462890625,-0.000106816199228218,7.38330906267035E-7,1,0.999253354069792,40.0298881530762,1.99491608581415,20.6700004637241,-0.0012011246619626,-0.000236515737891127,0.25,-1.7197685071968E-6,-0.000106744520711634,-2.51227084322294E-6,9.9969168,9.9972258,55260.09765625,55324.828125,57.0424677049483,20.5374543743896,10.38052,0,0,0,40,4449,10.0149,55292.462890625,,,,,,,,,,,,,0,,,,0.0049,,,,,,9.9970713,,,,
,31218166.22,9.9962597,59685.310546875,-0.00012126595862644,8.11425347042012E-7,1,0.999253354069792,40.0298881530762,1.99489851447552,20.6700004637241,-0.00136514711415682,-0.000263218491521539,0.25,-1.47201083745286E-6,-0.000121239300061836,-2.37445259092463E-6,9.9962597,9.9962597,59652.4140625,59718.20703125,56.9213152844676,20.5361169787447,10.760172,0,0,0,40,4449,10.01885,59685.310546875,,,,,,,,,,,,,0,,,,0,,,,,,9.9962597,,,,
,31218257.6,9.9963341,64253.763671875,-0.000137394371630281,8.0140511259038E-7,1,0.999253354069792,40.0298881530762,1.99490825359813,20.6700004637241,-0.00154851773417732,-0.000291992132770754,0.25,-1.10579252075825E-6,-0.000137426242236474,-2.12760473484135E-6,9.9963284,9.9963398,64221.078125,64286.44921875,56.9721211382176,20.5372735736092,11.139823,0,0,0,40,4449,10.02165,64253.763671875,,,,,,,,,,,,,0,,,,-0.0049,,,,,,9.9963341,,,,
,31218348.225,9.9961047,68784.109375,-0.000153118550060123,8.30112128429502E-7,1,0.999253354069792,40.0298881530762,1.9948907654674,20.6700004637241,-0.00172694746833563,-0.000322567273873648,0.25,-9.74482391391203E-7,-0.000153217083868863,-2.10891257628901E-6,9.9960136,9.9961958,68759.0859375,68809.1328125,56.9791557948906,20.5354252407929,10.760172,0,0,0,40,4449,10.02505,68784.109375,,,,,,,,,,,,,0,,,,0.00245,,,,,,9.9961047,,,,
,31218436.92,9.9958782,73214.56640625,-0.000169575871667276,8.3111316603078E-7,1,0.999253354069792,40.0298881530762,1.99494345735669,20.6700004637241,-0.00191488432821753,-0.000348688217746804,0.25,-3.18434608757284E-7,-0.000169753570493052,-1.56630143987987E-6,9.9958782,9.9958782,73182.1171875,73247.015625,56.7876568076791,20.532759796955,10.760172,0,0,0,40,4449,10.02855,73214.56640625,,,,,,,,,,,,,0,,,,0,,,,,,9.9958782,,,,
,31218526.795,9.9959183,77710.43359375,-0.000186936957773347,8.64582775003847E-7,1,0.999253354069792,40.0298881530762,1.99496216110245,20.6700004637241,-0.00211016015609877,-0.000393079190681565,0.25,-1.12026816967188E-6,-0.000187194012919612,-2.48514724987222E-6,9.9959183,9.9959183,77680.3984375,77740.46875,57.0870205305445,20.5347796238546,11.139823,0,0,0,40,4449,10.03215,77710.43359375,,,,,,,,,,,,,0,,,,-0.00245,,,,,,9.9959183,,,,
,31218616.765,9.9953547,82206.62109375,-0.000202713217817795,9.45722794683702E-7,1,0.999253354069792,40.0298881530762,1.99503419020899,20.6700004637241,-0.00228609791233947,-0.000443054209721642,0.25,-2.70319710201236E-6,-0.000203049737701278,-4.17063357032731E-6,9.9953547,9.9953547,82204.1640625,82209.078125,56.9650864815445,20.5364761604525,10.760172,0,0,0,40,4449,10.0363,82206.62109375,,,,,,,,,,,,,0,,,,0.00245,,,,,,9.9953547,,,,
,31218702.315,9.9948788,86482.28515625,-0.000217283067470027,1.05682234130541E-6,1,0.999253354069792,40.0298881530762,1.99500241603779,20.6700004637241,-0.00244781862784959,-0.000493355037472527,0.25,-4.53618173840971E-6,-0.000217698174428484,-6.09516808011261E-6,9.9948044,9.9949532,86452.5078125,86512.0625,56.8204852054868,20.5362750941218,11.139823,0,0,0,40,4449,10.03875,86482.28515625,,,,,,,,,,,,,0,,,,-0.00245,,,,,,9.9948788,,,,
,31218799.435,9.9963837,89411.57421875,-0.000229869754718167,1.03401807941966E-6,1,0.999253354069792,40.0298881530762,1.99495433815535,20.6700004637241,-0.00259342990155864,-0.000503335933173513,0.25,-3.16107801468291E-6,-0.000230366241428127,-4.79334679920485E-6,9.9963837,9.9963837,89381.75,89441.3984375,57.1182856713137,20.5355364959299,11.139823,0,0,0,40,4449,10.0433,89411.57421875,,,,,,,,,,,,,0,,,,-0.00245,,,,,,9.9963837,,,,
,31218883.86,9.9990206,85191.8359375,-0.000215311480660856,1.04939786886916E-6,1,0.999253354069792,40.0298881530762,1.9950342620684,20.6700004637241,-0.00242985533980368,-0.000464230145297826,0.25,-2.31259836243663E-6,-0.000215719022732205,-3.85837400555912E-6,9.9989996,9.9990416,85169.2265625,85214.4453125,57.0096393071407,20.5346273244228,10.760172,0,0,0,40,4449,10.04245,85191.8359375,,,,,,,,,,,,,0,,,,0,,,,,,9.9990206,,,,
,31218973.895,10.00162175,80690.83203125,-0.000196743115576044,7.46560817589341E-7,1,0.999253354069792,40.0298881530762,1.99509704592255,20.6700004637241,-0.00222233508896671,-0.000409164145278808,0.25,-7.77352525003342E-7,-0.000197061065445735,-2.20362647718639E-6,10.0014868,10.0017567,80660.75,80720.9140625,56.9650864815445,20.5337216401397,10.760172,0,0,0,40,4449,10.0414,80690.83203125,,,,,,,,,,,,,0,,,,0.00245,,,,,,10.00162175,,,,
,31219066.295,10.0027361,76069.50390625,-0.000181850847302008,1.02635175076474E-6,1,0.999253354069792,40.0298881530762,1.99511616381505,20.6700004637241,-0.00204981962737147,-0.000398003367693618,0.25,-2.46916237890029E-6,-0.000182067499499074,-3.80309568150633E-6,10.0027361,10.0027361,76036.890625,76102.1171875,57.2910255740638,20.5367878960887,10.38052,0,0,0,40,4449,10.03865,76069.50390625,,,,,,,,,,,,,0,,,,0.00245,,,,,,10.0027361,,,,
,31219158.89,10.0034218,71440.609375,-0.000164606071348171,8.13098965092224E-7,1,0.999253354069792,40.0298881530762,1.99495228808378,20.6700004637241,-0.00185743875806856,-0.000344315363665766,0.25,-8.27334747427231E-7,-0.000164750648288234,-2.04252660056398E-6,10.0034218,10.0034218,71438.359375,71442.859375,56.9338213407753,20.537828982334,11.519473,0,0,0,40,4449,10.0353,71440.609375,,,,,,,,,,,,,0,,,,0,,,,,,10.0034218,,,,
,31219247.22,10.0040379,67025.25390625,-0.000148246763301698,9.95572343862207E-7,1,0.999253354069792,40.0298881530762,1.99521381297788,20.6700004637241,-0.0016763840164428,-0.000288004432273672,0.25,1.21088684623444E-6,-0.000148335514837003,1.11759237384189E-7,10.0040379,10.0040379,66995.25,67055.2578125,56.9439825115252,20.5371009569527,11.139823,0,0,0,40,4449,10.031,67025.25390625,,,,,,,,,,,,,0,,,,-0.00245,,,,,,10.0040379,,,,
,31219336.9,10.00352765,62544.7421875,-0.000131816099052442,1.07654231586145E-6,1,0.999253354069792,40.0298881530762,1.99510903764122,20.6700004637241,-0.00148428299172673,-0.000287200197604035,0.25,-1.6872385630038E-6,-0.000131821521760548,-2.66827379581758E-6,10.00348,10.0035753,62512.53125,62576.953125,56.7712426087752,20.5383396860422,10.760172,0,0,0,40,4449,10.0286,62544.7421875,,,,,,,,,,,,,0,,,,0,,,,,,10.00352765,,,,
,31219428.825,10.0039387,57948.626953125,-0.000116815275687229,7.798152142699E-7,1,0.999253354069792,40.0298881530762,1.99502089412214,20.6700004637241,-0.00131743233430125,-0.00023950296399795,0.25,-1.74696499728037E-7,-0.000116779582871719,-1.04378734279319E-6,10.0039387,10.0039387,57918.0390625,57979.21484375,57.2097362080637,20.5410777168412,11.139823,0,0,0,40,4449,10.02465,57948.626953125,,,,,,,,,,,,,0,,,,0,,,,,,10.0039387,,,,
,31219518.95,10.00391145,53443.046875,-9.91576269639954E-5,8.89099977732109E-7,1,0.999253354069792,40.0298881530762,1.99508159220643,20.6700004637241,-0.00111705822498381,-0.000207509341274496,0.25,-5.3124714685238E-7,-9.90809398499896E-5,-1.26603024639567E-6,10.0037889,10.004034,53415.05078125,53471.04296875,56.8736359447945,20.5391047641753,10.760172,0,0,0,40,4449,10.02175,53443.046875,,,,,,,,,,,,,0,,,,-0.0049,,,,,,10.00391145,,,,
,31219612.725,10.003993,48757.7890625,-8.2109844570387E-5,5.71555052275209E-7,1,0.999253354069792,40.0298881530762,1.99513480110359,20.6700004637241,-0.00092509703993061,-0.000168958953785393,0.25,-1.96169265644069E-7,-8.20093832213632E-5,-7.99997424673507E-7,10.003993,10.003993,48753.01171875,48762.56640625,56.8017261210252,20.5370553304105,11.519473,0,0,0,40,4449,10.0185,48757.7890625,,,,,,,,,,,,,0,,,,0,,,,,,10.003993,,,,
,31219708.08,10.0036926,43992.353515625,-6.35859102681271E-5,8.93746033938781E-7,1,0.999253354069792,40.0298881530762,1.99506835052322,20.6700004637241,-0.000714694263911171,-0.000138128120619309,0.25,-8.10487611528429E-7,-6.34719750085829E-5,-1.27097518200619E-6,10.0036926,10.0036926,43965.0859375,44019.62109375,56.2530229005252,20.5366552053369,11.139823,0,0,0,40,4449,10.01515,43992.353515625,,,,,,,,,,,,,0,,,,0.00245,,,,,,10.0036926,,,,
,31219807.43,10.0032339,39024.69921875,-4.66250230162255E-5,6.37061417087974E-7,1,0.999253354069792,40.0298881530762,1.99502065481525,20.6700004637241,-0.000526500753379493,-8.60554091809296E-5,0.25,7.47004683677185E-7,-4.6526705685879E-5,4.13086181904447E-7,10.003109,10.0033588,38992.5234375,39056.875,56.7610814380252,20.5421131347582,10.760172,0,0,0,40,4449,10.01205,39024.69921875,,,,,,,,,,,,,0,,,,-0.0049,,,,,,10.0032339,,,,
,31219910,10.0027189,33897.9765625,-2.89683654829713E-5,7.43968664996885E-7,1,0.999253354069792,40.0298881530762,1.99526933126483,20.6700004637241,-0.000325602341550054,-6.10897797191972E-5,0.25,-2.20550572403841E-7,-2.88866802047214E-5,-4.20943653722375E-7,10.0027189,10.0027189,33895.79296875,33900.16015625,56.8204852054868,20.5409854267347,11.139823,0,0,0,40,4449,10.01035,33897.9765625,,,,,,,,,,,,,0,,,,-0.0049,,,,,,10.0027189,,,,
,31220009.61,10.0018177,28920.7060546875,-1.12832554038781E-5,5.55202231985881E-7,1,0.999253354069792,40.0298881530762,1.99497013958587,20.6700004637241,-0.000125784419827151,-2.90913957397817E-5,0.25,-5.60748987086995E-7,-1.12423524400614E-5,-6.34630092027952E-7,10.0018177,10.0018177,28918.333984375,28923.078125,57.1104693861214,20.5421833077086,11.139823,0,0,0,40,4449,10.0092,28920.7060546875,,,,,,,,,,,,,0,,,,-0.00245,,,,,,10.0018177,,,,
,31220111.155,10.0013762,23845.4580078125,5.15970900289571E-6,6.47316377865766E-7,1,0.999253354069792,40.0298881530762,1.99507676161096,20.6700004637241,5.79133472214666E-5,1.09534650387866E-5,0.25,4.9403742845781E-8,5.13971141572017E-6,8.24166595432159E-8,10.0013762,10.0013762,23810.396484375,23880.51953125,57.0229269919676,20.5416226776967,10.760172,0,0,0,40,4449,10.0076,23845.4580078125,,,,,,,,,,,,,0,,,,-0.00245,,,,,,10.0013762,,,,
,31220212.71,10.0005817,18768.2392578125,2.10277539205933E-5,5.40534959880002E-7,1,0.999253354069792,40.0298881530762,1.99526431078209,20.6700004637241,0.00023475368142308,5.11485077883807E-5,0.25,7.88755160582189E-7,2.09322019867017E-5,9.1396405802741E-7,10.0005817,10.0005817,18763.451171875,18773.02734375,56.9283499411406,20.5423079519539,10.760172,0,0,0,40,4449,10.0067,18768.2392578125,,,,,,,,,,,,,0,,,,-0.0049,,,,,,10.0005817,,,,
,31220313.345,9.9998617,13738.8471679688,3.68802108001351E-5,4.52354963223275E-7,1,0.999253354069792,40.0298881530762,1.99520959874584,20.6700004637241,0.000413368782287076,7.93812400987314E-5,0.25,4.80825282356357E-7,3.67012231445413E-5,6.91230671838847E-7,9.9998617,9.9998617,13736.306640625,13741.3876953125,56.7134020983521,20.5404857456922,10.38052,0,0,0,40,4449,10.0075,13738.8471679688,,,,,,,,,,,,,0,,,,0,,,,,,9.9998617,,,,
,31220414.485,9.99889135,8685.830078125,5.21349587427762E-5,4.06208258709424E-7,1,0.999253354069792,40.0298881530762,1.99506656794857,20.6700004637241,0.00058523972224879,0.000105567314105891,0.25,1.11857022392634E-7,5.18633144439368E-5,3.92636817149312E-7,9.9988213,9.9989614,8653.228515625,8718.431640625,56.851750346256,20.5426171289971,11.519473,0,0,0,40,4449,10.00925,8685.830078125,,,,,,,,,,,,,0,,,,0,,,,,,9.99889135,,,,
,31220512.105,9.99937105,3807.97009277344,6.6744707868769E-5,3.3980217432517E-7,1,0.999253354069792,40.0298881530762,1.99516321964333,20.6700004637241,0.000748717492687027,0.000136772979715838,0.25,3.1493662452676E-7,6.637293632642E-5,6.49853172484541E-7,9.9993639,9.9993782,3780.61547851562,3835.32470703125,56.8408075469868,20.5449605296519,11.139823,0,0,0,40,4449,10.00895,3807.97009277344,,,,,,,,,,,,,0,,,,0,,,,,,9.99937105,,,,
,31220587.985,10.00319195,23.0784119665623,7.65748508143915E-5,4.00146358768308E-7,1,0.999253354069792,40.0298881530762,1.99508671940823,20.6700004637241,0.000859524794676143,0.000152719402871902,0.25,7.81472130505E-9,7.61349549431959E-5,3.76893712048517E-7,10.0027847,10.0035992,-0.548055827617645,46.7048797607422,56.9377294833714,20.5471366578446,10.760172,0,0,0,40,4417,10.00705,23.0784119665623,,,,,,,,,,,,,0,,,,0.0049,,,,,,10.00319195,,,,