File: data/doubleLayers/dl_0-125/ppms/data/DD213_7_HYST_100OE_20K.DAT
[Header]
; VSM Data File (default extension .dat)
; Copyright (c) 2003-2013, Quantum Design, Inc. All rights reserved.
TITLE,
FILEOPENTIME,31221450.36,12/28/2018,4:39 pm
BYAPP,VSM,2.0,2.0
INFO,PPMS VSM Option Release 1.4.10 Build 1,APPNAME
INFO,Quantum Design Linear Motor Servo Controller,MOTOR_MODULE_NAME
INFO,3101-100 M1,MOTOR_HW_VERSION
INFO,MMC1014,MOTOR_SERIAL_NUMBER
INFO,SRV No X-over 01.03.11,MOTOR_SOFTWARE_VERSION
INFO,Quantum Design VSM Detection Module,VSM_MODULE_NAME
INFO,3101-150 F0,VSM_HW_VERSION
INFO,VSM707,VSM_SERIAL_NUMBER
INFO,VSM No X-over 01.02.05 May 20 2008 13:51:47,VSM_SOFTWARE_VERSION
INFO,704,PREAMP_SERIAL_NUMBER
INFO,822,COIL_SERIAL_NUMBER
INFO,0,MOMENT_UNITS
INFO,CoFe2O4,SAMPLE_MATERIAL
INFO,Double Layer thin concentration,SAMPLE_COMMENT
INFO,29.55,SAMPLE_MASS
INFO,,SAMPLE_VOLUME
INFO,,SAMPLE_MOLECULAR_WEIGHT
INFO,,SAMPLE_SIZE
INFO,,SAMPLE_SHAPE
DATATYPE,COMMENT,1
DATATYPE,TIME,2
STARTUPAXIS,X,2
STARTUPAXIS,Y1,5
[Data]
Comment,Time Stamp (sec),Temperature (K),Magnetic Field (Oe),Moment (emu),M. Std. Err. (emu),Transport Action,Averaging Time (sec),Frequency (Hz),Peak Amplitude (mm),Center Position (mm),Coil Signal' (mV),Coil Signal" (mV),Range (mV),M. Quad. Signal (emu),M. Raw' (emu),M. Raw" (emu),Min. Temperature (K),Max. Temperature (K),Min. Field (Oe),Max. Field (Oe),Mass (grams),Motor Lag (deg),Pressure (Torr),VSM Status (code),Motor Status (code),Measure Status (code),Measure Count,PPMS Status (code),System Temp. (K),System Field (Oe),Sample Position (deg),Bridge 1 Resistance (ohms),Bridge 1 Excitation (에),Bridge 2 Resistance (ohms),Bridge 2 Excitation (에),Bridge 3 Resistance (ohms),Bridge 3 Excitation (에),Bridge 4 Resistance (ohms),Bridge 4 Excitation (에),Signal 1 Vin (V),Signal 2 Vin (V),Digital Inputs (code),Drive 1 Iout (mA),Drive 1 Ipower (W),Drive 2 Iout (mA),Drive 2 Ipower (W),Pressure (),Map 20 (),Map 21 (),Map 22 (),Map 23 (),Map 24 (),Map 25 (),Map 26 (),Map 27 (),Map 28 (),Map 29 ()
,31221464.64,20.0009995,-0.395818114280701,,,2,,,,21.0099998110533,,,,,,,20.0009995,20.0009995,-0.395818114280701,-0.395818114280701,,,13.038077,,,,-99999999,4369,20.0107,-0.395818114280701,,,,,,,,,,,,,,,,,,,,,,,20.0009995,,,,
,31221605.095,20.0007143,4471.21704101562,6.02900451291652E-5,3.89653567393165E-7,1,0.999253354069792,40.0298881530762,1.99481307007121,20.9999997168779,0.000675983938685398,0.000124879123547487,0.25,4.00399342731231E-7,5.99558926417997E-5,7.06542448533249E-7,20.0005512,20.0008774,4446.1630859375,4496.27099609375,56.208470074929,20.5349924335533,12.658426,0,0,0,40,4449,20.0091,4471.21704101562,,,,,,,,,,,,,0,,,,0.00245,,,,,,20.0007143,,,,
,31221700.57,20.0012026,9242.3486328125,4.56139539767142E-5,3.23477012507053E-7,1,0.999253354069792,40.0298881530762,1.9945635955492,20.9999997168779,0.000511044598462528,9.73417126229675E-5,0.25,5.40097008999052E-7,4.53756439292992E-5,7.86340049908733E-7,20.0010567,20.0013485,9212.54296875,9272.154296875,56.4578095725637,20.5502184468503,12.278775,0,0,0,40,4449,20.00835,9242.3486328125,,,,,,,,,,,,,0,,,,-0.0049,,,,,,20.0012026,,,,
,31221794.695,20.0016117,13947.4365234375,3.00888446598486E-5,3.78415051709716E-7,1,0.999253354069792,40.0298881530762,1.99406939533773,20.9999997168779,0.000337869578436146,6.02457014019237E-5,0.25,-8.01164394411836E-9,2.99455401930265E-5,1.66575076569341E-7,20.0016117,20.0016117,13919.83984375,13975.033203125,57.0909286731407,20.5595951480337,13.038077,0,0,0,40,4449,20.00685,13947.4365234375,,,,,,,,,,,,,0,,,,0,,,,,,20.0016117,,,,
,31221888.615,20.0019093,18639.8720703125,1.47915094148476E-5,5.96675506538495E-7,1,0.999253354069792,40.0298881530762,1.99390058474365,20.9999997168779,0.000165485027852755,3.3365401538152E-5,0.25,3.24146809585178E-7,1.47254499778073E-5,4.133209362751E-7,20.0019093,20.0019093,18607.455078125,18672.2890625,56.8118872917752,20.5635658515115,12.658426,0,0,0,40,4449,20.00495,18639.8720703125,,,,,,,,,,,,,0,,,,-0.00245,,,,,,20.0019093,,,,
,31221982.17,20.0010891,23317.4560546875,3.34438515466478E-7,4.69605061777415E-7,1,0.999253354069792,40.0298881530762,1.9937997223955,20.9999997168779,3.55293514241795E-6,1.81618908827894E-6,0.25,1.01703673730937E-7,3.32490703331658E-7,1.03455768142106E-7,20.0009785,20.0011997,23285.0390625,23349.873046875,56.8181403199291,20.5671723726025,12.658426,0,0,0,40,4449,20.00355,23317.4560546875,,,,,,,,,,,,,0,,,,-0.0049,,,,,,20.0010891,,,,
,31222077.29,20.0015869,28070.6953125,-1.58663651819236E-5,8.75988653726275E-7,1,0.999253354069792,40.0298881530762,1.99337162552295,20.9999997168779,-0.000178012892650907,-3.36946821818097E-5,0.25,-1.50326759289104E-7,-1.58116305787267E-5,-2.55785895011463E-7,20.0015869,20.0015869,28062.9765625,28078.4140625,56.9416376259676,20.5746203912482,13.038077,0,0,0,40,4449,20.0026,28070.6953125,,,,,,,,,,,,,0,,,,0,,,,,,20.0015869,,,,
,31222170.925,20.00114155,32750.736328125,-3.17362849303308E-5,7.51656572577438E-7,1,0.999253354069792,40.0298881530762,1.9936580422255,20.9999997168779,-0.000355511149737194,-7.17711678808821E-5,0.25,-6.79012871845242E-7,-3.16396987883719E-5,-8.95981320364565E-7,20.0011063,20.0011768,32720.86328125,32780.609375,56.9689946241406,20.5698565087406,12.658426,0,0,0,40,4449,20.0009,32750.736328125,,,,,,,,,,,,,0,,,,0.00245,,,,,,20.00114155,,,,
,31222266.53,20.0016899,37528.123046875,-4.71047137300522E-5,6.21479015237775E-7,1,0.999253354069792,40.0298881530762,1.99362448708751,20.9999997168779,-0.000529451516133957,-9.8102319505234E-5,0.25,-2.45880679979748E-7,-4.69903841617091E-5,-5.78910822918912E-7,20.0016899,20.0016899,37503.23046875,37553.015625,57.027616763083,20.5699000475644,12.658426,0,0,0,40,4449,19.9988,37528.123046875,,,,,,,,,,,,,0,,,,0,,,,,,20.0016899,,,,
,31222358.74,20.00086975,42135.99609375,-6.40963397273776E-5,7.61763885688267E-7,1,0.999253354069792,40.0298881530762,1.99329981397994,20.9999997168779,-0.000720349768834482,-0.000135338932379266,0.25,-4.8623029506364E-7,-6.39707930981654E-5,-9.48183594045891E-7,20.0007248,20.0010147,42106.109375,42165.8828125,56.8322096332752,20.5759369060403,12.658426,0,0,0,40,4449,19.99865,42135.99609375,,,,,,,,,,,,,0,,,,-0.00245,,,,,,20.00086975,,,,
,31222453.585,20.00131035,46878.71484375,-8.02825185402065E-5,7.76052988487222E-7,1,0.999253354069792,40.0298881530762,1.99338012596805,20.9999997168779,-0.000903192841217152,-0.000167091156071415,0.25,-3.77440406979803E-7,-8.01665231772038E-5,-9.65157093871238E-7,20.0012302,20.0013905,46853.625,46903.8046875,57.2277136640061,20.5723071479035,12.658426,0,0,0,40,4449,19.9973,46878.71484375,,,,,,,,,,,,,0,,,,0,,,,,,20.00131035,,,,
,31222547.78,20.001236,51586.380859375,-9.74037372727309E-5,7.32311352313397E-7,1,0.999253354069792,40.0298881530762,1.9932252731806,20.9999997168779,-0.00109687779236694,-0.000199344323368425,0.25,-1.44038325204747E-7,-9.73119079677944E-5,-8.64383786369007E-7,20.001236,20.001236,51561.06640625,51611.6953125,56.6031924771406,20.5747336523085,13.038077,0,0,0,40,4449,19.99585,51586.380859375,,,,,,,,,,,,,0,,,,0,,,,,,20.001236,,,,
,31222641.445,20.0007505,56266.560546875,-0.000113679060447007,7.46590413249573E-7,1,0.999253354069792,40.0298881530762,1.99322527384608,20.9999997168779,-0.00128225654702084,-0.000224389219076716,0.25,5.78592045036848E-7,-0.000113629847610525,-2.66793359584018E-7,20.0006599,20.0008411,56239.08984375,56294.03125,57.2464727484676,20.574792207816,12.278775,0,0,0,40,4449,19.99465,56266.560546875,,,,,,,,,,,,,0,,,,0,,,,,,20.0007505,,,,
,31222736.66,20.0010643,61027.0625,-0.000130861452788595,7.75344608497799E-7,1,0.999253354069792,40.0298881530762,1.99307266743568,20.9999997168779,-0.0014738348031966,-0.000273887923741196,0.25,-7.06808400746586E-7,-0.000130853643400551,-1.68079404263408E-6,20.0010643,20.0010643,60997.50390625,61056.62109375,57.0135474497368,20.5774785790297,12.658426,0,0,0,40,4449,19.9942,61027.0625,,,,,,,,,,,,,0,,,,0,,,,,,20.0010643,,,,
,31222831.475,20.0016384,65764.703125,-0.00014670057615054,8.89801254490587E-7,1,0.999253354069792,40.0298881530762,1.99330181893721,20.9999997168779,-0.00165308805377029,-0.000307352118704613,0.25,-8.08449809449005E-7,-0.000146754710976039,-1.89816605113676E-6,20.0016384,20.0016384,65739.421875,65789.984375,57.2238055214099,20.5723851893577,12.658426,0,0,0,40,4449,19.99285,65764.703125,,,,,,,,,,,,,0,,,,-0.00245,,,,,,20.0016384,,,,
,31222927.12,20.0011482,70547.359375,-0.000165250398456444,9.81355628429487E-7,1,0.999253354069792,40.0298881530762,1.993230744117,20.9999997168779,-0.00186167836992824,-0.000352680901883856,0.25,-1.47911128979807E-6,-0.000165375352638328,-2.70086983828842E-6,20.0011482,20.0011482,70542.296875,70552.421875,56.800944492506,20.5715250885457,12.658426,0,0,0,40,4449,19.99135,70547.359375,,,,,,,,,,,,,0,,,,-0.0049,,,,,,20.0011482,,,,
,31223022.115,20.00112535,75293.0390625,-0.000182525311160564,9.49321386561131E-7,1,0.999253354069792,40.0298881530762,1.99335809181528,20.9999997168779,-0.00206316365462519,-0.000356703035328102,0.25,1.28003598478998E-6,-0.000182755490938291,-5.58194123712115E-8,20.0010872,20.0011635,75260.65625,75325.421875,57.2925888311022,20.5687569344291,12.658426,0,0,0,40,4449,19.99015,75293.0390625,,,,,,,,,,,,,0,,,,-0.00245,,,,,,20.00112535,,,,
,31223116.865,20.0021248,80031.18359375,-0.000199543013323254,9.49482233738152E-7,1,0.999253354069792,40.0298881530762,1.99336537790338,20.9999997168779,-0.00224983186263915,-0.000426306722015985,0.25,-1.82173780850229E-6,-0.000199844036203944,-3.27178696997557E-6,20.0021248,20.0021248,80028.8046875,80033.5625,57.0213637349291,20.5682227067325,12.278775,0,0,0,40,4449,19.989,80031.18359375,,,,,,,,,,,,,0,,,,0,,,,,,20.0021248,,,,
,31223210.38,20.001545,84704.94921875,-0.000214928135276273,1.07195671541417E-6,1,0.999253354069792,40.0298881530762,1.99339511483729,20.9999997168779,-0.0024262569676985,-0.000447646484039091,0.25,-9.46489558245449E-7,-0.00021533268063413,-2.48841698360082E-6,20.001545,20.001545,84702.46875,84707.4296875,57.1229754424291,20.567867211625,12.278775,0,0,0,40,4449,19.9872,84704.94921875,,,,,,,,,,,,,0,,,,-0.0049,,,,,,20.001545,,,,
,31223298.815,20.0015488,89125.36328125,-0.000232922019481812,1.01968030050509E-6,1,0.999253354069792,40.0298881530762,1.99341311106078,20.9999997168779,-0.00263284732030371,-0.000470545241123227,0.25,2.5570451150143E-7,-0.000233439882770228,-1.39140977051167E-6,20.0015488,20.0015488,89100.515625,89150.2109375,56.9205336559483,20.5664855656534,12.658426,0,0,0,40,4449,19.9857,89125.36328125,,,,,,,,,,,,,0,,,,0.00245,,,,,,20.0015488,,,,
,31223402.87,20.00031185,86493.74609375,-0.000222770851162897,8.53055477949751E-7,1,0.999253354069792,40.0298881530762,1.9934521507563,20.9999997168779,-0.00251443591773688,-0.000468139134531732,0.25,-1.3510274803485E-6,-0.000223215245051505,-2.94205269990145E-6,20.0002823,20.0003414,86463.7421875,86523.75,56.4898563418521,20.567661952412,12.658426,0,0,0,40,4449,19.9849,86493.74609375,,,,,,,,,,,,,0,,,,0,,,,,,20.00031185,,,,
,31223494.53,19.9996243,81912.765625,-0.000206818540781282,1.06326524576988E-6,1,0.999253354069792,40.0298881530762,1.99343671638998,20.9999997168779,-0.00233138483246017,-0.000446823313584282,0.25,-2.32878652073119E-6,-0.000207156164046568,-3.8257936735888E-6,19.9996243,19.9996243,81885.4921875,81940.0390625,56.9455457685637,20.569971130547,12.278775,0,0,0,40,4449,19.98535,81912.765625,,,,,,,,,,,,,0,,,,0,,,,,,19.9996243,,,,
,31223588.715,20.0005751,77203.984375,-0.000187980300477607,9.34588231693185E-7,1,0.999253354069792,40.0298881530762,1.99351201738006,20.9999997168779,-0.00211755513109359,-0.000410436723173843,0.25,-2.49455650216946E-6,-0.000188217657200747,-3.86998778834589E-6,20.0003777,20.0007725,77171.5546875,77236.4140625,56.7892200647175,20.5682001565736,12.658426,0,0,0,40,4449,19.98585,77203.984375,,,,,,,,,,,,,0,,,,-0.0049,,,,,,20.0005751,,,,
,31223682.545,19.9989624,72514.921875,-0.000171687904706917,9.52420720081104E-7,1,0.999253354069792,40.0298881530762,1.99353617458784,20.9999997168779,-0.00193129296045283,-0.00038600279116846,0.25,-3.26561200095523E-6,-0.000171833058511622,-4.53310361588105E-6,19.9989624,19.9989624,72482.4609375,72547.3828125,57.3285437429868,20.5689386560775,13.038077,0,0,0,40,4449,19.98705,72514.921875,,,,,,,,,,,,,0,,,,-0.0049,,,,,,19.9989624,,,,
,31223775.965,19.999012,67844.5546875,-0.000155183868480973,9.79040764703724E-7,1,0.999253354069792,40.0298881530762,1.99357797448865,20.9999997168779,-0.00174848042416238,-0.000329392022742987,0.25,-1.22677929329532E-6,-0.000155266628400023,-2.37759793033694E-6,19.999012,19.999012,67839.6484375,67849.4609375,56.638365760506,20.5696240858127,12.658426,0,0,0,40,4449,19.9884,67844.5546875,,,,,,,,,,,,,0,,,,0.0049,,,,,,19.999012,,,,
,31223871.265,19.9991474,63081.783203125,-0.000137455423634967,7.95522708974251E-7,1,0.999253354069792,40.0298881530762,1.99352698994861,20.9999997168779,-0.00154891580229734,-0.000286768497594802,0.25,-6.51257434394266E-7,-0.000137473839381974,-1.67383499688469E-6,19.9991474,19.9991474,63051.7578125,63111.80859375,57.3926372815638,20.5693176646871,12.658426,0,0,0,40,4449,19.98855,63081.783203125,,,,,,,,,,,,,0,,,,-0.0049,,,,,,19.9991474,,,,
,31223965.82,19.9981022,58353.595703125,-0.000120763947059449,1.00493549622441E-6,1,0.999253354069792,40.0298881530762,1.99368074774677,20.9999997168779,-0.00136442644968007,-0.000229125582204946,0.25,1.44452825282449E-6,-0.00012074201652821,5.45475516740363E-7,19.9981022,19.9981022,58328.5546875,58378.63671875,57.2793011462753,20.5678021640818,12.658426,0,0,0,40,4449,19.9902,58353.595703125,,,,,,,,,,,,,0,,,,0,,,,,,19.9981022,,,,
,31224060.33,19.9992485,53632.7734375,-0.000103388348896357,8.70359772348779E-7,1,0.999253354069792,40.0298881530762,1.99358314201937,20.9999997168779,-0.00116546772800928,-0.000207458085625806,0.25,2.22964501152234E-7,-0.000103314706188689,-5.44017834261988E-7,19.9992485,19.9992485,53605.30078125,53660.24609375,57.0229269919676,20.5702343622014,13.038077,0,0,0,40,4449,19.9916,53632.7734375,,,,,,,,,,,,,0,,,,0.0049,,,,,,19.9992485,,,,
,31224154.18,19.9986734,48940.224609375,-8.6285982837408E-5,5.6740135519677E-7,1,0.999253354069792,40.0298881530762,1.99368081290396,20.9999997168779,-0.000971470257821067,-0.000177473139326864,0.25,-2.0954779942334E-7,-8.61809613080897E-5,-8.44521809581049E-7,19.9983463,19.9990005,48907.5859375,48972.86328125,57.1026531009291,20.5690455825542,12.658426,0,0,0,40,4449,19.9924,48940.224609375,,,,,,,,,,,,,0,,,,-0.00245,,,,,,19.9986734,,,,
,31224248.96,19.9999313,44202.337890625,-6.94178876838385E-5,7.89066276286254E-7,1,0.999253354069792,40.0298881530762,1.99372322575046,20.9999997168779,-0.000782501312499481,-0.000135431468482138,0.25,4.72081596408085E-7,-6.93041543707829E-5,-3.3533994907089E-8,19.9999313,19.9999313,44169.88671875,44234.7890625,56.9088092281599,20.5687345581344,12.278775,0,0,0,40,4449,19.9923,44202.337890625,,,,,,,,,,,,,0,,,,0,,,,,,19.9999313,,,,
,31224342.49,19.99970055,39526.67578125,-5.32980836680525E-5,7.18321826445845E-7,1,0.999253354069792,40.0298881530762,1.99373730580927,20.9999997168779,-0.000599312742676295,-0.000110535127703137,0.25,-2.30811518154314E-7,-5.31803048839601E-5,-6.11247970271262E-7,19.999651,19.9997501,39496.58203125,39556.76953125,57.1862873524868,20.5698615731252,12.658426,0,0,0,40,4449,19.99265,39526.67578125,,,,,,,,,,,,,0,,,,0,,,,,,19.99970055,,,,
,31224437.775,19.99965,34764.654296875,-3.63537788874288E-5,5.76207365045128E-7,1,0.999253354069792,40.0298881530762,1.99364396382953,20.9999997168779,-0.000409629950117016,-6.93838819335804E-5,0.25,3.67325372592709E-7,-3.62588078687804E-5,1.12552883143535E-7,19.9995193,19.9997807,34734.61328125,34794.6953125,56.8423708040252,20.5728150435498,12.658426,0,0,0,40,4449,19.99345,34764.654296875,,,,,,,,,,,,,0,,,,0,,,,,,19.99965,,,,
,31224531.83,19.9987946,30064.4306640625,-2.01998860035636E-5,5.32226546256448E-7,1,0.999253354069792,40.0298881530762,1.99366634308118,20.9999997168779,-0.000228113395259244,-3.51096558338064E-5,0.25,5.0464335780961E-7,-2.013909972928E-5,3.66142269269115E-7,19.9987946,19.9987946,30031.83203125,30097.029296875,57.1456426694868,20.5747235031159,12.658426,0,0,0,40,4449,19.99455,30064.4306640625,,,,,,,,,,,,,0,,,,0,,,,,,19.9987946,,,,
,31224625.25,19.9988194,25394.0498046875,-4.37761797277773E-6,4.55969456970116E-7,1,0.999253354069792,40.0298881530762,1.9937560987792,20.9999997168779,-4.9472329011445E-5,-7.27646928583757E-6,0.25,1.37583946726453E-7,-4.36248450044837E-6,1.08468942875563E-7,19.9988194,19.9988194,25389.009765625,25399.08984375,57.1909771236022,20.5727728016507,12.658426,0,0,0,40,4449,19.99615,25394.0498046875,,,,,,,,,,,,,0,,,,0,,,,,,19.9988194,,,,
,31224719.865,19.99780275,20666.83203125,1.16259224121972E-5,4.97942204358183E-7,1,0.999253354069792,40.0298881530762,1.99373339353393,20.9999997168779,0.000129453050620787,2.97508314062893E-5,0.25,5.66899393479425E-7,1.15742925817064E-5,6.37268950543862E-7,19.9977818,19.9978237,20631.783203125,20701.880859375,57.2261504069676,20.5743002600076,12.278775,0,0,0,40,4449,19.99795,20666.83203125,,,,,,,,,,,,,0,,,,0,,,,,,19.99780275,,,,
,31224813.28,19.9982376,15997.1391601562,2.68961682272724E-5,4.62358772551863E-7,1,0.999253354069792,40.0298881530762,1.99367876997661,20.9999997168779,0.000301252964750802,5.81370297531561E-5,0.25,3.70514580397916E-7,2.67707935117959E-5,5.28712217073632E-7,19.998003,19.9984722,15969.6171875,16024.6611328125,57.4426615067945,20.5749242746322,12.658426,0,0,0,40,4449,19.9987,15997.1391601562,,,,,,,,,,,,,0,,,,0,,,,,,19.9982376,,,,
,31224906.65,19.9984856,11329.693359375,4.18662056600161E-5,3.8755763364515E-7,1,0.999253354069792,40.0298881530762,1.99376408294298,20.9999997168779,0.000469415935413867,8.67476129258112E-5,0.25,2.59726959061452E-7,4.16558409493729E-5,4.9339434286459E-7,19.9984856,19.9984856,11307.2626953125,11352.1240234375,57.1042163579676,20.5737643007628,12.278775,0,0,0,40,4449,20.0012,11329.693359375,,,,,,,,,,,,,0,,,,0,,,,,,19.9984856,,,,
,31225000.31,19.9989681,6651.60986328125,5.66059402805469E-5,2.87122867898777E-7,1,0.999253354069792,40.0298881530762,1.99373381739526,20.9999997168779,0.000634747395099619,0.000115510649458012,0.25,2.16090656508097E-7,5.63015586398E-5,5.13238789774492E-7,19.9989681,19.9989681,6649.1220703125,6654.09765625,57.0330881627176,20.5741474892764,12.278775,0,0,0,40,4449,20.0014,6651.60986328125,,,,,,,,,,,,,0,,,,0.00245,,,,,,19.9989681,,,,
,31225092.9,19.99917505,2021.00817871094,7.05156948215819E-5,3.53892012551865E-7,1,0.999253354069792,40.0298881530762,1.99379535505883,20.9999997168779,0.000790714882298279,0.000142687799945876,0.25,1.87558404180878E-7,7.0115783907208E-5,5.35650392468546E-7,19.9989204,19.9994297,1996.26574707031,2045.75061035156,57.1808159528522,20.5728927574425,12.658426,0,0,0,40,4449,20.00225,2021.00817871094,,,,,,,,,,,,,0,,,,0,,,,,,19.99917505,,,,
,31225185.055,19.9998913,-2579.96813964844,8.20750831444972E-5,3.40737251989727E-7,1,0.999253354069792,40.0298881530762,1.99385330637295,20.9999997168779,0.00092004148663056,0.000168042540163418,0.25,3.89614414232743E-7,8.16113529636169E-5,7.96709455641705E-7,19.9998474,19.9999352,-2607.53784179687,-2552.3984375,57.4473512779099,20.5722018511061,13.038077,0,0,0,40,4449,20.0013,-2579.96813964844,,,,,,,,,,,,,0,,,,-0.00245,,,,,,19.9998913,,,,
,31225277.945,19.9996738,-7224.50805664062,9.27562306727751E-5,4.57819701708705E-7,1,0.999253354069792,40.0298881530762,1.99380960508556,20.9999997168779,0.00104008094118089,0.00018995391878729,0.25,4.09014915961309E-7,9.22610628933786E-5,8.99521363761798E-7,19.9996738,19.9996738,-7257.2099609375,-7191.80615234375,56.9955699937945,20.5719560233989,12.658426,0,0,0,40,4449,20.00235,-7224.50805664062,,,,,,,,,,,,,0,,,,0.00245,,,,,,19.9996738,,,,
,31225370.595,20.0009737,-11855.169921875,9.84432450756372E-5,3.85462039477263E-7,1,0.999253354069792,40.0298881530762,1.99386793213104,20.9999997168779,0.00110443235172294,0.000200888149948638,0.25,3.30144561591275E-7,9.79545141787537E-5,8.84763429947216E-7,20.0008469,20.0011005,-11885.068359375,-11825.271484375,57.4528226775445,20.571859333344,12.658426,0,0,0,40,4449,20.0011,-11855.169921875,,,,,,,,,,,,,0,,,,0,,,,,,20.0009737,,,,
,31225466.735,20.0010204,-16660.6865234375,9.34801601699228E-5,5.42710868436974E-7,1,0.999253354069792,40.0298881530762,1.99389102286338,20.9999997168779,0.00104969883748649,0.000188135879877901,0.25,4.0604072640834E-8,9.30575474204059E-5,6.00418229636185E-7,20.0010204,20.0010204,-16663.421875,-16657.951171875,57.535675300583,20.5710633016888,12.658426,0,0,0,40,4449,20.0002,-16660.6865234375,,,,,,,,,,,,,0,,,,0,,,,,,20.0010204,,,,
,31225559.565,20.0024414,-21300.23828125,7.58125154106212E-5,5.32942032107299E-7,1,0.999253354069792,40.0298881530762,1.99390657802855,20.9999997168779,0.000850774945026395,0.000157785050743362,0.25,4.67280700651808E-7,7.55007338651376E-5,9.42556514890658E-7,20.0024414,20.0024414,-21335.390625,-21265.0859375,57.4379717356792,20.5708699371767,12.278775,0,0,0,40,4449,19.99855,-21300.23828125,,,,,,,,,,,,,0,,,,0.0049,,,,,,20.0024414,,,,
,31225653.465,20.0013123,-25994.8544921875,5.74333659692309E-5,7.39599142610793E-7,1,0.999253354069792,40.0298881530762,1.99393672527386,20.9999997168779,0.0006459713982117,0.000113272374449485,0.25,-2.23925681313302E-7,5.72280255286453E-5,1.54156881974528E-7,20.0013123,20.0013123,-26022.091796875,-25967.6171875,57.217552493256,20.5719497970448,13.038077,0,0,0,40,4449,19.99725,-25994.8544921875,,,,,,,,,,,,,0,,,,-0.0049,,,,,,20.0013123,,,,
,31225749.165,20.0008917,-30775.0087890625,4.92397149310831E-5,6.1036497113479E-7,1,0.999253354069792,40.0298881530762,1.99389841741623,20.9999997168779,0.000553834808269103,9.8536955929074E-5,0.25,-8.12408832113948E-8,4.90874290705455E-5,2.54358350579158E-7,20.0007038,20.0010796,-30799.66796875,-30750.349609375,57.1948852661984,20.5744759600939,12.658426,0,0,0,40,4449,19.9962,-30775.0087890625,,,,,,,,,,,,,0,,,,-0.00735,,,,,,20.0008917,,,,
,31225843.91,20.0023518,-35512.296875,5.21962646745676E-5,5.18461252490986E-7,1,0.999253354069792,40.0298881530762,1.99380169733861,20.9999997168779,0.00058869738439859,9.70510008451251E-5,0.25,-7.58667060570692E-7,5.20656760143438E-5,-3.90805084315311E-7,20.0023518,20.0023518,-35537.46484375,-35487.12890625,57.6615174921792,20.5760882690626,13.038077,0,0,0,40,4449,19.9945,-35512.296875,,,,,,,,,,,,,0,,,,-0.0049,,,,,,20.0023518,,,,
,31225938.98,20.0019569,-40262.265625,6.2230230021355E-5,6.75856910000585E-7,1,0.999253354069792,40.0298881530762,1.99380450799077,20.9999997168779,0.000700689669175539,0.000124284539719072,0.25,-1.57389123985028E-7,6.21005995385679E-5,2.89098983607222E-7,20.0019569,20.0019569,-40284.67578125,-40239.85546875,57.342613056333,20.5748412905126,12.278775,0,0,0,40,4449,19.9935,-40262.265625,,,,,,,,,,,,,0,,,,-0.00245,,,,,,20.0019569,,,,
,31226034.995,20.0008984,-45060.33203125,7.59338527693335E-5,5.64822871758863E-7,1,0.999253354069792,40.0298881530762,1.9938267119346,20.9999997168779,0.000854352755379277,0.000157702335731382,0.25,3.29268698257627E-7,7.5810065465954E-5,8.82382467582755E-7,20.0008984,20.0008984,-45062.65234375,-45058.01171875,57.5630322987561,20.5747280149339,13.038077,0,0,0,40,4449,19.9911,-45060.33203125,,,,,,,,,,,,,0,,,,-0.0049,,,,,,20.0008984,,,,
,31226131.96,20.0001612,-49909.78125,9.29605635340973E-5,7.97657401111549E-7,1,0.999253354069792,40.0298881530762,1.99404153785815,20.9999997168779,0.00104643922295683,0.000193819203568264,0.25,4.5226059040664E-7,9.28548974536482E-5,1.13742926529265E-6,19.9999104,20.000412,-49934.88671875,-49884.67578125,57.166746639506,20.5706841184659,12.658426,0,0,0,40,4449,19.99135,-49909.78125,,,,,,,,,,,,,0,,,,-0.0049,,,,,,20.0001612,,,,
,31226227.125,20.0009689,-54663.91796875,0.000108748220658822,7.26425873994731E-7,1,0.999253354069792,40.0298881530762,1.99398761470142,20.9999997168779,0.00122535406276192,0.000223248590373117,0.25,2.05718259981533E-7,0.000108678523761947,1.01302083840918E-6,20.0009689,20.0009689,-54691.35546875,-54636.48046875,57.2464727484676,20.5738084192625,13.038077,0,0,0,40,4449,19.9911,-54663.91796875,,,,,,,,,,,,,0,,,,0.00245,,,,,,20.0009689,,,,
,31226320,20.0013065,-59306.5234375,0.000124045569485975,7.42891273725707E-7,1,0.999253354069792,40.0298881530762,1.99398829079311,20.9999997168779,0.00139889656023958,0.000251715250405353,0.25,-3.7754036720506E-8,0.000124023470023054,8.85522848265725E-7,20.0013065,20.0013065,-59333.8828125,-59279.1640625,57.2785195177561,20.571686387679,12.658426,0,0,0,40,4449,19.99,-59306.5234375,,,,,,,,,,,,,0,,,,-0.00245,,,,,,20.0013065,,,,
,31226415.005,20.0011044,-64054.08203125,0.000142077398452923,7.61841517819367E-7,1,0.999253354069792,40.0298881530762,1.99393709783437,20.9999997168779,0.00160065376997728,0.000300933955648114,0.25,1.06721365132168E-6,0.000142106007457233,2.12380902676346E-6,20.0011044,20.0011044,-64076.34765625,-64031.81640625,57.3129111726022,20.5729336566114,12.278775,0,0,0,40,4449,19.98925,-64054.08203125,,,,,,,,,,,,,0,,,,0,,,,,,20.0011044,,,,
,31226509.295,20.00126835,-68766.59375,0.000160291789372452,8.16351145144002E-7,1,0.999253354069792,40.0298881530762,1.99399995676266,20.9999997168779,0.00180746630498351,0.000335191423434445,0.25,8.13239369175278E-7,0.000160393362822977,2.0004764080191E-6,20.0012302,20.0013065,-68793.8828125,-68739.3046875,57.0909286731407,20.5732618698805,13.038077,0,0,0,40,4449,19.9873,-68766.59375,,,,,,,,,,,,,0,,,,-0.00245,,,,,,20.00126835,,,,
,31226605.945,20.0025625,-73595.6640625,0.000175892560434378,7.87321684957348E-7,1,0.999253354069792,40.0298881530762,1.99404189493379,20.9999997168779,0.00198630744837035,0.000356378136505417,0.25,-1.2437898351445E-7,0.000176082309808812,1.16834348544309E-6,20.0025234,20.0026016,-73620.671875,-73570.65625,57.0002597649099,20.5708284401707,12.658426,0,0,0,40,4449,19.98525,-73595.6640625,,,,,,,,,,,,,0,,,,0.00245,,,,,,20.0025625,,,,
,31226703.74,20.0020943,-78483.12109375,0.000194970157472148,9.36105616696263E-7,1,0.999253354069792,40.0298881530762,1.99407138300002,20.9999997168779,0.00220406229787179,0.000387181833751021,0.25,-8.32155987989075E-7,0.000195260449168592,5.85719831806211E-7,20.0020943,20.0020943,-78488.234375,-78478.0078125,57.3754414541407,20.5729690007501,13.038077,0,0,0,40,4449,19.9832,-78483.12109375,,,,,,,,,,,,,0,,,,0.00245,,,,,,20.0020943,,,,
,31226798.94,20.00245855,-83243.10546875,0.000213049563363079,8.98853355623537E-7,1,0.999253354069792,40.0298881530762,1.99408972604898,20.9999997168779,0.00240243589713116,0.0004614223432637,0.25,2.48835961543943E-6,0.000213417269220654,4.0255646126E-6,20.0024471,20.00247,-83275.6640625,-83210.546875,56.7774956369291,20.5725406931715,13.038077,0,0,0,40,4449,19.9811,-83243.10546875,,,,,,,,,,,,,0,,,,0,,,,,,20.00245855,,,,
,31226892.62,20.0017433,-87922.3671875,0.000231021137986594,9.98956598465477E-7,1,0.999253354069792,40.0298881530762,1.99415237745544,20.9999997168779,0.00260721529516709,0.000493855520323072,0.25,2.13075174628092E-6,0.000231499284900433,3.77549799280565E-6,20.0017433,20.0017433,-87947.2890625,-87897.4453125,56.9174071418714,20.5737107407263,13.038077,0,0,0,40,4449,19.9795,-87922.3671875,,,,,,,,,,,,,0,,,,0.00245,,,,,,20.0017433,,,,
,31226998.145,20.0008011,-87616.23046875,0.000230318206712488,7.79330132260138E-7,1,0.999253354069792,40.0298881530762,1.99408423669076,20.9999997168779,0.00259923021203023,0.0004918467397703,0.25,2.08029186173369E-6,0.000230790439673665,3.72138757535455E-6,20.0008011,20.0008011,-87648.7265625,-87583.734375,57.261323690333,20.5733096501993,13.417728,0,0,0,40,4449,19.9787,-87616.23046875,,,,,,,,,,,,,0,,,,0,,,,,,20.0008011,,,,
,31227090.085,20.0000954,-83021.5546875,0.000214033382850749,8.37608344780099E-7,1,0.999253354069792,40.0298881530762,1.99403770184115,20.9999997168779,0.00241574857738526,0.000450659736969069,0.25,1.35956525862249E-6,0.000214407578444153,2.90268419311381E-6,20.0000687,20.0001221,-83026.4140625,-83016.6953125,57.8037738826792,20.5736267654852,12.278775,0,0,0,40,4449,19.97885,-83021.5546875,,,,,,,,,,,,,0,,,,0,,,,,,20.0000954,,,,
,31227188.315,20.0000973,-78111.6171875,0.000195445846339174,1.05075837766043E-6,1,0.999253354069792,40.0298881530762,1.99408200659187,20.9999997168779,0.00220329329727379,0.00042196516062416,0.25,2.16111971529728E-6,0.00019570947866152,3.58793803815856E-6,20.0000973,20.0000973,-78139.390625,-78083.84375,57.4199942797368,20.572856259698,12.658426,0,0,0,40,4449,19.9795,-78111.6171875,,,,,,,,,,,,,0,,,,0,,,,,,20.0000973,,,,
,31227292.625,19.998354,-72899.484375,0.000176377900373728,9.6151954446377E-7,1,0.999253354069792,40.0298881530762,1.99417659763165,20.9999997168779,0.00199143424348387,0.000359417664397325,0.25,5.54985884703488E-8,0.000176556859293569,1.35353487056738E-6,19.998354,19.998354,-72902.1875,-72896.78125,57.3801312252561,20.5699503296634,13.038077,0,0,0,40,4449,19.9811,-72899.484375,,,,,,,,,,,,,0,,,,0,,,,,,19.998354,,,,
,31227390.945,19.9957619,-67987.83984375,0.000159049325616748,1.00989588965338E-6,1,0.999253354069792,40.0298881530762,1.99402682337715,20.9999997168779,0.00179491143501894,0.000323961870606078,0.25,4.25870378586103E-8,0.00015914511524978,1.22116778008556E-6,19.9957619,19.9957619,-68020.1875,-67955.4921875,56.9103724851983,20.5720044031559,13.038077,0,0,0,40,4449,19.98355,-67987.83984375,,,,,,,,,,,,,0,,,,-0.00245,,,,,,19.9957619,,,,
,31227490.155,19.9966469,-63028.384765625,0.000138734360521894,8.74858704697662E-7,1,0.999253354069792,40.0298881530762,1.99412756769345,20.9999997168779,0.00156449503265983,0.000285493265751482,0.25,3.00479464193375E-7,0.00013875492774306,1.33253390218677E-6,19.9966469,19.9966469,-63033.2734375,-63023.49609375,57.4684552479292,20.5713826280634,13.038077,0,0,0,40,4449,19.9873,-63028.384765625,,,,,,,,,,,,,0,,,,0.0049,,,,,,19.9966469,,,,
,31227598.11,19.9988575,-57633.185546875,0.00011946865291864,9.17888777196954E-7,1,0.999253354069792,40.0298881530762,1.99407582811158,20.9999997168779,0.00134827293968868,0.000236023596751199,0.25,-6.01552885598675E-7,0.000119432591024448,2.8744848276471E-7,19.9988575,19.9988575,-57635.6875,-57630.68359375,57.4801796757176,20.56930278662,12.278775,0,0,0,40,4449,19.99,-57633.185546875,,,,,,,,,,,,,0,,,,0,,,,,,19.9988575,,,,
,31227705.255,19.9981689,-52279.310546875,9.95195738224429E-5,6.86681895753311E-7,1,0.999253354069792,40.0298881530762,1.9940304992499,20.9999997168779,0.00112297075682682,0.000194021820914407,0.25,-7.18301184916621E-7,9.94390456619422E-5,1.91902295785263E-8,19.9981689,19.9981689,-52309.39453125,-52249.2265625,57.0557553897753,20.5696049681005,13.038077,0,0,0,40,4449,19.99135,-52279.310546875,,,,,,,,,,,,,0,,,,0,,,,,,19.9981689,,,,
,31227808.75,20.0001583,-47104.486328125,8.05322756473352E-5,8.38132906542853E-7,1,0.999253354069792,40.0298881530762,1.99407113007993,20.9999997168779,0.000908905122116282,0.000153339785825834,0.25,-8.93980443259225E-7,8.04271154378454E-5,-3.02330446141575E-7,20.0001583,20.0001583,-47107.01953125,-47101.953125,56.9142806277945,20.5697814865162,12.658426,0,0,0,40,4449,19.9934,-47104.486328125,,,,,,,,,,,,,0,,,,-0.0049,,,,,,20.0001583,,,,
,31227901.025,19.998909,-42494.443359375,6.30897747918198E-5,7.11262502076002E-7,1,0.999253354069792,40.0298881530762,1.99394134290672,20.9999997168779,0.000708796635590022,0.000135954962031236,0.25,7.17455884334643E-7,6.29668349605581E-5,1.17231129713313E-6,19.9987831,19.9990349,-42529.5234375,-42459.36328125,57.108906129083,20.5703633153259,12.278775,0,0,0,40,4449,19.9919,-42494.443359375,,,,,,,,,,,,,0,,,,0.00245,,,,,,19.998909,,,,
,31227995.75,19.99884985,-37759.544921875,4.66109157313498E-5,7.83510034873086E-7,1,0.999253354069792,40.0298881530762,1.99417800207197,20.9999997168779,0.000525595281382609,8.85290225596325E-5,0.25,-5.18849128689369E-7,4.65043237536749E-5,-1.87135826852345E-7,19.9988136,19.9988861,-37782.02734375,-37737.0625,57.4536043060638,20.5639740971674,13.038077,0,0,0,40,4449,19.9914,-37759.544921875,,,,,,,,,,,,,0,,,,0,,,,,,19.99884985,,,,
,31228089.195,19.9981976,-33089.91015625,3.04925425778668E-5,6.98136229024876E-7,1,0.999253354069792,40.0298881530762,1.99435917892078,20.9999997168779,0.000343673233270579,5.80356611655562E-5,0.25,-3.21270345504953E-7,3.04075518802309E-5,-1.09559041654548E-7,19.9981976,19.9981976,-33114.7578125,-33065.0625,57.017455592333,20.5649586345063,12.278775,0,0,0,40,4449,19.99325,-33089.91015625,,,,,,,,,,,,,0,,,,0,,,,,,19.9981976,,,,
,31228182.185,19.9979458,-28443.2392578125,1.47207019747721E-5,6.35798056267109E-7,1,0.999253354069792,40.0298881530762,1.99436780234177,20.9999997168779,0.000168283992671661,1.43440302076268E-5,0.25,-1.36677918312073E-6,1.4680573683162E-5,-1.26360936024213E-6,19.9979439,19.9979477,-28478.259765625,-28408.21875,57.5896076684099,20.5663013945078,13.038077,0,0,0,40,4449,19.99515,-28443.2392578125,,,,,,,,,,,,,0,,,,0,,,,,,19.9979458,,,,
,31228277.315,19.9991016,-23687.8779296875,-1.4200883730233E-6,5.03756367682472E-7,1,0.999253354069792,40.0298881530762,1.99427264954514,20.9999997168779,-1.37136243067251E-5,-1.539454355497E-5,0.25,-1.11522272978935E-6,-1.40746122861035E-6,-1.12008814241462E-6,19.9991016,19.9991016,-23715.330078125,-23660.42578125,57.1534589546791,20.5666979281186,13.038077,0,0,0,40,4449,19.996,-23687.8779296875,,,,,,,,,,,,,0,,,,0.00245,,,,,,19.9991016,,,,
,31228369.875,19.9976425,-19062.873046875,-1.72553908974669E-5,4.362031956946E-7,1,0.999253354069792,40.0298881530762,1.99423001387563,20.9999997168779,-0.000193461895384031,-3.6845568052735E-5,0.25,-1.92038254193968E-7,-1.71801588456382E-5,-2.97358348719578E-7,19.9976368,19.9976482,-19093.01953125,-19032.7265625,56.7743691228522,20.5671282819558,12.278775,0,0,0,40,4449,19.9981,-19062.873046875,,,,,,,,,,,,,0,,,,0,,,,,,19.9976425,,,,
,31228464.67,19.9982691,-14325.5854492187,-3.27198128216392E-5,3.99156163752653E-7,1,0.999253354069792,40.0298881530762,1.99406532326313,20.9999997168779,-0.000365228667647773,-7.78099160126805E-5,0.25,-1.08529795101419E-6,-3.25586963836202E-5,-1.27084871938077E-6,19.99823,19.9983082,-14355.3095703125,-14295.861328125,57.108906129083,20.5694636158352,12.278775,0,0,0,40,4449,19.9981,-14325.5854492187,,,,,,,,,,,,,0,,,,0,,,,,,19.9982691,,,,
,31228559.935,19.9981461,-9560.609375,-4.69588418503904E-5,3.7267636544593E-7,1,0.999253354069792,40.0298881530762,1.99412060400059,20.9999997168779,-0.00052529135793347,-0.000104246973081969,0.25,-9.16077153743037E-7,-4.67127013363853E-5,-1.16883634540569E-6,19.9981461,19.9981461,-9563.1337890625,-9558.0849609375,57.1386080128137,20.567817610604,12.658426,0,0,0,40,4449,20.0005,-9560.609375,,,,,,,,,,,,,0,,,,0,,,,,,19.9981461,,,,
,31228653.49,19.9991646,-4886.8388671875,-6.13300036163858E-5,3.40157600081914E-7,1,0.999253354069792,40.0298881530762,1.99408465960416,20.9999997168779,-0.000686306061639471,-0.000133273449183946,0.25,-9.65242078683092E-7,-6.09888970170847E-5,-1.27539756387972E-6,19.9991646,19.9991646,-4889.466796875,-4884.2109375,56.7610814380252,20.5663228954108,12.658426,0,0,0,40,4449,20.0013,-4886.8388671875,,,,,,,,,,,,,0,,,,-0.0049,,,,,,19.9991646,,,,
,31228745.92,20.00042535,-265.27938079834,-7.46263509761331E-5,2.89565527267122E-7,1,0.999253354069792,40.0298881530762,1.99416365282545,20.9999997168779,-0.000835899375187554,-0.000156571465355746,0.25,-7.00516662292682E-7,-7.4194423893247E-5,-1.05882325712256E-6,20.0004025,20.0004482,-295.002960205078,-235.555801391602,57.1651833824676,20.5665998947731,12.658426,0,0,0,40,4449,19.99975,-265.27938079834,,,,,,,,,,,,,0,,,,0,,,,,,20.00042535,,,,
,31228839.19,19.99993515,4393.51586914063,-8.56951864825273E-5,3.55602064948246E-7,1,0.999253354069792,40.0298881530762,1.99395296217573,20.9999997168779,-0.00095985318824548,-0.000180674638584897,0.25,-8.59035227917309E-7,-8.52182979698581E-5,-1.29210104926357E-6,19.9996967,20.0001736,4363.52490234375,4423.5068359375,56.8908317722176,20.5691568672667,13.038077,0,0,0,40,4449,20.0003,4393.51586914063,,,,,,,,,,,,,0,,,,0.00245,,,,,,19.99993515,,,,
,31228932.875,19.9997854,9074.92578125,-9.44964262046365E-5,4.16439369009528E-7,1,0.999253354069792,40.0298881530762,1.99399945331331,20.9999997168779,-0.00105913706466283,-0.000197514474701263,0.25,-7.55949735317365E-7,-9.40034585196154E-5,-1.26677027682954E-6,19.9997787,19.9997921,9052.4853515625,9097.3662109375,56.8494054606983,20.5664768829024,12.658426,0,0,0,40,4449,20.0015,9074.92578125,,,,,,,,,,,,,0,,,,0,,,,,,19.9997854,,,,
,31229028.57,20.0005093,13860.0673828125,-9.66313176726729E-5,3.79877936939919E-7,1,0.999253354069792,40.0298881530762,1.99410717451167,20.9999997168779,-0.00108372088637918,-0.000201151565078532,0.25,-6.57823658639029E-7,-9.61663707967766E-5,-1.21464177225528E-6,20.0005093,20.0005093,13855.23046875,13864.904296875,57.2167708647368,20.5677739931184,13.038077,0,0,0,40,4449,20.0001,13860.0673828125,,,,,,,,,,,,,0,,,,0.0049,,,,,,20.0005093,,,,
,31229121.82,20.0005417,18517.568359375,-8.59545491566412E-5,3.88256033161453E-7,1,0.999253354069792,40.0298881530762,1.9939931519486,20.9999997168779,-0.000964697353596029,-0.000177013325527838,0.25,-3.81363063484159E-7,-8.55788648753664E-5,-9.0536353820888E-7,20.0003605,20.0007229,18487.6484375,18547.48828125,57.0901470446214,20.5682369138441,13.038077,0,0,0,40,4449,19.9999,18517.568359375,,,,,,,,,,,,,0,,,,0,,,,,,20.0005417,,,,
,31229214.835,20.0015373,23167.8623046875,-6.64549985376966E-5,4.43745843177636E-7,1,0.999253354069792,40.0298881530762,1.9941291110865,20.9999997168779,-0.000747090633239683,-0.000132167593260217,0.25,1.48066322411333E-7,-6.61975736518143E-5,-2.78334330894751E-7,20.0015335,20.0015411,23135.44140625,23200.283203125,57.2027015513907,20.5661875686152,12.658426,0,0,0,40,4449,19.99735,23167.8623046875,,,,,,,,,,,,,0,,,,0.00245,,,,,,20.0015373,,,,
,31229309.555,20.0013142,27903.0771484375,-5.11238380385507E-5,7.41059377547776E-7,1,0.999253354069792,40.0298881530762,1.99400056119274,20.9999997168779,-0.000576784656924718,-9.16765722238688E-5,0.25,1.02060039702801E-6,-5.09566216358725E-5,6.76122877197186E-7,20.0013142,20.0013142,27878.234375,27927.919921875,57.5286406439099,20.5673320164521,12.658426,0,0,0,40,4449,19.9958,27903.0771484375,,,,,,,,,,,,,0,,,,-0.00245,,,,,,20.0013142,,,,
,31229401.8,20.0018864,32513.3818359375,-4.88546438781832E-5,5.7159817846499E-7,1,0.999253354069792,40.0298881530762,1.99383296189255,20.9999997168779,-0.000549708810517106,-9.71071033083667E-5,0.25,1.44308118521717E-7,-4.87129353782523E-5,-1.92639521209562E-7,20.0018082,20.0019646,32481.005859375,32545.7578125,57.3340151426215,20.5678750400233,13.038077,0,0,0,40,4449,19.99475,32513.3818359375,,,,,,,,,,,,,0,,,,0,,,,,,20.0018864,,,,
,31229495.755,20.0019531,37208.48046875,-5.44933562471424E-5,7.19550542811357E-7,1,0.999253354069792,40.0298881530762,1.99355624094846,20.9999997168779,-0.000614353072005567,-0.000102948546624119,0.25,6.51349154589723E-7,-5.43658648983882E-5,2.6442522207947E-7,20.0019531,20.0019531,37178.78125,37238.1796875,57.0901470446214,20.574385289902,13.038077,0,0,0,40,4449,19.9937,37208.48046875,,,,,,,,,,,,,0,,,,0.00245,,,,,,20.0019531,,,,
,31229590.29,20.0012188,41936.224609375,-6.71075108860128E-5,6.71754720485079E-7,1,0.999253354069792,40.0298881530762,1.99372948366366,20.9999997168779,-0.000755682446126924,-0.000134212153935155,0.25,1.57870335893604E-7,-6.69794673984657E-5,-3.26702725640006E-7,20.0012188,20.0012188,41911.04296875,41961.40625,57.3793495967368,20.5704618700282,12.658426,0,0,0,40,4449,19.99215,41936.224609375,,,,,,,,,,,,,0,,,,-0.0049,,,,,,20.0012188,,,,
,31229685.98,20.0007401,46716.630859375,-8.12590792595828E-5,6.05471768666768E-7,1,0.999253354069792,40.0298881530762,1.99384866076533,20.9999997168779,-0.000915570253082626,-0.000162490706617552,0.25,2.09814162995794E-7,-8.11446449370833E-5,-3.8564429575918E-7,20.0007401,20.0007401,46714.171875,46719.08984375,57.1104693861214,20.5672246225979,12.278775,0,0,0,40,4449,19.9911,46716.630859375,,,,,,,,,,,,,0,,,,0,,,,,,20.0007401,,,,
,31229780.35,20.00073435,51434.125,-9.74272700921837E-5,8.0012068593397E-7,1,0.999253354069792,40.0298881530762,1.99383845308598,20.9999997168779,-0.00109886261558223,-0.000191598863930788,0.25,5.52396582389977E-7,-9.73390742714298E-5,-1.68610740144303E-7,20.0005074,20.0009613,51401.6328125,51466.6171875,57.0463758475445,20.5658967605719,13.038077,0,0,0,40,4449,19.9892,51434.125,,,,,,,,,,,,,0,,,,0,,,,,,20.00073435,,,,
,31229875.795,20.0013027,56204.650390625,-0.000113533704859385,7.62649940236217E-7,1,0.999253354069792,40.0298881530762,1.99380394085157,20.9999997168779,-0.00128058549999586,-0.000226263755918836,0.25,3.91463749624883E-7,-0.000113482481560618,-4.52720806211087E-7,20.0013027,20.0013027,56199.78515625,56209.515625,56.7939098358329,20.5678659903924,13.038077,0,0,0,40,4449,19.9892,56204.650390625,,,,,,,,,,,,,0,,,,0,,,,,,20.0013027,,,,
,31229968.7,20.001236,60847.04296875,-0.000130006829039285,7.88934427709688E-7,1,0.999253354069792,40.0298881530762,1.99384173775274,20.9999997168779,-0.00146418122836602,-0.000275207996466328,0.25,-9.69333116890253E-7,-0.000129994901195136,-1.93695768325526E-6,20.001236,20.001236,60817.13671875,60876.94921875,56.8767624588714,20.5668309372099,12.658426,0,0,0,40,4449,19.98835,60847.04296875,,,,,,,,,,,,,0,,,,-0.0049,,,,,,20.001236,,,,
,31230064.1,20.00189015,65615.50390625,-0.000147953811176562,9.32141587581687E-7,1,0.999253354069792,40.0298881530762,1.99395761018083,20.9999997168779,-0.00166863788818748,-0.000304931542703565,0.25,-3.597046437778E-7,-0.000148009830611209,-1.45867157089018E-6,20.0016479,20.0021324,65590.34375,65640.6640625,57.1182856713137,20.5639938166839,12.658426,0,0,0,40,4449,19.9881,65615.50390625,,,,,,,,,,,,,0,,,,0,,,,,,20.00189015,,,,
,31230159.71,20.0019169,70395.58984375,-0.00016642825300842,6.90022398520509E-7,1,0.999253354069792,40.0298881530762,1.99394289472447,20.9999997168779,-0.00187800093106864,-0.00034178329806308,0.25,-2.90901164629051E-7,-0.000166560821128743,-1.52064278792983E-6,20.0019169,20.0019169,70392.9921875,70398.1875,57.3301070000253,20.5634225632033,12.658426,0,0,0,40,4449,19.9856,70395.58984375,,,,,,,,,,,,,0,,,,0.0049,,,,,,20.0019169,,,,
,31230255.54,20.0018568,75185.75390625,-0.000183647201554081,7.15715361856623E-7,1,0.999253354069792,40.0298881530762,1.99397852403655,20.9999997168779,-0.00207138158492065,-0.000387103879192723,0.25,-1.20062181198335E-6,-0.000183858987132225,-2.54796834475975E-6,20.0016556,20.002058,75155.96875,75215.5390625,57.1112510146407,20.5638305614645,12.278775,0,0,0,40,4449,19.98385,75185.75390625,,,,,,,,,,,,,0,,,,0.00245,,,,,,20.0018568,,,,
,31230351.205,20.00250625,79966.55078125,-0.000202238009840871,1.03869103031054E-6,1,0.999253354069792,40.0298881530762,1.99396096782747,20.9999997168779,-0.00228277248358775,-0.000421546533005166,0.25,-9.0432829454572E-7,-0.000202548942681002,-2.37270116255475E-6,20.0023899,20.0026226,79934.0703125,79999.03125,56.8134505488137,20.5644167709114,13.417728,0,0,0,40,4449,19.9823,79966.55078125,,,,,,,,,,,,,0,,,,0.00245,,,,,,20.00250625,,,,
,31230446.82,20.00202085,84747.75390625,-0.000219171633477488,9.97483426019297E-7,1,0.999253354069792,40.0298881530762,1.99418577755158,20.9999997168779,-0.00247399789963197,-0.000462809216007082,0.25,-1.50954407783212E-6,-0.000219580917749383,-3.08277799748639E-6,20.0019646,20.0020771,84722.6875,84772.8203125,56.8806706014676,20.5647645857802,13.038077,0,0,0,40,4449,19.9805,84747.75390625,,,,,,,,,,,,,0,,,,0,,,,,,20.00202085,,,,
,31230536.18,20.0016346,89213.41796875,-0.000236690800362999,9.12963407714146E-7,1,0.999253354069792,40.0298881530762,1.99401309813983,20.9999997168779,-0.00267366340747756,-0.000492581389889601,0.25,-1.00402459675358E-6,-0.000237209477423504,-2.68014571272818E-6,20.0016346,20.0016346,89190.8046875,89236.03125,57.3441763133715,20.5652011264372,12.658426,0,0,0,40,4449,19.97995,89213.41796875,,,,,,,,,,,,,0,,,,-0.00245,,,,,,20.0016346,,,,
,31230639.665,20.0006561,86391.24609375,-0.000225723962016229,9.62271525294574E-7,1,0.999253354069792,40.0298881530762,1.99409720180861,20.9999997168779,-0.00254990323606694,-0.000466894194736259,0.25,-6.96590984563485E-7,-0.000226177442483145,-2.30780994351241E-6,20.0006561,20.0006561,86363.765625,86418.7265625,56.9611783389483,20.5661620739658,13.038077,0,0,0,40,4449,19.9792,86391.24609375,,,,,,,,,,,,,0,,,,0.00245,,,,,,20.0006561,,,,
,31230733.505,19.9997873,81700.21484375,-0.000207282143837251,7.50019997590201E-7,1,0.999253354069792,40.0298881530762,1.99403529486492,20.9999997168779,-0.00234293281809472,-0.000416345309353954,0.25,4.63727434938161E-7,-0.000207637496389235,-1.03265498984514E-6,19.9996452,19.9999294,81675.2421875,81725.1875,57.2761746321984,20.5649215956671,12.658426,0,0,0,40,4449,19.97995,81700.21484375,,,,,,,,,,,,,0,,,,0.00245,,,,,,19.9997873,,,,
,31230827.44,19.9990625,77003.9140625,-0.000190715934064119,8.43825970087461E-7,1,0.999253354069792,40.0298881530762,1.99414829427499,20.9999997168779,-0.00215165552338717,-0.000401743803319977,0.25,-1.22114798137734E-6,-0.000190963334183756,-2.61538630970659E-6,19.9988918,19.9992332,76976.5,77031.328125,56.9744660237753,20.5647314766759,12.278775,0,0,0,40,4449,19.9805,77003.9140625,,,,,,,,,,,,,0,,,,-0.00245,,,,,,19.9990625,,,,
,31230923.18,19.9983082,72217.96875,-0.000171857701054944,8.5417059058513E-7,1,0.999253354069792,40.0298881530762,1.9941560903863,20.9999997168779,-0.00193540102619004,-0.000377212422744823,0.25,-2.44651018604885E-6,-0.000172004846599501,-3.71499723030468E-6,19.9983082,19.9983082,72188.03125,72247.90625,57.3090030300061,20.5654065211684,12.658426,0,0,0,40,4449,19.98325,72217.96875,,,,,,,,,,,,,0,,,,0,,,,,,19.9983082,,,,
,31231019.455,19.9987659,67407.32421875,-0.000153382297797955,6.69825984786228E-7,1,0.999253354069792,40.0298881530762,1.99407162638665,20.9999997168779,-0.00173103434507547,-0.000311707519072999,0.25,2.19326288044857E-8,-0.000153467424635533,-1.11532474838036E-6,19.9987659,19.9987659,67404.75,67409.8984375,57.3199458292753,20.5671383828577,13.038077,0,0,0,40,4449,19.9844,67407.32421875,,,,,,,,,,,,,0,,,,-0.0049,,,,,,19.9987659,,,,
,31231115.025,19.99881645,62629.564453125,-0.000136752957846306,7.74145034710497E-7,1,0.999253354069792,40.0298881530762,1.99410476208932,20.9999997168779,-0.00154490877276494,-0.000265697539951964,0.25,1.0962053247927E-6,-0.000136778613199321,7.89147500785354E-8,19.9987907,19.9988422,62597.1875,62661.94140625,56.9854088230445,20.5697535935539,12.278775,0,0,0,40,4449,19.98465,62629.564453125,,,,,,,,,,,,,0,,,,0,,,,,,19.99881645,,,,
,31231210.345,19.9976692,57863.498046875,-0.000118450931016009,8.04427886897828E-7,1,0.999253354069792,40.0298881530762,1.99409562693771,20.9999997168779,-0.00133618818620675,-0.000237577832316496,0.25,2.80987865181298E-7,-0.000118415433101001,-6.0040687774717E-7,19.9976692,19.9976692,57833.53515625,57893.4609375,56.8548768603329,20.5674942397496,13.038077,0,0,0,40,4449,19.9868,57863.498046875,,,,,,,,,,,,,0,,,,-0.0049,,,,,,19.9976692,,,,
,31231306.11,19.998806,53078.083984375,-0.000101606702564173,8.13206580182265E-7,1,0.999253354069792,40.0298881530762,1.99421118661426,20.9999997168779,-0.0011464240219467,-0.000199722507476503,0.25,5.922478023127E-7,-0.000101531512507968,-1.61328408281757E-7,19.9986725,19.9989395,53045.30078125,53110.8671875,57.1745629246983,20.5662813549012,12.658426,0,0,0,40,4449,19.98865,53078.083984375,,,,,,,,,,,,,0,,,,-0.0049,,,,,,19.998806,,,,
,31231401.71,19.9988422,48300.560546875,-8.30867152875047E-5,7.48160836856054E-7,1,0.999253354069792,40.0298881530762,1.99418709999821,20.9999997168779,-0.000937425046886501,-0.000160882771516106,0.25,6.88660270561891E-7,-8.29867084544695E-5,7.69514570224812E-8,19.9988422,19.9988422,48297.98046875,48303.140625,57.2214606358522,20.5654801359942,13.038077,0,0,0,40,4449,19.989,48300.560546875,,,,,,,,,,,,,0,,,,0,,,,,,19.9988422,,,,
,31231495.78,19.9999771,43597.494140625,-6.62311663522954E-5,6.69282881476956E-7,1,0.999253354069792,40.0298881530762,1.99422422045433,20.9999997168779,-0.000747013234458084,-0.000127560020590252,0.25,5.98440564714278E-7,-6.61195388880618E-5,1.1668053945097E-7,19.9999771,19.9999771,43569.7109375,43625.27734375,57.0862389020253,20.5666456735999,13.038077,0,0,0,40,4449,19.9893,43597.494140625,,,,,,,,,,,,,0,,,,-0.00245,,,,,,19.9999771,,,,
,31231592.15,19.9996777,38780.20703125,-5.01947289285524E-5,8.56809758257335E-7,1,0.999253354069792,40.0298881530762,1.99429013057582,20.9999997168779,-0.000566070711265849,-9.55093734763351E-5,0.25,5.4635164843044E-7,-5.00852910662873E-5,1.87535644915211E-7,19.9996777,19.9996777,38747.6640625,38812.75,57.1120326431599,20.5675392209886,12.278775,0,0,0,40,4449,19.98935,38780.20703125,,,,,,,,,,,,,0,,,,-0.00245,,,,,,19.9996777,,,,
,31231685.88,19.9985466,34095.60546875,-3.29536995048293E-5,5.73685294810075E-7,1,0.999253354069792,40.0298881530762,1.99436842029389,20.9999997168779,-0.000371624183628275,-6.17789728984063E-5,0.25,4.32806073186838E-7,-3.28659616418176E-5,2.02440580552177E-7,19.9985466,19.9985466,34065.61328125,34125.59765625,57.3691884259868,20.5645645721429,12.658426,0,0,0,40,4449,19.99125,34095.60546875,,,,,,,,,,,,,0,,,,0,,,,,,19.9985466,,,,
,31231779.225,19.99855135,29430.66015625,-1.68318061587559E-5,5.84445588246328E-7,1,0.999253354069792,40.0298881530762,1.99446269259176,20.9999997168779,-0.000189444947613341,-3.31243437873304E-5,0.25,7.67926987493156E-8,-1.67777066290637E-5,-3.70137209585413E-8,19.9985275,19.9985752,29402.98828125,29458.33203125,57.5786648691407,20.5637497107093,12.278775,0,0,0,40,4449,19.99255,29430.66015625,,,,,,,,,,,,,0,,,,-0.00245,,,,,,19.99855135,,,,
,31231871.1,19.9984407,24837.6533203125,-2.00760146437755E-6,6.05741128682857E-7,1,0.999253354069792,40.0298881530762,1.99429320680231,20.9999997168779,-2.33818557391403E-5,5.05080546896975E-7,0.25,4.04913452120444E-7,-2.00276854122607E-6,3.90349046657803E-7,19.9982185,19.9986629,24810.62890625,24864.677734375,57.1425161554099,20.5664488902242,12.278775,0,0,0,40,4449,19.9937,24837.6533203125,,,,,,,,,,,,,0,,,,-0.0049,,,,,,19.9984407,,,,
,31231965.71,19.9987297,20109.8349609375,1.36509668569209E-5,5.16872426838051E-7,1,0.999253354069792,40.0298881530762,1.99428594150675,20.9999997168779,0.000152792098049465,3.07042472191068E-5,0.25,2.89095640309776E-7,1.35919666205524E-5,3.72780290464804E-7,19.9987297,19.9987297,20082.34765625,20137.322265625,56.8845787440637,20.5680471244158,13.038077,0,0,0,40,4449,19.9948,20109.8349609375,,,,,,,,,,,,,0,,,,-0.00245,,,,,,19.9987297,,,,
,31232063.065,19.9983463,15245.3666992187,2.96622085833632E-5,4.0032408352467E-7,1,0.999253354069792,40.0298881530762,1.99443224475351,20.9999997168779,0.000333760185207614,5.61379645904587E-5,0.25,-3.01815180034119E-7,2.95261128102973E-5,-1.25625934704047E-7,19.9983463,19.9983463,15215.205078125,15275.5283203125,56.5531682519098,20.5609597033866,13.038077,0,0,0,40,4449,19.9974,15245.3666992187,,,,,,,,,,,,,0,,,,-0.00245,,,,,,19.9983463,,,,
,31232156.52,19.9982109,10575.408203125,4.44878273196754E-5,3.8866495259754E-7,1,0.999253354069792,40.0298881530762,1.99434844848369,20.9999997168779,0.000498641712741178,9.37517704196776E-5,0.25,4.1668574329162E-7,4.42607389132811E-5,6.61803734691869E-7,19.9982109,19.9982109,10547.96875,10602.84765625,57.3856026248907,20.5633276674587,12.658426,0,0,0,40,4449,19.99855,10575.408203125,,,,,,,,,,,,,0,,,,0,,,,,,19.9982109,,,,
,31232249.885,19.99814985,5907.52465820312,5.90470820666174E-5,3.21445504555954E-7,1,0.999253354069792,40.0298881530762,1.99457453993166,20.9999997168779,0.000661952227668348,0.000122779864039893,0.25,4.28652273311625E-7,5.87253752165981E-5,7.3432815063718E-7,19.9979591,19.9983406,5879.91357421875,5935.1357421875,57.2402197203138,20.5586547882342,13.038077,0,0,0,40,4449,19.99985,5907.52465820312,,,,,,,,,,,,,0,,,,0,,,,,,19.99814985,,,,
,31232343.78,20.0000629,1213.67120361328,7.25329978828339E-5,3.27390719807104E-7,1,0.999253354069792,40.0298881530762,1.99448460232268,20.9999997168779,0.00081301705321169,0.000149919592486912,0.25,4.73336369742039E-7,7.21172049576774E-5,8.26297811389137E-7,20.0000629,20.0000629,1211.10913085938,1216.23327636719,57.4833061897945,20.5613519692337,13.038077,0,0,0,40,4449,19.99985,1213.67120361328,,,,,,,,,,,,,0,,,,0,,,,,,20.0000629,,,,
,31232367.405,19.9995537,30.6265907585621,7.61467937369504E-5,3.26138731218133E-7,1,0.999253354069792,40.0298881530762,1.99450008267819,20.9999997168779,0.000854237063606775,0.000153164556542405,0.25,1.25382414330219E-7,7.57083653273153E-5,4.93716073839203E-7,19.9993935,19.9997139,-0.42626565694809,61.6794471740723,57.2628869473714,20.5614064380417,13.038077,0,0,0,40,4417,19.9996,30.6265907585621,,,,,,,,,,,,,0,,,,0,,,,,,19.9995537,,,,