File: data/doubleLayers/dl_0-125/ppms/data/DD213_7_FCW_100OE.DAT
[Header]
; VSM Data File (default extension .dat)
; Copyright (c) 2003-2013, Quantum Design, Inc. All rights reserved.
TITLE,
FILEOPENTIME,31189755.28,12/28/2018,7:51 am
BYAPP,VSM,2.0,2.0
INFO,PPMS VSM Option Release 1.4.10 Build 1,APPNAME
INFO,Quantum Design Linear Motor Servo Controller,MOTOR_MODULE_NAME
INFO,3101-100 M1,MOTOR_HW_VERSION
INFO,MMC1014,MOTOR_SERIAL_NUMBER
INFO,SRV No X-over 01.03.11,MOTOR_SOFTWARE_VERSION
INFO,Quantum Design VSM Detection Module,VSM_MODULE_NAME
INFO,3101-150 F0,VSM_HW_VERSION
INFO,VSM707,VSM_SERIAL_NUMBER
INFO,VSM No X-over 01.02.05 May 20 2008 13:51:47,VSM_SOFTWARE_VERSION
INFO,704,PREAMP_SERIAL_NUMBER
INFO,822,COIL_SERIAL_NUMBER
INFO,0,MOMENT_UNITS
INFO,CoFe2O4,SAMPLE_MATERIAL
INFO,Double Layer thin concentration,SAMPLE_COMMENT
INFO,29.55,SAMPLE_MASS
INFO,,SAMPLE_VOLUME
INFO,,SAMPLE_MOLECULAR_WEIGHT
INFO,,SAMPLE_SIZE
INFO,,SAMPLE_SHAPE
DATATYPE,COMMENT,1
DATATYPE,TIME,2
STARTUPAXIS,X,2
STARTUPAXIS,Y1,5
[Data]
Comment,Time Stamp (sec),Temperature (K),Magnetic Field (Oe),Moment (emu),M. Std. Err. (emu),Transport Action,Averaging Time (sec),Frequency (Hz),Peak Amplitude (mm),Center Position (mm),Coil Signal' (mV),Coil Signal" (mV),Range (mV),M. Quad. Signal (emu),M. Raw' (emu),M. Raw" (emu),Min. Temperature (K),Max. Temperature (K),Min. Field (Oe),Max. Field (Oe),Mass (grams),Motor Lag (deg),Pressure (Torr),VSM Status (code),Motor Status (code),Measure Status (code),Measure Count,PPMS Status (code),System Temp. (K),System Field (Oe),Sample Position (deg),Bridge 1 Resistance (ohms),Bridge 1 Excitation (에),Bridge 2 Resistance (ohms),Bridge 2 Excitation (에),Bridge 3 Resistance (ohms),Bridge 3 Excitation (에),Bridge 4 Resistance (ohms),Bridge 4 Excitation (에),Signal 1 Vin (V),Signal 2 Vin (V),Digital Inputs (code),Drive 1 Iout (mA),Drive 1 Ipower (W),Drive 2 Iout (mA),Drive 2 Ipower (W),Pressure (),Map 20 (),Map 21 (),Map 22 (),Map 23 (),Map 24 (),Map 25 (),Map 26 (),Map 27 (),Map 28 (),Map 29 ()
sample offset = 36.28 mm,31189782,10.0033665,99.4873580932617,1.90783089400026E-5,3.30575776181223E-7,1,0.999253354069792,40.0298881530762,1.98294495749218,20.8500009030104,0.00021283403349696,3.82156424771682E-5,0.25,3.66076195610991E-8,1.8968582351764E-5,1.28408778842922E-7,10.0033665,10.0033665,99.4873580932617,99.4873580932617,56.9900985941599,20.5682947625911,11.899124,0,0,0,40,4369,9.995,99.4873580932617,,,,,,,,,,,,,0,,,,0,,,,,,10.0033665,,,,
,31189910.305,13.0310116,99.4873580932617,1.97488156504542E-5,2.91135976118948E-7,1,0.999253354069792,40.0298881530762,1.98289801409208,20.8500009030104,0.00022100919226553,3.56077910893755E-5,0.25,-3.16053881156935E-7,1.96368240854E-5,-2.18992668268011E-7,13.0310116,13.0310116,99.4873580932617,99.4873580932617,56.9134989992753,20.5691311939108,11.899124,0,0,0,40,4370,13.1275,99.4873580932617,,,,,,,,,,,,,0,,,,0,,,,,,13.0310116,,,,
,31190052.1,16.5375557,99.4873580932617,1.94437344994692E-5,3.16400596174078E-7,1,0.999253354069792,40.0298881530762,1.98276119365357,20.8500009030104,0.000217521837873919,3.53745557000842E-5,0.25,-2.82539576499788E-7,1.93331472863817E-5,-1.87140531781902E-7,16.5375557,16.5375557,99.4873580932617,99.4873580932617,56.4273260603137,20.572655099371,13.038077,0,0,0,40,4370,16.6811,99.4873580932617,,,,,,,,,,,,,0,,,,0.0049,,,,,,16.5375557,,,,
,31190203.67,20.3170319,99.4873580932617,,,2,,,,20.880000218153,,,,,,,20.3170319,20.3170319,99.4873580932617,99.4873580932617,,,13.038077,,,,-99999999,4370,20.488,99.4873580932617,,,,,,,,,,,,,,,,,,,,,,,20.3170319,,,,
,31190333.69,23.5357304,99.4873580932617,1.94061661687242E-5,3.34502881595463E-7,1,0.999253354069792,40.0298881530762,1.99433283903147,20.8700001239777,0.00021803374026139,3.72179000949019E-5,0.25,-1.32778647434386E-7,1.92973698168097E-5,-3.52194692368593E-8,23.5099049,23.5615559,99.4873580932617,99.4873580932617,56.6743206723906,20.5640336079431,13.417728,0,0,0,40,4370,23.7704,99.4873580932617,,,,,,,,,,,,,0,,,,0,,,,,,23.5357304,,,,
,31190473.52,27.0013008,99.4873580932617,1.95038425469262E-5,2.86298902493482E-7,1,0.999253354069792,40.0298881530762,1.99434736167299,20.8700001239777,0.000218594993597447,4.06958552457205E-5,0.25,1.54321686959105E-7,1.93970906347088E-5,2.55464049691857E-7,27.0013008,27.0013008,99.4873580932617,99.4873580932617,56.9119357422368,20.5636539547735,13.797379,0,0,0,40,4370,27.2951,99.4873580932617,,,,,,,,,,,,,0,,,,0,,,,,,27.0013008,,,,
,31190621.84,30.6896915,99.4873580932617,,,2,,,,20.880000218153,,,,,,,30.6896915,30.6896915,99.4873580932617,99.4873580932617,,,14.177031,,,,-99999999,4370,31.021,99.4873580932617,,,,,,,,,,,,,,,,,,,,,,,30.6896915,,,,
,31190756.155,34.0040665,99.4873580932617,1.93425920547611E-5,3.54724035795124E-7,1,0.999253354069792,40.0298881530762,1.99446681749078,20.8700001239777,0.000217497577649439,3.75128771086789E-5,0.25,-1.18354731135131E-7,1.92544157799418E-5,-1.9040072811745E-9,33.973774,34.034359,99.4873580932617,99.4873580932617,57.2222422643714,20.5605066967027,14.936333,0,0,0,40,4370,34.403,99.4873580932617,,,,,,,,,,,,,0,,,,0,,,,,,34.0040665,,,,
,31190897.925,37.5084953,99.4873580932617,1.97155643017139E-5,3.53507862421401E-7,1,0.999253354069792,40.0298881530762,1.9944181790361,20.8700001239777,0.00022143228319818,4.05283741947395E-5,0.25,7.20272019870328E-8,1.96378706426023E-5,1.98961697331291E-7,37.5084953,37.5084953,99.4873580932617,99.4873580932617,57.1284468420637,20.560350483656,15.315984,0,0,0,40,4370,37.9869,99.4873580932617,,,,,,,,,,,,,0,,,,0,,,,,,37.5084953,,,,
,31191041.7,41.0587006,99.4873580932617,,,2,,,,20.8699996763468,,,,,,,41.0587006,41.0587006,99.4873580932617,99.4873580932617,,,15.695635,,,,-99999999,4370,41.6137,99.4873580932617,,,,,,,,,,,,,,,,,,,,,,,41.0587006,,,,
,31191162.625,44.0436592,99.4873580932617,1.92956646230752E-5,3.72294551789429E-7,1,0.999253354069792,40.0298881530762,1.99465150138025,20.8599995821714,0.000217603479385559,3.70355431435892E-5,0.25,-1.83634548530577E-7,1.92547362339452E-5,-4.45067746397014E-8,44.0436592,44.0436592,99.4873580932617,99.4873580932617,56.9986965078714,20.5586887537082,15.315984,0,0,0,40,4370,44.6787,99.4873580932617,,,,,,,,,,,,,0,,,,0,,,,,,44.0436592,,,,
,31191304.58,47.5156517,99.4873580932617,1.92585742795458E-5,3.48402103141415E-7,1,0.999253354069792,40.0298881530762,1.99456015745844,20.8599995821714,0.000216835425570196,4.02321163046046E-5,0.25,9.92567474233166E-8,1.92369753195287E-5,2.41676998006557E-7,47.5156517,47.5156517,99.4873580932617,99.4873580932617,57.1722180391407,20.5621946437246,16.454937,0,0,0,40,4370,48.2897,99.4873580932617,,,,,,,,,,,,,0,,,,-0.0049,,,,,,47.5156517,,,,
,31191449.885,51.0499916,99.4873580932617,1.94923146696429E-5,3.06486592708481E-7,1,0.999253354069792,40.0298881530762,1.99461099591064,20.8599995821714,0.000220811867728243,3.47668775034017E-5,0.25,-4.31899533326796E-7,1.94972539055056E-5,-2.87123947802388E-7,51.0499916,51.0499916,99.4873580932617,99.4873580932617,57.1479875550445,20.5609885203802,16.454937,0,0,0,40,4374,52.0216,99.4873580932617,,,,,,,,,,,,,0,,,,0,,,,,,51.0499916,,,,
,31191572.53,54.00847245,99.4873580932617,1.93230121380201E-5,3.28876481260089E-7,1,0.999253354069792,40.0298881530762,1.99448684813557,20.8400003612041,0.000218214120623246,3.9349041027618E-5,0.25,4.13982571511606E-9,1.93430717623958E-5,1.45315558202999E-7,53.9835968,54.0333481,99.4873580932617,99.4873580932617,56.9775925378522,20.5630742500913,17.973541,0,0,0,40,4374,55.17935,99.4873580932617,,,,,,,,,,,,,0,,,,-0.00245,,,,,,54.00847245,,,,
,31191720.625,57.5208931,99.4873580932617,1.9219443761588E-5,3.45827491748348E-7,1,0.999253354069792,40.0298881530762,1.99506164390015,20.8400003612041,0.000217204414348435,3.98893972475903E-5,0.25,7.18464505237749E-8,1.92589886697189E-5,2.06691662073134E-7,57.5208931,57.5208931,99.4873580932617,99.4873580932617,57.1010898438907,20.5553972941875,19.492144,0,0,0,40,4374,59.0165,99.4873580932617,,,,,,,,,,,,,0,,,,0,,,,,,57.5208931,,,,
,31191864.19,61.00125885,99.4873580932617,1.89753626396509E-5,3.79976115476485E-7,1,0.999253354069792,40.0298881530762,1.99481719119195,20.8400003612041,0.000214516090146228,3.9897295110103E-5,0.25,1.21316214408295E-7,1.9030287021973E-5,2.47272273873022E-7,60.9719086,61.0306091,99.4873580932617,99.4873580932617,57.0713879601599,20.5570446778145,19.871798,0,0,0,40,4374,62.70985,99.4873580932617,,,,,,,,,,,,,0,,,,-0.00245,,,,,,61.00125885,,,,
,31192008.18,64.5461578,99.4873580932617,1.90180931218575E-5,2.90609432828026E-7,1,0.999253354069792,40.0298881530762,1.99496583779273,20.8199992775917,0.000215405535650276,3.86590712810595E-5,0.25,9.99997730886593E-9,1.90870132229968E-5,1.27639496800811E-7,64.5461578,64.5461578,99.4873580932617,99.4873580932617,56.689171614256,20.5519499100242,20.631098,0,0,0,40,4374,66.3671,99.4873580932617,,,,,,,,,,,,,0,,,,0,,,,,,64.5461578,,,,
,31192147.415,68.0122681,99.4873580932617,1.91173440582302E-5,3.59700418552226E-7,1,0.999253354069792,40.0298881530762,1.99430892647501,20.8199992775917,0.000216954924269601,3.67412733983469E-5,0.25,-1.69491847665184E-7,1.91977680162222E-5,-6.01910570117E-8,68.0122681,68.0122681,99.4873580932617,99.4873580932617,57.065134932006,20.5550535235772,21.3904,0,0,0,40,4374,69.87845,99.4873580932617,,,,,,,,,,,,,0,,,,0,,,,,,68.0122681,,,,
,31192289.14,71.5329361,99.4873580932617,1.92868747431697E-5,2.96130032101514E-7,1,0.999253354069792,40.0298881530762,1.99412054215472,20.8199992775917,0.000218638763208413,3.88262283094348E-5,0.25,-8.64760678284164E-9,1.93752175763158E-5,9.40872439059512E-8,71.5329361,71.5329361,99.4873580932617,99.4873580932617,56.9392927404099,20.5580123626787,21.01075,0,0,0,40,4374,73.45315,99.4873580932617,,,,,,,,,,,,,0,,,,-0.0049,,,,,,71.5329361,,,,
,31192430.47,75.0038452,99.4873580932617,1.93494372104472E-5,3.86362865086331E-7,1,0.999253354069792,40.0298881530762,1.9945435876767,20.7899995148182,0.000219251962678511,4.01596929511141E-5,0.25,1.03699510916041E-7,1.94437910914321E-5,1.99602349185817E-7,75.0038452,75.0038452,99.4873580932617,99.4873580932617,57.0424677049483,20.5528019455513,21.770052,0,0,0,40,4374,77.01545,99.4873580932617,,,,,,,,,,,,,0,,,,0,,,,,,75.0038452,,,,
,31192571.845,78.5182114,99.4873580932617,1.9304829289093E-5,3.39214418717942E-7,1,0.999253354069792,40.0298881530762,1.99422339193746,20.7899995148182,0.000219010047141394,3.870014854344E-5,0.25,-1.02474082625169E-8,1.9404315264735E-5,7.77334502776197E-8,78.5182114,78.5182114,99.4873580932617,99.4873580932617,57.1448610409676,20.5543235069582,21.3904,0,0,0,40,4374,80.6088,99.4873580932617,,,,,,,,,,,,,0,,,,0,,,,,,78.5182114,,,,
,31192715.245,82.0205841,99.4873580932617,1.92468565545705E-5,2.89201312047115E-7,1,0.999253354069792,40.0298881530762,1.99404177420021,20.7899995148182,0.000218347056959331,3.87378447384808E-5,0.25,9.50627439475797E-9,1.93495540887529E-5,9.08197373519029E-8,82.0205841,82.0205841,99.4873580932617,99.4873580932617,57.044812590506,20.5582301295822,21.3904,0,0,0,40,4374,84.22925,99.4873580932617,,,,,,,,,,,,,0,,,,-0.00245,,,,,,82.0205841,,,,
,31192856.93,85.55444335,99.4873580932617,1.9543414563514E-5,3.44426109250343E-7,1,0.999253354069792,40.0298881530762,1.99421953418775,20.7599997520447,0.000222177524944944,3.69748810478664E-5,0.25,-1.93204719236385E-7,1.96510863411988E-5,-1.17600674812649E-7,85.519989,85.5888977,99.4873580932617,99.4873580932617,56.9361662263329,20.5542425288608,21.770052,0,0,0,40,4374,87.7912,99.4873580932617,,,,,,,,,,,,,0,,,,0,,,,,,85.55444335,,,,
,31192995.87,89.02892305,99.4873580932617,1.92073033907146E-5,3.09691079355877E-7,1,0.999253354069792,40.0298881530762,1.99416079370312,20.7599997520447,0.000218758078675713,3.41369672405626E-5,0.25,-3.79049254372546E-7,1.93155225069876E-5,-3.10871293839251E-7,88.998024,89.0598221,99.4873580932617,99.4873580932617,56.790783321756,20.555555748779,21.3904,0,0,0,40,4374,91.2733,99.4873580932617,,,,,,,,,,,,,0,,,,0.00245,,,,,,89.02892305,,,,
,31193137.115,92.5430145,99.4873580932617,1.93561950601413E-5,3.20529837062864E-7,1,0.999253354069792,40.0298881530762,1.99420625157933,20.7599997520447,0.000219981468878637,3.71856137447006E-5,0.25,-1.32323602710456E-7,1.94655236409319E-5,-6.68978662341217E-8,92.5430145,92.5430145,99.4873580932617,99.4873580932617,56.9385111118906,20.5541807832046,22.149702,0,0,0,40,4374,94.8198,99.4873580932617,,,,,,,,,,,,,0,,,,-0.0049,,,,,,92.5430145,,,,
,31193257.85,95.5464478,99.4873580932617,1.89372345553891E-5,3.26585160616116E-7,1,0.999253354069792,40.0298881530762,1.99419360290641,20.7299999892712,0.00021490910855271,3.81803091718785E-5,0.25,3.24835084660724E-8,1.90442822304169E-5,9.38889983643815E-8,95.5464478,95.5464478,99.4873580932617,99.4873580932617,56.7970363499099,20.5551821456244,21.770052,0,0,0,40,4374,97.8428,99.4873580932617,,,,,,,,,,,,,0,,,,-0.00245,,,,,,95.5464478,,,,
,31193397.815,99.0496979,99.4873580932617,1.90187585404668E-5,2.87624346465467E-7,1,0.999253354069792,40.0298881530762,1.99416036172584,20.7299999892712,0.000216304512703771,3.56725545788174E-5,0.25,-1.99065452605104E-7,1.91273524432996E-5,-1.42433633745322E-7,99.0496979,99.0496979,99.4873580932617,99.4873580932617,56.8861420011022,20.5574735446074,22.149702,0,0,0,40,4374,101.3584,99.4873580932617,,,,,,,,,,,,,0,,,,0.0049,,,,,,99.0496979,,,,
,31193537.92,102.5010452,99.4873580932617,1.92229759878811E-5,3.58516608165447E-7,1,0.999253354069792,40.0298881530762,1.99415682650002,20.7299999892712,0.000218978249926087,3.40551993653361E-5,0.25,-3.74020064159652E-7,1.93332764217644E-5,-3.21169331969803E-7,102.5010452,102.5010452,99.4873580932617,99.4873580932617,57.0432493334676,20.5588120780721,22.529354,0,0,0,40,4374,104.8903,99.4873580932617,,,,,,,,,,,,,0,,,,0,,,,,,102.5010452,,,,
,31193659.04,105.5219574,99.4873580932617,1.8930873056328E-5,3.2895708024787E-7,1,0.999253354069792,40.0298881530762,1.98296935287036,20.7000002264977,0.000213729916619742,3.77077189840971E-5,0.25,1.95113479363914E-8,1.90382259135525E-5,7.11352711319538E-8,105.494339,105.5495758,99.4873580932617,99.4873580932617,57.2581971762561,20.5592396965939,22.149702,0,0,0,40,4374,107.9356,99.4873580932617,,,,,,,,,,,,,0,,,,-0.00245,,,,,,105.5219574,,,,
,31193800.53,109.0395012,99.4873580932617,1.88689650452053E-5,3.83957788350987E-7,1,0.999253354069792,40.0298881530762,1.98300273269468,20.7000002264977,0.000213744195026366,3.35072277383194E-5,0.25,-3.38824940980767E-7,1.89764910823111E-5,-2.92180776976435E-7,109.014801,109.0642014,99.4873580932617,99.4873580932617,57.0768593597945,20.5614383283817,22.529354,0,0,0,40,4374,111.49425,99.4873580932617,,,,,,,,,,,,,0,,,,0,,,,,,109.0395012,,,,
,31193940.345,112.5076828,99.4873580932617,1.91643060510436E-5,3.49670711585556E-7,1,0.999253354069792,40.0298881530762,1.98311658703352,20.7000002264977,0.000217178838753547,3.3550134802087E-5,0.25,-3.84315779237597E-7,1.92729740160828E-5,-3.39691170747335E-7,112.4842987,112.5310669,99.4873580932617,99.4873580932617,57.2378748347561,20.5599598161378,22.909004,0,0,0,40,4374,115.01235,99.4873580932617,,,,,,,,,,,,,0,,,,-0.00245,,,,,,112.5076828,,,,
,31194082.095,116.013176,99.4873580932617,1.94917452445521E-5,3.21031869212019E-7,1,0.999253354069792,40.0298881530762,1.9832526605836,20.6599999219179,0.000220610754910144,3.57467418032455E-5,0.25,-2.44846478779496E-7,1.96011042825848E-5,-2.01002251274433E-7,116.013176,116.013176,99.4873580932617,99.4873580932617,56.7626446950637,20.5547593884423,22.909004,0,0,0,40,4374,118.5781,99.4873580932617,,,,,,,,,,,,,0,,,,-0.00245,,,,,,116.013176,,,,
,31194223.065,119.5186539,99.4873580932617,1.92776769705157E-5,3.02988870313102E-7,1,0.999253354069792,40.0298881530762,1.98321915362834,20.6599999219179,0.000218047802567749,3.60716260581693E-5,0.25,-1.76308582924537E-7,1.93847412824463E-5,-1.34694396200013E-7,119.5186539,119.5186539,99.4873580932617,99.4873580932617,56.8322096332752,20.5568860625544,22.909004,0,0,0,40,4374,122.12195,99.4873580932617,,,,,,,,,,,,,0,,,,0.0049,,,,,,119.5186539,,,,
,31194362.225,123.003685,99.4873580932617,1.91466221047635E-5,2.91490672920698E-7,1,0.999253354069792,40.0298881530762,1.98330155640524,20.6599999219179,0.000216706635835118,3.49988384911391E-5,0.25,-2.46453701442693E-7,1.92520529193126E-5,-2.07405729128272E-7,123.003685,123.003685,99.4873580932617,99.4873580932617,56.9189703989099,20.5567804227745,23.288654,0,0,0,40,4374,125.61745,99.4873580932617,,,,,,,,,,,,,0,,,,0.00245,,,,,,123.003685,,,,
,31194503.07,126.5195999,99.4873580932617,1.89058697479641E-5,3.1812428208751E-7,1,0.999253354069792,40.0298881530762,1.99450252528931,20.6199996173382,0.000215078246970103,3.49958526085465E-5,0.25,-2.19351950380795E-7,1.9008762615745E-5,-1.82391449265642E-7,126.5195999,126.5195999,99.4873580932617,99.4873580932617,57.2183341217753,20.5472262344187,23.288654,0,0,0,40,4374,129.1547,99.4873580932617,,,,,,,,,,,,,0,,,,-0.0049,,,,,,126.5195999,,,,
,31194643.105,130.0016403,99.4873580932617,1.86855131489576E-5,3.89782791846336E-7,1,0.999253354069792,40.0298881530762,1.99446700167165,20.6199996173382,0.000212367685642626,3.56516856762338E-5,0.25,-1.21284782579967E-7,1.87857938118238E-5,-8.57996014632083E-8,129.9758911,130.0273895,99.4873580932617,99.4873580932617,57.291807202583,20.5473819945524,23.288654,0,0,0,40,4374,132.6686,99.4873580932617,,,,,,,,,,,,,0,,,,0,,,,,,130.0016403,,,,
,31194783.99,133.5121765,99.4873580932617,1.90066228068613E-5,3.02040572646539E-7,1,0.999253354069792,40.0298881530762,1.99442819674914,20.6199996173382,0.000216364551417276,3.41605925503927E-5,0.25,-3.0694352159709E-7,1.91076299118919E-5,-2.73289156774021E-7,133.4852295,133.5391235,99.4873580932617,99.4873580932617,57.1581487257945,20.548037572826,23.668306,0,0,0,40,4374,136.20405,99.4873580932617,,,,,,,,,,,,,0,,,,0.00245,,,,,,133.5121765,,,,
,31194905.55,136.5273743,99.4873580932617,1.90950923971987E-5,3.40382807847434E-7,1,0.999253354069792,40.0298881530762,1.99453747665485,20.5700006335974,0.000217022187598879,3.63082841875813E-5,0.25,-1.3196647451849E-7,1.91950267506645E-5,-9.8404400558359E-8,136.5273743,136.5273743,99.4873580932617,99.4873580932617,56.8681645451599,20.5448312004655,23.288654,0,0,0,40,4374,139.255,99.4873580932617,,,,,,,,,,,,,0,,,,0.0049,,,,,,136.5273743,,,,
,31195045.55,140.0106888,99.4873580932617,1.9099971335137E-5,3.13377492922794E-7,1,0.999253354069792,40.0298881530762,1.99469229007302,20.5700006335974,0.000217130004722934,3.60138097576143E-5,0.25,-1.57486434754385E-7,1.91985041172483E-5,-1.25309223012611E-7,139.985199,140.0361786,99.4873580932617,99.4873580932617,57.3449579418907,20.5441683953941,23.668306,0,0,0,40,4374,142.764,99.4873580932617,,,,,,,,,,,,,0,,,,0,,,,,,140.0106888,,,,
,31195186.36,143.5170746,99.4873580932617,1.90060265836639E-5,3.87943267036087E-7,1,0.999253354069792,40.0298881530762,1.99456176134352,20.5700006335974,0.000215710230847062,3.76726781316946E-5,0.25,6.67245933110812E-9,1.91022636295662E-5,3.83493247134484E-8,143.5170746,143.5170746,99.4873580932617,99.4873580932617,57.2167708647368,20.544750776923,23.288654,0,0,0,40,4374,146.29865,99.4873580932617,,,,,,,,,,,,,0,,,,0,,,,,,143.5170746,,,,
,31195306.295,146.5273285,99.4873580932617,1.91850862218739E-5,3.50604618543035E-7,1,0.999253354069792,40.0298881530762,1.99452147096948,20.5300003290176,0.000217539064208314,3.90783436640371E-5,0.25,1.0056194451806E-7,1.92807033969784E-5,1.32057348093065E-7,146.5273285,146.5273285,99.4873580932617,99.4873580932617,56.7696793517368,20.5432335037125,24.047956,0,0,0,40,4374,149.30605,99.4873580932617,,,,,,,,,,,,,0,,,,-0.0049,,,,,,146.5273285,,,,
,31195446.875,150.0363617,99.4873580932617,1.87794190140115E-5,3.29136457267719E-7,1,0.999253354069792,40.0298881530762,1.99453687758652,20.5300003290176,0.000214164301582929,3.1119902952852E-5,0.25,-5.28753054615497E-7,1.88723804282064E-5,-5.02026672600875E-7,150.0363617,150.0363617,99.4873580932617,99.4873580932617,57.0440309619868,20.5437313980282,24.047956,0,0,0,40,4374,152.8313,99.4873580932617,,,,,,,,,,,,,0,,,,0,,,,,,150.0363617,,,,
,31195587.28,153.5064545,99.4873580932617,1.93907213748041E-5,3.84280994236644E-7,1,0.999253354069792,40.0298881530762,1.99447342330827,20.5300003290176,0.000220806961326485,3.38657367732124E-5,0.25,-3.91946932998926E-7,1.94847464934125E-5,-3.64539243791004E-7,153.5064545,153.5064545,99.4873580932617,99.4873580932617,57.2441278629099,20.5426828772266,24.047956,0,0,0,40,4374,156.3536,99.4873580932617,,,,,,,,,,,,,0,,,,0.0049,,,,,,153.5064545,,,,
,31195727.295,157.0020447,99.4873580932617,1.9002468524038E-5,3.50734824045007E-7,1,0.999253354069792,40.0298881530762,1.98318459901544,20.4799994826317,0.000214914207347677,3.46262551454039E-5,0.25,-2.39572464040308E-7,1.90926510097642E-5,-2.12884598342794E-7,157.0020447,157.0020447,99.4873580932617,99.4873580932617,56.9361662263329,20.5479841118304,24.047956,0,0,0,40,4374,159.8477,99.4873580932617,,,,,,,,,,,,,0,,,,-0.0049,,,,,,157.0020447,,,,
,31195867.96,160.51906585,99.4873580932617,1.90182975302683E-5,3.13597932268257E-7,1,0.999253354069792,40.0298881530762,1.98318223312744,20.4799994826317,0.000215564264499041,3.18275101052674E-5,0.25,-4.89226225568098E-7,1.9107112540215E-5,-4.64491779396785E-7,160.4929352,160.5451965,99.4873580932617,99.4873580932617,57.0237086204868,20.5498230269865,23.668306,0,0,0,40,4374,163.3796,99.4873580932617,,,,,,,,,,,,,0,,,,0.0049,,,,,,160.51906585,,,,
,31196007.47,164.00068665,99.4873580932617,1.93629470095667E-5,2.87736312195831E-7,1,0.999253354069792,40.0298881530762,1.98320938613022,20.4799994826317,0.000218972139298659,3.51628163522278E-5,0.25,-2.52582955789098E-7,1.94511704390872E-5,-2.27035081282754E-7,163.9721985,164.0291748,99.4873580932617,99.4873580932617,57.0393411908714,20.5514544200768,24.047956,0,0,0,40,4374,166.87595,99.4873580932617,,,,,,,,,,,,,0,,,,0,,,,,,164.00068665,,,,
,31196147.37,167.5149994,99.4873580932617,1.8925025744624E-5,3.41672183236272E-7,1,0.999253354069792,40.0298881530762,1.99452994341716,20.4399991780519,0.000214888472465056,3.61416633281719E-5,0.25,-1.05962353800776E-7,1.90091979627543E-5,-8.10733408434077E-8,167.5149994,167.5149994,99.4873580932617,99.4873580932617,57.5012836457369,20.5457369724434,23.668306,0,0,0,40,4374,170.36815,99.4873580932617,,,,,,,,,,,,,0,,,,0.00245,,,,,,167.5149994,,,,
,31196286.88,171.0009384,99.4873580932617,1.89360527139242E-5,3.804754172639E-7,1,0.999253354069792,40.0298881530762,1.99443435046409,20.4399991780519,0.000215354193171251,3.40205561129691E-5,0.25,-2.93748327270039E-7,1.90186359980944E-5,-2.70337198585957E-7,170.9752502,171.0266266,99.4873580932617,99.4873580932617,57.017455592333,20.5444109599743,24.807261,0,0,0,40,4374,173.8561,99.4873580932617,,,,,,,,,,,,,0,,,,-0.00245,,,,,,171.0009384,,,,
,31196427.23,174.52067565,99.4873580932617,1.91983617967146E-5,3.86581097446363E-7,1,0.999253354069792,40.0298881530762,1.99435410846384,20.4399991780519,0.000218322883271409,3.43937272327924E-5,0.25,-3.05382049721466E-7,1.92801298034139E-5,-2.82311194692605E-7,174.491272,174.5500793,99.4873580932617,99.4873580932617,57.1753445532176,20.5469061101278,24.047956,0,0,0,40,4374,177.36985,99.4873580932617,,,,,,,,,,,,,0,,,,0,,,,,,174.52067565,,,,
,31196566.62,178.0017242,99.4873580932617,1.88889580518697E-5,3.5783037657295E-7,1,0.999253354069792,40.0298881530762,1.99432420561367,20.3799996525049,0.000214778009287238,3.38424514889556E-5,0.25,-2.99239699686749E-7,1.89674592515874E-5,-2.77114915923779E-7,178.0017242,178.0017242,99.4873580932617,99.4873580932617,57.1487691835637,20.5461948755777,24.807261,0,0,0,40,4374,180.8482,99.4873580932617,,,,,,,,,,,,,0,,,,-0.00245,,,,,,178.0017242,,,,
,31196706.605,181.5009308,99.4873580932617,1.92415072177307E-5,2.74129152735318E-7,1,0.999253354069792,40.0298881530762,1.99427656612268,20.3799996525049,0.000218435264974234,3.63309101891043E-5,0.25,-1.40079200834679E-7,1.93192504196365E-5,-1.17437875586124E-7,181.5009308,181.5009308,99.4873580932617,99.4873580932617,56.9275683126214,20.5486811359119,24.427608,0,0,0,40,4374,184.3511,99.4873580932617,,,,,,,,,,,,,0,,,,0,,,,,,181.5009308,,,,
,31196847.455,185.0074921,99.4873580932617,1.91731052890333E-5,3.04882291932759E-7,1,0.999253354069792,40.0298881530762,1.99419209398328,20.3799996525049,0.000218132136209064,3.32887057207686E-5,0.25,-3.95517189360003E-7,1.92488283362887E-5,-3.7451195207269E-7,185.0074921,185.0074921,99.4873580932617,99.4873580932617,56.9408559974483,20.5497299025994,24.047956,0,0,0,40,4374,187.8937,99.4873580932617,,,,,,,,,,,,,0,,,,0,,,,,,185.0074921,,,,
,31196966.84,188.0067291,99.4873580932617,1.89525408514481E-5,3.6405991488221E-7,1,0.999253354069792,40.0298881530762,1.99403717231883,20.3200001269579,0.000215168412565817,3.53084938532513E-5,0.25,-1.78053948236341E-7,1.90253895551195E-5,-1.56887336368197E-7,188.0067291,188.0067291,99.4873580932617,99.4873580932617,57.0409044479099,20.5500725839259,24.807261,0,0,0,40,4374,190.879,99.4873580932617,,,,,,,,,,,,,0,,,,0,,,,,,188.0067291,,,,
,31197108.955,191.5117493,99.4873580932617,1.8974137595856E-5,3.3284216201081E-7,1,0.999253354069792,40.0298881530762,1.9941954964859,20.3200001269579,0.0002156387404691,3.4010625429721E-5,0.25,-2.95704587681672E-7,1.90451283254764E-5,-2.75444064090309E-7,191.5117493,191.5117493,99.4873580932617,99.4873580932617,57.1315733561406,20.5471218530421,24.807261,0,0,0,40,4374,194.4445,99.4873580932617,,,,,,,,,,,,,0,,,,0.0049,,,,,,191.5117493,,,,
,31197249.75,195.0255432,99.4873580932617,1.90419135585138E-5,3.84613861030384E-7,1,0.999253354069792,40.0298881530762,1.9943396147813,20.3200001269579,0.000216789848391164,3.18863014984579E-5,0.25,-4.9430599058165E-7,1.91112606092833E-5,-4.75139444248192E-7,195.0255432,195.0255432,99.4873580932617,99.4873580932617,57.0369963053137,20.5491908376912,25.186911,0,0,0,40,4374,197.9821,99.4873580932617,,,,,,,,,,,,,0,,,,0,,,,,,195.0255432,,,,
,31197389.975,198.5210266,99.4873580932617,1.91394728281265E-5,3.07814487792219E-7,1,0.999253354069792,40.0298881530762,1.99426809523881,20.2799998223782,0.000217404807187425,3.47163872429689E-5,0.25,-2.60644636942941E-7,1.92067782314419E-5,-2.40959713563399E-7,198.5210266,198.5210266,99.4873580932617,99.4873580932617,57.0643533034868,20.5424009026495,24.807261,0,0,0,40,4374,201.49795,99.4873580932617,,,,,,,,,,,,,0,,,,0,,,,,,198.5210266,,,,
,31197530.08,202.0350494,99.4873580932617,1.90180023003327E-5,4.36003131056402E-7,1,0.999253354069792,40.0298881530762,1.99434529935512,20.2799998223782,0.00021584052019963,3.5461201758601E-5,0.25,-1.7315103308703E-7,1.908263254126E-5,-1.53707455676718E-7,202.0350494,202.0350494,99.4873580932617,99.4873580932617,57.0604451608906,20.5444060312446,24.807261,0,0,0,40,4374,204.99735,99.4873580932617,,,,,,,,,,,,,0,,,,0.00245,,,,,,202.0350494,,,,
,31197670.465,205.5297394,99.4873580932617,1.87868441782046E-5,3.13906144896925E-7,1,0.999253354069792,40.0298881530762,1.99444636870801,20.2799998223782,0.000213090861233269,3.56747049014075E-5,0.25,-1.13552118417552E-7,1.88484915427858E-5,-9.45507253067895E-8,205.5297394,205.5297394,99.4873580932617,99.4873580932617,57.0330881627176,20.5419556092095,25.186911,0,0,0,40,4374,208.5065,99.4873580932617,,,,,,,,,,,,,0,,,,0,,,,,,205.5297394,,,,
,31197809.525,209.0184021,99.4873580932617,1.86771806231369E-5,3.30813835695506E-7,1,0.999253354069792,40.0298881530762,1.99460689923134,20.2300008386374,0.000212375644396868,3.23745114337784E-5,0.25,-3.85276535188092E-7,1.87366029714473E-5,-3.67625740122033E-7,209.0184021,209.0184021,99.4873580932617,99.4873580932617,56.9564885678329,20.537592970534,24.807261,0,0,0,40,4374,211.9969,99.4873580932617,,,,,,,,,,,,,0,,,,0.0049,,,,,,209.0184021,,,,
,31197951.14,212.525528,99.4873580932617,1.93874674238013E-5,3.46289800577219E-7,1,0.999253354069792,40.0298881530762,1.99451711758768,20.2300008386374,0.000218953762209897,4.20303232718085E-5,0.25,3.44599661355308E-7,1.94461544881111E-5,3.64839716520599E-7,212.525528,212.525528,99.4873580932617,99.4873580932617,57.3512109700445,20.5400695180389,25.566563,0,0,0,40,4374,215.5363,99.4873580932617,,,,,,,,,,,,,0,,,,0.0049,,,,,,212.525528,,,,
,31198090.575,216.0561981,99.4873580932617,1.90002059007124E-5,3.88294550628665E-7,1,0.999253354069792,40.0298881530762,1.99471461198396,20.2300008386374,0.000215347621955186,3.67405168051705E-5,0.25,-5.46804261096127E-8,1.90558692342807E-5,-3.64011222660333E-8,216.0561981,216.0561981,99.4873580932617,99.4873580932617,57.0385595623522,20.5363644177362,25.186911,0,0,0,40,4374,219.041,99.4873580932617,,,,,,,,,,,,,0,,,,0,,,,,,216.0561981,,,,
,31198229.01,219.5009003,99.4873580932617,1.89740841676201E-5,3.24352435565534E-7,1,0.999253354069792,40.0298881530762,2.0073995679967,20.1699994504452,0.000216961633321017,3.32760583998015E-5,0.25,-3.72999290237249E-7,1.90277757655479E-5,-3.55982122061831E-7,219.5009003,219.5009003,99.4873580932617,99.4873580932617,57.0565370182945,20.5342769952719,25.566563,0,0,0,40,4374,222.49425,99.4873580932617,,,,,,,,,,,,,0,,,,-0.00245,,,,,,219.5009003,,,,
,31198370.92,223.0208282,99.4873580932617,1.92622567843412E-5,4.1680774291266E-7,1,0.999253354069792,40.0298881530762,2.00738928894482,20.1699994504452,0.000220408209987183,3.27471635861155E-5,0.25,-4.68720001262519E-7,1.93145458607884E-5,-4.51992323710642E-7,223.0208282,223.0208282,99.4873580932617,99.4873580932617,57.1948852661984,20.5345122408551,25.186911,0,0,0,40,4374,226.05275,99.4873580932617,,,,,,,,,,,,,0,,,,0,,,,,,223.0208282,,,,
,31198511.035,226.51075745,99.4873580932617,1.88887737447492E-5,4.37991239495309E-7,1,0.999253354069792,40.0298881530762,2.00763042641858,20.1699994504452,0.000215683709149385,3.47051847992509E-5,0.25,-2.31729179245651E-7,1.89375856058759E-5,-2.15011636656595E-7,226.4841309,226.537384,99.4873580932617,99.4873580932617,57.1479875550445,20.5351841802875,25.186911,0,0,0,40,4374,229.5647,99.4873580932617,,,,,,,,,,,,,0,,,,-0.00245,,,,,,226.51075745,,,,
,31198630.16,229.5188141,99.4873580932617,1.85073463631692E-5,4.75388551819985E-7,1,0.999253354069792,40.0298881530762,1.99506279697591,20.1099999248981,0.00021034550530652,3.20616963896431E-5,0.25,-3.80082582750736E-7,1.85533987594901E-5,-3.64319245930847E-7,229.5188141,229.5188141,99.4873580932617,99.4873580932617,56.9181887703906,20.5324230025922,25.566563,0,0,0,40,4374,232.5365,99.4873580932617,,,,,,,,,,,,,0,,,,0.00245,,,,,,229.5188141,,,,
,31198770.945,233.0028305,99.4873580932617,1.85300773652275E-5,3.64223713696109E-7,1,0.999253354069792,40.0298881530762,1.99502558126607,20.1099999248981,0.00021000717629854,3.53685902052492E-5,0.25,-9.13012701167642E-8,1.85736996917013E-5,-7.50959550944033E-8,232.9737549,233.0319061,99.4873580932617,99.4873580932617,56.8837971155445,20.5332492127498,25.566563,0,0,0,40,4374,236.0799,99.4873580932617,,,,,,,,,,,,,0,,,,0.00245,,,,,,233.0028305,,,,
,31198912.365,236.5472565,99.4873580932617,1.86731446803173E-5,3.83322967054594E-7,1,0.999253354069792,40.0298881530762,1.99471467300482,20.1099999248981,0.000211020384397273,3.88071318294052E-5,0.25,1.88759854046831E-7,1.87145649582129E-5,2.05432688623046E-7,236.5472565,236.5472565,99.4873580932617,99.4873580932617,56.9627415959868,20.5377258194174,25.566563,0,0,0,40,4374,239.6168,99.4873580932617,,,,,,,,,,,,,0,,,,-0.00245,,,,,,236.5472565,,,,
,31199032.16,239.53149415,99.4873580932617,1.87636510173033E-5,3.92151175645784E-7,1,0.999253354069792,40.0298881530762,1.99500386489102,20.0599990785122,0.000213048477234702,3.32435501980691E-5,0.25,-3.18257563557715E-7,1.88037613766451E-5,-3.02845088145672E-7,239.5061951,239.5567932,99.4873580932617,99.4873580932617,57.1003082153714,20.5317499174134,25.566563,0,0,0,40,4374,242.61785,99.4873580932617,,,,,,,,,,,,,0,,,,0.0049,,,,,,239.53149415,,,,
,31199172.79,243.0396881,99.4873580932617,1.87413345693681E-5,4.23583472108311E-7,1,0.999253354069792,40.0298881530762,1.99488719125309,20.0599990785122,0.000211996899977083,3.75812231594543E-5,0.25,6.96319116176063E-8,1.8778768392859E-5,8.55630163172147E-8,243.0144043,243.0649719,99.4873580932617,99.4873580932617,56.963523224506,20.5350633437147,25.946213,0,0,0,40,4374,246.15075,99.4873580932617,,,,,,,,,,,,,0,,,,-0.00245,,,,,,243.0396881,,,,
,31199313.21,246.5283356,99.4873580932617,1.81119810483446E-5,3.4803942917584E-7,1,0.999253354069792,40.0298881530762,1.99483567392213,20.0599990785122,0.000205953872657924,2.99359070236653E-5,0.25,-4.96004657505274E-7,1.81464082388915E-5,-4.81933584289657E-7,246.5283356,246.5283356,99.4873580932617,99.4873580932617,57.0674798175637,20.536032596022,25.566563,0,0,0,40,4374,249.67585,99.4873580932617,,,,,,,,,,,,,0,,,,-0.0049,,,,,,246.5283356,,,,
,31199452.165,250.0182037,99.4873580932617,1.8454452887132E-5,3.40214204093767E-7,1,0.999253354069792,40.0298881530762,1.98366066332597,20.0100000947714,0.000207533364401393,3.70611739541157E-5,0.25,9.2454284002096E-8,1.84867683782562E-5,1.07651085644351E-7,249.9932098,250.0431976,99.4873580932617,99.4873580932617,57.0252718775253,20.5415815869054,25.946213,0,0,0,40,4374,253.14665,99.4873580932617,,,,,,,,,,,,,0,,,,0,,,,,,250.0182037,,,,
,31199592.735,253.5098419,99.4873580932617,1.78363353365782E-5,4.2433691887856E-7,1,0.999253354069792,40.0298881530762,1.98366281459612,20.0100000947714,0.000200992696379199,3.33068994591822E-5,0.25,-1.33305906633084E-7,1.78655473273847E-5,-1.19232876106869E-7,253.5098419,253.5098419,99.4873580932617,99.4873580932617,57.2527257766214,20.5429445436211,26.325863,0,0,0,40,4374,256.68215,99.4873580932617,,,,,,,,,,,,,0,,,,0,,,,,,253.5098419,,,,
,31199733.43,257.0148926,99.4873580932617,1.79644339997434E-5,4.20700140414591E-7,1,0.999253354069792,40.0298881530762,1.98349593676392,20.0100000947714,0.000201865704279753,3.65908045211785E-5,0.25,1.37172578188549E-7,1.79914081150587E-5,1.51539362628493E-7,257.0148926,257.0148926,99.4873580932617,99.4873580932617,57.149550812083,20.5459681998262,25.946213,0,0,0,40,4374,260.19095,99.4873580932617,,,,,,,,,,,,,0,,,,-0.0049,,,,,,257.0148926,,,,
,31199872.945,260.5062866,99.4873580932617,1.78307188793434E-5,4.09512095936403E-7,1,0.999253354069792,40.0298881530762,2.00785535907565,19.9400000274181,0.000203616220281524,3.13747133684836E-5,0.25,-3.34953956083575E-7,1.78556468015726E-5,-3.2158600098546E-7,260.5062866,260.5062866,99.4873580932617,99.4873580932617,56.9830639374868,20.530344304009,25.946213,0,0,0,40,4374,263.6757,99.4873580932617,,,,,,,,,,,,,0,,,,0,,,,,,260.5062866,,,,
,31200014.87,264.0173645,99.4873580932617,1.76392773415733E-5,4.84983872743527E-7,1,0.999253354069792,40.0298881530762,2.00794852971529,19.9400000274181,0.000200561323642162,3.59525647818462E-5,0.25,1.0089731735264E-7,1.76613977733969E-5,1.14488607705458E-7,264.0173645,264.0173645,99.4873580932617,99.4873580932617,56.9424192544868,20.5301205562821,25.946213,0,0,0,40,4374,267.2258,99.4873580932617,,,,,,,,,,,,,0,,,,0.00245,,,,,,264.0173645,,,,
,31200156.17,267.5352173,99.4873580932617,1.74861177780032E-5,3.69011962967141E-7,1,0.999253354069792,40.0298881530762,2.00783044402205,19.9400000274181,0.000199420298046941,3.19622373564871E-5,0.25,-2.22430473331242E-7,1.75060946079117E-5,-2.09546471211362E-7,267.5352173,267.5352173,99.4873580932617,99.4873580932617,56.9643048530253,20.5319182614448,25.946213,0,0,0,40,4374,270.7924,99.4873580932617,,,,,,,,,,,,,0,,,,-0.0049,,,,,,267.5352173,,,,
,31200296.315,271.0222778,99.4873580932617,1.69642570950805E-5,3.02070788566612E-7,1,0.999253354069792,40.0298881530762,1.9953655994144,19.8999997228384,0.000192365928856865,3.04326556405078E-5,0.25,-2.49916511022463E-7,1.69815461588693E-5,-2.37619663730448E-7,271.0222778,271.0222778,99.4873580932617,99.4873580932617,56.9658681100637,20.5271398081137,26.325863,0,0,0,40,4374,274.2828,99.4873580932617,,,,,,,,,,,,,0,,,,0,,,,,,271.0222778,,,,
,31200436.875,274.53385925,99.4873580932617,1.7246898856941E-5,4.12746378382276E-7,1,0.999253354069792,40.0298881530762,1.9953341865659,19.8999997228384,0.000195522376898309,3.10567408190723E-5,0.25,-2.43152261549868E-7,1.72622979889125E-5,-2.30804005700797E-7,274.5079956,274.5597229,99.4873580932617,99.4873580932617,56.8666012881214,20.5304510539714,25.946213,0,0,0,40,4374,277.81195,99.4873580932617,,,,,,,,,,,,,0,,,,-0.0049,,,,,,274.53385925,,,,
,31200575.61,278.0053406,99.4873580932617,1.7379836581254E-5,3.58990955772076E-7,1,0.999253354069792,40.0298881530762,1.99547703283935,19.8999997228384,0.000196455539312608,3.45419980779347E-5,0.25,4.23457904378952E-8,1.73929846485415E-5,5.48503849850717E-8,278.0053406,278.0053406,99.4873580932617,99.4873580932617,56.9932251082368,20.529037521783,26.325863,0,0,0,40,4374,281.26755,99.4873580932617,,,,,,,,,,,,,0,,,,0,,,,,,278.0053406,,,,
,31200716.785,281.5282898,99.4873580932617,1.71583185812537E-5,4.15438457524352E-7,1,0.999253354069792,40.0298881530762,1.9956400604541,19.8400001972914,0.000194832186474257,2.89649289906658E-5,0.25,-4.12134324983312E-7,1.7169454483499E-5,-4.00264581759714E-7,281.5282898,281.5282898,99.4873580932617,99.4873580932617,57.0166739638137,20.5243008679623,26.705515,0,0,0,40,4374,284.7904,99.4873580932617,,,,,,,,,,,,,0,,,,-0.0049,,,,,,281.5282898,,,,
,31200858.23,285.0222168,99.4873580932617,1.68938479453006E-5,4.60174899354139E-7,1,0.999253354069792,40.0298881530762,1.99515255111686,19.8400001972914,0.000191439661404658,3.03588334057791E-5,0.25,-2.41894443345203E-7,1.69025787528986E-5,-2.30250468263095E-7,285.0222168,285.0222168,99.4873580932617,99.4873580932617,57.0995265868522,20.5306570763552,25.946213,0,0,0,40,4374,288.33735,99.4873580932617,,,,,,,,,,,,,0,,,,0,,,,,,285.0222168,,,,
,31200999.345,288.521637,99.4873580932617,1.65597972436551E-5,4.10820808274299E-7,1,0.999253354069792,40.0298881530762,1.99533649944557,19.8400001972914,0.000187334487090824,3.1562027365893E-5,0.25,-7.7293837796014E-8,1.65661671383333E-5,-6.59573746194333E-8,288.521637,288.521637,99.4873580932617,99.4873580932617,57.3676251689484,20.5284907480801,26.325863,0,0,0,40,4374,291.8749,99.4873580932617,,,,,,,,,,,,,0,,,,0,,,,,,288.521637,,,,
,31201119.54,291.5552063,99.4873580932617,1.61307207400058E-5,4.30300019313559E-7,1,0.999253354069792,40.0298881530762,1.98417533908692,19.7700001299381,0.000181632978016474,2.97284228212944E-5,0.25,-1.50611773003118E-7,1.61352234427043E-5,-1.39716774025915E-7,291.5552063,291.5552063,99.4873580932617,99.4873580932617,57.0917103016599,20.5350753702486,26.325863,0,0,0,40,4374,294.8782,99.4873580932617,,,,,,,,,,,,,0,,,,0,,,,,,291.5552063,,,,
,31201259.365,295.0157776,99.4873580932617,1.6473441059769E-5,4.58828947412689E-7,1,0.999253354069792,40.0298881530762,1.98418949589269,19.7700001299381,0.000186409972929642,2.49332546069534E-5,0.25,-6.36125676988936E-7,1.64763205141942E-5,-6.25208892273839E-7,295.0157776,295.0157776,99.4873580932617,99.4873580932617,57.0299616486406,20.5343708624995,26.325863,0,0,0,40,4374,298.37715,99.4873580932617,,,,,,,,,,,,,0,,,,0,,,,,,295.0157776,,,,
,31201399.11,298.5067444,99.4873580932617,1.6368150945426E-5,3.9551301453159E-7,1,0.999253354069792,40.0298881530762,1.98421659980233,19.7700001299381,0.000184214858965551,3.04443274701806E-5,0.25,-1.27145723425113E-7,1.63686309518257E-5,-1.16359418909295E-7,298.5067444,298.5067444,99.4873580932617,99.4873580932617,57.0096393071407,20.5348018437769,26.325863,0,0,0,40,4374,301.882,99.4873580932617,,,,,,,,,,,,,0,,,,0,,,,,,298.5067444,,,,
,31201520.085,301.5005188,99.4873580932617,1.59276544490977E-5,4.29247522569241E-7,1,0.999253354069792,40.0298881530762,1.9841138709389,19.7199992835522,0.000179172627172342,2.9947361555659E-5,0.25,-9.45033144018479E-8,1.5926399676395E-5,-8.41214851604985E-8,301.5005188,301.5005188,99.4873580932617,99.4873580932617,57.075296102756,20.5315827261914,26.325863,0,0,0,40,4374,304.92915,99.4873580932617,,,,,,,,,,,,,0,,,,0.0049,,,,,,301.5005188,,,,
,31201661.09,305.0063629,99.4873580932617,1.62299766429264E-5,4.51753400632026E-7,1,0.999253354069792,40.0298881530762,1.98418213665686,19.7199992835522,0.00018187248934435,3.44623636800481E-5,0.25,2.55320432797781E-7,1.62264437428578E-5,2.65695053490298E-7,304.977417,305.0353088,99.4873580932617,99.4873580932617,57.0416860764291,20.5332833737094,26.705515,0,0,0,40,4374,308.45215,99.4873580932617,,,,,,,,,,,,,0,,,,-0.0049,,,,,,305.0063629,,,,
,31201802.495,308.5105591,99.4873580932617,1.52087381746402E-5,4.64295711067422E-7,1,0.999253354069792,40.0298881530762,1.98423461779441,19.7199992835522,0.000171523475716525,2.58722913860811E-5,0.25,-3.31876072105387E-7,1.52038967004757E-5,-3.2212544091402E-7,308.5105591,308.5105591,99.4873580932617,99.4873580932617,57.1378263842945,20.535474447425,26.325863,0,0,0,40,4374,311.9959,99.4873580932617,,,,,,,,,,,,,0,,,,-0.00245,,,,,,308.5105591,,,,
,31201944.735,312.05238345,99.4873580932617,1.52685130397664E-5,3.6778611147894E-7,1,0.999253354069792,40.0298881530762,2.00817555590327,19.6599997580051,0.000173872770063909,2.79174890782253E-5,0.25,-1.88045693965437E-7,1.526164085493E-5,-1.78409804675403E-7,312.0245667,312.0802002,99.4873580932617,99.4873580932617,56.9002113144483,20.5272155172664,27.085165,0,0,0,40,4374,315.5638,99.4873580932617,,,,,,,,,,,,,0,,,,0,,,,,,312.05238345,,,,
,31202083.39,315.522644,99.4873580932617,1.53804631341214E-5,3.54072434963175E-7,1,0.999253354069792,40.0298881530762,2.00808835434335,19.6599997580051,0.000175599789186354,2.53409423759632E-5,0.25,-4.33690351887779E-7,1.53718020343876E-5,-4.23940786829542E-7,315.522644,315.522644,99.4873580932617,99.4873580932617,57.2042648084291,20.5296398682876,26.705515,0,0,0,40,4374,319.03485,99.4873580932617,,,,,,,,,,,,,0,,,,-0.0049,,,,,,315.522644,,,,
,31202225.75,319.0287018,99.4873580932617,1.44999818536028E-5,3.90254477726714E-7,1,0.999253354069792,40.0298881530762,2.0080260450895,19.6599997580051,0.000165415588950418,2.45001686801247E-5,0.25,-3.54736710276316E-7,1.44899880070756E-5,-3.45647074889453E-7,318.9967041,319.0606995,99.4873580932617,99.4873580932617,57.1542405831984,20.5303819203373,27.085165,0,0,0,40,4374,322.59455,99.4873580932617,,,,,,,,,,,,,0,,,,-0.00245,,,,,,319.0287018,,,,
,31202365.665,322.5013733,99.4873580932617,1.45808017640367E-5,4.31927467871518E-7,1,0.999253354069792,40.0298881530762,2.00833364259541,19.6100007742643,0.000166257985379882,2.5119729624505E-5,0.25,-3.14139238616426E-7,1.45689449382162E-5,-3.05100541549981E-7,322.5013733,322.5013733,99.4873580932617,99.4873580932617,57.115940785756,20.5246153484675,26.325863,0,0,0,40,4374,326.1182,99.4873580932617,,,,,,,,,,,,,0,,,,0.00245,,,,,,322.5013733,,,,
,31202506.635,326.0274353,99.4873580932617,1.47460225286703E-5,5.31979799265086E-7,1,0.999253354069792,40.0298881530762,2.00838473574693,19.6100007742643,0.000167568267610427,2.86175996064626E-5,0.25,-3.44906518126508E-8,1.47320407456294E-5,-2.56871357197426E-8,326.0274353,326.0274353,99.4873580932617,99.4873580932617,57.0768593597945,20.5272961373683,26.705515,0,0,0,40,4374,329.6571,99.4873580932617,,,,,,,,,,,,,0,,,,-0.0049,,,,,,326.0274353,,,,
,31202647.11,329.5006714,99.4873580932617,1.43934066548298E-5,4.369929393007E-7,1,0.999253354069792,40.0298881530762,2.0084478792133,19.6100007742643,0.000163459113099646,2.84344924523035E-5,0.25,1.07871782274917E-8,1.43779905805217E-5,1.92357052749508E-8,329.5006714,329.5006714,99.4873580932617,99.4873580932617,56.8447156895829,20.5292362209566,26.705515,0,0,0,40,4374,333.1746,99.4873580932617,,,,,,,,,,,,,0,,,,0,,,,,,329.5006714,,,,
,31202768.4,332.519104,99.4873580932617,1.43707257595149E-5,3.94887938983889E-7,1,0.999253354069792,40.0298881530762,2.00862246079806,19.5499993860722,0.000163132227975428,2.87685675940674E-5,0.25,4.4267098075786E-8,1.43538091286503E-5,5.25778857149392E-8,332.4898682,332.5483398,99.4873580932617,99.4873580932617,56.7915649502752,20.5237132446563,27.085165,0,0,0,40,4374,336.2069,99.4873580932617,,,,,,,,,,,,,0,,,,-0.0049,,,,,,332.519104,,,,
,31202909.265,336.026886,99.4873580932617,1.39693300624913E-5,4.31510016738465E-7,1,0.999253354069792,40.0298881530762,2.00842884350296,19.5499993860722,0.00015964671920036,2.15790380416967E-5,0.25,-5.18729155982047E-7,1.39515166269323E-5,-5.10019524578521E-7,336.026886,336.026886,99.4873580932617,99.4873580932617,56.9916618511983,20.5282611934245,26.705515,0,0,0,40,4374,339.7601,99.4873580932617,,,,,,,,,,,,,0,,,,-0.00245,,,,,,336.026886,,,,
,31203049.735,339.5134888,99.4873580932617,1.35665137271929E-5,5.44584586536945E-7,1,0.999253354069792,40.0298881530762,2.00840765964766,19.5499993860722,0.000154146236458578,2.60171884443131E-5,0.25,-5.77496826868534E-8,1.35473314056518E-5,-4.99469862388143E-8,339.5134888,339.5134888,99.4873580932617,99.4873580932617,57.2417829773522,20.5261234611509,27.464817,0,0,0,40,4374,343.2516,99.4873580932617,,,,,,,,,,,,,0,,,,-0.0049,,,,,,339.5134888,,,,
touchdown = 14.6099999547005 mm,31203185.02,342.8580017,99.4873580932617,1.32547559815279E-5,4.64164725324433E-7,1,0.999253354069792,40.0298881530762,2.00864392028435,19.4899998605251,0.000150658046172599,2.5104909656709E-5,0.25,-8.40323394240498E-8,1.32345146388371E-5,-7.64374904513949E-8,342.8580017,342.8580017,99.4873580932617,99.4873580932617,56.8353361473522,20.5178600034333,27.085165,0,0,0,40,4374,346.6644,99.4873580932617,,,,,,,,,,,,,0,,,,0.0049,,,,,,342.8580017,,,,
,31203310.95,346.00842285,99.4873580932617,1.32770652338136E-5,4.52400586262032E-7,1,0.999253354069792,40.0298881530762,2.0081401933688,19.4899998605251,0.000151669232641235,2.04611293296888E-5,0.25,-4.96206778912376E-7,1.32555976223476E-5,-4.87983730078547E-7,345.9818726,346.0349731,99.4873580932617,99.4873580932617,57.2503808910638,20.525684765499,27.085165,0,0,0,40,4374,349.81195,99.4873580932617,,,,,,,,,,,,,0,,,,-0.00245,,,,,,346.00842285,,,,
,31203622.245,349.5011597,99.4873580932617,1.38343064093635E-5,4.50065272744313E-7,1,0.999253354069792,40.0298881530762,2.00796190830132,19.4899998605251,0.000158245306175602,1.99144688798281E-5,0.25,-6.4048389116254E-7,1.38103690498037E-5,-6.31656665040561E-7,349.5011597,349.5011597,99.4873580932617,99.4873580932617,57.078422616833,20.5285210759124,27.085165,0,0,0,40,4374,350.6381,99.4873580932617,,,,,,,,,,,,,0,,,,-0.00245,,,,,,349.5011597,,,,
,31203748.275,349.7944336,99.4873580932617,1.33401759100482E-5,4.67941005792095E-7,1,0.999253354069792,40.0298881530762,2.00793822388807,19.4899998605251,0.000153461801552924,1.4167306841743E-5,0.25,-1.06135781745229E-6,1.3317208437357E-5,-1.05205936494417E-6,349.7935181,349.7953491,99.4873580932617,99.4873580932617,57.0455942190253,20.5273176131895,27.464817,0,0,0,40,4369,350.7897,99.4873580932617,,,,,,,,,,,,,0,,,,0,,,,,,349.7944336,,,,