File: data/doubleLayers/dl_0-125/ppms/data/DD213_7_ZFCW_100OE.DAT
[Header]
; VSM Data File (default extension .dat)
; Copyright (c) 2003-2013, Quantum Design, Inc. All rights reserved.
TITLE,
FILEOPENTIME,31149303.94,12/27/2018,8:36 pm
BYAPP,VSM,2.0,2.0
INFO,PPMS VSM Option Release 1.4.10 Build 1,APPNAME
INFO,Quantum Design Linear Motor Servo Controller,MOTOR_MODULE_NAME
INFO,3101-100 M1,MOTOR_HW_VERSION
INFO,MMC1014,MOTOR_SERIAL_NUMBER
INFO,SRV No X-over 01.03.11,MOTOR_SOFTWARE_VERSION
INFO,Quantum Design VSM Detection Module,VSM_MODULE_NAME
INFO,3101-150 F0,VSM_HW_VERSION
INFO,VSM707,VSM_SERIAL_NUMBER
INFO,VSM No X-over 01.02.05 May 20 2008 13:51:47,VSM_SOFTWARE_VERSION
INFO,704,PREAMP_SERIAL_NUMBER
INFO,822,COIL_SERIAL_NUMBER
INFO,0,MOMENT_UNITS
INFO,CoFe2O4,SAMPLE_MATERIAL
INFO,Double Layer thin concentration,SAMPLE_COMMENT
INFO,29.55,SAMPLE_MASS
INFO,,SAMPLE_VOLUME
INFO,,SAMPLE_MOLECULAR_WEIGHT
INFO,,SAMPLE_SIZE
INFO,,SAMPLE_SHAPE
DATATYPE,COMMENT,1
DATATYPE,TIME,2
STARTUPAXIS,X,2
STARTUPAXIS,Y1,5
[Data]
Comment,Time Stamp (sec),Temperature (K),Magnetic Field (Oe),Moment (emu),M. Std. Err. (emu),Transport Action,Averaging Time (sec),Frequency (Hz),Peak Amplitude (mm),Center Position (mm),Coil Signal' (mV),Coil Signal" (mV),Range (mV),M. Quad. Signal (emu),M. Raw' (emu),M. Raw" (emu),Min. Temperature (K),Max. Temperature (K),Min. Field (Oe),Max. Field (Oe),Mass (grams),Motor Lag (deg),Pressure (Torr),VSM Status (code),Motor Status (code),Measure Status (code),Measure Count,PPMS Status (code),System Temp. (K),System Field (Oe),Sample Position (deg),Bridge 1 Resistance (ohms),Bridge 1 Excitation (에),Bridge 2 Resistance (ohms),Bridge 2 Excitation (에),Bridge 3 Resistance (ohms),Bridge 3 Excitation (에),Bridge 4 Resistance (ohms),Bridge 4 Excitation (에),Signal 1 Vin (V),Signal 2 Vin (V),Digital Inputs (code),Drive 1 Iout (mA),Drive 1 Ipower (W),Drive 2 Iout (mA),Drive 2 Ipower (W),Pressure (),Map 20 (),Map 21 (),Map 22 (),Map 23 (),Map 24 (),Map 25 (),Map 26 (),Map 27 (),Map 28 (),Map 29 ()
,31161788.78,10.0010548,99.4873580932617,,,2,,,,20.9500002855062,,,,,,,10.0010548,10.0010548,99.4873580932617,99.4873580932617,,,11.139823,,,,-99999999,4373,9.9962,99.4873580932617,,,,,,,,,,,,,,,,,,,,,,,10.0010548,,,,
,31161988.945,12.5102196,99.4873580932617,-1.18894955654205E-7,2.77606625251785E-7,1,0.999253354069792,40.0298881530762,1.99727008529054,20.9400001913309,-1.45576060755833E-6,4.37370952273315E-7,0.25,6.00369271131577E-8,-1.18501235212408E-7,5.9118499310095E-8,12.5102196,12.5102196,99.4873580932617,99.4873580932617,56.5031440266791,20.4928476728225,11.519473,0,0,0,40,4370,12.6372,99.4873580932617,,,,,,,,,,,,,0,,,,0,,,,,,12.5102196,,,,
,31162129.225,16.0253735,99.4873580932617,3.50929165312594E-8,2.90658745531039E-7,1,0.999253354069792,40.0298881530762,1.99699400556533,20.9400001913309,7.15365902923121E-7,-1.73822110018806E-6,0.25,-1.60947286058679E-7,3.56671305391971E-8,-1.5985162391831E-7,16.0253735,16.0253735,99.4873580932617,99.4873580932617,56.5766171074867,20.5027970090934,12.278775,0,0,0,40,4370,16.1484,99.4873580932617,,,,,,,,,,,,,0,,,,-0.00245,,,,,,16.0253735,,,,
,31162269.9,19.50221445,99.4873580932617,-2.79479466735575E-7,2.95393341748245E-7,1,0.999253354069792,40.0298881530762,1.99711907477992,20.9400001913309,-2.6874976350827E-6,-3.10631816659953E-6,0.25,-2.26835715785347E-7,-2.76773657469364E-7,-2.26884535611986E-7,19.473629,19.5307999,99.4873580932617,99.4873580932617,56.750138638756,20.5080076296908,13.417728,0,0,0,40,4370,19.6892,99.4873580932617,,,,,,,,,,,,,0,,,,-0.0049,,,,,,19.50221445,,,,
,31162412.045,23.0163918,99.4873580932617,-2.75679698990268E-7,2.7581208774018E-7,1,0.999253354069792,40.0298881530762,1.99708011744245,20.9400001913309,-2.27296016004918E-6,-5.19055521952185E-6,0.25,-4.12955152500903E-7,-2.72069635661667E-7,-4.11985463332622E-7,23.0163918,23.0163918,99.4873580932617,99.4873580932617,56.9213152844676,20.5088072748696,13.417728,0,0,0,40,4370,23.262,99.4873580932617,,,,,,,,,,,,,0,,,,-0.0049,,,,,,23.0163918,,,,
,31162551.39,26.5043993,99.4873580932617,-4.25464308695625E-7,3.22535457263584E-7,1,0.999253354069792,40.0298881530762,1.99640838995224,20.9400001913309,-4.2607097715158E-6,-3.76760089690238E-6,0.25,-2.59653234592699E-7,-4.2179007909077E-7,-2.60439439515794E-7,26.4814053,26.5273933,99.4873580932617,99.4873580932617,56.9541436822753,20.511680853401,13.417728,0,0,0,40,4370,26.7715,99.4873580932617,,,,,,,,,,,,,0,,,,-0.00245,,,,,,26.5043993,,,,
,31162695.52,30.0781288,99.4873580932617,-2.62383666417487E-7,3.18066909290059E-7,1,0.999253354069792,40.0298881530762,1.9968105081402,20.9400001913309,-2.32116431236024E-6,-4.04744098097988E-6,0.25,-3.1332501313876E-7,-2.59303709247389E-7,-3.13162841033584E-7,30.0781288,30.0781288,99.4873580932617,99.4873580932617,57.0721695886791,20.5159010180959,14.556682,0,0,0,40,4370,30.40055,99.4873580932617,,,,,,,,,,,,,0,,,,-0.00245,,,,,,30.0781288,,,,
,31162834.12,33.5068474,99.4873580932617,-5.10544704052618E-7,3.13947739985826E-7,1,0.999253354069792,40.0298881530762,1.99603722198155,20.9299996495247,-5.41115848077083E-6,-2.8568459671804E-6,0.25,-1.62928707244953E-7,-5.07190733531811E-7,-1.65193156285962E-7,33.5068474,33.5068474,99.4873580932617,99.4873580932617,56.8251749766022,20.5108880237346,14.556682,0,0,0,40,4370,33.8897,99.4873580932617,,,,,,,,,,,,,0,,,,0,,,,,,33.5068474,,,,
,31162977.075,37.0355568,99.4873580932617,-6.38409580173578E-7,2.4329124135969E-7,1,0.999253354069792,40.0298881530762,1.99608816297556,20.9299996495247,-7.09526342005159E-6,-1.75932892976238E-6,0.25,-4.20335147336612E-8,-6.35575303547454E-7,-4.59445536028321E-8,37.0355568,37.0355568,99.4873580932617,99.4873580932617,57.0205821064099,20.511886396353,14.556682,0,0,0,40,4370,37.50595,99.4873580932617,,,,,,,,,,,,,0,,,,0.0049,,,,,,37.0355568,,,,
,31163118.43,40.5215149,99.4873580932617,-1.44618010759765E-7,2.99718102141121E-7,1,0.999253354069792,40.0298881530762,1.99595164746651,20.9299996495247,-1.26792549178483E-6,-2.29453014881765E-6,0.25,-1.77898620329885E-7,-1.42941568958627E-7,-1.78318782723108E-7,40.5215149,40.5215149,99.4873580932617,99.4873580932617,57.044812590506,20.5107967722757,14.556682,0,0,0,40,4370,41.0651,99.4873580932617,,,,,,,,,,,,,0,,,,0,,,,,,40.5215149,,,,
,31163241.68,43.5490189,99.4873580932617,-2.68716763801746E-7,3.38037089823537E-7,1,0.999253354069792,40.0298881530762,1.98438692029249,20.9199991077185,-2.38270212348545E-6,-4.02705562745453E-6,0.25,-3.11161273691566E-7,-2.65865612958457E-7,-3.12356214865093E-7,43.5490189,43.5490189,99.4873580932617,99.4873580932617,56.7892200647175,20.5203920570137,14.936333,0,0,0,40,4370,44.1884,99.4873580932617,,,,,,,,,,,,,0,,,,0,,,,,,43.5490189,,,,
,31163383.015,47.0201759,99.4873580932617,1.38481971810086E-8,3.25011162300051E-7,1,0.999253354069792,40.0298881530762,1.98438386227605,20.9199991077185,1.10597297031024E-6,-5.24786226861573E-6,0.25,-4.70512310462946E-7,1.73041711750922E-8,-4.69825825980123E-7,47.0201759,47.0201759,99.4873580932617,99.4873580932617,56.872072687756,20.5239165555781,16.075285,0,0,0,40,4370,47.78405,99.4873580932617,,,,,,,,,,,,,0,,,,0,,,,,,47.0201759,,,,
,31163526.78,50.5215034,99.4873580932617,-5.1571051645371E-8,3.18073097190244E-7,1,0.999253354069792,40.0298881530762,1.98452848232985,20.9199991077185,1.89729016931346E-7,-4.36908740321009E-6,0.25,-3.79874282758505E-7,-4.87415465887924E-8,-3.80226728014124E-7,50.5215034,50.5215034,99.4873580932617,99.4873580932617,56.8337728903137,20.5206685197624,16.454937,0,0,0,40,4370,51.4727,99.4873580932617,,,,,,,,,,,,,0,,,,0,,,,,,50.5215034,,,,
,31163650.915,53.5186081,99.4873580932617,-4.48833442982189E-7,2.87408164968865E-7,1,0.999253354069792,40.0298881530762,1.99597781906988,20.8999998867512,-4.9274477316407E-6,-1.7142285467546E-6,0.25,-7.08563354035001E-8,-4.48711710908428E-7,-7.42112907811375E-8,53.5186081,53.5186081,99.4873580932617,99.4873580932617,56.8368994043906,20.5111642347362,16.834587,0,0,0,40,4374,54.65565,99.4873580932617,,,,,,,,,,,,,0,,,,-0.0049,,,,,,53.5186081,,,,
,31163797.93,57.0226669,99.4873580932617,2.38593888169636E-7,3.25135731095937E-7,1,0.999253354069792,40.0298881530762,1.99591677615845,20.8999998867512,3.13621459621752E-6,-1.94610532066947E-6,0.25,-2.14950209365816E-7,2.40575086816982E-7,-2.13684071486643E-7,57.0226669,57.0226669,99.4873580932617,99.4873580932617,56.8470605751406,20.5138439725606,18.353191,0,0,0,40,4374,58.4713,99.4873580932617,,,,,,,,,,,,,0,,,,0,,,,,,57.0226669,,,,
,31163941.22,60.5082779,99.4873580932617,-4.80872894665382E-7,3.32802819739076E-7,1,0.999253354069792,40.0298881530762,1.99625892279727,20.8999998867512,-5.22575916826532E-6,-2.20205749673895E-6,0.25,-1.08163321443722E-7,-4.81505998788305E-7,-1.11681157294134E-7,60.5082779,60.5082779,99.4873580932617,99.4873580932617,57.0158923352945,20.5130739209564,19.871798,0,0,0,40,4374,62.16,99.4873580932617,,,,,,,,,,,,,0,,,,-0.0049,,,,,,60.5082779,,,,
,31164084.26,64.0079575,99.4873580932617,-2.92761762697393E-7,3.24503720121444E-7,1,0.999253354069792,40.0298881530762,1.98523001813795,20.8700001239777,-2.9606423214721E-6,-2.48889101979359E-6,0.25,-1.68371454693105E-7,-2.92741189173307E-7,-1.70796395498906E-7,64.0079575,64.0079575,99.4873580932617,99.4873580932617,56.790783321756,20.5202316297075,19.871798,0,0,0,40,4374,65.7852,99.4873580932617,,,,,,,,,,,,,0,,,,0.00245,,,,,,64.0079575,,,,
,31164224.845,67.5042038,99.4873580932617,4.9225647049288E-8,2.81210243266716E-7,1,0.999253354069792,40.0298881530762,1.98483898864892,20.8700001239777,3.62656614912506E-7,1.1773898703111E-6,0.25,9.56047863725773E-8,4.88701040491747E-8,9.6281507422739E-8,67.5042038,67.5042038,99.4873580932617,99.4873580932617,56.8869236296214,20.5261890436688,20.251448,0,0,0,40,4374,69.335,99.4873580932617,,,,,,,,,,,,,0,,,,0.00245,,,,,,67.5042038,,,,
,31164368.05,71.0247574,99.4873580932617,-1.57722345847082E-7,3.07148845665177E-7,1,0.999253354069792,40.0298881530762,1.98461712713844,20.8700001239777,-1.15839293503987E-6,-3.80466020040138E-6,0.25,-3.09113687869752E-7,-1.56770657602562E-7,-3.1136213474279E-7,71.0247574,71.0247574,99.4873580932617,99.4873580932617,56.8251749766022,20.5284567194107,21.01075,0,0,0,40,4374,72.9478,99.4873580932617,,,,,,,,,,,,,0,,,,0,,,,,,71.0247574,,,,
,31164509.005,74.5218124,99.4873580932617,-3.55815605251604E-7,3.0555552285931E-7,1,0.999253354069792,40.0298881530762,1.9846155050293,20.8400003612041,-3.80797756423979E-6,-1.88583941491948E-6,0.25,-1.038485123808E-7,-3.57027533029172E-7,-1.06127218223467E-7,74.5218124,74.5218124,99.4873580932617,99.4873580932617,56.8134505488137,20.5318056185087,20.631098,0,0,0,40,4374,76.5044,99.4873580932617,,,,,,,,,,,,,0,,,,0,,,,,,74.5218124,,,,
,31164650.125,78.0286484,99.4873580932617,1.47353951799056E-7,2.84657817179316E-7,1,0.999253354069792,40.0298881530762,1.98454936689584,20.8400003612041,1.64630604200082E-6,3.93284052217983E-7,0.25,8.70554669602882E-9,1.48067872512229E-7,9.42991830013062E-9,78.0286484,78.0286484,99.4873580932617,99.4873580932617,56.9205336559483,20.5346064134963,20.631098,0,0,0,40,4374,80.0695,99.4873580932617,,,,,,,,,,,,,0,,,,-0.0049,,,,,,78.0286484,,,,
,31164793.405,81.5304871,99.4873580932617,2.83072722206738E-7,3.03510120088525E-7,1,0.999253354069792,40.0298881530762,1.98434553594705,20.8400003612041,3.7164203404324E-6,-2.37198084874892E-6,0.25,-2.60139664132112E-7,2.85687472581949E-7,-2.60313669550406E-7,81.5304871,81.5304871,99.4873580932617,99.4873580932617,57.0119841926983,20.5388233629273,21.01075,0,0,0,40,4374,83.7063,99.4873580932617,,,,,,,,,,,,,0,,,,0.00245,,,,,,81.5304871,,,,
,31164931.82,85.0036392,99.4873580932617,3.46929082175436E-7,2.88419638453274E-7,1,0.999253354069792,40.0298881530762,1.98432648736374,20.8100005984306,4.48212000491325E-6,-2.49909348691583E-6,0.25,-2.82550564578202E-7,3.49942016599209E-7,-2.82712447938576E-7,85.0036392,85.0036392,99.4873580932617,99.4873580932617,56.7407590965252,20.535471371165,21.3904,0,0,0,40,4374,87.17865,99.4873580932617,,,,,,,,,,,,,0,,,,-0.00245,,,,,,85.0036392,,,,
,31165074.06,88.5429688,99.4873580932617,-8.38262862540433E-8,2.78046914862018E-7,1,0.999253354069792,40.0298881530762,1.9843290845742,20.8100005984306,-6.18492535151426E-7,-2.02917690303377E-6,0.25,-1.6485000604653E-7,-8.36819804781962E-8,-1.6607479077308E-7,88.5429688,88.5429688,99.4873580932617,99.4873580932617,56.8681645451599,20.5389682509074,21.3904,0,0,0,40,4374,90.74725,99.4873580932617,,,,,,,,,,,,,0,,,,0,,,,,,88.5429688,,,,
,31165212.46,92.0084686,99.4873580932617,-1.29029175722933E-7,2.67424439234674E-7,1,0.999253354069792,40.0298881530762,1.98427337362564,20.8100005984306,-7.52237098489622E-7,-4.26204211349534E-6,0.25,-3.54545246457494E-7,-1.2852791239575E-7,-3.56982139066745E-7,92.0084686,92.0084686,99.4873580932617,99.4873580932617,57.0565370182945,20.5382164104421,21.3904,0,0,0,40,4374,94.22225,99.4873580932617,,,,,,,,,,,,,0,,,,0.0049,,,,,,92.0084686,,,,
,31165334.315,95.0154877,99.4873580932617,-4.70951436724627E-7,3.27587656328869E-7,1,0.999253354069792,40.0298881530762,1.9954285886229,20.7800008356571,-5.48909988867522E-6,-1.46422183320851E-7,0.25,6.9960173003787E-8,-4.73842149402922E-7,6.88175586180165E-8,95.0154877,95.0154877,99.4873580932617,99.4873580932617,56.943200883006,20.532789495478,21.01075,0,0,0,40,4374,97.28405,99.4873580932617,,,,,,,,,,,,,0,,,,0,,,,,,95.0154877,,,,
,31165475.99,98.5444489,99.4873580932617,-1.50262755468928E-7,3.26373756271135E-7,1,0.999253354069792,40.0298881530762,1.99545613183953,20.7800008356571,-1.07350620058885E-6,-3.9044546233178E-6,0.25,-3.17319257130233E-7,-1.501431976286E-7,-3.19580884661628E-7,98.5444489,98.5444489,99.4873580932617,99.4873580932617,57.2191157502945,20.532705286332,21.3904,0,0,0,40,4374,100.8419,99.4873580932617,,,,,,,,,,,,,0,,,,0.00245,,,,,,98.5444489,,,,
,31165615.72,102.0084305,99.4873580932617,-3.53912731191094E-7,2.50773191027955E-7,1,0.999253354069792,40.0298881530762,1.99559457723473,20.7800008356571,-3.32380258080594E-6,-4.67546548634565E-6,0.25,-3.49432047128302E-7,-3.54915410692039E-7,-3.52438734107628E-7,101.9803162,102.0365448,99.4873580932617,99.4873580932617,56.8290831191983,20.53202790719,21.3904,0,0,0,40,4374,104.35805,99.4873580932617,,,,,,,,,,,,,0,,,,-0.00245,,,,,,102.0084305,,,,
,31165736.39,105.0018463,99.4873580932617,-4.91500760058048E-7,3.16673238782088E-7,1,0.999253354069792,40.0298881530762,1.98418387186935,20.7400005310774,-5.43039888014113E-6,-1.67466902011689E-6,0.25,-6.20148994544603E-8,-4.94120035042249E-7,-6.37159833821773E-8,105.0018463,105.0018463,99.4873580932617,99.4873580932617,56.9619599674676,20.5407175699323,21.770052,0,0,0,40,4374,107.39455,99.4873580932617,,,,,,,,,,,,,0,,,,0.0049,,,,,,105.0018463,,,,
,31165877.83,108.5110397,99.4873580932617,2.2540573107726E-8,2.67249180485991E-7,1,0.999253354069792,40.0298881530762,1.98416866003915,20.7400005310774,1.26269999282807E-6,-5.70777898921471E-6,0.25,-5.09124119689311E-7,2.3989081340938E-8,-5.11945380148651E-7,108.5110397,108.5110397,99.4873580932617,99.4873580932617,56.9353845978137,20.5411247800671,21.770052,0,0,0,40,4374,110.9614,99.4873580932617,,,,,,,,,,,,,0,,,,0.00245,,,,,,108.5110397,,,,
,31166018.79,112.0144272,99.4873580932617,2.64701347643233E-7,3.12085561432541E-7,1,0.999253354069792,40.0298881530762,1.98424896112038,20.7400005310774,3.59436107778237E-6,-2.9229893523119E-6,0.25,-3.0504295488934E-7,2.66940934914961E-7,-3.06108081640653E-7,112.0144272,112.0144272,99.4873580932617,99.4873580932617,56.9596150819099,20.5413385071347,22.149702,0,0,0,40,4374,114.49945,99.4873580932617,,,,,,,,,,,,,0,,,,0,,,,,,112.0144272,,,,
,31166160.78,115.5164795,99.4873580932617,-8.90584176676665E-8,3.83708965166245E-7,1,0.999253354069792,40.0298881530762,1.99548829868856,20.7000002264977,-3.06595989490107E-7,-4.20684455649947E-6,0.25,-3.54741402700101E-7,-8.87273264709678E-8,-3.5693158062029E-7,115.5164795,115.5164795,99.4873580932617,99.4873580932617,57.1026531009291,20.5303893335713,22.149702,0,0,0,40,4374,118.07145,99.4873580932617,,,,,,,,,,,,,0,,,,-0.0049,,,,,,115.5164795,,,,
,31166301.155,119.0194588,99.4873580932617,7.9240246397649E-8,3.19468873423222E-7,1,0.999253354069792,40.0298881530762,1.99555183431571,20.7000002264977,1.0835317158777E-6,-8.91277177131183E-7,0.25,-9.2313589430684E-8,7.98846809351946E-8,-9.26487599709427E-8,118.9936066,119.045311,99.4873580932617,99.4873580932617,56.9775925378522,20.5329864233768,22.529354,0,0,0,40,4374,121.5978,99.4873580932617,,,,,,,,,,,,,0,,,,0.00245,,,,,,119.0194588,,,,
,31166440.77,122.5040665,99.4873580932617,-2.68251177337258E-7,2.72318374943148E-7,1,0.999253354069792,40.0298881530762,1.99536952609776,20.7000002264977,-2.56185615744533E-6,-3.30830493084313E-6,0.25,-2.44383820433427E-7,-2.69204176359577E-7,-2.4629456678085E-7,122.5040665,122.5040665,99.4873580932617,99.4873580932617,56.963523224506,20.5350147306226,22.909004,0,0,0,40,4374,125.1123,99.4873580932617,,,,,,,,,,,,,0,,,,0.0049,,,,,,122.5040665,,,,
,31166581.5,126.0266571,99.4873580932617,-6.40534810074956E-8,2.46356100274011E-7,1,0.999253354069792,40.0298881530762,1.98425260862637,20.6499993801117,-5.70267176127981E-7,-1.00459351232385E-6,0.25,-7.77334371892484E-8,-6.42432966452345E-8,-7.82854147599153E-8,126.0266571,126.0266571,99.4873580932617,99.4873580932617,56.9275683126214,20.5399518255214,22.529354,0,0,0,40,4374,128.6465,99.4873580932617,,,,,,,,,,,,,0,,,,-0.0049,,,,,,126.0266571,,,,
,31166723.285,129.534668,99.4873580932617,8.17346858413345E-9,2.75612265004749E-7,1,0.999253354069792,40.0298881530762,1.98427865060675,20.6499993801117,4.60140132302789E-7,-2.09079770351301E-6,0.25,-1.86499045312763E-7,8.57996356641121E-9,-1.87483383012307E-7,129.534668,129.534668,99.4873580932617,99.4873580932617,57.0080760501022,20.5407029928635,23.288654,0,0,0,40,4374,132.203,99.4873580932617,,,,,,,,,,,,,0,,,,-0.0049,,,,,,129.534668,,,,
,31166862.925,133.02581025,99.4873580932617,1.40776808004941E-7,2.79966350851806E-7,1,0.999253354069792,40.0298881530762,1.98445960049862,20.6499993801117,2.18123982539565E-6,-3.10839829510753E-6,0.25,-2.997029406646E-7,1.42081497288788E-7,-3.0102689404159E-7,132.99823,133.0533905,99.4873580932617,99.4873580932617,56.9916618511983,20.5378229007124,22.909004,0,0,0,40,4374,135.7125,99.4873580932617,,,,,,,,,,,,,0,,,,0,,,,,,133.02581025,,,,
,31166983.085,136.00358585,99.4873580932617,9.88087463888414E-8,3.05312939073209E-7,1,0.999253354069792,40.0298881530762,2.00829407148655,20.609999075532,2.43035565822671E-6,-7.26367920699099E-6,0.25,-6.52924617924039E-7,1.00503811663238E-7,-6.56162626036991E-7,135.977829,136.0293427,99.4873580932617,99.4873580932617,56.9494539111599,20.5357786043149,22.529354,0,0,0,40,4374,138.7216,99.4873580932617,,,,,,,,,,,,,0,,,,0,,,,,,136.00358585,,,,
,31167124.485,139.5239334,99.4873580932617,2.0507820691406E-7,3.47202930749211E-7,1,0.999253354069792,40.0298881530762,2.00825184242961,20.609999075532,3.24124039965012E-6,-4.74255200710762E-6,0.25,-4.50842085790837E-7,2.06918196798661E-7,-4.52810339350247E-7,139.4984283,139.5494385,99.4873580932617,99.4873580932617,56.9932251082368,20.5365277330991,22.909004,0,0,0,40,4374,142.2721,99.4873580932617,,,,,,,,,,,,,0,,,,0,,,,,,139.5239334,,,,
,31167265.285,143.0471649,99.4873580932617,3.44599925799574E-7,3.12307051553602E-7,1,0.999253354069792,40.0298881530762,2.00822058173078,20.609999075532,4.37847473619019E-6,-1.84743330281912E-6,0.25,-2.21768631663215E-7,3.46719853483962E-7,-2.22317471171331E-7,143.0471649,143.0471649,99.4873580932617,99.4873580932617,57.1815975813714,20.5371523998504,23.288654,0,0,0,40,4374,145.8034,99.4873580932617,,,,,,,,,,,,,0,,,,-0.0049,,,,,,143.0471649,,,,
,31167385.915,146.0589294,99.4873580932617,1.89434999575087E-7,3.07272264589064E-7,1,0.999253354069792,40.0298881530762,1.98432027952081,20.5600000917912,2.28087081489726E-6,-4.38683676599736E-7,0.25,-7.18493796692373E-8,1.90499489207388E-7,-7.19014159863175E-8,146.0589294,146.0589294,99.4873580932617,99.4873580932617,57.1503324406022,20.5390745314945,23.668306,0,0,0,40,4374,148.82985,99.4873580932617,,,,,,,,,,,,,0,,,,-0.0049,,,,,,146.0589294,,,,
,31167526.205,149.5358276,99.4873580932617,5.11077498201386E-7,3.51413660778979E-7,1,0.999253354069792,40.0298881530762,1.98438941676393,20.5600000917912,6.41821829085783E-6,-2.70532820258685E-6,0.25,-3.28568465333307E-7,5.14106743965715E-7,-3.2938291481275E-7,149.5358276,149.5358276,99.4873580932617,99.4873580932617,56.8877052581406,20.5387713731275,23.668306,0,0,0,40,4374,152.3411,99.4873580932617,,,,,,,,,,,,,0,,,,0,,,,,,149.5358276,,,,
,31167665.21,153.0296783,99.4873580932617,1.1270266462822E-7,3.21490441718954E-7,1,0.999253354069792,40.0298881530762,1.98448954259325,20.5600000917912,1.65405597127736E-6,-1.96798143629196E-6,0.25,-1.93887986029351E-7,1.1354142493955E-7,-1.94653470919144E-7,153.0296783,153.0296783,99.4873580932617,99.4873580932617,57.126101956506,20.5371774381154,23.668306,0,0,0,40,4374,155.8297,99.4873580932617,,,,,,,,,,,,,0,,,,-0.0049,,,,,,153.0296783,,,,
,31167785.005,156.0038605,99.4873580932617,2.75422641254691E-7,2.28926371595612E-7,1,0.999253354069792,40.0298881530762,2.00860172433429,20.5099992454052,4.01662454610441E-6,-4.45185120747217E-6,0.25,-4.37664775738135E-7,2.77378457343796E-7,-4.39338355823057E-7,156.0038605,156.0038605,99.4873580932617,99.4873580932617,56.6766655579483,20.5339636678289,23.288654,0,0,0,40,4374,158.83175,99.4873580932617,,,,,,,,,,,,,0,,,,0,,,,,,156.0038605,,,,
,31167925.495,159.5166473,99.4873580932617,3.78017468439445E-7,3.57341480851451E-7,1,0.999253354069792,40.0298881530762,2.00842426153954,20.5099992454052,4.0773809450464E-6,2.13097568688519E-6,0.25,1.20785538278263E-7,3.79606173658836E-7,1.21889901840323E-7,159.5166473,159.5166473,99.4873580932617,99.4873580932617,56.8892685151791,20.5357564342638,23.668306,0,0,0,40,4374,162.351,99.4873580932617,,,,,,,,,,,,,0,,,,0,,,,,,159.5166473,,,,
,31168066.32,163.0123291,99.4873580932617,3.43086136027725E-7,2.95138019637052E-7,1,0.999253354069792,40.0298881530762,2.00850113724249,20.5099992454052,4.02044065326963E-6,9.49036732523201E-8,0.25,-5.13879827359326E-8,3.44723938749615E-7,-5.11456743247362E-8,162.9867859,163.0378723,99.4873580932617,99.4873580932617,57.0893654161022,20.5353580019517,23.288654,0,0,0,40,4374,165.8786,99.4873580932617,,,,,,,,,,,,,0,,,,0,,,,,,163.0123291,,,,
,31168205.29,166.5045776,99.4873580932617,6.13113435046606E-8,3.39624065281581E-7,1,0.999253354069792,40.0298881530762,1.98453621833267,20.4600002616644,7.97941310709302E-7,-4.87505298718677E-7,0.25,-5.38472963730982E-8,6.16580658825796E-8,-5.4005082895305E-8,166.5045776,166.5045776,99.4873580932617,99.4873580932617,56.9744660237753,20.5344858279188,24.047956,0,0,0,40,4374,169.3492,99.4873580932617,,,,,,,,,,,,,0,,,,-0.0049,,,,,,166.5045776,,,,
,31168345.615,170.0153122,99.4873580932617,5.90581739543901E-7,3.26177115699139E-7,1,0.999253354069792,40.0298881530762,1.98435001013884,20.4600002616644,7.04817555313285E-6,-1.03637721968482E-6,0.25,-1.94531640212281E-7,5.93417667039429E-7,-1.94605677854702E-7,169.988266,170.0423584,99.4873580932617,99.4873580932617,57.1792526958137,20.5373138891707,23.668306,0,0,0,40,4374,172.86265,99.4873580932617,,,,,,,,,,,,,0,,,,0.00245,,,,,,170.0153122,,,,
,31168486.095,173.5235748,99.4873580932617,4.07670321846487E-7,3.11347864989045E-7,1,0.999253354069792,40.0298881530762,1.98424510991948,20.4600002616644,5.39202757214693E-6,-3.74919468319424E-6,0.25,-4.03087854400958E-7,4.09925707352177E-7,-4.04286925138996E-7,173.5235748,173.5235748,99.4873580932617,99.4873580932617,57.2269320354868,20.5406100710642,23.668306,0,0,0,40,4374,176.3711,99.4873580932617,,,,,,,,,,,,,0,,,,0,,,,,,173.5235748,,,,
,31168624.645,177.0100098,99.4873580932617,8.57697751185487E-7,2.87977895976201E-7,1,0.999253354069792,40.0298881530762,1.99566256129769,20.4199999570847,1.0188463810345E-5,-9.32305510933629E-7,0.25,-2.31278846136349E-7,8.61558852482745E-7,-2.3117347233349E-7,177.0100098,177.0100098,99.4873580932617,99.4873580932617,56.8048526351022,20.5284079246444,23.668306,0,0,0,40,4374,179.8267,99.4873580932617,,,,,,,,,,,,,0,,,,0,,,,,,177.0100098,,,,
,31168765.915,180.5408936,99.4873580932617,-5.91083519537631E-8,2.89028380523936E-7,1,0.999253354069792,40.0298881530762,1.99556269854418,20.4199999570847,-6.80008011258082E-7,-6.24310635076026E-8,0.25,4.77152604885289E-9,-5.93541546043164E-8,4.71911298013059E-9,180.5408936,180.5408936,99.4873580932617,99.4873580932617,56.9861904515637,20.534892581822,24.427608,0,0,0,40,4374,183.3687,99.4873580932617,,,,,,,,,,,,,0,,,,0.0049,,,,,,180.5408936,,,,
,31168906.435,184.0466614,99.4873580932617,7.77255437460661E-7,3.60067731833293E-7,1,0.999253354069792,40.0298881530762,1.99537973269788,20.4199999570847,9.16600664308996E-6,-4.78883614271949E-7,0.25,-1.77298989485885E-7,7.80539100835912E-7,-1.77079256099164E-7,184.0466614,184.0466614,99.4873580932617,99.4873580932617,57.1229754424291,20.5366850735319,24.047956,0,0,0,40,4374,186.888,99.4873580932617,,,,,,,,,,,,,0,,,,0,,,,,,184.0466614,,,,
,31169025.605,187.0086975,99.4873580932617,8.99147478781982E-7,2.60862019871426E-7,1,0.999253354069792,40.0298881530762,2.00802654122494,20.3699991106987,1.07185844953993E-5,-8.56773353977339E-7,0.25,-2.31327714353802E-7,9.02890019047025E-7,-2.31177951318289E-7,187.0086975,187.0086975,99.4873580932617,99.4873580932617,56.7282530402175,20.5341631650457,24.047956,0,0,0,40,4374,189.88595,99.4873580932617,,,,,,,,,,,,,0,,,,0,,,,,,187.0086975,,,,
,31169166.93,190.51135255,99.4873580932617,1.51223068983575E-6,3.22318406317291E-7,1,0.999253354069792,40.0298881530762,2.00782155766362,20.3699991106987,1.80340678087539E-5,-1.5031218411912E-6,0.25,-3.94490253529086E-7,1.51835647128898E-6,-3.94257586351187E-7,190.484848,190.5378571,99.4873580932617,99.4873580932617,57.0237086204868,20.5377291472101,24.047956,0,0,0,40,4374,193.4203,99.4873580932617,,,,,,,,,,,,,0,,,,0,,,,,,190.51135255,,,,
,31169306.92,194.01097105,99.4873580932617,9.56079251943874E-7,3.21152758797152E-7,1,0.999253354069792,40.0298881530762,2.00806634403524,20.3699991106987,1.15858911389167E-5,-2.01063553891727E-6,0.25,-3.42323465205482E-7,9.59943662440893E-7,-3.42512226297066E-7,193.9845581,194.037384,99.4873580932617,99.4873580932617,56.9596150819099,20.5360605500683,24.427608,0,0,0,40,4374,196.93385,99.4873580932617,,,,,,,,,,,,,0,,,,0.00245,,,,,,194.01097105,,,,
touchdown = 15.429999679327 mm,31169441.12,197.3412018,99.4873580932617,9.04896982503328E-7,2.4168767733655E-7,1,0.999253354069792,40.0298881530762,1.98523154182397,20.3099995851517,1.1019110069254E-5,-2.88236139881492E-6,0.25,-4.12619373722842E-7,9.08547354727864E-7,-4.13098781500396E-7,197.3412018,197.3412018,99.4873580932617,99.4873580932617,56.8228300910445,20.5167271317927,24.807261,0,0,0,40,4374,200.3097,99.4873580932617,,,,,,,,,,,,,0,,,,0.0049,,,,,,197.3412018,,,,
,31169568.89,200.5503082,99.4873580932617,1.55565107741999E-6,3.32434923736056E-7,1,0.999253354069792,40.0298881530762,1.98403915792258,20.3099995851517,1.73580072280143E-5,4.10267739623028E-6,0.25,9.36766129768314E-8,1.56089783918685E-6,9.5652024723905E-8,200.5503082,200.5503082,99.4873580932617,99.4873580932617,57.0643533034868,20.539954526274,24.427608,0,0,0,40,4374,203.507,99.4873580932617,,,,,,,,,,,,,0,,,,0,,,,,,200.5503082,,,,
,31169707.85,204.0127563,99.4873580932617,1.84487472256106E-6,3.07317439211181E-7,1,0.999253354069792,40.0298881530762,1.984058200979,20.3099995851517,2.13093357783821E-5,6.82591154570119E-7,0.25,-2.59812226737578E-7,1.85127861358112E-6,-2.58756154939967E-7,204.0127563,204.0127563,99.4873580932617,99.4873580932617,56.9346029692945,20.5425111968319,24.807261,0,0,0,40,4374,206.9854,99.4873580932617,,,,,,,,,,,,,0,,,,0,,,,,,204.0127563,,,,
touchdown = 15.37000015378 mm,31169855.405,207.702652,99.4873580932617,1.64367382700135E-6,2.98148785726511E-7,1,0.999253354069792,40.0298881530762,1.99608988500878,20.2500000596046,1.88983915857044E-5,1.73197789476238E-6,0.25,-1.32629959210383E-7,1.64907518237094E-6,-1.31381557030494E-7,207.702652,207.702652,99.4873580932617,99.4873580932617,56.6883899857368,20.5163050370397,24.807261,0,0,0,40,4374,210.6799,99.4873580932617,,,,,,,,,,,,,0,,,,-0.0049,,,,,,207.702652,,,,
,31169987.445,211.00646975,99.4873580932617,2.28678654950377E-6,3.15504334222362E-7,1,0.999253354069792,40.0298881530762,1.99557433947439,20.2500000596046,2.55921261293664E-5,6.39014768851261E-6,0.25,1.66771827479275E-7,2.29369763740897E-6,1.69571909580447E-7,210.9788666,211.0340729,99.4873580932617,99.4873580932617,56.8626931455252,20.5306227837273,24.807261,0,0,0,40,4374,213.975,99.4873580932617,,,,,,,,,,,,,0,,,,-0.00245,,,,,,211.00646975,,,,
,31170127.52,214.5076447,99.4873580932617,2.61340102228816E-6,3.72337963889548E-7,1,0.999253354069792,40.0298881530762,1.99562877261403,20.2500000596046,3.0286977161765E-5,1.29810584964863E-6,0.25,-3.39105715130809E-7,2.62151729457213E-6,-3.37557379720339E-7,214.5076447,214.5076447,99.4873580932617,99.4873580932617,56.9502355396791,20.5321609114186,24.807261,0,0,0,40,4374,217.49125,99.4873580932617,,,,,,,,,,,,,0,,,,0,,,,,,214.5076447,,,,
touchdown = 15.3200002387166 mm,31170271.145,218.063858,99.4873580932617,2.63429106056762E-6,3.94163094150652E-7,1,0.999253354069792,40.0298881530762,1.98433016718386,20.1999992132187,3.03761162116502E-5,1.2102643912114E-6,0.25,-3.49837060047567E-7,2.64215936711971E-6,-3.48309746669335E-7,218.063858,218.063858,99.4873580932617,99.4873580932617,56.9932251082368,20.53465601458,25.186911,0,0,0,40,4374,221.0871,99.4873580932617,,,,,,,,,,,,,0,,,,-0.0049,,,,,,218.063858,,,,
,31170408.415,221.5220337,99.4873580932617,2.89468557006508E-6,3.56160484481865E-7,1,0.999253354069792,40.0298881530762,1.98436029696185,20.1999992132187,3.31686631342039E-5,2.52018459011589E-6,0.25,-2.78739032487634E-7,2.90288726591511E-6,-2.76777629430333E-7,221.5220337,221.5220337,99.4873580932617,99.4873580932617,56.9205336559483,20.5375867203875,24.807261,0,0,0,40,4374,224.517,99.4873580932617,,,,,,,,,,,,,0,,,,0.0049,,,,,,221.5220337,,,,
,31170549.625,225.02034,99.4873580932617,3.5885955910473E-6,3.70318118741306E-7,1,0.999253354069792,40.0298881530762,1.98429493982687,20.1999992132187,4.10693656755756E-5,3.37859128033591E-6,0.25,-3.22887344408317E-7,3.59830971496561E-6,-3.20418878015461E-7,225.02034,225.02034,99.4873580932617,99.4873580932617,57.1729996676599,20.5414971758778,24.807261,0,0,0,40,4374,228.0617,99.4873580932617,,,,,,,,,,,,,0,,,,0,,,,,,225.02034,,,,
touchdown = 15.259999781847 mm,31170687.53,228.4943237,99.4873580932617,3.34517267745978E-6,3.86836945930141E-7,1,0.999253354069792,40.0298881530762,1.99567656049778,20.1399996876717,3.81439560839145E-5,5.15239113090999E-6,0.25,-1.25615371346998E-7,3.35366621863693E-6,-1.22895050085197E-7,228.4943237,228.4943237,99.4873580932617,99.4873580932617,56.7235632691022,20.5281148993991,24.807261,0,0,0,40,4374,231.5154,99.4873580932617,,,,,,,,,,,,,0,,,,0.0049,,,,,,228.4943237,,,,
,31170809.18,231.5081177,99.4873580932617,3.83880337432236E-6,3.04163559369337E-7,1,0.999253354069792,40.0298881530762,1.9954724539397,20.1399996876717,4.29249461250359E-5,1.0746858625026E-5,0.25,2.82803333117407E-7,3.84776912787606E-6,2.86910605031601E-7,231.4800873,231.5361481,99.4873580932617,99.4873580932617,56.7688977232175,20.5333612815721,25.566563,0,0,0,40,4374,234.56595,99.4873580932617,,,,,,,,,,,,,0,,,,0,,,,,,231.5081177,,,,
,31170951.71,235.0668488,99.4873580932617,4.27314301104211E-6,3.20150591005328E-7,1,0.999253354069792,40.0298881530762,1.99562790746767,20.1399996876717,4.86033456031388E-5,7.21275037949292E-6,0.25,-1.04470362610475E-7,4.28297028899326E-6,-1.00961408613316E-7,235.0668488,235.0668488,99.4873580932617,99.4873580932617,57.0666981890445,20.533655874253,24.807261,0,0,0,40,4374,238.1428,99.4873580932617,,,,,,,,,,,,,0,,,,0,,,,,,235.0668488,,,,
,31171090.45,238.5093842,99.4873580932617,,,2,,,,20.0999998667836,,,,,,,238.5093842,238.5093842,99.4873580932617,99.4873580932617,,,25.186911,,,,-99999999,4374,241.6194,99.4873580932617,,,,,,,,,,,,,,,,,,,,,,,238.5093842,,,,
,31171210.94,241.5413361,99.4873580932617,5.04936499449042E-6,3.99253772241563E-7,1,0.999253354069792,40.0298881530762,1.99562271441631,20.0800001621246,5.81497949188575E-5,4.30833001240167E-6,0.25,-4.95334755058706E-7,5.06015156447945E-6,-4.92065192985863E-7,241.5413361,241.5413361,99.4873580932617,99.4873580932617,57.0901470446214,20.5283392736339,24.807261,0,0,0,40,4374,244.6341,99.4873580932617,,,,,,,,,,,,,0,,,,0,,,,,,241.5413361,,,,
,31171352.415,245.0545807,99.4873580932617,5.9530610248973E-6,3.37219445317013E-7,1,0.999253354069792,40.0298881530762,1.99580215130363,20.0800001621246,6.7399551609177E-5,1.17376678779356E-5,0.25,4.13830329230831E-9,5.96454627872912E-6,9.11302373428818E-9,245.0545807,245.0545807,99.4873580932617,99.4873580932617,57.0229269919676,20.5286285565014,24.807261,0,0,0,40,4374,248.1849,99.4873580932617,,,,,,,,,,,,,0,,,,0.0049,,,,,,245.0545807,,,,
,31171506.41,248.8913422,99.4873580932617,,,2,,,,20.0400003412366,,,,,,,248.8913422,248.8913422,99.4873580932617,99.4873580932617,,,25.186911,,,,-99999999,4374,252.035,99.4873580932617,,,,,,,,,,,,,,,,,,,,,,,248.8913422,,,,
,31171631.515,252.0285263,99.4873580932617,6.937685701091E-6,4.19645378900189E-7,1,0.999253354069792,40.0298881530762,2.00821429654897,20.0299993157387,7.92973577706938E-5,1.20070149819401E-5,0.25,-1.48648933737303E-7,6.94948992250393E-6,-1.43300734896642E-7,252.0011597,252.0558929,99.4873580932617,99.4873580932617,57.2386564632753,20.5332898512574,24.807261,0,0,0,40,4374,255.15475,99.4873580932617,,,,,,,,,,,,,0,,,,-0.0049,,,,,,252.0285263,,,,
,31171750.73,255.0010986,99.4873580932617,7.72007662701571E-6,4.26565201487619E-7,1,0.999253354069792,40.0298881530762,2.00850531829193,20.0299993157387,8.7788606973332E-5,1.59817885631653E-5,0.25,6.4761997928014E-8,7.73221483537196E-6,7.10071385041995E-8,255.0010986,255.0010986,99.4873580932617,99.4873580932617,56.966649738583,20.5302857545603,24.807261,0,0,0,40,4374,258.1566,99.4873580932617,,,,,,,,,,,,,0,,,,-0.0049,,,,,,255.0010986,,,,
,31171894.02,258.5442505,99.4873580932617,7.96504515750828E-6,3.29894745027139E-7,1,0.999253354069792,40.0298881530762,2.00841263062302,20.0299993157387,9.07040665585309E-5,1.56489276002274E-5,0.25,-6.60654462217084E-9,7.97662548600228E-6,-3.83042447283235E-10,258.5442505,258.5442505,99.4873580932617,99.4873580932617,56.926005055583,20.5308565382953,25.566563,0,0,0,40,4374,261.7559,99.4873580932617,,,,,,,,,,,,,0,,,,0,,,,,,258.5442505,,,,
,31172033.97,262.0387268,99.4873580932617,8.48651119883132E-6,3.4339995111566E-7,1,0.999253354069792,40.0298881530762,2.00837934756525,19.9800003319979,9.75628842241901E-5,1.12836997890824E-5,0.25,-4.80156122845301E-7,8.4981589289191E-6,-4.74258508775404E-7,262.0387268,262.0387268,99.4873580932617,99.4873580932617,56.6876083572175,20.5358550922407,25.946213,0,0,0,40,4374,265.2607,99.4873580932617,,,,,,,,,,,,,0,,,,0,,,,,,262.0387268,,,,
,31172173.815,265.5168152,99.4873580932617,9.59334870282494E-6,4.36309091111301E-7,1,0.999253354069792,40.0298881530762,2.00851646750059,19.9800003319979,0.000108793239061763,2.13354726854437E-5,0.25,2.11106847497467E-7,9.60474798763332E-6,2.18634170564836E-7,265.4884644,265.545166,99.4873580932617,99.4873580932617,56.9916618511983,20.5320367514517,25.946213,0,0,0,40,4374,268.7442,99.4873580932617,,,,,,,,,,,,,0,,,,-0.00245,,,,,,265.5168152,,,,
,31172314.425,269.02400205,99.4873580932617,9.4692500398907E-6,5.01300410592211E-7,1,0.999253354069792,40.0298881530762,2.00841537395598,19.9800003319979,0.000107824305862637,1.84196660757079E-5,0.25,-2.31226693452895E-8,9.47949114234946E-6,-1.60807049632955E-8,268.9963684,269.0516357,99.4873580932617,99.4873580932617,57.0948368157368,20.5331114230176,25.946213,0,0,0,40,4374,272.27365,99.4873580932617,,,,,,,,,,,,,0,,,,-0.00245,,,,,,269.02400205,,,,
,31172453.85,272.5069885,99.4873580932617,1.04007642087339E-5,4.27537346424514E-7,1,0.999253354069792,40.0298881530762,1.98459975851504,19.9200008064508,0.000117107166035998,1.98200480981994E-5,0.25,-4.12847675675988E-8,1.04107286774166E-5,-3.36803482847444E-8,272.4820251,272.5319519,99.4873580932617,99.4873580932617,56.8673829166406,20.5333687251723,25.566563,0,0,0,40,4374,275.7654,99.4873580932617,,,,,,,,,,,,,0,,,,0.0049,,,,,,272.5069885,,,,
,31172593.355,276.0152893,99.4873580932617,1.07187541547435E-5,4.42737752587733E-7,1,0.999253354069792,40.0298881530762,1.98469894710277,19.9200008064508,0.00012037139503058,2.21944421850415E-5,0.25,1.14891236509676E-7,1.07275624609099E-5,1.22746753201353E-7,276.0152893,276.0152893,99.4873580932617,99.4873580932617,56.8603482599676,20.5343321193803,25.566563,0,0,0,40,4374,279.2206,99.4873580932617,,,,,,,,,,,,,0,,,,0,,,,,,276.0152893,,,,
,31172735.01,279.51737975,99.4873580932617,1.13620617915592E-5,4.18401203932012E-7,1,0.999253354069792,40.0298881530762,1.98463565883946,19.9200008064508,0.000128991436468072,1.53549794682202E-5,0.25,-6.04175195789252E-7,1.13704924706022E-5,-5.96499330753543E-7,279.4864807,279.5482788,99.4873580932617,99.4873580932617,56.9275683126214,20.5354391297224,25.946213,0,0,0,40,4374,282.783,99.4873580932617,,,,,,,,,,,,,0,,,,-0.00245,,,,,,279.51737975,,,,
,31172856.03,282.5263977,99.4873580932617,1.20710577006608E-5,4.22751047858831E-7,1,0.999253354069792,40.0298881530762,1.98481017201464,19.8599994182587,0.000136319275366295,2.04554699960639E-5,0.25,-2.73488121313238E-7,1.20784477670557E-5,-2.65154124032964E-7,282.5263977,282.5263977,99.4873580932617,99.4873580932617,56.9752476522945,20.5311212805507,25.946213,0,0,0,40,4374,285.8106,99.4873580932617,,,,,,,,,,,,,0,,,,0.00245,,,,,,282.5263977,,,,
,31172996.19,286.0322571,99.4873580932617,1.26315939505275E-5,4.33215039833974E-7,1,0.999253354069792,40.0298881530762,1.98474003882667,19.8599994182587,0.000142917133368331,1.9725886071562E-5,0.25,-4.35079781571407E-7,1.26378405186222E-5,-4.26522127813544E-7,286.0322571,286.0322571,99.4873580932617,99.4873580932617,56.9416376259676,20.5312198864506,26.325863,0,0,0,40,4374,289.3072,99.4873580932617,,,,,,,,,,,,,0,,,,0.0049,,,,,,286.0322571,,,,
,31173137.235,289.5223999,99.4873580932617,1.29466342985182E-5,4.75249568202772E-7,1,0.999253354069792,40.0298881530762,1.984821972092,19.8599994182587,0.000145605292570803,2.5200573873959E-5,0.25,-2.58937977371464E-9,1.29511104441278E-5,6.26038417679311E-9,289.5223999,289.5223999,99.4873580932617,99.4873580932617,56.9095908566791,20.5299997332067,25.566563,0,0,0,40,4374,292.8445,99.4873580932617,,,,,,,,,,,,,0,,,,-0.00245,,,,,,289.5223999,,,,
,31173258.93,292.568512,99.4873580932617,1.29476795997272E-5,4.46219188788158E-7,1,0.999253354069792,40.0298881530762,1.98476275642271,19.7999998927116,0.000146170398597612,2.18900303771976E-5,0.25,-2.96763747738365E-7,1.29509425888714E-5,-2.88092523323548E-7,292.568512,292.568512,99.4873580932617,99.4873580932617,56.780622151006,20.5275641798984,26.325863,0,0,0,40,4374,295.9086,99.4873580932617,,,,,,,,,,,,,0,,,,0,,,,,,292.568512,,,,
,31173399.53,296.0502014,99.4873580932617,1.34582436543512E-5,4.53940985331353E-7,1,0.999253354069792,40.0298881530762,1.98475750324921,19.7999998927116,0.000152223432987401,2.09700533662498E-5,0.25,-4.66680173999225E-7,1.34600615529857E-5,-4.57774329576538E-7,296.0502014,296.0502014,99.4873580932617,99.4873580932617,57.0768593597945,20.5292396538937,26.325863,0,0,0,40,4374,299.4327,99.4873580932617,,,,,,,,,,,,,0,,,,-0.0049,,,,,,296.0502014,,,,
,31173538.99,299.5220642,99.4873580932617,1.40239334471271E-5,4.37774028928015E-7,1,0.999253354069792,40.0298881530762,1.98476500184691,19.7999998927116,0.000157849717741051,2.61948872266784E-5,0.25,-9.95768049772176E-8,1.40238298125508E-5,-9.03686456967558E-8,299.5220642,299.5220642,99.4873580932617,99.4873580932617,56.9955699937945,20.5329968381499,25.946213,0,0,0,40,4374,302.9029,99.4873580932617,,,,,,,,,,,,,0,,,,0,,,,,,299.5220642,,,,
,31173679.96,303.0271301,99.4873580932617,1.36663203936822E-5,4.34158883067826E-7,1,0.999253354069792,40.0298881530762,2.0087975642387,19.7400003671646,0.000155615381344481,2.5627442239527E-5,0.25,-1.13727747899647E-7,1.3664520700936E-5,-1.0486342452092E-7,303.0271301,303.0271301,99.4873580932617,99.4873580932617,56.7532651528329,20.5294697125441,25.566563,0,0,0,40,4374,306.4469,99.4873580932617,,,,,,,,,,,,,0,,,,-0.00245,,,,,,303.0271301,,,,
,31173820.665,306.5399475,99.4873580932617,1.42037459993735E-5,5.26369794063529E-7,1,0.999253354069792,40.0298881530762,2.00869142616817,19.7400003671646,0.000161525802419613,2.76738560438561E-5,0.25,-2.63059990614979E-8,1.42000394133001E-5,-1.72261795048434E-8,306.5399475,306.5399475,99.4873580932617,99.4873580932617,56.8634747740445,20.5313913338191,25.946213,0,0,0,40,4374,309.9687,99.4873580932617,,,,,,,,,,,,,0,,,,0,,,,,,306.5399475,,,,
,31173960.54,310.0050354,99.4873580932617,1.3890398854759E-5,4.85631922168889E-7,1,0.999253354069792,40.0298881530762,2.00881711221407,19.7400003671646,0.000158594863891671,2.33526719920645E-5,0.25,-3.51880846232146E-7,1.38852698144522E-5,-3.42989795030955E-7,309.9747925,310.0352783,99.4873580932617,99.4873580932617,56.7329428113329,20.5302993036103,26.325863,0,0,0,40,4374,313.48505,99.4873580932617,,,,,,,,,,,,,0,,,,0,,,,,,310.0050354,,,,
,31174102.145,313.5264587,99.4873580932617,1.42113933158967E-5,4.8073958759565E-7,1,0.999253354069792,40.0298881530762,1.98510086663393,19.6800008416176,0.000159967720324667,2.61790292380683E-5,0.25,-1.32195407917414E-7,1.42042281158064E-5,-1.23287934050804E-7,313.5018005,313.5511169,99.4873580932617,99.4873580932617,56.9158438848329,20.5262707047282,26.705515,0,0,0,40,4374,317.0455,99.4873580932617,,,,,,,,,,,,,0,,,,0.00245,,,,,,313.5264587,,,,
,31174243.015,317.0260315,99.4873580932617,1.37979152453805E-5,4.61013044852106E-7,1,0.999253354069792,40.0298881530762,1.98494677055822,19.6800008416176,0.000156048546960334,2.09911141720299E-5,0.25,-5.21727517065073E-7,1.37894934204192E-5,-5.12923463932876E-7,317.0010376,317.0510254,99.4873580932617,99.4873580932617,56.8728543162753,20.528207978948,26.705515,0,0,0,40,4374,320.56095,99.4873580932617,,,,,,,,,,,,,0,,,,-0.00245,,,,,,317.0260315,,,,
,31174383.57,320.5068665,99.4873580932617,1.46997497922356E-5,3.9222374236442E-7,1,0.999253354069792,40.0298881530762,1.98494921066611,19.6800008416176,0.000165297312196668,2.77319149188422E-5,0.25,-7.75924690690308E-8,1.46886818396379E-5,-6.86194063259022E-8,320.5068665,320.5068665,99.4873580932617,99.4873580932617,57.0033862789868,20.5287198923938,25.946213,0,0,0,40,4374,324.08165,99.4873580932617,,,,,,,,,,,,,0,,,,-0.00735,,,,,,320.5068665,,,,
,31174524.325,324.0143127,99.4873580932617,1.42744262533104E-5,4.42748210848835E-7,1,0.999253354069792,40.0298881530762,1.98516642686864,19.6199994534254,0.000160244151491525,2.84731939689895E-5,0.25,6.22086210231904E-8,1.42618393540588E-5,7.07038126063122E-8,324.0143127,324.0143127,99.4873580932617,99.4873580932617,56.9799374234099,20.5252407930973,26.325863,0,0,0,40,4374,327.6214,99.4873580932617,,,,,,,,,,,,,0,,,,-0.0049,,,,,,324.0143127,,,,
,31174666.125,327.5206299,99.4873580932617,1.39984374467358E-5,5.4002866159999E-7,1,0.999253354069792,40.0298881530762,1.98524627671158,19.6199994534254,0.000156990338033005,2.87422619621858E-5,0.25,1.3427411639255E-7,1.39843362086594E-5,1.42422956987082E-7,327.5206299,327.5206299,99.4873580932617,99.4873580932617,57.0205821064099,20.5271571645595,26.325863,0,0,0,40,4374,331.1736,99.4873580932617,,,,,,,,,,,,,0,,,,0,,,,,,327.5206299,,,,
,31174806,331.0279541,99.4873580932617,1.3396430416748E-5,5.11264747742899E-7,1,0.999253354069792,40.0298881530762,1.98526347542291,19.6199994534254,0.000151664717929166,1.91712983315713E-5,0.25,-6.13181035861588E-7,1.3381735825887E-5,-6.04657178176863E-7,331.0279541,331.0279541,99.4873580932617,99.4873580932617,57.0518472471791,20.5270209084568,26.705515,0,0,0,40,4374,334.68255,99.4873580932617,,,,,,,,,,,,,0,,,,0,,,,,,331.0279541,,,,
,31174927.915,334.0239868,99.4873580932617,1.38413837906266E-5,4.58079442522892E-7,1,0.999253354069792,40.0298881530762,1.98511731526602,19.5599999278784,0.000155951738500636,2.398007995668E-5,0.25,-2.6166356308337E-7,1.38245459911507E-5,-2.53327227637754E-7,334.0239868,334.0239868,99.4873580932617,99.4873580932617,56.8955215433329,20.5240943401072,26.325863,0,0,0,40,4374,337.7308,99.4873580932617,,,,,,,,,,,,,0,,,,0,,,,,,334.0239868,,,,
,31175067.985,337.5201721,99.4873580932617,1.35451581208892E-5,4.65907772657174E-7,1,0.999253354069792,40.0298881530762,1.98500773201134,19.5599999278784,0.000152043945663586,2.6602649869564E-5,0.25,2.36580474671672E-8,1.35268864246542E-5,3.13829733043358E-8,337.5201721,337.5201721,99.4873580932617,99.4873580932617,56.8798889729483,20.5292667937913,26.705515,0,0,0,40,4374,341.24245,99.4873580932617,,,,,,,,,,,,,0,,,,0.00245,,,,,,337.5201721,,,,
,31175208.77,341.01765445,99.4873580932617,1.3574664431863E-5,4.70049960161645E-7,1,0.999253354069792,40.0298881530762,1.98488356940812,19.5599999278784,0.00015256277916511,2.54140508895806E-5,0.25,-8.68179444949318E-8,1.35547879783236E-5,-7.90008318832527E-8,340.9917908,341.0435181,99.4873580932617,99.4873580932617,57.0213637349291,20.5292824369713,26.705515,0,0,0,40,4374,344.78035,99.4873580932617,,,,,,,,,,,,,0,,,,0,,,,,,341.01765445,,,,
,31175329.625,344.04400635,99.4873580932617,1.40690143049113E-5,4.07029845837812E-7,1,0.999253354069792,40.0298881530762,1.99654558909302,19.4899998605251,0.000158969067727472,2.66005625607727E-5,0.25,-7.96327145084638E-8,1.40469557559107E-5,-7.16092332030535E-8,344.0186462,344.0693665,99.4873580932617,99.4873580932617,56.8423708040252,20.518776957215,26.325863,0,0,0,40,4374,347.7997,99.4873580932617,,,,,,,,,,,,,0,,,,0.00245,,,,,,344.04400635,,,,
,31175469.695,347.50283815,99.4873580932617,1.32418991550283E-5,4.57351010494676E-7,1,0.999253354069792,40.0298881530762,1.99654886683464,19.4899998605251,0.000150190121361814,2.16600612634784E-5,0.25,-3.73786894779165E-7,1.32197501037994E-5,-3.65796488485502E-7,347.4761353,347.529541,99.4873580932617,99.4873580932617,56.9439825115252,20.5227269404916,26.705515,0,0,0,40,4374,351.3087,99.4873580932617,,,,,,,,,,,,,0,,,,0.0049,,,,,,347.50283815,,,,
,31175843.63,349.7865295,99.4873580932617,1.3014475855085E-5,4.42430076577205E-7,1,0.999253354069792,40.0298881530762,1.99630432578966,19.4899998605251,0.000147748122085895,2.03244538861617E-5,0.25,-4.52402001052109E-7,1.29917481226199E-5,-4.44360173290655E-7,349.7865295,349.7865295,99.4873580932617,99.4873580932617,56.9017745714868,20.5247258930579,27.085165,0,0,0,40,4369,350.7827,99.4873580932617,,,,,,,,,,,,,0,,,,-0.00245,,,,,,349.7865295,,,,