File: data/doubleLayers/dl_0-125/ppms/data/DD213_7_HYST_100OE_150K.DAT
[Header]
; VSM Data File (default extension .dat)
; Copyright (c) 2003-2013, Quantum Design, Inc. All rights reserved.
TITLE,
FILEOPENTIME,31257855.14,12/29/2018,2:46 am
BYAPP,VSM,2.0,2.0
INFO,PPMS VSM Option Release 1.4.10 Build 1,APPNAME
INFO,Quantum Design Linear Motor Servo Controller,MOTOR_MODULE_NAME
INFO,3101-100 M1,MOTOR_HW_VERSION
INFO,MMC1014,MOTOR_SERIAL_NUMBER
INFO,SRV No X-over 01.03.11,MOTOR_SOFTWARE_VERSION
INFO,Quantum Design VSM Detection Module,VSM_MODULE_NAME
INFO,3101-150 F0,VSM_HW_VERSION
INFO,VSM707,VSM_SERIAL_NUMBER
INFO,VSM No X-over 01.02.05 May 20 2008 13:51:47,VSM_SOFTWARE_VERSION
INFO,704,PREAMP_SERIAL_NUMBER
INFO,822,COIL_SERIAL_NUMBER
INFO,0,MOMENT_UNITS
INFO,CoFe2O4,SAMPLE_MATERIAL
INFO,Double Layer thin concentration,SAMPLE_COMMENT
INFO,29.55,SAMPLE_MASS
INFO,,SAMPLE_VOLUME
INFO,,SAMPLE_MOLECULAR_WEIGHT
INFO,,SAMPLE_SIZE
INFO,,SAMPLE_SHAPE
DATATYPE,COMMENT,1
DATATYPE,TIME,2
STARTUPAXIS,X,2
STARTUPAXIS,Y1,5
[Data]
Comment,Time Stamp (sec),Temperature (K),Magnetic Field (Oe),Moment (emu),M. Std. Err. (emu),Transport Action,Averaging Time (sec),Frequency (Hz),Peak Amplitude (mm),Center Position (mm),Coil Signal' (mV),Coil Signal" (mV),Range (mV),M. Quad. Signal (emu),M. Raw' (emu),M. Raw" (emu),Min. Temperature (K),Max. Temperature (K),Min. Field (Oe),Max. Field (Oe),Mass (grams),Motor Lag (deg),Pressure (Torr),VSM Status (code),Motor Status (code),Measure Status (code),Measure Count,PPMS Status (code),System Temp. (K),System Field (Oe),Sample Position (deg),Bridge 1 Resistance (ohms),Bridge 1 Excitation (에),Bridge 2 Resistance (ohms),Bridge 2 Excitation (에),Bridge 3 Resistance (ohms),Bridge 3 Excitation (에),Bridge 4 Resistance (ohms),Bridge 4 Excitation (에),Signal 1 Vin (V),Signal 2 Vin (V),Digital Inputs (code),Drive 1 Iout (mA),Drive 1 Ipower (W),Drive 2 Iout (mA),Drive 2 Ipower (W),Pressure (),Map 20 (),Map 21 (),Map 22 (),Map 23 (),Map 24 (),Map 25 (),Map 26 (),Map 27 (),Map 28 (),Map 29 ()
,31257869.83,149.9916382,-0.243580371141434,,,2,,,,20.489999576807,,,,,,,149.9916382,149.9916382,-0.243580371141434,-0.243580371141434,,,24.807261,,,,-99999999,4369,149.8887,-0.243580371141434,,,,,,,,,,,,,,,,,,,,,,,149.9916382,,,,
,31258010.795,149.9866562,4521.35961914063,4.43928531054016E-5,5.02338181849444E-7,1,0.999253354069792,40.0298881530762,2.00878928625795,20.4799994826317,0.000505999451323965,9.53799545394186E-5,0.25,6.13686472844884E-7,4.46093261493529E-5,6.87865885308843E-7,149.9863281,149.9869843,4491.38671875,4551.33251953125,56.333530638006,20.5099044063417,24.807261,0,0,0,40,4449,149.9118,4521.35961914063,,,,,,,,,,,,,0,,,,0.0049,,,,,,149.9866562,,,,
,31258104.25,149.9902802,9190.02880859375,4.01310003993295E-5,7.20081441770423E-7,1,0.999253354069792,40.0298881530762,1.99589718773518,20.4799994826317,0.00045525166068568,8.20754226516902E-5,0.25,2.36149293134685E-7,4.03272302019705E-5,3.01505029073715E-7,149.9902802,149.9902802,9187.498046875,9192.5595703125,56.2444249868136,20.5124777567221,24.427608,0,0,0,40,4449,149.9199,9190.02880859375,,,,,,,,,,,,,0,,,,0.00245,,,,,,149.9902802,,,,
,31258198.805,149.99491885,13914.9702148438,3.005237073859E-5,1.05653542748275E-6,1,0.999253354069792,40.0298881530762,1.99566137930587,20.4799994826317,0.000339166949234246,7.12894526933669E-5,0.25,1.0430100331078E-6,3.01979588586268E-5,1.09608001453548E-6,149.9945221,149.9953156,13890.310546875,13939.6298828125,56.1889293619483,20.516006487304,25.186911,0,0,0,40,4449,149.92365,13914.9702148438,,,,,,,,,,,,,0,,,,-0.0049,,,,,,149.99491885,,,,
,31258293.95,149.9967041,18670.10546875,1.62413205584907E-5,1.29484429553067E-6,1,0.999253354069792,40.0298881530762,1.99578475542975,20.4799994826317,0.000183225827439692,3.90030978108367E-5,0.25,6.05448526923189E-7,1.6319951221404E-5,6.34266909944221E-7,149.9967041,149.9967041,18637.453125,18702.7578125,56.5015807696406,20.5159216423376,24.807261,0,0,0,40,4449,149.9283,18670.10546875,,,,,,,,,,,,,0,,,,0,,,,,,149.9967041,,,,
,31258385.975,149.9991455,23270.40625,2.64819316630792E-6,1.57548219648769E-6,1,0.999253354069792,40.0298881530762,1.99563394922159,20.4799994826317,2.94363783182914E-5,8.86757573923467E-6,0.25,3.19655221351599E-7,2.66066597851493E-6,3.25426250022008E-7,149.9991455,149.9991455,23240.431640625,23300.380859375,56.4390504881021,20.518354944885,24.807261,0,0,0,40,4449,149.9265,23270.40625,,,,,,,,,,,,,0,,,,-0.00245,,,,,,149.9991455,,,,
,31258480.715,150.0007019,28005.5380859375,-1.42712740591099E-5,1.9638424881077E-6,1,0.999253354069792,40.0298881530762,1.99537676331936,20.4799994826317,-0.000164096286925176,-1.63173758741655E-5,0.25,1.04877889602174E-6,-1.43428990815855E-5,1.0313261516506E-6,150.0007019,150.0007019,27973.125,28037.951171875,56.5133051974291,20.5216012219392,25.186911,0,0,0,40,4449,149.9237,28005.5380859375,,,,,,,,,,,,,0,,,,-0.00245,,,,,,150.0007019,,,,
,31258574.895,150.00346375,32710.8408203125,-2.84728953717941E-5,1.5917147208E-6,1,0.999253354069792,40.0298881530762,1.99512856322785,20.4799994826317,-0.000329216355964878,-2.1854270197388E-5,0.25,3.03463714312695E-6,-2.86172995260396E-5,3.00456630681524E-6,150.0033264,150.0036011,32680.87890625,32740.802734375,56.9064643426022,20.5230081411431,24.427608,0,0,0,40,4449,149.92155,32710.8408203125,,,,,,,,,,,,,0,,,,-0.00245,,,,,,150.00346375,,,,
,31258671.84,150.0048065,37555.650390625,-4.55890127387623E-5,1.98317671521397E-6,1,0.999253354069792,40.0298881530762,1.99527842733412,20.4799994826317,-0.000527595589081108,-3.24855493281136E-5,0.25,5.07963420944681E-6,-4.58205929453865E-5,5.03278717835573E-6,150.0048065,150.0048065,37553.30859375,37557.9921875,56.5297193963329,20.5232850695061,24.807261,0,0,0,40,4449,149.9158,37555.650390625,,,,,,,,,,,,,0,,,,0.0049,,,,,,150.0048065,,,,
,31258764.48,150.00676725,42186.0234375,-6.24572911428088E-5,2.36025841769886E-6,1,0.999253354069792,40.0298881530762,1.99531819180069,20.4799994826317,-0.00071814897970819,-7.13455765198935E-5,0.25,4.59472916490823E-6,-6.2770873933081E-5,4.51924572806743E-6,150.0066833,150.0068512,42155.9921875,42216.0546875,57.047939104583,20.5265986518934,24.807261,0,0,0,40,4449,149.9149,42186.0234375,,,,,,,,,,,,,0,,,,0.00245,,,,,,150.00676725,,,,
,31258858.365,150.0083313,46881.33984375,-7.69143102710529E-5,2.13339828256402E-6,1,0.999253354069792,40.0298881530762,1.99518258933306,20.4799994826317,-0.000879563233176967,-0.0001151776904001,0.25,3.25100496595302E-6,-7.72967588840398E-5,3.14660165912756E-6,150.0083313,150.0083313,46848.91796875,46913.76171875,56.994006736756,20.5250336300863,24.427608,0,0,0,40,4449,149.906,46881.33984375,,,,,,,,,,,,,0,,,,0.00245,,,,,,150.0083313,,,,
,31258954.18,150.0095825,51668.9296875,-9.3066035098769E-5,2.52737950501061E-6,1,0.999253354069792,40.0298881530762,1.99526185896209,20.4799994826317,-0.00106696719092937,-0.00012411127929765,0.25,5.27734493388693E-6,-9.35309659982512E-5,5.15805807078805E-6,150.0095825,150.0095825,51661.48828125,51676.37109375,56.6727574153522,20.5258317665837,24.427608,0,0,0,40,4449,149.89365,51668.9296875,,,,,,,,,,,,,0,,,,0.0049,,,,,,150.0095825,,,,
,31259048.36,150.0105438,56376.44140625,-0.000110563268076384,2.23177225137584E-6,1,0.999253354069792,40.0298881530762,1.99508702020098,20.4799994826317,-0.00125817886231506,-0.00020072808011764,0.25,1.57405260942941E-6,-0.000111108389040992,1.40983257963305E-6,150.0105438,150.0105438,56373.8984375,56378.984375,56.7305979257752,20.524781712724,24.427608,0,0,0,40,4449,149.88735,56376.44140625,,,,,,,,,,,,,0,,,,0,,,,,,150.0105438,,,,
,31259144.285,150.0097961,61169.31640625,-0.000130342782494587,3.05839672340845E-6,1,0.999253354069792,40.0298881530762,1.99494990220945,20.4799994826317,-0.00148319705809479,-0.000236457588455335,0.25,1.86954743501901E-6,-0.000130985575971065,1.67665708776783E-6,150.0097961,150.0097961,61166.9140625,61171.71875,56.5398805670829,20.5291734419629,24.427608,0,0,0,40,4449,149.8756,61169.31640625,,,,,,,,,,,,,0,,,,0.0049,,,,,,150.0097961,,,,
,31259241.25,150.0077667,66017.37890625,-0.000149273314486804,3.64662050079622E-6,1,0.999253354069792,40.0298881530762,1.99491208380901,20.4799994826317,-0.00170378334797154,-0.000240932856792368,0.25,4.7712096788E-6,-0.000150013688946777,4.56398366747838E-6,150.0077667,150.0077667,66014.703125,66020.0546875,56.8220484625252,20.5296313631575,24.427608,0,0,0,40,4449,149.8706,66017.37890625,,,,,,,,,,,,,0,,,,-0.0049,,,,,,150.0077667,,,,
,31259335.555,150.0088043,70732.49609375,-0.000171027849714644,3.01868281679246E-6,1,0.999253354069792,40.0298881530762,1.99534844032409,20.4799994826317,-0.00196187851485739,-0.000222226753528926,0.25,1.02112668661276E-5,-0.000171883579143541,9.99799536252021E-6,150.0088043,150.0088043,70697.609375,70767.3828125,56.8353361473522,20.5219184393193,24.427608,0,0,0,40,4449,149.8617,70732.49609375,,,,,,,,,,,,,0,,,,0,,,,,,150.0088043,,,,
,31259430.28,150.0088806,75465.26953125,-0.000183320574515726,2.53005735394285E-6,1,0.999253354069792,40.0298881530762,1.99528168007605,20.4799994826317,-0.00208803804208309,-0.00032309571782982,0.25,3.46558186157938E-6,-0.000184226464934955,3.20116079579652E-6,150.0088806,150.0088806,75435.4921875,75495.046875,56.4968909985252,20.5235443446622,24.807261,0,0,0,40,4449,149.851,75465.26953125,,,,,,,,,,,,,0,,,,0,,,,,,150.0088806,,,,
,31259524.9,150.0101013,80193.77734375,-0.000200988177960703,3.15898090860211E-6,1,0.999253354069792,40.0298881530762,1.99525412302954,20.4799994826317,-0.00229067118969173,-0.000346043608327872,0.25,4.51965925377333E-6,-0.00020198266408124,4.23431280062359E-6,150.0101013,150.0101013,80163.53125,80224.0234375,56.4359239740252,20.5232466080008,25.186911,0,0,0,40,4449,149.8441,80193.77734375,,,,,,,,,,,,,0,,,,0,,,,,,150.0101013,,,,
,31259622.43,150.0089264,85069.8515625,-0.000219325339130092,2.46025070577576E-6,1,0.999253354069792,40.0298881530762,1.99506167223074,20.4799994826317,-0.0025042266511938,-0.000350052815157944,0.25,7.35588799275966E-6,-0.000220414475024984,7.05756688561594E-6,150.0089264,150.0089264,85067.390625,85072.3125,56.9541436822753,20.5242335640332,24.807261,0,0,0,40,4449,149.834,85069.8515625,,,,,,,,,,,,,0,,,,-0.00245,,,,,,150.0089264,,,,
,31259713.55,150.0104523,89625.3671875,-0.000236270912163407,3.29548422955933E-6,1,0.999253354069792,40.0298881530762,1.99524312183005,20.4799994826317,-0.00269930926462715,-0.000369298709377065,0.25,8.61304248134636E-6,-0.000237445438159785,8.29622622259701E-6,150.0104523,150.0104523,89600.25,89650.484375,57.139389641333,20.525780999744,24.807261,0,0,0,40,4449,149.82645,89625.3671875,,,,,,,,,,,,,0,,,,0,,,,,,150.0104523,,,,
,31259820.775,150.0046692,85784.08203125,-0.00022336976403376,3.41662301383558E-6,1,0.999253354069792,40.0298881530762,1.99513979644878,20.4799994826317,-0.00254588513449899,-0.000383029477271671,0.25,5.15628271107749E-6,-0.000224475475253085,4.84112310136279E-6,150.0046692,150.0046692,85779.140625,85789.0234375,56.8626931455252,20.5277948544848,24.427608,0,0,0,40,4449,149.8222,85784.08203125,,,,,,,,,,,,,0,,,,0,,,,,,150.0046692,,,,
,31259915.5,149.9988098,81045.40625,-0.000206009197735043,2.72848797977547E-6,1,0.999253354069792,40.0298881530762,1.99494005044549,20.4799994826317,-0.00234794101786793,-0.000352356718686129,0.25,4.83316357175091E-6,-0.000207028926012782,4.54181441862967E-6,149.9987488,149.9988708,81040.265625,81050.546875,56.5836517641598,20.5234574326951,24.807261,0,0,0,40,4449,149.82555,81045.40625,,,,,,,,,,,,,0,,,,-0.00245,,,,,,149.9988098,,,,
,31260016.035,149.9941025,76019.3984375,-0.000184104495458028,3.06295676977504E-6,1,0.999253354069792,40.0298881530762,1.99489110783484,20.4799994826317,-0.00210095544544279,-0.000299270260150682,0.25,5.69578281795997E-6,-0.000185017748752356,5.44117949914481E-6,149.993927,149.994278,75986.7890625,76052.0078125,56.9713395096983,20.5258938748222,24.807261,0,0,0,40,4449,149.83255,76019.3984375,,,,,,,,,,,,,0,,,,0.00245,,,,,,149.9941025,,,,
,31260115.175,149.9924622,71063.14453125,-0.000168464356538621,2.62201585095092E-6,1,0.999253354069792,40.0298881530762,1.99508082187319,20.4799994826317,-0.00192334303876368,-0.000269873319847335,0.25,5.56497726085259E-6,-0.000169300417431148,5.3328417272217E-6,149.9924622,149.9924622,71058.015625,71068.2734375,56.8204852054868,20.5260930811099,24.427608,0,0,0,40,4449,149.83895,71063.14453125,,,,,,,,,,,,,0,,,,-0.0049,,,,,,149.9924622,,,,
,31260210.095,149.9890442,66320.0390625,-0.000150209377501215,2.9911254605121E-6,1,0.999253354069792,40.0298881530762,1.99508297389356,20.4799994826317,-0.00171128289426664,-0.000261558859892894,0.25,3.11896550551534E-6,-0.000150951875229132,2.90218460933106E-6,149.9887848,149.9893036,66290.1875,66349.890625,56.8087607776983,20.5282889041785,24.807261,0,0,0,40,4449,149.8496,66320.0390625,,,,,,,,,,,,,0,,,,0,,,,,,149.9890442,,,,
,31260306.985,149.9909973,61476.73828125,-0.000129363275335563,2.96681888404071E-6,1,0.999253354069792,40.0298881530762,1.99531784805619,20.4799994826317,-0.00147634576721658,-0.000211555749108881,0.25,3.89606998997047E-6,-0.000130004470610161,3.71465105317058E-6,149.9909973,149.9909973,61471.5390625,61481.9375,56.9658681100637,20.5270994525446,24.427608,0,0,0,40,4449,149.8542,61476.73828125,,,,,,,,,,,,,0,,,,-0.0049,,,,,,149.9909973,,,,
,31260402.02,149.9929733,56726.23046875,-0.000111449139874736,2.26133745956814E-6,1,0.999253354069792,40.0298881530762,1.99512011792473,20.4799994826317,-0.00127449706309759,-0.000166647556620592,0.25,4.73086263690776E-6,-0.000112003572832722,4.58075794358586E-6,149.9926605,149.9932861,56693.77734375,56758.68359375,56.9603967104291,20.5289605670988,25.186911,0,0,0,40,4449,149.85995,56726.23046875,,,,,,,,,,,,,0,,,,-0.0049,,,,,,149.9929733,,,,
,31260495.835,149.9942627,52036.146484375,-9.71163967585425E-5,2.09744758229375E-6,1,0.999253354069792,40.0298881530762,1.99509819660744,20.4799994826317,-0.00111017832241155,-0.000147519206097522,0.25,3.91989327892263E-6,-9.75991273920968E-5,3.78762440424548E-6,149.9942627,149.9942627,52011.40234375,52060.890625,56.9064643426022,20.5266446895922,24.807261,0,0,0,40,4449,149.86515,52036.146484375,,,,,,,,,,,,,0,,,,0.00245,,,,,,149.9942627,,,,
,31260592,149.9916382,47231.103515625,-7.84892575574147E-5,2.27623542949575E-6,1,0.999253354069792,40.0298881530762,1.99506859381081,20.4799994826317,-0.000892100610961978,-0.000148673198965688,0.25,5.74015285526611E-7,-7.88752798263195E-5,4.54006848711289E-7,149.9916382,149.9916382,47223.7734375,47238.43359375,56.7954730928714,20.5284161250081,25.186911,0,0,0,40,4449,149.87585,47231.103515625,,,,,,,,,,,,,0,,,,-0.0049,,,,,,149.9916382,,,,
,31260687.49,149.9939575,42457.89453125,-6.23915660633973E-5,1.49933437797223E-6,1,0.999253354069792,40.0298881530762,1.99494266166994,20.4799994826317,-0.000713365074832991,-9.36449225216129E-5,0.25,2.61759723017406E-6,-6.27017429283648E-5,2.53250169831603E-6,149.9939575,149.9939575,42425.59375,42490.1953125,57.0831123879483,20.5313516578998,25.566563,0,0,0,40,4449,149.8776,42457.89453125,,,,,,,,,,,,,0,,,,-0.0049,,,,,,149.9939575,,,,
,31260782.505,149.9921417,37710.751953125,-4.64894622454766E-5,1.69194398297888E-6,1,0.999253354069792,40.0298881530762,1.9951502349901,20.4799994826317,-0.000528431492568838,-8.79620287105154E-5,0.25,3.49317171292379E-7,-4.67180266986878E-5,2.77840848618308E-7,149.9921417,149.9921417,37678.28125,37743.22265625,56.8626931455252,20.5345788852912,25.186911,0,0,0,40,4449,149.8871,37710.751953125,,,,,,,,,,,,,0,,,,0.00245,,,,,,149.9921417,,,,
,31260878.32,149.9892197,32920.935546875,-2.89772337612804E-5,1.52740205532783E-6,1,0.999253354069792,40.0298881530762,1.9951286770949,20.4799994826317,-0.000333889274708151,-2.88925879503783E-5,0.25,2.50247641622358E-6,-2.91232812522194E-5,2.46899236542186E-6,149.9890137,149.9894257,32891.01171875,32950.859375,56.9205336559483,20.5298610170013,25.186911,0,0,0,40,4449,149.88875,32920.935546875,,,,,,,,,,,,,0,,,,0,,,,,,149.9892197,,,,
,31260974.82,149.9936829,28095.705078125,-1.24382890330097E-5,1.25098714531927E-6,1,0.999253354069792,40.0298881530762,1.99522180953237,20.4799994826317,-0.000149656377106327,2.3936751368404E-5,0.25,4.27530783600104E-6,-1.25060390681059E-5,4.27657194556375E-6,149.9936829,149.9936829,28068.177734375,28123.232421875,57.2198973788137,20.5316632232312,24.807261,0,0,0,40,4449,149.8986,28095.705078125,,,,,,,,,,,,,0,,,,-0.00245,,,,,,149.9936829,,,,
,31261070.46,149.9930725,23318.2744140625,3.18484692207365E-6,1.20094350158762E-6,1,0.999253354069792,40.0298881530762,1.99523469747745,20.4799994826317,3.43891259555397E-5,1.64359246400724E-5,0.25,8.92999747715458E-7,3.19904003941858E-6,9.02434045627988E-7,149.9930725,149.9930725,23290.771484375,23345.77734375,57.1941036376791,20.5334126677745,24.427608,0,0,0,40,4449,149.90505,23318.2744140625,,,,,,,,,,,,,0,,,,0,,,,,,149.9930725,,,,
,31261165.3,149.9924011,18578.4453125,1.63673051894026E-5,1.2535182192711E-6,1,0.999253354069792,40.0298881530762,1.99529392520824,20.4799994826317,0.00018248963995573,5.14320831088339E-5,0.25,1.67912123562994E-6,1.64448443232684E-5,1.71340810776757E-6,149.9924011,149.9924011,18553.3671875,18603.5234375,57.088583787583,20.5319513700628,24.807261,0,0,0,40,4449,149.9093,18578.4453125,,,,,,,,,,,,,0,,,,0.00245,,,,,,149.9924011,,,,
,31261259.955,149.99108125,13845.9428710938,3.08431809510077E-5,9.40080666557874E-7,1,0.999253354069792,40.0298881530762,1.99519545202633,20.4799994826317,0.000347466599983618,7.62933985936436E-5,0.25,1.34743496730501E-6,3.09921603485973E-5,1.40326288990919E-6,149.9906464,149.9915161,13820.8447265625,13871.041015625,57.1769078102561,20.5317602637343,24.427608,0,0,0,40,4449,149.91865,13845.9428710938,,,,,,,,,,,,,0,,,,-0.00245,,,,,,149.99108125,,,,
,31261353.61,149.99111935,9165.91552734375,4.29250889110997E-5,7.9468510536993E-7,1,0.999253354069792,40.0298881530762,1.99518894039656,20.4799994826317,0.00048565088957767,9.4259866854714E-5,0.25,8.25161257384628E-7,4.31340648278618E-5,8.97869325064778E-7,149.9910583,149.9911804,9133.5234375,9198.3076171875,57.3183825722368,20.5334277748735,24.807261,0,0,0,40,4449,149.92575,9165.91552734375,,,,,,,,,,,,,0,,,,0,,,,,,149.99111935,,,,
,31261450.18,149.9955139,4337.58618164063,5.12251858202432E-5,5.14936420567149E-7,1,0.999253354069792,40.0298881530762,1.99541095849073,20.4799994826317,0.000580750380644519,0.000106001218423832,0.25,4.12292191449777E-7,5.14754386475141E-5,4.96431527952749E-7,149.9951172,149.9959106,4314.9619140625,4360.21044921875,57.5888260398907,20.5360732201872,24.807261,0,0,0,40,4449,149.929,4337.58618164063,,,,,,,,,,,,,0,,,,0.00245,,,,,,149.9955139,,,,
,31261542.555,149.9976501,-278.240173339844,4.87811442874754E-5,3.95500101173709E-7,1,0.999253354069792,40.0298881530762,1.99533918637033,20.4799994826317,0.00055403273133273,9.51415579175891E-5,0.25,-1.18259448125599E-7,4.90202490366165E-5,-4.05265189493536E-8,149.9976501,149.9976501,-298.31591796875,-258.164428710938,56.7743691228522,20.5329523153653,24.807261,0,0,0,40,4449,149.9333,-278.240173339844,,,,,,,,,,,,,0,,,,0,,,,,,149.9976501,,,,
,31261635.25,149.9965057,-4907.77758789063,2.41137695889878E-5,4.51577631037014E-7,1,0.999253354069792,40.0298881530762,1.99523651310208,20.4799994826317,0.000274430377020674,4.37506762901115E-5,0.25,-3.47144468451492E-7,2.42324429673561E-5,-3.1019871137257E-7,149.9965057,149.9965057,-4937.4423828125,-4878.11279296875,57.2996234877753,20.5353963604261,25.566563,0,0,0,40,4449,149.93335,-4907.77758789063,,,,,,,,,,,,,0,,,,-0.00245,,,,,,149.9965057,,,,
,31261729.965,150.0007782,-9643.173828125,-9.22368620672125E-6,9.32281530423023E-7,1,0.999253354069792,40.0298881530762,1.99530077373823,20.4799994826317,-0.000102943702182483,-2.83941757089012E-5,0.25,-8.94216123115747E-7,-9.26744280499241E-6,-9.13347064521112E-7,150.0005188,150.0010376,-9675.6669921875,-9610.6806640625,56.4492116588521,20.5368874359283,25.566563,0,0,0,40,4449,149.9336,-9643.173828125,,,,,,,,,,,,,0,,,,0,,,,,,150.0007782,,,,
,31261825,150.00575255,-14394.05859375,-2.04285754027931E-5,9.18354511520109E-7,1,0.999253354069792,40.0298881530762,1.99535353888203,20.4799994826317,-0.000229183828961882,-5.61234755979596E-5,0.25,-1.38465617202913E-6,-2.05264594127889E-5,-1.42403242764956E-6,150.0056915,150.0058136,-14424.1943359375,-14363.9228515625,57.2660134614484,20.5383851244322,25.566563,0,0,0,40,4449,149.92685,-14394.05859375,,,,,,,,,,,,,0,,,,0,,,,,,150.00575255,,,,
,31261921.845,150.0083008,-19233.5625,-1.34414413420424E-5,1.39554405259487E-6,1,0.999253354069792,40.0298881530762,1.99543234569076,20.4799994826317,-0.00014780070351039,-5.41603258855877E-5,0.25,-2.42884753194728E-6,-1.35034459602764E-5,-2.46213952092297E-6,150.0083008,150.0083008,-19240.703125,-19226.421875,57.0151107067753,20.535097520119,25.186911,0,0,0,40,4449,149.9212,-19233.5625,,,,,,,,,,,,,0,,,,0,,,,,,150.0083008,,,,
,31262016.405,150.00888825,-23961.033203125,4.67909455062199E-7,1.18420605979406E-6,1,0.999253354069792,40.0298881530762,1.99532633855324,20.4799994826317,7.51782270224065E-6,-1.17366526971836E-5,0.25,-1.11532917904825E-6,4.71973118561016E-7,-1.12005314828431E-6,150.0088501,150.0089264,-23993.458984375,-23928.607421875,56.8376810329099,20.5383981049032,25.186911,0,0,0,40,4449,149.90885,-23961.033203125,,,,,,,,,,,,,0,,,,-0.00245,,,,,,150.00888825,,,,
,31262111.71,150.0096588,-28723.673828125,1.52822337134941E-5,1.65525225665191E-6,1,0.999253354069792,40.0298881530762,1.99518638530954,20.4799994826317,0.000177731762317894,5.83481478863183E-6,0.25,-2.14816395887458E-6,1.53605519763849E-5,-2.13450428447453E-6,150.0093994,150.0099182,-28756.1328125,-28691.21484375,56.946327397083,20.5381015725518,24.807261,0,0,0,40,4449,149.89745,-28723.673828125,,,,,,,,,,,,,0,,,,0.00245,,,,,,150.0096588,,,,
,31262208.175,150.0107269,-33545.837890625,3.1375363417614E-5,1.57263565984178E-6,1,0.999253354069792,40.0298881530762,1.99505765259445,20.4799994826317,0.00036119310324834,3.30970930411412E-5,0.25,-2.54971565034703E-6,3.15332286299398E-5,-2.51269285863157E-6,150.0107269,150.0107269,-33548.3984375,-33543.27734375,57.180034324333,20.5369476100289,25.186911,0,0,0,40,4449,149.88535,-33545.837890625,,,,,,,,,,,,,0,,,,-0.00245,,,,,,150.0107269,,,,
,31262303.265,150.0104675,-38295.40234375,5.00174808129368E-5,1.72353269876315E-6,1,0.999253354069792,40.0298881530762,1.99509938081709,20.4799994826317,0.000574412408987381,6.08036688964936E-5,0.25,-3.35612922543776E-6,5.0268060233464E-5,-3.29386714306921E-6,150.0104675,150.0104675,-38330.51953125,-38260.28515625,57.2456911199484,20.5354915070461,25.186911,0,0,0,40,4449,149.8783,-38295.40234375,,,,,,,,,,,,,0,,,,0.00245,,,,,,150.0104675,,,,
,31262399.26,150.0103073,-43092.564453125,6.45917818383442E-5,1.92116118815473E-6,1,0.999253354069792,40.0298881530762,1.99517236240693,20.4799994826317,0.000741062800912328,8.28334188926319E-5,0.25,-3.95410538381502E-6,6.49148251632489E-5,-3.87214269504093E-6,150.0101318,150.0104828,-43122.87109375,-43062.2578125,57.2324034351214,20.5369290750065,25.186911,0,0,0,40,4449,149.8672,-43092.564453125,,,,,,,,,,,,,0,,,,0,,,,,,150.0103073,,,,
,31262496.225,150.0097656,-47940.052734375,8.28467042722753E-5,2.12194486984016E-6,1,0.999253354069792,40.0298881530762,1.99509775192889,20.4799994826317,0.000951006115406299,0.000103154532146128,0.25,-5.34303121918197E-6,8.32615337068934E-5,-5.23964079028999E-6,150.0097656,150.0097656,-47964.85546875,-47915.25,56.7337244398522,20.5363425531712,25.186911,0,0,0,40,4449,149.8582,-47940.052734375,,,,,,,,,,,,,0,,,,0,,,,,,150.0097656,,,,
,31262592.93,150.01020815,-52772.37109375,9.7579242453697E-5,2.32775737097725E-6,1,0.999253354069792,40.0298881530762,1.9952143844657,20.4799994826317,0.00111873207647558,0.000129851494873361,0.25,-5.55749529135559E-6,9.80667636192907E-5,-5.43259063740066E-6,150.0100708,150.0103455,-52802.3828125,-52742.359375,56.9580518248714,20.5397597774559,25.186911,0,0,0,40,4449,149.8487,-52772.37109375,,,,,,,,,,,,,0,,,,0.00245,,,,,,150.01020815,,,,
,31262690.875,150.0111847,-57667.171875,0.000116172890922985,2.12609068578349E-6,1,0.999253354069792,40.0298881530762,1.99517386674474,20.4799994826317,0.00132438146524386,0.000197649056580329,0.25,-2.82298074054282E-6,0.000116747499272494,-2.65623927857654E-6,150.0111847,150.0111847,-57669.79296875,-57664.55078125,56.9494539111599,20.5397570426926,24.807261,0,0,0,40,4449,149.8368,-57667.171875,,,,,,,,,,,,,0,,,,0.0049,,,,,,150.0111847,,,,
,31262788.325,150.01242065,-62537.669921875,0.000133389587999323,1.76161367147059E-6,1,0.999253354069792,40.0298881530762,1.99515391817513,20.4799994826317,0.00152611525177802,0.000195502681426701,0.25,-6.00986978865511E-6,0.000134053765184031,-5.8326844605151E-6,150.0115967,150.0132446,-62542.640625,-62532.69921875,57.1065612435253,20.5387451692408,25.566563,0,0,0,40,4449,149.8278,-62537.669921875,,,,,,,,,,,,,0,,,,0,,,,,,150.01242065,,,,
,31262884.8,150.0111542,-67359.70703125,0.000154385024610032,2.35266240339335E-6,1,0.999253354069792,40.0298881530762,1.99523986260642,20.4799994826317,0.0017598204452591,0.000264057164671397,0.25,-3.6277469823498E-6,0.000155148738411302,-3.4071135681042E-6,150.0111542,150.0111542,-67389.546875,-67329.8671875,57.1886322380445,20.5419075240892,25.186911,0,0,0,40,4449,149.8182,-67359.70703125,,,,,,,,,,,,,0,,,,0,,,,,,150.0111542,,,,
,31262981.625,150.0085907,-72199.33203125,0.000170904035196377,2.49786081182275E-6,1,0.999253354069792,40.0298881530762,1.99528641965794,20.4799994826317,0.00195416139426501,0.000257883296025503,0.25,-7.04819599605496E-6,0.000171754309155633,-6.81971875397685E-6,150.0085907,150.0085907,-72201.6875,-72196.9765625,57.0870205305445,20.5405877094163,25.186911,0,0,0,40,4449,149.80715,-72199.33203125,,,,,,,,,,,,,0,,,,0,,,,,,150.0085907,,,,
,31263077.07,150.0101166,-76966.09375,0.000191505223616743,1.78761509087094E-6,1,0.999253354069792,40.0298881530762,1.99526045243206,20.4799994826317,0.00218638838948307,0.000307954787582949,0.25,-6.22419366196519E-6,0.000192455578609443,-5.96091973809926E-6,150.0100403,150.0101929,-76998.5703125,-76933.6171875,57.352774227083,20.5407830284057,25.566563,0,0,0,40,4449,149.79485,-76966.09375,,,,,,,,,,,,,0,,,,-0.00245,,,,,,150.0101166,,,,
,31263173.93,150.0122986,-81808.4609375,0.000206924319926619,1.84428644325494E-6,1,0.999253354069792,40.0298881530762,1.99523604986231,20.4799994826317,0.00236124897610796,0.00033935862402225,0.25,-6.14181033581623E-6,0.000207950478668366,-5.85554821384836E-6,150.0122986,150.0122986,-81840.96875,-81775.953125,57.4121779945445,20.5432152544581,25.186911,0,0,0,40,4449,149.7861,-81808.4609375,,,,,,,,,,,,,0,,,,0,,,,,,150.0122986,,,,
,31263267.85,150.0112152,-86502.98046875,0.000224428679309976,2.7523762347916E-6,1,0.999253354069792,40.0298881530762,1.99546196086835,20.4799994826317,0.00257022143318952,0.000316721642477958,0.25,-1.11860123735955E-5,0.00022554875151267,-1.08989113587152E-5,150.0110321,150.0113983,-86527.7734375,-86478.1875,57.1323549846599,20.5406748009567,24.807261,0,0,0,40,4449,149.77795,-86502.98046875,,,,,,,,,,,,,0,,,,-0.00245,,,,,,150.0112152,,,,
,31263373.975,150.0074234,-88997.69140625,0.000236463876179532,2.23201856495783E-6,1,0.999253354069792,40.0298881530762,1.99526556790078,20.4799994826317,0.00269826468184803,0.000388426877846708,0.25,-6.96242302597824E-6,0.00023763680103564,-6.63686008921092E-6,150.0072937,150.0075531,-89022.8984375,-88972.484375,57.0432493334676,20.5421408874588,25.186911,0,0,0,40,4449,149.77355,-88997.69140625,,,,,,,,,,,,,0,,,,0,,,,,,150.0074234,,,,
,31263466.975,150.0023193,-84348.22265625,0.000216001636199945,2.35780304116511E-6,1,0.999253354069792,40.0298881530762,1.99527600185383,20.4799994826317,0.0024615334132785,0.000373474412866938,0.25,-4.71753047846212E-6,0.000217070386746609,-4.41095429252474E-6,150.0023193,150.0023193,-84380.4609375,-84315.984375,56.526592882256,20.5416137008973,25.186911,0,0,0,40,4449,149.77295,-84348.22265625,,,,,,,,,,,,,0,,,,-0.00245,,,,,,150.0023193,,,,
,31263561.525,149.9986191,-79623.1953125,0.000198546334741313,2.8521970412194E-6,1,0.999253354069792,40.0298881530762,1.99496594135836,20.4799994826317,0.00226955250551206,0.000301463985949484,0.25,-8.01792007696695E-6,0.000199534183268731,-7.75316605768351E-6,149.9980774,149.9991608,-79653.0390625,-79593.3515625,57.0588819038522,20.5412175548753,25.566563,0,0,0,40,4449,149.76965,-79623.1953125,,,,,,,,,,,,,0,,,,0,,,,,,149.9986191,,,,
,31263658.705,149.9945374,-74765.94921875,0.000181313039250411,2.47230172346144E-6,1,0.999253354069792,40.0298881530762,1.99526876223802,20.4799994826317,0.0020736193445291,0.000270977667814001,0.25,-7.7069487310539E-6,0.000182215597404434,-7.46612014749094E-6,149.9945374,149.9945374,-74790.9296875,-74740.96875,56.9385111118906,20.5406588891056,24.807261,0,0,0,40,4449,149.77825,-74765.94921875,,,,,,,,,,,,,0,,,,-0.00245,,,,,,149.9945374,,,,
,31263756.21,149.9934235,-69894.17578125,0.000159531867908262,2.4507553737095E-6,1,0.999253354069792,40.0298881530762,1.99546412177021,20.4799994826317,0.00182265994630693,0.000250069378143395,0.25,-5.7582777062294E-6,0.000160324290025357,-5.54052783518723E-6,149.9934235,149.9934235,-69898.875,-69889.4765625,57.4051433378714,20.5408599018113,25.186911,0,0,0,40,4449,149.7875,-69894.17578125,,,,,,,,,,,,,0,,,,-0.0049,,,,,,149.9934235,,,,
,31263852.685,149.99045565,-65071.93359375,0.000146111542508664,2.00806760683435E-6,1,0.999253354069792,40.0298881530762,1.99530347170287,20.4799994826317,0.00167063813311428,0.000220771420106042,0.25,-6.0007345805291E-6,0.000146838310062205,-5.80412818396925E-6,149.9904175,149.9904938,-65101.99609375,-65041.87109375,57.004167907506,20.5403530621243,25.186911,0,0,0,40,4449,149.79685,-65071.93359375,,,,,,,,,,,,,0,,,,0.00245,,,,,,149.99045565,,,,
,31263949.34,149.98963165,-60239.365234375,0.000128734561475084,2.690158702244E-6,1,0.999253354069792,40.0298881530762,1.99509307963872,20.4799994826317,0.00146815640947763,0.000215418302291629,0.25,-3.44455646528142E-6,0.00012937192580631,-3.26163155325152E-6,149.9894104,149.9898529,-60274.38671875,-60204.34375,57.0096393071407,20.5380141843992,25.566563,0,0,0,40,4449,149.80445,-60239.365234375,,,,,,,,,,,,,0,,,,0,,,,,,149.98963165,,,,
,31264046.4,149.9901733,-55389.791015625,0.000108996835761829,2.62681450230231E-6,1,0.999253354069792,40.0298881530762,1.99522730041342,20.4799994826317,0.0012487606061518,0.000150106763542092,0.25,-5.76175473137828E-6,0.000109540806573959,-5.62029759828275E-6,149.9901733,149.9901733,-55422.0859375,-55357.49609375,57.352774227083,20.5409057782704,24.807261,0,0,0,40,4449,149.81525,-55389.791015625,,,,,,,,,,,,,0,,,,0.00245,,,,,,149.9901733,,,,
,31264142.275,149.9913483,-50600.44921875,9.12250611616094E-5,1.57057186659449E-6,1,0.999253354069792,40.0298881530762,1.99513381084717,20.4799994826317,0.00104568506764436,0.000122292680056206,0.25,-5.11642675050542E-6,9.16807220091405E-5,-4.99902269760929E-6,149.9913483,149.9913483,-50625.14453125,-50575.75390625,57.4676736194099,20.5396140730641,25.186911,0,0,0,40,4449,149.82055,-50600.44921875,,,,,,,,,,,,,0,,,,0,,,,,,149.9913483,,,,
,31264236.43,149.9914093,-45895.556640625,7.39235223930623E-5,1.73886373871628E-6,1,0.999253354069792,40.0298881530762,1.99506951818826,20.4799994826317,0.000846984856081673,0.000101112379299672,0.25,-3.96875581678917E-6,7.42924300811588E-5,-3.87239540924087E-6,149.9910736,149.991745,-45927.859375,-45863.25390625,57.5247325013138,20.5364324305882,25.566563,0,0,0,40,4449,149.82965,-45895.556640625,,,,,,,,,,,,,0,,,,0,,,,,,149.9914093,,,,
,31264332.97,149.9939957,-41068.548828125,5.81058582968424E-5,1.69811889725289E-6,1,0.999253354069792,40.0298881530762,1.99513825195641,20.4799994826317,0.000666013666403986,7.8103633653662E-5,0.25,-3.24103704930549E-6,5.83959706582768E-5,-3.16560684415292E-6,149.9937897,149.9942017,-41100.93359375,-41036.1640625,57.271484861083,20.5372613130915,25.186911,0,0,0,40,4449,149.8346,-41068.548828125,,,,,,,,,,,,,0,,,,0,,,,,,149.9939957,,,,
,31264430.18,149.98936465,-36210.705078125,4.08590662867414E-5,1.72186825176201E-6,1,0.999253354069792,40.0298881530762,1.99502228414737,20.4799994826317,0.000469697941516797,4.69122404633796E-5,0.25,-2.98452506445873E-6,4.10641550021192E-5,-2.93474971489195E-6,149.9891968,149.9895325,-36238.15234375,-36183.2578125,57.0151107067753,20.5416623542543,25.186911,0,0,0,40,4449,149.84485,-36210.705078125,,,,,,,,,,,,,0,,,,-0.00245,,,,,,149.98936465,,,,
,31264525.735,149.9885559,-31433.771484375,2.51240045465988E-5,1.34211048953689E-6,1,0.999253354069792,40.0298881530762,1.99503398474253,20.4799994826317,0.000289833278856758,2.30063896181533E-5,0.25,-2.34974854921E-6,2.52509101991619E-5,-2.32155047966707E-6,149.9885254,149.9885864,-31461.3984375,-31406.14453125,56.9017745714868,20.5367434263749,25.186911,0,0,0,40,4449,149.85665,-31433.771484375,,,,,,,,,,,,,0,,,,0,,,,,,149.9885559,,,,
,31264620.695,149.9911728,-26688.40625,9.97999552680324E-6,1.40586392445753E-6,1,0.999253354069792,40.0298881530762,1.99511781923642,20.4799994826317,0.000117492922136041,-4.39712999898552E-6,0.25,-2.12589095857559E-6,1.00322905061124E-5,-2.12049036315845E-6,149.9908142,149.9915314,-26718.484375,-26658.328125,56.4781319140637,20.5378320964397,25.186911,0,0,0,40,4449,149.8613,-26688.40625,,,,,,,,,,,,,0,,,,0.00245,,,,,,149.9911728,,,,
,31264715.62,149.9915695,-21943.7109375,-5.75128664384664E-6,1.24495733037355E-6,1,0.999253354069792,40.0298881530762,1.99510811808657,20.4799994826317,-6.01585922253524E-5,-4.0805966760783E-5,0.25,-2.59284171670252E-6,-5.77535377996343E-6,-2.61469271189415E-6,149.9911041,149.9920349,-21976.158203125,-21911.263671875,57.1104693861214,20.5331455765891,25.186911,0,0,0,40,4449,149.8692,-21943.7109375,,,,,,,,,,,,,0,,,,-0.0049,,,,,,149.9915695,,,,
,31264810.695,149.9902344,-17191.2822265625,-2.08061649699286E-5,1.45756314487786E-6,1,0.999253354069792,40.0298881530762,1.99497193738132,20.4799994826317,-0.000232452612756957,-6.2459628649867E-5,0.25,-1.87802131564113E-6,-2.09051318060108E-5,-1.92038400806277E-6,149.9898224,149.9906464,-17218.84375,-17163.720703125,57.220679007333,20.5374420720135,25.566563,0,0,0,40,4449,149.8801,-17191.2822265625,,,,,,,,,,,,,0,,,,0,,,,,,149.9902344,,,,
,31264906.89,149.9912338,-12383.802734375,-3.42897957224443E-5,8.17620516505324E-7,1,0.999253354069792,40.0298881530762,1.99512029212087,20.4799994826317,-0.000387119842024939,-7.99990144049947E-5,0.25,-1.07361867864526E-6,-3.44560857168596E-5,-1.13366291098507E-6,149.9911346,149.991333,-12416.1103515625,-12351.4951171875,57.0831123879483,20.5336105100277,25.186911,0,0,0,40,4449,149.8883,-12383.802734375,,,,,,,,,,,,,0,,,,-0.0049,,,,,,149.9912338,,,,
,31265002.285,149.9915161,-7618.60864257812,-4.59868029595296E-5,6.26048370832886E-7,1,0.999253354069792,40.0298881530762,1.99514198405613,20.4799994826317,-0.000520210048310727,-0.000101376423782133,0.25,-9.18791041373693E-7,-4.62106099742641E-5,-9.96931490280332E-7,149.9915161,149.9915161,-7623.60302734375,-7613.6142578125,56.9893169656406,20.5349710621098,24.807261,0,0,0,40,4449,149.8947,-7618.60864257812,,,,,,,,,,,,,0,,,,0.00245,,,,,,149.9915161,,,,
,31265095.545,149.9928894,-2955.04296875,-5.17361927829128E-5,4.19610453453618E-7,1,0.999253354069792,40.0298881530762,1.99518589079185,20.4799994826317,-0.000585991248760574,-0.000109855252155272,0.25,-6.63709260142958E-7,-5.19885333330087E-5,-7.49967917374084E-7,149.9928894,149.9928894,-2980.04541015625,-2930.04052734375,56.9924434797176,20.5362095994212,25.186911,0,0,0,40,4449,149.9011,-2955.04296875,,,,,,,,,,,,,0,,,,-0.00245,,,,,,149.9928894,,,,
,31265190.13,149.9962463,1770.39953613281,-4.26376305060753E-5,3.74481719648424E-7,1,0.999253354069792,40.0298881530762,1.99529174217748,20.4799994826317,-0.000483321600403754,-8.84674931897992E-5,0.25,-3.6438185547626E-7,-4.28458754341313E-5,-4.34605821778682E-7,149.9962463,149.9962463,1765.5419921875,1775.25708007813,56.8470605751406,20.5328868609926,24.807261,0,0,0,40,4449,149.9015,1770.39953613281,,,,,,,,,,,,,0,,,,-0.0098,,,,,,149.9962463,,,,
,31265284.11,149.99790195,6465.06567382813,-1.22277173245045E-5,5.60453971027894E-7,1,0.999253354069792,40.0298881530762,1.99534274464926,20.4799994826317,-0.000139092488888462,-2.26109943528868E-5,0.25,1.38625280340086E-7,-1.22878359244581E-5,1.19715112266877E-7,149.9978638,149.9979401,6438.21044921875,6491.9208984375,56.7954730928714,20.5339375292234,25.186911,0,0,0,40,4449,149.9032,6465.06567382813,,,,,,,,,,,,,0,,,,-0.00245,,,,,,149.99790195,,,,
,31265376.99,150.0037994,11108.3125,1.64667905778379E-5,7.60386571939986E-7,1,0.999253354069792,40.0298881530762,1.99500773517797,20.4799994826317,0.000184493327444676,4.64564554186718E-5,0.25,1.2239687553624E-6,1.65455050472348E-5,1.25628854891988E-6,150.0037994,150.0037994,11080.671875,11135.953125,57.1948852661984,20.5365852939189,25.186911,0,0,0,40,4449,149.89635,11108.3125,,,,,,,,,,,,,0,,,,0,,,,,,150.0037994,,,,
,31265472.22,150.0060883,15868.849609375,2.07579246647646E-5,1.0590960415142E-6,1,0.999253354069792,40.0298881530762,1.99507670635531,20.4799994826317,0.000234265729806091,4.88824024041269E-5,0.25,6.9004452535478E-7,2.08585343658154E-5,7.26527178884106E-7,150.0060883,150.0060883,15838.826171875,15898.873046875,56.9424192544868,20.5325037065731,24.807261,0,0,0,40,4449,149.895,15868.849609375,,,,,,,,,,,,,0,,,,-0.00245,,,,,,150.0060883,,,,
,31265567.765,150.0072937,20645.9609375,9.40006083882025E-6,1.38783981881474E-6,1,0.999253354069792,40.0298881530762,1.99514305157824,20.4799994826317,0.000104481142593503,3.13653893096695E-5,0.25,1.12549356474346E-6,9.44433728405825E-6,1.14596091117104E-6,150.0072937,150.0072937,20640.978515625,20650.943359375,57.2261504069676,20.533383981263,25.186911,0,0,0,40,4449,149.8855,20645.9609375,,,,,,,,,,,,,0,,,,-0.00245,,,,,,150.0072937,,,,
,31265664.02,150.0106659,25453.8095703125,-5.85606040751028E-6,1.42145073640367E-6,1,0.999253354069792,40.0298881530762,1.99512500453055,20.4799994826317,-6.84707681920935E-5,-1.28824784005422E-7,0.25,1.0087932489213E-6,-5.8863642612591E-6,1.00444852974417E-6,150.0106659,150.0106659,25448.919921875,25458.69921875,56.8197035769676,20.5333569304991,25.566563,0,0,0,40,4449,149.8794,25453.8095703125,,,,,,,,,,,,,0,,,,0,,,,,,150.0106659,,,,
,31265759.045,150.0098267,30204.5224609375,-2.1799607035822E-5,1.60668862690317E-6,1,0.999253354069792,40.0298881530762,1.99526292240986,20.4799994826317,-0.000250960723499426,-2.31177043532274E-5,0.25,1.76108437881173E-6,-2.19092654638301E-5,1.73523252436574E-6,150.0098267,150.0098267,30176.71875,30232.326171875,57.1182856713137,20.5324730499226,25.566563,0,0,0,40,4449,149.86925,30204.5224609375,,,,,,,,,,,,,0,,,,0,,,,,,150.0098267,,,,
,31265857.37,150.0096893,35119.392578125,-3.79832326834612E-5,1.91800315582733E-6,1,0.999253354069792,40.0298881530762,1.99505990569724,20.4799994826317,-0.000434836954937918,-5.39973768166708E-5,0.25,1.85951202006469E-6,-3.81724167839051E-5,1.80871883897276E-6,150.0096893,150.0096893,35084.45703125,35154.328125,57.0252718775253,20.5341631926432,25.186911,0,0,0,40,4449,149.85915,35119.392578125,,,,,,,,,,,,,0,,,,0,,,,,,150.0096893,,,,
,31265954.875,150.0095673,39991.623046875,-5.57833902846582E-5,2.03891736517934E-6,1,0.999253354069792,40.0298881530762,1.99492754961436,20.4799994826317,-0.000635233389182868,-9.8484132740646E-5,0.25,1.0403025191567E-6,-5.60586175988034E-5,9.57678992085812E-7,150.0095673,150.0095673,39961.71875,40021.52734375,56.9791557948906,20.5355322133027,25.566563,0,0,0,40,4449,149.84935,39991.623046875,,,,,,,,,,,,,0,,,,0,,,,,,150.0095673,,,,
,31266050.15,150.01109315,44754.98046875,-7.06980407169543E-5,1.73825226547259E-6,1,0.999253354069792,40.0298881530762,1.99493688967532,20.4799994826317,-0.000806401580453171,-0.000117219086544279,0.25,1.98742548407871E-6,-7.10479662450094E-5,1.88632584410492E-6,150.0107269,150.0114594,44725.25,44784.7109375,57.0330881627176,20.5329785139986,25.186911,0,0,0,40,4449,149.84065,44754.98046875,,,,,,,,,,,,,0,,,,0.00245,,,,,,150.01109315,,,,
,31266144.75,150.01050565,49485.3828125,-8.81762547881928E-5,1.45739455722668E-6,1,0.999253354069792,40.0298881530762,1.99496612850609,20.4799994826317,-0.00101110934215516,-0.000115591762278661,0.25,5.17495416219266E-6,-8.86169838712699E-5,5.06250517202732E-6,150.010025,150.0109863,49452.67578125,49518.08984375,56.7001144135252,20.5333659429489,24.807261,0,0,0,40,4449,149.82885,49485.3828125,,,,,,,,,,,,,0,,,,0,,,,,,150.01050565,,,,
,31266241.48,150.0105591,54317.822265625,-0.000105190212355056,1.67856565518204E-6,1,0.999253354069792,40.0298881530762,1.99496534265458,20.4799994826317,-0.00119770907349822,-0.000186687501421631,0.25,1.87447323346429E-6,-0.000105709362253579,1.71974734657583E-6,150.0105591,150.0105591,54285.36328125,54350.28125,56.8017261210252,20.5336961234645,25.566563,0,0,0,40,4449,149.8174,54317.822265625,,,,,,,,,,,,,0,,,,0,,,,,,150.0105591,,,,
,31266338.75,150.012619,59180.439453125,-0.000121917147192911,2.30963000318942E-6,1,0.999253354069792,40.0298881530762,1.99503382877204,20.4799994826317,-0.00138928994842208,-0.000210185139238852,0.25,2.71778502860043E-6,-0.000122519808016008,2.54173349839866E-6,150.012619,150.012619,59177.9765625,59182.90234375,56.8783257159099,20.5336375868349,24.807261,0,0,0,40,4449,149.8033,59180.439453125,,,,,,,,,,,,,0,,,,0.00245,,,,,,150.012619,,,,
,31266434.205,150.009201,63950.767578125,-0.000143185829533768,2.39401283439759E-6,1,0.999253354069792,40.0298881530762,1.99482891140496,20.4799994826317,-0.0016318010898185,-0.000245076715917239,0.25,3.3455164704416E-6,-0.000143894016000267,3.14023543612677E-6,150.009201,150.009201,63920.796875,63980.73828125,57.0541921327368,20.5362461240646,25.186911,0,0,0,40,4449,149.8023,63950.767578125,,,,,,,,,,,,,0,,,,0.00245,,,,,,150.009201,,,,
,31266532.095,150.0095291,68843.87890625,-0.000160273023380127,2.29555170901092E-6,1,0.999253354069792,40.0298881530762,1.99499085949044,20.4799994826317,-0.00183008763978807,-0.000254758984687741,0.25,5.46938634892622E-6,-0.000161068536496713,5.24889700404182E-6,150.0091858,150.0098724,68813.7109375,68874.046875,56.8439340610637,20.534374010309,24.807261,0,0,0,40,4449,149.79085,68843.87890625,,,,,,,,,,,,,0,,,,-0.00245,,,,,,150.0095291,,,,
,31266627.685,150.0081024,73621.37890625,-0.000176434207378374,2.19110968904812E-6,1,0.999253354069792,40.0298881530762,1.99512774977134,20.4799994826317,-0.00201406804084196,-0.000284433669512164,0.25,5.67051273392885E-6,-0.000177309563806993,5.42697144396107E-6,150.0077667,150.0084381,73591.78125,73650.9765625,56.7767140084099,20.5298289502116,25.566563,0,0,0,40,4449,149.7843,73621.37890625,,,,,,,,,,,,,0,,,,-0.00245,,,,,,150.0081024,,,,
,31266725.035,150.0117798,78487.03125,-0.000196625934913636,2.82518572745192E-6,1,0.999253354069792,40.0298881530762,1.99500828116269,20.4799994826317,-0.00224767230255633,-0.000298397053125878,0.25,7.95442840306155E-6,-0.000197604137647327,7.69206634306274E-6,150.0116425,150.0119171,78454.5703125,78519.4921875,57.2574155477368,20.529042796488,25.566563,0,0,0,40,4449,149.77365,78487.03125,,,,,,,,,,,,,0,,,,0.0049,,,,,,150.0117798,,,,
,31266821.61,150.0104065,83315.49609375,-0.000214845354642966,1.78605325510096E-6,1,0.999253354069792,40.0298881530762,1.99513334278111,20.4799994826317,-0.00245155057631309,-0.000352142300843471,0.25,6.39333340867011E-6,-0.000215910884968411,6.09649412819415E-6,150.0104065,150.0104065,83307.9609375,83323.03125,56.8431524325445,20.5322491406659,25.566563,0,0,0,40,4449,149.7672,83315.49609375,,,,,,,,,,,,,0,,,,0.00245,,,,,,150.0104065,,,,
,31266912.95,150.0103302,87881.41796875,-0.000229165958641947,2.00144637691184E-6,1,0.999253354069792,40.0298881530762,1.99495174351999,20.4799994826317,-0.00260996385751694,-0.000402979333356691,0.25,4.40473533125025E-6,-0.000230299035731499,4.07736217198859E-6,150.0103302,150.0103302,87851.4609375,87911.375,56.7016776705637,20.5323800129276,25.186911,0,0,0,40,4449,149.7554,87881.41796875,,,,,,,,,,,,,0,,,,-0.00735,,,,,,150.0103302,,,,
,31267019.1,150.0076752,87600.58203125,-0.00023284935374223,2.37908100095295E-6,1,0.999253354069792,40.0298881530762,1.99476450226962,20.4799994826317,-0.00265352659789222,-0.000398794406794734,0.25,5.41179103766704E-6,-0.000234002067274304,5.08365625775086E-6,150.0072632,150.0080872,87573.046875,87628.1171875,56.638365760506,20.5296374240571,25.566563,0,0,0,40,4449,149.7464,87600.58203125,,,,,,,,,,,,,0,,,,0,,,,,,150.0076752,,,,
,31267113.61,150.0032959,82874.69140625,-0.000214253107875351,2.59077464530725E-6,1,0.999253354069792,40.0298881530762,1.99488326371102,20.4799994826317,-0.00244164785546679,-0.000367509123458198,0.25,4.932806720625E-6,-0.000215313510259777,4.62954056847925E-6,150.0032959,150.0032959,82844.75,82904.6328125,57.1909771236022,20.5319997075002,25.186911,0,0,0,40,4449,149.75025,82874.69140625,,,,,,,,,,,,,0,,,,0,,,,,,150.0032959,,,,
,31267208.26,149.9980774,78143.28515625,-0.000194825128587274,2.77561310434596E-6,1,0.999253354069792,40.0298881530762,1.99502417381725,20.4799994826317,-0.00222844752761908,-0.000287954163486208,0.25,8.56113604549418E-6,-0.000195795466391583,8.30437985283828E-6,149.9980774,149.9980774,78110.8359375,78175.734375,56.7032409276022,20.5298516313505,25.186911,0,0,0,40,4449,149.75035,78143.28515625,,,,,,,,,,,,,0,,,,-0.0049,,,,,,149.9980774,,,,
,31267307.04,149.9953003,73204.30078125,-0.000175804467824106,2.24559463949161E-6,1,0.999253354069792,40.0298881530762,1.99489432805628,20.4799994826317,-0.00200228922436745,-0.000308458663135277,0.25,3.44157579900885E-6,-0.000176673335744822,3.18789908519611E-6,149.9953003,149.9953003,73201.53125,73207.0703125,56.9361662263329,20.5297144798209,24.807261,0,0,0,40,4449,149.7538,73204.30078125,,,,,,,,,,,,,0,,,,-0.0049,,,,,,149.9953003,,,,
,31267403.645,149.9919281,68379.296875,-0.000157203663162088,2.27329380282647E-6,1,0.999253354069792,40.0298881530762,1.99503710600261,20.4799994826317,-0.00179356868329924,-0.000258565125822277,0.25,4.6001716928566E-6,-0.000157982813923057,4.38001174821124E-6,149.9919281,149.9919281,68354.3671875,68404.2265625,56.7884384361983,20.5327468654587,25.186911,0,0,0,40,4449,149.76365,68379.296875,,,,,,,,,,,,,0,,,,0,,,,,,149.9919281,,,,
,31267501.43,149.9917603,63488.85546875,-0.000140997808340208,2.59261477791937E-6,1,0.999253354069792,40.0298881530762,1.99511683792398,20.4799994826317,-0.00160893185935669,-0.000230774941629173,0.25,4.22742884360736E-6,-0.00014169666242834,4.0297330926198E-6,149.9915009,149.9920197,63461.45703125,63516.25390625,56.8447156895829,20.5303392794332,24.807261,0,0,0,40,4449,149.77095,63488.85546875,,,,,,,,,,,,,0,,,,0,,,,,,149.9917603,,,,
,31267598.585,149.9911346,58632.814453125,-0.000119346208047554,1.89203233373224E-6,1,0.999253354069792,40.0298881530762,1.99515195402143,20.4799994826317,-0.0013672036302441,-0.000164810200418468,0.25,6.26828367391242E-6,-0.000119941818869988,6.11354443085555E-6,149.9911346,149.9911346,58602.6875,58662.94140625,57.1268835850253,20.5333247820533,25.566563,0,0,0,40,4449,149.77885,58632.814453125,,,,,,,,,,,,,0,,,,0,,,,,,149.9911346,,,,
,31267696.125,149.98970795,53757.9140625,-0.000103722972191334,2.24431850827793E-6,1,0.999253354069792,40.0298881530762,1.99515951564488,20.4799994826317,-0.00118646872859367,-0.000153351981311394,0.25,4.55710218867523E-6,-0.000104239144879361,4.41772406652767E-6,149.9892426,149.9901733,53725.4921875,53790.3359375,56.902556200006,20.5344022868733,25.186911,0,0,0,40,4449,149.7881,53757.9140625,,,,,,,,,,,,,0,,,,-0.00245,,,,,,149.98970795,,,,
,31267792.12,149.9913483,48959.90234375,-8.76832769916752E-5,2.16253777966612E-6,1,0.999253354069792,40.0298881530762,1.99519881055326,20.4799994826317,-0.00100380945140047,-0.000125058638778996,0.25,4.25639014178941E-6,-8.81201829968977E-5,4.14011245605517E-6,149.9913483,149.9913483,48937.64453125,48982.16015625,57.1104693861214,20.534555367808,25.566563,0,0,0,40,4449,149.79345,48959.90234375,,,,,,,,,,,,,0,,,,-0.00245,,,,,,149.9913483,,,,
,31267889.685,149.9918594,44084.658203125,-7.07350078569816E-5,1.76790586138342E-6,1,0.999253354069792,40.0298881530762,1.9951182021566,20.4799994826317,-0.000810938886524342,-9.40658308541893E-5,0.25,4.03448523878654E-6,-7.10883482724225E-5,3.94328009570461E-6,149.9917297,149.9919891,44054.7109375,44114.60546875,57.1284468420637,20.5300924752604,24.807261,0,0,0,40,4449,149.80075,44084.658203125,,,,,,,,,,,,,0,,,,-0.00245,,,,,,149.9918594,,,,
,31267986.875,149.9926758,39224.298828125,-5.23796107554381E-5,1.66520750580915E-6,1,0.999253354069792,40.0298881530762,1.99507166295764,20.4799994826317,-0.000597575069551669,-8.63903619129837E-5,0.25,1.51347294983491E-6,-5.26388994588011E-5,1.43845029176905E-6,149.9921112,149.9932404,39196.71875,39251.87890625,57.3613721407945,20.5315215460661,25.186911,0,0,0,40,4449,149.8079,39224.298828125,,,,,,,,,,,,,0,,,,0,,,,,,149.9926758,,,,
,31268080.605,149.9892426,34539.814453125,-3.61921033025752E-5,1.26338441790069E-6,1,0.999253354069792,40.0298881530762,1.99521359456694,20.4799994826317,-0.000415353542968629,-4.5765578710311E-5,0.25,2.27303464449537E-6,-3.63731708573708E-5,2.22705096031546E-6,149.9892426,149.9892426,34509.75,34569.87890625,56.9580518248714,20.5305452660982,25.946213,0,0,0,40,4449,149.81625,34539.814453125,,,,,,,,,,,,,0,,,,0.00245,,,,,,149.9892426,,,,
,31268175.345,149.99143985,29804.697265625,-1.91368974172019E-5,1.62226378131046E-6,1,0.999253354069792,40.0298881530762,1.99525692542272,20.4799994826317,-0.000220840205269969,-1.72308419346831E-5,0.25,1.81581787020547E-6,-1.92335958949906E-5,1.79442667508257E-6,149.9914246,149.9914551,29777.302734375,29832.091796875,56.9924434797176,20.5322962894272,25.186911,0,0,0,40,4449,149.8243,29804.697265625,,,,,,,,,,,,,0,,,,0.00245,,,,,,149.99143985,,,,
,31268268.82,149.9888458,25134.384765625,-4.7161452359446E-6,1.02029577314528E-6,1,0.999253354069792,40.0298881530762,1.99535843804536,20.4799994826317,-5.66758386351302E-5,8.66242185608969E-6,0.25,1.58458351782466E-6,-4.74177857463941E-6,1.58486524450363E-6,149.9888458,149.9888458,25104.212890625,25164.556640625,56.9557069393137,20.5307586531732,25.566563,0,0,0,40,4449,149.8343,25134.384765625,,,,,,,,,,,,,0,,,,-0.00245,,,,,,149.9888458,,,,
,31268364.675,149.9911194,20344.5556640625,1.16198211968436E-5,9.5214587356539E-7,1,0.999253354069792,40.0298881530762,1.99530312686684,20.4799994826317,0.00013147591526064,2.55015782276096E-5,0.25,2.22055020246175E-7,1.16764156777815E-5,2.41636533065233E-7,149.9911194,149.9911194,20312.046875,20377.064453125,57.065134932006,20.53147591257,25.186911,0,0,0,40,4449,149.8425,20344.5556640625,,,,,,,,,,,,,0,,,,0,,,,,,149.9911194,,,,
,31268461.14,149.9925842,15522.0478515625,2.55748556468309E-5,1.04899418859736E-6,1,0.999253354069792,40.0298881530762,1.99538414980241,20.4799994826317,0.000289405483328166,5.60139261979593E-5,0.25,4.78381345053529E-7,2.56994083091267E-5,5.21535005978564E-7,149.9925842,149.9925842,15519.4970703125,15524.5986328125,57.1573670972753,20.5313831624983,25.566563,0,0,0,40,4449,149.8466,15522.0478515625,,,,,,,,,,,,,0,,,,0.0049,,,,,,149.9925842,,,,
,31268555.22,149.9918518,10820.0180664062,3.8462624371779E-5,9.45363165070643E-7,1,0.999253354069792,40.0298881530762,1.9953353372064,20.4799994826317,0.000435061701160922,8.52227138683641E-5,0.25,8.0598994969273E-7,3.86497701550132E-5,8.71456518930468E-7,149.9918518,149.9918518,10792.638671875,10847.3974609375,56.902556200006,20.5349017901446,25.186911,0,0,0,40,4449,149.85745,10820.0180664062,,,,,,,,,,,,,0,,,,0,,,,,,149.9918518,,,,
,31268649.4,149.993866,6112.07495117187,4.84538832678513E-5,5.58791018879126E-7,1,0.999253354069792,40.0298881530762,1.99523923862266,20.4799994826317,0.000549033743295718,0.000101709029342339,0.25,5.17793578260149E-7,4.86903975620382E-5,5.97994584851382E-7,149.993866,149.993866,6079.5390625,6144.61083984375,56.9549253107945,20.5334387622083,24.807261,0,0,0,40,4449,149.8667,6112.07495117187,,,,,,,,,,,,,0,,,,0,,,,,,149.993866,,,,
,31268743.855,149.9933243,1391.18133544922,5.21632407050161E-5,3.79711840191702E-7,1,0.999253354069792,40.0298881530762,1.99529880135175,20.4799994826317,0.000592670140196903,0.000100377787090351,0.25,-2.4611962323885E-7,5.24191160360791E-5,-1.63558030687741E-7,149.9929352,149.9937134,1356.13293457031,1426.22973632812,56.9822823089676,20.5339550715137,25.186911,0,0,0,40,4449,149.86855,1391.18133544922,,,,,,,,,,,,,0,,,,0,,,,,,149.9933243,,,,
,31268771.53,149.9944458,-0.525220185518265,4.97685784343517E-5,3.89676101683071E-7,1,0.999253354069792,40.0298881530762,1.995353981895,20.4799994826317,0.000565334343545591,9.65923295522953E-5,0.25,-1.62613826771337E-7,5.00125834275818E-5,-8.34597565296535E-8,149.9944458,149.9944458,-0.548055827617645,-0.502384543418884,56.9252234270637,20.5374336147844,25.566563,0,0,0,40,4417,149.87095,-0.525220185518265,,,,,,,,,,,,,0,,,,-0.0049,,,,,,149.9944458,,,,