File: data/doubleLayers/dl_0-125/ppms/data/DD213_7_FCC_100OE.DAT
[Header]
; VSM Data File (default extension .dat)
; Copyright (c) 2003-2013, Quantum Design, Inc. All rights reserved.
TITLE,
FILEOPENTIME,31175847.91,12/28/2018,3:59 am
BYAPP,VSM,2.0,2.0
INFO,PPMS VSM Option Release 1.4.10 Build 1,APPNAME
INFO,Quantum Design Linear Motor Servo Controller,MOTOR_MODULE_NAME
INFO,3101-100 M1,MOTOR_HW_VERSION
INFO,MMC1014,MOTOR_SERIAL_NUMBER
INFO,SRV No X-over 01.03.11,MOTOR_SOFTWARE_VERSION
INFO,Quantum Design VSM Detection Module,VSM_MODULE_NAME
INFO,3101-150 F0,VSM_HW_VERSION
INFO,VSM707,VSM_SERIAL_NUMBER
INFO,VSM No X-over 01.02.05 May 20 2008 13:51:47,VSM_SOFTWARE_VERSION
INFO,704,PREAMP_SERIAL_NUMBER
INFO,822,COIL_SERIAL_NUMBER
INFO,0,MOMENT_UNITS
INFO,CoFe2O4,SAMPLE_MATERIAL
INFO,Double Layer thin concentration,SAMPLE_COMMENT
INFO,29.55,SAMPLE_MASS
INFO,,SAMPLE_VOLUME
INFO,,SAMPLE_MOLECULAR_WEIGHT
INFO,,SAMPLE_SIZE
INFO,,SAMPLE_SHAPE
DATATYPE,COMMENT,1
DATATYPE,TIME,2
STARTUPAXIS,X,2
STARTUPAXIS,Y1,5
[Data]
Comment,Time Stamp (sec),Temperature (K),Magnetic Field (Oe),Moment (emu),M. Std. Err. (emu),Transport Action,Averaging Time (sec),Frequency (Hz),Peak Amplitude (mm),Center Position (mm),Coil Signal' (mV),Coil Signal" (mV),Range (mV),M. Quad. Signal (emu),M. Raw' (emu),M. Raw" (emu),Min. Temperature (K),Max. Temperature (K),Min. Field (Oe),Max. Field (Oe),Mass (grams),Motor Lag (deg),Pressure (Torr),VSM Status (code),Motor Status (code),Measure Status (code),Measure Count,PPMS Status (code),System Temp. (K),System Field (Oe),Sample Position (deg),Bridge 1 Resistance (ohms),Bridge 1 Excitation (에),Bridge 2 Resistance (ohms),Bridge 2 Excitation (에),Bridge 3 Resistance (ohms),Bridge 3 Excitation (에),Bridge 4 Resistance (ohms),Bridge 4 Excitation (에),Signal 1 Vin (V),Signal 2 Vin (V),Digital Inputs (code),Drive 1 Iout (mA),Drive 1 Ipower (W),Drive 2 Iout (mA),Drive 2 Ipower (W),Pressure (),Map 20 (),Map 21 (),Map 22 (),Map 23 (),Map 24 (),Map 25 (),Map 26 (),Map 27 (),Map 28 (),Map 29 ()
,31176019.85,349.6039429,99.4873580932617,1.31665065759386E-5,4.87914253746143E-7,1,0.999253354069792,40.0298881530762,1.99647103066019,19.4899998605251,0.000148109012787866,2.85213183832383E-5,0.25,2.47417869240656E-7,1.31432011567951E-5,2.54320433065769E-7,349.6039429,349.6039429,99.4873580932617,99.4873580932617,56.9916618511983,20.5235613038158,26.325863,0,0,0,40,4369,350.2868,99.4873580932617,,,,,,,,,,,,,0,,,,-0.00245,,,,,,349.6039429,,,,
,31176172.195,346.9840088,99.4873580932617,1.27576901466951E-5,3.90272874044574E-7,1,0.999253354069792,40.0298881530762,1.99629452178937,19.4899998605251,0.000144267363266968,2.32666922526784E-5,0.25,-1.47512679198315E-7,1.2736449252449E-5,-1.40048644712611E-7,346.9840088,346.9840088,99.4873580932617,99.4873580932617,57.0643533034868,20.5230666807882,27.085165,0,0,0,40,4374,345.149,99.4873580932617,,,,,,,,,,,,,0,,,,-0.00245,,,,,,346.9840088,,,,
,31176323.43,343.4790344,99.4873580932617,1.36008641763098E-5,5.07935059075315E-7,1,0.999253354069792,40.0298881530762,1.99636116613909,19.4899998605251,0.000153681563056507,2.56389350259135E-5,0.25,-8.37546260331279E-8,1.3579794973691E-5,-7.58350947932312E-8,343.4519958,343.506073,99.4873580932617,99.4873580932617,57.0354330482753,20.5206811878103,26.705515,0,0,0,40,4374,341.1439,99.4873580932617,,,,,,,,,,,,,0,,,,0.00245,,,,,,343.4790344,,,,
,31176469.12,339.9768066,99.4873580932617,1.39538531882238E-5,4.31766019700961E-7,1,0.999253354069792,40.0298881530762,1.99620100635269,19.4899998605251,0.000157445779331843,2.76402880323376E-5,0.25,3.22289581715915E-8,1.39338370279813E-5,4.0269084712231E-8,339.9768066,339.9768066,99.4873580932617,99.4873580932617,56.973684395256,20.5233919172017,27.085165,0,0,0,40,4374,337.43215,99.4873580932617,,,,,,,,,,,,,0,,,,0.0049,,,,,,339.9768066,,,,
,31176611.57,336.4985046,99.4873580932617,1.33880549732384E-5,3.98632003314323E-7,1,0.999253354069792,40.0298881530762,1.99625671116536,19.4899998605251,0.000151534838251919,2.39188629153756E-5,0.25,-1.99876790898983E-7,1.33705837693554E-5,-1.91762007086609E-7,336.4985046,336.4985046,99.4873580932617,99.4873580932617,56.9346029692945,20.5233980343104,27.085165,0,0,0,40,4374,333.75655,99.4873580932617,,,,,,,,,,,,,0,,,,0,,,,,,336.4985046,,,,
,31176754.285,332.9971924,99.4873580932617,1.40050657236683E-5,3.9022152851891E-7,1,0.999253354069792,40.0298881530762,1.99617009813262,19.4899998605251,0.000158109622555563,2.74574106219799E-5,0.25,6.41337652694848E-9,1.39883548831678E-5,1.47200183090845E-8,332.9971924,332.9971924,99.4873580932617,99.4873580932617,57.0823307594291,20.5221931947665,27.085165,0,0,0,40,4374,330.1462,99.4873580932617,,,,,,,,,,,,,0,,,,-0.0049,,,,,,332.9971924,,,,
,31176877.94,329.9524994,99.4873580932617,1.46954526933363E-5,4.71037099176709E-7,1,0.999253354069792,40.0298881530762,1.99651459755994,19.4499995559454,0.00016689614611558,2.3347647582418E-5,0.25,-4.77814005874254E-7,1.46797598180207E-5,-4.68475540720272E-7,329.9274597,329.9775391,99.4873580932617,99.4873580932617,56.8970848003714,20.5204997194767,26.705515,0,0,0,40,4374,327.0041,99.4873580932617,,,,,,,,,,,,,0,,,,-0.00245,,,,,,329.9524994,,,,
,31176998.58,326.9640198,99.4873580932617,1.47490163688076E-5,4.3840417054805E-7,1,0.999253354069792,40.0298881530762,1.99646593917087,19.4499995559454,0.000166304763454519,3.04396780246762E-5,0.25,1.40577804810491E-7,1.47344273680204E-5,1.49385193203772E-7,326.9640198,326.9640198,99.4873580932617,99.4873580932617,57.3293253715061,20.5198333647346,26.705515,0,0,0,40,4374,323.9734,99.4873580932617,,,,,,,,,,,,,0,,,,0,,,,,,326.9640198,,,,
,31177140.73,323.4674988,99.4873580932617,1.42579852402846E-5,4.36934520795746E-7,1,0.999253354069792,40.0298881530762,1.9964587260715,19.4499995559454,0.00016107445757954,2.77711090191373E-5,0.25,-1.1054226427323E-8,1.42457130486551E-5,-2.28434035369187E-9,323.4674988,323.4674988,99.4873580932617,99.4873580932617,56.8837971155445,20.5170743699722,26.705515,0,0,0,40,4374,320.3589,99.4873580932617,,,,,,,,,,,,,0,,,,0.0049,,,,,,323.4674988,,,,
,31177282.235,319.9776611,99.4873580932617,1.4289396724125E-5,3.78378104187374E-7,1,0.999253354069792,40.0298881530762,1.99671075681812,19.4600000977516,0.000162013253027318,2.46944642845799E-5,0.25,-2.89514696355974E-7,1.42790203247401E-5,-2.8040701475368E-7,319.9776611,319.9776611,99.4873580932617,99.4873580932617,56.9603967104291,20.5155623054992,27.085165,0,0,0,40,4374,316.822,99.4873580932617,,,,,,,,,,,,,0,,,,0,,,,,,319.9776611,,,,
,31177423.065,316.463562,99.4873580932617,1.45860625964597E-5,4.34198078376858E-7,1,0.999253354069792,40.0298881530762,1.99673974362327,19.4600000977516,0.000164767044774371,2.8862515308253E-5,0.25,2.75342784013169E-8,1.45770741827968E-5,3.67161301222897E-8,316.463562,316.463562,99.4873580932617,99.4873580932617,56.8064158921406,20.5169749605189,27.085165,0,0,0,40,4374,313.2831,99.4873580932617,,,,,,,,,,,,,0,,,,-0.00245,,,,,,316.463562,,,,
,31177565.085,312.956543,99.4873580932617,1.52166779475654E-5,4.76349503090548E-7,1,0.999253354069792,40.0298881530762,1.99689302058011,19.4600000977516,0.000171825877049737,3.06855925312136E-5,0.25,7.89653545142733E-8,1.52091534683853E-5,8.86541577653815E-8,312.956543,312.956543,99.4873580932617,99.4873580932617,56.8994296859291,20.5180408318559,26.705515,0,0,0,40,4374,309.7006,99.4873580932617,,,,,,,,,,,,,0,,,,0,,,,,,312.956543,,,,
,31177705.19,309.4927063,99.4873580932617,1.58630793942783E-5,4.25771472160561E-7,1,0.999253354069792,40.0298881530762,1.99643425906442,19.4799993187189,0.000178877038594898,3.33174873805621E-5,0.25,2.00001318227334E-7,1.58571047650505E-5,2.10206578088602E-7,309.4927063,309.4927063,99.4873580932617,99.4873580932617,56.8126689202945,20.5192585870191,27.085165,0,0,0,40,4374,306.188,99.4873580932617,,,,,,,,,,,,,0,,,,0,,,,,,309.4927063,,,,
,31177847.24,305.9481201,99.4873580932617,1.59430931589499E-5,3.74663072193412E-7,1,0.999253354069792,40.0298881530762,1.99650902355139,19.4799993187189,0.000182172102163803,1.98476311226298E-5,0.25,-1.00620756352505E-6,1.59398869065129E-5,-9.95487512004618E-7,305.9481201,305.9481201,99.4873580932617,99.4873580932617,56.9064643426022,20.5201796961885,26.705515,0,0,0,40,4374,302.6227,99.4873580932617,,,,,,,,,,,,,0,,,,0,,,,,,305.9481201,,,,
,31177987.7,302.4845581,99.4873580932617,1.57930886688535E-5,3.90149078475285E-7,1,0.999253354069792,40.0298881530762,1.99645550901005,19.4799993187189,0.000178066047199329,3.3571061216838E-5,0.25,2.33507917829723E-7,1.57910489825131E-5,2.44003512729264E-7,302.4845581,302.4845581,99.4873580932617,99.4873580932617,56.7759323798906,20.5192385573384,27.085165,0,0,0,40,4374,299.1054,99.4873580932617,,,,,,,,,,,,,0,,,,0.00245,,,,,,302.4845581,,,,
,31178109.14,299.47050475,99.4873580932617,1.5765967558977E-5,3.59798678968733E-7,1,0.999253354069792,40.0298881530762,1.99641599775422,19.4899998605251,0.000179409041246764,2.40915376005491E-5,0.25,-6.00718505956629E-7,1.57661862469505E-5,-5.90076017511867E-7,299.4395447,299.5014648,99.4873580932617,99.4873580932617,56.9150622563137,20.5153104679454,27.464817,0,0,0,40,4374,296.05175,99.4873580932617,,,,,,,,,,,,,0,,,,0,,,,,,299.47050475,,,,
,31178248.215,295.9946899,99.4873580932617,1.59218569144967E-5,4.7573061601919E-7,1,0.999253354069792,40.0298881530762,1.99612254359246,19.4899998605251,0.000179428671935224,3.44368973057115E-5,0.25,2.87291019418716E-7,1.59234481373371E-5,2.98217734985391E-7,295.9946899,295.9946899,99.4873580932617,99.4873580932617,56.9900985941599,20.5191711438477,27.085165,0,0,0,40,4374,292.5648,99.4873580932617,,,,,,,,,,,,,0,,,,-0.0049,,,,,,295.9946899,,,,
,31178389.95,292.4992981,99.4873580932617,1.60539392482949E-5,4.23619108872155E-7,1,0.999253354069792,40.0298881530762,1.99611998076612,19.4899998605251,0.000182039095568695,2.83815319091035E-5,0.25,-2.71720660585106E-7,1.60579365694034E-5,-2.60637018390511E-7,292.4992981,292.4992981,99.4873580932617,99.4873580932617,57.0901470446214,20.5205559688275,27.464817,0,0,0,40,4374,288.9974,99.4873580932617,,,,,,,,,,,,,0,,,,-0.0049,,,,,,292.4992981,,,,
,31178511.33,289.4827576,99.4873580932617,1.6246685578782E-5,4.31271863895441E-7,1,0.999253354069792,40.0298881530762,2.00877533114953,19.5099990814924,0.00018501914061993,3.08594658048473E-5,0.25,-1.02797397814264E-7,1.62523658608503E-5,-9.14064704022288E-8,289.4827576,289.4827576,99.4873580932617,99.4873580932617,56.9643048530253,20.523315356863,27.464817,0,0,0,40,4374,285.9593,99.4873580932617,,,,,,,,,,,,,0,,,,0.0049,,,,,,289.4827576,,,,
,31178651.195,285.997345,99.4873580932617,1.63870301640806E-5,4.25789313864539E-7,1,0.999253354069792,40.0298881530762,2.00860611901306,19.5099990814924,0.000187460015491939,2.63134643904808E-5,0.25,-5.27019666975468E-7,1.63951076295921E-5,-5.15569850922154E-7,285.997345,285.997345,99.4873580932617,99.4873580932617,56.9564885678329,20.5260953740202,27.464817,0,0,0,40,4374,282.4568,99.4873580932617,,,,,,,,,,,,,0,,,,-0.00245,,,,,,285.997345,,,,
,31178791.69,282.4861145,99.4873580932617,1.68204902654563E-5,4.22760283675821E-7,1,0.999253354069792,40.0298881530762,2.00847307167777,19.5099990814924,0.000191516915736543,3.22833095329826E-5,0.25,-7.77324577089046E-8,1.68305666341119E-5,-6.55890808880922E-8,282.4861145,282.4861145,99.4873580932617,99.4873580932617,57.0190188493714,20.5279067710471,26.705515,0,0,0,40,4374,278.9378,99.4873580932617,,,,,,,,,,,,,0,,,,-0.0049,,,,,,282.4861145,,,,
,31178933.195,278.9818268,99.4873580932617,1.67724842736219E-5,3.79152352396156E-7,1,0.999253354069792,40.0298881530762,1.98476450064785,19.5300001651049,0.000188169512201165,3.57114266820504E-5,0.25,2.67106819862941E-7,1.678438375576E-5,2.79642078889515E-7,278.9549561,279.0086975,99.4873580932617,99.4873580932617,56.8837971155445,20.5283757962992,27.085165,0,0,0,40,4374,275.4125,99.4873580932617,,,,,,,,,,,,,0,,,,0,,,,,,278.9818268,,,,
,31179073.67,275.4787292,99.4873580932617,1.68711348182356E-5,4.13628811581787E-7,1,0.999253354069792,40.0298881530762,1.98471867533563,19.5300001651049,0.000190182585502555,3.08093200317008E-5,0.25,-1.86211418078865E-7,1.68855564980957E-5,-1.73759449391899E-7,275.4787292,275.4787292,99.4873580932617,99.4873580932617,56.9830639374868,20.5291412529315,27.085165,0,0,0,40,4374,271.884,99.4873580932617,,,,,,,,,,,,,0,,,,0.0049,,,,,,275.4787292,,,,
,31179214.86,271.9550781,99.4873580932617,1.72145781337289E-5,4.15487282809816E-7,1,0.999253354069792,40.0298881530762,1.98467694002329,19.5300001651049,0.000194530125302115,2.88125731195955E-5,0.25,-4.23690741219127E-7,1.72316425305938E-5,-4.11032439129698E-7,271.9550781,271.9550781,99.4873580932617,99.4873580932617,57.0424677049483,20.5281022877438,27.085165,0,0,0,40,4374,268.355,99.4873580932617,,,,,,,,,,,,,0,,,,0,,,,,,271.9550781,,,,
,31179354.23,268.4877014,99.4873580932617,1.74119713436193E-5,3.72041535504581E-7,1,0.999253354069792,40.0298881530762,1.98473938727012,19.5599999278784,0.00019645889865719,3.10633156004974E-5,0.25,-2.58518065304424E-7,1.74312622210745E-5,-2.45371803563905E-7,268.4877014,268.4877014,99.4873580932617,99.4873580932617,56.7743691228522,20.5263120043909,27.085165,0,0,0,40,4374,264.8742,99.4873580932617,,,,,,,,,,,,,0,,,,-0.0049,,,,,,268.4877014,,,,
,31179495.18,264.9843292,99.4873580932617,1.74123709204162E-5,3.64220701049194E-7,1,0.999253354069792,40.0298881530762,1.98462703663755,19.5599999278784,0.000195071133996756,3.91766508226448E-5,0.25,4.61877980416424E-7,1.74332765839404E-5,4.76091868741573E-7,264.9613037,265.0073547,99.4873580932617,99.4873580932617,57.1346998702176,20.5295347573726,26.705515,0,0,0,40,4374,261.3267,99.4873580932617,,,,,,,,,,,,,0,,,,0,,,,,,264.9843292,,,,
,31179634.555,261.4856873,99.4873580932617,1.72623237587704E-5,3.56533677593602E-7,1,0.999253354069792,40.0298881530762,1.9846818237107,19.5599999278784,0.000194315224690042,3.3677712908593E-5,0.25,-1.36191310851608E-9,1.72855599656193E-5,1.23878633182379E-8,261.4856873,261.4856873,99.4873580932617,99.4873580932617,57.0815491309099,20.5297840116394,27.085165,0,0,0,40,4374,257.85575,99.4873580932617,,,,,,,,,,,,,0,,,,-0.00245,,,,,,261.4856873,,,,
,31179773.915,257.9960632,99.4873580932617,1.78671463445695E-5,3.84724083593428E-7,1,0.999253354069792,40.0298881530762,1.98478380436774,19.5899996906519,0.000201016928806691,3.56786926338829E-5,0.25,7.07469656074135E-8,1.78933535752015E-5,8.53187685119821E-8,257.9960632,257.9960632,99.4873580932617,99.4873580932617,56.8783257159099,20.5291868433386,26.705515,0,0,0,40,4374,254.3787,99.4873580932617,,,,,,,,,,,,,0,,,,0,,,,,,257.9960632,,,,
,31179915.785,254.48493955,99.4873580932617,1.81233953640511E-5,4.40633201234848E-7,1,0.999253354069792,40.0298881530762,1.98463599818595,19.5899996906519,0.000205272001773221,2.83427939194226E-5,0.25,-6.25667693559155E-7,1.81528064868712E-5,-6.11738984525112E-7,254.4595947,254.5102844,99.4873580932617,99.4873580932617,56.9580518248714,20.5288517266698,26.705515,0,0,0,40,4374,250.81775,99.4873580932617,,,,,,,,,,,,,0,,,,-0.00245,,,,,,254.48493955,,,,
,31180056.205,250.9874878,99.4873580932617,1.83639808155312E-5,3.85647605074421E-7,1,0.999253354069792,40.0298881530762,1.98456809046878,19.5899996906519,0.000206921191764867,3.5033599858337E-5,0.25,-7.36642442697818E-8,1.83955911328392E-5,-5.84073825450416E-8,250.9874878,250.9874878,99.4873580932617,99.4873580932617,57.1472059265253,20.529367204653,27.085165,0,0,0,40,4374,247.3028,99.4873580932617,,,,,,,,,,,,,0,,,,0,,,,,,250.9874878,,,,
,31180176.76,247.951004,99.4873580932617,1.83604795257052E-5,3.82781224300347E-7,1,0.999253354069792,40.0298881530762,1.98462872819663,19.6199994534254,0.000205957076364334,4.05249283943376E-5,0.25,4.13915491061749E-7,1.83936342657196E-5,4.3027961587557E-7,247.951004,247.951004,99.4873580932617,99.4873580932617,56.8298647477175,20.5276532898332,27.085165,0,0,0,40,4374,244.2944,99.4873580932617,,,,,,,,,,,,,0,,,,-0.0049,,,,,,247.951004,,,,
,31180316.62,244.4558716,99.4873580932617,1.83517613679887E-5,3.97184133912966E-7,1,0.999253354069792,40.0298881530762,1.98452585122514,19.6199994534254,0.000207301793131625,3.2278991535247E-5,0.25,-3.17280198186391E-7,1.83877781024883E-5,-3.02023481546754E-7,244.4558716,244.4558716,99.4873580932617,99.4873580932617,57.004167907506,20.5288389382991,27.464817,0,0,0,40,4374,240.7972,99.4873580932617,,,,,,,,,,,,,0,,,,0,,,,,,244.4558716,,,,
,31180455.02,240.9983826,99.4873580932617,1.81796398167551E-5,3.29577793612491E-7,1,0.999253354069792,40.0298881530762,1.98456848197169,19.6199994534254,0.000204398763173707,3.76746794705744E-5,0.25,1.90926414617836E-7,1.82170763502208E-5,2.07323912516627E-7,240.9983826,240.9983826,99.4873580932617,99.4873580932617,57.1135959001984,20.5297506894641,26.705515,0,0,0,40,4374,237.3376,99.4873580932617,,,,,,,,,,,,,0,,,,-0.00245,,,,,,240.9983826,,,,
,31180575.25,237.99377445,99.4873580932617,1.81842213041033E-5,3.52576679191167E-7,1,0.999253354069792,40.0298881530762,2.00818751182654,19.6599997580051,0.000207377506869397,3.47505843315653E-5,0.25,-1.04677183712602E-7,1.82238312050943E-5,-8.86490317881641E-8,237.9627686,238.0247803,99.4873580932617,99.4873580932617,56.9314764552176,20.5246345575534,26.705515,0,0,0,40,4374,234.32195,99.4873580932617,,,,,,,,,,,,,0,,,,0,,,,,,237.99377445,,,,
,31180715.71,234.48318485,99.4873580932617,1.84934292103583E-5,4.09467306368415E-7,1,0.999253354069792,40.0298881530762,2.00809162515477,19.6599997580051,0.000210410195156664,3.82812679928655E-5,0.25,1.51021751298001E-7,1.85357301667366E-5,1.68206146952567E-7,234.4587708,234.5075989,99.4873580932617,99.4873580932617,57.0463758475445,20.5288512831015,26.705515,0,0,0,40,4374,230.79745,99.4873580932617,,,,,,,,,,,,,0,,,,-0.00245,,,,,,234.48318485,,,,
,31180856.415,230.97581485,99.4873580932617,1.85948091215729E-5,3.39902986530901E-7,1,0.999253354069792,40.0298881530762,2.0079510184376,19.6599997580051,0.000211339019614492,3.98532051479109E-5,0.25,2.70894197884124E-7,1.86394776369647E-5,2.88796114237076E-7,230.9489899,231.0026398,99.4873580932617,99.4873580932617,56.8978664288906,20.5306787580978,27.085165,0,0,0,40,4374,227.28795,99.4873580932617,,,,,,,,,,,,,0,,,,0,,,,,,230.97581485,,,,
,31180995.85,227.4760132,99.4873580932617,1.87596916202551E-5,3.41484062929786E-7,1,0.999253354069792,40.0298881530762,1.98422217555231,19.6899995207787,0.000211605917028218,3.53018372082945E-5,0.25,-1.22510371141862E-7,1.88073763591667E-5,-1.05089275573519E-7,227.4509888,227.5010376,99.4873580932617,99.4873580932617,56.9283499411406,20.5331021319028,27.085165,0,0,0,40,4374,223.7882,99.4873580932617,,,,,,,,,,,,,0,,,,0,,,,,,227.4760132,,,,
,31181136.86,223.9603119,99.4873580932617,1.88029451031845E-5,3.76797693962037E-7,1,0.999253354069792,40.0298881530762,1.98418008978873,19.6899995207787,0.00021194174509561,3.63842644537891E-5,0.25,-3.46110059040193E-8,1.88529093574445E-5,-1.65835298109538E-8,223.9603119,223.9603119,99.4873580932617,99.4873580932617,57.068261446083,20.5345387663347,27.085165,0,0,0,40,4374,220.2699,99.4873580932617,,,,,,,,,,,,,0,,,,0.0049,,,,,,223.9603119,,,,
,31181275.765,220.4772797,99.4873580932617,1.84287172039435E-5,4.28962859340393E-7,1,0.999253354069792,40.0298881530762,1.98408091369967,19.6899995207787,0.000207702460157331,3.58677294132262E-5,0.25,-1.60657397422967E-8,1.84798427896536E-5,1.99700206160493E-9,220.4772797,220.4772797,99.4873580932617,99.4873580932617,57.1096877576022,20.5364221183257,27.085165,0,0,0,40,4374,216.79985,99.4873580932617,,,,,,,,,,,,,0,,,,0,,,,,,220.4772797,,,,
,31181415.08,216.9956055,99.4873580932617,1.91300475410408E-5,3.80867835360371E-7,1,0.999253354069792,40.0298881530762,1.98423081284085,19.7299998253584,0.000215924703228925,3.56435502531105E-5,0.25,-1.58672921622879E-7,1.9185499726372E-5,-1.39957274614878E-7,216.9956055,216.9956055,99.4873580932617,99.4873580932617,56.9510171681983,20.5325510875679,26.705515,0,0,0,40,4374,213.3176,99.4873580932617,,,,,,,,,,,,,0,,,,-0.00245,,,,,,216.9956055,,,,
,31181554.825,213.4936066,99.4873580932617,1.87097546737746E-5,3.59268419032416E-7,1,0.999253354069792,40.0298881530762,1.98398023103516,19.7299998253584,0.000211766551677232,3.14816771070508E-5,0.25,-4.55336293586864E-7,1.87664840667311E-5,-4.37566350472547E-7,213.4687653,213.5184479,99.4873580932617,99.4873580932617,56.8236117195637,20.539847673767,26.325863,0,0,0,40,4374,209.826,99.4873580932617,,,,,,,,,,,,,0,,,,-0.00245,,,,,,213.4936066,,,,
,31181694.735,209.9803772,99.4873580932617,1.88190061419744E-5,4.08948674173389E-7,1,0.999253354069792,40.0298881530762,1.98412636236435,19.7299998253584,0.000211598326312682,3.99903458141109E-5,0.25,2.79557629108595E-7,1.88774934570503E-5,3.00087245286464E-7,209.9803772,209.9803772,99.4873580932617,99.4873580932617,57.0620084179291,20.5371288592104,26.325863,0,0,0,40,4374,206.33395,99.4873580932617,,,,,,,,,,,,,0,,,,0,,,,,,209.9803772,,,,
,31181814.75,206.98532105,99.4873580932617,1.91077089712755E-5,3.46696796362799E-7,1,0.999253354069792,40.0298881530762,1.99571761334545,19.7700001299381,0.000216688788199407,3.72360296525573E-5,0.25,-3.39149904630988E-8,1.91693033269297E-5,-1.36965916554355E-8,206.9617615,207.0088806,99.4873580932617,99.4873580932617,56.8431524325445,20.5247427223045,26.705515,0,0,0,40,4374,203.32375,99.4873580932617,,,,,,,,,,,,,0,,,,0.0049,,,,,,206.98532105,,,,
,31181954.85,203.4723663,99.4873580932617,1.92753247513536E-5,3.43694682510528E-7,1,0.999253354069792,40.0298881530762,1.99548625186611,19.7700001299381,0.000219122325670779,3.44999861408434E-5,0.25,-3.04822983597778E-7,1.93399570527112E-5,-2.84882703804086E-7,203.4465637,203.4981689,99.4873580932617,99.4873580932617,57.1221938139099,20.5288269252968,26.705515,0,0,0,40,4374,199.8323,99.4873580932617,,,,,,,,,,,,,0,,,,-0.00245,,,,,,203.4723663,,,,
,31182094.565,199.9970703,99.4873580932617,1.84095438284429E-5,4.20220869150011E-7,1,0.999253354069792,40.0298881530762,1.99556205636506,19.7700001299381,0.000208842005308429,3.56556910351856E-5,0.25,-5.34144080661013E-8,1.84730755846186E-5,-3.31305324700374E-8,199.9970703,199.9970703,99.4873580932617,99.4873580932617,57.1128142716791,20.527524020725,26.705515,0,0,0,40,4374,196.33475,99.4873580932617,,,,,,,,,,,,,0,,,,0.00245,,,,,,199.9970703,,,,
touchdown = 14.9400001391768 mm,31182228.4,196.6300201,99.4873580932617,1.92393214630478E-5,3.99268548428407E-7,1,0.999253354069792,40.0298881530762,1.99576203456111,19.8199991136789,0.000219128985783645,3.24957513824543E-5,0.25,-4.77306021068943E-7,1.93082617470378E-5,-4.57137552146163E-7,196.6300201,196.6300201,99.4873580932617,99.4873580932617,56.8759808303522,20.5238249454516,26.705515,0,0,0,40,4374,192.983,99.4873580932617,,,,,,,,,,,,,0,,,,-0.0049,,,,,,196.6300201,,,,
,31182355.155,193.4544525,99.4873580932617,1.91877277316642E-5,3.55610115463306E-7,1,0.999253354069792,40.0298881530762,1.99560801762183,19.8199991136789,0.000217936904758745,3.59215664673936E-5,0.25,-1.66810331559148E-7,1.9258057034388E-5,-1.4514471720756E-7,193.4544525,193.4544525,99.4873580932617,99.4873580932617,56.9377294833714,20.5282176919369,26.705515,0,0,0,40,4374,189.8149,99.4873580932617,,,,,,,,,,,,,0,,,,0,,,,,,193.4544525,,,,
,31182494.975,189.98863985,99.4873580932617,1.90130919981834E-5,3.14685728329641E-7,1,0.999253354069792,40.0298881530762,1.99558207847111,19.8199991136789,0.000215031794177934,4.10192083682234E-5,0.25,3.12146286542589E-7,1.90842709566501E-5,3.35932233792916E-7,189.9612427,190.016037,99.4873580932617,99.4873580932617,57.1026531009291,20.5313820032421,26.705515,0,0,0,40,4374,186.31395,99.4873580932617,,,,,,,,,,,,,0,,,,-0.0049,,,,,,189.98863985,,,,
touchdown = 14.9900000542402 mm,31182644.6,186.2326508,99.4873580932617,1.92765464343324E-5,4.31354448268578E-7,1,0.999253354069792,40.0298881530762,1.98419532492713,19.8699999600649,0.000217774614858802,3.60364921473961E-5,0.25,-1.56529302740144E-7,1.93515056285498E-5,-1.33593345268974E-7,186.2326508,186.2326508,99.4873580932617,99.4873580932617,56.8329912617945,20.5340743988438,26.325863,0,0,0,40,4374,182.55935,99.4873580932617,,,,,,,,,,,,,0,,,,-0.00245,,,,,,186.2326508,,,,
,31182774.745,182.9821014,99.4873580932617,1.91002109913781E-5,3.77796523318458E-7,1,0.999253354069792,40.0298881530762,1.98397421967439,19.8699999600649,0.000214745871525308,4.16590012929556E-5,0.25,3.71986112404915E-7,1.91757127742924E-5,3.97351749012321E-7,182.9821014,182.9821014,99.4873580932617,99.4873580932617,57.3668435404292,20.5427398941105,26.325863,0,0,0,40,4374,179.31815,99.4873580932617,,,,,,,,,,,,,0,,,,0.0049,,,,,,182.9821014,,,,
,31182916.935,179.47246555,99.4873580932617,1.91841827301014E-5,3.41585549881021E-7,1,0.999253354069792,40.0298881530762,1.98382497195834,19.8699999600649,0.000216911597064776,3.48579010423445E-5,0.25,-2.4623221652013E-7,1.92628092756734E-5,-2.2258804856738E-7,179.4421387,179.5027924,99.4873580932617,99.4873580932617,57.0792042453522,20.5466605542008,26.705515,0,0,0,40,4374,175.71625,99.4873580932617,,,,,,,,,,,,,0,,,,0,,,,,,179.47246555,,,,
touchdown = 15.0399999693036 mm,31183059.715,175.8191376,99.4873580932617,1.94630392231888E-5,3.39359645986509E-7,1,0.999253354069792,40.0298881530762,1.98399628439344,19.9200008064508,0.00022005023023602,3.56943837153735E-5,0.25,-2.21867003822841E-7,1.95448752884417E-5,-1.97096183660353E-7,175.8191376,175.8191376,99.4873580932617,99.4873580932617,56.8032893780637,20.5365123436453,25.946213,0,0,0,40,4374,172.1921,99.4873580932617,,,,,,,,,,,,,0,,,,0,,,,,,175.8191376,,,,
,31183192.195,172.4816895,99.4873580932617,1.89441228014327E-5,3.65754597511604E-7,1,0.999253354069792,40.0298881530762,1.98429947901289,19.9200008064508,0.000214218309443088,3.48487445790146E-5,0.25,-2.07961541633548E-7,1.90256027856917E-5,-1.8317482537884E-7,172.4816895,172.4816895,99.4873580932617,99.4873580932617,57.0838940164676,20.5357543082109,26.705515,0,0,0,40,4374,168.9203,99.4873580932617,,,,,,,,,,,,,0,,,,0,,,,,,172.4816895,,,,
,31183332.195,168.9607239,99.4873580932617,1.93324603839205E-5,3.28410107434813E-7,1,0.999253354069792,40.0298881530762,1.98431139592325,19.9200008064508,0.000218857787320826,3.42733844577881E-5,0.25,-3.27577284311957E-7,1.94177122551925E-5,-3.02046280646585E-7,168.9607239,168.9607239,99.4873580932617,99.4873580932617,57.1565854687561,20.5367906035325,26.325863,0,0,0,40,4374,165.4389,99.4873580932617,,,,,,,,,,,,,0,,,,-0.0049,,,,,,168.9607239,,,,
touchdown = 15.1100000366569 mm,31183472.82,165.415802,99.4873580932617,1.94987691336562E-5,3.28568919969782E-7,1,0.999253354069792,40.0298881530762,1.99566060124855,19.9900008738041,0.000221720743963593,3.61802243914359E-5,0.25,-2.06123835187201E-7,1.95865120031499E-5,-1.79022808853603E-7,165.415802,165.415802,99.4873580932617,99.4873580932617,56.9392927404099,20.5248804272723,25.566563,0,0,0,40,4374,161.93165,99.4873580932617,,,,,,,,,,,,,0,,,,-0.00245,,,,,,165.415802,,,,
,31183611.36,161.9726715,99.4873580932617,1.94201595659515E-5,3.2318927241465E-7,1,0.999253354069792,40.0298881530762,1.99539300169372,19.9900008738041,0.000220857195796236,3.58153802749553E-5,0.25,-2.25334078048822E-7,1.95094039762637E-5,-1.97590794342389E-7,161.9726715,161.9726715,99.4873580932617,99.4873580932617,56.9510171681983,20.5275524528082,25.566563,0,0,0,40,4374,158.4811,99.4873580932617,,,,,,,,,,,,,0,,,,0,,,,,,161.9726715,,,,
,31183750.935,158.4827271,99.4873580932617,1.88061400196917E-5,3.88374411676676E-7,1,0.999253354069792,40.0298881530762,1.99538533379874,19.9900008738041,0.000213578284903187,3.64947967437307E-5,0.25,-5.97538692585183E-8,1.88940712485073E-5,-3.12657241667686E-8,158.4827271,158.4827271,99.4873580932617,99.4873580932617,56.9557069393137,20.5305955365556,25.946213,0,0,0,40,4374,154.9913,99.4873580932617,,,,,,,,,,,,,0,,,,0.00245,,,,,,158.4827271,,,,
touchdown = 15.1599999517202 mm,31183888.16,155.0527344,99.4873580932617,1.91377502660701E-5,3.84512088240604E-7,1,0.999253354069792,40.0298881530762,1.98424681445292,20.0399998575449,0.000216811142123159,3.34627386787045E-5,0.25,-3.70053384369233E-7,1.9229418360254E-5,-3.41574554164694E-7,155.0527344,155.0527344,99.4873580932617,99.4873580932617,57.0432493334676,20.5336865927067,26.325863,0,0,0,40,4374,151.5603,99.4873580932617,,,,,,,,,,,,,0,,,,0.00245,,,,,,155.0527344,,,,
,31184009.495,151.9983521,99.4873580932617,1.88069223311031E-5,3.75489436613128E-7,1,0.999253354069792,40.0298881530762,1.98402365622559,20.0399998575449,0.000212710407569956,3.48713151390998E-5,0.25,-1.88461550333284E-7,1.88981828401301E-5,-1.58765220754547E-7,151.9983521,151.9983521,99.4873580932617,99.4873580932617,57.1769078102561,20.5415266148332,25.566563,0,0,0,40,4374,148.5419,99.4873580932617,,,,,,,,,,,,,0,,,,0,,,,,,151.9983521,,,,
,31184148.58,148.4902191,99.4873580932617,1.9371742677753E-5,3.77699518639508E-7,1,0.999253354069792,40.0298881530762,1.98384189275869,20.0399998575449,0.000218550314091331,3.90622092517048E-5,0.25,8.31964688268482E-8,1.94669447899453E-5,1.16262245322817E-7,148.4902191,148.4902191,99.4873580932617,99.4873580932617,57.058100275333,20.5449625517572,25.186911,0,0,0,40,4374,145.0661,99.4873580932617,,,,,,,,,,,,,0,,,,-0.00245,,,,,,148.4902191,,,,
,31184289.2,144.9700928,99.4873580932617,,,2,,,,20.1100004085898,,,,,,,144.9700928,144.9700928,99.4873580932617,99.4873580932617,,,25.566563,,,,-99999999,4374,141.5785,99.4873580932617,,,,,,,,,,,,,,,,,,,,,,,144.9700928,,,,
,31184408.515,141.9778748,99.4873580932617,1.89508564337402E-5,3.56553811195563E-7,1,0.999253354069792,40.0298881530762,1.99524282404662,20.0999993830919,0.000215182238870024,3.74249804125569E-5,0.25,-9.30327901385925E-9,1.90469923670972E-5,2.48810513338393E-8,141.9778748,141.9778748,99.4873580932617,99.4873580932617,56.9752476522945,20.5345041567663,25.946213,0,0,0,40,4374,138.6052,99.4873580932617,,,,,,,,,,,,,0,,,,-0.0049,,,,,,141.9778748,,,,
,31184546.625,138.483551,99.4873580932617,1.92185799441481E-5,3.045105279262E-7,1,0.999253354069792,40.0298881530762,1.99532365315541,20.0999993830919,0.000218502344140475,3.64952067201931E-5,0.25,-1.39628507699692E-7,1.93177737141289E-5,-1.04255349712281E-7,138.4558258,138.5112762,99.4873580932617,99.4873580932617,57.0862389020253,20.5359285153372,25.566563,0,0,0,40,4374,135.16295,99.4873580932617,,,,,,,,,,,,,0,,,,-0.0049,,,,,,138.483551,,,,
,31184702.59,134.5629425,99.4873580932617,,,2,,,,20.1699999341369,,,,,,,134.5629425,134.5629425,99.4873580932617,99.4873580932617,,,25.566563,,,,-99999999,4374,131.2819,99.4873580932617,,,,,,,,,,,,,,,,,,,,,,,134.5629425,,,,
,31184824.315,131.4970245,99.4873580932617,1.91710601928283E-5,3.79058150246375E-7,1,0.999253354069792,40.0298881530762,1.99537464109689,20.1600007712841,0.000217899927286961,3.6971271393268E-5,0.25,-9.30297077729776E-8,1.92725962284693E-5,-5.44105271875091E-8,131.4970245,131.4970245,99.4873580932617,99.4873580932617,56.9439825115252,20.5323425613918,25.186911,0,0,0,40,4374,128.2596,99.4873580932617,,,,,,,,,,,,,0,,,,0,,,,,,131.4970245,,,,
,31184965.045,127.9720383,99.4873580932617,1.91885046525045E-5,3.81776733623705E-7,1,0.999253354069792,40.0298881530762,1.99528896297639,20.1600007712841,0.00021783548441639,3.85362238289273E-5,0.25,3.9877162004339E-8,1.92910569731575E-5,8.10261433651914E-8,127.9720383,127.9720383,99.4873580932617,99.4873580932617,56.9854088230445,20.5351721383714,25.566563,0,0,0,40,4374,124.755,99.4873580932617,,,,,,,,,,,,,0,,,,0,,,,,,127.9720383,,,,
,31185115.7,124.1796494,99.4873580932617,,,2,,,,20.2400000014901,,,,,,,124.1796494,124.1796494,99.4873580932617,99.4873580932617,,,24.807261,,,,-99999999,4374,121.0114,99.4873580932617,,,,,,,,,,,,,,,,,,,,,,,124.1796494,,,,
,31185242.365,120.9994125,99.4873580932617,1.92652347771904E-5,2.83006060532731E-7,1,0.999253354069792,40.0298881530762,1.99536081700352,20.2300008386374,0.000219253640857463,3.57440654105339E-5,0.25,-2.2385480500814E-7,1.93708510220268E-5,-1.79941682546801E-7,120.9994125,120.9994125,99.4873580932617,99.4873580932617,56.770460980256,20.5326392684037,24.427608,0,0,0,40,4374,117.8597,99.4873580932617,,,,,,,,,,,,,0,,,,0.00245,,,,,,120.9994125,,,,
,31185382.905,117.4734726,99.4873580932617,1.9121609627127E-5,3.68726231921547E-7,1,0.999253354069792,40.0298881530762,1.99538824927085,20.2300008386374,0.000217685312484638,3.51727527698148E-5,0.25,-2.51509460917873E-7,1.92273576039493E-5,-2.05774744940192E-7,117.4734726,117.4734726,99.4873580932617,99.4873580932617,57.1620568683907,20.5340201626235,24.807261,0,0,0,40,4374,114.3713,99.4873580932617,,,,,,,,,,,,,0,,,,0.0049,,,,,,117.4734726,,,,
,31185529.75,113.7524719,99.4873580932617,,,2,,,,20.3100000688434,,,,,,,113.7524719,113.7524719,99.4873580932617,99.4873580932617,,,24.427608,,,,-99999999,4374,110.7246,99.4873580932617,,,,,,,,,,,,,,,,,,,,,,,113.7524719,,,,
,31185659.555,110.4647064,99.4873580932617,1.89561617991112E-5,4.20849920289506E-7,1,0.999253354069792,40.0298881530762,1.99542375496665,20.3000009059906,0.000215492982694227,3.67303927482329E-5,0.25,-9.08453363907561E-8,1.90617454571026E-5,-3.94143227533787E-8,110.4647064,110.4647064,99.4873580932617,99.4873580932617,57.1182856713137,20.531765045372,24.427608,0,0,0,40,4374,107.5029,99.4873580932617,,,,,,,,,,,,,0,,,,0,,,,,,110.4647064,,,,
,31185796.665,106.9988632,99.4873580932617,1.87547624990456E-5,3.24091071330394E-7,1,0.999253354069792,40.0298881530762,1.99560733092328,20.3000009059906,0.000213218643979952,3.63806289798207E-5,0.25,-8.95863093745629E-8,1.88594713398776E-5,-3.57390836333408E-8,106.9725952,107.0251312,99.4873580932617,99.4873580932617,57.1839424669291,20.5329177631732,24.427608,0,0,0,40,4374,104.0985,99.4873580932617,,,,,,,,,,,,,0,,,,-0.00245,,,,,,106.9988632,,,,
,31185940.98,103.3735199,99.4873580932617,,,2,,,,20.3699995943904,,,,,,,103.3735199,103.3735199,99.4873580932617,99.4873580932617,,,24.047956,,,,-99999999,4374,100.5302,99.4873580932617,,,,,,,,,,,,,,,,,,,,,,,103.3735199,,,,
,31186055.92,100.4351883,99.4873580932617,1.91924910590913E-5,3.3203668585704E-7,1,0.999253354069792,40.0298881530762,1.99510920243102,20.3499998897314,0.000218382883902069,3.58408660917173E-5,0.25,-2.19754234285789E-7,1.9299784210337E-5,-1.58729448949683E-7,100.4351883,100.4351883,99.4873580932617,99.4873580932617,56.8322096332752,20.5355613276714,24.047956,0,0,0,40,4374,97.6615,99.4873580932617,,,,,,,,,,,,,0,,,,0,,,,,,100.4351883,,,,
,31186194.965,96.9496918,99.4873580932617,1.89636413350935E-5,3.57087503938056E-7,1,0.999253354069792,40.0298881530762,1.99490420745474,20.3499998897314,0.000215657463888377,3.59382733778407E-5,0.25,-1.74535895974373E-7,1.90688717639626E-5,-1.09946678608196E-7,96.9496918,96.9496918,99.4873580932617,99.4873580932617,56.7251265261406,20.5385346253574,24.047956,0,0,0,40,4374,94.22595,99.4873580932617,,,,,,,,,,,,,0,,,,-0.0049,,,,,,96.9496918,,,,
,31186332.375,93.4846878,99.4873580932617,1.89212414306451E-5,3.33817886394868E-7,1,0.999253354069792,40.0298881530762,1.99517405868641,20.3499998897314,0.000215430570280269,3.4502330862919E-5,0.25,-2.98185285151619E-7,1.9025614285626E-5,-2.29970997796287E-7,93.4846878,93.4846878,99.4873580932617,99.4873580932617,57.0252718775253,20.5362491484579,23.668306,0,0,0,40,4374,90.82725,99.4873580932617,,,,,,,,,,,,,0,,,,0,,,,,,93.4846878,,,,
,31186450.14,90.490448,99.4873580932617,1.91076813419264E-5,3.1211636364597E-7,1,0.999253354069792,40.0298881530762,1.98373252516639,20.4399991780519,0.000215880083969489,3.72927782813554E-5,0.25,-7.11921942082568E-8,1.92108420905789E-5,3.18819715519441E-9,90.490448,90.490448,99.4873580932617,99.4873580932617,57.065134932006,20.5510828702057,23.668306,0,0,0,40,4374,87.91055,99.4873580932617,,,,,,,,,,,,,0,,,,0,,,,,,90.490448,,,,
,31186589.425,86.9758606,99.4873580932617,1.90700179475632E-5,3.14634599104967E-7,1,0.999253354069792,40.0298881530762,1.98370134386117,20.4399991780519,0.000215630686595482,3.60566608306188E-5,0.25,-1.79063678032829E-7,1.91711450174679E-5,-9.99099042971252E-8,86.9758606,86.9758606,99.4873580932617,99.4873580932617,57.095618444256,20.5530256103317,22.909004,0,0,0,40,4374,84.47455,99.4873580932617,,,,,,,,,,,,,0,,,,0,,,,,,86.9758606,,,,
,31186727.1,83.4644165,99.4873580932617,1.95832573235779E-5,3.10627632522604E-7,1,0.999253354069792,40.0298881530762,1.98369005552249,20.4399991780519,0.0002220316438394,3.34438486484177E-5,0.25,-5.06981138918773E-7,1.96854172147157E-5,-4.2115218568471E-7,83.4644165,83.4644165,99.4873580932617,99.4873580932617,57.2073913225061,20.5488014206657,22.909004,0,0,0,40,4374,81.0704,99.4873580932617,,,,,,,,,,,,,0,,,,-0.00245,,,,,,83.4644165,,,,
,31186864.07,79.9925804,99.4873580932617,1.94379615160937E-5,3.25435636562345E-7,1,0.999253354069792,40.0298881530762,1.9950439221496,20.5000005662441,0.000220820721867257,3.74386907917287E-5,0.25,-1.51248018905188E-7,1.95336045869449E-5,-5.75682987061924E-8,79.9681091,80.0170517,99.4873580932617,99.4873580932617,57.3394865422561,20.5389690078592,23.288654,0,0,0,40,4374,77.69295,99.4873580932617,,,,,,,,,,,,,0,,,,-0.00245,,,,,,79.9925804,,,,
,31187003.295,76.4366684,99.4873580932617,1.9288150413647E-5,3.38790922411719E-7,1,0.999253354069792,40.0298881530762,1.99517273042961,20.5000005662441,0.000219331798952198,3.56749094022505E-5,0.25,-2.86685696342039E-7,1.93782852579068E-5,-1.87060252886815E-7,76.4366684,76.4366684,99.4873580932617,99.4873580932617,56.9885353371214,20.5359033538825,22.909004,0,0,0,40,4374,74.2787,99.4873580932617,,,,,,,,,,,,,0,,,,-0.00245,,,,,,76.4366684,,,,
,31187140.05,72.9501038,99.4873580932617,1.93363990563126E-5,2.88008555060569E-7,1,0.999253354069792,40.0298881530762,1.99526069959756,20.5000005662441,0.000219291665453325,3.86667244748963E-5,0.25,-3.80265635509429E-8,1.94183908809125E-5,7.06460257480636E-8,72.9501038,72.9501038,99.4873580932617,99.4873580932617,56.9869720800829,20.5437579012019,22.529354,0,0,0,40,4374,70.9157,99.4873580932617,,,,,,,,,,,,,0,,,,-0.0049,,,,,,72.9501038,,,,
,31187277.3,69.4755478,99.4873580932617,1.91877013717584E-5,3.02829041753746E-7,1,0.999253354069792,40.0298881530762,1.98401210804135,20.5700006335974,0.000216494649042988,3.72476321194995E-5,0.25,-1.25266730263691E-7,1.92606817457307E-5,-9.8765209412054E-9,69.4755478,69.4755478,99.4873580932617,99.4873580932617,57.0620084179291,20.545561447101,22.529354,0,0,0,40,4374,67.55225,99.4873580932617,,,,,,,,,,,,,0,,,,0,,,,,,69.4755478,,,,
,31187413.545,65.9745865,99.4873580932617,1.92482130474585E-5,3.31835358796439E-7,1,0.999253354069792,40.0298881530762,1.98379487038457,20.5700006335974,0.000217728582885825,3.34474468952025E-5,0.25,-4.79171314090957E-7,1.93126508931725E-5,-3.56651411711231E-7,65.9745865,65.9745865,99.4873580932617,99.4873580932617,56.8806706014676,20.5493929628726,22.529354,0,0,0,40,4374,64.203,99.4873580932617,,,,,,,,,,,,,0,,,,0,,,,,,65.9745865,,,,
,31187550.985,62.472971,99.4873580932617,1.90960368622156E-5,3.25422627878842E-7,1,0.999253354069792,40.0298881530762,1.98348080262255,20.5700006335974,0.000215071730483877,3.73502793815553E-5,0.25,-1.098463429944E-7,1.91441685018404E-5,2.02142347643478E-8,62.4452019,62.5007401,99.4873580932617,99.4873580932617,57.098744958333,20.556004512998,21.770052,0,0,0,40,4374,60.8395,99.4873580932617,,,,,,,,,,,,,0,,,,-0.0049,,,,,,62.472971,,,,
,31187688.585,58.9480171,99.4873580932617,1.92654610964627E-5,2.74285844257441E-7,1,0.999253354069792,40.0298881530762,1.99479879890194,20.6300001591444,0.000217653076551843,3.96749502030635E-5,0.25,4.39067812837157E-8,1.92967944661529E-5,1.816296218056E-7,58.9480171,58.9480171,99.4873580932617,99.4873580932617,56.8329912617945,20.5428281241015,21.3904,0,0,0,40,4374,57.4623,99.4873580932617,,,,,,,,,,,,,0,,,,0,,,,,,58.9480171,,,,
,31187824.325,55.4839439,99.4873580932617,1.90649411903425E-5,3.69937145425939E-7,1,0.999253354069792,40.0298881530762,1.99483910967505,20.6300001591444,0.000215328830685579,3.84552374574096E-5,0.25,-2.90386861822306E-8,1.90785540920312E-5,1.11264936502928E-7,55.4839439,55.4839439,99.4873580932617,99.4873580932617,56.9103724851983,20.5478296349289,21.3904,0,0,0,40,4374,54.1334,99.4873580932617,,,,,,,,,,,,,0,,,,-0.00245,,,,,,55.4839439,,,,
,31187959.63,51.99412155,99.4873580932617,1.9446418265417E-5,2.82513726794071E-7,1,0.999253354069792,40.0298881530762,1.99434304678177,20.6300001591444,0.000219185036969121,4.01774932106493E-5,0.25,5.7453775180153E-8,1.9440167723513E-5,2.02144830907118E-7,51.9664688,52.0217743,99.4873580932617,99.4873580932617,56.8337728903137,20.5557265515008,20.631098,0,0,0,40,4374,50.8515,99.4873580932617,,,,,,,,,,,,,0,,,,0,,,,,,51.99412155,,,,
,31188094.865,48.4911385,99.4873580932617,1.96401566957213E-5,3.2295262714942E-7,1,0.999253354069792,40.0298881530762,1.99441620309618,20.7000002264977,0.000221620178274722,3.79273139129012E-5,0.25,-1.72472470703064E-7,1.96154520553732E-5,-2.74396462918588E-8,48.4911385,48.4911385,99.4873580932617,99.4873580932617,56.953362053756,20.5596530512843,19.112494,0,0,0,40,4374,47.58105,99.4873580932617,,,,,,,,,,,,,0,,,,0,,,,,,48.4911385,,,,
,31188231.9,44.9611626,99.4873580932617,1.93680794162543E-5,3.51685378245553E-7,1,0.999253354069792,40.0298881530762,1.99413277993027,20.7000002264977,0.000217450642872959,4.2073400443222E-5,0.25,2.52968968347252E-7,1.93211302999179E-5,3.90914705903136E-7,44.9611626,44.9611626,99.4873580932617,99.4873580932617,56.9134989992753,20.5616904486656,17.593889,0,0,0,40,4370,44.2417,99.4873580932617,,,,,,,,,,,,,0,,,,0,,,,,,44.9611626,,,,
,31188368.97,41.4497452,99.4873580932617,1.92794894605808E-5,3.58658330963852E-7,1,0.999253354069792,40.0298881530762,1.99418080180758,20.7000002264977,0.000216653524166475,3.9662909922852E-5,0.25,6.4447742167605E-8,1.92163827317355E-5,1.95479627161725E-7,41.4497452,41.4497452,99.4873580932617,99.4873580932617,57.1487691835637,20.5629306136922,17.214239,0,0,0,40,4370,40.8691,99.4873580932617,,,,,,,,,,,,,0,,,,-0.00245,,,,,,41.4497452,,,,
,31188487.685,38.4573975,99.4873580932617,1.93604293017052E-5,3.39501030145754E-7,1,0.999253354069792,40.0298881530762,1.9945992088323,20.7599997520447,0.000218352992099947,3.48146224453001E-5,0.25,-3.72851408581644E-7,1.92867005273398E-5,-2.4654344674063E-7,38.4573975,38.4573975,99.4873580932617,99.4873580932617,56.9486722826406,20.5528300912143,16.834587,0,0,0,40,4370,37.9537,99.4873580932617,,,,,,,,,,,,,0,,,,0.0049,,,,,,38.4573975,,,,
,31188625.075,34.9646912,99.4873580932617,1.9470798745196E-5,2.91237128983384E-7,1,0.999253354069792,40.0298881530762,1.99471503509324,20.7599997520447,0.000218913094739456,3.80797322792394E-5,0.25,-9.16204053236263E-8,1.93822125548839E-5,2.58236659678616E-8,34.9646912,34.9646912,99.4873580932617,99.4873580932617,56.9346029692945,20.552593826199,16.454937,0,0,0,40,4370,34.54565,99.4873580932617,,,,,,,,,,,,,0,,,,0,,,,,,34.9646912,,,,
,31188763.08,31.49593355,99.4873580932617,1.924137151266E-5,3.31256131129301E-7,1,0.999253354069792,40.0298881530762,1.99475725488446,20.7599997520447,0.00021601507670219,3.88276489012996E-5,0.25,2.54277340066423E-8,1.91438128887775E-5,1.33100573112379E-7,31.4675293,31.5243378,99.4873580932617,99.4873580932617,57.027616763083,20.5501809406109,16.454937,0,0,0,40,4370,31.13295,99.4873580932617,,,,,,,,,,,,,0,,,,-0.00245,,,,,,31.49593355,,,,
,31188882.385,28.4550152,99.4873580932617,1.9072743469347E-5,2.48539938279301E-7,1,0.999253354069792,40.0298881530762,1.99470777022131,20.7899995148182,0.000214359366797461,3.67479009133799E-5,0.25,-1.22952628972805E-7,1.89710924640826E-5,-2.11063458558371E-8,28.4550152,28.4550152,99.4873580932617,99.4873580932617,57.0393411908714,20.5542610046156,14.936333,0,0,0,40,4370,28.1814,99.4873580932617,,,,,,,,,,,,,0,,,,0,,,,,,28.4550152,,,,
,31189020.205,24.9879026,99.4873580932617,1.95298818036503E-5,2.85942441868793E-7,1,0.999253354069792,40.0298881530762,1.99431945747208,20.7899995148182,0.000219378504073602,3.77588455784033E-5,0.25,-1.07800702383242E-7,1.94211345606134E-5,-8.66478615928709E-9,24.9600906,25.0157146,99.4873580932617,99.4873580932617,56.821266834006,20.563779124905,14.936333,0,0,0,40,4370,24.7574,99.4873580932617,,,,,,,,,,,,,0,,,,0,,,,,,24.9879026,,,,
,31189160.5,21.48360825,99.4873580932617,1.93528984624827E-5,3.48014076716248E-7,1,0.999253354069792,40.0298881530762,1.99434283478568,20.7899995148182,0.000217280296706464,3.7885685127278E-5,0.25,-6.14770255705979E-8,1.92424093953411E-5,3.33712030962723E-8,21.4575176,21.5096989,99.4873580932617,99.4873580932617,57.1769078102561,20.5621371919666,14.177031,0,0,0,40,4370,21.2782,99.4873580932617,,,,,,,,,,,,,0,,,,0,,,,,,21.48360825,,,,
,31189299.03,17.9647713,99.4873580932617,1.94487878057037E-5,3.57215654052846E-7,1,0.999253354069792,40.0298881530762,1.98304002827552,20.8299998193979,0.000217173953181312,3.78228485532291E-5,0.25,-6.44312553523889E-8,1.93370017317665E-5,2.97075555209934E-8,17.9647713,17.9647713,99.4873580932617,99.4873580932617,57.004167907506,20.568183719049,13.417728,0,0,0,40,4370,17.8331,99.4873580932617,,,,,,,,,,,,,0,,,,-0.0049,,,,,,17.9647713,,,,
,31189438.105,14.4815788,99.4873580932617,1.93905572284358E-5,3.82420734742527E-7,1,0.999253354069792,40.0298881530762,1.98268092059563,20.8299998193979,0.000216628447251443,3.69176926465586E-5,0.25,-1.34695563880475E-7,1.92796800671369E-5,-4.04044559970192E-8,14.4815788,14.4815788,99.4873580932617,99.4873580932617,56.9471090256022,20.5698370138551,12.658426,0,0,0,40,4370,14.3736,99.4873580932617,,,,,,,,,,,,,0,,,,0,,,,,,14.4815788,,,,
,31189578.645,10.9593716,99.4873580932617,1.95841045805139E-5,3.42783758347032E-7,1,0.999253354069792,40.0298881530762,1.9830351286815,20.8299998193979,0.000218682744714777,3.81209961642707E-5,0.25,-6.18336248474531E-8,1.94719170838751E-5,3.297210769445E-8,10.9593716,10.9593716,99.4873580932617,99.4873580932617,56.8775440873906,20.5678652794309,12.278775,0,0,0,40,4370,10.8662,99.4873580932617,,,,,,,,,,,,,0,,,,0,,,,,,10.9593716,,,,
,31189750.405,10.00328255,99.4873580932617,1.89281329193452E-5,3.31157760596601E-7,1,0.999253354069792,40.0298881530762,1.982948558723,20.8500009030104,0.000210939527040689,3.91511917710988E-5,0.25,1.4710267720908E-7,1.88187357646275E-5,2.37545087261099E-7,10.0031776,10.0033875,99.4873580932617,99.4873580932617,57.0674798175637,20.5675327987762,12.278775,0,0,0,40,4369,9.99605,99.4873580932617,,,,,,,,,,,,,0,,,,0,,,,,,10.00328255,,,,