File: data/monolayers/nanoparticles/Ol_CoFe_C/vsm/data_dispersion/DD67_HYST_300K_INIT.DAT
[Header]
; VSM Data File (default extension .dat)
; Copyright (c) 2003-2013, Quantum Design, Inc. All rights reserved.
TITLE,
FILEOPENTIME,28116559.28,11/22/2018,6:09 pm
BYAPP,VSM,2.0,2.0
INFO,PPMS VSM Option Release 1.4.10 Build 1,APPNAME
INFO,Quantum Design Linear Motor Servo Controller,MOTOR_MODULE_NAME
INFO,3101-100 M1,MOTOR_HW_VERSION
INFO,MMC1014,MOTOR_SERIAL_NUMBER
INFO,SRV No X-over 01.03.11,MOTOR_SOFTWARE_VERSION
INFO,Quantum Design VSM Detection Module,VSM_MODULE_NAME
INFO,3101-150 F0,VSM_HW_VERSION
INFO,VSM707,VSM_SERIAL_NUMBER
INFO,VSM No X-over 01.02.05 May 20 2008 13:51:47,VSM_SOFTWARE_VERSION
INFO,704,PREAMP_SERIAL_NUMBER
INFO,822,COIL_SERIAL_NUMBER
INFO,0,MOMENT_UNITS
INFO,CoFe2O4,SAMPLE_MATERIAL
INFO,dispersion in ampulle,SAMPLE_COMMENT
INFO,,SAMPLE_MASS
INFO,,SAMPLE_VOLUME
INFO,,SAMPLE_MOLECULAR_WEIGHT
INFO,,SAMPLE_SIZE
INFO,,SAMPLE_SHAPE
DATATYPE,COMMENT,1
DATATYPE,TIME,2
STARTUPAXIS,X,2
STARTUPAXIS,Y1,5
[Data]
Comment,Time Stamp (sec),Temperature (K),Magnetic Field (Oe),Moment (emu),M. Std. Err. (emu),Transport Action,Averaging Time (sec),Frequency (Hz),Peak Amplitude (mm),Center Position (mm),Coil Signal' (mV),Coil Signal" (mV),Range (mV),M. Quad. Signal (emu),M. Raw' (emu),M. Raw" (emu),Min. Temperature (K),Max. Temperature (K),Min. Field (Oe),Max. Field (Oe),Mass (grams),Motor Lag (deg),Pressure (Torr),VSM Status (code),Motor Status (code),Measure Status (code),Measure Count,PPMS Status (code),System Temp. (K),System Field (Oe),Sample Position (deg),Bridge 1 Resistance (ohms),Bridge 1 Excitation (에),Bridge 2 Resistance (ohms),Bridge 2 Excitation (에),Bridge 3 Resistance (ohms),Bridge 3 Excitation (에),Bridge 4 Resistance (ohms),Bridge 4 Excitation (에),Signal 1 Vin (V),Signal 2 Vin (V),Digital Inputs (code),Drive 1 Iout (mA),Drive 1 Ipower (W),Drive 2 Iout (mA),Drive 2 Ipower (W),Pressure (),Map 20 (),Map 21 (),Map 22 (),Map 23 (),Map 24 (),Map 25 (),Map 26 (),Map 27 (),Map 28 (),Map 29 ()
,28116585.56,300.0786133,0.258804142475128,,,2,,,,27.3199999135733,,,,,,,300.0786133,300.0786133,0.258804142475128,0.258804142475128,,,26.705515,,,,-99999999,4369,300.2758,0.258804142475128,,,,,,,,,,,,,,,,,,,,,,,300.0786133,,,,
,28116724.32,300.0475464,4211.66333007812,0.00469931435828732,0.00022863690958099,1,0.999253354069792,40.0298881530762,1.9713953392073,27.3100007325411,0.0472573193009107,0.0392840865556877,0.25,0.00270294793153025,0.00469737392415098,0.00270597881883347,300.0475464,300.0475464,4206.587890625,4216.73876953125,56.5445703381983,20.4952415701103,26.705515,0,0,0,40,4449,300.2308,4211.66333007812,,,,,,,,,,,,,0,,,,0,,,,,,300.0475464,,,,
,28116814.09,300.035675,8697.05908203125,0.00641233621082355,0.00029309254968398,1,0.999253354069792,40.0298881530762,1.97152600536371,27.3100007325411,0.0645195035426241,0.0534255811561244,0.25,0.00367195166301974,0.00640970372258105,0.00367608696592404,300.035675,300.035675,8687.056640625,8707.0615234375,56.536754053006,20.5005813061092,26.705515,0,0,0,40,4449,300.20835,8697.05908203125,,,,,,,,,,,,,0,,,,-0.00245,,,,,,300.035675,,,,
,28116907.025,300.0221558,13340.4208984375,0.00823726521469071,0.000408197416791962,1,0.999253354069792,40.0298881530762,1.97056583133409,27.3100007325411,0.0826616746049926,0.0696449723757261,0.25,0.00481071954788231,0.00823382821898214,0.00481602721761293,300.0221558,300.0221558,13335.3056640625,13345.5361328125,57.0369963053137,20.5124799712334,27.085165,0,0,0,40,4449,300.19475,13340.4208984375,,,,,,,,,,,,,0,,,,0.00245,,,,,,300.0221558,,,,
,28117002.405,300.0196533,18105.5654296875,0.0089210412965926,0.000427991136886367,1,0.999253354069792,40.0298881530762,1.97188678033303,27.3100007325411,0.0892572983387846,0.0774190285012999,2.5,0.00538321070568704,0.00891720870876826,0.00538894929585984,300.0196533,300.0196533,18103.193359375,18107.9375,57.0510656186599,20.4985015888713,27.085165,0,0,0,40,4449,300.1872,18105.5654296875,,,,,,,,,,,,,0,,,,0,,,,,,300.0196533,,,,
,28117096.845,300.0187073,22828.1435546875,0.0102901515669711,0.000500397381921845,1,0.999253354069792,40.0298881530762,1.97291255501778,27.3100007325411,0.10364364572402,0.0856695428423923,2.5,0.00588059925520396,0.0102859525838357,0.00588722310282138,300.0187073,300.0187073,22820.6171875,22835.669921875,56.9916618511983,20.4872577760289,26.705515,0,0,0,40,4449,300.1697,22828.1435546875,,,,,,,,,,,,,0,,,,0.0049,,,,,,300.0187073,,,,
,28117190.665,300.019165,27516.0859375,0.0108237575592324,0.00060713836409972,1,0.999253354069792,40.0298881530762,1.9729556489554,27.3100007325411,0.109388665189081,0.0879890162036381,2.5,0.0059954743458087,0.0108194704780608,0.00600244116550846,300.019165,300.019165,27513.568359375,27518.603515625,57.281646031833,20.4884014974627,27.085165,0,0,0,40,4449,300.15325,27516.0859375,,,,,,,,,,,,,0,,,,0,,,,,,300.019165,,,,
,28117285.055,300.01290895,32233.740234375,0.0115050897128721,0.000361202734657222,1,0.999253354069792,40.0298881530762,1.97302780169339,27.3100007325411,0.113867677914857,0.107446341126226,2.5,0.00761758719787829,0.0114997190297898,0.00762494946637908,300.0124817,300.0133362,32226.224609375,32241.255859375,57.2566339192176,20.4876001118075,27.085165,0,0,0,40,4449,300.1501,32233.740234375,,,,,,,,,,,,,0,,,,0.00245,,,,,,300.01290895,,,,
,28117378.08,300.0196533,36883.58984375,0.0119920319901081,0.000554852802339485,1,0.999253354069792,40.0298881530762,1.97295374684473,27.3100007325411,0.122194867148549,0.0917188663839024,2.5,0.00612672543949489,0.0119876323136871,0.00613444440238227,300.0196533,300.0196533,36873.4453125,36893.734375,57.0799858738714,20.4883426802414,26.705515,0,0,0,40,4449,300.15115,36883.58984375,,,,,,,,,,,,,0,,,,0,,,,,,300.0196533,,,,
,28117470.695,300.0109558,41513.849609375,0.0122447291558103,0.000576266312819746,1,0.999253354069792,40.0298881530762,1.9729963270779,27.3100007325411,0.12317734250789,0.102860147192163,2.5,0.00707936460587253,0.0122397027839923,0.00708721654415857,300.0109558,300.0109558,41511.26171875,41516.4375,57.068261446083,20.4880617326413,26.705515,0,0,0,40,4449,300.1193,41513.849609375,,,,,,,,,,,,,0,,,,0.00245,,,,,,300.0109558,,,,
,28117564.41,300.0137329,46196.998046875,0.0118978423841816,0.000552298370361692,1,0.999253354069792,40.0298881530762,1.97308062261317,27.3100007325411,0.119126632805947,0.10321770254797,2.5,0.00717107832706732,0.0118927704821078,0.0071786905914815,300.0137329,300.0137329,46189.51953125,46204.4765625,57.0596635323714,20.4876700110519,26.705515,0,0,0,40,4449,300.1121,46196.998046875,,,,,,,,,,,,,0,,,,0.00245,,,,,,300.0137329,,,,
,28117659.69,300.0212708,50959.390625,0.0136671143866451,0.000721596870033855,1,0.999253354069792,40.0298881530762,1.97355298856157,27.3100007325411,0.139098839941544,0.105745094706243,2.5,0.00708845618291197,0.0136620460929367,0.00709722378473568,300.0212708,300.0212708,50956.97265625,50961.80859375,57.1300100991022,20.4785894656451,26.705515,0,0,0,40,4449,300.09365,50959.390625,,,,,,,,,,,,,0,,,,0,,,,,,300.0212708,,,,
,28117752.525,300.0159302,55597.001953125,0.0141157317385416,0.000656833529539461,1,0.999253354069792,40.0298881530762,1.97304558825263,27.3100007325411,0.143112051818331,0.112175884812473,2.5,0.007588282652674,0.0141103305014872,0.00759732197751399,300.0159302,300.0159302,55589.67578125,55604.328125,57.3183825722368,20.48834947817,26.705515,0,0,0,40,4449,300.0846,55597.001953125,,,,,,,,,,,,,0,,,,-0.0049,,,,,,300.0159302,,,,
,28117847.745,300.0095825,60357.203125,0.0138082970301508,0.000786024126898786,1,0.999253354069792,40.0298881530762,1.97305769097964,27.3100007325411,0.137769886049871,0.122582740698225,2.5,0.00857235730379529,0.0138022694612339,0.0085811577750441,300.0095825,300.0095825,60352.421875,60361.984375,57.3035316303714,20.4871834236369,26.325863,0,0,0,40,4449,300.0781,60357.203125,,,,,,,,,,,,,0,,,,0,,,,,,300.0095825,,,,
,28117944.22,300.0160828,65180.431640625,0.0138545821012895,0.000677316572568478,1,0.999253354069792,40.0298881530762,1.97306797898266,27.3100007325411,0.138022487281915,0.124205995649212,2.5,0.00870948952320074,0.013848467479111,0.00871830445500048,300.0160828,300.0160828,65175.61328125,65185.25,57.3004051162945,20.4887643227669,27.085165,0,0,0,40,4449,300.0657,65180.431640625,,,,,,,,,,,,,0,,,,0,,,,,,300.0160828,,,,
,28118037.995,300.0174866,69868.17578125,0.0153959753858042,0.000741665294987993,1,0.999253354069792,40.0298881530762,1.97330766187774,27.3100007325411,0.154090986684203,0.134029644213122,2.5,0.00931975112954977,0.0153894220555449,0.00932954680501603,300.0174866,300.0174866,69863.25,69873.1015625,56.983845566006,20.4845455396191,26.705515,0,0,0,40,4449,300.0368,69868.17578125,,,,,,,,,,,,,0,,,,-0.0049,,,,,,300.0174866,,,,
,28118131.32,300.01153565,74533.30859375,0.014633831313513,0.000853961211178324,1,0.999253354069792,40.0298881530762,1.97324070649702,27.3100007325411,0.145046867555272,0.135538207722572,2.5,0.00958711335971564,0.0146271373974815,0.00959639368288192,300.0114136,300.0116577,74530.5,74536.1171875,57.3676251689484,20.4879858856935,27.085165,0,0,0,40,4449,300.0432,74533.30859375,,,,,,,,,,,,,0,,,,0.0049,,,,,,300.01153565,,,,
,28118224.75,300.0124512,79201.36328125,0.014751429015313,0.000932488683360942,1,0.999253354069792,40.0298881530762,1.97319293712555,27.3100007325411,0.147204795642868,0.130877448477182,2.5,0.00915016573168637,0.0147450245083024,0.00915952496793864,300.0124512,300.0124512,79193.78125,79208.9453125,57.1409528983714,20.4887535934521,27.464817,0,0,0,40,4449,300.03045,79201.36328125,,,,,,,,,,,,,0,,,,0.00245,,,,,,300.0124512,,,,
,28118317.47,300.0101624,83835.07421875,0.0158561578799741,0.000777326178796233,1,0.999253354069792,40.0298881530762,1.97344820228997,27.3100007325411,0.160026664548622,0.130433064603527,2.5,0.00891759317176825,0.015849882198229,0.00892766910173899,300.0101624,300.0101624,83832.375,83837.7734375,57.3957637956407,20.4837878569024,27.464817,0,0,0,40,4449,300.032,83835.07421875,,,,,,,,,,,,,0,,,,-0.0049,,,,,,300.0101624,,,,
,28118407.375,300.0091095,88330.8359375,0.0173150281191112,0.0008759489816823,1,0.999253354069792,40.0298881530762,1.97304187104877,27.3100007325411,0.175606456991412,0.137265149707311,2.5,0.00927826814025874,0.0173084834154401,0.00928927268594873,300.0090637,300.0091553,88325.7578125,88335.9140625,56.8658196596022,20.490058349878,27.464817,0,0,0,40,4449,300.0212,88330.8359375,,,,,,,,,,,,,0,,,,-0.00245,,,,,,300.0091095,,,,
,28118514.54,300.0145874,87263.00390625,0.0161307919701379,0.000675252285722212,1,0.999253354069792,40.0298881530762,1.97289483606134,27.3100007325411,0.160924584335727,0.143220610778752,2.5,0.0100170485327636,0.0161237948647613,0.0100272620254112,300.0145874,300.0145874,87258.109375,87267.8984375,57.2058280654676,20.4914193556119,27.085165,0,0,0,40,4449,300.00295,87263.00390625,,,,,,,,,,,,,0,,,,-0.00245,,,,,,300.0145874,,,,
,28118606.335,300.0068512,82676.9921875,0.0151750659580196,0.000823213064781292,1,0.999253354069792,40.0298881530762,1.97295354541382,27.3100007325411,0.15040583910216,0.140444276696742,2.5,0.00993390103114591,0.0151681466701697,0.00994350804089274,300.0063477,300.0073547,82669.390625,82684.59375,57.2144259791791,20.4916599334017,27.085165,0,0,0,40,4449,300.01205,82676.9921875,,,,,,,,,,,,,0,,,,-0.0049,,,,,,300.0068512,,,,
,28118700.12,299.9992676,77985.7421875,0.0148228740631878,0.000973285871958806,1,0.999253354069792,40.0298881530762,1.97276565298396,27.3100007325411,0.148565587841639,0.127568259023882,2.5,0.00884416446113838,0.0148166716660371,0.00885358698270384,299.9992676,299.9992676,77975.7265625,77995.7578125,57.0080760501022,20.4950576898336,27.085165,0,0,0,40,4449,300.013,77985.7421875,,,,,,,,,,,,,0,,,,-0.0049,,,,,,299.9992676,,,,
,28118796.25,299.994751,73181.8671875,0.0152690340376091,0.000778174583664018,1,0.999253354069792,40.0298881530762,1.97284241524486,27.3100007325411,0.152693518918689,0.13342981575491,2.5,0.00929078458307977,0.0152625211970071,0.00930049846393898,299.994751,299.994751,73171.640625,73192.09375,57.1651833824676,20.4947824946175,27.085165,0,0,0,40,4449,300.0171,73181.8671875,,,,,,,,,,,,,0,,,,0,,,,,,299.994751,,,,
,28118888.84,299.9944153,68551.16015625,0.0158255951456995,0.000673792235527976,1,0.999253354069792,40.0298881530762,1.97280570295426,27.3100007325411,0.15986986308731,0.128977685879903,2.5,0.00879628447539737,0.0158193822520895,0.00880638754183184,299.9944153,299.9944153,68538.578125,68563.7421875,57.0393411908714,20.4926418108405,27.464817,0,0,0,40,4449,300.0301,68551.16015625,,,,,,,,,,,,,0,,,,0,,,,,,299.9944153,,,,
,28118982.705,299.9888916,63860.818359375,0.0148755254627402,0.00072628153275596,1,0.999253354069792,40.0298881530762,1.97307053758809,27.3100007325411,0.15069797668637,0.118904172459404,2.5,0.00805835240819889,0.0148698189724475,0.00806786696677028,299.9888916,299.9888916,63855.84375,63865.79296875,57.2558522906984,20.4903773609632,27.085165,0,0,0,40,4449,300.0438,63860.818359375,,,,,,,,,,,,,0,,,,-0.00245,,,,,,299.9888916,,,,
,28119077.6,299.98635865,59117.423828125,0.0142450843617199,0.000597665748785933,1,0.999253354069792,40.0298881530762,1.97293836773876,27.3100007325411,0.14312859631243,0.120629963308558,2.5,0.00832262442139184,0.0142392169105756,0.00833172926565135,299.9860535,299.9866638,59112.44140625,59122.40625,57.5341120435445,20.4898178523087,27.085165,0,0,0,40,4449,300.0493,59117.423828125,,,,,,,,,,,,,0,,,,-0.0049,,,,,,299.98635865,,,,
,28119172.625,299.9892883,54367.03125,0.0138663977532984,0.000563142430914397,1,0.999253354069792,40.0298881530762,1.97301028798527,27.3100007325411,0.13883819999839,0.120257071799048,2.5,0.00835449442498897,0.0138605116397498,0.00836335888558553,299.9892883,299.9892883,54359.57421875,54374.48828125,57.2347483206791,20.4899280428833,26.705515,0,0,0,40,4449,300.0532,54367.03125,,,,,,,,,,,,,0,,,,0.00245,,,,,,299.9892883,,,,
,28119266.415,299.99168395,49679.705078125,0.0135833159491844,0.000691070894242966,1,0.999253354069792,40.0298881530762,1.97281589214345,27.3100007325411,0.13713208929565,0.111204249810762,2.5,0.0075947019619182,0.0135779293983974,0.00760341112075936,299.991394,299.9919739,49672.2265625,49687.18359375,57.3004051162945,20.4898534518312,27.085165,0,0,0,40,4449,300.0583,49679.705078125,,,,,,,,,,,,,0,,,,0,,,,,,299.99168395,,,,
,28119360.24,299.9888458,44991.609375,0.0112454058466348,0.00076331961987111,1,0.999253354069792,40.0298881530762,1.97276128442539,27.3100007325411,0.110829448819401,0.107627995205891,2.5,0.00768007822918777,0.0112400260691154,0.00768725615407406,299.9885864,299.9891052,44983.99609375,44999.22265625,57.4575124486599,20.4930370992591,27.464817,0,0,0,40,4449,300.0686,44991.609375,,,,,,,,,,,,,0,,,,0.00245,,,,,,299.9888458,,,,
,28119454.155,299.9815674,40296.361328125,0.0128179340737028,0.000580391796177711,1,0.999253354069792,40.0298881530762,1.97266458167973,27.3100007325411,0.129206064483834,0.106023957977184,2.5,0.0072645682046553,0.0128127797433137,0.00727280329836918,299.9815674,299.9815674,40286.25390625,40306.46875,57.3074397729676,20.4941164215227,27.464817,0,0,0,40,4449,300.07695,40296.361328125,,,,,,,,,,,,,0,,,,-0.0049,,,,,,299.9815674,,,,
,28119547.675,299.9800873,35623.728515625,0.0113632123709616,0.000526999141579519,1,0.999253354069792,40.0298881530762,1.97259047862122,27.3100007325411,0.114788347631784,0.0925437854004972,2.5,0.00631090530048138,0.0113587241664127,0.00631821655628937,299.9796753,299.9804993,35618.75390625,35628.703125,57.2261504069676,20.4956861017955,27.085165,0,0,0,40,4449,300.1041,35623.728515625,,,,,,,,,,,,,0,,,,0,,,,,,299.9800873,,,,
,28119641.175,299.990387,30950.8916015625,0.0120431450041783,0.000609651098600475,1,0.999253354069792,40.0298881530762,1.97274193863627,27.3100007325411,0.122749013261998,0.0918356786431956,2.5,0.00612914339022661,0.0120387476983799,0.00613691382213935,299.990387,299.990387,30940.830078125,30960.953125,57.4176493941791,20.492324897977,27.464817,0,0,0,40,4449,300.1004,30950.8916015625,,,,,,,,,,,,,0,,,,-0.00245,,,,,,299.990387,,,,
,28119733.87,299.9894104,26315.4951171875,0.0109075556854446,0.000510304169970748,1,0.999253354069792,40.0298881530762,1.97261791605076,27.3100007325411,0.10948415969276,0.0928891129333726,2.5,0.00642062624890718,0.0109029947403565,0.00642764549052086,299.9894104,299.9894104,26308.01953125,26322.970703125,57.3465211989291,20.4949206037974,27.085165,0,0,0,40,4449,300.10285,26315.4951171875,,,,,,,,,,,,,0,,,,0.00245,,,,,,299.9894104,,,,
,28119825.74,299.9897156,21722.9169921875,0.0091776234736085,0.000521218346156467,1,0.999253354069792,40.0298881530762,1.97245203115489,27.3100007325411,0.0924207710452484,0.0763718865557856,2.5,0.00524316051221597,0.00917388740885306,0.00524907618070971,299.9897156,299.9897156,21715.46875,21730.365234375,57.4481329064291,20.4987827331793,27.085165,0,0,0,40,4449,300.1186,21722.9169921875,,,,,,,,,,,,,0,,,,0,,,,,,299.9897156,,,,
,28119916.97,299.990509,17165.7802734375,0.007576269744651,0.000402996501259068,1,0.999253354069792,40.0298881530762,1.97276636707767,27.3100007325411,0.0758882386450523,0.0654690652661692,2.5,0.00454419868257789,0.00757303951554408,0.00454907991262015,299.990509,299.990509,17158.244140625,17173.31640625,57.200356665833,20.4942330796701,27.085165,0,0,0,40,4449,300.1218,17165.7802734375,,,,,,,,,,,,,0,,,,0.0049,,,,,,299.990509,,,,
,28120010.845,299.9846191,12470.6284179688,0.00846050926403106,0.000326619830668124,1,0.999253354069792,40.0298881530762,1.97250214756426,27.3100007325411,0.0861990265758093,0.0646474001186384,2.5,0.00431822588483278,0.00845740139718518,0.004323704753617,299.9846191,299.9846191,12465.6181640625,12475.638671875,57.3308886285445,20.4988003992357,26.705515,0,0,0,40,4449,300.1159,12470.6284179688,,,,,,,,,,,,,0,,,,0,,,,,,299.9846191,,,,
,28120103.5,299.9921875,7842.7861328125,0.00638697678277199,0.000412225884298141,1,0.999253354069792,40.0298881530762,1.97270539189706,27.3100007325411,0.0643211869975509,0.0531844899507905,2.5,0.00365141274157671,0.00638436735536204,0.00365553946715235,299.9921875,299.9921875,7842.7861328125,7842.7861328125,57.0932735586983,20.4962293937674,27.464817,0,0,0,40,4449,300.1258,7842.7861328125,,,,,,,,,,,,,0,,,,0,,,,,,299.9921875,,,,
,28120193.745,299.9968872,3329.75854492188,0.00443760888185207,0.00022124767962411,1,0.999253354069792,40.0298881530762,1.97265552096973,27.3100007325411,0.045123600963302,0.0344406428813572,2.5,0.00231236129175949,0.00443594287679204,0.00231523655377794,299.9968872,299.9968872,3324.84399414063,3334.67309570313,57.2941520881407,20.4987521678401,27.085165,0,0,0,40,4449,300.13755,3329.75854492188,,,,,,,,,,,,,0,,,,0,,,,,,299.9968872,,,,
,28120284.11,299.9942932,-1184.43701171875,-0.00236429532675218,0.000119066289821371,1,0.999253354069792,40.0298881530762,1.97260183020049,27.3100007325411,-0.0239371217701466,-0.0189258027701735,0.25,-0.00128381667240839,-0.00236337327056165,-0.00128534755862807,299.9942932,299.9942932,-1197.00207519531,-1171.87194824219,57.3770047111791,20.5002464173716,26.705515,0,0,0,40,4449,300.13775,-1184.43701171875,,,,,,,,,,,,,0,,,,0,,,,,,299.9942932,,,,
,28120372.5,299.9987488,-5600.4091796875,-0.00555563986965795,0.000243676137776483,1,0.999253354069792,40.0298881530762,1.97258462800376,27.3100007325411,-0.0560980516039327,-0.0453323204898278,0.25,-0.00309373905727279,-0.00555342261202367,-0.00309733151894136,299.9987488,299.9987488,-5602.83056640625,-5597.98779296875,57.241001348833,20.4985738198104,27.464817,0,0,0,40,4449,300.1317,-5600.4091796875,,,,,,,,,,,,,0,,,,0,,,,,,299.9987488,,,,
,28120462.9,299.9969482,-10119.3315429688,-0.00723562229634496,0.000426369395730395,1,0.999253354069792,40.0298881530762,1.97250449625643,27.3100007325411,-0.0730371455943699,-0.0591634988674921,0.25,-0.00404047906747332,-0.0072327297665997,-0.00404515459527079,299.9969482,299.9969482,-10127.068359375,-10111.5947265625,57.166746639506,20.5019985196001,27.464817,0,0,0,40,4449,300.12075,-10119.3315429688,,,,,,,,,,,,,0,,,,0.00245,,,,,,299.9969482,,,,
,28120557.065,300.0019836,-14824.84765625,-0.00816924316823726,0.000425778869385237,1,0.999253354069792,40.0298881530762,1.97257496934233,27.3100007325411,-0.0825448715012751,-0.0664037304291863,2.5,-0.00452562793192514,-0.00816600318618068,-0.00453090219269924,300.0019836,300.0019836,-14834.9453125,-14814.75,57.2222422643714,20.4976750681577,27.464817,0,0,0,40,4449,300.14235,-14824.84765625,,,,,,,,,,,,,0,,,,0,,,,,,300.0019836,,,,
,28120649.445,300.0018921,-19442.255859375,-0.0101433014759395,0.000408575779179234,1,0.999253354069792,40.0298881530762,1.97250226388493,27.3100007325411,-0.103725373467232,-0.0753044477641639,2.5,-0.00498017849174358,-0.0101397051266588,-0.0049867407270627,300.0018921,300.0018921,-19447.39453125,-19437.1171875,57.1972301517561,20.4978601555236,27.464817,0,0,0,40,4449,300.1376,-19442.255859375,,,,,,,,,,,,,0,,,,0,,,,,,300.0018921,,,,
,28120742.19,300.0112,-24076.9462890625,-0.0100698239986601,0.000506389776394354,1,0.999253354069792,40.0298881530762,1.97216276122409,27.3100007325411,-0.102179540288731,-0.0792342177288164,2.5,-0.00534568495380385,-0.0100659882991079,-0.00535218034547095,300.0112,300.0112,-24084.400390625,-24069.4921875,57.3418314278138,20.5034905658384,27.085165,0,0,0,40,4449,300.1233,-24076.9462890625,,,,,,,,,,,,,0,,,,0,,,,,,300.0112,,,,
,28120834.72,300.0097046,-28702.4091796875,-0.0110367619937193,0.000643516204554313,1,0.999253354069792,40.0298881530762,1.97257875697141,27.3100007325411,-0.1112317510009,-0.0913738956136066,2.5,-0.00626284406832565,-0.0110322961611266,-0.006269944847105,300.0097046,300.0097046,-28707.53125,-28697.287109375,57.3449579418907,20.4986911750846,26.705515,0,0,0,40,4449,300.1169,-28702.4091796875,,,,,,,,,,,,,0,,,,0,,,,,,300.0097046,,,,
,28120927.64,300.0099487,-33347.046875,-0.0118990798725765,0.000576479372746693,1,0.999253354069792,40.0298881530762,1.97237451701167,27.3100007325411,-0.120520264965281,-0.094984625365322,2.5,-0.00643733429199926,-0.0118944777801597,-0.00644499188649864,300.0099487,300.0099487,-33349.828125,-33344.265625,57.268358347006,20.5021736974949,27.844467,0,0,0,40,4449,300.11125,-33347.046875,,,,,,,,,,,,,0,,,,-0.0049,,,,,,300.0099487,,,,
,28121021.6,300.00886535,-38044.099609375,-0.0127203653467497,0.000567758148470475,1,0.999253354069792,40.0298881530762,1.97225497282068,27.3100007325411,-0.129069606509572,-0.100159119239797,2.5,-0.00675856503163193,-0.0127155325550175,-0.00676674704615432,300.0084839,300.0092468,-38051.5703125,-38036.62890625,57.3066581444484,20.5017456466481,27.085165,0,0,0,40,4449,300.1022,-38044.099609375,,,,,,,,,,,,,0,,,,0.00245,,,,,,300.00886535,,,,
,28121114.75,300.0084229,-42696.68359375,-0.0119869498862857,0.000488501861179818,1,0.999253354069792,40.0298881530762,1.97239388532676,27.3100007325411,-0.118401216972129,-0.113061987146525,2.5,-0.00803953306944719,-0.0119813012895825,-0.00804718584583116,300.0084229,300.0084229,-42704.2109375,-42689.15625,57.3191642007561,20.5016712477558,27.464817,0,0,0,40,4449,300.1033,-42696.68359375,,,,,,,,,,,,,0,,,,0,,,,,,300.0084229,,,,
,28121207.525,300.0101624,-47334.400390625,-0.013394543538877,0.000767826828066498,1,0.999253354069792,40.0298881530762,1.97242259613277,27.3100007325411,-0.134909562721828,-0.11131661074141,2.5,-0.00763936101149188,-0.0133891217009542,-0.0076479433226765,300.0101624,300.0101624,-47341.74609375,-47327.0546875,57.3316702570638,20.5002928194318,27.464817,0,0,0,40,4449,300.0889,-47334.400390625,,,,,,,,,,,,,0,,,,0.0049,,,,,,300.0101624,,,,
,28121301.215,300.0130005,-52019.22265625,-0.0140110619944441,0.000464101206858536,1,0.999253354069792,40.0298881530762,1.97239350166597,27.3100007325411,-0.141366143366169,-0.115001700350675,2.5,-0.00786242377989497,-0.014005480434486,-0.00787139432781079,300.0130005,300.0130005,-52029.37109375,-52009.07421875,57.220679007333,20.5025312864087,27.844467,0,0,0,40,4449,300.0919,-52019.22265625,,,,,,,,,,,,,0,,,,-0.0049,,,,,,300.0130005,,,,
,28121394.335,300.0153656,-56669.650390625,-0.0142756987672131,0.000748217758264968,1,0.999253354069792,40.0298881530762,1.97251385581825,27.3100007325411,-0.1441278504694,-0.116700639551541,2.5,-0.00796798852007444,-0.0142700449878927,-0.0079771199869207,300.0148621,300.0158691,-56706.76953125,-56632.53125,57.3379232852176,20.5005900348856,27.085165,0,0,0,40,4449,300.06725,-56669.650390625,,,,,,,,,,,,,0,,,,0,,,,,,300.0153656,,,,
,28121487.54,300.011261,-61329.3203125,-0.0138834949686246,0.000667579518500608,1,0.999253354069792,40.0298881530762,1.97246305016485,27.3100007325411,-0.139527287172241,-0.117171350619171,2.5,-0.00807831907145918,-0.0138777895111098,-0.00808718115323191,300.011261,300.011261,-61329.3203125,-61329.3203125,57.2464727484676,20.5003211171068,27.464817,0,0,0,40,4449,300.0695,-61329.3203125,,,,,,,,,,,,,0,,,,-0.00245,,,,,,300.011261,,,,
,28121582.565,300.0126343,-66078.66796875,-0.0142002182251066,0.000619230601073258,1,0.999253354069792,40.0298881530762,1.9723485290118,27.3100007325411,-0.142122221307264,-0.123186853323939,2.5,-0.00856229159807138,-0.0141941925676295,-0.00857133686328083,300.0126343,300.0126343,-66080.9765625,-66076.359375,57.3926372815638,20.5009457075279,27.464817,0,0,0,40,4449,300.0504,-66078.66796875,,,,,,,,,,,,,0,,,,0,,,,,,300.0126343,,,,
,28121676.81,300.0127258,-70788.62109375,-0.0152622942147136,0.000769546223273794,1,0.999253354069792,40.0298881530762,1.97223130067429,27.3100007325411,-0.153118630041576,-0.130226830512304,2.5,-0.00900887964175087,-0.0152559525405688,-0.00901859623062339,300.0127258,300.0127258,-70798.7578125,-70778.484375,57.2957153451791,20.5060366772314,27.464817,0,0,0,40,4449,300.04205,-70788.62109375,,,,,,,,,,,,,0,,,,0.00245,,,,,,300.0127258,,,,
,28121769.27,300.0113525,-75408.05078125,-0.0149967045923766,0.000875073683491527,1,0.999253354069792,40.0298881530762,1.97225641091851,27.3100007325411,-0.150587329788864,-0.12720438593194,2.5,-0.00878430607160734,-0.0149905258566642,-0.00879384547037748,300.0113525,300.0113525,-75415.6171875,-75400.484375,57.3082214014868,20.5021441250539,27.464817,0,0,0,40,4449,300.03155,-75408.05078125,,,,,,,,,,,,,0,,,,0.00245,,,,,,300.0113525,,,,
,28121864.27,300.0134277,-80157.71875,-0.0152324737095509,0.00069391452517847,1,0.999253354069792,40.0298881530762,1.97238784695366,27.3100007325411,-0.153050823226243,-0.128714749987903,2.5,-0.00887788604291264,-0.0152262336776421,-0.00888756491382961,300.0134277,300.0134277,-80167.6328125,-80147.8046875,57.2675767184868,20.5026555608237,27.085165,0,0,0,40,4449,300.0213,-80157.71875,,,,,,,,,,,,,0,,,,-0.0049,,,,,,300.0134277,,,,
,28121956.13,300.019043,-84747.921875,-0.0158063743362009,0.000644518878080097,1,0.999253354069792,40.0298881530762,1.9722432628578,27.3100007325411,-0.159572845170435,-0.129129200222541,2.5,-0.00881636396153158,-0.0158001620352535,-0.0088264061340681,300.019043,300.019043,-84750.4609375,-84745.3828125,57.3957637956407,20.5065703975728,27.085165,0,0,0,40,4449,300.0085,-84747.921875,,,,,,,,,,,,,0,,,,0.00245,,,,,,300.019043,,,,
,28122044.96,300.0157166,-89187.1171875,-0.0167813472707732,0.000737384027647354,1,0.999253354069792,40.0298881530762,1.97206478465282,27.3100007325411,-0.170164308671233,-0.132677104126802,2.5,-0.00896596345127487,-0.0167750186627256,-0.00897662559701273,300.0157166,300.0157166,-89197.1171875,-89177.1171875,57.268358347006,20.509691313078,27.085165,0,0,0,40,4449,300.00895,-89187.1171875,,,,,,,,,,,,,0,,,,-0.0049,,,,,,300.0157166,,,,
,28122153.095,300.0068359,-86414.66796875,-0.0164095575449114,0.00080019488229231,1,0.999253354069792,40.0298881530762,1.97225367121402,27.3100007325411,-0.165201836946985,-0.136720653357605,2.5,-0.00939110117293419,-0.0164029627282573,-0.00940151981871539,300.0068359,300.0068359,-86424.5859375,-86404.75,57.4864327038715,20.5036121553278,27.085165,0,0,0,40,4449,299.99355,-86414.66796875,,,,,,,,,,,,,0,,,,0,,,,,,300.0068359,,,,
,28122246.355,299.9973145,-81752.37109375,-0.0163183234996856,0.000670854094409358,1,0.999253354069792,40.0298881530762,1.97237933000766,27.3100007325411,-0.164118523486702,-0.136977708694583,2.5,-0.00942914699239379,-0.0163117031662381,-0.00943952107342271,299.9973145,299.9973145,-81762.2265625,-81742.515625,57.230840178083,20.5021916623347,27.464817,0,0,0,40,4449,299.9813,-81752.37109375,,,,,,,,,,,,,0,,,,0,,,,,,299.9973145,,,,
,28122344.595,299.9989319,-76842.640625,-0.0152068571391193,0.000662387248306479,1,0.999253354069792,40.0298881530762,1.97246244587409,27.3100007325411,-0.15231928553743,-0.131271755118428,2.5,-0.00911067639552291,-0.0152004675126709,-0.00912034522674123,299.9989319,299.9989319,-76845.2109375,-76840.0703125,57.2316218066022,20.5012925731687,27.464817,0,0,0,40,4449,300.0012,-76842.640625,,,,,,,,,,,,,0,,,,0,,,,,,299.9989319,,,,
,28122438.64,299.995575,-72142.5,-0.0145127030360541,0.000808828327857377,1,0.999253354069792,40.0298881530762,1.97203403494285,27.3100007325411,-0.144855433956081,-0.128027590072919,2.5,-0.00894304252510088,-0.014506436876871,-0.00895227438969716,299.995575,299.995575,-72147.078125,-72137.921875,57.2542890336599,20.5106541668246,27.844467,0,0,0,40,4449,300.009,-72142.5,,,,,,,,,,,,,0,,,,0,,,,,,299.995575,,,,
,28122532.645,299.98756405,-67445.64453125,-0.0152950052548351,0.000741027646945073,1,0.999253354069792,40.0298881530762,1.9725692661391,27.3100007325411,-0.155260637663929,-0.120203539418214,2.5,-0.00810451935937278,-0.0152892621724123,-0.00811430016049765,299.9872131,299.987915,-67450.5625,-67440.7265625,57.3996719382368,20.5014835812021,27.464817,0,0,0,40,4449,300.01995,-67445.64453125,,,,,,,,,,,,,0,,,,0,,,,,,299.98756405,,,,
,28122628.37,299.9907837,-62660.7109375,-0.0143481888235584,0.000720419686698381,1,0.999253354069792,40.0298881530762,1.97240094050424,27.3100007325411,-0.144876331411426,-0.117146489292763,2.5,-0.00799589472541185,-0.0143425352007745,-0.00800506829756327,299.9907837,299.9907837,-62668.0390625,-62653.3828125,57.383257739333,20.5062825369176,27.464817,0,0,0,40,4449,300.02655,-62660.7109375,,,,,,,,,,,,,0,,,,0,,,,,,299.9907837,,,,
,28122723.615,299.9875183,-57900.64453125,-0.0138123817795199,0.000947620470614159,1,0.999253354069792,40.0298881530762,1.97235325108038,27.3100007325411,-0.138933739642694,-0.115823569865501,2.5,-0.00797058521305654,-0.0138067550041774,-0.00797941894702292,299.9875183,299.9875183,-57905.51171875,-57895.77734375,57.3355783996599,20.5042292517605,27.464817,0,0,0,40,4449,300.0377,-57900.64453125,,,,,,,,,,,,,0,,,,-0.00245,,,,,,299.9875183,,,,
,28122818.015,299.9841309,-53180.931640625,-0.0135955035766429,0.000796631471129822,1,0.999253354069792,40.0298881530762,1.97226464901668,27.3100007325411,-0.136749865141713,-0.113979528311446,2.5,-0.00784358822073226,-0.013589961528903,-0.00785229349541724,299.9841309,299.9841309,-53193.50390625,-53168.359375,57.3363600281791,20.5064323119808,27.844467,0,0,0,40,4449,300.05045,-53180.931640625,,,,,,,,,,,,,0,,,,0.00245,,,,,,299.9841309,,,,
,28122912.64,299.9874573,-48451.08984375,-0.0135129464056931,0.000614982162821201,1,0.999253354069792,40.0298881530762,1.97242333404274,27.3100007325411,-0.136919275995346,-0.107585170151277,2.5,-0.00728496762014479,-0.0135077660515774,-0.00729364289456678,299.9874573,299.9874573,-48456.16015625,-48446.01953125,57.3011867448138,20.5031185578088,27.464817,0,0,0,40,4449,300.0634,-48451.08984375,,,,,,,,,,,,,0,,,,0,,,,,,299.9874573,,,,
,28123006.775,299.990387,-43748.345703125,-0.0130032470157082,0.00063162195015917,1,0.999253354069792,40.0298881530762,1.97228723385853,27.3100007325411,-0.131862019796177,-0.102850632656588,2.5,-0.00695025472310773,-0.0129982944146685,-0.00695861244638656,299.990387,299.990387,-43753.22265625,-43743.46875,57.1792526958137,20.5047264700431,27.844467,0,0,0,40,4449,300.07165,-43748.345703125,,,,,,,,,,,,,0,,,,0,,,,,,299.990387,,,,
,28123099.72,299.9892578,-39103.416015625,-0.0122484013718016,0.000533350155809127,1,0.999253354069792,40.0298881530762,1.97225644141331,27.3100007325411,-0.123288216770912,-0.102172747324376,2.5,-0.00702050680250727,-0.0122434193295718,-0.00702837391764386,299.9892578,299.9892578,-39105.9921875,-39100.83984375,57.2878990599868,20.5058541058203,27.844467,0,0,0,40,4449,300.0749,-39103.416015625,,,,,,,,,,,,,0,,,,-0.0049,,,,,,299.9892578,,,,
,28123196.195,299.9852295,-34281.34765625,-0.0115764239694305,0.000584401174822481,1,0.999253354069792,40.0298881530762,1.97209529407595,27.3100007325411,-0.116254537189347,-0.0980641121291287,2.5,-0.00676995982705546,-0.011571622799287,-0.00677740002493025,299.9852295,299.9852295,-34283.9609375,-34278.734375,57.3801312252561,20.5059910706648,27.464817,0,0,0,40,4449,300.08085,-34281.34765625,,,,,,,,,,,,,0,,,,-0.0049,,,,,,299.9852295,,,,
,28123289.79,299.989624,-29604.453125,-0.0117026371608327,0.000572580821475118,1,0.999253354069792,40.0298881530762,1.9724594467102,27.3100007325411,-0.118985005683496,-0.0908260106419775,2.5,-0.00609892316043739,-0.0116982685152263,-0.00610647229939303,299.989624,299.989624,-29612,-29596.90625,57.105779615006,20.5008519421909,27.844467,0,0,0,40,4449,300.0906,-29604.453125,,,,,,,,,,,,,0,,,,0,,,,,,299.989624,,,,
,28123382.37,299.9840698,-24976.888671875,-0.0107601706301864,0.000549150475259771,1,0.999253354069792,40.0298881530762,1.9724263476016,27.3100007325411,-0.108932920339345,-0.0862106773522269,2.5,-0.00584938042884146,-0.0107559922552064,-0.00585632195744153,299.9840698,299.9840698,-24984.490234375,-24969.287109375,57.0948368157368,20.5020377182764,27.464817,0,0,0,40,4449,300.10415,-24976.888671875,,,,,,,,,,,,,0,,,,0,,,,,,299.9840698,,,,
,28123475.345,299.9881592,-20332.1337890625,-0.00917712889692435,0.000490573651341255,1,0.999253354069792,40.0298881530762,1.9722794169447,27.3100007325411,-0.0925779579956346,-0.0753807143359422,2.5,-0.00515512514383928,-0.00917345040710564,-0.00516104505748059,299.9876709,299.9886475,-20341.92578125,-20322.341796875,57.3848209963715,20.5032788522466,27.844467,0,0,0,40,4449,300.11425,-20332.1337890625,,,,,,,,,,,,,0,,,,-0.00245,,,,,,299.9881592,,,,
,28123569.05,299.9923096,-15647.2387695313,-0.00876987454213782,0.000395124754608862,1,0.999253354069792,40.0298881530762,1.97223570183075,27.3100007325411,-0.0892254030935596,-0.0676606928478984,2.5,-0.00453501534739147,-0.0087666137171812,-0.00454068825241457,299.9923096,299.9923096,-15659.5380859375,-15634.939453125,57.2464727484676,20.5035707389014,27.464817,0,0,0,40,4449,300.11915,-15647.2387695313,,,,,,,,,,,,,0,,,,0,,,,,,299.9923096,,,,
,28123662.83,299.9931946,-10959.6342773438,-0.00796622142793195,0.000374788636732447,1,0.999253354069792,40.0298881530762,1.97243046160078,27.3100007325411,-0.0811599920024379,-0.0608694175342379,2.5,-0.00406603475017067,-0.00796329193370505,-0.00407119335688477,299.9931946,299.9931946,-10972.0322265625,-10947.236328125,57.2277136640061,20.5034052916655,27.464817,0,0,0,40,4449,300.12965,-10959.6342773438,,,,,,,,,,,,,0,,,,0,,,,,,299.9931946,,,,
,28123755.285,299.9914246,-6338.69946289063,-0.00625958967992348,0.000300559988285524,1,0.999253354069792,40.0298881530762,1.97258167068787,27.3100007325411,-0.0633407576899624,-0.0503531442728815,2.5,-0.00342045374050899,-0.00625713671471778,-0.00342450380972761,299.9914246,299.9914246,-6343.6376953125,-6333.76123046875,57.3097846585253,20.5034060847021,27.464817,0,0,0,40,4449,300.1304,-6338.69946289063,,,,,,,,,,,,,0,,,,-0.0049,,,,,,299.9914246,,,,
,28123849.875,299.9949951,-1609.73559570313,-0.00268611001910995,0.000142238001522365,1,0.999253354069792,40.0298881530762,1.97280549013686,27.3100007325411,-0.0270878068532885,-0.0221399604381714,0.25,-0.00151546197817394,-0.00268502466431165,-0.00151719946686619,299.9949951,299.9949951,-1614.81103515625,-1604.66015625,57.2769562607176,20.4961258567893,27.844467,0,0,0,40,4449,300.1323,-1609.73559570313,,,,,,,,,,,,,0,,,,0.00245,,,,,,299.9949951,,,,
,28123938.65,299.9945984,2822.85217285156,0.0042232144943758,0.000219494595086091,1,0.999253354069792,40.0298881530762,1.97244967803319,27.3100007325411,0.0432050515757031,0.0312029457321567,0.25,0.00206048829787917,0.00422172214418287,0.0020632292558957,299.9945984,299.9945984,2817.859375,2827.84497070313,57.3308886285445,20.5037215251715,27.464817,0,0,0,40,4449,300.1294,2822.85217285156,,,,,,,,,,,,,0,,,,-0.0049,,,,,,299.9945984,,,,
,28124029.725,299.9986877,7375.1474609375,0.00640478777158858,0.000328672844190073,1,0.999253354069792,40.0298881530762,1.97232943484697,27.3100007325411,0.0651064467132194,0.0497028736487598,0.25,0.00333824145655108,0.00640238380300942,0.00334238869136129,299.9986877,299.9986877,7367.71337890625,7382.58154296875,57.1409528983714,20.5060371388585,27.085165,0,0,0,40,4449,300.1305,7375.1474609375,,,,,,,,,,,,,0,,,,-0.00245,,,,,,299.9986877,,,,
,28124122.36,300.0082703,12006.0419921875,0.00753658913927226,0.000420475839034082,1,0.999253354069792,40.0298881530762,1.9727485606698,27.3100007325411,0.0756180992301988,0.0643214146763449,0.25,0.00444920175962626,0.0075334149999316,0.00445406105207807,300.0082703,300.0082703,12000.935546875,12011.1484375,57.1581487257945,20.4990097585327,27.844467,0,0,0,40,4449,300.13075,12006.0419921875,,,,,,,,,,,,,0,,,,0,,,,,,300.0082703,,,,
,28124217.62,300.0057678,16769.0322265625,0.00858641376912302,0.000431812425933237,1,0.999253354069792,40.0298881530762,1.97263663857707,27.3100007325411,0.0870898318111984,0.0679086824725792,2.5,0.0045878154926606,0.00858312010286221,0.00459336183638305,300.0057678,300.0057678,16763.91015625,16774.154296875,57.2433462343907,20.5024560215003,27.464817,0,0,0,40,4449,300.12675,16769.0322265625,,,,,,,,,,,,,0,,,,0,,,,,,300.0057678,,,,
,28124311.545,300.0013733,21463.4482421875,0.0103560078382139,0.000493593114831442,1,0.999253354069792,40.0298881530762,1.97268546286032,27.3100007325411,0.105140116383419,0.0813335927873506,2.5,0.00548211666146722,0.0103520748089399,0.00548880245967484,300.0013733,300.0013733,21460.884765625,21466.01171875,57.2261504069676,20.5012363559391,27.844467,0,0,0,40,4449,300.12585,21463.4482421875,,,,,,,,,,,,,0,,,,0,,,,,,300.0013733,,,,
,28124405.325,300.00291445,26148.9658203125,0.0107819444446854,0.000570020134450891,1,0.999253354069792,40.0298881530762,1.97265569603296,27.3100007325411,0.10859918740495,0.0896628945961526,2.5,0.00615360889856106,0.0107775585294249,0.00616054972393876,300.0028687,300.0029602,26144.201171875,26153.73046875,57.1839424669291,20.5012176980038,27.464817,0,0,0,40,4449,300.1206,26148.9658203125,,,,,,,,,,,,,0,,,,0.0049,,,,,,300.00291445,,,,
,28124500.26,300.00857545,30894.4638671875,0.0111826895697158,0.000491883451630815,1,0.999253354069792,40.0298881530762,1.97281034816885,27.3100007325411,0.112467378743275,0.0940224249160042,2.5,0.0064735780048976,0.011178082938491,0.00648076588477138,300.0084534,300.0086975,30887.359375,30901.568359375,57.2933704596215,20.4958605880937,27.464817,0,0,0,40,4449,300.1143,30894.4638671875,,,,,,,,,,,,,0,,,,-0.0098,,,,,,300.00857545,,,,
,28124597.095,300.0135803,35734.662109375,0.0127237437708085,0.000561566383336493,1,0.999253354069792,40.0298881530762,1.97275471579273,27.3100007325411,0.129839697064585,0.0961432508453013,2.5,0.00639654575613591,0.0127191447875739,0.00640474375294984,300.0135803,300.0135803,35724.79296875,35744.53125,57.2941520881407,20.4991517659541,27.844467,0,0,0,40,4449,300.1045,35734.662109375,,,,,,,,,,,,,0,,,,-0.00245,,,,,,300.0135803,,,,
,28124690.305,300.0108643,40394.5859375,0.0124581744974737,0.000622532072968772,1,0.999253354069792,40.0298881530762,1.97273754503552,27.3100007325411,0.125392750004483,0.104155400034051,2.5,0.00715941040823964,0.0124530871813102,0.00716740327347749,300.0108643,300.0108643,40392.29296875,40396.87890625,57.2324034351214,20.4968191687437,27.464817,0,0,0,40,4449,300.0946,40394.5859375,,,,,,,,,,,,,0,,,,0,,,,,,300.0108643,,,,
,28124786.09,300.0138855,45180.3203125,0.0135024351753149,0.000669048967592916,1,0.999253354069792,40.0298881530762,1.97273460356188,27.3100007325411,0.136380193533576,0.110132548163173,2.5,0.00751323228231427,0.0134970885545677,0.00752189229825531,300.0138855,300.0138855,45169.9140625,45190.7265625,57.2136443506599,20.4985384763727,27.844467,0,0,0,40,4449,300.09605,45180.3203125,,,,,,,,,,,,,0,,,,0.00245,,,,,,300.0138855,,,,
,28124879.935,300.0113831,49872.84375,0.0130431503972621,0.000785904053588224,1,0.999253354069792,40.0298881530762,1.97266886734258,27.3100007325411,0.130324264155409,0.114537781329622,2.5,0.00798723575147734,0.0130375130653157,0.00799557166382286,300.0113831,300.0113831,49863.1171875,49882.5703125,57.2800827747945,20.4989288369026,27.085165,0,0,0,40,4449,300.08165,49872.84375,,,,,,,,,,,,,0,,,,-0.0049,,,,,,300.0113831,,,,
,28124973.45,300.0144043,54546.072265625,0.0143668563642097,0.00049035025179545,1,0.999253354069792,40.0298881530762,1.97280142003564,27.3100007325411,0.1453303946208,0.11594981532128,2.5,0.00788356819070601,0.014361252723987,0.00789276680605407,300.0144043,300.0144043,54536.08984375,54556.0546875,57.2300585495638,20.4964029019224,27.844467,0,0,0,40,4449,300.06905,54546.072265625,,,,,,,,,,,,,0,,,,-0.00245,,,,,,300.0144043,,,,
,28125068.72,300.0126343,59305.9140625,0.0131950446817559,0.000972010666957854,1,0.999253354069792,40.0298881530762,1.97276559090609,27.3100007325411,0.131430010430322,0.118291319861402,2.5,0.0082962460572003,0.0131892127559979,0.00830465435031716,300.0126343,300.0126343,59303.34375,59308.484375,57.1933220091599,20.4975644087421,27.844467,0,0,0,40,4449,300.06055,59305.9140625,,,,,,,,,,,,,0,,,,0,,,,,,300.0126343,,,,
,28125163.495,300.0092468,64043.849609375,0.0147258564180855,0.000735775415534438,1,0.999253354069792,40.0298881530762,1.97290165505101,27.3100007325411,0.149342772047131,0.116697576146673,2.5,0.00788777323472641,0.0147202557868503,0.00789718798834955,300.0092468,300.0092468,64036.4453125,64051.25390625,57.0674798175637,20.4944609870116,27.464817,0,0,0,40,4449,300.05645,64043.849609375,,,,,,,,,,,,,0,,,,0,,,,,,300.0092468,,,,
,28125258.545,300.0151672,68796.6796875,0.0144498827865766,0.000651861783224254,1,0.999253354069792,40.0298881530762,1.97321537518503,27.3100007325411,0.143569080101677,0.131827866048381,2.5,0.00928726753414335,0.0144433781413019,0.0092964483586435,300.0151672,300.0151672,68794.2734375,68799.0859375,57.2449094914291,20.4925933943058,27.464817,0,0,0,40,4449,300.0387,68796.6796875,,,,,,,,,,,,,0,,,,0.0049,,,,,,300.0151672,,,,
,28125353.41,300.0120544,73536.75390625,0.0142998625241013,0.000820625720455326,1,0.999253354069792,40.0298881530762,1.97317112835756,27.3100007325411,0.143168087352422,0.124150551280717,2.5,0.00862684361735088,0.0142938038071877,0.00863593619700093,300.0120544,300.0120544,73531.71875,73541.7890625,57.2667950899676,20.4908859202306,27.085165,0,0,0,40,4449,300.03755,73536.75390625,,,,,,,,,,,,,0,,,,-0.0049,,,,,,300.0120544,,,,
,28125446.975,300.0116882,78212.7109375,0.0160270904014384,0.000705740230876393,1,0.999253354069792,40.0298881530762,1.97315027422678,27.3100007325411,0.162164556216008,0.129302097651543,2.5,0.00878849373037284,0.016020883058312,0.00879869923393635,300.0116882,300.0116882,78205.125,78220.296875,57.2097362080637,20.4902345672864,27.844467,0,0,0,40,4449,300.0222,78212.7109375,,,,,,,,,,,,,0,,,,0.0049,,,,,,300.0116882,,,,
,28125543.79,300.011322,83056.19921875,0.0153070210078818,0.000825842340778436,1,0.999253354069792,40.0298881530762,1.97326089110631,27.3100007325411,0.15330458494169,0.132634222947465,2.5,0.00921065477271428,0.0153005678825514,0.00922036625964451,300.011322,300.011322,83049.03125,83063.3671875,57.1612752398714,20.4887830540551,27.844467,0,0,0,40,4449,300.01725,83056.19921875,,,,,,,,,,,,,0,,,,-0.00245,,,,,,300.011322,,,,
,28125634.125,300.0090332,87569.609375,0.0169629045500237,0.000916492256744298,1,0.999253354069792,40.0298881530762,1.97311798322476,27.3100007325411,0.172811775375423,0.130033100549543,2.5,0.0086919509266745,0.0169567500838265,0.00870274614411523,300.0090332,300.0090332,87562.0390625,87577.1796875,57.1034347294484,20.4928872391344,27.844467,0,0,0,40,4449,300.0023,87569.609375,,,,,,,,,,,,,0,,,,0,,,,,,300.0090332,,,,
,28125741.735,300.0086975,88010.5390625,0.0153904364539064,0.00070986152242778,1,0.999253354069792,40.0298881530762,1.97335000004379,27.3100007325411,0.151768641688894,0.147089626494785,2.5,0.0104885095268167,0.0153831585177302,0.0104982275879633,300.0086975,300.0086975,88003.09375,88017.984375,57.0690430746022,20.4875391785034,27.844467,0,0,0,40,4449,299.99635,88010.5390625,,,,,,,,,,,,,0,,,,0,,,,,,300.0086975,,,,
,28125833.965,300.0072327,83399.28515625,0.0157402114559665,0.000735643085153487,1,0.999253354069792,40.0298881530762,1.97316395043623,27.3100007325411,0.158277538377937,0.132676906612932,2.5,0.00913997849024266,0.0157337940824092,0.00914997581496291,300.0072327,300.0072327,83389.2421875,83409.328125,57.2097362080637,20.4912280290855,27.844467,0,0,0,40,4449,299.9949,83399.28515625,,,,,,,,,,,,,0,,,,0.00245,,,,,,300.0072327,,,,
,28125928.55,299.9983215,78670.49609375,0.0156198004466174,0.000902922483877815,1,0.999253354069792,40.0298881530762,1.97303763836741,27.3100007325411,0.158177151397973,0.125188790155439,2.5,0.00849175552762249,0.015613806354988,0.00850170777990264,299.9983215,299.9983215,78665.53125,78675.4609375,57.2449094914291,20.491074372185,27.844467,0,0,0,40,4449,299.9954,78670.49609375,,,,,,,,,,,,,0,,,,-0.00245,,,,,,299.9983215,,,,
,28126021.46,299.996521,74027.19140625,0.0150553873831796,0.000769122973060563,1,0.999253354069792,40.0298881530762,1.97303965689027,27.3100007325411,0.151962206199583,0.123547682644874,2.5,0.00844272487882191,0.0150494351108643,0.00845232150559761,299.996521,299.996521,74022.2109375,74032.171875,57.1104693861214,20.4904796511643,27.844467,0,0,0,40,4449,300.00205,74027.19140625,,,,,,,,,,,,,0,,,,-0.00245,,,,,,299.996521,,,,
,28126116.015,299.9866638,69298.7109375,0.0144615885222935,0.000637310800651325,1,0.999253354069792,40.0298881530762,1.97323917722335,27.3100007325411,0.144936010312047,0.124728145054029,2.5,0.00865009859917708,0.0144555153806694,0.00865931464799008,299.9866638,299.9866638,69288.5234375,69308.8984375,57.312129544083,20.4890537494063,27.844467,0,0,0,40,4449,300.0104,69298.7109375,,,,,,,,,,,,,0,,,,0,,,,,,299.9866638,,,,
,28126212.095,299.9876709,64496.01171875,0.0139658522526877,0.000675196548859945,1,0.999253354069792,40.0298881530762,1.97310356614742,27.3100007325411,0.139638414631089,0.122291475050399,2.5,0.00851876190034469,0.0139598712483851,0.00852766708694234,299.9875183,299.9878235,64486.16015625,64505.86328125,57.3910740245253,20.4910056408662,27.844467,0,0,0,40,4449,300.01955,64496.01171875,,,,,,,,,,,,,0,,,,-0.0049,,,,,,299.9876709,,,,
,28126308.32,299.9859924,59687.54296875,0.0135552594394728,0.000672972200956393,1,0.999253354069792,40.0298881530762,1.97313203351972,27.3100007325411,0.135344753341493,0.119795143902619,2.5,0.00836645650853483,0.0135493836753872,0.0083751071052851,299.9859924,299.9859924,59682.65625,59692.4296875,57.2996234877753,20.489133572503,27.085165,0,0,0,40,4449,300.0329,59687.54296875,,,,,,,,,,,,,0,,,,-0.0049,,,,,,299.9859924,,,,
,28126405.835,299.9875183,54814.1328125,0.0141654295283681,0.000676053704896854,1,0.999253354069792,40.0298881530762,1.97304066500198,27.3100007325411,0.143254808711449,0.114653661027281,2.5,0.00780131500564008,0.014159899380827,0.00781039162671466,299.9875183,299.9875183,54804.03125,54824.234375,57.2730481181214,20.4912798922183,27.844467,0,0,0,40,4449,300.04465,54814.1328125,,,,,,,,,,,,,0,,,,-0.00245,,,,,,299.9875183,,,,
,28126499.985,299.9833069,50107.4765625,0.0124963917652842,0.000552680113003052,1,0.999253354069792,40.0298881530762,1.97311261878811,27.3100007325411,0.12666397886721,0.0995102975666308,2.5,0.00673562108037546,0.0124916057616945,0.0067436418688898,299.9833069,299.9833069,50097.94140625,50117.01171875,57.1487691835637,20.4898301834917,27.464817,0,0,0,40,4449,300.05825,50107.4765625,,,,,,,,,,,,,0,,,,-0.00245,,,,,,299.9833069,,,,
,28126593.205,299.990387,45447.12109375,0.0130787435588657,0.000636086822706512,1,0.999253354069792,40.0298881530762,1.97300630528793,27.3100007325411,0.130842855399859,0.114052156925952,2.5,0.00793593902288738,0.0130731420550626,0.00794431493756387,299.990387,299.990387,45444.59765625,45449.64453125,57.362935397833,20.4913294112652,27.464817,0,0,0,40,4449,300.0616,45447.12109375,,,,,,,,,,,,,0,,,,0,,,,,,299.990387,,,,
,28126689.37,299.9875793,40639.205078125,0.0118614487552481,0.000565569732922106,1,0.999253354069792,40.0298881530762,1.97295289326082,27.3100007325411,0.118886353768399,0.102137056121574,2.5,0.00708127155111118,0.0118564404140629,0.00708887988527444,299.9875793,299.9875793,40631.76171875,40646.6484375,57.1948852661984,20.4930233643382,27.464817,0,0,0,40,4449,300.0708,40639.205078125,,,,,,,,,,,,,0,,,,0.00245,,,,,,299.9875793,,,,
,28126785.25,299.9905701,35849.166015625,0.0113235986270149,0.000594203773163026,1,0.999253354069792,40.0298881530762,1.97287078252786,27.3100007325411,0.113593883243916,0.096907615533322,2.5,0.00670701398458868,0.0113188457289536,0.00671428572555218,299.9905701,299.9905701,35844.15625,35854.17578125,57.0213637349291,20.4921313202234,27.844467,0,0,0,40,4449,300.07225,35849.166015625,,,,,,,,,,,,,0,,,,0,,,,,,299.9905701,,,,
,28126881.625,299.9913635,31031.8515625,0.0107624846284126,0.000722105897661724,1,0.999253354069792,40.0298881530762,1.97268898020641,27.3100007325411,0.108660927479661,0.0880255225354256,2.5,0.00601036846276033,0.010758202436871,0.00601729725753082,299.9913635,299.9913635,31026.75,31036.953125,57.0080760501022,20.4947959654492,27.464817,0,0,0,40,4449,300.0794,31031.8515625,,,,,,,,,,,,,0,,,,-0.00245,,,,,,299.9913635,,,,
,28126975.47,299.9845581,26341.310546875,0.0100160378197546,0.000564565428734571,1,0.999253354069792,40.0298881530762,1.97301272388557,27.3100007325411,0.100078188996624,0.0880643706040645,2.5,0.00614192776016884,0.0100116887380937,0.00614836727032288,299.9845581,299.9845581,26333.810546875,26348.810546875,57.2292769210445,20.4927675847154,28.224119,0,0,0,40,4449,300.0975,26341.310546875,,,,,,,,,,,,,0,,,,0,,,,,,299.9845581,,,,
,28127070.225,299.9850464,21606.0615234375,0.00923498002488842,0.000491192207401103,1,0.999253354069792,40.0298881530762,1.9729411346505,27.3100007325411,0.0933110159698233,0.0751902024828161,2.5,0.0051258975164249,0.00923132107507736,0.00513185585216184,299.9850464,299.9850464,21601.234375,21610.888671875,57.2730481181214,20.4933062157051,27.844467,0,0,0,40,4449,300.1052,21606.0615234375,,,,,,,,,,,,,0,,,,-0.00245,,,,,,299.9850464,,,,
,28127162.94,299.9898071,16973.9619140625,0.00908987293613262,0.000433624285175862,1,0.999253354069792,40.0298881530762,1.97297290300806,27.3100007325411,0.091542592776098,0.0757622193182818,2.5,0.0052020989610777,0.00908616268537477,0.00520796334262756,299.9898071,299.9898071,16963.87890625,16984.044921875,57.2566339192176,20.490444613041,27.464817,0,0,0,40,4449,300.109,16973.9619140625,,,,,,,,,,,,,0,,,,0,,,,,,299.9898071,,,,
,28127258.07,299.9850464,12218.943359375,0.00756772579050215,0.000454507774188095,1,0.999253354069792,40.0298881530762,1.97285170064824,27.3100007325411,0.0758945310971061,0.0648856559727779,2.5,0.00449324231461315,0.00756452790207215,0.0044981245909726,299.9850464,299.9850464,12206.4404296875,12231.4462890625,57.1644017539484,20.492547255012,27.844467,0,0,0,40,4449,300.12495,12218.943359375,,,,,,,,,,,,,0,,,,-0.00245,,,,,,299.9850464,,,,
,28127351.065,299.993042,7568.84106445313,0.0061992967562825,0.000281376826569884,1,0.999253354069792,40.0298881530762,1.97299156714629,27.3100007325411,0.0625951584967573,0.0507320298831877,2.5,0.00346389753017382,0.006196816952925,0.00346790532494389,299.993042,299.993042,7558.82177734375,7578.8603515625,57.3308886285445,20.4907280481807,27.844467,0,0,0,40,4449,300.13265,7568.84106445313,,,,,,,,,,,,,0,,,,-0.00245,,,,,,299.993042,,,,
,28127442.69,299.990387,2990.70642089844,0.00398462908244376,0.000218836096914491,1,0.999253354069792,40.0298881530762,1.9732468337864,27.3100007325411,0.0401417696572046,0.0331695554757214,2.5,0.00227627607019003,0.00398300130668332,0.00227885257482214,299.990387,299.990387,2985.6142578125,2995.79858398438,57.2636685758907,20.4882741416669,27.844467,0,0,0,40,4449,300.13375,2990.70642089844,,,,,,,,,,,,,0,,,,0,,,,,,299.990387,,,,
,28127504.205,299.98744205,-0.243580371141434,-5.15335985284379E-5,2.12029265947116E-6,1,0.999253354069792,40.0298881530762,1.97320106862142,27.3100007325411,-0.00055347056390889,-0.000230420534686442,0.25,-1.16829974013864E-5,-5.152432904081E-5,-1.17168552139316E-5,299.9869385,299.9879456,-0.243580371141434,-0.243580371141434,57.2574155477368,20.4891679191996,27.464817,0,0,0,40,4417,300.13985,-0.243580371141434,,,,,,,,,,,,,0,,,,0,,,,,,299.98744205,,,,