File: data/monolayers/nanoparticles/Ol_CoFe_C/vsm/data_dispersion/DD67_HYST_10K.DAT
[Header]
; VSM Data File (default extension .dat)
; Copyright (c) 2003-2013, Quantum Design, Inc. All rights reserved.
TITLE,
FILEOPENTIME,28132172.34,11/22/2018,10:30 pm
BYAPP,VSM,2.0,2.0
INFO,PPMS VSM Option Release 1.4.10 Build 1,APPNAME
INFO,Quantum Design Linear Motor Servo Controller,MOTOR_MODULE_NAME
INFO,3101-100 M1,MOTOR_HW_VERSION
INFO,MMC1014,MOTOR_SERIAL_NUMBER
INFO,SRV No X-over 01.03.11,MOTOR_SOFTWARE_VERSION
INFO,Quantum Design VSM Detection Module,VSM_MODULE_NAME
INFO,3101-150 F0,VSM_HW_VERSION
INFO,VSM707,VSM_SERIAL_NUMBER
INFO,VSM No X-over 01.02.05 May 20 2008 13:51:47,VSM_SOFTWARE_VERSION
INFO,704,PREAMP_SERIAL_NUMBER
INFO,822,COIL_SERIAL_NUMBER
INFO,0,MOMENT_UNITS
INFO,CoFe2O4,SAMPLE_MATERIAL
INFO,dispersion in ampulle,SAMPLE_COMMENT
INFO,,SAMPLE_MASS
INFO,,SAMPLE_VOLUME
INFO,,SAMPLE_MOLECULAR_WEIGHT
INFO,,SAMPLE_SIZE
INFO,,SAMPLE_SHAPE
DATATYPE,COMMENT,1
DATATYPE,TIME,2
STARTUPAXIS,X,2
STARTUPAXIS,Y1,5
[Data]
Comment,Time Stamp (sec),Temperature (K),Magnetic Field (Oe),Moment (emu),M. Std. Err. (emu),Transport Action,Averaging Time (sec),Frequency (Hz),Peak Amplitude (mm),Center Position (mm),Coil Signal' (mV),Coil Signal" (mV),Range (mV),M. Quad. Signal (emu),M. Raw' (emu),M. Raw" (emu),Min. Temperature (K),Max. Temperature (K),Min. Field (Oe),Max. Field (Oe),Mass (grams),Motor Lag (deg),Pressure (Torr),VSM Status (code),Motor Status (code),Measure Status (code),Measure Count,PPMS Status (code),System Temp. (K),System Field (Oe),Sample Position (deg),Bridge 1 Resistance (ohms),Bridge 1 Excitation (에),Bridge 2 Resistance (ohms),Bridge 2 Excitation (에),Bridge 3 Resistance (ohms),Bridge 3 Excitation (에),Bridge 4 Resistance (ohms),Bridge 4 Excitation (에),Signal 1 Vin (V),Signal 2 Vin (V),Digital Inputs (code),Drive 1 Iout (mA),Drive 1 Ipower (W),Drive 2 Iout (mA),Drive 2 Ipower (W),Pressure (),Map 20 (),Map 21 (),Map 22 (),Map 23 (),Map 24 (),Map 25 (),Map 26 (),Map 27 (),Map 28 (),Map 29 ()
,28132189.11,9.9961271,-0.1674614995718,,,2,,,,27.3799994391203,,,,,,,9.9961271,9.9961271,-0.1674614995718,-0.1674614995718,,,12.658426,,,,-99999999,4369,10.0009,-0.1674614995718,,,,,,,,,,,,,,,,,,,,,,,9.9961271,,,,
,28132354.515,10.0219431,4695.78076171875,0.00290081532946196,1.62718414466966E-6,1,0.999253354069792,40.0298881530762,1.9804298037605,27.3599997162819,0.0322957481612893,0.00599766426432133,0.25,2.20210581476279E-5,0.0028847817122074,3.67118359336352E-5,10.0219431,10.0219431,4685.984375,4705.5771484375,56.1326521085636,20.6736283947725,11.899124,0,0,0,40,4449,9.9233,4695.78076171875,,,,,,,,,,,,,0,,,,-0.00245,,,,,,10.0219431,,,,
,28132451.175,10.01477675,9522.52294921875,0.00599837838292404,1.58626611759805E-6,1,0.999253354069792,40.0298881530762,1.98084968584132,27.3599997162819,0.0668178665899229,0.0124172093570573,0.25,4.41509972088711E-5,0.00596734841175772,7.66677085237285E-5,10.0129929,10.0165606,9517.283203125,9527.7626953125,56.4968909985252,20.6758396613842,12.278775,0,0,0,40,4449,9.9361,9522.52294921875,,,,,,,,,,,,,0,,,,-0.00245,,,,,,10.01477675,,,,
,28132550.22,10.0124922,14472.359375,0.00934414890497518,1.93334971427729E-6,1,0.999253354069792,40.0298881530762,1.98159802755964,27.3599997162819,0.104163802180144,0.0193872233884412,0.25,6.79891005767734E-5,0.0092997150105455,0.00012205094835308,10.0124922,10.0124922,14469.857421875,14474.861328125,56.8103240347368,20.6642316193861,12.278775,0,0,0,40,4449,9.9302,14472.359375,,,,,,,,,,,,,0,,,,0,,,,,,10.0124922,,,,
,28132650.485,10.0023899,19487.1552734375,0.0132036928841009,2.06952486975343E-6,1,0.999253354069792,40.0298881530762,1.98182213251831,27.3599997162819,0.14729946256486,0.0273733874300236,2.5,8.78800296619309E-5,0.0131470945252199,0.000168890298776336,10.0023899,10.0023899,19482.10546875,19492.205078125,56.7087123272368,20.6542871206308,12.278775,0,0,0,40,4449,9.9218,19487.1552734375,,,,,,,,,,,,,0,,,,-0.00245,,,,,,10.0023899,,,,
,28132749.765,10.0020084,24447.365234375,0.0174888917004832,2.75211531969445E-6,1,0.999253354069792,40.0298881530762,1.98261097038791,27.3599997162819,0.195265327790101,0.036345996223688,2.5,0.000116177315355914,0.0174225025482356,0.000228891398463377,10.0020084,10.0020084,24439.9765625,24454.75390625,56.6555615879291,20.6500179258369,11.899124,0,0,0,40,4449,9.91835,24447.365234375,,,,,,,,,,,,,0,,,,-0.00245,,,,,,10.0020084,,,,
,28132847.6,10.0008259,29337.44140625,0.0219908552412598,2.9431428835296E-6,1,0.999253354069792,40.0298881530762,1.98247999695423,27.3599997162819,0.245631770382757,0.0457639109809523,2.5,0.000144078706995914,0.0219184595154999,0.000291656898932186,10.0008259,10.0008259,29332.544921875,29342.337890625,56.6758839294291,20.6476135685169,12.278775,0,0,0,40,4449,9.92375,29337.44140625,,,,,,,,,,,,,0,,,,-0.00245,,,,,,10.0008259,,,,
,28132945.195,10.0027661,34215.07421875,0.0266268527359558,3.67152861300063E-6,1,0.999253354069792,40.0298881530762,1.98179771679311,27.3599997162819,0.29746884808049,0.0554302045252598,2.5,0.00016941748948043,0.0265528943810618,0.000354055906723418,10.0023813,10.0031509,34205.22265625,34224.92578125,56.5945945634291,20.6602401794991,12.278775,0,0,0,40,4449,9.92105,34215.07421875,,,,,,,,,,,,,0,,,,-0.00245,,,,,,10.0027661,,,,
,28133043.205,10.0008125,39114.765625,0.0310700305893857,3.86120989925676E-6,1,0.999253354069792,40.0298881530762,1.9821480838554,27.3599997162819,0.347333590913261,0.0647971815235106,2.5,0.000198779466636877,0.0309998460396371,0.000419839237505485,10.0008125,10.0008125,39112.53125,39117,56.6305494753137,20.6549077872558,12.278775,0,0,0,40,4449,9.9209,39114.765625,,,,,,,,,,,,,0,,,,0,,,,,,10.0008125,,,,
,28133139.875,9.9974594,43945,0.0350884110042173,4.51293526878046E-6,1,0.999253354069792,40.0298881530762,1.98171844092837,27.3599997162819,0.392370096721367,0.0732225979524404,2.5,0.000221962865272385,0.0350270016121874,0.000476414978362223,9.9974594,9.9974594,43935.00390625,43954.99609375,56.4179465180829,20.6599349440278,11.899124,0,0,0,40,4449,9.92105,43945,,,,,,,,,,,,,0,,,,0.00245,,,,,,9.9974594,,,,
,28133237.51,9.9983282,48825.400390625,0.0386957165810592,3.71044663852933E-6,1,0.999253354069792,40.0298881530762,1.98289912884131,27.3599997162819,0.433177666578204,0.080814617047261,2.5,0.000239217007570613,0.0386475602684986,0.000523647474100152,9.9983282,9.9983282,48822.84765625,48827.953125,56.6438371601406,20.6861849674951,11.519473,0,0,0,40,4449,9.9224,48825.400390625,,,,,,,,,,,,,0,,,,-0.00245,,,,,,9.9983282,,,,
,28133333.465,9.9990683,53620.291015625,0.041785883040126,2.645181079568E-6,1,0.999253354069792,40.0298881530762,1.98250588241405,27.3599997162819,0.467906927634328,0.0872996042089348,2.5,0.000256550916278896,0.0417540583175073,0.000566240047491616,9.9990683,9.9990683,53615.0859375,53625.49609375,56.6008475915829,20.6906697519594,11.899124,0,0,0,40,4449,9.92515,53620.291015625,,,,,,,,,,,,,0,,,,-0.0049,,,,,,9.9990683,,,,
,28133428.485,9.996851,58371.212890625,0.0444612193504117,4.45944397537461E-6,1,0.999253354069792,40.0298881530762,1.9830856567244,27.3599997162819,0.498223305522802,0.0930171061191677,2.5,0.000277267645358403,0.0444478608986301,0.000608051352107953,9.996851,9.996851,58363.8046875,58378.62109375,56.7407590965252,20.6777185614704,11.899124,0,0,0,40,4449,9.92775,58371.212890625,,,,,,,,,,,,,0,,,,0,,,,,,9.996851,,,,
,28133523.555,9.9941921,63124.013671875,0.0468236233205734,5.52983787740619E-6,1,0.999253354069792,40.0298881530762,1.98326362556063,27.3599997162819,0.524968700571253,0.0980387114784784,2.5,0.00029470523012543,0.046830297892631,0.000643083588121533,9.9941921,9.9941921,63116.609375,63131.41796875,56.7837486650829,20.6748191680405,12.278775,0,0,0,40,4449,9.93395,63124.013671875,,,,,,,,,,,,,0,,,,-0.0049,,,,,,9.9941921,,,,
,28133618.515,9.9952822,67869.359375,0.0489178315948564,5.25781345326029E-6,1,0.999253354069792,40.0298881530762,1.9835972315459,27.3599997162819,0.548761630385333,0.102517947868326,2.5,0.000312443751577914,0.0489454372544528,0.000675221211908227,9.9952822,9.9952822,67859.578125,67879.140625,56.8189219484483,20.6718177044747,11.519473,0,0,0,40,4449,9.9379,67869.359375,,,,,,,,,,,,,0,,,,0.00245,,,,,,9.9952822,,,,
,28133713.585,9.9954748,72622,0.0507950595895105,4.48895409227814E-6,1,0.999253354069792,40.0298881530762,1.98403674537188,27.3599997162819,0.570164025879463,0.106548884106195,2.5,0.000329831295642231,0.0508440955630095,0.000704224100013498,9.9954748,9.9954748,72616.9609375,72627.0390625,56.8470605751406,20.6652296454604,11.899124,0,0,0,40,4449,9.94355,72622,,,,,,,,,,,,,0,,,,0,,,,,,9.9954748,,,,
,28133808.335,9.9956808,77359.95703125,0.0524909934230818,3.01278537026826E-6,1,0.999253354069792,40.0298881530762,1.98300004513517,27.3599997162819,0.589129953152022,0.110087979920745,2.5,0.000343995884652009,0.0525615327074002,0.000727568138139575,9.9956808,9.9956808,77355.046875,77364.8671875,56.8501870892175,20.6823816264855,11.899124,0,0,0,40,4449,9.9457,77359.95703125,,,,,,,,,,,,,0,,,,0,,,,,,9.9956808,,,,
,28133904.445,9.99353645,82160.98046875,0.0540461654844024,5.48194866247138E-6,1,0.999253354069792,40.0298881530762,1.98350891905272,27.3599997162819,0.606940057977121,0.11348423212028,2.5,0.000364611571300078,0.0541382757818108,0.000755269472555868,9.993268,9.9938049,82153.484375,82168.4765625,56.8861420011022,20.6749572282854,11.899124,0,0,0,40,4449,9.94725,82160.98046875,,,,,,,,,,,,,0,,,,-0.0049,,,,,,9.99353645,,,,
,28133995.715,9.9935656,86724.1640625,0.0553992116206935,4.45391323934049E-6,1,0.999253354069792,40.0298881530762,1.98452498325385,27.3599997162819,0.62262925750329,0.116478934664578,2.5,0.000384073969574045,0.0555114812575431,0.000779697372459958,9.9935656,9.9935656,86716.46875,86731.859375,56.8814522299868,20.6612611493615,11.899124,0,0,0,40,4449,9.9553,86724.1640625,,,,,,,,,,,,,0,,,,-0.00245,,,,,,9.9935656,,,,
,28134101.19,9.9959898,88970.08203125,0.0561491694896264,2.58240273243273E-6,1,0.999253354069792,40.0298881530762,1.98484653338648,27.3599997162819,0.63125611615612,0.118065061534912,2.5,0.000389611974215654,0.0562714994866691,0.000787981772020235,9.9959898,9.9959898,88962.6328125,88977.53125,57.027616763083,20.6569390149545,12.278775,0,0,0,40,4449,9.9592,88970.08203125,,,,,,,,,,,,,0,,,,0.0049,,,,,,9.9959898,,,,
,28134190.435,9.9970493,84511.6953125,0.0551555338814703,3.42855792547079E-6,1,0.999253354069792,40.0298881530762,1.98424209256627,27.3599997162819,0.619713591229154,0.115917592485838,2.5,0.0003784993680721,0.0552588180198821,0.00077477918308944,9.9970493,9.9970493,84509.140625,84514.25,56.9721211382176,20.66756795164,11.899124,0,0,0,40,4449,9.9577,84511.6953125,,,,,,,,,,,,,0,,,,0.00245,,,,,,9.9970493,,,,
,28134284.89,10.0013313,79787.875,0.0540127449887717,3.79766307561003E-6,1,0.999253354069792,40.0298881530762,1.98403229676905,27.3599997162819,0.606609867425507,0.113429917552523,2.5,0.000362680745506896,0.0540952986878905,0.000755309688393492,10.0013313,10.0013313,79775.1015625,79800.6484375,56.7649895806214,20.6673569272061,11.139823,0,0,0,40,4449,9.9594,79787.875,,,,,,,,,,,,,0,,,,0,,,,,,10.0013313,,,,
,28134383.59,10.0038195,74854.21484375,0.0527588430220057,4.36607113047359E-6,1,0.999253354069792,40.0298881530762,1.98366511193117,27.3599997162819,0.592203947332455,0.110691882662362,2.5,0.00034627195809688,0.0528193081643955,0.000733677400501792,10.0038195,10.0038195,74846.796875,74861.6328125,56.8056342636214,20.6777740967657,11.139823,0,0,0,40,4449,9.95305,74854.21484375,,,,,,,,,,,,,0,,,,0.00245,,,,,,10.0038195,,,,
,28134481.205,10.0025034,69973.640625,0.0514342941359481,2.63737928572357E-6,1,0.999253354069792,40.0298881530762,1.98502809828467,27.3599997162819,0.577491861489466,0.107892147201626,2.5,0.00033014960458592,0.0514725952997372,0.000710679275708875,10.0025034,10.0025034,69968.78125,69978.5,57.0018230219483,20.6503557537772,11.519473,0,0,0,40,4449,9.9462,69973.640625,,,,,,,,,,,,,0,,,,0,,,,,,10.0025034,,,,
,28134579.205,9.9998884,65075.798828125,0.050017864191298,5.28057527219025E-6,1,0.999253354069792,40.0298881530762,1.98551484117234,27.3599997162819,0.561482725111754,0.104889471198461,2.5,0.000318019184967166,0.0500337872849499,0.000689805486855488,9.9998884,9.9998884,65070.68359375,65080.9140625,56.9846271945253,20.6395721288579,11.899124,0,0,0,40,4449,9.948,65075.798828125,,,,,,,,,,,,,0,,,,0.0049,,,,,,9.9998884,,,,
,28134676.915,10.001832,60192.515625,0.0484887013118956,4.56778289459407E-6,1,0.999253354069792,40.0298881530762,1.98531505713705,27.3599997162819,0.544019705666548,0.101635621777218,2.5,0.000308232874132662,0.0484824401942567,0.000669139370038587,10.001832,10.001832,60187.07421875,60197.95703125,57.0455942190253,20.6455802217424,11.519473,0,0,0,40,4449,9.94775,60192.515625,,,,,,,,,,,,,0,,,,0.00245,,,,,,10.001832,,,,
,28134775.35,10.00145295,55269.521484375,0.0468261595609429,3.75499404478683E-6,1,0.999253354069792,40.0298881530762,1.98539680586213,27.3599997162819,0.525144901692197,0.098078404025862,2.5,0.000295562071205335,0.0467980364308233,0.000643225088819107,10.001442,10.0014639,55264.39453125,55274.6484375,56.9174071418714,20.639888340798,11.519473,0,0,0,40,4449,9.9444,55269.521484375,,,,,,,,,,,,,0,,,,0.0049,,,,,,10.00145295,,,,
,28134872,10.0023184,50441.8046875,0.0450823860775037,3.29033864179567E-6,1,0.999253354069792,40.0298881530762,1.98530704189616,27.3599997162819,0.50532542719483,0.0943674188614465,2.5,0.000285698451344079,0.0450336380068873,0.000618163318448773,10.0023184,10.0023184,50431.69140625,50451.91796875,57.1581487257945,20.6364948456555,11.139823,0,0,0,40,4449,9.9436,50441.8046875,,,,,,,,,,,,,0,,,,0.0049,,,,,,10.0023184,,,,
,28134968.02,10.0032635,45642.216796875,0.0431936572619483,4.21932491195615E-6,1,0.999253354069792,40.0298881530762,1.98535637581469,27.3599997162819,0.483946917266052,0.0902634310294467,2.5,0.000267451672697851,0.043125738996618,0.000582358692454745,10.0032635,10.0032635,45634.4609375,45649.97265625,57.1925403806407,20.6394161230452,11.139823,0,0,0,40,4449,9.9425,45642.216796875,,,,,,,,,,,,,0,,,,0.00245,,,,,,10.0032635,,,,
,28135064.795,10.0030937,40803.9375,0.0411138053690403,4.03419635637577E-6,1,0.999253354069792,40.0298881530762,1.98526014461254,27.3599997162819,0.460389692389573,0.0858632223317094,2.5,0.000258798414866865,0.0410282985670256,0.000553481599790421,10.0030937,10.0030937,40796.60546875,40811.26953125,57.2183341217753,20.6451405614091,11.519473,0,0,0,40,4449,9.9392,40803.9375,,,,,,,,,,,,,0,,,,-0.0049,,,,,,10.0030937,,,,
,28135160.75,10.0024137,36009.01171875,0.038858141279387,3.1919255746922E-6,1,0.999253354069792,40.0298881530762,1.98551664990095,27.3599997162819,0.434983094864689,0.0810086807650445,2.5,0.000240608329095135,0.0387576383834694,0.000512843639818249,10.0024137,10.0024137,35994.328125,36023.6953125,56.953362053756,20.640842729952,11.519473,0,0,0,40,4449,9.93615,36009.01171875,,,,,,,,,,,,,0,,,,0,,,,,,10.0024137,,,,
,28135258.295,10.0022402,31133.9892578125,0.036331685532913,3.65357933476053E-6,1,0.999253354069792,40.0298881530762,1.98523739669013,27.3599997162819,0.406441161012607,0.0756660001429912,2.5,0.000229902578587949,0.0362189701926678,0.000476908806773789,10.0021105,10.0023699,31131.69140625,31136.287109375,57.2120810936214,20.6463254596769,10.760172,0,0,0,40,4449,9.9348,31133.9892578125,,,,,,,,,,,,,0,,,,0,,,,,,10.0022402,,,,
,28135352.195,10.0017691,26438.6943359375,0.0336663849922864,3.2676267177885E-6,1,0.999253354069792,40.0298881530762,1.98556973718031,27.3599997162819,0.376516193756458,0.0699993988217875,2.5,0.000212651269117076,0.0335454951955285,0.000433476146732372,10.0017691,10.0017691,26433.5859375,26443.802734375,57.0291800201214,20.6401278396593,11.519473,0,0,0,40,4449,9.93485,26438.6943359375,,,,,,,,,,,,,0,,,,0,,,,,,10.0017691,,,,
,28135446.69,10.0019741,21718.26171875,0.030694420231826,2.75642770074572E-6,1,0.999253354069792,40.0298881530762,1.98442698584241,27.3599997162819,0.342931681888134,0.0637184664609565,2.5,0.000199062914712448,0.0305695546938482,0.000391821755643307,10.0019741,10.0019741,21710.904296875,21725.619140625,57.0518472471791,20.658439991824,11.519473,0,0,0,40,4449,9.93235,21718.26171875,,,,,,,,,,,,,0,,,,0,,,,,,10.0019741,,,,
,28135545.045,10.0002565,16801.3134765625,0.0273181411183975,1.2182816914152E-6,1,0.999253354069792,40.0298881530762,1.98436236667019,27.3599997162819,0.305063368463421,0.0566393752578732,2.5,0.000182223622240597,0.0271941097264252,0.000344854554570954,10.0002565,10.0002565,16793.921875,16808.705078125,57.2245871499291,20.6561841037379,11.519473,0,0,0,40,4449,9.9341,16801.3134765625,,,,,,,,,,,,,0,,,,0.00245,,,,,,10.0002565,,,,
,28135640.615,9.9999151,12026.6040039062,0.0236783694870257,1.79676985616625E-6,1,0.999253354069792,40.0298881530762,1.98421889574388,27.3599997162819,0.26429876626005,0.0489998379462866,2.5,0.000159826731469391,0.0235608201562661,0.000292659847423855,9.9999151,9.9999151,12021.5634765625,12031.64453125,57.1620568683907,20.6633341145012,10.760172,0,0,0,40,4449,9.93455,12026.6040039062,,,,,,,,,,,,,0,,,,-0.0049,,,,,,9.9999151,,,,
,28135735.585,9.9971466,7278.6376953125,0.0197397608198572,2.21483000436385E-6,1,0.999253354069792,40.0298881530762,1.9847597772346,27.3599997162819,0.220314189697657,0.0408168053706442,2.5,0.00013768113114825,0.0196342935528962,0.000241432082714676,9.9971466,9.9971466,7273.37451171875,7283.90087890625,56.9220969129868,20.649455812543,11.519473,0,0,0,40,4449,9.9373,7278.6376953125,,,,,,,,,,,,,0,,,,-0.0049,,,,,,9.9971466,,,,
,28135828.995,10.0001469,2607.88696289062,0.0155320773418156,2.54440363508111E-6,1,0.999253354069792,40.0298881530762,1.98474006809053,27.3599997162819,0.17330167725267,0.0320760728255173,2.5,0.000110775234591293,0.0154442473204396,0.000187246897681522,10.0001469,10.0001469,2600.29272460938,2615.48120117187,57.085457273506,20.6504149545357,10.760172,0,0,0,40,4449,9.93485,2607.88696289062,,,,,,,,,,,,,0,,,,0,,,,,,10.0001469,,,,
,28135923.165,9.9990835,-2096.22900390625,0.0106063735618058,2.76816316283443E-6,1,0.999253354069792,40.0298881530762,1.98450176707945,27.3599997162819,0.11832646031722,0.0218941361560856,2.5,7.54132973435272E-5,0.0105460922603049,0.000127285667015457,9.9990835,9.9990835,-2098.8369140625,-2093.62109375,57.2621053188522,20.6538833626104,10.760172,0,0,0,40,4449,9.9353,-2096.22900390625,,,,,,,,,,,,,0,,,,0,,,,,,9.9990835,,,,
,28136017.945,9.9989614,-6829.78125,0.00526221805824684,2.45920100990258E-6,1,0.999253354069792,40.0298881530762,1.98435446193397,27.3599997162819,0.0587206222626864,0.01086296598255,2.5,3.54908612640522E-5,0.00523393601192432,6.29806793861639E-5,9.9989614,9.9989614,-6842.3486328125,-6817.2138671875,57.0964000727753,20.6540759404393,11.139823,0,0,0,40,4449,9.9371,-6829.78125,,,,,,,,,,,,,0,,,,0.00245,,,,,,9.9989614,,,,
,28136114.46,9.9997187,-11655.5610351562,4.39856626077615E-5,2.48812436756666E-6,1,0.999253354069792,40.0298881530762,1.98477745447998,27.3599997162819,0.000491675127983729,8.73735404350625E-5,0.25,-2.93588863845362E-8,4.37677580689461E-5,2.17808954237293E-7,9.9997187,9.9997187,-11660.2890625,-11650.8330078125,56.9752476522945,20.6540296735855,10.760172,0,0,0,40,4449,9.9367,-11655.5610351562,,,,,,,,,,,,,0,,,,-0.00245,,,,,,9.9997187,,,,
,28136209.63,10.0004435,-16413.369140625,-0.00529025193272154,2.71140961408681E-6,1,0.999253354069792,40.0298881530762,1.98466419462202,27.3599997162819,-0.0590696843675502,-0.0109998655849293,0.25,-3.82633319776236E-5,-0.00526602569199777,-6.96008326185405E-5,10.0004435,10.0004435,-16418.302734375,-16408.435546875,57.068261446083,20.6495505374978,11.519473,0,0,0,40,4449,9.93565,-16413.369140625,,,,,,,,,,,,,0,,,,0,,,,,,10.0004435,,,,
,28136305.5,9.9998379,-21205.361328125,-0.0109113274647923,2.61628428510465E-6,1,0.999253354069792,40.0298881530762,1.98514199861043,27.3599997162819,-0.121941400607789,-0.0226604614889627,2.5,-7.13814846233211E-5,-0.0108663852395956,-0.000139547733546734,9.9998379,9.9998379,-21210.044921875,-21200.677734375,56.9916618511983,20.6532441361192,10.760172,0,0,0,40,4449,9.93595,-21205.361328125,,,,,,,,,,,,,0,,,,0.0049,,,,,,9.9998379,,,,
,28136402.375,10.0014467,-26044.921875,-0.0167100567234024,2.90401806119434E-6,1,0.999253354069792,40.0298881530762,1.98495465388077,27.3599997162819,-0.186813013353041,-0.034760230458626,2.5,-0.000108429106681011,-0.0166493599933669,-0.000217658720326906,10.0014467,10.0014467,-26052.763671875,-26037.080078125,57.1761261817368,20.6507410377974,11.519473,0,0,0,40,4449,9.9347,-26044.921875,,,,,,,,,,,,,0,,,,0.00245,,,,,,10.0014467,,,,
,28136497.22,9.9995079,-30787.8642578125,-0.0222729087631205,2.86545334223943E-6,1,0.999253354069792,40.0298881530762,1.98534699290058,27.3599997162819,-0.249163733767774,-0.0464232851907955,2.5,-0.000144506283436448,-0.0222029755164,-0.000295557394876173,9.9995079,9.9995079,-30795.18359375,-30780.544921875,56.9510171681983,20.6469627141387,11.139823,0,0,0,40,4449,9.93505,-30787.8642578125,,,,,,,,,,,,,0,,,,0,,,,,,9.9995079,,,,
,28136592.905,10.0000219,-35567.705078125,-0.0274731750303087,3.2331729848055E-6,1,0.999253354069792,40.0298881530762,1.9852958281251,27.3599997162819,-0.307489800552269,-0.0572730091187799,2.5,-0.000171247405466943,-0.0274008257815299,-0.000363252278602394,10.0000219,10.0000219,-35572.8125,-35562.59765625,57.0166739638137,20.6395302045843,10.760172,0,0,0,40,4449,9.9346,-35567.705078125,,,,,,,,,,,,,0,,,,-0.0049,,,,,,10.0000219,,,,
,28136688.025,9.9986858,-40322.556640625,-0.032189560705807,1.58251403747038E-6,1,0.999253354069792,40.0298881530762,1.9857598822925,27.3599997162819,-0.360526797882791,-0.067227598857408,2.5,-0.000202110420292357,-0.0321209831539945,-0.000432365999399806,9.9986858,9.9986858,-40330.16796875,-40314.9453125,56.9517987967176,20.6341910908806,11.139823,0,0,0,40,4449,9.9362,-40322.556640625,,,,,,,,,,,,,0,,,,-0.0049,,,,,,9.9986858,,,,
,28136782.57,9.9976149,-45047.763671875,-0.0362232445410464,4.48820333662798E-6,1,0.999253354069792,40.0298881530762,1.98580952642684,27.3599997162819,-0.405916410125502,-0.0756894627891179,2.5,-0.000222998997006381,-0.0361640588224848,-0.000486619391133498,9.9976149,9.9976149,-45057.47265625,-45038.0546875,57.1268835850253,20.633778522772,11.139823,0,0,0,40,4449,9.9405,-45047.763671875,,,,,,,,,,,,,0,,,,0,,,,,,9.9976149,,,,
,28136877.37,9.996521,-49784.919921875,-0.0397459434644376,4.18239062137695E-6,1,0.999253354069792,40.0298881530762,1.98579192946154,27.3599997162819,-0.445597857893666,-0.0831329130661642,2.5,-0.000245268228303687,-0.0397003681926077,-0.000538011894258382,9.996521,9.996521,-49790.09765625,-49779.7421875,57.1722180391407,20.6325179698207,11.139823,0,0,0,40,4449,9.94075,-49784.919921875,,,,,,,,,,,,,0,,,,-0.0049,,,,,,9.996521,,,,
,28136973.11,9.9951296,-54569.642578125,-0.0428111590903879,2.53505817251516E-6,1,0.999253354069792,40.0298881530762,1.98629066155345,27.3599997162819,-0.480293527314111,-0.0896874369176977,2.5,-0.000269168415478607,-0.0427825173227353,-0.000586799784638337,9.9951296,9.9951296,-54572.08984375,-54567.1953125,57.0635716749676,20.6328919774868,10.38052,0,0,0,40,4449,9.9475,-54569.642578125,,,,,,,,,,,,,0,,,,0,,,,,,9.9951296,,,,
,28137069.385,9.9956808,-59382.201171875,-0.0454886221797231,3.18501616836162E-6,1,0.999253354069792,40.0298881530762,1.9863981198771,27.3599997162819,-0.510582271756102,-0.0954172563536322,2.5,-0.000291614568995444,-0.0454792606868567,-0.000630146460783485,9.9956808,9.9956808,-59389.796875,-59374.60546875,57.6669888918138,20.6289748580021,11.139823,0,0,0,40,4449,9.9512,-59382.201171875,,,,,,,,,,,,,0,,,,0,,,,,,9.9956808,,,,
,28137168.625,9.9960718,-64342.240234375,-0.0478724931517715,2.4954529358797E-6,1,0.999253354069792,40.0298881530762,1.9861379215994,27.3599997162819,-0.537514027576889,-0.100476362110039,2.5,-0.000309729079456215,-0.0478845414873847,-0.000665721918417063,9.9960718,9.9960718,-64347.26953125,-64337.2109375,57.1284468420637,20.6351941307881,10.760172,0,0,0,40,4449,9.9547,-64342.240234375,,,,,,,,,,,,,0,,,,-0.00245,,,,,,9.9960718,,,,
,28137264.57,9.9966927,-69136.7265625,-0.0499060132962193,2.6613732459099E-6,1,0.999253354069792,40.0298881530762,1.98640324133427,27.3599997162819,-0.560658382231527,-0.104776702907908,2.5,-0.000322455852474026,-0.0499396021163611,-0.000692055871904551,9.9966927,9.9966927,-69144.109375,-69129.34375,57.0713879601599,20.6307140280935,11.139823,0,0,0,40,4449,9.95825,-69136.7265625,,,,,,,,,,,,,0,,,,-0.00245,,,,,,9.9966927,,,,
,28137361.735,9.9958687,-73993.7265625,-0.0517476625981889,4.73226401961111E-6,1,0.999253354069792,40.0298881530762,1.98685142428689,27.3599997162819,-0.581698725417062,-0.108762382138806,2.5,-0.000341938638355713,-0.0518033670487188,-0.000722499120325541,9.9958687,9.9958687,-74001.3203125,-73986.1328125,57.007294421583,20.6203551273385,10.760172,0,0,0,40,4449,9.9611,-73993.7265625,,,,,,,,,,,,,0,,,,0,,,,,,9.9958687,,,,
,28137456.935,9.9963703,-78750.8671875,-0.0533728898003894,3.83994732468534E-6,1,0.999253354069792,40.0298881530762,1.9865137110014,27.3599997162819,-0.600098166308555,-0.112181266793262,2.5,-0.000354760165759028,-0.0534502947186096,-0.000743632917272174,9.9963703,9.9963703,-78758.15625,-78743.578125,57.3879475104484,20.6249681403433,11.139823,0,0,0,40,4449,9.9651,-78750.8671875,,,,,,,,,,,,,0,,,,-0.00245,,,,,,9.9963703,,,,
,28137553.12,9.9954157,-83558.12890625,-0.0548737510958252,3.56559969371172E-6,1,0.999253354069792,40.0298881530762,1.98615004032085,27.3599997162819,-0.617070791715586,-0.115430279772878,2.5,-0.000376128030588445,-0.0549727802073574,-0.000771373349471478,9.9954157,9.9954157,-83560.6328125,-83555.625,57.5896076684099,20.6272411675163,10.760172,0,0,0,40,4449,9.9695,-83558.12890625,,,,,,,,,,,,,0,,,,-0.0049,,,,,,9.9954157,,,,
,28137642.535,9.9966125,-88025.22265625,-0.0561618681324036,4.85821370529032E-6,1,0.999253354069792,40.0298881530762,1.98585091096284,27.3599997162819,-0.631674955508013,-0.118081333989816,2.5,-0.000383208050732398,-0.0562807086581117,-0.000782766750446409,9.9966125,9.9966125,-88032.7578125,-88017.6875,57.5419283287369,20.6339628831725,10.38052,0,0,0,40,4449,9.97185,-88025.22265625,,,,,,,,,,,,,0,,,,0.0049,,,,,,9.9966125,,,,
,28137744.135,9.9996119,-87898.6484375,-0.0563009201467271,4.96532205789009E-6,1,0.999253354069792,40.0298881530762,1.98602658538944,27.3599997162819,-0.633283369121564,-0.118403051341416,2.5,-0.000385810918466507,-0.0564195609081136,-0.000786510375972819,9.9996119,9.9996119,-87903.5078125,-87893.7890625,57.4465696493907,20.6318560481119,10.760172,0,0,0,40,4449,9.97485,-87898.6484375,,,,,,,,,,,,,0,,,,0,,,,,,9.9996119,,,,
,28137831.92,10.00271035,-83511.23046875,-0.0552985380761962,5.1484919109573E-6,1,0.999253354069792,40.0298881530762,1.9854899325728,27.3599997162819,-0.621649076343632,-0.116281359001543,2.5,-0.000378529566510247,-0.0553981507005322,-0.000776882043119681,10.0026941,10.0027266,-83521.1328125,-83501.328125,57.5489629854099,20.6416845585078,10.38052,0,0,0,40,4449,9.9719,-83511.23046875,,,,,,,,,,,,,0,,,,0,,,,,,10.00271035,,,,
,28137921.12,10.0026665,-79055.796875,-0.0542314446708006,3.21852097355399E-6,1,0.999253354069792,40.0298881530762,1.98521372440678,27.3599997162819,-0.609375502266362,-0.113966119463547,2.5,-0.000365097413860376,-0.0543113204796734,-0.000759967242227941,10.0026665,10.0026665,-79058.4140625,-79053.1796875,57.3879475104484,20.6425018420263,10.38052,0,0,0,40,4449,9.9677,-79055.796875,,,,,,,,,,,,,0,,,,-0.0049,,,,,,10.0026665,,,,
,28138008.43,10.00316425,-74690.984375,-0.0531333549803345,4.30357609436613E-6,1,0.999253354069792,40.0298881530762,1.98513036601903,27.3599997162819,-0.596809339024114,-0.111618254226639,2.5,-0.000354245091306648,-0.0531935134833034,-0.000744521807637181,10.003087,10.0032415,-74695.9453125,-74686.0234375,57.3199458292753,20.646421337695,11.139823,0,0,0,40,4449,9.9645,-74690.984375,,,,,,,,,,,,,0,,,,0,,,,,,10.00316425,,,,
,28138097.625,10.0026865,-70233.546875,-0.0519266349298194,2.65792254887611E-6,1,0.999253354069792,40.0298881530762,1.98531146346245,27.3599997162819,-0.583089443030203,-0.109067645884477,2.5,-0.000344615001373747,-0.0519663621096618,-0.000728668483609991,10.0026865,10.0026865,-70243.609375,-70223.484375,57.2839909173907,20.6453049613975,10.38052,0,0,0,40,4449,9.96325,-70233.546875,,,,,,,,,,,,,0,,,,-0.0049,,,,,,10.0026865,,,,
,28138184.4,10.0040646,-65896.328125,-0.050706326752759,3.38270606103233E-6,1,0.999253354069792,40.0298881530762,1.98520868649438,27.3599997162819,-0.569149389347317,-0.106433400715562,2.5,-0.000332279396522502,-0.0507261002074813,-0.000708974499875884,10.0040646,10.0040646,-65901.6015625,-65891.0546875,57.2300585495638,20.648790393489,10.760172,0,0,0,40,4449,9.9602,-65896.328125,,,,,,,,,,,,,0,,,,-0.0049,,,,,,10.0040646,,,,
,28138275.985,10.0048189,-61319.001953125,-0.0493124209398655,4.39656237259925E-6,1,0.999253354069792,40.0298881530762,1.98519063501865,27.3599997162819,-0.553269294440134,-0.10346214494062,2.5,-0.000322019357177037,-0.049311172617604,-0.000689060123490347,10.0048189,10.0048189,-61323.81640625,-61314.1875,57.2167708647368,20.6469590024024,10.760172,0,0,0,40,4449,9.955,-61319.001953125,,,,,,,,,,,,,0,,,,-0.0049,,,,,,10.0048189,,,,
,28138364.01,10.003336,-56921.1171875,-0.0478886587890203,3.85883788744901E-6,1,0.999253354069792,40.0298881530762,1.98546419279492,27.3599997162819,-0.537162827923515,-0.100331178813473,2.5,-0.000302621481062927,-0.0478675793026868,-0.0006586364462493,10.003336,10.003336,-56926.21484375,-56916.01953125,57.2042648084291,20.6461919412989,10.38052,0,0,0,40,4449,9.9544,-56921.1171875,,,,,,,,,,,,,0,,,,0,,,,,,10.003336,,,,
,28138450.665,10.0031662,-52588.35546875,-0.0463844982424287,1.7498797573988E-6,1,0.999253354069792,40.0298881530762,1.98562352301121,27.3599997162819,-0.520114562696464,-0.097115880468026,2.5,-0.000291716179289361,-0.0463443621581618,-0.000635005747211437,10.0031662,10.0031662,-52598.41796875,-52578.29296875,57.1175040427945,20.6420133582431,10.760172,0,0,0,40,4449,9.9512,-52588.35546875,,,,,,,,,,,,,0,,,,0,,,,,,10.0031662,,,,
,28138538.695,10.0037594,-48191.1015625,-0.0447446135814639,2.4172367747851E-6,1,0.999253354069792,40.0298881530762,1.98578543807164,27.3599997162819,-0.501550596546352,-0.0935991488341342,2.5,-0.000279524953280379,-0.0446860036891456,-0.000607937488040634,10.0037594,10.0037594,-48201.2265625,-48180.9765625,57.4051433378714,20.6418284135051,10.38052,0,0,0,40,4449,9.9474,-48191.1015625,,,,,,,,,,,,,0,,,,0,,,,,,10.0037594,,,,
,28138627.2,10.0028505,-43765.810546875,-0.0429767424079893,2.84865160643962E-6,1,0.999253354069792,40.0298881530762,1.98574136801215,27.3599997162819,-0.481507913613463,-0.0898281072473306,2.5,-0.000269534204340818,-0.0429007390214015,-0.00058100714481448,10.0028505,10.0028505,-43768.09765625,-43763.5234375,56.851750346256,20.6419361951015,10.00087,0,0,0,40,4449,9.9458,-43765.810546875,,,,,,,,,,,,,0,,,,-0.0049,,,,,,10.0028505,,,,
,28138715.21,10.0022459,-39368.412109375,-0.041060439316569,2.43149892096438E-6,1,0.999253354069792,40.0298881530762,1.98613809092646,27.3599997162819,-0.459920341002567,-0.0857524623595654,2.5,-0.000258193050111904,-0.0409688207416959,-0.000550679518472567,10.0022459,10.0022459,-39370.93359375,-39365.890625,57.241001348833,20.6419391635557,10.760172,0,0,0,40,4449,9.9453,-39368.412109375,,,,,,,,,,,,,0,,,,-0.0049,,,,,,10.0022459,,,,
,28138804.625,10.0009851,-34898.669921875,-0.0389335548425756,3.08586918004538E-6,1,0.999253354069792,40.0298881530762,1.98712975000256,27.3599997162819,-0.436109421436989,-0.0812441620421297,2.5,-0.00024492525227234,-0.0388282504602544,-0.000515991600279214,10.0009851,10.0009851,-34908.58984375,-34888.75,57.3168193151984,20.6237531619019,11.139823,0,0,0,40,4449,9.9441,-34898.669921875,,,,,,,,,,,,,0,,,,-0.00245,,,,,,10.0009851,,,,
,28138899.235,10.001791,-30171.384765625,-0.03647486554976,2.4259922752266E-6,1,0.999253354069792,40.0298881530762,1.98658755898609,27.3599997162819,-0.4082699254979,-0.0759866141315158,2.5,-0.000230726415942336,-0.0363580230248131,-0.000477031647541562,10.001791,10.001791,-30176.47265625,-30166.296875,57.2855541744291,20.6311630257281,10.38052,0,0,0,40,4449,9.9412,-30171.384765625,,,,,,,,,,,,,0,,,,0.0049,,,,,,10.001791,,,,
,28138986.805,10.0013437,-25793.5517578125,-0.0340048949633423,2.73394940756529E-6,1,0.999253354069792,40.0298881530762,1.98609890262492,27.3599997162819,-0.380363922278436,-0.0707697595531147,2.5,-0.000220739872310102,-0.0338805018141617,-0.000442542604665559,10.0013437,10.0013437,-25808.701171875,-25778.40234375,56.9549253107945,20.6417476561167,10.760172,0,0,0,40,4449,9.9421,-25793.5517578125,,,,,,,,,,,,,0,,,,0.00245,,,,,,10.0013437,,,,
,28139074.63,10.0014715,-21406.0546875,-0.031270245416979,2.64789438973126E-6,1,0.999253354069792,40.0298881530762,1.9855394814809,27.3599997162819,-0.349537913634838,-0.0649654505011407,2.5,-0.000205090198188048,-0.0311420609937193,-0.000400840480619435,10.0014715,10.0014715,-21416.125,-21395.984375,57.126101956506,20.6455773487722,10.760172,0,0,0,40,4449,9.9394,-21406.0546875,,,,,,,,,,,,,0,,,,0.00245,,,,,,10.0014715,,,,
,28139164.985,10.0001698,-16891.2412109375,-0.0281620150221061,1.34569670294097E-6,1,0.999253354069792,40.0298881530762,1.98600526531442,27.3599997162819,-0.314737118896231,-0.0584422789290412,2.5,-0.000188270116520523,-0.028034384349068,-0.000356098759943617,10.0001698,10.0001698,-16893.7109375,-16888.771484375,57.0385595623522,20.6355512231912,10.38052,0,0,0,40,4449,9.94055,-16891.2412109375,,,,,,,,,,,,,0,,,,-0.00245,,,,,,10.0001698,,,,
,28139249.305,9.9985256,-12675.9599609375,-0.0250166246151653,1.85963562164939E-6,1,0.999253354069792,40.0298881530762,1.986352359235,27.3599997162819,-0.279533704505605,-0.0518537977611238,2.5,-0.000170226865979722,-0.0248938070191214,-0.000311754967694902,9.9985256,9.9985256,-12675.9599609375,-12675.9599609375,57.0432493334676,20.6316854505588,10.760172,0,0,0,40,4449,9.941,-12675.9599609375,,,,,,,,,,,,,0,,,,-0.0049,,,,,,9.9985256,,,,
,28139335.76,9.99891,-8354.8779296875,-0.0214579982622623,2.13749093731683E-6,1,0.999253354069792,40.0298881530762,1.98620904352777,27.3599997162819,-0.239675700777487,-0.0444169642792938,2.5,-0.000149098687957081,-0.0213450906503989,-0.000263598852848059,9.99891,9.99891,-8362.3056640625,-8347.4501953125,57.0917103016599,20.6359097275028,10.00087,0,0,0,40,4449,9.94265,-8354.8779296875,,,,,,,,,,,,,0,,,,-0.00245,,,,,,9.99891,,,,
,28139420.485,10.0003977,-4119.1474609375,-0.017702387007799,2.24371731176671E-6,1,0.999253354069792,40.0298881530762,1.98580845284897,27.3599997162819,-0.19763010758769,-0.0366205218158297,2.5,-0.000128044159779861,-0.0176039090921001,-0.000217009356673105,10.0003977,10.0003977,-4124.2060546875,-4114.0888671875,57.1722180391407,20.6406153005224,10.38052,0,0,0,40,4449,9.9429,-4119.1474609375,,,,,,,,,,,,,0,,,,-0.00245,,,,,,10.0003977,,,,
,28139506.335,10.0033312,174.748718261719,-0.0133884551411461,2.14269023140963E-6,1,0.999253354069792,40.0298881530762,1.9865855735415,27.3599997162819,-0.149499666641565,-0.0276636971412141,2.5,-9.67379013465079E-5,-0.0133111419845983,-0.000160790262291791,10.0033312,10.0033312,169.588836669922,179.908599853516,57.1237570709483,20.6325916419633,10.00087,0,0,0,40,4449,9.9413,174.748718261719,,,,,,,,,,,,,0,,,,-0.00245,,,,,,10.0033312,,,,
,28139593,9.9987984,4501.33911132812,-0.00813380170277156,2.61821496069879E-6,1,0.999253354069792,40.0298881530762,1.98641945147976,27.3599997162819,-0.090836408607962,-0.0168237936321349,2.5,-5.79195296155967E-5,-0.0080887596550987,-9.90207695176952E-5,9.9987984,9.9987984,4493.55224609375,4509.1259765625,57.2167708647368,20.6342782289071,10.760172,0,0,0,40,4449,9.94135,4501.33911132812,,,,,,,,,,,,,0,,,,0,,,,,,9.9987984,,,,
,28139684.695,9.9994259,9085.15771484375,-0.00287291059310478,2.67155674362004E-6,1,0.999253354069792,40.0298881530762,1.98587135117183,27.3599997162819,-0.0320793824162628,-0.00595732160463804,0.25,-2.08750045860453E-5,-0.00285795142604704,-3.63565047525271E-5,9.9994259,9.9994259,9077.57421875,9092.7412109375,56.973684395256,20.6404958822161,10.38052,0,0,0,40,4449,9.9439,9085.15771484375,,,,,,,,,,,,,0,,,,0.00245,,,,,,9.9994259,,,,
,28139770.22,9.999815,13360.470703125,0.00218895884894757,2.76966668537177E-6,1,0.999253354069792,40.0298881530762,1.98614136517804,27.3599997162819,0.0244523106089565,0.00455177721730364,0.25,1.61578894829098E-5,0.00217833446121533,2.86450398528587E-5,9.999815,9.999815,13355.3525390625,13365.5888671875,57.3504293415253,20.6341112793553,10.760172,0,0,0,40,4449,9.942,13360.470703125,,,,,,,,,,,,,0,,,,-0.0049,,,,,,9.999815,,,,
,28139862.595,10.0003977,17975.8486328125,0.00799575198725155,2.85317598422325E-6,1,0.999253354069792,40.0298881530762,1.98656051936829,27.3599997162819,0.0893726870036585,0.016646050544455,0.25,5.72579041503453E-5,0.00796030268470661,0.000105487048738837,10.0003929,10.0004025,17968.435546875,17983.26171875,57.2957153451791,20.6255878388936,10.00087,0,0,0,40,4449,9.94285,17975.8486328125,,,,,,,,,,,,,0,,,,-0.00245,,,,,,10.0003977,,,,
,28139961.025,10.0004044,22898.357421875,0.0142681752172281,3.27899440542512E-6,1,0.999253354069792,40.0298881530762,1.98675534948403,27.3599997162819,0.159604959755015,0.0296722641663856,2.5,9.29645339634273E-5,0.01421180121513,0.000183608100164399,10.0004044,10.0004044,22895.9921875,22900.72265625,57.1894138665637,20.6233683783068,10.38052,0,0,0,40,4449,9.9406,22898.357421875,,,,,,,,,,,,,0,,,,0.00245,,,,,,10.0004044,,,,
,28140056.17,9.9986267,27651.6416015625,0.0202703105513505,3.01812890509151E-6,1,0.999253354069792,40.0298881530762,1.98689881685106,27.3599997162819,0.226867354935263,0.0422012345610377,2.5,0.000128769720493021,0.0202000542422844,0.000263053615737742,9.9986267,9.9986267,27644.3984375,27658.884765625,57.2261504069676,20.6230694047965,10.00087,0,0,0,40,4449,9.9428,27651.6416015625,,,,,,,,,,,,,0,,,,0,,,,,,9.9986267,,,,
,28140151.205,9.9995403,32401.33984375,0.02577621544615,3.09202021432586E-6,1,0.999253354069792,40.0298881530762,1.98639792739512,27.3599997162819,0.288553424489871,0.0537412217890723,2.5,0.000163560881112171,0.0256996836407481,0.000340295590049645,9.9995403,9.9995403,32396.435546875,32406.244140625,57.5012836457369,20.6249777919546,10.00087,0,0,0,40,4449,9.9437,32401.33984375,,,,,,,,,,,,,0,,,,0,,,,,,9.9995403,,,,
,28140248.2,9.9986115,37248.802734375,0.0307658643201451,2.89817104462666E-6,1,0.999253354069792,40.0298881530762,1.98722642193519,27.3599997162819,0.344721115481065,0.0642260235654678,2.5,0.000191489865290251,0.0306903265245258,0.000408437273312804,9.9986115,9.9986115,37243.828125,37253.77734375,57.2300585495638,20.6149005988243,10.38052,0,0,0,40,4449,9.9459,37248.802734375,,,,,,,,,,,,,0,,,,-0.0049,,,,,,9.9986115,,,,
,28140343.745,9.9997387,42026.580078125,0.0349860329392809,2.95050128469608E-6,1,0.999253354069792,40.0298881530762,1.98689994845741,27.3599997162819,0.392140777211329,0.0730788627986835,2.5,0.000214250394787665,0.0349178180144418,0.000466242286777565,9.9997387,9.9997387,42016.4375,42036.72265625,57.2691399755253,20.6224143535049,10.38052,0,0,0,40,4449,9.945,42026.580078125,,,,,,,,,,,,,0,,,,-0.0049,,,,,,9.9997387,,,,
,28140440.375,9.9973011,46854.44140625,0.0386739332413426,3.85001178560437E-6,1,0.999253354069792,40.0298881530762,1.98775297733951,27.3599997162819,0.433862714245535,0.0809151857841941,2.5,0.000237990966704515,0.0386179850612117,0.000520903626073848,9.9973011,9.9973011,46849.40625,46859.4765625,57.2191157502945,20.6114380134605,10.38052,0,0,0,40,4449,9.94825,46854.44140625,,,,,,,,,,,,,0,,,,0,,,,,,9.9973011,,,,
,28140535.345,9.9968672,51602.142578125,0.0417652226369149,2.69001419527534E-6,1,0.999253354069792,40.0298881530762,1.98734863497306,27.3599997162819,0.468666314540213,0.0874753579118665,2.5,0.00026014226310608,0.0417249801169086,0.000568777513632695,9.9968672,9.9968672,51597.03125,51607.25390625,56.9291315696599,20.6186149884931,10.38052,0,0,0,40,4449,9.9516,51602.142578125,,,,,,,,,,,,,0,,,,0.00245,,,,,,9.9968672,,,,
,28140631.565,9.9959879,56409.40625,0.0444703286318389,3.38506299727193E-6,1,0.999253354069792,40.0298881530762,1.98749401431233,27.3599997162819,0.499293809648657,0.0931905775162804,2.5,0.000275302245199949,0.0444485960560136,0.000605790849591789,9.9959879,9.9959879,56399.8203125,56418.9921875,57.0401228193907,20.6183067341502,10.00087,0,0,0,40,4449,9.9557,56409.40625,,,,,,,,,,,,,0,,,,0,,,,,,9.9959879,,,,
,28140727.425,9.99618625,61200.02734375,0.0468294478452195,4.1395435264529E-6,1,0.999253354069792,40.0298881530762,1.98725740672916,27.3599997162819,0.525950442976342,0.0982234948777362,2.5,0.000294611404100375,0.0468278289224018,0.000643173724949366,9.9961014,9.9962711,61192.40625,61207.6484375,57.1253203279868,20.6211304381332,10.38052,0,0,0,40,4449,9.95805,61200.02734375,,,,,,,,,,,,,0,,,,0,,,,,,9.99618625,,,,
,28140821.035,9.9953432,65882.875,0.0488759444150532,3.62527774444135E-6,1,0.999253354069792,40.0298881530762,1.98759717138235,27.3599997162819,0.549252470680891,0.102607482060117,2.5,0.000311242549055297,0.0488950136022478,0.000674339497545727,9.9953432,9.9953432,65880.4296875,65885.3203125,57.2722664896022,20.6154659744952,10.00087,0,0,0,40,4449,9.96225,65882.875,,,,,,,,,,,,,0,,,,0.0049,,,,,,9.9953432,,,,
,28140915.375,9.9958658,70596.01171875,0.0507118790849786,3.4772614180262E-6,1,0.999253354069792,40.0298881530762,1.98783372965329,27.3599997162819,0.570175353123513,0.106547867274387,2.5,0.000327800190433692,0.0507522933307751,0.000702683011699344,9.9958658,9.9958658,70593.4453125,70598.578125,57.1917587521214,20.6143566014551,10.00087,0,0,0,40,4449,9.9664,70596.01171875,,,,,,,,,,,,,0,,,,-0.00245,,,,,,9.9958658,,,,
,28141009.695,9.995677,75311.28515625,0.0523834939408869,2.56310940152313E-6,1,0.999253354069792,40.0298881530762,1.98801016246851,27.3599997162819,0.589249109315071,0.110100614149624,2.5,0.000340809587504461,0.0524454642246898,0.000725132977780479,9.995677,9.995677,75301.2421875,75321.328125,57.2433462343907,20.6132954659779,10.760172,0,0,0,40,4449,9.96985,75311.28515625,,,,,,,,,,,,,0,,,,0,,,,,,9.995677,,,,
,28141107.745,9.9942961,80212.24609375,0.0539580876809353,4.38335445748218E-6,1,0.999253354069792,40.0298881530762,1.98917654947003,27.3599997162819,0.60753680406013,0.113483309517158,2.5,0.000352426848578471,0.0540423506389851,0.00074425980072544,9.9942961,9.9942961,80199.5,80224.9921875,57.1995750373137,20.592442420225,10.760172,0,0,0,40,4449,9.975,80212.24609375,,,,,,,,,,,,,0,,,,-0.00245,,,,,,9.9942961,,,,
,28141200.51,9.9934235,84848.22265625,0.0553324289672928,4.27195922751204E-6,1,0.999253354069792,40.0298881530762,1.98933951520501,27.3599997162819,0.623268532161247,0.11642546950302,2.5,0.000366614937076123,0.0554374548137587,0.000763781609599891,9.9934235,9.9934235,84843.21875,84853.2265625,57.1300100991022,20.5885149850507,10.00087,0,0,0,40,4449,9.9817,84848.22265625,,,,,,,,,,,,,0,,,,0,,,,,,9.9934235,,,,
,28141288.46,9.994029,89246.3203125,0.0565459196114314,4.17000562932018E-6,1,0.999253354069792,40.0298881530762,1.98954898856757,27.3599997162819,0.637191183448921,0.119033730852173,2.5,0.000380586944892429,0.0566702376101191,0.000781413725346128,9.994029,9.994029,89241.453125,89251.1875,57.2198973788137,20.5918433442512,10.38052,0,0,0,40,4449,9.9872,89246.3203125,,,,,,,,,,,,,0,,,,-0.00245,,,,,,9.994029,,,,
,28141392.7,9.9976521,86561.04296875,0.0560418061881111,3.73086405585575E-6,1,0.999253354069792,40.0298881530762,1.98976149471497,27.3599997162819,0.631465432786542,0.117936739908332,2.5,0.00037159382687394,0.0561548690084457,0.000771955671957887,9.9976521,9.9976521,86553.25,86568.8359375,57.2394380917945,20.5926703677211,10.38052,0,0,0,40,4449,9.98935,86561.04296875,,,,,,,,,,,,,0,,,,0,,,,,,9.9976521,,,,
,28141484.405,10.0005846,81974.796875,0.054975109281572,3.22301471624061E-6,1,0.999253354069792,40.0298881530762,1.98959902485618,27.3599997162819,0.619192093374101,0.115671272084664,2.5,0.000361778421005284,0.0550681190448608,0.000759318377942928,10.0005846,10.0005846,81969.5859375,81980.0078125,57.0995265868522,20.5913349753646,10.00087,0,0,0,40,4449,9.98845,81974.796875,,,,,,,,,,,,,0,,,,0,,,,,,10.0005846,,,,
,28141581.95,10.0023031,77101.29296875,0.0537827756325448,3.51135368747541E-6,1,0.999253354069792,40.0298881530762,1.98960528389679,27.3599997162819,0.605539630926727,0.113135116546533,2.5,0.000350585329124881,0.0538539816064063,0.000743802748561679,10.0023031,10.0023031,77096.3828125,77106.203125,57.1683098965445,20.5910728940497,10.38052,0,0,0,40,4449,9.9848,77101.29296875,,,,,,,,,,,,,0,,,,0,,,,,,10.0023031,,,,
,28141679.055,10.0035219,72245.1875,0.0525009618008597,2.00985747031455E-6,1,0.999253354069792,40.0298881530762,1.98933801889824,27.3599997162819,0.590814156806193,0.110314570820161,2.5,0.000332649377637216,0.0525500737460266,0.000719833760146898,10.0035219,10.0035219,72237.90625,72252.46875,57.3582456267176,20.5951165835133,10.760172,0,0,0,40,4449,9.9812,72245.1875,,,,,,,,,,,,,0,,,,0,,,,,,10.0035219,,,,
,28141776.16,10.0031433,67392.54296875,0.051155340903612,3.3045824576252E-6,1,0.999253354069792,40.0298881530762,1.98976461767304,27.3599997162819,0.575556749688125,0.107440206202663,2.5,0.000319355979944538,0.0511821402741042,0.000698898952658238,10.0031433,10.0031433,67390.2578125,67394.828125,57.2050464369484,20.5912798093101,10.00087,0,0,0,40,4449,9.9779,67392.54296875,,,,,,,,,,,,,0,,,,0.00245,,,,,,10.0031433,,,,
,28141871.055,10.0025663,62649.3203125,0.0497447642880212,4.22034790424022E-6,1,0.999253354069792,40.0298881530762,1.98994730851389,27.3599997162819,0.559500533672483,0.104427904569593,2.5,0.000307877535182641,0.0497497346234495,0.000678045075903192,10.0025663,10.0025663,62647.1015625,62651.5390625,57.2910255740638,20.584296989394,10.00087,0,0,0,40,4449,9.9761,62649.3203125,,,,,,,,,,,,,0,,,,-0.00245,,,,,,10.0025663,,,,
,28141965.345,10.003787,57935.87890625,0.0482486692835738,4.20143661838223E-6,1,0.999253354069792,40.0298881530762,1.99010352434262,27.3599997162819,0.542478629537017,0.101226396172036,2.5,0.00029636484489313,0.0482321999125486,0.000655260691658416,10.003787,10.003787,57933.41015625,57938.34765625,57.1917587521214,20.5849780537664,10.38052,0,0,0,40,4449,9.972,57935.87890625,,,,,,,,,,,,,0,,,,-0.0049,,,,,,10.003787,,,,
,28142061.625,10.003396,53125.23046875,0.0465889074742219,4.28376315721495E-6,1,0.999253354069792,40.0298881530762,1.99020444835094,27.3599997162819,0.523603889474185,0.0976623688244433,2.5,0.000283746014396276,0.046551153409774,0.000628813245019584,10.003396,10.003396,53115.1171875,53135.34375,57.4098331089868,20.5841342763058,10.38052,0,0,0,40,4449,9.9684,53125.23046875,,,,,,,,,,,,,0,,,,0,,,,,,10.003396,,,,
,28142156.83,10.0020933,48365.3125,0.0448300473638723,3.2400883145512E-6,1,0.999253354069792,40.0298881530762,1.99048828393895,27.3599997162819,0.503675715475715,0.0938693598107307,2.5,0.00026906481009999,0.0447722066051059,0.00059825201754253,10.0020933,10.0020933,48352.796875,48377.828125,57.2363115777176,20.5825723998749,9.621219,0,0,0,40,4449,9.96705,48365.3125,,,,,,,,,,,,,0,,,,-0.00245,,,,,,10.0020933,,,,
,28142255.205,10.0024757,43449.6796875,0.0428630363478103,3.73131494192649E-6,1,0.999253354069792,40.0298881530762,1.99047900737463,27.3599997162819,0.481332852889477,0.08967638767836,2.5,0.000258890856583276,0.0427858885312938,0.000569221983467996,10.0024757,10.0024757,43444.71484375,43454.64453125,57.2925888311022,20.5808949628969,10.00087,0,0,0,40,4449,9.96445,43449.6796875,,,,,,,,,,,,,0,,,,-0.0049,,,,,,10.0024757,,,,
,28142349.905,10.0027981,38712.16015625,0.0407779711657084,3.14159294747095E-6,1,0.999253354069792,40.0298881530762,1.99039487146558,27.3599997162819,0.4576792683152,0.0852199497683828,2.5,0.000247379956393945,0.0406842162320796,0.000537001591059772,10.0027981,10.0027981,38706.953125,38717.3671875,57.3715333115445,20.58205914975,9.621219,0,0,0,40,4449,9.9629,38712.16015625,,,,,,,,,,,,,0,,,,0,,,,,,10.0027981,,,,
,28142447.595,10.0039234,33832.748046875,0.0384214749562425,2.12252392097392E-6,1,0.999253354069792,40.0298881530762,1.99000481181966,27.3700002580881,0.4309426952776,0.0801463145512886,2.5,0.000231668363539261,0.0383132907952145,0.000497518201700851,10.0039234,10.0039234,33825.1875,33840.30859375,57.0846756449868,20.5869382476251,9.621219,0,0,0,40,4449,9.95905,33832.748046875,,,,,,,,,,,,,0,,,,0.0049,,,,,,10.0039234,,,,
,28142542.53,10.0017004,29089.9052734375,0.0359148204875077,3.65464616695954E-6,1,0.999253354069792,40.0298881530762,1.9901745072195,27.3599997162819,0.402665225823659,0.0748476141116213,2.5,0.000220795438406816,0.0357957561128889,0.000461416258475592,10.0017004,10.0017004,29077.59765625,29102.212890625,57.2386564632753,20.5849822436686,10.00087,0,0,0,40,4449,9.95855,29089.9052734375,,,,,,,,,,,,,0,,,,0,,,,,,10.0017004,,,,
,28142633.74,10.0028343,24527.1630859375,0.033274293311847,3.31738700569596E-6,1,0.999253354069792,40.0298881530762,1.98939215486372,27.3599997162819,0.372751125375964,0.0692470506991062,2.5,0.000209192494392724,0.033148327110318,0.000423841326117182,10.0028343,10.0028343,24519.716796875,24534.609375,57.4825245612753,20.5917597712299,10.00087,0,0,0,40,4449,9.9576,24527.1630859375,,,,,,,,,,,,,0,,,,0,,,,,,10.0028343,,,,
,28142720.63,10.001502,20187.0380859375,0.0305047249989769,3.26370601186893E-6,1,0.999253354069792,40.0298881530762,1.98922635119204,27.3599997162819,0.341559403423009,0.0633970570642202,2.5,0.000195037113818554,0.0303760767314243,0.000383629791390138,10.001502,10.001502,20176.841796875,20197.234375,57.0127658212176,20.5930093533973,10.00087,0,0,0,40,4449,9.956,20187.0380859375,,,,,,,,,,,,,0,,,,0.00245,,,,,,10.001502,,,,
,28142807.185,10.0005741,15861.591796875,0.0274718746779035,3.51223751327345E-6,1,0.999253354069792,40.0298881530762,1.98929252307644,27.3599997162819,0.307493803499729,0.0570179835510816,2.5,0.000178760560895223,0.0273447999091297,0.000340520048772823,10.0005741,10.0005741,15854.22265625,15868.9609375,57.2370932062368,20.5915413417154,10.00087,0,0,0,40,4449,9.95335,15861.591796875,,,,,,,,,,,,,0,,,,0.00245,,,,,,10.0005741,,,,
,28142892.105,9.9994946,11616.7470703125,0.024227029773591,2.62170779296847E-6,1,0.999253354069792,40.0298881530762,1.98939094498701,27.3599997162819,0.271093505562487,0.0502199360687315,2.5,0.000160833180853019,0.0241059364948483,0.000296024662384495,9.9994946,9.9994946,11611.978515625,11621.515625,56.9369478548522,20.5912960716367,10.00087,0,0,0,40,4449,9.9545,11616.7470703125,,,,,,,,,,,,,0,,,,0,,,,,,9.9994946,,,,
,28142977.98,9.99939825,7323.59399414062,0.0206357145703575,2.32215964364355E-6,1,0.999253354069792,40.0298881530762,1.98956152945598,27.3700002580881,0.230852426709501,0.0427363711703183,2.5,0.000141025868153276,0.0205255441879929,0.000249569991111651,9.998991,9.9998055,7318.5625,7328.62548828125,57.0049495360253,20.5861371033703,10.00087,0,0,0,40,4449,9.9563,7323.59399414062,,,,,,,,,,,,,0,,,,0.0049,,,,,,9.99939825,,,,
,28143063.765,9.999135,3035.40832519531,0.0166926253408305,2.54583651702107E-6,1,0.999253354069792,40.0298881530762,1.99017818840125,27.3700002580881,0.186748181958996,0.0345333747710165,2.5,0.000115860572097792,0.0165986678707742,0.000198536849812932,9.999135,9.999135,3025.3095703125,3045.50708007812,56.8548768603329,20.5800612177787,10.00087,0,0,0,40,4449,9.9567,3035.40832519531,,,,,,,,,,,,,0,,,,-0.0049,,,,,,9.999135,,,,
,28143125.225,10.0019388,-0.42626565694809,0.0135919550014195,1.85840819616707E-6,1,0.999253354069792,40.0298881530762,1.98985047846267,27.3599997162819,0.152014768630123,0.0280982626384323,2.5,9.56198377873187E-5,0.0135134140359256,0.000160582879370132,10.0019388,10.0019388,-0.62417471408844,-0.228356599807739,57.1034347294484,20.587729269936,9.621219,0,0,0,40,4417,9.95565,-0.42626565694809,,,,,,,,,,,,,0,,,,0,,,,,,10.0019388,,,,