File: data/monolayers/nanoparticles/Ol_CoFe_C/vsm/data_dispersion/DD67_HYST_50K.DAT
[Header]
; VSM Data File (default extension .dat)
; Copyright (c) 2003-2013, Quantum Design, Inc. All rights reserved.
TITLE,
FILEOPENTIME,28154989.08,11/23/2018,4:50 am
BYAPP,VSM,2.0,2.0
INFO,PPMS VSM Option Release 1.4.10 Build 1,APPNAME
INFO,Quantum Design Linear Motor Servo Controller,MOTOR_MODULE_NAME
INFO,3101-100 M1,MOTOR_HW_VERSION
INFO,MMC1014,MOTOR_SERIAL_NUMBER
INFO,SRV No X-over 01.03.11,MOTOR_SOFTWARE_VERSION
INFO,Quantum Design VSM Detection Module,VSM_MODULE_NAME
INFO,3101-150 F0,VSM_HW_VERSION
INFO,VSM707,VSM_SERIAL_NUMBER
INFO,VSM No X-over 01.02.05 May 20 2008 13:51:47,VSM_SOFTWARE_VERSION
INFO,704,PREAMP_SERIAL_NUMBER
INFO,822,COIL_SERIAL_NUMBER
INFO,0,MOMENT_UNITS
INFO,CoFe2O4,SAMPLE_MATERIAL
INFO,dispersion in ampulle,SAMPLE_COMMENT
INFO,,SAMPLE_MASS
INFO,,SAMPLE_VOLUME
INFO,,SAMPLE_MOLECULAR_WEIGHT
INFO,,SAMPLE_SIZE
INFO,,SAMPLE_SHAPE
DATATYPE,COMMENT,1
DATATYPE,TIME,2
STARTUPAXIS,X,2
STARTUPAXIS,Y1,5
[Data]
Comment,Time Stamp (sec),Temperature (K),Magnetic Field (Oe),Moment (emu),M. Std. Err. (emu),Transport Action,Averaging Time (sec),Frequency (Hz),Peak Amplitude (mm),Center Position (mm),Coil Signal' (mV),Coil Signal" (mV),Range (mV),M. Quad. Signal (emu),M. Raw' (emu),M. Raw" (emu),Min. Temperature (K),Max. Temperature (K),Min. Field (Oe),Max. Field (Oe),Mass (grams),Motor Lag (deg),Pressure (Torr),VSM Status (code),Motor Status (code),Measure Status (code),Measure Count,PPMS Status (code),System Temp. (K),System Field (Oe),Sample Position (deg),Bridge 1 Resistance (ohms),Bridge 1 Excitation (에),Bridge 2 Resistance (ohms),Bridge 2 Excitation (에),Bridge 3 Resistance (ohms),Bridge 3 Excitation (에),Bridge 4 Resistance (ohms),Bridge 4 Excitation (에),Signal 1 Vin (V),Signal 2 Vin (V),Digital Inputs (code),Drive 1 Iout (mA),Drive 1 Ipower (W),Drive 2 Iout (mA),Drive 2 Ipower (W),Pressure (),Map 20 (),Map 21 (),Map 22 (),Map 23 (),Map 24 (),Map 25 (),Map 26 (),Map 27 (),Map 28 (),Map 29 ()
,28155005.69,50.011364,-0.137013956904411,,,2,,,,27.7899993014336,,,,,,,50.011364,50.011364,-0.137013956904411,-0.137013956904411,,,16.075285,,,,-99999999,4369,50.0231,-0.137013956904411,,,,,,,,,,,,,,,,,,,,,,,50.011364,,,,
,28155152.71,50.0087433,4353.6201171875,0.0108893889965912,2.06235050404942E-6,1,0.999253354069792,40.0298881530762,1.9795782850293,27.7800001204014,0.121808260437514,0.0227075060379248,2.5,6.49756792479693E-5,0.0108847369044227,0.000145984468122348,50.0087433,50.0087433,4341.20849609375,4366.03173828125,56.8197035769676,20.534431023894,16.834587,0,0,0,40,4449,50.0136,4353.6201171875,,,,,,,,,,,,,0,,,,-0.00245,,,,,,50.0087433,,,,
,28155246.305,50.00647545,9029.97119140625,0.0149842947371591,2.31866867793107E-6,1,0.999253354069792,40.0298881530762,1.97987639114675,27.7800001204014,0.167675112808531,0.0312625728969546,2.5,8.985602796924E-5,0.0149812927836762,0.000201321055552372,50.0061951,50.0067558,9017.3115234375,9042.630859375,56.9181887703906,20.5350290304258,16.834587,0,0,0,40,4449,50.0049,9029.97119140625,,,,,,,,,,,,,0,,,,-0.00245,,,,,,50.00647545,,,,
,28155338.065,50.0065689,13615.1665039062,0.0190396858133793,2.66453531123426E-6,1,0.999253354069792,40.0298881530762,1.97949511504828,27.7800001204014,0.213070378966044,0.0397104777257254,2.5,0.000113016681139324,0.0190404961168964,0.000254494151719135,50.0065689,50.0065689,13610.0126953125,13620.3203125,56.946327397083,20.5392274146152,16.834587,0,0,0,40,4449,50.0039,13615.1665039062,,,,,,,,,,,,,0,,,,-0.00245,,,,,,50.0065689,,,,
,28155429.695,50.00476265,18197.7978515625,0.023096586393169,2.79030040951334E-6,1,0.999253354069792,40.0298881530762,1.97912149822659,27.7800001204014,0.258490136534805,0.0481672050014657,2.5,0.000136847729964406,0.0231033612403541,0.000308083654208385,50.0046806,50.0048447,18192.8515625,18202.744140625,56.9822823089676,20.5461030528034,17.214239,0,0,0,40,4449,50.0047,18197.7978515625,,,,,,,,,,,,,0,,,,0,,,,,,50.00476265,,,,
,28155522.83,50.0035477,22853.15234375,0.0269968842708952,2.76769811634625E-6,1,0.999253354069792,40.0298881530762,1.97908455562567,27.7800001204014,0.302210134797211,0.0563319566659192,2.5,0.000162300735491543,0.0270117222047615,0.000361751756530813,50.0035477,50.0035477,22850.716796875,22855.587890625,57.034651419756,20.5467305756649,16.454937,0,0,0,40,4449,50.0037,22853.15234375,,,,,,,,,,,,,0,,,,0.0049,,,,,,50.0035477,,,,
,28155614.76,50.0039101,27446.2060546875,0.0305348493470477,3.42877618075122E-6,1,0.999253354069792,40.0298881530762,1.97910505204898,27.7800001204014,0.341902946083201,0.0637387623593106,2.5,0.000185415471944166,0.0305593075008384,0.000409959400421408,50.0039101,50.0039101,27438.810546875,27453.6015625,57.1933220091599,20.5444589888911,16.454937,0,0,0,40,4449,49.9985,27446.2060546875,,,,,,,,,,,,,0,,,,-0.00245,,,,,,50.0039101,,,,
,28155709.015,50.0017014,32158.6591796875,0.0338131097116056,4.06059764338756E-6,1,0.999253354069792,40.0298881530762,1.97960601057308,27.7800001204014,0.378806141072271,0.0705757022361316,2.5,0.000203243070294207,0.0338488925127625,0.000450403048860536,50.0017014,50.0017014,32151.27734375,32166.041015625,57.0127658212176,20.5383730566495,17.214239,0,0,0,40,4449,49.9989,32158.6591796875,,,,,,,,,,,,,0,,,,-0.00245,,,,,,50.0017014,,,,
,28155802.43,50.0009308,36826.072265625,0.0366591820568244,3.07794862267656E-6,1,0.999253354069792,40.0298881530762,1.97996773930969,27.7800001204014,0.410867956438651,0.076528679716636,2.5,0.000220598471663945,0.0367071175787099,0.000486666142194642,50.0009308,50.0009308,36818.6328125,36833.51171875,57.0588819038522,20.5384667253925,16.834587,0,0,0,40,4449,49.999,36826.072265625,,,,,,,,,,,,,0,,,,0.0049,,,,,,50.0009308,,,,
,28155895.1,50.0016022,41456.142578125,0.0391829927996698,3.75292746220786E-6,1,0.999253354069792,40.0298881530762,1.97988689793282,27.7800001204014,0.439243323667847,0.0818088851793529,2.5,0.00023776337038914,0.0392436409770532,0.000519862127681637,50.0016022,50.0016022,41451.01171875,41461.2734375,56.9541436822753,20.5366962963816,17.214239,0,0,0,40,4449,49.9956,41456.142578125,,,,,,,,,,,,,0,,,,0.00245,,,,,,50.0016022,,,,
,28155985.61,49.9999313,45981.931640625,0.0413612126099374,3.70116678811451E-6,1,0.999253354069792,40.0298881530762,1.98024058112645,27.7800001204014,0.463849425229441,0.0863752819350881,2.5,0.000252319158918645,0.041434723482598,0.000547464514460688,49.9999313,49.9999313,45974.60546875,45989.2578125,57.0401228193907,20.534133463083,17.214239,0,0,0,40,4449,49.998,45981.931640625,,,,,,,,,,,,,0,,,,0,,,,,,49.9999313,,,,
,28156079.24,50.0024376,50662.05078125,0.0434093748288174,3.84848534432888E-6,1,0.999253354069792,40.0298881530762,1.97999449800799,27.7800001204014,0.486875171105189,0.0906441029361507,2.5,0.000266415311305819,0.0434964489367476,0.000573073578824772,50.0024376,50.0024376,50657.03515625,50667.06640625,56.9807190519291,20.5386555119515,17.214239,0,0,0,40,4449,49.9954,50662.05078125,,,,,,,,,,,,,0,,,,0,,,,,,50.0024376,,,,
,28156175.995,50.0016556,55497.1796875,0.0453185016166863,3.72030851708225E-6,1,0.999253354069792,40.0298881530762,1.98014032252257,27.7800001204014,0.508451397180029,0.094588878995271,2.5,0.000275639112224864,0.0454197510792795,0.000592180131309371,50.0016556,50.0016556,55489.58203125,55504.77734375,56.9947883652753,20.5379034595866,17.214239,0,0,0,40,4449,49.99265,55497.1796875,,,,,,,,,,,,,0,,,,0,,,,,,50.0016556,,,,
,28156270.83,50.0010872,60234.8828125,0.0470172775343069,4.49143671956555E-6,1,0.999253354069792,40.0298881530762,1.97988700185174,27.7800001204014,0.527552431819354,0.0981821813580439,2.5,0.000293420197333733,0.0471323955376767,0.000617953304785453,50.0010872,50.0010872,60232.671875,60237.09375,56.8392442899483,20.5407751525374,16.834587,0,0,0,40,4449,49.99455,60234.8828125,,,,,,,,,,,,,0,,,,0,,,,,,50.0010872,,,,
,28156367.305,50.00269315,65060.73046875,0.0486082141590607,3.44034829487679E-6,1,0.999253354069792,40.0298881530762,1.97994573250771,27.7800001204014,0.545541763787366,0.101477352823605,2.5,0.000303204276668886,0.0487374216210459,0.000634436620332136,50.0026588,50.0027275,65050.7109375,65070.75,56.9947883652753,20.5402378036843,16.834587,0,0,0,40,4449,49.99315,65060.73046875,,,,,,,,,,,,,0,,,,-0.00245,,,,,,50.00269315,,,,
,28156460.05,50.0026741,69693.234375,0.0500042654743698,4.59211721552486E-6,1,0.999253354069792,40.0298881530762,1.97992939341761,27.7800001204014,0.561320391941673,0.10436887334897,2.5,0.000312654728790706,0.0501467929399296,0.000649026596915629,50.0026741,50.0026741,69688.2265625,69698.2421875,57.1401712698522,20.5410799133434,17.214239,0,0,0,40,4449,49.9887,69693.234375,,,,,,,,,,,,,0,,,,0,,,,,,50.0026741,,,,
,28156553.5,50.0024376,74368.3984375,0.0513258536484782,2.83298195019194E-6,1,0.999253354069792,40.0298881530762,1.98009690731459,27.7800001204014,0.576299725515407,0.107209136249655,2.5,0.000330459470022401,0.0514816657231327,0.00067106049020703,50.002079,50.0027962,74360.703125,74376.09375,57.1425161554099,20.5351399727578,17.214239,0,0,0,40,4449,49.9922,74368.3984375,,,,,,,,,,,,,0,,,,-0.0049,,,,,,50.0024376,,,,
,28156646.865,50.0015545,79031.75,0.0525346222490227,3.39240538210963E-6,1,0.999253354069792,40.0298881530762,1.98014285368149,27.7800001204014,0.590016177636442,0.109602172714837,2.5,0.000329550967322471,0.0527034376198076,0.000673286908663549,50.0012932,50.0018158,79024.046875,79039.453125,56.9689946241406,20.5334577740056,17.593889,0,0,0,40,4449,49.98605,79031.75,,,,,,,,,,,,,0,,,,-0.0049,,,,,,50.0015545,,,,
,28156740.265,50.0018616,83702.89453125,0.0536839675384584,3.4511647030643E-6,1,0.999253354069792,40.0298881530762,1.98040985744952,27.7800001204014,0.603103979657239,0.112032176610886,2.5,0.000341839693052158,0.0538655529832971,0.000688029045524229,50.0018616,50.0018616,83693.0859375,83712.703125,57.098744958333,20.5285850040043,17.593889,0,0,0,40,4449,49.988,83702.89453125,,,,,,,,,,,,,0,,,,0,,,,,,50.0018616,,,,
,28156830.905,50.0017929,88233.69921875,0.054717287596027,4.45445312213812E-6,1,0.999253354069792,40.0298881530762,1.98038099679662,27.7800001204014,0.614805000211203,0.114175111615871,2.5,0.000350945077934449,0.0549109234818521,0.000698736015319535,50.0017929,50.0017929,88231.0703125,88236.328125,57.0940551872176,20.533190033694,17.214239,0,0,0,40,4449,49.9871,88233.69921875,,,,,,,,,,,,,0,,,,-0.0049,,,,,,50.0017929,,,,
,28156935.695,49.99895285,87478.7578125,0.054627000974109,2.61744341559912E-6,1,0.999253354069792,40.0298881530762,1.98021012938588,27.7800001204014,0.613721396244014,0.113989873413485,2.5,0.000350870620392275,0.0548189002515414,0.000698946523483933,49.998806,49.9990997,87473.7265625,87483.7890625,56.6500901882945,20.5277288099039,17.593889,0,0,0,40,4449,49.98425,87478.7578125,,,,,,,,,,,,,0,,,,0,,,,,,49.99895285,,,,
,28157023.415,50.0007706,83089.98828125,0.0536786238187707,4.01820666789965E-6,1,0.999253354069792,40.0298881530762,1.98045117171144,27.7800001204014,0.603048065213306,0.11199259170286,2.5,0.000338614356286801,0.0538590494222076,0.000685424787458724,50.0007706,50.0007706,83079.9453125,83100.03125,57.2300585495638,20.5264857786271,17.593889,0,0,0,40,4449,49.98895,83089.98828125,,,,,,,,,,,,,0,,,,-0.00245,,,,,,50.0007706,,,,
,28157117.07,49.9992828,78408.765625,0.0526094492842033,3.04047198156922E-6,1,0.999253354069792,40.0298881530762,1.98035784653586,27.7800001204014,0.590894245511076,0.109824816121344,2.5,0.000334488750712855,0.0527772854008472,0.000679370994094635,49.9992828,49.9992828,78396.09375,78421.4375,57.0237086204868,20.5296511855686,17.214239,0,0,0,40,4449,49.9906,78408.765625,,,,,,,,,,,,,0,,,,-0.00245,,,,,,49.9992828,,,,
,28157207.89,49.9988136,73869.75390625,0.051538485927813,2.91807954258189E-6,1,0.999253354069792,40.0298881530762,1.98018928707386,27.7800001204014,0.578712093558696,0.107596913677503,2.5,0.000326044225984121,0.0516939504527025,0.00066856036922783,49.9988136,49.9988136,73867.0078125,73872.5,56.8970848003714,20.5329637644617,17.593889,0,0,0,40,4449,49.9877,73869.75390625,,,,,,,,,,,,,0,,,,-0.00245,,,,,,49.9988136,,,,
,28157302.005,50.0003929,69166.84375,0.0503282542140057,4.64640518350253E-6,1,0.999253354069792,40.0298881530762,1.98012216448079,27.7800001204014,0.564994506278797,0.105070304830091,2.5,0.000315728065836909,0.0504706059012054,0.000654796753785277,50.0003929,50.0003929,69159.3125,69174.375,57.1925403806407,20.5343376457473,17.214239,0,0,0,40,4449,49.9871,69166.84375,,,,,,,,,,,,,0,,,,0,,,,,,50.0003929,,,,
,28157396.105,49.9998627,64461.201171875,0.0490613689450967,3.7805900188156E-6,1,0.999253354069792,40.0298881530762,1.98014325836544,27.7800001204014,0.550660194079065,0.102460868416372,2.5,0.000308156546563792,0.049190470580919,0.000643047973592974,49.9998627,49.9998627,64456.23046875,64466.171875,56.9549253107945,20.533970900195,17.593889,0,0,0,40,4449,49.9875,64461.201171875,,,,,,,,,,,,,0,,,,-0.0049,,,,,,49.9998627,,,,
,28157488.65,49.9996338,59835.498046875,0.0477261438963681,4.20765808534751E-6,1,0.999253354069792,40.0298881530762,1.98010493499444,27.7800001204014,0.535563398772277,0.0996082734769991,2.5,0.000291876544747033,0.0478421082565605,0.000621660743582088,49.9996338,49.9996338,59828.00390625,59842.9921875,57.0385595623522,20.5370383614422,16.834587,0,0,0,40,4449,49.984,59835.498046875,,,,,,,,,,,,,0,,,,0,,,,,,49.9996338,,,,
,28157581.415,49.9993629,55199.65625,0.0462879330663207,2.83479021299205E-6,1,0.999253354069792,40.0298881530762,1.9802613951259,27.7800001204014,0.519348702275064,0.0966275302037301,2.5,0.000282259130133682,0.0463906626771796,0.000605822346835069,49.9993629,49.9993629,55189.5390625,55209.7734375,56.9471090256022,20.5299982851499,17.214239,0,0,0,40,4449,49.9873,55199.65625,,,,,,,,,,,,,0,,,,0.00245,,,,,,49.9993629,,,,
,28157674.1,49.9993553,50564.82421875,0.0447593512688855,3.10055154202321E-6,1,0.999253354069792,40.0298881530762,1.98045881971604,27.7800001204014,0.502129411496204,0.0934625321984026,2.5,0.000272746968305953,0.0448488612472396,0.000589032710259287,49.9993553,49.9993553,50557.55078125,50572.09765625,56.841589175506,20.5324461965797,17.593889,0,0,0,40,4449,49.9861,50564.82421875,,,,,,,,,,,,,0,,,,0.00245,,,,,,49.9993553,,,,
,28157766.705,50.00082395,45937.068359375,0.0430844091631566,4.53993476615765E-6,1,0.999253354069792,40.0298881530762,1.98019807554841,27.7800001204014,0.483161142802528,0.0899786556724005,2.5,0.000263400323174502,0.0431607934927567,0.000570897511050236,50.0006599,50.000988,45929.6796875,45944.45703125,57.0846756449868,20.5357470000126,17.214239,0,0,0,40,4449,49.9877,45937.068359375,,,,,,,,,,,,,0,,,,0,,,,,,50.00082395,,,,
,28157860.575,49.9996109,41246.59765625,0.0412446422824261,3.56291589102243E-6,1,0.999253354069792,40.0298881530762,1.98056010123807,27.7800001204014,0.462505630749036,0.0861024571438909,2.5,0.000246766137751946,0.041307979164954,0.000543839430650993,49.9996109,49.9996109,41236.66015625,41256.53515625,56.8103240347368,20.5333668722549,17.593889,0,0,0,40,4449,49.986,41246.59765625,,,,,,,,,,,,,0,,,,0,,,,,,49.9996109,,,,
,28157953.89,49.9993477,36581.55859375,0.0392539003649936,3.33380002975931E-6,1,0.999253354069792,40.0298881530762,1.98033874495166,27.7800001204014,0.440020035563322,0.0819634471725952,2.5,0.000236486535323748,0.0393046123688506,0.000521524607561138,49.9993477,49.9993477,36574.08984375,36589.02734375,57.1167224142753,20.5362094386958,17.214239,0,0,0,40,4449,49.9868,36581.55859375,,,,,,,,,,,,,0,,,,-0.00245,,,,,,49.9993477,,,,
,28158043.52,50.0000725,32101.68359375,0.0371320905524122,3.4494351551313E-6,1,0.999253354069792,40.0298881530762,1.98025842869215,27.7800001204014,0.41611743772708,0.0775244924351938,2.5,0.000222913518744777,0.0371711635003157,0.000494376136847789,50.0000725,50.0000725,32091.66015625,32111.70703125,57.1167224142753,20.5373506770485,16.834587,0,0,0,40,4449,49.9864,32101.68359375,,,,,,,,,,,,,0,,,,0,,,,,,50.0000725,,,,
,28158137.07,49.9996567,27426.5126953125,0.0346802718312456,2.72675913535718E-6,1,0.999253354069792,40.0298881530762,1.98034864732392,27.7800001204014,0.388562716077757,0.0723730905274396,2.5,0.000205032146226148,0.0347079631365679,0.00046007547122776,49.9996567,49.9996567,27419.193359375,27433.83203125,57.434063593083,20.534290072888,17.593889,0,0,0,40,4449,49.98795,27426.5126953125,,,,,,,,,,,,,0,,,,-0.00245,,,,,,49.9996567,,,,
,28158229.405,49.9987602,22811.166015625,0.0320030133215057,3.22200846619323E-6,1,0.999253354069792,40.0298881530762,1.98081433535352,27.7800001204014,0.358548587620891,0.0668237249896857,2.5,0.000191530820491646,0.0320204003466738,0.000427991177046262,49.9987602,49.9987602,22801.21875,22821.11328125,57.3926372815638,20.528285506283,16.834587,0,0,0,40,4449,49.9877,22811.166015625,,,,,,,,,,,,,0,,,,0.00245,,,,,,49.9987602,,,,
,28158322.9,50.0003853,18138.6103515625,0.0289340276322714,3.16044318693739E-6,1,0.999253354069792,40.0298881530762,1.98076423932269,27.7800001204014,0.324069668747489,0.0604199946462534,2.5,0.000174231208529564,0.0289422703783612,0.000388765058300431,50.0003853,50.0003853,18133.560546875,18143.66015625,57.1745629246983,20.5270607208877,17.593889,0,0,0,40,4449,49.98855,18138.6103515625,,,,,,,,,,,,,0,,,,0,,,,,,50.0003853,,,,
,28158413.4,49.9998398,13616.3017578125,0.0256177951409709,2.88497131282591E-6,1,0.999253354069792,40.0298881530762,1.98081179220794,27.7800001204014,0.286864434632384,0.0534752448401811,2.5,0.000153057981374701,0.0256188064808587,0.000343418917121094,49.9998398,49.9998398,13611.2900390625,13621.3134765625,57.2363115777176,20.5194931066828,17.973541,0,0,0,40,4449,49.9939,13616.3017578125,,,,,,,,,,,,,0,,,,-0.00245,,,,,,49.9998398,,,,
,28158504.18,50.0000458,9081.169921875,0.0218281594709838,2.79777274585558E-6,1,0.999253354069792,40.0298881530762,1.98130758336798,27.7800001204014,0.24442528304081,0.0455785023806413,2.5,0.000131418150593352,0.0218237191150255,0.000293794295327443,50.0000458,50.0000458,9073.6435546875,9088.6962890625,57.4919041035061,20.5272917925812,17.973541,0,0,0,40,4449,49.9865,9081.169921875,,,,,,,,,,,,,0,,,,0.00245,,,,,,50.0000458,,,,
,28158597.57,49.99978635,4410.05810546875,0.0174095113915954,2.84918794146229E-6,1,0.999253354069792,40.0298881530762,1.9814758263938,27.7800001204014,0.194917178204953,0.0363484605025923,2.5,0.000104914951051265,0.0174019615552473,0.000234426666146735,49.999649,49.9999237,4399.9736328125,4420.142578125,57.3035316303714,20.5218816376435,17.973541,0,0,0,40,4449,49.98615,4410.05810546875,,,,,,,,,,,,,0,,,,0.00245,,,,,,49.99978635,,,,
,28158689.49,50.0005951,-185.679672241211,0.0122541961012998,3.09021700475404E-6,1,0.999253354069792,40.0298881530762,1.98111574065696,27.7800001204014,0.1371523917819,0.0255715222322606,2.5,7.34511268136694E-5,0.0122468474409134,0.000164560323400336,50.0005951,50.0005951,-193.154968261719,-178.204376220703,57.0995265868522,20.5152036824689,17.593889,0,0,0,40,4449,49.9898,-185.679672241211,,,,,,,,,,,,,0,,,,-0.00245,,,,,,50.0005951,,,,
,28158782.15,49.9984856,-4812.82055664063,0.00567256727167506,3.24340642517475E-6,1,0.999253354069792,40.0298881530762,1.98165957200246,27.7800001204014,0.0635175672026895,0.0118420170916883,2.5,3.39397026506668E-5,0.00567022412204896,7.6140263067297E-5,49.9984856,49.9984856,-4817.84228515625,-4807.798828125,57.2050464369484,20.512928385415,17.973541,0,0,0,40,4449,49.99105,-4812.82055664063,,,,,,,,,,,,,0,,,,-0.00245,,,,,,49.9984856,,,,
,28158878.3,50.0000801,-9621.2333984375,-0.00125461351028463,3.54482327454809E-6,1,0.999253354069792,40.0298881530762,1.98105612290988,27.7800001204014,-0.0140448554077366,-0.00262355527951223,0.25,-7.95009426254778E-6,-0.00125439019441644,-1.72822595972863E-5,50.0000801,50.0000801,-9625.9951171875,-9616.4716796875,57.2019199228714,20.5129664997732,17.214239,0,0,0,40,4449,49.9858,-9621.2333984375,,,,,,,,,,,,,0,,,,0,,,,,,50.0000801,,,,
,28158969.555,50.0005035,-14179.1069335938,-0.00845007755159927,3.90053337098771E-6,1,0.999253354069792,40.0298881530762,1.9815569295124,27.7800001204014,-0.0946394742045242,-0.0176861830094205,0.25,-5.43123101353222E-5,-0.00845062274611264,-0.000117091312293066,50.0005035,50.0005035,-14189.11328125,-14169.1005859375,57.2542890336599,20.5111534941165,17.214239,0,0,0,40,4449,49.9868,-14179.1069335938,,,,,,,,,,,,,0,,,,0,,,,,,50.0005035,,,,
,28159064.61,49.9997253,-18931.3671875,-0.0159183417449696,3.81803889394908E-6,1,0.999253354069792,40.0298881530762,1.98149953933534,27.7800001204014,-0.178361904372493,-0.0332495645087129,2.5,-9.55376778250647E-5,-0.0159235715858528,-0.000213506186690073,49.9997253,49.9997253,-18941.111328125,-18921.623046875,56.9197520274291,20.5162201895767,17.214239,0,0,0,40,4449,49.9877,-18931.3671875,,,,,,,,,,,,,0,,,,0.0049,,,,,,49.9997253,,,,
,28159158.175,50.00043105,-23606.267578125,-0.0226162338706756,3.10532129496253E-6,1,0.999253354069792,40.0298881530762,1.98128176677539,27.7800001204014,-0.253450272957348,-0.047241727921298,2.5,-0.000135958820165623,-0.0226295108894385,-0.00030294325685659,50.0003624,50.0004997,-23618.677734375,-23593.857421875,57.3519925985638,20.5178535493985,17.593889,0,0,0,40,4449,49.9877,-23606.267578125,,,,,,,,,,,,,0,,,,-0.00245,,,,,,50.00043105,,,,
,28159251.89,50.0009537,-28291.6650390625,-0.0281569818482432,3.85404219046826E-6,1,0.999253354069792,40.0298881530762,1.98179669979479,27.7800001204014,-0.315705978325588,-0.0588237906199898,2.5,-0.000168483927785993,-0.028180734694753,-0.000375354929928531,50.0009537,50.0009537,-28296.498046875,-28286.83203125,57.1049979864868,20.5155480825675,17.593889,0,0,0,40,4449,49.98075,-28291.6650390625,,,,,,,,,,,,,0,,,,-0.0049,,,,,,50.0009537,,,,
,28159345.665,50.001152,-32976.517578125,-0.0326537855915988,3.35332674030287E-6,1,0.999253354069792,40.0298881530762,1.98166534984556,27.7800001204014,-0.366197300015869,-0.0682232377706762,2.5,-0.00019626255308551,-0.0326896667452662,-0.000434693280708054,50.001152,50.001152,-32984.06640625,-32968.96875,57.3738781971022,20.50733489934,17.973541,0,0,0,40,4449,49.984,-32976.517578125,,,,,,,,,,,,,0,,,,-0.00245,,,,,,50.001152,,,,
,28159440.51,50.0016136,-37716.00390625,-0.0362896989370638,2.97831389260436E-6,1,0.999253354069792,40.0298881530762,1.98150134286374,27.7800001204014,-0.407049204870352,-0.0757941813694915,2.5,-0.000216748033177062,-0.0363387095041241,-0.000479778491540459,50.0016136,50.0016136,-37725.84765625,-37706.16015625,57.3238539718714,20.5103986121351,17.593889,0,0,0,40,4449,49.9798,-37716.00390625,,,,,,,,,,,,,0,,,,0,,,,,,50.0016136,,,,
,28159534.555,50.0021439,-42418.203125,-0.0392368484256002,2.49763242536005E-6,1,0.999253354069792,40.0298881530762,1.98167259107816,27.7800001204014,-0.440245086874176,-0.0820022479415001,2.5,-0.000239174413968771,-0.0392993782950099,-0.000521185935851664,50.0021439,50.0021439,-42428.3984375,-42408.0078125,57.3191642007561,20.5120754705482,17.593889,0,0,0,40,4449,49.97995,-42418.203125,,,,,,,,,,,,,0,,,,0.00245,,,,,,50.0021439,,,,
,28159628.86,50.0015373,-47131.017578125,-0.0417328901620074,3.16905885966488E-6,1,0.999253354069792,40.0298881530762,1.98177870395833,27.7800001204014,-0.468394696755967,-0.08719442193229,2.5,-0.000252936593843958,-0.041809309004057,-0.000550062228760489,50.0015373,50.0015373,-47136.11328125,-47125.921875,57.2159892362176,20.5053143223318,17.593889,0,0,0,40,4449,49.9803,-47131.017578125,,,,,,,,,,,,,0,,,,-0.0049,,,,,,50.0015373,,,,
,28159722.415,50.0013161,-51806.49609375,-0.0438391388522454,3.78251629082314E-6,1,0.999253354069792,40.0298881530762,1.98177406564477,27.7800001204014,-0.492152065598708,-0.0915738780624287,2.5,-0.000265305098338649,-0.0439293666590287,-0.00057423421612336,50.0013161,50.0013161,-51814.0546875,-51798.9375,57.2574155477368,20.5062052761044,17.214239,0,0,0,40,4449,49.97795,-51806.49609375,,,,,,,,,,,,,0,,,,0,,,,,,50.0013161,,,,
,28159817.775,50.0004311,-56570.740234375,-0.0457473371119663,1.58996511257172E-6,1,0.999253354069792,40.0298881530762,1.98136001291371,27.7800001204014,-0.51358611036811,-0.0955603963908151,2.5,-0.000280477271752561,-0.0458516916108854,-0.000599217650941,50.0004311,50.0004311,-56575.59375,-56565.88671875,57.4332819645638,20.5151756333307,17.593889,0,0,0,40,4449,49.9796,-56570.740234375,,,,,,,,,,,,,0,,,,0,,,,,,50.0004311,,,,
,28159911.905,50.0008392,-61275.908203125,-0.0474253938909289,3.69076232036166E-6,1,0.999253354069792,40.0298881530762,1.98114817494488,27.7800001204014,-0.532485601233011,-0.0990604063386301,2.5,-0.000293399713180677,-0.0475436011123101,-0.00061990232650082,50.0008392,50.0008392,-61278.046875,-61273.76953125,57.2832092888714,20.515693808904,17.593889,0,0,0,40,4449,49.97975,-61275.908203125,,,,,,,,,,,,,0,,,,0,,,,,,50.0008392,,,,
,28160005.18,50.0013084,-65937.96875,-0.048929807163388,3.11560340459146E-6,1,0.999253354069792,40.0298881530762,1.98155003656669,27.7800001204014,-0.549598080112256,-0.102218081066645,2.5,-0.000304812301513069,-0.0490616151438669,-0.000637466266177069,50.0013084,50.0013084,-65945.6015625,-65930.3359375,57.2183341217753,20.5130111253927,17.214239,0,0,0,40,4449,49.98265,-65937.96875,,,,,,,,,,,,,0,,,,0,,,,,,50.0013084,,,,
,28160099.68,50.0018692,-70659.98828125,-0.0503221858324807,2.98967306552523E-6,1,0.999253354069792,40.0298881530762,1.98194412212331,27.7800001204014,-0.565463958660493,-0.105115927174036,2.5,-0.000313569938407541,-0.0504675528528194,-0.000651160886466929,50.0018692,50.0018692,-70662.6796875,-70657.296875,57.2652318329291,20.5072199396023,17.593889,0,0,0,40,4449,49.982,-70659.98828125,,,,,,,,,,,,,0,,,,-0.0049,,,,,,50.0018692,,,,
,28160195.575,50.0011063,-75454.78125,-0.0516464519400796,4.00742478905751E-6,1,0.999253354069792,40.0298881530762,1.98163820108476,27.7800001204014,-0.580371345838622,-0.107864525993221,2.5,-0.000324814005577372,-0.0518053370421063,-0.000666472858085534,50.0011063,50.0011063,-75459.5859375,-75449.9765625,57.2691399755253,20.5114538589118,17.214239,0,0,0,40,4449,49.9737,-75454.78125,,,,,,,,,,,,,0,,,,-0.0049,,,,,,50.0011063,,,,
,28160290.9,50.00263785,-80214.5546875,-0.0528597676539904,4.10895577868911E-6,1,0.999253354069792,40.0298881530762,1.98105734355787,27.7800001204014,-0.59395160676245,-0.110350294507873,2.5,-0.000334291702693577,-0.0530318255989898,-0.000678955699517714,50.0024719,50.0028038,-80222.2734375,-80206.8359375,57.1573670972753,20.5146153443765,17.593889,0,0,0,40,4449,49.97145,-80214.5546875,,,,,,,,,,,,,0,,,,-0.0049,,,,,,50.00263785,,,,
,28160387.01,50.0016479,-85019.55078125,-0.0540012042692424,3.81452357587376E-6,1,0.999253354069792,40.0298881530762,1.98138709817211,27.7800001204014,-0.606982886389662,-0.11274111671198,2.5,-0.000344286700641173,-0.0541862729305376,-0.000691124200519513,50.0016479,50.0016479,-85024.546875,-85014.5546875,57.2636685758907,20.5158818461445,17.593889,0,0,0,40,4449,49.9734,-85019.55078125,,,,,,,,,,,,,0,,,,-0.00245,,,,,,50.0016479,,,,
,28160476.825,50.002882,-89508.79296875,-0.055010429867462,3.4793538836745E-6,1,0.999253354069792,40.0298881530762,1.98160084930694,27.7800001204014,-0.618495005907376,-0.114819448048743,2.5,-0.00035072427985324,-0.0552073922857576,-0.000698976070838238,50.0027504,50.0030136,-89516.3515625,-89501.234375,57.1878506095253,20.5138985381702,17.593889,0,0,0,40,4449,49.9736,-89508.79296875,,,,,,,,,,,,,0,,,,0.00245,,,,,,50.002882,,,,
,28160583.8,49.9995308,-86117.23046875,-0.0543473027586314,3.55856644504299E-6,1,0.999253354069792,40.0298881530762,1.98149112479701,27.7800001204014,-0.610925509658902,-0.113482258332521,2.5,-0.000348503802732248,-0.0545356331888881,-0.000696342908456714,49.9995308,49.9995308,-86119.78125,-86114.6796875,57.444224763833,20.5126584494303,17.214239,0,0,0,40,4449,49.97565,-86117.23046875,,,,,,,,,,,,,0,,,,0.0049,,,,,,49.9995308,,,,
,28160674.29,49.9997978,-81594.6640625,-0.053367082345098,3.61021314659269E-6,1,0.999253354069792,40.0298881530762,1.9818591028217,27.7800001204014,-0.599924614430273,-0.11139881443229,2.5,-0.000333762840568346,-0.0535435169970208,-0.000680225482253179,49.9997978,49.9997978,-81602.125,-81587.203125,57.1511140691214,20.5079479364977,17.593889,0,0,0,40,4449,49.9735,-81594.6640625,,,,,,,,,,,,,0,,,,0,,,,,,49.9997978,,,,
,28160768.515,50.0004997,-76887.390625,-0.0522946708687459,2.91307604645385E-6,1,0.999253354069792,40.0298881530762,1.98174854194769,27.7800001204014,-0.587727733337104,-0.109180582413423,2.5,-0.00032600985599557,-0.0524584315186471,-0.000670460194993776,50.0004997,50.0004997,-76894.8515625,-76879.9296875,57.3176009437176,20.5094857916885,17.593889,0,0,0,40,4449,49.97305,-76887.390625,,,,,,,,,,,,,0,,,,-0.0049,,,,,,50.0004997,,,,
,28160861.21,49.9992638,-72255.10546875,-0.0511663942305624,2.31243334470152E-6,1,0.999253354069792,40.0298881530762,1.98145205780272,27.7800001204014,-0.574850150560484,-0.10685740564959,2.5,-0.00032013018384899,-0.0513173912875737,-0.000661836766625971,49.9992638,49.9992638,-72262.6875,-72247.5234375,57.3621537693137,20.5116162940089,17.973541,0,0,0,40,4449,49.97175,-72255.10546875,,,,,,,,,,,,,0,,,,0,,,,,,49.9992638,,,,
,28160955.3,49.9992027,-67553.0078125,-0.0499706697682086,4.31941745886109E-6,1,0.999253354069792,40.0298881530762,1.98169497556009,27.7800001204014,-0.561374290248458,-0.104360354783384,2.5,-0.000308712911465027,-0.0501086384819679,-0.000646932901944783,49.9992027,49.9992027,-67560.328125,-67545.6875,57.2355299491984,20.5093493945502,17.593889,0,0,0,40,4449,49.9766,-67553.0078125,,,,,,,,,,,,,0,,,,0.00245,,,,,,49.9992027,,,,
,28161049.19,49.9989967,-62860.822265625,-0.0486949206560185,5.22246508288038E-6,1,0.999253354069792,40.0298881530762,1.98218344313778,27.7800001204014,-0.547065364721581,-0.101685387220502,2.5,-0.000295174243876418,-0.0488196951475155,-0.000629005012254089,49.9989967,49.9989967,-62868.25,-62853.39453125,57.4176493941791,20.5068987587315,17.214239,0,0,0,40,4449,49.9775,-62860.822265625,,,,,,,,,,,,,0,,,,0.00245,,,,,,49.9989967,,,,
,28161142.2,49.9994659,-58212.857421875,-0.0473261488154584,3.3295894047499E-6,1,0.999253354069792,40.0298881530762,1.98155172771719,27.7800001204014,-0.531404780185673,-0.0988473657530457,2.5,-0.000289110994971833,-0.0474376879285426,-0.000617488286540954,49.9994659,49.9994659,-58225.29296875,-58200.421875,57.1339182416984,20.5102989157927,17.593889,0,0,0,40,4449,49.98355,-58212.857421875,,,,,,,,,,,,,0,,,,-0.0049,,,,,,49.9994659,,,,
,28161235.99,49.9991531,-53525.634765625,-0.0458471729142978,9.21016547343039E-7,1,0.999253354069792,40.0298881530762,1.98146171583123,27.7800001204014,-0.514653031590382,-0.0957963645316116,2.5,-0.000281875694361973,-0.045945249538352,-0.000603672406670245,49.9991531,49.9991531,-53533.06640625,-53518.203125,56.882233858506,20.5144579828674,17.214239,0,0,0,40,4449,49.9788,-53525.634765625,,,,,,,,,,,,,0,,,,0,,,,,,49.9991531,,,,
,28161330.015,49.99947165,-48823.57421875,-0.0442610632026516,2.52196239282067E-6,1,0.999253354069792,40.0298881530762,1.98164940063568,27.7800001204014,-0.496776624154799,-0.0924978555076883,2.5,-0.000271162797097558,-0.044345766391701,-0.000585156358354378,49.9992943,49.999649,-48835.953125,-48811.1953125,57.139389641333,20.5159880144185,17.973541,0,0,0,40,4449,49.9791,-48823.57421875,,,,,,,,,,,,,0,,,,-0.00245,,,,,,49.99947165,,,,
,28161424.155,49.9994316,-44117.923828125,-0.0425387478104656,4.09934875232619E-6,1,0.999253354069792,40.0298881530762,1.9819011268202,27.7800001204014,-0.477401273897341,-0.0888385995100367,2.5,-0.000253068659870724,-0.0426102446449406,-0.000557799914111053,49.9994316,49.9994316,-44127.9296875,-44107.91796875,57.200356665833,20.5119825250448,17.214239,0,0,0,40,4449,49.97795,-44117.923828125,,,,,,,,,,,,,0,,,,0.00245,,,,,,49.9994316,,,,
,28161515.905,49.9991531,-39533.3203125,-0.040691861358036,1.43269639341385E-6,1,0.999253354069792,40.0298881530762,1.98199360928966,27.7800001204014,-0.456577063080201,-0.0850215434781062,2.5,-0.000244440599150457,-0.0407506387218231,-0.000538467112648603,49.9991531,49.9991531,-39535.7109375,-39530.9296875,57.1221938139099,20.5070509500272,17.214239,0,0,0,40,4449,49.9753,-39533.3203125,,,,,,,,,,,,,0,,,,0,,,,,,49.9991531,,,,
,28161609.81,49.9993362,-34840.865234375,-0.0386169766963749,3.76038335243193E-6,1,0.999253354069792,40.0298881530762,1.98187219376678,27.7800001204014,-0.433162442578109,-0.0806714997821762,2.5,-0.000230559247081697,-0.0386632393138617,-0.000511757317744124,49.9993362,49.9993362,-34848.49609375,-34833.234375,57.2910255740638,20.508792492469,17.214239,0,0,0,40,4449,49.97905,-34840.865234375,,,,,,,,,,,,,0,,,,0,,,,,,49.9993362,,,,
,28161702.39,49.9989166,-30213.6767578125,-0.036346003430937,1.66335737220418E-6,1,0.999253354069792,40.0298881530762,1.98240537565633,27.7800001204014,-0.407690343105351,-0.0759391703321327,2.5,-0.00021613674712888,-0.0363804710192008,-0.000482538665736716,49.9989166,49.9989166,-30226.212890625,-30201.140625,57.2464727484676,20.4993021104256,17.214239,0,0,0,40,4449,49.9784,-30213.6767578125,,,,,,,,,,,,,0,,,,0,,,,,,49.9989166,,,,
,28161795.07,49.9980545,-25583.8203125,-0.0338162863724804,2.18202866125407E-6,1,0.999253354069792,40.0298881530762,1.98221464863734,27.7800001204014,-0.379182691754544,-0.0706358859908466,2.5,-0.000200221038935854,-0.0338397861601025,-0.000449421658026865,49.9979706,49.9981384,-25593.7109375,-25573.9296875,57.3027500018522,20.5047955523493,17.973541,0,0,0,40,4449,49.9798,-25583.8203125,,,,,,,,,,,,,0,,,,-0.00245,,,,,,49.9980545,,,,
,28161888.62,49.99832915,-20906.1875,-0.0309758701488196,2.35912176798294E-6,1,0.999253354069792,40.0298881530762,1.98205215749894,27.7800001204014,-0.347211577430587,-0.0647064701834414,2.5,-0.000184596645688855,-0.0309893750824337,-0.000413835535722579,49.9982376,49.9984207,-20910.9765625,-20901.3984375,57.393418910083,20.5078675194252,17.593889,0,0,0,40,4449,49.98005,-20906.1875,,,,,,,,,,,,,0,,,,0.0049,,,,,,49.99832915,,,,
,28161981.74,49.9976044,-16251.6430664062,-0.0277625350559654,2.00514070245218E-6,1,0.999253354069792,40.0298881530762,1.9820586440731,27.7800001204014,-0.31111599156209,-0.0579721070973114,2.5,-0.000164091184571575,-0.0277675670357845,-0.000370157461676197,49.9976044,49.9976044,-16254.15625,-16249.1298828125,57.3605905122753,20.5009708221958,17.214239,0,0,0,40,4449,49.986,-16251.6430664062,,,,,,,,,,,,,0,,,,-0.0049,,,,,,49.9976044,,,,
,28162074.52,49.9998055,-11616.427734375,-0.0241092523749809,2.88960475316611E-6,1,0.999253354069792,40.0298881530762,1.9823917314097,27.7800001204014,-0.270146554476534,-0.0503684086130947,2.5,-0.000144726202524926,-0.0241075664978159,-0.00032398828569693,49.9998055,49.9998055,-11626.4814453125,-11606.3740234375,57.4215575367753,20.5002937323701,17.593889,0,0,0,40,4449,49.98755,-11616.427734375,,,,,,,,,,,,,0,,,,0.00245,,,,,,49.9998055,,,,
,28162166.14,49.9992104,-7035.49877929688,-0.0199731982709221,2.91387811028275E-6,1,0.999253354069792,40.0298881530762,1.98235114302089,27.7800001204014,-0.223748448539389,-0.0416922971311465,2.5,-0.000117565965288314,-0.0199670668448449,-0.000266164411513368,49.9992104,49.9992104,-7042.86767578125,-7028.1298828125,57.1026531009291,20.5017899151413,17.214239,0,0,0,40,4449,49.9841,-7035.49877929688,,,,,,,,,,,,,0,,,,-0.00245,,,,,,49.9992104,,,,
,28162259.43,50.000061,-2372.20654296875,-0.0151260725357564,2.5640849030953E-6,1,0.999253354069792,40.0298881530762,1.98231678180812,27.7800001204014,-0.169406858337985,-0.0315826365655333,2.5,-9.04194498799639E-5,-0.0151181735108841,-0.000202917607088424,50.000061,50.000061,-2384.43774414062,-2359.97534179687,57.1995750373137,20.4979824869126,17.973541,0,0,0,40,4449,49.9878,-2372.20654296875,,,,,,,,,,,,,0,,,,-0.0049,,,,,,50.000061,,,,
,28162350.745,50.0009537,2187.00952148438,-0.00909958382863679,3.6346286049611E-6,1,0.999253354069792,40.0298881530762,1.98263326689992,27.7800001204014,-0.101926987424243,-0.0190017084238326,2.5,-5.43432455931211E-5,-0.00909475187918422,-0.000122018074176637,50.0009537,50.0009537,2179.62866210938,2194.39038085938,57.2331850636407,20.4897344582102,17.214239,0,0,0,40,4449,49.9839,2187.00952148438,,,,,,,,,,,,,0,,,,0,,,,,,50.0009537,,,,
,28162444.965,50.0003166,6895.69653320312,-0.00228533182447894,3.32296631641437E-6,1,0.999253354069792,40.0298881530762,1.98287304496354,27.7800001204014,-0.0256019157359505,-0.0047835944823822,0.25,-1.45770613206383E-5,-0.00228460371439062,-3.157942083369E-5,50.0003166,50.0003166,6893.28173828125,6898.111328125,57.0010413934291,20.4848840038303,17.973541,0,0,0,40,4449,49.9809,6895.69653320312,,,,,,,,,,,,,0,,,,0,,,,,,50.0003166,,,,
,28162537.1,50.0004463,11504.134765625,0.00472774577971953,3.66219867137104E-6,1,0.999253354069792,40.0298881530762,1.98303980322998,27.7800001204014,0.0529828645332329,0.00988593535405895,0.25,2.9013600193973E-5,0.00472737705125747,6.41674329678685E-5,50.0004463,50.0004463,11496.7412109375,11511.5283203125,57.1331366131791,20.4860493766896,17.593889,0,0,0,40,4449,49.9839,11504.134765625,,,,,,,,,,,,,0,,,,0.00245,,,,,,50.0004463,,,,
,28162632.79,49.9990005,16286.8725585938,0.0123817839064861,3.85170281168388E-6,1,0.999253354069792,40.0298881530762,1.98277624562117,27.7800001204014,0.13880528104382,0.0258485152291122,2.5,7.18132858258339E-5,0.0123840579431513,0.000163714891148825,49.9990005,49.9990005,16279.1904296875,16294.5546875,56.9049010855637,20.4914616204937,17.593889,0,0,0,40,4449,49.98485,16286.8725585938,,,,,,,,,,,,,0,,,,0,,,,,,49.9990005,,,,
,28162725.465,50.0009689,20916.61328125,0.0194287698516898,3.45775433315969E-6,1,0.999253354069792,40.0298881530762,1.98264489921636,27.7800001204014,0.21784571940455,0.0405737785929273,2.5,0.000113715664166528,0.0194372840714664,0.000257495518546346,50.0009689,50.0009689,20906.861328125,20926.365234375,57.0385595623522,20.490535613761,17.973541,0,0,0,40,4449,49.9834,20916.61328125,,,,,,,,,,,,,0,,,,0,,,,,,50.0009689,,,,
,28162818.315,50.0014458,25559.49609375,0.0255151748410651,3.17289785132182E-6,1,0.999253354069792,40.0298881530762,1.98281771939312,27.7800001204014,0.286187132457236,0.0533009185728547,2.5,0.000150093141161378,0.0255328987106736,0.000338121947699931,50.0014458,50.0014458,25549.6953125,25569.296875,57.3355783996599,20.4964784125965,17.593889,0,0,0,40,4449,49.98295,25559.49609375,,,,,,,,,,,,,0,,,,-0.0049,,,,,,50.0014458,,,,
,28162912.93,50.0007477,30290.0927734375,0.030516070608114,3.56008514497668E-6,1,0.999253354069792,40.0298881530762,1.98265749158658,27.7800001204014,0.342345079679036,0.0637383263871289,2.5,0.000178986408208649,0.0305452039401247,0.000402623868474334,50.0007477,50.0007477,30287.517578125,30292.66796875,57.0721695886791,20.4970195356913,17.593889,0,0,0,40,4449,49.9851,30290.0927734375,,,,,,,,,,,,,0,,,,0,,,,,,50.0007477,,,,
,28163006.23,50.001152,34949.802734375,0.0345093878485952,3.75556666709104E-6,1,0.999253354069792,40.0298881530762,1.9829265375019,27.7800001204014,0.387291558764263,0.0721051324277429,2.5,0.000204069624117148,0.0345509832422183,0.000455304504393014,50.001152,50.001152,34939.78125,34959.82421875,57.068261446083,20.4967739640467,17.973541,0,0,0,40,4449,49.984,34949.802734375,,,,,,,,,,,,,0,,,,0.00245,,,,,,50.001152,,,,
,28163098.835,50.0002823,39579.96875,0.0376656158738754,2.41037214075022E-6,1,0.999253354069792,40.0298881530762,1.98285211209915,27.7800001204014,0.42280531408392,0.0786873149468296,2.5,0.000222374047138821,0.0377201394104363,0.000494506017241643,50.0002823,50.0002823,39577.4296875,39582.5078125,57.0119841926983,20.4972579545105,17.214239,0,0,0,40,4449,49.9751,39579.96875,,,,,,,,,,,,,0,,,,0,,,,,,50.0002823,,,,
,28163191.515,50.0008698,44212.650390625,0.0403282217562526,4.6143612454617E-6,1,0.999253354069792,40.0298881530762,1.98311831663877,27.7800001204014,0.452865641570076,0.0842458859682982,2.5,0.000237660264274433,0.0403962241735234,0.000526494581154785,50.0008698,50.0008698,44204.89453125,44220.40625,57.2050464369484,20.4962911273498,17.973541,0,0,0,40,4449,49.97945,44212.650390625,,,,,,,,,,,,,0,,,,0.00245,,,,,,50.0008698,,,,
,28163283.43,50.0005455,48805.98828125,0.0425624908651718,3.65262905091222E-6,1,0.999253354069792,40.0298881530762,1.98258172222137,27.7800001204014,0.477937392350023,0.0889290856430186,2.5,0.000255503394278451,0.0426439667820817,0.000557441011716578,50.0005455,50.0005455,48793.9140625,48818.0625,57.2597604332945,20.5047969768223,17.593889,0,0,0,40,4449,49.98195,48805.98828125,,,,,,,,,,,,,0,,,,0.00245,,,,,,50.0005455,,,,
,28163377.035,49.9996414,53486.25390625,0.0445548323449598,4.10121288983848E-6,1,0.999253354069792,40.0298881530762,1.98261870373839,27.7800001204014,0.500436300010004,0.0930800850923123,2.5,0.00026787733510092,0.0446501090707369,0.000580617255582051,49.9996414,49.9996414,53481.34375,53491.1640625,56.9439825115252,20.5008682390765,17.593889,0,0,0,40,4449,49.97945,53486.25390625,,,,,,,,,,,,,0,,,,-0.00245,,,,,,49.9996414,,,,
,28163471.65,50.0014648,58214.3203125,0.0463277502960091,2.28625210597947E-6,1,0.999253354069792,40.0298881530762,1.98267487454944,27.7800001204014,0.520482135988488,0.0967733878750897,2.5,0.000279339065171483,0.0464368642025971,0.000600817394549696,50.0014648,50.0014648,58209.63671875,58219.00390625,57.1003082153714,20.4982550533768,17.593889,0,0,0,40,4449,49.9707,58214.3203125,,,,,,,,,,,,,0,,,,0,,,,,,50.0014648,,,,
,28163565.515,50.0017586,62907.060546875,0.047924967664884,3.25816659559426E-6,1,0.999253354069792,40.0298881530762,1.98257689416351,27.7800001204014,0.538523701465805,0.100068710455094,2.5,0.000288062028824039,0.0480478995096087,0.000616559453418718,50.0017586,50.0017586,62902,62912.12109375,57.0182372208522,20.4958949763371,17.973541,0,0,0,40,4449,49.98,62907.060546875,,,,,,,,,,,,,0,,,,0,,,,,,50.0017586,,,,
,28163660.565,50.0008965,67657.8359375,0.0494004552184578,4.11331763024945E-6,1,0.999253354069792,40.0298881530762,1.98271231414559,27.7800001204014,0.555253691089058,0.103160682482846,2.5,0.000299968651408464,0.0495370913188177,0.000634219828295188,50.0008965,50.0008965,67650.390625,67665.28125,56.8666012881214,20.4989060899997,17.973541,0,0,0,40,4449,49.9755,67657.8359375,,,,,,,,,,,,,0,,,,0.00245,,,,,,50.0008965,,,,
,28163752.92,50.0014,72273.08203125,0.0507329826855291,2.50654067807586E-6,1,0.999253354069792,40.0298881530762,1.98259441388867,27.7800001204014,0.570325053469313,0.105847097133378,2.5,0.000302915716541658,0.0508828809645982,0.000641642704592823,50.0014,50.0014,72263.3203125,72282.84375,56.9541436822753,20.5045090055555,17.593889,0,0,0,40,4449,49.9788,72273.08203125,,,,,,,,,,,,,0,,,,-0.00245,,,,,,50.0014,,,,
,28163848.515,50.000412,77051.2734375,0.0519935769355547,3.44586949861924E-6,1,0.999253354069792,40.0298881530762,1.98302225185871,27.7800001204014,0.584716643094996,0.108560961449443,2.5,0.00031912497204173,0.0521567480902332,0.000661407710266989,50.000412,50.000412,77051.2734375,77051.2734375,56.9760292808137,20.5016236435961,17.214239,0,0,0,40,4449,49.9726,77051.2734375,,,,,,,,,,,,,0,,,,0,,,,,,50.000412,,,,
,28163944.25,50.0013809,81836.90625,0.0531781222725907,4.68829564808008E-6,1,0.999253354069792,40.0298881530762,1.98286193915524,27.7800001204014,0.59810247746858,0.111014057934335,2.5,0.000328849468296404,0.0533544057438805,0.000673820435873,50.0013809,50.0013809,81824.375,81849.4375,57.0721695886791,20.5014011333002,17.973541,0,0,0,40,4449,49.971,81836.90625,,,,,,,,,,,,,0,,,,-0.00245,,,,,,50.0013809,,,,
,28164036.97,50.0021706,86472.81640625,0.0542602839531994,2.12271167268421E-6,1,0.999253354069792,40.0298881530762,1.98274236237287,27.7800001204014,0.610338622499746,0.113278611581196,2.5,0.000340189301595695,0.0544489832411341,0.000687074520981693,50.0021706,50.0021706,86467.7109375,86477.921875,57.0315249056791,20.4951391844719,17.593889,0,0,0,40,4449,49.9684,86472.81640625,,,,,,,,,,,,,0,,,,0,,,,,,50.0021706,,,,
,28164145.4,50.0002441,89179.37109375,0.0549105506228841,3.08293668737362E-6,1,0.999253354069792,40.0298881530762,1.9829856956807,27.7800001204014,0.617792259028709,0.11460210716589,2.5,0.000342227179605729,0.055106576034527,0.000690206766965736,50.0002441,50.0002441,89171.9375,89186.8046875,56.966649738583,20.5016508598802,17.973541,0,0,0,40,4449,49.96905,89179.37109375,,,,,,,,,,,,,0,,,,-0.0049,,,,,,50.0002441,,,,
,28164234.795,49.9992943,84711.82421875,0.0539758427659617,2.15530180257301E-6,1,0.999253354069792,40.0298881530762,1.98278758867066,27.7800001204014,0.607125443556058,0.112627347390789,2.5,0.000331731153714411,0.0541603327985349,0.000678696935078397,49.9992943,49.9992943,84709.40625,84714.2421875,57.1221938139099,20.5030613813177,17.214239,0,0,0,40,4449,49.9749,84711.82421875,,,,,,,,,,,,,0,,,,0.00245,,,,,,49.9992943,,,,
,28164329.075,49.9987869,79997.8828125,0.0529387815721825,2.87987295467171E-6,1,0.999253354069792,40.0298881530762,1.98284240182429,27.7800001204014,0.595349321837481,0.110595825359049,2.5,0.000333341710675946,0.0531106913522126,0.000678744944228881,49.9987869,49.9987869,79990.390625,80005.375,56.8963031718522,20.5000584570992,17.214239,0,0,0,40,4449,49.9722,79997.8828125,,,,,,,,,,,,,0,,,,0,,,,,,49.9987869,,,,
,28164423.445,49.9990883,75283.98046875,0.0518436934340143,3.61389851998487E-6,1,0.999253354069792,40.0298881530762,1.98312086967001,27.7800001204014,0.583007427668167,0.108314512670288,2.5,0.000322444012502312,0.0520028728336065,0.000665569885193884,49.9990883,49.9990883,75276.484375,75291.4765625,56.9760292808137,20.5028417230203,17.593889,0,0,0,40,4449,49.9743,75283.98046875,,,,,,,,,,,,,0,,,,0,,,,,,49.9990883,,,,
,28164515.615,49.9997864,70673.0703125,0.0506992195033567,4.32162545793265E-6,1,0.999253354069792,40.0298881530762,1.98204147655181,27.7800001204014,0.569736684812528,0.10585433498412,2.5,0.000311096317236815,0.0508456730524385,0.000651219794873146,49.9997864,49.9997864,70668.03125,70678.109375,57.1745629246983,20.512677756509,17.973541,0,0,0,40,4449,49.9731,70673.0703125,,,,,,,,,,,,,0,,,,-0.00245,,,,,,49.9997864,,,,
,28164609.575,49.99963,65977.359375,0.0494779892613898,5.37496769192252E-6,1,0.999253354069792,40.0298881530762,1.98248098300609,27.7800001204014,0.556024041579986,0.103304468236954,2.5,0.000298881329066131,0.0496113580754147,0.000635227782984068,49.99963,49.99963,65970,65984.71875,57.0643533034868,20.50696541098,17.593889,0,0,0,40,4449,49.9742,65977.359375,,,,,,,,,,,,,0,,,,-0.0049,,,,,,49.99963,,,,
,28164702.705,50.000248,61321.58203125,0.0481891777251554,5.88122866979958E-6,1,0.999253354069792,40.0298881530762,1.98278354341447,27.7800001204014,0.541502261854207,0.100658337403659,2.5,0.000291307150808871,0.0483093799923053,0.000623032688742928,50.000248,50.000248,61316.59375,61326.5703125,56.9236601700253,20.5032503634218,17.214239,0,0,0,40,4449,49.9729,61321.58203125,,,,,,,,,,,,,0,,,,0,,,,,,50.000248,,,,
,28164796.065,49.9995842,56656.25390625,0.0467929284379287,4.05065301659681E-6,1,0.999253354069792,40.0298881530762,1.98259592851266,27.7800001204014,0.525654132299847,0.0977167857926732,2.5,0.000279262354537437,0.0468998162773502,0.00060523456350515,49.9995842,49.9995842,56648.609375,56663.8984375,57.241001348833,20.5094250486778,17.214239,0,0,0,40,4449,49.9685,56656.25390625,,,,,,,,,,,,,0,,,,0,,,,,,49.9995842,,,,
,28164889.475,49.9990005,51985.876953125,0.0452996942207355,4.04721409562141E-6,1,0.999253354069792,40.0298881530762,1.98266243253958,27.7800001204014,0.508783083712383,0.0945972563580081,2.5,0.000268154372369986,0.0453933455255443,0.000587236309494741,49.9990005,49.9990005,51981.03125,51990.72265625,57.2800827747945,20.5049361517251,17.973541,0,0,0,40,4449,49.9763,51985.876953125,,,,,,,,,,,,,0,,,,-0.0049,,,,,,49.9990005,,,,
,28164983.04,49.9984512,47310.978515625,0.0436692111391961,4.42241333000037E-6,1,0.999253354069792,40.0298881530762,1.9825749054892,27.7800001204014,0.490327502863448,0.0912311123003025,2.5,0.000260807582835505,0.0437495677136295,0.000571601655609459,49.9984512,49.9984512,47303.40625,47318.55078125,56.8556584888522,20.5078499810172,17.593889,0,0,0,40,4449,49.9773,47310.978515625,,,,,,,,,,,,,0,,,,0,,,,,,49.9984512,,,,
,28165075.515,49.9988861,42687.826171875,0.0419346375244507,4.28146629117306E-6,1,0.999253354069792,40.0298881530762,1.98287999392821,27.7800001204014,0.47080949210356,0.0876118225681533,2.5,0.000248587565240857,0.0420020775526374,0.000549827675683616,49.9988861,49.9988861,42685.17578125,42690.4765625,57.3207274577945,20.5013899392764,17.593889,0,0,0,40,4449,49.9778,42687.826171875,,,,,,,,,,,,,0,,,,-0.00245,,,,,,49.9988861,,,,
,28165167.17,50.000824,38107.673828125,0.0400303969674876,3.33896785595521E-6,1,0.999253354069792,40.0298881530762,1.98243194308809,27.7800001204014,0.449220121850104,0.0836337702766883,2.5,0.000238187033589555,0.0400852783338417,0.000528139868843459,50.000824,50.000824,38097.60546875,38117.7421875,56.7657712091406,20.5041297604109,17.593889,0,0,0,40,4449,49.97845,38107.673828125,,,,,,,,,,,,,0,,,,-0.00245,,,,,,50.000824,,,,
,28165259.035,49.9991455,33517.677734375,0.0379544429786831,4.2278421317933E-6,1,0.999253354069792,40.0298881530762,1.98259771665055,27.7800001204014,0.425848568288623,0.0793119702562111,2.5,0.000226230024698756,0.0379971668127538,0.000503164823423464,49.9991455,49.9991455,33510.13671875,33525.21875,56.8970848003714,20.5017938403131,17.973541,0,0,0,40,4449,49.9726,33517.677734375,,,,,,,,,,,,,0,,,,-0.0049,,,,,,49.9991455,,,,
,28165353.43,49.9981575,28797.689453125,0.0355698318405454,3.26590168473646E-6,1,0.999253354069792,40.0298881530762,1.98208644621137,27.7800001204014,0.398890117740916,0.0743091910572625,2.5,0.000211810794324094,0.0356007873369792,0.000472991796221098,49.9981575,49.9981575,28787.837890625,28807.541015625,57.1026531009291,20.504822083112,18.353191,0,0,0,40,4449,49.97565,28797.689453125,,,,,,,,,,,,,0,,,,-0.00245,,,,,,49.9981575,,,,
,28165445.985,49.9984856,24172.3203125,0.0329895188437404,2.99296115348294E-6,1,0.999253354069792,40.0298881530762,1.98257452459653,27.7800001204014,0.36994883723539,0.0689076472940269,2.5,0.000194248624470554,0.0330098733869231,0.00043769985168175,49.9984856,49.9984856,24169.669921875,24174.970703125,57.1769078102561,20.5010440230734,17.973541,0,0,0,40,4449,49.979,24172.3203125,,,,,,,,,,,,,0,,,,-0.00245,,,,,,49.9984856,,,,
,28165537.535,50.0005951,19597.4404296875,0.0300963275738966,3.58134285644681E-6,1,0.999253354069792,40.0298881530762,1.98262179042896,27.7800001204014,0.337422471023271,0.0628713155638757,2.5,0.00017817316866697,0.0301072480956384,0.000401119433437559,50.0005951,50.0005951,19587.3515625,19607.529296875,57.4027984523138,20.5084043252183,17.593889,0,0,0,40,4449,49.9765,19597.4404296875,,,,,,,,,,,,,0,,,,-0.0049,,,,,,50.0005951,,,,
,28165629.815,49.999485,14985.2290039062,0.0268195795099969,3.25334737720434E-6,1,0.999253354069792,40.0298881530762,1.98267337491138,27.7800001204014,0.300615603677509,0.0560224017491427,2.5,0.000158966521476161,0.0268225471155728,0.000358154464329173,49.999485,49.999485,14975.2783203125,14995.1796875,57.4121779945445,20.5045916979722,17.593889,0,0,0,40,4449,49.9818,14985.2290039062,,,,,,,,,,,,,0,,,,0.00245,,,,,,49.999485,,,,
,28165721.36,49.9984398,10409.8354492187,0.023098906858315,2.70011702106171E-6,1,0.999253354069792,40.0298881530762,1.98305858184712,27.7800001204014,0.258898966244709,0.0482292116061761,2.5,0.000134964161042028,0.0230957944986064,0.000306760440466509,49.9984398,49.9984398,10397.396484375,10422.2744140625,56.9775925378522,20.4960317327445,17.973541,0,0,0,40,4449,49.98025,10409.8354492187,,,,,,,,,,,,,0,,,,-0.00245,,,,,,49.9984398,,,,
,28165814.57,49.9990196,5749.51611328125,0.0187789403368156,2.58588684993765E-6,1,0.999253354069792,40.0298881530762,1.98352588904169,27.7800001204014,0.210472695290114,0.0392337536030698,2.5,0.00011183282296534,0.018771952841337,0.000251543887542027,49.9990196,49.9990196,5744.50830078125,5754.52392578125,57.3176009437176,20.4945260584027,17.214239,0,0,0,40,4449,49.97915,5749.51611328125,,,,,,,,,,,,,0,,,,0.00245,,,,,,49.9990196,,,,
,28165906.49,50.0002899,1155.72039794922,0.0137898482323075,3.15812248341287E-6,1,0.999253354069792,40.0298881530762,1.9830068090555,27.7800001204014,0.154486475877098,0.0287956348419881,2.5,8.19778770246825E-5,0.0137819882422867,0.00018451887662506,50.0002899,50.0002899,1145.62060546875,1165.82019042969,57.3058765159291,20.4905733700902,17.593889,0,0,0,40,4449,49.98535,1155.72039794922,,,,,,,,,,,,,0,,,,-0.0049,,,,,,50.0002899,,,,
,28165929.475,49.9992828,-0.487160757184029,0.0123703372484293,2.7928875248715E-6,1,0.999253354069792,40.0298881530762,1.98282361317869,27.7800001204014,0.138568454737933,0.025817484439663,2.5,7.25914343431583E-5,0.0123628414003428,0.000164561707706833,49.9992828,49.9992828,-0.502384543418884,-0.471936970949173,57.2425646058714,20.4955468653941,17.973541,0,0,0,40,4417,49.9795,-0.487160757184029,,,,,,,,,,,,,0,,,,-0.0049,,,,,,49.9992828,,,,