File: data/monolayers/nanoparticles/Ol_CoFe_C/vsm/data_dispersion/DD67_HYST_20K.DAT
[Header]
; VSM Data File (default extension .dat)
; Copyright (c) 2003-2013, Quantum Design, Inc. All rights reserved.
TITLE,
FILEOPENTIME,28143429.06,11/23/2018,1:37 am
BYAPP,VSM,2.0,2.0
INFO,PPMS VSM Option Release 1.4.10 Build 1,APPNAME
INFO,Quantum Design Linear Motor Servo Controller,MOTOR_MODULE_NAME
INFO,3101-100 M1,MOTOR_HW_VERSION
INFO,MMC1014,MOTOR_SERIAL_NUMBER
INFO,SRV No X-over 01.03.11,MOTOR_SOFTWARE_VERSION
INFO,Quantum Design VSM Detection Module,VSM_MODULE_NAME
INFO,3101-150 F0,VSM_HW_VERSION
INFO,VSM707,VSM_SERIAL_NUMBER
INFO,VSM No X-over 01.02.05 May 20 2008 13:51:47,VSM_SOFTWARE_VERSION
INFO,704,PREAMP_SERIAL_NUMBER
INFO,822,COIL_SERIAL_NUMBER
INFO,0,MOMENT_UNITS
INFO,CoFe2O4,SAMPLE_MATERIAL
INFO,dispersion in ampulle,SAMPLE_COMMENT
INFO,,SAMPLE_MASS
INFO,,SAMPLE_VOLUME
INFO,,SAMPLE_MOLECULAR_WEIGHT
INFO,,SAMPLE_SIZE
INFO,,SAMPLE_SHAPE
DATATYPE,COMMENT,1
DATATYPE,TIME,2
STARTUPAXIS,X,2
STARTUPAXIS,Y1,5
[Data]
Comment,Time Stamp (sec),Temperature (K),Magnetic Field (Oe),Moment (emu),M. Std. Err. (emu),Transport Action,Averaging Time (sec),Frequency (Hz),Peak Amplitude (mm),Center Position (mm),Coil Signal' (mV),Coil Signal" (mV),Range (mV),M. Quad. Signal (emu),M. Raw' (emu),M. Raw" (emu),Min. Temperature (K),Max. Temperature (K),Min. Field (Oe),Max. Field (Oe),Mass (grams),Motor Lag (deg),Pressure (Torr),VSM Status (code),Motor Status (code),Measure Status (code),Measure Count,PPMS Status (code),System Temp. (K),System Field (Oe),Sample Position (deg),Bridge 1 Resistance (ohms),Bridge 1 Excitation (에),Bridge 2 Resistance (ohms),Bridge 2 Excitation (에),Bridge 3 Resistance (ohms),Bridge 3 Excitation (에),Bridge 4 Resistance (ohms),Bridge 4 Excitation (에),Signal 1 Vin (V),Signal 2 Vin (V),Digital Inputs (code),Drive 1 Iout (mA),Drive 1 Ipower (W),Drive 2 Iout (mA),Drive 2 Ipower (W),Pressure (),Map 20 (),Map 21 (),Map 22 (),Map 23 (),Map 24 (),Map 25 (),Map 26 (),Map 27 (),Map 28 (),Map 29 ()
,28143445.78,19.9957886,-0.137013956904411,,,2,,,,27.8299996060133,,,,,,,19.9957886,19.9957886,-0.137013956904411,-0.137013956904411,,,11.519473,,,,-99999999,4369,20.0132,-0.137013956904411,,,,,,,,,,,,,,,,,,,,,,,19.9957886,,,,
,28143595.105,20.0100899,4486.51904296875,0.0128438875052748,1.66458988953278E-6,1,0.999253354069792,40.0298881530762,1.97779131156441,27.8200004249811,0.142844244689112,0.026439346502881,2.5,8.97017088761547E-5,0.0127726880148691,0.000154907009978104,20.0100899,20.0100899,4481.5029296875,4491.53515625,57.0401228193907,20.5680287902853,11.899124,0,0,0,40,4449,19.9957,4486.51904296875,,,,,,,,,,,,,0,,,,0.0049,,,,,,20.0100899,,,,
,28143692.15,20.0025253,9334.50634765625,0.0162059100243017,2.38848341232771E-6,1,0.999253354069792,40.0298881530762,1.97781585460015,27.8099998831749,0.180294508175855,0.0334120675409564,2.5,0.000111059161006993,0.0161217955677326,0.000199067638456787,20.0025253,20.0025253,9331.6875,9337.3251953125,57.1300100991022,20.5690585174477,11.519473,0,0,0,40,4449,19.99,9334.50634765625,,,,,,,,,,,,,0,,,,-0.0098,,,,,,20.0025253,,,,
,28143790.22,20.00329495,14234.9384765625,0.0197045079598938,2.2388975853276E-6,1,0.999253354069792,40.0298881530762,1.97808287767793,27.8099998831749,0.21933146118603,0.0406761977019712,2.5,0.000130636625477229,0.0196103656133802,0.000244722097829985,20.0032883,20.0033016,14229.8232421875,14240.0537109375,57.2910255740638,20.5693352100212,11.899124,0,0,0,40,4449,19.98765,14234.9384765625,,,,,,,,,,,,,0,,,,0,,,,,,20.00329495,,,,
,28143892.9,20.0035076,19369.58203125,0.0234478259406192,2.55562488587018E-6,1,0.999253354069792,40.0298881530762,1.97811337016928,27.8200004249811,0.261115730229711,0.0484922661754529,2.5,0.000153089943680145,0.0233469427101206,0.000297139547942348,20.0035076,20.0035076,19361.90625,19377.2578125,57.4387533641984,20.5663226267812,12.278775,0,0,0,40,4449,19.9882,19369.58203125,,,,,,,,,,,,,0,,,,0,,,,,,20.0035076,,,,
,28143995.12,20.0033855,24477.2841796875,0.0271581940509661,2.79109964832857E-6,1,0.999253354069792,40.0298881530762,1.97863693361296,27.8200004249811,0.302655336049612,0.0562610854955674,2.5,0.000173597490488951,0.0270550627151582,0.000349036893842772,20.0033855,20.0033855,24469.640625,24484.927734375,57.3457395704099,20.5596204117165,11.899124,0,0,0,40,4449,19.98635,24477.2841796875,,,,,,,,,,,,,0,,,,0.00245,,,,,,20.0033855,,,,
,28144097.935,20.0038204,29617.5419921875,0.0306933543405242,2.95400249915127E-6,1,0.999253354069792,40.0298881530762,1.97861798735899,27.8200004249811,0.342222417599748,0.0636642709130999,2.5,0.000192096705440137,0.0305930533112048,0.000398828447643045,20.0038204,20.0038204,29612.267578125,29622.81640625,57.2495992625445,20.562335096876,12.278775,0,0,0,40,4449,19.9826,29617.5419921875,,,,,,,,,,,,,0,,,,-0.00245,,,,,,20.0038204,,,,
,28144201.085,20.0025539,34769.78125,0.0340575977348911,3.02104040129381E-6,1,0.999253354069792,40.0298881530762,1.97843914238247,27.8200004249811,0.379894156067017,0.0707455393421062,2.5,0.000211911063662181,0.0339647539955169,0.000449103843247968,20.0025539,20.0025539,34764.625,34774.9375,57.3191642007561,20.5647168061229,11.519473,0,0,0,40,4449,19.9799,34769.78125,,,,,,,,,,,,,0,,,,-0.0049,,,,,,20.0025539,,,,
,28144303.405,20.0034199,39886.892578125,0.0370825454019345,3.14711646527323E-6,1,0.999253354069792,40.0298881530762,1.97865314431664,27.8099998831749,0.413898196487572,0.0771071086257141,2.5,0.000226820949633129,0.0370015253118875,0.000491780386368263,20.0034199,20.0034199,39881.8125,39891.97265625,57.4207759082561,20.5647441495645,12.658426,0,0,0,40,4449,19.9775,39886.892578125,,,,,,,,,,,,,0,,,,0,,,,,,20.0034199,,,,
,28144405.015,20.0018215,44962.568359375,0.0398333327315372,4.25745950220102E-6,1,0.999253354069792,40.0298881530762,1.97911166687518,27.8200004249811,0.444930452059057,0.0829251258189374,2.5,0.000241773219100786,0.0397674809421159,0.000531727349509419,20.0018215,20.0018215,44959.609375,44965.52734375,57.3504293415253,20.5560302743492,11.899124,0,0,0,40,4449,19.9772,44962.568359375,,,,,,,,,,,,,0,,,,-0.00245,,,,,,20.0018215,,,,
,28144506.04,20.0021496,50012.56640625,0.0422879561218059,3.23498797724411E-6,1,0.999253354069792,40.0298881530762,1.9787044102291,27.8200004249811,0.472487344780487,0.0881363986696935,2.5,0.000259605052519025,0.0422399220267129,0.000571291315241755,20.0021496,20.0021496,50007.4375,50017.6953125,57.187068981006,20.560760401467,12.278775,0,0,0,40,4449,19.97605,50012.56640625,,,,,,,,,,,,,0,,,,-0.00245,,,,,,20.0021496,,,,
,28144606.965,20.0008984,55057.392578125,0.0445211543700099,3.45331739895928E-6,1,0.999253354069792,40.0298881530762,1.97899582720932,27.8200004249811,0.497750772256623,0.092897067255696,2.5,0.000275404517124495,0.0444929058800029,0.000605918677732638,20.0008984,20.0008984,55044.921875,55069.86328125,57.2058280654676,20.5565230911253,12.658426,0,0,0,40,4449,19.9745,55057.392578125,,,,,,,,,,,,,0,,,,0,,,,,,20.0008984,,,,
,28144710.05,20.0013218,60209.451171875,0.0465921744682091,3.8942316995674E-6,1,0.999253354069792,40.0298881530762,1.97888953811391,27.8200004249811,0.521136879053232,0.0972512144706302,2.5,0.000286733482013043,0.0465855754573992,0.000633511132426957,20.0013218,20.0013218,60201.7890625,60217.11328125,57.3074397729676,20.5570357554724,12.278775,0,0,0,40,4449,19.9744,60209.451171875,,,,,,,,,,,,,0,,,,0,,,,,,20.0013218,,,,
,28144803.185,20.0012646,64866.09765625,0.0483160299985408,4.74695131609715E-6,1,0.999253354069792,40.0298881530762,1.97931034307997,27.8200004249811,0.540758463743591,0.100911655811462,2.5,0.000297991663353495,0.0483297536093957,0.000657125229546972,20.0012646,20.0012646,64866.09765625,64866.09765625,57.3676251689484,20.5541186895354,12.278775,0,0,0,40,4449,19.9721,64866.09765625,,,,,,,,,,,,,0,,,,0.0049,,,,,,20.0012646,,,,
,28144897.97,20.0019588,69603.31640625,0.0499440905303546,4.27903585408634E-6,1,0.999253354069792,40.0298881530762,1.97944850297774,27.8200004249811,0.559239753827011,0.104406109451454,2.5,0.000313892170389235,0.0499788490298098,0.000683489329916666,20.0019588,20.0019588,69598.4453125,69608.1875,57.444224763833,20.5498940809764,12.278775,0,0,0,40,4449,19.9716,69603.31640625,,,,,,,,,,,,,0,,,,0,,,,,,20.0019588,,,,
,28144992.275,20.0024376,74315.6640625,0.0514569290020909,2.28916943013585E-6,1,0.999253354069792,40.0298881530762,1.97899440708085,27.8200004249811,0.576268750519443,0.107633339791277,2.5,0.000330508683969652,0.0515127279632452,0.000708616128877607,20.0024376,20.0024376,74311,74320.328125,57.3113479155637,20.5592440931738,11.899124,0,0,0,40,4449,19.9698,74315.6640625,,,,,,,,,,,,,0,,,,0.0049,,,,,,20.0024376,,,,
,28145085.235,20.0022945,78964.37109375,0.0528434480405685,3.19281806376195E-6,1,0.999253354069792,40.0298881530762,1.97932772630522,27.8200004249811,0.5921085141423,0.110578279872299,2.5,0.000342089184662417,0.0529199265570242,0.000726803114537277,20.0022945,20.0022945,78959.265625,78969.4765625,57.3910740245253,20.5513521205113,12.278775,0,0,0,40,4449,19.9689,78964.37109375,,,,,,,,,,,,,0,,,,-0.0049,,,,,,20.0022945,,,,
,28145177.975,20.00221535,83600.32421875,0.0541373675087212,3.98107163357367E-6,1,0.999253354069792,40.0298881530762,1.97935958004802,27.8200004249811,0.606818274561772,0.113350882957633,2.5,0.000357299033328607,0.0542341641688544,0.000747055976059761,20.0020065,20.0024242,83592.8125,83607.8359375,57.2808644033138,20.5554822183084,12.658426,0,0,0,40,4449,19.9669,83600.32421875,,,,,,,,,,,,,0,,,,-0.0049,,,,,,20.00221535,,,,
,28145264.08,20.0013142,87901.296875,0.0552828429918663,4.41071957060451E-6,1,0.999253354069792,40.0298881530762,1.97946489532902,27.8200004249811,0.619881046199441,0.115748952113268,2.5,0.000366160183219953,0.0553982006133232,0.000759462743457757,20.0013142,20.0013142,87866.421875,87936.171875,57.4067065949099,20.5471883156421,12.658426,0,0,0,40,4449,19.96565,87901.296875,,,,,,,,,,,,,0,,,,0.00245,,,,,,20.0013142,,,,
,28145371.61,20.0012836,87690.90625,0.0553779432185739,2.01371728971514E-6,1,0.999253354069792,40.0298881530762,1.97977340391787,27.8200004249811,0.621026769477258,0.115987626544246,2.5,0.000368670101279269,0.0554926982787618,0.000762894477525669,20.0012836,20.0012836,87683.4609375,87698.3515625,57.3988903097176,20.5438491391112,12.278775,0,0,0,40,4449,19.9653,87690.90625,,,,,,,,,,,,,0,,,,0,,,,,,20.0012836,,,,
,28145459.04,20.00025845,83319.95703125,0.0544091106519745,3.00689607177167E-6,1,0.999253354069792,40.0298881530762,1.97947152098454,27.8200004249811,0.609885467767613,0.113920899617736,2.5,0.000358541102878452,0.0545053043425295,0.000750538536029924,20.000164,20.0003529,83315.0390625,83324.875,57.2378748347561,20.5509045897621,13.038077,0,0,0,40,4449,19.965,83319.95703125,,,,,,,,,,,,,0,,,,0,,,,,,20.00025845,,,,
,28145552.085,19.999752,78668.16015625,0.0533142619042812,9.61847297143362E-7,1,0.999253354069792,40.0298881530762,1.97988153202022,27.8200004249811,0.597532411574866,0.111578794780292,2.5,0.000343796836434024,0.0533902299808712,0.000732190032790759,19.999752,19.999752,78665.78125,78670.5390625,57.3574639981984,20.5433119859435,12.658426,0,0,0,40,4449,19.9655,78668.16015625,,,,,,,,,,,,,0,,,,0.00245,,,,,,19.999752,,,,
,28145644.08,19.9991798,74067.3828125,0.0521679719431482,4.32416329541895E-6,1,0.999253354069792,40.0298881530762,1.98002156098945,27.8200004249811,0.584516636640931,0.109134858313099,2.5,0.000331531907881891,0.0522235246445329,0.000715027054156035,19.9991798,19.9991798,74062.3203125,74072.4453125,57.3246356003907,20.5429575955647,13.038077,0,0,0,40,4449,19.96635,74067.3828125,,,,,,,,,,,,,0,,,,0,,,,,,19.9991798,,,,
,28145735.94,19.998251,69476.61328125,0.0509547912177943,4.77297681062465E-6,1,0.999253354069792,40.0298881530762,1.98036892505183,27.8200004249811,0.570804345617922,0.106564563309789,2.5,0.000320128585279257,0.0509897049196123,0.000697263831075405,19.998251,19.998251,69474.1796875,69479.046875,57.2902439455445,20.5349910647577,12.658426,0,0,0,40,4449,19.9686,69476.61328125,,,,,,,,,,,,,0,,,,-0.0049,,,,,,19.998251,,,,
,28145829.285,19.9988861,64810.90625,0.0496513135090591,3.15542933656734E-6,1,0.999253354069792,40.0298881530762,1.98037509784444,27.8200004249811,0.555975514759953,0.103811437300704,2.5,0.000311398456816252,0.049665132429518,0.000680471526402732,19.9988861,19.9988861,64800.9453125,64820.8671875,57.1651833824676,20.5408354295563,12.278775,0,0,0,40,4449,19.9697,64810.90625,,,,,,,,,,,,,0,,,,-0.00245,,,,,,19.9988861,,,,
,28145923.305,19.99823,60112.609375,0.0482451488235785,3.97450494246793E-6,1,0.999253354069792,40.0298881530762,1.98044633850777,27.8200004249811,0.540022733183288,0.100795782153106,2.5,0.000298647729748787,0.0482378650207705,0.000657725316769348,19.99823,19.99823,60107.7734375,60117.4453125,57.2996234877753,20.5387281004473,12.278775,0,0,0,40,4449,19.97175,60112.609375,,,,,,,,,,,,,0,,,,-0.0049,,,,,,19.99823,,,,
,28146015.895,19.9989433,55482.203125,0.0467601873457401,2.96607104619887E-6,1,0.999253354069792,40.0298881530762,1.98060191987091,27.8200004249811,0.523225798687975,0.0975635997226431,2.5,0.000281550143959405,0.0467325117606161,0.0006288244079811,19.9989433,19.9989433,55469.6953125,55494.7109375,57.3699700545061,20.5341584489495,12.278775,0,0,0,40,4449,19.973,55482.203125,,,,,,,,,,,,,0,,,,0,,,,,,19.9989433,,,,
,28146109.03,19.9997215,50827.033203125,0.0451665307383133,3.40836512392952E-6,1,0.999253354069792,40.0298881530762,1.98038308271359,27.8200004249811,0.505113627148286,0.0941476054280482,2.5,0.000270361941176274,0.0451189877776016,0.000603771955535259,19.9997215,19.9997215,50821.8203125,50832.24609375,57.3770047111791,20.5383162117174,12.658426,0,0,0,40,4449,19.97295,50827.033203125,,,,,,,,,,,,,0,,,,-0.0049,,,,,,19.9997215,,,,
,28146202.015,19.9999409,46179.345703125,0.0434508056608876,4.24636423082267E-6,1,0.999253354069792,40.0298881530762,1.98060525146542,27.8200004249811,0.485753271979694,0.0905046423566579,2.5,0.000260181336103687,0.0433844708287151,0.000577590675071743,19.9999409,19.9999409,46174.25,46184.44140625,57.4051433378714,20.5391932500242,12.658426,0,0,0,40,4449,19.974,46179.345703125,,,,,,,,,,,,,0,,,,-0.00245,,,,,,19.9999409,,,,
,28146295.18,19.9985619,41523.908203125,0.0415714379723846,1.9360078210158E-6,1,0.999253354069792,40.0298881530762,1.98070320511348,27.8200004249811,0.464542263283036,0.086533392509004,2.5,0.000251644189734646,0.0414877870395823,0.000550677347897803,19.9985619,19.9985619,41521.2578125,41526.55859375,57.3004051162945,20.5343222192405,12.658426,0,0,0,40,4449,19.97415,41523.908203125,,,,,,,,,,,,,0,,,,0.0049,,,,,,19.9985619,,,,
,28146387.965,19.9980984,36886.37109375,0.0395741493386677,3.46431198252201E-6,1,0.999253354069792,40.0298881530762,1.98038850103693,27.8200004249811,0.441951089410134,0.0822569783664899,2.5,0.000239268718146614,0.0394751670440498,0.000518074370112776,19.9980984,19.9980984,36878.7890625,36893.953125,57.2972786022176,20.5349299158189,13.038077,0,0,0,40,4449,19.9751,36886.37109375,,,,,,,,,,,,,0,,,,0.0049,,,,,,19.9980984,,,,
,28146479.695,19.9987125,32301.53515625,0.0373962089394257,3.22633173316598E-6,1,0.999253354069792,40.0298881530762,1.98057054878365,27.8200004249811,0.41747311881901,0.0776375400808871,2.5,0.000227259704538606,0.0372845656453927,0.000483838882351328,19.9987125,19.9987125,32291.740234375,32311.330078125,57.2886806885061,20.5369068072292,12.658426,0,0,0,40,4449,19.97635,32301.53515625,,,,,,,,,,,,,0,,,,0,,,,,,19.9987125,,,,
,28146573.415,19.9991016,27618.873046875,0.0349614357194146,2.86139349809347E-6,1,0.999253354069792,40.0298881530762,1.98037676824813,27.8200004249811,0.390071824233031,0.0724972626154299,2.5,0.000216340786762343,0.0348399464518721,0.0004482767302014,19.9991016,19.9991016,27613.810546875,27623.935546875,57.3652802833907,20.5397750085698,12.278775,0,0,0,40,4449,19.9769,27618.873046875,,,,,,,,,,,,,0,,,,-0.00245,,,,,,19.9991016,,,,
,28146664.5,19.9987125,23066.044921875,0.0323668056378643,3.19415814998778E-6,1,0.999253354069792,40.0298881530762,1.97999179712747,27.8200004249811,0.360900551506932,0.0670005640377972,2.5,0.000201927098821473,0.032239330802455,0.000408334708865878,19.9987125,19.9987125,23055.97265625,23076.1171875,57.3011867448138,20.546527722131,13.038077,0,0,0,40,4449,19.9782,23066.044921875,,,,,,,,,,,,,0,,,,0.00245,,,,,,19.9987125,,,,
,28146754.98,19.998209,18543.8076171875,0.0295450978903686,1.90912041661494E-6,1,0.999253354069792,40.0298881530762,1.97975241683207,27.8200004249811,0.329259965852008,0.0610865776933898,2.5,0.000189213333212684,0.0294156710224326,0.000369118791885034,19.998209,19.998209,18539.005859375,18548.609375,57.4575124486599,20.5491685988987,12.658426,0,0,0,40,4449,19.9791,18543.8076171875,,,,,,,,,,,,,0,,,,0,,,,,,19.998209,,,,
,28146848.095,19.9986782,13890.9565429688,0.0262859602625098,2.89449043500598E-6,1,0.999253354069792,40.0298881530762,1.98029876330994,27.8200004249811,0.292897755188487,0.0542976227131505,2.5,0.000173019417278771,0.0261595797294196,0.000324565187868969,19.9986782,19.9986782,13885.796875,13896.1162109375,57.3316702570638,20.5375064758259,12.278775,0,0,0,40,4449,19.9798,13890.9565429688,,,,,,,,,,,,,0,,,,0.00245,,,,,,19.9986782,,,,
,28146941.055,19.9986649,9243.46630859375,0.0227184211115396,2.35059489430664E-6,1,0.999253354069792,40.0298881530762,1.98051378853476,27.8200004249811,0.253079551197155,0.046875766950158,2.5,0.000153693698217223,0.0226003491168238,0.000276923312005651,19.9986649,19.9986649,9238.416015625,9248.5166015625,57.4754899046022,20.5347746395206,12.658426,0,0,0,40,4449,19.9818,9243.46630859375,,,,,,,,,,,,,0,,,,-0.0049,,,,,,19.9986649,,,,
,28147032.68,19.998991,4665.47338867188,0.0188507492535308,2.41736460312934E-6,1,0.999253354069792,40.0298881530762,1.98089700238614,27.8200004249811,0.209967414922167,0.0388610573784327,2.5,0.000131226211179903,0.0187464715116995,0.000227161849304422,19.998991,19.998991,4655.55859375,4675.38818359375,57.5755383550638,20.5219761773118,13.038077,0,0,0,40,4449,19.98235,4665.47338867188,,,,,,,,,,,,,0,,,,0,,,,,,19.998991,,,,
,28147125.04,20.0005989,46.4474544525146,0.0143610632201041,2.7857392564639E-6,1,0.999253354069792,40.0298881530762,1.98026125739567,27.8200004249811,0.159875249189415,0.0295577243307456,2.5,0.000101211514561717,0.0142780018721794,0.000170233328047924,20.0005989,20.0005989,41.6004066467285,51.2945022583008,57.4489145349484,20.5383163321043,12.278775,0,0,0,40,4449,19.982,46.4474544525146,,,,,,,,,,,,,0,,,,0,,,,,,20.0005989,,,,
,28147216.71,19.9992752,-4532.53076171875,0.00879067641310012,2.77892301258518E-6,1,0.999253354069792,40.0298881530762,1.98062190942782,27.8200004249811,0.0979019043681887,0.0181106095456827,2.5,6.04769724368816E-5,0.00874197523723533,0.000105136353708911,19.9992752,19.9992752,-4542.552734375,-4522.5087890625,57.3566823696791,20.5275510511379,12.658426,0,0,0,40,4449,19.98285,-4532.53076171875,,,,,,,,,,,,,0,,,,0.0049,,,,,,19.9992752,,,,
,28147310,19.9985504,-9196.42333984375,0.00325436837231154,2.83071663181092E-6,1,0.999253354069792,40.0298881530762,1.98080045954343,27.8200004249811,0.0362512724268417,0.00672632819573384,0.25,2.30528804932263E-5,0.00323743716752288,4.06886657609178E-5,19.9985504,19.9985504,-9201.5185546875,-9191.328125,57.1878506095253,20.5291409033672,12.658426,0,0,0,40,4449,19.98295,-9196.42333984375,,,,,,,,,,,,,0,,,,0,,,,,,19.9985504,,,,
,28147401.2,20.0007706,-13754.6215820312,-0.00257075719838256,3.07758621012232E-6,1,0.999253354069792,40.0298881530762,1.98049892183085,27.8200004249811,-0.0286417186869324,-0.00532278721080131,0.25,-1.80881622836799E-5,-0.00255835977986185,-3.28786056397381E-5,20.0007706,20.0007706,-13759.37890625,-13749.8642578125,57.4840878183138,20.5327316459248,12.278775,0,0,0,40,4449,19.982,-13754.6215820312,,,,,,,,,,,,,0,,,,0,,,,,,20.0007706,,,,
,28147495.36,20.0015011,-18459.3046875,-0.0090333954417537,3.30478720995643E-6,1,0.999253354069792,40.0298881530762,1.98044213677495,27.8200004249811,-0.100682454574028,-0.018726672468749,0.25,-6.20103414258783E-5,-0.00899372573264881,-0.0001169475665458,20.0015011,20.0015011,-18461.666015625,-18456.943359375,57.3441763133715,20.5370076907335,12.278775,0,0,0,40,4449,19.98165,-18459.3046875,,,,,,,,,,,,,0,,,,0,,,,,,20.0015011,,,,
,28147592.065,20.0014572,-23291.396484375,-0.0156497533625639,3.05517839119172E-6,1,0.999253354069792,40.0298881530762,1.98058592417623,27.8200004249811,-0.174548998715127,-0.0324329910815491,2.5,-9.98767906079838E-5,-0.0155884559189593,-0.000199880199850447,20.0014572,20.0014572,-23298.693359375,-23284.099609375,57.3363600281791,20.5351842859586,12.278775,0,0,0,40,4449,19.9784,-23291.396484375,,,,,,,,,,,,,0,,,,0,,,,,,20.0014572,,,,
,28147685.32,20.0014935,-27954.2421875,-0.0217893392135865,2.93369868820327E-6,1,0.999253354069792,40.0298881530762,1.98076581833373,27.8200004249811,-0.243160231316839,-0.0452041954677461,2.5,-0.00013544234769393,-0.0217143746809489,-0.000280374213520096,20.0014935,20.0014935,-27961.740234375,-27946.744140625,57.2652318329291,20.528982226357,12.658426,0,0,0,40,4449,19.97975,-27954.2421875,,,,,,,,,,,,,0,,,,0.0049,,,,,,20.0014935,,,,
,28147778.7,20.0016594,-32619.1396484375,-0.027214423137179,2.55732315690079E-6,1,0.999253354069792,40.0298881530762,1.98104801204894,27.8200004249811,-0.303884006726244,-0.056540919130071,2.5,-0.000167400951838335,-0.0271340725034595,-0.000354496005526715,20.0016594,20.0016594,-32623.916015625,-32614.36328125,57.4403166212368,20.5239270195879,12.658426,0,0,0,40,4449,19.97685,-32619.1396484375,,,,,,,,,,,,,0,,,,0.0049,,,,,,20.0016594,,,,
,28147869.77,20.0017796,-37170.904296875,-0.0317794123376469,2.37983662319579E-6,1,0.999253354069792,40.0298881530762,1.98091768933856,27.8200004249811,-0.354998851364584,-0.0660991738340348,2.5,-0.00019407471510374,-0.0317008682430774,-0.000418284173334001,20.0017796,20.0017796,-37181.046875,-37160.76171875,57.403580080833,20.5218534481956,12.658426,0,0,0,40,4449,19.9759,-37170.904296875,,,,,,,,,,,,,0,,,,-0.00245,,,,,,20.0017796,,,,
,28147961.84,20.0021667,-41773.51171875,-0.0356807006482532,2.29988679214989E-6,1,0.999253354069792,40.0298881530762,1.98109524395659,27.8200004249811,-0.39879671924023,-0.0743156339025483,2.5,-0.000218267773563549,-0.0356098211811068,-0.000475169689429972,20.0021667,20.0021667,-41778.671875,-41768.3515625,57.4199942797368,20.5203675205154,12.278775,0,0,0,40,4449,19.97445,-41773.51171875,,,,,,,,,,,,,0,,,,0,,,,,,20.0021667,,,,
,28148055.825,20.0010643,-46471.51171875,-0.0390379691060193,1.90273437906566E-6,1,0.999253354069792,40.0298881530762,1.98091922963864,27.8200004249811,-0.436491278577162,-0.0813749218451215,2.5,-0.000237753666000776,-0.0389795179321163,-0.000523148412218289,20.0010643,20.0010643,-46476.140625,-46466.8828125,57.6451032932753,20.5219232900991,12.658426,0,0,0,40,4449,19.973,-46471.51171875,,,,,,,,,,,,,0,,,,0,,,,,,20.0010643,,,,
,28148147.775,20.0001316,-51066.337890625,-0.041833453377246,4.1682268274583E-6,1,0.999253354069792,40.0298881530762,1.98082894387324,27.8200004249811,-0.467935131181659,-0.087306305181238,2.5,-0.000257929993032785,-0.0417903697967565,-0.000566856684589169,20.0001316,20.0001316,-51073.7421875,-51058.93359375,57.2886806885061,20.5225989339107,12.658426,0,0,0,40,4449,19.9729,-51066.337890625,,,,,,,,,,,,,0,,,,0,,,,,,20.0001316,,,,
,28148240.55,20.0004139,-55701.001953125,-0.0442712734084814,3.86439894352018E-6,1,0.999253354069792,40.0298881530762,1.98066247229278,27.8200004249811,-0.495391470706705,-0.0924279278763298,2.5,-0.000271220184631256,-0.0442459778336881,-0.000600068525665008,20.0004139,20.0004139,-55706.03515625,-55695.96875,57.5513078709676,20.5290227896167,12.658426,0,0,0,40,4449,19.97245,-55701.001953125,,,,,,,,,,,,,0,,,,0,,,,,,20.0004139,,,,
,28148333.805,20.0011005,-60363.197265625,-0.0464232204271949,4.28889075046456E-6,1,0.999253354069792,40.0298881530762,1.98101093837422,27.8200004249811,-0.519783260750398,-0.0970168012647579,2.5,-0.000287269727551447,-0.0464172992317852,-0.000632792801414392,20.0011005,20.0011005,-60373.2109375,-60353.18359375,57.3605905122753,20.5212691203813,13.038077,0,0,0,40,4449,19.9719,-60363.197265625,,,,,,,,,,,,,0,,,,0.0049,,,,,,20.0011005,,,,
,28148428.06,20.0009842,-65075.8984375,-0.048332451667695,2.91984644369448E-6,1,0.999253354069792,40.0298881530762,1.98103020398501,27.8200004249811,-0.541394678285038,-0.101069420029497,2.5,-0.000301521109189337,-0.0483470586450616,-0.000660730037477674,20.0009842,20.0009842,-65080.6484375,-65071.1484375,57.2441278629099,20.5220692632463,12.658426,0,0,0,40,4449,19.9702,-65075.8984375,,,,,,,,,,,,,0,,,,0.0049,,,,,,20.0009842,,,,
,28148522.1,20.0011597,-69773.2109375,-0.0500510766177192,2.5348465243828E-6,1,0.999253354069792,40.0298881530762,1.98113736265752,27.8200004249811,-0.560898436723366,-0.104739879329527,2.5,-0.000316731147626,-0.0500866136213362,-0.00068704349974305,20.0011597,20.0011597,-69778.265625,-69768.15625,57.738898715583,20.5174157793332,13.038077,0,0,0,40,4449,19.96825,-69773.2109375,,,,,,,,,,,,,0,,,,0.0049,,,,,,20.0011597,,,,
,28148616.345,20.0017338,-74483.02734375,-0.051625654972511,3.16360470493273E-6,1,0.999253354069792,40.0298881530762,1.98114210738592,27.8200004249811,-0.578765913812984,-0.108097847315988,2.5,-0.000331550057960322,-0.0516823300746018,-0.000710784930615855,20.0017338,20.0017338,-74490.3984375,-74475.65625,57.3590272552368,20.5179791737135,12.658426,0,0,0,40,4449,19.96685,-74483.02734375,,,,,,,,,,,,,0,,,,-0.00245,,,,,,20.0017338,,,,
,28148711.235,20.00173665,-79224.9140625,-0.053059250900691,3.60083066822288E-6,1,0.999253354069792,40.0298881530762,1.98111722680792,27.8200004249811,-0.595046269510185,-0.111158953986261,2.5,-0.000346484702211385,-0.0531370663922727,-0.000732550383548455,20.0015545,20.0019188,-79232.3671875,-79217.4609375,57.5513078709676,20.5138035110325,12.278775,0,0,0,40,4449,19.9651,-79224.9140625,,,,,,,,,,,,,0,,,,0,,,,,,20.00173665,,,,
,28148804.97,20.00176145,-83909.6484375,-0.0543801979572111,3.39155450258762E-6,1,0.999253354069792,40.0298881530762,1.98125088702234,27.8200004249811,-0.610109347802989,-0.113969492016038,2.5,-0.000359565731725708,-0.0544786231946635,-0.000750755699719441,20.0016365,20.0018864,-83919.421875,-83899.875,57.5380201861407,20.5145031866616,12.278775,0,0,0,40,4449,19.96315,-83909.6484375,,,,,,,,,,,,,0,,,,0,,,,,,20.00176145,,,,
,28148892.955,20.0013676,-88306.9453125,-0.0555409631329638,3.89890178747587E-6,1,0.999253354069792,40.0298881530762,1.9808040615762,27.8200004249811,-0.623188304525046,-0.116403972286894,2.5,-0.000371585081186295,-0.0556583486979774,-0.000766262945015596,20.0013676,20.0013676,-88312.0546875,-88301.8359375,57.4262473078907,20.5211581360001,12.658426,0,0,0,40,4449,19.9623,-88306.9453125,,,,,,,,,,,,,0,,,,0,,,,,,20.0013676,,,,
,28148997.215,20.0016003,-87428.38671875,-0.0554750941811808,3.22219045116766E-6,1,0.999253354069792,40.0298881530762,1.98075147971827,27.8200004249811,-0.622394873846906,-0.116266105986737,2.5,-0.000370981313889518,-0.0555890498926834,-0.000766201166677243,20.0016003,20.0016003,-87438.3515625,-87418.421875,57.454385934583,20.5255143774152,12.658426,0,0,0,40,4449,19.96105,-87428.38671875,,,,,,,,,,,,,0,,,,0,,,,,,20.0016003,,,,
,28149088.165,20.000391,-82883.90625,-0.0544841354346944,1.81212456892494E-6,1,0.999253354069792,40.0298881530762,1.98051544351435,27.8200004249811,-0.611007987895949,-0.114171249177289,2.5,-0.000362077844644038,-0.0545787289113911,-0.000755060901257777,20.000391,20.000391,-82886.3515625,-82881.4609375,57.4840878183138,20.5260915753056,12.658426,0,0,0,40,4449,19.9613,-82883.90625,,,,,,,,,,,,,0,,,,0,,,,,,20.000391,,,,
,28149182.255,20.0005531,-78181.09765625,-0.0533707866277254,3.35757958476069E-6,1,0.999253354069792,40.0298881530762,1.98043226710724,27.8200004249811,-0.598293815521549,-0.111771902347537,2.5,-0.000348113972096141,-0.0534448182896571,-0.000737335516899787,20.0004253,20.0006809,-78188.5,-78173.6953125,57.5302039009484,20.5260479334032,12.658426,0,0,0,40,4449,19.9616,-78181.09765625,,,,,,,,,,,,,0,,,,0.00245,,,,,,20.0005531,,,,
,28149277.865,19.9997749,-73401.69921875,-0.0521934194240469,3.01332958069008E-6,1,0.999253354069792,40.0298881530762,1.98087103487489,27.8200004249811,-0.584999856634481,-0.109283350278353,2.5,-0.00033624401389525,-0.052246151599108,-0.000720366497640178,19.9997749,19.9997749,-73406.5546875,-73396.84375,57.4426615067945,20.5217400478223,13.038077,0,0,0,40,4449,19.9619,-73401.69921875,,,,,,,,,,,,,0,,,,0,,,,,,19.9997749,,,,
,28149371.725,19.998827,-68712.3359375,-0.0509594962719439,4.51294382693364E-6,1,0.999253354069792,40.0298881530762,1.98130576367944,27.8200004249811,-0.571078207844871,-0.106613529322254,2.5,-0.000319588162027327,-0.0509910894177838,-0.000697096199638246,19.998827,19.998827,-68719.7578125,-68704.9140625,57.5380201861407,20.51252729479,12.658426,0,0,0,40,4449,19.96345,-68712.3359375,,,,,,,,,,,,,0,,,,0.00245,,,,,,19.998827,,,,
,28149466.32,19.9973984,-63984.994140625,-0.0496297116354658,3.23095962961732E-6,1,0.999253354069792,40.0298881530762,1.98156901625503,27.8200004249811,-0.556005762782612,-0.103855819295004,2.5,-0.000314384539606256,-0.0496398201118306,-0.000683466956445262,19.9973984,19.9973984,-63992.31640625,-63977.671875,57.4700185049676,20.5099923088916,12.658426,0,0,0,40,4449,19.9659,-63984.994140625,,,,,,,,,,,,,0,,,,0,,,,,,19.9973984,,,,
,28149558.64,19.9983463,-59372.107421875,-0.0482612742391876,3.83582280103616E-6,1,0.999253354069792,40.0298881530762,1.98152984652437,27.8200004249811,-0.540446116766016,-0.100885611444694,2.5,-0.000299672653779662,-0.0482506238019948,-0.000658831581319064,19.9983463,19.9983463,-59379.421875,-59364.79296875,57.4590757056984,20.5089420707425,12.658426,0,0,0,40,4449,19.9678,-59372.107421875,,,,,,,,,,,,,0,,,,0,,,,,,19.9983463,,,,
,28149652.635,19.9986763,-54674.603515625,-0.0467552351752412,3.58806648094644E-6,1,0.999253354069792,40.0298881530762,1.98148087641981,27.8200004249811,-0.523335700262157,-0.097671083695099,2.5,-0.000289245406852295,-0.0467238157313917,-0.000636214212217982,19.9986763,19.9986763,-54682.28125,-54666.92578125,57.3676251689484,20.5121418187534,13.038077,0,0,0,40,4449,19.9686,-54674.603515625,,,,,,,,,,,,,0,,,,0.0049,,,,,,19.9986763,,,,
,28149744.335,19.9991856,-50090.033203125,-0.0451858397301165,3.69252581822397E-6,1,0.999253354069792,40.0298881530762,1.98124222091763,27.8200004249811,-0.505491144925291,-0.0942765080446836,2.5,-0.000275940752634257,-0.0451348753683322,-0.00060903664174998,19.9991856,19.9991856,-50094.8984375,-50085.16796875,57.4801796757176,20.5126626825241,13.038077,0,0,0,40,4449,19.9695,-50090.033203125,,,,,,,,,,,,,0,,,,-0.00245,,,,,,19.9991856,,,,
,28149839.24,19.9991493,-45350.56640625,-0.0434276255421192,2.05571456838609E-6,1,0.999253354069792,40.0298881530762,1.98105432799949,27.8200004249811,-0.485552187854803,-0.0904978158255415,2.5,-0.000263392602157851,-0.0433575759777422,-0.000579877196155502,19.9991493,19.9991493,-45358.05078125,-45343.08203125,57.098744958333,20.5169892439078,12.658426,0,0,0,40,4449,19.96895,-45350.56640625,,,,,,,,,,,,,0,,,,-0.00245,,,,,,19.9991493,,,,
,28149932.765,20.0000782,-40672.62890625,-0.0415393018079382,2.800979844609E-6,1,0.999253354069792,40.0298881530762,1.98064839897825,27.8200004249811,-0.464129456112275,-0.0864547541874874,2.5,-0.000252264974373453,-0.0414519895455704,-0.000550051812347996,20.0000782,20.0000782,-40680.2265625,-40665.03125,57.3942005386022,20.5203029657619,13.038077,0,0,0,40,4449,19.9693,-40672.62890625,,,,,,,,,,,,,0,,,,-0.00245,,,,,,20.0000782,,,,
,28150026.06,19.99924185,-36010.1171875,-0.0395012207194159,2.90915804431575E-6,1,0.999253354069792,40.0298881530762,1.98095258577075,27.8200004249811,-0.441212125970004,-0.0821393381165048,2.5,-0.000241779499832542,-0.0393987375258243,-0.000518788865401033,19.9991608,19.9993229,-36017.5390625,-36002.6953125,57.1503324406022,20.5201337170619,13.038077,0,0,0,40,4449,19.97025,-36010.1171875,,,,,,,,,,,,,0,,,,0,,,,,,19.99924185,,,,
,28150117.985,19.9985046,-31415.9599609375,-0.0373046935926038,2.87459668868213E-6,1,0.999253354069792,40.0298881530762,1.98035901793681,27.8200004249811,-0.416361246725353,-0.0774809472680424,2.5,-0.000232497729606628,-0.0371898087897314,-0.000486942359710329,19.9985046,19.9985046,-31421.015625,-31410.904296875,57.2292769210445,20.531039828989,12.658426,0,0,0,40,4449,19.9715,-31415.9599609375,,,,,,,,,,,,,0,,,,-0.0049,,,,,,19.9985046,,,,
,28150210.105,19.9991608,-26810.732421875,-0.0348828382361121,2.2116971712341E-6,1,0.999253354069792,40.0298881530762,1.98039252829876,27.8200004249811,-0.38916274498703,-0.0723423742674299,2.5,-0.000218543373137032,-0.034758696281127,-0.000448446193977009,19.9991608,19.9991608,-26813.197265625,-26808.267578125,57.4207759082561,20.5307964390256,13.038077,0,0,0,40,4449,19.9724,-26810.732421875,,,,,,,,,,,,,0,,,,0.0049,,,,,,19.9991608,,,,
,28150302.07,19.998188,-22218.20703125,-0.0322148539442403,1.77868938325891E-6,1,0.999253354069792,40.0298881530762,1.98044988459714,27.8200004249811,-0.359241230832515,-0.0667723155069221,2.5,-0.000209530840268736,-0.0320852025881817,-0.000413273323540247,19.998188,19.998188,-22220.62109375,-22215.79296875,57.606803495833,20.531392153827,13.417728,0,0,0,40,4449,19.9737,-22218.20703125,,,,,,,,,,,,,0,,,,-0.0049,,,,,,19.998188,,,,
,28150393.595,19.9985218,-17643.4638671875,-0.0292548555007845,1.77990981945711E-6,1,0.999253354069792,40.0298881530762,1.98046338207136,27.8200004249811,-0.326106827183771,-0.0605159729339737,2.5,-0.000190352866335644,-0.0291241949843912,-0.000366703581011488,19.9985218,19.9985218,-17653.53125,-17633.396484375,57.0573186468137,20.5305664547632,12.658426,0,0,0,40,4449,19.97515,-17643.4638671875,,,,,,,,,,,,,0,,,,0,,,,,,19.9985218,,,,
,28150486.57,19.9979477,-12995.7734375,-0.0259255160453947,1.4420407184237E-6,1,0.999253354069792,40.0298881530762,1.98035985440489,27.8200004249811,-0.288868498158292,-0.0535429519644879,2.5,-0.000171635123237667,-0.0257988388502915,-0.000319422429078288,19.9979477,19.9979477,-13005.7470703125,-12985.7998046875,57.3543374841214,20.535676804825,12.658426,0,0,0,40,4449,19.9772,-12995.7734375,,,,,,,,,,,,,0,,,,0.00245,,,,,,19.9979477,,,,
,28150579.03,19.9980392,-8374.8427734375,-0.0222485359278851,2.80042018751429E-6,1,0.999253354069792,40.0298881530762,1.98029330153113,27.8200004249811,-0.247799789900944,-0.0459096505655338,2.5,-0.000152958936229234,-0.0221313897516011,-0.000272196950321679,19.9980392,19.9980392,-8377.2607421875,-8372.4248046875,57.2019199228714,20.5301718853694,12.658426,0,0,0,40,4449,19.9789,-8374.8427734375,,,,,,,,,,,,,0,,,,0,,,,,,19.9980392,,,,
,28150671.075,19.999506,-3771.50415039063,-0.0180760293785456,2.16145959940391E-6,1,0.999253354069792,40.0298881530762,1.98045663661927,27.8200004249811,-0.201284544618782,-0.0372493710738303,2.5,-0.000126549932847069,-0.0179749894352825,-0.00021741190366883,19.999506,19.999506,-3774.22607421875,-3768.7822265625,57.4106147375061,20.5344603888957,13.417728,0,0,0,40,4449,19.9801,-3771.50415039063,,,,,,,,,,,,,0,,,,0.00245,,,,,,19.999506,,,,
,28150762.965,19.9999657,821.137878417969,-0.013303497766805,2.55134896387393E-6,1,0.999253354069792,40.0298881530762,1.98082717854914,27.8200004249811,-0.148142390297187,-0.0274139640690996,2.5,-9.55004077843246E-5,-0.0132269415973426,-0.000159895768839269,19.9999657,19.9999657,818.401245117187,823.87451171875,57.4481329064291,20.5282844755437,13.038077,0,0,0,40,4449,19.9788,821.137878417969,,,,,,,,,,,,,0,,,,0.00245,,,,,,19.9999657,,,,
,28150853.555,19.9994221,5344.00439453125,-0.0075405334704039,2.67295115699497E-6,1,0.999253354069792,40.0298881530762,1.98102418925347,27.8200004249811,-0.083997232082464,-0.0155542354491281,2.5,-5.28174222002641E-5,-0.00749916329040916,-9.15548078495716E-5,19.9994221,19.9994221,5334.01806640625,5353.99072265625,57.2011382943522,20.5235222909231,13.038077,0,0,0,40,4449,19.98,5344.00439453125,,,,,,,,,,,,,0,,,,0.00245,,,,,,19.9994221,,,,
,28150948.315,19.9994698,10079.4272460938,-0.00165499028608153,2.99200722341678E-6,1,0.999253354069792,40.0298881530762,1.98091087386746,27.8200004249811,-0.0184358178241536,-0.00343142465770447,0.25,-1.25454626705976E-5,-0.00164649170917241,-2.1617872155242E-5,19.9994698,19.9994698,10071.6455078125,10087.208984375,57.4090514804676,20.5215038489395,12.658426,0,0,0,40,4449,19.98075,10079.4272460938,,,,,,,,,,,,,0,,,,0,,,,,,19.9994698,,,,
,28151039.07,20.0009365,14617.646484375,0.00440329781753884,3.2016287360664E-6,1,0.999253354069792,40.0298881530762,1.98041986031928,27.8200004249811,0.0490618845726464,0.0091103037288593,0.25,3.00735432863179E-5,0.00438240409147698,5.5683359539432E-5,20.0008888,20.0009842,14614.994140625,14620.298828125,57.4051433378714,20.5278137513476,12.658426,0,0,0,40,4449,19.97955,14617.646484375,,,,,,,,,,,,,0,,,,0,,,,,,20.0009365,,,,
,28151134.815,20.0007458,19402.318359375,0.0110924250004486,3.46387303118505E-6,1,0.999253354069792,40.0298881530762,1.98086219648284,27.8200004249811,0.123691245152636,0.022963629229313,2.5,7.17677929630465E-5,0.0110447372746863,0.000139938299776515,20.0007458,20.0007458,19397.67578125,19406.9609375,57.4387533641984,20.5230930594771,12.658426,0,0,0,40,4449,19.9782,19402.318359375,,,,,,,,,,,,,0,,,,0,,,,,,20.0007458,,,,
,28151227.88,20.0016413,24055.3017578125,0.0175050568314713,3.38488937629273E-6,1,0.999253354069792,40.0298881530762,1.98090927376831,27.8200004249811,0.195286387849451,0.0362932566162317,2.5,0.000111551336329958,0.0174378360817354,0.000224201836952599,20.0015965,20.0016861,24050.248046875,24060.35546875,57.4403166212368,20.5203080763783,13.038077,0,0,0,40,4449,19.9764,24055.3017578125,,,,,,,,,,,,,0,,,,0.00245,,,,,,20.0016413,,,,
,28151320.9,20.001708,28705.65625,0.0234428085232644,3.05761004328618E-6,1,0.999253354069792,40.0298881530762,1.98078000385694,27.8200004249811,0.261632126093887,0.0486522539986719,2.5,0.000146057513706007,0.023363977862285,0.000302889253611742,20.0015945,20.0018215,28703.083984375,28708.228515625,57.4840878183138,20.5252201999523,13.417728,0,0,0,40,4449,19.97585,28705.65625,,,,,,,,,,,,,0,,,,0,,,,,,20.001708,,,,
,28151413.96,20.0018196,33356.015625,0.0286486725176671,2.16536341943127E-6,1,0.999253354069792,40.0298881530762,1.98114515063788,27.8200004249811,0.319938387413004,0.0595326535766542,2.5,0.000175744269742254,0.028566313411483,0.000373608391177234,20.0018196,20.0018196,33351.09765625,33360.93359375,57.555997642083,20.5234661711092,13.038077,0,0,0,40,4449,19.9736,33356.015625,,,,,,,,,,,,,0,,,,0.0049,,,,,,20.0018196,,,,
,28151508.585,20.0013027,38085.712890625,0.0331518258696378,2.67598817167553E-6,1,0.999253354069792,40.0298881530762,1.98131667156221,27.8200004249811,0.370431756695803,0.0690023752591181,2.5,0.000204009687908166,0.0330730821465013,0.000438950347905607,20.0013027,20.0013027,38078.16015625,38093.265625,57.5817913832176,20.5208750455755,13.417728,0,0,0,40,4449,19.97305,38085.712890625,,,,,,,,,,,,,0,,,,-0.0049,,,,,,20.0013027,,,,
,28151600.305,20.0013084,42668.56640625,0.0368065346159835,3.07960677093269E-6,1,0.999253354069792,40.0298881530762,1.98123997528512,27.8200004249811,0.411453273719843,0.0766404071287418,2.5,0.000221399674886007,0.0367368965426839,0.000487294468787107,20.0013084,20.0013084,42660.890625,42676.2421875,57.545836471333,20.5239672527444,13.038077,0,0,0,40,4449,19.9712,42668.56640625,,,,,,,,,,,,,0,,,,0.00245,,,,,,20.0013084,,,,
,28151692.5,20.0008144,47279.1640625,0.0398909052760904,3.84532050243846E-6,1,0.999253354069792,40.0298881530762,1.98132974654623,27.8200004249811,0.446148665139812,0.0832036606763197,2.5,0.000244825201018114,0.0398344768653738,0.00053706656368833,20.0008144,20.0008144,47269.1484375,47289.1796875,57.2847725459099,20.5214623310781,13.038077,0,0,0,40,4449,19.97025,47279.1640625,,,,,,,,,,,,,0,,,,0,,,,,,20.0008144,,,,
,28151786.24,20.0004292,51964.630859375,0.0425840986423119,3.21275761131975E-6,1,0.999253354069792,40.0298881530762,1.98132232303396,27.8200004249811,0.476487739712991,0.0889028879566577,2.5,0.000262225330190271,0.0425440747914574,0.000577154023498385,20.0004292,20.0004292,51956.9765625,51972.28515625,57.2628869473714,20.520839640125,13.417728,0,0,0,40,4449,19.9698,51964.630859375,,,,,,,,,,,,,0,,,,-0.00245,,,,,,20.0004292,,,,
,28151877.895,20.0006046,56542.322265625,0.0448392921202609,4.03228665450615E-6,1,0.999253354069792,40.0298881530762,1.98135866466272,27.8200004249811,0.50195887588996,0.0936422846281241,2.5,0.000273591889387808,0.0448173321008543,0.000606871437830138,20.0006046,20.0006046,56534.80859375,56549.8359375,57.3965454241599,20.5172845289346,13.038077,0,0,0,40,4449,19.9696,56542.322265625,,,,,,,,,,,,,0,,,,0.00245,,,,,,20.0006046,,,,
,28151970.835,20.00107,61187.2734375,0.0468731517793361,4.38608139254702E-6,1,0.999253354069792,40.0298881530762,1.98125682680139,27.8200004249811,0.524913848646639,0.0980293101625053,2.5,0.000294845013229962,0.0468707283052429,0.000643711482622935,20.00107,20.00107,61182.23046875,61192.31640625,57.2503808910638,20.5200375526457,13.038077,0,0,0,40,4449,19.9687,61187.2734375,,,,,,,,,,,,,0,,,,-0.00245,,,,,,20.00107,,,,
,28152066.125,20.0017319,65950.6171875,0.048751907041582,4.71653172720619E-6,1,0.999253354069792,40.0298881530762,1.9814169426054,27.8200004249811,0.546225141992337,0.102041503088547,2.5,0.000310478754759116,0.0487703768622972,0.000672583046701536,20.0017319,20.0017319,65945.6796875,65955.5546875,57.3746598256215,20.5191714194785,13.038077,0,0,0,40,4449,19.9674,65950.6171875,,,,,,,,,,,,,0,,,,-0.00245,,,,,,20.0017319,,,,
,28152161.41,20.00158215,70716.1171875,0.0504231513588541,3.52086587900417E-6,1,0.999253354069792,40.0298881530762,1.98171108582196,27.8200004249811,0.565259334100472,0.105611261622843,2.5,0.000324518127731701,0.0504629187750515,0.000697127294191124,20.0014038,20.0017605,70708.671875,70723.5625,57.1792526958137,20.5126011422552,13.038077,0,0,0,40,4449,19.96515,70716.1171875,,,,,,,,,,,,,0,,,,0.00245,,,,,,20.00158215,,,,
,28152253.615,20.00256345,75323.60546875,0.0518980711214038,4.02037367461126E-6,1,0.999253354069792,40.0298881530762,1.98167672857094,27.8200004249811,0.582001727137879,0.108743186483564,2.5,0.000337461591853427,0.051958495686086,0.00071811854626411,20.0025539,20.002573,75316.2578125,75330.953125,57.301968373333,20.5170668617289,13.038077,0,0,0,40,4449,19.9645,75323.60546875,,,,,,,,,,,,,0,,,,0.00245,,,,,,20.00256345,,,,
,28152344.89,20.0020847,79884.58203125,0.0532612321807887,2.99368441863715E-6,1,0.999253354069792,40.0298881530762,1.98212522503224,27.8200004249811,0.597630814088884,0.111645087997621,2.5,0.00034870453406927,0.0533419834657424,0.000735661975611363,20.0020847,20.0020847,79879.375,79889.7890625,57.5833546402561,20.5124416352267,13.038077,0,0,0,40,4449,19.9624,79884.58203125,,,,,,,,,,,,,0,,,,0.00245,,,,,,20.0020847,,,,
,28152437.51,20.0010586,84515.90234375,0.0545223498159681,4.05981630943868E-6,1,0.999253354069792,40.0298881530762,1.98182410353656,27.8200004249811,0.611898971086544,0.114306740563315,2.5,0.000361419891800342,0.0546233694835589,0.000753004385998386,20.0010586,20.0010586,84508.265625,84523.5390625,57.4027984523138,20.5149314825907,13.038077,0,0,0,40,4449,19.9607,84515.90234375,,,,,,,,,,,,,0,,,,0.0049,,,,,,20.0010586,,,,
,28152523.94,20.002121,88836.80859375,0.0556399366352125,2.60598305507101E-6,1,0.999253354069792,40.0298881530762,1.98176007971092,27.8200004249811,0.624602124351511,0.116706004186977,2.5,0.000376158925894264,0.055759474771681,0.000770929209797574,20.002121,20.002121,88831.7734375,88841.84375,57.2980602307368,20.5128660304556,13.417728,0,0,0,40,4449,19.95955,88836.80859375,,,,,,,,,,,,,0,,,,-0.0049,,,,,,20.002121,,,,
,28152627.41,20.0008984,86916.25390625,0.0553273311658537,4.21696781949973E-6,1,0.999253354069792,40.0298881530762,1.981915457398,27.8200004249811,0.621057079472379,0.116055852768209,2.5,0.000372802250295195,0.0554390314432796,0.000767554294862983,20.0008984,20.0008984,86883.8671875,86948.640625,57.3816944822945,20.5132570387396,13.038077,0,0,0,40,4449,19.9595,86916.25390625,,,,,,,,,,,,,0,,,,-0.00245,,,,,,20.0008984,,,,
,28152716.07,20.001482,82482.5546875,0.0543482664117188,4.61024050037141E-6,1,0.999253354069792,40.0298881530762,1.98150153736507,27.8200004249811,0.609758075445027,0.113929092665684,2.5,0.000360014401368313,0.0544410531027623,0.000752414056853584,20.001482,20.001482,82475.1015625,82490.0078125,57.4606389627369,20.5152435059002,13.038077,0,0,0,40,4449,19.9595,82482.5546875,,,,,,,,,,,,,0,,,,0,,,,,,20.001482,,,,
,28152807.815,19.99928665,77896.02734375,0.0532634157250365,1.99981409270497E-6,1,0.999253354069792,40.0298881530762,1.98144602865024,27.8200004249811,0.597365989006554,0.111616730782659,2.5,0.00034872672192634,0.0533361224871621,0.000737403211577639,19.9991798,19.9993935,77886.1796875,77905.875,57.159711982833,20.5172390343449,13.038077,0,0,0,40,4449,19.9599,77896.02734375,,,,,,,,,,,,,0,,,,0,,,,,,19.99928665,,,,
,28152897.78,19.9988537,73400.1953125,0.0521536208653016,4.14026740088378E-6,1,0.999253354069792,40.0298881530762,1.98140980581953,27.8200004249811,0.584701743561744,0.10924986099182,2.5,0.000337900052104358,0.0522062921614087,0.000721732686301746,19.9988537,19.9988537,73397.6015625,73402.7890625,57.6693337773715,20.5198099588412,13.038077,0,0,0,40,4449,19.9608,73400.1953125,,,,,,,,,,,,,0,,,,0,,,,,,19.9988537,,,,
,28152989.455,19.9985161,68814.5234375,0.050941855803002,2.78250025196836E-6,1,0.999253354069792,40.0298881530762,1.98156423694842,27.8200004249811,0.570946159344449,0.106649133643731,2.5,0.00032472252006074,0.0509738450904257,0.000702059804181697,19.9985161,19.9985161,68804.578125,68824.46875,57.4653287338522,20.5189078996321,13.417728,0,0,0,40,4449,19.96275,68814.5234375,,,,,,,,,,,,,0,,,,0,,,,,,19.9985161,,,,
,28153082.315,19.9979115,64173.404296875,0.0496506669371881,3.58681465679773E-6,1,0.999253354069792,40.0298881530762,1.98136799078671,27.8200004249811,0.556196835917348,0.103886899747072,2.5,0.000314166547461545,0.0496616236201617,0.000683369348985998,19.9979115,19.9979115,64165.8671875,64180.94140625,57.3816944822945,20.5234924292633,13.038077,0,0,0,40,4449,19.9636,64173.404296875,,,,,,,,,,,,,0,,,,-0.00245,,,,,,19.9979115,,,,
,28153175.4,19.9984455,59520.482421875,0.0482636596204016,2.72616426102567E-6,1,0.999253354069792,40.0298881530762,1.98172705583294,27.8200004249811,0.540519520673475,0.100969506298331,2.5,0.000305743029424414,0.0482536367827764,0.000664928988457195,19.9984455,19.9984455,59512.91796875,59528.046875,57.3387049137368,20.5207580839505,12.658426,0,0,0,40,4449,19.966,59520.482421875,,,,,,,,,,,,,0,,,,0,,,,,,19.9984455,,,,
,28153269.1,19.9985466,54837.708984375,0.046769984081304,3.73126282513078E-6,1,0.999253354069792,40.0298881530762,1.9818056225471,27.8200004249811,0.523584238180207,0.0977568960167194,2.5,0.000292693596572127,0.04673927543944,0.00063982642886581,19.9985466,19.9985466,54830.1875,54845.23046875,57.3926372815638,20.5172896402728,13.038077,0,0,0,40,4449,19.96655,54837.708984375,,,,,,,,,,,,,0,,,,0,,,,,,19.9985466,,,,
,28153360.845,19.9983978,50252.3515625,0.0451937770028579,4.81984055159815E-6,1,0.999253354069792,40.0298881530762,1.98221635779815,27.8200004249811,0.505825623586965,0.0943395288342474,2.5,0.00027595196574542,0.0451435442978883,0.000609208733229298,19.9983978,19.9983978,50247.35546875,50257.34765625,57.4168677656599,20.5087833551791,13.417728,0,0,0,40,4449,19.96775,50252.3515625,,,,,,,,,,,,,0,,,,0,,,,,,19.9983978,,,,
,28153453.155,19.9991379,45637.4375,0.0435045232547103,4.19369729362979E-6,1,0.999253354069792,40.0298881530762,1.9821244399438,27.8200004249811,0.486666019361121,0.0907711897303761,2.5,0.000269293166644506,0.0434356018848297,0.000586595188534716,19.9991379,19.9991379,45629.94921875,45644.92578125,57.5817913832176,20.5159012231746,13.417728,0,0,0,40,4449,19.96815,45637.4375,,,,,,,,,,,,,0,,,,-0.00245,,,,,,19.9991379,,,,
,28153546.71,19.99866105,40961.884765625,0.0416299489732926,3.3511595711995E-6,1,0.999253354069792,40.0298881530762,1.98200201385703,27.8200004249811,0.465451384904956,0.0867516727920119,2.5,0.000256861778934154,0.0415436837166317,0.00055564090204952,19.9986229,19.9986992,40951.82421875,40971.9453125,57.1917587521214,20.5153619028976,13.038077,0,0,0,40,4449,19.96905,40961.884765625,,,,,,,,,,,,,0,,,,0,,,,,,19.99866105,,,,
,28153640.045,19.9985638,36296.884765625,0.0396060885106782,5.19678009486692E-6,1,0.999253354069792,40.0298881530762,1.98224736303286,27.8200004249811,0.442671562088314,0.0824203947106058,2.5,0.000242821357972109,0.0395045310312072,0.000520989120523438,19.9985638,19.9985638,36294.3828125,36299.38671875,57.3660619119099,20.5132932397744,13.038077,0,0,0,40,4449,19.9699,36296.884765625,,,,,,,,,,,,,0,,,,0,,,,,,19.9985638,,,,
,28153733.12,19.9985352,31649.359375,0.0374004395651634,4.55933904428977E-6,1,0.999253354069792,40.0298881530762,1.98266352747735,27.8200004249811,0.417912166631319,0.077724129511198,2.5,0.000228776987498338,0.0372862064789618,0.000484286229394106,19.9985352,19.9985352,31641.974609375,31656.744140625,57.4512594205061,20.5099374948329,12.658426,0,0,0,40,4449,19.9722,31649.359375,,,,,,,,,,,,,0,,,,0,,,,,,19.9985352,,,,
,28153823.665,19.9981995,27121.572265625,0.0350301548102438,2.55250755287643E-6,1,0.999253354069792,40.0298881530762,1.98263077379612,27.8200004249811,0.391240939818721,0.0727281494232189,2.5,0.000218846856198408,0.0349066139435801,0.000450307544088998,19.9981995,19.9981995,27119.150390625,27123.994140625,57.4801796757176,20.5109665274329,13.417728,0,0,0,40,4449,19.9734,27121.572265625,,,,,,,,,,,,,0,,,,0.00245,,,,,,19.9981995,,,,
,28153916.03,19.9986649,22504.0478515625,0.0323850363023688,3.13772443624144E-6,1,0.999253354069792,40.0298881530762,1.98257520080641,27.8200004249811,0.36152839797267,0.0671467868442751,2.5,0.000205694265968568,0.0322556509868049,0.000411100259534362,19.9986649,19.9986649,22496.33203125,22511.763671875,57.3246356003907,20.5112455015519,13.038077,0,0,0,40,4449,19.9753,22504.0478515625,,,,,,,,,,,,,0,,,,0.00245,,,,,,19.9986649,,,,
,28154007.07,19.9986153,17953.9365234375,0.0294883957750447,3.43482485184735E-6,1,0.999253354069792,40.0298881530762,1.98203266941249,27.8200004249811,0.328962344523059,0.0610823572417847,2.5,0.000194422102596063,0.0293575373415541,0.000372789507504761,19.9986153,19.9986153,17949.04296875,17958.830078125,57.5481813568907,20.5167173178331,13.417728,0,0,0,40,4449,19.9763,17953.9365234375,,,,,,,,,,,,,0,,,,0.0049,,,,,,19.9986153,,,,
,28154097.19,19.9979973,13451.4858398438,0.0263148428426125,3.66364024726546E-6,1,0.999253354069792,40.0298881530762,1.98217011089007,27.8200004249811,0.29346117486231,0.0544699668867191,2.5,0.000179919974797449,0.0261872714789687,0.000330766985068163,19.9979973,19.9979973,13446.4755859375,13456.49609375,57.2558522906984,20.5132052669263,13.038077,0,0,0,40,4449,19.9783,13451.4858398438,,,,,,,,,,,,,0,,,,0,,,,,,19.9979973,,,,
,28154185.125,19.9980717,9056.115234375,0.0228657563366293,2.68717990868309E-6,1,0.999253354069792,40.0298881530762,1.98181439426519,27.8200004249811,0.254866888876261,0.0472646288307655,2.5,0.000160020057855234,0.0227465523648641,0.00028370351995162,19.9980717,19.9980717,9053.771484375,9058.458984375,57.2972786022176,20.5140337729089,13.417728,0,0,0,40,4449,19.9796,9056.115234375,,,,,,,,,,,,,0,,,,-0.00245,,,,,,19.9980717,,,,
,28154276.115,19.9985752,4507.98559570313,0.0188268390789766,2.64702872790361E-6,1,0.999253354069792,40.0298881530762,1.98176345785408,27.8200004249811,0.209785732119365,0.0388320203700915,2.5,0.000131666141075133,0.0187224946993154,0.000227267357677573,19.9985752,19.9985752,4500.3681640625,4515.60302734375,57.2839909173907,20.51415975934,13.417728,0,0,0,40,4449,19.98095,4507.98559570313,,,,,,,,,,,,,0,,,,0.00245,,,,,,19.9985752,,,,
,28154367.915,19.9996319,-0.182685278356075,0.0142580480880798,1.74642248203385E-6,1,0.999253354069792,40.0298881530762,1.9820658309508,27.8200004249811,0.15886369111442,0.029386819365007,2.5,0.000101900932499896,0.0141755611974479,0.00017040228217989,19.9996319,19.9996319,-0.19790905714035,-0.1674614995718,57.2980602307368,20.514844538994,13.038077,0,0,0,40,4417,19.9797,-0.182685278356075,,,,,,,,,,,,,0,,,,-0.0049,,,,,,19.9996319,,,,