File: data/monolayers/nanoparticles/Ol_CoFe_C/vsm/data_dispersion/DD67_HYST_100K.DAT
[Header]
; VSM Data File (default extension .dat)
; Copyright (c) 2003-2013, Quantum Design, Inc. All rights reserved.
TITLE,
FILEOPENTIME,28166606.94,11/23/2018,8:04 am
BYAPP,VSM,2.0,2.0
INFO,PPMS VSM Option Release 1.4.10 Build 1,APPNAME
INFO,Quantum Design Linear Motor Servo Controller,MOTOR_MODULE_NAME
INFO,3101-100 M1,MOTOR_HW_VERSION
INFO,MMC1014,MOTOR_SERIAL_NUMBER
INFO,SRV No X-over 01.03.11,MOTOR_SOFTWARE_VERSION
INFO,Quantum Design VSM Detection Module,VSM_MODULE_NAME
INFO,3101-150 F0,VSM_HW_VERSION
INFO,VSM707,VSM_SERIAL_NUMBER
INFO,VSM No X-over 01.02.05 May 20 2008 13:51:47,VSM_SOFTWARE_VERSION
INFO,704,PREAMP_SERIAL_NUMBER
INFO,822,COIL_SERIAL_NUMBER
INFO,0,MOMENT_UNITS
INFO,CoFe2O4,SAMPLE_MATERIAL
INFO,dispersion in ampulle,SAMPLE_COMMENT
INFO,,SAMPLE_MASS
INFO,,SAMPLE_VOLUME
INFO,,SAMPLE_MOLECULAR_WEIGHT
INFO,,SAMPLE_SIZE
INFO,,SAMPLE_SHAPE
DATATYPE,COMMENT,1
DATATYPE,TIME,2
STARTUPAXIS,X,2
STARTUPAXIS,Y1,5
[Data]
Comment,Time Stamp (sec),Temperature (K),Magnetic Field (Oe),Moment (emu),M. Std. Err. (emu),Transport Action,Averaging Time (sec),Frequency (Hz),Peak Amplitude (mm),Center Position (mm),Coil Signal' (mV),Coil Signal" (mV),Range (mV),M. Quad. Signal (emu),M. Raw' (emu),M. Raw" (emu),Min. Temperature (K),Max. Temperature (K),Min. Field (Oe),Max. Field (Oe),Mass (grams),Motor Lag (deg),Pressure (Torr),VSM Status (code),Motor Status (code),Measure Status (code),Measure Count,PPMS Status (code),System Temp. (K),System Field (Oe),Sample Position (deg),Bridge 1 Resistance (ohms),Bridge 1 Excitation (에),Bridge 2 Resistance (ohms),Bridge 2 Excitation (에),Bridge 3 Resistance (ohms),Bridge 3 Excitation (에),Bridge 4 Resistance (ohms),Bridge 4 Excitation (에),Signal 1 Vin (V),Signal 2 Vin (V),Digital Inputs (code),Drive 1 Iout (mA),Drive 1 Ipower (W),Drive 2 Iout (mA),Drive 2 Ipower (W),Pressure (),Map 20 (),Map 21 (),Map 22 (),Map 23 (),Map 24 (),Map 25 (),Map 26 (),Map 27 (),Map 28 (),Map 29 ()
,28166623.56,100.2991409,-0.319699227809906,,,2,,,,27.7400003176928,,,,,,,100.2991409,100.2991409,-0.319699227809906,-0.319699227809906,,,22.149702,,,,-99999999,4369,100.2799,-0.319699227809906,,,,,,,,,,,,,,,,,,,,,,,100.2991409,,,,
,28166742.03,100.2099762,2957.66845703125,0.00861224318352105,2.73029617408956E-6,1,0.999253354069792,40.0298881530762,1.99715573624933,27.7299992740154,0.0978404039786727,0.0176379394372542,2.5,3.77184657775423E-5,0.00866056935017105,6.46390678061449E-5,100.2099762,100.2099762,2950.10473632812,2965.23217773438,55.9896140895444,20.473120046303,22.149702,0,0,0,40,4449,100.0504,2957.66845703125,,,,,,,,,,,,,0,,,,0,,,,,,100.2099762,,,,
,28166808.46,100.1572266,6271.10498046875,0.0125679590630494,2.63360025254259E-6,1,0.999253354069792,40.0298881530762,1.99700513982853,27.7299992740154,0.142772381227596,0.0257238803725016,2.5,5.39064734496954E-5,0.0126385283424488,9.31233336986248E-5,100.1572266,100.1572266,6258.619140625,6283.5908203125,56.2850696698137,20.4794702582429,22.149702,0,0,0,40,4449,99.9723,6271.10498046875,,,,,,,,,,,,,0,,,,0.00245,,,,,,100.1572266,,,,
,28166900.735,100.0957413,10883.94140625,0.0179043743607575,3.13840325716833E-6,1,0.999253354069792,40.0298881530762,1.99679624414376,27.7299992740154,0.203379221889936,0.0366200235999593,2.5,7.49776751944329E-5,0.0180050278488357,0.000130637851213533,100.0957413,100.0957413,10876.6123046875,10891.2705078125,56.5625477941406,20.4872061829192,22.149702,0,0,0,40,4449,99.90925,10883.94140625,,,,,,,,,,,,,0,,,,0,,,,,,100.0957413,,,,
,28167003.435,100.0498581,16016.3422851562,0.0233164652679849,2.74774749639722E-6,1,0.999253354069792,40.0298881530762,1.99716181696274,27.7299992740154,0.264911353475944,0.0476598116445042,2.5,9.46340868147704E-5,0.0234477435226625,0.000166736817013012,100.0498581,100.0498581,16003.9375,16028.7470703125,56.8572217458906,20.4841346654174,22.149702,0,0,0,40,4449,99.875,16016.3422851562,,,,,,,,,,,,,0,,,,0,,,,,,100.0498581,,,,
,28167101.44,100.0240402,20916.1171875,0.0276983449885204,3.47938217600488E-6,1,0.999253354069792,40.0298881530762,1.99656653515432,27.7299992740154,0.314601712360253,0.0566445301698371,2.5,0.000116724271700279,0.027854510357766,0.000201932692101576,100.0240402,100.0240402,20901.26171875,20930.97265625,56.6188250475252,20.4919553466551,22.149702,0,0,0,40,4449,99.86165,20916.1171875,,,,,,,,,,,,,0,,,,0,,,,,,100.0240402,,,,
,28167198.345,100.0108261,25758.5849609375,0.0313510645561772,3.9244161921997E-6,1,0.999253354069792,40.0298881530762,1.99594306999019,27.7299992740154,0.355978057769865,0.0641447667103306,2.5,0.000136972534187094,0.0315280724422755,0.000232884768687722,100.0108261,100.0108261,25748.537109375,25768.6328125,56.6219515616021,20.4934601040035,22.149702,0,0,0,40,4449,99.8579,25758.5849609375,,,,,,,,,,,,,0,,,,0,,,,,,100.0108261,,,,
,28167294.295,100.0056686,30554.2314453125,0.0344163145631049,3.30757620499399E-6,1,0.999253354069792,40.0298881530762,1.99700050591393,27.7299992740154,0.390988446657799,0.0704242566485276,2.5,0.000148505780678798,0.0346109206673689,0.000253158068114681,100.0056686,100.0056686,30541.71875,30566.744140625,56.6071006197368,20.4889269393212,22.149702,0,0,0,40,4449,99.85475,30554.2314453125,,,,,,,,,,,,,0,,,,-0.0049,,,,,,100.0056686,,,,
,28167391.53,100.0020599,35414.361328125,0.0370979157467024,4.00496458439834E-6,1,0.999253354069792,40.0298881530762,1.99674530322628,27.7299992740154,0.421415455818779,0.0758439134187636,2.5,0.000155597077222776,0.0373080174387802,0.000267670878275619,100.0020599,100.0020599,35409.12109375,35419.6015625,56.6805737005445,20.4872228431849,21.770052,0,0,0,40,4449,99.85595,35414.361328125,,,,,,,,,,,,,0,,,,0.0049,,,,,,100.0020599,,,,
,28167488.195,100.0020905,40244.599609375,0.0394455759927079,4.69044974200228E-6,1,0.999253354069792,40.0298881530762,1.99676531022938,27.7299992740154,0.448091259500277,0.0806483049971131,2.5,0.000166487955176152,0.0396693046550408,0.000284906783288418,100.0020905,100.0020905,40231.82421875,40257.375,56.7657712091406,20.4922575885743,22.149702,0,0,0,40,4449,99.8543,40244.599609375,,,,,,,,,,,,,0,,,,0,,,,,,100.0020905,,,,
,28167586.045,100.0007324,45135.123046875,0.0415455085915539,1.26397997668908E-6,1,0.999253354069792,40.0298881530762,1.99640638095536,27.7299992740154,0.471863849776066,0.0849571935547547,2.5,0.000178742953221631,0.0417814972548969,0.000302671490533737,100.0007324,100.0007324,45119.99609375,45150.25,56.6266413327175,20.4956837802322,22.149702,0,0,0,40,4449,99.85305,45135.123046875,,,,,,,,,,,,,0,,,,-0.00245,,,,,,100.0007324,,,,
,28167683.45,100.0020523,50005.01171875,0.0434360849035384,3.78274003899885E-6,1,0.999253354069792,40.0298881530762,1.9969037401823,27.7299992740154,0.49348135550938,0.0887123764596937,2.5,0.000176052620076769,0.0436832170639967,0.000304703380833953,100.0020523,100.0020523,49992.5390625,50017.484375,56.6336759893906,20.4890698061259,22.529354,0,0,0,40,4449,99.8521,50005.01171875,,,,,,,,,,,,,0,,,,0,,,,,,100.0020523,,,,
,28167782.99,100.0030594,54979.80078125,0.0451638891662372,2.54093453443779E-6,1,0.999253354069792,40.0298881530762,1.99650412472997,27.7299992740154,0.513007499965753,0.0922813710792681,2.5,0.000188978839139451,0.0454212279476239,0.000321870648252129,100.0030594,100.0030594,54969.61328125,54989.98828125,56.6883899857368,20.4949219585819,22.909004,0,0,0,40,4449,99.8489,54979.80078125,,,,,,,,,,,,,0,,,,0,,,,,,100.0030594,,,,
,28167881.135,100.0050659,59885.0625,0.0467470533753279,5.1692432328574E-6,1,0.999253354069792,40.0298881530762,1.99667585778775,27.7299992740154,0.531049655421216,0.095460696350228,2.5,0.000190889336719806,0.0470138242600122,0.000327482952960659,100.0050659,100.0050659,59867.30859375,59902.81640625,56.9869720800829,20.4921706526642,22.149702,0,0,0,40,4449,99.8439,59885.0625,,,,,,,,,,,,,0,,,,0,,,,,,100.0050659,,,,
,28167982.33,100.0041046,64942.583984375,0.0482434023884757,3.89293117430964E-6,1,0.999253354069792,40.0298881530762,1.99699945679436,27.7299992740154,0.548137217239789,0.0985359472342525,2.5,0.000198301891752256,0.0485191346377409,0.000338278540392597,100.0041046,100.0041046,64930.0390625,64955.12890625,56.8337728903137,20.4945228013434,22.529354,0,0,0,40,4449,99.84055,64942.583984375,,,,,,,,,,,,,0,,,,0.00245,,,,,,100.0041046,,,,
,28168081.825,100.0035782,69918.53125,0.0495864293573961,5.30940770477122E-6,1,0.999253354069792,40.0298881530762,1.9967387059552,27.7299992740154,0.563348602776287,0.101167823504597,2.5,0.000196078755984748,0.0498702864544675,0.00033889983538645,100.0031967,100.0039597,69908.546875,69928.515625,56.8861420011022,20.4936347766801,22.149702,0,0,0,40,4449,99.83635,69918.53125,,,,,,,,,,,,,0,,,,0.00245,,,,,,100.0035782,,,,
,28168177.985,100.0052032,74723.2734375,0.0508121099729612,4.26716086229693E-6,1,0.999253354069792,40.0298881530762,1.9961762849844,27.7299992740154,0.577109978772915,0.103715374831393,2.5,0.000208419208465,0.0511033770344923,0.00035381998677548,100.0052032,100.0052032,74711.015625,74735.53125,56.9236601700253,20.5016831080419,22.529354,0,0,0,40,4449,99.8303,74723.2734375,,,,,,,,,,,,,0,,,,-0.00245,,,,,,100.0052032,,,,
,28168274.2,100.0055313,79531.640625,0.051963275455129,2.20747748442909E-6,1,0.999253354069792,40.0298881530762,1.99596155492997,27.7299992740154,0.590123873925301,0.106082935260779,2.5,0.000216613615041328,0.0522615562060354,0.000364306778070831,100.0055313,100.0055313,79519.1328125,79544.1484375,56.8767624588714,20.495945081554,22.149702,0,0,0,40,4449,99.8264,79531.640625,,,,,,,,,,,,,0,,,,0.00245,,,,,,100.0055313,,,,
,28168370.96,100.0040817,84370.26953125,0.0530395535943495,4.26034313878167E-6,1,0.999253354069792,40.0298881530762,1.99609591372949,27.7200005948544,0.602404760637382,0.108205316249393,2.5,0.000214871017346098,0.0533444638599218,0.000364539795849186,100.0040817,100.0040817,84362.8203125,84377.71875,56.7782772654483,20.4907135394939,22.529354,0,0,0,40,4449,99.8222,84370.26953125,,,,,,,,,,,,,0,,,,0,,,,,,100.0040817,,,,
,28168464.31,100.0039978,89038.30078125,0.0540277370588348,3.58575343700211E-6,1,0.999253354069792,40.0298881530762,1.99638720182642,27.7299992740154,0.613709851376299,0.110286392144214,2.5,0.000224207558617174,0.0543387372674528,0.000375660058308538,100.0039978,100.0039978,89025.7734375,89050.828125,56.9111541137176,20.4883765509511,22.909004,0,0,0,40,4449,99.82155,89038.30078125,,,,,,,,,,,,,0,,,,0,,,,,,100.0039978,,,,
,28168581.695,100.000412,86323.70703125,0.0534992658488502,5.33324858414144E-6,1,0.999253354069792,40.0298881530762,1.99618167710186,27.7299992740154,0.607631565257964,0.10926971842955,2.5,0.000227862697981472,0.0538069650461636,0.00037847086398352,100.000412,100.000412,86318.765625,86328.6484375,57.0291800201214,20.483918343685,22.149702,0,0,0,40,4449,99.81875,86323.70703125,,,,,,,,,,,,,0,,,,0,,,,,,100.000412,,,,
,28168676.475,99.9993134,81585.18359375,0.0524972992369759,1.58817310561909E-6,1,0.999253354069792,40.0298881530762,1.99656861173994,27.7299992740154,0.596357294907644,0.107241078788671,2.5,0.000222476000368518,0.0527988203716607,0.00037127679537588,99.9993134,99.9993134,81575.125,81595.2421875,57.2425646058714,20.4779700565274,22.149702,0,0,0,40,4449,99.8207,81585.18359375,,,,,,,,,,,,,0,,,,0,,,,,,99.9993134,,,,
,28168772.625,99.9970779,76778.7578125,0.0513998146837303,4.23053131459911E-6,1,0.999253354069792,40.0298881530762,1.99592784683844,27.7299992740154,0.583713246348987,0.104928056949851,2.5,0.000213460892799809,0.0516946255417306,0.000360142091947994,99.9970779,99.9970779,76771.203125,76786.3125,57.0166739638137,20.4842640338561,22.529354,0,0,0,40,4449,99.82185,76778.7578125,,,,,,,,,,,,,0,,,,0,,,,,,99.9970779,,,,
,28168869.89,99.9961243,71917.7421875,0.0502496295229189,2.00110208836785E-6,1,0.999253354069792,40.0298881530762,1.99589680387338,27.7299992740154,0.570650225751067,0.10250930598287,2.5,0.000201670849826195,0.0505374469479513,0.000346027715901099,99.9961243,99.9961243,71907.7734375,71927.7109375,56.9002113144483,20.4852033586175,22.149702,0,0,0,40,4449,99.82625,71917.7421875,,,,,,,,,,,,,0,,,,0,,,,,,99.9961243,,,,
,28168966.895,99.9960938,67067.328125,0.0490077313191893,5.40271028065408E-6,1,0.999253354069792,40.0298881530762,1.99599036839572,27.7299992740154,0.556550991375564,0.100071470916526,2.5,0.000203807958174917,0.04928800372947,0.000345614110658427,99.9960938,99.9960938,67059.9453125,67074.7109375,57.2808644033138,20.4756505135603,22.529354,0,0,0,40,4449,99.8284,67067.328125,,,,,,,,,,,,,0,,,,0,,,,,,99.9960938,,,,
,28169064.165,99.9963913,62203.8828125,0.0476932052693449,3.45869727979394E-6,1,0.999253354069792,40.0298881530762,1.99583661702906,27.7299992740154,0.54157849976845,0.0973786950551302,2.5,0.000197346303272961,0.0479655613134585,0.00033628734786762,99.9963913,99.9963913,62191.15234375,62216.61328125,57.0158923352945,20.4839911888376,22.529354,0,0,0,40,4449,99.8337,62203.8828125,,,,,,,,,,,,,0,,,,0,,,,,,99.9963913,,,,
,28169163.105,99.9933395,57258.109375,0.046235976281733,3.27670943938496E-6,1,0.999253354069792,40.0298881530762,1.99603214077544,27.7299992740154,0.525076420997277,0.0944070607060399,2.5,0.000190010317254015,0.046499620246002,0.00032562589414355,99.9933395,99.9933395,57243.5703125,57272.6484375,56.9119357422368,20.4776975573951,22.909004,0,0,0,40,4449,99.83955,57258.109375,,,,,,,,,,,,,0,,,,0,,,,,,99.9933395,,,,
,28169260.69,99.993515,52380.935546875,0.0446995815829919,4.2831595647203E-6,1,0.999253354069792,40.0298881530762,1.99609228391837,27.7200005948544,0.50763016301982,0.0913209173859215,2.5,0.000187140214689392,0.0449540755259764,0.000319146864567134,99.993515,99.993515,52371.06640625,52390.8046875,57.3199458292753,20.4832879471352,22.529354,0,0,0,40,4449,99.84635,52380.935546875,,,,,,,,,,,,,0,,,,0.00245,,,,,,99.993515,,,,
,28169357.645,99.994072,47535.650390625,0.04303628555921,4.38364828022888E-6,1,0.999253354069792,40.0298881530762,1.99574282767108,27.7299992740154,0.488650793476676,0.0879324932089336,2.5,0.000181550729021312,0.0432809405242345,0.000309490731102872,99.994072,99.994072,47522.93359375,47548.3671875,57.2167708647368,20.4851450191438,22.529354,0,0,0,40,4449,99.8516,47535.650390625,,,,,,,,,,,,,0,,,,0.00245,,,,,,99.994072,,,,
,28169455.16,99.9926682,42662.66796875,0.0411857752095297,3.3346048884022E-6,1,0.999253354069792,40.0298881530762,1.99599654758004,27.7299992740154,0.467695623085353,0.0841415376088439,2.5,0.00017123443375639,0.0414195684862503,0.000294457747420216,99.9926682,99.9926682,42650.1015625,42675.234375,57.1651833824676,20.4846049342877,22.149702,0,0,0,40,4449,99.8572,42662.66796875,,,,,,,,,,,,,0,,,,-0.00245,,,,,,99.9926682,,,,
,28169553.78,99.9927826,37735.482421875,0.0391500109329152,4.20138172636122E-6,1,0.999253354069792,40.0298881530762,1.99604644797162,27.7299992740154,0.44459073009006,0.0799501791944251,2.5,0.000159060729360392,0.0393719243182036,0.000276929501297033,99.9927826,99.9927826,37727.78515625,37743.1796875,57.088583787583,20.485583936829,22.529354,0,0,0,40,4449,99.86395,37735.482421875,,,,,,,,,,,,,0,,,,-0.0049,,,,,,99.9927826,,,,
,28169650.9,99.9907913,32880.380859375,0.0368762475905409,3.65824417321244E-6,1,0.999253354069792,40.0298881530762,1.9961655887447,27.7299992740154,0.418784422252786,0.0753429990039276,2.5,0.000151998245643883,0.0370849618621014,0.000263720467294515,99.9907913,99.9907913,32870.40625,32890.35546875,57.0510656186599,20.4774012376174,22.529354,0,0,0,40,4449,99.8739,32880.380859375,,,,,,,,,,,,,0,,,,-0.00245,,,,,,99.9907913,,,,
,28169747.57,99.991066,28048.0810546875,0.0343680254216014,3.06803891851378E-6,1,0.999253354069792,40.0298881530762,1.99604499226896,27.7299992740154,0.390276562193433,0.0702000880669812,2.5,0.00013982807650582,0.0345622658900915,0.000244571667307119,99.991066,99.991066,28037.990234375,28058.171875,57.2503808910638,20.4880141125732,22.149702,0,0,0,40,4449,99.8806,28048.0810546875,,,,,,,,,,,,,0,,,,0,,,,,,99.991066,,,,
,28169845.71,99.9918671,23140.64453125,0.0314279152571773,2.8424983154063E-6,1,0.999253354069792,40.0298881530762,1.9962477751277,27.7299992740154,0.356921174300448,0.0641989657978261,2.5,0.00012717359485765,0.0316052808922521,0.000223527215576414,99.9918671,99.9918671,23130.642578125,23150.646484375,57.3895107674868,20.4825339450886,22.909004,0,0,0,40,4449,99.88575,23140.64453125,,,,,,,,,,,,,0,,,,0,,,,,,99.9918671,,,,
,28169943.305,99.9922104,18265.826171875,0.0280959826138954,2.36264502974832E-6,1,0.999253354069792,40.0298881530762,1.99600402753825,27.7299992740154,0.319038246175884,0.0574031819350133,2.5,0.000114755139236558,0.0282543192424519,0.000201386539815372,99.9922104,99.9922104,18253.18359375,18278.46875,57.1323549846599,20.4842507532174,22.529354,0,0,0,40,4449,99.89565,18265.826171875,,,,,,,,,,,,,0,,,,0.0049,,,,,,99.9922104,,,,
,28170039.62,99.9914627,13450.9956054687,0.0242100157325556,2.72004610907615E-6,1,0.999253354069792,40.0298881530762,1.99593045049484,27.7299992740154,0.274902587265828,0.0494481514197699,2.5,9.73009104947853E-5,0.02434627556573,0.000172339705811542,99.9914627,99.9914627,13441.2783203125,13460.712890625,57.2566339192176,20.4921780385321,22.149702,0,0,0,40,4449,99.90385,13450.9956054687,,,,,,,,,,,,,0,,,,0.0049,,,,,,99.9914627,,,,
,28170136.655,99.9909439,8600.287109375,0.0196132442173942,2.94661027818036E-6,1,0.999253354069792,40.0298881530762,1.99591568575926,27.7299992740154,0.222700082105344,0.0400782797776481,2.5,8.02323060798986E-5,0.0197234870148689,0.000141337696406967,99.9909439,99.9909439,8592.6552734375,8607.9189453125,57.1987934087945,20.4887562833676,22.529354,0,0,0,40,4449,99.91035,8600.287109375,,,,,,,,,,,,,0,,,,0.00245,,,,,,99.9909439,,,,
,28170233.195,99.9923172,3777.39099121094,0.0141539409856604,3.24209020014642E-6,1,0.999253354069792,40.0298881530762,1.99603494571864,27.7299992740154,0.160718238900653,0.0289348956943457,2.5,5.86588998147763E-5,0.0142334041697631,0.00010295635718226,99.9923172,99.9923172,3759.8955078125,3794.88647460937,57.3449579418907,20.498248168449,22.529354,0,0,0,40,4449,99.91695,3777.39099121094,,,,,,,,,,,,,0,,,,-0.00245,,,,,,99.9923172,,,,
,28170328.195,99.9945526,-972.034118652344,0.00732570535860216,3.96215129069867E-6,1,0.999253354069792,40.0298881530762,1.99602207362543,27.7299992740154,0.0831856550423497,0.0149592405261203,2.5,2.88557741294372E-5,0.00736681567087308,5.18219264857206E-5,99.9945526,99.9945526,-982.0751953125,-961.993041992188,57.0846756449868,20.4887366406657,22.149702,0,0,0,40,4449,99.92355,-972.034118652344,,,,,,,,,,,,,0,,,,0,,,,,,99.9945526,,,,
,28170429.18,99.9972229,-6015.18237304687,-0.00173421314687187,4.13589373148109E-6,1,0.999253354069792,40.0298881530762,1.9960245193853,27.7299992740154,-0.0196869861271122,-0.00355864740527168,0.25,-8.41889926538783E-6,-0.00174395074209746,-1.38418487314396E-5,99.9972229,99.9972229,-6027.4619140625,-6002.90283203125,57.2535074051407,20.4888072116608,22.529354,0,0,0,40,4449,99.9228,-6015.18237304687,,,,,,,,,,,,,0,,,,0,,,,,,99.9972229,,,,
,28170530.695,100.0045624,-11093.5498046875,-0.0111793664363036,4.0177751028817E-6,1,0.999253354069792,40.0298881530762,1.99603580439709,27.7299992740154,-0.126942487194104,-0.0228582984776276,2.5,-4.6939101010128E-5,-0.0112422401142037,-8.16817865542157E-5,100.0045624,100.0045624,-11105.814453125,-11081.28515625,57.1628384969099,20.4868487428675,22.909004,0,0,0,40,4449,99.91635,-11093.5498046875,,,,,,,,,,,,,0,,,,-0.00245,,,,,,100.0045624,,,,
,28170629.545,100.0067406,-16030.98046875,-0.0194069723674735,3.64545259447263E-6,1,0.999253354069792,40.0298881530762,1.99605386299612,27.7299992740154,-0.220378720336267,-0.0396382689803553,2.5,-7.79721616015251E-5,-0.0195162756658313,-0.000137944416568162,100.006691,100.0067902,-16038.564453125,-16023.396484375,57.1526773261599,20.4865838393288,22.529354,0,0,0,40,4449,99.90945,-16030.98046875,,,,,,,,,,,,,0,,,,0.00245,,,,,,100.0067406,,,,
,28170730.305,100.00972365,-21068.3369140625,-0.0258543435239299,3.12154920397729E-6,1,0.999253354069792,40.0298881530762,1.99590494561023,27.7200005948544,-0.293565360569955,-0.0528538117238507,2.5,-0.000108756358654221,-0.0260001509333915,-0.000188224290752624,100.0097198,100.0097275,-21080.94921875,-21055.724609375,57.2449094914291,20.4885079950946,22.529354,0,0,0,40,4449,99.9001,-21068.3369140625,,,,,,,,,,,,,0,,,,0,,,,,,100.00972365,,,,
,28170828.32,100.0111237,-25967.5703125,-0.0304997615631542,3.15068441374581E-6,1,0.999253354069792,40.0298881530762,1.99621280645594,27.7200005948544,-0.346372936112034,-0.0623199972424268,2.5,-0.000125312857268933,-0.030672021530731,-0.000218499116438274,100.0111237,100.0111237,-25982.349609375,-25952.791015625,57.0518472471791,20.4753282871455,22.529354,0,0,0,40,4449,99.89105,-25967.5703125,,,,,,,,,,,,,0,,,,0,,,,,,100.0111237,,,,
,28170929.285,100.0104675,-31012.6796875,-0.0341916680017391,2.89649650358922E-6,1,0.999253354069792,40.0298881530762,1.99641715608339,27.7299992740154,-0.388341411087886,-0.0698718842500216,2.5,-0.000141196366262268,-0.034385067523181,-0.000245022653527961,100.0104675,100.0104675,-31030.509765625,-30994.849609375,57.0096393071407,20.4767064007428,22.149702,0,0,0,40,4449,99.8811,-31012.6796875,,,,,,,,,,,,,0,,,,0.00245,,,,,,100.0104675,,,,
,28171031.135,100.0088501,-36102.46875,-0.0371965491619563,3.21500255689318E-6,1,0.999253354069792,40.0298881530762,1.99624186154275,27.7299992740154,-0.422425708712593,-0.0760791907533616,2.5,-0.000160703099848842,-0.0374072494338619,-0.000272968324337071,100.0088501,100.0088501,-36112.0625,-36092.875,57.1909771236022,20.4762020631609,22.909004,0,0,0,40,4449,99.87305,-36102.46875,,,,,,,,,,,,,0,,,,-0.0049,,,,,,100.0088501,,,,
,28171131.75,100.01017,-41132.208984375,-0.0397134918362668,3.96056688863301E-6,1,0.999253354069792,40.0298881530762,1.99631093795826,27.7299992740154,-0.451034926791689,-0.0811929175951572,2.5,-0.000169040807195299,-0.039938799725694,-0.000288112276991255,100.01017,100.01017,-41139.796875,-41124.62109375,56.9963516223137,20.4793202926309,22.909004,0,0,0,40,4449,99.86375,-41132.208984375,,,,,,,,,,,,,0,,,,-0.00245,,,,,,100.01017,,,,
,28171233.37,100.0097427,-46209.87109375,-0.0418953219723836,2.77887097074513E-6,1,0.999253354069792,40.0298881530762,1.99649013821078,27.7299992740154,-0.475860495821211,-0.085655051763573,2.5,-0.000178575530821787,-0.0421333738620834,-0.000303357528004323,100.0097427,100.0097427,-46222.3984375,-46197.34375,57.1628384969099,20.4753326925497,22.909004,0,0,0,40,4449,99.8523,-46209.87109375,,,,,,,,,,,,,0,,,,-0.0049,,,,,,100.0097427,,,,
,28171331.1,100.01017,-51096.81640625,-0.0437801844005762,3.16885556872884E-6,1,0.999253354069792,40.0298881530762,1.99681178979956,27.7299992740154,-0.497338403966625,-0.0895891125208444,2.5,-0.000193257131443677,-0.0440292967471788,-0.000322841887746549,100.01017,100.01017,-51109.1640625,-51084.46875,56.9494539111599,20.4697068317254,22.529354,0,0,0,40,4449,99.84295,-51096.81640625,,,,,,,,,,,,,0,,,,-0.0049,,,,,,100.01017,,,,
,28171431.475,100.0100937,-56111.28515625,-0.0455355779269709,3.90312117556865E-6,1,0.999253354069792,40.0298881530762,1.99682783667789,27.7299992740154,-0.517296652419299,-0.0931328987044277,2.5,-0.000197531155366719,-0.0457950841933435,-0.00033137875096935,100.0100937,100.0100937,-56126.4765625,-56096.09375,57.1862873524868,20.4679668384274,22.909004,0,0,0,40,4449,99.8336,-56111.28515625,,,,,,,,,,,,,0,,,,0.0049,,,,,,100.0100937,,,,
,28171532.29,100.0093765,-61148.87109375,-0.0471134115572411,4.33268485359688E-6,1,0.999253354069792,40.0298881530762,1.99698922143748,27.7299992740154,-0.535287623155442,-0.0962517972721303,2.5,-0.000195085760641757,-0.0473823482212723,-0.000332561605616312,100.0093765,100.0093765,-61158.60546875,-61139.13671875,56.9986965078714,20.4763604433296,22.909004,0,0,0,40,4449,99.8253,-61148.87109375,,,,,,,,,,,,,0,,,,-0.00245,,,,,,100.0093765,,,,
,28171633.61,100.0090027,-66213.5,-0.0485863069880164,2.30151897700683E-6,1,0.999253354069792,40.0298881530762,1.99633746454861,27.7299992740154,-0.551841983015416,-0.0993051119973657,2.5,-0.00020871719251407,-0.0488640559777463,-0.00034953355892098,100.0090027,100.0090027,-66220.953125,-66206.046875,56.8298647477175,20.4682423299552,22.909004,0,0,0,40,4449,99.8193,-66213.5,,,,,,,,,,,,,0,,,,0.00245,,,,,,100.0090027,,,,
,28171732.555,100.0084,-71158.2578125,-0.0499159110763284,2.36170619497494E-6,1,0.999253354069792,40.0298881530762,1.99662974076448,27.7299992740154,-0.567038146369193,-0.101977504623102,2.5,-0.000210124917447146,-0.0502016968410262,-0.000353768525981498,100.0084,100.0084,-71168.375,-71148.140625,56.9588334533906,20.4737492209831,22.909004,0,0,0,40,4449,99.8118,-71158.2578125,,,,,,,,,,,,,0,,,,0.00245,,,,,,100.0084,,,,
,28171832.955,100.007576,-76175.3203125,-0.0511701782951094,3.98632911579099E-6,1,0.999253354069792,40.0298881530762,1.9958564801115,27.7299992740154,-0.581082172862559,-0.10446999118016,2.5,-0.000213616791289758,-0.0514635904365638,-0.000359810469553378,100.007576,100.007576,-76185.3203125,-76165.3203125,57.2535074051407,20.4852339702832,22.909004,0,0,0,40,4449,99.807,-76175.3203125,,,,,,,,,,,,,0,,,,-0.0049,,,,,,100.007576,,,,
,28171935.49,100.0052643,-81300.34375,-0.0523621883849667,2.82611460115378E-6,1,0.999253354069792,40.0298881530762,1.99634660866671,27.7299992740154,-0.594755884742502,-0.106969977177882,2.5,-0.000223232550205347,-0.0526628776839776,-0.000371768320392941,100.0052643,100.0052643,-81312.8671875,-81287.8203125,57.0846756449868,20.4767904921888,22.529354,0,0,0,40,4449,99.79955,-81300.34375,,,,,,,,,,,,,0,,,,-0.00245,,,,,,100.0052643,,,,
,28172033.92,100.0062714,-86219.41015625,-0.0534527263845138,3.0752677186725E-6,1,0.999253354069792,40.0298881530762,1.99594770449313,27.7299992740154,-0.607021387585456,-0.109237741181922,2.5,-0.000234214452146138,-0.053760099385891,-0.000384811564119893,100.0062714,100.0062714,-86229.328125,-86209.4921875,57.0096393071407,20.4835506236737,22.909004,0,0,0,40,4449,99.7932,-86219.41015625,,,,,,,,,,,,,0,,,,-0.00245,,,,,,100.0062714,,,,
,28172152.125,100.0046387,-89184.65234375,-0.0540940592442626,4.89959926430119E-6,1,0.999253354069792,40.0298881530762,1.99603050573224,27.7299992740154,-0.614330685468259,-0.110559810708382,2.5,-0.000238242523589192,-0.0544053835560709,-0.000390006122478025,100.0046387,100.0046387,-89192.0234375,-89177.28125,57.1503324406022,20.4744514255414,22.909004,0,0,0,40,4449,99.7879,-89184.65234375,,,,,,,,,,,,,0,,,,-0.00245,,,,,,100.0046387,,,,
,28172248.575,100.0006027,-84365.4921875,-0.053109217210414,4.66157209341676E-6,1,0.999253354069792,40.0298881530762,1.99620166327372,27.7299992740154,-0.603197513520614,-0.108516155829542,2.5,-0.000229442859802696,-0.0534144599625894,-0.000379467956187496,100.0006027,100.0006027,-84375.609375,-84355.375,57.2660134614484,20.4739630431686,22.529354,0,0,0,40,4449,99.7893,-84365.4921875,,,,,,,,,,,,,0,,,,-0.00245,,,,,,100.0006027,,,,
,28172345.545,99.9988098,-79518.28125,-0.052047859462336,3.50076735769425E-6,1,0.999253354069792,40.0298881530762,1.99648026577349,27.7299992740154,-0.59121955687863,-0.106345779512577,2.5,-0.000222500571168238,-0.0523465825620983,-0.000370550080345138,99.9988098,99.9988098,-79533.1484375,-79503.4140625,57.322290714833,20.4826510170406,22.529354,0,0,0,40,4449,99.79125,-79518.28125,,,,,,,,,,,,,0,,,,-0.00245,,,,,,99.9988098,,,,
,28172445.14,99.996521,-74541.0703125,-0.0509060392041951,5.42267839741646E-6,1,0.999253354069792,40.0298881530762,1.99579779370141,27.7299992740154,-0.578045088214963,-0.104039837053686,2.5,-0.000222025856103407,-0.0511977653705239,-0.000367893328602442,99.996521,99.996521,-74550.9921875,-74531.1484375,57.2112994651022,20.4898181680321,22.909004,0,0,0,40,4449,99.79385,-74541.0703125,,,,,,,,,,,,,0,,,,-0.00245,,,,,,99.996521,,,,
,28172544.67,99.997673,-69569.0390625,-0.0496744520933843,2.69364816420071E-6,1,0.999253354069792,40.0298881530762,1.99525568030692,27.7299992740154,-0.563895030121441,-0.101576361342512,2.5,-0.000222752631977124,-0.0499586753269819,-0.000366140956767233,99.997673,99.997673,-69574.1875,-69563.890625,57.2167708647368,20.4942979524601,23.288654,0,0,0,40,4449,99.7963,-69569.0390625,,,,,,,,,,,,,0,,,,-0.00245,,,,,,99.997673,,,,
,28172645.015,99.9965973,-64554.76171875,-0.0483716907251822,1.10692806170731E-6,1,0.999253354069792,40.0298881530762,1.9957191021804,27.7299992740154,-0.54922580313446,-0.098919597767285,2.5,-0.00021469818055217,-0.0486480471521438,-0.000355304768476841,99.9965973,99.9965973,-64562.1875,-64547.3359375,57.075296102756,20.4939305529821,22.909004,0,0,0,40,4449,99.80075,-64554.76171875,,,,,,,,,,,,,0,,,,-0.0049,,,,,,99.9965973,,,,
,28172745.53,99.9959564,-59529.642578125,-0.0469648235724806,3.61567196253086E-6,1,0.999253354069792,40.0298881530762,1.99636733336896,27.7299992740154,-0.533423397026832,-0.0960096791828596,2.5,-0.000202052212123603,-0.0472327495195599,-0.000339496784526607,99.9959564,99.9959564,-59539.5703125,-59519.71484375,57.1956668947176,20.4745396728603,22.529354,0,0,0,40,4449,99.80455,-59529.642578125,,,,,,,,,,,,,0,,,,0,,,,,,99.9959564,,,,
,28172843.975,99.994957,-54609.90625,-0.0454705287560411,3.2325070178071E-6,1,0.999253354069792,40.0298881530762,1.99614651611382,27.7299992740154,-0.516393688908603,-0.0929369147878089,2.5,-0.000194066520610626,-0.0457295440417856,-0.000328038007895271,99.994957,99.994957,-54622.25390625,-54597.55859375,57.1753445532176,20.476668811817,22.909004,0,0,0,40,4449,99.80905,-54609.90625,,,,,,,,,,,,,0,,,,0.0049,,,,,,99.994957,,,,
,28172945.51,99.9929504,-49535.56640625,-0.0437908279386608,3.7901613886105E-6,1,0.999253354069792,40.0298881530762,1.99617097570524,27.7299992740154,-0.49731989905756,-0.0895010086071225,2.5,-0.000185737478421712,-0.0440398918700914,-0.000315648108019272,99.9929504,99.9929504,-49545.58984375,-49525.54296875,57.2589788047753,20.4785488069167,22.529354,0,0,0,40,4449,99.81525,-49535.56640625,,,,,,,,,,,,,0,,,,0.00245,,,,,,99.9929504,,,,
,28173044.24,99.9928818,-44600.62109375,-0.0419987630263995,4.4869468473168E-6,1,0.999253354069792,40.0298881530762,1.99578693161639,27.7200005948544,-0.476876127347665,-0.0858228146209655,2.5,-0.00017739975821096,-0.0422372758660834,-0.000302814285820911,99.9928818,99.9928818,-44613.33203125,-44587.91015625,57.3254172289099,20.4846519058571,22.529354,0,0,0,40,4449,99.8231,-44600.62109375,,,,,,,,,,,,,0,,,,0.00245,,,,,,99.9928818,,,,
,28173143.14,99.9920731,-39658.01171875,-0.0400511272897321,3.47209426628501E-6,1,0.999253354069792,40.0298881530762,1.99631384584755,27.7299992740154,-0.454866214666835,-0.0818978063433205,2.5,-0.000171467173968987,-0.0402782266444757,-0.000291864669499632,99.9920731,99.9920731,-39670.53515625,-39645.48828125,57.1135959001984,20.4788983353614,22.909004,0,0,0,40,4449,99.8278,-39658.01171875,,,,,,,,,,,,,0,,,,-0.00245,,,,,,99.9920731,,,,
,28173240.425,99.9935379,-34795.556640625,-0.0378885438947383,2.72619085496541E-6,1,0.999253354069792,40.0298881530762,1.99656616905981,27.7299992740154,-0.430360665240682,-0.0774451363061848,2.5,-0.000158039243490801,-0.0381030730058506,-0.0002726303132742,99.9935379,99.9935379,-34807.97265625,-34783.140625,56.9689946241406,20.4732837446542,23.288654,0,0,0,40,4449,99.83445,-34795.556640625,,,,,,,,,,,,,0,,,,0.00245,,,,,,99.9935379,,,,
,28173338.565,99.9908524,-29891.4423828125,-0.0354469365326688,3.66050255655031E-6,1,0.999253354069792,40.0298881530762,1.99612741367692,27.7299992740154,-0.40253601158739,-0.0724594290145906,2.5,-0.000149020866605335,-0.0356473415291914,-0.00025689952143582,99.9908524,99.9908524,-29901.455078125,-29881.4296875,56.8947399148137,20.4749852250284,23.288654,0,0,0,40,4449,99.8417,-29891.4423828125,,,,,,,,,,,,,0,,,,-0.00245,,,,,,99.9908524,,,,
,28173436.89,99.9914398,-24978.8798828125,-0.0326487976271339,3.17963487565465E-6,1,0.999253354069792,40.0298881530762,1.99643549577072,27.7299992740154,-0.370797447144319,-0.0668311571337396,2.5,-0.000143905757316301,-0.0328330944384797,-0.000243900092538995,99.9914398,99.9914398,-24989.1015625,-24968.658203125,57.0502839901407,20.4712694171584,22.909004,0,0,0,40,4449,99.8529,-24978.8798828125,,,,,,,,,,,,,0,,,,0.00245,,,,,,99.9914398,,,,
,28173533.5,99.9900284,-20149.1259765625,-0.0295330092445238,2.48757625071593E-6,1,0.999253354069792,40.0298881530762,1.99574409477301,27.7299992740154,-0.33531507637602,-0.0603325238238824,2.5,-0.000120833826064957,-0.0296995125609975,-0.00021174927557661,99.9900284,99.9900284,-20156.677734375,-20141.57421875,57.1417345268907,20.4856922281115,22.529354,0,0,0,40,4449,99.8614,-20149.1259765625,,,,,,,,,,,,,0,,,,-0.0049,,,,,,99.9900284,,,,
,28173624.675,99.9911728,-15594.1083984375,-0.0260704012234742,2.6733804079977E-6,1,0.999253354069792,40.0298881530762,1.99586994420486,27.7299992740154,-0.296013768866198,-0.0532778553524135,2.5,-0.000107678932620502,-0.0262171889046144,-0.000188356744264716,99.9911728,99.9911728,-15603.91796875,-15584.298828125,57.1135959001984,20.4768208298262,23.288654,0,0,0,40,4449,99.86815,-15594.1083984375,,,,,,,,,,,,,0,,,,0.00245,,,,,,99.9911728,,,,
,28173717.955,99.9911575,-10928.931640625,-0.0219805540718095,2.09099820972105E-6,1,0.999253354069792,40.0298881530762,1.99648024726432,27.7299992740154,-0.249649506757573,-0.0449188234416176,2.5,-8.92364859320624E-5,-0.0221041621906219,-0.000157589860776016,99.9911575,99.9911575,-10941.3037109375,-10916.5595703125,57.3801312252561,20.4750223740583,23.288654,0,0,0,40,4449,99.87535,-10928.931640625,,,,,,,,,,,,,0,,,,0.00245,,,,,,99.9911575,,,,
,28173811.055,99.9917603,-6275.66259765625,-0.0171216322705744,2.66802580025671E-6,1,0.999253354069792,40.0298881530762,1.9959516386967,27.7200005948544,-0.194406496175266,-0.0350155317645972,2.5,-7.23762721575499E-5,-0.017217794249392,-0.000125879751373691,99.9917603,99.9917603,-6288.3662109375,-6262.958984375,57.3261988574291,20.4923196986998,22.909004,0,0,0,40,4449,99.8829,-6275.66259765625,,,,,,,,,,,,,0,,,,0,,,,,,99.9917603,,,,
,28173904.035,99.9929886,-1629.08819580078,-0.0112338747048086,3.01670346777263E-6,1,0.999253354069792,40.0298881530762,1.99589734896413,27.7299992740154,-0.127551872972473,-0.0229647542301552,2.5,-4.6561821059967E-5,-0.0112969077358352,-8.17979980465002E-5,99.9929886,99.9929886,-1644.24682617187,-1613.92956542969,57.301968373333,20.4868195104662,22.529354,0,0,0,40,4449,99.8895,-1629.08819580078,,,,,,,,,,,,,0,,,,0.00245,,,,,,99.9929886,,,,
,28174002.065,99.9949646,3268.48022460937,-0.002983984955388,4.07461949748117E-6,1,0.999253354069792,40.0298881530762,1.99596881873682,27.7200005948544,-0.0338742209972117,-0.0061188826501334,0.25,-1.40942186581331E-5,-0.00300072849652485,-2.34507112619561E-5,99.9949646,99.9949646,3258.45776367188,3278.50268554687,57.1300100991022,20.4899051470822,22.909004,0,0,0,40,4449,99.89375,3268.48022460937,,,,,,,,,,,,,0,,,,0,,,,,,99.9949646,,,,
,28174094.285,100.00089645,7878.06787109375,0.00540957272470669,4.41282174365248E-6,1,0.999253354069792,40.0298881530762,1.99582827739337,27.7200005948544,0.0614070212489628,0.0110847788892462,0.25,2.49809618776578E-5,0.00543996025639166,4.18697218516757E-5,100.0006027,100.0011902,7862.916015625,7893.2197265625,57.3551191126407,20.4860004088335,22.529354,0,0,0,40,4449,99.8869,7878.06787109375,,,,,,,,,,,,,0,,,,0,,,,,,100.00089645,,,,
,28174189.985,100.0060425,12661.4370117188,0.0140732915696037,4.44134247101327E-6,1,0.999253354069792,40.0298881530762,1.99639930361899,27.7299992740154,0.159831460529613,0.0287792502584275,2.5,5.90283235574623E-5,0.0141524636203705,0.0001027144445101,100.0060425,100.0060425,12656.71875,12666.1552734375,57.3473028274484,20.4839882725159,23.288654,0,0,0,40,4449,99.88475,12661.4370117188,,,,,,,,,,,,,0,,,,0,,,,,,100.0060425,,,,
,28174284.28,100.0074081,17374.0859375,0.0213575390591141,3.9103529142E-6,1,0.999253354069792,40.0298881530762,1.99617190390171,27.7299992740154,0.242531800557279,0.0436867222176425,2.5,9.13247718264453E-5,0.0214778407747666,0.000157290964731103,100.0074081,100.0074081,17364.3359375,17383.8359375,57.1862873524868,20.4919951384756,22.909004,0,0,0,40,4449,99.87715,17374.0859375,,,,,,,,,,,,,0,,,,-0.00245,,,,,,100.0074081,,,,
,28174379.005,100.0093079,22106.38671875,0.0269753648326381,2.99073518192654E-6,1,0.999253354069792,40.0298881530762,1.99665920974478,27.7299992740154,0.306401376820508,0.0551853116945057,2.5,0.000115276586221096,0.0271275151769677,0.000198142920569436,100.0093079,100.0093079,22091.291015625,22121.482421875,57.3004051162945,20.4820858582512,22.909004,0,0,0,40,4449,99.86775,22106.38671875,,,,,,,,,,,,,0,,,,0,,,,,,100.0093079,,,,
,28174476.5,100.0105286,26984.4423828125,0.0313377891886771,3.06735202031317E-6,1,0.999253354069792,40.0298881530762,1.99661001550006,27.7299992740154,0.355945079012055,0.0641181182935659,2.5,0.000135295514230503,0.0315147936504614,0.000231010958694697,100.0105286,100.0105286,26973.9765625,26994.908203125,57.0119841926983,20.475939718557,23.288654,0,0,0,40,4449,99.85855,26984.4423828125,,,,,,,,,,,,,0,,,,0,,,,,,100.0105286,,,,
,28174572.48,100.0093384,31780.125,0.0346886617721275,3.69411768705637E-6,1,0.999253354069792,40.0298881530762,1.99623597873314,27.7299992740154,0.393951157990367,0.070887903680773,2.5,0.000143870750129301,0.0348848944079878,0.000249158384865544,100.0093384,100.0093384,31767.634765625,31792.615234375,57.332451885583,20.4890578141254,23.288654,0,0,0,40,4449,99.85175,31780.125,,,,,,,,,,,,,0,,,,-0.00245,,,,,,100.0093384,,,,
,28174669.96,100.0100861,36652.888671875,0.0375042784837223,2.80799964850336E-6,1,0.999253354069792,40.0298881530762,1.99586962721181,27.7299992740154,0.425846569753246,0.0766846014061059,2.5,0.000161141395311367,0.0377167327905606,0.000274309664172339,100.0100861,100.0100861,36640.34375,36665.43359375,57.1214121853907,20.5039938470069,22.909004,0,0,0,40,4449,99.84085,36652.888671875,,,,,,,,,,,,,0,,,,0,,,,,,100.0100861,,,,
,28174765.63,100.0111656,41434.78515625,0.0398535899157179,3.6096683859521E-6,1,0.999253354069792,40.0298881530762,1.99588279537532,27.7299992740154,0.452529363839281,0.0814851174888991,2.5,0.000171598602036739,0.040079678957957,0.000291117149407838,100.0109253,100.0114059,41427.19921875,41442.37109375,57.2019199228714,20.4994353431395,22.909004,0,0,0,40,4449,99.8314,41434.78515625,,,,,,,,,,,,,0,,,,-0.00245,,,,,,100.0111656,,,,
,28174862.955,100.009964,46298.126953125,0.0419347310382372,3.76044469776786E-6,1,0.999253354069792,40.0298881530762,1.99605939897782,27.7299992740154,0.476220053804687,0.08565953255525,2.5,0.000173558145981066,0.0421730013094398,0.000298475184814589,100.009964,100.009964,46285.57421875,46310.6796875,57.1042163579676,20.4858359054819,22.909004,0,0,0,40,4449,99.8221,46298.126953125,,,,,,,,,,,,,0,,,,0,,,,,,100.009964,,,,
,28174960.01,100.0091095,51148.208984375,0.0437916430311374,2.98665929214713E-6,1,0.999253354069792,40.0298881530762,1.99633648885158,27.7299992740154,0.497362287656684,0.0895523805383749,2.5,0.00018975453056915,0.0440408085896511,0.000319406722205268,100.0091095,100.0091095,51128.41796875,51168,56.9557069393137,20.4879415554733,22.529354,0,0,0,40,4449,99.81325,51148.208984375,,,,,,,,,,,,,0,,,,-0.00245,,,,,,100.0091095,,,,
,28175058.86,100.0106049,56090.2578125,0.0455099932700514,2.56476038971549E-6,1,0.999253354069792,40.0298881530762,1.99658826803466,27.7299992740154,0.516957846652807,0.0930049092900542,2.5,0.000191635096521672,0.0457693387872023,0.000325447079679083,100.0106049,100.0106049,56080.18359375,56100.33203125,57.004167907506,20.4722144181603,22.529354,0,0,0,40,4449,99.80195,56090.2578125,,,,,,,,,,,,,0,,,,-0.00245,,,,,,100.0106049,,,,
,28175156.73,100.0082626,60983.3046875,0.0470565454275729,4.37115074047321E-6,1,0.999253354069792,40.0298881530762,1.99619689790778,27.7299992740154,0.53441550159356,0.0962309784238102,2.5,0.000206359618672445,0.0473250864603522,0.00034382605134536,100.0082626,100.0082626,60978.29296875,60988.31640625,57.0713879601599,20.4909727437936,23.288654,0,0,0,40,4449,99.7988,60983.3046875,,,,,,,,,,,,,0,,,,-0.00245,,,,,,100.0082626,,,,
,28175253.245,100.0077362,65806.234375,0.048450469148541,4.11770310426826E-6,1,0.999253354069792,40.0298881530762,1.9962429930528,27.7299992740154,0.55027154138805,0.0990346068204004,2.5,0.000209019025895199,0.0487273779857508,0.000349593709099452,100.0077362,100.0077362,65791.0234375,65821.4453125,56.9854088230445,20.4866248597983,22.909004,0,0,0,40,4449,99.7901,65806.234375,,,,,,,,,,,,,0,,,,0,,,,,,100.0077362,,,,
,28175350.25,100.0069199,70654.3203125,0.0497713894800828,3.42360486322973E-6,1,0.999253354069792,40.0298881530762,1.99616523547057,27.7200005948544,0.565271649275756,0.101650723105636,2.5,0.000208578675491591,0.0500562834363502,0.000351964003810987,100.0069199,100.0069199,70639.296875,70669.34375,57.1956668947176,20.486810378762,23.288654,0,0,0,40,4449,99.78565,70654.3203125,,,,,,,,,,,,,0,,,,-0.0049,,,,,,100.0069199,,,,
,28175448.735,100.005249,75576.97265625,0.0510148581976037,2.79447541552611E-6,1,0.999253354069792,40.0298881530762,1.99631870708694,27.7200005948544,0.579433562601053,0.104244218852699,2.5,0.000218802983867429,0.0513072867310961,0.000364775550916579,100.005249,100.005249,75567.3046875,75586.640625,56.9744660237753,20.4801226805926,23.288654,0,0,0,40,4449,99.7795,75576.97265625,,,,,,,,,,,,,0,,,,0,,,,,,100.005249,,,,
,28175546.945,100.0070267,80486.0078125,0.0521674051732435,4.94801090501493E-6,1,0.999253354069792,40.0298881530762,1.9962584283421,27.7200005948544,0.592517406981076,0.106566911367204,2.5,0.000222124401917257,0.0524668759349137,0.000370344881454762,100.0070267,100.0070267,80476.1640625,80495.8515625,56.8666012881214,20.4828342789948,22.909004,0,0,0,40,4449,99.772,80486.0078125,,,,,,,,,,,,,0,,,,-0.00245,,,,,,100.0070267,,,,
,28175641.4,100.0059891,85209.16796875,0.053224603754296,1.87293792764623E-6,1,0.999253354069792,40.0298881530762,1.99670373579932,27.7200005948544,0.604647881170976,0.10881143533618,2.5,0.00023300898489814,0.053530552141566,0.000383239077447389,100.0059891,100.0059891,85204.28125,85214.0546875,56.9416376259676,20.4832481708049,22.909004,0,0,0,40,4449,99.7693,85209.16796875,,,,,,,,,,,,,0,,,,0,,,,,,100.0059891,,,,
,28175734.015,100.0059891,89837.453125,0.0542018038230026,2.83448177261819E-6,1,0.999253354069792,40.0298881530762,1.9967621252562,27.7299992740154,0.615776185326434,0.110783947513831,2.5,0.000235739635751522,0.054513792891196,0.000387695441883169,100.0059891,100.0059891,89827.3046875,89847.6015625,56.8564401173714,20.4791406546568,22.909004,0,0,0,40,4449,99.76535,89837.453125,,,,,,,,,,,,,0,,,,0,,,,,,100.0059891,,,,
,28175850.585,100.0013275,85696.73046875,0.0533808623816357,4.34838424861325E-6,1,0.999253354069792,40.0298881530762,1.99658110737099,27.7299992740154,0.60639358331413,0.109092805615396,2.5,0.000230998984648775,0.0536877634774919,0.000381552957450446,100.0013275,100.0013275,85694.171875,85699.2890625,57.2495992625445,20.4898689749978,22.529354,0,0,0,40,4449,99.7669,85696.73046875,,,,,,,,,,,,,0,,,,0,,,,,,100.0013275,,,,
,28175946.04,99.9981232,80923.265625,0.0523504471217389,2.12888369613874E-6,1,0.999253354069792,40.0298881530762,1.99632044931834,27.7200005948544,0.594602711746898,0.107011463499583,2.5,0.000228915740524737,0.0526509965813849,0.000377606032242127,99.9981232,99.9981232,80910.6796875,80935.8515625,57.1440794124484,20.4921440641017,22.909004,0,0,0,40,4449,99.76785,80923.265625,,,,,,,,,,,,,0,,,,-0.00245,,,,,,99.9981232,,,,
,28176041.75,99.9957657,76136.765625,0.0512797006868985,3.51797280809194E-6,1,0.999253354069792,40.0298881530762,1.99701567863538,27.7299992740154,0.582629063059092,0.104861796316533,2.5,0.000223674112685314,0.0515736871426905,0.000370329598658358,99.9957657,99.9957657,76126.6484375,76146.8828125,57.2691399755253,20.4824205043664,22.529354,0,0,0,40,4449,99.76985,76136.765625,,,,,,,,,,,,,0,,,,0,,,,,,99.9957657,,,,
,28176139.205,99.9966278,71268.3046875,0.0501039961723579,4.73174953377233E-6,1,0.999253354069792,40.0298881530762,1.99637671067572,27.7299992740154,0.569101338539959,0.102374479108834,2.5,0.00021306156631432,0.0503908370546913,0.000357325083033929,99.9966278,99.9966278,71253.3125,71283.296875,57.0471574760637,20.4878444212379,22.909004,0,0,0,40,4449,99.7728,71268.3046875,,,,,,,,,,,,,0,,,,0,,,,,,99.9966278,,,,
,28176232.84,99.9961166,66585.0078125,0.0489050319326962,3.7474468889451E-6,1,0.999253354069792,40.0298881530762,1.9964683927635,27.7299992740154,0.555501177913315,0.0999383299759177,2.5,0.000207913058696464,0.0491846142022938,0.00034965990204736,99.9961166,99.9961166,66574.890625,66595.125,57.2324034351214,20.4858350727434,22.909004,0,0,0,40,4449,99.7777,66585.0078125,,,,,,,,,,,,,0,,,,0,,,,,,99.9961166,,,,
,28176327.335,99.9935379,61861.775390625,0.0476306035401903,4.16660629715576E-6,1,0.999253354069792,40.0298881530762,1.99655533875065,27.7299992740154,0.541058661146046,0.0972501289765081,2.5,0.0001939127341923,0.047902536353589,0.000332835361774237,99.9935379,99.9935379,61846.85546875,61876.6953125,57.0409044479099,20.4874501265508,22.909004,0,0,0,40,4449,99.7822,61861.775390625,,,,,,,,,,,,,0,,,,-0.00245,,,,,,99.9935379,,,,
,28176424.37,99.9931641,57011.25390625,0.0462107172016209,4.32069237109043E-6,1,0.999253354069792,40.0298881530762,1.99647338679716,27.7299992740154,0.524882159634782,0.0944741024578196,2.5,0.000198440961087637,0.0464741226680053,0.000334193328269576,99.9931641,99.9931641,56998.87890625,57023.62890625,57.2027015513907,20.4871766316953,22.909004,0,0,0,40,4449,99.7871,57011.25390625,,,,,,,,,,,,,0,,,,0.00245,,,,,,99.9931641,,,,
,28176521.515,99.9929428,52156.17578125,0.044679576836312,4.70967391776974E-6,1,0.999253354069792,40.0298881530762,1.99646798039861,27.7299992740154,0.507488395661818,0.0913246889751368,2.5,0.000189397653708639,0.044933882936231,0.000321514417438158,99.9929428,99.9929428,52151.25,52161.1015625,57.2394380917945,20.4900650317953,23.288654,0,0,0,40,4449,99.7931,52156.17578125,,,,,,,,,,,,,0,,,,0,,,,,,99.9929428,,,,
,28176617.935,99.9930496,47335.939453125,0.0430139167176194,4.29370729405242E-6,1,0.999253354069792,40.0298881530762,1.99609801055476,27.7200005948544,0.488475770373552,0.0879203327276565,2.5,0.000182958976335817,0.0432583767311729,0.000310988003434816,99.9930496,99.9930496,47323.37890625,47348.5,57.0573186468137,20.4863679104914,23.288654,0,0,0,40,4449,99.79835,47335.939453125,,,,,,,,,,,,,0,,,,0.00245,,,,,,99.9930496,,,,
,28176712.54,99.9921875,42610.619140625,0.0412265911067687,2.23348109749357E-6,1,0.999253354069792,40.0298881530762,1.99651079090453,27.7299992740154,0.468265871437565,0.0842899596753293,2.5,0.000175197373666838,0.0414605543216668,0.000298679906356091,99.9921875,99.9921875,42600.6328125,42620.60546875,57.0166739638137,20.4836567564835,22.909004,0,0,0,40,4449,99.80495,42610.619140625,,,,,,,,,,,,,0,,,,0.00245,,,,,,99.9921875,,,,
,28176806.57,99.9912186,37908.1796875,0.0392811923466836,2.94313118168465E-6,1,0.999253354069792,40.0298881530762,1.99631002948803,27.7299992740154,0.446123593787152,0.0803005445085133,2.5,0.000165893826988934,0.0395037996456462,0.000284265677233241,99.9912186,99.9912186,37893.22265625,37923.13671875,57.2785195177561,20.4920768561425,22.909004,0,0,0,40,4449,99.8137,37908.1796875,,,,,,,,,,,,,0,,,,0,,,,,,99.9912186,,,,
,28176901.34,99.9916153,33173.30859375,0.0370952094206799,3.82228363637218E-6,1,0.999253354069792,40.0298881530762,1.99668434151784,27.7299992740154,0.421363085454624,0.0758784142965161,2.5,0.000158941043147192,0.0373051190190187,0.000271417174918181,99.9916153,99.9916153,33155.734375,33190.8828125,57.3676251689484,20.4873104249549,22.909004,0,0,0,40,4449,99.82165,33173.30859375,,,,,,,,,,,,,0,,,,0.00245,,,,,,99.9916153,,,,
,28176997.66,99.9897079,28360.626953125,0.0346152358222425,3.81866385399567E-6,1,0.999253354069792,40.0298881530762,1.99607480776835,27.7299992740154,0.393069892595411,0.0708160506146319,2.5,0.000150472495356024,0.0348108251286271,0.000256068860163666,99.9897079,99.9897079,28353.203125,28368.05078125,57.332451885583,20.4970678689057,23.288654,0,0,0,40,4449,99.83235,28360.626953125,,,,,,,,,,,,,0,,,,-0.0049,,,,,,99.9897079,,,,
,28177092.395,99.9907036,23625.353515625,0.031824617756575,3.9103736424535E-6,1,0.999253354069792,40.0298881530762,1.99622897791982,27.7200005948544,0.361414086118904,0.0650602139502205,2.5,0.000133293239267545,0.0320042019759977,0.000230904652560155,99.9902878,99.9911194,23620.28515625,23630.421875,57.6302523514099,20.491950916607,22.909004,0,0,0,40,4449,99.8415,23625.353515625,,,,,,,,,,,,,0,,,,-0.00245,,,,,,99.9907036,,,,
,28177186.765,99.9920349,18907.947265625,0.0286580554870088,3.099435492548E-6,1,0.999253354069792,40.0298881530762,1.9963045401747,27.7200005948544,0.325466247048879,0.05856693356509,2.5,0.000117655486488866,0.0288195540528082,0.000206031973646699,99.9920349,99.9920349,18898.15625,18917.73828125,57.2034831799099,20.48130265912,23.288654,0,0,0,40,4449,99.84625,18907.947265625,,,,,,,,,,,,,0,,,,0.0049,,,,,,99.9920349,,,,
,28177281.075,99.9904709,14193.2138671875,0.0249372518982377,2.59533240317106E-6,1,0.999253354069792,40.0298881530762,1.99651192022353,27.7299992740154,0.283229585874004,0.0510013096850255,2.5,0.000104939670472789,0.0250775891698695,0.000182262673663859,99.9904709,99.9904709,14180.7080078125,14205.7197265625,57.5638139272753,20.4875851729715,22.529354,0,0,0,40,4449,99.8536,14193.2138671875,,,,,,,,,,,,,0,,,,-0.00245,,,,,,99.9904709,,,,
,28177376.665,99.9920807,9415.71923828125,0.0205044325175828,2.92632231030156E-6,1,0.999253354069792,40.0298881530762,1.99607977038147,27.7299992740154,0.2328317657521,0.0419347723379169,2.5,8.67050408094699E-5,0.020619675356887,0.000150602764015699,99.9920807,99.9920807,9408.2333984375,9423.205078125,57.3574639981984,20.4985726632429,23.288654,0,0,0,40,4449,99.8625,9415.71923828125,,,,,,,,,,,,,0,,,,-0.00245,,,,,,99.9920807,,,,
,28177469.59,99.9932861,4770.0322265625,0.0153735228552326,2.90928427098155E-6,1,0.999253354069792,40.0298881530762,1.99641182815744,27.7299992740154,0.17459879639678,0.0314296689345366,2.5,6.33561544544014E-5,0.0154598348050181,0.000111466409259364,99.9932861,99.9932861,4760.19140625,4779.873046875,57.4661103623715,20.4885379561952,23.288654,0,0,0,40,4449,99.86925,4770.0322265625,,,,,,,,,,,,,0,,,,-0.00245,,,,,,99.9932861,,,,
,28177562.99,99.99326325,101.033950805664,0.00904398797753233,3.60433466133025E-6,1,0.999253354069792,40.0298881530762,1.99611822478095,27.7299992740154,0.102698304024688,0.0184887509387445,2.5,3.73388222968409E-5,0.00909471760816253,6.57405309541736E-5,99.9932022,99.9933243,91.0774078369141,110.990493774414,57.5145713305638,20.488781132727,22.909004,0,0,0,40,4449,99.87335,101.033950805664,,,,,,,,,,,,,0,,,,-0.0049,,,,,,99.99326325,,,,
,28177566.265,99.99339295,-0.0304475463926792,0.00886025636187604,1.75574521016998E-6,1,0.999253354069792,40.0298881530762,1.99625871634311,27.7299992740154,0.100620167261333,0.0181060520688065,2.5,3.58479893066887E-5,0.0089099571471597,6.36696939333554E-5,99.9932022,99.9935837,-0.0304475463926792,-0.0304475463926792,57.3551191126407,20.4873145913353,22.909004,0,0,0,40,4417,99.8731,-0.0304475463926792,,,,,,,,,,,,,0,,,,-0.00245,,,,,,99.99339295,,,,