File: data/monolayers/nanoparticles/Ol_CoFe_C/vsm/data_dispersion/DD67_HYST_150K.DAT
[Header]
; VSM Data File (default extension .dat)
; Copyright (c) 2003-2013, Quantum Design, Inc. All rights reserved.
TITLE,
FILEOPENTIME,28178276.33,11/23/2018,11:18 am
BYAPP,VSM,2.0,2.0
INFO,PPMS VSM Option Release 1.4.10 Build 1,APPNAME
INFO,Quantum Design Linear Motor Servo Controller,MOTOR_MODULE_NAME
INFO,3101-100 M1,MOTOR_HW_VERSION
INFO,MMC1014,MOTOR_SERIAL_NUMBER
INFO,SRV No X-over 01.03.11,MOTOR_SOFTWARE_VERSION
INFO,Quantum Design VSM Detection Module,VSM_MODULE_NAME
INFO,3101-150 F0,VSM_HW_VERSION
INFO,VSM707,VSM_SERIAL_NUMBER
INFO,VSM No X-over 01.02.05 May 20 2008 13:51:47,VSM_SOFTWARE_VERSION
INFO,704,PREAMP_SERIAL_NUMBER
INFO,822,COIL_SERIAL_NUMBER
INFO,0,MOMENT_UNITS
INFO,CoFe2O4,SAMPLE_MATERIAL
INFO,dispersion in ampulle,SAMPLE_COMMENT
INFO,,SAMPLE_MASS
INFO,,SAMPLE_VOLUME
INFO,,SAMPLE_MOLECULAR_WEIGHT
INFO,,SAMPLE_SIZE
INFO,,SAMPLE_SHAPE
DATATYPE,COMMENT,1
DATATYPE,TIME,2
STARTUPAXIS,X,2
STARTUPAXIS,Y1,5
[Data]
Comment,Time Stamp (sec),Temperature (K),Magnetic Field (Oe),Moment (emu),M. Std. Err. (emu),Transport Action,Averaging Time (sec),Frequency (Hz),Peak Amplitude (mm),Center Position (mm),Coil Signal' (mV),Coil Signal" (mV),Range (mV),M. Quad. Signal (emu),M. Raw' (emu),M. Raw" (emu),Min. Temperature (K),Max. Temperature (K),Min. Field (Oe),Max. Field (Oe),Mass (grams),Motor Lag (deg),Pressure (Torr),VSM Status (code),Motor Status (code),Measure Status (code),Measure Count,PPMS Status (code),System Temp. (K),System Field (Oe),Sample Position (deg),Bridge 1 Resistance (ohms),Bridge 1 Excitation (에),Bridge 2 Resistance (ohms),Bridge 2 Excitation (에),Bridge 3 Resistance (ohms),Bridge 3 Excitation (에),Bridge 4 Resistance (ohms),Bridge 4 Excitation (에),Signal 1 Vin (V),Signal 2 Vin (V),Digital Inputs (code),Drive 1 Iout (mA),Drive 1 Ipower (W),Drive 2 Iout (mA),Drive 2 Ipower (W),Pressure (),Map 20 (),Map 21 (),Map 22 (),Map 23 (),Map 24 (),Map 25 (),Map 26 (),Map 27 (),Map 28 (),Map 29 ()
,28178292.27,150.3271637,0.0456713177263737,,,2,,,,27.6000001829863,,,,,,,150.3271637,150.3271637,0.0456713177263737,0.0456713177263737,,,24.427608,,,,-99999999,4369,150.1817,0.0456713177263737,,,,,,,,,,,,,,,,,,,,,,,150.3271637,,,,
,28178439.45,150.1776276,4373.5908203125,0.0114616210487997,3.83920361710951E-6,1,0.999253354069792,40.0298881530762,1.99629886886194,27.5800004601479,0.130137097582721,0.0230250294380937,2.5,3.01212136565095E-5,0.0115176558928652,4.86427337724864E-5,150.1776276,150.1776276,4366.12939453125,4381.05224609375,56.5344091674483,20.4776984147822,24.807261,0,0,0,40,4449,149.9278,4373.5908203125,,,,,,,,,,,,,0,,,,0,,,,,,150.1776276,,,,
,28178531.915,150.097641,8994.8857421875,0.0177244507608597,3.24653656361276E-6,1,0.999253354069792,40.0298881530762,1.99610732328004,27.5800004601479,0.201224698613687,0.035624425966044,2.5,4.84961078108996E-5,0.0178111504353074,7.71049359604231E-5,150.097641,150.097641,8987.6025390625,9002.1689453125,56.4695340003521,20.4841110943562,24.427608,0,0,0,40,4449,149.8675,8994.8857421875,,,,,,,,,,,,,0,,,,0.00245,,,,,,150.097641,,,,
,28178628.4,150.0456085,13815.3881835938,0.022875228752592,3.60872473467001E-6,1,0.999253354069792,40.0298881530762,1.99491878757382,27.5800004601479,0.259551997253531,0.0459634560560266,2.5,6.37704350992523E-5,0.0229871733035666,0.000100618094826552,150.0456085,150.0456085,13805.3916015625,13825.384765625,56.7337244398522,20.504141349395,24.427608,0,0,0,40,4449,149.8452,13815.3881835938,,,,,,,,,,,,,0,,,,-0.0049,,,,,,150.0456085,,,,
,28178725.845,150.0165634,18685.25390625,0.0270382203240943,2.90126368722621E-6,1,0.999253354069792,40.0298881530762,1.99618666994539,27.5800004601479,0.306974016750966,0.0543594066314111,2.5,7.53257195468564E-5,0.027170584668399,0.000118766077574924,150.0163269,150.0167999,18677.701171875,18692.806640625,56.6711941583137,20.4841259677899,24.807261,0,0,0,40,4449,149.84415,18685.25390625,,,,,,,,,,,,,0,,,,-0.00245,,,,,,150.0165634,,,,
,28178818.17,150.0024261,23300.5322265625,0.0302923647780831,4.18002700729536E-6,1,0.999253354069792,40.0298881530762,1.9966582342704,27.5800004601479,0.344006100254234,0.0608657018377285,2.5,8.01305932416992E-5,0.030440706983713,0.000128649951781312,150.0024261,150.0024261,23270.4375,23330.626953125,56.6446187886598,20.4841029158682,24.047956,0,0,0,40,4449,149.84905,23300.5322265625,,,,,,,,,,,,,0,,,,0,,,,,,150.0024261,,,,
,28178912.54,149.9966583,28018.21484375,0.0331305816712946,2.38121983592102E-6,1,0.999253354069792,40.0298881530762,1.99707173880338,27.5800004601479,0.376307800825767,0.0666072611926316,2.5,9.00377730184375E-5,0.0332928575204877,0.000142964643297333,149.9966583,149.9966583,28013.34765625,28023.08203125,56.8908317722176,20.482122751643,24.047956,0,0,0,40,4449,149.85755,28018.21484375,,,,,,,,,,,,,0,,,,-0.0049,,,,,,149.9966583,,,,
,28179005.17,149.9963684,32646.044921875,0.0355685975896996,3.38875689305935E-6,1,0.999253354069792,40.0298881530762,1.99682252638943,27.5800004601479,0.403951946226821,0.0714997834679146,2.5,9.67762324408816E-5,0.0357428505098227,0.000153438204850003,149.9963684,149.9963684,32640.962890625,32651.126953125,56.8001628639868,20.4845235903388,24.427608,0,0,0,40,4449,149.8616,32646.044921875,,,,,,,,,,,,,0,,,,0.0049,,,,,,149.9963684,,,,
,28179096.985,149.9943237,37233.4921875,0.0376973949995023,2.81071628624937E-6,1,0.999253354069792,40.0298881530762,1.99730623033186,27.5800004601479,0.428233227468988,0.0757671460946556,2.5,0.0001001383497023,0.0378821202739343,0.000160010563691243,149.9943237,149.9943237,37223.546875,37243.4375,56.8916134007368,20.4722273418642,24.427608,0,0,0,40,4449,149.86025,37233.4921875,,,,,,,,,,,,,0,,,,-0.00245,,,,,,149.9943237,,,,
,28179188.36,149.9963379,41803.8515625,0.0395923544505888,2.01769142275717E-6,1,0.999253354069792,40.0298881530762,1.99696563040065,27.5800004601479,0.44968781350066,0.0795566824878583,2.5,0.000104806196673451,0.0397864038312881,0.000167503679044192,149.9963379,149.9963379,41796.328125,41811.375,56.8955215433329,20.4818213902793,24.807261,0,0,0,40,4449,149.86265,41803.8515625,,,,,,,,,,,,,0,,,,-0.00245,,,,,,149.9963379,,,,
,28179281.005,149.9997864,46434.419921875,0.0413394377172904,3.44911870220869E-6,1,0.999253354069792,40.0298881530762,1.99670109572222,27.5800004601479,0.469464205358606,0.0831025188747373,2.5,0.000113646421354785,0.0415420820664251,0.000178935569730761,149.9997864,149.9997864,46424.40234375,46444.4375,56.8697278021983,20.4834754831755,24.427608,0,0,0,40,4449,149.8641,46434.419921875,,,,,,,,,,,,,0,,,,0,,,,,,149.9997864,,,,
,28179372.485,150.0005341,51004.57421875,0.0429040176925354,3.88085367376959E-6,1,0.999253354069792,40.0298881530762,1.99672561276623,27.5800004601479,0.487247156380642,0.086197863935727,2.5,0.000113665012103877,0.0431143814278062,0.000181202106369178,150.0005341,150.0005341,51002.0546875,51007.09375,56.8243933480829,20.4848504178977,24.807261,0,0,0,40,4449,149.86375,51004.57421875,,,,,,,,,,,,,0,,,,0,,,,,,150.0005341,,,,
,28179464.665,150.0019684,55612.3828125,0.0443807539071879,3.90174882230796E-6,1,0.999253354069792,40.0298881530762,1.99706487082845,27.5800004601479,0.504091880943956,0.0892270814781764,2.5,0.000121992306996554,0.0445983955228291,0.000191664466887263,150.0019684,150.0019684,55604.8828125,55619.8828125,56.9017745714868,20.4911231156474,24.047956,0,0,0,40,4449,149.8602,55612.3828125,,,,,,,,,,,,,0,,,,0,,,,,,150.0019684,,,,
,28179557.545,150.0042419,60255.275390625,0.0457385685329052,5.16873539009627E-6,1,0.999253354069792,40.0298881530762,1.99661373920582,27.5800004601479,0.519407864853057,0.0919087516741971,2.5,0.000123440664213155,0.0459629176939796,0.000195010672574877,150.0042419,150.0042419,60252.6484375,60257.90234375,56.9400743689291,20.4918763845389,24.427608,0,0,0,40,4449,149.8579,60255.275390625,,,,,,,,,,,,,0,,,,-0.0049,,,,,,150.0042419,,,,
,28179651.525,150.0060577,64950.7890625,0.0470233697115609,4.71670928871932E-6,1,0.999253354069792,40.0298881530762,1.99720730583326,27.5800004601479,0.534155962903145,0.0944838932381867,2.5,0.00012419069779214,0.0472540724239689,0.000197527492176758,150.0060577,150.0060577,64945.87109375,64955.70703125,56.7767140084099,20.4878035385024,24.807261,0,0,0,40,4449,149.85075,64950.7890625,,,,,,,,,,,,,0,,,,0.0049,,,,,,150.0060577,,,,
,28179744.89,150.0062714,69618.66015625,0.0482127076426242,4.15538966093801E-6,1,0.999253354069792,40.0298881530762,1.99700373925573,27.5800004601479,0.547608190647142,0.0968941684331873,2.5,0.000130197325779782,0.0484492920129696,0.000205164724047717,150.0062714,150.0062714,69613.328125,69623.9921875,56.9103724851983,20.4947342951221,24.807261,0,0,0,40,4449,149.846,69618.66015625,,,,,,,,,,,,,0,,,,0,,,,,,150.0062714,,,,
,28179836.955,150.0066681,74221.49609375,0.0493220961515164,2.56098087045826E-6,1,0.999253354069792,40.0298881530762,1.99651282530518,27.5800004601479,0.560082863898288,0.0990723788706011,2.5,0.000130951881178206,0.0495641791703674,0.000207391629503205,150.0066681,150.0066681,74211.3671875,74231.625,56.7610814380252,20.4999765364845,24.427608,0,0,0,40,4449,149.8406,74221.49609375,,,,,,,,,,,,,0,,,,0,,,,,,150.0066681,,,,
,28179927.22,150.0086441,78734.671875,0.0503453036014653,3.12679124288279E-6,1,0.999253354069792,40.0298881530762,1.99663643016376,27.5800004601479,0.571739433938785,0.101116011715776,2.5,0.00013234746673571,0.0505924595298229,0.000210125419437746,150.0085602,150.008728,78699.6171875,78769.7265625,56.912717370756,20.4983472573,24.807261,0,0,0,40,4449,149.83205,78734.671875,,,,,,,,,,,,,0,,,,-0.0049,,,,,,150.0086441,,,,
,28180021.03,150.0067749,83420.81640625,0.0513538026228876,3.85238921599433E-6,1,0.999253354069792,40.0298881530762,1.9967175883522,27.5800004601479,0.583207819723008,0.103190242615185,2.5,0.000139180574210659,0.0516059608247575,0.000218279048747996,150.0067749,150.0067749,83413.2890625,83428.34375,56.6876083572175,20.5010792832832,24.427608,0,0,0,40,4449,149.82495,83420.81640625,,,,,,,,,,,,,0,,,,-0.00245,,,,,,150.0067749,,,,
,28180109.735,150.0085449,87856.58203125,0.0522480217299774,3.03609236901706E-6,1,0.999253354069792,40.0298881530762,1.99655725329538,27.5800004601479,0.593319478318485,0.104972129326873,2.5,0.000141236860986513,0.0525046220027693,0.00022146009010673,150.0085449,150.0085449,87851.71875,87861.4453125,56.7665528376599,20.50153051985,24.047956,0,0,0,40,4449,149.81965,87856.58203125,,,,,,,,,,,,,0,,,,0,,,,,,150.0085449,,,,
,28180212.77,150.0056458,87873.06640625,0.0522670565987022,4.93556380199758E-6,1,0.999253354069792,40.0298881530762,1.99692075262332,27.5800004601479,0.593652870509889,0.104947923554401,2.5,0.000134185167506915,0.0525237652472525,0.000214403599726087,150.0056458,150.0056458,87868.171875,87877.9609375,56.9072459711214,20.4967653888391,24.047956,0,0,0,40,4449,149.81715,87873.06640625,,,,,,,,,,,,,0,,,,-0.00245,,,,,,150.0056458,,,,
,28180303.13,150.0005188,83352.01171875,0.0513544386167569,1.13919998068692E-6,1,0.999253354069792,40.0298881530762,1.99689440568073,27.5800004601479,0.583261181690887,0.103218806900264,2.5,0.000140804670062485,0.0516066043228492,0.000219922390845646,150.0005188,150.0005188,83344.546875,83359.4765625,56.9080275996406,20.498074080985,24.807261,0,0,0,40,4449,149.8161,83352.01171875,,,,,,,,,,,,,0,,,,-0.00245,,,,,,150.0005188,,,,
,28180396.75,149.9950638,78673.21484375,0.0503489243908384,1.92353579138858E-6,1,0.999253354069792,40.0298881530762,1.99724607269661,27.5800004601479,0.571946614293886,0.101157114745173,2.5,0.000132726613783481,0.0505961143637724,0.00021052333579752,149.9950409,149.9950867,78665.5625,78680.8671875,56.8900501436983,20.4924990888287,24.807261,0,0,0,40,4449,149.82095,78673.21484375,,,,,,,,,,,,,0,,,,-0.00245,,,,,,149.9950638,,,,
,28180488.465,149.9948883,74089.1953125,0.0493281404653188,5.50513925999906E-6,1,0.999253354069792,40.0298881530762,1.99669187862697,27.5800004601479,0.560198220506948,0.0991009269129521,2.5,0.000131648089646404,0.0495702652119134,0.000208115772599757,149.9948883,149.9948883,74086.5859375,74091.8046875,56.943200883006,20.4942703001718,24.807261,0,0,0,40,4449,149.8291,74089.1953125,,,,,,,,,,,,,0,,,,0.0049,,,,,,149.9948883,,,,
,28180582.83,149.9913635,69371.16796875,0.0482010062895923,5.24257135409849E-6,1,0.999253354069792,40.0298881530762,1.9969455801372,27.5800004601479,0.547463550159276,0.096849029758736,2.5,0.000128477218115772,0.0484375517877183,0.000203438119379455,149.9913635,149.9913635,69368.7265625,69373.609375,56.8243933480829,20.4954474777766,24.807261,0,0,0,40,4449,149.8358,69371.16796875,,,,,,,,,,,,,0,,,,-0.00245,,,,,,149.9913635,,,,
,28180676.725,149.990921,64677.875,0.0470087286950931,3.83919311814178E-6,1,0.999253354069792,40.0298881530762,1.99674033183636,27.5800004601479,0.533867879550588,0.0944494420273449,2.5,0.000125542696512717,0.0472393734091932,0.000198882312986227,149.990921,149.990921,64670.4375,64685.3125,57.0401228193907,20.4974134188588,24.807261,0,0,0,40,4449,149.84335,64677.875,,,,,,,,,,,,,0,,,,0,,,,,,149.990921,,,,
,28180771.965,149.9904938,59917.224609375,0.0457229535091908,3.78689635452687E-6,1,0.999253354069792,40.0298881530762,1.99661037116429,27.5800004601479,0.519229372712016,0.0918799965854684,2.5,0.000123618060301855,0.0459472386447589,0.000195186889455879,149.9904938,149.9904938,59907.29296875,59927.15625,56.7024592990829,20.4994339509013,24.807261,0,0,0,40,4449,149.8493,59917.224609375,,,,,,,,,,,,,0,,,,0,,,,,,149.9904938,,,,
,28180867.415,149.9890442,55146.515625,0.0443324233829696,3.9835831774577E-6,1,0.999253354069792,40.0298881530762,1.99649989971249,27.5800004601479,0.503402481906015,0.0891323365372465,2.5,0.000124166367760723,0.0445498355602273,0.000193796886277556,149.9890442,149.9890442,55138.890625,55154.140625,57.0565370182945,20.4946659688078,24.427608,0,0,0,40,4449,149.8584,55146.515625,,,,,,,,,,,,,0,,,,0.00245,,,,,,149.9890442,,,,
,28180962.07,149.9886932,50416.484375,0.0428464936368636,5.37394795590684E-6,1,0.999253354069792,40.0298881530762,1.9967853882918,27.5800004601479,0.48661129584618,0.086065200123451,2.5,0.000111768946228225,0.043056587707122,0.000179228199284992,149.9886932,149.9886932,50406.48828125,50426.48046875,56.8275198621599,20.5007152294909,24.427608,0,0,0,40,4449,149.87155,50416.484375,,,,,,,,,,,,,0,,,,0,,,,,,149.9886932,,,,
,28181053.855,149.9907227,45828.7265625,0.041263850351079,3.49032832778206E-6,1,0.999253354069792,40.0298881530762,1.99669738902174,27.5800004601479,0.468604316880661,0.0829546875997351,2.5,0.000113795860568832,0.0414661304213437,0.000178984442193899,149.9907227,149.9907227,45823.79296875,45833.66015625,57.2550706621791,20.4954163237164,24.427608,0,0,0,40,4449,149.8781,45828.7265625,,,,,,,,,,,,,0,,,,-0.00245,,,,,,149.9907227,,,,
,28181147.67,149.9919586,41138.48046875,0.0395045065797099,4.65124313930126E-6,1,0.999253354069792,40.0298881530762,1.99691287178802,27.5800004601479,0.448674779882146,0.079400949370947,2.5,0.00010656495026298,0.039698124063836,0.000169147155357151,149.9919586,149.9919586,41131.046875,41145.9140625,56.9846271945253,20.4935033089023,24.807261,0,0,0,40,4449,149.88375,41138.48046875,,,,,,,,,,,,,0,,,,0.00245,,,,,,149.9919586,,,,
,28181240.945,149.9922485,36478.51953125,0.0375805401524013,3.21665738254254E-6,1,0.999253354069792,40.0298881530762,1.99694672651382,27.5800004601479,0.426830649623204,0.0755295981247438,2.5,0.000100721570597446,0.0377646909192538,0.000160424778233116,149.9922485,149.9922485,36473.328125,36483.7109375,56.8955215433329,20.4959555160419,24.427608,0,0,0,40,4449,149.8884,36478.51953125,,,,,,,,,,,,,0,,,,0,,,,,,149.9922485,,,,
,28181334.225,149.9912415,31813.5439453125,0.0353978965802432,2.78785839431007E-6,1,0.999253354069792,40.0298881530762,1.99702152150147,27.5800004601479,0.402054762027413,0.0711450745475223,2.5,9.46877379011373E-5,0.0355713186713818,0.0001510799336852,149.9912415,149.9912415,31811.05859375,31816.029296875,57.047939104583,20.4956791557415,24.047956,0,0,0,40,4449,149.8961,31813.5439453125,,,,,,,,,,,,,0,,,,0,,,,,,149.9912415,,,,
,28181429.22,149.9905853,27068.5244140625,0.0329100683755264,3.57624738646183E-6,1,0.999253354069792,40.0298881530762,1.99701799711646,27.5800004601479,0.373795312271686,0.0661523662936301,2.5,8.85651320332814E-5,0.0330712701747202,0.000141139852887229,149.9905853,149.9905853,27063.3671875,27073.681640625,56.7352876968906,20.501298111445,24.427608,0,0,0,40,4449,149.90775,27068.5244140625,,,,,,,,,,,,,0,,,,-0.0049,,,,,,149.9905853,,,,
,28181524.34,149.989563,22313.1982421875,0.0300452725360212,3.63666883805296E-6,1,0.999253354069792,40.0298881530762,1.99670404168354,27.5800004601479,0.341205634225256,0.0603822836880447,2.5,8.051145415486E-5,0.0301924147529772,0.00012863658838661,149.989563,149.989563,22310.658203125,22315.73828125,57.0354330482753,20.5042686307272,24.427608,0,0,0,40,4449,149.9158,22313.1982421875,,,,,,,,,,,,,0,,,,-0.00245,,,,,,149.989563,,,,
,28181617.655,149.9928589,17648.03125,0.0267347665145981,2.59783399502688E-6,1,0.999253354069792,40.0298881530762,1.996976858089,27.5800004601479,0.303647008813082,0.0537506708632857,2.5,7.2815595151461E-5,0.0268656674085288,0.000115753121255189,149.9928589,149.9928589,17638.0390625,17658.0234375,57.0620084179291,20.5011004304898,24.807261,0,0,0,40,4449,149.92085,17648.03125,,,,,,,,,,,,,0,,,,-0.00245,,,,,,149.9928589,,,,
,28181710.25,149.991684,13020.4770507813,0.0228908423353603,3.17595154970798E-6,1,0.999253354069792,40.0298881530762,1.99679484813149,27.5800004601479,0.259971004052195,0.0459886278131795,2.5,5.96430930561965E-5,0.0230029080848129,9.64804364477326E-5,149.991684,149.991684,13015.4912109375,13025.462890625,57.0940551872176,20.5032577036691,24.807261,0,0,0,40,4449,149.9307,13020.4770507813,,,,,,,,,,,,,0,,,,-0.00245,,,,,,149.991684,,,,
,28181803.825,149.992691,8342.583984375,0.0181400719131145,2.94296395630656E-6,1,0.999253354069792,40.0298881530762,1.99718496090276,27.5800004601479,0.206053760924272,0.0364569115579722,2.5,4.77275425758674E-5,0.018228863489357,7.69881136350305E-5,149.992691,149.992691,8332.533203125,8352.634765625,56.8329912617945,20.4960331314047,25.186911,0,0,0,40,4449,149.935,8342.583984375,,,,,,,,,,,,,0,,,,-0.00245,,,,,,149.992691,,,,
,28181896.92,149.9924164,3691.61779785156,0.0122807770891525,3.10440695855071E-6,1,0.999253354069792,40.0298881530762,1.99686358266804,27.5800004601479,0.13947567495068,0.0246809342340381,2.5,3.25814380172338E-5,0.0123408795320827,5.24317183476526E-5,149.9924164,149.9924164,3683.9970703125,3699.23852539063,56.9697762526599,20.5005628669873,24.807261,0,0,0,40,4449,149.93955,3691.61779785156,,,,,,,,,,,,,0,,,,0,,,,,,149.9924164,,,,
,28181989.135,149.9941711,-917.589904785156,0.00388397993590777,5.99134188065741E-6,1,0.999253354069792,40.0298881530762,1.99663986537197,27.5800004601479,0.0441073397799762,0.00780028843617284,2.5,9.89451319316268E-6,0.00390298737509033,1.61763722334094E-5,149.9941711,149.9941711,-927.417846679688,-907.761962890625,56.9103724851983,20.4978685027387,24.427608,0,0,0,40,4449,149.94555,-917.589904785156,,,,,,,,,,,,,0,,,,0,,,,,,149.9941711,,,,
,28182081.34,149.99823,-5523.451171875,-0.00788542256532541,5.40031187441696E-6,1,0.999253354069792,40.0298881530762,1.99660298598734,27.5800004601479,-0.0895255431329579,-0.0158910357880945,0.25,-2.51181649552983E-5,-0.00792400836266625,-3.78739859256263E-5,149.99823,149.99823,-5528.37109375,-5518.53125,56.9275683126214,20.4995606641326,24.427608,0,0,0,40,4449,149.9456,-5523.451171875,,,,,,,,,,,,,0,,,,-0.00245,,,,,,149.99823,,,,
,28182177.47,150.0012054,-10329.2734375,-0.0171242251560197,3.53776326350875E-6,1,0.999253354069792,40.0298881530762,1.99697543819504,27.5800004601479,-0.19449450840411,-0.0344162381434385,2.5,-4.54668170585365E-5,-0.0172080459663418,-7.30624079169822E-5,150.0012054,150.0012054,-10331.9208984375,-10326.6259765625,56.8900501436983,20.5033449416412,24.807261,0,0,0,40,4449,149.9426,-10329.2734375,,,,,,,,,,,,,0,,,,-0.00245,,,,,,150.0012054,,,,
,28182271.515,150.0065308,-15029.2397460938,-0.0230866286112488,2.70687618538365E-6,1,0.999253354069792,40.0298881530762,1.99688450553996,27.5800004601479,-0.262203498426343,-0.0463970250949988,2.5,-6.13438849938446E-5,-0.0231996503834373,-9.84613882540191E-5,150.0065308,150.0065308,-15034.60546875,-15023.8740234375,56.9549253107945,20.5007327880724,24.807261,0,0,0,40,4449,149.936,-15029.2397460938,,,,,,,,,,,,,0,,,,0,,,,,,150.0065308,,,,
,28182367.035,150.0093384,-19804.1474609375,-0.0274363293242548,2.22417933392729E-6,1,0.999253354069792,40.0298881530762,1.99707719535095,27.5800004601479,-0.311632865420342,-0.0551480976459979,2.5,-7.33981254406609E-5,-0.027570666955828,-0.000117400488710242,150.0093384,150.0093384,-19811.177734375,-19797.1171875,57.044812590506,20.5001080657083,24.427608,0,0,0,40,4449,149.9283,-19804.1474609375,,,,,,,,,,,,,0,,,,-0.00245,,,,,,150.0093384,,,,
,28182462.22,150.0102081,-24561.46484375,-0.0308620442040611,2.54759807516496E-6,1,0.999253354069792,40.0298881530762,1.9971789561069,27.5800004601479,-0.35055801683508,-0.0620533799391429,2.5,-8.41328462494856E-5,-0.0310131805637208,-0.000133508530409681,150.0102081,150.0102081,-24569.0390625,-24553.890625,56.9572701963522,20.4985218384722,25.186911,0,0,0,40,4449,149.9178,-24561.46484375,,,,,,,,,,,,,0,,,,-0.0049,,,,,,150.0102081,,,,
,28182555.2,150.0104828,-29209.09375,-0.0336811419789547,3.45409277015026E-6,1,0.999253354069792,40.0298881530762,1.99689123888586,27.5800004601479,-0.382530746825324,-0.0676939643268238,2.5,-9.03361436265636E-5,-0.0338461173303728,-0.000144073147671295,150.0101929,150.0107727,-29216.4453125,-29201.7421875,57.1237570709483,20.4996672986726,24.807261,0,0,0,40,4449,149.90705,-29209.09375,,,,,,,,,,,,,0,,,,0,,,,,,150.0104828,,,,
,28182650.575,150.0108948,-33973.947265625,-0.0361311814867134,3.73237059242204E-6,1,0.999253354069792,40.0298881530762,1.99674633916209,27.5800004601479,-0.410331949013722,-0.0725953753051064,2.5,-9.54990125245842E-5,-0.0363081950527016,-0.000152975982922721,150.0108948,150.0108948,-33979.17578125,-33968.71875,57.1104693861214,20.5008146373165,24.427608,0,0,0,40,4449,149.8994,-33973.947265625,,,,,,,,,,,,,0,,,,0.0049,,,,,,150.0108948,,,,
,28182745.41,150.0121994,-38713.9375,-0.0382909438421655,2.90155431095872E-6,1,0.999253354069792,40.0298881530762,1.99714096297798,27.5800004601479,-0.434935959456564,-0.0769853057893167,2.5,-0.000104540397014996,-0.0384785699160546,-0.000165296276491083,150.012085,150.0123138,-38721.5234375,-38706.3515625,57.1409528983714,20.495059131299,24.807261,0,0,0,40,4449,149.8888,-38713.9375,,,,,,,,,,,,,0,,,,0,,,,,,150.0121994,,,,
,28182841.68,150.0099792,-43526.0234375,-0.0402358595564345,2.77476160341253E-6,1,0.999253354069792,40.0298881530762,1.99737523052875,27.5899991393089,-0.457084942292892,-0.0808727422113795,2.5,-0.000107220373132055,-0.0404330638150737,-0.000170860386927401,150.0099792,150.0099792,-43533.09765625,-43518.94921875,57.0119841926983,20.4888054535277,25.186911,0,0,0,40,4449,149.87895,-43526.0234375,,,,,,,,,,,,,0,,,,0.00245,,,,,,150.0099792,,,,
,28182936.94,150.0123901,-48286.171875,-0.0419828098093678,2.90448406804286E-6,1,0.999253354069792,40.0298881530762,1.99694735104253,27.5800004601479,-0.476833750939151,-0.0843653302006712,2.5,-0.000111935526075398,-0.0421886163833147,-0.000178141737148857,150.0123901,150.0123901,-48296.23046875,-48276.11328125,57.2793011462753,20.4954759540807,24.807261,0,0,0,40,4449,149.86735,-48286.171875,,,,,,,,,,,,,0,,,,0,,,,,,150.0123901,,,,
,28183032.035,150.0127716,-53038.359375,-0.0435645200399131,4.55792013990198E-6,1,0.999253354069792,40.0298881530762,1.99716995654061,27.5800004601479,-0.494851670429642,-0.0875533716326293,2.5,-0.000116374358143732,-0.0437781250248352,-0.000184867486048031,150.0127716,150.0127716,-53048.23046875,-53028.48828125,57.0018230219483,20.4933772680539,25.186911,0,0,0,40,4449,149.8577,-53038.359375,,,,,,,,,,,,,0,,,,-0.0049,,,,,,150.0127716,,,,
,28183129.97,150.0145569,-57936.00390625,-0.0450638065445245,2.53044446900143E-6,1,0.999253354069792,40.0298881530762,1.99748728701884,27.5800004601479,-0.511956895726648,-0.0905998286490982,2.5,-0.000122312725062984,-0.045284805857979,-0.000192950055841286,150.0145569,150.0145569,-57945.82421875,-57926.18359375,56.9197520274291,20.4905885577519,24.807261,0,0,0,40,4449,149.8438,-57936.00390625,,,,,,,,,,,,,0,,,,0.00245,,,,,,150.0145569,,,,
,28183225.405,150.0118942,-62706.14453125,-0.0464138992507625,2.45962291234576E-6,1,0.999253354069792,40.0298881530762,1.99725576828281,27.5899991393089,-0.527245077605133,-0.093258587135037,2.5,-0.000122214795035753,-0.0466415786244416,-0.000194720335019591,150.0117645,150.0120239,-62713.45703125,-62698.83203125,56.8955215433329,20.4988006276428,24.807261,0,0,0,40,4449,149.83605,-62706.14453125,,,,,,,,,,,,,0,,,,-0.0049,,,,,,150.0118942,,,,
,28183320.565,150.0113373,-67458.41796875,-0.0476741475939067,4.52635994998188E-6,1,0.999253354069792,40.0298881530762,1.99749261277139,27.5899991393089,-0.541624564210594,-0.0957922213978938,2.5,-0.000124930562992706,-0.0479080612232154,-0.000199167542409351,150.0113373,150.0113373,-67461.0625,-67455.7734375,57.1706547821022,20.4958026494918,24.427608,0,0,0,40,4449,149.8242,-67458.41796875,,,,,,,,,,,,,0,,,,0.0049,,,,,,150.0113373,,,,
,28183417.15,150.0117798,-72287.8203125,-0.0488591539696417,3.11681816403323E-6,1,0.999253354069792,40.0298881530762,1.99760230628086,27.5899991393089,-0.555113881917732,-0.0981967986378264,2.5,-0.000129889424638772,-0.0490989313162537,-0.000205734520475957,150.0117798,150.0117798,-72297.9609375,-72277.6796875,57.1206305568714,20.4922959210359,25.186911,0,0,0,40,4449,149.8124,-72287.8203125,,,,,,,,,,,,,0,,,,0,,,,,,150.0117798,,,,
,28183513.595,150.0104218,-77104.8046875,-0.0499827194300483,3.0712334130484E-6,1,0.999253354069792,40.0298881530762,1.99717254442577,27.5800004601479,-0.567761624237867,-0.100444150667611,2.5,-0.000133986588368119,-0.0502280655320461,-0.000211326344023691,150.0104218,150.0104218,-77109.8828125,-77099.7265625,57.1151591572368,20.4985376647069,24.807261,0,0,0,40,4449,149.8032,-77104.8046875,,,,,,,,,,,,,0,,,,0,,,,,,150.0104218,,,,
,28183609.785,150.0105286,-81914.8125,-0.0510305923818609,4.06295387565612E-6,1,0.999253354069792,40.0298881530762,1.99763399721802,27.5899991393089,-0.579789963952727,-0.102590253057499,2.5,-0.000138604454714618,-0.051281135109245,-0.000217312583021651,150.0105286,150.0105286,-81927.4375,-81902.1875,57.0166739638137,20.4964367968855,24.807261,0,0,0,40,4449,149.79455,-81914.8125,,,,,,,,,,,,,0,,,,-0.00245,,,,,,150.0105286,,,,
,28183705.35,150.009079,-86689.25390625,-0.0520281593105838,4.41428046060568E-6,1,0.999253354069792,40.0298881530762,1.99782172054401,27.5800004601479,-0.591186778896182,-0.104552621605671,2.5,-0.000136954794433717,-0.0522836658807349,-0.000216910622427323,150.009079,150.009079,-86694.1328125,-86684.375,56.9908802226791,20.4917891392561,24.807261,0,0,0,40,4449,149.7901,-86689.25390625,,,,,,,,,,,,,0,,,,0.0049,,,,,,150.009079,,,,
,28183814.07,150.0107117,-88834.94921875,-0.0524588281541343,3.15384608923987E-6,1,0.999253354069792,40.0298881530762,1.99750459506336,27.5800004601479,-0.595983820119696,-0.105439564741719,2.5,-0.000141495144200774,-0.0527164664434391,-0.000222014916253832,150.0107117,150.0107117,-88847.1328125,-88822.765625,57.1886322380445,20.4925421310786,25.186911,0,0,0,40,4449,149.7773,-88834.94921875,,,,,,,,,,,,,0,,,,-0.00245,,,,,,150.0107117,,,,
,28183906.995,150.0036621,-84193.171875,-0.0515324383420925,6.00100156078038E-6,1,0.999253354069792,40.0298881530762,1.99687535265525,27.5800004601479,-0.585280954254517,-0.10355571742442,2.5,-0.000139558557136038,-0.0517854800597164,-0.000218923695691175,150.0036621,150.0036621,-84200.6953125,-84185.6484375,57.1776894387753,20.5075886238098,24.807261,0,0,0,40,4449,149.7756,-84193.171875,,,,,,,,,,,,,0,,,,-0.00245,,,,,,150.0036621,,,,
,28184003.54,149.9971161,-79367.99609375,-0.0505135522184929,3.79103918426065E-6,1,0.999253354069792,40.0298881530762,1.99703045304142,27.5899991393089,-0.573753045892407,-0.101503533131858,2.5,-0.000135467892384898,-0.0507615458610724,-0.000213521532817337,149.9971161,149.9971161,-79373.1875,-79362.8046875,56.9877537086022,20.5007792623511,24.807261,0,0,0,40,4449,149.7796,-79367.99609375,,,,,,,,,,,,,0,,,,0,,,,,,149.9971161,,,,
,28184098.5,149.9930725,-74621.078125,-0.049455736802739,4.0854577081626E-6,1,0.999253354069792,40.0298881530762,1.99698153895653,27.5800004601479,-0.561721939639569,-0.0993889846415859,2.5,-0.000133567301094001,-0.049698487677113,-0.000210241823453598,149.9930725,149.9930725,-74626.0546875,-74616.1015625,57.1167224142753,20.507064391276,25.186911,0,0,0,40,4449,149.78675,-74621.078125,,,,,,,,,,,,,0,,,,0,,,,,,149.9930725,,,,
,28184195.37,149.9914551,-69779.0625,-0.0483143108014235,3.04856035336048E-6,1,0.999253354069792,40.0298881530762,1.99710389197613,27.5800004601479,-0.54879174314451,-0.097085207393813,2.5,-0.000128872584531699,-0.0485514098577323,-0.000204020441371315,149.9914551,149.9914551,-69783.9609375,-69774.1640625,57.0588819038522,20.5098009476665,24.807261,0,0,0,40,4449,149.7903,-69779.0625,,,,,,,,,,,,,0,,,,0,,,,,,149.9914551,,,,
,28184290.735,149.9908447,-65014.388671875,-0.0470995145106409,3.99617992189023E-6,1,0.999253354069792,40.0298881530762,1.99692395071313,27.5800004601479,-0.534941920271291,-0.0946626244282778,2.5,-0.000127751760341763,-0.0473305992599029,-0.000201254056788187,149.9908447,149.9908447,-65026.921875,-65001.85546875,56.8165770628906,20.5027927391373,25.186911,0,0,0,40,4449,149.8017,-65014.388671875,,,,,,,,,,,,,0,,,,0,,,,,,149.9908447,,,,
,28184386.36,149.9917755,-60234.197265625,-0.0458178648038333,4.00358563512464E-6,1,0.999253354069792,40.0298881530762,1.99721676733686,27.5899991393089,-0.520452914772983,-0.0921263727839239,2.5,-0.000126413981926033,-0.0460426077415819,-0.000198153865582725,149.9917755,149.9917755,-60239.25,-60229.14453125,57.2284952925253,20.5005442596732,25.186911,0,0,0,40,4449,149.81115,-60234.197265625,,,,,,,,,,,,,0,,,,-0.00245,,,,,,149.9917755,,,,
,28184482.72,149.9925385,-55419.341796875,-0.0444147605366703,2.97387763225791E-6,1,0.999253354069792,40.0298881530762,1.9972933330519,27.5800004601479,-0.504532627538079,-0.0893088471561261,2.5,-0.000122368488094293,-0.0446325720923059,-0.000192133099018054,149.9925385,149.9925385,-55421.84765625,-55416.8359375,57.1933220091599,20.5025908563115,25.186911,0,0,0,40,4449,149.8162,-55419.341796875,,,,,,,,,,,,,0,,,,0,,,,,,149.9925385,,,,
,28184580.405,149.99291995,-50537.5390625,-0.0428721197076173,3.27021760939851E-6,1,0.999253354069792,40.0298881530762,1.99767314025025,27.5899991393089,-0.487099811457926,-0.086204862619433,2.5,-0.00011635582777667,-0.0430823217059176,-0.000183903135210116,149.9926758,149.9931641,-50544.75,-50530.328125,57.1268835850253,20.497614071475,25.186911,0,0,0,40,4449,149.82265,-50537.5390625,,,,,,,,,,,,,0,,,,0.00245,,,,,,149.99291995,,,,
,28184675.405,149.9925232,-45787.681640625,-0.0412470735155391,2.84311282688738E-6,1,0.999253354069792,40.0298881530762,1.99763275820951,27.5899991393089,-0.468624643528554,-0.0829492485236124,2.5,-0.000112946717389428,-0.0414492635757148,-0.000178136563001504,149.9925232,149.9925232,-45792.7578125,-45782.60546875,57.0526288756983,20.4924549641273,24.807261,0,0,0,40,4449,149.82915,-45787.681640625,,,,,,,,,,,,,0,,,,0,,,,,,149.9925232,,,,
,28184771.915,149.9911041,-40965.142578125,-0.0394459632083833,3.83534585469488E-6,1,0.999253354069792,40.0298881530762,1.99714889163059,27.5899991393089,-0.448057817583531,-0.0793066715783097,2.5,-0.000107646298495047,-0.0396392854859353,-0.000170175026911879,149.9911041,149.9911041,-40975.0625,-40955.22265625,56.994006736756,20.4980410399198,24.427608,0,0,0,40,4449,149.83915,-40965.142578125,,,,,,,,,,,,,0,,,,-0.00245,,,,,,149.9911041,,,,
,28184867.76,149.9909058,-36175.29296875,-0.0374418998237806,2.16030660378555E-6,1,0.999253354069792,40.0298881530762,1.99716609059333,27.5800004601479,-0.425297914304881,-0.0752737875364183,2.5,-0.000101630389706424,-0.0376253628120407,-0.000161155156171415,149.9909058,149.9909058,-36182.94140625,-36167.64453125,57.1565854687561,20.4954541684773,24.807261,0,0,0,40,4449,149.84525,-36175.29296875,,,,,,,,,,,,,0,,,,0.00245,,,,,,149.9909058,,,,
,28184962.445,149.9907379,-31445.9921875,-0.035225223906093,1.83200667297429E-6,1,0.999253354069792,40.0298881530762,1.99746475533118,27.5899991393089,-0.400176979694842,-0.0708199870245064,2.5,-9.48079572248038E-5,-0.0353977925664378,-0.000150959876616363,149.9907379,149.9907379,-31450.966796875,-31441.017578125,57.1010898438907,20.4939676279387,25.186911,0,0,0,40,4449,149.85965,-31445.9921875,,,,,,,,,,,,,0,,,,-0.00245,,,,,,149.9907379,,,,
,28185056.57,149.9905853,-26738.16015625,-0.0327372463791169,2.2856550805559E-6,1,0.999253354069792,40.0298881530762,1.99697556019694,27.5800004601479,-0.37182282679075,-0.0658147706259198,2.5,-8.90497381671652E-5,-0.0328975933123544,-0.000141383919062791,149.9905853,149.9905853,-26743.185546875,-26733.134765625,57.3168193151984,20.5059125467275,24.807261,0,0,0,40,4449,149.8662,-26738.16015625,,,,,,,,,,,,,0,,,,0,,,,,,149.9905853,,,,
,28185150.69,149.991394,-22035.59765625,-0.0298770901864249,2.7130577119714E-6,1,0.999253354069792,40.0298881530762,1.99735649337804,27.5899991393089,-0.339402308668062,-0.0600578924960875,2.5,-7.95844139554057E-5,-0.0300234018967139,-0.000127465209487522,149.991394,149.991394,-22045.6875,-22025.5078125,57.0330881627176,20.5033061670262,25.186911,0,0,0,40,4449,149.87245,-22035.59765625,,,,,,,,,,,,,0,,,,0.00245,,,,,,149.991394,,,,
,28185244.455,149.9933929,-17348.3642578125,-0.0265359203817767,2.9651796328538E-6,1,0.999253354069792,40.0298881530762,1.99695846490801,27.5899991393089,-0.301387035271641,-0.0533435994694727,2.5,-7.16512082168237E-5,-0.0266658429725015,-0.000114290101916887,149.9933929,149.9933929,-17353.408203125,-17343.3203125,57.1300100991022,20.5058020307882,25.186911,0,0,0,40,4449,149.87965,-17348.3642578125,,,,,,,,,,,,,0,,,,0.0049,,,,,,149.9933929,,,,
,28185339.07,149.99150085,-12620.8134765625,-0.0225138685133494,2.65568301843273E-6,1,0.999253354069792,40.0298881530762,1.99737047435794,27.5899991393089,-0.255757025347198,-0.0452608359021206,2.5,-6.0145439478179E-5,-0.0226240814194875,-9.64060734041912E-5,149.991272,149.9917297,-12625.8076171875,-12615.8193359375,57.0620084179291,20.4997116435519,24.807261,0,0,0,40,4449,149.88695,-12620.8134765625,,,,,,,,,,,,,0,,,,0,,,,,,149.99150085,,,,
,28185432.735,149.9918671,-7940.1875,-0.01772890128395,2.87272469839144E-6,1,0.999253354069792,40.0298881530762,1.99733022031022,27.5899991393089,-0.201398991743778,-0.035622745332901,2.5,-4.57240997795627E-5,-0.0178156784203146,-7.43336553675933E-5,149.9918671,149.9918671,-7947.66064453125,-7932.71435546875,57.1003082153714,20.5035460181532,24.807261,0,0,0,40,4449,149.8939,-7940.1875,,,,,,,,,,,,,0,,,,-0.00245,,,,,,149.9918671,,,,
,28185527.67,149.9922333,-3192.17822265625,-0.0115301113318055,3.40959250992748E-6,1,0.999253354069792,40.0298881530762,1.99725998218314,27.5899991393089,-0.13097620657082,-0.0231696012802354,2.5,-2.99555790985531E-5,-0.0115865387248111,-4.85998884679701E-5,149.9922333,149.9922333,-3199.82080078125,-3184.53564453125,57.2707032325638,20.5065248716267,25.186911,0,0,0,40,4449,149.90175,-3192.17822265625,,,,,,,,,,,,,0,,,,-0.00245,,,,,,149.9922333,,,,
,28185623.255,149.9945831,1583.83062744141,-0.00208113678974478,6.37131582782486E-6,1,0.999253354069792,40.0298881530762,1.99706981756207,27.5800004601479,-0.0236343443056025,-0.00418733968345526,0.25,-5.95483760695753E-6,-0.00209132025351434,-9.32464668311705E-6,149.9945831,149.9945831,1581.38854980469,1586.27270507813,57.1769078102561,20.5036140274863,24.427608,0,0,0,40,4449,149.9041,1583.83062744141,,,,,,,,,,,,,0,,,,-0.0049,,,,,,149.9945831,,,,
,28185717.675,149.9975586,6300.87866210937,0.00972443224855688,4.99413477953014E-6,1,0.999253354069792,40.0298881530762,1.9976229760268,27.5800004601479,0.110458339181848,0.0196058192196065,0.25,3.09034519063818E-5,0.00977201709361858,4.66341958512556E-5,149.9975586,149.9975586,6293.2998046875,6308.45751953125,57.3011867448138,20.4993602007442,24.807261,0,0,0,40,4449,149.9075,6300.87866210937,,,,,,,,,,,,,0,,,,0.00245,,,,,,149.9975586,,,,
,28185812.71,150.002121,11049.4252929688,0.0182018207443638,3.90847557524318E-6,1,0.999253354069792,40.0298881530762,1.99713128693822,27.5899991393089,0.206748903655333,0.0365857138168984,2.5,4.84160238647678E-5,0.0182909156051713,7.77487048487222E-5,150.002121,150.002121,11042.015625,11056.8349609375,57.054973761256,20.5033306412558,24.807261,0,0,0,40,4449,149.90525,11049.4252929688,,,,,,,,,,,,,0,,,,-0.00245,,,,,,150.002121,,,,
,28185909.04,150.0066528,15866.6704101562,0.0239330130299361,3.35073913652642E-6,1,0.999253354069792,40.0298881530762,1.99723733331681,27.5899991393089,0.271858309922921,0.0481275581811354,2.5,6.54828640017989E-5,0.0240501758279048,0.000103967690303218,150.0066528,150.0066528,15859.3427734375,15873.998046875,57.0416860764291,20.5066619993733,24.807261,0,0,0,40,4449,149.8971,15866.6704101562,,,,,,,,,,,,,0,,,,-0.00245,,,,,,150.0066528,,,,
,28186006.37,150.00828555,20731.630859375,0.0281963816600875,4.06495942257879E-6,1,0.999253354069792,40.0298881530762,1.99710393757383,27.5800004601479,0.320271959297925,0.0566650787528932,2.5,7.44254448875988E-5,0.0283344441832631,0.000119637438377503,150.0080414,150.0085297,20726.52734375,20736.734375,57.1534589546791,20.5047377265532,25.186911,0,0,0,40,4449,149.8844,20731.630859375,,,,,,,,,,,,,0,,,,-0.0049,,,,,,150.00828555,,,,
,28186102.83,150.0075531,25552.1240234375,0.0315113855871027,3.0529286899068E-6,1,0.999253354069792,40.0298881530762,1.99703152996681,27.5800004601479,0.357909991308841,0.0633467794429846,2.5,8.52314215763337E-5,0.031665707758518,0.000135631574299427,150.0075531,150.0075531,25539.734375,25564.513671875,57.0635716749676,20.5041234059022,25.566563,0,0,0,40,4449,149.8806,25552.1240234375,,,,,,,,,,,,,0,,,,0,,,,,,150.0075531,,,,
,28186200.115,150.0114594,30414.7802734375,0.0343184922444197,2.95493057173338E-6,1,0.999253354069792,40.0298881530762,1.99713337582641,27.5800004601479,0.389812243538033,0.0689961678096996,2.5,9.32318841018286E-5,0.0344865913869679,0.000147969957584583,150.0114594,150.0114594,30407.474609375,30422.0859375,57.0690430746022,20.5032370307589,25.186911,0,0,0,40,4449,149.8725,30414.7802734375,,,,,,,,,,,,,0,,,,0.00245,,,,,,150.0114594,,,,
,28186295.82,150.0106506,35197.3828125,0.0367158322290895,3.71529198748544E-6,1,0.999253354069792,40.0298881530762,1.99777021745173,27.5899991393089,0.417174469851009,0.0738137219798429,2.5,9.77303178767626E-5,0.0368957142112478,0.000156118312707103,150.0106506,150.0106506,35185.31640625,35209.44921875,57.0158923352945,20.4965477021876,24.807261,0,0,0,40,4449,149.8603,35197.3828125,,,,,,,,,,,,,0,,,,0,,,,,,150.0106506,,,,
,28186392.66,150.0109253,40037.18359375,0.0388485029127523,3.36164040477837E-6,1,0.999253354069792,40.0298881530762,1.99770164375372,27.5899991393089,0.441396432344883,0.0780755761620269,2.5,0.000101546585423081,0.0390388759313312,0.00016313583046228,150.0109253,150.0109253,40027.39453125,40046.97265625,56.8556584888522,20.5002596065651,24.807261,0,0,0,40,4449,149.85055,40037.18359375,,,,,,,,,,,,,0,,,,-0.0049,,,,,,150.0109253,,,,
,28186489.35,150.0093689,44870.32421875,0.0407535316547223,2.64471795182526E-6,1,0.999253354069792,40.0298881530762,1.99767638815151,27.5800004601479,0.463029808979984,0.0819403844645226,2.5,0.000109982896464209,0.0409532791188322,0.000174414413233373,150.0093689,150.0093689,44870.32421875,44870.32421875,57.0815491309099,20.5045895592708,24.807261,0,0,0,40,4449,149.8432,44870.32421875,,,,,,,,,,,,,0,,,,0.0049,,,,,,150.0093689,,,,
,28186587.075,150.0120697,49758.380859375,0.0424945849958195,2.71428767056836E-6,1,0.999253354069792,40.0298881530762,1.99756029866925,27.5899991393089,0.482782104149174,0.0854520713019856,2.5,0.00011626972989887,0.0427029051889612,0.000183255984921083,150.0120697,150.0120697,49753.30859375,49763.453125,57.1182856713137,20.5077605147825,25.186911,0,0,0,40,4449,149.8307,49758.380859375,,,,,,,,,,,,,0,,,,0,,,,,,150.0120697,,,,
,28186685.98,150.0107727,54698.09375,0.0440793852769352,3.46751993225729E-6,1,0.999253354069792,40.0298881530762,1.99714943788686,27.5800004601479,0.500690299310031,0.0886159675155673,2.5,0.000120326094895249,0.0442955244791855,0.000189589524650316,150.0107727,150.0107727,54695.71875,54700.46875,56.9979148793522,20.5165530776726,24.807261,0,0,0,40,4449,149.81955,54698.09375,,,,,,,,,,,,,0,,,,0,,,,,,150.0107727,,,,
,28186781.355,150.0126953,59465.88671875,0.0455093486904627,4.70825604757825E-6,1,0.999253354069792,40.0298881530762,1.99726615839602,27.5800004601479,0.516967875329155,0.0914642317152972,2.5,0.000121661325858422,0.0457325490557595,0.000192938209889832,150.0126953,150.0126953,59458.17578125,59473.59765625,56.9392927404099,20.5102978174703,24.427608,0,0,0,40,4449,149.80775,59465.88671875,,,,,,,,,,,,,0,,,,-0.0049,,,,,,150.0126953,,,,
,28186877.33,150.014122,64263.865234375,0.0468308021125926,5.00305370870425E-6,1,0.999253354069792,40.0298881530762,1.99692169811408,27.5800004601479,0.531880063029006,0.0941733690566773,2.5,0.000131468442190026,0.0470605217457875,0.000204615541676267,150.0140686,150.0141754,64256.53515625,64271.1953125,57.0229269919676,20.5178095907114,25.186911,0,0,0,40,4449,149.79455,64263.865234375,,,,,,,,,,,,,0,,,,0.0049,,,,,,150.014122,,,,
,28186972.58,150.011322,69024.2890625,0.0480700065808783,5.13083594730748E-6,1,0.999253354069792,40.0298881530762,1.99762146688107,27.5800004601479,0.546141340152669,0.0966758158377793,2.5,0.000133255402149164,0.0483058629659743,0.000208090256292112,150.011322,150.011322,69019.046875,69029.53125,57.0807675023906,20.5074930705418,24.807261,0,0,0,40,4449,149.7856,69024.2890625,,,,,,,,,,,,,0,,,,-0.00245,,,,,,150.011322,,,,
,28187069.26,150.00944515,73854.46875,0.0492344074016421,2.33212001595908E-6,1,0.999253354069792,40.0298881530762,1.99768878952042,27.5899991393089,0.559397401479172,0.0989735728041232,2.5,0.000132570470490369,0.0494760395381911,0.000208947731924479,150.0090179,150.0098724,73847.171875,73861.765625,57.1417345268907,20.5039984286394,25.186911,0,0,0,40,4449,149.77685,73854.46875,,,,,,,,,,,,,0,,,,-0.00245,,,,,,150.00944515,,,,
,28187167.575,150.0095215,78770.1640625,0.0503565138359673,3.62072217852837E-6,1,0.999253354069792,40.0298881530762,1.99801816950999,27.5899991393089,0.572230857197804,0.101282588697578,2.5,0.000139131059774377,0.0506037038237787,0.000217003405617273,150.0095215,150.0095215,78765.2578125,78775.0703125,57.027616763083,20.5000063764903,24.807261,0,0,0,40,4449,149.7677,78770.1640625,,,,,,,,,,,,,0,,,,0,,,,,,150.0095215,,,,
,28187263.875,150.0113983,83583.34375,0.0513829086403217,1.52221594992099E-6,1,0.999253354069792,40.0298881530762,1.99788592146754,27.5899991393089,0.583862609183942,0.103314723314921,2.5,0.000139957375601171,0.0516351938594123,0.000219142334214113,150.0113983,150.0113983,83573.296875,83593.390625,56.7798405224868,20.5016744090513,25.186911,0,0,0,40,4449,149.75925,83583.34375,,,,,,,,,,,,,0,,,,-0.00245,,,,,,150.0113983,,,,
,28187357.785,150.0097198,88279.07421875,0.052341549085493,4.05064667806488E-6,1,0.999253354069792,40.0298881530762,1.99711682294108,27.5800004601479,0.594541165005633,0.105184152932851,2.5,0.000141111853096319,0.0525986019919801,0.000221502931257692,150.0097198,150.0097198,88271.546875,88286.6015625,57.0299616486406,20.5121981462209,24.807261,0,0,0,40,4449,149.7505,88279.07421875,,,,,,,,,,,,,0,,,,-0.0049,,,,,,150.0097198,,,,
,28187468.805,150.0048828,87061.15234375,0.0521134148471698,2.66700486787049E-6,1,0.999253354069792,40.0298881530762,1.99695608794437,27.5800004601479,0.591903902356784,0.104719606938051,2.5,0.00014059427856899,0.0523693381578215,0.000220711557784006,150.0048828,150.0048828,87053.640625,87068.6640625,56.8071975206598,20.5153130782995,25.186911,0,0,0,40,4449,149.7421,87061.15234375,,,,,,,,,,,,,0,,,,-0.0049,,,,,,150.0048828,,,,
,28187563.46,149.9984131,82327.91796875,0.0511419856315011,4.33842889835425E-6,1,0.999253354069792,40.0298881530762,1.99753673781112,27.5899991393089,0.581032095023124,0.102790199086057,2.5,0.000137202722417365,0.0513930929820679,0.00021608526408353,149.9984131,149.9984131,82325.390625,82330.4453125,56.9815006804483,20.5055144251146,25.186911,0,0,0,40,4449,149.74725,82327.91796875,,,,,,,,,,,,,0,,,,0,,,,,,149.9984131,,,,
,28187661.705,149.994812,77416.30078125,0.0500890567534998,4.54391304508927E-6,1,0.999253354069792,40.0298881530762,1.99790509379406,27.5899991393089,0.569159412120226,0.100747613075731,2.5,0.00013904730770765,0.0503349356238715,0.000216593289155959,149.994812,149.994812,77406.1328125,77426.46875,56.9752476522945,20.5016221141891,25.186911,0,0,0,40,4449,149.75375,77416.30078125,,,,,,,,,,,,,0,,,,0,,,,,,149.994812,,,,
,28187757.305,149.99453735,72637.765625,0.0489934380382191,4.04525937693221E-6,1,0.999253354069792,40.0298881530762,1.9981211989909,27.5899991393089,0.556769112241723,0.0985407848694545,2.5,0.000134592418609417,0.0492338868764619,0.000210688820273639,149.9945221,149.9945526,72632.796875,72642.734375,56.7563916669098,20.4972687000406,25.566563,0,0,0,40,4449,149.7553,72637.765625,,,,,,,,,,,,,0,,,,0,,,,,,149.99453735,,,,
,28187855.115,149.9909058,67750.12890625,0.0477963636055498,4.52175696677522E-6,1,0.999253354069792,40.0298881530762,1.9975342797721,27.5899991393089,0.54301029694893,0.0961191279332328,2.5,0.000132211471089976,0.048030888634253,0.000206696218357037,149.9909058,149.9909058,67745.078125,67755.1796875,56.9791557948906,20.5069754936084,25.186911,0,0,0,40,4449,149.76875,67750.12890625,,,,,,,,,,,,,0,,,,-0.00245,,,,,,149.9909058,,,,
,28187953.565,149.9904633,62829.3359375,0.046525841292192,3.73446194958468E-6,1,0.999253354069792,40.0298881530762,1.99778670437152,27.5800004601479,0.528653066647423,0.0934955380887929,2.5,0.000121445259690587,0.0467540924911619,0.000194152999954206,149.9904633,149.9904633,62821.83203125,62836.83984375,57.2011382943522,20.4957230846569,25.186911,0,0,0,40,4449,149.7789,62829.3359375,,,,,,,,,,,,,0,,,,0.00245,,,,,,149.9904633,,,,
,28188050.37,149.9906235,57991.1640625,0.0451748421230343,4.67354179293819E-6,1,0.999253354069792,40.0298881530762,1.99784154361487,27.5899991393089,0.513295694826151,0.0908945604027121,2.5,0.000127511675063976,0.0453964010588882,0.000198382848919875,149.990448,149.990799,57983.66796875,57998.66015625,56.7524835243137,20.5059134700107,24.807261,0,0,0,40,4449,149.7858,57991.1640625,,,,,,,,,,,,,0,,,,0.00245,,,,,,149.9906235,,,,
,28188146.49,149.991745,53185.76953125,0.043736973303994,4.14491842038241E-6,1,0.999253354069792,40.0298881530762,1.99767055504219,27.5899991393089,0.496928722132071,0.0879262172270463,2.5,0.000117256304043712,0.0439514412608234,0.000186058709794033,149.991745,149.991745,53180.921875,53190.6171875,56.9142806277945,20.5059772084149,25.186911,0,0,0,40,4449,149.7913,53185.76953125,,,,,,,,,,,,,0,,,,0,,,,,,149.991745,,,,
,28188244.57,149.990097,48282.83984375,0.0421196951351282,4.50421577697368E-6,1,0.999253354069792,40.0298881530762,1.99768247593891,27.5899991393089,0.478562525718635,0.0846369661246668,2.5,0.000109337524334976,0.0423261947324379,0.000175786753092642,149.990097,149.990097,48277.94921875,48287.73046875,56.9830639374868,20.5040022658525,25.186911,0,0,0,40,4449,149.8009,48282.83984375,,,,,,,,,,,,,0,,,,0,,,,,,149.990097,,,,
,28188340.355,149.9916382,43495.216796875,0.0404202144051027,2.63331713169451E-6,1,0.999253354069792,40.0298881530762,1.99766558908626,27.5899991393089,0.459240514319307,0.0812692693183907,2.5,0.000108959964821132,0.0406183315358641,0.00017294160172481,149.9916382,149.9916382,43490.484375,43499.94921875,56.9822823089676,20.5026192252925,24.807261,0,0,0,40,4449,149.8083,43495.216796875,,,,,,,,,,,,,0,,,,0,,,,,,149.9916382,,,,
,28188435.655,149.9900665,38730.33203125,0.0385281022443959,2.60944741544459E-6,1,0.999253354069792,40.0298881530762,1.99760408321892,27.5899991393089,0.437721512981691,0.0775096418961708,2.5,0.000107817433549351,0.0387169013754614,0.000169003040562939,149.9900665,149.9900665,38722.92578125,38737.73828125,57.2730481181214,20.5029485342755,25.186911,0,0,0,40,4449,149.81775,38730.33203125,,,,,,,,,,,,,0,,,,-0.00245,,,,,,149.9900665,,,,
,28188529.435,149.9911194,34042.888671875,0.036467418625633,2.81936856710673E-6,1,0.999253354069792,40.0298881530762,1.99750997416225,27.5899991393089,0.414299718544875,0.0733096699662947,2.5,9.7401202481012E-5,0.0366460897238793,0.000155456494492794,149.9911194,149.9911194,34035.4375,34050.33984375,57.1878506095253,20.5081763119143,25.186911,0,0,0,40,4449,149.8252,34042.888671875,,,,,,,,,,,,,0,,,,-0.0049,,,,,,149.9911194,,,,
,28188625.195,149.9890442,29257.7919921875,0.0341211581769095,2.99748648445833E-6,1,0.999253354069792,40.0298881530762,1.99737491643918,27.5899991393089,0.387617142306954,0.0685986851095634,2.5,9.18744015949901E-5,0.0342883008758959,0.000146351213947103,149.9890442,149.9890442,29252.912109375,29262.671875,56.9861904515637,20.5090924081424,25.566563,0,0,0,40,4449,149.83465,29257.7919921875,,,,,,,,,,,,,0,,,,0,,,,,,149.9890442,,,,
,28188721.405,149.9890594,24450.3076171875,0.0313824967544785,3.47242918588705E-6,1,0.999253354069792,40.0298881530762,1.99754301499389,27.5800004601479,0.356530524579158,0.0631187385232737,2.5,8.62083702462412E-5,0.0315361909163218,0.000136458706346702,149.9890594,149.9890594,24445.431640625,24455.18359375,57.1315733561406,20.5067083756743,25.186911,0,0,0,40,4449,149.84385,24450.3076171875,,,,,,,,,,,,,0,,,,-0.0049,,,,,,149.9890594,,,,
,28188817.68,149.9923401,19637.8369140625,0.0282330028225901,3.12363522711293E-6,1,0.999253354069792,40.0298881530762,1.9971668440126,27.5800004601479,0.320692726780734,0.0567683722480667,2.5,7.69419655319077E-5,0.0283712439473649,0.000122267497987618,149.9923401,149.9923401,19627.953125,19647.720703125,57.1268835850253,20.5151064324178,24.807261,0,0,0,40,4449,149.84925,19637.8369140625,,,,,,,,,,,,,0,,,,-0.00245,,,,,,149.9923401,,,,
,28188913.095,149.99049375,14870.5122070313,0.0245444965918854,2.44430928824517E-6,1,0.999253354069792,40.0298881530762,1.99730804943719,27.5800004601479,0.278811739916407,0.0493700803533219,2.5,6.81052596760236E-5,0.0246646544570392,0.000107614263686534,149.9904785,149.990509,14865.4873046875,14875.537109375,57.0526288756983,20.512387657865,24.807261,0,0,0,40,4449,149.8566,14870.5122070313,,,,,,,,,,,,,0,,,,0,,,,,,149.99049375,,,,
,28189009.19,149.99253845,10065.6796875,0.0200035167660795,2.74024938122497E-6,1,0.999253354069792,40.0298881530762,1.99732566731318,27.5800004601479,0.227232193302426,0.0402264776885296,2.5,5.45547793934962E-5,0.0201014276505831,8.68253994135316E-5,149.9922638,149.9928131,10058.005859375,10073.353515625,57.2292769210445,20.5104788890977,25.566563,0,0,0,40,4449,149.86595,10065.6796875,,,,,,,,,,,,,0,,,,0,,,,,,149.99253845,,,,
,28189103.83,149.9904327,5335.51806640625,0.0145621075182326,3.2472271922754E-6,1,0.999253354069792,40.0298881530762,1.99768793120895,27.5899991393089,0.16544896020867,0.0292858554578909,2.5,3.93860086610075E-5,0.0146333744041502,6.29276946703155E-5,149.9904327,149.9904327,5325.427734375,5345.6083984375,57.0182372208522,20.4995689314442,25.566563,0,0,0,40,4449,149.86765,5335.51806640625,,,,,,,,,,,,,0,,,,0,,,,,,149.9904327,,,,
,28189199.43,149.9919968,556.486206054687,0.00723811753934804,4.41890557439488E-6,1,0.999253354069792,40.0298881530762,1.99743034479484,27.5899991393089,0.0822289050276577,0.0145408697465822,2.5,1.83333362423515E-5,0.00727353806878835,3.00485837741529E-5,149.9917908,149.9922028,551.543090820313,561.429321289063,57.1690915250637,20.5085213951328,25.186911,0,0,0,40,4449,149.877,556.486206054687,,,,,,,,,,,,,0,,,,0.00245,,,,,,149.9919968,,,,
,28189212.11,149.9911804,-0.47954885661602,0.00598909820668744,1.71682296399854E-6,1,0.999253354069792,40.0298881530762,1.99760442793204,27.5899991393089,0.0680431853863612,0.0120432819761258,2.5,1.6101708549204E-5,0.0060184049611975,2.58008194205799E-5,149.9909973,149.9913635,-0.487160742282867,-0.471936970949173,57.2027015513907,20.5043904139288,25.566563,0,0,0,40,4417,149.8806,-0.47954885661602,,,,,,,,,,,,,0,,,,-0.0049,,,,,,149.9911804,,,,