File: data/monolayers/nanoparticles/Ol_CoFe_C/vsm/data_dispersion/DD67_HYST_200K.DAT
[Header]
; VSM Data File (default extension .dat)
; Copyright (c) 2003-2013, Quantum Design, Inc. All rights reserved.
TITLE,
FILEOPENTIME,28189935.59,11/23/2018,2:32 pm
BYAPP,VSM,2.0,2.0
INFO,PPMS VSM Option Release 1.4.10 Build 1,APPNAME
INFO,Quantum Design Linear Motor Servo Controller,MOTOR_MODULE_NAME
INFO,3101-100 M1,MOTOR_HW_VERSION
INFO,MMC1014,MOTOR_SERIAL_NUMBER
INFO,SRV No X-over 01.03.11,MOTOR_SOFTWARE_VERSION
INFO,Quantum Design VSM Detection Module,VSM_MODULE_NAME
INFO,3101-150 F0,VSM_HW_VERSION
INFO,VSM707,VSM_SERIAL_NUMBER
INFO,VSM No X-over 01.02.05 May 20 2008 13:51:47,VSM_SOFTWARE_VERSION
INFO,704,PREAMP_SERIAL_NUMBER
INFO,822,COIL_SERIAL_NUMBER
INFO,0,MOMENT_UNITS
INFO,CoFe2O4,SAMPLE_MATERIAL
INFO,dispersion in ampulle,SAMPLE_COMMENT
INFO,,SAMPLE_MASS
INFO,,SAMPLE_VOLUME
INFO,,SAMPLE_MOLECULAR_WEIGHT
INFO,,SAMPLE_SIZE
INFO,,SAMPLE_SHAPE
DATATYPE,COMMENT,1
DATATYPE,TIME,2
STARTUPAXIS,X,2
STARTUPAXIS,Y1,5
[Data]
Comment,Time Stamp (sec),Temperature (K),Magnetic Field (Oe),Moment (emu),M. Std. Err. (emu),Transport Action,Averaging Time (sec),Frequency (Hz),Peak Amplitude (mm),Center Position (mm),Coil Signal' (mV),Coil Signal" (mV),Range (mV),M. Quad. Signal (emu),M. Raw' (emu),M. Raw" (emu),Min. Temperature (K),Max. Temperature (K),Min. Field (Oe),Max. Field (Oe),Mass (grams),Motor Lag (deg),Pressure (Torr),VSM Status (code),Motor Status (code),Measure Status (code),Measure Count,PPMS Status (code),System Temp. (K),System Field (Oe),Sample Position (deg),Bridge 1 Resistance (ohms),Bridge 1 Excitation (에),Bridge 2 Resistance (ohms),Bridge 2 Excitation (에),Bridge 3 Resistance (ohms),Bridge 3 Excitation (에),Bridge 4 Resistance (ohms),Bridge 4 Excitation (에),Signal 1 Vin (V),Signal 2 Vin (V),Digital Inputs (code),Drive 1 Iout (mA),Drive 1 Ipower (W),Drive 2 Iout (mA),Drive 2 Ipower (W),Pressure (),Map 20 (),Map 21 (),Map 22 (),Map 23 (),Map 24 (),Map 25 (),Map 26 (),Map 27 (),Map 28 (),Map 29 ()
,28189952.08,200.2576141,-0.395818114280701,,,2,,,,27.4899998110533,,,,,,,200.2576141,200.2576141,-0.395818114280701,-0.395818114280701,,,25.566563,,,,-99999999,4433,200.2227,-0.395818114280701,,,,,,,,,,,,,,,,,,,,,,,200.2576141,,,,
,28190086.045,200.1873322,4051.74987792969,0.010957827010499,8.99460243230524E-6,1,0.999253354069792,40.0298881530762,1.99746900309776,27.4800006300211,0.116653379057017,0.0660599935351775,2.5,0.00391681195451849,0.0109913314213297,0.00394219877103865,200.1873322,200.1873322,4016.94458007812,4086.55517578125,56.6024108486214,20.4845443368978,25.946213,0,0,0,40,4449,200.0117,4051.74987792969,,,,,,,,,,,,,0,,,,-0.0049,,,,,,200.1873322,,,,
,28190171.02,200.1289063,8296.90966796875,0.0158412899638493,5.00695123194399E-6,1,0.999253354069792,40.0298881530762,1.99678899892053,27.4800006300211,0.168515108947533,0.0958816470803365,2.5,0.00569871760324496,0.0158897236122334,0.00573554253867123,200.1289063,200.1289063,8291.9560546875,8301.86328125,56.6555615879291,20.4993709557831,25.566563,0,0,0,40,4449,199.9392,8296.90966796875,,,,,,,,,,,,,0,,,,0.00245,,,,,,200.1289063,,,,
,28190255.335,200.0812531,12510.2016601562,0.0200545157294315,4.25921098742848E-6,1,0.999253354069792,40.0298881530762,1.99664528967835,27.4700000882149,0.214226301073119,0.116156783429021,2.5,0.00675450756432418,0.0201163726473352,0.00679952977652709,200.0812531,200.0812531,12505.1474609375,12515.255859375,56.8439340610637,20.5039988537018,25.946213,0,0,0,40,4449,199.9001,12510.2016601562,,,,,,,,,,,,,0,,,,0,,,,,,200.0812531,,,,
,28190336.695,200.0484467,16575.98046875,0.0234282605602889,2.74185237847077E-6,1,0.999253354069792,40.0298881530762,1.99637725637307,27.4800006300211,0.250992585510088,0.13131114553285,2.5,0.00750568947251822,0.0235009810087732,0.00755693538955017,200.0484467,200.0484467,16568.4921875,16583.46875,56.6672860157175,20.5086380792715,25.946213,0,0,0,40,4449,199.88225,16575.98046875,,,,,,,,,,,,,0,,,,0,,,,,,200.0484467,,,,
,28190420.565,200.0247498,20768.2890625,0.0263725145458297,4.16014129962371E-6,1,0.999253354069792,40.0298881530762,1.99629720364925,27.4800006300211,0.283113363934677,0.144418447513788,2.5,0.00815021177069277,0.0264547362803392,0.00820683467287403,200.0247498,200.0247498,20760.91015625,20775.66796875,56.7681160946983,20.5132473380974,25.566563,0,0,0,40,4449,199.87505,20768.2890625,,,,,,,,,,,,,0,,,,-0.00245,,,,,,200.0247498,,,,
,28190505.235,200.0113068,25001.5634765625,0.0289242928715887,3.10408607507412E-6,1,0.999253354069792,40.0298881530762,1.99620979199285,27.4800006300211,0.310963943892719,0.155683095748488,2.5,0.00870061256113746,0.0290147620668676,0.00876184997086612,200.0113068,200.0113068,24994.103515625,25009.0234375,56.9103724851983,20.5111502278572,25.946213,0,0,0,40,4449,199.87445,25001.5634765625,,,,,,,,,,,,,0,,,,0,,,,,,200.0113068,,,,
,28190587.58,200.0011139,29117.3251953125,0.0310483677237579,3.52637113858707E-6,1,0.999253354069792,40.0298881530762,1.99629849712268,27.4800006300211,0.33413304013966,0.16528792468103,2.5,0.00917783498405214,0.0311456886747387,0.00924296414488998,200.0011139,200.0011139,29107.548828125,29127.1015625,57.1112510146407,20.5134051422721,26.325863,0,0,0,40,4449,199.8768,29117.3251953125,,,,,,,,,,,,,0,,,,0.00245,,,,,,200.0011139,,,,
,28190671.155,199.996994,33295.291015625,0.0329532207199488,3.22414832518432E-6,1,0.999253354069792,40.0298881530762,1.99615800478207,27.4800006300211,0.35475829781841,0.174557220068184,2.5,0.00966518109053786,0.0330566240258486,0.00973399028038152,199.996994,199.996994,33290.54296875,33300.0390625,56.9033378285253,20.5141686522879,25.946213,0,0,0,40,4449,199.8802,33295.291015625,,,,,,,,,,,,,0,,,,0.00245,,,,,,199.996994,,,,
,28190756.29,199.9965515,37547.8125,0.0347161990495005,5.3304405014728E-6,1,0.999253354069792,40.0298881530762,1.99649626742603,27.4800006300211,0.374121002871948,0.18206844847823,2.5,0.0100186170690244,0.0348253386596637,0.0100904813015808,199.9965515,199.9965515,37542.56640625,37553.05859375,57.0033862789868,20.5117436681783,26.325863,0,0,0,40,4449,199.885,37547.8125,,,,,,,,,,,,,0,,,,0,,,,,,199.9965515,,,,
,28190839.85,199.9955597,41723.2578125,0.0363060509724985,4.53420786559814E-6,1,0.999253354069792,40.0298881530762,1.99661665571818,27.4800006300211,0.391515765631751,0.189042578922699,2.5,0.0103563150143357,0.0364203488704454,0.0104309880434051,199.9955597,199.9955597,41710.86328125,41735.65234375,56.8501870892175,20.5099654312224,26.325863,0,0,0,40,4449,199.89075,41723.2578125,,,,,,,,,,,,,0,,,,-0.00245,,,,,,199.9955597,,,,
,28190925.51,199.9959564,46006.40234375,0.0377921706789398,4.66704313483234E-6,1,0.999253354069792,40.0298881530762,1.99640149582659,27.4700000882149,0.407859181109202,0.194693225638463,2.5,0.0105980752965439,0.0379113721298789,0.0106751075080334,199.9959564,199.9959564,45998.734375,46014.0703125,56.9346029692945,20.5120014423669,25.946213,0,0,0,40,4449,199.88925,46006.40234375,,,,,,,,,,,,,0,,,,0,,,,,,199.9959564,,,,
,28191010.365,199.999176,50249.517578125,0.0391023376554913,9.58590971670682E-6,1,0.999253354069792,40.0298881530762,1.99651771839086,27.4800006300211,0.422103585977725,0.200987003373001,2.5,0.0109243937357776,0.0392257432285761,0.0110038813761122,199.999176,199.999176,50246.89453125,50252.140625,56.9815006804483,20.515849084497,25.946213,0,0,0,40,4449,199.8921,50249.517578125,,,,,,,,,,,,,0,,,,0,,,,,,199.999176,,,,
,28191095.055,199.9998245,54482.677734375,0.0403955590041023,3.93973223694738E-6,1,0.999253354069792,40.0298881530762,1.9968923063878,27.4800006300211,0.436566995438363,0.205225190335781,2.5,0.0110701891205522,0.0405233076259775,0.0111514866999462,199.9992523,200.0003967,54475.08984375,54490.265625,57.0369963053137,20.5127841016024,25.946213,0,0,0,40,4449,199.89115,54482.677734375,,,,,,,,,,,,,0,,,,0.00245,,,,,,199.9998245,,,,
,28191179.265,200.0011749,58690.36328125,0.0414942872623246,4.91194106501438E-6,1,0.999253354069792,40.0298881530762,1.99647696593787,27.4800006300211,0.448261670103765,0.211289052863952,2.5,0.0114175259636471,0.0416254929942805,0.0115011172733571,200.0011749,200.0011749,58687.8515625,58692.875,57.0526288756983,20.5160328539465,25.946213,0,0,0,40,4449,199.89005,58690.36328125,,,,,,,,,,,,,0,,,,-0.0049,,,,,,200.0011749,,,,
,28191263.36,200.0019379,62891.240234375,0.0425803949784784,5.61906675114977E-6,1,0.999253354069792,40.0298881530762,1.99640835235443,27.4800006300211,0.460250307302745,0.215256906353465,2.5,0.0115793408828664,0.0427152145288464,0.0116645662403503,200.0019379,200.0019379,62886.21484375,62896.265625,57.1237570709483,20.5182089941421,25.946213,0,0,0,40,4449,199.8917,62891.240234375,,,,,,,,,,,,,0,,,,-0.0049,,,,,,200.0019379,,,,
,28191346.24,200.0065155,67034.1015625,0.0436419718543517,4.31690430272383E-6,1,0.999253354069792,40.0298881530762,1.99688696453886,27.4800006300211,0.472168185517192,0.218744571534648,2.5,0.0116980698876037,0.0437803600168425,0.0117847528927636,200.0065155,200.0065155,67029.125,67039.078125,56.9236601700253,20.5148829151054,25.946213,0,0,0,40,4449,199.87935,67034.1015625,,,,,,,,,,,,,0,,,,0.00245,,,,,,200.0065155,,,,
,28191430.13,200.0090485,71226.8515625,0.044555785160365,9.31257949298306E-6,1,0.999253354069792,40.0298881530762,1.9961324563227,27.4800006300211,0.481956988212586,0.222808930614244,2.5,0.0119047122950712,0.0446971438040913,0.0119929930687835,200.0090485,200.0090485,71216.8828125,71236.8203125,56.9815006804483,20.5227912756442,25.946213,0,0,0,40,4449,199.87565,71226.8515625,,,,,,,,,,,,,0,,,,0,,,,,,200.0090485,,,,
,28191514.66,200.0103912,75455.26171875,0.0455155179970152,4.92602465064194E-6,1,0.999253354069792,40.0298881530762,1.99670945882721,27.4800006300211,0.492865544164496,0.225419786469518,2.5,0.011962809481949,0.0456601657194149,0.0120522199782413,200.0103912,200.0103912,75445.015625,75465.5078125,56.976810909333,20.5152968369239,25.566563,0,0,0,40,4449,199.8675,75455.26171875,,,,,,,,,,,,,0,,,,-0.00245,,,,,,200.0103912,,,,
,28191599.375,200.0095673,79688.359375,0.0463864497016126,4.18960992027628E-6,1,0.999253354069792,40.0298881530762,1.99670794770281,27.4800006300211,0.502343571218506,0.229462096571298,2.5,0.0121679220581244,0.0465339289052375,0.0122588731876205,200.0095673,200.0095673,79683.578125,79693.140625,56.9979148793522,20.5196411741993,26.325863,0,0,0,40,4449,199.8589,79688.359375,,,,,,,,,,,,,0,,,,0,,,,,,200.0095673,,,,
,28191684.495,200.0089111,83944.90234375,0.0472010116376868,6.16019877047763E-6,1,0.999253354069792,40.0298881530762,1.99646327083802,27.4800006300211,0.511147049187669,0.233225382486675,2.5,0.0123606271046595,0.0473511423959686,0.012453011432851,200.0089111,200.0089111,83942.359375,83947.4453125,56.8189219484483,20.5219515103242,25.946213,0,0,0,40,4449,199.85265,83944.90234375,,,,,,,,,,,,,0,,,,0,,,,,,200.0089111,,,,
,28191763.045,200.0110779,87868.30078125,0.0480366472742112,6.33789546847272E-6,1,0.999253354069792,40.0298881530762,1.99650056121801,27.4800006300211,0.520617454953253,0.234988790638334,2.5,0.0123706586746886,0.0481896878524896,0.0124638702248514,200.0110779,200.0110779,87860.6953125,87875.90625,56.7853119221214,20.5214924795876,26.325863,0,0,0,40,4449,199.8439,87868.30078125,,,,,,,,,,,,,0,,,,0,,,,,,200.0110779,,,,
,28191860.495,200.0089569,88170.47265625,0.0480503505654475,6.64283838673011E-6,1,0.999253354069792,40.0298881530762,1.99639330609912,27.4800006300211,0.520603108898665,0.235828212219068,2.5,0.0124433363894157,0.0482033675303436,0.0125368096639539,200.0089569,200.0089569,88162.9765625,88177.96875,56.9346029692945,20.5229990384357,25.946213,0,0,0,40,4449,199.8368,88170.47265625,,,,,,,,,,,,,0,,,,0,,,,,,200.0089569,,,,
,28191941.585,200.0059204,84116.87109375,0.0472237566863688,7.12724619280362E-6,1,0.999253354069792,40.0298881530762,1.99540828757323,27.4800006300211,0.511169798529733,0.233022433213654,2.5,0.0123491510797283,0.0473739826615017,0.0124415212502017,200.0059204,200.0059204,84109.3515625,84124.390625,57.3457395704099,20.5354293868394,26.325863,0,0,0,40,4449,199.8383,84116.87109375,,,,,,,,,,,,,0,,,,-0.00245,,,,,,200.0059204,,,,
,28192027.35,199.9952698,79830.48046875,0.0464056011765174,5.41075616984444E-6,1,0.999253354069792,40.0298881530762,1.99649525256179,27.4800006300211,0.502580810792217,0.229068878347837,2.5,0.0121319821066642,0.04655320568376,0.0122228367394938,199.9952698,199.9952698,79825.3671875,79835.59375,57.0659165605253,20.5242471969544,26.325863,0,0,0,40,4449,199.842,79830.48046875,,,,,,,,,,,,,0,,,,-0.0049,,,,,,199.9952698,,,,
,28192110.9,199.99263,75653.9765625,0.0454583107537254,5.04728141710389E-6,1,0.999253354069792,40.0298881530762,1.99643868611542,27.4800006300211,0.491910015963543,0.22667736728944,2.5,0.0120861532052169,0.0456026570095882,0.0121759372122219,199.99263,199.99263,75646.6015625,75661.3515625,57.1362631272561,20.5233553622529,26.705515,0,0,0,40,4449,199.8506,75653.9765625,,,,,,,,,,,,,0,,,,0,,,,,,199.99263,,,,
,28192195.41,199.9896393,71428.07421875,0.0445418074083566,4.58256179322571E-6,1,0.999253354069792,40.0298881530762,1.996653785812,27.4800006300211,0.48189586926658,0.222969341161274,2.5,0.0119163694855917,0.0446831338038072,0.0120046839963695,199.9896393,199.9896393,71422.9453125,71433.203125,57.1628384969099,20.5186504558749,25.946213,0,0,0,40,4449,199.85875,71428.07421875,,,,,,,,,,,,,0,,,,0,,,,,,199.9896393,,,,
,28192279.585,199.9901886,67219.9375,0.0435524415426684,5.77632884928752E-6,1,0.999253354069792,40.0298881530762,1.99669280191918,27.4800006300211,0.471080422699182,0.21871129288067,2.5,0.0117124641740961,0.0436905287842097,0.0117991080463865,199.9901886,199.9901886,67214.84375,67225.03125,56.997133250833,20.5166353300411,25.946213,0,0,0,40,4449,199.86695,67219.9375,,,,,,,,,,,,,0,,,,0,,,,,,199.9901886,,,,
,28192362.21,199.9895477,63091.712890625,0.0425259200716785,6.3328183407487E-6,1,0.999253354069792,40.0298881530762,1.99655823619647,27.4700000882149,0.459624276336337,0.215402002222043,2.5,0.0116002218520196,0.042660546207841,0.0116854673692487,199.9895477,199.9895477,63086.7890625,63096.63671875,57.1690915250637,20.5234061679329,26.705515,0,0,0,40,4449,199.87315,63091.712890625,,,,,,,,,,,,,0,,,,0.0049,,,,,,199.9895477,,,,
,28192446.195,199.9917755,58892.884765625,0.0413959660364911,3.21748831233755E-6,1,0.999253354069792,40.0298881530762,1.99674684321274,27.4800006300211,0.447077639061455,0.211850427138812,2.5,0.011481668558756,0.0415267768949229,0.0115653800773748,199.9917755,199.9917755,58888.0234375,58897.74609375,57.0917103016599,20.5211007874408,26.325863,0,0,0,40,4449,199.8771,58892.884765625,,,,,,,,,,,,,0,,,,-0.0049,,,,,,199.9917755,,,,
,28192529.635,199.9848938,54722.3359375,0.040246326524757,6.26182417142509E-6,1,0.999253354069792,40.0298881530762,1.99663389239493,27.4800006300211,0.434603994004568,0.20615038259371,2.5,0.0111798795103797,0.0403734646204142,0.0112613979275733,199.9848938,199.9848938,54709.74609375,54734.92578125,57.3785679682176,20.5179253945213,26.325863,0,0,0,40,4449,199.89255,54722.3359375,,,,,,,,,,,,,0,,,,-0.0049,,,,,,199.9848938,,,,
,28192614.68,199.986969,50472.169921875,0.0389455177004189,6.23099830565044E-6,1,0.999253354069792,40.0298881530762,1.99654378700946,27.4800006300211,0.420169156432382,0.201605821725603,2.5,0.0110059485670945,0.0390683122634455,0.0110855503936987,199.986969,199.986969,50462.34765625,50481.9921875,57.2652318329291,20.5194976410609,26.705515,0,0,0,40,4449,199.89535,50472.169921875,,,,,,,,,,,,,0,,,,0.00245,,,,,,199.986969,,,,
,28192700.605,199.9878998,46176.5234375,0.0376507278709105,3.37026665679136E-6,1,0.999253354069792,40.0298881530762,1.99669901317922,27.4800006300211,0.40625621205128,0.194766245651999,2.5,0.01062663664059,0.0377694231453912,0.0107036125797687,199.9878998,199.9878998,46169.109375,46183.9375,57.393418910083,20.5174141673935,25.946213,0,0,0,40,4449,199.905,46176.5234375,,,,,,,,,,,,,0,,,,-0.0049,,,,,,199.9878998,,,,
,28192784.12,199.9896545,42000.85546875,0.0361074741726597,5.2657147285088E-6,1,0.999253354069792,40.0298881530762,1.99654888464838,27.4800006300211,0.388876920407274,0.190794817119672,2.5,0.0105457918705059,0.036220894469009,0.0106208993693136,199.9896545,199.9896545,41995.82421875,42005.88671875,57.1683098965445,20.5205423716512,26.325863,0,0,0,40,4449,199.9128,42000.85546875,,,,,,,,,,,,,0,,,,0.00245,,,,,,199.9896545,,,,
,28192868.89,199.987793,37765.67578125,0.0345540610297941,5.59616544334912E-6,1,0.999253354069792,40.0298881530762,1.99682998015747,27.4800006300211,0.372099812791579,0.183167140684284,2.5,0.010141049349171,0.0346625243719479,0.0102131542593435,199.987793,199.987793,37763.11328125,37768.23828125,57.0846756449868,20.5125529554347,26.705515,0,0,0,40,4449,199.9213,37765.67578125,,,,,,,,,,,,,0,,,,0,,,,,,199.987793,,,,
,28192951.11,199.9879913,33655.33984375,0.0329058971186937,4.20890157341474E-6,1,0.999253354069792,40.0298881530762,1.99712209171133,27.4800006300211,0.354263047166147,0.17524635934242,2.5,0.00972704334391214,0.0330090869078924,0.00979600387586691,199.9879913,199.9879913,33650.19921875,33660.48046875,57.2605420618137,20.516242317844,26.705515,0,0,0,40,4449,199.9257,33655.33984375,,,,,,,,,,,,,0,,,,0,,,,,,199.9879913,,,,
,28193035.495,199.9885712,29440.1630859375,0.0309603641982479,3.8799120835485E-6,1,0.999253354069792,40.0298881530762,1.99669511038854,27.4800006300211,0.332773558805747,0.167590321715947,2.5,0.00939328631423812,0.0310571691914632,0.00945905347816806,199.9885712,199.9885712,29432.673828125,29447.65234375,57.2417829773522,20.5196913865476,25.946213,0,0,0,40,4449,199.9331,29440.1630859375,,,,,,,,,,,,,0,,,,0,,,,,,199.9885712,,,,
,28193120.425,199.9911499,25194.75,0.0288271800690388,3.86478486916516E-6,1,0.999253354069792,40.0298881530762,1.99645718789233,27.4700000882149,0.309589798792058,0.157292077301644,2.5,0.00885768363672423,0.0289171705845453,0.00891935023764457,199.9911499,199.9911499,25189.6015625,25199.8984375,57.4926857320253,20.5233100177813,26.325863,0,0,0,40,4449,199.9401,25194.75,,,,,,,,,,,,,0,,,,-0.0049,,,,,,199.9911499,,,,
,28193204.19,199.9907074,21009.314453125,0.0263766083550553,3.6760042529875E-6,1,0.999253354069792,40.0298881530762,1.99560484781226,27.4700000882149,0.282701181824986,0.146482023863349,2.5,0.00833568356218001,0.0264586807627436,0.00839294568715782,199.9907074,199.9907074,21006.689453125,21011.939453125,57.1675282680253,20.531917468801,25.946213,0,0,0,40,4449,199.9487,21009.314453125,,,,,,,,,,,,,0,,,,0.0049,,,,,,199.9907074,,,,
,28193287.31,199.9925385,16854.3232421875,0.0236478195081685,3.30841225675657E-6,1,0.999253354069792,40.0298881530762,1.99600305530725,27.4800006300211,0.25329902832009,0.132523789811807,2.5,0.00757652787572398,0.0237212708732739,0.0076282572558087,199.9925385,199.9925385,16849.37109375,16859.275390625,57.1456426694868,20.5264161116381,26.705515,0,0,0,40,4449,199.94975,16854.3232421875,,,,,,,,,,,,,0,,,,-0.00245,,,,,,199.9925385,,,,
,28193370.875,199.9912109,12676.6352539062,0.0203390685356637,3.09876134323874E-6,1,0.999253354069792,40.0298881530762,1.9963183208024,27.4800006300211,0.217451137985613,0.116529138385226,2.5,0.00673948476880661,0.0204019879682986,0.00678477542225018,199.9912109,199.9912109,12666.716796875,12686.5537109375,57.1573670972753,20.5168782146982,26.705515,0,0,0,40,4449,199.9537,12676.6352539062,,,,,,,,,,,,,0,,,,0,,,,,,199.9912109,,,,
,28193453.33,199.9932556,8555.91796875,0.0164923580077151,3.24404527941359E-6,1,0.999253354069792,40.0298881530762,1.9967211751577,27.4800006300211,0.175968795800148,0.0967526059105238,2.5,0.00566263357430943,0.0165431510040836,0.00570006263156949,199.9932556,199.9932556,8553.5224609375,8558.3134765625,57.2441278629099,20.5174738498966,26.325863,0,0,0,40,4449,199.95525,8555.91796875,,,,,,,,,,,,,0,,,,0,,,,,,199.9932556,,,,
,28193535.69,199.9925995,4440.3369140625,0.0116645633019849,3.60887951832756E-6,1,0.999253354069792,40.0298881530762,1.99595713745353,27.4800006300211,0.123687838278458,0.0725749052100146,2.5,0.00437262112402532,0.0117000820953744,0.00440037588105422,199.9925995,199.9925995,4430.39599609375,4450.27783203125,57.3215090863138,20.5280387223878,26.325863,0,0,0,40,4449,199.96585,4440.3369140625,,,,,,,,,,,,,0,,,,0,,,,,,199.9925995,,,,
,28193616.42,199.9908905,403.729156494141,0.00436393531461819,1.14931447615871E-5,1,0.999253354069792,40.0298881530762,1.99600062801805,27.4800006300211,0.0465137301984997,0.0257772897186876,2.5,0.00151465744253648,0.00437735333220209,0.00152462661580182,199.9908905,199.9908905,396.344512939453,411.113800048828,57.5090999309292,20.5271766394051,26.325863,0,0,0,40,4449,199.97275,403.729156494141,,,,,,,,,,,,,0,,,,0.00245,,,,,,199.9908905,,,,
,28193703.41,199.9945221,-3939.20556640625,-0.0110035687183937,1.29810120993337E-5,1,0.999253354069792,40.0298881530762,1.9963109114501,27.4800006300211,-0.116684395966395,-0.0685554331821712,2.5,-0.00413202589437169,-0.0110370658747674,-0.00415823313593018,199.9945221,199.9945221,-3946.62622070313,-3931.78491210937,57.3168193151984,20.5273969664076,26.325863,0,0,0,40,4449,199.97665,-3939.20556640625,,,,,,,,,,,,,0,,,,-0.0049,,,,,,199.9945221,,,,
,28193786.055,200.0005798,-8073.45654296875,-0.0157920931507439,3.84118159640781E-6,1,0.999253354069792,40.0298881530762,1.99642692388754,27.4800006300211,-0.168175837084417,-0.0943447631860597,2.5,-0.0055732208382305,-0.0158405615604203,-0.00560958129900092,200.0005798,200.0005798,-8076.02197265625,-8070.89111328125,57.4246840508522,20.5244443175507,26.325863,0,0,0,40,4449,199.97185,-8073.45654296875,,,,,,,,,,,,,0,,,,0,,,,,,200.0005798,,,,
,28193868.04,200.0052185,-12169.7905273437,-0.0197911951833924,1.4065925630981E-6,1,0.999253354069792,40.0298881530762,1.99648595199002,27.4800006300211,-0.211496428447136,-0.114056034423005,2.5,-0.0066158349933013,-0.0198523469697914,-0.00666010425204461,200.0052185,200.0052185,-12179.81640625,-12159.7646484375,57.423902422333,20.5215434792534,25.946213,0,0,0,40,4449,199.9657,-12169.7905273437,,,,,,,,,,,,,0,,,,0,,,,,,200.0052185,,,,
,28193952.42,200.0096283,-16385.0185546875,-0.023197556432326,2.97668091953714E-6,1,0.999253354069792,40.0298881530762,1.99617865167984,27.4800006300211,-0.248313864337983,-0.131064782006272,2.5,-0.00752513489979396,-0.0232694946740878,-0.00757619777631962,200.0096283,200.0096283,-16392.220703125,-16377.81640625,57.3144744296407,20.526889272379,26.325863,0,0,0,40,4449,199.9615,-16385.0185546875,,,,,,,,,,,,,0,,,,-0.00245,,,,,,200.0096283,,,,
,28194036.32,200.0075226,-20580.087890625,-0.0260634918083585,7.8551960601839E-6,1,0.999253354069792,40.0298881530762,1.99608351921447,27.4700000882149,-0.27946770805816,-0.144438296251214,2.5,-0.00820693859277765,-0.0261446061179838,-0.00826341655402602,200.0075226,200.0075226,-20585.01953125,-20575.15625,57.2566339192176,20.5301058271341,26.325863,0,0,0,40,4449,199.95515,-20580.087890625,,,,,,,,,,,,,0,,,,-0.00245,,,,,,200.0075226,,,,
,28194121.61,200.0088043,-24842.8076171875,-0.0284925296086761,3.00295416351581E-6,1,0.999253354069792,40.0298881530762,1.99616886048518,27.4800006300211,-0.30568935416671,-0.156965114299737,2.5,-0.00888890012751037,-0.0285813131514044,-0.0089503107969869,200.0088043,200.0088043,-24847.927734375,-24837.6875,57.4989387601791,20.5166806518484,26.325863,0,0,0,40,4449,199.94845,-24842.8076171875,,,,,,,,,,,,,0,,,,0,,,,,,200.0088043,,,,
,28194204.915,200.0111847,-29008.2958984375,-0.0307133628152206,3.93320995844605E-6,1,0.999253354069792,40.0298881530762,1.99577337023664,27.4700000882149,-0.330151655596895,-0.165151118346063,2.5,-0.00922763082660836,-0.0308094683448022,-0.00929255697413537,200.0111847,200.0111847,-29015.66015625,-29000.931640625,57.4410982497561,20.5310867562047,25.946213,0,0,0,40,4449,199.9399,-29008.2958984375,,,,,,,,,,,,,0,,,,0,,,,,,200.0111847,,,,
,28194289.845,200.0100098,-33251.57421875,-0.0326101138018754,2.68708036547055E-6,1,0.999253354069792,40.0298881530762,1.99583994532728,27.4800006300211,-0.350525133936048,-0.175511399803535,2.5,-0.00981125991651751,-0.0327121661299442,-0.00988018974306977,200.0100098,200.0100098,-33259.33984375,-33243.80859375,57.2456911199484,20.5314673004339,25.946213,0,0,0,40,4449,199.93425,-33251.57421875,,,,,,,,,,,,,0,,,,0,,,,,,200.0100098,,,,
,28194376.35,200.0123444,-37575.625,-0.0343789603777555,3.72632315487585E-6,1,0.999253354069792,40.0298881530762,1.99549981991409,27.4700000882149,-0.369756205052685,-0.183402967887049,2.5,-0.0102025377678763,-0.0344867238490601,-0.0102746613542216,200.0123444,200.0123444,-37580.640625,-37570.609375,57.3347967711407,20.5339953545479,26.325863,0,0,0,40,4449,199.92205,-37575.625,,,,,,,,,,,,,0,,,,-0.0049,,,,,,200.0123444,,,,
,28194460.77,200.0144348,-41793.44140625,-0.0359972600520792,4.35788027896437E-6,1,0.999253354069792,40.0298881530762,1.99573931423479,27.4800006300211,-0.387631837532882,-0.189607226274633,2.5,-0.0104667399922932,-0.036110353594974,-0.0105414504219709,200.0140381,200.0148315,-41803.5390625,-41783.34375,57.4379717356792,20.5305155323661,26.325863,0,0,0,40,4449,199.9148,-41793.44140625,,,,,,,,,,,,,0,,,,0,,,,,,200.0144348,,,,
,28194545.645,200.0142212,-46033.55859375,-0.0374812594145097,4.07309292676162E-6,1,0.999253354069792,40.0298881530762,1.99563212334381,27.4800006300211,-0.403893946859653,-0.19567369923157,2.5,-0.0107448596371106,-0.0375992091932585,-0.0108220554949672,200.0142212,200.0142212,-46041.09375,-46026.0234375,57.4106147375061,20.5301732662623,26.325863,0,0,0,40,4449,199.90545,-46033.55859375,,,,,,,,,,,,,0,,,,0.00245,,,,,,200.0142212,,,,
,28194632.21,200.0121613,-50361.59375,-0.0388471623948649,5.015877474631E-6,1,0.999253354069792,40.0298881530762,1.99614809906446,27.4800006300211,-0.419010175455638,-0.201163395563675,2.5,-0.0109874017456243,-0.0389696036308254,-0.0110668273921235,200.0121613,200.0121613,-50368.98828125,-50354.19921875,57.3277621144676,20.5267134167862,26.705515,0,0,0,40,4449,199.89435,-50361.59375,,,,,,,,,,,,,0,,,,0,,,,,,200.0121613,,,,
,28194717.02,200.0123749,-54601.314453125,-0.0400440334298688,4.1839678491792E-6,1,0.999253354069792,40.0298881530762,1.9962282823506,27.4800006300211,-0.432063136106469,-0.206641174172198,2.5,-0.0112618157228811,-0.0401703480561723,-0.0113433931165878,200.0123749,200.0123749,-54611.21875,-54591.41015625,57.4786164186792,20.5248780768864,26.325863,0,0,0,40,4449,199.894,-54601.314453125,,,,,,,,,,,,,0,,,,-0.00245,,,,,,200.0123749,,,,
,28194801.955,200.01297,-58846.658203125,-0.041272962644893,5.36579522150415E-6,1,0.999253354069792,40.0298881530762,1.99629832788302,27.4800006300211,-0.445845671871635,-0.210067933682198,2.5,-0.0113499179308135,-0.0414034595860201,-0.0114330356972359,200.01297,200.01297,-58849.09765625,-58844.21875,57.5348936720638,20.523212106222,26.705515,0,0,0,40,4449,199.87915,-58846.658203125,,,,,,,,,,,,,0,,,,0,,,,,,200.01297,,,,
,28194886.935,200.0130615,-63091.779296875,-0.0423650586680127,3.8075167599149E-6,1,0.999253354069792,40.0298881530762,1.99586912471209,27.4800006300211,-0.457577606299094,-0.215419572245528,2.5,-0.0116359774911032,-0.0424990574934832,-0.0117211678029765,200.0130615,200.0130615,-63101.7265625,-63081.83203125,57.3379232852176,20.5325623189118,26.325863,0,0,0,40,4449,199.8687,-63091.779296875,,,,,,,,,,,,,0,,,,0,,,,,,200.0130615,,,,
,28194969.43,200.012558,-67217.03125,-0.0434222996727462,5.53142065581607E-6,1,0.999253354069792,40.0298881530762,1.99587686420023,27.4800006300211,-0.469432127329304,-0.218301251816616,2.5,-0.0117064466725029,-0.0435599108287062,-0.0117929244186535,200.012558,200.012558,-67224.3125,-67209.75,57.4090514804676,20.5333506576275,26.705515,0,0,0,40,4449,199.8622,-67217.03125,,,,,,,,,,,,,0,,,,0,,,,,,200.012558,,,,
,28195053.16,200.0128021,-71398.98046875,-0.04443242479757,4.0445623393339E-6,1,0.999253354069792,40.0298881530762,1.99582759141411,27.4800006300211,-0.480572062014568,-0.222046788383696,2.5,-0.0118617993830086,-0.0445733954567769,-0.0119498036496283,200.0128021,200.0128021,-71406.5,-71391.4609375,57.5012836457369,20.5323547498957,26.325863,0,0,0,40,4449,199.84915,-71398.98046875,,,,,,,,,,,,,0,,,,-0.00245,,,,,,200.0128021,,,,
,28195137.505,200.0118713,-75614.09765625,-0.045320151412249,4.89447368323344E-6,1,0.999253354069792,40.0298881530762,1.99640424636681,27.4800006300211,-0.490437153016864,-0.225808503189109,2.5,-0.0120338977743251,-0.0454640452821614,-0.0121233503854312,200.0118713,200.0118713,-75624.25,-75603.9453125,57.4567308201407,20.5243354429907,26.325863,0,0,0,40,4449,199.84345,-75614.09765625,,,,,,,,,,,,,0,,,,0,,,,,,200.0118713,,,,
,28195222.45,200.0131836,-79858.72265625,-0.0462414172562595,4.34306858341861E-6,1,0.999253354069792,40.0298881530762,1.99640575486622,27.4800006300211,-0.500685210194159,-0.228799744986121,2.5,-0.0121376443541018,-0.0463884197739882,-0.0122283408826132,200.0131836,200.0131836,-79866.3046875,-79851.140625,57.434063593083,20.5214844319086,26.325863,0,0,0,40,4449,199.83055,-79858.72265625,,,,,,,,,,,,,0,,,,-0.0049,,,,,,200.0131836,,,,
,28195306.39,200.0131836,-84056.3671875,-0.0470651394946377,6.19989137310428E-6,1,0.999253354069792,40.0298881530762,1.9967652796267,27.4800006300211,-0.509742548893986,-0.232625595300655,2.5,-0.0123283917989523,-0.0472148253032442,-0.0124205261944353,200.0131836,200.0131836,-84063.8984375,-84048.8359375,57.4567308201407,20.5159757757381,26.325863,0,0,0,40,4449,199.8226,-84056.3671875,,,,,,,,,,,,,0,,,,0,,,,,,200.0131836,,,,
,28195386.25,200.0111542,-88046.5703125,-0.0478984553454885,6.05054974953564E-6,1,0.999253354069792,40.0298881530762,1.99628651752902,27.4800006300211,-0.519035371937226,-0.234468644349946,2.5,-0.0123509211363241,-0.0480510373829444,-0.0124439229029686,200.0111542,200.0111542,-88051.5390625,-88041.6015625,57.4207759082561,20.5231946926179,25.946213,0,0,0,40,4449,199.81775,-88046.5703125,,,,,,,,,,,,,0,,,,-0.00245,,,,,,200.0111542,,,,
,28195483.305,200.0076447,-88050.59375,-0.0478581948875937,7.21793971303882E-6,1,0.999253354069792,40.0298881530762,1.99634400851652,27.4800006300211,-0.51853368463689,-0.234737084989907,2.5,-0.0123810016506173,-0.0480106103124665,-0.0124740699500103,200.0076447,200.0076447,-88053.53125,-88047.65625,57.4708001334869,20.5228400491267,25.946213,0,0,0,40,4449,199.80575,-88050.59375,,,,,,,,,,,,,0,,,,0,,,,,,200.0076447,,,,
,28195564.095,200.0033417,-84013.140625,-0.0470922599007823,3.60895763666734E-6,1,0.999253354069792,40.0298881530762,1.99648187239341,27.4800006300211,-0.51013715847934,-0.231750205537735,2.5,-0.0122492886266596,-0.0472421357920279,-0.0123411875142706,200.0033417,200.0033417,-84020.734375,-84005.546875,57.2277136640061,20.5218064787853,26.325863,0,0,0,40,4449,199.8074,-84013.140625,,,,,,,,,,,,,0,,,,0,,,,,,200.0033417,,,,
,28195649.805,199.9971771,-79727.8203125,-0.0462542010966895,6.21716766665626E-6,1,0.999253354069792,40.0298881530762,1.99637171221826,27.4800006300211,-0.50101722403142,-0.227698960861608,2.5,-0.0120387029762041,-0.0464013733352636,-0.0121290852969095,199.9971771,199.9971771,-79732.609375,-79723.03125,57.3394865422561,20.5224364729187,25.946213,0,0,0,40,4449,199.8129,-79727.8203125,,,,,,,,,,,,,0,,,,-0.00245,,,,,,199.9971771,,,,
,28195732.43,199.9956207,-75602.91015625,-0.0453024618637686,5.15096680218185E-6,1,0.999253354069792,40.0298881530762,1.99645687327837,27.4800006300211,-0.490281821364892,-0.225590629433541,2.5,-0.0120172470786481,-0.0454463333894358,-0.0121066374359533,199.9956207,199.9956207,-75610.390625,-75595.4296875,57.3676251689484,20.5233444484,26.325863,0,0,0,40,4449,199.8175,-75602.91015625,,,,,,,,,,,,,0,,,,-0.0049,,,,,,199.9956207,,,,
,28195815.905,199.9934082,-71427.70703125,-0.0443694240822344,6.17923976241299E-6,1,0.999253354069792,40.0298881530762,1.99651552339311,27.4800006300211,-0.479958612140259,-0.222324426630171,2.5,-0.0118907543267519,-0.0445101720501407,-0.0119788063091477,199.9934082,199.9934082,-71437.625,-71417.7890625,57.4332819645638,20.5236349013,26.325863,0,0,0,40,4449,199.8227,-71427.70703125,,,,,,,,,,,,,0,,,,0,,,,,,199.9934082,,,,
,28195899.5,199.9897919,-67253.00390625,-0.0434137040556706,6.63963883835997E-6,1,0.999253354069792,40.0298881530762,1.99676779718063,27.4800006300211,-0.469434953301283,-0.218953084814226,2.5,-0.0117571684085202,-0.0435512613975342,-0.0118438282839271,199.9897919,199.9897919,-67260.5703125,-67245.4375,57.2261504069676,20.5208921695274,26.325863,0,0,0,40,4449,199.8332,-67253.00390625,,,,,,,,,,,,,0,,,,0,,,,,,199.9897919,,,,
,28195982.17,199.9914551,-63118.044921875,-0.042396746803736,6.81312175771716E-6,1,0.999253354069792,40.0298881530762,1.99626561428634,27.4800006300211,-0.458250154816487,-0.214221470811954,2.5,-0.011521237033884,-0.0425310037655329,-0.0116060810060876,199.9914551,199.9914551,-63122.98046875,-63113.109375,57.2441278629099,20.5266470662348,26.325863,0,0,0,40,4449,199.83605,-63118.044921875,,,,,,,,,,,,,0,,,,0,,,,,,199.9914551,,,,
,28196066.53,199.9946594,-58905.314453125,-0.0412697897090582,4.15510989338875E-6,1,0.999253354069792,40.0298881530762,1.9964171107753,27.4800006300211,-0.445646992919402,-0.211157574814338,2.5,-0.0114454459665595,-0.0414001953011409,-0.0115289058919834,199.9946594,199.9946594,-58915.04296875,-58895.5859375,57.1143775287176,20.5269608269445,26.705515,0,0,0,40,4449,199.8417,-58905.314453125,,,,,,,,,,,,,0,,,,0.00245,,,,,,199.9946594,,,,
,28196152.675,199.9865723,-54597.548828125,-0.0400978053703735,4.54529651042964E-6,1,0.999253354069792,40.0298881530762,1.99624598892435,27.4800006300211,-0.432794856899865,-0.206070905540209,2.5,-0.0112020259111316,-0.0402243987301617,-0.0112834749494577,199.986496,199.9866486,-54607.64453125,-54587.453125,57.4160861371407,20.5354548572812,26.325863,0,0,0,40,4449,199.8495,-54597.548828125,,,,,,,,,,,,,0,,,,0,,,,,,199.9865723,,,,
,28196238.04,199.9884491,-50333.580078125,-0.0388402022510947,4.44393885826793E-6,1,0.999253354069792,40.0298881530762,1.99656633846778,27.4800006300211,-0.419079633463206,-0.200819554576472,2.5,-0.0109547369680586,-0.0389626810232619,-0.0110340595056557,199.9884491,199.9884491,-50336.171875,-50330.98828125,57.3105662870445,20.5246907645274,26.325863,0,0,0,40,4449,199.86145,-50333.580078125,,,,,,,,,,,,,0,,,,0.0049,,,,,,199.9884491,,,,
,28196323.555,199.9905396,-46057.494140625,-0.0374725086343514,4.22873844404521E-6,1,0.999253354069792,40.0298881530762,1.99680022892007,27.4800006300211,-0.404058455232239,-0.195547744194963,2.5,-0.0107256228717706,-0.037590473961334,-0.010802760665111,199.9905396,199.9905396,-46067.68359375,-46047.3046875,57.3097846585253,20.5277975279306,26.705515,0,0,0,40,4449,199.86455,-46057.494140625,,,,,,,,,,,,,0,,,,0,,,,,,199.9905396,,,,
,28196406.945,199.9892273,-41889.671875,-0.0360334742800005,5.43483180522442E-6,1,0.999253354069792,40.0298881530762,1.99625838141959,27.4800006300211,-0.388234863000644,-0.189174727411809,2.5,-0.0104181534025067,-0.0361467711753685,-0.0104927520103951,199.9892273,199.9892273,-41924.83203125,-41854.51171875,57.4246840508522,20.5285807608435,26.705515,0,0,0,40,4449,199.87145,-41889.671875,,,,,,,,,,,,,0,,,,0.00245,,,,,,199.9892273,,,,
,28196490.595,199.9876099,-37709.208984375,-0.0344582231145911,3.18603947204669E-6,1,0.999253354069792,40.0298881530762,1.99646681208799,27.4800006300211,-0.370961186745406,-0.182869939974909,2.5,-0.0101342914523886,-0.0345663585066773,-0.0102062798006419,199.9876099,199.9876099,-37716.671875,-37701.74609375,57.5317671579869,20.5279994240951,26.325863,0,0,0,40,4449,199.88125,-37709.208984375,,,,,,,,,,,,,0,,,,0,,,,,,199.9876099,,,,
,28196574.68,199.9891357,-33509.59765625,-0.0327187162368283,2.91593416937202E-6,1,0.999253354069792,40.0298881530762,1.99627699323356,27.4800006300211,-0.351853959824785,-0.175627616053181,2.5,-0.0097993923735056,-0.0328211759639215,-0.00986841110262868,199.9891357,199.9891357,-33519.56640625,-33499.62890625,57.4903408464676,20.5232842371567,25.946213,0,0,0,40,4449,199.88745,-33509.59765625,,,,,,,,,,,,,0,,,,0,,,,,,199.9891357,,,,
,28196658.34,199.9895935,-29324.38671875,-0.0308654272110741,3.8694281317734E-6,1,0.999253354069792,40.0298881530762,1.99632819652841,27.4800006300211,-0.33172128629352,-0.16689516902175,2.5,-0.00935108093535743,-0.0309619446985689,-0.00941660842643376,199.9895935,199.9895935,-29331.708984375,-29317.064453125,57.3543374841214,20.5233843870072,26.325863,0,0,0,40,4449,199.8966,-29324.38671875,,,,,,,,,,,,,0,,,,0,,,,,,199.9895935,,,,
,28196742.275,199.9904327,-25131.58203125,-0.0287450367422019,4.4082552517922E-6,1,0.999253354069792,40.0298881530762,1.99639117982175,27.4800006300211,-0.308643591225299,-0.157151293688242,2.5,-0.00885997126401003,-0.028834738304966,-0.00892156480637994,199.9904327,199.9904327,-25139.046875,-25124.1171875,57.3785679682176,20.5236264757829,26.325863,0,0,0,40,4449,199.90365,-25131.58203125,,,,,,,,,,,,,0,,,,-0.00245,,,,,,199.9904327,,,,
,28196825.435,199.9902802,-20974.046875,-0.0263559466765162,3.26805899464717E-6,1,0.999253354069792,40.0298881530762,1.99663884632842,27.4800006300211,-0.282696967007388,-0.145993048115131,2.5,-0.00828978412695944,-0.0264379944230549,-0.00834687229992611,199.9902802,199.9902802,-20976.51171875,-20971.58203125,57.4762715331215,20.5230479448559,26.705515,0,0,0,40,4449,199.91095,-20974.046875,,,,,,,,,,,,,0,,,,0.00245,,,,,,199.9902802,,,,
,28196909.945,199.988205,-16751.55859375,-0.0235368723270953,2.26823460238441E-6,1,0.999253354069792,40.0298881530762,1.99654129005826,27.4800006300211,-0.252051620950049,-0.132649383829339,2.5,-0.00760385422159874,-0.0236099113742841,-0.0076555653440275,199.988205,199.988205,-16759.052734375,-16744.064453125,57.2456911199484,20.5256393169729,26.705515,0,0,0,40,4449,199.9139,-16751.55859375,,,,,,,,,,,,,0,,,,-0.0049,,,,,,199.988205,,,,
,28196991.405,199.9918671,-12680.8857421875,-0.0203315835731311,4.04285426080905E-6,1,0.999253354069792,40.0298881530762,1.99686415325643,27.4800006300211,-0.217250156107516,-0.117539481625278,2.5,-0.00682714070798317,-0.0203943796913428,-0.0068727298845149,199.9918671,199.9918671,-12685.83203125,-12675.939453125,57.4207759082561,20.5273116256595,26.325863,0,0,0,40,4449,199.92165,-12680.8857421875,,,,,,,,,,,,,0,,,,0.0049,,,,,,199.9918671,,,,
,28197072.34,199.9908752,-8635.07568359375,-0.0165322822801493,9.35844322416499E-7,1,0.999253354069792,40.0298881530762,1.99641760031421,27.4800006300211,-0.176140089859289,-0.0982916919876639,2.5,-0.00579259865442772,-0.0165830719120962,-0.00583052310523631,199.9908752,199.9908752,-8637.7080078125,-8632.443359375,57.2417829773522,20.5253591385498,26.325863,0,0,0,40,4449,199.9232,-8635.07568359375,,,,,,,,,,,,,0,,,,0,,,,,,199.9908752,,,,
,28197155.775,199.9939728,-4466.80834960937,-0.0117132358270419,4.17260656096975E-6,1,0.999253354069792,40.0298881530762,1.99632403518674,27.4800006300211,-0.124193916344333,-0.0730736162922679,2.5,-0.00440700449859993,-0.0117488834138412,-0.00443493303411104,199.9939728,199.9939728,-4474.47998046875,-4459.13671875,57.2269320354868,20.5250073130117,26.705515,0,0,0,40,4449,199.932,-4466.80834960937,,,,,,,,,,,,,0,,,,0,,,,,,199.9939728,,,,
,28197236.17,199.9933929,-445.115097045898,-0.00479704065500792,1.23081151469514E-5,1,0.999253354069792,40.0298881530762,1.99634617477004,27.4800006300211,-0.0511855329902775,-0.0280694503709572,2.5,-0.00164110769850045,-0.00481181531076887,-0.00165198487815944,199.9933929,199.9933929,-450.0537109375,-440.176483154297,57.5552160135638,20.5262946656303,26.705515,0,0,0,40,4449,199.9347,-445.115097045898,,,,,,,,,,,,,0,,,,0.00245,,,,,,199.9933929,,,,
,28197316.16,199.9962158,3547.73461914063,0.0105546908251605,8.64916850465171E-6,1,0.999253354069792,40.0298881530762,1.99645656483635,27.4800006300211,0.112111239995458,0.0647323176775293,2.5,0.00387257929186782,0.0105869176054286,0.00389740710273836,199.9962158,199.9962158,3543.12817382812,3552.34106445313,57.3691884259868,20.5344131444318,25.946213,0,0,0,40,4449,199.93955,3547.73461914063,,,,,,,,,,,,,0,,,,-0.00245,,,,,,199.9962158,,,,
,28197398.985,200.0010681,7690.06860351562,0.0154039380275367,2.30973346400812E-6,1,0.999253354069792,40.0298881530762,1.99602579629141,27.4800006300211,0.163843362524101,0.0929718254777745,2.5,0.0055211869285344,0.0154511197734199,0.00555695243256381,200.0010681,200.0010681,7687.44580078125,7692.69140625,57.4809613042369,20.5315941451627,26.705515,0,0,0,40,4449,199.93335,7690.06860351562,,,,,,,,,,,,,0,,,,0.00245,,,,,,200.0010681,,,,
,28197478.915,200.0052185,11686.2299804687,0.0193810648464913,3.97760121531356E-6,1,0.999253354069792,40.0298881530762,1.99675863575739,27.4800006300211,0.207003181954907,0.112498018137271,2.5,0.0065484407301197,0.0194408698915926,0.00659204107164333,200.0052185,200.0052185,11681.3232421875,11691.13671875,57.5630322987561,20.5219657617178,26.325863,0,0,0,40,4449,199.9275,11686.2299804687,,,,,,,,,,,,,0,,,,0,,,,,,200.0052185,,,,
,28197561.47,200.0072632,15811.8208007813,0.0227742874169376,2.88461856650598E-6,1,0.999253354069792,40.0298881530762,1.99685834554249,27.4800006300211,0.24371688412039,0.129552084116172,2.5,0.00746157604064929,0.0228448299851948,0.00751197257959048,200.0072632,200.0072632,15803.97265625,15819.6689453125,57.1511140691214,20.5169924938188,26.325863,0,0,0,40,4449,199.92295,15811.8208007813,,,,,,,,,,,,,0,,,,-0.00245,,,,,,200.0072632,,,,
,28197643.7,200.0082245,19919.7470703125,0.0256330741437648,3.19513087476391E-6,1,0.999253354069792,40.0298881530762,1.99679672179645,27.4800006300211,0.274842849304429,0.142696374593051,2.5,0.00812382722565681,0.0257127857729336,0.0081795654721768,200.0082245,200.0082245,19912.6953125,19926.798828125,57.3379232852176,20.5168251442246,26.325863,0,0,0,40,4449,199.9187,19919.7470703125,,,,,,,,,,,,,0,,,,0.0049,,,,,,200.0082245,,,,
,28197721.895,200.0068359,23829.9345703125,0.0279675950148586,3.90827618663479E-6,1,0.999253354069792,40.0298881530762,1.99682745635876,27.4800006300211,0.300225277534322,0.153699164394559,2.5,0.00868787495789808,0.0280547770636679,0.00874804238021326,200.0068359,200.0068359,23819.61328125,23840.255859375,57.2660134614484,20.5212795495478,26.705515,0,0,0,40,4449,199.9179,23829.9345703125,,,,,,,,,,,,,0,,,,0,,,,,,200.0068359,,,,
,28197805.22,200.0082245,27993.208984375,0.0301568285649168,4.69994212996165E-6,1,0.999253354069792,40.0298881530762,1.99649663049295,27.4800006300211,0.324039024091328,0.163609489030792,2.5,0.00918335406093747,0.0302510550010883,0.00924754650263677,200.0082245,200.0082245,27988.1484375,27998.26953125,57.2566339192176,20.5295530256863,26.325863,0,0,0,40,4449,199.9115,27993.208984375,,,,,,,,,,,,,0,,,,0.00245,,,,,,200.0082245,,,,
,28197888.01,200.0122528,32131.048828125,0.032107944403165,6.79083226558801E-6,1,0.999253354069792,40.0298881530762,1.99645701482974,27.4800006300211,0.345340733933408,0.172216502019644,2.5,0.00960346431953866,0.032208473575483,0.00967115805108232,200.0122528,200.0122528,32125.818359375,32136.279296875,57.2542890336599,20.5246726305389,26.705515,0,0,0,40,4449,199.89775,32131.048828125,,,,,,,,,,,,,0,,,,-0.00245,,,,,,200.0122528,,,,
,28197972.305,200.0120392,36344.103515625,0.033924191653707,4.36135413661102E-6,1,0.999253354069792,40.0298881530762,1.99638023059593,27.4800006300211,0.365235951018003,0.179801377405155,2.5,0.00995721812490789,0.0340306374018327,0.0100280305924299,200.0120392,200.0120392,36339.140625,36349.06640625,57.2488176340253,20.5227577622997,27.085165,0,0,0,40,4449,199.8906,36344.103515625,,,,,,,,,,,,,0,,,,-0.0049,,,,,,200.0120392,,,,
,28198056.165,200.0134125,40534.326171875,0.0355295778255196,4.83367374573062E-6,1,0.999253354069792,40.0298881530762,1.99655990376633,27.4800006300211,0.382864409704437,0.18653366896791,2.5,0.0102704777059129,0.0356412559584709,0.0103440357925709,200.0134125,200.0134125,40526.671875,40541.98046875,57.4254656793715,20.5206943174362,26.325863,0,0,0,40,4449,199.8819,40534.326171875,,,,,,,,,,,,,0,,,,0,,,,,,200.0134125,,,,
,28198138.79,200.0104523,44667.734375,0.0369206267421262,4.89869599118055E-6,1,0.999253354069792,40.0298881530762,1.99679716532818,27.4800006300211,0.397913841730458,0.193777710122128,2.5,0.010665496013115,0.037036716968476,0.0107418479018266,200.0104523,200.0104523,44660.1953125,44675.2734375,57.0612267894099,20.520001512367,26.705515,0,0,0,40,4449,199.8755,44667.734375,,,,,,,,,,,,,0,,,,0,,,,,,200.0104523,,,,
,28198221.125,200.0113373,48780.619140625,0.0383731969467105,5.3733430021533E-6,1,0.999253354069792,40.0298881530762,1.99610484140739,27.4800006300211,0.414194862212256,0.196944995024139,2.5,0.0106981605673794,0.03849429643646,0.0107761144849046,200.0113373,200.0113373,48773.2109375,48788.02734375,57.2527257766214,20.5243631261117,26.705515,0,0,0,40,4449,199.8661,48780.619140625,,,,,,,,,,,,,0,,,,0,,,,,,200.0113373,,,,
,28198304.155,200.0140533,52931.095703125,0.0396334997993543,5.28035850020771E-6,1,0.999253354069792,40.0298881530762,1.99595988419776,27.4800006300211,0.42806779570142,0.201679082308826,2.5,0.0108979321673043,0.0397587654886003,0.0109778522469258,200.0140533,200.0140533,52925.98046875,52936.2109375,57.3598088837561,20.53262066046,26.705515,0,0,0,40,4449,199.8588,52931.095703125,,,,,,,,,,,,,0,,,,0,,,,,,200.0140533,,,,
,28198385.74,200.0158234,57011.154296875,0.0407841248468604,6.19127263113332E-6,1,0.999253354069792,40.0298881530762,1.99606179217653,27.4800006300211,0.440726564042525,0.206338184428045,2.5,0.0111080541147516,0.0409131693142414,0.0111898550986801,200.0158234,200.0158234,57003.77734375,57018.53125,57.2245871499291,20.5281671477804,26.325863,0,0,0,40,4449,199.85295,57011.154296875,,,,,,,,,,,,,0,,,,0.00245,,,,,,200.0158234,,,,
,28198468.235,200.0104828,61131.814453125,0.0418449887749006,8.38544292166678E-6,1,0.999253354069792,40.0298881530762,1.99595211657915,27.4800006300211,0.452260639976185,0.211157077669671,2.5,0.0113496937016995,0.0419774791839381,0.0114333883828328,200.0104828,200.0104828,61126.6640625,61136.96484375,57.105779615006,20.5275171784638,26.705515,0,0,0,40,4449,199.838,61131.814453125,,,,,,,,,,,,,0,,,,0,,,,,,200.0104828,,,,
,28198552.465,200.0131226,65342.77734375,0.0429331662091131,7.69609977945922E-6,1,0.999253354069792,40.0298881530762,1.99619957556821,27.4800006300211,0.464264051309995,0.215596343480822,2.5,0.0115499289746434,0.0430692332094681,0.0116353921877022,200.0131226,200.0131226,65335.31640625,65350.23828125,57.2245871499291,20.5252340448622,26.705515,0,0,0,40,4449,199.82995,65342.77734375,,,,,,,,,,,,,0,,,,0.00245,,,,,,200.0131226,,,,
,28198635.275,200.0119781,69483.43359375,0.0439042428397292,6.70491756083335E-6,1,0.999253354069792,40.0298881530762,1.9961141675005,27.4800006300211,0.474878449216359,0.21970086971963,2.5,0.0117439857578989,0.0440434946751308,0.0118310703839727,200.0119781,200.0119781,69478.3984375,69488.46875,57.4504777919868,20.5255270828331,26.325863,0,0,0,40,4449,199.8209,69483.43359375,,,,,,,,,,,,,0,,,,-0.0049,,,,,,200.0119781,,,,
,28198717.36,200.0109406,73584.17578125,0.0448415098463442,6.14014135523647E-6,1,0.999253354069792,40.0298881530762,1.99674950343275,27.4800006300211,0.485336156506341,0.223467366363454,2.5,0.0119073580489203,0.0449838633232372,0.0119959186421098,200.0109406,200.0109406,73581.6328125,73586.71875,57.217552493256,20.5251684645109,26.705515,0,0,0,40,4449,199.81245,73584.17578125,,,,,,,,,,,,,0,,,,0,,,,,,200.0109406,,,,
,28198801.235,200.0140991,77777.64453125,0.0457681404778856,5.73635883953479E-6,1,0.999253354069792,40.0298881530762,1.99679585625574,27.4800006300211,0.495729137430796,0.226061163960033,2.5,0.0119746733944007,0.0459136557371266,0.0120643600123908,200.0140991,200.0140991,77770.125,77785.1640625,57.2027015513907,20.5265259607448,26.325863,0,0,0,40,4449,199.8005,77777.64453125,,,,,,,,,,,,,0,,,,0,,,,,,200.0140991,,,,
,28198883.865,200.0113525,81908.73828125,0.0466222424925924,6.66270340117674E-6,1,0.999253354069792,40.0298881530762,1.9967310867381,27.4800006300211,0.505187664252363,0.228990649557108,2.5,0.0120852296103685,0.0467706333966314,0.0121761131571404,200.0113525,200.0113525,81903.8515625,81913.625,57.0768593597945,20.5240495710291,26.325863,0,0,0,40,4449,199.7942,81908.73828125,,,,,,,,,,,,,0,,,,-0.00245,,,,,,200.0113525,,,,
,28198966.485,200.0122528,86036.9375,0.0474291139891674,5.55697354649058E-6,1,0.999253354069792,40.0298881530762,1.9968295431485,27.4800006300211,0.514133849573077,0.231936685478365,2.5,0.0122038728044391,0.0475802039699008,0.0122959271496921,200.0122528,200.0122528,86027.078125,86046.796875,57.3512109700445,20.5222396042979,26.325863,0,0,0,40,4449,199.78495,86036.9375,,,,,,,,,,,,,0,,,,0,,,,,,200.0122528,,,,
,28199044.18,200.0122681,89920.59765625,0.048175325164862,7.06681402539368E-6,1,0.999253354069792,40.0298881530762,1.99687354074485,27.4800006300211,0.522375772547705,0.234775536845772,2.5,0.0123241163088392,0.0483289030868373,0.0124172855107958,200.0122681,200.0122681,89915.703125,89925.4921875,57.1925403806407,20.5236899530054,26.325863,0,0,0,40,4449,199.77595,89920.59765625,,,,,,,,,,,,,0,,,,-0.00245,,,,,,200.0122681,,,,
,28199139.545,200.0049896,86211.3828125,0.0474979249261244,6.79622369860887E-6,1,0.999253354069792,40.0298881530762,1.99697830076049,27.4800006300211,0.515010107931485,0.231750706911308,2.5,0.0121740771632666,0.0476492958226947,0.0122661030154325,200.0049896,200.0049896,86203.7578125,86219.0078125,57.2636685758907,20.5237681098284,26.705515,0,0,0,40,4449,199.77435,86211.3828125,,,,,,,,,,,,,0,,,,0.00245,,,,,,200.0049896,,,,
,28199221.02,199.9985199,73984.7734375,0.0449083588784544,7.40682832733858E-6,1,0.999253354069792,40.0298881530762,1.99703845755995,27.4800006300211,0.486200857505026,0.223406297365094,2.5,0.0118876386448978,0.045050982183301,0.0119762078280158,199.9985199,199.9985199,73964.8125,74004.734375,57.1722180391407,20.5255396063576,26.705515,0,0,0,40,4449,199.77855,73984.7734375,,,,,,,,,,,,,0,,,,0.00245,,,,,,199.9985199,,,,
,28199304.33,199.9817047,57403.212890625,0.0408438421488439,5.93167117277285E-6,1,0.999253354069792,40.0298881530762,1.99671131625625,27.4800006300211,0.441259593845038,0.208143319456914,2.5,0.0112511021724325,0.0409729839781224,0.0113334798087209,199.9817047,199.9817047,57393.3359375,57413.08984375,57.3918556530445,20.5240464516685,26.705515,0,0,0,40,4449,199.80105,57403.212890625,,,,,,,,,,,,,0,,,,-0.0049,,,,,,199.9817047,,,,
,28199387.75,199.9715576,40756.431640625,0.0356790867852029,7.17149934208744E-6,1,0.999253354069792,40.0298881530762,1.99698284897437,27.4800006300211,0.384621470924195,0.186966652217556,2.5,0.0102793118826962,0.0357913167504397,0.0103530848115356,199.9715576,199.9715576,40736.51953125,40776.34375,57.525514129833,20.5223899141073,26.705515,0,0,0,40,4449,199.8242,40756.431640625,,,,,,,,,,,,,0,,,,-0.00245,,,,,,199.9715576,,,,
,28199468.695,199.9620056,24591.296875,0.028587915887929,5.73148545967993E-6,1,0.999253354069792,40.0298881530762,1.99673180467169,27.4800006300211,0.307149064091086,0.155498421282655,2.5,0.00873930576849693,0.0286772249905122,0.00880033613917373,199.9620056,199.9620056,24550.833984375,24631.759765625,57.3824761108138,20.5248070653138,26.325863,0,0,0,40,4449,199.8557,24591.296875,,,,,,,,,,,,,0,,,,0,,,,,,199.9620056,,,,
,28199548.76,199.963623,8600.9638671875,0.0165823859851808,1.12293587689468E-5,1,0.999253354069792,40.0298881530762,1.99680238576837,27.4700000882149,0.176938434525604,0.097272695683131,2.5,0.00569248580062447,0.0166334695427681,0.00573012908786872,199.963623,199.963623,8570.701171875,8631.2265625,57.3871658819292,20.5269288060702,26.325863,0,0,0,40,4449,199.8785,8600.9638671875,,,,,,,,,,,,,0,,,,0,,,,,,199.963623,,,,
,28199592.71,199.9638062,-0.258804142475128,0.00199496980146743,2.39450098403137E-5,1,0.999253354069792,40.0298881530762,1.99692823366207,27.4800006300211,0.0224443222491421,0.00504657840533081,2.5,9.82194777960833E-5,0.00200175093226914,0.00010072700252356,199.9638062,199.9638062,-0.274027913808823,-0.243580371141434,57.3840393678522,20.5270815622086,26.325863,0,0,0,40,4417,199.8985,-0.258804142475128,,,,,,,,,,,,,0,,,,0,,,,,,199.9638062,,,,