File: data/monolayers/nanoparticles/Ol_CoFe_C/vsm/ZFCFC/DD172_6_ZFCw_100OE.DAT
[Header]
; VSM Data File (default extension .dat)
; Copyright (c) 2003-2013, Quantum Design, Inc. All rights reserved.
TITLE,
FILEOPENTIME,26894711.56,11/08/2018,2:45 pm
BYAPP,VSM,2.0,2.0
INFO,PPMS VSM Option Release 1.4.10 Build 1,APPNAME
INFO,Quantum Design Linear Motor Servo Controller,MOTOR_MODULE_NAME
INFO,3101-100 M1,MOTOR_HW_VERSION
INFO,MMC1014,MOTOR_SERIAL_NUMBER
INFO,SRV No X-over 01.03.11,MOTOR_SOFTWARE_VERSION
INFO,Quantum Design VSM Detection Module,VSM_MODULE_NAME
INFO,3101-150 F0,VSM_HW_VERSION
INFO,VSM707,VSM_SERIAL_NUMBER
INFO,VSM No X-over 01.02.05 May 20 2008 13:51:47,VSM_SOFTWARE_VERSION
INFO,704,PREAMP_SERIAL_NUMBER
INFO,822,COIL_SERIAL_NUMBER
INFO,0,MOMENT_UNITS
INFO,CoFe2O4 DD67,SAMPLE_MATERIAL
INFO,Colloidal Crystal,SAMPLE_COMMENT
INFO,31.86,SAMPLE_MASS
INFO,,SAMPLE_VOLUME
INFO,,SAMPLE_MOLECULAR_WEIGHT
INFO,,SAMPLE_SIZE
INFO,,SAMPLE_SHAPE
DATATYPE,COMMENT,1
DATATYPE,TIME,2
STARTUPAXIS,X,2
STARTUPAXIS,Y1,5
[Data]
Comment,Time Stamp (sec),Temperature (K),Magnetic Field (Oe),Moment (emu),M. Std. Err. (emu),Transport Action,Averaging Time (sec),Frequency (Hz),Peak Amplitude (mm),Center Position (mm),Coil Signal' (mV),Coil Signal" (mV),Range (mV),M. Quad. Signal (emu),M. Raw' (emu),M. Raw" (emu),Min. Temperature (K),Max. Temperature (K),Min. Field (Oe),Max. Field (Oe),Mass (grams),Motor Lag (deg),Pressure (Torr),VSM Status (code),Motor Status (code),Measure Status (code),Measure Count,PPMS Status (code),System Temp. (K),System Field (Oe),Sample Position (deg),Bridge 1 Resistance (ohms),Bridge 1 Excitation (�A),Bridge 2 Resistance (ohms),Bridge 2 Excitation (�A),Bridge 3 Resistance (ohms),Bridge 3 Excitation (�A),Bridge 4 Resistance (ohms),Bridge 4 Excitation (�A),Signal 1 Vin (V),Signal 2 Vin (V),Digital Inputs (code),Drive 1 Iout (mA),Drive 1 Ipower (W),Drive 2 Iout (mA),Drive 2 Ipower (W),Pressure (),Map 20 (),Map 21 (),Map 22 (),Map 23 (),Map 24 (),Map 25 (),Map 26 (),Map 27 (),Map 28 (),Map 29 ()
,26937765.84,10.0027866,99.7613830566406,,,2,,,,20.0200002738833,,,,,,,10.0027866,10.0027866,99.7613830566406,99.7613830566406,,,12.278775,,,,-99999999,4373,10.0019,99.7613830566406,,,,,,,,,,,,,,,,,,,,,,,10.0027866,,,,
,26937969.555,12.5211754,99.7613830566406,5.06377639656135E-6,2.9004037107481E-7,1,0.999253354069792,40.0298881530762,1.9987524705858,20.0100000947714,5.74266936743284E-5,7.36792807414697E-6,0.25,-2.43957605799573E-7,5.03585231704927E-6,-2.18133978543938E-7,12.5211754,12.5211754,99.7613830566406,99.7613830566406,56.2835064127752,20.5546937680347,13.417728,0,0,0,40,4370,12.60095,99.7613830566406,,,,,,,,,,,,,0,,,,0.0049,,,,,,12.5211754,,,,
,26938111.57,16.0508242,99.7613830566406,4.82333709793805E-6,3.62637616961952E-7,1,0.999253354069792,40.0298881530762,1.99880065678983,20.0100000947714,5.46795503605957E-5,7.13725497589359E-6,0.25,-2.21784344384951E-7,4.79664310045645E-6,-1.97245896800016E-7,16.0243073,16.0773411,99.7613830566406,99.7613830566406,56.8290831191983,20.5587176615931,14.177031,0,0,0,40,4370,16.1667,99.7613830566406,,,,,,,,,,,,,0,,,,0,,,,,,16.0508242,,,,
,26938253.085,19.5308876,99.7613830566406,4.62379790324867E-6,3.75360578513784E-7,1,0.999253354069792,40.0298881530762,1.99863023243827,20.0100000947714,5.29396828867192E-5,3.87892064320408E-6,0.25,-4.76187913172886E-7,4.59951269525279E-6,-4.51056522781593E-7,19.5308876,19.5308876,99.7613830566406,99.7613830566406,56.7321611828137,20.5642000226197,14.556682,0,0,0,40,4370,19.7093,99.7613830566406,,,,,,,,,,,,,0,,,,0.00245,,,,,,19.5308876,,,,
,26938373.35,22.5474052,99.7613830566406,5.17429524689802E-6,3.35039099540427E-7,1,0.999253354069792,40.0298881530762,1.99849099760914,20.0299993157387,5.82575478950288E-5,9.88878287957925E-6,0.25,-3.9946532175666E-8,5.145098613818E-6,-1.41673848154453E-8,22.5474052,22.5474052,99.7613830566406,99.7613830566406,56.9447641400445,20.5588424782896,15.315984,0,0,0,40,4370,22.7362,99.7613830566406,,,,,,,,,,,,,0,,,,0,,,,,,22.5474052,,,,
,26938512.375,26.0006485,99.7613830566406,5.27830412499091E-6,3.12086312983906E-7,1,0.999253354069792,40.0298881530762,1.99859512099058,20.0299993157387,6.00254267746356E-5,6.81109902763912E-6,0.25,-3.33403404588547E-7,5.2509536651163E-6,-3.04404639807774E-7,26.0006485,26.0006485,99.7613830566406,99.7613830566406,56.9807190519291,20.5654573267842,15.695635,0,0,0,40,4370,26.243,99.7613830566406,,,,,,,,,,,,,0,,,,0.0049,,,,,,26.0006485,,,,
,26938654.06,29.5072079,99.7613830566406,5.7220271260334E-6,3.11717608907028E-7,1,0.999253354069792,40.0298881530762,1.9984541646476,20.0299993157387,6.46200455314713E-5,1.00118931136809E-5,0.25,-1.29745470053876E-7,5.69294278288832E-6,-9.78191680463237E-8,29.5072079,29.5072079,99.7613830566406,99.7613830566406,57.0799858738714,20.5723050607097,16.454937,0,0,0,40,4370,29.807,99.7613830566406,,,,,,,,,,,,,0,,,,0,,,,,,29.5072079,,,,
,26938796.785,33.0387611,99.7613830566406,6.16918205496282E-6,2.97345903580878E-7,1,0.999253354069792,40.0298881530762,1.99805003558592,20.0399998575449,7.06231357730239E-5,5.56882807819206E-6,0.25,-6.07143350497548E-7,6.14342803366303E-6,-5.68056480549198E-7,33.0387611,33.0387611,99.7613830566406,99.7613830566406,56.9783741663714,20.5702630551776,16.834587,0,0,0,40,4370,33.4035,99.7613830566406,,,,,,,,,,,,,0,,,,0.0049,,,,,,33.0387611,,,,
,26938939.455,36.5515442,99.7613830566406,6.23451365322019E-6,3.3303144123396E-7,1,0.999253354069792,40.0298881530762,1.99842379868125,20.0399998575449,7.10745370130743E-5,7.63040178931751E-6,0.25,-4.38992135866257E-7,6.21159223407811E-6,-3.97744685798162E-7,36.5515442,36.5515442,99.7613830566406,99.7613830566406,56.7774956369291,20.5693627469835,17.593889,0,0,0,40,4370,37.0016,99.7613830566406,,,,,,,,,,,,,0,,,,0,,,,,,36.5515442,,,,
,26939078.175,40.0101852,99.7613830566406,6.25297467823911E-6,2.95269625366979E-7,1,0.999253354069792,40.0298881530762,1.99817758666042,20.0399998575449,7.13079514117058E-5,7.81053109463509E-6,0.25,-4.29513136849326E-7,6.23502097793627E-6,-3.85790340254654E-7,40.0101852,40.0101852,99.7613830566406,99.7613830566406,57.047939104583,20.5730234386803,17.973541,0,0,0,40,4370,40.492,99.7613830566406,,,,,,,,,,,,,0,,,,-0.0049,,,,,,40.0101852,,,,
,26939220.97,43.5158348,99.7613830566406,6.39516611608296E-6,3.42371072040328E-7,1,0.999253354069792,40.0298881530762,1.9984243828252,20.0399998575449,7.2591527529675E-5,1.03329901471694E-5,0.25,-2.34534774525381E-7,6.3817770100697E-6,-1.88310836554906E-7,43.5158348,43.5158348,99.7613830566406,99.7613830566406,57.1526773261599,20.5715376612979,17.593889,0,0,0,40,4370,44.1118,99.7613830566406,,,,,,,,,,,,,0,,,,-0.00245,,,,,,43.5158348,,,,
,26939366.235,47.0614929,99.7613830566406,6.99900682570534E-6,3.33149812954089E-7,1,0.999253354069792,40.0298881530762,1.99790216725583,20.0399998575449,7.98282266442765E-5,9.58437659994212E-6,0.25,-4.11975667667228E-7,6.99338540791261E-6,-3.59797372165219E-7,47.0614929,47.0614929,99.7613830566406,99.7613830566406,57.3004051162945,20.573762411729,17.973541,0,0,0,40,4370,47.7979,99.7613830566406,,,,,,,,,,,,,0,,,,0.0049,,,,,,47.0614929,,,,
,26939506.125,50.5145607,99.7613830566406,6.77477439289276E-6,2.75043469543925E-7,1,0.999253354069792,40.0298881530762,1.99782994980863,20.0399998575449,7.69262390659693E-5,1.16658659786179E-5,0.25,-1.88587035218981E-7,6.77538052334265E-6,-1.38170433241508E-7,50.5145607,50.5145607,99.7613830566406,99.7613830566406,57.007294421583,20.5756189050696,18.732843,0,0,0,40,4370,51.36185,99.7613830566406,,,,,,,,,,,,,0,,,,0,,,,,,50.5145607,,,,
,26939649.375,54.0006065,99.7613830566406,7.10798028386528E-6,2.97914292084392E-7,1,0.999253354069792,40.0298881530762,1.99787597127796,20.0299993157387,8.14062493928717E-5,8.89344917609914E-6,0.25,-4.93972459384901E-7,7.11867772617937E-6,-4.42476488101007E-7,54.0006065,54.0006065,99.7613830566406,99.7613830566406,57.014329078256,20.574981044617,19.492144,0,0,0,40,4374,55.0365,99.7613830566406,,,,,,,,,,,,,0,,,,0,,,,,,54.0006065,,,,
,26939796.62,57.5772476,99.7613830566406,7.55488724019438E-6,3.33044029363663E-7,1,0.999253354069792,40.0298881530762,1.9979436407132,20.0299993157387,8.62805309770633E-5,1.13221592531871E-5,0.25,-3.58566959684549E-7,7.57275747051121E-6,-3.06212465728877E-7,57.5772476,57.5772476,99.7613830566406,99.7613830566406,56.6446187886598,20.5737596432463,20.631098,0,0,0,40,4374,58.82345,99.7613830566406,,,,,,,,,,,,,0,,,,0,,,,,,57.5772476,,,,
,26939939.32,61.0531654,99.7613830566406,7.53610326985758E-6,3.21756408639098E-7,1,0.999253354069792,40.0298881530762,1.99786405143142,20.0299993157387,8.55139490677241E-5,1.47557366736272E-5,0.25,-5.01390541516549E-8,7.55810893617669E-6,-1.70170147974143E-10,61.0531654,61.0531654,99.7613830566406,99.7613830566406,56.8462789466214,20.5763564179601,20.631098,0,0,0,40,4374,62.4403,99.7613830566406,,,,,,,,,,,,,0,,,,-0.00245,,,,,,61.0531654,,,,
,26940079.115,64.5108414,99.7613830566406,7.73407909212668E-6,3.47821536068015E-7,1,0.999253354069792,40.0298881530762,1.99775856530348,20.0299993157387,8.8636903221041E-5,1.05595734289454E-5,0.25,-4.53194127389228E-7,7.76438541845575E-6,-4.06598959001085E-7,64.5108414,64.5108414,99.7613830566406,99.7613830566406,56.7235632691022,20.5780545481143,21.01075,0,0,0,40,4374,65.96395,99.7613830566406,,,,,,,,,,,,,0,,,,-0.0049,,,,,,64.5108414,,,,
,26940220.62,68.0075607,99.7613830566406,8.0297741879351E-6,3.35675335886451E-7,1,0.999253354069792,40.0298881530762,1.99772270531174,20.0299993157387,9.23002669417835E-5,9.69117858121873E-6,0.25,-5.7956539044199E-7,8.06609765584274E-6,-5.35409625256123E-7,68.0075607,68.0075607,99.7613830566406,99.7613830566406,57.115940785756,20.5798868860347,20.631098,0,0,0,40,4374,69.5404,99.7613830566406,,,,,,,,,,,,,0,,,,0.0049,,,,,,68.0075607,,,,
,26940363.475,71.5174637,99.7613830566406,8.21383357576844E-6,3.37021574877465E-7,1,0.999253354069792,40.0298881530762,1.99778465311072,20.0299993157387,9.41495381872525E-5,1.16424689065669E-5,0.25,-4.37372244586057E-7,8.25348908897677E-6,-3.9530331830803E-7,71.5174637,71.5174637,99.7613830566406,99.7613830566406,56.9494539111599,20.5821285865694,21.3904,0,0,0,40,4374,73.15295,99.7613830566406,,,,,,,,,,,,,0,,,,-0.0049,,,,,,71.5174637,,,,
,26940484.17,74.5381393,99.7613830566406,8.16026138006007E-6,3.35270426306137E-7,1,0.999253354069792,40.0298881530762,1.99789402459291,20.0100000947714,9.33487701921817E-5,1.27889857324196E-5,0.25,-3.24401802168732E-7,8.20131203569467E-6,-2.85019258072076E-7,74.5381393,74.5381393,99.7613830566406,99.7613830566406,57.0354330482753,20.5792490382983,21.770052,0,0,0,40,4374,76.2042,99.7613830566406,,,,,,,,,,,,,0,,,,-0.00245,,,,,,74.5381393,,,,
,26940628.94,78.09636305,99.7613830566406,9.01774139123208E-6,3.92588500282232E-7,1,0.999253354069792,40.0298881530762,1.99798360370659,20.0100000947714,0.00010299550725408,1.52231378180775E-5,0.25,-2.59446618976299E-7,9.06493289764842E-6,-2.18978601492682E-7,78.0556183,78.1371078,99.7613830566406,99.7613830566406,56.9416376259676,20.5805375525319,21.770052,0,0,0,40,4374,79.86105,99.7613830566406,,,,,,,,,,,,,0,,,,0,,,,,,78.09636305,,,,
,26940768.445,81.5449753,99.7613830566406,8.8782308067551E-6,3.93761543064597E-7,1,0.999253354069792,40.0298881530762,1.99814908064609,20.0100000947714,0.000101452585720347,1.48564279933542E-5,0.25,-2.64317138222195E-7,8.92637664350885E-6,-2.27580530964194E-7,81.5449753,81.5449753,99.7613830566406,99.7613830566406,57.088583787583,20.5832944543873,21.3904,0,0,0,40,4374,83.41115,99.7613830566406,,,,,,,,,,,,,0,,,,0,,,,,,81.5449753,,,,
,26940910.515,85.0402985,99.7613830566406,9.43323503597494E-6,2.8706552875953E-7,1,0.999253354069792,40.0298881530762,1.99826359841255,19.9900008738041,0.000107937248354496,1.50955919026026E-5,0.25,-3.38852159072232E-7,9.48589388902505E-6,-3.03077568348556E-7,85.0402985,85.0402985,99.7613830566406,99.7613830566406,57.1440794124484,20.5779301695433,22.149702,0,0,0,40,4374,86.9829,99.7613830566406,,,,,,,,,,,,,0,,,,-0.0049,,,,,,85.0402985,,,,
,26941050.035,88.537262,99.7613830566406,9.85628314487692E-6,2.93656603997503E-7,1,0.999253354069792,40.0298881530762,1.99827069778087,19.9900008738041,0.000112871511558313,1.53016979722771E-5,0.25,-3.92919733175086E-7,9.91233287007676E-6,-3.58462426246809E-7,88.537262,88.537262,99.7613830566406,99.7613830566406,57.0283983916022,20.5792794689578,22.529354,0,0,0,40,4374,90.48135,99.7613830566406,,,,,,,,,,,,,0,,,,0.00245,,,,,,88.537262,,,,
,26941190.04,92.0086746,99.7613830566406,9.89859348956879E-6,3.38953655620675E-7,1,0.999253354069792,40.0298881530762,1.9980258723897,19.9900008738041,0.00011364746209397,1.36740075010645E-5,0.25,-5.4101966228038E-7,9.95597809872698E-6,-5.09688530079867E-7,92.0086746,92.0086746,99.7613830566406,99.7613830566406,56.9189703989099,20.5780668074416,22.149702,0,0,0,40,4374,94.003,99.7613830566406,,,,,,,,,,,,,0,,,,0,,,,,,92.0086746,,,,
,26941331.755,95.5368042,99.7613830566406,1.0042691865945E-5,3.3134423245537E-7,1,0.999253354069792,40.0298881530762,1.99801239989529,19.9699997901917,0.000114574489404212,1.80237711140844E-5,0.25,-1.81724926672488E-7,1.01000262869694E-5,-1.50114121051641E-7,95.5368042,95.5368042,99.7613830566406,99.7613830566406,57.3746598256215,20.5813558128324,22.149702,0,0,0,40,4374,97.5537,99.7613830566406,,,,,,,,,,,,,0,,,,0.0049,,,,,,95.5368042,,,,
,26941470.935,99.0042343,99.7613830566406,1.06638531965993E-5,3.40846999816328E-7,1,0.999253354069792,40.0298881530762,1.99804868115629,19.9699997901917,0.000121897649192787,1.78171535237022E-5,0.25,-3.07124663748317E-7,1.07252725718569E-5,-2.76304952558198E-7,99.0042343,99.0042343,99.7613830566406,99.7613830566406,57.126101956506,20.5858180350904,22.149702,0,0,0,40,4374,101.0502,99.7613830566406,,,,,,,,,,,,,0,,,,-0.00245,,,,,,99.0042343,,,,
,26941613.3,102.5229568,99.7613830566406,1.06059989555821E-5,3.43364909341713E-7,1,0.999253354069792,40.0298881530762,1.99838773616535,19.9699997901917,0.000121241673967004,1.78042003899651E-5,0.25,-2.96439444073824E-7,1.06670567744368E-5,-2.67657792118763E-7,102.5229568,102.5229568,99.7613830566406,99.7613830566406,57.2503808910638,20.5841128599672,22.529354,0,0,0,40,4374,104.62915,99.7613830566406,,,,,,,,,,,,,0,,,,-0.00245,,,,,,102.5229568,,,,
,26941753.875,106.0162277,99.7613830566406,1.13894800773457E-5,4.07058855533153E-7,1,0.999253354069792,40.0298881530762,1.99810139578925,19.9400000274181,0.000130366592931173,1.80425813810024E-5,0.25,-4.10925856627948E-7,1.14551367801678E-5,-3.82380039980668E-7,106.0162277,106.0162277,99.7613830566406,99.7613830566406,56.9775925378522,20.5785152721296,22.529354,0,0,0,40,4374,108.173,99.7613830566406,,,,,,,,,,,,,0,,,,0,,,,,,106.0162277,,,,
,26941895.105,109.566864,99.7613830566406,1.20075266252987E-5,3.49660045095809E-7,1,0.999253354069792,40.0298881530762,1.99819401319844,19.9400000274181,0.000137224702532313,2.02682436317654E-5,0.25,-3.21911302192854E-7,1.20761209574297E-5,-2.92934159236537E-7,109.566864,109.566864,99.7613830566406,99.7613830566406,56.7782772654483,20.5800940986867,22.149702,0,0,0,40,4374,111.72135,99.7613830566406,,,,,,,,,,,,,0,,,,0,,,,,,109.566864,,,,
,26942034.68,113.0221939,99.7613830566406,1.21326784695208E-5,3.1910477824995E-7,1,0.999253354069792,40.0298881530762,1.99807942176005,19.9400000274181,0.000138282102176264,2.25363064325545E-5,0.25,-1.42686438715481E-7,1.22011189064579E-5,-1.13966078500418E-7,113.0221939,113.0221939,99.7613830566406,99.7613830566406,57.017455592333,20.5785875355937,22.529354,0,0,0,40,4374,115.2377,99.7613830566406,,,,,,,,,,,,,0,,,,0.00245,,,,,,113.0221939,,,,
,26942176.415,116.5294075,99.7613830566406,1.28176045367539E-5,3.7857063065352E-7,1,0.999253354069792,40.0298881530762,1.99799724242576,19.9100002646446,0.000146205616608031,2.30694240806178E-5,0.25,-2.14016087750579E-7,1.28895151441604E-5,-1.8557255462477E-7,116.5012131,116.5576019,99.7613830566406,99.7613830566406,56.8978664288906,20.5791090023479,22.909004,0,0,0,40,4374,118.8042,99.7613830566406,,,,,,,,,,,,,0,,,,-0.0049,,,,,,116.5294075,,,,
,26942316.495,120.008728,99.7613830566406,1.33852657304082E-5,3.29564193400165E-7,1,0.999253354069792,40.0298881530762,1.99792112771048,19.9100002646446,0.000153104647525441,2.15890769355465E-5,0.25,-4.41867396634222E-7,1.34601757750402E-5,-4.14817889068832E-7,120.008728,120.008728,99.7613830566406,99.7613830566406,56.9861904515637,20.5841974389754,23.288654,0,0,0,40,4374,122.32715,99.7613830566406,,,,,,,,,,,,,0,,,,0,,,,,,120.008728,,,,
,26942457.61,123.5153885,99.7613830566406,1.41111844694244E-5,3.52127220178617E-7,1,0.999253354069792,40.0298881530762,1.99818166678461,19.9100002646446,0.000160973349721862,2.53097410131475E-5,0.25,-2.40374265761561E-7,1.41888606936875E-5,-2.12008914031466E-7,123.5153885,123.5153885,99.7613830566406,99.7613830566406,57.0635716749676,20.5849463006238,23.288654,0,0,0,40,4374,125.8626,99.7613830566406,,,,,,,,,,,,,0,,,,-0.0049,,,,,,123.5153885,,,,
,26942599.435,127.0550308,99.7613830566406,1.49987050962639E-5,3.08236981752167E-7,1,0.999253354069792,40.0298881530762,1.9981586876274,19.8699999600649,0.000171132217161907,2.66300937992802E-5,0.25,-2.77812226865905E-7,1.50803699153556E-5,-2.49155357887313E-7,127.0550308,127.0550308,99.7613830566406,99.7613830566406,56.8916134007368,20.5849710375642,23.288654,0,0,0,40,4374,129.4385,99.7613830566406,,,,,,,,,,,,,0,,,,0,,,,,,127.0550308,,,,
,26942738.02,130.5003967,99.7613830566406,1.59204186901651E-5,3.42878153680168E-7,1,0.999253354069792,40.0298881530762,1.99799782758488,19.8699999600649,0.000181636905597357,2.81820198280828E-5,0.25,-3.00664834393411E-7,1.60060598928606E-5,-2.71569107785441E-7,130.5003967,130.5003967,99.7613830566406,99.7613830566406,57.1612752398714,20.5844048140975,22.909004,0,0,0,40,4374,132.90205,99.7613830566406,,,,,,,,,,,,,0,,,,0.0049,,,,,,130.5003967,,,,
,26942880.24,134.0515137,99.7613830566406,1.69784111037071E-5,3.54447083684654E-7,1,0.999253354069792,40.0298881530762,1.99796930545505,19.8699999600649,0.000193933816478172,2.8660230721561E-5,0.25,-4.41748570445376E-7,1.70687350333525E-5,-4.12663718898983E-7,134.0515137,134.0515137,99.7613830566406,99.7613830566406,57.2245871499291,20.5869231293948,23.668306,0,0,0,40,4374,136.4784,99.7613830566406,,,,,,,,,,,,,0,,,,0,,,,,,134.0515137,,,,
,26943001.33,137.0571899,99.7613830566406,1.80602077201566E-5,3.52662123629953E-7,1,0.999253354069792,40.0298881530762,1.99797026817089,19.8400001972914,0.000205765074914013,3.34209187294478E-5,0.25,-2.105233434538E-7,1.81546484374911E-5,-1.79316900289903E-7,137.0571899,137.0571899,99.7613830566406,99.7613830566406,57.0369963053137,20.5880174227752,23.288654,0,0,0,40,4374,139.51295,99.7613830566406,,,,,,,,,,,,,0,,,,0,,,,,,137.0571899,,,,
,26943140.235,140.5270844,99.7613830566406,1.95129881056578E-5,3.55684993311494E-7,1,0.999253354069792,40.0298881530762,1.99808185784566,19.8400001972914,0.000222551293495623,3.47342874477095E-5,0.25,-3.47039775115104E-7,1.96137209970255E-5,-3.15206498053811E-7,140.5270844,140.5270844,99.7613830566406,99.7613830566406,57.0026046504676,20.5864648869341,23.668306,0,0,0,40,4374,143.0067,99.7613830566406,,,,,,,,,,,,,0,,,,0,,,,,,140.5270844,,,,
,26943279.98,144.0140076,99.7613830566406,2.1698191402513E-5,3.66429998647866E-7,1,0.999253354069792,40.0298881530762,1.99793329040743,19.8400001972914,0.000247040318058623,4.08916285431759E-5,0.25,-1.84602687425867E-7,2.18081029174272E-5,-1.49490232796701E-7,144.0140076,144.0140076,99.7613830566406,99.7613830566406,57.2191157502945,20.5885289679068,23.288654,0,0,0,40,4374,146.5168,99.7613830566406,,,,,,,,,,,,,0,,,,0.00245,,,,,,144.0140076,,,,
,26943421.355,147.54599,99.7613830566406,2.38691899168085E-5,3.4117055180516E-7,1,0.999253354069792,40.0298881530762,1.99797972559546,19.7999998927116,0.000272157441524651,4.25885806843305E-5,0.25,-4.12092627693096E-7,2.39884027363191E-5,-3.75862860412058E-7,147.54599,147.54599,99.7613830566406,99.7613830566406,56.9783741663714,20.5864256306168,23.288654,0,0,0,40,4374,150.05815,99.7613830566406,,,,,,,,,,,,,0,,,,-0.00245,,,,,,147.54599,,,,
,26943563.08,151.048233,99.7613830566406,2.67420291029042E-5,2.98561840449716E-7,1,0.999253354069792,40.0298881530762,1.99794752964583,19.7999998927116,0.000304362759740296,5.06931069527573E-5,0.25,-1.97782808022872E-7,2.6872840006064E-5,-1.57302936338906E-7,151.048233,151.048233,99.7613830566406,99.7613830566406,57.1120326431599,20.5867578173902,23.288654,0,0,0,40,4374,153.61215,99.7613830566406,,,,,,,,,,,,,0,,,,0,,,,,,151.048233,,,,
,26943702.68,154.5309753,99.7613830566406,3.04358023128639E-5,3.07339422123965E-7,1,0.999253354069792,40.0298881530762,1.99781384441913,19.7999998927116,0.000346217792032747,5.84474195331538E-5,0.25,-1.56643221522833E-7,3.05818629379555E-5,-1.11727679091094E-7,154.5309753,154.5309753,99.7613830566406,99.7613830566406,56.9306948266983,20.5871095984335,23.668306,0,0,0,40,4374,157.11185,99.7613830566406,,,,,,,,,,,,,0,,,,-0.00245,,,,,,154.5309753,,,,
,26943844.135,158.0478363,99.7613830566406,3.48706069615428E-5,3.31693070907536E-7,1,0.999253354069792,40.0298881530762,1.9979917927574,19.7599995881319,0.000396782402398545,6.62741436727497E-5,0.25,-2.38487903301738E-7,3.50348134120191E-5,-1.88920797796476E-7,158.0478363,158.0478363,99.7613830566406,99.7613830566406,57.004167907506,20.5839731828071,24.047956,0,0,0,40,4374,160.65935,99.7613830566406,,,,,,,,,,,,,0,,,,-0.0049,,,,,,158.0478363,,,,
,26943983.05,161.539917,99.7613830566406,3.96229420770808E-5,3.68399005204828E-7,1,0.999253354069792,40.0298881530762,1.99779594356655,19.7599995881319,0.000450975845819084,7.41285461294126E-5,0.25,-3.71708703114346E-7,3.98059358510373E-5,-3.17524769933238E-7,161.539917,161.539917,99.7613830566406,99.7613830566406,56.9830639374868,20.585985862119,24.427608,0,0,0,40,4374,164.13025,99.7613830566406,,,,,,,,,,,,,0,,,,0,,,,,,161.539917,,,,
,26944122.275,165.02148435,99.7613830566406,4.46769770107014E-5,3.60846811436633E-7,1,0.999253354069792,40.0298881530762,1.9978845026368,19.7599995881319,0.000507775944003007,8.75808951797768E-5,0.25,-6.5164946453209E-8,4.48785345138972E-5,-4.2421758955257E-9,164.9928894,165.0500793,99.7613830566406,99.7613830566406,56.7618630665445,20.5872833565538,23.668306,0,0,0,40,4374,167.618,99.7613830566406,,,,,,,,,,,,,0,,,,0.0049,,,,,,165.02148435,,,,
,26944262.22,168.5008698,99.7613830566406,5.07862087631566E-5,3.67035656404965E-7,1,0.999253354069792,40.0298881530762,1.99802606762671,19.7199992835522,0.000577391528250386,9.84141318529727E-5,0.25,-1.7246764921933E-7,5.10104987297223E-5,-1.05580045082981E-7,168.5008698,168.5008698,99.7613830566406,99.7613830566406,57.4012351952753,20.5867554098413,24.427608,0,0,0,40,4374,171.1152,99.7613830566406,,,,,,,,,,,,,0,,,,-0.00245,,,,,,168.5008698,,,,
,26944402.62,172.0160217,99.7613830566406,5.72208281556653E-5,2.48397878764167E-7,1,0.999253354069792,40.0298881530762,1.99788410757811,19.7199992835522,0.000650151533393236,0.000112510500586423,0.25,-4.73875597447365E-8,5.74675845953936E-5,2.65604867671669E-8,172.0160217,172.0160217,99.7613830566406,99.7613830566406,57.1432977839291,20.5866795666177,24.047956,0,0,0,40,4374,174.62805,99.7613830566406,,,,,,,,,,,,,0,,,,0,,,,,,172.0160217,,,,
,26944543.4,175.5437851,99.7613830566406,6.39380048939643E-5,3.91761374131075E-7,1,0.999253354069792,40.0298881530762,1.99802099718398,19.7199992835522,0.000726300962866641,0.000126548999544183,0.25,2.27625448156641E-8,6.42070626825916E-5,1.03530801306062E-7,175.514801,175.5727692,99.7613830566406,99.7613830566406,57.2011382943522,20.5849002122788,24.047956,0,0,0,40,4374,178.1496,99.7613830566406,,,,,,,,,,,,,0,,,,-0.00245,,,,,,175.5437851,,,,
,26944683.055,179.020752,99.7613830566406,7.0913596795292E-5,3.85336311554037E-7,1,0.999253354069792,40.0298881530762,1.99857320977671,19.6599997580051,0.000806069179089447,0.000138080491721054,0.25,-1.74714863981061E-7,7.12049588670219E-5,-8.82283018211005E-8,179.020752,179.020752,99.7613830566406,99.7613830566406,57.0463758475445,20.5822710920574,24.047956,0,0,0,40,4374,181.6399,99.7613830566406,,,,,,,,,,,,,0,,,,-0.0049,,,,,,179.020752,,,,
,26944824.655,182.5296326,99.7613830566406,7.80807456915573E-5,3.73357341195287E-7,1,0.999253354069792,40.0298881530762,1.99832012700859,19.6599997580051,0.000887831013820533,0.000149159967352773,0.25,-4.40151132145426E-7,7.83936177418553E-5,-3.48304563264002E-7,182.5296326,182.5296326,99.7613830566406,99.7613830566406,57.0838940164676,20.5870589235808,24.427608,0,0,0,40,4374,185.196,99.7613830566406,,,,,,,,,,,,,0,,,,0,,,,,,182.5296326,,,,
,26944963.135,186.0320892,99.7613830566406,8.50355677884624E-5,3.35564682227233E-7,1,0.999253354069792,40.0298881530762,1.99825124023476,19.6599997580051,0.000965803612753632,0.000168025739595477,0.25,1.63079685498993E-8,8.53666306403062E-5,1.15889439609638E-7,186.0320892,186.0320892,99.7613830566406,99.7613830566406,57.3183825722368,20.5890130683297,24.427608,0,0,0,40,4374,188.6634,99.7613830566406,,,,,,,,,,,,,0,,,,-0.0049,,,,,,186.0320892,,,,
,26945085.145,189.051178,99.7613830566406,9.03046937624775E-5,3.41196691287734E-7,1,0.999253354069792,40.0298881530762,1.9981193471794,19.6299999952316,0.00102541187364251,0.000178851503573405,0.25,5.83933245544227E-8,9.06478127503453E-5,1.62132493871947E-7,189.051178,189.051178,99.7613830566406,99.7613830566406,56.9689946241406,20.5878978130622,24.047956,0,0,0,40,4374,191.7226,99.7613830566406,,,,,,,,,,,,,0,,,,-0.0049,,,,,,189.051178,,,,
,26945223.385,192.5016479,99.7613830566406,9.58488918829194E-5,4.1338166498203E-7,1,0.999253354069792,40.0298881530762,1.99799934947623,19.6299999952316,0.00108896110434059,0.000185345908793588,0.25,-3.27890789435699E-7,9.62031894679416E-5,-2.21720431941419E-7,192.5016479,192.5016479,99.7613830566406,99.7613830566406,57.2746113751599,20.5922688933959,24.427608,0,0,0,40,4374,195.1942,99.7613830566406,,,,,,,,,,,,,0,,,,0,,,,,,192.5016479,,,,
,26945364.795,196.0028992,99.7613830566406,0.000101381961092286,4.01881959523872E-7,1,0.999253354069792,40.0298881530762,1.99792958284923,19.6299999952316,0.00115095957680347,0.000200039065850116,0.25,9.98819839755874E-9,0.000101745102550562,1.21032074055178E-7,196.0028992,196.0028992,99.7613830566406,99.7613830566406,56.8673829166406,20.5926882846241,24.807261,0,0,0,40,4374,198.75165,99.7613830566406,,,,,,,,,,,,,0,,,,0,,,,,,196.0028992,,,,
,26945485.07,199.0262604,99.7613830566406,0.000105806626414285,3.93697305871924E-7,1,0.999253354069792,40.0298881530762,1.99784926938977,19.5799991488457,0.00120088812261111,0.000209557498287844,0.25,8.44755428144973E-8,0.000106175324067057,1.98448378562003E-7,199.0262604,199.0262604,99.7613830566406,99.7613830566406,56.9658681100637,20.5878308946562,24.427608,0,0,0,40,4374,201.764,99.7613830566406,,,,,,,,,,,,,0,,,,0,,,,,,199.0262604,,,,
,26945624.515,202.50784305,99.7613830566406,0.000109304729667252,4.03930233466609E-7,1,0.999253354069792,40.0298881530762,1.99802027826967,19.5799991488457,0.00124092218691384,0.000214356819491445,0.25,-9.72371548803086E-8,0.000109673546989597,1.73792088314073E-8,202.4758301,202.539856,99.7613830566406,99.7613830566406,56.9189703989099,20.5925929972629,24.807261,0,0,0,40,4374,205.25155,99.7613830566406,,,,,,,,,,,,,0,,,,0.00245,,,,,,202.50784305,,,,
,26945765.455,206.0042114,99.7613830566406,0.000112754730367322,3.37604087688343E-7,1,0.999253354069792,40.0298881530762,1.99809936825007,19.5799991488457,0.00128082088057731,0.000216336384376533,0.25,-5.18044223583393E-7,0.000113122788114454,-4.03651348197651E-7,206.0042114,206.0042114,99.7613830566406,99.7613830566406,56.9197520274291,20.5910288112734,24.427608,0,0,0,40,4374,208.78485,99.7613830566406,,,,,,,,,,,,,0,,,,0,,,,,,206.0042114,,,,
,26945905.42,209.5323944,99.7613830566406,0.000115069913678676,4.80005205198731E-7,1,0.999253354069792,40.0298881530762,1.99788910254499,19.5300001651049,0.00130604593787033,0.000225289589343821,0.25,-1.24553436246275E-7,0.000115431770200072,-8.88942418761758E-9,209.5323944,209.5323944,99.7613830566406,99.7613830566406,56.7579549239483,20.5895400120078,24.807261,0,0,0,40,4374,212.2817,99.7613830566406,,,,,,,,,,,,,0,,,,0.00245,,,,,,209.5323944,,,,
,26946046.27,213.0191193,99.7613830566406,0.000116527542255827,3.69892883363392E-7,1,0.999253354069792,40.0298881530762,1.99773858730099,19.5300001651049,0.00132202248784154,0.000229945038409625,0.25,3.87664730287182E-8,0.00011688035881541,1.54045476331215E-7,213.0191193,213.0191193,99.7613830566406,99.7613830566406,56.9049010855637,20.5938662549779,24.427608,0,0,0,40,4374,215.8158,99.7613830566406,,,,,,,,,,,,,0,,,,-0.00245,,,,,,213.0191193,,,,
,26946185.76,216.5026398,99.7613830566406,0.000117039653968127,3.73271743141397E-7,1,0.999253354069792,40.0298881530762,1.99799306620911,19.5300001651049,0.0013277212398018,0.000231640189779894,0.25,1.01398951819995E-7,0.000117380344683849,2.15105457153827E-7,216.5026398,216.5026398,99.7613830566406,99.7613830566406,57.2433462343907,20.5907589991162,24.427608,0,0,0,40,4374,219.31395,99.7613830566406,,,,,,,,,,,,,0,,,,-0.00245,,,,,,216.5026398,,,,
,26946327.26,220.0339661,99.7613830566406,0.000116818237994219,3.85542645339959E-7,1,0.999253354069792,40.0298881530762,1.99807711565307,19.4899998605251,0.00132570968359611,0.000227703293081128,0.25,-2.03413667544797E-7,0.000117144693425557,-9.2975111526242E-8,220.0339661,220.0339661,99.7613830566406,99.7613830566406,57.0838940164676,20.5923823097644,24.807261,0,0,0,40,4374,222.8529,99.7613830566406,,,,,,,,,,,,,0,,,,0,,,,,,220.0339661,,,,
,26946467.215,223.5528259,99.7613830566406,0.000116238487814157,3.72411112738171E-7,1,0.999253354069792,40.0298881530762,1.99821466817265,19.4899998605251,0.00132008441374559,0.000220658527778978,0.25,-7.20652281101308E-7,0.00011654993943676,-6.14202720219695E-7,223.5528259,223.5528259,99.7613830566406,99.7613830566406,57.0205821064099,20.5881655365148,25.186911,0,0,0,40,4374,226.3623,99.7613830566406,,,,,,,,,,,,,0,,,,-0.0049,,,,,,223.5528259,,,,
,26946609.22,227.0621185,99.7613830566406,0.000115293838839799,3.90960721264291E-7,1,0.999253354069792,40.0298881530762,1.9983414970179,19.4899998605251,0.00130814145799284,0.000225409183906529,0.25,-1.34794643598286E-7,0.000115588416998859,-2.9657031913628E-8,227.0621185,227.0621185,99.7613830566406,99.7613830566406,56.9979148793522,20.5935104111108,24.807261,0,0,0,40,4374,229.91975,99.7613830566406,,,,,,,,,,,,,0,,,,-0.0049,,,,,,227.0621185,,,,
,26946749.05,230.5406647,99.7613830566406,0.000113559538277408,3.75598039761141E-7,1,0.999253354069792,40.0298881530762,1.9981280393366,19.4400008767843,0.00128785821162491,0.000223818559611761,0.25,3.21518765509812E-8,0.00011383597970458,1.34234177087998E-7,230.5406647,230.5406647,99.7613830566406,99.7613830566406,56.9174071418714,20.5886002169439,24.807261,0,0,0,40,4374,233.4375,99.7613830566406,,,,,,,,,,,,,0,,,,-0.0049,,,,,,230.5406647,,,,
,26946886.71,234.0081635,99.7613830566406,0.000111784479428949,4.06353331498666E-7,1,0.999253354069792,40.0298881530762,1.9980119869663,19.4400008767843,0.00126774849670545,0.000218883455517459,0.25,-8.9897017525488E-8,0.000112043328431802,8.54287195896234E-9,234.0081635,234.0081635,99.7613830566406,99.7613830566406,56.7587365524675,20.5884316634093,24.807261,0,0,0,40,4374,236.884,99.7613830566406,,,,,,,,,,,,,0,,,,0,,,,,,234.0081635,,,,
,26947028.365,237.52404785,99.7613830566406,0.000110289213982097,3.63382348076302E-7,1,0.999253354069792,40.0298881530762,1.99803742528489,19.4400008767843,0.00125026311787436,0.000218183311583327,0.25,1.11586235566712E-7,0.000110530975243614,2.07427826561222E-7,237.4946594,237.5534363,99.7613830566406,99.7613830566406,57.0838940164676,20.5916176416682,25.186911,0,0,0,40,4374,240.4371,99.7613830566406,,,,,,,,,,,,,0,,,,-0.00245,,,,,,237.52404785,,,,
,26947168.82,241.0123749,99.7613830566406,0.000107503881309625,3.67312328713921E-7,1,0.999253354069792,40.0298881530762,1.99845566022612,19.3900000303984,0.00121952050205212,0.000208441045343383,0.25,-2.64326518016515E-7,0.000107726786150194,-1.73311033488687E-7,241.0123749,241.0123749,99.7613830566406,99.7613830566406,56.7571732954291,20.5784584868376,25.566563,0,0,0,40,4374,243.963,99.7613830566406,,,,,,,,,,,,,0,,,,-0.0049,,,,,,241.0123749,,,,
,26947309.305,244.5074005,99.7613830566406,0.000105568525640119,4.64907936316783E-7,1,0.999253354069792,40.0298881530762,1.99847909276499,19.3900000303984,0.00119705387959163,0.000206851832642066,0.25,-6.52414140515951E-8,0.000105774334724012,2.30095143433756E-8,244.5074005,244.5074005,99.7613830566406,99.7613830566406,57.1690915250637,20.5803838760819,25.566563,0,0,0,40,4374,247.48205,99.7613830566406,,,,,,,,,,,,,0,,,,0,,,,,,244.5074005,,,,
,26947448.75,248.0014954,99.7613830566406,0.00010289151821524,4.46024374690576E-7,1,0.999253354069792,40.0298881530762,1.99856080110996,19.3900000303984,0.0011667349936038,0.000200819673783019,0.25,-1.30072812621531E-7,0.000103079525901388,-4.56163618066995E-8,248.0014954,248.0014954,99.7613830566406,99.7613830566406,57.1956668947176,20.5786501050408,25.566563,0,0,0,40,4374,250.98185,99.7613830566406,,,,,,,,,,,,,0,,,,0.00245,,,,,,248.0014954,,,,
,26947589.61,251.5246429,99.7613830566406,0.000100421743385782,3.96396415052488E-7,1,0.999253354069792,40.0298881530762,1.99842893363633,19.3499997258186,0.00113844945010816,0.000196346813711611,0.25,-9.16914637877193E-8,0.000100592727603211,-1.05619344976119E-8,251.5246429,251.5246429,99.7613830566406,99.7613830566406,56.7978179784291,20.5784011835861,25.186911,0,0,0,40,4374,254.5074,99.7613830566406,,,,,,,,,,,,,0,,,,-0.00245,,,,,,251.5246429,,,,
,26947730.105,255.0213318,99.7613830566406,9.81484740113429E-5,3.93134454436564E-7,1,0.999253354069792,40.0298881530762,1.99836603068482,19.3499997258186,0.00111330999650106,0.000187242894370805,0.25,-4.96838050278096E-7,9.83037661103305E-5,-4.19474966983254E-7,255.0213318,255.0213318,99.7613830566406,99.7613830566406,56.9299131981791,20.582271010771,25.566563,0,0,0,40,4374,258.0175,99.7613830566406,,,,,,,,,,,,,0,,,,0,,,,,,255.0213318,,,,
,26947870.4,258.5063782,99.7613830566406,9.61061158598395E-5,4.00067106287097E-7,1,0.999253354069792,40.0298881530762,1.9981487314489,19.3499997258186,0.00108954694703017,0.000185315129853463,0.25,-3.0786158101003E-7,9.6246145095741E-5,-2.33022307477987E-7,258.5063782,258.5063782,99.7613830566406,99.7613830566406,56.9752476522945,20.5791740666242,25.566563,0,0,0,40,4374,261.5275,99.7613830566406,,,,,,,,,,,,,0,,,,0,,,,,,258.5063782,,,,
,26947992.845,261.5441284,99.7613830566406,9.44044028461182E-5,4.01173276707466E-7,1,0.999253354069792,40.0298881530762,1.99828894660003,19.3000007420778,0.00106952547470465,0.0001859800432134,0.25,4.75637826557399E-8,9.45314796903822E-5,1.20548777939823E-7,261.5441284,261.5441284,99.7613830566406,99.7613830566406,57.0510656186599,20.5890140464442,25.566563,0,0,0,40,4374,264.6023,99.7613830566406,,,,,,,,,,,,,0,,,,-0.0049,,,,,,261.5441284,,,,
,26948132,265.0083008,99.7613830566406,9.14955527843639E-5,4.86340253294295E-7,1,0.999253354069792,40.0298881530762,1.9984715640774,19.3000007420778,0.00103634243519098,0.000181343051779221,0.25,1.44280977211543E-7,9.1607343652694E-5,2.14032573122712E-7,265.0083008,265.0083008,99.7613830566406,99.7613830566406,57.0776409883137,20.5821132210446,25.186911,0,0,0,40,4374,268.0688,99.7613830566406,,,,,,,,,,,,,0,,,,0.0049,,,,,,265.0083008,,,,
,26948270.77,268.5077515,99.7613830566406,8.93517589375516E-5,3.7020946687293E-7,1,0.999253354069792,40.0298881530762,1.99825535787417,19.3000007420778,0.00101286372260112,0.000171087889098754,0.25,-3.84736426423427E-7,8.94501616444713E-5,-3.18265194158924E-7,268.5077515,268.5077515,99.7613830566406,99.7613830566406,56.9002113144483,20.5911156928155,25.186911,0,0,0,40,4374,271.56165,99.7613830566406,,,,,,,,,,,,,0,,,,0,,,,,,268.5077515,,,,
,26948414.485,272.04953,99.7613830566406,8.71477588879464E-5,3.76339777183231E-7,1,0.999253354069792,40.0298881530762,1.99831677171446,19.2499998956919,0.000987300788290507,0.000169638262916637,0.25,-1.28186582710861E-7,8.72325131912951E-5,-6.40913564382462E-8,272.04953,272.04953,99.7613830566406,99.7613830566406,57.2222422643714,20.5831281499768,25.566563,0,0,0,40,4374,275.1507,99.7613830566406,,,,,,,,,,,,,0,,,,0.00245,,,,,,272.04953,,,,
,26948553.395,275.5198669,99.7613830566406,8.52012934464251E-5,3.8033381246552E-7,1,0.999253354069792,40.0298881530762,1.99809608477383,19.2499998956919,0.000965068619671899,0.000165575049887483,0.25,-1.4525170430647E-7,8.52735846366091E-5,-8.35325106796805E-8,275.5198669,275.5198669,99.7613830566406,99.7613830566406,56.821266834006,20.583010714912,25.186911,0,0,0,40,4374,278.6283,99.7613830566406,,,,,,,,,,,,,0,,,,0,,,,,,275.5198669,,,,
,26948694.165,279.0320129,99.7613830566406,8.33345829592838E-5,4.65485031446183E-7,1,0.999253354069792,40.0298881530762,1.99832616590366,19.2499998956919,0.000943427600114145,0.000164725756758941,0.25,1.04416633445625E-7,8.33946283744698E-5,1.64075738936995E-7,279.0320129,279.0320129,99.7613830566406,99.7613830566406,57.139389641333,20.5846133765135,25.566563,0,0,0,40,4374,282.12985,99.7613830566406,,,,,,,,,,,,,0,,,,0.0049,,,,,,279.0320129,,,,
,26948833.47,282.5255737,99.7613830566406,8.06662692289922E-5,3.88995434109523E-7,1,0.999253354069792,40.0298881530762,1.99832206551691,19.2000009119511,0.000913238013095513,0.000158656080437328,0.25,3.34640491329378E-8,8.0714342488268E-5,9.03091280295513E-8,282.5255737,282.5255737,99.7613830566406,99.7613830566406,56.9729027667368,20.5799057379078,25.566563,0,0,0,40,4374,285.63175,99.7613830566406,,,,,,,,,,,,,0,,,,0.00245,,,,,,282.5255737,,,,
,26948973.97,286.0128174,99.7613830566406,7.91180499224081E-5,3.8782712651104E-7,1,0.999253354069792,40.0298881530762,1.99834534123402,19.2000009119511,0.00089554977659407,0.000155931716641713,0.25,6.3520261904632E-8,7.91552927706678E-5,1.18471860908503E-7,286.0128174,286.0128174,99.7613830566406,99.7613830566406,56.8439340610637,20.5815080105697,26.325863,0,0,0,40,4374,289.1385,99.7613830566406,,,,,,,,,,,,,0,,,,-0.0049,,,,,,286.0128174,,,,
,26949115.085,289.5061646,99.7613830566406,7.70694467659186E-5,4.25119335411409E-7,1,0.999253354069792,40.0298881530762,1.99822583552719,19.2000009119511,0.000873609955101714,0.000143743651876948,0.25,-6.55005248733901E-7,7.70965719030758E-5,-6.02508616299624E-7,289.5061646,289.5061646,99.7613830566406,99.7613830566406,56.7220000120637,20.5838754972169,25.566563,0,0,0,40,4374,292.6737,99.7613830566406,,,,,,,,,,,,,0,,,,0,,,,,,289.5061646,,,,
,26949255.545,293.0245361,99.7613830566406,7.56387693154481E-5,4.60566279188775E-7,1,0.999253354069792,40.0298881530762,1.99815047497689,19.1500000655651,0.000856832191045629,0.000143485730009055,0.25,-4.27097926140688E-7,7.56557112053168E-5,-3.76185629788945E-7,293.0245361,293.0245361,99.7613830566406,99.7613830566406,56.8157954343714,20.5796281333803,25.946213,0,0,0,40,4374,296.1971,99.7613830566406,,,,,,,,,,,,,0,,,,0.00245,,,,,,293.0245361,,,,
,26949397.595,296.5214539,99.7613830566406,7.30656873571561E-5,4.05922206783358E-7,1,0.999253354069792,40.0298881530762,1.99823742416973,19.1500000655651,0.00082813001284095,0.000135622157090838,0.25,-6.7441699752452E-7,7.30730850084042E-5,-6.25907798049056E-7,296.5214539,296.5214539,99.7613830566406,99.7613830566406,56.9322580837368,20.5779636611193,25.946213,0,0,0,40,4374,299.7445,99.7613830566406,,,,,,,,,,,,,0,,,,0,,,,,,296.5214539,,,,
,26949537.685,300.0221558,99.7613830566406,7.11896295374337E-5,4.03851384565022E-7,1,0.999253354069792,40.0298881530762,1.99835935692736,19.1500000655651,0.000805659377577758,0.000138787958142757,0.25,-6.81381287135802E-8,7.11875428135749E-5,-2.14622333037742E-8,300.0221558,300.0221558,99.7613830566406,99.7613830566406,56.9510171681983,20.5791848300097,26.325863,0,0,0,40,4374,303.2462,99.7613830566406,,,,,,,,,,,,,0,,,,0,,,,,,300.0221558,,,,
,26949658.375,303.0571289,99.7613830566406,7.04079208851354E-5,4.2009124334228E-7,1,0.999253354069792,40.0298881530762,1.99833875055194,19.0999992191792,0.000796896119548776,0.000136223098885208,0.25,-1.57419798072934E-7,7.03982931258544E-5,-1.11778733632368E-7,303.0571289,303.0571289,99.7613830566406,99.7613830566406,57.0260535060445,20.5777473288101,25.946213,0,0,0,40,4374,306.26835,99.7613830566406,,,,,,,,,,,,,0,,,,0,,,,,,303.0571289,,,,
,26949798.94,306.5296631,99.7613830566406,6.903099968803E-5,4.06765812749332E-7,1,0.999253354069792,40.0298881530762,1.99847683932595,19.0999992191792,0.000781437854870065,0.000132563066704008,0.25,-2.41102173251987E-7,6.90130806856209E-5,-1.96913787537451E-7,306.5296631,306.5296631,99.7613830566406,99.7613830566406,56.9744660237753,20.5789186622705,26.325863,0,0,0,40,4374,309.7869,99.7613830566406,,,,,,,,,,,,,0,,,,0,,,,,,306.5296631,,,,
,26949939.08,310.0309143,99.7613830566406,6.72607277081562E-5,4.07752525852397E-7,1,0.999253354069792,40.0298881530762,1.99848065677616,19.0999992191792,0.000761506280388392,0.000127984862817887,0.25,-3.37150225516595E-7,6.72349660067076E-5,-2.94598644772894E-7,310.0309143,310.0309143,99.7613830566406,99.7613830566406,56.6125720193714,20.5785198081137,26.325863,0,0,0,40,4374,313.3256,99.7613830566406,,,,,,,,,,,,,0,,,,-0.0049,,,,,,310.0309143,,,,
,26950059.905,313.0057068,99.7613830566406,6.5451537769386E-5,4.12588599154346E-7,1,0.999253354069792,40.0298881530762,1.99844960044767,19.0399996936321,0.000740956213784864,0.000124399115563067,0.25,-3.389577158955E-7,6.54195745623369E-5,-2.97973726026976E-7,313.0057068,313.0057068,99.7613830566406,99.7613830566406,56.983845566006,20.5832459548866,25.946213,0,0,0,40,4374,316.35325,99.7613830566406,,,,,,,,,,,,,0,,,,-0.00245,,,,,,313.0057068,,,,
,26950201.87,316.5436096,99.7613830566406,6.41495907533169E-5,4.44144578041473E-7,1,0.999253354069792,40.0298881530762,1.998521141038,19.0399996936321,0.000725938399683577,0.000123142168296912,0.25,-2.23059797795896E-7,6.41101734240993E-5,-1.83437280604362E-7,316.5121765,316.5750427,99.7613830566406,99.7613830566406,56.8626931455252,20.5819317732943,26.325863,0,0,0,40,4374,319.9302,99.7613830566406,,,,,,,,,,,,,0,,,,-0.0049,,,,,,316.5436096,,,,
,26950343.985,320.0953674,99.7613830566406,6.25470646479838E-5,3.72426084295379E-7,1,0.999253354069792,40.0298881530762,1.99840721340799,19.0399996936321,0.0007079538347435,0.000118443440560909,0.25,-3.58586326280702E-7,6.25008911918163E-5,-3.20309299418239E-7,320.0953674,320.0953674,99.7613830566406,99.7613830566406,56.8736359447945,20.5815264234325,26.705515,0,0,0,40,4374,323.4814,99.7613830566406,,,,,,,,,,,,,0,,,,0.00245,,,,,,320.0953674,,,,
,26950481.89,323.5020142,99.7613830566406,6.10569710140396E-5,4.34352437078522E-7,1,0.999253354069792,40.0298881530762,1.99861939870849,18.9800001680851,0.000690654974197548,0.000118045632411832,0.25,-1.35042701892532E-7,6.10044663743317E-5,-9.82690623449745E-8,323.5020142,323.5020142,99.7613830566406,99.7613830566406,56.912717370756,20.5751611929609,26.325863,0,0,0,40,4374,326.93985,99.7613830566406,,,,,,,,,,,,,0,,,,0.0049,,,,,,323.5020142,,,,
,26950624.07,327.0227356,99.7613830566406,5.96998153282372E-5,4.8630925286801E-7,1,0.999253354069792,40.0298881530762,1.99853090925527,18.9800001680851,0.000675655604771047,0.000112723343894661,0.25,-3.68600099859873E-7,5.96412696402073E-5,-3.32832227031553E-7,327.0227356,327.0227356,99.7613830566406,99.7613830566406,56.811105663256,20.5776996421031,26.325863,0,0,0,40,4374,330.5149,99.7613830566406,,,,,,,,,,,,,0,,,,0,,,,,,327.0227356,,,,
,26950765.985,330.5383606,99.7613830566406,5.82712160418435E-5,3.88971925778627E-7,1,0.999253354069792,40.0298881530762,1.99862682815759,18.9800001680851,0.000659516192397481,0.00010955876639884,0.25,-3.99950551760114E-7,5.82069619623191E-5,-3.65359088927216E-7,330.5383606,330.5383606,99.7613830566406,99.7613830566406,57.0729512171983,20.5768662419012,27.085165,0,0,0,40,4374,334.06695,99.7613830566406,,,,,,,,,,,,,0,,,,-0.00245,,,,,,330.5383606,,,,
,26950904.985,334.015625,99.7613830566406,5.69258049789746E-5,4.42942327123177E-7,1,0.999253354069792,40.0298881530762,1.99885450274283,18.9399998635054,0.000644185460949369,0.000107579981212577,0.25,-3.4150736545988E-7,5.68561453617912E-5,-3.0810366262678E-7,333.9846191,334.0466309,99.7613830566406,99.7613830566406,56.6813553290637,20.5738523547135,25.946213,0,0,0,40,4374,337.536,99.7613830566406,,,,,,,,,,,,,0,,,,-0.00245,,,,,,334.015625,,,,
,26951044.915,337.5178223,99.7613830566406,5.51120382013864E-5,4.47517455893985E-7,1,0.999253354069792,40.0298881530762,1.99883039936164,18.9399998635054,0.00062383165405222,0.000102672967176169,0.25,-4.5993318573232E-7,5.50380166316444E-5,-4.27733189371722E-7,337.5178223,337.5178223,99.7613830566406,99.7613830566406,56.9111541137176,20.5762122183675,26.705515,0,0,0,40,4374,341.0435,99.7613830566406,,,,,,,,,,,,,0,,,,0.0049,,,,,,337.5178223,,,,
,26951187.09,341.0542297,99.7613830566406,5.35669839158001E-5,4.84054488057278E-7,1,0.999253354069792,40.0298881530762,1.99877595417015,18.9399998635054,0.000606373225935975,9.90870484728863E-5,0.25,-5.08008964780852E-7,5.34885748459065E-5,-4.76902704061205E-7,341.0542297,341.0542297,99.7613830566406,99.7613830566406,56.9416376259676,20.5765371282812,26.705515,0,0,0,40,4374,344.607,99.7613830566406,,,,,,,,,,,,,0,,,,-0.0049,,,,,,341.0542297,,,,
,26951328.86,344.5487366,99.7613830566406,5.28096005847864E-5,4.76668668708692E-7,1,0.999253354069792,40.0298881530762,1.99897417530842,18.8699997961521,0.000596897521619863,0.000102808661669927,0.25,-4.7015542200787E-8,5.27257528658329E-5,-1.73258180068108E-8,344.5487366,344.5487366,99.7613830566406,99.7613830566406,56.9713395096983,20.5734717724253,26.705515,0,0,0,40,4374,348.1713,99.7613830566406,,,,,,,,,,,,,0,,,,-0.00245,,,,,,344.5487366,,,,
,26951467.925,348.015686,99.7613830566406,5.16541812699049E-5,4.35363210660562E-7,1,0.999253354069792,40.0298881530762,1.99892841074633,18.8699997961521,0.000585274960193333,9.17761287678275E-5,0.25,-8.21767425262994E-7,5.1566531834423E-5,-7.91686162714988E-7,347.9884338,348.0429382,99.7613830566406,99.7613830566406,57.0815491309099,20.5758692971808,27.085165,0,0,0,40,4374,351.6502,99.7613830566406,,,,,,,,,,,,,0,,,,-0.00245,,,,,,348.015686,,,,
,26951790.045,349.7524109,99.7613830566406,5.08675413168326E-5,4.80856068149537E-7,1,0.999253354069792,40.0298881530762,1.99901991900495,18.8699997961521,0.00057469141781083,9.9973406287088E-5,0.25,3.99489393526411E-8,5.07777606517779E-5,6.81986590045474E-8,349.7524109,349.7524109,99.7613830566406,99.7613830566406,56.9588334533906,20.5759923595026,26.705515,0,0,0,40,4369,350.65,99.7613830566406,,,,,,,,,,,,,0,,,,0,,,,,,349.7524109,,,,