File: data/monolayers/nanoparticles/Ol_CoFe_C/vsm/ZFCFC/DD172_6_FCW_100OE.DAT
[Header]
; VSM Data File (default extension .dat)
; Copyright (c) 2003-2013, Quantum Design, Inc. All rights reserved.
TITLE,
FILEOPENTIME,26965705.44,11/09/2018,10:28 am
BYAPP,VSM,2.0,2.0
INFO,PPMS VSM Option Release 1.4.10 Build 1,APPNAME
INFO,Quantum Design Linear Motor Servo Controller,MOTOR_MODULE_NAME
INFO,3101-100 M1,MOTOR_HW_VERSION
INFO,MMC1014,MOTOR_SERIAL_NUMBER
INFO,SRV No X-over 01.03.11,MOTOR_SOFTWARE_VERSION
INFO,Quantum Design VSM Detection Module,VSM_MODULE_NAME
INFO,3101-150 F0,VSM_HW_VERSION
INFO,VSM707,VSM_SERIAL_NUMBER
INFO,VSM No X-over 01.02.05 May 20 2008 13:51:47,VSM_SOFTWARE_VERSION
INFO,704,PREAMP_SERIAL_NUMBER
INFO,822,COIL_SERIAL_NUMBER
INFO,0,MOMENT_UNITS
INFO,CoFe2O4 DD67,SAMPLE_MATERIAL
INFO,Colloidal Crystal,SAMPLE_COMMENT
INFO,31.86,SAMPLE_MASS
INFO,,SAMPLE_VOLUME
INFO,,SAMPLE_MOLECULAR_WEIGHT
INFO,,SAMPLE_SIZE
INFO,,SAMPLE_SHAPE
DATATYPE,COMMENT,1
DATATYPE,TIME,2
STARTUPAXIS,X,2
STARTUPAXIS,Y1,5
[Data]
Comment,Time Stamp (sec),Temperature (K),Magnetic Field (Oe),Moment (emu),M. Std. Err. (emu),Transport Action,Averaging Time (sec),Frequency (Hz),Peak Amplitude (mm),Center Position (mm),Coil Signal' (mV),Coil Signal" (mV),Range (mV),M. Quad. Signal (emu),M. Raw' (emu),M. Raw" (emu),Min. Temperature (K),Max. Temperature (K),Min. Field (Oe),Max. Field (Oe),Mass (grams),Motor Lag (deg),Pressure (Torr),VSM Status (code),Motor Status (code),Measure Status (code),Measure Count,PPMS Status (code),System Temp. (K),System Field (Oe),Sample Position (deg),Bridge 1 Resistance (ohms),Bridge 1 Excitation (에),Bridge 2 Resistance (ohms),Bridge 2 Excitation (에),Bridge 3 Resistance (ohms),Bridge 3 Excitation (에),Bridge 4 Resistance (ohms),Bridge 4 Excitation (에),Signal 1 Vin (V),Signal 2 Vin (V),Digital Inputs (code),Drive 1 Iout (mA),Drive 1 Ipower (W),Drive 2 Iout (mA),Drive 2 Ipower (W),Pressure (),Map 20 (),Map 21 (),Map 22 (),Map 23 (),Map 24 (),Map 25 (),Map 26 (),Map 27 (),Map 28 (),Map 29 ()
,26965841.57,10.0051603,99.7613830566406,0.000170116429820346,3.49604495137435E-7,1,0.999253354069792,40.0298881530762,1.99822672503253,20.2099997550249,0.00191114260873178,0.000346682970976554,0.25,6.303560943225E-7,0.000169136560810921,1.44718008430977E-6,10.0051603,10.0051603,99.7613830566406,99.7613830566406,56.9244417985445,20.5947323501612,12.658426,0,0,0,40,4369,9.9891,99.7613830566406,,,,,,,,,,,,,0,,,,0,,,,,,10.0051603,,,,
,26965971.565,13.0476351,99.7613830566406,0.000169935025787429,3.76914579048066E-7,1,0.999253354069792,40.0298881530762,1.99823686160454,20.2099997550249,0.0019086395325291,0.000348920541935574,0.25,8.61644518972913E-7,0.000168954081679583,1.67625560728494E-6,13.0476351,13.0476351,99.7613830566406,99.7613830566406,57.0862389020253,20.5893249517769,13.797379,0,0,0,40,4370,13.1371,99.7613830566406,,,,,,,,,,,,,0,,,,-0.00245,,,,,,13.0476351,,,,
,26966111.79,16.5189323,99.7613830566406,0.000169786332275632,2.94461754254906E-7,1,0.999253354069792,40.0298881530762,1.9982007364003,20.2099997550249,0.00190709506979715,0.000347610132659585,0.25,7.72312699799692E-7,0.000168805052149188,1.58670490648635E-6,16.5189323,16.5189323,99.7613830566406,99.7613830566406,57.0315249056791,20.5924964811077,14.177031,0,0,0,40,4370,16.65675,99.7613830566406,,,,,,,,,,,,,0,,,,0,,,,,,16.5189323,,,,
,26966265.97,20.3654613,99.7613830566406,,,2,,,,20.2499996969104,,,,,,,20.3654613,20.3654613,99.7613830566406,99.7613830566406,,,14.177031,,,,-99999999,4370,20.5162,99.7613830566406,,,,,,,,,,,,,,,,,,,,,,,20.3654613,,,,
,26966393.61,23.5066433,99.7613830566406,0.0001696833402446,2.95354385915676E-7,1,0.999253354069792,40.0298881530762,1.99752054526355,20.2399995177984,0.0019057246997231,0.000346293673542625,0.25,6.51990784680384E-7,0.000168722770091024,1.4945133848707E-6,23.5066433,23.5066433,99.7613830566406,99.7613830566406,57.0463758475445,20.5961779528614,15.315984,0,0,0,40,4370,23.7383,99.7613830566406,,,,,,,,,,,,,0,,,,-0.00245,,,,,,23.5066433,,,,
,26966535.78,27.0349255,99.7613830566406,0.000169723169921978,3.42533500343264E-7,1,0.999253354069792,40.0298881530762,1.99757867892254,20.2399995177984,0.00190638063467609,0.000347875908370691,0.25,7.36645751471116E-7,0.000168797828927721,1.62057441310139E-6,27.0349255,27.0349255,99.7613830566406,99.7613830566406,57.1894138665637,20.5992442503828,14.936333,0,0,0,40,4370,27.3297,99.7613830566406,,,,,,,,,,,,,0,,,,0,,,,,,27.0349255,,,,
,26966686.03,30.7816429,99.7613830566406,,,2,,,,20.2499996969104,,,,,,,30.7816429,30.7816429,99.7613830566406,99.7613830566406,,,15.315984,,,,-99999999,4370,31.0926,99.7613830566406,,,,,,,,,,,,,,,,,,,,,,,30.7816429,,,,
,26966818.705,34.0489578,99.7613830566406,0.000169580949888699,2.965698281371E-7,1,0.999253354069792,40.0298881530762,1.99786670297656,20.2399995177984,0.00190606686185892,0.000351239516845923,0.25,9.00699031261893E-7,0.000168797495695816,1.91369264783723E-6,34.014904,34.0830116,99.7613830566406,99.7613830566406,57.0409044479099,20.5996877726179,16.075285,0,0,0,40,4370,34.44715,99.7613830566406,,,,,,,,,,,,,0,,,,-0.0049,,,,,,34.0489578,,,,
,26966957.915,37.5024033,99.7613830566406,0.000169482028623445,3.64051956957351E-7,1,0.999253354069792,40.0298881530762,1.99773364251773,20.2399995177984,0.00190710966336976,0.000345654041673105,0.25,3.27228414693084E-7,0.000168814995849286,1.41894368243537E-6,37.5024033,37.5024033,99.7613830566406,99.7613830566406,56.9588334533906,20.5959867971373,16.075285,0,0,0,40,4370,37.9592,99.7613830566406,,,,,,,,,,,,,0,,,,0.00245,,,,,,37.5024033,,,,
,26967106,41.1719627,99.7613830566406,,,2,,,,20.2400000864267,,,,,,,41.1719627,41.1719627,99.7613830566406,99.7613830566406,,,16.454937,,,,-99999999,4370,41.6962,99.7613830566406,,,,,,,,,,,,,,,,,,,,,,,41.1719627,,,,
,26967241.915,44.5041504,99.7613830566406,0.000169267870252461,3.22078763922042E-7,1,0.999253354069792,40.0298881530762,1.99763106218051,20.2300008386374,0.00190731564107324,0.000350718341307432,0.25,6.28849337460086E-7,0.000168915970715813,1.85067230114542E-6,44.5041504,44.5041504,99.7613830566406,99.7613830566406,56.9689946241406,20.5981298148796,16.834587,0,0,0,40,4370,45.1422,99.7613830566406,,,,,,,,,,,,,0,,,,-0.00245,,,,,,44.5041504,,,,
,26967385.52,48.0337143,99.7613830566406,0.000168917674620109,3.72088058784352E-7,1,0.999253354069792,40.0298881530762,1.99751144512696,20.2300008386374,0.00190511807658587,0.000352011583612966,0.25,7.42293594533447E-7,0.000168756137381207,1.99434987705559E-6,48.0337143,48.0337143,99.7613830566406,99.7613830566406,57.1128142716791,20.6043563181894,17.214239,0,0,0,40,4370,48.79835,99.7613830566406,,,,,,,,,,,,,0,,,,0.0049,,,,,,48.0337143,,,,
,26967529.75,51.5536232,99.7613830566406,,,2,,,,20.2199999341369,,,,,,,51.5536232,51.5536232,99.7613830566406,99.7613830566406,,,17.593889,,,,-99999999,4370,52.4761,99.7613830566406,,,,,,,,,,,,,,,,,,,,,,,51.5536232,,,,
,26967653.465,54.5139961,99.7613830566406,0.000168304461420044,3.14090958329336E-7,1,0.999253354069792,40.0298881530762,1.99744160334401,20.2099997550249,0.00190278259148696,0.000347855954250967,0.25,4.47144143230257E-7,0.000168499711132158,1.67227264775837E-6,54.4792442,54.548748,99.7613830566406,99.7613830566406,57.2707032325638,20.6068009423407,19.112494,0,0,0,40,4374,55.6668,99.7613830566406,,,,,,,,,,,,,0,,,,0,,,,,,54.5139961,,,,
,26967796.89,58.0028191,99.7613830566406,0.000168529399068257,3.98484338040626E-7,1,0.999253354069792,40.0298881530762,1.99745725923313,20.2099997550249,0.00190774356914485,0.000345710589055944,0.25,2.38317593142082E-7,0.00016889254406525,1.41459413208982E-6,58.0028191,58.0028191,99.7613830566406,99.7613830566406,57.2089545795445,20.6092678735406,19.871798,0,0,0,40,4374,59.3486,99.7613830566406,,,,,,,,,,,,,0,,,,0.0049,,,,,,58.0028191,,,,
,26967940.68,61.500824,99.7613830566406,0.000168333560936695,3.9959972077945E-7,1,0.999253354069792,40.0298881530762,1.99760701679168,20.2099997550249,0.00190699402560594,0.000346957053471172,0.25,4.2260884301294E-7,0.000168834584838951,1.53259203578371E-6,61.500824,61.500824,99.7613830566406,99.7613830566406,57.1378263842945,20.6077219685008,19.871798,0,0,0,40,4374,62.99425,99.7613830566406,,,,,,,,,,,,,0,,,,-0.0049,,,,,,61.500824,,,,
,26968062.115,64.5255432,99.7613830566406,0.0001682138218589,2.78853719623576E-7,1,0.999253354069792,40.0298881530762,1.99759890990585,20.1799999922514,0.00190720443637513,0.000344245687811975,0.25,2.49474385261505E-7,0.000168813134403754,1.29673864254786E-6,64.5255432,64.5255432,99.7613830566406,99.7613830566406,57.1339182416984,20.6063555389707,19.871798,0,0,0,40,4374,66.06565,99.7613830566406,,,,,,,,,,,,,0,,,,0,,,,,,64.5255432,,,,
,26968202.415,68.0039902,99.7613830566406,0.000168010465726993,3.0447942649666E-7,1,0.999253354069792,40.0298881530762,1.9975647106072,20.1799999922514,0.00190575733816456,0.000344794972898954,0.25,3.91568336111744E-7,0.00016869980964062,1.36534849432401E-6,68.0039902,68.0039902,99.7613830566406,99.7613830566406,57.515352959083,20.607195607208,20.631098,0,0,0,40,4374,69.614,99.7613830566406,,,,,,,,,,,,,0,,,,0.00245,,,,,,68.0039902,,,,
,26968345.025,71.5299454,99.7613830566406,0.000168048964459662,3.00628444318013E-7,1,0.999253354069792,40.0298881530762,1.9974613824154,20.1799999922514,0.00190707550776675,0.000344124122514951,0.25,3.86320360415647E-7,0.000168811358195196,1.28829812024464E-6,71.5299454,71.5299454,99.7613830566406,99.7613830566406,56.9244417985445,20.6084069017424,21.01075,0,0,0,40,4374,73.21045,99.7613830566406,,,,,,,,,,,,,0,,,,0,,,,,,71.5299454,,,,
,26968485.07,75.0036087,99.7613830566406,0.00016786989211753,3.52701253105224E-7,1,0.999253354069792,40.0298881530762,1.99727658844092,20.1699994504452,0.0019061078151884,0.000340383062203785,0.25,1.48263377356571E-7,0.000168687757339633,9.81569116511398E-7,75.0036087,75.0036087,99.7613830566406,99.7613830566406,56.7212183835445,20.6079214379737,21.3904,0,0,0,40,4374,76.74105,99.7613830566406,,,,,,,,,,,,,0,,,,0.00245,,,,,,75.0036087,,,,
,26968627.515,78.5219727,99.7613830566406,0.000167422668017974,3.71572749581649E-7,1,0.999253354069792,40.0298881530762,1.9973925029389,20.1699994504452,0.0019007764988119,0.000344318242116918,0.25,6.27595137024993E-7,0.000168279032766294,1.39832742077463E-6,78.5219727,78.5219727,99.7613830566406,99.7613830566406,57.6834030907176,20.60174290122,21.3904,0,0,0,40,4374,80.3641,99.7613830566406,,,,,,,,,,,,,0,,,,0.0049,,,,,,78.5219727,,,,
,26968771.71,82.0258179,99.7613830566406,0.000167449113125609,2.96152980016111E-7,1,0.999253354069792,40.0298881530762,1.99730493694128,20.1699994504452,0.00190209853256677,0.000340259719559177,0.25,3.18599384341961E-7,0.000168339441611778,1.03036813501413E-6,82.0258179,82.0258179,99.7613830566406,99.7613830566406,57.1034347294484,20.6027090974652,21.3904,0,0,0,40,4374,84.0221,99.7613830566406,,,,,,,,,,,,,0,,,,0,,,,,,82.0258179,,,,
,26968911.32,85.5234756,99.7613830566406,0.000167510529774569,3.53309173365912E-7,1,0.999253354069792,40.0298881530762,1.99757984014552,20.1399996876717,0.00190434521817701,0.000334535662866774,0.25,-1.54205235268706E-7,0.000168425391583173,5.05595565388954E-7,85.5234756,85.5234756,99.7613830566406,99.7613830566406,57.2863358029484,20.6016845898131,21.3904,0,0,0,40,4374,87.5249,99.7613830566406,,,,,,,,,,,,,0,,,,0.00245,,,,,,85.5234756,,,,
,26969053.395,89.0778122,99.7613830566406,0.00016718850120383,2.89873962462655E-7,1,0.999253354069792,40.0298881530762,1.99724933081692,20.1399996876717,0.00189984225226441,0.000337962059828968,0.25,2.51292583679041E-7,0.000168116161282104,8.66562466879617E-7,89.0778122,89.0778122,99.7613830566406,99.7613830566406,57.3316702570638,20.6034804915238,21.770052,0,0,0,40,4374,91.1005,99.7613830566406,,,,,,,,,,,,,0,,,,-0.00245,,,,,,89.0778122,,,,
,26969191.03,92.5092316,99.7613830566406,0.000167151809771942,3.04047145294511E-7,1,0.999253354069792,40.0298881530762,1.99754214690576,20.1399996876717,0.00190001702302819,0.000336767833633331,0.25,1.85917422069842E-7,0.000168089952525217,7.6133754311723E-7,92.5092316,92.5092316,99.7613830566406,99.7613830566406,56.7790588939676,20.6001202745878,21.770052,0,0,0,40,4374,94.54525,99.7613830566406,,,,,,,,,,,,,0,,,,0.0049,,,,,,92.5092316,,,,
,26969333.055,96.0309525,99.7613830566406,0.000166950677645013,3.33754215077433E-7,1,0.999253354069792,40.0298881530762,1.99748017305219,20.1099999248981,0.00189729059686302,0.000338973097022429,0.25,4.5146365171619E-7,0.000167893551777649,9.91060884299777E-7,96.0309525,96.0309525,99.7613830566406,99.7613830566406,57.2300585495638,20.5983647160666,21.770052,0,0,0,40,4374,98.1181,99.7613830566406,,,,,,,,,,,,,0,,,,0.00245,,,,,,96.0309525,,,,
,26969475.6,99.5503998,99.7613830566406,0.000166715775224187,3.24106536092883E-7,1,0.999253354069792,40.0298881530762,1.99749719717636,20.1099999248981,0.00189549397062285,0.000333828839439511,0.25,7.22332474867263E-8,0.000167661746873317,5.76067111343289E-7,99.5503998,99.5503998,99.7613830566406,99.7613830566406,57.0643533034868,20.59951815367,22.149702,0,0,0,40,4374,101.69025,99.7613830566406,,,,,,,,,,,,,0,,,,-0.0049,,,,,,99.5503998,,,,
,26969615.7,103.0238876,99.7613830566406,0.000166541869865117,3.80972337908024E-7,1,0.999253354069792,40.0298881530762,1.99771443685659,20.1099999248981,0.00189308242059591,0.000337129673564892,0.25,4.18984191068872E-7,0.000167486247208949,8.95056203157718E-7,103.0238876,103.0238876,99.7613830566406,99.7613830566406,56.7954730928714,20.6021108908331,22.149702,0,0,0,40,4374,105.21975,99.7613830566406,,,,,,,,,,,,,0,,,,-0.00245,,,,,,103.0238876,,,,
,26969737.25,106.0421982,99.7613830566406,0.000166306454293937,2.97339970008799E-7,1,0.999253354069792,40.0298881530762,1.99765390045724,20.0800001621246,0.00189104349436822,0.000332591848708811,0.25,8.5199169363632E-8,0.000167248854059349,5.35771285611666E-7,106.0421982,106.0421982,99.7613830566406,99.7613830566406,57.4801796757176,20.6009609800396,22.149702,0,0,0,40,4374,108.27495,99.7613830566406,,,,,,,,,,,,,0,,,,0,,,,,,106.0421982,,,,
,26969875.735,109.5033531,99.7613830566406,0.000166271442097705,3.80710598995378E-7,1,0.999253354069792,40.0298881530762,1.99752959428467,20.0800001621246,0.00189049231806613,0.00033248612130268,0.25,1.08121918452037E-7,0.000167209906471159,5.34892558895699E-7,109.4764404,109.5302658,99.7613830566406,99.7613830566406,56.9049010855637,20.5992401092852,22.149702,0,0,0,40,4374,111.7602,99.7613830566406,,,,,,,,,,,,,0,,,,0,,,,,,109.5033531,,,,
,26970016.955,113.0175934,99.7613830566406,0.000166124644585385,3.60993755360947E-7,1,0.999253354069792,40.0298881530762,1.99742304710453,20.0800001621246,0.00188865793358754,0.000332209823152612,0.25,1.33867046810089E-7,0.000167056849601523,5.38377177447183E-7,113.0175934,113.0175934,99.7613830566406,99.7613830566406,56.5445703381983,20.5995157652865,22.529354,0,0,0,40,4374,115.31485,99.7613830566406,,,,,,,,,,,,,0,,,,-0.0049,,,,,,113.0175934,,,,
,26970139.515,116.0307846,99.7613830566406,0.000166564546868074,3.58714466280631E-7,1,0.999253354069792,40.0298881530762,1.99748217006938,20.0399998575449,0.00189337080916124,0.000334669422176953,0.25,2.90738896841324E-7,0.00016749314233573,6.79684556658174E-7,116.0307846,116.0307846,99.7613830566406,99.7613830566406,56.8283014906791,20.5962135421979,22.529354,0,0,0,40,4374,118.39755,99.7613830566406,,,,,,,,,,,,,0,,,,-0.00245,,,,,,116.0307846,,,,
,26970278.705,119.5052109,99.7613830566406,0.000166103700784274,3.47350006430714E-7,1,0.999253354069792,40.0298881530762,1.99747084707374,20.0399998575449,0.0018879182038348,0.00033438410838308,0.25,3.65859937031459E-7,0.000167021743955437,7.35974856878033E-7,119.5052109,119.5052109,99.7613830566406,99.7613830566406,56.9869720800829,20.6000049857104,22.149702,0,0,0,40,4374,121.8949,99.7613830566406,,,,,,,,,,,,,0,,,,0,,,,,,119.5052109,,,,
,26970420.68,123.0444183,99.7613830566406,0.000166485335230948,3.57832629615225E-7,1,0.999253354069792,40.0298881530762,1.99769659340809,20.0399998575449,0.00189222196442707,0.00033594292352842,0.25,4.51500089171773E-7,0.000167396237647627,8.0594465583512E-7,123.0444183,123.0444183,99.7613830566406,99.7613830566406,56.9220969129868,20.5993501459631,23.288654,0,0,0,40,4374,125.46355,99.7613830566406,,,,,,,,,,,,,0,,,,0.00245,,,,,,123.0444183,,,,
,26970539.51,126.0243912,99.7613830566406,0.000166195660660481,3.28940023583199E-7,1,0.999253354069792,40.0298881530762,1.99756539422933,19.9999995529652,0.00188863791551454,0.000335766668345746,0.25,5.02914810540206E-7,0.00016709646141549,8.43959882817571E-7,126.0243912,126.0243912,99.7613830566406,99.7613830566406,56.618043419006,20.5967045072956,22.909004,0,0,0,40,4374,128.4463,99.7613830566406,,,,,,,,,,,,,0,,,,0,,,,,,126.0243912,,,,
,26970681.55,129.5428619,99.7613830566406,0.000165937530733885,2.94064480875549E-7,1,0.999253354069792,40.0298881530762,1.99758797945301,19.9999995529652,0.00188589647606635,0.000333552551208794,0.25,3.69113320686214E-7,0.000166826533417686,6.94502669661833E-7,129.5428619,129.5428619,99.7613830566406,99.7613830566406,57.0674798175637,20.5987586195926,22.909004,0,0,0,40,4374,132.0121,99.7613830566406,,,,,,,,,,,,,0,,,,0,,,,,,129.5428619,,,,
,26970821.845,133.0450745,99.7613830566406,0.000166047641707806,3.41548288452716E-7,1,0.999253354069792,40.0298881530762,1.99765372462548,19.9999995529652,0.00188762453734534,0.000330627469882911,0.25,1.06685280655307E-7,0.000166926294808389,4.17801191540027E-7,133.0450745,133.0450745,99.7613830566406,99.7613830566406,56.7681160946983,20.5957578935752,23.288654,0,0,0,40,4374,135.5343,99.7613830566406,,,,,,,,,,,,,0,,,,0,,,,,,133.0450745,,,,
,26970962.47,136.5174561,99.7613830566406,0.000166225504549713,3.25606898063365E-7,1,0.999253354069792,40.0298881530762,1.99770810480127,19.9599992483854,0.00188935062647609,0.000332163253165784,0.25,2.24070441170429E-7,0.000167092866911664,5.2404557189201E-7,136.5174561,136.5174561,99.7613830566406,99.7613830566406,56.8611298884868,20.5949124638668,23.288654,0,0,0,40,4374,139.05835,99.7613830566406,,,,,,,,,,,,,0,,,,0,,,,,,136.5174561,,,,
,26971104.47,140.0520325,99.7613830566406,0.000166176103569214,3.31048319045293E-7,1,0.999253354069792,40.0298881530762,1.99767780019082,19.9599992483854,0.00188812768751156,0.000334834911603698,0.25,4.816071790497E-7,0.000167029889687238,7.71494209717105E-7,140.0520325,140.0520325,99.7613830566406,99.7613830566406,56.6704125297944,20.5969247147241,23.288654,0,0,0,40,4374,142.6291,99.7613830566406,,,,,,,,,,,,,0,,,,0,,,,,,140.0520325,,,,
,26971243.455,143.541275,99.7613830566406,0.000166296398025581,2.95821940228008E-7,1,0.999253354069792,40.0298881530762,1.9977242878919,19.9599992483854,0.00188999799884275,0.000331546430244935,0.25,1.83206115392443E-7,0.000167138004900077,4.61507370598741E-7,143.541275,143.541275,99.7613830566406,99.7613830566406,56.7837486650829,20.596575222329,23.288654,0,0,0,40,4374,146.1184,99.7613830566406,,,,,,,,,,,,,0,,,,0,,,,,,143.541275,,,,
,26971382.89,147.0167084,99.7613830566406,0.000165942103387689,3.40642155086726E-7,1,0.999253354069792,40.0298881530762,1.99759038552386,19.9100002646446,0.00188500310456038,0.000334764364249844,0.25,5.41791134112575E-7,0.000166767606509872,8.11758118151051E-7,147.0167084,147.0167084,99.7613830566406,99.7613830566406,56.9900985941599,20.5950836340252,23.668306,0,0,0,40,4374,149.61275,99.7613830566406,,,,,,,,,,,,,0,,,,0,,,,,,147.0167084,,,,
,26971525.94,150.5526581,99.7613830566406,0.000166004053734881,2.82012154344302E-7,1,0.999253354069792,40.0298881530762,1.99764618209321,19.9100002646446,0.00188590099158213,0.000333106208075015,0.25,3.95900295864757E-7,0.000166815670278148,6.56103452676562E-7,150.5526581,150.5526581,99.7613830566406,99.7613830566406,57.0627900464484,20.5954154914453,23.668306,0,0,0,40,4374,153.2052,99.7613830566406,,,,,,,,,,,,,0,,,,0,,,,,,150.5526581,,,,
,26971664.75,154.0298767,99.7613830566406,0.000165684099646661,3.10833725650436E-7,1,0.999253354069792,40.0298881530762,1.997718455391,19.9100002646446,0.00188204113306418,0.000333160896127382,0.25,4.66145632420967E-7,0.000166479411257853,7.17951239832241E-7,154.0013733,154.0583801,99.7613830566406,99.7613830566406,56.6297678467945,20.5998230651205,23.668306,0,0,0,40,4374,156.6836,99.7613830566406,,,,,,,,,,,,,0,,,,0,,,,,,154.0298767,,,,
,26971806.265,157.5572052,99.7613830566406,0.000165432850946943,4.13432441855442E-7,1,0.999253354069792,40.0298881530762,1.99761755536924,19.8699999600649,0.00187986167454305,0.00032722435457794,0.25,-6.98902095693751E-10,0.000166212411839141,2.40686521301869E-7,157.5572052,157.5572052,99.7613830566406,99.7613830566406,56.8916134007368,20.5943871841496,24.047956,0,0,0,40,4374,160.2273,99.7613830566406,,,,,,,,,,,,,0,,,,0.00245,,,,,,157.5572052,,,,
,26971944.01,161.0197601,99.7613830566406,0.000164742682919992,4.20759942741527E-7,1,0.999253354069792,40.0298881530762,1.99756720519904,19.8699999600649,0.00187103790124725,0.000330206356023804,0.25,3.92286772377704E-7,0.000165503146009448,6.27386278886998E-7,161.0197601,161.0197601,99.7613830566406,99.7613830566406,57.6802765766407,20.5982520186481,23.288654,0,0,0,40,4374,163.68295,99.7613830566406,,,,,,,,,,,,,0,,,,0,,,,,,161.0197601,,,,
,26972084.015,164.5230103,99.7613830566406,0.00016435477525311,3.23271603525383E-7,1,0.999253354069792,40.0298881530762,1.9975464373372,19.8699999600649,0.00186721604179539,0.000324907477507359,0.25,3.1240748402174E-9,0.000165098214331149,2.29146000605543E-7,164.5230103,164.5230103,99.7613830566406,99.7613830566406,56.3241510957752,20.5963171016401,23.668306,0,0,0,40,4374,167.183,99.7613830566406,,,,,,,,,,,,,0,,,,0.0049,,,,,,164.5230103,,,,
,26972225.555,168.0115356,99.7613830566406,0.000163515236837312,3.59037073815595E-7,1,0.999253354069792,40.0298881530762,1.99747646988185,19.7999998927116,0.0018576210267897,0.000322139401979686,0.25,-8.44447044356262E-8,0.0001642390454685,1.33677446163617E-7,168.0115356,168.0115356,99.7613830566406,99.7613830566406,56.9643048530253,20.5973142388966,24.427608,0,0,0,40,4374,170.7188,99.7613830566406,,,,,,,,,,,,,0,,,,0,,,,,,168.0115356,,,,
,26972365.79,171.5361328,99.7613830566406,0.000162336381952326,3.34800636220609E-7,1,0.999253354069792,40.0298881530762,1.99732559577163,19.7999998927116,0.00184395252534807,0.000319522117643348,0.25,-9.90907260475264E-8,0.000163038657733971,1.1150164163428E-7,171.5361328,171.5361328,99.7613830566406,99.7613830566406,57.4160861371407,20.6000093833182,24.427608,0,0,0,40,4374,174.22895,99.7613830566406,,,,,,,,,,,,,0,,,,0,,,,,,171.5361328,,,,
,26972504.765,175.050415,99.7613830566406,0.000160875413242443,4.01551632747789E-7,1,0.999253354069792,40.0298881530762,1.99719882209476,19.7999998927116,0.00182713793471927,0.000316152289546718,0.25,-1.31781889953189E-7,0.000161554972551009,7.13260434059619E-8,175.050415,175.050415,99.7613830566406,99.7613830566406,56.9979148793522,20.5996647419475,24.427608,0,0,0,40,4374,177.70095,99.7613830566406,,,,,,,,,,,,,0,,,,0,,,,,,175.050415,,,,
,26972626.165,178.0498657,99.7613830566406,0.000159598400440566,3.62196907765298E-7,1,0.999253354069792,40.0298881530762,1.99727772430501,19.7700001299381,0.00181151982974557,0.000319511759366605,0.25,3.9195766444347E-7,0.000160257799531963,5.9114352043202E-7,178.0498657,178.0498657,99.7613830566406,99.7613830566406,57.0080760501022,20.6010114660834,23.668306,0,0,0,40,4374,180.7309,99.7613830566406,,,,,,,,,,,,,0,,,,-0.0049,,,,,,178.0498657,,,,
,26972764.58,181.5118866,99.7613830566406,0.000158625293877613,3.78164213557847E-7,1,0.999253354069792,40.0298881530762,1.99706989692916,19.7700001299381,0.0018009461105092,0.000312689730055268,0.25,-2.92541865792321E-8,0.000159264757511055,1.62132146098505E-7,181.5118866,181.5118866,99.7613830566406,99.7613830566406,56.926005055583,20.6056387311259,23.668306,0,0,0,40,4374,184.20655,99.7613830566406,,,,,,,,,,,,,0,,,,0,,,,,,181.5118866,,,,
,26972905.275,185.0010071,99.7613830566406,0.00015615958163478,3.99393498037427E-7,1,0.999253354069792,40.0298881530762,1.99699935510197,19.7700001299381,0.00177247982647497,0.000309081625209705,0.25,8.98708546907918E-8,0.000156772429145448,2.74148544831182E-7,185.0010071,185.0010071,99.7613830566406,99.7613830566406,56.8939582862945,20.6047554034672,24.427608,0,0,0,40,4374,187.73635,99.7613830566406,,,,,,,,,,,,,0,,,,0,,,,,,185.0010071,,,,
,26973046.555,188.5441895,99.7613830566406,0.000153739499857637,3.57506063976186E-7,1,0.999253354069792,40.0298881530762,1.99704819224934,19.7299998253584,0.00174494313981036,0.000303798428214132,0.25,5.15897170963055E-8,0.000154326126698719,2.28548925369052E-7,188.5441895,188.5441895,99.7613830566406,99.7613830566406,56.8728543162753,20.6017275626942,24.047956,0,0,0,40,4374,191.27585,99.7613830566406,,,,,,,,,,,,,0,,,,0,,,,,,188.5441895,,,,
,26973188.61,192.08834075,99.7613830566406,0.000151153460661349,3.98803772584865E-7,1,0.999253354069792,40.0298881530762,1.99707358328299,19.7299998253584,0.00171574097148161,0.000296831936415285,0.25,-1.06238590003342E-7,0.000151713697795254,6.31024746953715E-8,192.0631561,192.1135254,99.7613830566406,99.7613830566406,57.0690430746022,20.6016437210586,24.807261,0,0,0,40,4374,194.83775,99.7613830566406,,,,,,,,,,,,,0,,,,-0.0049,,,,,,192.08834075,,,,
,26973326.3,195.5114594,99.7613830566406,0.000148935097921158,4.08983857179898E-7,1,0.999253354069792,40.0298881530762,1.99722216481749,19.7299998253584,0.00168978456559899,0.000296574863151023,0.25,2.61128871215703E-7,0.000149470630381536,4.2561193483945E-7,195.5114594,195.5114594,99.7613830566406,99.7613830566406,56.983845566006,20.5994148685185,24.427608,0,0,0,40,4374,198.3025,99.7613830566406,,,,,,,,,,,,,0,,,,-0.0049,,,,,,195.5114594,,,,
,26973467.635,199.0442047,99.7613830566406,0.000146161216321834,3.17150562941277E-7,1,0.999253354069792,40.0298881530762,1.99742852683862,19.6599997580051,0.00165866096434156,0.000288911669797653,0.25,7.16078922455184E-8,0.000146670508792165,2.28811197484626E-7,199.0442047,199.0442047,99.7613830566406,99.7613830566406,56.6125720193714,20.5969306168112,25.186911,0,0,0,40,4374,201.8478,99.7613830566406,,,,,,,,,,,,,0,,,,-0.00245,,,,,,199.0442047,,,,
,26973608.405,202.5431519,99.7613830566406,0.00014320621471895,3.74624558323195E-7,1,0.999253354069792,40.0298881530762,1.99771910428384,19.6599997580051,0.00162587994945033,0.000278990316458859,0.25,-2.86745469805197E-7,0.000143689437715595,-1.37228901342134E-7,202.5431519,202.5431519,99.7613830566406,99.7613830566406,56.9424192544868,20.5948286157865,24.807261,0,0,0,40,4374,205.3739,99.7613830566406,,,,,,,,,,,,,0,,,,0,,,,,,202.5431519,,,,
,26973748.735,206.0380707,99.7613830566406,0.000140047988280008,4.30887343159611E-7,1,0.999253354069792,40.0298881530762,1.99765539144217,19.6599997580051,0.0015889895417047,0.000277434360707928,0.25,1.31160742145826E-7,0.000140504192812824,2.75684287180938E-7,206.0380707,206.0380707,99.7613830566406,99.7613830566406,57.088583787583,20.5979844386871,24.427608,0,0,0,40,4374,208.8831,99.7613830566406,,,,,,,,,,,,,0,,,,0,,,,,,206.0380707,,,,
,26973888.655,209.5571136,99.7613830566406,0.000136772728809892,3.97704698906969E-7,1,0.999253354069792,40.0298881530762,1.99763489505162,19.6199994534254,0.00155173351659876,0.000270340639733588,0.25,8.05620395449999E-8,0.000137202500450068,2.18673592633241E-7,209.5571136,209.5571136,99.7613830566406,99.7613830566406,56.6930797568522,20.5960119819725,25.186911,0,0,0,40,4374,212.3894,99.7613830566406,,,,,,,,,,,,,0,,,,0.00245,,,,,,209.5571136,,,,
,26974027.98,213.0426483,99.7613830566406,0.000134256449244643,3.8493782101013E-7,1,0.999253354069792,40.0298881530762,1.99756955589186,19.6199994534254,0.00152385269990876,0.000260200176205198,0.25,-3.70279245808758E-7,0.000134663252043107,-2.38754734018682E-7,213.0426483,213.0426483,99.7613830566406,99.7613830566406,57.3801312252561,20.5995782086593,24.807261,0,0,0,40,4374,215.8653,99.7613830566406,,,,,,,,,,,,,0,,,,0,,,,,,213.0426483,,,,
,26974167.89,216.50634765,99.7613830566406,0.000130917437147708,3.999700046134E-7,1,0.999253354069792,40.0298881530762,1.99758568617368,19.6199994534254,0.00148520940433462,0.000257068898293677,0.25,-6.17070249181661E-8,0.000131298684659187,6.49197498684835E-8,216.4734039,216.5392914,99.7613830566406,99.7613830566406,56.5828701356406,20.6016836558677,25.186911,0,0,0,40,4374,219.38845,99.7613830566406,,,,,,,,,,,,,0,,,,0.00245,,,,,,216.50634765,,,,
,26974308.35,220.0039825,99.7613830566406,0.000128075401883738,4.05903400032973E-7,1,0.999253354069792,40.0298881530762,1.99740941728658,19.5599999278784,0.0014525812652265,0.00025197592316799,0.25,-1.05312852525446E-8,0.000128433251921649,1.11101020790281E-7,220.0039825,220.0039825,99.7613830566406,99.7613830566406,57.0948368157368,20.5990489992152,24.807261,0,0,0,40,4374,222.91675,99.7613830566406,,,,,,,,,,,,,0,,,,0,,,,,,220.0039825,,,,
,26974448.21,223.5299225,99.7613830566406,0.000124253687772209,4.25538892931986E-7,1,0.999253354069792,40.0298881530762,1.99738987218866,19.5599999278784,0.00140979691480722,0.000240154510082421,0.25,-3.84671641011707E-7,0.000124586357689162,-2.69877094486578E-7,223.5299225,223.5299225,99.7613830566406,99.7613830566406,57.1073428720445,20.6039230090206,25.186911,0,0,0,40,4374,226.40465,99.7613830566406,,,,,,,,,,,,,0,,,,0,,,,,,223.5299225,,,,
,26974589.93,227.0437317,99.7613830566406,0.000121266360429454,3.70140332005871E-7,1,0.999253354069792,40.0298881530762,1.99732357311437,19.5599999278784,0.00137545501777454,0.000235723750127146,0.25,-2.51747523182017E-7,0.000121576379314445,-1.41465449110776E-7,227.0437317,227.0437317,99.7613830566406,99.7613830566406,56.8853603725829,20.607920617889,24.807261,0,0,0,40,4374,229.9559,99.7613830566406,,,,,,,,,,,,,0,,,,-0.00245,,,,,,227.0437317,,,,
,26974708.985,230.0250702,99.7613830566406,0.000118729638548454,3.77899008173081E-7,1,0.999253354069792,40.0298881530762,1.99715557010818,19.5099990814924,0.00134608540911468,0.000232776484712045,0.25,-6.61111122487905E-8,0.000119020863070265,4.0648521344876E-8,230.0250702,230.0250702,99.7613830566406,99.7613830566406,56.6321127323521,20.6078513309184,25.566563,0,0,0,40,4374,232.94315,99.7613830566406,,,,,,,,,,,,,0,,,,-0.00245,,,,,,230.0250702,,,,
,26974849.31,233.5234375,99.7613830566406,0.00011521298745951,4.07066741404147E-7,1,0.999253354069792,40.0298881530762,1.99709060783127,19.5099990814924,0.00130478303225749,0.000232966013912279,0.25,5.65707924639122E-7,0.00011548112907395,6.68920948317376E-7,233.5234375,233.5234375,99.7613830566406,99.7613830566406,56.2569310431213,20.6133205644744,24.807261,0,0,0,40,4374,236.4598,99.7613830566406,,,,,,,,,,,,,0,,,,0.00245,,,,,,233.5234375,,,,
,26974988.905,237.0003052,99.7613830566406,0.000112682489813074,3.59884358705779E-7,1,0.999253354069792,40.0298881530762,1.99718105633218,19.5099990814924,0.00127771724142025,0.000218088069331081,0.25,-3.04684638271867E-7,0.000112931914781751,-2.07448462812373E-7,237.0003052,237.0003052,99.7613830566406,99.7613830566406,57.088583787583,20.6137786824579,25.186911,0,0,0,40,4374,239.9512,99.7613830566406,,,,,,,,,,,,,0,,,,0,,,,,,237.0003052,,,,
,26975110.735,240.0160828,99.7613830566406,0.000110249256780739,4.20877469691193E-7,1,0.999253354069792,40.0298881530762,1.99752340030368,19.4600000977516,0.00125026607122772,0.000213010640808189,0.25,-3.3024898768981E-7,0.000110481743279534,-2.36600574638284E-7,240.0160828,240.0160828,99.7613830566406,99.7613830566406,56.6954246424098,20.6121947919848,25.566563,0,0,0,40,4374,243.01225,99.7613830566406,,,,,,,,,,,,,0,,,,-0.00245,,,,,,240.0160828,,,,
,26975253.715,243.5678711,99.7613830566406,0.000107185730543686,3.5556163357133E-7,1,0.999253354069792,40.0298881530762,1.99728235572852,19.4600000977516,0.00121536150448951,0.000206306451883231,0.25,-3.84405343378878E-7,0.000107398493972097,-2.95048073590808E-7,243.5678711,243.5678711,99.7613830566406,99.7613830566406,57.0268351345637,20.6108679333211,25.186911,0,0,0,40,4374,246.5985,99.7613830566406,,,,,,,,,,,,,0,,,,0,,,,,,243.5678711,,,,
,26975391.72,247.0180359,99.7613830566406,0.000104895510959487,3.76468659132454E-7,1,0.999253354069792,40.0298881530762,1.99733264752,19.4600000977516,0.00118921914428318,0.000202216918366062,0.25,-3.44893535795304E-7,0.000105090990275642,-2.58809519872593E-7,247.0180359,247.0180359,99.7613830566406,99.7613830566406,56.9049010855637,20.6158787656913,25.946213,0,0,0,40,4374,250.0624,99.7613830566406,,,,,,,,,,,,,0,,,,0,,,,,,247.0180359,,,,
,26975531.405,250.5228729,99.7613830566406,0.000102387407255359,3.94665122608318E-7,1,0.999253354069792,40.0298881530762,1.9976671432597,19.4099992513657,0.00116051049911753,0.000199212153865646,0.25,-1.74359102008688E-7,0.000102565429450731,-9.14140095558346E-8,250.5228729,250.5228729,99.7613830566406,99.7613830566406,56.9111541137176,20.6085583764815,25.186911,0,0,0,40,4374,253.5637,99.7613830566406,,,,,,,,,,,,,0,,,,-0.0049,,,,,,250.5228729,,,,
,26975672.415,254.0372925,99.7613830566406,9.93480065676965E-5,4.24757369454868E-7,1,0.999253354069792,40.0298881530762,1.9974872838434,19.4099992513657,0.00112601527966015,0.000192154396769148,0.25,-2.65271109703965E-7,9.95084738393816E-5,-1.86252487818479E-7,254.0372925,254.0372925,99.7613830566406,99.7613830566406,56.5523866233906,20.6090225454956,25.566563,0,0,0,40,4374,257.08825,99.7613830566406,,,,,,,,,,,,,0,,,,0,,,,,,254.0372925,,,,
,26975812.925,257.5083923,99.7613830566406,9.7260033015655E-5,3.83413450152167E-7,1,0.999253354069792,40.0298881530762,1.99758078002933,19.4099992513657,0.00110322358643949,0.00018256578772496,0.25,-7.47097767267647E-7,9.74055379619993E-5,-6.71695979568187E-7,257.5083923,257.5083923,99.7613830566406,99.7613830566406,56.9252234270637,20.6097035918544,25.946213,0,0,0,40,4374,260.60765,99.7613830566406,,,,,,,,,,,,,0,,,,0.0049,,,,,,257.5083923,,,,
,26975953.405,261.0551147,99.7613830566406,9.47029351703528E-5,4.20653875123107E-7,1,0.999253354069792,40.0298881530762,1.99766940432327,19.3600002676249,0.00107278481815277,0.00018550095470021,0.25,-4.20731574546227E-8,9.48321324461769E-5,3.1179135856879E-8,261.0551147,261.0551147,99.7613830566406,99.7613830566406,57.3129111726022,20.5900335073991,25.566563,0,0,0,40,4374,264.1282,99.7613830566406,,,,,,,,,,,,,0,,,,-0.00245,,,,,,261.0551147,,,,
,26976093.65,264.539978,99.7613830566406,9.23353950294676E-5,3.81316328535654E-7,1,0.999253354069792,40.0298881530762,1.9978022738385,19.3600002676249,0.00104715530477262,0.000173624537657029,0.25,-6.78065161386755E-7,9.24503828054876E-5,-6.08553434381023E-7,264.539978,264.539978,99.7613830566406,99.7613830566406,56.9596150819099,20.5929827265414,25.946213,0,0,0,40,4374,267.6305,99.7613830566406,,,,,,,,,,,,,0,,,,-0.0049,,,,,,264.539978,,,,
,26976232.62,268.0172729,99.7613830566406,9.04238592925857E-5,4.294830500233E-7,1,0.999253354069792,40.0298881530762,1.99772202120962,19.3600002676249,0.00102446484258283,0.000174880701017091,0.25,-2.32214601708167E-7,9.0524911006585E-5,-1.64640063373196E-7,268.0172729,268.0172729,99.7613830566406,99.7613830566406,56.8071975206598,20.5933599629408,26.325863,0,0,0,40,4374,271.1057,99.7613830566406,,,,,,,,,,,,,0,,,,0.00245,,,,,,268.0172729,,,,
,26976375.24,271.5193787,99.7613830566406,8.75653768812046E-5,4.36575497952806E-7,1,0.999253354069792,40.0298881530762,1.99771058616431,19.3099994212389,0.000991561054453269,0.000171573692003516,0.25,-2.57261383055331E-8,8.76521237675235E-5,3.89097102331391E-8,271.5193787,271.5193787,99.7613830566406,99.7613830566406,56.8322096332752,20.5933133572582,26.325863,0,0,0,40,4374,274.6785,99.7613830566406,,,,,,,,,,,,,0,,,,-0.00245,,,,,,271.5193787,,,,
,26976515.645,275.0140076,99.7613830566406,8.56751626719912E-5,4.16346231265266E-7,1,0.999253354069792,40.0298881530762,1.99779837021608,19.3099994212389,0.000971001558715978,0.000162518196143116,0.25,-4.95669785162677E-7,8.57496645328717E-5,-4.33799864840114E-7,275.0140076,275.0140076,99.7613830566406,99.7613830566406,56.9885353371214,20.590886427774,26.325863,0,0,0,40,4374,278.2109,99.7613830566406,,,,,,,,,,,,,0,,,,0,,,,,,275.0140076,,,,
,26976655.33,278.5066833,99.7613830566406,8.33482920827549E-5,3.58991240575624E-7,1,0.999253354069792,40.0298881530762,1.99768671984084,19.3099994212389,0.000943992828105489,0.000160779723838611,0.25,-2.42483950003359E-7,8.34101666668626E-5,-1.82958380555264E-7,278.5066833,278.5066833,99.7613830566406,99.7613830566406,57.0229269919676,20.5932801882599,26.325863,0,0,0,40,4374,281.6933,99.7613830566406,,,,,,,,,,,,,0,,,,-0.0049,,,,,,278.5066833,,,,
,26976794.9,282.0144043,99.7613830566406,8.14467487284019E-5,3.80501321451427E-7,1,0.999253354069792,40.0298881530762,1.99778529392538,19.2499998956919,0.000921875746319511,0.000160030342536757,0.25,2.28403406152442E-8,8.14967879961923E-5,8.03406111970041E-8,282.0144043,282.0144043,99.7613830566406,99.7613830566406,56.7431039820829,20.5894021001921,25.946213,0,0,0,40,4374,285.173,99.7613830566406,,,,,,,,,,,,,0,,,,0,,,,,,282.0144043,,,,
,26976936.495,285.5228271,99.7613830566406,8.00145082042669E-5,4.86269804995274E-7,1,0.999253354069792,40.0298881530762,1.99786033743273,19.2499998956919,0.000905538327640997,0.00015746126480409,0.25,4.61663673951271E-8,8.0053592192611E-5,1.01827620953142E-7,285.5228271,285.5228271,99.7613830566406,99.7613830566406,57.0604451608906,20.5907757101931,25.566563,0,0,0,40,4374,288.73015,99.7613830566406,,,,,,,,,,,,,0,,,,0,,,,,,285.5228271,,,,
,26977077.315,289.0107117,99.7613830566406,7.73569895550002E-5,4.01970142112983E-7,1,0.999253354069792,40.0298881530762,1.99780678208082,19.2499998956919,0.000876375690879099,0.000146179672824654,0.25,-4.87346166711484E-7,7.73854742740193E-5,-4.34510403146196E-7,289.0107117,289.0107117,99.7613830566406,99.7613830566406,57.0080760501022,20.5930546693737,26.325863,0,0,0,40,4374,292.2469,99.7613830566406,,,,,,,,,,,,,0,,,,0,,,,,,289.0107117,,,,
,26977218.59,292.5358887,99.7613830566406,7.60809461449056E-5,3.70390629516292E-7,1,0.999253354069792,40.0298881530762,1.99769161539848,19.2000009119511,0.000861706445933447,0.000144069819586684,0.25,-4.49620733684959E-7,7.60993329807876E-5,-3.98335896510501E-7,292.5358887,292.5358887,99.7613830566406,99.7613830566406,56.7884384361983,20.5896389635037,26.705515,0,0,0,40,4374,295.77885,99.7613830566406,,,,,,,,,,,,,0,,,,0,,,,,,292.5358887,,,,
,26977357.44,296.0111084,99.7613830566406,7.37615700294187E-5,4.24041465620771E-7,1,0.999253354069792,40.0298881530762,1.9978269063256,19.2000009119511,0.000836023314578294,0.000135996144629052,0.25,-7.59897213926161E-7,7.37704376428257E-5,-7.10849012118025E-7,296.0111084,296.0111084,99.7613830566406,99.7613830566406,56.7985996069483,20.5923356425448,26.325863,0,0,0,40,4374,299.2431,99.7613830566406,,,,,,,,,,,,,0,,,,-0.0049,,,,,,296.0111084,,,,
,26977498.605,299.5076904,99.7613830566406,7.24033612421203E-5,5.07111283540351E-7,1,0.999253354069792,40.0298881530762,1.99774219341079,19.2000009119511,0.000819543354525772,0.000138953517946164,0.25,-2.60477857583671E-7,7.24026952875692E-5,-2.12919798827442E-7,299.5076904,299.5076904,99.7613830566406,99.7613830566406,56.8650380310829,20.5956188805841,26.705515,0,0,0,40,4374,302.7901,99.7613830566406,,,,,,,,,,,,,0,,,,0.0049,,,,,,299.5076904,,,,
,26977619.395,302.5334167,99.7613830566406,6.9827176596369E-5,4.15301664169145E-7,1,0.999253354069792,40.0298881530762,1.99765114088977,19.1500000655651,0.000790264452876015,0.00013398332615823,0.25,-2.51187768459245E-7,6.9818994549627E-5,-2.05833238397458E-7,302.5334167,302.5334167,99.7613830566406,99.7613830566406,56.8806706014676,20.5879585021147,26.325863,0,0,0,40,4374,305.8059,99.7613830566406,,,,,,,,,,,,,0,,,,0,,,,,,302.5334167,,,,
,26977762.145,306.057312,99.7613830566406,6.87200478032402E-5,4.46547383351657E-7,1,0.999253354069792,40.0298881530762,1.99783294965054,19.1500000655651,0.00077828382413544,0.000128509792630764,0.25,-5.42273548208475E-7,6.8703559003459E-5,-4.9814826249758E-7,306.057312,306.057312,99.7613830566406,99.7613830566406,56.9893169656406,20.5891224067753,25.946213,0,0,0,40,4374,309.39535,99.7613830566406,,,,,,,,,,,,,0,,,,0.00245,,,,,,306.057312,,,,
,26977901.385,309.5391235,99.7613830566406,6.75946072644912E-5,4.58485446647713E-7,1,0.999253354069792,40.0298881530762,1.9978397906135,19.1500000655651,0.000765984231713126,0.000123279640304767,0.25,-8.07862523770509E-7,6.75701948139652E-5,-7.64864704691508E-7,309.5391235,309.5391235,99.7613830566406,99.7613830566406,57.0807675023906,20.590684835721,26.705515,0,0,0,40,4374,312.90225,99.7613830566406,,,,,,,,,,,,,0,,,,0,,,,,,309.5391235,,,,
,26978020.01,312.507782,99.7613830566406,6.5695603265522E-5,4.2722899812793E-7,1,0.999253354069792,40.0298881530762,1.99803354869609,19.0799999982119,0.000743645634801682,0.00012448780135916,0.25,-3.71474407270215E-7,6.56646988993886E-5,-3.30254330269371E-7,312.507782,312.507782,99.7613830566406,99.7613830566406,56.7087123272368,20.5865196359359,26.325863,0,0,0,40,4374,315.86285,99.7613830566406,,,,,,,,,,,,,0,,,,0,,,,,,312.507782,,,,
,26978163.505,316.056488,99.7613830566406,6.44545505172061E-5,4.33990619643241E-7,1,0.999253354069792,40.0298881530762,1.99799213773268,19.0799999982119,0.000728835148949976,0.000125907157687708,0.25,-2.8845667047958E-8,6.44159338182934E-5,1.09130398444721E-8,316.056488,316.056488,99.7613830566406,99.7613830566406,57.0010413934291,20.5903965170902,26.705515,0,0,0,40,4374,319.4535,99.7613830566406,,,,,,,,,,,,,0,,,,-0.00245,,,,,,316.056488,,,,
,26978302.17,319.5018616,99.7613830566406,6.25049615679747E-5,4.69747646724447E-7,1,0.999253354069792,40.0298881530762,1.99809057702898,19.0799999982119,0.000707580245446663,0.000117221549806026,0.25,-4.58079517084146E-7,6.24601853702566E-5,-4.19686606822285E-7,319.5018616,319.5018616,99.7613830566406,99.7613830566406,57.0526288756983,20.5903092057489,26.325863,0,0,0,40,4374,322.91065,99.7613830566406,,,,,,,,,,,,,0,,,,-0.00245,,,,,,319.5018616,,,,
,26978444.93,323.0420837,99.7613830566406,6.08616494971044E-5,4.67224390901114E-7,1,0.999253354069792,40.0298881530762,1.99832444814849,19.0299991518259,0.000689522171046508,0.000110941566499527,0.25,-7.28315931998866E-7,6.08106510953812E-5,-6.91105781610824E-7,323.0420837,323.0420837,99.7613830566406,99.7613830566406,56.7556100383906,20.5832864624837,26.705515,0,0,0,40,4374,326.51155,99.7613830566406,,,,,,,,,,,,,0,,,,0,,,,,,323.0420837,,,,
,26978585.88,326.519043,99.7613830566406,6.01390081966716E-5,3.98130636935689E-7,1,0.999253354069792,40.0298881530762,1.99847444745606,19.0299991518259,0.000680098500408464,0.000116561701545572,0.25,-1.05108205396816E-7,6.00809315278484E-5,-6.92853007577087E-8,326.519043,326.519043,99.7613830566406,99.7613830566406,57.1690915250637,20.5851524727399,26.705515,0,0,0,40,4374,330.0557,99.7613830566406,,,,,,,,,,,,,0,,,,0,,,,,,326.519043,,,,
,26978724.765,330.0064697,99.7613830566406,5.84437680583594E-5,4.29428349093724E-7,1,0.999253354069792,40.0298881530762,1.99855271035762,19.0299991518259,0.000661910749513324,0.000107266889298299,0.25,-6.3247233024609E-7,5.83805397978029E-5,-5.97472628709041E-7,330.0064697,330.0064697,99.7613830566406,99.7613830566406,57.241001348833,20.5841765424273,26.705515,0,0,0,40,4374,333.526,99.7613830566406,,,,,,,,,,,,,0,,,,0.00245,,,,,,330.0064697,,,,
,26978867.395,333.5267029,99.7613830566406,5.7118989783099E-5,4.50898651130504E-7,1,0.999253354069792,40.0298881530762,1.99865717646185,18.9800001680851,0.000645136732160307,0.000114778966687718,0.25,2.62601885234277E-7,5.70497087662335E-5,2.95427574622928E-7,333.5267029,333.5267029,99.7613830566406,99.7613830566406,56.7837486650829,20.5819056128813,26.705515,0,0,0,40,4374,337.0972,99.7613830566406,,,,,,,,,,,,,0,,,,-0.0049,,,,,,333.5267029,,,,
,26979006.995,337.013092,99.7613830566406,5.55501699848915E-5,4.4123857039187E-7,1,0.999253354069792,40.0298881530762,1.99858385397692,18.9800001680851,0.000628073633793984,0.000107257253380363,0.25,-1.29314124354137E-7,5.5476333298215E-5,-9.72664288862268E-8,337.013092,337.013092,99.7613830566406,99.7613830566406,57.0502839901407,20.5850860809923,26.705515,0,0,0,40,4374,340.59805,99.7613830566406,,,,,,,,,,,,,0,,,,-0.00245,,,,,,337.013092,,,,
,26979148.85,340.559906,99.7613830566406,5.40661624849234E-5,4.67525992745966E-7,1,0.999253354069792,40.0298881530762,1.99870578341753,18.9800001680851,0.00061061562173851,0.000108082839302537,0.25,2.0166208054883E-7,5.39875320104787E-5,2.32054327496182E-7,340.559906,340.559906,99.7613830566406,99.7613830566406,56.9486722826406,20.5842551809815,26.325863,0,0,0,40,4374,344.1532,99.7613830566406,,,,,,,,,,,,,0,,,,0,,,,,,340.559906,,,,
,26979289.65,344.0570679,99.7613830566406,5.35470261218093E-5,4.5574252220547E-7,1,0.999253354069792,40.0298881530762,1.99874532710587,18.9100001007318,0.000605269030031364,0.000103700373101544,0.25,-9.49943976692164E-8,5.34629291805997E-5,-6.47723776126251E-8,344.0570679,344.0570679,99.7613830566406,99.7613830566406,56.8642564025637,20.5795459227881,27.085165,0,0,0,40,4374,347.6697,99.7613830566406,,,,,,,,,,,,,0,,,,-0.0049,,,,,,344.0570679,,,,
,26979429.595,347.5141602,99.7613830566406,5.18806097496118E-5,4.89221168602295E-7,1,0.999253354069792,40.0298881530762,1.99873696300629,18.9100001007318,0.000585792862599721,0.000103744969045146,0.25,1.98907856052225E-7,5.17928865736261E-5,2.2741469659639E-7,347.5141602,347.5141602,99.7613830566406,99.7613830566406,57.1980117802753,20.5814446274825,26.705515,0,0,0,40,4374,351.1901,99.7613830566406,,,,,,,,,,,,,0,,,,0,,,,,,347.5141602,,,,
,26985169.95,9.9967594,9999.673828125,,,2,,,,19.9799999693036,,,,,,,9.9967594,9.9967594,9999.673828125,9999.673828125,,,12.658426,,,,-99999999,4369,10.0061,9999.673828125,,,,,,,,,,,,,,,,,,,,,,,9.9967594,,,,