File: data/monolayers/nanoparticles/Ac_CoFe_C_2/vsm/data_dispersion/YF45_HYST_300K.DAT
[Header]
; VSM Data File (default extension .dat)
; Copyright (c) 2003-2013, Quantum Design, Inc. All rights reserved.
TITLE,
FILEOPENTIME,28005413.42,11/21/2018,11:17 am
BYAPP,VSM,2.0,2.0
INFO,PPMS VSM Option Release 1.4.10 Build 1,APPNAME
INFO,Quantum Design Linear Motor Servo Controller,MOTOR_MODULE_NAME
INFO,3101-100 M1,MOTOR_HW_VERSION
INFO,MMC1014,MOTOR_SERIAL_NUMBER
INFO,SRV No X-over 01.03.11,MOTOR_SOFTWARE_VERSION
INFO,Quantum Design VSM Detection Module,VSM_MODULE_NAME
INFO,3101-150 F0,VSM_HW_VERSION
INFO,VSM707,VSM_SERIAL_NUMBER
INFO,VSM No X-over 01.02.05 May 20 2008 13:51:47,VSM_SOFTWARE_VERSION
INFO,704,PREAMP_SERIAL_NUMBER
INFO,822,COIL_SERIAL_NUMBER
INFO,0,MOMENT_UNITS
INFO,CoFe2O4,SAMPLE_MATERIAL
INFO,dispersion in ampulle,SAMPLE_COMMENT
INFO,,SAMPLE_MASS
INFO,,SAMPLE_VOLUME
INFO,,SAMPLE_MOLECULAR_WEIGHT
INFO,,SAMPLE_SIZE
INFO,,SAMPLE_SHAPE
DATATYPE,COMMENT,1
DATATYPE,TIME,2
STARTUPAXIS,X,2
STARTUPAXIS,Y1,5
[Data]
Comment,Time Stamp (sec),Temperature (K),Magnetic Field (Oe),Moment (emu),M. Std. Err. (emu),Transport Action,Averaging Time (sec),Frequency (Hz),Peak Amplitude (mm),Center Position (mm),Coil Signal' (mV),Coil Signal" (mV),Range (mV),M. Quad. Signal (emu),M. Raw' (emu),M. Raw" (emu),Min. Temperature (K),Max. Temperature (K),Min. Field (Oe),Max. Field (Oe),Mass (grams),Motor Lag (deg),Pressure (Torr),VSM Status (code),Motor Status (code),Measure Status (code),Measure Count,PPMS Status (code),System Temp. (K),System Field (Oe),Sample Position (deg),Bridge 1 Resistance (ohms),Bridge 1 Excitation (에),Bridge 2 Resistance (ohms),Bridge 2 Excitation (에),Bridge 3 Resistance (ohms),Bridge 3 Excitation (에),Bridge 4 Resistance (ohms),Bridge 4 Excitation (에),Signal 1 Vin (V),Signal 2 Vin (V),Digital Inputs (code),Drive 1 Iout (mA),Drive 1 Ipower (W),Drive 2 Iout (mA),Drive 2 Ipower (W),Pressure (),Map 20 (),Map 21 (),Map 22 (),Map 23 (),Map 24 (),Map 25 (),Map 26 (),Map 27 (),Map 28 (),Map 29 ()
,28005429.11,300.2423096,-0.274027913808823,,,2,,,,19.9400004354119,,,,,,,300.2423096,300.2423096,-0.274027913808823,-0.274027913808823,,,28.603769,,,,-99999999,4369,300.7523,-0.274027913808823,,,,,,,,,,,,,,,,,,,,,,,300.2423096,,,,
,28005575.775,300.2271423,4426.41284179687,0.00364428896737621,4.75099924433234E-5,1,0.999253354069792,40.0298881530762,2.00512999367656,19.9299994856119,0.0377486696193606,0.0280619214465525,0.25,0.00184064323687152,0.00364293136970926,0.0018429877593599,300.2271423,300.2271423,4421.517578125,4431.30810546875,55.9333368361598,20.3279531352711,28.224119,0,0,0,40,4449,300.451,4426.41284179687,,,,,,,,,,,,,0,,,,0,,,,,,300.2271423,,,,
,28005670.755,300.16474915,9172.697265625,0.00369645743481784,5.61265559484313E-5,1,0.999253354069792,40.0298881530762,2.00496340197018,19.9299994856119,0.038327689591405,0.0282214123822443,0.25,0.00184584660740311,0.00369510309317858,0.00184822898758783,300.1642151,300.1652832,9167.708984375,9177.685546875,56.0974788251982,20.3342925735371,28.224119,0,0,0,40,4449,300.3291,9172.697265625,,,,,,,,,,,,,0,,,,0,,,,,,300.16474915,,,,
,28005764.29,300.1135559,13845.578125,0.00369906446969998,6.49204250103477E-5,1,0.999253354069792,40.0298881530762,2.00487221343042,19.9299994856119,0.0383333436795854,0.0283543857700013,0.25,0.00185721474116687,0.00369771011014578,0.00185960056462962,300.1135559,300.1135559,13840.7509765625,13850.4052734375,56.249114757929,20.3372112192946,27.844467,0,0,0,40,4449,300.25915,13845.578125,,,,,,,,,,,,,0,,,,-0.00245,,,,,,300.1135559,,,,
,28005855.165,300.066864,18388.0595703125,0.00363002204920857,4.88952878879394E-5,1,0.999253354069792,40.0298881530762,2.00476733832499,19.9299994856119,0.0376817468213762,0.0274446654609588,0.25,0.00178914584615038,0.00362872218166128,0.00179148960752326,300.066864,300.066864,18378.13671875,18397.982421875,56.3687039213713,20.3384765976525,28.224119,0,0,0,40,4449,300.224,18388.0595703125,,,,,,,,,,,,,0,,,,0.00245,,,,,,300.066864,,,,
,28005950.905,300.0367737,23173.21875,0.00348961100301818,5.18047475172307E-5,1,0.999253354069792,40.0298881530762,2.00481132135713,19.9299994856119,0.0360920449706834,0.0271511135700529,0.25,0.00178755824372739,0.00348832172011088,0.00178980911521501,300.0367737,300.0367737,23170.673828125,23175.763671875,56.4593728296021,20.3389662511066,28.224119,0,0,0,40,4449,300.21165,23173.21875,,,,,,,,,,,,,0,,,,0.0049,,,,,,300.0367737,,,,
,28006046.665,300.0192871,27961.1083984375,0.00339565490133024,6.58552724745153E-5,1,0.999253354069792,40.0298881530762,2.00477861372961,19.9299994856119,0.0351433650990886,0.026283529150757,0.25,0.00172743439442421,0.00339441167849779,0.00172962406656426,300.0192871,300.0192871,27953.662109375,27968.5546875,56.262402442756,20.3417962743626,28.224119,0,0,0,40,4449,300.2021,27961.1083984375,,,,,,,,,,,,,0,,,,-0.0049,,,,,,300.0192871,,,,
,28006138.705,300.0064697,32558.9638671875,0.00337780925872872,4.98513184556313E-5,1,0.999253354069792,40.0298881530762,2.00474592151692,19.9299994856119,0.0350287457752573,0.0257375937560711,0.25,0.00168246189099444,0.00337659916018099,0.00168463974302972,300.0064697,300.0064697,32556.203125,32561.724609375,56.435142345506,20.3421281402925,28.224119,0,0,0,40,4449,300.2102,32558.9638671875,,,,,,,,,,,,,0,,,,0.0049,,,,,,300.0064697,,,,
,28006234.79,300.0007935,37363.759765625,0.0032471113120936,4.6012478051596E-5,1,0.999253354069792,40.0298881530762,2.0045653978112,19.9299994856119,0.0335305297527671,0.0255475206190915,0.25,0.00168855405069757,0.00324590318247733,0.00169064361119384,300.0007935,300.0007935,37358.83984375,37368.6796875,56.2686554709098,20.344001176937,28.603769,0,0,0,40,4449,300.2206,37363.759765625,,,,,,,,,,,,,0,,,,0.0049,,,,,,300.0007935,,,,
,28006333.235,299.995575,42283.587890625,0.00302923013926661,5.74819670088797E-5,1,0.999253354069792,40.0298881530762,2.00466617266157,19.9299994856119,0.031112367316829,0.0248144049960306,0.25,0.0016616008118325,0.00302804813843613,0.00166354586663437,299.995575,299.995575,42275.96484375,42291.2109375,56.343691808756,20.3439779402596,27.844467,0,0,0,40,4449,300.2136,42283.587890625,,,,,,,,,,,,,0,,,,0,,,,,,299.995575,,,,
,28006428.08,299.9955444,47023.919921875,0.00287810310482816,6.28076800270725E-5,1,0.999253354069792,40.0298881530762,2.00476620303473,19.9299994856119,0.0294639205986652,0.0241413800344659,0.25,0.00162838367726441,0.00287694875064846,0.00163022826126572,299.9955444,299.9955444,47013.65625,47034.18359375,56.414820004006,20.3404670801702,28.224119,0,0,0,40,4449,300.21485,47023.919921875,,,,,,,,,,,,,0,,,,-0.0049,,,,,,299.9955444,,,,
,28006522.855,300.0003662,51759.595703125,0.00277734093265994,4.84290176142674E-5,1,0.999253354069792,40.0298881530762,2.00492055236834,19.9299994856119,0.0284131979512941,0.0234207933737606,0.25,0.00158220286022838,0.00277622073755889,0.0015839803384743,300.0003662,300.0003662,51752.09375,51767.09765625,56.4710972573906,20.3414769090868,28.603769,0,0,0,40,4449,300.21475,51759.595703125,,,,,,,,,,,,,0,,,,0,,,,,,300.0003662,,,,
,28006618.585,300.0066528,56544.3984375,0.00279841641981485,4.46083360483469E-5,1,0.999253354069792,40.0298881530762,2.00473833741474,19.9299994856119,0.0288108388910503,0.022531522709102,0.25,0.00150038043435657,0.00279734995028315,0.00150217191069273,300.0055847,300.0077209,56539.3828125,56549.4140625,56.4484300303329,20.3435820243347,28.603769,0,0,0,40,4449,300.1977,56544.3984375,,,,,,,,,,,,,0,,,,0,,,,,,300.0066528,,,,
,28006714.74,300.0062561,61349.642578125,0.00265748526538498,3.84456439018007E-5,1,0.999253354069792,40.0298881530762,2.00438495508681,19.9299994856119,0.0272605020302251,0.0219404426400956,0.25,0.00147304490178956,0.00265644225071111,0.00147474277801061,300.0062561,300.0062561,61342.28515625,61357,56.4601544581214,20.3436949266768,28.224119,0,0,0,40,4449,300.2037,61349.642578125,,,,,,,,,,,,,0,,,,0,,,,,,300.0062561,,,,
,28006813.345,299.9992981,66280.18359375,0.00250625231208668,5.6066548178003E-5,1,0.999253354069792,40.0298881530762,2.00468614123064,19.9299994856119,0.0256464749635396,0.0210779929096161,0.25,0.00142297954930304,0.00250524846513796,0.00142457828064151,299.9992981,299.9992981,66270.34375,66290.0234375,56.3749569495252,20.3411754680551,28.224119,0,0,0,40,4449,300.201,66280.18359375,,,,,,,,,,,,,0,,,,0.00245,,,,,,299.9992981,,,,
,28006908.665,300.0045776,71043,0.00244045460707652,4.66518633901242E-5,1,0.999253354069792,40.0298881530762,2.00475056474174,19.9299994856119,0.0250195512141659,0.0202619950465376,0.25,0.0013624283862555,0.00243949305603252,0.00136398375688037,300.0045776,300.0045776,71038.0234375,71047.9765625,56.4984542555637,20.3419372298928,28.603769,0,0,0,40,4449,300.19895,71043,,,,,,,,,,,,,0,,,,-0.0049,,,,,,300.0045776,,,,
,28007008.705,300.0072327,76046.45703125,0.00229663674579979,4.03665787856332E-5,1,0.999253354069792,40.0298881530762,2.00471728642309,19.9299994856119,0.0234505164684804,0.0196116661111646,0.25,0.00133007496098859,0.00229570157420819,0.00133153535450469,300.0072327,300.0072327,76041.921875,76050.9921875,56.5703640793329,20.3434489971448,28.224119,0,0,0,40,4449,300.196,76046.45703125,,,,,,,,,,,,,0,,,,0,,,,,,300.0072327,,,,
,28007105.91,300.0123291,80902.265625,0.00207028391813966,5.30515361792845E-5,1,0.999253354069792,40.0298881530762,2.00472536499231,19.9299994856119,0.0209324280219693,0.0188732706675902,0.25,0.00130422633630902,0.0020693730347243,0.00130553791773424,300.0123291,300.0123291,80894.734375,80909.796875,56.4875114562944,20.3431798884785,28.603769,0,0,0,40,4449,300.1915,80902.265625,,,,,,,,,,,,,0,,,,0.0049,,,,,,300.0123291,,,,
,28007203.31,300.0096741,85773.00390625,0.00202783017357005,4.51314540773192E-5,1,0.999253354069792,40.0298881530762,2.00464120599948,19.9299994856119,0.0206217988008926,0.0177961943421551,0.25,0.00121674548018195,0.00202697880653359,0.00121803061996087,300.0096741,300.0096741,85763.078125,85782.9296875,56.1709519060059,20.3432686539715,28.224119,0,0,0,40,4449,300.1613,85773.00390625,,,,,,,,,,,,,0,,,,0,,,,,,300.0096741,,,,
,28007312.89,300.0134583,89748.296875,0.00188626334258211,3.8417224982268E-5,1,0.999253354069792,40.0298881530762,2.00467050041538,19.9299994856119,0.0190650482280321,0.0172315495280094,0.25,0.0011914995652016,0.00188543320048918,0.00119269187957174,300.0134583,300.0134583,89738.53125,89758.0625,56.4460851447752,20.3440665280353,28.224119,0,0,0,40,4449,300.16085,89748.296875,,,,,,,,,,,,,0,,,,-0.00245,,,,,,300.0134583,,,,
,28007406.935,300.0059204,85051.875,0.00199902312948171,4.03820801064536E-5,1,0.999253354069792,40.0298881530762,2.00458512795021,19.9299994856119,0.0202442273735225,0.0180282316180738,0.25,0.00124222348666408,0.00199815607834576,0.00124348955980365,300.0059204,300.0059204,85049.4609375,85054.2890625,56.5914680493521,20.3450712371304,28.224119,0,0,0,40,4449,300.154,85051.875,,,,,,,,,,,,,0,,,,-0.00245,,,,,,300.0059204,,,,
,28007502.39,300.0048523,80277.84375,0.00217219067960687,4.4146213597102E-5,1,0.999253354069792,40.0298881530762,2.00465102487565,19.9299994856119,0.0220844149939209,0.019095126881346,0.25,0.00130617733961883,0.00217127582729207,0.0013075560636025,300.0048523,300.0048523,80270.46875,80285.21875,56.4922012274098,20.3441039480285,28.224119,0,0,0,40,4449,300.15435,80277.84375,,,,,,,,,,,,,0,,,,0,,,,,,300.0048523,,,,
,28007597.875,299.9971008,75506.49609375,0.00225863251407946,4.20942189000104E-5,1,0.999253354069792,40.0298881530762,2.00450997709774,19.9299994856119,0.0229770234675502,0.0197652951597104,0.25,0.00135036607003444,0.00225768572040891,0.00135180197870214,299.9971008,299.9971008,75501.4921875,75511.5,56.6438371601406,20.346560061299,28.224119,0,0,0,40,4449,300.15355,75506.49609375,,,,,,,,,,,,,0,,,,0,,,,,,299.9971008,,,,
,28007694,299.9895325,70700.45703125,0.00237820920151334,4.37076350243583E-5,1,0.999253354069792,40.0298881530762,2.00460821125347,19.9299994856119,0.0242632463795069,0.0204164495103257,0.25,0.00138694163355874,0.00237723451272212,0.00138845665966478,299.9895325,299.9895325,70692.828125,70708.0859375,56.6618146160829,20.3460566849415,28.224119,0,0,0,40,4449,300.16845,70700.45703125,,,,,,,,,,,,,0,,,,0,,,,,,299.9895325,,,,
,28007790.545,299.9880066,65874.83203125,0.002572553925031,3.13878865173845E-5,1,0.999253354069792,40.0298881530762,2.00467344478052,19.9299994856119,0.026446846942879,0.0209309587118591,0.25,0.001398547625487,0.002571564974546,0.00140019133628038,299.9880066,299.9880066,65869.6796875,65879.984375,56.4875114562944,20.3465572046143,28.224119,0,0,0,40,4449,300.17605,65874.83203125,,,,,,,,,,,,,0,,,,0,,,,,,299.9880066,,,,
,28007885.9,299.9886169,61109.0078125,0.00253043614699902,6.23985695014113E-5,1,0.999253354069792,40.0298881530762,2.00466114598934,19.9299994856119,0.0257961312445638,0.0218439143439021,0.25,0.00148629561628008,0.00252938964616625,0.00148791099644596,299.9886169,299.9886169,61101.30078125,61116.71484375,56.5734905934098,20.3461188566311,28.224119,0,0,0,40,4449,300.1883,61109.0078125,,,,,,,,,,,,,0,,,,0.00245,,,,,,299.9886169,,,,
,28007984.61,299.9817505,56173.85546875,0.00279856725110179,4.11231121873849E-5,1,0.999253354069792,40.0298881530762,2.00442725397909,19.9299994856119,0.0288519867716564,0.0222764098082794,0.25,0.00147816548093491,0.00279751778377078,0.00147995913802757,299.9817505,299.9817505,56173.85546875,56173.85546875,56.5305010248521,20.3485236122243,28.224119,0,0,0,40,4449,300.2054,56173.85546875,,,,,,,,,,,,,0,,,,0,,,,,,299.9817505,,,,
,28008079.63,299.9906006,51426.5,0.00287544596999311,4.25202175020827E-5,1,0.999253354069792,40.0298881530762,2.00438270491544,19.9299994856119,0.0296155145450468,0.0230518136913076,0.25,0.00153321747974571,0.00287435594786539,0.00153506155313419,299.9906006,299.9906006,51421.2578125,51431.7421875,56.5273745107752,20.3471968610506,27.844467,0,0,0,40,4449,300.2062,51426.5,,,,,,,,,,,,,0,,,,-0.0049,,,,,,299.9906006,,,,
,28008175.105,299.993042,46653.720703125,0.0030029834320419,4.75341032943495E-5,1,0.999253354069792,40.0298881530762,2.0042597101029,19.9299994856119,0.0309014839205858,0.0242215686152428,0.25,0.00161432696022404,0.00300183483054852,0.00161625437461017,299.993042,299.993042,46643.85546875,46663.5859375,56.5828701356406,20.352602553169,28.224119,0,0,0,40,4449,300.21245,46653.720703125,,,,,,,,,,,,,0,,,,-0.00245,,,,,,299.993042,,,,
,28008269.875,299.9938354,41915.787109375,0.00300528097719905,5.43904374452579E-5,1,0.999253354069792,40.0298881530762,2.00431968809384,19.9299994856119,0.0308609024761614,0.0246164828443537,0.25,0.00164866837647632,0.00300410829809612,0.00165059826488478,299.9938354,299.9938354,41911.07421875,41920.5,56.7673344661791,20.3533640585351,28.603769,0,0,0,40,4449,300.21965,41915.787109375,,,,,,,,,,,,,0,,,,-0.0049,,,,,,299.9938354,,,,
,28008367.615,299.9934692,37030.279296875,0.0032224409829372,4.6051420784173E-5,1,0.999253354069792,40.0298881530762,2.00440502204012,19.9299994856119,0.0332742219220732,0.0253458569554205,0.25,0.0016752283738253,0.00322124312461545,0.00167730264350248,299.9934692,299.9934692,37022.70703125,37037.8515625,56.6024108486214,20.3501712733337,28.603769,0,0,0,40,4449,300.2234,37030.279296875,,,,,,,,,,,,,0,,,,-0.00245,,,,,,299.9934692,,,,
,28008464.295,299.99383545,32198.6376953125,0.00328972302544829,6.4661009051553E-5,1,0.999253354069792,40.0298881530762,2.00431914369581,19.9299994856119,0.0339538979029025,0.0259528357803232,0.25,0.00171715129943706,0.0032884941404278,0.00171927083022191,299.9935608,299.9941101,32191.1953125,32206.080078125,56.6821369575829,20.3534788716353,27.844467,0,0,0,40,4449,300.2268,32198.6376953125,,,,,,,,,,,,,0,,,,0,,,,,,299.99383545,,,,
,28008561.51,299.9914246,27340.9384765625,0.00332853437060261,5.0445246672619E-5,1,0.999253354069792,40.0298881530762,2.00421976067458,19.9299994856119,0.0342635907493762,0.026772909604553,0.25,0.00178280627800833,0.00332725998156457,0.00178495169852449,299.9914246,299.9914246,27333.5078125,27348.369140625,56.6297678467945,20.3556869291059,28.224119,0,0,0,40,4449,300.24135,27340.9384765625,,,,,,,,,,,,,0,,,,-0.0049,,,,,,299.9914246,,,,
,28008655.89,299.9809265,22622.9990234375,0.00340597267910434,5.86980581161062E-5,1,0.999253354069792,40.0298881530762,2.00420383660493,19.9299994856119,0.0351430467313176,0.0269189364392519,0.25,0.00178227413040991,0.00340469630424695,0.00178447347435865,299.9809265,299.9809265,22620.60546875,22625.392578125,56.536754053006,20.3556649947833,27.844467,0,0,0,40,4449,300.23985,22622.9990234375,,,,,,,,,,,,,0,,,,0.0049,,,,,,299.9809265,,,,
,28008752.77,299.9876099,17782.9267578125,0.00351479401299712,5.95924952022785E-5,1,0.999253354069792,40.0298881530762,2.00418261110556,19.9299994856119,0.0362845998115145,0.0276683701760398,0.25,0.00182949155077676,0.00351348114552451,0.00183176303072875,299.9876099,299.9876099,17778.06640625,17787.787109375,56.6313311038329,20.3567825143305,28.603769,0,0,0,40,4449,300.252,17782.9267578125,,,,,,,,,,,,,0,,,,0,,,,,,299.9876099,,,,
,28008846.45,299.9902954,13100.3896484375,0.00358412208934882,6.97784515934432E-5,1,0.999253354069792,40.0298881530762,2.00437059813193,19.9299994856119,0.0370106798348221,0.0281757391188611,0.25,0.00186197147949937,0.00358278411688937,0.00186428964264781,299.9902954,299.9902954,13095.3232421875,13105.4560546875,56.6454004171791,20.3563951864631,28.224119,0,0,0,40,4449,300.2567,13100.3896484375,,,,,,,,,,,,,0,,,,0.00245,,,,,,299.9902954,,,,
,28008938.555,299.99221805,8495.07958984375,0.00377557113166706,4.34519697241272E-5,1,0.999253354069792,40.0298881530762,2.00436371872214,19.9299994856119,0.0392273702830337,0.0282961729580162,0.25,0.00183942096407399,0.00377424103471978,0.00184186834908104,299.9919739,299.9924622,8487.7275390625,8502.431640625,56.7860935506406,20.3556594412851,28.224119,0,0,0,40,4449,300.256,8495.07958984375,,,,,,,,,,,,,0,,,,0,,,,,,299.99221805,,,,
,28009031.19,299.9971008,3864.56018066406,0.00370920351259727,4.40917738862384E-5,1,0.999253354069792,40.0298881530762,2.00434160418265,19.9299994856119,0.0385941287941366,0.0274710649533771,0.25,0.00177823230768992,0.00370791426814367,0.00178063888511565,299.9971008,299.9971008,3854.68994140625,3874.43041992188,56.8845787440637,20.3566300089478,28.224119,0,0,0,40,4449,300.25945,3864.56018066406,,,,,,,,,,,,,0,,,,0.00245,,,,,,299.9971008,,,,
,28009123.96,299.9925232,-770.652313232422,-0.00282948214934707,4.41700962097113E-5,1,0.999253354069792,40.0298881530762,2.00427611069521,19.9299994856119,-0.0293257324408293,-0.0216130582792965,0.25,-0.00141447411735636,-0.00282846026248166,-0.00141630912796331,299.9925232,299.9925232,-778.033447265625,-763.271179199219,56.7220000120637,20.3577263301006,28.603769,0,0,0,40,4449,300.2609,-770.652313232422,,,,,,,,,,,,,0,,,,0,,,,,,299.9925232,,,,
,28009214.97,299.999176,-5318.43969726562,-0.00359479112182196,6.7866514179932E-5,1,0.999253354069792,40.0298881530762,2.00422251499604,19.9299994856119,-0.0371126697913365,-0.0282895379972186,0.25,-0.00187032526516771,-0.00359344428754481,-0.00187265257182719,299.999176,299.999176,-5323.322265625,-5313.55712890625,56.7126204698329,20.3583384726625,28.224119,0,0,0,40,4449,300.26445,-5318.43969726562,,,,,,,,,,,,,0,,,,0,,,,,,299.999176,,,,
,28009309.89,300.0033569,-10062.1137695312,-0.00369021908390797,4.82886317556151E-5,1,0.999253354069792,40.0298881530762,2.00428041230248,19.9299994856119,-0.0382736937795865,-0.0280326100450528,0.25,-0.00183108231895374,-0.00368889598127786,-0.00183347196502719,300.0033569,300.0033569,-10067.388671875,-10056.8388671875,56.6336759893906,20.3592527762342,28.224119,0,0,0,40,4449,300.2641,-10062.1137695312,,,,,,,,,,,,,0,,,,0,,,,,,300.0033569,,,,
,28009401.81,300.0084534,-14657.2231445313,-0.00360623384339894,5.11274246757898E-5,1,0.999253354069792,40.0298881530762,2.00420160719434,19.9299994856119,-0.0372453120616127,-0.0282935047115147,0.25,-0.00186872107619796,-0.00360488878083084,-0.0018710518649837,300.0084534,300.0084534,-14664.32421875,-14650.1220703125,56.8384626614291,20.3593236159207,28.603769,0,0,0,40,4449,300.25005,-14657.2231445313,,,,,,,,,,,,,0,,,,0.00245,,,,,,300.0084534,,,,
,28009494.12,300.0091553,-19269.4150390625,-0.00347095981566577,5.95810756295655E-5,1,0.999253354069792,40.0298881530762,2.00426320094699,19.9299994856119,-0.0357489530537772,-0.0278119329151825,0.25,-0.00184964697398207,-0.00346963258235849,-0.00185188686936854,300.0091553,300.0091553,-19276.673828125,-19262.15625,56.9244417985445,20.3586811171508,28.603769,0,0,0,40,4449,300.2441,-19269.4150390625,,,,,,,,,,,,,0,,,,-0.00245,,,,,,300.0091553,,,,
,28009586.75,300.0085449,-23899.5341796875,-0.00339201307118144,5.8280115520398E-5,1,0.999253354069792,40.0298881530762,2.00426564861479,19.9299994856119,-0.0350355647879905,-0.0266041526580388,0.25,-0.00175688444164849,-0.00339075084898842,-0.00175907302574489,300.0085449,300.0085449,-23903.94140625,-23895.126953125,56.8509687177368,20.3600255104767,28.603769,0,0,0,40,4449,300.2358,-23899.5341796875,,,,,,,,,,,,,0,,,,0,,,,,,300.0085449,,,,
,28009680.875,300.0134277,-28604.9150390625,-0.00331688670100605,4.43078981220172E-5,1,0.999253354069792,40.0298881530762,2.00419272817533,19.9299994856119,-0.0342205664447204,-0.0262324799118275,0.25,-0.00173722827128722,-0.00331564046086477,-0.00173936543554765,300.0134277,300.0134277,-28612.609375,-28597.220703125,56.831428004756,20.361235339179,28.603769,0,0,0,40,4449,300.23715,-28604.9150390625,,,,,,,,,,,,,0,,,,-0.00245,,,,,,300.0134277,,,,
,28009779.065,300.0116577,-33512.359375,-0.00323951527430375,5.23552883546482E-5,1,0.999253354069792,40.0298881530762,2.00421260656653,19.9299994856119,-0.033362314776739,-0.0259690760572204,0.25,-0.00172739931604218,-0.00323827940890141,-0.0017294837395357,300.0116577,300.0116577,-33519.97265625,-33504.74609375,56.7251265261406,20.3612679842646,28.224119,0,0,0,40,4449,300.22685,-33512.359375,,,,,,,,,,,,,0,,,,0.00245,,,,,,300.0116577,,,,
,28009875.165,300.0153809,-38313.990234375,-0.00311285011789294,4.88397558572198E-5,1,0.999253354069792,40.0298881530762,2.00425502243943,19.9299994856119,-0.0319795656356677,-0.025409809052351,0.25,-0.00170001319765019,-0.00311163697961814,-0.00170201274916765,300.0153809,300.0153809,-38321.33203125,-38306.6484375,56.8509687177368,20.3597456678287,28.603769,0,0,0,40,4449,300.2085,-38313.990234375,,,,,,,,,,,,,0,,,,-0.0049,,,,,,300.0153809,,,,
,28009971.65,300.01571655,-43136.6171875,-0.0030074585895233,5.18253719534784E-5,1,0.999253354069792,40.0298881530762,2.00411816313194,19.9299994856119,-0.0309552777024777,-0.0241990645410529,0.25,-0.00161171232802017,-0.00300630803927108,-0.00161364310436785,300.0152893,300.0161438,-43144.2421875,-43128.9921875,56.7712426087752,20.3618483612109,28.983419,0,0,0,40,4449,300.196,-43136.6171875,,,,,,,,,,,,,0,,,,0.0049,,,,,,300.01571655,,,,
,28010069.76,300.0166321,-48039.064453125,-0.00291903930488286,5.06311697091754E-5,1,0.999253354069792,40.0298881530762,2.00419311267769,19.9299994856119,-0.0299957569407889,-0.023780053684727,0.25,-0.00159002917504704,-0.00291790688536654,-0.00159190039560947,300.0166321,300.0166321,-48041.5078125,-48036.62109375,57.004167907506,20.3632923626298,28.603769,0,0,0,40,4449,300.18,-48039.064453125,,,,,,,,,,,,,0,,,,0,,,,,,300.0166321,,,,
,28010166.67,300.0136414,-52884.271484375,-0.00280931260124222,4.38388869482291E-5,1,0.999253354069792,40.0298881530762,2.00412815381855,19.9299994856119,-0.0287816684551741,-0.0233799565605939,0.25,-0.0015738439373903,-0.0028081957463518,-0.0015756417193558,300.0136414,300.0136414,-52889.3046875,-52879.23828125,56.6665043871983,20.3637344623171,28.224119,0,0,0,40,4449,300.17275,-52884.271484375,,,,,,,,,,,,,0,,,,0.00245,,,,,,300.0136414,,,,
,28010262.53,300.0116577,-57676.2109375,-0.00267994744573961,6.14974845629247E-5,1,0.999253354069792,40.0298881530762,2.00402145304009,19.9299994856119,-0.0274266049252831,-0.0224657148765826,0.25,-0.00151578324512394,-0.00267887402255438,-0.00151749607330828,300.0116577,300.0116577,-57681.16796875,-57671.25390625,56.8509687177368,20.3658192811225,28.224119,0,0,0,40,4449,300.15995,-57676.2109375,,,,,,,,,,,,,0,,,,-0.0049,,,,,,300.0116577,,,,
,28010359.265,300.0101318,-62508.748046875,-0.0025516868552043,4.78054943302278E-5,1,0.999253354069792,40.0298881530762,2.00416103887622,19.9299994856119,-0.026083570900877,-0.0215776003629393,0.25,-0.00145960293112478,-0.00255065549947371,-0.00146123153298693,300.0101318,300.0101318,-62518.53515625,-62498.9609375,56.8298647477175,20.3619677917837,28.983419,0,0,0,40,4449,300.1546,-62508.748046875,,,,,,,,,,,,,0,,,,-0.00245,,,,,,300.0101318,,,,
,28010456.03,300.0122986,-67343.921875,-0.00248803197640496,5.1214167170556E-5,1,0.999253354069792,40.0298881530762,2.00405341705438,19.9299994856119,-0.0254404502895767,-0.0209871293022399,0.25,-0.00141868807802025,-0.002487030365988,-0.00142027425944975,300.0122986,300.0122986,-67351.4140625,-67336.4296875,56.8337728903137,20.3660090005332,28.224119,0,0,0,40,4449,300.14725,-67343.921875,,,,,,,,,,,,,0,,,,0.00245,,,,,,300.0122986,,,,
,28010549.75,300.011261,-72028.1015625,-0.00242514430479818,4.017971233928E-5,1,0.999253354069792,40.0298881530762,2.00403861753659,19.9299994856119,-0.0248787443165021,-0.0199861641441547,0.25,-0.00134137532252589,-0.00242419642681427,-0.00134292090457886,300.011261,300.011261,-72032.9296875,-72023.2734375,56.8056342636214,20.3671803727365,28.224119,0,0,0,40,4449,300.1471,-72028.1015625,,,,,,,,,,,,,0,,,,-0.00245,,,,,,300.011261,,,,
,28010645.54,300.0155029,-76815.6953125,-0.00229655375840251,4.16837769696376E-5,1,0.999253354069792,40.0298881530762,2.00409543636273,19.9299994856119,-0.0234894346038977,-0.0193355238971652,0.25,-0.00130626337878579,-0.00229563337113173,-0.00130772413845754,300.0155029,300.0155029,-76820.96875,-76810.421875,56.7767140084099,20.366297394955,28.983419,0,0,0,40,4449,300.1243,-76815.6953125,,,,,,,,,,,,,0,,,,0.0049,,,,,,300.0155029,,,,
,28010742.11,300.0188599,-81642.91015625,-0.00208605065753788,3.61341962376035E-5,1,0.999253354069792,40.0298881530762,2.00398289533367,19.9299994856119,-0.0211464623952651,-0.0186519712414496,0.25,-0.00128257743519078,-0.00208515281725699,-0.0012838997902393,300.0188599,300.0188599,-81653.09375,-81632.7265625,56.7032409276022,20.3675700463877,28.603769,0,0,0,40,4449,300.1093,-81642.91015625,,,,,,,,,,,,,0,,,,0,,,,,,300.0188599,,,,
,28010837.38,300.0152588,-86402.61328125,-0.00199953246677074,3.29844821146001E-5,1,0.999253354069792,40.0298881530762,2.00398661754599,19.9299994856119,-0.0203053112725629,-0.0176715531410753,0.25,-0.00121115096874679,-0.00199868508678197,-0.0012124177074958,300.0152588,300.0152588,-86410.15625,-86395.0703125,56.6266413327175,20.3671124436531,28.224119,0,0,0,40,4449,300.0961,-86402.61328125,,,,,,,,,,,,,0,,,,0,,,,,,300.0152588,,,,
,28010948.605,300.013855,-88982.4609375,-0.00195706520852733,2.90596106536207E-5,1,0.999253354069792,40.0298881530762,2.00395848208729,19.9299994856119,-0.0199108014438991,-0.0170824065779755,0.25,-0.00116660189068703,-0.00195624874089187,-0.00116784156714336,300.013855,300.013855,-88987.4296875,-88977.4921875,56.6055373626983,20.3697342802838,28.224119,0,0,0,40,4449,300.08565,-88982.4609375,,,,,,,,,,,,,0,,,,0.0049,,,,,,300.013855,,,,
,28011038.205,300.0041199,-84505.390625,-0.00207321501492889,3.8430477695422E-5,1,0.999253354069792,40.0298881530762,2.00390819889078,19.9299994856119,-0.021095864076708,-0.0180733650269135,0.25,-0.00123385943909186,-0.00207235101144596,-0.001235174692324,300.0041199,300.0041199,-84515.265625,-84495.515625,56.8869236296214,20.3672231331937,28.224119,0,0,0,40,4449,300.08315,-84505.390625,,,,,,,,,,,,,0,,,,0,,,,,,300.0041199,,,,
,28011138.16,299.9996033,-79508.1015625,-0.0021327092768436,4.69288366551506E-5,1,0.999253354069792,40.0298881530762,2.00381378701849,19.9299994856119,-0.0216398692094962,-0.0189397402367786,0.25,-0.00129999027206331,-0.00213179950758926,-0.00130134434913926,299.9996033,299.9996033,-79517.921875,-79498.28125,56.8712910592368,20.3679726367485,28.224119,0,0,0,40,4449,300.0729,-79508.1015625,,,,,,,,,,,,,0,,,,-0.00245,,,,,,299.9996033,,,,
,28011236.825,300.0033264,-74578.50390625,-0.00225943624424112,5.22716396461699E-5,1,0.999253354069792,40.0298881530762,2.00375594280818,19.9299994856119,-0.023022996973663,-0.0194993899780722,0.25,-0.00132741243842213,-0.00225850340338422,-0.0013288499462134,300.0033264,300.0033264,-74580.859375,-74576.1484375,56.8963031718522,20.3703338351055,28.603769,0,0,0,40,4449,300.08365,-74578.50390625,,,,,,,,,,,,,0,,,,0,,,,,,300.0033264,,,,
,28011335.07,299.9955444,-69669.234375,-0.00237889097411779,5.12490323075586E-5,1,0.999253354069792,40.0298881530762,2.00395401576197,19.9299994856119,-0.0242475032049428,-0.0205032759255074,0.25,-0.00139503635534691,-0.00237790986015963,-0.00139655213685713,299.9955444,299.9955444,-69678.828125,-69659.640625,56.8204852054868,20.3688909469903,28.603769,0,0,0,40,4449,300.0882,-69669.234375,,,,,,,,,,,,,0,,,,-0.00245,,,,,,299.9955444,,,,
,28011433.965,299.9898376,-64727.041015625,-0.00250697030603836,4.61703404982153E-5,1,0.999253354069792,40.0298881530762,2.00381620331429,19.9299994856119,-0.0256293092431511,-0.0211554948055596,0.25,-0.00143045413597473,-0.00250596155611703,-0.00143205481988274,299.9898376,299.9898376,-64731.9609375,-64722.12109375,56.7008960420445,20.3702739926168,28.603769,0,0,0,40,4449,300.1002,-64727.041015625,,,,,,,,,,,,,0,,,,-0.00245,,,,,,299.9898376,,,,
,28011530.95,299.9873047,-59876.42578125,-0.00264220210460882,3.52461128437498E-5,1,0.999253354069792,40.0298881530762,2.00393189173284,19.9299994856119,-0.0270529836305693,-0.0220687819921173,0.25,-0.00148741942508244,-0.0026411510860022,-0.0014891090936442,299.9873047,299.9873047,-59883.984375,-59868.8671875,56.9002113144483,20.3677551373995,28.603769,0,0,0,40,4449,300.10715,-59876.42578125,,,,,,,,,,,,,0,,,,-0.00245,,,,,,299.9873047,,,,
,28011628.52,299.9890137,-55001.986328125,-0.00277785205611306,3.69012061388883E-5,1,0.999253354069792,40.0298881530762,2.00380571771258,19.9299994856119,-0.0285556335097704,-0.022533835813993,0.25,-0.00150502624708073,-0.00277678412487958,-0.00150680622698816,299.9890137,299.9890137,-55006.7421875,-54997.23046875,57.1065612435253,20.369172717624,28.603769,0,0,0,40,4449,300.11965,-55001.986328125,,,,,,,,,,,,,0,,,,-0.0049,,,,,,299.9890137,,,,
,28011723.555,299.9842529,-50252.58203125,-0.00288584775363393,5.80042148826428E-5,1,0.999253354069792,40.0298881530762,2.00407635432319,19.9299994856119,-0.0296953264264174,-0.0232645085976932,0.25,-0.00155045626330166,-0.00288474609991328,-0.00155230803791612,299.9842529,299.9842529,-50255.23046875,-50249.93359375,56.6414922745829,20.3635643487595,28.603769,0,0,0,40,4449,300.13365,-50252.58203125,,,,,,,,,,,,,0,,,,0,,,,,,299.9842529,,,,
,28011818.205,299.9916077,-45523.0078125,-0.00304286379355216,3.74239369467161E-5,1,0.999253354069792,40.0298881530762,2.0039105857846,19.9299994856119,-0.0314146640622667,-0.0239157394596225,0.25,-0.00158081458510015,-0.00304173555967903,-0.00158277031284082,299.9916077,299.9916077,-45528.0546875,-45517.9609375,56.6711941583137,20.3663688527302,28.603769,0,0,0,40,4449,300.14065,-45523.0078125,,,,,,,,,,,,,0,,,,-0.00245,,,,,,299.9916077,,,,
,28011914.39,299.9897156,-40715.44140625,-0.00312270129621753,4.51245921782388E-5,1,0.999253354069792,40.0298881530762,2.00414685254957,19.9299994856119,-0.0321676750617905,-0.0249779998215935,0.25,-0.00166036350586862,-0.00312151723144487,-0.00166237169634203,299.9897156,299.9897156,-40720,-40710.8828125,56.7141837268714,20.3604734032517,28.983419,0,0,0,40,4449,300.14405,-40715.44140625,,,,,,,,,,,,,0,,,,-0.00245,,,,,,299.9897156,,,,
,28012012.315,299.9866333,-35820.41796875,-0.00323899724328242,4.51171206356948E-5,1,0.999253354069792,40.0298881530762,2.00416884371623,19.9299994856119,-0.0334276979259893,-0.0255524133043114,0.25,-0.00169081364385122,-0.00323778866984047,-0.00169289996425197,299.9866333,299.9866333,-35827.5078125,-35813.328125,56.7524835243137,20.3610997924696,29.363071,0,0,0,40,4449,300.14405,-35820.41796875,,,,,,,,,,,,,0,,,,0,,,,,,299.9866333,,,,
,28012109.02,299.9888306,-30987.703125,-0.00332353094383003,4.41408119405883E-5,1,0.999253354069792,40.0298881530762,2.00397181026902,19.9299994856119,-0.0343235073878574,-0.0260631686966573,0.25,-0.00172139543973305,-0.00332229818033204,-0.00172353853267509,299.9888306,299.9888306,-30990.01171875,-30985.39453125,56.7462304961599,20.3628378530095,28.983419,0,0,0,40,4449,300.16235,-30987.703125,,,,,,,,,,,,,0,,,,-0.0049,,,,,,299.9888306,,,,
,28012206.195,299.9876099,-26133.0869140625,-0.00345992897747125,5.78590547843561E-5,1,0.999253354069792,40.0298881530762,2.00417845827551,19.9299994856119,-0.0357895391141015,-0.0268244267049198,0.25,-0.00176462662019724,-0.00345866250883427,-0.00176686069864562,299.9876099,299.9876099,-26143.08203125,-26123.091796875,56.7235632691022,20.359861820144,28.983419,0,0,0,40,4449,300.1734,-26133.0869140625,,,,,,,,,,,,,0,,,,-0.00245,,,,,,299.9876099,,,,
,28012302.595,299.9936218,-21313.2412109375,-0.00354045866398844,5.11231037386525E-5,1,0.999253354069792,40.0298881530762,2.00394707592963,19.9299994856119,-0.0366863211121439,-0.027054184749214,0.25,-0.00177118448716187,-0.00353918342945159,-0.00177347332784139,299.9936218,299.9936218,-21320.6171875,-21305.865234375,56.5680191937752,20.3633420986696,28.983419,0,0,0,40,4449,300.1812,-21313.2412109375,,,,,,,,,,,,,0,,,,0.0049,,,,,,299.9936218,,,,
,28012399.82,299.9856873,-16453.728515625,-0.00362225589315138,4.04615254240676E-5,1,0.999253354069792,40.0298881530762,2.00397541332461,19.9299994856119,-0.0375304806747117,-0.0277022801495796,0.25,-0.00181410105139316,-0.00362094959432751,-0.00181644535622562,299.9856873,299.9856873,-16458.837890625,-16448.619140625,56.6672860157175,20.3640556917719,28.983419,0,0,0,40,4449,300.1875,-16453.728515625,,,,,,,,,,,,,0,,,,0.00245,,,,,,299.9856873,,,,
,28012493.82,299.9881592,-11755.9150390625,-0.00370468970423702,3.71768968641378E-5,1,0.999253354069792,40.0298881530762,2.00375817706916,19.9299994856119,-0.0384061950991588,-0.0281820381945944,0.25,-0.0018423600559345,-0.00370336074159281,-0.00184475992398575,299.9881592,299.9881592,-11760.953125,-11750.876953125,56.8306463762368,20.362778155885,28.603769,0,0,0,40,4449,300.19205,-11755.9150390625,,,,,,,,,,,,,0,,,,0.0049,,,,,,299.9881592,,,,
,28012587.455,299.9934387,-7075.2880859375,-0.00368201151619543,5.45084289105022E-5,1,0.999253354069792,40.0298881530762,2.00381495443048,19.9299994856119,-0.0381829661458274,-0.0279475786542396,0.25,-0.00182555399607772,-0.00368069251439087,-0.00182794084453133,299.9934387,299.9934387,-7077.65185546875,-7072.92431640625,56.7814037795252,20.3654769289681,28.983419,0,0,0,40,4449,300.19285,-7075.2880859375,,,,,,,,,,,,,0,,,,0.00245,,,,,,299.9934387,,,,
,28012682.515,299.9940186,-2324.18188476562,-0.00352412614445709,4.27793492792165E-5,1,0.999253354069792,40.0298881530762,2.00392284408856,19.9299994856119,-0.0365851225816498,-0.0265336305170346,0.25,-0.00172815227120237,-0.00352287536219011,-0.00173043885118236,299.9940186,299.9940186,-2329.30419921875,-2319.0595703125,56.5742722219291,20.3627194379145,29.363071,0,0,0,40,4449,300.19495,-2324.18188476562,,,,,,,,,,,,,0,,,,0,,,,,,299.9940186,,,,
,28012772.43,299.9936523,2167.31860351562,0.00349980642610992,6.09447611224801E-5,1,0.999253354069792,40.0298881530762,2.00388960314464,19.9299994856119,0.0362442643847318,0.0268569321572276,0.25,0.00176089994112655,0.00349853466682795,0.00176316947348495,299.9936523,299.9936523,2160.07421875,2174.56298828125,56.6328943608714,20.3631267330439,29.363071,0,0,0,40,4449,300.1964,2167.31860351562,,,,,,,,,,,,,0,,,,-0.00245,,,,,,299.9936523,,,,
,28012865.62,299.9967651,6823.78466796875,0.00363822433264554,6.1183668592144E-5,1,0.999253354069792,40.0298881530762,2.00388797303978,19.9299994856119,0.0376693951580854,0.0279670889720802,0.25,0.00183477490373123,0.00363690006662506,0.00183713225181135,299.9967651,299.9967651,6818.5810546875,6828.98828125,56.8283014906791,20.3633439947746,28.983419,0,0,0,40,4449,300.2011,6823.78466796875,,,,,,,,,,,,,0,,,,-0.0049,,,,,,299.9967651,,,,
,28012959.955,300.0042419,11541.9614257813,0.00362778149339608,6.51604939744693E-5,1,0.999253354069792,40.0298881530762,2.00371235941794,19.9299994856119,0.0375444481861507,0.0279634732889952,0.25,0.0018364738959198,0.00362645657722952,0.00183882195194755,300.0042419,300.0042419,11531.9248046875,11551.998046875,56.7227816405829,20.3674277011977,29.363071,0,0,0,40,4449,300.19955,11541.9614257813,,,,,,,,,,,,,0,,,,0,,,,,,300.0042419,,,,
,28013057.415,300.0066223,16412.119140625,0.00363255680374914,4.74860897632637E-5,1,0.999253354069792,40.0298881530762,2.00351214696536,19.9299994856119,0.0376307344959885,0.0277642128812023,0.25,0.00181831675872458,0.00363124469645189,0.00182066636746062,300.0066223,300.0066223,16404.640625,16419.59765625,56.8040710065829,20.3686569496297,28.983419,0,0,0,40,4449,300.19185,16412.119140625,,,,,,,,,,,,,0,,,,-0.00245,,,,,,300.0066223,,,,
,28013154.54,300.0019836,21264.5810546875,0.00350091845769519,5.1145385451071E-5,1,0.999253354069792,40.0298881530762,2.00372578885895,19.9299994856119,0.0362327854791255,0.0269800076902459,0.25,0.00177174830760701,0.0034996429621919,0.00177401045488375,300.0019836,300.0019836,21256.873046875,21272.2890625,56.729816297256,20.3641817846632,28.983419,0,0,0,40,4449,300.1837,21264.5810546875,,,,,,,,,,,,,0,,,,0.00245,,,,,,300.0019836,,,,
,28013251.39,300.0150146,26107.140625,0.00340653406261045,4.8405486061504E-5,1,0.999253354069792,40.0298881530762,2.00357303488783,19.9299994856119,0.035145164763769,0.0268753542196208,0.25,0.0017790512470411,0.00340525638178438,0.00178124770551626,300.0150146,300.0150146,26104.1875,26110.09375,56.5922496778714,20.3665395869383,29.363071,0,0,0,40,4449,300.1956,26107.140625,,,,,,,,,,,,,0,,,,-0.0049,,,,,,300.0150146,,,,
,28013346.305,300.0096741,30852.5498046875,0.00320419808501447,6.06108453728529E-5,1,0.999253354069792,40.0298881530762,2.00350072948484,19.9299994856119,0.0329108374061012,0.0261192086483205,0.25,0.00174752814781345,0.00320294917790266,0.00174959038439086,300.0096741,300.0096741,30842.365234375,30862.734375,56.6454004171791,20.3653089829239,29.363071,0,0,0,40,4449,300.1744,30852.5498046875,,,,,,,,,,,,,0,,,,-0.00245,,,,,,300.0096741,,,,
,28013440.475,300.0105286,35558.08203125,0.00322666201910082,3.73223642720474E-5,1,0.999253354069792,40.0298881530762,2.00360525936561,19.9299994856119,0.0333155683611212,0.0253089421382627,0.25,0.00167209366238548,0.00322546341975503,0.00167417088726669,300.0105286,300.0105286,35555.6171875,35560.546875,56.7134020983521,20.3659265949485,28.983419,0,0,0,40,4449,300.1676,35558.08203125,,,,,,,,,,,,,0,,,,0,,,,,,300.0105286,,,,
,28013534.905,300.0135803,40277.7578125,0.00309822769628477,5.31506253757988E-5,1,0.999253354069792,40.0298881530762,2.00351321746856,19.9299994856119,0.0318323194055995,0.0251995127660867,0.25,0.00168479817188067,0.00309702554314112,0.00168678816962811,300.0135803,300.0135803,40268.04296875,40287.47265625,56.4890747133329,20.3678382856777,28.603769,0,0,0,40,4449,300.15905,40277.7578125,,,,,,,,,,,,,0,,,,0,,,,,,300.0135803,,,,
,28013630.4,300.0122375,45051.4453125,0.00295783849826655,5.36949272681475E-5,1,0.999253354069792,40.0298881530762,2.0036553192042,19.9299994856119,0.0304416958407807,0.0237723480740645,0.25,0.00158316279530094,0.00295670895395857,0.00158506141584528,300.0122375,300.0122375,45046.09375,45056.796875,56.6532167023714,20.3651006694131,29.363071,0,0,0,40,4449,300.15955,45051.4453125,,,,,,,,,,,,,0,,,,0,,,,,,300.0122375,,,,
,28013728.065,300.0130615,49931.50390625,0.00291195310901761,4.42150557415875E-5,1,0.999253354069792,40.0298881530762,2.00382052505715,19.9299994856119,0.0300001569347271,0.023241849400394,0.25,0.00154418783457476,0.00291085174043868,0.00154605545353458,300.0130615,300.0130615,49918.9609375,49944.046875,56.6508718168137,20.3634180957307,29.363071,0,0,0,40,4449,300.1376,49931.50390625,,,,,,,,,,,,,0,,,,-0.00245,,,,,,300.0130615,,,,
,28013826.48,300.0110474,54851.28125,0.00281623263598279,3.05359483886161E-5,1,0.999253354069792,40.0298881530762,2.00363744903442,19.9299994856119,0.0289938710303939,0.0225776079809708,0.25,0.00150239609069348,0.00281516307412005,0.00150420018316758,300.0110474,300.0110474,54846.3203125,54856.2421875,56.6071006197368,20.3637631707025,29.363071,0,0,0,40,4449,300.1239,54851.28125,,,,,,,,,,,,,0,,,,0,,,,,,300.0110474,,,,
,28013922.81,300.0134277,59666.4765625,0.0026846952934266,3.86963311666259E-5,1,0.999253354069792,40.0298881530762,2.00353152478485,19.9299994856119,0.0275488907659145,0.0220379233905435,0.25,0.00147770954002178,0.00268364687720822,0.0014794259983561,300.0134277,300.0134277,59659.140625,59673.8125,56.8634747740445,20.3673384571453,28.603769,0,0,0,40,4449,300.11435,59666.4765625,,,,,,,,,,,,,0,,,,0,,,,,,300.0134277,,,,
,28014022.8,300.0140381,64662.162109375,0.00252733704846063,4.82565301972505E-5,1,0.999253354069792,40.0298881530762,2.00344447090236,19.9299994856119,0.0258028765078716,0.0214970255249038,0.25,0.00145736747946043,0.00252630789260256,0.00145897945994251,300.0140381,300.0140381,64657.265625,64667.05859375,56.4546830584867,20.365628031406,28.983419,0,0,0,40,4449,300.10435,64662.162109375,,,,,,,,,,,,,0,,,,0.0049,,,,,,300.0140381,,,,
,28014117.255,300.0126038,69384.828125,0.00242699670858606,4.31672130868754E-5,1,0.999253354069792,40.0298881530762,2.00349289690959,19.9299994856119,0.0248107651607978,0.0204608967674847,0.25,0.00138336370971121,0.00242602032574517,0.00138491048748606,300.0126038,300.0126038,69374.75,69394.90625,56.4687523718329,20.3646957538928,28.983419,0,0,0,40,4449,300.0994,69384.828125,,,,,,,,,,,,,0,,,,-0.00245,,,,,,300.0126038,,,,
,28014215.41,300.0172424,74290.12890625,0.00228528357492263,4.77455047834193E-5,1,0.999253354069792,40.0298881530762,2.00362431674632,19.9299994856119,0.0233080695827379,0.0195874874771425,0.25,0.00133080910819781,0.00228434654118667,0.00133226285149455,300.0172424,300.0172424,74282.78125,74297.4765625,56.8916134007368,20.3627808042865,28.983419,0,0,0,40,4449,300.0818,74290.12890625,,,,,,,,,,,,,0,,,,-0.0049,,,,,,300.0172424,,,,
,28014312.695,300.0134583,79155.796875,0.00214781375039355,4.70562152986405E-5,1,0.999253354069792,40.0298881530762,2.00357679302334,19.9299994856119,0.0218063488991291,0.018981151095642,0.25,0.00130121324169827,0.00214690162162659,0.00130257656872314,300.0134583,300.0134583,79145.8046875,79165.7890625,56.5117419403906,20.3625579697145,28.983419,0,0,0,40,4449,300.0812,79155.796875,,,,,,,,,,,,,0,,,,-0.00245,,,,,,300.0134583,,,,
,28014411.095,300.012207,84074.3125,0.00206076307187507,3.99578616261598E-5,1,0.999253354069792,40.0298881530762,2.00355876865674,19.9299994856119,0.0209853437238392,0.0178482272701795,0.25,0.00121643439848114,0.00205991001417317,0.00121774192645928,300.012207,300.012207,84064.3046875,84084.3203125,56.177986562679,20.3603657249881,28.603769,0,0,0,40,4449,300.0638,84074.3125,,,,,,,,,,,,,0,,,,0.00245,,,,,,300.012207,,,,
,28014508.37,300.0136414,88934.9140625,0.00187485015840675,3.82377259715216E-5,1,0.999253354069792,40.0298881530762,2.00355118803338,19.9299994856119,0.0188950793097032,0.0173750931049894,0.25,0.00120693988240468,0.00187400972510764,0.00120812504458971,300.0136414,300.0136414,88932.3203125,88937.5078125,56.5680191937752,20.3635242699306,28.603769,0,0,0,40,4449,300.05175,88934.9140625,,,,,,,,,,,,,0,,,,0,,,,,,300.0136414,,,,
,28014620.11,300.006958,86416.3046875,0.00189336953404798,5.55571153120299E-5,1,0.999253354069792,40.0298881530762,2.00351218027828,19.9299994856119,0.0190067286827694,0.0179772011675806,0.25,0.00125684045365219,0.00189249591941703,0.00125803728072741,300.006958,300.006958,86408.9453125,86423.6640625,56.4820400566598,20.3610183412991,29.363071,0,0,0,40,4449,300.0522,86416.3046875,,,,,,,,,,,,,0,,,,-0.00245,,,,,,300.006958,,,,
,28014715.5,300.005249,81647.75390625,0.00207804843202752,4.47584635259442E-5,1,0.999253354069792,40.0298881530762,2.00370484989491,19.9299994856119,0.0210439206261297,0.0186855730250052,0.25,0.0012871423988052,0.00207714862874412,0.00128846034927397,300.005249,300.005249,81645.1171875,81650.390625,56.7173102409483,20.3626078387024,29.363071,0,0,0,40,4449,300.0448,81647.75390625,,,,,,,,,,,,,0,,,,0.0049,,,,,,300.005249,,,,
,28014813.6,299.9896851,76744.140625,0.00226347666448439,3.37717619979198E-5,1,0.999253354069792,40.0298881530762,2.00366403497935,19.9299994856119,0.0230934783194175,0.0193585040312054,0.25,0.00131436784010803,0.00226255379873453,0.00131580835700594,299.9896851,299.9896851,76731.546875,76756.734375,56.5187765970637,20.3654390352868,29.363071,0,0,0,40,4449,300.0611,76744.140625,,,,,,,,,,,,,0,,,,0,,,,,,299.9896851,,,,
,28014909.23,299.9920959,71963.1015625,0.00240646664622248,3.25442321760575E-5,1,0.999253354069792,40.0298881530762,2.00370078332599,19.9299994856119,0.0246426823025935,0.0200628090958843,0.25,0.00135164923922003,0.00240551388593906,0.00135318378807534,299.9920959,299.9920959,71952.96875,71973.234375,56.7517018957945,20.3666633808958,29.363071,0,0,0,40,4449,300.05755,71963.1015625,,,,,,,,,,,,,0,,,,0.0049,,,,,,299.9920959,,,,
,28015003.32,299.9898071,67262.23046875,0.0024617949651685,5.23660734724476E-5,1,0.999253354069792,40.0298881530762,2.0036659361239,19.9299994856119,0.0252019945632621,0.0205631665839396,0.25,0.00138619928739388,0.00246081699991688,0.00138777092574856,299.9898071,299.9898071,67254.6015625,67269.859375,56.3624508932175,20.363498988513,28.983419,0,0,0,40,4449,300.0607,67262.23046875,,,,,,,,,,,,,0,,,,0,,,,,,299.9898071,,,,
,28015098.93,299.9918213,62482.58984375,0.00255418682147144,5.24237692945599E-5,1,0.999253354069792,40.0298881530762,2.00371599639563,19.9299994856119,0.0261175417390558,0.0215137538403911,0.25,0.00145394289259544,0.00255316041894281,0.00145557477615001,299.9918213,299.9918213,62477.796875,62487.3828125,56.546915223756,20.3657783129823,29.363071,0,0,0,40,4449,300.07215,62482.58984375,,,,,,,,,,,,,0,,,,0,,,,,,299.9918213,,,,
,28015194.77,299.9880676,57690.572265625,0.0026647626614168,5.89250648914058E-5,1,0.999253354069792,40.0298881530762,2.003650043322,19.9299994856119,0.0273040805283255,0.022117011489661,0.25,0.00148802256294831,0.0026637098357605,0.00148972797963579,299.9880676,299.9880676,57688.09375,57693.05078125,56.7673344661791,20.3650566777364,29.363071,0,0,0,40,4449,300.08735,57690.572265625,,,,,,,,,,,,,0,,,,0.00245,,,,,,299.9880676,,,,
,28015289.89,299.9868164,52938,0.00279148675614996,6.30226850397264E-5,1,0.999253354069792,40.0298881530762,2.0034977407175,19.9299994856119,0.0286890450818529,0.0226557638781358,0.25,0.00151370343589894,0.00279041229067247,0.00151549323868826,299.9868164,299.9868164,52930.484375,52945.515625,56.5555131374675,20.3665971048076,28.603769,0,0,0,40,4449,300.0993,52938,,,,,,,,,,,,,0,,,,0.0049,,,,,,299.9868164,,,,
,28015384.06,299.989624,48229.908203125,0.00290867609964014,4.67042005562362E-5,1,0.999253354069792,40.0298881530762,2.00385594232009,19.9299994856119,0.029846470673864,0.023911315183327,0.25,0.00160372862929797,0.00290753746684723,0.00160559468927506,299.989624,299.989624,48222.515625,48237.30078125,56.3444734372752,20.3639620636308,29.363071,0,0,0,40,4449,300.09765,48229.908203125,,,,,,,,,,,,,0,,,,0.00245,,,,,,299.989624,,,,
,28015476.905,299.9934387,43587.45703125,0.00307751695732748,4.12430142505925E-5,1,0.999253354069792,40.0298881530762,2.00363440185748,19.9299994856119,0.031712791087673,0.0245049440615601,0.25,0.00162702817439708,0.0030763563878365,0.0016290063692678,299.9934387,299.9934387,43579.96484375,43594.94921875,56.5680191937752,20.3652427091433,29.363071,0,0,0,40,4449,300.1068,43587.45703125,,,,,,,,,,,,,0,,,,-0.0049,,,,,,299.9934387,,,,
,28015569.22,299.9858704,38976.775390625,0.00313015276640506,4.18419797095551E-5,1,0.999253354069792,40.0298881530762,2.00332509470299,19.9299994856119,0.0322193246511806,0.0250999287712618,0.25,0.00167068298058254,0.00312896151825854,0.00167269693167072,299.9858704,299.9858704,38967.1328125,38986.41796875,56.638365760506,20.3684610797088,29.742722,0,0,0,40,4449,300.12485,38976.775390625,,,,,,,,,,,,,0,,,,-0.00245,,,,,,299.9858704,,,,
,28015664.04,299.9892578,34234.912109375,0.00324276708242786,5.87958733418298E-5,1,0.999253354069792,40.0298881530762,2.00336565994746,19.9299994856119,0.0334183477797066,0.0257769942144238,0.25,0.00171082162720575,0.00324154436417754,0.00171291052423616,299.9892578,299.9892578,34224.85546875,34244.96875,56.7696793517368,20.3664138266058,29.363071,0,0,0,40,4449,300.1293,34234.912109375,,,,,,,,,,,,,0,,,,0.00245,,,,,,299.9892578,,,,
,28015760.625,299.98703,29409.9658203125,0.00331068368702026,4.86228155507323E-5,1,0.999253354069792,40.0298881530762,2.0033732927114,19.9299994856119,0.034078170751343,0.0265490084789182,0.25,0.00176710942515862,0.00330942077671709,0.00176924369048986,299.98703,299.98703,29407.22265625,29412.708984375,56.6618146160829,20.3658654759018,29.742722,0,0,0,40,4449,300.1426,29409.9658203125,,,,,,,,,,,,,0,,,,0,,,,,,299.98703,,,,
,28015857.5,299.9875183,24569.59375,0.00342798300780753,4.17359581931229E-5,1,0.999253354069792,40.0298881530762,2.00356435515639,19.9299994856119,0.035399790847485,0.0268513803458153,0.25,0.0017732280426853,0.00342671119837986,0.00177544171837171,299.9875183,299.9875183,24559.6640625,24579.5234375,56.6610329875637,20.3655281047921,28.983419,0,0,0,40,4449,300.14485,24569.59375,,,,,,,,,,,,,0,,,,0.0049,,,,,,299.9875183,,,,
,28015951.595,299.99497985,19864.7080078125,0.00354076679915985,5.10126622696028E-5,1,0.999253354069792,40.0298881530762,2.00365836965625,19.9299994856119,0.0365951713703874,0.0275681882579252,0.25,0.00181676945006623,0.00353946066629301,0.00181905797620917,299.9942932,299.9956665,19862.3515625,19867.064453125,56.7001144135252,20.3658646059076,29.363071,0,0,0,40,4449,300.151,19864.7080078125,,,,,,,,,,,,,0,,,,-0.0049,,,,,,299.99497985,,,,
,28016046.04,299.9902344,15144.8227539062,0.00361847277413551,5.81207423722105E-5,1,0.999253354069792,40.0298881530762,2.00355672587681,19.9299994856119,0.0374072022895453,0.0281099203184429,0.25,0.00185117959034922,0.00361714091442374,0.00185352086539615,299.9902344,299.9902344,15134.8984375,15154.7470703125,56.9791557948906,20.3665272713725,29.363071,0,0,0,40,4449,300.15505,15144.8227539062,,,,,,,,,,,,,0,,,,0.0049,,,,,,299.9902344,,,,
,28016140.87,299.986908,10407.3295898438,0.00360201440235268,6.6805064642104E-5,1,0.999253354069792,40.0298881530762,2.00351516103097,19.9299994856119,0.0372542464083416,0.0278780020989513,0.25,0.00183363241362046,0.00360069390639934,0.00183596538601836,299.986908,299.986908,10397.43359375,10417.2255859375,56.6235148186406,20.368654039476,29.363071,0,0,0,40,4449,300.1661,10407.3295898438,,,,,,,,,,,,,0,,,,0,,,,,,299.986908,,,,
,28016231.205,299.9927979,5889.1181640625,0.00358985088940663,7.16066920584125E-5,1,0.999253354069792,40.0298881530762,2.00334903660344,19.9299994856119,0.0371463420284394,0.0276612855654796,0.25,0.00181682607177953,0.00358854003376029,0.00181915284136371,299.9927979,299.9927979,5879.24462890625,5898.99169921875,56.7313795542945,20.3694433650363,29.363071,0,0,0,40,4449,300.16085,5889.1181640625,,,,,,,,,,,,,0,,,,0,,,,,,299.9927979,,,,
,28016321.47,299.9908447,1377.87445068359,0.00333380808886004,3.56637059782247E-5,1,0.999253354069792,40.0298881530762,2.0034467032405,19.9299994856119,0.0346486621635539,0.0248229464822965,0.25,0.0016108381344792,0.00333264090236435,0.00161300252998481,299.9908447,299.9908447,1370.54711914062,1385.20178222656,56.8892685151791,20.3693263711259,28.983419,0,0,0,40,4449,300.1759,1377.87445068359,,,,,,,,,,,,,0,,,,-0.00245,,,,,,299.9908447,,,,
,28016348.77,299.9916992,-0.350146770477295,0.000301960940273403,1.74921552731249E-5,1,0.999253354069792,40.0298881530762,2.0033156275395,19.9299994856119,0.0031501684536001,0.00217866578026213,0.25,0.000139770902613974,0.000301859266129762,0.000139967145592354,299.9916992,299.9916992,-0.365370541810989,-0.3349229991436,56.7149653553906,20.369994529587,29.363071,0,0,0,40,4417,300.1764,-0.350146770477295,,,,,,,,,,,,,0,,,,0,,,,,,299.9916992,,,,