File: data/monolayers/nanoparticles/Ac_CoFe_C_2/vsm/data_dispersion/YF45_HYST_200K.DAT
[Header]
; VSM Data File (default extension .dat)
; Copyright (c) 2003-2013, Quantum Design, Inc. All rights reserved.
TITLE,
FILEOPENTIME,27993373.19,11/21/2018,7:56 am
BYAPP,VSM,2.0,2.0
INFO,PPMS VSM Option Release 1.4.10 Build 1,APPNAME
INFO,Quantum Design Linear Motor Servo Controller,MOTOR_MODULE_NAME
INFO,3101-100 M1,MOTOR_HW_VERSION
INFO,MMC1014,MOTOR_SERIAL_NUMBER
INFO,SRV No X-over 01.03.11,MOTOR_SOFTWARE_VERSION
INFO,Quantum Design VSM Detection Module,VSM_MODULE_NAME
INFO,3101-150 F0,VSM_HW_VERSION
INFO,VSM707,VSM_SERIAL_NUMBER
INFO,VSM No X-over 01.02.05 May 20 2008 13:51:47,VSM_SOFTWARE_VERSION
INFO,704,PREAMP_SERIAL_NUMBER
INFO,822,COIL_SERIAL_NUMBER
INFO,0,MOMENT_UNITS
INFO,CoFe2O4,SAMPLE_MATERIAL
INFO,dispersion in ampulle,SAMPLE_COMMENT
INFO,,SAMPLE_MASS
INFO,,SAMPLE_VOLUME
INFO,,SAMPLE_MOLECULAR_WEIGHT
INFO,,SAMPLE_SIZE
INFO,,SAMPLE_SHAPE
DATATYPE,COMMENT,1
DATATYPE,TIME,2
STARTUPAXIS,X,2
STARTUPAXIS,Y1,5
[Data]
Comment,Time Stamp (sec),Temperature (K),Magnetic Field (Oe),Moment (emu),M. Std. Err. (emu),Transport Action,Averaging Time (sec),Frequency (Hz),Peak Amplitude (mm),Center Position (mm),Coil Signal' (mV),Coil Signal" (mV),Range (mV),M. Quad. Signal (emu),M. Raw' (emu),M. Raw" (emu),Min. Temperature (K),Max. Temperature (K),Min. Field (Oe),Max. Field (Oe),Mass (grams),Motor Lag (deg),Pressure (Torr),VSM Status (code),Motor Status (code),Measure Status (code),Measure Count,PPMS Status (code),System Temp. (K),System Field (Oe),Sample Position (deg),Bridge 1 Resistance (ohms),Bridge 1 Excitation (에),Bridge 2 Resistance (ohms),Bridge 2 Excitation (에),Bridge 3 Resistance (ohms),Bridge 3 Excitation (에),Bridge 4 Resistance (ohms),Bridge 4 Excitation (에),Signal 1 Vin (V),Signal 2 Vin (V),Digital Inputs (code),Drive 1 Iout (mA),Drive 1 Ipower (W),Drive 2 Iout (mA),Drive 2 Ipower (W),Pressure (),Map 20 (),Map 21 (),Map 22 (),Map 23 (),Map 24 (),Map 25 (),Map 26 (),Map 27 (),Map 28 (),Map 29 ()
,27993388.98,200.280426,0.380594313144684,,,2,,,,20.7600001600385,,,,,,,200.280426,200.280426,0.380594313144684,0.380594313144684,,,26.325863,,,,-99999999,4433,200.2999,0.380594313144684,,,,,,,,,,,,,,,,,,,,,,,200.280426,,,,
,27993531.155,200.2038879,4574.06884765625,0.00293625876397219,1.96834329027399E-5,1,0.999253354069792,40.0298881530762,1.99166372797992,20.7499992102385,0.0299358310314005,0.0247420618479213,0.25,0.00167619993380496,0.00294455568884134,0.00168515983226901,200.2038879,200.2038879,4571.650390625,4576.4873046875,56.3577611221021,20.3476103442259,26.325863,0,0,0,40,4449,200.0415,4574.06884765625,,,,,,,,,,,,,0,,,,-0.00245,,,,,,200.2038879,,,,
,27993627.975,200.1327209,9412.72802734375,0.00293352986724282,1.9739986576825E-5,1,0.999253354069792,40.0298881530762,1.9917884292867,20.7499992102385,0.0298892909834239,0.024839200820205,0.25,0.00168512287985587,0.00294181659336898,0.0016941120421412,200.1327209,200.1327209,9407.7841796875,9417.671875,56.1021685963136,20.3537613471461,26.325863,0,0,0,40,4449,199.9557,9412.72802734375,,,,,,,,,,,,,0,,,,0,,,,,,200.1327209,,,,
,27993723.845,200.0756378,14202.9282226563,0.00289839048676653,2.87551645185501E-5,1,0.999253354069792,40.0298881530762,1.9918510126413,20.7499992102385,0.0294669832513964,0.0249181387244246,0.25,0.00169813367507201,0.00290655040348614,0.00170712913612042,200.0756378,200.0756378,14190.775390625,14215.0810546875,56.3093001539098,20.3564547030989,26.325863,0,0,0,40,4449,199.9157,14202.9282226563,,,,,,,,,,,,,0,,,,-0.0049,,,,,,200.0756378,,,,
,27993822.945,200.0379333,19155.28125,0.00282659636872941,1.9174247498744E-5,1,0.999253354069792,40.0298881530762,1.9917493850978,20.7499992102385,0.0287116552569897,0.0244385009845438,0.25,0.00166833317521726,0.00283454802535313,0.001677145735434,200.0379333,200.0379333,19147.896484375,19162.666015625,56.445303516256,20.3558605333531,25.946213,0,0,0,40,4449,199.9001,19155.28125,,,,,,,,,,,,,0,,,,0.00245,,,,,,200.0379333,,,,
,27993919.995,200.019928,24007.8671875,0.00277313929968475,2.37468032546941E-5,1,0.999253354069792,40.0298881530762,1.99172367312446,20.7499992102385,0.0282098463040429,0.023737224428608,0.25,0.00161568495674239,0.00278096874594236,0.00162425435369868,200.019928,200.019928,24000.341796875,24015.392578125,56.7407590965252,20.3562428628661,26.325863,0,0,0,40,4449,199.89235,24007.8671875,,,,,,,,,,,,,0,,,,0,,,,,,200.019928,,,,
,27994018.855,200.00335695,28948.123046875,0.00268766573138947,1.57430193734449E-5,1,0.999253354069792,40.0298881530762,1.99167242815138,20.7499992102385,0.0272732893956622,0.0233877187574126,0.25,0.00159970319270954,0.00269522288099488,0.00160812111528862,200.0029755,200.0037384,28937.97265625,28958.2734375,56.5969394489868,20.3584212305857,25.946213,0,0,0,40,4449,199.89625,28948.123046875,,,,,,,,,,,,,0,,,,-0.00245,,,,,,200.00335695,,,,
,27994118.095,200.0006866,33907.69921875,0.00262435805673735,2.17171880481484E-5,1,0.999253354069792,40.0298881530762,1.99157460265945,20.7499992102385,0.0266115638066712,0.022940004600669,0.25,0.00157123836631987,0.00263173152595497,0.00157948504514538,200.0006866,200.0006866,33900.4765625,33914.921875,56.6579064734868,20.3567220308757,26.325863,0,0,0,40,4449,199.8945,33907.69921875,,,,,,,,,,,,,0,,,,0.0049,,,,,,200.0006866,,,,
,27994216.84,199.9995422,38843.03125,0.00255101546817242,2.26906821144326E-5,1,0.999253354069792,40.0298881530762,1.99136451885208,20.7499992102385,0.0258799146668872,0.0222124933698206,0.25,0.0015198936910294,0.00255819503263486,0.00152787927905716,199.9995422,199.9995422,38843.03125,38843.03125,56.4585912010829,20.3565026901972,25.946213,0,0,0,40,4449,199.9008,38843.03125,,,,,,,,,,,,,0,,,,0,,,,,,199.9995422,,,,
,27994314.27,199.9981079,43713.044921875,0.00246996287178535,2.18315325021553E-5,1,0.999253354069792,40.0298881530762,1.99119945440104,20.7499992102385,0.0250202877492794,0.0217089616911601,0.25,0.00148962878862169,0.002476899032155,0.00149741819411516,199.9981079,199.9981079,43705.8046875,43720.28515625,57.0620084179291,20.3507611053832,25.946213,0,0,0,40,4449,199.90035,43713.044921875,,,,,,,,,,,,,0,,,,-0.00245,,,,,,199.9981079,,,,
,27994414.665,200.0003128,48730.7421875,0.00238588792998313,1.59374711879094E-5,1,0.999253354069792,40.0298881530762,1.99156131308132,20.7499992102385,0.0241382868620429,0.0211727271302191,0.25,0.00145651873010357,0.00239257301454275,0.00146409879635332,200.0002136,200.000412,48718.21484375,48743.26953125,56.729816297256,20.358925204073,26.325863,0,0,0,40,4449,199.901,48730.7421875,,,,,,,,,,,,,0,,,,0,,,,,,200.0003128,,,,
,27994511.35,200.0058441,53563.708984375,0.00228528234886958,2.11007421652151E-5,1,0.999253354069792,40.0298881530762,1.99141797718574,20.7499992102385,0.0230441740174027,0.0207088095877086,0.25,0.00143312800578893,0.0022916482840511,0.00144051507649906,200.0058441,200.0058441,53556.21875,53571.19921875,56.8775440873906,20.351329980304,26.705515,0,0,0,40,4449,199.89465,53563.708984375,,,,,,,,,,,,,0,,,,-0.00245,,,,,,200.0058441,,,,
,27994608.895,200.002182,58438.919921875,0.00220519334150469,1.79769766906364E-5,1,0.999253354069792,40.0298881530762,1.99161701662113,20.7499992102385,0.0222369759439951,0.0199951624539035,0.25,0.00138380789129114,0.00221133927111987,0.00139093491324933,200.002182,200.002182,58433.88671875,58443.953125,56.6727574153522,20.3602272114585,26.325863,0,0,0,40,4449,199.89285,58438.919921875,,,,,,,,,,,,,0,,,,0.00245,,,,,,200.002182,,,,
,27994704.145,200.0067291,63199.64453125,0.00209826339013507,2.11048720051107E-5,1,0.999253354069792,40.0298881530762,1.99158317668384,20.7499992102385,0.0210656576485161,0.0195592980299113,0.25,0.00136389690243924,0.00210406438886122,0.00137083704033615,200.0067291,200.0067291,63192.140625,63207.1484375,56.6414922745829,20.3582839267345,26.325863,0,0,0,40,4449,199.88595,63199.64453125,,,,,,,,,,,,,0,,,,0.00245,,,,,,200.0067291,,,,
,27994801.045,200.0067673,68042.09765625,0.00204918130365909,1.51508008554613E-5,1,0.999253354069792,40.0298881530762,1.9915506528796,20.7499992102385,0.0206156988113583,0.0188533950694376,0.25,0.00131007547477941,0.00205487348966591,0.00131677336391974,200.0065308,200.0070038,68034.421875,68049.7734375,56.8673829166406,20.3574184796276,26.705515,0,0,0,40,4449,199.88215,68042.09765625,,,,,,,,,,,,,0,,,,0,,,,,,200.0067673,,,,
,27994900.04,200.0075531,72992.41015625,0.00197497113852185,1.58891000779707E-5,1,0.999253354069792,40.0298881530762,1.99151298361853,20.7499992102385,0.0198734613613438,0.0181434116858902,0.25,0.00126025921010866,0.00198046314324456,0.00126670225042364,200.0075531,200.0075531,72987.484375,72997.3359375,56.4257628032752,20.3585595506956,26.705515,0,0,0,40,4449,199.8689,72992.41015625,,,,,,,,,,,,,0,,,,-0.00245,,,,,,200.0075531,,,,
,27994999.905,200.0099335,77985.37109375,0.00185112443141324,2.04871693789198E-5,1,0.999253354069792,40.0298881530762,1.99157392057085,20.7499992102385,0.018515561163983,0.0176525806268596,0.25,0.00123835246141337,0.00185621508432348,0.00124458477268049,200.0099335,200.0099335,77980.1640625,77990.578125,56.6727574153522,20.357576142046,26.325863,0,0,0,40,4449,199.8676,77985.37109375,,,,,,,,,,,,,0,,,,0,,,,,,200.0099335,,,,
,27995095.935,200.0105896,82784.0234375,0.00178100300788454,2.01368483757697E-5,1,0.999253354069792,40.0298881530762,1.9915673756692,20.7499992102385,0.0178165623779912,0.0169700355722537,0.25,0.00119022646519742,0.00178590535295509,0.00119621480695897,200.0105896,200.0105896,82784.0234375,82784.0234375,56.6063189912175,20.3578179362688,25.946213,0,0,0,40,4449,199.8605,82784.0234375,,,,,,,,,,,,,0,,,,-0.0049,,,,,,200.0105896,,,,
,27995190.21,200.01109315,87497.09375,0.00170397196082205,1.39718240060286E-5,1,0.999253354069792,40.0298881530762,1.99134672727509,20.7499992102385,0.0170233020063263,0.0163546905052401,0.25,0.00114938598410222,0.00170865415241733,0.00115514863672535,200.0106049,200.0115814,87492.1484375,87502.0390625,56.953362053756,20.3595992667288,26.325863,0,0,0,40,4449,199.85085,87497.09375,,,,,,,,,,,,,0,,,,0.00245,,,,,,200.01109315,,,,
,27995302.01,200.0045624,87958.52734375,0.00166756552104301,2.14170540297096E-5,1,0.999253354069792,40.0298881530762,1.99134659397091,20.7499992102385,0.0166069763342841,0.0163082632850389,0.25,0.00115160528603452,0.00167212013564887,0.00115733736892096,200.0045624,200.0045624,87953.484375,87963.5703125,56.6532167023714,20.3580312059189,26.325863,0,0,0,40,4449,199.8412,87958.52734375,,,,,,,,,,,,,0,,,,0,,,,,,200.0045624,,,,
,27995398.34,200.0013428,83142.21875,0.00174960623245215,1.87734357257572E-5,1,0.999253354069792,40.0298881530762,1.99132840441861,20.7499992102385,0.0174514222972764,0.0169514763095821,0.25,0.00119421010786484,0.00175439656019468,0.00120017936863126,200.0013428,200.0013428,83134.75,83149.6875,56.6391473890252,20.3595095417092,26.705515,0,0,0,40,4449,199.84955,83142.21875,,,,,,,,,,,,,0,,,,0,,,,,,200.0013428,,,,
,27995494.045,199.9953308,78355.87890625,0.00183836001632728,2.02546665083572E-5,1,0.999253354069792,40.0298881530762,1.99123958105053,20.7499992102385,0.018404492318583,0.0174155250628896,0.25,0.00121986848685723,0.00184342707221891,0.00122602390598906,199.9953308,199.9953308,78351.140625,78360.6171875,56.6500901882945,20.3588829163746,26.705515,0,0,0,40,4449,199.85295,78355.87890625,,,,,,,,,,,,,0,,,,0,,,,,,199.9953308,,,,
,27995592.945,199.9937286,73414.765625,0.001944230515438,1.90137043981673E-5,1,0.999253354069792,40.0298881530762,1.99139209883009,20.7499992102385,0.0195166114587373,0.0181271387965237,0.25,0.00126425206532121,0.00194961319031859,0.00127067672080488,199.9937286,199.9937286,73402.40625,73427.125,56.465625857756,20.360612954375,25.946213,0,0,0,40,4449,199.8604,73414.765625,,,,,,,,,,,,,0,,,,-0.00245,,,,,,199.9937286,,,,
,27995691.57,199.9914246,68482.23046875,0.0020227958336507,1.95701500411643E-5,1,0.999253354069792,40.0298881530762,1.99130677803331,20.7499992102385,0.0203204863007513,0.018766223558555,0.25,0.00130714820533693,0.00202840119202541,0.001313808445766,199.9914246,199.9914246,68474.5234375,68489.9375,56.6360208749483,20.3612734028736,26.325863,0,0,0,40,4449,199.87035,68482.23046875,,,,,,,,,,,,,0,,,,0,,,,,,199.9914246,,,,
,27995786.405,199.9884644,63744.27734375,0.00213220721924775,1.77950253506464E-5,1,0.999253354069792,40.0298881530762,1.99118710204708,20.7599997520447,0.0215003538987723,0.0193078615514897,0.25,0.001336107891645,0.00213815658787353,0.00134298851922077,199.9884644,199.9884644,63736.9296875,63751.625,56.597721077506,20.36161660303,26.705515,0,0,0,40,4449,199.87495,63744.27734375,,,,,,,,,,,,,0,,,,0,,,,,,199.9884644,,,,
,27995883.845,199.9890747,58873.462890625,0.00216215468043071,1.9310591168845E-5,1,0.999253354069792,40.0298881530762,1.99119079245085,20.7499992102385,0.0217245214792771,0.0200270998302765,0.25,0.00139446553987276,0.00216814180832985,0.0014015838645987,199.9890747,199.9890747,58863.4921875,58883.43359375,56.8142321773329,20.3616759805324,26.325863,0,0,0,40,4449,199.8878,58873.462890625,,,,,,,,,,,,,0,,,,0,,,,,,199.9890747,,,,
,27995981.695,199.98880005,53980.109375,0.00225425492944844,1.90364623130092E-5,1,0.999253354069792,40.0298881530762,1.99120277625049,20.7499992102385,0.0227090989479921,0.0205399834824731,0.25,0.00142378418290459,0.0022605252421274,0.00143110632539087,199.9886627,199.9889374,53975.19140625,53985.02734375,56.9189703989099,20.3621023121523,25.946213,0,0,0,40,4449,199.8936,53980.109375,,,,,,,,,,,,,0,,,,-0.00245,,,,,,199.98880005,,,,
,27996078.665,199.9860382,49135.380859375,0.00236032356349426,2.20061890234845E-5,1,0.999253354069792,40.0298881530762,1.99126052318198,20.7599997520447,0.023868998255702,0.0209844473578956,0.25,0.00144458859375089,0.00236693460844776,0.00145210033938478,199.9860382,199.9860382,49132.95703125,49137.8046875,56.7712426087752,20.3637302491342,26.705515,0,0,0,40,4449,199.9076,49135.380859375,,,,,,,,,,,,,0,,,,0,,,,,,199.9860382,,,,
,27996176.32,199.9893188,44254.96875,0.00243816607800527,2.32871392202923E-5,1,0.999253354069792,40.0298881530762,1.99122515402353,20.7599997520447,0.0246484064196877,0.0217182554030424,0.25,0.00149594888613371,0.00244498696008403,0.00150372579326616,199.9893188,199.9893188,44250.1171875,44259.8203125,56.7352876968906,20.360465689893,26.325863,0,0,0,40,4449,199.91335,44254.96875,,,,,,,,,,,,,0,,,,-0.00245,,,,,,199.9893188,,,,
,27996271.95,199.9906311,39474.5234375,0.00252806143905071,2.90716545546343E-5,1,0.999253354069792,40.0298881530762,1.99132238434008,20.7499992102385,0.025605687207697,0.0222474418919571,0.25,0.00152700869519238,0.0025351556224086,0.00153499373683208,199.9906311,199.9906311,39471.87890625,39477.16796875,56.8322096332752,20.3623945753439,26.325863,0,0,0,40,4449,199.9215,39474.5234375,,,,,,,,,,,,,0,,,,0,,,,,,199.9906311,,,,
,27996369.18,199.9891205,34614.71875,0.00257604290639387,1.89539769306132E-5,1,0.999253354069792,40.0298881530762,1.99111669672315,20.7499992102385,0.0261070668191478,0.0225637400537063,0.25,0.00154682011762006,0.00258327776498256,0.0015549299180221,199.9891205,199.9891205,34609.79296875,34619.64453125,56.7524835243137,20.3626941584005,26.325863,0,0,0,40,4449,199.92745,34614.71875,,,,,,,,,,,,,0,,,,-0.00245,,,,,,199.9891205,,,,
,27996467.395,199.989975,29707.3330078125,0.00262961890640528,1.97877038730808E-5,1,0.999253354069792,40.0298881530762,1.99123328171829,20.7499992102385,0.0266273579212204,0.0231731889644398,0.25,0.00159126079586035,0.00263698703980745,0.00159958636703416,199.989975,199.989975,29697.140625,29717.525390625,57.095618444256,20.3601099839929,25.946213,0,0,0,40,4449,199.9366,29707.3330078125,,,,,,,,,,,,,0,,,,-0.00245,,,,,,199.989975,,,,
,27996563.825,199.9872894,24887.177734375,0.0027103648483312,2.38453872896231E-5,1,0.999253354069792,40.0298881530762,1.99104533567319,20.7499992102385,0.0274707131069789,0.023719995304099,0.25,0.00162574659648247,0.00271797114131522,0.00163428296067844,199.9872894,199.9872894,24874.53515625,24899.8203125,56.9002113144483,20.3571902015108,26.705515,0,0,0,40,4449,199.94835,24887.177734375,,,,,,,,,,,,,0,,,,-0.00245,,,,,,199.9872894,,,,
,27996661.1,199.9878998,20024.884765625,0.00280988894753436,1.75176151594631E-5,1,0.999253354069792,40.0298881530762,1.9911511402897,20.7499992102385,0.0285453631460897,0.0242206916461321,0.25,0.00165260224507307,0.00281780600917221,0.00166134345350737,199.9878998,199.9878998,20017.056640625,20032.712890625,57.0440309619868,20.364230774998,26.705515,0,0,0,40,4449,199.95195,20024.884765625,,,,,,,,,,,,,0,,,,0,,,,,,199.9878998,,,,
,27996758.2,199.9940948,15172.7802734375,0.00282976186691518,2.18077484019851E-5,1,0.999253354069792,40.0298881530762,1.99104460551541,20.7499992102385,0.0287710744670743,0.0242448391880574,0.25,0.00165139078452333,0.00283774463900155,0.00166015348233262,199.9940948,199.9940948,15165.2373046875,15180.3232421875,56.8564401173714,20.3651985817287,26.705515,0,0,0,40,4449,199.96075,15172.7802734375,,,,,,,,,,,,,0,,,,0,,,,,,199.9940948,,,,
,27996856.055,199.990921,10280.1323242187,0.0028431386635545,3.00337322083624E-5,1,0.999253354069792,40.0298881530762,1.99123138021646,20.7499992102385,0.0288639969253626,0.0246243751549325,0.25,0.0016824138870686,0.0028511308325589,0.0016913026825844,199.990921,199.990921,10272.859375,10287.4052734375,56.9033378285253,20.3637579461134,26.705515,0,0,0,40,4449,199.96775,10280.1323242187,,,,,,,,,,,,,0,,,,0,,,,,,199.990921,,,,
,27996952.98,199.9936066,5437.38403320313,0.00292023680063436,2.01478614081551E-5,1,0.999253354069792,40.0298881530762,1.99123993369952,20.7499992102385,0.0297278291085673,0.0248256488403474,0.25,0.00168679845843574,0.00292848684302627,0.00169578991179623,199.9936066,199.9936066,5434.79345703125,5439.974609375,56.8775440873906,20.3635732942134,26.325863,0,0,0,40,4449,199.9682,5437.38403320313,,,,,,,,,,,,,0,,,,0,,,,,,199.9936066,,,,
,27997049.025,199.9914856,636.282318115234,0.00243087101425384,1.92476595186792E-5,1,0.999253354069792,40.0298881530762,1.99115290377346,20.7499992102385,0.0247511568627255,0.0206294748410373,0.25,0.00140102520876182,0.0024377400379921,0.00140850185323248,199.9909973,199.9919739,631.330200195313,641.234436035156,56.6579064734868,20.3656883346986,26.705515,0,0,0,40,4449,199.98205,636.282318115234,,,,,,,,,,,,,0,,,,-0.00245,,,,,,199.9914856,,,,
,27997143.375,199.9966888,-4077.38354492188,-0.00290072053426471,2.40529816806944E-5,1,0.999253354069792,40.0298881530762,1.99101940704559,20.7499992102385,-0.0295240481291294,-0.0246684911604086,0.25,-0.00167652923689337,-0.00290891343959543,-0.00168546466901974,199.9966888,199.9966888,-4087.41918945313,-4067.34790039063,57.088583787583,20.3635210594079,25.946213,0,0,0,40,4449,199.9833,-4077.38354492188,,,,,,,,,,,,,0,,,,-0.0049,,,,,,199.9966888,,,,
,27997239.4,200.0025635,-8876.2900390625,-0.00287739573365679,2.27796779528572E-5,1,0.999253354069792,40.0298881530762,1.99124618878892,20.7499992102385,-0.0292042521379626,-0.02496566101596,0.25,-0.00170661007734547,-0.00288547804580029,-0.00171561984111067,200.0025635,200.0025635,-8881.2412109375,-8871.3388671875,56.8666012881214,20.3635357595544,26.705515,0,0,0,40,4449,199.9819,-8876.2900390625,,,,,,,,,,,,,0,,,,-0.0049,,,,,,200.0025635,,,,
,27997335.005,200.0008545,-13654.48828125,-0.00286029406414945,2.41842903272457E-5,1,0.999253354069792,40.0298881530762,1.99121117091195,20.7499992102385,-0.0290582562655705,-0.0246555102027677,0.25,-0.0016822103661011,-0.00286834729309175,-0.00169111332190273,200.0008545,200.0008545,-13659.3564453125,-13649.6201171875,56.6266413327175,20.363571316917,26.325863,0,0,0,40,4449,199.9737,-13654.48828125,,,,,,,,,,,,,0,,,,0,,,,,,200.0008545,,,,
,27997430.61,200.0060272,-18434.513671875,-0.00285375959671936,1.9923659472248E-5,1,0.999253354069792,40.0298881530762,1.99122846604471,20.7499992102385,-0.0290495477875224,-0.0242689097495967,0.25,-0.00164916477076534,-0.00286182914048568,-0.00165794176182441,200.0060272,200.0060272,-18442.05078125,-18426.9765625,56.9986965078714,20.3649415984821,26.705515,0,0,0,40,4449,199.9704,-18434.513671875,,,,,,,,,,,,,0,,,,0.0049,,,,,,200.0060272,,,,
,27997528.705,200.0103912,-23336.8232421875,-0.00273561330265398,2.34715145394237E-5,1,0.999253354069792,40.0298881530762,1.99123715780397,20.7499992102385,-0.027758769949726,-0.0237725100635466,0.25,-0.00162581007055953,-0.00274330353406145,-0.00163437397102011,200.0103912,200.0103912,-23339.44921875,-23334.197265625,57.0487207331022,20.3662757072016,26.705515,0,0,0,40,4449,199.9602,-23336.8232421875,,,,,,,,,,,,,0,,,,0.0049,,,,,,200.0103912,,,,
,27997628.57,200.0121002,-28326.84375,-0.0026725917529587,2.13014663839404E-5,1,0.999253354069792,40.0298881530762,1.99101047947717,20.7499992102385,-0.0270608334010611,-0.0235421083530801,0.25,-0.00161662399333646,-0.00268007804196588,-0.00162508341526899,200.0121002,200.0121002,-28331.859375,-28321.828125,56.8673829166406,20.3639823382299,26.325863,0,0,0,40,4449,199.948,-28326.84375,,,,,,,,,,,,,0,,,,-0.0049,,,,,,200.0121002,,,,
,27997726.095,200.0119629,-33201.439453125,-0.00261433043129836,2.29173086462509E-5,1,0.999253354069792,40.0298881530762,1.99111286424817,20.7499992102385,-0.0264825753902193,-0.0229706586760707,0.25,-0.00157613877864444,-0.00262166300871827,-0.00158439103728047,200.0119629,200.0119629,-33203.8203125,-33199.05859375,56.7532651528329,20.3663794908931,25.946213,0,0,0,40,4449,199.9376,-33201.439453125,,,,,,,,,,,,,0,,,,0.0049,,,,,,200.0119629,,,,
,27997828.075,200.0085754,-38298.455078125,-0.00252660911532801,2.58240825728337E-5,1,0.999253354069792,40.0298881530762,1.9913352829209,20.7499992102385,-0.0255599103825897,-0.02241442976037,0.25,-0.0015420062248187,-0.00253367985513273,-0.00155004160766216,200.0085754,200.0085754,-38305.6640625,-38291.24609375,56.8376810329099,20.3624580541457,26.325863,0,0,0,40,4449,199.93155,-38298.455078125,,,,,,,,,,,,,0,,,,-0.0049,,,,,,200.0085754,,,,
,27997927.47,200.0132294,-43265.578125,-0.00245398667638753,1.38367437134049E-5,1,0.999253354069792,40.0298881530762,1.99112885827598,20.7499992102385,-0.0248625620722111,-0.0215392082322884,0.25,-0.00147746615607339,-0.00246087928015468,-0.00148519591470984,200.0132294,200.0132294,-43273.3984375,-43257.7578125,57.1143775287176,20.3641101890116,26.325863,0,0,0,40,4449,199.9162,-43265.578125,,,,,,,,,,,,,0,,,,0,,,,,,200.0132294,,,,
,27998026.945,200.01100155,-48235.78515625,-0.00235008540463383,2.06314322627839E-5,1,0.999253354069792,40.0298881530762,1.99118519246862,20.7499992102385,-0.0236909712742193,-0.0213164751991126,0.25,-0.00147577875111587,-0.00235662512242051,-0.00148338691224819,200.0107269,200.0112762,-48240.70703125,-48230.86328125,57.1526773261599,20.3631444431637,26.705515,0,0,0,40,4449,199.9104,-48235.78515625,,,,,,,,,,,,,0,,,,0.0049,,,,,,200.01100155,,,,
,27998126.99,200.0114899,-53237.728515625,-0.00229360809579691,1.96552367279216E-5,1,0.999253354069792,40.0298881530762,1.9914032156071,20.7499992102385,-0.0231746177394122,-0.0205154394154487,0.25,-0.0014146071081346,-0.00230002190720845,-0.00142193905650206,200.0114899,200.0114899,-53242.65234375,-53232.8046875,56.8462789466214,20.3654075732771,26.325863,0,0,0,40,4449,199.89965,-53237.728515625,,,,,,,,,,,,,0,,,,-0.00245,,,,,,200.0114899,,,,
,27998226.37,200.0139923,-58205.19921875,-0.00217563332257504,2.17813936914107E-5,1,0.999253354069792,40.0298881530762,1.99116304211198,20.7499992102385,-0.0218927219078634,-0.0199611441717669,0.25,-0.00138632007518434,-0.00218167337221856,-0.00139342405332887,200.0139923,200.0139923,-58215.35546875,-58195.04296875,57.0018230219483,20.3641676842954,25.946213,0,0,0,40,4449,199.8882,-58205.19921875,,,,,,,,,,,,,0,,,,0,,,,,,200.0139923,,,,
,27998323.885,200.0096741,-63080.45703125,-0.00208878131092125,2.20520430504257E-5,1,0.999253354069792,40.0298881530762,1.99125207098688,20.7499992102385,-0.0209533442227032,-0.0195471912175292,0.25,-0.00136474806000799,-0.0020945482717377,-0.00137168113078768,200.0096741,200.0096741,-63082.89453125,-63078.01953125,56.9658681100637,20.3651449977599,26.325863,0,0,0,40,4449,199.8787,-63080.45703125,,,,,,,,,,,,,0,,,,-0.0049,,,,,,200.0096741,,,,
,27998422.93,200.0151367,-68030.12109375,-0.00201820637363659,1.9925367303729E-5,1,0.999253354069792,40.0298881530762,1.99121592024253,20.7499992102385,-0.0202458860676142,-0.0188816969357545,0.25,-0.00131822363686282,-0.00202378216538569,-0.00132491669326224,200.0151367,200.0151367,-68039.953125,-68020.2890625,56.997133250833,20.3644224954077,26.705515,0,0,0,40,4449,199.866,-68030.12109375,,,,,,,,,,,,,0,,,,-0.00245,,,,,,200.0151367,,,,
,27998519.195,200.0143433,-72839.37109375,-0.00192834917287108,1.83894023158604E-5,1,0.999253354069792,40.0298881530762,1.9912641600728,20.7499992102385,-0.0193190174658774,-0.0181908216244233,0.25,-0.00127273690701379,-0.00193366616691086,-0.00127917379940992,200.0143433,200.0143433,-72846.921875,-72831.8203125,56.9306948266983,20.3670282121818,25.946213,0,0,0,40,4449,199.85195,-72839.37109375,,,,,,,,,,,,,0,,,,0.00245,,,,,,200.0143433,,,,
,27998618.24,200.0110321,-77788.72265625,-0.00181967876877261,2.37235595679165E-5,1,0.999253354069792,40.0298881530762,1.9911358044234,20.7499992102385,-0.0181687358896733,-0.0175129939943563,0.25,-0.00123180398388739,-0.00182466725630321,-0.00123798081897039,200.0110321,200.0110321,-77793.7734375,-77783.671875,57.2581971762561,20.3656935252577,26.325863,0,0,0,40,4449,199.8469,-77788.72265625,,,,,,,,,,,,,0,,,,0.00245,,,,,,200.0110321,,,,
,27998717.785,200.0147552,-82763.55078125,-0.00173671236945637,1.94211258201389E-5,1,0.999253354069792,40.0298881530762,1.99126135823516,20.7599997520447,-0.0172902111058034,-0.0170104625226847,0.25,-0.00120171063131921,-0.00174144910019264,-0.00120769210393041,200.0147552,200.0147552,-82765.9921875,-82761.109375,56.9979148793522,20.3635091236911,26.325863,0,0,0,40,4449,199.83885,-82763.55078125,,,,,,,,,,,,,0,,,,-0.0049,,,,,,200.0147552,,,,
,27998814.36,200.0105438,-87590.65625,-0.00165280629513774,1.72218734457236E-5,1,0.999253354069792,40.0298881530762,1.991201109624,20.7599997520447,-0.0164220572287491,-0.016374582888449,0.25,-0.00116012992419742,-0.00165730019891983,-0.00116587618188328,200.0105438,200.0105438,-87603.078125,-87578.234375,57.0323065341983,20.3669608013454,26.705515,0,0,0,40,4449,199.8228,-87590.65625,,,,,,,,,,,,,0,,,,0.00245,,,,,,200.0105438,,,,
,27998928.335,200.0095978,-87701.0859375,-0.00164886358714574,2.03279275924729E-5,1,0.999253354069792,40.0298881530762,1.99125094753063,20.7499992102385,-0.0164096557229015,-0.0161839996314342,0.25,-0.00114393707348095,-0.00165336094292131,-0.00114962323924731,200.0095978,200.0095978,-87708.609375,-87693.5625,56.8634747740445,20.3668418826354,26.705515,0,0,0,40,4449,199.8161,-87701.0859375,,,,,,,,,,,,,0,,,,0,,,,,,200.0095978,,,,
,27999023.22,200.002243,-82958.9375,-0.00172554205097386,1.68920788904825E-5,1,0.999253354069792,40.0298881530762,1.99106828305544,20.7499992102385,-0.0172097136158479,-0.0167135254287208,0.25,-0.00117754463706899,-0.00173026626596699,-0.00118343139806473,200.002243,200.002243,-82966.4296875,-82951.4453125,57.1987934087945,20.3673789986922,26.325863,0,0,0,40,4449,199.8163,-82958.9375,,,,,,,,,,,,,0,,,,-0.00245,,,,,,200.002243,,,,
,27999120.685,199.99617765,-78086.43359375,-0.00185674888182051,2.29434859716509E-5,1,0.999253354069792,40.0298881530762,1.99105858404657,20.7499992102385,-0.0185831781492075,-0.0176100389306341,0.25,-0.00123400010575956,-0.00186186401494443,-0.00124022431309156,199.9959869,199.9963684,-78094.015625,-78078.8515625,56.8666012881214,20.3666666149632,26.705515,0,0,0,40,4449,199.81895,-78086.43359375,,,,,,,,,,,,,0,,,,-0.0049,,,,,,199.99617765,,,,
,27999221.18,199.9919586,-73066.73046875,-0.00195868316020723,1.76530048123148E-5,1,0.999253354069792,40.0298881530762,1.99120128471151,20.7499992102385,-0.0196791300750869,-0.018149405141836,0.25,-0.00126385595021683,-0.00196411573660394,-0.00127029525673705,199.9919586,199.9919586,-73076.9140625,-73056.546875,57.0026046504676,20.3652593668521,26.325863,0,0,0,40,4449,199.8278,-73066.73046875,,,,,,,,,,,,,0,,,,0.00245,,,,,,199.9919586,,,,
,27999319.515,199.9882507,-68152.5390625,-0.00201612030828423,2.27870690842932E-5,1,0.999253354069792,40.0298881530762,1.99117037921339,20.7499992102385,-0.0202541445147739,-0.0186912779052414,0.25,-0.00130179159822107,-0.00202170790287826,-0.0013084270600355,199.9882507,199.9882507,-68159.8984375,-68145.1796875,56.8837971155445,20.3633465591051,26.705515,0,0,0,40,4449,199.83785,-68152.5390625,,,,,,,,,,,,,0,,,,-0.0049,,,,,,199.9882507,,,,
,27999415.865,199.9929123,-63337.669921875,-0.00209987032880961,1.58848579828183E-5,1,0.999253354069792,40.0298881530762,1.99126871776904,20.7499992102385,-0.0211342557043604,-0.0192509693878687,0.25,-0.0013366287723937,-0.00210570651201413,-0.00134347734900429,199.9928436,199.992981,-63342.51171875,-63332.828125,56.9017745714868,20.3657355375972,26.705515,0,0,0,40,4449,199.84945,-63337.669921875,,,,,,,,,,,,,0,,,,-0.00245,,,,,,199.9929123,,,,
,27999514.595,199.9875641,-58402.966796875,-0.00217352346283588,2.52659218315025E-5,1,0.999253354069792,40.0298881530762,1.99112747697688,20.7499992102385,-0.0218873252742154,-0.0198482377124242,0.25,-0.00137673603877763,-0.00217956812308094,-0.00138380610734797,199.9875641,199.9875641,-58415.71875,-58390.21484375,56.9049010855637,20.3633327713091,26.325863,0,0,0,40,4449,199.8559,-58402.966796875,,,,,,,,,,,,,0,,,,-0.00245,,,,,,199.9875641,,,,
,27999614.24,199.9896698,-53422.5,-0.00227833939232572,2.30426496638262E-5,1,0.999253354069792,40.0298881530762,1.99122994206234,20.7499992102385,-0.0229456547561414,-0.0207963062660939,0.25,-0.00144223000525262,-0.0022846723614938,-0.00144964246854742,199.9896698,199.9896698,-53427.27734375,-53417.72265625,57.0018230219483,20.3643660332033,27.085165,0,0,0,40,4449,199.86155,-53422.5,,,,,,,,,,,,,0,,,,-0.0049,,,,,,199.9896698,,,,
,27999715.9,199.9892883,-48340.71484375,-0.00234200322230977,2.01559248086844E-5,1,0.999253354069792,40.0298881530762,1.99115047456679,20.7499992102385,-0.0236093493715714,-0.021241477751044,0.25,-0.00147058374132497,-0.00234852187236188,-0.00147816683879831,199.9892883,199.9892883,-48345.64453125,-48335.78515625,57.0268351345637,20.361340016424,26.325863,0,0,0,40,4449,199.87065,-48340.71484375,,,,,,,,,,,,,0,,,,0,,,,,,199.9892883,,,,
,27999812.36,199.9889832,-43520.88671875,-0.00241934526527978,2.19335171254647E-5,1,0.999253354069792,40.0298881530762,1.99120669597776,20.7499992102385,-0.0243864177627294,-0.021962068121664,0.25,-0.00152078124778746,-0.00242607359486776,-0.00152862496577457,199.9889832,199.9889832,-43528.390625,-43513.3828125,57.0127658212176,20.3622287567756,27.085165,0,0,0,40,4449,199.88235,-43520.88671875,,,,,,,,,,,,,0,,,,0.0049,,,,,,199.9889832,,,,
,27999909.47,199.9895477,-38668.482421875,-0.00252434876296171,1.42070866372251E-5,1,0.999253354069792,40.0298881530762,1.99129622833459,20.7499992102385,-0.0256016743316358,-0.022019168628035,0.25,-0.00150750350993081,-0.00253145007746376,-0.00151541854770654,199.9895477,199.9895477,-38676.0625,-38660.90234375,56.9775925378522,20.3631861115744,26.705515,0,0,0,40,4449,199.8895,-38668.482421875,,,,,,,,,,,,,0,,,,0.0049,,,,,,199.9895477,,,,
,28000004.32,199.9896545,-33926.904296875,-0.00254632809034515,2.28621168972504E-5,1,0.999253354069792,40.0298881530762,1.99122622835676,20.7499992102385,-0.0257521524928234,-0.0226219547290987,0.25,-0.0015570201489299,-0.00255344837041891,-0.00156513436588653,199.9896545,199.9896545,-33939.44140625,-33914.3671875,56.9471090256022,20.3642062921118,26.325863,0,0,0,40,4449,199.89715,-33926.904296875,,,,,,,,,,,,,0,,,,-0.0049,,,,,,199.9896545,,,,
,28000101.975,199.9927979,-29046.751953125,-0.00264942591286008,2.72754539992947E-5,1,0.999253354069792,40.0298881530762,1.99106711494397,20.7499992102385,-0.0268388694758051,-0.0232704600849868,0.25,-0.00159658031192016,-0.00265685554247604,-0.00160494655504011,199.9927979,199.9927979,-29051.203125,-29042.30078125,56.9181887703906,20.3643214496951,26.325863,0,0,0,40,4449,199.90715,-29046.751953125,,,,,,,,,,,,,0,,,,0.00245,,,,,,199.9927979,,,,
,28000198.905,199.9887238,-24201.8515625,-0.00271452295120837,2.0254019568898E-5,1,0.999253354069792,40.0298881530762,1.99091409264749,20.7499992102385,-0.0275275818195262,-0.0236600657417962,0.25,-0.00161985818021671,-0.00272214880592564,-0.00162837986482314,199.9887238,199.9887238,-24209.431640625,-24194.271484375,57.0229269919676,20.3632920398396,26.705515,0,0,0,40,4449,199.91395,-24201.8515625,,,,,,,,,,,,,0,,,,-0.00245,,,,,,199.9887238,,,,
,28000288.68,199.9881134,-19716.736328125,-0.00278238047977691,2.4410089702349E-5,1,0.999253354069792,40.0298881530762,1.99112553617234,20.7499992102385,-0.0282548070602763,-0.0240451443302277,0.25,-0.00164189044418514,-0.00279021340144149,-0.001650565819184,199.9881134,199.9881134,-19721.826171875,-19711.646484375,57.0502839901407,20.3626893959058,26.705515,0,0,0,40,4449,199.9182,-19716.736328125,,,,,,,,,,,,,0,,,,-0.00245,,,,,,199.9881134,,,,
,28000376.125,199.9867096,-15344.4267578125,-0.00280200038514837,2.30102638996932E-5,1,0.999253354069792,40.0298881530762,1.99116658196945,20.7499992102385,-0.0284146321566028,-0.0244451130825259,0.25,-0.00167378662605877,-0.00280986346615787,-0.00168259738918877,199.9867096,199.9867096,-15349.611328125,-15339.2421875,57.1675282680253,20.3621156490047,26.325863,0,0,0,40,4449,199.92995,-15344.4267578125,,,,,,,,,,,,,0,,,,0,,,,,,199.9867096,,,,
,28000466.49,199.9888153,-10829.12109375,-0.00284297243082118,2.73189674583531E-5,1,0.999253354069792,40.0298881530762,1.99112872003729,20.7499992102385,-0.0288406406959453,-0.0247383112671795,0.25,-0.00169261958864494,-0.00285095315486498,-0.00170154356785772,199.988266,199.9893646,-10841.7060546875,-10816.5361328125,56.8626931455252,20.3632024074627,26.705515,0,0,0,40,4449,199.93945,-10829.12109375,,,,,,,,,,,,,0,,,,0,,,,,,199.9888153,,,,
,28000560.53,199.993042,-6127.9248046875,-0.00292361163728434,1.73554162525016E-5,1,0.999253354069792,40.0298881530762,1.99104932467877,20.7599997520447,-0.0297440835014241,-0.024940630858847,0.25,-0.00169657555920886,-0.00293186285160209,-0.00170560435961669,199.993042,199.993042,-6137.98388671875,-6117.86572265625,56.926005055583,20.36265629842,26.705515,0,0,0,40,4449,199.9428,-6127.9248046875,,,,,,,,,,,,,0,,,,0,,,,,,199.993042,,,,
,28000653.87,199.9928589,-1459.35961914062,-0.00275735949048003,2.28029300676698E-5,1,0.999253354069792,40.0298881530762,1.99114487849542,20.7499992102385,-0.0281056284411329,-0.0232258219605752,0.25,-0.00157379168409456,-0.00276516756647562,-0.00158221943124213,199.9928589,199.9928589,-1469.18591308594,-1449.53332519531,57.0377779338329,20.3612314693377,26.325863,0,0,0,40,4449,199.9466,-1459.35961914062,,,,,,,,,,,,,0,,,,0.00245,,,,,,199.9928589,,,,
,28000746.295,199.9962158,3153.33581542969,0.00285503787730398,2.07431495730298E-5,1,0.999253354069792,40.0298881530762,1.99087775580621,20.7499992102385,0.029067683999499,0.0242173874809478,0.25,0.00164473672824141,0.0028631066002742,0.00165351418679105,199.9962158,199.9962158,3143.40112304687,3163.2705078125,57.1987934087945,20.3613125417076,26.705515,0,0,0,40,4449,199.9461,3153.33581542969,,,,,,,,,,,,,0,,,,-0.00245,,,,,,199.9962158,,,,
,28000838.85,199.9991302,7780.6611328125,0.00287161925682259,2.75406074715969E-5,1,0.999253354069792,40.0298881530762,1.9909774727134,20.7599997520447,0.0291624304894435,0.0247938857267683,0.25,0.00169271327576836,0.00287969579572857,0.00170167051722343,199.9991302,199.9991302,7773.103515625,7788.21875,56.9134989992753,20.3619161432683,26.325863,0,0,0,40,4449,199.9491,7780.6611328125,,,,,,,,,,,,,0,,,,0.0049,,,,,,199.9991302,,,,
,28000934.25,200.00213625,12548.5102539062,0.0028607369487991,2.44332054456123E-5,1,0.999253354069792,40.0298881530762,1.99104078006583,20.7499992102385,0.0290830558600848,0.0245266749906699,0.25,0.0016709231325421,0.00286880258997931,0.00167978904586846,200.0017853,200.0024872,12541.3056640625,12555.71484375,57.0385595623522,20.3607515199919,27.085165,0,0,0,40,4449,199.946,12548.5102539062,,,,,,,,,,,,,0,,,,0,,,,,,200.00213625,,,,
,28001028.75,200.0042419,17273.779296875,0.00281603956032815,1.70072864372352E-5,1,0.999253354069792,40.0298881530762,1.99093721584668,20.7499992102385,0.02862102867847,0.024178170779337,0.25,0.0016479938738154,0.00282397901809404,0.00165672778364316,200.0042419,200.0042419,17268.849609375,17278.708984375,56.9525804252368,20.3615355843416,26.705515,0,0,0,40,4449,199.94145,17273.779296875,,,,,,,,,,,,,0,,,,-0.0049,,,,,,200.0042419,,,,
,28001123.405,200.003418,22003.7900390625,0.00277328347018238,2.03522420212185E-5,1,0.999253354069792,40.0298881530762,1.99105002431709,20.7499992102385,0.0282104572327645,0.0236833072307735,0.25,0.00161156984701716,0.00278111846909126,0.00162012720821405,200.003418,200.003418,21996.4375,22011.142578125,57.0088576786214,20.3640118492188,26.325863,0,0,0,40,4449,199.94355,22003.7900390625,,,,,,,,,,,,,0,,,,0,,,,,,200.003418,,,,
,28001217.705,200.0078735,26717.474609375,0.00267176178517838,2.85055404677271E-5,1,0.999253354069792,40.0298881530762,1.99074247541842,20.7499992102385,0.0270820274315912,0.023341262788978,0.25,0.00159927938533185,0.00267926271893005,0.00160768014113426,200.0077972,200.0079498,26715.10546875,26719.84375,56.7438856106022,20.3579506356124,26.325863,0,0,0,40,4449,199.9302,26717.474609375,,,,,,,,,,,,,0,,,,0,,,,,,200.0078735,,,,
,28001315.225,200.010498,31592.505859375,0.00264222406640238,1.89518185372228E-5,1,0.999253354069792,40.0298881530762,1.99093620243987,20.7499992102385,0.0268154895430682,0.0229106801236303,0.25,0.00156616297543516,0.00264966224125768,0.00157441278167538,200.010498,200.010498,31582.48828125,31602.5234375,56.7259081546598,20.3603132322975,26.325863,0,0,0,40,4449,199.9185,31592.505859375,,,,,,,,,,,,,0,,,,0,,,,,,200.010498,,,,
,28001410.71,200.0128021,36365.107421875,0.00253027161082275,2.92355941912026E-5,1,0.999253354069792,40.0298881530762,1.99078809129499,20.7499992102385,0.0255835240217255,0.0224795831394688,0.25,0.00154764760448942,0.00253734671229034,0.00155570843869787,200.0128021,200.0128021,36360.11328125,36370.1015625,56.7798405224868,20.3590132813778,27.085165,0,0,0,40,4449,199.9089,36365.107421875,,,,,,,,,,,,,0,,,,-0.00245,,,,,,200.0128021,,,,
,28001506.28,200.0150452,41139.966796875,0.00247346148938712,2.102187313977E-5,1,0.999253354069792,40.0298881530762,1.990764854266,20.7499992102385,0.0249998055459897,0.0220268771546781,0.25,0.00151752269386472,0.00248037637417957,0.00152541386309277,200.0150452,200.0150452,41132.33203125,41147.6015625,56.8447156895829,20.3632559055685,26.705515,0,0,0,40,4449,199.9013,41139.966796875,,,,,,,,,,,,,0,,,,0,,,,,,200.0150452,,,,
,28001598.925,200.011322,45770.548828125,0.00237491980049845,1.68311182052236E-5,1,0.999253354069792,40.0298881530762,1.9911950315041,20.7499992102385,0.023930115510593,0.0216068743015958,0.25,0.00149711958393176,0.00238152019810699,0.00150483062083725,200.011322,200.011322,45765.265625,45775.83203125,56.6344576179098,20.3607525971476,27.085165,0,0,0,40,4449,199.8909,45770.548828125,,,,,,,,,,,,,0,,,,0.00245,,,,,,200.011322,,,,
,28001696.14,200.0111542,50630.498046875,0.00228304949834316,2.40438245088625E-5,1,0.999253354069792,40.0298881530762,1.99106616155397,20.7499992102385,0.0229852305906219,0.0208722829070764,0.25,0.00144827074669822,0.00228938864199893,0.00145571043595898,200.0111542,200.0111542,50622.8515625,50638.14453125,56.9267866841022,20.3602645781257,26.705515,0,0,0,40,4449,199.88065,50630.498046875,,,,,,,,,,,,,0,,,,-0.00245,,,,,,200.0111542,,,,
,28001793.415,200.0149994,55493.361328125,0.00218817886452429,1.8024183286807E-5,1,0.999253354069792,40.0298881530762,1.99104259850141,20.7499992102385,0.0219965310361593,0.0201967705775531,0.25,0.00140506671592917,0.00219423983334359,0.00141225151273478,200.0149994,200.0149994,55485.73046875,55500.9921875,56.9627415959868,20.3585458179822,26.705515,0,0,0,40,4449,199.8662,55493.361328125,,,,,,,,,,,,,0,,,,-0.00245,,,,,,200.0149994,,,,
,28001887.47,200.00928495,60193.572265625,0.00216289278438962,1.98272798188384E-5,1,0.999253354069792,40.0298881530762,1.99108872111883,20.7499992102385,0.0218013712275701,0.0196269779969854,0.25,0.00135906198285445,0.00216891939867143,0.00136605701112951,200.0091705,200.0093994,60163.64453125,60223.5,57.0268351345637,20.3579417221634,26.705515,0,0,0,40,4449,199.8599,60193.572265625,,,,,,,,,,,,,0,,,,0.00245,,,,,,200.00928495,,,,
,28001981.26,200.0124512,64879.126953125,0.00205494824619164,2.08776919129596E-5,1,0.999253354069792,40.0298881530762,1.99124024239591,20.7499992102385,0.0206425955144883,0.0190649192623718,0.25,0.00132801329196235,0.00206063821919249,0.00133478216801319,200.0124512,200.0124512,64866.54296875,64891.7109375,56.8017261210252,20.3572678786994,26.705515,0,0,0,40,4449,199.85095,64879.126953125,,,,,,,,,,,,,0,,,,-0.0049,,,,,,200.0124512,,,,
,28002075.735,200.0123901,69604.5859375,0.00196768632539353,1.72714489075545E-5,1,0.999253354069792,40.0298881530762,1.99107983656031,20.7499992102385,0.0197340683458818,0.0184294073996395,0.25,0.00128713204745025,0.00197312162643382,0.00129366321719209,200.0123901,200.0123901,69599.734375,69609.4375,56.8908317722176,20.3593135655993,26.705515,0,0,0,40,4449,199.8418,69604.5859375,,,,,,,,,,,,,0,,,,0,,,,,,200.0123901,,,,
,28002169.985,200.0127869,74312.375,0.00187896286686157,2.01907164349457E-5,1,0.999253354069792,40.0298881530762,1.99111867353194,20.7499992102385,0.0187886332788868,0.01792126901935,0.25,0.00125760287881121,0.00188412617868453,0.00126393436335222,200.0127869,200.0127869,74302.265625,74322.484375,56.9752476522945,20.3568132981268,26.705515,0,0,0,40,4449,199.82995,74312.375,,,,,,,,,,,,,0,,,,-0.00245,,,,,,200.0127869,,,,
,28002265.45,200.0101471,79085.74609375,0.00178827527411262,2.27073540983283E-5,1,0.999253354069792,40.0298881530762,1.9911226162866,20.7499992102385,0.0178411305989994,0.0172909810145368,0.25,0.00121764611659803,0.00179317091829628,0.00122374017501318,200.0101471,200.0101471,79080.7734375,79090.71875,56.8658196596022,20.3595940182733,26.705515,0,0,0,40,4449,199.822,79085.74609375,,,,,,,,,,,,,0,,,,-0.00245,,,,,,200.0101471,,,,
,28002362.51,200.01223755,83939.0078125,0.00171967025001567,1.78589712639242E-5,1,0.999253354069792,40.0298881530762,1.99111702298371,20.7499992102385,0.0171574766024745,0.0166229286635259,0.25,0.00117052380301916,0.00172438163050577,0.00117637902981752,200.0121613,200.0123138,83934.03125,83943.984375,56.912717370756,20.3562711184555,27.085165,0,0,0,40,4449,199.8122,83939.0078125,,,,,,,,,,,,,0,,,,-0.0049,,,,,,200.01223755,,,,
,28002451.58,200.0127106,88390.07421875,0.00163248523821777,1.81367777893118E-5,1,0.999253354069792,40.0298881530762,1.99109527555049,20.7499992102385,0.016212350035569,0.0162126320034746,0.25,0.00114941908186978,0.00163692041457927,0.00115510649008012,200.0127106,200.0127106,88387.4453125,88392.703125,56.7954730928714,20.3575625585232,26.705515,0,0,0,40,4449,199.80385,88390.07421875,,,,,,,,,,,,,0,,,,-0.00245,,,,,,200.0127106,,,,
,28002561.29,200.0100403,87150.8984375,0.00166293827166923,1.75146375549656E-5,1,0.999253354069792,40.0298881530762,1.99113033091818,20.7499992102385,0.0165518485584766,0.0163034463697626,0.25,0.00115213201586973,0.00166747514333131,0.00115786181315787,200.0100403,200.0100403,87143.359375,87158.4375,56.8658196596022,20.3573327875596,26.705515,0,0,0,40,4449,199.8019,87150.8984375,,,,,,,,,,,,,0,,,,-0.0049,,,,,,200.0100403,,,,
,28002655.275,200.0016174,82449.90625,0.00174714263057236,1.85485226134038E-5,1,0.999253354069792,40.0298881530762,1.99108316984459,20.7499992102385,0.0174337215976263,0.0168741775419483,0.25,0.00118798135774192,0.00175193003335064,0.00119392752692865,200.0016174,200.0016174,82439.8359375,82459.9765625,57.0659165605253,20.3585663038078,26.325863,0,0,0,40,4449,199.79845,82449.90625,,,,,,,,,,,,,0,,,,0,,,,,,200.0016174,,,,
,28002747.72,199.9968109,77828.6796875,0.00182856113992338,1.6079279868911E-5,1,0.999253354069792,40.0298881530762,1.99081755940268,20.7499992102385,0.0182757455671351,0.0174742702022267,0.25,0.00122707365514736,0.00183358576584709,0.00123324454781285,199.9968109,199.9968109,77826.0859375,77831.2734375,56.7462304961599,20.3588925196674,26.325863,0,0,0,40,4449,199.801,77828.6796875,,,,,,,,,,,,,0,,,,0,,,,,,199.9968109,,,,
,28002838.7,199.9933472,73282.38671875,0.00187267393039488,2.10116825783766E-5,1,0.999253354069792,40.0298881530762,1.99108163717565,20.7499992102385,0.0187070575280873,0.0179666916029318,0.25,0.00126273582660369,0.00187781032818038,0.00126908027684347,199.9933472,199.9933472,73277.5078125,73287.265625,56.7454488676406,20.3587235395273,26.705515,0,0,0,40,4449,199.8087,73282.38671875,,,,,,,,,,,,,0,,,,-0.0049,,,,,,199.9933472,,,,
,28002934.27,199.9896088,68504.1015625,0.0019765710379982,2.00983476496309E-5,1,0.999253354069792,40.0298881530762,1.9911232429137,20.7499992102385,0.0198155531413192,0.0185592917694815,0.25,0.00129703226223357,0.00198202695399673,0.00130360925766132,199.9896088,199.9896088,68494.171875,68514.03125,56.7431039820829,20.3577395935001,26.325863,0,0,0,40,4449,199.816,68504.1015625,,,,,,,,,,,,,0,,,,-0.00245,,,,,,199.9896088,,,,
,28003030.26,199.987793,63705.8359375,0.00208121290978605,1.92272059291494E-5,1,0.999253354069792,40.0298881530762,1.99097116287608,20.7499992102385,0.0208672421601238,0.0195162670026265,0.25,0.00136356052249709,0.00208695642451746,0.0013704825191619,199.987793,199.987793,63696.01953125,63715.65234375,56.8798889729483,20.3591787571343,27.085165,0,0,0,40,4449,199.82735,63705.8359375,,,,,,,,,,,,,0,,,,-0.00245,,,,,,199.987793,,,,
,28003125.6,199.9896851,58940.439453125,0.00217433658503728,2.37200493595279E-5,1,0.999253354069792,40.0298881530762,1.99089192498792,20.7499992102385,0.0218785415590037,0.0199369047151515,0.25,0.00138463064422907,0.00218037565516916,0.00139172857792295,199.9896851,199.9896851,58933.23828125,58947.640625,56.8204852054868,20.3589601145569,26.705515,0,0,0,40,4449,199.83175,58940.439453125,,,,,,,,,,,,,0,,,,-0.0049,,,,,,199.9896851,,,,
,28003220.73,199.9885406,54185.2578125,0.00224329216829021,2.02563845166732E-5,1,0.999253354069792,40.0298881530762,1.99091219125226,20.7499992102385,0.0225786047672232,0.020534576776569,0.25,0.00142546276627168,0.00224952244359117,0.00143277948951018,199.9885406,199.9885406,54180.1953125,54190.3203125,57.095618444256,20.3579679238381,27.085165,0,0,0,40,4449,199.845,54185.2578125,,,,,,,,,,,,,0,,,,-0.0049,,,,,,199.9885406,,,,
,28003315.765,199.9887314,49435.158203125,0.00232277546724363,2.19257254879158E-5,1,0.999253354069792,40.0298881530762,1.99103534719811,20.7499992102385,0.0234406030664619,0.0209140919959444,0.25,0.00144509141073953,0.00232925572876133,0.00145256504057263,199.9882202,199.9892426,49427.50390625,49442.8125,56.8783257159099,20.3597978056493,26.325863,0,0,0,40,4449,199.8594,49435.158203125,,,,,,,,,,,,,0,,,,0,,,,,,199.9887314,,,,
,28003414.28,199.9898834,44509.45703125,0.0023844756356327,2.65070870734644E-5,1,0.999253354069792,40.0298881530762,1.99092028797967,20.7499992102385,0.0240306235739507,0.0216484434592314,0.25,0.00149938318051503,0.00239110694879299,0.00150711491449998,199.9898834,199.9898834,44499.34375,44519.5703125,57.0604451608906,20.3568898132082,26.705515,0,0,0,40,4449,199.8643,44509.45703125,,,,,,,,,,,,,0,,,,0,,,,,,199.9898834,,,,
,28003509.515,199.9884186,39749.12109375,0.00248380826636898,1.90315276265362E-5,1,0.999253354069792,40.0298881530762,1.9909578488992,20.7499992102385,0.0251204932591995,0.0220417316917112,0.25,0.00151685523588916,0.00249076031667338,0.00152475829571158,199.9884186,199.9884186,39741.58984375,39756.65234375,56.8150138058522,20.3588562212211,26.705515,0,0,0,40,4449,199.8748,39749.12109375,,,,,,,,,,,,,0,,,,0,,,,,,199.9884186,,,,
,28003605.765,199.9878998,34942.0234375,0.00250447805488168,2.58125837806266E-5,1,0.999253354069792,40.0298881530762,1.99104029719674,20.7499992102385,0.025338306129967,0.0221810902919362,0.25,0.00152550164762719,0.0025114885127614,0.00153346129326673,199.9878998,199.9878998,34939.7890625,34944.2578125,57.0729512171983,20.3610000058341,27.085165,0,0,0,40,4449,199.88695,34942.0234375,,,,,,,,,,,,,0,,,,-0.00245,,,,,,199.9878998,,,,
,28003696.79,199.98617555,30391.5263671875,0.00263032119540151,1.666722832781E-5,1,0.999253354069792,40.0298881530762,1.99109396871974,20.7499992102385,0.0266954052099555,0.0228167559156258,0.25,0.00155977274478943,0.00263772593324714,0.00156799058483334,199.9859619,199.9863892,30386.576171875,30396.4765625,56.7391958394868,20.3620953271632,26.705515,0,0,0,40,4449,199.8908,30391.5263671875,,,,,,,,,,,,,0,,,,-0.00245,,,,,,199.98617555,,,,
,28003789.995,199.9899139,25731.3310546875,0.00266620756756119,2.35425290594605E-5,1,0.999253354069792,40.0298881530762,1.99112497485842,20.7499992102385,0.0270033866094557,0.0234542162333592,0.25,0.00160984614226042,0.00267367832099828,0.00161827981296581,199.9899139,199.9899139,25724.05859375,25738.603515625,56.8705094307176,20.3595304139803,27.085165,0,0,0,40,4449,199.89995,25731.3310546875,,,,,,,,,,,,,0,,,,0,,,,,,199.9899139,,,,
,28003881.71,199.9907227,21149.0546875,0.00272527768079656,2.12029117691782E-5,1,0.999253354069792,40.0298881530762,1.99095534568718,20.7499992102385,0.0276067511600437,0.0239293508363419,0.25,0.00164174816653405,0.00273291432486731,0.00165036003414711,199.9907227,199.9907227,21146.69140625,21151.41796875,56.8767624588714,20.3593129084912,26.705515,0,0,0,40,4449,199.9065,21149.0546875,,,,,,,,,,,,,0,,,,0.0049,,,,,,199.9907227,,,,
,28003973.785,199.9928589,16546.611328125,0.00276203223018413,3.13562189739113E-5,1,0.999253354069792,40.0298881530762,1.9910607990166,20.7499992102385,0.0279805690721378,0.0242525727804139,0.25,0.00166382177276923,0.00276976823632648,0.00167255369588268,199.9928589,199.9928589,16544.119140625,16549.103515625,56.6594697305252,20.3607755662542,26.325863,0,0,0,40,4449,199.9144,16546.611328125,,,,,,,,,,,,,0,,,,0.0049,,,,,,199.9928589,,,,
,28004066.52,199.9907074,11911.4833984375,0.00285837716017354,2.70111991684093E-5,1,0.999253354069792,40.0298881530762,1.99106903808589,20.7499992102385,0.0290441175929118,0.024595121192559,0.25,0.00167735147480442,0.00286642793963395,0.0016862386981859,199.9907074,199.9907074,11906.587890625,11916.37890625,56.9596150819099,20.3621932741065,26.705515,0,0,0,40,4449,199.9201,11911.4833984375,,,,,,,,,,,,,0,,,,0,,,,,,199.9907074,,,,
,28004162.265,199.9913483,7128.51123046875,0.00286867809625688,2.35306468747075E-5,1,0.999253354069792,40.0298881530762,1.99106079092754,20.7499992102385,0.0291111964836017,0.0248991840719843,0.25,0.00170244185306477,0.00287673382035022,0.00171143097226689,199.9913483,199.9913483,7118.3125,7138.7099609375,57.200356665833,20.3623819807721,26.705515,0,0,0,40,4449,199.9207,7128.51123046875,,,,,,,,,,,,,0,,,,0.0049,,,,,,199.9913483,,,,
,28004257.775,199.9886017,2353.13122558594,0.00280423382623078,2.47299214966158E-5,1,0.999253354069792,40.0298881530762,1.99119172937059,20.7499992102385,0.0284964375626119,0.024125690087231,0.25,0.00164513335458804,0.00281212685285012,0.00165385818936906,199.9886017,199.9886017,2345.6201171875,2360.64233398438,57.2402197203138,20.3624288414366,26.325863,0,0,0,40,4449,199.93315,2353.13122558594,,,,,,,,,,,,,0,,,,0,,,,,,199.9886017,,,,
,28004305.555,199.9918365,-0.380594328045845,-6.05083075423285E-5,6.69224069003305E-6,1,0.999253354069792,40.0298881530762,1.99104083912851,20.7499992102385,-0.000606920403361161,-0.000566109994697098,0.25,-3.95260752153788E-5,-6.06742149902133E-5,-3.97282611423546E-5,199.9918365,199.9918365,-0.395818114280701,-0.365370541810989,56.9783741663714,20.3629152495372,26.705515,0,0,0,40,4417,199.9387,-0.380594328045845,,,,,,,,,,,,,0,,,,0,,,,,,199.9918365,,,,