File: data/monolayers/nanoparticles/Ac_CoFe_C_2/vsm/data_dispersion/YF45_HYST_150K.DAT
[Header]
; VSM Data File (default extension .dat)
; Copyright (c) 2003-2013, Quantum Design, Inc. All rights reserved.
TITLE,
FILEOPENTIME,27981692.27,11/21/2018,4:42 am
BYAPP,VSM,2.0,2.0
INFO,PPMS VSM Option Release 1.4.10 Build 1,APPNAME
INFO,Quantum Design Linear Motor Servo Controller,MOTOR_MODULE_NAME
INFO,3101-100 M1,MOTOR_HW_VERSION
INFO,MMC1014,MOTOR_SERIAL_NUMBER
INFO,SRV No X-over 01.03.11,MOTOR_SOFTWARE_VERSION
INFO,Quantum Design VSM Detection Module,VSM_MODULE_NAME
INFO,3101-150 F0,VSM_HW_VERSION
INFO,VSM707,VSM_SERIAL_NUMBER
INFO,VSM No X-over 01.02.05 May 20 2008 13:51:47,VSM_SOFTWARE_VERSION
INFO,704,PREAMP_SERIAL_NUMBER
INFO,822,COIL_SERIAL_NUMBER
INFO,0,MOMENT_UNITS
INFO,CoFe2O4,SAMPLE_MATERIAL
INFO,dispersion in ampulle,SAMPLE_COMMENT
INFO,,SAMPLE_MASS
INFO,,SAMPLE_VOLUME
INFO,,SAMPLE_MOLECULAR_WEIGHT
INFO,,SAMPLE_SIZE
INFO,,SAMPLE_SHAPE
DATATYPE,COMMENT,1
DATATYPE,TIME,2
STARTUPAXIS,X,2
STARTUPAXIS,Y1,5
[Data]
Comment,Time Stamp (sec),Temperature (K),Magnetic Field (Oe),Moment (emu),M. Std. Err. (emu),Transport Action,Averaging Time (sec),Frequency (Hz),Peak Amplitude (mm),Center Position (mm),Coil Signal' (mV),Coil Signal" (mV),Range (mV),M. Quad. Signal (emu),M. Raw' (emu),M. Raw" (emu),Min. Temperature (K),Max. Temperature (K),Min. Field (Oe),Max. Field (Oe),Mass (grams),Motor Lag (deg),Pressure (Torr),VSM Status (code),Motor Status (code),Measure Status (code),Measure Count,PPMS Status (code),System Temp. (K),System Field (Oe),Sample Position (deg),Bridge 1 Resistance (ohms),Bridge 1 Excitation (에),Bridge 2 Resistance (ohms),Bridge 2 Excitation (에),Bridge 3 Resistance (ohms),Bridge 3 Excitation (에),Bridge 4 Resistance (ohms),Bridge 4 Excitation (에),Signal 1 Vin (V),Signal 2 Vin (V),Digital Inputs (code),Drive 1 Iout (mA),Drive 1 Ipower (W),Drive 2 Iout (mA),Drive 2 Ipower (W),Pressure (),Map 20 (),Map 21 (),Map 22 (),Map 23 (),Map 24 (),Map 25 (),Map 26 (),Map 27 (),Map 28 (),Map 29 ()
,27981707.13,150.3653717,-0.365370541810989,,,2,,,,21.0400004294515,,,,,,,150.3653717,150.3653717,-0.365370541810989,-0.365370541810989,,,24.427608,,,,-99999999,4369,150.2749,-0.365370541810989,,,,,,,,,,,,,,,,,,,,,,,150.3653717,,,,
,27981863.74,150.20050815,4493.59423828125,0.00327943765153973,5.6725452293241E-7,1,0.999253354069792,40.0298881530762,1.9910429143475,21.0299994796514,0.037128108036156,0.00662064993375999,0.25,1.30391925691008E-5,0.00329546168911365,1.83586548869963E-5,150.1985779,150.2024384,4480.986328125,4506.2021484375,56.3882446343521,20.3574264473974,24.427608,0,0,0,40,4449,149.95385,4493.59423828125,,,,,,,,,,,,,0,,,,0,,,,,,150.20050815,,,,
,27981959.905,150.1063232,9299.455078125,0.00365910194848093,1.13680672387529E-6,1,0.999253354069792,40.0298881530762,1.99087775726099,21.0299994796514,0.0414238925446832,0.00738330032266462,0.25,1.42692225306625E-5,0.00367699328862487,2.01941985597842E-5,150.1063232,150.1063232,9291.7529296875,9307.1572265625,56.4241995462367,20.3660844469486,24.047956,0,0,0,40,4449,149.8871,9299.455078125,,,,,,,,,,,,,0,,,,-0.0049,,,,,,150.1063232,,,,
,27982061.32,150.04483795,14367.1313476563,0.00375372905373278,9.27849200137336E-7,1,0.999253354069792,40.0298881530762,1.9910099290078,21.0299994796514,0.0424996905725804,0.00756473524162401,0.25,1.3769587145503E-5,0.00377209416688239,1.98292897749708E-5,150.0445862,150.0450897,14359.546875,14374.7158203125,56.7782772654483,20.3662660946284,24.427608,0,0,0,40,4449,149.8675,14367.1313476563,,,,,,,,,,,,,0,,,,-0.00245,,,,,,150.04483795,,,,
,27982163.28,150.0135803,19464.47265625,0.00375296934904407,1.42568925219966E-6,1,0.999253354069792,40.0298881530762,1.9906155878617,21.0299994796514,0.0424799738858379,0.00757991675292248,0.25,1.53837103339463E-5,0.00377133516096656,2.14336370252514E-5,150.0135803,150.0135803,19462.072265625,19466.873046875,56.4156016325252,20.3735194211537,24.807261,0,0,0,40,4449,149.8659,19464.47265625,,,,,,,,,,,,,0,,,,0,,,,,,150.0135803,,,,
,27982262.255,150.0007324,24409.3427734375,0.00371881542888053,1.36783666190535E-6,1,0.999253354069792,40.0298881530762,1.99078576811827,21.0299994796514,0.0421013878948516,0.00748567085511306,0.25,1.29752545035886E-5,0.00373702282817131,1.89420951144654E-5,150.0007324,150.0007324,24404.31640625,24414.369140625,56.5117419403906,20.370624526953,25.186911,0,0,0,40,4449,149.8697,24409.3427734375,,,,,,,,,,,,,0,,,,-0.00245,,,,,,150.0007324,,,,
,27982361.705,149.9974365,29382.2197265625,0.00366939677109771,1.28041379130052E-6,1,0.999253354069792,40.0298881530762,1.99070191186794,21.0299994796514,0.0415387907294741,0.00739449148690125,0.25,1.35779312337443E-5,0.00368736516705,1.94520031254666E-5,149.9974365,149.9974365,29372.349609375,29392.08984375,57.0299616486406,20.3626839895919,24.807261,0,0,0,40,4449,149.8717,29382.2197265625,,,,,,,,,,,,,0,,,,0,,,,,,149.9974365,,,,
,27982459.045,149.9987183,34247.408203125,0.00360858404919594,2.07305333411838E-6,1,0.999253354069792,40.0298881530762,1.99079733342164,21.0299994796514,0.040858934942802,0.00723408561921022,0.25,9.99807965896719E-6,0.00362626361826728,1.57412103951386E-5,149.9987183,149.9987183,34234.921875,34259.89453125,57.0158923352945,20.3645319850739,24.047956,0,0,0,40,4449,149.8746,34247.408203125,,,,,,,,,,,,,0,,,,0.00245,,,,,,149.9987183,,,,
,27982557.2,149.9976501,39152.322265625,0.00353695905958478,1.35054819196094E-6,1,0.999253354069792,40.0298881530762,1.99060295043026,21.0299994796514,0.0400443523715662,0.00708929756618519,0.25,9.76853075937318E-6,0.00355429170718615,1.53800778587011E-5,149.9976501,149.9976501,39147.14453125,39157.5,56.9119357422368,20.3635490523058,24.807261,0,0,0,40,4449,149.87975,39152.322265625,,,,,,,,,,,,,0,,,,0,,,,,,149.9976501,,,,
,27982653.475,150.0014191,43964.92578125,0.00346010211585155,1.92485500352963E-6,1,0.999253354069792,40.0298881530762,1.99089941752236,21.0299994796514,0.0391793931657526,0.00693863116682112,0.25,9.78370813778394E-6,0.00347706105423873,1.52577989503681E-5,150.0014191,150.0014191,43959.8046875,43970.046875,56.6500901882945,20.3729379192101,24.807261,0,0,0,40,4449,149.87675,43964.92578125,,,,,,,,,,,,,0,,,,-0.00245,,,,,,150.0014191,,,,
,27982753.515,150.0036163,48962.779296875,0.00337549448219607,1.97347400792565E-6,1,0.999253354069792,40.0298881530762,1.99038958869846,21.0299994796514,0.0382107813488566,0.0067746512826903,0.25,1.02090635986347E-5,0.0033920412291558,1.55354435305307E-5,150.0036163,150.0036163,48952.86328125,48972.6953125,56.6602513590445,20.3708655534813,24.807261,0,0,0,40,4449,149.8734,48962.779296875,,,,,,,,,,,,,0,,,,0.00245,,,,,,150.0036163,,,,
,27982855.175,150.0036774,54044.90625,0.00328154097610664,2.27419038178359E-6,1,0.999253354069792,40.0298881530762,1.99012031979428,21.0299994796514,0.0371398706288102,0.00660014137212267,0.25,1.12575890890286E-5,0.00329762881031375,1.64251464306978E-5,150.0035706,150.0037842,54039.953125,54049.859375,56.2405168442175,20.3760359942498,24.807261,0,0,0,40,4449,149.86885,54044.90625,,,,,,,,,,,,,0,,,,-0.00245,,,,,,150.0036774,,,,
,27982950.83,150.0065765,58828.080078125,0.00319353634982585,2.49852029844666E-6,1,0.999253354069792,40.0298881530762,1.99043295756002,21.0299994796514,0.0361423665037328,0.006463960973225,0.25,1.44899783325791E-5,0.00320919041693587,1.95205639200346E-5,150.0065765,150.0065765,58817.640625,58838.51953125,56.6438371601406,20.3723841345269,24.807261,0,0,0,40,4449,149.8619,58828.080078125,,,,,,,,,,,,,0,,,,-0.0049,,,,,,150.0065765,,,,
,27983041.225,150.005661,63343.73828125,0.00309722014327005,2.19052315148899E-6,1,0.999253354069792,40.0298881530762,1.99057063899517,21.0299994796514,0.0350615122322586,0.00623016823823213,0.25,1.06013943188419E-5,0.00311241071829108,1.54486185716901E-5,150.005661,150.005661,63336.1484375,63351.328125,56.5789619930445,20.3734655008907,25.186911,0,0,0,40,4449,149.85855,63343.73828125,,,,,,,,,,,,,0,,,,-0.00245,,,,,,150.005661,,,,
,27983137.96,150.0061646,68178.8359375,0.0030062196048293,2.84388498505272E-6,1,0.999253354069792,40.0298881530762,1.99073719522503,21.0299994796514,0.0340425869326215,0.00599894916867406,0.25,6.00979678207814E-6,0.0030209737345751,1.06782742807245E-5,150.0061646,150.0061646,68173.953125,68183.71875,56.7259081546598,20.3658240694456,24.807261,0,0,0,40,4449,149.8527,68178.8359375,,,,,,,,,,,,,0,,,,-0.0049,,,,,,150.0061646,,,,
,27983236.59,150.00785065,73108.96875,0.00290573003324805,2.21119619459537E-6,1,0.999253354069792,40.0298881530762,1.99063874047728,21.0299994796514,0.0328976712265952,0.00582943347658395,0.25,8.58545675399147E-6,0.00291998981397489,1.30963473973999E-5,150.007431,150.0082703,73096.2578125,73121.6796875,56.394497662506,20.3749885460811,24.807261,0,0,0,40,4449,149.8457,73108.96875,,,,,,,,,,,,,0,,,,0,,,,,,150.00785065,,,,
,27983330.77,150.0073242,77817.01171875,0.00280506339197848,2.78905010214797E-6,1,0.999253354069792,40.0298881530762,1.99055625972023,21.0299994796514,0.0317529356958219,0.00564908149781603,0.25,1.0228295357048E-5,0.0028188292046132,1.45785289392303E-5,150.0073242,150.0073242,77809.6484375,77824.375,56.3515080939483,20.3564955616334,24.807261,0,0,0,40,4449,149.83485,77817.01171875,,,,,,,,,,,,,0,,,,-0.0049,,,,,,150.0073242,,,,
,27983426.57,150.0071869,82605.5390625,0.00270328396579994,3.18301785617833E-6,1,0.999253354069792,40.0298881530762,1.990582147615,21.0400000214577,0.0305994058188894,0.00545460015436233,0.25,1.07907100599597E-5,0.00271655186479756,1.49737711204761E-5,150.0071869,150.0071869,82592.578125,82618.5,56.5093970548329,20.3720412790193,24.807261,0,0,0,40,4449,149.82895,82605.5390625,,,,,,,,,,,,,0,,,,0,,,,,,150.0071869,,,,
,27983519.79,150.0085297,87268.8515625,0.00260288289167952,2.06754680743962E-6,1,0.999253354069792,40.0298881530762,1.99062568089632,21.0299994796514,0.0294731568025138,0.00519711433142766,0.25,5.54616426269966E-6,0.0026156680814014,9.5370280293411E-6,150.0085297,150.0085297,87261.296875,87276.40625,56.5859966497175,20.3678848201031,24.807261,0,0,0,40,4449,149.82085,87268.8515625,,,,,,,,,,,,,0,,,,0.0049,,,,,,150.0085297,,,,
,27983628.115,150.0063324,88300.7421875,0.00258093725204478,2.51751492535887E-6,1,0.999253354069792,40.0298881530762,1.99085604154955,21.0299994796514,0.0292345830029319,0.00511547598962559,0.25,2.1133331751387E-6,0.00259362053983666,6.05115835390787E-6,150.0063324,150.0063324,88293.375,88308.109375,56.7759323798906,20.3693099904067,24.807261,0,0,0,40,4449,149.8157,88300.7421875,,,,,,,,,,,,,0,,,,0,,,,,,150.0063324,,,,
,27983720.235,149.9997711,83694.8203125,0.00267686775449546,2.35621668050917E-6,1,0.999253354069792,40.0298881530762,1.99081223027581,21.0299994796514,0.0303090687131989,0.00537134558399262,0.25,7.99113952605438E-6,0.00269001125868864,1.21173536841139E-5,149.9997711,149.9997711,83689.828125,83699.8125,56.5789619930445,20.3751982745896,24.807261,0,0,0,40,4449,149.81665,83694.8203125,,,,,,,,,,,,,0,,,,0,,,,,,149.9997711,,,,
,27983815.485,149.9949036,78935.5625,0.00278003814670562,2.30453197222617E-6,1,0.999253354069792,40.0298881530762,1.99075843529964,21.0299994796514,0.0314810418901571,0.00555146337836183,0.25,5.92350830270317E-6,0.00279368923438814,1.02111590910006E-5,149.9949036,149.9949036,78925.3359375,78945.7890625,56.9611783389483,20.3687719746777,25.186911,0,0,0,40,4449,149.8268,78935.5625,,,,,,,,,,,,,0,,,,0.00245,,,,,,149.9949036,,,,
,27983907.89,149.99245455,74314.78125,0.00287899295489851,2.52051217420113E-6,1,0.999253354069792,40.0298881530762,1.99057899354125,21.0299994796514,0.0325922400517982,0.00578602993876886,0.25,9.42755949502735E-6,0.00289312203725347,1.38983015831888E-5,149.9922028,149.9927063,74311.9921875,74317.5703125,56.6837002146214,20.3691944436773,24.427608,0,0,0,40,4449,149.8313,74314.78125,,,,,,,,,,,,,0,,,,0,,,,,,149.99245455,,,,
,27984001.385,149.9923096,69641.21875,0.00297439240668603,2.84063006914837E-6,1,0.999253354069792,40.0298881530762,1.99068456897595,21.0299994796514,0.0336777593275855,0.00595589042195816,0.25,7.76864188560004E-6,0.00298898955371563,1.23925871791573E-5,149.9923096,149.9923096,69633.8359375,69648.6015625,56.8095424062176,20.3751007390443,25.186911,0,0,0,40,4449,149.83815,69641.21875,,,,,,,,,,,,,0,,,,0,,,,,,149.9923096,,,,
,27984094.995,149.9908142,64963.6328125,0.00306744704544392,2.57454402258688E-6,1,0.999253354069792,40.0298881530762,1.99056716356393,21.0299994796514,0.0347253004907623,0.00616532968644706,0.25,1.00678707850098E-5,0.00308249458841142,1.48615701817574E-5,149.9904785,149.9911499,64955.89453125,64971.37109375,56.8150138058522,20.3679519787919,24.807261,0,0,0,40,4449,149.8475,64963.6328125,,,,,,,,,,,,,0,,,,0,,,,,,149.9908142,,,,
,27984189.195,149.99183655,60255.611328125,0.00316478327417028,2.02973544825109E-6,1,0.999253354069792,40.0298881530762,1.99054417811438,21.0299994796514,0.0358303946144179,0.00634008007706801,0.25,8.53458898566414E-6,0.00318030772532937,1.34868284382959E-5,149.9917145,149.9919586,60248.48046875,60262.7421875,56.8298647477175,20.3670867522586,24.807261,0,0,0,40,4449,149.855,60255.611328125,,,,,,,,,,,,,0,,,,0.00245,,,,,,149.99183655,,,,
,27984283.995,149.9933624,55514.40234375,0.00325671970874181,2.49097754675772E-6,1,0.999253354069792,40.0298881530762,1.99033028958204,21.0400000214577,0.0368641712723733,0.00654234017750485,0.25,1.0422880842345E-5,0.00327268898996465,1.55429905824362E-5,149.9933624,149.9933624,55499.4375,55529.3671875,57.0745144742368,20.3703792605194,25.186911,0,0,0,40,4449,149.862,55514.40234375,,,,,,,,,,,,,0,,,,-0.00245,,,,,,149.9933624,,,,
,27984377.93,149.9923401,50819.40625,0.00334343658383252,2.30317780332689E-6,1,0.999253354069792,40.0298881530762,1.9907952685604,21.0299994796514,0.0378560199852403,0.00670735170535384,0.25,9.741133515214E-6,0.00335982912270137,1.50091571985493E-5,149.9923401,149.9923401,50806.8828125,50831.9296875,56.9619599674676,20.374839749855,24.807261,0,0,0,40,4449,149.8639,50819.40625,,,,,,,,,,,,,0,,,,-0.0049,,,,,,149.9923401,,,,
,27984474.43,149.9880829,45997.134765625,0.00342951392327635,1.82124806597197E-6,1,0.999253354069792,40.0298881530762,1.99086950717478,21.0299994796514,0.0388365455027382,0.00685404552957789,0.25,7.66069043592805E-6,0.00344632901470648,1.30691005722114E-5,149.9880829,149.9880829,45989.64453125,46004.625,56.8798889729483,20.3663025001021,24.807261,0,0,0,40,4449,149.88055,45997.134765625,,,,,,,,,,,,,0,,,,0,,,,,,149.9880829,,,,
,27984568.81,149.9895782,41279.19921875,0.00351095669163777,2.0618572001196E-6,1,0.999253354069792,40.0298881530762,1.99075202412104,21.0299994796514,0.0397494598707206,0.00705705007887077,0.25,1.14138718695267E-5,0.00352816176330872,1.69846329086738E-5,149.9895782,149.9895782,41271.66796875,41286.73046875,56.6203883045637,20.3774504058429,24.807261,0,0,0,40,4449,149.88865,41279.19921875,,,,,,,,,,,,,0,,,,-0.0049,,,,,,149.9895782,,,,
,27984662.595,149.9893494,36594.400390625,0.00358270767881237,1.92002914295217E-6,1,0.999253354069792,40.0298881530762,1.99079436141649,21.0299994796514,0.0405596015099758,0.00721848446009459,0.25,1.31382412673524E-5,0.00360025845117258,1.88464318391298E-5,149.9893494,149.9893494,36584.734375,36604.06640625,56.8650380310829,20.3706992138107,25.186911,0,0,0,40,4449,149.8976,36594.400390625,,,,,,,,,,,,,0,,,,-0.00245,,,,,,149.9893494,,,,
,27984759.155,149.990448,31766.7744140625,0.0036528377667604,1.56730219897584E-6,1,0.999253354069792,40.0298881530762,1.99104413602229,21.0299994796514,0.041361877318006,0.00734098640995976,0.25,1.16423908963663E-5,0.00367073102379946,1.74705421995341E-5,149.990448,149.990448,31761.501953125,31772.046875,56.9869720800829,20.3667294818016,25.186911,0,0,0,40,4449,149.90525,31766.7744140625,,,,,,,,,,,,,0,,,,0,,,,,,149.990448,,,,
,27984853.385,149.9893951,27056.8232421875,0.00370829986721667,1.18778172133233E-6,1,0.999253354069792,40.0298881530762,1.99065840887134,21.0299994796514,0.0419791210260781,0.00746805219198213,0.25,1.33030529854406E-5,0.00372645898694159,1.92431191087802E-5,149.9893951,149.9893951,27054.30078125,27059.345703125,56.7642079521022,20.3705106615445,24.427608,0,0,0,40,4449,149.91445,27056.8232421875,,,,,,,,,,,,,0,,,,0,,,,,,149.9893951,,,,
,27984946.705,149.9914856,22391.4365234375,0.0037576018190251,1.37180214200465E-6,1,0.999253354069792,40.0298881530762,1.99077026748944,21.0299994796514,0.0425379767670667,0.00757633846819653,0.25,1.42232642455469E-5,0.00377599743226297,2.02618205008636E-5,149.9914856,149.9914856,22381.5234375,22401.349609375,57.0495023616214,20.3659629574998,25.186911,0,0,0,40,4449,149.92085,22391.4365234375,,,,,,,,,,,,,0,,,,-0.00245,,,,,,149.9914856,,,,
,27985039.995,149.99009705,17728.7998046875,0.00378904412020699,1.31052737195876E-6,1,0.999253354069792,40.0298881530762,1.99088389367054,21.0299994796514,0.0428965650807383,0.00763816760204202,0.25,1.41525019152197E-5,0.00380759068908769,2.02559910288827E-5,149.9900818,149.9901123,17724.0234375,17733.576171875,56.9791557948906,20.36842319402,24.427608,0,0,0,40,4449,149.92845,17728.7998046875,,,,,,,,,,,,,0,,,,0,,,,,,149.99009705,,,,
,27985136.62,149.992569,12901.3051757813,0.00380137172960119,9.44684168715728E-7,1,0.999253354069792,40.0298881530762,1.99054018903927,21.0299994796514,0.0430266592420745,0.00767514632613163,0.25,1.53663096560844E-5,0.00381997310789757,2.15105849359713E-5,149.992569,149.992569,12886.2705078125,12916.33984375,56.9947883652753,20.3708883992394,25.186911,0,0,0,40,4449,149.9351,12901.3051757813,,,,,,,,,,,,,0,,,,0,,,,,,149.992569,,,,
,27985232.875,149.99263,8091.02001953125,0.00376266695582788,5.50652310253288E-7,1,0.999253354069792,40.0298881530762,1.99072098403291,21.0299994796514,0.0425927348217462,0.00759475106554351,0.25,1.49399608046902E-5,0.00378107625751329,2.10341845209529E-5,149.99263,149.99263,8083.53955078125,8098.50048828125,56.8963031718522,20.3714577777749,25.186911,0,0,0,40,4449,149.9435,8091.02001953125,,,,,,,,,,,,,0,,,,0,,,,,,149.99263,,,,
,27985327.495,149.9926758,3360.31103515625,0.00359489571080571,4.44622680234715E-7,1,0.999253354069792,40.0298881530762,1.9907691256906,21.0400000214577,0.0406958831904264,0.00724835743958663,0.25,1.3563157666489E-5,0.00361248267419452,1.93938643283754E-5,149.9926758,149.9926758,3355.63159179687,3364.99047851562,57.0393411908714,20.3705370425858,24.807261,0,0,0,40,4449,149.9477,3360.31103515625,,,,,,,,,,,,,0,,,,0,,,,,,149.9926758,,,,
,27985420.465,149.995636,-1285.67498779297,0.000236103447479443,8.56877784896521E-7,1,0.999253354069792,40.0298881530762,1.99077363941332,21.0299994796514,0.0026791454194139,0.000439662375180377,0.25,-2.32205669557858E-6,0.000237263588080079,-1.95457483267684E-6,149.995636,149.995636,-1290.78015136719,-1280.56982421875,57.1628384969099,20.3763958379548,25.186911,0,0,0,40,4449,149.95175,-1285.67498779297,,,,,,,,,,,,,0,,,,0,,,,,,149.995636,,,,
,27985516.205,149.9978943,-6067.06469726563,-0.00147952553221467,1.04066727617137E-6,1,0.999253354069792,40.0298881530762,1.99066910258792,21.0299994796514,-0.0167431010646413,-0.00301179180841301,0.25,-8.12562362006743E-6,-0.00148676002221388,-1.05349389444704E-5,149.9978943,149.9978943,-6071.984375,-6062.14501953125,56.8955215433329,20.3774694708509,24.427608,0,0,0,40,4449,149.9535,-6067.06469726563,,,,,,,,,,,,,0,,,,0,,,,,,149.9978943,,,,
,27985609.68,150.0031509,-10740.6005859375,-0.00299406594152,8.28874004530939E-7,1,0.999253354069792,40.0298881530762,1.99073583098469,21.0299994796514,-0.0338925159268682,-0.00604362314549902,0.25,-1.19130278899539E-5,-0.00300871527112931,-1.67561465083829E-5,150.0030975,150.0032043,-10750.5234375,-10730.677734375,56.9619599674676,20.3795359051544,24.807261,0,0,0,40,4449,149.9478,-10740.6005859375,,,,,,,,,,,,,0,,,,-0.00245,,,,,,150.0031509,,,,
,27985707.485,150.0048065,-15630.5,-0.00363637251803424,8.86866610473165E-7,1,0.999253354069792,40.0298881530762,1.99051997939083,21.0299994796514,-0.0411579958052585,-0.00734591019470706,0.25,-1.50589429291571E-5,-0.00365416662965062,-2.09295588320321E-5,150.0048065,150.0048065,-15637.900390625,-15623.099609375,57.0002597649099,20.3792761987907,25.186911,0,0,0,40,4449,149.9421,-15630.5,,,,,,,,,,,,,0,,,,-0.00245,,,,,,150.0048065,,,,
,27985805.055,150.0084381,-20505.306640625,-0.00373511196922183,9.5951631494961E-7,1,0.999253354069792,40.0298881530762,1.9907879430814,21.0299994796514,-0.0422853803078624,-0.00752143240246247,0.25,-1.32835611465676E-5,-0.00375339582523397,-1.92873069556466E-5,150.0084381,150.0084381,-20510.333984375,-20500.279296875,56.7814037795252,20.3809130510274,25.186911,0,0,0,40,4449,149.9355,-20505.306640625,,,,,,,,,,,,,0,,,,-0.0049,,,,,,150.0084381,,,,
,27985899.99,150.0104218,-25250.3330078125,-0.00371231102838673,1.02623102646214E-6,1,0.999253354069792,40.0298881530762,1.99066649107887,21.0299994796514,-0.0420255025217707,-0.00747127550044703,0.25,-1.28813725452375E-5,-0.00373048704903869,-1.88312764650334E-5,150.0104218,150.0104218,-25257.791015625,-25242.875,56.8025077495445,20.3799570407247,25.186911,0,0,0,40,4449,149.92705,-25250.3330078125,,,,,,,,,,,,,0,,,,0.00245,,,,,,150.0104218,,,,
,27985995.88,150.0124512,-30042.7265625,-0.00366154350062204,1.55682789581554E-6,1,0.999253354069792,40.0298881530762,1.99085607607724,21.0299994796514,-0.0414512701593537,-0.00738884209717765,0.25,-1.44036874014704E-5,-0.00367947156228361,-2.02647691478327E-5,150.0124512,150.0124512,-30055.279296875,-30030.173828125,56.7900016932368,20.3776299949332,25.186911,0,0,0,40,4449,149.9129,-30042.7265625,,,,,,,,,,,,,0,,,,0,,,,,,150.0124512,,,,
,27986091.825,150.012558,-34837.328125,-0.00359824405680079,1.41396767612852E-6,1,0.999253354069792,40.0298881530762,1.99089867326017,21.0299994796514,-0.0407401618893224,-0.00723477332554946,0.25,-1.1832625786748E-5,-0.00361586942424282,-1.75648122370311E-5,150.012558,150.012558,-34847.51953125,-34827.13671875,56.9392927404099,20.3804867238069,24.807261,0,0,0,40,4449,149.90295,-34837.328125,,,,,,,,,,,,,0,,,,-0.0049,,,,,,150.012558,,,,
,27986189.515,150.0108032,-39722.1875,-0.0035246833627837,1.73897273125325E-6,1,0.999253354069792,40.0298881530762,1.99115719158119,21.0299994796514,-0.0399085961505036,-0.00710890941172345,0.25,-1.34742414284176E-5,-0.00354194926206983,-1.90819501719737E-5,150.0108032,150.0108032,-39729.66796875,-39714.70703125,56.729816297256,20.3802882997438,25.186911,0,0,0,40,4449,149.8928,-39722.1875,,,,,,,,,,,,,0,,,,0,,,,,,150.0108032,,,,
,27986286.2,150.0131683,-44552.322265625,-0.00344623090688526,2.06794064874912E-6,1,0.999253354069792,40.0298881530762,1.9908461844881,21.0299994796514,-0.0390199149633547,-0.00691872113536589,0.25,-1.04602470595921E-5,-0.00346312007146627,-1.59137314749868E-5,150.0131683,150.0131683,-44557.48046875,-44547.1640625,57.0424677049483,20.3754446961034,24.807261,0,0,0,40,4449,149.87885,-44552.322265625,,,,,,,,,,,,,0,,,,-0.0049,,,,,,150.0131683,,,,
,27986385.195,150.0121002,-49502.353515625,-0.00336241633544777,1.69302475097242E-6,1,0.999253354069792,40.0298881530762,1.9911506476961,21.0299994796514,-0.0380695509829068,-0.00679149167769101,0.25,-1.37567217795123E-5,-0.0033788929159096,-1.90784541542445E-5,150.0121002,150.0121002,-49504.6875,-49500.01953125,56.7634263235829,20.37840234889,24.427608,0,0,0,40,4449,149.86805,-49502.353515625,,,,,,,,,,,,,0,,,,0,,,,,,150.0121002,,,,
,27986480.91,150.0121307,-54284.470703125,-0.00327223837268964,2.17933106714694E-6,1,0.999253354069792,40.0298881530762,1.99089289052295,21.0299994796514,-0.0370509331024624,-0.00656878159316103,0.25,-9.89431808810205E-6,-0.0032882819927211,-1.50402453162106E-5,150.0121307,150.0121307,-54286.9375,-54282.00390625,57.004167907506,20.3743635784494,25.186911,0,0,0,40,4449,149.861,-54284.470703125,,,,,,,,,,,,,0,,,,0.00245,,,,,,150.0121307,,,,
,27986577.34,150.0151062,-59101.54296875,-0.00317811378777243,2.5035270270037E-6,1,0.999253354069792,40.0298881530762,1.99096732113134,21.0299994796514,-0.0359791408364765,-0.00642230467914988,0.25,-1.33532523932378E-5,-0.00319369318711355,-1.83541338465006E-5,150.0151062,150.0151062,-59104.125,-59098.9609375,56.9220969129868,20.378839711397,24.427608,0,0,0,40,4449,149.8457,-59101.54296875,,,,,,,,,,,,,0,,,,-0.0049,,,,,,150.0151062,,,,
,27986676.51,150.010498,-64059.240234375,-0.00308480664209947,2.02103927140169E-6,1,0.999253354069792,40.0298881530762,1.9911742913485,21.0299994796514,-0.034937574918606,-0.00616980299368676,0.25,-7.27784994298233E-6,-0.0030999413001865,-1.20881147085439E-5,150.010498,150.010498,-64067.01171875,-64051.46875,56.8189219484483,20.3788448820235,25.566563,0,0,0,40,4449,149.8376,-64059.240234375,,,,,,,,,,,,,0,,,,0.0049,,,,,,150.010498,,,,
,27986774.885,150.0101013,-68976.328125,-0.00298575421387108,2.40528689678864E-6,1,0.999253354069792,40.0298881530762,1.99110288702748,21.0299994796514,-0.0338145301773935,-0.00597199114388665,0.25,-7.10321559883951E-6,-0.00300040612550141,-1.17440634685551E-5,150.0101013,150.0101013,-68988.796875,-68963.859375,56.9611783389483,20.3822777294773,25.186911,0,0,0,40,4449,149.826,-68976.328125,,,,,,,,,,,,,0,,,,0.0049,,,,,,150.0101013,,,,
,27986872.545,150.0117798,-73855.71484375,-0.00288595359449507,2.90230710971959E-6,1,0.999253354069792,40.0298881530762,1.99068871262689,21.0299994796514,-0.0326717065600286,-0.00580623422771221,0.25,-9.97048183598589E-6,-0.00290011404795559,-1.44565332424267E-5,150.0117798,150.0117798,-73865.6875,-73845.7421875,56.9095908566791,20.3786342002247,24.807261,0,0,0,40,4449,149.81875,-73855.71484375,,,,,,,,,,,,,0,,,,0,,,,,,150.0117798,,,,
,27986969.825,150.0090942,-78720.390625,-0.00278484762147766,2.83452956464201E-6,1,0.999253354069792,40.0298881530762,1.99127958527616,21.0299994796514,-0.03153942260162,-0.00558512637177614,0.25,-7.93330737760373E-6,-0.00279851786949668,-1.22395095766699E-5,150.0090942,150.0090942,-78728.03125,-78712.75,56.9994781363906,20.3788939964032,25.186911,0,0,0,40,4449,149.81005,-78720.390625,,,,,,,,,,,,,0,,,,0.0049,,,,,,150.0090942,,,,
,27987071.44,150.0108185,-83797.3203125,-0.00267432512937198,2.5835944378836E-6,1,0.999253354069792,40.0298881530762,1.99062183394969,21.0299994796514,-0.0302814894540239,-0.00534286673677881,0.25,-5.96283813481467E-6,-0.00268745831875544,-1.00755945157715E-5,150.0108185,150.0108185,-83804.671875,-83789.96875,56.8157954343714,20.3687695648701,24.807261,0,0,0,40,4449,149.7981,-83797.3203125,,,,,,,,,,,,,0,,,,0,,,,,,150.0108185,,,,
,27987164.325,150.0113525,-88439.45703125,-0.00257475375952862,3.12794296838725E-6,1,0.999253354069792,40.0298881530762,1.99085395841537,21.0299994796514,-0.0291646086909486,-0.00510263219135591,0.25,-2.05636960115683E-6,-0.00258740626318643,-5.98503860114309E-6,150.0113525,150.0113525,-88446.796875,-88432.1171875,57.0307432771599,20.3814460865264,25.186911,0,0,0,40,4449,149.78985,-88439.45703125,,,,,,,,,,,,,0,,,,-0.0049,,,,,,150.0113525,,,,
,27987275.845,150.00675965,-86966.58203125,-0.0026030919214844,2.82557141593017E-6,1,0.999253354069792,40.0298881530762,1.99074788434141,21.0299994796514,-0.0294750594812957,-0.00521040082618893,0.25,-6.65356478160771E-6,-0.00261587610391699,-1.06524431338405E-5,150.0067444,150.0067749,-86969.125,-86964.0390625,57.0268351345637,20.3740945469911,25.186911,0,0,0,40,4449,149.7827,-86966.58203125,,,,,,,,,,,,,0,,,,0,,,,,,150.00675965,,,,
,27987372.995,150.0006714,-82111.796875,-0.00271224950904958,2.43957007208001E-6,1,0.999253354069792,40.0298881530762,1.99072919187335,21.0299994796514,-0.0307087295426737,-0.00544048033653048,0.25,-7.94583022627184E-6,-0.00272556562126849,-1.21318385463104E-5,150.0006714,150.0006714,-82116.75,-82106.84375,56.9322580837368,20.3816126375906,25.186911,0,0,0,40,4449,149.7828,-82111.796875,,,,,,,,,,,,,0,,,,-0.0049,,,,,,150.0006714,,,,
,27987468.265,149.9963226,-77349.20703125,-0.00281251693601058,3.32231537359829E-6,1,0.999253354069792,40.0298881530762,1.99099182745733,21.0299994796514,-0.0318481278762505,-0.00564135459975211,0.25,-8.1406099649962E-6,-0.00282632269928426,-1.24954748462586E-5,149.9963226,149.9963226,-77359.4375,-77338.9765625,56.7157469839098,20.3846582664331,25.186911,0,0,0,40,4449,149.78405,-77349.20703125,,,,,,,,,,,,,0,,,,-0.00245,,,,,,149.9963226,,,,
,27987568.155,149.9927826,-72357.11328125,-0.0029133424868201,2.1334985328812E-6,1,0.999253354069792,40.0298881530762,1.99063924524173,21.0400000214577,-0.0329858779765352,-0.00583316442435127,0.25,-7.58437059439183E-6,-0.00292764145432591,-1.21066286744843E-5,149.9927826,149.9927826,-72362.1875,-72352.0390625,56.628204589756,20.380122092822,24.807261,0,0,0,40,4449,149.7928,-72357.11328125,,,,,,,,,,,,,0,,,,-0.00245,,,,,,149.9927826,,,,
,27987666.09,149.9924622,-67462.7578125,-0.00301253264921093,3.04543185511772E-6,1,0.999253354069792,40.0298881530762,1.99100518019527,21.0299994796514,-0.0341073319768204,-0.00607623351202535,0.25,-1.16592739131613E-5,-0.00302730924682661,-1.63697649825088E-5,149.9924622,149.9924622,-67465.3359375,-67460.1796875,56.7204367550252,20.3787186115541,25.566563,0,0,0,40,4449,149.80185,-67462.7578125,,,,,,,,,,,,,0,,,,-0.00245,,,,,,149.9924622,,,,
,27987762.325,149.9918518,-62653.283203125,-0.00311118282967303,2.12105585428689E-6,1,0.999253354069792,40.0298881530762,1.99109929636114,21.0299994796514,-0.0352344293701979,-0.00622584344707952,0.25,-7.64396832634766E-6,-0.00312644678655845,-1.250274786902E-5,149.9918518,149.9918518,-62663.21484375,-62643.3515625,56.8650380310829,20.3790445763113,25.186911,0,0,0,40,4449,149.81055,-62653.283203125,,,,,,,,,,,,,0,,,,0,,,,,,149.9918518,,,,
,27987859.09,149.9898224,-57815.578125,-0.00320840253635668,1.78924740903272E-6,1,0.999253354069792,40.0298881530762,1.99100494875526,21.0299994796514,-0.0363322106342105,-0.00642905087892328,0.25,-8.6573184021108E-6,-0.00322413896179282,-1.36878470252333E-5,149.9896088,149.990036,-57820.65234375,-57810.50390625,57.0745144742368,20.376730291905,25.186911,0,0,0,40,4449,149.8181,-57815.578125,,,,,,,,,,,,,0,,,,0,,,,,,149.9898224,,,,
,27987957.885,149.9892273,-52880.583984375,-0.00330004822997913,2.54765591254614E-6,1,0.999253354069792,40.0298881530762,1.99088410431391,21.0299994796514,-0.0373639447990945,-0.00663448105366741,0.25,-1.08456225787058E-5,-0.00331622752163505,-1.60462212080629E-5,149.9892273,149.9892273,-52882.58984375,-52878.578125,57.3355783996599,20.3797915802846,24.807261,0,0,0,40,4449,149.82325,-52880.583984375,,,,,,,,,,,,,0,,,,-0.0049,,,,,,149.9892273,,,,
,27988054.14,149.9894867,-48068.32421875,-0.00338885574573687,1.94488901856515E-6,1,0.999253354069792,40.0298881530762,1.99061072791135,21.0299994796514,-0.0383618044926152,-0.00682687531945115,0.25,-1.24238675356737E-5,-0.0034054648519392,-1.7786964267207E-5,149.9894867,149.9894867,-48075.69921875,-48060.94921875,56.9275683126214,20.3806320062466,25.186911,0,0,0,40,4449,149.83685,-48068.32421875,,,,,,,,,,,,,0,,,,0,,,,,,149.9894867,,,,
,27988149.89,149.9922638,-43280.880859375,-0.00347129158183255,2.0982748890916E-6,1,0.999253354069792,40.0298881530762,1.99088529734942,21.0299994796514,-0.039302836025114,-0.00697819638551815,0.25,-1.1327217254648E-5,-0.00348830298535494,-1.68305365524337E-5,149.9920654,149.9924622,-43288.13671875,-43273.625,56.8837971155445,20.3792042351709,25.186911,0,0,0,40,4449,149.844,-43280.880859375,,,,,,,,,,,,,0,,,,0.00245,,,,,,149.9922638,,,,
,27988246.98,149.9919434,-38431.5546875,-0.00354991859041941,1.81152847549543E-6,1,0.999253354069792,40.0298881530762,1.99060805301005,21.0299994796514,-0.0401865888791515,-0.00714159415041788,0.25,-1.2122472046517E-5,-0.00356731076379601,-1.77700607920622E-5,149.9919434,149.9919434,-38441.6015625,-38421.5078125,56.8970848003714,20.3802671228703,25.186911,0,0,0,40,4449,149.85055,-38431.5546875,,,,,,,,,,,,,0,,,,0.00245,,,,,,149.9919434,,,,
,27988343.47,149.9918365,-33609.255859375,-0.00362363862343778,1.38512365458961E-6,1,0.999253354069792,40.0298881530762,1.99103720053799,21.0299994796514,-0.0410292219360112,-0.0072931852964764,0.25,-1.25156535578465E-5,-0.00364138807974506,-1.82978952645284E-5,149.9918365,149.9918365,-33619.50390625,-33599.0078125,56.9861904515637,20.3780762402958,24.807261,0,0,0,40,4449,149.86095,-33609.255859375,,,,,,,,,,,,,0,,,,0.0049,,,,,,149.9918365,,,,
,27988439.75,149.9915924,-28797.3115234375,-0.00368629495944664,9.88894060060721E-7,1,0.999253354069792,40.0298881530762,1.99087853797388,21.0299994796514,-0.0417353077339573,-0.00741948704029226,0.25,-1.27831361349722E-5,-0.00370434756665426,-1.86823106545231E-5,149.9915924,149.9915924,-28807.380859375,-28787.2421875,56.9471090256022,20.3799810158134,25.566563,0,0,0,40,4449,149.8682,-28797.3115234375,,,,,,,,,,,,,0,,,,0,,,,,,149.9915924,,,,
,27988535.305,149.9908905,-24022.1201171875,-0.00373967178259869,8.18365251451224E-7,1,0.999253354069792,40.0298881530762,1.99105587272237,21.0299994796514,-0.0423408524060754,-0.00754096080678105,0.25,-1.41355151927531E-5,-0.00375798040324604,-2.01420597510589E-5,149.9908905,149.9908905,-24029.705078125,-24014.53515625,56.892395029256,20.3784292253559,25.186911,0,0,0,40,4449,149.8773,-24022.1201171875,,,,,,,,,,,,,0,,,,0,,,,,,149.9908905,,,,
,27988632.355,149.9917908,-19172.1279296875,-0.00378111979075681,1.26310091264062E-6,1,0.999253354069792,40.0298881530762,1.99121501360134,21.0299994796514,-0.0428129985273559,-0.00762716295848193,0.25,-1.44568537999124E-5,-0.00379962735755569,-2.05469861831009E-5,149.9917908,149.9917908,-19182.16015625,-19162.095703125,56.4632809721983,20.3780491752571,24.807261,0,0,0,40,4449,149.88415,-19172.1279296875,,,,,,,,,,,,,0,,,,0,,,,,,149.9917908,,,,
,27988729,149.9918823,-14340.3017578125,-0.00380085486735196,9.03893677002236E-7,1,0.999253354069792,40.0298881530762,1.99118719577762,21.0299994796514,-0.0430363436547841,-0.0076639837628531,0.25,-1.42625793030641E-5,-0.00381945594066786,-2.03988721762054E-5,149.9918823,149.9918823,-14345.3681640625,-14335.2353515625,56.9877537086022,20.3728595973797,25.186911,0,0,0,40,4449,149.8874,-14340.3017578125,,,,,,,,,,,,,0,,,,-0.00245,,,,,,149.9918823,,,,
,27988825.055,149.9914856,-9539.95947265625,-0.00378360893530482,6.41635396520781E-7,1,0.999253354069792,40.0298881530762,1.99123037539807,21.0299994796514,-0.0428414083995805,-0.00763231762180053,0.25,-1.44447741207246E-5,-0.00380212209825734,-2.05685134825151E-5,149.9914856,149.9914856,-9547.412109375,-9532.5068359375,57.0190188493714,20.3772098725931,25.186911,0,0,0,40,4449,149.89875,-9539.95947265625,,,,,,,,,,,,,0,,,,0,,,,,,149.9914856,,,,
,27988918.275,149.9934235,-4881.6513671875,-0.00367787001547874,5.3868406675324E-7,1,0.999253354069792,40.0298881530762,1.99109613598826,21.0299994796514,-0.0416405887296224,-0.00742333121339091,0.25,-1.44520050852698E-5,-0.0036958621772188,-2.041890437399E-5,149.9934235,149.9934235,-4889.0771484375,-4874.2255859375,56.8142321773329,20.3782678022248,25.186911,0,0,0,40,4449,149.90435,-4881.6513671875,,,,,,,,,,,,,0,,,,-0.0049,,,,,,149.9934235,,,,
,27989016.045,149.9978638,10.0835951082408,-0.0022625840317601,1.10333213321424E-5,1,0.999253354069792,40.0298881530762,1.99114288639534,21.0299994796514,-0.0256218451391784,-0.00454118897050664,0.25,-6.61979727644908E-6,-0.00227365457605596,-1.0285627864776E-5,149.9978638,149.9978638,-0.0628932490944862,20.2300834655762,56.7118388413137,20.3731409778889,25.186911,0,0,0,40,4449,149.90765,10.0835951082408,,,,,,,,,,,,,0,,,,-0.00245,,,,,,149.9978638,,,,
,27989110.805,149.9984283,4739.20458984375,0.000860599182471529,1.01938669777839E-6,1,0.999253354069792,40.0298881530762,1.99119787752102,21.0299994796514,0.00974244076528799,0.0017467260365974,0.25,4.23133139398951E-6,0.000864807744858056,5.63175717922295E-6,149.9984283,149.9984283,4729.10302734375,4749.30615234375,57.054973761256,20.3748695636158,25.186911,0,0,0,40,4449,149.9071,4739.20458984375,,,,,,,,,,,,,0,,,,0,,,,,,149.9984283,,,,
,27989206.135,150.0021973,9505.37646484375,0.00259981568374637,9.10259361733087E-7,1,0.999253354069792,40.0298881530762,1.99120907092644,21.0299994796514,0.0294362134687585,0.00524958149719851,0.25,1.0391029092728E-5,0.00261253507883095,1.46008629524835E-5,150.0021973,150.0021973,9502.814453125,9507.9384765625,56.7071490701983,20.3762392043321,25.186911,0,0,0,40,4449,149.906,9505.37646484375,,,,,,,,,,,,,0,,,,0,,,,,,150.0021973,,,,
,27989303.6,150.0046844,14378.1142578125,0.00353329029700687,9.30527816871075E-7,1,0.999253354069792,40.0298881530762,1.99112630789281,21.0299994796514,0.0400056597259632,0.00712381087841474,0.25,1.32196321331408E-5,0.00355058089340792,1.89229843018499E-5,150.0046844,150.0046844,14370.6142578125,14385.6142578125,56.8595666314483,20.3776891388,24.807261,0,0,0,40,4449,149.8995,14378.1142578125,,,,,,,,,,,,,0,,,,-0.0049,,,,,,150.0046844,,,,
,27989399.33,150.0077972,19160.416015625,0.00372605118916219,1.24779236337293E-6,1,0.999253354069792,40.0298881530762,1.99117108853834,21.0299994796514,0.0421895366146167,0.00751030980429184,0.25,1.37517374465869E-5,0.00374428842643591,1.97502572847224E-5,150.0077972,150.0077972,19152.71875,19168.11328125,56.8025077495445,20.3743014394861,25.186911,0,0,0,40,4449,149.89325,19160.416015625,,,,,,,,,,,,,0,,,,-0.00245,,,,,,150.0077972,,,,
,27989495.805,150.0104218,23983.12890625,0.00372363183826408,1.37833347011867E-6,1,0.999253354069792,40.0298881530762,1.99091326205098,21.0299994796514,0.0421585412572327,0.00749546580118155,0.25,1.29596794069979E-5,0.00374186164047283,1.89350470689927E-5,150.0104218,150.0104218,23975.4375,23990.8203125,56.6219515616021,20.3683143354954,25.186911,0,0,0,40,4449,149.87855,23983.12890625,,,,,,,,,,,,,0,,,,0,,,,,,150.0104218,,,,
,27989590.985,150.0101776,28740.9208984375,0.00367697992502918,1.31719157573929E-6,1,0.999253354069792,40.0298881530762,1.9911768009249,21.0299994796514,0.0416373343572988,0.00739286041076928,0.25,1.19623739773884E-5,0.00369498622727602,1.7842821626203E-5,150.0101776,150.0101776,28738.638671875,28743.203125,56.9377294833714,20.3757095488912,24.807261,0,0,0,40,4449,149.87075,28740.9208984375,,,,,,,,,,,,,0,,,,0,,,,,,150.0101776,,,,
,27989690.775,150.0107117,33728.328125,0.00361237227084346,1.6379715420131E-6,1,0.999253354069792,40.0298881530762,1.99130103243529,21.0299994796514,0.0409082105307452,0.00726339315424765,0.25,1.1768274357236E-5,0.00363006584613143,1.75285803946174E-5,150.0107117,150.0107117,33720.76953125,33735.88671875,56.872072687756,20.3735019593513,25.566563,0,0,0,40,4449,149.86195,33728.328125,,,,,,,,,,,,,0,,,,0,,,,,,150.0107117,,,,
,27989788.76,150.0121613,38623.28125,0.00354459841603796,1.9401940839664E-6,1,0.999253354069792,40.0298881530762,1.99125937340766,21.0299994796514,0.0401399321304029,0.00712705674081061,0.25,1.15702432694026E-5,0.00356196348782162,1.72061036741006E-5,150.0121613,150.0121613,38618.14453125,38628.41796875,56.9424192544868,20.3728457627524,25.186911,0,0,0,40,4449,149.84975,38623.28125,,,,,,,,,,,,,0,,,,0.00245,,,,,,150.0121613,,,,
,27989883.675,150.0095673,43371.08984375,0.00346579477282894,1.76501628341814E-6,1,0.999253354069792,40.0298881530762,1.99127045518342,21.0299994796514,0.0392489584377683,0.00696195074505361,0.25,1.07377654013295E-5,0.00348277851794265,1.62292386594382E-5,150.0095673,150.0095673,43365.80078125,43376.37890625,56.8447156895829,20.3758521184657,24.807261,0,0,0,40,4449,149.84405,43371.08984375,,,,,,,,,,,,,0,,,,0,,,,,,150.0095673,,,,
,27989982.31,150.0089417,48298.8359375,0.00338154930515614,1.7260004682555E-6,1,0.999253354069792,40.0298881530762,1.99133932720373,21.0299994796514,0.0382960859049116,0.00679367980716137,0.25,1.05572247222941E-5,0.00339812374648108,1.58991839592912E-5,150.0089417,150.0089417,48288.9296875,48308.7421875,56.6743206723906,20.3736708659608,24.807261,0,0,0,40,4449,149.83155,48298.8359375,,,,,,,,,,,,,0,,,,-0.00245,,,,,,150.0089417,,,,
,27990080.395,150.0125122,53204.1875,0.00328931302064459,2.00998681541847E-6,1,0.999253354069792,40.0298881530762,1.99108403529652,21.0299994796514,0.0372479540709332,0.00660200776682701,0.25,9.79448372666431E-6,0.00330543933606778,1.49721277446273E-5,150.0125122,150.0125122,53196.73046875,53211.64453125,56.8611298884868,20.3682352818692,25.186911,0,0,0,40,4449,149.8218,53204.1875,,,,,,,,,,,,,0,,,,0,,,,,,150.0125122,,,,
,27990177.86,150.0112915,58074.265625,0.00319823891206669,1.77821582455394E-6,1,0.999253354069792,40.0298881530762,1.99146077665882,21.0299994796514,0.0362237906083821,0.00641710086080159,0.25,9.24977148969088E-6,0.00321392269873529,1.42669031735755E-5,150.0112915,150.0112915,58069.1640625,58079.3671875,56.8048526351022,20.3702329654,25.186911,0,0,0,40,4449,149.81,58074.265625,,,,,,,,,,,,,0,,,,-0.00245,,,,,,150.0112915,,,,
,27990278.595,150.011795,63110.00390625,0.00309813538359437,2.36558393968954E-6,1,0.999253354069792,40.0298881530762,1.99117335002779,21.0400000214577,0.035089143276259,0.0061927810009783,0.25,6.98003529830563E-6,0.00311333477226829,1.18143813971158E-5,150.011795,150.011795,63102.48828125,63117.51953125,56.8408075469868,20.3715896451738,25.566563,0,0,0,40,4449,149.79805,63110.00390625,,,,,,,,,,,,,0,,,,0,,,,,,150.011795,,,,
,27990375.85,150.0119476,67969.82421875,0.00300685062037348,2.45665284416126E-6,1,0.999253354069792,40.0298881530762,1.99125215422664,21.0299994796514,0.0340522979534229,0.00603516473072782,0.25,8.96202993719023E-6,0.00302160203875142,1.36495259409025E-5,150.0119476,150.0119476,67964.9140625,67974.734375,56.7071490701983,20.3716459237503,25.566563,0,0,0,40,4449,149.78625,67969.82421875,,,,,,,,,,,,,0,,,,-0.00245,,,,,,150.0119476,,,,
,27990471.085,150.009964,72729.91796875,0.00290684807342794,2.14791622244188E-6,1,0.999253354069792,40.0298881530762,1.99136505701866,21.0299994796514,0.0329203788328516,0.00584176848460848,0.25,9.29637578280586E-6,0.00292111123846364,1.38163881065355E-5,150.009964,150.009964,72727.2421875,72732.59375,56.8150138058522,20.3720879285289,25.566563,0,0,0,40,4449,149.7802,72729.91796875,,,,,,,,,,,,,0,,,,0.0049,,,,,,150.009964,,,,
,27990567.51,150.0076141,77551.03125,0.00280378826641762,2.32904707251368E-6,1,0.999253354069792,40.0298881530762,1.99124824378648,21.0299994796514,0.0317579458745731,0.0055971769465401,0.25,5.70084874147243E-6,0.0028175540204534,1.00302203437142E-5,150.0076141,150.0076141,77541.0703125,77560.9921875,56.5390989385637,20.3725548807805,25.566563,0,0,0,40,4449,149.77135,77551.03125,,,,,,,,,,,,,0,,,,0,,,,,,150.0076141,,,,
,27990665.355,150.0074768,82441.96484375,0.00269510061944421,2.55250734936719E-6,1,0.999253354069792,40.0298881530762,1.99142462106363,21.0299994796514,0.0305328714306252,0.0053611808259969,0.25,3.77445576585331E-6,0.00270833837960159,7.91347201274591E-6,150.0074768,150.0074768,82434.40625,82449.5234375,56.9627415959868,20.3728308573875,25.186911,0,0,0,40,4449,149.76425,82441.96484375,,,,,,,,,,,,,0,,,,0,,,,,,150.0074768,,,,
,27990761.195,150.0084839,87230.1015625,0.00259616877522473,3.20917149086007E-6,1,0.999253354069792,40.0298881530762,1.99136282946743,21.0299994796514,0.0294055088016857,0.00519708440569404,0.25,6.54816452019845E-6,0.00260891891555824,1.05362072691364E-5,150.0084839,150.0084839,87222.578125,87237.625,56.8400259184676,20.3738661121019,24.807261,0,0,0,40,4449,149.75555,87230.1015625,,,,,,,,,,,,,0,,,,-0.00245,,,,,,150.0084839,,,,
,27990870.975,150.0088348,88258.15625,0.00257243305782247,2.38298225766728E-6,1,0.999253354069792,40.0298881530762,1.99109159584653,21.0400000214577,0.0291346235275106,0.00513890613278229,0.25,5.60878708629222E-6,0.00258506850597266,9.55339077166993E-6,150.0088348,150.0088348,88253.09375,88263.21875,56.6047557341791,20.3720241196061,25.566563,0,0,0,40,4449,149.7483,88258.15625,,,,,,,,,,,,,0,,,,-0.00245,,,,,,150.0088348,,,,
,27990966.985,150.0027313,83459.70703125,0.00267387602253443,2.44261206763626E-6,1,0.999253354069792,40.0298881530762,1.9913322525774,21.0299994796514,0.0302857913918034,0.00534912583848542,0.25,6.42978867913958E-6,0.00268700626713392,1.05471346649956E-5,150.0027313,150.0027313,83454.6328125,83464.78125,56.709493955756,20.3742458950887,25.566563,0,0,0,40,4449,149.7452,83459.70703125,,,,,,,,,,,,,0,,,,0.0049,,,,,,150.0027313,,,,
,27991064.5,149.9961395,78583.8203125,0.00278319915944466,1.89469289817469E-6,1,0.999253354069792,40.0298881530762,1.99143375749802,21.0299994796514,0.0315207837179508,0.00559546646292625,0.25,9.09364124834651E-6,0.00279685996137508,1.34057467072111E-5,149.9961395,149.9961395,78571.390625,78596.25,56.4531198014483,20.3727899494419,25.566563,0,0,0,40,4449,149.75145,78583.8203125,,,,,,,,,,,,,0,,,,0,,,,,,149.9961395,,,,
,27991164.575,149.9926758,73580.23046875,0.00288595501631775,2.5749109486157E-6,1,0.999253354069792,40.0298881530762,1.9912006806131,21.0299994796514,0.0326955051653458,0.0057172263568441,0.25,1.9854196802493E-6,0.0029001286103641,6.43552613491793E-6,149.9926758,149.9926758,73567.8515625,73592.609375,56.8134505488137,20.3751359965477,25.186911,0,0,0,40,4449,149.76025,73580.23046875,,,,,,,,,,,,,0,,,,-0.0049,,,,,,149.9926758,,,,
,27991259.94,149.9928131,68814.5625,0.00298179610846456,2.61672057869677E-6,1,0.999253354069792,40.0298881530762,1.99133162752537,21.0299994796514,0.0337759602809875,0.00595012456166122,0.25,5.80180350059321E-6,0.00299643138697835,1.04332070360528E-5,149.9928131,149.9928131,68809.65625,68819.46875,56.6844818431406,20.3728969708359,24.807261,0,0,0,40,4449,149.767,68814.5625,,,,,,,,,,,,,0,,,,-0.00245,,,,,,149.9928131,,,,
,27991355.42,149.9907684,64041.421875,0.00307798666225517,2.38637549313759E-6,1,0.999253354069792,40.0298881530762,1.99153098180628,21.0299994796514,0.0348691170693276,0.00614109313212809,0.25,5.83608717534407E-6,0.00309309117496334,1.06315171065368E-5,149.9907684,149.9907684,64031.56640625,64051.27734375,56.9729027667368,20.3733865576768,25.566563,0,0,0,40,4449,149.7762,64041.421875,,,,,,,,,,,,,0,,,,0.0049,,,,,,149.9907684,,,,
,27991451.68,149.9909363,59230.7109375,0.00317948719955689,2.41729766579715E-6,1,0.999253354069792,40.0298881530762,1.99150905554394,21.0299994796514,0.0360162502287164,0.00635675635016228,0.25,7.17997091933805E-6,0.00319508459775712,1.21549673045397E-5,149.9909363,149.9909363,59223.15625,59238.265625,56.8681645451599,20.3739537499714,25.186911,0,0,0,40,4449,149.7872,59230.7109375,,,,,,,,,,,,,0,,,,0,,,,,,149.9909363,,,,
,27991548.355,149.990509,54398.2421875,0.00326830421275123,2.2570703000252E-6,1,0.999253354069792,40.0298881530762,1.99159741153482,21.0299994796514,0.0370166362955587,0.00657613778236487,0.25,1.10298982508421E-5,0.00328432815968323,1.61779644042413E-5,149.990509,149.990509,54390.859375,54405.625,56.7235632691022,20.3716762851851,25.186911,0,0,0,40,4449,149.7969,54398.2421875,,,,,,,,,,,,,0,,,,-0.00245,,,,,,149.990509,,,,
,27991645.525,149.9904633,49542.978515625,0.00335973980567272,1.54030017664175E-6,1,0.999253354069792,40.0298881530762,1.99151677512048,21.0299994796514,0.0380514587424487,0.00675559980802131,0.25,1.09471093671852E-5,0.00337620901233094,1.62539813379862E-5,149.9904633,149.9904633,49532.94921875,49553.0078125,56.8197035769676,20.3726603059259,25.566563,0,0,0,40,4449,149.8028,49542.978515625,,,,,,,,,,,,,0,,,,-0.00245,,,,,,149.9904633,,,,
,27991739.345,149.9897614,44853.01953125,0.00344319191717368,1.98606390209006E-6,1,0.999253354069792,40.0298881530762,1.99159234653668,21.0299994796514,0.0390020843324239,0.00690012594024701,0.25,9.12755862349927E-6,0.0034600700081673,1.45721428475541E-5,149.9897614,149.9897614,44845.625,44860.4140625,56.6407106460637,20.3727419241934,24.807261,0,0,0,40,4449,149.81155,44853.01953125,,,,,,,,,,,,,0,,,,0,,,,,,149.9897614,,,,
,27991836.195,149.9922028,40012.28515625,0.00352071707379934,1.69323270669432E-6,1,0.999253354069792,40.0298881530762,1.99143328536438,21.0299994796514,0.0398745980460056,0.00706959178224821,0.25,1.06092620287868E-5,0.00353796923341269,1.61995770588563E-5,149.9922028,149.9922028,40007.14453125,40017.42578125,56.8032893780637,20.374408463991,25.186911,0,0,0,40,4449,149.81865,40012.28515625,,,,,,,,,,,,,0,,,,-0.00245,,,,,,149.9922028,,,,
,27991935.385,149.9916382,35052.55078125,0.00360160283005387,1.530575883821E-6,1,0.999253354069792,40.0298881530762,1.99148476567177,21.0299994796514,0.0407873741832803,0.00725673397895819,0.25,1.30025287674457E-5,0.00361924421652014,1.87490447243583E-5,149.9916382,149.9916382,35040.15625,35064.9453125,56.8931766577752,20.370810836741,25.566563,0,0,0,40,4449,149.8284,35052.55078125,,,,,,,,,,,,,0,,,,0.00245,,,,,,149.9916382,,,,
,27992030.52,149.9883881,30299.953125,0.00366491424898427,1.32942358632391E-6,1,0.999253354069792,40.0298881530762,1.99128031957678,21.0299994796514,0.0415010681841295,0.00737891256934342,0.25,1.28039463891325E-5,0.00368286312668042,1.86657818643968E-5,149.9883881,149.9883881,30292.46875,30307.4375,56.7220000120637,20.3756607123127,24.807261,0,0,0,40,4449,149.8381,30299.953125,,,,,,,,,,,,,0,,,,0,,,,,,149.9883881,,,,
,27992125.915,149.9908447,25529.666015625,0.00372307984247817,1.10239236646421E-6,1,0.999253354069792,40.0298881530762,1.99072568070087,21.0299994796514,0.04214768553588,0.00749854150996199,0.25,1.33898707586393E-5,0.00374130908597189,1.93629837109676E-5,149.9908447,149.9908447,25525.08203125,25534.25,56.9416376259676,20.3745221982886,25.186911,0,0,0,40,4449,149.8461,25529.666015625,,,,,,,,,,,,,0,,,,0,,,,,,149.9908447,,,,
,27992220.7,149.9915161,20794.7353515625,0.0037684207453888,1.15429388069478E-6,1,0.999253354069792,40.0298881530762,1.9910604471859,21.0299994796514,0.0426663360476382,0.00759938214686822,0.25,1.42706190233913E-5,0.00378686725659552,2.03357970220652E-5,149.9915161,149.9915161,20787.125,20802.345703125,56.8595666314483,20.3702803224175,25.186911,0,0,0,40,4449,149.85585,20794.7353515625,,,,,,,,,,,,,0,,,,0,,,,,,149.9915161,,,,
,27992314.365,149.9901428,16112.5517578125,0.00379826400991775,1.14107016163871E-6,1,0.999253354069792,40.0298881530762,1.99140341260308,21.0299994796514,0.0430133763309178,0.00764866828547452,0.25,1.32963111662386E-5,0.00381685508007877,1.94194263901393E-5,149.9901428,149.9901428,16105.0234375,16120.080078125,56.8900501436983,20.3680048717515,25.186911,0,0,0,40,4449,149.86325,16112.5517578125,,,,,,,,,,,,,0,,,,0,,,,,,149.9901428,,,,
,27992411.455,149.992569,11262.630859375,0.00379909298961285,7.86611776368231E-7,1,0.999253354069792,40.0298881530762,1.99133073085534,21.0299994796514,0.0430221625605263,0.00764467527308805,0.25,1.28084896271379E-5,0.00381768523331913,1.89457655982839E-5,149.992569,149.992569,11252.7294921875,11272.5322265625,56.7900016932368,20.3645792694703,25.566563,0,0,0,40,4449,149.86545,11262.630859375,,,,,,,,,,,,,0,,,,-0.00245,,,,,,149.992569,,,,
,27992507.415,149.9926758,6464.955078125,0.00373411469032783,6.38687635711097E-7,1,0.999253354069792,40.0298881530762,1.99041598073152,21.0299994796514,0.0422655155993967,0.00752343035626469,0.25,1.37072832560793E-5,0.00375238420661592,1.97581302051863E-5,149.9926758,149.9926758,6455.0537109375,6474.8564453125,56.8423708040252,20.3634859871635,25.566563,0,0,0,40,4449,149.87705,6464.955078125,,,,,,,,,,,,,0,,,,-0.00245,,,,,,149.9926758,,,,
,27992602.05,149.9933929,1731.48052978516,0.00346918735481929,5.39744231582096E-7,1,0.999253354069792,40.0298881530762,1.99150372563454,21.0299994796514,0.0392878096368641,0.00699055063103843,0.25,1.24814820454163E-5,0.00348615864350108,1.81123766879748E-5,149.9933929,149.9933929,1726.55346679687,1736.40759277344,57.1315733561406,20.3721320478235,24.807261,0,0,0,40,4449,149.88015,1731.48052978516,,,,,,,,,,,,,0,,,,-0.00245,,,,,,149.9933929,,,,
,27992637.38,149.9936066,0.106566414237022,0.00227416900508862,6.28107492730839E-6,1,0.999253354069792,40.0298881530762,1.99134339139781,21.0299994796514,0.0257568443465536,0.00455723339516747,0.25,5.97802525132065E-6,0.00228529740357857,9.66015240026882E-6,149.9936066,149.9936066,0.106566414237022,0.106566414237022,56.9424192544868,20.3706949158446,25.186911,0,0,0,40,4417,149.88435,0.106566414237022,,,,,,,,,,,,,0,,,,-0.0049,,,,,,149.9936066,,,,