File: data/monolayers/nanoparticles/Ac_CoFe_C_2/vsm/data_dispersion/YF45_HYST_50K.DAT
[Header]
; VSM Data File (default extension .dat)
; Copyright (c) 2003-2013, Quantum Design, Inc. All rights reserved.
TITLE,
FILEOPENTIME,27958368.97,11/20/2018,10:13 pm
BYAPP,VSM,2.0,2.0
INFO,PPMS VSM Option Release 1.4.10 Build 1,APPNAME
INFO,Quantum Design Linear Motor Servo Controller,MOTOR_MODULE_NAME
INFO,3101-100 M1,MOTOR_HW_VERSION
INFO,MMC1014,MOTOR_SERIAL_NUMBER
INFO,SRV No X-over 01.03.11,MOTOR_SOFTWARE_VERSION
INFO,Quantum Design VSM Detection Module,VSM_MODULE_NAME
INFO,3101-150 F0,VSM_HW_VERSION
INFO,VSM707,VSM_SERIAL_NUMBER
INFO,VSM No X-over 01.02.05 May 20 2008 13:51:47,VSM_SOFTWARE_VERSION
INFO,704,PREAMP_SERIAL_NUMBER
INFO,822,COIL_SERIAL_NUMBER
INFO,0,MOMENT_UNITS
INFO,CoFe2O4,SAMPLE_MATERIAL
INFO,dispersion in ampulle,SAMPLE_COMMENT
INFO,,SAMPLE_MASS
INFO,,SAMPLE_VOLUME
INFO,,SAMPLE_MOLECULAR_WEIGHT
INFO,,SAMPLE_SIZE
INFO,,SAMPLE_SHAPE
DATATYPE,COMMENT,1
DATATYPE,TIME,2
STARTUPAXIS,X,2
STARTUPAXIS,Y1,5
[Data]
Comment,Time Stamp (sec),Temperature (K),Magnetic Field (Oe),Moment (emu),M. Std. Err. (emu),Transport Action,Averaging Time (sec),Frequency (Hz),Peak Amplitude (mm),Center Position (mm),Coil Signal' (mV),Coil Signal" (mV),Range (mV),M. Quad. Signal (emu),M. Raw' (emu),M. Raw" (emu),Min. Temperature (K),Max. Temperature (K),Min. Field (Oe),Max. Field (Oe),Mass (grams),Motor Lag (deg),Pressure (Torr),VSM Status (code),Motor Status (code),Measure Status (code),Measure Count,PPMS Status (code),System Temp. (K),System Field (Oe),Sample Position (deg),Bridge 1 Resistance (ohms),Bridge 1 Excitation (에),Bridge 2 Resistance (ohms),Bridge 2 Excitation (에),Bridge 3 Resistance (ohms),Bridge 3 Excitation (에),Bridge 4 Resistance (ohms),Bridge 4 Excitation (에),Signal 1 Vin (V),Signal 2 Vin (V),Digital Inputs (code),Drive 1 Iout (mA),Drive 1 Ipower (W),Drive 2 Iout (mA),Drive 2 Ipower (W),Pressure (),Map 20 (),Map 21 (),Map 22 (),Map 23 (),Map 24 (),Map 25 (),Map 26 (),Map 27 (),Map 28 (),Map 29 ()
,27958383.52,50.0146599,0.0456713177263737,,,2,,,,21.4800000545383,,,,,,,50.0146599,50.0146599,0.0456713177263737,0.0456713177263737,,,16.075285,,,,-99999999,4369,50.0183,0.0456713177263737,,,,,,,,,,,,,,,,,,,,,,,50.0146599,,,,
,27958537.915,50.004406,4746.20776367188,0.0035943656154353,3.81252147251555E-7,1,0.999253354069792,40.0298881530762,1.99097256265939,21.4699991047382,0.0404197771297922,0.00755333976852538,0.25,2.30182796492463E-5,0.00359288646012127,4.97578788775389E-5,50.004406,50.004406,4741.443359375,4750.97216796875,56.259275928679,20.3556089692673,16.454937,0,0,0,40,4449,50.0159,4746.20776367188,,,,,,,,,,,,,0,,,,0.0049,,,,,,50.004406,,,,
,27958639.265,50.002079,9809.40380859375,0.0036626295379289,6.05769437808105E-7,1,0.999253354069792,40.0298881530762,1.99091323459005,21.4699991047382,0.0411985747127555,0.00768755737032584,0.25,2.2501068128008E-5,0.00366204923988917,4.97433846394725E-5,50.002079,50.002079,9802.4560546875,9816.3515625,56.3890262628713,20.3613324747886,16.075285,0,0,0,40,4449,50.0133,9809.40380859375,,,,,,,,,,,,,0,,,,0.0049,,,,,,50.002079,,,,
,27958745.97,50.0015106,15141.9926757813,0.00371919613027626,6.19645013541346E-7,1,0.999253354069792,40.0298881530762,1.99087412417801,21.4699991047382,0.0418458489261946,0.00780911694930498,0.25,2.29744194319283E-5,0.00371966535462104,5.05930021735699E-5,50.0015106,50.0015106,15129.4814453125,15154.50390625,56.4609360866406,20.3643831725702,16.454937,0,0,0,40,4449,50.01245,15141.9926757813,,,,,,,,,,,,,0,,,,0,,,,,,50.0015106,,,,
,27958854.14,50.0016861,20548.92578125,0.00375591614096372,8.23567298953631E-7,1,0.999253354069792,40.0298881530762,1.99089865219851,21.4699991047382,0.0422693675520162,0.00790338312898022,0.25,2.46146957148643E-5,0.00375749395490804,5.24160452445532E-5,50.0016861,50.0016861,20536.533203125,20561.318359375,56.882233858506,20.3630709046799,16.454937,0,0,0,40,4449,50.01055,20548.92578125,,,,,,,,,,,,,0,,,,0,,,,,,50.0016861,,,,
,27958957.705,50.00174905,25726.681640625,0.00377625106760939,8.42105679324164E-7,1,0.999253354069792,40.0298881530762,1.99102767349031,21.4699991047382,0.0425169695407453,0.00792675929717012,0.25,2.29258947353272E-5,0.00377892984464938,5.07462150308272E-5,50.0016022,50.0018959,25714.052734375,25739.310546875,56.6071006197368,20.3662320515966,15.695635,0,0,0,40,4449,50.0098,25726.681640625,,,,,,,,,,,,,0,,,,0.00245,,,,,,50.00174905,,,,
,27959064.58,50.0019073,31068.8115234375,0.00378047629076336,7.92737890840764E-7,1,0.999253354069792,40.0298881530762,1.99090544390501,21.4699991047382,0.0425734890030346,0.00794257908394431,0.25,2.35966446755297E-5,0.00378425363926213,5.12715495995926E-5,50.0019073,50.0019073,31066.431640625,31071.19140625,57.0104209356599,20.362621442533,16.075285,0,0,0,40,4449,50.0055,31068.8115234375,,,,,,,,,,,,,0,,,,0,,,,,,50.0019073,,,,
,27959169.59,50.0023613,36313.953125,0.00377566994661235,9.9428434080927E-7,1,0.999253354069792,40.0298881530762,1.99091576113845,21.4699991047382,0.0425349170780045,0.00791593141531902,0.25,2.21262280390138E-5,0.00378051728970435,4.95497753203142E-5,50.0023613,50.0023613,36308.94921875,36318.95703125,56.5727089648906,20.3654424086322,15.695635,0,0,0,40,4449,50.0087,36313.953125,,,,,,,,,,,,,0,,,,0,,,,,,50.0023613,,,,
,27959266.38,50.0021973,41151.576171875,0.00376492936849892,7.92963710938636E-7,1,0.999253354069792,40.0298881530762,1.99093177302352,21.4699991047382,0.0424247635676459,0.0078960835766282,0.25,2.23586407969121E-5,0.00377070754725285,4.94772396544922E-5,50.0021973,50.0021973,41141.4609375,41161.69140625,56.8986480574099,20.3659739603161,16.075285,0,0,0,40,4449,50.00345,41151.576171875,,,,,,,,,,,,,0,,,,0,,,,,,50.0021973,,,,
,27959367.43,50.0021896,46204.2734375,0.00374478078228145,8.74909845019688E-7,1,0.999253354069792,40.0298881530762,1.99093528829033,21.4699991047382,0.0422079375623167,0.00785920265479791,0.25,2.28148454310903E-5,0.00375148139320274,4.95235031250703E-5,50.0021896,50.0021896,46194.296875,46214.25,56.6829185861022,20.3667689211102,16.075285,0,0,0,40,4449,50.00265,46204.2734375,,,,,,,,,,,,,0,,,,0.00245,,,,,,50.0021896,,,,
,27959463.795,50.0018425,51019.07421875,0.00371679110831928,9.66441149941257E-7,1,0.999253354069792,40.0298881530762,1.99087958114724,21.4699991047382,0.04190431939363,0.00778464551362634,0.25,2.13862303685034E-5,0.00372432718042958,4.76165198849096E-5,50.0018425,50.0018425,51016.484375,51021.6640625,56.8626931455252,20.3645499354452,16.075285,0,0,0,40,4449,50.0052,51019.07421875,,,,,,,,,,,,,0,,,,0,,,,,,50.0018425,,,,
,27959562.255,50.0019417,55941.66015625,0.00368265086636316,1.10427970959522E-6,1,0.999253354069792,40.0298881530762,1.990990464759,21.4699991047382,0.0415426270514827,0.00765148883341331,0.25,1.58447612654653E-5,0.00369100445571447,4.15227211221607E-5,50.0019417,50.0019417,55934.296875,55949.0234375,56.5562947659868,20.3684043275799,16.454937,0,0,0,40,4449,49.9999,55941.66015625,,,,,,,,,,,,,0,,,,0,,,,,,50.0019417,,,,
,27959661.755,49.999752,60914.44140625,0.00363900164502405,9.41804656903072E-7,1,0.999253354069792,40.0298881530762,1.99094991217245,21.4699991047382,0.0410563361815308,0.00757503953661215,0.25,1.71094489716729E-5,0.00364806407620602,4.21670695063669E-5,49.999752,49.999752,60911.87890625,60917.00390625,56.6563432164483,20.3669365430184,16.075285,0,0,0,40,4449,50.0022,60914.44140625,,,,,,,,,,,,,0,,,,-0.0049,,,,,,49.999752,,,,
,27959761.6,50.0031586,65904.89453125,0.00359688074639448,1.12868191448805E-6,1,0.999253354069792,40.0298881530762,1.99108238805043,21.4699991047382,0.0405836601321837,0.00753792105332462,0.25,2.15425864577455E-5,0.00360657969947428,4.59922570872257E-5,50.0031586,50.0031586,65899.9453125,65909.84375,56.739977468006,20.3654463146217,16.454937,0,0,0,40,4449,49.9991,65904.89453125,,,,,,,,,,,,,0,,,,-0.0049,,,,,,50.0031586,,,,
,27959861.255,49.9999542,70887.65625,0.00354516546115664,1.06345737464208E-6,1,0.999253354069792,40.0298881530762,1.99093162275625,21.4699991047382,0.0400047006643777,0.00743456361696439,0.25,2.19359355145773E-5,0.00355544798346638,4.56991359084026E-5,49.9999542,49.9999542,70877.5234375,70897.7890625,56.7407590965252,20.3693038289439,16.454937,0,0,0,40,4449,49.99795,70887.65625,,,,,,,,,,,,,0,,,,0.00245,,,,,,49.9999542,,,,
,27959961.435,50.0009995,75895.87109375,0.00348397742843663,1.22776276183666E-6,1,0.999253354069792,40.0298881530762,1.99108565577785,21.4699991047382,0.0393370409179606,0.00724007538298316,0.25,1.58774724680467E-5,0.00349480469377891,3.88703868064279E-5,50.0009995,50.0009995,75885.8125,75905.9296875,56.8501870892175,20.3649997597639,16.454937,0,0,0,40,4449,49.99675,75895.87109375,,,,,,,,,,,,,0,,,,0,,,,,,50.0009995,,,,
,27960060.26,50.0012436,80834.21875,0.00342959178234279,1.01457564650007E-6,1,0.999253354069792,40.0298881530762,1.99109475181138,21.4699991047382,0.0387214570745839,0.00717752761177893,0.25,2.03240346716211E-5,0.00344085380198076,4.26320403510441E-5,50.0012436,50.0012436,80829.1796875,80839.2578125,56.6711941583137,20.364167125729,16.075285,0,0,0,40,4449,50.0008,80834.21875,,,,,,,,,,,,,0,,,,0.00245,,,,,,50.0012436,,,,
,27960157.155,50.0024109,85677.09765625,0.00336791808054298,1.37575277637624E-6,1,0.999253354069792,40.0298881530762,1.99100347582579,21.4699991047382,0.0380316141499531,0.00704008115296335,0.25,1.94758058969258E-5,0.00337955883605046,4.10498432491557E-5,50.0024109,50.0024109,85667.1015625,85687.09375,56.3819916061983,20.3633801932071,16.075285,0,0,0,40,4449,49.9965,85677.09765625,,,,,,,,,,,,,0,,,,-0.0049,,,,,,50.0024109,,,,
,27960270.665,50.0014648,89718.60546875,0.00331739500170209,1.00070795529586E-6,1,0.999253354069792,40.0298881530762,1.99115640878505,21.4699991047382,0.0374744620661991,0.00690512378768156,0.25,1.67397324332502E-5,0.00332933220860618,3.77054680860892E-5,50.0014648,50.0014648,89713.8046875,89723.40625,56.8259566051214,20.3629633956689,16.834587,0,0,0,40,4449,49.9979,89718.60546875,,,,,,,,,,,,,0,,,,-0.0049,,,,,,50.0014648,,,,
,27960364.615,50,85026.71484375,0.00337776403629989,1.0872939678735E-6,1,0.999253354069792,40.0298881530762,1.99240478939058,21.4699991047382,0.0381705355409442,0.0070488395906573,0.25,1.80371994709112E-5,0.00338937409770631,3.97128793250373E-5,50,50,85024.234375,85029.1953125,56.6321127323521,20.3484145033674,16.834587,0,0,0,40,4449,50.0019,85026.71484375,,,,,,,,,,,,,0,,,,0.0049,,,,,,50,,,,
,27960461.83,49.9998245,80162.63671875,0.00343819883702774,1.20766910357364E-6,1,0.999253354069792,40.0298881530762,1.99222418580808,21.4699991047382,0.0388428372574099,0.00717613921671737,0.25,1.82821126819672E-5,0.00344941676739531,4.06867337039944E-5,49.9998245,49.9998245,80154.953125,80170.3203125,57.1151591572368,20.3492676388672,16.075285,0,0,0,40,4449,49.997,80162.63671875,,,,,,,,,,,,,0,,,,-0.00245,,,,,,49.9998245,,,,
,27960560.69,50.0004921,75221.36328125,0.00350071247766318,1.24282567308041E-6,1,0.999253354069792,40.0298881530762,1.99191211163275,21.4699991047382,0.0395278563532947,0.00734885458203624,0.25,2.2213979210019E-5,0.00351146023031105,4.53835631679354E-5,50.0004921,50.0004921,75216.109375,75226.6171875,56.912717370756,20.3536996610351,16.454937,0,0,0,40,4449,49.9978,75221.36328125,,,,,,,,,,,,,0,,,,-0.00245,,,,,,50.0004921,,,,
,27960659.635,50.0008316,70275.8828125,0.00355160722508438,8.64669011406477E-7,1,0.999253354069792,40.0298881530762,1.99142200446305,21.4699991047382,0.0400856993320991,0.00745036671921155,0.25,2.19968924892961E-5,0.00356182031485038,4.58454791799638E-5,50.0008316,50.0008316,70273.1328125,70278.6328125,56.7384142109675,20.3623990440822,16.454937,0,0,0,40,4449,49.9975,70275.8828125,,,,,,,,,,,,,0,,,,0.0049,,,,,,50.0008316,,,,
,27960759.4,50.0010223,65288.1640625,0.00360559459595294,9.02671563708924E-7,1,0.999253354069792,40.0298881530762,1.99140873242886,21.4699991047382,0.0406907228003104,0.00753784442706515,0.25,1.98405299526208E-5,0.00361523172644944,4.43877417929009E-5,50.0010223,50.0010223,65280.78515625,65295.54296875,56.997133250833,20.3614194605592,16.834587,0,0,0,40,4449,49.9932,65288.1640625,,,,,,,,,,,,,0,,,,0.0049,,,,,,50.0010223,,,,
,27960857.085,49.998724,60404.634765625,0.00365040333019892,1.05104408299923E-6,1,0.999253354069792,40.0298881530762,1.99133580116214,21.4699991047382,0.0411862764118508,0.00762993068112809,0.25,1.97776553762975E-5,0.00365939218298776,4.49545413459809E-5,49.9984932,49.9989548,60397.00390625,60412.265625,57.054973761256,20.3643513331047,16.834587,0,0,0,40,4449,49.99935,60404.634765625,,,,,,,,,,,,,0,,,,-0.0049,,,,,,49.998724,,,,
,27960955.38,49.998951,55494.490234375,0.00369004357263025,1.17778261262696E-6,1,0.999253354069792,40.0298881530762,1.99135405293642,21.4699991047382,0.0416248725674041,0.00770995146056287,0.25,1.9560202129863E-5,0.00369831070620326,4.53268837046639E-5,49.998951,49.998951,55489.56640625,55499.4140625,57.0026046504676,20.3637356688035,16.834587,0,0,0,40,4449,49.9976,55494.490234375,,,,,,,,,,,,,0,,,,0.0049,,,,,,49.998951,,,,
,27961055.96,49.9997215,50466.95703125,0.0037252717124037,8.96376167644821E-7,1,0.999253354069792,40.0298881530762,1.99124478723884,21.4699991047382,0.0420082875014302,0.00779161357779246,0.25,2.03413815170608E-5,0.00373273028578495,4.66632737450306E-5,49.9997215,49.9997215,50456.828125,50477.0859375,56.831428004756,20.3652703598736,16.075285,0,0,0,40,4449,50.00005,50466.95703125,,,,,,,,,,,,,0,,,,0.00245,,,,,,49.9997215,,,,
,27961153.8,50.0001526,45577.146484375,0.00375054592904738,8.81985246401007E-7,1,0.999253354069792,40.0298881530762,1.99125388531003,21.4699991047382,0.0422843479295913,0.00783719380045163,0.25,1.97064021582614E-5,0.00375716024503872,4.64855833841907E-5,50.0001526,50.0001526,45574.5,45579.79296875,56.8712910592368,20.3655024750408,16.454937,0,0,0,40,4449,50.00025,45577.146484375,,,,,,,,,,,,,0,,,,-0.00245,,,,,,50.0001526,,,,
,27961252.585,50.0004425,40639.283203125,0.003770431954975,8.72073370822847E-7,1,0.999253354069792,40.0298881530762,1.99129696772808,21.4699991047382,0.0424936273483721,0.00790536242838265,0.25,2.20591381089639E-5,0.00377611423838352,4.92442509963167E-5,50.0003014,50.0005836,40631.98046875,40646.5859375,56.9322580837368,20.3689992620965,16.075285,0,0,0,40,4449,49.9945,40639.283203125,,,,,,,,,,,,,0,,,,0.0049,,,,,,50.0004425,,,,
,27961352.725,50.0002022,35634.322265625,0.00378547789279846,7.9345624734238E-7,1,0.999253354069792,40.0298881530762,1.99121086438102,21.4699991047382,0.0426484598492258,0.0079446041574156,0.25,2.2796227616681E-5,0.00379018468997312,5.0324392561822E-5,50.0002022,50.0002022,35629.4921875,35639.15234375,56.8423708040252,20.3683476126217,16.075285,0,0,0,40,4449,49.99435,35634.322265625,,,,,,,,,,,,,0,,,,0,,,,,,50.0002022,,,,
,27961452.35,49.9989052,30654.3134765625,0.00379217275514171,8.26234719617875E-7,1,0.999253354069792,40.0298881530762,1.99132081351353,21.4699991047382,0.0427099704191246,0.00798350790288344,0.25,2.49786653459996E-5,0.0037958588583032,5.27573140200715E-5,49.9989052,49.9989052,30646.7109375,30661.916015625,56.811105663256,20.3680091154209,16.454937,0,0,0,40,4449,49.9966,30654.3134765625,,,,,,,,,,,,,0,,,,-0.0049,,,,,,49.9989052,,,,
,27961549.765,49.9997368,25786.630859375,0.00379212488960778,7.25541953311169E-7,1,0.999253354069792,40.0298881530762,1.99125817877971,21.4699991047382,0.042700819502016,0.00795874654092274,0.25,2.28258699738215E-5,0.00379481703210304,5.0762907589651E-5,49.999733,49.9997406,25779.23828125,25794.0234375,56.5500417378329,20.369501462476,16.454937,0,0,0,40,4449,49.99755,25786.630859375,,,,,,,,,,,,,0,,,,0.0049,,,,,,49.9997368,,,,
,27961647.43,49.999157,20904.15234375,0.00378683134086716,7.82543268008582E-7,1,0.999253354069792,40.0298881530762,1.99112295509667,21.4699991047382,0.0426245592610479,0.00795807526425592,0.25,2.3817736089696E-5,0.0037884866581918,5.18416173639308E-5,49.999157,49.999157,20896.62890625,20911.67578125,57.0135474497368,20.3699015261017,16.834587,0,0,0,40,4449,49.9937,20904.15234375,,,,,,,,,,,,,0,,,,-0.00245,,,,,,49.999157,,,,
,27961747.07,49.9993172,15924.5541992187,0.0037690311056861,6.85944272475758E-7,1,0.999253354069792,40.0298881530762,1.99107484852084,21.4699991047382,0.0424103982738502,0.00792522062791806,0.25,2.42166490326142E-5,0.00376964485413578,5.21962496231031E-5,49.9993172,49.9993172,15914.55078125,15934.5576171875,56.6360208749483,20.3681047306656,16.075285,0,0,0,40,4449,49.9977,15924.5541992187,,,,,,,,,,,,,0,,,,0,,,,,,49.9993172,,,,
,27961844.945,49.9988251,11034.791015625,0.00373856229878127,6.10144097435923E-7,1,0.999253354069792,40.0298881530762,1.99115954091142,21.4699991047382,0.0420593041250201,0.00785341005623284,0.25,2.34270858474111E-5,0.00373819390091424,5.12280473587729E-5,49.9988251,49.9988251,11027.5029296875,11042.0791015625,56.8478422036599,20.3693862298507,16.834587,0,0,0,40,4449,50.00155,11034.791015625,,,,,,,,,,,,,0,,,,0,,,,,,49.9988251,,,,
,27961943.065,50.0007477,6127.03686523437,0.00368608600281049,4.64527427614435E-7,1,0.999253354069792,40.0298881530762,1.99105378034434,21.4699991047382,0.0414546125410123,0.00775048918366303,0.25,2.39307862426909E-5,0.00368478474140495,5.13541974996233E-5,50.0007477,50.0007477,6114.67138671875,6139.40234375,56.8642564025637,20.3695172430282,16.454937,0,0,0,40,4449,49.99445,6127.03686523437,,,,,,,,,,,,,0,,,,0.0049,,,,,,50.0007477,,,,
,27962042.74,50.0006027,1145.873046875,0.00359036727371956,4.71371474477282E-7,1,0.999253354069792,40.0298881530762,1.99106403248214,21.4699991047382,0.0403707518505647,0.00754108136669776,0.25,2.27310350814589E-5,0.0035883252091496,4.94286755421027E-5,50.0006027,50.0006027,1140.88000488281,1150.86608886719,56.9658681100637,20.3695430966402,16.834587,0,0,0,40,4449,49.9991,1145.873046875,,,,,,,,,,,,,0,,,,0.0049,,,,,,50.0006027,,,,
,27962140.835,49.9999542,-3752.36828613281,0.00340451770985265,4.86464004907342E-7,1,0.999253354069792,40.0298881530762,1.99090370779083,21.4699991047382,0.0382806156249571,0.00715946487944407,0.25,2.23075377150551E-5,0.00340293753026602,4.76320192657176E-5,49.9999542,49.9999542,-3757.26293945313,-3747.4736328125,56.8556584888522,20.3714373763947,16.454937,0,0,0,40,4449,49.99665,-3752.36828613281,,,,,,,,,,,,,0,,,,0.00245,,,,,,49.9999542,,,,
,27962237.915,50.0002556,-8606.2587890625,0.00297173479492538,5.65953127501092E-7,1,0.999253354069792,40.0298881530762,1.99091974855666,21.4699991047382,0.0334219990045578,0.00625374690808336,0.25,1.97349837352038E-5,0.00297105433149228,4.18418625922754E-5,50.0002556,50.0002556,-8611.177734375,-8601.33984375,56.8806706014676,20.3720399566736,16.454937,0,0,0,40,4449,49.9979,-8606.2587890625,,,,,,,,,,,,,0,,,,-0.0049,,,,,,50.0002556,,,,
,27962337.625,50.0006142,-13592.0717773437,0.00185576111539572,8.82200412513662E-7,1,0.999253354069792,40.0298881530762,1.99106189180436,21.4699991047382,0.0208755696997295,0.00391986755342089,0.25,1.35261059173389E-5,0.00185581506148227,2.7316172910223E-5,50.0006142,50.0006142,-13594.599609375,-13589.5439453125,56.882233858506,20.3723927645025,16.454937,0,0,0,40,4449,49.9962,-13592.0717773437,,,,,,,,,,,,,0,,,,0,,,,,,50.0006142,,,,
,27962439.855,50.0000229,-18699.2431640625,-0.000202728398160438,1.12098469508479E-6,1,0.999253354069792,40.0298881530762,1.99130478904529,21.4699991047382,-0.00228507430096723,-0.000408031376086346,0.25,3.24137912346946E-7,-0.000202804238545916,-1.1778861136984E-6,50.0000229,50.0000229,-18701.8515625,-18696.634765625,57.0033862789868,20.3700389598993,16.834587,0,0,0,40,4449,49.9951,-18699.2431640625,,,,,,,,,,,,,0,,,,0,,,,,,50.0000229,,,,
,27962542.23,50.0002289,-23816.228515625,-0.0021726606644257,7.83123959423338E-7,1,0.999253354069792,40.0298881530762,1.99116874304247,21.4699991047382,-0.0244648491918018,-0.00453958541563705,0.25,-1.13033398174564E-5,-0.0021739804466975,-2.73398877625748E-5,50.0002289,50.0002289,-23823.544921875,-23808.912109375,57.0158923352945,20.3714888480324,16.454937,0,0,0,40,4449,49.9984,-23816.228515625,,,,,,,,,,,,,0,,,,0.00245,,,,,,50.0002289,,,,
,27962636.875,50.0025558,-28546.552734375,-0.00310211972378337,7.33161559558424E-7,1,0.999253354069792,40.0298881530762,1.99125232022874,21.4699991047382,-0.0349369025690056,-0.00650782515684385,0.25,-1.84186869296699E-5,-0.00310479009099929,-4.12015854241123E-5,50.0025558,50.0025558,-28556.66015625,-28536.4453125,56.8986480574099,20.3690572951932,16.454937,0,0,0,40,4449,49.9926,-28546.552734375,,,,,,,,,,,,,0,,,,0.00245,,,,,,50.0025558,,,,
,27962729.325,50.0023003,-33166.3828125,-0.00347673184788398,7.01892798871837E-7,1,0.999253354069792,40.0298881530762,1.99104459832367,21.4699991047382,-0.0391621801533869,-0.00729260740349744,0.25,-2.06155546415124E-5,-0.00348059702460464,-4.59931546226077E-5,50.0023003,50.0023003,-33168.69921875,-33164.06640625,56.8056342636214,20.3748463812387,16.454937,0,0,0,40,4449,49.9929,-33166.3828125,,,,,,,,,,,,,0,,,,0.00245,,,,,,50.0023003,,,,
,27962824.28,50.0015106,-37913.556640625,-0.0036294949623802,9.22937179745625E-7,1,0.999253354069792,40.0298881530762,1.99123507400565,21.4699991047382,-0.0408944234989684,-0.00762948814144489,0.25,-2.29573076218264E-5,-0.00363443341052845,-4.92552795821987E-5,50.0015106,50.0015106,-37921.14453125,-37905.96875,57.0510656186599,20.3738006269347,16.834587,0,0,0,40,4449,49.99005,-37913.556640625,,,,,,,,,,,,,0,,,,-0.0049,,,,,,50.0015106,,,,
,27962918.9,50.0022964,-42641.06640625,-0.00367657591286996,7.73690525261612E-7,1,0.999253354069792,40.0298881530762,1.99099892491956,21.4699991047382,-0.0414322951627064,-0.00771855113124992,0.25,-2.25254021219051E-5,-0.00368248527553082,-4.89369803850668E-5,50.0022964,50.0022964,-42653.65625,-42628.4765625,56.9416376259676,20.3745294438605,16.075285,0,0,0,40,4449,49.9919,-42641.06640625,,,,,,,,,,,,,0,,,,0.0049,,,,,,50.0022964,,,,
,27963015.03,50.0005379,-47445.87109375,-0.00367601730721946,9.26117347506589E-7,1,0.999253354069792,40.0298881530762,1.99106313705665,21.4699991047382,-0.0414395937906041,-0.00770611682041826,0.25,-2.1604369664271E-5,-0.00368281557882259,-4.7756314007748E-5,50.0005379,50.0005379,-47455.7109375,-47436.03125,57.146424298006,20.3739968826927,16.454937,0,0,0,40,4449,49.98715,-47445.87109375,,,,,,,,,,,,,0,,,,0,,,,,,50.0005379,,,,
,27963109.61,50.0013542,-52173.375,-0.00365341780577739,1.04972326255101E-6,1,0.999253354069792,40.0298881530762,1.99116342366983,21.4699991047382,-0.0411992804585703,-0.00764388883079745,0.25,-2.02499775740662E-5,-0.00366102177330688,-4.59668793031006E-5,50.0013542,50.0013542,-52178.3828125,-52168.3671875,56.9369478548522,20.374663278533,17.214239,0,0,0,40,4449,49.98945,-52173.375,,,,,,,,,,,,,0,,,,0,,,,,,50.0013542,,,,
,27963205.76,50.0016556,-56977.681640625,-0.0036149421269864,9.08394047997012E-7,1,0.999253354069792,40.0298881530762,1.99120738570526,21.4699991047382,-0.0407760559753945,-0.00756133140248409,0.25,-1.99924426338127E-5,-0.00362327716041384,-4.51463243187018E-5,50.0016556,50.0016556,-56985.16796875,-56970.1953125,57.2136443506599,20.3737342584594,16.454937,0,0,0,40,4449,49.99015,-56977.681640625,,,,,,,,,,,,,0,,,,0,,,,,,50.0016556,,,,
,27963302.415,50.0021629,-61810.3515625,-0.00357095228054588,1.04761894682006E-6,1,0.999253354069792,40.0298881530762,1.99129980710127,21.4699991047382,-0.0402910743653848,-0.00746686041286358,0.25,-1.96743502677781E-5,-0.00357995660092679,-4.4216658400401E-5,50.0021629,50.0021629,-61812.66015625,-61808.04296875,56.9353845978137,20.3757616369906,16.834587,0,0,0,40,4449,49.9856,-61810.3515625,,,,,,,,,,,,,0,,,,0,,,,,,50.0021629,,,,
,27963398.495,50.0033264,-66610.26953125,-0.00351984900601519,1.15009347264302E-6,1,0.999253354069792,40.0298881530762,1.99151636899158,21.4699991047382,-0.0397309953385944,-0.00733862207290269,0.25,-1.76209801975905E-5,-0.00352946259415552,-4.14932046226281E-5,50.0033264,50.0033264,-66615.265625,-66605.2734375,57.2800827747945,20.3716731979956,16.454937,0,0,0,40,4449,49.98855,-66610.26953125,,,,,,,,,,,,,0,,,,-0.0049,,,,,,50.0033264,,,,
,27963494.045,50.0020714,-71384.69140625,-0.00346156917232049,1.27844419803061E-6,1,0.999253354069792,40.0298881530762,1.99151076524838,21.4699991047382,-0.0390824865185901,-0.00720801220610486,0.25,-1.67245934078941E-5,-0.00347170146693083,-3.98840941155027E-5,50.0020714,50.0020714,-71397.046875,-71372.3359375,56.780622151006,20.370756254444,16.454937,0,0,0,40,4449,49.98095,-71384.69140625,,,,,,,,,,,,,0,,,,0.00245,,,,,,50.0020714,,,,
,27963589.575,50.0029297,-76159.46484375,-0.00340087571386432,1.13154849393659E-6,1,0.999253354069792,40.0298881530762,1.99171750012092,21.4699991047382,-0.0384106692520807,-0.00706982528400294,0.25,-1.5535697771821E-5,-0.00341147354403581,-3.79650973573444E-5,50.0029297,50.0029297,-76164.5078125,-76154.421875,56.8353361473522,20.370064257834,16.454937,0,0,0,40,4449,49.98495,-76159.46484375,,,,,,,,,,,,,0,,,,0.00245,,,,,,50.0029297,,,,
,27963685.405,50.0006599,-80949.47265625,-0.00333667305581129,1.01975553675145E-6,1,0.999253354069792,40.0298881530762,1.99171241537582,21.4699991047382,-0.0376921591302775,-0.00693741476209309,0.25,-1.55553009706708E-5,-0.00334766425521956,-3.72410380797444E-5,50.0006599,50.0006599,-80951.96875,-80946.9765625,57.1573670972753,20.3693156258028,16.454937,0,0,0,40,4449,49.983,-80949.47265625,,,,,,,,,,,,,0,,,,0,,,,,,50.0006599,,,,
,27963780.07,50.000679,-85679.421875,-0.00327035989343926,1.12147915480049E-6,1,0.999253354069792,40.0298881530762,1.99179950647418,21.4699991047382,-0.0369525819641816,-0.00679086873826891,0.25,-1.46746465057367E-5,-0.0032816861678998,-3.56115574826483E-5,50.000679,50.000679,-85689.234375,-85669.609375,57.0815491309099,20.3706149474886,16.454937,0,0,0,40,4449,49.9836,-85679.421875,,,,,,,,,,,,,0,,,,0,,,,,,50.000679,,,,
,27963892.515,49.9997673,-89743.10546875,-0.00320758208283427,1.29141861315267E-6,1,0.999253354069792,40.0298881530762,1.99184384114417,21.4699991047382,-0.0362523628440492,-0.00664263250090026,0.25,-1.29912984592606E-5,-0.00321914217912625,-3.32527678286832E-5,49.9997673,49.9997673,-89747.875,-89738.3359375,56.9979148793522,20.3693110901237,16.454937,0,0,0,40,4449,49.9836,-89743.10546875,,,,,,,,,,,,,0,,,,-0.00245,,,,,,49.9997673,,,,
,27963983.88,49.999794,-85183.0078125,-0.00326819142213789,1.35964347579532E-6,1,0.999253354069792,40.0298881530762,1.99188310569423,21.4699991047382,-0.0369305745672847,-0.00677732210030565,0.25,-1.38175954207485E-5,-0.00327945916186203,-3.47710170817752E-5,49.999794,49.999794,-85190.453125,-85175.5625,57.0627900464484,20.3681858086174,16.834587,0,0,0,40,4449,49.98335,-85183.0078125,,,,,,,,,,,,,0,,,,0,,,,,,49.999794,,,,
,27964077.765,49.9987488,-80490.703125,-0.00333144731623129,1.09368587666862E-6,1,0.999253354069792,40.0298881530762,1.99181524847935,21.4699991047382,-0.0376367526662928,-0.00691325869470197,0.25,-1.43029375749896E-5,-0.0033423711595422,-3.59829711750466E-5,49.9987488,49.9987488,-80498.0234375,-80483.3828125,57.0792042453522,20.3694701540602,16.834587,0,0,0,40,4449,49.97695,-80490.703125,,,,,,,,,,,,,0,,,,-0.0049,,,,,,49.9987488,,,,
,27964170.93,49.9993935,-75835.6875,-0.00338884483339945,1.23902244590392E-6,1,0.999253354069792,40.0298881530762,1.99181277489637,21.4699991047382,-0.0382733522247846,-0.00706005047152905,0.25,-1.67847093944158E-5,-0.0033993526306628,-3.91618135941703E-5,49.9993935,49.9993935,-75845.5546875,-75825.8203125,56.9361662263329,20.3714261103634,16.834587,0,0,0,40,4449,49.98015,-75835.6875,,,,,,,,,,,,,0,,,,0,,,,,,49.9993935,,,,
,27964262.895,50.0002289,-71237.72265625,-0.0034402396450139,1.14596482955375E-6,1,0.999253354069792,40.0298881530762,1.99169043422652,21.4699991047382,-0.0388488265416054,-0.00714170406474493,0.25,-1.46234892604268E-5,-0.00345030333699681,-3.76439010593628E-5,50.0002289,50.0002289,-71247.765625,-71227.6796875,56.9979148793522,20.3693071429462,16.834587,0,0,0,40,4449,49.9824,-71237.72265625,,,,,,,,,,,,,0,,,,0,,,,,,50.0002289,,,,
,27964357.515,49.9975967,-66508.55078125,-0.00349787668469403,7.80237583631621E-7,1,0.999253354069792,40.0298881530762,1.9918315237627,21.4699991047382,-0.03948838057083,-0.00729592513464968,0.25,-1.76840930651359E-5,-0.00350741166500986,-4.1415727686829E-5,49.9975967,49.9975967,-66510.8984375,-66506.203125,57.0385595623522,20.3691646474211,17.214239,0,0,0,40,4449,49.9833,-66508.55078125,,,,,,,,,,,,,0,,,,0,,,,,,49.9975967,,,,
,27964451.66,49.9997482,-61803.173828125,-0.00354722128605975,9.40816452280226E-7,1,0.999253354069792,40.0298881530762,1.99184943335465,21.4699991047382,-0.0400397404751862,-0.00738635118114576,0.25,-1.66359347513815E-5,-0.00355618367520788,-4.10085894946439E-5,49.9997482,49.9997482,-61813.20703125,-61793.140625,56.9322580837368,20.3689660569425,16.454937,0,0,0,40,4449,49.9838,-61803.173828125,,,,,,,,,,,,,0,,,,0,,,,,,49.9997482,,,,
,27964547.4,49.9991913,-57018.533203125,-0.0035923827334058,9.71453178904247E-7,1,0.999253354069792,40.0298881530762,1.99188098229107,21.4699991047382,-0.0405395347242309,-0.00748976074882914,0.25,-1.74946397101537E-5,-0.00360068564483636,-4.24847275595194E-5,49.9991913,49.9991913,-57026.05859375,-57011.0078125,57.1745629246983,20.3679030664188,16.834587,0,0,0,40,4449,49.9846,-57018.533203125,,,,,,,,,,,,,0,,,,0.0049,,,,,,49.9991913,,,,
,27964641.58,49.9988708,-52313.96484375,-0.00363371536275698,1.11479873221668E-6,1,0.999253354069792,40.0298881530762,1.9919275270876,21.4699991047382,-0.0409937866519682,-0.0075975835685924,0.25,-1.94477869711963E-5,-0.00364130566879177,-4.5016859060817E-5,49.9988708,49.9988708,-52318.9375,-52308.9921875,57.0291800201214,20.3683368842948,16.454937,0,0,0,40,4449,49.98655,-52313.96484375,,,,,,,,,,,,,0,,,,0.0049,,,,,,49.9988708,,,,
,27964734.06,49.9998703,-47691.70703125,-0.00366974915068392,8.60931862940411E-7,1,0.999253354069792,40.0298881530762,1.99195988004727,21.4699991047382,-0.0413903101723931,-0.00767934577319834,0.25,-2.00734146946227E-5,-0.00367659305433451,-4.6163619653339E-5,49.9998703,49.9998703,-47701.64453125,-47681.76953125,56.7767140084099,20.3677499895664,16.834587,0,0,0,40,4449,49.9901,-47691.70703125,,,,,,,,,,,,,0,,,,-0.0049,,,,,,49.9998703,,,,
,27964825.3,50.0015182,-43131.64453125,-0.00369595619369756,9.01778170970998E-7,1,0.999253354069792,40.0298881530762,1.99186026862175,21.4699991047382,-0.0416751116676385,-0.00772790688051153,0.25,-1.95926912558641E-5,-0.00370200440592921,-4.61151244915431E-5,50.0015182,50.0015182,-43134.24609375,-43129.04296875,57.3582456267176,20.3676085314608,16.834587,0,0,0,40,4449,49.9833,-43131.64453125,,,,,,,,,,,,,0,,,,-0.0049,,,,,,50.0015182,,,,
,27964920.82,49.9990616,-38356.740234375,-0.00372026567138202,7.24928571111549E-7,1,0.999253354069792,40.0298881530762,1.99176588550309,21.4699991047382,-0.0419351682919354,-0.0077867756960347,0.25,-2.03893278365938E-5,-0.00372543194317453,-4.73213841402344E-5,49.9990616,49.9990616,-38366.73046875,-38346.75,57.2589788047753,20.3698327754903,17.214239,0,0,0,40,4449,49.98395,-38356.740234375,,,,,,,,,,,,,0,,,,0.00245,,,,,,49.9990616,,,,
,27965012.87,49.9992485,-33756.99609375,-0.00373892576453764,8.03650690377304E-7,1,0.999253354069792,40.0298881530762,1.99189149443845,21.4699991047382,-0.0421374002265982,-0.0078267491311084,0.25,-2.04883980457515E-5,-0.00374320839936149,-4.77551817718825E-5,49.9992485,49.9992485,-33764.578125,-33749.4140625,57.044812590506,20.3689539539151,16.834587,0,0,0,40,4449,49.98715,-33756.99609375,,,,,,,,,,,,,0,,,,0.0049,,,,,,49.9992485,,,,
,27965108.89,49.9984589,-28957.396484375,-0.00375115027077019,7.02655704620143E-7,1,0.999253354069792,40.0298881530762,1.99182059979145,21.4699991047382,-0.0422598848357739,-0.00786607661764455,0.25,-2.17864258889774E-5,-0.00375446294154869,-4.93225052073632E-5,49.9984589,49.9984589,-28967.05078125,-28947.7421875,56.831428004756,20.3698354825678,16.834587,0,0,0,40,4449,49.98785,-28957.396484375,,,,,,,,,,,,,0,,,,-0.0049,,,,,,49.9984589,,,,
,27965200.345,49.9987984,-24387.4091796875,-0.00375638357314057,6.93419935480653E-7,1,0.999253354069792,40.0298881530762,1.99179468592735,21.4699991047382,-0.0423069228032435,-0.00787924950896198,0.25,-2.2044265214078E-5,-0.00375875420981889,-4.97582635214721E-5,49.9987984,49.9987984,-24389.919921875,-24384.8984375,56.9525804252368,20.3682119856919,17.214239,0,0,0,40,4449,49.9869,-24387.4091796875,,,,,,,,,,,,,0,,,,-0.0049,,,,,,49.9987984,,,,
,27965294.17,49.99882125,-19699.8017578125,-0.00375368968112107,6.49604144564882E-7,1,0.999253354069792,40.0298881530762,1.99181317326841,21.4699991047382,-0.0422651856668127,-0.00787639603254647,0.25,-2.23290179452798E-5,-0.00375508588371435,-5.01322066586147E-5,49.9986687,49.9989738,-19707.357421875,-19692.24609375,56.6547799594098,20.3671714188785,16.834587,0,0,0,40,4449,49.9897,-19699.8017578125,,,,,,,,,,,,,0,,,,0.00245,,,,,,49.99882125,,,,
,27965386.91,49.9983101,-15062.6577148438,-0.00374270026856484,5.64828692281423E-7,1,0.999253354069792,40.0298881530762,1.9917705576141,21.4699991047382,-0.0421276424512665,-0.00786349797868927,0.25,-2.32706451440422E-5,-0.00374313136689339,-5.10662187894141E-5,49.9983101,49.9983101,-15075.044921875,-15050.2705078125,57.1253203279868,20.3688647301405,16.834587,0,0,0,40,4449,49.9903,-15062.6577148438,,,,,,,,,,,,,0,,,,0,,,,,,49.9983101,,,,
,27965480.43,50.0003738,-10389.8012695312,-0.00371724563457148,5.03426644456583E-7,1,0.999253354069792,40.0298881530762,1.99191205771954,21.4699991047382,-0.0418334006126415,-0.00780878783301785,0.25,-2.3077919114168E-5,-0.0037167384122643,-5.07244139505522E-5,50.0003738,50.0003738,-10392.345703125,-10387.2568359375,56.7321611828137,20.3658082405879,16.454937,0,0,0,40,4449,49.98715,-10389.8012695312,,,,,,,,,,,,,0,,,,0,,,,,,50.0003738,,,,
,27965573.07,50.0000801,-5756.6259765625,-0.00367030933642742,4.06739179681942E-7,1,0.999253354069792,40.0298881530762,1.9919410482396,21.4699991047382,-0.0412966386207339,-0.00770570853840735,0.25,-2.25183927909265E-5,-0.00366895531358147,-4.98245421335267E-5,50.0000801,50.0000801,-5764.18017578125,-5749.07177734375,56.8908317722176,20.3656504789185,16.454937,0,0,0,40,4449,49.9925,-5756.6259765625,,,,,,,,,,,,,0,,,,-0.0049,,,,,,50.0000801,,,,
,27965664.385,50.0009079,-1192.53344726562,-0.00358662961188817,3.8991943425341E-7,1,0.999253354069792,40.0298881530762,1.99174214397541,21.4699991047382,-0.0403403904022415,-0.0075434432346115,0.25,-2.3397602264614E-5,-0.0035845803262028,-5.00669526043631E-5,50.0009079,50.0009079,-1195.08898925781,-1189.97790527344,56.7782772654483,20.3670868182584,16.834587,0,0,0,40,4449,49.9903,-1192.53344726562,,,,,,,,,,,,,0,,,,-0.0049,,,,,,50.0009079,,,,
,27965755.645,49.9999962,3364.951171875,-0.00342215052236553,4.53449051877104E-7,1,0.999253354069792,40.0298881530762,1.99172495116836,21.4699991047382,-0.0384924985220017,-0.00720375667933367,0.25,-2.28240930845882E-5,-0.0034204949493867,-4.8278307715083E-5,49.9999962,49.9999962,3357.24951171875,3372.65283203125,56.5906864208329,20.3666906409794,16.454937,0,0,0,40,4449,49.9917,3364.951171875,,,,,,,,,,,,,0,,,,-0.0049,,,,,,49.9999962,,,,
,27965849.745,50.0009079,8067.29125976563,-0.00304454594118751,5.40793890127274E-7,1,0.999253354069792,40.0298881530762,1.99194338650555,21.4699991047382,-0.0342557439467427,-0.00641482659183913,0.25,-2.06518245511769E-5,-0.00304375147717842,-4.33013167809594E-5,50.0009079,50.0009079,8057.3251953125,8077.25732421875,56.9338213407753,20.3632993364032,17.214239,0,0,0,40,4449,49.9868,8067.29125976563,,,,,,,,,,,,,0,,,,-0.00245,,,,,,50.0009079,,,,
,27965942.355,50.0001526,12698.1611328125,-0.00214905024982295,9.53498401257144E-7,1,0.999253354069792,40.0298881530762,1.9918185922934,21.4699991047382,-0.0241838779397181,-0.00453227731248891,0.25,-1.49017965704252E-5,-0.00214900943706059,-3.08761204435287E-5,50.0001526,50.0001526,12695.6171875,12700.705078125,56.5961578204675,20.3657290773932,16.834587,0,0,0,40,4449,49.9876,12698.1611328125,,,,,,,,,,,,,0,,,,0,,,,,,50.0001526,,,,
,27966033.87,50.0009804,17270.7578125,-0.000449554863564762,1.12076732043063E-6,1,0.999253354069792,40.0298881530762,1.99168717328268,21.4699991047382,-0.0050571199031092,-0.000963787092064323,0.25,-4.502019769307E-6,-0.000449648512479513,-7.83746781521939E-6,50.0009804,50.0009804,17258.125,17283.390625,56.9572701963522,20.3656747763556,16.834587,0,0,0,40,4449,49.99155,17270.7578125,,,,,,,,,,,,,0,,,,0,,,,,,50.0009804,,,,
,27966127.665,50.0008698,21958.1337890625,0.00153411827372758,1.07400581941794E-6,1,0.999253354069792,40.0298881530762,1.99187732353622,21.4699991047382,0.0172792102478017,0.00320340874735214,0.25,7.71604070380949E-6,0.00153489086542271,1.90585953712558E-5,50.0008698,50.0008698,21950.53515625,21965.732421875,56.8478422036599,20.3659249235298,16.454937,0,0,0,40,4449,49.9895,21958.1337890625,,,,,,,,,,,,,0,,,,-0.00245,,,,,,50.0008698,,,,
,27966220.36,50.0002937,26591.025390625,0.00277702225995831,1.06688571697726E-6,1,0.999253354069792,40.0298881530762,1.99195323595292,21.4699991047382,0.0312860501058161,0.00580848830003859,0.25,1.47838448447011E-5,0.0027791238624432,3.52242969654417E-5,50.0002937,50.0002937,26583.564453125,26598.486328125,57.0049495360253,20.3627717463675,16.454937,0,0,0,40,4449,49.9876,26591.025390625,,,,,,,,,,,,,0,,,,0.0049,,,,,,50.0002937,,,,
,27966314.635,50.0001183,31304.46875,0.00332419742285326,8.33310386267004E-7,1,0.999253354069792,40.0298881530762,1.99193422439769,21.4699991047382,0.0374570854144769,0.0069699976351661,0.25,1.92055077427147E-5,0.0033275589516901,4.35333811052722E-5,50.0001183,50.0001183,31296.69921875,31312.23828125,57.217552493256,20.3641560863876,16.834587,0,0,0,40,4449,49.98835,31304.46875,,,,,,,,,,,,,0,,,,-0.00245,,,,,,50.0001183,,,,
,27966407.16,50.0000153,35929.38671875,0.00353870227762035,9.4677779822847E-7,1,0.999253354069792,40.0298881530762,1.99187962229281,21.4699991047382,0.0398842723076614,0.00741391702492778,0.25,1.99686438385086E-5,0.00354315980638647,4.56901225149232E-5,50.0000153,50.0000153,35924.62890625,35934.14453125,57.3144744296407,20.3621220608099,16.834587,0,0,0,40,4449,49.98485,35929.38671875,,,,,,,,,,,,,0,,,,-0.00245,,,,,,50.0000153,,,,
,27966500.985,50.000679,40616.93359375,0.00361216371804866,9.39227768297372E-7,1,0.999253354069792,40.0298881530762,1.99180101819807,21.4699991047382,0.0407244997860697,0.0075485699733306,0.25,1.87590643726479E-5,0.00361761869887366,4.48008695311652E-5,50.000679,50.000679,40606.90625,40626.9609375,56.8626931455252,20.3646529731179,17.214239,0,0,0,40,4449,49.9923,40616.93359375,,,,,,,,,,,,,0,,,,0,,,,,,50.000679,,,,
,27966594.155,50.0003281,45275.123046875,0.00362388114021162,9.51413756050947E-7,1,0.999253354069792,40.0298881530762,1.99186170024864,21.4699991047382,0.0408680335491955,0.00757159246399348,0.25,1.87561930802623E-5,0.00363021020865342,4.46490978679894E-5,50.0003281,50.0003281,45270.01953125,45280.2265625,56.8806706014676,20.364389102118,16.834587,0,0,0,40,4449,49.9877,45275.123046875,,,,,,,,,,,,,0,,,,0,,,,,,50.0003281,,,,
,27966685.905,50.0008965,49862.98046875,0.00360621513592503,9.98414652991674E-7,1,0.999253354069792,40.0298881530762,1.99173304249531,21.4699991047382,0.0406764601763304,0.00753019272556053,0.25,1.84179894356408E-5,0.00361332828415358,4.39340554993431E-5,50.0008965,50.0008965,49852.93359375,49873.02734375,56.8040710065829,20.3639869936695,16.454937,0,0,0,40,4449,49.9842,49862.98046875,,,,,,,,,,,,,0,,,,0,,,,,,50.0008965,,,,
,27966781.11,49.9993801,54617.859375,0.00356911745150253,1.06345021521832E-6,1,0.999253354069792,40.0298881530762,1.99179986321735,21.4699991047382,0.0402706343666485,0.00744207081108198,0.25,1.74010637371271E-5,0.00357697079174534,4.23758562936807E-5,49.9991264,49.9996338,54610.58203125,54625.13671875,56.6500901882945,20.3614099182866,16.834587,0,0,0,40,4449,49.9847,54617.859375,,,,,,,,,,,,,0,,,,0,,,,,,49.9993801,,,,
,27966876.14,50.0001183,59368.138671875,0.00352460392354212,1.39011317954058E-6,1,0.999253354069792,40.0298881530762,1.99173945651249,21.4699991047382,0.0397805345353867,0.00732446537188753,0.25,1.51661892423207E-5,0.00353313921255802,3.9534220971727E-5,50.0001183,50.0001183,59358.22265625,59378.0546875,56.8486238321791,20.3628284654171,16.834587,0,0,0,40,4449,49.98545,59368.138671875,,,,,,,,,,,,,0,,,,0,,,,,,50.0001183,,,,
,27966969.395,50.0009995,64031.39453125,0.00347489640220149,1.08456259561219E-6,1,0.999253354069792,40.0298881530762,1.99178045211513,21.4699991047382,0.0392261292701859,0.00723457464065025,0.25,1.62981411231808E-5,0.00348401186031925,4.00315589989593E-5,50.0009995,50.0009995,64026.296875,64036.4921875,56.6876083572175,20.3630985428806,17.214239,0,0,0,40,4449,49.9836,64031.39453125,,,,,,,,,,,,,0,,,,-0.0049,,,,,,50.0009995,,,,
,27967063.875,50.0012283,68754.140625,0.00341762027068416,1.13008420301909E-6,1,0.999253354069792,40.0298881530762,1.99172368606258,21.4699991047382,0.0385879652990058,0.00710633419192569,0.25,1.54381831367206E-5,0.00342726764826462,3.84738738559395E-5,50.0012283,50.0012283,68743.921875,68764.359375,56.9815006804483,20.3633406888488,16.834587,0,0,0,40,4449,49.9836,68754.140625,,,,,,,,,,,,,0,,,,0.0049,,,,,,50.0012283,,,,
,27967156.595,50.00177575,73386.8125,0.00335714537269512,1.13895981291623E-6,1,0.999253354069792,40.0298881530762,1.99168017005701,21.4699991047382,0.0379102301937046,0.00698800927831933,0.25,1.6028647633079E-5,0.00336723984223343,3.83572943135184E-5,50.0016098,50.0019417,73376.796875,73396.828125,56.9299131981791,20.3636242668699,16.834587,0,0,0,40,4449,49.98065,73386.8125,,,,,,,,,,,,,0,,,,-0.00245,,,,,,50.00177575,,,,
,27967249.3,50.0027008,78020.15625,0.00329126362485555,1.0612833741872E-6,1,0.999253354069792,40.0298881530762,1.99167975773616,21.4699991047382,0.0371799174748224,0.0068125864755803,0.25,1.25294111726993E-5,0.0033017669140826,3.41058501970311E-5,50.0027008,50.0027008,78010.0390625,78030.2734375,56.5523866233906,20.3624983599519,16.454937,0,0,0,40,4449,49.98205,78020.15625,,,,,,,,,,,,,0,,,,0.0049,,,,,,50.0027008,,,,
,27967342.04,50.0022964,82658.73828125,0.00322344522250332,1.36200898499615E-6,1,0.999253354069792,40.0298881530762,1.99177456737432,21.4699991047382,0.0364163411033477,0.00670291753863719,0.25,1.5168026355208E-5,0.00323425972587679,3.60072158538488E-5,50.0022964,50.0022964,82648.7109375,82668.765625,56.7821854080445,20.361114855248,16.834587,0,0,0,40,4449,49.97875,82658.73828125,,,,,,,,,,,,,0,,,,0,,,,,,50.0022964,,,,
,27967431.65,50.0015106,87136.8984375,0.00315264375339505,1.07858488795327E-6,1,0.999253354069792,40.0298881530762,1.99171220025044,21.4699991047382,0.0356274948610625,0.00651999192576886,0.25,1.18991411350162E-5,0.00316373371951632,3.19806085244354E-5,50.0015106,50.0015106,87126.8984375,87146.8984375,56.8454973181022,20.3643229391589,16.454937,0,0,0,40,4449,49.9808,87136.8984375,,,,,,,,,,,,,0,,,,-0.00245,,,,,,50.0015106,,,,
,27967541.095,49.9995117,88425.35546875,0.00313011328402026,1.17546882680903E-6,1,0.999253354069792,40.0298881530762,1.99170507033312,21.4699991047382,0.0353774292488296,0.00645611798258626,0.25,1.03473604873239E-5,0.00314126949527022,3.0197234188832E-5,49.9995117,49.9995117,88418.015625,88432.6953125,56.4945461129675,20.3648051051514,16.454937,0,0,0,40,4449,49.97905,88425.35546875,,,,,,,,,,,,,0,,,,0.00245,,,,,,49.9995117,,,,
,27967630.235,49.999649,83969.41015625,0.00319791241958843,1.39060665243493E-6,1,0.999253354069792,40.0298881530762,1.99174855825606,21.4699991047382,0.0361348134478298,0.00661820663771578,0.25,1.23186585525432E-5,0.00320880767974274,3.28979516309603E-5,49.999649,49.999649,83964.421875,83974.3984375,56.6133536478906,20.3620161833045,16.454937,0,0,0,40,4449,49.9783,83969.41015625,,,,,,,,,,,,,0,,,,-0.00245,,,,,,49.999649,,,,
,27967722.45,49.999649,79357.87890625,0.00326159497052737,1.2124866222043E-6,1,0.999253354069792,40.0298881530762,1.99172332395185,21.4699991047382,0.0368410609640139,0.00678664522680307,0.25,1.5600576632771E-5,0.0032721434039103,3.69060062813123E-5,49.999649,49.999649,79350.421875,79365.3359375,56.485948199256,20.3652539837951,16.454937,0,0,0,40,4449,49.977,79357.87890625,,,,,,,,,,,,,0,,,,0.00245,,,,,,49.999649,,,,
,27967817.07,49.9990997,74629.2265625,0.00332766020043946,1.11960949589165E-6,1,0.999253354069792,40.0298881530762,1.9917034079088,21.4699991047382,0.037579353585863,0.0069278940113491,0.25,1.60462096540321E-5,0.00333782674003493,3.80974452268639E-5,49.9990997,49.9990997,74621.71875,74636.734375,56.9416376259676,20.3633852862249,16.454937,0,0,0,40,4449,49.9812,74629.2265625,,,,,,,,,,,,,0,,,,0,,,,,,49.9990997,,,,
,27967910.105,49.9992638,69978.80078125,0.00338713271905617,1.35803406421562E-6,1,0.999253354069792,40.0298881530762,1.99174581307462,21.4699991047382,0.0382460228487696,0.00704333235235295,0.25,1.5378472721571E-5,0.00339686086806908,3.81299603708544E-5,49.9992638,49.9992638,69973.7578125,69983.84375,56.8439340610637,20.3628776472667,16.454937,0,0,0,40,4449,49.9791,69978.80078125,,,,,,,,,,,,,0,,,,-0.00245,,,,,,49.9992638,,,,
,27968004.745,50.0009041,65248.396484375,0.0034461141891103,1.03123990440546E-6,1,0.999253354069792,40.0298881530762,1.99186864658364,21.4699991047382,0.0389031974690538,0.00718459685719683,0.25,1.7063341634902E-5,0.00345532575141943,4.05250348682123E-5,50.0009041,50.0009041,65241.11328125,65255.6796875,56.7517018957945,20.3635084266319,16.454937,0,0,0,40,4449,49.9809,65248.396484375,,,,,,,,,,,,,0,,,,0.0049,,,,,,50.0009041,,,,
,27968096.21,49.9991341,60674.740234375,0.00349760128317656,1.0604239997725E-6,1,0.999253354069792,40.0298881530762,1.99198567593382,21.4699991047382,0.0394780691493332,0.00729535594728439,0.25,1.74107107041574E-5,0.00350625656119007,4.15168408234726E-5,49.9991341,49.9991341,60667.3125,60682.16796875,56.4335790884675,20.359757391061,16.834587,0,0,0,40,4449,49.9821,60674.740234375,,,,,,,,,,,,,0,,,,-0.0049,,,,,,49.9991341,,,,
,27968192.22,49.9993401,55876.880859375,0.00354690375898735,1.02502209330016E-6,1,0.999253354069792,40.0298881530762,1.99195378993118,21.4699991047382,0.040023293981595,0.00740759157526279,0.25,1.83322218841706E-5,0.0035549057283053,4.30790312979639E-5,49.9993401,49.9993401,55869.4375,55884.32421875,56.9385111118906,20.3607944794712,16.454937,0,0,0,40,4449,49.98065,55876.880859375,,,,,,,,,,,,,0,,,,0,,,,,,49.9993401,,,,
,27968285.75,49.9999428,51201.759765625,0.00359178275054388,9.43498611229766E-7,1,0.999253354069792,40.0298881530762,1.99180520697613,21.4699991047382,0.0405181413278929,0.0074980633060539,0.25,1.81809300988176E-5,0.00359909826567561,4.35187365571746E-5,49.9999428,49.9999428,51186.84765625,51216.671875,56.7212183835445,20.3617058365688,16.454937,0,0,0,40,4449,49.9809,51201.759765625,,,,,,,,,,,,,0,,,,0,,,,,,49.9999428,,,,
,27968380.165,49.9987411,46484.1796875,0.00363045315252485,1.18388051488322E-6,1,0.999253354069792,40.0298881530762,1.99185003680644,21.4699991047382,0.0409456024233337,0.0075787330791548,0.25,1.82364656516386E-5,0.00363701339346789,4.41117194874291E-5,49.9987411,49.9987411,46479.16796875,46489.19140625,56.8236117195637,20.3612875948957,16.075285,0,0,0,40,4449,49.983,46484.1796875,,,,,,,,,,,,,0,,,,-0.00245,,,,,,49.9987411,,,,
,27968475.895,49.9985657,41698.857421875,0.00366502515336882,7.43064762297986E-7,1,0.999253354069792,40.0298881530762,1.99190925950066,21.4699991047382,0.0413261671722156,0.00765228468766238,0.25,1.84167968887496E-5,0.00367075926976459,4.4788294936047E-5,49.9985657,49.9985657,41686.14453125,41711.5703125,56.6297678467945,20.3614527143542,17.214239,0,0,0,40,4449,49.9801,41698.857421875,,,,,,,,,,,,,0,,,,0,,,,,,49.9985657,,,,
,27968568.29,49.9992256,37081.142578125,0.00369116898856578,8.49544309370676E-7,1,0.999253354069792,40.0298881530762,1.99190860412955,21.4699991047382,0.0416072172039326,0.00772620364412217,0.25,2.01975465686681E-5,0.00369604941910551,4.69759770824163E-5,49.9992256,49.9992256,37078.50390625,37083.78125,56.8283014906791,20.3624563830416,16.834587,0,0,0,40,4449,49.9863,37081.142578125,,,,,,,,,,,,,0,,,,0,,,,,,49.9992256,,,,
,27968659.335,49.9995117,32531.14453125,0.00371229065641238,9.21914780856884E-7,1,0.999253354069792,40.0298881530762,1.99200119540331,21.4699991047382,0.0418338493629101,0.00778632507856392,0.25,2.16591727668129E-5,0.00371628459428285,4.8782217443598E-5,49.9995117,49.9995117,32526.162109375,32536.126953125,56.892395029256,20.3600141559945,16.834587,0,0,0,40,4449,49.9829,32531.14453125,,,,,,,,,,,,,0,,,,0.00245,,,,,,49.9995117,,,,
,27968749.37,49.9999428,28030.9775390625,0.00372662151454484,7.42012401899975E-7,1,0.999253354069792,40.0298881530762,1.99194015769468,21.4699991047382,0.0419851047013938,0.00780727818547422,0.25,2.09536392077487E-5,0.00372972344583143,4.83403682507902E-5,49.9999428,49.9999428,28023.494140625,28038.4609375,57.0862389020253,20.362812616657,16.834587,0,0,0,40,4449,49.9824,28030.9775390625,,,,,,,,,,,,,0,,,,0,,,,,,49.9999428,,,,
,27968842.945,50.0000153,23353.6337890625,0.00373492584589271,6.57649105345352E-7,1,0.999253354069792,40.0298881530762,1.99186942806488,21.4699991047382,0.0420655801367585,0.00782726554510243,0.25,2.12847460058464E-5,0.0037370737335739,4.88669943854919E-5,50.0000153,50.0000153,23345.853515625,23361.4140625,56.9627415959868,20.3656087163993,16.834587,0,0,0,40,4449,49.9865,23353.6337890625,,,,,,,,,,,,,0,,,,0.0049,,,,,,50.0000153,,,,
,27968936.905,49.9987869,18658.7275390625,0.00373489476679664,6.66172677916453E-7,1,0.999253354069792,40.0298881530762,1.99196466029864,21.4699991047382,0.042053283333985,0.00784196789592679,0.25,2.2629028178401E-5,0.00373606314278235,5.03128692995099E-5,49.9987869,49.9987869,18648.79296875,18668.662109375,56.7563916669098,20.3670661889058,16.834587,0,0,0,40,4449,49.9868,18658.7275390625,,,,,,,,,,,,,0,,,,0.0049,,,,,,49.9987869,,,,
,27969029.155,49.9997139,14046.0849609375,0.00372584710152698,5.20143962942897E-7,1,0.999253354069792,40.0298881530762,1.99182557581081,21.4699991047382,0.0419380448859826,0.00782019670878226,0.25,2.24719059713909E-5,0.00372606942682201,5.01540793714298E-5,49.9997139,49.9997139,14040.3857421875,14051.7841796875,56.4077853473329,20.366634787066,17.214239,0,0,0,40,4449,49.9848,14046.0849609375,,,,,,,,,,,,,0,,,,-0.00245,,,,,,49.9997139,,,,
,27969122.305,49.99965095,9391.02294921875,0.0037013279236187,5.67246206595218E-7,1,0.999253354069792,40.0298881530762,1.99186943619691,21.4699991047382,0.0416507656073784,0.00777728265258122,0.25,2.31941815891179E-5,0.00370062600291036,5.07266014774846E-5,49.9996414,49.9996605,9383.611328125,9398.4345703125,56.7735874943329,20.3660822987922,16.834587,0,0,0,40,4449,49.9851,9391.02294921875,,,,,,,,,,,,,0,,,,0.00245,,,,,,49.99965095,,,,
,27969216.22,50.0001907,4698.078125,0.00365110079603565,4.50160644453144E-7,1,0.999253354069792,40.0298881530762,1.99187794701289,21.4699991047382,0.0410763131946372,0.00766943052404745,0.25,2.28148419453083E-5,0.00364956291385229,4.99762524088103E-5,50.0001907,50.0001907,4690.61962890625,4705.53662109375,56.6508718168137,20.3686432494038,16.454937,0,0,0,40,4449,49.98855,4698.078125,,,,,,,,,,,,,0,,,,0,,,,,,50.0001907,,,,
,27969308.415,50.0001736,89.2388381958008,0.00355610200900323,4.20341096190087E-7,1,0.999253354069792,40.0298881530762,1.99188068966234,21.4699991047382,0.0399993322975896,0.00747376962615152,0.25,2.26944133452423E-5,0.0035539508315787,4.91327373574366E-5,50.0000916,50.0002556,81.6846084594727,96.7930679321289,57.2894623170253,20.366560161655,16.834587,0,0,0,40,4449,49.9895,89.2388381958008,,,,,,,,,,,,,0,,,,0.00245,,,,,,50.0001736,,,,
,27969310.86,50.0002556,-0.418653756380081,0.00355369887191619,4.23375896087476E-7,1,0.999253354069792,40.0298881530762,1.99182450831731,21.4699991047382,0.0399716433136697,0.00746558385729613,0.25,2.24205240967735E-5,0.00355154155282341,4.88407706639751E-5,50.0002556,50.0002556,-0.42626565694809,-0.411041855812073,56.7188734979868,20.3660298520176,17.214239,0,0,0,40,4417,49.9862,-0.418653756380081,,,,,,,,,,,,,0,,,,0,,,,,,50.0002556,,,,