File: data/monolayers/nanoparticles/Ac_CoFe_C_2/vsm/data_dispersion/YF45_HYST_20K.DAT
[Header]
; VSM Data File (default extension .dat)
; Copyright (c) 2003-2013, Quantum Design, Inc. All rights reserved.
TITLE,
FILEOPENTIME,27946802.48,11/20/2018,7:00 pm
BYAPP,VSM,2.0,2.0
INFO,PPMS VSM Option Release 1.4.10 Build 1,APPNAME
INFO,Quantum Design Linear Motor Servo Controller,MOTOR_MODULE_NAME
INFO,3101-100 M1,MOTOR_HW_VERSION
INFO,MMC1014,MOTOR_SERIAL_NUMBER
INFO,SRV No X-over 01.03.11,MOTOR_SOFTWARE_VERSION
INFO,Quantum Design VSM Detection Module,VSM_MODULE_NAME
INFO,3101-150 F0,VSM_HW_VERSION
INFO,VSM707,VSM_SERIAL_NUMBER
INFO,VSM No X-over 01.02.05 May 20 2008 13:51:47,VSM_SOFTWARE_VERSION
INFO,704,PREAMP_SERIAL_NUMBER
INFO,822,COIL_SERIAL_NUMBER
INFO,0,MOMENT_UNITS
INFO,CoFe2O4,SAMPLE_MATERIAL
INFO,dispersion in ampulle,SAMPLE_COMMENT
INFO,,SAMPLE_MASS
INFO,,SAMPLE_VOLUME
INFO,,SAMPLE_MOLECULAR_WEIGHT
INFO,,SAMPLE_SIZE
INFO,,SAMPLE_SHAPE
DATATYPE,COMMENT,1
DATATYPE,TIME,2
STARTUPAXIS,X,2
STARTUPAXIS,Y1,5
[Data]
Comment,Time Stamp (sec),Temperature (K),Magnetic Field (Oe),Moment (emu),M. Std. Err. (emu),Transport Action,Averaging Time (sec),Frequency (Hz),Peak Amplitude (mm),Center Position (mm),Coil Signal' (mV),Coil Signal" (mV),Range (mV),M. Quad. Signal (emu),M. Raw' (emu),M. Raw" (emu),Min. Temperature (K),Max. Temperature (K),Min. Field (Oe),Max. Field (Oe),Mass (grams),Motor Lag (deg),Pressure (Torr),VSM Status (code),Motor Status (code),Measure Status (code),Measure Count,PPMS Status (code),System Temp. (K),System Field (Oe),Sample Position (deg),Bridge 1 Resistance (ohms),Bridge 1 Excitation (에),Bridge 2 Resistance (ohms),Bridge 2 Excitation (에),Bridge 3 Resistance (ohms),Bridge 3 Excitation (에),Bridge 4 Resistance (ohms),Bridge 4 Excitation (에),Signal 1 Vin (V),Signal 2 Vin (V),Digital Inputs (code),Drive 1 Iout (mA),Drive 1 Ipower (W),Drive 2 Iout (mA),Drive 2 Ipower (W),Pressure (),Map 20 (),Map 21 (),Map 22 (),Map 23 (),Map 24 (),Map 25 (),Map 26 (),Map 27 (),Map 28 (),Map 29 ()
,27946817.19,20.0032063,-0.152237743139267,,,2,,,,21.5000002068281,,,,,,,20.0032063,20.0032063,-0.152237743139267,-0.152237743139267,,,12.278775,,,,-99999999,4369,20.0099,-0.152237743139267,,,,,,,,,,,,,,,,,,,,,,,20.0032063,,,,
,27946970.37,20.0201893,4648.18115234375,0.00380181194789486,5.19340359883318E-7,1,0.999253354069792,40.0298881530762,1.99052616857383,21.5000007301569,0.0425348199056352,0.00788608435041657,0.25,2.76512770214101E-5,0.00378077176938089,4.69897323212108E-5,20.0201893,20.0201893,4640.79541015625,4655.56689453125,56.4226362891983,20.3693874792547,11.899124,0,0,0,40,4449,20.00035,4648.18115234375,,,,,,,,,,,,,0,,,,0,,,,,,20.0201893,,,,
,27947072.37,20.0032063,9744.703125,0.00398485748776055,5.66019108441274E-7,1,0.999253354069792,40.0298881530762,1.99035495135386,21.4900001883507,0.0445956001892843,0.0082701054969848,0.25,2.76791984001762E-5,0.00396430186302614,4.94380415222117E-5,20.0032063,20.0032063,9732.5380859375,9756.8681640625,56.4851665707367,20.3757804808221,11.899124,0,0,0,40,4449,19.98325,9744.703125,,,,,,,,,,,,,0,,,,0,,,,,,20.0032063,,,,
,27947177.795,20.0051136,15017.1625976562,0.00416303229641734,5.75226560495251E-7,1,0.999253354069792,40.0298881530762,1.99043674216789,21.4900001883507,0.0466119770397641,0.00864729258865633,0.25,2.76173427565536E-5,0.00414343243091204,5.19518560659842E-5,20.0051136,20.0051136,15010.1884765625,15024.13671875,56.6610329875637,20.3795073741226,11.899124,0,0,0,40,4449,19.9829,15017.1625976562,,,,,,,,,,,,,0,,,,0,,,,,,20.0051136,,,,
,27947281.4,20.0037975,20193.939453125,0.00432776779679075,6.6938899400576E-7,1,0.999253354069792,40.0298881530762,1.99044451188262,21.4900001883507,0.0484800103651085,0.00899566831959805,0.25,2.73682291137174E-5,0.00430949673270403,5.41908553364852E-5,20.0037975,20.0037975,20186.408203125,20201.470703125,56.7884384361983,20.3794590647038,11.899124,0,0,0,40,4449,19.98025,20193.939453125,,,,,,,,,,,,,0,,,,0,,,,,,20.0037975,,,,
,27947385.13,20.0030384,25379.185546875,0.00448181748104185,5.34775346509376E-7,1,0.999253354069792,40.0298881530762,1.99056345375199,21.4900001883507,0.0502355893919498,0.00931619737883342,0.25,2.65094145380915E-5,0.00446522162976093,5.56999270080749E-5,20.0030384,20.0030384,25369.29296875,25389.078125,56.8197035769676,20.3795507401446,12.658426,0,0,0,40,4449,19.9787,25379.185546875,,,,,,,,,,,,,0,,,,0,,,,,,20.0030384,,,,
,27947491.6,20.0039082,30701.734375,0.00462605615034692,7.30299334349233E-7,1,0.999253354069792,40.0298881530762,1.99065831522939,21.4900001883507,0.0518817490745959,0.00963119409649089,0.25,2.69539341935603E-5,0.00461147614313252,5.8359335566241E-5,20.0039082,20.0039082,30696.873046875,30706.595703125,56.800944492506,20.3766532870689,12.278775,0,0,0,40,4449,19.9752,30701.734375,,,,,,,,,,,,,0,,,,0.00245,,,,,,20.0039082,,,,
,27947597.29,20.00245475,35981.6484375,0.00475856613519941,7.91554906086174E-7,1,0.999253354069792,40.0298881530762,1.99057785222832,21.4900001883507,0.0533960529289958,0.00991010733875885,0.25,2.65037362126817E-5,0.00474622457909807,5.98756933824253E-5,20.0020618,20.0028477,35969.38671875,35993.91015625,56.7016776705637,20.3787745182939,12.278775,0,0,0,40,4449,19.97245,35981.6484375,,,,,,,,,,,,,0,,,,0.0049,,,,,,20.00245475,,,,
,27947701.755,20.0026569,41206.22265625,0.00487777274650525,8.54395060912724E-7,1,0.999253354069792,40.0298881530762,1.99059087949584,21.4900001883507,0.0547634520349291,0.0101689795506172,0.25,2.67981893331342E-5,0.00486781403954734,6.18468678683693E-5,20.0026569,20.0026569,41201.265625,41211.1796875,56.2975757261213,20.377714656902,12.658426,0,0,0,40,4449,19.96965,41206.22265625,,,,,,,,,,,,,0,,,,0,,,,,,20.0026569,,,,
,27947800.46,20.0015163,46136.59375,0.00497925935279629,9.39874342034738E-7,1,0.999253354069792,40.0298881530762,1.99033139760437,21.4900001883507,0.055919181722067,0.0104154741383783,0.25,2.9537080952107E-5,0.00497163732640676,6.59067479134305E-5,20.0015163,20.0015163,46124.3125,46148.875,57.0424677049483,20.3768230398555,12.658426,0,0,0,40,4449,19.96835,46136.59375,,,,,,,,,,,,,0,,,,0.0049,,,,,,20.0015163,,,,
,27947894.985,20.0013485,50861.919921875,0.00506446246416547,9.15402330615229E-7,1,0.999253354069792,40.0298881530762,1.99029753748636,21.4900001883507,0.0569032436633136,0.0105951262370094,0.25,2.93662058484353E-5,0.00505915595068967,6.67542214873583E-5,20.0013485,20.0013485,50851.8125,50872.02734375,56.8681645451599,20.3770569684846,12.658426,0,0,0,40,4449,19.96765,50861.919921875,,,,,,,,,,,,,0,,,,0,,,,,,20.0013485,,,,
,27947991.595,20.001606,55689.541015625,0.00514389932092151,7.61914705085532E-7,1,0.999253354069792,40.0298881530762,1.99037406682902,21.4900001883507,0.0578292033271336,0.0107466185293618,0.25,2.78256523085529E-5,0.00514098151027126,6.60362469783507E-5,20.001606,20.001606,55679.52734375,55699.5546875,56.8290831191983,20.3765425197187,12.658426,0,0,0,40,4449,19.96645,55689.541015625,,,,,,,,,,,,,0,,,,0,,,,,,20.001606,,,,
,27948085.29,20.0010033,60374.70703125,0.00520887302763715,8.61564092851414E-7,1,0.999253354069792,40.0298881530762,1.99042165645498,21.4900001883507,0.0585874464304276,0.0108858788250101,0.25,2.79892718810815E-5,0.00520824548186164,6.67587181150049E-5,20.0010033,20.0010033,60367.15625,60382.2578125,56.7931282073137,20.3756676389758,12.278775,0,0,0,40,4449,19.96545,60374.70703125,,,,,,,,,,,,,0,,,,0,,,,,,20.0010033,,,,
,27948181.205,20.001667,65167.98046875,0.00527150388034775,7.99596765527442E-7,1,0.999253354069792,40.0298881530762,1.99055553420502,21.4900001883507,0.0593226438026996,0.0110166511110714,0.25,2.79159212197701E-5,0.00527317694432424,6.70898459943068E-5,20.001667,20.001667,65160.67578125,65175.28515625,56.6524350738522,20.3759512555819,12.278775,0,0,0,40,4449,19.9651,65167.98046875,,,,,,,,,,,,,0,,,,0.00245,,,,,,20.001667,,,,
,27948276.325,20.0031796,69923.49609375,0.0053195309507626,1.04283348919614E-6,1,0.999253354069792,40.0298881530762,1.9904962622365,21.4900001883507,0.0598885868871884,0.0111075211172585,0.25,2.71610678322012E-5,0.00532342334520926,6.6506176258833E-5,20.0031796,20.0031796,69918.7109375,69928.28125,56.7790588939676,20.3788672546006,12.278775,0,0,0,40,4449,19.96225,69923.49609375,,,,,,,,,,,,,0,,,,-0.0049,,,,,,20.0031796,,,,
,27948370.46,20.002161,74628.421875,0.00536100776638683,1.12308463421634E-6,1,0.999253354069792,40.0298881530762,1.99048190714564,21.4900001883507,0.0603792806354563,0.0111938395594876,0.25,2.72848005945626E-5,0.00536700775096655,6.6647556467594E-5,20.002161,20.002161,74615.8671875,74640.9765625,56.9947883652753,20.375695188009,12.278775,0,0,0,40,4449,19.96015,74628.421875,,,,,,,,,,,,,0,,,,0,,,,,,20.002161,,,,
,27948463.715,20.0019989,79289.09765625,0.00539633606722833,1.17792542883416E-6,1,0.999253354069792,40.0298881530762,1.99041866079569,21.5000007301569,0.0607992126422675,0.0112607800582793,0.25,2.69270616102859E-5,0.00540433653567888,6.61732513314934E-5,20.0019989,20.0019989,79284.1171875,79294.078125,56.6391473890252,20.3793676088054,11.899124,0,0,0,40,4449,19.9578,79289.09765625,,,,,,,,,,,,,0,,,,0,,,,,,20.0019989,,,,
,27948559.885,20.0013332,84097.734375,0.00542602371742968,1.09160697298204E-6,1,0.999253354069792,40.0298881530762,1.99053532776694,21.4900001883507,0.0611597991446242,0.0113206136530328,0.25,2.6966503169958E-5,0.00543598087543587,6.59632443500043E-5,20.0013332,20.0013332,84092.625,84102.84375,56.8861420011022,20.3744542366105,11.899124,0,0,0,40,4449,19.9564,84097.734375,,,,,,,,,,,,,0,,,,-0.00245,,,,,,20.0013332,,,,
,27948649.165,20.0013809,88558.41015625,0.00544479440639873,1.08365450966238E-6,1,0.999253354069792,40.0298881530762,1.99061621523795,21.4900001883507,0.0613967818710722,0.0113401590121967,0.25,2.54830702391986E-5,0.00545647107378295,6.41216726758871E-5,20.0013809,20.0013809,88550.78125,88566.0390625,56.8423708040252,20.372079768267,12.278775,0,0,0,40,4449,19.95505,88558.41015625,,,,,,,,,,,,,0,,,,0,,,,,,20.0013809,,,,
,27948759.995,20.0010872,86983.79296875,0.00543568307530478,1.04966031863486E-6,1,0.999253354069792,40.0298881530762,1.99049556132838,21.4900001883507,0.0612793790277279,0.0113450119386005,0.25,2.75319905017672E-5,0.00544674688063468,6.62884945828909E-5,20.0010872,20.0010872,86978.8984375,86988.6875,56.5727089648906,20.375807271489,12.278775,0,0,0,40,4449,19.9546,86983.79296875,,,,,,,,,,,,,0,,,,-0.0049,,,,,,20.0010872,,,,
,27948851.75,19.9999657,82397.78125,0.00540977508863616,1.15232744517029E-6,1,0.999253354069792,40.0298881530762,1.99045376075952,21.4900001883507,0.0609648874288985,0.0112958097639067,0.25,2.76734965086622E-5,0.00541903641707844,6.67266732436334E-5,19.9998646,20.0000668,82390.3203125,82405.2421875,57.0932735586983,20.3730109835633,12.278775,0,0,0,40,4449,19.95435,82397.78125,,,,,,,,,,,,,0,,,,0,,,,,,19.9999657,,,,
,27948944.77,19.9999599,77746.28125,0.00538164908533013,9.07493647621349E-7,1,0.999253354069792,40.0298881530762,1.99041347142436,21.4900001883507,0.0606239786316037,0.0112426203079147,0.25,2.79406038131502E-5,0.00538898620975391,6.72140654614601E-5,19.9999599,19.9999599,77746.28125,77746.28125,56.9572701963522,20.3767087350216,12.278775,0,0,0,40,4449,19.9556,77746.28125,,,,,,,,,,,,,0,,,,0,,,,,,19.9999599,,,,
,27949041.24,20.0005989,72922.5390625,0.00534207970081998,9.96784786568383E-7,1,0.999253354069792,40.0298881530762,1.99037777926987,21.4900001883507,0.0601571248874253,0.011139382637905,0.25,2.59246857307427E-5,0.0053473305527837,6.52625325899386E-5,20.0005989,20.0005989,72912.53125,72932.546875,56.9416376259676,20.3780128601193,12.278775,0,0,0,40,4449,19.95635,72922.5390625,,,,,,,,,,,,,0,,,,0,,,,,,20.0005989,,,,
,27949137.14,19.9989052,68129.8984375,0.00529994649948664,9.28690239705948E-7,1,0.999253354069792,40.0298881530762,1.99045025943749,21.4900001883507,0.0596582674781083,0.011061275822158,0.25,2.66650836675866E-5,0.00530301511622017,6.59479878683263E-5,19.9989052,19.9989052,68119.96875,68139.828125,56.9346029692945,20.3763666509893,12.278775,0,0,0,40,4449,19.9567,68129.8984375,,,,,,,,,,,,,0,,,,-0.0049,,,,,,19.9989052,,,,
,27949232.87,19.998354,63344.458984375,0.00524712716707213,8.43897881484075E-7,1,0.999253354069792,40.0298881530762,1.99038763502046,21.4900001883507,0.059033057088272,0.0109676527569575,0.25,2.81477508096445E-5,0.00524792935374378,6.71794549093337E-5,19.998354,19.998354,63341.76171875,63347.15625,57.068261446083,20.3771899803451,12.278775,0,0,0,40,4449,19.9577,63344.458984375,,,,,,,,,,,,,0,,,,-0.0049,,,,,,19.998354,,,,
,27949325.875,19.99890515,58696.04296875,0.00518611247164101,8.20008109253058E-7,1,0.999253354069792,40.0298881530762,1.99036322882214,21.4900001883507,0.0583232819797897,0.0108213820045361,0.25,2.65424394320069E-5,0.00518467826593183,6.51318882714863E-5,19.998867,19.9989433,58688.47265625,58703.61328125,56.8587850029291,20.3770921959552,12.278775,0,0,0,40,4449,19.9579,58696.04296875,,,,,,,,,,,,,0,,,,0.00245,,,,,,19.99890515,,,,
,27949420.08,19.9993629,53988.173828125,0.00511958644924459,7.86637876505866E-7,1,0.999253354069792,40.0298881530762,1.99030574266344,21.4900001883507,0.0575456441372724,0.0106867380421366,0.25,2.71284324968228E-5,0.00511583413501162,6.50956321656365E-5,19.9993629,19.9993629,53980.70703125,53995.640625,56.7548284098714,20.3795061976188,12.278775,0,0,0,40,4449,19.9597,53988.173828125,,,,,,,,,,,,,0,,,,-0.00245,,,,,,19.9993629,,,,
,27949513.76,19.9990749,49305.673828125,0.00504318882580087,9.22305340142455E-7,1,0.999253354069792,40.0298881530762,1.99036008354955,21.4900001883507,0.0566629055442543,0.010516382043406,0.25,2.64183647291528E-5,0.00503713146106125,6.35420953033695E-5,19.9990749,19.9990749,49298.09765625,49313.25,56.8361177758714,20.3742759837275,12.658426,0,0,0,40,4449,19.9592,49305.673828125,,,,,,,,,,,,,0,,,,0,,,,,,19.9990749,,,,
,27949607.79,19.9999008,44605.27734375,0.00495764765060961,8.01628245385061E-7,1,0.999253354069792,40.0298881530762,1.99030720775616,21.5000007301569,0.0556740139515931,0.0103293333059227,0.25,2.60777300118571E-5,0.00494929579913839,6.21319600726872E-5,19.9999008,19.9999008,44600.32421875,44610.23046875,56.811105663256,20.372789448693,12.278775,0,0,0,40,4449,19.95965,44605.27734375,,,,,,,,,,,,,0,,,,0.0049,,,,,,19.9999008,,,,
,27949702.015,19.9982052,39897.17578125,0.00486359556906664,7.23252498887179E-7,1,0.999253354069792,40.0298881530762,1.9903895925256,21.4900001883507,0.0545898975791467,0.0101456793001598,0.25,2.7669105651988E-5,0.00485298838345938,6.24257507772362E-5,19.9982052,19.9982052,39887.0078125,39907.34375,56.8243933480829,20.3776669011277,12.278775,0,0,0,40,4449,19.96165,39897.17578125,,,,,,,,,,,,,0,,,,-0.0049,,,,,,19.9982052,,,,
,27949797.835,19.9998112,35107.138671875,0.0047592017334074,7.21526836411329E-7,1,0.999253354069792,40.0298881530762,1.99047814864237,21.4900001883507,0.0533905730466711,0.00993833064820387,0.25,2.91816003613245E-5,0.0047463991081833,6.23909608419805E-5,19.9998112,19.9998112,35099.4609375,35114.81640625,56.9932251082368,20.3744084564623,12.278775,0,0,0,40,4449,19.9625,35107.138671875,,,,,,,,,,,,,0,,,,0.00245,,,,,,19.9998112,,,,
,27949891.08,19.9979076,30447.52734375,0.00464759897475937,6.2870546091364E-7,1,0.999253354069792,40.0298881530762,1.99039061919841,21.4900001883507,0.0521113385325902,0.00969635227419442,0.25,2.90773983976845E-5,0.00463281290285328,6.05664377249247E-5,19.9979076,19.9979076,30437.54296875,30457.51171875,56.8681645451599,20.3791458251988,11.899124,0,0,0,40,4449,19.9626,30447.52734375,,,,,,,,,,,,,0,,,,-0.00245,,,,,,19.9979076,,,,
,27949988.505,19.9990959,25577.3701171875,0.00452212613957201,5.95948512938703E-7,1,0.999253354069792,40.0298881530762,1.99059163896792,21.4900001883507,0.050686361853704,0.00941559215835887,0.25,2.80617148804804E-5,0.00450546274159608,5.75597041830544E-5,19.9990959,19.9990959,25569.96875,25584.771484375,56.8947399148137,20.3718208759626,12.658426,0,0,0,40,4449,19.9652,25577.3701171875,,,,,,,,,,,,,0,,,,0.00245,,,,,,19.9990959,,,,
,27950080.18,19.9983139,20994.5107421875,0.0043974145114739,6.92795302648475E-7,1,0.999253354069792,40.0298881530762,1.99049897214567,21.4900001883507,0.0492620336816054,0.00915988896519444,0.25,2.92372386334112E-5,0.00437918223987918,5.67097935769279E-5,19.9983139,19.9983139,20987.03515625,21001.986328125,57.1182856713137,20.3801414229397,12.278775,0,0,0,40,4449,19.96575,20994.5107421875,,,,,,,,,,,,,0,,,,0.0049,,,,,,19.9983139,,,,
,27950175.345,19.9984856,16239.9750976562,0.00425531701970047,6.81225468089317E-7,1,0.999253354069792,40.0298881530762,1.99041206509777,21.4900001883507,0.0476491127005214,0.00884492384345782,0.25,2.8320824088684E-5,0.00423575332411493,5.35585299540454E-5,19.9984856,19.9984856,16229.927734375,16250.0224609375,56.8697278021983,20.3771319305064,12.278775,0,0,0,40,4449,19.96735,16239.9750976562,,,,,,,,,,,,,0,,,,0.0049,,,,,,19.9984856,,,,
,27950270.545,19.9980812,11479.8198242187,0.00410318430291421,5.20034081206307E-7,1,0.999253354069792,40.0298881530762,1.99040598778102,21.4900001883507,0.0459268260978034,0.00852095919531676,0.25,2.83258868638607E-5,0.00408259971366382,5.12555897600606E-5,19.9980812,19.9980812,11477.3740234375,11482.265625,56.7540467813522,20.379016258046,12.278775,0,0,0,40,4449,19.9679,11479.8198242187,,,,,,,,,,,,,0,,,,-0.0049,,,,,,19.9980812,,,,
,27950365.985,19.9991436,6709.56884765625,0.00393232236645833,5.81635843430008E-7,1,0.999253354069792,40.0298881530762,1.99053582939432,21.4900001883507,0.0440011328875145,0.00816016389478583,0.25,2.82146270804164E-5,0.00391112209917804,4.88006629821309E-5,19.9991436,19.9991436,6704.498046875,6714.6396484375,56.5523866233906,20.3803860469866,12.278775,0,0,0,40,4449,19.9705,6709.56884765625,,,,,,,,,,,,,0,,,,0,,,,,,19.9991436,,,,
,27950459.81,20.0002213,2021.33209228516,0.00373954960831113,5.71110114470174E-7,1,0.999253354069792,40.0298881530762,1.99055479204497,21.4900001883507,0.0418315441878039,0.00775843642855878,0.25,2.80935843243147E-5,0.00371824974178402,4.64482901340601E-5,20.0002213,20.0002213,2016.29699707031,2026.3671875,56.6399290175445,20.3755291013812,12.278775,0,0,0,40,4449,19.9699,2021.33209228516,,,,,,,,,,,,,0,,,,0.0049,,,,,,20.0002213,,,,
,27950552.665,19.9991703,-2614.29113769531,0.00350242830882147,4.62557492163779E-7,1,0.999253354069792,40.0298881530762,1.99061907514559,21.5000007301569,0.0391806430439299,0.00727220403432645,0.25,2.66495123018095E-5,0.00348259431072283,4.39708418561733E-5,19.9991703,19.9991703,-2616.8037109375,-2611.77856445313,56.7477937531983,20.3759381294004,12.278775,0,0,0,40,4449,19.9702,-2614.29113769531,,,,,,,,,,,,,0,,,,-0.0049,,,,,,19.9991703,,,,
,27950646.62,19.9991798,-7314.05590820312,0.00317112283303285,5.50794115122571E-7,1,0.999253354069792,40.0298881530762,1.99061552990991,21.4900001883507,0.035483881742075,0.00659611262990612,0.25,2.39527657750576E-5,0.00315416032133633,4.0688070678741E-5,19.9991798,19.9991798,-7321.443359375,-7306.66845703125,56.8236117195637,20.381201084838,11.899124,0,0,0,40,4449,19.97055,-7314.05590820312,,,,,,,,,,,,,0,,,,0.00245,,,,,,19.9991798,,,,
,27950741.885,19.9996452,-12074.8266601562,0.00256884226570054,5.86233168931765E-7,1,0.999253354069792,40.0298881530762,1.9906152047059,21.4900001883507,0.0287538312948402,0.00535498437232579,0.25,1.93661986984707E-5,0.00255607439850143,3.38256493914178E-5,19.9996452,19.9996452,-12079.9169921875,-12069.736328125,56.7126204698329,20.3793432875066,12.658426,0,0,0,40,4449,19.9707,-12074.8266601562,,,,,,,,,,,,,0,,,,0,,,,,,19.9996452,,,,
,27950838.07,20.000803,-16882.037109375,0.00128776242981608,9.25323002002418E-7,1,0.999253354069792,40.0298881530762,1.99072803721882,21.5000007301569,0.0144195582061563,0.0026955424388627,0.25,1.01449614369626E-5,0.00128190878546277,1.78326549932289E-5,20.000803,20.000803,-16887.115234375,-16876.958984375,57.1206305568714,20.3785083991938,12.658426,0,0,0,40,4449,19.96965,-16882.037109375,,,,,,,,,,,,,0,,,,-0.00245,,,,,,20.000803,,,,
,27950932.355,19.999649,-21594.685546875,-0.000705170456619388,1.14936235770876E-6,1,0.999253354069792,40.0298881530762,1.99068324021004,21.4900001883507,-0.00790369930001822,-0.00145313080398886,0.25,-3.23877017745444E-6,-0.000702297424463644,-7.67676971308981E-6,19.999649,19.999649,-21599.69921875,-21589.671875,57.0760777312753,20.3764069556487,12.278775,0,0,0,40,4449,19.9671,-21594.685546875,,,,,,,,,,,,,0,,,,0,,,,,,19.999649,,,,
,27951029.85,20.002079,-26466.9365234375,-0.00266049884781104,8.37572650833007E-7,1,0.999253354069792,40.0298881530762,1.99061477468947,21.4900001883507,-0.0298242688189203,-0.00553480754710501,0.25,-1.59153249400909E-5,-0.00265094129561259,-3.3402819908371E-5,20.002079,20.002079,-26472.115234375,-26461.7578125,57.0495023616214,20.3789946665997,11.899124,0,0,0,40,4449,19.9661,-26466.9365234375,,,,,,,,,,,,,0,,,,0.00245,,,,,,20.002079,,,,
,27951126.59,20.0026913,-31302.0576171875,-0.00378982010370388,7.57532487703445E-7,1,0.999253354069792,40.0298881530762,1.99064681156279,21.4900001883507,-0.0425032726785906,-0.00790425050037563,0.25,-2.31899227330348E-5,-0.00377810596922664,-4.90204805068944E-5,20.0026913,20.0026913,-31309.8046875,-31294.310546875,57.2042648084291,20.3772301335001,12.278775,0,0,0,40,4449,19.9646,-31302.0576171875,,,,,,,,,,,,,0,,,,0.00245,,,,,,20.0026913,,,,
,27951222.705,20.0017014,-36106.611328125,-0.00437002239656706,5.7683089041204E-7,1,0.999253354069792,40.0298881530762,1.99062059940793,21.4900001883507,-0.0490338787762391,-0.00912325057968942,0.25,-2.62797444000803E-5,-0.00435873194262762,-5.69421146794438E-5,20.0017014,20.0017014,-36111.59765625,-36101.625,56.8994296859291,20.3814854555099,12.278775,0,0,0,40,4449,19.9623,-36106.611328125,,,,,,,,,,,,,0,,,,0.00245,,,,,,20.0017014,,,,
,27951318.675,20.0026779,-40901.369140625,-0.00469364821193979,6.96373983300156E-7,1,0.999253354069792,40.0298881530762,1.99066281622055,21.4900001883507,-0.0526928457997142,-0.00980475647099398,0.25,-2.75709140379654E-5,-0.00468390158743328,-6.12517987957268E-5,20.0024967,20.0028591,-40908.76171875,-40893.9765625,57.4043617093522,20.3817807069355,12.658426,0,0,0,40,4449,19.9616,-40901.369140625,,,,,,,,,,,,,0,,,,0,,,,,,20.0026779,,,,
,27951411.5,20.0011044,-45541.666015625,-0.00488277318462255,5.79823549395899E-7,1,0.999253354069792,40.0298881530762,1.99056206174098,21.5000007301569,-0.0548369716002599,-0.0102214025757063,0.25,-2.96665297659537E-5,-0.00487499271775195,-6.52700875684995E-5,20.0011044,20.0011044,-45551.5703125,-45531.76171875,56.8259566051214,20.3809602454423,12.278775,0,0,0,40,4449,19.9588,-45541.666015625,,,,,,,,,,,,,0,,,,-0.0049,,,,,,20.0011044,,,,
,27951506.57,20.0014153,-50294.267578125,-0.00501776634635957,7.90325033350045E-7,1,0.999253354069792,40.0298881530762,1.99064284005295,21.4900001883507,-0.0563862675300037,-0.0104897396920958,0.25,-2.83446116794547E-5,-0.00501222661472679,-6.53506408698577E-5,20.0014153,20.0014153,-50299.3671875,-50289.16796875,56.9994781363906,20.377828945128,11.899124,0,0,0,40,4449,19.95825,-50294.267578125,,,,,,,,,,,,,0,,,,-0.00245,,,,,,20.0014153,,,,
,27951602.605,19.9996319,-55091.212890625,-0.00511542713729072,7.18113960000451E-7,1,0.999253354069792,40.0298881530762,1.99041389634104,21.4900001883507,-0.0575047806077441,-0.0106981899014462,0.25,-2.87075591740624E-5,-0.00511221914678489,-6.6686098301259E-5,19.9996319,19.9996319,-55096.15625,-55086.26953125,57.0393411908714,20.381658906722,12.278775,0,0,0,40,4449,19.9577,-55091.212890625,,,,,,,,,,,,,0,,,,-0.0049,,,,,,19.9996319,,,,
,27951696.045,20.0017776,-59763.525390625,-0.00519229346738677,6.89302237918118E-7,1,0.999253354069792,40.0298881530762,1.990632244885,21.4900001883507,-0.0583993749466315,-0.0108746923893172,0.25,-2.99400931270957E-5,-0.00519135522548198,-6.85839088995039E-5,20.0017776,20.0017776,-59773.46484375,-59753.5859375,56.8447156895829,20.3793038379851,12.278775,0,0,0,40,4449,19.95755,-59763.525390625,,,,,,,,,,,,,0,,,,-0.00245,,,,,,20.0017776,,,,
,27951792.97,20.0013905,-64606.119140625,-0.0052553756871643,7.7444591424514E-7,1,0.999253354069792,40.0298881530762,1.99055503637203,21.4900001883507,-0.0591363530117746,-0.0109924214400823,0.25,-2.87036931820768E-5,-0.00525677292971375,-6.77719890979538E-5,20.0013905,20.0013905,-64611.0078125,-64601.23046875,56.9158438848329,20.3821499847653,12.278775,0,0,0,40,4449,19.95545,-64606.119140625,,,,,,,,,,,,,0,,,,0,,,,,,20.0013905,,,,
,27951891.335,20.000576,-69520.49609375,-0.00531211043339067,9.44892839861065E-7,1,0.999253354069792,40.0298881530762,1.99067115283681,21.5000007301569,-0.0598029706275931,-0.0111205946587518,0.25,-2.95870133330933E-5,-0.00531579742370339,-6.88990759287626E-5,20.000576,20.000576,-69532.9921875,-69508,56.9979148793522,20.3792245666143,12.278775,0,0,0,40,4449,19.95525,-69520.49609375,,,,,,,,,,,,,0,,,,0,,,,,,20.000576,,,,
,27951990.99,20.0009222,-74502.51953125,-0.00535267833303116,1.14852539291483E-6,1,0.999253354069792,40.0298881530762,1.99052971486121,21.4900001883507,-0.0602827453442144,-0.0111960031725086,0.25,-2.89547591224569E-5,-0.00535860219730983,-6.82672935792762E-5,20.0008354,20.001009,-74510.1171875,-74494.921875,57.0924919301791,20.3843261057511,12.278775,0,0,0,40,4449,19.9534,-74502.51953125,,,,,,,,,,,,,0,,,,0,,,,,,20.0009222,,,,
,27952088.22,20.0026016,-79359.5859375,-0.0053916817334205,1.1029848591647E-6,1,0.999253354069792,40.0298881530762,1.99051794210955,21.4900001883507,-0.0607374359823698,-0.0113213654344602,0.25,-3.30910794247948E-5,-0.00539965882576811,-7.23066395680241E-5,20.0026016,20.0026016,-79371.984375,-79347.1875,57.0463758475445,20.3822318859805,12.658426,0,0,0,40,4449,19.95115,-79359.5859375,,,,,,,,,,,,,0,,,,0.00245,,,,,,20.0026016,,,,
,27952184.77,20.0013332,-84186.66796875,-0.00541927823155269,1.16550572077159E-6,1,0.999253354069792,40.0298881530762,1.99057447121183,21.5000007301569,-0.0610832243659546,-0.0113183330220721,0.25,-2.79627492185669E-5,-0.00542924962698549,-6.69037706198446E-5,20.0013332,20.0013332,-84194.0546875,-84179.28125,57.0299616486406,20.3837540708272,12.278775,0,0,0,40,4449,19.9499,-84186.66796875,,,,,,,,,,,,,0,,,,0.0049,,,,,,20.0013332,,,,
,27952275.98,20.0005856,-88743.4609375,-0.00543910825085065,1.03708964595283E-6,1,0.999253354069792,40.0298881530762,1.99057199206347,21.4900001883507,-0.0613249563898167,-0.0113680168805147,0.25,-2.90052472724055E-5,-0.00545081465495623,-6.75899976705019E-5,20.0005856,20.0005856,-88751.109375,-88735.8125,57.0260535060445,20.3847835625847,11.899124,0,0,0,40,4449,19.94875,-88743.4609375,,,,,,,,,,,,,0,,,,-0.00245,,,,,,20.0005856,,,,
,27952388.5,20.0005398,-86674.30859375,-0.00543126535109609,9.95250373952988E-7,1,0.999253354069792,40.0298881530762,1.99060106368518,21.5000007301569,-0.0612322099620251,-0.0113315160288196,0.25,-2.70654426438861E-5,-0.005442208086879,-6.58238729973072E-5,20.0005398,20.0005398,-86684.2734375,-86664.34375,57.065134932006,20.3823660481752,11.899124,0,0,0,40,4449,19.9477,-86674.30859375,,,,,,,,,,,,,0,,,,0.00245,,,,,,20.0005398,,,,
,27952480.6,20.0002327,-82072.5078125,-0.00541021051284969,1.15034121641037E-6,1,0.999253354069792,40.0298881530762,1.99063473676474,21.4900001883507,-0.0609691984738058,-0.0113221475586748,0.25,-2.98331655503182E-5,-0.0054193287678734,-6.8925177559568E-5,20.0002327,20.0002327,-82072.5078125,-82072.5078125,57.4754899046022,20.3827087303186,12.278775,0,0,0,40,4449,19.948,-82072.5078125,,,,,,,,,,,,,0,,,,-0.0049,,,,,,20.0002327,,,,
,27952575.105,19.9989052,-77346.8359375,-0.00538068110493122,9.50052516101982E-7,1,0.999253354069792,40.0298881530762,1.99074409111341,21.4900001883507,-0.0606091406056461,-0.0113068879452828,0.25,-3.36515602419915E-5,-0.00538780895055452,-7.29587734804595E-5,19.9989052,19.9989052,-77359.453125,-77334.21875,57.2902439455445,20.3824909651242,13.038077,0,0,0,40,4449,19.9489,-77346.8359375,,,,,,,,,,,,,0,,,,-0.0049,,,,,,19.9989052,,,,
,27952671.415,19.99799825,-72534.52734375,-0.00534010288410207,1.093318259162E-6,1,0.999253354069792,40.0298881530762,1.99072239468386,21.4900001883507,-0.0601336150571639,-0.0111882643271458,0.25,-3.04585862189925E-5,-0.00534514847322708,-6.98109815396444E-5,19.9978695,19.998127,-72542.390625,-72526.6640625,57.2425646058714,20.3844945202144,12.278775,0,0,0,40,4449,19.9507,-72534.52734375,,,,,,,,,,,,,0,,,,0,,,,,,19.99799825,,,,
,27952767.27,19.9988537,-67745.6328125,-0.00529381549414216,7.43956475007045E-7,1,0.999253354069792,40.0298881530762,1.99064144328949,21.4900001883507,-0.059591469928146,-0.0110561688439185,0.25,-2.72413691416202E-5,-0.00529669990743612,-6.6494930956997E-5,19.9988537,19.9988537,-67755.875,-67735.390625,57.3027500018522,20.3834843782651,12.658426,0,0,0,40,4449,19.9514,-67745.6328125,,,,,,,,,,,,,0,,,,-0.0049,,,,,,19.9988537,,,,
,27952861.785,19.9994926,-63021.099609375,-0.00524302453501449,9.35729144817367E-7,1,0.999253354069792,40.0298881530762,1.99062736514519,21.4900001883507,-0.0589887931766886,-0.0109775197487238,0.25,-2.96730667868679E-5,-0.00524366025656955,-6.8679452542194E-5,19.9994926,19.9994926,-63028.51171875,-63013.6875,56.9517987967176,20.3795957625873,11.899124,0,0,0,40,4449,19.953,-63021.099609375,,,,,,,,,,,,,0,,,,0.0049,,,,,,19.9994926,,,,
,27952958.355,19.998558,-58195.505859375,-0.0051833175903403,8.40997313186614E-7,1,0.999253354069792,40.0298881530762,1.99067256104851,21.4900001883507,-0.0582878754331484,-0.0108712900464679,0.25,-3.13861503502173E-5,-0.00518160141625697,-6.99467861377065E-5,19.998558,19.998558,-58205.5234375,-58185.48828125,56.966649738583,20.3818558525457,12.278775,0,0,0,40,4449,19.9547,-58195.505859375,,,,,,,,,,,,,0,,,,0,,,,,,19.998558,,,,
,27953048.475,20.0011654,-53690.58203125,-0.00511537978081298,7.94343878767991E-7,1,0.999253354069792,40.0298881530762,1.99076602781995,21.4900001883507,-0.0575033866249929,-0.0107131660500148,0.25,-3.00645669110862E-5,-0.00511145826218737,-6.79853105683475E-5,20.0010166,20.0013142,-53723.0625,-53658.1015625,56.9791557948906,20.3756976368894,12.278775,0,0,0,40,4449,19.95565,-53690.58203125,,,,,,,,,,,,,0,,,,0,,,,,,20.0011654,,,,
,27953144.27,19.9980869,-48903.38671875,-0.00503782063191805,7.8797665411221E-7,1,0.999253354069792,40.0298881530762,1.99071193660483,21.4900001883507,-0.0566046980357895,-0.0105349700061185,0.25,-2.89476420815147E-5,-0.00503154463899116,-6.59973503399732E-5,19.9980869,19.9980869,-48910.73046875,-48896.04296875,57.5708485839484,20.3791526933537,11.899124,0,0,0,40,4449,19.9567,-48903.38671875,,,,,,,,,,,,,0,,,,0,,,,,,19.9980869,,,,
,27953239.28,19.9990387,-44155.8125,-0.00494867533433484,7.93664675786607E-7,1,0.999253354069792,40.0298881530762,1.99063946622759,21.5000007301569,-0.0555728924517694,-0.010348514293238,0.25,-2.93449036298659E-5,-0.0049400829247015,-6.52770424355521E-5,19.9990387,19.9990387,-44163.21875,-44148.40625,56.9705578811791,20.3796859877664,11.899124,0,0,0,40,4449,19.95745,-44155.8125,,,,,,,,,,,,,0,,,,0,,,,,,19.9990387,,,,
,27953334.055,19.9992428,-39418.390625,-0.00485263941754999,7.87193663831536E-7,1,0.999253354069792,40.0298881530762,1.99064570640133,21.4900001883507,-0.0544678244626557,-0.0101403725294344,0.25,-2.91728542135563E-5,-0.00484179969486237,-6.37754413574616E-5,19.9992428,19.9992428,-39430.97265625,-39405.80859375,56.6508718168137,20.3803073937333,12.658426,0,0,0,40,4449,19.9582,-39418.390625,,,,,,,,,,,,,0,,,,-0.00245,,,,,,19.9992428,,,,
,27953431.2,19.9993238,-34563.8828125,-0.00474579234654064,7.35982087323098E-7,1,0.999253354069792,40.0298881530762,1.9907799241647,21.4900001883507,-0.0532432139091837,-0.00991986247712412,0.25,-2.99705877619933E-5,-0.00473274704523773,-6.29815498702018E-5,19.9992599,19.9993877,-34573.94921875,-34553.81640625,56.8462789466214,20.3744291637338,12.658426,0,0,0,40,4449,19.95865,-34563.8828125,,,,,,,,,,,,,0,,,,0,,,,,,19.9993238,,,,
,27953523.21,19.9980659,-29964.12109375,-0.0046372635763001,6.00952268343133E-7,1,0.999253354069792,40.0298881530762,1.9907723176762,21.4900001883507,-0.0520017995495022,-0.00967900537969877,0.25,-2.93792862501634E-5,-0.00462227339148952,-6.0689438110059E-5,19.9980659,19.9980659,-29971.611328125,-29956.630859375,56.9744660237753,20.3758499968744,12.278775,0,0,0,40,4449,19.96055,-29964.12109375,,,,,,,,,,,,,0,,,,-0.0049,,,,,,19.9980659,,,,
,27953615.98,19.998394,-25329.2705078125,-0.00451635260117511,6.83523752534582E-7,1,0.999253354069792,40.0298881530762,1.99076141238934,21.4900001883507,-0.0506224143474867,-0.00941561106713352,0.25,-2.91139037741846E-5,-0.00449958893342228,-5.85070636251837E-5,19.998394,19.998394,-25339.21484375,-25319.326171875,56.9299131981791,20.3763746563911,12.278775,0,0,0,40,4449,19.96165,-25329.2705078125,,,,,,,,,,,,,0,,,,0,,,,,,19.998394,,,,
,27953710.355,19.9987946,-20611.93359375,-0.00438620531975408,5.58143958216066E-7,1,0.999253354069792,40.0298881530762,1.99070017606586,21.4900001883507,-0.0491399870198605,-0.0091335331035197,0.25,-2.89519349166055E-5,-0.00436785681523566,-5.6248430855431E-5,19.9987946,19.9987946,-20622.107421875,-20601.759765625,57.1440794124484,20.3746447627279,12.278775,0,0,0,40,4449,19.963,-20611.93359375,,,,,,,,,,,,,0,,,,0,,,,,,19.9987946,,,,
,27953804.525,19.9986897,-15906.9228515625,-0.00424613134251143,5.02324997974361E-7,1,0.999253354069792,40.0298881530762,1.9907004060321,21.4900001883507,-0.0475483809863744,-0.00884348971096603,0.25,-2.98476296475867E-5,-0.00422647083424581,-5.49247762797995E-5,19.9986897,19.9986897,-15914.2001953125,-15899.6455078125,56.9455457685637,20.3782987218617,11.899124,0,0,0,40,4449,19.9639,-15906.9228515625,,,,,,,,,,,,,0,,,,0,,,,,,19.9986897,,,,
,27953894.885,19.9981861,-11388.9946289062,-0.00409983850740115,5.54095567492818E-7,1,0.999253354069792,40.0298881530762,1.9907490845033,21.4900001883507,-0.04589468188414,-0.00852596724929336,0.25,-2.92775584346246E-5,-0.00407923400431979,-5.21562012170304E-5,19.9981861,19.9981861,-11391.318359375,-11386.6708984375,56.902556200006,20.3725811542525,11.899124,0,0,0,40,4449,19.9656,-11388.9946289062,,,,,,,,,,,,,0,,,,0,,,,,,19.9981861,,,,
,27953985.055,19.9988155,-6883.47583007812,-0.00393693799607244,3.55750667180369E-7,1,0.999253354069792,40.0298881530762,1.9906551369111,21.5000007301569,-0.0440550089105067,-0.00817509536551107,0.25,-2.86250472530287E-5,-0.00391576029964609,-4.9283076421757E-5,19.9988155,19.9988155,-6893.31591796875,-6873.6357421875,56.4898563418521,20.3772051799112,11.899124,0,0,0,40,4449,19.96685,-6883.47583007812,,,,,,,,,,,,,0,,,,-0.00245,,,,,,19.9988155,,,,
,27954074.695,20.00028035,-2399.87646484375,-0.0037527862848663,3.81743987000584E-7,1,0.999253354069792,40.0298881530762,1.99057463390525,21.4900001883507,-0.0419796648321592,-0.0077931169554572,0.25,-2.87269865409878E-5,-0.00373148726869146,-4.72331990373413E-5,20.0001907,20.00037,-2404.73217773438,-2395.02075195313,56.7970363499099,20.3816091337748,12.278775,0,0,0,40,4449,19.96605,-2399.87646484375,,,,,,,,,,,,,0,,,,-0.00245,,,,,,20.00028035,,,,
,27954164.045,20.0000668,2062.21337890625,-0.00352878657895362,5.02741453261187E-7,1,0.999253354069792,40.0298881530762,1.99059017984065,21.4900001883507,-0.0394732301034093,-0.00732931154579614,0.25,-2.72161252850707E-5,-0.00350869134949711,-4.45410836818774E-5,20.0000668,20.0000668,2054.44067382813,2069.98608398438,56.8791073444291,20.3759359165646,12.278775,0,0,0,40,4449,19.9661,2062.21337890625,,,,,,,,,,,,,0,,,,-0.0049,,,,,,20.0000668,,,,
,27954253.64,19.99823,6540.84252929688,-0.00323182748063802,4.4713863196015E-7,1,0.999253354069792,40.0298881530762,1.99074777654688,21.4900001883507,-0.0361651514889173,-0.00671246698951308,0.25,-2.37046012752455E-5,-0.00321436155120087,-4.0580683554189E-5,19.99823,19.99823,6538.30517578125,6543.3798828125,56.7931282073137,20.3780869087955,12.658426,0,0,0,40,4449,19.9673,6540.84252929688,,,,,,,,,,,,,0,,,,0,,,,,,19.99823,,,,
,27954346.815,19.9998779,11196.3540039062,-0.00271146514467297,5.59860642038844E-7,1,0.999253354069792,40.0298881530762,1.99070815093253,21.4900001883507,-0.0303497378326169,-0.00564994852203193,0.25,-2.04202719415475E-5,-0.00269778893035655,-3.55076581574693E-5,19.9998779,19.9998779,11186.3681640625,11206.33984375,56.9549253107945,20.3769971082314,12.278775,0,0,0,40,4449,19.96745,11196.3540039062,,,,,,,,,,,,,0,,,,-0.00245,,,,,,19.9998779,,,,
,27954438.82,20.0001698,15796.7036132812,-0.00166318525467346,9.36911441413437E-7,1,0.999253354069792,40.0298881530762,1.99070933759714,21.5000007301569,-0.0186223080228805,-0.00347518079665724,0.25,-1.27077196638115E-5,-0.0016554617115064,-2.25128688975794E-5,20.0001698,20.0001698,15794.3515625,15799.0556640625,56.9885353371214,20.3750098252084,12.278775,0,0,0,40,4449,19.9672,15796.7036132812,,,,,,,,,,,,,0,,,,0,,,,,,20.0001698,,,,
,27954533.05,20.0023746,20504.09375,0.000196071343943563,1.16622360108728E-6,1,0.999253354069792,40.0298881530762,1.99066665282695,21.4900001883507,0.00219948877428209,0.000392073792095948,0.25,-1.48876240539801E-7,0.000195258090786896,1.07597233848147E-6,20.0023746,20.0023746,20496.6171875,20511.5703125,56.9009929429675,20.3734658738691,11.899124,0,0,0,40,4449,19.9655,20504.09375,,,,,,,,,,,,,0,,,,0,,,,,,20.0023746,,,,
,27954625.86,20.0007935,25144.52734375,0.00219272148208444,9.6257862384684E-7,1,0.999253354069792,40.0298881530762,1.99062301070189,21.4900001883507,0.0245737118774754,0.00458063992312895,0.25,1.50204185335614E-5,0.00218453569832878,2.92648556310244E-5,20.0007935,20.0007935,25134.310546875,25154.744140625,56.7978179784291,20.3752280702424,12.278775,0,0,0,40,4449,19.96405,25144.52734375,,,,,,,,,,,,,0,,,,0.00245,,,,,,20.0007935,,,,
,27954718.76,20.00156305,29789.8251953125,0.00351113569775538,7.87988050499124E-7,1,0.999253354069792,40.0298881530762,1.99081916898578,21.5000007301569,0.0393740304632849,0.00732661365969735,0.25,2.21006711526254E-5,0.00349972297877792,4.57781648206123E-5,20.0014019,20.0017242,29782.328125,29797.322265625,56.7798405224868,20.374523896203,12.658426,0,0,0,40,4449,19.96335,29789.8251953125,,,,,,,,,,,,,0,,,,0,,,,,,20.00156305,,,,
,27954812.4,20.0020123,34470.2421875,0.00421553141470245,7.98482608667974E-7,1,0.999253354069792,40.0298881530762,1.99069236828517,21.4900001883507,0.0472913163056913,0.00881340240576191,0.25,2.68484016758644E-5,0.00420390055782242,5.61544982594243E-5,20.0020123,20.0020123,34460.15234375,34480.33203125,56.7040225561214,20.3719502694513,12.278775,0,0,0,40,4449,19.9611,34470.2421875,,,,,,,,,,,,,0,,,,0,,,,,,20.0020123,,,,
,27954907.69,20.0024223,39232.390625,0.00460151583149423,7.3483752357818E-7,1,0.999253354069792,40.0298881530762,1.99067935896886,21.4900001883507,0.0516437977588973,0.00964413531830248,0.25,3.02308520901252E-5,0.00459112854666199,6.30099842478528E-5,20.0024223,20.0024223,39227.359375,39237.421875,56.6117903908521,20.3743914766318,12.658426,0,0,0,40,4449,19.96035,39232.390625,,,,,,,,,,,,,0,,,,0,,,,,,20.0024223,,,,
,27955002.11,20.0016241,43952.732421875,0.00482824373856629,7.72999847238993E-7,1,0.999253354069792,40.0298881530762,1.99063112218429,21.4900001883507,0.0542150289076905,0.0101190017900076,0.25,3.0661646073721E-5,0.00481974357325828,6.56927058360653E-5,20.0014801,20.0017681,43945.171875,43960.29296875,56.7337244398522,20.3806060936951,12.278775,0,0,0,40,4449,19.95865,43952.732421875,,,,,,,,,,,,,0,,,,-0.00245,,,,,,20.0016241,,,,
,27955095.18,20.0002823,48603.16015625,0.0049761009806473,8.78985827139988E-7,1,0.999253354069792,40.0298881530762,1.99073072242056,21.4900001883507,0.0559049108781735,0.0104339731669134,0.25,3.11307546967742E-5,0.00496973100685356,6.76994048759394E-5,20.0002823,20.0002823,48593.03125,48613.2890625,56.8329912617945,20.3743511877417,12.278775,0,0,0,40,4449,19.95775,48603.16015625,,,,,,,,,,,,,0,,,,-0.0049,,,,,,20.0002823,,,,
,27955191.21,20.0011044,53401.0859375,0.00508588780049747,8.75910012858151E-7,1,0.999253354069792,40.0298881530762,1.99064365832265,21.4900001883507,0.0571681392425214,0.0106434151822707,0.25,2.92756028223285E-5,0.00508184810060912,6.69648376425624E-5,20.0011044,20.0011044,53391.15234375,53411.01953125,56.7141837268714,20.3786510673966,12.278775,0,0,0,40,4449,19.95705,53401.0859375,,,,,,,,,,,,,0,,,,0,,,,,,20.0011044,,,,
,27955285.215,20.0006084,58098.8046875,0.00516957789686948,8.85608150774586E-7,1,0.999253354069792,40.0298881530762,1.99066293126954,21.4900001883507,0.058132469941913,0.0108428548452603,0.25,3.13510408636028E-5,0.00516781841384332,6.98079461348184E-5,20.0006084,20.0006084,58088.87109375,58108.73828125,56.8728543162753,20.3748232860382,12.278775,0,0,0,40,4449,19.9573,58098.8046875,,,,,,,,,,,,,0,,,,0.0049,,,,,,20.0006084,,,,
,27955379.78,20.0003719,62826.923828125,0.00523577134488345,7.88009371305975E-7,1,0.999253354069792,40.0298881530762,1.99076810826457,21.4900001883507,0.0589062182917707,0.0109845528263422,0.25,3.15524241383894E-5,0.00523629941465797,7.05077725979071E-5,20.0003719,20.0003719,62821.81640625,62832.03125,56.7212183835445,20.3722716967111,11.899124,0,0,0,40,4449,19.9561,62826.923828125,,,,,,,,,,,,,0,,,,0.0049,,,,,,20.0003719,,,,
,27955473.515,20.0012684,67512.23046875,0.0052911794645367,8.7004764011299E-7,1,0.999253354069792,40.0298881530762,1.9906705490143,21.5000007301569,0.0595540620654789,0.0110914461697207,0.25,3.08430331171229E-5,0.00529392855333169,7.0088248873743E-5,20.0012684,20.0012684,67509.8046875,67514.65625,57.1346998702176,20.3738762463206,12.278775,0,0,0,40,4449,19.9541,67512.23046875,,,,,,,,,,,,,0,,,,0,,,,,,20.0012684,,,,
,27955566.955,20.0011311,72182.68359375,0.00533618826767733,1.17831991293112E-6,1,0.999253354069792,40.0298881530762,1.99074416098402,21.4900001883507,0.0600793265864595,0.0112303608298858,0.25,3.48931451092576E-5,0.00534104292198184,7.42425404343169E-5,20.0011311,20.0011311,72172.8125,72192.5546875,57.0385595623522,20.372002443935,12.278775,0,0,0,40,4449,19.9536,72182.68359375,,,,,,,,,,,,,0,,,,0.00245,,,,,,20.0011311,,,,
,27955662.4,20.0015888,76953.19921875,0.00537389989909523,8.28206787437626E-7,1,0.999253354069792,40.0298881530762,1.99077065512154,21.4900001883507,0.0605304856229206,0.0112990841190457,0.25,3.41646978582949E-5,0.00538085051203688,7.34547763265284E-5,20.0015888,20.0015888,76945.7734375,76960.625,56.7610814380252,20.3727056184714,12.658426,0,0,0,40,4449,19.95235,76953.19921875,,,,,,,,,,,,,0,,,,0,,,,,,20.0015888,,,,
,27955757.44,20.0011044,81704.4140625,0.00540618425756955,9.34750757239966E-7,1,0.999253354069792,40.0298881530762,1.99073930273796,21.4900001883507,0.0609176098410265,0.011356417940404,0.25,3.35350032459346E-5,0.00541512341122467,7.26398920785763E-5,20.0011044,20.0011044,81694.3359375,81714.4921875,56.8634747740445,20.3735970230154,12.278775,0,0,0,40,4449,19.9501,81704.4140625,,,,,,,,,,,,,0,,,,-0.0049,,,,,,20.0011044,,,,
,27955848.25,20.0015965,86244.8671875,0.00542969368957854,1.08010685199125E-6,1,0.999253354069792,40.0298881530762,1.99084921580073,21.4900001883507,0.0612016773928946,0.0114309600420158,0.25,3.60211657030237E-5,0.00544040892230636,7.48336601104968E-5,20.0015965,20.0015965,86242.5703125,86247.1640625,56.6899532427752,20.3741423564586,12.658426,0,0,0,40,4449,19.94965,86244.8671875,,,,,,,,,,,,,0,,,,0.00245,,,,,,20.0015965,,,,
,27955953.745,20.0017185,89560.3984375,0.00544518707785295,1.11896567089965E-6,1,0.999253354069792,40.0298881530762,1.99082888564152,21.4900001883507,0.0613904671581868,0.0114600491780205,0.25,3.59851667917609E-5,0.00545715251614121,7.45337006774946E-5,20.0017185,20.0017185,89555.3515625,89565.4453125,56.7532651528329,20.3723303116898,11.899124,0,0,0,40,4449,19.9479,89560.3984375,,,,,,,,,,,,,0,,,,0,,,,,,20.0017185,,,,
,27956042.775,20.0009613,85109.26953125,0.0054255431696171,9.98758492368338E-7,1,0.999253354069792,40.0298881530762,1.99060599989336,21.4900001883507,0.0611423558934785,0.0114232943968328,0.25,3.61589825169325E-5,0.00543582046292557,7.50638983255855E-5,20.0009613,20.0009613,85104.3515625,85114.1875,56.5492601093137,20.3744912048354,11.899124,0,0,0,40,4449,19.9487,85109.26953125,,,,,,,,,,,,,0,,,,0.00245,,,,,,20.0009613,,,,
,27956137.58,19.9991646,80373.37890625,0.00539883131053281,1.18536438251749E-6,1,0.999253354069792,40.0298881530762,1.99074355141783,21.4900001883507,0.0608160239733333,0.0114114853698629,0.25,3.97054405868749E-5,0.00540718207654004,7.88920731847097E-5,19.9991322,19.999197,80365.5234375,80381.234375,56.6563432164483,20.3704077641854,11.899124,0,0,0,40,4449,19.94895,80373.37890625,,,,,,,,,,,,,0,,,,0,,,,,,19.9991646,,,,
,27956232.415,19.9980907,75628.9921875,0.00536590388448323,9.53284592120983E-7,1,0.999253354069792,40.0298881530762,1.99068606144034,21.4900001883507,0.0604261796957997,0.0113113164694494,0.25,3.6724496954489E-5,0.00537226739903134,7.60615561202718E-5,19.9980907,19.9980907,75621.6328125,75636.3515625,56.9017745714868,20.3730186889147,12.278775,0,0,0,40,4449,19.95035,75628.9921875,,,,,,,,,,,,,0,,,,0,,,,,,19.9980907,,,,
,27956327.76,19.99853515,70863.1875,0.00532837424386623,1.05834492436367E-6,1,0.999253354069792,40.0298881530762,1.99061356753312,21.4900001883507,0.0599719588821059,0.0112623251815012,0.25,3.92249554078735E-5,0.0053326053277604,7.85960486753977E-5,19.9983883,19.998682,70858.3515625,70868.0234375,56.8673829166406,20.3757773953418,12.658426,0,0,0,40,4449,19.9518,70863.1875,,,,,,,,,,,,,0,,,,0.0049,,,,,,19.99853515,,,,
,27956421.6,19.9984398,66172.8125,0.00528240848630149,7.91345680165376E-7,1,0.999253354069792,40.0298881530762,1.99065576490399,21.4900001883507,0.0594331287998547,0.0111539707231403,0.25,3.80409237682504E-5,0.0052844799964624,7.72711500309855E-5,19.9984398,19.9984398,66170.296875,66175.328125,56.7579549239483,20.3736371551532,12.658426,0,0,0,40,4449,19.9521,66172.8125,,,,,,,,,,,,,0,,,,0,,,,,,19.9984398,,,,
,27956517.715,19.9984264,61369.005859375,0.00522398032633711,8.48569979472931E-7,1,0.999253354069792,40.0298881530762,1.99073731153801,21.4900001883507,0.0587559895898059,0.0110072040476282,0.25,3.58120816483796E-5,0.00522377543111895,7.4692376539672E-5,19.9984264,19.9984264,61361.515625,61376.49609375,56.7313795542945,20.3738763321396,12.658426,0,0,0,40,4449,19.95425,61369.005859375,,,,,,,,,,,,,0,,,,-0.00245,,,,,,19.9984264,,,,
,27956612.525,19.9984846,56628.935546875,0.00516315593919265,6.97692620370906E-7,1,0.999253354069792,40.0298881530762,1.9907914434823,21.4900001883507,0.0580422877191514,0.0109026404103622,0.25,3.79167905318592E-5,0.00516062196944388,7.62926694201453E-5,19.9984245,19.9985447,56624.03515625,56633.8359375,56.4382688595829,20.3728384407077,12.658426,0,0,0,40,4449,19.9555,56628.935546875,,,,,,,,,,,,,0,,,,0,,,,,,19.9984846,,,,
,27956707.795,19.9992847,51866.123046875,0.00508919875824759,9.24168035719592E-7,1,0.999253354069792,40.0298881530762,1.99069746520154,21.5000007301569,0.0571846417189525,0.0107236078141086,0.25,3.59974159825258E-5,0.00508433009772323,7.36243106191222E-5,19.9992847,19.9992847,51855.90625,51876.33984375,56.9166255133522,20.3727888309204,12.658426,0,0,0,40,4449,19.95565,51866.123046875,,,,,,,,,,,,,0,,,,-0.00245,,,,,,19.9992847,,,,
,27956799.21,19.9994755,47298.2734375,0.00501178789858522,7.69056887620082E-7,1,0.999253354069792,40.0298881530762,1.99079048853786,21.4900001883507,0.0562891106529453,0.0105676889582558,0.25,3.67931792983942E-5,0.00500466305251162,7.3502954327241E-5,19.9994755,19.9994755,47283.09375,47313.453125,56.7743691228522,20.3738386330457,12.278775,0,0,0,40,4449,19.9565,47298.2734375,,,,,,,,,,,,,0,,,,-0.00245,,,,,,19.9994755,,,,
,27956892.585,19.9991951,42633.3125,0.00492253997569965,8.57955090208154E-7,1,0.999253354069792,40.0298881530762,1.99093751632055,21.4900001883507,0.0552693218847355,0.0103445542986934,0.25,3.3889814996295E-5,0.00491317636944751,6.9438129887093E-5,19.9991951,19.9991951,42626.1484375,42640.4765625,56.8478422036599,20.3711108567106,12.278775,0,0,0,40,4449,19.95645,42633.3125,,,,,,,,,,,,,0,,,,0,,,,,,19.9991951,,,,
,27956984.86,19.9992123,38017.99609375,0.00482549455184205,7.84569999787994E-7,1,0.999253354069792,40.0298881530762,1.99086493486834,21.4900001883507,0.0541526432283044,0.0101285060492112,0.25,3.3253413781853E-5,0.00481397190757115,6.74309736655621E-5,19.9992123,19.9992123,38008.1875,38027.8046875,56.9744660237753,20.37161567992,12.278775,0,0,0,40,4449,19.9576,38017.99609375,,,,,,,,,,,,,0,,,,-0.00245,,,,,,19.9992123,,,,
,27957079.45,19.9973564,33293.197265625,0.00471595166890072,8.23908215541158E-7,1,0.999253354069792,40.0298881530762,1.99099092148115,21.5000007301569,0.0529049514689287,0.00986662199758447,0.25,3.0864839534812E-5,0.00470234868387102,6.34174241188424E-5,19.9973564,19.9973564,33285.6640625,33300.73046875,56.7391958394868,20.3706572845116,12.658426,0,0,0,40,4449,19.9604,33293.197265625,,,,,,,,,,,,,0,,,,-0.00245,,,,,,19.9973564,,,,
,27957172.85,19.999445,28625.8095703125,0.00460259670051521,7.09858943988337E-7,1,0.999253354069792,40.0298881530762,1.99083147195663,21.4900001883507,0.0516041995481946,0.00962269387511461,0.25,3.09830735185681E-5,0.00458706482085508,6.17473997738565E-5,19.999445,19.999445,28618.470703125,28633.1484375,56.7626446950637,20.3752506177307,12.278775,0,0,0,40,4449,19.9607,28625.8095703125,,,,,,,,,,,,,0,,,,-0.00245,,,,,,19.999445,,,,
,27957267.26,19.9984608,23905.228515625,0.0044783001710205,6.53332014338654E-7,1,0.999253354069792,40.0298881530762,1.99083016380416,21.4900001883507,0.0501877304132233,0.0093493567283449,0.25,3.04880222234328E-5,0.00446102174247946,5.92597013278174E-5,19.9984608,19.9984608,23894.87109375,23915.5859375,56.7767140084099,20.3743313517595,12.658426,0,0,0,40,4449,19.96155,23905.228515625,,,,,,,,,,,,,0,,,,0.00245,,,,,,19.9984608,,,,
,27957361.57,19.998848,19192.5146484375,0.00434461634817002,7.72691948609549E-7,1,0.999253354069792,40.0298881530762,1.99085725061991,21.4900001883507,0.0486690902664561,0.00905698384498491,0.25,3.0018699501133E-5,0.00432583790778608,5.66503704518891E-5,19.998848,19.998848,19187.484375,19197.544921875,56.7939098358329,20.37657805453,12.658426,0,0,0,40,4449,19.9624,19192.5146484375,,,,,,,,,,,,,0,,,,0,,,,,,19.998848,,,,
,27957453.295,19.9986477,14607.87890625,0.00420349586122198,4.89866171387437E-7,1,0.999253354069792,40.0298881530762,1.99089074841497,21.4900001883507,0.0470697489097484,0.0087540727015383,0.25,2.98944746597308E-5,0.00418353845328063,5.43327776946935E-5,19.9986477,19.9986477,14600.3349609375,14615.4228515625,56.5000175126021,20.3764047992503,12.278775,0,0,0,40,4449,19.96445,14607.87890625,,,,,,,,,,,,,0,,,,0,,,,,,19.9986477,,,,
,27957548.24,19.9994049,9863.21484375,0.00404533664262995,5.7565019927319E-7,1,0.999253354069792,40.0298881530762,1.99092598474977,21.4900001883507,0.045282763466472,0.00841199264140628,0.25,2.93138814260658E-5,0.00402449929178105,5.14308532243117E-5,19.9994049,19.9994049,9853.162109375,9873.267578125,57.2707032325638,20.3767308089777,12.658426,0,0,0,40,4449,19.96395,9863.21484375,,,,,,,,,,,,,0,,,,-0.0049,,,,,,19.9994049,,,,
,27957640.585,19.9986706,5245.22021484375,0.00387484794793567,6.29563577011724E-7,1,0.999253354069792,40.0298881530762,1.9910081306656,21.4900001883507,0.0433622497898136,0.00804793015308772,0.25,2.8750640126362E-5,0.00385355365841431,4.86193365459753E-5,19.9986515,19.9986897,5240.18505859375,5250.25537109375,56.8642564025637,20.3755087721703,11.899124,0,0,0,40,4449,19.96585,5245.22021484375,,,,,,,,,,,,,0,,,,-0.0049,,,,,,19.9986706,,,,
,27957732.82,20.0002594,633.7373046875,0.00366962502321774,4.75739131980215E-7,1,0.999253354069792,40.0298881530762,1.99104089289361,21.4900001883507,0.0410558560622343,0.00761576435238453,0.25,2.79621563019776E-5,0.0036484687598818,4.56791537479575E-5,20.0002594,20.0002594,626.086853027344,641.387756347656,56.8712910592368,20.3749829579581,12.658426,0,0,0,40,4449,19.9658,633.7373046875,,,,,,,,,,,,,0,,,,-0.0049,,,,,,20.0002594,,,,
,27957745.165,20.0011845,-0.167461507022381,0.00364059639421039,4.77741196779906E-7,1,0.999253354069792,40.0298881530762,1.99096176067404,21.4900001883507,0.0407292682529947,0.00755133766609859,0.25,2.75050508278968E-5,0.00361952642313378,4.49863693489215E-5,20.0011845,20.0011845,-0.182685270905495,-0.152237743139267,56.8142321773329,20.3768424423491,12.658426,0,0,0,40,4417,19.96665,-0.167461507022381,,,,,,,,,,,,,0,,,,-0.00245,,,,,,20.0011845,,,,