File: data/monolayers/nanoparticles/Ac_CoFe_C_2/vsm/data_dispersion/YF45_HYST_10K.DAT
[Header]
; VSM Data File (default extension .dat)
; Copyright (c) 2003-2013, Quantum Design, Inc. All rights reserved.
TITLE,
FILEOPENTIME,27935559.81,11/20/2018,3:53 pm
BYAPP,VSM,2.0,2.0
INFO,PPMS VSM Option Release 1.4.10 Build 1,APPNAME
INFO,Quantum Design Linear Motor Servo Controller,MOTOR_MODULE_NAME
INFO,3101-100 M1,MOTOR_HW_VERSION
INFO,MMC1014,MOTOR_SERIAL_NUMBER
INFO,SRV No X-over 01.03.11,MOTOR_SOFTWARE_VERSION
INFO,Quantum Design VSM Detection Module,VSM_MODULE_NAME
INFO,3101-150 F0,VSM_HW_VERSION
INFO,VSM707,VSM_SERIAL_NUMBER
INFO,VSM No X-over 01.02.05 May 20 2008 13:51:47,VSM_SOFTWARE_VERSION
INFO,704,PREAMP_SERIAL_NUMBER
INFO,822,COIL_SERIAL_NUMBER
INFO,0,MOMENT_UNITS
INFO,CoFe2O4,SAMPLE_MATERIAL
INFO,dispersion in ampulle,SAMPLE_COMMENT
INFO,,SAMPLE_MASS
INFO,,SAMPLE_VOLUME
INFO,,SAMPLE_MOLECULAR_WEIGHT
INFO,,SAMPLE_SIZE
INFO,,SAMPLE_SHAPE
DATATYPE,COMMENT,1
DATATYPE,TIME,2
STARTUPAXIS,X,2
STARTUPAXIS,Y1,5
[Data]
Comment,Time Stamp (sec),Temperature (K),Magnetic Field (Oe),Moment (emu),M. Std. Err. (emu),Transport Action,Averaging Time (sec),Frequency (Hz),Peak Amplitude (mm),Center Position (mm),Coil Signal' (mV),Coil Signal" (mV),Range (mV),M. Quad. Signal (emu),M. Raw' (emu),M. Raw" (emu),Min. Temperature (K),Max. Temperature (K),Min. Field (Oe),Max. Field (Oe),Mass (grams),Motor Lag (deg),Pressure (Torr),VSM Status (code),Motor Status (code),Measure Status (code),Measure Count,PPMS Status (code),System Temp. (K),System Field (Oe),Sample Position (deg),Bridge 1 Resistance (ohms),Bridge 1 Excitation (에),Bridge 2 Resistance (ohms),Bridge 2 Excitation (에),Bridge 3 Resistance (ohms),Bridge 3 Excitation (에),Bridge 4 Resistance (ohms),Bridge 4 Excitation (에),Signal 1 Vin (V),Signal 2 Vin (V),Digital Inputs (code),Drive 1 Iout (mA),Drive 1 Ipower (W),Drive 2 Iout (mA),Drive 2 Ipower (W),Pressure (),Map 20 (),Map 21 (),Map 22 (),Map 23 (),Map 24 (),Map 25 (),Map 26 (),Map 27 (),Map 28 (),Map 29 ()
,27935573.84,9.9952898,-0.289251685142517,,,2,,,,21.2100003269315,,,,,,,9.9952898,9.9952898,-0.289251685142517,-0.289251685142517,,,11.519473,,,,-99999999,4369,9.9841,-0.289251685142517,,,,,,,,,,,,,,,,,,,,,,,9.9952898,,,,
,27935729.51,10.0149603,4663.00219726562,0.000199173407991031,3.50621817362707E-7,1,0.999253354069792,40.0298881530762,1.98938950066996,21.1999993771315,0.00222576417402732,0.000420763596745261,0.25,2.1535784007559E-6,0.00019806881732219,3.15827716182453E-6,10.0149603,10.0149603,4655.521484375,4670.48291015625,55.443255754602,20.3622072280397,11.519473,0,0,0,40,4449,9.9561,4663.00219726562,,,,,,,,,,,,,0,,,,0.0049,,,,,,10.0149603,,,,
,27935829.28,10.0132227,9652.138671875,0.000699118216995174,4.73805259109519E-7,1,0.999253354069792,40.0298881530762,1.98921990727293,21.1999993771315,0.00781553054064335,0.00147376105820603,0.25,6.9843475095296E-6,0.000695498780263151,1.0771548724244E-5,10.0128431,10.0136023,9647.1103515625,9657.1669921875,56.2428617297752,20.3669063026867,11.139823,0,0,0,40,4449,9.94995,9652.138671875,,,,,,,,,,,,,0,,,,-0.00735,,,,,,10.0132227,,,,
,27935929.43,10.0123577,14656.7998046875,0.0013396848163539,5.70192648922113E-7,1,0.999253354069792,40.0298881530762,1.98876757141776,21.1999993771315,0.0149837587191571,0.00280164786415968,0.25,1.0839085947801E-5,0.00133332989758785,1.86026453727642E-5,10.0123577,10.0123577,14649.5068359375,14664.0927734375,56.2061251893713,20.3737610240512,11.139823,0,0,0,40,4449,9.94045,14656.7998046875,,,,,,,,,,,,,0,,,,0,,,,,,10.0123577,,,,
,27936028.275,10.00746345,19596.794921875,0.00233138447867894,8.62806588467617E-7,1,0.999253354069792,40.0298881530762,1.98842360913155,21.1999993771315,0.0260856990186598,0.0048632062701018,0.25,1.68455959167853E-5,0.00232140725354106,3.11608692213002E-5,10.0073748,10.0075521,19591.947265625,19601.642578125,56.4007506906598,20.3782314868911,11.519473,0,0,0,40,4449,9.9321,19596.794921875,,,,,,,,,,,,,0,,,,0,,,,,,10.00746345,,,,
,27936128,10.0044003,24579.4912109375,0.00372140229258022,7.50108776941697E-7,1,0.999253354069792,40.0298881530762,1.98869036425242,21.1999993771315,0.0416636999889229,0.00777234064778434,0.25,2.61782625921258E-5,0.00370731591585019,5.01855661006195E-5,10.0044003,10.0044003,24574.248046875,24584.734375,56.2459882438521,20.3795497190567,11.899124,0,0,0,40,4449,9.9304,24579.4912109375,,,,,,,,,,,,,0,,,,0,,,,,,10.0044003,,,,
,27936219.445,10.0026989,29152.1826171875,0.00477932348848256,8.42811525535628E-7,1,0.999253354069792,40.0298881530762,1.98841921327457,21.1999993771315,0.0535328579184514,0.00994854401053458,0.25,2.91801366954423E-5,0.00476351152120476,6.12161396372907E-5,10.0026989,10.0026989,29142.08203125,29162.283203125,56.3499448369098,20.385041188184,11.899124,0,0,0,40,4449,9.9265,29152.1826171875,,,,,,,,,,,,,0,,,,0.00245,,,,,,10.0026989,,,,
,27936307.335,10.0009909,33542.64453125,0.0053914437729214,7.65961563294725E-7,1,0.999253354069792,40.0298881530762,1.98882802387238,21.1999993771315,0.0604305648847752,0.0112218758188116,0.25,3.11113553455792E-5,0.00537610727828101,6.83543103038209E-5,10.0009909,10.0009909,33535.14453125,33550.14453125,56.4077853473329,20.3835975511376,11.899124,0,0,0,40,4449,9.9267,33542.64453125,,,,,,,,,,,,,0,,,,0,,,,,,10.0009909,,,,
,27936394.71,10.0006351,37910.357421875,0.00578175631325656,9.52930806492432E-7,1,0.999253354069792,40.0298881530762,1.98841978996465,21.1999993771315,0.0648172171546644,0.0120688717910738,0.25,3.52171087535571E-5,0.00576797131281897,7.61240165517294E-5,10.0006351,10.0006351,37902.9453125,37917.76953125,56.2756901275829,20.387028502614,11.519473,0,0,0,40,4449,9.9269,37910.357421875,,,,,,,,,,,,,0,,,,0.0049,,,,,,10.0006351,,,,
,27936479.975,9.9983692,42173.876953125,0.00606235847263058,1.02193923133402E-6,1,0.999253354069792,40.0298881530762,1.98905277043043,21.1999993771315,0.0680111827550971,0.012681751764797,0.25,3.77285939188538E-5,0.00605062775522966,8.14168147731622E-5,9.9983692,9.9983692,42171.44921875,42176.3046875,56.3585427506213,20.3843296197441,11.519473,0,0,0,40,4449,9.9276,42173.876953125,,,,,,,,,,,,,0,,,,0,,,,,,9.9983692,,,,
,27936567.06,9.9972868,46526.337890625,0.00628719994542148,8.77014635021941E-7,1,0.999253354069792,40.0298881530762,1.98896923190212,21.1999993771315,0.0705682598515745,0.0131277466478613,0.25,3.5868976922856E-5,0.00627791206487349,8.18254408195912E-5,9.9972868,9.9972868,46518.92578125,46533.75,56.3085185253906,20.3859968276321,11.519473,0,0,0,40,4449,9.93065,46526.337890625,,,,,,,,,,,,,0,,,,0,,,,,,9.9972868,,,,
,27936654.865,9.9957685,50914.21484375,0.00646700510743441,8.06957375078376E-7,1,0.999253354069792,40.0298881530762,1.98921052236863,21.1999993771315,0.0726310346631466,0.0134909517214304,0.25,3.4699023191532E-5,0.00646036737123062,8.24380552868478E-5,9.9957685,9.9957685,50906.66796875,50921.76171875,56.2584943001598,20.3831412251298,11.139823,0,0,0,40,4449,9.9343,50914.21484375,,,,,,,,,,,,,0,,,,0.00245,,,,,,9.9957685,,,,
,27936745.845,9.9954052,55461.744140625,0.00662815986664392,6.67241565741449E-7,1,0.999253354069792,40.0298881530762,1.98925646811659,21.1999993771315,0.0744786798985483,0.0138204149347872,0.25,3.41260919576127E-5,0.00662436094019064,8.33500029211544E-5,9.9954052,9.9954052,55454.21484375,55469.2734375,56.2014354182559,20.3824736986862,11.139823,0,0,0,40,4449,9.93705,55461.744140625,,,,,,,,,,,,,0,,,,0.0049,,,,,,9.9954052,,,,
,27936842.955,9.9949617,60314.630859375,0.00676255325194627,8.90034075236474E-7,1,0.999253354069792,40.0298881530762,1.98917255978507,21.1999993771315,0.0760236217317528,0.0140925130086326,0.25,3.34898117099234E-5,0.00676182822101409,8.38254073988771E-5,9.9949617,9.9949617,60312.3515625,60316.91015625,56.4156016325252,20.3852654996005,11.519473,0,0,0,40,4449,9.942,60314.630859375,,,,,,,,,,,,,0,,,,0.0049,,,,,,9.9949617,,,,
,27936939.65,9.9950256,65149.8125,0.00688049633811235,9.58897938607154E-7,1,0.999253354069792,40.0298881530762,1.98965577678385,21.1999993771315,0.0774004309722193,0.0143550219429514,0.25,3.48143556918552E-5,0.00688279867938903,8.59518326341119E-5,9.9950256,9.9950256,65139.62109375,65160.00390625,56.6008475915829,20.3801367873723,11.899124,0,0,0,40,4449,9.94775,65149.8125,,,,,,,,,,,,,0,,,,0.00245,,,,,,9.9950256,,,,
,27937034.985,9.9944086,69915.5625,0.00697773645625331,1.28057624988105E-6,1,0.999253354069792,40.0298881530762,1.98973005070332,21.1999993771315,0.0785297830677172,0.0145637926201753,0.25,3.55235918801874E-5,0.006982966725646,8.71439233048027E-5,9.9944086,9.9944086,69907.9765625,69923.1484375,56.4210730321598,20.3819312371656,11.519473,0,0,0,40,4449,9.95225,69915.5625,,,,,,,,,,,,,0,,,,0,,,,,,9.9944086,,,,
,27937130.34,9.9955235,74678.015625,0.00705597707740154,1.00310084740647E-6,1,0.999253354069792,40.0298881530762,1.98978566536126,21.1999993771315,0.0794432426510639,0.0147353339541957,0.25,3.65226265702287E-5,0.00706403590799751,8.83391915231059E-5,9.9955235,9.9955235,74675.34375,74680.6875,56.4906379703714,20.3802193818795,11.519473,0,0,0,40,4449,9.9562,74678.015625,,,,,,,,,,,,,0,,,,0,,,,,,9.9955235,,,,
,27937222.775,9.9948778,79301.15625,0.00711913520350908,1.08143555425703E-6,1,0.999253354069792,40.0298881530762,1.98982584556124,21.1999993771315,0.08018413401446,0.0148761273499438,0.25,3.76600792933994E-5,0.00712982808139558,8.94517707023257E-5,9.9948778,9.9948778,79293.546875,79308.765625,56.8454973181022,20.3807709223232,11.899124,0,0,0,40,4449,9.9599,79301.15625,,,,,,,,,,,,,0,,,,-0.00245,,,,,,9.9948778,,,,
,27937319.82,9.9947281,84152.12109375,0.00717156617335147,9.05314212332761E-7,1,0.999253354069792,40.0298881530762,1.98982466687825,21.1999993771315,0.0808143846645361,0.0149295042197131,0.25,3.3134682328167E-5,0.00718492795680287,8.46794609451117E-5,9.9947281,9.9947281,84147.1953125,84157.046875,56.6665043871983,20.3811625271239,11.139823,0,0,0,40,4449,9.96545,84152.12109375,,,,,,,,,,,,,0,,,,-0.00245,,,,,,9.9947281,,,,
,27937410.18,9.9942875,88667.96484375,0.00720350279293805,1.13043895454936E-6,1,0.999253354069792,40.0298881530762,1.99015032527057,21.1999993771315,0.0812022195057457,0.0150582676413737,0.25,3.88637019497382E-5,0.0072191301077924,8.999283322929E-5,9.9942875,9.9942875,88660.421875,88675.5078125,56.6094455052945,20.3791895392666,11.899124,0,0,0,40,4449,9.97035,88667.96484375,,,,,,,,,,,,,0,,,,-0.00245,,,,,,9.9942875,,,,
,27937515.545,9.996932,87090.80078125,0.00719783927784015,1.15671252664013E-6,1,0.999253354069792,40.0298881530762,1.98994416549932,21.1999993771315,0.0811257368665846,0.0150210626470769,0.25,3.66129324943498E-5,0.00721270173950517,8.79335170775025E-5,9.996932,9.996932,87078.171875,87103.4296875,56.4773502855444,20.3797597488443,11.139823,0,0,0,40,4449,9.9706,87090.80078125,,,,,,,,,,,,,0,,,,0,,,,,,9.996932,,,,
,27937606.77,9.9997272,82531.94140625,0.00715779736395179,1.25131107437989E-6,1,0.999253354069792,40.0298881530762,1.99011295952824,21.1999993771315,0.0806539691321809,0.0149403623438624,0.25,3.63191426304787E-5,0.00717027609869787,8.79880634011257E-5,9.9997272,9.9997272,82524.484375,82539.3984375,56.6883899857368,20.3807680906606,11.139823,0,0,0,40,4449,9.97205,82531.94140625,,,,,,,,,,,,,0,,,,-0.00245,,,,,,9.9997272,,,,
,27937704.19,10.0017214,77663.4609375,0.00710646217582025,1.16961680222263E-6,1,0.999253354069792,40.0298881530762,1.990159219015,21.1999993771315,0.0800501544200669,0.0148170501264111,0.25,3.44601702895925E-5,0.00711626759031491,8.63400502645975E-5,10.0017214,10.0017214,77656.0078125,77670.9140625,56.7087123272368,20.3800463201977,11.899124,0,0,0,40,4449,9.96925,77663.4609375,,,,,,,,,,,,,0,,,,0,,,,,,10.0017214,,,,
,27937802.665,10.0023766,72739.125,0.00703759727058965,9.69170481030086E-7,1,0.999253354069792,40.0298881530762,1.99050731743935,21.1999993771315,0.0792501135642371,0.0147062837553825,0.25,3.68241666837404E-5,0.00704452416838297,8.86772001495598E-5,10.0023766,10.0023766,72735.7890625,72742.4609375,56.7993812354675,20.3771420985842,10.760172,0,0,0,40,4449,9.966,72739.125,,,,,,,,,,,,,0,,,,-0.0049,,,,,,10.0023766,,,,
,27937900.275,10.0022964,67859.39453125,0.00695624381359993,8.22102601105658E-7,1,0.999253354069792,40.0298881530762,1.99047493728586,21.1999993771315,0.0782929409439259,0.0145722822790832,0.25,3.97789851132117E-5,0.00696019779311769,9.13645645175818E-5,10.0022964,10.0022964,67854.5,67864.2890625,56.6211699330829,20.3774315685416,11.139823,0,0,0,40,4449,9.9636,67859.39453125,,,,,,,,,,,,,0,,,,-0.0049,,,,,,10.0022964,,,,
,27937995.11,10.0015383,63116.38671875,0.00686159580889246,8.15686188187676E-7,1,0.999253354069792,40.0298881530762,1.99045667085844,21.1999993771315,0.0771918473053527,0.0143820880693873,0.25,4.02992140880687E-5,0.00686259053616461,9.13506320544796E-5,10.0015383,10.0015383,63111.1640625,63121.609375,56.7016776705637,20.3771985934257,11.139823,0,0,0,40,4449,9.96215,63116.38671875,,,,,,,,,,,,,0,,,,0,,,,,,10.0015383,,,,
,27938095.43,10.002285,58105.35546875,0.00674777040928887,9.41053776403465E-7,1,0.999253354069792,40.0298881530762,1.99038081495304,21.1999993771315,0.0758709010312949,0.0141482548179353,0.25,4.06513644470165E-5,0.00674558239189851,9.08484514717181E-5,10.002285,10.002285,58097.78125,58112.9296875,56.7923465787945,20.3767796944218,11.519473,0,0,0,40,4449,9.9598,58105.35546875,,,,,,,,,,,,,0,,,,0.00245,,,,,,10.002285,,,,
,27938192.47,10.003006,53254.552734375,0.00661707416160221,1.05079410963878E-6,1,0.999253354069792,40.0298881530762,1.99041068250776,21.1999993771315,0.0743688709988075,0.0138587933099855,0.25,3.92224046214629E-5,0.00661180490798248,8.8241893610883E-5,10.003006,10.003006,53249.8515625,53259.25390625,56.5047072837175,20.3768868093427,11.139823,0,0,0,40,4449,9.9572,53254.552734375,,,,,,,,,,,,,0,,,,0,,,,,,10.003006,,,,
,27938289.97,10.0024185,48379.71484375,0.00646589788916969,8.29653843798738E-7,1,0.999253354069792,40.0298881530762,1.99031640285623,21.1999993771315,0.0726317126246881,0.0135293778623397,0.25,3.8212806161251E-5,0.00645756934360311,8.56942397579025E-5,10.0024185,10.0024185,48377.29296875,48382.13671875,56.6907348712945,20.3777503119493,11.139823,0,0,0,40,4449,9.9548,48379.71484375,,,,,,,,,,,,,0,,,,0.0049,,,,,,10.0024185,,,,
,27938385.67,10.0044231,43596.9375,0.00629245217628287,7.61194231585387E-7,1,0.999253354069792,40.0298881530762,1.99026732512373,21.1999993771315,0.0706483883555582,0.0131497487448262,0.25,3.6895861878342E-5,0.00628123159640659,8.24785798027447E-5,10.0044231,10.0044231,43589.62109375,43604.25390625,56.9275683126214,20.3770413982033,11.139823,0,0,0,40,4449,9.951,43596.9375,,,,,,,,,,,,,0,,,,-0.0049,,,,,,10.0044231,,,,
,27938477.835,10.0030403,38989.59765625,0.00610788980534852,5.96574501274039E-7,1,0.999253354069792,40.0298881530762,1.99071243280884,21.1999993771315,0.0685565694157645,0.0127655269765911,0.25,3.70244021731383E-5,0.00609402633506341,8.04609845290391E-5,10.0030403,10.0030403,38977.4765625,39001.71875,56.5602029085829,20.3753482314903,11.519473,0,0,0,40,4449,9.94895,38989.59765625,,,,,,,,,,,,,0,,,,0,,,,,,10.0030403,,,,
,27938573.32,10.00115965,34219.79296875,0.00589333116260605,6.15682199003348E-7,1,0.999253354069792,40.0298881530762,1.99059790218975,21.1999993771315,0.0661130738578831,0.0122991914603099,0.25,3.57482173917047E-5,0.00587697704879567,7.6620234377619E-5,10.000864,10.0014553,34214.71875,34224.8671875,56.6219515616021,20.3777365706539,11.139823,0,0,0,40,4449,9.9481,34219.79296875,,,,,,,,,,,,,0,,,,0.00245,,,,,,10.00115965,,,,
,27938670.6,10.0016975,29357.412109375,0.00565190346809587,6.11150605831517E-7,1,0.999253354069792,40.0298881530762,1.99054430808473,21.1999993771315,0.0633704888319666,0.0117885412765133,0.25,3.54657645464841E-5,0.00563331923496468,7.34057883334836E-5,10.0016975,10.0016975,29347.458984375,29367.365234375,56.5813068786021,20.3766679121294,11.519473,0,0,0,40,4449,9.94745,29357.412109375,,,,,,,,,,,,,0,,,,0.0049,,,,,,10.0016975,,,,
,27938769.89,10.0004702,24394.2744140625,0.00537721687448572,5.83618006995536E-7,1,0.999253354069792,40.0298881530762,1.9906522694129,21.1999993771315,0.0602611292515834,0.0112194556962229,0.25,3.59664566617786E-5,0.0053567740826048,7.06044249480393E-5,10.0004702,10.0004702,24388.998046875,24399.55078125,56.6633778731214,20.3786285428074,11.139823,0,0,0,40,4449,9.94705,24394.2744140625,,,,,,,,,,,,,0,,,,-0.0049,,,,,,10.0004702,,,,
,27938863.725,9.9995842,19701.8212890625,0.00509709725580771,5.2139014704585E-7,1,0.999253354069792,40.0298881530762,1.99062499902499,21.1999993771315,0.0570929682671963,0.0106380147130733,0.25,3.62826020799924E-5,0.00507533909585002,6.76176126447886E-5,9.9995842,9.9995842,19696.689453125,19706.953125,56.9158438848329,20.3784369629517,10.760172,0,0,0,40,4449,9.9477,19701.8212890625,,,,,,,,,,,,,0,,,,0,,,,,,9.9995842,,,,
,27938961.26,9.9983301,14829.5942382812,0.00478249350377809,6.64881979316314E-7,1,0.999253354069792,40.0298881530762,1.99065969989436,21.1999993771315,0.0535502396546696,0.00995017349301816,0.25,3.32326085857333E-5,0.00475991311373567,6.10323382314485E-5,9.9983301,9.9983301,14824.53125,14834.6572265625,56.8306463762368,20.3806427469224,11.519473,0,0,0,40,4449,9.94815,14829.5942382812,,,,,,,,,,,,,0,,,,-0.00245,,,,,,9.9983301,,,,
,27939056.35,9.9976721,10074.5390625,0.00445463743796393,6.00408692661204E-7,1,0.999253354069792,40.0298881530762,1.99066940349245,21.1999993771315,0.0498592750694519,0.00926287438468966,0.25,3.23641933710401E-5,0.00443179219419676,5.66978751684103E-5,9.9976721,9.9976721,10067.0185546875,10082.0595703125,56.7313795542945,20.3808427865829,11.139823,0,0,0,40,4449,9.94795,10074.5390625,,,,,,,,,,,,,0,,,,0.00245,,,,,,9.9976721,,,,
,27939151.11,9.9977512,5341.9345703125,0.00410208758289494,4.99307189286229E-7,1,0.999253354069792,40.0298881530762,1.99075997812488,21.2099999189377,0.0459004385783706,0.00851839910260306,0.25,3.0450222179907E-5,0.00407959598178063,5.14185936267252E-5,9.9977512,9.9977512,5334.5234375,5349.345703125,56.4796951711021,20.3793179892339,10.760172,0,0,0,40,4449,9.951,5341.9345703125,,,,,,,,,,,,,0,,,,0,,,,,,9.9977512,,,,
,27939246.775,10.0013599,558.088073730469,0.00371453564497523,4.33532880842396E-7,1,0.999253354069792,40.0298881530762,1.99072455694687,21.1999993771315,0.0415535070726337,0.00770014868691835,0.25,2.77269552835288E-5,0.00369313542658352,4.55570161195025E-5,10.0013599,10.0013599,545.533264160156,570.642883300781,56.6547799594098,20.380258536202,11.519473,0,0,0,40,4449,9.95,558.088073730469,,,,,,,,,,,,,0,,,,0,,,,,,10.0013599,,,,
,27939340.985,9.9981747,-4145.46704101562,0.00328200605577864,5.01714386236741E-7,1,0.999253354069792,40.0298881530762,1.99081430524797,21.1999993771315,0.0367239052197363,0.00680503106601159,0.25,2.37465652415752E-5,0.00326375385728694,4.02466408437247E-5,9.9981747,9.9981747,-4147.93798828125,-4142.99609375,56.3773018350829,20.3810539058074,11.519473,0,0,0,40,4449,9.95085,-4145.46704101562,,,,,,,,,,,,,0,,,,0,,,,,,9.9981747,,,,
,27939436.915,9.9989996,-8942.0830078125,0.00273942175267552,4.67860083446725E-7,1,0.999253354069792,40.0298881530762,1.99081660348383,21.1999993771315,0.0306643676423129,0.00567627956249127,0.25,1.83564016481305E-5,0.00272513543531399,3.30973523653761E-5,9.9989996,9.9989996,-8947.19921875,-8936.966796875,56.0935706826021,20.380828033898,11.139823,0,0,0,40,4449,9.9511,-8942.0830078125,,,,,,,,,,,,,0,,,,-0.00245,,,,,,9.9989996,,,,
,27939533.48,10.0002041,-13770.0268554687,0.00190294551082626,7.45970359927766E-7,1,0.999253354069792,40.0298881530762,1.99087881665092,21.1999993771315,0.0213102736083503,0.00394513622364561,0.25,1.21127337673637E-5,0.0018937885359608,2.30341997709123E-5,10.0002041,10.0002041,-13779.7998046875,-13760.25390625,56.8408075469868,20.3803769586318,11.139823,0,0,0,40,4449,9.95165,-13770.0268554687,,,,,,,,,,,,,0,,,,-0.00245,,,,,,10.0002041,,,,
,27939633.265,10.0003138,-18757.64453125,0.000295915693919188,1.13728573002251E-6,1,0.999253354069792,40.0298881530762,1.99090966563296,21.1999993771315,0.00331741750261989,0.000602570299133219,0.25,7.82386771740149E-7,0.00029463383277464,2.58871206514694E-6,10.0003138,10.0003138,-18767.720703125,-18747.568359375,56.6946430138906,20.3814268799536,11.519473,0,0,0,40,4449,9.95125,-18757.64453125,,,,,,,,,,,,,0,,,,0,,,,,,10.0003138,,,,
,27939727.82,9.9997959,-23479.50390625,-0.00191288645055825,1.17421152501289E-6,1,0.999253354069792,40.0298881530762,1.99085088757644,21.1999993771315,-0.0214325267222489,-0.00401780028753194,0.25,-1.52664785106762E-5,-0.00190542192468596,-2.74752315307522E-5,9.9997959,9.9997959,-23489.501953125,-23469.505859375,56.4140383754867,20.3805383247302,11.519473,0,0,0,40,4449,9.9511,-23479.50390625,,,,,,,,,,,,,0,,,,0.00245,,,,,,9.9997959,,,,
,27939825.865,10.0005331,-28382.1484375,-0.00388105041265046,8.79549459235004E-7,1,0.999253354069792,40.0298881530762,1.99097347391627,21.1999993771315,-0.0435153302907494,-0.00812053719475721,0.25,-2.67454450804699E-5,-0.00386787881054401,-5.25975719046064E-5,10.0005331,10.0005331,-28387.1953125,-28377.1015625,57.068261446083,20.3841134292152,10.760172,0,0,0,40,4449,9.9508,-28382.1484375,,,,,,,,,,,,,0,,,,-0.00245,,,,,,10.0005331,,,,
,27939922.78,9.9998207,-33224.251953125,-0.00503930266231541,7.45641056122527E-7,1,0.999253354069792,40.0298881530762,1.99092333476052,21.1999993771315,-0.0565306512498802,-0.0105425764172416,0.25,-3.30153872769349E-5,-0.00502477108385825,-6.77461124582579E-5,9.9998207,9.9998207,-33229.32421875,-33219.1796875,56.7188734979868,20.3815991309262,10.760172,0,0,0,40,4449,9.9514,-33224.251953125,,,,,,,,,,,,,0,,,,0,,,,,,9.9998207,,,,
,27940019.245,10.0002499,-38046.3125,-0.00569152093771116,6.91143856508303E-7,1,0.999253354069792,40.0298881530762,1.99095277944426,21.1999993771315,-0.0638784069940634,-0.0119270891845911,0.25,-3.74853542431297E-5,-0.0056780130470419,-7.77739627593245E-5,10.0002499,10.0002499,-38051.2890625,-38041.3359375,56.455464687006,20.3821461784565,10.760172,0,0,0,40,4449,9.9523,-38046.3125,,,,,,,,,,,,,0,,,,0,,,,,,10.0002499,,,,
,27940107.78,9.9992762,-42471.748046875,-0.00607560094476134,7.99962639082132E-7,1,0.999253354069792,40.0298881530762,1.99092222830638,21.1999993771315,-0.068215785937607,-0.012761639110586,0.25,-4.13568221075971E-5,-0.00606400908058103,-8.51825821281394E-5,9.9992762,9.9992762,-42479.1171875,-42464.37890625,56.8447156895829,20.3824984632702,11.519473,0,0,0,40,4449,9.9522,-42471.748046875,,,,,,,,,,,,,0,,,,0.00245,,,,,,9.9992762,,,,
,27940197.43,9.999012,-46951.525390625,-0.00634897813850608,7.77900858895682E-7,1,0.999253354069792,40.0298881530762,1.9909643735296,21.1999993771315,-0.071320157013535,-0.013341654077543,0.25,-4.25413399966241E-5,-0.00633983145341012,-8.89932955296029E-5,9.999012,9.999012,-46961.72265625,-46941.328125,56.6516534453329,20.3832116270732,11.139823,0,0,0,40,4449,9.95385,-46951.525390625,,,,,,,,,,,,,0,,,,0.00245,,,,,,9.999012,,,,
,27940288.055,9.9969492,-51481.740234375,-0.00655538927192291,7.84681424471168E-7,1,0.999253354069792,40.0298881530762,1.99070373187207,21.1999993771315,-0.073665493953253,-0.0137701169021985,0.25,-4.26150842511989E-5,-0.00654898040270342,-9.10465941081875E-5,9.9969492,9.9969492,-51484.2265625,-51479.25390625,56.7845302936022,20.3833050531742,11.139823,0,0,0,40,4449,9.9549,-51481.740234375,,,,,,,,,,,,,0,,,,0,,,,,,9.9969492,,,,
,27940376.82,9.9959469,-55916.39453125,-0.00671348630016188,9.43946209877501E-7,1,0.999253354069792,40.0298881530762,1.99065918272527,21.1999993771315,-0.0754749163285335,-0.0141009905011688,0.25,-4.27785386484328E-5,-0.00670987497054635,-9.26512743079701E-5,9.9959469,9.9959469,-55926.30859375,-55906.48046875,56.861911517006,20.3882270156876,11.519473,0,0,0,40,4449,9.95995,-55916.39453125,,,,,,,,,,,,,0,,,,0.0049,,,,,,9.9959469,,,,
,27940463.54,9.9959965,-60252.29296875,-0.00683830313631272,9.15907716301535E-7,1,0.999253354069792,40.0298881530762,1.99075842841865,21.1999993771315,-0.0769131656872338,-0.0143726267385585,0.25,-4.37660289541566E-5,-0.00683745632428275,-9.46644942856772E-5,9.9959965,9.9959965,-60260.05859375,-60244.52734375,56.7798405224868,20.3869110243885,10.760172,0,0,0,40,4449,9.9623,-60252.29296875,,,,,,,,,,,,,0,,,,0,,,,,,9.9959965,,,,
,27940552.995,9.9965906,-64721.98828125,-0.00694650060658154,9.7403344903644E-7,1,0.999253354069792,40.0298881530762,1.99079621121132,21.2099999189377,-0.0781596802805247,-0.0146278444615524,0.25,-4.64703281307526E-5,-0.00694847473566201,-9.81160231749977E-5,9.9965906,9.9965906,-64726.98046875,-64716.99609375,56.7321611828137,20.3871876941544,11.139823,0,0,0,40,4449,9.9666,-64721.98828125,,,,,,,,,,,,,0,,,,0,,,,,,9.9965906,,,,
,27940641.625,9.995635,-69151.83203125,-0.00703739195589971,9.4942487362308E-7,1,0.999253354069792,40.0298881530762,1.99062247343499,21.1999993771315,-0.0792044410609809,-0.0148351192640836,0.25,-4.83278075237691E-5,-0.00704211637701008,-0.000100447327446037,9.995635,9.995635,-69159.1328125,-69144.53125,56.7970363499099,20.3940208900436,11.519473,0,0,0,40,4449,9.9698,-69151.83203125,,,,,,,,,,,,,0,,,,0.0049,,,,,,9.995635,,,,
,27940730.175,9.9960775,-73576.44921875,-0.00711159966071052,6.9497273073372E-7,1,0.999253354069792,40.0298881530762,1.99031097976322,21.2099999189377,-0.080057639901217,-0.014992309871505,0.25,-4.89802464461742E-5,-0.0071189996270164,-0.000101319282071202,9.9960775,9.9960775,-73581.265625,-73571.6328125,56.7180918694675,20.3915370080482,10.760172,0,0,0,40,4449,9.9725,-73576.44921875,,,,,,,,,,,,,0,,,,-0.0049,,,,,,9.9960775,,,,
,27940819.245,9.9949951,-78026.52734375,-0.00717361988083674,1.04498764297692E-6,1,0.999253354069792,40.0298881530762,1.99059788635011,21.1999993771315,-0.0807949281582418,-0.0151327008442608,0.25,-5.0086247016607E-5,-0.00718360755437879,-0.000102438103699151,9.9949951,9.9949951,-78033.9453125,-78019.109375,56.7579549239483,20.3888772530911,11.139823,0,0,0,40,4449,9.9769,-78026.52734375,,,,,,,,,,,,,0,,,,0.00245,,,,,,9.9949951,,,,
,27940915.65,9.9951591,-82846.37890625,-0.00722953022293171,1.02640346111828E-6,1,0.999253354069792,40.0298881530762,1.99059376315156,21.2099999189377,-0.0814605879129036,-0.0152178670095883,0.25,-4.77144744150876E-5,-0.00724221949421773,-9.98793415013833E-5,9.9951591,9.9951591,-82856.484375,-82836.2734375,56.5656743082175,20.3919358713043,11.139823,0,0,0,40,4449,9.9798,-82846.37890625,,,,,,,,,,,,,0,,,,-0.00245,,,,,,9.9951591,,,,
,27941005.745,9.9960051,-87351.05078125,-0.007268798442342,1.38256501031897E-6,1,0.999253354069792,40.0298881530762,1.9905845926545,21.1999993771315,-0.0819318180999831,-0.0152869987219849,0.25,-4.70208130590528E-5,-0.00728386513328578,-9.8829734510981E-5,9.9960051,9.9960051,-87358.59375,-87343.5078125,56.6414922745829,20.3904379547443,11.519473,0,0,0,40,4449,9.9837,-87351.05078125,,,,,,,,,,,,,0,,,,0,,,,,,9.9960051,,,,
,27941116.08,9.9975815,-88195.67578125,-0.00727983064343039,1.18515458320295E-6,1,0.999253354069792,40.0298881530762,1.99047236556607,21.1999993771315,-0.0820517946178328,-0.0153360246914948,0.25,-4.95088798041264E-5,-0.00729531993291501,-0.000101274408050553,9.9975815,9.9975815,-88203.21875,-88188.1328125,56.8040710065829,20.3904434774224,11.139823,0,0,0,40,4449,9.98805,-88195.67578125,,,,,,,,,,,,,0,,,,0,,,,,,9.9975815,,,,
,27941209.75,9.9995384,-83516.4453125,-0.00723862579085735,9.9995280547006E-7,1,0.999253354069792,40.0298881530762,1.99060895580909,21.1999993771315,-0.0815682980289219,-0.015233946741417,0.25,-4.75223391746242E-5,-0.00725168249370424,-9.96625609056873E-5,9.9995384,9.9995384,-83526.484375,-83506.40625,56.8650380310829,20.3911821272323,10.760172,0,0,0,40,4449,9.98755,-83516.4453125,,,,,,,,,,,,,0,,,,0,,,,,,9.9995384,,,,
,27941309.02,10.0007696,-78553.77734375,-0.00718682182368411,7.74917494237545E-7,1,0.999253354069792,40.0298881530762,1.99055401938916,21.1999993771315,-0.0809538456464715,-0.0151127317824288,0.25,-4.59754523840686E-5,-0.00719714937733176,-9.83581922920305E-5,10.0007696,10.0007696,-78558.984375,-78548.5703125,56.821266834006,20.3906113141507,10.760172,0,0,0,40,4449,9.98505,-78553.77734375,,,,,,,,,,,,,0,,,,0.0049,,,,,,10.0007696,,,,
,27941407.175,10.0026007,-73646.5625,-0.00711874625967897,1.18839524753001E-6,1,0.999253354069792,40.0298881530762,1.9906889836991,21.1999993771315,-0.0801633637135344,-0.0149530930728163,0.25,-4.39721034203277E-5,-0.0071262313527922,-9.63520354611295E-5,10.0026007,10.0026007,-73656.3359375,-73636.7890625,56.7329428113329,20.3885158529696,10.760172,0,0,0,40,4449,9.98295,-73646.5625,,,,,,,,,,,,,0,,,,0,,,,,,10.0026007,,,,
,27941505.465,10.0029926,-68735.17578125,-0.00704016944873765,1.12925340728604E-6,1,0.999253354069792,40.0298881530762,1.99073208035502,21.1999993771315,-0.0792497276668178,-0.014770804527789,0.25,-4.20696108010811E-5,-0.00704469045536679,-9.42300432904443E-5,10.0029926,10.0029926,-68745.0703125,-68725.28125,56.6156985334483,20.3904743182983,10.760172,0,0,0,40,4449,9.9791,-68735.17578125,,,,,,,,,,,,,0,,,,0.00245,,,,,,10.0029926,,,,
,27941604.535,10.0032043,-63782.765625,-0.00694300699970559,8.69273725470322E-7,1,0.999253354069792,40.0298881530762,1.99073228564723,21.1999993771315,-0.0781259899012116,-0.014537652011616,0.25,-3.92094453575289E-5,-0.00694444579104034,-9.0852194069566E-5,10.0032043,10.0032043,-63793.19140625,-63772.33984375,56.6524350738522,20.3898205809149,10.760172,0,0,0,40,4449,9.97565,-63782.765625,,,,,,,,,,,,,0,,,,-0.0049,,,,,,10.0032043,,,,
,27941704.85,10.0040216,-58770.5546875,-0.0068264076908452,9.32475877343467E-7,1,0.999253354069792,40.0298881530762,1.99038534787247,21.1999993771315,-0.0767646417535711,-0.0142889886266115,0.25,-3.88896048310794E-5,-0.00682464342564662,-8.96849757030477E-5,10.0040216,10.0040216,-58775.34765625,-58765.76171875,56.7149653553906,20.3860186088548,10.760172,0,0,0,40,4449,9.9739,-58770.5546875,,,,,,,,,,,,,0,,,,-0.0049,,,,,,10.0040216,,,,
,27941805.4,10.0034237,-53745.509765625,-0.00668877155417201,9.97691282036998E-7,1,0.999253354069792,40.0298881530762,1.99033411198253,21.1999993771315,-0.0751827652398773,-0.0139692287746993,0.25,-3.60750585340625E-5,-0.00668379716694759,-8.56589309367144E-5,10.0034237,10.0034237,-53758.28125,-53732.73828125,56.6649411301598,20.3906396270216,10.760172,0,0,0,40,4449,9.97055,-53745.509765625,,,,,,,,,,,,,0,,,,0.00245,,,,,,10.0034237,,,,
,27941903.06,10.0034428,-48866.01953125,-0.00653225135945594,7.20798047713052E-7,1,0.999253354069792,40.0298881530762,1.99032748231035,21.1999993771315,-0.0733888564865261,-0.0136259860649763,0.25,-3.47341631025094E-5,-0.00652419066704829,-8.27601337231752E-5,10.0034428,10.0034428,-48875.86328125,-48856.17578125,56.8181403199291,20.3901064871739,10.760172,0,0,0,40,4449,9.9674,-48866.01953125,,,,,,,,,,,,,0,,,,0.0049,,,,,,10.0034428,,,,
,27942002.355,10.0049076,-43903.203125,-0.00635509906283921,7.90089580647753E-7,1,0.999253354069792,40.0298881530762,1.99041053231901,21.1999993771315,-0.0713600706710917,-0.0132757834489204,0.25,-3.66646777692693E-5,-0.00634397464389414,-8.27498289379259E-5,10.0049076,10.0049076,-43913.265625,-43893.140625,56.8345545188329,20.3940558498765,10.760172,0,0,0,40,4449,9.96445,-43903.203125,,,,,,,,,,,,,0,,,,-0.00245,,,,,,10.0049076,,,,
,27942101.365,10.0038919,-38953.923828125,-0.00615099175496038,8.62965506643216E-7,1,0.999253354069792,40.0298881530762,1.99054501484583,21.1999993771315,-0.0690377020291219,-0.012837019320101,0.25,-3.57341268280919E-5,-0.00613701828181282,-7.94735108772714E-5,10.0038919,10.0038919,-38961.734375,-38946.11328125,56.8611298884868,20.3944635815069,10.760172,0,0,0,40,4449,9.9608,-38953.923828125,,,,,,,,,,,,,0,,,,0.0049,,,,,,10.0038919,,,,
,27942201.345,10.0021811,-33956.9375,-0.00592225848982895,4.84060236850739E-7,1,0.999253354069792,40.0298881530762,1.99067835528886,21.1999993771315,-0.0664403633254368,-0.0123481856842542,0.25,-3.49616238881999E-5,-0.00590566606372865,-7.59723501280645E-5,10.0021811,10.0021811,-33969.65625,-33944.21875,56.7509202672752,20.3916713769788,10.760172,0,0,0,40,4449,9.95965,-33956.9375,,,,,,,,,,,,,0,,,,0.00245,,,,,,10.0021811,,,,
,27942299.08,10.001236,-29074.38671875,-0.00567295764631206,4.98672817120007E-7,1,0.999253354069792,40.0298881530762,1.99066606737916,21.1999993771315,-0.0636127039814562,-0.0118086990625605,0.25,-3.35300659721772E-5,-0.0056541505950689,-7.15375077777248E-5,10.001236,10.001236,-29081.845703125,-29066.927734375,56.8095424062176,20.3869381147151,10.38052,0,0,0,40,4449,9.9578,-29074.38671875,,,,,,,,,,,,,0,,,,0,,,,,,10.001236,,,,
,27942398.84,10.0011406,-24084.93359375,-0.00539430511747178,7.03070811097974E-7,1,0.999253354069792,40.0298881530762,1.99079691424632,21.2099999189377,-0.0604617901966774,-0.0112172251997375,0.25,-3.2762723111045E-5,-0.00537365012557217,-6.74251709426228E-5,10.000926,10.0013552,-24089.94921875,-24079.91796875,56.6696309012752,20.3898813919284,10.760172,0,0,0,40,4449,9.9557,-24084.93359375,,,,,,,,,,,,,0,,,,0,,,,,,10.0011406,,,,
,27942500.22,10.0003958,-19020.2431640625,-0.00508754423610679,6.14951511157505E-7,1,0.999253354069792,40.0298881530762,1.99068150664641,21.1999993771315,-0.0569925306218637,-0.010568583746234,0.25,-3.20646112850551E-5,-0.00506551946482674,-6.31288997799787E-5,10.0003958,10.0003958,-19027.755859375,-19012.73046875,56.7266897831791,20.3907829422041,10.760172,0,0,0,40,4449,9.95475,-19020.2431640625,,,,,,,,,,,,,0,,,,0,,,,,,10.0003958,,,,
,27942599.68,10.00035765,-14050.6977539062,-0.00475867695478588,5.44936879589443E-7,1,0.999253354069792,40.0298881530762,1.99067808842888,21.1999993771315,-0.0532841756704873,-0.009878369230322,0.25,-3.13996652728445E-5,-0.00473588930491241,-5.8802228818467E-5,10.000289,10.0004263,-14055.578125,-14045.8173828125,56.8791073444291,20.3896024147821,10.760172,0,0,0,40,4449,9.9566,-14050.6977539062,,,,,,,,,,,,,0,,,,0.00245,,,,,,10.00035765,,,,
,27942697.195,9.99936815,-9178.0537109375,-0.00441267548133094,6.32222259697471E-7,1,0.999253354069792,40.0298881530762,1.99082018808714,21.1999993771315,-0.0493946468760307,-0.00914744039178833,0.25,-2.98370800829134E-5,-0.00438974302388587,-5.36581001103674E-5,9.9989223,9.999814,-9187.8701171875,-9168.2373046875,56.5656743082175,20.3881482310176,10.760172,0,0,0,40,4449,9.9572,-9178.0537109375,,,,,,,,,,,,,0,,,,-0.00245,,,,,,9.99936815,,,,
,27942794.095,9.9983139,-4331.68530273438,-0.00404776811756507,5.23820280153253E-7,1,0.999253354069792,40.0298881530762,1.99094939855189,21.1999993771315,-0.0452968307474772,-0.00838798321149594,0.25,-2.87478468317933E-5,-0.00402530867316367,-4.91536918636427E-5,9.9983139,9.9983139,-4334.1767578125,-4329.19384765625,56.5625477941406,20.3865429878746,10.760172,0,0,0,40,4449,9.95825,-4331.68530273438,,,,,,,,,,,,,0,,,,-0.00245,,,,,,9.9983139,,,,
,27942892.775,10.0022817,601.503662109375,-0.00362871876789145,4.8940932920778E-7,1,0.999253354069792,40.0298881530762,1.99093638406568,21.1999993771315,-0.0405972148105236,-0.00752573923697758,0.25,-2.73203841537886E-5,-0.00360781843697942,-4.4745016939906E-5,10.0021811,10.0023823,593.864135742188,609.143188476563,56.3452550657944,20.3797925947685,10.38052,0,0,0,40,4449,9.9552,601.503662109375,,,,,,,,,,,,,0,,,,0.00245,,,,,,10.0022817,,,,
,27942990.805,9.9995804,5498.57250976562,-0.00316125325953296,4.78268433213115E-7,1,0.999253354069792,40.0298881530762,1.99090808358034,21.1999993771315,-0.0353746226540486,-0.00657203774386277,0.25,-2.4041037354953E-5,-0.00314395115494004,-4.02329018624013E-5,9.9995804,9.9995804,5493.7529296875,5503.39208984375,56.6461820456983,20.3802305719658,10.760172,0,0,0,40,4449,9.9575,5498.57250976562,,,,,,,,,,,,,0,,,,-0.00245,,,,,,9.9995804,,,,
,27943081.275,10.0005655,10019.47265625,-0.00260538095663258,5.72282553500716E-7,1,0.999253354069792,40.0298881530762,1.99099563752294,21.1999993771315,-0.029162435813335,-0.00543611497734578,0.25,-2.05203149349593E-5,-0.00259199917699894,-3.47335462097031E-5,10.0005655,10.0005655,10012.177734375,10026.767578125,56.8251749766022,20.3831115529112,11.139823,0,0,0,40,4449,9.9569,10019.47265625,,,,,,,,,,,,,0,,,,0,,,,,,10.0005655,,,,
,27943172.51,10.0022182,14579.8090820313,-0.00170859992264402,7.961749792574E-7,1,0.999253354069792,40.0298881530762,1.99084220982748,21.2099999189377,-0.0191279050052172,-0.00358173761805743,0.25,-1.42838953840325E-5,-0.00170048064969546,-2.41737224355431E-5,10.0022182,10.0022182,14569.96875,14589.6494140625,56.4421770021791,20.3779941601836,11.139823,0,0,0,40,4449,9.9566,14579.8090820313,,,,,,,,,,,,,0,,,,0,,,,,,10.0022182,,,,
,27943262.9,10.0007544,19097.4404296875,-0.000150226650444191,1.09370205620437E-6,1,0.999253354069792,40.0298881530762,1.99108969663772,21.1999993771315,-0.00167957555491377,-0.000332592547788034,0.25,-2.76971770062137E-6,-0.000149566216086492,-3.67995881767005E-6,10.0007544,10.0007544,19092.3828125,19102.498046875,56.3702671784098,20.3768527524338,10.38052,0,0,0,40,4449,9.9558,19097.4404296875,,,,,,,,,,,,,0,,,,0,,,,,,10.0007544,,,,
,27943351.755,9.99989845,23537.7724609375,0.00194307964967595,1.23485100741779E-6,1,0.999253354069792,40.0298881530762,1.99107636645733,21.1999993771315,0.0217845123445861,0.00401913414256408,0.25,9.92680441329367E-6,0.00193554447218352,2.2356530196925E-5,9.9997387,10.0000582,23530.25390625,23545.291015625,56.750138638756,20.3761352767967,10.760172,0,0,0,40,4449,9.9556,23537.7724609375,,,,,,,,,,,,,0,,,,-0.00245,,,,,,9.99989845,,,,
,27943442.445,10.0013142,28070.6923828125,0.00379971155360673,1.09746504705689E-6,1,0.999253354069792,40.0298881530762,1.99103637083105,21.1999993771315,0.0426143408468373,0.00788845892921662,0.25,2.07338575258016E-5,0.00378672952273015,4.60009873809588E-5,10.0013142,10.0013142,28058.154296875,28083.23046875,56.8118872917752,20.3794995119396,10.760172,0,0,0,40,4449,9.9545,28070.6923828125,,,,,,,,,,,,,0,,,,0.0049,,,,,,10.0013142,,,,
,27943530.86,10.0005207,32491.20703125,0.00493158749121342,8.46300941300301E-7,1,0.999253354069792,40.0298881530762,1.99114502303617,21.1999993771315,0.0553337494818539,0.0102626190224763,0.25,2.75748007397585E-5,0.00491701749562793,6.14187987253526E-5,10.0005207,10.0005207,32486.19921875,32496.21484375,56.790783321756,20.3748928583651,11.139823,0,0,0,40,4449,9.95505,32491.20703125,,,,,,,,,,,,,0,,,,0,,,,,,10.0005207,,,,
,27943620.6,9.9983025,36976.6171875,0.00560731717080129,7.32346192318452E-7,1,0.999253354069792,40.0298881530762,1.99108452493045,21.2099999189377,0.0629409900331445,0.0116898462109607,0.25,3.17778543172854E-5,0.00559341014057169,7.12708019202684E-5,9.9983025,9.9983025,36969.30078125,36983.93359375,56.8048526351022,20.3800478118197,11.139823,0,0,0,40,4449,9.95465,36976.6171875,,,,,,,,,,,,,0,,,,0,,,,,,9.9983025,,,,
,27943714.765,9.9975262,41681.478515625,0.00604734326574736,8.86858365025445E-7,1,0.999253354069792,40.0298881530762,1.99109414778829,21.1999993771315,0.0679108318011493,0.0126334979803628,0.25,3.51706784877973E-5,0.0060353462194156,7.86733352234545E-5,9.9975262,9.9975262,41676.7421875,41686.21484375,56.597721077506,20.3789806822014,11.139823,0,0,0,40,4449,9.9573,41681.478515625,,,,,,,,,,,,,0,,,,0,,,,,,9.9975262,,,,
,27943812,9.9981689,46544.673828125,0.00635814053858218,7.61790971348866E-7,1,0.999253354069792,40.0298881530762,1.99087604843108,21.1999993771315,0.0714350793347192,0.0132596779355445,0.25,3.374871492488E-5,0.00634877838005218,8.02296555917216E-5,9.9981689,9.9981689,46539.75,46549.59765625,56.5859966497175,20.3836693444111,11.139823,0,0,0,40,4449,9.9581,46544.673828125,,,,,,,,,,,,,0,,,,-0.00245,,,,,,9.9981689,,,,
,27943907.915,9.9977169,51337.134765625,0.00657913290725287,9.00378554122679E-7,1,0.999253354069792,40.0298881530762,1.99086765088907,21.1999993771315,0.073950352923913,0.0137470358172539,0.25,3.62169834154041E-5,0.00657265360032903,8.48182806096533E-5,9.9977169,9.9977169,51332.1953125,51342.07421875,56.6321127323521,20.3819255238221,10.38052,0,0,0,40,4449,9.9624,51337.134765625,,,,,,,,,,,,,0,,,,0.00245,,,,,,9.9977169,,,,
,27944005.275,9.9963284,56202.08203125,0.00675386740551661,7.90455555924588E-7,1,0.999253354069792,40.0298881530762,1.99091716183752,21.1999993771315,0.0759592924552957,0.0140831287350162,0.25,3.37147315717666E-5,0.00675049116283537,8.39031656292254E-5,9.9963284,9.9963284,56199.46484375,56204.69921875,56.9213152844676,20.3791014625866,10.760172,0,0,0,40,4449,9.9646,56202.08203125,,,,,,,,,,,,,0,,,,-0.00245,,,,,,9.9963284,,,,
,27944104.065,9.99778845,61139.982421875,0.0068940722555331,8.30691057339994E-7,1,0.999253354069792,40.0298881530762,1.99098209292019,21.1999993771315,0.0775694305538526,0.0144134716681571,0.25,3.71045872992342E-5,0.0068938420788735,8.84188862693828E-5,9.9974642,9.9981127,61132.45703125,61147.5078125,56.9603967104291,20.3847513838662,10.38052,0,0,0,40,4449,9.96895,61139.982421875,,,,,,,,,,,,,0,,,,0,,,,,,9.99778845,,,,
,27944202.82,9.9971762,66077.98046875,0.00700982260531595,1.23926224235571E-6,1,0.999253354069792,40.0298881530762,1.99096998747475,21.1999993771315,0.0789128864267299,0.0146275437268732,0.25,3.48250868932106E-5,0.00701275152530088,8.68885645969287E-5,9.9971762,9.9971762,66070.6484375,66085.3125,56.8220484625252,20.3826319161591,10.760172,0,0,0,40,4449,9.97175,66077.98046875,,,,,,,,,,,,,0,,,,0,,,,,,9.9971762,,,,
,27944303.825,9.996911,71125.64453125,0.00710485944560766,1.35742705397846E-6,1,0.999253354069792,40.0298881530762,1.99081210079249,21.1999993771315,0.0800082921148564,0.0148485427235804,0.25,3.7171165138762E-5,0.00711090213495304,8.96472821518032E-5,9.996911,9.996911,71122.8828125,71128.40625,56.9033378285253,20.3805284804862,10.760172,0,0,0,40,4449,9.97435,71125.64453125,,,,,,,,,,,,,0,,,,0.00245,,,,,,9.996911,,,,
,27944402.025,9.9944801,76036.38671875,0.00718175125950236,1.17137544032441E-6,1,0.999253354069792,40.0298881530762,1.99085608276535,21.1999993771315,0.0808993293430168,0.01506430580169,0.25,4.23712359957138E-5,0.00719069224246896,9.49838518583882E-5,9.9944801,9.9944801,76026.2265625,76046.546875,56.7204367550252,20.3800344430646,11.139823,0,0,0,40,4449,9.97965,76036.38671875,,,,,,,,,,,,,0,,,,0,,,,,,9.9944801,,,,
,27944501.77,9.9949017,81022.140625,0.00724249021252326,1.13201434232875E-6,1,0.999253354069792,40.0298881530762,1.99085026606104,21.1999993771315,0.0816175150892121,0.0151798431020323,0.25,4.17762909658886E-5,0.00725427759150006,9.42603131771111E-5,9.9949017,9.9949017,81019.5546875,81024.7265625,56.6641595016406,20.3785887665299,10.760172,0,0,0,40,4449,9.9852,81022.140625,,,,,,,,,,,,,0,,,,0,,,,,,9.9949017,,,,
,27944598.915,9.9949722,85877.79296875,0.0072902772173754,1.09323603425574E-6,1,0.999253354069792,40.0298881530762,1.99074358370026,21.1999993771315,0.0821759883463408,0.0153089814250904,0.25,4.49120158400034E-5,0.00730466475701238,9.70863809278669E-5,9.9949722,9.9949722,85872.9375,85882.6484375,56.9361662263329,20.3788655740479,10.760172,0,0,0,40,4449,9.99,85877.79296875,,,,,,,,,,,,,0,,,,0,,,,,,9.9949722,,,,
,27944709.355,9.9963703,89585.21875,0.00731806429192195,1.22873131215411E-6,1,0.999253354069792,40.0298881530762,1.990273169163,21.1999993771315,0.0824970112770501,0.0153356583694872,0.25,4.28272717719858E-5,0.00733436311999651,9.4633961288303E-5,9.9963703,9.9963703,89570.2734375,89600.1640625,56.567237565256,20.3819486260067,11.139823,0,0,0,40,4449,9.9943,89585.21875,,,,,,,,,,,,,0,,,,-0.00245,,,,,,9.9963703,,,,
,27944794.825,9.9991179,85314.2421875,0.00728594153122618,1.288427534271E-6,1,0.999253354069792,40.0298881530762,1.99029002753033,21.1999993771315,0.0821059073461743,0.0152966439957783,0.25,4.48621912675427E-5,0.00730003396627418,9.70865670989084E-5,9.9991179,9.9991179,85309.3671875,85319.1171875,56.8283014906791,20.3795497894353,11.139823,0,0,0,40,4449,9.9918,85314.2421875,,,,,,,,,,,,,0,,,,0.00245,,,,,,9.9991179,,,,
,27944882.445,10.0023489,80935.39453125,0.00724104385640634,1.204502017884E-6,1,0.999253354069792,40.0298881530762,1.99021324766797,21.1999993771315,0.0815681442289725,0.0152143842554408,0.25,4.55079197468281E-5,0.00725275512891104,9.79985852934774E-5,10.0023489,10.0023489,80930.5,80940.2890625,56.8556584888522,20.384705696003,10.760172,0,0,0,40,4449,9.9909,80935.39453125,,,,,,,,,,,,,0,,,,0,,,,,,10.0023489,,,,
,27944973.855,10.0019989,76364.26171875,0.00718514780781925,1.27748701852064E-6,1,0.999253354069792,40.0298881530762,1.99053874029778,21.2099999189377,0.0809251471162203,0.0150817860831821,0.25,4.35148686139442E-5,0.00719427033920814,9.61201325754573E-5,10.0019989,10.0019989,76357.2265625,76371.296875,56.6735390438714,20.3812224523839,11.139823,0,0,0,40,4449,9.9883,76364.26171875,,,,,,,,,,,,,0,,,,0.00245,,,,,,10.0019989,,,,
,27945064.93,10.004612,71812.56640625,0.00711790086045893,1.07980489966381E-6,1,0.999253354069792,40.0298881530762,1.99047068075343,21.1999993771315,0.080138182014908,0.0149209699958956,0.25,4.1445688129759E-5,0.0071243311388136,9.39695845957852E-5,10.004612,10.004612,71807.6171875,71817.515625,56.7470121246791,20.3820088749753,10.760172,0,0,0,40,4449,9.98445,71812.56640625,,,,,,,,,,,,,0,,,,0.00245,,,,,,10.004612,,,,
,27945157.92,10.0034161,67164.81640625,0.00703492482732341,8.20060882283612E-7,1,0.999253354069792,40.0298881530762,1.99020481188266,21.2099999189377,0.0791548099066904,0.0147822721565434,0.25,4.4446425362495E-5,0.00703846640405121,9.6652835947946E-5,10.0034161,10.0034161,67160.0625,67169.5703125,56.6399290175445,20.3839831586506,10.760172,0,0,0,40,4449,9.9812,67164.81640625,,,,,,,,,,,,,0,,,,0,,,,,,10.0034161,,,,
,27945249.29,10.0044785,62596.892578125,0.00693866290815894,9.70807604969643E-7,1,0.999253354069792,40.0298881530762,1.98981589897572,21.1999993771315,0.0780286678203151,0.0145521732105057,0.25,4.19568470775301E-5,0.0069393301810191,9.35903948403696E-5,10.0044785,10.0044785,62591.984375,62601.80078125,56.6641595016406,20.3874504140135,10.760172,0,0,0,40,4449,9.97625,62596.892578125,,,,,,,,,,,,,0,,,,-0.00245,,,,,,10.0044785,,,,
,27945341.555,10.0049429,57983.453125,0.00682599734147948,8.74936886751368E-7,1,0.999253354069792,40.0298881530762,1.99020637585027,21.1999993771315,0.0767455977403163,0.0142973582033072,0.25,3.99201665488484E-5,0.00682371332820519,9.06967807334476E-5,10.0049429,10.0049429,57973.453125,57993.453125,56.8986480574099,20.3835032918507,10.760172,0,0,0,40,4449,9.9734,57983.453125,,,,,,,,,,,,,0,,,,0.00245,,,,,,10.0049429,,,,
,27945432.295,10.0035496,53447.814453125,0.00669917797049667,8.88489955054512E-7,1,0.999253354069792,40.0298881530762,1.99057369528084,21.1999993771315,0.0753065497100461,0.0139900284286488,0.25,3.59577704547868E-5,0.00669399960005615,8.56006249229729E-5,10.0035496,10.0035496,53435.18359375,53460.4453125,56.8798889729483,20.38336886811,10.38052,0,0,0,40,4449,9.9707,53447.814453125,,,,,,,,,,,,,0,,,,-0.00245,,,,,,10.0035496,,,,
,27945525.83,10.0044842,48772.572265625,0.00654919129985241,8.8284705573081E-7,1,0.999253354069792,40.0298881530762,1.99064350585265,21.2099999189377,0.0735837677709613,0.013695771802118,0.25,3.77238120814774E-5,0.00654102583958521,8.58609142725693E-5,10.0044842,10.0044842,48762.75,48782.39453125,56.6368025034675,20.3800088201778,10.760172,0,0,0,40,4449,9.9676,48772.572265625,,,,,,,,,,,,,0,,,,-0.00245,,,,,,10.0044842,,,,
,27945619.025,10.00453375,44114.708984375,0.00637984762854771,8.65574660581794E-7,1,0.999253354069792,40.0298881530762,1.99084206915212,21.1999993771315,0.0716498531677596,0.0133557068489614,0.25,3.90155023308105E-5,0.00636880482238697,8.5308796596732E-5,10.0044479,10.0046196,44109.82421875,44119.59375,56.902556200006,20.389074437467,11.139823,0,0,0,40,4449,9.9638,44114.708984375,,,,,,,,,,,,,0,,,,0,,,,,,10.00453375,,,,
,27945711.29,10.0043468,39504.390625,0.00619072200468488,6.42870152224547E-7,1,0.999253354069792,40.0298881530762,1.99089579180489,21.1999993771315,0.0694971377568044,0.0129353415293769,0.25,3.69696888366062E-5,0.0061770115500273,8.10992857920142E-5,10.0043468,10.0043468,39496.70703125,39512.07421875,56.6094455052945,20.3789236903748,10.760172,0,0,0,40,4449,9.9592,39504.390625,,,,,,,,,,,,,0,,,,0,,,,,,10.0043468,,,,
,27945802.9,10.0030603,34927.162109375,0.00598449906445145,8.44338618293689E-7,1,0.999253354069792,40.0298881530762,1.99083138516921,21.1999993771315,0.0671499460299166,0.0124831695576957,0.25,3.5366875229302E-5,0.00596834662416792,7.70455230202715E-5,10.0030603,10.0030603,34924.63671875,34929.6875,56.8931766577752,20.38096827092,10.38052,0,0,0,40,4449,9.9589,34927.162109375,,,,,,,,,,,,,0,,,,-0.0049,,,,,,10.0030603,,,,
,27945896.095,10.0011182,30266.9853515625,0.00574816614187956,8.76396844732323E-7,1,0.999253354069792,40.0298881530762,1.99092457066517,21.1999993771315,0.0644666932091146,0.0119984633275821,0.25,3.63360607571262E-5,0.00572981036896199,7.51786391821985E-5,10.0007086,10.0015278,30256.966796875,30277.00390625,56.7782772654483,20.3775473947913,10.760172,0,0,0,40,4449,9.9567,30266.9853515625,,,,,,,,,,,,,0,,,,-0.0049,,,,,,10.0011182,,,,
,27945987.14,10.001049,25716.4306640625,0.00549888505334772,5.22548964300385E-7,1,0.999253354069792,40.0298881530762,1.99088291855746,21.1999993771315,0.0616433079724813,0.0114565845682684,0.25,3.46283779954195E-5,0.00547873323009242,7.04757908725283E-5,10.001049,10.001049,25708.4765625,25724.384765625,56.9049010855637,20.3817586143289,10.760172,0,0,0,40,4449,9.9564,25716.4306640625,,,,,,,,,,,,,0,,,,0,,,,,,10.001049,,,,
,27946076.525,10.0003004,21248.9501953125,0.00523591134399211,5.43342191337961E-7,1,0.999253354069792,40.0298881530762,1.99099428787105,21.1999993771315,0.0586738195084591,0.010893957909816,0.25,3.34243661785414E-5,0.00521437296623604,6.61525116080497E-5,10.0003004,10.0003004,21241.466796875,21256.43359375,56.5961578204675,20.3797170159082,10.760172,0,0,0,40,4449,9.9555,21248.9501953125,,,,,,,,,,,,,0,,,,-0.00245,,,,,,10.0003004,,,,
,27946166.845,10.0005922,16734.0888671875,0.00494537230047917,6.38145158871124E-7,1,0.999253354069792,40.0298881530762,1.99098751064685,21.1999993771315,0.0553926415352513,0.0102911812488146,0.25,3.35927327574942E-5,0.00492288465685666,6.300779047714E-5,10.0005922,10.0005922,16724.236328125,16743.94140625,56.6242964471598,20.3832405372544,11.139823,0,0,0,40,4449,9.955,16734.0888671875,,,,,,,,,,,,,0,,,,0,,,,,,10.0005922,,,,
,27946255.96,10.0006075,12281.44140625,0.00464226867997007,6.2484764732963E-7,1,0.999253354069792,40.0298881530762,1.99068787254866,21.1999993771315,0.0519715066533512,0.00964319520228202,0.25,3.19312121643553E-5,0.00461931941802056,5.80580246464139E-5,10.0006075,10.0006075,12271.2041015625,12291.6787109375,56.8071975206598,20.3814066215825,10.760172,0,0,0,40,4449,9.95635,12281.44140625,,,,,,,,,,,,,0,,,,-0.00245,,,,,,10.0006075,,,,
,27946345.525,9.9989243,7803.39184570312,0.00431527410514614,6.39867699593336E-7,1,0.999253354069792,40.0298881530762,1.99083167041898,21.1999993771315,0.0482973521793745,0.00895646741528912,0.25,3.06738194954945E-5,0.0042923837533691,5.35195485925826E-5,9.9989243,9.9989243,7793.546875,7813.23681640625,56.8751992018329,20.3831575422358,10.38052,0,0,0,40,4449,9.9572,7803.39184570312,,,,,,,,,,,,,0,,,,0.0049,,,,,,9.9989243,,,,
,27946435.72,10.0001574,3297.99938964844,0.00396477698254062,5.25587070251918E-7,1,0.999253354069792,40.0298881530762,1.99075355920796,21.1999993771315,0.0443602217944242,0.00821922582568817,0.25,2.88452746287223E-5,0.00394251666050915,4.85450860428959E-5,10.0001574,10.0001574,3290.51611328125,3305.48266601562,56.8384626614291,20.383608542636,10.38052,0,0,0,40,4449,9.9572,3297.99938964844,,,,,,,,,,,,,0,,,,0.00245,,,,,,10.0001574,,,,
,27946502.65,10.00214,-0.205520935356617,0.00368251189773776,4.25995956783604E-7,1,0.999253354069792,40.0298881530762,1.99074003996194,21.1999993771315,0.0411954893401848,0.00762959560056381,0.25,2.72084431972376E-5,0.00366122625887541,4.48016004670692E-5,10.00214,10.00214,-0.228356599807739,-0.182685270905495,56.8580033744099,20.3822067035944,11.139823,0,0,0,40,4417,9.95445,-0.205520935356617,,,,,,,,,,,,,0,,,,0,,,,,,10.00214,,,,