File: data/monolayers/nanoparticles/Ac_CoFe_C_2/vsm/data_dispersion/YF45_HYST_100K.DAT
[Header]
; VSM Data File (default extension .dat)
; Copyright (c) 2003-2013, Quantum Design, Inc. All rights reserved.
TITLE,
FILEOPENTIME,27970007.00,11/21/2018,1:27 am
BYAPP,VSM,2.0,2.0
INFO,PPMS VSM Option Release 1.4.10 Build 1,APPNAME
INFO,Quantum Design Linear Motor Servo Controller,MOTOR_MODULE_NAME
INFO,3101-100 M1,MOTOR_HW_VERSION
INFO,MMC1014,MOTOR_SERIAL_NUMBER
INFO,SRV No X-over 01.03.11,MOTOR_SOFTWARE_VERSION
INFO,Quantum Design VSM Detection Module,VSM_MODULE_NAME
INFO,3101-150 F0,VSM_HW_VERSION
INFO,VSM707,VSM_SERIAL_NUMBER
INFO,VSM No X-over 01.02.05 May 20 2008 13:51:47,VSM_SOFTWARE_VERSION
INFO,704,PREAMP_SERIAL_NUMBER
INFO,822,COIL_SERIAL_NUMBER
INFO,0,MOMENT_UNITS
INFO,CoFe2O4,SAMPLE_MATERIAL
INFO,dispersion in ampulle,SAMPLE_COMMENT
INFO,,SAMPLE_MASS
INFO,,SAMPLE_VOLUME
INFO,,SAMPLE_MOLECULAR_WEIGHT
INFO,,SAMPLE_SIZE
INFO,,SAMPLE_SHAPE
DATATYPE,COMMENT,1
DATATYPE,TIME,2
STARTUPAXIS,X,2
STARTUPAXIS,Y1,5
[Data]
Comment,Time Stamp (sec),Temperature (K),Magnetic Field (Oe),Moment (emu),M. Std. Err. (emu),Transport Action,Averaging Time (sec),Frequency (Hz),Peak Amplitude (mm),Center Position (mm),Coil Signal' (mV),Coil Signal" (mV),Range (mV),M. Quad. Signal (emu),M. Raw' (emu),M. Raw" (emu),Min. Temperature (K),Max. Temperature (K),Min. Field (Oe),Max. Field (Oe),Mass (grams),Motor Lag (deg),Pressure (Torr),VSM Status (code),Motor Status (code),Measure Status (code),Measure Count,PPMS Status (code),System Temp. (K),System Field (Oe),Sample Position (deg),Bridge 1 Resistance (ohms),Bridge 1 Excitation (에),Bridge 2 Resistance (ohms),Bridge 2 Excitation (에),Bridge 3 Resistance (ohms),Bridge 3 Excitation (에),Bridge 4 Resistance (ohms),Bridge 4 Excitation (에),Signal 1 Vin (V),Signal 2 Vin (V),Digital Inputs (code),Drive 1 Iout (mA),Drive 1 Ipower (W),Drive 2 Iout (mA),Drive 2 Ipower (W),Pressure (),Map 20 (),Map 21 (),Map 22 (),Map 23 (),Map 24 (),Map 25 (),Map 26 (),Map 27 (),Map 28 (),Map 29 ()
,27970022.19,100.3780823,-0.3349229991436,,,2,,,,21.3199997675419,,,,,,,100.3780823,100.3780823,-0.3349229991436,-0.3349229991436,,,21.770052,,,,-99999999,4369,100.426,-0.3349229991436,,,,,,,,,,,,,,,,,,,,,,,100.3780823,,,,
,27970139.455,100.2799873,2900.09252929687,0.00336659294837265,4.58721213023995E-7,1,0.999253354069792,40.0298881530762,1.99085969641149,21.3099997490644,0.0381250157986567,0.00688171273044823,0.25,1.55093056234782E-5,0.00338548169857804,2.60263661693153E-5,100.2782974,100.2816772,2895.07958984375,2905.10546875,55.9247389224482,20.3561645863783,22.529354,0,0,0,40,4449,100.1113,2900.09252929687,,,,,,,,,,,,,0,,,,0.00245,,,,,,100.2799873,,,,
,27970201.205,100.211731,5981.03271484375,0.00347384772283856,5.81725094706581E-7,1,0.999253354069792,40.0298881530762,1.99093840158389,21.3099997490644,0.0393415561893214,0.00709935333919571,0.25,1.58482214510878E-5,0.0034933490196074,2.66879439980734E-5,100.211731,100.211731,5973.517578125,5988.5478515625,56.4578095725637,20.3608880352919,22.149702,0,0,0,40,4449,100.0163,5981.03271484375,,,,,,,,,,,,,0,,,,0,,,,,,100.211731,,,,
,27970265.265,100.1489487,9184.607421875,0.00356311087170869,5.9964686537802E-7,1,0.999253354069792,40.0298881530762,1.99092021790658,21.3099997490644,0.0403520384626474,0.00728315187608101,0.25,1.64024458005232E-5,0.00358312802682191,2.74987533567558E-5,100.1489487,100.1489487,9182.1259765625,9187.0888671875,56.3397836661598,20.3612725264593,22.149702,0,0,0,40,4449,99.9531,9184.607421875,,,,,,,,,,,,,0,,,,0,,,,,,100.1489487,,,,
,27970363.515,100.0802078,14092.1450195313,0.00364791213281535,7.49549524579745E-7,1,0.999253354069792,40.0298881530762,1.9910811704037,21.3200002908707,0.0413164758668313,0.00745392368092886,0.25,1.65605919287342E-5,0.00366843468772043,2.78696782608037E-5,100.0802078,100.0802078,14089.8310546875,14094.458984375,56.7548284098714,20.3581943170369,22.149702,0,0,0,40,4449,99.9051,14092.1450195313,,,,,,,,,,,,,0,,,,-0.0049,,,,,,100.0802078,,,,
,27970461.055,100.039093,18969.314453125,0.00367866052024172,9.34269420259004E-7,1,0.999253354069792,40.0298881530762,1.99095397410837,21.3099997490644,0.0416627770555543,0.00751495887473246,0.25,1.66360386160565E-5,0.00369938653758696,2.79808847579454E-5,100.039093,100.039093,18956.66796875,18981.9609375,56.648526931256,20.3588811335294,21.770052,0,0,0,40,4449,99.8839,18969.314453125,,,,,,,,,,,,,0,,,,0.00245,,,,,,100.039093,,,,
,27970555.965,100.0189056,23712.296875,0.00368175269097572,1.14570474001544E-6,1,0.999253354069792,40.0298881530762,1.99081744426469,21.3099997490644,0.041697011038818,0.00751168474236351,0.25,1.59040795478864E-5,0.00370252829774383,2.71919652765794E-5,100.0189056,100.0189056,23699.8125,23724.78125,56.3694855498906,20.3615066154469,22.529354,0,0,0,40,4449,99.87365,23712.296875,,,,,,,,,,,,,0,,,,0.0049,,,,,,100.0189056,,,,
,27970652.7,100.0078049,28547.5576171875,0.00366692275576973,1.44010599249723E-6,1,0.999253354069792,40.0298881530762,1.99060265186451,21.3099997490644,0.0415176669433527,0.007523186325358,0.25,1.96540202236293E-5,0.00368763425813461,3.08510687393697E-5,100.0078049,100.0078049,28537.603515625,28557.51171875,56.5891231637945,20.3683175714406,22.529354,0,0,0,40,4449,99.87235,28547.5576171875,,,,,,,,,,,,,0,,,,0,,,,,,100.0078049,,,,
,27970746.205,100.0032883,33220.21875,0.00364090637433221,1.825215323368E-6,1,0.999253354069792,40.0298881530762,1.99083705621094,21.3099997490644,0.0412349300069471,0.00743165811296424,0.25,1.61340662924913E-5,0.0036615107145939,2.7167408181761E-5,100.0032883,100.0032883,33215.33203125,33225.10546875,56.6493085597752,20.3653738380223,22.149702,0,0,0,40,4449,99.8679,33220.21875,,,,,,,,,,,,,0,,,,0,,,,,,100.0032883,,,,
,27970840.295,100.0024796,37925.20703125,0.0036054603600514,1.85573449892757E-6,1,0.999253354069792,40.0298881530762,1.99070971762377,21.3099997490644,0.0408341070084606,0.00734309351730526,0.25,1.46474422658098E-5,0.00362589791593483,2.5498980444626E-5,100.0024796,100.0024796,37917.67578125,37932.73828125,56.5500417378329,20.3655668458101,22.529354,0,0,0,40,4449,99.8677,37925.20703125,,,,,,,,,,,,,0,,,,-0.00245,,,,,,100.0024796,,,,
,27970934.835,100.0020599,42650.958984375,0.00356426084767601,1.46393845382733E-6,1,0.999253354069792,40.0298881530762,1.99082492169449,21.3099997490644,0.0403669295137749,0.00727746091990835,0.25,1.61186801848493E-5,0.00358448960461899,2.6788603553179E-5,100.0020599,100.0020599,42640.96484375,42660.953125,56.9517987967176,20.3634175242348,22.149702,0,0,0,40,4449,99.86575,42650.958984375,,,,,,,,,,,,,0,,,,-0.00245,,,,,,100.0020599,,,,
,27971031.06,100.0028381,47458.3984375,0.00350820877033591,1.62460512570021E-6,1,0.999253354069792,40.0298881530762,1.99062836601963,21.3099997490644,0.0397323667588156,0.00714151612982974,0.25,1.40901748150228E-5,0.00352815431629544,2.45144619750894E-5,100.0028381,100.0028381,47443.41796875,47473.37890625,56.6649411301598,20.3696111098933,22.149702,0,0,0,40,4449,99.8639,47458.3984375,,,,,,,,,,,,,0,,,,0,,,,,,100.0028381,,,,
,27971127.125,100.00471875,52258.57421875,0.00344962011774134,2.22649462953045E-6,1,0.999253354069792,40.0298881530762,1.990706500501,21.3099997490644,0.0390670763268373,0.00704267098565285,0.25,1.56947451951221E-5,0.0034692560285223,2.5888803010317E-5,100.0045242,100.0049133,52251.171875,52265.9765625,56.7524835243137,20.369852143874,22.149702,0,0,0,40,4449,99.85965,52258.57421875,,,,,,,,,,,,,0,,,,0,,,,,,100.00471875,,,,
,27971222.79,100.0041046,57040.9765625,0.00338864256659609,1.32876469193244E-6,1,0.999253354069792,40.0298881530762,1.9904735824944,21.3099997490644,0.0383699458669893,0.00693220981599294,0.25,1.67839720141689E-5,0.00340795587891981,2.67398746983359E-5,100.0041046,100.0041046,57023.4453125,57058.5078125,56.4241995462367,20.3721127721724,22.149702,0,0,0,40,4449,99.8565,57040.9765625,,,,,,,,,,,,,0,,,,-0.00245,,,,,,100.0041046,,,,
,27971315.65,100.0054779,61680.98828125,0.00331384164975927,2.03822507396721E-6,1,0.999253354069792,40.0298881530762,1.99092143508625,21.3099997490644,0.0375396860451926,0.00673308369656452,0.25,1.22753464515397E-5,0.00333276735639257,2.19252853570219E-5,100.0054779,100.0054779,61670.87109375,61691.10546875,56.6172617904868,20.3695096620302,22.529354,0,0,0,40,4449,99.8526,61680.98828125,,,,,,,,,,,,,0,,,,0.00245,,,,,,100.0054779,,,,
,27971410.545,100.0045013,66426.8515625,0.00324736751626843,2.11151481309635E-6,1,0.999253354069792,40.0298881530762,1.99083149655116,21.3099997490644,0.0367838694164142,0.00660634317307934,0.25,1.28464570010968E-5,0.00326593805289941,2.22445107468257E-5,100.0045013,100.0045013,66419.453125,66434.25,56.5625477941406,20.3665201311813,22.149702,0,0,0,40,4449,99.84945,66426.8515625,,,,,,,,,,,,,0,,,,0.00245,,,,,,100.0045013,,,,
,27971505.04,100.0028992,71149.71875,0.00316830020020126,2.35076951987242E-6,1,0.999253354069792,40.0298881530762,1.99063713058055,21.3099997490644,0.0358926971326306,0.00640220211918247,0.25,8.82396516456728E-6,0.00318645514289142,1.79105298600206E-5,100.0028992,100.0028992,71137.2734375,71162.1640625,56.9158438848329,20.3654402266725,22.529354,0,0,0,40,4449,99.8472,71149.71875,,,,,,,,,,,,,0,,,,-0.00245,,,,,,100.0028992,,,,
,27971593.85,100.004097,75587.8203125,0.00309812262937777,2.19451354345744E-6,1,0.999253354069792,40.0298881530762,1.99082721433895,21.3099997490644,0.0350835478847335,0.00636125118461019,0.25,1.75275287689801E-5,0.00311587354290817,2.64078533242722E-5,100.004097,100.004097,75575.2734375,75600.3671875,56.7853119221214,20.371678441295,22.529354,0,0,0,40,4449,99.8426,75587.8203125,,,,,,,,,,,,,0,,,,0,,,,,,100.004097,,,,
,27971681.33,100.0047226,79960.96875,0.00302171526577338,1.76049375043623E-6,1,0.999253354069792,40.0298881530762,1.99045696205497,21.3099997490644,0.0342210484203596,0.00615445009613964,0.25,1.28378078091941E-5,0.00303906281812883,2.14207848408873E-5,100.0047226,100.0047226,79953.390625,79968.546875,56.4882930848137,20.3747868619301,22.529354,0,0,0,40,4449,99.8381,79960.96875,,,,,,,,,,,,,0,,,,-0.00245,,,,,,100.0047226,,,,
,27971774.215,100.0042343,84604.62890625,0.00293799823055195,2.49593747523268E-6,1,0.999253354069792,40.0298881530762,1.99094079145705,21.3099997490644,0.0332796884705111,0.00599244848006654,0.25,1.31616310303051E-5,0.00295488628043807,2.14550153663714E-5,100.0042114,100.0042572,84597.15625,84612.1015625,56.6164801619675,20.3675700901674,22.909004,0,0,0,40,4449,99.8345,84604.62890625,,,,,,,,,,,,,0,,,,0,,,,,,100.0042343,,,,
,27971863.07,100.0039597,89045.2734375,0.00285920098731298,2.17160655429583E-6,1,0.999253354069792,40.0298881530762,1.99079801171127,21.3099997490644,0.0323851428074978,0.00583139201925589,0.25,1.2861924337198E-5,0.00287565721471048,2.08813206544536E-5,100.0039597,100.0039597,89035.1640625,89055.3828125,56.5938129349098,20.3696318155921,22.149702,0,0,0,40,4449,99.832,89045.2734375,,,,,,,,,,,,,0,,,,0.0049,,,,,,100.0039597,,,,
,27971975.415,100.0010452,86638.6875,0.00290529995807595,2.26897857015498E-6,1,0.999253354069792,40.0298881530762,1.99059559056581,21.3099997490644,0.0329021035215243,0.00593542678645613,0.25,1.3977143449396E-5,0.00292200744231621,2.21597074291606E-5,100.0010452,100.0010452,86633.8046875,86643.5703125,56.5101786833521,20.3751332122035,22.529354,0,0,0,40,4449,99.83265,86638.6875,,,,,,,,,,,,,0,,,,-0.0049,,,,,,100.0010452,,,,
,27972066.055,99.9994736,82110.046875,0.00298442625842788,2.31309472021005E-6,1,0.999253354069792,40.0298881530762,1.99078187641485,21.3099997490644,0.0338100411914089,0.00604583315415117,0.25,9.73742849608781E-6,0.00300157894016317,1.81718689486261E-5,99.9994736,99.9994736,82099.6171875,82120.4765625,56.6954246424098,20.3714859111323,22.909004,0,0,0,40,4449,99.8325,82110.046875,,,,,,,,,,,,,0,,,,0,,,,,,99.9994736,,,,
,27972159.565,99.9979019,77436.28515625,0.00306173282283863,2.3261276130007E-6,1,0.999253354069792,40.0298881530762,1.99057532481775,21.3099997490644,0.0346775284495666,0.00622798570118105,0.25,1.22434721602694E-5,0.00307929928745665,2.09680622201307E-5,99.9978027,99.9980011,77426.28125,77446.2890625,56.6344576179098,20.3732964550216,22.909004,0,0,0,40,4449,99.83465,77436.28515625,,,,,,,,,,,,,0,,,,0.0049,,,,,,99.9979019,,,,
,27972251.945,99.9979248,72815.0546875,0.00314370865979967,2.71371339894806E-6,1,0.999253354069792,40.0298881530762,1.99089124214675,21.3099997490644,0.0356028402698682,0.00644279755162006,0.25,1.66706771979507E-5,0.00316170893021896,2.57119670497382E-5,99.9979248,99.9979248,72802.6015625,72827.5078125,56.7876568076791,20.3671791202969,22.529354,0,0,0,40,4449,99.83725,72815.0546875,,,,,,,,,,,,,0,,,,-0.00245,,,,,,99.9979248,,,,
,27972346.355,99.9950409,68097.12109375,0.00321968808759893,2.29253303728179E-6,1,0.999253354069792,40.0298881530762,1.99077072656004,21.3099997490644,0.036458812540846,0.00661007538886267,0.25,1.80703417392282E-5,0.00323809463589656,2.73977064144941E-5,99.9950409,99.9950409,68089.625,68104.6171875,56.9385111118906,20.3716270303034,22.529354,0,0,0,40,4449,99.84265,68097.12109375,,,,,,,,,,,,,0,,,,0,,,,,,99.9950409,,,,
,27972436.875,99.9958801,63571.0390625,0.00329427476729274,2.04104259385368E-6,1,0.999253354069792,40.0298881530762,1.99075384591597,21.3099997490644,0.037310401536726,0.0067198854619675,0.25,1.46157737382254E-5,0.00331309281490557,2.4198146010158E-5,99.9958801,99.9958801,63555.859375,63586.21875,56.597721077506,20.36607985127,22.149702,0,0,0,40,4449,99.84465,63571.0390625,,,,,,,,,,,,,0,,,,-0.0049,,,,,,99.9958801,,,,
,27972529.6,99.9945526,58938.111328125,0.00336138394212227,1.78877157758245E-6,1,0.999253354069792,40.0298881530762,1.99078882750539,21.3099997490644,0.0380735860645183,0.00684100226244124,0.25,1.34530901049164E-5,0.00338056260134076,2.32856361915053E-5,99.9945526,99.9945526,58933.19921875,58943.0234375,56.7001144135252,20.3670272525936,22.149702,0,0,0,40,4449,99.84925,58938.111328125,,,,,,,,,,,,,0,,,,0.0049,,,,,,99.9945526,,,,
,27972623.07,99.9947891,54265.134765625,0.00342934633732666,2.11289210016274E-6,1,0.999253354069792,40.0298881530762,1.99077636038415,21.3099997490644,0.0388416395243074,0.00698604534187029,0.25,1.42631263118809E-5,0.00344888350673995,2.43618410585876E-5,99.9947891,99.9947891,54250.23828125,54280.03125,56.861911517006,20.3686829081978,22.909004,0,0,0,40,4449,99.85775,54265.134765625,,,,,,,,,,,,,0,,,,0.00245,,,,,,99.9947891,,,,
,27972717.405,99.9935379,49551.89453125,0.00349065356767275,2.15816817294682E-6,1,0.999253354069792,40.0298881530762,1.99074447419446,21.3099997490644,0.0395307650207792,0.0071354238284249,0.25,1.6626887762834E-5,0.00351050501827129,2.69847421796592E-5,99.9935379,99.9935379,49541.8671875,49561.921875,56.7751507513714,20.3725096520138,23.288654,0,0,0,40,4449,99.8608,49551.89453125,,,,,,,,,,,,,0,,,,0,,,,,,99.9935379,,,,
,27972813.71,99.9941788,44737.341796875,0.00354604900937782,1.5575555255002E-6,1,0.999253354069792,40.0298881530762,1.99072467068195,21.3099997490644,0.0401685178674265,0.00718515162304212,0.25,1.12306146742384E-5,0.00356620229314991,2.17889278651731E-5,99.9941788,99.9941788,44724.7421875,44749.94140625,56.9525804252368,20.3681555992883,22.529354,0,0,0,40,4449,99.86555,44737.341796875,,,,,,,,,,,,,0,,,,0,,,,,,99.9941788,,,,
,27972906.72,99.9931335,40089.265625,0.00359288428159247,1.6718841977118E-6,1,0.999253354069792,40.0298881530762,1.99078620673591,21.3099997490644,0.040694396423118,0.0073117221489614,0.25,1.40936454530575E-5,0.00361326678416169,2.48727653820379E-5,99.9931335,99.9931335,40076.83984375,40101.69140625,56.8853603725829,20.3678000042452,22.149702,0,0,0,40,4449,99.8719,40089.265625,,,,,,,,,,,,,0,,,,-0.0049,,,,,,99.9931335,,,,
,27973000.225,99.9933472,35414.134765625,0.00363386505271637,1.55125823051424E-6,1,0.999253354069792,40.0298881530762,1.99084439216121,21.3200002908707,0.0411556220318584,0.00741667046632841,0.25,1.60768178577527E-5,0.00365444528241375,2.70552793945662E-5,99.9933472,99.9933472,35409.1171875,35419.15234375,56.8204852054868,20.3680127042391,22.529354,0,0,0,40,4449,99.8793,35414.134765625,,,,,,,,,,,,,0,,,,-0.0049,,,,,,99.9933472,,,,
,27973093.715,99.99189,30741.376953125,0.0036649151653169,1.22871187250131E-6,1,0.999253354069792,40.0298881530762,1.99059822148671,21.3099997490644,0.0415046198167398,0.00746450906941121,0.25,1.48613824475698E-5,0.00368564621876506,2.59913262825108E-5,99.99189,99.99189,30726.552734375,30756.201171875,56.7415407250445,20.3777514583213,22.529354,0,0,0,40,4449,99.8877,30741.376953125,,,,,,,,,,,,,0,,,,-0.00245,,,,,,99.99189,,,,
,27973186.845,99.9925385,26088.904296875,0.00369036069003698,1.25796585109886E-6,1,0.999253354069792,40.0298881530762,1.99098837699242,21.3099997490644,0.0417961596157648,0.0075411492965049,0.25,1.69703777728343E-5,0.00371120049658638,2.8253542569263E-5,99.9925385,99.9925385,26073.734375,26104.07421875,56.7290346687368,20.3728252438102,23.288654,0,0,0,40,4449,99.8941,26088.904296875,,,,,,,,,,,,,0,,,,0,,,,,,99.9925385,,,,
,27973278.805,99.9912491,21491.015625,0.00370393112696102,9.0669552651847E-7,1,0.999253354069792,40.0298881530762,1.99089937026125,21.3099997490644,0.0419504534327454,0.00755311860075796,0.25,1.56137482024651E-5,0.00372482384378104,2.69924524102153E-5,99.9912491,99.9912491,21481.15234375,21500.87890625,56.7110572127945,20.373426985392,23.288654,0,0,0,40,4449,99.9023,21491.015625,,,,,,,,,,,,,0,,,,0,,,,,,99.9912491,,,,
,27973370.295,99.9918976,16919.1259765625,0.00370404747806916,7.89554448435923E-7,1,0.999253354069792,40.0298881530762,1.99094933001055,21.3099997490644,0.0419491640276058,0.00757229131209859,0.25,1.72137916208026E-5,0.00372490849292375,2.86619907426573E-5,99.9918976,99.9918976,16909.359375,16928.892578125,57.1143775287176,20.3715829437086,22.529354,0,0,0,40,4449,99.90825,16919.1259765625,,,,,,,,,,,,,0,,,,-0.0049,,,,,,99.9918976,,,,
,27973465.405,99.9903946,12166.7680664062,0.00368593368066764,6.89867735909963E-7,1,0.999253354069792,40.0298881530762,1.99108961323468,21.3099997490644,0.0417473952132667,0.00753078424410801,0.25,1.66361333747067E-5,0.00370666733025848,2.80843088991521E-5,99.9903946,99.9903946,12156.361328125,12177.1748046875,57.0010413934291,20.3709145990222,23.288654,0,0,0,40,4449,99.91725,12166.7680664062,,,,,,,,,,,,,0,,,,0,,,,,,99.9903946,,,,
,27973558.49,99.9924622,7513.68286132813,0.00363499223098063,6.48480760600889E-7,1,0.999253354069792,40.0298881530762,1.99093547727349,21.3099997490644,0.0411666885203501,0.0074284769114337,0.25,1.65622267594749E-5,0.0036554140827323,2.79063331406529E-5,99.9924622,99.9924622,7503.7294921875,7523.63623046875,57.0354330482753,20.370755716107,22.529354,0,0,0,40,4449,99.92355,7513.68286132813,,,,,,,,,,,,,0,,,,-0.00245,,,,,,99.9924622,,,,
,27973651.31,99.9918594,2873.18664550781,0.00351356830803547,5.18100326570572E-7,1,0.999253354069792,40.0298881530762,1.99093307637392,21.3099997490644,0.0397916229415356,0.00717827212399324,0.25,1.5786399473253E-5,0.00353328775145713,2.67954587895706E-5,99.9918594,99.9918594,2865.4775390625,2880.89575195313,56.7626446950637,20.3712003867828,23.288654,0,0,0,40,4449,99.9303,2873.18664550781,,,,,,,,,,,,,0,,,,0.00245,,,,,,99.9918594,,,,
,27973744.4,99.9943924,-1776.94940185547,0.00223321568961182,5.09206053723125E-7,1,0.999253354069792,40.0298881530762,1.99105383503706,21.3099997490644,0.0252922828380379,0.00456624786176145,0.25,1.03370084786377E-5,0.00224574582087736,1.73412829400896E-5,99.9943924,99.9943924,-1784.59692382813,-1769.30187988281,57.0198004778906,20.3737687805895,22.529354,0,0,0,40,4449,99.93645,-1776.94940185547,,,,,,,,,,,,,0,,,,-0.0049,,,,,,99.9943924,,,,
,27973838.265,99.9984741,-6467.62060546875,0.00144635626133135,7.22968989138197E-7,1,0.999253354069792,40.0298881530762,1.9909856323179,21.3200002908707,0.0163813185790537,0.00295128377414856,0.25,6.18408420541977E-6,0.00145448143740149,1.06992951360574E-5,99.9984741,99.9984741,-6477.58349609375,-6457.65771484375,56.8423708040252,20.3717256339588,22.909004,0,0,0,40,4449,99.9348,-6467.62060546875,,,,,,,,,,,,,0,,,,0,,,,,,99.9984741,,,,
,27973932.36,100.00359345,-11172.98828125,-0.000126137687746959,1.07199575862727E-6,1,0.999253354069792,40.0298881530762,1.99110891130479,21.3099997490644,-0.00142770480737893,-0.000263174053237822,0.25,-1.05051523365326E-6,-0.00012684554971786,-1.44533335054778E-6,100.0033493,100.0038376,-11180.509765625,-11165.466796875,56.8916134007368,20.3707742646261,22.909004,0,0,0,40,4449,99.9296,-11172.98828125,,,,,,,,,,,,,0,,,,-0.00245,,,,,,100.00359345,,,,
,27974027.84,100.0072937,-15945.5639648438,-0.00207483614955423,1.10572514587077E-6,1,0.999253354069792,40.0298881530762,1.99105770235627,21.3099997490644,-0.0234968087829267,-0.00425528631187602,0.25,-1.0821233202458E-5,-0.00208651472055535,-1.72461459546982E-5,100.0072937,100.0072937,-15958.05859375,-15933.0693359375,56.7642079521022,20.3682147302841,22.909004,0,0,0,40,4449,99.9229,-15945.5639648438,,,,,,,,,,,,,0,,,,0.00245,,,,,,100.0072937,,,,
,27974123.515,100.01119615,-20725.5029296875,-0.00317853873780954,1.18130321382214E-6,1,0.999253354069792,40.0298881530762,1.99109219246882,21.3099997490644,-0.0360012444638045,-0.00649330033630118,0.25,-1.43602579426469E-5,-0.00319646023476921,-2.41378149522118E-5,100.0111237,100.0112686,-20735.3359375,-20715.669921875,56.7728058658137,20.3706217460971,22.529354,0,0,0,40,4449,99.9111,-20725.5029296875,,,,,,,,,,,,,0,,,,0.00245,,,,,,100.01119615,,,,
,27974219.82,100.0097427,-25537.822265625,-0.00352878105272765,1.1251231305873E-6,1,0.999253354069792,40.0298881530762,1.99098418909757,21.3099997490644,-0.0399666599778018,-0.00720731870164536,0.25,-1.59018438101885E-5,-0.0035487055449347,-2.66948482139095E-5,100.0097427,100.0097427,-25552.96875,-25522.67578125,57.1683098965445,20.3723430360444,23.288654,0,0,0,40,4449,99.90305,-25537.822265625,,,,,,,,,,,,,0,,,,-0.0049,,,,,,100.0097427,,,,
,27974316.4,100.0111771,-30365.373046875,-0.00360983747379786,1.04676212491001E-6,1,0.999253354069792,40.0298881530762,1.99093309160065,21.3099997490644,-0.0408820124250783,-0.007384189383463,0.25,-1.73411610627443E-5,-0.00363024554389791,-2.83232376402863E-5,100.0111771,100.0111771,-30375.525390625,-30355.220703125,56.9252234270637,20.3714380933519,22.909004,0,0,0,40,4449,99.894,-30365.373046875,,,,,,,,,,,,,0,,,,0.00245,,,,,,100.0111771,,,,
,27974413.54,100.0103378,-35219.91015625,-0.00360974706488301,1.27932258684137E-6,1,0.999253354069792,40.0298881530762,1.99111703770188,21.3200002908707,-0.040888352277613,-0.007365222806197,0.25,-1.5687411717089E-5,-0.00363018938738173,-2.65933886832452E-5,100.0102615,100.0104141,-35227.37890625,-35212.44140625,57.2503808910638,20.3715912537864,23.288654,0,0,0,40,4449,99.8835,-35219.91015625,,,,,,,,,,,,,0,,,,-0.00245,,,,,,100.0103378,,,,
,27974510.275,100.0112228,-40054.763671875,-0.00358124500899241,1.61885235562502E-6,1,0.999253354069792,40.0298881530762,1.99094528392654,21.3099997490644,-0.0405635055166102,-0.00730076118685308,0.25,-1.51215296891377E-5,-0.00360155678348178,-2.58721735494562E-5,100.0112228,100.0112228,-40059.86328125,-40049.6640625,56.9807190519291,20.3766397945645,23.288654,0,0,0,40,4449,99.8727,-40054.763671875,,,,,,,,,,,,,0,,,,0.0049,,,,,,100.0112228,,,,
,27974607.465,100.0099869,-44912.84375,-0.00353553010547671,1.67698636250081E-6,1,0.999253354069792,40.0298881530762,1.99101794651562,21.3099997490644,-0.0400485349381196,-0.0072016300948713,0.25,-1.44446763473914E-5,-0.00355561384113464,-2.49878536671162E-5,100.0099869,100.0099869,-44917.9921875,-44907.6953125,56.8916134007368,20.3733527408604,22.909004,0,0,0,40,4449,99.86435,-44912.84375,,,,,,,,,,,,,0,,,,0,,,,,,100.0099869,,,,
,27974701.68,100.0114975,-49620.048828125,-0.00347938010695931,1.90268790577196E-6,1,0.999253354069792,40.0298881530762,1.99095975600654,21.3099997490644,-0.0394150504212562,-0.0070681057754031,0.25,-1.26025350705327E-5,-0.0034991776626149,-2.29046552365968E-5,100.0114975,100.0114975,-49630.01953125,-49610.078125,56.9510171681983,20.3738099563524,22.909004,0,0,0,40,4449,99.85295,-49620.048828125,,,,,,,,,,,,,0,,,,-0.00245,,,,,,100.0114975,,,,
,27974799.695,100.008934,-54519.58203125,-0.00341808370560542,1.81360008677326E-6,1,0.999253354069792,40.0298881530762,1.99110617225131,21.3099997490644,-0.038712784868547,-0.00700641398636604,0.25,-1.79413331115577E-5,-0.00343754547249387,-2.80266467713848E-5,100.008934,100.008934,-54532.0234375,-54507.140625,57.2675767184868,20.3750848512538,23.288654,0,0,0,40,4449,99.84515,-54519.58203125,,,,,,,,,,,,,0,,,,-0.00245,,,,,,100.008934,,,,
,27974895.95,100.0090256,-59331.76953125,-0.00335417886113443,2.05740476568068E-6,1,0.999253354069792,40.0298881530762,1.99108602881425,21.3099997490644,-0.0379884175175657,-0.00687846092373799,0.25,-1.79396052624372E-5,-0.00337330379167,-2.77734083227948E-5,100.0090256,100.0090256,-59334.375,-59329.1640625,56.8970848003714,20.3747951464002,23.288654,0,0,0,40,4449,99.83695,-59331.76953125,,,,,,,,,,,,,0,,,,-0.0049,,,,,,100.0090256,,,,
,27974991.055,100.0088272,-64081.541015625,-0.00328099672722561,2.00168526813357E-6,1,0.999253354069792,40.0298881530762,1.9912372597595,21.3099997490644,-0.0371610102604798,-0.00673784458063977,0.25,-1.83974941996051E-5,-0.00329972891989318,-2.79586570320656E-5,100.0088272,100.0088272,-64091.80859375,-64071.2734375,57.068261446083,20.3748566867086,22.909004,0,0,0,40,4449,99.8294,-64081.541015625,,,,,,,,,,,,,0,,,,-0.0049,,,,,,100.0088272,,,,
,27975087.555,100.0078583,-68906.8671875,-0.00320792256141299,2.26213533718223E-6,1,0.999253354069792,40.0298881530762,1.99112698761366,21.3099997490644,-0.0363279953907102,-0.00660882491383733,0.25,-1.99326633627762E-5,-0.00322625874366484,-2.92292779174992E-5,100.0078583,100.0078583,-68919.4140625,-68894.3203125,56.8064158921406,20.3703323002675,22.529354,0,0,0,40,4449,99.8223,-68906.8671875,,,,,,,,,,,,,0,,,,-0.00245,,,,,,100.0078583,,,,
,27975184.585,100.0073547,-73753.51171875,-0.00312429472351918,2.4166982861303E-6,1,0.999253354069792,40.0298881530762,1.99132315360593,21.3099997490644,-0.0354081929100468,-0.00630261167715562,0.25,-7.60422156356162E-6,-0.00314221251947947,-1.65291169752793E-5,100.0073547,100.0073547,-73766.015625,-73741.0078125,56.8783257159099,20.3729399495419,22.909004,0,0,0,40,4449,99.81595,-73753.51171875,,,,,,,,,,,,,0,,,,0.00245,,,,,,100.0073547,,,,
,27975279.61,100.00831985,-78505.49609375,-0.003049932323551,2.12671830485955E-6,1,0.999253354069792,40.0298881530762,1.99115964997307,21.3099997490644,-0.0345489244925066,-0.006232343234979,0.25,-1.45536941783266E-5,-0.00306742784252323,-2.32483977957253E-5,100.0082092,100.0084305,-78518.0546875,-78492.9375,56.9314764552176,20.3733954522116,23.288654,0,0,0,40,4449,99.80785,-78505.49609375,,,,,,,,,,,,,0,,,,0,,,,,,100.00831985,,,,
,27975375.08,100.0058823,-83275.27734375,-0.00296617475537936,2.13282803739885E-6,1,0.999253354069792,40.0298881530762,1.99100744496829,21.3099997490644,-0.0335978795460387,-0.00606122641936281,0.25,-1.42495179691601E-5,-0.0029832135994148,-2.2648303497539E-5,100.0058823,100.0058823,-83290.2109375,-83260.34375,56.7954730928714,20.3720560917226,23.288654,0,0,0,40,4449,99.80295,-83275.27734375,,,,,,,,,,,,,0,,,,0,,,,,,100.0058823,,,,
,27975468.4,100.0034332,-87937.15234375,-0.00287899087757899,2.60579088868085E-6,1,0.999253354069792,40.0298881530762,1.99091478310399,21.3099997490644,-0.0326089105109487,-0.00588422505095709,0.25,-1.40060190209894E-5,-0.0028955510113643,-2.21043503077295E-5,100.0034332,100.0034332,-87951.9453125,-87922.359375,57.0416860764291,20.3674564034362,22.909004,0,0,0,40,4449,99.79785,-87937.15234375,,,,,,,,,,,,,0,,,,-0.00245,,,,,,100.0034332,,,,
,27975588.86,100.0022659,-87408.8359375,-0.00288908034056585,2.29933983523924E-6,1,0.999253354069792,40.0298881530762,1.99095698492429,21.3099997490644,-0.0327201048806303,-0.00592615575378153,0.25,-1.59184644137961E-5,-0.00290569080945143,-2.40622075047548E-5,100.0022659,100.0022659,-87418.890625,-87398.78125,57.1135959001984,20.3715651828281,22.529354,0,0,0,40,4449,99.79775,-87408.8359375,,,,,,,,,,,,,0,,,,0,,,,,,100.0022659,,,,
,27975682.74,99.9981842,-82717.0703125,-0.00297190690771458,1.81261006155595E-6,1,0.999253354069792,40.0298881530762,1.99097183263374,21.3099997490644,-0.0336603592030957,-0.00608334467768215,0.25,-1.51971016210906E-5,-0.00298897351031629,-2.36248347831762E-5,99.9981842,99.9981842,-82732.1875,-82701.953125,57.0065127930637,20.3731100058685,23.288654,0,0,0,40,4449,99.7985,-82717.0703125,,,,,,,,,,,,,0,,,,-0.00245,,,,,,99.9981842,,,,
,27975780.345,99.9971619,-77839.26171875,-0.00305746690128558,2.59166539881776E-6,1,0.999253354069792,40.0298881530762,1.9910775653805,21.3099997490644,-0.0346387293908359,-0.00621412376047771,0.25,-1.16372538264504E-5,-0.00307501074782551,-2.0345952254127E-5,99.9971619,99.9971619,-77844.390625,-77834.1328125,57.0112025641791,20.3703553940034,22.529354,0,0,0,40,4449,99.79995,-77839.26171875,,,,,,,,,,,,,0,,,,-0.00245,,,,,,99.9971619,,,,
,27975876.325,99.9977112,-73041.8359375,-0.00313825346059324,1.95706887528052E-6,1,0.999253354069792,40.0298881530762,1.9911511280534,21.3099997490644,-0.0355575273183716,-0.00636377083157354,0.25,-1.05847571151787E-5,-0.00315623893749663,-1.95775161743616E-5,99.9977112,99.9977112,-73046.8125,-73036.859375,57.0190188493714,20.3709909798489,22.909004,0,0,0,40,4449,99.803,-73041.8359375,,,,,,,,,,,,,0,,,,-0.00245,,,,,,99.9977112,,,,
,27975972.235,99.9964676,-68249.91796875,-0.00321647024784589,1.87616516040395E-6,1,0.999253354069792,40.0298881530762,1.99103924797188,21.3099997490644,-0.0364333527059494,-0.00656839626457999,0.25,-1.48803174495159E-5,-0.00323486596092551,-2.41835571191737E-5,99.9964676,99.9964676,-68254.953125,-68244.8828125,56.9963516223137,20.3684795904014,22.909004,0,0,0,40,4449,99.80605,-68249.91796875,,,,,,,,,,,,,0,,,,0,,,,,,99.9964676,,,,
,27976067.295,99.994751,-63497.890625,-0.00328992608127119,1.92599648525359E-6,1,0.999253354069792,40.0298881530762,1.9911746887373,21.3099997490644,-0.0372673714086295,-0.00671960621069714,0.25,-1.52293570157967E-5,-0.00330871501559252,-2.48086254541769E-5,99.994751,99.994751,-63507.7734375,-63488.0078125,56.7571732954291,20.3703532099639,22.909004,0,0,0,40,4449,99.8125,-63497.890625,,,,,,,,,,,,,0,,,,0,,,,,,99.994751,,,,
,27976162.745,99.9936676,-58725.248046875,-0.00336000288481075,2.00527348804372E-6,1,0.999253354069792,40.0298881530762,1.99120929709548,21.3099997490644,-0.0380528855246619,-0.00691187804274541,0.25,-1.98182387774121E-5,-0.00337915181102052,-2.96911140685863E-5,99.9936676,99.9936676,-58735.484375,-58715.01171875,56.8400259184676,20.3682655643205,23.288654,0,0,0,40,4449,99.8177,-58725.248046875,,,,,,,,,,,,,0,,,,-0.0049,,,,,,99.9936676,,,,
,27976258.38,99.9937286,-53948.2265625,-0.00342471782787457,1.52492765519419E-6,1,0.999253354069792,40.0298881530762,1.99091591683357,21.3099997490644,-0.0387942488501609,-0.00696291490219116,0.25,-1.29843591194705E-5,-0.00344422789962419,-2.30726333780921E-5,99.9937286,99.9937286,-53963.1953125,-53933.2578125,56.8283014906791,20.3671204280973,22.909004,0,0,0,40,4449,99.8216,-53948.2265625,,,,,,,,,,,,,0,,,,-0.0049,,,,,,99.9937286,,,,
,27976352.275,99.9945526,-49256.314453125,-0.00348768885652648,1.82159384742904E-6,1,0.999253354069792,40.0298881530762,1.99121165605254,21.3099997490644,-0.0395047674207212,-0.0071379204458082,0.25,-1.72174974853047E-5,-0.00350751724433684,-2.75799668668619E-5,99.9945526,99.9945526,-49261.46484375,-49251.1640625,56.9924434797176,20.3683794036043,22.909004,0,0,0,40,4449,99.82675,-49256.314453125,,,,,,,,,,,,,0,,,,-0.00245,,,,,,99.9945526,,,,
,27976447.155,99.9910507,-44513.029296875,-0.00354326119242398,1.70313413293735E-6,1,0.999253354069792,40.0298881530762,1.99145048032406,21.3099997490644,-0.0401408989163737,-0.00723878159431634,0.25,-1.62218298231773E-5,-0.0035633803181188,-2.68088332115947E-5,99.9910507,99.9910507,-44528.11328125,-44497.9453125,57.159711982833,20.3696716158294,23.288654,0,0,0,40,4449,99.8351,-44513.029296875,,,,,,,,,,,,,0,,,,-0.00245,,,,,,99.9910507,,,,
,27976541.64,99.9936447,-39790.2890625,-0.0035899780611861,1.27714043068748E-6,1,0.999253354069792,40.0298881530762,1.99128295933565,21.3099997490644,-0.0406672758441857,-0.007329414594659,0.25,-1.60019770486449E-5,-0.00361033396787803,-2.67931279324053E-5,99.9936447,99.9936447,-39800.38671875,-39780.19140625,57.241001348833,20.3709783408351,22.909004,0,0,0,40,4449,99.84095,-39790.2890625,,,,,,,,,,,,,0,,,,0,,,,,,99.9936447,,,,
,27976637.265,99.9906387,-35013.42578125,-0.0036304180033741,1.34026928352802E-6,1,0.999253354069792,40.0298881530762,1.99118370738425,21.3099997490644,-0.0411266632199095,-0.0073912360617776,0.25,-1.43221452398221E-5,-0.00365097928323606,-2.52911985121192E-5,99.9906387,99.9906387,-35023.33203125,-35003.51953125,56.9400743689291,20.3690713272838,22.909004,0,0,0,40,4449,99.8513,-35013.42578125,,,,,,,,,,,,,0,,,,-0.00245,,,,,,99.9906387,,,,
,27976732.025,99.9897385,-30278.7578125,-0.0036629438836312,1.33590450265035E-6,1,0.999253354069792,40.0298881530762,1.99113521759746,21.3099997490644,-0.0414911309626588,-0.00747259355860591,0.25,-1.57400233611954E-5,-0.00368365580843764,-2.68811940732586E-5,99.9897385,99.9897385,-30286.267578125,-30271.248046875,57.0565370182945,20.3683782215277,22.909004,0,0,0,40,4449,99.85775,-30278.7578125,,,,,,,,,,,,,0,,,,0,,,,,,99.9897385,,,,
,27976825.86,99.9925308,-25588.8681640625,-0.0036877120705461,1.3265550043538E-6,1,0.999253354069792,40.0298881530762,1.99107243218719,21.3200002908707,-0.0417694235619548,-0.00752668770692218,0.25,-1.6121631740929E-5,-0.00370853381279549,-2.7404448422815E-5,99.9925308,99.9925308,-25603.3203125,-25574.416015625,56.9369478548522,20.3720861870721,22.909004,0,0,0,40,4449,99.86535,-25588.8681640625,,,,,,,,,,,,,0,,,,-0.0049,,,,,,99.9925308,,,,
,27976921.485,99.9921265,-20806.6240234375,-0.00370099747032031,8.64324106940974E-7,1,0.999253354069792,40.0298881530762,1.99112439563057,21.3099997490644,-0.0419197698941625,-0.00755876318732281,0.25,-1.65412496748996E-5,-0.00372186375540732,-2.7931526049448E-5,99.9921265,99.9921265,-20811.9375,-20801.310546875,56.7462304961599,20.3748809444209,23.288654,0,0,0,40,4449,99.87165,-20806.6240234375,,,,,,,,,,,,,0,,,,0.0049,,,,,,99.9921265,,,,
,27977015.36,99.9907837,-16116.8764648438,-0.00369967318760641,8.95832555578256E-7,1,0.999253354069792,40.0298881530762,1.99110273987085,21.3099997490644,-0.0419031705929416,-0.00756078673523537,0.25,-1.69035779067098E-5,-0.00372050316198838,-2.83527236754859E-5,99.9907837,99.9907837,-16129.4609375,-16104.2919921875,56.9252234270637,20.3698229507125,22.529354,0,0,0,40,4449,99.8797,-16116.8764648438,,,,,,,,,,,,,0,,,,-0.00245,,,,,,99.9907837,,,,
,27977112.46,99.9913254,-11264.1762695312,-0.0036749206392016,6.78662688655213E-7,1,0.999253354069792,40.0298881530762,1.99108665914272,21.3099997490644,-0.0416226708477586,-0.00750735327902071,0.25,-1.64896800518825E-5,-0.00369558468962404,-2.79201899343864E-5,99.9913254,99.9913254,-11276.6103515625,-11251.7421875,57.0776409883137,20.3711291257895,23.288654,0,0,0,40,4449,99.8867,-11264.1762695312,,,,,,,,,,,,,0,,,,0.00245,,,,,,99.9913254,,,,
,27977205.455,99.9916992,-6613.52661132813,-0.00361429825651681,4.21929151617364E-7,1,0.999253354069792,40.0298881530762,1.99101905936545,21.3099997490644,-0.0409336355707153,-0.00738790142830958,0.25,-1.65788210058828E-5,-0.00363459633024699,-2.78745625443533E-5,99.9916992,99.9916992,-6623.59716796875,-6603.4560546875,56.861911517006,20.3742666833428,22.909004,0,0,0,40,4449,99.89445,-6613.52661132813,,,,,,,,,,,,,0,,,,0,,,,,,99.9916992,,,,
,27977299.915,99.9921951,-1892.31268310547,-0.00346674987765314,3.32951011883136E-7,1,0.999253354069792,40.0298881530762,1.99106861750634,21.3099997490644,-0.0392618156130954,-0.00709479633108994,0.25,-1.65967581144689E-5,-0.00348619684125471,-2.74788489277315E-5,99.9921951,99.9921951,-1904.85046386719,-1879.77490234375,57.0698247031214,20.3770817187203,23.288654,0,0,0,40,4449,99.9007,-1892.31268310547,,,,,,,,,,,,,0,,,,0,,,,,,99.9921951,,,,
,27977392.275,99.9940948,2717.99304199219,-0.00210714051474477,4.99059542241873E-7,1,0.999253354069792,40.0298881530762,1.99122083709685,21.3200002908707,-0.023865875431159,-0.00431142810584616,0.25,-9.98567717137453E-6,-0.00211896309159905,-1.65946815816928E-5,99.9940948,99.9940948,2702.98950195313,2732.99658203125,56.9314764552176,20.370224225196,22.909004,0,0,0,40,4449,99.90465,2717.99304199219,,,,,,,,,,,,,0,,,,-0.00245,,,,,,99.9940948,,,,
,27977490.905,99.999176,7650.3017578125,-0.00114122652536058,8.7930791535731E-7,1,0.999253354069792,40.0298881530762,1.99112170052113,21.3099997490644,-0.01292435658577,-0.00233986191101325,0.25,-5.85550692665327E-6,-0.00114763550026618,-9.42159254137732E-6,99.999176,99.999176,7637.9931640625,7662.6103515625,57.105779615006,20.3694593672448,23.288654,0,0,0,40,4449,99.9021,7650.3017578125,,,,,,,,,,,,,0,,,,-0.0049,,,,,,99.999176,,,,
,27977589.305,100.0055618,12568.1171875,0.000710835361803815,1.22449479261213E-6,1,0.999253354069792,40.0298881530762,1.99101141492269,21.3099997490644,0.00805060721126878,0.00145288386159416,0.25,3.26323523116948E-6,0.000714833557066716,5.47114436809783E-6,100.0055618,100.0055618,12555.576171875,12580.658203125,56.6258597041983,20.3728663106254,22.909004,0,0,0,40,4449,99.89705,12568.1171875,,,,,,,,,,,,,0,,,,-0.00245,,,,,,100.0055618,,,,
,27977684.69,100.0077286,17335.919921875,0.00248967111154284,1.18398710730237E-6,1,0.999253354069792,40.0298881530762,1.99118949212682,21.3099997490644,0.0282001948526438,0.00508534575896901,0.25,1.11351611080448E-5,0.00250369392865061,1.88262880587145E-5,100.0077286,100.0077286,17328.322265625,17343.517578125,56.8806706014676,20.3678935344855,22.909004,0,0,0,40,4449,99.8902,17335.919921875,,,,,,,,,,,,,0,,,,0,,,,,,100.0077286,,,,
,27977783.26,100.008728,22263.4384765625,0.00333461974726478,1.30891955816276E-6,1,0.999253354069792,40.0298881530762,1.99108581609459,21.3099997490644,0.0377681064286329,0.00681739806722142,0.25,1.5542756979958E-5,0.00335342628650357,2.57892967232656E-5,100.008728,100.008728,22250.904296875,22275.97265625,56.9799374234099,20.3624293826769,23.288654,0,0,0,40,4449,99.88225,22263.4384765625,,,,,,,,,,,,,0,,,,0.00245,,,,,,100.008728,,,,
,27977879.08,100.0099335,27054.1162109375,0.00356228255260064,1.39263113016672E-6,1,0.999253354069792,40.0298881530762,1.99106988135043,21.3099997490644,0.0403473229304696,0.00727892667435604,0.25,1.63207702234002E-5,0.00358240203252886,2.72030293689982E-5,100.0099335,100.0099335,27039.025390625,27069.20703125,56.9439825115252,20.3643486166826,22.909004,0,0,0,40,4449,99.87185,27054.1162109375,,,,,,,,,,,,,0,,,,-0.00245,,,,,,100.0099335,,,,
,27977975.4,100.0105286,31866.751953125,0.00360920306099793,1.59709163519077E-6,1,0.999253354069792,40.0298881530762,1.99117087120537,21.3099997490644,0.0408835427669944,0.00736110404814855,0.25,1.5355756292132E-5,0.00362962035719926,2.63095277327326E-5,100.0105286,100.0105286,31861.921875,31871.58203125,56.9267866841022,20.3670514749545,22.909004,0,0,0,40,4449,99.86215,31866.751953125,,,,,,,,,,,,,0,,,,-0.0049,,,,,,100.0105286,,,,
,27978073.105,100.0109482,36749.4375,0.00359538048327871,1.49043099296766E-6,1,0.999253354069792,40.0298881530762,1.99077083818304,21.3099997490644,0.0407126313422495,0.00737060217051224,0.25,1.88078857350594E-5,0.00361573891764729,2.96727136072833E-5,100.0109482,100.0109482,36739.48046875,36759.39453125,56.9181887703906,20.3777159196324,22.909004,0,0,0,40,4449,99.85105,36749.4375,,,,,,,,,,,,,0,,,,0.00245,,,,,,100.0109482,,,,
,27978172.2,100.0096588,41704.080078125,0.00355823119032248,1.5322831429937E-6,1,0.999253354069792,40.0298881530762,1.99128841694286,21.3099997490644,0.0403079937865796,0.00726396853629089,0.25,1.58287160498424E-5,0.00357841818779324,2.64966761558699E-5,100.0096588,100.0096588,41691.21484375,41716.9453125,56.946327397083,20.3722683289788,22.909004,0,0,0,40,4449,99.84275,41704.080078125,,,,,,,,,,,,,0,,,,-0.00245,,,,,,100.0096588,,,,
,27978267.78,100.00888825,46482.025390625,0.00350885413629939,1.60553201776898E-6,1,0.999253354069792,40.0298881530762,1.99133392151982,21.3099997490644,0.039752349851049,0.00714908312891222,0.25,1.44137355445834E-5,0.00352879366190138,2.4860750257116E-5,100.008728,100.0090485,46469.49609375,46494.5546875,56.7485753817175,20.3706607142016,22.909004,0,0,0,40,4449,99.8342,46482.025390625,,,,,,,,,,,,,0,,,,0,,,,,,100.00888825,,,,
,27978365.17,100.0098572,51347.208984375,0.00344868922871906,2.17872872893632E-6,1,0.999253354069792,40.0298881530762,1.99131489315246,21.3099997490644,0.0390738461300835,0.00700857335367556,0.25,1.26521443548354E-5,0.00346832022085651,2.2844920894597E-5,100.0098572,100.0098572,51337.16796875,51357.25,56.7743691228522,20.369954795886,23.668306,0,0,0,40,4449,99.82375,51347.208984375,,,,,,,,,,,,,0,,,,-0.00245,,,,,,100.0098572,,,,
,27978464.245,100.0092926,56299.353515625,0.00339151734143223,1.8179867064083E-6,1,0.999253354069792,40.0298881530762,1.99129330992746,21.3099997490644,0.0384235739600032,0.00690627419708944,0.25,1.37357645047858E-5,0.00341084831785946,2.36994916294545E-5,100.0092926,100.0092926,56289.390625,56309.31640625,56.8540952318137,20.370253068248,23.288654,0,0,0,40,4449,99.81585,56299.353515625,,,,,,,,,,,,,0,,,,0,,,,,,100.0092926,,,,
,27978559.685,100.0087585,61069.85546875,0.00331352769193701,2.1959706985865E-6,1,0.999253354069792,40.0298881530762,1.99105791276212,21.3099997490644,0.0375345824578306,0.00675525298385232,0.25,1.42332209734901E-5,0.00333243921654735,2.39086598391361E-5,100.0087585,100.0087585,61062.40625,61077.3046875,56.8165770628906,20.3650472857574,23.288654,0,0,0,40,4449,99.8084,61069.85546875,,,,,,,,,,,,,0,,,,0,,,,,,100.0087585,,,,
,27978657.58,100.0084839,65962.8671875,0.00324016112697268,2.04938666730243E-6,1,0.999253354069792,40.0298881530762,1.99108388362642,21.3099997490644,0.0367029900386305,0.00661312401427046,0.25,1.46263997926654E-5,0.00325867921111937,2.40275821119327E-5,100.0084839,100.0084839,65950.4375,65975.296875,56.5680191937752,20.3726188291653,22.909004,0,0,0,40,4449,99.7999,65962.8671875,,,,,,,,,,,,,0,,,,0,,,,,,100.0084839,,,,
,27978754.635,100.0065994,70815.6328125,0.00316499935971689,2.31591989295347E-6,1,0.999253354069792,40.0298881530762,1.99111031164704,21.3099997490644,0.0358537681073659,0.00645175132318078,0.25,1.36347483791038E-5,0.00318311636731761,2.27514603847454E-5,100.0065994,100.0065994,70803.234375,70828.03125,56.7798405224868,20.373858665827,23.288654,0,0,0,40,4449,99.79455,70815.6328125,,,,,,,,,,,,,0,,,,-0.0049,,,,,,100.0065994,,,,
,27978849.835,100.0080261,75571.05859375,0.00308877172978371,2.40248270745884E-6,1,0.999253354069792,40.0298881530762,1.99112161681244,21.3099997490644,0.0349814156765253,0.00634943160523075,0.25,1.80392023824484E-5,0.00310646381941072,2.69040625842985E-5,100.0080261,100.0080261,75565.96875,75576.1484375,56.7532651528329,20.3704482317131,23.668306,0,0,0,40,4449,99.78575,75571.05859375,,,,,,,,,,,,,0,,,,-0.00245,,,,,,100.0080261,,,,
,27978948.705,100.0073242,80515.0078125,0.00299451346464909,2.16550395730237E-6,1,0.999253354069792,40.0298881530762,1.99094040364049,21.3099997490644,0.0339033349849251,0.00620026505340594,0.25,2.15257378144643E-5,0.00301167964360297,3.00827081165836E-5,100.0073242,100.0073242,80505.0625,80524.953125,56.6164801619675,20.3764193177876,22.909004,0,0,0,40,4449,99.78185,80515.0078125,,,,,,,,,,,,,0,,,,0,,,,,,100.0073242,,,,
,27979047.375,100.005394,85447.8515625,0.00291188586344346,2.59465895183664E-6,1,0.999253354069792,40.0298881530762,1.99111677845126,21.3099997490644,0.0329969862833464,0.00588106483618671,0.25,7.87617813328655E-6,0.0029286393326773,1.60633128722001E-5,100.005394,100.005394,85437.921875,85457.78125,56.6258597041983,20.3675305399211,23.288654,0,0,0,40,4449,99.77665,85447.8515625,,,,,,,,,,,,,0,,,,0,,,,,,100.005394,,,,
,27979169.095,100.0037994,89928.92578125,0.00283377640500586,1.97103450815783E-6,1,0.999253354069792,40.0298881530762,1.99114754373826,21.3200002908707,0.0321037568139829,0.00577370434789465,0.25,1.21504822626335E-5,0.00285008926715072,2.00919412597202E-5,100.0037994,100.0037994,89921.84375,89936.0078125,56.6602513590445,20.3668597594604,23.288654,0,0,0,40,4449,99.7737,89928.92578125,,,,,,,,,,,,,0,,,,0.0049,,,,,,100.0037994,,,,
,27979264.165,100.00177,85189.16796875,0.00291517058358933,2.19631340463001E-6,1,0.999253354069792,40.0298881530762,1.99103612841182,21.3099997490644,0.0330241141406103,0.00593765183032113,0.25,1.23084063047598E-5,0.0029319294794325,2.05334831093166E-5,100.00177,100.00177,85179.4453125,85198.890625,56.8462789466214,20.3742196592415,22.909004,0,0,0,40,4449,99.77575,85189.16796875,,,,,,,,,,,,,0,,,,0.00245,,,,,,100.00177,,,,
,27979362.335,99.9987259,80280.6875,0.00299956898243567,1.94714752301065E-6,1,0.999253354069792,40.0298881530762,1.99106213246745,21.3099997490644,0.0339900475427869,0.00605434627063114,0.25,7.73203192151125E-6,0.00301680212781207,1.62275251644394E-5,99.9987259,99.9987259,80270.8125,80290.5625,56.3687039213713,20.3743131751189,23.288654,0,0,0,40,4449,99.77635,80280.6875,,,,,,,,,,,,,0,,,,0.00245,,,,,,99.9987259,,,,
,27979459.31,99.9979935,75434.1328125,0.00308639699108287,2.18138300606337E-6,1,0.999253354069792,40.0298881530762,1.99087303866051,21.3099997490644,0.0349537101528836,0.00632464839015833,0.25,1.63341040210372E-5,0.00310407993804992,2.51847810425938E-5,99.9979935,99.9979935,75427.1328125,75441.1328125,56.7134020983521,20.3782446680875,23.288654,0,0,0,40,4449,99.78145,75434.1328125,,,,,,,,,,,,,0,,,,-0.00245,,,,,,99.9979935,,,,
,27979555.12,99.9967422,70643.27734375,0.00316810521106445,2.46248182824856E-6,1,0.999253354069792,40.0298881530762,1.99104589773616,21.3099997490644,0.0358852393861279,0.00647265620388991,0.25,1.49476240449824E-5,0.00318623531352618,2.40845882737354E-5,99.9967422,99.9967422,70628.4765625,70658.078125,56.7087123272368,20.3693892270679,23.288654,0,0,0,40,4449,99.78355,70643.27734375,,,,,,,,,,,,,0,,,,-0.0049,,,,,,99.9967422,,,,
,27979653.355,99.9949951,65733.19921875,0.00324151270740709,2.12582282841471E-6,1,0.999253354069792,40.0298881530762,1.99088904343662,21.3099997490644,0.0367104006881307,0.00664063302999447,0.25,1.68653572432028E-5,0.00326003070919156,2.62886506369238E-5,99.9949951,99.9949951,65720.8828125,65745.515625,56.6696309012752,20.3765584343647,23.668306,0,0,0,40,4449,99.78445,65733.19921875,,,,,,,,,,,,,0,,,,0.00245,,,,,,99.9949951,,,,
,27979749.975,99.9920044,60902.29296875,0.00332712496619489,1.66794363502374E-6,1,0.999253354069792,40.0298881530762,1.99100472876982,21.3099997490644,0.0376884509516155,0.00677816524852389,0.25,1.38782130809337E-5,0.00334611445483348,2.35956658453357E-5,99.9920044,99.9920044,60892.52734375,60912.05859375,56.5922496778714,20.3730182709836,23.288654,0,0,0,40,4449,99.79325,60902.29296875,,,,,,,,,,,,,0,,,,0,,,,,,99.9920044,,,,
,27979850.31,99.9934998,55886.810546875,0.00339021226977226,1.75031192823115E-6,1,0.999253354069792,40.0298881530762,1.99094553499676,21.3099997490644,0.0384059606743549,0.0068819336060428,0.25,1.19114861182494E-5,0.00340953871342195,2.18691487064162E-5,99.9934998,99.9934998,55879.3203125,55894.30078125,56.9549253107945,20.3738411783097,23.288654,0,0,0,40,4449,99.80095,55886.810546875,,,,,,,,,,,,,0,,,,0,,,,,,99.9934998,,,,
,27979947.915,99.9928131,51009.189453125,0.00346030961190665,1.8651667149013E-6,1,0.999253354069792,40.0298881530762,1.99085705541974,21.3099997490644,0.0391896900192876,0.00707156594533746,0.25,1.62977068401557E-5,0.00347999407926582,2.65530216251545E-5,99.9928131,99.9928131,50996.90234375,51021.4765625,56.6102271338137,20.3744739452197,23.288654,0,0,0,40,4449,99.80665,51009.189453125,,,,,,,,,,,,,0,,,,-0.00245,,,,,,99.9928131,,,,
,27980044.025,99.99366,46206.740234375,0.00352377405237214,1.83253879742698E-6,1,0.999253354069792,40.0298881530762,1.99104836269222,21.3099997490644,0.0399188684724505,0.00716151888072714,0.25,1.29696318813278E-5,0.00354380044879648,2.34604481665329E-5,99.99366,99.99366,46199.41015625,46214.0703125,56.811105663256,20.3627690281494,23.288654,0,0,0,40,4449,99.811,46206.740234375,,,,,,,,,,,,,0,,,,0.00245,,,,,,99.99366,,,,
,27980139.08,99.9922104,41456.171875,0.0035671841054541,1.5135980347214E-6,1,0.999253354069792,40.0298881530762,1.99101470931326,21.3099997490644,0.0404085319499054,0.00725597068185051,0.25,1.36275221601104E-5,0.00358742641168552,2.43173909194538E-5,99.9922104,99.9922104,41446.59765625,41465.74609375,56.8048526351022,20.3767869811873,23.288654,0,0,0,40,4449,99.8188,41456.171875,,,,,,,,,,,,,0,,,,-0.00245,,,,,,99.9922104,,,,
,27980237.405,99.990799,36541.451171875,0.00361738369503943,1.38092693521758E-6,1,0.999253354069792,40.0298881530762,1.99096833748767,21.3099997490644,0.0409737972054042,0.00737000990936331,0.25,1.48223916856451E-5,0.00363787726833011,2.57377172302016E-5,99.990799,99.990799,36533.9609375,36548.94140625,56.8376810329099,20.3645697148546,23.288654,0,0,0,40,4449,99.8275,36541.451171875,,,,,,,,,,,,,0,,,,-0.00245,,,,,,99.990799,,,,
,27980330.45,99.9909286,31891.5341796875,0.00365330238192919,9.93457823311505E-7,1,0.999253354069792,40.0298881530762,1.99108343229717,21.3099997490644,0.0413841143907133,0.00743494044810242,0.25,1.41456786873596E-5,0.00367397280798291,2.52299263470829E-5,99.9909286,99.9909286,31881.708984375,31901.359375,56.8095424062176,20.3678337262555,23.288654,0,0,0,40,4449,99.8359,31891.5341796875,,,,,,,,,,,,,0,,,,0,,,,,,99.9909286,,,,
,27980423.33,99.9910355,27248.955078125,0.00368099283796251,1.39683809303451E-6,1,0.999253354069792,40.0298881530762,1.99090737505538,21.3099997490644,0.0416889580550636,0.00751898016734955,0.25,1.66921133774595E-5,0.00370178354822382,2.79387162061658E-5,99.9910355,99.9910355,27238.830078125,27259.080078125,56.8392442899483,20.3638852587559,23.288654,0,0,0,40,4449,99.8435,27248.955078125,,,,,,,,,,,,,0,,,,-0.00245,,,,,,99.9910355,,,,
,27980516.19,99.9893723,22608.7177734375,0.00369622501924737,1.18903301746356E-6,1,0.999253354069792,40.0298881530762,1.99106778286579,21.3099997490644,0.0418666509043637,0.00753763324246158,0.25,1.55524084678369E-5,0.00371707681439123,2.69021845273619E-5,99.9893723,99.9893723,22601.56640625,22615.869140625,56.6235148186406,20.3666305517268,23.288654,0,0,0,40,4449,99.8497,22608.7177734375,,,,,,,,,,,,,0,,,,0.00245,,,,,,99.9893723,,,,
,27980610.5,99.9894409,17893.9501953125,0.0036993630691427,9.87384708405806E-7,1,0.999253354069792,40.0298881530762,1.99099792421644,21.3200002908707,0.0418959504649571,0.00756948454050207,0.25,1.77768864113623E-5,0.0037201976955478,2.92104237634183E-5,99.9894409,99.9894409,17878.6328125,17909.267578125,56.7728058658137,20.3657100551965,23.288654,0,0,0,40,4449,99.8605,17893.9501953125,,,,,,,,,,,,,0,,,,-0.00245,,,,,,99.9894409,,,,
,27980704.64,99.9924622,13191.3403320312,0.00368781275442908,6.95023082228513E-7,1,0.999253354069792,40.0298881530762,1.99112775263965,21.3099997490644,0.0417710015520115,0.00752596073593888,0.25,1.58708686655928E-5,0.00370856050614917,2.73176763172498E-5,99.9924622,99.9924622,13176.2275390625,13206.453125,56.9697762526599,20.3674645301334,23.668306,0,0,0,40,4449,99.86705,13191.3403320312,,,,,,,,,,,,,0,,,,-0.0049,,,,,,99.9924622,,,,
,27980798.47,99.9906082,8498.3349609375,0.00364630212274404,7.20639650887462E-7,1,0.999253354069792,40.0298881530762,1.99106116509441,21.3099997490644,0.0412977638077958,0.00744924645179883,0.25,1.63687362348954E-5,0.00366678910674718,2.77452636377522E-5,99.9906082,99.9906082,8488.5302734375,8508.1396484375,57.1761261817368,20.3654571311031,23.288654,0,0,0,40,4449,99.8746,8498.3349609375,,,,,,,,,,,,,0,,,,-0.00245,,,,,,99.9906082,,,,
,27980892.025,99.9921036,3822.84851074219,0.00354585757807352,3.72338161760207E-7,1,0.999253354069792,40.0298881530762,1.99100354485299,21.3099997490644,0.0401581256474457,0.00724751627012343,0.25,1.61987071309583E-5,0.00356575725892065,2.73107280983887E-5,99.9921036,99.9921036,3810.33984375,3835.35717773438,56.9478906541214,20.3662739179118,23.288654,0,0,0,40,4449,99.8831,3822.84851074219,,,,,,,,,,,,,0,,,,-0.00245,,,,,,99.9921036,,,,
,27980970.655,99.9919281,-0.418653771281242,0.00303237471159142,1.03509505889733E-6,1,0.999253354069792,40.0298881530762,1.99109767501564,21.3099997490644,0.0343439463543002,0.00619947924320823,0.25,1.39365136198175E-5,0.00304938057902516,2.34652577861033E-5,99.9919281,99.9919281,-0.441489428281784,-0.395818114280701,56.9400743689291,20.3685926952609,23.288654,0,0,0,40,4417,99.88785,-0.418653771281242,,,,,,,,,,,,,0,,,,0,,,,,,99.9919281,,,,