File: data/monolayers/nanoparticles/Ac_CoFe_C_2/vsm/data_dispersion/YF45.dat
[Header]
; VSM Data File (default extension .dat)
; Copyright (c) 2003-2013, Quantum Design, Inc. All rights reserved.
TITLE,YF45
FILEOPENTIME,27918454.41,11/20/2018,11:08 am
BYAPP,VSM,2.0,2.0
INFO,PPMS VSM Option Release 1.4.10 Build 1,APPNAME
INFO,Quantum Design Linear Motor Servo Controller,MOTOR_MODULE_NAME
INFO,3101-100 M1,MOTOR_HW_VERSION
INFO,MMC1014,MOTOR_SERIAL_NUMBER
INFO,SRV No X-over 01.03.11,MOTOR_SOFTWARE_VERSION
INFO,Quantum Design VSM Detection Module,VSM_MODULE_NAME
INFO,3101-150 F0,VSM_HW_VERSION
INFO,VSM707,VSM_SERIAL_NUMBER
INFO,VSM No X-over 01.02.05 May 20 2008 13:51:47,VSM_SOFTWARE_VERSION
INFO,704,PREAMP_SERIAL_NUMBER
INFO,822,COIL_SERIAL_NUMBER
INFO,0,MOMENT_UNITS
INFO,CoFe2O4,SAMPLE_MATERIAL
INFO,dispersion in ampulle,SAMPLE_COMMENT
INFO,,SAMPLE_MASS
INFO,,SAMPLE_VOLUME
INFO,,SAMPLE_MOLECULAR_WEIGHT
INFO,,SAMPLE_SIZE
INFO,,SAMPLE_SHAPE
DATATYPE,COMMENT,1
DATATYPE,TIME,2
STARTUPAXIS,X,2
STARTUPAXIS,Y1,5
[Data]
Comment,Time Stamp (sec),Temperature (K),Magnetic Field (Oe),Moment (emu),M. Std. Err. (emu),Transport Action,Averaging Time (sec),Frequency (Hz),Peak Amplitude (mm),Center Position (mm),Coil Signal' (mV),Coil Signal" (mV),Range (mV),M. Quad. Signal (emu),M. Raw' (emu),M. Raw" (emu),Min. Temperature (K),Max. Temperature (K),Min. Field (Oe),Max. Field (Oe),Mass (grams),Motor Lag (deg),Pressure (Torr),VSM Status (code),Motor Status (code),Measure Status (code),Measure Count,PPMS Status (code),System Temp. (K),System Field (Oe),Sample Position (deg),Bridge 1 Resistance (ohms),Bridge 1 Excitation (에),Bridge 2 Resistance (ohms),Bridge 2 Excitation (에),Bridge 3 Resistance (ohms),Bridge 3 Excitation (에),Bridge 4 Resistance (ohms),Bridge 4 Excitation (에),Signal 1 Vin (V),Signal 2 Vin (V),Digital Inputs (code),Drive 1 Iout (mA),Drive 1 Ipower (W),Drive 2 Iout (mA),Drive 2 Ipower (W),Pressure (),Map 20 (),Map 21 (),Map 22 (),Map 23 (),Map 24 (),Map 25 (),Map 26 (),Map 27 (),Map 28 (),Map 29 ()
,27919924.5,299.9958496,0.106566414237022,,,2,,,,19.1699996945262,,,,,,,299.9958496,299.9958496,0.106566414237022,0.106566414237022,,,27.464817,,,,-99999999,4369,300.1201,0.106566414237022,,,,,,,,,,,,,,,,,,,,,,,299.9958496,,,,
,27920069.995,299.9976501,4266.23999023438,0.00378023145820175,3.64406049616393E-5,1,0.999253354069792,40.0298881530762,2.00611547426431,19.1500000655651,0.0392806833571998,0.028515283265645,0.25,0.00185582722423035,0.00377888786317125,0.00185827973401361,299.9976501,299.9976501,4261.205078125,4271.27490234375,55.8043681304867,20.2977156563447,27.085165,0,0,0,40,4449,300.1201,4266.23999023438,,,,,,,,,,,,,0,,,,-0.0049,,,,,,299.9976501,,,,
,27920165.125,300.0014954,9020.1572265625,0.00366549107568893,6.6376613792998E-5,1,0.999253354069792,40.0298881530762,2.00555146617825,19.1500000655651,0.0378616097275379,0.0288924410598203,0.25,0.00190960045499931,0.00366411584419924,0.00191197322538331,300.0014954,300.0014954,9012.5341796875,9027.7802734375,55.9333368361598,20.3066530544722,27.085165,0,0,0,40,4449,300.12085,9020.1572265625,,,,,,,,,,,,,0,,,,-0.00245,,,,,,300.0014954,,,,
,27920259.705,300.0039978,13745.3549804687,0.00383650365325,5.52742057475008E-5,1,0.999253354069792,40.0298881530762,2.00532820417418,19.1500000655651,0.0399281955566034,0.0284805264107478,0.25,0.00184396016294758,0.00383516764064292,0.00184644614784475,300.0039978,300.0039978,13735.466796875,13755.2431640625,56.1740784200829,20.3126835457419,27.085165,0,0,0,40,4449,300.11035,13745.3549804687,,,,,,,,,,,,,0,,,,0,,,,,,300.0039978,,,,
,27920357.955,300.0059204,18655.2998046875,0.00381585227285338,3.58085698836094E-5,1,0.999253354069792,40.0298881530762,2.00526644885668,19.1500000655651,0.0398076803294076,0.0277748026423835,0.25,0.0017854495640075,0.00381455669659314,0.00178792121520798,300.0059204,300.0059204,18642.83984375,18667.759765625,56.3773018350829,20.3187285123165,27.085165,0,0,0,40,4449,300.1123,18655.2998046875,,,,,,,,,,,,,0,,,,0,,,,,,300.0059204,,,,
,27920454.125,300.0016785,23465.2666015625,0.00367479412811734,4.39184578232382E-5,1,0.999253354069792,40.0298881530762,2.0051966674824,19.1500000655651,0.0382083477454845,0.0274775206702883,0.25,0.00178378455832757,0.00367350575620056,0.00178616098747421,300.0016785,300.0016785,23460.56640625,23469.966796875,56.3929344054675,20.3189546739706,27.844467,0,0,0,40,4449,300.108,23465.2666015625,,,,,,,,,,,,,0,,,,0,,,,,,300.0016785,,,,
,27920551.655,300.0088501,28338.0478515625,0.00357531911312419,4.08569055135254E-5,1,0.999253354069792,40.0298881530762,2.00493845721506,19.1500000655651,0.0371378357764644,0.0269132149458958,0.25,0.00175160405164311,0.00357405542397846,0.00175391295366913,300.0088501,300.0088501,28328.06640625,28348.029296875,56.3225878387367,20.3273779143803,27.464817,0,0,0,40,4449,300.10465,28338.0478515625,,,,,,,,,,,,,0,,,,0.00245,,,,,,300.0088501,,,,
,27920650.16,300.005127,33260.75390625,0.00346652908165975,4.40609024356875E-5,1,0.999253354069792,40.0298881530762,2.00478288909123,19.1500000655651,0.0359906452907115,0.0261761433733026,0.25,0.00170568918059317,0.00346530084429754,0.00170792551366545,300.005127,300.005127,33255.65234375,33265.85546875,56.1646988778521,20.329822489179,27.464817,0,0,0,40,4449,300.1042,33260.75390625,,,,,,,,,,,,,0,,,,0,,,,,,300.005127,,,,
,27920749.155,300.0137634,38207.9375,0.00322295643079734,5.51436529558759E-5,1,0.999253354069792,40.0298881530762,2.00505328923034,19.1500000655651,0.0332937804629471,0.0253346463406204,0.25,0.00167346386100821,0.00322175709895986,0.00167553772679387,300.0137634,300.0137634,38203.02734375,38212.84765625,56.3984058051021,20.3256155886642,27.085165,0,0,0,40,4449,300.10215,38207.9375,,,,,,,,,,,,,0,,,,-0.0049,,,,,,300.0137634,,,,
,27920845.465,300.0151062,43023.234375,0.00324232629510167,4.39265917773671E-5,1,0.999253354069792,40.0298881530762,2.00537480072934,19.1500000655651,0.0336345450533309,0.0247085239553826,0.25,0.00161461860881566,0.0032411662370326,0.00161670492265938,300.0151062,300.0151062,43015.91796875,43030.55078125,56.4054404617752,20.3255381232139,27.464817,0,0,0,40,4449,300.07245,43023.234375,,,,,,,,,,,,,0,,,,-0.0049,,,,,,300.0151062,,,,
,27920944.24,300.009613,47958.841796875,0.00305230679236504,3.89046506515663E-5,1,0.999253354069792,40.0298881530762,2.00519639508048,19.1500000655651,0.031500368003744,0.0241838838013971,0.25,0.00160151149952747,0.00305116303053947,0.00160347128177387,300.009613,300.009613,47953.4140625,47964.26953125,56.5140868259483,20.3276425467108,27.464817,0,0,0,40,4449,300.06425,47958.841796875,,,,,,,,,,,,,0,,,,0,,,,,,300.009613,,,,
,27921040.945,300.0092773,52794.181640625,0.00294270238905475,4.36094773701125E-5,1,0.999253354069792,40.0298881530762,2.0049827357689,19.1500000655651,0.0303429539698942,0.0234470466311185,0.25,0.00155580543883779,0.00294159337029075,0.00155769236105693,300.0092773,300.0092773,52781.74609375,52806.6171875,56.3616692646983,20.3303422373342,27.464817,0,0,0,40,4449,300.06995,52794.181640625,,,,,,,,,,,,,0,,,,0,,,,,,300.0092773,,,,
,27921140.29,300.0116577,57758.318359375,0.00285674422734309,5.12728931997662E-5,1,0.999253354069792,40.0298881530762,2.00503408566928,19.1500000655651,0.0294617827689631,0.0227371119184595,0.25,0.00150810716895773,0.00285567015062012,0.00150993688506272,300.0116577,300.0116577,57753.26171875,57763.375,56.4296709458714,20.333057225621,27.085165,0,0,0,40,4449,300.0532,57758.318359375,,,,,,,,,,,,,0,,,,0.00245,,,,,,300.0116577,,,,
,27921238.055,300.0090332,62646.876953125,0.00269118966846367,5.43523407454981E-5,1,0.999253354069792,40.0298881530762,2.00506233264761,19.1500000655651,0.027614351999179,0.0222303883839127,0.25,0.00149212491795487,0.00269013257488116,0.0014938446425184,300.0090332,300.0090332,62637.03515625,62656.71875,56.3991874336214,20.3261955412965,27.844467,0,0,0,40,4449,300.0486,62646.876953125,,,,,,,,,,,,,0,,,,-0.00245,,,,,,300.0090332,,,,
,27921337.41,300.0082703,67612.29296875,0.00264776942173037,3.67075331979877E-5,1,0.999253354069792,40.0298881530762,2.00489363333385,19.1500000655651,0.0272514864290978,0.0213803023055243,0.25,0.00142491243629808,0.00264675905789454,0.00142660370233325,300.0082703,300.0082703,67604.65625,67619.9296875,56.4523381729291,20.3374512026743,27.464817,0,0,0,40,4449,300.04555,67612.29296875,,,,,,,,,,,,,0,,,,0,,,,,,300.0082703,,,,
,27921436.85,300.0152283,72581.8984375,0.00253313917763083,3.09957256598598E-5,1,0.999253354069792,40.0298881530762,2.00492637435128,19.1500000655651,0.0260737985244648,0.0204451825840998,0.25,0.00136236068586566,0.00253217374769114,0.00136397650125116,300.0152283,300.0152283,72571.8203125,72591.9765625,56.5719273363714,20.3373877861979,27.464817,0,0,0,40,4449,300.03515,72581.8984375,,,,,,,,,,,,,0,,,,0,,,,,,300.0152283,,,,
,27921534.39,300.0148621,77455.453125,0.00225282769959533,5.80445668777649E-5,1,0.999253354069792,40.0298881530762,2.0049357274452,19.1500000655651,0.0229703844525092,0.0194426626502594,0.25,0.00132259612529795,0.00225189773669155,0.00132402824409886,300.0148621,300.0148621,77450.375,77460.53125,56.5125235689098,20.3374031603653,27.085165,0,0,0,40,4449,300.0162,77455.453125,,,,,,,,,,,,,0,,,,0,,,,,,300.0148621,,,,
,27921632.585,300.0132141,82363.84765625,0.00220755481080185,4.25560863187944E-5,1,0.999253354069792,40.0298881530762,2.00475566672338,19.1500000655651,0.0225289680978976,0.0189226929002779,0.25,0.00128477458076733,0.00220665223225414,0.00128617659602582,300.0132141,300.0132141,82358.9453125,82368.75,56.4703156288714,20.3397429930334,27.085165,0,0,0,40,4449,300.0158,82363.84765625,,,,,,,,,,,,,0,,,,0,,,,,,300.0132141,,,,
,27921728.315,300.0132751,87149.1875,0.00202516990421389,4.35103158878264E-5,1,0.999253354069792,40.0298881530762,2.00478971922061,19.1500000655651,0.0204918479298778,0.018376405241725,0.25,0.00126821554663878,0.00202428460060663,0.00126949760161805,300.0132751,300.0132751,87141.515625,87156.859375,56.4499932873714,20.339996287367,27.085165,0,0,0,40,4449,300.0036,87149.1875,,,,,,,,,,,,,0,,,,0.00245,,,,,,300.0132751,,,,
,27921838.555,300.0122986,88280.65234375,0.00201170483735589,4.90631900974327E-5,1,0.999253354069792,40.0298881530762,2.00490276001422,19.1500000655651,0.0203903605740679,0.0180609052377312,0.25,0.00124266549715053,0.00201083684608759,0.00124393929715533,300.0122986,300.0122986,88273.0234375,88288.28125,56.4679707433137,20.3393800671126,27.085165,0,0,0,40,4449,299.9841,88280.65234375,,,,,,,,,,,,,0,,,,0.00245,,,,,,300.0122986,,,,
,27921931.055,300.0004272,83659.59375,0.0021959314789137,4.20753447880267E-5,1,0.999253354069792,40.0298881530762,2.00497237744531,19.1500000655651,0.0224131272946071,0.0188223785481649,0.25,0.00127777842639422,0.00219503506152823,0.0012791733009607,300.0004272,300.0004272,83649.40625,83669.78125,56.4093486043714,20.341914267032,27.464817,0,0,0,40,4449,299.99585,83659.59375,,,,,,,,,,,,,0,,,,0,,,,,,300.0004272,,,,
,27922030.065,299.9935608,78705.7890625,0.00223399880683692,4.9155907322745E-5,1,0.999253354069792,40.0298881530762,2.00504967456207,19.1500000655651,0.022742902701918,0.0194933613746535,0.25,0.00133023064838681,0.00223306636063082,0.00133165093586349,299.9935608,299.9935608,78696.0078125,78715.5703125,56.3663590358137,20.3380527129914,27.844467,0,0,0,40,4449,299.9949,78705.7890625,,,,,,,,,,,,,0,,,,0.00245,,,,,,299.9935608,,,,
,27922125.925,299.9911499,73914.51953125,0.00237688801804448,4.89160346737221E-5,1,0.999253354069792,40.0298881530762,2.00494480164799,19.1500000655651,0.0242871522844514,0.0202150104018414,0.25,0.0013691360889737,0.00237592504828848,0.00137065042492145,299.9911499,299.9911499,73906.84375,73922.1953125,56.4234179177175,20.3417976856647,27.464817,0,0,0,40,4449,300.003,73914.51953125,,,,,,,,,,,,,0,,,,-0.00245,,,,,,299.9911499,,,,
,27922225.975,299.9860535,68916.59765625,0.0025545163674719,3.78552442781878E-5,1,0.999253354069792,40.0298881530762,2.00473881336921,19.1500000655651,0.0261432204471481,0.0214717933936146,0.25,0.00144926725493154,0.0025534950561306,0.00145089760869212,299.9860535,299.9860535,68909.015625,68924.1796875,56.536754053006,20.3445399070782,27.844467,0,0,0,40,4449,300.0127,68916.59765625,,,,,,,,,,,,,0,,,,-0.0049,,,,,,299.9860535,,,,
,27922324.46,299.9838867,63990.798828125,0.0026109080662194,4.37063748559764E-5,1,0.999253354069792,40.0298881530762,2.00512743790492,19.1500000655651,0.0267480667529138,0.0218182514074036,0.25,0.00146966585789848,0.00260987067823884,0.00147133457340868,299.9838867,299.9838867,63985.58984375,63996.0078125,56.5203398541021,20.3413323966937,27.085165,0,0,0,40,4449,300.0243,63990.798828125,,,,,,,,,,,,,0,,,,0,,,,,,299.9838867,,,,
,27922422.095,299.9895935,59110.396484375,0.00278515125582205,4.52248280155086E-5,1,0.999253354069792,40.0298881530762,2.0049124444917,19.1500000655651,0.0286086620897845,0.0228190767603857,0.25,0.0015278467272486,0.00278406884618463,0.00152962966187331,299.9895935,299.9895935,59102.8203125,59117.97265625,56.414820004006,20.3450853450971,27.464817,0,0,0,40,4449,300.0329,59110.396484375,,,,,,,,,,,,,0,,,,0,,,,,,299.9895935,,,,
,27922520.89,299.9895325,54172.546875,0.0028481820752568,4.60170804630763E-5,1,0.999253354069792,40.0298881530762,2.00478337740486,19.1500000655651,0.0292295051127181,0.0234771351665593,0.25,0.00157502722157459,0.00284706552598284,0.00157685219275116,299.9895325,299.9895325,54164.93359375,54180.16015625,56.4843849422175,20.3464949221963,27.464817,0,0,0,40,4449,300.0448,54172.546875,,,,,,,,,,,,,0,,,,0.00245,,,,,,299.9895325,,,,
,27922615.51,299.9877319,49442.6640625,0.00305110200610447,5.50288219053135E-5,1,0.999253354069792,40.0298881530762,2.00483276374561,19.1500000655651,0.031510232653642,0.0240102032354433,0.25,0.0015867856821387,0.00304997075260658,0.00158874574597506,299.9877319,299.9877319,49432.609375,49452.71875,56.5945945634291,20.3444218212762,27.844467,0,0,0,40,4449,300.05655,49442.6640625,,,,,,,,,,,,,0,,,,0.00245,,,,,,299.9877319,,,,
,27922712.865,299.9851379,44577.033203125,0.00319531423099377,4.73632019428691E-5,1,0.999253354069792,40.0298881530762,2.00468683901587,19.1500000655651,0.0330962472072993,0.0245720846254134,0.25,0.00161145263067165,0.0031941615134959,0.00161350916514095,299.9851379,299.9851379,44569.35546875,44584.7109375,56.6508718168137,20.3482557896066,27.464817,0,0,0,40,4449,300.06465,44577.033203125,,,,,,,,,,,,,0,,,,0,,,,,,299.9851379,,,,
,27922811.29,299.983429,39656.705078125,0.0032132973527001,6.74269945429879E-5,1,0.999253354069792,40.0298881530762,2.00480329731297,19.1500000655651,0.033203766389159,0.0251768119785074,0.25,0.00166149462437215,0.00321210992075639,0.00166356394598644,299.983429,299.983429,39651.69921875,39661.7109375,56.6336759893906,20.3450610997388,27.464817,0,0,0,40,4449,300.0628,39656.705078125,,,,,,,,,,,,,0,,,,-0.0049,,,,,,299.983429,,,,
,27922908.135,299.98356625,34819.494140625,0.00344065487625599,4.11313345743612E-5,1,0.999253354069792,40.0298881530762,2.00485977203232,19.1500000655651,0.0356590053077121,0.0263531159817027,0.25,0.00172567825626039,0.00343941724035302,0.00172789768787804,299.983551,299.9835815,34809.59375,34829.39453125,56.6782288149868,20.3438576632661,27.464817,0,0,0,40,4449,300.08445,34819.494140625,,,,,,,,,,,,,0,,,,0,,,,,,299.98356625,,,,
,27923005.655,299.9865417,29944.56640625,0.0035392622455796,4.58772293069661E-5,1,0.999253354069792,40.0298881530762,2.00499794615027,19.1500000655651,0.0366711607901354,0.0271806027029792,0.25,0.00178133896131399,0.00353798328371511,0.00178362386280072,299.9865417,299.9865417,29937.142578125,29951.990234375,56.6352392464291,20.3460014132424,27.085165,0,0,0,40,4449,300.1003,29944.56640625,,,,,,,,,,,,,0,,,,-0.0049,,,,,,299.9865417,,,,
,27923101.565,299.9896851,25149.3017578125,0.00358472830589023,4.50227400333725E-5,1,0.999253354069792,40.0298881530762,2.00478815875323,19.1500000655651,0.0371594168090228,0.0274063980504373,0.25,0.00179359292530603,0.00358343815039201,0.00179590951395981,299.9896851,299.9896851,25144.455078125,25154.1484375,56.5453519667175,20.3486662419214,27.464817,0,0,0,40,4449,300.1074,25149.3017578125,,,,,,,,,,,,,0,,,,0,,,,,,299.9896851,,,,
,27923196.37,299.9841309,20411.79296875,0.00368007994907034,5.60415520324499E-5,1,0.999253354069792,40.0298881530762,2.00487384284783,19.1500000655651,0.038254017849437,0.0275326174550214,0.25,0.00178809195802015,0.00367879008235921,0.00179047422654343,299.9841309,299.9841309,20401.767578125,20421.818359375,56.5390989385637,20.3478816172291,27.085165,0,0,0,40,4449,300.1181,20411.79296875,,,,,,,,,,,,,0,,,,0,,,,,,299.9841309,,,,
,27923292.9,299.993042,15586.9223632812,0.00378481152308933,5.23077232448199E-5,1,0.999253354069792,40.0298881530762,2.00473465806339,19.1500000655651,0.0393826243695188,0.0280686006507578,0.25,0.00181733048267272,0.00378349674768375,0.00181978279340243,299.993042,299.993042,15579.3486328125,15594.49609375,56.6156985334483,20.349216984981,27.464817,0,0,0,40,4449,300.1234,15586.9223632812,,,,,,,,,,,,,0,,,,0.0049,,,,,,299.993042,,,,
,27923389.335,299.98551945,10767.0424804688,0.00383492121880386,4.52272649049767E-5,1,0.999253354069792,40.0298881530762,2.0048761574752,19.1500000655651,0.0399091602967849,0.0284280619257381,0.25,0.00184014895579814,0.00383358965420875,0.00184263635185782,299.9855042,299.9855347,10761.81640625,10772.2685546875,56.7259081546598,20.347619089821,27.464817,0,0,0,40,4449,300.1294,10767.0424804688,,,,,,,,,,,,,0,,,,0,,,,,,299.98551945,,,,
,27923481.58,299.990509,6156.67822265625,0.00378898934933884,6.22993335813184E-5,1,0.999253354069792,40.0298881530762,2.004865577135,19.1500000655651,0.0393368308936721,0.0286305910539746,0.25,0.0018659619601353,0.00378764025648889,0.00186841961391093,299.990509,299.990509,6149.005859375,6164.3505859375,56.6031924771406,20.3472152633008,27.464817,0,0,0,40,4449,300.1363,6156.67822265625,,,,,,,,,,,,,0,,,,0,,,,,,299.990509,,,,
,27923574.77,299.995575,1498.09692382813,0.00351278251018139,4.63705237950798E-5,1,0.999253354069792,40.0298881530762,2.00535982220531,19.1500000655651,0.0366342474556724,0.0256470256743472,0.25,0.00165042426209668,0.00351158299333731,0.00165270627292389,299.995575,299.995575,1490.46557617187,1505.72827148438,56.3116450394675,20.3435350540934,27.085165,0,0,0,40,4449,300.13635,1498.09692382813,,,,,,,,,,,,,0,,,,-0.00245,,,,,,299.995575,,,,
,27923669.32,299.992218,-3222.35925292969,-0.00377021000639724,5.6709352607298E-5,1,0.999253354069792,40.0298881530762,2.00505304251554,19.1500000655651,-0.0392277451968722,-0.0280156568986682,0.25,-0.0018148172233966,-0.00376889454729494,-0.00181726483223449,299.992218,299.992218,-3227.35522460937,-3217.36328125,56.719655126506,20.3448780610624,27.085165,0,0,0,40,4449,300.1395,-3222.35925292969,,,,,,,,,,,,,0,,,,0,,,,,,299.992218,,,,
,27923765.345,300.0010986,-8021.90747070312,-0.0037989327151593,6.22618292950212E-5,1,0.999253354069792,40.0298881530762,2.00506078694413,19.1500000655651,-0.0393996369791607,-0.0289627840393683,0.25,-0.00189327098873454,-0.00379756419966376,-0.00189573302051191,300.0010986,300.0010986,-8027.1025390625,-8016.71240234375,56.8126689202945,20.3471012327459,27.464817,0,0,0,40,4449,300.13255,-8021.90747070312,,,,,,,,,,,,,0,,,,-0.00245,,,,,,300.0010986,,,,
,27923863.025,300.0006409,-12907.3725585938,-0.00376412319013446,4.82765916432788E-5,1,0.999253354069792,40.0298881530762,2.00503269981554,19.1500000655651,-0.0390853998672531,-0.0284240906970362,0.25,-0.00185188124955292,-0.00376278448969565,-0.00185431937628804,300.0006409,300.0006409,-12909.8251953125,-12904.919921875,56.628204589756,20.347983831697,27.464817,0,0,0,40,4449,300.1391,-12907.3725585938,,,,,,,,,,,,,0,,,,-0.0049,,,,,,300.0006409,,,,
,27923958.985,300.0046692,-17702.759765625,-0.00364089682083272,5.95941939270725E-5,1,0.999253354069792,40.0298881530762,2.00471818111933,19.1500000655651,-0.0376522699898677,-0.0283433233694832,0.25,-0.00186649190481246,-0.00363955287717895,-0.00186884565802815,300.0046692,300.0046692,-17712.97265625,-17692.546875,56.6446187886598,20.3529437697143,27.085165,0,0,0,40,4449,300.13585,-17702.759765625,,,,,,,,,,,,,0,,,,-0.00245,,,,,,300.0046692,,,,
,27924055.025,300.0076294,-22502.611328125,-0.00371760193669364,5.1695741669484E-5,1,0.999253354069792,40.0298881530762,2.00481772191262,19.1500000655651,-0.0386944414505372,-0.0275156567022118,0.25,-0.00178016451103434,-0.00371631377783103,-0.00178256915954557,300.0076294,300.0076294,-22510.25,-22494.97265625,56.7165286124291,20.3535890603632,27.464817,0,0,0,40,4449,300.1371,-22502.611328125,,,,,,,,,,,,,0,,,,-0.0049,,,,,,300.0076294,,,,
,27924152.345,300.0090332,-27365.287109375,-0.00351469987556002,5.10139248520504E-5,1,0.999253354069792,40.0298881530762,2.00469232795696,19.1500000655651,-0.0364090263516113,-0.0270013347195271,0.25,-0.00177014849543159,-0.00351342557369003,-0.00177241704469978,300.0090332,300.0090332,-27367.79296875,-27362.78125,56.6196066760444,20.3526564261516,27.844467,0,0,0,40,4449,300.1286,-27365.287109375,,,,,,,,,,,,,0,,,,0,,,,,,300.0090332,,,,
,27924250.295,300.0077362,-32262.6923828125,-0.00343568422129542,4.64969966016659E-5,1,0.999253354069792,40.0298881530762,2.00475402214793,19.1500000655651,-0.035579819430519,-0.0264628430097881,0.25,-0.00173632522906109,-0.00343443612553513,-0.00173854052644475,300.0072021,300.0082703,-32270.130859375,-32255.25390625,56.6266413327175,20.3535303897023,27.464817,0,0,0,40,4449,300.1143,-32262.6923828125,,,,,,,,,,,,,0,,,,-0.0049,,,,,,300.0077362,,,,
,27924347.515,300.0102844,-37119.134765625,-0.00332731183190578,6.12629711812305E-5,1,0.999253354069792,40.0298881530762,2.00480241760614,19.1500000655651,-0.0344690065430275,-0.0255670590408346,0.25,-0.0016761263111661,-0.00332610775992751,-0.00167826952399839,300.0102844,300.0102844,-37126.703125,-37111.56640625,56.6672860157175,20.3518908267057,27.464817,0,0,0,40,4449,300.11025,-37119.134765625,,,,,,,,,,,,,0,,,,0,,,,,,300.0102844,,,,
,27924448,300.010437,-42141.59375,-0.00326375983195894,4.32145015973329E-5,1,0.999253354069792,40.0298881530762,2.00487240369278,19.1500000655651,-0.03380750792131,-0.0251042576435245,0.25,-0.00164628999381574,-0.00326257868941113,-0.0016483899704806,300.010437,300.010437,-42149.0625,-42134.125,56.6696309012752,20.3534035869166,27.464817,0,0,0,40,4449,300.09645,-42141.59375,,,,,,,,,,,,,0,,,,0,,,,,,300.010437,,,,
,27924545.655,300.0079956,-47024.322265625,-0.00304404142448864,5.85739331568829E-5,1,0.999253354069792,40.0298881530762,2.00528974924558,19.1500000655651,-0.0314125555533718,-0.0241420240237771,0.25,-0.00159916139074232,-0.00304289950864352,-0.00160111608861111,300.0079956,300.0079956,-47031.8984375,-47016.74609375,56.6610329875637,20.350224232425,27.844467,0,0,0,40,4449,300.0951,-47024.322265625,,,,,,,,,,,,,0,,,,0,,,,,,300.0079956,,,,
,27924644.71,300.0178528,-51974.111328125,-0.00291329966096641,4.53380563396899E-5,1,0.999253354069792,40.0298881530762,2.00496339079574,19.1500000655651,-0.0299076677946645,-0.023973396636309,0.25,-0.00160728980362377,-0.00291215661881984,-0.00160915565730632,300.0178528,300.0178528,-51984.17578125,-51964.046875,56.7720242372945,20.3527042582988,27.844467,0,0,0,40,4449,300.083,-51974.111328125,,,,,,,,,,,,,0,,,,0,,,,,,300.0178528,,,,
,27924743.57,300.0118408,-56913.740234375,-0.00276618961912704,5.7477629895843E-5,1,0.999253354069792,40.0298881530762,2.00505276010201,19.1500000655651,-0.0283263537464303,-0.023181261977107,0.25,-0.00156290542830577,-0.00276508209301578,-0.00156467432643903,300.0118408,300.0118408,-56921.31640625,-56906.1640625,56.8322096332752,20.3522819262711,27.844467,0,0,0,40,4449,300.07175,-56913.740234375,,,,,,,,,,,,,0,,,,-0.0049,,,,,,300.0118408,,,,
,27924841.925,300.0125732,-61830.630859375,-0.00269391784573058,4.92395393540424E-5,1,0.999253354069792,40.0298881530762,2.00493602417271,19.1500000655651,-0.0276623383142196,-0.0221265700024752,0.25,-0.00148262357648551,-0.0026928663878503,-0.00148434543007238,300.0125732,300.0125732,-61838.14453125,-61823.1171875,56.6625962446021,20.3536520432437,27.464817,0,0,0,40,4449,300.0621,-61830.630859375,,,,,,,,,,,,,0,,,,-0.00245,,,,,,300.0125732,,,,
,27924941.825,300.0101318,-66823.05078125,-0.00261992659747167,4.89789039680213E-5,1,0.999253354069792,40.0298881530762,2.00484855689775,19.1500000655651,-0.0268857748761982,-0.0216084913315037,0.25,-0.00144988078204294,-0.00261890034557882,-0.00145155327094408,300.0101318,300.0101318,-66830.3046875,-66815.796875,56.7610814380252,20.3550045197862,27.464817,0,0,0,40,4449,300.0527,-66823.05078125,,,,,,,,,,,,,0,,,,0,,,,,,300.0101318,,,,
,27925038.76,300.0085449,-71667.8515625,-0.00250086786888615,4.68431821190762E-5,1,0.999253354069792,40.0298881530762,2.00490214271422,19.1500000655651,-0.02565533562995,-0.0206808764978991,0.25,-0.00138873671804537,-0.00249988655488651,-0.00139033127707911,300.0085449,300.0085449,-71677.7890625,-71657.9140625,56.5461335952368,20.3538041283112,27.464817,0,0,0,40,4449,300.0475,-71667.8515625,,,,,,,,,,,,,0,,,,-0.0049,,,,,,300.0085449,,,,
,27925137.21,300.0126343,-76587.4140625,-0.00230340210268535,5.66192535531794E-5,1,0.999253354069792,40.0298881530762,2.00498304461358,19.1500000655651,-0.0234850522095413,-0.0198884181439017,0.25,-0.00135306540374779,-0.0023024507936043,-0.00135452996202184,300.0126343,300.0126343,-76589.90625,-76584.921875,56.577398736006,20.3538166747296,27.085165,0,0,0,40,4449,300.0368,-76587.4140625,,,,,,,,,,,,,0,,,,0,,,,,,300.0126343,,,,
,27925234.375,300.0151367,-81442.34375,-0.00224720279519016,4.44371237678162E-5,1,0.999253354069792,40.0298881530762,2.00487371734886,19.1500000655651,-0.0229705118193246,-0.0190579354773877,0.25,-0.00128972708640969,-0.00224629549256457,-0.00129115497766241,300.0151367,300.0151367,-81447.328125,-81437.359375,56.6368025034675,20.3568543929718,27.464817,0,0,0,40,4449,300.0305,-81442.34375,,,,,,,,,,,,,0,,,,-0.00245,,,,,,300.0151367,,,,
,27925331.34,300.013031,-86289.2109375,-0.00206948293339717,4.12317809654957E-5,1,0.999253354069792,40.0298881530762,2.00486384082499,19.1500000655651,-0.0210338341175431,-0.0182431425185945,0.25,-0.00124874026683032,-0.00206860886236051,-0.00125005200656592,300.013031,300.013031,-86294.046875,-86284.375,56.6751023009098,20.3561524279911,27.464817,0,0,0,40,4449,300.0133,-86289.2109375,,,,,,,,,,,,,0,,,,0.0049,,,,,,300.013031,,,,
,27925443.275,300.0139771,-89119.55859375,-0.00192826488647374,4.49667075782457E-5,1,0.999253354069792,40.0298881530762,2.00493037814187,19.1500000655651,-0.0194834039687627,-0.0176668831990905,0.25,-0.00122238740263498,-0.00192741271714595,-0.00122360699504773,300.0139771,300.0139771,-89127.046875,-89112.0703125,56.6594697305252,20.3566841840753,27.464817,0,0,0,40,4449,300.01155,-89119.55859375,,,,,,,,,,,,,0,,,,-0.0049,,,,,,300.0139771,,,,
,27925536.46,300.00616455,-84462.95703125,-0.00217363238265454,3.51159201951122E-5,1,0.999253354069792,40.0298881530762,2.00501386679986,19.1500000655651,-0.0221704424576307,-0.018721198877738,0.25,-0.00127269603796851,-0.002172739721323,-0.0012740759100649,300.0051575,300.0071716,-84475.4609375,-84450.453125,56.5852150211983,20.3556227479493,27.464817,0,0,0,40,4449,300.0086,-84462.95703125,,,,,,,,,,,,,0,,,,0.00245,,,,,,300.00616455,,,,
,27925634.64,299.9940491,-79558.15625,-0.00236900872620726,3.76640014499836E-5,1,0.999253354069792,40.0298881530762,2.00449237870848,19.1500000655651,-0.024313834685035,-0.0194949456178204,0.25,-0.00130743569485882,-0.00236808750536562,-0.00130894437151838,299.9940491,299.9940491,-79567.984375,-79548.328125,56.4898563418521,20.3712866312931,27.464817,0,0,0,40,4449,300.00475,-79558.15625,,,,,,,,,,,,,0,,,,0,,,,,,299.9940491,,,,
,27925734.88,299.9885864,-74546.05859375,-0.00236488763203166,4.11329660811718E-5,1,0.999253354069792,40.0298881530762,2.0043008904532,19.1500000655651,-0.0241246309473214,-0.0202943947536472,0.25,-0.00137875691351432,-0.00236391916429192,-0.00138026293443001,299.9885864,299.9885864,-74555.609375,-74536.5078125,56.6922981283329,20.3667452114785,27.464817,0,0,0,40,4449,300.0183,-74546.05859375,,,,,,,,,,,,,0,,,,0,,,,,,299.9885864,,,,
,27925833.115,299.9928131,-69639.28515625,-0.00251342747402546,4.44217117312072E-5,1,0.999253354069792,40.0298881530762,2.00448735888006,19.1500000655651,-0.0257449108224801,-0.0209779755218575,0.25,-0.00141309852859727,-0.00251243064618199,-0.0014147023143326,299.9919128,299.9937134,-69644.4609375,-69634.109375,56.7845302936022,20.3616771449183,27.464817,0,0,0,40,4449,300.0264,-69639.28515625,,,,,,,,,,,,,0,,,,-0.0049,,,,,,299.9928131,,,,
,27925928.04,299.98703,-64894.298828125,-0.00264378518144827,5.74766536673602E-5,1,0.999253354069792,40.0298881530762,2.00487348880376,19.1500000655651,-0.0271658582251999,-0.0216040583215799,0.25,-0.00144533176281069,-0.00264276281482303,-0.00144702207962874,299.98703,299.98703,-64906.77734375,-64881.8203125,56.8173586914099,20.3600781616883,27.464817,0,0,0,40,4449,300.03995,-64894.298828125,,,,,,,,,,,,,0,,,,0,,,,,,299.98703,,,,
,27926021.235,299.9863586,-60236.568359375,-0.00283175361384944,4.10729572013334E-5,1,0.999253354069792,40.0298881530762,2.00456205064045,19.1500000655651,-0.0291838120445968,-0.0226123410486477,0.25,-0.00150189162925552,-0.00283068760059675,-0.00150370546437349,299.9863586,299.9863586,-60239.1484375,-60233.98828125,56.6368025034675,20.3617007380408,27.085165,0,0,0,40,4449,300.0478,-60236.568359375,,,,,,,,,,,,,0,,,,0,,,,,,299.9863586,,,,
,27926115.24,299.98849485,-55536.83984375,-0.00290407311918046,4.52763216806814E-5,1,0.999253354069792,40.0298881530762,2.00429455828052,19.1500000655651,-0.0299183903013534,-0.0232267796431177,0.25,-0.00154376263505742,-0.00290297603388119,-0.00154562459967857,299.9883728,299.9886169,-55541.86328125,-55531.81640625,56.7407590965252,20.3644460273338,27.464817,0,0,0,40,4449,300.05515,-55536.83984375,,,,,,,,,,,,,0,,,,-0.00245,,,,,,299.98849485,,,,
,27926208.165,299.9879303,-50894.576171875,-0.00303741249675179,4.56954796262573E-5,1,0.999253354069792,40.0298881530762,2.00444619436573,19.1500000655651,-0.0313562817526868,-0.0239373728915228,0.25,-0.00158312939570422,-0.00303628446558873,-0.00158507985882551,299.987915,299.9879456,-50904.62109375,-50884.53125,56.7774956369291,20.3624827624265,27.085165,0,0,0,40,4449,300.0619,-50894.576171875,,,,,,,,,,,,,0,,,,0,,,,,,299.9879303,,,,
,27926301.155,299.9838562,-46247.4453125,-0.0031086976592273,4.27666330346686E-5,1,0.999253354069792,40.0298881530762,2.0045824619004,19.1500000655651,-0.0320989298312395,-0.0244737667879017,0.25,-0.00161790429724304,-0.00310754388332805,-0.00161990285808907,299.9838562,299.9838562,-46252.4375,-46242.453125,56.6829185861022,20.3602467157464,27.464817,0,0,0,40,4449,300.0774,-46247.4453125,,,,,,,,,,,,,0,,,,0,,,,,,299.9838562,,,,
,27926394.155,299.9913635,-41597.283203125,-0.00315707415730884,6.22700290330736E-5,1,0.999253354069792,40.0298881530762,2.0044821062039,19.1500000655651,-0.0324907437139322,-0.0254659183770554,0.25,-0.00169705194313702,-0.0031558646840082,-0.00169908169946136,299.9913635,299.9913635,-41599.57421875,-41594.9921875,56.6969878994483,20.3620854210767,27.464817,0,0,0,40,4449,300.0802,-41597.283203125,,,,,,,,,,,,,0,,,,0,,,,,,299.9913635,,,,
,27926486.955,299.9789734,-36959.466796875,-0.00330118772871589,4.08357330555066E-5,1,0.999253354069792,40.0298881530762,2.00452202907873,19.1500000655651,-0.0340553806724961,-0.0261621924365636,0.25,-0.00173339192705518,-0.00329995032587634,-0.0017355182804199,299.9789734,299.9789734,-36966.91796875,-36952.015625,56.5648926796983,20.3594703171885,27.085165,0,0,0,40,4449,300.10505,-36959.466796875,,,,,,,,,,,,,0,,,,0,,,,,,299.9789734,,,,
,27926578.37,299.983551,-32392.5234375,-0.00335316153395381,5.03576370545807E-5,1,0.999253354069792,40.0298881530762,2.00458938839463,19.1500000655651,-0.034559313051674,-0.0267672645658878,0.25,-0.00177762742046529,-0.00335189157402188,-0.00177978855332676,299.983551,299.983551,-32395.0390625,-32390.0078125,56.5305010248521,20.3607801808196,27.464817,0,0,0,40,4449,300.1104,-32392.5234375,,,,,,,,,,,,,0,,,,-0.00245,,,,,,299.983551,,,,
,27926672.235,299.9836121,-27700.46875,-0.00357183940151262,5.01840159009018E-5,1,0.999253354069792,40.0298881530762,2.00459006295563,19.1500000655651,-0.0370228385926897,-0.0273024010131085,0.25,-0.00178689069814338,-0.00357055567869703,-0.00178919798336802,299.9836121,299.9836121,-27702.84375,-27698.09375,56.6625962446021,20.3591085034002,27.464817,0,0,0,40,4449,300.1262,-27700.46875,,,,,,,,,,,,,0,,,,0.0049,,,,,,299.9836121,,,,
,27926765.03,299.98797605,-23065.4580078125,-0.00363998623423695,3.98225681459675E-5,1,0.999253354069792,40.0298881530762,2.00450530084101,19.1500000655651,-0.0377699386711684,-0.027578099458596,0.25,-0.00179947324955214,-0.00363869031608785,-0.00180182708698519,299.9872131,299.988739,-23100.41015625,-23030.505859375,56.6797920720252,20.3605127627145,27.464817,0,0,0,40,4449,300.12895,-23065.4580078125,,,,,,,,,,,,,0,,,,0,,,,,,299.98797605,,,,
,27926859.79,299.9880676,-18328.236328125,-0.00376666397864863,4.51186019100107E-5,1,0.999253354069792,40.0298881530762,2.00448289887187,19.1500000655651,-0.0391926261609142,-0.0279103900271351,0.25,-0.00180683030481999,-0.00376535810110526,-0.00180926999317786,299.9880676,299.9880676,-18338.1953125,-18318.27734375,56.6500901882945,20.3619897821885,27.464817,0,0,0,40,4449,300.1216,-18328.236328125,,,,,,,,,,,,,0,,,,0,,,,,,299.9880676,,,,
,27926952.595,299.9833069,-13688.1879882812,-0.00377603182666008,6.35169931921739E-5,1,0.999253354069792,40.0298881530762,2.00503465636905,19.1500000655651,-0.0392214651960033,-0.0284427954274289,0.25,-0.00185146210942039,-0.00377469554765354,-0.00185390904750265,299.9833069,299.9833069,-13695.701171875,-13680.6748046875,56.516431711506,20.3556766577718,27.844467,0,0,0,40,4449,300.12865,-13688.1879882812,,,,,,,,,,,,,0,,,,-0.00245,,,,,,299.9833069,,,,
,27927047.71,299.9898376,-8932.31103515625,-0.00375863947687567,6.61914816152993E-5,1,0.999253354069792,40.0298881530762,2.00431722114606,19.1500000655651,-0.0389935224134507,-0.0284980182737853,0.25,-0.00186019657485871,-0.0037572959277598,-0.00186263311635137,299.9898376,299.9898376,-8942.287109375,-8922.3349609375,56.4812584281406,20.3634004203837,27.844467,0,0,0,40,4449,300.14905,-8932.31103515625,,,,,,,,,,,,,0,,,,0,,,,,,299.9898376,,,,
,27927139,299.9883118,-4371.74072265625,-0.00370059087935564,5.8263289447496E-5,1,0.999253354069792,40.0298881530762,2.00439630123807,19.1500000655651,-0.0384093164372065,-0.0279632849974322,0.25,-0.00182303595565348,-0.00369927298405711,-0.00182543667046173,299.9883118,299.9883118,-4374.3701171875,-4369.111328125,56.6266413327175,20.3591393198064,27.464817,0,0,0,40,4449,300.1757,-4371.74072265625,,,,,,,,,,,,,0,,,,0.00245,,,,,,299.9883118,,,,
,27927228.03,299.9862061,80.1911964416504,0.000490040209042366,1.73043774112111E-5,1,0.999253354069792,40.0298881530762,2.00452295055797,19.1500000655651,0.00510610509620952,0.00359031748878626,0.25,0.000231464894052416,0.000489872231997206,0.000231783267816256,299.9862061,299.9862061,75.4839706420898,84.8984222412109,56.5273745107752,20.3582484627139,27.464817,0,0,0,40,4449,300.1832,80.1911964416504,,,,,,,,,,,,,0,,,,-0.0049,,,,,,299.9862061,,,,
,27927314.04,299.9990387,4373.97485351562,0.00371590450184916,5.49621698832231E-5,1,0.999253354069792,40.0298881530762,2.00488529731921,19.1500000655651,0.0385710508483215,0.0281211386965655,0.25,0.00183371766371469,0.00371457768155762,0.00183612744601865,299.9986267,299.9994507,4339.15283203125,4408.796875,56.5758354789675,20.3556015217487,27.464817,0,0,0,40,4449,300.18285,4373.97485351562,,,,,,,,,,,,,0,,,,-0.00245,,,,,,299.9990387,,,,
,27927405.475,299.9929504,8945.513671875,0.00389714239775024,4.0842374328656E-5,1,0.999253354069792,40.0298881530762,2.00442738589087,19.1500000655651,0.0405886786894048,0.0286483981406603,0.25,0.00184932022903454,0.0038958017402354,0.00185184835710308,299.9929504,299.9929504,8938.0029296875,8953.0244140625,56.7188734979868,20.3583407330147,27.085165,0,0,0,40,4449,300.1821,8945.513671875,,,,,,,,,,,,,0,,,,0.0049,,,,,,299.9929504,,,,
,27927498.415,300.0001831,13590.8647460938,0.00376479482978914,6.55813382747891E-5,1,0.999253354069792,40.0298881530762,2.00461448795886,19.1500000655651,0.0390721109716565,0.0284955937226499,0.25,0.00185856407263169,0.00376345210399139,0.00186100188768822,300.0001831,300.0001831,13585.7431640625,13595.986328125,56.5797436215637,20.3538887622006,27.464817,0,0,0,40,4449,300.17,13590.8647460938,,,,,,,,,,,,,0,,,,0,,,,,,300.0001831,,,,
,27927592.64,300.0037231,18300.880859375,0.00370387258843294,5.022492103352E-5,1,0.999253354069792,40.0298881530762,2.00490903890324,19.1500000655651,0.038399833498731,0.0283004788012058,0.25,0.00185157984373717,0.00370253712585167,0.00185397518699736,300.0037231,300.0037231,18293.314453125,18308.447265625,56.4546830584867,20.3486440557326,27.844467,0,0,0,40,4449,300.17085,18300.880859375,,,,,,,,,,,,,0,,,,0,,,,,,300.0037231,,,,
,27927683.85,300.0021973,22861.06640625,0.00357798475186006,6.03831467244997E-5,1,0.999253354069792,40.0298881530762,2.00493229219074,19.1500000655651,0.0370710068658234,0.0274780789171566,0.25,0.00180091139578943,0.00357668800328417,0.00180322306039737,300.0021973,300.0021973,22856.02734375,22866.10546875,56.4742237714675,20.3481923123947,27.464817,0,0,0,40,4449,300.1644,22861.06640625,,,,,,,,,,,,,0,,,,-0.0049,,,,,,300.0021973,,,,
,27927778.345,300.0031738,27581.7177734375,0.00357625975110102,5.23701536404978E-5,1,0.999253354069792,40.0298881530762,2.0051163845336,19.1500000655651,0.0371923150096615,0.0266827320826107,0.25,0.00173093622900069,0.00357501050368708,0.00173324657150857,300.0031738,300.0031738,27579,27584.435546875,56.7235632691022,20.3466337821095,27.464817,0,0,0,40,4449,300.1626,27581.7177734375,,,,,,,,,,,,,0,,,,-0.0049,,,,,,300.0031738,,,,
,27927872.18,300.0065613,32271.900390625,0.00346897265701844,4.5852653271252E-5,1,0.999253354069792,40.0298881530762,2.00492127878079,19.1500000655651,0.0359967065886713,0.0263214425658525,0.25,0.0017179150491906,0.00346773611204749,0.0017201525272799,300.0065613,300.0065613,32266.947265625,32276.853515625,56.5133051974291,20.3494989987027,27.085165,0,0,0,40,4449,300.1611,32271.900390625,,,,,,,,,,,,,0,,,,0,,,,,,300.0065613,,,,
,27927966.7,300.0115662,36996.73828125,0.00328224429905222,5.26424721968802E-5,1,0.999253354069792,40.0298881530762,2.00480161104911,19.1500000655651,0.0338773040182625,0.0259411692376746,0.25,0.00171689697248374,0.00328101473468523,0.00171900889032663,300.0115662,300.0115662,36989.05859375,37004.41796875,56.3210245816983,20.3494774984968,27.085165,0,0,0,40,4449,300.15355,36996.73828125,,,,,,,,,,,,,0,,,,0,,,,,,300.0115662,,,,
,27928059.805,300.0062561,41651.978515625,0.00320787541090342,5.66138547383423E-5,1,0.999253354069792,40.0298881530762,2.00474057889866,19.1500000655651,0.0331212648901632,0.0252805697181746,0.25,0.00167164528902467,0.00320667979607311,0.00167370784499032,300.0062561,300.0062561,41642.0234375,41661.93359375,56.7431039820829,20.3512309551735,27.844467,0,0,0,40,4449,300.14045,41651.978515625,,,,,,,,,,,,,0,,,,0,,,,,,300.0062561,,,,
,27928153.985,300.0141907,46357.44921875,0.00318526840413888,4.98772886168077E-5,1,0.999253354069792,40.0298881530762,2.00467141518877,19.1500000655651,0.0329780670169505,0.0245746356750865,0.25,0.00161343732010422,0.00318411224099669,0.00161548406724886,300.0141907,300.0141907,46355.18359375,46359.71484375,56.5766171074867,20.3512410362329,27.085165,0,0,0,40,4449,300.1418,46357.44921875,,,,,,,,,,,,,0,,,,0,,,,,,300.0141907,,,,
,27928246.875,300.0162048,51000.193359375,0.00302353698819652,4.22912313032023E-5,1,0.999253354069792,40.0298881530762,2.00471409565136,19.1500000655651,0.0312554649415033,0.0236089692299837,0.25,0.00155633160871784,0.00302242418598988,0.00155827168927307,300.0162048,300.0162048,50992.8125,51007.57421875,56.4570279440444,20.3496311786451,27.464817,0,0,0,40,4449,300.11685,51000.193359375,,,,,,,,,,,,,0,,,,-0.00245,,,,,,300.0162048,,,,
,27928342.285,300.0137329,55770.296875,0.00295027616219909,3.25523589998312E-5,1,0.999253354069792,40.0298881530762,2.00463910804829,19.1500000655651,0.0304854669536838,0.0231030705109983,0.25,0.00152452426301051,0.00294918805661803,0.00152641516978493,300.0137329,300.0137329,55765.30078125,55775.29296875,56.8376810329099,20.3502407751743,27.085165,0,0,0,40,4449,300.1183,55770.296875,,,,,,,,,,,,,0,,,,0,,,,,,300.0137329,,,,
,27928434.39,300.0162659,60370.734375,0.00272176326343586,4.99045046961093E-5,1,0.999253354069792,40.0298881530762,2.00462240488789,19.1500000655651,0.0279077706165457,0.0225615784939402,0.25,0.00151642013799816,0.00272068824506557,0.00151815937138877,300.0162659,300.0162659,60368.08203125,60373.38671875,56.6110087623329,20.3518732913803,27.464817,0,0,0,40,4449,300.1044,60370.734375,,,,,,,,,,,,,0,,,,-0.0049,,,,,,300.0162659,,,,
,27928529.99,300.0098267,65151.1953125,0.0026762402489243,3.42819034115544E-5,1,0.999253354069792,40.0298881530762,2.00451910528609,19.1500000655651,0.0275411681724399,0.021597292966774,0.25,0.0014394356558433,0.00267521890254067,0.00144114579703885,300.0098267,300.0098267,65146.26171875,65156.12890625,56.4984542555637,20.3521726434823,27.844467,0,0,0,40,4449,300.0886,65151.1953125,,,,,,,,,,,,,0,,,,-0.0049,,,,,,300.0098267,,,,
,27928622.265,300.0122986,69763.984375,0.00256037726516219,4.15003871139131E-5,1,0.999253354069792,40.0298881530762,2.00476504749553,19.1500000655651,0.0262575608397648,0.0212093251957912,0.25,0.00142510539259369,0.00255936971151836,0.00142673815138981,300.0122986,300.0122986,69759.0546875,69768.9140625,56.3819916061983,20.3507062954631,27.464817,0,0,0,40,4449,300.08305,69763.984375,,,,,,,,,,,,,0,,,,0,,,,,,300.0122986,,,,
,27928717.32,300.0106506,74517.20703125,0.00240935443269947,4.456468279201E-5,1,0.999253354069792,40.0298881530762,2.00469639949826,19.1500000655651,0.0246582206770105,0.0202448483678404,0.25,0.00136635264164241,0.00240839112420739,0.00136788665461736,300.0106506,300.0106506,74512.09375,74522.3203125,56.5047072837175,20.3522843855223,27.464817,0,0,0,40,4449,300.07805,74517.20703125,,,,,,,,,,,,,0,,,,-0.0049,,,,,,300.0106506,,,,
,27928815.015,300.0123901,79397.59375,0.00231362728665577,3.8104948982386E-5,1,0.999253354069792,40.0298881530762,2.00466326550116,19.1500000655651,0.0236803052585485,0.0194277600922117,0.25,0.0013109723510489,0.00231270401267878,0.00131244363913974,300.0123901,300.0123901,79395.15625,79400.03125,56.5015807696406,20.3518670847274,27.085165,0,0,0,40,4449,300.0654,79397.59375,,,,,,,,,,,,,0,,,,0.0049,,,,,,300.0123901,,,,
,27928912.285,300.0108032,84258.63671875,0.00220174590986203,4.22231026488007E-5,1,0.999253354069792,40.0298881530762,2.00476663008414,19.1500000655651,0.0225427428124484,0.0184520416939061,0.25,0.00124430526678837,0.0022008707062889,0.00124570388428191,300.0108032,300.0108032,84253.5859375,84263.6875,56.3530713509867,20.3502698166832,27.085165,0,0,0,40,4449,300.0596,84258.63671875,,,,,,,,,,,,,0,,,,-0.00245,,,,,,300.0108032,,,,
,27929006.265,300.0092163,88956.8984375,0.00198251363616197,5.02621625282092E-5,1,0.999253354069792,40.0298881530762,2.00465260727489,19.1500000655651,0.0201098352559847,0.0176943310094336,0.25,0.00121561300796917,0.00198166473214751,0.00121686818556015,300.0089722,300.0094604,88947.0703125,88966.7265625,56.3483815798714,20.3503502308374,27.085165,0,0,0,40,4449,300.0519,88956.8984375,,,,,,,,,,,,,0,,,,0,,,,,,300.0092163,,,,
,27929117.55,300.0034485,86431.54296875,0.0021307986594722,3.63586210464751E-5,1,0.999253354069792,40.0298881530762,2.00456410443829,19.1500000655651,0.0217518473346531,0.0182159523215235,0.25,0.00123595047081303,0.00212993201510094,0.00123730273869093,300.0034485,300.0034485,86424.265625,86438.8203125,56.3155531820637,20.3515937771009,27.464817,0,0,0,40,4449,300.04665,86431.54296875,,,,,,,,,,,,,0,,,,0.00245,,,,,,300.0034485,,,,
,27929216.355,300.0041199,81492.87109375,0.00222364486132765,3.62654197404658E-5,1,0.999253354069792,40.0298881530762,2.00436559717805,19.1500000655651,0.0226968648834339,0.0190114964088608,0.25,0.00129012149913103,0.00222273891694475,0.00129153446198484,300.0041199,300.0041199,81484.9765625,81500.765625,56.4030955762175,20.3536586564647,27.464817,0,0,0,40,4449,300.0387,81492.87109375,,,,,,,,,,,,,0,,,,-0.00245,,,,,,300.0041199,,,,
,27929315.245,299.9963684,76548.8984375,0.00234039231475004,4.58669646011884E-5,1,0.999253354069792,40.0298881530762,2.00453442743998,19.1500000655651,0.0238891982471939,0.0200183403217122,0.25,0.00135847826523016,0.00233943779539002,0.00135996755400915,299.9963684,299.9963684,76541.234375,76556.5625,56.3851181202752,20.354577799048,27.464817,0,0,0,40,4449,300.0505,76548.8984375,,,,,,,,,,,,,0,,,,0.0049,,,,,,299.9963684,,,,
,27929416.39,299.9909363,71493.19140625,0.00248944129189465,4.93002453859692E-5,1,0.999253354069792,40.0298881530762,2.0044912832765,19.1500000655651,0.0255108561845209,0.0207109900886369,0.25,0.00139372501658923,0.00248845861662378,0.0013953128529305,299.9909363,299.9909363,71483.078125,71503.3046875,56.4023139476983,20.353810532516,27.085165,0,0,0,40,4449,300.05685,71493.19140625,,,,,,,,,,,,,0,,,,0.00245,,,,,,299.9909363,,,,
,27929514.975,299.99269105,66562.6171875,0.00258177658239543,3.25456539854568E-5,1,0.999253354069792,40.0298881530762,2.00462026815893,19.1500000655651,0.0264399428564471,0.021588645340945,0.25,0.00145494720441085,0.00258074972797666,0.00145659551831949,299.9926453,299.9927368,66555.0234375,66570.2109375,56.4906379703714,20.3534622433452,27.085165,0,0,0,40,4449,300.0636,66562.6171875,,,,,,,,,,,,,0,,,,0.00245,,,,,,299.99269105,,,,
,27929614.07,299.99201965,61612.01171875,0.00279976785088846,3.93031708007857E-5,1,0.999253354069792,40.0298881530762,2.00483628414272,19.1500000655651,0.0288563428610854,0.0223690303001373,0.25,0.0014857377144675,0.00279871331370375,0.00148752991234218,299.9919739,299.9920654,61606.8671875,61617.15625,56.4710972573906,20.3532069435509,27.844467,0,0,0,40,4449,300.0819,61612.01171875,,,,,,,,,,,,,0,,,,-0.0049,,,,,,299.99201965,,,,
,27929713.275,299.9878845,56653.978515625,0.00291990250457248,5.26104302367595E-5,1,0.999253354069792,40.0298881530762,2.00476468805016,19.1500000655651,0.030120644541269,0.0231713701345965,0.25,0.00153568087810157,0.00291881079586783,0.00153755278309682,299.9878845,299.9878845,56649.01171875,56658.9453125,56.5750538504483,20.3521872501482,27.464817,0,0,0,40,4449,300.08655,56653.978515625,,,,,,,,,,,,,0,,,,0,,,,,,299.9878845,,,,
,27929809.33,299.987793,51853.89453125,0.00302980452013357,4.67676073249853E-5,1,0.999253354069792,40.0298881530762,2.00478126107732,19.1500000655651,0.0312939256017451,0.023816630767593,0.25,0.00157347366178743,0.00302868351461973,0.00157541871311353,299.987793,299.987793,51851.19140625,51856.59765625,56.6164801619675,20.3512012171521,27.464817,0,0,0,40,4449,300.0976,51853.89453125,,,,,,,,,,,,,0,,,,-0.00245,,,,,,299.987793,,,,
,27929907.11,299.992218,46966.388671875,0.0030969452009422,5.7875219356357E-5,1,0.999253354069792,40.0298881530762,2.00470510351229,19.1500000655651,0.031962667629613,0.0244794667482088,0.25,0.00162031793225309,0.00309578957018607,0.00162230769930827,299.992218,299.992218,46964.296875,46968.48046875,56.5562947659868,20.3530333645661,27.085165,0,0,0,40,4449,300.101,46966.388671875,,,,,,,,,,,,,0,,,,-0.0049,,,,,,299.992218,,,,
,27930002.12,299.9881592,42218.41015625,0.00318128760198583,4.35582123075359E-5,1,0.999253354069792,40.0298881530762,2.00459066087327,19.1500000655651,0.0328168253778806,0.0252285584057728,0.25,0.00167182619206713,0.00318009466904929,0.00167387240883742,299.9881592,299.9881592,42215.83203125,42220.98828125,56.607882248256,20.3536889564175,27.464817,0,0,0,40,4449,300.0966,42218.41015625,,,,,,,,,,,,,0,,,,0.0049,,,,,,299.9881592,,,,
,27930099.39,299.9912109,37356.0703125,0.00334139692156261,4.07223521924835E-5,1,0.999253354069792,40.0298881530762,2.0047514805295,19.1500000655651,0.0346737242861139,0.0253305751814852,0.25,0.00165290309854633,0.00334021009809102,0.00165505730401323,299.9912109,299.9912109,37348.35546875,37363.78515625,56.5781803645252,20.3524235691135,27.844467,0,0,0,40,4449,300.11105,37356.0703125,,,,,,,,,,,,,0,,,,-0.00245,,,,,,299.9912109,,,,
,27930196.46,299.9909973,32503.6396484375,0.00337492811988546,6.85317975733075E-5,1,0.999253354069792,40.0298881530762,2.00479731775807,19.1500000655651,0.034894027692494,0.0263264191982154,0.25,0.00173478259989121,0.00337368498976359,0.0017369587261386,299.9909973,299.9909973,32491.103515625,32516.17578125,56.5797436215637,20.3519485252584,27.085165,0,0,0,40,4449,300.1215,32503.6396484375,,,,,,,,,,,,,0,,,,0,,,,,,299.9909973,,,,
,27930291.79,299.9902649,27738.9736328125,0.00354293891441524,4.82007412485201E-5,1,0.999253354069792,40.0298881530762,2.00485887378944,19.1500000655651,0.0367115326634348,0.0271798134965266,0.25,0.00178079051260411,0.00354165926566164,0.00178307837404036,299.9902649,299.9902649,27729.078125,27748.869140625,56.7618630665445,20.3513522949826,27.464817,0,0,0,40,4449,300.134,27738.9736328125,,,,,,,,,,,,,0,,,,0,,,,,,299.9902649,,,,
,27930388.335,299.9897461,22913.76953125,0.00368695189785013,6.20640466264932E-5,1,0.999253354069792,40.0298881530762,2.00482923969771,19.1500000655651,0.0382905518519693,0.0277801846389855,0.25,0.00180876630628646,0.00368564823906376,0.00181115079158377,299.9897461,299.9897461,22906.53125,22921.0078125,56.5891231637945,20.3505091108168,27.085165,0,0,0,40,4449,300.1384,22913.76953125,,,,,,,,,,,,,0,,,,0,,,,,,299.9897461,,,,
,27930484.955,299.9908447,18086.2626953125,0.00370490181269323,5.21251642487066E-5,1,0.999253354069792,40.0298881530762,2.00480540529528,19.1500000655651,0.0384688149844723,0.0279595615149708,0.25,0.00182148630902081,0.00370358772902517,0.00182388442627782,299.9908447,299.9908447,18083.8046875,18088.720703125,56.5156500829868,20.3522679506842,27.844467,0,0,0,40,4449,300.1433,18086.2626953125,,,,,,,,,,,,,0,,,,0.0049,,,,,,299.9908447,,,,
,27930579.315,299.9900818,13368.59375,0.00380336131596672,4.89336948343139E-5,1,0.999253354069792,40.0298881530762,2.00471077749098,19.1500000655651,0.039509927685907,0.0285825414569468,0.25,0.00185942683467009,0.00380201810123168,0.00186189108705512,299.9900818,299.9900818,13360.92578125,13376.26171875,56.5695824508137,20.3529023451102,27.464817,0,0,0,40,4449,300.1542,13368.59375,,,,,,,,,,,,,0,,,,0,,,,,,299.9900818,,,,
,27930675.055,299.9929199,8585.6533203125,0.00388767098101141,5.70654962594624E-5,1,0.999253354069792,40.0298881530762,2.00476886184402,19.1500000655651,0.0405068182166396,0.0285245057895059,0.25,0.00183963489542588,0.00388633679178659,0.00184215743284332,299.9929199,299.9929199,8578.1796875,8593.126953125,56.6047557341791,20.3531259528362,27.464817,0,0,0,40,4449,300.15655,8585.6533203125,,,,,,,,,,,,,0,,,,-0.0049,,,,,,299.9929199,,,,
,27930771.07,299.9915161,3785.45910644531,0.00377432344086214,5.46188822138115E-5,1,0.999253354069792,40.0298881530762,2.00498260573423,19.1500000655651,0.0393111518484866,0.0278033379292668,0.25,0.00179548268398703,0.00377302105329132,0.00179793318042917,299.9915161,299.9915161,3780.37963867188,3790.53857421875,56.6321127323521,20.3524605981196,27.085165,0,0,0,40,4449,300.1679,3785.45910644531,,,,,,,,,,,,,0,,,,0,,,,,,299.9915161,,,,
,27930848.11,299.9918213,-0.304475456476212,-8.29537471649531E-5,3.25825973206026E-6,1,0.999253354069792,40.0298881530762,2.0047754303063,19.1500000655651,-0.000856954618678254,-0.000651172500677808,0.25,-4.30001453257163E-5,-8.29227602120644E-5,-4.30539214745905E-5,299.9918213,299.9918213,-0.319699227809906,-0.289251685142517,56.6672860157175,20.3543372438213,27.464817,0,0,0,40,4417,300.1709,-0.304475456476212,,,,,,,,,,,,,0,,,,0.00245,,,,,,299.9918213,,,,