File: data/monolayers/magneticStructure/ML_Ac_CoFe_C/PPMS/data/DD205_4_FCC_100OE.DAT
[Header]
; VSM Data File (default extension .dat)
; Copyright (c) 2003-2013, Quantum Design, Inc. All rights reserved.
TITLE,
FILEOPENTIME,32294179.91,01/10/2019,2:38 am
BYAPP,VSM,2.0,2.0
INFO,PPMS VSM Option Release 1.4.10 Build 1,APPNAME
INFO,Quantum Design Linear Motor Servo Controller,MOTOR_MODULE_NAME
INFO,3101-100 M1,MOTOR_HW_VERSION
INFO,MMC1014,MOTOR_SERIAL_NUMBER
INFO,SRV No X-over 01.03.11,MOTOR_SOFTWARE_VERSION
INFO,Quantum Design VSM Detection Module,VSM_MODULE_NAME
INFO,3101-150 F0,VSM_HW_VERSION
INFO,VSM707,VSM_SERIAL_NUMBER
INFO,VSM No X-over 01.02.05 May 20 2008 13:51:47,VSM_SOFTWARE_VERSION
INFO,704,PREAMP_SERIAL_NUMBER
INFO,822,COIL_SERIAL_NUMBER
INFO,0,MOMENT_UNITS
INFO,DD205_4,SAMPLE_MATERIAL
INFO,Monolayer,SAMPLE_COMMENT
INFO,29.55,SAMPLE_MASS
INFO,,SAMPLE_VOLUME
INFO,,SAMPLE_MOLECULAR_WEIGHT
INFO,,SAMPLE_SIZE
INFO,,SAMPLE_SHAPE
DATATYPE,COMMENT,1
DATATYPE,TIME,2
STARTUPAXIS,X,2
STARTUPAXIS,Y1,5
[Data]
Comment,Time Stamp (sec),Temperature (K),Magnetic Field (Oe),Moment (emu),M. Std. Err. (emu),Transport Action,Averaging Time (sec),Frequency (Hz),Peak Amplitude (mm),Center Position (mm),Coil Signal' (mV),Coil Signal" (mV),Range (mV),M. Quad. Signal (emu),M. Raw' (emu),M. Raw" (emu),Min. Temperature (K),Max. Temperature (K),Min. Field (Oe),Max. Field (Oe),Mass (grams),Motor Lag (deg),Pressure (Torr),VSM Status (code),Motor Status (code),Measure Status (code),Measure Count,PPMS Status (code),System Temp. (K),System Field (Oe),Sample Position (deg),Bridge 1 Resistance (ohms),Bridge 1 Excitation (에),Bridge 2 Resistance (ohms),Bridge 2 Excitation (에),Bridge 3 Resistance (ohms),Bridge 3 Excitation (에),Bridge 4 Resistance (ohms),Bridge 4 Excitation (에),Signal 1 Vin (V),Signal 2 Vin (V),Digital Inputs (code),Drive 1 Iout (mA),Drive 1 Ipower (W),Drive 2 Iout (mA),Drive 2 Ipower (W),Pressure (),Map 20 (),Map 21 (),Map 22 (),Map 23 (),Map 24 (),Map 25 (),Map 26 (),Map 27 (),Map 28 (),Map 29 ()
,32294317.69,349.5692139,99.4112396240234,7.64444319550105E-6,4.69635206627032E-7,1,0.999253354069792,40.0298881530762,1.99515281367991,19.7599995881319,8.70669288882725E-5,1.00271242677277E-5,0.25,-4.34604204106718E-7,7.63124336619367E-6,-4.29579783770916E-7,349.5692139,349.5692139,99.4112396240234,99.4112396240234,57.0268351345637,20.5193315230604,26.705515,0,0,0,40,4369,350.3011,99.4112396240234,,,,,,,,,,,,,0,,,,0,,,,,,349.5692139,,,,
,32294467.645,346.9665222,99.4112396240234,7.73207127737059E-6,5.3334690201641E-7,1,0.999253354069792,40.0298881530762,1.99513132673246,19.7599995881319,8.72314610677905E-5,1.49959985985643E-5,0.25,-9.38418778114877E-9,7.7191571731294E-6,-4.99517301161546E-9,346.9665222,346.9665222,99.4112396240234,99.4112396240234,56.8181403199291,20.5193431481271,27.464817,0,0,0,40,4374,345.22345,99.4112396240234,,,,,,,,,,,,,0,,,,0,,,,,,346.9665222,,,,
,32294617.205,343.4473267,99.4112396240234,7.05933246811454E-6,4.60005553403315E-7,1,0.999253354069792,40.0298881530762,1.99525693044698,19.7599995881319,7.91381889787624E-5,1.66844484870646E-5,0.25,2.56488707931179E-7,7.04823303340835E-6,2.60130499299639E-7,343.4473267,343.4473267,99.4112396240234,99.4112396240234,56.8017261210252,20.5188430348842,27.085165,0,0,0,40,4374,341.40765,99.4112396240234,,,,,,,,,,,,,0,,,,-0.00245,,,,,,343.4473267,,,,
,32294763.725,339.94104005,99.4112396240234,7.64203346662584E-6,5.59240354590121E-7,1,0.999253354069792,40.0298881530762,1.99529381371046,19.7599995881319,8.57386403866107E-5,1.77386475780008E-5,0.25,2.48760724418483E-7,7.63094698612269E-6,2.52831357056826E-7,339.9113159,339.9707642,99.4112396240234,99.4112396240234,57.0205821064099,20.5158717049911,27.464817,0,0,0,40,4374,337.55755,99.4112396240234,,,,,,,,,,,,,0,,,,0,,,,,,339.94104005,,,,
,32294905.58,336.4802246,99.4112396240234,7.69503284406115E-6,4.5080169522096E-7,1,0.999253354069792,40.0298881530762,1.99584086711644,19.7299998253584,8.68136097712147E-5,1.52844421094942E-5,0.25,2.14998257404113E-8,7.68491601682308E-6,2.59824031204065E-8,336.4802246,336.4802246,99.4112396240234,99.4112396240234,56.8728543162753,20.5099823668344,26.705515,0,0,0,40,4374,333.9181,99.4112396240234,,,,,,,,,,,,,0,,,,0,,,,,,336.4802246,,,,
,32295049.85,332.9784546,99.4112396240234,7.80993509781162E-6,4.92727649680429E-7,1,0.999253354069792,40.0298881530762,1.99550556303528,19.7299998253584,8.75864839128738E-5,1.85143024650535E-5,0.25,2.87761406457888E-7,7.80045286476738E-6,2.92053067871899E-7,332.9784546,332.9784546,99.4112396240234,99.4112396240234,56.7610814380252,20.5152722532717,27.464817,0,0,0,40,4374,330.25685,99.4112396240234,,,,,,,,,,,,,0,,,,-0.00245,,,,,,332.9784546,,,,
,32295191.985,329.4518127,99.4112396240234,7.67174937896172E-6,4.79895892190281E-7,1,0.999253354069792,40.0298881530762,1.99539333626917,19.7299998253584,8.71135914417452E-5,1.2004610367916E-5,0.25,-2.65190255179792E-7,7.66370024747596E-6,-2.60296811628283E-7,329.4518127,329.4518127,99.4112396240234,99.4112396240234,56.8728543162753,20.5191424444651,27.085165,0,0,0,40,4374,326.64345,99.4112396240234,,,,,,,,,,,,,0,,,,-0.00245,,,,,,329.4518127,,,,
,32295332.89,325.9729919,99.4112396240234,8.64233565844224E-6,4.69326641201063E-7,1,0.999253354069792,40.0298881530762,1.99542790513659,19.7299998253584,9.84434642959956E-5,1.18208848265169E-5,0.25,-4.49778897022593E-7,8.63440973091602E-6,-4.44093741829221E-7,325.9729919,325.9729919,99.4112396240234,99.4112396240234,56.9439825115252,20.5181423287271,27.085165,0,0,0,40,4374,323.08185,99.4112396240234,,,,,,,,,,,,,0,,,,-0.0049,,,,,,325.9729919,,,,
,32295473.79,322.4909668,99.4112396240234,7.85099053637702E-6,4.12496062618246E-7,1,0.999253354069792,40.0298881530762,1.99554973144121,19.7299998253584,8.90844638139305E-5,1.28249722118411E-5,0.25,-2.24037253308997E-7,7.84463616526682E-6,-2.19013788587867E-7,322.4909668,322.4909668,99.4112396240234,99.4112396240234,56.9963516223137,20.5163271292435,26.705515,0,0,0,40,4374,319.5379,99.4112396240234,,,,,,,,,,,,,0,,,,0,,,,,,322.4909668,,,,
,32295615.245,318.9880371,99.4112396240234,8.12195026179655E-6,4.24405772571844E-7,1,0.999253354069792,40.0298881530762,1.99562278679898,19.7299998253584,9.26104020753594E-5,1.07480845159195E-5,0.25,-4.55127225660294E-7,8.11651705066087E-6,-4.49735945562335E-7,318.9880371,318.9880371,99.4112396240234,99.4112396240234,56.943200883006,20.5168833912476,26.705515,0,0,0,40,4374,315.9815,99.4112396240234,,,,,,,,,,,,,0,,,,0,,,,,,318.9880371,,,,
,32295758.765,315.4584656,99.4112396240234,8.80086125920817E-6,4.66467560327282E-7,1,0.999253354069792,40.0298881530762,1.99585017290651,19.7500009089708,9.81074459029923E-5,2.47398991099331E-5,0.25,6.65683323483786E-7,8.79533935357812E-6,6.70867179007388E-7,315.4584656,315.4584656,99.4112396240234,99.4112396240234,56.9885353371214,20.5182060227002,27.085165,0,0,0,40,4374,312.3595,99.4112396240234,,,,,,,,,,,,,0,,,,-0.00245,,,,,,315.4584656,,,,
,32295899.05,311.9748535,99.4112396240234,8.77728493766024E-6,4.02340326469097E-7,1,0.999253354069792,40.0298881530762,1.99606434287681,19.7500009089708,9.95781125909779E-5,1.4799882228205E-5,0.25,-2.10602027117111E-7,8.77341404383286E-6,-2.04876159015331E-7,311.9748535,311.9748535,99.4112396240234,99.4112396240234,56.8580033744099,20.5130665280782,27.464817,0,0,0,40,4374,308.8336,99.4112396240234,,,,,,,,,,,,,0,,,,0,,,,,,311.9748535,,,,
,32296041.11,308.4763794,99.4112396240234,8.50400150590091E-6,3.4000851986363E-7,1,0.999253354069792,40.0298881530762,1.99602926614844,19.7500009089708,9.69448958220629E-5,1.17038962083809E-5,0.25,-4.37475351373589E-7,8.50145943091703E-6,-4.31799504719214E-7,308.4763794,308.4763794,99.4112396240234,99.4112396240234,56.9893169656406,20.513890806596,27.464817,0,0,0,40,4374,305.257,99.4112396240234,,,,,,,,,,,,,0,,,,0.00245,,,,,,308.4763794,,,,
,32296182.655,304.9742126,99.4112396240234,9.01913437423099E-6,4.03852538920856E-7,1,0.999253354069792,40.0298881530762,1.99605480874906,19.7599995881319,0.000102062958213707,1.68502790130301E-5,0.25,-7.1542329754781E-8,9.01730628291168E-6,-6.5579518474456E-8,304.9742126,304.9742126,99.4112396240234,99.4112396240234,56.8900501436983,20.5089071642521,26.705515,0,0,0,40,4374,301.7028,99.4112396240234,,,,,,,,,,,,,0,,,,0,,,,,,304.9742126,,,,
,32296324.525,301.4448547,99.4112396240234,8.82852991163804E-6,4.55611871921756E-7,1,0.999253354069792,40.0298881530762,1.99648173556599,19.7599995881319,9.97160877241986E-5,1.77861141129634E-5,0.25,4.36915738980609E-8,8.82777478993474E-6,4.95932863961994E-8,301.4448547,301.4448547,99.4112396240234,99.4112396240234,56.9346029692945,20.4963199094009,27.464817,0,0,0,40,4374,298.1516,99.4112396240234,,,,,,,,,,,,,0,,,,0,,,,,,301.4448547,,,,
,32296464.41,297.9465027,99.4112396240234,8.40013943392148E-6,3.63090705346881E-7,1,0.999253354069792,40.0298881530762,1.99654355755044,19.7599995881319,9.48116667623549E-5,1.7390257126415E-5,0.25,8.25821342576789E-8,8.40044122912395E-6,8.82847844198669E-8,297.9465027,297.9465027,99.4112396240234,99.4112396240234,57.0612267894099,20.5026380492154,27.085165,0,0,0,40,4374,294.6421,99.4112396240234,,,,,,,,,,,,,0,,,,-0.0049,,,,,,297.9465027,,,,
,32296584.455,294.9967957,99.4112396240234,8.87394994734974E-6,3.57460113583958E-7,1,0.999253354069792,40.0298881530762,1.99655080418526,19.7700001299381,0.000100737551424834,1.51003047440862E-5,0.25,-2.02277374706326E-7,8.87540193851769E-6,-1.96211891774878E-7,294.9967957,294.9967957,99.4112396240234,99.4112396240234,57.0237086204868,20.4963952482486,27.085165,0,0,0,40,4374,291.62865,99.4112396240234,,,,,,,,,,,,,0,,,,0,,,,,,294.9967957,,,,
,32296725.555,291.4680481,99.4112396240234,9.33632743408705E-6,4.51170903167143E-7,1,0.999253354069792,40.0298881530762,1.99663926487861,19.7700001299381,0.0001058132861121,1.69924217753666E-5,0.25,-1.15412744053972E-7,9.33896761483716E-6,-1.08936619268696E-7,291.4680481,291.4680481,99.4112396240234,99.4112396240234,56.7407590965252,20.5013389753274,26.705515,0,0,0,40,4374,288.0952,99.4112396240234,,,,,,,,,,,,,0,,,,0,,,,,,291.4680481,,,,
,32296867.495,287.9653625,99.4112396240234,9.53982344024799E-6,3.15940581661058E-7,1,0.999253354069792,40.0298881530762,1.99650709861617,19.7700001299381,0.000107820976872824,1.91258752570217E-5,0.25,3.77643141220841E-8,9.54360810319976E-6,4.45294369475328E-8,287.9653625,287.9653625,99.4112396240234,99.4112396240234,56.8705094307176,20.5020376660662,27.085165,0,0,0,40,4374,284.5311,99.4112396240234,,,,,,,,,,,,,0,,,,0.0049,,,,,,287.9653625,,,,
,32297007.66,284.4648438,99.4112396240234,9.57969192953881E-6,4.91336641252681E-7,1,0.999253354069792,40.0298881530762,1.99645315088417,19.7999998927116,0.000108143581318452,2.00083746699879E-5,0.25,1.08606496189034E-7,9.58464204136985E-6,1.15543753254448E-7,284.4648438,284.4648438,99.4112396240234,99.4112396240234,57.0815491309099,20.5093538246499,27.085165,0,0,0,40,4374,281.0255,99.4112396240234,,,,,,,,,,,,,0,,,,-0.0049,,,,,,284.4648438,,,,
,32297148.545,280.9647827,99.4112396240234,9.26949744539907E-6,4.28006624742111E-7,1,0.999253354069792,40.0298881530762,1.99637120510734,19.7999998927116,0.000105184079411427,1.62856877835488E-5,0.25,-1.66976659108972E-7,9.27564632259247E-6,-1.60325413105611E-7,280.9647827,280.9647827,99.4112396240234,99.4112396240234,57.1229754424291,20.5127924306288,27.085165,0,0,0,40,4374,277.48995,99.4112396240234,,,,,,,,,,,,,0,,,,0,,,,,,280.9647827,,,,
,32297287.125,277.4987183,99.4112396240234,9.30168204147598E-6,3.43416625998764E-7,1,0.999253354069792,40.0298881530762,1.99644105610537,19.7999998927116,0.00010567884536704,1.56933725537518E-5,0.25,-2.25238061404956E-7,9.30905119239173E-6,-2.18525729165893E-7,277.4987183,277.4987183,99.4112396240234,99.4112396240234,56.831428004756,20.5150358912209,27.464817,0,0,0,40,4374,274.0265,99.4112396240234,,,,,,,,,,,,,0,,,,0,,,,,,277.4987183,,,,
,32297427.485,273.99006655,99.4112396240234,9.88372961573864E-6,3.26903661962856E-7,1,0.999253354069792,40.0298881530762,1.99635259943659,19.8199991136789,0.000112566055061575,1.51478187622188E-5,0.25,-3.74575237809229E-7,9.89290529766701E-6,-3.67480209359259E-7,273.9633179,274.0168152,99.4112396240234,99.4112396240234,56.9658681100637,20.5120095736591,27.464817,0,0,0,40,4374,270.5201,99.4112396240234,,,,,,,,,,,,,0,,,,0,,,,,,273.99006655,,,,
,32297568.845,270.4854431,99.4112396240234,9.51008128341598E-6,3.74363331654273E-7,1,0.999253354069792,40.0298881530762,1.99618719177992,19.8199991136789,0.000108178672629207,1.53657054238009E-5,0.25,-2.90722103866136E-7,9.52005264297659E-6,-2.83755226713134E-7,270.4854431,270.4854431,99.4112396240234,99.4112396240234,56.7360693254098,20.5126094333204,26.705515,0,0,0,40,4374,266.9974,99.4112396240234,,,,,,,,,,,,,0,,,,0,,,,,,270.4854431,,,,
,32297708.135,266.9704895,99.4112396240234,8.95913256875578E-6,3.59955674915814E-7,1,0.999253354069792,40.0298881530762,1.99610708161928,19.8199991136789,0.000102611156386505,1.04929429223824E-5,0.25,-6.26037444561751E-7,8.96992737787379E-6,-6.19804550330039E-7,266.9704895,266.9704895,99.4112396240234,99.4112396240234,57.1612752398714,20.512439485885,27.085165,0,0,0,40,4374,263.5094,99.4112396240234,,,,,,,,,,,,,0,,,,0.0049,,,,,,266.9704895,,,,
,32297849.775,263.4680023,99.4112396240234,9.74279486017625E-6,4.68886734854073E-7,1,0.999253354069792,40.0298881530762,1.98470138580192,19.8400001972914,0.000110005886839778,1.7035428414278E-5,0.25,-1.7580330182132E-7,9.75536044452942E-6,-1.68341705369783E-7,263.4354553,263.5005493,99.4112396240234,99.4112396240234,57.0768593597945,20.5182178189456,27.085165,0,0,0,40,4374,259.96095,99.4112396240234,,,,,,,,,,,,,0,,,,-0.00245,,,,,,263.4680023,,,,
,32297990.675,259.9855957,99.4112396240234,9.98469310659842E-6,4.79740655071906E-7,1,0.999253354069792,40.0298881530762,1.9849051520125,19.8400001972914,0.000112717844328446,1.77180193549105E-5,0.25,-1.57580332363237E-7,9.99879176555198E-6,-1.49794153631074E-7,259.9855957,259.9855957,99.4112396240234,99.4112396240234,56.9502355396791,20.5182853361549,27.085165,0,0,0,40,4374,256.4468,99.4112396240234,,,,,,,,,,,,,0,,,,0,,,,,,259.9855957,,,,
,32298130.87,256.4777222,99.4112396240234,1.00362579051339E-5,4.16714931367195E-7,1,0.999253354069792,40.0298881530762,1.98503973260093,19.8400001972914,0.000113550016073339,1.64946477528699E-5,0.25,-2.7559722408722E-7,1.00517765521204E-5,-2.6783453102839E-7,256.4777222,256.4777222,99.4112396240234,99.4112396240234,56.8353361473522,20.5160894527617,27.085165,0,0,0,40,4374,252.9345,99.4112396240234,,,,,,,,,,,,,0,,,,0,,,,,,256.4777222,,,,
,32298268.945,252.9833679,99.4112396240234,9.9026375111592E-6,4.30379555707772E-7,1,0.999253354069792,40.0298881530762,1.99630306435078,19.8699999600649,0.000112667965009971,1.63141811187642E-5,0.25,-2.76570832257033E-7,9.91918199976406E-6,-2.68817521890364E-7,252.9833679,252.9833679,99.4112396240234,99.4112396240234,56.9713395096983,20.5098692935102,27.085165,0,0,0,40,4374,249.46565,99.4112396240234,,,,,,,,,,,,,0,,,,0,,,,,,252.9833679,,,,
,32298409.41,249.4947815,99.4112396240234,1.0054500739274E-5,4.08940116838583E-7,1,0.999253354069792,40.0298881530762,1.9962461480404,19.8699999600649,0.000114143221385993,1.80855831026411E-5,0.25,-1.46756973910522E-7,1.00724274838512E-5,-1.3853864265954E-7,249.4947815,249.4947815,99.4112396240234,99.4112396240234,57.1933220091599,20.5112932082053,27.085165,0,0,0,40,4374,245.95595,99.4112396240234,,,,,,,,,,,,,0,,,,0.00245,,,,,,249.4947815,,,,
,32298550.455,245.9703369,99.4112396240234,1.05477563573235E-5,4.32742775626504E-7,1,0.999253354069792,40.0298881530762,1.99616712084464,19.8699999600649,0.000120026720839535,1.73975772144513E-5,0.25,-2.93354303126593E-7,1.05679915479576E-5,-2.84859668745658E-7,245.9703369,245.9703369,99.4112396240234,99.4112396240234,56.8759808303522,20.5113234744322,27.464817,0,0,0,40,4374,242.42265,99.4112396240234,,,,,,,,,,,,,0,,,,0,,,,,,245.9703369,,,,
,32298670.785,242.9430084,99.4112396240234,1.07200458929214E-5,3.46426125479275E-7,1,0.999253354069792,40.0298881530762,1.99618949538431,19.8999997228384,0.000121997763363208,1.77055368009753E-5,0.25,-2.96367351946819E-7,1.07417510018495E-5,-2.87622217824035E-7,242.9430084,242.9430084,99.4112396240234,99.4112396240234,57.3027500018522,20.5107452969747,27.085165,0,0,0,40,4374,239.4067,99.4112396240234,,,,,,,,,,,,,0,,,,0,,,,,,242.9430084,,,,
,32298810.455,239.4863815,99.4112396240234,1.07303395583247E-5,3.99761225661582E-7,1,0.999253354069792,40.0298881530762,1.99611835611691,19.8999997228384,0.000121742280140876,1.9933026318586E-5,0.25,-1.01801155862869E-7,1.07531914887617E-5,-9.25026349584014E-8,239.4552307,239.5175323,99.4112396240234,99.4112396240234,56.6672860157175,20.5108534151501,27.464817,0,0,0,40,4374,235.9086,99.4112396240234,,,,,,,,,,,,,0,,,,-0.0049,,,,,,239.4863815,,,,
,32298950.1,235.9721985,99.4112396240234,1.05751180758233E-5,3.36529377379431E-7,1,0.999253354069792,40.0298881530762,1.99619284386638,19.8999997228384,0.000119402627251433,2.3091383391983E-5,0.25,2.03474204177979E-7,1.05986578698343E-5,2.13477463890952E-7,235.9721985,235.9721985,99.4112396240234,99.4112396240234,57.4567308201407,20.5087658544849,27.464817,0,0,0,40,4374,232.42745,99.4112396240234,,,,,,,,,,,,,0,,,,0,,,,,,235.9721985,,,,
,32299070.335,232.9752808,99.4112396240234,1.05728772307749E-5,3.40678153854042E-7,1,0.999253354069792,40.0298881530762,1.98491208027654,19.9400000274181,0.000119705567304679,1.74304437334938E-5,0.25,-2.87797606190387E-7,1.05979550595498E-5,-2.78776720848519E-7,232.9752808,232.9752808,99.4112396240234,99.4112396240234,56.9807190519291,20.5080279557382,27.085165,0,0,0,40,4374,229.42235,99.4112396240234,,,,,,,,,,,,,0,,,,0,,,,,,232.9752808,,,,
,32299210.235,229.4936371,99.4112396240234,1.04858644035261E-5,3.67229573309966E-7,1,0.999253354069792,40.0298881530762,1.98367049812023,19.9400000274181,0.000118225366740359,1.98046612324934E-5,0.25,-6.13476033488953E-8,1.05117870671396E-5,-5.17010326822097E-8,229.4936371,229.4936371,99.4112396240234,99.4112396240234,57.044812590506,20.5381787521667,27.085165,0,0,0,40,4374,225.91635,99.4112396240234,,,,,,,,,,,,,0,,,,0,,,,,,229.4936371,,,,
,32299351.485,225.9776001,99.4112396240234,1.09046554682807E-5,3.74238056519991E-7,1,0.999253354069792,40.0298881530762,1.98366296882454,19.9400000274181,0.000123180056162462,1.93383990287797E-5,0.25,-1.7581511210318E-7,1.09330323533091E-5,-1.65883954175607E-7,225.9776001,225.9776001,99.4112396240234,99.4112396240234,57.3480844559676,20.540444341945,26.705515,0,0,0,40,4374,222.39315,99.4112396240234,,,,,,,,,,,,,0,,,,-0.0049,,,,,,225.9776001,,,,
,32299492.895,222.4319,99.4112396240234,1.01697932693507E-5,3.73405789333524E-7,1,0.999253354069792,40.0298881530762,1.98398198499192,19.9699997901917,0.000114531868463506,2.02213525120934E-5,0.25,2.94258597976547E-8,1.01972983030229E-5,3.93833080441716E-8,222.4319,222.4319,99.4112396240234,99.4112396240234,57.166746639506,20.5302667302247,26.705515,0,0,0,40,4374,218.8523,99.4112396240234,,,,,,,,,,,,,0,,,,0,,,,,,222.4319,,,,
,32299629.93,218.9914093,99.4112396240234,1.04466231478959E-5,3.87772604530264E-7,1,0.999253354069792,40.0298881530762,1.98377843073209,19.9699997901917,0.000118291195752407,1.70877495168175E-5,0.25,-2.96955880268551E-7,1.04764132815365E-5,-2.87449532643679E-7,218.9914093,218.9914093,99.4112396240234,99.4112396240234,57.3871658819292,20.5365972412048,27.085165,0,0,0,40,4374,215.4272,99.4112396240234,,,,,,,,,,,,,0,,,,-0.0049,,,,,,218.9914093,,,,
,32299769.36,215.4826508,99.4112396240234,1.03731425273419E-5,4.45695989190721E-7,1,0.999253354069792,40.0298881530762,1.98378928807502,19.9699997901917,0.000117350568490773,1.76782870129701E-5,0.25,-2.32189887474717E-7,1.04038852291701E-5,-2.22392729823217E-7,215.4826508,215.4826508,99.4112396240234,99.4112396240234,57.3004051162945,20.5347057930781,27.085165,0,0,0,40,4374,211.94885,99.4112396240234,,,,,,,,,,,,,0,,,,0.00245,,,,,,215.4826508,,,,
,32299910.995,211.9598999,99.4112396240234,1.12880927580309E-5,3.50014241821757E-7,1,0.999253354069792,40.0298881530762,1.98396170431161,20.0100000947714,0.000127794811671873,1.88503302286607E-5,0.25,-2.87606738266089E-7,1.13229099322617E-5,-2.76841760842591E-7,211.9598999,211.9598999,99.4112396240234,99.4112396240234,57.2628869473714,20.5317065665648,26.325863,0,0,0,40,4374,208.41115,99.4112396240234,,,,,,,,,,,,,0,,,,-0.00245,,,,,,211.9598999,,,,
,32300049.69,208.460434,99.4112396240234,1.07043096522598E-5,3.02622176384392E-7,1,0.999253354069792,40.0298881530762,1.98405039901183,20.0100000947714,0.000121282842364203,1.74292525723813E-5,0.25,-3.12795906946758E-7,1.07386090551509E-5,-3.0251321361206E-7,208.460434,208.460434,99.4112396240234,99.4112396240234,57.0924919301791,20.5277973175931,26.705515,0,0,0,40,4374,204.94385,99.4112396240234,,,,,,,,,,,,,0,,,,0.0049,,,,,,208.460434,,,,
,32300187.67,204.9972687,99.4112396240234,1.02757034478934E-5,4.06939321980897E-7,1,0.999253354069792,40.0298881530762,1.98394250601457,20.0100000947714,0.000116228389133977,1.79149313983792E-5,0.25,-1.95609614534301E-7,1.03096860154006E-5,-1.8519629402929E-7,204.9972687,204.9972687,99.4112396240234,99.4112396240234,56.9494539111599,20.5326604970837,26.325863,0,0,0,40,4374,201.4981,99.4112396240234,,,,,,,,,,,,,0,,,,0,,,,,,204.9972687,,,,
,32300329.58,201.46492,99.4112396240234,1.05947844184207E-5,3.34807172811278E-7,1,0.999253354069792,40.0298881530762,1.99518812609709,20.0399998575449,0.000120715617215089,1.73311268145854E-5,0.25,-3.11519275612879E-7,1.06311582156926E-5,-3.00920744284552E-7,201.46492,201.46492,99.4112396240234,99.4112396240234,57.3840393678522,20.5282895656758,27.085165,0,0,0,40,4374,197.94775,99.4112396240234,,,,,,,,,,,,,0,,,,0.00245,,,,,,201.46492,,,,
,32300468.78,197.9779053,99.4112396240234,1.02979830741041E-5,3.75095281082463E-7,1,0.999253354069792,40.0298881530762,1.99489144403124,20.0399998575449,0.000117826058718884,1.39920221231427E-5,0.25,-5.54741558211898E-7,1.03347785430027E-5,-5.45100792315511E-7,197.9779053,197.9779053,99.4112396240234,99.4112396240234,57.2167708647368,20.5298935681566,27.085165,0,0,0,40,4374,194.47215,99.4112396240234,,,,,,,,,,,,,0,,,,0,,,,,,197.9779053,,,,
,32300611.095,194.4474182,99.4112396240234,1.07933563385681E-5,3.3615431769858E-7,1,0.999253354069792,40.0298881530762,1.99477654751072,20.0399998575449,0.000123221213060896,1.62766751708701E-5,0.25,-4.396275331753E-7,1.0832979943725E-5,-4.2878364474049E-7,194.4474182,194.4474182,99.4112396240234,99.4112396240234,57.4489145349484,20.5316157017336,26.705515,0,0,0,40,4374,190.9168,99.4112396240234,,,,,,,,,,,,,0,,,,0,,,,,,194.4474182,,,,
,32300730.57,191.4629669,99.4112396240234,1.10562470670726E-5,4.48441210929494E-7,1,0.999253354069792,40.0298881530762,1.98376404037893,20.0800001621246,0.000124927612987599,2.02763057647534E-5,0.25,-1.2343406048994E-7,1.10974949921107E-5,-1.10890894328413E-7,191.4629669,191.4629669,99.4112396240234,99.4112396240234,57.3574639981984,20.5353208688662,26.705515,0,0,0,40,4374,187.9302,99.4112396240234,,,,,,,,,,,,,0,,,,-0.00245,,,,,,191.4629669,,,,
,32300868.495,187.9744873,99.4112396240234,1.05705179282158E-5,3.96378835395799E-7,1,0.999253354069792,40.0298881530762,1.98333568979484,20.0800001621246,0.0001196291742567,1.82231774240757E-5,0.25,-2.21222713232826E-7,1.06112228968677E-5,-2.09333859135556E-7,187.9744873,187.9744873,99.4112396240234,99.4112396240234,57.1073428720445,20.5454506563133,26.705515,0,0,0,40,4374,184.4702,99.4112396240234,,,,,,,,,,,,,0,,,,-0.0049,,,,,,187.9744873,,,,
,32301012.045,184.4568329,99.4112396240234,1.09303674890329E-5,3.73945838934607E-7,1,0.999253354069792,40.0298881530762,1.98296757492732,20.0800001621246,0.000123982591493616,1.71766733479472E-5,0.25,-3.76816992493403E-7,1.09738202935186E-5,-3.64780572060871E-7,184.4568329,184.4568329,99.4112396240234,99.4112396240234,56.9783741663714,20.5483206576159,26.325863,0,0,0,40,4374,180.82755,99.4112396240234,,,,,,,,,,,,,0,,,,-0.00245,,,,,,184.4568329,,,,
,32301129.265,181.49264525,99.4112396240234,1.04451778619113E-5,3.81872232358049E-7,1,0.999253354069792,40.0298881530762,1.98308047664693,20.1399996876717,0.000118318109263635,1.74409426135715E-5,0.25,-2.69531234809907E-7,1.04875307397157E-5,-2.57417828987526E-7,181.4597015,181.525589,99.4112396240234,99.4112396240234,57.0377779338329,20.5459245676291,26.325863,0,0,0,40,4374,177.9362,99.4112396240234,,,,,,,,,,,,,0,,,,0.0049,,,,,,181.49264525,,,,
,32301270.69,177.9483948,99.4112396240234,1.06255000631588E-5,3.06758960227434E-7,1,0.999253354069792,40.0298881530762,1.98304222657039,20.1399996876717,0.000120434146560137,1.73817932042831E-5,0.25,-3.06625493927842E-7,1.06697541594527E-5,-2.94101963351542E-7,177.9483948,177.9483948,99.4112396240234,99.4112396240234,57.291807202583,20.5526710663771,26.705515,0,0,0,40,4374,174.4196,99.4112396240234,,,,,,,,,,,,,0,,,,-0.0049,,,,,,177.9483948,,,,
,32301407.595,174.4713135,99.4112396240234,1.04908639091306E-5,3.07365568272299E-7,1,0.999253354069792,40.0298881530762,1.98296614343406,20.1399996876717,0.000118575599924946,1.91192096536246E-5,0.25,-1.29630327031369E-7,1.05354038264493E-5,-1.16196793099726E-7,174.4713135,174.4713135,99.4112396240234,99.4112396240234,57.3207274577945,20.5530575482761,26.705515,0,0,0,40,4374,171.0231,99.4112396240234,,,,,,,,,,,,,0,,,,0,,,,,,174.4713135,,,,
,32301547.47,170.9902344,99.4112396240234,1.04862831045776E-5,3.78127092064483E-7,1,0.999253354069792,40.0298881530762,1.9944754970487,20.1999992132187,0.000120036425324375,1.4368537403135E-5,0.25,-5.57594877416531E-7,1.05324423109802E-5,-5.45634211589996E-7,170.9902344,170.9902344,99.4112396240234,99.4112396240234,56.9893169656406,20.5374638952544,26.325863,0,0,0,40,4374,167.54405,99.4112396240234,,,,,,,,,,,,,0,,,,0,,,,,,170.9902344,,,,
,32301687.1,167.4551239,99.4112396240234,1.04828676081279E-5,3.48295560527338E-7,1,0.999253354069792,40.0298881530762,1.99469900026501,20.1999992132187,0.000119470261578003,1.75391894226242E-5,0.25,-2.7819358747574E-7,1.05296840342778E-5,-2.64632224389688E-7,167.4551239,167.4551239,99.4112396240234,99.4112396240234,57.0377779338329,20.5387592583298,26.325863,0,0,0,40,4374,164.06735,99.4112396240234,,,,,,,,,,,,,0,,,,0.00245,,,,,,167.4551239,,,,
,32301828.37,163.9318542,99.4112396240234,1.05870021133913E-5,3.65149428940531E-7,1,0.999253354069792,40.0298881530762,1.99460903031696,20.1999992132187,0.000120526076627663,1.85047695517385E-5,0.25,-2.1174719114788E-7,1.0635222207036E-5,-1.97303223900082E-7,163.9318542,163.9318542,99.4112396240234,99.4112396240234,56.9986965078714,20.5414261163498,25.946213,0,0,0,40,4374,160.5431,99.4112396240234,,,,,,,,,,,,,0,,,,0,,,,,,163.9318542,,,,
,32301966.53,160.441803,99.4112396240234,1.04781916495864E-5,3.04079971533544E-7,1,0.999253354069792,40.0298881530762,2.00713705467714,20.2500000596046,0.000120563409783378,1.52676077950539E-5,0.25,-4.86767524671463E-7,1.05273265689011E-5,-4.73294973161623E-7,160.441803,160.441803,99.4112396240234,99.4112396240234,56.6930797568522,20.5317330878127,25.566563,0,0,0,40,4374,157.0954,99.4112396240234,,,,,,,,,,,,,0,,,,0,,,,,,160.441803,,,,
,32302105.055,156.9865265,99.4112396240234,1.06836235124622E-5,3.40913534300342E-7,1,0.999253354069792,40.0298881530762,2.00698440221224,20.2500000596046,0.000122219088496264,1.96467374689312E-5,0.25,-1.39415944016876E-7,1.07341612995555E-5,-1.23521855022337E-7,156.9865265,156.9865265,99.4112396240234,99.4112396240234,57.0979633298137,20.5381731970918,25.946213,0,0,0,40,4374,153.63805,99.4112396240234,,,,,,,,,,,,,0,,,,0,,,,,,156.9865265,,,,
,32302243.58,153.4789124,99.4112396240234,1.06765974575593E-5,3.04846271403542E-7,1,0.999253354069792,40.0298881530762,2.00696997792261,20.2500000596046,0.000121983536069697,2.05844046247283E-5,0.25,-5.67442561725378E-8,1.07279338829805E-5,-3.99184979133904E-8,153.4789124,153.4789124,99.4112396240234,99.4112396240234,57.4395349927176,20.5355800153721,25.946213,0,0,0,40,4374,150.17795,99.4112396240234,,,,,,,,,,,,,0,,,,-0.0049,,,,,,153.4789124,,,,
,32302384.525,149.93573,99.4112396240234,1.10551884973494E-5,3.89127949865105E-7,1,0.999253354069792,40.0298881530762,1.99487687832915,20.3099995851517,0.000126618153226376,1.53157829488653E-5,0.25,-5.77251434288053E-7,1.11101782229563E-5,-5.61740490270091E-7,149.93573,149.93573,99.4112396240234,99.4112396240234,57.3637170263522,20.535229138755,25.186911,0,0,0,40,4374,146.676,99.4112396240234,,,,,,,,,,,,,0,,,,0.0049,,,,,,149.93573,,,,
,32302523.915,146.4641571,99.4112396240234,1.07611488219062E-5,3.38247591722303E-7,1,0.999253354069792,40.0298881530762,1.99506818584603,20.3099995851517,0.000123335707376134,1.45472043164508E-5,0.25,-5.94601729559265E-7,1.08156571591877E-5,-5.79058655581861E-7,146.4641571,146.4641571,99.4112396240234,99.4112396240234,57.1620568683907,20.5352860299861,25.186911,0,0,0,40,4374,143.19345,99.4112396240234,,,,,,,,,,,,,0,,,,-0.0049,,,,,,146.4641571,,,,
,32302661.63,142.98485565,99.4112396240234,1.05415929925342E-5,3.65272350102361E-7,1,0.999253354069792,40.0298881530762,1.99479843755231,20.3099995851517,0.000119767160083968,2.02509987063704E-5,0.25,-5.4454743877395E-8,1.05949290865172E-5,-3.59314416414535E-8,142.9550629,143.0146484,99.4112396240234,99.4112396240234,57.5341120435445,20.5358226307912,25.566563,0,0,0,40,4374,139.7738,99.4112396240234,,,,,,,,,,,,,0,,,,0.00245,,,,,,142.98485565,,,,
,32302802.885,139.4844971,99.4112396240234,1.04264087627553E-5,3.65327812611122E-7,1,0.999253354069792,40.0298881530762,1.9947286771087,20.3699991106987,0.000119359974836778,1.4893372378285E-5,0.25,-5.07155348437913E-7,1.04808058232639E-5,-4.90420015046636E-7,139.4844971,139.4844971,99.4112396240234,99.4112396240234,57.5771016121022,20.5330502473992,25.566563,0,0,0,40,4374,136.2627,99.4112396240234,,,,,,,,,,,,,0,,,,0.00245,,,,,,139.4844971,,,,
,32302940.76,135.9877472,99.4112396240234,1.03744586913508E-5,2.972159941907E-7,1,0.999253354069792,40.0298881530762,1.99478162053326,20.3699991106987,0.000117962065713242,1.94912932102161E-5,0.25,-9.39907938358228E-8,1.04285876735661E-5,-7.44558479138942E-8,135.9877472,135.9877472,99.4112396240234,99.4112396240234,56.9588334533906,20.5361827365783,25.186911,0,0,0,40,4374,132.81895,99.4112396240234,,,,,,,,,,,,,0,,,,0,,,,,,135.9877472,,,,
,32303081.315,132.4649963,99.4112396240234,1.04692461540228E-5,2.90691418947683E-7,1,0.999253354069792,40.0298881530762,1.99474446025061,20.3699991106987,0.000119066783417645,1.95514040165018E-5,0.25,-1.06197034910378E-7,1.05246227628645E-5,-8.56777764752203E-8,132.4649963,132.4649963,99.4112396240234,99.4112396240234,56.8884868866599,20.5384674984456,25.186911,0,0,0,40,4374,129.3215,99.4112396240234,,,,,,,,,,,,,0,,,,0,,,,,,132.4649963,,,,
,32303219.76,128.975769,99.4112396240234,1.09688123570649E-5,3.10562172280114E-7,1,0.999253354069792,40.0298881530762,1.98354931492261,20.4199999570847,0.000124402779112623,1.85726002704415E-5,0.25,-2.71921321335174E-7,1.10278772749213E-5,-2.50309121703853E-7,128.975769,128.975769,99.4112396240234,99.4112396240234,56.9713395096983,20.5425661627646,25.186911,0,0,0,40,4374,125.88015,99.4112396240234,,,,,,,,,,,,,0,,,,-0.00245,,,,,,128.975769,,,,
,32303358.07,125.4637833,99.4112396240234,1.08066115201708E-5,3.06232378139458E-7,1,0.999253354069792,40.0298881530762,1.98344602936845,20.4199999570847,0.000122154578577475,2.06432220926321E-5,0.25,-6.1279072075864E-8,1.08650097267283E-5,-3.78380981202903E-8,125.4637833,125.4637833,99.4112396240234,99.4112396240234,57.5044101598138,20.5429358569866,24.807261,0,0,0,40,4374,122.43555,99.4112396240234,,,,,,,,,,,,,0,,,,-0.00245,,,,,,125.4637833,,,,
,32303498.345,121.9612122,99.4112396240234,1.05764131590371E-5,3.83927067230247E-7,1,0.999253354069792,40.0298881530762,1.98339594552011,20.4199999570847,0.000119697134302061,1.93967199620589E-5,0.25,-1.32591732576289E-7,1.06342920747804E-5,-1.08916420916512E-7,121.9612122,121.9612122,99.4112396240234,99.4112396240234,57.2808644033138,20.5399678485124,24.427608,0,0,0,40,4374,118.962,99.4112396240234,,,,,,,,,,,,,0,,,,0,,,,,,121.9612122,,,,
,32303615.97,118.9598465,99.4112396240234,1.0341004409396E-5,3.09346590381198E-7,1,0.999253354069792,40.0298881530762,1.99469821492549,20.5000005662441,0.000117579245412402,1.96130945462361E-5,0.25,-8.27249275579095E-8,1.03979040526553E-5,-5.83100054694789E-8,118.9598465,118.9598465,99.4112396240234,99.4112396240234,57.0659165605253,20.5360344230605,24.807261,0,0,0,40,4374,116.0346,99.4112396240234,,,,,,,,,,,,,0,,,,-0.00245,,,,,,118.9598465,,,,
,32303756.67,115.4518051,99.4112396240234,1.07933857971606E-5,3.54575907152755E-7,1,0.999253354069792,40.0298881530762,1.99473258389849,20.5000005662441,0.000123200746721645,1.7783181042474E-5,0.25,-3.24539727165003E-7,1.08537964631193E-5,-2.98993968617812E-7,115.4518051,115.4518051,99.4112396240234,99.4112396240234,57.1808159528522,20.5387379082057,24.807261,0,0,0,40,4374,112.5331,99.4112396240234,,,,,,,,,,,,,0,,,,0,,,,,,115.4518051,,,,
,32303893.125,111.9932022,99.4112396240234,1.07379378350544E-5,3.77450970341199E-7,1,0.999253354069792,40.0298881530762,1.99471933354765,20.5000005662441,0.000122171902768689,1.99695808711576E-5,0.25,-1.23766008270892E-7,1.07978618786679E-5,-9.57955700505896E-8,111.9932022,111.9932022,99.4112396240234,99.4112396240234,57.6732419199676,20.5419282814575,24.427608,0,0,0,40,4374,109.1492,99.4112396240234,,,,,,,,,,,,,0,,,,0,,,,,,111.9932022,,,,
touchdown = 15.3200002387166 mm,32304025.7,108.6527481,99.4112396240234,1.05589106548093E-5,3.50431419027607E-7,1,0.999253354069792,40.0298881530762,1.98367764104237,20.5600000917912,0.000119712787616758,1.83333038615425E-5,0.25,-2.29463606204891E-7,1.06183432473613E-5,-2.01029791211641E-7,108.6527481,108.6527481,99.4112396240234,99.4112396240234,56.729816297256,20.5403094538366,24.047956,0,0,0,40,4374,105.8644,99.4112396240234,,,,,,,,,,,,,0,,,,-0.00245,,,,,,108.6527481,,,,
,32304151.79,105.4546356,99.4112396240234,1.07105641824703E-5,3.49755638165921E-7,1,0.999253354069792,40.0298881530762,1.98320621140041,20.5600000917912,0.000121620310221231,1.73713468001572E-5,0.25,-3.42524887017604E-7,1.07712806825405E-5,-3.12675118806234E-7,105.4546356,105.4546356,99.4112396240234,99.4112396240234,57.0838940164676,20.5466374716187,24.427608,0,0,0,40,4374,102.74135,99.4112396240234,,,,,,,,,,,,,0,,,,-0.00245,,,,,,105.4546356,,,,
,32304289.49,101.9864502,99.4112396240234,1.07547199203136E-5,2.66100917062512E-7,1,0.999253354069792,40.0298881530762,1.98325489563998,20.5600000917912,0.000121636807582467,2.02163910874933E-5,0.25,-1.00318003962586E-7,1.08148912223045E-5,-6.70103626136474E-8,101.9864502,101.9864502,99.4112396240234,99.4112396240234,57.4512594205061,20.5485156588578,24.047956,0,0,0,40,4374,99.29985,99.4112396240234,,,,,,,,,,,,,0,,,,0.0049,,,,,,101.9864502,,,,
touchdown = 15.3900003060699 mm,32304441.415,98.150589,99.4112396240234,1.11244690975313E-5,3.21299366391165E-7,1,0.999253354069792,40.0298881530762,1.9948570232494,20.6300001591444,0.000126565471562153,2.07594880212331E-5,0.25,-1.29847203868361E-7,1.11865039977877E-5,-9.3066352701448E-8,98.150589,98.150589,99.4112396240234,99.4112396240234,56.9955699937945,20.5326914641984,24.047956,0,0,0,40,4374,95.56375,99.4112396240234,,,,,,,,,,,,,0,,,,0,,,,,,98.150589,,,,
,32304567.93,94.9254532,99.4112396240234,1.05667390865235E-5,3.69795770748926E-7,1,0.999253354069792,40.0298881530762,1.99469788464035,20.6300001591444,0.000120269585649422,1.93556551345411E-5,0.25,-1.57290364764802E-7,1.06253447950819E-5,-1.20348931756944E-7,94.9254532,94.9254532,99.4112396240234,99.4112396240234,57.2488176340253,20.5408208047375,24.047956,0,0,0,40,4374,92.42735,99.4112396240234,,,,,,,,,,,,,0,,,,-0.00245,,,,,,94.9254532,,,,
,32304705.91,91.4867325,99.4112396240234,1.06833063430685E-5,3.533096122363E-7,1,0.999253354069792,40.0298881530762,1.99460041784201,20.6300001591444,0.000121824423874871,1.81940785332272E-5,0.25,-2.82622707135528E-7,1.07422663031082E-5,-2.43273059883446E-7,91.4867325,91.4867325,99.4112396240234,99.4112396240234,57.6849663477561,20.5410781686805,23.668306,0,0,0,40,4374,89.01415,99.4112396240234,,,,,,,,,,,,,0,,,,0,,,,,,91.4867325,,,,
touchdown = 15.4600003734231 mm,32304852.96,87.7223892,99.4112396240234,1.10028276924576E-5,3.42648437864644E-7,1,0.999253354069792,40.0298881530762,1.99492770629487,20.7000002264977,0.000125194829235423,2.03213306421141E-5,0.25,-1.54902747451489E-7,1.1061820903847E-5,-1.10391975876513E-7,87.7223892,87.7223892,99.4112396240234,99.4112396240234,57.5411467002176,20.5331723577037,23.668306,0,0,0,40,4374,85.3971,99.4112396240234,,,,,,,,,,,,,0,,,,0,,,,,,87.7223892,,,,
,32304980.785,84.480835,99.4112396240234,1.06813960483703E-5,3.36112782772983E-7,1,0.999253354069792,40.0298881530762,1.99487219439929,20.7000002264977,0.000121419666711986,2.02792379568923E-5,0.25,-1.04532030833545E-7,1.07370094691417E-5,-5.80149800071135E-8,84.480835,84.480835,99.4112396240234,99.4112396240234,56.6344576179098,20.5421112964501,23.288654,0,0,0,40,4374,82.216,99.4112396240234,,,,,,,,,,,,,0,,,,-0.00245,,,,,,84.480835,,,,
,32305116.965,80.9937286,99.4112396240234,1.08689611313296E-5,2.94636844246171E-7,1,0.999253354069792,40.0298881530762,1.99500720564707,20.7000002264977,0.00012355171215734,2.05464088856523E-5,0.25,-1.17554365498166E-7,1.09235192998932E-5,-6.66720524893E-8,80.9937286,80.9937286,99.4112396240234,99.4112396240234,56.9994781363906,20.5437459215439,23.288654,0,0,0,40,4374,78.8645,99.4112396240234,,,,,,,,,,,,,0,,,,0,,,,,,80.9937286,,,,
touchdown = 15.5199998989701 mm,32305257.595,77.4473877,99.4112396240234,1.07833615155794E-5,3.38262914627151E-7,1,0.999253354069792,40.0298881530762,1.99506635453733,20.7599997520447,0.000122537823650202,2.04504614543838E-5,0.25,-1.14394737085839E-7,1.08346499432819E-5,-5.98783801876142E-8,77.4473877,77.4473877,99.4112396240234,99.4112396240234,56.516431711506,20.5440544206746,22.529354,0,0,0,40,4374,75.41225,99.4112396240234,,,,,,,,,,,,,0,,,,0,,,,,,77.4473877,,,,
,32305394.57,73.9687119,99.4112396240234,1.09090870942422E-5,3.29976730014361E-7,1,0.999253354069792,40.0298881530762,1.99488316678166,20.7599997520447,0.000123518135676257,2.29057032179345E-5,0.25,7.63380777158261E-8,1.09562774728575E-5,1.366058646938E-7,73.9687119,73.9687119,99.4112396240234,99.4112396240234,57.3090030300061,20.546123099498,22.529354,0,0,0,40,4374,72.04095,99.4112396240234,,,,,,,,,,,,,0,,,,0,,,,,,73.9687119,,,,
,32305532.805,70.444664,99.4112396240234,1.03052907540736E-5,3.18066962477827E-7,1,0.999253354069792,40.0298881530762,1.99507796113276,20.7599997520447,0.000116998831564473,1.9632347488721E-5,0.25,-1.08462845108734E-7,1.03464178736002E-5,-4.8036189567478E-8,70.444664,70.444664,99.4112396240234,99.4112396240234,56.465625857756,20.5464558418295,22.909004,0,0,0,40,4374,68.6401,99.4112396240234,,,,,,,,,,,,,0,,,,0.00245,,,,,,70.444664,,,,
touchdown = 15.5899999663234 mm,32305665.275,67.0716782,99.4112396240234,1.07374474855047E-5,3.09626506618042E-7,1,0.999253354069792,40.0298881530762,1.98383549599195,20.8299998193979,0.000121140421167146,2.05960707316013E-5,0.25,-9.41272716495151E-8,1.07746376051767E-5,-2.67821221085643E-8,67.0716782,67.0716782,99.4112396240234,99.4112396240234,56.9033378285253,20.5439103784581,22.529354,0,0,0,40,4374,65.39315,99.4112396240234,,,,,,,,,,,,,0,,,,0,,,,,,67.0716782,,,,
,32305787.68,63.9105721,99.4112396240234,1.08154527217504E-5,3.3500081070451E-7,1,0.999253354069792,40.0298881530762,1.98359287772011,20.8299998193979,0.000122818071509704,1.58146422360647E-5,0.25,-5.3547738473311E-7,1.08495668750102E-5,-4.65007557426499E-7,63.9105721,63.9105721,99.4112396240234,99.4112396240234,56.6657227586791,20.5531632755674,22.149702,0,0,0,40,4374,62.3869,99.4112396240234,,,,,,,,,,,,,0,,,,-0.00245,,,,,,63.9105721,,,,
,32305923.87,60.4403648,99.4112396240234,1.10400346099617E-5,3.21180050349177E-7,1,0.999253354069792,40.0298881530762,1.98357205913552,20.8299998193979,0.00012515524925247,1.67848332040786E-5,0.25,-4.92367414708367E-7,1.10661216097569E-5,-4.16025733465951E-7,60.4403648,60.4403648,99.4112396240234,99.4112396240234,57.3207274577945,20.5509414128284,22.149702,0,0,0,40,4374,59.03345,99.4112396240234,,,,,,,,,,,,,0,,,,0,,,,,,60.4403648,,,,
touchdown = 15.650000423193 mm,32306071.795,56.6955719,99.4112396240234,1.05751332874455E-5,2.92560649536676E-7,1,0.999253354069792,40.0298881530762,1.98363699337706,20.889999344945,0.000118889000517935,2.09783231952266E-5,0.25,-3.72434510753471E-8,1.0586808809306E-5,3.98246113338488E-8,56.6955719,56.6955719,99.4112396240234,99.4112396240234,56.760299809506,20.5432405808627,21.770052,0,0,0,40,4374,55.4171,99.4112396240234,,,,,,,,,,,,,0,,,,0,,,,,,56.6955719,,,,
,32306197.76,53.4447899,99.4112396240234,1.0952326153984E-5,3.14043620353803E-7,1,0.999253354069792,40.0298881530762,1.98344074234589,20.889999344945,0.000123484346110217,1.90437717481612E-5,0.25,-2.77157771462497E-7,1.09561062961304E-5,-1.95903161130369E-7,53.4447899,53.4447899,99.4112396240234,99.4112396240234,56.4929828559291,20.5523984807285,21.01075,0,0,0,40,4374,52.3216,99.4112396240234,,,,,,,,,,,,,0,,,,0,,,,,,53.4447899,,,,
,32306333.5,49.9744072,99.4112396240234,1.08641348952049E-5,3.06521133696798E-7,1,0.999253354069792,40.0298881530762,1.98327424842494,20.889999344945,0.00012184958769918,2.16674045097967E-5,0.25,-2.54223623561939E-8,1.0854824688144E-5,5.52295688248276E-8,49.9744072,49.9744072,99.4112396240234,99.4112396240234,56.9447641400445,20.5524106699901,20.251448,0,0,0,40,4374,49.0145,99.4112396240234,,,,,,,,,,,,,0,,,,-0.0049,,,,,,49.9744072,,,,
touchdown = 15.6999994069338 mm,32306478.905,46.2236481,99.4112396240234,1.07472140691481E-5,3.43026430365542E-7,1,0.999253354069792,40.0298881530762,1.99530251952324,20.9400001913309,0.000120938007264929,2.24527165296801E-5,0.25,5.81128472401304E-8,1.07256413414487E-5,1.35915349994586E-7,46.2236481,46.2236481,99.4112396240234,99.4112396240234,57.1933220091599,20.5319759133477,19.871798,0,0,0,40,4370,45.4693,99.4112396240234,,,,,,,,,,,,,0,,,,0,,,,,,46.2236481,,,,
,32306607.495,42.9739342,99.4112396240234,1.09661217855165E-5,3.14232906434176E-7,1,0.999253354069792,40.0298881530762,1.99505251560273,20.9400001913309,0.000123205912527172,2.32692483826508E-5,0.25,9.63435572985316E-8,1.09339480814536E-5,1.72470232045418E-7,42.9739342,42.9739342,99.4112396240234,99.4112396240234,56.7954730928714,20.5354217034988,18.732843,0,0,0,40,4370,42.3116,99.4112396240234,,,,,,,,,,,,,0,,,,0,,,,,,42.9739342,,,,
,32306744.32,39.4765244,99.4112396240234,1.03961334368204E-5,3.06724791558406E-7,1,0.999253354069792,40.0298881530762,1.99570865372729,20.9400001913309,0.000117184214220957,1.95723794028316E-5,0.25,-1.24725377237201E-7,1.03583352350193E-5,-5.59227080038758E-8,39.4765244,39.4765244,99.4112396240234,99.4112396240234,57.0557553897753,20.5300777219532,17.593889,0,0,0,40,4370,38.9406,99.4112396240234,,,,,,,,,,,,,0,,,,0,,,,,,39.4765244,,,,
touchdown = 15.7500002533197 mm,32306887.895,35.8643265,99.4112396240234,1.09563493376249E-5,3.50301877196393E-7,1,0.999253354069792,40.0298881530762,1.99594891614083,20.9899991750717,0.000123715131975938,1.89824018616267E-5,0.25,-2.71668875424404E-7,1.09094514803373E-5,-2.03424356410869E-7,35.8643265,35.8643265,99.4112396240234,99.4112396240234,57.5083183024099,20.5216010826068,17.593889,0,0,0,40,4370,35.39855,99.4112396240234,,,,,,,,,,,,,0,,,,0,,,,,,35.8643265,,,,
,32307021.485,32.4639778,99.4112396240234,1.04751422527039E-5,3.25045300208284E-7,1,0.999253354069792,40.0298881530762,1.99571302720879,20.9899991750717,0.000117749650721814,2.06948194570455E-5,0.25,-2.78400762429654E-8,1.04235368571503E-5,3.21301427217352E-8,32.4370422,32.4909134,99.4112396240234,99.4112396240234,57.5278590153907,20.5224093577413,17.214239,0,0,0,40,4370,32.0955,99.4112396240234,,,,,,,,,,,,,0,,,,0,,,,,,32.4639778,,,,
,32307160.6,28.9475536,99.4112396240234,1.06528446236262E-5,2.92904781952869E-7,1,0.999253354069792,40.0298881530762,1.99575586769595,20.9899991750717,0.00012009328241248,1.8848996994452E-5,0.25,-2.1934021814202E-7,1.05973088804176E-5,-1.61203615347852E-7,28.9475536,28.9475536,99.4112396240234,99.4112396240234,57.2261504069676,20.5268073907315,16.454937,0,0,0,40,4370,28.6445,99.4112396240234,,,,,,,,,,,,,0,,,,0,,,,,,28.9475536,,,,
touchdown = 15.7900005578995 mm,32307300.31,25.4416065,99.4112396240234,1.08696014422648E-5,3.9379298239666E-7,1,0.999253354069792,40.0298881530762,1.99568038870995,21.0299994796514,0.000122534628601775,1.90361325668675E-5,0.25,-2.37784715957842E-7,1.08102224557098E-5,-1.81330122201896E-7,25.4416065,25.4416065,99.4112396240234,99.4112396240234,56.9150622563137,20.5202769644224,16.075285,0,0,0,40,4370,25.1779,99.4112396240234,,,,,,,,,,,,,0,,,,-0.00245,,,,,,25.4416065,,,,
,32307436.96,21.9952602,99.4112396240234,1.06663410450553E-5,3.02607557226624E-7,1,0.999253354069792,40.0298881530762,1.99562011100242,21.0299994796514,0.000119778730622141,2.11749325866774E-5,0.25,-9.02005767125435E-9,1.06054592513933E-5,4.32962094382032E-8,21.9952602,21.9952602,99.4112396240234,99.4112396240234,56.7204367550252,20.526412028373,15.695635,0,0,0,40,4370,21.783,99.4112396240234,,,,,,,,,,,,,0,,,,0.0049,,,,,,21.9952602,,,,
,32307577.52,18.4421597,99.4112396240234,1.06460811932415E-5,3.03335538816591E-7,1,0.999253354069792,40.0298881530762,1.99543246254795,21.0299994796514,0.000120027217216334,1.83559656957792E-5,0.25,-2.55443792050018E-7,1.05859600951103E-5,-2.02614279297439E-7,18.4421597,18.4421597,99.4112396240234,99.4112396240234,57.0815491309099,20.5261760799442,14.556682,0,0,0,40,4370,18.2984,99.4112396240234,,,,,,,,,,,,,0,,,,0,,,,,,18.4421597,,,,
touchdown = 15.8099997788668 mm,32307713.9,15.0079279,99.4112396240234,1.05813336572112E-5,3.28322326744799E-7,1,0.999253354069792,40.0298881530762,1.98435519750829,21.0500005632639,0.000118236039022602,2.05688872171625E-5,0.25,-3.70689364136605E-8,1.05206375154083E-5,1.41756656326199E-8,15.0079279,15.0079279,99.4112396240234,99.4112396240234,57.6865296047946,20.5289602759606,14.177031,0,0,0,40,4370,14.8976,99.4112396240234,,,,,,,,,,,,,0,,,,0.00245,,,,,,15.0079279,,,,
,32307837.52,11.9743633,99.4112396240234,1.05307723354903E-5,3.85180885460891E-7,1,0.999253354069792,40.0298881530762,1.98416714504132,21.0500005632639,0.000117901957012981,1.91135866187829E-5,0.25,-1.58268864022689E-7,1.04710292089371E-5,-1.06571628600761E-7,11.9743633,11.9743633,99.4112396240234,99.4112396240234,56.9596150819099,20.5313227092083,13.797379,0,0,0,40,4370,11.8466,99.4112396240234,,,,,,,,,,,,,0,,,,-0.00245,,,,,,11.9743633,,,,
,32308117.615,5.9910755,99.4112396240234,1.06708440127022E-5,3.39112520063583E-7,1,0.999253354069792,40.0298881530762,1.98413806918105,21.0500005632639,0.000119450579052154,1.94739616972061E-5,0.25,-1.50857491737526E-7,1.06103428533451E-5,-9.85280673902516E-8,5.9910755,5.9910755,99.4112396240234,99.4112396240234,57.2042648084291,20.5317308895759,10.00087,0,0,0,40,4370,5.954,99.4112396240234,,,,,,,,,,,,,0,,,,0,,,,,,5.9910755,,,,
,32308778.62,5.0006652,99.4112396240234,1.06991022812559E-5,2.73382103494757E-7,1,0.999253354069792,40.0298881530762,1.98390984687317,21.0999995470047,0.0001201422349849,1.73359297929486E-5,0.25,-3.47181171276057E-7,1.06393900766105E-5,-2.93589084715138E-7,5.0006652,5.0006652,99.4112396240234,99.4112396240234,57.3551191126407,20.5379548536374,8.861917,0,0,0,40,4369,5.0113,99.4112396240234,,,,,,,,,,,,,0,,,,0,,,,,,5.0006652,,,,