File: data/monolayers/magneticStructure/ML_Ac_CoFe_C/PPMS/data/DD205_4_KOELNPPMS_HYST_100OE_5K.DAT
[Header]
; VSM Data File (default extension .dat)
; Copyright (c) 2003-2013, Quantum Design, Inc. All rights reserved.
TITLE,
FILEOPENTIME,19679421.06,08/16/2018,6:28 pm
BYAPP,VSM,2.0,2.0
INFO,PPMS VSM Option Release 1.4.10 Build 1,APPNAME
INFO,Quantum Design Linear Motor Servo Controller,MOTOR_MODULE_NAME
INFO,3101-100 M1,MOTOR_HW_VERSION
INFO,MMC1014,MOTOR_SERIAL_NUMBER
INFO,SRV No X-over 01.03.11,MOTOR_SOFTWARE_VERSION
INFO,Quantum Design VSM Detection Module,VSM_MODULE_NAME
INFO,3101-150 F0,VSM_HW_VERSION
INFO,VSM707,VSM_SERIAL_NUMBER
INFO,VSM No X-over 01.02.05 May 20 2008 13:51:47,VSM_SOFTWARE_VERSION
INFO,704,PREAMP_SERIAL_NUMBER
INFO,822,COIL_SERIAL_NUMBER
INFO,0,MOMENT_UNITS
INFO,,SAMPLE_MATERIAL
INFO,,SAMPLE_COMMENT
INFO,,SAMPLE_MASS
INFO,,SAMPLE_VOLUME
INFO,,SAMPLE_MOLECULAR_WEIGHT
INFO,,SAMPLE_SIZE
INFO,,SAMPLE_SHAPE
DATATYPE,COMMENT,1
DATATYPE,TIME,2
STARTUPAXIS,X,2
STARTUPAXIS,Y1,5
[Data]
Comment,Time Stamp (sec),Temperature (K),Magnetic Field (Oe),Moment (emu),M. Std. Err. (emu),Transport Action,Averaging Time (sec),Frequency (Hz),Peak Amplitude (mm),Center Position (mm),Coil Signal' (mV),Coil Signal" (mV),Range (mV),M. Quad. Signal (emu),M. Raw' (emu),M. Raw" (emu),Min. Temperature (K),Max. Temperature (K),Min. Field (Oe),Max. Field (Oe),Mass (grams),Motor Lag (deg),Pressure (Torr),VSM Status (code),Motor Status (code),Measure Status (code),Measure Count,PPMS Status (code),System Temp. (K),System Field (Oe),Sample Position (deg),Bridge 1 Resistance (ohms),Bridge 1 Excitation (에),Bridge 2 Resistance (ohms),Bridge 2 Excitation (에),Bridge 3 Resistance (ohms),Bridge 3 Excitation (에),Bridge 4 Resistance (ohms),Bridge 4 Excitation (에),Signal 1 Vin (V),Signal 2 Vin (V),Digital Inputs (code),Drive 1 Iout (mA),Drive 1 Ipower (W),Drive 2 Iout (mA),Drive 2 Ipower (W),Pressure (),Map 20 (),Map 21 (),Map 22 (),Map 23 (),Map 24 (),Map 25 (),Map 26 (),Map 27 (),Map 28 (),Map 29 ()
sample offset = 35.68 mm,19679455.87,5.02255,0.350146800279617,9.1709682448706E-6,2.52574502840632E-7,1,0.999253354069792,40.0298881530762,1.98158962200817,14.2400003969669,0.00010328102656389,1.25127745028499E-5,0.25,-5.06532422976356E-7,9.12076826061302E-6,-4.59421257283863E-7,5.0223,5.0223,0.350146800279617,0.350146800279617,54.3950919103134,19.5730964933278,9.241568,0,0,0,40,4417,5.02255,0.350146800279617,,,,,,,,,,,,,0,,,,,,,,,,,,,,
,19679543.315,5.0219,3683.50109863281,4.72387127104449E-6,2.96908072659866E-7,1,0.999253354069792,40.0298881530762,1.98178324800086,14.2400003969669,5.37586327470789E-5,3.38861677886513E-6,0.25,-5.36111820729159E-7,4.70035552654774E-6,-5.09349494244172E-7,5.0219,5.0219,3678.27514648438,3688.72705078125,54.1238668141403,19.5729771026874,9.241568,0,0,0,40,4449,5.0219,3683.50109863281,,,,,,,,,,,,,0,,,,,,,,,,,,,,
,19679618.185,5.0253,7425.27685546875,-7.66125720271975E-6,3.94673140566516E-7,1,0.999253354069792,40.0298881530762,1.98175663594768,14.2500000074506,-8.41916771379589E-5,-2.24532139146468E-5,0.25,-6.48152198362596E-7,-7.61728789995264E-6,-6.85356608009559E-7,5.0253,5.0253,7422.7060546875,7427.84765625,54.2973883454096,19.5718624937569,8.861917,0,0,0,40,4449,5.0253,7425.27685546875,,,,,,,,,,,,,0,,,,,,,,,,,,,,
,19679694.885,5.0242,11261.216796875,-2.04104229806282E-5,3.62533762251788E-7,1,0.999253354069792,40.0298881530762,1.98161399827182,14.2400003969669,-0.000226816339263468,-4.59691806174778E-5,0.25,-4.7880261883508E-7,-2.03059763425959E-5,-5.90449106399183E-7,5.0242,5.0242,11256.126953125,11266.306640625,54.2622150620442,19.572383138649,9.241568,0,0,0,40,4449,5.0242,11261.216796875,,,,,,,,,,,,,0,,,,,,,,,,,,,,
,19679770.665,5.0254,15046.7670898438,-3.21940690612182E-5,3.59120245729993E-7,1,0.999253354069792,40.0298881530762,1.98167796605519,14.2400003969669,-0.00035835778060446,-6.99335982026342E-5,0.25,-5.13423819929536E-7,-3.20411420180855E-5,-6.99714391673777E-7,5.0256,5.0256,15044.3232421875,15049.2109375,54.3341248858134,19.5727699401961,9.241568,0,0,0,40,4449,5.0254,15046.7670898438,,,,,,,,,,,,,0,,,,,,,,,,,,,,
,19679844.69,5.0269,18747.1484375,-4.27839433818737E-5,3.82820665234729E-7,1,0.999253354069792,40.0298881530762,1.98174927076846,14.2500000074506,-0.000476929697419801,-9.00989632697863E-5,0.25,-4.14132474690818E-7,-4.25969220785144E-5,-6.73967526344141E-7,5.026,5.026,18717.10546875,18777.19140625,54.2872271746596,19.5696995857443,8.482265,0,0,0,40,4449,5.0269,18747.1484375,,,,,,,,,,,,,0,,,,,,,,,,,,,,
,19679922.02,5.02895,22610.4404296875,-5.2800656319193E-5,2.64649906575811E-7,1,0.999253354069792,40.0298881530762,1.98181437715326,14.2400003969669,-0.000588572603657184,-0.000112684925341157,0.25,-6.27621686850116E-7,-5.25889607763609E-5,-9.61013449882041E-7,5.0287,5.0287,22585.3828125,22635.498046875,54.0926016733711,19.5752303920498,9.241568,0,0,0,40,4449,5.02895,22610.4404296875,,,,,,,,,,,,,0,,,,,,,,,,,,,,
,19679996.39,5.0283,26327.8125,-6.17998474458751E-5,4.39950385271312E-7,1,0.999253354069792,40.0298881530762,1.98184897452332,14.2400003969669,-0.000688898313684502,-0.000133396547501501,0.25,-8.51526853112222E-7,-6.15744823717525E-5,-1.25487043078957E-6,5.0279,5.0279,26292.669921875,26362.955078125,53.8299744909095,19.570955459054,8.861917,0,0,0,40,4449,5.0283,26327.8125,,,,,,,,,,,,,0,,,,,,,,,,,,,,
,19680073.1,5.03,30163.8173828125,-7.10973831882386E-5,5.00663981996886E-7,1,0.999253354069792,40.0298881530762,1.9818652369,14.2400003969669,-0.000792995529840613,-0.000152790178332922,0.25,-8.99784377663356E-7,-7.08668533401976E-5,-1.37844387544294E-6,5.0301,5.0301,30156.4453125,30171.189453125,54.1926501238326,19.5703951190987,8.861917,0,0,0,40,4449,5.03,30163.8173828125,,,,,,,,,,,,,0,,,,,,,,,,,,,,
,19680149.82,5.03155,33996.724609375,-8.0822343912644E-5,5.2037833492897E-7,1,0.999253354069792,40.0298881530762,1.98176670505931,14.2400003969669,-0.000902015430489151,-0.000172479307414154,0.25,-8.95507367860403E-7,-8.05937093801037E-5,-1.45417701506482E-6,5.0313,5.0313,33994.125,33999.32421875,54.1152689004288,19.5671867386365,8.861917,0,0,0,40,4449,5.03155,33996.724609375,,,,,,,,,,,,,0,,,,,,,,,,,,,,
,19680225.33,5.03045,37769.70703125,-9.36581244801392E-5,5.10329405865612E-7,1,0.999253354069792,40.0298881530762,1.98186256790859,14.2400003969669,-0.00104753904496716,-0.00018994042557588,0.25,-1.28977586605905E-7,-9.34369843121459E-5,-7.92210952539439E-7,5.031,5.031,37767.265625,37772.1484375,54.2700313472365,19.5651976827993,8.482265,0,0,0,40,4449,5.03045,37769.70703125,,,,,,,,,,,,,0,,,,,,,,,,,,,,
,19680301.14,5.033,41559.994140625,-0.000106192489464562,6.16641313914596E-7,1,0.999253354069792,40.0298881530762,1.98181285323095,14.2400003969669,-0.00118696856829195,-0.000222184052412079,0.25,-7.36525134450685E-7,-0.000105980090941983,-1.49985228197164E-6,5.033,5.033,41549.96484375,41570.0234375,53.9730125099288,19.564035137468,8.861917,0,0,0,40,4449,5.033,41559.994140625,,,,,,,,,,,,,0,,,,,,,,,,,,,,
,19680377.605,5.0345,45381.0234375,-0.000117160710325086,6.23741505439606E-7,1,0.999253354069792,40.0298881530762,1.98179795284868,14.2500000074506,-0.00131168152555859,-0.000236348766246311,0.25,-8.83374848472884E-9,-0.000116979072795717,-8.63461691838995E-7,5.0344,5.0344,45378.3203125,45383.7265625,54.1738910393711,19.5630287650265,8.861917,0,0,0,40,4449,5.0345,45381.0234375,,,,,,,,,,,,,0,,,,,,,,,,,,,,
,19680453.5,5.039,49173.982421875,-0.000131852998907249,6.0926141559788E-7,1,0.999253354069792,40.0298881530762,1.98180705401282,14.2400003969669,-0.00147517203181151,-0.000274880598624475,0.25,-7.85860711279445E-7,-0.00013169441912506,-1.75581640694634E-6,5.039,5.039,49171.375,49176.58984375,53.750248381948,19.5607224408288,8.861917,0,0,0,40,4449,5.039,49173.982421875,,,,,,,,,,,,,0,,,,,,,,,,,,,,
,19680527.73,5.0413,52884.279296875,-0.000143861775827608,6.4651408024452E-7,1,0.999253354069792,40.0298881530762,1.98176276594448,14.2400003969669,-0.00160881337754672,-0.0003071331996832,0.25,-1.48595567953383E-6,-0.000143737890078185,-2.55066921587151E-6,5.0412,5.0412,52854.33984375,52914.21875,54.0214734781211,19.5639846457337,8.482265,0,0,0,40,4449,5.0413,52884.279296875,,,,,,,,,,,,,0,,,,,,,,,,,,,,
,19680605.705,5.046,56782.220703125,-0.000157982036042259,6.00372787159686E-7,1,0.999253354069792,40.0298881530762,1.98177054432857,14.2400003969669,-0.0017696157412495,-0.000325138303089556,0.25,-5.33155222753455E-7,-0.000157914561560872,-1.7077190918454E-6,5.046,5.046,56777.2578125,56787.18359375,54.281755775025,19.5625898000076,8.861917,0,0,0,40,4449,5.046,56782.220703125,,,,,,,,,,,,,0,,,,,,,,,,,,,,
,19680681.235,5.0413,60557.8046875,-0.000170149114873519,5.8764526011396E-7,1,0.999253354069792,40.0298881530762,1.98181910145569,14.2400003969669,-0.00190393351480494,-0.000365288504742913,0.25,-1.90901170224321E-6,-0.00017012758647358,-3.17545576134707E-6,5.0412,5.0412,60550.375,60565.234375,54.1254300711788,19.5618879619745,8.861917,0,0,0,40,4449,5.0413,60557.8046875,,,,,,,,,,,,,0,,,,,,,,,,,,,,
,19680758.295,5.0388,64411.279296875,-0.000183835213239831,8.14597711945325E-7,1,0.999253354069792,40.0298881530762,1.98194458594101,14.2400003969669,-0.00205855648435219,-0.000391359003543213,0.25,-1.75498981646081E-6,-0.000183879261510206,-3.12217542434474E-6,5.0388,5.0388,64408.75,64413.80859375,54.0511753618519,19.560867759885,8.861917,0,0,0,40,4449,5.0388,64411.279296875,,,,,,,,,,,,,0,,,,,,,,,,,,,,
,19680835.42,5.0413,68264.328125,-0.000195801979701781,5.70095766227433E-7,1,0.999253354069792,40.0298881530762,1.98192536872821,14.2400003969669,-0.00219234129339937,-0.000422198678005988,0.25,-2.34040595990215E-6,-0.000195911999076409,-3.79261542038598E-6,5.0413,5.0413,68262.0390625,68266.6171875,54.3692981691788,19.5599423625814,8.861917,0,0,0,40,4449,5.0413,68264.328125,,,,,,,,,,,,,0,,,,,,,,,,,,,,
,19680911.94,5.0412,72087.5703125,-0.000209328460770349,6.97055380575101E-7,1,0.999253354069792,40.0298881530762,1.98192695364517,14.2400003969669,-0.00234505278760537,-0.000448737488184736,0.25,-2.2635043212317E-6,-0.000209515603385243,-3.80855710186254E-6,5.0412,5.0412,72080.09375,72095.046875,54.3075495161596,19.5596389862312,8.861917,0,0,0,40,4449,5.0412,72087.5703125,,,,,,,,,,,,,0,,,,,,,,,,,,,,
,19680984.585,5.04315,75720.68359375,-0.000222765623512781,5.70410907924137E-7,1,0.999253354069792,40.0298881530762,1.98200115516546,14.2500000074506,-0.00249548619931815,-0.00048282200555672,0.25,-2.87601505487257E-6,-0.000223026979505214,-4.51095210647611E-6,5.0429,5.0429,75688.0078125,75753.359375,53.9667594817749,19.5584709415457,8.861917,0,0,0,40,4449,5.04315,75720.68359375,,,,,,,,,,,,,0,,,,,,,,,,,,,,
,19681059.4,5.0463,79459.15234375,-0.000235135803423498,7.46170560940888E-7,1,0.999253354069792,40.0298881530762,1.98200529783342,14.2400003969669,-0.0026342014146297,-0.000513258999612698,0.25,-3.35960655538295E-6,-0.000235477497359608,-5.07291563480815E-6,5.0463,5.0463,79456.5234375,79461.78125,53.8612396316788,19.5557093550044,8.861917,0,0,0,40,4449,5.0463,79459.15234375,,,,,,,,,,,,,0,,,,,,,,,,,,,,
,19681135.325,5.04905,83255.15625,-0.000247790377918209,8.50151613243165E-7,1,0.999253354069792,40.0298881530762,1.9820019616661,14.2400003969669,-0.00277661828023122,-0.000541718435156394,0.25,-3.61889288269895E-6,-0.000248219478894682,-5.40862135923051E-6,5.0496,5.0496,83225.0859375,83285.2265625,54.3755511973327,19.5573527264424,8.482265,0,0,0,40,4449,5.04905,83255.15625,,,,,,,,,,,,,0,,,,,,,,,,,,,,
,19681209.175,5.0514,86946.34375,-0.000260266196494248,8.08613414006273E-7,1,0.999253354069792,40.0298881530762,1.98203134266354,14.2400003969669,-0.00291839268520513,-0.000562591690663543,0.25,-3.23725738023415E-6,-0.00026078860026143,-5.09774919867328E-6,5.0515,5.0515,86939.125,86953.5625,53.8784354591019,19.5581170335897,8.861917,0,0,0,40,4449,5.0514,86946.34375,,,,,,,,,,,,,0,,,,,,,,,,,,,,
,19681293.44,5.05405,89659.0703125,-0.000268525860299943,6.18418180956831E-7,1,0.999253354069792,40.0298881530762,1.98193411776063,14.2400003969669,-0.00301110179370763,-0.00058227466169947,0.25,-3.51158553666262E-6,-0.000269112760187792,-5.41656687508651E-6,5.0527,5.0527,89629.40625,89688.734375,54.2755027468711,19.5568041871155,9.241568,0,0,0,40,4449,5.05405,89659.0703125,,,,,,,,,,,,,0,,,,,,,,,,,,,,
,19681364.035,5.05335,86133.71484375,-0.000258313341398421,6.56656821183882E-7,1,0.999253354069792,40.0298881530762,1.98190482462828,14.2400003969669,-0.00289498209707192,-0.000564832914805273,0.25,-3.7894703311427E-6,-0.000258813211627385,-5.64132422301431E-6,5.0516,5.0516,86103.78125,86163.6484375,54.1621666115827,19.5586721647193,8.861917,0,0,0,40,4449,5.05335,86133.71484375,,,,,,,,,,,,,0,,,,,,,,,,,,,,
,19681439.89,5.05145,82340.046875,-0.000243699241559223,8.16304408327099E-7,1,0.999253354069792,40.0298881530762,1.98187327949811,14.2400003969669,-0.00273207755525185,-0.000523524292862422,0.25,-2.73749084024849E-6,-0.000244110990782174,-4.5001698817287E-6,5.0511,5.0511,82335.1796875,82344.9140625,54.058210018525,19.5584420702019,8.861917,0,0,0,40,4449,5.05145,82340.046875,,,,,,,,,,,,,0,,,,,,,,,,,,,,
,19681513.645,5.0515,78653.3671875,-0.000232164421576976,7.10775798648848E-7,1,0.999253354069792,40.0298881530762,1.98195714743988,14.2400003969669,-0.0026049490887166,-0.000483098999155047,0.25,-1.20979584119906E-6,-0.000232502884005355,-2.90121312202348E-6,5.0504,5.0504,78620.8828125,78685.8515625,53.9308045698903,19.5591002903994,8.861917,0,0,0,40,4449,5.0515,78653.3671875,,,,,,,,,,,,,0,,,,,,,,,,,,,,
,19681591.01,5.04905,74786.73828125,-0.000218474707053169,6.86222880583905E-7,1,0.999253354069792,40.0298881530762,1.98197616326323,14.2400003969669,-0.00244495268875068,-0.000485993741998586,0.25,-3.93210850323785E-6,-0.000218706589965758,-5.53954778753761E-6,5.0486,5.0486,74756.9921875,74816.484375,54.1942133808711,19.5592579051548,8.482265,0,0,0,40,4449,5.04905,74786.73828125,,,,,,,,,,,,,0,,,,,,,,,,,,,,
,19681668.655,5.0477,70905.85546875,-0.000205910046911554,4.48468684139659E-7,1,0.999253354069792,40.0298881530762,1.98189799685788,14.2400003969669,-0.00230594070126099,-0.000444453240827355,0.25,-2.49928972340391E-6,-0.000206071825869124,-4.02185601828637E-6,5.0484,5.0484,70898.6171875,70913.09375,53.841698918698,19.5588062940602,8.861917,0,0,0,40,4449,5.0477,70905.85546875,,,,,,,,,,,,,0,,,,,,,,,,,,,,
,19681743.995,5.04485,67140.23046875,-0.000190923542195692,5.88729206161144E-7,1,0.999253354069792,40.0298881530762,1.98184735488592,14.2400003969669,-0.00213902826401417,-0.000402752926963265,0.25,-1.48959473649854E-6,-0.000191018023487886,-2.9066451398196E-6,5.0439,5.0439,67110.296875,67170.1640625,54.0496121048134,19.5600487855758,8.482265,0,0,0,40,4449,5.04485,67140.23046875,,,,,,,,,,,,,0,,,,,,,,,,,,,,
,19681821.93,5.04055,63244.5859375,-0.000177088223572815,6.31149762003146E-7,1,0.999253354069792,40.0298881530762,1.98195923428539,14.2400003969669,-0.00198518091595401,-0.000363801106768517,0.25,-5.16535714415103E-7,-0.000177120673317207,-1.83394315897348E-6,5.0408,5.0408,63212.11328125,63277.05859375,53.9159536280249,19.5632225331178,8.482265,0,0,0,40,4449,5.04055,63244.5859375,,,,,,,,,,,,,0,,,,,,,,,,,,,,
,19681896.93,5.0383,59493.400390625,-0.000164367601738557,6.49617825381197E-7,1,0.999253354069792,40.0298881530762,1.98195002181439,14.2400003969669,-0.00183972592886516,-0.000349788779724603,0.25,-1.56986192776812E-6,-0.000164332412632615,-2.79307212693406E-6,5.0377,5.0377,59463.34765625,59523.453125,54.1981215234673,19.5627612606791,8.482265,0,0,0,40,4449,5.0383,59493.400390625,,,,,,,,,,,,,0,,,,,,,,,,,,,,
,19681972.985,5.03555,55692.59375,-0.000151818306045918,4.71755395538902E-7,1,0.999253354069792,40.0298881530762,1.98187734444322,14.2400003969669,-0.00169867247495947,-0.000322470099949341,0.25,-1.40837345827319E-6,-0.000151730749700646,-2.53576536231073E-6,5.0354,5.0354,55660.01171875,55725.17578125,53.8932864009672,19.5607081241234,8.861917,0,0,0,40,4449,5.03555,55692.59375,,,,,,,,,,,,,0,,,,,,,,,,,,,,
,19682050.07,5.0328,51839.982421875,-0.000139055944428661,4.60466174881569E-7,1,0.999253354069792,40.0298881530762,1.98209707262305,14.2500000074506,-0.00155797905352432,-0.000281234194321658,0.25,-4.04495552092035E-8,-0.000138932022719191,-1.06917809678286E-6,5.0328,5.0328,51837.6953125,51842.26953125,54.0824405026211,19.5672410484741,9.241568,0,0,0,40,4449,5.0328,51839.982421875,,,,,,,,,,,,,0,,,,,,,,,,,,,,
,19682127.945,5.0316,47949.201171875,-0.00012434409990755,5.64904894797982E-7,1,0.999253354069792,40.0298881530762,1.98212644901615,14.2400003969669,-0.00139458649402549,-0.000240447064538398,0.25,9.33885209021087E-7,-0.000124191273069955,1.9556341216387E-8,5.0315,5.0315,47944.2109375,47954.19140625,53.9894267088326,19.5670269933071,8.861917,0,0,0,40,4449,5.0316,47949.201171875,,,,,,,,,,,,,0,,,,,,,,,,,,,,
,19682203.255,5.0275,44185.93359375,-0.000111398944461425,4.55580293476091E-7,1,0.999253354069792,40.0298881530762,1.98210359055324,14.2400003969669,-0.00124816389059643,-0.000219395126256155,0.25,4.65298303202686E-7,-0.000111215798691664,-3.45147557342817E-7,5.028,5.028,44180.83984375,44191.02734375,54.078532360025,19.5677299645648,8.861917,0,0,0,40,4449,5.0275,44185.93359375,,,,,,,,,,,,,0,,,,,,,,,,,,,,
,19682277.155,5.02685,40493.390625,-9.96068185528329E-5,6.12906923095895E-7,1,0.999253354069792,40.0298881530762,1.98213601412357,14.2400003969669,-0.00111532269227028,-0.000197758756039989,0.25,2.58234578020856E-7,-9.94032025945008E-5,-4.56607494414543E-7,5.0268,5.0268,40458.19140625,40528.58984375,54.0081857932942,19.5662923909231,8.861917,0,0,0,40,4449,5.02685,40493.390625,,,,,,,,,,,,,0,,,,,,,,,,,,,,
,19682354.65,5.0247,36617.4140625,-8.55068145860159E-5,5.46359364747512E-7,1,0.999253354069792,40.0298881530762,1.98214115857572,14.2400003969669,-0.000955788414721872,-0.000176700172430085,0.25,-4.15122526794898E-7,-8.52923697719816E-5,-1.01641042464146E-6,5.0247,5.0247,36609.38671875,36625.44140625,53.7580646671403,19.5675853342085,8.482265,0,0,0,40,4449,5.0247,36617.4140625,,,,,,,,,,,,,0,,,,,,,,,,,,,,
,19682431.1,5.02385,32800.0126953125,-7.09975023168465E-5,4.33279798474987E-7,1,0.999253354069792,40.0298881530762,1.98204386799456,14.2400003969669,-0.000792902853882692,-0.000148553171061534,0.25,-5.25446554735129E-7,-7.07894996704573E-5,-1.01328064899587E-6,5.0241,5.0241,32767.626953125,32832.3984375,53.9503452828711,19.56869654937,8.861917,0,0,0,40,4449,5.02385,32800.0126953125,,,,,,,,,,,,,0,,,,,,,,,,,,,,
,19682506.34,5.0222,29037.0146484375,-5.81267315201553E-5,4.88056836706478E-7,1,0.999253354069792,40.0298881530762,1.98203076603971,14.2400003969669,-0.000648642510420254,-0.000123006155325187,0.25,-5.68391079304497E-7,-5.79325587284627E-5,-9.56983478704885E-7,5.0233,5.0233,29004.51953125,29069.509765625,54.237984577948,19.5688348390818,8.861917,0,0,0,40,4449,5.0222,29037.0146484375,,,,,,,,,,,,,0,,,,,,,,,,,,,,
,19682581.61,5.0214,25273.53515625,-4.56159630081728E-5,5.46199323568754E-7,1,0.999253354069792,40.0298881530762,1.98208463832652,14.2400003969669,-0.000510086728906541,-8.9588816138421E-5,0.25,1.62993917529368E-7,-4.54498748685142E-5,-1.34884947810804E-7,5.0214,5.0214,25271.2109375,25275.859375,54.2012480375442,19.5677217237278,9.241568,0,0,0,40,4449,5.0214,25273.53515625,,,,,,,,,,,,,0,,,,,,,,,,,,,,
,19682657.975,5.0181,21458.275390625,-3.14899020749782E-5,4.95174705618083E-7,1,0.999253354069792,40.0298881530762,1.98218724453218,14.2400003969669,-0.000353203830984998,-5.51429782660388E-5,0.25,7.03499689177908E-7,-3.13668472218894E-5,5.02584465473402E-7,5.0184,5.0184,21423.33984375,21493.2109375,54.2246968931211,19.568565487905,8.861917,0,0,0,40,4449,5.0181,21458.275390625,,,,,,,,,,,,,0,,,,,,,,,,,,,,
,19682733.86,5.0182,17665.509765625,-1.84189865716903E-5,4.15715400199747E-7,1,0.999253354069792,40.0298881530762,1.98205100474371,14.2400003969669,-0.000206024636377617,-3.49201798707607E-5,0.25,1.66936651733355E-7,-1.83386784254782E-5,5.49061162436497E-8,5.0182,5.0182,17660.611328125,17670.408203125,54.2426743490634,19.5684641239624,8.861917,0,0,0,40,4449,5.0182,17665.509765625,,,,,,,,,,,,,0,,,,,,,,,,,,,,
,19682808.855,5.0179,13918.0512695313,-4.82141104193405E-6,3.76800088121725E-7,1,0.999253354069792,40.0298881530762,1.98218087197642,14.2500000074506,-5.33284563724136E-5,-1.24187609366456E-5,0.25,-2.51394316835789E-7,-4.79701944617708E-6,-2.78067477426037E-7,5.0181,5.0181,13887.978515625,13948.1240234375,54.0292897633134,19.5696933333803,8.482265,0,0,0,40,4449,5.0179,13918.0512695313,,,,,,,,,,,,,0,,,,,,,,,,,,,,
,19682884.36,5.0162,10142.3857421875,7.82798394948239E-6,3.66149432590876E-7,1,0.999253354069792,40.0298881530762,1.98193747953187,14.2400003969669,8.73887888042212E-5,1.54296917083759E-5,0.25,-1.30220081575015E-8,7.78830207008631E-6,3.01337185838234E-8,5.0162,5.0162,10139.7333984375,10145.0380859375,54.3036413735634,19.5701482603519,8.861917,0,0,0,40,4449,5.0162,10142.3857421875,,,,,,,,,,,,,0,,,,,,,,,,,,,,
,19682959.305,5.0151,6398.97045898438,2.09386406870627E-5,3.50158536797573E-7,1,0.999253354069792,40.0298881530762,1.9819119784847,14.2400003969669,0.000233203695681439,4.39388206988866E-5,0.25,2.11079312309248E-7,2.08251854481788E-5,3.1942546624226E-7,5.0151,5.0151,6396.552734375,6401.38818359375,54.0644630466788,19.5713667937441,8.482265,0,0,0,40,4449,5.0151,6398.97045898438,,,,,,,,,,,,,0,,,,,,,,,,,,,,
,19683032.16,5.0168,2755.75732421875,3.28673677781562E-5,3.25512088172153E-7,1,0.999253354069792,40.0298881530762,1.981931271801,14.2400003969669,0.000366914186419887,6.36709007355632E-5,0.25,-1.33933357629868E-7,3.26837753966729E-5,3.02743135698058E-8,5.0168,5.0168,2753.48193359375,2758.03271484375,54.4466793925827,19.5727503949193,8.861917,0,0,0,40,4449,5.0168,2755.75732421875,,,,,,,,,,,,,0,,,,,,,,,,,,,,
,19683107.445,5.0136,-1006.60827636719,3.21775689144271E-5,2.93327266583852E-7,1,0.999253354069792,40.0298881530762,1.98202452508619,14.2400003969669,0.000359621111016662,5.99347312992863E-5,0.25,-3.42531948343582E-7,3.19958132425375E-5,-1.83994555249073E-7,5.0136,5.0136,-1009.14752197266,-1004.06903076172,54.3489758276788,19.570456994242,8.861917,0,0,0,40,4449,5.0136,-1006.60827636719,,,,,,,,,,,,,0,,,,,,,,,,,,,,
,19683182.43,5.0136,-4752.58642578125,4.15375425268447E-5,3.23612437054128E-7,1,0.999253354069792,40.0298881530762,1.98204167914916,14.2400003969669,0.000463756795276128,8.06541887052969E-5,0.25,-1.5946686937462E-7,4.13107266974706E-5,5.36667523834881E-8,5.0136,5.0136,-4755.14697265625,-4750.02587890625,54.3755511973327,19.5712242974904,8.482265,0,0,0,40,4449,5.0136,-4752.58642578125,,,,,,,,,,,,,0,,,,,,,,,,,,,,
,19683256.12,5.0128,-8435.931640625,5.21881171979342E-5,3.23015291956043E-7,1,0.999253354069792,40.0298881530762,1.98202362258865,14.2400003969669,0.00058304705206677,0.000100089029318341,0.25,-3.28348666248369E-7,5.19177931171317E-5,-4.59517711708692E-8,5.0128,5.0128,-8438.302734375,-8433.560546875,53.9777022810442,19.5715872515757,8.861917,0,0,0,40,4449,5.0128,-8435.931640625,,,,,,,,,,,,,0,,,,,,,,,,,,,,
,19683330.99,5.01465,-12177.0122070312,6.36272369483236E-5,3.1380631716658E-7,1,0.999253354069792,40.0298881530762,1.98198457343286,14.2400003969669,0.000711020473784789,0.000122239130468942,0.25,-4.0207545357896E-7,6.33171678042905E-5,-4.03428603196274E-8,5.015,5.015,-12206.9130859375,-12147.111328125,54.0574283900057,19.5707267661733,8.861917,0,0,0,40,4449,5.01465,-12177.0122070312,,,,,,,,,,,,,0,,,,,,,,,,,,,,
,19683406.275,5.015,-15937.390625,7.15507847191602E-5,3.99825811407235E-7,1,0.999253354069792,40.0298881530762,1.9821094024586,14.2400003969669,0.000799739906776862,0.000138317134472829,0.25,-3.99651788480462E-7,7.12257645550284E-5,2.59976957118816E-8,5.015,5.015,-15940.2470703125,-15934.5341796875,54.251272262775,19.567379506811,8.861917,0,0,0,40,4449,5.015,-15937.390625,,,,,,,,,,,,,0,,,,,,,,,,,,,,
,19683480.52,5.0154,-19647.71484375,7.7024115579606E-5,4.80115935291742E-7,1,0.999253354069792,40.0298881530762,1.98210337422821,14.2400003969669,0.000860422245278422,0.000153404897739934,0.25,-5.06372079221251E-8,7.66989687345063E-5,4.25138674713444E-7,5.0154,5.0154,-19652.587890625,-19642.841796875,54.1277749567365,19.570469582574,8.482265,0,0,0,40,4449,5.0154,-19647.71484375,,,,,,,,,,,,,0,,,,,,,,,,,,,,
,19683556.52,5.0167,-23447.62890625,7.90906463902191E-5,4.24401294130604E-7,1,0.999253354069792,40.0298881530762,1.98194523215933,14.2400003969669,0.000885217600428285,0.000149516269561099,0.25,-7.91345353907004E-7,7.87912459763089E-5,-2.81229626118591E-7,5.0167,5.0167,-23450.037109375,-23445.220703125,54.0081857932942,19.5723527042844,8.482265,0,0,0,40,4449,5.0167,-23447.62890625,,,,,,,,,,,,,0,,,,,,,,,,,,,,
,19683634.11,5.01695,-27323.7548828125,7.97472958621134E-5,5.40675987654712E-7,1,0.999253354069792,40.0298881530762,1.98203782286106,14.2500000074506,0.000893604788158592,0.000147261859983163,0.25,-1.13393811872848E-6,7.94794310796754E-5,-6.01363302007141E-7,5.0171,5.0171,-27353.654296875,-27293.85546875,53.8667110313134,19.5750767561856,8.482265,0,0,0,40,4449,5.01695,-27323.7548828125,,,,,,,,,,,,,0,,,,,,,,,,,,,,
,19683711.255,5.0186,-31180.8818359375,8.28373214121298E-5,4.29554944727252E-7,1,0.999253354069792,40.0298881530762,1.9819606404139,14.2400003969669,0.000928676358979199,0.000152459806241064,0.25,-1.24405694090892E-6,8.25931749236483E-5,-6.7529599196758E-7,5.0187,5.0187,-31190.80859375,-31170.955078125,54.1574768404673,19.5774008826773,8.482265,0,0,0,40,4449,5.0186,-31180.8818359375,,,,,,,,,,,,,0,,,,,,,,,,,,,,
,19683786.635,5.01925,-34948.634765625,9.02950750309497E-5,4.5994217825193E-7,1,0.999253354069792,40.0298881530762,1.98200343597643,14.2400003969669,0.00101228227181579,0.00016865419028507,0.25,-1.15597105592103E-6,9.00637791691165E-5,-5.2255523366224E-7,5.0197,5.0197,-34983.71484375,-34913.5546875,54.2778476324288,19.5756240847704,8.102614,0,0,0,40,4449,5.01925,-34948.634765625,,,,,,,,,,,,,0,,,,,,,,,,,,,,
,19683862.255,5.02045,-38726.453125,9.96206636296712E-5,5.05782434021353E-7,1,0.999253354069792,40.0298881530762,1.98187903066073,14.2400003969669,0.00111616920783623,0.000191948234233431,0.25,-7.69210329456655E-7,9.94020031085368E-5,-5.85204941896763E-8,5.0202,5.0202,-38761.4921875,-38691.4140625,53.9300229413711,19.5744486927127,8.482265,0,0,0,40,4449,5.02045,-38726.453125,,,,,,,,,,,,,0,,,,,,,,,,,,,,
,19683936.86,5.0219,-42454.1796875,0.000109400733587354,6.74069606670964E-7,1,0.999253354069792,40.0298881530762,1.98203265298357,14.2400003969669,0.00122628382381802,0.000211112707076564,0.25,-8.3661293081549E-7,0.000109203729674495,-4.45707222307875E-8,5.0219,5.0219,-42459.1796875,-42449.1796875,54.0808772455826,19.5744404728771,8.861917,0,0,0,40,4449,5.0219,-42454.1796875,,,,,,,,,,,,,0,,,,,,,,,,,,,,
,19684015.585,5.02375,-46389.8203125,0.000121223746128972,5.4650910058983E-7,1,0.999253354069792,40.0298881530762,1.98199535614742,14.2400003969669,0.00135974275265668,0.00023181715401059,0.25,-1.13426473560602E-6,0.000121056866820488,-2.45861294463001E-7,5.0234,5.0234,-46392.64453125,-46386.99609375,54.4982668748519,19.5754712342261,8.861917,0,0,0,40,4449,5.02375,-46389.8203125,,,,,,,,,,,,,0,,,,,,,,,,,,,,
,19684091.545,5.025,-50187.720703125,0.000134167645575152,4.78492804255459E-7,1,0.999253354069792,40.0298881530762,1.98206137628024,14.2400003969669,0.00150528966868075,0.000258223923295462,0.25,-1.12544878683689E-6,0.00013403430970737,-1.34399376801992E-7,5.025,5.025,-50190.27734375,-50185.1640625,54.3028597450442,19.5757983689023,8.482265,0,0,0,40,4449,5.025,-50187.720703125,,,,,,,,,,,,,0,,,,,,,,,,,,,,
,19684167.955,5.0272,-54005.16015625,0.000147095258358853,4.74338312892036E-7,1,0.999253354069792,40.0298881530762,1.98200749863129,14.2400003969669,0.0016499706654789,0.000288474875184373,0.25,-7.69374609622244E-7,0.000147001909699113,3.22439121650918E-7,5.0261,5.0261,-54012.53515625,-53997.78515625,54.2442376061019,19.5765405890109,8.861917,0,0,0,40,4449,5.0272,-54005.16015625,,,,,,,,,,,,,0,,,,,,,,,,,,,,
,19684243.04,5.0304,-57757.75,0.000159323957762828,5.41674897747707E-7,1,0.999253354069792,40.0298881530762,1.98191999574945,14.2400003969669,0.0017846349819579,0.00032966539397736,0.25,6.89837794940873E-7,0.000159269736891732,1.87496033245617E-6,5.0307,5.0307,-57765.28125,-57750.21875,54.5326585296981,19.5749401690018,8.861917,0,0,0,40,4449,5.0304,-57757.75,,,,,,,,,,,,,0,,,,,,,,,,,,,,
,19684317.39,5.0332,-61473.107421875,0.000172322695399163,6.19302596956139E-7,1,0.999253354069792,40.0298881530762,1.98198491059768,14.2400003969669,0.00193262483696713,0.000347541923914948,0.25,-7.04106531189202E-8,0.000172330488181095,1.21215934167297E-6,5.0332,5.0332,-61478.171875,-61468.04296875,54.5295320156212,19.5756609074522,8.861917,0,0,0,40,4449,5.0332,-61473.107421875,,,,,,,,,,,,,0,,,,,,,,,,,,,,
,19684393.11,5.03395,-65258.447265625,0.000183951490657539,6.48404744851479E-7,1,0.999253354069792,40.0298881530762,1.98205361487531,14.2400003969669,0.00206250577676997,0.000378437374630851,0.25,5.78630469031184E-7,0.000184018288648839,1.94557706595998E-6,5.0345,5.0345,-65290.7578125,-65226.13671875,54.1895236097557,19.5764633418734,8.482265,0,0,0,40,4449,5.03395,-65258.447265625,,,,,,,,,,,,,0,,,,,,,,,,,,,,
,19684470.61,5.0387,-69130.984375,0.000197016255386551,5.30165486000134E-7,1,0.999253354069792,40.0298881530762,1.98204991004301,14.2400003969669,0.00221123771811716,0.000397106906100322,0.25,-1.17736846582802E-7,0.00019715995578399,1.34036414513593E-6,5.0387,5.0387,-69133.5546875,-69128.4140625,53.8080888923711,19.5772420613566,8.482265,0,0,0,40,4449,5.0387,-69130.984375,,,,,,,,,,,,,0,,,,,,,,,,,,,,
,19684546.165,5.03865,-72905.7265625,0.000210757872489311,7.62310404072512E-7,1,0.999253354069792,40.0298881530762,1.98191053574602,14.2400003969669,0.00236634581279277,0.000423301132360389,0.25,-2.60216779470158E-7,0.000210979198221237,1.29082513118668E-6,5.0392,5.0392,-72930.703125,-72880.75,54.3341248858134,19.5791285677075,8.482265,0,0,0,40,4449,5.03865,-72905.7265625,,,,,,,,,,,,,0,,,,,,,,,,,,,,
,19684622.61,5.04315,-76726.1171875,0.000223573430405578,5.73682250647876E-7,1,0.999253354069792,40.0298881530762,1.98194174849605,14.2400003969669,0.00250979970490616,0.00045606988539913,0.25,3.49381688112153E-7,0.000223872005060056,1.98373438587022E-6,5.0431,5.0431,-76728.625,-76723.609375,54.2082826942173,19.5791459712752,8.482265,0,0,0,40,4449,5.04315,-76726.1171875,,,,,,,,,,,,,0,,,,,,,,,,,,,,
,19684699.265,5.0437,-80556.3515625,0.000237486736257423,5.66310335549491E-7,1,0.999253354069792,40.0298881530762,1.98187579543454,14.2500000074506,0.0026651178653479,0.000493259799129472,0.25,1.1594769104652E-6,0.000237867641435463,2.88204558861494E-6,5.0433,5.0433,-80561.328125,-80551.375,54.3036413735634,19.5789169929667,8.482265,0,0,0,40,4449,5.0437,-80556.3515625,,,,,,,,,,,,,0,,,,,,,,,,,,,,
,19684776.15,5.0472,-84398.3125,0.000249197209293218,5.27774773778259E-7,1,0.999253354069792,40.0298881530762,1.98186734691155,14.2400003969669,0.00279762968410004,0.000515904945767877,0.25,1.0729836084448E-6,0.00024966756701829,2.86274303996298E-6,5.0464,5.0464,-84428.2265625,-84368.3984375,54.4279203081211,19.5783125347471,8.102614,0,0,0,40,4449,5.0472,-84398.3125,,,,,,,,,,,,,0,,,,,,,,,,,,,,
,19684848.57,5.0507,-88018.54296875,0.000260463954734538,6.54054354336124E-7,1,0.999253354069792,40.0298881530762,1.98186504458053,14.2400003969669,0.00292552681514156,0.000535562866036209,0.25,8.02957979032131E-7,0.000261023101196594,2.65394599989508E-6,5.0507,5.0507,-88020.9453125,-88016.140625,54.4052530810634,19.5779813989223,8.482265,0,0,0,40,4449,5.0507,-88018.54296875,,,,,,,,,,,,,0,,,,,,,,,,,,,,
,19684935.79,5.05195,-88487.640625,0.000262856861847014,6.03101039397397E-7,1,0.999253354069792,40.0298881530762,1.98201673073947,14.2400003969669,0.00295105855079711,0.000549735304339649,0.25,1.63118108423649E-6,0.000263423622640007,3.49837478748674E-6,5.053,5.053,-88512.7265625,-88462.5546875,54.2645599476019,19.5782268934124,8.102614,0,0,0,40,4449,5.05195,-88487.640625,,,,,,,,,,,,,0,,,,,,,,,,,,,,
,19685006.4,5.0521,-84960.62109375,0.000251103693457174,6.56035994302177E-7,1,0.999253354069792,40.0298881530762,1.98204801235622,14.2400003969669,0.00281993665141815,0.000516879971100356,0.25,8.13704280890233E-7,0.000251589539377001,2.61388780786826E-6,5.0521,5.0521,-84965.3203125,-84955.921875,54.2442376061019,19.5756376655495,8.861917,0,0,0,40,4449,5.0521,-84960.62109375,,,,,,,,,,,,,0,,,,,,,,,,,,,,
,19685080.705,5.04885,-81248.26171875,0.000238591058195182,5.79181358102847E-7,1,0.999253354069792,40.0298881530762,1.98216703457241,14.2500000074506,0.00267848089765093,0.000493109035258129,0.25,9.41841598660197E-7,0.000238987603184726,2.66917327284626E-6,5.0495,5.0495,-81253.359375,-81243.1640625,54.1684196397365,19.5767969118099,8.482265,0,0,0,40,4449,5.04885,-81248.26171875,,,,,,,,,,,,,0,,,,,,,,,,,,,,
,19685156.22,5.0508,-77472.39453125,0.000226011100569555,5.75455241771401E-7,1,0.999253354069792,40.0298881530762,1.98207442622261,14.2400003969669,0.00253679551620891,0.000464865476226479,0.25,6.91285895143838E-7,0.000226323594901402,2.34135871438246E-6,5.0508,5.0508,-77474.7421875,-77470.046875,54.3739879402942,19.5773630819895,8.482265,0,0,0,40,4449,5.0508,-77472.39453125,,,,,,,,,,,,,0,,,,,,,,,,,,,,
,19685233.15,5.0475,-73629.95703125,0.000212877119260118,6.7326831189713E-7,1,0.999253354069792,40.0298881530762,1.98219903731641,14.2500000074506,0.00238961583316207,0.000433180413237575,0.25,2.32469664048598E-7,0.000213109600481292,1.79769164260045E-6,5.0469,5.0469,-73662.375,-73597.5390625,54.0589916470442,19.5742663421391,8.482265,0,0,0,40,4449,5.0475,-73629.95703125,,,,,,,,,,,,,0,,,,,,,,,,,,,,
,19685309.89,5.0445,-69795.0234375,0.000199808934879595,6.56760364910989E-7,1,0.999253354069792,40.0298881530762,1.98209230486416,14.2400003969669,0.0022405391466237,0.000415059712686198,0.25,9.77231748324882E-7,0.000199957871204062,2.45559657681026E-6,5.0445,5.0445,-69799.9296875,-69790.1171875,54.1449707841596,19.5760601294303,8.861917,0,0,0,40,4449,5.0445,-69795.0234375,,,,,,,,,,,,,0,,,,,,,,,,,,,,
,19685386.22,5.0409,-65979.609375,0.000186848047551858,6.2238402934205E-7,1,0.999253354069792,40.0298881530762,1.98208348302551,14.2400003969669,0.00209517546078623,0.000384268539291624,0.25,5.74532990447785E-7,0.000186927974954777,1.96225172357257E-6,5.0409,5.0409,-65986.9453125,-65972.2734375,54.3114576587558,19.5754870033771,8.861917,0,0,0,40,4449,5.0409,-65979.609375,,,,,,,,,,,,,0,,,,,,,,,,,,,,
,19685461.79,5.0417,-62204.150390625,0.000173988255585067,6.59859849519299E-7,1,0.999253354069792,40.0298881530762,1.98199050834804,14.2400003969669,0.00195035001226051,0.000356980004805562,0.25,4.69059893369186E-7,0.000174003849183876,1.76385428401829E-6,5.0417,5.0417,-62209.32421875,-62198.9765625,54.3036413735634,19.5750565631837,8.482265,0,0,0,40,4449,5.0417,-62204.150390625,,,,,,,,,,,,,0,,,,,,,,,,,,,,
,19685538.515,5.0377,-58369.265625,0.000161896998092176,6.4240082389015E-7,1,0.999253354069792,40.0298881530762,1.98199242003898,14.2400003969669,0.00181399819423689,0.000332954379970401,0.25,5.16470662133614E-7,0.000161852737733498,1.72108839600553E-6,5.0377,5.0377,-58371.91796875,-58366.61328125,54.3911837677173,19.5748211186514,8.482265,0,0,0,40,4449,5.0377,-58369.265625,,,,,,,,,,,,,0,,,,,,,,,,,,,,
,19685615.775,5.03445,-54509.185546875,0.000148927876855491,4.17002621984948E-7,1,0.999253354069792,40.0298881530762,1.98191443698024,14.2400003969669,0.00166804572162546,0.000305883815977842,0.25,4.53145468186031E-7,0.000148831623852423,1.55833405237448E-6,5.034,5.034,-54539.15625,-54479.21484375,54.4365182218327,19.5748071145238,8.482265,0,0,0,40,4449,5.03445,-54509.185546875,,,,,,,,,,,,,0,,,,,,,,,,,,,,
,19685690.09,5.0323,-50794.193359375,0.000135142498009983,5.76107222479692E-7,1,0.999253354069792,40.0298881530762,1.98202058468636,14.2400003969669,0.00151436854479153,0.0002707769329247,0.25,-1.82585881932139E-7,0.000135009473937123,8.15725171336116E-7,5.0316,5.0316,-50826.7578125,-50761.62890625,54.1269933282173,19.571885462741,8.482265,0,0,0,40,4449,5.0323,-50794.193359375,,,,,,,,,,,,,0,,,,,,,,,,,,,,
,19685767.405,5.0316,-46931.40234375,0.000121395504449685,5.48062882338383E-7,1,0.999253354069792,40.0298881530762,1.98201255457597,14.2400003969669,0.00135969282651784,0.00024362049819183,0.25,-1.13746110299135E-7,0.000121227711813899,7.75686066376383E-7,5.0318,5.0318,-46934.05078125,-46928.75390625,54.2551804053711,19.5727653102294,8.861917,0,0,0,40,4449,5.0316,-46931.40234375,,,,,,,,,,,,,0,,,,,,,,,,,,,,
,19685844.445,5.0282,-43080.978515625,0.000107866894368296,5.287019042857E-7,1,0.999253354069792,40.0298881530762,1.98199338130795,14.2400003969669,0.00120809655075668,0.000214002355804492,0.25,-3.04887305637514E-7,0.000107676003398706,4.76788876519183E-7,5.0282,5.0282,-43105.88671875,-43056.0703125,54.1309014708134,19.5750946944307,8.482265,0,0,0,40,4449,5.0282,-43080.978515625,,,,,,,,,,,,,0,,,,,,,,,,,,,,
,19685921.04,5.02455,-39253.36328125,9.48061998481089E-5,4.77761513296261E-7,1,0.999253354069792,40.0298881530762,1.98203297586537,14.2400003969669,0.00106115572891527,0.000189418907606609,0.25,-1.32774278880954E-7,9.45991391225313E-5,5.43814679814694E-7,5.0243,5.0243,-39257.91015625,-39248.81640625,53.9659778532557,19.5709589796145,8.482265,0,0,0,40,4449,5.02455,-39253.36328125,,,,,,,,,,,,,0,,,,,,,,,,,,,,
,19685997.435,5.0214,-35433.060546875,8.10450346377371E-5,4.60327314103688E-7,1,0.999253354069792,40.0298881530762,1.9820632237198,14.2400003969669,0.00090772909323262,0.000156538694630646,0.25,-5.78685811057542E-7,8.08384087667792E-5,-9.87981734721761E-9,5.0214,5.0214,-35435.63671875,-35430.484375,54.0199102210826,19.5727291348668,8.482265,0,0,0,40,4449,5.0214,-35433.060546875,,,,,,,,,,,,,0,,,,,,,,,,,,,,
,19686072.945,5.022,-31661.0654296875,6.81352660773159E-5,5.04862771389702E-7,1,0.999253354069792,40.0298881530762,1.98191888407802,14.2400003969669,0.00076208646691411,0.00013537546281106,0.25,-1.32999684960518E-7,6.79318327020929E-5,3.33588758222494E-7,5.0214,5.0214,-31693.46875,-31628.662109375,54.2348580638711,19.5727204470216,8.861917,0,0,0,40,4449,5.022,-31661.0654296875,,,,,,,,,,,,,0,,,,,,,,,,,,,,
,19686147.795,5.0216,-27920.6435546875,5.49133705664596E-5,6.5711068643983E-7,1,0.999253354069792,40.0298881530762,1.98194486818691,14.2500000074506,0.000614279617915731,0.000107316070159969,0.25,-2.53683577141252E-7,5.47288367628381E-5,1.12924999326055E-7,5.0206,5.0206,-27925.56640625,-27915.720703125,54.1324647278519,19.5716852878919,8.482265,0,0,0,40,4449,5.0216,-27920.6435546875,,,,,,,,,,,,,0,,,,,,,,,,,,,,
,19686226.1,5.021,-24007.65234375,4.07363494962471E-5,4.3009231626779E-7,1,0.999253354069792,40.0298881530762,1.98197292868259,14.2400003969669,0.00045614569926715,7.60434043776397E-5,0.25,-4.95896673856492E-7,4.05850274562479E-5,-2.31499339154938E-7,5.021,5.021,-24012.673828125,-24002.630859375,54.2567436624096,19.5713950608294,8.482265,0,0,0,40,4449,5.021,-24007.65234375,,,,,,,,,,,,,0,,,,,,,,,,,,,,
,19686300.955,5.01825,-20267.46875,2.77332197959379E-5,3.41021569090862E-7,1,0.999253354069792,40.0298881530762,1.98198871812238,14.2400003969669,0.00031128549085763,4.69613210460836E-5,0.25,-7.60088505577608E-7,2.76224287275793E-5,-5.84579350396474E-7,5.0187,5.0187,-20274.939453125,-20259.998046875,54.1684196397365,19.5699526879282,8.861917,0,0,0,40,4449,5.01825,-20267.46875,,,,,,,,,,,,,0,,,,,,,,,,,,,,
,19686376.92,5.01925,-16469.6533203125,1.40973550543579E-5,3.7752317939974E-7,1,0.999253354069792,40.0298881530762,1.98194472439413,14.2500000074506,0.000158921519211397,1.96609831971197E-5,0.25,-7.59046550799419E-7,1.40380669086595E-5,-6.71585273185756E-7,5.0201,5.0201,-16477.154296875,-16462.15234375,54.0628997896403,19.5694410603432,8.102614,0,0,0,40,4449,5.01925,-16469.6533203125,,,,,,,,,,,,,0,,,,,,,,,,,,,,
,19686451.185,5.0174,-12759.2260742187,8.77646767406197E-7,2.57050095997974E-7,1,0.999253354069792,40.0298881530762,1.98195260547555,14.2400003969669,1.21616436379084E-5,-1.1501968646412E-5,0.25,-1.18705146556264E-6,8.80144457443105E-7,-1.17628404311847E-6,5.0186,5.0186,-12789.16015625,-12729.2919921875,54.1238668141403,19.5721909678574,8.102614,0,0,0,40,4449,5.0174,-12759.2260742187,,,,,,,,,,,,,0,,,,,,,,,,,,,,
,19686529.185,5.01515,-8858.3046875,-1.22949849500518E-5,3.27814238682184E-7,1,0.999253354069792,40.0298881530762,1.98196551303044,14.2500000074506,-0.000135335315079941,-3.49467128668209E-5,0.25,-9.40820735846102E-7,-1.22261977829931E-5,-1.00245715757628E-6,5.0151,5.0151,-8865.62890625,-8850.98046875,54.0167837070057,19.569763240602,8.482265,0,0,0,40,4449,5.01515,-8858.3046875,,,,,,,,,,,,,0,,,,,,,,,,,,,,
,19686603.115,5.0158,-5162.71704101562,-2.5174997678816E-5,3.08650932380842E-7,1,0.999253354069792,40.0298881530762,1.98185930529633,14.2400003969669,-0.000279690119142123,-5.65578394332271E-5,0.25,-5.9083124911367E-7,-2.50346964424993E-5,-7.16990262839573E-7,5.015,5.015,-5197.56640625,-5127.86767578125,54.1074526152365,19.569634940101,8.861917,0,0,0,40,4449,5.0158,-5162.71704101562,,,,,,,,,,,,,0,,,,,,,,,,,,,,
,19686676.045,5.01475,-1516.02709960938,-3.58102759319592E-5,2.65099839736074E-7,1,0.999253354069792,40.0298881530762,1.98194175934272,14.2400003969669,-0.000398038113332037,-7.89548477146004E-5,0.25,-7.1635017393993E-7,-3.56035456488724E-5,-8.8759149767868E-7,5.0152,5.0152,-1543.6611328125,-1488.39306640625,54.7233758883904,19.5706711894433,8.482265,0,0,0,40,4449,5.01475,-1516.02709960938,,,,,,,,,,,,,0,,,,,,,,,,,,,,
,19686745.945,5.01435,1973.54992675781,-3.27208089826428E-5,3.63051537738055E-7,1,0.999253354069792,40.0298881530762,1.98191952011915,14.2400003969669,-0.000364689807658616,-6.65900328325297E-5,0.25,-1.55733205655489E-7,-3.25351491560238E-5,-3.15944583273843E-7,5.0143,5.0143,1941.03723144531,2006.06262207031,54.1793624390057,19.5692227718196,8.102614,0,0,0,40,4449,5.01435,1973.54992675781,,,,,,,,,,,,,0,,,,,,,,,,,,,,
,19686817.925,5.01445,5572.47900390625,-4.34723195560523E-5,3.54646065967757E-7,1,0.999253354069792,40.0298881530762,1.98186319526377,14.2400003969669,-0.00048360176980138,-9.41994509830479E-5,0.25,-7.0814204390866E-7,-4.3232856288725E-5,-9.28993861392601E-7,5.0151,5.0151,5539.85986328125,5605.09814453125,53.8948496580057,19.5703319763012,8.861917,0,0,0,40,4449,5.01445,5572.47900390625,,,,,,,,,,,,,0,,,,,,,,,,,,,,
,19686892.525,5.0146,9298.51123046875,-5.48023302174067E-5,2.94568543491579E-7,1,0.999253354069792,40.0298881530762,1.98183529855673,14.2500000074506,-0.000610687497791205,-0.000113809247221101,0.25,-4.32133605668773E-7,-5.45179599260287E-5,-7.28152155911379E-7,5.0157,5.0157,9263.6103515625,9333.412109375,53.7424320967557,19.5711911218962,8.861917,0,0,0,40,4449,5.0146,9298.51123046875,,,,,,,,,,,,,0,,,,,,,,,,,,,,
,19686968.235,5.01415,13083.6953125,-6.44104199478736E-5,3.61215749250742E-7,1,0.999253354069792,40.0298881530762,1.98185994852513,14.2400003969669,-0.000717803975564541,-0.000134850967011611,0.25,-5.83588146445638E-7,-6.40959261753778E-5,-9.49204708003619E-7,5.0141,5.0141,13081.2236328125,13086.1669921875,54.0019327651403,19.5719198547332,8.102614,0,0,0,40,4449,5.01415,13083.6953125,,,,,,,,,,,,,0,,,,,,,,,,,,,,
,19687039.69,5.0148,16654.5263671875,-7.17131512185372E-5,3.06449949222027E-7,1,0.999253354069792,40.0298881530762,1.98178266088506,14.2400003969669,-0.000799610926373808,-0.00014908656748206,0.25,-5.3346603346592E-7,-7.13865807060046E-5,-9.59413692695152E-7,5.0153,5.0153,16619.478515625,16689.57421875,54.2528355198134,19.570583603094,8.482265,0,0,0,40,4449,5.0148,16654.5263671875,,,,,,,,,,,,,0,,,,,,,,,,,,,,
,19687112.19,5.0152,20277.41015625,-7.57727512208367E-5,3.41915958590829E-7,1,0.999253354069792,40.0298881530762,1.9817122008967,14.2400003969669,-0.000844159839216192,-0.000163050810027747,0.25,-1.03569806382638E-6,-7.54507790000501E-5,-1.50231009078528E-6,5.0141,5.0141,20242.4140625,20312.40625,53.8073072638518,19.5705433165323,8.861917,0,0,0,40,4449,5.0152,20277.41015625,,,,,,,,,,,,,0,,,,,,,,,,,,,,
,19687184.645,5.017,23898.2109375,-7.72302879016212E-5,3.43778155826193E-7,1,0.999253354069792,40.0298881530762,1.98167695326582,14.2400003969669,-0.000862479390878553,-0.000156276887687662,0.25,-1.462978897213E-7,-7.69355472427075E-5,-6.42939259622867E-7,5.0177,5.0177,23895.83984375,23900.58203125,54.0058409077365,19.5716792837118,8.482265,0,0,0,40,4449,5.017,23898.2109375,,,,,,,,,,,,,0,,,,,,,,,,,,,,
,19687259.64,5.0168,27649.4501953125,-7.91363069148793E-5,4.24192314499244E-7,1,0.999253354069792,40.0298881530762,1.98163831676737,14.2400003969669,-0.000884707958933273,-0.000156754095643012,0.25,1.74155558079541E-7,-7.8866865914221E-5,-3.52405532705122E-7,5.0168,5.0168,27644.2890625,27654.611328125,54.0761874744673,19.5702656975433,8.482265,0,0,0,40,4449,5.0168,27649.4501953125,,,,,,,,,,,,,0,,,,,,,,,,,,,,
,19687334.64,5.01845,31397.0859375,-8.27397865374814E-5,4.0214371842288E-7,1,0.999253354069792,40.0298881530762,1.98166804347306,14.2400003969669,-0.000924572549478533,-0.000168410928100196,0.25,-2.01100526109684E-7,-8.24879652091325E-5,-7.65614399988654E-7,5.018,5.018,31392.091796875,31402.080078125,53.9151719995057,19.5708106380487,8.482265,0,0,0,40,4449,5.01845,31397.0859375,,,,,,,,,,,,,0,,,,,,,,,,,,,,
,19687406.93,5.0181,35010.287109375,-8.90938907483031E-5,4.31832379042838E-7,1,0.999253354069792,40.0298881530762,1.98168630365316,14.2400003969669,-0.000995622627882489,-0.000183334866229579,0.25,-3.74703670712172E-7,-8.88556756530499E-5,-9.95894199477298E-7,5.018,5.018,34980.22265625,35040.3515625,53.7103853274672,19.5671094961003,8.102614,0,0,0,40,4449,5.0181,35010.287109375,,,,,,,,,,,,,0,,,,,,,,,,,,,,
,19687481.455,5.0219,38732.900390625,-9.73087186921034E-5,5.7477452337674E-7,1,0.999253354069792,40.0298881530762,1.98187903928978,14.2400003969669,-0.00108749288467476,-0.000202908512833485,0.25,-6.26336557014969E-7,-9.708539459268E-5,-1.31745424126021E-6,5.0219,5.0219,38728.22265625,38737.578125,53.7189832411788,19.5676179751588,8.861917,0,0,0,40,4449,5.0219,38732.900390625,,,,,,,,,,,,,0,,,,,,,,,,,,,,
,19687554.18,5.0212,42366.1171875,-0.000107729730178956,5.55194664259674E-7,1,0.999253354069792,40.0298881530762,1.98174046224835,14.2400003969669,-0.00120267757157752,-0.00023393183879086,0.25,-1.50618534865409E-6,-0.000107517905085496,-2.28154363145883E-6,5.0214,5.0214,42336.1484375,42396.0859375,54.2536171483327,19.5653093017795,8.482265,0,0,0,40,4449,5.0212,42366.1171875,,,,,,,,,,,,,0,,,,,,,,,,,,,,
,19687628.46,5.02205,46079.591796875,-0.000118607073866108,5.26659409972668E-7,1,0.999253354069792,40.0298881530762,1.98163267254116,14.2500000074506,-0.00132751500774918,-0.000241209157910476,0.25,-1.80964418329163E-7,-0.000118430542945307,-1.04759352832525E-6,5.0221,5.0221,46074.53515625,46084.6484375,53.9292413128519,19.5668943075947,8.482265,0,0,0,40,4449,5.02205,46079.591796875,,,,,,,,,,,,,0,,,,,,,,,,,,,,
,19687700.42,5.0252,49677.81640625,-0.000129974686793742,5.24228964193047E-7,1,0.999253354069792,40.0298881530762,1.98172114959089,14.2500000074506,-0.00145435860636546,-0.000269931817193492,0.25,-6.81278903778865E-7,-0.000129825720943727,-1.63852528367006E-6,5.0252,5.0252,49672.7734375,49682.859375,54.1246484426596,19.564993827794,8.861917,0,0,0,40,4449,5.0252,49677.81640625,,,,,,,,,,,,,0,,,,,,,,,,,,,,
,19687774.375,5.02745,53373.189453125,-0.000142753617643229,4.59861924574589E-7,1,0.999253354069792,40.0298881530762,1.98171140067922,14.2400003969669,-0.00159879572747631,-0.000291808648394065,0.25,-3.16663574302562E-7,-0.000142646203479441,-1.37474816594777E-6,5.0258,5.0258,53345.78125,53400.59765625,53.9831736806788,19.5654049147001,8.102614,0,0,0,40,4449,5.02745,53373.189453125,,,,,,,,,,,,,0,,,,,,,,,,,,,,
,19687848.355,5.0306,57070.919921875,-0.000155639508818986,5.13346620266678E-7,1,0.999253354069792,40.0298881530762,1.98174978495192,14.2500000074506,-0.00174122398697016,-0.000332436253499035,0.25,-1.6058311258837E-6,-0.000155569335657489,-2.76277605764407E-6,5.0306,5.0306,57068.359375,57073.48046875,54.1520054408327,19.5678068663073,8.102614,0,0,0,40,4449,5.0306,57070.919921875,,,,,,,,,,,,,0,,,,,,,,,,,,,,
,19687922.07,5.0319,60754.2421875,-0.000167158940256197,7.28529192016621E-7,1,0.999253354069792,40.0298881530762,1.98169803252021,14.2400003969669,-0.00187250921085195,-0.000347148878800464,0.25,-8.31464935499709E-7,-0.000167148628398298,-2.07569895022801E-6,5.03,5.03,60721.6875,60786.796875,54.0980730730057,19.5634116016943,8.102614,0,0,0,40,4449,5.0319,60754.2421875,,,,,,,,,,,,,0,,,,,,,,,,,,,,
,19687993.93,5.03365,64348.078125,-0.000179461465268682,5.37822813402849E-7,1,0.999253354069792,40.0298881530762,1.98163596245722,14.2400003969669,-0.0020104048834937,-0.000375690039999968,0.25,-1.15155019484761E-6,-0.000179507619855774,-2.48607872936677E-6,5.0337,5.0337,64315.38671875,64380.76953125,53.8729640594672,19.5651138187823,8.482265,0,0,0,40,4449,5.03365,64348.078125,,,,,,,,,,,,,0,,,,,,,,,,,,,,
,19688069.08,5.0374,68103.703125,-0.00019115423092347,6.39596866392128E-7,1,0.999253354069792,40.0298881530762,1.98172427835762,14.2400003969669,-0.00214241975989963,-0.000399062116311692,0.25,-1.11973194933377E-6,-0.00019126761497316,-2.53695172400634E-6,5.0374,5.0374,68103.703125,68103.703125,53.7393055826788,19.5657938261962,8.482265,0,0,0,40,4449,5.0374,68103.703125,,,,,,,,,,,,,0,,,,,,,,,,,,,,
,19688144.235,5.0391,71858.68359375,-0.000204058898935584,5.5206101722341E-7,1,0.999253354069792,40.0298881530762,1.98170919535688,14.2400003969669,-0.00228493605123001,-0.000441826686950309,0.25,-2.60154199597151E-6,-0.00020423454417959,-4.10857689813635E-6,5.0391,5.0391,71856.3828125,71860.984375,54.2395478349865,19.562889069288,8.861917,0,0,0,40,4449,5.0391,71858.68359375,,,,,,,,,,,,,0,,,,,,,,,,,,,,
,19688217.37,5.0428,75514.7890625,-0.000216385313815784,4.82986244737991E-7,1,0.999253354069792,40.0298881530762,1.98159313974582,14.2400003969669,-0.00242328485257481,-0.000470064525642755,0.25,-2.89729637372984E-6,-0.000216634884828163,-4.48613071533247E-6,5.0426,5.0426,75484.5859375,75544.9921875,53.841698918698,19.5634413627239,8.482265,0,0,0,40,4449,5.0428,75514.7890625,,,,,,,,,,,,,0,,,,,,,,,,,,,,
,19688294.585,5.0436,79373.36328125,-0.000229350268262125,4.69923256617121E-7,1,0.999253354069792,40.0298881530762,1.9816844216371,14.2400003969669,-0.0025688452269447,-0.000501256984063251,0.25,-3.33959687480869E-6,-0.000229681607803796,-5.01115764941763E-6,5.0439,5.0439,79368.1796875,79378.546875,54.2121908368134,19.5611409605985,8.102614,0,0,0,40,4449,5.0436,79373.36328125,,,,,,,,,,,,,0,,,,,,,,,,,,,,
,19688366.01,5.04735,82944.87109375,-0.000240872235483486,6.45050403446275E-7,1,0.999253354069792,40.0298881530762,1.98161867383999,14.2400003969669,-0.00269942220446841,-0.000521571985366583,0.25,-3.07902284206595E-6,-0.00024128711106275,-4.81932461698967E-6,5.0482,5.0482,82912.3046875,82977.4375,54.3083311446788,19.5643660070427,8.482265,0,0,0,40,4449,5.04735,82944.87109375,,,,,,,,,,,,,0,,,,,,,,,,,,,,
,19688437.275,5.0505,86508.3515625,-0.000252401817302903,6.83566726723639E-7,1,0.999253354069792,40.0298881530762,1.98152711928664,14.2400003969669,-0.00283024042892179,-0.000540969946970946,0.25,-2.7389681470593E-6,-0.000252903675638016,-4.54460771510886E-6,5.0499,5.0499,86505.8125,86510.890625,54.1277749567365,19.5644928780163,8.482265,0,0,0,40,4449,5.0505,86508.3515625,,,,,,,,,,,,,0,,,,,,,,,,,,,,
,19688507.72,5.051,89998.64453125,-0.000264553226434873,5.56902770582824E-7,1,0.999253354069792,40.0298881530762,1.98153140815187,14.2400003969669,-0.0029660336632389,-0.00057362598282654,0.25,-3.46735530357778E-6,-0.00026513732471161,-5.34227638531682E-6,5.0501,5.0501,89997.7734375,89999.515625,54.2966067168904,19.5615168454862,8.482265,0,0,0,40,4417,5.051,89998.64453125,,,,,,,,,,,,,0,,,,,,,,,,,,,,