File: data/monolayers/magneticStructure/ML_Ac_CoFe_C/PPMS/data/DD205_4_HYST_100OE_250K.DAT
[Header]
; VSM Data File (default extension .dat)
; Copyright (c) 2003-2013, Quantum Design, Inc. All rights reserved.
TITLE,
FILEOPENTIME,32415065.52,01/11/2019,12:13 pm
BYAPP,VSM,2.0,2.0
INFO,PPMS VSM Option Release 1.4.10 Build 1,APPNAME
INFO,Quantum Design Linear Motor Servo Controller,MOTOR_MODULE_NAME
INFO,3101-100 M1,MOTOR_HW_VERSION
INFO,MMC1014,MOTOR_SERIAL_NUMBER
INFO,SRV No X-over 01.03.11,MOTOR_SOFTWARE_VERSION
INFO,Quantum Design VSM Detection Module,VSM_MODULE_NAME
INFO,3101-150 F0,VSM_HW_VERSION
INFO,VSM707,VSM_SERIAL_NUMBER
INFO,VSM No X-over 01.02.05 May 20 2008 13:51:47,VSM_SOFTWARE_VERSION
INFO,704,PREAMP_SERIAL_NUMBER
INFO,822,COIL_SERIAL_NUMBER
INFO,0,MOMENT_UNITS
INFO,DD205_4,SAMPLE_MATERIAL
INFO,Monolayer,SAMPLE_COMMENT
INFO,29.55,SAMPLE_MASS
INFO,,SAMPLE_VOLUME
INFO,,SAMPLE_MOLECULAR_WEIGHT
INFO,,SAMPLE_SIZE
INFO,,SAMPLE_SHAPE
DATATYPE,COMMENT,1
DATATYPE,TIME,2
STARTUPAXIS,X,2
STARTUPAXIS,Y1,5
[Data]
Comment,Time Stamp (sec),Temperature (K),Magnetic Field (Oe),Moment (emu),M. Std. Err. (emu),Transport Action,Averaging Time (sec),Frequency (Hz),Peak Amplitude (mm),Center Position (mm),Coil Signal' (mV),Coil Signal" (mV),Range (mV),M. Quad. Signal (emu),M. Raw' (emu),M. Raw" (emu),Min. Temperature (K),Max. Temperature (K),Min. Field (Oe),Max. Field (Oe),Mass (grams),Motor Lag (deg),Pressure (Torr),VSM Status (code),Motor Status (code),Measure Status (code),Measure Count,PPMS Status (code),System Temp. (K),System Field (Oe),Sample Position (deg),Bridge 1 Resistance (ohms),Bridge 1 Excitation (에),Bridge 2 Resistance (ohms),Bridge 2 Excitation (에),Bridge 3 Resistance (ohms),Bridge 3 Excitation (에),Bridge 4 Resistance (ohms),Bridge 4 Excitation (에),Signal 1 Vin (V),Signal 2 Vin (V),Digital Inputs (code),Drive 1 Iout (mA),Drive 1 Ipower (W),Drive 2 Iout (mA),Drive 2 Ipower (W),Pressure (),Map 20 (),Map 21 (),Map 22 (),Map 23 (),Map 24 (),Map 25 (),Map 26 (),Map 27 (),Map 28 (),Map 29 ()
,32415081.63,249.9964142,-0.304475486278534,,,2,,,,20.169999986887,,,,,,,249.9964142,249.9964142,-0.304475486278534,-0.304475486278534,,,27.844467,,,,-99999999,4369,250.0347,-0.304475486278534,,,,,,,,,,,,,,,,,,,,,,,249.9964142,,,,
,32415225.735,249.9826355,4441.56860351562,2.01557042680621E-5,4.64753974417725E-7,1,0.999253354069792,40.0298881530762,1.98459081179213,20.1600007712841,0.000227916224372575,3.38672437442448E-5,0.25,-4.87912354136746E-7,2.01914840056944E-5,-4.72117232015052E-7,249.9826355,249.9826355,4436.4521484375,4446.68505859375,56.5133051974291,20.4956937859541,27.085165,0,0,0,40,4449,250.0558,4441.56860351562,,,,,,,,,,,,,0,,,,0,,,,,,249.9826355,,,,
,32415320.095,249.9827118,9155.3837890625,9.73529779589528E-6,4.9587902350697E-7,1,0.999253354069792,40.0298881530762,1.98457266626427,20.1600007712841,0.000111177838792299,1.00484977536778E-5,0.25,-7.95971978044607E-7,9.75304270450875E-6,-7.89334999062465E-7,249.9827118,249.9827118,9142.8583984375,9167.9091796875,56.5547315089483,20.4990494801448,27.464817,0,0,0,40,4449,250.07585,9155.3837890625,,,,,,,,,,,,,0,,,,0,,,,,,249.9827118,,,,
,32415416.52,249.9839172,13977.72265625,-4.52132329087959E-6,6.93829830470865E-7,1,0.999253354069792,40.0298881530762,1.98464745238612,20.1600007712841,-4.73700133270987E-5,-2.92638526795419E-5,0.25,-1.81462564439254E-6,-4.5277638923082E-6,-1.82153786167035E-6,249.9839172,249.9839172,13975.2802734375,13980.1650390625,56.6852634716598,20.5008638195579,27.085165,0,0,0,40,4449,250.0842,13977.72265625,,,,,,,,,,,,,0,,,,0.0049,,,,,,249.9839172,,,,
,32415512.78,249.9887543,18787.8466796875,-2.11976880746984E-5,1.02201899793544E-6,1,0.999253354069792,40.0298881530762,1.98450090336786,20.1600007712841,-0.000235555069227158,-5.94501924438092E-5,0.25,-1.60358617365708E-6,-2.12335754515021E-5,-1.62385307953282E-6,249.9887543,249.9887543,18782.830078125,18792.86328125,57.0182372208522,20.5068332883093,27.085165,0,0,0,40,4449,250.0892,18787.8466796875,,,,,,,,,,,,,0,,,,-0.00245,,,,,,249.9887543,,,,
,32415609.93,249.9929352,23642.7001953125,-3.60317533269093E-5,1.00712107936059E-6,1,0.999253354069792,40.0298881530762,1.98457931729324,20.1600007712841,-0.000399864168577485,-0.000104208980118782,0.25,-3.00572081456482E-6,-3.60925261770638E-5,-3.04062340487087E-6,249.9929352,249.9929352,23640.265625,23645.134765625,56.6602513590445,20.503827834127,27.464817,0,0,0,40,4449,250.09535,23642.7001953125,,,,,,,,,,,,,0,,,,-0.00245,,,,,,249.9929352,,,,
,32415707.63,249.9956665,28525.513671875,-5.40038299078996E-5,1.43841584600924E-6,1,0.999253354069792,40.0298881530762,1.98452843153169,20.1600007712841,-0.000602885735203913,-0.000135480960000777,0.25,-2.6664696934675E-6,-5.40964311803718E-5,-2.71549541538794E-6,249.9953766,249.9959564,28523.037109375,28527.990234375,56.7728058658137,20.5049890421018,27.464817,0,0,0,40,4449,250.0962,28525.513671875,,,,,,,,,,,,,0,,,,0,,,,,,249.9956665,,,,
,32415802.36,249.9952393,33258.458984375,-6.97078807576494E-5,1.51162349742214E-6,1,0.999253354069792,40.0298881530762,1.98448016428372,20.1600007712841,-0.000780024798160864,-0.000164259666993704,0.25,-2.49926438991695E-6,-6.98281961995972E-5,-2.56081716024889E-6,249.9952393,249.9952393,33255.99609375,33260.921875,56.8689461736791,20.5067945049081,27.085165,0,0,0,40,4449,250.0942,33258.458984375,,,,,,,,,,,,,0,,,,0,,,,,,249.9952393,,,,
,32415897.735,250.0025482,38025.783203125,-8.47053460811382E-5,1.62975449053002E-6,1,0.999253354069792,40.0298881530762,1.98434560315636,20.1600007712841,-0.000949366003328936,-0.000190461872040305,0.25,-2.22663233666644E-6,-8.48522027409562E-5,-2.2999090795341E-6,250.0025482,250.0025482,38023.296875,38028.26953125,56.9346029692945,20.5086096751699,27.844467,0,0,0,40,4449,250.0972,38025.783203125,,,,,,,,,,,,,0,,,,0,,,,,,250.0025482,,,,
,32415992.46,250.0098724,42760.853515625,-0.000100209444811092,1.98686122408482E-6,1,0.999253354069792,40.0298881530762,1.98439958998366,20.1600007712841,-0.00112366153010932,-0.000222453697540141,0.25,-2.37892779614982E-6,-0.000100383379308268,-2.4650572627082E-6,250.0098724,250.0098724,42755.8828125,42765.82421875,56.7251265261406,20.5079531132145,27.464817,0,0,0,40,4449,250.0889,42760.853515625,,,,,,,,,,,,,0,,,,0,,,,,,250.0098724,,,,
,32416086.445,250.0071716,47459.0703125,-0.000118902235765822,1.91221028670652E-6,1,0.999253354069792,40.0298881530762,1.98449543403485,20.1600007712841,-0.00133048738561927,-0.000280342523354795,0.25,-4.27758754840383E-6,-0.000119107456862,-4.38220366338994E-6,250.0071716,250.0071716,47448.89453125,47469.24609375,56.9189703989099,20.5056742119552,27.464817,0,0,0,40,4449,250.0822,47459.0703125,,,,,,,,,,,,,0,,,,-0.00245,,,,,,250.0071716,,,,
,32416182.435,250.0070038,52256.333984375,-0.000134613118238979,1.63118523202268E-6,1,0.999253354069792,40.0298881530762,1.98423159604334,20.1600007712841,-0.00150981556845686,-0.000295903586863908,0.25,-2.93853209081653E-6,-0.000134847033012399,-3.05346930818024E-6,250.0070038,250.0070038,52251.41796875,52261.25,56.6985511564868,20.5104199237795,27.464817,0,0,0,40,4449,250.0792,52256.333984375,,,,,,,,,,,,,0,,,,0.0049,,,,,,250.0070038,,,,
,32416278.335,250.0095978,57048.630859375,-0.000151754090749261,2.56443806725021E-6,1,0.999253354069792,40.0298881530762,1.98443133434301,20.1600007712841,-0.00170373948273337,-0.000324920631912073,0.25,-2.54075596736665E-6,-0.000152018429354291,-2.66879488864518E-6,250.0095978,250.0095978,57043.64453125,57053.6171875,56.9072459711214,20.5059823708675,27.464817,0,0,0,40,4449,250.0691,57048.630859375,,,,,,,,,,,,,0,,,,0,,,,,,250.0095978,,,,
,32416374.945,250.0075989,61879.37890625,-0.00016554489623198,2.60370162769356E-6,1,0.999253354069792,40.0298881530762,1.98440591351131,20.1600007712841,-0.00185411551126468,-0.000379993791756289,0.25,-5.04103164319614E-6,-0.000165831448927674,-5.18449077226626E-6,250.0075989,250.0075989,61871.69921875,61887.05859375,56.9611783389483,20.5073703457684,27.085165,0,0,0,40,4449,250.0605,61879.37890625,,,,,,,,,,,,,0,,,,0,,,,,,250.0075989,,,,
,32416471.975,250.0077362,66729.7109375,-0.000184084608589217,2.26954279168142E-6,1,0.999253354069792,40.0298881530762,1.98433745295822,20.1600007712841,-0.00206221385602033,-0.000419539054174146,0.25,-5.33961787059492E-6,-0.00018440350019502,-5.4984480732579E-6,250.0077362,250.0077362,66725.109375,66734.3125,56.9517987967176,20.5089237124217,27.464817,0,0,0,40,4449,250.055,66729.7109375,,,,,,,,,,,,,0,,,,0,,,,,,250.0077362,,,,
,32416566.25,250.0102539,71440.06640625,-0.000203880323806893,3.09547107464092E-6,1,0.999253354069792,40.0298881530762,1.98452254466273,20.1600007712841,-0.00228505460172462,-0.000459650686630414,0.25,-5.46599962717342E-6,-0.000204233887318364,-5.64087314366388E-6,250.0102539,250.0102539,71432.953125,71447.1796875,56.9197520274291,20.5054090361764,27.085165,0,0,0,40,4449,250.05155,71440.06640625,,,,,,,,,,,,,0,,,,0.0049,,,,,,250.0102539,,,,
,32416660.43,250.0116577,76148.4765625,-0.000216687417712148,3.24806997208721E-6,1,0.999253354069792,40.0298881530762,1.98452714158259,20.1600007712841,-0.00242589592987358,-0.000504118603411963,0.25,-7.19441211944029E-6,-0.000217062095266463,-7.38243804454846E-6,250.0116577,250.0116577,76141.078125,76155.875,57.0401228193907,20.5049680621108,27.464817,0,0,0,40,4449,250.0435,76148.4765625,,,,,,,,,,,,,0,,,,0.00245,,,,,,250.0116577,,,,
,32416757.645,250.0138397,81006.68359375,-0.000232648966236829,3.12887030292195E-6,1,0.999253354069792,40.0298881530762,1.98433219607009,20.1600007712841,-0.00261158660956031,-0.000499454417918755,0.25,-4.01677310344934E-6,-0.000233054263747934,-4.21184263359634E-6,250.0138397,250.0138397,81004.203125,81009.1640625,56.9697762526599,20.5068967852627,27.844467,0,0,0,40,4449,250.0349,81006.68359375,,,,,,,,,,,,,0,,,,0,,,,,,250.0138397,,,,
,32416853.515,250.0115356,85802.25390625,-0.000253096703073002,2.71777599531168E-6,1,0.999253354069792,40.0298881530762,1.98435344006027,20.1600007712841,-0.00283829215496518,-0.000559844918568723,0.25,-5.83446024345498E-6,-0.000253536502047346,-6.04892924734754E-6,250.0115356,250.0115356,85797.2890625,85807.21875,57.0604451608906,20.5070826263016,27.464817,0,0,0,40,4449,250.0237,85802.25390625,,,,,,,,,,,,,0,,,,0.00245,,,,,,250.0115356,,,,
,32416960.57,250.0141144,89794.70703125,-0.000270360873351697,3.60143662255782E-6,1,0.999253354069792,40.0298881530762,1.98430254720184,20.1600007712841,-0.0030312009612543,-0.000601604958436133,0.25,-6.55128250791443E-6,-0.000270830427670343,-6.78065654806334E-6,250.0141144,250.0141144,89787.234375,89802.1796875,57.0291800201214,20.5080861251532,27.464817,0,0,0,40,4449,250.01315,89794.70703125,,,,,,,,,,,,,0,,,,0,,,,,,250.0141144,,,,
,32417052.47,250.0039063,85206.7734375,-0.00024771398506149,3.10293907031129E-6,1,0.999253354069792,40.0298881530762,1.98438455803105,20.1600007712841,-0.0027862507607838,-0.000500200548695599,0.25,-1.46977207426174E-6,-0.000248147913913558,-1.67228393507175E-6,250.0039063,250.0039063,85204.125,85209.421875,56.8236117195637,20.5083745350432,27.464817,0,0,0,40,4449,250.0117,85206.7734375,,,,,,,,,,,,,0,,,,-0.00245,,,,,,250.0039063,,,,
,32417145.945,250.0016937,80533.1015625,-0.000235149522938552,2.4901473471456E-6,1,0.999253354069792,40.0298881530762,1.9843445431234,20.1600007712841,-0.00263919188630971,-0.000507601547923694,0.25,-4.30642020082188E-6,-0.000235559072791174,-4.50407315920974E-6,250.0016937,250.0016937,80525.4765625,80540.7265625,57.0323065341983,20.5100800895637,27.844467,0,0,0,40,4449,250.00995,80533.1015625,,,,,,,,,,,,,0,,,,-0.00245,,,,,,250.0016937,,,,
,32417243.585,249.996048,75653.66796875,-0.000217630226158672,2.90667488817397E-6,1,0.999253354069792,40.0298881530762,1.98416441279311,20.1600007712841,-0.0024346724232934,-0.00051403476549243,0.25,-7.91945628992574E-6,-0.000218006086324734,-8.10957330323924E-6,249.9953766,249.9967194,75645.90625,75661.4296875,56.8744175733137,20.5112761461339,27.464817,0,0,0,40,4449,250.0171,75653.66796875,,,,,,,,,,,,,0,,,,0.0049,,,,,,249.996048,,,,
,32417340.485,249.9922333,70810.59375,-0.000202374092847761,2.13893076542291E-6,1,0.999253354069792,40.0298881530762,1.98427140525131,20.1600007712841,-0.00226919499957445,-0.000448733480470962,0.25,-4.76239735471994E-6,-0.000202725705457086,-4.9348675924998E-6,249.9922333,249.9922333,70802.8671875,70818.3203125,56.9783741663714,20.5113313367252,27.464817,0,0,0,40,4449,250.0301,70810.59375,,,,,,,,,,,,,0,,,,0,,,,,,249.9922333,,,,
,32417436.6,249.9911652,66004.9921875,-0.000184455442036486,2.46204236243748E-6,1,0.999253354069792,40.0298881530762,1.98433121819325,20.1600007712841,-0.00206311044541519,-0.000439139855054085,0.25,-7.01623315439442E-6,-0.000184773725529502,-7.17836077173127E-6,249.9911652,249.9911652,66000.046875,66009.9375,56.7188734979868,20.5088550776714,27.464817,0,0,0,40,4449,250.0359,66004.9921875,,,,,,,,,,,,,0,,,,0,,,,,,249.9911652,,,,
,32417531.985,249.9835052,61236.76953125,-0.000170099428154187,2.59933250573963E-6,1,0.999253354069792,40.0298881530762,1.98462803447646,20.1600007712841,-0.00190680134009239,-0.000382016654434242,0.25,-4.42717803500429E-6,-0.000170394617072744,-4.57330893553926E-6,249.9835052,249.9835052,61226.6484375,61246.890625,57.0721695886791,20.5067043214473,27.464817,0,0,0,40,4449,250.03885,61236.76953125,,,,,,,,,,,,,0,,,,0.0049,,,,,,249.9835052,,,,
,32417627.07,249.9849854,56483.923828125,-0.000151067963939365,2.43941707601001E-6,1,0.999253354069792,40.0298881530762,1.98430264216751,20.1600007712841,-0.00169260103823712,-0.000342644168552344,0.25,-4.2356427125817E-6,-0.000151329846504946,-4.36613157831849E-6,249.9849854,249.9849854,56478.87890625,56488.96875,57.0487207331022,20.5114238946746,27.844467,0,0,0,40,4449,250.0557,56483.923828125,,,,,,,,,,,,,0,,,,-0.0049,,,,,,249.9849854,,,,
,32417723.855,249.9929657,51646.060546875,-0.000133357817302405,2.29526663542722E-6,1,0.999253354069792,40.0298881530762,1.98433382927236,20.1600007712841,-0.00148862876429639,-0.00033457215192698,0.25,-6.58930102156629E-6,-0.00013358661340291,-6.70965538642866E-6,249.9929657,249.9929657,51641.078125,51651.04296875,56.9713395096983,20.5126029683799,27.085165,0,0,0,40,4449,250.06295,51646.060546875,,,,,,,,,,,,,0,,,,-0.0049,,,,,,249.9929657,,,,
,32417819.99,249.9886169,46840.90625,-0.000115890670190768,1.80876531080697E-6,1,0.999253354069792,40.0298881530762,1.98425695072687,20.1600007712841,-0.00129630222918262,-0.000275162288063123,0.25,-4.34255420822352E-6,-0.000116090625374827,-4.44484988177707E-6,249.9886169,249.9886169,46833.5,46848.3125,57.3738781971022,20.5145379196039,27.464817,0,0,0,40,4449,250.07215,46840.90625,,,,,,,,,,,,,0,,,,-0.00245,,,,,,249.9886169,,,,
,32417913.905,249.9924164,42148.14453125,-0.000101278296261106,1.73639588130213E-6,1,0.999253354069792,40.0298881530762,1.98433116910934,20.1600007712841,-0.00113293188601942,-0.000240262125050021,0.25,-3.77587703202466E-6,-0.000101453024217699,-3.86535614991143E-6,249.9924164,249.9924164,42140.77734375,42155.51171875,57.2402197203138,20.511896691478,27.085165,0,0,0,40,4449,250.0728,42148.14453125,,,,,,,,,,,,,0,,,,-0.00245,,,,,,249.9924164,,,,
,32418006.815,249.9888916,37502.70703125,-8.33744819569961E-5,1.51123057694512E-6,1,0.999253354069792,40.0298881530762,1.98423513420055,20.1600007712841,-0.000933937391325661,-0.000190130540161388,0.25,-2.42887626404696E-6,-8.35188754689285E-5,-2.5014346883681E-6,249.9888916,249.9888916,37497.84375,37507.5703125,57.0698247031214,20.5140624648991,27.844467,0,0,0,40,4449,250.0816,37502.70703125,,,,,,,,,,,,,0,,,,-0.00245,,,,,,249.9888916,,,,
,32418103.495,249.9909973,32672.958984375,-6.72011406128784E-5,1.65783436370606E-6,1,0.999253354069792,40.0298881530762,1.9841507974025,20.1600007712841,-0.000752217146585455,-0.000156242239573475,0.25,-2.2241404285837E-6,-6.73172902941437E-5,-2.28316340786601E-6,249.9909973,249.9909973,32665.501953125,32680.416015625,57.251162519583,20.5166791243061,27.464817,0,0,0,40,4449,250.09645,32672.958984375,,,,,,,,,,,,,0,,,,-0.00245,,,,,,249.9909973,,,,
,32418198.4,249.98647305,27928.11328125,-5.09771713588358E-5,1.31570109202916E-6,1,0.999253354069792,40.0298881530762,1.98422616820633,20.1600007712841,-0.000570037438409183,-0.000121969169569139,0.25,-1.99296019909039E-6,-5.10650289493955E-5,-2.0383249572745E-6,249.9864349,249.9865112,27923.16796875,27933.05859375,57.0080760501022,20.5166806196269,27.844467,0,0,0,40,4449,250.101,27928.11328125,,,,,,,,,,,,,0,,,,0,,,,,,249.98647305,,,,
,32418294.6,249.9880371,23120.6845703125,-3.46671772136261E-5,1.08555014480652E-6,1,0.999253354069792,40.0298881530762,1.98414042668441,20.1600007712841,-0.000385073582768095,-9.77382787403453E-5,0.25,-2.66955985998653E-6,-3.47258370910899E-5,-2.70275237337903E-6,249.9880371,249.9880371,23115.75390625,23125.615234375,56.5476968522752,20.5177449961902,27.844467,0,0,0,40,4449,250.1133,23120.6845703125,,,,,,,,,,,,,0,,,,0,,,,,,249.9880371,,,,
,32418389.865,249.9913483,18360.3466796875,-1.87755120564606E-5,9.04351622226218E-7,1,0.999253354069792,40.0298881530762,1.98408730416644,20.1600007712841,-0.000207479553349917,-5.90933049951086E-5,0.25,-1.9929985764922E-6,-1.88068256234125E-5,-2.01195416402355E-6,249.9913483,249.9913483,18352.755859375,18367.9375,56.9471090256022,20.5186058003236,27.464817,0,0,0,40,4449,250.1184,18360.3466796875,,,,,,,,,,,,,0,,,,0,,,,,,249.9913483,,,,
,32418485.305,249.9898834,13588.1723632812,-3.84595118086345E-6,7.50572662957025E-7,1,0.999253354069792,40.0298881530762,1.98403719496963,20.1600007712841,-3.8151877910925E-5,-3.71696081222756E-5,0.25,-2.63478115155653E-6,-3.85052971854342E-6,-2.64257537227176E-6,249.9898834,249.9898834,13585.94140625,13590.4033203125,57.1034347294484,20.5204651481892,27.844467,0,0,0,40,4449,250.1299,13588.1723632812,,,,,,,,,,,,,0,,,,0.0049,,,,,,249.9898834,,,,
,32418579.4,249.9934387,8887.62646484375,9.81805941215272E-6,4.73369224437762E-7,1,0.999253354069792,40.0298881530762,1.98416464135592,20.1600007712841,0.000113326886750525,3.06278393958326E-6,0.25,-1.4306481509706E-6,9.83646954660573E-6,-1.42505793502693E-6,249.9934387,249.9934387,8877.6552734375,8897.59765625,56.9783741663714,20.5192696217472,27.464817,0,0,0,40,4449,250.12855,8887.62646484375,,,,,,,,,,,,,0,,,,0.0049,,,,,,249.9934387,,,,
,32418672.675,249.9898987,4224.63891601562,2.01216466353742E-5,4.19510268558061E-7,1,0.999253354069792,40.0298881530762,1.98409373382195,20.1600007712841,0.000227754384248587,3.2200270925968E-5,0.25,-6.2935207436577E-7,2.01574787066493E-5,-6.13839128288699E-7,249.9898987,249.9898987,4219.43505859375,4229.8427734375,56.7180918694675,20.5177956674666,27.844467,0,0,0,40,4449,250.1392,4224.63891601562,,,,,,,,,,,,,0,,,,-0.00245,,,,,,249.9898987,,,,
,32418764.355,249.9949036,-358.553970336914,3.13922539693293E-6,2.63511881921109E-7,1,0.999253354069792,40.0298881530762,1.98405068504799,20.1600007712841,3.64081818953403E-5,-3.00755654781666E-8,0.25,-5.47096005722793E-7,3.14518591288231E-6,-5.45461853124298E-7,249.9949036,249.9949036,-363.560852050781,-353.547088623047,57.2152076076984,20.5202292790969,27.464817,0,0,0,40,4449,250.1405,-358.553970336914,,,,,,,,,,,,,0,,,,0,,,,,,249.9949036,,,,
,32418858.355,250.0004578,-5055.41650390625,-1.79366596189561E-5,5.39161079599285E-7,1,0.999253354069792,40.0298881530762,1.98394360363424,20.1600007712841,-0.000203861574540413,-2.37799939717531E-5,0.25,9.98212747847922E-7,-1.79689551718828E-5,9.85153855063042E-7,250.0004578,250.0004578,-5057.78857421875,-5053.04443359375,57.4622022197753,20.5204034314283,27.464817,0,0,0,40,4449,250.1426,-5055.41650390625,,,,,,,,,,,,,0,,,,0.00245,,,,,,250.0004578,,,,
,32418951.585,250.0053253,-9714.79150390625,-7.12939274065686E-6,6.00007205300255E-7,1,0.999253354069792,40.0298881530762,1.98410761966243,20.1600007712841,-8.13644696408927E-5,-7.56149434721118E-6,0.25,5.64751415212141E-7,-7.14236710858542E-6,5.59861340440388E-7,250.0053253,250.0053253,-9722.5576171875,-9707.025390625,57.1401712698522,20.5207919609483,27.464817,0,0,0,40,4449,250.14415,-9714.79150390625,,,,,,,,,,,,,0,,,,0.00245,,,,,,250.0053253,,,,
,32419044.57,250.0050812,-14362.30859375,6.24883511675397E-6,6.28781611768824E-7,1,0.999253354069792,40.0298881530762,1.98393784466284,20.1600007712841,6.8079006584049E-5,2.52532808121387E-5,0.25,1.15964992018801E-6,6.25884377493814E-6,1.16683382178913E-6,250.0050812,250.0050812,-14364.88671875,-14359.73046875,56.9502355396791,20.522237523255,27.464817,0,0,0,40,4449,250.1371,-14362.30859375,,,,,,,,,,,,,0,,,,-0.00245,,,,,,250.0050812,,,,
,32419141.555,250.0088043,-19209.4384765625,2.26440375344702E-5,9.69446224092806E-7,1,0.999253354069792,40.0298881530762,1.98394504358026,20.1600007712841,0.000251888430104285,6.15948142585676E-5,0.25,1.54469172847039E-6,2.26824968257931E-5,1.56603992630158E-6,250.0088043,250.0088043,-19211.66015625,-19207.216796875,57.2839909173907,20.5226063371812,28.224119,0,0,0,40,4449,250.1235,-19209.4384765625,,,,,,,,,,,,,0,,,,-0.0049,,,,,,250.0088043,,,,
,32419235.935,250.008728,-23926.6376953125,3.80551946459633E-5,1.11985320960575E-6,1,0.999253354069792,40.0298881530762,1.98392522772133,20.1600007712841,0.000424704915574562,9.55028563301355E-5,0.25,1.88433300933517E-6,3.81204205965333E-5,1.91892449626193E-6,250.008728,250.008728,-23934.283203125,-23918.9921875,57.0534105042176,20.5224327367148,27.844467,0,0,0,40,4449,250.11655,-23926.6376953125,,,,,,,,,,,,,0,,,,0,,,,,,250.008728,,,,
,32419331.365,250.0104218,-28694.484375,5.35857082911244E-5,1.08540779091541E-6,1,0.999253354069792,40.0298881530762,1.98376105646523,20.1600007712841,0.000598522711966694,0.000131348856821109,0.25,2.37633526792362E-6,5.36777863303734E-5,2.42450284151364E-6,250.0104218,250.0104218,-28701.896484375,-28687.072265625,57.3035316303714,20.5276690800677,27.844467,0,0,0,40,4449,250.10695,-28694.484375,,,,,,,,,,,,,0,,,,0,,,,,,250.0104218,,,,
,32419429.46,250.0092773,-33599.232421875,7.10180803193674E-5,1.40367300430674E-6,1,0.999253354069792,40.0298881530762,1.98389620918928,20.1600007712841,0.000791200774315763,0.000186105550167741,0.25,4.21685779166288E-6,7.11392527543416E-5,4.2824908175034E-6,250.0092773,250.0092773,-33604.3359375,-33594.12890625,57.1323549846599,20.5247995832036,27.464817,0,0,0,40,4449,250.09975,-33599.232421875,,,,,,,,,,,,,0,,,,0.0049,,,,,,250.0092773,,,,
,32419524.585,250.0104218,-38351.140625,8.73494857810525E-5,1.44616431183306E-6,1,0.999253354069792,40.0298881530762,1.98388165430522,20.1600007712841,0.000976284997213386,0.000210763459988517,0.25,3.57539352957525E-6,8.74998552702814E-5,3.65319696007648E-6,250.0104218,250.0104218,-38356.35546875,-38345.92578125,57.2472543769868,20.5268483756707,27.844467,0,0,0,40,4449,250.0923,-38351.140625,,,,,,,,,,,,,0,,,,-0.00245,,,,,,250.0104218,,,,
,32419621.075,250.011795,-43176.30859375,0.0001027392086448,1.68623554038861E-6,1,0.999253354069792,40.0298881530762,1.98387099693646,20.1600007712841,0.0011492936799845,0.000242088538842673,0.25,3.68955224147465E-6,0.000102916505327564,3.78004352749736E-6,250.011795,250.011795,-43183.80859375,-43168.80859375,57.301968373333,20.5275187380754,27.844467,0,0,0,40,4449,250.08075,-43176.30859375,,,,,,,,,,,,,0,,,,0,,,,,,250.011795,,,,
,32419718.53,250.0136414,-48043.47265625,0.000119940010576443,1.83144874666173E-6,1,0.999253354069792,40.0298881530762,1.98379873725091,20.1600007712841,0.00134398025529859,0.000269253989210464,0.25,3.12088828482861E-6,0.000120147971972078,3.22430857922549E-6,250.0136414,250.0136414,-48045.95703125,-48040.98828125,57.2988418592561,20.5292009086751,27.464817,0,0,0,40,4449,250.07105,-48043.47265625,,,,,,,,,,,,,0,,,,0,,,,,,250.0136414,,,,
,32419812.78,250.0130768,-52753.439453125,0.000138801004762509,1.95312304038404E-6,1,0.999253354069792,40.0298881530762,1.98379190730985,20.1600007712841,0.00155471094523498,0.00031511264283803,0.25,3.92440065431156E-6,0.000139041438607328,4.04447296727511E-6,250.0130768,250.0130768,-52762.97265625,-52743.90625,57.1987934087945,20.5305394903545,27.844467,0,0,0,40,4449,250.0653,-52753.439453125,,,,,,,,,,,,,0,,,,0,,,,,,250.0130768,,,,
,32419911.51,250.0127411,-57690.60546875,0.000152213456927298,1.85490414832987E-6,1,0.999253354069792,40.0298881530762,1.98383865628183,20.1600007712841,0.00170265253955383,0.000359006434893235,0.25,5.49746036264413E-6,0.000152476179298356,5.6310485667118E-6,250.0127411,250.0127411,-57695.78515625,-57685.42578125,57.4426615067945,20.5304437832763,27.844467,0,0,0,40,4449,250.0515,-57690.60546875,,,,,,,,,,,,,0,,,,-0.00245,,,,,,250.0127411,,,,
,32420010.1,250.0104218,-62618.4921875,0.000171437673961786,2.23446481318333E-6,1,0.999253354069792,40.0298881530762,1.9838727638751,20.1600007712841,0.00192082275162181,0.000386495591279264,0.25,4.60543439283318E-6,0.000171734912752344,4.75289751231683E-6,250.0104218,250.0104218,-62628.3828125,-62608.6015625,57.5005020172176,20.5312972810869,27.844467,0,0,0,40,4449,250.0444,-62618.4921875,,,,,,,,,,,,,0,,,,0.0049,,,,,,250.0104218,,,,
,32420109.28,250.0100861,-67575.57421875,0.000189809590627944,2.43763945721589E-6,1,0.999253354069792,40.0298881530762,1.98387565613731,20.1600007712841,0.00213526774422106,0.000378327697562713,0.25,6.94091285524061E-7,0.000190142293187915,8.4938614485483E-7,250.0100861,250.0100861,-67580.3203125,-67570.828125,57.3512109700445,20.5339644784062,27.464817,0,0,0,40,4449,250.0331,-67575.57421875,,,,,,,,,,,,,0,,,,0,,,,,,250.0100861,,,,
,32420208.03,250.0149384,-72509.77734375,0.000206728194075036,2.60700704334573E-6,1,0.999253354069792,40.0298881530762,1.9837885658139,20.1600007712841,0.00231361411317424,0.000480553829298738,0.25,6.84365116744348E-6,0.000207085611587708,7.02321787327389E-6,250.0149384,250.0149384,-72517.3203125,-72502.234375,57.5747567265446,20.5324120629701,27.844467,0,0,0,40,4449,250.0192,-72509.77734375,,,,,,,,,,,,,0,,,,0.00245,,,,,,250.0149384,,,,
,32420305.79,250.0140839,-77394.34765625,0.000223683068331323,2.50789930493789E-6,1,0.999253354069792,40.0298881530762,1.98386188494352,20.1600007712841,0.00250471214874574,0.000512734104964659,0.25,6.76106515322303E-6,0.00022407036776851,6.95394786123233E-6,250.0140839,250.0140839,-77404.7578125,-77383.9375,57.0760777312753,20.5324608884147,27.844467,0,0,0,40,4449,250.0074,-77394.34765625,,,,,,,,,,,,,0,,,,0,,,,,,250.0140839,,,,
,32420404.08,250.0126953,-82306.890625,0.000241139415546506,2.70042345700214E-6,1,0.999253354069792,40.0298881530762,1.98377216386891,20.1600007712841,0.00270306617424191,0.00053541853444698,0.25,5.75155628543914E-6,0.000241558238410094,5.95647582538837E-6,250.0126953,250.0126953,-82316.6796875,-82297.1015625,57.1956668947176,20.5339939526679,27.844467,0,0,0,40,4449,250.00565,-82306.890625,,,,,,,,,,,,,0,,,,0,,,,,,250.0126953,,,,
,32420500.33,250.0116577,-87116.140625,0.000258867478878004,2.84201095798313E-6,1,0.999253354069792,40.0298881530762,1.98389677612247,20.1600007712841,0.00290753020181435,0.000542720445058956,0.25,3.32351077855286E-6,0.00025931944577017,3.53816165884807E-6,250.0116577,250.0116577,-87118.6484375,-87113.6328125,57.1894138665637,20.5322360535726,27.844467,0,0,0,40,4449,249.9947,-87116.140625,,,,,,,,,,,,,0,,,,-0.0049,,,,,,250.0116577,,,,
,32420612.22,250.0112457,-88305.6015625,0.000262680122308284,3.56999545854383E-6,1,0.999253354069792,40.0298881530762,1.98377234928482,20.1600007712841,0.00295298782853026,0.000534466443434618,0.25,1.93204561181738E-6,0.000263139920291114,2.14725398127871E-6,250.0112457,250.0112457,-88308.140625,-88303.0625,57.2996234877753,20.5326830728292,27.844467,0,0,0,40,4449,249.9833,-88305.6015625,,,,,,,,,,,,,0,,,,0.0049,,,,,,250.0112457,,,,
,32420707.23,250.0054474,-83556.16796875,0.000246027534180585,2.62455593541445E-6,1,0.999253354069792,40.0298881530762,1.9838596112867,20.1600007712841,0.00276542040619156,0.000503369262849842,0.25,2.0548081712938E-6,0.000246457998643618,2.2571249804686E-6,250.0054474,250.0054474,-83566.2578125,-83546.078125,57.2691399755253,20.5329137868238,27.844467,0,0,0,40,4449,249.981,-83556.16796875,,,,,,,,,,,,,0,,,,-0.0049,,,,,,250.0054474,,,,
,32420806.07,250.0003052,-78616.55078125,0.000228687785984446,2.3609142863715E-6,1,0.999253354069792,40.0298881530762,1.98382539293261,20.1600007712841,0.00256586300721868,0.000494477048257842,0.25,4.27210638311066E-6,0.000229086006774276,4.4646181940525E-6,250.0003052,250.0003052,-78623.890625,-78609.2109375,57.2652318329291,20.5319438527805,28.224119,0,0,0,40,4449,249.9814,-78616.55078125,,,,,,,,,,,,,0,,,,0,,,,,,250.0003052,,,,
,32420904.295,249.9907227,-73706.93359375,0.000212978878680091,2.43685170107437E-6,1,0.999253354069792,40.0298881530762,1.98381392084379,20.1600007712841,0.00238785099188109,0.000470578359787128,0.25,4.87299818956515E-6,0.000213349058447377,5.05412876869695E-6,249.9907227,249.9907227,-73711.8203125,-73702.046875,57.3097846585253,20.531687425848,27.464817,0,0,0,40,4449,249.99295,-73706.93359375,,,,,,,,,,,,,0,,,,-0.0049,,,,,,249.9907227,,,,
,32421002.935,249.9903717,-68777.484375,0.000195740740320524,2.46502234894299E-6,1,0.999253354069792,40.0298881530762,1.98373443349776,20.1600007712841,0.00219601451573644,0.000423729690086295,0.25,3.70147794661406E-6,0.000196081558352856,3.86683157411047E-6,249.9903717,249.9903717,-68785.078125,-68769.890625,57.2550706621791,20.5326943128366,27.085165,0,0,0,40,4449,250.0021,-68777.484375,,,,,,,,,,,,,0,,,,-0.00245,,,,,,249.9903717,,,,
,32421101.945,249.9874115,-63830.51953125,0.000176911424434448,2.37273326354422E-6,1,0.999253354069792,40.0298881530762,1.98379140972851,20.1600007712841,0.00198354499566103,0.000390348267024294,0.25,3.99983651766848E-6,0.000177218915183558,4.15065767767549E-6,249.9874115,249.9874115,-63843.01953125,-63818.01953125,57.0979633298137,20.530236045713,27.844467,0,0,0,40,4449,250.0096,-63830.51953125,,,,,,,,,,,,,0,,,,-0.00245,,,,,,249.9874115,,,,
,32421199.64,249.9921417,-58947.77734375,0.000159793026787235,1.76546264408356E-6,1,0.999253354069792,40.0298881530762,1.9839209590301,20.1600007712841,0.00179090357857482,0.000357326161885885,0.25,4.03253223048602E-6,0.000160070368715447,4.16969500022605E-6,249.9921417,249.9921417,-58950.3359375,-58945.21875,57.7670373422753,20.532000217369,27.085165,0,0,0,40,4449,250.0138,-58947.77734375,,,,,,,,,,,,,0,,,,0,,,,,,249.9921417,,,,
,32421298.43,249.9862061,-54010.150390625,0.000144126360621223,1.97354685230511E-6,1,0.999253354069792,40.0298881530762,1.98374444501493,20.1600007712841,0.00161279237362017,0.000336033153390475,0.25,4.86015816771269E-6,0.000144375520714034,4.98619585546399E-6,249.9862061,249.9862061,-54012.79296875,-54007.5078125,57.1198489283522,20.5316797220819,27.844467,0,0,0,40,4449,250.0267,-54010.150390625,,,,,,,,,,,,,0,,,,0,,,,,,249.9862061,,,,
,32421394.64,249.9883118,-49201.296875,0.000126759601065894,1.84054999898544E-6,1,0.999253354069792,40.0298881530762,1.9837210877509,20.1600007712841,0.00141595991869119,0.000309839124917337,0.25,5.54485429764065E-6,0.00012697766994909,5.65808367068527E-6,249.9883118,249.9883118,-49206.27734375,-49196.31640625,57.5067550453715,20.5322246762178,27.844467,0,0,0,40,4449,250.03575,-49201.296875,,,,,,,,,,,,,0,,,,-0.0049,,,,,,249.9883118,,,,
,32421492.19,249.988205,-44325.697265625,0.000107310356514818,1.69750099713715E-6,1,0.999253354069792,40.0298881530762,1.98369995845649,20.1600007712841,0.00119784556094137,0.000267171619946228,0.25,5.12708318858317E-6,0.000107494593446023,5.2238227001828E-6,249.988205,249.988205,-44338.3828125,-44313.01171875,57.2519441481022,20.5330985099872,28.224119,0,0,0,40,4449,250.0497,-44325.697265625,,,,,,,,,,,,,0,,,,-0.0049,,,,,,249.988205,,,,
,32421589.275,249.98718265,-39476.0234375,9.16927346405819E-5,1.22639864124296E-6,1,0.999253354069792,40.0298881530762,1.98370129075402,20.1600007712841,0.00102416933597348,0.000224516852518467,0.25,4.04571997795285E-6,9.18504193490546E-5,4.12789655336793E-6,249.9866791,249.9876862,-39481.234375,-39470.8125,57.0674798175637,20.5302659034969,27.464817,0,0,0,40,4449,250.05745,-39476.0234375,,,,,,,,,,,,,0,,,,0,,,,,,249.98718265,,,,
,32421685.665,249.9888306,-34656.31640625,7.39810761145986E-5,1.22804251813476E-6,1,0.999253354069792,40.0298881530762,1.98360541346958,20.1600007712841,0.00082296644340334,0.000200357959695832,0.25,4.97162433926388E-6,7.41068848929207E-5,5.04100719486093E-6,249.9888306,249.9888306,-34663.6875,-34648.9453125,57.3824761108138,20.5300381657126,27.844467,0,0,0,40,4449,250.06395,-34656.31640625,,,,,,,,,,,,,0,,,,0,,,,,,249.9888306,,,,
,32421783.48,249.9881592,-29769.2646484375,5.72005491667887E-5,1.3093008778441E-6,1,0.999253354069792,40.0298881530762,1.98375057654486,20.1600007712841,0.000639405890312238,0.000137267472657461,0.25,2.2753235177858E-6,5.72990998637777E-5,2.3262763151185E-6,249.9881592,249.9881592,-29771.62890625,-29766.900390625,57.0182372208522,20.5273614558554,27.464817,0,0,0,40,4449,250.0776,-29769.2646484375,,,,,,,,,,,,,0,,,,0,,,,,,249.9881592,,,,
,32421880.395,249.9918976,-24924.0439453125,4.1011390634772E-5,8.67872147752358E-7,1,0.999253354069792,40.0298881530762,1.98364810512094,20.1600007712841,0.000456204462492613,0.000111162469422235,0.25,2.76409114524104E-6,4.10811057637363E-5,2.80265513074788E-6,249.9918976,249.9918976,-24933.9453125,-24914.142578125,57.3480844559676,20.5302087920843,27.844467,0,0,0,40,4449,250.08025,-24924.0439453125,,,,,,,,,,,,,0,,,,0.0049,,,,,,249.9918976,,,,
,32421979.535,249.9914398,-19972.4580078125,2.53459411128885E-5,8.68449841888857E-7,1,0.999253354069792,40.0298881530762,1.98361884624979,20.1600007712841,0.000282429243460434,6.5880887696503E-5,0.25,1.45778274241642E-6,2.53892283834883E-5,1.48120306595398E-6,249.9914398,249.9914398,-19977.533203125,-19967.3828125,56.8447156895829,20.5285214216155,27.844467,0,0,0,40,4449,250.0843,-19972.4580078125,,,,,,,,,,,,,0,,,,0.0049,,,,,,249.9914398,,,,
,32422077.705,249.9907837,-15062.5698242187,7.72020481329126E-6,6.75280921565284E-7,1,0.999253354069792,40.0298881530762,1.98358714074384,20.1600007712841,8.46994165255446E-5,2.77086737217086E-5,0.25,1.12301559969415E-6,7.73282921886049E-6,1.13134844300716E-6,249.9907837,249.9907837,-15070.0107421875,-15055.12890625,57.1276652135445,20.5288643495533,27.844467,0,0,0,40,4449,250.0946,-15062.5698242187,,,,,,,,,,,,,0,,,,-0.0049,,,,,,249.9907837,,,,
,32422172.06,249.9898224,-10349.6459960938,-5.84940661226036E-6,6.38503564369777E-7,1,0.999253354069792,40.0298881530762,1.98363119102454,20.1600007712841,-6.71526274401693E-5,-3.83073597413544E-6,0.25,6.74083191728299E-7,-5.86022867113994E-6,6.70440943004767E-7,249.9898224,249.9898224,-10357.1435546875,-10342.1484375,57.3105662870445,20.5270679538971,27.464817,0,0,0,40,4449,250.10525,-10349.6459960938,,,,,,,,,,,,,0,,,,0,,,,,,249.9898224,,,,
,32422266.12,249.9854431,-5646.51391601562,-1.70705929790627E-5,4.99455639365041E-7,1,0.999253354069792,40.0298881530762,1.9835761245592,20.1600007712841,-0.000192954831318149,-2.8561844954487E-5,0.25,4.22777692358732E-7,-1.71009029399969E-5,4.09424223204732E-7,249.9854431,249.9854431,-5658.8359375,-5634.19189453125,57.5700669554292,20.5293401607027,27.844467,0,0,0,40,4449,250.11415,-5646.51391601562,,,,,,,,,,,,,0,,,,0.0049,,,,,,249.9854431,,,,
,32422359.48,249.9957581,-979.870910644531,-2.10236669825913E-5,4.57066862594053E-7,1,0.999253354069792,40.0298881530762,1.98347346675335,20.1600007712841,-0.000237051936823126,-3.84840383591924E-5,0.25,2.26605861505465E-7,-2.10607438264728E-5,2.09629165966031E-7,249.9957581,249.9957581,-984.922668457031,-974.819152832031,57.3379232852176,20.5282554149881,27.844467,0,0,0,40,4449,250.1103,-979.870910644531,,,,,,,,,,,,,0,,,,-0.00245,,,,,,249.9957581,,,,
,32422449.95,249.9931335,3537.77172851562,1.86671093432244E-5,4.21848482459341E-7,1,0.999253354069792,40.0298881530762,1.98352492993918,20.1600007712841,0.000211097556184598,3.06440726106062E-5,0.25,-5.14588171194003E-7,1.87002915431354E-5,-5.00071332315002E-7,249.9931335,249.9931335,3527.79516601562,3547.74829101562,57.1909771236022,20.5291125674841,27.844467,0,0,0,40,4449,250.1164,3537.77172851562,,,,,,,,,,,,,0,,,,-0.00245,,,,,,249.9931335,,,,
,32422544.135,249.9986877,8247.59423828125,1.16745409242073E-5,5.3175804801349E-7,1,0.999253354069792,40.0298881530762,1.9835324194495,20.1600007712841,0.000133989802076613,7.82040650923715E-6,0.25,-1.32980705535242E-6,1.16961236089119E-5,-1.32250571313425E-6,249.9986877,249.9986877,8242.7265625,8252.4619140625,57.2941520881407,20.5284432445579,27.844467,0,0,0,40,4449,250.1119,8247.59423828125,,,,,,,,,,,,,0,,,,0.0049,,,,,,249.9986877,,,,
,32422638.995,249.9998627,12988.0141601562,-1.81149454867583E-6,6.20917491350389E-7,1,0.999253354069792,40.0298881530762,1.98357170662945,20.1600007712841,-1.6623705476608E-5,-2.52434477409384E-5,0.25,-1.92871206115629E-6,-1.81308325257189E-6,-1.93358984942441E-6,249.9998627,249.9998627,12980.2353515625,12995.79296875,57.1839424669291,20.5261909257749,27.844467,0,0,0,40,4449,250.1116,12988.0141601562,,,,,,,,,,,,,0,,,,0,,,,,,249.9998627,,,,
,32422734.705,250.008316,17772.9306640625,-1.64613353753001E-5,8.20901435362631E-7,1,0.999253354069792,40.0298881530762,1.98357626002692,20.1600007712841,-0.000181285918364831,-5.51175079158478E-5,0.25,-2.04237594259917E-6,-1.6488535899009E-5,-2.05951435172455E-6,250.008316,250.008316,17767.99609375,17777.865234375,57.3097846585253,20.5270921384339,27.464817,0,0,0,40,4449,250.10835,17772.9306640625,,,,,,,,,,,,,0,,,,-0.00245,,,,,,250.008316,,,,
,32422830.555,250.0095673,22563.3427734375,-3.18718312169291E-5,1.21196592699387E-6,1,0.999253354069792,40.0298881530762,1.98362154416453,20.1600007712841,-0.000352792039159853,-9.64248765108381E-5,0.25,-3.03981274973664E-6,-3.19252539295652E-5,-3.07136018368466E-6,250.0095673,250.0095673,22560.994140625,22565.69140625,57.1120326431599,20.5254497400373,27.844467,0,0,0,40,4449,250.0963,22563.3427734375,,,,,,,,,,,,,0,,,,0.0049,,,,,,250.0095673,,,,
,32422926.355,250.01345825,27351.576171875,-4.86135568329172E-5,1.08879031954294E-6,1,0.999253354069792,40.0298881530762,1.98356700522594,20.1600007712841,-0.000542180733392685,-0.000123503380009033,0.25,-2.54261594514508E-6,-4.86967652086962E-5,-2.58701079595317E-6,250.0132446,250.0136719,27344.2890625,27358.86328125,57.1831608384099,20.5250229087319,27.844467,0,0,0,40,4449,250.08765,27351.576171875,,,,,,,,,,,,,0,,,,-0.0049,,,,,,250.01345825,,,,
,32423023.485,250.0110474,32206.3994140625,-6.57569692228254E-5,1.29066470564201E-6,1,0.999253354069792,40.0298881530762,1.9835704826361,20.1600007712841,-0.000732710960380654,-0.000170917112553239,0.25,-3.78232204433786E-6,-6.58692566076545E-5,-3.84290439276475E-6,250.0110474,250.0110474,32201.22265625,32211.576171875,57.0198004778906,20.524849262645,27.464817,0,0,0,40,4449,250.0802,32206.3994140625,,,,,,,,,,,,,0,,,,0.00245,,,,,,250.0110474,,,,
,32423117.86,250.0096741,36921.689453125,-8.2967919286615E-5,1.45380560625667E-6,1,0.999253354069792,40.0298881530762,1.98358021598187,20.1600007712841,-0.000926036450716654,-0.000206748356460407,0.25,-3.98118553270006E-6,-8.31102637148415E-5,-4.05614687742472E-6,250.0096741,250.0096741,36914.3515625,36929.02734375,57.0166739638137,20.5266706421179,27.844467,0,0,0,40,4449,250.07495,36921.689453125,,,,,,,,,,,,,0,,,,-0.00245,,,,,,250.0096741,,,,
,32423215.77,250.0101776,41817.015625,-9.83253502991838E-5,1.64195558638333E-6,1,0.999253354069792,40.0298881530762,1.98355102298893,20.1600007712841,-0.00109553581220315,-0.000255944525304282,0.25,-5.68937741018659E-6,-9.84932642403339E-5,-5.77980725276716E-6,250.0101776,250.0101776,41811.91015625,41822.12109375,57.0393411908714,20.5257638149239,27.844467,0,0,0,40,4449,250.06595,41817.015625,,,,,,,,,,,,,0,,,,0,,,,,,250.0101776,,,,
,32423313.36,250.0084839,46694.50390625,-0.000116252314234603,1.56779364179857E-6,1,0.999253354069792,40.0298881530762,1.98347779519194,20.1600007712841,-0.00130147078533823,-0.000266621320820211,0.25,-3.53012575042931E-6,-0.000116453484562558,-3.63129535499825E-6,250.0084839,250.0084839,46689.40625,46699.6015625,57.2300585495638,20.5289035577726,27.844467,0,0,0,40,4449,250.0643,46694.50390625,,,,,,,,,,,,,0,,,,0.0049,,,,,,250.0084839,,,,
,32423411.375,250.0150146,51592.166015625,-0.000134245902734142,1.93102988648794E-6,1,0.999253354069792,40.0298881530762,1.98357813051459,20.1600007712841,-0.0014998526033541,-0.000325970195685676,0.25,-5.68184388239313E-6,-0.000134476891093436,-5.80133587613218E-6,250.0150146,250.0150146,51587.3984375,51596.93359375,57.166746639506,20.5266472363194,28.224119,0,0,0,40,4449,250.0446,51592.166015625,,,,,,,,,,,,,0,,,,0,,,,,,250.0150146,,,,
,32423506.52,250.0100403,56349.71484375,-0.000147930282133885,1.88141643948274E-6,1,0.999253354069792,40.0298881530762,1.98356917541192,20.1600007712841,-0.00165356751088457,-0.000354388966163135,0.25,-5.83404074102323E-6,-0.00014818521693549,-5.964792576408E-6,250.0100403,250.0100403,56349.71484375,56349.71484375,56.9252234270637,20.5265161228792,28.224119,0,0,0,40,4449,250.0351,56349.71484375,,,,,,,,,,,,,0,,,,-0.0049,,,,,,250.0100403,,,,
,32423603.355,250.011734,61187.494140625,-0.000167619598569124,1.45207897902933E-6,1,0.999253354069792,40.0298881530762,1.98352516010695,20.1600007712841,-0.00187620797315656,-0.000386599899729313,0.25,-5.28248229417476E-6,-0.000167909565374437,-5.42810359634457E-6,250.011734,250.011734,61182.7890625,61192.19921875,57.1307917276214,20.52587989476,27.844467,0,0,0,40,4449,250.0257,61187.494140625,,,,,,,,,,,,,0,,,,-0.00245,,,,,,250.011734,,,,
,32423699.37,250.0098419,65988.078125,-0.000182251194833203,2.49594414582078E-6,1,0.999253354069792,40.0298881530762,1.98341600243366,20.1600007712841,-0.00203513454588151,-0.000447668431270158,0.25,-8.17349614418551E-6,-0.000182564543407083,-8.33587299283399E-6,250.0098419,250.0098419,65985.875,65990.28125,56.8783257159099,20.5255602291627,27.844467,0,0,0,40,4449,250.0192,65988.078125,,,,,,,,,,,,,0,,,,-0.0049,,,,,,250.0098419,,,,
,32423796.525,250.0171967,70843.16015625,-0.000200729719574863,2.90625979082994E-6,1,0.999253354069792,40.0298881530762,1.98357202817146,20.1600007712841,-0.00224888185737083,-0.000451367776448455,0.25,-5.29504585705495E-6,-0.000201077830479491,-5.46713142034908E-6,250.0171967,250.0171967,70838.125,70848.1953125,57.0534105042176,20.5235640656563,27.464817,0,0,0,40,4449,250.00405,70843.16015625,,,,,,,,,,,,,0,,,,0.00245,,,,,,250.0171967,,,,
,32423893.235,250.0136261,75678.61328125,-0.000215575414412539,2.38214301516028E-6,1,0.999253354069792,40.0298881530762,1.98354398018852,20.1600007712841,-0.00241472309865037,-0.000487345133034976,0.25,-5.91805229329128E-6,-0.000215949148523922,-6.10299983548592E-6,250.0136261,250.0136261,75666.2265625,75691,57.1346998702176,20.5226963014489,27.464817,0,0,0,40,4449,249.9986,75678.61328125,,,,,,,,,,,,,0,,,,-0.00245,,,,,,250.0136261,,,,
,32423991.04,250.0133972,80567.484375,-0.000237711882067367,3.02248248865755E-6,1,0.999253354069792,40.0298881530762,1.98358142259654,20.1600007712841,-0.00266820257004829,-0.000505831386635555,0.25,-3.7213844462274E-6,-0.000238126304539412,-3.92009261284859E-6,250.0133972,250.0133972,80565.1171875,80569.8515625,57.0424677049483,20.5226388967709,27.844467,0,0,0,40,4449,249.9928,80567.484375,,,,,,,,,,,,,0,,,,0.0049,,,,,,250.0133972,,,,
,32424087.325,250.0110168,85380.66796875,-0.000251033134896363,3.11472257471014E-6,1,0.999253354069792,40.0298881530762,1.983601748299,20.1600007712841,-0.00281335099872641,-0.00055958332682605,0.25,-6.18697842138817E-6,-0.000251469019640886,-6.40047766863224E-6,250.0110168,250.0110168,85378.234375,85383.1015625,56.9572701963522,20.5224393456279,27.844467,0,0,0,40,4449,249.9732,85380.66796875,,,,,,,,,,,,,0,,,,-0.00245,,,,,,250.0110168,,,,
,32424198.145,250.0139008,89969.6953125,-0.000269840891819848,2.50546894255357E-6,1,0.999253354069792,40.0298881530762,1.9836417281096,20.1600007712841,-0.00303115000760634,-0.00056138041377327,0.25,-3.08462313412394E-6,-0.00027031232424747,-3.30752509337533E-6,250.0139008,250.0139008,89965.71875,89973.671875,57.0713879601599,20.5228232786767,27.844467,0,0,0,40,4449,249.9651,89969.6953125,,,,,,,,,,,,,0,,,,0.00245,,,,,,250.0139008,,,,
,32424292.95,250.0045319,85249.125,-0.000249503930190384,2.08063825527089E-6,1,0.999253354069792,40.0298881530762,1.98364784220652,20.1600007712841,-0.0027964497513755,-0.000555183616219331,0.25,-6.06012490771674E-6,-0.000249937287163604,-6.27218533197063E-6,250.0045319,250.0045319,85239.234375,85259.015625,56.7337244398522,20.5223325250905,27.844467,0,0,0,40,4449,249.96465,85249.125,,,,,,,,,,,,,0,,,,0,,,,,,250.0045319,,,,
,32424392.34,249.9985504,80280.5078125,-0.000233165937346515,2.42441221916361E-6,1,0.999253354069792,40.0298881530762,1.98355786997597,20.1600007712841,-0.00261652926012602,-0.000499721604986607,0.25,-3.96728271660119E-6,-0.000233572296858271,-4.16278867208353E-6,249.9985504,249.9985504,80275.5546875,80285.4609375,57.2519441481022,20.5244653893367,27.844467,0,0,0,40,4449,249.969,80280.5078125,,,,,,,,,,,,,0,,,,0.0049,,,,,,249.9985504,,,,
,32424493.4,249.9949036,75229.10546875,-0.000215245922049816,2.80297104507581E-6,1,0.999253354069792,40.0298881530762,1.9835737928803,20.1600007712841,-0.00241018850619329,-0.000491682320592342,0.25,-6.35985140017269E-6,-0.000215618857676215,-6.54535586225315E-6,249.9949036,249.9949036,75226.3671875,75231.84375,57.0674798175637,20.5246627179897,28.224119,0,0,0,40,4449,249.9766,75229.10546875,,,,,,,,,,,,,0,,,,0,,,,,,249.9949036,,,,
,32424590.22,249.9887238,70388.34375,-0.000198835488531374,1.85749549479499E-6,1,0.999253354069792,40.0298881530762,1.98356354104869,20.1600007712841,-0.00222589021571636,-0.000457271634872553,0.25,-6.14816854881427E-6,-0.000199179779052492,-6.3202582867922E-6,249.9887238,249.9887238,70378.25,70398.4375,56.9478906541214,20.524863662148,27.464817,0,0,0,40,4449,249.9876,70388.34375,,,,,,,,,,,,,0,,,,0,,,,,,249.9887238,,,,
,32424687.395,249.9913254,65530.39453125,-0.00017992401773065,2.60844439000112E-6,1,0.999253354069792,40.0298881530762,1.98371008710123,20.1600007712841,-0.00201250225880569,-0.000424319341091412,0.25,-6.49694799532866E-6,-0.000180234755288022,-6.65453461920712E-6,249.9907532,249.9918976,65525.4609375,65535.328125,57.1456426694868,20.5214977837698,27.844467,0,0,0,40,4449,249.99325,65530.39453125,,,,,,,,,,,,,0,,,,0.00245,,,,,,249.9913254,,,,
,32424785.025,249.9884033,60649.55859375,-0.000165374009982419,1.87826617007529E-6,1,0.999253354069792,40.0298881530762,1.98345522875823,20.1600007712841,-0.00185012909878383,-0.000386497514584369,0.25,-5.66388729323241E-6,-0.000165659856050837,-5.80839786225122E-6,249.9884033,249.9884033,60637.0703125,60662.046875,57.4129596230638,20.5237644794052,27.844467,0,0,0,40,4449,249.9961,60649.55859375,,,,,,,,,,,,,0,,,,0.0049,,,,,,249.9884033,,,,
,32424881.625,249.9903412,55821.681640625,-0.000146657241363215,1.62344006782264E-6,1,0.999253354069792,40.0298881530762,1.98349922658012,20.1600007712841,-0.00164317251660436,-0.0003289003518255,0.25,-3.79108416768128E-6,-0.000146911703983499,-3.91725065454682E-6,249.9903412,249.9903412,55814.33203125,55829.03125,57.3090030300061,20.5264324600037,27.844467,0,0,0,40,4449,250.00715,55821.681640625,,,,,,,,,,,,,0,,,,0,,,,,,249.9903412,,,,
,32424979.86,249.9919586,50914.3203125,-0.000131488675132396,2.04654457298009E-6,1,0.999253354069792,40.0298881530762,1.9835705952451,20.1600007712841,-0.00147000690446781,-0.000313718789120887,0.25,-5.07150511597626E-6,-0.000131715424671482,-5.18771811634651E-6,249.9919586,249.9919586,50906.90234375,50921.73828125,57.108906129083,20.5263114112232,27.844467,0,0,0,40,4449,250.0146,50914.3203125,,,,,,,,,,,,,0,,,,-0.00245,,,,,,249.9919586,,,,
,32425075.44,249.9883728,46136.599609375,-0.000113637159004451,1.96749919839211E-6,1,0.999253354069792,40.0298881530762,1.98346575417868,20.1600007712841,-0.00126642352047739,-0.000293857112882436,0.25,-6.40373201080958E-6,-0.000113831467581287,-6.50784603648544E-6,249.9883728,249.9883728,46134.05859375,46139.140625,57.2136443506599,20.5272577863783,28.224119,0,0,0,40,4449,250.02585,46136.599609375,,,,,,,,,,,,,0,,,,0,,,,,,249.9883728,,,,
,32425171.415,249.9879608,41339.060546875,-9.68760246535766E-5,1.28790333199833E-6,1,0.999253354069792,40.0298881530762,1.98340711891737,20.1600007712841,-0.0010790556473109,-0.000253641525012,0.25,-5.73761643461502E-6,-9.70414284429905E-5,-5.82697228995759E-6,249.9879608,249.9879608,41336.48828125,41341.6328125,57.2269320354868,20.5297949444553,27.464817,0,0,0,40,4449,250.0354,41339.060546875,,,,,,,,,,,,,0,,,,0.0049,,,,,,249.9879608,,,,
,32425267.375,249.9890289,36543.876953125,-7.99806592361761E-5,1.48311309841785E-6,1,0.999253354069792,40.0298881530762,1.98337057471168,20.1600007712841,-0.000892219261823333,-0.000201508750674923,0.25,-4.03547853230279E-6,-8.01177730384653E-5,-4.10810647513895E-6,249.9890289,249.9890289,36538.93359375,36548.8203125,57.301968373333,20.5278497062055,27.844467,0,0,0,40,4449,250.04705,36543.876953125,,,,,,,,,,,,,0,,,,0,,,,,,249.9890289,,,,
,32425363.76,249.9877472,31726.572265625,-6.42885851415723E-5,1.03969702783476E-6,1,0.999253354069792,40.0298881530762,1.98335524678968,20.1600007712841,-0.00071782151617529,-0.000158168383218244,0.25,-2.9056825359723E-6,-6.43990663081477E-5,-2.96353810090493E-6,249.9877472,249.9877472,31721.689453125,31731.455078125,56.8931766577752,20.5291812020453,27.844467,0,0,0,40,4449,250.0536,31726.572265625,,,,,,,,,,,,,0,,,,-0.0049,,,,,,249.9877472,,,,
,32425460.36,249.990448,26898.685546875,-4.75529693672606E-5,1.27134139320414E-6,1,0.999253354069792,40.0298881530762,1.98359184584137,20.1600007712841,-0.000530207134299235,-0.000121685611046165,0.25,-2.56488855066622E-6,-4.76343360124957E-5,-2.60846305232514E-6,249.990448,249.990448,26893.658203125,26903.712890625,57.1128142716791,20.5278427761114,27.844467,0,0,0,40,4449,250.0613,26898.685546875,,,,,,,,,,,,,0,,,,0,,,,,,249.990448,,,,
,32425554.655,249.9891968,22183.4873046875,-3.19015223254701E-5,1.15271408709234E-6,1,0.999253354069792,40.0298881530762,1.98361279945905,20.1600007712841,-0.000355087769444305,-8.51645101647052E-5,0.25,-2.03423016777131E-6,-3.19558464104228E-5,-2.06404472836701E-6,249.9891968,249.9891968,22176.283203125,22190.69140625,57.3191642007561,20.5276032838301,27.844467,0,0,0,40,4449,250.0719,22183.4873046875,,,,,,,,,,,,,0,,,,0,,,,,,249.9891968,,,,
,32425650.14,249.9873657,17411.1787109375,-1.63954435748224E-5,7.77445392976463E-7,1,0.999253354069792,40.0298881530762,1.98351205043391,20.1600007712841,-0.000179977883964154,-5.82218913789732E-5,0.25,-2.32977887320148E-6,-1.64223033167533E-5,-2.34737204776571E-6,249.9873657,249.9873657,17408.70703125,17413.650390625,57.115940785756,20.5283546977144,27.844467,0,0,0,40,4449,250.07985,17411.1787109375,,,,,,,,,,,,,0,,,,0,,,,,,249.9873657,,,,
,32425743.775,249.9887848,12733.7465820312,-1.80793675478318E-6,7.42518679236342E-7,1,0.999253354069792,40.0298881530762,1.98389559976471,20.1600007712841,-1.65020730193882E-5,-2.5725845310722E-5,0.25,-1.9718323323188E-6,-1.80948408090944E-6,-1.9767838533515E-6,249.9887848,249.9887848,12726.2421875,12741.2509765625,57.5333304150253,20.5224350553973,28.224119,0,0,0,40,4449,250.0889,12733.7465820312,,,,,,,,,,,,,0,,,,-0.00245,,,,,,249.9887848,,,,
,32425839.26,249.9925079,7958.337890625,1.19947669921151E-5,6.0846103590982E-7,1,0.999253354069792,40.0298881530762,1.98378869987985,20.1600007712841,0.000137390354531888,9.71809620952188E-6,0.25,-1.2168381548205E-6,1.20168209787089E-5,-1.20907338134743E-6,249.9925079,249.9925079,7953.35009765625,7963.32568359375,56.9627415959868,20.525500674799,28.224119,0,0,0,40,4449,250.0999,7958.337890625,,,,,,,,,,,,,0,,,,0,,,,,,249.9925079,,,,
,32425935.325,249.99308775,3158.14367675781,2.17017506723191E-5,3.68672523816397E-7,1,0.999253354069792,40.0298881530762,1.98371309099097,20.1600007712841,0.000244980402347745,3.82625159237637E-5,0.25,-3.64273797497718E-7,2.17401336964843E-5,-3.4698384734506E-7,249.9930725,249.993103,3150.69580078125,3165.59155273438,57.1003082153714,20.5271013893268,27.464817,0,0,0,40,4449,250.1005,3158.14367675781,,,,,,,,,,,,,0,,,,-0.00245,,,,,,249.99308775,,,,
,32425999.495,249.9893799,-0.304475456476212,1.37843119380052E-5,4.25303235260794E-7,1,0.999253354069792,40.0298881530762,1.98371646331549,20.1600007712841,0.000155284382109532,2.61496432984046E-5,0.25,-6.73427132240862E-8,1.38085574292996E-5,-5.60674038462387E-8,249.9893799,249.9893799,-0.319699227809906,-0.289251685142517,56.9205336559483,20.5265465245066,27.844467,0,0,0,40,4417,250.0996,-0.304475456476212,,,,,,,,,,,,,0,,,,0.00245,,,,,,249.9893799,,,,