File: data/monolayers/magneticStructure/ML_Ac_CoFe_C/PPMS/data/DD205_4_KOELNPPMS_FCC_100OE_TOUCHDOWN.DAT
[Header]
; VSM Data File (default extension .dat)
; Copyright (c) 2003-2013, Quantum Design, Inc. All rights reserved.
TITLE,
FILEOPENTIME,19846509.16,08/18/2018,4:53 pm
BYAPP,VSM,2.0,2.0
INFO,PPMS VSM Option Release 1.4.10 Build 1,APPNAME
INFO,Quantum Design Linear Motor Servo Controller,MOTOR_MODULE_NAME
INFO,3101-100 M1,MOTOR_HW_VERSION
INFO,MMC1014,MOTOR_SERIAL_NUMBER
INFO,SRV No X-over 01.03.11,MOTOR_SOFTWARE_VERSION
INFO,Quantum Design VSM Detection Module,VSM_MODULE_NAME
INFO,3101-150 F0,VSM_HW_VERSION
INFO,VSM707,VSM_SERIAL_NUMBER
INFO,VSM No X-over 01.02.05 May 20 2008 13:51:47,VSM_SOFTWARE_VERSION
INFO,704,PREAMP_SERIAL_NUMBER
INFO,822,COIL_SERIAL_NUMBER
INFO,0,MOMENT_UNITS
INFO,,SAMPLE_MATERIAL
INFO,,SAMPLE_COMMENT
INFO,,SAMPLE_MASS
INFO,,SAMPLE_VOLUME
INFO,,SAMPLE_MOLECULAR_WEIGHT
INFO,,SAMPLE_SIZE
INFO,,SAMPLE_SHAPE
DATATYPE,COMMENT,1
DATATYPE,TIME,2
STARTUPAXIS,X,2
STARTUPAXIS,Y1,5
[Data]
Comment,Time Stamp (sec),Temperature (K),Magnetic Field (Oe),Moment (emu),M. Std. Err. (emu),Transport Action,Averaging Time (sec),Frequency (Hz),Peak Amplitude (mm),Center Position (mm),Coil Signal' (mV),Coil Signal" (mV),Range (mV),M. Quad. Signal (emu),M. Raw' (emu),M. Raw" (emu),Min. Temperature (K),Max. Temperature (K),Min. Field (Oe),Max. Field (Oe),Mass (grams),Motor Lag (deg),Pressure (Torr),VSM Status (code),Motor Status (code),Measure Status (code),Measure Count,PPMS Status (code),System Temp. (K),System Field (Oe),Sample Position (deg),Bridge 1 Resistance (ohms),Bridge 1 Excitation (에),Bridge 2 Resistance (ohms),Bridge 2 Excitation (에),Bridge 3 Resistance (ohms),Bridge 3 Excitation (에),Bridge 4 Resistance (ohms),Bridge 4 Excitation (에),Signal 1 Vin (V),Signal 2 Vin (V),Digital Inputs (code),Drive 1 Iout (mA),Drive 1 Ipower (W),Drive 2 Iout (mA),Drive 2 Ipower (W),Pressure (),Map 20 (),Map 21 (),Map 22 (),Map 23 (),Map 24 (),Map 25 (),Map 26 (),Map 27 (),Map 28 (),Map 29 ()
,19847035.795,349.9333801,99.8070526123047,7.70233092725308E-6,4.29629551911342E-7,1,0.999253354069792,40.0298881530762,1.98204727895896,14.3499998375773,8.59767547530891E-5,1.69587062469766E-5,0.25,1.79480989100131E-7,7.68859394278996E-6,1.83439601964281E-7,349.9333801,349.9333801,99.8070526123047,99.8070526123047,54.0113123073711,19.5512392146203,27.464817,0,0,0,40,4369,351.6368,99.8070526123047,,,,,,,,,,,,,0,,,,0.00245,,,,,,349.9333801,,,,
,19847200.585,346.9327087,99.8070526123047,8.7368508036812E-6,3.75057259691283E-7,1,0.999253354069792,40.0298881530762,1.98190774826268,14.3499998375773,9.78947324607181E-5,1.71179648394079E-5,0.25,1.44217326876076E-8,8.72225436447284E-6,1.93396717757659E-8,346.9327087,346.9327087,99.8070526123047,99.8070526123047,54.0691528177942,19.5505597098318,27.464817,0,0,0,40,4374,345.19855,99.8070526123047,,,,,,,,,,,,,0,,,,-0.00245,,,,,,346.9327087,,,,
,19847350.365,343.4490356,99.8070526123047,8.49616542407517E-6,4.11650812737941E-7,1,0.999253354069792,40.0298881530762,1.98195484854599,14.3499998375773,9.62312382172028E-5,1.07589956322558E-5,0.25,-5.11451894132564E-7,8.48327568542242E-6,-5.05796475210452E-7,343.4490356,343.4490356,99.8070526123047,99.8070526123047,54.0691528177942,19.5536729035962,27.464817,0,0,0,40,4374,341.4148,99.8070526123047,,,,,,,,,,,,,0,,,,-0.0049,,,,,,343.4490356,,,,
,19847499.945,339.9466248,99.8070526123047,9.36637228491016E-6,4.33923699188723E-7,1,0.999253354069792,40.0298881530762,1.98178079103993,14.3499998375773,0.000106071972145116,1.19736869007892E-5,0.25,-5.53888152022906E-7,9.3532798785861E-6,-5.47666429173528E-7,339.9466248,339.9466248,99.8070526123047,99.8070526123047,53.9980246225442,19.5541270847364,27.464817,0,0,0,40,4374,337.39445,99.8070526123047,,,,,,,,,,,,,0,,,,0,,,,,,339.9466248,,,,
,19847645.305,336.4659729,99.8070526123047,8.15769575102781E-6,4.06114991867209E-7,1,0.999253354069792,40.0298881530762,1.98184855473823,14.2700001597404,9.25591451518207E-5,9.50023650326007E-6,0.25,-5.65411417296179E-7,8.14731942755187E-6,-5.59882720039987E-7,336.4659729,336.4659729,99.8070526123047,99.8070526123047,53.7846400367942,19.5533306853285,28.224119,0,0,0,40,4374,333.6317,99.8070526123047,,,,,,,,,,,,,0,,,,-0.00245,,,,,,336.4659729,,,,
,19847788.14,332.9953613,99.8070526123047,8.13904421122647E-6,4.19717658918745E-7,1,0.999253354069792,40.0298881530762,1.98163435462137,14.2700001597404,9.18360231071845E-5,1.24412131728666E-5,0.25,-2.9994459219002E-7,8.12951338011315E-6,-2.94752144310806E-7,332.9953613,332.9953613,99.8070526123047,99.8070526123047,53.7948012075442,19.5557278535528,27.464817,0,0,0,40,4374,329.9746,99.8070526123047,,,,,,,,,,,,,0,,,,0.0049,,,,,,332.9953613,,,,
,19847933.58,329.4613342,99.8070526123047,8.73068649791655E-6,5.00298703441634E-7,1,0.999253354069792,40.0298881530762,1.98164475833346,14.2700001597404,9.84532242459988E-5,1.3758029853787E-5,0.25,-2.85185418066247E-7,8.72151310165796E-6,-2.79626985690351E-7,329.4613342,329.4613342,99.8070526123047,99.8070526123047,53.9831736806788,19.5591178173258,27.844467,0,0,0,40,4374,326.246,99.8070526123047,,,,,,,,,,,,,0,,,,-0.0049,,,,,,329.4613342,,,,
,19848075.085,325.9831543,99.8070526123047,8.62974766489571E-6,5.22409064516998E-7,1,0.999253354069792,40.0298881530762,1.98168082324953,14.2700001597404,9.67844477337461E-5,1.67418834549253E-5,0.25,-1.87477227903167E-9,8.62155744932382E-6,3.38535872708506E-9,325.9831543,325.9831543,99.8070526123047,99.8070526123047,53.7854216653134,19.5543307187136,27.844467,0,0,0,40,4374,322.6723,99.8070526123047,,,,,,,,,,,,,0,,,,0,,,,,,325.9831543,,,,
,19848217.495,322.4894714,99.8070526123047,9.12954362155969E-6,4.38370768999867E-7,1,0.999253354069792,40.0298881530762,1.98140086927514,14.2700001597404,0.000102985721117347,1.42631958604823E-5,0.25,-3.09517914002488E-7,9.12218462158426E-6,-3.03626247846812E-7,322.4894714,322.4894714,99.8070526123047,99.8070526123047,53.7924563219865,19.5595107920391,27.844467,0,0,0,40,4374,319.0652,99.8070526123047,,,,,,,,,,,,,0,,,,0,,,,,,322.4894714,,,,
,19848361.18,318.97229,99.8070526123047,9.2883226395232E-6,4.33569829115514E-7,1,0.999253354069792,40.0298881530762,1.98174866031076,14.2700001597404,0.000104704801506797,1.5107671071877E-5,0.25,-2.62188614273753E-7,9.2819524159216E-6,-2.56193222583109E-7,318.97229,318.97229,99.8070526123047,99.8070526123047,53.9917715943903,19.5571544599495,28.224119,0,0,0,40,4374,315.427,99.8070526123047,,,,,,,,,,,,,0,,,,-0.0049,,,,,,318.97229,,,,
,19848504.135,315.4654846,99.8070526123047,9.04129984370783E-6,3.26175263822473E-7,1,0.999253354069792,40.0298881530762,1.98132824949548,14.2900003120303,0.000101924413945184,1.4633909658776E-5,0.25,-2.61605732769781E-7,9.03622248455258E-6,-2.55720128966285E-7,315.4654846,315.4654846,99.8070526123047,99.8070526123047,53.8432621757365,19.5595929024196,28.224119,0,0,0,40,4374,311.79625,99.8070526123047,,,,,,,,,,,,,0,,,,0.0049,,,,,,315.4654846,,,,
,19848645.735,311.9542542,99.8070526123047,9.28999599969038E-6,3.79946947723711E-7,1,0.999253354069792,40.0298881530762,1.98161721577546,14.2799997702241,0.000105308262232622,1.18504956167103E-5,0.25,-5.53189963647157E-7,9.28611726421437E-6,-5.46965086073232E-7,311.9542542,311.9542542,99.8070526123047,99.8070526123047,53.811215406448,19.5540237943336,27.844467,0,0,0,40,4374,308.2115,99.8070526123047,,,,,,,,,,,,,0,,,,0,,,,,,311.9542542,,,,
,19848787.625,308.4815063,99.8070526123047,9.05434414649243E-6,4.3837046137497E-7,1,0.999253354069792,40.0298881530762,1.98146717433429,14.2799997702241,0.000102347015837316,1.32546615989811E-5,0.25,-3.8735823681133E-7,9.05158422214365E-6,-3.8132627034969E-7,308.4815063,308.4815063,99.8070526123047,99.8070526123047,53.9011026861596,19.5514586767949,27.844467,0,0,0,40,4374,304.6106,99.8070526123047,,,,,,,,,,,,,0,,,,-0.0049,,,,,,308.4815063,,,,
,19848931.61,304.9562378,99.8070526123047,8.96431715140445E-6,3.80258268651361E-7,1,0.999253354069792,40.0298881530762,1.9945420176198,14.2900003120303,0.000101423173593171,1.64247797245291E-5,0.25,-9.86628184355198E-8,8.9625227706964E-6,-9.27135050873825E-8,304.9562378,304.9562378,99.8070526123047,99.8070526123047,53.7846400367942,19.5521211913493,28.224119,0,0,0,40,4374,300.96975,99.8070526123047,,,,,,,,,,,,,0,,,,0,,,,,,304.9562378,,,,
,19849074.275,301.4509125,99.8070526123047,9.51602799899807E-6,3.96746848219559E-7,1,0.999253354069792,40.0298881530762,1.99474756484912,14.299999922514,0.000108067187849168,1.52587712306244E-5,0.25,-2.97898610229745E-7,9.51544155937342E-6,-2.91488620878763E-7,301.4230042,301.4788208,99.8070526123047,99.8070526123047,53.9495636543519,19.5588506088711,27.844467,0,0,0,40,4374,297.35695,99.8070526123047,,,,,,,,,,,,,0,,,,0,,,,,,301.4509125,,,,
,19849214.985,297.9854431,99.8070526123047,9.80707292817007E-6,3.71610629506831E-7,1,0.999253354069792,40.0298881530762,1.99474544095847,14.2900003120303,0.000111450572778705,1.53552020121709E-5,0.25,-3.40051964004562E-7,9.8077063563096E-6,-3.33389618050201E-7,297.9854431,297.9854431,99.8070526123047,99.8070526123047,54.3036413735634,19.5624424973241,27.464817,0,0,0,40,4374,293.80345,99.8070526123047,,,,,,,,,,,,,0,,,,0,,,,,,297.9854431,,,,
,19849335.56,294.9837036,99.8070526123047,9.87670517788441E-6,3.34956260965601E-7,1,0.999253354069792,40.0298881530762,1.9817992439064,14.3200000748038,0.000111145284492645,1.77523994681911E-5,0.25,-1.30360245953929E-7,9.8782589005067E-6,-1.23571711426079E-7,294.9837036,294.9837036,99.8070526123047,99.8070526123047,53.8377907761019,19.5564630475034,27.844467,0,0,0,40,4374,290.7783,99.8070526123047,,,,,,,,,,,,,0,,,,0.00245,,,,,,294.9837036,,,,
,19849479.03,291.4520874,99.8070526123047,9.70602632693563E-6,3.70706851522333E-7,1,0.999253354069792,40.0298881530762,1.98155294625863,14.3200000748038,0.000110048378359389,1.26969489950748E-5,0.25,-5.51164166322832E-7,9.70907618430549E-6,-5.44523655108176E-7,291.4520874,291.4520874,99.8070526123047,99.8070526123047,53.8479519468519,19.5553312792997,28.224119,0,0,0,40,4374,287.15905,99.8070526123047,,,,,,,,,,,,,0,,,,0,,,,,,291.4520874,,,,
,19849620.54,287.9757996,99.8070526123047,9.66671838553496E-6,4.23765655195883E-7,1,0.999253354069792,40.0298881530762,1.98186617849097,14.3200000748038,0.00010873673246382,1.78202546720749E-5,0.25,-8.85802827805191E-8,9.67063711734832E-6,-8.17484479316429E-8,287.9757996,287.9757996,99.8070526123047,99.8070526123047,53.9261147987749,19.5573391621244,27.464817,0,0,0,40,4374,283.58215,99.8070526123047,,,,,,,,,,,,,0,,,,0.00245,,,,,,287.9757996,,,,
,19849739.625,284.9880981,99.8070526123047,9.99102249417191E-6,4.23942147368729E-7,1,0.999253354069792,40.0298881530762,1.98179932477433,14.3299996852875,0.000113584825907032,1.15434687906986E-5,0.25,-7.03847012585603E-7,9.99658286539878E-6,-6.97014134250035E-7,284.9880981,284.9880981,99.8070526123047,99.8070526123047,53.9948981084673,19.5536277188087,28.224119,0,0,0,40,4374,280.5878,99.8070526123047,,,,,,,,,,,,,0,,,,0.0049,,,,,,284.9880981,,,,
,19849882.025,281.4850769,99.8070526123047,1.01406322583123E-5,3.89717072571487E-7,1,0.999253354069792,40.0298881530762,1.98196530267108,14.3299996852875,0.00011463813202187,1.55918939706891E-5,0.25,-3.69724476496202E-7,1.0147303859343E-5,-3.62547557222637E-7,281.4850769,281.4850769,99.8070526123047,99.8070526123047,53.9472187687942,19.5531852298258,27.844467,0,0,0,40,4374,277.00865,99.8070526123047,,,,,,,,,,,,,0,,,,-0.0049,,,,,,281.4850769,,,,
,19850023.6,277.9496765,99.8070526123047,1.03590628999182E-5,3.60348918285735E-7,1,0.999253354069792,40.0298881530762,1.98184607684345,14.3299996852875,0.000116892432686058,1.72162151676446E-5,0.25,-2.63216507700921E-7,1.03671087531992E-5,-2.55727777711872E-7,277.9496765,277.9496765,99.8070526123047,99.8070526123047,53.6353489896211,19.5541278188324,28.224119,0,0,0,40,4374,273.4676,99.8070526123047,,,,,,,,,,,,,0,,,,0,,,,,,277.9496765,,,,
,19850162.505,274.4909973,99.8070526123047,1.00895261901419E-5,3.92038553898078E-7,1,0.999253354069792,40.0298881530762,1.98194364720748,14.3600003793836,0.000113044628413608,2.15348410027904E-5,0.25,1.67467257343457E-7,1.00982948429648E-5,1.75219464756397E-7,274.4909973,274.4909973,99.8070526123047,99.8070526123047,53.8260663483134,19.5490538399663,27.844467,0,0,0,40,4374,269.9882,99.8070526123047,,,,,,,,,,,,,0,,,,0,,,,,,274.4909973,,,,
,19850304.66,270.9754333,99.8070526123047,1.01690903351199E-5,3.58505933845138E-7,1,0.999253354069792,40.0298881530762,1.98193841776535,14.3699999898672,0.000114391732417688,1.91597602299653E-5,0.25,-5.80301191334879E-8,1.01793777350058E-5,-5.03002823104303E-8,270.9754333,270.9754333,99.8070526123047,99.8070526123047,53.7150750985826,19.549771272062,28.224119,0,0,0,40,4374,266.4208,99.8070526123047,,,,,,,,,,,,,0,,,,0,,,,,,270.9754333,,,,
,19850446.205,267.4618835,99.8070526123047,1.08415644381757E-5,3.77255772416416E-7,1,0.999253354069792,40.0298881530762,1.981871404667,14.3600003793836,0.000122269176490286,1.86899712483142E-5,0.25,-2.16706102848365E-7,1.08540135010477E-5,-2.08513721135005E-7,267.4618835,267.4618835,99.8070526123047,99.8070526123047,53.9167352565442,19.5512363703724,27.464817,0,0,0,40,4374,262.8875,99.8070526123047,,,,,,,,,,,,,0,,,,-0.0049,,,,,,267.4618835,,,,
,19850585.555,263.9412842,99.8070526123047,1.0335145851423E-5,3.70989060750416E-7,1,0.999253354069792,40.0298881530762,1.99475797150489,14.3799996003509,0.00011687670066016,2.03496170245603E-5,0.25,7.23930544804421E-9,1.03481442464692E-5,1.5421914334507E-8,263.9412842,263.9412842,99.8070526123047,99.8070526123047,53.7877665508711,19.5482850300133,27.844467,0,0,0,40,4374,259.4143,99.8070526123047,,,,,,,,,,,,,0,,,,0,,,,,,263.9412842,,,,
,19850723.65,260.4915466,99.8070526123047,1.07567240521782E-5,3.55144548391233E-7,1,0.999253354069792,40.0298881530762,1.99475899840668,14.3799996003509,0.000122504748619226,1.63058698506869E-5,0.25,-4.23709888698866E-7,1.07719194604597E-5,-4.15649724824632E-7,260.4915466,260.4915466,99.8070526123047,99.8070526123047,53.8643661457557,19.5487160281913,27.844467,0,0,0,40,4374,255.9578,99.8070526123047,,,,,,,,,,,,,0,,,,-0.0049,,,,,,260.4915466,,,,
,19850865.835,256.9764099,99.8070526123047,1.04162170310602E-5,3.48003703577889E-7,1,0.999253354069792,40.0298881530762,1.99468287309164,14.3799996003509,0.000118904756253273,1.42491229732875E-5,0.25,-5.46747627806039E-7,1.04323481258023E-5,-5.39057012231307E-7,256.9764099,256.9764099,99.8070526123047,99.8070526123047,53.7783870086403,19.5507751441387,27.844467,0,0,0,40,4374,252.3974,99.8070526123047,,,,,,,,,,,,,0,,,,0,,,,,,256.9764099,,,,
,19851005.385,253.4882813,99.8070526123047,1.0543660248274E-5,3.11767526188173E-7,1,0.999253354069792,40.0298881530762,1.99459751211865,14.4100002944469,0.000119646385018802,1.85945648414809E-5,0.25,-1.8499651945318E-7,1.05609922058747E-5,-1.76534872675587E-7,253.4882813,253.4882813,99.8070526123047,99.8070526123047,53.9323678269288,19.5503885888395,27.844467,0,0,0,40,4374,248.921,99.8070526123047,,,,,,,,,,,,,0,,,,0,,,,,,253.4882813,,,,
,19851143.945,249.9975128,99.8070526123047,1.07969663762115E-5,3.76567470036262E-7,1,0.999253354069792,40.0298881530762,1.99481905129964,14.4100002944469,0.000123315485690151,1.46260554417481E-5,0.25,-5.80160006421563E-7,1.0816378048284E-5,-5.72050181467067E-7,249.9975128,249.9975128,99.8070526123047,99.8070526123047,53.9714492528903,19.5471679794338,27.844467,0,0,0,40,4374,245.4496,99.8070526123047,,,,,,,,,,,,,0,,,,0.00245,,,,,,249.9975128,,,,
,19851285.12,246.4574738,99.8070526123047,1.0746834335008E-5,3.18835853395674E-7,1,0.999253354069792,40.0298881530762,1.99460690859574,14.4100002944469,0.000122094762957253,1.83117458506209E-5,0.25,-2.45949780899324E-7,1.07672175429101E-5,-2.37167848566087E-7,246.4574738,246.4574738,99.8070526123047,99.8070526123047,53.9581615680634,19.5537885167976,27.464817,0,0,0,40,4374,241.92905,99.8070526123047,,,,,,,,,,,,,0,,,,0.0049,,,,,,246.4574738,,,,
,19851403.47,243.4869995,99.8070526123047,1.09918717635407E-5,2.89271209226745E-7,1,0.999253354069792,40.0298881530762,1.99479273298858,14.4499996677041,0.000124932901551174,1.85591058606526E-5,0.25,-2.67051685549287E-7,1.10138809425118E-5,-2.57985352161502E-7,243.4869995,243.4869995,99.8070526123047,99.8070526123047,53.9487820258326,19.5507591689204,27.844467,0,0,0,40,4374,238.9745,99.8070526123047,,,,,,,,,,,,,0,,,,-0.00245,,,,,,243.4869995,,,,
,19851545.22,239.9704895,99.8070526123047,1.07045623336999E-5,3.24499494855836E-7,1,0.999253354069792,40.0298881530762,1.99476682083571,14.4499996677041,0.000122220102356252,1.49674901769525E-5,0.25,-5.34856397725152E-7,1.07275586346254E-5,-5.26467277395702E-7,239.9704895,239.9704895,99.8070526123047,99.8070526123047,53.9917715943903,19.5521625954475,27.464817,0,0,0,40,4374,235.4342,99.8070526123047,,,,,,,,,,,,,0,,,,0,,,,,,239.9704895,,,,
,19851684.985,236.4474487,99.8070526123047,1.17174568524481E-5,3.19855728149609E-7,1,0.999253354069792,40.0298881530762,1.99470155388141,14.4499996677041,0.000134070465497313,1.48101570911762E-5,0.25,-7.24792459166269E-7,1.1744199439847E-5,-7.15801367789779E-7,236.4474487,236.4474487,99.8070526123047,99.8070526123047,53.9339310839672,19.548295404385,28.224119,0,0,0,40,4374,231.9381,99.8070526123047,,,,,,,,,,,,,0,,,,0,,,,,,236.4474487,,,,
touchdown = 8.99000000208616 mm,19851817.085,233.140686,99.8070526123047,1.09072342271409E-5,3.21609509662744E-7,1,0.999253354069792,40.0298881530762,1.98232159445342,14.469999819994,0.000123128349425492,1.91582119169087E-5,0.25,-1.90399329350525E-7,1.09329396568913E-5,-1.80800548144087E-7,233.140686,233.140686,99.8070526123047,99.8070526123047,53.7314892974864,19.5483504512102,27.464817,0,0,0,40,4374,228.6342,99.8070526123047,,,,,,,,,,,,,0,,,,-0.00245,,,,,,233.140686,,,,
,19851944.665,229.9807892,99.8070526123047,1.19296847862627E-5,3.73170833383895E-7,1,0.999253354069792,40.0298881530762,1.98205931274426,14.469999819994,0.000134595249969519,2.13734941469269E-5,0.25,-1.71137665541982E-7,1.1959065264226E-5,-1.60382356126237E-7,229.9807892,229.9807892,99.8070526123047,99.8070526123047,53.9847369377173,19.5563267725411,27.844467,0,0,0,40,4374,225.4526,99.8070526123047,,,,,,,,,,,,,0,,,,-0.00245,,,,,,229.9807892,,,,
,19852084.38,226.4533691,99.8070526123047,1.10668220579794E-5,3.76041191092814E-7,1,0.999253354069792,40.0298881530762,1.98193899845721,14.469999819994,0.000125533848095661,1.5991947701526E-5,0.25,-4.9985882410243E-7,1.10957418786032E-5,-4.90578367929568E-7,226.4533691,226.4533691,99.8070526123047,99.8070526123047,53.9347127124865,19.5559659407441,27.844467,0,0,0,40,4374,221.9608,99.8070526123047,,,,,,,,,,,,,0,,,,0,,,,,,226.4533691,,,,
touchdown = 9.0300003066659 mm,19852233.835,222.6954346,99.8070526123047,1.11748581126063E-5,3.30131429721536E-7,1,0.999253354069792,40.0298881530762,1.9822210491415,14.5100001245737,0.000125373145376372,2.43312969165221E-5,0.25,2.21544596407984E-7,1.12047900127615E-5,2.33034215740406E-7,222.6954346,222.6954346,99.8070526123047,99.8070526123047,53.9988062510634,19.5538506888263,27.844467,0,0,0,40,4374,218.2237,99.8070526123047,,,,,,,,,,,,,0,,,,0,,,,,,222.6954346,,,,
,19852362.75,219.4711761,99.8070526123047,1.13851599035858E-5,3.38760116020788E-7,1,0.999253354069792,40.0298881530762,1.98192158553195,14.5100001245737,0.000128418014593097,2.081320473961E-5,0.25,-1.2759320771225E-7,1.1417241161792E-5,-1.16651139686828E-7,219.4711761,219.4711761,99.8070526123047,99.8070526123047,54.0675895607557,19.5555577733628,27.464817,0,0,0,40,4374,215.0186,99.8070526123047,,,,,,,,,,,,,0,,,,0,,,,,,219.4711761,,,,
,19852502.64,215.9396667,99.8070526123047,1.13358670585591E-5,3.00930918462836E-7,1,0.999253354069792,40.0298881530762,1.98194022141168,14.5100001245737,0.000128031772042864,1.98417495628942E-5,0.25,-2.05781981070051E-7,1.13692340451907E-5,-1.94903411237396E-7,215.9396667,215.9396667,99.8070526123047,99.8070526123047,53.8971945435634,19.556714076983,27.844467,0,0,0,40,4374,211.5278,99.8070526123047,,,,,,,,,,,,,0,,,,-0.0049,,,,,,215.9396667,,,,
touchdown = 9.06999967992306 mm,19852647.295,212.3176575,99.8070526123047,1.1352500670428E-5,3.04431756245939E-7,1,0.999253354069792,40.0298881530762,1.98187145746336,14.5600000396371,0.000128275957471273,1.96127690173781E-5,0.25,-2.29405548289062E-7,1.1387312686482E-5,-2.18359113281522E-7,212.3176575,212.3176575,99.8070526123047,99.8070526123047,53.9902083373519,19.5549168396462,27.085165,0,0,0,40,4374,207.91825,99.8070526123047,,,,,,,,,,,,,0,,,,-0.00245,,,,,,212.3176575,,,,
,19852780.525,208.9741364,99.8070526123047,1.14972667314805E-5,3.66191401183342E-7,1,0.999253354069792,40.0298881530762,1.98230488714872,14.5600000396371,0.000129843641953287,2.05001268396499E-5,0.25,-1.76555344885145E-7,1.15337365066842E-5,-1.64976665313438E-7,208.9741364,208.9741364,99.8070526123047,99.8070526123047,53.8979761720826,19.5552478854338,27.844467,0,0,0,40,4374,204.59755,99.8070526123047,,,,,,,,,,,,,0,,,,0,,,,,,208.9741364,,,,
,19852919.705,205.4991913,99.8070526123047,1.09537165832266E-5,3.19621056395616E-7,1,0.999253354069792,40.0298881530762,1.98196233035735,14.5600000396371,0.000123644408134576,1.98426623358508E-5,0.25,-1.40691230034051E-7,1.09896806288955E-5,-1.29338856525846E-7,205.4991913,205.4991913,99.8070526123047,99.8070526123047,54.0879119022557,19.5601807966327,27.085165,0,0,0,40,4374,201.132,99.8070526123047,,,,,,,,,,,,,0,,,,0.0049,,,,,,205.4991913,,,,
touchdown = 9.13000013679266 mm,19853063.255,201.8884888,99.8070526123047,1.10212084223178E-5,3.24630975246058E-7,1,0.999253354069792,40.0298881530762,1.99458475247453,14.6099999547005,0.000124969999395104,2.12825974334351E-5,0.25,-3.64757004170194E-8,1.10585699914185E-5,-2.44409913859758E-8,201.8884888,201.8884888,99.8070526123047,99.8070526123047,53.9362759695249,19.5526718293915,27.464817,0,0,0,40,4374,197.544,99.8070526123047,,,,,,,,,,,,,0,,,,0,,,,,,201.8884888,,,,
,19853199.835,198.4805603,99.8070526123047,1.14482342434665E-5,2.72723074971087E-7,1,0.999253354069792,40.0298881530762,1.99430248304672,14.6099999547005,0.00013074074426449,1.67416750707425E-5,0.25,-5.11594002170419E-7,1.14888286278056E-5,-5.00471959288454E-7,198.4805603,198.4805603,99.8070526123047,99.8070526123047,54.0496121048134,19.5566695935207,27.085165,0,0,0,40,4374,194.1542,99.8070526123047,,,,,,,,,,,,,0,,,,-0.00245,,,,,,198.4805603,,,,
,19853339.475,194.9900818,99.8070526123047,1.1609357262853E-5,3.47806151723568E-7,1,0.999253354069792,40.0298881530762,1.9942348690849,14.6099999547005,0.000132364181492505,1.82855860481863E-5,0.25,-4.03778053698717E-7,1.16516880752985E-5,-3.91834371328833E-7,194.9900818,194.9900818,99.8070526123047,99.8070526123047,54.0308530203519,19.563109806225,27.464817,0,0,0,40,4374,190.6659,99.8070526123047,,,,,,,,,,,,,0,,,,0,,,,,,194.9900818,,,,
touchdown = 9.17000044137239 mm,19853478.015,191.4682159,99.8070526123047,1.11225992024732E-5,3.12818083697009E-7,1,0.999253354069792,40.0298881530762,1.98204554344234,14.6500002592802,0.000126096770603871,1.73684394517382E-5,0.25,-3.91602347094479E-7,1.11643990266622E-5,-3.79912137605424E-7,191.4682159,191.4682159,99.8070526123047,99.8070526123047,53.9495636543519,19.5569563741684,27.844467,0,0,0,40,4374,187.2041,99.8070526123047,,,,,,,,,,,,,0,,,,0.00245,,,,,,191.4682159,,,,
,19853618.695,187.9520874,99.8070526123047,1.1214817826744E-5,3.01153572365712E-7,1,0.999253354069792,40.0298881530762,1.98180925308195,14.6500002592802,0.000126294890426986,2.23840011372797E-5,0.25,3.7167494461301E-8,1.12576718474491E-5,5.08955768189645E-8,187.9520874,187.9520874,99.8070526123047,99.8070526123047,54.0605549040826,19.5588528106766,27.464817,0,0,0,40,4374,183.6934,99.8070526123047,,,,,,,,,,,,,0,,,,0,,,,,,187.9520874,,,,
,19853759.29,184.4401703,99.8070526123047,1.09191486666916E-5,3.00193428628077E-7,1,0.999253354069792,40.0298881530762,1.98149377372206,14.6599998697638,0.000122803395269656,2.26916266825556E-5,0.25,1.15616982236543E-7,1.09619428465599E-5,1.29638687175891E-7,184.4401703,184.4401703,99.8070526123047,99.8070526123047,53.8815619731788,19.5638075903066,27.085165,0,0,0,40,4374,180.1937,99.8070526123047,,,,,,,,,,,,,0,,,,0.00245,,,,,,184.4401703,,,,
touchdown = 9.22999996691942 mm,19853892.585,181.0883636,99.8070526123047,1.15223654749984E-5,3.06408321880695E-7,1,0.999253354069792,40.0298881530762,1.99461737932512,14.7099997848272,0.000131665075316383,1.6939295231832E-5,0.25,-5.09741125077579E-7,1.15694862707606E-5,-4.97121203839116E-7,181.0883636,181.0883636,99.8070526123047,99.8070526123047,53.9214250276596,19.5562926551231,26.705515,0,0,0,40,4374,176.8669,99.8070526123047,,,,,,,,,,,,,0,,,,0,,,,,,181.0883636,,,,
,19854018.205,177.9538574,99.8070526123047,1.20325144603066E-5,3.48604308114995E-7,1,0.999253354069792,40.0298881530762,1.99386862088026,14.7099997848272,0.000137091317644658,1.97938297964199E-5,0.25,-3.46623067416025E-7,1.20826137166707E-5,-3.3235736802838E-7,177.9538574,177.9538574,99.8070526123047,99.8070526123047,53.9136087424672,19.5673042665042,27.085165,0,0,0,40,4374,173.74995,99.8070526123047,,,,,,,,,,,,,0,,,,-0.0049,,,,,,177.9538574,,,,
,19854158.195,174.4393768,99.8070526123047,1.12293688587774E-5,3.30441647754562E-7,1,0.999253354069792,40.0298881530762,1.99381512366945,14.7099997848272,0.000127849232561982,1.90572223664792E-5,0.25,-2.7246039666369E-7,1.12772182739805E-5,-2.58551075893546E-7,174.4393768,174.4393768,99.8070526123047,99.8070526123047,54.027726506275,19.5689832133235,27.464817,0,0,0,40,4374,170.22445,99.8070526123047,,,,,,,,,,,,,0,,,,0,,,,,,174.4393768,,,,
touchdown = 9.30999964475632 mm,19854307.915,170.634964,99.8070526123047,1.13760056866794E-5,3.37144674830302E-7,1,0.999253354069792,40.0298881530762,1.98172107364383,14.8000000044703,0.000129431950441863,1.54635357536582E-5,0.25,-6.07612574932296E-7,1.14261906674787E-5,-5.94523334578524E-7,170.634964,170.634964,99.8070526123047,99.8070526123047,54.0496121048134,19.5652140755442,27.085165,0,0,0,40,4374,166.53055,99.8070526123047,,,,,,,,,,,,,0,,,,0,,,,,,170.634964,,,,
,19854433.775,167.4806061,99.8070526123047,1.14755961164577E-5,3.08939737851608E-7,1,0.999253354069792,40.0298881530762,1.98164152492204,14.7900003939867,0.000130305537459064,1.71298348021807E-5,0.25,-4.77622536564076E-7,1.15270678541115E-5,-4.63452912976462E-7,167.4806061,167.4806061,99.8070526123047,99.8070526123047,54.2200071220057,19.5679025592367,27.085165,0,0,0,40,4374,163.4187,99.8070526123047,,,,,,,,,,,,,0,,,,0.00245,,,,,,167.4806061,,,,
,19854571.76,163.9713287,99.8070526123047,1.14539895645828E-5,3.58409027161362E-7,1,0.999253354069792,40.0298881530762,1.98113237234672,14.7900003939867,0.000129769542625678,1.86546286329484E-5,0.25,-3.38848566149697E-7,1.15062909887102E-5,-3.23637313261822E-7,163.9713287,163.9713287,99.8070526123047,99.8070526123047,54.1387177560057,19.5717170006052,26.705515,0,0,0,40,4374,159.99565,99.8070526123047,,,,,,,,,,,,,0,,,,-0.0049,,,,,,163.9713287,,,,
touchdown = 9.32999979704618 mm,19854720.475,160.2479248,99.8070526123047,1.15709310615103E-5,3.53789254679631E-7,1,0.999253354069792,40.0298881530762,1.98137887878307,14.8200001567602,0.000130632714365187,2.1666590700465E-5,0.25,-9.29749697926421E-8,1.16245642542571E-5,-7.59196698858431E-8,160.2479248,160.2479248,99.8070526123047,99.8070526123047,53.9816104236403,19.5659779001914,27.085165,0,0,0,40,4374,156.3116,99.8070526123047,,,,,,,,,,,,,0,,,,-0.00245,,,,,,160.2479248,,,,
,19854850.28,156.9865265,99.8070526123047,1.1713706320101E-5,3.10270668586716E-7,1,0.999253354069792,40.0298881530762,1.98082529525685,14.809999614954,0.000132225557283958,2.19015169531855E-5,0.25,-9.71830717876715E-8,1.17690107830044E-5,-7.93979415916073E-8,156.9865265,156.9865265,99.8070526123047,99.8070526123047,53.9526901684288,19.5748859042838,26.325863,0,0,0,40,4374,153.07695,99.8070526123047,,,,,,,,,,,,,0,,,,0.0049,,,,,,156.9865265,,,,
,19854989.005,153.4472504,99.8070526123047,1.13418996480921E-5,3.70490483058185E-7,1,0.999253354069792,40.0298881530762,1.98124402366827,14.8200001567602,0.000129046524200175,1.55847578610355E-5,0.25,-5.93827325080196E-7,1.13972835941785E-5,-5.78417780505404E-7,153.4472504,153.4472504,99.8070526123047,99.8070526123047,54.0574283900057,19.5725246942727,26.705515,0,0,0,40,4374,149.64025,99.8070526123047,,,,,,,,,,,,,0,,,,0.00245,,,,,,153.4472504,,,,
touchdown = 9.39000025391579 mm,19855133.965,149.81427765,99.8070526123047,1.13075738807221E-5,2.3883163949847E-7,1,0.999253354069792,40.0298881530762,1.99390512504944,14.8799996823072,0.000129464101507961,1.55701809408647E-5,0.25,-5.98308766871459E-7,1.13638489792718E-5,-5.82359962895964E-7,149.7847137,149.8438416,99.8070526123047,99.8070526123047,53.9675411102942,19.5666551257916,25.946213,0,0,0,40,4374,146.03285,99.8070526123047,,,,,,,,,,,,,0,,,,0,,,,,,149.81427765,,,,
,19855266.835,146.4879913,99.8070526123047,1.15725788209826E-5,3.62097018394209E-7,1,0.999253354069792,40.0298881530762,1.99344125023246,14.8700000718236,0.000131618215979905,2.08738171736108E-5,0.25,-1.77405691942678E-7,1.16303735664632E-5,-1.58295833137994E-7,146.4879913,146.4879913,99.8070526123047,99.8070526123047,54.0589916470442,19.5737177284712,25.946213,0,0,0,40,4374,142.72725,99.8070526123047,,,,,,,,,,,,,0,,,,0,,,,,,146.4879913,,,,
,19855405.655,142.9873657,99.8070526123047,1.14322325237288E-5,3.27921879407368E-7,1,0.999253354069792,40.0298881530762,1.99414914906787,14.8700000718236,0.000129958081070922,2.13089788229993E-5,0.25,-1.16106605705667E-7,1.14901488682987E-5,-9.61927589304253E-8,142.9873657,142.9873657,99.8070526123047,99.8070526123047,54.2450192346211,19.5677781561241,25.946213,0,0,0,40,4374,139.2668,99.8070526123047,,,,,,,,,,,,,0,,,,0,,,,,,142.9873657,,,,
touchdown = 9.46000032126904 mm,19855549.76,139.3392639,99.8070526123047,1.11485623684761E-5,2.54014915426136E-7,1,0.999253354069792,40.0298881530762,2.00484662393244,14.9400001391768,0.000127999063755747,1.74110118720675E-5,0.25,-4.18890159538733E-7,1.12065116400409E-5,-4.00227710954249E-7,139.3392639,139.3392639,99.8070526123047,99.8070526123047,53.8667110313134,19.571320291638,25.946213,0,0,0,40,4374,135.6887,99.8070526123047,,,,,,,,,,,,,0,,,,0,,,,,,139.3392639,,,,
,19855684.9,135.9447937,99.8070526123047,1.16131032197322E-5,3.31218857709771E-7,1,0.999253354069792,40.0298881530762,2.00428046944223,14.9400001391768,0.000133051392444784,1.95934991908671E-5,0.25,-3.09134016322508E-7,1.16740694615268E-5,-2.88194474710484E-7,135.9447937,135.9447937,99.8070526123047,99.8070526123047,53.9933348514288,19.5807907010584,25.946213,0,0,0,40,4374,132.32315,99.8070526123047,,,,,,,,,,,,,0,,,,0.00245,,,,,,135.9447937,,,,
,19855823,132.4689331,99.8070526123047,1.14325142964296E-5,2.63588965003511E-7,1,0.999253354069792,40.0298881530762,2.0044096239099,14.9400001391768,0.000131612290264737,1.57831148063162E-5,0.25,-6.12863502679238E-7,1.14939569311568E-5,-5.92948218583749E-7,132.4689331,132.4689331,99.8070526123047,99.8070526123047,54.0074041647749,19.5847127582142,25.566563,0,0,0,40,4374,128.88505,99.8070526123047,,,,,,,,,,,,,0,,,,-0.00245,,,,,,132.4689331,,,,
touchdown = 9.53000038862228 mm,19855963.45,128.9322968,99.8070526123047,1.14169198478136E-5,2.74087023953938E-7,1,0.999253354069792,40.0298881530762,1.99356412515396,15.0199998170137,0.00012960376478994,2.23153729158297E-5,0.25,-2.84049027370013E-8,1.14778320032134E-5,-4.4054947586193E-9,128.9322968,128.9322968,99.8070526123047,99.8070526123047,53.6392571322172,19.5819401597655,25.946213,0,0,0,40,4374,125.4074,99.8070526123047,,,,,,,,,,,,,0,,,,0,,,,,,128.9322968,,,,
,19856102.415,125.4280548,99.8070526123047,1.15837671590929E-5,2.78378794904625E-7,1,0.999253354069792,40.0298881530762,1.99395325942938,15.0199998170137,0.000131632052231033,2.20630078529963E-5,0.25,-8.14122633017976E-8,1.16463596734847E-5,-5.62046645650394E-8,125.4280548,125.4280548,99.8070526123047,99.8070526123047,54.0574283900057,19.5819963554649,25.946213,0,0,0,40,4374,121.95305,99.8070526123047,,,,,,,,,,,,,0,,,,-0.0049,,,,,,125.4280548,,,,
,19856238.93,121.9881897,99.8070526123047,1.16913773192721E-5,3.13450634966225E-7,1,0.999253354069792,40.0298881530762,1.99353421039417,15.0199998170137,0.00013222913478692,2.57280367521849E-5,0.25,2.21813881606269E-7,1.1754448755689E-5,2.50138284173252E-7,121.9881897,121.9881897,99.8070526123047,99.8070526123047,54.0238183636788,19.5926667383822,25.566563,0,0,0,40,4374,118.56785,99.8070526123047,,,,,,,,,,,,,0,,,,0,,,,,,121.9881897,,,,
touchdown = 9.58999991416931 mm,19856377.79,118.4725952,99.8070526123047,1.13335535120727E-5,3.43139405368674E-7,1,0.999253354069792,40.0298881530762,1.99398616018396,15.0699997320771,0.000128603136502428,2.27324709816893E-5,0.25,1.85970370308054E-8,1.13956604584379E-5,4.63096536468091E-8,118.4725952,118.4725952,99.8070526123047,99.8070526123047,54.5443829574865,19.5779898949871,25.566563,0,0,0,40,4374,115.145,99.8070526123047,,,,,,,,,,,,,0,,,,0.00245,,,,,,118.4725952,,,,
,19856514.32,114.99427415,99.8070526123047,1.15261479783613E-5,2.82769451524741E-7,1,0.999253354069792,40.0298881530762,1.99364019410464,15.0699997320771,0.000131570855528957,1.85543591673452E-5,0.25,-3.84463899189934E-7,1.15907671731161E-5,-3.57056334169773E-7,114.9641342,115.0244141,99.8070526123047,99.8070526123047,54.1957766379096,19.5848042582391,25.186911,0,0,0,40,4374,111.7783,99.8070526123047,,,,,,,,,,,,,0,,,,-0.0049,,,,,,114.99427415,,,,
,19856654.21,111.4426575,99.8070526123047,1.15212517847276E-5,3.09537565592111E-7,1,0.999253354069792,40.0298881530762,1.99378939045536,15.0699997320771,0.000131723320648274,1.74384049070458E-5,0.25,-4.83727887268907E-7,1.15864887964464E-5,-4.55261222000003E-7,111.4426575,111.4426575,99.8070526123047,99.8070526123047,54.1199586715442,19.5814226480755,24.807261,0,0,0,40,4374,108.3282,99.8070526123047,,,,,,,,,,,,,0,,,,-0.0049,,,,,,111.4426575,,,,
touchdown = 9.63000021874905 mm,19856784.71,108.0951309,99.8070526123047,1.15325322045703E-5,2.85497558765966E-7,1,0.999253354069792,40.0298881530762,2.00465317456731,15.1100000366569,0.000132092544186757,2.01010749221622E-5,0.25,-2.61960704316637E-7,1.15974622508771E-5,-2.30563015506179E-7,108.0951309,108.0951309,99.8070526123047,99.8070526123047,54.0488304762942,19.5742695830042,25.186911,0,0,0,40,4374,105.1143,99.8070526123047,,,,,,,,,,,,,0,,,,-0.00245,,,,,,108.0951309,,,,
,19856910.3,104.9468002,99.8070526123047,1.11849370767524E-5,2.80728357715776E-7,1,0.999253354069792,40.0298881530762,2.00454612096752,15.1100000366569,0.000128393395766925,1.78560852357487E-5,0.25,-3.99384101842007E-7,1.1248422973865E-5,-3.68028684764386E-7,104.9468002,104.9468002,99.8070526123047,99.8070526123047,53.8956312865249,19.5839684278874,25.186911,0,0,0,40,4374,102.01915,99.8070526123047,,,,,,,,,,,,,0,,,,0.00245,,,,,,104.9468002,,,,
,19857047.4,101.4460983,99.8070526123047,1.12542355876689E-5,3.02914780556927E-7,1,0.999253354069792,40.0298881530762,2.00429501335565,15.1100000366569,0.000128749441949235,2.03737028664111E-5,0.25,-1.92709211731693E-7,1.13174095463102E-5,-1.57908153229297E-7,101.4460983,101.4460983,99.8070526123047,99.8070526123047,53.7869849223518,19.5871443963173,24.427608,0,0,0,40,4374,98.62065,99.8070526123047,,,,,,,,,,,,,0,,,,0.00245,,,,,,101.4460983,,,,
touchdown = 9.73000004887581 mm,19857199.995,97.6380005,99.8070526123047,1.12782818112184E-5,3.11301066197993E-7,1,0.999253354069792,40.0298881530762,1.98111237910104,15.2099998667836,0.000127837320949214,1.88182172798916E-5,0.25,-3.17422359812492E-7,1.13416658137398E-5,-2.80635327792447E-7,97.6380005,97.6380005,99.8070526123047,99.8070526123047,53.6001757062557,19.5796708390582,24.427608,0,0,0,40,4374,94.835,99.8070526123047,,,,,,,,,,,,,0,,,,-0.0049,,,,,,97.6380005,,,,
,19857325.365,94.4772873,99.8070526123047,1.16047598340795E-5,2.71286878794364E-7,1,0.999253354069792,40.0298881530762,1.98105050258509,15.2200004085898,0.000130753164903919,2.37589824345225E-5,0.25,6.08879303539383E-8,1.16680708090609E-5,1.03312054794393E-7,94.4772873,94.4772873,99.8070526123047,99.8070526123047,53.8588947461211,19.5789296203539,24.807261,0,0,0,40,4374,91.7226,99.8070526123047,,,,,,,,,,,,,0,,,,0,,,,,,94.4772873,,,,
,19857463.015,90.8903656,99.8070526123047,1.1754864536153E-5,2.79605906730501E-7,1,0.999253354069792,40.0298881530762,1.98082588976635,15.2200004085898,0.000133120575182912,2.00933598444104E-5,0.25,-2.93233853044686E-7,1.18194540052831E-5,-2.49229942462017E-7,90.8903656,90.8903656,99.8070526123047,99.8070526123047,53.8057440068134,19.5867869482544,24.427608,0,0,0,40,4374,88.3498,99.8070526123047,,,,,,,,,,,,,0,,,,0.00245,,,,,,90.8903656,,,,
touchdown = 9.80000011622906 mm,19857607.805,87.1810303,99.8070526123047,1.13199512737355E-5,2.68413363518053E-7,1,0.999253354069792,40.0298881530762,1.99393028412464,15.2899995446205,0.00012871750438473,2.10184777043401E-5,0.25,-1.49159963520937E-7,1.13803643054514E-5,-1.02773046808827E-7,87.1441269,87.2179337,99.8070526123047,99.8070526123047,53.9268964272942,19.5683413140875,24.047956,0,0,0,40,4374,84.8486,99.8070526123047,,,,,,,,,,,,,0,,,,-0.0049,,,,,,87.1810303,,,,
,19857733.535,83.9401627,99.8070526123047,1.15000006882719E-5,3.06663389982325E-7,1,0.999253354069792,40.0298881530762,1.99361805616466,15.2799999341369,0.000130675922078032,2.16386898455274E-5,0.25,-1.29008401139128E-7,1.1559701038393E-5,-7.85153410307717E-8,83.9401627,83.9401627,99.8070526123047,99.8070526123047,53.9909899658711,19.579059744887,23.288654,0,0,0,40,4374,81.76225,99.8070526123047,,,,,,,,,,,,,0,,,,0,,,,,,83.9401627,,,,
,19857870.605,80.4571533,99.8070526123047,1.13697757722984E-5,3.34071706026534E-7,1,0.999253354069792,40.0298881530762,1.99364206166546,15.2799999341369,0.000129240694120598,2.10047935476275E-5,0.25,-1.65272783631704E-7,1.14267272354592E-5,-1.11729262257544E-7,80.4571533,80.4571533,99.8070526123047,99.8070526123047,54.0206918496019,19.583779711489,23.668306,0,0,0,40,4374,78.4205,99.8070526123047,,,,,,,,,,,,,0,,,,0.0049,,,,,,80.4571533,,,,
touchdown = 9.87000018358231 mm,19858010.025,76.8794098,99.8070526123047,1.1641438556657E-5,2.43539726616872E-7,1,0.999253354069792,40.0298881530762,1.99358824809892,15.3500000014901,0.000132386808675498,2.09590429133224E-5,0.25,-2.21296294712715E-7,1.16969221595462E-5,-1.62362628679358E-7,76.8794098,76.8794098,99.8070526123047,99.8070526123047,53.8542049750057,19.5846044919969,23.668306,0,0,0,40,4374,75.0048,99.8070526123047,,,,,,,,,,,,,0,,,,0.00245,,,,,,76.8794098,,,,
,19858145.825,73.4493408,99.8070526123047,1.15852233348412E-5,3.26933087903927E-7,1,0.999253354069792,40.0298881530762,1.99314071910227,15.3599996119738,0.000131797577640346,2.01602996914871E-5,0.25,-2.85297604718609E-7,1.16368843350748E-5,-2.22360095211241E-7,73.4493408,73.4493408,99.8070526123047,99.8070526123047,54.0871302737365,19.5909730587804,23.288654,0,0,0,40,4374,71.6624,99.8070526123047,,,,,,,,,,,,,0,,,,0,,,,,,73.4493408,,,,
,19858282.665,69.9675751,99.8070526123047,1.12692259360127E-5,2.51824203880732E-7,1,0.999253354069792,40.0298881530762,1.99308207424893,15.3599996119738,0.000128188633278081,1.93503356792341E-5,0.25,-3.04335995805872E-7,1.13147263869806E-5,-2.38465451448873E-7,69.9675751,69.9675751,99.8070526123047,99.8070526123047,53.8690559168711,19.5966602523366,23.288654,0,0,0,40,4374,68.2739,99.8070526123047,,,,,,,,,,,,,0,,,,0.0049,,,,,,69.9675751,,,,
touchdown = 9.92999970912933 mm,19858420.985,66.4411469,99.8070526123047,1.13973933119979E-5,2.72315391648425E-7,1,0.999253354069792,40.0298881530762,1.99342474634636,15.4100004583597,0.000129303313566,2.12002193704678E-5,0.25,-1.67876427760901E-7,1.14362031901119E-5,-9.5861596650043E-8,66.4411469,66.4411469,99.8070526123047,99.8070526123047,53.9472187687942,19.5910207348989,22.909004,0,0,0,40,4374,64.85035,99.8070526123047,,,,,,,,,,,,,0,,,,0,,,,,,66.4411469,,,,
,19858559.245,62.9458046,99.8070526123047,1.16834243612894E-5,2.75463848949848E-7,1,0.999253354069792,40.0298881530762,1.99326775545856,15.4200000688434,0.000132377473525992,2.21117866966081E-5,0.25,-1.41687639232022E-7,1.17150266331827E-5,-6.30927825033162E-8,62.9458046,62.9458046,99.8070526123047,99.8070526123047,53.9409657406403,19.5948455483491,22.909004,0,0,0,40,4374,61.45665,99.8070526123047,,,,,,,,,,,,,0,,,,0,,,,,,62.9458046,,,,
,19858694.765,59.4788132,99.8070526123047,1.10410413500412E-5,3.30384895119212E-7,1,0.999253354069792,40.0298881530762,1.99332634175845,15.4100004583597,0.000125274138002237,1.93738541887614E-5,0.25,-2.70923595817989E-7,1.10630611344821E-5,-1.93151221064641E-7,59.4788132,59.4788132,99.8070526123047,99.8070526123047,54.180144067525,19.5940587640091,22.149702,0,0,0,40,4374,58.1295,99.8070526123047,,,,,,,,,,,,,0,,,,0,,,,,,59.4788132,,,,
touchdown = 10.0100003182888 mm,19858831.57,55.9761581,99.8070526123047,1.1417446841525E-5,2.42129142710174E-7,1,0.999253354069792,40.0298881530762,2.00430564692473,15.4900001361966,0.000130195639244151,1.96267616286421E-5,0.25,-3.26548852747273E-7,1.1430066982539E-5,-2.43175128505511E-7,55.9761581,55.9761581,99.8070526123047,99.8070526123047,54.2622150620442,19.5925722470539,21.770052,0,0,0,40,4374,54.78225,99.8070526123047,,,,,,,,,,,,,0,,,,0.00245,,,,,,55.9761581,,,,
,19858969.625,52.4599533,99.8070526123047,1.13793711901619E-5,2.75562706748043E-7,1,0.999253354069792,40.0298881530762,2.00405519211459,15.4900001361966,0.000129485570036211,2.02492391716578E-5,0.25,-2.64123688939565E-7,1.13798579981577E-5,-1.79448647226157E-7,52.4599533,52.4599533,99.8070526123047,99.8070526123047,53.6884997289287,19.5984528904746,21.3904,0,0,0,40,4374,51.392,99.8070526123047,,,,,,,,,,,,,0,,,,0,,,,,,52.4599533,,,,
,19859104.71,48.9857674,99.8070526123047,1.13364180233341E-5,3.08133835149933E-7,1,0.999253354069792,40.0298881530762,2.00425225228946,15.4900001361966,0.000129197246225462,1.83690407659626E-5,0.25,-4.20364853130838E-7,1.13263546185552E-5,-3.36058225195446E-7,48.9857674,48.9857674,99.8070526123047,99.8070526123047,54.1144872719096,19.5969318464738,21.01075,0,0,0,40,4370,48.0954,99.8070526123047,,,,,,,,,,,,,0,,,,-0.0049,,,,,,48.9857674,,,,
,19859240.605,45.4982109,99.8070526123047,1.1168222026052E-5,3.04226647203786E-7,1,0.999253354069792,40.0298881530762,1.99270437438865,15.5300004407763,0.000125786654211666,2.16704581433481E-5,0.25,-8.3783194812467E-8,1.11445563278327E-5,-3.21738598707069E-9,45.4982109,45.4982109,99.8070526123047,99.8070526123047,53.8245030912749,19.6006776235602,20.251448,0,0,0,40,4370,44.7798,99.8070526123047,,,,,,,,,,,,,0,,,,0,,,,,,45.4982109,,,,
,19859379.775,41.9448013,99.8070526123047,1.15567123503012E-5,2.82192086380051E-7,1,0.999253354069792,40.0298881530762,1.99305835145059,15.5300004407763,0.000130640378029476,1.91715108549156E-5,0.25,-3.70715314889121E-7,1.15231143223066E-5,-2.90250666848944E-7,41.9448013,41.9448013,99.8070526123047,99.8070526123047,54.2731578613134,19.599107509905,19.871798,0,0,0,40,4370,41.3495,99.8070526123047,,,,,,,,,,,,,0,,,,0,,,,,,41.9448013,,,,
,19859515.125,38.4839745,99.8070526123047,1.15844143814124E-5,2.94565026324955E-7,1,0.999253354069792,40.0298881530762,1.99304649040467,15.54000005126,0.000130882682028721,1.90017379243485E-5,0.25,-3.84755483415157E-7,1.15415039111142E-5,-3.08454608486407E-7,38.4839745,38.4839745,99.8070526123047,99.8070526123047,53.9464371402749,19.5974755232933,19.112494,0,0,0,40,4370,38.01665,99.8070526123047,,,,,,,,,,,,,0,,,,-0.00245,,,,,,38.4839745,,,,
,19859653.91,34.9758377,99.8070526123047,1.1181809248689E-5,2.76418378285575E-7,1,0.999253354069792,40.0298881530762,1.99292748189373,15.5800003558397,0.000126438549494872,1.72291500735332E-5,0.25,-4.64386256495259E-7,1.11335084942175E-5,-3.94988453139692E-7,34.9758377,34.9758377,99.8070526123047,99.8070526123047,54.0253816207173,19.5965509226459,18.353191,0,0,0,40,4370,34.59525,99.8070526123047,,,,,,,,,,,,,0,,,,0,,,,,,34.9758377,,,,
,19859794.395,31.4487553,99.8070526123047,1.12694487843381E-5,3.04125556979367E-7,1,0.999253354069792,40.0298881530762,1.99279014866195,15.5800003558397,0.000127132612459388,1.86022360825454E-5,0.25,-3.52082962874383E-7,1.1214343853803E-5,-2.87183392115622E-7,31.4487553,31.4487553,99.8070526123047,99.8070526123047,54.1754542964096,19.6020551737852,18.353191,0,0,0,40,4370,31.1154,99.8070526123047,,,,,,,,,,,,,0,,,,0,,,,,,31.4487553,,,,
,19859933.675,27.9526672,99.8070526123047,1.17528191585203E-5,2.68795594034949E-7,1,0.999253354069792,40.0298881530762,1.99295051867504,15.5800003558397,0.000132161710612991,2.15680233714022E-5,0.25,-1.69417700403669E-7,1.16901714659473E-5,-1.0667925764449E-7,27.9526672,27.9526672,99.8070526123047,99.8070526123047,54.1621666115827,19.6029471367601,17.214239,0,0,0,40,4370,27.6684,99.8070526123047,,,,,,,,,,,,,0,,,,0,,,,,,27.9526672,,,,
,19860070.375,24.4960556,99.8070526123047,1.12618924927093E-5,3.40839754938366E-7,1,0.999253354069792,40.0298881530762,1.99288423269949,15.6199997290969,0.000127313411242908,1.67011527979895E-5,0.25,-5.12781434633078E-7,1.12011670829313E-5,-4.53411393942202E-7,24.4624996,24.5296116,99.8070526123047,99.8070526123047,54.1613849830634,19.6033984643931,16.834587,0,0,0,40,4370,24.2632,99.8070526123047,,,,,,,,,,,,,0,,,,-0.00245,,,,,,24.4960556,,,,
,19860209.525,20.99666405,99.8070526123047,1.1290922231076E-5,2.80125731492081E-7,1,0.999253354069792,40.0298881530762,1.99291042914016,15.6199997290969,0.000127313449903364,1.85107959789054E-5,0.25,-3.54724812828902E-7,1.12278979237678E-5,-2.977185686763E-7,20.9658566,21.0274715,99.8070526123047,99.8070526123047,54.3982184243904,19.6001397324007,16.075285,0,0,0,40,4370,20.8064,99.8070526123047,,,,,,,,,,,,,0,,,,-0.00245,,,,,,20.99666405,,,,
,19860349.02,17.4775276,99.8070526123047,1.14759821706871E-5,3.11940818642621E-7,1,0.999253354069792,40.0298881530762,1.99289074615514,15.6199997290969,0.000128992178679095,2.10820312249928E-5,0.25,-1.57658226860826E-7,1.14106059240036E-5,-1.01434692540354E-7,17.4775276,17.4775276,99.8070526123047,99.8070526123047,54.3044230020827,19.6007778082813,15.695635,0,0,0,40,4370,17.33605,99.8070526123047,,,,,,,,,,,,,0,,,,-0.00245,,,,,,17.4775276,,,,
,19860488.775,13.9600563,99.8070526123047,1.15790843888615E-5,3.09162713253775E-7,1,0.999253354069792,40.0298881530762,1.99314909693836,15.6399998813868,0.000130223094328065,2.09688916720726E-5,0.25,-1.86343304225415E-7,1.15134006815647E-5,-1.29428204289734E-7,13.9600563,13.9600563,99.8070526123047,99.8070526123047,54.505301531525,19.5926205750806,14.556682,0,0,0,40,4370,13.8499,99.8070526123047,,,,,,,,,,,,,0,,,,-0.0049,,,,,,13.9600563,,,,
,19860629.135,10.4350452,99.8070526123047,1.13764299939394E-5,3.24350964907302E-7,1,0.999253354069792,40.0298881530762,1.99308056618041,15.650000423193,0.000128220511658649,1.90257374405447E-5,0.25,-3.23587468596167E-7,1.13126579338041E-5,-2.66862536107482E-7,10.4350452,10.4350452,99.8070526123047,99.8070526123047,54.0972914444865,19.5992766311829,13.417728,0,0,0,40,4370,10.3214,99.8070526123047,,,,,,,,,,,,,0,,,,0,,,,,,10.4350452,,,,
,19861414.83,4.9982309,99.8070526123047,1.14113055555302E-5,2.66179466943695E-7,1,0.999253354069792,40.0298881530762,1.99304798769867,15.6399998813868,0.000128449000689247,2.00032399501502E-5,0.25,-2.42594692259899E-7,1.13470027915812E-5,-1.86167674406595E-7,4.9982309,4.9982309,99.8070526123047,99.8070526123047,54.3059862591211,19.5880205597546,8.861917,0,0,0,40,4369,5.0229,99.8070526123047,,,,,,,,,,,,,0,,,,0,,,,,,4.9982309,,,,