File: data/monolayers/magneticStructure/ML_Ac_CoFe_C/PPMS/data/DD205_4_ZFCW_100OE.DAT
[Header]
; VSM Data File (default extension .dat)
; Copyright (c) 2003-2013, Quantum Design, Inc. All rights reserved.
TITLE,
FILEOPENTIME,32267115.55,01/09/2019,7:07 pm
BYAPP,VSM,2.0,2.0
INFO,PPMS VSM Option Release 1.4.10 Build 1,APPNAME
INFO,Quantum Design Linear Motor Servo Controller,MOTOR_MODULE_NAME
INFO,3101-100 M1,MOTOR_HW_VERSION
INFO,MMC1014,MOTOR_SERIAL_NUMBER
INFO,SRV No X-over 01.03.11,MOTOR_SOFTWARE_VERSION
INFO,Quantum Design VSM Detection Module,VSM_MODULE_NAME
INFO,3101-150 F0,VSM_HW_VERSION
INFO,VSM707,VSM_SERIAL_NUMBER
INFO,VSM No X-over 01.02.05 May 20 2008 13:51:47,VSM_SOFTWARE_VERSION
INFO,704,PREAMP_SERIAL_NUMBER
INFO,822,COIL_SERIAL_NUMBER
INFO,0,MOMENT_UNITS
INFO,DD205_4,SAMPLE_MATERIAL
INFO,Monolayer,SAMPLE_COMMENT
INFO,29.55,SAMPLE_MASS
INFO,,SAMPLE_VOLUME
INFO,,SAMPLE_MOLECULAR_WEIGHT
INFO,,SAMPLE_SIZE
INFO,,SAMPLE_SHAPE
DATATYPE,COMMENT,1
DATATYPE,TIME,2
STARTUPAXIS,X,2
STARTUPAXIS,Y1,5
[Data]
Comment,Time Stamp (sec),Temperature (K),Magnetic Field (Oe),Moment (emu),M. Std. Err. (emu),Transport Action,Averaging Time (sec),Frequency (Hz),Peak Amplitude (mm),Center Position (mm),Coil Signal' (mV),Coil Signal" (mV),Range (mV),M. Quad. Signal (emu),M. Raw' (emu),M. Raw" (emu),Min. Temperature (K),Max. Temperature (K),Min. Field (Oe),Max. Field (Oe),Mass (grams),Motor Lag (deg),Pressure (Torr),VSM Status (code),Motor Status (code),Measure Status (code),Measure Count,PPMS Status (code),System Temp. (K),System Field (Oe),Sample Position (deg),Bridge 1 Resistance (ohms),Bridge 1 Excitation (에),Bridge 2 Resistance (ohms),Bridge 2 Excitation (에),Bridge 3 Resistance (ohms),Bridge 3 Excitation (에),Bridge 4 Resistance (ohms),Bridge 4 Excitation (에),Signal 1 Vin (V),Signal 2 Vin (V),Digital Inputs (code),Drive 1 Iout (mA),Drive 1 Ipower (W),Drive 2 Iout (mA),Drive 2 Ipower (W),Pressure (),Map 20 (),Map 21 (),Map 22 (),Map 23 (),Map 24 (),Map 25 (),Map 26 (),Map 27 (),Map 28 (),Map 29 ()
,32279907.05,4.9926195,99.4112396240234,,,2,,,,21.2100004553795,,,,,,,4.9926195,4.9926195,99.4112396240234,99.4112396240234,,,8.861917,,,,-99999999,4373,5.005,99.4112396240234,,,,,,,,,,,,,,,,,,,,,,,4.9926195,,,,
,32280108.36,7.5655055,99.4112396240234,-2.40665110876887E-7,2.9658437545787E-7,1,0.999253354069792,40.0298881530762,1.99734798355396,21.1999993771315,-2.08507044060321E-6,-3.96770240023268E-6,0.25,-3.10355231811487E-7,-2.37787117484441E-7,-3.09734761952481E-7,7.5655055,7.5655055,99.4112396240234,99.4112396240234,56.4179465180829,20.4792084390268,10.00087,0,0,0,40,4370,7.62825,99.4112396240234,,,,,,,,,,,,,0,,,,-0.0049,,,,,,7.5655055,,,,
,32280248.405,11.016613,99.4112396240234,-3.04827321654862E-7,2.57392205113076E-7,1,0.999253354069792,40.0298881530762,1.99733693818786,21.1999993771315,-2.93976775451387E-6,-3.34259252531146E-6,0.25,-2.43335108734647E-7,-3.01902885021054E-7,-2.4340755898344E-7,11.016613,11.016613,99.4112396240234,99.4112396240234,56.6352392464291,20.4848297830981,11.519473,0,0,0,40,4370,11.1426,99.4112396240234,,,,,,,,,,,,,0,,,,0.0049,,,,,,11.016613,,,,
,32280388.77,14.5381746,99.4112396240234,-2.17748877363485E-7,3.03876046877781E-7,1,0.999253354069792,40.0298881530762,1.99706776219622,21.1999993771315,-2.2946714978227E-6,-1.28940356564297E-6,0.25,-7.60957318326148E-8,-2.16129446192173E-7,-7.67082019395487E-8,14.5381746,14.5381746,99.4112396240234,99.4112396240234,56.7071490701983,20.485785292559,12.278775,0,0,0,40,4370,14.6774,99.4112396240234,,,,,,,,,,,,,0,,,,0,,,,,,14.5381746,,,,
,32280529.355,18.0009308,99.4112396240234,-3.79530458896844E-7,3.16667062357085E-7,1,0.999253354069792,40.0298881530762,1.9971524982683,21.1999993771315,-4.28779300718056E-6,-6.24941009425836E-7,0.25,1.17748963490967E-8,-3.77400398628251E-7,9.87642970577644E-9,18.0009308,18.0009308,99.4112396240234,99.4112396240234,56.9275683126214,20.4906108080174,13.417728,0,0,0,40,4370,18.2061,99.4112396240234,,,,,,,,,,,,,0,,,,0,,,,,,18.0009308,,,,
,32280671.75,21.5623074,99.4112396240234,-2.89024203077859E-7,2.6002398334698E-7,1,0.999253354069792,40.0298881530762,1.99710944079204,21.1999993771315,-3.14174508857116E-6,-1.17195863429285E-6,0.25,-5.29577664726606E-8,-2.87114313917766E-7,-5.4071496518131E-8,21.5623074,21.5623074,99.4112396240234,99.4112396240234,56.9799374234099,20.48837980768,13.038077,0,0,0,40,4370,21.7755,99.4112396240234,,,,,,,,,,,,,0,,,,-0.00245,,,,,,21.5623074,,,,
,32280810.68,25.0147514,99.4112396240234,-3.61872895783663E-7,3.2806135226234E-7,1,0.999253354069792,40.0298881530762,1.99703964776225,21.1999993771315,-2.9332139626891E-6,-7.0945628920844E-6,0.25,-5.67009986230286E-7,-3.56979241995698E-7,-5.65692665382226E-7,25.0147514,25.0147514,99.4112396240234,99.4112396240234,56.8071975206598,20.4952437776933,13.797379,0,0,0,40,4370,25.2877,99.4112396240234,,,,,,,,,,,,,0,,,,-0.0049,,,,,,25.0147514,,,,
,32280954.08,28.5438766,99.4112396240234,-5.83612241336817E-7,3.13857862453979E-7,1,0.999253354069792,40.0298881530762,1.99680638792606,21.1999993771315,-5.6199034263864E-6,-6.43812940809387E-6,0.25,-4.68919482676783E-7,-5.78002504840011E-7,-4.69571017500226E-7,28.5438766,28.5438766,99.4112396240234,99.4112396240234,56.8806706014676,20.4945905164918,14.556682,0,0,0,40,4370,28.8973,99.4112396240234,,,,,,,,,,,,,0,,,,-0.0049,,,,,,28.5438766,,,,
,32281094.2,32.0018768,99.4112396240234,2.09660278538621E-7,2.90534702965326E-7,1,0.999253354069792,40.0298881530762,1.99697801804039,21.1999993771315,2.76525915866288E-6,-1.86491186535753E-6,0.25,-2.03307248410628E-7,2.09804125940558E-7,-2.01107081781671E-7,32.0018768,32.0018768,99.4112396240234,99.4112396240234,56.9510171681983,20.4938051826291,14.556682,0,0,0,40,4370,32.43165,99.4112396240234,,,,,,,,,,,,,0,,,,0,,,,,,32.0018768,,,,
,32281236.29,35.5236969,99.4112396240234,-1.88379613237221E-7,3.25910714997978E-7,1,0.999253354069792,40.0298881530762,1.99669294448766,21.1999993771315,-1.36438099980213E-6,-4.59344332844694E-6,0.25,-3.74698070055437E-7,-1.85244825902923E-7,-3.74249149213764E-7,35.5236969,35.5236969,99.4112396240234,99.4112396240234,57.7005989181407,20.4979473204621,15.315984,0,0,0,40,4370,36.0085,99.4112396240234,,,,,,,,,,,,,0,,,,0.00245,,,,,,35.5236969,,,,
,32281376.48,39.0014725,99.4112396240234,-2.47646145708872E-7,2.8039912953027E-7,1,0.999253354069792,40.0298881530762,1.99651983412104,21.1999993771315,-2.15544878998752E-6,-4.01890126617866E-6,0.25,-3.12679001586767E-7,-2.44684459855157E-7,-3.13211418000781E-7,39.0014725,39.0014725,99.4112396240234,99.4112396240234,57.0112025641791,20.494017527491,15.695635,0,0,0,40,4370,39.55075,99.4112396240234,,,,,,,,,,,,,0,,,,0,,,,,,39.0014725,,,,
,32281517.225,42.5056229,99.4112396240234,-2.28247527638364E-7,2.93850074265751E-7,1,0.999253354069792,40.0298881530762,1.99631370961315,21.1999993771315,-2.08827246218441E-6,-3.14376460978793E-6,0.25,-2.38090729818382E-7,-2.25966489554662E-7,-2.3907057348803E-7,42.5056229,42.5056229,99.4112396240234,99.4112396240234,56.8501870892175,20.5008310996453,16.075285,0,0,0,40,4370,43.108,99.4112396240234,,,,,,,,,,,,,0,,,,-0.0049,,,,,,42.5056229,,,,
,32281661.86,46.0434799,99.4112396240234,1.47790977571432E-7,3.27677180250702E-7,1,0.999253354069792,40.0298881530762,1.99632500506869,21.1999993771315,2.25560983565373E-6,-2.97167646586192E-6,0.25,-2.90212268913417E-7,1.49689439223119E-7,-2.88677373432347E-7,46.0434799,46.0434799,99.4112396240234,99.4112396240234,57.0299616486406,20.5064940703997,16.834587,0,0,0,40,4370,46.778,99.4112396240234,,,,,,,,,,,,,0,,,,0,,,,,,46.0434799,,,,
,32281805.095,49.5332241,99.4112396240234,-2.57811276580506E-7,3.15646750973511E-7,1,0.999253354069792,40.0298881530762,1.98496581676074,21.1800001561642,-1.79851356543808E-6,-6.59929659624456E-6,0.25,-5.41420597825456E-7,-2.53676856231251E-7,-5.43117340028985E-7,49.5067978,49.5596504,99.4112396240234,99.4112396240234,57.2339666921599,20.5073522595944,16.834587,0,0,0,40,4370,50.42805,99.4112396240234,,,,,,,,,,,,,0,,,,-0.00245,,,,,,49.5332241,,,,
,32281948.94,53.0108032,99.4112396240234,-1.68161065546385E-7,3.10837268802727E-7,1,0.999253354069792,40.0298881530762,1.98480180268481,21.1800001561642,-1.34931672677963E-6,-3.33984455912134E-6,0.25,-2.66911896755139E-7,-1.66318288613404E-7,-2.68343587821149E-7,53.0108032,53.0108032,99.4112396240234,99.4112396240234,57.0807675023906,20.5084361105942,17.973541,0,0,0,40,4374,54.1131,99.4112396240234,,,,,,,,,,,,,0,,,,-0.0049,,,,,,53.0108032,,,,
,32282093.69,56.5336914,99.4112396240234,1.12314638126027E-7,3.53399575327419E-7,1,0.999253354069792,40.0298881530762,1.98492500022067,21.1800001561642,1.83061375746661E-6,-2.92463481592905E-6,0.25,-2.80162823612575E-7,1.14507491754925E-7,-2.79863352308401E-7,56.5336914,56.5336914,99.4112396240234,99.4112396240234,57.2284952925253,20.5077874283291,19.112494,0,0,0,40,4374,57.8548,99.4112396240234,,,,,,,,,,,,,0,,,,-0.0049,,,,,,56.5336914,,,,
,32282217.65,59.5653915,99.4112396240234,-4.1040428605844E-7,2.68402537734886E-7,1,0.999253354069792,40.0298881530762,1.99623061247375,21.1599990725517,-4.11018159080097E-6,-3.81917948347201E-6,0.25,-2.63654234706154E-7,-4.09660791966743E-7,-2.67123323348162E-7,59.5653915,59.5653915,99.4112396240234,99.4112396240234,57.2425646058714,20.5009393286248,19.492144,0,0,0,40,4374,61.0104,99.4112396240234,,,,,,,,,,,,,0,,,,0.0049,,,,,,59.5653915,,,,
,32282358.815,63.0221558,99.4112396240234,-1.13509143411354E-8,3.29278188478222E-7,1,0.999253354069792,40.0298881530762,1.99614688523606,21.1599990725517,6.84094531061201E-7,-4.55934108580832E-6,0.25,-4.00389155686568E-7,-8.82542363967767E-9,-4.01784500699355E-7,63.0221558,63.0221558,99.4112396240234,99.4112396240234,57.098744958333,20.5045649502079,19.492144,0,0,0,40,4374,64.5695,99.4112396240234,,,,,,,,,,,,,0,,,,-0.0049,,,,,,63.0221558,,,,
,32282499.75,66.5297852,99.4112396240234,-2.65240432756054E-7,2.89249334854385E-7,1,0.999253354069792,40.0298881530762,1.99593877423448,21.1599990725517,-2.31716165947235E-6,-4.39659397540623E-6,0.25,-3.40435555306254E-7,-2.6424436824693E-7,-3.43347643959239E-7,66.5297852,66.5297852,99.4112396240234,99.4112396240234,57.2019199228714,20.5134907785197,19.492144,0,0,0,40,4374,68.12985,99.4112396240234,,,,,,,,,,,,,0,,,,0,,,,,,66.5297852,,,,
,32282621.93,69.5073395,99.4112396240234,-8.02181847373365E-8,3.68132515729447E-7,1,0.999253354069792,40.0298881530762,1.99584136253339,21.1500003933907,-5.48136694071404E-7,-2.19027140308564E-6,0.25,-1.7882110717776E-7,-7.95650778376133E-8,-1.80042990022193E-7,69.5073395,69.5073395,99.4112396240234,99.4112396240234,57.3316702570638,20.5104794478688,20.251448,0,0,0,40,4374,71.2202,99.4112396240234,,,,,,,,,,,,,0,,,,-0.0049,,,,,,69.5073395,,,,
,32282763.985,73.0508804,99.4112396240234,-1.12791490347867E-7,2.93967420122409E-7,1,0.999253354069792,40.0298881530762,1.9958413171811,21.1500003933907,-6.87646799986313E-7,-3.55636293348817E-6,0.25,-2.93372810628542E-7,-1.11804784330182E-7,-2.95337765738651E-7,73.0508804,73.0508804,99.4112396240234,99.4112396240234,57.3895107674868,20.5096066710986,20.251448,0,0,0,40,4374,74.8078,99.4112396240234,,,,,,,,,,,,,0,,,,-0.00245,,,,,,73.0508804,,,,
,32282903.61,76.5110474,99.4112396240234,1.02755492482005E-7,3.35231433094273E-7,1,0.999253354069792,40.0298881530762,1.99581714507726,21.1500003933907,1.50618972509117E-6,-1.70798734823907E-6,0.25,-1.68717878866604E-7,1.04077242310546E-7,-1.69069296741904E-7,76.5110474,76.5110474,99.4112396240234,99.4112396240234,57.166746639506,20.508132505694,20.251448,0,0,0,40,4374,78.3463,99.4112396240234,,,,,,,,,,,,,0,,,,0,,,,,,76.5110474,,,,
,32283048.345,80.077095,99.4112396240234,-1.02347925945936E-7,3.10611128083903E-7,1,0.999253354069792,40.0298881530762,1.98416844403072,21.1200006306171,-1.41454981102444E-6,1.25777529740012E-6,0.25,1.2953037952404E-7,-1.03455943607719E-7,1.29754916295137E-7,80.077095,80.077095,99.4112396240234,99.4112396240234,57.3293253715061,20.5159389517183,20.631098,0,0,0,40,4374,82.03345,99.4112396240234,,,,,,,,,,,,,0,,,,-0.00245,,,,,,80.077095,,,,
,32283187.155,83.530159,99.4112396240234,2.48480666860523E-8,3.27834309363156E-7,1,0.999253354069792,40.0298881530762,1.98430290811213,21.1200006306171,1.33485327114367E-6,-5.91362494001005E-6,0.25,-5.28028243781259E-7,2.71518641914571E-8,-5.30770750609067E-7,83.530159,83.530159,99.4112396240234,99.4112396240234,57.8928795338715,20.51631633729,21.01075,0,0,0,40,4374,85.5244,99.4112396240234,,,,,,,,,,,,,0,,,,0,,,,,,83.530159,,,,
,32283330.43,87.0554199,99.4112396240234,-1.65392972054503E-7,2.90074296796137E-7,1,0.999253354069792,40.0298881530762,1.98415350134224,21.1200006306171,-1.24017045804877E-6,-3.88715372545331E-6,0.25,-3.14973446691165E-7,-1.65100761002449E-7,-3.17339363598429E-7,87.0554199,87.0554199,99.4112396240234,99.4112396240234,57.0026046504676,20.5205018831172,20.631098,0,0,0,40,4374,89.1176,99.4112396240234,,,,,,,,,,,,,0,,,,0.00245,,,,,,87.0554199,,,,
,32283472.06,90.6056671,99.4112396240234,-1.28550824042866E-7,3.24733631401172E-7,1,0.999253354069792,40.0298881530762,1.98425221076475,21.0800003260374,-1.09496388226494E-6,-2.28286540144986E-6,0.25,-1.79433342598922E-7,-1.28630031219685E-7,-1.80893543991374E-7,90.6056671,90.6056671,99.4112396240234,99.4112396240234,57.6818398336792,20.5155079528828,20.631098,0,0,0,40,4374,92.67545,99.4112396240234,,,,,,,,,,,,,0,,,,0,,,,,,90.6056671,,,,
,32283610.965,94.031311,99.4112396240234,-3.76963272588225E-7,2.48185398047548E-7,1,0.999253354069792,40.0298881530762,1.98418260525396,21.0800003260374,-3.92420856649197E-6,-2.64942216948886E-6,0.25,-1.68180004402677E-7,-3.78528216291282E-7,-1.70385063262051E-7,94.031311,94.031311,99.4112396240234,99.4112396240234,57.2863358029484,20.5192610910503,21.01075,0,0,0,40,4374,96.16495,99.4112396240234,,,,,,,,,,,,,0,,,,0.00245,,,,,,94.031311,,,,
,32283751.385,97.5100403,99.4112396240234,-1.08328424575534E-7,3.21052277645441E-7,1,0.999253354069792,40.0298881530762,1.98418616405587,21.0800003260374,-1.04236277138572E-6,-1.24774955081948E-6,0.25,-9.13994267975211E-8,-1.08656664489447E-7,-9.22563016734227E-8,97.5100403,97.5100403,99.4112396240234,99.4112396240234,57.505191788333,20.5228448840251,21.770052,0,0,0,40,4374,99.6942,99.4112396240234,,,,,,,,,,,,,0,,,,0,,,,,,97.5100403,,,,
,32283892.705,101.0247192,99.4112396240234,-1.81331672320162E-7,2.96958567846303E-7,1,0.999253354069792,40.0298881530762,1.99554583272406,21.0299994796514,-1.06312580964856E-6,-6.03868162475566E-6,0.25,-4.99730661365139E-7,-1.80892114240124E-7,-5.03102007918892E-7,101.0247192,101.0247192,99.4112396240234,99.4112396240234,57.3918556530445,20.5121700372588,21.3904,0,0,0,40,4374,103.24015,99.4112396240234,,,,,,,,,,,,,0,,,,0,,,,,,101.0247192,,,,
,32284033.905,104.53508,99.4112396240234,-2.26173576058062E-7,3.41024669773914E-7,1,0.999253354069792,40.0298881530762,1.99545208443223,21.0299994796514,-2.16925825583419E-6,-2.73119978933945E-6,0.25,-2.00751260890273E-7,-2.26900566596307E-7,-2.02517425500833E-7,104.53508,104.53508,99.4112396240234,99.4112396240234,57.6146197810253,20.5135809545492,21.770052,0,0,0,40,4374,106.7876,99.4112396240234,,,,,,,,,,,,,0,,,,-0.00245,,,,,,104.53508,,,,
,32284173.77,108.0394745,99.4112396240234,2.78818202345111E-7,2.83004947097348E-7,1,0.999253354069792,40.0298881530762,1.99556370658259,21.0299994796514,3.94065051846276E-6,-3.85611038931347E-6,0.25,-3.88296301927391E-7,2.81413145133955E-7,-3.89762099059833E-7,108.0394745,108.0394745,99.4112396240234,99.4112396240234,57.6794949481215,20.516832958614,22.149702,0,0,0,40,4374,110.3116,99.4112396240234,,,,,,,,,,,,,0,,,,0,,,,,,108.0394745,,,,
,32284315.26,111.5592957,99.4112396240234,3.68891977060717E-8,3.09269535993669E-7,1,0.999253354069792,40.0298881530762,2.00821109735794,20.9999997168779,1.04153641096033E-6,-3.46615965935621E-6,0.25,-3.09732960201162E-7,3.78657353866211E-8,-3.11384723584279E-7,111.5592957,111.5592957,99.4112396240234,99.4112396240234,57.2261504069676,20.5135661262414,21.770052,0,0,0,40,4374,113.8786,99.4112396240234,,,,,,,,,,,,,0,,,,-0.0049,,,,,,111.5592957,,,,
,32284453.77,115.0085602,99.4112396240234,2.65616214988378E-8,3.4791149420301E-7,1,0.999253354069792,40.0298881530762,1.99543589063073,20.9999997168779,6.61392211604756E-7,-2.00247666295098E-6,0.25,-1.80928449640591E-7,2.71371362946414E-8,-1.81877405975934E-7,115.0085602,115.0085602,99.4112396240234,99.4112396240234,57.3770047111791,20.5210790316633,22.149702,0,0,0,40,4374,117.3522,99.4112396240234,,,,,,,,,,,,,0,,,,0,,,,,,115.0085602,,,,
,32284595.345,118.5021057,99.4112396240234,-2.0580698690292E-7,3.58462004292678E-7,1,0.999253354069792,40.0298881530762,1.99549834026427,20.9999997168779,-1.59280110679717E-6,-4.66953716382729E-6,0.25,-3.75071734598906E-7,-2.06106222442581E-7,-3.77614216551864E-7,118.5021057,118.5021057,99.4112396240234,99.4112396240234,57.312129544083,20.5195325758173,22.149702,0,0,0,40,4374,120.9171,99.4112396240234,,,,,,,,,,,,,0,,,,0.00245,,,,,,118.5021057,,,,
,32284736.79,122.0243645,99.4112396240234,-2.09527534561253E-7,2.83410811834564E-7,1,0.999253354069792,40.0298881530762,1.99554659787857,20.9500007331371,-2.11486168760094E-6,-1.93382109763908E-6,0.25,-1.3361828926935E-7,-2.10392463588088E-7,-1.3480109863422E-7,121.9958344,122.0528946,99.4112396240234,99.4112396240234,57.0729512171983,20.5155202610941,22.149702,0,0,0,40,4374,124.4667,99.4112396240234,,,,,,,,,,,,,0,,,,0,,,,,,122.0243645,,,,
,32284876.955,125.50743485,99.4112396240234,-1.21990591812724E-7,2.69064174476827E-7,1,0.999253354069792,40.0298881530762,1.99569601174196,20.9500007331371,-2.49283778773827E-7,-6.74854025283503E-6,0.25,-5.7275922930811E-7,-1.21481086098973E-7,-5.76122396534057E-7,125.4800034,125.5348663,99.4112396240234,99.4112396240234,56.6149169049291,20.5142202450966,22.149702,0,0,0,40,4374,127.98865,99.4112396240234,,,,,,,,,,,,,0,,,,0.0049,,,,,,125.50743485,,,,
,32285019.73,129.0512543,99.4112396240234,1.3551259009562E-7,2.75839669903996E-7,1,0.999253354069792,40.0298881530762,1.9958155381809,20.9500007331371,2.01724001739102E-6,-2.46814729161204E-6,0.25,-2.40925301473885E-7,1.36712504411882E-7,-2.41953945361611E-7,129.0512543,129.0512543,99.4112396240234,99.4112396240234,56.8791073444291,20.5222761018184,22.149702,0,0,0,40,4374,131.57835,99.4112396240234,,,,,,,,,,,,,0,,,,0,,,,,,129.0512543,,,,
,32285138.73,132.0028076,99.4112396240234,1.54244971717833E-7,2.91072923347778E-7,1,0.999253354069792,40.0298881530762,1.99563501292919,20.9100004285574,2.56027511057246E-6,-4.32587297549902E-6,0.25,-4.07767722494261E-7,1.55835941207315E-7,-4.09642917833262E-7,132.0028076,132.0028076,99.4112396240234,99.4112396240234,57.4496961634676,20.5139053117771,23.288654,0,0,0,40,4374,134.5561,99.4112396240234,,,,,,,,,,,,,0,,,,0,,,,,,132.0028076,,,,
,32285278.97,135.5215149,99.4112396240234,1.27417678590696E-7,2.80752730313238E-7,1,0.999253354069792,40.0298881530762,1.99586437289372,20.9100004285574,1.81393951168229E-6,-1.8490969223671E-6,0.25,-1.8501282545691E-7,1.28421779072583E-7,-1.85751060562004E-7,135.5215149,135.5215149,99.4112396240234,99.4112396240234,56.8767624588714,20.521208701525,23.288654,0,0,0,40,4374,138.0773,99.4112396240234,,,,,,,,,,,,,0,,,,-0.0049,,,,,,135.5215149,,,,
,32285418.52,139.0052185,99.4112396240234,2.9351235026776E-7,2.83244260410094E-7,1,0.999253354069792,40.0298881530762,1.99585560082465,20.9100004285574,3.82060142213516E-6,-2.2104975435041E-6,0.25,-2.45794933350519E-7,2.95458588929847E-7,-2.46551437368045E-7,139.0052185,139.0052185,99.4112396240234,99.4112396240234,56.5797436215637,20.5252018987703,22.909004,0,0,0,40,4374,141.58305,99.4112396240234,,,,,,,,,,,,,0,,,,0.0049,,,,,,139.0052185,,,,
,32285538.68,142.0075531,99.4112396240234,2.03072000127143E-7,3.49523024817312E-7,1,0.999253354069792,40.0298881530762,1.9845396697499,20.8599995821714,2.00797387686228E-6,2.04031971947937E-6,0.25,1.45223045920585E-7,2.03861293288429E-7,1.46307506938983E-7,142.0075531,142.0075531,99.4112396240234,99.4112396240234,56.8509687177368,20.5231513021062,22.529354,0,0,0,40,4374,144.596,99.4112396240234,,,,,,,,,,,,,0,,,,0,,,,,,142.0075531,,,,
,32285681.795,145.5271149,99.4112396240234,1.79777272674342E-8,3.10872101812333E-7,1,0.999253354069792,40.0298881530762,1.98452292799849,20.8599995821714,7.31434646057278E-7,-2.99686475349178E-6,0.25,-2.68453927724699E-7,1.85064092324025E-8,-2.69771137808091E-7,145.5271149,145.5271149,99.4112396240234,99.4112396240234,57.2112994651022,20.5217226109726,23.288654,0,0,0,40,4374,148.1911,99.4112396240234,,,,,,,,,,,,,0,,,,-0.00245,,,,,,145.5271149,,,,
,32285821.155,149.0187531,99.4112396240234,-8.60409882369448E-8,3.59024717401072E-7,1,0.999253354069792,40.0298881530762,1.98428746421023,20.8599995821714,-7.11020536104407E-7,-1.66556800714167E-6,0.25,-1.32497564085305E-7,-8.62561183922933E-8,-1.3328673641116E-7,149.0187531,149.0187531,99.4112396240234,99.4112396240234,57.5997688391599,20.522558525658,22.909004,0,0,0,40,4374,151.68615,99.4112396240234,,,,,,,,,,,,,0,,,,-0.0049,,,,,,149.0187531,,,,
,32285961,152.5149536,99.4112396240234,2.04364388814982E-7,4.19314718010607E-7,1,0.999253354069792,40.0298881530762,1.99559124823508,20.8100005984306,2.79752762730467E-6,-2.33651756071245E-6,0.25,-2.41383230898436E-7,2.05722819283864E-7,-2.42240225253008E-7,152.5149536,152.5149536,99.4112396240234,99.4112396240234,57.4199942797368,20.5137505611569,23.288654,0,0,0,40,4374,155.1872,99.4112396240234,,,,,,,,,,,,,0,,,,-0.0049,,,,,,152.5149536,,,,
,32286101.75,156.0371704,99.4112396240234,2.06534883612926E-7,2.65165814555418E-7,1,0.999253354069792,40.0298881530762,1.99575874079497,20.8100005984306,2.16226673642363E-6,1.45737845904293E-6,0.25,9.24063668131349E-8,2.07379737516995E-7,9.31509527773332E-8,156.0371704,156.0371704,99.4112396240234,99.4112396240234,57.1831608384099,20.5204874589416,22.909004,0,0,0,40,4374,158.7126,99.4112396240234,,,,,,,,,,,,,0,,,,-0.0049,,,,,,156.0371704,,,,
,32286242.075,159.5559845,99.4112396240234,1.22740294277075E-7,3.28012924956441E-7,1,0.999253354069792,40.0298881530762,1.99583997105257,20.8100005984306,1.74765320176394E-6,-1.79239899049271E-6,0.25,-1.79240336477914E-7,1.23569131059401E-7,-1.79899426313974E-7,159.5559845,159.5559845,99.4112396240234,99.4112396240234,57.2042648084291,20.5140057687952,24.047956,0,0,0,40,4374,162.23395,99.4112396240234,,,,,,,,,,,,,0,,,,0,,,,,,159.5559845,,,,
,32286383.245,163.0496979,99.4112396240234,1.51624545662022E-7,3.18598371197285E-7,1,0.999253354069792,40.0298881530762,1.99564666433699,20.7599997520447,1.63834928279135E-6,7.75025360197358E-7,0.25,4.18947176592844E-8,1.52258290901762E-7,4.22969072044504E-8,163.0496979,163.0496979,99.4112396240234,99.4112396240234,56.7102755842752,20.5166743571994,24.047956,0,0,0,40,4374,165.76275,99.4112396240234,,,,,,,,,,,,,0,,,,0,,,,,,163.0496979,,,,
,32286522.795,166.5319366,99.4112396240234,2.35239999709634E-7,2.94833586333393E-7,1,0.999253354069792,40.0298881530762,1.99580269496143,20.7599997520447,3.46891960350536E-6,-4.12692125370646E-6,0.25,-4.04500528203095E-7,2.36837831033984E-7,-4.05989612930835E-7,166.5319366,166.5319366,99.4112396240234,99.4112396240234,57.0620084179291,20.5172197762212,23.288654,0,0,0,40,4374,169.2599,99.4112396240234,,,,,,,,,,,,,0,,,,0.0049,,,,,,166.5319366,,,,
,32286661.78,170.0507507,99.4112396240234,-1.92558497513586E-7,2.87603380052216E-7,1,0.999253354069792,40.0298881530762,1.99578627936747,20.7599997520447,-1.94592305280525E-6,-1.75750434282604E-6,0.25,-1.21359073487231E-7,-1.93239961181846E-7,-1.22142391985802E-7,170.0507507,170.0507507,99.4112396240234,99.4112396240234,57.4614205912561,20.5203249254986,23.288654,0,0,0,40,4374,172.7322,99.4112396240234,,,,,,,,,,,,,0,,,,0,,,,,,170.0507507,,,,
,32286800.945,173.5110016,99.4112396240234,3.29018333945093E-7,2.8310098014198E-7,1,0.999253354069792,40.0298881530762,1.99568548082847,20.7100007683039,3.26074842609813E-6,3.36932447639966E-6,0.25,2.39692942427806E-7,3.30115733831782E-7,2.41137231192109E-7,173.5110016,173.5110016,99.4112396240234,99.4112396240234,57.3332335141022,20.5169278831564,23.288654,0,0,0,40,4374,176.2076,99.4112396240234,,,,,,,,,,,,,0,,,,0,,,,,,173.5110016,,,,
,32286942.28,177.0370178,99.4112396240234,5.00427765450746E-7,3.3236002385835E-7,1,0.999253354069792,40.0298881530762,1.99547020942513,20.7100007683039,6.41846774571126E-6,-3.2732537170387E-6,0.25,-3.75500077392692E-7,5.0298009707302E-7,-3.76439975678321E-7,177.0370178,177.0370178,99.4112396240234,99.4112396240234,57.5317671579869,20.5196594563434,24.047956,0,0,0,40,4374,179.7493,99.4112396240234,,,,,,,,,,,,,0,,,,0,,,,,,177.0370178,,,,
,32287082.78,180.54815675,99.4112396240234,2.39302555032116E-7,3.39751442041566E-7,1,0.999253354069792,40.0298881530762,1.99580977586913,20.7100007683039,3.21106449120044E-6,-2.3803446636205E-6,0.25,-2.51381796534688E-7,2.40579689521218E-7,-2.52111561912864E-7,180.5214081,180.5749054,99.4112396240234,99.4112396240234,57.4926857320253,20.5166303104494,24.427608,0,0,0,40,4374,183.25785,99.4112396240234,,,,,,,,,,,,,0,,,,0,,,,,,180.54815675,,,,
,32287201.465,183.5149536,99.4112396240234,9.51109971032739E-8,3.34047438320754E-7,1,0.999253354069792,40.0298881530762,1.9956765695635,20.6599999219179,1.52520765898329E-6,-2.37973051185413E-6,0.25,-2.26292479667218E-7,9.57579429913586E-8,-2.27077774010022E-7,183.5149536,183.5149536,99.4112396240234,99.4112396240234,57.024490249006,20.5136562319552,24.047956,0,0,0,40,4374,186.2404,99.4112396240234,,,,,,,,,,,,,0,,,,0.0049,,,,,,183.5149536,,,,
,32287341.775,187.0049286,99.4112396240234,4.78157972509416E-7,3.18647531972857E-7,1,0.999253354069792,40.0298881530762,1.99554891079703,20.6599999219179,5.89019546078521E-6,-1.7417199785556E-6,0.25,-2.36638462623021E-7,4.80280303600745E-7,-2.36997340166404E-7,187.0049286,187.0049286,99.4112396240234,99.4112396240234,57.1761261817368,20.5185981042638,24.047956,0,0,0,40,4374,189.76055,99.4112396240234,,,,,,,,,,,,,0,,,,0,,,,,,187.0049286,,,,
,32287484.055,190.52034,99.4112396240234,4.04649109243917E-7,3.31343318726656E-7,1,0.999253354069792,40.0298881530762,1.99564899326342,20.6599999219179,4.71597076146866E-6,7.06088886556634E-8,0.25,-6.40787230252897E-8,4.06241138952817E-7,-6.38604074986455E-8,190.52034,190.52034,99.4112396240234,99.4112396240234,57.2152076076984,20.5141771989732,24.427608,0,0,0,40,4374,193.332,99.4112396240234,,,,,,,,,,,,,0,,,,-0.0049,,,,,,190.52034,,,,
,32287604.445,193.5578461,99.4112396240234,5.99945941737712E-7,3.45158697488048E-7,1,0.999253354069792,40.0298881530762,1.99574037842839,20.6000003963709,7.63138912823832E-6,-3.57784075780806E-6,0.25,-4.19675620110968E-7,6.02608097504713E-7,-4.20544249827679E-7,193.5578461,193.5578461,99.4112396240234,99.4112396240234,56.9525804252368,20.5162668338239,24.047956,0,0,0,40,4374,196.3395,99.4112396240234,,,,,,,,,,,,,0,,,,0,,,,,,193.5578461,,,,
,32287745.735,197.0573654,99.4112396240234,5.13358584883658E-7,3.03358290792975E-7,1,0.999253354069792,40.0298881530762,1.995647482249,20.6000003963709,6.03206303549972E-6,-2.00717891025823E-7,0.25,-1.06866238779491E-7,5.15296433440024E-7,-1.06687411654179E-7,197.026535,197.0881958,99.4112396240234,99.4112396240234,56.976810909333,20.5222440158544,24.427608,0,0,0,40,4374,199.89545,99.4112396240234,,,,,,,,,,,,,0,,,,0.0049,,,,,,197.0573654,,,,
,32287885.735,200.5357971,99.4112396240234,5.37998130547735E-7,3.20266444485343E-7,1,0.999253354069792,40.0298881530762,1.9958139189479,20.6000003963709,5.99396616561286E-6,1.67478055972478E-6,0.25,5.42565650729418E-8,5.39789580344945E-7,5.50152319885337E-8,200.5357971,200.5357971,99.4112396240234,99.4112396240234,57.3332335141022,20.5119872740367,24.427608,0,0,0,40,4374,203.40605,99.4112396240234,,,,,,,,,,,,,0,,,,-0.0049,,,,,,200.5357971,,,,
,32288024.5,204.0316772,99.4112396240234,8.40491706794417E-7,4.03835550811291E-7,1,0.999253354069792,40.0298881530762,1.99561680135454,20.5499995499849,9.82330731353546E-6,-3.95393662274905E-8,0.25,-1.49435324595092E-7,8.43441027788919E-7,-1.49056747960163E-7,204.0316772,204.0316772,99.4112396240234,99.4112396240234,57.017455592333,20.5137775413089,24.807261,0,0,0,40,4374,206.8642,99.4112396240234,,,,,,,,,,,,,0,,,,-0.0098,,,,,,204.0316772,,,,
,32288163.775,207.5094757,99.4112396240234,8.31592884778447E-7,3.05088169229106E-7,1,0.999253354069792,40.0298881530762,1.99560633444278,20.5499995499849,9.5764128112113E-6,7.77029713643377E-7,0.25,-7.58405402386204E-8,8.34339853049206E-7,-7.52358429811596E-8,207.5094757,207.5094757,99.4112396240234,99.4112396240234,56.9916618511983,20.5206890425714,24.427608,0,0,0,40,4374,210.3664,99.4112396240234,,,,,,,,,,,,,0,,,,0.00245,,,,,,207.5094757,,,,
,32288306.6,211.0482941,99.4112396240234,9.69773465947081E-7,3.14325829528148E-7,1,0.999253354069792,40.0298881530762,1.99561852560119,20.5499995499849,1.08741080646901E-5,2.58978659838806E-6,0.25,6.01212493000219E-8,9.72713471005721E-7,6.12760117812221E-8,211.0482941,211.0482941,99.4112396240234,99.4112396240234,57.4481329064291,20.5177185257964,24.807261,0,0,0,40,4374,213.9359,99.4112396240234,,,,,,,,,,,,,0,,,,-0.0049,,,,,,211.0482941,,,,
,32288444.96,214.516861,99.4112396240234,8.42653601426566E-7,3.43190405075835E-7,1,0.999253354069792,40.0298881530762,1.99579594007152,20.5000005662441,9.72126853950921E-6,6.78463643615737E-7,0.25,-8.64128730395668E-8,8.45247855050042E-7,-8.58449088047938E-8,214.516861,214.516861,99.4112396240234,99.4112396240234,57.0369963053137,20.505254454756,24.807261,0,0,0,40,4374,217.40405,99.4112396240234,,,,,,,,,,,,,0,,,,0.00245,,,,,,214.516861,,,,
,32288585.915,218.04327395,99.4112396240234,1.18535466262571E-6,4.43418014718377E-7,1,0.999253354069792,40.0298881530762,1.99550029324411,20.5000005662441,1.31998180000917E-5,3.67043331229666E-6,0.25,1.18171028573158E-7,1.18863135358912E-6,1.19647352054488E-7,218.0171814,218.0693665,99.4112396240234,99.4112396240234,57.0909286731407,20.5171141411532,24.807261,0,0,0,40,4374,220.9309,99.4112396240234,,,,,,,,,,,,,0,,,,0,,,,,,218.04327395,,,,
,32288726.575,221.5528412,99.4112396240234,1.14794619532823E-6,2.76280587107633E-7,1,0.999253354069792,40.0298881530762,1.99553207795607,20.5000005662441,1.3211375158469E-5,1.07981923911107E-6,0.25,-1.0391915390205E-7,1.15119127646709E-6,-1.03122732221921E-7,221.5528412,221.5528412,99.4112396240234,99.4112396240234,57.0541921327368,20.5204509713779,24.807261,0,0,0,40,4374,224.4626,99.4112396240234,,,,,,,,,,,,,0,,,,-0.00245,,,,,,221.5528412,,,,
,32288867.09,225.0432129,99.4112396240234,1.76986983911927E-6,4.28655045320142E-7,1,0.999253354069792,40.0298881530762,1.995624453006,20.4399991780519,2.02760114531722E-5,2.19118584721243E-6,0.25,-1.13720309733106E-7,1.77461726210004E-6,-1.1238259291102E-7,225.0432129,225.0432129,99.4112396240234,99.4112396240234,56.6516534453329,20.5091878222801,24.807261,0,0,0,40,4374,227.9759,99.4112396240234,,,,,,,,,,,,,0,,,,0,,,,,,225.0432129,,,,
,32289004.455,228.5080872,99.4112396240234,1.76065169711286E-6,3.59353121212794E-7,1,0.999253354069792,40.0298881530762,1.99544527688595,20.4399991780519,1.99626665527414E-5,3.35278160215542E-6,0.25,-9.50641768495846E-9,1.76506977245089E-6,-7.93205098308893E-9,228.5080872,228.5080872,99.4112396240234,99.4112396240234,57.0096393071407,20.5180981899861,24.427608,0,0,0,40,4374,231.4209,99.4112396240234,,,,,,,,,,,,,0,,,,-0.00245,,,,,,228.5080872,,,,
,32289146.92,232.0440521,99.4112396240234,1.88620810267935E-6,3.80278701868318E-7,1,0.999253354069792,40.0298881530762,1.99550160589426,20.4399991780519,2.13900204402474E-5,3.55817557350222E-6,0.25,-1.3098754930978E-8,1.89071422868773E-6,-1.14491273390318E-8,232.0440521,232.0440521,99.4112396240234,99.4112396240234,57.149550812083,20.5131421410622,24.807261,0,0,0,40,4374,234.9809,99.4112396240234,,,,,,,,,,,,,0,,,,-0.0049,,,,,,232.0440521,,,,
,32289288.405,235.5500946,99.4112396240234,2.61666521228265E-6,3.51457113192891E-7,1,0.999253354069792,40.0298881530762,1.99560551073141,20.3900001943111,3.07595967232722E-5,-1.33684598948888E-6,0.25,-5.71964144054433E-7,2.62308343513917E-6,-5.70967783565814E-7,235.5500946,235.5500946,99.4112396240234,99.4112396240234,56.8056342636214,20.5041383799189,25.186911,0,0,0,40,4374,238.5375,99.4112396240234,,,,,,,,,,,,,0,,,,-0.0049,,,,,,235.5500946,,,,
,32289425.58,239.0001984,99.4112396240234,2.65592039719401E-6,3.87260929505815E-7,1,0.999253354069792,40.0298881530762,1.99555482984833,20.3900001943111,3.03350419673337E-5,3.72464977031016E-6,0.25,-1.31787248586352E-7,2.66172163893278E-6,-1.29785046559668E-7,239.0001984,239.0001984,99.4112396240234,99.4112396240234,57.1151591572368,20.5146771714732,25.186911,0,0,0,40,4374,241.9804,99.4112396240234,,,,,,,,,,,,,0,,,,-0.0049,,,,,,239.0001984,,,,
,32289566.22,242.5006866,99.4112396240234,2.97785948722816E-6,4.18801256189612E-7,1,0.999253354069792,40.0298881530762,1.99525109792409,20.3900001943111,3.33912390395038E-5,7.70217381426407E-6,0.25,1.63835372523971E-7,2.98373434724921E-6,1.6668323417004E-7,242.5006866,242.5006866,99.4112396240234,99.4112396240234,57.1620568683907,20.5144885747148,25.566563,0,0,0,40,4374,245.5145,99.4112396240234,,,,,,,,,,,,,0,,,,-0.00245,,,,,,242.5006866,,,,
,32289707.835,246.027771,99.4112396240234,3.49241260592379E-6,3.88948481262113E-7,1,0.999253354069792,40.0298881530762,1.99552173889634,20.3200001269579,4.03112249488063E-5,2.40252046308492E-6,0.25,-3.93479400914789E-7,3.49935991764289E-6,-3.91323843218987E-7,246.027771,246.027771,99.4112396240234,99.4112396240234,57.0573186468137,20.5142378244345,25.186911,0,0,0,40,4374,249.0595,99.4112396240234,,,,,,,,,,,,,0,,,,0.00245,,,,,,246.027771,,,,
,32289848.91,249.5270996,99.4112396240234,3.55538429738651E-6,3.77788987982867E-7,1,0.999253354069792,40.0298881530762,1.99523230755115,20.3200001269579,3.98876603404723E-5,9.01680645087173E-6,0.25,1.80090349587613E-7,3.56153903578528E-6,1.83313600494829E-7,249.5270996,249.5270996,99.4112396240234,99.4112396240234,57.3942005386022,20.5193269758777,25.186911,0,0,0,40,4374,252.60015,99.4112396240234,,,,,,,,,,,,,0,,,,-0.0049,,,,,,249.5270996,,,,
,32289987.39,253.0011139,99.4112396240234,4.37923451699058E-6,3.56581959368989E-7,1,0.999253354069792,40.0298881530762,1.99512580954474,20.3200001269579,4.9836038355892E-5,6.98588423062826E-6,0.25,-1.42049805828699E-7,4.38657330814244E-6,-1.38765379072691E-7,253.0011139,253.0011139,99.4112396240234,99.4112396240234,57.3699700545061,20.5180700761837,25.566563,0,0,0,40,4374,256.06815,99.4112396240234,,,,,,,,,,,,,0,,,,0.0049,,,,,,253.0011139,,,,
,32290110.44,256.0692139,99.4112396240234,3.98548287920353E-6,4.04781439683997E-7,1,0.999253354069792,40.0298881530762,2.00750637347606,20.2799998223782,4.56163283851937E-5,6.40805329019083E-6,0.25,-1.28059417152843E-7,3.99172617895708E-6,-1.25099872588238E-7,256.0692139,256.0692139,99.4112396240234,99.4112396240234,56.8525319747752,20.5136555457695,25.566563,0,0,0,40,4374,259.132,99.4112396240234,,,,,,,,,,,,,0,,,,-0.0049,,,,,,256.0692139,,,,
,32290250.66,259.5220032,99.4112396240234,4.8384856365931E-6,3.89883864402982E-7,1,0.999253354069792,40.0298881530762,2.00742471998845,20.2799998223782,5.47867889075496E-5,1.11451321256193E-5,0.25,1.40439103276798E-7,4.84523940798213E-6,1.44408882437805E-7,259.5220032,259.5220032,99.4112396240234,99.4112396240234,57.2339666921599,20.5146310738547,25.186911,0,0,0,40,4374,262.6676,99.4112396240234,,,,,,,,,,,,,0,,,,0,,,,,,259.5220032,,,,
,32290389.955,263.0435181,99.4112396240234,4.88084366160838E-6,4.43823716638083E-7,1,0.999253354069792,40.0298881530762,2.00734344890681,20.2799998223782,5.47278033852284E-5,1.42955405927895E-5,0.25,4.10186736383746E-7,4.88684034511709E-6,4.14461158273983E-7,263.0435181,263.0435181,99.4112396240234,99.4112396240234,56.9979148793522,20.5159659054829,25.186911,0,0,0,40,4374,266.1339,99.4112396240234,,,,,,,,,,,,,0,,,,0,,,,,,263.0435181,,,,
,32290529.93,266.5139465,99.4112396240234,5.26057579768703E-6,4.37117176585511E-7,1,0.999253354069792,40.0298881530762,1.99513691901251,20.2200002968311,5.97357718444322E-5,8.97338985382425E-6,0.25,-1.18617126635765E-7,5.26681659290515E-6,-1.14783617144183E-7,266.5139465,266.5139465,99.4112396240234,99.4112396240234,57.1417345268907,20.5061828843791,25.186911,0,0,0,40,4374,269.63975,99.4112396240234,,,,,,,,,,,,,0,,,,0,,,,,,266.5139465,,,,
,32290672.84,270.0450439,99.4112396240234,5.16586908341833E-6,4.66852977413846E-7,1,0.999253354069792,40.0298881530762,1.99493992788042,20.2200002968311,5.8351443723762E-5,1.05173024127078E-5,0.25,3.45610618940704E-8,5.17123226474887E-6,3.84362612585426E-8,270.0450439,270.0450439,99.4112396240234,99.4112396240234,57.2081729510253,20.5119507410895,25.566563,0,0,0,40,4374,273.2238,99.4112396240234,,,,,,,,,,,,,0,,,,0.0049,,,,,,270.0450439,,,,
,32290812.89,273.5594482,99.4112396240234,5.83304439740791E-6,4.36757135253337E-7,1,0.999253354069792,40.0298881530762,1.99467495716988,20.2200002968311,6.57007779189645E-5,1.28543894147603E-5,0.25,1.25927451690173E-7,5.83830375163198E-6,1.30311574469128E-7,273.5594482,273.5594482,99.4112396240234,99.4112396240234,56.9979148793522,20.5206480864463,25.946213,0,0,0,40,4374,276.7454,99.4112396240234,,,,,,,,,,,,,0,,,,0,,,,,,273.5594482,,,,
,32290952.085,277.0328979,99.4112396240234,6.16822497817824E-6,4.31411801176857E-7,1,0.999253354069792,40.0298881530762,1.99507315359217,20.1699994504452,7.03104059910315E-5,8.8068840759548E-6,0.25,-2.90154449458742E-7,6.17332600121185E-6,-2.85938074132149E-7,277.0328979,277.0328979,99.4112396240234,99.4112396240234,55.9263021794867,20.5145858430291,25.566563,0,0,0,40,4374,280.22105,99.4112396240234,,,,,,,,,,,,,0,,,,0.00245,,,,,,277.0328979,,,,
,32291091.69,280.5116272,99.4112396240234,6.51438570769071E-6,4.13597140065614E-7,1,0.999253354069792,40.0298881530762,1.99493837631556,20.1699994504452,7.37254202365842E-5,1.2280954182263E-5,0.25,-4.26164670042785E-8,6.5187704726476E-6,-3.8018513404256E-8,280.5116272,280.5116272,99.4112396240234,99.4112396240234,56.587559906756,20.5173319869764,26.325863,0,0,0,40,4374,283.7145,99.4112396240234,,,,,,,,,,,,,0,,,,0,,,,,,280.5116272,,,,
,32291233.9,284.0296631,99.4112396240234,6.5470864509514E-6,3.86173247551542E-7,1,0.999253354069792,40.0298881530762,1.99467554201468,20.1699994504452,7.43329836074429E-5,1.08614750405422E-5,0.25,-1.73540709241206E-7,6.55075885314488E-6,-1.69054118763268E-7,284.0296631,284.0296631,99.4112396240234,99.4112396240234,56.435142345506,20.5155542640262,25.946213,0,0,0,40,4374,287.2557,99.4112396240234,,,,,,,,,,,,,0,,,,-0.00245,,,,,,284.0296631,,,,
,32291372.455,287.5047607,99.4112396240234,7.13540188734056E-6,4.84805859292466E-7,1,0.999253354069792,40.0298881530762,1.99538864185756,20.1099999248981,8.02143635776047E-5,1.65470017801344E-5,0.25,2.27328340267513E-7,7.13822665030638E-6,2.32344074488262E-7,287.5047607,287.5047607,99.4112396240234,99.4112396240234,56.7743691228522,20.509493173989,25.566563,0,0,0,40,4374,290.7238,99.4112396240234,,,,,,,,,,,,,0,,,,0.0049,,,,,,287.5047607,,,,
,32291515.725,291.0531921,99.4112396240234,7.31062425923665E-6,3.9631377391162E-7,1,0.999253354069792,40.0298881530762,1.99538356732552,20.1099999248981,8.215504408812E-5,1.7057981708556E-5,0.25,2.42435680687186E-7,7.31258520912569E-6,2.47473867149969E-7,291.0531921,291.0531921,99.4112396240234,99.4112396240234,57.1815975813714,20.512659646623,25.946213,0,0,0,40,4374,294.3172,99.4112396240234,,,,,,,,,,,,,0,,,,-0.0049,,,,,,291.0531921,,,,
,32291653.97,294.5025635,99.4112396240234,7.61574977195912E-6,3.21747351250733E-7,1,0.999253354069792,40.0298881530762,1.99529063280068,20.1099999248981,8.7686127471182E-5,5.55170747919967E-6,0.25,-8.28290422580328E-7,7.61757902156873E-6,-8.23326134872293E-7,294.5025635,294.5025635,99.4112396240234,99.4112396240234,56.9455457685637,20.515862025344,25.946213,0,0,0,40,4374,297.78185,99.4112396240234,,,,,,,,,,,,,0,,,,0.00245,,,,,,294.5025635,,,,
,32291797.36,298.0569153,99.4112396240234,7.89582532080984E-6,4.46896774130893E-7,1,0.999253354069792,40.0298881530762,1.98426283612082,20.0599990785122,8.81710899729315E-5,1.87016788530594E-5,0.25,2.95877287104868E-7,7.89594775787334E-6,3.01104580820764E-7,298.0569153,298.0569153,99.4112396240234,99.4112396240234,56.5359724244868,20.5154831915934,26.325863,0,0,0,40,4374,301.3631,99.4112396240234,,,,,,,,,,,,,0,,,,0,,,,,,298.0569153,,,,
,32291936.72,301.5392761,99.4112396240234,7.54686760119498E-6,4.29926555632153E-7,1,0.999253354069792,40.0298881530762,1.98397531928257,20.0599990785122,8.60908530608488E-5,7.25783320592052E-6,0.25,-6.61581431086206E-7,7.54666430035139E-6,-6.56609194311728E-7,301.5392761,301.5392761,99.4112396240234,99.4112396240234,56.516431711506,20.5163387886894,26.325863,0,0,0,40,4374,304.8659,99.4112396240234,,,,,,,,,,,,,0,,,,0.00245,,,,,,301.5392761,,,,
,32292077.455,305.0105896,99.4112396240234,7.59246030126689E-6,3.77222628623626E-7,1,0.999253354069792,40.0298881530762,1.983860282865,20.0599990785122,8.67941986075077E-5,6.15267802543717E-6,0.25,-7.67665626471559E-7,7.59137641800334E-6,-7.62626917140634E-7,305.0105896,305.0105896,99.4112396240234,99.4112396240234,56.6633778731214,20.5148672995541,26.705515,0,0,0,40,4374,308.39025,99.4112396240234,,,,,,,,,,,,,0,,,,0.0049,,,,,,305.0105896,,,,
,32292198.71,308.0141296,99.4112396240234,7.64659355142689E-6,4.73629780372728E-7,1,0.999253354069792,40.0298881530762,1.99603959399108,19.9999995529652,8.68981850154273E-5,1.21072371407345E-5,0.25,-2.53144149864496E-7,7.6443491351943E-6,-2.48206979338146E-7,308.0141296,308.0141296,99.4112396240234,99.4112396240234,56.6977695279675,20.5016633652699,26.325863,0,0,0,40,4374,311.41885,99.4112396240234,,,,,,,,,,,,,0,,,,-0.0049,,,,,,308.0141296,,,,
,32292337.6,311.5024719,99.4112396240234,7.56368330807866E-6,4.29198403761311E-7,1,0.999253354069792,40.0298881530762,1.99572329901814,19.9999995529652,8.61038872725274E-5,1.09821182028337E-5,0.25,-3.3802398717706E-7,7.56057986183409E-6,-3.33133617860054E-7,311.5024719,311.5024719,99.4112396240234,99.4112396240234,56.7110572127945,20.5014853082022,26.325863,0,0,0,40,4374,314.9131,99.4112396240234,,,,,,,,,,,,,0,,,,0.0049,,,,,,311.5024719,,,,
,32292479.15,315.0270996,99.4112396240234,7.91378102304274E-6,3.70389850789718E-7,1,0.999253354069792,40.0298881530762,1.99532977388292,19.9999995529652,8.88422198812409E-5,1.85237976794766E-5,0.25,2.69525546096921E-7,7.90915840718723E-6,2.74271032390303E-7,315.0270996,315.0270996,99.4112396240234,99.4112396240234,56.6829185861022,20.505794673649,26.705515,0,0,0,40,4374,318.4572,99.4112396240234,,,,,,,,,,,,,0,,,,0.00245,,,,,,315.0270996,,,,
,32292599.64,318.0198059,99.4112396240234,8.08266137757763E-6,4.78332575564834E-7,1,0.999253354069792,40.0298881530762,1.99601428819065,19.9400000274181,9.09422709231651E-5,1.78609154708803E-5,0.25,1.81277231602624E-7,8.07714608327807E-6,1.86103120302851E-7,318.0198059,318.0198059,99.4112396240234,99.4112396240234,56.7454488676406,20.5011276012365,26.705515,0,0,0,40,4374,321.4888,99.4112396240234,,,,,,,,,,,,,0,,,,0,,,,,,318.0198059,,,,
,32292741.93,321.5314941,99.4112396240234,7.83300797934908E-6,5.04090573359664E-7,1,0.999253354069792,40.0298881530762,1.99534698226705,19.9400000274181,8.92250871751257E-5,1.077272071839E-5,0.25,-4.02526977388409E-7,7.82704644288824E-6,-3.9747449147481E-7,321.5314941,321.5314941,99.4112396240234,99.4112396240234,56.800944492506,20.5091676846214,26.325863,0,0,0,40,4374,325.0707,99.4112396240234,,,,,,,,,,,,,0,,,,-0.00245,,,,,,321.5314941,,,,
,32292882.07,325.0045166,99.4112396240234,7.88587773370278E-6,4.12307926560267E-7,1,0.999253354069792,40.0298881530762,1.99536063991022,19.9400000274181,8.83773075108263E-5,1.91564901782446E-5,0.25,3.31124224645111E-7,7.8784737269943E-6,3.35529688371757E-7,325.0045166,325.0045166,99.4112396240234,99.4112396240234,56.6962062709291,20.5107240759601,26.325863,0,0,0,40,4374,328.562,99.4112396240234,,,,,,,,,,,,,0,,,,-0.00245,,,,,,325.0045166,,,,
touchdown = 14.639999717474 mm,32293016.5,328.3634949,99.4112396240234,8.22434161517825E-6,4.44965430297373E-7,1,0.999253354069792,40.0298881530762,1.99585582310363,19.8699999600649,9.39201962644592E-5,9.94171404704923E-6,0.25,-5.43796115635704E-7,8.21618285714646E-6,-5.38381313241672E-7,328.3634949,328.3634949,99.4112396240234,99.4112396240234,56.4992358840829,20.4992991966905,26.705515,0,0,0,40,4374,331.9356,99.4112396240234,,,,,,,,,,,,,0,,,,-0.0049,,,,,,328.3634949,,,,
,32293145.775,331.5430908,99.4112396240234,7.5036802132894E-6,4.06708724412261E-7,1,0.999253354069792,40.0298881530762,1.99541300927885,19.8699999600649,8.59910707299151E-5,7.17173619217326E-6,0.25,-6.64072925180698E-7,7.49550215231352E-6,-6.58933394864694E-7,331.5430908,331.5430908,99.4112396240234,99.4112396240234,56.9220969129868,20.5087746195986,26.705515,0,0,0,40,4374,335.1703,99.4112396240234,,,,,,,,,,,,,0,,,,0,,,,,,331.5430908,,,,
,32293283.975,335.0224609,99.4112396240234,7.62397218485369E-6,5.29848778173283E-7,1,0.999253354069792,40.0298881530762,1.99543198592243,19.8699999600649,8.64918528103507E-5,1.22980115010636E-5,0.25,-2.30553449268117E-7,7.61448442236026E-6,-2.25860560740376E-7,335.0224609,335.0224609,99.4112396240234,99.4112396240234,56.7259081546598,20.5138553533379,27.085165,0,0,0,40,4374,338.642,99.4112396240234,,,,,,,,,,,,,0,,,,0.0049,,,,,,335.0224609,,,,
touchdown = 14.580000191927 mm,32293435.42,338.7548218,99.4112396240234,7.22195761007827E-6,4.34588946450641E-7,1,0.999253354069792,40.0298881530762,1.9957072658274,19.8199991136789,8.19389005927693E-5,1.16059218601753E-5,0.25,-2.22214467161226E-7,7.21204328380015E-6,-2.1778519149685E-7,338.7548218,338.7548218,99.4112396240234,99.4112396240234,56.628204589756,20.5052473911972,26.705515,0,0,0,40,4374,342.44595,99.4112396240234,,,,,,,,,,,,,0,,,,0,,,,,,338.7548218,,,,
,32293567.2,342.0588989,99.4112396240234,7.05817213648214E-6,5.27988534087091E-7,1,0.999253354069792,40.0298881530762,1.99531500467762,19.8199991136789,7.91815752855702E-5,1.63921222988738E-5,0.25,2.30719434939467E-7,7.04743032692451E-6,2.34359296987374E-7,342.0588989,342.0588989,99.4112396240234,99.4112396240234,56.7774956369291,20.5171461833641,26.705515,0,0,0,40,4374,345.73925,99.4112396240234,,,,,,,,,,,,,0,,,,0,,,,,,342.0588989,,,,
,32293705.77,345.5049744,99.4112396240234,7.11965915681615E-6,4.69841673801015E-7,1,0.999253354069792,40.0298881530762,1.99522253667975,19.8199991136789,7.98249884123003E-5,1.67255846917463E-5,0.25,2.49908479675569E-7,7.10798063599755E-6,2.53484158393687E-7,345.5049744,345.5049744,99.4112396240234,99.4112396240234,57.0283983916022,20.5228057593242,26.705515,0,0,0,40,4374,349.2015,99.4112396240234,,,,,,,,,,,,,0,,,,0.00245,,,,,,345.5049744,,,,
touchdown = 14.5199997350574 mm,32293851.4,348.8825684,99.4112396240234,7.40742335184431E-6,4.54591696929426E-7,1,0.999253354069792,40.0298881530762,1.99603056560816,19.7599995881319,8.3665423685475E-5,1.39904760922563E-5,0.25,-4.26989635744369E-8,7.39459440635501E-6,-3.85047655558992E-8,348.8825684,348.8825684,99.4112396240234,99.4112396240234,56.7126204698329,20.5045166934856,26.325863,0,0,0,40,4374,351.0004,99.4112396240234,,,,,,,,,,,,,0,,,,-0.00245,,,,,,348.8825684,,,,
,32294173.115,349.792572,99.4112396240234,6.85779457077487E-6,4.84555947213002E-7,1,0.999253354069792,40.0298881530762,1.99534983828502,19.7599995881319,7.77389151865624E-5,1.1162943722569E-5,0.25,-1.97768578230273E-7,6.84579453184489E-6,-1.93603246754387E-7,349.792572,349.792572,99.4112396240234,99.4112396240234,56.3272776098521,20.5153556090449,26.705515,0,0,0,40,4369,350.83085,99.4112396240234,,,,,,,,,,,,,0,,,,-0.0049,,,,,,349.792572,,,,