File: data/monolayers/magneticStructure/ML_Ac_CoFe_C/PPMS/data/DD205_4_KOELNPPMS_HYST_100OE_150K.DAT
[Header]
; VSM Data File (default extension .dat)
; Copyright (c) 2003-2013, Quantum Design, Inc. All rights reserved.
TITLE,
FILEOPENTIME,19727777.34,08/17/2018,7:54 am
BYAPP,VSM,2.0,2.0
INFO,PPMS VSM Option Release 1.4.10 Build 1,APPNAME
INFO,Quantum Design Linear Motor Servo Controller,MOTOR_MODULE_NAME
INFO,3101-100 M1,MOTOR_HW_VERSION
INFO,MMC1014,MOTOR_SERIAL_NUMBER
INFO,SRV No X-over 01.03.11,MOTOR_SOFTWARE_VERSION
INFO,Quantum Design VSM Detection Module,VSM_MODULE_NAME
INFO,3101-150 F0,VSM_HW_VERSION
INFO,VSM707,VSM_SERIAL_NUMBER
INFO,VSM No X-over 01.02.05 May 20 2008 13:51:47,VSM_SOFTWARE_VERSION
INFO,704,PREAMP_SERIAL_NUMBER
INFO,822,COIL_SERIAL_NUMBER
INFO,0,MOMENT_UNITS
INFO,,SAMPLE_MATERIAL
INFO,,SAMPLE_COMMENT
INFO,,SAMPLE_MASS
INFO,,SAMPLE_VOLUME
INFO,,SAMPLE_MOLECULAR_WEIGHT
INFO,,SAMPLE_SIZE
INFO,,SAMPLE_SHAPE
DATATYPE,COMMENT,1
DATATYPE,TIME,2
STARTUPAXIS,X,2
STARTUPAXIS,Y1,5
[Data]
Comment,Time Stamp (sec),Temperature (K),Magnetic Field (Oe),Moment (emu),M. Std. Err. (emu),Transport Action,Averaging Time (sec),Frequency (Hz),Peak Amplitude (mm),Center Position (mm),Coil Signal' (mV),Coil Signal" (mV),Range (mV),M. Quad. Signal (emu),M. Raw' (emu),M. Raw" (emu),Min. Temperature (K),Max. Temperature (K),Min. Field (Oe),Max. Field (Oe),Mass (grams),Motor Lag (deg),Pressure (Torr),VSM Status (code),Motor Status (code),Measure Status (code),Measure Count,PPMS Status (code),System Temp. (K),System Field (Oe),Sample Position (deg),Bridge 1 Resistance (ohms),Bridge 1 Excitation (에),Bridge 2 Resistance (ohms),Bridge 2 Excitation (에),Bridge 3 Resistance (ohms),Bridge 3 Excitation (에),Bridge 4 Resistance (ohms),Bridge 4 Excitation (에),Signal 1 Vin (V),Signal 2 Vin (V),Digital Inputs (code),Drive 1 Iout (mA),Drive 1 Ipower (W),Drive 2 Iout (mA),Drive 2 Ipower (W),Pressure (),Map 20 (),Map 21 (),Map 22 (),Map 23 (),Map 24 (),Map 25 (),Map 26 (),Map 27 (),Map 28 (),Map 29 ()
,19728027.67,150.0517,0.137013956904411,-2.81898447441717E-5,3.74031066608613E-7,1,0.999253354069792,40.0298881530762,1.9938326921636,14.2400003969669,-0.000321566065761055,-4.5582246544436E-5,0.25,8.93256793038405E-7,-2.83293104023538E-5,8.52425147493486E-7,150.0525,150.0525,0.106566414237022,0.1674614995718,53.4751151431787,19.5583115948471,24.427608,0,0,0,40,4417,150.0517,0.137013956904411,,,,,,,,,,,,,0,,,,,,,,,,,,,,
,19728113.89,150.0553,3477.05798339844,-1.27642057402103E-5,5.65703100912238E-7,1,0.999253354069792,40.0298881530762,1.99388780690712,14.2400003969669,-0.000145741273556496,-1.9870453533121E-5,0.25,4.72264384799213E-7,-1.28274669351179E-5,4.54132547599123E-7,150.0555,150.0555,3471.91967773438,3482.1962890625,53.892504772448,19.5577453066415,24.807261,0,0,0,40,4449,150.0553,3477.05798339844,,,,,,,,,,,,,0,,,,,,,,,,,,,,
,19728188.36,150.0687,7202.06982421875,-3.91468483987605E-6,1.06120017404587E-6,1,0.999253354069792,40.0298881530762,1.99396310662696,14.2400003969669,-4.60326441570361E-5,1.55874156231161E-6,0.25,8.19391092852232E-7,-3.93516564410175E-6,8.1714449560378E-7,150.0688,150.0688,7197.17431640625,7206.96533203125,53.7182016126595,19.5600701854961,24.047956,0,0,0,40,4449,150.0687,7202.06982421875,,,,,,,,,,,,,0,,,,,,,,,,,,,,
,19728264.465,150.0797,11008.0717773438,3.30397155955813E-6,1.46338126736807E-6,1,0.999253354069792,40.0298881530762,1.99376716885355,14.2400003969669,3.4895028670476E-5,2.13729550990583E-5,0.25,1.30844900161382E-6,3.31806467521268E-6,1.32012965517304E-6,150.0797,150.0797,11000.6201171875,11015.5234375,53.8088705208903,19.5607783395687,24.807261,0,0,0,40,4449,150.0797,11008.0717773438,,,,,,,,,,,,,0,,,,,,,,,,,,,,
,19728338.23,150.0881,14693.482421875,2.49044185201844E-6,2.00343916450127E-6,1,0.999253354069792,40.0298881530762,1.99402895830908,14.2400003969669,2.38022614675146E-5,3.04857968758011E-5,0.25,2.2531485949178E-6,2.49905139380207E-6,2.26815082905114E-6,150.0881,150.0881,14688.603515625,14698.361328125,53.8229398342365,19.55783482581,24.427608,0,0,0,40,4449,150.0881,14693.482421875,,,,,,,,,,,,,0,,,,,,,,,,,,,,
,19728411.52,150.0935,18356.5625,-8.61079897555106E-6,1.91891378649897E-6,1,0.999253354069792,40.0298881530762,1.99413767445015,14.2400003969669,-0.000101740725508082,6.17415315662179E-6,0.25,2.04421131819291E-6,-8.65622812717906E-6,2.04053863435439E-6,150.0942,150.0942,18346.66796875,18366.45703125,53.9323678269288,19.549088552423,24.047956,0,0,0,40,4449,150.0935,18356.5625,,,,,,,,,,,,,0,,,,,,,,,,,,,,
,19728484.87,150.09525,22022.0302734375,-1.67286892746343E-5,2.42384352788044E-6,1,0.999253354069792,40.0298881530762,1.99419041475418,14.2400003969669,-0.000199932050638272,2.50236017407605E-5,0.25,5.11957646791223E-6,-1.6818766379578E-5,5.11812421681075E-6,150.0949,150.0949,22014.53515625,22029.525390625,53.7979277216211,19.5536625644582,24.807261,0,0,0,40,4449,150.09525,22022.0302734375,,,,,,,,,,,,,0,,,,,,,,,,,,,,
,19728559.835,150.09385,25767.583984375,-2.85093166526253E-5,1.9985914503687E-6,1,0.999253354069792,40.0298881530762,1.99412013000946,14.2400003969669,-0.000330567644030264,-1.56132864889277E-5,0.25,3.59021314729468E-6,-2.86546934649244E-5,3.56268290214971E-6,150.0939,150.0939,25762.70703125,25772.4609375,54.2590885479673,19.5558464691512,24.427608,0,0,0,40,4449,150.09385,25767.583984375,,,,,,,,,,,,,0,,,,,,,,,,,,,,
,19728632.165,150.0878,29383.3720703125,-4.24070308117282E-5,2.63259399987072E-6,1,0.999253354069792,40.0298881530762,1.99388223018972,14.2400003969669,-0.000498446106125098,1.57527615788715E-5,0.25,8.77565528160489E-6,-4.26287217192157E-5,8.75168560812478E-6,150.0878,150.0878,29375.716796875,29391.02734375,54.1105791293134,19.5580821559834,24.427608,0,0,0,40,4449,150.0878,29383.3720703125,,,,,,,,,,,,,0,,,,,,,,,,,,,,
,19728707.725,150.08305,33161.642578125,-4.46190636396664E-5,2.3437400473307E-6,1,0.999253354069792,40.0298881530762,1.99391949954683,14.2400003969669,-0.000515947097337486,-3.22699936000237E-5,0.25,4.92789093739484E-6,-4.48455411699157E-5,4.88173352739942E-6,150.0826,150.0826,33159.09765625,33164.1875,53.5884512784672,19.5619967921139,24.427608,0,0,0,40,4449,150.08305,33161.642578125,,,,,,,,,,,,,0,,,,,,,,,,,,,,
,19728783.285,150.07805,36936.935546875,-5.72276202686055E-5,3.54795496460395E-6,1,0.999253354069792,40.0298881530762,1.99391878174679,14.2400003969669,-0.000660274993827144,-4.98264895464892E-5,0.25,5.5765002974352E-6,-5.7516956824851E-5,5.51386541270192E-6,150.0778,150.0778,36926.87890625,36946.9921875,54.1355912419288,19.560148289264,24.427608,0,0,0,40,4449,150.07805,36936.935546875,,,,,,,,,,,,,0,,,,,,,,,,,,,,
,19728860.14,150.0681,40780.447265625,-6.69873498843276E-5,2.89925603933954E-6,1,0.999253354069792,40.0298881530762,1.99392181771244,14.2400003969669,-0.000774417302744281,-4.95069017292037E-5,0.25,7.30446226740436E-6,-6.73272972549859E-5,7.23520851337684E-6,150.0679,150.0679,40770.9453125,40789.94921875,53.9558166825057,19.559432041464,24.807261,0,0,0,40,4449,150.0681,40780.447265625,,,,,,,,,,,,,0,,,,,,,,,,,,,,
,19728935.29,150.0573,44535.6328125,-7.82452864796582E-5,3.53340375053371E-6,1,0.999253354069792,40.0298881530762,1.99412732812223,14.2400003969669,-0.000899657047904377,-8.65324789942193E-5,0.25,6.00233780524088E-6,-7.86384609109545E-5,5.90933043872045E-6,150.0572,150.0572,44528.0234375,44543.2421875,54.0034960221788,19.5542900032761,24.427608,0,0,0,40,4449,150.0573,44535.6328125,,,,,,,,,,,,,0,,,,,,,,,,,,,,
,19729003.305,150.05375,47931.7109375,-8.80681764348163E-5,3.01464972116398E-6,1,0.999253354069792,40.0298881530762,1.99373752739694,14.2400003969669,-0.00101620583274345,-7.55924190773501E-5,0.25,8.67595090429454E-6,-8.85137585661652E-5,8.58099300535599E-6,150.0538,150.0538,47896.7890625,47966.6328125,53.9011026861596,19.5593631699587,24.807261,0,0,0,40,4449,150.05375,47931.7109375,,,,,,,,,,,,,0,,,,,,,,,,,,,,
,19729079.14,150.05205,51724.935546875,-0.00010077641245241,3.39529596589935E-6,1,0.999253354069792,40.0298881530762,1.99371989651177,14.2400003969669,-0.00116604872114515,-6.80488266892192E-5,0.25,1.15539680960184E-5,-0.000101288875261441,1.14536867002474E-5,150.0516,150.0516,51714.9765625,51734.89453125,54.058210018525,19.5592468801458,24.427608,0,0,0,40,4449,150.05205,51724.935546875,,,,,,,,,,,,,0,,,,,,,,,,,,,,
,19729158.62,150.0538,55697.845703125,-0.000116371383700519,3.61402886729252E-6,1,0.999253354069792,40.0298881530762,1.99394261517511,14.2400003969669,-0.00134184122122534,-0.000106121509748406,0.25,1.09145520592695E-5,-0.000116959420900356,1.07873359710768E-5,150.0549,150.0549,55687.6171875,55708.07421875,53.9769206525249,19.5571440106838,24.047956,0,0,0,40,4449,150.0538,55697.845703125,,,,,,,,,,,,,0,,,,,,,,,,,,,,
,19729236.92,150.05095,59610.998046875,-0.00012693031800223,3.51635005058658E-6,1,0.999253354069792,40.0298881530762,1.99383850715819,14.2400003969669,-0.00146823456582774,-8.86796814092942E-5,0.25,1.42900402265961E-5,-0.000127575478278675,1.41635164404427E-5,150.0509,150.0509,59605.94140625,59616.0546875,53.8878150013326,19.5601735524763,24.427608,0,0,0,40,4449,150.05095,59610.998046875,,,,,,,,,,,,,0,,,,,,,,,,,,,,
,19729316.75,150.0442,63599.392578125,-0.000138352365733186,3.02681744819138E-6,1,0.999253354069792,40.0298881530762,1.99394364946337,14.2400003969669,-0.0015973864854232,-0.000114184415595732,0.25,1.4031156261751E-5,-0.000139053278427054,1.38862506217753E-5,150.0444,150.0444,63594.44140625,63604.34375,53.9089189713519,19.5604814959246,24.427608,0,0,0,40,4449,150.0442,63599.392578125,,,,,,,,,,,,,0,,,,,,,,,,,,,,
,19729401.35,150.03145,67829.75390625,-0.000153204397075493,2.76121510268254E-6,1,0.999253354069792,40.0298881530762,1.99389017249191,14.2500000074506,-0.00176884619411292,-0.00012629426927828,0.25,1.55494721869325E-5,-0.000153980699547063,1.5389753848133E-5,150.0314,150.0314,67817.1015625,67842.40625,54.1707645252942,19.5578138578609,24.047956,0,0,0,40,4449,150.03145,67829.75390625,,,,,,,,,,,,,0,,,,,,,,,,,,,,
,19729481.305,150.0139,71825.03125,-0.000166918235165122,3.49469827579999E-6,1,0.999253354069792,40.0298881530762,1.99382624599408,14.2400003969669,-0.00192559444044149,-0.000146380062857211,0.25,1.61663281501305E-5,-0.0001677629928503,1.59892034748929E-5,150.0144,150.0144,71809.9921875,71840.0703125,54.0496121048134,19.5543003208391,24.047956,0,0,0,40,4449,150.0139,71825.03125,,,,,,,,,,,,,0,,,,,,,,,,,,,,
,19729559.33,149.9923,75723.24609375,-0.000175207894905857,3.45147821493525E-6,1,0.999253354069792,40.0298881530762,1.99378081002547,14.2500000074506,-0.0020251885439493,-0.000130647885029241,0.25,1.89957912942549E-5,-0.000176097897364347,1.88205364799482E-5,149.9938,149.9938,75713.3125,75733.1796875,54.1762359249288,19.5555166250371,24.807261,0,0,0,40,4449,149.9923,75723.24609375,,,,,,,,,,,,,0,,,,,,,,,,,,,,
,19729639.7,149.96635,79741.58984375,-0.000194950769973912,5.1460280345933E-6,1,0.999253354069792,40.0298881530762,1.99400643593168,14.2500000074506,-0.00224062561018584,-0.000220107256932436,0.25,1.45496650851103E-5,-0.000195931211526133,1.43231014768629E-5,149.9668,149.9668,79736.5859375,79746.59375,53.9526901684288,19.5566270585061,24.427608,0,0,0,40,4449,149.96635,79741.58984375,,,,,,,,,,,,,0,,,,,,,,,,,,,,
,19729717.895,149.9437,83653.06640625,-0.0002096134545228,3.01829123215858E-6,1,0.999253354069792,40.0298881530762,1.99384902034394,14.2400003969669,-0.00241009246841817,-0.000230194810858783,0.25,1.62116496556809E-5,-0.000210668748891617,1.59716882347248E-5,149.9445,149.9445,83650.703125,83655.4296875,53.8276296053519,19.5573196710633,24.427608,0,0,0,40,4449,149.9437,83653.06640625,,,,,,,,,,,,,0,,,,,,,,,,,,,,
,19729794.36,149.9203,87473.8046875,-0.000211708765124084,3.85710692909368E-6,1,0.999253354069792,40.0298881530762,1.99381005676073,14.2400003969669,-0.00242317761102585,-0.00029545245461601,0.25,1.0823150868902E-5,-0.000212766412527425,1.05543350050148E-5,149.9203,149.9203,87463.546875,87484.0625,53.8510784609288,19.5566340766453,24.427608,0,0,0,40,4449,149.9203,87473.8046875,,,,,,,,,,,,,0,,,,,,,,,,,,,,
,19729885.58,149.89785,88925.10546875,-0.000221125321214914,3.54442887136682E-6,1,0.999253354069792,40.0298881530762,1.99391555963463,14.2400003969669,-0.00255094176759474,-0.000194593702211809,0.25,2.13538040193412E-5,-0.00022224546975782,2.11227566571706E-5,149.8992,149.8992,88917.7109375,88932.5,53.9612880821403,19.5557843407497,24.807261,0,0,0,40,4449,149.89785,88925.10546875,,,,,,,,,,,,,0,,,,,,,,,,,,,,
,19729955.59,149.88885,85426.9453125,-0.000214006410922473,4.38691559285421E-6,1,0.999253354069792,40.0298881530762,1.99389928090701,14.2400003969669,-0.00245647507755231,-0.000259086823582321,0.25,1.44303014309232E-5,-0.00021508095292171,1.41751597287836E-5,149.89,149.89,85424.3515625,85429.5390625,53.8534233464865,19.555521544435,24.047956,0,0,0,40,4449,149.88885,85426.9453125,,,,,,,,,,,,,0,,,,,,,,,,,,,,
,19730027.405,149.88395,81837.8828125,-0.000200921174497687,5.00492374187786E-6,1,0.999253354069792,40.0298881530762,1.99380446828446,14.2400003969669,-0.00230932614805411,-0.00022511226653506,0.25,1.51461460757715E-5,-0.000201932369453298,1.49136503870365E-5,149.8839,149.8839,81830.15625,81845.609375,53.9339310839672,19.5547389100676,24.427608,0,0,0,40,4449,149.88395,81837.8828125,,,,,,,,,,,,,0,,,,,,,,,,,,,,
,19730101.24,149.8871,78146.2421875,-0.000190641065217894,4.67506643398874E-6,1,0.999253354069792,40.0298881530762,1.99387613046136,14.2500000074506,-0.00219734588093488,-0.000178560411892855,0.25,1.74606109322607E-5,-0.000191605135417447,1.72544273560619E-5,149.8871,149.8871,78141.203125,78151.28125,53.8659294027942,19.5550507866786,24.807261,0,0,0,40,4449,149.8871,78146.2421875,,,,,,,,,,,,,0,,,,,,,,,,,,,,
,19730176.245,149.8894,74395.0703125,-0.000182937242606654,4.5918247190005E-6,1,0.999253354069792,40.0298881530762,1.99388057529429,14.2400003969669,-0.0021094220146083,-0.000166362423734464,0.25,1.71949540712163E-5,-0.000183862930057767,1.69985096167352E-5,149.8893,149.8893,74387.5625,74402.578125,54.0793139885442,19.5542129347257,25.186911,0,0,0,40,4449,149.8894,74395.0703125,,,,,,,,,,,,,0,,,,,,,,,,,,,,
,19730252.435,149.894,70586.36328125,-0.000171692465805556,3.08016433502248E-6,1,0.999253354069792,40.0298881530762,1.99399839335605,14.2400003969669,-0.00198245341675179,-0.000141315005659743,0.25,1.7445826021263E-5,-0.000172563162970601,1.72671722532941E-5,149.8939,149.8939,70578.8046875,70593.921875,53.8526417179672,19.5550043081872,24.807261,0,0,0,40,4449,149.894,70586.36328125,,,,,,,,,,,,,0,,,,,,,,,,,,,,
,19730334.445,149.8995,66488.21484375,-0.000155894027182204,3.45921710538931E-6,1,0.999253354069792,40.0298881530762,1.99402712519524,14.2400003969669,-0.00180691982309847,-8.89241638313054E-5,0.25,1.93128886699823E-5,-0.000156689869817217,1.91670443749093E-5,149.8988,149.8988,66480.625,66495.8046875,53.7580646671403,19.5536750994242,24.427608,0,0,0,40,4449,149.8995,66488.21484375,,,,,,,,,,,,,0,,,,,,,,,,,,,,
,19730409.045,149.90775,62760.1796875,-0.00013956612811416,2.98618375203051E-6,1,0.999253354069792,40.0298881530762,1.99406941408155,14.2400003969669,-0.00161440368031255,-9.85385690987448E-5,0.25,1.56225509411664E-5,-0.000140275954461184,1.54832323799933E-5,149.9081,149.9081,62752.80859375,62767.55078125,53.9878634517942,19.5557861449187,24.807261,0,0,0,40,4449,149.90775,62760.1796875,,,,,,,,,,,,,0,,,,,,,,,,,,,,
,19730488.795,149.92935,58774.400390625,-0.000130489307124259,3.19484464698739E-6,1,0.999253354069792,40.0298881530762,1.99399817195693,14.2500000074506,-0.0015078851418509,-0.000100573943229154,0.25,1.38625120475327E-5,-0.000131151683338294,1.37280686092893E-5,149.9288,149.9288,58764.34375,58784.45703125,53.9175168850634,19.5596013249552,24.807261,0,0,0,40,4449,149.92935,58774.400390625,,,,,,,,,,,,,0,,,,,,,,,,,,,,
,19730569.375,149.95435,54745.9453125,-0.000116851619065947,2.77753673883251E-6,1,0.999253354069792,40.0298881530762,1.9939683611977,14.2400003969669,-0.00134786600369194,-0.000103877632139684,0.25,1.11963970138592E-5,-0.000117442744091378,1.10695567697332E-5,149.9541,149.9541,54735.7578125,54756.1328125,54.576429726775,19.559400373135,24.807261,0,0,0,40,4449,149.95435,54745.9453125,,,,,,,,,,,,,0,,,,,,,,,,,,,,
,19730652.42,149.97725,50595.64453125,-0.000102520183206915,2.99864234127847E-6,1,0.999253354069792,40.0298881530762,1.99389899466375,14.2500000074506,-0.00119217713255119,-3.56576309298274E-5,0.25,1.47135271296049E-5,-0.000103046322687758,1.46258230176402E-5,149.978,149.978,50583.04296875,50608.24609375,53.9808287951211,19.5650036156687,24.427608,0,0,0,40,4449,149.97725,50595.64453125,,,,,,,,,,,,,0,,,,,,,,,,,,,,
,19730732.2,149.9887,46610.33984375,-8.68291016599479E-5,2.83514994190468E-6,1,0.999253354069792,40.0298881530762,1.9940521134587,14.2500000074506,-0.00100936972144587,-3.25782717093192E-5,0.25,1.22525038820499E-5,-8.72743342280801E-5,1.21768412926487E-5,149.9893,149.9893,46600.2109375,46620.46875,54.095728187448,19.5634927277805,24.427608,0,0,0,40,4449,149.9887,46610.33984375,,,,,,,,,,,,,0,,,,,,,,,,,,,,
,19730811.89,149.9951,42624.587890625,-7.73486683342544E-5,2.82983924706854E-6,1,0.999253354069792,40.0298881530762,1.99402091204236,14.2400003969669,-0.000892220532348134,-6.87910066852657E-5,0.25,7.40972083856955E-6,-7.77397563488848E-5,7.32480662380518E-6,149.9957,149.9957,42617.21484375,42631.9609375,54.1817073245634,19.562473579036,24.807261,0,0,0,40,4449,149.9951,42624.587890625,,,,,,,,,,,,,0,,,,,,,,,,,,,,
,19730891.14,149.9892,38664.078125,-6.13794735807156E-5,1.8928487768687E-6,1,0.999253354069792,40.0298881530762,1.99380793683057,14.2400003969669,-0.000714729567677555,-1.56201589706982E-5,0.25,9.31467862882311E-6,-6.1695197698955E-5,9.26389047478563E-6,149.9892,149.9892,38659.1640625,38668.9921875,53.9980246225442,19.566867949172,24.807261,0,0,0,40,4449,149.9892,38664.078125,,,,,,,,,,,,,0,,,,,,,,,,,,,,
,19730974.215,149.9835,34514.203125,-5.45850359234601E-5,1.73735256526227E-6,1,0.999253354069792,40.0298881530762,1.99373020439406,14.2400003969669,-0.000628985025127215,-5.17992606032509E-5,0.25,4.94211180242792E-6,-5.48605384016108E-5,4.88032281694935E-6,149.9837,149.9837,34511.82421875,34516.58203125,53.9503452828711,19.5672729106373,24.807261,0,0,0,40,4449,149.9835,34514.203125,,,,,,,,,,,,,0,,,,,,,,,,,,,,
,19731055.82,149.97315,30433.8095703125,-4.41934931840296E-5,2.13342720052631E-6,1,0.999253354069792,40.0298881530762,1.9939224029946,14.2400003969669,-0.000513410949196669,-1.82833519771413E-5,0.25,6.08679269600244E-6,-4.44198325473745E-5,6.04680986506287E-6,149.9722,149.9722,30428.767578125,30438.8515625,54.2035929231019,19.5630704741665,24.807261,0,0,0,40,4449,149.97315,30433.8095703125,,,,,,,,,,,,,0,,,,,,,,,,,,,,
,19731136.25,149.96435,26415.751953125,-2.96999265862503E-5,1.32600169029871E-6,1,0.999253354069792,40.0298881530762,1.99366374097662,14.2400003969669,-0.000351195136427042,2.33265379989603E-5,0.25,7.2300798061877E-6,-2.98570075428778E-5,7.21848386866567E-6,149.9656,149.9656,26410.6953125,26420.80859375,54.0707160748326,19.5658884505379,24.807261,0,0,0,40,4449,149.96435,26415.751953125,,,,,,,,,,,,,0,,,,,,,,,,,,,,
,19731211.56,149.9563,22650.3671875,-1.69790378693421E-5,1.64567079495114E-6,1,0.999253354069792,40.0298881530762,1.99381295595804,14.2400003969669,-0.000204799145405258,3.6362995878003E-5,0.25,6.16315387799307E-6,-1.7072066979579E-5,6.1664127539015E-6,149.9557,149.9557,22637.91796875,22662.81640625,54.1512238123134,19.5657496256485,24.807261,0,0,0,40,4449,149.9563,22650.3671875,,,,,,,,,,,,,0,,,,,,,,,,,,,,
,19731287.54,149.95155,18852.8046875,-5.6448267397779E-6,1.39553437075135E-6,1,0.999253354069792,40.0298881530762,1.99382929691595,14.2500000074506,-7.01042905787093E-5,2.36644493167969E-5,0.25,3.06933857977557E-6,-5.67738220308121E-6,3.07540290464916E-6,149.9518,149.9518,18845.533203125,18860.076171875,54.1316830993327,19.5658535825308,24.807261,0,0,0,40,4449,149.95155,18852.8046875,,,,,,,,,,,,,0,,,,,,,,,,,,,,
,19731363.05,149.94945,15080.044921875,4.17061373071067E-6,9.98098767850593E-7,1,0.999253354069792,40.0298881530762,1.99390986892383,14.2400003969669,4.13712379099044E-5,4.23651641052047E-5,0.25,3.00768329673927E-6,4.18626009097285E-6,3.02907527218766E-6,149.9488,149.9488,15072.685546875,15087.404296875,54.0394509340634,19.5676318787694,24.427608,0,0,0,40,4449,149.94945,15080.044921875,,,,,,,,,,,,,0,,,,,,,,,,,,,,
,19731434.285,149.95175,11519.5571289062,1.22488378264622E-5,9.41263046570151E-7,1,0.999253354069792,40.0298881530762,1.99390295210604,14.2500000074506,0.000135064738970907,4.65839900508035E-5,0.25,1.97221420825011E-6,1.23057158392291E-5,2.00144576810152E-6,149.9512,149.9512,11514.4169921875,11524.697265625,54.4310468221981,19.5685659606081,24.807261,0,0,0,40,4449,149.95175,11519.5571289062,,,,,,,,,,,,,0,,,,,,,,,,,,,,
,19731506.27,149.95435,7921.00952148438,2.12458148019784E-5,5.29955688524282E-7,1,0.999253354069792,40.0298881530762,1.99372777824202,14.2400003969669,0.000238483933508035,5.65035225023621E-5,0.25,1.27953159739294E-6,2.13478731205426E-5,1.31979817731095E-6,149.9548,149.9548,7916.11376953125,7925.9052734375,54.2864455461404,19.5719861393859,24.807261,0,0,0,40,4449,149.95435,7921.00952148438,,,,,,,,,,,,,0,,,,,,,,,,,,,,
,19731584.265,149.9584,4022.77062988281,2.87662773542686E-5,5.38608633076391E-7,1,0.999253354069792,40.0298881530762,1.99382295879038,14.2400003969669,0.000324722919243936,6.61330178761437E-5,0.25,8.17862549199459E-7,2.89059024939926E-5,8.67978016137645E-7,149.9578,149.9578,4017.75024414063,4027.791015625,54.4099428521788,19.5720607900147,24.807261,0,0,0,40,4449,149.9584,4022.77062988281,,,,,,,,,,,,,0,,,,,,,,,,,,,,
,19731661.765,149.9649,146.535499572754,2.62039985258832E-5,2.9202744822223E-7,1,0.999253354069792,40.0298881530762,1.99384410352384,14.2400003969669,0.000297909898346058,4.81433921845194E-5,0.25,-3.21587966713438E-7,2.63328804457122E-5,-2.81107711490253E-7,149.9663,149.9663,139.227874755859,153.843124389648,54.0816588741019,19.5710394535717,25.186911,0,0,0,40,4449,149.9649,146.535499572754,,,,,,,,,,,,,0,,,,,,,,,,,,,,
,19731734.525,149.9728,-3481.38366699219,1.38867401213153E-5,4.77427055733814E-7,1,0.999253354069792,40.0298881530762,1.993700416606,14.2400003969669,0.000158762979317227,2.03616421446746E-5,0.25,-6.24395009431291E-7,1.39557710069661E-5,-6.05193545867544E-7,149.9728,149.9728,-3488.91821289063,-3473.84912109375,54.332561628775,19.572576581964,24.807261,0,0,0,40,4449,149.9728,-3481.38366699219,,,,,,,,,,,,,0,,,,,,,,,,,,,,
,19731807.93,149.985,-7153.90380859375,4.87680366042677E-6,4.24266732464604E-7,1,0.999253354069792,40.0298881530762,1.9937068462538,14.2400003969669,5.9870434694403E-5,-1.64704321755419E-5,0.25,-2.30154424248439E-6,4.90437904809447E-6,-2.3050157788002E-6,149.985,149.985,-7163.82080078125,-7143.98681640625,54.1629482401019,19.5731780866728,24.807261,0,0,0,40,4449,149.985,-7153.90380859375,,,,,,,,,,,,,0,,,,,,,,,,,,,,
,19731890.19,149.99645,-11264.7177734375,-1.71968180882096E-6,8.47899087599248E-7,1,0.999253354069792,40.0298881530762,1.99374966575639,14.2400003969669,-1.5031298452999E-5,-2.90968973917581E-5,0.25,-2.26533821737938E-6,-1.7244900183084E-6,-2.27918362425683E-6,149.9962,149.9962,-11272.50390625,-11256.931640625,54.1199586715442,19.5720679238397,24.807261,0,0,0,40,4449,149.99645,-11264.7177734375,,,,,,,,,,,,,0,,,,,,,,,,,,,,
,19731975.5,150.0037,-15528.0864257813,6.23296601100295E-7,1.03775029395685E-6,1,0.999253354069792,40.0298881530762,1.9939780759627,14.2400003969669,1.51265749370817E-5,-4.50056019029362E-5,0.25,-4.07544951637104E-6,6.32844127424999E-7,-4.09442692365162E-6,150.0049,150.0049,-15535.703125,-15520.4697265625,54.230949921275,19.5726337488059,24.807261,0,0,0,40,4449,150.0037,-15528.0864257813,,,,,,,,,,,,,0,,,,,,,,,,,,,,
,19732058.655,150.00515,-19687.8623046875,1.01220621709223E-5,1.08897869204081E-6,1,0.999253354069792,40.0298881530762,1.99373292012234,14.2500000074506,0.000121566955523875,-1.86957329461545E-5,0.25,-3.41138832988854E-6,1.01770926838277E-5,-3.41201721392262E-6,150.0051,150.0051,-19698.01171875,-19677.712890625,53.9784839095634,19.5762567537447,24.427608,0,0,0,40,4449,150.00515,-19687.8623046875,,,,,,,,,,,,,0,,,,,,,,,,,,,,
,19732141.08,149.9989,-23802.6875,2.03249479369481E-5,1.60373312342705E-6,1,0.999253354069792,40.0298881530762,1.99380364205558,14.2500000074506,0.00024385394215529,-3.60559743586825E-5,0.25,-6.71894230879604E-6,2.04352353560236E-5,-6.71964298077634E-6,149.9995,149.9995,-23809.9140625,-23795.4609375,54.1707645252942,19.5740887765553,24.807261,0,0,0,40,4449,149.9989,-23802.6875,,,,,,,,,,,,,0,,,,,,,,,,,,,,
,19732224.315,149.9871,-27963.4677734375,3.17192231587283E-5,2.13837941073593E-6,1,0.999253354069792,40.0298881530762,1.99374998781469,14.2400003969669,0.000370064166657319,3.92678779379852E-6,0.25,-5.17929630072253E-6,3.18829395571184E-5,-5.15450193912212E-6,149.9871,149.9871,-27968.28125,-27958.654296875,54.0644630466788,19.5719610107999,24.807261,0,0,0,40,4449,149.9871,-27963.4677734375,,,,,,,,,,,,,0,,,,,,,,,,,,,,
,19732306.405,149.96845,-32066.5078125,4.20858150137679E-5,1.87334831730698E-6,1,0.999253354069792,40.0298881530762,1.99390140659183,14.2400003969669,0.000492108173087631,-8.88040491077026E-7,0.25,-7.40941041767848E-6,4.23039166112151E-5,-7.3793106245423E-6,149.9695,149.9695,-32071.83984375,-32061.17578125,54.1676380112173,19.5747913407311,24.807261,0,0,0,40,4449,149.96845,-32066.5078125,,,,,,,,,,,,,0,,,,,,,,,,,,,,
,19732385.43,149.94735,-36015.69921875,5.38121959997924E-5,2.31192526560134E-6,1,0.999253354069792,40.0298881530762,1.99398088143329,14.2500000074506,0.0006327725415739,-2.1364694354928E-5,0.25,-1.12567144987858E-5,5.40939152309634E-5,-1.12271773783524E-5,149.9476,149.9476,-36023.23046875,-36008.16796875,53.8815619731788,19.5733921680383,24.427608,0,0,0,40,4449,149.94735,-36015.69921875,,,,,,,,,,,,,0,,,,,,,,,,,,,,
,19732468.74,149.9271,-40183.021484375,6.73434418621611E-5,1.93417360179287E-6,1,0.999253354069792,40.0298881530762,1.99387164369881,14.2400003969669,0.000792298712222325,-2.93446311259624E-5,0.25,-1.43169614434973E-5,6.76964015552529E-5,-1.42814026946328E-5,149.9269,149.9269,-40195.625,-40170.41796875,54.1543503263903,19.5762407204632,24.807261,0,0,0,40,4449,149.9271,-40183.021484375,,,,,,,,,,,,,0,,,,,,,,,,,,,,
,19732551.61,149.9058,-44320.595703125,7.70258504515572E-5,3.093321295044E-6,1,0.999253354069792,40.0298881530762,1.99371771952609,14.2500000074506,0.000901070231325793,-4.41822673350608E-6,0.25,-1.38060959055964E-5,7.74255775885116E-5,-1.37531339687787E-5,149.9053,149.9053,-44323.3203125,-44317.87109375,53.9644145962173,19.5802936146666,24.807261,0,0,0,40,4449,149.9058,-44320.595703125,,,,,,,,,,,,,0,,,,,,,,,,,,,,
,19732631.545,149.8878,-48313.591796875,9.21305754042286E-5,2.61988560188049E-6,1,0.999253354069792,40.0298881530762,1.9937562551807,14.2500000074506,0.00107288051296391,2.29025363434157E-5,0.25,-1.40284031901005E-5,9.26048627064899E-5,-1.39532281381856E-5,149.887,149.887,-48315.984375,-48311.19921875,54.109015872275,19.5789397962986,25.186911,0,0,0,40,4449,149.8878,-48313.591796875,,,,,,,,,,,,,0,,,,,,,,,,,,,,
,19732706.53,149.87305,-52064.1640625,0.000103893868220637,3.02046992815591E-6,1,0.999253354069792,40.0298881530762,1.99390190779708,14.2400003969669,0.00121201160371463,1.4002273573665E-5,0.25,-1.68615796241707E-5,0.000104430405359556,-1.67823237042414E-5,149.8731,149.8731,-52069.3671875,-52058.9609375,54.0910384163326,19.5782055961696,24.807261,0,0,0,40,4449,149.87305,-52064.1640625,,,,,,,,,,,,,0,,,,,,,,,,,,,,
,19732781.325,149.8612,-55799.005859375,0.000112368119783253,3.05593758000024E-6,1,0.999253354069792,40.0298881530762,1.99383010864755,14.2500000074506,0.00129962225023375,7.94736059969431E-5,0.25,-1.25660680061536E-5,0.000112939654882743,-1.24529309543731E-5,149.861,149.861,-55831.6953125,-55766.31640625,54.0206918496019,19.5785994520774,25.186911,0,0,0,40,4449,149.8612,-55799.005859375,,,,,,,,,,,,,0,,,,,,,,,,,,,,
,19732858.015,149.8529,-59634.20703125,0.000130611754623363,3.58955978849702E-6,1,0.999253354069792,40.0298881530762,1.99375284231799,14.2400003969669,0.00151244229254021,8.16160877242915E-5,0.25,-1.55539647473471E-5,0.000131277635854502,-1.54276441002252E-5,149.8538,149.8538,-59644.71875,-59623.6953125,54.1520054408327,19.5800236772792,24.807261,0,0,0,40,4449,149.8529,-59634.20703125,,,,,,,,,,,,,0,,,,,,,,,,,,,,
,19732931.895,149.8423,-63327.67578125,0.000139762033661098,3.93641649734237E-6,1,0.999253354069792,40.0298881530762,1.99370892858105,14.2500000074506,0.00161998526900507,7.80382071089561E-5,0.25,-1.74623631918966E-5,0.000140475923837731,-1.73317622716347E-5,149.8423,149.8423,-63332.91796875,-63322.43359375,54.2645599476019,19.5774364116579,25.186911,0,0,0,40,4449,149.8423,-63327.67578125,,,,,,,,,,,,,0,,,,,,,,,,,,,,
,19733004.85,149.83475,-66972.99609375,0.00015246317002456,4.33159994434465E-6,1,0.999253354069792,40.0298881530762,1.99369111298846,14.2500000074506,0.00177011726063278,6.83234549187318E-5,0.25,-2.05301741595602E-5,0.000153244307077848,-2.03955817045542E-5,149.8341,149.8341,-66980.3046875,-66965.6875,54.1637298686211,19.581558271657,24.807261,0,0,0,40,4449,149.83475,-66972.99609375,,,,,,,,,,,,,0,,,,,,,,,,,,,,
,19733078.48,149.8306,-70650.11328125,0.000164790634541657,2.98423010751695E-6,1,0.999253354069792,40.0298881530762,1.99373547009702,14.2400003969669,0.00190750901657233,0.000106998579010565,0.25,-1.92674075615874E-5,0.000165630496599234,-1.91082271121207E-5,149.8307,149.8307,-70652.640625,-70647.5859375,54.2082826942173,19.5816356962188,24.807261,0,0,0,40,4449,149.8306,-70650.11328125,,,,,,,,,,,,,0,,,,,,,,,,,,,,
,19733150.55,149.82435,-74252.66015625,0.000180552345963392,2.58273550803533E-6,1,0.999253354069792,40.0298881530762,1.99367998446358,14.2400003969669,0.00209056473227005,0.000113423553236525,0.25,-2.14450911605308E-5,0.000181473149870509,-2.12730410459485E-5,149.8248,149.8248,-74255.1328125,-74250.1875,54.0527386188903,19.5822538349302,25.186911,0,0,0,40,4449,149.82435,-74252.66015625,,,,,,,,,,,,,0,,,,,,,,,,,,,,
,19733227.385,149.8178,-78092.94140625,0.000192032417222366,3.67223394883124E-6,1,0.999253354069792,40.0298881530762,1.99373579728817,14.2400003969669,0.00222657811895932,0.000103249854094017,0.25,-2.43406546146199E-5,0.000193014225013517,-2.41660087533658E-5,149.8175,149.8175,-78097.890625,-78087.9921875,54.1777991819673,19.5859139394262,24.807261,0,0,0,40,4449,149.8178,-78092.94140625,,,,,,,,,,,,,0,,,,,,,,,,,,,,
,19733304.305,149.80895,-81938.1875,0.000205049376169634,3.20634726668945E-6,1,0.999253354069792,40.0298881530762,1.99372412366731,14.2400003969669,0.00237377391748516,0.000131617671696341,0.25,-2.41060266868289E-5,0.000206094976105217,-2.39111364519899E-5,149.809,149.809,-81945.7421875,-81930.6328125,54.078532360025,19.5852878770702,25.186911,0,0,0,40,4449,149.80895,-81938.1875,,,,,,,,,,,,,0,,,,,,,,,,,,,,
,19733376.9,149.8057,-85566.2265625,0.000218004237881623,4.22244670921354E-6,1,0.999253354069792,40.0298881530762,1.99374305539793,14.2400003969669,0.00251218623146189,0.000206460961485523,0.25,-1.97639408150318E-5,0.000219107053863058,-1.95287605059485E-5,149.8066,149.8066,-85573.8359375,-85558.6171875,54.1621666115827,19.5852124809356,24.807261,0,0,0,40,4449,149.8057,-85566.2265625,,,,,,,,,,,,,0,,,,,,,,,,,,,,
,19733446.875,149.8018,-89063.33984375,0.000228026032087431,3.89080171825522E-6,1,0.999253354069792,40.0298881530762,1.99380697408102,14.2400003969669,0.00263907726804819,0.000150938574991122,0.25,-2.64028990364899E-5,0.000229188389497587,-2.6185993196318E-5,149.8026,149.8026,-89070.78125,-89055.8984375,54.0558651329673,19.585306164351,24.807261,0,0,0,40,4449,149.8018,-89063.33984375,,,,,,,,,,,,,0,,,,,,,,,,,,,,
,19733532.47,149.7976,-87536.234375,0.000225745960046652,3.06165105744479E-6,1,0.999253354069792,40.0298881530762,1.99395943407047,14.2500000074506,0.00261194221627053,0.000154821385159384,0.25,-2.56649951050857E-5,0.000226895963049962,-2.544752629344E-5,149.7975,149.7975,-87538.546875,-87533.921875,54.1488789267557,19.5819023360152,25.186911,0,0,0,40,4449,149.7976,-87536.234375,,,,,,,,,,,,,0,,,,,,,,,,,,,,
,19733603.05,149.7995,-84008.421875,0.000213193520402873,3.3059145323682E-6,1,0.999253354069792,40.0298881530762,1.99375302397128,14.2500000074506,0.00245807355828933,0.000194370032429977,0.25,-1.99924695644787E-5,0.000214273006607365,-1.97653618017244E-5,149.8,149.8,-84020.9375,-83995.90625,54.1840522101211,19.5832888463605,24.807261,0,0,0,40,4449,149.7995,-84008.421875,,,,,,,,,,,,,0,,,,,,,,,,,,,,
,19733675.305,149.80505,-80401.0546875,0.000196525387655145,2.98527993668966E-6,1,0.999253354069792,40.0298881530762,1.99387245357101,14.2400003969669,0.00227004217711348,0.000156098183929867,0.25,-2.04649988221508E-5,0.000197523472385198,-2.02648811202146E-5,149.8053,149.8053,-80408.5546875,-80393.5546875,54.1387177560057,19.5829096353124,24.807261,0,0,0,40,4449,149.80505,-80401.0546875,,,,,,,,,,,,,0,,,,,,,,,,,,,,
,19733749.015,149.8109,-76715.60546875,0.000189095375895096,3.37044867535911E-6,1,0.999253354069792,40.0298881530762,1.99378978677306,14.2500000074506,0.0021900745077322,0.00011606330105184,0.25,-2.27002488720396E-5,0.000190060232701036,-2.25217311960638E-5,149.811,149.811,-76725.671875,-76705.5390625,54.1434075271211,19.5796351405515,24.807261,0,0,0,40,4449,149.8109,-76715.60546875,,,,,,,,,,,,,0,,,,,,,,,,,,,,
,19733821.205,149.81595,-73107.55078125,0.000177430991505549,3.29792313615507E-6,1,0.999253354069792,40.0298881530762,1.99373745089042,14.2500000074506,0.00206036954133418,7.76488873196157E-5,0.25,-2.40555361825993E-5,0.000178340482264379,-2.39008770118904E-5,149.8153,149.8153,-73117.5234375,-73097.578125,54.2153173508904,19.5823681249816,24.807261,0,0,0,40,4449,149.81595,-73107.55078125,,,,,,,,,,,,,0,,,,,,,,,,,,,,
,19733894.805,149.8242,-69429.84375,0.000163735720061966,2.42236423970473E-6,1,0.999253354069792,40.0298881530762,1.99380073651414,14.2400003969669,0.00189715746714995,9.59807079339657E-5,0.25,-2.00554067358535E-5,0.000164571618669222,-1.99014926788783E-5,149.8247,149.8247,-69434.953125,-69424.734375,54.1199586715442,19.5812557616789,24.427608,0,0,0,40,4449,149.8242,-69429.84375,,,,,,,,,,,,,0,,,,,,,,,,,,,,
,19733968.1,149.83215,-65767.23828125,0.000150484053914845,3.62368003021758E-6,1,0.999253354069792,40.0298881530762,1.99364233130654,14.2500000074506,0.00174149721816703,9.95970150625084E-5,0.25,-1.742867266767E-5,0.000151250663479404,-1.72816880330624E-5,149.8329,149.8329,-65777.171875,-65757.3046875,53.9651962247365,19.5806224616325,24.427608,0,0,0,40,4449,149.83215,-65767.23828125,,,,,,,,,,,,,0,,,,,,,,,,,,,,
,19734039.93,149.8385,-62178.75390625,0.000137015288258749,2.36264212169906E-6,1,0.999253354069792,40.0298881530762,1.99387905815598,14.2400003969669,0.00159280809932286,5.04948839966567E-5,0.25,-1.94124917785538E-5,0.000137718701579991,-1.92955492541653E-5,149.8392,149.8392,-62188.4921875,-62169.015625,54.1684196397365,19.5820531332467,24.807261,0,0,0,40,4449,149.8385,-62178.75390625,,,,,,,,,,,,,0,,,,,,,,,,,,,,
,19734113.755,149.84705,-58489.125,0.000128884473886708,2.80605975268722E-6,1,0.999253354069792,40.0298881530762,1.99374137077265,14.2400003969669,0.00149812920844028,4.78301447620278E-5,0.25,-1.82314827001587E-5,0.00012954603372485,-1.81208294468114E-5,149.8472,149.8472,-58496.6484375,-58481.6015625,54.2340764353519,19.5821226106347,25.186911,0,0,0,40,4449,149.84705,-58489.125,,,,,,,,,,,,,0,,,,,,,,,,,,,,
,19734185.765,149.8552,-54891.09765625,0.000116972009743287,2.71294739750915E-6,1,0.999253354069792,40.0298881530762,1.99362024484493,14.2500000074506,0.00136184092632775,3.04339938971333E-5,0.25,-1.76904467311648E-5,0.00011757414679046,-1.7595194663545E-5,149.8552,149.8552,-54893.42578125,-54888.76953125,53.9581615680634,19.5842864166347,24.807261,0,0,0,40,4449,149.8552,-54891.09765625,,,,,,,,,,,,,0,,,,,,,,,,,,,,
,19734257.595,149.8602,-51300.884765625,0.00010171964816875,2.48700461527637E-6,1,0.999253354069792,40.0298881530762,1.99375222444447,14.2400003969669,0.00118539048405399,2.04387581666489E-5,0.25,-1.59155235589271E-5,0.000102244062634283,-1.58349153390722E-5,149.8602,149.8602,-51305.83984375,-51295.9296875,54.068371189275,19.580842653066,24.427608,0,0,0,40,4449,149.8602,-51300.884765625,,,,,,,,,,,,,0,,,,,,,,,,,,,,
,19734331.29,149.867,-47615.619140625,9.41458598728542E-5,2.27252976994151E-6,1,0.999253354069792,40.0298881530762,1.99384383246579,14.2400003969669,0.00109436135296029,3.50827698533769E-5,0.25,-1.33059704850592E-5,9.46289603959052E-5,-1.32240053971932E-5,149.867,149.867,-47622.83203125,-47608.40625,54.0566467614865,19.5794935914002,25.186911,0,0,0,40,4449,149.867,-47615.619140625,,,,,,,,,,,,,0,,,,,,,,,,,,,,
,19734405.665,149.87395,-43899.875,7.78619163790377E-5,2.36456865271237E-6,1,0.999253354069792,40.0298881530762,1.99391063476958,14.2400003969669,0.000907934860921714,1.27612748415336E-5,0.25,-1.24375033600352E-5,7.82636681120115E-5,-1.23764514993446E-5,149.8744,149.8744,-43904.80078125,-43894.94921875,54.1238668141403,19.5792071276417,25.186911,0,0,0,40,4449,149.87395,-43899.875,,,,,,,,,,,,,0,,,,,,,,,,,,,,
,19734477.885,149.8787,-40289.68359375,6.68586207517983E-5,2.22444430302027E-6,1,0.999253354069792,40.0298881530762,1.99395475712334,14.2400003969669,0.000781084168155894,2.68718102783575E-6,0.25,-1.14091154125671E-5,6.72047215416287E-5,-1.13600218309999E-5,149.8789,149.8789,-40297.20703125,-40282.16015625,54.2856639176211,19.5753605209648,24.427608,0,0,0,40,4449,149.8787,-40289.68359375,,,,,,,,,,,,,0,,,,,,,,,,,,,,
,19734549.27,149.88625,-36721.9453125,5.83184515419022E-5,2.35207432587818E-6,1,0.999253354069792,40.0298881530762,1.99380916545859,14.2400003969669,0.000681705834536334,-1.87895075727066E-7,0.25,-1.01751414748977E-5,5.86206734454511E-5,-1.01332045782463E-5,149.8874,149.8874,-36754.3984375,-36689.4921875,54.207501065698,19.5731342942709,25.186911,0,0,0,40,4449,149.88625,-36721.9453125,,,,,,,,,,,,,0,,,,,,,,,,,,,,
,19734623.415,149.8937,-33019.533203125,4.81326576410935E-5,1.93442669257802E-6,1,0.999253354069792,40.0298881530762,1.99393303051829,14.2400003969669,0.000564823503418662,-1.24975231407779E-5,0.25,-9.48603976195119E-6,4.83837945629459E-5,-9.45658827345861E-6,149.8937,149.8937,-33021.47265625,-33017.59375,54.1606033545442,19.5740137633481,24.807261,0,0,0,40,4449,149.8937,-33019.533203125,,,,,,,,,,,,,0,,,,,,,,,,,,,,
,19734696.99,149.90115,-29341.41796875,3.68609598750414E-5,1.79156098346289E-6,1,0.999253354069792,40.0298881530762,1.99385007846709,14.2400003969669,0.00043566937023259,-2.75582006157391E-5,0.25,-8.85028414006547E-6,3.70557842405471E-5,-8.83537459966999E-6,149.9002,149.9002,-29349.03125,-29333.8046875,54.0879119022557,19.5774936667453,25.186911,0,0,0,40,4449,149.90115,-29341.41796875,,,,,,,,,,,,,0,,,,,,,,,,,,,,
,19734770.235,149.9085,-25681.05078125,2.60008625831514E-5,1.34101664329282E-6,1,0.999253354069792,40.0298881530762,1.99373191907054,14.2400003969669,0.000309012804577697,-2.93068230454795E-5,0.25,-7.11284388725422E-6,2.6139663260491E-5,-7.10650146604189E-6,149.9085,149.9085,-25686.119140625,-25675.982421875,54.1676380112173,19.5796212344569,24.807261,0,0,0,40,4449,149.9085,-25681.05078125,,,,,,,,,,,,,0,,,,,,,,,,,,,,
,19734841.74,149.9138,-22108.2783203125,1.63576524796102E-5,1.20670865934587E-6,1,0.999253354069792,40.0298881530762,1.99386835247011,14.2400003969669,0.000197831733278948,-3.80305943449549E-5,0.25,-6.20182961363313E-6,1.64477190730298E-5,-6.2062517820921E-6,149.9144,149.9144,-22113.255859375,-22103.30078125,54.1402810130442,19.5792666094577,25.186911,0,0,0,40,4449,149.9138,-22108.2783203125,,,,,,,,,,,,,0,,,,,,,,,,,,,,
,19734913.49,149.9197,-18520.4501953125,5.80275138774683E-6,7.78137605560624E-7,1,0.999253354069792,40.0298881530762,1.99375581097445,14.2500000074506,7.47474687066105E-5,-3.97344019635985E-5,0.25,-4.51350489330103E-6,5.83838668770596E-6,-4.52639611889274E-6,149.9183,149.9183,-18530.056640625,-18510.84375,54.1152689004288,19.5796297283017,24.427608,0,0,0,40,4449,149.9197,-18520.4501953125,,,,,,,,,,,,,0,,,,,,,,,,,,,,
,19734987.68,149.9245,-14812.6923828125,-3.64050389187929E-6,9.15127238528465E-7,1,0.999253354069792,40.0298881530762,1.9939298154823,14.2400003969669,-3.23370049563472E-5,-5.86557219136487E-5,0.25,-4.53590128229624E-6,-3.65111451485039E-6,-4.56394329783072E-6,149.9245,149.9245,-14817.87890625,-14807.505859375,54.0675895607557,19.5772096112809,25.186911,0,0,0,40,4449,149.9245,-14812.6923828125,,,,,,,,,,,,,0,,,,,,,,,,,,,,
,19735060.695,149.93175,-11164.4458007813,-1.3998188032084E-5,7.50207407199912E-7,1,0.999253354069792,40.0298881530762,1.99386876042216,14.2500000074506,-0.000150390319312964,-7.59757463831554E-5,0.25,-4.25828110711002E-6,-1.40599909067118E-5,-4.30152069346222E-6,149.9315,149.9315,-11169.6064453125,-11159.28515625,54.0808772455826,19.5795551239843,25.186911,0,0,0,40,4449,149.93175,-11164.4458007813,,,,,,,,,,,,,0,,,,,,,,,,,,,,
,19735135.525,149.93555,-7423.40771484375,-2.16694248877901E-5,6.53305184743366E-7,1,0.999253354069792,40.0298881530762,1.993980135479,14.2400003969669,-0.000242606738429361,-6.14351405740491E-5,0.25,-1.63979431851173E-6,-2.17729896371517E-5,-1.68251909464027E-6,149.9354,149.9354,-7430.79736328125,-7416.01806640625,54.0714977033519,19.5720128564342,24.427608,0,0,0,40,4449,149.93555,-7423.40771484375,,,,,,,,,,,,,0,,,,,,,,,,,,,,
,19735208.915,149.94285,-3757.14233398438,-2.86683730725345E-5,4.32236019828333E-7,1,0.999253354069792,40.0298881530762,1.99381689067347,14.2400003969669,-0.000323741047155657,-6.51952491841705E-5,0.25,-7.52259525963553E-7,-2.88076332870436E-5,-8.01908879451934E-7,149.9428,149.9428,-3762.17651367188,-3752.10815429687,54.3145841728327,19.5727463209727,24.427608,0,0,0,40,4449,149.94285,-3757.14233398438,,,,,,,,,,,,,0,,,,,,,,,,,,,,
,19735283.735,149.94595,-15.7147655487061,-2.49116859843271E-5,3.09504547242008E-7,1,0.999253354069792,40.0298881530762,1.99377265458538,14.2400003969669,-0.000282254570554518,-5.1241208859309E-5,0.25,-1.7677022382775E-7,-2.50334487826577E-5,-2.17626181814266E-7,149.9455,149.9455,-18.2056770324707,-13.2238540649414,54.200466409025,19.5748053637006,24.427608,0,0,0,40,4449,149.94595,-15.7147655487061,,,,,,,,,,,,,0,,,,,,,,,,,,,,
,19735359.035,149.9489,3742.51245117188,-1.22507163090389E-5,4.00530862209333E-7,1,0.999253354069792,40.0298881530762,1.99372205737131,14.2400003969669,-0.000139191099029334,-2.29523478440037E-5,0.25,1.11011925738114E-7,-1.23109172078222E-5,9.19155155478654E-8,149.9482,149.9482,3735.10229492188,3749.92260742188,53.9706676243711,19.5742643411471,24.807261,0,0,0,40,4449,149.9489,3742.51245117188,,,,,,,,,,,,,0,,,,,,,,,,,,,,
,19735432.6,149.94975,7422.21459960937,-3.55579589565693E-6,5.11482584994125E-7,1,0.999253354069792,40.0298881530762,1.99346694834253,14.2500000074506,-4.29123443276121E-5,7.78488460546002E-6,0.25,1.30582261668002E-6,-3.57530973382556E-6,1.3065298297791E-6,149.9501,149.9501,7414.58740234375,7429.841796875,53.8885966298519,19.5778297828545,24.807261,0,0,0,40,4449,149.94975,7422.21459960937,,,,,,,,,,,,,0,,,,,,,,,,,,,,
,19735505.67,149.95035,11078.353515625,1.61827388189042E-6,8.23249846424834E-7,1,0.999253354069792,40.0298881530762,1.99379600147859,14.2400003969669,1.41939338013564E-5,2.71021330830642E-5,0.25,2.10710701752314E-6,1.62283788024817E-6,2.12001895135455E-6,149.9495,149.9495,11073.3974609375,11083.3095703125,53.9018843146788,19.5733178824164,25.186911,0,0,0,40,4449,149.95035,11078.353515625,,,,,,,,,,,,,0,,,,,,,,,,,,,,
,19735580.01,149.9454,14791.4013671875,5.12017523983013E-7,9.08939986304905E-7,1,0.999253354069792,40.0298881530762,1.99372051002707,14.2500000074506,4.31361777353929E-6,9.59171719991651E-6,0.25,7.56333213087825E-7,5.13320984543243E-7,7.60856937447551E-7,149.9454,149.9454,14786.4482421875,14796.3544921875,53.994116479948,19.5745074019241,24.427608,0,0,0,40,4449,149.9454,14791.4013671875,,,,,,,,,,,,,0,,,,,,,,,,,,,,
,19735656.64,149.939,18621.998046875,-7.18611238073964E-6,9.27723347542001E-7,1,0.999253354069792,40.0298881530762,1.99387394012185,14.2400003969669,-8.92985021945483E-5,3.04176338708847E-5,0.25,3.93306503810784E-6,-7.22760122353472E-6,3.94090918061288E-6,149.939,149.939,18619.41015625,18624.5859375,53.9925532229096,19.5717944294709,24.427608,0,0,0,40,4449,149.939,18621.998046875,,,,,,,,,,,,,0,,,,,,,,,,,,,,
,19735732.455,149.9326,22409.900390625,-1.69095192432614E-5,1.80886899872089E-6,1,0.999253354069792,40.0298881530762,1.99374204136542,14.2500000074506,-0.000198419064853698,4.44120859047775E-6,0.25,3.33721715014821E-6,-1.69977318690282E-5,3.32672348932942E-6,149.9326,149.9326,22402.470703125,22417.330078125,54.0238183636788,19.5710732392153,25.186911,0,0,0,40,4449,149.9326,22409.900390625,,,,,,,,,,,,,0,,,,,,,,,,,,,,
,19735808.83,149.92435,26227.451171875,-2.76588552606042E-5,2.068170798314E-6,1,0.999253354069792,40.0298881530762,1.99371598390158,14.2400003969669,-0.000319700626273977,-2.05709589069148E-5,0.25,3.00483410398382E-6,-2.77992638138353E-5,2.97573480373495E-6,149.9248,149.9248,26220.146484375,26234.755859375,53.8753089450249,19.5691815586961,24.807261,0,0,0,40,4449,149.92435,26227.451171875,,,,,,,,,,,,,0,,,,,,,,,,,,,,
,19735886.79,149.91355,30123.52734375,-3.95019237453802E-5,1.6503608851804E-6,1,0.999253354069792,40.0298881530762,1.9935759328146,14.2500000074506,-0.000462175600667723,2.85469468569383E-6,0.25,7.13280752037694E-6,-3.97069733750766E-5,7.10533016653263E-6,149.9136,149.9136,30118.626953125,30128.427734375,54.1011995870826,19.5724650340169,25.186911,0,0,0,40,4449,149.91355,30123.52734375,,,,,,,,,,,,,0,,,,,,,,,,,,,,
,19735962.19,149.90655,33891.646484375,-5.03661525582937E-5,2.59597579050247E-6,1,0.999253354069792,40.0298881530762,1.9937626153478,14.2400003969669,-0.000587752956132945,-5.47520066758782E-6,0.25,8.29084560310061E-6,-5.06263455246261E-5,8.25205515494384E-6,149.9066,149.9066,33886.671875,33896.62109375,54.1645114971403,19.5699340913899,24.807261,0,0,0,40,4449,149.90655,33891.646484375,,,,,,,,,,,,,0,,,,,,,,,,,,,,
,19736038.63,149.8975,37712.171875,-6.40704644583895E-5,3.11989510632167E-6,1,0.999253354069792,40.0298881530762,1.99366301799118,14.2500000074506,-0.00074203713184528,-3.91384244666115E-5,0.25,7.71024778650789E-6,-6.43970177052966E-5,7.64722663370068E-6,149.8982,149.8982,37704.30078125,37720.04296875,53.9706676243711,19.5706989273615,24.807261,0,0,0,40,4449,149.8975,37712.171875,,,,,,,,,,,,,0,,,,,,,,,,,,,,
,19736114.745,149.88945,41517.55078125,-7.42275705261846E-5,2.5302337315373E-6,1,0.999253354069792,40.0298881530762,1.99370535256234,14.2400003969669,-0.000862132631454673,-3.13230686078548E-5,0.25,1.0168251623793E-5,-7.46078761633596E-5,1.01015880026233E-5,149.889,149.889,41517.55078125,41517.55078125,53.8159051775634,19.5709608701201,24.807261,0,0,0,40,4449,149.88945,41517.55078125,,,,,,,,,,,,,0,,,,,,,,,,,,,,
,19736191.92,149.8787,45373.208984375,-8.22370982086106E-5,3.13629183912891E-6,1,0.999253354069792,40.0298881530762,1.99380949852973,14.2500000074506,-0.000951156460736265,-5.79722991735967E-5,0.25,9.21416684703158E-6,-8.26552762131063E-5,9.13056035906006E-6,149.8787,149.8787,45365.66015625,45380.7578125,53.6830283292941,19.5696841956808,24.427608,0,0,0,40,4449,149.8787,45373.208984375,,,,,,,,,,,,,0,,,,,,,,,,,,,,
,19736270.215,149.8697,49289.34375,-9.65617633789889E-5,3.78220158909403E-6,1,0.999253354069792,40.0298881530762,1.99355890220163,14.2500000074506,-0.0011077085609414,-0.00011969928174631,0.25,6.26656445507697E-6,-9.70457310926016E-5,6.14642648702714E-6,149.8699,149.8699,49284.6640625,49294.0234375,53.7549381530634,19.5703518822334,24.807261,0,0,0,40,4449,149.8697,49289.34375,,,,,,,,,,,,,0,,,,,,,,,,,,,,
,19736347.785,149.8609,53163.83984375,-0.000106894598032771,3.79731255014942E-6,1,0.999253354069792,40.0298881530762,1.9935617663279,14.2400003969669,-0.00123320289862434,-9.25570073713061E-5,0.25,1.04587284512873E-5,-0.000107435932864779,1.03434557040142E-5,149.8609,149.8609,53161.38671875,53166.29296875,54.0081857932942,19.5712789374569,24.807261,0,0,0,40,4449,149.8609,53163.83984375,,,,,,,,,,,,,0,,,,,,,,,,,,,,
,19736424.445,149.8527,56997.060546875,-0.00012095192670524,4.04533751647587E-6,1,0.999253354069792,40.0298881530762,1.99355391677376,14.2400003969669,-0.00139916828132374,-8.29363767057657E-5,0.25,1.3754792675284E-5,-0.000121567520194719,1.36342810483933E-5,149.8515,149.8515,56989.40625,57004.71484375,54.0558651329673,19.5695192260588,24.807261,0,0,0,40,4449,149.8527,56997.060546875,,,,,,,,,,,,,0,,,,,,,,,,,,,,
,19736499.61,149.8435,60752.88671875,-0.000138094263864984,3.8528902303557E-6,1,0.999253354069792,40.0298881530762,1.99370901866045,14.2500000074506,-0.00159024256772585,-0.000136884030004512,0.25,1.1984951991361E-5,-0.000138791423977571,1.18296317016598E-5,149.8445,149.8445,60742.84375,60762.9296875,53.8463886898134,19.5687309651543,24.427608,0,0,0,40,4449,149.8435,60752.88671875,,,,,,,,,,,,,0,,,,,,,,,,,,,,
,19736574.865,149.83465,64514.2578125,-0.000144130300451782,3.90495797140663E-6,1,0.999253354069792,40.0298881530762,1.99350546847861,14.2500000074506,-0.00166680912039711,-0.00010140741955948,0.25,1.61621019231254E-5,-0.000144863692580325,1.60185209965476E-5,149.8347,149.8347,64506.9609375,64521.5546875,53.8948496580057,19.5714632892694,24.807261,0,0,0,40,4449,149.83465,64514.2578125,,,,,,,,,,,,,0,,,,,,,,,,,,,,
,19736651.005,149.8237,68317.3203125,-0.000160074479166487,3.49951092693037E-6,1,0.999253354069792,40.0298881530762,1.99323460755029,14.2500000074506,-0.00184700823194701,-0.000135291865271188,0.25,1.5949577217576E-5,-0.000160886026630362,1.5780927213325E-5,149.8237,149.8237,68314.828125,68319.8125,53.790893064948,19.5737967847228,24.807261,0,0,0,40,4449,149.8237,68317.3203125,,,,,,,,,,,,,0,,,,,,,,,,,,,,
,19736728.82,149.8198,72210.13671875,-0.000168536251244314,4.06750258461947E-6,1,0.999253354069792,40.0298881530762,1.99338894449531,14.2400003969669,-0.00194953920054402,-0.000115176399593948,0.25,1.91969170384329E-5,-0.00016939449613884,1.90318891511838E-5,149.8198,149.8198,72207.515625,72212.7578125,53.7064771848711,19.5714121471157,24.427608,0,0,0,40,4449,149.8198,72210.13671875,,,,,,,,,,,,,0,,,,,,,,,,,,,,
,19736806.365,149.80975,76083.8671875,-0.000181996451167429,3.95785308131335E-6,1,0.999253354069792,40.0298881530762,1.9934848087406,14.2400003969669,-0.00210170163332264,-0.000145260340603878,0.25,1.88885992642201E-5,-0.000182920536688361,1.8702097638411E-5,149.8107,149.8107,76076.421875,76091.3125,53.8432621757365,19.5716853051854,24.427608,0,0,0,40,4449,149.80975,76083.8671875,,,,,,,,,,,,,0,,,,,,,,,,,,,,
,19736880.575,149.80145,79791.734375,-0.000197185516332831,4.24689740618278E-6,1,0.999253354069792,40.0298881530762,1.9935110692131,14.2400003969669,-0.00227742021572422,-0.000155751301413506,0.25,2.06082996449146E-5,-0.000198187072696776,2.04077340251293E-5,149.8015,149.8015,79784.3203125,79799.1484375,53.8557682320442,19.5688679435849,25.186911,0,0,0,40,4449,149.80145,79791.734375,,,,,,,,,,,,,0,,,,,,,,,,,,,,
,19736956.245,149.7915,83575.76171875,-0.000210153786954733,3.38164760295395E-6,1,0.999253354069792,40.0298881530762,1.99358133115036,14.2400003969669,-0.00241908712468461,-0.000213060669809373,0.25,1.78141598886332E-5,-0.000211215023182172,1.75808532516663E-5,149.7915,149.7915,83573.03125,83578.4921875,53.5743819651211,19.5705081540813,24.807261,0,0,0,40,4449,149.7915,83575.76171875,,,,,,,,,,,,,0,,,,,,,,,,,,,,
,19737032.25,149.78595,87376.73828125,-0.000221788868750453,3.44315609442167E-6,1,0.999253354069792,40.0298881530762,1.99366727257987,14.2400003969669,-0.00255096312035822,-0.000237284754147087,0.25,1.77047942840233E-5,-0.000222907339514504,1.74541077586522E-5,149.787,149.787,87371.640625,87381.8359375,53.7228913837749,19.5698973550554,24.427608,0,0,0,40,4449,149.78595,87376.73828125,,,,,,,,,,,,,0,,,,,,,,,,,,,,
,19737085.285,149.78075,89999.4453125,-0.000232034536954367,5.14966529310051E-6,1,0.999253354069792,40.0298881530762,1.9937455920708,14.2500000074506,-0.00267392287406976,-0.000219455821557955,0.25,2.10606843211213E-5,-0.000233208653450666,2.08115775998819E-5,149.7813,149.7813,89999.4453125,89999.4453125,53.6642692448326,19.5666758042187,24.427608,0,0,0,40,4417,149.78075,89999.4453125,,,,,,,,,,,,,0,,,,,,,,,,,,,,