File: data/monolayers/magneticStructure/ML_Ac_CoFe_C/PPMS/data/DD205_4_HYST_100OE_50K.DAT
[Header]
; VSM Data File (default extension .dat)
; Copyright (c) 2003-2013, Quantum Design, Inc. All rights reserved.
TITLE,
FILEOPENTIME,32366258.72,01/10/2019,10:39 pm
BYAPP,VSM,2.0,2.0
INFO,PPMS VSM Option Release 1.4.10 Build 1,APPNAME
INFO,Quantum Design Linear Motor Servo Controller,MOTOR_MODULE_NAME
INFO,3101-100 M1,MOTOR_HW_VERSION
INFO,MMC1014,MOTOR_SERIAL_NUMBER
INFO,SRV No X-over 01.03.11,MOTOR_SOFTWARE_VERSION
INFO,Quantum Design VSM Detection Module,VSM_MODULE_NAME
INFO,3101-150 F0,VSM_HW_VERSION
INFO,VSM707,VSM_SERIAL_NUMBER
INFO,VSM No X-over 01.02.05 May 20 2008 13:51:47,VSM_SOFTWARE_VERSION
INFO,704,PREAMP_SERIAL_NUMBER
INFO,822,COIL_SERIAL_NUMBER
INFO,0,MOMENT_UNITS
INFO,DD205_4,SAMPLE_MATERIAL
INFO,Monolayer,SAMPLE_COMMENT
INFO,29.55,SAMPLE_MASS
INFO,,SAMPLE_VOLUME
INFO,,SAMPLE_MOLECULAR_WEIGHT
INFO,,SAMPLE_SIZE
INFO,,SAMPLE_SHAPE
DATATYPE,COMMENT,1
DATATYPE,TIME,2
STARTUPAXIS,X,2
STARTUPAXIS,Y1,5
[Data]
Comment,Time Stamp (sec),Temperature (K),Magnetic Field (Oe),Moment (emu),M. Std. Err. (emu),Transport Action,Averaging Time (sec),Frequency (Hz),Peak Amplitude (mm),Center Position (mm),Coil Signal' (mV),Coil Signal" (mV),Range (mV),M. Quad. Signal (emu),M. Raw' (emu),M. Raw" (emu),Min. Temperature (K),Max. Temperature (K),Min. Field (Oe),Max. Field (Oe),Mass (grams),Motor Lag (deg),Pressure (Torr),VSM Status (code),Motor Status (code),Measure Status (code),Measure Count,PPMS Status (code),System Temp. (K),System Field (Oe),Sample Position (deg),Bridge 1 Resistance (ohms),Bridge 1 Excitation (에),Bridge 2 Resistance (ohms),Bridge 2 Excitation (에),Bridge 3 Resistance (ohms),Bridge 3 Excitation (에),Bridge 4 Resistance (ohms),Bridge 4 Excitation (에),Signal 1 Vin (V),Signal 2 Vin (V),Digital Inputs (code),Drive 1 Iout (mA),Drive 1 Ipower (W),Drive 2 Iout (mA),Drive 2 Ipower (W),Pressure (),Map 20 (),Map 21 (),Map 22 (),Map 23 (),Map 24 (),Map 25 (),Map 26 (),Map 27 (),Map 28 (),Map 29 ()
,32366275.09,50.0000343,-0.380594313144684,,,2,,,,21.2100004553795,,,,,,,50.0000343,50.0000343,-0.380594313144684,-0.380594313144684,,,17.973541,,,,-99999999,4369,50.0426,-0.380594313144684,,,,,,,,,,,,,,,,,,,,,,,50.0000343,,,,
,32366434.31,50.0017509,4528.720703125,2.46365168717546E-5,3.42454633705021E-7,1,0.999253354069792,40.0298881530762,2.00755446369366,21.1999993771315,0.000280425684580783,4.56395074160371E-5,0.25,-4.18896231007007E-7,2.46306065942355E-5,-2.35406958502207E-7,50.0017509,50.0017509,4521.19873046875,4536.24267578125,56.4476484018137,20.5127315365674,17.973541,0,0,0,40,4449,50.0396,4528.720703125,,,,,,,,,,,,,0,,,,0,,,,,,50.0017509,,,,
,32366529.87,50.0010452,9304.82177734375,8.80757502518369E-6,5.8021927983777E-7,1,0.999253354069792,40.0298881530762,2.00764893088974,21.1999993771315,0.000102053437031874,6.48398933833637E-6,0.25,-1.01632018523655E-6,8.81397041459559E-6,-9.50664900548691E-7,50.0010452,50.0010452,9297.4130859375,9312.23046875,56.6954246424098,20.5179561539929,17.593889,0,0,0,40,4449,50.03505,9304.82177734375,,,,,,,,,,,,,0,,,,0,,,,,,50.0010452,,,,
,32366623.405,50.0017738,13979.810546875,-5.55089170004473E-6,6.9017566894585E-7,1,0.999253354069792,40.0298881530762,2.00770048554746,21.1999993771315,-5.9588261490937E-5,-3.04272949480758E-5,0.25,-1.67940032331767E-6,-5.53905497011458E-6,-1.72082842103969E-6,50.0017738,50.0017738,13969.8544921875,13989.7666015625,56.6821369575829,20.5223820352944,17.973541,0,0,0,40,4449,50.0335,13979.810546875,,,,,,,,,,,,,0,,,,0,,,,,,50.0017738,,,,
,32366716.68,50.001503,18640.1044921875,-2.09162687017357E-5,6.4252606461122E-7,1,0.999253354069792,40.0298881530762,2.00751616607289,21.1999993771315,-0.000233676059850942,-6.41593405134579E-5,0.25,-1.88044680238815E-6,-2.0910062766646E-5,-2.0361091115563E-6,50.001503,50.001503,18637.54296875,18642.666015625,56.8978664288906,20.5204695268299,17.973541,0,0,0,40,4449,50.03255,18640.1044921875,,,,,,,,,,,,,0,,,,0,,,,,,50.001503,,,,
,32366813.835,50.0015907,23497.4462890625,-3.69404735715348E-5,6.91893723018962E-7,1,0.999253354069792,40.0298881530762,2.00750405984686,21.1999993771315,-0.000417001431975209,-9.0063758416855E-5,0.25,-1.27290499408181E-6,-3.69545981736409E-5,-1.54629585806617E-6,50.0015907,50.0015907,23489.884765625,23505.0078125,57.1003082153714,20.5184009962329,17.973541,0,0,0,40,4449,50.0303,23497.4462890625,,,,,,,,,,,,,0,,,,0.0049,,,,,,50.0015907,,,,
,32366906.45,50.0017128,28127.7841796875,-5.31940079351121E-5,9.03234341209615E-7,1,0.999253354069792,40.0298881530762,2.00760255908373,21.1999993771315,-0.000598362375307719,-0.000142486210506013,0.25,-2.95771376868773E-6,-5.32196773911686E-5,-3.3508567622197E-6,50.0017128,50.0017128,28122.978515625,28132.58984375,57.3050948874099,20.5211268816613,18.353191,0,0,0,40,4449,50.02965,28127.7841796875,,,,,,,,,,,,,0,,,,0.0049,,,,,,50.0017128,,,,
,32367001.66,50.0015907,32885.5703125,-6.90515663962536E-5,1.05948911351698E-6,1,0.999253354069792,40.0298881530762,2.00758206838736,21.1999993771315,-0.000780540337262573,-0.000164981467351304,0.25,-2.0807191114255E-6,-6.91157268281888E-5,-2.58674730569015E-6,50.0015907,50.0015907,32880.6015625,32890.5390625,57.0362146767945,20.5183706032056,18.353191,0,0,0,40,4449,50.03135,32885.5703125,,,,,,,,,,,,,0,,,,0.00245,,,,,,50.0015907,,,,
,32367097.21,50.00086785,37657.90234375,-8.56146089058889E-5,1.32658902657181E-6,1,0.999253354069792,40.0298881530762,2.00761958197805,21.1999993771315,-0.000972020879311522,-0.000182424673007025,0.25,-6.33255995458566E-7,-8.57299850844601E-5,-1.25382119955557E-6,50.0007591,50.0009766,37647.921875,37667.8828125,57.3433946848522,20.5185620400233,18.353191,0,0,0,40,4449,50.0268,37657.90234375,,,,,,,,,,,,,0,,,,0,,,,,,50.00086785,,,,
,32367191.495,50.0014915,42372.927734375,-0.000102717813790853,1.02418577466636E-6,1,0.999253354069792,40.0298881530762,2.00742168088616,21.1999993771315,-0.00116403197267117,-0.00023192335190878,0.25,-1.911711522446E-6,-0.000102873077042083,-2.65189022614987E-6,50.0014915,50.0014915,42365.7109375,42380.14453125,56.8767624588714,20.5182728146256,17.973541,0,0,0,40,4449,50.0279,42372.927734375,,,,,,,,,,,,,0,,,,0,,,,,,50.0014915,,,,
,32367287.805,50.0023994,47186.115234375,-0.000117693076088835,1.30614512236296E-6,1,0.999253354069792,40.0298881530762,2.00761519850935,21.1999993771315,-0.00133039869789256,-0.000286854695466425,0.25,-4.04788319353563E-6,-0.000117886350739297,-4.89167121168376E-6,50.0023994,50.0023994,47178.4375,47193.79296875,57.1229754424291,20.5183636593008,17.973541,0,0,0,40,4449,50.0295,47186.115234375,,,,,,,,,,,,,0,,,,0,,,,,,50.0023994,,,,
,32367385.01,50.001091,52046.216796875,-0.000136839697992193,1.27784869262106E-6,1,0.999253354069792,40.0298881530762,2.00756068178579,21.1999993771315,-0.00154773657822899,-0.000330368559590485,0.25,-4.43395861005644E-6,-0.000137098811009356,-5.40494320823018E-6,50.001091,50.001091,52036.203125,52056.23046875,56.9705578811791,20.5198069122712,17.973541,0,0,0,40,4449,50.02785,52046.216796875,,,,,,,,,,,,,0,,,,0,,,,,,50.001091,,,,
,32367479.47,50.0006104,56766.251953125,-0.000155136209968482,1.22727583497909E-6,1,0.999253354069792,40.0298881530762,2.00776320900705,21.1999993771315,-0.00175221422134369,-0.000391481405628674,0.25,-6.51755994645746E-6,-0.000155454046905853,-7.61050021295578E-6,50.0006104,50.0006104,56763.70703125,56768.796875,57.2394380917945,20.5210309316635,17.593889,0,0,0,40,4449,50.02605,56766.251953125,,,,,,,,,,,,,0,,,,0,,,,,,50.0006104,,,,
,32367574.78,50.0012054,61531.552734375,-0.000171561604319174,1.10190405917659E-6,1,0.999253354069792,40.0298881530762,2.00763942866989,21.1999993771315,-0.00194671842171586,-0.00038466562711487,0.25,-2.97631856267773E-6,-0.000171979176407606,-4.16105913346904E-6,50.0012054,50.0012054,61521.859375,61541.24609375,57.1995750373137,20.5192018968271,17.973541,0,0,0,40,4449,50.02235,61531.552734375,,,,,,,,,,,,,0,,,,0,,,,,,50.0012054,,,,
,32367670.415,50.0022545,66309.359375,-0.000191723643009657,1.54698684039304E-6,1,0.999253354069792,40.0298881530762,2.00757959039427,21.1999993771315,-0.0021710221430633,-0.000457020018794648,0.25,-5.72145429858822E-6,-0.000192213622024954,-7.03552984985553E-6,50.0022545,50.0022545,66304.84375,66313.875,57.3144744296407,20.5196666898397,18.353191,0,0,0,40,4449,50.0236,66309.359375,,,,,,,,,,,,,0,,,,-0.00245,,,,,,50.0022545,,,,
,32367764.78,50.0026798,71027.17578125,-0.000204977264586966,9.38919530112131E-7,1,0.999253354069792,40.0298881530762,2.00765162254313,21.1999993771315,-0.00231906229226683,-0.000503048029710377,0.25,-7.39367843299403E-6,-0.000205532624268192,-8.78485976405144E-6,50.0023994,50.0029602,71017.2890625,71037.0625,57.1558038402368,20.5183070045474,18.353191,0,0,0,40,4449,50.01955,71027.17578125,,,,,,,,,,,,,0,,,,-0.0049,,,,,,50.0026798,,,,
,32367860.61,50.0019302,75817.9765625,-0.00022431357790015,1.49529638599001E-6,1,0.999253354069792,40.0298881530762,2.00759364541449,21.1999993771315,-0.00254434562333955,-0.0005165502035365,0.25,-5.12390767970254E-6,-0.000224983706861749,-6.61714336249659E-6,50.0019302,50.0019302,75810.25,75825.703125,57.2066096939868,20.5188263553101,18.353191,0,0,0,40,4449,50.02115,75817.9765625,,,,,,,,,,,,,0,,,,-0.00245,,,,,,50.0019302,,,,
,32367954.01,50.00086975,80486.5546875,-0.000239613079248879,1.60562935434894E-6,1,0.999253354069792,40.0298881530762,2.00769147395237,21.1999993771315,-0.00271847658957264,-0.000551958033385696,0.25,-5.50096070031674E-6,-0.00024037088786074,-7.07446175101165E-6,50.000824,50.0009155,80474.1328125,80498.9765625,57.1761261817368,20.5178613990062,18.732843,0,0,0,40,4449,50.01825,80486.5546875,,,,,,,,,,,,,0,,,,0,,,,,,50.00086975,,,,
,32368049.715,50.0010071,85269.5625,-0.00025623166806473,1.06805470489471E-6,1,0.999253354069792,40.0298881530762,2.00767316337073,21.1999993771315,-0.00290952948422406,-0.000578949702146587,0.25,-4.90857491881567E-6,-0.00025709228517391,-6.56369321601401E-6,50.0010071,50.0010071,85262.0703125,85277.0546875,57.159711982833,20.5151836949152,18.353191,0,0,0,40,4449,50.01465,85269.5625,,,,,,,,,,,,,0,,,,0.0049,,,,,,50.0010071,,,,
,32368138.3,50.0012817,89697.6484375,-0.000272125190020258,1.37193359483842E-6,1,0.999253354069792,40.0298881530762,2.00759093157807,21.1999993771315,-0.00308452418871877,-0.000647467370119581,0.25,-8.0936399472414E-6,-0.000273062647616972,-9.83749827203847E-6,50.0012817,50.0012817,89690.234375,89705.0625,57.0526288756983,20.5158820486364,18.353191,0,0,0,40,4449,50.0255,89697.6484375,,,,,,,,,,,,,0,,,,0,,,,,,50.0012817,,,,
,32368244.715,49.9998131,85961.51953125,-0.000260227899354052,1.36206077320101E-6,1,0.999253354069792,40.0298881530762,2.00774056761313,21.1999993771315,-0.00295257985721376,-0.000601932839908402,0.25,-6.21058590687537E-6,-0.000261100495177352,-7.89216556816089E-6,49.9998131,49.9998131,85954.1796875,85968.859375,57.1487691835637,20.5186737943012,18.353191,0,0,0,40,4449,50.01735,85961.51953125,,,,,,,,,,,,,0,,,,0,,,,,,49.9998131,,,,
,32368337.37,50.00027655,81330.3828125,-0.000244099731831743,1.62230606701583E-6,1,0.999253354069792,40.0298881530762,2.00764184888327,21.1999993771315,-0.00277119432486445,-0.000552284700553324,0.25,-4.72934847807862E-6,-0.000244885036361322,-6.32530761599529E-6,50.0002365,50.0003166,81325.328125,81335.4375,57.3090030300061,20.5217933307141,18.732843,0,0,0,40,4449,50.0209,81330.3828125,,,,,,,,,,,,,0,,,,-0.0049,,,,,,50.00027655,,,,
,32368432.405,50.0001259,76576.5390625,-0.000223661236355009,1.36323119872472E-6,1,0.999253354069792,40.0298881530762,2.0077323811212,21.1999993771315,-0.00253475727331517,-0.000528640035436853,0.25,-6.30140076476484E-6,-0.000224328019392871,-7.7908517207398E-6,50.0001259,50.0001259,76571.6875,76581.390625,56.9893169656406,20.5203885483889,18.732843,0,0,0,40,4449,50.01775,76576.5390625,,,,,,,,,,,,,0,,,,0,,,,,,50.0001259,,,,
,32368528.515,49.9997025,71773.01953125,-0.00020815376102996,9.66295403739292E-7,1,0.999253354069792,40.0298881530762,2.00769899028593,21.1999993771315,-0.00236118382102274,-0.000477093966362049,0.25,-4.54536400270316E-6,-0.000208743700426686,-5.94648249309738E-6,49.9997025,49.9997025,71767.9609375,71778.078125,56.9822823089676,20.5186383792486,18.353191,0,0,0,40,4449,50.01655,71773.01953125,,,,,,,,,,,,,0,,,,0,,,,,,49.9997025,,,,
,32368623.415,50.0002632,67029.703125,-0.000189778912749283,1.10274395098101E-6,1,0.999253354069792,40.0298881530762,2.00787083222978,21.1999993771315,-0.00215348397955385,-0.000429498076977866,0.25,-3.64941758708416E-6,-0.000190283195728219,-4.94215865605873E-6,50.0002632,50.0002632,67024.234375,67035.171875,57.1987934087945,20.5196870958625,18.353191,0,0,0,40,4449,50.0192,67029.703125,,,,,,,,,,,,,0,,,,0,,,,,,50.0002632,,,,
,32368717.88,49.9995041,62306.16015625,-0.000172394323393043,1.02156973745705E-6,1,0.999253354069792,40.0298881530762,2.00788015626851,21.1999993771315,-0.00195375831990803,-0.000401612813213672,0.25,-4.31286552520165E-6,-0.000172810688566318,-5.50443542789023E-6,49.9995041,49.9995041,62296.05859375,62316.26171875,57.2769562607176,20.5195148709567,17.973541,0,0,0,40,4449,50.0205,62306.16015625,,,,,,,,,,,,,0,,,,-0.00245,,,,,,49.9995041,,,,
,32368813.775,49.9996605,57515.84765625,-0.000155507502650215,1.20906028914011E-6,1,0.999253354069792,40.0298881530762,1.99532404630433,21.1999993771315,-0.00174781922543451,-0.000380442797445695,0.25,-5.68058452089963E-6,-0.000155837192189796,-6.77235972851223E-6,49.9996605,49.9996605,57503.3203125,57528.375,57.566158812833,20.5211700209547,18.732843,0,0,0,40,4449,50.0182,57515.84765625,,,,,,,,,,,,,0,,,,-0.00245,,,,,,49.9996605,,,,
,32368909.04,49.9998627,52753.083984375,-0.000139143129484642,8.48022971088572E-7,1,0.999253354069792,40.0298881530762,1.99543089952359,21.1999993771315,-0.00156625167383185,-0.000325740652699659,0.25,-3.77970448716819E-6,-0.000139416201084962,-4.76405224047129E-6,49.9998627,49.9998627,52740.625,52765.54296875,57.1948852661984,20.5225708601597,18.353191,0,0,0,40,4449,50.019,52753.083984375,,,,,,,,,,,,,0,,,,0,,,,,,49.9998627,,,,
,32369001.285,49.99996375,48140.373046875,-0.000122662300716542,9.3328283452733E-7,1,0.999253354069792,40.0298881530762,1.9954272968381,21.1999993771315,-0.00138001818040109,-0.000289364406781254,0.25,-3.52347589623499E-6,-0.0001228742092062,-4.40000856093813E-6,49.9998169,50.0001106,48102.9921875,48177.75390625,57.2535074051407,20.521366928741,18.732843,0,0,0,40,4449,50.01835,48140.373046875,,,,,,,,,,,,,0,,,,-0.0049,,,,,,49.99996375,,,,
,32369098.06,50.0001526,43305.29296875,-0.000105795675015047,8.05199823143331E-7,1,0.999253354069792,40.0298881530762,1.99525985283389,21.1999993771315,-0.00119075575684147,-0.000244610962891605,0.25,-2.59914088986947E-6,-0.000105955963980501,-3.36130123339251E-6,50.0001526,50.0001526,43295.265625,43315.3203125,57.1487691835637,20.5198094722597,17.973541,0,0,0,40,4449,50.0211,43305.29296875,,,,,,,,,,,,,0,,,,0.0049,,,,,,50.0001526,,,,
,32369192.635,50.0001984,38579.9140625,-8.78453738882892E-5,8.40094703320723E-7,1,0.999253354069792,40.0298881530762,1.99536855228875,21.1999993771315,-0.000989525442008522,-0.000197544299519306,0.25,-1.66358229163142E-6,-8.79605283952806E-5,-2.3008235580776E-6,50.0001984,50.0001984,38572.5703125,38587.2578125,57.4293738219676,20.5229632372153,18.732843,0,0,0,40,4449,50.01935,38579.9140625,,,,,,,,,,,,,0,,,,-0.00245,,,,,,50.0001984,,,,
,32369285.97,50.0003624,33912.71484375,-7.25811820648156E-5,7.80910012824454E-7,1,0.999253354069792,40.0298881530762,1.99534371778285,21.1999993771315,-0.000814219029437319,-0.000180684599116914,0.25,-2.91972746068172E-6,-7.26470951459157E-5,-3.45183512828447E-6,50.0003624,50.0003624,33905.109375,33920.3203125,57.4371901071599,20.5222396713502,18.353191,0,0,0,40,4449,50.01905,33912.71484375,,,,,,,,,,,,,0,,,,0,,,,,,50.0003624,,,,
,32369380.83,49.9994011,29172.515625,-5.59557195497182E-5,7.94633694069455E-7,1,0.999253354069792,40.0298881530762,1.99557656739903,21.1999993771315,-0.000628117360696069,-0.000136530640640762,0.25,-2.00503433582983E-6,-5.59939499729205E-5,-2.41718920287327E-6,49.9994011,49.9994011,29162.525390625,29182.505859375,57.4090514804676,20.5206708891033,17.973541,0,0,0,40,4449,50.0223,29172.515625,,,,,,,,,,,,,0,,,,-0.0049,,,,,,49.9994011,,,,
,32369475.485,50.00017355,24442.3818359375,-3.9514443731296E-5,7.32026760748055E-7,1,0.999253354069792,40.0298881530762,1.99536381461412,21.1999993771315,-0.000442346262396503,-0.000102220599244965,0.25,-1.93142785127197E-6,-3.95272896413383E-5,-2.22406667931207E-6,50.0000076,50.0003395,24434.849609375,24449.9140625,57.4098331089868,20.5206567008462,18.732843,0,0,0,40,4449,50.0178,24442.3818359375,,,,,,,,,,,,,0,,,,-0.00245,,,,,,50.00017355,,,,
,32369568.69,50.0002937,19784.828125,-2.40489416862471E-5,6.56348771322733E-7,1,0.999253354069792,40.0298881530762,1.99544312145431,21.1999993771315,-0.000268749869064189,-6.44624838867599E-5,0.25,-1.37516706016609E-6,-2.40490723174908E-5,-1.55379402447471E-6,50.0002937,50.0002937,19782.333984375,19787.322265625,57.0870205305445,20.5215751252464,18.732843,0,0,0,40,4449,50.0191,19784.828125,,,,,,,,,,,,,0,,,,-0.00245,,,,,,50.0002937,,,,
,32369664.25,50.0005226,15007.7578125,-7.69595330261242E-6,4.85562781212202E-7,1,0.999253354069792,40.0298881530762,1.99550893291896,21.1999993771315,-8.49660210371874E-5,-2.62678625110057E-5,0.25,-9.39837141418896E-7,-7.6902514868684E-6,-9.97137848688233E-7,50.0005226,50.0005226,15005.087890625,15010.427734375,57.4481329064291,20.519095307616,18.353191,0,0,0,40,4449,50.0165,15007.7578125,,,,,,,,,,,,,0,,,,0,,,,,,50.0005226,,,,
,32369758.375,50.0005226,10302.6459960938,8.09998691230534E-6,3.91532884581315E-7,1,0.999253354069792,40.0298881530762,1.99550699520722,21.1999993771315,9.27663548495618E-5,8.98610463281396E-6,0.25,-6.63773955375409E-7,8.10423897933561E-6,-6.03472268489994E-7,50.0005226,50.0005226,10297.625,10307.6669921875,57.2894623170253,20.5187122917925,17.973541,0,0,0,40,4449,50.02125,10302.6459960938,,,,,,,,,,,,,0,,,,0.0049,,,,,,50.0005226,,,,
,32369853.49,50.0005455,5549.62426757812,2.34212668710722E-5,3.59815387558788E-7,1,0.999253354069792,40.0298881530762,1.99543305000363,21.1999993771315,0.000265116888219315,4.28680310025078E-5,0.25,-4.22333985441934E-7,2.34167822205074E-5,-2.47901817183508E-7,50.0005455,50.0005455,5544.470703125,5554.77783203125,57.1307917276214,20.5224819582697,18.353191,0,0,0,40,4449,50.0165,5549.62426757812,,,,,,,,,,,,,0,,,,0,,,,,,50.0005455,,,,
,32369947.195,50.0001335,863.593444824219,3.73086734779361E-5,3.91841588884402E-7,1,0.999253354069792,40.0298881530762,1.99551537033638,21.1999993771315,0.000421233986817868,7.3898845191127E-5,0.25,-1.74211188610239E-7,3.72903767630445E-5,1.0342396136669E-7,50.0001335,50.0001335,856.145080566406,871.041809082031,57.5395834431792,20.5217470309633,18.353191,0,0,0,40,4449,50.0187,863.593444824219,,,,,,,,,,,,,0,,,,-0.0049,,,,,,50.0001335,,,,
,32370041.56,50.0004196,-3847.03381347656,4.94628064746991E-5,3.30163258029693E-7,1,0.999253354069792,40.0298881530762,1.99553999452008,21.1999993771315,0.000558370715075436,9.88991178116776E-5,0.25,-1.50114212894074E-7,4.94439966516268E-5,2.180163675375E-7,50.0004196,50.0004196,-3851.86499023438,-3842.20263671875,57.0745144742368,20.5228547125798,18.732843,0,0,0,40,4449,50.02265,-3847.03381347656,,,,,,,,,,,,,0,,,,-0.0049,,,,,,50.0004196,,,,
,32370137.75,50.0017776,-8656.36474609375,5.98914130014671E-5,4.48535911068774E-7,1,0.999253354069792,40.0298881530762,1.99555278633711,21.1999993771315,0.000674726794311911,0.000128268037736819,0.25,5.70622793040157E-7,5.98769123772274E-5,1.01612133688838E-6,50.0017776,50.0017776,-8666.3935546875,-8646.3359375,57.586481154333,20.5226349973491,18.732843,0,0,0,40,4449,50.0168,-8656.36474609375,,,,,,,,,,,,,0,,,,0,,,,,,50.0017776,,,,
,32370235.08,49.999897,-13522.6098632812,6.52296014639704E-5,4.02720159867297E-7,1,0.999253354069792,40.0298881530762,1.99554456494548,21.1999993771315,0.000734835764295577,0.000140934299031653,0.25,7.28403411032564E-7,6.52297636890184E-5,1.21313591029875E-6,49.999897,49.999897,-13530.1630859375,-13515.056640625,57.4661103623715,20.5207937063251,18.732843,0,0,0,40,4449,50.0166,-13522.6098632812,,,,,,,,,,,,,0,,,,0.0049,,,,,,49.999897,,,,
,32370329.85,50.0003738,-18259.5185546875,6.27758560088562E-5,4.6981600652063E-7,1,0.999253354069792,40.0298881530762,1.99554093660628,21.1999993771315,0.000708246342073351,0.000130836499699108,0.25,2.74434965166962E-7,6.27954720721357E-5,7.39775495990611E-7,50.0003738,50.0003738,-18266.724609375,-18252.3125,57.5200427301984,20.5221556815866,18.353191,0,0,0,40,4449,50.0197,-18259.5185546875,,,,,,,,,,,,,0,,,,0,,,,,,50.0003738,,,,
,32370423.005,50.0008621,-22914.44921875,5.9629090068809E-5,5.63773949454055E-7,1,0.999253354069792,40.0298881530762,1.99564890101617,21.1999993771315,0.000672882104777919,0.000124698507410144,0.25,2.96285831710863E-7,5.9662736853501E-5,7.36734648679022E-7,50.0008621,50.0008621,-22924.681640625,-22904.216796875,57.5090999309292,20.5207907423994,18.353191,0,0,0,40,4449,50.017,-22914.44921875,,,,,,,,,,,,,0,,,,0.00245,,,,,,50.0008621,,,,
,32370518.435,50.0021973,-27681.94921875,6.19247002746958E-5,7.32839560939343E-7,1,0.999253354069792,40.0298881530762,1.99556903108325,21.1999993771315,0.000697685486517813,0.000136508253058922,0.25,9.28011251562849E-7,6.19713117668328E-5,1.3836981865751E-6,50.0021973,50.0021973,-27686.935546875,-27676.962890625,57.3543374841214,20.524183565762,18.732843,0,0,0,40,4449,50.0154,-27681.94921875,,,,,,,,,,,,,0,,,,-0.00245,,,,,,50.0021973,,,,
,32370613.04,50.0015564,-32414.2421875,7.15830707149592E-5,8.39149124955517E-7,1,0.999253354069792,40.0298881530762,1.99562311608448,21.1999993771315,0.00080888369052486,0.000145889698533274,0.25,1.83338477585234E-8,7.16630357060558E-5,5.40885899372782E-7,50.0015564,50.0015564,-32424.037109375,-32404.447265625,57.5802281261792,20.5246218662367,18.353191,0,0,0,40,4449,50.0117,-32414.2421875,,,,,,,,,,,,,0,,,,0,,,,,,50.0015564,,,,
,32370709,50.002346,-37206.17578125,8.69104480151863E-5,8.80781833882349E-7,1,0.999253354069792,40.0298881530762,1.99575645784396,21.1999993771315,0.000981409510859709,0.000182656522716735,0.25,5.11333621412926E-7,8.70261877981666E-5,1.14164566315733E-6,50.002346,50.002346,-37216.32421875,-37196.02734375,57.2378748347561,20.5229091831632,19.112494,0,0,0,40,4449,50.0129,-37206.17578125,,,,,,,,,,,,,0,,,,-0.0049,,,,,,50.002346,,,,
,32370807.25,50.0013275,-42116.4609375,0.000103269319338963,7.63368720976414E-7,1,0.999253354069792,40.0298881530762,1.99568189623896,21.1999993771315,0.00116356749303156,0.000232781576102689,0.25,2.00269871375785E-6,0.000103423208630453,2.7473965290887E-6,50.0013275,50.0013275,-42118.8515625,-42114.0703125,57.4207759082561,20.5202461474345,18.353191,0,0,0,40,4449,50.0154,-42116.4609375,,,,,,,,,,,,,0,,,,0,,,,,,50.0013275,,,,
,32370903.22,50.0014572,-46913.947265625,0.000119332943277293,8.38894758186896E-7,1,0.999253354069792,40.0298881530762,1.99574630852819,21.1999993771315,0.00134816406162221,0.000251069023658529,0.25,7.31685040758006E-7,0.000119550890319014,1.58146956650599E-6,50.0014572,50.0014572,-46921.828125,-46906.06640625,57.5114448164869,20.5232046268832,18.732843,0,0,0,40,4449,50.01335,-46913.947265625,,,,,,,,,,,,,0,,,,-0.0049,,,,,,50.0014572,,,,
,32370998.46,50.0010681,-51673.568359375,0.000136238715252889,8.66524783451544E-7,1,0.999253354069792,40.0298881530762,1.99568067443693,21.1999993771315,0.00153645160448544,0.000303437416888471,0.25,2.3258500104641E-6,0.000136508474479753,3.28908814151952E-6,50.0010681,50.0010681,-51678.60546875,-51668.53125,57.2996234877753,20.522612703481,19.112494,0,0,0,40,4449,50.0093,-51673.568359375,,,,,,,,,,,,,0,,,,0.00245,,,,,,50.0010681,,,,
,32371095.46,49.9997406,-56520.845703125,0.000154220154502064,9.43087523818744E-7,1,0.999253354069792,40.0298881530762,1.99568814057463,21.1999993771315,0.00173901541318294,0.000347045867098241,0.25,2.95331112078663E-6,0.000154558457847194,4.03232229713704E-6,49.9997406,49.9997406,-56525.96484375,-56515.7265625,56.9682129956214,20.5257721261272,18.732843,0,0,0,40,4449,50.01065,-56520.845703125,,,,,,,,,,,,,0,,,,0.00245,,,,,,49.9997406,,,,
,32371191.54,50.0014725,-61322.955078125,0.000170421645870575,1.03895774755321E-6,1,0.999253354069792,40.0298881530762,1.99567574661071,21.1999993771315,0.00192308297887254,0.00037816714128899,0.25,2.79974745045941E-6,0.000170835629015019,3.97697106475862E-6,50.0014725,50.0014725,-61328.40625,-61317.50390625,57.3441763133715,20.522742406497,18.353191,0,0,0,40,4449,50.0106,-61322.955078125,,,,,,,,,,,,,0,,,,0.00245,,,,,,50.0014725,,,,
,32371289.085,50.0002289,-66197.6640625,0.000187797528662003,9.6215428893518E-7,1,0.999253354069792,40.0298881530762,1.99562659022549,21.1999993771315,0.00212052295753285,0.000411388770658303,0.25,2.62436403208738E-6,0.000188296391286758,3.90386715789473E-6,50.0002289,50.0002289,-66210.2890625,-66185.0390625,57.2058280654676,20.5257375434873,18.732843,0,0,0,40,4449,50.01,-66197.6640625,,,,,,,,,,,,,0,,,,-0.00245,,,,,,50.0002289,,,,
,32371387.36,50.0010662,-71112.40234375,0.000207085996367486,1.18893344164257E-6,1,0.999253354069792,40.0298881530762,1.99558262218524,21.1999993771315,0.0023354984891463,0.000471787782071052,0.25,4.50925293035696E-6,0.000207667150392385,5.9058728392506E-6,50.0010605,50.0010719,-71117.3125,-71107.4921875,56.8275198621599,20.5259580021946,18.732843,0,0,0,40,4449,50.0052,-71112.40234375,,,,,,,,,,,,,0,,,,0,,,,,,50.0010662,,,,
,32371483.465,50.0019035,-75912.14453125,0.000223127608838607,1.32159333307103E-6,1,0.999253354069792,40.0298881530762,1.99558982801838,21.1999993771315,0.00251381467759534,0.000525620501386856,0.25,6.39790858204826E-6,0.000223785957140648,7.88717006976367E-6,50.0019035,50.0019035,-75914.578125,-75909.7109375,57.7787617700638,20.5263739232328,18.732843,0,0,0,40,4449,50.0045,-75912.14453125,,,,,,,,,,,,,0,,,,-0.0049,,,,,,50.0019035,,,,
,32371581.015,49.9996414,-80789.5390625,0.000241330511636028,1.2305422077892E-6,1,0.999253354069792,40.0298881530762,1.99572681738203,21.1999993771315,0.00272305982075412,0.000549163234445657,0.25,5.22425775544163E-6,0.000242097950294931,6.80684662511753E-6,49.9996414,49.9996414,-80796.8984375,-80782.1796875,57.3136928011214,20.5280935718113,18.353191,0,0,0,40,4449,49.9994,-80789.5390625,,,,,,,,,,,,,0,,,,0,,,,,,49.9996414,,,,
,32371676.205,50.00047875,-85546.58984375,0.000259393218705999,1.25405810418817E-6,1,0.999253354069792,40.0298881530762,1.99567109412959,21.1999993771315,0.00292653275700448,0.000594587787588263,0.25,6.01495138646018E-6,0.00026026005994531,7.69283698148394E-6,50.0002632,50.0006943,-85554.171875,-85539.0078125,57.332451885583,20.5259681486397,18.732843,0,0,0,40,4449,50.00665,-85546.58984375,,,,,,,,,,,,,0,,,,0,,,,,,50.00047875,,,,
,32371785.42,50.0009537,-89963.37109375,0.000274978610915298,1.29739870604049E-6,1,0.999253354069792,40.0298881530762,1.99587358526208,21.1999993771315,0.0031053997568341,0.000617834681296702,0.25,5.28685602158183E-6,0.00027594604300365,7.03733567731925E-6,50.0009537,50.0009537,-89965.4140625,-89961.328125,57.7818882841407,20.5259659931765,19.112494,0,0,0,40,4449,50.0075,-89963.37109375,,,,,,,,,,,,,0,,,,0,,,,,,50.0009537,,,,
,32371876.56,49.9987793,-85425.23828125,0.000257544388315255,1.29110338443296E-6,1,0.999253354069792,40.0298881530762,1.99581628875711,21.1999993771315,0.00290249624573108,0.000609192443945406,0.25,7.63114535782465E-6,0.000258393482771929,9.30340630313315E-6,49.9987793,49.9987793,-85430.1484375,-85420.328125,57.2550706621791,20.5231048411653,19.112494,0,0,0,40,4449,50.01095,-85425.23828125,,,,,,,,,,,,,0,,,,-0.00245,,,,,,49.9987793,,,,
,32371970.435,50.0003738,-80732.69921875,0.000241251788797344,1.28028415486933E-6,1,0.999253354069792,40.0298881530762,1.99578783088434,21.1999993771315,0.0027208889068452,0.0005565753476927,0.25,5.89115149959409E-6,0.000242014271745184,7.47563884891139E-6,50.0003738,50.0003738,-80737.7421875,-80727.65625,57.5880444113715,20.5239094774622,18.353191,0,0,0,40,4449,50.00415,-80732.69921875,,,,,,,,,,,,,0,,,,0,,,,,,50.0003738,,,,
,32372065.515,50.0002747,-75980.24609375,0.000222452390333277,9.68054645421079E-7,1,0.999253354069792,40.0298881530762,1.99580762183201,21.1999993771315,0.00250872601398456,0.000511543948183509,0.25,5.27151385163872E-6,0.000223116757614487,6.75243647991971E-6,50.0002747,50.0002747,-75985.1953125,-75975.296875,57.4684552479292,20.5250269196741,18.732843,0,0,0,40,4449,50.0091,-75980.24609375,,,,,,,,,,,,,0,,,,0,,,,,,50.0002747,,,,
,32372162.165,50.000473,-71153.1796875,0.00020669088228092,1.13457394323239E-6,1,0.999253354069792,40.0298881530762,1.99584160442238,21.1999993771315,0.00232850068885829,0.000486740969284031,0.25,5.89562279946015E-6,0.000207261938153767,7.29354626116079E-6,50.000473,50.000473,-71158.203125,-71148.15625,57.3965454241599,20.5231525226435,18.732843,0,0,0,40,4449,50.0047,-71153.1796875,,,,,,,,,,,,,0,,,,0,,,,,,50.000473,,,,
,32372259.28,49.9992027,-66295.890625,0.000188755607850743,8.94706679438344E-7,1,0.999253354069792,40.0298881530762,1.99588288743766,21.1999993771315,0.00213235464654697,0.000409387113622179,0.25,2.27124836530013E-6,0.000189260095131557,3.55600904781729E-6,49.9992027,49.9992027,-66300.9921875,-66290.7890625,57.187068981006,20.518987278211,19.112494,0,0,0,40,4449,50.00335,-66295.890625,,,,,,,,,,,,,0,,,,0.00245,,,,,,49.9992027,,,,
,32372354.54,50.0002937,-61538.486328125,0.000172521548404667,1.20093317417625E-6,1,0.999253354069792,40.0298881530762,1.9957448331605,21.1999993771315,0.00194476696594335,0.000394497664875743,0.25,3.86463814569335E-6,0.000172935111051522,5.05837752995781E-6,50.0002937,50.0002937,-61543.44921875,-61533.5234375,57.4715817620061,20.52100232988,18.732843,0,0,0,40,4449,50.0072,-61538.486328125,,,,,,,,,,,,,0,,,,-0.0049,,,,,,50.0002937,,,,
,32372448.84,49.9987144,-56823.53515625,0.000152762121178336,1.22202658688708E-6,1,0.999253354069792,40.0298881530762,1.99577304186867,21.1999993771315,0.00172520715998067,0.000329655453430466,0.25,1.67767672310789E-6,0.000153108008406524,2.74280314465813E-6,49.9987144,49.9987144,-56830.80859375,-56816.26171875,57.2167708647368,20.5211450215785,18.732843,0,0,0,40,4449,50.01005,-56823.53515625,,,,,,,,,,,,,0,,,,0,,,,,,49.9987144,,,,
,32372545.21,49.9995842,-52006.287109375,0.000137531118676704,9.8611815883808E-7,1,0.999253354069792,40.0298881530762,1.99573156990479,21.1999993771315,0.00154993736053252,0.000312728472040578,0.25,2.91441794284309E-6,0.000137801555927557,3.88730488282267E-6,49.9995842,49.9995842,-52013.58203125,-51998.9921875,57.6122748954676,20.5234507296986,18.732843,0,0,0,40,4449,50.0057,-52006.287109375,,,,,,,,,,,,,0,,,,-0.0049,,,,,,49.9995842,,,,
,32372641.36,49.9998856,-47204.330078125,0.000119016576634294,1.06096923127979E-6,1,0.999253354069792,40.0298881530762,1.99573798544616,21.1999993771315,0.00134045247036516,0.000273479197500302,0.25,2.77033091651188E-6,0.000119221095453516,3.62120681026887E-6,49.9998856,49.9998856,-47206.82421875,-47201.8359375,57.5567792706022,20.5250262379267,18.732843,0,0,0,40,4449,50.0107,-47204.330078125,,,,,,,,,,,,,0,,,,-0.0049,,,,,,49.9998856,,,,
,32372736.335,50.0003548,-42456.6171875,0.000101754338861724,9.55562484539743E-7,1,0.999253354069792,40.0298881530762,1.99586848606276,21.1999993771315,0.00114721484270817,0.000226068932879205,0.25,1.68000434956539E-6,0.000101909591900146,2.41291156816185E-6,50.0003548,50.0003548,-42459.08984375,-42454.14453125,57.4051433378714,20.5203624448281,18.353191,0,0,0,40,4449,50.00325,-42456.6171875,,,,,,,,,,,,,0,,,,0,,,,,,50.0003548,,,,
,32372829.17,49.9999962,-37814.3203125,8.58279642881438E-5,8.3863648330271E-7,1,0.999253354069792,40.0298881530762,1.99581158643305,21.1999993771315,0.000967238473179139,0.00019152265315772,0.25,1.49022424550283E-6,8.5937872867219E-5,2.11343826044895E-6,49.9999962,49.9999962,-37816.86328125,-37811.77734375,57.5544343850446,20.5210944257742,18.732843,0,0,0,40,4449,50.0126,-37814.3203125,,,,,,,,,,,,,0,,,,-0.00245,,,,,,49.9999962,,,,
,32372922.885,49.9994736,-33134.822265625,6.88710338681306E-5,8.00003701751737E-7,1,0.999253354069792,40.0298881530762,1.99576816969799,21.1999993771315,0.000776799958508635,0.000148823617174983,0.25,7.65515831369646E-7,6.89451017726535E-5,1.26861650136365E-6,49.9994736,49.9994736,-33144.8046875,-33124.83984375,57.3910740245253,20.5199805253091,18.353191,0,0,0,40,4449,50.00655,-33134.822265625,,,,,,,,,,,,,0,,,,-0.0049,,,,,,49.9994736,,,,
,32373018.34,49.9992027,-28362.517578125,5.28522127696404E-5,6.97245113091052E-7,1,0.999253354069792,40.0298881530762,1.99582590379732,21.1999993771315,0.000595420757028779,0.000117319138316765,0.25,8.62469124043641E-7,5.28933939672951E-5,1.25117170012309E-6,49.9992027,49.9992027,-28367.697265625,-28357.337890625,57.2878990599868,20.5184631114868,18.353191,0,0,0,40,4449,50.011,-28362.517578125,,,,,,,,,,,,,0,,,,0.0049,,,,,,49.9992027,,,,
,32373114.71,49.9993744,-23545.0517578125,3.58072878698434E-5,7.35253291727371E-7,1,0.999253354069792,40.0298881530762,1.99580686239477,21.1999993771315,0.000403085968419798,8.05707900363908E-5,0.25,6.8102553717588E-7,3.58249483142057E-5,9.45690294345709E-7,49.9993744,49.9993744,-23555.076171875,-23535.02734375,57.2699216040445,20.5192285977306,17.973541,0,0,0,40,4449,50.0086,-23545.0517578125,,,,,,,,,,,,,0,,,,-0.00245,,,,,,49.9993744,,,,
,32373209.74,50.0001907,-18795.2841796875,2.03237280244692E-5,5.06432234624098E-7,1,0.999253354069792,40.0298881530762,1.99579908599421,21.1999993771315,0.000228582184938034,4.65125038946997E-5,0.25,4.56194990186086E-7,2.03278976512006E-5,6.06938093614493E-7,50.0001907,50.0001907,-18802.74609375,-18787.822265625,57.3652802833907,20.5170210341988,19.112494,0,0,0,40,4449,50.0092,-18795.2841796875,,,,,,,,,,,,,0,,,,0,,,,,,50.0001907,,,,
,32373304.555,49.9995308,-14055.2915039062,4.34850174204204E-6,5.08738022417982E-7,1,0.999253354069792,40.0298881530762,1.99580061091246,21.1999993771315,4.9152863936739E-5,8.51955968861872E-6,0.25,-2.91287985005441E-8,4.34920308522421E-6,3.17176694406383E-9,49.9995308,49.9995308,-14065.4287109375,-14045.154296875,57.2871174314676,20.5189541072355,19.112494,0,0,0,40,4449,50.00725,-14055.2915039062,,,,,,,,,,,,,0,,,,0,,,,,,49.9995308,,,,
,32373398.005,49.99963,-9387.6044921875,-1.09716037673E-5,3.98569077610809E-7,1,0.999253354069792,40.0298881530762,1.99561992821869,21.1999993771315,-0.000124865777654632,-1.65465474460191E-5,0.25,5.11498731601438E-7,-1.09739137859874E-5,4.29808522745184E-7,49.99963,49.99963,-9397.4873046875,-9377.7216796875,57.2574155477368,20.5183046070814,18.732843,0,0,0,40,4449,50.00785,-9387.6044921875,,,,,,,,,,,,,0,,,,-0.0049,,,,,,49.99963,,,,
,32373491.705,49.9995575,-4704.20361328125,-2.53359886724238E-5,3.746197241799E-7,1,0.999253354069792,40.0298881530762,1.99567946493928,21.1999993771315,-0.000285782224317204,-5.20897731247178E-5,0.25,-4.9506103550086E-8,-2.53262886769017E-5,-2.38028604933042E-7,49.9995575,49.9995575,-4714.19482421875,-4694.21240234375,57.4192126512176,20.5182240162983,18.732843,0,0,0,40,4449,50.00785,-4704.20361328125,,,,,,,,,,,,,0,,,,-0.00245,,,,,,49.9995575,,,,
,32373585.105,50.000164,-32.5857563018799,-3.9311669748895E-5,3.63684168239644E-7,1,0.999253354069792,40.0298881530762,1.99575753056793,21.1999993771315,-0.000442052525229836,-8.80543803098409E-5,0.25,-7.18895988677094E-7,-3.92845682974058E-5,-1.01091088137611E-6,50.000164,50.000164,-39.8190765380859,-25.3524360656738,57.3684067974676,20.5178365554888,19.112494,0,0,0,40,4449,50.0055,-32.5857563018799,,,,,,,,,,,,,0,,,,0.00245,,,,,,50.000164,,,,
,32373679.19,50.0003281,4666.55590820313,-5.08556937998574E-5,4.34340693782543E-7,1,0.999253354069792,40.0298881530762,1.9958308633487,21.1999993771315,-0.000572904143739772,-0.000108855536454088,0.25,-4.79612880156482E-7,-5.0833334095759E-5,-8.57883958747749E-7,50.0003014,50.0003548,4659.0341796875,4674.07763671875,57.413741251583,20.5169884105809,18.732843,0,0,0,40,4449,50.0097,4666.55590820313,,,,,,,,,,,,,0,,,,-0.0049,,,,,,50.0003281,,,,
,32373771.255,50.0006943,9270.35498046875,-6.01562381544478E-5,4.21721993673028E-7,1,0.999253354069792,40.0298881530762,1.99584415610054,21.1999993771315,-0.000678293522713227,-0.000126255503173132,0.25,-3.42721042234864E-7,-6.01451534508393E-5,-7.90198271040778E-7,50.0006943,50.0006943,9262.75,9277.9599609375,57.1769078102561,20.515420560627,18.353191,0,0,0,40,4449,50.0094,9270.35498046875,,,,,,,,,,,,,0,,,,-0.00245,,,,,,50.0006943,,,,
,32373866.52,50.0005493,14030.2485351562,-6.4343009360607E-5,4.98506552144943E-7,1,0.999253354069792,40.0298881530762,1.99570743109511,21.1999993771315,-0.000724462966490637,-0.000141585834792546,0.25,-9.44727351413452E-7,-6.4343141731301E-5,-1.42282015929713E-6,50.0005493,50.0005493,14025.2080078125,14035.2890625,57.2073913225061,20.5153600958854,18.353191,0,0,0,40,4449,50.0106,14030.2485351562,,,,,,,,,,,,,0,,,,0.00245,,,,,,50.0005493,,,,
,32373960.485,50.0017128,18725.29296875,-6.18908575689387E-5,5.88792506841441E-7,1,0.999253354069792,40.0298881530762,1.99572075348364,21.1999993771315,-0.00069730910426575,-0.000134713874750886,0.25,-7.76170389401788E-7,-6.19078717182783E-5,-1.23501156028554E-6,50.0017128,50.0017128,18722.958984375,18727.626953125,57.2120810936214,20.5163040956542,18.732843,0,0,0,40,4449,50.01005,18725.29296875,,,,,,,,,,,,,0,,,,0.0049,,,,,,50.0017128,,,,
,32374052.975,50.0018616,23348.396484375,-5.83801814525261E-5,7.11629098361681E-7,1,0.999253354069792,40.0298881530762,1.99571379320334,21.1999993771315,-0.00065734184068402,-0.000130318531510822,0.25,-1.0184673237791E-6,-5.84090433138284E-5,-1.44998639962807E-6,50.0018616,50.0018616,23335.763671875,23361.029296875,57.474708276083,20.5145298540428,18.353191,0,0,0,40,4449,50.01035,23348.396484375,,,,,,,,,,,,,0,,,,-0.00245,,,,,,50.0018616,,,,
,32374149.94,50.0000267,28195.7744140625,-6.34950407291347E-5,7.25640701726083E-7,1,0.999253354069792,40.0298881530762,1.99592168508942,21.1999993771315,-0.000715808376985429,-0.000138385030653265,0.25,-8.09148143084155E-7,-6.35455930430376E-5,-1.2760096239521E-6,50.0000267,50.0000267,28188.216796875,28203.33203125,57.1714364106214,20.5161735205696,19.112494,0,0,0,40,4449,50.01055,28195.7744140625,,,,,,,,,,,,,0,,,,0.0049,,,,,,50.0000267,,,,
,32374246.475,50.000885,33021.09375,-7.28317317253244E-5,1.0345228727341E-6,1,0.999253354069792,40.0298881530762,1.99576300362024,21.1999993771315,-0.000818549169518931,-0.000173579794692365,0.25,-2.2427726687016E-6,-7.28992083425831E-5,-2.77653188564112E-6,50.000885,50.000885,33016.18359375,33026.00390625,57.6544828355061,20.5164988057161,19.112494,0,0,0,40,4449,50.0094,33021.09375,,,,,,,,,,,,,0,,,,0,,,,,,50.000885,,,,
,32374341.815,50.003334,37786.037109375,-8.84553098545425E-5,8.77183090706123E-7,1,0.999253354069792,40.0298881530762,1.9958094341012,21.1999993771315,-0.000997240622126184,-0.000195174753859876,0.25,-1.34028771887779E-6,-8.85696833772196E-5,-1.98237395195404E-6,50.003334,50.003334,37773.55078125,37798.5234375,57.1933220091599,20.5151979514071,18.732843,0,0,0,40,4449,50.00345,37786.037109375,,,,,,,,,,,,,0,,,,0.00245,,,,,,50.003334,,,,
,32374437.29,50.0009384,42558.515625,-0.000103869472676675,1.16200209899034E-6,1,0.999253354069792,40.0298881530762,1.99579371210939,21.1999993771315,-0.00117027151333582,-0.000234953924772252,0.25,-2.08587652995835E-6,-0.00010402585335848,-2.83448549545842E-6,50.0009346,50.0009422,42550.9453125,42566.0859375,57.4113963660253,20.5116087095936,18.353191,0,0,0,40,4449,50.0042,42558.515625,,,,,,,,,,,,,0,,,,0,,,,,,50.0009384,,,,
,32374532.865,50.0013847,47334.029296875,-0.000120325808353586,1.09697541414253E-6,1,0.999253354069792,40.0298881530762,1.99578367419379,21.1999993771315,-0.00135679494817971,-0.000267822385635337,0.25,-2.03421935673863E-6,-0.000120538666346886,-2.8928220865858E-6,50.0013847,50.0013847,47323.90234375,47344.15625,57.2964969736984,20.5156336243494,18.353191,0,0,0,40,4449,50.00525,47334.029296875,,,,,,,,,,,,,0,,,,0.00245,,,,,,50.0013847,,,,
,32374629.795,50.0004997,52179.412109375,-0.000137837507417128,1.17175780536057E-6,1,0.999253354069792,40.0298881530762,1.99576802752537,21.1999993771315,-0.00155541551365408,-0.000302384170452318,0.25,-1.94463758623103E-6,-0.000138116433281314,-2.91728588299014E-6,50.0004997,50.0004997,52167.09765625,52191.7265625,57.0463758475445,20.5155952548714,18.732843,0,0,0,40,4449,50.0012,52179.412109375,,,,,,,,,,,,,0,,,,-0.00245,,,,,,50.0004997,,,,
,32374724.405,50.0004082,56908.9375,-0.000153562832735915,1.19884084044709E-6,1,0.999253354069792,40.0298881530762,1.99571207990658,21.1999993771315,-0.00172895840647695,-0.000360562400358288,0.25,-4.26609643159691E-6,-0.000153893033946637,-5.34269376316178E-6,50.0004082,50.0004082,56903.98828125,56913.88671875,56.9869720800829,20.5114879240163,18.732843,0,0,0,40,4449,50.0032,56908.9375,,,,,,,,,,,,,0,,,,0.00245,,,,,,50.0004082,,,,
,32374819.445,50.00094225,61656.640625,-0.000169800575570024,1.08178371456914E-6,1,0.999253354069792,40.0298881530762,1.99565915010437,21.1999993771315,-0.00191251253829803,-0.000396677716453997,0.25,-4.54762865150907E-6,-0.000170203250100157,-5.7241502963538E-6,50.0008316,50.0010529,61651.671875,61661.609375,56.8869236296214,20.5123195400148,19.112494,0,0,0,40,4449,50.0018,61656.640625,,,,,,,,,,,,,0,,,,-0.0049,,,,,,50.00094225,,,,
,32374915.435,50.0005493,66455.04296875,-0.000188284977483427,1.32444723508059E-6,1,0.999253354069792,40.0298881530762,1.99575869494863,21.1999993771315,-0.00212167279892814,-0.000437601660967316,0.25,-4.85050615652945E-6,-0.000188771940276604,-6.13865392235341E-6,50.0005493,50.0005493,66450.2265625,66459.859375,57.4176493941791,20.5109726478654,18.353191,0,0,0,40,4449,50.00245,66455.04296875,,,,,,,,,,,,,0,,,,-0.0049,,,,,,50.0005493,,,,
,32375010.845,50.0011902,71225.734375,-0.000206524697050668,1.27480834773284E-6,1,0.999253354069792,40.0298881530762,1.99578640354346,21.1999993771315,-0.00232977914245412,-0.000468477349636264,0.25,-4.31383662731692E-6,-0.000207106456765518,-5.70568431867033E-6,50.0011902,50.0011902,71213.3828125,71238.0859375,57.1862873524868,20.5138996961927,18.732843,0,0,0,40,4449,50.0056,71225.734375,,,,,,,,,,,,,0,,,,-0.00245,,,,,,50.0011902,,,,
,32375106.375,49.9998779,75998.93359375,-0.000221616430837307,1.36043464389025E-6,1,0.999253354069792,40.0298881530762,1.99587642156965,21.1999993771315,-0.00249861804821244,-0.000513886456511453,0.25,-5.62675360512648E-6,-0.000222275769306788,-7.10332150613608E-6,49.9998779,49.9998779,75996.3671875,76001.5,57.2253687784484,20.5118805099698,18.732843,0,0,0,40,4449,50.0013,75998.93359375,,,,,,,,,,,,,0,,,,0,,,,,,49.9998779,,,,
,32375201.835,50.0017014,80772.2265625,-0.000240083882680113,1.43852986583137E-6,1,0.999253354069792,40.0298881530762,1.99576141673476,21.1999993771315,-0.00270388874813203,-0.000575059296074984,0.25,-7.73296388267258E-6,-0.000240830821373214,-9.31584079039943E-6,50.0017014,50.0017014,80764.9140625,80779.5390625,57.1143775287176,20.5119628827855,18.353191,0,0,0,40,4449,50.0018,80772.2265625,,,,,,,,,,,,,0,,,,-0.00245,,,,,,50.0017014,,,,
,32375296.585,50.0014324,85507.88671875,-0.000256279082705948,1.52790069759134E-6,1,0.999253354069792,40.0298881530762,1.99591202561967,21.1999993771315,-0.00289011567419174,-0.000596504234744691,0.25,-6.73570882132888E-6,-0.000257129939577632,-8.39650459383418E-6,50.0014267,50.0014381,85498.0234375,85517.75,57.3441763133715,20.5132939507876,18.353191,0,0,0,40,4449,50.00105,85507.88671875,,,,,,,,,,,,,0,,,,0.00245,,,,,,50.0014324,,,,
,32375388.505,50.0013275,89999.7421875,-0.000270689977634863,1.52218110651425E-6,1,0.999253354069792,40.0298881530762,1.99583705037675,21.1999993771315,-0.00304958135779809,-0.000649146105362644,0.25,-8.81877669750142E-6,-0.000271619638293992,-1.05550658484068E-5,50.0013275,50.0013275,89999.734375,89999.75,57.1206305568714,20.5095136464391,18.732843,0,0,0,40,4417,49.99845,89999.7421875,,,,,,,,,,,,,0,,,,-0.0049,,,,,,50.0013275,,,,
,32375496.565,49.9988594,85541.77734375,-0.00025485777393978,1.57785617135114E-6,1,0.999253354069792,40.0298881530762,1.99585589766088,21.1999993771315,-0.0028728040060713,-0.000599928723745492,0.25,-7.29406778428934E-6,-0.000255700349976954,-8.94759863896771E-6,49.9988594,49.9988594,85534.2421875,85549.3125,57.126101956506,20.5118780531293,19.112494,0,0,0,40,4449,49.9987,85541.77734375,,,,,,,,,,,,,0,,,,0.00245,,,,,,49.9988594,,,,
,32375591.09,50.0006676,80818.1015625,-0.000241403857269417,1.60946065190478E-6,1,0.999253354069792,40.0298881530762,1.99580476556928,21.1999993771315,-0.00271701769435581,-0.000588262243376704,0.25,-8.66096885398698E-6,-0.000242149532959813,-1.02552968442665E-5,50.0006676,50.0006676,80805.53125,80830.671875,57.1690915250637,20.5141464202818,19.112494,0,0,0,40,4449,50.00045,80818.1015625,,,,,,,,,,,,,0,,,,-0.00245,,,,,,50.0006676,,,,
,32375688.15,49.9995956,75966.96484375,-0.000222727346352658,1.12700314990991E-6,1,0.999253354069792,40.0298881530762,1.99572899904876,21.1999993771315,-0.00251007929518272,-0.000521353534122754,0.25,-6.0899623385966E-6,-0.000223386864495226,-7.57542821738003E-6,49.9995956,49.9995956,75956.9921875,75976.9375,57.4481329064291,20.5119365307578,18.732843,0,0,0,40,4449,50.00175,75966.96484375,,,,,,,,,,,,,0,,,,-0.00245,,,,,,49.9995956,,,,
,32375784.505,49.9986801,71150.84375,-0.000206647786876088,1.23422355499207E-6,1,0.999253354069792,40.0298881530762,1.99593674178704,21.1999993771315,-0.00232535936598924,-0.000502046263113819,0.25,-7.25294161444579E-6,-0.000207209555993403,-8.65462995710589E-6,49.9986801,49.9986801,71143.4140625,71158.2734375,57.1042163579676,20.5160885105049,18.353191,0,0,0,40,4449,50.002,71150.84375,,,,,,,,,,,,,0,,,,-0.00245,,,,,,49.9986801,,,,
,32375879.22,49.9984322,66415.39453125,-0.00018980612464632,1.4423266962793E-6,1,0.999253354069792,40.0298881530762,1.99581617079555,21.1999993771315,-0.00213796401069586,-0.000446191000215906,0.25,-5.33497055007221E-6,-0.000190293723496372,-6.6348762898948E-6,49.9984322,49.9984322,66405.53125,66425.2578125,57.1401712698522,20.5144550790568,18.353191,0,0,0,40,4449,50.00355,66415.39453125,,,,,,,,,,,,,0,,,,0.0049,,,,,,49.9984322,,,,
,32375975.32,49.998642,61611.83203125,-0.000170048552737298,1.25311269593484E-6,1,0.999253354069792,40.0298881530762,1.99578369027326,21.1999993771315,-0.0019149546223591,-0.000399850374007044,0.25,-4.78124056465958E-6,-0.000170449961989966,-5.96017695487894E-6,49.998642,49.998642,61606.4921875,61617.171875,57.1784710672945,20.5164062877649,19.112494,0,0,0,40,4449,50.00315,61611.83203125,,,,,,,,,,,,,0,,,,0.0049,,,,,,49.998642,,,,
,32376071.435,49.9985924,56806.384765625,-0.000155395809898316,1.43974114825844E-6,1,0.999253354069792,40.0298881530762,1.99573852024286,21.1999993771315,-0.00174834455322234,-0.000371913493412926,0.25,-4.93928800302479E-6,-0.000155724969544208,-6.03042541089299E-6,49.9984322,49.9987526,56799.1171875,56813.65234375,57.4168677656599,20.5166613485575,18.732843,0,0,0,40,4449,50.0059,56806.384765625,,,,,,,,,,,,,0,,,,0.00245,,,,,,49.9985924,,,,
,32376168.175,49.9989548,51973.990234375,-0.000138020806450777,1.19854173163312E-6,1,0.999253354069792,40.0298881530762,1.99569523805517,21.1999993771315,-0.00155440862886237,-0.000319496727593675,0.25,-3.42510698827298E-6,-0.000138288466979731,-4.40258791450236E-6,49.9989548,49.9989548,51971.49609375,51976.484375,57.2980602307368,20.5167390059053,18.732843,0,0,0,40,4449,50.0053,51973.990234375,,,,,,,,,,,,,0,,,,0,,,,,,49.9989548,,,,
,32376263.52,49.9987717,47208.779296875,-0.000120105698632818,8.80859680451232E-7,1,0.999253354069792,40.0298881530762,1.9954576184236,21.1999993771315,-0.00135507775909322,-0.000261809420504552,0.25,-1.54568406496785E-6,-0.000120320745627344,-2.40205893183184E-6,49.9987717,49.9987717,47198.25,47219.30859375,57.1729996676599,20.5215545436112,18.732843,0,0,0,40,4449,49.99995,47208.779296875,,,,,,,,,,,,,0,,,,-0.00245,,,,,,49.9987717,,,,
,32376360.155,50.0001049,42375.900390625,-0.000101982501758435,1.14722589868107E-6,1,0.999253354069792,40.0298881530762,1.99583292738025,21.1999993771315,-0.00114921545317435,-0.000229612539790321,0.25,-1.95262625398176E-6,-0.000102135740381349,-2.68772911148845E-6,49.9999161,50.0002937,42370.63671875,42381.1640625,57.4051433378714,20.5173225023517,18.353191,0,0,0,40,4449,50.0027,42375.900390625,,,,,,,,,,,,,0,,,,0,,,,,,50.0001049,,,,
,32376455.22,49.99983595,37626.203125,-8.48490258769712E-5,7.15959372163077E-7,1,0.999253354069792,40.0298881530762,1.9958460157269,21.1999993771315,-0.000954490501808538,-0.000198899054079031,0.25,-2.31863491079243E-6,-8.49506257818733E-5,-2.93612646093821E-6,49.9997673,49.9999046,37618.75,37633.65625,57.271484861083,20.5184827160501,18.353191,0,0,0,40,4449,50.0076,37626.203125,,,,,,,,,,,,,0,,,,0.0049,,,,,,49.99983595,,,,
,32376550.22,49.998806,32876.330078125,-6.8922297916999E-5,9.33574519299257E-7,1,0.999253354069792,40.0298881530762,1.99585125699854,21.1999993771315,-0.000776513793745656,-0.000153851997754015,0.25,-1.20065525271275E-6,-6.89923296464194E-5,-1.70480334856654E-6,49.998806,49.998806,32871.25,32881.41015625,57.0026046504676,20.5193143306164,19.112494,0,0,0,40,4449,50.00885,32876.330078125,,,,,,,,,,,,,0,,,,-0.00245,,,,,,49.998806,,,,
,32376646.25,49.9993992,28078.6513671875,-5.19400029843062E-5,7.04932242299318E-7,1,0.999253354069792,40.0298881530762,1.99584308217439,21.1999993771315,-0.000586526914195968,-0.000107588292913559,0.25,-1.6550884284108E-7,-5.19846023713559E-5,-5.4703216185513E-7,49.9991188,49.9996796,28073.564453125,28083.73828125,57.6755868055253,20.5186384705797,19.112494,0,0,0,40,4449,50.00555,28078.6513671875,,,,,,,,,,,,,0,,,,-0.00245,,,,,,49.9993992,,,,
,32376741.91,49.99946975,23296.0341796875,-3.52327417625468E-5,5.8980194651293E-7,1,0.999253354069792,40.0298881530762,1.99590950301268,21.1999993771315,-0.000396813525273198,-7.82736111659897E-5,0.25,-5.80872036780157E-7,-3.5250273705987E-5,-8.41290290487576E-7,49.9992828,49.9996567,23290.69140625,23301.376953125,57.2769562607176,20.5153854428419,18.732843,0,0,0,40,4449,50.00665,23296.0341796875,,,,,,,,,,,,,0,,,,0,,,,,,49.99946975,,,,
,32376837.945,49.9995766,18496.3447265625,-1.84460658776062E-5,5.7959013146212E-7,1,0.999253354069792,40.0298881530762,1.99578445286426,21.1999993771315,-0.00020553442347229,-5.28941254558943E-5,0.25,-1.35976295028261E-6,-1.84425332608825E-5,-1.49693659434577E-6,49.9994965,49.9996567,18488.732421875,18503.95703125,57.4622022197753,20.5157421894259,18.732843,0,0,0,40,4449,50.0083,18496.3447265625,,,,,,,,,,,,,0,,,,0,,,,,,49.9995766,,,,
,32376932.07,50.0001907,13794.08203125,-2.93676867211007E-6,4.82693694866215E-7,1,0.999253354069792,40.0298881530762,1.99583542885528,21.1999993771315,-3.24119503510952E-5,-1.01015711982956E-5,0.25,-3.65438153938337E-7,-2.9343423825551E-6,-3.8729278229905E-7,50.0001907,50.0001907,13786.66015625,13801.50390625,56.9658681100637,20.5171531221602,19.112494,0,0,0,40,4449,50.01045,13794.08203125,,,,,,,,,,,,,0,,,,-0.00245,,,,,,50.0001907,,,,
,32377025.555,49.9997482,9121.29150390625,1.25373916981556E-5,4.35050998735544E-7,1,0.999253354069792,40.0298881530762,1.99594394203723,21.1999993771315,0.000142236575111601,2.15139616455356E-5,0.25,-3.53863408739343E-7,1.25381393269669E-5,-2.60537028537613E-7,49.9997482,49.9997482,9113.9296875,9128.6533203125,57.70138054666,20.5160550110546,18.732843,0,0,0,40,4449,50.00685,9121.29150390625,,,,,,,,,,,,,0,,,,0.00245,,,,,,49.9997482,,,,
,32377119.465,49.9996605,4425.55615234375,2.68449739015751E-5,3.53872800459311E-7,1,0.999253354069792,40.0298881530762,1.99589388651703,21.1999993771315,0.000303638825998978,5.07111756457524E-5,0.25,-3.45071533124902E-7,2.68373044186323E-5,-1.45172106963948E-7,49.9996605,49.9996605,4420.373046875,4430.7392578125,57.5739750980253,20.5169800311593,18.732843,0,0,0,40,4449,50.00745,4425.55615234375,,,,,,,,,,,,,0,,,,-0.00245,,,,,,49.9996605,,,,
,32377209.54,49.999527,-0.433877542614937,3.95693285014481E-5,3.00681221057118E-7,1,0.999253354069792,40.0298881530762,1.99587163610696,21.1999993771315,0.000446571378871701,7.97738551965827E-5,0.25,-6.18877784660623E-8,3.95478729644885E-5,2.32475169098202E-7,49.9991837,49.9998703,-0.441489428281784,-0.42626565694809,57.0870205305445,20.5214924059713,18.732843,0,0,0,40,4417,50.00545,-0.433877542614937,,,,,,,,,,,,,0,,,,0.00245,,,,,,49.999527,,,,