File: data/monolayers/magneticStructure/ML_Ac_CoFe_C/PPMS/data/DD205_4_KOELNPPMS_HYST_100OE_20K.DAT
[Header]
; VSM Data File (default extension .dat)
; Copyright (c) 2003-2013, Quantum Design, Inc. All rights reserved.
TITLE,
FILEOPENTIME,19698361.53,08/16/2018,11:44 pm
BYAPP,VSM,2.0,2.0
INFO,PPMS VSM Option Release 1.4.10 Build 1,APPNAME
INFO,Quantum Design Linear Motor Servo Controller,MOTOR_MODULE_NAME
INFO,3101-100 M1,MOTOR_HW_VERSION
INFO,MMC1014,MOTOR_SERIAL_NUMBER
INFO,SRV No X-over 01.03.11,MOTOR_SOFTWARE_VERSION
INFO,Quantum Design VSM Detection Module,VSM_MODULE_NAME
INFO,3101-150 F0,VSM_HW_VERSION
INFO,VSM707,VSM_SERIAL_NUMBER
INFO,VSM No X-over 01.02.05 May 20 2008 13:51:47,VSM_SOFTWARE_VERSION
INFO,704,PREAMP_SERIAL_NUMBER
INFO,822,COIL_SERIAL_NUMBER
INFO,0,MOMENT_UNITS
INFO,,SAMPLE_MATERIAL
INFO,,SAMPLE_COMMENT
INFO,,SAMPLE_MASS
INFO,,SAMPLE_VOLUME
INFO,,SAMPLE_MOLECULAR_WEIGHT
INFO,,SAMPLE_SIZE
INFO,,SAMPLE_SHAPE
DATATYPE,COMMENT,1
DATATYPE,TIME,2
STARTUPAXIS,X,2
STARTUPAXIS,Y1,5
[Data]
Comment,Time Stamp (sec),Temperature (K),Magnetic Field (Oe),Moment (emu),M. Std. Err. (emu),Transport Action,Averaging Time (sec),Frequency (Hz),Peak Amplitude (mm),Center Position (mm),Coil Signal' (mV),Coil Signal" (mV),Range (mV),M. Quad. Signal (emu),M. Raw' (emu),M. Raw" (emu),Min. Temperature (K),Max. Temperature (K),Min. Field (Oe),Max. Field (Oe),Mass (grams),Motor Lag (deg),Pressure (Torr),VSM Status (code),Motor Status (code),Measure Status (code),Measure Count,PPMS Status (code),System Temp. (K),System Field (Oe),Sample Position (deg),Bridge 1 Resistance (ohms),Bridge 1 Excitation (에),Bridge 2 Resistance (ohms),Bridge 2 Excitation (에),Bridge 3 Resistance (ohms),Bridge 3 Excitation (에),Bridge 4 Resistance (ohms),Bridge 4 Excitation (에),Signal 1 Vin (V),Signal 2 Vin (V),Digital Inputs (code),Drive 1 Iout (mA),Drive 1 Ipower (W),Drive 2 Iout (mA),Drive 2 Ipower (W),Pressure (),Map 20 (),Map 21 (),Map 22 (),Map 23 (),Map 24 (),Map 25 (),Map 26 (),Map 27 (),Map 28 (),Map 29 ()
,19698553.44,20.0726,0,3.62268411434205E-5,3.11834739059153E-7,1,0.999253354069792,40.0298881530762,1.98183533185934,14.2500000074506,0.00040618311757729,5.97890118464251E-5,0.25,-1.07339878447594E-6,3.60237679523863E-5,-8.91617901394104E-7,20.0726,20.0726,-0.0304475463926792,0.0304475463926792,53.6314408470249,19.5645978798752,14.556682,0,0,0,40,4417,20.0726,0,,,,,,,,,,,,,0,,,,,,,,,,,,,,
,19698646.375,20.06695,3645.572265625,3.15620229785856E-5,3.06902981076849E-7,1,0.999253354069792,40.0298881530762,1.98189647732843,14.2400003969669,0.000352037693548885,6.29138215866766E-5,0.25,2.7330098941005E-8,3.13863731789863E-5,1.86841864392816E-7,20.067,20.067,3643.23413085937,3647.91040039063,53.841698918698,19.5660727074651,13.797379,0,0,0,40,4449,20.06695,3645.572265625,,,,,,,,,,,,,0,,,,,,,,,,,,,,
,19698727.21,20.0718,7682.41552734375,1.93520742536109E-5,2.79283716081896E-7,1,0.999253354069792,40.0298881530762,1.98189756543009,14.2400003969669,0.000216403597900971,3.58225268958749E-5,0.25,-2.3649369659784E-7,1.92511668944743E-5,-1.31783164351209E-7,20.0718,20.0718,7677.26611328125,7687.56494140625,53.8917231439288,19.5667271910295,13.797379,0,0,0,40,4449,20.0718,7682.41552734375,,,,,,,,,,,,,0,,,,,,,,,,,,,,
,19698806.23,20.0756,11633.1435546875,6.8195214934253E-6,3.27432671374645E-7,1,0.999253354069792,40.0298881530762,1.98187811999029,14.2400003969669,7.59509798157834E-5,1.4487867888237E-5,0.25,8.13702769198803E-8,6.78521584767604E-6,1.19398410618831E-7,20.0756,20.0756,11630.5234375,11635.763671875,53.983955309198,19.5638693258106,13.797379,0,0,0,40,4449,20.0756,11633.1435546875,,,,,,,,,,,,,0,,,,,,,,,,,,,,
,19698885.365,20.0698,15588.5991210938,-5.19413783176352E-6,3.33417762315987E-7,1,0.999253354069792,40.0298881530762,1.98188437917664,14.2400003969669,-5.80719597313936E-5,-9.9023086368476E-6,0.25,4.12679829289776E-8,-5.17040677099831E-6,1.03407842194769E-8,20.0698,20.0698,15583.6162109375,15593.58203125,54.0285081347942,19.5655002614657,13.797379,0,0,0,40,4449,20.0698,15588.5991210938,,,,,,,,,,,,,0,,,,,,,,,,,,,,
,19698959.505,20.07005,19293.8427734375,-1.65181033439276E-5,3.72118379007522E-7,1,0.999253354069792,40.0298881530762,1.98191836524169,14.2400003969669,-0.000185415097701569,-2.77599380958261E-5,0.25,4.70451212402571E-7,-1.64505027912302E-5,3.66570056164838E-7,20.0701,20.0701,19281.421875,19306.263671875,53.8237214627557,19.5665975903028,14.177031,0,0,0,40,4449,20.07005,19293.8427734375,,,,,,,,,,,,,0,,,,,,,,,,,,,,
,19699034.63,20.0701,23046.94140625,-2.74434681638332E-5,3.79990814808793E-7,1,0.999253354069792,40.0298881530762,1.98193741170451,14.2400003969669,-0.000306389551620292,-5.60823116015563E-5,0.25,-1.02052301774816E-7,-2.733581308717E-5,-2.77329465815262E-7,20.0702,20.0702,23039.451171875,23054.431640625,53.8690559168711,19.5632071628103,14.556682,0,0,0,40,4449,20.0701,23046.94140625,,,,,,,,,,,,,0,,,,,,,,,,,,,,
,19699105.515,20.0693,26589.6865234375,-3.88876241916096E-5,5.34167243092647E-7,1,0.999253354069792,40.0298881530762,1.98190423311695,14.2500000074506,-0.000434614535933458,-7.77818965343947E-5,0.25,1.65641704575565E-8,-3.87501220838746E-5,-2.4022462593124E-7,20.0693,20.0693,26587.13671875,26592.236328125,54.0691528177942,19.5653657622744,13.797379,0,0,0,40,4449,20.0693,26589.6865234375,,,,,,,,,,,,,0,,,,,,,,,,,,,,
,19699178.965,20.067,30260.884765625,-5.00065277574362E-5,4.76823604304113E-7,1,0.999253354069792,40.0298881530762,1.98187102721211,14.2400003969669,-0.000558922421185765,-0.00010097565088582,0.25,-5.15842628684436E-8,-4.98483096277437E-5,-3.90816311962739E-7,20.067,20.067,30255.748046875,30266.021484375,53.8964129150442,19.5651345408241,14.177031,0,0,0,40,4449,20.067,30260.884765625,,,,,,,,,,,,,0,,,,,,,,,,,,,,
,19699253.26,20.06585,33973.7734375,-6.23021301751258E-5,5.59023490295607E-7,1,0.999253354069792,40.0298881530762,1.98189797555967,14.2400003969669,-0.000696651438590407,-0.000125753584051992,0.25,-4.52150129905297E-8,-6.21295075503603E-5,-4.78087649253663E-7,20.0658,20.0658,33968.8046875,33978.7421875,53.9339310839672,19.5643730503096,14.177031,0,0,0,40,4449,20.06585,33973.7734375,,,,,,,,,,,,,0,,,,,,,,,,,,,,
,19699326.075,20.0639,37614.576171875,-7.34505016288547E-5,3.97822575552948E-7,1,0.999253354069792,40.0298881530762,1.98187735607482,14.2500000074506,-0.000823686895087856,-0.000136826003441584,0.25,9.83194940009549E-7,-7.32826408794554E-5,4.60401807829671E-7,20.0639,20.0639,37612.15234375,37617,54.0691528177942,19.5643526463555,14.177031,0,0,0,40,4449,20.0639,37614.576171875,,,,,,,,,,,,,0,,,,,,,,,,,,,,
,19699398.24,20.062,41219.9765625,-8.46928224798134E-5,5.61447170366492E-7,1,0.999253354069792,40.0298881530762,1.98186756710107,14.2500000074506,-0.000947200282307197,-0.000174049953548149,0.25,-3.06581839612376E-7,-8.45212733551327E-5,-9.1551488223899E-7,20.0621,20.0621,41214.94140625,41225.01171875,53.7486851249095,19.5621874114229,14.556682,0,0,0,40,4449,20.062,41219.9765625,,,,,,,,,,,,,0,,,,,,,,,,,,,,
,19699469.725,20.0604,44793.68359375,-9.61908425244858E-5,3.92542527156774E-7,1,0.999253354069792,40.0298881530762,1.98182670224557,14.2400003969669,-0.0010774013443431,-0.000190944768052224,0.25,2.67884542152741E-7,-9.60364329664434E-5,-4.33353514200757E-7,20.0604,20.0604,44788.90234375,44798.46484375,53.7221097552557,19.5611167810487,14.556682,0,0,0,40,4449,20.0604,44793.68359375,,,,,,,,,,,,,0,,,,,,,,,,,,,,
,19699543.315,20.06005,48471.2890625,-0.000107308871947776,5.59238077809874E-7,1,0.999253354069792,40.0298881530762,1.98189203835609,14.2400003969669,-0.00120248356839834,-0.000212781607877353,0.25,3.34631710701569E-7,-0.000107177581566727,-4.5501022195393E-7,20.0601,20.0601,48466.3046875,48476.2734375,53.760409552698,19.5637665643375,14.556682,0,0,0,40,4449,20.06005,48471.2890625,,,,,,,,,,,,,0,,,,,,,,,,,,,,
,19699615.84,20.0597,52097.24609375,-0.000119230577521368,5.55358146216806E-7,1,0.999253354069792,40.0298881530762,1.98184528469384,14.2400003969669,-0.00133463206638174,-0.000247069914490314,0.25,-5.66052464525277E-7,-0.000119121445149852,-1.44815702684145E-6,20.0596,20.0596,52084.92578125,52109.56640625,54.4021265669865,19.5639049280432,14.177031,0,0,0,40,4449,20.0597,52097.24609375,,,,,,,,,,,,,0,,,,,,,,,,,,,,
,19699688.615,20.05885,55732.482421875,-0.000130242333188581,5.42198171743331E-7,1,0.999253354069792,40.0298881530762,1.98181238685888,14.2400003969669,-0.0014593324141615,-0.000264774601817994,0.25,-1.50336777548341E-7,-0.000130173227402318,-1.11815180954266E-6,20.0589,20.0589,55722.53515625,55742.4296875,53.7439953537942,19.56121811776,14.556682,0,0,0,40,4449,20.05885,55732.482421875,,,,,,,,,,,,,0,,,,,,,,,,,,,,
,19699761.12,20.05785,59358.7109375,-0.00014387025672245,5.26148564076834E-7,1,0.999253354069792,40.0298881530762,1.9817877098488,14.2500000074506,-0.00161428649208223,-0.000283057244325768,0.25,6.844203421015E-7,-0.000143850174071647,-3.86532666766368E-7,20.0578,20.0578,59351.19921875,59366.22265625,53.8753089450249,19.5614130975143,14.556682,0,0,0,40,4449,20.05785,59358.7109375,,,,,,,,,,,,,0,,,,,,,,,,,,,,
,19699837.095,20.05655,63154.560546875,-0.00015628516898936,5.58229983513691E-7,1,0.999253354069792,40.0298881530762,1.98178793449388,14.2400003969669,-0.00175282073693452,-0.000315261470281826,0.25,5.8361565878695E-8,-0.000156313152673914,-1.10411914376712E-6,20.0566,20.0566,63144.58984375,63164.53125,53.8049623782942,19.5617710620342,14.556682,0,0,0,40,4449,20.05655,63154.560546875,,,,,,,,,,,,,0,,,,,,,,,,,,,,
,19699911.195,20.054,66860.17578125,-0.00016778981865122,6.61640006352576E-7,1,0.999253354069792,40.0298881530762,1.98183897618118,14.2400003969669,-0.00188198295501308,-0.000341563506841022,0.25,-2.06192074891178E-7,-0.000167873297707058,-1.4510636682844E-6,20.0541,20.0541,66857.515625,66862.8359375,53.943310626198,19.5603140657929,14.936333,0,0,0,40,4449,20.054,66860.17578125,,,,,,,,,,,,,0,,,,,,,,,,,,,,
,19699985.94,20.0522,70595.8359375,-0.000179658082282775,6.83134936628304E-7,1,0.999253354069792,40.0298881530762,1.98179800018684,14.2400003969669,-0.00201492471864105,-0.000370165151003257,0.25,-6.13193105530468E-7,-0.000179802062955872,-1.94055464416208E-6,20.0523,20.0523,70585.8828125,70605.7890625,54.2246968931211,19.5630429090897,14.556682,0,0,0,40,4449,20.0522,70595.8359375,,,,,,,,,,,,,0,,,,,,,,,,,,,,
,19700059.515,20.0503,74274.11328125,-0.000192513562285031,5.99902114973303E-7,1,0.999253354069792,40.0298881530762,1.98178679195136,14.2400003969669,-0.00215877131171057,-0.000402161623088657,0.25,-1.14630707958309E-6,-0.000192722417457458,-2.56088662201202E-6,20.0504,20.0504,74269.15625,74279.0703125,54.1144872719096,19.5609781310194,14.556682,0,0,0,40,4449,20.0503,74274.11328125,,,,,,,,,,,,,0,,,,,,,,,,,,,,
,19700133.89,20.04905,77990.1640625,-0.000205192513403167,5.74651754801205E-7,1,0.999253354069792,40.0298881530762,1.98184485059563,14.2400003969669,-0.00230146640211272,-0.000429987377527052,0.25,-1.34056456974095E-6,-0.000205474196737633,-2.83757736919225E-6,20.0489,20.0489,77982.6953125,77997.6328125,53.7088220704288,19.5608023427385,14.177031,0,0,0,40,4449,20.04905,77990.1640625,,,,,,,,,,,,,0,,,,,,,,,,,,,,
,19700208.18,20.0475,81704.1015625,-0.000216937688385095,7.50916986951261E-7,1,0.999253354069792,40.0298881530762,1.98186781738711,14.2400003969669,-0.00243537697150659,-0.000446553343190265,0.25,-7.03497319155287E-7,-0.000217301115069356,-2.27156524573327E-6,20.0475,20.0475,81701.65625,81706.546875,53.9261147987749,19.5620842603485,14.177031,0,0,0,40,4449,20.0475,81704.1015625,,,,,,,,,,,,,0,,,,,,,,,,,,,,
,19700284.32,20.0442,85509.98828125,-0.000230090109256771,7.87657301149635E-7,1,0.999253354069792,40.0298881530762,1.98183148488787,14.2400003969669,-0.00258469670323709,-0.000468109556337252,0.25,-2.61664331276166E-7,-0.000230541570068548,-1.90722480872246E-6,20.0442,20.0442,85504.9375,85515.0390625,54.1082342437557,19.5597765612043,14.177031,0,0,0,40,4449,20.0442,85509.98828125,,,,,,,,,,,,,0,,,,,,,,,,,,,,
,19700353.17,20.045,88950.68359375,-0.000241006480926133,6.74512197608382E-7,1,0.999253354069792,40.0298881530762,1.9818297919737,14.2400003969669,-0.00270733591604349,-0.00049386485367616,0.25,-5.97201473848339E-7,-0.000241533454643864,-2.30427648431426E-6,20.045,20.045,88948.3203125,88953.046875,53.7267995263711,19.5575592525883,14.177031,0,0,0,40,4449,20.045,88950.68359375,,,,,,,,,,,,,0,,,,,,,,,,,,,,
,19700438.32,20.0452,87760.96875,-0.000237915283299263,7.49879599450209E-7,1,0.999253354069792,40.0298881530762,1.98176531433135,14.2400003969669,-0.00267238406412125,-0.000487098171133849,0.25,-5.49692184450534E-7,-0.000238416821372622,-2.24079162797163E-6,20.0453,20.0453,87758.2421875,87763.6953125,53.7174199841403,19.5596113660958,14.556682,0,0,0,40,4449,20.0452,87760.96875,,,,,,,,,,,,,0,,,,,,,,,,,,,,
,19700508.255,20.0449,84267.14453125,-0.000225307819839633,6.23907157119587E-7,1,0.999253354069792,40.0298881530762,1.9817608233495,14.2500000074506,-0.00252721690123987,-0.000477508734144906,0.25,-1.9581635791233E-6,-0.000225718039220884,-3.57826400215701E-6,20.0449,20.0449,84264.6796875,84269.609375,53.8487335753711,19.5616856452725,14.556682,0,0,0,40,4449,20.0449,84267.14453125,,,,,,,,,,,,,0,,,,,,,,,,,,,,
,19700582.33,20.04555,80563.14453125,-0.000213858719801682,7.69891541093529E-7,1,0.999253354069792,40.0298881530762,1.98187791843467,14.2400003969669,-0.00240094512517789,-0.000438387661426095,0.25,-5.29381816336229E-7,-0.000214200178898546,-2.07924062856429E-6,20.0456,20.0456,80561.140625,80565.1484375,53.7252362693326,19.5621341066428,14.556682,0,0,0,40,4449,20.04555,80563.14453125,,,,,,,,,,,,,0,,,,,,,,,,,,,,
,19700654.695,20.04545,76946.90625,-0.000201914684789133,6.96322207339655E-7,1,0.999253354069792,40.0298881530762,1.98181724689289,14.2400003969669,-0.00226641921866286,-0.000412364059134725,0.25,-3.61457147510306E-7,-0.000202182570782041,-1.83646973854776E-6,20.0455,20.0455,76942.3125,76951.5,54.0167837070057,19.5626531536632,14.177031,0,0,0,40,4449,20.04545,76946.90625,,,,,,,,,,,,,0,,,,,,,,,,,,,,
,19700727.77,20.04555,73292.89453125,-0.000188736794378681,7.9859611196642E-7,1,0.999253354069792,40.0298881530762,1.98168874937134,14.2400003969669,-0.0021166210625972,-0.000391621171948897,0.25,-8.8956449793025E-7,-0.000188928294542345,-2.27848110901146E-6,20.0457,20.0457,73287.8125,73297.9765625,53.7010057852365,19.5619048674359,14.556682,0,0,0,40,4449,20.04555,73292.89453125,,,,,,,,,,,,,0,,,,,,,,,,,,,,
,19700801.33,20.0464,69617.14453125,-0.000177117929691322,6.47176483637247E-7,1,0.999253354069792,40.0298881530762,1.98171633218286,14.2400003969669,-0.0019866602839815,-0.000362299689287854,0.25,-3.72082871751453E-7,-0.000177246962604743,-1.68220791433633E-6,20.0464,20.0464,69614.5703125,69619.71875,53.8526417179672,19.563181520075,14.936333,0,0,0,40,4449,20.0464,69617.14453125,,,,,,,,,,,,,0,,,,,,,,,,,,,,
,19700874.46,20.0482,65961.1953125,-0.000166021005397503,6.52403697014856E-7,1,0.999253354069792,40.0298881530762,1.98176598275603,14.2400003969669,-0.00186129685960083,-0.000341442190763364,0.25,-5.16531217227201E-7,-0.000166088165710188,-1.74940082396265E-6,20.0481,20.0481,65951,65971.390625,54.2801925179865,19.5645551132185,14.556682,0,0,0,40,4449,20.0482,65961.1953125,,,,,,,,,,,,,0,,,,,,,,,,,,,,
,19700948.405,20.0492,62265.296875,-0.000153608057688761,5.52004117168508E-7,1,0.999253354069792,40.0298881530762,1.98176363043616,14.2400003969669,-0.00172070936402706,-0.000320518471341392,0.25,-8.9509741564449E-7,-0.000153616002413654,-2.03815674214774E-6,20.0492,20.0492,62262.7734375,62267.8203125,53.7643176952942,19.5618214012254,14.556682,0,0,0,40,4449,20.0492,62265.296875,,,,,,,,,,,,,0,,,,,,,,,,,,,,
,19701020.265,20.0502,58674.7109375,-0.000141995985668576,5.87468409626619E-7,1,0.999253354069792,40.0298881530762,1.98170835222447,14.2400003969669,-0.0015922277040885,-0.000284137695024374,0.25,2.47529255826913E-7,-0.000141963794303016,-8.09281262756696E-7,20.0502,20.0502,58669.72265625,58679.69921875,54.4615303344481,19.5640865090894,14.556682,0,0,0,40,4449,20.0502,58674.7109375,,,,,,,,,,,,,0,,,,,,,,,,,,,,
,19701093.695,20.0505,55003.779296875,-0.000129394583138138,5.39970798341124E-7,1,0.999253354069792,40.0298881530762,1.98178849583616,14.2400003969669,-0.00144961351759781,-0.000263585602711116,0.25,-1.99486328915514E-7,-0.000129316359165359,-1.16039561105436E-6,20.0505,20.0505,54996.34765625,55011.2109375,54.0160020784865,19.5638135584024,14.556682,0,0,0,40,4449,20.0505,55003.779296875,,,,,,,,,,,,,0,,,,,,,,,,,,,,
,19701167.18,20.0512,51330.72265625,-0.000117742880400483,6.14184999327499E-7,1,0.999253354069792,40.0298881530762,1.98170778080539,14.2400003969669,-0.00131950859314697,-0.000234418384811192,0.25,2.91178090893756E-7,-0.00011763235816703,-5.79690513165142E-7,20.0512,20.0512,51328.1796875,51333.265625,54.1520054408327,19.5616416788498,14.556682,0,0,0,40,4449,20.0512,51330.72265625,,,,,,,,,,,,,0,,,,,,,,,,,,,,
,19701240,20.05045,47690.0859375,-0.00010584309907425,5.70187083172195E-7,1,0.999253354069792,40.0298881530762,1.98181951208602,14.2500000074506,-0.00118488068375768,-0.000215629430525519,0.25,-1.87261463149158E-7,-0.000105701327722814,-9.64089768638368E-7,20.0504,20.0504,47655.140625,47725.03125,53.8839068587365,19.5636814319786,14.177031,0,0,0,40,4449,20.05045,47690.0859375,,,,,,,,,,,,,0,,,,,,,,,,,,,,
,19701313.295,20.0498,44029.23828125,-9.39046539961299E-5,5.78898843273591E-7,1,0.999253354069792,40.0298881530762,1.98174975101683,14.2400003969669,-0.00105029563224998,-0.000194023981075621,0.25,-4.22497818266884E-7,-9.37414523362745E-5,-1.10431329181621E-6,20.0498,20.0498,44021.75,44036.7265625,53.5845431358711,19.564582898367,14.177031,0,0,0,40,4449,20.0498,44029.23828125,,,,,,,,,,,,,0,,,,,,,,,,,,,,
,19701384.915,20.0495,40448.966796875,-8.27027184011011E-5,5.55376705154115E-7,1,0.999253354069792,40.0298881530762,1.98181117865054,14.2400003969669,-0.000924659056617357,-0.000170960557072922,0.25,-3.92203950403894E-7,-8.25278127167139E-5,-9.8479377935056E-7,20.0495,20.0495,40439.02734375,40458.90625,53.6275327044288,19.5644546789394,14.556682,0,0,0,40,4449,20.0495,40448.966796875,,,,,,,,,,,,,0,,,,,,,,,,,,,,
,19701457.085,20.05035,36843.41796875,-7.144058848501E-5,4.34350044722497E-7,1,0.999253354069792,40.0298881530762,1.98175100215339,14.2400003969669,-0.000799073693414266,-0.000143952377643448,0.25,-1.91217281836015E-8,-7.1264564262908E-5,-5.23366461736612E-7,20.0504,20.0504,36836.08203125,36850.75390625,54.4201040229288,19.564952275543,14.936333,0,0,0,40,4449,20.05035,36843.41796875,,,,,,,,,,,,,0,,,,,,,,,,,,,,
,19701531.955,20.05075,33100.66796875,-5.95538631757281E-5,4.89919173267122E-7,1,0.999253354069792,40.0298881530762,1.98179276917191,14.2400003969669,-0.00066624296082297,-0.000117864182650758,0.25,1.62574807145598E-7,-5.9384771085403E-5,-2.49631166372219E-7,20.0508,20.0508,33093.40625,33107.9296875,53.9792655380826,19.5657667299852,14.936333,0,0,0,40,4449,20.05075,33100.66796875,,,,,,,,,,,,,0,,,,,,,,,,,,,,
,19701604.57,20.0514,29469.966796875,-4.80439109150155E-5,5.78416159019585E-7,1,0.999253354069792,40.0298881530762,1.98175104126994,14.2400003969669,-0.000536998679251801,-9.65071777162582E-5,0.25,-7.37087460173479E-9,-4.78882006794697E-5,-3.31594676712027E-7,20.0512,20.0512,29465.09375,29474.83984375,53.8643661457557,19.5651201293233,14.556682,0,0,0,40,4449,20.0514,29469.966796875,,,,,,,,,,,,,0,,,,,,,,,,,,,,
,19701677.085,20.0522,25844.1982421875,-3.61870494999505E-5,5.58457249920538E-7,1,0.999253354069792,40.0298881530762,1.98174795768519,14.2400003969669,-0.000404954797951609,-6.91127534538275E-5,0.25,3.05398596331942E-7,-3.60582176019918E-5,6.68631668124268E-8,20.0522,20.0522,25841.5859375,25846.810546875,54.2340764353519,19.5678640515144,14.177031,0,0,0,40,4449,20.0522,25844.1982421875,,,,,,,,,,,,,0,,,,,,,,,,,,,,
,19701751.045,20.0525,22148.9248046875,-2.47800413166778E-5,3.71691333423408E-7,1,0.999253354069792,40.0298881530762,1.98181029856606,14.2400003969669,-0.000276277789969478,-5.24976353089372E-5,0.25,-2.60522996343198E-7,-2.46795423538575E-5,-4.16764758317828E-7,20.0525,20.0525,22143.962890625,22153.88671875,53.7205464982172,19.5677482889258,14.556682,0,0,0,40,4449,20.0525,22148.9248046875,,,,,,,,,,,,,0,,,,,,,,,,,,,,
,19701825.785,20.0514,18413.7373046875,-1.22182128330998E-5,4.06785033099512E-7,1,0.999253354069792,40.0298881530762,1.98180481744588,14.2400003969669,-0.000135978346741969,-2.6965612862772E-5,0.25,-2.28981673535908E-7,-1.21636315905729E-5,-3.02630119201587E-7,20.0513,20.0513,18406.12109375,18421.353515625,54.2575252909288,19.569545687838,14.177031,0,0,0,40,4449,20.0514,18413.7373046875,,,,,,,,,,,,,0,,,,,,,,,,,,,,
,19701900.85,20.05115,14660.7373046875,-8.74518341406641E-7,2.76227124422154E-7,1,0.999253354069792,40.0298881530762,1.98187927603268,14.2400003969669,-8.88942739210558E-6,-6.63286730033221E-6,0.25,-4.3792961648358E-7,-8.67845171086741E-7,-4.40989280803079E-7,20.0511,20.0511,14648.2587890625,14673.2158203125,54.0105306788519,19.5657849467324,14.177031,0,0,0,40,4449,20.05115,14660.7373046875,,,,,,,,,,,,,0,,,,,,,,,,,,,,
,19701978.605,20.049,10778.1733398438,1.06338687334556E-5,3.69888443655017E-7,1,0.999253354069792,40.0298881530762,1.98185078116092,14.2400003969669,0.000118912148558555,1.98435038930085E-5,0.25,-1.18494910185903E-7,1.05809875972551E-5,-5.86379559752699E-8,20.049,20.049,10770.798828125,10785.5478515625,54.2332948068327,19.5678406919667,14.556682,0,0,0,40,4449,20.049,10778.1733398438,,,,,,,,,,,,,0,,,,,,,,,,,,,,
,19702054.285,20.04775,6994.85595703125,2.23989567978161E-5,2.93882084586938E-7,1,0.999253354069792,40.0298881530762,1.98191954450446,14.2400003969669,0.00025003068309728,4.38978981423717E-5,0.25,-5.4177759762315E-8,2.22798287643798E-5,6.47288641980958E-8,20.0476,20.0476,6992.87890625,6996.8330078125,54.1520054408327,19.5676607691409,14.556682,0,0,0,40,4449,20.04775,6994.85595703125,,,,,,,,,,,,,0,,,,,,,,,,,,,,
,19702129.995,20.04415,3208.79736328125,3.35472402306318E-5,3.66954051538543E-7,1,0.999253354069792,40.0298881530762,1.98182836137308,14.2400003969669,0.000374758007453049,6.34912280448161E-5,0.25,-2.72572733663556E-7,3.33611400626176E-5,-1.02344769668865E-7,20.0441,20.0441,3203.93481445313,3213.65991210937,53.9581615680634,19.5689086908492,14.936333,0,0,0,40,4449,20.04415,3208.79736328125,,,,,,,,,,,,,0,,,,,,,,,,,,,,
,19702210.04,20.0497,-789.100952148438,3.24375390173405E-5,3.18049898956211E-7,1,0.999253354069792,40.0298881530762,1.98197694154151,14.2400003969669,0.000362511255423241,6.04161438641855E-5,0.25,-3.45817931401462E-7,3.22536878701768E-5,-1.85500090651088E-7,20.0491,20.0491,-794.355834960937,-783.846069335938,53.8463886898134,19.5680895691806,14.936333,0,0,0,40,4449,20.0497,-789.100952148438,,,,,,,,,,,,,0,,,,,,,,,,,,,,
,19702290.03,20.04905,-4786.46435546875,3.9854322838883E-5,3.14305936023025E-7,1,0.999253354069792,40.0298881530762,1.98186095343841,14.2400003969669,0.000444669029858973,7.88025564523736E-5,0.25,-2.64573662262908E-8,3.96357813298134E-5,1.78431284733658E-7,20.049,20.049,-4798.7900390625,-4774.138671875,53.7260178978518,19.5705817912819,14.556682,0,0,0,40,4449,20.04905,-4786.46435546875,,,,,,,,,,,,,0,,,,,,,,,,,,,,
,19702363.45,20.0476,-8455.01416015625,4.91171687429047E-5,3.35979425285512E-7,1,0.999253354069792,40.0298881530762,1.98189239471459,14.2500000074506,0.000547477799209833,0.000101050951359344,0.25,3.04384241037651E-7,4.8859086328507E-5,5.68147243674705E-7,20.0476,20.0476,-8462.5322265625,-8447.49609375,53.922988284698,19.5687041844068,14.556682,0,0,0,40,4449,20.0476,-8455.01416015625,,,,,,,,,,,,,0,,,,,,,,,,,,,,
,19702438.57,20.0452,-12208.537109375,5.72945292919293E-5,3.26858306023208E-7,1,0.999253354069792,40.0298881530762,1.98186560569878,14.2400003969669,0.000639959316286953,0.000111490060977444,0.25,-2.35771777000654E-7,5.70142694855558E-5,9.0638388009962E-8,20.0455,20.0455,-12215.8232421875,-12201.2509765625,53.9104822283903,19.5707954987811,14.556682,0,0,0,40,4449,20.0452,-12208.537109375,,,,,,,,,,,,,0,,,,,,,,,,,,,,
,19702511.86,20.05045,-15874.2788085938,6.0936896246647E-5,4.27425756118433E-7,1,0.999253354069792,40.0298881530762,1.98187974046145,14.2500000074506,0.000681097510422081,0.000117355303981585,0.25,-3.79644607086494E-7,6.06594485809968E-5,-1.61121576868836E-8,20.0506,20.0506,-15884.2958984375,-15864.26171875,53.6666141303903,19.5709263764362,14.556682,0,0,0,40,4449,20.05045,-15874.2788085938,,,,,,,,,,,,,0,,,,,,,,,,,,,,
,19702593.28,20.0561,-19941.646484375,6.21232896566732E-5,3.40836260726501E-7,1,0.999253354069792,40.0298881530762,1.98183746862343,14.2400003969669,0.000695108464656972,0.000116922977895734,0.25,-6.51102449335484E-7,6.18660569821595E-5,-2.62637800386073E-7,20.0561,20.0561,-19941.646484375,-19941.646484375,53.9902083373519,19.5704519075613,14.177031,0,0,0,40,4449,20.0561,-19941.646484375,,,,,,,,,,,,,0,,,,,,,,,,,,,,
,19702674.29,20.0597,-23992.0986328125,6.08669027436506E-5,4.24879467502404E-7,1,0.999253354069792,40.0298881530762,1.98183294992302,14.2500000074506,0.000680383450717644,0.000119866530848533,0.25,-1.81948588466663E-7,6.06365403896187E-5,2.1174552648977E-7,20.0597,20.0597,-23999.607421875,-23984.58984375,54.169982896775,19.5710927279661,14.936333,0,0,0,40,4449,20.0597,-23992.0986328125,,,,,,,,,,,,,0,,,,,,,,,,,,,,
,19702750.585,20.0584,-27805.0263671875,6.16600231445373E-5,4.06006090642865E-7,1,0.999253354069792,40.0298881530762,1.98182190540402,14.2400003969669,0.000691304255684123,0.000111518324588854,0.25,-1.08803359176591E-6,6.14568152424376E-5,-6.73315143287224E-7,20.0584,20.0584,-27812.408203125,-27797.64453125,54.0394509340634,19.5708221832264,14.936333,0,0,0,40,4449,20.0584,-27805.0263671875,,,,,,,,,,,,,0,,,,,,,,,,,,,,
,19702824.07,20.0555,-31475.6572265625,6.61279108495614E-5,5.16329094943769E-7,1,0.999253354069792,40.0298881530762,1.98186856939804,14.2400003969669,0.000741472323608913,0.000120924095766335,0.25,-1.06434669258483E-6,6.59348600867396E-5,-6.08611622981003E-7,20.0555,20.0555,-31480.50390625,-31470.810546875,54.2661232046404,19.5726414217637,14.556682,0,0,0,40,4449,20.0555,-31475.6572265625,,,,,,,,,,,,,0,,,,,,,,,,,,,,
,19702896.04,20.0533,-35072.6796875,7.27545924525517E-5,5.2747871290777E-7,1,0.999253354069792,40.0298881530762,1.9818939340156,14.2500000074506,0.000816129523770663,0.000132924774377958,0.25,-1.1969819018938E-6,7.25701966679615E-5,-6.85010079828892E-7,20.0533,20.0533,-35077.8515625,-35067.5078125,53.912827113948,19.5723788779405,14.556682,0,0,0,40,4449,20.0533,-35072.6796875,,,,,,,,,,,,,0,,,,,,,,,,,,,,
,19702968.91,20.05145,-38718.01953125,8.09812191667398E-5,5.189219525052E-7,1,0.999253354069792,40.0298881530762,1.98198212061002,14.2400003969669,0.000909094274081312,0.000146412130321085,0.25,-1.48618367054483E-6,8.08084946416635E-5,-9.0605441759982E-7,20.0515,20.0515,-38730.765625,-38705.2734375,54.044922333698,19.5732225911399,14.936333,0,0,0,40,4449,20.05145,-38718.01953125,,,,,,,,,,,,,0,,,,,,,,,,,,,,
,19703043.54,20.04965,-42443.626953125,9.24740309811068E-5,4.53930650768268E-7,1,0.999253354069792,40.0298881530762,1.98186426724241,14.2400003969669,0.00103674923586195,0.000176775266601912,0.25,-8.55563979234769E-7,9.23071897667266E-5,-1.85395666791968E-7,20.0496,20.0496,-42448.73828125,-42438.515625,53.882343601698,19.5712628049991,14.177031,0,0,0,40,4449,20.04965,-42443.626953125,,,,,,,,,,,,,0,,,,,,,,,,,,,,
,19703116.875,20.0489,-46109.169921875,0.000102372707703805,5.50623380272017E-7,1,0.999253354069792,40.0298881530762,1.98186120622928,14.2400003969669,0.00114856222242252,0.000193565326781865,0.25,-1.15250373146764E-6,0.000102228675476382,-4.0216322676136E-7,20.0489,20.0489,-46116.71875,-46101.62109375,53.4172746327557,19.5738327103045,14.936333,0,0,0,40,4449,20.0489,-46109.169921875,,,,,,,,,,,,,0,,,,,,,,,,,,,,
,19703188.54,20.04875,-49692.23828125,0.000114365869042789,5.05437911474087E-7,1,0.999253354069792,40.0298881530762,1.98192605724783,14.2500000074506,0.00128138030932885,0.000228822595962881,0.25,-1.78659844531394E-7,0.000114238836281578,6.64756343874873E-7,20.0487,20.0487,-49699.7578125,-49684.71875,54.2137540938519,19.5758032416241,14.177031,0,0,0,40,4449,20.04875,-49692.23828125,,,,,,,,,,,,,0,,,,,,,,,,,,,,
,19703266.945,20.04895,-53609.74609375,0.000124613424030012,6.00504848955004E-7,1,0.999253354069792,40.0298881530762,1.98194439868373,14.2400003969669,0.00139904125251381,0.000236753339410721,0.25,-1.33070531192105E-6,0.000124532318310874,-4.05506605389431E-7,20.049,20.049,-53617.15625,-53602.3359375,54.2121908368134,19.5742394297866,14.936333,0,0,0,40,4449,20.04895,-53609.74609375,,,,,,,,,,,,,0,,,,,,,,,,,,,,
,19703342.805,20.0518,-57402.046875,0.000138754583582613,6.69338581351846E-7,1,0.999253354069792,40.0298881530762,1.98183923217279,14.2400003969669,0.0015566795077315,0.000272704071597024,0.25,-6.81494654922484E-7,0.000138709568402047,3.50927901938306E-7,20.0518,20.0518,-57409.34375,-57394.75,54.0206918496019,19.5749675558229,14.556682,0,0,0,40,4449,20.0518,-57402.046875,,,,,,,,,,,,,0,,,,,,,,,,,,,,
,19703425.165,20.05485,-61514.546875,0.000153353705476936,7.60141991294059E-7,1,0.999253354069792,40.0298881530762,1.98195763218906,14.2400003969669,0.00172030962026593,0.000306639679008635,0.25,-2.97695447698425E-7,0.000153359916122225,8.43607561882859E-7,20.055,20.055,-61527.01171875,-61502.08203125,54.1152689004288,19.5731140328153,14.177031,0,0,0,40,4449,20.05485,-61514.546875,,,,,,,,,,,,,0,,,,,,,,,,,,,,
,19703506.26,20.05445,-65569.8671875,0.000164687136350436,7.03954460292385E-7,1,0.999253354069792,40.0298881530762,1.98194878739896,14.2400003969669,0.00184870400140276,0.000326163650477373,0.25,-6.07085285485754E-7,0.000164756374899159,6.15812841426517E-7,20.0545,20.0545,-65575.1015625,-65564.6328125,54.0300713918326,19.5750282461782,14.556682,0,0,0,40,4449,20.05445,-65569.8671875,,,,,,,,,,,,,0,,,,,,,,,,,,,,
,19703584.32,20.05545,-69472.609375,0.000177943764187913,7.50087612087704E-7,1,0.999253354069792,40.0298881530762,1.98191420563771,14.2400003969669,0.00199688870237197,0.000359583338064996,0.25,-2.17377055432879E-8,0.00017807414816683,1.29444780629482E-6,20.0555,20.0555,-69477.6484375,-69467.5703125,53.9792655380826,19.5754568986349,14.556682,0,0,0,40,4449,20.05545,-69472.609375,,,,,,,,,,,,,0,,,,,,,,,,,,,,
,19703658.62,20.0484,-73182.47265625,0.000190823973579909,8.04019259488807E-7,1,0.999253354069792,40.0298881530762,1.98192371429104,14.2500000074506,0.00214135101642809,0.000389889173476106,0.25,3.55344752906906E-7,0.000191019880420532,1.75931306825776E-6,20.0485,20.0485,-73194.9765625,-73169.96875,54.1731094108519,19.5762607611855,14.556682,0,0,0,40,4449,20.0484,-73182.47265625,,,,,,,,,,,,,0,,,,,,,,,,,,,,
,19703736.275,20.04845,-77062.86328125,0.000203867903126919,7.80120895689386E-7,1,0.999253354069792,40.0298881530762,1.98202698669951,14.2400003969669,0.00228928989797204,0.000412542289696435,0.25,2.18952521718785E-8,0.000204142723831141,1.5103527039869E-6,20.0486,20.0486,-77067.8515625,-77057.875,54.1309014708134,19.577271078802,14.177031,0,0,0,40,4449,20.04845,-77062.86328125,,,,,,,,,,,,,0,,,,,,,,,,,,,,
,19703816.125,20.0501,-81058.06640625,0.000215744149847001,7.7396531678029E-7,1,0.999253354069792,40.0298881530762,1.9819894692489,14.2400003969669,0.0024221685435399,0.00044319597783301,0.25,6.16425710857871E-7,0.000216095932700711,2.17821011293486E-6,20.0501,20.0501,-81060.34375,-81055.7890625,54.1692012682557,19.5742315034486,14.177031,0,0,0,40,4449,20.0501,-81058.06640625,,,,,,,,,,,,,0,,,,,,,,,,,,,,
,19703896.375,20.0507,-85065.67578125,0.000229716366999878,6.68068813275556E-7,1,0.999253354069792,40.0298881530762,1.9820885291536,14.2400003969669,0.0025815954866556,0.000462629457586682,0.25,-1.6474733719462E-7,0.000230163022608911,1.47934946596331E-6,20.0507,20.0507,-85068.9140625,-85062.4375,54.3927470247558,19.5764628501728,14.556682,0,0,0,40,4449,20.0507,-85065.67578125,,,,,,,,,,,,,0,,,,,,,,,,,,,,
,19703973.11,20.0556,-88899.52734375,0.000241782154118269,6.98012570499232E-7,1,0.999253354069792,40.0298881530762,1.98194935751519,14.2400003969669,0.00271923965286917,0.000478563190659949,0.25,-9.06432472959654E-7,0.000242320661350464,8.03084500508045E-7,20.0556,20.0556,-88904.59375,-88894.4609375,54.3755511973327,19.5757740227039,14.177031,0,0,0,40,4449,20.0556,-88899.52734375,,,,,,,,,,,,,0,,,,,,,,,,,,,,
,19704060.89,20.0485,-87678.375,0.000239212174036146,8.81281559521841E-7,1,0.999253354069792,40.0298881530762,1.98196901990573,14.2400003969669,0.00268714065318226,0.00049013055959233,0.25,5.81789275674854E-7,0.000239714905205968,2.28258157499958E-6,20.0485,20.0485,-87688.375,-87668.375,54.1379361274865,19.5748422082566,14.556682,0,0,0,40,4449,20.0485,-87678.375,,,,,,,,,,,,,0,,,,,,,,,,,,,,
,19704129.44,20.04465,-84253.44140625,0.000227436356505478,6.71949657468967E-7,1,0.999253354069792,40.0298881530762,1.98198623703706,14.2400003969669,0.00255487154569765,0.000462597097705349,0.25,2.43284317692222E-7,0.000227862666403464,1.87548695344964E-6,20.0445,20.0445,-84255.90625,-84250.9765625,54.1152689004288,19.5744110281418,14.556682,0,0,0,40,4449,20.04465,-84253.44140625,,,,,,,,,,,,,0,,,,,,,,,,,,,,
,19704203.48,20.0443,-80553.70703125,0.000215296703598352,7.16954701455039E-7,1,0.999253354069792,40.0298881530762,1.98191297604071,14.2400003969669,0.00241971596220857,0.000426968750338995,0.25,-7.46815716959699E-7,0.000215649576751362,8.11434703476063E-7,20.0443,20.0443,-80558.65625,-80548.7578125,54.4318284507173,19.5726001220653,14.556682,0,0,0,40,4449,20.0443,-80553.70703125,,,,,,,,,,,,,0,,,,,,,,,,,,,,
,19704278.315,20.0429,-76815.37109375,0.000203126794095539,7.03966445173718E-7,1,0.999253354069792,40.0298881530762,1.98187741056854,14.2400003969669,0.00227953210545979,0.000417820337494937,0.25,6.27979533691903E-7,0.000203392276384417,2.11260366949579E-6,20.043,20.043,-76820.5078125,-76810.234375,54.4052530810634,19.5742038206511,14.556682,0,0,0,40,4449,20.0429,-76815.37109375,,,,,,,,,,,,,0,,,,,,,,,,,,,,
,19704356.235,20.0432,-72920.18359375,0.000189197290720307,6.81591815591311E-7,1,0.999253354069792,40.0298881530762,1.98196478834328,14.2500000074506,0.00212404768453048,0.000381269759628815,0.25,-1.20053665512132E-7,0.0001893909541355,1.27208018562686E-6,20.0432,20.0432,-72922.53125,-72917.8359375,53.9151719995057,19.5736238530775,14.556682,0,0,0,40,4449,20.0432,-72920.18359375,,,,,,,,,,,,,0,,,,,,,,,,,,,,
,19704431.045,20.04425,-69177.62890625,0.000176813668546326,7.03131543316263E-7,1,0.999253354069792,40.0298881530762,1.98192307031333,14.2400003969669,0.00198814954166406,0.000335182791529759,0.25,-1.99239462984455E-6,0.000176953360335934,-6.85466420536951E-7,20.0441,20.0441,-69185.515625,-69169.7421875,53.9597248251019,19.5743672332381,14.556682,0,0,0,40,4449,20.04425,-69177.62890625,,,,,,,,,,,,,0,,,,,,,,,,,,,,
,19704508.39,20.0492,-65317.4765625,0.000164000765359664,5.77806149990311E-7,1,0.999253354069792,40.0298881530762,1.98194192009512,14.2500000074506,0.00184211792573628,0.000318325686851785,0.25,-1.18160542256709E-6,0.000164070324314834,3.62348615973859E-8,20.0492,20.0492,-65322.34375,-65312.609375,54.139499384525,19.5741716395689,14.177031,0,0,0,40,4449,20.0492,-65317.4765625,,,,,,,,,,,,,0,,,,,,,,,,,,,,
,19704589.495,20.0532,-61262.203125,0.000151079113177029,8.01210530210214E-7,1,0.999253354069792,40.0298881530762,1.98189340262412,14.2400003969669,0.00169418417439201,0.000304944643600113,0.25,-3.74570906735436E-8,0.000151079802138276,1.0869797694586E-6,20.0533,20.0533,-61264.79296875,-61259.61328125,53.9706676243711,19.5719344511841,14.556682,0,0,0,40,4449,20.0532,-61262.203125,,,,,,,,,,,,,0,,,,,,,,,,,,,,
,19704672.24,20.0556,-57127.13671875,0.000137076033532865,6.22125176995288E-7,1,0.999253354069792,40.0298881530762,1.98191986267023,14.2400003969669,0.00153727995850122,0.000272666309484108,0.25,-3.82503546379092E-7,0.000137025788226073,6.37201912182788E-7,20.0556,20.0556,-57132.06640625,-57122.20703125,53.8581131176019,19.5701354619333,14.177031,0,0,0,40,4449,20.0556,-57127.13671875,,,,,,,,,,,,,0,,,,,,,,,,,,,,
,19704752.32,20.05595,-53124.572265625,0.000124395097897729,6.2306577760452E-7,1,0.999253354069792,40.0298881530762,1.98184543376159,14.2400003969669,0.00139506186101106,0.000244053470558903,0.25,-6.37311474840184E-7,0.000124303042286617,2.85266996303519E-7,20.056,20.056,-53129.671875,-53119.47265625,54.2184438649673,19.5733218186781,14.556682,0,0,0,40,4449,20.05595,-53124.572265625,,,,,,,,,,,,,0,,,,,,,,,,,,,,
,19704827.005,20.0547,-49394.9296875,0.000111743667515741,4.56333923720177E-7,1,0.999253354069792,40.0298881530762,1.98196172131459,14.2400003969669,0.00125088009048868,0.000229701549712031,0.25,3.73013482565424E-7,0.000111612146244491,1.19599289664653E-6,20.0547,20.0547,-49397.203125,-49392.65625,53.9573799395442,19.569897300751,14.556682,0,0,0,40,4449,20.0547,-49394.9296875,,,,,,,,,,,,,0,,,,,,,,,,,,,,
,19704901.93,20.0511,-45649.6484375,9.96170087047261E-5,5.8622970635703E-7,1,0.999253354069792,40.0298881530762,1.98182734375054,14.2400003969669,0.00111837599208465,0.000183886103997885,0.25,-1.51866016252972E-6,9.94750093888068E-5,-7.88768775918606E-7,20.0511,20.0511,-45654.625,-45644.671875,54.0910384163326,19.5711924130337,14.936333,0,0,0,40,4449,20.0511,-45649.6484375,,,,,,,,,,,,,0,,,,,,,,,,,,,,
,19704978.455,20.04905,-41823.984375,8.76146799511034E-5,5.24915168263047E-7,1,0.999253354069792,40.0298881530762,1.9819268343087,14.2400003969669,0.000982022333547226,0.000168662553865314,0.25,-7.03573882283394E-7,8.74501216591112E-5,-7.01991927224987E-8,20.0491,20.0491,-41831.3125,-41816.65625,54.403689824025,19.5699924920386,14.556682,0,0,0,40,4449,20.04905,-41823.984375,,,,,,,,,,,,,0,,,,,,,,,,,,,,
,19705051.55,20.04935,-38170.84765625,7.61790725207432E-5,5.91021587259266E-7,1,0.999253354069792,40.0298881530762,1.98196602786408,14.2400003969669,0.000852920564004362,0.000149994258712406,0.25,-2.99738954218109E-7,7.60043514951534E-5,2.42160606166666E-7,20.0492,20.0492,-38178.3359375,-38163.359375,53.9706676243711,19.5708442140807,14.556682,0,0,0,40,4449,20.04935,-38170.84765625,,,,,,,,,,,,,0,,,,,,,,,,,,,,
,19705129.875,20.0546,-34258.337890625,6.29247672297541E-5,4.3761267374697E-7,1,0.999253354069792,40.0298881530762,1.9819067346704,14.2500000074506,0.000705767818548164,0.000115166456070444,0.25,-1.01446551093256E-6,6.2759683988806E-5,-5.73648069716613E-7,20.0546,20.0546,-34265.75390625,-34250.921875,54.0535202474096,19.5696028770762,14.556682,0,0,0,40,4449,20.0546,-34258.337890625,,,,,,,,,,,,,0,,,,,,,,,,,,,,
,19705210.28,20.0608,-30238.4453125,5.06057189372764E-5,5.07393692200359E-7,1,0.999253354069792,40.0298881530762,1.98183323712066,14.2400003969669,0.000567987649615698,8.89327275691289E-5,0.25,-1.13308317934138E-6,5.04535248788445E-5,-7.860978803747E-7,20.0608,20.0608,-30243.611328125,-30233.279296875,53.9347127124865,19.5695315956072,14.936333,0,0,0,40,4449,20.0608,-30238.4453125,,,,,,,,,,,,,0,,,,,,,,,,,,,,
,19705285.65,20.0574,-26473.1474609375,3.7876354417562E-5,6.61115285917016E-7,1,0.999253354069792,40.0298881530762,1.98173172956471,14.2500000074506,0.000424181702153498,7.06813230452588E-5,0.25,-4.69672092415293E-7,3.77449582692246E-5,-2.18191963407534E-7,20.0574,20.0574,-26505.791015625,-26440.50390625,54.0902567878134,19.5683655174914,14.177031,0,0,0,40,4449,20.0574,-26473.1474609375,,,,,,,,,,,,,0,,,,,,,,,,,,,,
,19705357.825,20.0568,-22865.4658203125,2.6738910332632E-5,3.91214038520542E-7,1,0.999253354069792,40.0298881530762,1.9817925811225,14.2400003969669,0.0003002577387212,4.48129366332417E-5,0.25,-7.7977334701931E-7,2.66391472123747E-5,-6.05847138697403E-7,20.0569,20.0569,-22872.80078125,-22858.130859375,53.8581131176019,19.5679742539678,14.556682,0,0,0,40,4449,20.0568,-22865.4658203125,,,,,,,,,,,,,0,,,,,,,,,,,,,,
,19705431.18,20.0554,-19197.322265625,1.50224314578947E-5,3.69802455461625E-7,1,0.999253354069792,40.0298881530762,1.98180876130955,14.2400003969669,0.000170226851108957,1.62415481992212E-5,0.25,-1.23396477080255E-6,1.49657726668458E-5,-1.13613474630803E-6,20.0554,20.0554,-19199.986328125,-19194.658203125,54.0777507315057,19.5684773370809,14.556682,0,0,0,40,4449,20.0554,-19197.322265625,,,,,,,,,,,,,0,,,,,,,,,,,,,,
,19705504.46,20.0544,-15537.7783203125,3.69432565081547E-6,2.55149603105715E-7,1,0.999253354069792,40.0298881530762,1.98179467458632,14.2400003969669,4.27647742221005E-5,-1.14495125647869E-6,0.25,-7.62738870032012E-7,3.6817659668169E-6,-7.37366937332695E-7,20.0544,20.0544,-15542.6064453125,-15532.9501953125,53.9292413128519,19.5674242009258,14.936333,0,0,0,40,4449,20.0544,-15537.7783203125,,,,,,,,,,,,,0,,,,,,,,,,,,,,
,19705576.555,20.0523,-11934.3081054687,-7.13037744784969E-6,3.9284749522434E-7,1,0.999253354069792,40.0298881530762,1.98182864230371,14.2400003969669,-7.82762845742565E-5,-2.1519653978045E-5,0.25,-6.55784795068406E-7,-7.0914567088028E-6,-6.92883476189755E-7,20.0524,20.0524,-11939.2412109375,-11929.375,54.2661232046404,19.5693739871251,14.177031,0,0,0,40,4449,20.0523,-11934.3081054687,,,,,,,,,,,,,0,,,,,,,,,,,,,,
,19705649.675,20.05,-8277.96826171875,-1.8485990622736E-5,3.37882795324205E-7,1,0.999253354069792,40.0298881530762,1.98202847239217,14.2400003969669,-0.000204450221827145,-4.70822340336431E-5,0.25,-9.25621285480196E-7,-1.83842357855465E-5,-1.02040620437638E-6,20.0501,20.0501,-8285.484375,-8270.4521484375,53.9917715943903,19.5687614896107,14.936333,0,0,0,40,4449,20.05,-8277.96826171875,,,,,,,,,,,,,0,,,,,,,,,,,,,,
,19705722.615,20.0439,-4632.57983398438,-2.89189918560468E-5,2.66563786411422E-7,1,0.999253354069792,40.0298881530762,1.9818561887284,14.2400003969669,-0.00032154072192164,-6.34463643194728E-5,0.25,-5.42844781193907E-7,-2.87572333637947E-5,-6.88110770633369E-7,20.0438,20.0438,-4642.6982421875,-4622.46142578125,53.9894267088326,19.5667884297225,14.177031,0,0,0,40,4449,20.0439,-4632.57983398438,,,,,,,,,,,,,0,,,,,,,,,,,,,,
,19705796.165,20.0424,-955.55078125,-3.70498696044267E-5,2.93776680072118E-7,1,0.999253354069792,40.0298881530762,1.98180433600718,14.2500000074506,-0.00041176638451115,-8.17208284101723E-5,0.25,-7.45050809868312E-7,-3.68345857839687E-5,-9.21970611539266E-7,20.0425,20.0425,-958.224975585938,-952.876586914062,54.085567016698,19.5669134291152,14.556682,0,0,0,40,4449,20.0424,-955.55078125,,,,,,,,,,,,,0,,,,,,,,,,,,,,
,19705870.06,20.0391,2732.34875488281,-3.43220048177864E-5,3.27794704716466E-7,1,0.999253354069792,40.0298881530762,1.98188299454141,14.2500000074506,-0.000382528707237333,-6.99255104179741E-5,0.25,-1.67590140480302E-7,-3.41283829135087E-5,-3.38169119793285E-7,20.0391,20.0391,2730.017578125,2734.67993164062,53.9268964272942,19.566509331255,14.556682,0,0,0,40,4449,20.0391,2732.34875488281,,,,,,,,,,,,,0,,,,,,,,,,,,,,
,19705942.82,20.04115,6372.69775390625,-4.3774993980564E-5,3.44819979617929E-7,1,0.999253354069792,40.0298881530762,1.98180031702895,14.2500000074506,-0.000487537034833614,-9.17103900901315E-5,0.25,-4.27456911081363E-7,-4.35373856388947E-5,-6.54995779287082E-7,20.0412,20.0412,6365.22314453125,6380.17236328125,53.7205464982172,19.5670187373528,14.936333,0,0,0,40,4449,20.04115,6372.69775390625,,,,,,,,,,,,,0,,,,,,,,,,,,,,
,19706016.055,20.04485,10031.1748046875,-5.24926679394193E-5,4.42012111485776E-7,1,0.999253354069792,40.0298881530762,1.98177230372602,14.2400003969669,-0.000585660736360154,-0.000105092373421144,0.25,-5.84293811824386E-8,-5.22248355071497E-5,-3.47787803988677E-7,20.0448,20.0448,10023.7119140625,10038.6376953125,54.0746242174288,19.5671584674045,14.556682,0,0,0,40,4449,20.04485,10031.1748046875,,,,,,,,,,,,,0,,,,,,,,,,,,,,
,19706089.89,20.04665,13722.0024414062,-5.89705233645728E-5,3.17013926602395E-7,1,0.999253354069792,40.0298881530762,1.98171906040451,14.2400003969669,-0.000658073253271727,-0.000118384200677967,0.25,-7.57495232703858E-8,-5.86879949848065E-5,-4.16570779143044E-7,20.0467,20.0467,13717.0400390625,13726.96484375,53.9714492528903,19.5655237285134,14.556682,0,0,0,40,4449,20.04665,13722.0024414062,,,,,,,,,,,,,0,,,,,,,,,,,,,,
,19706163.28,20.0492,17392.341796875,-6.20474455741453E-5,4.72433369689117E-7,1,0.999253354069792,40.0298881530762,1.98168641597747,14.2400003969669,-0.000692163597821955,-0.000127221928546748,0.25,-2.98638395738343E-7,-6.17695757649735E-5,-6.72136764370102E-7,20.0492,20.0492,17389.81640625,17394.8671875,54.078532360025,19.5643192179001,14.936333,0,0,0,40,4449,20.0492,17392.341796875,,,,,,,,,,,,,0,,,,,,,,,,,,,,
,19706237.265,20.0512,21087.927734375,-6.22701958848916E-5,4.20317750357096E-7,1,0.999253354069792,40.0298881530762,1.98183393360276,14.2400003969669,-0.000694937683805649,-0.000127780564447902,0.25,-2.89026221293668E-7,-6.20134561100955E-5,-6.78999038769977E-7,20.0512,20.0512,21082.970703125,21092.884765625,53.7822951512364,19.5637636921384,14.936333,0,0,0,40,4449,20.0512,21087.927734375,,,,,,,,,,,,,0,,,,,,,,,,,,,,
,19706309.015,20.0521,24673.6240234375,-6.1287616544168E-5,3.97930275121837E-7,1,0.999253354069792,40.0298881530762,1.98186049762729,14.2400003969669,-0.000684474343892016,-0.000124434681824032,0.25,-1.48223665800939E-7,-6.10577430155751E-5,-5.45781983002114E-7,20.0521,20.0521,24671.27734375,24675.970703125,54.1981215234673,19.5635163807057,14.177031,0,0,0,40,4449,20.0521,24673.6240234375,,,,,,,,,,,,,0,,,,,,,,,,,,,,
,19706381.965,20.0516,28319.193359375,-6.28100506120094E-5,5.30524220333393E-7,1,0.999253354069792,40.0298881530762,1.98193036918012,14.2400003969669,-0.000702067777051751,-0.000125894500444006,0.25,1.09284131235196E-8,-6.25990857174268E-5,-4.09424951414741E-7,20.0516,20.0516,28309.322265625,28329.064453125,54.2200071220057,19.5647954953557,14.556682,0,0,0,40,4449,20.0516,28319.193359375,,,,,,,,,,,,,0,,,,,,,,,,,,,,
,19706454.005,20.0528,31920.0009765625,-6.68788871906088E-5,4.52234499273679E-7,1,0.999253354069792,40.0298881530762,1.98183155530127,14.2400003969669,-0.000747504986310481,-0.000135713821623383,0.25,-1.2190590433945E-7,-6.66785685455851E-5,-5.80517366002142E-7,20.0528,20.0528,31917.40625,31922.595703125,53.8237214627557,19.5624586106916,14.177031,0,0,0,40,4449,20.0528,31920.0009765625,,,,,,,,,,,,,0,,,,,,,,,,,,,,
,19706527.085,20.0508,35572.93359375,-7.41988583204852E-5,3.91982512580934E-7,1,0.999253354069792,40.0298881530762,1.98177168713454,14.2500000074506,-0.00083047947842313,-0.00014583211957833,0.25,3.03946681920961E-7,-7.40083248851352E-5,-2.1715801905703E-7,20.0508,20.0508,35565.28125,35580.5859375,53.9472187687942,19.5639076164634,14.556682,0,0,0,40,4449,20.0508,35572.93359375,,,,,,,,,,,,,0,,,,,,,,,,,,,,
,19706599.6,20.0497,39195.51953125,-8.31400008436504E-5,5.11017149412135E-7,1,0.999253354069792,40.0298881530762,1.98175550418356,14.2500000074506,-0.000929488097434462,-0.000171346588707094,0.25,-3.53511285159512E-7,-8.29534764933342E-5,-9.46126936222285E-7,20.0498,20.0498,39187.87890625,39203.16015625,53.6204980477557,19.565112678388,14.556682,0,0,0,40,4449,20.0497,39195.51953125,,,,,,,,,,,,,0,,,,,,,,,,,,,,
,19706671.83,20.0488,42806.28515625,-9.23454195935939E-5,5.31527928074487E-7,1,0.999253354069792,40.0298881530762,1.98181640056769,14.2400003969669,-0.00103400351584962,-0.000183860439300078,0.25,2.00458588176147E-7,-9.21775936312777E-5,-4.6839601020052E-7,20.0488,20.0488,42796.33984375,42816.23046875,54.1606033545442,19.567987341069,14.556682,0,0,0,40,4449,20.0488,42806.28515625,,,,,,,,,,,,,0,,,,,,,,,,,,,,
,19706745.28,20.0494,46479.955078125,-0.000104247920429396,6.24462741163406E-7,1,0.999253354069792,40.0298881530762,1.98176117309307,14.2400003969669,-0.00116595583883327,-0.000217281606369262,0.25,-6.27336590344293E-7,-0.000104092068232458,-1.38951082667901E-6,20.0494,20.0494,46474.8515625,46485.05859375,54.1856154671596,19.5645240620277,14.556682,0,0,0,40,4449,20.0494,46479.955078125,,,,,,,,,,,,,0,,,,,,,,,,,,,,
,19706818.97,20.0488,50160.365234375,-0.000115431541810767,4.70850736340054E-7,1,0.999253354069792,40.0298881530762,1.98174708895265,14.2400003969669,-0.00129262839326688,-0.0002345075989859,0.25,-1.36971848045872E-7,-0.000115306456537282,-9.88637770588101E-7,20.0489,20.0489,50157.76953125,50162.9609375,54.027726506275,19.5643560386952,14.556682,0,0,0,40,4449,20.0488,50160.365234375,,,,,,,,,,,,,0,,,,,,,,,,,,,,
,19706891.75,20.04925,53798.439453125,-0.00012622743762513,5.59377088261413E-7,1,0.999253354069792,40.0298881530762,1.98166330164041,14.2400003969669,-0.00141318550118293,-0.00026093563536401,0.25,-5.39020491962658E-7,-0.000126133636471755,-1.47503154793426E-6,20.0493,20.0493,53790.828125,53806.05078125,53.7948012075442,19.5632106260348,14.936333,0,0,0,40,4449,20.04925,53798.439453125,,,,,,,,,,,,,0,,,,,,,,,,,,,,
,19706965.075,20.0503,57463.892578125,-0.000139309439234409,5.70260981033893E-7,1,0.999253354069792,40.0298881530762,1.98170438526181,14.2500000074506,-0.00155995119604031,-0.000289649987596264,0.25,-7.31808362473713E-7,-0.000139254534126374,-1.76788108488686E-6,20.0503,20.0503,57459.0078125,57468.77734375,53.9104822283903,19.5647106887852,14.556682,0,0,0,40,4449,20.0503,57463.892578125,,,,,,,,,,,,,0,,,,,,,,,,,,,,
,19707040.18,20.0489,61217.1640625,-0.000151110176242357,6.02447980430913E-7,1,0.999253354069792,40.0298881530762,1.98179276800077,14.2500000074506,-0.00169361488798887,-0.000309586573429129,0.25,-3.72348888763383E-7,-0.000151107181009756,-1.49702517095053E-6,20.0489,20.0489,61212.23828125,61222.08984375,53.8971945435634,19.5635538654686,14.177031,0,0,0,40,4449,20.0489,61217.1640625,,,,,,,,,,,,,0,,,,,,,,,,,,,,
,19707113.365,20.0479,64875.755859375,-0.000161939368615878,7.56741347028903E-7,1,0.999253354069792,40.0298881530762,1.98182999844829,14.2500000074506,-0.00181516697313886,-0.000334418534434095,0.25,-6.26854338482386E-7,-0.00016198835476589,-1.83041449746119E-6,20.0479,20.0479,64870.7734375,64880.73828125,53.6204980477557,19.5635773533515,14.556682,0,0,0,40,4449,20.0479,64875.755859375,,,,,,,,,,,,,0,,,,,,,,,,,,,,
,19707186.875,20.047,68548.953125,-0.000174420616963968,7.07797956731028E-7,1,0.999253354069792,40.0298881530762,1.98180483762159,14.2400003969669,-0.00195402490411817,-0.00036945105053493,0.25,-1.49521882378125E-6,-0.000174523425513312,-2.78781211022655E-6,20.047,20.047,68539.015625,68558.890625,53.6040838488518,19.5625081504931,14.556682,0,0,0,40,4449,20.047,68548.953125,,,,,,,,,,,,,0,,,,,,,,,,,,,,
,19707260.195,20.045,72212.26171875,-0.000186606424335075,7.06091425436683E-7,1,0.999253354069792,40.0298881530762,1.98185075336418,14.2500000074506,-0.00209547902031104,-0.000371818586134343,0.25,4.93184746349412E-7,-0.000186789370019582,-8.81135384079327E-7,20.0452,20.0452,72207.34375,72217.1796875,54.0996363300442,19.5626618817329,14.556682,0,0,0,40,4449,20.045,72212.26171875,,,,,,,,,,,,,0,,,,,,,,,,,,,,
,19707334.51,20.0436,75928.0234375,-0.000199420166493955,5.60147232464315E-7,1,0.999253354069792,40.0298881530762,1.98178246630392,14.2400003969669,-0.00223680015761963,-0.000415022618335723,0.25,-1.04788855382765E-6,-0.000199663786177163,-2.50856600426244E-6,20.0436,20.0436,75920.5625,75935.484375,53.8143419205249,19.5616864196765,14.556682,0,0,0,40,4449,20.0436,75928.0234375,,,,,,,,,,,,,0,,,,,,,,,,,,,,
,19707407.6,20.0426,79581.3671875,-0.000211118013147695,6.76064161320265E-7,1,0.999253354069792,40.0298881530762,1.98176628135355,14.2400003969669,-0.00236923127983149,-0.000436288985802339,0.25,-8.37189777000093E-7,-0.000211437315090565,-2.37121843322539E-6,20.0426,20.0426,79574.015625,79588.71875,53.9565983110249,19.5621709042369,14.936333,0,0,0,40,4449,20.0426,79581.3671875,,,,,,,,,,,,,0,,,,,,,,,,,,,,
,19707484.045,20.0417,83405.2890625,-0.000223856005524128,5.96802218791867E-7,1,0.999253354069792,40.0298881530762,1.98174170858086,14.2400003969669,-0.00251505859022552,-0.000450488961114296,0.25,1.86687648223566E-7,-0.00022426515673141,-1.42270236951245E-6,20.0417,20.0417,83402.7421875,83407.8359375,53.8119970349672,19.5603567716942,14.556682,0,0,0,40,4449,20.0417,83405.2890625,,,,,,,,,,,,,0,,,,,,,,,,,,,,
,19707552.625,20.041,86831.24609375,-0.000236459317587991,7.56627719778999E-7,1,0.999253354069792,40.0298881530762,1.98171208531225,14.2400003969669,-0.00265253775253054,-0.00050217801791743,0.25,-2.15282214885146E-6,-0.000236931404198587,-3.84145476671231E-6,20.0412,20.0412,86801.03125,86861.4609375,54.2676864616788,19.561096349217,14.556682,0,0,0,40,4449,20.041,86831.24609375,,,,,,,,,,,,,0,,,,,,,,,,,,,,
,19707618.345,20.0406,89999.61328125,-0.000245876553840287,8.16760069414124E-7,1,0.999253354069792,40.0298881530762,1.9816733223996,14.2400003969669,-0.00275952352535309,-0.000517754133817642,0.25,-1.85298021025062E-6,-0.000246422414066957,-3.59179427998934E-6,20.0406,20.0406,89999.5859375,89999.640625,53.7150750985826,19.5633362826576,14.936333,0,0,0,40,4417,20.0406,89999.61328125,,,,,,,,,,,,,0,,,,,,,,,,,,,,