File: data/monolayers/magneticStructure/ML_Ac_CoFe_C/PPMS/data/DD205_4_HYST_100OE_100K.DAT
[Header]
; VSM Data File (default extension .dat)
; Copyright (c) 2003-2013, Quantum Design, Inc. All rights reserved.
TITLE,
FILEOPENTIME,32378414.45,01/11/2019,2:02 am
BYAPP,VSM,2.0,2.0
INFO,PPMS VSM Option Release 1.4.10 Build 1,APPNAME
INFO,Quantum Design Linear Motor Servo Controller,MOTOR_MODULE_NAME
INFO,3101-100 M1,MOTOR_HW_VERSION
INFO,MMC1014,MOTOR_SERIAL_NUMBER
INFO,SRV No X-over 01.03.11,MOTOR_SOFTWARE_VERSION
INFO,Quantum Design VSM Detection Module,VSM_MODULE_NAME
INFO,3101-150 F0,VSM_HW_VERSION
INFO,VSM707,VSM_SERIAL_NUMBER
INFO,VSM No X-over 01.02.05 May 20 2008 13:51:47,VSM_SOFTWARE_VERSION
INFO,704,PREAMP_SERIAL_NUMBER
INFO,822,COIL_SERIAL_NUMBER
INFO,0,MOMENT_UNITS
INFO,DD205_4,SAMPLE_MATERIAL
INFO,Monolayer,SAMPLE_COMMENT
INFO,29.55,SAMPLE_MASS
INFO,,SAMPLE_VOLUME
INFO,,SAMPLE_MOLECULAR_WEIGHT
INFO,,SAMPLE_SIZE
INFO,,SAMPLE_SHAPE
DATATYPE,COMMENT,1
DATATYPE,TIME,2
STARTUPAXIS,X,2
STARTUPAXIS,Y1,5
[Data]
Comment,Time Stamp (sec),Temperature (K),Magnetic Field (Oe),Moment (emu),M. Std. Err. (emu),Transport Action,Averaging Time (sec),Frequency (Hz),Peak Amplitude (mm),Center Position (mm),Coil Signal' (mV),Coil Signal" (mV),Range (mV),M. Quad. Signal (emu),M. Raw' (emu),M. Raw" (emu),Min. Temperature (K),Max. Temperature (K),Min. Field (Oe),Max. Field (Oe),Mass (grams),Motor Lag (deg),Pressure (Torr),VSM Status (code),Motor Status (code),Measure Status (code),Measure Count,PPMS Status (code),System Temp. (K),System Field (Oe),Sample Position (deg),Bridge 1 Resistance (ohms),Bridge 1 Excitation (에),Bridge 2 Resistance (ohms),Bridge 2 Excitation (에),Bridge 3 Resistance (ohms),Bridge 3 Excitation (에),Bridge 4 Resistance (ohms),Bridge 4 Excitation (에),Signal 1 Vin (V),Signal 2 Vin (V),Digital Inputs (code),Drive 1 Iout (mA),Drive 1 Ipower (W),Drive 2 Iout (mA),Drive 2 Ipower (W),Pressure (),Map 20 (),Map 21 (),Map 22 (),Map 23 (),Map 24 (),Map 25 (),Map 26 (),Map 27 (),Map 28 (),Map 29 ()
,32378430.59,100.0005493,-0.395818114280701,,,2,,,,21.019999474287,,,,,,,100.0005493,100.0005493,-0.395818114280701,-0.395818114280701,,,22.909004,,,,-99999999,4369,99.8993,-0.395818114280701,,,,,,,,,,,,,,,,,,,,,,,100.0005493,,,,
,32378601.655,99.9914398,5112.43505859375,1.95126296368967E-5,4.54448702780441E-7,1,0.999253354069792,40.0298881530762,1.99568269052248,21.0100002586842,0.000224226375771865,2.43685432442596E-5,0.25,-1.28432402124858E-6,1.9626446931925E-5,-1.23101130930881E-6,99.9914398,99.9914398,5104.92724609375,5119.94287109375,56.3515080939483,20.5047384405006,22.149702,0,0,0,40,4449,99.916,5112.43505859375,,,,,,,,,,,,,0,,,,0.0049,,,,,,99.9914398,,,,
,32378709.3,99.9953384,10491.5712890625,3.41791714900971E-6,4.31302990361772E-7,1,0.999253354069792,40.0298881530762,1.99568104125027,21.0100002586842,4.36864134346472E-5,-2.08240241486815E-5,0.25,-2.43375331203456E-6,3.44469217160487E-6,-2.43692369794376E-6,99.9953384,99.9953384,10481.7451171875,10501.3974609375,57.105779615006,20.5057354212392,22.529354,0,0,0,40,4449,99.91995,10491.5712890625,,,,,,,,,,,,,0,,,,0.00245,,,,,,99.9953384,,,,
,32378807.07,99.9970093,15376.6284179687,-1.20499646040244E-5,7.59844320214614E-7,1,0.999253354069792,40.0298881530762,1.9957358431096,21.0100002586842,-0.000132254194228641,-5.04542492202633E-5,0.25,-2.32378111334277E-6,-1.21108416155346E-5,-2.37388055851077E-6,99.9970093,99.9970093,15364.015625,15389.2412109375,57.0190188493714,20.5062979883553,22.529354,0,0,0,40,4449,99.9212,15376.6284179687,,,,,,,,,,,,,0,,,,-0.00245,,,,,,99.9970093,,,,
,32378899.335,100.00095745,19989.16796875,-2.67169197817774E-5,8.74593604709304E-7,1,0.999253354069792,40.0298881530762,1.99537953629449,21.0100002586842,-0.000297494580226965,-8.73161963882928E-5,0.25,-2.99292625219687E-6,-2.68587674364583E-5,-3.0914020291709E-6,100.0008163,100.0010986,19981.73828125,19996.59765625,56.7532651528329,20.5123502708739,22.909004,0,0,0,40,4449,99.91975,19989.16796875,,,,,,,,,,,,,0,,,,0.00245,,,,,,100.00095745,,,,
,32378971.055,100.00265885,23572.2421875,-4.02400039147338E-5,1.02760768217005E-6,1,0.999253354069792,40.0298881530762,1.99574399469612,21.0100002586842,-0.000449985515631507,-0.000121124769673346,0.25,-3.59191908197943E-6,-4.04567269377579E-5,-3.73455907566528E-6,100.002594,100.0027237,23564.8203125,23579.6640625,56.7985996069483,20.5059565146088,22.529354,0,0,0,40,4449,99.91625,23572.2421875,,,,,,,,,,,,,0,,,,-0.0049,,,,,,100.00265885,,,,
,32379045.49,100.0045776,27293.5634765625,-5.1232585044679E-5,9.95323701089056E-7,1,0.999253354069792,40.0298881530762,1.99534845096411,21.0100002586842,-0.000577668378069527,-0.000126508971446807,0.25,-2.13729709943398E-6,-5.15162623830296E-5,-2.30442261444171E-6,100.0045776,100.0045776,27288.466796875,27298.66015625,57.3027500018522,20.5153175200984,22.529354,0,0,0,40,4449,99.91365,27293.5634765625,,,,,,,,,,,,,0,,,,0,,,,,,100.0045776,,,,
,32379112.75,100.0039368,30656.490234375,-6.32340121035075E-5,1.28584995417291E-6,1,0.999253354069792,40.0298881530762,1.99578409319262,21.0100002586842,-0.000709624970269838,-0.000176201184831989,0.25,-4.40123608018878E-6,-6.3579224349906E-5,-4.61671117979234E-6,100.0039368,100.0039368,30641.55078125,30671.4296875,57.2699216040445,20.5100403380444,23.288654,0,0,0,40,4449,99.91155,30656.490234375,,,,,,,,,,,,,0,,,,0.00245,,,,,,100.0039368,,,,
,32379181.085,100.0055466,34069.841796875,-7.49337160697027E-5,1.2893039961225E-6,1,0.999253354069792,40.0298881530762,1.99591779124535,21.0100002586842,-0.000841317252153869,-0.000206901341225507,0.25,-5.04793714276384E-6,-7.53438035635652E-5,-5.30137586779877E-6,100.0055466,100.0055466,34064.73046875,34074.953125,56.8759808303522,20.5062352352467,22.909004,0,0,0,40,4449,99.90765,34069.841796875,,,,,,,,,,,,,0,,,,-0.0049,,,,,,100.0055466,,,,
,32379249.415,100.0069809,37485.576171875,-8.68458509070341E-5,1.40435216394464E-6,1,0.999253354069792,40.0298881530762,1.99589948861208,21.0100002586842,-0.000977874302023784,-0.000223759781517918,0.25,-4.44053195534021E-6,-8.7325922500562E-5,-4.72513155648205E-6,100.0069809,100.0069809,37478.02734375,37493.125,57.1354814987368,20.5070674760313,22.909004,0,0,0,40,4449,99.9036,37485.576171875,,,,,,,,,,,,,0,,,,-0.0049,,,,,,100.0069809,,,,
,32379316.43,100.0067368,40836.595703125,-9.79977162330658E-5,1.82796488107284E-6,1,0.999253354069792,40.0298881530762,1.99580113054474,21.0100002586842,-0.00110542503694176,-0.000240941171763262,0.25,-3.99619613331313E-6,-9.85430792055745E-5,-4.31031510134252E-6,100.0067368,100.0067368,40831.54296875,40841.6484375,57.268358347006,20.5094919805001,22.909004,0,0,0,40,4449,99.8989,40836.595703125,,,,,,,,,,,,,0,,,,0.0049,,,,,,100.0067368,,,,
,32379382.125,100.0074158,44119.560546875,-0.000112273612365332,1.65735341401547E-6,1,0.999253354069792,40.0298881530762,1.99581038958069,21.0100002586842,-0.00126089222149427,-0.000307817054231831,0.25,-7.37637153089409E-6,-0.000112890825424265,-7.7507535198517E-6,100.0074158,100.0074158,44114.57421875,44124.546875,56.7728058658137,20.5082196625,22.529354,0,0,0,40,4449,99.89305,44119.560546875,,,,,,,,,,,,,0,,,,-0.00245,,,,,,100.0074158,,,,
,32379448.625,100.0067139,47443.353515625,-0.000130998219947611,1.73961608988011E-6,1,0.999253354069792,40.0298881530762,1.99563561791799,21.0100002586842,-0.001461389099058,-0.000414235881016486,0.25,-1.34592089600195E-5,-0.000131704936051946,-1.39219889998006E-5,100.0067139,100.0067139,47433.43359375,47453.2734375,57.8186248245446,20.5242334997221,22.909004,0,0,0,40,4449,99.88955,47443.353515625,,,,,,,,,,,,,0,,,,0.00245,,,,,,100.0067139,,,,
,32379517.455,100.0067902,50881.724609375,-0.000134381174136106,2.12753482212672E-6,1,0.999253354069792,40.0298881530762,1.99574873244992,21.0100002586842,-0.00151089432929812,-0.000358473361324534,0.25,-7.9567534409973E-6,-0.000135124284510402,-8.39635812003409E-6,100.0067902,100.0067902,50876.84765625,50886.6015625,56.8853603725829,20.5117611218657,22.909004,0,0,0,40,4449,99.88385,50881.724609375,,,,,,,,,,,,,0,,,,0,,,,,,100.0067902,,,,
,32379586.305,100.0069084,54325.05078125,-0.000148348505779975,1.96887319398682E-6,1,0.999253354069792,40.0298881530762,1.99568645523265,21.0100002586842,-0.00166884594861876,-0.000390308632149814,0.25,-8.30922068546067E-6,-0.000149171237038131,-8.78981153887828E-6,100.0067291,100.0070877,54315.0625,54335.0390625,56.9338213407753,20.5110158802442,23.288654,0,0,0,40,4449,99.8784,54325.05078125,,,,,,,,,,,,,0,,,,0.00245,,,,,,100.0069084,,,,
,32379653.895,100.0087738,57703.12890625,-0.000160069638931996,1.86785702897217E-6,1,0.999253354069792,40.0298881530762,1.99556020322044,21.0100002586842,-0.00180786434460405,-0.000379777328695296,0.25,-5.32840227340732E-6,-0.00016096899108431,-5.82404550881946E-6,100.0087738,100.0087738,57698.12109375,57708.13671875,57.2066096939868,20.5111532399949,22.909004,0,0,0,40,4449,99.8739,57703.12890625,,,,,,,,,,,,,0,,,,0,,,,,,100.0087738,,,,
,32379721.835,100.0071869,61099.1328125,-0.000172943586738289,1.54992801332674E-6,1,0.999253354069792,40.0298881530762,1.99561868239862,21.0100002586842,-0.00195509523923506,-0.0004002942661685,0.25,-4.87546126144666E-6,-0.000173918910751769,-5.40358447559129E-6,100.0071869,100.0071869,61091.9375,61106.328125,57.1081245005637,20.5107279332681,22.909004,0,0,0,40,4449,99.86885,61099.1328125,,,,,,,,,,,,,0,,,,0,,,,,,100.0071869,,,,
,32379789.525,100.0086441,64480.607421875,-0.000186354460606771,2.32051190710002E-6,1,0.999253354069792,40.0298881530762,1.99571748823718,21.0100002586842,-0.00209814859536495,-0.000480731786870655,0.25,-9.60171504600481E-6,-0.000187394037855487,-1.0193174158271E-5,100.0086441,100.0086441,64475.34375,64485.87109375,57.1417345268907,20.5101545657995,22.529354,0,0,0,40,4449,99.86335,64480.607421875,,,,,,,,,,,,,0,,,,-0.00245,,,,,,100.0086441,,,,
,32379857.35,100.0079651,67871.46875,-0.000198185452502625,2.25766601222799E-6,1,0.999253354069792,40.0298881530762,1.99566015102573,21.0100002586842,-0.00222836800909902,-0.000527979323054556,0.25,-1.16872653291626E-5,-0.00019928808240225,-1.23220732553997E-5,100.0079651,100.0079651,67863.8359375,67879.1015625,56.9267866841022,20.5140664735295,22.909004,0,0,0,40,4449,99.85765,67871.46875,,,,,,,,,,,,,0,,,,0,,,,,,100.0079651,,,,
,32379925.16,100.0079727,71259.78125,-0.000212959342313496,2.32649060169696E-6,1,0.999253354069792,40.0298881530762,1.99565924938491,21.0100002586842,-0.0023967917504273,-0.000554271561875793,0.25,-1.14110936717917E-5,-0.000214148844476777,-1.20837575051967E-5,100.0079727,100.0079727,71252.28125,71267.28125,57.2886806885061,20.5127862133509,23.288654,0,0,0,40,4449,99.85505,71259.78125,,,,,,,,,,,,,0,,,,0.0049,,,,,,100.0079727,,,,
,32379992.025,100.0071869,74603.30078125,-0.000226136773399303,2.45513084299398E-6,1,0.999253354069792,40.0298881530762,1.99563298633191,21.0100002586842,-0.00254723254263862,-0.000576320116278913,0.25,-1.10425150667704E-5,-0.000227404373606568,-1.1747615084681E-5,100.0071869,100.0071869,74595.640625,74610.9609375,56.8509687177368,20.5143162654661,22.909004,0,0,0,40,4449,99.85105,74603.30078125,,,,,,,,,,,,,0,,,,0,,,,,,100.0071869,,,,
,32380060.61,100.0070267,78031.91796875,-0.000239586301470302,2.21308457578066E-6,1,0.999253354069792,40.0298881530762,1.99571978531776,21.0100002586842,-0.00271562608941437,-0.000515069481623627,0.25,-3.29244121052488E-6,-0.000240954567670019,-3.98786974018516E-6,100.0070267,100.0070267,78019.65625,78044.1796875,57.119067299833,20.5086116462055,22.909004,0,0,0,40,4449,99.8459,78031.91796875,,,,,,,,,,,,,0,,,,-0.00245,,,,,,100.0070267,,,,
,32380129.085,100.005928,81456.03125,-0.000250396815820556,2.67724235683735E-6,1,0.999253354069792,40.0298881530762,1.99571532257043,21.0100002586842,-0.00282716620858107,-0.000601027945650696,0.25,-8.96419965268125E-6,-0.000251812784366394,-9.71932488714606E-6,100.005928,100.005928,81453.6015625,81458.4609375,57.2386564632753,20.5112776998647,22.909004,0,0,0,40,4449,99.84155,81456.03125,,,,,,,,,,,,,0,,,,-0.0049,,,,,,100.005928,,,,
,32380196.55,100.0044708,84827.3984375,-0.000264250917460819,2.19384775589345E-6,1,0.999253354069792,40.0298881530762,1.99560326885302,21.0100002586842,-0.00298261819066764,-0.000638978469091905,0.25,-9.87981514238456E-6,-0.000265745671597442,-1.0675560852165E-5,100.0044708,100.0044708,84817.296875,84837.5,56.8204852054868,20.5113520989253,22.909004,0,0,0,40,4449,99.83785,84827.3984375,,,,,,,,,,,,,0,,,,0.00245,,,,,,100.0044708,,,,
,32380266.03,100.0063248,88300.69921875,-0.000275444863463652,2.44351595677896E-6,1,0.999253354069792,40.0298881530762,1.995542669839,21.0100002586842,-0.0031061360490303,-0.000681752859372859,0.25,-1.16860268513181E-5,-0.000277000794041956,-1.25196329965612E-5,100.0063248,100.0063248,88295.65625,88305.7421875,56.9658681100637,20.5112337666632,22.529354,0,0,0,40,4449,99.8354,88300.69921875,,,,,,,,,,,,,0,,,,0,,,,,,100.0063248,,,,
,32380348.255,100.0051422,88545.08984375,-0.000276085339988777,2.50931603861006E-6,1,0.999253354069792,40.0298881530762,1.99541623180401,21.0100002586842,-0.00312828659337115,-0.000597134938263248,0.25,-4.1292004218955E-6,-0.000277666094084427,-4.92076686644328E-6,100.0051422,100.0051422,88542.6015625,88547.578125,57.1081245005637,20.515596135961,23.288654,0,0,0,40,4449,99.8326,88545.08984375,,,,,,,,,,,,,0,,,,0,,,,,,100.0051422,,,,
,32380413.845,100.0018158,85266.58203125,-0.00026646229989831,2.56033853280731E-6,1,0.999253354069792,40.0298881530762,1.9954451836429,21.0100002586842,-0.00301562500567674,-0.000597127254533895,0.25,-5.81262594945759E-6,-0.00026798135612211,-6.59071577745728E-6,100.0018158,100.0018158,85258.859375,85274.3046875,56.9455457685637,20.5164308117156,22.909004,0,0,0,40,4449,99.83175,85266.58203125,,,,,,,,,,,,,0,,,,-0.0049,,,,,,100.0018158,,,,
,32380481.5,99.99946595,81885.00390625,-0.000252500311989864,1.89234406631216E-6,1,0.999253354069792,40.0298881530762,1.99544647652603,21.0100002586842,-0.00286066712353713,-0.000548347621036842,0.25,-3.96518369147079E-6,-0.0002539426255674,-4.69707529207157E-6,99.9992142,99.9997177,81874.890625,81895.1171875,57.4582940771792,20.5138147965952,22.909004,0,0,0,40,4449,99.8351,81885.00390625,,,,,,,,,,,,,0,,,,-0.00245,,,,,,99.99946595,,,,
,32380549.645,99.9966354,78478.14453125,-0.000236729868502352,2.56493150252188E-6,1,0.999253354069792,40.0298881530762,1.99532290562757,21.0100002586842,-0.00268360315272822,-0.00050392646578185,0.25,-2.82166133671532E-6,-0.000238083236768797,-3.50597560398428E-6,99.9966354,99.9966354,78470.7109375,78485.578125,56.8486238321791,20.520359899683,22.909004,0,0,0,40,4449,99.8372,78478.14453125,,,,,,,,,,,,,0,,,,-0.00245,,,,,,99.9966354,,,,
,32380620.39,99.995903,74941.3046875,-0.000226915200010859,1.94324774102364E-6,1,0.999253354069792,40.0298881530762,1.99533800101006,21.0100002586842,-0.00257151454170594,-0.00048777103593882,0.25,-3.11834949219978E-6,-0.000228209895930157,-3.77994199920356E-6,99.995903,99.995903,74936.109375,74946.5,56.9322580837368,20.5194575264714,22.909004,0,0,0,40,4449,99.8398,74941.3046875,,,,,,,,,,,,,0,,,,0,,,,,,99.995903,,,,
,32380694.985,99.9960938,71212.98046875,-0.000208776902421873,2.11234268918216E-6,1,0.999253354069792,40.0298881530762,1.99549433453953,21.0100002586842,-0.0023622006080289,-0.000471168287364239,0.25,-4.83377378489207E-6,-0.000209961138164057,-5.45693076757711E-6,99.9960938,99.9960938,71207.84375,71218.1171875,57.2636685758907,20.5180534534373,22.909004,0,0,0,40,4449,99.84235,71212.98046875,,,,,,,,,,,,,0,,,,-0.00245,,,,,,99.9960938,,,,
,32380762.19,99.9955597,67854.58984375,-0.000196858269773798,1.53415769146111E-6,1,0.999253354069792,40.0298881530762,1.99521115425252,21.0100002586842,-0.0022297712637996,-0.000428602435731105,0.25,-3.18129117448466E-6,-0.000197977640398187,-3.76370091287178E-6,99.9955597,99.9955597,67849.5859375,67859.59375,57.0213637349291,20.5190809783103,23.288654,0,0,0,40,4449,99.8409,67854.58984375,,,,,,,,,,,,,0,,,,0.00245,,,,,,99.9955597,,,,
,32380837.505,99.9965744,64088.4453125,-0.000182941708708928,1.75930588119679E-6,1,0.999253354069792,40.0298881530762,1.9955221173621,21.0100002586842,-0.00207371452401029,-0.000391075171423586,0.25,-2.31237873702803E-6,-0.000183982573675466,-2.852725105558E-6,99.9965744,99.9965744,64075.8671875,64101.0234375,57.0917103016599,20.5149993798462,23.288654,0,0,0,40,4449,99.8443,64088.4453125,,,,,,,,,,,,,0,,,,-0.00245,,,,,,99.9965744,,,,
,32380914.28,99.9942398,60252.41796875,-0.00017110633443559,2.03640180040884E-6,1,0.999253354069792,40.0298881530762,1.99527306905855,21.0100002586842,-0.00193595680285816,-0.000384842065034315,0.25,-3.84276739422792E-6,-0.000172073841790306,-4.36042308342153E-6,99.9942398,99.9942398,60247.80859375,60257.02734375,57.0119841926983,20.5202961057447,22.909004,0,0,0,40,4449,99.84845,60252.41796875,,,,,,,,,,,,,0,,,,-0.0049,,,,,,99.9942398,,,,
,32381003.235,99.993515,55804.068359375,-0.000154333376041189,1.74876335500918E-6,1,0.999253354069792,40.0298881530762,1.99542936286708,21.0100002586842,-0.00174523750912782,-0.000353183287134773,0.25,-3.99524463329851E-6,-0.000155203259275211,-4.46793212706083E-6,99.993515,99.993515,55798.9921875,55809.14453125,57.0666981890445,20.5184592485958,22.909004,0,0,0,40,4449,99.85425,55804.068359375,,,,,,,,,,,,,0,,,,0,,,,,,99.993515,,,,
,32381097.335,99.99494555,51103.923828125,-0.000135038043499259,1.53072282367806E-6,1,0.999253354069792,40.0298881530762,1.99516677514425,21.0100002586842,-0.00152607451742608,-0.000313325749296104,0.25,-3.87530831031737E-6,-0.00013579689039665,-4.29359806294246E-6,99.9945755,99.9953156,51091.3203125,51116.52734375,57.3746598256215,20.5221605450458,23.288654,0,0,0,40,4449,99.8596,51103.923828125,,,,,,,,,,,,,0,,,,0,,,,,,99.99494555,,,,
,32381195.19,99.9923325,46211.412109375,-0.00011944160058471,1.74416912921236E-6,1,0.999253354069792,40.0298881530762,1.99571166373786,21.0100002586842,-0.00134600976591799,-0.000300830031447878,0.25,-5.50463798435401E-6,-0.000120105600784583,-5.88875424414307E-6,99.9923325,99.9923325,46203.4765625,46219.34765625,57.332451885583,20.5177647772471,22.909004,0,0,0,40,4449,99.8663,46211.412109375,,,,,,,,,,,,,0,,,,-0.00245,,,,,,99.9923325,,,,
,32381280.305,99.992836,41955.6640625,-0.000104190478951686,1.26208359254464E-6,1,0.999253354069792,40.0298881530762,1.99547946947637,21.0100002586842,-0.00117133050999433,-0.000277599567653239,0.25,-6.13919557433736E-6,-0.000104764874445169,-6.48360009798894E-6,99.992836,99.992836,41950.6796875,41960.6484375,57.2910255740638,20.5192273646722,23.288654,0,0,0,40,4449,99.87135,41955.6640625,,,,,,,,,,,,,0,,,,0.00245,,,,,,99.992836,,,,
,32381382.015,99.9917374,36873.51171875,-8.47316066430036E-5,1.67130938422932E-6,1,0.999253354069792,40.0298881530762,1.99553262280217,21.0100002586842,-0.00095005632999607,-0.000240153737029475,0.25,-6.25818091280174E-6,-8.51941034987587E-5,-6.54710073663312E-6,99.9917374,99.9917374,36858.46484375,36888.55859375,57.1651833824676,20.5197799736079,23.668306,0,0,0,40,4449,99.8774,36873.51171875,,,,,,,,,,,,,0,,,,0.00245,,,,,,99.9917374,,,,
,32381486.4,99.9907379,31656.3974609375,-6.71028447641809E-5,1.12554058956979E-6,1,0.999253354069792,40.0298881530762,1.99536295300814,21.0100002586842,-0.000754825427980313,-0.000175933902474757,0.25,-3.70136820540576E-6,-6.74722042156944E-5,-3.92436189108613E-6,99.9907379,99.9907379,31651.33984375,31661.455078125,56.8056342636214,20.5214791903401,22.909004,0,0,0,40,4449,99.88695,31656.3974609375,,,,,,,,,,,,,0,,,,-0.0049,,,,,,99.9907379,,,,
,32381590.84,99.9928818,26436.015625,-4.86283127696091E-5,1.40207114749621E-6,1,0.999253354069792,40.0298881530762,1.99531467249287,21.0100002586842,-0.000545249341031591,-0.000137408340962512,0.25,-3.55438489791619E-6,-4.88928583454457E-5,-3.72185601394242E-6,99.9928818,99.9928818,26423.677734375,26448.353515625,57.3785679682176,20.5252548358872,23.288654,0,0,0,40,4449,99.8949,26436.015625,,,,,,,,,,,,,0,,,,0,,,,,,99.9928818,,,,
,32381695.21,99.9915771,21221.2060546875,-3.12035737499103E-5,6.23117222451179E-7,1,0.999253354069792,40.0298881530762,1.99539401667516,21.0100002586842,-0.000348060889267059,-9.85429843564712E-5,0.25,-3.19302879829589E-6,-3.1370234694148E-5,-3.30622452979577E-6,99.9915771,99.9915771,21216.31640625,21226.095703125,57.3590272552368,20.5208839926723,23.668306,0,0,0,40,4449,99.9032,21221.2060546875,,,,,,,,,,,,,0,,,,0.00245,,,,,,99.9915771,,,,
,32381802.55,99.9917831,15854.47265625,-1.26205071685676E-5,8.84281960973711E-7,1,0.999253354069792,40.0298881530762,1.99560455147655,21.0100002586842,-0.000138532421406969,-5.26985862820753E-5,0.25,-2.42138372737865E-6,-1.26843152762876E-5,-2.47377242790653E-6,99.9917831,99.9917831,15844.560546875,15864.384765625,57.0338697912368,20.5195954083459,23.288654,0,0,0,40,4449,99.91095,15854.47265625,,,,,,,,,,,,,0,,,,0,,,,,,99.9917831,,,,
,32381908.57,99.991188,10557.5595703125,5.58851229802847E-6,4.75503946884769E-7,1,0.999253354069792,40.0298881530762,1.99539163386432,21.0100002586842,6.75416490884036E-5,-1.19739318290108E-5,0.25,-2.03630038264574E-6,5.62629576252897E-6,-2.03053363768078E-6,99.991188,99.991188,10552.4365234375,10562.6826171875,57.1948852661984,20.52041801824,23.668306,0,0,0,40,4449,99.919,10557.5595703125,,,,,,,,,,,,,0,,,,0,,,,,,99.991188,,,,
,32382014.645,99.9928665,5254.85668945313,2.17098493417794E-5,4.08031649337321E-7,1,0.999253354069792,40.0298881530762,1.99579698749857,21.0100002586842,0.000248718461423799,3.14989557347096E-5,0.25,-1.04294511391676E-6,2.18352948456896E-5,-9.81481498127857E-7,99.9928665,99.9928665,5244.9482421875,5264.76513671875,57.119067299833,20.5184613653294,23.668306,0,0,0,40,4449,99.92925,5254.85668945313,,,,,,,,,,,,,0,,,,-0.0049,,,,,,99.9928665,,,,
,32382122.045,99.9936676,-113.743392944336,3.5391314228997E-5,3.43359152811629E-7,1,0.999253354069792,40.0298881530762,1.99563453787838,21.0100002586842,0.000402862827535747,6.59299742119606E-5,0.25,-4.16727412374121E-7,3.55916373273045E-5,-3.08864334376102E-7,99.9936676,99.9936676,-128.787734985352,-98.6990509033203,57.6552644640253,20.5214073834385,23.288654,0,0,0,40,4449,99.9319,-113.743392944336,,,,,,,,,,,,,0,,,,0.00245,,,,,,99.9936676,,,,
,32382230.525,99.9967804,-5532.865234375,4.33279694345723E-5,4.90342163493072E-7,1,0.999253354069792,40.0298881530762,1.99537628634487,21.0100002586842,0.000490869352073642,9.36735684772481E-5,0.25,6.32119970956925E-7,4.35699310733101E-5,7.70019789735586E-7,99.9967804,99.9967804,-5542.82763671875,-5522.90283203125,57.1745629246983,20.5241520431306,22.909004,0,0,0,40,4449,99.93295,-5532.865234375,,,,,,,,,,,,,0,,,,-0.00735,,,,,,99.9967804,,,,
,32382321.345,100.0018692,-10073.943359375,4.24927423193258E-5,4.32357369034947E-7,1,0.999253354069792,40.0298881530762,1.99538799454011,21.0100002586842,0.000479993664668551,9.99437866417136E-5,0.25,1.33143985528422E-6,4.27281206679402E-5,1.47009895170301E-6,100.0018692,100.0018692,-10076.791015625,-10071.095703125,57.1636201254291,20.5216230498581,23.288654,0,0,0,40,4449,99.9329,-10073.943359375,,,,,,,,,,,,,0,,,,0.00245,,,,,,100.0018692,,,,
,32382393.085,100.0072174,-13659.6225585938,3.76809663193034E-5,7.08495927007981E-7,1,0.999253354069792,40.0298881530762,1.99547235836794,21.0100002586842,0.000424422218297747,9.56733011590853E-5,0.25,1.80113066293161E-6,3.78879914076818E-5,1.9271578096594E-6,100.0072174,100.0072174,-13669.58984375,-13649.6552734375,57.393418910083,20.5202832508788,22.909004,0,0,0,40,4449,99.92565,-13659.6225585938,,,,,,,,,,,,,0,,,,0,,,,,,100.0072174,,,,
,32382483.735,100.0079193,-18189.82421875,3.64403636518532E-5,9.37096188594544E-7,1,0.999253354069792,40.0298881530762,1.99609087265452,21.0100002586842,0.000407566387891465,0.000109663569324595,0.25,3.24841816808246E-6,3.66362458400559E-5,3.3782523554959E-6,100.0079193,100.0079193,-18197.47265625,-18182.17578125,57.7943943404484,20.517903810637,23.288654,0,0,0,40,4449,99.918,-18189.82421875,,,,,,,,,,,,,0,,,,0,,,,,,100.0079193,,,,
,32382574.975,100.0117569,-22750.115234375,4.43834905929294E-5,1.22095242875944E-6,1,0.999253354069792,40.0298881530762,1.99616229543195,21.0100002586842,0.000493372520724304,0.000150960145286428,0.25,5.48734950000269E-6,4.46177948044011E-5,5.65345306671997E-6,100.0117569,100.0117569,-22759.66796875,-22740.5625,57.0596635323714,20.5191057997676,23.288654,0,0,0,40,4449,99.90795,-22750.115234375,,,,,,,,,,,,,0,,,,-0.00245,,,,,,100.0117569,,,,
,32382684.14,100.01091,-28203.9677734375,5.78821443961992E-5,1.36883588939951E-6,1,0.999253354069792,40.0298881530762,1.9960283508859,21.0100002586842,0.000649994351547067,0.000159275728956422,0.25,3.84944054361328E-6,5.81983702149523E-5,4.04623359445409E-6,100.01091,100.01091,-28216.19921875,-28191.736328125,57.7303008018715,20.5179506761706,22.909004,0,0,0,40,4449,99.8975,-28203.9677734375,,,,,,,,,,,,,0,,,,0,,,,,,100.01091,,,,
,32382772.725,100.0094528,-32631.7607421875,7.31257572372391E-5,1.65145243874253E-6,1,0.999253354069792,40.0298881530762,1.99597691604229,21.0100002586842,0.000820746737809649,0.000203577492664136,0.25,5.07203995467264E-6,7.35252634119222E-5,5.32065312125374E-6,100.0094528,100.0094528,-32644.275390625,-32619.24609375,57.3840393678522,20.5173248952751,22.909004,0,0,0,40,4449,99.89035,-32631.7607421875,,,,,,,,,,,,,0,,,,0.00245,,,,,,100.0094528,,,,
,32382865.695,100.0097504,-37279.19921875,8.81272624035547E-5,1.81787738965399E-6,1,0.999253354069792,40.0298881530762,1.99593101081267,21.0100002586842,0.000985298358981079,0.000267024294257584,0.25,8.02282196366305E-6,8.86038194097411E-5,8.33176024618413E-6,100.0097504,100.0097504,-37291.65625,-37266.7421875,57.3082214014868,20.519856902901,23.668306,0,0,0,40,4449,99.8817,-37279.19921875,,,,,,,,,,,,,0,,,,0,,,,,,100.0097504,,,,
,32382970.485,100.0102081,-42516.048828125,0.000105933634563832,1.75175074047854E-6,1,0.999253354069792,40.0298881530762,1.9957082605931,21.0100002586842,0.00119294136855172,0.000271553759516594,0.25,5.29843742443606E-6,0.000106520510453945,5.64302145587399E-6,100.0102081,100.0102081,-42523.80859375,-42508.2890625,56.8908317722176,20.5238985825984,23.668306,0,0,0,40,4449,99.8676,-42516.048828125,,,,,,,,,,,,,0,,,,0,,,,,,100.0102081,,,,
,32383079.04,100.01068875,-47940.4375,0.000124930805716032,1.56706110875726E-6,1,0.999253354069792,40.0298881530762,1.99579255700492,21.0100002586842,0.0014041686369117,0.000336072576182004,0.25,7.64236600426063E-6,0.000125620126885529,8.0540385068233E-6,100.0106277,100.0107498,-47954.96484375,-47925.91015625,57.647448178833,20.5279222563233,22.909004,0,0,0,40,4449,99.86205,-47940.4375,,,,,,,,,,,,,0,,,,0,,,,,,100.01068875,,,,
,32383189.705,100.0114136,-53472.212890625,0.000144403528667387,2.00496442897746E-6,1,0.999253354069792,40.0298881530762,1.99570159676159,21.0100002586842,0.00162490031123938,0.000377506860936717,0.25,7.87415802307991E-6,0.000145204645286528,8.34145010682182E-6,100.0114136,100.0114136,-53481.921875,-53462.50390625,56.8830154870253,20.5273798077894,22.909004,0,0,0,40,4449,99.8471,-53472.212890625,,,,,,,,,,,,,0,,,,0,,,,,,100.0114136,,,,
,32383299.835,100.0106163,-58974.46484375,0.000165076139309753,1.6301308396852E-6,1,0.999253354069792,40.0298881530762,1.99591932141052,21.0100002586842,0.00185685413163363,0.000436598676234477,0.25,9.44499553344297E-6,0.000165992405746097,9.97816686159209E-6,100.0104141,100.0108185,-58989.359375,-58959.5703125,57.220679007333,20.5226992088372,23.288654,0,0,0,40,4449,99.8355,-58974.46484375,,,,,,,,,,,,,0,,,,-0.00245,,,,,,100.0106163,,,,
,32383411.235,100.009346,-64544.416015625,0.000184156724229285,1.98031318369403E-6,1,0.999253354069792,40.0298881530762,1.99562237999093,21.0100002586842,0.00207481533261274,0.000466457337399014,0.25,8.73274055418616E-6,0.000185186092761262,9.31315118525387E-6,100.009346,100.009346,-64557.046875,-64531.78515625,57.6740235484869,20.5283136316511,23.668306,0,0,0,40,4449,99.82735,-64544.416015625,,,,,,,,,,,,,0,,,,0.0049,,,,,,100.009346,,,,
,32383521.85,100.0095062,-70073.390625,0.000206113046481389,2.04316137102992E-6,1,0.999253354069792,40.0298881530762,1.99552052069019,21.0100002586842,0.00232994926837777,0.000477319582551912,0.25,5.84112863192978E-6,0.000207278532134097,6.46365473155828E-6,100.0095062,100.0095062,-70088.3359375,-70058.4453125,57.2339666921599,20.5287216332884,23.288654,0,0,0,40,4449,99.81785,-70073.390625,,,,,,,,,,,,,0,,,,0.00245,,,,,,100.0095062,,,,
,32383632.27,100.0090179,-75590.05078125,0.000229884148195188,2.48032262982792E-6,1,0.999253354069792,40.0298881530762,1.99573792113898,21.0100002586842,0.0025947467690763,0.000556433495995213,0.25,8.632553400756E-6,0.000231180328371055,9.3339506888959E-6,100.0090179,100.0090179,-75600.03125,-75580.0703125,57.0901470446214,20.5278225480405,23.288654,0,0,0,40,4449,99.80885,-75590.05078125,,,,,,,,,,,,,0,,,,0,,,,,,100.0090179,,,,
,32383743.14,100.0067444,-81132.34765625,0.000248933099930604,2.18396197148803E-6,1,0.999253354069792,40.0298881530762,1.99552095349637,21.0100002586842,0.00282113288629607,0.000536143931673518,0.25,3.51417155956613E-6,0.000250355642467865,4.23454651945582E-6,100.0067444,100.0067444,-81137.328125,-81127.3671875,57.4668919908907,20.5299943574646,22.909004,0,0,0,40,4449,99.80505,-81132.34765625,,,,,,,,,,,,,0,,,,0,,,,,,100.0067444,,,,
,32383853.22,100.0068207,-86633.34375,0.000269798432146152,2.47804145709133E-6,1,0.999253354069792,40.0298881530762,1.99577841447133,21.0100002586842,0.00304532262071071,0.000653436637380826,0.25,1.01756704793186E-5,0.000271324983932707,1.09871231327587E-5,100.0068207,100.0068207,-86643.15625,-86623.53125,57.1268835850253,20.5288581473353,22.909004,0,0,0,40,4449,99.79725,-86633.34375,,,,,,,,,,,,,0,,,,-0.0049,,,,,,100.0068207,,,,
,32383985.115,100.004982,-88187.79296875,0.000273922804264227,2.0111666020532E-6,1,0.999253354069792,40.0298881530762,1.9958906717108,21.0100002586842,0.00308643325121737,0.000695482590349305,0.25,1.31507094231703E-5,0.000275465590948244,1.39891794223711E-5,100.004982,100.004982,-88193.0546875,-88182.53125,57.065134932006,20.528661814834,23.288654,0,0,0,40,4449,99.7901,-88187.79296875,,,,,,,,,,,,,0,,,,0.0049,,,,,,100.004982,,,,
,32384091.775,99.9993134,-82858.828125,0.00025485803280206,2.43614681880147E-6,1,0.999253354069792,40.0298881530762,1.9956346976796,21.0100002586842,0.00287273904518555,0.000638453851425181,0.25,1.14783630397299E-5,0.000256293064659795,1.22595934566943E-5,99.9993134,99.9993134,-82866.421875,-82851.234375,57.0573186468137,20.5301656885985,22.909004,0,0,0,40,4449,99.7919,-82858.828125,,,,,,,,,,,,,0,,,,0.00245,,,,,,99.9993134,,,,
,32384201.54,99.9970856,-77374.2890625,0.000229365519380593,2.15458332859879E-6,1,0.999253354069792,40.0298881530762,1.99582020849787,21.0100002586842,0.00258865969598856,0.000557160080222498,0.25,8.78698831595194E-6,0.000230659047460925,9.48625607970151E-6,99.9970856,99.9970856,-77384.40625,-77364.171875,57.5950790680446,20.5276414642592,23.288654,0,0,0,40,4449,99.79725,-77374.2890625,,,,,,,,,,,,,0,,,,-0.00245,,,,,,99.9970856,,,,
,32384314.625,99.9957886,-71722.83203125,0.00021331896973582,2.38029367096334E-6,1,0.999253354069792,40.0298881530762,1.99570845347641,21.0100002586842,0.00240298894122684,0.000543293287167759,0.25,1.03804665004547E-5,0.000214513471563757,1.10483637474341E-5,99.9957886,99.9957886,-71732.796875,-71712.8671875,57.5231692442753,20.5376924817131,23.288654,0,0,0,40,4449,99.8005,-71722.83203125,,,,,,,,,,,,,0,,,,-0.00245,,,,,,99.9957886,,,,
,32384424.18,99.99619295,-66245.73046875,0.00019462550842778,2.4236793044646E-6,1,0.999253354069792,40.0298881530762,1.99571297662739,21.0100002586842,0.00219246042424026,0.000495298065138673,0.25,9.4328631739408E-6,0.000195713403907251,1.00462996174911E-5,99.996109,99.9962769,-66250.59375,-66240.8671875,57.3027500018522,20.5311312647922,23.668306,0,0,0,40,4449,99.8045,-66245.73046875,,,,,,,,,,,,,0,,,,0,,,,,,99.99619295,,,,
,32384535.77,99.9935684,-60669.00390625,0.000169873578266875,2.12077466290797E-6,1,0.999253354069792,40.0298881530762,1.99579072020862,21.0100002586842,0.00191522343440069,0.000423529687187687,0.25,7.45579899950909E-6,0.000170823569994167,7.9905497714849E-6,99.9935684,99.9935684,-60684.09765625,-60653.91015625,57.4387533641984,20.5272348872411,23.288654,0,0,0,40,4449,99.81185,-60669.00390625,,,,,,,,,,,,,0,,,,-0.00245,,,,,,99.9935684,,,,
,32384644.03,99.9945526,-55257.103515625,0.00015306465243306,2.43206653854539E-6,1,0.999253354069792,40.0298881530762,1.99576269225525,21.0100002586842,0.00172369177813645,0.000392891648713075,0.25,7.70741841958865E-6,0.000153916169978503,8.19821628506079E-6,99.9945526,99.9945526,-55267.078125,-55247.12890625,57.2964969736984,20.5263156088284,23.288654,0,0,0,40,4449,99.8167,-55257.103515625,,,,,,,,,,,,,0,,,,-0.00245,,,,,,99.9945526,,,,
,32384754.35,99.9946289,-49746.005859375,0.000132743635256737,1.70694170439821E-6,1,0.999253354069792,40.0298881530762,1.99601487604195,21.0100002586842,0.00149099186437643,0.000363693570522037,0.25,8.69877603054437E-6,0.000133474765681263,9.13878570902495E-6,99.9946289,99.9946289,-49751.21484375,-49740.796875,57.4786164186792,20.5233111743409,23.288654,0,0,0,40,4449,99.8237,-49746.005859375,,,,,,,,,,,,,0,,,,0,,,,,,99.9946289,,,,
,32384863.34,99.9936447,-44298.01953125,0.000114112210171584,1.70924738313779E-6,1,0.999253354069792,40.0298881530762,1.9960451714769,21.0100002586842,0.00127822656805095,0.000332577235246859,0.25,9.22924881340863E-6,0.000114734296101073,9.61988423209436E-6,99.9936447,99.9936447,-44303.01953125,-44293.01953125,57.4817429327561,20.5287860864587,23.668306,0,0,0,40,4449,99.83055,-44298.01953125,,,,,,,,,,,,,0,,,,-0.00245,,,,,,99.9936447,,,,
,32384973.865,99.9929504,-38774.056640625,9.7039832393877E-5,1.77335955809616E-6,1,0.999253354069792,40.0298881530762,1.99609904428208,21.0100002586842,0.00108335219992357,0.000303629786401461,0.25,9.67730471196874E-6,9.75622899920271E-5,1.00219400414059E-5,99.9929504,99.9929504,-38786.6875,-38761.42578125,57.1644017539484,20.5258412345284,22.909004,0,0,0,40,4449,99.83605,-38774.056640625,,,,,,,,,,,,,0,,,,-0.0049,,,,,,99.9929504,,,,
,32385083.755,99.9918747,-33279.962890625,7.52965359162312E-5,1.87117981510347E-6,1,0.999253354069792,40.0298881530762,1.99601808275955,21.0100002586842,0.000840393299619743,0.000236580088066942,0.25,7.5949240042041E-6,7.57008090652982E-5,7.86435435200157E-6,99.9918747,99.9918747,-33294.859375,-33265.06640625,57.1526773261599,20.5207263738202,23.668306,0,0,0,40,4449,99.8464,-33279.962890625,,,,,,,,,,,,,0,,,,0,,,,,,99.9918747,,,,
,32385190.055,99.9911957,-27967.90625,5.90462485553794E-5,1.29553981367474E-6,1,0.999253354069792,40.0298881530762,1.99614558224995,21.0100002586842,0.000656570750034679,0.000199672243913804,0.25,7.19908030452781E-6,5.93588610250708E-5,7.41854389582416E-6,99.9911957,99.9911957,-27972.830078125,-27962.982421875,57.1425161554099,20.530823490023,23.288654,0,0,0,40,4449,99.8545,-27967.90625,,,,,,,,,,,,,0,,,,0.00245,,,,,,99.9911957,,,,
,32385298.98,99.9897614,-22523.39453125,3.62513237721982E-5,1.27277044414137E-6,1,0.999253354069792,40.0298881530762,1.99609577960824,21.0100002586842,0.000403070790637885,0.000122671243606328,0.25,4.42679524656318E-6,3.64428155692256E-5,4.56226462707463E-6,99.9897614,99.9897614,-22536.12109375,-22510.66796875,57.9358691024292,20.5247126086959,23.668306,0,0,0,40,4449,99.8629,-22523.39453125,,,,,,,,,,,,,0,,,,0,,,,,,99.9897614,,,,
,32385408.28,99.9901657,-17063.517578125,1.78605532536593E-5,1.1044262681258E-6,1,0.999253354069792,40.0298881530762,1.99602514785852,21.0100002586842,0.000196210423102506,7.39143651895385E-5,0.25,3.36695512239036E-6,1.79510667306163E-5,3.44071814673995E-6,99.9901657,99.9901657,-17073.4453125,-17053.58984375,57.2660134614484,20.5257091519683,23.668306,0,0,0,40,4449,99.87675,-17063.517578125,,,,,,,,,,,,,0,,,,0,,,,,,99.9901657,,,,
,32385517.695,99.9923172,-11593.9599609375,-6.01804084979041E-7,7.43420788965249E-7,1,0.999253354069792,40.0298881530762,1.99615817858404,21.0100002586842,-1.16243728341966E-5,2.60338464613285E-5,0.25,2.39693728039034E-6,-6.12589327153896E-7,2.40859321142926E-6,99.9923172,99.9923172,-11606.337890625,-11581.58203125,57.535675300583,20.5309986571498,23.288654,0,0,0,40,4449,99.8825,-11593.9599609375,,,,,,,,,,,,,0,,,,0.0049,,,,,,99.9923172,,,,
,32385625.515,99.9912567,-6203.466796875,-1.85959935023532E-5,6.09641890384055E-7,1,0.999253354069792,40.0298881530762,1.9961207319207,21.0100002586842,-0.000213716096755732,-2.33527492911191E-5,0.25,1.21303945440943E-6,-1.87044425642983E-5,1.16220203634905E-6,99.9912567,99.9912567,-6213.33642578125,-6193.59716796875,57.7342089444676,20.5223217137234,23.288654,0,0,0,40,4449,99.8887,-6203.466796875,,,,,,,,,,,,,0,,,,0.00245,,,,,,99.9912567,,,,
,32385732.995,99.9930496,-832.213500976563,-3.31653363222825E-5,2.68438985312626E-7,1,0.999253354069792,40.0298881530762,1.99601552983472,21.0100002586842,-0.000376402618926218,-6.85669002696699E-5,0.25,-2.05539863843883E-7,-3.33511944429237E-5,-3.09991561941375E-7,99.9930496,99.9930496,-849.8984375,-814.528564453125,57.1339182416984,20.5300656941284,23.668306,0,0,0,40,4449,99.8975,-832.213500976563,,,,,,,,,,,,,0,,,,0,,,,,,99.9930496,,,,
,32385839.21,99.9961395,4473.95678710937,-4.19996988765639E-5,6.31129457604174E-7,1,0.999253354069792,40.0298881530762,1.99584743509023,21.0100002586842,-0.00047448050466857,-9.90541891823244E-5,0.25,-1.33714204187373E-6,-4.22318993982757E-5,-1.47508919145617E-6,99.9961395,99.9961395,4464.03662109375,4483.876953125,57.1346998702176,20.5246538362154,23.288654,0,0,0,40,4449,99.9012,4473.95678710937,,,,,,,,,,,,,0,,,,-0.00245,,,,,,99.9961395,,,,
,32385945.07,100.003006,9765.0205078125,-4.45826569252214E-5,9.12619018525382E-7,1,0.999253354069792,40.0298881530762,1.995976173178,21.0100002586842,-0.000501520136336512,-0.000117531862319541,0.25,-2.50959115874928E-6,-4.48261083460634E-5,-2.6614703284569E-6,100.003006,100.003006,9757.24609375,9772.794921875,57.6036769817561,20.5239645764412,23.668306,0,0,0,40,4449,99.89625,9765.0205078125,,,,,,,,,,,,,0,,,,-0.00245,,,,,,100.003006,,,,
,32386052.3,100.005394,15124.9267578125,-3.83395912667984E-5,1.12379312746636E-6,1,0.999253354069792,40.0298881530762,1.99601958342394,21.0100002586842,-0.00042892418740783,-0.000114615586757017,0.25,-3.35046318706434E-6,-3.85456365757852E-5,-3.48713597273613E-6,100.005394,100.005394,15120.185546875,15129.66796875,57.484869446833,20.5220128184096,23.668306,0,0,0,40,4449,99.8917,15124.9267578125,,,,,,,,,,,,,0,,,,0,,,,,,100.005394,,,,
,32386159.21,100.0090179,20466.6708984375,-3.84557494941296E-5,1.22612690309828E-6,1,0.999253354069792,40.0298881530762,1.99629713350944,21.0100002586842,-0.000427429352509455,-0.000131232078320784,0.25,-4.79158634620088E-6,-3.86584340536027E-5,-4.93607069341393E-6,100.0090179,100.0090179,20456.65234375,20476.689453125,57.1268835850253,20.526604282009,23.288654,0,0,0,40,4449,99.8824,20466.6708984375,,,,,,,,,,,,,0,,,,0,,,,,,100.0090179,,,,
,32386267.605,100.0112228,25883.9267578125,-5.26040076577531E-5,1.40750871613178E-6,1,0.999253354069792,40.0298881530762,1.99614048452866,21.0100002586842,-0.000585518785117933,-0.000174543263349603,0.25,-6.11908086332092E-6,-5.28831683799028E-5,-6.31328926447379E-6,100.0112228,100.0112228,25873.875,25893.978515625,56.8666012881214,20.5239143538531,23.288654,0,0,0,40,4449,99.86865,25883.9267578125,,,,,,,,,,,,,0,,,,-0.00245,,,,,,100.0112228,,,,
,32386378.86,100.0091553,31447,-7.09217695900713E-5,1.78525456536846E-6,1,0.999253354069792,40.0298881530762,1.99626071782938,21.0100002586842,-0.000789985094811191,-0.000232364999797789,0.25,-7.98965772232077E-6,-7.12997607001992E-5,-8.24860948356463E-6,100.0091553,100.0091553,31431.994140625,31462.005859375,56.5844333926791,20.5250812137032,23.668306,0,0,0,40,4449,99.8599,31447,,,,,,,,,,,,,0,,,,-0.0049,,,,,,100.0091553,,,,
,32386489.63,100.0099411,36983.59375,-9.01766961110589E-5,1.41334077992262E-6,1,0.999253354069792,40.0298881530762,1.99617973394234,21.0100002586842,-0.0010077838470069,-0.000276377167005717,0.25,-8.48291536999373E-6,-9.06633817339074E-5,-8.80083632299002E-6,100.0099411,100.0099411,36973.75390625,36993.43359375,57.1003082153714,20.5268356249928,23.668306,0,0,0,40,4449,99.84885,36983.59375,,,,,,,,,,,,,0,,,,0.0049,,,,,,100.0099411,,,,
,32386601.535,100.009552,42575.912109375,-0.000113823566143847,2.25860822405929E-6,1,0.999253354069792,40.0298881530762,1.99606444150736,21.0200008004904,-0.00127377825638394,-0.000338696825868872,0.25,-9.81758525610482E-6,-0.000114441839343768,-1.02114289326467E-5,100.009552,100.009552,42560.4453125,42591.37890625,57.0385595623522,20.5229831809987,23.668306,0,0,0,40,4449,99.8384,42575.912109375,,,,,,,,,,,,,0,,,,-0.00245,,,,,,100.009552,,,,
,32386711.82,100.0103302,48088.45703125,-0.000131724986572716,1.73099294308859E-6,1,0.999253354069792,40.0298881530762,1.99613874357693,21.0100002586842,-0.00147130632622749,-0.000408340543015182,0.25,-1.28039872385589E-5,-0.000132437741112593,-1.32652179712402E-5,100.0103302,100.0103302,48077.81640625,48099.09765625,57.6724602914484,20.5227072796195,22.909004,0,0,0,40,4449,99.82905,48088.45703125,,,,,,,,,,,,,0,,,,0,,,,,,100.0103302,,,,
,32386822.385,100.0086365,53613.734375,-0.000155516864507056,2.19219709552257E-6,1,0.999253354069792,40.0298881530762,1.99607739012589,21.0100002586842,-0.00173845857096285,-0.000473889389108282,0.25,-1.43987840690155E-5,-0.00015636227066639,-1.49359348234132E-5,100.0086365,100.0086365,53601.140625,53626.328125,56.8103240347368,20.523644207505,23.288654,0,0,0,40,4449,99.81895,53613.734375,,,,,,,,,,,,,0,,,,0,,,,,,100.0086365,,,,
,32386934.96,100.0088882,59241.001953125,-0.000177040100271021,2.16179467786151E-6,1,0.999253354069792,40.0298881530762,1.99611659271424,21.0100002586842,-0.00198435815773079,-0.000509641140824398,0.25,-1.37687800335658E-5,-0.000178012200308643,-1.43614281733896E-5,100.0088882,100.0088882,59228.38671875,59253.6171875,56.8970848003714,20.5238294670924,23.288654,0,0,0,40,4449,99.8086,59241.001953125,,,,,,,,,,,,,0,,,,0.00245,,,,,,100.0088882,,,,
,32387045.03,100.0078049,64743.74609375,-0.000190279267922407,2.06767770526789E-6,1,0.999253354069792,40.0298881530762,1.99598709421006,21.0100002586842,-0.00213848549720854,-0.000514429821944927,0.25,-1.18726252749292E-5,-0.000191334630876598,-1.248870490938E-5,100.0078049,100.0078049,64726.13671875,64761.35546875,56.7431039820829,20.5194626160831,23.668306,0,0,0,40,4449,99.8033,64743.74609375,,,,,,,,,,,,,0,,,,0,,,,,,100.0078049,,,,
,32387154.965,100.0075989,70238.47265625,-0.000210225695142193,2.15534138404409E-6,1,0.999253354069792,40.0298881530762,1.99582636452973,21.0100002586842,-0.00236843371955096,-0.000534510584117486,0.25,-1.01464874719149E-5,-0.000211402440824165,-1.0805530366534E-5,100.0075989,100.0075989,70223.375,70253.5703125,57.5223876157561,20.5178442819464,23.668306,0,0,0,40,4449,99.79555,70238.47265625,,,,,,,,,,,,,0,,,,0.00245,,,,,,100.0075989,,,,
,32387267.195,100.0072556,75848.7421875,-0.000230010120239293,2.12177566140481E-6,1,0.999253354069792,40.0298881530762,1.99596741972161,21.0100002586842,-0.00259909376162755,-0.000541755863529987,0.25,-7.31343585418381E-6,-0.000231310788964872,-8.00757632780942E-6,100.0072556,100.0072556,75841.15625,75856.328125,56.7329428113329,20.5195351490724,23.288654,0,0,0,40,4449,99.7886,75848.7421875,,,,,,,,,,,,,0,,,,-0.00245,,,,,,100.0072556,,,,
,32387376.765,100.0046616,81324.2421875,-0.000257631790774427,2.44044868866711E-6,1,0.999253354069792,40.0298881530762,1.99600675886706,21.0100002586842,-0.00289865544716431,-0.000678896311331148,0.25,-1.45390915321074E-5,-0.00025907337705027,-1.53474010331414E-5,100.0046616,100.0046616,81309.3203125,81339.1640625,56.7212183835445,20.5256948547648,23.288654,0,0,0,40,4449,99.78465,81324.2421875,,,,,,,,,,,,,0,,,,0.00245,,,,,,100.0046616,,,,
,32387488.07,100.0073318,86887.3984375,-0.000277502432671989,2.68509207945099E-6,1,0.999253354069792,40.0298881530762,1.99607702834915,21.0100002586842,-0.00312615636527585,-0.000709651212446225,0.25,-1.3762561862033E-5,-0.000279063383398905,-1.461616290132E-5,100.0073318,100.0073318,86877.3515625,86897.4453125,56.8329912617945,20.5174569972527,22.909004,0,0,0,40,4449,99.77485,86887.3984375,,,,,,,,,,,,,0,,,,0.00245,,,,,,100.0073318,,,,
,32387617.595,100.00278475,87928.10546875,-0.000280541028911013,1.98931845777447E-6,1,0.999253354069792,40.0298881530762,1.99594315268047,21.0100002586842,-0.0031587699235901,-0.000725478291086426,0.25,-1.46273358883386E-5,-0.000282117644221935,-1.54932464205816E-5,100.002388,100.0031815,87918,87938.2109375,57.2363115777176,20.5251708096652,23.668306,0,0,0,40,4449,99.7728,87928.10546875,,,,,,,,,,,,,0,,,,-0.0049,,,,,,100.00278475,,,,
,32387726.475,100.0008469,82484.89453125,-0.000261689338407051,2.085271668396E-6,1,0.999253354069792,40.0298881530762,1.99593535017401,21.0100002586842,-0.00294592835253961,-0.000679789908963934,0.25,-1.39088385388118E-5,-0.000263156583572556,-1.47238387268942E-5,100.0008469,100.0008469,82470,82499.7890625,56.5992843345444,20.5272662129085,23.668306,0,0,0,40,4449,99.773,82484.89453125,,,,,,,,,,,,,0,,,,0,,,,,,100.0008469,,,,
,32387836.455,99.9964066,76988.87890625,-0.000237260411985939,2.23368262898273E-6,1,0.999253354069792,40.0298881530762,1.99590161856172,21.0100002586842,-0.00267290635110367,-0.000604613641756681,0.25,-1.15753612911847E-5,-0.000238591172236824,-1.23135488159293E-5,99.9964066,99.9964066,76976.3984375,77001.359375,56.9729027667368,20.5208925344229,23.668306,0,0,0,40,4449,99.77895,76988.87890625,,,,,,,,,,,,,0,,,,0.0049,,,,,,99.9964066,,,,
,32387947.86,99.9956589,71420.53515625,-0.000215071584406894,1.91517420684042E-6,1,0.999253354069792,40.0298881530762,1.99598480123548,21.0100002586842,-0.00241710797505992,-0.000581684352277343,0.25,-1.34446809652662E-5,-0.00021626719050203,-1.41355982711464E-5,99.9956589,99.9956589,71408.0625,71433.0078125,57.2253687784484,20.5178320948417,23.288654,0,0,0,40,4449,99.78205,71420.53515625,,,,,,,,,,,,,0,,,,0.00245,,,,,,99.9956589,,,,
,32388056.79,99.9962997,65972.70703125,-0.000192963307507461,1.77560919528382E-6,1,0.999253354069792,40.0298881530762,1.99606930347059,21.0100002586842,-0.00216959281302941,-0.000516853972356309,0.25,-1.16137878142549E-5,-0.000194035236759042,-1.22352962098969E-5,99.9962997,99.9962997,65960.3515625,65985.0625,57.3176009437176,20.5237073542534,23.288654,0,0,0,40,4449,99.78815,65972.70703125,,,,,,,,,,,,,0,,,,-0.00245,,,,,,99.9962997,,,,
,32388166.185,99.9946365,60506.658203125,-0.000177975639499383,3.04888037142422E-6,1,0.999253354069792,40.0298881530762,1.9960085451097,21.0100002586842,-0.00200338676993539,-0.000463087168669567,0.25,-9.51060102058637E-6,-0.000178965876167073,-1.00808583313941E-5,99.9946365,99.9946365,60501.984375,60511.33203125,57.1612752398714,20.5231380519429,23.288654,0,0,0,40,4449,99.7915,60506.658203125,,,,,,,,,,,,,0,,,,-0.00245,,,,,,99.9946365,,,,
,32388277.955,99.9935532,54919.845703125,-0.000154269925719688,1.96364175695852E-6,1,0.999253354069792,40.0298881530762,1.99607521766373,21.0100002586842,-0.00173421594205363,-0.000414876863565156,0.25,-9.42507485692688E-6,-0.000155123139701327,-9.92954873321756E-6,99.9935532,99.9935532,54909.453125,54930.23828125,57.017455592333,20.523789951538,24.047956,0,0,0,40,4449,99.79705,54919.845703125,,,,,,,,,,,,,0,,,,-0.00245,,,,,,99.9935532,,,,
,32388390.34,99.9941711,49302.875,-0.000136305137217989,2.08551137838508E-6,1,0.999253354069792,40.0298881530762,1.99589658818226,21.0100002586842,-0.00152700799885558,-0.000395631597853447,0.25,-1.08858001986274E-5,-0.000137049952369993,-1.13491053420691E-5,99.9941711,99.9941711,49292.75390625,49312.99609375,57.1331366131791,20.5277979562449,23.288654,0,0,0,40,4449,99.80575,49302.875,,,,,,,,,,,,,0,,,,0.00245,,,,,,99.9941711,,,,
,32388502.57,99.9929733,43695.083984375,-0.000111910250957518,1.99723618872011E-6,1,0.999253354069792,40.0298881530762,1.99588075774725,21.0100002586842,-0.0012544617000712,-0.000320433631058361,0.25,-8.54912752701739E-6,-0.000112521634367145,-8.92972277346217E-6,99.9929733,99.9929733,43684.80859375,43705.359375,57.2839909173907,20.5244272589045,23.668306,0,0,0,40,4449,99.81355,43695.083984375,,,,,,,,,,,,,0,,,,0.00245,,,,,,99.9929733,,,,
,32388609.51,99.9923706,38349.8125,-9.50997450094295E-5,1.76994118492936E-6,1,0.999253354069792,40.0298881530762,1.99586261506117,21.0100002586842,-0.00106650869738691,-0.000269416017587714,0.25,-7.00954909203219E-6,-9.56190220696056E-5,-7.33346649238408E-6,99.9923706,99.9923706,38337.32421875,38362.30078125,57.301968373333,20.5246660910265,23.668306,0,0,0,40,4449,99.82,38349.8125,,,,,,,,,,,,,0,,,,-0.0049,,,,,,99.9923706,,,,
,32388716.32,99.9922714,33010.46875,-7.52991393928715E-5,1.96014641551571E-6,1,0.999253354069792,40.0298881530762,1.9960018587914,21.0100002586842,-0.000844040743616975,-0.000215944960154892,0.25,-5.77840089310912E-6,-7.57088100341376E-5,-6.03767911033802E-6,99.9922714,99.9922714,33005.38671875,33015.55078125,57.7787617700638,20.5258461720104,23.288654,0,0,0,40,4449,99.82835,33010.46875,,,,,,,,,,,,,0,,,,0,,,,,,99.9922714,,,,
,32388822.62,99.9903259,27698.73828125,-5.45661922238878E-5,1.67283771191792E-6,1,0.999253354069792,40.0298881530762,1.99603367979325,21.0100002586842,-0.000605709456486764,-0.000190271302343773,0.25,-7.15960106379418E-6,-5.48534919309099E-5,-7.36538288247644E-6,99.9903259,99.9903259,27688.767578125,27708.708984375,57.4285921934484,20.5297591466811,23.668306,0,0,0,40,4449,99.83695,27698.73828125,,,,,,,,,,,,,0,,,,-0.00245,,,,,,99.9903259,,,,
,32388931.135,99.9896088,22273.4912109375,-3.67596002688954E-5,1.53892550678543E-6,1,0.999253354069792,40.0298881530762,1.99593636530256,21.0100002586842,-0.000408090133510012,-0.000127799683464058,0.25,-4.78964541957366E-6,-3.69528268424925E-5,-4.92877002358064E-6,99.9896088,99.9896088,22266.111328125,22280.87109375,57.4020168237945,20.520003990989,22.909004,0,0,0,40,4449,99.8503,22273.4912109375,,,,,,,,,,,,,0,,,,-0.0049,,,,,,99.9896088,,,,
,32389037.945,99.9895248,16936.2451171875,-1.65654470089693E-5,1.37542348942311E-6,1,0.999253354069792,40.0298881530762,1.9959838648342,21.0100002586842,-0.000179825183539798,-8.08106828603273E-5,0.25,-4.20161161891737E-6,-1.66460741408572E-5,-4.27613665356364E-6,99.9895248,99.9895248,16923.69921875,16948.791015625,57.2667950899676,20.5234123955285,23.668306,0,0,0,40,4449,99.85955,16936.2451171875,,,,,,,,,,,,,0,,,,-0.0049,,,,,,99.9895248,,,,
,32389146.285,99.9915924,11521.9350585938,1.46685062657379E-6,6.97192628561132E-7,1,0.999253354069792,40.0298881530762,1.99576223492635,21.0100002586842,2.2266587361469E-5,-2.89510717694057E-5,0.25,-2.80618165770373E-6,1.48377682272782E-6,-2.81747369390991E-6,99.9915924,99.9915924,11517.0078125,11526.8623046875,57.4356268501215,20.5257632361571,23.668306,0,0,0,40,4449,99.86725,11521.9350585938,,,,,,,,,,,,,0,,,,0.00245,,,,,,99.9915924,,,,
,32389254.275,99.990921,6121.84399414062,1.85999374823663E-5,6.09271729859138E-7,1,0.999253354069792,40.0298881530762,1.99582686247765,21.0100002586842,0.000214764574396775,1.74754382739061E-5,0.25,-1.73079509198654E-6,1.87100086344366E-5,-1.68284364796208E-6,99.990921,99.990921,6114.3583984375,6129.32958984375,57.6232176947369,20.5261411271291,23.668306,0,0,0,40,4449,99.8775,6121.84399414062,,,,,,,,,,,,,0,,,,-0.00245,,,,,,99.990921,,,,
,32389360.815,99.9915466,798.531799316406,3.3890763143709E-5,3.70834179168354E-7,1,0.999253354069792,40.0298881530762,1.99580833149215,21.0100002586842,0.000385375614545939,6.56323911737956E-5,0.25,-1.79704368803615E-7,3.40818876352799E-5,-7.51291863913601E-8,99.9915466,99.9915466,785.916381835938,811.147216796875,56.6883899857368,20.5222895984496,23.668306,0,0,0,40,4449,99.88245,798.531799316406,,,,,,,,,,,,,0,,,,-0.00245,,,,,,99.9915466,,,,
,32389378.805,99.9941025,-0.106566410511732,3.51406093025909E-5,2.80923404270791E-7,1,0.999253354069792,40.0298881530762,1.99585927324652,21.0100002586842,0.00039899798516128,7.14639489704402E-5,0.25,1.13741857457139E-7,3.53378278348028E-5,2.23898802381533E-7,99.9941025,99.9941025,-0.121790185570717,-0.0913426354527473,57.1933220091599,20.5222135571236,23.668306,0,0,0,40,4417,99.8869,-0.106566410511732,,,,,,,,,,,,,0,,,,0,,,,,,99.9941025,,,,