File: data/monolayers/magneticStructure/ML_Ac_CoFe_C/PPMS/data/DD205_4_HYST_INIT_300K.DAT
[Header]
; VSM Data File (default extension .dat)
; Copyright (c) 2003-2013, Quantum Design, Inc. All rights reserved.
TITLE,
FILEOPENTIME,32256518.55,01/09/2019,4:10 pm
BYAPP,VSM,2.0,2.0
INFO,PPMS VSM Option Release 1.4.10 Build 1,APPNAME
INFO,Quantum Design Linear Motor Servo Controller,MOTOR_MODULE_NAME
INFO,3101-100 M1,MOTOR_HW_VERSION
INFO,MMC1014,MOTOR_SERIAL_NUMBER
INFO,SRV No X-over 01.03.11,MOTOR_SOFTWARE_VERSION
INFO,Quantum Design VSM Detection Module,VSM_MODULE_NAME
INFO,3101-150 F0,VSM_HW_VERSION
INFO,VSM707,VSM_SERIAL_NUMBER
INFO,VSM No X-over 01.02.05 May 20 2008 13:51:47,VSM_SOFTWARE_VERSION
INFO,704,PREAMP_SERIAL_NUMBER
INFO,822,COIL_SERIAL_NUMBER
INFO,0,MOMENT_UNITS
INFO,DD205_4,SAMPLE_MATERIAL
INFO,Monolayer,SAMPLE_COMMENT
INFO,29.55,SAMPLE_MASS
INFO,,SAMPLE_VOLUME
INFO,,SAMPLE_MOLECULAR_WEIGHT
INFO,,SAMPLE_SIZE
INFO,,SAMPLE_SHAPE
DATATYPE,COMMENT,1
DATATYPE,TIME,2
STARTUPAXIS,X,2
STARTUPAXIS,Y1,5
[Data]
Comment,Time Stamp (sec),Temperature (K),Magnetic Field (Oe),Moment (emu),M. Std. Err. (emu),Transport Action,Averaging Time (sec),Frequency (Hz),Peak Amplitude (mm),Center Position (mm),Coil Signal' (mV),Coil Signal" (mV),Range (mV),M. Quad. Signal (emu),M. Raw' (emu),M. Raw" (emu),Min. Temperature (K),Max. Temperature (K),Min. Field (Oe),Max. Field (Oe),Mass (grams),Motor Lag (deg),Pressure (Torr),VSM Status (code),Motor Status (code),Measure Status (code),Measure Count,PPMS Status (code),System Temp. (K),System Field (Oe),Sample Position (deg),Bridge 1 Resistance (ohms),Bridge 1 Excitation (에),Bridge 2 Resistance (ohms),Bridge 2 Excitation (에),Bridge 3 Resistance (ohms),Bridge 3 Excitation (에),Bridge 4 Resistance (ohms),Bridge 4 Excitation (에),Signal 1 Vin (V),Signal 2 Vin (V),Digital Inputs (code),Drive 1 Iout (mA),Drive 1 Ipower (W),Drive 2 Iout (mA),Drive 2 Ipower (W),Pressure (),Map 20 (),Map 21 (),Map 22 (),Map 23 (),Map 24 (),Map 25 (),Map 26 (),Map 27 (),Map 28 (),Map 29 ()
,32256535,300.0256653,0.0761188715696335,,,2,,,,20.169999986887,,,,,,,300.0256653,300.0256653,0.0761188715696335,0.0761188715696335,,,25.946213,,,,-99999999,4369,300.7482,0.0761188715696335,,,,,,,,,,,,,,,,,,,,,,,300.0256653,,,,
,32256664.88,300.0466309,3672.814453125,2.04343970350246E-5,4.22342860155708E-7,1,0.999253354069792,40.0298881530762,1.9976596545666,20.1600007712841,0.000233275201026672,2.77332861748821E-5,0.25,-1.08863534414263E-6,2.04344762861107E-5,-1.07507355562759E-6,300.0466309,300.0466309,3662.68505859375,3682.94384765625,56.2397352156983,20.464713272215,25.566563,0,0,0,40,4449,300.6683,3672.814453125,,,,,,,,,,,,,0,,,,-0.00245,,,,,,300.0466309,,,,
,32256742.905,300.0349426,7570.513671875,1.17767964098714E-5,5.84612008375046E-7,1,0.999253354069792,40.0298881530762,1.99766798348363,20.1600007712841,0.000136580556140413,3.64174766440248E-6,0.25,-1.71847428374958E-6,1.17775690825234E-5,-1.71062908416205E-6,300.0349426,300.0349426,7563.1025390625,7577.9248046875,56.3475999513521,20.4690983559935,25.566563,0,0,0,40,4449,300.6543,7570.513671875,,,,,,,,,,,,,0,,,,-0.00245,,,,,,300.0349426,,,,
,32256822.15,300.0336456,11531.4350585938,2.64070620473079E-8,8.51073415531752E-7,1,0.999253354069792,40.0298881530762,1.99742795608036,20.1600007712841,5.76914961740009E-6,-3.15224842196451E-5,0.25,-2.79167012085695E-6,2.82522444696399E-8,-2.79156652023711E-6,300.0328979,300.0343933,11526.4111328125,11536.458984375,56.6539983308906,20.4732306027647,25.946213,0,0,0,40,4449,300.63245,11531.4350585938,,,,,,,,,,,,,0,,,,0.0049,,,,,,300.0336456,,,,
,32256901.98,300.0235596,15519.5087890625,-1.09977642054132E-5,1.46953855561899E-6,1,0.999253354069792,40.0298881530762,1.99750251121855,20.1600007712841,-0.000122038190741403,-3.5131178275072E-5,0.25,-1.20060641924963E-6,-1.09966359904951E-5,-1.20783689050981E-6,300.0235596,300.0235596,15514.4951171875,15524.5224609375,56.7438856106022,20.4737771745327,25.186911,0,0,0,40,4449,300.63075,15519.5087890625,,,,,,,,,,,,,0,,,,0.0049,,,,,,300.0235596,,,,
,32256982.53,300.0237732,19547.1357421875,-2.58341883900934E-5,1.56160783972638E-6,1,0.999253354069792,40.0298881530762,1.99738175511221,20.1600007712841,-0.00028575258721666,-8.77345393978983E-5,0.25,-3.2813616803174E-6,-2.58312357384269E-5,-3.29832113511039E-6,300.0237732,300.0237732,19542.099609375,19552.171875,56.7376325824483,20.4774431189537,25.186911,0,0,0,40,4449,300.6011,19547.1357421875,,,,,,,,,,,,,0,,,,0.00245,,,,,,300.0237732,,,,
,32257061.555,300.0162354,23495.294921875,-3.84315941241355E-5,2.08185343979843E-6,1,0.999253354069792,40.0298881530762,1.99732128136037,20.1600007712841,-0.000432145252327349,-8.97371310969796E-5,0.25,-1.2760865780148E-6,-3.84295952901446E-5,-1.30140601191077E-6,300.0162354,300.0162354,23490.279296875,23500.310546875,56.933039712256,20.4784085267263,25.566563,0,0,0,40,4449,300.5995,23495.294921875,,,,,,,,,,,,,0,,,,0.00245,,,,,,300.0162354,,,,
,32257141.57,300.0208435,27496.1025390625,-5.26376121777039E-5,2.6916833593658E-6,1,0.999253354069792,40.0298881530762,1.99736317448849,20.1600007712841,-0.000585743251625007,-0.00015842896543583,0.25,-4.88831881566294E-6,-5.26327984556118E-5,-4.92287566135409E-6,300.0208435,300.0208435,27488.525390625,27503.6796875,56.9994781363906,20.4794271512772,25.946213,0,0,0,40,4449,300.5833,27496.1025390625,,,,,,,,,,,,,0,,,,-0.00245,,,,,,300.0208435,,,,
,32257220.885,300.021759,31459.138671875,-6.7451770995874E-5,2.84885213468398E-6,1,0.999253354069792,40.0298881530762,1.99742889530055,20.1600007712841,-0.00075759167312376,-0.000162763847301952,0.25,-2.7045467302172E-6,-6.74479515779852E-5,-2.74890246078194E-6,300.021759,300.021759,31451.94921875,31466.328125,56.872072687756,20.4799203437165,25.946213,0,0,0,40,4449,300.56405,31459.138671875,,,,,,,,,,,,,0,,,,0,,,,,,300.021759,,,,
,32257301.265,300.0144653,35476.892578125,-8.02443602746499E-5,1.97299048408183E-6,1,0.999253354069792,40.0298881530762,1.99722308724681,20.1600007712841,-0.000892438987097501,-0.000244092622644936,0.25,-7.68108554791743E-6,-8.02369053353814E-5,-7.73367543956028E-6,300.0144653,300.0144653,35474.41015625,35479.375,57.1284468420637,20.4827515624187,25.566563,0,0,0,40,4449,300.5603,35476.892578125,,,,,,,,,,,,,0,,,,0.0049,,,,,,300.0144653,,,,
,32257383.86,300.0162659,39602.1171875,-9.65805971223975E-5,1.34842941283149E-6,1,0.999253354069792,40.0298881530762,1.99724718490129,20.1600007712841,-0.00108254724184584,-0.000245235060093402,0.25,-4.95158152634742E-6,-9.65744520532323E-5,-5.0149501662896E-6,300.0162659,300.0162659,39592.26171875,39611.97265625,56.9510171681983,20.4836542276276,25.566563,0,0,0,40,4449,300.54885,39602.1171875,,,,,,,,,,,,,0,,,,-0.00245,,,,,,300.0162659,,,,
,32257465.375,300.0201416,43677.767578125,-0.000107310876208834,2.40694938471267E-6,1,0.999253354069792,40.0298881530762,1.9971864286543,20.1600007712841,-0.0012072745423254,-0.000246561241005342,0.25,-3.21047803290422E-6,-0.000107305547578927,-3.28089434176587E-6,300.0201416,300.0201416,43675.1953125,43680.33984375,57.0166739638137,20.482877903237,25.566563,0,0,0,40,4449,300.5317,43677.767578125,,,,,,,,,,,,,0,,,,0.0049,,,,,,300.0201416,,,,
,32257546.18,300.0161133,47718.986328125,-0.000123747545876871,2.38226343716542E-6,1,0.999253354069792,40.0298881530762,1.9972142823562,20.1600007712841,-0.00139016792302868,-0.000296117637557688,0.25,-4.74456768336657E-6,-0.000123740743330517,-4.82566660080109E-6,300.0161133,300.0161133,47714.0859375,47723.88671875,56.5969394489868,20.4846749100919,25.946213,0,0,0,40,4449,300.52,47718.986328125,,,,,,,,,,,,,0,,,,0.0049,,,,,,300.0161133,,,,
,32257625.285,300.021637,51671.8984375,-0.000138702523119937,2.49040796407855E-6,1,0.999253354069792,40.0298881530762,1.997134439909,20.1600007712841,-0.00156056537136272,-0.000317724731451183,0.25,-4.06533625574391E-6,-0.000138695702746399,-4.15619303255022E-6,300.021637,300.021637,51666.80078125,51676.99609375,57.0565370182945,20.4858044500837,25.566563,0,0,0,40,4449,300.50515,51671.8984375,,,,,,,,,,,,,0,,,,-0.0049,,,,,,300.021637,,,,
,32257707.345,300.0158691,55771.3828125,-0.000152310430712113,2.70050992382165E-6,1,0.999253354069792,40.0298881530762,1.99717818101033,20.1600007712841,-0.00170846919733296,-0.000379133248937871,0.25,-7.13737265283775E-6,-0.000152301232298559,-7.2369697981346E-6,300.0158691,300.0158691,55768.39453125,55774.37109375,57.1182856713137,20.4861242044083,25.186911,0,0,0,40,4449,300.4979,55771.3828125,,,,,,,,,,,,,0,,,,0,,,,,,300.0158691,,,,
,32257787.205,300.0134888,59765.248046875,-0.000167151715127948,2.52455878169736E-6,1,0.999253354069792,40.0298881530762,1.99718492867483,20.1600007712841,-0.0018770675636693,-0.000403858442463575,0.25,-6.75243871427854E-6,-0.000167142356019292,-6.8616707503254E-6,300.0134888,300.0134888,59758.04296875,59772.453125,57.0158923352945,20.4851081543899,25.566563,0,0,0,40,4449,300.49025,59765.248046875,,,,,,,,,,,,,0,,,,0.00245,,,,,,300.0134888,,,,
,32257867.315,300.0184326,63768.54296875,-0.000181609776348404,2.46061840280006E-6,1,0.999253354069792,40.0298881530762,1.99708786491226,20.1600007712841,-0.00204046715971106,-0.00043222289683023,0.25,-6.75761098578863E-6,-0.000181599968315619,-6.87619751009096E-6,300.0184326,300.0184326,63765.984375,63771.1015625,56.9486722826406,20.4861758819995,25.566563,0,0,0,40,4449,300.4749,63768.54296875,,,,,,,,,,,,,0,,,,0,,,,,,300.0184326,,,,
,32257949.56,300.0175171,67879.24609375,-0.00019659198776096,3.27396406881446E-6,1,0.999253354069792,40.0298881530762,1.99701743929453,20.1600007712841,-0.00220711296134096,-0.000477168439262653,0.25,-8.13802314090746E-6,-0.000196580855115933,-8.26624369522532E-6,300.0167542,300.01828,67874.203125,67884.2890625,57.0643533034868,20.4870220621836,25.946213,0,0,0,40,4449,300.4624,67879.24609375,,,,,,,,,,,,,0,,,,0,,,,,,300.0175171,,,,
,32258030.46,300.0094604,71922.4296875,-0.000206648437235561,1.97118122555532E-6,1,0.999253354069792,40.0298881530762,1.9969982680015,20.1600007712841,-0.00232126928560883,-0.000494218077816488,0.25,-7.9040219682368E-6,-0.000206637237319683,-8.03868592266014E-6,300.0094604,300.0094604,71912.4453125,71932.4140625,57.0917103016599,20.4892339000882,25.946213,0,0,0,40,4449,300.4629,71922.4296875,,,,,,,,,,,,,0,,,,-0.00245,,,,,,300.0094604,,,,
,32258112.055,300.0226898,76000.87890625,-0.000226842389417816,3.58575393030662E-6,1,0.999253354069792,40.0298881530762,1.99695067946538,20.1600007712841,-0.00255599919216332,-0.000496604982922508,0.25,-4.6176794863284E-6,-0.000226832651979414,-4.76547917982334E-6,300.0220642,300.0233154,75990.8359375,76010.921875,57.1573670972753,20.4876318397116,25.946213,0,0,0,40,4449,300.44005,76000.87890625,,,,,,,,,,,,,0,,,,0.0049,,,,,,300.0226898,,,,
,32258192.595,300.0181274,80026.36328125,-0.00023806433108645,3.6270790128876E-6,1,0.999253354069792,40.0298881530762,1.99693370280381,20.1600007712841,-0.00267447071849071,-0.000567074320206466,0.25,-8.90606985443469E-6,-0.000238051522347247,-9.0609110631319E-6,300.0181274,300.0181274,80024.1484375,80028.578125,57.1792526958137,20.4887321398075,25.566563,0,0,0,40,4449,300.42565,80026.36328125,,,,,,,,,,,,,0,,,,-0.0049,,,,,,300.0181274,,,,
,32258274.93,300.018219,84142.69140625,-0.000251285284222312,3.61121820531717E-6,1,0.999253354069792,40.0298881530762,1.99696377292689,20.1600007712841,-0.00282732318290811,-0.000573845751816145,0.25,-7.21384714504489E-6,-0.000251273207735748,-7.3771844782201E-6,300.018219,300.018219,84132.5078125,84152.875,56.8994296859291,20.4898684455582,25.566563,0,0,0,40,4449,300.4149,84142.69140625,,,,,,,,,,,,,0,,,,0,,,,,,300.018219,,,,
,32258351.415,300.0198364,87968.671875,-0.000267179135759558,3.33270669653315E-6,1,0.999253354069792,40.0298881530762,1.99687415869128,20.1600007712841,-0.00301403872093293,-0.000563849551847461,0.25,-3.57856740758098E-6,-0.000267168959815257,-3.7521898590203E-6,300.0198364,300.0198364,87961.2421875,87976.1015625,57.0612267894099,20.4898178361522,25.186911,0,0,0,40,4449,300.4035,87968.671875,,,,,,,,,,,,,0,,,,0,,,,,,300.0198364,,,,
,32258444.29,300.0124817,88382.859375,-0.000272032177129856,3.88194842107353E-6,1,0.999253354069792,40.0298881530762,1.99685685811874,20.1600007712841,-0.00306380100368801,-0.000602717411038222,0.25,-6.17567847235367E-6,-0.000272020243387904,-6.35236732639358E-6,300.0124817,300.0124817,88382.859375,88382.859375,56.9072459711214,20.4886066462507,25.186911,0,0,0,40,4449,300.3967,88382.859375,,,,,,,,,,,,,0,,,,0,,,,,,300.0124817,,,,
,32258522.33,300.0104065,84481.83203125,-0.000255797906132843,3.07949148723811E-6,1,0.999253354069792,40.0298881530762,1.9967905036673,20.1600007712841,-0.00288589968732051,-0.000537692162035712,0.25,-3.23872210473241E-6,-0.000255788356768581,-3.40510750668677E-6,300.0104065,300.0104065,84474.40625,84489.2578125,57.0237086204868,20.4899023377223,25.186911,0,0,0,40,4449,300.40245,84481.83203125,,,,,,,,,,,,,0,,,,0.0049,,,,,,300.0104065,,,,
,32258602.49,300,80475.6171875,-0.000239277255696469,2.67664137839162E-6,1,0.999253354069792,40.0298881530762,1.99676678061666,20.1600007712841,-0.00268591612375634,-0.000581278920864255,0.25,-9.95621485596249E-6,-0.000239263883600535,-1.01118164579191E-5,300,300,80465.546875,80485.6875,57.5935158110061,20.4910513687737,25.566563,0,0,0,40,4449,300.40485,80475.6171875,,,,,,,,,,,,,0,,,,0,,,,,,300,,,,
,32258681.305,300.0019836,76534.078125,-0.000227470157383328,2.47949154089126E-6,1,0.999253354069792,40.0298881530762,1.99683968672454,20.1600007712841,-0.00255452598050572,-0.000546511651372729,0.25,-8.92498944233355E-6,-0.000227457760804588,-9.07308286324063E-6,300.0019836,300.0019836,76531.703125,76536.453125,57.1972301517561,20.4928969045165,25.946213,0,0,0,40,4449,300.39555,76534.078125,,,,,,,,,,,,,0,,,,-0.00245,,,,,,300.0019836,,,,
,32258760.785,299.9981689,72559.875,-0.000213553968028457,3.66928112210309E-6,1,0.999253354069792,40.0298881530762,1.99676880066342,20.1600007712841,-0.00240305696504684,-0.000484816479101421,0.25,-5.88089994954914E-6,-0.000213543972382392,-6.02014305660473E-6,299.9981689,299.9981689,72552.4375,72567.3125,57.2027015513907,20.4931020459122,25.566563,0,0,0,40,4449,300.403,72559.875,,,,,,,,,,,,,0,,,,0,,,,,,299.9981689,,,,
,32258841.93,299.9953918,68503.65625,-0.000198304150965017,1.55637190723951E-6,1,0.999253354069792,40.0298881530762,1.99669122915799,20.1600007712841,-0.00222489620402972,-0.000487562136770397,0.25,-8.76721914960062E-6,-0.00019829271291257,-8.89655614727837E-6,299.9953918,299.9953918,68494.0703125,68513.2421875,57.1378263842945,20.4944744683622,25.566563,0,0,0,40,4449,300.4037,68503.65625,,,,,,,,,,,,,0,,,,-0.00245,,,,,,299.9953918,,,,
,32258922.515,299.9933167,64475.96484375,-0.000185411008055724,1.44967504669545E-6,1,0.999253354069792,40.0298881530762,1.99659318028892,20.1600007712841,-0.00208319704175406,-0.000438210639502526,0.25,-6.63766144144899E-6,-0.000185401331615427,-6.75875484089641E-6,299.9933167,299.9933167,64470.69921875,64481.23046875,57.1589303543137,20.4953691165225,25.566563,0,0,0,40,4449,300.4065,64475.96484375,,,,,,,,,,,,,0,,,,-0.0049,,,,,,299.9933167,,,,
,32259001.93,299.9949036,60507.12890625,-0.000168077902846388,1.7167816064627E-6,1,0.999253354069792,40.0298881530762,1.99643111174657,20.1600007712841,-0.00188829979333299,-0.000397233975320205,0.25,-6.01882392808956E-6,-0.000168069107518157,-6.12869888571675E-6,299.9949036,299.9949036,60501.9609375,60512.296875,57.1933220091599,20.4978071614386,26.325863,0,0,0,40,4449,300.4182,60507.12890625,,,,,,,,,,,,,0,,,,0,,,,,,299.9949036,,,,
,32259083.19,299.9910889,56446.27734375,-0.000155483344622863,2.04954299582372E-6,1,0.999253354069792,40.0298881530762,1.99645467415168,20.1600007712841,-0.00174880656576469,-0.000356028202968013,0.25,-4.55540979825524E-6,-0.000155475880695887,-4.65718117522015E-6,299.9910889,299.9910889,56438.58203125,56453.97265625,57.2707032325638,20.4957665249169,25.566563,0,0,0,40,4449,300.42,56446.27734375,,,,,,,,,,,,,0,,,,0,,,,,,299.9910889,,,,
,32259162.09,299.9898529,52503.314453125,-0.000142623602453607,1.46644385190182E-6,1,0.999253354069792,40.0298881530762,1.99632882157488,20.1600007712841,-0.00159996850096244,-0.000350232292233076,0.25,-6.27246925193553E-6,-0.000142615377936055,-6.36585288894678E-6,299.9892883,299.9904175,52495.70703125,52510.921875,57.1042163579676,20.4987476183397,25.946213,0,0,0,40,4449,300.4164,52503.314453125,,,,,,,,,,,,,0,,,,-0.00245,,,,,,299.9898529,,,,
,32259241.115,299.9908142,48552.6640625,-0.000128676868825192,2.1247368798268E-6,1,0.999253354069792,40.0298881530762,1.99622465520025,20.1600007712841,-0.00143888896920874,-0.000342238405919413,0.25,-7.9830524002081E-6,-0.000128667908089716,-8.06731246550968E-6,299.9908142,299.9908142,48547.72265625,48557.60546875,56.8978664288906,20.5001009957048,25.946213,0,0,0,40,4449,300.4264,48552.6640625,,,,,,,,,,,,,0,,,,-0.0049,,,,,,299.9908142,,,,
,32259319.975,299.9925232,44612.208984375,-0.000113901653679343,1.54619792892148E-6,1,0.999253354069792,40.0298881530762,1.99651749977438,20.1600007712841,-0.00127520049146668,-0.00029517639318611,0.25,-6.3757619437918E-6,-0.000113894158594019,-6.45043328848434E-6,299.9925232,299.9925232,44604.71875,44619.69921875,57.1425161554099,20.5001692620742,26.325863,0,0,0,40,4449,300.43215,44612.208984375,,,,,,,,,,,,,0,,,,0,,,,,,299.9925232,,,,
,32259399.18,299.9985657,40651.546875,-9.92083331225414E-5,1.38171499206919E-6,1,0.999253354069792,40.0298881530762,1.99634199285487,20.1600007712841,-0.00111154508100973,-0.000251656856303394,0.25,-5.07375775414252E-6,-9.92020904893193E-5,-5.13886618372102E-6,299.9985657,299.9985657,40646.6015625,40656.4921875,57.0268351345637,20.4991432298543,25.566563,0,0,0,40,4449,300.44055,40651.546875,,,,,,,,,,,,,0,,,,-0.0049,,,,,,299.9985657,,,,
,32259478.945,300.0004272,36665.9296875,-8.5636435078272E-5,1.2923661933927E-6,1,0.999253354069792,40.0298881530762,1.99641031668233,20.1600007712841,-0.000957846367381385,-0.000226866052726221,0.25,-5.23140141972948E-6,-8.56304724718223E-5,-5.28763041276084E-6,300.0004272,300.0004272,36658.46484375,36673.39453125,57.5669404413522,20.4993762227357,25.566563,0,0,0,40,4449,300.42915,36665.9296875,,,,,,,,,,,,,0,,,,-0.0049,,,,,,300.0004272,,,,
,32259558.115,299.996521,32710.748046875,-7.32719283772234E-5,1.30626514364277E-6,1,0.999253354069792,40.0298881530762,1.99635353478688,20.1600007712841,-0.000817708642565333,-0.000204598818314299,0.25,-5.40432565719374E-6,-7.32662191152025E-5,-5.45245021493825E-6,299.996521,299.996521,32705.55859375,32715.9375,56.8728543162753,20.5025789066815,25.566563,0,0,0,40,4449,300.4355,32710.748046875,,,,,,,,,,,,,0,,,,-0.00245,,,,,,299.996521,,,,
,32259639.615,299.9908142,28635.3994140625,-5.63663490140405E-5,1.254561767089E-6,1,0.999253354069792,40.0298881530762,1.996155815699,20.1600007712841,-0.000628600049645755,-0.000159596460157404,0.25,-4.35364169471402E-6,-5.63618340080735E-5,-4.39068922731209E-6,299.9908142,299.9908142,28632.748046875,28638.05078125,57.200356665833,20.5034334339169,25.566563,0,0,0,40,4449,300.44305,28635.3994140625,,,,,,,,,,,,,0,,,,0,,,,,,299.9908142,,,,
,32259717.5,299.9947205,24741.5654296875,-4.38190305187112E-5,9.6642432914854E-7,1,0.999253354069792,40.0298881530762,1.99621643755897,20.1600007712841,-0.000488654867416345,-0.000124252168652278,0.25,-3.40030152940722E-6,-4.38155000698327E-5,-3.42912457587331E-6,299.9947205,299.9947205,24738.90625,24744.224609375,57.3269804859484,20.5061617933353,26.325863,0,0,0,40,4449,300.4439,24741.5654296875,,,,,,,,,,,,,0,,,,-0.0049,,,,,,299.9947205,,,,
,32259796.095,299.9928894,20813.736328125,-2.95404950637515E-5,8.1605054775335E-7,1,0.999253354069792,40.0298881530762,1.99627531091985,20.1600007712841,-0.000327559352267556,-9.4591210465304E-5,0.25,-3.24988051897202E-6,-2.95374819444467E-5,-3.26929833527927E-6,299.9928894,299.9928894,20806.333984375,20821.138671875,57.3457395704099,20.5049855336058,25.946213,0,0,0,40,4449,300.4532,20813.736328125,,,,,,,,,,,,,0,,,,0,,,,,,299.9928894,,,,
,32259878.345,299.9898376,16703.7802734375,-1.66374409487733E-5,8.62447720411252E-7,1,0.999253354069792,40.0298881530762,1.9962346324016,20.1600007712841,-0.000184325982086434,-5.41649542573092E-5,0.25,-1.9092148123415E-6,-1.66356918820586E-5,-1.92015763351741E-6,299.9898376,299.9898376,16693.77734375,16713.783203125,57.383257739333,20.5072943503356,25.946213,0,0,0,40,4449,300.45545,16703.7802734375,,,,,,,,,,,,,0,,,,0,,,,,,299.9898376,,,,
,32259955.05,299.9957275,12868.2705078125,-3.7456871158562E-6,6.20207619480362E-7,1,0.999253354069792,40.0298881530762,1.99633476863631,20.1600007712841,-3.97540105320806E-5,-2.22747071599276E-5,0.25,-1.3214986982387E-6,-3.7447023022231E-6,-1.32393765163502E-6,299.9948425,299.9966125,12830.9501953125,12905.5908203125,57.5481813568907,20.5041080872153,25.946213,0,0,0,40,4449,300.45665,12868.2705078125,,,,,,,,,,,,,0,,,,-0.00245,,,,,,299.9957275,,,,
,32260034.57,300.0001526,8895.26220703125,7.91001086022877E-6,5.1623849376038E-7,1,0.999253354069792,40.0298881530762,1.99625292096051,20.1600007712841,9.14191725758228E-5,3.91448359117136E-6,0.25,-1.02417968523648E-6,7.91045378360177E-6,-1.01891282295353E-6,300.0001526,300.0001526,8887.828125,8902.6962890625,57.3715333115445,20.5076331831322,25.946213,0,0,0,40,4449,300.46185,8895.26220703125,,,,,,,,,,,,,0,,,,0,,,,,,300.0001526,,,,
,32260112.415,299.9947205,5005.01904296875,1.74922847817844E-5,4.29167256749757E-7,1,0.999253354069792,40.0298881530762,1.99616312022693,20.1600007712841,0.000200140197828455,2.02949566732362E-5,0.25,-1.23521166909357E-6,1.7492585898241E-5,-1.22358797667088E-6,299.9947205,299.9947205,5000.02587890625,5010.01220703125,57.2081729510253,20.5061039939745,25.946213,0,0,0,40,4449,300.4606,5005.01904296875,,,,,,,,,,,,,0,,,,-0.00245,,,,,,299.9947205,,,,
,32260188.57,299.9950256,1198.13732910156,2.07181993130425E-5,4.36872188136868E-7,1,0.999253354069792,40.0298881530762,1.99641229140065,20.1600007712841,0.000235316022433355,3.42110440429503E-5,0.25,-5.63348957364572E-7,2.07179593487995E-5,-5.49601266248476E-7,299.9950256,299.9950256,1190.79675292969,1205.47790527344,57.4903408464676,20.5078985253368,25.946213,0,0,0,40,4449,300.46315,1198.13732910156,,,,,,,,,,,,,0,,,,0.00245,,,,,,299.9950256,,,,
,32260261.41,299.997406,-2437.86413574219,-1.97865323185849E-5,5.03944489141099E-7,1,0.999253354069792,40.0298881530762,1.99633841982647,20.1600007712841,-0.000223452041326193,-4.00258263939732E-5,0.25,-1.12567950769158E-7,-1.97858704819588E-5,-1.25676027808744E-7,299.997406,299.997406,-2442.62084960938,-2433.107421875,57.2722664896022,20.5060487138034,25.946213,0,0,0,40,4449,300.4658,-2437.86413574219,,,,,,,,,,,,,0,,,,0,,,,,,299.997406,,,,
,32260337.07,299.997345,-6222.703125,-1.52778059625936E-5,4.01043683909605E-7,1,0.999253354069792,40.0298881530762,1.99629426142259,20.1600007712841,-0.000173197492098449,-2.70562258930466E-5,0.25,2.53515619813729E-7,-1.52775209352198E-5,2.43389518577643E-7,299.997345,299.997345,-6227.65673828125,-6217.74951171875,57.200356665833,20.5026890443742,26.325863,0,0,0,40,4449,300.4552,-6222.703125,,,,,,,,,,,,,0,,,,0,,,,,,299.997345,,,,
,32260416.3,300.0077515,-10181.2202148438,-4.30556636571428E-6,6.0532717975731E-7,1,0.999253354069792,40.0298881530762,1.9963594344033,20.1600007712841,-5.06274140617612E-5,2.85440031469079E-6,0.25,9.9847931636497E-7,-4.30609814362129E-6,9.95599657750879E-7,300.0077515,300.0077515,-10186.078125,-10176.3623046875,57.4879959609099,20.507368275095,25.946213,0,0,0,40,4449,300.45575,-10181.2202148438,,,,,,,,,,,,,0,,,,-0.00245,,,,,,300.0077515,,,,
,32260495.975,300.0047302,-14164.7963867188,8.35525031190882E-6,7.79733050599202E-7,1,0.999253354069792,40.0298881530762,1.99621135531273,20.1600007712841,9.14923772247962E-5,3.34013281953958E-5,0.25,1.50731621396568E-6,8.35400411813294E-6,1.51279747015617E-6,300.0047302,300.0047302,-14169.9130859375,-14159.6796875,57.5083183024099,20.5079205101286,25.946213,0,0,0,40,4449,300.4516,-14164.7963867188,,,,,,,,,,,,,0,,,,0,,,,,,300.0047302,,,,
,32260575.395,300.0095215,-18132.349609375,2.20004155710345E-5,9.53212387415299E-7,1,0.999253354069792,40.0298881530762,1.99599824780435,20.1600007712841,0.000245352555783522,6.21626041817874E-5,0.25,1.68818995396131E-6,2.199864055445E-5,1.70268074060481E-6,300.0095215,300.0095215,-18137.509765625,-18127.189453125,57.5231692442753,20.5088349385606,25.566563,0,0,0,40,4449,300.4322,-18132.349609375,,,,,,,,,,,,,0,,,,-0.0049,,,,,,300.0095215,,,,
,32260656.525,300.0158081,-22189.91015625,3.59995971645061E-5,1.13850585920826E-6,1,0.999253354069792,40.0298881530762,1.99637639064779,20.1600007712841,0.000402701685132391,9.50682660159334E-5,0.25,2.17260243394392E-6,3.5997077189984E-5,2.1963125311706E-6,300.0158081,300.0158081,-22194.890625,-22184.9296875,57.4887775894292,20.5065305838554,26.325863,0,0,0,40,4449,300.4269,-22189.91015625,,,,,,,,,,,,,0,,,,-0.0049,,,,,,300.0158081,,,,
,32260737.345,300.0133057,-26227.447265625,4.87849583233926E-5,1.39281518129391E-6,1,0.999253354069792,40.0298881530762,1.99611298048233,20.1600007712841,0.000545529155279167,0.000129534817050194,0.25,3.00784571934104E-6,4.87815098993852E-5,3.03994748128341E-6,300.0133057,300.0133057,-26232.38671875,-26222.5078125,57.3566823696791,20.5087611594676,25.946213,0,0,0,40,4449,300.4332,-26227.447265625,,,,,,,,,,,,,0,,,,0,,,,,,300.0133057,,,,
,32260818.92,300.0108337,-30305.431640625,6.34535647088844E-5,1.31820379585393E-6,1,0.999253354069792,40.0298881530762,1.99606537146653,20.1600007712841,0.000712886225637504,0.000149178389907475,0.25,2.20464612587709E-6,6.34502160124862E-5,2.24641828683472E-6,300.0108337,300.0108337,-30315.34765625,-30295.515625,57.5810097546984,20.5098641953415,25.946213,0,0,0,40,4449,300.4165,-30305.431640625,,,,,,,,,,,,,0,,,,0,,,,,,300.0108337,,,,
,32260899.995,300.0138855,-34358.318359375,7.79619260881954E-5,1.20167269134579E-6,1,0.999253354069792,40.0298881530762,1.99628220712923,20.1600007712841,0.000871907029297308,0.000206786632589659,0.25,4.78594377326937E-6,7.79564402890802E-5,4.83716012540669E-6,300.0138855,300.0138855,-34368.25,-34348.38671875,57.241001348833,20.5098119470041,25.946213,0,0,0,40,4449,300.41235,-34358.318359375,,,,,,,,,,,,,0,,,,-0.00245,,,,,,300.0138855,,,,
,32260982.68,300.0145874,-38488.296875,9.17868604352006E-5,1.3341426666568E-6,1,0.999253354069792,40.0298881530762,1.99609167052101,20.1600007712841,0.00102981879538089,0.00022386405606277,0.25,3.90330198308682E-6,9.17815470983849E-5,3.96359931204595E-6,300.0145874,300.0145874,-38495.58984375,-38481.00390625,56.9877537086022,20.5104074668429,25.946213,0,0,0,40,4449,300.40175,-38488.296875,,,,,,,,,,,,,0,,,,0.0049,,,,,,300.0145874,,,,
,32261064.32,300.0167847,-42568.720703125,0.000105379792480606,1.5919964249039E-6,1,0.999253354069792,40.0298881530762,1.99611743567344,20.1600007712841,0.00118565629365786,0.000237888068647074,0.25,2.7888055589924E-6,0.000105374805230114,2.85802052457102E-6,300.0167847,300.0167847,-42573.75,-42563.69140625,57.0776409883137,20.5103335658632,26.325863,0,0,0,40,4449,300.3949,-42568.720703125,,,,,,,,,,,,,0,,,,0.00245,,,,,,300.0167847,,,,
,32261145.93,300.0133667,-46649.451171875,0.000120870149513341,2.00035153611E-6,1,0.999253354069792,40.0298881530762,1.99627697521235,20.1600007712841,0.00135844960711068,0.000282094252132197,0.25,4.01418241861861E-6,0.00012086391649312,4.09347674509077E-6,300.0133667,300.0133667,-46661.90234375,-46637,57.4207759082561,20.5108069494569,25.566563,0,0,0,40,4449,300.38255,-46649.451171875,,,,,,,,,,,,,0,,,,-0.00245,,,,,,300.0133667,,,,
,32261226.865,300.0138245,-50692.025390625,0.000135681081762402,1.82364474897653E-6,1,0.999253354069792,40.0298881530762,1.99626159070355,20.1600007712841,0.00152666396981356,0.000306461662321247,0.25,3.60407043116725E-6,0.00013567468486239,3.69302612261689E-6,300.0134888,300.0141602,-50699.61328125,-50684.4375,57.4879959609099,20.5116479572866,26.325863,0,0,0,40,4449,300.3745,-50692.025390625,,,,,,,,,,,,,0,,,,0,,,,,,300.0138245,,,,
,32261306.53,300.01474,-54674.69140625,0.000147752473728046,2.05454740887413E-6,1,0.999253354069792,40.0298881530762,1.99624642023806,20.1600007712841,0.00165667935953312,0.000367191457996165,0.25,6.88546438434968E-6,0.00014774357123766,6.98215914107661E-6,300.01474,300.01474,-54677.09375,-54672.2890625,57.1706547821022,20.5092829136838,25.946213,0,0,0,40,4449,300.3616,-54674.69140625,,,,,,,,,,,,,0,,,,0,,,,,,300.01474,,,,
,32261386.205,300.0157776,-58657.400390625,0.00016462590000116,2.43795808383261E-6,1,0.999253354069792,40.0298881530762,1.99628375077687,20.1600007712841,0.00184860898507009,0.000393532056099733,0.25,6.2918267411273E-6,0.000164616892402024,6.39950548279263E-6,300.0157776,300.0157776,-58659.68359375,-58655.1171875,57.3113479155637,20.5115122968551,26.325863,0,0,0,40,4449,300.35105,-58657.400390625,,,,,,,,,,,,,0,,,,0.0049,,,,,,300.0157776,,,,
,32261467.055,300.01518245,-62698.017578125,0.000177195929291606,2.63622023542355E-6,1,0.999253354069792,40.0298881530762,1.99622150367364,20.1600007712841,0.00198710199870281,0.000438567422531301,0.25,8.09933317974828E-6,0.000177185383324948,8.21508249485634E-6,300.0150146,300.0153503,-62703.25390625,-62692.78125,57.2519441481022,20.513835597532,25.566563,0,0,0,40,4449,300.3454,-62698.017578125,,,,,,,,,,,,,0,,,,0,,,,,,300.01518245,,,,
,32261548.535,300.0118103,-66767.7421875,0.000190145442347706,2.12229176466492E-6,1,0.999253354069792,40.0298881530762,1.99635217685211,20.1600007712841,0.00213862321020834,0.000435035776947594,0.25,5.54109488809785E-6,0.000190136225170111,5.66527510262145E-6,300.0118103,300.0118103,-66775.1796875,-66760.3046875,57.281646031833,20.5118990437069,26.325863,0,0,0,40,4449,300.33835,-66767.7421875,,,,,,,,,,,,,0,,,,-0.00245,,,,,,300.0118103,,,,
,32261632.475,300.0176392,-70962.81640625,0.000207428210256295,2.15235533924756E-6,1,0.999253354069792,40.0298881530762,1.99613776646317,20.1600007712841,0.00233456700294172,0.000464146136254495,0.25,5.12635042489639E-6,0.000207418728751584,5.26170024211965E-6,300.0176392,300.0176392,-70968.0234375,-70957.609375,57.2402197203138,20.5147349070072,26.325863,0,0,0,40,4449,300.3399,-70962.81640625,,,,,,,,,,,,,0,,,,0,,,,,,300.0176392,,,,
,32261712.525,300.0152283,-74965.234375,0.000221588679119949,2.65248738683138E-6,1,0.999253354069792,40.0298881530762,1.99609520518447,20.1600007712841,0.00249253344534324,0.000503652869171024,0.25,6.1692647707922E-6,0.000221578132337263,6.31370212338727E-6,300.0152283,300.0152283,-74970.1171875,-74960.3515625,57.322290714833,20.5120263226732,26.325863,0,0,0,40,4449,300.3145,-74965.234375,,,,,,,,,,,,,0,,,,0,,,,,,300.0152283,,,,
,32261794.97,300.0166016,-79085.60546875,0.000236035045737962,2.4405464325627E-6,1,0.999253354069792,40.0298881530762,1.99604411936056,20.1600007712841,0.00265725104715349,0.000523298289674696,0.25,5.40580723956571E-6,0.000236024577985696,5.55953851511885E-6,300.0166016,300.0166016,-79093.109375,-79078.1015625,57.2746113751599,20.5135851391518,26.325863,0,0,0,40,4449,300.30495,-79085.60546875,,,,,,,,,,,,,0,,,,0,,,,,,300.0166016,,,,
,32261877.35,300.0113831,-83200.8125,0.000249947160735327,2.63732725909417E-6,1,0.999253354069792,40.0298881530762,1.99619376494462,20.1600007712841,0.00281189751776091,0.0005667438662544,0.25,6.83594416826368E-6,0.000249935417780485,6.9985363248952E-6,300.0113831,300.0113831,-83205.78125,-83195.84375,57.2878990599868,20.5133480408893,25.946213,0,0,0,40,4449,300.2982,-83200.8125,,,,,,,,,,,,,0,,,,0,,,,,,300.0113831,,,,
,32261957.36,300.02101135,-87200.6484375,0.000264632832065266,3.16430680050543E-6,1,0.999253354069792,40.0298881530762,1.9959135430149,20.1600007712841,0.00297395576253577,0.000615866784104561,0.25,8.64498123740397E-6,0.000264619411947442,8.81690984913261E-6,300.0209351,300.0210876,-87203.0703125,-87198.2265625,57.2878990599868,20.5167889649161,25.946213,0,0,0,40,4449,300.28795,-87200.6484375,,,,,,,,,,,,,0,,,,0,,,,,,300.02101135,,,,
,32262053.495,300.0148621,-88897.1328125,0.000271596626628531,2.73831866331967E-6,1,0.999253354069792,40.0298881530762,1.99593337362378,20.1600007712841,0.00305811123741795,0.000598218352322721,0.25,5.8765541339856E-6,0.000271584870793473,6.05302272476924E-6,300.0148621,300.0148621,-88902.1953125,-88892.0703125,57.3863842534099,20.5177926602127,26.325863,0,0,0,40,4449,300.2811,-88897.1328125,,,,,,,,,,,,,0,,,,0,,,,,,300.0148621,,,,
,32262132.81,300.0052185,-84935.3125,0.000257945690499519,3.88660766772259E-6,1,0.999253354069792,40.0298881530762,1.99612808474372,20.1600007712841,0.0029108535594792,0.000532547991199165,0.25,2.42650624751637E-6,0.000257936649020481,2.59437807221933E-6,300.0052185,300.0052185,-84945.40625,-84925.21875,57.1175040427945,20.5146854473549,26.325863,0,0,0,40,4449,300.27225,-84935.3125,,,,,,,,,,,,,0,,,,0,,,,,,300.0052185,,,,
,32262216.25,300.0035706,-80762.70703125,0.000243072501410096,2.62372712200229E-6,1,0.999253354069792,40.0298881530762,1.9958755232547,20.1600007712841,0.00273821452197019,0.000527567166008396,0.25,4.56805586394988E-6,0.000243062491879344,4.72635338024487E-6,300.0035706,300.0035706,-80767.6015625,-80757.8125,57.1980117802753,20.5179537671953,25.946213,0,0,0,40,4449,300.27295,-80762.70703125,,,,,,,,,,,,,0,,,,0.00245,,,,,,300.0035706,,,,
,32262298.795,299.9984131,-76639.98828125,0.000225871293082081,3.15694316312523E-6,1,0.999253354069792,40.0298881530762,1.99583312396869,20.1600007712841,0.00253748696405922,0.000530076360321302,0.25,7.77094011791538E-6,0.000225859716464652,7.91808899999482E-6,299.9984131,299.9984131,-76649.6953125,-76630.28125,57.3347967711407,20.5172692341887,25.946213,0,0,0,40,4449,300.27625,-76639.98828125,,,,,,,,,,,,,0,,,,0.0049,,,,,,299.9984131,,,,
,32262379.365,300.0027466,-72611.9296875,0.000212110367839758,2.81638690777221E-6,1,0.999253354069792,40.0298881530762,1.99568647446403,20.1600007712841,0.00238666596175876,0.000475005899195258,0.25,5.28500587515322E-6,0.000212100760249044,5.4233904247013E-6,300.0027466,300.0027466,-72617.046875,-72606.8125,57.4285921934484,20.5211342945797,26.325863,0,0,0,40,4449,300.2734,-72611.9296875,,,,,,,,,,,,,0,,,,0.0049,,,,,,300.0027466,,,,
,32262460.82,299.9880676,-68542.1015625,0.000197750776480711,2.25007154273901E-6,1,0.999253354069792,40.0298881530762,1.99597094488756,20.1600007712841,0.00222701871847144,0.000433540304073004,0.25,4.09816485704494E-6,0.000197742451027229,4.22733527047492E-6,299.9880676,299.9880676,-68554.1640625,-68530.0390625,57.4676736194099,20.5200690980679,25.946213,0,0,0,40,4449,300.2823,-68542.1015625,,,,,,,,,,,,,0,,,,0,,,,,,299.9880676,,,,
,32262545.12,299.9934387,-64329.38671875,0.000182931579152954,2.67469510763598E-6,1,0.999253354069792,40.0298881530762,1.99564995636381,20.1600007712841,0.00205648333410892,0.000420202227324065,0.25,5.49106798893685E-6,0.000182922716092926,5.61063271920166E-6,299.9934387,299.9934387,-64331.7265625,-64327.046875,57.3605905122753,20.5220237399015,26.325863,0,0,0,40,4449,300.2859,-64329.38671875,,,,,,,,,,,,,0,,,,0,,,,,,299.9934387,,,,
,32262628.46,299.9926453,-60161.703125,0.000167470416136913,2.27885254990748E-6,1,0.999253354069792,40.0298881530762,1.99568606031666,20.1600007712841,0.0018834341831618,0.000380480342593187,0.25,4.65400819220352E-6,0.000167462538201614,4.76358798791238E-6,299.9926453,299.9926453,-60169.10546875,-60154.30078125,57.1221938139099,20.5240019727983,25.946213,0,0,0,40,4449,300.2924,-60161.703125,,,,,,,,,,,,,0,,,,0.00245,,,,,,299.9926453,,,,
,32262712.75,299.9934387,-55949.033203125,0.00015319398583089,1.87989804336928E-6,1,0.999253354069792,40.0298881530762,1.99552108651519,20.1600007712841,0.00171940873654937,0.000367245964176165,0.25,5.95878365090429E-6,0.000153185647354607,6.05907439069505E-6,299.9934387,299.9934387,-55961.78125,-55936.28515625,57.3863842534099,20.5247628745295,26.705515,0,0,0,40,4449,300.29505,-55949.033203125,,,,,,,,,,,,,0,,,,-0.00245,,,,,,299.9934387,,,,
,32262797.65,299.986908,-51709.177734375,0.000140485501113196,1.67426202996269E-6,1,0.999253354069792,40.0298881530762,1.99578282154452,20.1600007712841,0.00157913246775772,0.00032433938055226,0.25,4.35978724679278E-6,0.000140478600957927,4.45188083135196E-6,299.986908,299.986908,-51719.07421875,-51699.28125,57.4387533641984,20.520215913667,26.325863,0,0,0,40,4449,300.3059,-51709.177734375,,,,,,,,,,,,,0,,,,0,,,,,,299.986908,,,,
,32262882.08,299.9879456,-47486.51171875,0.00012474844773462,1.91891787333971E-6,1,0.999253354069792,40.0298881530762,1.99586802606761,20.1600007712841,0.00140047523641969,0.000298531152719343,0.25,4.80147457200773E-6,0.00012474169551468,4.88330178346192E-6,299.9872437,299.9886475,-47496.5625,-47476.4609375,57.2355299491984,20.5172615010536,25.946213,0,0,0,40,4449,300.32065,-47486.51171875,,,,,,,,,,,,,0,,,,-0.00245,,,,,,299.9879456,,,,
,32262962.665,299.9897156,-43461.013671875,0.000108636618573683,1.47899661464888E-6,1,0.999253354069792,40.0298881530762,1.9958422020451,20.1600007712841,0.00121938803114194,0.000261092326068916,0.25,4.28047425312164E-6,0.000108630658156304,4.35179373105816E-6,299.9897156,299.9897156,-43468.5859375,-43453.44140625,56.8056342636214,20.5186881209639,26.325863,0,0,0,40,4449,300.33085,-43461.013671875,,,,,,,,,,,,,0,,,,0,,,,,,299.9897156,,,,
,32263043.12,299.9812622,-39438.060546875,9.65784385924724E-5,1.53491002948003E-6,1,0.999253354069792,40.0298881530762,1.995762643266,20.1600007712841,0.00108607764505566,0.000220113900462247,0.25,2.74438867320635E-6,9.65738597188399E-5,2.80788366630831E-6,299.9812622,299.9812622,-39440.62109375,-39435.5,57.5599057846792,20.5149770888585,26.705515,0,0,0,40,4449,300.3234,-39438.060546875,,,,,,,,,,,,,0,,,,0,,,,,,299.9812622,,,,
,32263122.155,299.9832764,-35487.98828125,7.9719706527087E-5,1.29463454844963E-6,1,0.999253354069792,40.0298881530762,1.99582985572871,20.1600007712841,0.000895065228171775,0.000190096943797444,0.25,3.00857132762546E-6,7.97154261736537E-5,3.061006141913E-6,299.9832764,299.9832764,-35497.91796875,-35478.05859375,57.3777863396984,20.5186197977593,26.705515,0,0,0,40,4449,300.32945,-35487.98828125,,,,,,,,,,,,,0,,,,0,,,,,,299.9832764,,,,
,32263203.88,299.9891357,-31405.9501953125,6.54998009006238E-5,1.48990098117891E-6,1,0.999253354069792,40.0298881530762,1.99579091503189,20.1600007712841,0.000737177518834749,0.000145898209483911,0.25,1.56159558841333E-6,6.54968657796819E-5,1.60474055027221E-6,299.9891357,299.9891357,-31415.9453125,-31395.955078125,57.2097362080637,20.5131715921594,26.325863,0,0,0,40,4449,300.3372,-31405.9501953125,,,,,,,,,,,,,0,,,,0.0049,,,,,,299.9891357,,,,
,32263285.085,299.9879456,-27346.0947265625,5.34821360928865E-5,1.1507490556684E-6,1,0.999253354069792,40.0298881530762,1.99598471510893,20.1600007712841,0.00060188946889233,0.00011965512604678,0.25,1.3205949621603E-6,5.34797085524904E-5,1.355850667767E-6,299.9879456,299.9879456,-27348.865234375,-27343.32421875,57.2902439455445,20.5115468776044,26.705515,0,0,0,40,4449,300.355,-27346.0947265625,,,,,,,,,,,,,0,,,,0,,,,,,299.9879456,,,,
,32263365.72,299.9930725,-23317.55859375,3.90096848807925E-5,1.26289795470508E-6,1,0.999253354069792,40.0298881530762,1.99580051678048,20.1600007712841,0.000435930940356708,0.000104851311380276,0.25,2.51904197179168E-6,3.90068770058835E-5,2.54473314364157E-6,299.9930725,299.9930725,-23324.845703125,-23310.271484375,57.0948368157368,20.51470910066,26.705515,0,0,0,40,4449,300.35405,-23317.55859375,,,,,,,,,,,,,0,,,,0,,,,,,299.9930725,,,,
,32263444.185,299.9937744,-19394.765625,2.5341906453889E-5,1.14129513908029E-6,1,0.999253354069792,40.0298881530762,1.99565410545368,20.1600007712841,0.000282593799080752,7.1461329691011E-5,0.25,1.93300632229847E-6,2.5339883722908E-5,1.94970015266854E-6,299.9937744,299.9937744,-19402.337890625,-19387.193359375,57.4809613042369,20.5176651312004,26.325863,0,0,0,40,4449,300.3588,-19394.765625,,,,,,,,,,,,,0,,,,0,,,,,,299.9937744,,,,
,32263521.745,299.9937439,-15519.4516601562,1.22264974997818E-5,9.13387364038371E-7,1,0.999253354069792,40.0298881530762,1.99604156446033,20.1600007712841,0.000135192113158343,4.12586417504613E-5,0.25,1.53200234388131E-6,1.22251241444056E-5,1.54004475087908E-6,299.9937439,299.9937439,-15529.4931640625,-15509.41015625,57.4731450190445,20.512578629872,26.325863,0,0,0,40,4449,300.3615,-15519.4516601562,,,,,,,,,,,,,0,,,,0,,,,,,299.9937439,,,,
,32263602.17,299.99632265,-11498.8237304688,5.81227673600681E-8,7.27352640579153E-7,1,0.999253354069792,40.0298881530762,1.99598672969293,20.1600007712841,-1.91599406908134E-7,5.01126982082531E-6,0.25,4.33311463920743E-7,5.78342239859661E-8,4.33337121676413E-7,299.9960938,299.9965515,-11501.541015625,-11496.1064453125,57.0721695886791,20.5126487265833,26.325863,0,0,0,40,4449,300.3717,-11498.8237304688,,,,,,,,,,,,,0,,,,-0.0049,,,,,,299.99632265,,,,
,32263684.395,299.9924011,-7390.2421875,-1.14271205665197E-5,5.51380070992848E-7,1,0.999253354069792,40.0298881530762,1.99582744386954,20.1600007712841,-0.000129906510969738,-1.79734809697307E-5,0.25,3.89491768321656E-7,-1.14270417288744E-5,3.81911020541989E-7,299.9924011,299.9924011,-7397.6708984375,-7382.8134765625,57.3762230826599,20.5115405673371,26.705515,0,0,0,40,4449,300.3738,-7390.2421875,,,,,,,,,,,,,0,,,,-0.0049,,,,,,299.9924011,,,,
,32263766.61,299.9940186,-3279.39147949219,-2.05252722413395E-5,5.05131785637691E-7,1,0.999253354069792,40.0298881530762,1.99586281533801,20.1600007712841,-0.000231654077601951,-4.20185210124751E-5,0.25,-1.61694089767857E-7,-2.05245581051365E-5,-1.75293506221562E-7,299.9940186,299.9940186,-3289.40795898438,-3269.375,57.0205821064099,20.5119791410962,25.946213,0,0,0,40,4449,300.37635,-3279.39147949219,,,,,,,,,,,,,0,,,,-0.00245,,,,,,299.9940186,,,,
,32263844.97,299.9973755,636.823669433594,1.56727036560782E-5,4.27540952243955E-7,1,0.999253354069792,40.0298881530762,1.99579054442073,20.1600007712841,0.000177429242256025,2.89160558753144E-5,0.25,-1.56802117692544E-7,1.56723419544097E-5,-1.46406137276061E-7,299.9973755,299.9973755,634.229675292969,639.417663574219,57.3918556530445,20.5129380636944,26.325863,0,0,0,40,4449,300.3755,636.823669433594,,,,,,,,,,,,,0,,,,0,,,,,,299.9973755,,,,
,32263925.86,299.9992981,4676.82788085937,1.83016211632254E-5,5.18990715618827E-7,1,0.999253354069792,40.0298881530762,1.99577147918599,20.1600007712841,0.000206722130644393,3.64611678876736E-5,0.25,5.53795393811589E-8,1.83010399856851E-5,6.75060209183829E-8,299.9992981,299.9992981,4669.00634765625,4684.6494140625,57.4192126512176,20.5129108148101,25.946213,0,0,0,40,4449,300.3719,4676.82788085937,,,,,,,,,,,,,0,,,,-0.0049,,,,,,299.9992981,,,,
,32264007.195,299.9967041,8742.5869140625,8.71367766178288E-6,6.30285414899965E-7,1,0.999253354069792,40.0298881530762,1.99583628764007,20.1600007712841,9.94515075741158E-5,1.14446979594148E-5,0.25,-4.97056879061063E-7,8.71374875446596E-6,-4.91271569168018E-7,299.9967041,299.9967041,8737.5263671875,8747.6474609375,57.2128627221407,20.5137329230851,26.325863,0,0,0,40,4449,300.3744,8742.5869140625,,,,,,,,,,,,,0,,,,0,,,,,,299.9967041,,,,
,32264089.235,300.0013733,12843.4462890625,-3.05723329352616E-6,6.17699520059136E-7,1,0.999253354069792,40.0298881530762,1.99582250463283,20.1600007712841,-3.21216603979778E-5,-2.00095279388932E-5,0.25,-1.24082959456644E-6,-3.05632121646857E-6,-1.24281587834978E-6,300.0013733,300.0013733,12836.0224609375,12850.8701171875,57.2245871499291,20.5125874774876,26.325863,0,0,0,40,4449,300.37325,12843.4462890625,,,,,,,,,,,,,0,,,,0,,,,,,300.0013733,,,,
,32264174.86,300.0049438,17123.7314453125,-1.78805650309926E-5,1.06281362700092E-6,1,0.999253354069792,40.0298881530762,1.99592430421203,20.1600007712841,-0.000198872626610554,-5.35652429363265E-5,0.25,-1.64148267524212E-6,-1.78789463189551E-5,-1.65325726392789E-6,300.0049438,300.0049438,17113.580078125,17133.8828125,57.4020168237945,20.5099194077208,25.946213,0,0,0,40,4449,300.3694,17123.7314453125,,,,,,,,,,,,,0,,,,0.00245,,,,,,300.0049438,,,,
,32264257.28,300.0048523,21241.5830078125,-3.23071024608194E-5,1.30558433840615E-6,1,0.999253354069792,40.0298881530762,1.99607771171689,20.1600007712841,-0.000362165692102412,-8.05675834701108E-5,0.25,-1.53062192005089E-6,-3.23051292420709E-5,-1.55192236411942E-6,300.0048523,300.0048523,21236.638671875,21246.52734375,57.2964969736984,20.5079397155897,26.705515,0,0,0,40,4449,300.36705,21241.5830078125,,,,,,,,,,,,,0,,,,0.00245,,,,,,300.0048523,,,,
,32264340.93,300.0088043,25422.0771484375,-4.60897975843735E-5,1.12947503435092E-6,1,0.999253354069792,40.0298881530762,1.99610941807387,20.1600007712841,-0.000517797350809335,-0.000108484711344194,0.25,-1.61246492037543E-6,-4.60873565715456E-5,-1.64284375664222E-6,300.008728,300.0088806,25414.603515625,25429.55078125,57.4708001334869,20.5081947881778,26.705515,0,0,0,40,4449,300.36325,25422.0771484375,,,,,,,,,,,,,0,,,,-0.00245,,,,,,300.0088043,,,,
,32264421.365,300.0110474,29443.5419921875,-5.84002011343713E-5,1.23894793572846E-6,1,0.999253354069792,40.0298881530762,1.99585065452621,20.1600007712841,-0.00065625074662878,-0.000136098981761266,0.25,-1.92420807446819E-6,-5.83971856543607E-5,-1.96267426086479E-6,300.0110474,300.0110474,29438.763671875,29448.3203125,57.1847240954484,20.5080375816141,26.325863,0,0,0,40,4449,300.3468,29443.5419921875,,,,,,,,,,,,,0,,,,0.0049,,,,,,300.0110474,,,,
,32264504.11,300.0125122,33578.927734375,-7.32124407381425E-5,1.3114300744175E-6,1,0.999253354069792,40.0298881530762,1.99598703483714,20.1600007712841,-0.000825001009273843,-0.000157645616841527,0.25,-1.26353273114878E-6,-7.32094188317741E-5,-1.31174745898733E-6,300.0125122,300.0125122,33576.171875,33581.68359375,57.0799858738714,20.5091562831476,25.946213,0,0,0,40,4449,300.34075,33578.927734375,,,,,,,,,,,,,0,,,,0.0049,,,,,,300.0125122,,,,
,32264586.41,300.0165405,37693.78515625,-8.7452538715495E-5,1.23521758324267E-6,1,0.999253354069792,40.0298881530762,1.99596673480655,20.1600007712841,-0.000986177292018276,-0.000184150130915174,0.25,-1.14160179790196E-6,-8.74491636833898E-5,-1.19915695467788E-6,300.0165405,300.0165405,37689.03515625,37698.53515625,57.2417829773522,20.5076863188681,26.325863,0,0,0,40,4449,300.3221,37693.78515625,,,,,,,,,,,,,0,,,,0.00245,,,,,,300.0165405,,,,
,32264669.75,300.0138855,41859.470703125,-0.00010165066504143,1.71319816550698E-6,1,0.999253354069792,40.0298881530762,1.99596158126139,20.1600007712841,-0.00114725566720401,-0.00020843195389054,0.25,-8.30212506165429E-7,-0.00010164708502624,-8.97063811523779E-7,300.0138855,300.0138855,41851.671875,41867.26953125,57.1753445532176,20.5076229125642,26.325863,0,0,0,40,4449,300.32185,41859.470703125,,,,,,,,,,,,,0,,,,0.0049,,,,,,300.0138855,,,,
,32264751.095,300.0084534,45925.158203125,-0.000116922096398778,1.35970199626713E-6,1,0.999253354069792,40.0298881530762,1.99592776562331,20.1600007712841,-0.00131520815163987,-0.000265044754373625,0.25,-3.19379934496742E-6,-0.000116916536710607,-3.27055684606595E-6,300.0084534,300.0084534,45915.08984375,45935.2265625,56.9815006804483,20.5058285535588,26.325863,0,0,0,40,4449,300.31845,45925.158203125,,,,,,,,,,,,,0,,,,-0.0049,,,,,,300.0084534,,,,
,32264834.235,300.0115051,50078.47265625,-0.00013160683034914,1.71700684876395E-6,1,0.999253354069792,40.0298881530762,1.99587943231647,20.1600007712841,-0.00148272220635212,-0.000284670487655291,0.25,-2.38675317623776E-6,-0.000131601361023478,-2.47310341205576E-6,300.0115051,300.0115051,50073.359375,50083.5859375,56.811105663256,20.508243746701,26.705515,0,0,0,40,4449,300.315,50078.47265625,,,,,,,,,,,,,0,,,,0,,,,,,300.0115051,,,,
,32264919.56,300.0112305,54343.685546875,-0.000145853273798561,2.12916373101242E-6,1,0.999253354069792,40.0298881530762,1.99595135425604,20.1600007712841,-0.00164665104120594,-0.000296060193693186,0.25,-9.25479013824516E-7,-0.00014584835182617,-1.02113611819416E-6,300.0112305,300.0112305,54336.20703125,54351.1640625,57.1683098965445,20.5076194603142,25.946213,0,0,0,40,4449,300.29935,54343.685546875,,,,,,,,,,,,,0,,,,-0.00245,,,,,,300.0112305,,,,
,32265005.705,300.0146179,58651.44921875,-0.000162707372419639,1.89257535647015E-6,1,0.999253354069792,40.0298881530762,1.99595445454079,20.1600007712841,-0.0018367769391248,-0.000331170884101939,0.25,-1.11206514008796E-6,-0.000162701819800987,-1.21866756693472E-6,300.0146179,300.0146179,58643.796875,58659.1015625,57.126101956506,20.5077597164429,26.325863,0,0,0,40,4449,300.28635,58651.44921875,,,,,,,,,,,,,0,,,,0.00245,,,,,,300.0146179,,,,
,32265091.85,300.0123291,62957.57421875,-0.000178781380228094,1.95084616722392E-6,1,0.999253354069792,40.0298881530762,1.99599270303028,20.1600007712841,-0.00201959538748379,-0.000356249918800476,0.25,-5.45702382216596E-7,-0.000178775748039475,-6.62735774667403E-7,300.0123291,300.0123291,62947.8515625,62967.296875,57.1620568683907,20.5073545253811,26.325863,0,0,0,40,4449,300.2791,62957.57421875,,,,,,,,,,,,,0,,,,0.0049,,,,,,300.0123291,,,,
,32265174.545,300.0111389,67087.7890625,-0.000195447460338847,2.40206519042846E-6,1,0.999253354069792,40.0298881530762,1.99590570088354,20.1600007712841,-0.00220628828599002,-0.000398003723621558,0.25,-1.35410941879955E-6,-0.000195440827854001,-1.48190167002317E-6,300.0111389,300.0111389,67080.3203125,67095.2578125,56.9783741663714,20.5083745469932,26.325863,0,0,0,40,4449,300.2741,67087.7890625,,,,,,,,,,,,,0,,,,0,,,,,,300.0111389,,,,
,32265259.07,300.0131531,71313.55078125,-0.000209062009136244,2.03997816460608E-6,1,0.999253354069792,40.0298881530762,1.99600990662787,20.1600007712841,-0.00236023585273066,-0.000424920540604805,0.25,-1.37525546707903E-6,-0.000209054960647026,-1.51181256250135E-6,300.0131531,300.0131531,71308.4609375,71318.640625,57.220679007333,20.5075808302943,26.325863,0,0,0,40,4449,300.2625,71313.55078125,,,,,,,,,,,,,0,,,,-0.0049,,,,,,300.0131531,,,,
,32265344.81,300.0159302,75598.9921875,-0.000221128769780338,2.80350908196191E-6,1,0.999253354069792,40.0298881530762,1.99595620376545,20.1600007712841,-0.00249600667691132,-0.000451711411092753,0.25,-1.65621616747536E-6,-0.000221121175304415,-1.8004972636543E-6,300.0159302,300.0159302,75591.59375,75606.390625,57.2855541744291,20.5071125240383,26.705515,0,0,0,40,4449,300.25275,75598.9921875,,,,,,,,,,,,,0,,,,0,,,,,,300.0159302,,,,
,32265428.32,300.0162659,79774.9609375,-0.000236741125184453,2.73766034896574E-6,1,0.999253354069792,40.0298881530762,1.99597638525836,20.1600007712841,-0.0026714764614521,-0.000488120369496438,0.25,-2.17252331213661E-6,-0.000236732746324612,-2.32682265787286E-6,300.0162659,300.0162659,79769.8984375,79780.0234375,56.9197520274291,20.5059751628137,26.325863,0,0,0,40,4449,300.2379,79774.9609375,,,,,,,,,,,,,0,,,,-0.0049,,,,,,300.0162659,,,,
,32265513.015,300.0150146,84008.484375,-0.000253511274478913,2.47803891117436E-6,1,0.999253354069792,40.0298881530762,1.99595510689097,20.1600007712841,-0.00286003650058959,-0.000526455075719623,0.25,-2.65951547640819E-6,-0.000253502113720989,-2.82455944717668E-6,300.0150146,300.0150146,84003.4921875,84013.4765625,57.1331366131791,20.5057779752979,25.946213,0,0,0,40,4449,300.2296,84008.484375,,,,,,,,,,,,,0,,,,-0.0049,,,,,,300.0150146,,,,
,32265590.005,300.0127563,87857.09765625,-0.00026642927524582,2.16739943443639E-6,1,0.999253354069792,40.0298881530762,1.99606028793697,20.1600007712841,-0.00300855794931893,-0.000538111781010607,0.25,-1.45063572084252E-6,-0.000266420561031165,-1.62395819845818E-6,300.0127563,300.0127563,87847.0234375,87867.171875,57.1284468420637,20.5048442652357,26.325863,0,0,0,40,4449,300.22445,87857.09765625,,,,,,,,,,,,,0,,,,0.0049,,,,,,300.0127563,,,,
,32265633.86,300.0155334,89999.55078125,-0.000273666217316725,3.13077813358509E-6,1,0.999253354069792,40.0298881530762,1.99588063202862,20.1600007712841,-0.00308816113194289,-0.000563369248862618,0.25,-2.4358611107969E-6,-0.000273656633248826,-2.61376512019665E-6,300.0155334,300.0155334,89999.515625,89999.5859375,57.2824276603522,20.5056787704053,26.325863,0,0,0,40,4417,300.2219,89999.55078125,,,,,,,,,,,,,0,,,,-0.00245,,,,,,300.0155334,,,,