File: data/monolayers/magneticStructure/ML_Ac_CoFe_C/PPMS/data/DD205_4_HYST_100OE_150K.DAT
[Header]
; VSM Data File (default extension .dat)
; Copyright (c) 2003-2013, Quantum Design, Inc. All rights reserved.
TITLE,
FILEOPENTIME,32390624.11,01/11/2019,5:26 am
BYAPP,VSM,2.0,2.0
INFO,PPMS VSM Option Release 1.4.10 Build 1,APPNAME
INFO,Quantum Design Linear Motor Servo Controller,MOTOR_MODULE_NAME
INFO,3101-100 M1,MOTOR_HW_VERSION
INFO,MMC1014,MOTOR_SERIAL_NUMBER
INFO,SRV No X-over 01.03.11,MOTOR_SOFTWARE_VERSION
INFO,Quantum Design VSM Detection Module,VSM_MODULE_NAME
INFO,3101-150 F0,VSM_HW_VERSION
INFO,VSM707,VSM_SERIAL_NUMBER
INFO,VSM No X-over 01.02.05 May 20 2008 13:51:47,VSM_SOFTWARE_VERSION
INFO,704,PREAMP_SERIAL_NUMBER
INFO,822,COIL_SERIAL_NUMBER
INFO,0,MOMENT_UNITS
INFO,DD205_4,SAMPLE_MATERIAL
INFO,Monolayer,SAMPLE_COMMENT
INFO,29.55,SAMPLE_MASS
INFO,,SAMPLE_VOLUME
INFO,,SAMPLE_MOLECULAR_WEIGHT
INFO,,SAMPLE_SIZE
INFO,,SAMPLE_SHAPE
DATATYPE,COMMENT,1
DATATYPE,TIME,2
STARTUPAXIS,X,2
STARTUPAXIS,Y1,5
[Data]
Comment,Time Stamp (sec),Temperature (K),Magnetic Field (Oe),Moment (emu),M. Std. Err. (emu),Transport Action,Averaging Time (sec),Frequency (Hz),Peak Amplitude (mm),Center Position (mm),Coil Signal' (mV),Coil Signal" (mV),Range (mV),M. Quad. Signal (emu),M. Raw' (emu),M. Raw" (emu),Min. Temperature (K),Max. Temperature (K),Min. Field (Oe),Max. Field (Oe),Mass (grams),Motor Lag (deg),Pressure (Torr),VSM Status (code),Motor Status (code),Measure Status (code),Measure Count,PPMS Status (code),System Temp. (K),System Field (Oe),Sample Position (deg),Bridge 1 Resistance (ohms),Bridge 1 Excitation (에),Bridge 2 Resistance (ohms),Bridge 2 Excitation (에),Bridge 3 Resistance (ohms),Bridge 3 Excitation (에),Bridge 4 Resistance (ohms),Bridge 4 Excitation (에),Signal 1 Vin (V),Signal 2 Vin (V),Digital Inputs (code),Drive 1 Iout (mA),Drive 1 Ipower (W),Drive 2 Iout (mA),Drive 2 Ipower (W),Pressure (),Map 20 (),Map 21 (),Map 22 (),Map 23 (),Map 24 (),Map 25 (),Map 26 (),Map 27 (),Map 28 (),Map 29 ()
,32390639.77,149.9844513,-0.0913426354527473,,,2,,,,20.7299995943904,,,,,,,149.9844513,149.9844513,-0.0913426354527473,-0.0913426354527473,,,24.427608,,,,-99999999,4369,149.8921,-0.0913426354527473,,,,,,,,,,,,,,,,,,,,,,,149.9844513,,,,
,32390786.62,149.9806061,4508.66967773438,1.66976506289171E-5,4.38860290825122E-7,1,0.999253354069792,40.0298881530762,1.99623109274254,20.7199994474649,0.000191628066771457,2.16570563054396E-5,0.25,-1.00222843137107E-6,1.67810535363405E-5,-9.80369406858032E-7,149.9806061,149.9806061,4501.32177734375,4516.017578125,56.2522412720059,20.4921035603362,25.186911,0,0,0,40,4449,149.9203,4508.66967773438,,,,,,,,,,,,,0,,,,0,,,,,,149.9806061,,,,
,32390880.47,149.9871521,9194.95263671875,6.6254870434189E-6,6.56458756903031E-7,1,0.999253354069792,40.0298881530762,1.99618713786616,20.7199994474649,7.98020104435858E-5,-1.30303948207343E-5,0.25,-2.30157715978353E-6,6.66162862708909E-6,-2.30225517722491E-6,149.9871521,149.9871521,9187.4853515625,9202.419921875,56.5328459104098,20.5080252499485,25.186911,0,0,0,40,4449,149.92915,9194.95263671875,,,,,,,,,,,,,0,,,,0,,,,,,149.9871521,,,,
,32390977.115,149.9915619,14027.5141601562,-5.96566820084004E-6,1.67359656696419E-6,1,0.999253354069792,40.0298881530762,1.99621429580936,20.7199994474649,-6.33047383066399E-5,-3.73499939203263E-5,0.25,-2.24927639021423E-6,-5.9913111260172E-6,-2.26981672907042E-6,149.9915619,149.9915619,14025.033203125,14029.9951171875,56.5727089648906,20.5043564446517,24.807261,0,0,0,40,4449,149.9341,14027.5141601562,,,,,,,,,,,,,0,,,,-0.00245,,,,,,149.9915619,,,,
,32391072.94,149.9964676,18815.056640625,-2.30974307383741E-5,1.41624663331958E-6,1,0.999253354069792,40.0298881530762,1.99607044497269,20.7199994474649,-0.000253546916911596,-9.60101823015626E-5,0.25,-4.43025698470352E-6,-2.32035764310275E-5,-4.48872595541332E-6,149.9959717,149.9969635,18807.630859375,18822.482421875,56.7235632691022,20.5088178229409,25.186911,0,0,0,40,4449,149.9395,18815.056640625,,,,,,,,,,,,,0,,,,-0.00245,,,,,,149.9964676,,,,
,32391166.835,149.9984894,23509.9228515625,-4.13420733384873E-5,1.4521992225465E-6,1,0.999253354069792,40.0298881530762,1.99596586342989,20.7199994474649,-0.000454379630728826,-0.000168521498391627,0.25,-7.637653860089E-6,-4.15325966815988E-5,-7.74070738071055E-6,149.9984894,149.9984894,23504.962890625,23514.8828125,57.0862389020253,20.5108523655627,24.807261,0,0,0,40,4449,149.94,23509.9228515625,,,,,,,,,,,,,0,,,,0,,,,,,149.9984894,,,,
,32391260.61,150.0001678,28198.0419921875,-5.38586383678288E-5,1.80257831116285E-6,1,0.999253354069792,40.0298881530762,1.99605319820571,20.7199994474649,-0.000603546400185946,-0.000153105934449902,0.25,-4.0994200563435E-6,-5.4116195882342E-5,-4.2047659885089E-6,150.0001678,150.0001678,28188.21484375,28207.869140625,56.9064643426022,20.504905759928,24.807261,0,0,0,40,4449,149.93745,28198.0419921875,,,,,,,,,,,,,0,,,,0,,,,,,150.0001678,,,,
,32391356.63,150.0018768,32995.53125,-6.95371604519706E-5,1.89605796703632E-6,1,0.999253354069792,40.0298881530762,1.99612734965583,20.7199994474649,-0.000785227586150368,-0.000163484880289921,0.25,-2.28193097847826E-6,-6.98745364634977E-5,-2.40286595806765E-6,150.0018768,150.0018768,32985.53515625,33005.52734375,56.8368994043906,20.5083401925802,24.427608,0,0,0,40,4449,149.936,32995.53125,,,,,,,,,,,,,0,,,,-0.0049,,,,,,150.0018768,,,,
,32391451.42,150.0072174,37733.029296875,-8.58173696652301E-5,2.01451410458991E-6,1,0.999253354069792,40.0298881530762,1.99601604900918,20.7199994474649,-0.000965179859274102,-0.000223774618147587,0.25,-4.75596688926176E-6,-8.62307654709213E-5,-4.91433931917684E-6,150.0072174,150.0072174,37723.1484375,37742.91015625,56.8228300910445,20.5124471092592,24.807261,0,0,0,40,4449,149.92995,37733.029296875,,,,,,,,,,,,,0,,,,-0.00245,,,,,,150.0072174,,,,
,32391546.68,150.0074768,42493.18359375,-0.000104576285317728,2.06732613342864E-6,1,0.999253354069792,40.0298881530762,1.99593210839471,20.7199994474649,-0.00117039347416349,-0.000305520145992973,0.25,-8.68799383526695E-6,-0.000105075640481583,-8.89468810337349E-6,150.0074768,150.0074768,42485.66796875,42500.69921875,57.1855057239676,20.5112605335631,24.427608,0,0,0,40,4449,149.92495,42493.18359375,,,,,,,,,,,,,0,,,,0,,,,,,150.0074768,,,,
,32391644.015,150.006073,47361.125,-0.00012119339016171,2.06964490528478E-6,1,0.999253354069792,40.0298881530762,1.99565016837961,20.7199994474649,-0.00136536208833869,-0.000301346096532245,0.25,-5.43011290702206E-6,-0.000121779527697583,-5.64631685942855E-6,150.006073,150.006073,47358.86328125,47363.38671875,56.9088092281599,20.5114056249621,24.807261,0,0,0,40,4449,149.9168,47361.125,,,,,,,,,,,,,0,,,,-0.0049,,,,,,150.006073,,,,
,32391740.34,150.006485,52173.724609375,-0.000135729601789018,2.59566334322356E-6,1,0.999253354069792,40.0298881530762,1.99569382520097,20.7199994474649,-0.00152905000880204,-0.000338132384639712,0.25,-6.13796708844861E-6,-0.000136386123840441,-6.37972660681944E-6,150.006485,150.006485,52166.30859375,52181.140625,56.9994781363906,20.5132516230493,25.186911,0,0,0,40,4449,149.9092,52173.724609375,,,,,,,,,,,,,0,,,,0,,,,,,150.006485,,,,
,32391836.81,150.0072327,56996.15234375,-0.000157623487192042,2.13194082750782E-6,1,0.999253354069792,40.0298881530762,1.99581063201582,20.7199994474649,-0.00177411859307918,-0.000402322880933234,0.25,-7.97648440644151E-6,-0.000158384789219535,-8.26063620270204E-6,150.0072327,150.0072327,56988.3515625,57003.953125,56.7313795542945,20.5128191349388,25.566563,0,0,0,40,4449,149.90095,56996.15234375,,,,,,,,,,,,,0,,,,0,,,,,,150.0072327,,,,
,32391932.94,150.00914,61801.580078125,-0.000172537314247895,2.46998099319598E-6,1,0.999253354069792,40.0298881530762,1.99569005880356,20.7199994474649,-0.0019493375614196,-0.000397490589125113,0.25,-4.95623184334567E-6,-0.000173376714732753,-5.24788557590662E-6,150.00914,150.00914,61796.6015625,61806.55859375,57.2746113751599,20.5116440551969,24.807261,0,0,0,40,4449,149.8937,61801.580078125,,,,,,,,,,,,,0,,,,0,,,,,,150.00914,,,,
,32392028.415,150.0106506,66572.0078125,-0.000189976950864829,2.61706043023501E-6,1,0.999253354069792,40.0298881530762,1.99572061778071,20.7199994474649,-0.00214573102626019,-0.000441547487790676,0.25,-5.7991772688204E-6,-0.000190900885324688,-6.12106140435602E-6,150.0106506,150.0106506,66564.75,66579.265625,57.576319983583,20.5100040257733,25.186911,0,0,0,40,4449,149.8814,66572.0078125,,,,,,,,,,,,,0,,,,0.0049,,,,,,150.0106506,,,,
,32392123.835,150.0105896,71339.8359375,-0.000209010522387311,2.43948376581132E-6,1,0.999253354069792,40.0298881530762,1.99612111131235,20.7199994474649,-0.00236388224566306,-0.000470273134297193,0.25,-5.00712656875383E-6,-0.000210029393871794,-5.35347225398362E-6,150.0105896,150.0105896,71332.4921875,71347.1796875,57.352774227083,20.5072070758243,24.807261,0,0,0,40,4449,149.874,71339.8359375,,,,,,,,,,,,,0,,,,0,,,,,,150.0105896,,,,
,32392221.34,150.0124512,76215.28125,-0.00022750361772631,3.02836413739403E-6,1,0.999253354069792,40.0298881530762,1.99592450966911,20.7199994474649,-0.00256851065702776,-0.000536452855688529,0.25,-7.61910302446521E-6,-0.000228609573431098,-8.0055864895E-6,150.0124512,150.0124512,76205.4140625,76225.1484375,57.0596635323714,20.510306317571,24.807261,0,0,0,40,4449,149.86325,76215.28125,,,,,,,,,,,,,0,,,,0.00245,,,,,,150.0124512,,,,
,32392316.165,150.013092,80953.90234375,-0.000245034299020423,3.39121438185405E-6,1,0.999253354069792,40.0298881530762,1.9959701038149,20.7199994474649,-0.00277373425907772,-0.000536234583550574,0.25,-4.54707018606579E-6,-0.000246231368587551,-4.94413019711632E-6,150.013092,150.013092,80949.046875,80958.7578125,57.2691399755253,20.510640589812,25.186911,0,0,0,40,4449,149.8537,80953.90234375,,,,,,,,,,,,,0,,,,0.0049,,,,,,150.013092,,,,
,32392409.21,150.0117798,85604.76171875,-0.000260572207553912,2.74876828753609E-6,1,0.999253354069792,40.0298881530762,1.9956814101935,20.7199994474649,-0.00294518222506637,-0.00059332457610516,0.25,-6.87674410053522E-6,-0.000261842374967526,-7.30774132506244E-6,150.0117798,150.0117798,85602.3203125,85607.203125,56.983845566006,20.5100523915532,24.807261,0,0,0,40,4449,149.84005,85604.76171875,,,,,,,,,,,,,0,,,,-0.00245,,,,,,150.0117798,,,,
,32392518.36,150.0098724,89879.953125,-0.000274879298281822,2.46045842639705E-6,1,0.999253354069792,40.0298881530762,1.99559326762411,20.7199994474649,-0.00310333059738039,-0.000645594045749146,0.25,-8.9921320469044E-6,-0.000276216873625893,-9.45409711633803E-6,150.0098724,150.0098724,89870.5,89889.40625,56.7274714116983,20.5059343042984,25.186911,0,0,0,40,4449,149.8277,89879.953125,,,,,,,,,,,,,0,,,,0,,,,,,150.0098724,,,,
,32392611.15,150.0049591,85249.4453125,-0.000259814209323236,2.69989529127799E-6,1,0.999253354069792,40.0298881530762,1.99572390761353,20.7199994474649,-0.00294572905492476,-0.000539615329474322,0.25,-2.27757942600389E-6,-0.000261087677539207,-2.68497492110479E-6,150.0049591,150.0049591,85244.3984375,85254.4921875,57.1987934087945,20.5124150911664,25.186911,0,0,0,40,4449,149.8247,85249.4453125,,,,,,,,,,,,,0,,,,0,,,,,,150.0049591,,,,
,32392709.07,150.0016785,80355.875,-0.000239431555594797,2.49188888266203E-6,1,0.999253354069792,40.0298881530762,1.99573373710195,20.7199994474649,-0.00270240569001812,-0.000567559708226602,0.25,-8.28650732749711E-6,-0.00024059539371677,-8.69361836295997E-6,150.0016785,150.0016785,80351.0546875,80360.6953125,56.6164801619675,20.5106103774762,25.186911,0,0,0,40,4449,149.82795,80355.875,,,,,,,,,,,,,0,,,,0,,,,,,150.0016785,,,,
,32392805.61,149.9959259,75529.11328125,-0.00022503340319055,2.35150290756012E-6,1,0.999253354069792,40.0298881530762,1.9962816553692,20.7199994474649,-0.00254323231636625,-0.000518223963429139,0.25,-6.43602463059579E-6,-0.000226129077740665,-6.81318144987497E-6,149.9954987,149.9963531,75521.0859375,75537.140625,57.0721695886791,20.5067128421186,24.807261,0,0,0,40,4449,149.8301,75529.11328125,,,,,,,,,,,,,0,,,,-0.0049,,,,,,149.9959259,,,,
,32392902.27,149.9942017,70695.84375,-0.000206894934741068,2.70136619179705E-6,1,0.999253354069792,40.0298881530762,1.99613853962373,20.7199994474649,-0.00233251489668318,-0.00050835353855329,0.25,-8.72789288612642E-6,-0.000207897718790358,-9.08951101513385E-6,149.9942017,149.9942017,70693.2578125,70698.4296875,57.0166739638137,20.5090621248631,25.566563,0,0,0,40,4449,149.8374,70695.84375,,,,,,,,,,,,,0,,,,0.0049,,,,,,149.9942017,,,,
,32392998.025,149.9922485,65910.328125,-0.000188636000193414,2.85499986708878E-6,1,0.999253354069792,40.0298881530762,1.99601650052234,20.7199994474649,-0.00212463344115918,-0.00047440191997441,0.25,-8.91994445651818E-6,-0.000189548568650931,-9.25531196712304E-6,149.9922485,149.9922485,65905.2265625,65915.4296875,56.7563916669098,20.5104602167254,24.807261,0,0,0,40,4449,149.84705,65910.328125,,,,,,,,,,,,,0,,,,0,,,,,,149.9922485,,,,
,32393094,149.989975,61114.369140625,-0.000169810205408033,2.49828931613166E-6,1,0.999253354069792,40.0298881530762,1.99605297981873,20.7199994474649,-0.00192170243190056,-0.000374955305218286,0.25,-3.44059989705553E-6,-0.000170638604186645,-3.72081381791154E-6,149.989975,149.989975,61111.51953125,61117.21875,57.2081729510253,20.5061100491986,25.566563,0,0,0,40,4449,149.85255,61114.369140625,,,,,,,,,,,,,0,,,,0,,,,,,149.989975,,,,
,32393190.1,149.993248,56309.140625,-0.000153556249932674,1.95285097078772E-6,1,0.999253354069792,40.0298881530762,1.99582052632854,20.7199994474649,-0.0017306073075958,-0.000378973835015136,0.25,-6.62832338581054E-6,-0.000154299690891195,-6.89974197095294E-6,149.9931183,149.9933777,56304.609375,56313.671875,57.0565370182945,20.5116934207917,25.186911,0,0,0,40,4449,149.85895,56309.140625,,,,,,,,,,,,,0,,,,0,,,,,,149.993248,,,,
,32393285.1,149.9923706,51561.392578125,-0.000136885026291677,2.39553421915261E-6,1,0.999253354069792,40.0298881530762,1.99577808778199,20.7199994474649,-0.00153858531088183,-0.000361367555560114,0.25,-7.98153530730082E-6,-0.000137544349387826,-8.23432404241103E-6,149.9923706,149.9923706,51556.51953125,51566.265625,57.2480360055061,20.5144530837857,25.186911,0,0,0,40,4449,149.8635,51561.392578125,,,,,,,,,,,,,0,,,,-0.0049,,,,,,149.9923706,,,,
,32393381.97,149.9907608,46718.81640625,-0.00011838546059129,1.73643656681224E-6,1,0.999253354069792,40.0298881530762,1.9961560029649,20.7199994474649,-0.00133723553777293,-0.000276151448135907,0.25,-3.69426324354336E-6,-0.000118960548934346,-3.89771417404399E-6,149.9905548,149.9909668,46713.7890625,46723.84375,57.0971817012945,20.5109880265795,25.186911,0,0,0,40,4449,149.87285,46718.81640625,,,,,,,,,,,,,0,,,,-0.00245,,,,,,149.9907608,,,,
,32393476.875,149.9920197,41978.4765625,-0.000102142463957931,1.72927162837164E-6,1,0.999253354069792,40.0298881530762,1.99602573708237,20.7199994474649,-0.0011487330463658,-0.00026669234862364,0.25,-5.691639661674E-6,-0.000102634592723656,-5.87994020215554E-6,149.9920197,149.9920197,41975.97265625,41980.98046875,57.1401712698522,20.5107099407669,24.807261,0,0,0,40,4449,149.87975,41978.4765625,,,,,,,,,,,,,0,,,,-0.0049,,,,,,149.9920197,,,,
,32393572.545,149.990921,37195.94921875,-8.3284027433892E-5,1.79393991985629E-6,1,0.999253354069792,40.0298881530762,1.99596585331199,20.7199994474649,-0.000938373227455042,-0.00020735833230855,0.25,-3.7520498342355E-6,-8.36865908980462E-5,-3.90161181412689E-6,149.9906158,149.9912262,37183.703125,37208.1953125,56.8603482599676,20.5127852486696,25.566563,0,0,0,40,4449,149.88635,37195.94921875,,,,,,,,,,,,,0,,,,0,,,,,,149.990921,,,,
,32393669.245,149.9911194,32360.978515625,-6.86471508931566E-5,1.58256112089579E-6,1,0.999253354069792,40.0298881530762,1.99591351404029,20.7199994474649,-0.000769789344237526,-0.000191852076216398,0.25,-4.93635562715018E-6,-6.89759701003185E-5,-5.06898553820634E-6,149.9911194,149.9911194,32356.142578125,32365.814453125,57.0713879601599,20.5126659593574,25.186911,0,0,0,40,4449,149.8965,32360.978515625,,,,,,,,,,,,,0,,,,0.00245,,,,,,149.9911194,,,,
,32393764.865,149.9902802,27583.46875,-5.19985821723858E-5,1.8365791427032E-6,1,0.999253354069792,40.0298881530762,1.99583724934222,20.7199994474649,-0.00057971389031735,-0.000164612970959948,0.25,-5.43811884282309E-6,-5.22448978333504E-5,-5.54714078462326E-6,149.9902802,149.9902802,27578.5546875,27588.3828125,57.1120326431599,20.5165799843855,25.566563,0,0,0,40,4449,149.90385,27583.46875,,,,,,,,,,,,,0,,,,0,,,,,,149.9902802,,,,
,32393858.985,149.99193575,22878.3193359375,-3.60225057812912E-5,1.51119742022951E-6,1,0.999253354069792,40.0298881530762,1.99591554849165,20.7199994474649,-0.000405583180094076,-9.12722331941358E-5,0.25,-1.76211513974824E-6,-3.61962760551051E-5,-1.8279640723131E-6,149.9917603,149.9921112,22870.798828125,22885.83984375,57.5833546402561,20.5141110965496,24.807261,0,0,0,40,4449,149.9081,22878.3193359375,,,,,,,,,,,,,0,,,,0,,,,,,149.99193575,,,,
,32393954.085,149.9923096,18125.984375,-1.98867143221362E-5,1.15482550522061E-6,1,0.999253354069792,40.0298881530762,1.99587669591184,20.7199994474649,-0.000221278872235797,-6.54519236023454E-5,0.25,-2.29934932005031E-6,-1.9980511860777E-5,-2.34228480545781E-6,149.9923096,149.9923096,18118.54296875,18133.42578125,57.3097846585253,20.5144699583846,25.566563,0,0,0,40,4449,149.9155,18125.984375,,,,,,,,,,,,,0,,,,0.00245,,,,,,149.9923096,,,,
,32394050.97,149.9929657,13285.9951171875,-4.40425753170922E-6,1.1367654346848E-6,1,0.999253354069792,40.0298881530762,1.99565227935421,20.7199994474649,-4.47213436692238E-5,-3.90578822672417E-5,0.25,-2.6725903623801E-6,-4.42157090688315E-6,-2.69271658621317E-6,149.9929657,149.9929657,13281.0537109375,13290.9365234375,56.9142806277945,20.5210303474026,25.186911,0,0,0,40,4449,149.9209,13285.9951171875,,,,,,,,,,,,,0,,,,0,,,,,,149.9929657,,,,
,32394146.785,149.9915161,8492.939453125,1.05863728975483E-5,6.55362847750863E-7,1,0.999253354069792,40.0298881530762,1.99560642884133,20.7199994474649,0.000122953181037831,5.13648120380291E-6,0.25,-1.39193894127203E-6,1.06404631127935E-5,-1.38181919389792E-6,149.9915161,149.9915161,8487.9384765625,8497.9404296875,56.9572701963522,20.5183235799436,24.807261,0,0,0,40,4449,149.9327,8492.939453125,,,,,,,,,,,,,0,,,,0.0049,,,,,,149.9915161,,,,
,32394243.015,149.9941254,3685.02661132812,2.25085814995993E-5,3.82309966587708E-7,1,0.999253354069792,40.0298881530762,1.9956799538443,20.7199994474649,0.000257755105720775,3.20162173479773E-5,0.25,-1.10178073841371E-6,2.2620599841932E-5,-1.07108504480068E-6,149.9941254,149.9941254,3680.18310546875,3689.8701171875,57.3754414541407,20.5175975310792,25.566563,0,0,0,40,4449,149.932,3685.02661132812,,,,,,,,,,,,,0,,,,0.0049,,,,,,149.9941254,,,,
,32394336.61,149.994278,-994.203674316406,2.65754903616432E-5,3.90933927275716E-7,1,0.999253354069792,40.0298881530762,1.99569574480441,20.7199994474649,0.000301474318046027,5.41876478415906E-5,0.25,1.42247863403167E-7,2.67054252475588E-5,1.85598445351216E-7,149.994278,149.994278,-1006.72747802734,-981.679870605469,57.3551191126407,20.5215133947714,25.186911,0,0,0,40,4449,149.9362,-994.203674316406,,,,,,,,,,,,,0,,,,0,,,,,,149.994278,,,,
,32394430.71,149.9975891,-5692.61572265625,1.87154006239603E-5,3.93159387082295E-7,1,0.999253354069792,40.0298881530762,1.99567506085613,20.7199994474649,0.000211185006250155,4.46000986858791E-5,0.25,6.67369450914618E-7,1.88060077808393E-5,7.0062038925917E-7,149.9975891,149.9975891,-5702.57568359375,-5682.65576171875,57.4895592179484,20.5198682845805,25.186911,0,0,0,40,4449,149.9414,-5692.61572265625,,,,,,,,,,,,,0,,,,0.0049,,,,,,149.9975891,,,,
,32394525.955,150.0017242,-10453.6513671875,9.52324202090267E-6,7.98420001321338E-7,1,0.999253354069792,40.0298881530762,1.99577238403541,20.7199994474649,0.000106282134608774,2.94885320920549E-5,0.25,9.37846064815091E-7,9.5683980819978E-6,9.57663714039644E-7,150.0017242,150.0017242,-10461.248046875,-10446.0546875,57.6122748954676,20.5193176856511,25.186911,0,0,0,40,4449,149.93435,-10453.6513671875,,,,,,,,,,,,,0,,,,0,,,,,,150.0017242,,,,
,32394623.9,150.007309,-15351.6044921875,1.3631408667122E-5,1.43732099490104E-6,1,0.999253354069792,40.0298881530762,1.99575768072533,20.7199994474649,0.000152554909977001,3.97675582237737E-5,0.25,1.12744974072246E-6,1.36964021657033E-5,1.15470994506408E-6,150.007309,150.007309,-15358.8779296875,-15344.3310546875,57.3011867448138,20.519205259301,25.186911,0,0,0,40,4449,149.9301,-15351.6044921875,,,,,,,,,,,,,0,,,,0,,,,,,150.007309,,,,
,32394720.755,150.0086975,-20190.919921875,2.74030041187131E-5,1.35863553671289E-6,1,0.999253354069792,40.0298881530762,1.99573006517954,20.7199994474649,0.000304416443877372,9.29080375620307E-5,0.25,3.40839531771175E-6,2.75318760992525E-5,3.46868223209081E-6,150.0086975,150.0086975,-20200.939453125,-20180.900390625,56.9822823089676,20.520972829555,25.186911,0,0,0,40,4449,149.9204,-20190.919921875,,,,,,,,,,,,,0,,,,0.0049,,,,,,150.0086975,,,,
,32394816.71,150.0089264,-24985.6513671875,4.34857869732478E-5,1.53770351934151E-6,1,0.999253354069792,40.0298881530762,1.99578793419205,20.7199994474649,0.000486706729012022,0.000126690211982213,0.25,3.58164038175153E-6,4.36932552436243E-5,3.6681735416556E-6,150.0089264,150.0089264,-24992.99609375,-24978.306640625,57.3269804859484,20.5189971310688,24.807261,0,0,0,40,4449,149.9127,-24985.6513671875,,,,,,,,,,,,,0,,,,0,,,,,,150.0089264,,,,
,32394912.14,150.0110168,-29755.6171875,5.95705294493024E-5,1.49768462756615E-6,1,0.999253354069792,40.0298881530762,1.99578344564323,20.7199994474649,0.000669142839399731,0.000159709255532219,0.25,3.68772940045129E-6,5.98567385238973E-5,3.80004337790894E-6,150.0110168,150.0110168,-29760.595703125,-29750.638671875,57.3465211989291,20.5200685220519,25.186911,0,0,0,40,4449,149.8995,-29755.6171875,,,,,,,,,,,,,0,,,,0,,,,,,150.0110168,,,,
,32395009.24,150.0108948,-34608.107421875,7.81074363638228E-5,1.66282862345794E-6,1,0.999253354069792,40.0298881530762,1.99570875842471,20.7199994474649,0.000881327890379079,0.000186469903843424,0.25,2.81623504963158E-6,7.84859914888512E-5,2.95324620133679E-6,150.0108948,150.0108948,-34613.078125,-34603.13671875,57.241001348833,20.5200707807583,25.186911,0,0,0,40,4449,149.89055,-34608.107421875,,,,,,,,,,,,,0,,,,0,,,,,,150.0108948,,,,
,32395105.125,150.0097961,-39399.888671875,9.29370261141781E-5,1.72375978929925E-6,1,0.999253354069792,40.0298881530762,1.9958539471939,20.7199994474649,0.00104826618112483,0.000224563964748845,0.25,3.5869175316821E-6,9.3387194468686E-5,3.75067402077803E-6,150.0097961,150.0097961,-39404.5234375,-39395.25390625,57.4145228801022,20.517597278016,25.186911,0,0,0,40,4449,149.88145,-39399.888671875,,,,,,,,,,,,,0,,,,-0.00245,,,,,,150.0097961,,,,
,32395202.315,150.0114136,-44257.666015625,0.000112093494487905,1.5483154884929E-6,1,0.999253354069792,40.0298881530762,1.99584212500862,20.7199994474649,0.00125971949852603,0.000297333314641474,0.25,6.65892248580517E-6,0.00011263292593357,6.86734790895559E-6,150.0114136,150.0114136,-44267.625,-44247.70703125,57.3027500018522,20.520917922163,24.807261,0,0,0,40,4449,149.87085,-44257.666015625,,,,,,,,,,,,,0,,,,-0.00245,,,,,,150.0114136,,,,
,32395299.705,150.0118256,-49125.6328125,0.000129150314701253,2.0710296506049E-6,1,0.999253354069792,40.0298881530762,1.99579118601684,20.7199994474649,0.00145278242015955,0.000334474866292598,0.25,6.95996212747066E-6,0.000129773111674625,7.19599604615245E-6,150.0118256,150.0118256,-49130.22265625,-49121.04296875,57.065134932006,20.5211893993173,25.566563,0,0,0,40,4449,149.8578,-49125.6328125,,,,,,,,,,,,,0,,,,-0.00245,,,,,,150.0118256,,,,
,32395397.28,150.0117188,-54002.205078125,0.000145856421886168,2.08481787987989E-6,1,0.999253354069792,40.0298881530762,1.99596677767949,20.7199994474649,0.00164945296637699,0.000328354232995629,0.25,3.50935529659618E-6,0.00014656675392704,3.75385697951881E-6,150.0117188,150.0117188,-54011.875,-53992.53515625,57.3261988574291,20.5205011779374,24.807261,0,0,0,40,4449,149.8486,-54002.205078125,,,,,,,,,,,,,0,,,,0,,,,,,150.0117188,,,,
,32395493.835,150.0108795,-58827.54296875,0.000164321948052144,2.59147596837196E-6,1,0.999253354069792,40.0298881530762,1.99572025321727,20.7199994474649,0.00185456502554958,0.000389936171971185,0.25,5.72065422121778E-6,0.000165119662207239,6.00397236073412E-6,150.0108795,150.0108795,-58829.86328125,-58825.22265625,57.4129596230638,20.5192145825042,25.566563,0,0,0,40,4449,149.8407,-58827.54296875,,,,,,,,,,,,,0,,,,-0.0049,,,,,,150.0108795,,,,
,32395590.165,150.0109253,-63642.375,0.000180130427443786,2.35123915733898E-6,1,0.999253354069792,40.0298881530762,1.99572159492763,20.7199994474649,0.0020296098240017,0.000446835282522164,0.25,7.97904709267731E-6,0.000181002462237756,8.2971206613985E-6,150.0109253,150.0109253,-63647.4609375,-63637.2890625,57.4575124486599,20.5194249031324,24.807261,0,0,0,40,4449,149.8298,-63642.375,,,,,,,,,,,,,0,,,,0,,,,,,150.0109253,,,,
,32395689.125,150.0106506,-68586.890625,0.000200984944019163,2.12471518629119E-6,1,0.999253354069792,40.0298881530762,1.99575648766705,20.7199994474649,0.00226330492281976,0.000506171801601449,0.25,9.57273517928825E-6,0.000201957171385449,9.92990090057529E-6,150.0106506,150.0106506,-68589.5390625,-68584.2421875,57.2214606358522,20.5221305017451,25.186911,0,0,0,40,4449,149.81815,-68586.890625,,,,,,,,,,,,,0,,,,-0.0049,,,,,,150.0106506,,,,
,32395787.32,150.0102692,-73496.2109375,0.000215895028458612,2.45071302966341E-6,1,0.999253354069792,40.0298881530762,1.99555383334443,20.7199994474649,0.00243569065787498,0.000516598406472414,0.25,7.89970325505876E-6,0.000216943339288225,8.27054987620209E-6,150.0102692,150.0102692,-73506.0703125,-73486.3515625,57.7201396311215,20.5236525318043,25.566563,0,0,0,40,4449,149.81005,-73496.2109375,,,,,,,,,,,,,0,,,,0,,,,,,150.0102692,,,,
,32395886.645,150.011261,-78458.4140625,0.000234535309978412,2.48215153622411E-6,1,0.999253354069792,40.0298881530762,1.99584022245354,20.7199994474649,0.00265092084558683,0.000535048586320031,0.25,6.2731207577979E-6,0.000235677968518534,6.66342257822216E-6,150.011261,150.011261,-78468.5546875,-78448.2734375,57.5520894994869,20.5214846524097,25.186911,0,0,0,40,4449,149.79915,-78458.4140625,,,,,,,,,,,,,0,,,,0.00245,,,,,,150.011261,,,,
,32395982.785,150.009552,-83263.171875,0.000254992810988301,2.92061137525106E-6,1,0.999253354069792,40.0298881530762,1.99586811372902,20.7199994474649,0.00288741513747041,0.000551729446179996,0.25,4.18002776826444E-6,0.000256239496210094,4.59009217223159E-6,150.009552,150.009552,-83265.46875,-83260.875,57.1472059265253,20.5242287942073,25.566563,0,0,0,40,4449,149.7918,-83263.171875,,,,,,,,,,,,,0,,,,-0.0049,,,,,,150.009552,,,,
,32396077.15,150.010498,-87977.56640625,0.000270634086993449,2.5152658636511E-6,1,0.999253354069792,40.0298881530762,1.99582596881022,20.7199994474649,0.00305509785489338,0.000639387572068006,0.25,9.17779796000026E-6,0.000271950328166233,9.63495363712924E-6,150.010498,150.010498,-87982.53125,-87972.6015625,57.078422616833,20.522216997999,25.566563,0,0,0,40,4449,149.7833,-87977.56640625,,,,,,,,,,,,,0,,,,0,,,,,,150.010498,,,,
,32396188.815,150.00717165,-87443.85546875,0.000272733193529231,2.81762839820272E-6,1,0.999253354069792,40.0298881530762,1.99593840768316,20.7199994474649,0.00308771682019659,0.000594090584568558,0.25,4.82034643644214E-6,0.000274066366908839,5.25947868925433E-6,150.0067902,150.0075531,-87448.7578125,-87438.953125,57.3097846585253,20.5223863210462,25.186911,0,0,0,40,4449,149.7733,-87443.85546875,,,,,,,,,,,,,0,,,,-0.00245,,,,,,150.00717165,,,,
,32396284.445,150.0013885,-82664.01953125,0.000249271174994264,2.15971348156243E-6,1,0.999253354069792,40.0298881530762,1.99584683197195,20.7199994474649,0.00280561589623076,0.000636858921822192,0.25,1.2673238984688E-5,0.000250476770211249,1.31165160822838E-5,150.0013885,150.0013885,-82671.0234375,-82657.015625,57.474708276083,20.5203612566083,25.186911,0,0,0,40,4449,149.7771,-82664.01953125,,,,,,,,,,,,,0,,,,0,,,,,,150.0013885,,,,
,32396380.815,149.9954071,-77849.32421875,0.000231987355279143,1.98459276516523E-6,1,0.999253354069792,40.0298881530762,1.99587180941018,20.7199994474649,0.00262433710048825,0.000516753181466703,0.25,5.10480824115061E-6,0.00023311933767631,5.48569046321911E-6,149.9954071,149.9954071,-77854.28125,-77844.3671875,57.5841362687753,20.5243169704661,25.946213,0,0,0,40,4449,149.77785,-77849.32421875,,,,,,,,,,,,,0,,,,0,,,,,,149.9954071,,,,
,32396477.985,149.9933472,-72989.4140625,0.000216077967425278,2.0395092528063E-6,1,0.999253354069792,40.0298881530762,1.99590392757002,20.7199994474649,0.00243468401269552,0.000537101577534611,0.25,9.66550638644034E-6,0.000217124515847662,1.00454984429783E-5,149.9933472,149.9933472,-72991.3828125,-72987.4453125,57.5974239536023,20.5212258135177,25.946213,0,0,0,40,4449,149.78775,-72989.4140625,,,,,,,,,,,,,0,,,,0,,,,,,149.9933472,,,,
,32396575.905,149.9909363,-68097.5390625,0.000198981983401408,2.17165738748229E-6,1,0.999253354069792,40.0298881530762,1.99585235789973,20.7199994474649,0.00224069142867906,0.000502077614034035,0.25,9.55878564646255E-6,0.000199944457687999,9.91298295619118E-6,149.9909363,149.9909363,-68099.640625,-68095.4375,57.217552493256,20.5226496250208,25.186911,0,0,0,40,4449,149.7893,-68097.5390625,,,,,,,,,,,,,0,,,,0,,,,,,149.9909363,,,,
,32396672.86,149.9904327,-63252.595703125,0.000180885339563542,2.28922099533891E-6,1,0.999253354069792,40.0298881530762,1.99586236413714,20.7199994474649,0.00204281406358777,0.000422554360706182,0.25,5.70657432373986E-6,0.000181764669858993,6.01479987723238E-6,149.9904327,149.9904327,-63257.79296875,-63247.3984375,57.627125837333,20.5218551304297,25.566563,0,0,0,40,4449,149.80595,-63252.595703125,,,,,,,,,,,,,0,,,,0,,,,,,149.9904327,,,,
,32396771.6,149.9914856,-58317.974609375,0.000160670183335348,2.26376703839047E-6,1,0.999253354069792,40.0298881530762,1.99577658784174,20.7199994474649,0.00181663244725021,0.000362721924104214,0.25,3.95898833782268E-6,0.000161452761023402,4.22813618489208E-6,149.9914856,149.9914856,-58325.55859375,-58310.390625,57.0878021590637,20.5217098626263,25.186911,0,0,0,40,4449,149.8146,-58317.974609375,,,,,,,,,,,,,0,,,,0,,,,,,149.9914856,,,,
,32396870.055,149.9920349,-53398.08984375,0.000145916390893849,2.10150746199989E-6,1,0.999253354069792,40.0298881530762,1.9958234364677,20.7199994474649,0.001641496949338,0.000377392214447511,0.25,7.81914404150435E-6,0.000146620341537803,8.08504473472902E-6,149.9920349,149.9920349,-53403.08984375,-53393.08984375,56.9338213407753,20.5215444432022,24.807261,0,0,0,40,4449,149.8206,-53398.08984375,,,,,,,,,,,,,0,,,,-0.0049,,,,,,149.9920349,,,,
,32396968.16,149.989502,-48495.80859375,0.000127381802059255,1.91950879427919E-6,1,0.999253354069792,40.0298881530762,1.99581940527665,20.7199994474649,0.00143027864100015,0.000344998770998508,0.25,8.19422682232542E-6,0.000127994035687735,8.43368711997379E-6,149.989502,149.989502,-48500.87109375,-48490.74609375,57.1753445532176,20.5195560734949,25.186911,0,0,0,40,4449,149.832,-48495.80859375,,,,,,,,,,,,,0,,,,-0.00245,,,,,,149.989502,,,,
,32397065.865,149.98991395,-43610.349609375,0.000106207604721314,1.93636246651825E-6,1,0.999253354069792,40.0298881530762,1.99578890310007,20.7199994474649,0.00119501404196168,0.000273269327135247,0.25,5.56550977372173E-6,0.000106719909763275,5.75946382009909E-6,149.9898071,149.9900208,-43617.40625,-43603.29296875,57.1565854687561,20.5196572555332,25.186911,0,0,0,40,4449,149.83975,-43610.349609375,,,,,,,,,,,,,0,,,,-0.00245,,,,,,149.98991395,,,,
,32397162.775,149.990036,-38768.59375,9.28692646167735E-5,1.65892994792319E-6,1,0.999253354069792,40.0298881530762,1.99576329541111,20.7199994474649,0.00104024657868781,0.00026578318253924,0.25,7.22946795271085E-6,9.33133937388415E-5,7.41108632721856E-6,149.990036,149.990036,-38776.43359375,-38760.75390625,56.9541436822753,20.5211784977758,24.807261,0,0,0,40,4449,149.8509,-38768.59375,,,,,,,,,,,,,0,,,,-0.0049,,,,,,149.990036,,,,
,32397260.76,149.9910583,-33869.1875,7.42665162624606E-5,1.86818580413693E-6,1,0.999253354069792,40.0298881530762,1.99578769264566,20.7199994474649,0.000836605833421038,0.00018542868007481,0.25,3.39288976529377E-6,7.46253457258484E-5,3.52676129139929E-6,149.9910583,149.9910583,-33874.25,-33864.125,56.9564885678329,20.5188809670001,24.807261,0,0,0,40,4449,149.8581,-33869.1875,,,,,,,,,,,,,0,,,,0.0049,,,,,,149.9910583,,,,
,32397356.82,149.9915619,-29069.4970703125,5.81353577342319E-5,1.61816825372185E-6,1,0.999253354069792,40.0298881530762,1.99589949392984,20.7199994474649,0.000651625925374785,0.000164092542589007,0.25,4.32287385327162E-6,5.8413537632317E-5,4.43610227665589E-6,149.9915619,149.9915619,-29076.880859375,-29062.11328125,57.1284468420637,20.5194702226084,25.566563,0,0,0,40,4449,149.86375,-29069.4970703125,,,,,,,,,,,,,0,,,,0,,,,,,149.9915619,,,,
,32397454.085,149.9931793,-24207.013671875,4.18759934766361E-5,1.11561291291344E-6,1,0.999253354069792,40.0298881530762,1.99584226260397,20.7199994474649,0.000470205634851165,0.000113369743395963,0.25,2.68868662188684E-6,4.20769902533178E-5,2.76834609886567E-6,149.9931793,149.9931793,-24214.53125,-24199.49609375,57.322290714833,20.5172770219852,24.807261,0,0,0,40,4449,149.87205,-24207.013671875,,,,,,,,,,,,,0,,,,0,,,,,,149.9931793,,,,
,32397549.525,149.9922485,-19439.81640625,2.41637370375106E-5,1.04666059127786E-6,1,0.999253354069792,40.0298881530762,1.99584031844914,20.7199994474649,0.000267526092562718,8.72103584007859E-5,0.25,3.47048053286925E-6,2.42766355253037E-5,3.52595173817861E-6,149.9922485,149.9922485,-19452.453125,-19427.1796875,56.963523224506,20.5163076780485,24.807261,0,0,0,40,4449,149.87965,-19439.81640625,,,,,,,,,,,,,0,,,,0.00245,,,,,,149.9922485,,,,
,32397646.89,149.9907074,-14572.611328125,8.21279371760465E-6,1.02143740499085E-6,1,0.999253354069792,40.0298881530762,1.99583144975372,20.7199994474649,9.04265115009513E-5,3.25109876632177E-5,0.25,1.43225976914996E-6,8.25075059747186E-6,1.45238429981579E-6,149.9907074,149.9907074,-14575.1552734375,-14570.0673828125,57.3011867448138,20.5155296498292,25.186911,0,0,0,40,4449,149.88785,-14572.611328125,,,,,,,,,,,,,0,,,,-0.00245,,,,,,149.9907074,,,,
,32397743.345,149.9906006,-9752.45947265625,-6.11666315013154E-6,7.05924020494208E-7,1,0.999253354069792,40.0298881530762,1.99576098133208,20.7199994474649,-7.10428781795851E-5,-2.98559411316278E-6,0.25,8.02692214931428E-7,-6.14791365242202E-6,7.96840249535527E-7,149.9906006,149.9906006,-9762.302734375,-9742.6162109375,57.5192611016792,20.5176423520589,24.807261,0,0,0,40,4449,149.8974,-9752.45947265625,,,,,,,,,,,,,0,,,,0.00245,,,,,,149.9906006,,,,
,32397839.305,149.9909668,-4956.56567382812,-1.94417858429842E-5,6.7738954350234E-7,1,0.999253354069792,40.0298881530762,1.99593222171872,20.7199994474649,-0.000222119160047995,-3.07780762212913E-5,0.25,6.76845019758998E-7,-1.95381042474983E-5,6.48993726524656E-7,149.9909668,149.9909668,-4964.025390625,-4949.10595703125,57.3316702570638,20.515497651096,25.566563,0,0,0,40,4449,149.90435,-4956.56567382812,,,,,,,,,,,,,0,,,,0,,,,,,149.9909668,,,,
,32397933.875,149.9933624,-227.060638427734,-2.63090833159165E-5,3.5931508829251E-7,1,0.999253354069792,40.0298881530762,1.99583496622641,20.7199994474649,-0.000298590666378711,-5.29669148088222E-5,0.25,-8.08219857592549E-8,-2.64378080136911E-5,-1.23464737508111E-7,149.9933624,149.9933624,-234.607666015625,-219.513610839844,57.3480844559676,20.5169516411159,25.186911,0,0,0,40,4449,149.9081,-227.060638427734,,,,,,,,,,,,,0,,,,-0.0049,,,,,,149.9933624,,,,
,32398026.1,149.9951172,4378.80493164063,-2.12372500968412E-5,4.25187249971273E-7,1,0.999253354069792,40.0298881530762,1.99600568665615,20.7199994474649,-0.000239493108285694,-5.16873558203244E-5,0.25,-8.51445494557445E-7,-2.13399094228816E-5,-8.89666815086425E-7,149.9951172,149.9951172,4373.84619140625,4383.763671875,57.8053371397177,20.5149917016728,25.186911,0,0,0,40,4449,149.9121,4378.80493164063,,,,,,,,,,,,,0,,,,0,,,,,,149.9951172,,,,
,32398122.23,150.0032349,9185.3662109375,-1.15237121768339E-5,9.10338078303388E-7,1,0.999253354069792,40.0298881530762,1.99603430855229,20.7199994474649,-0.000127811279963305,-4.03524385956956E-5,0.25,-1.5456160152057E-6,-1.15776909586685E-5,-1.57162461795811E-6,150.0032349,150.0032349,9177.9599609375,9192.7724609375,57.0440309619868,20.5131351680217,25.946213,0,0,0,40,4449,149.90785,9185.3662109375,,,,,,,,,,,,,0,,,,0,,,,,,150.0032349,,,,
,32398217.915,150.0058289,13968.2817382812,-1.05991324980481E-5,1.16259763731275E-6,1,0.999253354069792,40.0298881530762,1.99592550911026,20.7199994474649,-0.000118263162842151,-3.30230881761903E-5,0.25,-1.06149434096229E-6,-1.06493685380156E-5,-1.08361312349031E-6,150.0058289,150.0058289,13965.822265625,13970.7412109375,57.4246840508522,20.5155587946938,25.186911,0,0,0,40,4449,149.9008,13968.2817382812,,,,,,,,,,,,,0,,,,0.0049,,,,,,150.0058289,,,,
,32398311.005,150.0067749,18620.9306640625,-2.37439689952909E-5,1.51549476614907E-6,1,0.999253354069792,40.0298881530762,1.99614464311582,20.7199994474649,-0.000264742704730491,-7.52265599112562E-5,0.25,-2.48730648347632E-6,-2.38563617883098E-5,-2.53730140802742E-6,150.0067749,150.0067749,18618.384765625,18623.4765625,56.9643048530253,20.5139833508227,25.946213,0,0,0,40,4449,149.89515,18620.9306640625,,,,,,,,,,,,,0,,,,0,,,,,,150.0067749,,,,
,32398408.115,150.0087128,23473.107421875,-3.81750286629058E-5,1.51005482311121E-6,1,0.999253354069792,40.0298881530762,1.9959660383186,20.7199994474649,-0.000427447971064521,-0.000110396381856852,0.25,-3.07097907075171E-6,-3.83572552082442E-5,-3.1466535656626E-6,150.0087128,150.0087128,23465.693359375,23480.521484375,56.9869720800829,20.5153773826876,25.566563,0,0,0,40,4449,149.885,23473.107421875,,,,,,,,,,,,,0,,,,-0.00245,,,,,,150.0087128,,,,
,32398506.35,150.0085144,28383.494140625,-5.52475346541959E-5,1.37609861435757E-6,1,0.999253354069792,40.0298881530762,1.9958634035769,20.7199994474649,-0.000620044030951678,-0.000151357040522682,0.25,-3.70465577691318E-6,-5.55125022446189E-5,-3.81030166900111E-6,150.0085144,150.0085144,28373.515625,28393.47265625,57.1729996676599,20.5140262891174,25.566563,0,0,0,40,4449,149.88015,28383.494140625,,,,,,,,,,,,,0,,,,0.00245,,,,,,150.0085144,,,,
,32398604.43,150.0104065,33286.185546875,-7.38478466829232E-5,2.02931675583538E-6,1,0.999253354069792,40.0298881530762,1.99551709387044,20.7199994474649,-0.000820017605385408,-0.000251891340922031,0.25,-9.3216930644655E-6,-7.41952132586199E-5,-9.48400226065906E-6,150.0104065,150.0104065,33276.40234375,33295.96875,56.7477937531983,20.520414649691,25.566563,0,0,0,40,4449,149.8679,33286.185546875,,,,,,,,,,,,,0,,,,-0.0049,,,,,,150.0104065,,,,
,32398702.51,150.0105896,38188.4296875,-8.7797024956108E-5,1.99113529714024E-6,1,0.999253354069792,40.0298881530762,1.9957951719204,20.7199994474649,-0.000988393111725294,-0.000222868463018323,0.25,-4.33336440560609E-6,-8.82207722234752E-5,-4.4928318846623E-6,150.0105896,150.0105896,38178.48828125,38198.37109375,57.5083183024099,20.5150314317519,25.566563,0,0,0,40,4449,149.8593,38188.4296875,,,,,,,,,,,,,0,,,,0,,,,,,150.0105896,,,,
,32398801.07,150.0113068,43113.650390625,-0.000105945884774674,2.04940352712309E-6,1,0.999253354069792,40.0298881530762,1.9957364055477,20.7199994474649,-0.00119284580711011,-0.000267954109256129,0.25,-5.14358674589794E-6,-0.000106457493976519,-5.33509493031947E-6,150.0113068,150.0113068,43111.0234375,43116.27734375,57.1026531009291,20.5125439443504,25.566563,0,0,0,40,4449,149.84935,43113.650390625,,,,,,,,,,,,,0,,,,0,,,,,,150.0113068,,,,
,32398899.51,150.0100861,48034.15625,-0.000123115659560826,2.62707724113672E-6,1,0.999253354069792,40.0298881530762,1.99575637075073,20.7199994474649,-0.00138746463140958,-0.000303981689387256,0.25,-5.32600068115991E-6,-0.000123711363449451,-5.54475395490159E-6,150.0100861,150.0100861,48024.44140625,48043.87109375,57.1542405831984,20.5139098770013,25.566563,0,0,0,40,4449,149.8401,48034.15625,,,,,,,,,,,,,0,,,,-0.0049,,,,,,150.0100861,,,,
,32398996.275,150.0115662,52871.638671875,-0.000143024046338232,2.5882444976948E-6,1,0.999253354069792,40.0298881530762,1.99560951528576,20.7199994474649,-0.00161493600643233,-0.000334608023923098,0.25,-4.5582001646253E-6,-0.000143718791574784,-4.80364905537746E-6,150.0115662,150.0115662,52861.4609375,52881.81640625,57.0971817012945,20.5120268257965,25.186911,0,0,0,40,4449,149.8268,52871.638671875,,,,,,,,,,,,,0,,,,0,,,,,,150.0115662,,,,
,32399092.88,150.0109863,57699.431640625,-0.000157131594014073,2.02384808905913E-6,1,0.999253354069792,40.0298881530762,1.99541709978184,20.7199994474649,-0.0017721841115227,-0.00037839756204812,0.25,-5.96142926082911E-6,-0.000157893578636641,-6.23499726245613E-6,150.0109863,150.0109863,57694.17578125,57704.6875,57.5130080735253,20.5154771680201,25.946213,0,0,0,40,4449,149.8184,57699.431640625,,,,,,,,,,,,,0,,,,-0.0049,,,,,,150.0109863,,,,
,32399190.265,150.0100555,62567.890625,-0.000175529253734925,2.6858290717711E-6,1,0.999253354069792,40.0298881530762,1.9955125523004,20.7199994474649,-0.00198729732366543,-0.000379514879812215,0.25,-2.85482927562148E-6,-0.000176386578398517,-3.14087172687014E-6,150.0100555,150.0100555,62558.0859375,62577.6953125,57.1503324406022,20.5150272254894,25.566563,0,0,0,40,4449,149.8098,62567.890625,,,,,,,,,,,,,0,,,,0,,,,,,150.0100555,,,,
,32399287.43,150.0112152,67422.8203125,-0.000195601975940835,3.6141927530616E-6,1,0.999253354069792,40.0298881530762,1.99587197457397,20.7199994474649,-0.00220990174923249,-0.000451909160222145,0.25,-5.72910562261987E-6,-0.000196553623656792,-6.05938979265519E-6,150.0112152,150.0112152,67410.1640625,67435.4765625,56.9752476522945,20.510210988283,25.566563,0,0,0,40,4449,149.7977,67422.8203125,,,,,,,,,,,,,0,,,,0,,,,,,150.0112152,,,,
,32399385.095,150.0097504,72305.66796875,-0.000212298917351007,2.97823708131402E-6,1,0.999253354069792,40.0298881530762,1.99557212404454,20.7199994474649,-0.00240271851231296,-0.000464481947255516,0.25,-3.93523431524855E-6,-0.000213335588006759,-4.28140893454824E-6,150.0097504,150.0097504,72298.109375,72313.2265625,57.4043617093522,20.5143927079436,25.566563,0,0,0,40,4449,149.79055,72305.66796875,,,,,,,,,,,,,0,,,,-0.0049,,,,,,150.0097504,,,,
,32399484.235,150.0102692,77261.1015625,-0.000232538963542141,3.54292916340818E-6,1,0.999253354069792,40.0298881530762,1.99566866666135,20.7199994474649,-0.0026335613886552,-0.000499319203742312,0.25,-3.47767331104163E-6,-0.000233676023018036,-3.85154383638718E-6,150.0102692,150.0102692,77251.109375,77271.09375,56.9893169656406,20.5133428150627,25.566563,0,0,0,40,4449,149.781,77261.1015625,,,,,,,,,,,,,0,,,,0,,,,,,150.0102692,,,,
,32399579.885,150.0103455,82042.1796875,-0.000249081394881119,2.41192721076577E-6,1,0.999253354069792,40.0298881530762,1.9962670168803,20.7199994474649,-0.00281614942924635,-0.000566976158340175,0.25,-6.54217635130434E-6,-0.000250295321977935,-6.95521622841973E-6,150.0103455,150.0103455,82034.8046875,82049.5546875,57.5036285312945,20.5029814486604,25.566563,0,0,0,40,4449,149.77285,82042.1796875,,,,,,,,,,,,,0,,,,0,,,,,,150.0103455,,,,
,32399675.97,150.0104065,86845.37109375,-0.000266946294060469,3.28666750600411E-6,1,0.999253354069792,40.0298881530762,1.99617366730516,20.7199994474649,-0.00302125753872706,-0.000588916639644256,0.25,-5.36643219491697E-6,-0.000268250118483449,-5.79964783984854E-6,150.0104065,150.0104065,86842.78125,86847.9609375,56.8408075469868,20.5052236179088,25.566563,0,0,0,40,4449,149.7627,86845.37109375,,,,,,,,,,,,,0,,,,-0.0049,,,,,,150.0104065,,,,
,32399784.41,150.0094147,88647.9609375,-0.000274464944433694,2.91501821137756E-6,1,0.999253354069792,40.0298881530762,1.99598456208522,20.7199994474649,-0.00311240802019616,-0.000569069743414279,0.25,-2.31470807464552E-6,-0.000275810492311281,-2.7438722805587E-6,150.0094147,150.0094147,88638.0625,88657.859375,56.7696793517368,20.5073451150388,25.186911,0,0,0,40,4449,149.75405,88647.9609375,,,,,,,,,,,,,0,,,,0,,,,,,150.0094147,,,,
,32399876.57,150.0024414,84039.72265625,-0.000255483143997603,2.69346021347171E-6,1,0.999253354069792,40.0298881530762,1.99579642935673,20.7199994474649,-0.00288764982583287,-0.000582742705920916,0.25,-6.82749345187053E-6,-0.000256728267237873,-7.25122787399044E-6,150.0024414,150.0024414,84029.765625,84049.6796875,56.9385111118906,20.5092190972535,25.566563,0,0,0,40,4449,149.75645,84039.72265625,,,,,,,,,,,,,0,,,,0,,,,,,150.0024414,,,,
,32399975.86,149.9960785,79078.28125,-0.000237296707567985,2.82161067949794E-6,1,0.999253354069792,40.0298881530762,1.99566857083667,20.7199994474649,-0.00268065828404449,-0.000548512210105844,0.25,-6.98181876054758E-6,-0.000238451954020432,-7.37981326153158E-6,149.9960785,149.9960785,79075.734375,79080.828125,56.9150622563137,20.5111769081279,25.566563,0,0,0,40,4449,149.75875,79078.28125,,,,,,,,,,,,,0,,,,-0.0049,,,,,,149.9960785,,,,
,32400071.795,149.9930573,74282.109375,-0.000218010611946939,2.44709932808079E-6,1,0.999253354069792,40.0298881530762,1.9959076173215,20.7199994474649,-0.00245951547728587,-0.000524392561919025,0.25,-8.20993481873835E-6,-0.000219068955150083,-8.5855141813792E-6,149.9930573,149.9930573,74277.09375,74287.125,57.1839424669291,20.5101625420558,25.566563,0,0,0,40,4449,149.7661,74282.109375,,,,,,,,,,,,,0,,,,-0.0049,,,,,,149.9930573,,,,
,32400169.755,149.9908905,69384.2734375,-0.00020048392800177,2.48846266911793E-6,1,0.999253354069792,40.0298881530762,1.99583383201443,20.7199994474649,-0.00226357873252667,-0.000471448609377539,0.25,-6.6005814644237E-6,-0.000201458404430637,-6.94233604028585E-6,149.9908905,149.9908905,69379.078125,69389.46875,56.8595666314483,20.5111029183949,25.186911,0,0,0,40,4449,149.77445,69384.2734375,,,,,,,,,,,,,0,,,,0,,,,,,149.9908905,,,,
,32400267.3,149.989624,64508.9609375,-0.000183221907059679,3.20376496367146E-6,1,0.999253354069792,40.0298881530762,1.99586648591705,20.7199994474649,-0.00207412325799502,-0.000399783124504395,0.25,-3.29448465343282E-6,-0.000184116493836857,-3.59430107331471E-6,149.989624,149.989624,64501.58984375,64516.33203125,57.0455942190253,20.5114208770235,25.566563,0,0,0,40,4449,149.7832,64508.9609375,,,,,,,,,,,,,0,,,,-0.00245,,,,,,149.989624,,,,
,32400364.335,149.9928589,59658.107421875,-0.000163998530836432,2.22165385976784E-6,1,0.999253354069792,40.0298881530762,1.99589722771987,20.7199994474649,-0.00184794007543713,-0.000407187334055688,0.25,-7.29321864876555E-6,-0.000164792307263952,-7.58372189940333E-6,149.9928589,149.9928589,59653.05078125,59663.1640625,57.4106147375061,20.5122855039905,25.566563,0,0,0,40,4449,149.79535,59658.107421875,,,,,,,,,,,,,0,,,,-0.00245,,,,,,149.9928589,,,,
,32400461.46,149.990387,54802.671875,-0.000148212597559818,2.0419685506719E-6,1,0.999253354069792,40.0298881530762,1.99581563949703,20.7199994474649,-0.00167035109606371,-0.000365942381632275,0.25,-6.41118334942282E-6,-0.000148930065119083,-6.67358149616646E-6,149.9902802,149.9904938,54790.40625,54814.9375,57.3699700545061,20.513408444664,25.566563,0,0,0,40,4449,149.8007,54802.671875,,,,,,,,,,,,,0,,,,-0.00245,,,,,,149.990387,,,,
,32400558.63,149.9894409,49947.5859375,-0.000131092490262106,2.21622675498174E-6,1,0.999253354069792,40.0298881530762,1.99567434206988,20.7199994474649,-0.00147359148724336,-0.000344978060670384,0.25,-7.54832802262659E-6,-0.00013172398484044,-7.79026989603243E-6,149.9894409,149.9894409,49942.7109375,49952.4609375,57.1714364106214,20.5159658889211,25.186911,0,0,0,40,4449,149.81055,49947.5859375,,,,,,,,,,,,,0,,,,0.0049,,,,,,149.9894409,,,,
,32400654.845,149.9907684,45137.701171875,-0.000113688402282661,1.81340680878834E-6,1,0.999253354069792,40.0298881530762,1.99559597614167,20.7199994474649,-0.00128060571752619,-0.000283661870651763,0.25,-5.1801160044214E-6,-0.000114238045440778,-5.38377921762789E-6,149.9907684,149.9907684,45130.1640625,45145.23828125,57.268358347006,20.5154904184916,25.186911,0,0,0,40,4449,149.8176,45137.701171875,,,,,,,,,,,,,0,,,,-0.0049,,,,,,149.9907684,,,,
,32400750.525,149.9902802,40354.74609375,-9.63372278753224E-5,1.8477607842384E-6,1,0.999253354069792,40.0298881530762,1.99579361385483,20.7199994474649,-0.00108526501358816,-0.000240365058972907,0.25,-4.38672463026477E-6,-9.68028709137333E-5,-4.55974115857153E-6,149.9902802,149.9902802,40347.44921875,40362.04296875,56.9564885678329,20.5151267304246,25.566563,0,0,0,40,4449,149.8264,40354.74609375,,,,,,,,,,,,,0,,,,0.0049,,,,,,149.9902802,,,,
,32400846.675,149.991745,35549.599609375,-7.80374259244251E-5,1.08510333409177E-6,1,0.999253354069792,40.0298881530762,1.99562622584644,20.7199994474649,-0.000877779932754679,-0.000201931719119409,0.25,-4.19082148060633E-6,-7.84135133633822E-5,-4.33445842854172E-6,149.991745,149.991745,35544.734375,35554.46484375,57.4410982497561,20.5177819657499,25.186911,0,0,0,40,4449,149.8346,35549.599609375,,,,,,,,,,,,,0,,,,0,,,,,,149.991745,,,,
,32400944.1,149.9929047,30679.48828125,-6.27587488244472E-5,1.41224208558777E-6,1,0.999253354069792,40.0298881530762,1.99568767850118,20.7199994474649,-0.000707256148592548,-0.000154858487759126,0.25,-2.70578417022264E-6,-6.30621741281474E-5,-2.81832626187807E-6,149.9929047,149.9929047,30671.8671875,30687.109375,57.2394380917945,20.5169207159661,25.566563,0,0,0,40,4449,149.84405,30679.48828125,,,,,,,,,,,,,0,,,,-0.00245,,,,,,149.9929047,,,,
,32401038.745,149.9909821,25951.7529296875,-4.48650494107662E-5,1.20463684402224E-6,1,0.999253354069792,40.0298881530762,1.99570599190091,20.7199994474649,-0.000504502655157302,-0.000117051456338603,0.25,-2.49292873539075E-6,-4.50810273446866E-5,-2.57631634447675E-6,149.9909821,149.9909821,25944.125,25959.380859375,57.3066581444484,20.5154449866874,25.186911,0,0,0,40,4449,149.85105,25951.7529296875,,,,,,,,,,,,,0,,,,0.00245,,,,,,149.9909821,,,,
,32401135.365,149.9895172,21121.873046875,-2.96798842339587E-5,1.39262848552797E-6,1,0.999253354069792,40.0298881530762,1.99540081069023,20.7199994474649,-0.000331771820663898,-8.84793591019873E-5,0.25,-2.62294307377632E-6,-2.98211785233469E-5,-2.68300721764751E-6,149.9895172,149.9895172,21111.958984375,21131.787109375,57.115940785756,20.5190127792396,25.566563,0,0,0,40,4449,149.85755,21121.873046875,,,,,,,,,,,,,0,,,,0.00245,,,,,,149.9895172,,,,
,32401229.245,149.9906006,16429.5224609375,-1.33736528805584E-5,9.31289745833822E-7,1,0.999253354069792,40.0298881530762,1.9954118532665,20.7199994474649,-0.000148492838572223,-4.56260075894841E-5,0.25,-1.68894981088268E-6,-1.34364941862684E-5,-1.71855158862287E-6,149.9906006,149.9906006,16424.517578125,16434.52734375,56.7892200647175,20.5187369530438,25.946213,0,0,0,40,4449,149.8676,16429.5224609375,,,,,,,,,,,,,0,,,,0,,,,,,149.9906006,,,,
,32401326.695,149.9911957,11557.26953125,1.82099692173472E-6,5.78853248403091E-7,1,0.999253354069792,40.0298881530762,1.9955436658141,20.7199994474649,2.31237878231442E-5,-1.04520933600658E-5,0.25,-1.23782139926957E-6,1.83189743340921E-6,-1.24097490715393E-6,149.9911957,149.9911957,11552.1845703125,11562.3544921875,57.7271742877946,20.517941824224,25.566563,0,0,0,40,4449,149.8724,11557.26953125,,,,,,,,,,,,,0,,,,-0.0049,,,,,,149.9911957,,,,
,32401421.45,149.9919128,6821.48974609375,1.52277725364294E-5,5.1589104007432E-7,1,0.999253354069792,40.0298881530762,1.99555611374269,20.7199994474649,0.000174515687054061,2.08182570788452E-5,0.25,-8.19392899173729E-7,1.53036795505052E-5,-7.99009537772538E-7,149.9919128,149.9919128,6809.0615234375,6833.91796875,57.3840393678522,20.5203224079389,25.566563,0,0,0,40,4449,149.879,6821.48974609375,,,,,,,,,,,,,0,,,,0,,,,,,149.9919128,,,,
,32401518.745,149.9920349,1960.93011474609,2.53848522518827E-5,3.46260702559998E-7,1,0.999253354069792,40.0298881530762,1.9953612109609,20.7199994474649,0.000288683250576472,4.7379690218539E-5,0.25,-2.49228970308238E-7,2.55095841893094E-5,-2.09700682688963E-7,149.9920349,149.9920349,1955.9541015625,1965.90612792969,56.7024592990829,20.5194511412475,25.566563,0,0,0,40,4449,149.88765,1960.93011474609,,,,,,,,,,,,,0,,,,0.0049,,,,,,149.9920349,,,,
,32401557.405,149.9928131,-0.487160757184029,2.72792550991831E-5,4.03141166950771E-7,1,0.999253354069792,40.0298881530762,1.99547113728869,20.7199994474649,0.000310353737489742,5.02834172073045E-5,0.25,-3.2376184189754E-7,2.74133794267659E-5,-2.81532705786906E-7,149.9928131,149.9928131,-0.502384543418884,-0.471936970949173,57.4708001334869,20.5219373634779,25.186911,0,0,0,40,4417,149.8892,-0.487160757184029,,,,,,,,,,,,,0,,,,0.0049,,,,,,149.9928131,,,,