File: data/monolayers/magneticStructure/ML_Ac_CoFe_C/PPMS/data/DD205_4_HYST_100OE_20K.DAT
[Header]
; VSM Data File (default extension .dat)
; Copyright (c) 2003-2013, Quantum Design, Inc. All rights reserved.
TITLE,
FILEOPENTIME,32354156.89,01/10/2019,7:18 pm
BYAPP,VSM,2.0,2.0
INFO,PPMS VSM Option Release 1.4.10 Build 1,APPNAME
INFO,Quantum Design Linear Motor Servo Controller,MOTOR_MODULE_NAME
INFO,3101-100 M1,MOTOR_HW_VERSION
INFO,MMC1014,MOTOR_SERIAL_NUMBER
INFO,SRV No X-over 01.03.11,MOTOR_SOFTWARE_VERSION
INFO,Quantum Design VSM Detection Module,VSM_MODULE_NAME
INFO,3101-150 F0,VSM_HW_VERSION
INFO,VSM707,VSM_SERIAL_NUMBER
INFO,VSM No X-over 01.02.05 May 20 2008 13:51:47,VSM_SOFTWARE_VERSION
INFO,704,PREAMP_SERIAL_NUMBER
INFO,822,COIL_SERIAL_NUMBER
INFO,0,MOMENT_UNITS
INFO,DD205_4,SAMPLE_MATERIAL
INFO,Monolayer,SAMPLE_COMMENT
INFO,29.55,SAMPLE_MASS
INFO,,SAMPLE_VOLUME
INFO,,SAMPLE_MOLECULAR_WEIGHT
INFO,,SAMPLE_SIZE
INFO,,SAMPLE_SHAPE
DATATYPE,COMMENT,1
DATATYPE,TIME,2
STARTUPAXIS,X,2
STARTUPAXIS,Y1,5
[Data]
Comment,Time Stamp (sec),Temperature (K),Magnetic Field (Oe),Moment (emu),M. Std. Err. (emu),Transport Action,Averaging Time (sec),Frequency (Hz),Peak Amplitude (mm),Center Position (mm),Coil Signal' (mV),Coil Signal" (mV),Range (mV),M. Quad. Signal (emu),M. Raw' (emu),M. Raw" (emu),Min. Temperature (K),Max. Temperature (K),Min. Field (Oe),Max. Field (Oe),Mass (grams),Motor Lag (deg),Pressure (Torr),VSM Status (code),Motor Status (code),Measure Status (code),Measure Count,PPMS Status (code),System Temp. (K),System Field (Oe),Sample Position (deg),Bridge 1 Resistance (ohms),Bridge 1 Excitation (에),Bridge 2 Resistance (ohms),Bridge 2 Excitation (에),Bridge 3 Resistance (ohms),Bridge 3 Excitation (에),Bridge 4 Resistance (ohms),Bridge 4 Excitation (에),Signal 1 Vin (V),Signal 2 Vin (V),Digital Inputs (code),Drive 1 Iout (mA),Drive 1 Ipower (W),Drive 2 Iout (mA),Drive 2 Ipower (W),Pressure (),Map 20 (),Map 21 (),Map 22 (),Map 23 (),Map 24 (),Map 25 (),Map 26 (),Map 27 (),Map 28 (),Map 29 ()
,32354171.97,20.0018749,-0.137013956904411,,,2,,,,21.3599992692471,,,,,,,20.0018749,20.0018749,-0.137013956904411,-0.137013956904411,,,12.658426,,,,-99999999,4369,20.0188,-0.137013956904411,,,,,,,,,,,,,,,,,,,,,,,20.0018749,,,,
,32354319.625,20.0000973,4463.68798828125,2.6526682297121E-5,2.86992671234942E-7,1,0.999253354069792,40.0298881530762,1.98349031970291,21.339999511838,0.000296401555620222,5.13214526458363E-5,0.25,-1.21685952661821E-7,2.63811743453882E-5,1.46430437164342E-8,20.0000973,20.0000973,4461.14453125,4466.2314453125,56.5695824508137,20.5267273476364,12.278775,0,0,0,40,4449,20.0166,4463.68798828125,,,,,,,,,,,,,0,,,,0,,,,,,20.0000973,,,,
,32354412.055,20.0005569,9082.43408203125,1.14018271089321E-5,2.9407605200018E-7,1,0.999253354069792,40.0298881530762,1.98357991320024,21.339999511838,0.000127570617053859,2.13897319911095E-5,0.25,-1.16817718430765E-7,1.13434894857503E-5,-5.40972727452766E-8,20.0005569,20.0005569,9072.4248046875,9092.443359375,56.8705094307176,20.5297404060063,12.658426,0,0,0,40,4449,20.0167,9082.43408203125,,,,,,,,,,,,,0,,,,-0.00245,,,,,,20.0005569,,,,
,32354512.95,20.0013218,14125.1440429688,-5.97189755678055E-6,4.14365202268719E-7,1,0.999253354069792,40.0298881530762,1.98378962241694,21.339999511838,-6.61476750493575E-5,-1.51576673152801E-5,0.25,-2.90013447676676E-7,-5.94185486451389E-6,-3.23356169871873E-7,20.0013218,20.0013218,14120.248046875,14130.0400390625,56.9650864815445,20.532189231603,12.658426,0,0,0,40,4449,20.0152,14125.1440429688,,,,,,,,,,,,,0,,,,0,,,,,,20.0013218,,,,
,32354608.195,20.0020542,18887.490234375,-2.24064004298726E-5,4.74903213800993E-7,1,0.999253354069792,40.0298881530762,1.98364081289835,21.339999511838,-0.000249372311059327,-5.07472742389082E-5,0.25,-5.31101542388901E-7,-2.23066127364744E-5,-6.66390558598922E-7,20.0020542,20.0020542,18877.568359375,18897.412109375,56.6391473890252,20.5342310702833,13.038077,0,0,0,40,4449,20.0137,18887.490234375,,,,,,,,,,,,,0,,,,-0.0049,,,,,,20.0020542,,,,
,32354700.745,20.0020313,23510.1005859375,-3.7441358492787E-5,5.20411379777433E-7,1,0.999253354069792,40.0298881530762,1.98375732998125,21.339999511838,-0.000416422977064574,-8.75914920962365E-5,0.25,-1.12260258077307E-6,-3.72898705793964E-5,-1.35895338504634E-6,20.0020313,20.0020313,23504.970703125,23515.23046875,56.7743691228522,20.5352647846337,12.658426,0,0,0,40,4449,20.0122,23510.1005859375,,,,,,,,,,,,,0,,,,0,,,,,,20.0020313,,,,
,32354795.585,20.0016727,28252.8603515625,-5.35860195419487E-5,5.89458608706201E-7,1,0.999253354069792,40.0298881530762,1.98375714913209,21.339999511838,-0.000597630636453641,-0.000117846719233666,0.25,-9.15765883835817E-7,-5.3399450141204E-5,-1.27107304937994E-6,20.0016727,20.0016727,28247.798828125,28257.921875,56.9846271945253,20.5341416791995,12.658426,0,0,0,40,4449,20.0102,28252.8603515625,,,,,,,,,,,,,0,,,,0.0049,,,,,,20.0016727,,,,
,32354891.89,20.0019627,33065.427734375,-7.04063605590211E-5,6.16826494900033E-7,1,0.999253354069792,40.0298881530762,1.9837800870866,21.339999511838,-0.00078595563256966,-0.000153095987455558,0.25,-1.02486507537996E-6,-7.01977435839392E-5,-1.50857972021062E-6,20.0019627,20.0019627,33060.515625,33070.33984375,56.9908802226791,20.5395317193184,13.417728,0,0,0,40,4449,20.00915,33065.427734375,,,,,,,,,,,,,0,,,,0,,,,,,20.0019627,,,,
,32354989.735,20.0030613,37955.291015625,-8.83746288811213E-5,7.44324023696654E-7,1,0.999253354069792,40.0298881530762,1.98386865172991,21.339999511838,-0.000987751296587552,-0.000188603230751799,0.25,-9.42461855559474E-7,-8.81607193986242E-5,-1.56744505100918E-6,20.0030613,20.0030613,37952.66015625,37957.921875,57.2417829773522,20.5367810680012,13.038077,0,0,0,40,4449,20.0081,37955.291015625,,,,,,,,,,,,,0,,,,0,,,,,,20.0030613,,,,
,32355081.97,20.0013866,42565.39453125,-0.000104372238917147,7.18687134396822E-7,1,0.999253354069792,40.0298881530762,1.9838696067351,21.339999511838,-0.00116849650611169,-0.000215222755899805,0.25,-4.18195585390127E-7,-0.000104175209322056,-1.17231579533111E-6,20.0013866,20.0013866,42555.19921875,42575.58984375,57.4176493941791,20.5320354580988,12.658426,0,0,0,40,4449,20.0061,42565.39453125,,,,,,,,,,,,,0,,,,-0.00245,,,,,,20.0013866,,,,
,32355173.95,20.0021725,47163.55078125,-0.000121972454150925,1.0343667482028E-6,1,0.999253354069792,40.0298881530762,1.98381612768108,21.339999511838,-0.00136441285969601,-0.000261317799043342,0.25,-1.34132723878314E-6,-0.000121794178244333,-2.23383011894056E-6,20.0021725,20.0021725,47153.49609375,47173.60546875,56.7266897831791,20.5340073363081,13.038077,0,0,0,40,4449,20.00485,47163.55078125,,,,,,,,,,,,,0,,,,0,,,,,,20.0021725,,,,
,32355269.96,20.0031681,51960.642578125,-0.000138183639363113,8.60261718828059E-7,1,0.999253354069792,40.0298881530762,1.98380166381781,21.339999511838,-0.00154419379834704,-0.000308973408764087,0.25,-2.65047794051182E-6,-0.000138040454452709,-3.67080050775955E-6,20.0031681,20.0031681,51955.83984375,51965.4453125,57.2370932062368,20.5369947977181,13.038077,0,0,0,40,4449,20.0079,51960.642578125,,,,,,,,,,,,,0,,,,-0.00245,,,,,,20.0031681,,,,
,32355364.725,20.0013428,56696.529296875,-0.000155288055439208,8.44061900626657E-7,1,0.999253354069792,40.0298881530762,1.98375784684288,21.339999511838,-0.00174102250321465,-0.00032009161393235,0.25,-5.41878567092084E-7,-0.000155217390291829,-1.6963927197858E-6,20.0013428,20.0013428,56694.046875,56699.01171875,57.291807202583,20.5363548488873,12.658426,0,0,0,40,4449,20.0045,56696.529296875,,,,,,,,,,,,,0,,,,0.0049,,,,,,20.0013428,,,,
,32355457.89,20.0009689,61353.8828125,-0.000171727888266765,9.13101489885528E-7,1,0.999253354069792,40.0298881530762,1.98365966876573,21.339999511838,-0.00192648171656715,-0.000351973712958656,0.25,-4.07665779481592E-7,-0.000171726723079491,-1.68577045503199E-6,20.0009689,20.0009689,61346.26171875,61361.50390625,57.3988903097176,20.5365291789876,13.417728,0,0,0,40,4449,20.0026,61353.8828125,,,,,,,,,,,,,0,,,,-0.00245,,,,,,20.0009689,,,,
,32355557,20.00202655,66307.42578125,-0.000189891258693656,8.38565385740755E-7,1,0.999253354069792,40.0298881530762,1.98371000257652,21.339999511838,-0.00213115823252628,-0.000389872227525046,0.25,-4.98651648765997E-7,-0.000189974507343054,-1.90833943146019E-6,20.0017319,20.0023212,66299.671875,66315.1796875,56.8877052581406,20.5353356178992,13.038077,0,0,0,40,4449,20.00135,66307.42578125,,,,,,,,,,,,,0,,,,0.00245,,,,,,20.00202655,,,,
,32355657.745,20.0013542,71342.40234375,-0.000209965208545822,9.1211675044544E-7,1,0.999253354069792,40.0298881530762,1.98369437305979,21.339999511838,-0.00235284766403771,-0.000456788357457278,0.25,-2.8332605678641E-6,-0.000210130914880806,-4.38477729083541E-6,20.0013542,20.0013542,71337.5546875,71347.25,57.0596635323714,20.5355635482759,13.417728,0,0,0,40,4449,20.0004,71342.40234375,,,,,,,,,,,,,0,,,,0,,,,,,20.0013542,,,,
,32355753.705,20.0014381,76140.4765625,-0.000226403382126644,1.06802276331525E-6,1,0.999253354069792,40.0298881530762,1.98371446720097,21.339999511838,-0.00254047554157606,-0.0004793395520352,0.25,-1.87685664726485E-6,-0.000226678690501014,-3.53537929813919E-6,20.0014381,20.0014381,76135.671875,76145.28125,56.8384626614291,20.5347964664949,13.797379,0,0,0,40,4449,19.99855,76140.4765625,,,,,,,,,,,,,0,,,,0.0049,,,,,,20.0014381,,,,
,32355850.485,20.002697,80976.33203125,-0.000246039066980464,1.05762479271514E-6,1,0.999253354069792,40.0298881530762,1.98365427505496,21.339999511838,-0.00276209910912171,-0.000519115118782396,0.25,-1.88415854684526E-6,-0.000246430180404179,-3.66756732054051E-6,20.002697,20.002697,80968.8203125,80983.84375,56.8845787440637,20.5343758954275,13.038077,0,0,0,40,4449,19.996,80976.33203125,,,,,,,,,,,,,0,,,,0.00245,,,,,,20.002697,,,,
,32355942.915,20.0022907,85597.1484375,-0.000263308438205773,1.37256718400542E-6,1,0.999253354069792,40.0298881530762,1.98371689302195,21.339999511838,-0.00295812435299667,-0.000549704200195565,0.25,-1.50238251802408E-6,-0.00026381804868461,-3.38745115563557E-6,20.0022907,20.0022907,85592.265625,85602.03125,57.0018230219483,20.5344043855827,13.417728,0,0,0,40,4449,19.9942,85597.1484375,,,,,,,,,,,,,0,,,,-0.00245,,,,,,20.0022907,,,,
,32356032.53,20.0019302,89999.390625,-0.000279104634203641,1.04005020769735E-6,1,0.999253354069792,40.0298881530762,1.98364491114923,21.339999511838,-0.00314079657882493,-0.000558419504827897,0.25,5.51339307579329E-7,-0.000279742969554631,-1.41644802659392E-6,20.0019302,20.0019302,89999.3828125,89999.3984375,57.3762230826599,20.5345176499052,13.797379,0,0,0,40,4417,19.99325,89999.390625,,,,,,,,,,,,,0,,,,0.0049,,,,,,20.0019302,,,,
,32356136.875,20.0004978,85748.7109375,-0.000265057635165827,1.31333721252279E-6,1,0.999253354069792,40.0298881530762,1.98367141298768,21.339999511838,-0.00297897285007065,-0.000546506889368443,0.25,-9.04723746650848E-7,-0.000265577765098681,-2.80031228856348E-6,20.0004978,20.0004978,85743.953125,85753.46875,57.159711982833,20.5356777623006,13.038077,0,0,0,40,4449,19.99225,85748.7109375,,,,,,,,,,,,,0,,,,0.0049,,,,,,20.0004978,,,,
,32356229.265,19.9994507,81130.38671875,-0.000246135645671015,1.02129688644415E-6,1,0.999253354069792,40.0298881530762,1.98364409672509,21.339999511838,-0.00276771947057812,-0.000494223458123885,0.25,3.47028782110998E-7,-0.000246545858397256,-1.43272831181757E-6,19.9994507,19.9994507,81125.4453125,81135.328125,56.8462789466214,20.5372326678751,13.417728,0,0,0,40,4449,19.9931,81130.38671875,,,,,,,,,,,,,0,,,,-0.00245,,,,,,19.9994507,,,,
,32356327.845,19.9982414,76201.34375,-0.000226770003826147,1.02802882904366E-6,1,0.999253354069792,40.0298881530762,1.98365034008844,21.339999511838,-0.00254487848848182,-0.000478129064408377,0.25,-1.70443108063072E-6,-0.000227048122342696,-3.36522057115897E-6,19.9982414,19.9982414,76196.5546875,76206.1328125,57.2097362080637,20.5349460989719,13.797379,0,0,0,40,4449,19.9941,76201.34375,,,,,,,,,,,,,0,,,,0.00245,,,,,,19.9982414,,,,
,32356422.76,19.9981823,71455.0390625,-0.000209093211521875,1.20082953452392E-6,1,0.999253354069792,40.0298881530762,1.98366810628569,21.339999511838,-0.00234985597358949,-0.000417217804568558,0.25,5.31866877591523E-7,-0.000209284921365622,-1.00995825171357E-6,19.9981823,19.9981823,71452,71458.078125,57.3910740245253,20.5374545441809,13.038077,0,0,0,40,4449,19.9963,71455.0390625,,,,,,,,,,,,,0,,,,-0.0049,,,,,,19.9981823,,,,
,32356516.565,19.9980392,66766.98828125,-0.000193345302499813,1.07696545242196E-6,1,0.999253354069792,40.0298881530762,1.98366797696736,21.339999511838,-0.00216471230377063,-0.000426126207291999,0.25,-3.10483078720869E-6,-0.000193418591861125,-4.54086735085402E-6,19.9980392,19.9980392,66759.9453125,66774.03125,56.851750346256,20.5391032056981,13.417728,0,0,0,40,4449,19.9978,66766.98828125,,,,,,,,,,,,,0,,,,-0.0049,,,,,,19.9980392,,,,
,32356610.775,19.9983444,62058.533203125,-0.000173737730786438,1.06620078964041E-6,1,0.999253354069792,40.0298881530762,1.98372772504381,21.339999511838,-0.00194531197648032,-0.000377803414594694,0.25,-2.34389500057615E-6,-0.000173733458817407,-3.63691357764063E-6,19.9980659,19.9986229,62056.3046875,62060.76171875,57.0760777312753,20.5374381775185,13.417728,0,0,0,40,4449,19.9989,62058.533203125,,,,,,,,,,,,,0,,,,0.0049,,,,,,19.9983444,,,,
,32356703.68,19.9972687,57413.22265625,-0.000155839759397659,9.40212839216069E-7,1,0.999253354069792,40.0298881530762,1.98377648406116,21.339999511838,-0.00174428756752443,-0.000338210551919677,0.25,-2.05482068003981E-6,-0.000155768330844468,-3.21335413745637E-6,19.9972687,19.9972687,57408.12109375,57418.32421875,57.4192126512176,20.5366238185003,13.417728,0,0,0,40,4449,19.9994,57413.22265625,,,,,,,,,,,,,0,,,,0,,,,,,19.9972687,,,,
,32356796.925,20.0003014,52755.373046875,-0.00014166049304489,1.0310021550933E-6,1,0.999253354069792,40.0298881530762,1.9838419347132,21.339999511838,-0.0015840330015634,-0.000312175372315941,0.25,-2.30563548825403E-6,-0.000141527942782525,-3.35332269690461E-6,20.0003014,20.0003014,52750.41796875,52760.328125,56.7532651528329,20.5349175115496,13.417728,0,0,0,40,4449,20.00125,52755.373046875,,,,,,,,,,,,,0,,,,-0.00245,,,,,,20.0003014,,,,
,32356889.705,19.999176,48117.57421875,-0.000123898951169166,9.97688845261791E-7,1,0.999253354069792,40.0298881530762,1.98380019235608,21.339999511838,-0.00138605161495003,-0.000265672015351314,0.25,-1.37866444415788E-6,-0.000123729838694964,-2.28740995662578E-6,19.999176,19.999176,48107.5390625,48127.609375,57.166746639506,20.5369500538474,13.797379,0,0,0,40,4449,19.99995,48117.57421875,,,,,,,,,,,,,0,,,,0,,,,,,19.999176,,,,
,32356982.47,20.0001907,43482.208984375,-0.000108374399401226,7.27851405288119E-7,1,0.999253354069792,40.0298881530762,1.98375386335989,21.339999511838,-0.00121023669250222,-0.000240782769695673,0.25,-1.97578941626854E-6,-0.000108169012259011,-2.75860407479673E-6,20.0001907,20.0001907,43479.59765625,43484.8203125,57.2894623170253,20.5402677455524,13.797379,0,0,0,40,4449,20.00035,43482.208984375,,,,,,,,,,,,,0,,,,-0.0049,,,,,,20.0001907,,,,
,32357075.65,19.9995003,38824.85546875,-9.06896254464492E-5,6.5184719202762E-7,1,0.999253354069792,40.0298881530762,1.98387368059913,21.339999511838,-0.00101152403379784,-0.000205773760385245,0.25,-2.05502437090257E-6,-9.04706668142522E-5,-2.69659304123799E-6,19.9995003,19.9995003,38822.08984375,38827.62109375,57.1886322380445,20.539445459947,13.417728,0,0,0,40,4449,20.0003,38824.85546875,,,,,,,,,,,,,0,,,,0,,,,,,19.9995003,,,,
,32357167.605,19.9997034,34227.28125,-7.47088986205085E-5,7.01645042172562E-7,1,0.999253354069792,40.0298881530762,1.98382134792632,21.339999511838,-0.000834866502845264,-0.000158235426053016,0.25,-7.05251414953643E-7,-7.44993109342769E-5,-1.2232767502154E-6,19.9994545,19.9999523,34219.76171875,34234.80078125,57.2253687784484,20.5385024837997,13.797379,0,0,0,40,4449,20.0018,34227.28125,,,,,,,,,,,,,0,,,,0,,,,,,19.9997034,,,,
,32357260.34,19.9992256,29592.16796875,-5.82649102964325E-5,6.78927898889116E-7,1,0.999253354069792,40.0298881530762,1.98382048233838,21.339999511838,-0.00064924568474961,-0.000131932697964999,0.25,-1.32923430459818E-6,-5.80678619080493E-5,-1.71849486507817E-6,19.9992256,19.9992256,29581.921875,29602.4140625,57.5888260398907,20.5399273657146,13.038077,0,0,0,40,4449,20.00265,29592.16796875,,,,,,,,,,,,,0,,,,-0.00245,,,,,,19.9992256,,,,
,32357355.4,19.99836255,24839.365234375,-4.16766678466892E-5,5.62849275719607E-7,1,0.999253354069792,40.0298881530762,1.98376415800915,21.339999511838,-0.000462758680700269,-0.000102156855523524,0.25,-1.66165926902126E-6,-4.15108701587304E-5,-1.92657416287812E-6,19.9982948,19.9984303,24829.607421875,24849.123046875,56.922878541506,20.5405019576155,13.038077,0,0,0,40,4449,20.00385,24839.365234375,,,,,,,,,,,,,0,,,,-0.0049,,,,,,19.99836255,,,,
,32357447.75,19.9989109,20226.8544921875,-2.56142972124843E-5,5.81746449228787E-7,1,0.999253354069792,40.0298881530762,1.98385159198968,21.339999511838,-0.000284438869278372,-6.19432912447223E-5,0.25,-9.55333103679302E-7,-2.55013123991423E-5,-1.11083228622392E-6,19.9989109,19.9989109,20216.716796875,20236.9921875,57.2081729510253,20.5403628154668,13.417728,0,0,0,40,4449,20.005,20226.8544921875,,,,,,,,,,,,,0,,,,-0.0049,,,,,,19.9989109,,,,
,32357541.74,19.9987183,15527.3833007813,-9.38183803205816E-6,4.22991672806986E-7,1,0.999253354069792,40.0298881530762,1.98399853254643,21.339999511838,-0.000103255371395264,-2.76548702051754E-5,0.25,-7.98010576256569E-7,-9.33375340856047E-6,-8.4979057156084E-7,19.9987183,19.9987183,15519.8486328125,15534.91796875,57.2621053188522,20.5375688491524,14.177031,0,0,0,40,4449,20.00435,15527.3833007813,,,,,,,,,,,,,0,,,,-0.00245,,,,,,19.9987183,,,,
,32357635.06,19.9988365,10864.7915039062,6.61411127438376E-6,3.60248080976252E-7,1,0.999253354069792,40.0298881530762,1.98391523730057,21.339999511838,7.44899527190681E-5,9.80794001629885E-6,0.25,-3.01713962848452E-7,6.58253562684673E-6,-2.63300636346938E-7,19.9988365,19.9988365,10857.263671875,10872.3193359375,57.4778347901599,20.5388119716176,13.417728,0,0,0,40,4449,20.0067,10864.7915039062,,,,,,,,,,,,,0,,,,0.00245,,,,,,19.9988365,,,,
,32357729.445,19.9993343,6146.92407226563,2.18433907296581E-5,3.28549631803116E-7,1,0.999253354069792,40.0298881530762,1.98390371949779,21.339999511838,0.000243662697984975,4.50061721585286E-5,0.25,1.41832386027371E-7,2.17248398984057E-5,2.55384090489268E-7,19.9993343,19.9993343,6139.48046875,6154.36767578125,57.0893654161022,20.535745425078,13.038077,0,0,0,40,4449,20.0071,6146.92407226563,,,,,,,,,,,,,0,,,,0.0049,,,,,,19.9993343,,,,
,32357822.455,19.9999075,1495.78784179687,3.71024151208302E-5,3.46970049424059E-7,1,0.999253354069792,40.0298881530762,1.9839665715529,21.339999511838,0.000414055836476354,7.48046238740425E-5,0.25,1.07367273101535E-7,3.68909205650506E-5,2.89294376464468E-7,19.9998722,19.9999428,1490.82507324219,1500.75061035156,57.1221938139099,20.5378429514913,13.797379,0,0,0,40,4449,20.0073,1495.78784179687,,,,,,,,,,,,,0,,,,-0.0049,,,,,,19.9999075,,,,
,32357913.925,19.9999008,-3069.60205078125,4.94426254682077E-5,3.09611613380491E-7,1,0.999253354069792,40.0298881530762,1.98393062656931,21.339999511838,0.000552710188109709,9.46286152595293E-5,0.25,-3.15259313885148E-7,4.91674657851333E-5,-6.53484827436515E-8,19.9999008,19.9999008,-3077.16381835937,-3062.04028320313,57.6490114358715,20.5369267296732,13.417728,0,0,0,40,4449,20.00755,-3069.60205078125,,,,,,,,,,,,,0,,,,-0.00245,,,,,,19.9999008,,,,
,32358007.22,19.9999771,-7734.57983398438,6.23668998867793E-5,3.3630487510871E-7,1,0.999253354069792,40.0298881530762,1.98394243159905,21.339999511838,0.000696152193568322,0.000126520579083694,0.25,2.18891612569924E-7,6.20366424453029E-5,5.51332488662239E-7,19.9999771,19.9999771,-7742.23291015625,-7726.9267578125,57.5411467002176,20.5393872056969,13.417728,0,0,0,40,4449,20.008,-7734.57983398438,,,,,,,,,,,,,0,,,,0.0049,,,,,,19.9999771,,,,
,32358103.265,20.0004559,-12534.962890625,7.29521564969761E-5,4.22477188141386E-7,1,0.999253354069792,40.0298881530762,1.98399090631727,21.339999511838,0.000814022902969837,0.000151542392290939,0.25,5.42523149164693E-7,7.25925094244732E-5,9.55685064739721E-7,20.0004559,20.0004559,-12544.876953125,-12525.048828125,57.80299225416,20.5403957482926,13.038077,0,0,0,40,4449,20.0067,-12534.962890625,,,,,,,,,,,,,0,,,,0,,,,,,20.0004559,,,,
,32358197.69,20.0015011,-17254.966796875,7.68917657174182E-5,3.54706028685575E-7,1,0.999253354069792,40.0298881530762,1.9840695607471,21.339999511838,0.000858116843172995,0.00016127527570261,0.25,6.78384384852128E-7,7.65445234111829E-5,1.13909795683918E-6,20.0015011,20.0015011,-17257.4140625,-17252.51953125,57.1128142716791,20.5391972909127,13.797379,0,0,0,40,4449,20.0061,-17254.966796875,,,,,,,,,,,,,0,,,,0,,,,,,20.0015011,,,,
,32358292.47,20.0018578,-21991.91015625,7.56824385842176E-5,4.71526453579842E-7,1,0.999253354069792,40.0298881530762,1.98395900038124,21.339999511838,0.000844227236147646,0.00016291202958632,0.25,1.01214669902424E-6,7.53729013859524E-5,1.4876887148506E-6,20.0018578,20.0018578,-21999.953125,-21983.8671875,57.2136443506599,20.5432740883156,14.177031,0,0,0,40,4449,20.00505,-21991.91015625,,,,,,,,,,,,,0,,,,0.00245,,,,,,20.0018578,,,,
,32358388.25,20.0011539,-26780.4130859375,7.44306604401991E-5,5.84972836995805E-7,1,0.999253354069792,40.0298881530762,1.98398040896429,21.339999511838,0.000830430285970018,0.00016166270549603,0.25,1.09722544312411E-6,7.41614113127074E-5,1.58545530979401E-6,20.0011539,20.0011539,-26783.021484375,-26777.8046875,57.4395349927176,20.540950505638,13.797379,0,0,0,40,4449,20.0027,-26780.4130859375,,,,,,,,,,,,,0,,,,0.0049,,,,,,20.0011539,,,,
,32358483.29,20.0004787,-31527.693359375,7.8681480378806E-5,6.72983466369996E-7,1,0.999253354069792,40.0298881530762,1.98392192899625,21.339999511838,0.000879943524653187,0.000161643852164136,0.25,3.07923162887032E-7,7.8441383167958E-5,8.45559175544643E-7,20.0004787,20.0004787,-31540.068359375,-31515.318359375,57.4293738219676,20.5415649561318,13.417728,0,0,0,40,4449,20.00245,-31527.693359375,,,,,,,,,,,,,0,,,,0,,,,,,20.0004787,,,,
,32358579.29,20.0020361,-36326.998046875,8.88216905305825E-5,7.27321258585832E-7,1,0.999253354069792,40.0298881530762,1.98390734532137,21.339999511838,0.000994414427946563,0.000179412131849212,0.25,4.87114069100264E-8,8.85977520644765E-5,6.73900992816067E-7,20.001873,20.0021992,-36332.12890625,-36321.8671875,57.3871658819292,20.5419617543135,14.177031,0,0,0,40,4449,20.001,-36326.998046875,,,,,,,,,,,,,0,,,,0,,,,,,20.0020361,,,,
,32358675.58,20.0029678,-41136.90625,0.000102425286820527,7.05198471847068E-7,1,0.999253354069792,40.0298881530762,1.98396902975267,21.339999511838,0.0011456934101094,0.000216120851649543,0.25,8.54686652281555E-7,0.000102213369354245,1.58987579691669E-6,20.0029678,20.0029678,-41139.80078125,-41134.01171875,57.3770047111791,20.541064450043,13.417728,0,0,0,40,4449,19.9994,-41136.90625,,,,,,,,,,,,,0,,,,0,,,,,,20.0029678,,,,
,32358771.385,20.002203,-45929.583984375,0.00011870401848468,7.39023115331485E-7,1,0.999253354069792,40.0298881530762,1.98401058555698,21.339999511838,0.00132863191253505,0.000249723582271627,0.25,8.99136910904354E-7,0.000118518394823918,1.76539295406476E-6,20.002203,20.002203,-45936.7265625,-45922.44140625,57.3473028274484,20.5404603719814,13.797379,0,0,0,40,4449,19.9968,-45929.583984375,,,,,,,,,,,,,0,,,,0.00245,,,,,,20.002203,,,,
,32358869.345,20.0017662,-50821.92578125,0.000134930575182671,7.05036616903573E-7,1,0.999253354069792,40.0298881530762,1.98396630006641,21.339999511838,0.00151237198940646,0.000276251731827378,0.25,3.21252121260399E-7,0.000134792108715504,1.31776865362753E-6,20.0017662,20.0017662,-50829.33203125,-50814.51953125,57.799865740083,20.5420903067414,13.797379,0,0,0,40,4449,19.9963,-50821.92578125,,,,,,,,,,,,,0,,,,-0.00245,,,,,,20.0017662,,,,
,32358964.6,20.0012856,-55581.734375,0.000153240471330096,9.67920422152441E-7,1,0.999253354069792,40.0298881530762,1.98411335943134,21.339999511838,0.00171797672813907,0.000316986397636991,0.25,6.33107970766156E-7,0.000153153449697231,1.77143567069309E-6,20.0012856,20.0012856,-55586.70703125,-55576.76171875,57.0862389020253,20.541954755578,13.797379,0,0,0,40,4449,19.9962,-55581.734375,,,,,,,,,,,,,0,,,,0,,,,,,20.0012856,,,,
,32359062.46,20.001009,-60473.666015625,0.000170204162845087,1.02138328518363E-6,1,0.999253354069792,40.0298881530762,1.98405539054746,21.339999511838,0.00190837749145914,0.000355647730447473,0.25,1.00600234511648E-6,0.000170184600167531,2.27282239054628E-6,20.001009,20.001009,-60478.78125,-60468.55078125,57.5028469027753,20.5432658445544,13.417728,0,0,0,40,4449,19.99475,-60473.666015625,,,,,,,,,,,,,0,,,,-0.0049,,,,,,20.001009,,,,
,32359160.25,20.0012951,-65363.755859375,0.000188120050530333,1.00322874414439E-6,1,0.999253354069792,40.0298881530762,1.98395355554125,21.339999511838,0.00211100694844865,0.000388159590868972,0.25,6.62964109443986E-7,0.000188185557332109,2.06061775104193E-6,20.0012951,20.0012951,-65371.22265625,-65356.2890625,57.3988903097176,20.5446988472312,13.417728,0,0,0,40,4449,19.9932,-65363.755859375,,,,,,,,,,,,,0,,,,0,,,,,,20.0012951,,,,
,32359258.025,20.0016651,-70248.19921875,0.000207547836438731,9.30300391451332E-7,1,0.999253354069792,40.0298881530762,1.98408321429622,21.339999511838,0.0023257985477541,0.000452585902596431,0.25,2.88828545708349E-6,0.000207691933239857,4.42418265420226E-6,20.0016651,20.0016651,-70258.3203125,-70238.078125,57.4371901071599,20.5459002698559,14.177031,0,0,0,40,4449,19.99195,-70248.19921875,,,,,,,,,,,,,0,,,,0,,,,,,20.0016651,,,,
,32359353.53,20.0019054,-75020.2890625,0.000224396921979632,1.0985530013453E-6,1,0.999253354069792,40.0298881530762,1.98406244879911,21.339999511838,0.00251839031412051,0.000473850371874311,0.25,1.74268955492825E-6,0.000224650733396654,3.38982880972453E-6,20.0019054,20.0019054,-75025.421875,-75015.15625,57.3824761108138,20.5444375736852,13.797379,0,0,0,40,4449,19.98985,-75020.2890625,,,,,,,,,,,,,0,,,,0,,,,,,20.0019054,,,,
,32359450.575,20.0014572,-79872.05078125,0.000243897118464013,9.31366573020689E-7,1,0.999253354069792,40.0298881530762,1.98416589036648,21.339999511838,0.00274082784514205,0.00050176714504925,0.25,7.14402298380469E-7,0.000244273112853849,2.48504476242464E-6,20.0014572,20.0014572,-79877.1171875,-79866.984375,57.3715333115445,20.5446488936231,13.417728,0,0,0,40,4449,19.9884,-79872.05078125,,,,,,,,,,,,,0,,,,0,,,,,,20.0014572,,,,
,32359545.36,20.0023232,-84607.140625,0.00025851456160958,1.27385813251217E-6,1,0.999253354069792,40.0298881530762,1.9840864035398,21.339999511838,0.00290488502631249,0.000538080781069265,0.25,1.32096001025257E-6,0.000258998055251006,3.17642285727278E-6,20.0023232,20.0023232,-84614.609375,-84599.671875,57.4661103623715,20.5436838645603,14.177031,0,0,0,40,4449,19.9865,-84607.140625,,,,,,,,,,,,,0,,,,-0.00245,,,,,,20.0023232,,,,
,32359634.725,20.0021801,-89074.2421875,0.000278111326812585,1.32447958141918E-6,1,0.999253354069792,40.0298881530762,1.98408488749468,21.339999511838,0.00312449079045039,0.000587659349284101,0.25,2.21297404841407E-6,0.000278710901389551,4.18552586217721E-6,20.0021801,20.0021801,-89081.859375,-89066.625,57.3379232852176,20.5473140994078,13.797379,0,0,0,40,4449,19.9856,-89074.2421875,,,,,,,,,,,,,0,,,,0,,,,,,20.0021801,,,,
,32359744.635,19.997364,-86357.09765625,0.000268180970698403,9.99458649045407E-7,1,0.999253354069792,40.0298881530762,1.98405661066843,21.339999511838,0.00301514321414746,0.000550949058489202,0.25,7.30011909832735E-7,0.000268719823593245,2.64427544806504E-6,19.997364,19.997364,-86364.734375,-86349.4609375,57.4840878183138,20.5464694577188,13.797379,0,0,0,40,4449,19.98405,-86357.09765625,,,,,,,,,,,,,0,,,,0,,,,,,19.997364,,,,
,32359837.38,19.9980545,-81722.51953125,0.000250151548220606,1.26285583011961E-6,1,0.999253354069792,40.0298881530762,1.98407838338859,21.339999511838,0.00281037169087831,0.000520276147489662,0.25,1.23856013377397E-6,0.000250567824540187,3.04737132055868E-6,19.9980545,19.9980545,-81732.34375,-81712.6953125,57.4387533641984,20.544301884851,14.177031,0,0,0,40,4449,19.9857,-81722.51953125,,,,,,,,,,,,,0,,,,-0.00245,,,,,,19.9980545,,,,
,32359932.81,19.998867,-76952.33984375,0.000232555031346259,9.48140904880851E-7,1,0.999253354069792,40.0298881530762,1.98403581562123,21.339999511838,0.00261453423255094,0.000467695781986371,0.25,-2.73364161505711E-7,0.000232868653600015,1.42455548129055E-6,19.998867,19.998867,-76959.8125,-76944.8671875,57.5552160135638,20.5462993239486,13.417728,0,0,0,40,4449,19.98705,-76952.33984375,,,,,,,,,,,,,0,,,,0,,,,,,19.998867,,,,
,32360027.6,19.9992924,-72215.1328125,0.00021393438425463,1.153006632243E-6,1,0.999253354069792,40.0298881530762,1.9840434658829,21.339999511838,0.00240272691838597,0.000438753663666934,0.25,5.05506448900033E-7,0.000214136227463231,2.08212742358791E-6,19.9992924,19.9992924,-72222.5859375,-72207.6796875,57.1253203279868,20.5435731966305,13.797379,0,0,0,40,4449,19.98875,-72215.1328125,,,,,,,,,,,,,0,,,,0,,,,,,19.9992924,,,,
,32360124.465,19.9979954,-67373.48828125,0.000195869858876746,7.31816100769915E-7,1,0.999253354069792,40.0298881530762,1.98408636353107,21.339999511838,0.0021993066357053,0.000399775681032728,0.25,2.95010233255191E-7,0.000195975605935844,1.74752073230998E-6,19.9979954,19.9979954,-67375.9453125,-67371.03125,57.3840393678522,20.5454268637756,14.177031,0,0,0,40,4449,19.99045,-67373.48828125,,,,,,,,,,,,,0,,,,-0.00245,,,,,,19.9979954,,,,
,32360221.93,19.9981976,-62501.068359375,0.000177666198432301,9.24341949066356E-7,1,0.999253354069792,40.0298881530762,1.98408243938237,21.339999511838,0.00199448590203244,0.000359979880628954,0.25,4.12943014087674E-8,0.00017768655324573,1.3631831424237E-6,19.9981976,19.9981976,-62508.47265625,-62493.6640625,57.3090030300061,20.5472137632252,13.797379,0,0,0,40,4449,19.9921,-62501.068359375,,,,,,,,,,,,,0,,,,0.00245,,,,,,19.9981976,,,,
,32360316.24,19.9986343,-57788.078125,0.000160847796733479,7.99077008433153E-7,1,0.999253354069792,40.0298881530762,1.98404976416271,21.339999511838,0.00180057215565607,0.000349531024183659,0.25,2.15576420864525E-6,0.000160779569406457,3.35178003256046E-6,19.9986343,19.9986343,-57800.421875,-57775.734375,57.5341120435445,20.5428322664674,13.797379,0,0,0,40,4449,19.99425,-57788.078125,,,,,,,,,,,,,0,,,,-0.0049,,,,,,19.9986343,,,,
,32360410.42,19.9986,-53083.384765625,0.000144125285352922,8.64872111131588E-7,1,0.999253354069792,40.0298881530762,1.98399635394994,21.339999511838,0.00161605478053771,0.000293845594728904,0.25,2.23788662360595E-7,0.000144010832739184,1.29188307717291E-6,19.9986,19.9986,-53088.36328125,-53078.40625,57.4293738219676,20.5437981387751,13.797379,0,0,0,40,4449,19.995,-53083.384765625,,,,,,,,,,,,,0,,,,0.0049,,,,,,19.9986,,,,
,32360504.26,19.9994392,-48393.888671875,0.000124923165288648,8.90056694227482E-7,1,0.999253354069792,40.0298881530762,1.98397535221942,21.339999511838,0.00139886125704851,0.000261268417312593,0.25,7.98131840688195E-7,0.000124760523282438,1.71573151126521E-6,19.9994392,19.9994392,-48396.4921875,-48391.28515625,56.9142806277945,20.5424445503177,13.417728,0,0,0,40,4449,19.99545,-48393.888671875,,,,,,,,,,,,,0,,,,0,,,,,,19.9994392,,,,
,32360595.985,19.9996738,-43808.564453125,0.00010936872181497,6.86528727424062E-7,1,0.999253354069792,40.0298881530762,1.98414105337002,21.339999511838,0.0012253299299188,0.000222386712465185,0.25,1.49621712175087E-7,0.000109178551744366,9.43718522327098E-7,19.9996738,19.9996738,-43813.8515625,-43803.27734375,57.5513078709676,20.5439122472215,13.797379,0,0,0,40,4449,19.99605,-43808.564453125,,,,,,,,,,,,,0,,,,0.00245,,,,,,19.9996738,,,,
,32360691.405,19.9992905,-39041.28515625,9.22456385437247E-5,5.92719406458857E-7,1,0.999253354069792,40.0298881530762,1.98403333445421,21.339999511838,0.00103284479685035,0.000187858036846089,0.25,1.73032833398438E-7,9.20386884780552E-5,8.30564937439222E-7,19.9992905,19.9992905,-39046.25,-39036.3203125,57.2339666921599,20.5420762729973,13.417728,0,0,0,40,4449,19.99655,-39041.28515625,,,,,,,,,,,,,0,,,,0,,,,,,19.9992905,,,,
,32360784.57,19.99891375,-34384.140625,7.44803921091828E-5,7.21928574205603E-7,1,0.999253354069792,40.0298881530762,1.98400186279278,21.339999511838,0.000831840457411372,0.000160875154408386,0.25,9.80203483614405E-7,7.42707426371052E-5,1.49636680086633E-6,19.9988537,19.9989738,-34389.0625,-34379.21875,57.0002597649099,20.5399941138391,13.797379,0,0,0,40,4449,19.998,-34384.140625,,,,,,,,,,,,,0,,,,0.00245,,,,,,19.99891375,,,,
,32360876.945,19.9991322,-29766.888671875,5.85883027153911E-5,6.15144850696779E-7,1,0.999253354069792,40.0298881530762,1.9840194696967,21.339999511838,0.000655459758349961,0.00011855697671112,0.25,7.40159092586382E-8,5.8399755651281E-5,4.70006304994887E-7,19.9991322,19.9991322,-29776.994140625,-29756.783203125,57.3301070000253,20.5387117425338,13.797379,0,0,0,40,4449,19.9992,-29766.888671875,,,,,,,,,,,,,0,,,,0.00245,,,,,,19.9991322,,,,
,32360973.52,19.9984322,-24939.5048828125,4.20177948911239E-5,4.61424592497452E-7,1,0.999253354069792,40.0298881530762,1.98396304580797,21.339999511838,0.000469561438381209,8.64647598015516E-5,0.25,1.96290853781027E-7,4.1860685437991E-5,4.69112781874033E-7,19.9984322,19.9984322,-24944.548828125,-24934.4609375,57.5341120435445,20.5401420808112,14.177031,0,0,0,40,4449,20.001,-24939.5048828125,,,,,,,,,,,,,0,,,,-0.0049,,,,,,19.9984322,,,,
,32361068.32,19.9984303,-20201.8896484375,2.52049000362585E-5,5.8064442424961E-7,1,0.999253354069792,40.0298881530762,1.98397048380287,21.339999511838,0.000281280695834112,5.32886642374794E-5,0.25,2.54241576973975E-7,2.5097929080635E-5,4.10079478881077E-7,19.9984303,19.9984303,-20206.763671875,-20197.015625,57.3902923960061,20.5415101082784,13.417728,0,0,0,40,4449,20.0017,-20201.8896484375,,,,,,,,,,,,,0,,,,-0.00245,,,,,,19.9984303,,,,
,32361162.755,19.9982777,-15482.296875,9.37163082516006E-6,4.23862838559511E-7,1,0.999253354069792,40.0298881530762,1.98397263225993,21.339999511838,0.000104970706000631,1.73870766917599E-5,0.25,-1.18866502459645E-7,9.32897530087657E-6,-6.29377648325584E-8,19.9982777,19.9982777,-15484.65625,-15479.9375,57.4129596230638,20.5441578138276,13.797379,0,0,0,40,4449,20.0035,-15482.296875,,,,,,,,,,,,,0,,,,-0.0049,,,,,,19.9982777,,,,
,32361257.42,19.9988689,-10752.1274414062,-6.89167780994452E-6,4.05386314338462E-7,1,0.999253354069792,40.0298881530762,1.98392981196959,21.339999511838,-7.56859629583659E-5,-2.10399842621027E-5,0.25,-6.54270700378311E-7,-6.85331454393096E-6,-6.89362147217596E-7,19.9988689,19.9988689,-10757.1728515625,-10747.08203125,57.5755383550638,20.5393564759697,14.177031,0,0,0,40,4449,20.0045,-10752.1274414062,,,,,,,,,,,,,0,,,,-0.0049,,,,,,19.9988689,,,,
,32361351.86,19.99904915,-6031.1689453125,-2.23691070023021E-5,2.93664420893628E-7,1,0.999253354069792,40.0298881530762,1.98402987773429,21.339999511838,-0.000249247776506324,-4.7734347315114E-5,0.25,-2.92505265764212E-7,-2.22467497191224E-5,-4.07805815051407E-7,19.9988441,19.9992542,-6038.7041015625,-6023.6337890625,57.5341120435445,20.5394354849284,13.417728,0,0,0,40,4449,20.0051,-6031.1689453125,,,,,,,,,,,,,0,,,,-0.00245,,,,,,19.99904915,,,,
,32361445.15,19.9995365,-1367.65313720703,-3.66967547612551E-5,3.86971137305455E-7,1,0.999253354069792,40.0298881530762,1.98397768333615,21.339999511838,-0.000408772096989807,-7.8242421072032E-5,0.25,-4.87620828627832E-7,-3.64854577784003E-5,-6.65111716173786E-7,19.9995365,19.9995365,-1380.29675292969,-1355.00952148438,57.4145228801022,20.5361382372178,13.797379,0,0,0,40,4449,20.00555,-1367.65313720703,,,,,,,,,,,,,0,,,,-0.00245,,,,,,19.9995365,,,,
,32361537.565,19.9980736,3244.81579589844,-4.89699932627917E-5,3.49678890591017E-7,1,0.999253354069792,40.0298881530762,1.98399982100265,21.339999511838,-0.000544971728183026,-0.000107672472114744,0.25,-9.35930543332422E-7,-4.86917102358531E-5,-1.1770458132006E-6,19.9980736,19.9980736,3242.21850585937,3247.4130859375,57.3535558556022,20.5384041352168,13.417728,0,0,0,40,4449,20.0067,3244.81579589844,,,,,,,,,,,,,0,,,,0,,,,,,19.9980736,,,,
,32361631.56,19.9993134,7944.81616210937,-6.21810162585036E-5,4.23243326491705E-7,1,0.999253354069792,40.0298881530762,1.98389013204282,21.339999511838,-0.000693264344794064,-0.000130670511208206,0.25,-6.22706293497503E-7,-6.18505600979241E-5,-9.52987046013488E-7,19.9993134,19.9993134,7937.54541015625,7952.0869140625,56.8853603725829,20.5361405823192,14.177031,0,0,0,40,4449,20.00635,7944.81616210937,,,,,,,,,,,,,0,,,,0.00245,,,,,,19.9993134,,,,
,32361724.955,20.0004063,12616.0791015625,-7.20839337657122E-5,3.87377737302485E-7,1,0.999253354069792,40.0298881530762,1.98399958848273,21.339999511838,-0.000803652739811098,-0.000153613394764288,0.25,-8.82265336836926E-7,-7.17270914974268E-5,-1.28924611440029E-6,20.0004063,20.0004063,12606.0146484375,12626.1435546875,57.7842331696984,20.5386217154199,13.797379,0,0,0,40,4449,20.0065,12616.0791015625,,,,,,,,,,,,,0,,,,-0.00245,,,,,,20.0004063,,,,
,32361821.635,20.0011768,17448.0078125,-7.67746355315495E-5,4.24830952422559E-7,1,0.999253354069792,40.0298881530762,1.98407907112152,21.339999511838,-0.000856747833312684,-0.000161487804936423,0.25,-7.17018278732683E-7,-7.64290621850382E-5,-1.17786713665917E-6,20.0011768,20.0011768,17442.9296875,17453.0859375,57.1135959001984,20.5370945635567,13.417728,0,0,0,40,4449,20.00535,17448.0078125,,,,,,,,,,,,,0,,,,0.0049,,,,,,20.0011768,,,,
,32361914.625,20.000658,22093.2041015625,-7.5065995866151E-5,5.37839676053785E-7,1,0.999253354069792,40.0298881530762,1.98402312120012,21.339999511838,-0.000836645670004994,-0.0001657196471509,0.25,-1.37259879672282E-6,-7.47573886879999E-5,-1.84326791840657E-6,20.000658,20.000658,22085.7109375,22100.697265625,57.2394380917945,20.534861822664,13.417728,0,0,0,40,4449,20.00375,22093.2041015625,,,,,,,,,,,,,0,,,,-0.00245,,,,,,20.000658,,,,
,32362011.025,20.0019588,26914.2158203125,-7.35971659744123E-5,6.48029504573403E-7,1,0.999253354069792,40.0298881530762,1.98398187084408,21.339999511838,-0.000820423267990862,-0.000163864899623059,0.25,-1.44289635286795E-6,-7.33295699150828E-5,-1.92494245399848E-6,20.0019588,20.0019588,26904.162109375,26924.26953125,57.5169162161215,20.5359899996203,14.177031,0,0,0,40,4449,20.0021,26914.2158203125,,,,,,,,,,,,,0,,,,-0.0049,,,,,,20.0019588,,,,
,32362104.915,20.0011902,31606.447265625,-7.80202623287253E-5,6.60303101006532E-7,1,0.999253354069792,40.0298881530762,1.98406479097215,21.339999511838,-0.000870834168768326,-0.000170215563599143,0.25,-1.19118452641396E-6,-7.77767603374004E-5,-1.72190810492588E-6,20.0011902,20.0011902,31596.396484375,31616.498046875,57.4293738219676,20.5364844109848,13.797379,0,0,0,40,4449,20.0014,31606.447265625,,,,,,,,,,,,,0,,,,0.00245,,,,,,20.0011902,,,,
,32362199.71,20.0015488,36344.412109375,-8.7636476535028E-5,6.93791428533573E-7,1,0.999253354069792,40.0298881530762,1.98400748755591,21.339999511838,-0.000978388999757857,-0.000192624742798169,0.25,-1.44100349167515E-6,-8.74058791807031E-5,-2.054401756553E-6,20.0015488,20.0015488,36339.5078125,36349.31640625,57.2558522906984,20.5322921804516,13.797379,0,0,0,40,4449,19.9999,36344.412109375,,,,,,,,,,,,,0,,,,-0.0049,,,,,,20.0015488,,,,
,32362296.77,20.0016384,41197.072265625,-0.000101475037937118,8.96082786053844E-7,1,0.999253354069792,40.0298881530762,1.98393614986645,21.339999511838,-0.00113539660796989,-0.000212207621615117,0.25,-6.76436727526427E-7,-0.000101266952642105,-1.40532144256867E-6,20.0016384,20.0016384,41192.16015625,41201.984375,56.8392442899483,20.5370875571635,13.417728,0,0,0,40,4449,19.99855,41197.072265625,,,,,,,,,,,,,0,,,,-0.00245,,,,,,20.0016384,,,,
,32362392.965,20.0013905,46004.31640625,-0.000118319986712624,1.07560730660825E-6,1,0.999253354069792,40.0298881530762,1.9839761783764,21.339999511838,-0.00132282612088171,-0.000257217268915856,0.25,-1.63693862604553E-6,-0.000118130463504401,-2.49946347794774E-6,20.0013905,20.0013905,45994.45703125,46014.17578125,57.515352959083,20.5354137451824,13.797379,0,0,0,40,4449,19.99745,46004.31640625,,,,,,,,,,,,,0,,,,-0.00245,,,,,,20.0013905,,,,
,32362490.125,20.0006561,50859.720703125,-0.000134446414647093,8.5070988035943E-7,1,0.999253354069792,40.0298881530762,1.98403456735085,21.339999511838,-0.00150760511205939,-0.00027191577938245,0.25,-2.087131786766E-8,-0.000134311169531287,-1.01417698553873E-6,20.0006561,20.0006561,50852.4765625,50866.96484375,57.1995750373137,20.5355577929547,13.797379,0,0,0,40,4449,19.99725,50859.720703125,,,,,,,,,,,,,0,,,,-0.00245,,,,,,20.0006561,,,,
,32362583.85,20.0012074,55544.958984375,-0.000150130260255919,8.97994249767672E-7,1,0.999253354069792,40.0298881530762,1.98398748254556,21.339999511838,-0.00168464994713324,-0.000301379720394122,0.25,1.95598785669303E-7,-0.000150050530087641,-9.20032359599042E-7,20.0012074,20.0012074,55539.93359375,55549.984375,57.3988903097176,20.5351958761995,13.417728,0,0,0,40,4449,19.9963,55544.958984375,,,,,,,,,,,,,0,,,,-0.00245,,,,,,20.0012074,,,,
,32362678.61,20.0014343,60282.427734375,-0.000167625819317668,9.6661781939543E-7,1,0.999253354069792,40.0298881530762,1.98394521645204,21.339999511838,-0.00187979074251841,-0.000347707757632217,0.25,-7.65525133964455E-7,-0.000167605238315562,-2.01316527377859E-6,20.0014343,20.0014343,60278.08984375,60286.765625,57.3488660844868,20.5333995231686,13.797379,0,0,0,40,4449,19.9954,60282.427734375,,,,,,,,,,,,,0,,,,0,,,,,,20.0014343,,,,
,32362773.805,20.0008793,65038.5390625,-0.000185857074278147,9.48902548629535E-7,1,0.999253354069792,40.0298881530762,1.983932924604,21.339999511838,-0.00208474930288811,-0.000387816576813503,0.25,-1.04124837097127E-6,-0.000185913546191673,-2.42253664650273E-6,20.0008793,20.0008793,65030.87109375,65046.20703125,57.1792526958137,20.5360930613562,14.177031,0,0,0,40,4449,19.995,65038.5390625,,,,,,,,,,,,,0,,,,-0.00245,,,,,,20.0008793,,,,
,32362869.535,20.0009384,69823.4453125,-0.000204066481394429,1.10660233535633E-6,1,0.999253354069792,40.0298881530762,1.98406720857208,21.339999511838,-0.00228792422016071,-0.000438106730978818,0.25,-2.22752202856453E-6,-0.000204205362099885,-3.7379590111974E-6,20.0009384,20.0009384,69818.125,69828.765625,56.9564885678329,20.5339621781184,14.177031,0,0,0,40,4449,19.9938,69823.4453125,,,,,,,,,,,,,0,,,,0.00245,,,,,,20.0009384,,,,
,32362965.415,20.0010509,74616.70703125,-0.000221357715975,9.53891803602532E-7,1,0.999253354069792,40.0298881530762,1.9840175964326,21.339999511838,-0.0024863809832655,-0.00045501118631399,0.25,-6.14734258213847E-7,-0.000221609057429235,-2.23946928736314E-6,20.0010509,20.0010509,74611.78125,74621.6328125,57.1425161554099,20.5332581162684,14.177031,0,0,0,40,4449,19.9921,74616.70703125,,,,,,,,,,,,,0,,,,-0.00245,,,,,,20.0010509,,,,
,32363060.255,20.0015221,79356.87890625,-0.000239828820392575,1.12881963966467E-6,1,0.999253354069792,40.0298881530762,1.98406659684127,21.339999511838,-0.00269503710600262,-0.000492464957111022,0.25,-6.2116674753885E-7,-0.000240189842870889,-2.36422552266326E-6,20.0015221,20.0015221,79354.46875,79359.2890625,57.1096877576022,20.5332868831981,13.797379,0,0,0,40,4449,19.9901,79356.87890625,,,,,,,,,,,,,0,,,,0,,,,,,20.0015221,,,,
,32363155.29,20.0017681,84108.0703125,-0.000257346028869271,1.36993661804443E-6,1,0.999253354069792,40.0298881530762,1.98399769233764,21.339999511838,-0.00289528423246649,-0.000514741673112818,0.25,5.42882860693455E-7,-0.000257831590387032,-1.30318509205165E-6,20.0017681,20.0017681,84103.046875,84113.09375,57.159711982833,20.5309184729913,13.797379,0,0,0,40,4449,19.99,84108.0703125,,,,,,,,,,,,,0,,,,-0.0049,,,,,,20.0017681,,,,
,32363243.64,20.0004311,88521.43359375,-0.000274053525514,1.41232315652361E-6,1,0.999253354069792,40.0298881530762,1.98402461390168,21.339999511838,-0.00308278472803411,-0.000556339590095057,0.25,-1.58921666335404E-7,-0.000274648579419689,-2.10147925729501E-6,20.0004311,20.0004311,88516.578125,88526.2890625,57.1026531009291,20.5323072937182,13.797379,0,0,0,40,4449,19.9881,88521.43359375,,,,,,,,,,,,,0,,,,0.0049,,,,,,20.0004311,,,,
,32363348.845,20.0006599,87135.7421875,-0.000268601890020235,1.02726538773033E-6,1,0.999253354069792,40.0298881530762,1.98392909987097,21.339999511838,-0.00301883125657315,-0.000557475085300119,0.25,-1.23928660995749E-6,-0.000269152295924496,-3.15331999361826E-6,20.0006599,20.0006599,87128.15625,87143.328125,57.1284468420637,20.5306254695192,13.797379,0,0,0,40,4449,19.9877,87135.7421875,,,,,,,,,,,,,0,,,,0,,,,,,20.0006599,,,,
,32363439.845,20.0005207,82584.66796875,-0.000250767062989476,1.1020699155522E-6,1,0.999253354069792,40.0298881530762,1.98412130832348,21.339999511838,-0.00281879730125463,-0.000514510541640512,0.25,-6.15313486711227E-7,-0.000251204621747369,-2.42355649584008E-6,20.0005207,20.0005207,82579.59375,82589.7421875,57.2824276603522,20.5340111288932,14.177031,0,0,0,40,4449,19.98675,82584.66796875,,,,,,,,,,,,,0,,,,0,,,,,,20.0005207,,,,
,32363535.815,20.0000896,77788.66015625,-0.000232379522966414,1.06487472894721E-6,1,0.999253354069792,40.0298881530762,1.98403408179343,21.339999511838,-0.00260756405510469,-0.000496044176950428,0.25,-2.28060767625102E-6,-0.000232689317547207,-3.97778172102207E-6,20.0000896,20.0000896,77781.2265625,77796.09375,57.1268835850253,20.5332139840615,13.797379,0,0,0,40,4449,19.98745,77788.66015625,,,,,,,,,,,,,0,,,,0,,,,,,20.0000896,,,,
,32363630.99,19.9986782,73029.8203125,-0.000216171112073038,1.1785794411073E-6,1,0.999253354069792,40.0298881530762,1.98415859964249,21.339999511838,-0.00242657048448823,-0.000452130831599419,0.25,-1.29043187170638E-6,-0.000216383763332507,-2.88222684209623E-6,19.9986782,19.9986782,73022.421875,73037.21875,56.9150622563137,20.532244030132,13.797379,0,0,0,40,4449,19.9882,73029.8203125,,,,,,,,,,,,,0,,,,-0.00245,,,,,,19.9986782,,,,
,32363727.055,19.9982758,68229.35546875,-0.000198514750725,9.52872470260694E-7,1,0.999253354069792,40.0298881530762,1.98406546083894,21.339999511838,-0.00222946876856586,-0.000403414706229584,0.25,-1.41534190069227E-7,-0.000198637800172164,-1.61221602210238E-6,19.9982758,19.9982758,68219.5390625,68239.171875,57.159711982833,20.53173684936,13.797379,0,0,0,40,4449,19.99045,68229.35546875,,,,,,,,,,,,,0,,,,0.00245,,,,,,19.9982758,,,,
,32363822.33,19.9991646,63466.697265625,-0.000179633520494548,1.06971682407865E-6,1,0.999253354069792,40.0298881530762,1.98409690718814,21.339999511838,-0.00201304143680274,-0.000384644117099282,0.25,-1.88107609147377E-6,-0.000179656208836576,-3.21742848401294E-6,19.9991646,19.9991646,63461.29296875,63472.1015625,57.301968373333,20.5333762740631,13.797379,0,0,0,40,4449,19.9914,63466.697265625,,,,,,,,,,,,,0,,,,0.0049,,,,,,19.9991646,,,,
,32363915.37,19.9983139,58815.486328125,-0.000164373124754707,9.59930342956394E-7,1,0.999253354069792,40.0298881530762,1.98399293347031,21.339999511838,-0.00184192490505502,-0.000347453553575033,0.25,-1.33274896952494E-6,-0.00016432593174728,-2.5557687977491E-6,19.9983139,19.9983139,58812.9609375,58818.01171875,56.8587850029291,20.5329072826013,13.797379,0,0,0,40,4449,19.9927,58815.486328125,,,,,,,,,,,,,0,,,,0,,,,,,19.9983139,,,,
,32364011.345,19.9992752,54017.5859375,-0.000146030929390173,8.27418746413394E-7,1,0.999253354069792,40.0298881530762,1.98408365704116,21.339999511838,-0.00163414442802911,-0.000317180300359681,0.25,-1.95597316209252E-6,-0.000145915610203926,-3.03817348098866E-6,19.9992752,19.9992752,54015.0078125,54020.1640625,57.4825245612753,20.53877274025,14.177031,0,0,0,40,4449,19.9943,54017.5859375,,,,,,,,,,,,,0,,,,-0.0049,,,,,,19.9992752,,,,
,32364103.86,19.9989948,49395.361328125,-0.000128137123816664,8.03222818878526E-7,1,0.999253354069792,40.0298881530762,1.98408510339751,21.339999511838,-0.00143333513342609,-0.000277676015924891,0.25,-1.67694453971812E-6,-0.00012797703468112,-2.61920579045361E-6,19.9989948,19.9989948,49387.83203125,49402.890625,56.9783741663714,20.5366763977199,14.177031,0,0,0,40,4449,19.99475,49395.361328125,,,,,,,,,,,,,0,,,,-0.00245,,,,,,19.9989948,,,,
,32364199.66,19.9990215,44607.611328125,-0.00011127732616103,6.61497545139086E-7,1,0.999253354069792,40.0298881530762,1.98408236515489,21.339999511838,-0.00124660969165893,-0.000227237891250282,0.25,-2.35737816800221E-7,-0.000111092493280158,-1.04558974909123E-6,19.9990215,19.9990215,44605.1953125,44610.02734375,57.1042163579676,20.5346988723806,13.417728,0,0,0,40,4449,19.9952,44607.611328125,,,,,,,,,,,,,0,,,,0.00245,,,,,,19.9990215,,,,
,32364296.515,19.9985027,39764.310546875,-9.480170780859E-5,6.90382337973297E-7,1,0.999253354069792,40.0298881530762,1.98410195692595,21.339999511838,-0.00105960222224257,-0.000204078261146399,0.25,-1.15718336018854E-6,-9.45892535362736E-5,-1.83295965427225E-6,19.9985027,19.9985027,39756.5703125,39772.05078125,57.6794949481215,20.5367587557508,14.177031,0,0,0,40,4449,19.9961,39764.310546875,,,,,,,,,,,,,0,,,,-0.0049,,,,,,19.9985027,,,,
,32364393.32,19.99881935,34927.359375,-7.71951768672065E-5,7.67171015172767E-7,1,0.999253354069792,40.0298881530762,1.9839492740569,21.339999511838,-0.00086231828615875,-0.000166022633205829,0.25,-9.49840758426943E-7,-7.69827640777024E-5,-1.48670282284526E-6,19.9987946,19.9988441,34924.859375,34929.859375,57.1729996676599,20.5375301110784,13.417728,0,0,0,40,4449,19.9971,34927.359375,,,,,,,,,,,,,0,,,,-0.0049,,,,,,19.99881935,,,,
,32364488.66,19.9988384,30162.0498046875,-6.0135713337688E-5,4.83239414365871E-7,1,0.999253354069792,40.0298881530762,1.98412902987439,21.339999511838,-0.00067045647827848,-0.00013494371944024,0.25,-1.25828733280312E-6,-5.99366544808965E-5,-1.66212821748188E-6,19.9988384,19.9988384,30157.001953125,30167.09765625,57.3512109700445,20.534626045924,13.417728,0,0,0,40,4449,19.998,30162.0498046875,,,,,,,,,,,,,0,,,,0.00245,,,,,,19.9988384,,,,
,32364581.695,19.9986401,25511.9677734375,-4.33088069075613E-5,5.10903280678667E-7,1,0.999253354069792,40.0298881530762,1.98413557392994,21.339999511838,-0.000482775327719405,-9.62831354687553E-5,0.25,-8.4004525926534E-7,-4.31452206220431E-5,-1.12032068543545E-6,19.9986401,19.9986401,25509.40625,25514.529296875,57.0487207331022,20.5381136407839,13.797379,0,0,0,40,4449,19.99955,25511.9677734375,,,,,,,,,,,,,0,,,,-0.00245,,,,,,19.9986401,,,,
,32364676.11,19.9990234,20791.8818359375,-2.70049650311528E-5,4.48886028582326E-7,1,0.999253354069792,40.0298881530762,1.98410637385884,21.339999511838,-0.000300616605837462,-6.1510548102877E-5,0.25,-6.65726489138529E-7,-2.68894365250051E-5,-8.32097109130583E-7,19.9990234,19.9990234,20777.0546875,20806.708984375,57.7256110307561,20.5379038644932,13.417728,0,0,0,40,4449,19.9998,20791.8818359375,,,,,,,,,,,,,0,,,,-0.00245,,,,,,19.9990234,,,,
,32364768.92,19.9979897,16152.1748046875,-1.14250072045651E-5,3.6815586653765E-7,1,0.999253354069792,40.0298881530762,1.98420482246397,21.339999511838,-0.00012724098289039,-2.54057443108918E-5,0.25,-2.30798189029578E-7,-1.13714749952557E-5,-2.97787765269449E-7,19.9979897,19.9979897,16144.8955078125,16159.4541015625,57.251162519583,20.5360430170351,13.797379,0,0,0,40,4449,20.0023,16152.1748046875,,,,,,,,,,,,,0,,,,-0.0049,,,,,,19.9979897,,,,
,32364864.805,19.9987049,11362.0346679688,4.82577752377617E-6,3.91192971318841E-7,1,0.999253354069792,40.0298881530762,1.98415098243753,21.339999511838,5.48611825061231E-5,4.33525784968256E-6,0.25,-4.72875912468259E-7,4.80436586517791E-6,-4.43422574981708E-7,19.9987049,19.9987049,11357.291015625,11366.7783203125,57.1198489283522,20.535857140554,14.556682,0,0,0,40,4449,20.0041,11362.0346679688,,,,,,,,,,,,,0,,,,-0.0049,,,,,,19.9987049,,,,
,32364957.72,19.9979496,6719.16040039063,2.017331735781E-5,3.86874721983546E-7,1,0.999253354069792,40.0298881530762,1.98413294153384,21.339999511838,0.000226161317724748,3.54262949419458E-5,0.25,-4.20019862485411E-7,2.00675637887104E-5,-3.11360548827802E-7,19.9979496,19.9979496,6714.0634765625,6724.25732421875,57.2034831799099,20.535329959794,13.797379,0,0,0,40,4449,20.006,6719.16040039063,,,,,,,,,,,,,0,,,,-0.0049,,,,,,19.9979496,,,,
,32365050.695,19.9991055,2071.10986328125,3.52016161640868E-5,3.71759895633356E-7,1,0.999253354069792,40.0298881530762,1.98414012829983,21.339999511838,0.000394005727910574,6.46927248500486E-5,0.25,-4.62432985341792E-7,3.50048344526691E-5,-2.85407402270926E-7,19.9991055,19.9991055,2071.10986328125,2071.10986328125,57.2261504069676,20.5369633978968,13.417728,0,0,0,40,4449,20.0062,2071.10986328125,,,,,,,,,,,,,0,,,,0.00245,,,,,,19.9991055,,,,
,32365091.65,20.0000916,-0.548055797815323,4.16009119372968E-5,3.84440317294056E-7,1,0.999253354069792,40.0298881530762,1.98413555509796,21.339999511838,0.000465697962018819,7.5812658488815E-5,0.25,-5.98659103752565E-7,4.13646000771514E-5,-3.93616680645844E-7,20.0000916,20.0000916,-0.563279569149017,-0.532832026481628,57.034651419756,20.5366893801998,13.417728,0,0,0,40,4417,20.0053,-0.548055797815323,,,,,,,,,,,,,0,,,,0.00245,,,,,,20.0000916,,,,