File: data/monolayers/magneticStructure/ML_Ac_CoFe_C/PPMS/data/DD205_4_HYST_100OE_200K.DAT
[Header]
; VSM Data File (default extension .dat)
; Copyright (c) 2003-2013, Quantum Design, Inc. All rights reserved.
TITLE,
FILEOPENTIME,32402822.41,01/11/2019,8:49 am
BYAPP,VSM,2.0,2.0
INFO,PPMS VSM Option Release 1.4.10 Build 1,APPNAME
INFO,Quantum Design Linear Motor Servo Controller,MOTOR_MODULE_NAME
INFO,3101-100 M1,MOTOR_HW_VERSION
INFO,MMC1014,MOTOR_SERIAL_NUMBER
INFO,SRV No X-over 01.03.11,MOTOR_SOFTWARE_VERSION
INFO,Quantum Design VSM Detection Module,VSM_MODULE_NAME
INFO,3101-150 F0,VSM_HW_VERSION
INFO,VSM707,VSM_SERIAL_NUMBER
INFO,VSM No X-over 01.02.05 May 20 2008 13:51:47,VSM_SOFTWARE_VERSION
INFO,704,PREAMP_SERIAL_NUMBER
INFO,822,COIL_SERIAL_NUMBER
INFO,0,MOMENT_UNITS
INFO,DD205_4,SAMPLE_MATERIAL
INFO,Monolayer,SAMPLE_COMMENT
INFO,29.55,SAMPLE_MASS
INFO,,SAMPLE_VOLUME
INFO,,SAMPLE_MOLECULAR_WEIGHT
INFO,,SAMPLE_SIZE
INFO,,SAMPLE_SHAPE
DATATYPE,COMMENT,1
DATATYPE,TIME,2
STARTUPAXIS,X,2
STARTUPAXIS,Y1,5
[Data]
Comment,Time Stamp (sec),Temperature (K),Magnetic Field (Oe),Moment (emu),M. Std. Err. (emu),Transport Action,Averaging Time (sec),Frequency (Hz),Peak Amplitude (mm),Center Position (mm),Coil Signal' (mV),Coil Signal" (mV),Range (mV),M. Quad. Signal (emu),M. Raw' (emu),M. Raw" (emu),Min. Temperature (K),Max. Temperature (K),Min. Field (Oe),Max. Field (Oe),Mass (grams),Motor Lag (deg),Pressure (Torr),VSM Status (code),Motor Status (code),Measure Status (code),Measure Count,PPMS Status (code),System Temp. (K),System Field (Oe),Sample Position (deg),Bridge 1 Resistance (ohms),Bridge 1 Excitation (에),Bridge 2 Resistance (ohms),Bridge 2 Excitation (에),Bridge 3 Resistance (ohms),Bridge 3 Excitation (에),Bridge 4 Resistance (ohms),Bridge 4 Excitation (에),Signal 1 Vin (V),Signal 2 Vin (V),Digital Inputs (code),Drive 1 Iout (mA),Drive 1 Ipower (W),Drive 2 Iout (mA),Drive 2 Ipower (W),Pressure (),Map 20 (),Map 21 (),Map 22 (),Map 23 (),Map 24 (),Map 25 (),Map 26 (),Map 27 (),Map 28 (),Map 29 ()
,32402838.23,199.9941254,-0.258804142475128,,,2,,,,20.4500002563,,,,,,,199.9941254,199.9941254,-0.258804142475128,-0.258804142475128,,,26.705515,,,,-99999999,4369,199.9328,-0.258804142475128,,,,,,,,,,,,,,,,,,,,,,,199.9941254,,,,
,32402997.67,199.9852142,4698.33471679687,1.80475518792859E-5,4.00185426307632E-7,1,0.999253354069792,40.0298881530762,1.99542824704021,20.4399991780519,0.000206025201689627,2.74566883945679E-5,0.25,-7.13018488335028E-7,1.81106285393581E-5,-6.95890617780833E-7,199.9852142,199.9852142,4695.646484375,4701.02294921875,56.1029502248329,20.4988335325338,26.325863,0,0,0,40,4449,199.95325,4698.33471679687,,,,,,,,,,,,,0,,,,0,,,,,,199.9852142,,,,
,32403093.615,199.9848633,9489.79638671875,7.98342309303598E-6,4.52464932560126E-7,1,0.999253354069792,40.0298881530762,1.99594170958875,20.4399991780519,9.43643774429821E-5,-6.30804764077266E-6,0.25,-1.94286672388703E-6,8.01309073170001E-6,-1.94092153744717E-6,199.9846802,199.9850464,9482.26171875,9497.3310546875,56.4765686570252,20.4957013686381,26.705515,0,0,0,40,4449,199.96645,9489.79638671875,,,,,,,,,,,,,0,,,,0,,,,,,199.9848633,,,,
,32403189.75,199.9871216,14294.9443359375,-6.27768185872521E-6,8.07049578344792E-7,1,0.999253354069792,40.0298881530762,1.99615654366965,20.4399991780519,-6.58859461183725E-5,-4.29650102507531E-5,0.25,-2.69783044593991E-6,-6.29643669031586E-6,-2.71393796380196E-6,199.9871216,199.9871216,14290.0546875,14299.833984375,56.5156500829868,20.5016429232577,26.325863,0,0,0,40,4449,199.9767,14294.9443359375,,,,,,,,,,,,,0,,,,-0.0049,,,,,,199.9871216,,,,
,32403284.37,199.9933319,19024.712890625,-2.19802656176595E-5,1.22851857151891E-6,1,0.999253354069792,40.0298881530762,1.99612709435322,20.4399991780519,-0.000244589787024654,-7.03796423897764E-5,0.25,-2.38773570966319E-6,-2.20535755343296E-5,-2.41972634530863E-6,199.992569,199.9940948,19012.189453125,19037.236328125,56.7978179784291,20.501727022892,26.325863,0,0,0,40,4449,199.97385,19024.712890625,,,,,,,,,,,,,0,,,,0.0049,,,,,,199.9933319,,,,
,32403380.38,199.9966736,23822.248046875,-3.74105492140021E-5,1.25381496275255E-6,1,0.999253354069792,40.0298881530762,1.99610921840896,20.4399991780519,-0.000422108588083541,-8.62842118747402E-5,0.25,-1.11016143524585E-6,-3.75385227772177E-5,-1.15434027400787E-6,199.9966736,199.9966736,23814.744140625,23829.751953125,56.4968909985252,20.502240359819,26.325863,0,0,0,40,4449,199.98025,23822.248046875,,,,,,,,,,,,,0,,,,0.00245,,,,,,199.9966736,,,,
,32403475.11,200.0004883,28557.6865234375,-5.52618388949783E-5,9.90163229282325E-7,1,0.999253354069792,40.0298881530762,1.99592567155318,20.4399991780519,-0.000626116889027391,-0.000112220909324099,0.25,-2.97519575104977E-7,-5.54523347212625E-5,-3.58038912684603E-7,200.0004883,200.0004883,28552.6640625,28562.708984375,57.1386080128137,20.5038507198883,26.325863,0,0,0,40,4449,199.9804,28557.6865234375,,,,,,,,,,,,,0,,,,0,,,,,,200.0004883,,,,
,32403572.735,200.0050964,33437.904296875,-7.27673366415239E-5,1.35710866334047E-6,1,0.999253354069792,40.0298881530762,1.99606524126197,20.4399991780519,-0.000821358547264975,-0.00016592121653301,0.25,-1.991521993363E-6,-7.30164684294212E-5,-2.07659148230227E-6,200.0050964,200.0050964,33430.64453125,33445.1640625,57.0792042453522,20.5022155452077,25.946213,0,0,0,40,4449,199.9751,33437.904296875,,,,,,,,,,,,,0,,,,0,,,,,,200.0050964,,,,
,32403670.815,200.0043945,38339.779296875,-8.69636463881032E-5,1.94103732756802E-6,1,0.999253354069792,40.0298881530762,1.99607258143971,20.4399991780519,-0.000976554219228415,-0.000227359806187692,0.25,-4.94322154013037E-6,-8.72586659829384E-5,-5.05356022633557E-6,200.0043945,200.0043945,38337.55078125,38342.0078125,56.7923465787945,20.5013330561002,25.946213,0,0,0,40,4449,199.9716,38339.779296875,,,,,,,,,,,,,0,,,,0,,,,,,200.0043945,,,,
,32403768.71,200.0050507,43232.689453125,-0.000106193817924791,1.79540918722321E-6,1,0.999253354069792,40.0298881530762,1.99601628953142,20.4399991780519,-0.00120008109989621,-0.000233786804696469,0.25,-2.17082746275979E-6,-0.000106558255595368,-2.29199240622308E-6,200.0050507,200.0050507,43229.9921875,43235.38671875,56.9854088230445,20.5005289020422,26.705515,0,0,0,40,4449,199.96885,43232.689453125,,,,,,,,,,,,,0,,,,-0.0049,,,,,,200.0050507,,,,
,32403866.405,200.0084534,48115.82421875,-0.000121996038848554,1.91620362057402E-6,1,0.999253354069792,40.0298881530762,1.9959710799854,20.4399991780519,-0.00137526403385007,-0.000287952280275377,0.25,-4.20319374405437E-6,-0.000122412909757242,-4.34803604655247E-6,200.0084534,200.0084534,48108.3125,48123.3359375,56.9650864815445,20.5045031423813,25.946213,0,0,0,40,4449,199.9597,48115.82421875,,,,,,,,,,,,,0,,,,0.0049,,,,,,200.0084534,,,,
,32403962.095,200.0126953,52895.6875,-0.000142309524734559,2.33098030152821E-6,1,0.999253354069792,40.0298881530762,1.99617262989466,20.4399991780519,-0.00160807699647357,-0.000314836476444033,0.25,-3.04345702296581E-6,-0.000142797824910801,-3.20569616708271E-6,200.0126953,200.0126953,52890.8203125,52900.5546875,57.0190188493714,20.5018812427099,26.705515,0,0,0,40,4449,199.9507,52895.6875,,,,,,,,,,,,,0,,,,0.00245,,,,,,200.0126953,,,,
,32404058.475,200.0114441,57713.24609375,-0.000157297039233676,1.97043014753352E-6,1,0.999253354069792,40.0298881530762,1.99609390727965,20.4399991780519,-0.00177752790542556,-0.00034705747064123,0.25,-3.28289339500455E-6,-0.000157836913858697,-3.46160572088956E-6,200.0114136,200.0114746,57708.2109375,57718.28125,57.1018714724099,20.5026184091512,26.325863,0,0,0,40,4449,199.9387,57713.24609375,,,,,,,,,,,,,0,,,,0.00245,,,,,,200.0114441,,,,
,32404154.79,200.0098114,62531.69921875,-0.000176225076623744,2.41633544819481E-6,1,0.999253354069792,40.0298881530762,1.99594271404019,20.4399991780519,-0.00198857680251797,-0.000404358384756395,0.25,-5.05092200923009E-6,-0.000176828531281362,-5.25549991305628E-6,200.0098114,200.0098114,62526.82421875,62536.57421875,57.1831608384099,20.5029900491301,26.705515,0,0,0,40,4449,199.93065,62531.69921875,,,,,,,,,,,,,0,,,,0.0049,,,,,,200.0098114,,,,
,32404253.23,200.0101013,67449.15234375,-0.000191989675626274,2.5166436682302E-6,1,0.999253354069792,40.0298881530762,1.99604660095435,20.4399991780519,-0.0021729096255694,-0.000404092630915414,0.25,-2.28834994216885E-6,-0.000192650592435711,-2.49969395998172E-6,200.0101013,200.0101013,67439.203125,67459.1015625,57.1878506095253,20.5028558399968,26.325863,0,0,0,40,4449,199.92105,67449.15234375,,,,,,,,,,,,,0,,,,-0.00245,,,,,,200.0101013,,,,
,32404351.62,200.0118866,72369.515625,-0.000212497174585862,2.3413789214895E-6,1,0.999253354069792,40.0298881530762,1.9958314652655,20.4399991780519,-0.00240357392371466,-0.00045406100346874,0.25,-3.13739647410946E-6,-0.00021322811308031,-3.37291037055321E-6,200.0118866,200.0118866,72361.9140625,72377.1171875,57.1745629246983,20.502324596002,26.705515,0,0,0,40,4449,199.9209,72369.515625,,,,,,,,,,,,,0,,,,0,,,,,,200.0118866,,,,
,32404448.385,200.0107269,77202.60546875,-0.000229957582517883,2.13916010217883E-6,1,0.999253354069792,40.0298881530762,1.99578437722583,20.4399991780519,-0.0026050459454847,-0.000468133365869325,0.25,-1.34754138971456E-6,-0.00023075083073956,-1.59482209340839E-6,200.0107269,200.0107269,77194.9609375,77210.25,57.2902439455445,20.5038001602335,25.946213,0,0,0,40,4449,199.90655,77202.60546875,,,,,,,,,,,,,0,,,,0,,,,,,200.0107269,,,,
,32404545.675,200.0117493,82068.55859375,-0.000244320212345981,2.35436913867765E-6,1,0.999253354069792,40.0298881530762,1.99604356670255,20.4399991780519,-0.00276230518433132,-0.000530774976407206,0.25,-4.37206395225831E-6,-0.000245159984656133,-4.64439307905392E-6,200.0117493,200.0117493,82063.4453125,82073.671875,57.0096393071407,20.5019878777288,25.946213,0,0,0,40,4449,199.89735,82068.55859375,,,,,,,,,,,,,0,,,,0,,,,,,200.0117493,,,,
,32404642.195,200.0136414,86891.67578125,-0.000261199746462579,2.6275426600321E-6,1,0.999253354069792,40.0298881530762,1.99588081392817,20.4399991780519,-0.00295389126294479,-0.000561794653961684,0.25,-4.18033843204842E-6,-0.000262098134222683,-4.4691866428099E-6,200.0136414,200.0136414,86881.6953125,86901.65625,57.1276652135445,20.5012961572594,26.705515,0,0,0,40,4449,199.88435,86891.67578125,,,,,,,,,,,,,0,,,,0,,,,,,200.0136414,,,,
,32404753.035,200.0107269,88520.578125,-0.000264021513468402,3.55181679422679E-6,1,0.999253354069792,40.0298881530762,1.99590375718854,20.4399991780519,-0.00298235643710489,-0.00058790652130665,0.25,-5.99248116957608E-6,-0.000264927808268817,-6.29036242723606E-6,200.0107269,200.0107269,88513.125,88528.03125,57.393418910083,20.500507347693,26.705515,0,0,0,40,4449,199.876,88520.578125,,,,,,,,,,,,,0,,,,0,,,,,,200.0107269,,,,
,32404844.755,200.0031586,83936.66796875,-0.000251118423823976,2.94177683987722E-6,1,0.999253354069792,40.0298881530762,1.99591367908526,20.4399991780519,-0.00283374840591629,-0.000575700429010915,0.25,-7.15604172443217E-6,-0.000251978863999298,-7.44496247030783E-6,200.0031586,200.0031586,83933.953125,83939.3828125,57.0760777312753,20.5036433348047,26.705515,0,0,0,40,4449,199.8739,83936.66796875,,,,,,,,,,,,,0,,,,0,,,,,,200.0031586,,,,
,32404941.77,199.9996796,79085.78125,-0.000232207379238066,2.74074904124914E-6,1,0.999253354069792,40.0298881530762,1.996005329412,20.4399991780519,-0.00262496298167021,-0.000506442817090705,0.25,-4.33054966724744E-6,-0.000233005366460125,-4.59035029862633E-6,199.9996796,199.9996796,79080.6875,79090.875,57.3293253715061,20.5052954280175,26.705515,0,0,0,40,4449,199.8756,79085.78125,,,,,,,,,,,,,0,,,,-0.0049,,,,,,199.9996796,,,,
,32405040.39,199.9949799,74154.6953125,-0.000217642159353799,2.36315973958802E-6,1,0.999253354069792,40.0298881530762,1.9959149177471,20.4399991780519,-0.00245267401138242,-0.000518022327488987,0.25,-7.88243854848544E-6,-0.000218386005259248,-8.13965646055E-6,199.9949799,199.9949799,74147.265625,74162.125,57.1534589546791,20.5055262345873,26.705515,0,0,0,40,4449,199.8863,74154.6953125,,,,,,,,,,,,,0,,,,-0.00245,,,,,,199.9949799,,,,
,32405138.045,199.9930878,69271.4765625,-0.000201383133337202,2.19039570418269E-6,1,0.999253354069792,40.0298881530762,1.99573873388471,20.4399991780519,-0.00226918290391263,-0.000479693517272891,0.25,-7.32934612675187E-6,-0.000202071302396398,-7.56792679427795E-6,199.9930878,199.9930878,69269.1484375,69273.8046875,57.2081729510253,20.5046245199366,25.946213,0,0,0,40,4449,199.89465,69271.4765625,,,,,,,,,,,,,0,,,,-0.0049,,,,,,199.9930878,,,,
,32405235.12,199.9885254,64421.041015625,-0.000179108906036095,2.78202896106415E-6,1,0.999253354069792,40.0298881530762,1.9958981368879,20.4399991780519,-0.00201558771631118,-0.000442577491551133,0.25,-7.92108601625691E-6,-0.000179719425073195,-8.13852729874409E-6,199.9885254,199.9885254,64411.15234375,64430.9296875,56.9830639374868,20.5060845466757,26.325863,0,0,0,40,4449,199.8988,64421.041015625,,,,,,,,,,,,,0,,,,-0.00245,,,,,,199.9885254,,,,
,32405331.965,199.9891357,59579.861328125,-0.000162922134204573,2.20036277033897E-6,1,0.999253354069792,40.0298881530762,1.99595270303433,20.4399991780519,-0.00183638038462207,-0.000385879461965454,0.25,-5.73135063953902E-6,-0.000163478974875844,-5.92440240728627E-6,199.9891357,199.9891357,59572.37109375,59587.3515625,56.8947399148137,20.5043332490282,26.705515,0,0,0,40,4449,199.9089,59579.861328125,,,,,,,,,,,,,0,,,,0.00245,,,,,,199.9891357,,,,
,32405428.19,199.9919739,54772.4140625,-0.000145665932153858,2.34301894214264E-6,1,0.999253354069792,40.0298881530762,1.99605205118267,20.4399991780519,-0.00163900955434388,-0.000361978401777895,0.25,-6.61886062180102E-6,-0.000146162130640495,-6.79694329168507E-6,199.9919739,199.9919739,54764.97265625,54779.85546875,57.2722664896022,20.5061364587895,26.705515,0,0,0,40,4449,199.91425,54772.4140625,,,,,,,,,,,,,0,,,,0,,,,,,199.9919739,,,,
,32405523.93,199.9883423,49984.9765625,-0.000128465882167748,1.62198486369517E-6,1,0.999253354069792,40.0298881530762,1.9960329968574,20.4399991780519,-0.00144551035853902,-0.000318965353791988,0.25,-5.81340536635107E-6,-0.000128903479674144,-5.97064633777889E-6,199.9883423,199.9883423,49977.359375,49992.59375,56.9854088230445,20.5085714297087,26.705515,0,0,0,40,4449,199.92535,49984.9765625,,,,,,,,,,,,,0,,,,-0.00245,,,,,,199.9883423,,,,
,32405622.09,199.9882965,45079.943359375,-0.00011061811818333,1.71215369435867E-6,1,0.999253354069792,40.0298881530762,1.99579596829693,20.4399991780519,-0.00124374967779193,-0.000279194098274581,0.25,-5.4088530415188E-6,-0.000110994444274626,-5.54587479978627E-6,199.9882965,199.9882965,45069.953125,45089.93359375,57.0713879601599,20.5080310590374,26.325863,0,0,0,40,4449,199.93505,45079.943359375,,,,,,,,,,,,,0,,,,-0.00245,,,,,,199.9882965,,,,
,32405719.065,199.98909,40231.91015625,-9.30919164839993E-5,1.79347536000583E-6,1,0.999253354069792,40.0298881530762,1.99596602812571,20.4399991780519,-0.00104729909328047,-0.000231966950563873,0.25,-4.28618973336807E-6,-9.34088627127568E-5,-4.40077543645578E-6,199.98909,199.98909,40221.7109375,40242.109375,56.6876083572175,20.5092046524365,26.325863,0,0,0,40,4449,199.9438,40231.91015625,,,,,,,,,,,,,0,,,,0,,,,,,199.98909,,,,
,32405815.565,199.9906006,35409.62890625,-7.82188343773943E-5,1.72018398660437E-6,1,0.999253354069792,40.0298881530762,1.99604514084709,20.4399991780519,-0.000873872770321903,-0.000230235203857551,0.25,-6.71568412606873E-6,-7.84817639953853E-5,-6.82287598888364E-6,199.9906006,199.9906006,35374.64453125,35444.61328125,57.2339666921599,20.5088684880641,26.705515,0,0,0,40,4449,199.9504,35409.62890625,,,,,,,,,,,,,0,,,,0.00245,,,,,,199.9906006,,,,
,32405913.915,199.9896545,30494.4560546875,-6.08969782022201E-5,1.33957117448703E-6,1,0.999253354069792,40.0298881530762,1.99598859951929,20.4399991780519,-0.000683982814519219,-0.000158221642700236,0.25,-3.37469671173946E-6,-6.11036491442105E-5,-3.45186902410093E-6,199.9896545,199.9896545,30492.056640625,30496.85546875,57.1948852661984,20.5105753269085,26.325863,0,0,0,40,4449,199.9603,30494.4560546875,,,,,,,,,,,,,0,,,,0.0049,,,,,,199.9896545,,,,
,32406009.25,199.990509,25726.525390625,-4.42246538498858E-5,1.21299601054357E-6,1,0.999253354069792,40.0298881530762,1.99589515644355,20.4399991780519,-0.000496748978702889,-0.000114617627130108,0.25,-2.42590866160789E-6,-4.4374751163442E-5,-2.48195015211697E-6,199.990509,199.990509,25719.08203125,25733.96875,57.4325003360445,20.5102123216948,25.946213,0,0,0,40,4449,199.96745,25726.525390625,,,,,,,,,,,,,0,,,,-0.0049,,,,,,199.990509,,,,
,32406106.695,199.990921,20859.291015625,-2.68520427389644E-5,1.40195533283543E-6,1,0.999253354069792,40.0298881530762,1.99578610964074,20.4399991780519,-0.000300560850123255,-7.55549642117007E-5,0.25,-1.99899077977208E-6,-2.69425992895083E-5,-2.03488438236345E-6,199.990921,199.990921,20851.625,20866.95703125,57.5176978446407,20.5087982769331,26.325863,0,0,0,40,4449,199.9717,20859.291015625,,,,,,,,,,,,,0,,,,0.0049,,,,,,199.990921,,,,
,32406204.165,199.9902649,15987.21484375,-1.17033830076806E-5,8.97211371917874E-7,1,0.999253354069792,40.0298881530762,1.99594792840615,20.4399991780519,-0.000129438786021704,-4.19713778278477E-5,0.25,-1.66822318851472E-6,-1.17419855770689E-5,-1.686639458455E-6,199.9902649,199.9902649,15979.8046875,15994.625,57.2628869473714,20.5108239232,26.325863,0,0,0,40,4449,199.98135,15987.21484375,,,,,,,,,,,,,0,,,,0,,,,,,199.9902649,,,,
,32406300.835,199.9927673,11154.8520507813,3.21571707059441E-6,5.56350367532446E-7,1,0.999253354069792,40.0298881530762,1.99571804942883,20.4399991780519,3.83435608376043E-5,-4.4850941535527E-6,0.25,-9.5406282163534E-7,3.22785184872082E-6,-9.53873420051166E-7,199.9927673,199.9927673,11152.3916015625,11157.3125,56.9236601700253,20.5123464665998,25.946213,0,0,0,40,4449,199.9871,11154.8520507813,,,,,,,,,,,,,0,,,,0,,,,,,199.9927673,,,,
,32406397.38,199.99329375,6329.16870117187,1.5910558321939E-5,3.99783122744838E-7,1,0.999253354069792,40.0298881530762,1.99578059379909,20.4399991780519,0.000182088714378935,2.17444272293724E-5,0.25,-8.45973769316233E-7,1.59663989656945E-5,-8.3163628503501E-7,199.9931946,199.9933929,6319.07275390625,6339.2646484375,57.3621537693137,20.5122428914862,26.705515,0,0,0,40,4449,199.9923,6329.16870117187,,,,,,,,,,,,,0,,,,0,,,,,,199.99329375,,,,
,32406489.575,199.9953613,1723.63305664062,2.23323726752651E-5,3.32894445621265E-7,1,0.999253354069792,40.0298881530762,1.9959072838554,20.4399991780519,0.000254316082800096,3.79074438265661E-5,0.25,-5.36272900961592E-7,2.24100404505895E-5,-5.13872922066216E-7,199.9953613,199.9953613,1721.16369628906,1726.10241699219,57.4403166212368,20.5148538992205,26.705515,0,0,0,40,4449,199.9985,1723.63305664062,,,,,,,,,,,,,0,,,,0.0049,,,,,,199.9953613,,,,
,32406586.93,199.9971771,-3139.37316894531,5.99321727016818E-8,3.79072339414138E-7,1,0.999253354069792,40.0298881530762,1.99580245306889,20.4399991780519,1.06381509375549E-6,-2.09386995771707E-6,0.25,-1.95055773351909E-7,6.03507867100289E-8,-1.95663992815526E-7,199.9971771,199.9971771,-3141.60083007812,-3137.1455078125,57.5481813568907,20.5145549300335,26.705515,0,0,0,40,4449,199.998,-3139.37316894531,,,,,,,,,,,,,0,,,,0,,,,,,199.9971771,,,,
,32406684.835,199.9992676,-8034.07958984375,-8.59752165487388E-6,4.3891315188474E-7,1,0.999253354069792,40.0298881530762,1.99580620996615,20.4399991780519,-9.84695880800965E-5,-1.13247190258985E-5,0.25,4.94640926192278E-7,-8.62773546209563E-6,4.87027866583388E-7,199.9992676,199.9992676,-8041.5615234375,-8026.59765625,56.902556200006,20.5152435477319,26.325863,0,0,0,40,4449,199.99905,-8034.07958984375,,,,,,,,,,,,,0,,,,0.00245,,,,,,199.9992676,,,,
,32406780.9,200.0050354,-12837.2397460938,2.89507964838771E-6,6.87354656765793E-7,1,0.999253354069792,40.0298881530762,1.99587735249943,20.4399991780519,3.12446056439041E-5,1.48367704485087E-5,0.25,8.0547964295853E-7,2.90420129182986E-6,8.11394029707354E-7,200.0050354,200.0050354,-12844.8681640625,-12829.611328125,56.9478906541214,20.5133484815576,26.705515,0,0,0,40,4449,199.9933,-12837.2397460938,,,,,,,,,,,,,0,,,,0.0049,,,,,,200.0050354,,,,
,32406878.72,200.0075378,-17725.24609375,1.83732801592002E-5,1.02485289661821E-6,1,0.999253354069792,40.0298881530762,1.99579783997008,20.4399991780519,0.000206295168699661,4.80248457683345E-5,0.25,1.04385041805758E-6,1.84355782584002E-5,1.0673110714783E-6,200.0075378,200.0075378,-17732.958984375,-17717.533203125,57.4285921934484,20.516036862743,27.085165,0,0,0,40,4449,199.9872,-17725.24609375,,,,,,,,,,,,,0,,,,-0.00245,,,,,,200.0075378,,,,
,32406976.01,200.0092087,-22589.7080078125,3.43422045723782E-5,9.25018470566151E-7,1,0.999253354069792,40.0298881530762,1.99581758018556,20.4399991780519,0.000386957688570994,8.1937432049235E-5,0.25,1.26081838547662E-6,3.44594041272846E-5,1.30222360292559E-6,200.008606,200.0098114,-22594.57421875,-22584.841796875,56.7634263235829,20.515002652504,27.085165,0,0,0,40,4449,199.9837,-22589.7080078125,,,,,,,,,,,,,0,,,,0,,,,,,200.0092087,,,,
,32407072.92,200.0102386,-27432.6572265625,4.95360838524621E-5,1.32826577429341E-6,1,0.999253354069792,40.0298881530762,1.99580838178978,20.4399991780519,0.000558083712739969,0.000118601471655655,0.25,1.85517534054381E-6,4.97051116582824E-5,1.91493233951035E-6,200.0102386,200.0102386,-27437.44140625,-27427.873046875,57.6841847192369,20.5171678158506,26.705515,0,0,0,40,4449,199.9767,-27432.6572265625,,,,,,,,,,,,,0,,,,-0.00245,,,,,,200.0102386,,,,
,32407172.82,200.0106201,-32424.203125,6.79007530788115E-5,1.56979882257001E-6,1,0.999253354069792,40.0298881530762,1.99578166940653,20.4399991780519,0.000763378834103664,0.000171755459143742,0.25,3.35319456124376E-6,6.81315979537131E-5,3.43776928658491E-6,200.0106201,200.0106201,-32429.5390625,-32418.8671875,56.8400259184676,20.5168957215752,26.325863,0,0,0,40,4449,199.9648,-32424.203125,,,,,,,,,,,,,0,,,,-0.0049,,,,,,200.0106201,,,,
,32407270.68,200.0107422,-37313.939453125,8.39414110087231E-5,1.3628034949386E-6,1,0.999253354069792,40.0298881530762,1.99585219120339,20.4399991780519,0.000947038091761351,0.000193401062546314,0.25,2.47565023301568E-6,8.42286145118078E-5,2.57427014689481E-6,200.0107422,200.0107422,-37316.125,-37311.75390625,57.3957637956407,20.5154804042451,26.705515,0,0,0,40,4449,199.9576,-37313.939453125,,,,,,,,,,,,,0,,,,0,,,,,,200.0107422,,,,
,32407369.305,200.0104828,-42246.3359375,0.000101092227460557,1.49915424911704E-6,1,0.999253354069792,40.0298881530762,1.99591531722582,20.4399991780519,0.00114210483368852,0.00022409048199128,0.25,2.20277893076568E-6,0.000101438983556258,2.31865166571171E-6,200.0104828,200.0104828,-42253.6640625,-42239.0078125,56.9189703989099,20.5175792350214,26.705515,0,0,0,40,4449,199.9465,-42246.3359375,,,,,,,,,,,,,0,,,,0,,,,,,200.0104828,,,,
,32407466.25,200.013031,-47091.322265625,0.000117645367897038,1.76618974168745E-6,1,0.999253354069792,40.0298881530762,1.99594197870268,20.4399991780519,0.0013275642138064,0.000269824378079988,0.25,3.36059824940041E-6,0.000118048081816684,3.49795372529991E-6,200.013031,200.013031,-47101.41796875,-47081.2265625,57.2589788047753,20.5136682769151,26.705515,0,0,0,40,4449,199.9363,-47091.322265625,,,,,,,,,,,,,0,,,,-0.00245,,,,,,200.013031,,,,
,32407564.575,200.0113373,-52003.705078125,0.000136209242558385,2.09247766652553E-6,1,0.999253354069792,40.0298881530762,1.99574775207719,20.4399991780519,0.00153935014837471,0.00029829548738121,0.25,2.6497843611481E-6,0.000136676885563708,2.80423436406567E-6,200.0113373,200.0113373,-52008.7578125,-51998.65234375,57.2863358029484,20.5140298625388,27.085165,0,0,0,40,4449,199.92875,-52003.705078125,,,,,,,,,,,,,0,,,,-0.0049,,,,,,200.0113373,,,,
,32407662.46,200.0152893,-56895.4609375,0.000153174760381649,2.35872191799839E-6,1,0.999253354069792,40.0298881530762,1.99593728408851,20.4399991780519,0.00172790171733857,0.000354707498001859,0.25,4.67558763590944E-6,0.000153698879613022,4.85480317837305E-6,200.0152893,200.0152893,-56905.59375,-56885.328125,57.4692368764484,20.5155930777668,26.325863,0,0,0,40,4449,199.9167,-56895.4609375,,,,,,,,,,,,,0,,,,-0.00245,,,,,,200.0152893,,,,
,32407760.895,200.01296995,-61815.595703125,0.000166827351823655,2.37111132531954E-6,1,0.999253354069792,40.0298881530762,1.99586513904245,20.4399991780519,0.00188322731203561,0.000378361353317432,0.25,4.39179810043579E-6,0.000167399007468636,4.58420331312598E-6,200.0127563,200.0131836,-61818.09375,-61813.09765625,57.268358347006,20.5127434127646,26.325863,0,0,0,40,4449,199.90405,-61815.595703125,,,,,,,,,,,,,0,,,,0.0049,,,,,,200.01296995,,,,
,32407859.79,200.0142365,-66757.90234375,0.000186170839802353,2.41346262880501E-6,1,0.999253354069792,40.0298881530762,1.99597521187292,20.4399991780519,0.00209870759246621,0.000439469422420318,0.25,6.41939570885179E-6,0.000186807232438142,6.63893907500716E-6,200.0142365,200.0142365,-66760.5234375,-66755.28125,57.3347967711407,20.5174089698759,26.325863,0,0,0,40,4449,199.89375,-66757.90234375,,,,,,,,,,,,,0,,,,-0.00245,,,,,,200.0142365,,,,
,32407958.22,200.0143127,-71677.2578125,0.000206946250098777,2.53131187991132E-6,1,0.999253354069792,40.0298881530762,1.9959505416913,20.4399991780519,0.00233511295419915,0.000475662687250291,0.25,6.00376255542589E-6,0.000207654939955602,6.2434316805016E-6,200.0143127,200.0143127,-71687.546875,-71666.96875,57.4762715331215,20.5187189859653,26.705515,0,0,0,40,4449,199.8812,-71677.2578125,,,,,,,,,,,,,0,,,,0,,,,,,200.0143127,,,,
,32408057.535,200.0114746,-76639.47265625,0.000226554830790825,2.30568375764692E-6,1,0.999253354069792,40.0298881530762,1.99600584968217,20.4399991780519,0.00256049516294569,0.000497387265097548,0.25,4.51344095391402E-6,0.00022733295631943,4.76818043783313E-6,200.0114746,200.0114746,-76644.34375,-76634.6015625,56.9502355396791,20.5183823932582,26.705515,0,0,0,40,4449,199.8736,-76639.47265625,,,,,,,,,,,,,0,,,,0.00245,,,,,,200.0114746,,,,
,32408155.655,200.012085,-81544.3984375,0.000241243366344856,3.64303893984796E-6,1,0.999253354069792,40.0298881530762,1.99597974888721,20.4399991780519,0.00272355110330361,0.000546437703588316,0.25,6.28877172340303E-6,0.000242070464898102,6.56460047435803E-6,200.012085,200.012085,-81546.734375,-81542.0625,56.8220484625252,20.5161362313231,26.325863,0,0,0,40,4449,199.8621,-81544.3984375,,,,,,,,,,,,,0,,,,-0.0049,,,,,,200.012085,,,,
,32408250.94,200.011261,-86306.3515625,0.000259065099734198,3.19818268284524E-6,1,0.999253354069792,40.0298881530762,1.99589083817675,20.4399991780519,0.00292546746886323,0.00058195197517863,0.25,6.3281301373304E-6,0.000259953852656188,6.62228454736005E-6,200.011261,200.011261,-86313.7890625,-86298.9140625,57.6052402387946,20.5181619343402,25.946213,0,0,0,40,4449,199.853,-86306.3515625,,,,,,,,,,,,,0,,,,-0.0049,,,,,,200.011261,,,,
,32408362.125,200.0107269,-89089.546875,0.000271299110942971,2.44363069751058E-6,1,0.999253354069792,40.0298881530762,1.99588809379509,20.4399991780519,0.00306797053551113,0.000584354788315252,0.25,4.41591876262818E-6,0.000272232219890089,4.71596437624374E-6,200.0107269,200.0107269,-89101.8828125,-89077.2109375,57.4622022197753,20.5176780418316,26.705515,0,0,0,40,4449,199.84735,-89089.546875,,,,,,,,,,,,,0,,,,-0.00245,,,,,,200.0107269,,,,
,32408455.585,200.0062256,-84420.41796875,0.000251834236443005,3.01982001093664E-6,1,0.999253354069792,40.0298881530762,1.99588808075404,20.4399991780519,0.00284252330261136,0.000573116954328271,0.25,6.80455389068272E-6,0.000252697495126332,7.09301112888843E-6,200.0062256,200.0062256,-84430.40625,-84410.4296875,57.3301070000253,20.5185459904147,26.325863,0,0,0,40,4449,199.8375,-84420.41796875,,,,,,,,,,,,,0,,,,0,,,,,,200.0062256,,,,
,32408553.82,199.99971005,-79510.47265625,0.000233366300424427,2.86547200914228E-6,1,0.999253354069792,40.0298881530762,1.99597484285547,20.4399991780519,0.00263737486587976,0.000512709111324493,0.25,4.6824774025663E-6,0.000234167921299178,4.94471935516902E-6,199.9996948,199.9997253,-79513.0625,-79507.8828125,57.1401712698522,20.5162090265484,26.705515,0,0,0,40,4449,199.84145,-79510.47265625,,,,,,,,,,,,,0,,,,0,,,,,,199.99971005,,,,
,32408651.095,199.994278,-74648.4296875,0.000217889219075343,2.40082230767336E-6,1,0.999253354069792,40.0298881530762,1.99599192065307,20.4399991780519,0.00246498533266812,0.000464290041609861,0.25,3.09998726071099E-6,0.000218638977035853,3.34094014653572E-6,199.994278,199.994278,-74655.875,-74640.984375,57.4864327038715,20.5153514764183,27.085165,0,0,0,40,4449,199.848,-74648.4296875,,,,,,,,,,,,,0,,,,0.0049,,,,,,199.994278,,,,
,32408748.97,199.9927826,-69756.4375,0.000197276131073287,1.80136241462281E-6,1,0.999253354069792,40.0298881530762,1.99591592820231,20.4399991780519,0.00222542004837918,0.00045655444824505,0.25,5.99862406586851E-6,0.000197951517806343,6.22826100112545E-6,199.9927826,199.9927826,-69763.984375,-69748.890625,57.4793980471984,20.5139937508251,26.705515,0,0,0,40,4449,199.8559,-69756.4375,,,,,,,,,,,,,0,,,,0,,,,,,199.9927826,,,,
,32408848.25,199.9898376,-64794.078125,0.000180153944408167,2.36363143536275E-6,1,0.999253354069792,40.0298881530762,1.99606494785931,20.4399991780519,0.00202755217471599,0.000444950081757306,0.25,7.94567709816967E-6,0.000180768039372758,8.16431915314824E-6,199.9898376,199.9898376,-64801.515625,-64786.640625,57.3301070000253,20.5136792979689,26.325863,0,0,0,40,4449,199.8656,-64794.078125,,,,,,,,,,,,,0,,,,0.00245,,,,,,199.9898376,,,,
,32408946.71,199.9874725,-59874.365234375,0.000160962059311462,2.33839089801188E-6,1,0.999253354069792,40.0298881530762,1.99592084584452,20.4399991780519,0.0018181182322676,0.000359013948756489,0.25,3.70329661965303E-6,0.000161514290645937,3.88727033790812E-6,199.9874725,199.9874725,-59879.34375,-59869.38671875,56.8423708040252,20.515122930438,26.325863,0,0,0,40,4449,199.875,-59874.365234375,,,,,,,,,,,,,0,,,,0,,,,,,199.9874725,,,,
,32409045.07,199.9898376,-54959.2890625,0.000144920706568271,2.00980288129718E-6,1,0.999253354069792,40.0298881530762,1.99598325527006,20.4399991780519,0.00163759130512711,0.000319690622607926,0.25,3.02055193610111E-6,0.00014541817208994,3.18542599938207E-6,199.9898376,199.9898376,-54967.12109375,-54951.45703125,57.2441278629099,20.5156729101339,27.085165,0,0,0,40,4449,199.88335,-54959.2890625,,,,,,,,,,,,,0,,,,-0.00245,,,,,,199.9898376,,,,
,32409144.735,199.9895325,-49980.935546875,0.000127313109949923,2.19177658385395E-6,1,0.999253354069792,40.0298881530762,1.99580858770014,20.4399991780519,0.00144064179009621,0.000268529363647336,0.25,1.56898604159534E-6,0.000127751246795235,1.71036364889634E-6,199.9895325,199.9895325,-49985.609375,-49976.26171875,57.3996719382368,20.5155724447023,26.705515,0,0,0,40,4449,199.8891,-49980.935546875,,,,,,,,,,,,,0,,,,-0.0049,,,,,,199.9895325,,,,
,32409244.045,199.9894257,-45015.79296875,0.00011083584154777,1.81503062825799E-6,1,0.999253354069792,40.0298881530762,1.99587956082778,20.4399991780519,0.00125337271816903,0.000238728033597319,0.25,1.80171670004568E-6,0.000111216770123828,1.92653766268871E-6,199.9894257,199.9894257,-45023.31640625,-45008.26953125,57.6075851243522,20.5134690888957,26.705515,0,0,0,40,4449,199.9028,-45015.79296875,,,,,,,,,,,,,0,,,,0.00245,,,,,,199.9894257,,,,
,32409344.305,199.9896393,-40005.24609375,9.29481551610983E-5,1.96346477406452E-6,1,0.999253354069792,40.0298881530762,1.9958170541575,20.4399991780519,0.0010517723778997,0.000196094189246964,0.25,1.14921597946779E-6,9.32679609529934E-5,1.2528412679996E-6,199.9896393,199.9896393,-40015.0234375,-39995.46875,57.7076335748138,20.5129310259276,26.705515,0,0,0,40,4449,199.9117,-40005.24609375,,,,,,,,,,,,,0,,,,-0.00245,,,,,,199.9896393,,,,
,32409441.39,199.986084,-35153.244140625,7.58922241424934E-5,1.34557435123267E-6,1,0.999253354069792,40.0298881530762,1.99602238915307,20.4399991780519,0.000854278367163589,0.000186488911747222,0.25,3.26265760074704E-6,7.61508338608012E-5,3.35544727625439E-6,199.9854126,199.9867554,-35183.12890625,-35123.359375,57.5325487865061,20.5111952746466,26.705515,0,0,0,40,4449,199.92405,-35153.244140625,,,,,,,,,,,,,0,,,,0.0049,,,,,,199.986084,,,,
,32409540.28,199.988678,-30208.365234375,5.90525896711277E-5,8.45154393110251E-7,1,0.999253354069792,40.0298881530762,1.99601558863165,20.4399991780519,0.000667790241559866,0.000127437437190511,0.25,9.80441138526905E-7,5.92554660156673E-5,1.0473793571245E-6,199.988678,199.988678,-30215.7578125,-30200.97265625,57.3066581444484,20.5093940526409,26.705515,0,0,0,40,4449,199.93085,-30208.365234375,,,,,,,,,,,,,0,,,,0,,,,,,199.988678,,,,
,32409638.68,199.9892426,-25291.3583984375,4.32456904141781E-5,1.12376665998115E-6,1,0.999253354069792,40.0298881530762,1.99611240803447,20.4399991780519,0.000486644901457048,0.000107246594683207,0.25,1.9449626512083E-6,4.33929244300194E-5,1.99830396190309E-6,199.9892426,199.9892426,-25293.88671875,-25288.830078125,57.1862873524868,20.5107583654997,26.705515,0,0,0,40,4449,199.9393,-25291.3583984375,,,,,,,,,,,,,0,,,,0.0049,,,,,,199.9892426,,,,
,32409735.955,199.9912262,-20431.6611328125,2.660976699304E-5,9.75203516280918E-7,1,0.999253354069792,40.0298881530762,1.99596738351722,20.4399991780519,0.000298334665468209,7.2232059150852E-5,0.25,1.74748084164586E-6,2.66997564293563E-5,1.78225310463947E-6,199.9912262,199.9912262,-20441.44921875,-20421.873046875,57.2589788047753,20.5119065535385,26.325863,0,0,0,40,4449,199.9473,-20431.6611328125,,,,,,,,,,,,,0,,,,0,,,,,,199.9912262,,,,
,32409835.265,199.9905243,-15464.4428710938,9.75537549272872E-6,7.78557329245751E-7,1,0.999253354069792,40.0298881530762,1.99593654563925,20.4399991780519,0.000109771900824822,2.41692794901024E-5,0.25,4.36823590658448E-7,9.78858335280398E-6,4.48885335247092E-7,199.9905243,199.9905243,-15474.30078125,-15454.5849609375,57.0432493334676,20.5115033485231,26.325863,0,0,0,40,4449,199.95415,-15464.4428710938,,,,,,,,,,,,,0,,,,0.00245,,,,,,199.9905243,,,,
,32409932.295,199.9928741,-10616.662109375,-5.01041967699719E-6,4.8556399875224E-7,1,0.999253354069792,40.0298881530762,1.99585378481763,20.4399991780519,-5.92192244243976E-5,3.94941329696748E-6,0.25,1.2185210367824E-6,-5.02903679388606E-6,1.21729871352743E-6,199.9928741,199.9928741,-10626.7919921875,-10606.5322265625,56.8431524325445,20.51056344372,27.085165,0,0,0,40,4449,199.9577,-10616.662109375,,,,,,,,,,,,,0,,,,-0.00245,,,,,,199.9928741,,,,
,32410030.73,199.993866,-5696.13427734375,-1.68787520745965E-5,4.48582116032692E-7,1,0.999253354069792,40.0298881530762,1.99590781236193,20.4399991780519,-0.000192483001426479,-2.70874896101285E-5,0.25,5.43113099452729E-7,-1.69376053297122E-5,5.26673398175331E-7,199.993866,199.993866,-5698.7001953125,-5693.568359375,57.2644502044099,20.5124823944291,27.085165,0,0,0,40,4449,199.9637,-5696.13427734375,,,,,,,,,,,,,0,,,,0,,,,,,199.993866,,,,
,32410127.37,199.996582,-864.549530029297,-2.1190363700774E-5,3.90951643889721E-7,1,0.999253354069792,40.0298881530762,1.99596440474549,20.4399991780519,-0.000240345907341949,-4.15649274434493E-5,0.25,1.55086433140504E-8,-2.12635218790671E-5,-7.45772928441462E-9,199.996582,199.996582,-874.626403808594,-854.47265625,57.2847725459099,20.5072144558745,27.085165,0,0,0,40,4449,199.9645,-864.549530029297,,,,,,,,,,,,,0,,,,0,,,,,,199.996582,,,,
,32410222.905,200.000061,3906.19177246094,4.39230482292136E-6,3.5399378566672E-7,1,0.999253354069792,40.0298881530762,1.99576615234554,20.4399991780519,5.15368394388541E-5,-1.3054842588428E-6,0.25,-8.78028808064722E-7,4.40841859319424E-6,-8.76291350833099E-7,200.000061,200.000061,3903.53979492188,3908.84375,57.5169162161215,20.5092300029573,26.705515,0,0,0,40,4449,199.9676,3906.19177246094,,,,,,,,,,,,,0,,,,0,,,,,,200.000061,,,,
,32410321.5,200.0036926,8832.7822265625,7.82127277265279E-6,4.64479432287497E-7,1,0.999253354069792,40.0298881530762,1.99574758583633,20.4399991780519,9.05201351859616E-5,4.868998566655E-6,0.25,-9.29093129423723E-7,7.84927691210341E-6,-9.23821378042174E-7,200.0036926,200.0036926,8822.720703125,8842.84375,57.2019199228714,20.5081176173298,26.705515,0,0,0,40,4449,199.96525,8832.7822265625,,,,,,,,,,,,,0,,,,0.0049,,,,,,200.0036926,,,,
,32410416.64,200.0066223,13588.5424804687,-3.99679886079542E-6,6.32653877027356E-7,1,0.999253354069792,40.0298881530762,1.99585397476842,20.4399991780519,-4.19357963811038E-5,-2.73825237371212E-5,0.25,-1.72044738175563E-6,-4.0087328784364E-6,-1.73071269433294E-6,200.0066223,200.0066223,13585.5517578125,13591.533203125,57.2144259791791,20.5078137612687,26.325863,0,0,0,40,4449,199.9536,13588.5424804687,,,,,,,,,,,,,0,,,,0.0049,,,,,,200.0066223,,,,
,32410514.62,200.0066681,18488.423828125,-1.92251596821128E-5,8.2429100874376E-7,1,0.999253354069792,40.0298881530762,1.99604348525152,20.4399991780519,-0.000214850758692534,-5.62146085836353E-5,0.25,-1.61751681564942E-6,-1.9289779258872E-5,-1.64387788318256E-6,200.0066681,200.0066681,18483.431640625,18493.416015625,57.2519441481022,20.5058795247296,27.085165,0,0,0,40,4449,199.9497,18488.423828125,,,,,,,,,,,,,0,,,,-0.0049,,,,,,200.0066681,,,,
,32410613.795,200.0094147,23443.4375,-3.56641202322069E-5,1.00911288095567E-6,1,0.999253354069792,40.0298881530762,1.99609771734703,20.4399991780519,-0.000399026796152412,-0.000101682786221711,0.25,-2.77123406171097E-6,-3.57842539104858E-5,-2.81927849796703E-6,200.0094147,200.0094147,23440.658203125,23446.216796875,57.1518956976407,20.5047767418452,27.085165,0,0,0,40,4449,199.9396,23443.4375,,,,,,,,,,,,,0,,,,0,,,,,,200.0094147,,,,
,32410715.095,200.0148926,28508.74609375,-5.29575541158522E-5,1.09082514695706E-6,1,0.999253354069792,40.0298881530762,1.99605499149591,20.4399991780519,-0.000596031290243234,-0.000130664124045381,0.25,-2.32330469056237E-6,-5.31378835636383E-5,-2.38835638518925E-6,200.0148926,200.0148926,28503.423828125,28514.068359375,57.2324034351214,20.503783213532,26.705515,0,0,0,40,4449,199.92865,28508.74609375,,,,,,,,,,,,,0,,,,0.00245,,,,,,200.0148926,,,,
,32410814.1,200.0148926,33453.90625,-6.96678386815805E-5,1.261071214535E-6,1,0.999253354069792,40.0298881530762,1.99608687399261,20.4399991780519,-0.000784778601600541,-0.00016808106785055,0.25,-2.72010720616925E-6,-6.99054570605684E-5,-2.80438824912857E-6,200.0148926,200.0148926,33446.48046875,33461.33203125,56.9760292808137,20.5046282819158,26.705515,0,0,0,40,4449,199.9151,33453.90625,,,,,,,,,,,,,0,,,,-0.00245,,,,,,200.0148926,,,,
,32410912.77,200.0124664,38386.068359375,-8.79928163490597E-5,1.57698514459411E-6,1,0.999253354069792,40.0298881530762,1.99612498120931,20.4399991780519,-0.000990817994032162,-0.00021461178841794,0.25,-3.639948591989E-6,-8.82927570910861E-5,-3.74692760575227E-6,200.0124664,200.0124664,38378.59375,38393.54296875,57.0799858738714,20.5021314529219,27.085165,0,0,0,40,4449,199.9025,38386.068359375,,,,,,,,,,,,,0,,,,0.0049,,,,,,200.0124664,,,,
,32411013.535,200.0135803,43423.6171875,-0.000103436249024149,1.47992534314258E-6,1,0.999253354069792,40.0298881530762,1.99617292959848,20.4399991780519,-0.00116382882114337,-0.000257538667312095,0.25,-4.74232551922368E-6,-0.000103788372584094,-4.86946321965932E-6,200.0135803,200.0135803,43421.23828125,43425.99609375,57.3394865422561,20.5029593243799,27.085165,0,0,0,40,4449,199.8903,43423.6171875,,,,,,,,,,,,,0,,,,-0.0049,,,,,,200.0135803,,,,
,32411112.695,200.0153503,48378.8203125,-0.000122841464010939,2.0516996606393E-6,1,0.999253354069792,40.0298881530762,1.99604073254555,20.4399991780519,-0.00138391653175051,-0.000295275961357912,0.25,-4.70123230544522E-6,-0.000123260685347446,-4.8487480866932E-6,200.0153503,200.0153503,48373.72265625,48383.91796875,57.1565854687561,20.503333479643,26.325863,0,0,0,40,4449,199.87785,48378.8203125,,,,,,,,,,,,,0,,,,0,,,,,,200.0153503,,,,
,32411209.745,200.0117645,53229.080078125,-0.000137699685750491,1.99428910451487E-6,1,0.999253354069792,40.0298881530762,1.99600598732168,20.4399991780519,-0.00155488965846923,-0.00031021507051056,0.25,-3.4387242915422E-6,-0.000138171637803012,-3.59746251010775E-6,200.0117645,200.0117645,53221.6796875,53236.48046875,57.1784710672945,20.5034507115081,27.085165,0,0,0,40,4449,199.87335,53229.080078125,,,,,,,,,,,,,0,,,,-0.0049,,,,,,200.0117645,,,,
,32411309.53,200.0114594,58216.927734375,-0.0001563962725413,1.89194227929298E-6,1,0.999253354069792,40.0298881530762,1.99585738465912,20.4399991780519,-0.00176583960781024,-0.000352569745157847,0.25,-3.92882262257792E-6,-0.000156932339966858,-4.10885584190171E-6,200.0114594,200.0114594,58214.83984375,58219.015625,57.007294421583,20.5048614900694,26.705515,0,0,0,40,4449,199.85565,58216.927734375,,,,,,,,,,,,,0,,,,-0.00245,,,,,,200.0114594,,,,
,32411410.745,200.0136108,63277.59375,-0.000173575600620606,2.00090847670726E-6,1,0.999253354069792,40.0298881530762,1.99600626506354,20.4399991780519,-0.00195520047756258,-0.000418663696747879,0.25,-6.77130531475997E-6,-0.000174168046951956,-6.97904667637929E-6,200.0134277,200.0137939,63272.97265625,63282.21484375,57.2394380917945,20.5034915704911,26.325863,0,0,0,40,4449,199.84635,63277.59375,,,,,,,,,,,,,0,,,,-0.0049,,,,,,200.0136108,,,,
,32411511.02,200.0147858,68287.48828125,-0.000191559876298856,2.48511028472482E-6,1,0.999253354069792,40.0298881530762,1.99589212325673,20.4399991780519,-0.00215932148944651,-0.000452467039410136,0.25,-6.63124393985555E-6,-0.000192214672095307,-6.8571612858664E-6,200.0147858,200.0147858,68279.765625,68295.2109375,57.3090030300061,20.5034052549138,26.705515,0,0,0,40,4449,199.8396,68287.48828125,,,,,,,,,,,,,0,,,,0,,,,,,200.0147858,,,,
,32411612.06,200.0139008,73340.4140625,-0.000210229515459225,2.20125392767807E-6,1,0.999253354069792,40.0298881530762,1.99590660896282,20.4399991780519,-0.00237144129856605,-0.000487053231602537,0.25,-6.43896131305588E-6,-0.000210949108770479,-6.68351278433086E-6,200.0139008,200.0139008,73327.796875,73353.03125,57.5286406439099,20.5030908231197,26.325863,0,0,0,40,4449,199.82835,73340.4140625,,,,,,,,,,,,,0,,,,0.0049,,,,,,200.0139008,,,,
,32411710.97,200.012619,78283.15625,-0.000228458805550715,2.44866622806943E-6,1,0.999253354069792,40.0298881530762,1.99587946493398,20.4399991780519,-0.00257686878245879,-0.000530265003252142,0.25,-7.0846987733327E-6,-0.000229240803780698,-7.35024165150848E-6,200.012619,200.012619,78275.53125,78290.78125,57.1737812961791,20.5028634018472,26.325863,0,0,0,40,4449,199.8129,78283.15625,,,,,,,,,,,,,0,,,,-0.0049,,,,,,200.012619,,,,
,32411809.46,200.0160217,83209.37109375,-0.000247975826170068,2.5077899000171E-6,1,0.999253354069792,40.0298881530762,1.99594459323494,20.4399991780519,-0.00280611149906544,-0.000523668736711484,0.25,-3.11284135383276E-6,-0.00024882952116744,-3.38467822580831E-6,200.0160217,200.0160217,83204.2578125,83214.484375,57.088583787583,20.5029095947843,27.085165,0,0,0,40,4449,199.8031,83209.37109375,,,,,,,,,,,,,0,,,,0,,,,,,200.0160217,,,,
,32411903.78,200.0121002,87922.6015625,-0.000262561272352956,2.32830922216109E-6,1,0.999253354069792,40.0298881530762,1.99590722984225,20.4399991780519,-0.00296821731929555,-0.000571116255638666,0.25,-4.7652173211629E-6,-0.000263463760830247,-5.0575427502748E-6,200.0121002,200.0121002,87917.46875,87927.734375,57.1331366131791,20.5024447905222,26.705515,0,0,0,40,4449,199.7897,87922.6015625,,,,,,,,,,,,,0,,,,0.0049,,,,,,200.0121002,,,,
,32412016.385,200.0084839,87463.50390625,-0.000262812632372753,2.34442990338435E-6,1,0.999253354069792,40.0298881530762,1.99573835984288,20.4399991780519,-0.00297053610213865,-0.00057324710297557,0.25,-4.91347024300557E-6,-0.000263715853777462,-5.20664408244184E-6,200.0084839,200.0084839,87453.453125,87473.5546875,57.0807675023906,20.5049866167832,26.705515,0,0,0,40,4449,199.78215,87463.50390625,,,,,,,,,,,,,0,,,,0,,,,,,200.0084839,,,,
,32412112.955,200.0025787,82634.96484375,-0.000245966341654223,2.31705520046225E-6,1,0.999253354069792,40.0298881530762,1.99576849285835,20.4399991780519,-0.00277969264449238,-0.000539225469719362,0.25,-4.83743420934813E-6,-0.000246811368574808,-5.11322365580287E-6,200.0025787,200.0025787,82624.9765625,82644.953125,57.1987934087945,20.5081397493308,27.085165,0,0,0,40,4449,199.77895,82634.96484375,,,,,,,,,,,,,0,,,,0,,,,,,200.0025787,,,,
,32412211.06,199.9958954,77731.3125,-0.000225572188423123,1.84702563359053E-6,1,0.999253354069792,40.0298881530762,1.99578637525604,20.4399991780519,-0.00254671849585847,-0.000509025392451335,0.25,-5.71496101154052E-6,-0.000226345765915725,-5.972821230901E-6,199.9958954,199.9958954,77721.3984375,77741.2265625,57.1432977839291,20.5061810854924,26.705515,0,0,0,40,4449,199.78955,77731.3125,,,,,,,,,,,,,0,,,,0.0049,,,,,,199.9958954,,,,
,32412308.83,199.9917297,72845.2421875,-0.000210579223096253,2.12294239493217E-6,1,0.999253354069792,40.0298881530762,1.99593861423689,20.4399991780519,-0.00237712169749615,-0.00047809540261944,0.25,-5.58757455037194E-6,-0.000211301064178854,-5.82964859607335E-6,199.9917297,199.9917297,72838.109375,72852.375,56.9643048530253,20.505127515849,26.705515,0,0,0,40,4449,199.7981,72845.2421875,,,,,,,,,,,,,0,,,,-0.00245,,,,,,199.9917297,,,,
,32412405.625,199.9890137,68004.6953125,-0.000193185703031185,2.27686417533148E-6,1,0.999253354069792,40.0298881530762,1.99571039546921,20.4399991780519,-0.00218067444170657,-0.000437762911806157,0.25,-5.05554471992688E-6,-0.000193847938651874,-5.2778157918226E-6,199.9890137,199.9890137,68004.6953125,68004.6953125,57.129228470583,20.5071777978034,26.325863,0,0,0,40,4449,199.8038,68004.6953125,,,,,,,,,,,,,0,,,,0.0049,,,,,,199.9890137,,,,
,32412500.87,199.9866638,63244.638671875,-0.000174513472131536,1.77382257434143E-6,1,0.999253354069792,40.0298881530762,1.99586963094572,20.4399991780519,-0.00196885050002277,-0.000402401459328122,0.25,-5.17675795081784E-6,-0.000175111001272485,-5.38002837031827E-6,199.9866638,199.9866638,63237.0703125,63252.20703125,57.1792526958137,20.5061238865055,26.705515,0,0,0,40,4449,199.8161,63244.638671875,,,,,,,,,,,,,0,,,,0,,,,,,199.9866638,,,,
,32412597.35,199.9886322,58421.533203125,-0.000155800626436794,1.84297145067576E-6,1,0.999253354069792,40.0298881530762,1.99592098130449,20.4399991780519,-0.00175784876259903,-0.000358840431259172,0.25,-4.58422734942717E-6,-0.000156334054403763,-4.76590604273773E-6,199.9886322,199.9886322,58408.921875,58434.14453125,56.8916134007368,20.5064019326793,27.085165,0,0,0,40,4449,199.8294,58421.533203125,,,,,,,,,,,,,0,,,,0,,,,,,199.9886322,,,,
,32412694.735,199.9870453,53553.451171875,-0.000141378738595814,1.98633926194994E-6,1,0.999253354069792,40.0298881530762,1.99587538052579,20.4399991780519,-0.00159395706578313,-0.000332174106269244,0.25,-4.73781167838659E-6,-0.000141862126444846,-4.90497595365576E-6,199.9870453,199.9870453,53550.9765625,53555.92578125,57.2253687784484,20.5056273696882,27.085165,0,0,0,40,4449,199.83865,53553.451171875,,,,,,,,,,,,,0,,,,0,,,,,,199.9870453,,,,
,32412792.34,199.9894867,48675.568359375,-0.000121842008094028,1.80425127133423E-6,1,0.999253354069792,40.0298881530762,1.99597657338076,20.4399991780519,-0.00137323206962978,-0.000289316509681827,0.25,-4.35009494436136E-6,-0.000122258255289138,-4.49534494008965E-6,199.9894867,199.9894867,48668.2109375,48682.92578125,57.2855541744291,20.5071422608219,27.085165,0,0,0,40,4449,199.84355,48675.568359375,,,,,,,,,,,,,0,,,,-0.00245,,,,,,199.9894867,,,,
,32412886.35,199.9916611,43977.439453125,-0.000105406261872721,1.65665761587738E-6,1,0.999253354069792,40.0298881530762,1.9957990874354,20.4399991780519,-0.00118940819292416,-0.000241526929740647,0.25,-2.99224708904523E-6,-0.000105767138829382,-3.11545446333896E-6,199.9913025,199.9920197,43965.1796875,43989.69921875,57.3668435404292,20.5102045078271,26.705515,0,0,0,40,4449,199.85105,43977.439453125,,,,,,,,,,,,,0,,,,-0.00245,,,,,,199.9916611,,,,
,32412982.535,199.9887695,39169.630859375,-9.04474756165655E-5,1.61421533041404E-6,1,0.999253354069792,40.0298881530762,1.99588112718283,20.4399991780519,-0.00101770172697164,-0.000224248326546438,0.25,-4.06557895612099E-6,-9.07555077650474E-5,-4.17665962977542E-6,199.9887695,199.9887695,39162.12109375,39177.140625,57.4489145349484,20.5077779690449,26.705515,0,0,0,40,4449,199.8598,39169.630859375,,,,,,,,,,,,,0,,,,0,,,,,,199.9887695,,,,
,32413071.905,199.9897614,34702.5078125,-7.49476597636473E-5,1.38410170326569E-6,1,0.999253354069792,40.0298881530762,1.99584409997997,20.4399991780519,-0.000844296738406487,-0.000179989566728122,0.25,-2.85494631599531E-6,-7.5203428077406E-5,-2.94535554688581E-6,199.9897614,199.9897614,34695.015625,34710,57.2370932062368,20.5072219264856,26.705515,0,0,0,40,4449,199.8667,34702.5078125,,,,,,,,,,,,,0,,,,0.00245,,,,,,199.9897614,,,,
,32413169.585,199.986084,29822.6689453125,-5.69701855402878E-5,1.22222698563711E-6,1,0.999253354069792,40.0298881530762,1.99583072733212,20.4399991780519,-0.000642862758713394,-0.000130543583749,0.25,-1.61698867912623E-6,-5.71651852908828E-5,-1.68391313256636E-6,199.986084,199.986084,29817.626953125,29827.7109375,57.0924919301791,20.5086279013088,27.085165,0,0,0,40,4449,199.87835,29822.6689453125,,,,,,,,,,,,,0,,,,-0.00245,,,,,,199.986084,,,,
,32413263.665,199.99038695,25119.720703125,-4.1681920838859E-5,1.02806195772547E-6,1,0.999253354069792,40.0298881530762,1.9959820210451,20.4399991780519,-0.000466912144207287,-0.000115489390685454,0.25,-2.9439556370571E-6,-4.18226724361884E-5,-2.99907843738866E-6,199.9901581,199.9906158,25114.849609375,25124.591796875,57.2722664896022,20.5100705327598,26.705515,0,0,0,40,4449,199.88455,25119.720703125,,,,,,,,,,,,,0,,,,0.0049,,,,,,199.99038695,,,,
,32413359.715,199.9879913,20317.1630859375,-2.49260443721185E-5,7.57530387719352E-7,1,0.999253354069792,40.0298881530762,1.99594677194003,20.4399991780519,-0.000277382013477976,-7.95956773232192E-5,0.25,-2.68927933774365E-6,-2.5009203269557E-5,-2.72549527825942E-6,199.9879913,199.9879913,20312.296875,20322.029296875,57.2011382943522,20.5100124466978,26.705515,0,0,0,40,4449,199.8931,20317.1630859375,,,,,,,,,,,,,0,,,,0,,,,,,199.9879913,,,,
,32413455.145,199.9859314,15550.1025390625,-1.03588037318951E-5,7.99673858593004E-7,1,0.999253354069792,40.0298881530762,1.99595901256544,20.4399991780519,-0.000115385579405597,-3.24447483394789E-5,0.25,-1.06169869671853E-6,-1.03934196581668E-5,-1.07657409530156E-6,199.9859314,199.9859314,15539.978515625,15560.2265625,57.2331850636407,20.5103559711776,27.085165,0,0,0,40,4449,199.9015,15550.1025390625,,,,,,,,,,,,,0,,,,-0.00245,,,,,,199.9859314,,,,
,32413547.645,199.9908066,10925.0302734375,4.34305417320497E-6,4.24233502078568E-7,1,0.999253354069792,40.0298881530762,1.99589033509335,20.4399991780519,5.21391661720125E-5,-8.06837033366916E-6,0.25,-1.46581307884969E-6,4.35963586254428E-6,-1.46616659624386E-6,199.9907837,199.9908295,10922.599609375,10927.4609375,57.1933220091599,20.5130848101993,26.705515,0,0,0,40,4449,199.908,10925.0302734375,,,,,,,,,,,,,0,,,,0,,,,,,199.9908066,,,,
,32413640.88,199.9941101,6267.07348632813,1.67871329493247E-5,5.29721339514865E-7,1,0.999253354069792,40.0298881530762,1.99588455520422,20.4399991780519,0.000191109668007771,2.88192850968907E-5,0.25,-3.74464937492113E-7,1.6845486476273E-5,-3.57539789134567E-7,199.9941101,199.9941101,6264.73486328125,6269.412109375,57.2355299491984,20.5126901628705,27.085165,0,0,0,40,4449,199.91455,6267.07348632813,,,,,,,,,,,,,0,,,,0,,,,,,199.9941101,,,,
,32413731.615,199.9920807,1728.67010498047,2.199845521005E-5,3.54473513827536E-7,1,0.999253354069792,40.0298881530762,1.99583934354597,20.4399991780519,0.000251429587298437,3.20184530502542E-5,0.25,-9.97484444327741E-7,2.20754723614788E-5,-9.77026850435844E-7,199.9920807,199.9920807,1721.24328613281,1736.09692382813,57.3668435404292,20.5134498061248,26.705515,0,0,0,40,4449,199.9167,1728.67010498047,,,,,,,,,,,,,0,,,,0.00245,,,,,,199.9920807,,,,
,32413767.695,199.99333955,-0.403429985046387,2.0177051007936E-5,3.38827060890635E-7,1,0.999253354069792,40.0298881530762,1.99594202006272,20.4399991780519,0.000229784336461878,3.41990370559939E-5,0.25,-4.88985972031285E-7,2.02472269962712E-5,-4.68745557622385E-7,199.9932709,199.9934082,-0.411041855812073,-0.395818114280701,57.4567308201407,20.5134175526816,27.085165,0,0,0,40,4417,199.92,-0.403429985046387,,,,,,,,,,,,,0,,,,0.00245,,,,,,199.99333955,,,,