File: data/monolayers/magneticStructure/ML_Ac_CoFe_C/PPMS/data/DD205_4_FCW_100OE.DAT
[Header]
; VSM Data File (default extension .dat)
; Copyright (c) 2003-2013, Quantum Design, Inc. All rights reserved.
TITLE,
FILEOPENTIME,32308783.50,01/10/2019,6:42 am
BYAPP,VSM,2.0,2.0
INFO,PPMS VSM Option Release 1.4.10 Build 1,APPNAME
INFO,Quantum Design Linear Motor Servo Controller,MOTOR_MODULE_NAME
INFO,3101-100 M1,MOTOR_HW_VERSION
INFO,MMC1014,MOTOR_SERIAL_NUMBER
INFO,SRV No X-over 01.03.11,MOTOR_SOFTWARE_VERSION
INFO,Quantum Design VSM Detection Module,VSM_MODULE_NAME
INFO,3101-150 F0,VSM_HW_VERSION
INFO,VSM707,VSM_SERIAL_NUMBER
INFO,VSM No X-over 01.02.05 May 20 2008 13:51:47,VSM_SOFTWARE_VERSION
INFO,704,PREAMP_SERIAL_NUMBER
INFO,822,COIL_SERIAL_NUMBER
INFO,0,MOMENT_UNITS
INFO,DD205_4,SAMPLE_MATERIAL
INFO,Monolayer,SAMPLE_COMMENT
INFO,29.55,SAMPLE_MASS
INFO,,SAMPLE_VOLUME
INFO,,SAMPLE_MOLECULAR_WEIGHT
INFO,,SAMPLE_SIZE
INFO,,SAMPLE_SHAPE
DATATYPE,COMMENT,1
DATATYPE,TIME,2
STARTUPAXIS,X,2
STARTUPAXIS,Y1,5
[Data]
Comment,Time Stamp (sec),Temperature (K),Magnetic Field (Oe),Moment (emu),M. Std. Err. (emu),Transport Action,Averaging Time (sec),Frequency (Hz),Peak Amplitude (mm),Center Position (mm),Coil Signal' (mV),Coil Signal" (mV),Range (mV),M. Quad. Signal (emu),M. Raw' (emu),M. Raw" (emu),Min. Temperature (K),Max. Temperature (K),Min. Field (Oe),Max. Field (Oe),Mass (grams),Motor Lag (deg),Pressure (Torr),VSM Status (code),Motor Status (code),Measure Status (code),Measure Count,PPMS Status (code),System Temp. (K),System Field (Oe),Sample Position (deg),Bridge 1 Resistance (ohms),Bridge 1 Excitation (에),Bridge 2 Resistance (ohms),Bridge 2 Excitation (에),Bridge 3 Resistance (ohms),Bridge 3 Excitation (에),Bridge 4 Resistance (ohms),Bridge 4 Excitation (에),Signal 1 Vin (V),Signal 2 Vin (V),Digital Inputs (code),Drive 1 Iout (mA),Drive 1 Ipower (W),Drive 2 Iout (mA),Drive 2 Ipower (W),Pressure (),Map 20 (),Map 21 (),Map 22 (),Map 23 (),Map 24 (),Map 25 (),Map 26 (),Map 27 (),Map 28 (),Map 29 ()
,32308915.565,4.9953861,99.4112396240234,1.06800448107735E-5,3.66326029021906E-7,1,0.999253354069792,40.0298881530762,1.98373647521918,21.0999995470047,0.000119525275275119,1.95164515020225E-5,0.25,-1.48348774265974E-7,1.0619483026759E-5,-9.59894093722689E-8,4.9953861,4.9953861,99.4112396240234,99.4112396240234,57.0002597649099,20.537258931902,8.482265,0,0,0,40,4369,5.0075,99.4112396240234,,,,,,,,,,,,,0,,,,0,,,,,,4.9953861,,,,
,32309043.39,8.0098,99.4112396240234,1.08048334975886E-5,2.64408991236057E-7,1,0.999253354069792,40.0298881530762,1.98353677535405,21.0999995470047,0.000120828380242121,2.02020238465352E-5,0.25,-1.0892096417754E-7,1.07433440705168E-5,-5.61858691028869E-8,8.0098,8.0098,99.4112396240234,99.4112396240234,57.3801312252561,20.5429832075344,10.38052,0,0,0,40,4370,8.09645,99.4112396240234,,,,,,,,,,,,,0,,,,-0.00245,,,,,,8.0098,,,,
,32309183.645,11.5262451,99.4112396240234,1.06868179893068E-5,2.89969699985609E-7,1,0.999253354069792,40.0298881530762,1.98348298814829,21.0999995470047,0.000120484587179293,1.44637947450509E-5,0.25,-6.01971912868289E-7,1.06283277171621E-5,-5.46973216087586E-7,11.5262451,11.5262451,99.4112396240234,99.4112396240234,57.0948368157368,20.5449996407866,11.139823,0,0,0,40,4370,11.6192,99.4112396240234,,,,,,,,,,,,,0,,,,-0.00245,,,,,,11.5262451,,,,
,32309341.19,15.3991747,99.4112396240234,,,2,,,,21.180000692606,,,,,,,15.3991747,15.3991747,99.4112396240234,99.4112396240234,,,13.038077,,,,-99999999,4370,15.5767,99.4112396240234,,,,,,,,,,,,,,,,,,,,,,,15.3991747,,,,
,32309465.295,18.5198421,99.4112396240234,1.05562950819215E-5,3.08134881100873E-7,1,0.999253354069792,40.0298881530762,2.00748955532709,21.1699996143579,0.000119834885606072,1.75541056360782E-5,0.25,-3.19931277706255E-7,1.04970341090965E-5,-2.67124957408953E-7,18.5198421,18.5198421,99.4112396240234,99.4112396240234,57.1456426694868,20.5317054996158,13.038077,0,0,0,40,4370,18.694,99.4112396240234,,,,,,,,,,,,,0,,,,-0.0049,,,,,,18.5198421,,,,
,32309606.93,22.0452595,99.4112396240234,1.05374700118161E-5,3.26046892378543E-7,1,0.999253354069792,40.0298881530762,1.99515100442372,21.1699996143579,0.00011889803565725,1.75876600862132E-5,0.25,-3.05488052724953E-7,1.04789487059293E-5,-2.51922598777755E-7,22.0452595,22.0452595,99.4112396240234,99.4112396240234,57.6193095521407,20.5372630358653,13.797379,0,0,0,40,4370,22.26025,99.4112396240234,,,,,,,,,,,,,0,,,,0.00245,,,,,,22.0452595,,,,
,32309759.72,25.8209209,99.4112396240234,,,2,,,,21.1999999135733,,,,,,,25.8209209,25.8209209,99.4112396240234,99.4112396240234,,,14.177031,,,,-99999999,4370,26.1021,99.4112396240234,,,,,,,,,,,,,,,,,,,,,,,25.8209209,,,,
,32309888.955,29.02183915,99.4112396240234,1.07387233505639E-5,3.02339080889488E-7,1,0.999253354069792,40.0298881530762,1.98356045702604,21.1900006979704,0.000120273058698865,1.94018661689027E-5,0.25,-1.76160245206688E-7,1.06832973807807E-5,-1.17052393642284E-7,28.9914913,29.052187,99.4112396240234,99.4112396240234,57.4598573342176,20.5452696921032,14.177031,0,0,0,40,4370,29.37475,99.4112396240234,,,,,,,,,,,,,0,,,,-0.00245,,,,,,29.02183915,,,,
,32310032.16,32.5552711,99.4112396240234,1.07166550976178E-5,2.95695703296776E-7,1,0.999253354069792,40.0298881530762,1.98370437797391,21.1900006979704,0.000120078639010283,1.94231487808273E-5,0.25,-1.7547622201842E-7,1.06660738535692E-5,-1.12305802141888E-7,32.5552711,32.5552711,99.4112396240234,99.4112396240234,56.7853119221214,20.5460595284649,14.936333,0,0,0,40,4370,32.97235,99.4112396240234,,,,,,,,,,,,,0,,,,0.00245,,,,,,32.5552711,,,,
,32310180.55,36.2496147,99.4112396240234,,,2,,,,21.180000692606,,,,,,,36.2496147,36.2496147,99.4112396240234,99.4112396240234,,,15.315984,,,,-99999999,4370,36.7112,99.4112396240234,,,,,,,,,,,,,,,,,,,,,,,36.2496147,,,,
,32310312.51,39.5252495,99.4112396240234,1.06288490795345E-5,3.36794677974217E-7,1,0.999253354069792,40.0298881530762,1.99501576362747,21.1699996143579,0.000119639544822668,2.09050295862471E-5,0.25,-4.93111617437738E-8,1.05925601459796E-5,2.21761868166354E-8,39.5252495,39.5252495,99.4112396240234,99.4112396240234,57.4067065949099,20.5392208104153,16.075285,0,0,0,40,4370,40.0455,99.4112396240234,,,,,,,,,,,,,0,,,,0,,,,,,39.5252495,,,,
,32310455.275,43.0257835,99.4112396240234,1.08587853531147E-5,3.4491697117975E-7,1,0.999253354069792,40.0298881530762,1.9949247602224,21.1699996143579,0.000122463419836932,2.06957001198701E-5,0.25,-1.15096294953042E-7,1.0832626628276E-5,-3.77007140695917E-8,43.0257835,43.0257835,99.4112396240234,99.4112396240234,57.6935642614676,20.5354452276215,16.075285,0,0,0,40,4370,43.6629,99.4112396240234,,,,,,,,,,,,,0,,,,-0.00245,,,,,,43.0257835,,,,
,32310604.2,46.6672974,99.4112396240234,,,2,,,,21.1700001507998,,,,,,,46.6672974,46.6672974,99.4112396240234,99.4112396240234,,,16.454937,,,,-99999999,4370,47.4284,99.4112396240234,,,,,,,,,,,,,,,,,,,,,,,46.6672974,,,,
,32310740.575,50.0255699,99.4112396240234,1.05946087092872E-5,3.00514273757203E-7,1,0.999253354069792,40.0298881530762,1.99452915952973,21.1599990725517,0.00012038281151216,1.66053140502617E-5,0.25,-4.37424512880582E-7,1.05951331831388E-5,-3.58473190638707E-7,50.0255699,50.0255699,99.4112396240234,99.4112396240234,57.0393411908714,20.5392652029334,17.214239,0,0,0,40,4370,50.9121,99.4112396240234,,,,,,,,,,,,,0,,,,0,,,,,,50.0255699,,,,
,32310885.85,53.5387497,99.4112396240234,1.07132987182397E-5,3.4255984421549E-7,1,0.999253354069792,40.0298881530762,1.99453809741998,21.1599990725517,0.000121754733814212,1.74520291896317E-5,0.25,-3.8428235003526E-7,1.07255870291205E-5,-3.06036876131916E-7,53.5387497,53.5387497,99.4112396240234,99.4112396240234,57.0315249056791,20.5421073592305,18.353191,0,0,0,40,4374,54.6472,99.4112396240234,,,,,,,,,,,,,0,,,,0.00245,,,,,,53.5387497,,,,
,32311033.97,57.0900154,99.4112396240234,,,2,,,,21.1500009298325,,,,,,,57.0900154,57.0900154,99.4112396240234,99.4112396240234,,,19.492144,,,,-99999999,4374,58.4605,99.4112396240234,,,,,,,,,,,,,,,,,,,,,,,57.0900154,,,,
,32311155.565,60.0498009,99.4112396240234,1.04858740061126E-5,3.24432072025571E-7,1,0.999253354069792,40.0298881530762,1.98347149758842,21.1399998515844,0.000118128069144471,2.0481256823809E-5,0.25,-6.23639885416159E-8,1.05144769481727E-5,8.21873058552241E-9,60.0498009,60.0498009,99.4112396240234,99.4112396240234,57.0706063316407,20.5451148454936,19.871798,0,0,0,40,4374,61.56575,99.4112396240234,,,,,,,,,,,,,0,,,,0,,,,,,60.0498009,,,,
,32311297.255,63.5449181,99.4112396240234,1.06414543061543E-5,2.70924846959909E-7,1,0.999253354069792,40.0298881530762,1.98337468341005,21.1399998515844,0.000120121616802436,1.99033934359425E-5,0.25,-1.38355593775652E-7,1.06786450312479E-5,-7.14584456050392E-8,63.5449181,63.5449181,99.4112396240234,99.4112396240234,57.2292769210445,20.54489424279,19.871798,0,0,0,40,4374,65.1558,99.4112396240234,,,,,,,,,,,,,0,,,,0,,,,,,63.5449181,,,,
,32311437.875,67.0195694,99.4112396240234,1.07216931667889E-5,2.83638459800229E-7,1,0.999253354069792,40.0298881530762,1.98323840739422,21.1399998515844,0.000121078535259999,2.01169642506143E-5,0.25,-1.29989333018361E-7,1.07652409334347E-5,-6.7277282280312E-8,67.0195694,67.0195694,99.4112396240234,99.4112396240234,57.281646031833,20.5464892891511,19.871798,0,0,0,40,4374,68.70425,99.4112396240234,,,,,,,,,,,,,0,,,,0.00245,,,,,,67.0195694,,,,
,32311557.945,70.0165787,99.4112396240234,1.08095398280705E-5,3.46995881274097E-7,1,0.999253354069792,40.0298881530762,1.99454321096804,21.0999995470047,0.000122238384181608,2.34526785584046E-5,0.25,1.42225910114256E-7,1.08561608337925E-5,2.02634683056245E-7,70.0165787,70.0165787,99.4112396240234,99.4112396240234,57.0002597649099,20.5405474808108,20.251448,0,0,0,40,4374,71.73425,99.4112396240234,,,,,,,,,,,,,0,,,,0.00245,,,,,,70.0165787,,,,
,32311700.845,73.5341339,99.4112396240234,1.06861694075715E-5,2.96430747486266E-7,1,0.999253354069792,40.0298881530762,1.99449119074178,21.0999995470047,0.000121754980507515,1.8304345614759E-5,0.25,-2.86046705570939E-7,1.07384939347162E-5,-2.32776170366727E-7,73.5341339,73.5341339,99.4112396240234,99.4112396240234,57.2503808910638,20.5411659281607,20.631098,0,0,0,40,4374,75.3531,99.4112396240234,,,,,,,,,,,,,0,,,,-0.00245,,,,,,73.5341339,,,,
,32311843.03,77.0371552,99.4112396240234,1.06560666342882E-5,3.57118390786203E-7,1,0.999253354069792,40.0298881530762,1.99440097739345,21.0999995470047,0.000120898435772739,2.13056567543759E-5,0.25,-1.23740316314644E-8,1.070984887813E-5,3.79473537352212E-8,77.0371552,77.0371552,99.4112396240234,99.4112396240234,57.2550706621791,20.5408570178306,21.01075,0,0,0,40,4374,78.9357,99.4112396240234,,,,,,,,,,,,,0,,,,0.00245,,,,,,77.0371552,,,,
,32311965.705,80.0255814,99.4112396240234,1.07178747119991E-5,3.16737584165913E-7,1,0.999253354069792,40.0298881530762,1.98327428974223,21.0900008678436,0.000121339167269098,1.92596945593761E-5,0.25,-1.91624437909641E-7,1.07747945834246E-5,-1.45258753010057E-7,80.0255814,80.0255814,99.4112396240234,99.4112396240234,57.4129596230638,20.5447804135554,21.01075,0,0,0,40,4374,82.0701,99.4112396240234,,,,,,,,,,,,,0,,,,0,,,,,,80.0255814,,,,
,32312105.625,83.5489273,99.4112396240234,1.07653266818672E-5,2.8125202204615E-7,1,0.999253354069792,40.0298881530762,1.9835389822604,21.0900008678436,0.00012254014631559,1.57872969309165E-5,0.25,-5.04709597486538E-7,1.08254222510655E-5,-4.63237801024666E-7,83.5489273,83.5489273,99.4112396240234,99.4112396240234,57.3050948874099,20.5455867550821,21.3904,0,0,0,40,4374,85.5768,99.4112396240234,,,,,,,,,,,,,0,,,,0.0049,,,,,,83.5489273,,,,
,32312248.575,87.1031799,99.4112396240234,1.05411809472163E-5,3.26616840462565E-7,1,0.999253354069792,40.0298881530762,1.9830949623387,21.0900008678436,0.000119403536248663,1.86970144057885E-5,0.25,-2.04122282214224E-7,1.06000179026197E-5,-1.650342762044E-7,87.1031799,87.1031799,99.4112396240234,99.4112396240234,57.3394865422561,20.5494551132705,21.01075,0,0,0,40,4374,89.17285,99.4112396240234,,,,,,,,,,,,,0,,,,-0.0049,,,,,,87.1031799,,,,
,32312387.845,90.5275726,99.4112396240234,1.06608978695245E-5,3.79198200159304E-7,1,0.999253354069792,40.0298881530762,1.99448547523394,21.0500005632639,0.000121896670582766,1.63714187710713E-5,0.25,-4.36571506050931E-7,1.07220271816185E-5,-4.01047634452395E-7,90.5275726,90.5275726,99.4112396240234,99.4112396240234,56.9142806277945,20.5398981179698,21.770052,0,0,0,40,4374,92.67545,99.4112396240234,,,,,,,,,,,,,0,,,,0.00245,,,,,,90.5275726,,,,
,32312527.565,94.0619278,99.4112396240234,1.08564738240752E-5,3.33129146021264E-7,1,0.999253354069792,40.0298881530762,1.99452671004058,21.0500005632639,0.000123759586597146,1.88360169013601E-5,0.25,-2.51575152940879E-7,1.0918526488881E-5,-2.16806412862162E-7,94.0619278,94.0619278,99.4112396240234,99.4112396240234,57.0330881627176,20.5407854298512,21.770052,0,0,0,40,4374,96.17415,99.4112396240234,,,,,,,,,,,,,0,,,,0,,,,,,94.0619278,,,,
,32312670.445,97.6229019,99.4112396240234,1.08088382066009E-5,3.34970438549338E-7,1,0.999253354069792,40.0298881530762,1.99450663581654,21.0500005632639,0.000122693886465644,2.17372185311108E-5,0.25,1.45669056908584E-8,1.08700585582416E-5,4.84083134997085E-8,97.6229019,97.6229019,99.4112396240234,99.4112396240234,57.4418798782753,20.5437260008221,21.3904,0,0,0,40,4374,99.76605,99.4112396240234,,,,,,,,,,,,,0,,,,-0.0049,,,,,,97.6229019,,,,
,32312809.115,101.0171509,99.4112396240234,1.0775728499419E-5,3.17425823101834E-7,1,0.999253354069792,40.0298881530762,1.9945275357433,21.0200008004904,0.000122921336099008,1.82501023960449E-5,0.25,-2.84801528915878E-7,1.08377689607389E-5,-2.54738852199887E-7,101.0171509,101.0171509,99.4112396240234,99.4112396240234,57.1268835850253,20.540516897962,21.770052,0,0,0,40,4374,103.2489,99.4112396240234,,,,,,,,,,,,,0,,,,0,,,,,,101.0171509,,,,
,32312948.96,104.5063705,99.4112396240234,1.07938595221282E-5,2.94775909778241E-7,1,0.999253354069792,40.0298881530762,1.99427231781877,21.0200008004904,0.000123064108916241,1.85511340764298E-5,0.25,-2.59463379868323E-7,1.08558345440498E-5,-2.31006807282799E-7,104.5063705,104.5063705,99.4112396240234,99.4112396240234,57.5231692442753,20.5430174458875,22.149702,0,0,0,40,4374,106.7704,99.4112396240234,,,,,,,,,,,,,0,,,,0,,,,,,104.5063705,,,,
,32313089.08,108.0060272,99.4112396240234,1.03358034619701E-5,3.94604586984854E-7,1,0.999253354069792,40.0298881530762,1.99451974849382,21.0200008004904,0.000117620741602257,1.9091375706226E-5,0.25,-1.30138039715543E-7,1.03946193468185E-5,-1.03780694623096E-7,108.0060272,108.0060272,99.4112396240234,99.4112396240234,56.709493955756,20.5407104260809,22.149702,0,0,0,40,4374,110.30145,99.4112396240234,,,,,,,,,,,,,0,,,,-0.00245,,,,,,108.0060272,,,,
,32313210.305,111.0074615,99.4112396240234,1.07134989848443E-5,3.63605661516544E-7,1,0.999253354069792,40.0298881530762,1.99465156037372,20.9800004959106,0.000121829296553992,2.03277127542838E-5,0.25,-8.62541152466882E-8,1.07740742766347E-5,-5.9930959566983E-8,111.0074615,111.0074615,99.4112396240234,99.4112396240234,57.4942489890638,20.5396117035898,22.529354,0,0,0,40,4374,113.3441,99.4112396240234,,,,,,,,,,,,,0,,,,0,,,,,,111.0074615,,,,
,32313352.815,114.5401535,99.4112396240234,1.06595842777217E-5,2.84716017911668E-7,1,0.999253354069792,40.0298881530762,1.99449400920099,20.9800004959106,0.000121787225757274,1.68820419929483E-5,0.25,-3.78714839349858E-7,1.07201503018792E-5,-3.55525505031139E-7,114.5401535,114.5401535,99.4112396240234,99.4112396240234,57.4676736194099,20.5411575321763,22.909004,0,0,0,40,4374,116.93025,99.4112396240234,,,,,,,,,,,,,0,,,,0,,,,,,114.5401535,,,,
,32313492.34,118.0183258,99.4112396240234,1.02675978978136E-5,3.61214855169441E-7,1,0.999253354069792,40.0298881530762,1.99446360691385,20.9800004959106,0.000117469968362893,1.52961256705351E-5,0.25,-4.48536739437504E-7,1.03256301001637E-5,-4.27817826737289E-7,117.9927902,118.0438614,99.4112396240234,99.4112396240234,57.2214606358522,20.5404077790563,22.909004,0,0,0,40,4374,120.4345,99.4112396240234,,,,,,,,,,,,,0,,,,-0.0049,,,,,,118.0183258,,,,
,32313611.64,121.0013123,99.4112396240234,1.05248087133343E-5,3.58484081085949E-7,1,0.999253354069792,40.0298881530762,1.99461307410053,20.9299996495247,0.000119640050697441,2.01163745817688E-5,0.25,-6.80955034198793E-8,1.0582945195273E-5,-4.56215331273846E-8,121.0013123,121.0013123,99.4112396240234,99.4112396240234,56.9986965078714,20.5394719129381,23.288654,0,0,0,40,4374,123.4331,99.4112396240234,,,,,,,,,,,,,0,,,,-0.0049,,,,,,121.0013123,,,,
,32313754.315,124.544693,99.4112396240234,1.06355399114505E-5,3.2562998693819E-7,1,0.999253354069792,40.0298881530762,1.99456607051392,20.9299996495247,0.000120749529529552,2.11251245377559E-5,0.25,2.57761274260554E-9,1.06935238172668E-5,2.46341510823576E-8,124.544693,124.544693,99.4112396240234,99.4112396240234,57.0768593597945,20.5386009944333,23.288654,0,0,0,40,4374,127.0174,99.4112396240234,,,,,,,,,,,,,0,,,,0.0049,,,,,,124.544693,,,,
,32313894.415,128.02149585,99.4112396240234,1.03596714179064E-5,3.96179731990508E-7,1,0.999253354069792,40.0298881530762,1.99447986685696,20.9299996495247,0.000117494473603862,2.12103391780073E-5,0.25,5.93796902947009E-8,1.0415399769743E-5,8.02529315021292E-8,127.9945145,128.0484772,99.4112396240234,99.4112396240234,56.9447641400445,20.5398487725814,22.909004,0,0,0,40,4374,130.5366,99.4112396240234,,,,,,,,,,,,,0,,,,-0.00245,,,,,,128.02149585,,,,
,32314014.295,131.0185089,99.4112396240234,1.05574463213699E-5,3.41889459987953E-7,1,0.999253354069792,40.0298881530762,1.99465306669988,20.889999344945,0.000120436324802826,1.7630216255409E-5,0.25,-2.89806669898862E-7,1.061430915447E-5,-2.71144669633152E-7,131.0185089,131.0185089,99.4112396240234,99.4112396240234,56.9916618511983,20.5342513092173,22.909004,0,0,0,40,4374,133.5388,99.4112396240234,,,,,,,,,,,,,0,,,,0,,,,,,131.0185089,,,,
,32314155.445,134.5030518,99.4112396240234,1.05767370763949E-5,3.42483953062965E-7,1,0.999253354069792,40.0298881530762,1.99470199532793,20.889999344945,0.000119887817820316,2.20333182371521E-5,0.25,9.55437807674475E-8,1.06322293323126E-5,1.15482529932843E-7,134.5030518,134.5030518,99.4112396240234,99.4112396240234,57.4199942797368,20.5366756901816,23.668306,0,0,0,40,4374,137.0832,99.4112396240234,,,,,,,,,,,,,0,,,,-0.0049,,,,,,134.5030518,,,,
,32314295.19,138.010498,99.4112396240234,1.05822677261898E-5,3.43654415418123E-7,1,0.999253354069792,40.0298881530762,1.99477695163159,20.889999344945,0.000119862089021884,2.25247088449933E-5,0.25,1.38671912030487E-7,1.06369256806842E-5,1.58097732570306E-7,138.010498,138.010498,99.4112396240234,99.4112396240234,57.3113479155637,20.5381672198677,23.668306,0,0,0,40,4374,140.59235,99.4112396240234,,,,,,,,,,,,,0,,,,0,,,,,,138.010498,,,,
,32314417.53,141.0726318,99.4112396240234,1.06577679838578E-5,3.10383778995201E-7,1,0.999253354069792,40.0298881530762,1.98333561391602,20.8400003612041,0.000121467415079471,1.44168894452171E-5,0.25,-5.80986758330239E-7,1.0713327232701E-5,-5.657254937811E-7,141.0726318,141.0726318,99.4112396240234,99.4112396240234,56.8611298884868,20.5453172413895,22.909004,0,0,0,40,4374,143.6511,99.4112396240234,,,,,,,,,,,,,0,,,,-0.00245,,,,,,141.0726318,,,,
,32314557.805,144.5339355,99.4112396240234,1.07062750852408E-5,3.12785934222311E-7,1,0.999253354069792,40.0298881530762,1.98340085503859,20.8400003612041,0.000121653071127115,1.655257566219E-5,0.25,-3.99548579318252E-7,1.07608901911002E-5,-3.83897673649288E-7,144.5339355,144.5339355,99.4112396240234,99.4112396240234,56.9056827140829,20.5464993420063,23.288654,0,0,0,40,4374,147.1904,99.4112396240234,,,,,,,,,,,,,0,,,,0,,,,,,144.5339355,,,,
,32314698.06,148.0262146,99.4112396240234,1.10722534329123E-5,2.6199663523494E-7,1,0.999253354069792,40.0298881530762,1.98320799697984,20.8400003612041,0.000125492912079358,1.88156327179098E-5,0.25,-2.6195005891177E-7,1.11275402989529E-5,-2.45604965552502E-7,148.0262146,148.0262146,99.4112396240234,99.4112396240234,57.3394865422561,20.5435268272464,23.668306,0,0,0,40,4374,150.70915,99.4112396240234,,,,,,,,,,,,,0,,,,0.0049,,,,,,148.0262146,,,,
,32314838.235,151.5566711,99.4112396240234,1.01708628880481E-5,3.97391074656237E-7,1,0.999253354069792,40.0298881530762,1.99473376751295,20.8000000566244,0.000115925380479478,1.726648968061E-5,0.25,-2.4994071494497E-7,1.02207555188842E-5,-2.35482803623382E-7,151.5566711,151.5566711,99.4112396240234,99.4112396240234,57.1761261817368,20.5370523140895,23.668306,0,0,0,40,4374,154.211,99.4112396240234,,,,,,,,,,,,,0,,,,-0.0049,,,,,,151.5566711,,,,
,32314976.345,155.0041351,99.4112396240234,1.08035501256357E-5,2.85144508640178E-7,1,0.999253354069792,40.0298881530762,1.99484646454878,20.8000000566244,0.000123397895567023,1.6814325723831E-5,0.25,-3.99395750756391E-7,1.08557790229031E-5,-3.85177661985508E-7,155.0041351,155.0041351,99.4112396240234,99.4112396240234,57.566158812833,20.5344978730389,23.288654,0,0,0,40,4374,157.677,99.4112396240234,,,,,,,,,,,,,0,,,,0.0049,,,,,,155.0041351,,,,
,32315119.07,158.5526123,99.4112396240234,1.05552702513205E-5,3.45021047649191E-7,1,0.999253354069792,40.0298881530762,1.99457915293359,20.8000000566244,0.000119760509759638,2.08750491973047E-5,0.25,2.53389989389575E-9,1.0604727262235E-5,1.78090471540264E-8,158.5526123,158.5526123,99.4112396240234,99.4112396240234,57.1300100991022,20.5377690627354,23.668306,0,0,0,40,4374,161.2556,99.4112396240234,,,,,,,,,,,,,0,,,,0,,,,,,158.5526123,,,,
,32315259.825,162.0477753,99.4112396240234,1.03602163600332E-5,3.44965485234715E-7,1,0.999253354069792,40.0298881530762,1.98328766806341,20.7499992102385,0.000117282077894012,1.8186163338208E-5,0.25,-1.91187092363245E-7,1.04080546884819E-5,-1.77528672970329E-7,162.0477753,162.0477753,99.4112396240234,99.4112396240234,57.0565370182945,20.5440747056451,23.668306,0,0,0,40,4374,164.76945,99.4112396240234,,,,,,,,,,,,,0,,,,0,,,,,,162.0477753,,,,
,32315399.545,165.5270538,99.4112396240234,1.03154197455923E-5,3.44665708506541E-7,1,0.999253354069792,40.0298881530762,1.9832794020115,20.7499992102385,0.000117632893434879,1.31070409830261E-5,0.25,-6.32969937688603E-7,1.03626572676421E-5,-6.21756802906186E-7,165.5270538,165.5270538,99.4112396240234,99.4112396240234,57.2847725459099,20.5460674656476,24.427608,0,0,0,40,4374,168.2725,99.4112396240234,,,,,,,,,,,,,0,,,,-0.0049,,,,,,165.5270538,,,,
,32315538.525,169.0273438,99.4112396240234,1.03795653772823E-5,3.68509991591027E-7,1,0.999253354069792,40.0298881530762,1.98327847795396,20.7499992102385,0.000116730887790656,2.25099032437073E-5,0.25,1.89806959668979E-7,1.04249537188397E-5,2.04398310949205E-7,169.0273438,169.0273438,99.4112396240234,99.4112396240234,57.3035316303714,20.5479292719079,24.047956,0,0,0,40,4374,171.7474,99.4112396240234,,,,,,,,,,,,,0,,,,0.0049,,,,,,169.0273438,,,,
,32315677.42,172.5162506,99.4112396240234,1.08046958882055E-5,3.8149533684675E-7,1,0.999253354069792,40.0298881530762,1.99454173345569,20.7000002264977,0.000123054323268714,1.84068938756625E-5,0.25,-2.56070389968989E-7,1.08514536661029E-5,-2.43231467980251E-7,172.5162506,172.5162506,99.4112396240234,99.4112396240234,57.3762230826599,20.540395165163,24.427608,0,0,0,40,4374,175.2108,99.4112396240234,,,,,,,,,,,,,0,,,,0,,,,,,172.5162506,,,,
,32315820.145,176.0467224,99.4112396240234,1.05815355714184E-5,4.17807495774763E-7,1,0.999253354069792,40.0298881530762,1.99426357504855,20.7000002264977,0.000120403481646963,1.84870368221664E-5,0.25,-2.09450663335641E-7,1.06261773952527E-5,-1.97041438397629E-7,176.0467224,176.0467224,99.4112396240234,99.4112396240234,56.8970848003714,20.5451579616186,24.047956,0,0,0,40,4374,178.7887,99.4112396240234,,,,,,,,,,,,,0,,,,-0.00245,,,,,,176.0467224,,,,
,32315958.245,179.5234985,99.4112396240234,1.08582968832781E-5,4.51391991242538E-7,1,0.999253354069792,40.0298881530762,1.99439749743118,20.7000002264977,0.000123458811374309,1.94816948166653E-5,0.25,-1.69449012266223E-7,1.09029234515222E-5,-1.56847743030408E-7,179.5234985,179.5234985,99.4112396240234,99.4112396240234,57.0065127930637,20.5431765912057,24.807261,0,0,0,40,4374,182.24415,99.4112396240234,,,,,,,,,,,,,0,,,,0,,,,,,179.5234985,,,,
,32316077.865,182.5069733,99.4112396240234,1.09242236002362E-5,3.66450722639484E-7,1,0.999253354069792,40.0298881530762,1.98326679327019,20.6400007009506,0.00012259498351541,2.49036151285343E-5,0.25,3.0949244400053E-7,1.09675611781798E-5,3.23822637885482E-7,182.5069733,182.5069733,99.4112396240234,99.4112396240234,57.0471574760637,20.5425243378158,24.807261,0,0,0,40,4374,185.2466,99.4112396240234,,,,,,,,,,,,,0,,,,0,,,,,,182.5069733,,,,
,32316217.445,186.0039063,99.4112396240234,1.08368056045415E-5,3.57243306917158E-7,1,0.999253354069792,40.0298881530762,1.98324571641004,20.6400007009506,0.000122409632577118,2.00418510052098E-5,0.25,-1.05887951383875E-7,1.08791328328439E-5,-9.36242698779947E-8,186.0039063,186.0039063,99.4112396240234,99.4112396240234,57.0588819038522,20.5456690498938,24.427608,0,0,0,40,4374,188.73715,99.4112396240234,,,,,,,,,,,,,0,,,,-0.0049,,,,,,186.0039063,,,,
,32316360.785,189.5661774,99.4112396240234,1.0568887025675E-5,3.7315553551453E-7,1,0.999253354069792,40.0298881530762,1.98326368413887,20.6400007009506,0.000119598461313251,1.82364358004066E-5,0.25,-2.18974715179984E-7,1.06091341189186E-5,-2.07737055273162E-7,189.5661774,189.5661774,99.4112396240234,99.4112396240234,57.1690915250637,20.546151227134,24.047956,0,0,0,40,4374,192.32835,99.4112396240234,,,,,,,,,,,,,0,,,,-0.00245,,,,,,189.5661774,,,,
touchdown = 15.3500000014901 mm,32316494.575,192.8824921,99.4112396240234,1.08036501762204E-5,3.2070534662012E-7,1,0.999253354069792,40.0298881530762,2.00732973714338,20.5899998545647,0.000123668814674573,1.87924561253596E-5,0.25,-2.29090984460089E-7,1.08436715224245E-5,-2.17870269261675E-7,192.8824921,192.8824921,99.4112396240234,99.4112396240234,57.0995265868522,20.5312738531304,25.186911,0,0,0,40,4374,195.6978,99.4112396240234,,,,,,,,,,,,,0,,,,0.00245,,,,,,192.8824921,,,,
,32316621.265,196.0362244,99.4112396240234,1.06892376064351E-5,3.41820553580467E-7,1,0.999253354069792,40.0298881530762,2.00718333431227,20.5899998545647,0.000122247976514519,1.91109501756264E-5,0.25,-1.80766083917525E-7,1.07277141335674E-5,-1.69718350215615E-7,196.0362244,196.0362244,99.4112396240234,99.4112396240234,57.4911224749868,20.5364436620346,24.807261,0,0,0,40,4374,198.8746,99.4112396240234,,,,,,,,,,,,,0,,,,-0.0049,,,,,,196.0362244,,,,
,32316759.975,199.507019,99.4112396240234,1.06940239966768E-5,3.33396068311816E-7,1,0.999253354069792,40.0298881530762,2.00706838095623,20.5899998545647,0.00012304397142359,1.47317303810642E-5,0.25,-5.65170879825364E-7,1.07317390580577E-5,-5.55684174764291E-7,199.507019,199.507019,99.4112396240234,99.4112396240234,57.4059249663907,20.5382380710138,24.807261,0,0,0,40,4374,202.3498,99.4112396240234,,,,,,,,,,,,,0,,,,0,,,,,,199.507019,,,,
touchdown = 15.3000000864267 mm,32316911.06,203.2722473,99.4112396240234,1.02496457186888E-5,3.53810859688441E-7,1,0.999253354069792,40.0298881530762,1.99461172534109,20.5400008708239,0.000116893227164861,1.59055647385392E-5,0.25,-3.76303166470889E-7,1.02843612849847E-5,-3.66842765320884E-7,203.2722473,203.2722473,99.4112396240234,99.4112396240234,57.0815491309099,20.5342829204166,24.427608,0,0,0,40,4374,206.1423,99.4112396240234,,,,,,,,,,,,,0,,,,0,,,,,,203.2722473,,,,
,32317043.22,206.5724487,99.4112396240234,1.06827662119418E-5,3.93729958758801E-7,1,0.999253354069792,40.0298881530762,1.99478199375503,20.5400008708239,0.000121807195810992,1.6706074712586E-5,0.25,-3.80619438253566E-7,1.0717779214856E-5,-3.70898048408791E-7,206.5724487,206.5724487,99.4112396240234,99.4112396240234,56.8267382336406,20.5332243877057,25.186911,0,0,0,40,4374,209.44585,99.4112396240234,,,,,,,,,,,,,0,,,,0,,,,,,206.5724487,,,,
,32317182.005,210.0502472,99.4112396240234,1.03445045351644E-5,3.98577499279103E-7,1,0.999253354069792,40.0298881530762,1.9946029343952,20.5400008708239,0.000117611372100544,1.79896934403342E-5,0.25,-2.08084875732272E-7,1.03770564890747E-5,-1.98341013579965E-7,210.0502472,210.0502472,99.4112396240234,99.4112396240234,56.7939098358329,20.5365861540225,24.807261,0,0,0,40,4374,212.92235,99.4112396240234,,,,,,,,,,,,,0,,,,0,,,,,,210.0502472,,,,
touchdown = 15.2399996295571 mm,32317327.245,213.6460876,99.4112396240234,1.03979128620192E-5,3.63331132519797E-7,1,0.999253354069792,40.0298881530762,2.00728897125639,20.4799994826317,0.00011916595309066,1.67831266488084E-5,0.25,-3.32395304362891E-7,1.04295095598476E-5,-3.23162185613922E-7,213.6460876,213.6460876,99.4112396240234,99.4112396240234,57.1886322380445,20.5280598288812,25.186911,0,0,0,40,4374,216.5603,99.4112396240234,,,,,,,,,,,,,0,,,,0,,,,,,213.6460876,,,,
,32317462.585,217.0563812,99.4112396240234,1.04679798269581E-5,4.33315259735542E-7,1,0.999253354069792,40.0298881530762,2.00724469966995,20.4799994826317,0.000119737730878394,1.81325733065773E-5,0.25,-2.25750425291927E-7,1.04984839469361E-5,-2.16295687244905E-7,217.0563812,217.0563812,99.4112396240234,99.4112396240234,57.2581971762561,20.5311182772626,25.186911,0,0,0,40,4374,219.9457,99.4112396240234,,,,,,,,,,,,,0,,,,0,,,,,,217.0563812,,,,
,32317603.335,220.5578003,99.4112396240234,1.03391843762538E-5,3.61288921795092E-7,1,0.999253354069792,40.0298881530762,2.00705407729491,20.4799994826317,0.000118584128932197,1.59219215368025E-5,0.25,-3.96901329931479E-7,1.03682542341345E-5,-3.88211046951612E-7,220.5578003,220.5578003,99.4112396240234,99.4112396240234,57.2652318329291,20.5314337546321,25.186911,0,0,0,40,4374,223.4706,99.4112396240234,,,,,,,,,,,,,0,,,,0,,,,,,220.5578003,,,,
touchdown = 15.1899997144938 mm,32317743.225,224.0308533,99.4112396240234,1.13475532246529E-5,3.34954047891223E-7,1,0.999253354069792,40.0298881530762,2.00711535099358,20.4199999570847,0.000128978278981077,2.41557778774044E-5,0.25,1.51164873856959E-7,1.13775684664468E-5,1.62111632547288E-7,224.0308533,224.0308533,99.4112396240234,99.4112396240234,56.9502355396791,20.5278662290457,25.186911,0,0,0,40,4374,226.9815,99.4112396240234,,,,,,,,,,,,,0,,,,-0.0049,,,,,,224.0308533,,,,
,32317883.87,227.5589905,99.4112396240234,1.04859212748018E-5,3.44368089046359E-7,1,0.999253354069792,40.0298881530762,2.00745788574576,20.4199999570847,0.000119772722137547,1.89637389868836E-5,0.25,-1.54948306188325E-7,1.05126652896356E-5,-1.457771794845E-7,227.5589905,227.5589905,99.4112396240234,99.4112396240234,57.0307432771599,20.5310866773656,25.946213,0,0,0,40,4374,230.50175,99.4112396240234,,,,,,,,,,,,,0,,,,0.00245,,,,,,227.5589905,,,,
,32318024.48,231.0653687,99.4112396240234,1.03616546825741E-5,3.69219481277918E-7,1,0.999253354069792,40.0298881530762,2.00717471941232,20.4199999570847,0.000118451924654808,1.79919941262934E-5,0.25,-2.18106465365941E-7,1.0386889440523E-5,-2.09354093635398E-7,231.0653687,231.0653687,99.4112396240234,99.4112396240234,57.1339182416984,20.532673081495,25.186911,0,0,0,40,4374,234.01735,99.4112396240234,,,,,,,,,,,,,0,,,,0.00245,,,,,,231.0653687,,,,
touchdown = 15.1399997994304 mm,32318159.22,234.4060516,99.4112396240234,1.06791018084447E-5,3.72846414712209E-7,1,0.999253354069792,40.0298881530762,1.99473123892337,20.3799996525049,0.000121286822795717,1.87647322570898E-5,0.25,-1.95180914422797E-7,1.07038482725526E-5,-1.86231077589746E-7,234.4060516,234.4060516,99.4112396240234,99.4112396240234,57.1933220091599,20.5284138568674,25.186911,0,0,0,40,4374,237.4101,99.4112396240234,,,,,,,,,,,,,0,,,,-0.0049,,,,,,234.4060516,,,,
,32318283.325,237.5073395,99.4112396240234,1.05325045420519E-5,3.97509023109934E-7,1,0.999253354069792,40.0298881530762,1.9948835971837,20.3799996525049,0.000119676677028722,1.81665334318255E-5,0.25,-2.22387648547995E-7,1.05558010569387E-5,-2.1374977450105E-7,237.5073395,237.5073395,99.4112396240234,99.4112396240234,57.3652802833907,20.530248513648,25.566563,0,0,0,40,4374,240.5188,99.4112396240234,,,,,,,,,,,,,0,,,,-0.0049,,,,,,237.5073395,,,,
,32318425.49,241.0276489,99.4112396240234,1.04812996559547E-5,4.0458568227336E-7,1,0.999253354069792,40.0298881530762,1.99472043476694,20.3799996525049,0.000119404062868138,1.61540285272905E-5,0.25,-3.90825677726589E-7,1.05033378324112E-5,-3.82712805003923E-7,241.0276489,241.0276489,99.4112396240234,99.4112396240234,57.3285437429868,20.5323107417827,25.566563,0,0,0,40,4374,244.0747,99.4112396240234,,,,,,,,,,,,,0,,,,-0.0049,,,,,,241.0276489,,,,
,32318562.44,244.4444275,99.4112396240234,,,2,,,,20.3300002738833,,,,,,,244.4444275,244.4444275,99.4112396240234,99.4112396240234,,,25.946213,,,,-99999999,4374,247.5123,99.4112396240234,,,,,,,,,,,,,,,,,,,,,,,244.4444275,,,,
,32318685.53,247.5176544,99.4112396240234,1.01783263476955E-5,4.22292686451249E-7,1,0.999253354069792,40.0298881530762,1.98338330854312,20.3200001269579,0.000115729688952501,1.31025389283054E-5,0.25,-6.01013626603595E-7,1.01975834838419E-5,-5.93727976963498E-7,247.5176544,247.5176544,99.4112396240234,99.4112396240234,57.3691884259868,20.5388855425214,25.946213,0,0,0,40,4374,250.60195,99.4112396240234,,,,,,,,,,,,,0,,,,0,,,,,,247.5176544,,,,
,32318827.07,251.0495148,99.4112396240234,1.000619634705E-5,3.81858902280299E-7,1,0.999253354069792,40.0298881530762,1.98334019265776,20.3200001269579,0.00011286639812859,1.80087578993328E-5,0.25,-1.34875889892148E-7,1.00235039331152E-5,-1.26994676778505E-7,251.0495148,251.0495148,99.4112396240234,99.4112396240234,57.2472543769868,20.5406062531478,25.566563,0,0,0,40,4374,254.1537,99.4112396240234,,,,,,,,,,,,,0,,,,-0.0049,,,,,,251.0495148,,,,
,32318979.97,254.8961945,99.4112396240234,,,2,,,,20.28000035882,,,,,,,254.8961945,254.8961945,99.4112396240234,99.4112396240234,,,25.946213,,,,-99999999,4374,257.9887,99.4112396240234,,,,,,,,,,,,,,,,,,,,,,,254.8961945,,,,
,32319107.6,258.0551453,99.4112396240234,1.02155995753115E-5,4.4072465342028E-7,1,0.999253354069792,40.0298881530762,1.99458986500924,20.2699992805719,0.000115420390675015,2.08067138208482E-5,0.25,6.82051478778003E-8,1.02305689632738E-5,7.63213212376476E-8,258.0551453,258.0551453,99.4112396240234,99.4112396240234,57.3770047111791,20.5325380396172,25.566563,0,0,0,40,4374,261.1694,99.4112396240234,,,,,,,,,,,,,0,,,,0.0049,,,,,,258.0551453,,,,
,32319246.245,261.5276489,99.4112396240234,1.03932675827331E-5,3.66356545092398E-7,1,0.999253354069792,40.0298881530762,1.99461617092448,20.2699992805719,0.000118126618153179,1.70603093814284E-5,0.25,-2.93506384301684E-7,1.04074948956327E-5,-2.85875201480066E-7,261.5276489,261.5276489,99.4112396240234,99.4112396240234,57.3035316303714,20.5357855137417,26.325863,0,0,0,40,4374,264.6446,99.4112396240234,,,,,,,,,,,,,0,,,,0.00245,,,,,,261.5276489,,,,
,32319396.48,265.2352295,99.4112396240234,,,2,,,,20.2300004437566,,,,,,,265.2352295,265.2352295,99.4112396240234,99.4112396240234,,,26.325863,,,,-99999999,4374,268.4101,99.4112396240234,,,,,,,,,,,,,,,,,,,,,,,265.2352295,,,,
,32319528.08,268.5206909,99.4112396240234,1.00524704545954E-5,4.71166094382898E-7,1,0.999253354069792,40.0298881530762,1.98381557803985,20.2200002968311,0.000113084618605765,1.95806611999479E-5,0.25,-1.91187385948119E-9,1.00635060590196E-5,5.60666908307116E-9,268.5206909,268.5206909,99.4112396240234,99.4112396240234,57.0995265868522,20.5323845800073,26.325863,0,0,0,40,4374,271.7186,99.4112396240234,,,,,,,,,,,,,0,,,,0,,,,,,268.5206909,,,,
,32319667.62,272.0054016,99.4112396240234,9.78255241018988E-6,3.39938403056978E-7,1,0.999253354069792,40.0298881530762,1.98366753197343,20.2200002968311,0.00011060921926826,1.56902290144311E-5,0.25,-3.00583525938751E-7,9.79229287290039E-6,-2.93668617817763E-7,272.0054016,272.0054016,99.4112396240234,99.4112396240234,57.1135959001984,20.5336901383459,25.946213,0,0,0,40,4374,275.19685,99.4112396240234,,,,,,,,,,,,,0,,,,0.00245,,,,,,272.0054016,,,,
,32319815.42,275.6586304,99.4112396240234,,,2,,,,20.169999986887,,,,,,,275.6586304,275.6586304,99.4112396240234,99.4112396240234,,,26.705515,,,,-99999999,4374,278.8793,99.4112396240234,,,,,,,,,,,,,,,,,,,,,,,275.6586304,,,,
,32319950.415,279.0493774,99.4112396240234,9.7069087268549E-6,4.75007253425894E-7,1,0.999253354069792,40.0298881530762,1.98375043499983,20.1600007712841,0.000110171430926312,1.30219233367966E-5,0.25,-5.24259668294854E-7,9.71428049504842E-6,-5.17700873372979E-7,279.0493774,279.0493774,99.4112396240234,99.4112396240234,57.0252718775253,20.5384921851636,26.325863,0,0,0,40,4374,282.25515,99.4112396240234,,,,,,,,,,,,,0,,,,0,,,,,,279.0493774,,,,
,32320089.355,282.5142212,99.4112396240234,9.60316990231867E-6,4.49515941504799E-7,1,0.999253354069792,40.0298881530762,1.98345117851109,20.1600007712841,0.00010887278862945,1.34098064205889E-5,0.25,-4.71364947950707E-7,9.60923186209849E-6,-4.64884094446972E-7,282.5142212,282.5142212,99.4112396240234,99.4112396240234,57.3793495967368,20.537718921398,26.325863,0,0,0,40,4374,285.7315,99.4112396240234,,,,,,,,,,,,,0,,,,-0.0049,,,,,,282.5142212,,,,
,32320234.16,286.0939941,99.4112396240234,,,2,,,,20.1200000718236,,,,,,,286.0939941,286.0939941,99.4112396240234,99.4112396240234,,,26.325863,,,,-99999999,4374,289.3944,99.4112396240234,,,,,,,,,,,,,,,,,,,,,,,286.0939941,,,,
,32320371.375,289.5505676,99.4112396240234,9.69673498808749E-6,4.54685980683465E-7,1,0.999253354069792,40.0298881530762,1.98376414470818,20.1099999248981,0.000108604757936987,2.11426419506334E-5,0.25,2.00686176099725E-7,9.69993903482892E-6,2.0738524381766E-7,289.5505676,289.5505676,99.4112396240234,99.4112396240234,57.2370932062368,20.5342590230277,26.705515,0,0,0,40,4374,292.80815,99.4112396240234,,,,,,,,,,,,,0,,,,0,,,,,,289.5505676,,,,
,32320511.9,293.0278015,99.4112396240234,9.19522832099422E-6,4.26758521057869E-7,1,0.999253354069792,40.0298881530762,1.98378068521884,20.1099999248981,0.000103253596610241,1.84438040305516E-5,0.25,4.77669081183396E-8,9.19721992121418E-6,5.39748335911915E-8,293.0278015,293.0278015,99.4112396240234,99.4112396240234,57.271484861083,20.5327270952301,26.705515,0,0,0,40,4374,296.33005,99.4112396240234,,,,,,,,,,,,,0,,,,-0.0049,,,,,,293.0278015,,,,
,32320652.41,296.4957886,99.4112396240234,,,2,,,,20.059999614954,,,,,,,296.4957886,296.4957886,99.4112396240234,99.4112396240234,,,26.705515,,,,-99999999,4374,299.8399,99.4112396240234,,,,,,,,,,,,,,,,,,,,,,,296.4957886,,,,
,32320773.91,299.5586548,99.4112396240234,8.72124342872337E-6,4.5612891280799E-7,1,0.999253354069792,40.0298881530762,1.98380937013596,20.0399998575449,9.81229975291029E-5,1.62581255695859E-5,0.25,-6.41069239428394E-8,8.72116890763523E-6,-5.83799515921481E-8,299.5586548,299.5586548,99.4112396240234,99.4112396240234,56.6930797568522,20.5300013485727,26.705515,0,0,0,40,4374,302.88175,99.4112396240234,,,,,,,,,,,,,0,,,,0,,,,,,299.5586548,,,,
,32320915.825,303.0617676,99.4112396240234,8.7398983786935E-6,4.39988562645047E-7,1,0.999253354069792,40.0298881530762,1.9836652854589,20.0399998575449,9.83501849972852E-5,1.60795363535541E-5,0.25,-8.28755829009475E-8,8.73874313005214E-6,-7.72049167681429E-8,303.0617676,303.0617676,99.4112396240234,99.4112396240234,57.2347483206791,20.5337034119642,26.325863,0,0,0,40,4374,306.435,99.4112396240234,,,,,,,,,,,,,0,,,,0,,,,,,303.0617676,,,,
,32321070.09,306.8614502,99.4112396240234,,,2,,,,20.000000089407,,,,,,,306.8614502,306.8614502,99.4112396240234,99.4112396240234,,,26.705515,,,,-99999999,4374,310.3097,99.4112396240234,,,,,,,,,,,,,,,,,,,,,,,306.8614502,,,,
,32321194.055,310.0098572,99.4112396240234,9.08076349053435E-6,3.62637162314425E-7,1,0.999253354069792,40.0298881530762,1.98385741608035,19.9900008738041,0.000103024790406885,1.17702740990623E-5,0.25,-5.25183692598923E-7,9.07759484433867E-6,-5.19255909134582E-7,310.0098572,310.0098572,99.4112396240234,99.4112396240234,57.0268351345637,20.5286508576824,26.325863,0,0,0,40,4374,313.41355,99.4112396240234,,,,,,,,,,,,,0,,,,0.0049,,,,,,310.0098572,,,,
,32321336.17,313.5074463,99.4112396240234,8.37709262822822E-6,4.968758549156E-7,1,0.999253354069792,40.0298881530762,1.98381916538559,19.9900008738041,9.34926073681551E-5,1.97193937696149E-5,0.25,3.04696216381201E-7,8.37263651702395E-6,3.09753161227629E-7,313.5074463,313.5074463,99.4112396240234,99.4112396240234,57.0917103016599,20.5270259702869,26.325863,0,0,0,40,4374,316.9804,99.4112396240234,,,,,,,,,,,,,0,,,,0.00245,,,,,,313.5074463,,,,
,32321488,317.295929,99.4112396240234,,,2,,,,19.9399996325374,,,,,,,317.295929,317.295929,99.4112396240234,99.4112396240234,,,27.085165,,,,-99999999,4374,320.8028,99.4112396240234,,,,,,,,,,,,,,,,,,,,,,,317.295929,,,,
,32321618.405,320.5242615,99.4112396240234,8.27352308398061E-6,4.1043280703373E-7,1,0.999253354069792,40.0298881530762,1.98376569183994,19.9299994856119,9.38830318030965E-5,1.03970605463778E-5,0.25,-5.07014382384399E-7,8.2675695522354E-6,-5.01612863355572E-7,320.5242615,320.5242615,99.4112396240234,99.4112396240234,56.8001628639868,20.5287237389276,27.464817,0,0,0,40,4374,324.0526,99.4112396240234,,,,,,,,,,,,,0,,,,0,,,,,,320.5242615,,,,
,32321759.29,324.0422058,99.4112396240234,8.72538031996073E-6,3.22734622568551E-7,1,0.999253354069792,40.0298881530762,1.98376092751203,19.9299994856119,9.85105965137148E-5,1.37773660405625E-5,0.25,-2.84003322215089E-7,8.71787075750276E-6,-2.78526716092631E-7,324.0422058,324.0422058,99.4112396240234,99.4112396240234,57.2777378892368,20.5299958768486,27.464817,0,0,0,40,4374,327.5965,99.4112396240234,,,,,,,,,,,,,0,,,,0.00245,,,,,,324.0422058,,,,
,32321904.52,327.6195068,99.4112396240234,,,2,,,,19.8800001069903,,,,,,,327.6195068,327.6195068,99.4112396240234,99.4112396240234,,,27.464817,,,,-99999999,4374,331.2209,99.4112396240234,,,,,,,,,,,,,,,,,,,,,,,327.6195068,,,,
,32322040.59,331.039978,99.4112396240234,8.1552027047152E-6,4.7812504706558E-7,1,0.999253354069792,40.0298881530762,1.98348034908774,19.8699999600649,9.20420878950958E-5,1.28500757383264E-5,0.25,-2.67299106253627E-7,8.14619180021426E-6,-2.62228372815657E-7,331.039978,331.039978,99.4112396240234,99.4112396240234,56.9134989992753,20.530622539699,26.705515,0,0,0,40,4374,334.63555,99.4112396240234,,,,,,,,,,,,,0,,,,-0.0049,,,,,,331.039978,,,,
,32322181.645,334.5545959,99.4112396240234,7.76029519379288E-6,4.82473512914657E-7,1,0.999253354069792,40.0298881530762,1.98352642022507,19.8699999600649,8.89700583503545E-5,4.17823028770665E-6,0.25,-9.71532574728039E-7,7.75118943388928E-6,-9.65834426334269E-7,334.5545959,334.5545959,99.4112396240234,99.4112396240234,57.1503324406022,20.531525102978,26.705515,0,0,0,40,4374,338.1413,99.4112396240234,,,,,,,,,,,,,0,,,,-0.00245,,,,,,334.5545959,,,,
,32322324.11,338.0716553,99.4112396240234,,,2,,,,19.830000191927,,,,,,,338.0716553,338.0716553,99.4112396240234,99.4112396240234,,,27.085165,,,,-99999999,4374,341.7269,99.4112396240234,,,,,,,,,,,,,,,,,,,,,,,338.0716553,,,,
,32322441.93,341.0041809,99.4112396240234,7.66611543304837E-6,4.62866022849295E-7,1,0.999253354069792,40.0298881530762,1.99463620987529,19.8199991136789,8.70671041734007E-5,1.15030621705518E-5,0.25,-3.07610200462091E-7,7.65504045159303E-6,-3.02815178391088E-7,341.0041809,341.0041809,99.4112396240234,99.4112396240234,56.6954246424098,20.5256058676482,27.085165,0,0,0,40,4374,344.7043,99.4112396240234,,,,,,,,,,,,,0,,,,0,,,,,,341.0041809,,,,
,32322583.195,344.52340695,99.4112396240234,7.40241335460815E-6,4.03807790659708E-7,1,0.999253354069792,40.0298881530762,1.99447909685115,19.8199991136789,8.38460120578099E-5,1.2316155071841E-5,0.25,-1.89601412876608E-7,7.39076934075437E-6,-1.85150051067849E-7,344.4967651,344.5500488,99.4112396240234,99.4112396240234,56.8157954343714,20.5293434565089,27.085165,0,0,0,40,4374,348.2382,99.4112396240234,,,,,,,,,,,,,0,,,,-0.00245,,,,,,344.52340695,,,,
,32322723.055,348.0023499,99.4112396240234,7.19119905441517E-6,3.44782377937268E-7,1,0.999253354069792,40.0298881530762,1.99489624567922,19.8199991136789,8.19553829189055E-5,9.10615589513711E-6,0.25,-4.37708459160066E-7,7.17917943313871E-6,-4.32970356482534E-7,348.0023499,348.0023499,99.4112396240234,99.4112396240234,56.9322580837368,20.5272644465211,27.464817,0,0,0,40,4374,351.7411,99.4112396240234,,,,,,,,,,,,,0,,,,0,,,,,,348.0023499,,,,
,32323086.39,349.7850952,99.4112396240234,7.42680615952247E-6,4.3240182307295E-7,1,0.999253354069792,40.0298881530762,2.00659944421049,19.7599995881319,8.54720255302692E-5,7.36051136462749E-6,0.25,-6.36894049262638E-7,7.41404754236882E-6,-6.31636748188604E-7,349.7850952,349.7850952,99.4112396240234,99.4112396240234,56.9854088230445,20.5319919031766,27.085165,0,0,0,40,4369,350.8265,99.4112396240234,,,,,,,,,,,,,0,,,,0,,,,,,349.7850952,,,,