File: data/monolayers/magneticStructure/ML_Ac_CoFe_C/PPMS/data/DD205_4_KOELNPPMS_HYST_100OE_100K.DAT
[Header]
; VSM Data File (default extension .dat)
; Copyright (c) 2003-2013, Quantum Design, Inc. All rights reserved.
TITLE,
FILEOPENTIME,19717821.41,08/17/2018,5:08 am
BYAPP,VSM,2.0,2.0
INFO,PPMS VSM Option Release 1.4.10 Build 1,APPNAME
INFO,Quantum Design Linear Motor Servo Controller,MOTOR_MODULE_NAME
INFO,3101-100 M1,MOTOR_HW_VERSION
INFO,MMC1014,MOTOR_SERIAL_NUMBER
INFO,SRV No X-over 01.03.11,MOTOR_SOFTWARE_VERSION
INFO,Quantum Design VSM Detection Module,VSM_MODULE_NAME
INFO,3101-150 F0,VSM_HW_VERSION
INFO,VSM707,VSM_SERIAL_NUMBER
INFO,VSM No X-over 01.02.05 May 20 2008 13:51:47,VSM_SOFTWARE_VERSION
INFO,704,PREAMP_SERIAL_NUMBER
INFO,822,COIL_SERIAL_NUMBER
INFO,0,MOMENT_UNITS
INFO,,SAMPLE_MATERIAL
INFO,,SAMPLE_COMMENT
INFO,,SAMPLE_MASS
INFO,,SAMPLE_VOLUME
INFO,,SAMPLE_MOLECULAR_WEIGHT
INFO,,SAMPLE_SIZE
INFO,,SAMPLE_SHAPE
DATATYPE,COMMENT,1
DATATYPE,TIME,2
STARTUPAXIS,X,2
STARTUPAXIS,Y1,5
[Data]
Comment,Time Stamp (sec),Temperature (K),Magnetic Field (Oe),Moment (emu),M. Std. Err. (emu),Transport Action,Averaging Time (sec),Frequency (Hz),Peak Amplitude (mm),Center Position (mm),Coil Signal' (mV),Coil Signal" (mV),Range (mV),M. Quad. Signal (emu),M. Raw' (emu),M. Raw" (emu),Min. Temperature (K),Max. Temperature (K),Min. Field (Oe),Max. Field (Oe),Mass (grams),Motor Lag (deg),Pressure (Torr),VSM Status (code),Motor Status (code),Measure Status (code),Measure Count,PPMS Status (code),System Temp. (K),System Field (Oe),Sample Position (deg),Bridge 1 Resistance (ohms),Bridge 1 Excitation (에),Bridge 2 Resistance (ohms),Bridge 2 Excitation (에),Bridge 3 Resistance (ohms),Bridge 3 Excitation (에),Bridge 4 Resistance (ohms),Bridge 4 Excitation (에),Signal 1 Vin (V),Signal 2 Vin (V),Digital Inputs (code),Drive 1 Iout (mA),Drive 1 Ipower (W),Drive 2 Iout (mA),Drive 2 Ipower (W),Pressure (),Map 20 (),Map 21 (),Map 22 (),Map 23 (),Map 24 (),Map 25 (),Map 26 (),Map 27 (),Map 28 (),Map 29 ()
,19718015.37,100.3159,0.243580378592014,-3.37093827250755E-5,4.40110421048545E-7,1,0.999253354069792,40.0298881530762,1.99399936206579,14.2400003969669,-0.000384434136977232,-5.69664499791169E-5,0.25,9.05554057908002E-7,-3.39018480952776E-5,8.06385155888984E-7,100.3159,100.3159,0.182685270905495,0.304475486278534,53.6978792711595,19.5530460523875,22.529354,0,0,0,40,4417,100.3159,0.243580378592014,,,,,,,,,,,,,0,,,,,,,,,,,,,,
,19718106.545,100.3024,3697.19140625,-2.73315674572593E-5,3.56494562433823E-7,1,0.999253354069792,40.0298881530762,1.99408567632666,14.2400003969669,-0.000310607573782991,-5.2481515267664E-5,0.25,1.79806243226034E-7,-2.74860029662307E-5,9.6485083127235E-8,100.3027,100.3027,3692.11083984375,3702.27197265625,53.6595794737172,19.5557201267585,22.149702,0,0,0,40,4449,100.3024,3697.19140625,,,,,,,,,,,,,0,,,,,,,,,,,,,,
,19718184.88,100.30125,7613.99536132813,-2.81895946102572E-5,8.4396457603335E-7,1,0.999253354069792,40.0298881530762,1.99417876666185,14.2400003969669,-0.000324476815508593,-3.07864873535679E-5,0.25,2.2416478289983E-6,-2.83553418250293E-5,2.16761394229987E-6,100.3015,100.3015,7606.7197265625,7621.27099609375,53.5970491921788,19.5538050547442,22.149702,0,0,0,40,4449,100.30125,7613.99536132813,,,,,,,,,,,,,0,,,,,,,,,,,,,,
,19718269.845,100.302,11859.75,-2.40943698597255E-5,1.12087351798941E-6,1,0.999253354069792,40.0298881530762,1.994248451928,14.2400003969669,-0.000278053482534701,-2.23073711430735E-5,0.25,2.26868949788206E-6,-2.42372392126071E-5,2.20773839744144E-6,100.3018,100.3018,11854.45703125,11865.04296875,53.9823920521596,19.555450978696,22.149702,0,0,0,40,4449,100.302,11859.75,,,,,,,,,,,,,0,,,,,,,,,,,,,,
,19718354.78,100.298,16105.2778320313,-1.94194391489257E-5,1.34648224156463E-6,1,0.999253354069792,40.0298881530762,1.9941407455073,14.2400003969669,-0.000225473317284638,-1.01249813575687E-5,0.25,2.52003883384675E-6,-1.95367947806413E-5,2.47510674377282E-6,100.2982,100.2982,16097.6630859375,16112.892578125,53.6838099578134,19.5559995456793,22.909004,0,0,0,40,4449,100.298,16105.2778320313,,,,,,,,,,,,,0,,,,,,,,,,,,,,
,19718438.065,100.29295,20267.60546875,-1.93571866907901E-5,1.16552213825746E-6,1,0.999253354069792,40.0298881530762,1.99402137176024,14.2400003969669,-0.000234327009782433,4.44851162235675E-5,0.25,7.31966863326357E-6,-1.94888352712012E-5,7.30236231080105E-6,100.2932,100.2932,20265.26953125,20269.94140625,54.0816588741019,19.556412810998,22.529354,0,0,0,40,4449,100.29295,20267.60546875,,,,,,,,,,,,,0,,,,,,,,,,,,,,
,19718521.805,100.28,24453.0576171875,-2.56201566307326E-5,1.60688651178849E-6,1,0.999253354069792,40.0298881530762,1.99413374280233,14.2400003969669,-0.000304752632987317,2.80997685141885E-5,0.25,6.97595309666301E-6,-2.57862483637536E-5,6.9381352063651E-6,100.2814,100.2814,24448.0859375,24458.029296875,54.2645599476019,19.554297235463,22.529354,0,0,0,40,4449,100.28,24453.0576171875,,,,,,,,,,,,,0,,,,,,,,,,,,,,
,19718606.07,100.26455,28666.2197265625,-3.28906953674972E-5,1.94682086978595E-6,1,0.999253354069792,40.0298881530762,1.99396793914741,14.2400003969669,-0.00038611265867958,7.07466177276203E-6,0.25,6.40059447054633E-6,-3.30963441958207E-5,6.33811859821782E-6,100.2641,100.2641,28661.328125,28671.111328125,53.9487820258326,19.5572072213684,22.529354,0,0,0,40,4449,100.26455,28666.2197265625,,,,,,,,,,,,,0,,,,,,,,,,,,,,
,19718687.85,100.24915,32754.033203125,-4.85042098922553E-5,2.19860062157609E-6,1,0.999253354069792,40.0298881530762,1.99397739357897,14.2500000074506,-0.000566862570138501,-4.06319053299559E-6,0.25,8.16121800500921E-6,-4.88038570005496E-5,8.06261836042508E-6,100.2497,100.2497,32749.388671875,32758.677734375,53.9847369377173,19.5562528259967,22.529354,0,0,0,40,4449,100.24915,32754.033203125,,,,,,,,,,,,,0,,,,,,,,,,,,,,
,19718765.75,100.2358,36644.673828125,-5.8451034414533E-5,1.95853904595189E-6,1,0.999253354069792,40.0298881530762,1.99378087534709,14.2500000074506,-0.000682897116774496,-5.75730147558885E-6,0.25,9.75810235260491E-6,-5.88121460259627E-5,9.63975605844119E-6,100.2363,100.2363,36637.06640625,36652.28125,53.8190316916403,19.5571900909798,22.149702,0,0,0,40,4449,100.2358,36644.673828125,,,,,,,,,,,,,0,,,,,,,,,,,,,,
,19718841.12,100.22035,40412.814453125,-7.01794203368225E-5,2.51332509326304E-6,1,0.999253354069792,40.0298881530762,1.99390951408486,14.2400003969669,-0.000814135136325246,-4.0175946356668E-5,0.25,8.78475100062269E-6,-7.06046026764703E-5,8.62704571997291E-6,100.2194,100.2194,40405.140625,40420.48828125,53.9917715943903,19.5580889963077,22.529354,0,0,0,40,4449,100.22035,40412.814453125,,,,,,,,,,,,,0,,,,,,,,,,,,,,
,19718917.93,100.2093,44252.68359375,-8.11956254158382E-5,2.09363330665427E-6,1,0.999253354069792,40.0298881530762,1.99404386256318,14.2400003969669,-0.000947398001035852,-1.57245678499343E-5,0.25,1.28722353041207E-5,-8.16959102893195E-5,1.27064596319571E-5,100.2094,100.2094,44247.67578125,44257.69140625,53.9347127124865,19.5562468619908,22.529354,0,0,0,40,4449,100.2093,44252.68359375,,,,,,,,,,,,,0,,,,,,,,,,,,,,
,19718994.015,100.1984,48055.904296875,-9.29136569548385E-5,2.43942833384613E-6,1,0.999253354069792,40.0298881530762,1.99399840148433,14.2400003969669,-0.00107722580502581,-5.71793347074706E-5,0.25,1.12766445234247E-5,-9.34764163398133E-5,1.10687175608291E-5,100.1984,100.1984,48050.78125,48061.02734375,54.3309983717365,19.5554040801657,22.909004,0,0,0,40,4449,100.1984,48055.904296875,,,,,,,,,,,,,0,,,,,,,,,,,,,,
,19719069.76,100.18765,51841.68359375,-0.000107869698395306,1.95456646518622E-6,1,0.999253354069792,40.0298881530762,1.99396601822132,14.2400003969669,-0.0012495669305705,-7.23247554974682E-5,0.25,1.25667566900948E-5,-0.000108522023344484,1.23240374684588E-5,100.1869,100.1869,51834.28515625,51849.08203125,54.034761162948,19.557624879063,22.909004,0,0,0,40,4449,100.18765,51841.68359375,,,,,,,,,,,,,0,,,,,,,,,,,,,,
,19719143.515,100.17815,55524.763671875,-0.000119410975558646,2.62966248010336E-6,1,0.999253354069792,40.0298881530762,1.9937509870951,14.2400003969669,-0.00138322813091747,-7.94704165455357E-5,0.25,1.39610781078033E-5,-0.00012013379480666,1.36944880709413E-5,100.1771,100.1771,55522.28515625,55527.2421875,53.9175168850634,19.5611271686153,22.909004,0,0,0,40,4449,100.17815,55524.763671875,,,,,,,,,,,,,0,,,,,,,,,,,,,,
,19719219.815,100.1665,59340.5390625,-0.000129746331046684,2.55556218279518E-6,1,0.999253354069792,40.0298881530762,1.9940254871471,14.2400003969669,-0.00150181474117142,-9.39963236789657E-5,0.25,1.44948778973022E-5,-0.000130530389867576,1.42033943815325E-5,100.1674,100.1674,59330.4921875,59350.5859375,53.9448738832365,19.5555074898994,22.529354,0,0,0,40,4449,100.1665,59340.5390625,,,,,,,,,,,,,0,,,,,,,,,,,,,,
,19719293.61,100.1589,63026.798828125,-0.000142780347019155,2.3474510861436E-6,1,0.999253354069792,40.0298881530762,1.99403767330825,14.2400003969669,-0.00165326206996581,-0.000100242419500129,0.25,1.62305559162971E-5,-0.000143644640962793,1.59135863781892E-5,100.1595,100.1595,63019.25,63034.34765625,53.7150750985826,19.5556848162498,22.529354,0,0,0,40,4449,100.1589,63026.798828125,,,,,,,,,,,,,0,,,,,,,,,,,,,,
,19719369.265,100.15165,66809.390625,-0.000155576434549654,2.67521701716121E-6,1,0.999253354069792,40.0298881530762,1.99399522347191,14.2400003969669,-0.0017957523966311,-0.000141407124585984,0.25,1.48479142148814E-5,-0.000156510821528428,1.4488735363938E-5,100.1522,100.1522,66806.921875,66811.859375,53.8729640594672,19.5585136210011,22.149702,0,0,0,40,4449,100.15165,66809.390625,,,,,,,,,,,,,0,,,,,,,,,,,,,,
,19719446.705,100.1459,70680.06640625,-0.000165958033027462,2.85859068719988E-6,1,0.999253354069792,40.0298881530762,1.99404729018617,14.2400003969669,-0.00191379124513188,-0.000161383372477762,0.25,1.49080986449686E-5,-0.000166952972515289,1.45222965858702E-5,100.146,100.146,70675.0234375,70685.109375,53.6416020177749,19.5569334218093,22.529354,0,0,0,40,4449,100.1459,70680.06640625,,,,,,,,,,,,,0,,,,,,,,,,,,,,
,19719523.09,100.137,74495.8984375,-0.000176406643309745,1.97191106886414E-6,1,0.999253354069792,40.0298881530762,1.99399327011164,14.2400003969669,-0.0020309338294405,-0.000190381471087689,0.25,1.41843870582423E-5,-0.000177460424295279,1.37675274049252E-5,100.1371,100.1371,74493.3828125,74498.4140625,53.8995394291211,19.5568105195035,22.909004,0,0,0,40,4449,100.137,74495.8984375,,,,,,,,,,,,,0,,,,,,,,,,,,,,
,19719600.225,100.13105,78354.37890625,-0.000190482424681833,2.24808639517897E-6,1,0.999253354069792,40.0298881530762,1.99393755519539,14.2400003969669,-0.0021918948127913,-0.000211514937963773,0.25,1.47893660631955E-5,-0.000191619804463365,1.43392683841465E-5,100.1317,100.1317,78346.921875,78361.8359375,53.8268479768326,19.5557215950991,22.529354,0,0,0,40,4449,100.13105,78354.37890625,,,,,,,,,,,,,0,,,,,,,,,,,,,,
,19719678.57,100.1222,82270.6328125,-0.000204435263473794,1.88637429044456E-6,1,0.999253354069792,40.0298881530762,1.99405963939694,14.2400003969669,-0.00234650941605519,-0.000261744664745819,0.25,1.28111603462834E-5,-0.000205648490991974,1.23137567010898E-5,100.1223,100.1223,82260.5703125,82280.6953125,53.9362759695249,19.5535831864234,22.529354,0,0,0,40,4449,100.1222,82270.6328125,,,,,,,,,,,,,0,,,,,,,,,,,,,,
,19719753.745,100.11595,86028.9453125,-0.000215205223350518,2.69245346630592E-6,1,0.999253354069792,40.0298881530762,1.9940501395109,14.2400003969669,-0.00246965677180681,-0.000278224262276809,0.25,1.32458663287102E-5,-0.000216482833764688,1.27242011320213E-5,100.114,100.114,86018.953125,86038.9375,54.0660263037173,19.5515864371979,22.149702,0,0,0,40,4449,100.11595,86028.9453125,,,,,,,,,,,,,0,,,,,,,,,,,,,,
,19719822.84,100.10925,89480.12890625,-0.000228389047531398,2.41590353223018E-6,1,0.999253354069792,40.0298881530762,1.99404136503112,14.2400003969669,-0.002616201934379,-0.000322357112358845,0.25,1.16682484201816E-5,-0.000229739422888068,1.11040638951084E-5,100.1096,100.1096,89452.6171875,89507.640625,53.7627544382557,19.5530463319142,22.149702,0,0,0,40,4449,100.10925,89480.12890625,,,,,,,,,,,,,0,,,,,,,,,,,,,,
,19719911.985,100.1077,86936.60546875,-0.000215975443921698,2.70230499199242E-6,1,0.999253354069792,40.0298881530762,1.99384640233052,14.2400003969669,-0.00248048428099158,-0.00026649720438234,0.25,1.44109251214776E-5,-0.000217261012617468,1.38945813941219E-5,100.1077,100.1077,86934.078125,86939.1328125,54.0675895607557,19.5506392781115,22.909004,0,0,0,40,4449,100.1077,86936.60546875,,,,,,,,,,,,,0,,,,,,,,,,,,,,
,19719985.41,100.10645,83267.734375,-0.000211149782399568,2.52307522521281E-6,1,0.999253354069792,40.0298881530762,1.99391030407658,14.2400003969669,-0.00242477207608003,-0.000262552915459884,0.25,1.39156219141879E-5,-0.000212405079406027,1.34065574273365E-5,100.1057,100.1057,83235.234375,83300.234375,53.8753089450249,19.5528516800357,22.909004,0,0,0,40,4449,100.10645,83267.734375,,,,,,,,,,,,,0,,,,,,,,,,,,,,
,19720064.455,100.1083,79316.1875,-0.000196052521749464,2.34949223624061E-6,1,0.999253354069792,40.0298881530762,1.99396199824176,14.2400003969669,-0.00224838583264774,-0.000261213977493029,0.25,1.13885608290225E-5,-0.0001972126844485,1.09038415659816E-5,100.1083,100.1083,79311.09375,79321.28125,53.6970976426403,19.5539635402066,22.529354,0,0,0,40,4449,100.1083,79316.1875,,,,,,,,,,,,,0,,,,,,,,,,,,,,
,19720141.47,100.1087,75465.15234375,-0.000179304763891854,2.6860478724454E-6,1,0.999253354069792,40.0298881530762,1.99401179474879,14.2400003969669,-0.0020681853642979,-0.00017148589566153,0.25,1.63570163716325E-5,-0.000180381596826966,1.59449655789334E-5,100.1086,100.1086,75462.3984375,75467.90625,54.0003695081019,19.5476340165228,22.909004,0,0,0,40,4449,100.1087,75465.15234375,,,,,,,,,,,,,0,,,,,,,,,,,,,,
,19720219.805,100.1078,71549.1015625,-0.00016583723120109,2.30707152946516E-6,1,0.999253354069792,40.0298881530762,1.99414620172118,14.2400003969669,-0.00190857707351579,-0.00018357936754234,0.25,1.29322739142984E-5,-0.000166826098556458,1.25357969502151E-5,100.1078,100.1078,71539.0625,71559.140625,53.8033991212557,19.5504336080046,23.288654,0,0,0,40,4449,100.1078,71549.1015625,,,,,,,,,,,,,0,,,,,,,,,,,,,,
,19720297.225,100.1106,67680.85546875,-0.00015651773072546,2.13390349809E-6,1,0.999253354069792,40.0298881530762,1.99407058855073,14.2400003969669,-0.00180253007377485,-0.000165943032551604,0.25,1.2852105696541E-5,-0.000157452036326058,1.24790786405658E-5,100.1106,100.1106,67675.9609375,67685.75,53.6275327044288,19.5545201131582,22.529354,0,0,0,40,4449,100.1106,67680.85546875,,,,,,,,,,,,,0,,,,,,,,,,,,,,
,19720374.14,100.1121,63835.279296875,-0.000144722184843916,1.84967740632257E-6,1,0.999253354069792,40.0298881530762,1.99410121083486,14.2400003969669,-0.00166918465138313,-0.000139299025427389,0.25,1.31312716511137E-5,-0.000145588896204477,1.27911599176557E-5,100.1122,100.1122,63827.73046875,63842.828125,54.1817073245634,19.5560250243043,22.909004,0,0,0,40,4449,100.1121,63835.279296875,,,,,,,,,,,,,0,,,,,,,,,,,,,,
,19720447.895,100.11775,60148.953125,-0.000130130294579805,2.60857811412895E-6,1,0.999253354069792,40.0298881530762,1.99403778048144,14.2400003969669,-0.00150763347774165,-8.65072959213999E-5,0.25,1.5221886148646E-5,-0.00013091881974935,1.4933606242049E-5,100.1179,100.1179,60139,60158.90625,53.9198617706211,19.5522650562378,22.909004,0,0,0,40,4449,100.11775,60148.953125,,,,,,,,,,,,,0,,,,,,,,,,,,,,
,19720525.72,100.1214,56258.255859375,-0.000119053663174088,2.64121197424346E-6,1,0.999253354069792,40.0298881530762,1.99404808929388,14.2400003969669,-0.00137771435744524,-8.82026275143015E-5,0.25,1.31301290409243E-5,-0.000119772181819371,1.2859878179133E-5,100.1209,100.1209,56250.51171875,56266,54.1348096134096,19.5528432195754,22.529354,0,0,0,40,4449,100.1214,56258.255859375,,,,,,,,,,,,,0,,,,,,,,,,,,,,
,19720599.635,100.1237,52564.931640625,-0.000111147937719339,2.16286517900074E-6,1,0.999253354069792,40.0298881530762,1.99410511431803,14.2400003969669,-0.0012886983877989,-6.84399085196526E-5,0.25,1.34849407010407E-5,-0.000111821793778232,1.32379069742506E-5,100.1236,100.1236,52562.5,52567.36328125,53.7643176952942,19.5583769447778,22.529354,0,0,0,40,4449,100.1237,52564.931640625,,,,,,,,,,,,,0,,,,,,,,,,,,,,
,19720673.54,100.12735,48872.17578125,-9.91674847424284E-5,2.20687214923349E-6,1,0.999253354069792,40.0298881530762,1.99387956454414,14.2400003969669,-0.0011523980487203,-4.54750567197941E-5,0.25,1.3405512438132E-5,-9.977227777261E-5,1.31914028263965E-5,100.1268,100.1268,48864.69921875,48879.65234375,54.0378876770249,19.5580711977931,23.288654,0,0,0,40,4449,100.12735,48872.17578125,,,,,,,,,,,,,0,,,,,,,,,,,,,,
,19720750.365,100.1315,45031.818359375,-8.67491666811176E-5,2.1580265290652E-6,1,0.999253354069792,40.0298881530762,1.99398373611832,14.2400003969669,-0.00100774531924282,-4.19953315466116E-5,0.25,1.15331791317358E-5,-8.72772568008477E-5,1.13433798108107E-5,100.1319,100.1319,45016.73046875,45046.90625,53.9487820258326,19.5583109957106,22.529354,0,0,0,40,4449,100.1315,45031.818359375,,,,,,,,,,,,,0,,,,,,,,,,,,,,
,19720827.89,100.134,41153.802734375,-7.31872460412666E-5,1.60593254158188E-6,1,0.999253354069792,40.0298881530762,1.99381638850367,14.2400003969669,-0.000852834381006211,-2.00131943432965E-5,0.25,1.10892332427364E-5,-7.36364604217017E-5,1.09356502300659E-5,100.134,100.134,41148.94921875,41158.65625,53.7385239541595,19.5603593978727,22.909004,0,0,0,40,4449,100.134,41153.802734375,,,,,,,,,,,,,0,,,,,,,,,,,,,,
,19720905.16,100.13965,37295.603515625,-6.17297294360643E-5,2.53796156350258E-6,1,0.999253354069792,40.0298881530762,1.99406412011227,14.2400003969669,-0.000713960475268899,-4.78815532978882E-5,0.25,6.62339200539482E-6,-6.21002268972957E-5,6.47735382349647E-6,100.1386,100.1386,37290.265625,37300.94140625,54.1473156697173,19.5583355827474,22.909004,0,0,0,40,4449,100.13965,37295.603515625,,,,,,,,,,,,,0,,,,,,,,,,,,,,
,19720980.32,100.14365,33537.6875,-4.90240265245123E-5,1.73253924299294E-6,1,0.999253354069792,40.0298881530762,1.99388002694859,14.2400003969669,-0.000575964503574997,1.32739381607245E-5,0.25,9.77999715641111E-6,-4.93315407235239E-5,9.68892951121207E-6,100.1446,100.1446,33532.44921875,33542.92578125,54.0535202474096,19.5628560893547,22.909004,0,0,0,40,4449,100.14365,33537.6875,,,,,,,,,,,,,0,,,,,,,,,,,,,,
,19721053.79,100.1467,29867.341796875,-3.97511785384009E-5,1.95959300985963E-6,1,0.999253354069792,40.0298881530762,1.99406294985436,14.2400003969669,-0.000466890973738225,9.79789342292361E-6,0.25,7.84558222175903E-6,-4.00001361086602E-5,7.77065441979814E-6,100.1474,100.1474,29854.771484375,29879.912109375,54.0136571929288,19.5607066596133,22.909004,0,0,0,40,4449,100.1467,29867.341796875,,,,,,,,,,,,,0,,,,,,,,,,,,,,
,19721131.515,100.15105,25981.349609375,-2.81511734814279E-5,1.68732945992722E-6,1,0.999253354069792,40.0298881530762,1.99396071852636,14.2400003969669,-0.000332557773270568,1.79256631548241E-5,0.25,6.52449225864598E-6,-2.83303014938104E-5,6.47646873386738E-6,100.1513,100.1513,25976.330078125,25986.369140625,54.1785808104865,19.5655547651771,22.149702,0,0,0,40,4449,100.15105,25981.349609375,,,,,,,,,,,,,0,,,,,,,,,,,,,,
,19721206.955,100.1547,22211.2763671875,-1.58939447612884E-5,1.25887737327546E-6,1,0.999253354069792,40.0298881530762,1.99370566817201,14.2400003969669,-0.000194388075186486,4.79823858871259E-5,0.25,7.01995762581053E-6,-1.60051477042812E-5,7.01147530413607E-6,100.1547,100.1547,22203.771484375,22218.78125,54.085567016698,19.5627824556214,22.529354,0,0,0,40,4449,100.1547,22211.2763671875,,,,,,,,,,,,,0,,,,,,,,,,,,,,
,19721284.805,100.15995,18321.44921875,-6.19969237320104E-6,8.02330176205587E-7,1,0.999253354069792,40.0298881530762,1.99399700358827,14.2400003969669,-8.06723008147385E-5,4.62519911407827E-5,0.25,5.1639301233058E-6,-6.25045670579503E-6,5.17422597392222E-6,100.1606,100.1606,18311.53515625,18331.36328125,53.8542049750057,19.5644480705119,22.909004,0,0,0,40,4449,100.15995,18321.44921875,,,,,,,,,,,,,0,,,,,,,,,,,,,,
,19721363.03,100.1637,14408.7705078125,4.36079058180305E-6,8.04160391774557E-7,1,0.999253354069792,40.0298881530762,1.99395068508737,14.2500000074506,4.27216013291532E-5,4.72651704799683E-5,0.25,3.39780326864351E-6,4.37501024734234E-6,3.43032570368987E-6,100.1629,100.1629,14403.96484375,14413.576171875,54.0066225362557,19.5590246404945,22.909004,0,0,0,40,4449,100.1637,14408.7705078125,,,,,,,,,,,,,0,,,,,,,,,,,,,,
,19721439.055,100.168,10613.47265625,1.41328643450357E-5,7.20660414699807E-7,1,0.999253354069792,40.0298881530762,1.99401362586779,14.2400003969669,0.000154552365230077,6.15965440471288E-5,0.25,2.94302469182369E-6,1.42035192503616E-5,3.00303838223733E-6,100.1689,100.1689,10606.0791015625,10620.8662109375,53.8307561194288,19.561771864754,22.909004,0,0,0,40,4449,100.168,10613.47265625,,,,,,,,,,,,,0,,,,,,,,,,,,,,
,19721513.315,100.1728,6899.810546875,2.43007488465524E-5,5.53795815275936E-7,1,0.999253354069792,40.0298881530762,1.99387112084137,14.2400003969669,0.000272642892810379,6.65381318798599E-5,0.25,1.59178121887501E-6,2.44327460748435E-5,1.67568014912774E-6,100.1728,100.1728,6892.37060546875,6907.25048828125,53.8628028887172,19.5662789591393,22.909004,0,0,0,40,4449,100.1728,6899.810546875,,,,,,,,,,,,,0,,,,,,,,,,,,,,
,19721586.715,100.17545,3233.89465332031,3.2361927548815E-5,3.36341739790178E-7,1,0.999253354069792,40.0298881530762,1.99389017534326,14.2400003969669,0.000366392308762946,6.98029298296859E-5,0.25,4.62429809013694E-7,3.25426649926927E-5,5.65150561213577E-7,100.1749,100.1749,3223.90112304687,3243.88818359375,54.1168321574673,19.5657226200583,22.909004,0,0,0,40,4449,100.17545,3233.89465332031,,,,,,,,,,,,,0,,,,,,,,,,,,,,
,19721659.72,100.17825,-417.177871704102,2.98930492557873E-5,3.11261295050518E-7,1,0.999253354069792,40.0298881530762,1.99395173358042,14.2500000074506,0.000340019007366213,5.55483821275525E-5,0.25,-3.59874164230983E-7,3.00623479710464E-5,-2.69232127377876E-7,100.1779,100.1779,-424.680908203125,-409.674835205078,53.8237214627557,19.5654011373158,23.288654,0,0,0,40,4449,100.17825,-417.177871704102,,,,,,,,,,,,,0,,,,,,,,,,,,,,
,19721736.85,100.1804,-4268.82568359375,2.97975846679672E-5,3.9995604771052E-7,1,0.999253354069792,40.0298881530762,1.99409736297548,14.2400003969669,0.000341100138277895,4.31868780020533E-5,0.25,-1.43217032037886E-6,2.99697824113777E-5,-1.34813991563391E-6,100.1804,100.1804,-4273.7197265625,-4263.931640625,54.1168321574673,19.5606352283858,22.909004,0,0,0,40,4449,100.1804,-4268.82568359375,,,,,,,,,,,,,0,,,,,,,,,,,,,,
,19721813.75,100.17735,-8112.56689453125,2.92763815502904E-5,5.89407755210383E-7,1,0.999253354069792,40.0298881530762,1.99370671187544,14.2400003969669,0.00033643386831712,3.46777134618201E-5,0.25,-2.08930498203644E-6,2.94478026287179E-5,-2.01092120525358E-6,100.1787,100.1787,-8117.685546875,-8107.4482421875,53.9581615680634,19.5666111919773,22.909004,0,0,0,40,4449,100.17735,-8112.56689453125,,,,,,,,,,,,,0,,,,,,,,,,,,,,
,19721891.63,100.16965,-12006.4140625,2.56886834527033E-5,7.19946971731568E-7,1,0.999253354069792,40.0298881530762,1.9940187433214,14.2400003969669,0.000296691686261772,2.22329000648163E-5,0.25,-2.55534606329508E-6,2.58414355658085E-5,-2.49096242780298E-6,100.1696,100.1696,-12011.3505859375,-12001.4775390625,54.078532360025,19.5667580183651,22.909004,0,0,0,40,4449,100.16965,-12006.4140625,,,,,,,,,,,,,0,,,,,,,,,,,,,,
,19721970.52,100.16465,-15949.2407226562,2.06475861956382E-5,8.06094362409958E-7,1,0.999253354069792,40.0298881530762,1.99396772414546,14.2400003969669,0.000242842846120749,-7.04741283633596E-6,0.25,-4.24877160285855E-6,2.07771642309595E-5,-4.20970174567179E-6,100.1651,100.1651,-15954.333984375,-15944.1474609375,54.0136571929288,19.5662848134436,22.909004,0,0,0,40,4449,100.16465,-15949.2407226562,,,,,,,,,,,,,0,,,,,,,,,,,,,,
,19722047.085,100.1546,-19774.2646484375,2.13326478142827E-5,9.64358812541748E-7,1,0.999253354069792,40.0298881530762,1.99389917361408,14.2400003969669,0.000253682901622837,-2.31623251568056E-5,0.25,-5.78860692234177E-6,2.14708516465308E-5,-5.75645401010745E-6,100.1546,100.1546,-19777.05859375,-19771.470703125,54.1590400975057,19.5675957002043,22.529354,0,0,0,40,4449,100.1546,-19774.2646484375,,,,,,,,,,,,,0,,,,,,,,,,,,,,
,19722124.73,100.1448,-23654.6123046875,2.58427491347239E-5,1.43738240714377E-6,1,0.999253354069792,40.0298881530762,1.99378219672221,14.2400003969669,0.000305718857532925,-1.90600937362765E-5,0.25,-6.21930463223453E-6,2.60078379758366E-5,-6.1762636154097E-6,100.1438,100.1438,-23664.66796875,-23644.556640625,54.0417958196211,19.5698703918723,22.909004,0,0,0,40,4449,100.1448,-23654.6123046875,,,,,,,,,,,,,0,,,,,,,,,,,,,,
,19722201.14,100.1369,-27475.296875,3.45695452550781E-5,1.18349620418244E-6,1,0.999253354069792,40.0298881530762,1.99391513680177,14.2400003969669,0.000409762856160042,-2.9933098837172E-5,0.25,-8.70969604804357E-6,3.47916624304256E-5,-8.65486562176751E-6,100.1369,100.1369,-27477.84375,-27472.75,53.8706191739095,19.5672599694077,22.529354,0,0,0,40,4449,100.1369,-27475.296875,,,,,,,,,,,,,0,,,,,,,,,,,,,,
,19722278.18,100.12605,-31325.564453125,4.6507598510755E-5,2.06263055997659E-6,1,0.999253354069792,40.0298881530762,1.99380308854436,14.2400003969669,0.000549684427014673,-3.14114785987385E-5,0.25,-1.09364757153168E-5,4.68042136699688E-5,-1.0859015266734E-5,100.1261,100.1261,-31330.462890625,-31320.666015625,54.2121908368134,19.5687262232872,22.909004,0,0,0,40,4449,100.12605,-31325.564453125,,,,,,,,,,,,,0,,,,,,,,,,,,,,
,19722356.575,100.1173,-35240.333984375,5.68062865287375E-5,1.82107937458206E-6,1,0.999253354069792,40.0298881530762,1.99379798680534,14.2400003969669,0.000667058399268732,-1.36048083598301E-5,0.25,-1.11757556031111E-5,5.71622521086371E-5,-1.10696752359391E-5,100.1176,100.1176,-35247.76171875,-35232.90625,53.9542534254672,19.5686819916955,22.909004,0,0,0,40,4449,100.1173,-35240.333984375,,,,,,,,,,,,,0,,,,,,,,,,,,,,
,19722434.17,100.109,-39117.74609375,6.83652638286551E-5,1.40555028454156E-6,1,0.999253354069792,40.0298881530762,1.99391506401993,14.2400003969669,0.000796805905274413,1.79836481857078E-5,0.25,-1.04219692680766E-5,6.8784924793079E-5,-1.02781919412224E-5,100.109,100.109,-39120.5,-39114.9921875,53.8549866035249,19.569043920008,22.909004,0,0,0,40,4449,100.109,-39117.74609375,,,,,,,,,,,,,0,,,,,,,,,,,,,,
,19722514.395,100.0995,-43130.5546875,7.93777394284765E-5,1.73635606945269E-6,1,0.999253354069792,40.0298881530762,1.99394257846868,14.2400003969669,0.000932076858024791,-1.84281581758028E-5,0.25,-1.55624157090147E-5,7.98755896630795E-5,-1.54164971095843E-5,100.0997,100.0997,-43133.15234375,-43127.95703125,53.8190316916403,19.5664816422137,23.288654,0,0,0,40,4449,100.0995,-43130.5546875,,,,,,,,,,,,,0,,,,,,,,,,,,,,
,19722591.46,100.0911,-46980.935546875,9.06430040707074E-5,2.67008104224875E-6,1,0.999253354069792,40.0298881530762,1.99399610344028,14.2400003969669,0.0010532360431003,4.2468421789151E-5,0.25,-1.21747324043678E-5,9.11953964074621E-5,-1.1977690195065E-5,100.0905,100.0905,-46986.046875,-46975.82421875,54.156695211948,19.5695812396518,23.288654,0,0,0,40,4449,100.0911,-46980.935546875,,,,,,,,,,,,,0,,,,,,,,,,,,,,
,19722669.375,100.0848,-50878.85546875,0.000106737726742076,2.64089708709525E-6,1,0.999253354069792,40.0298881530762,1.99395504078563,14.2400003969669,0.00123711809030321,6.774260170233E-5,0.25,-1.27725902206157E-5,0.00010738412935379,-1.25333805668898E-5,100.0843,100.0843,-50893.8515625,-50863.859375,54.1324647278519,19.5716820946447,22.529354,0,0,0,40,4449,100.0848,-50878.85546875,,,,,,,,,,,,,0,,,,,,,,,,,,,,
,19722747.495,100.07475,-54778.8515625,0.000115819590501768,2.01034983625365E-6,1,0.999253354069792,40.0298881530762,1.9937944718689,14.2400003969669,0.00134384135952523,6.46220716890331E-5,0.25,-1.46397982073681E-5,0.000116523832026729,-1.43865644894035E-5,100.0756,100.0756,-54786.2734375,-54771.4296875,54.0941649304096,19.5718955489766,22.529354,0,0,0,40,4449,100.07475,-54778.8515625,,,,,,,,,,,,,0,,,,,,,,,,,,,,
,19722822.735,100.0675,-58539.431640625,0.000128921064149986,2.05594274568438E-6,1,0.999253354069792,40.0298881530762,1.9941027269109,14.2400003969669,0.00149244380672054,9.26789078646153E-5,0.25,-1.44673922892989E-5,0.000129700272115756,-1.41770923451022E-5,100.0674,100.0674,-58549.44921875,-58529.4140625,54.2778476324288,19.5702843282218,22.909004,0,0,0,40,4449,100.0675,-58539.431640625,,,,,,,,,,,,,0,,,,,,,,,,,,,,
,19722899.37,100.062,-62366.955078125,0.000143930087304965,2.98394526976034E-6,1,0.999253354069792,40.0298881530762,1.99397597215811,14.2500000074506,0.00166825762008532,9.11783154761684E-5,0.25,-1.72315844294518E-5,0.000144803819517245,-1.69159919639287E-5,100.062,100.062,-62372.015625,-62361.89453125,54.2082826942173,19.5719626848281,23.288654,0,0,0,40,4449,100.062,-62366.955078125,,,,,,,,,,,,,0,,,,,,,,,,,,,,
,19722974.795,100.0547,-66137.1171875,0.000152006172407736,3.05419113271982E-6,1,0.999253354069792,40.0298881530762,1.99404520154568,14.2400003969669,0.00176038357421169,0.000105120446774946,0.25,-1.74190316653264E-5,0.000152927408161939,-1.70836763302906E-5,100.0523,100.0523,-66144.578125,-66129.65625,54.0292897633134,19.5721588412065,22.909004,0,0,0,40,4449,100.0547,-66137.1171875,,,,,,,,,,,,,0,,,,,,,,,,,,,,
,19723052.86,100.04745,-70039.703125,0.000165536494389947,1.88818500607596E-6,1,0.999253354069792,40.0298881530762,1.99395438896981,14.2400003969669,0.00191367838196042,0.000133423587587967,0.25,-1.72975894243686E-5,0.00016653577678157,-1.69255090753258E-5,100.0469,100.0469,-70052.171875,-70027.234375,54.2082826942173,19.5689603363212,22.529354,0,0,0,40,4449,100.04745,-70039.703125,,,,,,,,,,,,,0,,,,,,,,,,,,,,
,19723131.73,100.03985,-73981.99609375,0.000182077396894148,3.39854528570444E-6,1,0.999253354069792,40.0298881530762,1.9941831612309,14.2400003969669,0.00209142547893348,0.000224927156303752,0.25,-1.21394435561013E-5,0.00018315794941873,-1.16936256057089E-5,100.0404,100.0404,-73989.4375,-73974.5546875,54.0464855907365,19.569013846823,22.909004,0,0,0,40,4449,100.03985,-73981.99609375,,,,,,,,,,,,,0,,,,,,,,,,,,,,
,19723210.885,100.03515,-77937.0234375,0.000192862744433255,2.5527737234646E-6,1,0.999253354069792,40.0298881530762,1.99401230896189,14.2400003969669,0.00222176520274193,0.000200485384333206,0.25,-1.61803507540543E-5,0.000194017737390434,-1.57304089515293E-5,100.0351,100.0351,-77947.03125,-77927.015625,54.3505390847173,19.572302194187,22.529354,0,0,0,40,4449,100.03515,-77937.0234375,,,,,,,,,,,,,0,,,,,,,,,,,,,,
,19723286.965,100.0312,-81740.11328125,0.000203333894209584,2.21864148042026E-6,1,0.999253354069792,40.0298881530762,1.99418222269677,14.2400003969669,0.00233633031675094,0.000247092405082983,0.25,-1.39110488714233E-5,0.000204543813646031,-1.34217950152711E-5,100.0312,100.0312,-81750.203125,-81730.0234375,54.1527870693519,19.5701957310109,23.288654,0,0,0,40,4449,100.0312,-81740.11328125,,,,,,,,,,,,,0,,,,,,,,,,,,,,
,19723363.94,100.02635,-85585.45703125,0.000219358435470316,2.68848656434494E-6,1,0.999253354069792,40.0298881530762,1.99427821951426,14.2400003969669,0.00251227055451664,0.00031396408513429,0.25,-1.08307133078026E-5,0.000220653247125467,-1.02823269161106E-5,100.0265,100.0265,-85597.9296875,-85572.984375,54.2192254934865,19.5724630436832,22.909004,0,0,0,40,4449,100.02635,-85585.45703125,,,,,,,,,,,,,0,,,,,,,,,,,,,,
,19723439.85,100.0214,-89377.41015625,0.000229984617154197,2.5840362973714E-6,1,0.999253354069792,40.0298881530762,1.99387007859349,14.2500000074506,0.00264381589284772,0.000270130116295881,0.25,-1.65473158359847E-5,0.000231357796268433,-1.60059177125547E-5,100.0214,100.0214,-89379.6953125,-89375.125,54.0847853881788,19.5761858170823,23.288654,0,0,0,40,4449,100.0214,-89377.41015625,,,,,,,,,,,,,0,,,,,,,,,,,,,,
,19723530.555,100.0198,-87059.3828125,0.000222048755550235,3.44514913376437E-6,1,0.999253354069792,40.0298881530762,1.99400847773971,14.2400003969669,0.00255128658012098,0.00026916502550469,0.25,-1.52438877288983E-5,0.000223371823942871,-1.47147663407529E-5,100.0195,100.0195,-87064.203125,-87054.5625,53.9268964272942,19.5720232358607,23.288654,0,0,0,40,4449,100.0198,-87059.3828125,,,,,,,,,,,,,0,,,,,,,,,,,,,,
,19723605.22,100.01985,-83328.98046875,0.000214072949383562,2.65015645498436E-6,1,0.999253354069792,40.0298881530762,1.99391605393015,14.2500000074506,0.002458161307886,0.00026725841458184,0.25,-1.40147900795947E-5,0.000215345492715106,-1.34973875621941E-5,100.0186,100.0186,-83336.703125,-83321.2578125,54.1199586715442,19.5708624786873,23.288654,0,0,0,40,4449,100.01985,-83328.98046875,,,,,,,,,,,,,0,,,,,,,,,,,,,,
,19723682.75,100.0209,-79453.2578125,0.000199322027882834,2.00573519881094E-6,1,0.999253354069792,40.0298881530762,1.99351909699537,14.2400003969669,0.0022965934826536,0.000201707409303624,0.25,-1.72007856694874E-5,0.000200517468907443,-1.67396855202646E-5,100.0208,100.0208,-79458.3515625,-79448.1640625,54.4724731337173,19.5798149750345,23.288654,0,0,0,40,4449,100.0209,-79453.2578125,,,,,,,,,,,,,0,,,,,,,,,,,,,,
,19723761.945,100.0239,-75493.609375,0.000188014907706565,2.25768400201594E-6,1,0.999253354069792,40.0298881530762,1.99372205464328,14.2400003969669,0.00216483913665031,0.000199815085850624,0.25,-1.53882692568496E-5,0.000189139177729196,-1.49453775152689E-5,100.0244,100.0244,-75501.1015625,-75486.1171875,54.2973883454096,19.5760841865814,22.909004,0,0,0,40,4449,100.0239,-75493.609375,,,,,,,,,,,,,0,,,,,,,,,,,,,,
,19723840.345,100.0281,-71578.38671875,0.000173208700812876,2.81480465871567E-6,1,0.999253354069792,40.0298881530762,1.99404528575881,14.2400003969669,0.00199556432684838,0.0001789302253172,0.25,-1.4635200125401E-5,0.000174244813774338,-1.42269742937716E-5,100.028,100.028,-71583.265625,-71573.5078125,54.136372870448,19.5704784617995,22.909004,0,0,0,40,4449,100.0281,-71578.38671875,,,,,,,,,,,,,0,,,,,,,,,,,,,,
,19723918.235,100.03015,-67686.39453125,0.000159468386162106,2.04501751057025E-6,1,0.999253354069792,40.0298881530762,1.99405216927287,14.2400003969669,0.00184163357580495,0.000139795747276102,0.25,-1.56735792586263E-5,0.000160427747865684,-1.53077283363529E-5,100.0309,100.0309,-67691.25,-67681.5390625,54.1285565852557,19.5708098480804,22.909004,0,0,0,40,4449,100.03015,-67686.39453125,,,,,,,,,,,,,0,,,,,,,,,,,,,,
,19723997,100.035,-63748.650390625,0.000147065955267636,1.90696346496573E-6,1,0.999253354069792,40.0298881530762,1.99400192465035,14.2500000074506,0.0016985749620756,0.000127658197858845,0.25,-1.45680534699917E-5,0.00014795026710062,-1.42288662654176E-5,100.0347,100.0347,-63758.625,-63738.67578125,54.0300713918326,19.5693563697461,22.909004,0,0,0,40,4449,100.035,-63748.650390625,,,,,,,,,,,,,0,,,,,,,,,,,,,,
,19724073.97,100.0372,-59900.765625,0.000133462992028169,1.89238876252819E-6,1,0.999253354069792,40.0298881530762,1.99419930514186,14.2400003969669,0.00154801471471944,7.93292358919321E-5,0.25,-1.64403600593182E-5,0.000134274134940798,-1.61487924881387E-5,100.038,100.038,-59910.71875,-59890.8125,54.119177043025,19.5661463759157,23.288654,0,0,0,40,4449,100.0372,-59900.765625,,,,,,,,,,,,,0,,,,,,,,,,,,,,
,19724149.38,100.04035,-56133.095703125,0.000121506932545516,3.07088797992876E-6,1,0.999253354069792,40.0298881530762,1.99425034968987,14.2400003969669,0.00141023832668222,6.72573632621684E-5,0.25,-1.54069111268069E-5,0.000122246123539823,-1.51420250663735E-5,100.0401,100.0401,-56137.78125,-56128.41015625,54.2958250883711,19.5639113346742,22.529354,0,0,0,40,4449,100.04035,-56133.095703125,,,,,,,,,,,,,0,,,,,,,,,,,,,,
,19724227.335,100.0447,-52235.390625,0.000110436918683697,2.37075041253223E-6,1,0.999253354069792,40.0298881530762,1.99411848223628,14.2400003969669,0.00128274408864206,5.50089872779861E-5,0.25,-1.4543784265872E-5,0.00011110981675022,-1.43042932715358E-5,100.0446,100.0446,-52239.96484375,-52230.81640625,54.0363244199865,19.5660048115134,22.909004,0,0,0,40,4449,100.0447,-52235.390625,,,,,,,,,,,,,0,,,,,,,,,,,,,,
,19724306.5,100.05045,-48280.224609375,9.7462332547969E-5,2.23623825375954E-6,1,0.999253354069792,40.0298881530762,1.99382988563569,14.2400003969669,0.00113326455639188,4.06555133054779E-5,0.25,-1.35312249297359E-5,9.80577527422807E-5,-1.33222171687522E-5,100.0507,100.0507,-48287.60546875,-48272.84375,54.169982896775,19.5698594955228,22.909004,0,0,0,40,4449,100.05045,-48280.224609375,,,,,,,,,,,,,0,,,,,,,,,,,,,,
,19724383.37,100.0539,-44439.720703125,8.67924285026393E-5,1.77339760883034E-6,1,0.999253354069792,40.0298881530762,1.99426637470267,14.2400003969669,0.00100871315482289,4.01480201252385E-5,0.25,-1.17045308284853E-5,8.73212504565613E-5,-1.15150306783368E-5,100.0546,100.0546,-44444.6953125,-44434.74609375,54.0230367351596,19.5657795569197,22.909004,0,0,0,40,4449,100.0539,-44439.720703125,,,,,,,,,,,,,0,,,,,,,,,,,,,,
,19724462.83,100.0612,-40467.431640625,7.53694445710465E-5,2.16638320713795E-6,1,0.999253354069792,40.0298881530762,1.99394965097411,14.2400003969669,0.00087934566058789,1.47643572551975E-5,0.25,-1.19354411580785E-5,7.58335615195638E-5,-1.17797188323104E-5,100.0609,100.0609,-40472.43359375,-40462.4296875,54.220788750525,19.5674727642537,22.909004,0,0,0,40,4449,100.0612,-40467.431640625,,,,,,,,,,,,,0,,,,,,,,,,,,,,
,19724538.16,100.0688,-36704.591796875,6.5829988774597E-5,1.94892921574314E-6,1,0.999253354069792,40.0298881530762,1.99416281014248,14.2400003969669,0.00076711084488648,1.86583400659848E-5,0.25,-9.91825242367975E-6,6.62335766750925E-5,-9.77833925585599E-6,100.0689,100.0689,-36714.54296875,-36694.640625,54.1559135834288,19.5633493665421,22.909004,0,0,0,40,4449,100.0688,-36704.591796875,,,,,,,,,,,,,0,,,,,,,,,,,,,,
,19724613.36,100.0765,-32944.490234375,4.91096896568181E-5,1.02933807321969E-6,1,0.999253354069792,40.0298881530762,1.99390325989449,14.2400003969669,0.000577645131079347,-1.70990280782276E-5,0.25,-1.01323030686362E-5,4.94187467079732E-5,-1.00426871754606E-5,100.0773,100.0773,-32946.82421875,-32942.15625,54.0472672192557,19.567506701745,22.909004,0,0,0,40,4449,100.0765,-32944.490234375,,,,,,,,,,,,,0,,,,,,,,,,,,,,
,19724687.205,100.08375,-29254.158203125,3.83152788978465E-5,1.38674913276411E-6,1,0.999253354069792,40.0298881530762,1.99397209397663,14.2400003969669,0.000455196426283676,-3.89902125604308E-5,0.25,-1.01653413086642E-5,3.85630759255035E-5,-1.01076546392572E-5,100.0845,100.0845,-29264.291015625,-29244.025390625,54.0832221311403,19.5653186285707,22.909004,0,0,0,40,4449,100.08375,-29254.158203125,,,,,,,,,,,,,0,,,,,,,,,,,,,,
,19724764.275,100.091,-25403.83984375,2.75801325183351E-5,1.46743565180579E-6,1,0.999253354069792,40.0298881530762,1.99375284024252,14.2400003969669,0.00032876097777587,-3.45317373559222E-5,0.25,-7.8875806702593E-6,2.77601523593858E-5,-7.84884639863713E-6,100.091,100.091,-25416.486328125,-25391.193359375,54.9398869882174,19.56556376688,23.288654,0,0,0,40,4449,100.091,-25403.83984375,,,,,,,,,,,,,0,,,,,,,,,,,,,,
,19724838.665,100.09885,-21686.0439453125,1.46897037917439E-5,1.49059702838998E-6,1,0.999253354069792,40.0298881530762,1.99405339360964,14.2400003969669,0.000175193186754793,-1.87592926426239E-5,0.25,-4.2333914196272E-6,1.47856499848035E-5,-4.21272099626822E-6,100.099,100.099,-21693.287109375,-21678.80078125,54.4716915051981,19.5635450887248,22.909004,0,0,0,40,4449,100.09885,-21686.0439453125,,,,,,,,,,,,,0,,,,,,,,,,,,,,
,19724917.18,100.10355,-17763.5458984375,4.92320540082531E-6,6.28332368565443E-7,1,0.999253354069792,40.0298881530762,1.99417078278381,14.2500000074506,6.74513239122663E-5,-5.59892622325358E-5,0.25,-5.79710228634138E-6,4.96870869218698E-6,-5.81483398100776E-6,100.1044,100.1044,-17771.162109375,-17755.9296875,54.0933833018903,19.5628790293862,23.288654,0,0,0,40,4449,100.10355,-17763.5458984375,,,,,,,,,,,,,0,,,,,,,,,,,,,,
,19724993.255,100.11075,-13958.4858398438,-5.29400928292243E-6,9.05941604696582E-7,1,0.999253354069792,40.0298881530762,1.99420551755031,14.2400003969669,-5.13201186153147E-5,-6.05174354513909E-5,0.25,-4.40068026613468E-6,-5.31040452743543E-6,-4.4417383434069E-6,100.1098,100.1098,-13968.626953125,-13948.3447265625,54.2708129757557,19.5597237833369,22.909004,0,0,0,40,4449,100.11075,-13958.4858398438,,,,,,,,,,,,,0,,,,,,,,,,,,,,
,19725069.985,100.11415,-10125.4672851562,-1.4871671969455E-5,7.93386186566106E-7,1,0.999253354069792,40.0298881530762,1.99413141153299,14.2400003969669,-0.000163167688257269,-6.18206392626711E-5,0.25,-2.83257428725927E-6,-1.49468061715122E-5,-2.89429881549171E-6,100.1141,100.1141,-10135.572265625,-10115.3623046875,54.149660555275,19.5623450087077,22.529354,0,0,0,40,4449,100.11415,-10125.4672851562,,,,,,,,,,,,,0,,,,,,,,,,,,,,
,19725144.975,100.11965,-6376.669921875,-2.53664592380146E-5,5.25315095480448E-7,1,0.999253354069792,40.0298881530762,1.99402910052578,14.2500000074506,-0.000283600028169431,-7.52700034910283E-5,0.25,-2.17320719307865E-6,-2.55026347187879E-5,-2.26377849788277E-6,100.1204,100.1204,-6381.53271484375,-6371.80712890625,53.9315861984096,19.5601689094641,22.909004,0,0,0,40,4449,100.11965,-6376.669921875,,,,,,,,,,,,,0,,,,,,,,,,,,,,
,19725221.955,100.1267,-2528.09802246094,-3.36611701577133E-5,3.92297524261519E-7,1,0.999253354069792,40.0298881530762,1.99404761999578,14.2400003969669,-0.000380240353794904,-7.76742582069766E-5,0.25,-9.26931369534331E-7,-3.38477455789624E-5,-1.0364351916429E-6,100.1269,100.1269,-2538.03173828125,-2518.16430664062,54.1207403000634,19.5609504089328,22.909004,0,0,0,40,4449,100.1267,-2528.09802246094,,,,,,,,,,,,,0,,,,,,,,,,,,,,
,19725296.385,100.12985,1191.59362792969,-2.74823250103061E-5,3.324577931713E-7,1,0.999253354069792,40.0298881530762,1.99405003069415,14.2400003969669,-0.00031189336603482,-5.51659559408838E-5,0.25,-2.98630917981846E-8,-2.76368658723722E-5,-1.15255831458822E-7,100.1299,100.1299,1188.98205566406,1194.20520019531,53.8284112338711,19.5620763039134,22.909004,0,0,0,40,4449,100.12985,1191.59362792969,,,,,,,,,,,,,0,,,,,,,,,,,,,,
,19725369.71,100.1307,4852.8095703125,-2.93379506556814E-5,4.4783341864791E-7,1,0.999253354069792,40.0298881530762,1.99397461693081,14.2400003969669,-0.000333089661998908,-5.80487461814921E-5,0.25,4.18674997843473E-8,-2.9503279473405E-5,-4.86019624195818E-8,100.1299,100.1299,4844.96240234375,4860.65673828125,54.241111092025,19.5635279273412,22.909004,0,0,0,40,4449,100.1307,4852.8095703125,,,,,,,,,,,,,0,,,,,,,,,,,,,,
,19725441.3,100.12765,8431.384765625,-2.93800483469328E-5,6.41355742287622E-7,1,0.999253354069792,40.0298881530762,1.99385843446098,14.2500000074506,-0.000334796595583938,-5.10391759253281E-5,0.25,6.66274524141932E-7,-2.95476802755456E-5,5.79502472584191E-7,100.1278,100.1278,8423.84375,8438.92578125,54.1480972982365,19.5623785708004,22.909004,0,0,0,40,4449,100.12765,8431.384765625,,,,,,,,,,,,,0,,,,,,,,,,,,,,
,19725520.055,100.1217,12367.0961914062,-2.41669095275648E-5,8.54727530553938E-7,1,0.999253354069792,40.0298881530762,1.99401285664225,14.2400003969669,-0.000280485161345317,-1.31201423869224E-5,0.25,3.09077987274526E-6,-2.43127329288049E-5,3.03405286046286E-6,100.1228,100.1228,12361.921875,12372.2705078125,54.2121908368134,19.5629884160902,23.288654,0,0,0,40,4449,100.1217,12367.0961914062,,,,,,,,,,,,,0,,,,,,,,,,,,,,
,19725594.53,100.11395,16090.6225585938,-1.92381767488948E-5,1.0526317546751E-6,1,0.999253354069792,40.0298881530762,1.9938816624061,14.2500000074506,-0.000224872092770897,-1.31649685603939E-6,0.25,3.26431949385749E-6,-1.93567972226393E-5,3.22395293743993E-6,100.114,100.114,16085.7060546875,16095.5390625,54.0371060485057,19.5635919248242,22.909004,0,0,0,40,4449,100.11395,16090.6225585938,,,,,,,,,,,,,0,,,,,,,,,,,,,,
,19725671.35,100.1066,19928.638671875,-2.03598740314557E-5,8.69955946506077E-7,1,0.999253354069792,40.0298881530762,1.99379037916185,14.2400003969669,-0.000242570814213532,2.47707744976939E-5,0.25,5.75955860119997E-6,-2.04925039045414E-5,5.7301605766228E-6,100.1074,100.1074,19918.396484375,19938.880859375,53.9456555117557,19.5601487087396,22.909004,0,0,0,40,4449,100.1066,19928.638671875,,,,,,,,,,,,,0,,,,,,,,,,,,,,
,19725750.4,100.0998,23881.4453125,-2.54091656185158E-5,1.70586824074318E-6,1,0.999253354069792,40.0298881530762,1.99358913684366,14.2400003969669,-0.000301749011465753,2.54953514934036E-5,0.25,6.7103581173851E-6,-2.55733041253279E-5,6.67137265579414E-6,100.1006,100.1006,23871.341796875,23891.548828125,54.0378876770249,19.5644797956384,23.668306,0,0,0,40,4449,100.0998,23881.4453125,,,,,,,,,,,,,0,,,,,,,,,,,,,,
,19725827.535,100.08955,27737.4287109375,-3.32921609267861E-5,1.47540478355008E-6,1,0.999253354069792,40.0298881530762,1.9938549864165,14.2500000074506,-0.000392063063603595,1.43242440649557E-5,0.25,7.110272843688E-6,-3.35022422345594E-5,7.05018401864829E-6,100.0887,100.0887,27730.07421875,27744.783203125,54.2598701764865,19.5610868389263,23.288654,0,0,0,40,4449,100.08955,27737.4287109375,,,,,,,,,,,,,0,,,,,,,,,,,,,,
,19725904.105,100.0823,31563.294921875,-4.44988285822565E-5,2.07721005962503E-6,1,0.999253354069792,40.0298881530762,1.9938035255165,14.2400003969669,-0.000523460656797739,1.59239951643054E-5,0.25,9.21920895657492E-6,-4.47789251372894E-5,9.137977165039E-6,100.0822,100.0822,31553.21484375,31573.375,54.0840037596596,19.5618667836134,22.909004,0,0,0,40,4449,100.0823,31563.294921875,,,,,,,,,,,,,0,,,,,,,,,,,,,,
,19725980.43,100.0742,35378.564453125,-5.60948525179749E-5,1.75156924241706E-6,1,0.999253354069792,40.0298881530762,1.99394184279337,14.2400003969669,-0.000655775248305639,-3.50139347847363E-6,0.25,9.54382895770108E-6,-5.64419327522619E-5,9.43051409693567E-6,100.0739,100.0739,35370.81640625,35386.3125,54.1410626415634,19.5591894329616,23.288654,0,0,0,40,4449,100.0742,35378.564453125,,,,,,,,,,,,,0,,,,,,,,,,,,,,
,19726056.735,100.0637,39191.00390625,-6.88402736145359E-5,1.66015374844747E-6,1,0.999253354069792,40.0298881530762,1.99378274582808,14.2400003969669,-0.000804216086003386,-7.14980829598296E-6,0.25,1.14599093104214E-5,-6.9265746259761E-5,1.13204878812242E-5,100.0637,100.0637,39188.44140625,39193.56640625,54.0371060485057,19.5615572650166,22.909004,0,0,0,40,4449,100.0637,39191.00390625,,,,,,,,,,,,,0,,,,,,,,,,,,,,
,19726134.65,100.05815,43086.544921875,-7.98062854453643E-5,2.11648297803176E-6,1,0.999253354069792,40.0298881530762,1.99367954769138,14.2400003969669,-0.000927785887730107,-3.38954949107729E-5,0.25,1.10280642333498E-5,-8.02931956302746E-5,1.08548886737423E-5,100.0579,100.0579,43081.4375,43091.65234375,54.0425774481403,19.5612531309774,23.288654,0,0,0,40,4449,100.05815,43086.544921875,,,,,,,,,,,,,0,,,,,,,,,,,,,,
,19726212.555,100.0474,46979.83984375,-9.34003098513308E-5,2.22660061291601E-6,1,0.999253354069792,40.0298881530762,1.99376606822678,14.2400003969669,-0.001080213250154,-7.19027613458729E-5,0.25,1.00654831650803E-5,-9.39622377408141E-5,9.84811493809871E-6,100.0474,100.0474,46974.88671875,46984.79296875,54.2028112945827,19.5621729274372,22.909004,0,0,0,40,4449,100.0474,46979.83984375,,,,,,,,,,,,,0,,,,,,,,,,,,,,
,19726286.76,100.0418,50688.0078125,-0.000100753186205894,2.12005971584711E-6,1,0.999253354069792,40.0298881530762,1.99371200232009,14.2400003969669,-0.00116451845472158,-8.16012461575908E-5,0.25,1.05004876733006E-5,-0.000101358794194978,1.02655207030538E-5,100.0418,100.0418,50683.09375,50692.921875,53.9573799395442,19.5625068974809,22.909004,0,0,0,40,4449,100.0418,50688.0078125,,,,,,,,,,,,,0,,,,,,,,,,,,,,
,19726364.875,100.0369,54590.935546875,-0.000118363700938457,1.81018037940238E-6,1,0.999253354069792,40.0298881530762,1.9935446101795,14.2400003969669,-0.00136576684803959,-0.000108351441319852,0.25,1.12331273394011E-5,-0.000119072560737256,1.09527240319099E-5,100.0379,100.0379,54585.8984375,54595.97265625,53.9777022810442,19.5609603930007,22.909004,0,0,0,40,4449,100.0369,54590.935546875,,,,,,,,,,,,,0,,,,,,,,,,,,,,
,19726441.055,100.0289,58399.248046875,-0.000130737060185252,2.72484943098708E-6,1,0.999253354069792,40.0298881530762,1.99375007159591,14.2400003969669,-0.00151193616514093,-0.000101231457730726,0.25,1.40316398750456E-5,-0.000131525399863027,1.3733276702926E-5,100.0296,100.0296,58389.12109375,58409.375,53.9284596843326,19.5594568638886,22.529354,0,0,0,40,4449,100.0289,58399.248046875,,,,,,,,,,,,,0,,,,,,,,,,,,,,
,19726518.63,100.0239,62277.068359375,-0.000140659861052775,1.92857805313574E-6,1,0.999253354069792,40.0298881530762,1.99365298172861,14.2400003969669,-0.0016288859685995,-9.60172948789504E-5,0.25,1.62303152439849E-5,-0.000141512005819734,1.59180980509152E-5,100.024,100.024,62271.921875,62282.21484375,54.0800956170634,19.5610281248856,22.909004,0,0,0,40,4449,100.0239,62277.068359375,,,,,,,,,,,,,0,,,,,,,,,,,,,,
,19726595.625,100.0159,66125.6015625,-0.0001567653750167,3.13942446641227E-6,1,0.999253354069792,40.0298881530762,1.99372916431601,14.2400003969669,-0.00180631886627042,-0.000159143050670197,0.25,1.34939075981009E-5,-0.000157702685626788,1.31221379813496E-5,100.0159,100.0159,66120.859375,66130.34375,53.6720855300249,19.5586559928248,22.529354,0,0,0,40,4449,100.0159,66125.6015625,,,,,,,,,,,,,0,,,,,,,,,,,,,,
,19726671.705,100.00995,69928.5859375,-0.00016780183980004,2.27284404179575E-6,1,0.999253354069792,40.0298881530762,1.9939212669418,14.2500000074506,-0.00193123602917936,-0.000184252775956042,0.25,1.32178089338304E-5,-0.000168802515132402,1.28154986327302E-5,100.0103,100.0103,69918.5390625,69938.6328125,54.1645114971403,19.5554170938108,23.288654,0,0,0,40,4449,100.00995,69928.5859375,,,,,,,,,,,,,0,,,,,,,,,,,,,,
,19726747.475,100.006,73714.2421875,-0.000180056347117898,3.02452964571757E-6,1,0.999253354069792,40.0298881530762,1.9938589219988,14.2400003969669,-0.0020690500899353,-0.00021578126465168,0.25,1.25878613331806E-5,-0.00018112652192137,1.21498650367476E-5,100.006,100.006,73711.6796875,73716.8046875,53.9175168850634,19.5595634057382,22.909004,0,0,0,40,4449,100.006,73714.2421875,,,,,,,,,,,,,0,,,,,,,,,,,,,,
,19726823.595,99.9994,77520.2890625,-0.000194025772600299,3.43237111196455E-6,1,0.999253354069792,40.0298881530762,1.99385912305833,14.2400003969669,-0.00223278874432672,-0.000214273689936504,0.25,1.51691399338669E-5,-0.000195184540751636,1.47094562950258E-5,99.9994,99.9994,77520.2890625,77520.2890625,53.9112638569095,19.5603266058854,23.288654,0,0,0,40,4449,99.9994,77520.2890625,,,,,,,,,,,,,0,,,,,,,,,,,,,,
,19726898.82,99.99455,81281.6796875,-0.000201359220695796,3.54919607038893E-6,1,0.999253354069792,40.0298881530762,1.99353260910681,14.2400003969669,-0.00230953241478852,-0.000263928496851902,0.25,1.20752083764714E-5,-0.000202552537263077,1.15802000570517E-5,99.9947,99.9947,81274.25,81289.109375,53.9894267088326,19.5616883486501,23.288654,0,0,0,40,4449,99.99455,81281.6796875,,,,,,,,,,,,,0,,,,,,,,,,,,,,
,19726977.405,99.9908,85209.90234375,-0.000214971338063033,4.20081620481885E-6,1,0.999253354069792,40.0298881530762,1.9935158995698,14.2400003969669,-0.00246509244415511,-0.00028496700403799,0.25,1.26063857483935E-5,-0.000216245731614817,1.20797834356249E-5,99.9898,99.9898,85207.2265625,85212.578125,53.7455586108326,19.565309668159,22.529354,0,0,0,40,4449,99.9908,85209.90234375,,,,,,,,,,,,,0,,,,,,,,,,,,,,
,19727052.785,99.987,88975.76171875,-0.000233059902620845,2.62369756985103E-6,1,0.999253354069792,40.0298881530762,1.99360351591184,14.2400003969669,-0.00267232747003355,-0.000310750413413624,0.25,1.35058428323502E-5,-0.000234442324886479,1.29376399582139E-5,99.987,99.987,88970.7265625,88980.796875,53.7948012075442,19.5616932388884,22.909004,0,0,0,40,4449,99.987,88975.76171875,,,,,,,,,,,,,0,,,,,,,,,,,,,,
,19727074.36,99.985,89999.46875,-0.000233105695981794,2.12973978611218E-6,1,0.999253354069792,40.0298881530762,1.99358606465449,14.2400003969669,-0.00267001986374892,-0.000326852491780246,0.25,1.20941478938256E-5,-0.000234484812579028,1.15186475924547E-5,99.985,99.985,89999.4609375,89999.4765625,53.7635360667749,19.5608752087945,23.288654,0,0,0,40,4417,99.985,89999.46875,,,,,,,,,,,,,0,,,,,,,,,,,,,,