File: data/monolayers/magneticStructure/ML_Ac_CoFe_C/PPMS/data/DD205_4_KOELNPPMS_HYST_100OE_200K.DAT
[Header]
; VSM Data File (default extension .dat)
; Copyright (c) 2003-2013, Quantum Design, Inc. All rights reserved.
TITLE,
FILEOPENTIME,19737829.72,08/17/2018,10:42 am
BYAPP,VSM,2.0,2.0
INFO,PPMS VSM Option Release 1.4.10 Build 1,APPNAME
INFO,Quantum Design Linear Motor Servo Controller,MOTOR_MODULE_NAME
INFO,3101-100 M1,MOTOR_HW_VERSION
INFO,MMC1014,MOTOR_SERIAL_NUMBER
INFO,SRV No X-over 01.03.11,MOTOR_SOFTWARE_VERSION
INFO,Quantum Design VSM Detection Module,VSM_MODULE_NAME
INFO,3101-150 F0,VSM_HW_VERSION
INFO,VSM707,VSM_SERIAL_NUMBER
INFO,VSM No X-over 01.02.05 May 20 2008 13:51:47,VSM_SOFTWARE_VERSION
INFO,704,PREAMP_SERIAL_NUMBER
INFO,822,COIL_SERIAL_NUMBER
INFO,0,MOMENT_UNITS
INFO,,SAMPLE_MATERIAL
INFO,,SAMPLE_COMMENT
INFO,,SAMPLE_MASS
INFO,,SAMPLE_VOLUME
INFO,,SAMPLE_MOLECULAR_WEIGHT
INFO,,SAMPLE_SIZE
INFO,,SAMPLE_SHAPE
DATATYPE,COMMENT,1
DATATYPE,TIME,2
STARTUPAXIS,X,2
STARTUPAXIS,Y1,5
[Data]
Comment,Time Stamp (sec),Temperature (K),Magnetic Field (Oe),Moment (emu),M. Std. Err. (emu),Transport Action,Averaging Time (sec),Frequency (Hz),Peak Amplitude (mm),Center Position (mm),Coil Signal' (mV),Coil Signal" (mV),Range (mV),M. Quad. Signal (emu),M. Raw' (emu),M. Raw" (emu),Min. Temperature (K),Max. Temperature (K),Min. Field (Oe),Max. Field (Oe),Mass (grams),Motor Lag (deg),Pressure (Torr),VSM Status (code),Motor Status (code),Measure Status (code),Measure Count,PPMS Status (code),System Temp. (K),System Field (Oe),Sample Position (deg),Bridge 1 Resistance (ohms),Bridge 1 Excitation (에),Bridge 2 Resistance (ohms),Bridge 2 Excitation (에),Bridge 3 Resistance (ohms),Bridge 3 Excitation (에),Bridge 4 Resistance (ohms),Bridge 4 Excitation (에),Signal 1 Vin (V),Signal 2 Vin (V),Digital Inputs (code),Drive 1 Iout (mA),Drive 1 Ipower (W),Drive 2 Iout (mA),Drive 2 Ipower (W),Pressure (),Map 20 (),Map 21 (),Map 22 (),Map 23 (),Map 24 (),Map 25 (),Map 26 (),Map 27 (),Map 28 (),Map 29 ()
,19738121.83,200.0674,-0.0761188715696335,-2.24597869577177E-5,4.13021365872201E-7,1,0.999253354069792,40.0298881530762,1.99391822169981,14.2500000074506,-0.000256815831984053,-3.06448639297997E-5,0.25,1.19623350778497E-6,-2.2538557874637E-5,1.17597326951609E-6,200.0686,200.0686,-0.152237743139267,0,53.5587493947364,19.5616172230997,25.566563,0,0,0,40,4417,200.0674,-0.0761188715696335,,,,,,,,,,,,,0,,,,,,,,,,,,,,
,19738212.705,200.0619,3659.49291992188,1.05404848062429E-5,7.11068724326872E-7,1,0.999253354069792,40.0298881530762,1.99380433149914,14.2400003969669,0.000116414315383872,3.80094473253767E-5,0.25,1.52426170032228E-6,1.05751921940868E-5,1.54095612196352E-6,200.0619,200.0619,3651.90673828125,3667.0791015625,53.8065256353326,19.5626583762597,25.566563,0,0,0,40,4449,200.0619,3659.49291992188,,,,,,,,,,,,,0,,,,,,,,,,,,,,
,19738286.815,200.0676,7366.68481445313,1.78549185961113E-5,9.78487169358671E-7,1,0.999253354069792,40.0298881530762,1.99383971913586,14.2400003969669,0.000200078561568759,4.78246025060985E-5,0.25,1.12013393887488E-6,1.79152977569144E-5,1.14334983501637E-6,200.0682,200.0682,7356.84326171875,7376.5263671875,53.7385239541595,19.5627987156912,25.566563,0,0,0,40,4449,200.0676,7366.68481445313,,,,,,,,,,,,,0,,,,,,,,,,,,,,
,19738359.485,200.0747,10998.2456054688,1.2987780833149E-5,1.80281098431141E-6,1,0.999253354069792,40.0298881530762,1.99406939750326,14.2400003969669,0.000141075461282163,6.05791345214393E-5,0.25,3.09073731865298E-6,1.30292374509568E-5,3.11545957300358E-6,200.0757,200.0757,10995.830078125,11000.6611328125,53.8198133201595,19.5609825282526,25.566563,0,0,0,40,4449,200.0747,10998.2456054688,,,,,,,,,,,,,0,,,,,,,,,,,,,,
,19738434.9,200.0816,14768.4897460938,4.53955067810432E-6,1.84121634006615E-6,1,0.999253354069792,40.0298881530762,1.99402544594529,14.2500000074506,4.41039155774388E-5,5.11379361830385E-5,0.25,3.7249377198572E-6,4.55118272494013E-6,3.74269539441736E-6,200.0816,200.0816,14763.3037109375,14773.67578125,53.9057924572749,19.5635051140648,25.186911,0,0,0,40,4449,200.0816,14768.4897460938,,,,,,,,,,,,,0,,,,,,,,,,,,,,
,19738506.66,200.0846,18354.15625,-6.1429373951166E-6,2.0129130967665E-6,1,0.999253354069792,40.0298881530762,1.99371890118754,14.2400003969669,-8.07878450558604E-5,5.23802459272073E-5,0.25,5.69065604954514E-6,-6.17027367571863E-6,5.70365336816589E-6,200.0846,200.0846,18346.701171875,18361.611328125,53.7447769823134,19.5642106861299,25.566563,0,0,0,40,4449,200.0846,18354.15625,,,,,,,,,,,,,0,,,,,,,,,,,,,,
,19738579.76,200.0864,22009.1689453125,-1.58209777078351E-5,3.11247081717101E-6,1,0.999253354069792,40.0298881530762,1.9940205184006,14.2400003969669,-0.000192516748831071,4.52195502650556E-5,0.25,6.73889687084573E-6,-1.58828248239864E-5,6.7450826286862E-6,200.0864,200.0864,22004.259765625,22014.078125,53.8534233464865,19.5616233359536,25.946213,0,0,0,40,4449,200.0864,22009.1689453125,,,,,,,,,,,,,0,,,,,,,,,,,,,,
,19738654.33,200.0862,25737.455078125,-2.78035504652742E-5,2.52718902065261E-6,1,0.999253354069792,40.0298881530762,1.99401993166676,14.2400003969669,-0.000326960154380418,1.40285921684023E-5,0.25,6.06713675234834E-6,-2.79060080918142E-5,6.0581247244688E-6,200.0862,200.0862,25732.47265625,25742.4375,53.912827113948,19.5655244372603,25.566563,0,0,0,40,4449,200.0862,25737.455078125,,,,,,,,,,,,,0,,,,,,,,,,,,,,
,19738726.345,200.0844,29333.7529296875,-3.52357829309607E-5,2.93381146870365E-6,1,0.999253354069792,40.0298881530762,1.99400027301145,14.2400003969669,-0.000414704551315957,1.97811239332411E-5,0.25,7.86566129065704E-6,-3.5365817248832E-5,7.85490304716808E-6,200.0844,200.0844,29331.134765625,29336.37109375,54.0457039622173,19.5655307096061,25.566563,0,0,0,40,4449,200.0844,29333.7529296875,,,,,,,,,,,,,0,,,,,,,,,,,,,,
,19738799.275,200.0805,32978.943359375,-4.78399452509488E-5,2.63634590256554E-6,1,0.999253354069792,40.0298881530762,1.99376281691116,14.2400003969669,-0.000567339300976686,5.19296945659283E-5,0.25,1.28926449292645E-5,-4.80188720120947E-5,1.28857507883667E-5,200.0805,200.0805,32968.9140625,32988.97265625,54.0050592792172,19.5650201324799,25.566563,0,0,0,40,4449,200.0805,32978.943359375,,,,,,,,,,,,,0,,,,,,,,,,,,,,
,19738873.975,200.07495,36712.466796875,-6.22819673713437E-5,3.53381072692211E-6,1,0.999253354069792,40.0298881530762,1.99380832344912,14.2400003969669,-0.000720577712053435,-3.63045181071055E-5,0.25,7.61244896978831E-6,-6.25050712568777E-5,7.57192252040727E-6,200.0733,200.0733,36702.4765625,36722.45703125,53.8940680294865,19.5663059282735,25.566563,0,0,0,40,4449,200.07495,36712.466796875,,,,,,,,,,,,,0,,,,,,,,,,,,,,
,19738948.36,200.06695,40430.18359375,-7.14367703001672E-5,2.89758358221948E-6,1,0.999253354069792,40.0298881530762,1.99395527686835,14.2400003969669,-0.000834635480649363,4.89063369332024E-6,0.25,1.28385097043126E-5,-7.16970882366275E-5,1.28063171405183E-5,200.0677,200.0677,40425.171875,40435.1953125,53.8065256353326,19.5646033471705,26.325863,0,0,0,40,4449,200.06695,40430.18359375,,,,,,,,,,,,,0,,,,,,,,,,,,,,
,19739022.275,200.0609,44125.658203125,-8.24232695985825E-5,3.42005439357147E-6,1,0.999253354069792,40.0298881530762,1.99401229023893,14.2400003969669,-0.000959972113018609,-1.19253890483707E-5,0.25,1.32622829687365E-5,-8.27219765295387E-5,1.32199227240008E-5,200.0609,200.0609,44118.21875,44133.09765625,54.1371544989673,19.5642519819424,25.946213,0,0,0,40,4449,200.0609,44125.658203125,,,,,,,,,,,,,0,,,,,,,,,,,,,,
,19739097.27,200.0522,47871.568359375,-9.22485371639738E-5,3.29038818084362E-6,1,0.999253354069792,40.0298881530762,1.99392038210056,14.2400003969669,-0.00107832048347835,9.46589042319355E-6,0.25,1.68565464670766E-5,-9.25850255678431E-5,1.68162434867118E-5,200.052,200.052,47866.6328125,47876.50390625,53.8127786634865,19.5657304066415,25.566563,0,0,0,40,4449,200.0522,47871.568359375,,,,,,,,,,,,,0,,,,,,,,,,,,,,
,19739172.5,200.04305,51634.6953125,-0.000108594064165134,3.35618894333678E-6,1,0.999253354069792,40.0298881530762,1.99402478418925,14.2400003969669,-0.00127002515082238,1.4444243289305E-5,0.25,2.01344778764431E-5,-0.000108990511660224,2.0088226656323E-5,200.0424,200.0424,51624.6953125,51644.6953125,53.7776053801211,19.5623467989762,26.325863,0,0,0,40,4449,200.04305,51634.6953125,,,,,,,,,,,,,0,,,,,,,,,,,,,,
,19739248.405,200.0342,55427.68359375,-0.000116676010849831,2.8588228036015E-6,1,0.999253354069792,40.0298881530762,1.99395119669547,14.2400003969669,-0.00135703769843689,-2.743281427503E-5,0.25,1.78417782026514E-5,-0.000117097954108493,1.77791976038499E-5,200.0339,200.0339,55422.75,55432.6171875,53.9190801421018,19.5635471438282,25.946213,0,0,0,40,4449,200.0342,55427.68359375,,,,,,,,,,,,,0,,,,,,,,,,,,,,
,19739323.595,200.0257,59186.130859375,-0.000130066724555102,2.78645982584625E-6,1,0.999253354069792,40.0298881530762,1.99383718034095,14.2500000074506,-0.00151489727946296,-1.79302774538172E-5,0.25,2.10057374547148E-5,-0.000130538314831433,2.09400581249566E-5,200.0242,200.0242,59181.171875,59191.08984375,53.9394024836019,19.5636880768476,25.946213,0,0,0,40,4449,200.0257,59186.130859375,,,,,,,,,,,,,0,,,,,,,,,,,,,,
,19739399.23,200.01315,62967.337890625,-0.0001422906515389,3.68612204361745E-6,1,0.999253354069792,40.0298881530762,1.99405199325615,14.2400003969669,-0.00165741355045315,-1.9777751187119E-5,0.25,2.29655047029686E-5,-0.000142806602682115,2.28938560052689E-5,200.0122,200.0122,62954.984375,62979.69140625,53.8549866035249,19.5616109667058,25.946213,0,0,0,40,4449,200.01315,62967.337890625,,,,,,,,,,,,,0,,,,,,,,,,,,,,
,19739474.845,200.0067,66742.765625,-0.000157172201380606,2.97449603396415E-6,1,0.999253354069792,40.0298881530762,1.99383263360267,14.2400003969669,-0.00182739073872158,-4.01116133139267E-5,0.25,2.37546618839649E-5,-0.000157740434051473,2.36702303286712E-5,200.007,200.007,66737.8515625,66747.6796875,53.689281357448,19.5623075656584,25.566563,0,0,0,40,4449,200.0067,66742.765625,,,,,,,,,,,,,0,,,,,,,,,,,,,,
,19739551.06,199.99515,70555.7734375,-0.000170341978763682,3.59400678415039E-6,1,0.999253354069792,40.0298881530762,1.99426952222915,14.2400003969669,-0.00198037726139717,-4.66444785529341E-5,0.25,2.54657096000896E-5,-0.000170957592421106,2.53735477165415E-5,199.9954,199.9954,70550.9453125,70560.6015625,53.6900629859672,19.5611040421639,25.946213,0,0,0,40,4449,199.99515,70555.7734375,,,,,,,,,,,,,0,,,,,,,,,,,,,,
,19739627.025,199.98605,74351.7109375,-0.000180033814928694,3.87709848774391E-6,1,0.999253354069792,40.0298881530762,1.99414330595733,14.2400003969669,-0.00208569215249875,-9.09599643938685E-5,0.25,2.3237261199472E-5,-0.000180680624228804,2.31274743282614E-5,199.9861,199.9861,74349.1015625,74354.3203125,53.7135118415441,19.562590698996,25.946213,0,0,0,40,4449,199.98605,74351.7109375,,,,,,,,,,,,,0,,,,,,,,,,,,,,
,19739704.28,199.9754,78212.421875,-0.000192941180727664,3.14679271169113E-6,1,0.999253354069792,40.0298881530762,1.99419762206487,14.2400003969669,-0.00224124883177258,-6.31299073632245E-5,0.25,2.79346535662279E-5,-0.000193637631142463,2.78278338298077E-5,199.9754,199.9754,78207.2265625,78217.6171875,53.8080888923711,19.5614382246727,25.566563,0,0,0,40,4449,199.9754,78212.421875,,,,,,,,,,,,,0,,,,,,,,,,,,,,
,19739777.255,199.96535,81858.92578125,-0.000204101506139048,4.67886226419639E-6,1,0.999253354069792,40.0298881530762,1.99416231343843,14.2400003969669,-0.0023648541610955,-0.000101309788249479,0.25,2.65028340129231E-5,-0.000204835101388232,2.637966034075E-5,199.9654,199.9654,81856.3984375,81861.453125,53.9409657406403,19.5607518492569,25.566563,0,0,0,40,4449,199.96535,81858.92578125,,,,,,,,,,,,,0,,,,,,,,,,,,,,
,19739850.085,199.9559,85500.046875,-0.000220489087102816,4.58993673959077E-6,1,0.999253354069792,40.0298881530762,1.99418724609177,14.2400003969669,-0.002556389188143,-0.000100079719276283,0.25,2.9456936095487E-5,-0.000221282525830168,2.9327121233818E-5,199.957,199.957,85495.015625,85505.078125,53.8737456879865,19.5583382529272,25.946213,0,0,0,40,4449,199.9559,85500.046875,,,,,,,,,,,,,0,,,,,,,,,,,,,,
,19739919.315,199.947,88961.18359375,-0.00023253688093617,3.33400276158739E-6,1,0.999253354069792,40.0298881530762,1.99417005943007,14.2500000074506,-0.0026979854649893,-9.44137480886509E-5,0.25,3.20486769876265E-5,-0.000233374776681042,3.19155611223732E-5,199.9473,199.9473,88953.8203125,88968.546875,53.7142934700634,19.5582374381058,25.946213,0,0,0,40,4449,199.947,88961.18359375,,,,,,,,,,,,,0,,,,,,,,,,,,,,
,19740008.295,199.93875,87545.98046875,-0.000225591471502028,5.37347656253109E-6,1,0.999253354069792,40.0298881530762,1.99422531455328,14.2400003969669,-0.00261566737002118,-0.000101988298110345,0.25,3.01745238261432E-5,-0.000226403439104255,3.00420500296413E-5,199.9383,199.9383,87543.6484375,87548.3125,53.7627544382557,19.557876992482,25.566563,0,0,0,40,4449,199.93875,87545.98046875,,,,,,,,,,,,,0,,,,,,,,,,,,,,
,19740080.86,199.93715,83917.109375,-0.000213514947544176,3.33159122274036E-6,1,0.999253354069792,40.0298881530762,1.99429013934905,14.2400003969669,-0.00248478536237143,-4.43315757565756E-5,0.25,3.31660695876878E-5,-0.000214288300888822,3.30562365202324E-5,199.9367,199.9367,83904.53125,83929.6875,53.7377423256403,19.5565102588603,25.566563,0,0,0,40,4449,199.93715,83917.109375,,,,,,,,,,,,,0,,,,,,,,,,,,,,
,19740156.935,199.9374,80113.3125,-0.000205098386110774,4.18520301766687E-6,1,0.999253354069792,40.0298881530762,1.99420865936385,14.2400003969669,-0.00238315143203816,-6.32721476128342E-5,0.25,3.00332020066554E-5,-0.000205839334249864,2.9920999740365E-5,199.9372,199.9372,80100.90625,80125.71875,53.9550350539865,19.5575326773024,25.946213,0,0,0,40,4449,199.9374,80113.3125,,,,,,,,,,,,,0,,,,,,,,,,,,,,
,19740228.745,199.94055,76524.91015625,-0.000190409041689191,3.80701201072669E-6,1,0.999253354069792,40.0298881530762,1.99411292958893,14.2400003969669,-0.00221053847303288,-6.92627390417358E-5,0.25,2.69536563547494E-5,-0.000191095923661752,2.68459449516192E-5,199.9397,199.9397,76517.4921875,76532.328125,53.6369122466595,19.5589169218273,25.566563,0,0,0,40,4449,199.94055,76524.91015625,,,,,,,,,,,,,0,,,,,,,,,,,,,,
,19740301.66,199.9459,72880.85546875,-0.000181266531121068,4.96997208543454E-6,1,0.999253354069792,40.0298881530762,1.99426375550639,14.2400003969669,-0.00210211872814839,-7.9946463997885E-5,0.25,2.44239054699037E-5,-0.000181919093676058,2.43167736539716E-5,199.9457,199.9457,72873.4921875,72888.21875,53.9339310839672,19.5599216675923,26.325863,0,0,0,40,4449,199.9459,72880.85546875,,,,,,,,,,,,,0,,,,,,,,,,,,,,
,19740375.36,199.9503,69197.16796875,-0.000166114104023017,4.08908560799522E-6,1,0.999253354069792,40.0298881530762,1.99427801482634,14.2400003969669,-0.00193191664870423,-4.15628906001762E-5,0.25,2.51801050598936E-5,-0.000166715052542633,2.5091307013037E-5,199.9503,199.9503,69194.6875,69199.6484375,53.841698918698,19.5579442657395,25.946213,0,0,0,40,4449,199.9503,69197.16796875,,,,,,,,,,,,,0,,,,,,,,,,,,,,
,19740448.815,199.9552,65526.3828125,-0.0001502356573083,3.35254480525875E-6,1,0.999253354069792,40.0298881530762,1.99403009712206,14.2400003969669,-0.00174751736280262,-3.48470758225928E-5,0.25,2.30151500265206E-5,-0.000150779396611541,2.29354121944329E-5,199.9555,199.9555,65516.453125,65536.3125,53.8760905735442,19.558592015155,26.325863,0,0,0,40,4449,199.9552,65526.3828125,,,,,,,,,,,,,0,,,,,,,,,,,,,,
,19740523.24,199.9604,61802.564453125,-0.000143516399425648,3.52696628390109E-6,1,0.999253354069792,40.0298881530762,1.99393110937584,14.2400003969669,-0.00166854993521725,-3.74945432418049E-5,0.25,2.16146812371461E-5,-0.000144035403354217,2.15369729793942E-5,199.9616,199.9616,61797.69921875,61807.4296875,53.7541565245441,19.5601732933275,25.566563,0,0,0,40,4449,199.9604,61802.564453125,,,,,,,,,,,,,0,,,,,,,,,,,,,,
,19740601.79,199.9666,57879.53125,-0.00012859461770653,4.06888317154104E-6,1,0.999253354069792,40.0298881530762,1.99427249437462,14.2400003969669,-0.00149682288581154,-2.48927267411035E-5,0.25,2.0136120503934E-5,-0.000129060452145108,2.00689114002572E-5,199.9666,199.9666,57869.36328125,57889.69921875,53.8909415154095,19.5586948224508,25.566563,0,0,0,40,4449,199.9666,57879.53125,,,,,,,,,,,,,0,,,,,,,,,,,,,,
,19740679.785,199.97365,53981.552734375,-0.000116115827911717,2.76374406751563E-6,1,0.999253354069792,40.0298881530762,1.99418619255209,14.2400003969669,-0.00135780006312785,1.37108173912293E-5,0.25,2.13758899115183E-5,-0.000116539836172004,2.13260278676567E-5,199.9731,199.9731,53976.40234375,53986.703125,53.8534233464865,19.5622019125707,26.325863,0,0,0,40,4449,199.97365,53981.552734375,,,,,,,,,,,,,0,,,,,,,,,,,,,,
,19740759.07,199.9783,50018.78125,-0.000105180945995372,2.94798043618734E-6,1,0.999253354069792,40.0298881530762,1.99410743788756,14.2400003969669,-0.00122325779846624,-2.57492072818159E-5,0.25,1.5994512465743E-5,-0.00010556142041983,1.59375147333026E-5,199.9777,199.9777,50008.7734375,50028.7890625,53.9823920521596,19.563454913364,26.325863,0,0,0,40,4449,199.9783,50018.78125,,,,,,,,,,,,,0,,,,,,,,,,,,,,
,19740834.485,199.982,46248.41796875,-9.11610650201924E-5,2.8211942216377E-6,1,0.999253354069792,40.0298881530762,1.99425804920401,14.2400003969669,-0.00106526387391845,6.36397510559862E-6,0.25,1.63939160567695E-5,-9.14935206114419E-5,1.63531041301298E-5,199.9819,199.9819,46240.84765625,46255.98828125,53.8471703183326,19.5602888643513,25.946213,0,0,0,40,4449,199.982,46248.41796875,,,,,,,,,,,,,0,,,,,,,,,,,,,,
,19740906.07,199.9857,42669.625,-7.72507081524619E-5,2.90838915415669E-6,1,0.999253354069792,40.0298881530762,1.99432382722978,14.2400003969669,-0.00090802012678617,3.57805077412517E-5,0.25,1.65740490849302E-5,-7.75352994399445E-5,1.65486030620001E-5,199.9848,199.9848,42661.87890625,42677.37109375,53.9714492528903,19.5596028880041,26.325863,0,0,0,40,4449,199.9857,42669.625,,,,,,,,,,,,,0,,,,,,,,,,,,,,
,19740979.09,199.9954,39018.859375,-6.8497140697053E-5,2.33096836477485E-6,1,0.999253354069792,40.0298881530762,1.99423792983017,14.2400003969669,-0.000801526666504163,1.11750369014074E-5,0.25,1.28825807362385E-5,-6.87475249938794E-5,1.28536425448678E-5,199.9951,199.9951,39013.91796875,39023.80078125,53.770570723448,19.5614956155379,26.325863,0,0,0,40,4449,199.9954,39018.859375,,,,,,,,,,,,,0,,,,,,,,,,,,,,
,19741051.145,200.00535,35421.13671875,-5.76310293321747E-5,2.51417203558663E-6,1,0.999253354069792,40.0298881530762,1.99399952876026,14.2400003969669,-0.000676679115190252,2.31078792653153E-5,0.25,1.20487782011097E-5,-5.78429770175358E-5,1.20285175339914E-5,200.0046,200.0046,35411,35431.2734375,54.0058409077365,19.5628518636745,25.946213,0,0,0,40,4449,200.00535,35421.13671875,,,,,,,,,,,,,0,,,,,,,,,,,,,,
,19741132.335,200.01825,31361.166015625,-4.36544946506945E-5,1.42413525591371E-6,1,0.999253354069792,40.0298881530762,1.99398510120516,14.2400003969669,-0.000514101120547615,2.6325967617295E-5,0.25,9.90547186478586E-6,-4.3815864333823E-5,9.89273654209147E-6,200.0182,200.0182,31353.46875,31368.86328125,53.8151235490442,19.5647132082397,25.566563,0,0,0,40,4449,200.01825,31361.166015625,,,,,,,,,,,,,0,,,,,,,,,,,,,,
,19741210.05,200.0269,27478.646484375,-3.11791354543605E-5,1.38418011882065E-6,1,0.999253354069792,40.0298881530762,1.99411109240922,14.2400003969669,-0.000372284232234264,4.80424474468823E-5,0.25,9.6552543440644E-6,-3.12971630311857E-5,9.65501493632671E-6,200.0269,200.0269,27471.037109375,27486.255859375,54.0066225362557,19.5663892587475,26.325863,0,0,0,40,4449,200.0269,27478.646484375,,,,,,,,,,,,,0,,,,,,,,,,,,,,
,19741289.585,200.032,23502.603515625,-2.23079670279364E-5,1.20010295470418E-6,1,0.999253354069792,40.0298881530762,1.99383900880346,14.2400003969669,-0.000267743326808367,4.25275595221896E-5,0.25,7.62830184639761E-6,-2.23931915166431E-5,7.63057885533831E-6,200.0328,200.0328,23497.615234375,23507.591796875,53.9120454854288,19.5671195558779,26.325863,0,0,0,40,4449,200.032,23502.603515625,,,,,,,,,,,,,0,,,,,,,,,,,,,,
,19741368.225,200.03595,19572.4482421875,-9.58524715598696E-6,1.17411712460238E-6,1,0.999253354069792,40.0298881530762,1.99390824003717,14.2400003969669,-0.000122617366176038,6.18587807620092E-5,0.25,7.12471988321198E-6,-9.62602156023413E-6,7.13895990678421E-6,200.0359,200.0359,19569.685546875,19575.2109375,53.9308045698903,19.5660579971575,25.946213,0,0,0,40,4449,200.03595,19572.4482421875,,,,,,,,,,,,,0,,,,,,,,,,,,,,
,19741449.39,200.0338,15517.2954101562,1.89642362474063E-6,7.2454396178104E-7,1,0.999253354069792,40.0298881530762,1.99413027680168,14.2400003969669,1.10891254090138E-5,6.36041137845944E-5,0.25,5.28397840722E-6,1.89725507106093E-6,5.30426473975257E-6,200.0334,200.0334,15507.345703125,15527.2451171875,53.8127786634865,19.5658025784175,25.946213,0,0,0,40,4449,200.0338,15517.2954101562,,,,,,,,,,,,,0,,,,,,,,,,,,,,
,19741530.265,200.03275,11474.6484375,1.29807633139409E-5,1.08469924136764E-6,1,0.999253354069792,40.0298881530762,1.99390953598882,14.2500000074506,0.0001399487281652,6.65290530927357E-5,0.25,3.61752055703562E-6,1.30216428009143E-5,3.64405894317361E-6,200.033,200.033,11464.7841796875,11484.5126953125,53.7088220704288,19.5687913684066,25.946213,0,0,0,40,4449,200.03275,11474.6484375,,,,,,,,,,,,,0,,,,,,,,,,,,,,
,19741609.495,200.02705,7516.28344726563,2.11929071415056E-5,5.37077706078971E-7,1,0.999253354069792,40.0298881530762,1.99418408341681,14.2400003969669,0.00023420234980159,7.58922638230839E-5,0.25,3.01669589100158E-6,2.12627726883232E-5,3.05008089706692E-6,200.0268,200.0268,7511.30810546875,7521.2587890625,53.9245515417365,19.5658056445778,25.946213,0,0,0,40,4449,200.02705,7516.28344726563,,,,,,,,,,,,,0,,,,,,,,,,,,,,
,19741688.415,200.0206,3570.6396484375,2.70087953851326E-5,3.94806341297474E-7,1,0.999253354069792,40.0298881530762,1.99410555868784,14.2400003969669,0.000304336507453439,6.28957524096745E-5,0.25,8.59738722865675E-7,2.71010694496466E-5,8.92017976288438E-7,200.0213,200.0213,3568.05908203125,3573.22021484375,53.8862517442942,19.5664021491083,25.566563,0,0,0,40,4449,200.0206,3570.6396484375,,,,,,,,,,,,,0,,,,,,,,,,,,,,
,19741765.485,200.01055,-282.984573364258,1.52078108103769E-5,4.07359142484311E-7,1,0.999253354069792,40.0298881530762,1.99388995786274,14.2400003969669,0.000172829239836559,2.68642639694419E-5,0.25,-2.70296767453422E-7,1.52605895735584E-5,-2.54711889993796E-7,200.0101,200.0101,-285.51171875,-280.457427978516,54.0511753618519,19.5695712246664,25.946213,0,0,0,40,4449,200.01055,-282.984573364258,,,,,,,,,,,,,0,,,,,,,,,,,,,,
,19741844.705,200.00025,-4237.05590820313,-1.26389551266611E-5,4.6178646950014E-7,1,0.999253354069792,40.0298881530762,1.99402007515071,14.2400003969669,-0.000139440641280475,-4.65308579813437E-5,0.25,-1.91151542646049E-6,-1.26805062101308E-5,-1.93182965352275E-6,200.0005,200.0005,-4244.5556640625,-4229.55615234375,54.0386693055442,19.5695963076139,26.325863,0,0,0,40,4449,200.00025,-4237.05590820313,,,,,,,,,,,,,0,,,,,,,,,,,,,,
,19741915.215,199.98755,-7761.31005859375,-1.72919824324708E-5,8.06258456467925E-7,1,0.999253354069792,40.0298881530762,1.99397243832254,14.2500000074506,-0.000190407045985498,-6.57578125302211E-5,0.25,-2.80043237470359E-6,-1.73486420949302E-5,-2.82884909325073E-6,199.9873,199.9873,-7763.81201171875,-7758.80810546875,53.8854701157749,19.5697648052894,25.946213,0,0,0,40,4449,199.98755,-7761.31005859375,,,,,,,,,,,,,0,,,,,,,,,,,,,,
,19741986.28,199.97605,-11314.8286132813,-1.17356919627129E-5,9.74203469837935E-7,1,0.999253354069792,40.0298881530762,1.99405941216335,14.2400003969669,-0.000125241902805492,-6.75948826388623E-5,0.25,-3.9274053679383E-6,-1.1771958777332E-5,-3.9536773945467E-6,199.9761,199.9761,-11317.2255859375,-11312.431640625,54.0902567878134,19.5686546757442,25.946213,0,0,0,40,4449,199.97605,-11314.8286132813,,,,,,,,,,,,,0,,,,,,,,,,,,,,
,19742056.58,199.9674,-14828.392578125,-2.36767550274259E-6,1.06717226576818E-6,1,0.999253354069792,40.0298881530762,1.99407031093015,14.2400003969669,-1.78548777068365E-5,-5.63164921543018E-5,0.25,-4.55909263056322E-6,-2.37091887055142E-6,-4.57739804011946E-6,199.9674,199.9674,-14830.994140625,-14825.791015625,54.0050592792172,19.5691777054468,26.325863,0,0,0,40,4449,199.9674,-14828.392578125,,,,,,,,,,,,,0,,,,,,,,,,,,,,
,19742127.97,199.9562,-18398.6669921875,6.89046512037416E-6,8.67599028383227E-7,1,0.999253354069792,40.0298881530762,1.99388898566822,14.2400003969669,9.2066857416562E-5,-6.70513849738299E-5,0.25,-7.11504461532228E-6,6.92195278172418E-6,-7.13217187526351E-6,199.9562,199.9562,-18408.705078125,-18388.62890625,53.9620697106595,19.5725605316993,25.946213,0,0,0,40,4449,199.9562,-18398.6669921875,,,,,,,,,,,,,0,,,,,,,,,,,,,,
,19742199.805,199.95115,-21986.18359375,1.77348476777496E-5,1.05550380453626E-6,1,0.999253354069792,40.0298881530762,1.99406153368685,14.2400003969669,0.000215594211770189,-4.94438045080143E-5,0.25,-7.44404788502341E-6,1.78041416826362E-5,-7.45061826892508E-6,199.9494,199.9494,-21996.021484375,-21976.345703125,53.9878634517942,19.5713212839761,26.325863,0,0,0,40,4449,199.95115,-21986.18359375,,,,,,,,,,,,,0,,,,,,,,,,,,,,
,19742270.08,199.943,-25499.4404296875,2.73536914055048E-5,1.87973886358002E-6,1,0.999253354069792,40.0298881530762,1.99398384418356,14.2400003969669,0.00032491135163098,-3.24871577048927E-5,0.25,-7.61821252946266E-6,2.74564010409404E-5,-7.61504226615949E-6,199.9418,199.9418,-25504.54296875,-25494.337890625,54.0761874744673,19.5731510404646,26.325863,0,0,0,40,4449,199.943,-25499.4404296875,,,,,,,,,,,,,0,,,,,,,,,,,,,,
,19742342.715,199.9367,-29129.7109375,3.65623471321466E-5,1.79032832013847E-6,1,0.999253354069792,40.0298881530762,1.9938495260913,14.2500000074506,0.000432018781723803,-3.04867561098958E-5,0.25,-9.0411630129934E-6,3.66984056359505E-5,-9.03303738929797E-6,199.9367,199.9367,-29137.228515625,-29122.193359375,53.9675411102942,19.5735126855694,25.946213,0,0,0,40,4449,199.9367,-29129.7109375,,,,,,,,,,,,,0,,,,,,,,,,,,,,
,19742413.97,199.92995,-32690.59375,4.98508215981481E-5,1.99601289195109E-6,1,0.999253354069792,40.0298881530762,1.99396897042285,14.2500000074506,0.000588622867636237,-3.90040284582676E-5,0.25,-1.21006434697546E-5,5.00360905738496E-5,-1.20888587673095E-5,199.9293,199.9293,-32700.783203125,-32680.404296875,54.0691528177942,19.5732066609743,25.946213,0,0,0,40,4449,199.92995,-32690.59375,,,,,,,,,,,,,0,,,,,,,,,,,,,,
,19742483.555,199.9232,-36168.234375,6.2231891190823E-5,2.16432508236812E-6,1,0.999253354069792,40.0298881530762,1.99360015775884,14.2400003969669,0.000729313807632969,-1.77567470082646E-5,0.25,-1.2375869179589E-5,6.24602479180284E-5,-1.23518178854817E-5,199.9224,199.9224,-36173.27734375,-36163.19140625,54.0050592792172,19.5766318501576,26.325863,0,0,0,40,4449,199.9232,-36168.234375,,,,,,,,,,,,,0,,,,,,,,,,,,,,
,19742553.405,199.9183,-39661.046875,6.68784152560737E-5,2.26508599162657E-6,1,0.999253354069792,40.0298881530762,1.99381696332203,14.2400003969669,0.000780778037141048,-1.40126517795726E-6,0.25,-1.17389525352564E-5,6.71221540651195E-5,-1.1707813717936E-5,199.9176,199.9176,-39665.9609375,-39656.1328125,53.8846884872557,19.5741326313978,25.946213,0,0,0,40,4449,199.9183,-39661.046875,,,,,,,,,,,,,0,,,,,,,,,,,,,,
,19742624.285,199.9129,-43201.462890625,8.15375473403521E-5,2.50054968851736E-6,1,0.999253354069792,40.0298881530762,1.99397550250283,14.2400003969669,0.000953185829360363,-8.59529093430156E-6,0.25,-1.49197248453956E-5,8.18353731028738E-5,-1.48839902536315E-5,199.9136,199.9136,-43208.984375,-43193.94140625,54.0316346488711,19.5732744376686,26.325863,0,0,0,40,4449,199.9129,-43201.462890625,,,,,,,,,,,,,0,,,,,,,,,,,,,,
,19742697.57,199.90815,-46861.927734375,9.06413557712733E-5,3.14452366967942E-6,1,0.999253354069792,40.0298881530762,1.99395787325419,14.2400003969669,0.00106048168298408,-1.46209602009237E-5,0.25,-1.70325272750269E-5,9.09729211075723E-5,-1.69944987231172E-5,199.9082,199.9082,-46867.078125,-46856.77734375,54.0050592792172,19.5737617560407,25.946213,0,0,0,40,4449,199.90815,-46861.927734375,,,,,,,,,,,,,0,,,,,,,,,,,,,,
,19742775.715,199.9003,-50767.65625,0.000102817460588991,2.9044621726641E-6,1,0.999253354069792,40.0298881530762,1.99406417352827,14.2500000074506,0.00120149125966212,-7.89531313486364E-6,0.25,-1.85533723963844E-5,0.000103192766397115,-1.85077674915367E-5,199.9007,199.9007,-50775.1953125,-50760.1171875,54.0558651329673,19.5727411684471,25.946213,0,0,0,40,4449,199.9003,-50767.65625,,,,,,,,,,,,,0,,,,,,,,,,,,,,
,19742847.69,199.8907,-54365.224609375,0.00011693678379684,3.41235249261341E-6,1,0.999253354069792,40.0298881530762,1.99399027740488,14.2500000074506,0.00136035762156618,2.60263907227147E-5,0.25,-1.80114234158286E-5,0.000117360365498239,-1.7949066194772E-5,199.8909,199.8909,-54372.53515625,-54357.9140625,54.0019327651403,19.5749285048605,25.946213,0,0,0,40,4449,199.8907,-54365.224609375,,,,,,,,,,,,,0,,,,,,,,,,,,,,
,19742918.035,199.88995,-57882.73828125,0.000126184584595423,4.26433167581224E-6,1,0.999253354069792,40.0298881530762,1.99378097699883,14.2400003969669,0.00146833548519491,2.49566915091679E-5,0.25,-1.97114799026938E-5,0.000126641959428686,-1.96453525673951E-5,199.89,199.89,-57890.33203125,-57875.14453125,54.0933833018903,19.576776424059,25.946213,0,0,0,40,4449,199.88995,-57882.73828125,,,,,,,,,,,,,0,,,,,,,,,,,,,,
,19742990.26,199.8879,-61490.65234375,0.000136591768320843,3.01822918195997E-6,1,0.999253354069792,40.0298881530762,1.99415689612091,14.2400003969669,0.00159240268828972,1.15949957886754E-5,0.25,-2.26982567871269E-5,0.000137088318564011,-2.26316159727667E-5,199.8885,199.8885,-61498.265625,-61483.0390625,54.1527870693519,19.5745494115157,26.325863,0,0,0,40,4449,199.8879,-61490.65234375,,,,,,,,,,,,,0,,,,,,,,,,,,,,
,19743061.155,199.8891,-65036.576171875,0.000149247037424978,3.77777245300029E-6,1,0.999253354069792,40.0298881530762,1.99403249682415,14.2400003969669,0.00173699470240748,2.90265808986749E-5,0.25,-2.33572758234346E-5,0.000149788049907806,-2.32797194379352E-5,199.8897,199.8897,-65041.60546875,-65031.546875,53.9065740857942,19.5740972365303,26.325863,0,0,0,40,4449,199.8891,-65036.576171875,,,,,,,,,,,,,0,,,,,,,,,,,,,,
,19743138.8,199.88795,-68914.40625,0.000163275340481177,2.91589114972498E-6,1,0.999253354069792,40.0298881530762,1.99413105686833,14.2400003969669,0.00189343589359806,7.157647556771E-5,0.25,-2.20381470083317E-5,0.000163863484976284,-2.19414477733072E-5,199.8887,199.8887,-68924.4453125,-68904.3671875,53.9667594817749,19.5737700915912,25.946213,0,0,0,40,4449,199.88795,-68914.40625,,,,,,,,,,,,,0,,,,,,,,,,,,,,
,19743218.65,199.8825,-72903.9921875,0.000181361351849162,3.47082335627541E-6,1,0.999253354069792,40.0298881530762,1.99425674366135,14.2500000074506,0.00210923091226192,4.53506103162232E-5,0.25,-2.74934593323351E-5,0.000182017867794922,-2.73968246180713E-5,199.8828,199.8828,-72911.4765625,-72896.5078125,54.0777507315057,19.5729768496957,25.566563,0,0,0,40,4449,199.8825,-72903.9921875,,,,,,,,,,,,,0,,,,,,,,,,,,,,
,19743297.495,199.8747,-76844.17578125,0.000197158125189284,4.98464100079377E-6,1,0.999253354069792,40.0298881530762,1.99441954442233,14.2400003969669,0.00229225806026746,5.43052510715753E-5,0.25,-2.94465330790991E-5,0.000197871406417653,-2.93403303832676E-5,199.8747,199.8747,-76849.34375,-76839.0078125,53.9151719995057,19.5717373932981,25.566563,0,0,0,40,4449,199.8747,-76844.17578125,,,,,,,,,,,,,0,,,,,,,,,,,,,,
,19743375.86,199.8639,-80761.9375,0.000210856168283224,4.03651536304536E-6,1,0.999253354069792,40.0298881530762,1.99429524296366,14.2400003969669,0.00245152910160865,5.71775736212482E-5,0.25,-3.15711901691372E-5,0.000211619162714737,-3.14582840070912E-5,199.8634,199.8634,-80772.0390625,-80751.8359375,54.0980730730057,19.5746972866564,26.325863,0,0,0,40,4449,199.8639,-80761.9375,,,,,,,,,,,,,0,,,,,,,,,,,,,,
,19743455.015,199.85275,-84716.80078125,0.000224124500309876,3.93330440643563E-6,1,0.999253354069792,40.0298881530762,1.99428036474307,14.2400003969669,0.00260416912661948,7.00303149742394E-5,0.25,-3.2740673534349E-5,0.000224934727562505,-3.26182687954425E-5,199.8525,199.8525,-84724.2265625,-84709.375,53.8854701157749,19.5751818833401,26.325863,0,0,0,40,4449,199.85275,-84716.80078125,,,,,,,,,,,,,0,,,,,,,,,,,,,,
,19743528.58,199.8373,-88391.65625,0.000235662705623211,3.19246795588968E-6,1,0.999253354069792,40.0298881530762,1.99405958196685,14.2400003969669,0.00273437181366186,9.42154875769794E-5,0.25,-3.26088072774654E-5,0.000236512855308647,-3.24742335521629E-5,199.8373,199.8373,-88396.75,-88386.5625,54.169982896775,19.5765924936218,26.325863,0,0,0,40,4449,199.8373,-88391.65625,,,,,,,,,,,,,0,,,,,,,,,,,,,,
,19743622.04,199.82015,-87889.1640625,0.000230581075415698,4.53902744660047E-6,1,0.999253354069792,40.0298881530762,1.99408390811633,14.2400003969669,0.00267412415708269,9.97785622007437E-5,0.25,-3.12355731143486E-5,0.000231412319845128,-3.11015156885523E-5,199.8195,199.8195,-87898.90625,-87879.421875,54.0019327651403,19.5750515595954,26.325863,0,0,0,40,4449,199.82015,-87889.1640625,,,,,,,,,,,,,0,,,,,,,,,,,,,,
,19743695.445,199.8118,-84218.734375,0.000219600588687969,3.17919387303346E-6,1,0.999253354069792,40.0298881530762,1.9941036766186,14.2400003969669,0.00254758382572597,9.05409661839958E-5,0.25,-3.01445109802947E-5,0.000220392723188837,-3.00178062355816E-5,199.8124,199.8124,-84226.3046875,-84211.1640625,54.1582584689865,19.5750949651724,25.566563,0,0,0,40,4449,199.8118,-84218.734375,,,,,,,,,,,,,0,,,,,,,,,,,,,,
,19743774.175,199.8034,-80286.34375,0.00020711089396195,4.770977855901E-6,1,0.999253354069792,40.0298881530762,1.99419420870715,14.2400003969669,0.00240057372930232,9.81907933149864E-5,0.25,-2.73012483784045E-5,0.000207856841150266,-2.7177435439137E-5,199.8034,199.8034,-80293.96875,-80278.71875,53.9933348514288,19.5761330045161,25.946213,0,0,0,40,4449,199.8034,-80286.34375,,,,,,,,,,,,,0,,,,,,,,,,,,,,
,19743851.415,199.8004,-76426.12109375,0.00019371580799012,3.30470784649452E-6,1,0.999253354069792,40.0298881530762,1.99434401974743,14.2400003969669,0.00225858476190045,1.6359785363411E-5,0.25,-3.21971823479287E-5,0.000194420560913387,-3.2104075250651E-5,199.8002,199.8002,-76431.0703125,-76421.171875,54.0371060485057,19.5742426169853,25.946213,0,0,0,40,4449,199.8004,-76426.12109375,,,,,,,,,,,,,0,,,,,,,,,,,,,,
,19743923.555,199.79835,-72820.4375,0.000179823804296962,2.78146999746925E-6,1,0.999253354069792,40.0298881530762,1.99417994622387,14.2400003969669,0.00209564737127408,1.98055522488706E-5,0.25,-2.94807996415765E-5,0.000180477605194434,-2.93926408985899E-5,199.7976,199.7976,-72827.875,-72813,54.0019327651403,19.5729870991028,25.946213,0,0,0,40,4449,199.79835,-72820.4375,,,,,,,,,,,,,0,,,,,,,,,,,,,,
,19743994.52,199.7987,-69275.3828125,0.000167522915192802,3.29412588164163E-6,1,0.999253354069792,40.0298881530762,1.99419587852283,14.2400003969669,0.00195010001815741,3.11710791257535E-5,0.25,-2.63418824694596E-5,0.000168130807176855,-2.62555799412364E-5,199.7989,199.7989,-69280.203125,-69270.5625,54.1684196397365,19.5739984788602,26.325863,0,0,0,40,4449,199.7987,-69275.3828125,,,,,,,,,,,,,0,,,,,,,,,,,,,,
,19744066.57,199.8001,-65675.19140625,0.000155056042687818,3.42276308858219E-6,1,0.999253354069792,40.0298881530762,1.9941451869069,14.2400003969669,0.00179661623252367,7.67335467352686E-5,0.25,-2.01560159843341E-5,0.000155614207818859,-2.0061238900817E-5,199.7991,199.7991,-65682.796875,-65667.5859375,53.9722308814096,19.5722843560402,25.946213,0,0,0,40,4449,199.8001,-65675.19140625,,,,,,,,,,,,,0,,,,,,,,,,,,,,
,19744137.44,199.8051,-62131.869140625,0.00014494097094842,3.66336798363473E-6,1,0.999253354069792,40.0298881530762,1.99414167731095,14.2400003969669,0.00169052107721119,7.7541894223932E-6,0.25,-2.44872352074386E-5,0.000145468697853157,-2.44179410345326E-5,199.8051,199.8051,-62134.4609375,-62129.27734375,54.119177043025,19.5728800249405,26.325863,0,0,0,40,4449,199.8051,-62131.869140625,,,,,,,,,,,,,0,,,,,,,,,,,,,,
,19744208.485,199.8081,-58579.193359375,0.000131256875005604,4.03088855215749E-6,1,0.999253354069792,40.0298881530762,1.99402634400095,14.2500000074506,0.0015319311603789,6.91628562937532E-7,0.25,-2.27342583604966E-5,0.000131735365467681,-2.26732193531048E-5,199.8094,199.8094,-58586.9375,-58571.44921875,53.9464371402749,19.5738147351522,25.566563,0,0,0,40,4449,199.8081,-58579.193359375,,,,,,,,,,,,,0,,,,,,,,,,,,,,
,19744278.18,199.8144,-55096.236328125,0.000118778087842241,2.362631788027E-6,1,0.999253354069792,40.0298881530762,1.99415335365802,14.2400003969669,0.00138912765962817,-1.52398207866145E-5,0.25,-2.19732619764146E-5,0.000119212560831201,-2.19226778432602E-5,199.8151,199.8151,-55098.59375,-55093.87890625,54.0316346488711,19.5731079015969,25.566563,0,0,0,40,4449,199.8144,-55096.236328125,,,,,,,,,,,,,0,,,,,,,,,,,,,,
,19744349.305,199.8236,-51543.326171875,0.000107470355980963,2.80527201670257E-6,1,0.999253354069792,40.0298881530762,1.99402627407214,14.2400003969669,0.001259873478892,-3.14547826573734E-5,0.25,-2.14407936067051E-5,0.000107865105681568,-2.14002427550886E-5,199.8236,199.8236,-51550.75,-51535.90234375,54.0691528177942,19.5725412421276,25.946213,0,0,0,40,4449,199.8236,-51543.326171875,,,,,,,,,,,,,0,,,,,,,,,,,,,,
,19744418.71,199.8304,-48072.876953125,9.61994416961555E-5,3.2466288796445E-6,1,0.999253354069792,40.0298881530762,1.99405047042553,14.2400003969669,0.00112676059551192,-2.24155612192729E-5,0.25,-1.8685688920025E-5,9.65522368536718E-5,-1.86474837368684E-5,199.8318,199.8318,-48077.74609375,-48068.0078125,53.9464371402749,19.5726357748017,25.566563,0,0,0,40,4449,199.8304,-48072.876953125,,,,,,,,,,,,,0,,,,,,,,,,,,,,
,19744491.475,199.8399,-44437.380859375,8.42112005584091E-5,2.02689411873079E-6,1,0.999253354069792,40.0298881530762,1.99383170199808,14.2500000074506,0.000989647068649495,-3.92276310861719E-5,0.25,-1.80879265565775E-5,8.4521863927057E-5,-1.80603296519793E-5,199.8398,199.8398,-44444.921875,-44429.83984375,53.8487335753711,19.572982197448,26.325863,0,0,0,40,4449,199.8399,-44437.380859375,,,,,,,,,,,,,0,,,,,,,,,,,,,,
,19744568.85,199.8483,-40569.591796875,7.61265890178244E-5,2.00683628738175E-6,1,0.999253354069792,40.0298881530762,1.99391441276803,14.2400003969669,0.000891368083442898,-1.64381127608838E-5,0.25,-1.4672347891878E-5,7.64056143494387E-5,-1.46414596348366E-5,199.8483,199.8483,-40577.70703125,-40561.4765625,54.1856154671596,19.5721716880704,25.566563,0,0,0,40,4449,199.8483,-40569.591796875,,,,,,,,,,,,,0,,,,,,,,,,,,,,
,19744644.98,199.85985,-36766.89453125,6.14448769081549E-5,1.54013728691924E-6,1,0.999253354069792,40.0298881530762,1.99398941935987,14.2400003969669,0.0007217539830029,-2.63315712269923E-5,0.25,-1.29957099174461E-5,6.16713089011946E-5,-1.29746624958492E-5,199.8591,199.8591,-36774.40234375,-36759.38671875,53.8901598868903,19.5708510148584,25.946213,0,0,0,40,4449,199.85985,-36766.89453125,,,,,,,,,,,,,0,,,,,,,,,,,,,,
,19744719.155,199.8701,-33059.537109375,4.88278031337337E-5,1.56418549416465E-6,1,0.999253354069792,40.0298881530762,1.99396662600801,14.2500000074506,0.000575762577034117,-3.37050656668302E-5,0.25,-1.14552832260913E-5,4.90089410439724E-5,-1.14423787112312E-5,199.8696,199.8696,-33061.9140625,-33057.16015625,53.8596763746403,19.5693461184967,26.325863,0,0,0,40,4449,199.8701,-33059.537109375,,,,,,,,,,,,,0,,,,,,,,,,,,,,
,19744793.09,199.88715,-29363.974609375,3.73258034734363E-5,1.85143319509312E-6,1,0.999253354069792,40.0298881530762,1.99413568539051,14.2400003969669,0.000439661187242616,-2.28383144221569E-5,0.25,-8.498392721649E-6,3.74639773691794E-5,-8.48757468846397E-6,199.8863,199.8863,-29373.96875,-29353.98046875,54.0222551066403,19.5697168514997,25.946213,0,0,0,40,4449,199.88715,-29363.974609375,,,,,,,,,,,,,0,,,,,,,,,,,,,,
,19744864.52,199.90135,-25795.9375,2.82762059221341E-5,1.20604029774492E-6,1,0.999253354069792,40.0298881530762,1.99401176358058,14.2400003969669,0.000336268842097365,-3.58561853574417E-5,0.25,-8.07574818826368E-6,2.83826353810683E-5,-8.07317042162118E-6,199.9011,199.9011,-25801.11328125,-25790.76171875,53.9620697106595,19.5709390412133,26.325863,0,0,0,40,4449,199.90135,-25795.9375,,,,,,,,,,,,,0,,,,,,,,,,,,,,
,19744943.83,199.91725,-21830.8486328125,1.64941338388469E-5,1.13310849819387E-6,1,0.999253354069792,40.0298881530762,1.9942146197754,14.2400003969669,0.000202359644537401,-5.65433517940446E-5,0.25,-7.8547759250746E-6,1.65596056345488E-5,-7.86410793668881E-6,199.9171,199.9171,-21838.400390625,-21823.296875,54.0058409077365,19.567005946281,25.566563,0,0,0,40,4449,199.91725,-21830.8486328125,,,,,,,,,,,,,0,,,,,,,,,,,,,,
,19745023.615,199.9296,-17843.392578125,5.35335309856532E-6,8.2416135186858E-7,1,0.999253354069792,40.0298881530762,1.99429641738945,14.2400003969669,7.15662963602038E-5,-5.22392185947796E-5,0.25,-5.53977846461198E-6,5.37783602635946E-6,-5.55312874013265E-6,199.9296,199.9296,-17850.7265625,-17836.05859375,53.8815619731788,19.5651093214847,26.325863,0,0,0,40,4449,199.9296,-17843.392578125,,,,,,,,,,,,,0,,,,,,,,,,,,,,
,19745104.575,199.9392,-13798.2661132812,-4.91657145315723E-6,7.55091321856786E-7,1,0.999253354069792,40.0298881530762,1.99401548292062,14.2500000074506,-4.67473411153406E-5,-6.12544220331324E-5,0.25,-4.55232389833055E-6,-4.92862572692262E-6,-4.57337039863274E-6,199.9392,199.9392,-13803.146484375,-13793.3857421875,53.8424805472172,19.564673782721,26.325863,0,0,0,40,4449,199.9392,-13798.2661132812,,,,,,,,,,,,,0,,,,,,,,,,,,,,
,19745184.625,199.9431,-9797.94580078125,-1.65994387823551E-5,7.3251171693371E-7,1,0.999253354069792,40.0298881530762,1.99408517643954,14.2400003969669,-0.000181958095443034,-6.79253960730904E-5,0.25,-3.11170701108303E-6,-1.66533965840474E-5,-3.14044612498185E-6,199.9431,199.9431,-9800.314453125,-9795.5771484375,53.6978792711595,19.5647236709147,26.325863,0,0,0,40,4449,199.9431,-9797.94580078125,,,,,,,,,,,,,0,,,,,,,,,,,,,,
,19745266.805,199.94595,-5689.21533203125,-2.42263654888309E-5,4.50351768132319E-7,1,0.999253354069792,40.0298881530762,1.99396865530853,14.2500000074506,-0.000270531698831222,-7.04320715066136E-5,0.25,-2.00853945868004E-6,-2.4307851102278E-5,-2.04176601091593E-6,199.9456,199.9456,-5691.638671875,-5686.7919921875,53.8753089450249,19.5651428964598,26.325863,0,0,0,40,4449,199.94595,-5689.21533203125,,,,,,,,,,,,,0,,,,,,,,,,,,,,
,19745347.455,199.945,-1657.76873779297,-2.66413404508567E-5,3.13923415334459E-7,1,0.999253354069792,40.0298881530762,1.99416178660773,14.2400003969669,-0.000299368610360099,-6.6855979350192E-5,0.25,-1.27287613007912E-6,-2.673195950657E-5,-1.30621219961102E-6,199.945,199.945,-1662.78149414062,-1652.75598144531,53.9597248251019,19.5638087316426,26.325863,0,0,0,40,4449,199.945,-1657.76873779297,,,,,,,,,,,,,0,,,,,,,,,,,,,,
,19745426.345,199.94205,2280.74243164062,2.39351775922265E-6,3.95382206951153E-7,1,0.999253354069792,40.0298881530762,1.99416178964153,14.2400003969669,2.56980499395114E-5,1.29032009066966E-5,0.25,7.23015254826276E-7,2.40099837218801E-6,7.28111915532632E-7,199.9405,199.9405,2270.98486328125,2290.5,54.1316830993327,19.5628781584539,25.946213,0,0,0,40,4449,199.94205,2280.74243164062,,,,,,,,,,,,,0,,,,,,,,,,,,,,
,19745505.7,199.93495,6247.87890625,1.73814549497616E-5,6.16150990706139E-7,1,0.999253354069792,40.0298881530762,1.99432320947039,14.2400003969669,0.000193299147228884,5.53172444427088E-5,0.25,1.86255188611799E-6,1.74394669824244E-5,1.88784533239793E-6,199.9347,199.9347,6245.39453125,6250.36328125,53.8745273165057,19.5628875929945,25.946213,0,0,0,40,4449,199.93495,6247.87890625,,,,,,,,,,,,,0,,,,,,,,,,,,,,
,19745582.965,199.92575,10111.6196289062,1.53571019477582E-5,7.93748138450927E-7,1,0.999253354069792,40.0298881530762,1.99400810435776,14.2400003969669,0.000167877992117879,6.54640186459371E-5,0.25,3.11046497281288E-6,1.54067791120442E-5,3.13785521463034E-6,199.9253,199.9253,10109.087890625,10114.1513671875,53.8862517442942,19.5638112409764,26.325863,0,0,0,40,4449,199.92575,10111.6196289062,,,,,,,,,,,,,0,,,,,,,,,,,,,,
,19745661.895,199.91115,14057.1147460938,5.43407351124617E-6,1.2667925389205E-6,1,0.999253354069792,40.0298881530762,1.99403415579648,14.2400003969669,5.23656758142632E-5,6.3687506644825E-5,0.25,4.67712660174392E-6,5.44778469596276E-6,4.6991692029861E-6,199.9112,199.9112,14052.2822265625,14061.947265625,53.9386208550826,19.5617440110295,25.946213,0,0,0,40,4449,199.91115,14057.1147460938,,,,,,,,,,,,,0,,,,,,,,,,,,,,
,19745741.97,199.9011,18057.25,-4.63841064330232E-6,1.46821584926493E-6,1,0.999253354069792,40.0298881530762,1.99409041006755,14.2400003969669,-6.45108021652054E-5,5.9699556733574E-5,0.25,6.07447319681403E-6,-4.66100676399125E-6,6.09044868291802E-6,199.9011,199.9011,18054.73046875,18059.76953125,53.862021260198,19.5638886859073,25.566563,0,0,0,40,4449,199.9011,18057.25,,,,,,,,,,,,,0,,,,,,,,,,,,,,
,19745817.165,199.8884,21815.0048828125,-1.48788575391926E-5,8.05668027818436E-7,1,0.999253354069792,40.0298881530762,1.99412618160017,14.2400003969669,-0.000182521494401361,5.09264526620727E-5,0.25,7.07872052236141E-6,-1.49379254783943E-5,7.08711859379091E-6,199.8895,199.8895,21802.26171875,21827.748046875,53.9261147987749,19.5620857979717,25.946213,0,0,0,40,4449,199.8884,21815.0048828125,,,,,,,,,,,,,0,,,,,,,,,,,,,,
,19745890.955,199.87865,25502.7421875,-2.76519081284995E-5,1.69855835402839E-6,1,0.999253354069792,40.0298881530762,1.99401941343036,14.2400003969669,-0.000327247509995339,2.58613812863302E-5,0.25,7.08518206147382E-6,-2.77551335975284E-5,7.07985158691672E-6,199.8789,199.8789,25500.0078125,25505.4765625,53.9581615680634,19.5611656838007,25.946213,0,0,0,40,4449,199.87865,25502.7421875,,,,,,,,,,,,,0,,,,,,,,,,,,,,
,19745966.935,199.86575,29301.1865234375,-3.87007677655855E-5,1.7096196651342E-6,1,0.999253354069792,40.0298881530762,1.99433041728597,14.2400003969669,-0.000461144852646376,5.38813439624826E-5,0.25,1.14764286525011E-5,-3.88469297264417E-5,1.14744253263942E-5,199.8661,199.8661,29293.794921875,29308.578125,53.9354943410057,19.5598391059121,25.946213,0,0,0,40,4449,199.86575,29301.1865234375,,,,,,,,,,,,,0,,,,,,,,,,,,,,
,19746040.945,199.8549,33002.6796875,-5.13041451136661E-5,2.04199665883659E-6,1,0.999253354069792,40.0298881530762,1.99434833864858,14.2400003969669,-0.000596472813492001,-1.41003675262685E-5,0.25,7.66625640529948E-6,-5.14897958505625E-5,7.63758576025861E-6,199.8549,199.8549,32997.7109375,33007.6484375,53.5900145355057,19.5575645322456,26.325863,0,0,0,40,4449,199.8549,33002.6796875,,,,,,,,,,,,,0,,,,,,,,,,,,,,
,19746116.68,199.8448,36787.28125,-6.26403575669141E-5,2.17185815642507E-6,1,0.999253354069792,40.0298881530762,1.99440654786401,14.2400003969669,-0.000735293787241786,2.31064244130134E-5,0.25,1.29182863483214E-5,-6.28708719333015E-5,1.28956878724724E-5,199.8445,199.8445,36779.7578125,36794.8046875,53.8542049750057,19.5570849495897,25.946213,0,0,0,40,4449,199.8448,36787.28125,,,,,,,,,,,,,0,,,,,,,,,,,,,,
,19746189.245,199.8364,40413.3203125,-7.20552791302713E-5,1.78262864806227E-6,1,0.999253354069792,40.0298881530762,1.99433225231536,14.2400003969669,-0.000843892894025639,1.57162167452064E-5,0.25,1.39012694794022E-5,-7.23194254505347E-5,1.38720747885343E-5,199.8344,199.8344,40408.265625,40418.375,53.7940195790249,19.5577777763298,25.946213,0,0,0,40,4449,199.8364,40413.3203125,,,,,,,,,,,,,0,,,,,,,,,,,,,,
,19746261.755,199.8295,44036.40234375,-8.38630830651981E-5,3.02432838652932E-6,1,0.999253354069792,40.0298881530762,1.99409420650567,14.2400003969669,-0.000979109771932152,1.2387198966886E-6,0.25,1.46743280271373E-5,-8.4168916781756E-5,1.4635279679338E-5,199.8295,199.8295,44031.71484375,44041.08984375,53.7416504682365,19.5575868254106,25.946213,0,0,0,40,4449,199.8295,44036.40234375,,,,,,,,,,,,,0,,,,,,,,,,,,,,
,19746335.79,199.8229,47739.744140625,-9.46321713787246E-5,3.38162447492931E-6,1,0.999253354069792,40.0298881530762,1.99419598233583,14.2400003969669,-0.00110447572528783,-1.0102828996275E-6,0.25,1.63460222080626E-5,-9.49770668738329E-5,1.63013829840075E-5,199.8225,199.8225,47734.57421875,47744.9140625,53.9925532229096,19.5600882759616,25.946213,0,0,0,40,4449,199.8229,47739.744140625,,,,,,,,,,,,,0,,,,,,,,,,,,,,
,19746416.33,199.8166,51762.705078125,-0.000107840670923807,2.7139069364209E-6,1,0.999253354069792,40.0298881530762,1.99420622271591,14.2400003969669,-0.00126179673790316,1.70147518103571E-5,0.25,2.02305218764237E-5,-0.000108235434586366,2.01853985946718E-5,199.817,199.817,51752.62890625,51772.78125,53.8940680294865,19.5598728801387,25.566563,0,0,0,40,4449,199.8166,51762.705078125,,,,,,,,,,,,,0,,,,,,,,,,,,,,
,19746494.925,199.81025,55690.24609375,-0.000121557448622348,2.44067496739974E-6,1,0.999253354069792,40.0298881530762,1.99391860378245,14.2400003969669,-0.00142155530146385,1.6067835640457E-5,0.25,2.25291592713634E-5,-0.000122002148106591,2.24775695890333E-5,199.8101,199.8101,55685.38671875,55695.10546875,53.8768722020634,19.5612388827982,26.325863,0,0,0,40,4449,199.81025,55690.24609375,,,,,,,,,,,,,0,,,,,,,,,,,,,,
,19746567.29,199.80925,59308.984375,-0.000133325665754741,2.3299576616805E-6,1,0.999253354069792,40.0298881530762,1.99412720223004,14.2400003969669,-0.00154791034262279,-4.81562772945709E-5,0.25,1.89045691388256E-5,-0.00013380723479278,1.88281193048996E-5,199.8088,199.8088,59298.828125,59319.140625,53.8964129150442,19.5577589145324,25.946213,0,0,0,40,4449,199.80925,59308.984375,,,,,,,,,,,,,0,,,,,,,,,,,,,,
,19746641.985,199.81165,63042.599609375,-0.000147154298126513,3.71074207383443E-6,1,0.999253354069792,40.0298881530762,1.99431293504263,14.2400003969669,-0.00171856995908226,4.18080912708041E-6,0.25,2.59248176080902E-5,-0.000147691180163307,2.58582119831663E-5,199.8115,199.8115,63037.7109375,63047.48828125,53.770570723448,19.5578422737956,25.946213,0,0,0,40,4449,199.81165,63042.599609375,,,,,,,,,,,,,0,,,,,,,,,,,,,,
,19746722.8,199.8158,67080.4453125,-0.000157002360643075,4.0001909138315E-6,1,0.999253354069792,40.0298881530762,1.99438801497944,14.2400003969669,-0.00183922801091357,3.65916524072025E-5,0.25,3.04947968391961E-5,-0.000157578148031257,3.04338525171609E-5,199.8156,199.8156,67075.5078125,67085.3828125,53.994116479948,19.5560874662494,25.946213,0,0,0,40,4449,199.8158,67080.4453125,,,,,,,,,,,,,0,,,,,,,,,,,,,,
,19746803.04,199.8184,71090.765625,-0.000170546471609231,4.36948950579011E-6,1,0.999253354069792,40.0298881530762,1.99436352293911,14.2400003969669,-0.00197913499353532,-6.81263080160949E-5,0.25,2.36059513229377E-5,-0.000171161822317765,2.35071296993185E-5,199.8184,199.8184,71088.28125,71093.25,53.882343601698,19.5539223657102,25.946213,0,0,0,40,4449,199.8184,71090.765625,,,,,,,,,,,,,0,,,,,,,,,,,,,,
,19746882.365,199.8188,75056.3359375,-0.000190688656103098,4.5414060683026E-6,1,0.999253354069792,40.0298881530762,1.99431456957899,14.2400003969669,-0.00221738647690696,-4.99124849337226E-5,0.25,2.87106907712536E-5,-0.000191379129688954,2.86085863421295E-5,199.8189,199.8189,75051.2734375,75061.3984375,53.9112638569095,19.5544854948328,26.325863,0,0,0,40,4449,199.8188,75056.3359375,,,,,,,,,,,,,0,,,,,,,,,,,,,,
,19746961.765,199.81335,79025.0078125,-0.000203850626936234,4.34526294847948E-6,1,0.999253354069792,40.0298881530762,1.99401396279393,14.2400003969669,-0.00236527326808434,-8.11283189569557E-5,0.25,2.82403399043334E-5,-0.000204586207095682,2.81230933820383E-5,199.8137,199.8137,79015.25,79034.765625,53.994116479948,19.5583205080592,25.946213,0,0,0,40,4449,199.81335,79025.0078125,,,,,,,,,,,,,0,,,,,,,,,,,,,,
,19747045.125,199.80195,83193.78125,-0.000218287455627729,4.22883119533968E-6,1,0.999253354069792,40.0298881530762,1.9941266535495,14.2500000074506,-0.00253889546667284,-5.24749065212907E-5,0.25,3.32761494848773E-5,-0.000219078410857163,3.31615563330773E-5,199.8016,199.8016,83188.75,83198.8125,53.6314408470249,19.5557090098329,25.946213,0,0,0,40,4449,199.80195,83193.78125,,,,,,,,,,,,,0,,,,,,,,,,,,,,
,19747124.33,199.79145,87151.9375,-0.000224040037101441,3.16567917390739E-6,1,0.999253354069792,40.0298881530762,1.99378129058954,14.2400003969669,-0.00259574098580521,-0.000109318707322272,0.25,2.92564563810586E-5,-0.000224846764262969,2.91223209736774E-5,199.7928,199.7928,87147.046875,87156.828125,53.6705222729865,19.5558625406453,25.946213,0,0,0,40,4449,199.79145,87151.9375,,,,,,,,,,,,,0,,,,,,,,,,,,,,
,19747183.2,199.7788,89999.48046875,-0.000242835014937032,3.82377155999446E-6,1,0.999253354069792,40.0298881530762,1.99379285523194,14.2400003969669,-0.00281290438922191,-0.000122020896396256,0.25,3.13988538816279E-5,-0.000243709197593707,3.12527228168548E-5,199.7788,199.7788,89999.4453125,89999.515625,53.6728671585441,19.5555699896264,25.566563,0,0,0,40,4417,199.7788,89999.48046875,,,,,,,,,,,,,0,,,,,,,,,,,,,,