File: data/monolayers/magneticStructure/ML_Ac_CoFe_C/PPMS/data/DD205_4_HYST_100OE_10K.DAT
[Header]
; VSM Data File (default extension .dat)
; Copyright (c) 2003-2013, Quantum Design, Inc. All rights reserved.
TITLE,
FILEOPENTIME,32342128.08,01/10/2019,3:57 pm
BYAPP,VSM,2.0,2.0
INFO,PPMS VSM Option Release 1.4.10 Build 1,APPNAME
INFO,Quantum Design Linear Motor Servo Controller,MOTOR_MODULE_NAME
INFO,3101-100 M1,MOTOR_HW_VERSION
INFO,MMC1014,MOTOR_SERIAL_NUMBER
INFO,SRV No X-over 01.03.11,MOTOR_SOFTWARE_VERSION
INFO,Quantum Design VSM Detection Module,VSM_MODULE_NAME
INFO,3101-150 F0,VSM_HW_VERSION
INFO,VSM707,VSM_SERIAL_NUMBER
INFO,VSM No X-over 01.02.05 May 20 2008 13:51:47,VSM_SOFTWARE_VERSION
INFO,704,PREAMP_SERIAL_NUMBER
INFO,822,COIL_SERIAL_NUMBER
INFO,0,MOMENT_UNITS
INFO,DD205_4,SAMPLE_MATERIAL
INFO,Monolayer,SAMPLE_COMMENT
INFO,29.55,SAMPLE_MASS
INFO,,SAMPLE_VOLUME
INFO,,SAMPLE_MOLECULAR_WEIGHT
INFO,,SAMPLE_SIZE
INFO,,SAMPLE_SHAPE
DATATYPE,COMMENT,1
DATATYPE,TIME,2
STARTUPAXIS,X,2
STARTUPAXIS,Y1,5
[Data]
Comment,Time Stamp (sec),Temperature (K),Magnetic Field (Oe),Moment (emu),M. Std. Err. (emu),Transport Action,Averaging Time (sec),Frequency (Hz),Peak Amplitude (mm),Center Position (mm),Coil Signal' (mV),Coil Signal" (mV),Range (mV),M. Quad. Signal (emu),M. Raw' (emu),M. Raw" (emu),Min. Temperature (K),Max. Temperature (K),Min. Field (Oe),Max. Field (Oe),Mass (grams),Motor Lag (deg),Pressure (Torr),VSM Status (code),Motor Status (code),Measure Status (code),Measure Count,PPMS Status (code),System Temp. (K),System Field (Oe),Sample Position (deg),Bridge 1 Resistance (ohms),Bridge 1 Excitation (에),Bridge 2 Resistance (ohms),Bridge 2 Excitation (에),Bridge 3 Resistance (ohms),Bridge 3 Excitation (에),Bridge 4 Resistance (ohms),Bridge 4 Excitation (에),Signal 1 Vin (V),Signal 2 Vin (V),Digital Inputs (code),Drive 1 Iout (mA),Drive 1 Ipower (W),Drive 2 Iout (mA),Drive 2 Ipower (W),Pressure (),Map 20 (),Map 21 (),Map 22 (),Map 23 (),Map 24 (),Map 25 (),Map 26 (),Map 27 (),Map 28 (),Map 29 ()
,32342142.78,9.9992304,-0.3349229991436,,,2,,,,21.410000115633,,,,,,,9.9992304,9.9992304,-0.3349229991436,-0.3349229991436,,,9.621219,,,,-99999999,4369,10.0225,-0.3349229991436,,,,,,,,,,,,,,,,,,,,,,,9.9992304,,,,
,32342287.715,9.9963923,4568.71362304687,2.73483913186885E-5,3.81857926219876E-7,1,0.999253354069792,40.0298881530762,2.00744211904959,21.4000009000301,0.000309171918634353,5.31622088665046E-5,0.25,-1.56805543251105E-7,2.71988586618603E-5,-1.65472572918309E-8,9.9963923,9.9963923,4566.13525390625,4571.2919921875,56.6704125297944,20.5199091068892,9.241568,0,0,0,40,4449,10.0279,4568.71362304687,,,,,,,,,,,,,0,,,,0,,,,,,9.9963923,,,,
,32342383.665,9.9981089,9362.58349609375,1.13468738414743E-5,3.31063072680835E-7,1,0.999253354069792,40.0298881530762,2.00764639869805,21.4000009000301,0.000129150375243158,1.74863552293974E-5,0.25,-4.744791078355E-7,1.12910718986014E-5,-4.1023275948971E-7,9.9981089,9.9981089,9357.646484375,9367.5205078125,56.6125720193714,20.5227418833861,9.241568,0,0,0,40,4449,10.029,9362.58349609375,,,,,,,,,,,,,0,,,,0,,,,,,9.9981089,,,,
,32342477.82,10.0003824,14067.6635742187,-4.74536038306881E-6,4.78123759148443E-7,1,0.999253354069792,40.0298881530762,2.00752790329405,21.4000009000301,-5.20654790772903E-5,-1.83232721627915E-5,0.25,-7.73980285503382E-7,-4.71834281004937E-6,-7.9778509165796E-7,10.0003824,10.0003824,14065.5712890625,14069.755859375,56.9189703989099,20.5274100988528,10.00087,0,0,0,40,4449,10.0302,14067.6635742187,,,,,,,,,,,,,0,,,,-0.00245,,,,,,10.0003824,,,,
,32342570.875,9.9998074,18717.5634765625,-2.08372725856354E-5,4.98723284521429E-7,1,0.999253354069792,40.0298881530762,2.00760987050731,21.4000009000301,-0.000232675531483268,-5.83826189990365E-5,0.25,-1.43608424395723E-6,-2.07384870787525E-5,-1.55725799205173E-6,9.9998074,9.9998074,18712.60546875,18722.521484375,57.098744958333,20.5309989737405,9.241568,0,0,0,40,4449,10.0299,18717.5634765625,,,,,,,,,,,,,0,,,,0,,,,,,9.9998074,,,,
,32342666.26,9.99887705,23487.935546875,-3.6448340013969E-5,5.23035740025964E-7,1,0.999253354069792,40.0298881530762,2.00757923712764,21.4000009000301,-0.000410225747748917,-8.51269152779898E-5,0.25,-9.94436196055148E-7,-3.63016287592508E-5,-1.22437276463844E-6,9.9987774,9.9989767,23460.341796875,23515.529296875,57.1049979864868,20.5324671443377,9.241568,0,0,0,40,4449,10.0292,23487.935546875,,,,,,,,,,,,,0,,,,0,,,,,,9.99887705,,,,
,32342762.835,9.99921325,28313.048828125,-5.2501730873022E-5,6.066010364356E-7,1,0.999253354069792,40.0298881530762,2.00750753278252,21.4000009000301,-0.000590626734420973,-0.000125741907720734,0.25,-1.68943170890798E-6,-5.23143031798776E-5,-2.03450958328932E-6,9.9989796,9.9994469,28308.25,28317.84765625,57.1995750373137,20.5321927306479,9.621219,0,0,0,40,4449,10.0308,28313.048828125,,,,,,,,,,,,,0,,,,-0.0049,,,,,,9.99921325,,,,
,32342856.54,9.99888565,32995.66796875,-6.92257007609313E-5,7.03766190867743E-7,1,0.999253354069792,40.0298881530762,2.00756908540008,21.4000009000301,-0.000779818234132884,-0.000162269060011703,0.25,-1.89338659316686E-6,-6.90144709098643E-5,-2.36568129488325E-6,9.9985867,9.9991846,32960.5546875,33030.78125,57.0291800201214,20.5281234636005,9.241568,0,0,0,40,4449,10.03055,32995.66796875,,,,,,,,,,,,,0,,,,-0.00245,,,,,,9.99888565,,,,
,32342954.515,9.9989691,37893.240234375,-8.602699139247E-5,7.14007469956496E-7,1,0.999253354069792,40.0298881530762,2.00756197183426,21.4000009000301,-0.00096991229905594,-0.000199912791889129,0.25,-2.17426896650815E-6,-8.58100295243159E-5,-2.77900720657732E-6,9.9989691,9.9989691,37858.1484375,37928.33203125,57.3097846585253,20.5310059419786,9.241568,0,0,0,40,4449,10.03225,37893.240234375,,,,,,,,,,,,,0,,,,0,,,,,,9.9989691,,,,
,32343049.5,9.997716,42640.69140625,-0.000103357602692531,8.06927663974938E-7,1,0.999253354069792,40.0298881530762,2.00751898468648,21.4000009000301,-0.00116855734366568,-0.000225353327849966,0.25,-1.27877155190971E-6,-0.000103158076862363,-2.02373665991924E-6,9.997716,9.997716,42635.09375,42646.2890625,57.0534105042176,20.5333855043323,9.621219,0,0,0,40,4449,10.0343,42640.69140625,,,,,,,,,,,,,0,,,,0,,,,,,9.997716,,,,
,32343142.25,9.99689105,47276.2734375,-0.000118488461873906,7.64911145945177E-7,1,0.999253354069792,40.0298881530762,2.00756950392134,21.4000009000301,-0.00133969983764164,-0.000261839090561661,0.25,-1.75114562678648E-6,-0.000118314708953988,-2.61749241737885E-6,9.9968691,9.996913,47243.86328125,47308.68359375,57.301968373333,20.5320843602712,9.241568,0,0,0,40,4449,10.03665,47276.2734375,,,,,,,,,,,,,0,,,,0,,,,,,9.99689105,,,,
,32343237.025,9.9964647,52013.587890625,-0.000135211303325342,6.41175356583929E-7,1,0.999253354069792,40.0298881530762,2.00757786308489,21.4000009000301,-0.0015308881356514,-0.000291353142566962,0.25,-1.32070794519743E-6,-0.000135083059546613,-2.32012574880509E-6,9.9964647,9.9964647,52011.4453125,52015.73046875,57.1518956976407,20.5292775631644,9.621219,0,0,0,40,4449,10.041,52013.587890625,,,,,,,,,,,,,0,,,,-0.0049,,,,,,9.9964647,,,,
,32343332.86,9.99582575,56803.73828125,-0.000153940398674291,8.58236073990745E-7,1,0.999253354069792,40.0298881530762,2.00753302383437,21.4000009000301,-0.00174533853872235,-0.00032292534178445,0.25,-7.11227828592041E-7,-0.000153872839797753,-1.85567321395372E-6,9.9957142,9.9959373,56798.7734375,56808.703125,57.068261446083,20.5262382493102,9.621219,0,0,0,40,4449,10.0436,56803.73828125,,,,,,,,,,,,,0,,,,-0.0049,,,,,,9.99582575,,,,
,32343427.085,9.9962454,61513.923828125,-0.000170656873922621,8.18458510754687E-7,1,0.999253354069792,40.0298881530762,2.00743517636386,21.4000009000301,-0.00193175795362445,-0.000379666137037182,0.25,-2.68463225002408E-6,-0.000170643953970476,-3.95490231667544E-6,9.9962454,9.9962454,61481.421875,61546.42578125,56.8134505488137,20.5303066681462,9.621219,0,0,0,40,4449,10.04825,61513.923828125,,,,,,,,,,,,,0,,,,0,,,,,,9.9962454,,,,
,32343523.64,9.9962292,66339.9609375,-0.000187882944060125,8.95552296386438E-7,1,0.999253354069792,40.0298881530762,2.00745188386576,21.4000009000301,-0.00212936036111358,-0.000408933703486927,0.25,-2.14613146092325E-6,-0.000187956794802183,-3.54186471723427E-6,9.9962292,9.9962292,66335.1015625,66344.8203125,57.4708001334869,20.5294650392051,10.00087,0,0,0,40,4449,10.0508,66339.9609375,,,,,,,,,,,,,0,,,,0,,,,,,9.9962292,,,,
,32343619.61,9.9954443,71135.0546875,-0.000204997376727178,9.68780547554314E-7,1,0.999253354069792,40.0298881530762,2.0074054373731,21.4000009000301,-0.00232164445820824,-0.000460717433462309,0.25,-3.61477077790579E-6,-0.000205153124130876,-5.13111279910807E-6,9.9954443,9.9954443,71132.5390625,71137.5703125,57.2707032325638,20.5325901478376,9.621219,0,0,0,40,4449,10.0566,71135.0546875,,,,,,,,,,,,,0,,,,-0.0049,,,,,,9.9954443,,,,
,32343715.305,9.9950533,75920.74609375,-0.000222926546944753,7.88080073835938E-7,1,0.999253354069792,40.0298881530762,2.0074592778607,21.4000009000301,-0.0025283412743463,-0.000486801878454487,0.25,-2.67668914615816E-6,-0.000223192078493175,-4.31192745896194E-6,9.9950533,9.9950533,75915.6953125,75925.796875,57.3113479155637,20.5327158184271,9.621219,0,0,0,40,4449,10.0608,75920.74609375,,,,,,,,,,,,,0,,,,0,,,,,,9.9950533,,,,
,32343810.53,9.9950333,80679.09375,-0.000238951852842047,1.0915138696142E-6,1,0.999253354069792,40.0298881530762,2.00738086554624,21.4000009000301,-0.00271308216866414,-0.000510296815499615,0.25,-1.8616757049717E-6,-0.000239331162558021,-3.59549554630275E-6,9.9950333,9.9950333,80679.09375,80679.09375,57.268358347006,20.5290778089796,9.621219,0,0,0,40,4449,10.0637,80679.09375,,,,,,,,,,,,,0,,,,0,,,,,,9.9950333,,,,
,32343904.475,9.9950891,85377.59375,-0.000257254602911095,9.46897312282723E-7,1,0.999253354069792,40.0298881530762,2.00741488800691,21.4000009000301,-0.00292048827052779,-0.000557584646400419,0.25,-2.73159211524905E-6,-0.000257745116626604,-4.57750426183402E-6,9.9947062,9.995472,85347.6484375,85407.5390625,57.2964969736984,20.5308559657057,9.621219,0,0,0,40,4449,10.0692,85377.59375,,,,,,,,,,,,,0,,,,0,,,,,,9.9950891,,,,
,32343993.64,9.994648,89832.9609375,-0.000274029462715697,1.29308635564137E-6,1,0.999253354069792,40.0298881530762,2.00740575668059,21.4000009000301,-0.00311087393611162,-0.000599553021946764,0.25,-3.41346063823932E-6,-0.00027463148712933,-5.35606801511336E-6,9.994648,9.994648,89830.4921875,89835.4296875,57.2277136640061,20.5295002693146,9.621219,0,0,0,40,4449,10.0734,89832.9609375,,,,,,,,,,,,,0,,,,-0.0049,,,,,,9.994648,,,,
,32344098.1,9.99848225,85786.6015625,-0.000259955298795753,1.08196760399647E-6,1,0.999253354069792,40.0298881530762,2.00741735696803,21.4000009000301,-0.00294862652447552,-0.000577954798260784,0.25,-4.03721753793869E-6,-0.000260449269465806,-5.90301051671575E-6,9.9981871,9.9987774,85759.3125,85813.890625,57.3809128537753,20.5322955971188,9.621219,0,0,0,40,4449,10.07325,85786.6015625,,,,,,,,,,,,,0,,,,0,,,,,,9.99848225,,,,
,32344193.63,10.0014286,81012.80078125,-0.00024169816264883,1.07903243269845E-6,1,0.999253354069792,40.0298881530762,2.00738316175694,21.4000009000301,-0.00274288523812798,-0.00052422729795417,0.25,-2.59272096651841E-6,-0.000242082689928151,-4.34626973903945E-6,10.0014286,10.0014286,81010.40625,81015.1953125,57.1049979864868,20.5316783242105,9.621219,0,0,0,40,4449,10.0707,81012.80078125,,,,,,,,,,,,,0,,,,0,,,,,,10.0014286,,,,
,32344293.275,10.0031614,76029.0859375,-0.000222821574174751,1.00869771671979E-6,1,0.999253354069792,40.0298881530762,2.00731442173675,21.4000009000301,-0.00252570173703984,-0.000493742287171741,0.25,-3.30920122287867E-6,-0.000223084249187542,-4.94415551233063E-6,10.0031614,10.0031614,76021.703125,76036.46875,57.0151107067753,20.5338901675288,9.241568,0,0,0,40,4449,10.06765,76029.0859375,,,,,,,,,,,,,0,,,,0,,,,,,10.0031614,,,,
,32344389.65,10.00401445,71213.0390625,-0.000205626795970173,9.28526546754918E-7,1,0.999253354069792,40.0298881530762,2.00730209487225,21.4000009000301,-0.00233111441032926,-0.000448565792654695,0.25,-2.43366762350758E-6,-0.00020579316119682,-3.95344492903889E-6,10.003643,10.0043859,71178.0546875,71248.0234375,57.1722180391407,20.5349394270159,9.241568,0,0,0,40,4449,10.0651,71213.0390625,,,,,,,,,,,,,0,,,,0,,,,,,10.00401445,,,,
,32344488.88,10.0046911,66252.4453125,-0.000187880803940799,1.04649334560021E-6,1,0.999253354069792,40.0298881530762,2.0073659830267,21.4000009000301,-0.00212665291063209,-0.00042322342704628,0.25,-3.40645927015283E-6,-0.000187943842379584,-4.80285929443426E-6,10.0046911,10.0046911,66249.84375,66255.046875,57.0846756449868,20.5366162904814,9.241568,0,0,0,40,4449,10.0595,66252.4453125,,,,,,,,,,,,,0,,,,-0.00245,,,,,,10.0046911,,,,
,32344589.47,10.0051203,61224.251953125,-0.000169801547202478,1.02336563210621E-6,1,0.999253354069792,40.0298881530762,2.00738398330181,21.4000009000301,-0.00192500417926789,-0.000360953130341235,0.25,-1.19186692448664E-6,-0.000169795136742295,-2.45573855463466E-6,10.0051203,10.0051203,61221.83984375,61226.6640625,57.2996234877753,20.5364746925692,9.621219,0,0,0,40,4449,10.0548,61224.251953125,,,,,,,,,,,,,0,,,,0.0049,,,,,,10.0051203,,,,
,32344688.705,10.0046072,56263.91015625,-0.000151381550856478,8.96441755654131E-7,1,0.999253354069792,40.0298881530762,2.00746093212606,21.4000009000301,-0.00171285155431929,-0.000335987249535034,0.25,-2.32645149388823E-6,-0.000151295105463017,-3.45071214411109E-6,10.0043659,10.0048485,56258.921875,56268.8984375,57.4450063923522,20.5303292987527,9.621219,0,0,0,40,4449,10.0519,56263.91015625,,,,,,,,,,,,,0,,,,0,,,,,,10.0046072,,,,
,32344787.875,10.0045547,51308.9453125,-0.000134556255424666,7.70647772151248E-7,1,0.999253354069792,40.0298881530762,2.00754743831879,21.4000009000301,-0.00152171020849336,-0.000298969955667134,0.25,-2.11356424007594E-6,-0.00013441320952662,-3.10620940176864E-6,10.0045547,10.0045547,51306.40234375,51311.48828125,57.2886806885061,20.5351267729783,9.621219,0,0,0,40,4449,10.0481,51308.9453125,,,,,,,,,,,,,0,,,,-0.0049,,,,,,10.0045547,,,,
,32344887.335,10.0048199,46336.626953125,-0.000115467440961441,7.1408918371131E-7,1,0.999253354069792,40.0298881530762,2.00746788487482,21.4000009000301,-0.00130585808824655,-0.000252319759798701,0.25,-1.46088722770607E-6,-0.000115288730921723,-2.30329384688314E-6,10.0044661,10.0051737,46329.03515625,46344.21875,57.3574639981984,20.5279388749431,10.00087,0,0,0,40,4449,10.0433,46336.626953125,,,,,,,,,,,,,0,,,,-0.00245,,,,,,10.0048199,,,,
,32344985.56,10.0038643,41428.548828125,-9.84666568506461E-5,7.89708716448628E-7,1,0.999253354069792,40.0298881530762,2.00751505335038,21.4000009000301,-0.00111268720220918,-0.000217044930218449,0.25,-1.431722483948E-6,-9.82625069411966E-5,-2.13766707347221E-6,10.0038643,10.0038643,41425.96484375,41431.1328125,56.9033378285253,20.5341723235741,9.241568,0,0,0,40,4449,10.0404,41428.548828125,,,,,,,,,,,,,0,,,,0,,,,,,10.0038643,,,,
,32345081.74,10.003396,36621.517578125,-8.21748154351558E-5,6.80663566756815E-7,1,0.999253354069792,40.0298881530762,2.00747546831927,21.4000009000301,-0.000926182477806996,-0.000191681891835838,0.25,-2.14713679409191E-6,-8.19560711888369E-5,-2.72067002167693E-6,10.003396,10.003396,36619.27734375,36623.7578125,57.1073428720445,20.535967059827,10.00087,0,0,0,40,4449,10.0373,36621.517578125,,,,,,,,,,,,,0,,,,0,,,,,,10.003396,,,,
,32345180.685,10.002202,31673.755859375,-6.38295249419859E-5,7.1616574633779E-7,1,0.999253354069792,40.0298881530762,2.00742657314754,21.4000009000301,-0.000719873844753182,-0.000144070708472017,0.25,-1.26188804118515E-6,-6.36292530157059E-5,-1.69486322264811E-6,10.002202,10.002202,31665.955078125,31681.556640625,57.4457880208715,20.5364607715767,9.621219,0,0,0,40,4449,10.0353,31673.755859375,,,,,,,,,,,,,0,,,,0,,,,,,10.002202,,,,
,32345278.735,10.0028586,26773.642578125,-4.67965519918306E-5,6.16778176301835E-7,1,0.999253354069792,40.0298881530762,2.00739034899901,21.4000009000301,-0.00052759048910985,-0.000105043688951497,0.25,-8.89914888506834E-7,-4.66262036894433E-5,-1.1956336616277E-6,10.0026941,10.0030231,26768.3671875,26778.91796875,57.2839909173907,20.5373767570458,9.621219,0,0,0,40,4449,10.03195,26773.642578125,,,,,,,,,,,,,0,,,,-0.0049,,,,,,10.0028586,,,,
,32345377.08,10.0021133,21858.5908203125,-2.96462165079355E-5,5.94109627592657E-7,1,0.999253354069792,40.0298881530762,1.9949142267961,21.4000009000301,-0.000330695084785394,-7.38957246041923E-5,0.25,-1.26400704815044E-6,-2.95192582195311E-5,-1.44614293232688E-6,10.0021133,10.0021133,21856.240234375,21860.94140625,57.5513078709676,20.5420154158909,9.621219,0,0,0,40,4449,10.0326,21858.5908203125,,,,,,,,,,,,,0,,,,0.0049,,,,,,10.0021133,,,,
,32345474.735,10.0008974,16978.7890625,-1.33145266968806E-5,5.44952738886267E-7,1,0.999253354069792,40.0298881530762,1.99484056506846,21.4000009000301,-0.000148213498671684,-3.44719411823302E-5,0.25,-6.87698706358221E-7,-1.32507037878155E-5,-7.64441665142409E-7,10.0008974,10.0008974,16973.814453125,16983.763671875,57.1386080128137,20.5383986164518,9.621219,0,0,0,40,4449,10.0321,16978.7890625,,,,,,,,,,,,,0,,,,0,,,,,,10.0008974,,,,
,32345572.415,10.0007896,12096.69921875,3.1084077807808E-6,3.90599969900831E-7,1,0.999253354069792,40.0298881530762,1.9949923899728,21.4000009000301,3.64878114825668E-5,-2.59245324503774E-6,0.25,-7.854352011558E-7,3.09754962998288E-6,-7.64013447673773E-7,10.0007896,10.0007896,12091.759765625,12101.638671875,57.1862873524868,20.5395564081977,9.241568,0,0,0,40,4449,10.0308,12096.69921875,,,,,,,,,,,,,0,,,,-0.00245,,,,,,10.0007896,,,,
,32345671.505,9.9990444,7143.78491210937,1.97889083811051E-5,4.04311278576666E-7,1,0.999253354069792,40.0298881530762,1.99495529173551,21.4000009000301,0.000222890333692243,3.56349946549113E-5,0.25,-3.49697294045896E-7,1.96855585559171E-5,-2.43292779527596E-7,9.9990444,9.9990444,7138.6728515625,7148.89697265625,57.3707516830253,20.5362830421818,10.00087,0,0,0,40,4449,10.0325,7143.78491210937,,,,,,,,,,,,,0,,,,0,,,,,,9.9990444,,,,
,32345765.555,9.9999065,2442.94921875,3.48327528789088E-5,3.67829951276621E-7,1,0.999253354069792,40.0298881530762,1.99486468839311,21.4000009000301,0.000390931256340153,6.97954464592048E-5,0.25,2.78853325654485E-8,3.46365454350301E-5,2.00250621599748E-7,9.9999065,9.9999065,2440.275390625,2445.623046875,57.6763684340446,20.5371737812423,9.621219,0,0,0,40,4449,10.0305,2442.94921875,,,,,,,,,,,,,0,,,,0,,,,,,9.9999065,,,,
,32345862.255,9.9996405,-2387.71630859375,4.78463474260985E-5,3.47227574123698E-7,1,0.999253354069792,40.0298881530762,1.9949823831347,21.4000009000301,0.000537372667008911,9.38499598320496E-5,0.25,-1.4204004169806E-7,4.75775780008373E-5,9.55671721272565E-8,9.9996405,9.9996405,-2397.69409179687,-2377.73852539062,57.4332819645638,20.5378524984239,9.621219,0,0,0,40,4449,10.0306,-2387.71630859375,,,,,,,,,,,,,0,,,,0,,,,,,9.9996405,,,,
,32345957.4,9.9991088,-7144.6357421875,6.12880731173788E-5,3.37916961792213E-7,1,0.999253354069792,40.0298881530762,1.99499194572287,21.4000009000301,0.000687302280564347,0.000127338191525347,0.25,4.28439057269763E-7,6.09600077841271E-5,7.49952496028382E-7,9.9990463,9.9991713,-7177.115234375,-7112.15625,57.1651833824676,20.5407713572219,10.00087,0,0,0,40,4449,10.0315,-7144.6357421875,,,,,,,,,,,,,0,,,,0.0049,,,,,,9.9991088,,,,
,32346054.03,10.0003386,-11972.9116210938,7.32588421838193E-5,4.13685775123833E-7,1,0.999253354069792,40.0298881530762,1.99500938060768,21.4000009000301,0.00082263369525663,0.000147992057736184,0.25,1.05186288497307E-7,7.28970177045749E-5,5.17790189764479E-7,10.0003386,10.0003386,-11975.408203125,-11970.4150390625,57.2386564632753,20.5372677131334,9.241568,0,0,0,40,4449,10.0304,-11972.9116210938,,,,,,,,,,,,,0,,,,0,,,,,,10.0003386,,,,
,32346151.39,10.00061465,-16837.771484375,8.02223439948986E-5,4.05455329318238E-7,1,0.999253354069792,40.0298881530762,1.99496207943445,21.4000009000301,0.000900185673787599,0.000167809676687577,0.25,5.93262844993866E-7,7.98580366560369E-5,1.07078584897481E-6,10.0004835,10.0007458,-16867.599609375,-16807.943359375,57.6083667528715,20.5401604373896,9.241568,0,0,0,40,4449,10.0297,-16837.771484375,,,,,,,,,,,,,0,,,,0.0049,,,,,,10.00061465,,,,
,32346251.035,10.00020985,-21820.16015625,7.9687555296167E-5,3.64389523211339E-7,1,0.999253354069792,40.0298881530762,1.99503671893281,21.4000009000301,0.000895644921597738,0.000161208351973705,0.25,6.80027457397502E-8,7.93670197590809E-5,5.70747216625734E-7,9.9999886,10.0004311,-21850.23046875,-21790.08984375,56.9932251082368,20.5423588766501,10.00087,0,0,0,40,4449,10.03075,-21820.16015625,,,,,,,,,,,,,0,,,,-0.0049,,,,,,10.00020985,,,,
,32346347.29,10.00051025,-26629.8134765625,7.81714747286813E-5,5.14181403531238E-7,1,0.999253354069792,40.0298881530762,1.99492531794381,21.4000009000301,0.000877509148256021,0.000166462841412706,0.25,7.78844966626238E-7,7.78904320268841E-5,1.29140270134337E-6,10.0001116,10.0009089,-26662.41796875,-26597.208984375,56.9181887703906,20.5421337072868,10.00087,0,0,0,40,4449,10.0304,-26629.8134765625,,,,,,,,,,,,,0,,,,0.00245,,,,,,10.00051025,,,,
,32346444.45,9.9993153,-31485.1279296875,7.94266073855208E-5,6.12894502389509E-7,1,0.999253354069792,40.0298881530762,1.99496759011491,21.4000009000301,0.000893100509917452,0.000163487789739104,0.25,2.62401748855893E-7,7.91847687843078E-5,8.04418377482239E-7,9.9993153,9.9993153,-31489.99609375,-31480.259765625,57.0823307594291,20.542563568415,10.00087,0,0,0,40,4449,10.0318,-31485.1279296875,,,,,,,,,,,,,0,,,,0,,,,,,9.9993153,,,,
,32346540.93,9.9981775,-36307.005859375,9.09355380573547E-5,6.2911015920951E-7,1,0.999253354069792,40.0298881530762,1.99495533889075,21.4000009000301,0.00102155665379406,0.00019546297968356,0.25,1.01030240347897E-6,9.07000688627346E-5,1.64728554133872E-6,9.9981775,9.9981775,-36311.74609375,-36302.265625,57.0838940164676,20.54106840922,9.621219,0,0,0,40,4449,10.03165,-36307.005859375,,,,,,,,,,,,,0,,,,0.0049,,,,,,9.9981775,,,,
,32346637.4,9.9980354,-41129.50390625,0.00010377299129421,6.49680345139513E-7,1,0.999253354069792,40.0298881530762,1.99491008736849,21.4000009000301,0.00116915100905368,0.000207561414814838,0.25,-2.48665545581803E-7,0.000103567215019191,4.97919569906686E-7,9.9980354,9.9980354,-41134.73046875,-41124.27734375,57.261323690333,20.5462154004712,9.621219,0,0,0,40,4449,10.0336,-41129.50390625,,,,,,,,,,,,,0,,,,0.00245,,,,,,9.9980354,,,,
,32346733.03,9.9973612,-45909.568359375,0.000117302147493621,6.97284175425014E-7,1,0.999253354069792,40.0298881530762,1.99495192565564,21.4000009000301,0.00132088039126161,0.000242444210769407,0.25,3.89103097066689E-7,0.000117123417483318,1.24547284976678E-6,9.9970827,9.9976397,-45942.18359375,-45876.953125,57.0698247031214,20.5448070827757,10.00087,0,0,0,40,4449,10.03585,-45909.568359375,,,,,,,,,,,,,0,,,,0.00245,,,,,,9.9973612,,,,
,32346828.685,9.9964323,-50689.44140625,0.000132030292946549,6.83830420261907E-7,1,0.999253354069792,40.0298881530762,1.99485715081985,21.4000009000301,0.00148808745918158,0.000269131319176001,0.25,8.42263705268343E-8,0.000131896390182162,1.05910400803348E-6,9.9964323,9.9964323,-50694.5234375,-50684.359375,57.2112994651022,20.5476902527333,9.241568,0,0,0,40,4449,10.03955,-50689.44140625,,,,,,,,,,,,,0,,,,0,,,,,,9.9964323,,,,
,32346924.4,9.9953952,-55471.720703125,0.000147798643249304,7.83498365336173E-7,1,0.999253354069792,40.0298881530762,1.99492083252056,21.4000009000301,0.0016651061527092,0.000310012048091672,0.25,8.49465558206971E-7,0.000147713419022783,1.94705199469418E-6,9.9953394,9.995451,-55506.66015625,-55436.78125,57.3973270526791,20.5459169138383,9.241568,0,0,0,40,4449,10.0437,-55471.720703125,,,,,,,,,,,,,0,,,,-0.00245,,,,,,9.9953952,,,,
,32347022.89,9.9957514,-60396.287109375,0.000166982761188355,9.83642724386656E-7,1,0.999253354069792,40.0298881530762,1.99493220100223,21.4000009000301,0.00188180468387097,0.000352237056288876,0.25,1.11910611309553E-6,0.000166963960499974,2.36199304144724E-6,9.9957514,9.9957514,-60398.6953125,-60393.87890625,57.3926372815638,20.5463685852313,9.621219,0,0,0,40,4449,10.0471,-60396.287109375,,,,,,,,,,,,,0,,,,0,,,,,,9.9957514,,,,
,32347116.995,9.9957266,-65098.958984375,0.00018285287562239,8.38485920573232E-7,1,0.999253354069792,40.0298881530762,1.9949653699012,21.4000009000301,0.00206041173780569,0.000392322440058876,0.25,1.7986271612751E-6,0.000182906740265987,3.1579993616444E-6,9.9957266,9.9957266,-65106.640625,-65091.27734375,57.2691399755253,20.5457007536782,10.00087,0,0,0,40,4449,10.0513,-65098.958984375,,,,,,,,,,,,,0,,,,0.0049,,,,,,9.9957266,,,,
,32347210.54,9.9954939,-69773.9453125,0.000201714207287595,9.97668595900665E-7,1,0.999253354069792,40.0298881530762,1.99498618472973,21.4000009000301,0.00227624435311662,0.000419920407322184,0.25,8.36231370614055E-7,0.000201864389224672,2.32860487681105E-6,9.9954939,9.9954939,-69803.96875,-69743.921875,57.5810097546984,20.5460470760329,9.621219,0,0,0,40,4449,10.05515,-69773.9453125,,,,,,,,,,,,,0,,,,0,,,,,,9.9954939,,,,
,32347309.255,9.995738,-74705.35546875,0.00022113953490613,1.0406980212148E-6,1,0.999253354069792,40.0298881530762,1.99492794202082,21.4000009000301,0.00249399455911785,0.000473857261175818,0.25,2.10961679949396E-6,0.000221385509545386,3.73464682008224E-6,9.995738,9.995738,-74735.28125,-74675.4296875,57.3926372815638,20.5483541462317,10.00087,0,0,0,40,4449,10.0585,-74705.35546875,,,,,,,,,,,,,0,,,,-0.00245,,,,,,9.995738,,,,
,32347404.71,9.9951887,-79477.6875,0.000235913670500221,1.47546751716192E-6,1,0.999253354069792,40.0298881530762,1.99492134076476,21.4000009000301,0.0026654147419027,0.000484489018684285,0.25,3.91541794965161E-7,0.000236277384299612,2.10579729262115E-6,9.9951887,9.9951887,-79477.6875,-79477.6875,56.9760292808137,20.5473118372341,10.00087,0,0,0,40,4449,10.0641,-79477.6875,,,,,,,,,,,,,0,,,,0,,,,,,9.9951887,,,,
,32347498.545,9.99472,-84164.71875,0.000254340647090174,9.71739761150922E-7,1,0.999253354069792,40.0298881530762,1.99494922602386,21.4000009000301,0.00286868519163287,0.000555550714152655,0.25,3.36621845830351E-6,0.000254799024153873,5.19835720322089E-6,9.9945517,9.9948883,-84169.6640625,-84159.7734375,57.6904377473907,20.548433971281,9.621219,0,0,0,40,4449,10.0688,-84164.71875,,,,,,,,,,,,,0,,,,-0.0049,,,,,,9.99472,,,,
,32347585.515,9.9953222,-88511.9609375,0.000269300009523417,1.08907091908367E-6,1,0.999253354069792,40.0298881530762,1.99493691673655,21.4000009000301,0.00304173978133123,0.000569296011005706,0.25,1.89959079477796E-6,0.000269878247163985,3.81290095053052E-6,9.9953222,9.9953222,-88516.8984375,-88507.0234375,57.1425161554099,20.5463982614621,9.241568,0,0,0,40,4449,10.0715,-88511.9609375,,,,,,,,,,,,,0,,,,0,,,,,,9.9953222,,,,
,32347691.3,9.99796195,-87099.06640625,0.000265873581032955,1.48995617369309E-6,1,0.999253354069792,40.0298881530762,1.9950411617017,21.4000009000301,0.00299980241262808,0.000579254928980423,0.25,3.39072492635797E-6,0.000266408209038487,5.29064192914997E-6,9.9979362,9.9979877,-87129.046875,-87069.0859375,57.0541921327368,20.546455264249,9.621219,0,0,0,40,4449,10.0737,-87099.06640625,,,,,,,,,,,,,0,,,,-0.00245,,,,,,9.99796195,,,,
,32347783.7,10.00061845,-82481.765625,0.000248601475405445,1.38992983907343E-6,1,0.999253354069792,40.0298881530762,1.99500347169692,21.4000009000301,0.00280576408798673,0.000531426044388745,0.25,2.26151892329923E-6,0.000249026762860835,4.05806553964035E-6,10.0005951,10.0006418,-82486.921875,-82476.609375,57.2370932062368,20.5460547761139,9.241568,0,0,0,40,4449,10.0729,-82481.765625,,,,,,,,,,,,,0,,,,0,,,,,,10.00061845,,,,
,32347883.195,10.0022869,-77509.66796875,0.000230183260439041,1.00394229851393E-6,1,0.999253354069792,40.0298881530762,1.99500817865058,21.4000009000301,0.00259777215252831,0.000487198731308514,0.25,1.66015974938839E-6,0.000230494154456037,3.3418913880937E-6,10.0022869,10.0022869,-77514.578125,-77504.7578125,57.1456426694868,20.5463861841441,10.00087,0,0,0,40,4449,10.0692,-77509.66796875,,,,,,,,,,,,,0,,,,0,,,,,,10.0022869,,,,
,32347980.885,10.0038433,-72627.2734375,0.000212209186344629,1.02173300665472E-6,1,0.999253354069792,40.0298881530762,1.99488759459857,21.4000009000301,0.00239320251220062,0.000452563730161189,0.25,1.83501136323672E-6,0.000212410770009213,3.39958210923543E-6,10.0038433,10.0038433,-72632.171875,-72622.375,57.3699700545061,20.5464721581726,10.00087,0,0,0,40,4449,10.0654,-72627.2734375,,,,,,,,,,,,,0,,,,0,,,,,,10.0038433,,,,
,32348081.415,10.0043001,-67603.12890625,0.000194889646346019,1.08811910615187E-6,1,0.999253354069792,40.0298881530762,1.99502373058836,21.4000009000301,0.00219721136802121,0.000414804252691402,0.25,1.61517240645053E-6,0.000194992367956632,3.06108327350992E-6,10.0043001,10.0043001,-67611.0234375,-67595.234375,57.5872627828522,20.5472754207232,9.621219,0,0,0,40,4449,10.06095,-67603.12890625,,,,,,,,,,,,,0,,,,-0.00245,,,,,,10.0043001,,,,
,32348179.025,10.0035276,-62723.423828125,0.000175382038319989,9.53902382723974E-7,1,0.999253354069792,40.0298881530762,1.99488990143479,21.4000009000301,0.00197656896290267,0.00037156280232259,0.25,1.3123717834897E-6,0.000175399063902063,2.61745516292768E-6,10.0035276,10.0035276,-62728.17578125,-62718.671875,57.5630322987561,20.5468733004526,9.241568,0,0,0,40,4449,10.0573,-62723.423828125,,,,,,,,,,,,,0,,,,0,,,,,,10.0035276,,,,
,32348276.515,10.0050545,-57850.56640625,0.000158430137979644,7.55307409243111E-7,1,0.999253354069792,40.0298881530762,1.99486593750956,21.4000009000301,0.00178647328393296,0.000325566094192228,0.25,3.05096853813576E-7,0.000158379735086843,1.48372870024458E-6,10.0050545,10.0050545,-57850.56640625,-57850.56640625,57.3777863396984,20.545807635126,9.621219,0,0,0,40,4449,10.0527,-57850.56640625,,,,,,,,,,,,,0,,,,0.0049,,,,,,10.0050545,,,,
,32348373.3,10.00472975,-53013.390625,0.000140797534659604,9.49781564966101E-7,1,0.999253354069792,40.0298881530762,1.99483295748369,21.4000009000301,0.00158575124153829,0.00029540178414742,0.25,8.25743958534784E-7,0.000140682106797905,1.86844797078355E-6,10.0043516,10.0051079,-53048.265625,-52978.515625,57.2112994651022,20.545270471698,10.00087,0,0,0,40,4449,10.04935,-53013.390625,,,,,,,,,,,,,0,,,,0.00245,,,,,,10.00472975,,,,
,32348470.73,10.0044699,-48143.796875,0.000122606608322485,7.58474094407106E-7,1,0.999253354069792,40.0298881530762,1.99489321995379,21.4000009000301,0.00138140955237026,0.000250583859845943,0.25,1.46699541398566E-7,0.000122449963629668,1.04728187393603E-6,10.0044699,10.0044699,-48146.20703125,-48141.38671875,57.2214606358522,20.5430495518146,9.621219,0,0,0,40,4449,10.0453,-48143.796875,,,,,,,,,,,,,0,,,,0.0049,,,,,,10.0044699,,,,
,32348569.35,10.0041542,-43216.572265625,0.000104742310811529,7.24744487438764E-7,1,0.999253354069792,40.0298881530762,1.99487445384352,21.4000009000301,0.00117713169935374,0.000227205232386427,0.25,1.3114448247665E-6,0.00010454631345802,2.06796258473677E-6,10.0041542,10.0041542,-43224.4921875,-43208.65234375,57.1675282680253,20.544977358845,10.00087,0,0,0,40,4449,10.0422,-43216.572265625,,,,,,,,,,,,,0,,,,0,,,,,,10.0041542,,,,
,32348668.165,10.0036821,-38276.828125,8.81903740116766E-5,7.36132653654727E-7,1,0.999253354069792,40.0298881530762,1.99488847121116,21.4000009000301,0.000990861463837159,0.000189774580847302,0.25,9.89692792387148E-7,8.79803170483173E-5,1.61372092249493E-6,10.0036821,10.0036821,-38281.70703125,-38271.94921875,57.2910255740638,20.5446564512688,9.241568,0,0,0,40,4449,10.0385,-38276.828125,,,,,,,,,,,,,0,,,,-0.0049,,,,,,10.0036821,,,,
,32348755.83,10.0034151,-33894.529296875,7.23007025630897E-5,6.18580925351458E-7,1,0.999253354069792,40.0298881530762,1.99486934130506,21.4000009000301,0.000811745655655666,0.000156632125474465,0.25,9.22847599656524E-7,7.20942180822473E-5,1.42195773502962E-6,10.0034151,10.0034151,-33899.375,-33889.68359375,57.3473028274484,20.5459026266968,9.621219,0,0,0,40,4449,10.0351,-33894.529296875,,,,,,,,,,,,,0,,,,-0.00245,,,,,,10.0034151,,,,
,32348849.275,10.00239275,-29227.0341796875,5.54266428277114E-5,5.85193858424049E-7,1,0.999253354069792,40.0298881530762,1.9948942890071,21.4000009000301,0.000622093160148933,0.000119475493917208,0.25,6.70783427248352E-7,5.52414656943449E-5,1.04143572678034E-6,10.0021038,10.0026817,-29257.263671875,-29196.8046875,57.535675300583,20.5437364093177,10.00087,0,0,0,40,4449,10.0341,-29227.0341796875,,,,,,,,,,,,,0,,,,0.00245,,,,,,10.00239275,,,,
,32348944.73,10.0019512,-24454.744140625,3.90192240726589E-5,5.75039644843647E-7,1,0.999253354069792,40.0298881530762,1.99498611961692,21.4000009000301,0.000437552518795121,8.5139766213615E-5,0.25,5.77229867042962E-7,3.88690755811052E-5,8.27528182078736E-7,10.0019512,10.0019512,-24459.76171875,-24449.7265625,57.5880444113715,20.5433494882126,9.621219,0,0,0,40,4449,10.0327,-24454.744140625,,,,,,,,,,,,,0,,,,0.0049,,,,,,10.0019512,,,,
,32349038.925,10.0012827,-19750.0791015625,2.29692982889885E-5,5.36633739126075E-7,1,0.999253354069792,40.0298881530762,1.99489853606532,21.4000009000301,0.00025648170832389,5.54549425669636E-5,0.25,8.23476878411049E-7,2.28672760657026E-5,9.61971115095206E-7,10.0012827,10.0012827,-19752.373046875,-19747.78515625,56.8556584888522,20.543017928875,9.621219,0,0,0,40,4449,10.0304,-19750.0791015625,,,,,,,,,,,,,0,,,,0,,,,,,10.0012827,,,,
,32349131.835,10.00136325,-15105.0205078125,7.02165535226426E-6,3.28685895626139E-7,1,0.999253354069792,40.0298881530762,1.99480380433627,21.4000009000301,7.86040532072407E-5,1.5626792679574E-5,0.25,1.36655395189117E-7,6.98816102709417E-6,1.77200039386384E-7,10.0011005,10.001626,-15110.02734375,-15100.013671875,57.434063593083,20.5415822324133,9.241568,0,0,0,40,4449,10.0299,-15105.0205078125,,,,,,,,,,,,,0,,,,0,,,,,,10.00136325,,,,
,32349226.415,10.0005121,-10379.6982421875,-9.05473102030814E-6,4.47550552966868E-7,1,0.999253354069792,40.0298881530762,1.9947981357401,21.4000009000301,-0.000101431971019628,-1.9526726872746E-5,0.25,-1.244230791701E-7,-9.00819403770477E-6,-1.73793827080536E-7,10.0005121,10.0005121,-10382.2568359375,-10377.1396484375,57.1581487257945,20.539761989705,9.241568,0,0,0,40,4449,10.0315,-10379.6982421875,,,,,,,,,,,,,0,,,,0,,,,,,10.0005121,,,,
,32349317.425,10.0002851,-5826.43725585938,-2.35963010107954E-5,3.72043174592771E-7,1,0.999253354069792,40.0298881530762,1.9948078979224,21.4000009000301,-0.000264898866319308,-4.71533453654545E-5,0.25,-1.21238938608817E-9,-2.34686142038135E-5,-1.23598637308371E-7,10.0002851,10.0002851,-5858.96484375,-5793.90966796875,57.0745144742368,20.5381779166377,9.621219,0,0,0,40,4449,10.0314,-5826.43725585938,,,,,,,,,,,,,0,,,,0,,,,,,10.0002851,,,,
,32349410.485,10.0005884,-1177.42517089844,-3.9216346157892E-5,2.14793181537016E-7,1,0.999253354069792,40.0298881530762,1.99483780601711,21.4000009000301,-0.00043574870081433,-0.000103029149341985,0.25,-2.21338713543908E-6,-3.89821523853661E-5,-2.39198846957293E-6,10.0005884,10.0005884,-1179.97607421875,-1174.87426757812,57.3433946848522,20.540841508911,10.00087,0,0,0,40,4449,10.0289,-1177.42517089844,,,,,,,,,,,,,0,,,,0,,,,,,10.0005884,,,,
,32349501.785,9.9989624,3382.5625,-5.00683402025458E-5,3.19102727723253E-7,1,0.999253354069792,40.0298881530762,1.99478064106647,21.4000009000301,-0.000560946777258677,-0.000105860784249857,0.25,-5.30136069901643E-7,-4.9786657157061E-5,-7.78274494483672E-7,9.9989624,9.9989624,3377.49780273438,3387.62719726562,56.5602029085829,20.5418461603252,9.621219,0,0,0,40,4449,10.02855,3382.5625,,,,,,,,,,,,,0,,,,0,,,,,,9.9989624,,,,
,32349592.96,9.9991074,7942.26318359375,-6.29418842141129E-5,4.90914950123801E-7,1,0.999253354069792,40.0298881530762,1.99495157556473,21.4000009000301,-0.000706053840496644,-0.000129788845359594,0.25,-3.48064872939455E-7,-6.26091985792512E-5,-6.82460707077695E-7,9.9991074,9.9991074,7936.982421875,7947.5439453125,57.0627900464484,20.5361054872465,9.241568,0,0,0,40,4449,10.0312,7942.26318359375,,,,,,,,,,,,,0,,,,-0.00245,,,,,,9.9991074,,,,
,32349684.87,10.0002756,12535.6782226563,-7.38204902020785E-5,3.98630440285153E-7,1,0.999253354069792,40.0298881530762,1.99493713125209,21.4000009000301,-0.000827086009545519,-0.000159585144246929,0.25,-1.03390628450348E-6,-7.34541665552745E-5,-1.44818018483045E-6,10.0002756,10.0002756,12530.810546875,12540.5458984375,57.7005989181407,20.5358276432122,9.621219,0,0,0,40,4449,10.03095,12535.6782226563,,,,,,,,,,,,,0,,,,0,,,,,,10.0002756,,,,
,32349777.645,10.000062,17170.78515625,-7.99502821387369E-5,5.43683361779926E-7,1,0.999253354069792,40.0298881530762,1.99492319523767,21.4000009000301,-0.000897060318619795,-0.000167711375986954,0.25,-6.31144222553911E-7,-7.95894419586993E-5,-1.10871486854855E-6,10.000062,10.000062,17168.083984375,17173.486328125,57.2996234877753,20.5373943320718,9.621219,0,0,0,40,4449,10.03025,17170.78515625,,,,,,,,,,,,,0,,,,0,,,,,,10.000062,,,,
,32349871.64,10.0005312,21868.33203125,-7.92374633327837E-5,5.79809323943618E-7,1,0.999253354069792,40.0298881530762,1.99469074348991,21.4000009000301,-0.000889669007041649,-0.000164593264627251,0.25,-4.51855067465624E-7,-7.89166901982785E-5,-9.5045512290645E-7,10.0005312,10.0005312,21865.984375,21870.6796875,57.7787617700638,20.5448597152854,10.00087,0,0,0,40,4449,10.0306,21868.33203125,,,,,,,,,,,,,0,,,,-0.0049,,,,,,10.0005312,,,,
,32349965.945,9.9992733,26585.8115234375,-7.79441515971108E-5,7.36029109876688E-7,1,0.999253354069792,40.0298881530762,1.99474060146666,21.4000009000301,-0.000874498841049893,-0.00016806593839706,0.25,-9.63753077250414E-7,-7.76623408699214E-5,-1.47396951816847E-6,9.999155,9.9993916,26553.51953125,26618.103515625,57.4825245612753,20.5392257032805,9.621219,0,0,0,40,4449,10.0307,26585.8115234375,,,,,,,,,,,,,0,,,,-0.00245,,,,,,9.9992733,,,,
,32350060.375,9.99950265,31304.443359375,-7.75871865938515E-5,6.27913205587867E-7,1,0.999253354069792,40.0298881530762,1.99480279014521,21.4000009000301,-0.000870650929391586,-0.00016904379386676,0.25,-1.08876845926198E-6,-7.73437902106465E-5,-1.61505545160782E-6,9.9993095,9.9996958,31271.634765625,31337.251953125,57.6646440062561,20.538947707781,10.00087,0,0,0,40,4449,10.0311,31304.443359375,,,,,,,,,,,,,0,,,,-0.00245,,,,,,9.99950265,,,,
,32350156.37,9.9983902,36099.337890625,-8.56399246373059E-5,4.06475711130399E-7,1,0.999253354069792,40.0298881530762,1.99488310930157,21.4000009000301,-0.000960360884660614,-0.000193250976385962,0.25,-1.76780355089408E-6,-8.54105517538389E-5,-2.36494469692774E-6,9.9983902,9.9983902,36093.921875,36104.75390625,57.2331850636407,20.5401181324563,9.621219,0,0,0,40,4449,10.0321,36099.337890625,,,,,,,,,,,,,0,,,,-0.00245,,,,,,9.9983902,,,,
,32350247.75,9.9985156,40669.39453125,-0.000100449915555967,7.07886587535489E-7,1,0.999253354069792,40.0298881530762,1.99476459814682,21.4000009000301,-0.0011228118950637,-0.000249592739574249,0.25,-4.0856911551665E-6,-0.000100214796305914,-4.79818995140256E-6,9.9982929,9.9987383,40666.8984375,40671.890625,57.0713879601599,20.5400698970425,9.241568,0,0,0,40,4449,10.0336,40669.39453125,,,,,,,,,,,,,0,,,,-0.0049,,,,,,9.9985156,,,,
,32350341.095,9.9960165,45335.294921875,-0.000117082883969323,8.04137382142897E-7,1,0.999253354069792,40.0298881530762,1.99473617166208,21.4000009000301,-0.00131896108980968,-0.000237705990875727,0.25,-1.28525072986404E-8,-0.00011690024467787,-8.66789103609405E-7,9.9960165,9.9960165,45325.48046875,45345.109375,57.4629838482945,20.5406427581449,10.00087,0,0,0,40,4449,10.0352,45335.294921875,,,,,,,,,,,,,0,,,,0.00245,,,,,,9.9960165,,,,
,32350434.095,9.9971743,49982.671875,-0.000130967253588994,8.92778416208561E-7,1,0.999253354069792,40.0298881530762,1.99480710533989,21.4000009000301,-0.00147208648906162,-0.000288463003288051,0.25,-1.99440187667024E-6,-0.000130810958789506,-2.95812190651168E-6,9.9971743,9.9971743,49977.75390625,49987.58984375,57.4879959609099,20.5385758514346,9.621219,0,0,0,40,4449,10.0386,49982.671875,,,,,,,,,,,,,0,,,,-0.0049,,,,,,9.9971743,,,,
,32350528.805,9.9959717,54715.591796875,-0.000147813741486785,9.30774006686326E-7,1,0.999253354069792,40.0298881530762,1.9948711709627,21.4000009000301,-0.0016637690364385,-0.000317471351247746,0.25,-1.51157293341399E-6,-0.000147712647557226,-2.60807065843366E-6,9.9959717,9.9959717,54710.40234375,54720.78125,57.0026046504676,20.5382758617745,10.00087,0,0,0,40,4449,10.04295,54715.591796875,,,,,,,,,,,,,0,,,,0.0049,,,,,,9.9959717,,,,
,32350621.55,9.9957132,59350.67578125,-0.000163272358155797,8.31910373045148E-7,1,0.999253354069792,40.0298881530762,1.9947658851932,21.4000009000301,-0.00183736267906345,-0.000357110969635326,0.25,-2.22548039264133E-6,-0.000163229496701515,-3.44037457141982E-6,9.9957132,9.9957132,59348.26171875,59353.08984375,57.291807202583,20.5365184129316,9.621219,0,0,0,40,4449,10.0463,59350.67578125,,,,,,,,,,,,,0,,,,-0.0049,,,,,,9.9957132,,,,
,32350712.47,9.9964662,63896.6328125,-0.00018001094197116,1.14309819199034E-6,1,0.999253354069792,40.0298881530762,1.99484971637598,21.4000009000301,-0.00202613702809308,-0.000396813548026514,0.25,-2.71329796407193E-6,-0.000180037486316548,-4.05260591397185E-6,9.9963055,9.9966269,63866.6015625,63926.6640625,57.2488176340253,20.5360844321736,9.621219,0,0,0,40,4449,10.04965,63896.6328125,,,,,,,,,,,,,0,,,,0,,,,,,9.9964662,,,,
,32350805.925,9.9958057,68566.84765625,-0.000198064317433962,9.20659029345874E-7,1,0.999253354069792,40.0298881530762,1.99465656587679,21.4000009000301,-0.00222914547423655,-0.000441784673634512,0.25,-3.43789125155529E-6,-0.000198171945311719,-4.90713330516921E-6,9.9958057,9.9958057,68564.375,68569.3203125,57.3965454241599,20.5399564133654,9.621219,0,0,0,40,4449,10.0536,68566.84765625,,,,,,,,,,,,,0,,,,0,,,,,,9.9958057,,,,
,32350898.28,9.9947386,73184.6171875,-0.00021192879364434,9.81888547831181E-7,1,0.999253354069792,40.0298881530762,1.99472777420213,21.4000009000301,-0.0023869059701992,-0.000468940932791438,0.25,-3.33826422250913E-6,-0.00021212872413918,-4.90098908981054E-6,9.9947386,9.9947386,73157.2265625,73212.0078125,57.0510656186599,20.5377347565251,9.621219,0,0,0,40,4449,10.05815,73184.6171875,,,,,,,,,,,,,0,,,,-0.00245,,,,,,9.9947386,,,,
,32350991.165,9.99468085,77825.640625,-0.00023149247690097,1.08824002562549E-6,1,0.999253354069792,40.0298881530762,1.99476509484669,21.4000009000301,-0.00261166749631723,-0.000493478128716246,0.25,-1.98527267006103E-6,-0.000231808501330693,-3.67590802109897E-6,9.9943256,9.9950361,77795.6015625,77855.6796875,57.4731450190445,20.5361064284685,10.00087,0,0,0,40,4449,10.06215,77825.640625,,,,,,,,,,,,,0,,,,-0.00245,,,,,,9.99468085,,,,
,32351081.96,9.9956141,82366.62890625,-0.000246117174700575,9.51961106011092E-7,1,0.999253354069792,40.0298881530762,1.99473042123575,21.4000009000301,-0.00277454418141878,-0.000541572936400667,0.25,-3.61238918885709E-6,-0.000246526243109041,-5.39391907367831E-6,9.9956141,9.9956141,82329.109375,82404.1484375,56.8322096332752,20.5368543055354,9.621219,0,0,0,40,4449,10.0664,82366.62890625,,,,,,,,,,,,,0,,,,-0.0049,,,,,,9.9956141,,,,
,32351170.53,9.99538805,86794.99609375,-0.000264060848008951,1.14206954993073E-6,1,0.999253354069792,40.0298881530762,1.99476695882034,21.4000009000301,-0.00297965638363566,-0.000570996342238302,0.25,-2.99252641780915E-6,-0.000264588988776558,-4.88030818850948E-6,9.9953308,9.9954453,86792.2734375,86797.71875,57.2902439455445,20.5397921926029,9.621219,0,0,0,40,4449,10.07,86794.99609375,,,,,,,,,,,,,0,,,,-0.0049,,,,,,9.99538805,,,,
,32351270.265,9.99652575,89004.890625,-0.000271069061294195,7.86384585519872E-7,1,0.999253354069792,40.0298881530762,1.99480487721365,21.4000009000301,-0.00305649496715492,-0.000601559149308531,0.25,-4.43872421254594E-6,-0.000271642152151619,-6.36742228766751E-6,9.9963245,9.996727,88972.1953125,89037.5859375,57.4489145349484,20.5363456716643,9.621219,0,0,0,40,4449,10.0739,89004.890625,,,,,,,,,,,,,0,,,,0.00245,,,,,,9.99652575,,,,
,32351357.145,9.99953125,84661.67578125,-0.000255810646357421,1.04074165090726E-6,1,0.999253354069792,40.0298881530762,1.99488034794782,21.4000009000301,-0.00288824526256218,-0.000542238099365249,0.25,-1.92662163760203E-6,-0.000256291164427895,-3.76415582662405E-6,9.999403,9.9996595,84634.046875,84689.3046875,56.8963031718522,20.5350364226656,9.621219,0,0,0,40,4449,10.0722,84661.67578125,,,,,,,,,,,,,0,,,,0,,,,,,9.99953125,,,,
,32351453.75,10.0018797,79832.58203125,-0.000239495490593298,1.17978188391192E-6,1,0.999253354069792,40.0298881530762,1.99475637284382,21.4000009000301,-0.00270007407897722,-0.000523297078616346,0.25,-3.18436916720074E-6,-0.000239850904535011,-4.92762103476702E-6,10.0018797,10.0018797,79830.0078125,79835.15625,57.0237086204868,20.5387268934034,10.00087,0,0,0,40,4449,10.0709,79832.58203125,,,,,,,,,,,,,0,,,,0.0049,,,,,,10.0018797,,,,
,32351551.345,10.003417,74953.953125,-0.000220235794050244,1.23638935252734E-6,1,0.999253354069792,40.0298881530762,1.99487650466163,21.4000009000301,-0.00248494970216491,-0.000465482880713372,0.25,-1.53212237627077E-6,-0.000220489322132028,-3.14911381257592E-6,10.003417,10.003417,74946.390625,74961.515625,57.2949337166599,20.5355421074783,9.241568,0,0,0,40,4449,10.0678,74953.953125,,,,,,,,,,,,,0,,,,0,,,,,,10.003417,,,,
,32351646.74,10.0045462,70185.95703125,-0.000203352942863387,1.0593932490551E-6,1,0.999253354069792,40.0298881530762,1.99489521179971,21.4000009000301,-0.00229526259688711,-0.000420299060384217,0.25,-5.75672894164501E-7,-0.000203513421576854,-2.07915278630372E-6,10.0045462,10.0045462,70183.3046875,70188.609375,56.9244417985445,20.5346827351101,10.00087,0,0,0,40,4449,10.0626,70185.95703125,,,,,,,,,,,,,0,,,,0.0049,,,,,,10.0045462,,,,
,32351743.195,10.0040884,65362.8359375,-0.000184450119524285,1.08283215517446E-6,1,0.999253354069792,40.0298881530762,1.99490522901061,21.4000009000301,-0.00207560425178337,-0.000411252498832751,0.25,-3.18821841539111E-6,-0.00018449859201189,-4.5597810168622E-6,10.0040884,10.0040884,65360.2578125,65365.4140625,57.4575124486599,20.5352751175097,9.621219,0,0,0,40,4449,10.0606,65362.8359375,,,,,,,,,,,,,0,,,,0,,,,,,10.0040884,,,,
,32351839.47,10.00406265,60549.767578125,-0.000168531524677807,9.01081608791234E-7,1,0.999253354069792,40.0298881530762,1.99481339727193,21.4000009000301,-0.00189781492673433,-0.000363049216936294,0.25,-1.79959155748758E-6,-0.000168509979226007,-3.05398461207219E-6,10.0038824,10.0042429,60517.28515625,60582.25,57.3605905122753,20.5373600435881,9.621219,0,0,0,40,4449,10.0563,60549.767578125,,,,,,,,,,,,,0,,,,-0.00245,,,,,,10.00406265,,,,
,32351934.47,10.0039167,55801.6875,-0.000150985834380833,9.08261536367198E-7,1,0.999253354069792,40.0298881530762,1.99493737995923,21.4000009000301,-0.00169852547752241,-0.000330890551731698,0.25,-2.12487437077599E-6,-0.000150894287088147,-3.24581827205559E-6,10.0039167,10.0039167,55799.203125,55804.171875,57.4786164186792,20.5391355972412,10.00087,0,0,0,40,4449,10.0521,55801.6875,,,,,,,,,,,,,0,,,,0.00245,,,,,,10.0039167,,,,
,32352029.67,10.0043459,51044.529296875,-0.000133091256856467,7.80973984733814E-7,1,0.999253354069792,40.0298881530762,1.99495046367928,21.4000009000301,-0.00149626395643291,-0.000292970685809175,0.25,-2.00529129424329E-6,-0.000132946858705082,-2.98673004629463E-6,10.0043459,10.0043459,51036.61328125,51052.4453125,57.1565854687561,20.5369181329107,9.241568,0,0,0,40,4449,10.0476,51044.529296875,,,,,,,,,,,,,0,,,,0.0049,,,,,,10.0043459,,,,
,32352123.99,10.0046082,46328.916015625,-0.000116496725874249,6.58001183845493E-7,1,0.999253354069792,40.0298881530762,1.99490113041952,21.4000009000301,-0.00130675887964629,-0.000268971363852876,0.25,-2.88714548789324E-6,-0.000116305993779256,-3.73498497363042E-6,10.0046082,10.0046082,46323.91796875,46333.9140625,57.4504777919868,20.5392551077173,9.621219,0,0,0,40,4449,10.0437,46328.916015625,,,,,,,,,,,,,0,,,,-0.00245,,,,,,10.0046082,,,,
,32352219.01,10.0043621,41581.20703125,-9.91084831355431E-5,6.06597331209051E-7,1,0.999253354069792,40.0298881530762,1.99492374476867,21.4000009000301,-0.00111205551886502,-0.000223817119080504,0.25,-2.03214015143535E-6,-9.89003347388465E-5,-2.74197377035607E-6,10.0043621,10.0043621,41581.20703125,41581.20703125,57.1628384969099,20.53633362158,10.00087,0,0,0,40,4449,10.0399,41581.20703125,,,,,,,,,,,,,0,,,,0.00245,,,,,,10.0043621,,,,
,32352314.43,10.0031528,36810.970703125,-8.2250653591453E-5,7.07163364524877E-7,1,0.999253354069792,40.0298881530762,1.99488947496327,21.4000009000301,-0.00092266081207694,-0.000184312934014738,0.25,-1.5798475248702E-6,-8.20373615388426E-5,-2.15591493076342E-6,10.0031528,10.0031528,36808.41015625,36813.53125,57.2198973788137,20.5371611923419,9.621219,0,0,0,40,4449,10.03755,36810.970703125,,,,,,,,,,,,,0,,,,-0.00245,,,,,,10.0031528,,,,
,32352410.08,10.0021887,32031.0224609375,-6.53890780098357E-5,5.94040881391842E-7,1,0.999253354069792,40.0298881530762,1.99497897689914,21.4000009000301,-0.000733155875657073,-0.000146559242434516,0.25,-1.27713135414185E-6,-6.51864658255683E-5,-1.72182873918112E-6,10.0021887,10.0021887,32025.66796875,32036.376953125,57.2660134614484,20.5380207666543,9.241568,0,0,0,40,4449,10.03485,32031.0224609375,,,,,,,,,,,,,0,,,,0.0049,,,,,,10.0021887,,,,
,32352504.38,10.0029383,27316.2626953125,-4.88729805299098E-5,5.58563606963631E-7,1,0.999253354069792,40.0298881530762,1.99489691725351,21.4000009000301,-0.000547592653014941,-0.000109984070698438,0.25,-1.01023921175964E-6,-4.86972546033161E-5,-1.33071213429473E-6,10.0029383,10.0029383,27313.73828125,27318.787109375,57.1346998702176,20.5385417744898,9.621219,0,0,0,40,4449,10.0328,27316.2626953125,,,,,,,,,,,,,0,,,,0.0049,,,,,,10.0029383,,,,
,32352599.04,10.00190165,22586.06640625,-3.17110876578304E-5,4.40731097359412E-7,1,0.999253354069792,40.0298881530762,1.994950608866,21.4000009000301,-0.000353294647794492,-8.16440027516587E-5,0.25,-1.58142523074271E-6,-3.15760655592789E-5,-1.7768569622204E-6,10.001895,10.0019083,22551.0703125,22621.0625,57.2527257766214,20.5410864060332,9.621219,0,0,0,40,4449,10.0323,22586.06640625,,,,,,,,,,,,,0,,,,0.0049,,,,,,10.00190165,,,,
,32352693.595,10.0017214,17861.12890625,-1.58221132640645E-5,4.08181039219317E-7,1,0.999253354069792,40.0298881530762,1.9948960986081,21.4000009000301,-0.000175365584150242,-4.53327158787719E-5,0.25,-1.20465220151849E-6,-1.57451860827647E-5,-1.29516203466445E-6,10.0017214,10.0017214,17858.654296875,17863.603515625,57.2793011462753,20.5387717858951,10.00087,0,0,0,40,4449,10.0309,17861.12890625,,,,,,,,,,,,,0,,,,0.00245,,,,,,10.0017214,,,,
,32352790.7,10.001215,13008.5888671875,5.73740954075666E-7,3.22865185524525E-7,1,0.999253354069792,40.0298881530762,1.99494748955068,21.4000009000301,8.01525015535213E-6,-7.64919573350892E-6,0.25,-7.83395839992228E-7,5.7543977833828E-7,-7.76323957097922E-7,10.001215,10.001215,13006.1220703125,13011.0556640625,57.3410497992945,20.5383687069109,9.621219,0,0,0,40,4449,10.0308,13008.5888671875,,,,,,,,,,,,,0,,,,-0.0049,,,,,,10.001215,,,,
,32352884.05,10.0003071,8343.12255859375,1.57639626609266E-5,4.22443086756708E-7,1,0.999253354069792,40.0298881530762,1.9949898451762,21.4000009000301,0.000178334753876988,2.41266505929734E-5,0.25,-6.59648728704755E-7,1.56851333093857E-5,-5.71526541098528E-7,10.0003071,10.0003071,8308.1376953125,8378.107421875,57.190195495083,20.5368435776344,9.621219,0,0,0,40,4449,10.03115,8343.12255859375,,,,,,,,,,,,,0,,,,0.00245,,,,,,10.0003071,,,,
,32352978.25,10.0001783,3632.466796875,3.08648374424581E-5,3.34153141272053E-7,1,0.999253354069792,40.0298881530762,1.99491014928367,21.4000009000301,0.000347205370774052,5.7498230246467E-5,0.25,-3.65457321059354E-7,3.06951505327153E-5,-2.08114373710712E-7,10.0001783,10.0001783,3630.13793945313,3634.79565429687,57.0182372208522,20.5380630225092,9.621219,0,0,0,40,4449,10.0314,3632.466796875,,,,,,,,,,,,,0,,,,0.00245,,,,,,10.0001783,,,,
,32353050.17,10.003624,35.6175910532474,4.19756460668116E-5,4.85736181124797E-7,1,0.999253354069792,40.0298881530762,1.99504950481142,21.4000009000301,0.000471633918902801,8.10061258034825E-5,0.25,-2.36970038241856E-7,4.17356858129381E-5,-3.32537716692847E-8,10.003624,10.003624,-0.304475486278534,71.5396575927734,57.4840878183138,20.5394847545262,9.621219,0,0,0,40,4417,10.02795,35.6175910532474,,,,,,,,,,,,,0,,,,0.00245,,,,,,10.003624,,,,