File: data/monolayers/magneticStructure/ML_Ac_CoFe_C/PPMS/data/DD205_4_KOELNPPMS_FCW_100OE_TOUCHDOWN.DAT
[Header]
; VSM Data File (default extension .dat)
; Copyright (c) 2003-2013, Quantum Design, Inc. All rights reserved.
TITLE,
FILEOPENTIME,19861420.25,08/18/2018,9:02 pm
BYAPP,VSM,2.0,2.0
INFO,PPMS VSM Option Release 1.4.10 Build 1,APPNAME
INFO,Quantum Design Linear Motor Servo Controller,MOTOR_MODULE_NAME
INFO,3101-100 M1,MOTOR_HW_VERSION
INFO,MMC1014,MOTOR_SERIAL_NUMBER
INFO,SRV No X-over 01.03.11,MOTOR_SOFTWARE_VERSION
INFO,Quantum Design VSM Detection Module,VSM_MODULE_NAME
INFO,3101-150 F0,VSM_HW_VERSION
INFO,VSM707,VSM_SERIAL_NUMBER
INFO,VSM No X-over 01.02.05 May 20 2008 13:51:47,VSM_SOFTWARE_VERSION
INFO,704,PREAMP_SERIAL_NUMBER
INFO,822,COIL_SERIAL_NUMBER
INFO,0,MOMENT_UNITS
INFO,,SAMPLE_MATERIAL
INFO,,SAMPLE_COMMENT
INFO,,SAMPLE_MASS
INFO,,SAMPLE_VOLUME
INFO,,SAMPLE_MOLECULAR_WEIGHT
INFO,,SAMPLE_SIZE
INFO,,SAMPLE_SHAPE
DATATYPE,COMMENT,1
DATATYPE,TIME,2
STARTUPAXIS,X,2
STARTUPAXIS,Y1,5
[Data]
Comment,Time Stamp (sec),Temperature (K),Magnetic Field (Oe),Moment (emu),M. Std. Err. (emu),Transport Action,Averaging Time (sec),Frequency (Hz),Peak Amplitude (mm),Center Position (mm),Coil Signal' (mV),Coil Signal" (mV),Range (mV),M. Quad. Signal (emu),M. Raw' (emu),M. Raw" (emu),Min. Temperature (K),Max. Temperature (K),Min. Field (Oe),Max. Field (Oe),Mass (grams),Motor Lag (deg),Pressure (Torr),VSM Status (code),Motor Status (code),Measure Status (code),Measure Count,PPMS Status (code),System Temp. (K),System Field (Oe),Sample Position (deg),Bridge 1 Resistance (ohms),Bridge 1 Excitation (에),Bridge 2 Resistance (ohms),Bridge 2 Excitation (에),Bridge 3 Resistance (ohms),Bridge 3 Excitation (에),Bridge 4 Resistance (ohms),Bridge 4 Excitation (에),Signal 1 Vin (V),Signal 2 Vin (V),Digital Inputs (code),Drive 1 Iout (mA),Drive 1 Ipower (W),Drive 2 Iout (mA),Drive 2 Ipower (W),Pressure (),Map 20 (),Map 21 (),Map 22 (),Map 23 (),Map 24 (),Map 25 (),Map 26 (),Map 27 (),Map 28 (),Map 29 ()
,19861441.61,4.9795089,99.8070526123047,,,2,,,,15.7999998086691,,,,,,,4.9795089,4.9795089,99.8070526123047,99.8070526123047,,,8.861917,,,,-99999999,4373,5.0111,99.8070526123047,,,,,,,,,,,,,,,,,,,,,,,4.9795089,,,,
,19861678.745,8.0780535,99.8070526123047,1.12940190683855E-5,2.78838088315932E-7,1,0.999253354069792,40.0298881530762,2.00456206379342,15.7800000160933,0.000128843882134114,1.41932327198286E-5,0.25,-7.46808287315911E-7,1.1232797698587E-5,-6.88052555841651E-7,8.0780535,8.0780535,99.8070526123047,99.8070526123047,54.0808772455826,19.5897212525814,11.139823,0,0,0,40,4370,8.1873,99.8070526123047,,,,,,,,,,,,,0,,,,-0.0049,,,,,,8.0780535,,,,
,19861805.945,11.23076865,99.8070526123047,1.14000677749781E-5,2.68857296346064E-7,1,0.999253354069792,40.0298881530762,2.00476487740792,15.7800000160933,0.000128962995620484,2.05372958204912E-5,0.25,-2.03178433986436E-7,1.13355632677469E-5,-1.47030779175422E-7,11.2039289,11.2576084,99.8070526123047,99.8070526123047,54.4552773062942,19.5870165586801,11.519473,0,0,0,40,4370,11.39205,99.8070526123047,,,,,,,,,,,,,0,,,,-0.00245,,,,,,11.23076865,,,,
,19861931.68,14.3362713,99.8070526123047,1.17446338982253E-5,2.85033469262327E-7,1,0.999253354069792,40.0298881530762,2.00473753151338,15.7800000160933,0.000132844677585555,2.12339190448614E-5,0.25,-2.02552416018305E-7,1.16780649551656E-5,-1.44745556083551E-7,14.3070288,14.3655138,99.8070526123047,99.8070526123047,54.1301198422942,19.5876454378681,12.658426,0,0,0,40,4370,14.5689,99.8070526123047,,,,,,,,,,,,,0,,,,0,,,,,,14.3362713,,,,
,19862087.805,18.208374,99.8070526123047,1.12506762282527E-5,3.12782926310095E-7,1,0.999253354069792,40.0298881530762,1.99382060437796,15.7999992370605,0.000127204685149134,1.68010845303079E-5,0.25,-5.00175663833072E-7,1.11882783082732E-5,-4.43000932288966E-7,18.208374,18.208374,99.8070526123047,99.8070526123047,54.1762359249288,19.5862230777725,13.417728,0,0,0,40,4374,18.496,99.8070526123047,,,,,,,,,,,,,0,,,,-0.0049,,,,,,18.208374,,,,
,19862213.39,21.3075829,99.8070526123047,1.14906783442975E-5,2.97336932748613E-7,1,0.999253354069792,40.0298881530762,1.99380947640272,15.7999992370605,0.000130211056331647,1.5546041336973E-5,0.25,-6.55548310674233E-7,1.1428245696962E-5,-5.95547914002149E-7,21.3075829,21.3075829,99.8070526123047,99.8070526123047,54.1926501238326,19.5899839019573,13.797379,0,0,0,40,4370,21.6639,99.8070526123047,,,,,,,,,,,,,0,,,,0,,,,,,21.3075829,,,,
,19862330.565,24.2198772,99.8070526123047,1.15832642883493E-5,2.74894012247568E-7,1,0.999253354069792,40.0298881530762,1.99383811178714,15.7999992370605,0.000130612282453605,1.94185540087142E-5,0.25,-3.28672407304795E-7,1.15200623886454E-5,-2.68481104833673E-7,24.2198772,24.2198772,99.8070526123047,99.8070526123047,54.3857123680827,19.5900892055273,14.556682,0,0,0,40,4370,24.6308,99.8070526123047,,,,,,,,,,,,,0,,,,0,,,,,,24.2198772,,,,
,19862472.035,27.6954193,99.8070526123047,1.16878575218452E-5,3.02305359916197E-7,1,0.999253354069792,40.0298881530762,1.99390675238051,15.8099997788668,0.000131324805706018,2.24347317930017E-5,0.25,-8.21881284700609E-8,1.16257148987219E-5,-1.96813521830348E-8,27.6954193,27.6954193,99.8070526123047,99.8070526123047,54.159821726025,19.5885818769903,14.556682,0,0,0,40,4374,28.23705,99.8070526123047,,,,,,,,,,,,,0,,,,0,,,,,,27.6954193,,,,
,19862601.755,30.8956127,99.8070526123047,1.18002632259275E-5,2.93989976576174E-7,1,0.999253354069792,40.0298881530762,1.9940753075042,15.7999992370605,0.000132938237108931,2.10149671014022E-5,0.25,-2.33461220030371E-7,1.17424388320221E-5,-1.65698754585762E-7,30.8956127,30.8956127,99.8070526123047,99.8070526123047,54.3818042254865,19.5858549972835,15.315984,0,0,0,40,4374,31.4966,99.8070526123047,,,,,,,,,,,,,0,,,,0.00245,,,,,,30.8956127,,,,
,19862733.085,34.1517181,99.8070526123047,1.14943025594468E-5,3.39701025381021E-7,1,0.999253354069792,40.0298881530762,1.99405297522197,15.7999992370605,0.000129336097445803,2.17021665040594E-5,0.25,-1.23188167856639E-7,1.14430310191572E-5,-5.31592173794991E-8,34.1517181,34.1517181,99.8070526123047,99.8070526123047,54.2043745516211,19.5847872100849,15.695635,0,0,0,40,4370,34.8115,99.8070526123047,,,,,,,,,,,,,0,,,,-0.00245,,,,,,34.1517181,,,,
,19862891.83,38.0483551,99.8070526123047,1.15577214238731E-5,3.16007149737447E-7,1,0.999253354069792,40.0298881530762,1.99408425299197,15.7800000160933,0.000130399773447306,2.04855527429173E-5,0.25,-2.50298334554317E-7,1.15162655959767E-5,-1.73551348038285E-7,38.0483551,38.0483551,99.8070526123047,99.8070526123047,54.3388146569288,19.5828987349474,16.075285,0,0,0,40,4374,38.8288,99.8070526123047,,,,,,,,,,,,,0,,,,0,,,,,,38.0483551,,,,
,19863016.835,41.1022377,99.8070526123047,1.16151338950307E-5,2.55386954891433E-7,1,0.999253354069792,40.0298881530762,1.99394144305419,15.7800000160933,0.000131210857203019,2.02260366588962E-5,0.25,-2.89300744105224E-7,1.15829467223641E-5,-2.07915303874633E-7,41.1022377,41.1022377,99.8070526123047,99.8070526123047,54.2653415761211,19.5881544266271,16.834587,0,0,0,40,4374,41.9943,99.8070526123047,,,,,,,,,,,,,0,,,,0,,,,,,41.1022377,,,,
,19863143.785,44.2343407,99.8070526123047,1.1632218846181E-5,3.12646226356649E-7,1,0.999253354069792,40.0298881530762,1.99400849924786,15.7800000160933,0.000130828459088097,2.41748378050456E-5,0.25,5.32931226394947E-8,1.16082912980076E-5,1.37311641698654E-7,44.2343407,44.2343407,99.8070526123047,99.8070526123047,54.464656848525,19.5885013351677,16.834587,0,0,0,40,4374,45.22525,99.8070526123047,,,,,,,,,,,,,0,,,,0.0049,,,,,,44.2343407,,,,
,19863294.94,47.9269333,99.8070526123047,1.13009398835432E-5,2.94884689483433E-7,1,0.999253354069792,40.0298881530762,1.99403263594457,15.769999474287,0.000127886032058694,2.00208694266108E-5,0.25,-2.60318367667208E-7,1.12935079577836E-5,-1.76210025785448E-7,47.9269333,47.9269333,99.8070526123047,99.8070526123047,54.2903536887365,19.5877019058633,16.834587,0,0,0,40,4374,49.08725,99.8070526123047,,,,,,,,,,,,,0,,,,0,,,,,,47.9269333,,,,
,19863417.805,50.8796883,99.8070526123047,1.13587597122924E-5,2.99136998555714E-7,1,0.999253354069792,40.0298881530762,1.99413412574822,15.769999474287,0.000128842167288605,1.92102710527749E-5,0.25,-3.44368478465472E-7,1.1363141532514E-5,-2.6008581428663E-7,50.8796883,50.8796883,99.8070526123047,99.8070526123047,54.3138025443134,19.5867424293899,17.973541,0,0,0,40,4374,52.2401,99.8070526123047,,,,,,,,,,,,,0,,,,0,,,,,,50.8796883,,,,
,19863540.32,53.821434,99.8070526123047,1.14387597310989E-5,2.80214883533559E-7,1,0.999253354069792,40.0298881530762,1.99415925947703,15.7800000160933,0.000130319407921826,1.68891211758881E-5,0.25,-5.64364889099749E-7,1.14555772995638E-5,-4.81576820197174E-7,53.821434,53.821434,99.8070526123047,99.8070526123047,54.2223520075634,19.5877706156302,18.732843,0,0,0,40,4374,55.4077,99.8070526123047,,,,,,,,,,,,,0,,,,-0.00245,,,,,,53.821434,,,,
,19863693.155,57.5626297,99.8070526123047,1.15750712115811E-5,3.20819626958213E-7,1,0.999253354069792,40.0298881530762,2.00487714459123,15.7399997115135,0.000131760983989297,2.23394080267552E-5,0.25,-1.14710184182897E-7,1.16009076026497E-5,-3.41718947088443E-8,57.5626297,57.5626297,99.8070526123047,99.8070526123047,54.078532360025,19.5838788997329,19.871798,0,0,0,40,4374,59.32045,99.8070526123047,,,,,,,,,,,,,0,,,,-0.00245,,,,,,57.5626297,,,,
,19863814.47,60.4987907,99.8070526123047,1.17074801899027E-5,2.52914379016121E-7,1,0.999253354069792,40.0298881530762,2.00492533607664,15.7399997115135,0.000133722867100851,2.06214246560532E-5,0.25,-2.87137370068035E-7,1.17431001971838E-5,-2.10089572316906E-7,60.4987907,60.4987907,99.8070526123047,99.8070526123047,54.2325131783134,19.5883897610571,19.492144,0,0,0,40,4374,62.4234,99.8070526123047,,,,,,,,,,,,,0,,,,0.00245,,,,,,60.4987907,,,,
,19863937.05,63.5458717,99.8070526123047,1.12918391055499E-5,2.88228743821282E-7,1,0.999253354069792,40.0298881530762,2.00464257416766,15.7399997115135,0.000128756338853537,2.1452083969999E-5,0.25,-1.36225789340144E-7,1.13320492800015E-5,-6.57265113460908E-8,63.5458717,63.5458717,99.8070526123047,99.8070526123047,54.4302651936788,19.5874882858756,20.251448,0,0,0,40,4374,65.5316,99.8070526123047,,,,,,,,,,,,,0,,,,-0.00245,,,,,,63.5458717,,,,
,19864061.53,66.5453339,99.8070526123047,1.13921314914626E-5,3.08542580511874E-7,1,0.999253354069792,40.0298881530762,2.00469595649219,15.7399997115135,0.000130460474155477,1.89006884876569E-5,0.25,-3.74838778136752E-7,1.14398809754095E-5,-3.09155175149039E-7,66.5453339,66.5453339,99.8070526123047,99.8070526123047,54.5686134415827,19.5900988782022,19.871798,0,0,0,40,4374,68.70645,99.8070526123047,,,,,,,,,,,,,0,,,,0,,,,,,66.5453339,,,,
,19864211.93,70.2103271,99.8070526123047,1.10886718511619E-5,3.08047278378097E-7,1,0.999253354069792,40.0298881530762,1.99377536006075,15.6999994069338,0.000125414117553961,2.37582177199318E-5,0.25,1.21059844982502E-7,1.11377888394643E-5,1.81853395570032E-7,70.2103271,70.2103271,99.8070526123047,99.8070526123047,54.4255754225635,19.5869529649984,20.251448,0,0,0,40,4374,72.55645,99.8070526123047,,,,,,,,,,,,,0,,,,0,,,,,,70.2103271,,,,
,19864334.615,73.24286655,99.8070526123047,1.12904535047347E-5,2.79770378490779E-7,1,0.999253354069792,40.0298881530762,1.99401220525847,15.6999994069338,0.000128491737849922,2.00300299230691E-5,0.25,-2.40584556550648E-7,1.13458371102664E-5,-1.84412339465524E-7,73.217598,73.2681351,99.8070526123047,99.8070526123047,54.2520538912942,19.5857966252974,20.631098,0,0,0,40,4374,75.6678,99.8070526123047,,,,,,,,,,,,,0,,,,-0.0049,,,,,,73.24286655,,,,
,19864457.345,76.2771988,99.8070526123047,1.14924650849833E-5,3.05370903729277E-7,1,0.999253354069792,40.0298881530762,1.99400422193575,15.6999994069338,0.000130796748818982,2.05286734874734E-5,0.25,-2.29113556135672E-7,1.1551481520238E-5,-1.75741038723267E-7,76.2771988,76.2771988,99.8070526123047,99.8070526123047,54.3700797976981,19.5853256150046,21.3904,0,0,0,40,4374,78.77625,99.8070526123047,,,,,,,,,,,,,0,,,,0,,,,,,76.2771988,,,,
,19864653.315,81.1163712,99.8070526123047,1.16184180210289E-5,2.79515311401837E-7,1,0.999253354069792,40.0298881530762,2.00475789830182,15.6800001859665,0.000133017814950377,2.04626875072738E-5,0.25,-2.61455237239573E-7,1.16813771493656E-5,-2.13276814433182E-7,81.1163712,81.1163712,99.8070526123047,99.8070526123047,54.3356881428519,19.5866897459256,21.01075,0,0,0,40,4374,83.73235,99.8070526123047,,,,,,,,,,,,,0,,,,0,,,,,,81.1163712,,,,
,19864844.09,85.8196182,99.8070526123047,1.13868960652253E-5,3.01115384227844E-7,1,0.999253354069792,40.0298881530762,2.00488419832499,15.6800001859665,0.000130385983951359,2.01212489325623E-5,0.25,-2.46249759706967E-7,1.1450502919691E-5,-2.03618786503448E-7,85.8196182,85.8196182,99.8070526123047,99.8070526123047,54.0613365326019,19.5898314680718,21.3904,0,0,0,40,4374,88.5501,99.8070526123047,,,,,,,,,,,,,0,,,,0,,,,,,85.8196182,,,,
,19865070.14,91.4358673,99.8070526123047,1.11009670115947E-5,3.0763594878795E-7,1,0.999253354069792,40.0298881530762,1.99390071569742,15.6100001186132,0.000126860595642735,1.72512680405185E-5,0.25,-4.350677211055E-7,1.11649412017333E-5,-3.99165662689975E-7,91.4358673,91.4358673,99.8070526123047,99.8070526123047,54.0496121048134,19.5899743801756,22.149702,0,0,0,40,4374,94.26285,99.8070526123047,,,,,,,,,,,,,0,,,,0,,,,,,91.4358673,,,,
,19865263.05,96.0984879,99.8070526123047,1.13897237123002E-5,2.45128428699873E-7,1,0.999253354069792,40.0298881530762,1.99377516054212,15.6199997290969,0.000129587711092176,2.09454190030576E-5,0.25,-1.57022548795273E-7,1.14549601489342E-5,-1.21978240221724E-7,96.0984879,96.0984879,99.8070526123047,99.8070526123047,54.1777991819673,19.5901657737186,22.149702,0,0,0,40,4374,99.19515,99.8070526123047,,,,,,,,,,,,,0,,,,0.0049,,,,,,96.0984879,,,,
,19865420.235,99.9960213,99.8070526123047,1.1767853558658E-5,3.05156020691552E-7,1,0.999253354069792,40.0298881530762,1.98103140827017,15.599999576807,0.00013329791067079,2.02339218939407E-5,0.25,-2.72781484004774E-7,1.18357252776587E-5,-2.39691127460434E-7,99.9670029,100.0250397,99.8070526123047,99.8070526123047,54.210627579775,19.5860387586314,22.149702,0,0,0,40,4374,103.1686,99.8070526123047,,,,,,,,,,,,,0,,,,-0.00245,,,,,,99.9960213,,,,
,19865543.185,103.0293808,99.8070526123047,1.1557886122007E-5,2.77768362815939E-7,1,0.999253354069792,40.0298881530762,1.9810637859449,15.6100001186132,0.000130304336412547,2.33872554088543E-5,0.25,4.52822844848388E-8,1.16236112138282E-5,7.78501368747143E-8,103.0293808,103.0293808,99.8070526123047,99.8070526123047,54.2731578613134,19.5891125761526,22.909004,0,0,0,40,4374,106.2719,99.8070526123047,,,,,,,,,,,,,0,,,,-0.00245,,,,,,103.0293808,,,,
,19865665.065,106.0779572,99.8070526123047,1.13799693958426E-5,2.75698303032315E-7,1,0.999253354069792,40.0298881530762,1.9810052192458,15.6100001186132,0.000129243961068743,1.76030058291768E-5,0.25,-4.34619068540701E-7,1.1445816929574E-5,-4.06801688597446E-7,106.0779572,106.0779572,99.8070526123047,99.8070526123047,54.1082342437557,19.5898544527976,22.529354,0,0,0,40,4374,109.3308,99.8070526123047,,,,,,,,,,,,,0,,,,0,,,,,,106.0779572,,,,
,19865811.25,109.6993828,99.8070526123047,1.14869055572858E-5,2.99814133525714E-7,1,0.999253354069792,40.0298881530762,1.99373159084799,15.5600002035499,0.000130134457124999,2.42720755659806E-5,0.25,1.26385870033624E-7,1.15515904378745E-5,1.55992056318366E-7,109.6715622,109.7272034,99.8070526123047,99.8070526123047,54.2528355198134,19.5858296831565,22.529354,0,0,0,40,4374,113.00675,99.8070526123047,,,,,,,,,,,,,0,,,,0,,,,,,109.6993828,,,,
,19865929.23,112.6160278,99.8070526123047,1.11904050197714E-5,3.03823081869202E-7,1,0.999253354069792,40.0298881530762,1.9938295071377,15.5600002035499,0.000127557419559782,1.91928233584306E-5,0.25,-2.67988128900714E-7,1.12540587303293E-5,-2.42557677599535E-7,112.6160278,112.6160278,99.8070526123047,99.8070526123047,54.0714977033519,19.5848267116663,22.909004,0,0,0,40,4374,115.9724,99.8070526123047,,,,,,,,,,,,,0,,,,-0.00245,,,,,,112.6160278,,,,
,19866047.955,115.601326,99.8070526123047,1.1545541005883E-5,3.11339878980385E-7,1,0.999253354069792,40.0298881530762,1.99384537583585,15.5600002035499,0.000132280129849492,1.59224700004803E-5,0.25,-6.17056825511668E-7,1.16115630711328E-5,-5.93873295935483E-7,115.601326,115.601326,99.8070526123047,99.8070526123047,54.2747211183519,19.5857098207334,22.529354,0,0,0,40,4374,118.9636,99.8070526123047,,,,,,,,,,,,,0,,,,0,,,,,,115.601326,,,,
,19866165.895,118.5500183,99.8070526123047,1.12121991241658E-5,2.83098267695112E-7,1,0.999253354069792,40.0298881530762,1.99360516402302,15.5600002035499,0.000127775670720365,1.92619674920166E-5,0.25,-2.63252754347907E-7,1.12750643441787E-5,-2.39876420503841E-7,118.5500183,118.5500183,99.8070526123047,99.8070526123047,54.2137540938519,19.5903753657637,22.909004,0,0,0,40,4374,121.9203,99.8070526123047,,,,,,,,,,,,,0,,,,-0.00245,,,,,,118.5500183,,,,
,19866312.055,122.157341,99.8070526123047,1.15944116390156E-5,2.81123362740596E-7,1,0.999253354069792,40.0298881530762,1.98107270340818,15.4600003734231,0.000131712541785334,1.76114150120808E-5,0.25,-4.64837691262447E-7,1.16591594213155E-5,-4.42921432194697E-7,122.157341,122.157341,99.8070526123047,99.8070526123047,54.2028112945827,19.5864847604857,22.909004,0,0,0,40,4374,125.58995,99.8070526123047,,,,,,,,,,,,,0,,,,0,,,,,,122.157341,,,,
,19866430.21,125.0709152,99.8070526123047,1.16867885687165E-5,3.2935744460068E-7,1,0.999253354069792,40.0298881530762,1.98105623219023,15.4600003734231,0.00013275311091085,1.7755740043981E-5,0.25,-4.67183063853596E-7,1.17514411657535E-5,-4.45975176984975E-7,125.0709152,125.0709152,99.8070526123047,99.8070526123047,53.9526901684288,19.5870897463533,23.288654,0,0,0,40,4374,128.5693,99.8070526123047,,,,,,,,,,,,,0,,,,0,,,,,,125.0709152,,,,
,19866549.955,128.0600586,99.8070526123047,1.13322539817797E-5,3.61416780620184E-7,1,0.999253354069792,40.0298881530762,1.9809293897367,15.4600003734231,0.000128113425551864,2.06358910475314E-5,0.25,-1.48899476228429E-7,1.1393701099154E-5,-1.27501362245937E-7,128.0600586,128.0600586,99.8070526123047,99.8070526123047,54.0699344463134,19.5907667590152,23.288654,0,0,0,40,4374,131.57985,99.8070526123047,,,,,,,,,,,,,0,,,,0.00245,,,,,,128.0600586,,,,
,19866699.56,131.8016663,99.8070526123047,1.12719274480561E-5,2.86988416640185E-7,1,0.999253354069792,40.0298881530762,1.99376940418215,15.4600003734231,0.000128412734374612,1.94938437362798E-5,0.25,-2.49172511250619E-7,1.13324044636305E-5,-2.2937162392674E-7,131.8016663,131.8016663,99.8070526123047,99.8070526123047,54.1183954145057,19.5807688490941,23.288654,0,0,0,40,4374,135.34655,99.8070526123047,,,,,,,,,,,,,0,,,,-0.00245,,,,,,131.8016663,,,,
,19866821.045,134.7854767,99.8070526123047,1.12445954896393E-5,3.09673094200908E-7,1,0.999253354069792,40.0298881530762,1.99372236861592,15.4699999839067,0.000127702377081142,2.16699303007937E-5,0.25,-5.1780442637513E-8,1.13038659582862E-5,-3.16932152208555E-8,134.7854767,134.7854767,99.8070526123047,99.8070526123047,54.1215219285826,19.5794425125265,24.047956,0,0,0,40,4374,138.4079,99.8070526123047,,,,,,,,,,,,,0,,,,0,,,,,,134.7854767,,,,
,19866942.625,137.8036499,99.8070526123047,1.14810628354366E-5,3.35933067883076E-7,1,0.999253354069792,40.0298881530762,1.99363060646924,15.4600003734231,0.00013139474506562,1.62675461646412E-5,0.25,-5.68268669529129E-7,1.15417334368268E-5,-5.51115997446438E-7,137.8036499,137.8036499,99.8070526123047,99.8070526123047,53.9456555117557,19.5819241202095,24.047956,0,0,0,40,4374,141.4617,99.8070526123047,,,,,,,,,,,,,0,,,,0,,,,,,137.8036499,,,,
,19867093.095,141.5453644,99.8070526123047,1.12156562045861E-5,3.47882060007602E-7,1,0.999253354069792,40.0298881530762,2.00476084035483,15.4100004583597,0.00012805358030676,2.15755017018145E-5,0.25,-6.33406282203643E-8,1.12731148355793E-5,-4.47896984182014E-8,141.5453644,141.5453644,99.8070526123047,99.8070526123047,53.9628513391788,19.5782450655636,24.047956,0,0,0,40,4374,145.2504,99.8070526123047,,,,,,,,,,,,,0,,,,-0.0049,,,,,,141.5453644,,,,
,19867212.415,144.4842834,99.8070526123047,1.0859977068742E-5,2.70593249591193E-7,1,0.999253354069792,40.0298881530762,2.00444405959734,15.4100004583597,0.000124184772211938,1.96280468952284E-5,0.25,-1.71161104214932E-7,1.09150444774334E-5,-1.54294894087329E-7,144.4842834,144.4842834,99.8070526123047,99.8070526123047,53.9511269113903,19.589471301916,23.668306,0,0,0,40,4374,148.2477,99.8070526123047,,,,,,,,,,,,,0,,,,0,,,,,,144.4842834,,,,
,19867331.765,147.4861145,99.8070526123047,1.1264840344138E-5,2.96253520700816E-7,1,0.999253354069792,40.0298881530762,2.00449487755314,15.4100004583597,0.000129483984218223,1.64790986796087E-5,0.25,-5.17238197637131E-7,1.13216739658978E-5,-5.01952339299566E-7,147.4861145,147.4861145,99.8070526123047,99.8070526123047,54.1660747541788,19.5886035431388,23.668306,0,0,0,40,4374,151.2445,99.8070526123047,,,,,,,,,,,,,0,,,,-0.00245,,,,,,147.4861145,,,,
,19867480.47,151.1903076,99.8070526123047,1.14635958077864E-5,2.99313370647672E-7,1,0.999253354069792,40.0298881530762,1.99357936917896,15.3599996119738,0.000130527487039716,1.98044150577066E-5,0.25,-2.50391009543922E-7,1.15199240090404E-5,-2.34069932914017E-7,151.1578827,151.2227325,99.8070526123047,99.8070526123047,53.7580646671403,19.5779170353917,24.047956,0,0,0,40,4374,154.9677,99.8070526123047,,,,,,,,,,,,,0,,,,0,,,,,,151.1903076,,,,
,19867600.18,154.1645355,99.8070526123047,1.12222525069915E-5,3.4698050732499E-7,1,0.999253354069792,40.0298881530762,1.99348495610245,15.3599996119738,0.000127996754970532,1.80477469550957E-5,0.25,-3.62570410300529E-7,1.12767057590655E-5,-3.47605207954295E-7,154.1645355,154.1645355,99.8070526123047,99.8070526123047,54.105889358198,19.5835787484655,24.047956,0,0,0,40,4374,157.9776,99.8070526123047,,,,,,,,,,,,,0,,,,0,,,,,,154.1645355,,,,
,19867718.86,157.1244812,99.8070526123047,1.11575354274618E-5,3.51024985288409E-7,1,0.999253354069792,40.0298881530762,1.99347243210783,15.37000015378,0.000126552911169421,2.1934721816906E-5,0.25,-8.00081247908459E-9,1.12102847063328E-5,8.13919711311045E-9,157.1244812,157.1244812,99.8070526123047,99.8070526123047,54.0644630466788,19.5799701970891,24.427608,0,0,0,40,4374,160.95015,99.8070526123047,,,,,,,,,,,,,0,,,,-0.00245,,,,,,157.1244812,,,,
,19867835.56,160.0491943,99.8070526123047,1.11644702794922E-5,3.12223993256652E-7,1,0.999253354069792,40.0298881530762,1.99344575153409,15.37000015378,0.000127708823921546,1.56901702810547E-5,0.25,-5.59297903037666E-7,1.12171580976418E-5,-5.4611354196628E-7,160.0491943,160.0491943,99.8070526123047,99.8070526123047,54.0722793318711,19.5814539583232,24.047956,0,0,0,40,4374,163.8763,99.8070526123047,,,,,,,,,,,,,0,,,,0.00245,,,,,,160.0491943,,,,
,19867982.71,163.7430573,99.8070526123047,1.14634087441929E-5,3.61792620666325E-7,1,0.999253354069792,40.0298881530762,1.99314836572676,15.3000000864267,0.00013030688679723,2.06430873505509E-5,0.25,-1.73623960505205E-7,1.15157760279414E-5,-1.58698679498919E-7,163.7430573,163.7430573,99.8070526123047,99.8070526123047,53.7901114364288,19.585713432128,24.047956,0,0,0,40,4374,167.5635,99.8070526123047,,,,,,,,,,,,,0,,,,0,,,,,,163.7430573,,,,
,19868099.72,166.6502228,99.8070526123047,1.1500422850934E-5,2.4953499736146E-7,1,0.999253354069792,40.0298881530762,1.9929049932657,15.3099996969104,0.000131710707920442,1.49055676645915E-5,0.25,-6.85506469100983E-7,1.15527066570952E-5,-6.73173129133072E-7,166.6502228,166.6502228,99.8070526123047,99.8070526123047,53.9816104236403,19.5890724127705,24.047956,0,0,0,40,4374,170.497,99.8070526123047,,,,,,,,,,,,,0,,,,0,,,,,,166.6502228,,,,
,19868214.065,169.4873199,99.8070526123047,1.13637829674674E-5,3.04481114376207E-7,1,0.999253354069792,40.0298881530762,1.99309326374315,15.3099996969104,0.000130218125450487,1.43191104924889E-5,0.25,-7.13147524293915E-7,1.14145593599642E-5,-7.01403561372631E-7,169.4873199,169.4873199,99.8070526123047,99.8070526123047,53.7776053801211,19.589919928541,24.807261,0,0,0,40,4374,173.3631,99.8070526123047,,,,,,,,,,,,,0,,,,-0.00245,,,,,,169.4873199,,,,
,19868361.265,173.1786041,99.8070526123047,1.12197731998361E-5,3.29778233578274E-7,1,0.999253354069792,40.0298881530762,2.00379952175746,15.259999781847,0.000128049631896273,2.08986791804431E-5,0.25,-1.16454326592401E-7,1.12679391880859E-5,-1.02678444142475E-7,173.1786041,173.1786041,99.8070526123047,99.8070526123047,53.7721339804865,19.5874498293383,24.427608,0,0,0,40,4374,177.0495,99.8070526123047,,,,,,,,,,,,,0,,,,0,,,,,,173.1786041,,,,
,19868480.01,176.1417694,99.8070526123047,1.14666003492916E-5,2.78823613285148E-7,1,0.999253354069792,40.0298881530762,2.0037502541123,15.259999781847,0.000130447557920301,2.36836692189044E-5,0.25,8.56349659033798E-8,1.15145730397719E-5,1.00262449615066E-7,176.1417694,176.1417694,99.8070526123047,99.8070526123047,53.9347127124865,19.5894490195413,24.807261,0,0,0,40,4374,180.0265,99.8070526123047,,,,,,,,,,,,,0,,,,-0.0049,,,,,,176.1417694,,,,
,19868597.115,179.0729675,99.8070526123047,1.16176092025665E-5,3.11800506054356E-7,1,0.999253354069792,40.0298881530762,2.003894702236,15.2700003236532,0.000132907184295159,1.97147434378285E-5,0.25,-2.88707404136466E-7,1.16656623831696E-5,-2.75741172013095E-7,179.0729675,179.0729675,99.8070526123047,99.8070526123047,53.9995878795826,19.5871471253912,24.807261,0,0,0,40,4374,182.9589,99.8070526123047,,,,,,,,,,,,,0,,,,0.00245,,,,,,179.0729675,,,,
,19868741.595,182.6547699,99.8070526123047,1.1288271686917E-5,3.9096589974377E-7,1,0.999253354069792,40.0298881530762,1.9929941186666,15.2099998667836,0.000128463859796056,1.90042460345884E-5,0.25,-2.84600242734261E-7,1.13337422627333E-5,-2.72335353173964E-7,182.6547699,182.6547699,99.8070526123047,99.8070526123047,53.7666625808518,19.5890863739499,25.186911,0,0,0,40,4374,186.5814,99.8070526123047,,,,,,,,,,,,,0,,,,-0.00245,,,,,,182.6547699,,,,
,19868859.435,185.5770645,99.8070526123047,1.1438051069525E-5,3.69609990829149E-7,1,0.999253354069792,40.0298881530762,1.99327471178242,15.2099998667836,0.000130222021849763,1.89823828671071E-5,0.25,-3.12364542220549E-7,1.14831268754064E-5,-3.00278539742054E-7,185.5446014,185.6095276,99.8070526123047,99.8070526123047,53.7736972375249,19.5843594165878,24.427608,0,0,0,40,4374,189.53615,99.8070526123047,,,,,,,,,,,,,0,,,,0.0049,,,,,,185.5770645,,,,
,19868974.33,188.4325562,99.8070526123047,1.14538226222318E-5,3.04927095636623E-7,1,0.999253354069792,40.0298881530762,1.9930157444675,15.2099998667836,0.000129585621876647,2.35413904306862E-5,0.25,8.79294304342762E-8,1.14974880791468E-5,1.01334453295128E-7,188.4325562,188.4325562,99.8070526123047,99.8070526123047,53.9089189713519,19.5872045740569,25.566563,0,0,0,40,4374,192.4219,99.8070526123047,,,,,,,,,,,,,0,,,,0.00245,,,,,,188.4325562,,,,
,19869087.685,191.2715988,99.8070526123047,1.15739715829442E-5,3.31530337909328E-7,1,0.999253354069792,40.0298881530762,1.9930102067604,15.2000002563,0.000131543649172209,2.02716754084272E-5,0.25,-2.21158020336686E-7,1.16174203653544E-5,-2.09022609827328E-7,191.2393341,191.3038635,99.8070526123047,99.8070526123047,54.065244675198,19.5870229618752,24.807261,0,0,0,40,4374,195.267,99.8070526123047,,,,,,,,,,,,,0,,,,0.00245,,,,,,191.2715988,,,,
,19869232.6,194.8953705,99.8070526123047,1.13639820027868E-5,3.63045073428278E-7,1,0.999253354069792,40.0298881530762,1.99309592904354,15.1500003412366,0.000129357685647869,1.86927548738036E-5,0.25,-3.23647871831749E-7,1.14054562453687E-5,-3.12387587473335E-7,194.8953705,194.8953705,99.8070526123047,99.8070526123047,54.1527870693519,19.5903600767291,25.186911,0,0,0,40,4374,198.9048,99.8070526123047,,,,,,,,,,,,,0,,,,0.00245,,,,,,194.8953705,,,,
,19869349.07,197.7681885,99.8070526123047,1.13810188760657E-5,3.82978278887272E-7,1,0.999253354069792,40.0298881530762,1.99335738299388,15.1599999517202,0.00013041474050836,1.37768133697848E-5,0.25,-7.60418898211902E-7,1.14219772757832E-5,-7.50878456944935E-7,197.739151,197.797226,99.8070526123047,99.8070526123047,53.9847369377173,19.5884620197434,24.807261,0,0,0,40,4374,201.83995,99.8070526123047,,,,,,,,,,,,,0,,,,0,,,,,,197.7681885,,,,
,19869466.505,200.7134094,99.8070526123047,1.16406651346715E-5,3.27537633457022E-7,1,0.999253354069792,40.0298881530762,1.99345873682782,15.1599999517202,0.000132595092878212,1.86318393593752E-5,0.25,-3.76610991874511E-7,1.16810187569556E-5,-3.65626347038585E-7,200.7134094,200.7134094,99.8070526123047,99.8070526123047,54.1606033545442,19.5887891646618,25.186911,0,0,0,40,4374,204.7753,99.8070526123047,,,,,,,,,,,,,0,,,,0,,,,,,200.7134094,,,,
,19869611.225,204.3143768,99.8070526123047,1.15058053610818E-5,3.0756673992359E-7,1,0.999253354069792,40.0298881530762,1.99363010799723,15.1000004261732,0.000130962274755777,1.89456841153611E-5,0.25,-3.25164374081268E-7,1.15442916763029E-5,-3.14370499658921E-7,204.3143768,204.3143768,99.8070526123047,99.8070526123047,53.9964613655057,19.581587402655,25.186911,0,0,0,40,4374,208.4126,99.8070526123047,,,,,,,,,,,,,0,,,,0,,,,,,204.3143768,,,,
,19869725.195,207.1395874,99.8070526123047,1.17976175792275E-5,3.4293322821016E-7,1,0.999253354069792,40.0298881530762,1.99349806483462,15.1100000366569,0.000134731604828666,1.67232172330003E-5,0.25,-5.71615671757196E-7,1.18362263493177E-5,-5.61488573133369E-7,207.1395874,207.1395874,99.8070526123047,99.8070526123047,54.1144872719096,19.583912014195,25.566563,0,0,0,40,4374,211.26935,99.8070526123047,,,,,,,,,,,,,0,,,,0,,,,,,207.1395874,,,,
,19869840.87,210.053894,99.8070526123047,1.15653439255965E-5,3.0589967316072E-7,1,0.999253354069792,40.0298881530762,1.99368876313149,15.1100000366569,0.00013190480987494,1.73932199793045E-5,0.25,-4.71924779731563E-7,1.16019845550236E-5,-4.61862667698693E-7,210.053894,210.053894,99.8070526123047,99.8070526123047,54.1715461538134,19.5782606555395,25.946213,0,0,0,40,4374,214.17495,99.8070526123047,,,,,,,,,,,,,0,,,,-0.0049,,,,,,210.053894,,,,
,19869982.4,213.5454712,99.8070526123047,1.12234732128179E-5,3.0276395553168E-7,1,0.999253354069792,40.0298881530762,1.99361508779282,15.0600001215935,0.000126858965468516,2.33711510524653E-5,0.25,1.15811422994393E-7,1.12571603023485E-5,1.27133701557085E-7,213.5454712,213.5454712,99.8070526123047,99.8070526123047,53.8682742883518,19.5781246571313,25.566563,0,0,0,40,4374,217.721,99.8070526123047,,,,,,,,,,,,,0,,,,-0.0049,,,,,,213.5454712,,,,
,19870097.545,216.4262009,99.8070526123047,1.13296744582953E-5,3.64753640161401E-7,1,0.999253354069792,40.0298881530762,1.9936235684504,15.0600001215935,0.000128172251868681,2.28719503485471E-5,0.25,5.36519116781857E-8,1.1362651827645E-5,6.47085550820902E-8,216.3953705,216.4570313,99.8070526123047,99.8070526123047,53.9956797369865,19.5815906225878,25.186911,0,0,0,40,4374,220.6093,99.8070526123047,,,,,,,,,,,,,0,,,,-0.0049,,,,,,216.4262009,,,,
,19870213.95,219.3295135,99.8070526123047,1.1600710922402E-5,3.20747808030026E-7,1,0.999253354069792,40.0298881530762,1.99366476888273,15.0600001215935,0.000132256751615006,1.74912713654246E-5,0.25,-4.68322788995705E-7,1.16338405213178E-5,-4.58658889060375E-7,219.3295135,219.3295135,99.8070526123047,99.8070526123047,53.8995394291211,19.581331241079,25.566563,0,0,0,40,4374,223.53015,99.8070526123047,,,,,,,,,,,,,0,,,,-0.0049,,,,,,219.3295135,,,,
,19870327.94,222.1367188,99.8070526123047,1.15163452417749E-5,3.53587578002999E-7,1,0.999253354069792,40.0298881530762,1.99381485191513,15.0499995797873,0.000130719346475315,2.06627085300237E-5,0.25,-1.73346294769963E-7,1.15478618281025E-5,-1.63081919407301E-7,222.1367188,222.1367188,99.8070526123047,99.8070526123047,54.0394509340634,19.5762829849159,25.946213,0,0,0,40,4374,226.39005,99.8070526123047,,,,,,,,,,,,,0,,,,-0.00245,,,,,,222.1367188,,,,
,19870470.625,225.7258453,99.8070526123047,1.12085321234704E-5,3.4493935649996E-7,1,0.999253354069792,40.0298881530762,1.98079514047808,14.8999998345971,0.000127492659691329,1.37801294536176E-5,0.25,-7.19881882821494E-7,1.12383379093405E-5,-7.11500870751904E-7,225.7258453,225.7258453,99.8070526123047,99.8070526123047,53.5915777925441,19.5790296781479,25.946213,0,0,0,40,4374,229.9586,99.8070526123047,,,,,,,,,,,,,0,,,,0.00245,,,,,,225.7258453,,,,
,19870585.22,228.5935974,99.8070526123047,1.12744079410702E-5,4.07326471974767E-7,1,0.999253354069792,40.0298881530762,1.98090720469707,14.8999998345971,0.000127051561829097,2.06884611500371E-5,0.25,-1.16964145799076E-7,1.13027248928081E-5,-1.07096934405957E-7,228.5935974,228.5935974,99.8070526123047,99.8070526123047,53.8995394291211,19.5828539362707,26.325863,0,0,0,40,4374,232.82415,99.8070526123047,,,,,,,,,,,,,0,,,,0.0049,,,,,,228.5935974,,,,
,19870699.34,231.43250275,99.8070526123047,1.0869332522592E-5,3.41848775040036E-7,1,0.999253354069792,40.0298881530762,1.98082037324487,14.8999998345971,0.000122973096991648,1.70406467200767E-5,0.25,-3.70613194000656E-7,1.08957982093454E-5,-3.61853736895852E-7,231.4030914,231.4619141,99.8070526123047,99.8070526123047,53.9401841121211,19.5791781502685,26.325863,0,0,0,40,4374,235.7005,99.8070526123047,,,,,,,,,,,,,0,,,,-0.00245,,,,,,231.43250275,,,,
,19870840.43,234.9236908,99.8070526123047,1.1373919851572E-5,2.96747423725712E-7,1,0.999253354069792,40.0298881530762,1.99362758584726,14.9100003764033,0.000128972645280288,2.07531433187526E-5,0.25,-1.38995609039754E-7,1.14000184999123E-5,-1.29394242207919E-7,234.9236908,234.9236908,99.8070526123047,99.8070526123047,53.8346642620249,19.5774169323739,25.946213,0,0,0,40,4374,239.2376,99.8070526123047,,,,,,,,,,,,,0,,,,0.00245,,,,,,234.9236908,,,,
,19870955.235,237.7861023,99.8070526123047,1.12768942531957E-5,3.96582649048991E-7,1,0.999253354069792,40.0298881530762,1.99331242731332,14.919999986887,0.000127998163681571,1.96616869684926E-5,0.25,-2.18047440323328E-7,1.13017165280914E-5,-2.08830652506323E-7,237.7861023,237.7861023,99.8070526123047,99.8070526123047,53.6970976426403,19.5858322110941,25.946213,0,0,0,40,4374,242.1241,99.8070526123047,,,,,,,,,,,,,0,,,,0,,,,,,237.7861023,,,,
,19871070.08,240.6874847,99.8070526123047,1.11552591885273E-5,3.68721250601459E-7,1,0.999253354069792,40.0298881530762,1.99362391673309,14.919999986887,0.00012590474328236,2.3595180199559E-5,0.25,1.50795739849266E-7,1.11783719211666E-5,1.60562972908809E-7,240.6874847,240.6874847,99.8070526123047,99.8070526123047,53.9956797369865,19.5782962234358,25.946213,0,0,0,40,4374,245.0028,99.8070526123047,,,,,,,,,,,,,0,,,,0,,,,,,240.6874847,,,,
,19871184.075,243.4884033,99.8070526123047,1.1145631030485E-5,4.16220289146028E-7,1,0.999253354069792,40.0298881530762,1.99312573319591,14.919999986887,0.000126039084751758,2.19219069507513E-5,0.25,5.34138862662889E-9,1.116775492753E-5,1.46662514784915E-8,243.4884033,243.4884033,99.8070526123047,99.8070526123047,54.2864455461404,19.5858885428771,25.566563,0,0,0,40,4374,247.8555,99.8070526123047,,,,,,,,,,,,,0,,,,0,,,,,,243.4884033,,,,
,19871326.735,247.0480804,99.8070526123047,1.10991785246761E-5,3.50114164608057E-7,1,0.999253354069792,40.0298881530762,1.99359042481005,14.8700000718236,0.000125370370333284,2.27303984764396E-5,0.25,8.48471630419057E-8,1.11197574682331E-5,9.4121982396917E-8,247.0480804,247.0480804,99.8070526123047,99.8070526123047,54.0980730730057,19.5789331063642,26.325863,0,0,0,40,4374,251.4314,99.8070526123047,,,,,,,,,,,,,0,,,,-0.0049,,,,,,247.0480804,,,,
,19871441.275,249.9369659,99.8070526123047,1.08387016855626E-5,3.43487120383498E-7,1,0.999253354069792,40.0298881530762,1.99362269344068,14.8600004613399,0.000122695807154791,2.05908485453318E-5,0.25,-5.88693959883706E-8,1.08578099657239E-5,-5.01908777269421E-8,249.9369659,249.9369659,99.8070526123047,99.8070526123047,53.8151235490442,19.5782178209719,26.325863,0,0,0,40,4374,254.3072,99.8070526123047,,,,,,,,,,,,,0,,,,0.00245,,,,,,249.9369659,,,,
,19871557.75,252.8479004,99.8070526123047,1.09550243597198E-5,3.33932451978765E-7,1,0.999253354069792,40.0298881530762,1.99402521079365,14.8600004613399,0.000124307396907614,1.91779259175383E-5,0.25,-2.04005830432712E-7,1.09733256710619E-5,-1.95588045524427E-7,252.8479004,252.8479004,99.8070526123047,99.8070526123047,54.180144067525,19.5724757615819,25.946213,0,0,0,40,4374,257.21905,99.8070526123047,,,,,,,,,,,,,0,,,,0,,,,,,252.8479004,,,,
,19871700.49,256.3949585,99.8070526123047,1.02716301404077E-5,3.78129476946146E-7,1,0.999253354069792,40.0298881530762,1.99368950247466,14.8200001567602,0.000116649797058842,1.7224894784999E-5,0.25,-2.57609189226009E-7,1.02875484591311E-5,-2.49929235345638E-7,256.3666382,256.4232788,99.8070526123047,99.8070526123047,54.0714977033519,19.5749769806809,26.325863,0,0,0,40,4374,260.7959,99.8070526123047,,,,,,,,,,,,,0,,,,0,,,,,,256.3949585,,,,
,19871815.765,259.2349243,99.8070526123047,1.02832156151535E-5,3.12106810070925E-7,1,0.999253354069792,40.0298881530762,1.99419185006829,14.8200001567602,0.00011641896631874,1.94309920823221E-5,0.25,-6.46494300845081E-8,1.02979620849113E-5,-5.67649239653808E-8,259.2349243,259.2349243,99.8070526123047,99.8070526123047,54.1910868667942,19.5644595678994,25.946213,0,0,0,40,4374,263.68095,99.8070526123047,,,,,,,,,,,,,0,,,,0,,,,,,259.2349243,,,,
,19871931.525,262.1087036,99.8070526123047,1.03585344780661E-5,3.29863800066997E-7,1,0.999253354069792,40.0298881530762,1.9936071306588,14.8200001567602,0.000117595077078893,1.74419086152357E-5,0.25,-2.52899941470206E-7,1.03724726530352E-5,-2.45305180138385E-7,262.1087036,262.1087036,99.8070526123047,99.8070526123047,53.933149455448,19.5877751377755,26.325863,0,0,0,40,4374,266.5778,99.8070526123047,,,,,,,,,,,,,0,,,,-0.0049,,,,,,262.1087036,,,,
,19872074.8,265.6841431,99.8070526123047,1.06997844674206E-5,3.49586376251063E-7,1,0.999253354069792,40.0298881530762,1.9808602724329,14.7799998521805,0.000120252735823453,2.05526865117042E-5,0.25,-2.53481349568651E-8,1.07126368681494E-5,-1.73184995737173E-8,265.6841431,265.6841431,99.8070526123047,99.8070526123047,53.8698375453903,19.5669747593289,26.325863,0,0,0,40,4374,270.1858,99.8070526123047,,,,,,,,,,,,,0,,,,0.0049,,,,,,265.6841431,,,,
,19872188.285,268.5247498,99.8070526123047,1.07314707560221E-5,4.12612482132243E-7,1,0.999253354069792,40.0298881530762,1.98122683853978,14.7799998521805,0.0001205895347787,2.07790259636486E-5,0.25,-1.07329217474174E-8,1.07432613031257E-5,-2.76195574366699E-9,268.5247498,268.5247498,99.8070526123047,99.8070526123047,54.0879119022557,19.5727013934328,26.705515,0,0,0,40,4374,273.02475,99.8070526123047,,,,,,,,,,,,,0,,,,0,,,,,,268.5247498,,,,
,19872300.4,271.3273926,99.8070526123047,1.09203053850355E-5,3.87253438298118E-7,1,0.999253354069792,40.0298881530762,1.9811610437764,14.7700002416968,0.000123014219885694,1.93018915628763E-5,0.25,-1.74616073168131E-7,1.09313292442741E-5,-1.66766547510135E-7,271.3273926,271.3273926,99.8070526123047,99.8070526123047,54.0480488477749,19.5741005880744,26.325863,0,0,0,40,4374,275.8308,99.8070526123047,,,,,,,,,,,,,0,,,,0.00245,,,,,,271.3273926,,,,
,19872414.985,274.1360168,99.8070526123047,1.03237561035691E-5,3.753842353201E-7,1,0.999253354069792,40.0298881530762,1.98091131639891,14.7799998521805,0.000117743630022055,9.73293595788268E-6,0.25,-9.22744923669262E-7,1.03336885270832E-5,-9.1608154519058E-7,274.1360168,274.1360168,99.8070526123047,99.8070526123047,53.9089189713519,19.5805957032838,26.325863,0,0,0,40,4374,278.70425,99.8070526123047,,,,,,,,,,,,,0,,,,0,,,,,,274.1360168,,,,
,19872559.325,277.7104797,99.8070526123047,1.0331571688115E-5,4.34808232065108E-7,1,0.999253354069792,40.0298881530762,1.99411041687036,14.6700004115701,0.000116840038710284,1.97666084707115E-5,0.25,-4.15075953897193E-8,1.03395486197622E-5,-3.41580262796071E-8,277.7104797,277.7104797,99.8070526123047,99.8070526123047,53.9933348514288,19.5577212414371,26.705515,0,0,0,40,4374,282.3177,99.8070526123047,,,,,,,,,,,,,0,,,,-0.0049,,,,,,277.7104797,,,,
,19872672.485,280.5237427,99.8070526123047,1.06099801699268E-5,4.55933150117356E-7,1,0.999253354069792,40.0298881530762,1.99391745635538,14.6700004115701,0.000120449404515639,1.75024989181668E-5,0.25,-2.89712440581666E-7,1.06172766026429E-5,-2.82416776298315E-7,280.5237427,280.5237427,99.8070526123047,99.8070526123047,53.9863001947557,19.5686032183977,26.325863,0,0,0,40,4374,285.1653,99.8070526123047,,,,,,,,,,,,,0,,,,-0.00245,,,,,,280.5237427,,,,
,19872785.28,283.3166199,99.8070526123047,1.04554978020152E-5,3.65953506687278E-7,1,0.999253354069792,40.0298881530762,1.99381029154203,14.6700004115701,0.000118329136735151,1.92562071181226E-5,0.25,-1.07386287187832E-7,1.04615148967207E-5,-1.00154366254703E-7,283.3166199,283.3166199,99.8070526123047,99.8070526123047,53.8714008024288,19.5689198678189,26.325863,0,0,0,40,4374,287.99795,99.8070526123047,,,,,,,,,,,,,0,,,,0,,,,,,283.3166199,,,,
,19872931.43,286.9328003,99.8070526123047,9.95379875301014E-6,4.26562770110771E-7,1,0.999253354069792,40.0298881530762,1.99431052970399,14.5699996501207,0.000113395606947298,1.41097786804964E-5,0.25,-4.76021896013372E-7,9.9584929413517E-6,-4.6939270146229E-7,286.9328003,286.9328003,99.8070526123047,99.8070526123047,53.9964613655057,19.556471167734,27.085165,0,0,0,40,4374,291.66765,99.8070526123047,,,,,,,,,,,,,0,,,,0,,,,,,286.9328003,,,,
,19873044.96,289.7607727,99.8070526123047,9.95667940932918E-6,3.71608563997851E-7,1,0.999253354069792,40.0298881530762,1.99440345964184,14.5699996501207,0.000113377945955293,1.43669438370845E-5,0.25,-4.53608195352399E-7,9.96034711296168E-6,-4.47001104350025E-7,289.7607727,289.7607727,99.8070526123047,99.8070526123047,54.0965098159673,19.5568965882523,26.705515,0,0,0,40,4374,294.5328,99.8070526123047,,,,,,,,,,,,,0,,,,0,,,,,,289.7607727,,,,
,19873159.115,292.602356,99.8070526123047,9.93343401893336E-6,3.91361336547155E-7,1,0.999253354069792,40.0298881530762,1.99480016994572,14.5699996501207,0.000112668801033325,1.69570538274552E-5,0.25,-2.2037973060026E-7,9.93592311735825E-6,-2.1376545446879E-7,292.602356,292.602356,99.8070526123047,99.8070526123047,54.156695211948,19.5527725788685,27.085165,0,0,0,40,4374,297.4081,99.8070526123047,,,,,,,,,,,,,0,,,,-0.00245,,,,,,292.602356,,,,
,19873272.06,295.3562317,99.8070526123047,1.02002184988216E-5,3.49151689751391E-7,1,0.999253354069792,40.0298881530762,1.99443985813664,14.5699996501207,0.000115796689125486,1.66385170584443E-5,0.25,-2.94320129341847E-7,1.02018129643219E-5,-2.87592984378491E-7,295.3562317,295.3562317,99.8070526123047,99.8070526123047,54.0574283900057,19.5543972855721,27.464817,0,0,0,40,4374,300.2588,99.8070526123047,,,,,,,,,,,,,0,,,,-0.00245,,,,,,295.3562317,,,,
,19873414.57,298.8955994,99.8070526123047,1.00285770411108E-5,3.67604146265705E-7,1,0.999253354069792,40.0298881530762,1.99441322960041,14.6000003442168,0.000113910658929784,1.59037932220215E-5,0.25,-3.29335709715869E-7,1.00288995252311E-5,-3.22779073030792E-7,298.8955994,298.8955994,99.8070526123047,99.8070526123047,54.0222551066403,19.5561009113998,26.705515,0,0,0,40,4374,303.8376,99.8070526123047,,,,,,,,,,,,,0,,,,-0.00245,,,,,,298.8955994,,,,
,19873528.885,301.7343445,99.8070526123047,9.76113143933814E-6,3.78366650791426E-7,1,0.999253354069792,40.0298881530762,1.99446728182988,14.6000003442168,0.000111158230392584,1.37827680433885E-5,0.25,-4.70632483233882E-7,9.76055110735699E-6,-4.64276033779227E-7,301.7343445,301.7343445,99.8070526123047,99.8070526123047,54.2239152646019,19.5564924103851,26.705515,0,0,0,40,4374,306.72245,99.8070526123047,,,,,,,,,,,,,0,,,,-0.0049,,,,,,301.7343445,,,,
,19873644.955,304.57724,99.8070526123047,9.84017448500793E-6,4.0917943196411E-7,1,0.999253354069792,40.0298881530762,1.99458582992519,14.6000003442168,0.000112565348647526,1.09381034364755E-5,0.25,-7.36096410707181E-7,9.83875649709731E-6,-7.29661370403982E-7,304.57724,304.57724,99.8070526123047,99.8070526123047,53.9667594817749,19.5542016254061,27.085165,0,0,0,40,4374,309.6451,99.8070526123047,,,,,,,,,,,,,0,,,,0,,,,,,304.57724,,,,
,19873785.95,308.0678711,99.8070526123047,9.51301349925805E-6,3.69326723678436E-7,1,0.999253354069792,40.0298881530762,1.98193578963097,14.5399998873472,0.000108570868949639,8.08028737885447E-6,0.25,-9.2794883429438E-7,9.51059194502538E-6,-9.21652375746941E-7,308.0678711,308.0678711,99.8070526123047,99.8070526123047,53.9464371402749,19.5547060818397,27.464817,0,0,0,40,4374,313.19825,99.8070526123047,,,,,,,,,,,,,0,,,,0,,,,,,308.0678711,,,,
,19873899.86,310.8905945,99.8070526123047,9.31988970920965E-6,4.57416593288793E-7,1,0.999253354069792,40.0298881530762,1.98215347352893,14.5399998873472,0.000105650998871454,1.20509226919306E-5,0.25,-5.40649874617637E-7,9.3163474472147E-6,-5.3460619511738E-7,310.8905945,310.8905945,99.8070526123047,99.8070526123047,54.0707160748326,19.5545901765076,26.705515,0,0,0,40,4374,316.07,99.8070526123047,,,,,,,,,,,,,0,,,,0,,,,,,310.8905945,,,,
,19874012.77,313.684845,99.8070526123047,9.61003360091372E-6,4.09707070899695E-7,1,0.999253354069792,40.0298881530762,1.98209837423203,14.5399998873472,0.000109152846048225,1.11170470782662E-5,0.25,-6.73929979564573E-7,9.60549838627497E-6,-6.67645672215095E-7,313.684845,313.684845,99.8070526123047,99.8070526123047,54.3380330284096,19.5550169419773,27.085165,0,0,0,40,4374,318.9294,99.8070526123047,,,,,,,,,,,,,0,,,,-0.00245,,,,,,313.684845,,,,
,19874126.43,316.4490509,99.8070526123047,9.43292001274367E-6,4.04058953067339E-7,1,0.999253354069792,40.0298881530762,1.98208618865119,14.5399998873472,0.000106226584283263,1.61268800390316E-5,0.25,-1.96609330644601E-7,9.42725874966921E-6,-1.90721413936701E-7,316.4147034,316.4833984,99.8070526123047,99.8070526123047,54.0496121048134,19.5572063872782,27.085165,0,0,0,40,4374,321.8031,99.8070526123047,,,,,,,,,,,,,0,,,,0.0049,,,,,,316.4490509,,,,
,19874268.535,319.9732361,99.8070526123047,9.56507778730635E-6,4.11364569113955E-7,1,0.999253354069792,40.0298881530762,1.98217138594317,14.4800003618002,0.000108598871079695,1.11955414973598E-5,0.25,-6.58826408942366E-7,9.55842552277743E-6,-6.52566675425549E-7,319.9732361,319.9732361,99.8070526123047,99.8070526123047,54.149660555275,19.5534226162224,27.844467,0,0,0,40,4374,325.3955,99.8070526123047,,,,,,,,,,,,,0,,,,0,,,,,,319.9732361,,,,
,19874381.565,322.7410889,99.8070526123047,9.40916448650388E-6,4.42858272074331E-7,1,0.999253354069792,40.0298881530762,1.9822770898287,14.4800003618002,0.000105268781187927,1.9990434562304E-5,0.25,1.52185568618024E-7,9.40122400238552E-6,1.57682608137892E-7,322.7410889,322.7410889,99.8070526123047,99.8070526123047,53.9456555117557,19.5538403037959,27.085165,0,0,0,40,4374,328.24565,99.8070526123047,,,,,,,,,,,,,0,,,,0,,,,,,322.7410889,,,,
,19874497.465,325.6081238,99.8070526123047,8.66661451698086E-6,4.03867798202166E-7,1,0.999253354069792,40.0298881530762,1.98220439877188,14.4800003618002,9.87718934461378E-5,7.87943901172283E-6,0.25,-7.98539172020182E-7,8.65898722893218E-6,-7.92664214283456E-7,325.6081238,325.6081238,99.8070526123047,99.8070526123047,54.0175653355249,19.5542355423971,27.085165,0,0,0,40,4374,331.1751,99.8070526123047,,,,,,,,,,,,,0,,,,0.0049,,,,,,325.6081238,,,,
,19874640.485,329.1310425,99.8070526123047,8.60770994579593E-6,3.76620030948204E-7,1,0.999253354069792,40.0298881530762,1.9822487903002,14.3799996003509,9.74782619144668E-5,1.13605979476428E-5,0.25,-4.77849859160969E-7,8.59888711924444E-6,-4.72311645139112E-7,329.1310425,329.1310425,99.8070526123047,99.8070526123047,53.9167352565442,19.5533903788366,27.464817,0,0,0,40,4374,334.7803,99.8070526123047,,,,,,,,,,,,,0,,,,0,,,,,,329.1310425,,,,
,19874755.3,331.9808197,99.8070526123047,8.75621772434875E-6,4.69874143267487E-7,1,0.999253354069792,40.0298881530762,1.98241069478623,14.3900001421571,9.91061781807698E-5,1.18551668519268E-5,0.25,-4.59406112793809E-7,8.74635794146909E-6,-4.53802903441872E-7,331.9500122,332.0116272,99.8070526123047,99.8070526123047,53.8971945435634,19.5529459486657,27.464817,0,0,0,40,4374,337.66275,99.8070526123047,,,,,,,,,,,,,0,,,,0,,,,,,331.9808197,,,,
,19874868.765,334.8155212,99.8070526123047,8.84365814857176E-6,3.54757233601224E-7,1,0.999253354069792,40.0298881530762,1.98243893434761,14.3799996003509,9.99596049794438E-5,1.27103396298253E-5,0.25,-3.98163982811397E-7,8.83279242978072E-6,-3.9258806368776E-7,334.8155212,334.8155212,99.8070526123047,99.8070526123047,53.9050108287557,19.5533909732442,27.085165,0,0,0,40,4374,340.5094,99.8070526123047,,,,,,,,,,,,,0,,,,-0.00245,,,,,,334.8155212,,,,
,19875010.36,338.3252869,99.8070526123047,8.72771551039568E-6,4.20153362868832E-7,1,0.999253354069792,40.0298881530762,1.98211086812275,14.3299996852875,9.89307032963526E-5,1.07548584853251E-5,0.25,-5.52118366564176E-7,8.71602540304764E-6,-5.46404160141382E-7,338.3252869,338.3252869,99.8070526123047,99.8070526123047,53.9495636543519,19.5513799618107,27.085165,0,0,0,40,4374,344.0804,99.8070526123047,,,,,,,,,,,,,0,,,,-0.0049,,,,,,338.3252869,,,,
,19875123.1,341.0862122,99.8070526123047,8.54029024966695E-6,5.11038813386457E-7,1,0.999253354069792,40.0298881530762,1.98231914232242,14.3299996852875,9.61376034287564E-5,1.43881197958874E-5,0.25,-1.95590642858962E-7,8.52784668304064E-6,-1.90495646150987E-7,341.0862122,341.0862122,99.8070526123047,99.8070526123047,53.9003210576403,19.5512604685182,27.844467,0,0,0,40,4374,346.9079,99.8070526123047,,,,,,,,,,,,,0,,,,0,,,,,,341.0862122,,,,
,19875235.955,343.8771973,99.8070526123047,8.25482025412866E-6,4.17444250683348E-7,1,0.999253354069792,40.0298881530762,1.98222346958371,14.3299996852875,9.25381794003091E-5,1.60579366358077E-5,0.25,3.00576497920532E-9,8.24189873197961E-6,7.6096826430728E-9,343.8771973,343.8771973,99.8070526123047,99.8070526123047,53.8346642620249,19.5532755214331,27.464817,0,0,0,40,4374,349.7363,99.8070526123047,,,,,,,,,,,,,0,,,,0,,,,,,343.8771973,,,,
,19875347.77,346.6640015,99.8070526123047,8.40113818288398E-6,4.31314699605604E-7,1,0.999253354069792,40.0298881530762,1.98232350961972,14.3299996852875,9.5690261469281E-5,7.58507780583426E-6,0.25,-7.78030036931891E-7,8.38762559092341E-6,-7.72085578573347E-7,346.6640015,346.6640015,99.8070526123047,99.8070526123047,53.7439953537942,19.5522851309271,27.844467,0,0,0,40,4374,352.54875,99.8070526123047,,,,,,,,,,,,,0,,,,0,,,,,,346.6640015,,,,
,19875482.59,348.4468689,99.8070526123047,8.47663120822297E-6,4.31204989877735E-7,1,0.999253354069792,40.0298881530762,1.98249297816741,14.299999922514,9.51692492444052E-5,1.5640291440444E-5,0.25,-7.25968629954281E-8,8.46208905477166E-6,-6.77625136465599E-8,348.4468689,348.4468689,99.8070526123047,99.8070526123047,53.9018843146788,19.5506444236317,27.464817,0,0,0,40,4374,351.4129,99.8070526123047,,,,,,,,,,,,,0,,,,-0.0049,,,,,,348.4468689,,,,
,19875586,348.7765198,99.8070526123047,8.38624936962305E-6,4.80541276773727E-7,1,0.999253354069792,40.0298881530762,1.98250902899525,14.299999922514,9.4883912966156E-5,1.12590516429918E-5,0.25,-4.47753874860283E-7,8.37197758807044E-6,-4.4232072555279E-7,348.7765198,348.7765198,99.8070526123047,99.8070526123047,53.7385239541595,19.5518580133783,27.844467,0,0,0,40,4374,351.5141,99.8070526123047,,,,,,,,,,,,,0,,,,-0.00245,,,,,,348.7765198,,,,
,19875690.43,349.2929993,99.8070526123047,7.68894204019325E-6,4.63838110449327E-7,1,0.999253354069792,40.0298881530762,1.98256229070231,14.299999922514,8.6378998111578E-5,1.38813688532255E-5,0.25,-9.31048737229603E-8,7.67554673344558E-6,-8.86777439440907E-8,349.2929993,349.2929993,99.8070526123047,99.8070526123047,53.9480003973134,19.5521156722471,27.464817,0,0,0,40,4374,352.0383,99.8070526123047,,,,,,,,,,,,,0,,,,0.0049,,,,,,349.2929993,,,,
,19875797.845,349.7023621,99.8070526123047,8.72660225683882E-6,5.37093042437852E-7,1,0.999253354069792,40.0298881530762,1.98258484286065,14.299999922514,9.79717532549106E-5,1.61255750224715E-5,0.25,-7.2584080459723E-8,8.71126024370243E-6,-6.761801768834E-8,349.7023621,349.7023621,99.8070526123047,99.8070526123047,53.8385724046211,19.5516758234065,27.844467,0,0,0,40,4373,352.15815,99.8070526123047,,,,,,,,,,,,,0,,,,0,,,,,,349.7023621,,,,
,19875867.125,349.8675842,99.8070526123047,8.13239234305268E-6,4.70770449352072E-7,1,0.999253354069792,40.0298881530762,1.98249126426557,14.299999922514,9.1243717670796E-5,1.53290589720412E-5,0.25,-4.06782027863008E-8,8.11803466131744E-6,-3.60974531430367E-8,349.8675842,349.8675842,99.8070526123047,99.8070526123047,53.9769206525249,19.552296272254,28.224119,0,0,0,40,4369,352.1452,99.8070526123047,,,,,,,,,,,,,0,,,,0,,,,,,349.8675842,,,,