File: data/monolayers/magneticStructure/ML_Ac_CoFe_C/PPMS/data/DD205_4_HYST_100OE_5K.DAT
[Header]
; VSM Data File (default extension .dat)
; Copyright (c) 2003-2013, Quantum Design, Inc. All rights reserved.
TITLE,
FILEOPENTIME,32330373.30,01/10/2019,12:41 pm
BYAPP,VSM,2.0,2.0
INFO,PPMS VSM Option Release 1.4.10 Build 1,APPNAME
INFO,Quantum Design Linear Motor Servo Controller,MOTOR_MODULE_NAME
INFO,3101-100 M1,MOTOR_HW_VERSION
INFO,MMC1014,MOTOR_SERIAL_NUMBER
INFO,SRV No X-over 01.03.11,MOTOR_SOFTWARE_VERSION
INFO,Quantum Design VSM Detection Module,VSM_MODULE_NAME
INFO,3101-150 F0,VSM_HW_VERSION
INFO,VSM707,VSM_SERIAL_NUMBER
INFO,VSM No X-over 01.02.05 May 20 2008 13:51:47,VSM_SOFTWARE_VERSION
INFO,704,PREAMP_SERIAL_NUMBER
INFO,822,COIL_SERIAL_NUMBER
INFO,0,MOMENT_UNITS
INFO,DD205_4,SAMPLE_MATERIAL
INFO,Monolayer,SAMPLE_COMMENT
INFO,29.55,SAMPLE_MASS
INFO,,SAMPLE_VOLUME
INFO,,SAMPLE_MOLECULAR_WEIGHT
INFO,,SAMPLE_SIZE
INFO,,SAMPLE_SHAPE
DATATYPE,COMMENT,1
DATATYPE,TIME,2
STARTUPAXIS,X,2
STARTUPAXIS,Y1,5
[Data]
Comment,Time Stamp (sec),Temperature (K),Magnetic Field (Oe),Moment (emu),M. Std. Err. (emu),Transport Action,Averaging Time (sec),Frequency (Hz),Peak Amplitude (mm),Center Position (mm),Coil Signal' (mV),Coil Signal" (mV),Range (mV),M. Quad. Signal (emu),M. Raw' (emu),M. Raw" (emu),Min. Temperature (K),Max. Temperature (K),Min. Field (Oe),Max. Field (Oe),Mass (grams),Motor Lag (deg),Pressure (Torr),VSM Status (code),Motor Status (code),Measure Status (code),Measure Count,PPMS Status (code),System Temp. (K),System Field (Oe),Sample Position (deg),Bridge 1 Resistance (ohms),Bridge 1 Excitation (에),Bridge 2 Resistance (ohms),Bridge 2 Excitation (에),Bridge 3 Resistance (ohms),Bridge 3 Excitation (에),Bridge 4 Resistance (ohms),Bridge 4 Excitation (에),Signal 1 Vin (V),Signal 2 Vin (V),Digital Inputs (code),Drive 1 Iout (mA),Drive 1 Ipower (W),Drive 2 Iout (mA),Drive 2 Ipower (W),Pressure (),Map 20 (),Map 21 (),Map 22 (),Map 23 (),Map 24 (),Map 25 (),Map 26 (),Map 27 (),Map 28 (),Map 29 ()
,32330388.63,4.9990859,0.350146800279617,,,2,,,,21.2699999809265,,,,,,,4.9990859,4.9990859,0.350146800279617,0.350146800279617,,,8.102614,,,,-99999999,4369,5.0144,0.350146800279617,,,,,,,,,,,,,,,,,,,,,,,4.9990859,,,,
,32330533.1,4.9995236,4496.56323242188,-1.25834932051793E-5,3.81802993407292E-7,1,0.999253354069792,40.0298881530762,1.98517323208146,21.2600007653236,-0.000140176622520096,-2.74202158433771E-5,0.25,-2.15943048220007E-7,-1.25132206889834E-5,-2.78831157700005E-7,4.9995236,4.9995236,4494.078125,4499.04833984375,56.1279623374482,20.4837358297839,8.102614,0,0,0,40,4449,5.013,4496.56323242188,,,,,,,,,,,,,0,,,,0,,,,,,4.9995236,,,,
,32330626.275,4.9999461,9152.37255859375,-2.63593672789037E-5,3.73554291812223E-7,1,0.999253354069792,40.0298881530762,1.98517536282539,21.2600007653236,-0.000294190334165096,-5.49052473007026E-5,0.25,-2.14995152374452E-7,-2.62222467779777E-5,-3.57052780997673E-7,4.9990997,5.0007925,9122.3349609375,9182.41015625,56.5359724244868,20.487095564845,8.482265,0,0,0,40,4449,5.0124,9152.37255859375,,,,,,,,,,,,,0,,,,0,,,,,,4.9999461,,,,
,32330718.805,5.0000153,13777.69921875,-4.0239667894727E-5,4.88917117461298E-7,1,0.999253354069792,40.0298881530762,1.98519415417906,21.2600007653236,-0.000449040670597995,-8.52111878141571E-5,0.25,-4.36282537254539E-7,-4.00452064781582E-5,-6.66393064507276E-7,5.0000153,5.0000153,13750.1953125,13805.203125,56.4750053999867,20.4920166612603,8.102614,0,0,0,40,4449,5.01135,13777.69921875,,,,,,,,,,,,,0,,,,0.00245,,,,,,5.0000153,,,,
,32330813.81,5.0001879,18527.75390625,-5.12875587726966E-5,4.67323583800306E-7,1,0.999253354069792,40.0298881530762,1.98494746763392,21.2600007653236,-0.000573295821675148,-0.000104238096828386,0.25,-1.455263680468E-7,-5.10644388827058E-5,-4.57766655371341E-7,5.0001879,5.0001879,18522.57421875,18532.93359375,57.1729996676599,20.4973099432539,7.722963,0,0,0,40,4449,5.01035,18527.75390625,,,,,,,,,,,,,0,,,,0,,,,,,5.0001879,,,,
,32330910.905,5.0035667,23380.193359375,-5.97115521579516E-5,5.11131226708151E-7,1,0.999253354069792,40.0298881530762,1.98493924296245,21.2600007653236,-0.000665037674646959,-0.000136704795452046,0.25,-1.51759979570645E-6,-5.9471552590604E-5,-1.8943328725235E-6,5.0035667,5.0035667,23375.296875,23385.08984375,56.8689461736791,20.5039653737917,8.102614,0,0,0,40,4449,5.0119,23380.193359375,,,,,,,,,,,,,0,,,,0.00245,,,,,,5.0035667,,,,
,32331006.665,5.008553,28168.10546875,-6.55282401302196E-5,4.52617890253648E-7,1,0.999253354069792,40.0298881530762,1.98476492015956,21.2600007653236,-0.000730021009305898,-0.000150611134606988,0.25,-1.69539441888344E-6,-6.52963928545511E-5,-2.12697461722076E-6,5.008553,5.008553,28163.19140625,28173.01953125,56.4539014299675,20.502917209801,8.482265,0,0,0,40,4449,5.0166,28168.10546875,,,,,,,,,,,,,0,,,,0,,,,,,5.008553,,,,
,32331098.075,4.9992905,32733.4404296875,-7.5774588214858E-5,5.86348264369762E-7,1,0.999253354069792,40.0298881530762,1.98500624502463,21.2600007653236,-0.000846423201273004,-0.000164519903536794,0.25,-1.07411126101268E-6,-7.55485218867733E-5,-1.59306614209818E-6,4.9992905,4.9992905,32725.80859375,32741.072265625,56.8900501436983,20.5038813510742,8.102614,0,0,0,40,4449,5.0085,32733.4404296875,,,,,,,,,,,,,0,,,,-0.0049,,,,,,4.9992905,,,,
,32331190.78,4.9991717,37368.3671875,-8.7059520081289E-5,5.99469057784591E-7,1,0.999253354069792,40.0298881530762,1.98503058231234,21.2600007653236,-0.000974124582849189,-0.000182691556005511,0.25,-6.4509564244697E-7,-8.68465398857629E-5,-1.25913105064568E-6,4.9991717,4.9991717,37363.234375,37373.5,57.2777378892368,20.5057695439384,8.482265,0,0,0,40,4449,5.01025,37368.3671875,,,,,,,,,,,,,0,,,,0.0049,,,,,,4.9991717,,,,
,32331283.145,4.998497,41983.626953125,-0.000101411986062857,7.0202837622566E-7,1,0.999253354069792,40.0298881530762,1.98492298028616,21.2600007653236,-0.00113592905871828,-0.000208929174629951,0.25,-3.8280738058884E-7,-0.000101215981512641,-1.11358230244169E-6,4.998497,4.998497,41981.3203125,41985.93359375,57.0573186468137,20.5037808936207,8.482265,0,0,0,40,4449,5.011,41983.626953125,,,,,,,,,,,,,0,,,,0.00245,,,,,,4.998497,,,,
,32331376.88,4.9972882,46671.609375,-0.000117426018068158,5.7846898256218E-7,1,0.999253354069792,40.0298881530762,1.98492267720305,21.2600007653236,-0.00131451693591155,-0.000249994852222042,0.25,-1.14041182586425E-6,-0.000117251406056412,-1.99841841521104E-6,4.9972882,4.9972882,46669.04296875,46674.17578125,57.1753445532176,20.502784902449,8.861917,0,0,0,40,4449,5.0112,46671.609375,,,,,,,,,,,,,0,,,,0,,,,,,4.9972882,,,,
,32331469.745,4.997195,51311.716796875,-0.000134630036211506,7.45767983152577E-7,1,0.999253354069792,40.0298881530762,1.98493778169798,21.2600007653236,-0.00150841830091388,-0.000283505202469812,0.25,-1.00825340798531E-6,-0.000134495748415665,-2.00250462673687E-6,4.9970388,4.9973512,51281.91796875,51341.515625,57.1049979864868,20.5016813978295,8.482265,0,0,0,40,4449,5.0145,51311.716796875,,,,,,,,,,,,,0,,,,0,,,,,,4.997195,,,,
,32331562.87,4.9972408,55966.828125,-0.000150881220927475,8.65151102098107E-7,1,0.999253354069792,40.0298881530762,1.98500158278466,21.2600007653236,-0.00169346173368787,-0.000306064474522995,0.25,-7.14878972998636E-8,-0.0001508081060858,-1.19282891063672E-6,4.9971166,4.997365,55934.16015625,55999.49609375,57.2144259791791,20.506213017186,8.102614,0,0,0,40,4449,5.01615,55966.828125,,,,,,,,,,,,,0,,,,-0.00245,,,,,,4.9972408,,,,
,32331657.025,4.9973607,60672.044921875,-0.000167748263676091,7.64189319256032E-7,1,0.999253354069792,40.0298881530762,1.98474123881569,21.2600007653236,-0.00188136832328506,-0.000351569804345524,0.25,-1.07383257655222E-6,-0.000167734847781835,-2.32244581236194E-6,4.9973607,4.9973607,60667.06640625,60677.0234375,57.0182372208522,20.5092921757593,8.482265,0,0,0,40,4449,5.0197,60672.044921875,,,,,,,,,,,,,0,,,,0.0049,,,,,,4.9973607,,,,
,32331749.005,4.9963169,65267.525390625,-0.000183449918674554,7.57763384003439E-7,1,0.999253354069792,40.0298881530762,1.98469182660761,21.2600007653236,-0.00205574466198382,-0.000398716289068542,0.25,-2.43149707992142E-6,-0.000183502907016796,-3.7954261480361E-6,4.9963169,4.9963169,65264.76953125,65270.28125,57.4098331089868,20.5048103789,8.482265,0,0,0,40,4449,5.0222,65267.525390625,,,,,,,,,,,,,0,,,,0.00245,,,,,,4.9963169,,,,
,32331842.74,4.9968019,69955.5859375,-0.000200674683150014,9.66671289744857E-7,1,0.999253354069792,40.0298881530762,1.9846392061625,21.2600007653236,-0.00225071550209702,-0.00043027512665375,0.25,-2.12974009493752E-6,-0.000200818513029495,-3.61512054370519E-6,4.9968019,4.9968019,69953.21875,69957.953125,57.3347967711407,20.5063779280633,8.482265,0,0,0,40,4449,5.0254,69955.5859375,,,,,,,,,,,,,0,,,,0.00245,,,,,,4.9968019,,,,
,32331935.815,4.997345,74605.640625,-0.000218357470257772,6.79710312479299E-7,1,0.999253354069792,40.0298881530762,1.98471800837409,21.2600007653236,-0.00244809528023344,-0.000479368415507773,0.25,-3.306829220144E-6,-0.000218590625113209,-4.91315600592301E-6,4.997345,4.997345,74570.9765625,74640.3046875,57.1042163579676,20.5083048067563,8.482265,0,0,0,40,4449,5.0266,74605.640625,,,,,,,,,,,,,0,,,,0.00245,,,,,,4.997345,,,,
,32332028.515,4.9965148,79238.78515625,-0.000235485998095903,6.12596079783663E-7,1,0.999253354069792,40.0298881530762,1.98463864128234,21.2600007653236,-0.00264359772751948,-0.000502622097365552,0.25,-2.2926358671672E-6,-0.000235832057018694,-4.0076626708939E-6,4.9965148,4.9965148,79228.734375,79248.8359375,57.3035316303714,20.5117762462809,8.482265,0,0,0,40,4449,5.02925,79238.78515625,,,,,,,,,,,,,0,,,,0,,,,,,4.9965148,,,,
,32332122.11,4.9962454,83919.86328125,-0.000253137944447983,9.22044439089134E-7,1,0.999253354069792,40.0298881530762,1.98453421591535,21.2600007653236,-0.0028398276438713,-0.000555833630288559,0.25,-3.85342944916178E-6,-0.000253587278606266,-5.6790223072878E-6,4.9962454,4.9962454,83917.4453125,83922.28125,57.0557553897753,20.5101904248088,8.861917,0,0,0,40,4449,5.0342,83919.86328125,,,,,,,,,,,,,0,,,,0,,,,,,4.9962454,,,,
,32332208.505,4.9966331,88238.19921875,-0.000268111468033718,8.48974930546244E-7,1,0.999253354069792,40.0298881530762,1.98432238120236,21.2600007653236,-0.00300923651588674,-0.000584184543305675,0.25,-3.6927859012315E-6,-0.000268670668864871,-5.60313789582271E-6,4.9966331,4.9966331,88205.7109375,88270.6875,56.9119357422368,20.51368400655,8.861917,0,0,0,40,4449,5.0363,88238.19921875,,,,,,,,,,,,,0,,,,0,,,,,,4.9966331,,,,
,32332309.35,4.9986877,87561.078125,-0.000265499900936431,6.99840960237339E-7,1,0.999253354069792,40.0298881530762,1.98438177403317,21.2600007653236,-0.00297829728621344,-0.000587247130235897,0.25,-4.43174238767133E-6,-0.000266035949152537,-6.32878544172595E-6,4.9986877,4.9986877,87528.875,87593.28125,56.9603967104291,20.5119123200312,8.861917,0,0,0,40,4449,5.0367,87561.078125,,,,,,,,,,,,,0,,,,0.0049,,,,,,4.9986877,,,,
,32332397.79,5.0016069,83137.37890625,-0.00024993774702136,6.36058193116282E-7,1,0.999253354069792,40.0298881530762,1.98440226370145,21.2600007653236,-0.00280396524831875,-0.000546661288232452,0.25,-3.61596580660286E-6,-0.000250368690357448,-5.42166991116992E-6,5.0016069,5.0016069,83129.90625,83144.8515625,57.6216544376984,20.5140337728772,8.861917,0,0,0,40,4449,5.035,83137.37890625,,,,,,,,,,,,,0,,,,0,,,,,,5.0016069,,,,
,32332493,5.001503,78378.3125,-0.000232002336171812,7.35890402574397E-7,1,0.999253354069792,40.0298881530762,1.98430052010875,21.2600007653236,-0.00260164489175097,-0.00050757062159204,0.25,-3.3668390331547E-6,-0.000232319967195216,-5.06127318353148E-6,5.001503,5.001503,78375.71875,78380.90625,56.8306463762368,20.5158276092564,8.102614,0,0,0,40,4449,5.0365,78378.3125,,,,,,,,,,,,,0,,,,-0.0049,,,,,,5.001503,,,,
,32332588.08,5.0021286,73624.6171875,-0.000214442945243241,6.52503740198524E-7,1,0.999253354069792,40.0298881530762,1.9843177387087,21.2600007653236,-0.00240406372680351,-0.000467819229142646,0.25,-2.99305499392166E-6,-0.000214656764166741,-4.57283864499726E-6,5.0021286,5.0021286,73621.953125,73627.28125,57.4207759082561,20.5146419218787,8.102614,0,0,0,40,4449,5.0339,73624.6171875,,,,,,,,,,,,,0,,,,0,,,,,,5.0021286,,,,
,32332680.485,5.00288605,69006.52734375,-0.000197252849702954,8.07516403208571E-7,1,0.999253354069792,40.0298881530762,1.98435095095925,21.2600007653236,-0.00221227491977434,-0.000420494689649544,0.25,-1.8823022833406E-6,-0.000197379816584678,-3.34380786872442E-6,5.0026579,5.0031142,68974.1328125,69038.921875,57.058100275333,20.5164091509814,8.102614,0,0,0,40,4449,5.03,69006.52734375,,,,,,,,,,,,,0,,,,-0.00245,,,,,,5.00288605,,,,
,32332774.305,5.0037608,64318.630859375,-0.000180738776572916,6.01657719210725E-7,1,0.999253354069792,40.0298881530762,1.9843439303949,21.2600007653236,-0.00202306640796276,-0.000402632048623626,0.25,-3.27682394029094E-6,-0.000180769042237056,-4.6215116932951E-6,5.0037608,5.0037608,64316.1796875,64321.08203125,56.9900985941599,20.5195501123575,8.861917,0,0,0,40,4449,5.0258,64318.630859375,,,,,,,,,,,,,0,,,,-0.0049,,,,,,5.0037608,,,,
,32332866.875,5.0030522,59690.435546875,-0.000163847339274584,8.95057583341611E-7,1,0.999253354069792,40.0298881530762,1.98435216556897,21.2600007653236,-0.00183461693520766,-0.000357098764925139,0.25,-2.27818716690081E-6,-0.000163809998246867,-3.49749302221264E-6,5.0030522,5.0030522,59687.8359375,59693.03515625,56.8650380310829,20.5166698247666,8.482265,0,0,0,40,4449,5.0249,59690.435546875,,,,,,,,,,,,,0,,,,-0.00245,,,,,,5.0030522,,,,
,32332963.385,5.0036392,54864.45703125,-0.000144630476440805,6.96316550146632E-7,1,0.999253354069792,40.0298881530762,1.98438367179164,21.2600007653236,-0.00161740799083512,-0.00032233267058254,0.25,-2.65995933438411E-6,-0.000144525567545656,-3.7323317868956E-6,5.0036392,5.0036392,54829.3203125,54899.59375,57.1573670972753,20.5160170236319,8.482265,0,0,0,40,4449,5.0214,54864.45703125,,,,,,,,,,,,,0,,,,0,,,,,,5.0036392,,,,
,32333058.395,5.00361465,50117.0859375,-0.000127644723478893,5.60461969489455E-7,1,0.999253354069792,40.0298881530762,1.98437242169258,21.2600007653236,-0.00142551305838577,-0.00029132517052595,0.25,-2.97609799664124E-6,-0.000127487102491307,-3.91454844025591E-6,5.0033827,5.0038466,50087.1875,50146.984375,57.5302039009484,20.5189004292005,8.482265,0,0,0,40,4449,5.0201,50117.0859375,,,,,,,,,,,,,0,,,,0.00245,,,,,,5.00361465,,,,
,32333153.085,5.0024977,45384.60546875,-0.000111052133070803,8.59992985988249E-7,1,0.999253354069792,40.0298881530762,1.98428764859713,21.2600007653236,-0.00123919524896138,-0.000255330371486586,0.25,-2.77712748197217E-6,-0.000110859811025404,-3.5829149729113E-6,5.0024977,5.0024977,45379.50390625,45389.70703125,57.0385595623522,20.5200885224246,8.482265,0,0,0,40,4449,5.0182,45384.60546875,,,,,,,,,,,,,0,,,,-0.00245,,,,,,5.0024977,,,,
,32333248.385,5.0014133,40621.59765625,-9.46046934006174E-5,7.07160449050244E-7,1,0.999253354069792,40.0298881530762,1.98439631846178,21.2600007653236,-0.00105598228711425,-0.000213029139262059,0.25,-1.98516007873714E-6,-9.43965829424987E-5,-2.65988510018665E-6,5.0014133,5.0014133,40616.5390625,40626.65625,56.9174071418714,20.5190648363143,8.861917,0,0,0,40,4449,5.0158,40621.59765625,,,,,,,,,,,,,0,,,,0,,,,,,5.0014133,,,,
,32333343.2,5.0024991,35881.361328125,-7.79964830238144E-5,6.47894792850751E-7,1,0.999253354069792,40.0298881530762,1.98424922391875,21.2600007653236,-0.000869433253617484,-0.000179251386759674,0.25,-1.98101818906246E-6,-7.77835439712406E-5,-2.52325395821344E-6,5.001997,5.0030012,35878.88671875,35883.8359375,57.2089545795445,20.5213859038657,8.482265,0,0,0,40,4449,5.0121,35881.361328125,,,,,,,,,,,,,0,,,,-0.0049,,,,,,5.0024991,,,,
,32333437.595,5.0033016,31163.71484375,-6.0954573670052E-5,6.94553043676361E-7,1,0.999253354069792,40.0298881530762,1.98436135753689,21.2600007653236,-0.000677939148705468,-0.000146844788477842,0.25,-2.16942282480988E-6,-6.07537746725365E-5,-2.57847677375793E-6,5.0033016,5.0033016,31161.279296875,31166.150390625,57.220679007333,20.5231821862644,8.102614,0,0,0,40,4449,5.011,31163.71484375,,,,,,,,,,,,,0,,,,-0.00245,,,,,,5.0033016,,,,
,32333531.165,5.001811,26486.0439453125,-4.48208295399894E-5,4.31145410384822E-7,1,0.999253354069792,40.0298881530762,1.98436566270033,21.2600007653236,-0.000498933352307617,-0.000104167657435781,0.25,-1.26980558580144E-6,-4.46538131892691E-5,-1.56042163459543E-6,5.001811,5.001811,26483.787109375,26488.30078125,57.484869446833,20.5256936608744,8.482265,0,0,0,40,4449,5.0109,26486.0439453125,,,,,,,,,,,,,0,,,,0.0049,,,,,,5.001811,,,,
,32333625.71,5.0010138,21760.8720703125,-2.85945184376679E-5,4.81821616750498E-7,1,0.999253354069792,40.0298881530762,1.98427038829028,21.2600007653236,-0.0003168662455317,-7.35384387286048E-5,0.25,-1.45430516166555E-6,-2.84704418594253E-5,-1.62885623948025E-6,5.0010138,5.0010138,21755.849609375,21765.89453125,57.1917587521214,20.5245992031826,8.102614,0,0,0,40,4449,5.0078,21760.8720703125,,,,,,,,,,,,,0,,,,0,,,,,,5.0010138,,,,
,32333717.705,5.0014462,17163.392578125,-1.28555519603859E-5,4.52892245841857E-7,1,0.999253354069792,40.0298881530762,1.98432747502363,21.2600007653236,-0.000141677927827843,-3.70832565235773E-5,0.25,-1.0186367309489E-6,-1.27920705850956E-5,-1.09132930992624E-6,5.0014462,5.0014462,17163.392578125,17163.392578125,57.2152076076984,20.5224439818741,8.102614,0,0,0,40,4449,5.0084,17163.392578125,,,,,,,,,,,,,0,,,,-0.0049,,,,,,5.0014462,,,,
,32333811.41,5.0016689,12480.9389648438,2.94700260458532E-6,3.26445902641637E-7,1,0.999253354069792,40.0298881530762,1.98425086503499,21.2600007653236,3.45643427859819E-5,-3.27188376650897E-6,0.25,-8.18707617696231E-7,2.93725986829874E-6,-7.97981753849803E-7,5.0016689,5.0016689,12476.0322265625,12485.845703125,57.0823307594291,20.52335842888,8.482265,0,0,0,40,4449,5.0068,12480.9389648438,,,,,,,,,,,,,0,,,,-0.0049,,,,,,5.0016689,,,,
,32333903.37,4.9998059,7885.44091796875,1.81042152951096E-5,3.67935345225767E-7,1,0.999253354069792,40.0298881530762,1.98425952269799,21.2600007653236,0.000203677471925366,2.79780460361232E-5,0.25,-7.20006271010085E-7,1.80129062811946E-5,-6.19587765320098E-7,4.9998059,4.9998059,7883.15869140625,7887.72314453125,57.1354814987368,20.5247920092569,8.482265,0,0,0,40,4449,5.00775,7885.44091796875,,,,,,,,,,,,,0,,,,-0.0049,,,,,,4.9998059,,,,
,32333994.695,5.0009346,3320.130859375,3.22295998727541E-5,4.10221531128258E-7,1,0.999253354069792,40.0298881530762,1.98427452311239,21.2600007653236,0.000360590166873086,6.03879816780894E-5,0.25,-3.22379138551584E-7,3.20516273571738E-5,-1.59086561114157E-7,5.0009346,5.0009346,3315.30981445313,3324.95190429687,57.0002597649099,20.5222279502944,8.102614,0,0,0,40,4449,5.00745,3320.130859375,,,,,,,,,,,,,0,,,,0,,,,,,5.0009346,,,,
,32334085.17,4.9996672,-1204.03393554688,4.44730633322733E-5,3.26571954580449E-7,1,0.999253354069792,40.0298881530762,1.98428917720059,21.2600007653236,0.000496685128236344,8.79920773617508E-5,0.25,-2.04229857368434E-8,4.42200771667743E-5,1.96602136047694E-7,4.9996672,4.9996672,-1206.33288574219,-1201.73498535156,57.1550222117176,20.5271674030122,8.102614,0,0,0,40,4449,5.0074,-1204.03393554688,,,,,,,,,,,,,0,,,,-0.00245,,,,,,4.9996672,,,,
,32334177.795,5.0002208,-5827.89892578125,5.74641409377782E-5,3.38646752390017E-7,1,0.999253354069792,40.0298881530762,1.98417376434548,21.2600007653236,0.000640744193795944,0.000120337365502883,0.25,5.48081473959095E-7,5.71506261628877E-5,8.43189358705875E-7,5.0002208,5.0002208,-5832.95849609375,-5822.83935546875,57.0995265868522,20.5287313724386,8.102614,0,0,0,40,4449,5.0072,-5827.89892578125,,,,,,,,,,,,,0,,,,0,,,,,,5.0002208,,,,
,32334270.095,5.0001736,-10444.1459960938,6.96349329079547E-5,4.39513894862453E-7,1,0.999253354069792,40.0298881530762,1.98419385712779,21.2600007653236,0.000776742367336954,0.00014583198967261,0.25,6.36439238622854E-7,6.92794947997093E-5,1.0180842628028E-6,5.0001736,5.0001736,-10446.5537109375,-10441.73828125,57.0909286731407,20.5266192930318,8.102614,0,0,0,40,4449,5.0073,-10444.1459960938,,,,,,,,,,,,,0,,,,0,,,,,,5.0001736,,,,
,32334361.405,4.9998176,-15006.73046875,7.92309173045683E-5,3.48032255792031E-7,1,0.999253354069792,40.0298881530762,1.98422088326387,21.2600007653236,0.000885240787737704,0.000159838319753163,0.25,1.47032627628603E-7,7.88608157591412E-5,6.10475629535295E-7,4.9996753,4.9999599,-15039.1943359375,-14974.2666015625,57.5442732142945,20.5243349316808,8.482265,0,0,0,40,4449,5.006,-15006.73046875,,,,,,,,,,,,,0,,,,0,,,,,,4.9998176,,,,
,32334454.9,4.9997375,-19679.017578125,8.30372629315424E-5,4.85042182104968E-7,1,0.999253354069792,40.0298881530762,1.98426559117521,21.2600007653236,0.000926809819759916,0.000175352436818628,0.25,8.21591115356142E-7,8.26815730355796E-5,1.33097969181874E-6,4.9994698,5.0000052,-19706.62109375,-19651.4140625,57.0393411908714,20.5267424282947,7.722963,0,0,0,40,4449,5.0073,-19679.017578125,,,,,,,,,,,,,0,,,,-0.0049,,,,,,4.9997375,,,,
,32334549.49,5.0003495,-24409.224609375,8.11518936788738E-5,5.65441659652862E-7,1,0.999253354069792,40.0298881530762,1.9842102615894,21.2600007653236,0.00090573049448199,0.00017389325854253,0.25,9.98114972798376E-7,8.08409250882757E-5,1.51923177636781E-6,5.0003495,5.0003495,-24419.40625,-24399.04296875,57.1307917276214,20.5288660363415,8.102614,0,0,0,40,4449,5.00715,-24409.224609375,,,,,,,,,,,,,0,,,,0,,,,,,5.0003495,,,,
,32334642.535,4.99941445,-29056.76171875,8.00824586700377E-5,5.46289094992481E-7,1,0.999253354069792,40.0298881530762,1.98426591424018,21.2600007653236,0.000896380705851533,0.000159806969974768,0.25,-9.66620993582829E-8,7.98210180474903E-5,4.41669803206936E-7,4.9990306,4.9997983,-29086.8203125,-29026.703125,57.3770047111791,20.5286520656864,8.482265,0,0,0,40,4449,5.0073,-29056.76171875,,,,,,,,,,,,,0,,,,-0.00245,,,,,,4.99941445,,,,
,32334737.495,4.9986739,-33803.890625,8.54110487134835E-5,5.24733586044501E-7,1,0.999253354069792,40.0298881530762,1.98418787694878,21.2600007653236,0.00095430650380421,0.000182558854818167,0.25,9.53985248651135E-7,8.51676424734939E-5,1.54365484477028E-6,4.9986739,4.9986739,-33809.08203125,-33798.69921875,57.3840393678522,20.5300453972591,7.722963,0,0,0,40,4449,5.00675,-33803.890625,,,,,,,,,,,,,0,,,,0.00245,,,,,,4.9986739,,,,
,32334831.695,4.9975896,-38513.701171875,9.50515731610593E-5,5.74574772224805E-7,1,0.999253354069792,40.0298881530762,1.9841634081643,21.2600007653236,0.00106123366571936,0.000210525774794451,0.25,1.69367757044602E-6,9.4823533034738E-5,2.3656103285884E-6,4.9975896,4.9975896,-38516.2578125,-38511.14453125,57.3973270526791,20.5316332961427,8.102614,0,0,0,40,4449,5.0105,-38513.701171875,,,,,,,,,,,,,0,,,,0,,,,,,4.9975896,,,,
,32334924.67,4.9968209,-43156.158203125,0.000107858920386665,6.60396491270336E-7,1,0.999253354069792,40.0298881530762,1.98419793702154,21.2600007653236,0.0012051142729413,0.00023746434862915,0.25,1.76957759622837E-6,0.000107653869814784,2.54769832488405E-6,4.9968209,4.9968209,-43163.86328125,-43148.453125,57.2222422643714,20.5328331240944,7.722963,0,0,0,40,4449,5.0109,-43156.158203125,,,,,,,,,,,,,0,,,,0.0049,,,,,,4.9968209,,,,
,32335018.605,4.99778105,-47853.900390625,0.000122775840363024,7.14200230300769E-7,1,0.999253354069792,40.0298881530762,1.98415561048108,21.2600007653236,0.00137115410133453,0.000277479725692059,0.25,2.63125236623142E-6,0.000122597649736712,3.52926043951553E-6,4.9974809,4.9980812,-47886.453125,-47821.34765625,57.3824761108138,20.5345260111489,8.102614,0,0,0,40,4449,5.0129,-47853.900390625,,,,,,,,,,,,,0,,,,0,,,,,,4.99778105,,,,
,32335113.765,4.9969716,-52608.3359375,0.000138474085413566,7.94524391992061E-7,1,0.999253354069792,40.0298881530762,1.98414402257852,21.2600007653236,0.00154947339978953,0.000300534617754158,0.25,1.83831336865158E-6,0.000138348013263721,2.86240639082396E-6,4.9969716,4.9969716,-52608.3359375,-52608.3359375,57.4348452216022,20.5330045320077,8.482265,0,0,0,40,4449,5.0154,-52608.3359375,,,,,,,,,,,,,0,,,,0,,,,,,4.9969716,,,,
,32335208.02,4.9978371,-57320.783203125,0.00015425859766389,5.92079625161557E-7,1,0.999253354069792,40.0298881530762,1.98417118865314,21.2600007653236,0.00172720265283622,0.000333364989476661,0.25,1.90208843252292E-6,0.00015419044962512,3.04884498777861E-6,4.9978371,4.9978371,-57325.62890625,-57315.9375,57.5739750980253,20.5329496508112,8.102614,0,0,0,40,4449,5.0178,-57320.783203125,,,,,,,,,,,,,0,,,,0.0049,,,,,,4.9978371,,,,
,32335301.62,4.9968393,-61995.568359375,0.000172466336996528,7.21761926163643E-7,1,0.999253354069792,40.0298881530762,1.98404081886161,21.2600007653236,0.00193152823776768,0.000374366508712989,0.25,2.26124461784065E-6,0.000172465114655587,3.54494141426488E-6,4.9962225,4.9974561,-62028.08984375,-61963.046875,57.2652318329291,20.5354901666521,8.482265,0,0,0,40,4449,5.0188,-61995.568359375,,,,,,,,,,,,,0,,,,0,,,,,,4.9968393,,,,
,32335394.35,4.9970174,-66633.31640625,0.000189348713252538,7.14280122432819E-7,1,0.999253354069792,40.0298881530762,1.9841417825794,21.2600007653236,0.00212369619540803,0.00039952287323995,0.25,1.44701154628282E-6,0.000189434219897384,2.8529709678427E-6,4.996706,4.9973288,-66665.734375,-66600.8984375,57.3770047111791,20.5335580923375,8.482265,0,0,0,40,4449,5.0215,-66633.31640625,,,,,,,,,,,,,0,,,,0,,,,,,4.9970174,,,,
,32335487.795,4.997457,-71302.875,0.000206135998286378,9.67489428016158E-7,1,0.999253354069792,40.0298881530762,1.98411274284408,21.2600007653236,0.00231194953562377,0.000440228501641038,0.25,2.03996203985905E-6,0.000206308224854385,3.56297247119787E-6,4.997457,4.997457,-71307.8515625,-71297.8984375,57.2081729510253,20.5366972157999,8.102614,0,0,0,40,4449,5.02355,-71302.875,,,,,,,,,,,,,0,,,,0,,,,,,4.997457,,,,
,32335580.555,4.9963145,-75937.85546875,0.000223889797430772,8.22108905859513E-7,1,0.999253354069792,40.0298881530762,1.98413585936906,21.2600007653236,0.00250995264959115,0.000489933213585628,0.25,3.2619906496408E-6,0.000224153609817187,4.90499960526714E-6,4.9963145,4.9963145,-75940.265625,-75935.4453125,57.7467150007753,20.5395092974736,8.102614,0,0,0,40,4449,5.0286,-75937.85546875,,,,,,,,,,,,,0,,,,0,,,,,,4.9963145,,,,
,32335676.5,4.9957066,-80732.8203125,0.000241082849610087,9.95098995003947E-7,1,0.999253354069792,40.0298881530762,1.9841841908303,21.2600007653236,0.00270436178238615,0.000524389314254788,0.25,3.2318092863215E-6,0.000241457813668012,4.98312386547184E-6,4.9950891,4.9963241,-80742.9375,-80722.703125,57.5145713305638,20.5357184804686,8.102614,0,0,0,40,4449,5.0309,-80732.8203125,,,,,,,,,,,,,0,,,,0,,,,,,4.9957066,,,,
,32335772.69,4.9961963,-85539.9609375,0.000258913431125851,7.27156197373038E-7,1,0.999253354069792,40.0298881530762,1.98402454065136,21.2600007653236,0.00290624561809043,0.000557290016416554,0.25,2.95847182631137E-6,0.00025940974738491,4.8159117852988E-6,4.9961963,4.9961963,-85544.703125,-85535.21875,57.505191788333,20.5374933414425,8.482265,0,0,0,40,4449,5.03455,-85539.9609375,,,,,,,,,,,,,0,,,,0,,,,,,4.9961963,,,,
,32335859.93,4.99557065,-89899.54296875,0.000274371798021744,6.9759736599559E-7,1,0.999253354069792,40.0298881530762,1.98411056267577,21.2600007653236,0.0030825495667006,0.000581025494451324,0.25,2.29557876914753E-6,0.000274984965328555,4.2376771376776E-6,4.995151,4.9959903,-89902,-89897.0859375,57.3816944822945,20.5396102164522,7.722963,0,0,0,40,4449,5.0381,-89899.54296875,,,,,,,,,,,,,0,,,,0,,,,,,4.99557065,,,,
,32335962.735,4.9989519,-85780.0234375,0.000259797532874389,7.22815770652599E-7,1,0.999253354069792,40.0298881530762,1.9840652424259,21.2600007653236,0.00291574405560236,0.000562165894388949,0.25,3.23235729461739E-6,0.00026029801582643,5.09546071529334E-6,4.9989519,4.9989519,-85784.890625,-85775.15625,57.7334273159484,20.5385308298614,8.482265,0,0,0,40,4449,5.036,-85780.0234375,,,,,,,,,,,,,0,,,,-0.0049,,,,,,4.9989519,,,,
,32336053.475,5.0014782,-81247.78125,0.000242016655229885,8.6642184259927E-7,1,0.999253354069792,40.0298881530762,1.9841069275045,21.2600007653236,0.00271459562012853,0.000527774864578076,0.25,3.3670114140904E-6,0.000242401444738951,5.12322255966684E-6,5.0014782,5.0014782,-81252.7265625,-81242.8359375,57.515352959083,20.5427834923252,8.482265,0,0,0,40,4449,5.0362,-81247.78125,,,,,,,,,,,,,0,,,,0.00245,,,,,,5.0014782,,,,
,32336149.125,5.0015445,-76467.55078125,0.000224349534090816,8.27382583293225E-7,1,0.999253354069792,40.0298881530762,1.98407176872499,21.2600007653236,0.00251793714502225,0.000475379890041599,0.25,1.88578960768471E-6,0.000224633377961069,3.52871815807071E-6,5.0015445,5.0015445,-76470.2578125,-76464.84375,57.2495992625445,20.5410059972018,7.722963,0,0,0,40,4449,5.0337,-76467.55078125,,,,,,,,,,,,,0,,,,0.0049,,,,,,5.0015445,,,,
,32336243.745,5.0039954,-71737.65625,0.000207651826443627,8.95564640690038E-7,1,0.999253354069792,40.0298881530762,1.98410579158803,21.2600007653236,0.00233130049281424,0.000430861902488063,0.25,9.33004394279159E-7,0.000207841119583109,2.46521573315083E-6,5.0039954,5.0039954,-71742.546875,-71732.765625,57.281646031833,20.5382024144152,8.102614,0,0,0,40,4449,5.0317,-71737.65625,,,,,,,,,,,,,0,,,,-0.0049,,,,,,5.0039954,,,,
,32336339.83,5.0031877,-66936.02734375,0.000190352211795125,6.16229899593298E-7,1,0.999253354069792,40.0298881530762,1.98398006900444,21.2600007653236,0.00213435061273617,0.000404344600292579,0.25,1.69775469937926E-6,0.000190441429697826,3.11093233078522E-6,5.0031877,5.0031877,-66941.390625,-66930.6640625,57.1518956976407,20.5393053231554,8.102614,0,0,0,40,4449,5.0305,-66936.02734375,,,,,,,,,,,,,0,,,,-0.00245,,,,,,5.0031877,,,,
,32336431.425,5.0039825,-62355.67578125,0.000172012523958858,7.21724413485194E-7,1,0.999253354069792,40.0298881530762,1.98400171409646,21.2600007653236,0.00192798285687522,0.000365012269002981,0.25,1.5094880087934E-6,0.000172022557406822,2.78965572350663E-6,5.0039825,5.0039825,-62383.7421875,-62327.609375,57.3895107674868,20.5388248106551,8.102614,0,0,0,40,4449,5.027,-62355.67578125,,,,,,,,,,,,,0,,,,0.00245,,,,,,5.0039825,,,,
,32336527.375,5.0025182,-57560.501953125,0.000154901741976652,6.88974894540225E-7,1,0.999253354069792,40.0298881530762,1.98396117147909,21.2600007653236,0.0017339043502118,0.000336748488416453,0.25,2.08991450921818E-6,0.000154835538705883,3.24156735817087E-6,5.0025182,5.0025182,-57565.3828125,-57555.62109375,57.200356665833,20.5385355522552,8.482265,0,0,0,40,4449,5.0228,-57560.501953125,,,,,,,,,,,,,0,,,,0,,,,,,5.0025182,,,,
,32336620.51,5.0033956,-52908.263671875,0.000137873385748808,6.6896965037126E-7,1,0.999253354069792,40.0298881530762,1.98392191007403,21.2600007653236,0.00154424879790507,0.000290242033789323,0.25,1.0305566045376E-6,0.000137757903240882,2.05129346049393E-6,5.0033956,5.0033956,-52938.4765625,-52878.05078125,57.4864327038715,20.5405725002373,8.102614,0,0,0,40,4449,5.0215,-52908.263671875,,,,,,,,,,,,,0,,,,0,,,,,,5.0033956,,,,
,32336714.41,5.00325655,-48216.15234375,0.000120845478807253,6.23309110887548E-7,1,0.999253354069792,40.0298881530762,1.98395155860274,21.2600007653236,0.00135180385686743,0.000260387586645936,0.25,1.45517565902758E-6,0.000120682907016827,2.34132631497968E-6,5.0028963,5.0036168,-48246.6171875,-48185.6875,57.4199942797368,20.5398748395891,8.102614,0,0,0,40,4449,5.0193,-48216.15234375,,,,,,,,,,,,,0,,,,0,,,,,,5.00325655,,,,
,32336808.485,5.0038443,-43512.794921875,0.000104573440357413,7.29614410205241E-7,1,0.999253354069792,40.0298881530762,1.98391563383747,21.2600007653236,0.00116886908605104,0.000226993925424456,0.25,1.42791889766133E-6,0.000104380618408123,2.18381876136443E-6,5.0038443,5.0038443,-43517.73828125,-43507.8515625,57.3488660844868,20.5403242358269,8.102614,0,0,0,40,4449,5.0174,-43512.794921875,,,,,,,,,,,,,0,,,,0,,,,,,5.0038443,,,,
,32336901.205,5.0028362,-38878.529296875,8.74293984364734E-5,6.11870538237715E-7,1,0.999253354069792,40.0298881530762,1.98394583785223,21.2600007653236,0.000976181861433251,0.000193003345095834,0.25,1.50080934924443E-6,8.72234147387927E-5,2.12008643633551E-6,5.0028362,5.0028362,-38880.7890625,-38876.26953125,57.5528711280061,20.5378834583101,8.482265,0,0,0,40,4449,5.0145,-38878.529296875,,,,,,,,,,,,,0,,,,-0.0049,,,,,,5.0028362,,,,
,32336997.785,5.0032964,-34051.484375,7.13642305726378E-5,5.33291058994493E-7,1,0.999253354069792,40.0298881530762,1.98384211696633,21.2600007653236,0.000797650733427045,0.000150274117733248,0.25,5.96315478934079E-7,7.11641149481683E-5,1.09030611261248E-6,5.0032964,5.0032964,-34054.171875,-34048.796875,57.4129596230638,20.5405057921153,8.102614,0,0,0,40,4449,5.0122,-34051.484375,,,,,,,,,,,,,0,,,,0.0049,,,,,,5.0032964,,,,
,32337090.19,5.0020337,-29434.193359375,5.48411260513975E-5,4.41638756798315E-7,1,0.999253354069792,40.0298881530762,1.98392220171127,21.2600007653236,0.000611442117738763,0.000122398368512824,0.25,1.09237521300286E-6,5.46564512283274E-5,1.45830627746817E-6,5.0020337,5.0020337,-29436.646484375,-29431.740234375,57.5888260398907,20.5379553692407,8.102614,0,0,0,40,4449,5.0112,-29434.193359375,,,,,,,,,,,,,0,,,,0,,,,,,5.0020337,,,,
,32337182.835,5.0021329,-24804.19140625,3.89902999651455E-5,5.89937775851056E-7,1,0.999253354069792,40.0298881530762,1.98394502610103,21.2600007653236,0.000434122239301215,8.9161670576321E-5,0.25,9.81162020517916E-7,3.88391920307075E-5,1.2305816229865E-6,5.0021329,5.0021329,-24839.279296875,-24769.103515625,57.268358347006,20.5357011212534,8.102614,0,0,0,40,4449,5.00855,-24804.19140625,,,,,,,,,,,,,0,,,,0,,,,,,5.0021329,,,,
,32337275.82,5.00140975,-20156.7001953125,2.29422189006686E-5,5.52480842607137E-7,1,0.999253354069792,40.0298881530762,1.98386906628607,21.2600007653236,0.000255470578196207,5.15641815644249E-5,0.25,5.05672446180947E-7,2.28432735031348E-5,6.45967529065746E-7,5.0013795,5.00144,-20186.619140625,-20126.78125,57.3918556530445,20.5365284182107,8.482265,0,0,0,40,4449,5.00895,-20156.7001953125,,,,,,,,,,,,,0,,,,-0.00245,,,,,,5.00140975,,,,
,32337368.475,5.00140475,-15526.9580078125,7.49105230547559E-6,4.54054854443018E-7,1,0.999253354069792,40.0298881530762,1.98397805652642,21.2600007653236,8.40619547501818E-5,1.30358674348662E-5,0.25,-1.720715856461E-7,7.45750948287659E-6,-1.2712098284123E-7,5.0013604,5.0014491,-15559.357421875,-15494.55859375,57.2425646058714,20.5382866877513,8.102614,0,0,0,40,4449,5.0081,-15526.9580078125,,,,,,,,,,,,,0,,,,-0.00245,,,,,,5.00140475,,,,
,32337462.295,5.0015607,-10836.9135742187,-8.34373710341044E-6,5.21685879379744E-7,1,0.999253354069792,40.0298881530762,1.98389381715562,21.2600007653236,-9.30456253761277E-5,-1.75508542977237E-5,0.25,-8.30942409056795E-8,-8.30137739786126E-6,-1.29033222367912E-7,5.0015607,5.0015607,-10842.0029296875,-10831.82421875,56.8931766577752,20.5354334392007,7.722963,0,0,0,40,4449,5.007,-10836.9135742187,,,,,,,,,,,,,0,,,,0,,,,,,5.0015607,,,,
,32337554.35,4.999166,-6235.86962890625,-2.35131970638049E-5,4.11125425772785E-7,1,0.999253354069792,40.0298881530762,1.98391650079046,21.2600007653236,-0.000262106521075678,-4.95076508513183E-5,0.25,-2.47980240018897E-7,-2.33854625061641E-5,-3.69307415943476E-7,4.999166,4.999166,-6243.61572265625,-6228.12353515625,57.0526288756983,20.5368387510987,8.102614,0,0,0,40,4449,5.008,-6235.86962890625,,,,,,,,,,,,,0,,,,-0.00245,,,,,,4.999166,,,,
,32337646.595,4.999517,-1622.08563232422,-3.71388375351985E-5,3.52955866750354E-7,1,0.999253354069792,40.0298881530762,1.98388450216494,21.2600007653236,-0.000414086178829648,-7.69401049899705E-5,0.25,-2.92987558262636E-7,-3.6926843735611E-5,-4.73371775506832E-7,4.999517,4.999517,-1624.60021972656,-1619.57104492187,57.1440794124484,20.5350195091641,8.102614,0,0,0,40,4449,5.0082,-1622.08563232422,,,,,,,,,,,,,0,,,,0,,,,,,4.999517,,,,
,32337737.97,5.0010147,2938.23095703125,-5.03963121837028E-5,2.68388202483902E-7,1,0.999253354069792,40.0298881530762,1.98386499683078,21.2600007653236,-0.000557335833885639,-0.00013031166744203,0.25,-2.71287288704819E-6,-5.01008058385372E-5,-2.94893214881142E-6,5.0010147,5.0010147,2938.23095703125,2938.23095703125,57.4661103623715,20.5355669216471,7.722963,0,0,0,40,4449,5.0054,2938.23095703125,,,,,,,,,,,,,0,,,,0,,,,,,5.0010147,,,,
,32337830.135,5.0011506,7548.06689453125,-6.22546802380233E-5,4.16099904775642E-7,1,0.999253354069792,40.0298881530762,1.98395549712238,21.2600007653236,-0.00069380311088033,-0.000132456261603166,0.25,-7.725513467294E-7,-6.1921792145339E-5,-1.09921773382476E-6,5.0011506,5.0011506,7542.93603515625,7553.19775390625,56.8673829166406,20.5335640396683,8.482265,0,0,0,40,4449,5.0059,7548.06689453125,,,,,,,,,,,,,0,,,,0,,,,,,5.0011506,,,,
,32337924.58,5.000248,12268.392578125,-7.5510648024861E-5,3.61288977516352E-7,1,0.999253354069792,40.0298881530762,1.98385843709595,21.2600007653236,-0.000844287099824686,-0.000146864244980985,0.25,3.28839604176342E-7,-7.514242151821E-5,-1.00225487353473E-7,5.000248,5.000248,12265.9541015625,12270.8310546875,56.9705578811791,20.5335790581318,8.102614,0,0,0,40,4449,5.0061,12268.392578125,,,,,,,,,,,,,0,,,,0.0049,,,,,,5.000248,,,,
,32338016.56,4.9989386,16863.7666015625,-8.00440203952441E-5,2.72765696129663E-7,1,0.999253354069792,40.0298881530762,1.98382473777308,21.2600007653236,-0.000887842132838851,-0.000197645499329221,0.25,-3.3745451653747E-6,-7.96644212718059E-5,-3.83866245515556E-6,4.9989386,4.9989386,16858.615234375,16868.91796875,57.2355299491984,20.538557720069,8.102614,0,0,0,40,4449,5.0061,16863.7666015625,,,,,,,,,,,,,0,,,,-0.0049,,,,,,4.9989386,,,,
,32338110.865,4.9992986,21578.7685546875,-8.19427856110578E-5,5.91813236253854E-7,1,0.999253354069792,40.0298881530762,1.98393716003952,21.2600007653236,-0.000913636938580536,-0.000178533967406984,0.25,-1.29169917615052E-6,-8.16039012950944E-5,-1.80251126515226E-6,4.9992986,4.9992986,21576.515625,21581.021484375,56.9166255133522,20.5348983784997,7.722963,0,0,0,40,4449,5.0059,21578.7685546875,,,,,,,,,,,,,0,,,,0.00245,,,,,,4.9992986,,,,
,32338201.68,4.9990554,26119.0322265625,-7.92648860918232E-5,6.09486514793834E-7,1,0.999253354069792,40.0298881530762,1.98391715058671,21.2600007653236,-0.000882610564231877,-0.000181502280879004,0.25,-2.00853050362007E-6,-7.89681259749625E-5,-2.52165252959515E-6,4.9990554,4.9990554,26089.134765625,26148.9296875,57.2120810936214,20.5361626125277,7.722963,0,0,0,40,4449,5.00695,26119.0322265625,,,,,,,,,,,,,0,,,,0.00245,,,,,,4.9990554,,,,
,32338294.86,4.9981761,30774.6689453125,-8.08667426970253E-5,4.93016137601692E-7,1,0.999253354069792,40.0298881530762,1.98388348678666,21.2600007653236,-0.000902997120233004,-0.00017339683733458,0.25,-9.70335575649959E-7,-8.06100622533394E-5,-1.51733620968936E-6,4.9981761,4.9981761,30772.185546875,30777.15234375,57.3996719382368,20.5337143313002,8.102614,0,0,0,40,4449,5.0071,30774.6689453125,,,,,,,,,,,,,0,,,,0.0049,,,,,,4.9981761,,,,
,32338387.88,4.9989777,35422.59765625,-8.70377515061508E-5,7.73617557667401E-7,1,0.999253354069792,40.0298881530762,1.9839248365473,21.2600007653236,-0.000972138502773549,-0.000188198626116673,0.25,-1.15905085216916E-6,-8.68032880162843E-5,-1.76525135620313E-6,4.9989777,4.9989777,35419.796875,35425.3984375,57.0213637349291,20.5375206152715,8.482265,0,0,0,40,4449,5.0096,35422.59765625,,,,,,,,,,,,,0,,,,-0.00245,,,,,,4.9989777,,,,
,32338479.335,4.998281,39995.177734375,-9.81818973348384E-5,6.19282745541643E-7,1,0.999253354069792,40.0298881530762,1.98392569913094,21.2600007653236,-0.00109645403125019,-0.000216221273363408,0.25,-1.6336375925834E-6,-9.79625049982703E-5,-2.33281263468477E-6,4.998281,4.998281,39987.79296875,40002.5625,57.1933220091599,20.5313055973713,7.722963,0,0,0,40,4449,5.0102,39995.177734375,,,,,,,,,,,,,0,,,,-0.0049,,,,,,4.998281,,,,
,32338572.435,4.997386,44650.767578125,-0.000110707161879531,7.66586554460459E-7,1,0.999253354069792,40.0298881530762,1.98389280194991,21.2600007653236,-0.00123758499808491,-0.000240208905249218,0.25,-1.49765387491708E-6,-0.000110516267247616,-2.30102710382994E-6,4.997386,4.997386,44645.9609375,44655.57421875,57.2355299491984,20.535168689303,8.102614,0,0,0,40,4449,5.01265,44650.767578125,,,,,,,,,,,,,0,,,,0,,,,,,4.997386,,,,
,32338665.92,4.9978724,49321.181640625,-0.000126045801970428,7.05171508679808E-7,1,0.999253354069792,40.0298881530762,1.98383431215079,21.2600007653236,-0.00140960312845543,-0.000274119591334477,0.25,-1.73971541543073E-6,-0.000125888818092887,-2.66611054560855E-6,4.9978724,4.9978724,49293.7265625,49348.63671875,57.3863842534099,20.533161717484,7.722963,0,0,0,40,4449,5.014,49321.181640625,,,,,,,,,,,,,0,,,,0.00245,,,,,,4.9978724,,,,
,32338759.585,4.997458,54003.67578125,-0.00014220064427416,7.42127796449995E-7,1,0.999253354069792,40.0298881530762,1.98381118367113,21.2600007653236,-0.00159031626903722,-0.000313173641691105,0.25,-2.29249776721661E-6,-0.000142087856144653,-3.34593456095388E-6,4.9969893,4.9979267,53971.08203125,54036.26953125,56.9322580837368,20.5323402010709,8.102614,0,0,0,40,4449,5.01545,54003.67578125,,,,,,,,,,,,,0,,,,-0.00245,,,,,,4.997458,,,,
,32338854.165,4.99706385,58731.49609375,-0.000159329114991792,9.56010973371304E-7,1,0.999253354069792,40.0298881530762,1.98378957241877,21.2600007653236,-0.00178255072979261,-0.000351731211075063,0.25,-2.62586525924823E-6,-0.000159275292597145,-3.81105989576527E-6,4.9969072,4.9972205,58699.171875,58763.8203125,57.1894138665637,20.5359546088278,8.102614,0,0,0,40,4449,5.0177,58731.49609375,,,,,,,,,,,,,0,,,,0.00245,,,,,,4.99706385,,,,
,32338946.54,4.9970386,63347.08203125,-0.000175408068951478,8.46162896858805E-7,1,0.999253354069792,40.0298881530762,1.98380881141604,21.2600007653236,-0.00196359989724118,-0.000385738037596645,0.25,-2.7443518218217E-6,-0.000175425242095249,-4.04968237022254E-6,4.9964318,4.9976454,63312.04296875,63382.12109375,57.1722180391407,20.5366527457744,8.102614,0,0,0,40,4449,5.02,63347.08203125,,,,,,,,,,,,,0,,,,0,,,,,,4.9970386,,,,
,32339040.65,4.9962854,68049.9296875,-0.000192862695348082,8.5726920733907E-7,1,0.999253354069792,40.0298881530762,1.98377642945603,21.2600007653236,-0.00215970023883987,-0.000425198812920978,0.25,-3.10402199304834E-6,-0.0001929615658673,-4.53523572829531E-6,4.9962854,4.9962854,68044.546875,68055.3125,57.4090514804676,20.5365214621985,8.482265,0,0,0,40,4449,5.0238,68049.9296875,,,,,,,,,,,,,0,,,,-0.0049,,,,,,4.9962854,,,,
,32339133.92,4.996944,72712.4609375,-0.000209691392389256,1.00464464508384E-6,1,0.999253354069792,40.0298881530762,1.98374376204929,21.2600007653236,-0.00235029451603267,-0.000455495724966635,0.25,-2.76425476948114E-6,-0.000209886018369907,-4.31104848987561E-6,4.996944,4.996944,72712.4609375,72712.4609375,57.5098815594484,20.5369374211963,8.102614,0,0,0,40,4449,5.0257,72712.4609375,,,,,,,,,,,,,0,,,,0,,,,,,4.996944,,,,
,32339228.555,4.9970791,77443.60546875,-0.000225980309434009,8.75961117170104E-7,1,0.999253354069792,40.0298881530762,1.98377615141601,21.2600007653236,-0.0025319537236542,-0.000501669235942773,0.25,-3.93737345850917E-6,-0.00022626857283254,-5.59187521307477E-6,4.9964952,4.997663,77411.078125,77476.1328125,57.2066096939868,20.534743128491,7.722963,0,0,0,40,4449,5.0311,77443.60546875,,,,,,,,,,,,,0,,,,0,,,,,,4.9970791,,,,
,32339325.91,4.9968519,82309.375,-0.000248468824125845,8.36927133826992E-7,1,0.999253354069792,40.0298881530762,1.98370280921086,21.2600007653236,-0.00278691596395964,-0.000540256850398419,0.25,-3.32606250060621E-6,-0.000248884220167339,-5.12432117617759E-6,4.9968519,4.9968519,82304.4140625,82314.3359375,56.9932251082368,20.5318065556519,8.102614,0,0,0,40,4449,5.03245,82309.375,,,,,,,,,,,,,0,,,,0.0049,,,,,,4.9968519,,,,
,32339415.21,4.9955072,86775.3828125,-0.000261821148637274,9.49309951447528E-7,1,0.999253354069792,40.0298881530762,1.98378851712209,21.2600007653236,-0.00294452328100897,-0.000531726416116797,0.25,-1.70631314570063E-7,-0.000262365589711897,-2.03669784080041E-6,4.9955072,4.9955072,86742.8828125,86807.8828125,57.5325487865061,20.5333997492514,8.482265,0,0,0,40,4449,5.03595,86775.3828125,,,,,,,,,,,,,0,,,,0.00245,,,,,,4.9955072,,,,
,32339517.505,4.9968195,88925.05859375,-0.000270404716601255,1.05370029508293E-6,1,0.999253354069792,40.0298881530762,1.98380007588842,21.2600007653236,-0.00303308373762619,-0.000596111029307683,0.25,-4.35521111540631E-6,-0.000270976718132386,-6.27949280780965E-6,4.9968195,4.9968195,88922.703125,88927.4140625,57.1206305568714,20.5350468223012,8.102614,0,0,0,40,4449,5.0391,88925.05859375,,,,,,,,,,,,,0,,,,0.00245,,,,,,4.9968195,,,,
,32339605.18,4.9989634,84544.21484375,-0.000252893133750054,9.89588058089228E-7,1,0.999253354069792,40.0298881530762,1.98369533963958,21.2600007653236,-0.00284292859855847,-0.000516935881323561,0.25,-4.59389599595072E-7,-0.000253377598795971,-2.27376594906362E-6,4.9989634,4.9989634,84514.4375,84573.9921875,57.5833546402561,20.5347055884199,7.722963,0,0,0,40,4449,5.0382,84544.21484375,,,,,,,,,,,,,0,,,,0.00245,,,,,,4.9989634,,,,
,32339696.54,5.0018249,79975.25390625,-0.000235497498582495,8.5262262776259E-7,1,0.999253354069792,40.0298881530762,1.98362727524286,21.2600007653236,-0.00263794590136976,-0.000528204247756249,0.25,-4.58867256689474E-6,-0.000235840022194192,-6.3046287276688E-6,5.0018249,5.0018249,79970.453125,79980.0546875,57.3371416566984,20.5373981437092,8.482265,0,0,0,40,4449,5.0348,79975.25390625,,,,,,,,,,,,,0,,,,-0.00245,,,,,,5.0018249,,,,
,32339791,5.0021,75254.12109375,-0.000218094122958543,9.14458724839399E-7,1,0.999253354069792,40.0298881530762,1.98368342863518,21.2600007653236,-0.00244656732465196,-0.00046461211528785,0.25,-2.06216147473295E-6,-0.000218347425857954,-3.66323366549319E-6,5.0021,5.0021,75251.671875,75256.5703125,57.2292769210445,20.5372225630319,8.102614,0,0,0,40,4449,5.0331,75254.12109375,,,,,,,,,,,,,0,,,,0,,,,,,5.0021,,,,
,32339885.3,5.0025268,70540.93359375,-0.000202793902345446,8.21227939831163E-7,1,0.999253354069792,40.0298881530762,1.98362232034869,21.2600007653236,-0.00226735338736958,-0.00046864701864855,0.25,-5.18221379268588E-6,-0.000202926908189885,-6.68474191482873E-6,5.0025268,5.0025268,70533.1328125,70548.734375,57.2495992625445,20.5363486675061,7.722963,0,0,0,40,4449,5.032,70540.93359375,,,,,,,,,,,,,0,,,,0,,,,,,5.0025268,,,,
,32339977.73,5.0023613,65920.26953125,-0.000185343471337634,7.48054704809494E-7,1,0.999253354069792,40.0298881530762,1.98363952539658,21.2600007653236,-0.00207440800776935,-0.000411663986538702,0.25,-3.26009892274342E-6,-0.000185401805442874,-4.63790593656955E-6,5.0023613,5.0023613,65914.984375,65925.5546875,57.3254172289099,20.5393633028076,8.102614,0,0,0,40,4449,5.0304,65920.26953125,,,,,,,,,,,,,0,,,,-0.0049,,,,,,5.0023613,,,,
,32340071.015,5.003808,61259.359375,-0.000167259315123461,8.31306282418435E-7,1,0.999253354069792,40.0298881530762,1.98368559028452,21.2600007653236,-0.00187087757130804,-0.00037344516948678,0.25,-3.12541893313112E-6,-0.000167239792320911,-4.37042028867229E-6,5.003808,5.003808,61256.95703125,61261.76171875,57.4911224749868,20.539960524171,8.482265,0,0,0,40,4449,5.0253,61259.359375,,,,,,,,,,,,,0,,,,0.0049,,,,,,5.003808,,,,
,32340164.36,5.002733,56591.24609375,-0.000149271453353685,7.81427961908876E-7,1,0.999253354069792,40.0298881530762,1.98364370186842,21.2600007653236,-0.00167200938611988,-0.000315886746731424,0.25,-1.25298741279438E-6,-0.000149199373378647,-2.36233815872256E-6,5.0025406,5.0029254,56563.7421875,56618.75,57.2675767184868,20.5426881078596,8.102614,0,0,0,40,4449,5.02235,56591.24609375,,,,,,,,,,,,,0,,,,0,,,,,,5.002733,,,,
,32340257.49,5.0021491,51936.28515625,-0.000135120847081378,7.64134078978883E-7,1,0.999253354069792,40.0298881530762,1.98365305044608,21.2600007653236,-0.00151153329993252,-0.00029294361958557,0.25,-1.77468008579417E-6,-0.000134988897924669,-2.77291542302255E-6,5.0021491,5.0021491,51906.2265625,51966.34375,57.352774227083,20.5395423487798,8.482265,0,0,0,40,4449,5.0206,51936.28515625,,,,,,,,,,,,,0,,,,0,,,,,,5.0021491,,,,
,32340351.18,5.0030389,47253.560546875,-0.000117304384124803,9.75875619588686E-7,1,0.999253354069792,40.0298881530762,1.98375583815363,21.2600007653236,-0.00131185968946413,-0.000253147692437414,0.25,-1.45358036225749E-6,-0.000117134685120028,-2.311608925076E-6,5.0027323,5.0033455,47223.63671875,47283.484375,57.0620084179291,20.5417446816208,8.102614,0,0,0,40,4449,5.01785,47253.560546875,,,,,,,,,,,,,0,,,,0.0049,,,,,,5.0030389,,,,
,32340445.675,5.00281,42530.8125,-9.99858341673794E-5,8.08432060779006E-7,1,0.999253354069792,40.0298881530762,1.98369208103599,21.2600007653236,-0.00111821914858428,-0.000212193779695729,0.25,-9.39535229730456E-7,-9.97942750104782E-5,-1.66045881714399E-6,5.00281,5.00281,42525.43359375,42536.19140625,57.3887291389676,20.5396659892183,7.722963,0,0,0,40,4449,5.0166,42530.8125,,,,,,,,,,,,,0,,,,0,,,,,,5.00281,,,,
,32340538.275,5.0021272,37900.39453125,-8.3860904676379E-5,6.43558131415051E-7,1,0.999253354069792,40.0298881530762,1.98367993344848,21.2600007653236,-0.000935690243435846,-0.000187479260852429,0.25,-1.65622501746391E-6,-8.36531379746676E-5,-2.24685388354399E-6,5.0013843,5.0028701,37867.9765625,37932.8125,57.8584878790253,20.5413693490165,8.102614,0,0,0,40,4449,5.0122,37900.39453125,,,,,,,,,,,,,0,,,,0,,,,,,5.0021272,,,,
,32340631.62,5.002002,33235.509765625,-6.921821866635E-5,6.03360184188013E-7,1,0.999253354069792,40.0298881530762,1.98375216302843,21.2600007653236,-0.000775291294031492,-0.000136124297446334,0.25,2.78076385021275E-7,-6.90240733827005E-5,-2.01083611301727E-7,5.0014048,5.0025992,33205.3359375,33265.68359375,57.3308886285445,20.5408137704472,8.102614,0,0,0,40,4449,5.0119,33235.509765625,,,,,,,,,,,,,0,,,,0,,,,,,5.002002,,,,
,32340725.005,5.0019388,28570.55078125,-5.15151071972783E-5,5.6712549958751E-7,1,0.999253354069792,40.0298881530762,1.98372114570996,21.2600007653236,-0.000579100784540119,-8.79406429064868E-5,0.25,1.38628000253161E-6,-5.1353174651636E-5,1.03684041952404E-6,5.0019388,5.0019388,28568.10546875,28572.99609375,57.3754414541407,20.542554031766,8.482265,0,0,0,40,4449,5.0118,28570.55078125,,,,,,,,,,,,,0,,,,0,,,,,,5.0019388,,,,
,32340817.205,5.0020597,23960.1318359375,-3.27524670952385E-5,4.92736690189879E-7,1,0.999253354069792,40.0298881530762,1.98372805627599,21.2600007653236,-0.000364093827999606,-7.77091327926203E-5,0.25,-1.07850793261091E-6,-3.26211285734513E-5,-1.2853866685407E-6,5.0020447,5.0020747,23930.263671875,23990,57.230840178083,20.5420563919479,8.102614,0,0,0,40,4449,5.01015,23960.1318359375,,,,,,,,,,,,,0,,,,0,,,,,,5.0020597,,,,
,32340911.895,5.0012269,19230.25,-2.09494236587263E-5,5.05314331045259E-7,1,0.999253354069792,40.0298881530762,1.98368760158928,21.2600007653236,-0.000227792432316379,-7.75139150817406E-5,0.25,-3.18603382616619E-6,-2.08404750689391E-5,-3.30121626247814E-6,5.0012269,5.0012269,19227.52734375,19232.97265625,57.312129544083,20.5428729744775,8.102614,0,0,0,40,4449,5.0096,19230.25,,,,,,,,,,,,,0,,,,-0.0049,,,,,,5.0012269,,,,
,32341003.32,5.0006685,14660.6103515625,-3.71715693714488E-6,5.33179554118597E-7,1,0.999253354069792,40.0298881530762,1.98379360736731,21.2600007653236,-3.99722575860609E-5,-1.61714612474311E-5,0.25,-7.83284784233668E-7,-3.69514887046019E-6,-8.0129354976839E-7,5.0006685,5.0006685,14630.6708984375,14690.5498046875,57.2707032325638,20.5381500409892,8.482265,0,0,0,40,4449,5.00815,14660.6103515625,,,,,,,,,,,,,0,,,,-0.00245,,,,,,5.0006685,,,,
,32341095.795,5.0000362,10038.0278320312,1.13042759229175E-5,4.05807290697497E-7,1,0.999253354069792,40.0298881530762,1.98384213406409,21.2600007653236,0.000126290942031992,2.24181197173502E-5,0.25,-8.32748763197215E-9,1.12468185963223E-5,5.38527410755676E-8,5.0000362,5.0000362,10032.98046875,10043.0751953125,57.3660619119099,20.5409192313701,8.102614,0,0,0,40,4449,5.0074,10038.0278320312,,,,,,,,,,,,,0,,,,0.0049,,,,,,5.0000362,,,,
,32341188.21,5.0004787,5419.93139648438,2.60634104464132E-5,4.257150402847E-7,1,0.999253354069792,40.0298881530762,1.98378443548955,21.2600007653236,0.000291645008541314,4.84303457044258E-5,0.25,-3.00307265195304E-7,2.59233105834862E-5,-1.6424863143362E-7,5.0004787,5.0004787,5414.833984375,5425.02880859375,57.383257739333,20.5400141151879,8.102614,0,0,0,40,4449,5.0062,5419.93139648438,,,,,,,,,,,,,0,,,,0,,,,,,5.0004787,,,,
,32341280.24,4.999764,818.682983398438,3.97126441003524E-5,3.26582434403096E-7,1,0.999253354069792,40.0298881530762,1.98376870091438,21.2600007653236,0.000443869758643396,7.59093869410778E-5,0.25,-2.54115653461989E-7,3.94871563655308E-5,-5.98147137401145E-8,4.999764,4.999764,811.084594726563,826.281372070312,56.9291315696599,20.5411072646978,8.102614,0,0,0,40,4449,5.0066,818.682983398438,,,,,,,,,,,,,0,,,,0,,,,,,4.999764,,,,
,32341296.84,5.0008292,-0.449101313948631,4.27139400979358E-5,3.94799548553567E-7,1,0.999253354069792,40.0298881530762,1.98382032547185,21.2600007653236,0.000478002094782736,7.83235924402516E-5,0.25,-5.69338121771368E-7,4.24715061442114E-5,-3.60190751825732E-7,5.0008292,5.0008292,-0.456713199615479,-0.441489428281784,57.3410497992945,20.5418188893589,8.482265,0,0,0,40,4417,5.00485,-0.449101313948631,,,,,,,,,,,,,0,,,,0,,,,,,5.0008292,,,,