File: defense/images/np_vsm/data_disorderedWafer/DD226_2_HYST_300K_REPEAT.DAT
[Header]
; VSM Data File (default extension .dat)
; Copyright (c) 2003-2013, Quantum Design, Inc. All rights reserved.
TITLE,
FILEOPENTIME,27485986.81,11/15/2018,11:00 am
BYAPP,VSM,2.0,2.0
INFO,PPMS VSM Option Release 1.4.10 Build 1,APPNAME
INFO,Quantum Design Linear Motor Servo Controller,MOTOR_MODULE_NAME
INFO,3101-100 M1,MOTOR_HW_VERSION
INFO,MMC1014,MOTOR_SERIAL_NUMBER
INFO,SRV No X-over 01.03.11,MOTOR_SOFTWARE_VERSION
INFO,Quantum Design VSM Detection Module,VSM_MODULE_NAME
INFO,3101-150 F0,VSM_HW_VERSION
INFO,VSM707,VSM_SERIAL_NUMBER
INFO,VSM No X-over 01.02.05 May 20 2008 13:51:47,VSM_SOFTWARE_VERSION
INFO,704,PREAMP_SERIAL_NUMBER
INFO,822,COIL_SERIAL_NUMBER
INFO,0,MOMENT_UNITS
INFO,CoFe2O4 AH11,SAMPLE_MATERIAL
INFO,Quick Dry Monolayer Conc,SAMPLE_COMMENT
INFO,27.96,SAMPLE_MASS
INFO,,SAMPLE_VOLUME
INFO,,SAMPLE_MOLECULAR_WEIGHT
INFO,,SAMPLE_SIZE
INFO,,SAMPLE_SHAPE
DATATYPE,COMMENT,1
DATATYPE,TIME,2
STARTUPAXIS,X,2
STARTUPAXIS,Y1,5
[Data]
Comment,Time Stamp (sec),Temperature (K),Magnetic Field (Oe),Moment (emu),M. Std. Err. (emu),Transport Action,Averaging Time (sec),Frequency (Hz),Peak Amplitude (mm),Center Position (mm),Coil Signal' (mV),Coil Signal" (mV),Range (mV),M. Quad. Signal (emu),M. Raw' (emu),M. Raw" (emu),Min. Temperature (K),Max. Temperature (K),Min. Field (Oe),Max. Field (Oe),Mass (grams),Motor Lag (deg),Pressure (Torr),VSM Status (code),Motor Status (code),Measure Status (code),Measure Count,PPMS Status (code),System Temp. (K),System Field (Oe),Sample Position (deg),Bridge 1 Resistance (ohms),Bridge 1 Excitation (에),Bridge 2 Resistance (ohms),Bridge 2 Excitation (에),Bridge 3 Resistance (ohms),Bridge 3 Excitation (에),Bridge 4 Resistance (ohms),Bridge 4 Excitation (에),Signal 1 Vin (V),Signal 2 Vin (V),Digital Inputs (code),Drive 1 Iout (mA),Drive 1 Ipower (W),Drive 2 Iout (mA),Drive 2 Ipower (W),Pressure (),Map 20 (),Map 21 (),Map 22 (),Map 23 (),Map 24 (),Map 25 (),Map 26 (),Map 27 (),Map 28 (),Map 29 ()
sample offset = 36.12 mm touchdown = 10.950000025332 mm,27486023.84,300.0024719,0.426265642046928,-4.82966898419036E-7,3.80244517815775E-7,1,0.999253354069792,40.0298881530762,1.99616564070783,15.990000218153,-5.10235929854462E-6,-3.00508528773507E-6,0.25,-1.82179594725314E-7,-4.82831760412729E-7,-1.82494181317193E-7,300.0024719,300.0024719,0.411041855812073,0.441489428281784,55.219709998102,20.4556810851384,27.464817,0,0,0,40,4417,300.53975,0.426265642046928,,,,,,,,,,,,,0,,,,-0.0049,,,,,,300.0024719,,,,
,27486093.33,300.0055542,2606.41552734375,1.99542347783101E-5,5.21409931792696E-7,1,0.999253354069792,40.0298881530762,1.99620116614797,15.990000218153,0.000224937963995678,4.26313532326728E-5,0.25,3.14254709209568E-7,1.99534288957695E-5,3.27463882377783E-7,300.0055542,300.0055542,2596.35815429687,2616.47290039062,55.676962681852,20.4661270713646,26.705515,0,0,0,40,4449,300.53605,2606.41552734375,,,,,,,,,,,,,0,,,,0,,,,,,300.0055542,,,,
,27486141.745,300.0048523,5020.68334960937,1.73277431704539E-5,4.93928504378217E-7,1,0.999253354069792,40.0298881530762,1.99629264804222,15.990000218153,0.000194909996273863,3.9497004208518E-5,0.25,4.9187965551135E-7,1.7326899185629E-5,5.03339788215712E-7,300.0039063,300.0057983,4980.7626953125,5060.60400390625,56.0591790277559,20.4697176164531,27.844467,0,0,0,40,4449,300.5337,5020.68334960937,,,,,,,,,,,,,0,,,,0,,,,,,300.0048523,,,,
,27486199.24,300.0047607,7892.78686523437,1.12700574074954E-5,7.27886059157173E-7,1,0.999253354069792,40.0298881530762,1.99631510874328,15.990000218153,0.000125745867900318,3.16111783798861E-5,0.25,8.43788271982086E-7,1.12691621302564E-5,8.51223113418411E-7,300.0047607,300.0047607,7882.806640625,7902.76708984375,55.9614754628521,20.469106307568,27.085165,0,0,0,40,4449,300.5288,7892.78686523437,,,,,,,,,,,,,0,,,,-0.0049,,,,,,300.0047607,,,,
,27486256.33,300.0107117,10747.005859375,3.31322799641049E-6,8.36345176661533E-7,1,0.999253354069792,40.0298881530762,1.99615991527895,15.990000218153,3.41002904350727E-5,2.58248540687307E-5,0.25,1.71067156956363E-6,3.31199658921668E-6,1.71281220614711E-6,300.0107117,300.0107117,10741.8681640625,10752.1435546875,56.1232725663329,20.4734535230071,27.085165,0,0,0,40,4449,300.5301,10747.005859375,,,,,,,,,,,,,0,,,,-0.00245,,,,,,300.0107117,,,,
,27486313.955,300.0108643,13625.712890625,-6.25526233772744E-6,6.58406340789052E-7,1,0.999253354069792,40.0298881530762,1.99614334896552,15.990000218153,-7.45975119318653E-5,1.02185487077234E-5,0.25,1.98781159784804E-6,-6.2563889576189E-6,1.98361528364436E-6,300.0108643,300.0108643,13620.7265625,13630.69921875,56.2373903301406,20.4721701024818,27.844467,0,0,0,40,4449,300.5184,13625.712890625,,,,,,,,,,,,,0,,,,-0.00245,,,,,,300.0108643,,,,
,27486371.625,300.01037595,16509.2158203125,-1.55944319618652E-5,1.33774882965898E-6,1,0.999253354069792,40.0298881530762,1.9961723443053,15.990000218153,-0.000179135596019148,-1.39995863765843E-5,0.25,1.46332155296141E-6,-1.55949314270837E-5,1.45297030977805E-6,300.0103149,300.010437,16504.09765625,16514.333984375,56.1279623374482,20.4746242206349,27.844467,0,0,0,40,4449,300.5099,16509.2158203125,,,,,,,,,,,,,0,,,,0,,,,,,300.01037595,,,,
,27486428.2,300.0127258,19337.447265625,-2.43036821089183E-5,1.87015466862331E-6,1,0.999253354069792,40.0298881530762,1.99610247940438,15.990000218153,-0.000280253592237385,-1.5567309595205E-5,0.25,2.83351420603197E-6,-2.43048237071431E-5,2.81737413570967E-6,300.0127258,300.0127258,19332.564453125,19342.330078125,56.3679222928521,20.4758660858064,27.464817,0,0,0,40,4449,300.51155,19337.447265625,,,,,,,,,,,,,0,,,,0.00245,,,,,,300.0127258,,,,
,27486485.47,300.01296995,22200.81640625,-3.61351061994166E-5,1.78791478833815E-6,1,0.999253354069792,40.0298881530762,1.99607453950972,15.990000218153,-0.00041462775677115,-3.49904138452547E-5,0.25,3.16493712827321E-6,-3.61361109648949E-5,3.14098364521285E-6,300.0127563,300.0131836,22195.904296875,22205.728515625,56.3601060076598,20.4763006999289,27.464817,0,0,0,40,4449,300.497,22200.81640625,,,,,,,,,,,,,0,,,,0.0049,,,,,,300.01296995,,,,
,27486542.055,300.0133362,25029.939453125,-4.58484230413593E-5,1.19627057905784E-6,1,0.999253354069792,40.0298881530762,1.99623657460219,15.990000218153,-0.000523056254832714,-6.20986518023568E-5,0.25,2.44988893449578E-6,-4.58486641321085E-5,2.41956225734535E-6,300.0133362,300.0133362,25019.70703125,25040.171875,56.3264959813329,20.4770476243258,27.464817,0,0,0,40,4449,300.50575,25029.939453125,,,,,,,,,,,,,0,,,,0,,,,,,300.0133362,,,,
,27486599.885,300.0181885,27918.5029296875,-5.35671977209943E-5,2.1423725328802E-6,1,0.999253354069792,40.0298881530762,1.99628037245041,15.990000218153,-0.000611882227911674,-6.81995745103333E-5,0.25,3.2475966999882E-6,-5.35677247943395E-5,3.21217021916807E-6,300.0181885,300.0181885,27913.447265625,27923.55859375,56.4710972573906,20.4764430735836,27.464817,0,0,0,40,4449,300.4803,27918.5029296875,,,,,,,,,,,,,0,,,,-0.00245,,,,,,300.0181885,,,,
,27486657.295,300.01635745,30787.134765625,-6.45691256177306E-5,1.3660768232683E-6,1,0.999253354069792,40.0298881530762,1.99628184079464,15.990000218153,-0.000737654466632199,-8.16302319102799E-5,0.25,3.96558978319699E-6,-6.45697995481633E-5,3.92291206407232E-6,300.0159302,300.0167847,30781.994140625,30792.275390625,56.3515080939483,20.4779740579798,27.844467,0,0,0,40,4449,300.4797,30787.134765625,,,,,,,,,,,,,0,,,,-0.0049,,,,,,300.01635745,,,,
,27486714.595,300.0195923,33653.306640625,-7.54537612672258E-5,1.37061489949409E-6,1,0.999253354069792,40.0298881530762,1.99637356953232,15.990000218153,-0.000865233146383947,-7.69710505751848E-5,0.25,6.26385460960853E-6,-7.54556144325892E-5,6.21396176580274E-6,300.0195923,300.0195923,33650.921875,33655.69140625,56.310081782429,20.4761144302392,27.844467,0,0,0,40,4449,300.4678,33653.306640625,,,,,,,,,,,,,0,,,,0.00245,,,,,,300.0195923,,,,
,27486772.825,300.0121155,36564.388671875,-8.51329626403408E-5,1.9029207988567E-6,1,0.999253354069792,40.0298881530762,1.99632425666314,15.990000218153,-0.000972873961958775,-0.000106054226556766,0.25,5.36785758223753E-6,-8.51339578176039E-5,5.31165365928502E-6,300.0121155,300.0121155,36559.3828125,36569.39453125,56.3007022401983,20.4769405717919,27.464817,0,0,0,40,4449,300.46895,36564.388671875,,,,,,,,,,,,,0,,,,-0.00245,,,,,,300.0121155,,,,
,27486829.705,300.0237732,39404.91796875,-9.54399547841331E-5,2.03580193334842E-6,1,0.999253354069792,40.0298881530762,1.99619722708843,15.990000218153,-0.00108939548915351,-0.000125795795915002,0.25,5.40648644296837E-6,-9.54406292415201E-5,5.34352944121839E-6,300.0237732,300.0237732,39402.42578125,39407.41015625,56.5289377678137,20.4786983998247,27.464817,0,0,0,40,4449,300.4497,39404.91796875,,,,,,,,,,,,,0,,,,0,,,,,,300.0237732,,,,
,27486886.29,300.0176392,42234.150390625,-0.000105066021002833,2.77441710523891E-6,1,0.999253354069792,40.0298881530762,1.99635921720586,15.990000218153,-0.00120123689721125,-0.000127689945819797,0.25,6.90750818509221E-6,-0.000105067416438742,6.83821625199129E-6,300.0176392,300.0176392,42226.71875,42241.58203125,56.3757385780444,20.476449020466,27.464817,0,0,0,40,4449,300.4405,42234.150390625,,,,,,,,,,,,,0,,,,0,,,,,,300.0176392,,,,
,27486942.45,300.0224609,45040.501953125,-0.000115864778459291,1.34778150083249E-6,1,0.999253354069792,40.0298881530762,1.99635051575172,15.990000218153,-0.00131839741640851,-0.000177163035856735,0.25,4.40187239068906E-6,-0.000115864185449013,4.32560456355029E-6,300.0224609,300.0224609,45030.51953125,45050.484375,56.5234663681791,20.4785381572368,27.844467,0,0,0,40,4449,300.4438,45040.501953125,,,,,,,,,,,,,0,,,,0,,,,,,300.0224609,,,,
,27486998.85,300.0148315,47858.771484375,-0.000126890936220441,1.56031114749334E-6,1,0.999253354069792,40.0298881530762,1.99634241805775,15.990000218153,-0.00145157266483526,-0.000149483471357464,0.25,8.760671102955E-6,-0.00012689291149833,8.67707964154052E-6,300.0148315,300.0148315,47853.66796875,47863.875,56.5742722219291,20.4771823558849,27.464817,0,0,0,40,4449,300.4295,47858.771484375,,,,,,,,,,,,,0,,,,0.00245,,,,,,300.0148315,,,,
,27487056.31,300.0228577,50730.001953125,-0.000137060196423049,1.72026012106781E-6,1,0.999253354069792,40.0298881530762,1.99637004564742,15.990000218153,-0.00155919447833014,-0.000211854330871972,0.25,5.00527380818204E-6,-0.000137059366176423,4.91517111040525E-6,300.0228577,300.0228577,50722.359375,50737.64453125,56.4460851447752,20.4764206209711,27.464817,0,0,0,40,4449,300.41665,50730.001953125,,,,,,,,,,,,,0,,,,0.0049,,,,,,300.0228577,,,,
,27487114.595,300.01428225,53643.236328125,-0.000143425304799192,1.88752584431514E-6,1,0.999253354069792,40.0298881530762,1.99626460612834,15.990000218153,-0.00164053429623935,-0.00016966421660577,0.25,9.8393948157122E-6,-0.000143427501573739,9.74503731012778E-6,300.0139771,300.0145874,53635.59375,53650.87890625,56.4296709458714,20.4783414019952,27.844467,0,0,0,40,4449,300.41385,53643.236328125,,,,,,,,,,,,,0,,,,0,,,,,,300.01428225,,,,
,27487172.6,300.0205078,56541.603515625,-0.000157931832729361,1.29915780862827E-6,1,0.999253354069792,40.0298881530762,1.99631542662345,15.990000218153,-0.0018018485915525,-0.00021371765234123,0.25,8.4558799757576E-6,-0.0001579326586999,8.35211542539545E-6,300.0205078,300.0205078,56539.28515625,56543.921875,56.5453519667175,20.4774844262462,27.844467,0,0,0,40,4449,300.40205,56541.603515625,,,,,,,,,,,,,0,,,,-0.0049,,,,,,300.0205078,,,,
,27487229.36,300.0177917,59383.259765625,-0.000169192618688743,1.89949944255635E-6,1,0.999253354069792,40.0298881530762,1.99622901345563,15.990000218153,-0.00192550346247633,-0.000256306926742988,0.25,6.63825116073338E-6,-0.000169191937232142,6.52723455810523E-6,300.0177917,300.0177917,59373.33984375,59393.1796875,56.6508718168137,20.4792342482291,27.844467,0,0,0,40,4449,300.39445,59383.259765625,,,,,,,,,,,,,0,,,,0,,,,,,300.0177917,,,,
,27487289.18,300.0263367,62369.228515625,-0.000178674032314158,1.53026669324333E-6,1,0.999253354069792,40.0298881530762,1.99631303707824,15.990000218153,-0.00203646392340215,-0.000253505065134578,0.25,8.52960375000773E-6,-0.00017867425629646,8.41239889373399E-6,300.0263367,300.0263367,62356.671875,62381.78515625,56.6321127323521,20.4742687573137,27.085165,0,0,0,40,4449,300.38275,62369.228515625,,,,,,,,,,,,,0,,,,0,,,,,,300.0263367,,,,
,27487347.955,300.0223694,65308.056640625,-0.000190358058795789,2.03103172400832E-6,1,0.999253354069792,40.0298881530762,1.99628305847856,15.990000218153,-0.0021738376579499,-0.000245639783514154,0.25,1.12492670131384E-5,-0.000190359742064593,1.11244178985846E-5,300.0223694,300.0223694,65300.79296875,65315.3203125,56.7282530402175,20.4748694074409,28.224119,0,0,0,40,4449,300.3668,65308.056640625,,,,,,,,,,,,,0,,,,-0.00245,,,,,,300.0223694,,,,
,27487406.87,300.01878355,68254.2109375,-0.00020024984154524,1.9886926881378E-6,1,0.999253354069792,40.0298881530762,1.99627269790714,15.990000218153,-0.00227732971250612,-0.000312997123450907,0.25,7.00407932695074E-6,-0.000200248483839064,6.87297887280965E-6,300.01828,300.0192871,68249.1875,68259.234375,56.5461335952368,20.4770366397665,27.464817,0,0,0,40,4449,300.35665,68254.2109375,,,,,,,,,,,,,0,,,,-0.00245,,,,,,300.01878355,,,,
,27487465.04,300.0224915,71160.37890625,-0.000210155061401343,3.27417693248124E-6,1,0.999253354069792,40.0298881530762,1.99632510876753,15.990000218153,-0.00239739446243306,-0.000286013602771118,0.25,1.11077812524093E-5,-0.000210156067944929,1.09701805855889E-5,300.0224915,300.0224915,71152.8671875,71167.890625,56.6454004171791,20.4770647428123,27.464817,0,0,0,40,4449,300.3501,71160.37890625,,,,,,,,,,,,,0,,,,0.00245,,,,,,300.0224915,,,,
,27487522.885,300.0166931,74051.35546875,-0.000226903924611971,2.96461153334841E-6,1,0.999253354069792,40.0298881530762,1.99625534891468,15.990000218153,-0.00258329369019489,-0.000338129800224063,0.25,9.39809406965533E-6,-0.00022690336836255,9.2497060161236E-6,300.0166931,300.0166931,74046.4296875,74056.28125,56.5766171074867,20.4795271945101,27.844467,0,0,0,40,4449,300.3344,74051.35546875,,,,,,,,,,,,,0,,,,-0.0049,,,,,,300.0166931,,,,
,27487581.015,300.0235901,76958.03125,-0.000230320181039172,3.02393142618923E-6,1,0.999253354069792,40.0298881530762,1.99624206796831,15.990000218153,-0.00261695748720592,-0.000373307754938725,0.25,6.87758736654396E-6,-0.000230317828827431,6.7271629746617E-6,300.0235901,300.0235901,76950.3203125,76965.7421875,56.6758839294291,20.4784478478162,28.224119,0,0,0,40,4449,300.35,76958.03125,,,,,,,,,,,,,0,,,,-0.00245,,,,,,300.0235901,,,,
,27487638.63,300.0227051,79838.9375,-0.000242843611850562,3.38482212600056E-6,1,0.999253354069792,40.0298881530762,1.99611301513418,15.990000218153,-0.00275837149580366,-0.000397681895452874,0.25,6.88870549370454E-6,-0.000242840908587097,6.7302091740157E-6,300.0227051,300.0227051,79833.7890625,79844.0859375,56.6735390438714,20.480852150448,27.464817,0,0,0,40,4449,300.31525,79838.9375,,,,,,,,,,,,,0,,,,-0.00245,,,,,,300.0227051,,,,
,27487696.325,300.0213318,82721.046875,-0.000255532643942852,2.6682620980985E-6,1,0.999253354069792,40.0298881530762,1.99621170971414,15.990000218153,-0.00291910518204777,-0.000323435669728985,0.25,1.56569573698533E-5,-0.000255535296071977,1.5490051601752E-5,300.0213318,300.0213318,82718.4765625,82723.6171875,56.6602513590445,20.4809555839684,27.844467,0,0,0,40,4449,300.3086,82721.046875,,,,,,,,,,,,,0,,,,-0.0049,,,,,,300.0213318,,,,
,27487754.76,300.0183105,85642.390625,-0.000264393459105381,3.46974380291937E-6,1,0.999253354069792,40.0298881530762,1.99609264818203,15.990000218153,-0.00300816012030544,-0.000403874095737615,0.25,1.00737506614591E-5,-0.000264392247969819,9.90136638356962E-6,300.0183105,300.0183105,85637.46875,85647.3125,56.7649895806214,20.481233049579,27.464817,0,0,0,40,4449,300.3021,85642.390625,,,,,,,,,,,,,0,,,,-0.00245,,,,,,300.0183105,,,,
,27487809.82,300.0191956,88393.6015625,-0.000277380224756096,2.7402151524064E-6,1,0.999253354069792,40.0298881530762,1.99607987642615,15.990000218153,-0.00315096165077306,-0.000452207813984519,0.25,8.04710715087818E-6,-0.000277377311596064,7.86645510783879E-6,300.0191956,300.0191956,88385.984375,88401.21875,56.5985027060252,20.4827452288461,27.464817,0,0,0,40,4449,300.2954,88393.6015625,,,,,,,,,,,,,0,,,,0,,,,,,300.0191956,,,,
,27487883.875,300.0171814,88867.6875,-0.000276469158854296,1.98832087598166E-6,1,0.999253354069792,40.0298881530762,1.99599936125009,15.990000218153,-0.00314654914378807,-0.000415739879669426,0.25,1.11142577522892E-5,-0.000276468288219058,1.09341257093878E-5,300.0171814,300.0171814,88862.7265625,88872.6484375,56.5586396515444,20.4847135726734,27.464817,0,0,0,40,4449,300.2871,88867.6875,,,,,,,,,,,,,0,,,,0.0049,,,,,,300.0171814,,,,
,27487939.905,300.0121765,86066.51953125,-0.000269112694218015,4.00396619845638E-6,1,0.999253354069792,40.0298881530762,1.99598970274383,15.990000218153,-0.00306346431911884,-0.00040089972529689,0.25,1.11527522836733E-5,-0.00026911210618311,1.09772703455848E-5,300.0121765,300.0121765,86063.9921875,86069.046875,56.6680676442368,20.4827295015293,27.464817,0,0,0,40,4449,300.2782,86066.51953125,,,,,,,,,,,,,0,,,,-0.0049,,,,,,300.0121765,,,,
,27487997.32,300.0087891,83197.0625,-0.000257754237993642,3.48540638975563E-6,1,0.999253354069792,40.0298881530762,1.99595017382142,15.990000218153,-0.00293708305510021,-0.00036680704753857,0.25,1.22008481551059E-5,-0.000257754689700713,1.20326080380986E-5,300.0087891,300.0087891,83189.5859375,83204.5390625,56.5562947659868,20.4833981160334,27.844467,0,0,0,40,4449,300.2846,83197.0625,,,,,,,,,,,,,0,,,,0,,,,,,300.0087891,,,,
,27488055.975,300.0046997,80262.94140625,-0.000245063070104576,1.88438707045951E-6,1,0.999253354069792,40.0298881530762,1.99596980636755,15.990000218153,-0.00278983465123573,-0.000364105830184469,0.25,1.02415665500005E-5,-0.000245062644770217,1.00815237923753E-5,300.0046997,300.0046997,80250.3828125,80275.5,56.6954246424098,20.4830487813743,27.844467,0,0,0,40,4449,300.27575,80262.94140625,,,,,,,,,,,,,0,,,,-0.00245,,,,,,300.0046997,,,,
,27488115.015,300.0012512,77311.203125,-0.000233146631920665,2.55315325824248E-6,1,0.999253354069792,40.0298881530762,1.99603359879846,15.990000218153,-0.00265088182949558,-0.000365895261038729,0.25,8.01983775754038E-6,-0.000233145126840588,7.86752284465658E-6,300.0012512,300.0012512,77301.21875,77321.1875,56.8775440873906,20.4844304403779,27.464817,0,0,0,40,4449,300.29365,77311.203125,,,,,,,,,,,,,0,,,,-0.00245,,,,,,300.0012512,,,,
,27488173.76,299.9997559,74374.5234375,-0.000225148271082617,1.99947339392082E-6,1,0.999253354069792,40.0298881530762,1.99616571487186,15.990000218153,-0.00256189556320056,-0.000343013201691163,0.25,8.66065333849954E-6,-0.000225147421283536,8.51341932968342E-6,299.9997559,299.9997559,74361.90625,74387.140625,56.7165286124291,20.4844127536176,28.224119,0,0,0,40,4449,300.2801,74374.5234375,,,,,,,,,,,,,0,,,,-0.0049,,,,,,299.9997559,,,,
,27488232.54,299.997467,71435.4296875,-0.000216572980507005,2.18931305775454E-6,1,0.999253354069792,40.0298881530762,1.99641611497528,15.990000218153,-0.0024633991534557,-0.000337006524508225,0.25,7.71006689471218E-6,-0.000216571770425389,7.56836047652129E-6,299.997467,299.997467,71433.0234375,71437.8359375,56.597721077506,20.4813592919057,27.844467,0,0,0,40,4449,300.2931,71435.4296875,,,,,,,,,,,,,0,,,,-0.0049,,,,,,299.997467,,,,
,27488289.91,299.9997253,68569.125,-0.000204744706106312,2.29087998943697E-6,1,0.999253354069792,40.0298881530762,1.9963356520121,15.990000218153,-0.00233737332617826,-0.000268925176945258,0.25,1.16823880455148E-5,-0.000204746412362416,1.15481890220762E-5,299.9997253,299.9997253,68564.328125,68573.921875,56.628204589756,20.4799775646402,27.464817,0,0,0,40,4449,300.2793,68569.125,,,,,,,,,,,,,0,,,,0,,,,,,299.9997253,,,,
,27488346.74,299.9915466,65728.14453125,-0.000190638305084261,2.83828791167136E-6,1,0.999253354069792,40.0298881530762,1.99629083034862,15.990000218153,-0.00217765618251459,-0.000242494993647226,0.25,1.15761475022062E-5,-0.000190640404261581,1.14510952661053E-5,299.9915466,299.9915466,65725.40625,65730.8828125,56.8525319747752,20.4825763764096,27.464817,0,0,0,40,4449,300.29315,65728.14453125,,,,,,,,,,,,,0,,,,0,,,,,,299.9915466,,,,
,27488404.355,299.9913635,62846.580078125,-0.000184273057466902,2.49251760092234E-6,1,0.999253354069792,40.0298881530762,1.99623142624535,15.990000218153,-0.0020913818755783,-0.000312338979687009,0.25,4.29399755818517E-6,-0.000184270570784368,4.17323160685751E-6,299.9913635,299.9913635,62836.65234375,62856.5078125,56.9095908566791,20.4861370959479,27.844467,0,0,0,40,4449,300.29155,62846.580078125,,,,,,,,,,,,,0,,,,-0.00245,,,,,,299.9913635,,,,
,27488461.72,299.9967041,59982.41796875,-0.000173194316741407,1.69245171813171E-6,1,0.999253354069792,40.0298881530762,1.99614498405687,15.990000218153,-0.00197622648101489,-0.000232002555017466,0.25,9.48089408997449E-6,-0.000173195508475438,9.36715100712745E-6,299.9967041,299.9967041,59977.375,59987.4609375,56.6297678467945,20.4866330652023,27.464817,0,0,0,40,4449,300.2936,59982.41796875,,,,,,,,,,,,,0,,,,-0.0049,,,,,,299.9967041,,,,
,27488520.625,299.9936218,57036.013671875,-0.000161212584588064,1.58643103744613E-6,1,0.999253354069792,40.0298881530762,1.99608895048579,15.990000218153,-0.00183991279142903,-0.000213335010568475,0.25,9.05612953907864E-6,-0.000161213860744984,8.95017594822258E-6,299.9936218,299.9936218,57033.671875,57038.35546875,56.7384142109675,20.486815742598,28.224119,0,0,0,40,4449,300.29995,57036.013671875,,,,,,,,,,,,,0,,,,0,,,,,,299.9936218,,,,
,27488578.645,299.9909363,54135.4140625,-0.000148238935513163,1.5060441871314E-6,1,0.999253354069792,40.0298881530762,1.99612512199587,15.990000218153,-0.00168903922552192,-0.000212534924553084,0.25,6.87959615072257E-6,-0.000148239171371938,6.78214691623024E-6,299.9909363,299.9909363,54130.15234375,54140.67578125,56.7141837268714,20.4858306079726,27.844467,0,0,0,40,4449,300.3093,54135.4140625,,,,,,,,,,,,,0,,,,0,,,,,,299.9909363,,,,
,27488637.72,299.9902954,51181.669921875,-0.000139386459909016,1.80898467799746E-6,1,0.999253354069792,40.0298881530762,1.99603685870156,15.990000218153,-0.00159107578155445,-0.000182697775713867,0.25,7.98498790143338E-6,-0.000139387677471731,7.89324754252899E-6,299.9902954,299.9902954,51171.72265625,51191.6171875,56.8040710065829,20.4878292046298,27.844467,0,0,0,40,4449,300.3035,51181.669921875,,,,,,,,,,,,,0,,,,-0.00245,,,,,,299.9902954,,,,
,27488697.515,299.99310305,48195.197265625,-0.0001291503874708,1.76074058077052E-6,1,0.999253354069792,40.0298881530762,1.99609695880027,15.990000218153,-0.00147091516838341,-0.000188676944724896,0.25,5.68308866021484E-6,-0.000129150373740782,5.59807689202669E-6,299.9928894,299.9933167,48187.953125,48202.44140625,56.7431039820829,20.4873234391982,27.844467,0,0,0,40,4449,300.31145,48195.197265625,,,,,,,,,,,,,0,,,,0.00245,,,,,,299.99310305,,,,
,27488755.025,299.9931335,45322.18359375,-0.000116142379390276,1.09520505637462E-6,1,0.999253354069792,40.0298881530762,1.99596213034703,15.990000218153,-0.00132494548313137,-0.000156583520021867,0.25,6.26793688509297E-6,-0.000116143125451418,6.19140462288831E-6,299.9931335,299.9931335,45314.71875,45329.6484375,56.7556100383906,20.4886581207787,27.844467,0,0,0,40,4449,300.31885,45322.18359375,,,,,,,,,,,,,0,,,,-0.00245,,,,,,299.9931335,,,,
,27488813.885,299.9924622,42377.904296875,-0.000104958196386338,1.70724630169437E-6,1,0.999253354069792,40.0298881530762,1.99612655400553,15.990000218153,-0.0011974910576099,-0.000141285653058255,0.25,5.68478595661029E-6,-0.000104958884950011,5.61557687834063E-6,299.9924622,299.9924622,42370.6640625,42385.14453125,56.658688102006,20.48930364256,27.844467,0,0,0,40,4449,300.32235,42377.904296875,,,,,,,,,,,,,0,,,,0,,,,,,299.9924622,,,,
,27488872.74,299.9926147,39436.716796875,-9.68775265021321E-5,1.44001717451396E-6,1,0.999253354069792,40.0298881530762,1.99613290533911,15.990000218153,-0.00110457036496484,-0.000134621379190396,0.25,4.87444925764402E-6,-9.68779146739698E-5,4.81053568651966E-6,299.9926147,299.9926147,39431.6875,39441.74609375,56.7900016932368,20.4873671277566,27.844467,0,0,0,40,4449,300.31935,39436.716796875,,,,,,,,,,,,,0,,,,0.0049,,,,,,299.9926147,,,,
,27488932.29,299.9934387,36460.87109375,-8.54838017563382E-5,1.51110572879813E-6,1,0.999253354069792,40.0298881530762,1.99603800697086,15.990000218153,-0.000975778624885379,-0.000112084528143066,0.25,4.8938681657338E-6,-8.54845307376528E-5,4.83741769993633E-6,299.9934387,299.9934387,36453.34375,36468.3984375,56.9103724851983,20.4889145995676,27.844467,0,0,0,40,4449,300.326,36460.87109375,,,,,,,,,,,,,0,,,,0.00245,,,,,,299.9934387,,,,
,27488987.78,299.9960632,33687.6953125,-7.63483470140416E-5,9.90924519411919E-7,1,0.999253354069792,40.0298881530762,1.99605112583935,15.990000218153,-0.00087420696689327,-8.45105717943526E-5,0.25,5.75077697411043E-6,-7.63498993942784E-5,5.70028772851563E-6,299.9960632,299.9960632,33679.86328125,33695.52734375,56.7345060683714,20.4902058445893,28.224119,0,0,0,40,4449,300.32785,33687.6953125,,,,,,,,,,,,,0,,,,0.0049,,,,,,299.9960632,,,,
,27489044.71,299.9951172,30841.4326171875,-6.66401751477666E-5,1.20485280040864E-6,1,0.999253354069792,40.0298881530762,1.99615190543365,15.990000218153,-0.000758857959848782,-9.81533458767241E-5,0.25,2.86219544355154E-6,-6.66401092435517E-5,2.81816221728838E-6,299.9951172,299.9951172,30836.33984375,30846.525390625,56.8869236296214,20.4881130699189,28.224119,0,0,0,40,4449,300.3278,30841.4326171875,,,,,,,,,,,,,0,,,,0,,,,,,299.9951172,,,,
,27489103.07,299.9927673,27925.4677734375,-5.63221325579506E-5,1.31385485969244E-6,1,0.999253354069792,40.0298881530762,1.99607240132737,15.990000218153,-0.00064310076090298,-7.27786107935116E-5,0.25,3.31921110816205E-6,-5.63226745742431E-5,3.28194642802443E-6,299.9927673,299.9927673,27912.705078125,27938.23046875,56.7251265261406,20.4890443146625,27.464817,0,0,0,40,4449,300.32905,27925.4677734375,,,,,,,,,,,,,0,,,,-0.00245,,,,,,299.9927673,,,,
,27489161.22,299.9874573,25019.0166015625,-4.64417983459974E-5,1.0783265149842E-6,1,0.999253354069792,40.0298881530762,1.99607717017229,15.990000218153,-0.000533542835700328,-4.12128737777759E-5,0.25,4.40013026669232E-6,-4.64433517879553E-5,4.36933653398417E-6,299.9870911,299.9878235,25013.904296875,25024.12890625,56.9283499411406,20.489977622002,27.844467,0,0,0,40,4449,300.3327,25019.0166015625,,,,,,,,,,,,,0,,,,0.0049,,,,,,299.9874573,,,,
,27489218.6,299.9929504,22150.7392578125,-3.69879841754242E-5,1.43061054364468E-6,1,0.999253354069792,40.0298881530762,1.99606749674913,15.990000218153,-0.000422254849240546,-4.82717950196663E-5,0.25,2.13766102533323E-6,-3.69883111929524E-5,2.11316181358653E-6,299.9929504,299.9929504,22145.865234375,22155.61328125,56.7759323798906,20.4880321008407,27.464817,0,0,0,40,4449,300.34435,22150.7392578125,,,,,,,,,,,,,0,,,,0,,,,,,299.9929504,,,,
,27489275.08,299.991333,19327.2890625,-2.7099642589149E-5,9.70316243104672E-7,1,0.999253354069792,40.0298881530762,1.99607773850615,15.990000218153,-0.000312177754927413,-1.91675011068587E-5,0.25,2.99941120456949E-6,-2.71008308472379E-5,2.98140947395392E-6,299.991333,299.991333,19317.177734375,19337.400390625,56.7477937531983,20.4900701545277,27.844467,0,0,0,40,4449,300.34375,19327.2890625,,,,,,,,,,,,,0,,,,-0.0049,,,,,,299.991333,,,,
,27489333.255,299.9947205,16421.640625,-1.58231619146294E-5,8.98538204892061E-7,1,0.999253354069792,40.0298881530762,1.99597263298603,15.990000218153,-0.000185080805980271,5.0452321002318E-6,0.25,3.18787799500503E-6,-1.58248040525406E-5,3.1773186596368E-6,299.9947205,299.9947205,16414.37109375,16428.91015625,56.7423223535637,20.4920652419861,27.464817,0,0,0,40,4449,300.34775,16421.640625,,,,,,,,,,,,,0,,,,-0.00245,,,,,,299.9947205,,,,
,27489390.64,299.9959412,13553.3232421875,-6.32774011534077E-6,7.61905912340535E-7,1,0.999253354069792,40.0298881530762,1.9959614822695,15.990000218153,-7.43400881074761E-5,3.89914611023092E-6,0.25,1.44132216784999E-6,-6.32850695724643E-6,1.43709215517893E-6,299.9959412,299.9959412,13550.72265625,13555.923828125,56.7688977232175,20.4932223745715,27.844467,0,0,0,40,4449,300.3459,13553.3232421875,,,,,,,,,,,,,0,,,,0.0049,,,,,,299.9959412,,,,
,27489449.61,300.0001526,10604.6938476562,3.57257373850004E-6,6.77741336988855E-7,1,0.999253354069792,40.0298881530762,1.99597179657945,15.990000218153,3.8875353768713E-5,1.5670464916429E-5,0.25,7.67505335442517E-7,3.57195938146936E-6,7.69847866958827E-7,300.0001526,300.0001526,10597.0341796875,10612.353515625,56.882233858506,20.4922258210936,27.844467,0,0,0,40,4449,300.35445,10604.6938476562,,,,,,,,,,,,,0,,,,0,,,,,,300.0001526,,,,
,27489505.035,299.9989319,7835.45385742188,1.17277215339742E-5,5.83200332013138E-7,1,0.999253354069792,40.0298881530762,1.99589871288332,15.990000218153,0.000131352816484649,2.98490186885416E-5,0.25,6.09127263353211E-7,1.17269694878912E-5,6.16878361979239E-7,299.9989319,299.9989319,7827.8466796875,7843.06103515625,56.8032893780637,20.491714813435,27.844467,0,0,0,40,4449,300.32855,7835.45385742188,,,,,,,,,,,,,0,,,,-0.00245,,,,,,299.9989319,,,,
,27489560.175,299.9962463,5079.84985351562,1.81019551509644E-5,5.88903295501168E-7,1,0.999253354069792,40.0298881530762,1.9959298182399,15.990000218153,0.000204113933007964,3.81925151268603E-5,0.25,2.42917058965907E-7,1.81012575900557E-5,2.54905968499012E-7,299.9962463,299.9962463,5069.63037109375,5090.0693359375,56.8939582862945,20.4924716008782,27.464817,0,0,0,40,4449,300.35035,5079.84985351562,,,,,,,,,,,,,0,,,,-0.00245,,,,,,299.9962463,,,,
,27489616.91,299.9978027,2242.95471191406,2.07404107156185E-5,4.86190607725692E-7,1,0.999253354069792,40.0298881530762,1.99600656737611,15.990000218153,0.000234478868048875,4.02650388582933E-5,0.25,-3.09804566118587E-8,2.07398147936623E-5,-1.72292504079804E-8,299.9978027,299.9978027,2230.53588867187,2255.37353515625,56.6907348712945,20.4929121995145,28.224119,0,0,0,40,4449,300.34705,2242.95471191406,,,,,,,,,,,,,0,,,,-0.00245,,,,,,299.9978027,,,,
,27489670.65,299.9924011,-443.382369995117,-1.29573303779991E-5,4.13766520042867E-7,1,0.999253354069792,40.0298881530762,1.99603950785011,15.990000218153,-0.00014579166266093,-2.91877141785895E-5,0.25,-3.37391360166014E-7,-1.29567239067377E-5,-3.45973258549181E-7,299.9924011,299.9924011,-448.529510498047,-438.235229492188,56.8197035769676,20.4947871804816,28.224119,0,0,0,40,4449,300.354,-443.382369995117,,,,,,,,,,,,,0,,,,0,,,,,,299.9924011,,,,
,27489725.945,299.9985962,-3202.14685058594,-1.96600168610558E-5,5.32415451959748E-7,1,0.999253354069792,40.0298881530762,1.99603960186074,15.990000218153,-0.00022047545972611,-4.85146205420521E-5,0.25,-8.86032896065937E-7,-1.96588447549607E-5,-8.99038951657853E-7,299.9985962,299.9985962,-3207.23388671875,-3197.05981445313,56.8056342636214,20.4941395750473,28.224119,0,0,0,40,4449,300.34585,-3202.14685058594,,,,,,,,,,,,,0,,,,0,,,,,,299.9985962,,,,
,27489783.105,300.0028076,-6060.078125,-1.60071009708294E-5,4.82844926175771E-7,1,0.999253354069792,40.0298881530762,1.99597867751581,15.990000218153,-0.000179219357542857,-4.11474155285912E-5,0.25,-8.67235062169378E-7,-1.60060482403644E-5,-8.77815343675673E-7,300.0028076,300.0028076,-6072.65576171875,-6047.50048828125,56.6031924771406,20.4923437916708,27.464817,0,0,0,40,4449,300.352,-6060.078125,,,,,,,,,,,,,0,,,,-0.00245,,,,,,300.0028076,,,,
,27489839.355,300.0036011,-8874.09765625,-8.91496144130509E-6,6.28281667278057E-7,1,0.999253354069792,40.0298881530762,1.99605830742953,15.990000218153,-9.73847545988561E-5,-3.69605938870603E-5,0.25,-1.72545266092184E-6,-8.91355238506175E-6,-1.73130547725607E-6,300.0036011,300.0036011,-8881.5556640625,-8866.6396484375,56.7524835243137,20.4950092317926,27.464817,0,0,0,40,4449,300.34855,-8874.09765625,,,,,,,,,,,,,0,,,,0,,,,,,300.0036011,,,,
,27489896.36,300.0049744,-11723.0463867188,1.23253843072595E-6,4.74334661761389E-7,1,0.999253354069792,40.0298881530762,1.9959721777372,15.990000218153,1.85661663753525E-5,-2.43420805392087E-5,0.25,-2.36727585735517E-6,1.23406869078467E-6,-2.36638917275393E-6,300.0049744,300.0049744,-11730.537109375,-11715.5556640625,56.7352876968906,20.4956173809337,28.224119,0,0,0,40,4449,300.3423,-11723.0463867188,,,,,,,,,,,,,0,,,,-0.00245,,,,,,300.0049744,,,,
,27489955.725,300.0039673,-14689.4697265625,1.03539249538942E-5,6.14412839187302E-7,1,0.999253354069792,40.0298881530762,1.99587118467533,15.990000218153,0.000121669581703291,-6.5761562974837E-6,0.25,-2.3757724526811E-6,1.03551880330629E-5,-2.36885122522356E-6,300.0039673,300.0039673,-14694.3408203125,-14684.5986328125,56.926005055583,20.4952013730033,27.844467,0,0,0,40,4449,300.34455,-14689.4697265625,,,,,,,,,,,,,0,,,,-0.00245,,,,,,300.0039673,,,,
,27490013.6,300.0066986,-17582.7314453125,2.0632238214075E-5,8.12427719259263E-7,1,0.999253354069792,40.0298881530762,1.99583622832937,15.990000218153,0.000238257274677797,1.10754043261032E-5,0.25,-2.59470800778758E-6,2.06333373329561E-5,-2.58098700622118E-6,300.0065613,300.0068359,-17587.78125,-17577.681640625,56.8736359447945,20.4961135401183,27.844467,0,0,0,40,4449,300.34025,-17582.7314453125,,,,,,,,,,,,,0,,,,-0.0049,,,,,,300.0066986,,,,
,27490072.64,300.0084229,-20533.4873046875,2.97419163819681E-5,1.00743015215306E-6,1,0.999253354069792,40.0298881530762,1.99628551447562,15.990000218153,0.00034342766340301,1.65475976643822E-5,0.25,-3.68913640833119E-6,2.97434647135862E-5,-3.66936962345046E-6,300.0084229,300.0084229,-20535.845703125,-20531.12890625,56.851750346256,20.4919142885596,28.224119,0,0,0,40,4449,300.3348,-20533.4873046875,,,,,,,,,,,,,0,,,,-0.0049,,,,,,300.0084229,,,,
,27490129.23,300.0086975,-23362.0859375,4.12685305903361E-5,8.88308079122743E-7,1,0.999253354069792,40.0298881530762,1.99615318874837,15.990000218153,0.000473173440345651,4.2127337522443E-5,0.25,-3.42306326422634E-6,4.12695579179162E-5,-3.39570166014936E-6,300.0086975,300.0086975,-23369.576171875,-23354.595703125,56.8806706014676,20.4933922030887,28.224119,0,0,0,40,4449,300.3301,-23362.0859375,,,,,,,,,,,,,0,,,,0,,,,,,300.0086975,,,,
,27490187.73,300.0119629,-26285.017578125,5.10005416879711E-5,1.11215538122337E-6,1,0.999253354069792,40.0298881530762,1.99620271681187,15.990000218153,0.000585927119612822,4.53945060803963E-5,0.25,-4.82023147334598E-6,5.10021948769739E-5,-4.78641915946334E-6,300.0119629,300.0119629,-26287.64453125,-26282.390625,56.9095908566791,20.4957100596462,28.224119,0,0,0,40,4449,300.32565,-26285.017578125,,,,,,,,,,,,,0,,,,0,,,,,,300.0119629,,,,
,27490246.555,300.0123291,-29226.3173828125,6.26497644284452E-5,1.10866293405325E-6,1,0.999253354069792,40.0298881530762,1.99602202217165,15.990000218153,0.000715092693346565,8.23433964223177E-5,0.25,-3.56909637415541E-6,6.26502424368655E-5,-3.5276556172761E-6,300.0123291,300.0123291,-29231.5078125,-29221.126953125,56.6016292201021,20.4963958665356,27.844467,0,0,0,40,4449,300.3161,-29226.3173828125,,,,,,,,,,,,,0,,,,-0.00245,,,,,,300.0123291,,,,
,27490306.49,300.0126038,-32220.0625,7.25021613877646E-5,1.62083195611741E-6,1,0.999253354069792,40.0298881530762,1.99600766286738,15.990000218153,0.000827274890558919,9.68429862208753E-5,0.25,-3.99313969962893E-6,7.25026243372403E-5,-3.94521590206894E-6,300.0126038,300.0126038,-32230.00390625,-32210.12109375,56.7774956369291,20.4960750323902,27.844467,0,0,0,40,4449,300.31025,-32220.0625,,,,,,,,,,,,,0,,,,0,,,,,,300.0126038,,,,
,27490367.17,300.013855,-35252.73828125,8.42544805825054E-5,1.27570169473865E-6,1,0.999253354069792,40.0298881530762,1.99587311084625,15.990000218153,0.00095883757373281,0.000126810120162943,0.25,-3.37716752239897E-6,8.42541835884454E-5,-3.32154803399738E-6,300.013855,300.013855,-35262.95703125,-35242.51953125,56.7860935506406,20.4978805988445,28.224119,0,0,0,40,4449,300.30015,-35252.73828125,,,,,,,,,,,,,0,,,,-0.0049,,,,,,300.013855,,,,
,27490424.49,300.0133057,-38118.69921875,9.6271057696811E-5,1.31427051161041E-6,1,0.999253354069792,40.0298881530762,1.99595785003195,15.990000218153,0.0010994441563717,0.000122908859086868,0.25,-5.80469625270136E-6,9.62720036003606E-5,-5.74112565886981E-6,300.0133057,300.0133057,-38121.7421875,-38115.65625,56.831428004756,20.5007323409028,27.844467,0,0,0,40,4449,300.2955,-38118.69921875,,,,,,,,,,,,,0,,,,-0.0049,,,,,,300.0133057,,,,
,27490482.845,300.0122986,-41034.630859375,0.000106956586582398,1.36518428665996E-6,1,0.999253354069792,40.0298881530762,1.996040593847,15.990000218153,0.00121706136643938,0.000162316823241029,0.25,-4.1697982791183E-6,0.000106956142740301,-4.09928574033532E-6,300.0113831,300.0132141,-41045.046875,-41024.21484375,56.7993812354675,20.4987209215944,27.844467,0,0,0,40,4449,300.2923,-41034.630859375,,,,,,,,,,,,,0,,,,0,,,,,,300.0122986,,,,
,27490542.275,300.0123596,-44002.78515625,0.000115870155268393,1.47717383571891E-6,1,0.999253354069792,40.0298881530762,1.99606983679008,15.990000218153,0.00132677535246337,0.000128125655498658,0.25,-8.73927180082117E-6,0.000115872453380239,-8.66280845064295E-6,300.0123596,300.0123596,-44007.9765625,-43997.59375,56.8345545188329,20.4987578058517,28.603769,0,0,0,40,4449,300.28945,-44002.78515625,,,,,,,,,,,,,0,,,,-0.0049,,,,,,300.0123596,,,,
,27490599.815,300.014679,-46879.25390625,0.000127673652352086,1.39920542701252E-6,1,0.999253354069792,40.0298881530762,1.99596312298234,15.990000218153,0.00145310581897959,0.000191681206491117,0.25,-5.16038365932442E-6,0.000127673237334777,-5.07631670138914E-6,300.014679,300.014679,-46886.73046875,-46871.77734375,56.7188734979868,20.4993294823031,28.224119,0,0,0,40,4449,300.2792,-46879.25390625,,,,,,,,,,,,,0,,,,-0.00245,,,,,,300.014679,,,,
,27490655.335,300.01422115,-49653.138671875,0.000137567619868179,1.97364839317515E-6,1,0.999253354069792,40.0298881530762,1.99600356313081,15.990000218153,0.00156625837738432,0.000203567144520893,0.25,-5.82320105172717E-6,0.00013756735034128,-5.73266697397867E-6,300.0136108,300.0148315,-49665.578125,-49640.69921875,56.750138638756,20.5009979423649,28.603769,0,0,0,40,4449,300.2683,-49653.138671875,,,,,,,,,,,,,0,,,,-0.00245,,,,,,300.01422115,,,,
,27490713.205,300.0137024,-52548.349609375,0.000148802843976986,1.51685388793861E-6,1,0.999253354069792,40.0298881530762,1.99595283643353,15.990000218153,0.00169537927781575,0.000213002753778706,0.25,-6.93438797847943E-6,0.000148802975655513,-6.83651069451188E-6,300.0137024,300.0137024,-52558.2734375,-52538.42578125,56.9603967104291,20.5010802514558,27.464817,0,0,0,40,4449,300.2736,-52548.349609375,,,,,,,,,,,,,0,,,,-0.0049,,,,,,300.0137024,,,,
,27490770.21,300.0171509,-55396.95703125,0.000156047062640761,1.58433627639751E-6,1,0.999253354069792,40.0298881530762,1.99594405967718,15.990000218153,0.00177850899605715,0.000219904544493841,0.25,-7.57866469053512E-6,0.000156047385209831,-7.47607442081515E-6,300.0171509,300.0171509,-55407.19921875,-55386.71484375,56.8978664288906,20.5021554032975,28.224119,0,0,0,40,4449,300.25285,-55396.95703125,,,,,,,,,,,,,0,,,,0.00245,,,,,,300.0171509,,,,
,27490828.78,300.015625,-58322.626953125,0.000170976575975713,2.35637217669308E-6,1,0.999253354069792,40.0298881530762,1.99594124281647,15.990000218153,0.00194372096480873,0.000269462936461408,0.25,-5.78026942212219E-6,0.000170975287767039,-5.66801836332431E-6,300.015625,300.015625,-58325.40234375,-58319.8515625,56.933039712256,20.5016851172653,28.224119,0,0,0,40,4449,300.2507,-58322.626953125,,,,,,,,,,,,,0,,,,0,,,,,,300.015625,,,,
,27490888.825,300.0163269,-61325.890625,0.000181327639813264,1.78271781766541E-6,1,0.999253354069792,40.0298881530762,1.99607522436354,15.990000218153,0.0020619301094033,0.000283471026888663,0.25,-6.33571689793363E-6,0.000181326408204725,-6.21674628366873E-6,300.0163269,300.0163269,-61333.12890625,-61318.65234375,57.0088576786214,20.501575026128,28.603769,0,0,0,40,4449,300.23955,-61325.890625,,,,,,,,,,,,,0,,,,0,,,,,,300.0163269,,,,
,27490950.26,300.0081787,-64394.408203125,0.00019507674530261,2.06634668431814E-6,1,0.999253354069792,40.0298881530762,1.99584250167436,15.990000218153,0.00221387479937987,0.000328909810635398,0.25,-4.69432798526414E-6,0.000195074094140186,-4.56650358732279E-6,300.0081787,300.0081787,-64401.83203125,-64386.984375,56.7876568076791,20.5049500281323,28.224119,0,0,0,40,4449,300.2511,-64394.408203125,,,,,,,,,,,,,0,,,,-0.0049,,,,,,300.0081787,,,,
,27491005.71,300.01594545,-67165.59375,0.000203552336258274,2.3371873022507E-6,1,0.999253354069792,40.0298881530762,1.99615577017097,15.990000218153,0.00230993151883124,0.000345999097776865,0.25,-4.65511940565722E-6,0.00020354935928928,-4.52182817160188E-6,300.0159302,300.0159607,-67170.4453125,-67160.7421875,56.8079791491791,20.4981443391066,27.844467,0,0,0,40,4449,300.22945,-67165.59375,,,,,,,,,,,,,0,,,,0,,,,,,300.01594545,,,,
,27491061.045,300.013855,-69930.9140625,0.000214487151467771,2.27765261952243E-6,1,0.999253354069792,40.0298881530762,1.99611375081176,15.990000218153,0.00243958356547807,0.000332190053289783,0.25,-7.7705796127039E-6,0.000214485910091126,-7.63013946282221E-6,300.013855,300.013855,-69938.2890625,-69923.5390625,56.8798889729483,20.5029497408428,28.224119,0,0,0,40,4449,300.22575,-69930.9140625,,,,,,,,,,,,,0,,,,0,,,,,,300.013855,,,,
,27491120.215,300.01416015,-72889.0859375,0.000222091761262467,2.03064554969673E-6,1,0.999253354069792,40.0298881530762,1.99596503087886,15.990000218153,0.00252398497736977,0.000354991320501028,0.25,-7.06847823272124E-6,0.000222089840448355,-6.9231944961922E-6,300.0133667,300.0149536,-72896.7421875,-72881.4296875,56.7814037795252,20.5038629635492,28.224119,0,0,0,40,4449,300.2223,-72889.0859375,,,,,,,,,,,,,0,,,,0,,,,,,300.01416015,,,,
,27491179.085,300.0151367,-75829.83203125,0.000233684597906384,2.65102424204812E-6,1,0.999253354069792,40.0298881530762,1.99589867359504,15.990000218153,0.00265515084754072,0.000376382944835638,0.25,-7.18308925634528E-6,0.000233682408489134,-7.0303330655388E-6,300.0151367,300.0151367,-75844.8359375,-75814.828125,56.8189219484483,20.5027649832298,28.603769,0,0,0,40,4449,300.2041,-75829.83203125,,,,,,,,,,,,,0,,,,-0.0049,,,,,,300.0151367,,,,
,27491238.64,300.0212402,-78808.1796875,0.000248205946653486,2.60966253228005E-6,1,0.999253354069792,40.0298881530762,1.99599652594754,15.990000218153,0.00281242529145042,0.000445102013822906,0.25,-3.62032330906866E-6,0.000248200958151049,-3.45830643952297E-6,300.0212402,300.0212402,-78813.2890625,-78803.0703125,56.8634747740445,20.5024215559353,27.844467,0,0,0,40,4449,300.18895,-78808.1796875,,,,,,,,,,,,,0,,,,0,,,,,,300.0212402,,,,
,27491297.18,300.024765,-81731.66796875,0.00025698843877265,2.90088946864349E-6,1,0.999253354069792,40.0298881530762,1.99581370817349,15.990000218153,0.0029235568014886,0.000392286327255156,0.25,-9.81164345472996E-6,0.000256987203226079,-9.6438493772455E-6,300.0247192,300.0248108,-81741.890625,-81721.4453125,57.0104209356599,20.5075756654565,28.224119,0,0,0,40,4449,300.2033,-81731.66796875,,,,,,,,,,,,,0,,,,0.00245,,,,,,300.024765,,,,
,27491355.23,300.0163269,-84631.98046875,0.000272059271168365,2.2907307469096E-6,1,0.999253354069792,40.0298881530762,1.99621204510805,15.990000218153,0.00308042446751416,0.000502945032842074,0.25,-2.63947759430614E-6,0.000272053004778299,-2.46218768902529E-6,300.0163269,300.0163269,-84639.453125,-84624.5078125,56.8955215433329,20.5021029685242,28.224119,0,0,0,40,4449,300.17365,-84631.98046875,,,,,,,,,,,,,0,,,,-0.0049,,,,,,300.0163269,,,,
,27491411.13,300.0186768,-87428.02734375,0.000280598335241227,1.71005760332316E-6,1,0.999253354069792,40.0298881530762,1.99605095237278,15.990000218153,0.00318624459090743,0.000464546318580954,0.25,-7.51257545888633E-6,0.00028059497697254,-7.32971368077696E-6,300.0186768,300.0186768,-87437.9921875,-87418.0625,56.8423708040252,20.5051143616065,28.224119,0,0,0,40,4449,300.17355,-87428.02734375,,,,,,,,,,,,,0,,,,-0.00245,,,,,,300.0186768,,,,
,27491484.75,300.0149841,-89857.55078125,0.000294237206153839,2.23248259646317E-6,1,0.999253354069792,40.0298881530762,1.99592316167754,15.990000218153,0.00333488290330714,0.000521901681833157,0.25,-4.79808341844955E-6,0.000294231727310062,-4.60653796537284E-6,300.0149841,300.0149841,-89860.078125,-89855.0234375,56.8853603725829,20.5062762226341,27.844467,0,0,0,40,4449,300.16125,-89857.55078125,,,,,,,,,,,,,0,,,,-0.0049,,,,,,300.0149841,,,,
,27491540.735,300.0174866,-87063.8828125,0.000277186125211617,2.10104749449977E-6,1,0.999253354069792,40.0298881530762,1.99614131895929,15.990000218153,0.00314487279160791,0.000474857669187297,0.25,-6.01097368239271E-6,0.000277181900134911,-5.83035371247406E-6,300.0174866,300.0174866,-87068.9921875,-87058.7734375,57.0354330482753,20.5058960002009,28.603769,0,0,0,40,4449,300.1645,-87063.8828125,,,,,,,,,,,,,0,,,,0,,,,,,300.0174866,,,,
,27491594.43,300.0045166,-84380.45703125,0.000269114438478753,2.58675615116667E-6,1,0.999253354069792,40.0298881530762,1.99628379600184,15.990000218153,0.00305138457060632,0.000473289869106768,0.25,-4.7542758460822E-6,0.000269109748809199,-4.57882396613288E-6,300.0037231,300.0053101,-84390.328125,-84370.5859375,56.9627415959868,20.5031556903344,28.224119,0,0,0,40,4449,300.1611,-84380.45703125,,,,,,,,,,,,,0,,,,-0.00245,,,,,,300.0045166,,,,
,27491651.66,300.0044861,-81519.97265625,0.000257973858261211,2.20656167066922E-6,1,0.999253354069792,40.0298881530762,1.99618348808497,15.990000218153,0.00293718379202926,0.000382919313938583,0.25,-1.08172511028962E-5,0.000257973435026637,-1.06487538455559E-5,300.0044861,300.0044861,-81527.46875,-81512.4765625,56.8658196596022,20.5037209004607,28.603769,0,0,0,40,4449,300.15805,-81519.97265625,,,,,,,,,,,,,0,,,,-0.00245,,,,,,300.0044861,,,,
,27491711.58,300.0013733,-78523.77734375,0.000250322052281248,2.76793715227443E-6,1,0.999253354069792,40.0298881530762,1.99621610343372,15.990000218153,0.0028439920777185,0.000406869803242811,0.25,-7.37341663544233E-6,0.000250319626254798,-7.20988416893914E-6,300.0013733,300.0013733,-78528.71875,-78518.8359375,56.6625962446021,20.503889549955,28.224119,0,0,0,40,4449,300.16175,-78523.77734375,,,,,,,,,,,,,0,,,,-0.00245,,,,,,300.0013733,,,,
,27491770.41,300.0006409,-75585.10546875,0.000233125633100665,2.62745226735768E-6,1,0.999253354069792,40.0298881530762,1.99623292045369,15.990000218153,0.00264391006205841,0.000406218379709708,0.25,-4.45219189736666E-6,0.000233121796467866,-4.29984886837952E-6,300.0006409,300.0006409,-75595.3828125,-75574.828125,56.8900501436983,20.5020250422527,27.844467,0,0,0,40,4449,300.1621,-75585.10546875,,,,,,,,,,,,,0,,,,-0.00245,,,,,,300.0006409,,,,
,27491830.005,299.9910889,-72606.9609375,0.000221585094488786,2.02220867050277E-6,1,0.999253354069792,40.0298881530762,1.99616772087908,15.990000218153,0.00252259670465649,0.000330414307472971,0.25,-9.15811313740242E-6,0.000221584735345717,-9.01306628871694E-6,299.9910889,299.9910889,-72616.9140625,-72597.0078125,56.6938613853714,20.5028818943537,28.603769,0,0,0,40,4449,300.1697,-72606.9609375,,,,,,,,,,,,,0,,,,-0.00245,,,,,,299.9910889,,,,
,27491888.81,299.9925232,-69669.04296875,0.000216502423932552,2.43479953548841E-6,1,0.999253354069792,40.0298881530762,1.99610139529284,15.990000218153,0.00245891020847044,0.000355987381815886,0.25,-6.01421741906784E-6,0.000216500138650543,-5.87247872555915E-6,299.9925232,299.9925232,-69674.1171875,-69663.96875,56.8329912617945,20.5036230320458,28.224119,0,0,0,40,4449,300.1748,-69669.04296875,,,,,,,,,,,,,0,,,,0.00245,,,,,,299.9925232,,,,
,27491946.54,299.9916687,-66783.28515625,0.000199366502997063,1.96167633117968E-6,1,0.999253354069792,40.0298881530762,1.99608376226663,15.990000218153,0.00226748968322605,0.000309231431465731,0.25,-7.1818652909983E-6,0.0001993654745284,-7.05120429744091E-6,299.9916687,299.9916687,-66785.6640625,-66780.90625,56.8423708040252,20.5030999282475,28.224119,0,0,0,40,4449,300.1767,-66783.28515625,,,,,,,,,,,,,0,,,,-0.0049,,,,,,299.9916687,,,,
,27492004.22,299.9862671,-63902.521484375,0.000190715071615847,2.08471270657993E-6,1,0.999253354069792,40.0298881530762,1.99616636245306,15.990000218153,0.00216071180696987,0.000344695957337495,0.25,-2.54665585345374E-6,0.00019071128908491,-2.42170213073209E-6,299.9862671,299.9862671,-63912.42578125,-63892.6171875,56.800944492506,20.5019667741713,28.224119,0,0,0,40,4449,300.1813,-63902.521484375,,,,,,,,,,,,,0,,,,0,,,,,,299.9862671,,,,
,27492062.22,299.9916992,-61003.73828125,0.000180943238180466,2.29264610030749E-6,1,0.999253354069792,40.0298881530762,1.99625553981589,15.990000218153,0.00206254717360315,0.000255137391747506,0.25,-8.77788220440839E-6,0.000180943776501548,-8.65906499339207E-6,299.9916992,299.9916992,-61008.83984375,-60998.63671875,56.8283014906791,20.5023740515146,28.603769,0,0,0,40,4449,300.1874,-61003.73828125,,,,,,,,,,,,,0,,,,0,,,,,,299.9916992,,,,
,27492120.735,299.9870911,-58077.955078125,0.000169369283048665,2.02494636462427E-6,1,0.999253354069792,40.0298881530762,1.99615634303508,15.990000218153,0.00192242040459179,0.0002855910960565,0.25,-4.07746423973147E-6,0.000169367097578553,-3.96628495036483E-6,299.9870911,299.9870911,-58085.57421875,-58070.3359375,56.6461820456983,20.5035227540536,28.224119,0,0,0,40,4449,300.1818,-58077.955078125,,,,,,,,,,,,,0,,,,0,,,,,,299.9870911,,,,
,27492176.935,299.9883728,-55269.5546875,0.000159912264580452,1.91070816933721E-6,1,0.999253354069792,40.0298881530762,1.99612125972912,15.990000218153,0.00181933500129778,0.000244897319460908,0.25,-6.03887605660477E-6,0.000159911625959564,-5.9337773276937E-6,299.9883728,299.9883728,-55276.9609375,-55262.1484375,56.8548768603329,20.5024417270808,28.224119,0,0,0,40,4449,300.1999,-55269.5546875,,,,,,,,,,,,,0,,,,0.00245,,,,,,299.9883728,,,,
,27492233.905,299.9911499,-52421.26171875,0.000149459120812013,2.03311839501774E-6,1,0.999253354069792,40.0298881530762,1.99614697070425,15.990000218153,0.00170594503108426,0.00019705607143174,0.25,-8.46068854067524E-6,0.000149460354902315,-8.36231061402302E-6,299.9911499,299.9911499,-52428.4765625,-52414.046875,56.8728543162753,20.5000287348067,28.224119,0,0,0,40,4449,300.19995,-52421.26171875,,,,,,,,,,,,,0,,,,-0.0049,,,,,,299.9911499,,,,
,27492291.875,299.9888306,-49525.673828125,0.000135951107432827,1.8070213355278E-6,1,0.999253354069792,40.0298881530762,1.99627343321744,15.990000218153,0.00154377824744111,0.000225885782842768,0.25,-3.57109015446541E-6,0.000135949529121742,-3.4816625024561E-6,299.9888306,299.9888306,-49530.5703125,-49520.77734375,56.8767624588714,20.5009144812248,28.224119,0,0,0,40,4449,300.2028,-49525.673828125,,,,,,,,,,,,,0,,,,-0.00245,,,,,,299.9888306,,,,
,27492349.355,299.98750305,-46652.3125,0.000126994679416018,1.08898697443826E-6,1,0.999253354069792,40.0298881530762,1.99616973748244,15.990000218153,0.00144819248182078,0.000175269229501903,0.25,-6.4964172148633E-6,0.000126995285801085,-6.41273860645864E-6,299.986969,299.9880371,-46662.33984375,-46642.28515625,56.9861904515637,20.5020109177145,28.224119,0,0,0,40,4449,300.2185,-46652.3125,,,,,,,,,,,,,0,,,,-0.00245,,,,,,299.98750305,,,,
,27492406.36,299.9898987,-43803.322265625,0.000115281428608897,1.44595738309784E-6,1,0.999253354069792,40.0298881530762,1.99607765032165,15.990000218153,0.00131693848117805,0.000145377408914577,0.25,-7.11103721313007E-6,0.000115282765697305,-7.03498824072387E-6,299.9898987,299.9898987,-43808.1171875,-43798.52734375,56.9377294833714,20.5018394171831,28.224119,0,0,0,40,4449,300.2108,-43803.322265625,,,,,,,,,,,,,0,,,,0.0049,,,,,,299.9898987,,,,
,27492465.92,299.9886169,-40825.255859375,0.00010517989180284,1.42156042995868E-6,1,0.999253354069792,40.0298881530762,1.99602701923169,15.990000218153,0.00120156161198882,0.000132353079272046,0.25,-6.51296307559861E-6,0.000105181131862703,-6.44353442810051E-6,299.9886169,299.9886169,-40835.375,-40815.13671875,56.8126689202945,20.5013526333384,28.603769,0,0,0,40,4449,300.2274,-40825.255859375,,,,,,,,,,,,,0,,,,0.00245,,,,,,299.9886169,,,,
,27492524.64,299.9908752,-37891.44921875,9.43117525419962E-5,1.05339527487192E-6,1,0.999253354069792,40.0298881530762,1.99608639912401,15.990000218153,0.00107357154236514,0.000140984788510058,0.25,-3.86670982331391E-6,9.43115557752089E-5,-3.80446992353524E-6,299.9908752,299.9908752,-37896.44140625,-37886.45703125,56.9650864815445,20.5007719472254,28.224119,0,0,0,40,4449,300.2244,-37891.44921875,,,,,,,,,,,,,0,,,,0,,,,,,299.9908752,,,,
,27492581.025,299.9937439,-35073.845703125,8.47899703845028E-5,1.31482705754187E-6,1,0.999253354069792,40.0298881530762,1.99598287083584,15.990000218153,0.000964889645365023,0.000128161238415958,0.25,-3.35101628642119E-6,8.47897004728416E-5,-3.29502882722776E-6,299.9937439,299.9937439,-35083.4921875,-35064.19921875,56.9369478548522,20.5008163406172,28.224119,0,0,0,40,4449,300.22705,-35073.845703125,,,,,,,,,,,,,0,,,,0.0049,,,,,,299.9937439,,,,
,27492585.515,299.9944153,-34848.15234375,8.2679506874236E-5,1.21342845178729E-6,1,0.999253354069792,40.0298881530762,1.99604333322657,15.990000218153,0.000943598302590973,0.000109402204294007,0.25,-4.64539234005025E-6,8.26801497619396E-5,-4.59075520527566E-6,299.9944153,299.9944153,-34852.55078125,-34843.75390625,56.7321611828137,20.5020871951792,28.224119,0,0,0,40,4449,300.22655,-34848.15234375,,,,,,,,,,,,,0,,,,0.00245,,,,,,299.9944153,,,,