File: defense/images/np_vsm/data_disorderedWafer/DD226_2_HYST_350K.DAT
[Header]
; VSM Data File (default extension .dat)
; Copyright (c) 2003-2013, Quantum Design, Inc. All rights reserved.
TITLE,
FILEOPENTIME,27362604.63,11/14/2018,12:43 am
BYAPP,VSM,2.0,2.0
INFO,PPMS VSM Option Release 1.4.10 Build 1,APPNAME
INFO,Quantum Design Linear Motor Servo Controller,MOTOR_MODULE_NAME
INFO,3101-100 M1,MOTOR_HW_VERSION
INFO,MMC1014,MOTOR_SERIAL_NUMBER
INFO,SRV No X-over 01.03.11,MOTOR_SOFTWARE_VERSION
INFO,Quantum Design VSM Detection Module,VSM_MODULE_NAME
INFO,3101-150 F0,VSM_HW_VERSION
INFO,VSM707,VSM_SERIAL_NUMBER
INFO,VSM No X-over 01.02.05 May 20 2008 13:51:47,VSM_SOFTWARE_VERSION
INFO,704,PREAMP_SERIAL_NUMBER
INFO,822,COIL_SERIAL_NUMBER
INFO,0,MOMENT_UNITS
INFO,CoFe2O4 AH11,SAMPLE_MATERIAL
INFO,Quick Dry Monolayer Conc,SAMPLE_COMMENT
INFO,27.96,SAMPLE_MASS
INFO,,SAMPLE_VOLUME
INFO,,SAMPLE_MOLECULAR_WEIGHT
INFO,,SAMPLE_SIZE
INFO,,SAMPLE_SHAPE
DATATYPE,COMMENT,1
DATATYPE,TIME,2
STARTUPAXIS,X,2
STARTUPAXIS,Y1,5
[Data]
Comment,Time Stamp (sec),Temperature (K),Magnetic Field (Oe),Moment (emu),M. Std. Err. (emu),Transport Action,Averaging Time (sec),Frequency (Hz),Peak Amplitude (mm),Center Position (mm),Coil Signal' (mV),Coil Signal" (mV),Range (mV),M. Quad. Signal (emu),M. Raw' (emu),M. Raw" (emu),Min. Temperature (K),Max. Temperature (K),Min. Field (Oe),Max. Field (Oe),Mass (grams),Motor Lag (deg),Pressure (Torr),VSM Status (code),Motor Status (code),Measure Status (code),Measure Count,PPMS Status (code),System Temp. (K),System Field (Oe),Sample Position (deg),Bridge 1 Resistance (ohms),Bridge 1 Excitation (에),Bridge 2 Resistance (ohms),Bridge 2 Excitation (에),Bridge 3 Resistance (ohms),Bridge 3 Excitation (에),Bridge 4 Resistance (ohms),Bridge 4 Excitation (에),Signal 1 Vin (V),Signal 2 Vin (V),Digital Inputs (code),Drive 1 Iout (mA),Drive 1 Ipower (W),Drive 2 Iout (mA),Drive 2 Ipower (W),Pressure (),Map 20 (),Map 21 (),Map 22 (),Map 23 (),Map 24 (),Map 25 (),Map 26 (),Map 27 (),Map 28 (),Map 29 ()
,27362621.72,350.1689453,-0.411041855812073,,,2,,,,20.2099999928474,,,,,,,350.1689453,350.1689453,-0.411041855812073,-0.411041855812073,,,27.085165,,,,-99999999,4369,350.7462,-0.411041855812073,,,,,,,,,,,,,,,,,,,,,,,350.1689453,,,,
,27362771.395,350.1622314,4478.765625,1.78696829321789E-5,2.08902897663533E-6,1,0.999253354069792,40.0298881530762,1.99694120956628,20.1999992132187,0.000211340585819589,-2.06788132217902E-5,0.25,-4.92609044455162E-6,1.78406463480884E-5,-4.9073808263875E-6,350.1622314,350.1622314,4471.18115234375,4486.35009765625,56.4070037188137,20.5777821324572,27.085165,0,0,0,40,4449,350.4778,4478.765625,,,,,,,,,,,,,0,,,,-0.0049,,,,,,350.1622314,,,,
,27362867.965,350.10301205,9307.2666015625,3.06411504974623E-6,5.88593855967295E-7,1,0.999253354069792,40.0298881530762,1.99686564894753,20.1999992132187,3.62159829674237E-5,-3.42234149468028E-6,0.25,-8.3374951034047E-7,3.05913603385731E-6,-8.30563258459069E-7,350.1029968,350.1030273,9297.1923828125,9317.3408203125,56.3007022401983,20.5824488479425,27.085165,0,0,0,40,4449,350.4158,9307.2666015625,,,,,,,,,,,,,0,,,,0.00245,,,,,,350.10301205,,,,
,27362967.4,350.0579529,14274.9184570312,-1.48008108120234E-5,7.77398762710131E-7,1,0.999253354069792,40.0298881530762,1.99678580676375,20.1999992132187,-0.000159120182799313,-7.47773186752552E-5,0.25,-4.06221457693791E-6,-1.47722828206652E-5,-4.06323626468198E-6,350.0575867,350.0583191,14269.974609375,14279.8623046875,56.4468667732944,20.5861263180984,27.844467,0,0,0,40,4449,350.3916,14274.9184570312,,,,,,,,,,,,,0,,,,0.0049,,,,,,350.0579529,,,,
,27363063.465,350.032135,19076.998046875,-3.07027411031449E-5,9.4569711964364E-7,1,0.999253354069792,40.0298881530762,1.99664011115235,20.1999992132187,-0.000337759503017087,-0.000110614490912852,0.25,-4.48450773420858E-6,-3.06457845210868E-5,-4.49361595526413E-6,350.032135,350.032135,19071.84375,19082.15234375,56.546915223756,20.5888002439505,27.844467,0,0,0,40,4449,350.37165,19076.998046875,,,,,,,,,,,,,0,,,,0.00245,,,,,,350.032135,,,,
,27363163.18,350.0010071,24059.6416015625,-4.78490403031744E-5,1.02599032671311E-6,1,0.999253354069792,40.0298881530762,1.99657142357109,20.1999992132187,-0.000530837219243043,-0.000146574631803991,0.25,-4.70220918715241E-6,-4.77616010823171E-5,-4.72044100614099E-6,350.0010071,350.0010071,24049.6875,24069.595703125,56.5633294226598,20.593076367423,27.464817,0,0,0,40,4449,350.41075,24059.6416015625,,,,,,,,,,,,,0,,,,0,,,,,,350.0010071,,,,
,27363261.995,349.9830627,28999.3623046875,-6.46360870567113E-5,1.46209430643529E-6,1,0.999253354069792,40.0298881530762,1.9965251927067,20.1999992132187,-0.000713556298426487,-0.000218213546086264,0.25,-8.14355220061826E-6,-6.45170216347813E-5,-8.1649791719046E-6,349.9830627,349.9830627,28992.251953125,29006.47265625,56.6242964471598,20.5898563886023,27.464817,0,0,0,40,4449,350.4097,28999.3623046875,,,,,,,,,,,,,0,,,,0,,,,,,349.9830627,,,,
,27363360.665,349.9753723,33932.27734375,-8.20458551053881E-5,1.87640289161926E-6,1,0.999253354069792,40.0298881530762,1.99633890796063,20.1999992132187,-0.000907733122321504,-0.000265065614330464,0.25,-9.28260984558958E-6,-8.18953334136203E-5,-9.31163817910194E-6,349.9753723,349.9753723,33925.0859375,33939.46875,56.7149653553906,20.5921828946876,27.844467,0,0,0,40,4449,350.42395,33932.27734375,,,,,,,,,,,,,0,,,,0.00245,,,,,,349.9753723,,,,
,27363458.145,349.9813843,38802.326171875,-9.72258012445218E-5,1.96359194557251E-6,1,0.999253354069792,40.0298881530762,1.99624266898295,20.1999992132187,-0.00107802390884913,-0.000300269083799793,0.25,-9.77504909890562E-6,-9.70480983270219E-5,-9.81156764989283E-6,349.9813843,349.9813843,38792.234375,38812.41796875,56.5750538504483,20.5894322822482,28.224119,0,0,0,40,4449,350.4367,38802.326171875,,,,,,,,,,,,,0,,,,0,,,,,,349.9813843,,,,
,27363557.8,349.9779968,43781.822265625,-0.000115714877527896,1.95325776247561E-6,1,0.999253354069792,40.0298881530762,1.9962634887416,20.1999992132187,-0.00128465693435965,-0.000348040084857809,0.25,-1.08068627772045E-5,-0.000115503863151904,-1.08517314312755E-5,349.9779968,349.9779968,43774.41015625,43789.234375,56.6305494753137,20.5937564456112,27.844467,0,0,0,40,4449,350.4507,43781.822265625,,,,,,,,,,,,,0,,,,0,,,,,,349.9779968,,,,
,27363657.915,349.9889832,48785.123046875,-0.000129705703208447,2.25529011330669E-6,1,0.999253354069792,40.0298881530762,1.99648605484453,20.1999992132187,-0.00145782022200706,-0.000288020822536266,0.25,-3.06296484092347E-6,-0.000129474141621122,-3.12922219570642E-6,349.9889832,349.9889832,48777.56640625,48792.6796875,56.709493955756,20.5880435937843,27.844467,0,0,0,40,4449,350.4693,48785.123046875,,,,,,,,,,,,,0,,,,0.00245,,,,,,349.9889832,,,,
,27363758.71,349.9998169,53825.015625,-0.000149612980780839,2.24778041884708E-6,1,0.999253354069792,40.0298881530762,1.99645182420175,20.1999992132187,-0.00165895223313736,-0.000462669391938781,0.25,-1.50921980284286E-5,-0.000149339449051103,-1.51480590644603E-5,349.9998169,349.9998169,53820.125,53829.90625,56.7391958394868,20.5905359376,27.464817,0,0,0,40,4449,350.4448,53825.015625,,,,,,,,,,,,,0,,,,-0.00245,,,,,,349.9998169,,,,
,27363857.08,349.9960938,58742.7890625,-0.000165343844196857,2.72034077497007E-6,1,0.999253354069792,40.0298881530762,1.99630123837362,20.1999992132187,-0.00183075373377935,-0.000525691139106128,0.25,-1.795625583341E-5,-0.000165040885706002,-1.80156322484335E-5,349.9960938,349.9960938,58707.83984375,58777.73828125,56.8173586914099,20.592583623395,27.844467,0,0,0,40,4449,350.479,58742.7890625,,,,,,,,,,,,,0,,,,0,,,,,,349.9960938,,,,
,27363959.775,349.9910583,63875.412109375,-0.000185577907648592,2.6772572727005E-6,1,0.999253354069792,40.0298881530762,1.99632701916216,20.1999992132187,-0.00205693853563214,-0.000577790961620794,0.25,-1.90691730809166E-5,-0.000185238523032622,-1.91376356609447E-5,349.9910583,349.9910583,63870.6015625,63880.22265625,56.6102271338137,20.5921210413779,27.464817,0,0,0,40,4449,350.4827,63875.412109375,,,,,,,,,,,,,0,,,,0.00245,,,,,,349.9910583,,,,
,27364060.19,349.9986267,68893.0234375,-0.000201160372722489,2.81869488783642E-6,1,0.999253354069792,40.0298881530762,1.99621245271061,20.1999992132187,-0.00223077653548519,-0.000619081409713604,0.25,-2.00332346636363E-5,-0.000200792810079846,-2.01084589582058E-5,349.9986267,349.9986267,68882.90625,68903.140625,56.7329428113329,20.5916477598167,27.464817,0,0,0,40,4449,350.4782,68893.0234375,,,,,,,,,,,,,0,,,,0.00245,,,,,,349.9986267,,,,
,27364160.405,350.0021667,73903.16015625,-0.000215055792145717,2.79315638805851E-6,1,0.999253354069792,40.0298881530762,1.99613895779626,20.1999992132187,-0.00237917084780158,-0.000694255561119884,0.25,-2.42915470847713E-5,-0.000214661254495522,-2.43667492225408E-5,350.0021667,350.0021667,73895.640625,73910.6796875,56.282724784256,20.5892822350626,28.224119,0,0,0,40,4449,350.4768,73903.16015625,,,,,,,,,,,,,0,,,,0,,,,,,350.0021667,,,,
,27364262.46,350.0068054,79003.5625,-0.000231925266837739,2.75450968079022E-6,1,0.999253354069792,40.0298881530762,1.99614273679986,20.1999992132187,-0.00257084884482193,-0.000719573530956463,0.25,-2.36144823599088E-5,-0.000231501188266713,-2.37000240386102E-5,350.0065002,350.0071106,78993.4609375,79013.6640625,56.6868267286983,20.5937154751256,28.224119,0,0,0,40,4449,350.47265,79003.5625,,,,,,,,,,,,,0,,,,-0.0049,,,,,,350.0068054,,,,
,27364365.4,350.0111389,84149.515625,-0.000253015849874516,3.06293623015524E-6,1,0.999253354069792,40.0298881530762,1.9960845821297,20.1999992132187,-0.00280387957241275,-0.000788894005132451,0.25,-2.610827386173E-5,-0.000252553005336985,-2.62008330912398E-5,350.0111389,350.0111389,84141.9453125,84157.0859375,56.5328459104098,20.5939716852131,27.844467,0,0,0,40,4449,350.45605,84149.515625,,,,,,,,,,,,,0,,,,0,,,,,,350.0111389,,,,
,27364460.815,350.0098877,88920.1328125,-0.000264628266637826,3.82169062086094E-6,1,0.999253354069792,40.0298881530762,1.99616811198327,20.1999992132187,-0.0029310424775593,-0.000834614839925662,0.25,-2.8146883350878E-5,-0.000264143755720942,-2.82420580268366E-5,350.0098877,350.0098877,88915.171875,88925.09375,56.343691808756,20.5944378517642,27.844467,0,0,0,40,4449,350.44965,88920.1328125,,,,,,,,,,,,,0,,,,0,,,,,,350.0098877,,,,
,27364575.455,350.0090027,86321.28515625,-0.000259222286325501,3.05321210792687E-6,1,0.999253354069792,40.0298881530762,1.99603792347772,20.1999992132187,-0.00287450389696531,-0.000797199669910844,0.25,-2.57713994864647E-5,-0.000258748654201606,-2.58679011457189E-5,350.0090027,350.0090027,86318.7578125,86323.8125,56.4335790884675,20.5944932218761,28.603769,0,0,0,40,4449,350.4485,86321.28515625,,,,,,,,,,,,,0,,,,-0.0049,,,,,,350.0090027,,,,
,27364675.545,349.9982605,81320.2890625,-0.000238194430675866,3.51119577861812E-6,1,0.999253354069792,40.0298881530762,1.9961798189355,20.1999992132187,-0.00263318026871218,-0.000780672496614554,0.25,-2.79426050200632E-5,-0.000237756941677923,-2.802386981339E-5,349.9982605,349.9982605,81315.15625,81325.421875,56.7282530402175,20.5944760718788,28.603769,0,0,0,40,4449,350.45455,81320.2890625,,,,,,,,,,,,,0,,,,0,,,,,,349.9982605,,,,
,27364774.85,349.9963379,76353.87890625,-0.000210503596527273,3.81726127578996E-6,1,0.999253354069792,40.0298881530762,1.99595047752065,20.1999992132187,-0.00232741933837422,-0.000686320159042656,0.25,-2.43819918250735E-5,-0.000210117129097326,-2.44544836686549E-5,349.9963379,349.9963379,76346.4375,76361.3203125,56.7407590965252,20.5880065209653,28.224119,0,0,0,40,4449,350.45495,76353.87890625,,,,,,,,,,,,,0,,,,0,,,,,,349.9963379,,,,
,27364875.67,349.990448,71312.84765625,-0.00019043358559018,2.64322994333954E-6,1,0.999253354069792,40.0298881530762,1.99608480211963,20.1999992132187,-0.00211477867310788,-0.000568213083916927,0.25,-1.73856678320628E-5,-0.000190086552815164,-1.74596379385634E-5,349.990448,349.990448,71307.6015625,71318.09375,56.5766171074867,20.5906612251693,28.224119,0,0,0,40,4449,350.46125,71312.84765625,,,,,,,,,,,,,0,,,,0.0049,,,,,,349.990448,,,,
,27364974.765,349.9888306,66362.75,-0.000172752553564804,3.63217681694368E-6,1,0.999253354069792,40.0298881530762,1.99625169168552,20.1999992132187,-0.00190779004366639,-0.000577830123300823,0.25,-2.12951799582789E-5,-0.000172434693956558,-2.13525834366637E-5,349.9888306,349.9888306,66355.2578125,66370.2421875,56.811105663256,20.5877962638008,28.224119,0,0,0,40,4449,350.4877,66362.75,,,,,,,,,,,,,0,,,,0,,,,,,349.9888306,,,,
,27365075.195,349.98345945,61341.77734375,-0.00015788939661948,2.72009942645657E-6,1,0.999253354069792,40.0298881530762,1.99616935039005,20.1999992132187,-0.00174006833451033,-0.000548378793360339,0.25,-2.12605461932129E-5,-0.000157597904263817,-2.13099198924669E-5,349.9828491,349.9840698,61331.83203125,61351.72265625,56.7860935506406,20.5880919216806,28.224119,0,0,0,40,4449,350.47405,61341.77734375,,,,,,,,,,,,,0,,,,0,,,,,,349.98345945,,,,
,27365174.5,349.993042,56376.68359375,-0.00014068771093636,2.08972127120022E-6,1,0.999253354069792,40.0298881530762,1.99598984324776,20.1999992132187,-0.00155558457141169,-0.000458406978243474,0.25,-1.62688938191432E-5,-0.000140429391296221,-1.63176973111258E-5,349.993042,349.993042,56374.28515625,56379.08203125,56.4077853473329,20.5903821147107,28.603769,0,0,0,40,4449,350.4849,56376.68359375,,,,,,,,,,,,,0,,,,0.0049,,,,,,349.993042,,,,
,27365273.145,349.9870605,51446.669921875,-0.000124520907708068,1.89695837442604E-6,1,0.999253354069792,40.0298881530762,1.99607168885609,20.1999992132187,-0.0013697900091611,-0.000446706709993374,0.25,-1.80295047314305E-5,-0.000124290280240305,-1.80663327501122E-5,349.9870605,349.9870605,51436.140625,51457.19921875,56.5289377678137,20.5926851452074,28.224119,0,0,0,40,4449,350.5001,51446.669921875,,,,,,,,,,,,,0,,,,0,,,,,,349.9870605,,,,
,27365372.785,349.9908752,46466.5625,-0.000106878094800852,2.24047232997426E-6,1,0.999253354069792,40.0298881530762,1.99613557006047,20.1999992132187,-0.00117461928919259,-0.000389934845290741,0.25,-1.60517281540066E-5,-0.000106679799940622,-1.60823651371893E-5,349.9908752,349.9908752,46459.2109375,46473.9140625,56.4851665707367,20.5825129703089,28.224119,0,0,0,40,4449,350.52915,46466.5625,,,,,,,,,,,,,0,,,,-0.00245,,,,,,349.9908752,,,,
,27365471.76,349.9825134,41518.947265625,-9.09365792686106E-5,2.03700504507133E-6,1,0.999253354069792,40.0298881530762,1.99616766275767,20.1999992132187,-0.00100354985278862,-0.000308003490297396,0.25,-1.15504463804631E-5,-9.07690422487159E-5,-1.15802981478109E-5,349.9825134,349.9825134,41511.36328125,41526.53125,56.4476484018137,20.5866590527178,28.983419,0,0,0,40,4449,350.52585,41518.947265625,,,,,,,,,,,,,0,,,,-0.0049,,,,,,349.9825134,,,,
,27365570.43,349.9884644,36588.845703125,-7.78519851075994E-5,1.48237019343682E-6,1,0.999253354069792,40.0298881530762,1.99638161995904,20.1999992132187,-0.000857486602971397,-0.000273837388796719,0.25,-1.07856275073694E-5,-7.77080339009649E-5,-1.0809631454452E-5,349.9884644,349.9884644,36579.01953125,36598.671875,56.7829670365637,20.5872544162542,28.224119,0,0,0,40,4449,350.5194,36588.845703125,,,,,,,,,,,,,0,,,,0,,,,,,349.9884644,,,,
,27365666.675,349.9787598,31778.986328125,-6.03586998291513E-5,1.57242653210378E-6,1,0.999253354069792,40.0298881530762,1.99641184222415,20.1999992132187,-0.000663806866532657,-0.000218159143822091,0.25,-8.88042815288211E-6,-6.02468207493558E-5,-8.89815071401323E-6,349.9787598,349.9787598,31771.46484375,31786.5078125,56.6680676442368,20.5862068323221,28.603769,0,0,0,40,4449,350.52495,31778.986328125,,,,,,,,,,,,,0,,,,0.0049,,,,,,349.9787598,,,,
,27365764.695,349.9849548,26879.2744140625,-4.69831103437462E-5,1.76351047327793E-6,1,0.999253354069792,40.0298881530762,1.99642337504953,20.1999992132187,-0.000516063319740721,-0.000173543692020093,0.25,-7.24284018453613E-6,-4.6895826079573E-5,-7.25606936766311E-6,349.9849548,349.9849548,26874.103515625,26884.4453125,56.7180918694675,20.5888198168176,28.603769,0,0,0,40,4449,350.54025,26879.2744140625,,,,,,,,,,,,,0,,,,0.00245,,,,,,349.9849548,,,,
,27365861.815,349.9880676,22023.845703125,-3.29483182757463E-5,1.187582980887E-6,1,0.999253354069792,40.0298881530762,1.99649116688936,20.1999992132187,-0.000358100845147847,-0.000143743802656561,0.25,-7.03192154544301E-6,-3.28860166365842E-5,-7.03775173178592E-6,349.9880676,349.9880676,22016.671875,22031.01953125,56.5742722219291,20.5903895090001,28.983419,0,0,0,40,4449,350.54975,22023.845703125,,,,,,,,,,,,,0,,,,-0.00245,,,,,,349.9880676,,,,
,27365956.955,349.9930725,17269.3173828125,-1.68230174258577E-5,1.06989772525784E-6,1,0.999253354069792,40.0298881530762,1.99645315348709,20.1999992132187,-0.000180540374834354,-8.66657455690374E-5,0.25,-4.76654952401131E-6,-1.67905486169652E-5,-4.76744773995677E-6,349.9930725,349.9930725,17264.2265625,17274.408203125,57.1034347294484,20.5903845570967,28.603769,0,0,0,40,4449,350.55815,17269.3173828125,,,,,,,,,,,,,0,,,,0,,,,,,349.9930725,,,,
,27366054.59,349.993927,12389.2080078125,-2.67946975642874E-6,6.87677500977495E-7,1,0.999253354069792,40.0298881530762,1.99656269003879,20.1999992132187,-2.38225184302132E-5,-4.23019446946388E-5,0.25,-3.28422980691387E-6,-2.67289383353872E-6,-3.27989789038957E-6,349.993927,349.993927,12386.6279296875,12391.7880859375,56.8767624588714,20.5881292512422,28.983419,0,0,0,40,4449,350.5616,12389.2080078125,,,,,,,,,,,,,0,,,,0,,,,,,349.993927,,,,
,27366150.29,349.9942017,7606.36596679688,1.14128340607557E-5,5.29544870731336E-7,1,0.999253354069792,40.0298881530762,1.996590645791,20.1999992132187,0.000132969950439261,-1.74007730945252E-6,0.25,-2.1303195996819E-6,1.13937879676148E-5,-2.12019299144207E-6,349.9942017,349.9942017,7593.8427734375,7618.88916015625,56.6117903908521,20.5899729946125,28.983419,0,0,0,40,4449,350.5621,7606.36596679688,,,,,,,,,,,,,0,,,,0,,,,,,349.9942017,,,,
,27366244.635,349.9868469,2891.25305175781,2.09418770525722E-5,5.41494088654081E-7,1,0.999253354069792,40.0298881530762,1.99656829178514,20.1999992132187,0.00023939522769282,2.33402567228943E-5,0.25,-1.55804176722489E-6,2.09056256853257E-5,-1.54362188024192E-6,349.9868469,349.9868469,2886.32250976562,2896.18359375,56.7157469839098,20.5911933740114,28.603769,0,0,0,40,4449,350.58385,2891.25305175781,,,,,,,,,,,,,0,,,,0,,,,,,349.9868469,,,,
,27366336.785,349.9906006,-1711.84552001953,-2.02827644505843E-5,5.34797488040187E-7,1,0.999253354069792,40.0298881530762,1.99642010464844,20.1999992132187,-0.000228552795714374,-4.16128123972826E-5,0.25,-1.75386306344565E-7,-2.02467135566834E-5,-1.863693295442E-7,349.9906006,349.9906006,-1719.34985351562,-1704.34118652344,56.8580033744099,20.5915759847413,29.363071,0,0,0,40,4449,350.5482,-1711.84552001953,,,,,,,,,,,,,0,,,,-0.00245,,,,,,349.9906006,,,,
,27366432.015,349.9992065,-6471.62915039063,-1.37542325079318E-5,6.05668267155375E-7,1,0.999253354069792,40.0298881530762,1.99641531885567,20.1999992132187,-0.000157182301063419,-1.5538744699718E-5,0.25,1.00464343161862E-6,-1.37304071758897E-5,9.95208119679493E-7,349.9992065,349.9992065,-6481.361328125,-6461.89697265625,56.7649895806214,20.5909185731158,28.983419,0,0,0,40,4449,350.558,-6471.62915039063,,,,,,,,,,,,,0,,,,0,,,,,,349.9992065,,,,
,27366528.51,349.9937134,-11294.9287109375,-1.2344643227089E-6,5.96018527507306E-7,1,0.999253354069792,40.0298881530762,1.9963802247945,20.1999992132187,-2.01625579825397E-5,3.35774587163211E-5,0.25,3.18915212323444E-6,-1.23404954046481E-6,3.1828123828869E-6,349.9937134,349.9937134,-11299.966796875,-11289.890625,56.7204367550252,20.5910685470607,28.983419,0,0,0,40,4449,350.5769,-11294.9287109375,,,,,,,,,,,,,0,,,,0,,,,,,349.9937134,,,,
,27366624.655,350.0036926,-16100.240234375,1.26702165827276E-5,1.0826896343986E-6,1,0.999253354069792,40.0298881530762,1.99646310820298,20.1999992132187,0.000135186867352866,6.9819268827054E-5,0.25,3.99281199089314E-6,1.26455340135943E-5,3.99277377107945E-6,350.0036926,350.0036926,-16107.8662109375,-16092.6142578125,56.8267382336406,20.5932557602466,28.983419,0,0,0,40,4449,350.57655,-16100.240234375,,,,,,,,,,,,,0,,,,0.0049,,,,,,350.0036926,,,,
,27366722.135,350.0083313,-20972.2470703125,2.62219135817265E-5,1.13369958651636E-6,1,0.999253354069792,40.0298881530762,1.99641973688276,20.1999992132187,0.000285924944252155,0.000108963471377761,0.25,5.11510062841663E-6,2.61725796000437E-5,5.12059186166427E-6,350.0076294,350.0090332,-20979.697265625,-20964.796875,57.0127658212176,20.5944562373924,28.983419,0,0,0,40,4449,350.5659,-20972.2470703125,,,,,,,,,,,,,0,,,,-0.0049,,,,,,350.0083313,,,,
,27366819.41,350.0078125,-25834.3564453125,4.25621421338623E-5,1.22819734783616E-6,1,0.999253354069792,40.0298881530762,1.99672026155268,20.1999992132187,0.000467005012969467,0.00016049497990604,0.25,6.85005422558194E-6,4.24828773544483E-5,6.86152437142271E-6,350.0078125,350.0078125,-25846.865234375,-25821.84765625,57.0534105042176,20.5912067134241,28.983419,0,0,0,40,4449,350.56065,-25834.3564453125,,,,,,,,,,,,,0,,,,-0.0049,,,,,,350.0078125,,,,
,27366916.66,350.0144958,-30694.3837890625,5.77351023306348E-5,1.32248521831127E-6,1,0.999253354069792,40.0298881530762,1.9967017415913,20.1999992132187,0.000637096815320536,0.000196829419607828,0.25,7.44223653291848E-6,5.76285988969296E-5,7.46104907323694E-6,350.0144958,350.0144958,-30699.26953125,-30689.498046875,56.851750346256,20.5889361584131,28.983419,0,0,0,40,4449,350.53855,-30694.3837890625,,,,,,,,,,,,,0,,,,0.0049,,,,,,350.0144958,,,,
,27367016.75,350.0188599,-35696.37109375,7.31948116356515E-5,1.42362598226534E-6,1,0.999253354069792,40.0298881530762,1.99668897312239,20.1999992132187,0.000807668860625086,0.000249637877578768,0.25,9.4443841905045E-6,7.30597809669929E-5,9.46818172031566E-6,350.0188599,350.0188599,-35696.37109375,-35696.37109375,57.1440794124484,20.5895269137162,29.363071,0,0,0,40,4449,350.5268,-35696.37109375,,,,,,,,,,,,,0,,,,0.00245,,,,,,350.0188599,,,,
,27367113.735,350.0158386,-40544.109375,8.63664557781768E-5,1.98166133721654E-6,1,0.999253354069792,40.0298881530762,1.99680112360677,20.1999992132187,0.000954631597172249,0.000285516278561591,0.25,1.03412472711761E-5,8.62075873603099E-5,1.03707110216959E-5,350.0158386,350.0158386,-40554.0390625,-40534.1796875,56.9682129956214,20.5888916842835,29.363071,0,0,0,40,4449,350.51675,-40544.109375,,,,,,,,,,,,,0,,,,-0.00245,,,,,,350.0158386,,,,
,27367210.495,350.0143433,-45381.486328125,0.000102579574200887,2.02523736991623E-6,1,0.999253354069792,40.0298881530762,1.99672270656186,20.1999992132187,0.00113859919075023,0.000311368569334361,0.25,9.82545459863434E-6,0.000102392255851024,9.86475750016428E-6,350.0143433,350.0143433,-45391.5078125,-45371.46484375,57.0158923352945,20.5879501200888,29.363071,0,0,0,40,4449,350.506,-45381.486328125,,,,,,,,,,,,,0,,,,0,,,,,,350.0143433,,,,
,27367304.775,350.0118713,-50091.494140625,0.000117926392251322,2.13970056447847E-6,1,0.999253354069792,40.0298881530762,1.99669672136146,20.1999992132187,0.00130632126812267,0.000373001213546478,0.25,1.26292275039525E-5,0.00011771033251161,1.26719876123331E-5,350.0118713,350.0118713,-50123.9765625,-50059.01171875,56.9627415959868,20.5907607177257,29.363071,0,0,0,40,4449,350.51015,-50091.494140625,,,,,,,,,,,,,0,,,,-0.00245,,,,,,350.0118713,,,,
,27367403.99,350.0035706,-55050.775390625,0.000131572706605219,2.28620916223829E-6,1,0.999253354069792,40.0298881530762,1.99682365223079,20.1999992132187,0.00146283248568121,0.000385833139605358,0.25,1.14012988354258E-5,0.000131333178195136,1.14537118753085E-5,350.0035706,350.0035706,-55060.765625,-55040.78515625,57.0909286731407,20.5903789863212,29.363071,0,0,0,40,4449,350.49515,-55050.775390625,,,,,,,,,,,,,0,,,,0,,,,,,350.0035706,,,,
,27367502.225,350.0145569,-59960.53125,0.000150149507941634,2.33617109976039E-6,1,0.999253354069792,40.0298881530762,1.99682489021203,20.1999992132187,0.00166707804899439,0.000453551391097844,0.25,1.41843126437126E-5,0.000149875470262607,1.42419639517178E-5,350.0145569,350.0145569,-59962.90234375,-59958.16015625,56.9697762526599,20.5908625784442,28.983419,0,0,0,40,4449,350.4816,-59960.53125,,,,,,,,,,,,,0,,,,0,,,,,,350.0145569,,,,
,27367600.28,350.0136414,-64860.435546875,0.0001629353578615,2.27959423595474E-6,1,0.999253354069792,40.0298881530762,1.99672091622347,20.1999992132187,0.001810567658382,0.000482788283189207,0.25,1.45629270735125E-5,0.000162638461306073,1.46268722221514E-5,350.0136414,350.0136414,-64870.53515625,-64850.3359375,56.9643048530253,20.5921223322533,29.363071,0,0,0,40,4449,350.4744,-64860.435546875,,,,,,,,,,,,,0,,,,0,,,,,,350.0136414,,,,
,27367698.865,350.0106812,-69787.48046875,0.000179906741856276,2.43138667406901E-6,1,0.999253354069792,40.0298881530762,1.99650552835181,20.1999992132187,0.00200307060318157,0.000509230006064838,0.25,1.39718503576323E-5,0.000179580114533024,1.40460985262541E-5,350.0106812,350.0106812,-69797.5078125,-69777.453125,56.946327397083,20.5946768123262,29.363071,0,0,0,40,4449,350.46425,-69787.48046875,,,,,,,,,,,,,0,,,,0,,,,,,350.0106812,,,,
,27367799.345,350.0175781,-74809.06640625,0.0001932131593076,2.92803660743649E-6,1,0.999253354069792,40.0298881530762,1.99662122409935,20.1999992132187,0.00215137643411046,0.0005467259852556,0.25,1.49877878689757E-5,0.000192862354819561,1.50674474567901E-5,350.0175781,350.0175781,-74824.0390625,-74794.09375,57.1511140691214,20.5941857060479,29.742722,0,0,0,40,4449,350.4573,-74809.06640625,,,,,,,,,,,,,0,,,,0.00245,,,,,,350.0175781,,,,
,27367897.835,350.0209656,-79728.5859375,0.000211161459364783,3.11504195473493E-6,1,0.999253354069792,40.0298881530762,1.99665163883405,20.1999992132187,0.00235978248529873,0.000548300148295223,0.25,1.20190354596755E-5,0.000210780456294424,1.21137095952253E-5,350.0209656,350.0209656,-79735.953125,-79721.21875,56.8251749766022,20.5964596667124,28.983419,0,0,0,40,4449,350.44805,-79728.5859375,,,,,,,,,,,,,0,,,,0.00245,,,,,,350.0209656,,,,
,27367994.69,350.0132446,-84570.87890625,0.000223381143692907,3.14401204381001E-6,1,0.999253354069792,40.0298881530762,1.99662594216672,20.1999992132187,0.00248966680441857,0.000618395087817574,0.25,1.61145760158412E-5,0.000222976300912929,1.62085837971822E-5,350.0132446,350.0132446,-84578.40625,-84563.3515625,57.078422616833,20.5990774849647,29.363071,0,0,0,40,4449,350.43585,-84570.87890625,,,,,,,,,,,,,0,,,,-0.0049,,,,,,350.0132446,,,,
,27368089.5,350.0246887,-89307.52734375,0.000236671941754804,3.26401731152148E-6,1,0.999253354069792,40.0298881530762,1.9963874255786,20.1999992132187,0.00263791710890715,0.000652682473341476,0.25,1.6858059449771E-5,0.000236243056448177,1.69579114698898E-5,350.0246887,350.0246887,-89314.9453125,-89300.109375,57.3605905122753,20.6006342924431,29.363071,0,0,0,40,4449,350.41745,-89307.52734375,,,,,,,,,,,,,0,,,,0,,,,,,350.0246887,,,,
,27368202.735,350.0076599,-85990.07421875,0.000229481676618156,2.64674377613729E-6,1,0.999253354069792,40.0298881530762,1.99652012575355,20.1999992132187,0.00256439343272083,0.000595615112468484,0.25,1.3042632822983E-5,0.000229067751590352,1.31454091502504E-5,350.0076599,350.0076599,-86000.34375,-85979.8046875,57.1073428720445,20.5939145622921,30.122374,0,0,0,40,4449,350.40515,-85990.07421875,,,,,,,,,,,,,0,,,,0,,,,,,350.0076599,,,,
,27368301.375,349.9960327,-81058.4453125,0.000218096190768298,3.115533916873E-6,1,0.999253354069792,40.0298881530762,1.99665764505802,20.1999992132187,0.00242681292198095,0.000626813850167294,0.25,1.77745881438471E-5,0.000217699918176456,1.78628561925369E-5,349.9951782,349.9968872,-81063.5546875,-81053.3359375,56.9377294833714,20.5986588093653,29.742722,0,0,0,40,4449,350.42345,-81058.4453125,,,,,,,,,,,,,0,,,,0,,,,,,349.9960327,,,,
,27368402.11,349.9946594,-76025.80078125,0.000198348698763452,2.15206090475829E-6,1,0.999253354069792,40.0298881530762,1.99636385838084,20.1999992132187,0.00221089054786643,0.000546165569793368,0.25,1.40548778860143E-5,0.000197989457736821,1.41390102269686E-5,349.9946594,349.9946594,-76035.96875,-76015.6328125,57.0229269919676,20.5981929678899,29.742722,0,0,0,40,4449,350.41865,-76025.80078125,,,,,,,,,,,,,0,,,,0.00245,,,,,,349.9946594,,,,
,27368501.985,349.991394,-71033.5234375,0.000183224582816777,2.22912003437101E-6,1,0.999253354069792,40.0298881530762,1.99663611646884,20.1999992132187,0.00204209466507772,0.000507364457128438,0.25,1.322926160112E-5,0.000182892603938628,1.33066453875463E-5,349.991394,349.991394,-71038.4296875,-71028.6171875,56.9807190519291,20.5955855507635,29.742722,0,0,0,40,4449,350.42795,-71033.5234375,,,,,,,,,,,,,0,,,,0,,,,,,349.991394,,,,
,27368601.86,349.9888611,-66041.421875,0.000162359371572189,2.05380717039816E-6,1,0.999253354069792,40.0298881530762,1.99652992039654,20.1999992132187,0.0018100773785241,0.000445961340373944,0.25,1.14034253843086E-5,0.000162065374450097,1.14726519445625E-5,349.9888611,349.9888611,-66051.4765625,-66031.3671875,56.9775925378522,20.5951099750633,29.742722,0,0,0,40,4449,350.4386,-66041.421875,,,,,,,,,,,,,0,,,,-0.0049,,,,,,349.9888611,,,,
,27368699.44,349.9899597,-61166.55859375,0.000151068173050489,2.06740538829756E-6,1,0.999253354069792,40.0298881530762,1.99656080604017,20.1999992132187,0.0016784659051078,0.000448192628234424,0.25,1.35554831236622E-5,0.000150792980356929,1.36147576553552E-5,349.9899597,349.9899597,-61178.8671875,-61154.25,56.9799374234099,20.5957764291586,29.742722,0,0,0,40,4449,350.4367,-61166.55859375,,,,,,,,,,,,,0,,,,-0.00245,,,,,,349.9899597,,,,
,27368797.695,349.9872131,-56254.740234375,0.000138466662974903,2.28485550804881E-6,1,0.999253354069792,40.0298881530762,1.99665251839762,20.1999992132187,0.0015341284347484,0.000436201208998685,0.25,1.46731066547487E-5,0.000138213185617419,1.47235263355176E-5,349.9872131,349.9872131,-56262.3046875,-56247.17578125,57.0237086204868,20.5956224609943,29.742722,0,0,0,40,4449,350.44275,-56254.740234375,,,,,,,,,,,,,0,,,,0.0049,,,,,,349.9872131,,,,
,27368895.68,349.9867554,-51357.640625,0.000121622258829917,1.50495581307876E-6,1,0.999253354069792,40.0298881530762,1.9965397762384,20.1999992132187,0.00135049028438337,0.00036544068876466,0.25,1.13218488294902E-5,0.000121400473001972,1.13689710675264E-5,349.9867554,349.9867554,-51360.33984375,-51354.94140625,56.9353845978137,20.5950457183149,29.742722,0,0,0,40,4449,350.462,-51357.640625,,,,,,,,,,,,,0,,,,0,,,,,,349.9867554,,,,
,27368996.785,349.9802246,-46305.6171875,0.000105965858660908,1.85851157333147E-6,1,0.999253354069792,40.0298881530762,1.99663369675641,20.1999992132187,0.00117276854431143,0.000341089071847156,0.25,1.18735800937858E-5,0.00010577152643222,1.19111328191706E-5,349.9802246,349.9802246,-46313.1171875,-46298.1171875,56.8204852054868,20.5947492036456,29.742722,0,0,0,40,4449,350.4735,-46305.6171875,,,,,,,,,,,,,0,,,,0,,,,,,349.9802246,,,,
,27369095.665,349.9906311,-41363.0546875,9.04402993635465E-5,1.90029474179283E-6,1,0.999253354069792,40.0298881530762,1.99653010932344,20.1999992132187,0.00100220600586693,0.000283503314907326,0.25,9.46076590344793E-6,9.02747718538809E-5,9.49405165116484E-6,349.9906311,349.9906311,-41370.6171875,-41355.4921875,57.085457273506,20.5920801343637,30.122374,0,0,0,40,4449,350.47745,-41363.0546875,,,,,,,,,,,,,0,,,,-0.0049,,,,,,349.9906311,,,,
,27369194.555,349.9882813,-36420.90625,7.50945270464385E-5,1.37363315226774E-6,1,0.999253354069792,40.0298881530762,1.99663206240571,20.1999992132187,0.000829629323751161,0.000250221052740419,0.25,9.1677017767116E-6,7.49563584020927E-5,9.1930513422511E-6,349.9882813,349.9882813,-36428.51953125,-36413.29296875,56.7657712091406,20.5912495058786,29.742722,0,0,0,40,4449,350.4838,-36420.90625,,,,,,,,,,,,,0,,,,-0.00245,,,,,,349.9882813,,,,
,27369291.455,349.9882813,-31579.3837890625,5.87258206097604E-5,1.24557203938091E-6,1,0.999253354069792,40.0298881530762,1.99657562974835,20.1999992132187,0.000647413480021467,0.000203528904545137,0.25,7.86533770462554E-6,5.86173778727549E-5,7.883955881728E-6,349.9882813,349.9882813,-31581.802734375,-31576.96484375,56.9963516223137,20.5921137465249,29.742722,0,0,0,40,4449,350.487,-31579.3837890625,,,,,,,,,,,,,0,,,,-0.0049,,,,,,349.9882813,,,,
,27369392.405,349.9852295,-26531.673828125,4.39363201974163E-5,1.37291083714221E-6,1,0.999253354069792,40.0298881530762,1.99658016352479,20.1999992132187,0.000480428208666022,0.000175038053018865,0.25,7.90164095985202E-6,4.38540688884917E-5,7.91201544066133E-6,349.9852295,349.9852295,-26539.1328125,-26524.21484375,56.7126204698329,20.5917597187098,30.502024,0,0,0,40,4449,350.5134,-26531.673828125,,,,,,,,,,,,,0,,,,-0.0049,,,,,,349.9852295,,,,
,27369490.515,349.9900208,-21629.3388671875,2.96444300766011E-5,1.22352540294242E-6,1,0.999253354069792,40.0298881530762,1.99649137318229,20.1999992132187,0.000324923873868094,0.000113554304213071,0.25,4.92894209123431E-6,2.95891491946118E-5,4.93666770426975E-6,349.9900208,349.9900208,-21636.876953125,-21621.80078125,57.2214606358522,20.5934498322751,30.502024,0,0,0,40,4449,350.51085,-21629.3388671875,,,,,,,,,,,,,0,,,,0.00245,,,,,,349.9900208,,,,
,27369586.555,349.9953766,-16832.3876953125,1.54467181028431E-5,1.11524585022495E-6,1,0.999253354069792,40.0298881530762,1.99659597570883,20.1999992132187,0.000166373283503564,7.61637035453075E-5,0.25,4.07380775801702E-6,1.54170721027299E-5,4.07517038737434E-6,349.9951782,349.995575,-16839.9609375,-16824.814453125,56.9502355396791,20.5913041945623,30.502024,0,0,0,40,4449,350.5192,-16832.3876953125,,,,,,,,,,,,,0,,,,-0.00245,,,,,,349.9953766,,,,
,27369685.125,349.9932251,-11905.0478515625,-1.46096693798001E-8,5.9107576334157E-7,1,0.999253354069792,40.0298881530762,1.99691009479983,20.1999992132187,-6.095947778492E-6,3.42250835561449E-5,0.25,3.03455368466802E-6,-1.62714385911971E-8,3.0291663943941E-6,349.9932251,349.9932251,-11917.5068359375,-11892.5888671875,57.2910255740638,20.5872549640083,30.122374,0,0,0,40,4449,350.51435,-11905.0478515625,,,,,,,,,,,,,0,,,,0.00245,,,,,,349.9932251,,,,
,27369782.605,349.9885559,-7031.82275390625,-1.19047600034148E-5,7.21657230848837E-7,1,0.999253354069792,40.0298881530762,1.99682978146617,20.1999992132187,-0.000137508544430969,-5.16519224227976E-6,0.25,1.60371440982439E-6,-1.18845512054874E-5,1.59424675560611E-6,349.9885559,349.9885559,-7034.38818359375,-7029.25732421875,56.9361662263329,20.5885224986017,30.122374,0,0,0,40,4449,350.5282,-7031.82275390625,,,,,,,,,,,,,0,,,,0,,,,,,349.9885559,,,,
,27369874.9,349.9911499,-2415.75207519531,-2.06986240663269E-5,5.8283845270169E-7,1,0.999253354069792,40.0298881530762,1.99682174141139,20.1999992132187,-0.000235125798812261,-3.18350112176699E-5,0.25,7.6358647284848E-7,-2.06623584978988E-5,7.50707978067373E-7,349.9911499,349.9911499,-2425.85229492187,-2405.65185546875,57.1354814987368,20.588346078173,30.502024,0,0,0,40,4449,350.5387,-2415.75207519531,,,,,,,,,,,,,0,,,,-0.00245,,,,,,349.9911499,,,,
,27369965.45,349.9968567,2103.751953125,2.05527483034153E-5,5.20228242622816E-7,1,0.999253354069792,40.0298881530762,1.99676651503462,20.1999992132187,0.000233558844908201,3.10534852663516E-5,0.25,-8.0749409898708E-7,2.05167617876203E-5,-7.94618355229679E-7,349.9968567,349.9968567,2098.7646484375,2108.7392578125,57.159711982833,20.5912671530881,30.502024,0,0,0,40,4449,350.5352,2103.751953125,,,,,,,,,,,,,0,,,,-0.00245,,,,,,349.9968567,,,,
,27370057.14,350.0018005,6686.92602539063,1.36336337829201E-5,4.53887117267841E-7,1,0.999253354069792,40.0298881530762,1.99666677974439,20.1999992132187,0.000157380415271115,6.40878341575032E-6,0.25,-1.79285119044047E-6,1.36104597065392E-5,-1.78208531393915E-6,350.0018005,350.0018005,6681.9423828125,6691.90966796875,57.0565370182945,20.5910999546567,30.502024,0,0,0,40,4449,350.54185,6686.92602539063,,,,,,,,,,,,,0,,,,0,,,,,,350.0018005,,,,
,27370151.45,350.0042419,11402.9584960938,1.12792418306078E-6,6.63826242340952E-7,1,0.999253354069792,40.0298881530762,1.996702197985,20.1999992132187,1.96968402702876E-5,-3.80280346840737E-5,0.25,-3.5645668371209E-6,1.12790682448142E-6,-3.5576195185725E-6,350.0042419,350.0042419,11395.423828125,11410.4931640625,56.9885353371214,20.5894282017171,30.881676,0,0,0,40,4449,350.5349,11402.9584960938,,,,,,,,,,,,,0,,,,0,,,,,,350.0042419,,,,
,27370245.88,350.0036621,16123.14453125,-1.22979497276373E-5,7.77050930639611E-7,1,0.999253354069792,40.0298881530762,1.99669710122877,20.1999992132187,-0.000130448507941541,-7.22864364648926E-5,0.25,-4.27516768486138E-6,-1.22737699241916E-5,-4.27442281130103E-6,350.0032959,350.0040283,16112.9794921875,16133.3095703125,56.983845566006,20.5912371488623,30.502024,0,0,0,40,4449,350.5316,16123.14453125,,,,,,,,,,,,,0,,,,-0.00245,,,,,,350.0036621,,,,
,27370341.47,349.9997253,20900.2421875,-2.64952011534867E-5,9.26401785004464E-7,1,0.999253354069792,40.0298881530762,1.99663611895578,20.1999992132187,-0.0002888499877313,-0.000110600628478863,0.25,-5.21183377600735E-6,-2.64453361387711E-5,-5.2173084023198E-6,349.9997253,349.9997253,20890.38671875,20910.09765625,57.058100275333,20.5879991489284,30.502024,0,0,0,40,4449,350.5298,20900.2421875,,,,,,,,,,,,,0,,,,0.00245,,,,,,349.9997253,,,,
,27370438.195,350.0073853,25735.5078125,-4.18002137801362E-5,1.08731633341093E-6,1,0.999253354069792,40.0298881530762,1.99674735574478,20.1999992132187,-0.000457544947962652,-0.000164010825295909,0.25,-7.29328966294535E-6,-4.17220538184809E-5,-7.30355436968052E-6,350.0073853,350.0073853,25732.9765625,25738.0390625,56.9017745714868,20.58734278387,30.502024,0,0,0,40,4449,350.5186,25735.5078125,,,,,,,,,,,,,0,,,,-0.00245,,,,,,350.0073853,,,,
,27370533.685,350.0166931,30505.80859375,-5.60454773924928E-5,1.25302143330809E-6,1,0.999253354069792,40.0298881530762,1.99666477947498,20.1999992132187,-0.000615659495187832,-0.000207130691614022,0.25,-8.64780206001313E-6,-5.5941296405019E-5,-8.66354418317476E-6,350.0166931,350.0166931,30500.701171875,30510.916015625,56.8916134007368,20.5895173100568,30.881676,0,0,0,40,4449,350.49545,30505.80859375,,,,,,,,,,,,,0,,,,0,,,,,,350.0166931,,,,
,27370630.9,350.0092773,35365.6953125,-7.10419166465988E-5,1.74760902988313E-6,1,0.999253354069792,40.0298881530762,1.99664429669048,20.1999992132187,-0.000781687154328314,-0.000255048356596128,0.25,-1.02969933138343E-5,-7.09102532920308E-5,-1.03180949216889E-5,350.0092773,350.0092773,35358.09375,35373.296875,56.9377294833714,20.5884390339443,30.881676,0,0,0,40,4449,350.4997,35365.6953125,,,,,,,,,,,,,0,,,,0,,,,,,350.0092773,,,,
,27370725.95,350.0135498,40118.478515625,-8.56018966312281E-5,1.62013291803158E-6,1,0.999253354069792,40.0298881530762,1.99666445174288,20.1999992132187,-0.000947909322360889,-0.000272630259083163,0.25,-9.33355870227793E-6,-8.54449472341693E-5,-9.36439238506816E-6,350.0135498,350.0135498,40110.97265625,40125.984375,56.8501870892175,20.5866614450655,30.502024,0,0,0,40,4449,350.5028,40118.478515625,,,,,,,,,,,,,0,,,,0.00245,,,,,,350.0135498,,,,
,27370822.74,350.0065002,44953.994140625,-9.96909772081795E-5,1.95541099083663E-6,1,0.999253354069792,40.0298881530762,1.99662257827256,20.1999992132187,-0.00110588136071727,-0.000306066898283808,0.25,-9.8571694948214E-6,-9.95087881203562E-5,-9.89482940776747E-6,350.0065002,350.0065002,44949,44958.98828125,56.7259081546598,20.5861572044746,30.881676,0,0,0,40,4449,350.48285,44953.994140625,,,,,,,,,,,,,0,,,,0,,,,,,350.0065002,,,,
,27370921.31,350.0077515,49881.685546875,-0.000114365002556988,1.98800145856732E-6,1,0.999253354069792,40.0298881530762,1.99652159675602,20.1999992132187,-0.00126929360781459,-0.000347098609513865,0.25,-1.09534686578101E-5,-0.00011415619725221,-1.09972430896738E-5,350.0077515,350.0077515,49876.75,49886.62109375,57.2378748347561,20.5864782491148,30.502024,0,0,0,40,4449,350.47165,49881.685546875,,,,,,,,,,,,,0,,,,-0.0049,,,,,,350.0077515,,,,
,27371017.805,350.0162354,54704.021484375,-0.000134051212437381,2.46219040669968E-6,1,0.999253354069792,40.0298881530762,1.99656566934247,20.1999992132187,-0.00148742220824962,-0.000409119964213079,0.25,-1.30397073420193E-5,-0.00013380632649004,-1.30905917759416E-5,350.0162354,350.0162354,54699.08203125,54708.9609375,56.8400259184676,20.5870629536336,30.881676,0,0,0,40,4449,350.45455,54704.021484375,,,,,,,,,,,,,0,,,,0,,,,,,350.0162354,,,,
,27371112.39,350.0053711,59431.728515625,-0.000145458354934059,2.15156407177875E-6,1,0.999253354069792,40.0298881530762,1.99661004451732,20.1999992132187,-0.0016138700822485,-0.000444867304436758,0.25,-1.42312268756708E-5,-0.000145192651427908,-1.42862267906209E-5,350.0053711,350.0053711,59426.71875,59436.73828125,57.044812590506,20.5866686855163,30.881676,0,0,0,40,4449,350.455,59431.728515625,,,,,,,,,,,,,0,,,,0.00245,,,,,,350.0053711,,,,
,27371209.565,350.0104065,64289.998046875,-0.000159971636345958,2.85843580501037E-6,1,0.999253354069792,40.0298881530762,1.99657976674391,20.1999992132187,-0.00178102684289096,-0.000453688969337665,0.25,-1.25006166276106E-5,-0.000159681145982232,-1.25665992080308E-5,350.0104065,350.0104065,64279.90625,64300.08984375,57.0612267894099,20.5862331237244,30.502024,0,0,0,40,4449,350.46465,64289.998046875,,,,,,,,,,,,,0,,,,-0.0049,,,,,,350.0104065,,,,
,27371307.7,350.008728,69195.06640625,-0.000176657209093489,2.34713778364527E-6,1,0.999253354069792,40.0298881530762,1.99668039198731,20.1999992132187,-0.00196562167628616,-0.000508352304038141,0.25,-1.44529344243838E-5,-0.000176336086854288,-1.45245582726324E-5,350.008728,350.008728,69187.6015625,69202.53125,56.7110572127945,20.585495720138,30.502024,0,0,0,40,4449,350.44815,69195.06640625,,,,,,,,,,,,,0,,,,0,,,,,,350.008728,,,,
,27371404.89,350.0198669,74052.81640625,-0.000192348810499307,2.40016435516355E-6,1,0.999253354069792,40.0298881530762,1.99672373910927,20.1999992132187,-0.00213967828534823,-0.000556889406140483,0.25,-1.6035514422735E-5,-0.000191998943579328,-1.61128649834981E-5,350.0198669,350.0198669,74045.2734375,74060.359375,57.0596635323714,20.5849353740382,30.881676,0,0,0,40,4449,350.428,74052.81640625,,,,,,,,,,,,,0,,,,-0.0049,,,,,,350.0198669,,,,
,27371502.57,350.0187378,78935.921875,-0.000207533872964883,2.53108721428971E-6,1,0.999253354069792,40.0298881530762,1.99672839012457,20.1999992132187,-0.0023121512589392,-0.000580353196945326,0.25,-1.5485158750052E-5,-0.00020715740900965,-1.55717263545126E-5,350.0187378,350.0187378,78928.359375,78943.484375,56.943200883006,20.5840064679464,31.261326,0,0,0,40,4449,350.41125,78935.921875,,,,,,,,,,,,,0,,,,0,,,,,,350.0187378,,,,
,27371599.195,350.0141754,83764.37890625,-0.000225904308037261,3.07099166971134E-6,1,0.999253354069792,40.0298881530762,1.99662500741759,20.1999992132187,-0.00251562249350751,-0.00063788185419606,0.25,-1.74042728830802E-5,-0.000225494271114701,-1.74974202829427E-5,350.0132141,350.0151367,83756.9609375,83771.796875,56.8525319747752,20.5830249772531,31.261326,0,0,0,40,4449,350.3748,83764.37890625,,,,,,,,,,,,,0,,,,0,,,,,,350.0141754,,,,
,27371692.39,350.02272035,88422.33984375,-0.000236615247536825,3.19670809138805E-6,1,0.999253354069792,40.0298881530762,1.99675697645878,20.1999992132187,-0.00263974637121713,-0.000641118457593263,0.25,-1.5833077500316E-5,-0.000236187034591908,-1.59347575265957E-5,350.0219727,350.023468,88419.6640625,88425.015625,57.0565370182945,20.5834663880021,30.881676,0,0,0,40,4449,350.37235,88422.33984375,,,,,,,,,,,,,0,,,,0,,,,,,350.02272035,,,,
,27371803.925,350.0021362,87048.57421875,-0.000233046316266031,3.03965492789884E-6,1,0.999253354069792,40.0298881530762,1.996833278206,20.1999992132187,-0.00259607372888985,-0.000654303926423787,0.25,-1.76170209501126E-5,-0.000232623610209575,-1.77136239935538E-5,350.0021362,350.0021362,87043.6171875,87053.53125,56.8845787440637,20.5828067800522,30.881676,0,0,0,40,4449,350.3911,87048.57421875,,,,,,,,,,,,,0,,,,-0.00245,,,,,,350.0021362,,,,
,27371900.07,349.9968872,82240.1953125,-0.000218536608993433,3.27989342417747E-6,1,0.999253354069792,40.0298881530762,1.99678615623901,20.1999992132187,-0.00243871941569589,-0.000588518001143712,0.25,-1.43020884985354E-5,-0.00021814145898244,-1.43967344984862E-5,349.9968872,349.9968872,82230.03125,82250.359375,56.7853119221214,20.5825143554234,31.261326,0,0,0,40,4449,350.3861,82240.1953125,,,,,,,,,,,,,0,,,,-0.00245,,,,,,349.9968872,,,,
,27371999.415,349.9945374,77276.11328125,-0.000203517552197764,2.3879827260599E-6,1,0.999253354069792,40.0298881530762,1.99693789805259,20.1999992132187,-0.00226778519456085,-0.000568305822345355,0.25,-1.51080556579099E-5,-0.000203148575954977,-1.51931418713598E-5,349.9945374,349.9945374,77265.734375,77286.4921875,56.933039712256,20.5822385255413,30.881676,0,0,0,40,4449,350.3934,77276.11328125,,,,,,,,,,,,,0,,,,-0.00245,,,,,,349.9945374,,,,
,27372100.19,349.987793,72237.97265625,-0.000186475196498813,2.86658052163055E-6,1,0.999253354069792,40.0298881530762,1.99683670500293,20.1999992132187,-0.00207458461836922,-0.00053916336122829,0.25,-1.54793199453334E-5,-0.000186136244546103,-1.55544881990685E-5,349.987793,349.987793,72228.0625,72247.8828125,56.8884868866599,20.5833215711464,31.261326,0,0,0,40,4449,350.4049,72237.97265625,,,,,,,,,,,,,0,,,,0,,,,,,349.987793,,,,
,27372198.355,349.9849548,67330.04296875,-0.000174759297114334,2.53416532979585E-6,1,0.999253354069792,40.0298881530762,1.99689006434698,20.1999992132187,-0.0019404182540665,-0.000527673433246855,0.25,-1.64886394264573E-5,-0.000174440551235024,-1.65556686148107E-5,349.9849548,349.9849548,67324.984375,67335.1015625,56.9682129956214,20.582368459287,31.261326,0,0,0,40,4449,350.41385,67330.04296875,,,,,,,,,,,,,0,,,,0,,,,,,349.9849548,,,,
,27372297.07,349.9847717,62396.640625,-0.000157004736118003,2.64026511647452E-6,1,0.999253354069792,40.0298881530762,1.99705122900658,20.1999992132187,-0.00174308283251759,-0.000476030163476833,0.25,-1.49842716739133E-5,-0.000156718265432742,-1.50442730905741E-5,349.9847717,349.9847717,62386.46875,62406.8125,57.3129111726022,20.5886293792139,31.261326,0,0,0,40,4449,350.41925,62396.640625,,,,,,,,,,,,,0,,,,0,,,,,,349.9847717,,,,
,27372395.92,349.984436,57456.283203125,-0.000141783908032831,2.13985917800752E-6,1,0.999253354069792,40.0298881530762,1.99701193953036,20.1999992132187,-0.00156958969311495,-0.000455748863262887,0.25,-1.58237651395483E-5,-0.000141523933369382,-1.58739620315511E-5,349.984436,349.984436,57443.73046875,57468.8359375,56.8071975206598,20.5857061946452,31.640976,0,0,0,40,4449,350.43165,57456.283203125,,,,,,,,,,,,,0,,,,-0.00245,,,,,,349.984436,,,,
,27372494.67,349.9884949,52521.208984375,-0.000123775683229038,1.94413338945327E-6,1,0.999253354069792,40.0298881530762,1.99701378589923,20.1999992132187,-0.00137395100897513,-0.000376397515319672,0.25,-1.19122922333573E-5,-0.000123549749852244,-1.1959545101499E-5,349.9884949,349.9884949,52516.12109375,52526.296875,56.9338213407753,20.587821775673,30.881676,0,0,0,40,4449,350.44385,52521.208984375,,,,,,,,,,,,,0,,,,-0.0049,,,,,,349.9884949,,,,
,27372593.675,349.9874573,47571.5078125,-0.00010961906840499,1.84968915698181E-6,1,0.999253354069792,40.0298881530762,1.99712328038842,20.1999992132187,-0.00121799010077819,-0.000326904866791904,0.25,-9.97752670971803E-6,-0.000109419286643946,-1.00204437574448E-5,349.9874573,349.9874573,47563.95703125,47579.05859375,56.8877052581406,20.590066818622,31.640976,0,0,0,40,4449,350.4641,47571.5078125,,,,,,,,,,,,,0,,,,0.00245,,,,,,349.9874573,,,,
,27372692.945,349.9858398,42608.765625,-9.43388511179494E-5,1.61361290811046E-6,1,0.999253354069792,40.0298881530762,1.99712348443171,20.1999992132187,-0.00104804466430679,-0.000282290790556711,0.25,-8.67121727439706E-6,-9.41668682711817E-5,-8.70804941004201E-6,349.9858398,349.9858398,42601.578125,42615.953125,57.0979633298137,20.5901504741609,31.261326,0,0,0,40,4449,350.47715,42608.765625,,,,,,,,,,,,,0,,,,0,,,,,,349.9858398,,,,
,27372792.625,349.9880676,37628.65625,-7.83485469285876E-5,1.4095524167907E-6,1,0.999253354069792,40.0298881530762,1.99722055316283,20.1999992132187,-0.000866752798323425,-0.000255764898555681,0.25,-9.08910765941109E-6,-7.82046570168326E-5,-9.11639006506847E-6,349.9880676,349.9880676,37623.8203125,37633.4921875,56.943200883006,20.5878092798782,30.881676,0,0,0,40,4449,350.4803,37628.65625,,,,,,,,,,,,,0,,,,-0.00245,,,,,,349.9880676,,,,
,27372890.235,349.9929199,32751.28515625,-6.24990755264106E-5,1.51770265691185E-6,1,0.999253354069792,40.0298881530762,1.99713107530036,20.1999992132187,-0.000685757501364591,-0.000236510517414254,0.25,-1.01287789687813E-5,-6.23826820188692E-5,-1.01454701574312E-5,349.9929199,349.9929199,32741.173828125,32761.396484375,56.9783741663714,20.5891644528104,30.881676,0,0,0,40,4449,350.4728,32751.28515625,,,,,,,,,,,,,0,,,,-0.0049,,,,,,349.9929199,,,,
,27372988.815,349.9969788,27821.6953125,-4.69483378162938E-5,1.25323985297695E-6,1,0.999253354069792,40.0298881530762,1.99697788107946,20.1999992132187,-0.000517497668799852,-0.00016375968563192,0.25,-6.37804741513434E-6,-4.68615757390817E-5,-6.39278807325162E-6,349.9969788,349.9969788,27809.1328125,27834.2578125,56.8908317722176,20.5886197676009,31.640976,0,0,0,40,4449,350.4724,27821.6953125,,,,,,,,,,,,,0,,,,-0.00245,,,,,,349.9969788,,,,
,27373087.315,349.9887695,22898.9560546875,-3.35752053235132E-5,1.35699739230066E-6,1,0.999253354069792,40.0298881530762,1.99706383265702,20.1999992132187,-0.000366563167591311,-0.00013757237543734,0.25,-6.37319919159014E-6,-3.35121572943611E-5,-6.38054568877136E-6,349.9887695,349.9887695,22896.494140625,22901.41796875,56.8540952318137,20.5888625451601,31.261326,0,0,0,40,4449,350.481,22898.9560546875,,,,,,,,,,,,,0,,,,-0.00245,,,,,,349.9887695,,,,
,27373184.075,349.9887085,18063.7080078125,-1.69928313446936E-5,9.60260365693481E-7,1,0.999253354069792,40.0298881530762,1.99705204195252,20.1999992132187,-0.000183539015353148,-8.1074134021123E-5,0.25,-4.23961572092505E-6,-1.69603566860419E-5,-4.24154332316182E-6,349.9887085,349.9887085,18058.625,18068.791015625,57.0315249056791,20.5895084174663,31.640976,0,0,0,40,4449,350.49945,18063.7080078125,,,,,,,,,,,,,0,,,,-0.0049,,,,,,349.9887085,,,,
,27373277.475,349.9933777,13394.4111328125,-4.41658821179855E-6,8.13837560048618E-7,1,0.999253354069792,40.0298881530762,1.9971606141822,20.1999992132187,-4.18465868615978E-5,-5.49123370150717E-5,0.25,-4.09940559477984E-6,-4.40647977351182E-6,-4.09459465167181E-6,349.9933777,349.9933777,13391.7958984375,13397.0263671875,57.2019199228714,20.5931607081449,31.261326,0,0,0,40,4449,350.5056,13394.4111328125,,,,,,,,,,,,,0,,,,0,,,,,,349.9933777,,,,
,27373374.355,349.9828491,8551.30126953125,9.02362604535219E-6,5.16361008213626E-7,1,0.999253354069792,40.0298881530762,1.99720042944066,20.1999992132187,0.00010640138862428,-8.5214813814132E-6,0.25,-2.31726696746707E-6,9.00892273097851E-6,-2.30813936737572E-6,349.9828491,349.9828491,8548.716796875,8553.8857421875,56.9385111118906,20.5916793807561,30.881676,0,0,0,40,4449,350.52675,8551.30126953125,,,,,,,,,,,,,0,,,,-0.0049,,,,,,349.9828491,,,,
,27373466.525,349.9893188,3945.69665527344,1.88692653192142E-5,4.88216835653654E-7,1,0.999253354069792,40.0298881530762,1.99728236942324,20.1999992132187,0.000215359612043186,2.34419889717868E-5,0.25,-1.19086189130012E-6,1.88364815922125E-5,-1.17824599627772E-6,349.9893188,349.9893188,3940.80712890625,3950.58618164063,57.0432493334676,20.5915670494409,31.640976,0,0,0,40,4449,350.523,3945.69665527344,,,,,,,,,,,,,0,,,,0,,,,,,349.9893188,,,,
,27373545.6,349.9882813,-0.372982427477837,2.6931148848107E-6,5.08777164633278E-7,1,0.999253354069792,40.0298881530762,1.99727524364925,20.1999992132187,3.20575254547429E-5,-4.28018391812045E-6,0.25,-8.45434820042885E-7,2.68881211564849E-6,-8.42436341627579E-7,349.9882813,349.9882813,-0.380594313144684,-0.365370541810989,57.0713879601599,20.595991161191,31.640976,0,0,0,40,4417,350.5202,-0.372982427477837,,,,,,,,,,,,,0,,,,-0.0049,,,,,,349.9882813,,,,