File: defense/images/np_vsm/data_disorderedWafer/DD226_2_HYST_20K.DAT
[Header]
; VSM Data File (default extension .dat)
; Copyright (c) 2003-2013, Quantum Design, Inc. All rights reserved.
TITLE,
FILEOPENTIME,27292428.38,11/13/2018,5:14 am
BYAPP,VSM,2.0,2.0
INFO,PPMS VSM Option Release 1.4.10 Build 1,APPNAME
INFO,Quantum Design Linear Motor Servo Controller,MOTOR_MODULE_NAME
INFO,3101-100 M1,MOTOR_HW_VERSION
INFO,MMC1014,MOTOR_SERIAL_NUMBER
INFO,SRV No X-over 01.03.11,MOTOR_SOFTWARE_VERSION
INFO,Quantum Design VSM Detection Module,VSM_MODULE_NAME
INFO,3101-150 F0,VSM_HW_VERSION
INFO,VSM707,VSM_SERIAL_NUMBER
INFO,VSM No X-over 01.02.05 May 20 2008 13:51:47,VSM_SOFTWARE_VERSION
INFO,704,PREAMP_SERIAL_NUMBER
INFO,822,COIL_SERIAL_NUMBER
INFO,0,MOMENT_UNITS
INFO,CoFe2O4 AH11,SAMPLE_MATERIAL
INFO,Quick Dry Monolayer Conc,SAMPLE_COMMENT
INFO,27.96,SAMPLE_MASS
INFO,,SAMPLE_VOLUME
INFO,,SAMPLE_MOLECULAR_WEIGHT
INFO,,SAMPLE_SIZE
INFO,,SAMPLE_SHAPE
DATATYPE,COMMENT,1
DATATYPE,TIME,2
STARTUPAXIS,X,2
STARTUPAXIS,Y1,5
[Data]
Comment,Time Stamp (sec),Temperature (K),Magnetic Field (Oe),Moment (emu),M. Std. Err. (emu),Transport Action,Averaging Time (sec),Frequency (Hz),Peak Amplitude (mm),Center Position (mm),Coil Signal' (mV),Coil Signal" (mV),Range (mV),M. Quad. Signal (emu),M. Raw' (emu),M. Raw" (emu),Min. Temperature (K),Max. Temperature (K),Min. Field (Oe),Max. Field (Oe),Mass (grams),Motor Lag (deg),Pressure (Torr),VSM Status (code),Motor Status (code),Measure Status (code),Measure Count,PPMS Status (code),System Temp. (K),System Field (Oe),Sample Position (deg),Bridge 1 Resistance (ohms),Bridge 1 Excitation (에),Bridge 2 Resistance (ohms),Bridge 2 Excitation (에),Bridge 3 Resistance (ohms),Bridge 3 Excitation (에),Bridge 4 Resistance (ohms),Bridge 4 Excitation (에),Signal 1 Vin (V),Signal 2 Vin (V),Digital Inputs (code),Drive 1 Iout (mA),Drive 1 Ipower (W),Drive 2 Iout (mA),Drive 2 Ipower (W),Pressure (),Map 20 (),Map 21 (),Map 22 (),Map 23 (),Map 24 (),Map 25 (),Map 26 (),Map 27 (),Map 28 (),Map 29 ()
,27292442.25,19.9980965,-0.1674614995718,,,2,,,,25.6299993538857,,,,,,,19.9980965,19.9980965,-0.1674614995718,-0.1674614995718,,,14.177031,,,,-99999999,4369,20.0059,-0.1674614995718,,,,,,,,,,,,,,,,,,,,,,,19.9980965,,,,
,27292592.9,20.0121746,4613.529296875,1.07093736874264E-5,3.27820270964033E-7,1,0.999253354069792,40.0298881530762,1.98401646673967,25.620000436902,0.000120265844405229,1.75159446126926E-5,0.25,-3.36594528415563E-7,1.06522079757853E-5,-2.79863743462044E-7,20.0121746,20.0121746,4605.9951171875,4621.0634765625,57.0635716749676,20.6492824954206,14.556682,0,0,0,40,4449,20.01425,4613.529296875,,,,,,,,,,,,,0,,,,0,,,,,,20.0121746,,,,
,27292692.275,19.9990597,9574.56201171875,1.09099159374744E-5,3.75553036134162E-7,1,0.999253354069792,40.0298881530762,1.98344912790647,25.620000436902,0.000122945996462329,1.55183355601806E-5,0.25,-5.55233793701163E-7,1.08569544797277E-5,-4.9255577503718E-7,19.9990597,19.9990597,9567.0107421875,9582.11328125,56.9947883652753,20.6594021557338,14.177031,0,0,0,40,4449,20.00235,9574.56201171875,,,,,,,,,,,,,0,,,,-0.0049,,,,,,19.9990597,,,,
,27292797.525,20.0018044,14836.875,1.14888556409427E-5,4.22490551364291E-7,1,0.999253354069792,40.0298881530762,1.98399475183297,25.620000436902,0.000128468748324344,2.24923321124131E-5,0.25,-3.9769051402497E-8,1.14352643045877E-5,2.77878363943692E-8,20.0018044,20.0018044,14834.486328125,14839.263671875,57.4051433378714,20.6563545637683,14.936333,0,0,0,40,4449,20.0035,14836.875,,,,,,,,,,,,,0,,,,0,,,,,,20.0018044,,,,
,27292900.235,20.0023155,19971.568359375,1.12674340503577E-5,3.48256256919253E-7,1,0.999253354069792,40.0298881530762,1.98424697713113,25.620000436902,0.000126824726583758,1.78530187079422E-5,0.25,-4.20239877629582E-7,1.12226793539644E-5,-3.48499357372733E-7,20.0023155,20.0023155,19961.701171875,19981.435546875,57.4778347901599,20.655786643732,14.556682,0,0,0,40,4449,20.00205,19971.568359375,,,,,,,,,,,,,0,,,,-0.0049,,,,,,20.0023155,,,,
,27293005.92,20.0037117,25253.7421875,1.18598600710881E-5,4.29506209921902E-7,1,0.999253354069792,40.0298881530762,1.98424296173317,25.620000436902,0.000132592397868993,2.42266315728725E-5,0.25,3.88545380448329E-8,1.18160013715869E-5,1.16132678747782E-7,20.0037117,20.0037117,25243.7578125,25263.7265625,57.2378748347561,20.6577819138401,14.177031,0,0,0,40,4449,20.00055,25253.7421875,,,,,,,,,,,,,0,,,,0,,,,,,20.0037117,,,,
,27293103.43,20.0023403,30126.6181640625,1.11774294809903E-5,5.08162035529404E-7,1,0.999253354069792,40.0298881530762,1.98433853016585,25.620000436902,0.00012733352207441,1.00299457685102E-5,0.25,-1.11119089127099E-6,1.11495085435473E-5,-1.0318821780822E-6,20.0023403,20.0023403,30121.5546875,30131.681640625,57.3723149400638,20.6567783193662,14.177031,0,0,0,40,4449,19.9966,30126.6181640625,,,,,,,,,,,,,0,,,,0,,,,,,20.0023403,,,,
,27293198.465,20.0032215,34876.666015625,1.18845331250635E-5,6.55627906423366E-7,1,0.999253354069792,40.0298881530762,1.98428595795547,25.620000436902,0.000132636664146136,2.63524789550613E-5,0.25,2.16681252237901E-7,1.18512747412017E-5,2.9912082815956E-7,20.0032215,20.0032215,34869.171875,34884.16015625,57.4801796757176,20.6582647679804,14.556682,0,0,0,40,4449,19.99365,34876.666015625,,,,,,,,,,,,,0,,,,-0.00245,,,,,,20.0032215,,,,
,27293294.77,20.0024414,39689.208984375,1.20244529729186E-5,5.96916528894225E-7,1,0.999253354069792,40.0298881530762,1.98440132039834,25.620000436902,0.000135579969307839,1.94210021172171E-5,0.25,-4.30479888996915E-7,1.20015384478222E-5,-3.43546776083963E-7,20.0024414,20.0024414,39681.7109375,39696.70703125,57.4356268501215,20.6574208991911,14.936333,0,0,0,40,4449,19.99205,39689.208984375,,,,,,,,,,,,,0,,,,0,,,,,,20.0024414,,,,
,27293387.4,20.0023899,44319.490234375,1.03663064845462E-5,5.90472150349999E-7,1,0.999253354069792,40.0298881530762,1.98422737885668,25.620000436902,0.000117421583309959,1.40285404354083E-5,0.25,-6.15156445378661E-7,1.0353411233564E-5,-5.38712616841036E-7,20.0023899,20.0023899,44314.625,44324.35546875,57.1112510146407,20.6573592812205,14.556682,0,0,0,40,4449,19.9911,44319.490234375,,,,,,,,,,,,,0,,,,0,,,,,,20.0023899,,,,
,27293482.01,20.0013428,49047.65234375,1.17010546567417E-5,8.69237106826268E-7,1,0.999253354069792,40.0298881530762,1.98418295436004,25.620000436902,0.000131441524095457,2.22896907186892E-5,0.25,-1.20347766938048E-7,1.1688035719688E-5,-3.40442832299795E-8,20.0013428,20.0013428,49037.4140625,49057.890625,57.0901470446214,20.6572451133524,15.315984,0,0,0,40,4449,19.9895,49047.65234375,,,,,,,,,,,,,0,,,,0,,,,,,20.0013428,,,,
,27293579.06,20.0009365,53902.568359375,1.21571932393051E-5,9.7427529355678E-7,1,0.999253354069792,40.0298881530762,1.98420330756365,25.6299991160631,0.000134741743468506,3.36662076589493E-5,0.25,8.09973531160377E-7,1.21426530743405E-5,8.9960048923153E-7,20.0009365,20.0009365,53895.02734375,53910.109375,57.0534105042176,20.6585502426492,14.936333,0,0,0,40,4449,19.98825,53902.568359375,,,,,,,,,,,,,0,,,,-0.0049,,,,,,20.0009365,,,,
,27293675.485,20.0009918,58717.81640625,1.0405786531706E-5,6.43973659844552E-7,1,0.999253354069792,40.0298881530762,1.98420096892026,25.620000436902,0.000120451634537524,7.14619582802665E-7,0.25,-1.81199289543137E-6,1.04168151002041E-5,-1.73412333470826E-6,20.0009918,20.0009918,58712.64453125,58722.98828125,57.6560460925446,20.6581857481417,15.315984,0,0,0,40,4449,19.9877,58717.81640625,,,,,,,,,,,,,0,,,,0.0049,,,,,,20.0009918,,,,
,27293770.055,20.0024166,63445.826171875,1.09650788520821E-5,7.35817415413774E-7,1,0.999253354069792,40.0298881530762,1.98432519473629,25.620000436902,0.000126536383144688,3.26312829506361E-6,0.25,-1.68578366830229E-6,1.09798339869046E-5,-1.60457436967164E-6,20.0024166,20.0024166,63440.85546875,63450.796875,57.5442732142945,20.6588694609024,14.936333,0,0,0,40,4449,19.9867,63445.826171875,,,,,,,,,,,,,0,,,,-0.00245,,,,,,20.0024166,,,,
,27293867.04,20.0015545,68293.578125,1.15278947585494E-5,7.56406820871558E-7,1,0.999253354069792,40.0298881530762,1.98425893785346,25.620000436902,0.000130115081827,1.99026931472013E-5,0.25,-3.05680357075481E-7,1.15374285426937E-5,-2.20480913389884E-7,20.0015545,20.0015545,68283.671875,68303.484375,57.5184794731599,20.6595908231115,14.936333,0,0,0,40,4449,19.98455,68293.578125,,,,,,,,,,,,,0,,,,0,,,,,,20.0015545,,,,
,27293962.55,20.0015354,73066.0546875,1.04138298005775E-5,7.66369545718319E-7,1,0.999253354069792,40.0298881530762,1.98426396470587,25.620000436902,0.000118150978656824,1.48598846671627E-5,0.25,-5.53801515167832E-7,1.04286359840427E-5,-4.77757621191177E-7,20.0015354,20.0015354,73061.0234375,73071.0859375,57.1417345268907,20.6580829947776,14.936333,0,0,0,40,4449,19.9829,73066.0546875,,,,,,,,,,,,,0,,,,-0.00245,,,,,,20.0015354,,,,
,27294056.42,20.0021152,77756.8828125,9.74840418353934E-6,6.55567140771999E-7,1,0.999253354069792,40.0298881530762,1.98441005814003,25.620000436902,0.00011303834395626,6.52403809713924E-7,0.25,-1.69749416081061E-6,9.77444827656886E-6,-1.62880667867801E-6,20.0021152,20.0021152,77754.5859375,77759.1796875,57.4348452216022,20.6535333785066,14.556682,0,0,0,40,4449,19.9805,77756.8828125,,,,,,,,,,,,,0,,,,0,,,,,,20.0021152,,,,
,27294149.57,20.0024281,82415.484375,9.61128649570676E-6,9.06734459966623E-7,1,0.999253354069792,40.0298881530762,1.98451865734056,25.620000436902,0.000109145631407162,1.3675024023466E-5,0.25,-5.14197531801459E-7,9.63181595316693E-6,-4.45803116197291E-7,20.0024281,20.0024281,82408.140625,82422.828125,57.5708485839484,20.6540158650856,14.936333,0,0,0,40,4449,19.9789,82415.484375,,,,,,,,,,,,,0,,,,0,,,,,,20.0024281,,,,
,27294239.85,20.0015945,86928.4140625,9.37839997352544E-6,7.26196710284896E-7,1,0.999253354069792,40.0298881530762,1.98425289703214,25.620000436902,0.000110094833141235,-6.52185842154968E-6,0.25,-2.2669271904135E-6,9.41393459037437E-6,-2.20483453353994E-6,20.0015945,20.0015945,86920.90625,86935.921875,57.4919041035061,20.6571182651005,15.315984,0,0,0,40,4449,19.9776,86928.4140625,,,,,,,,,,,,,0,,,,0,,,,,,20.0015945,,,,
,27294348.4,20.0015831,88703.0859375,1.01270640263549E-5,8.7619319448E-7,1,0.999253354069792,40.0298881530762,1.9842401493447,25.620000436902,0.000118906479600636,-7.10215839921789E-6,0.25,-2.45272046847436E-6,1.01665895351091E-5,-2.38635475651856E-6,20.0015831,20.0015831,88698.015625,88708.15625,57.0776409883137,20.6568542210417,14.936333,0,0,0,40,4449,19.97625,88703.0859375,,,,,,,,,,,,,0,,,,0,,,,,,20.0015831,,,,
,27294437.835,20.0001507,84231.40625,8.40098203237559E-6,8.40412465541003E-7,1,0.999253354069792,40.0298881530762,1.98446428948423,25.620000436902,9.65896421688054E-5,5.40541028807535E-6,0.25,-1.03131948341823E-6,8.42417842147273E-6,-9.72981251884794E-7,20.0001507,20.0001507,84224.0703125,84238.7421875,57.3004051162945,20.6544475698768,14.936333,0,0,0,40,4449,19.97645,84231.40625,,,,,,,,,,,,,0,,,,0,,,,,,20.0001507,,,,
,27294533.625,20.0003815,79443.29296875,9.91539680071227E-6,7.95134189564152E-7,1,0.999253354069792,40.0298881530762,1.98435633622936,25.620000436902,0.000117437277403944,-1.29511143905426E-5,0.25,-2.93710371744742E-6,9.95190394571633E-6,-2.86958821718318E-6,20.0003815,20.0003815,79440.671875,79445.9140625,57.1253203279868,20.6555563519939,14.556682,0,0,0,40,4449,19.9766,79443.29296875,,,,,,,,,,,,,0,,,,0,,,,,,20.0003815,,,,
,27294630.17,20.000185,74614.8359375,8.17611308662241E-6,8.60901592878161E-7,1,0.999253354069792,40.0298881530762,1.98425904309226,25.620000436902,9.54818539229825E-5,-3.3641943315565E-6,0.25,-1.77210925133681E-6,8.19856259701773E-6,-1.71417138982638E-6,20.000185,20.000185,74607.4375,74622.234375,57.9421221305831,20.6580280535702,14.556682,0,0,0,40,4449,19.9769,74614.8359375,,,,,,,,,,,,,0,,,,0,,,,,,20.000185,,,,
,27294725.205,19.9992428,69866.6171875,9.22613051107725E-6,9.03146000362598E-7,1,0.999253354069792,40.0298881530762,1.98448064435276,25.620000436902,0.000106154431117733,4.86514778626987E-6,0.25,-1.22949633519029E-6,9.24227637816431E-6,-1.1622281760737E-6,19.9992428,19.9992428,69859.265625,69873.96875,57.3332335141022,20.6551928056881,14.936333,0,0,0,40,4449,19.97945,69866.6171875,,,,,,,,,,,,,0,,,,-0.00245,,,,,,19.9992428,,,,
,27294819.57,19.9985714,65148.431640625,9.34153616513248E-6,7.95412740545452E-7,1,0.999253354069792,40.0298881530762,1.98441731666804,25.620000436902,0.000103889405931155,2.45992661678545E-5,0.25,5.06629715756744E-7,9.34108968629102E-6,5.76212309252959E-7,19.9983883,19.9987545,65141.07421875,65155.7890625,57.3988903097176,20.6561579657519,14.556682,0,0,0,40,4449,19.98035,65148.431640625,,,,,,,,,,,,,0,,,,-0.00245,,,,,,19.9985714,,,,
,27294915.575,19.9984455,60352.984375,1.06465956589217E-5,8.43111012914024E-7,1,0.999253354069792,40.0298881530762,1.98435853376273,25.620000436902,0.000117811528162979,3.09993607396926E-5,0.25,8.4237688368548E-7,1.06394489817658E-5,9.21554398067627E-7,19.9984455,19.9984455,60348.0234375,60357.9453125,57.342613056333,20.6553245985384,15.315984,0,0,0,40,4449,19.9816,60352.984375,,,,,,,,,,,,,0,,,,-0.00245,,,,,,19.9984455,,,,
,27295012.405,19.9993267,55510.044921875,1.03654796554815E-5,8.9229231344468E-7,1,0.999253354069792,40.0298881530762,1.98442120162543,25.620000436902,0.000117312099028508,1.54057081104201E-5,0.25,-4.95352264123604E-7,1.03635181714252E-5,-4.18065349831253E-7,19.9993267,19.9993267,55504.98828125,55515.1015625,57.0401228193907,20.6575189834457,14.556682,0,0,0,40,4449,19.9821,55510.044921875,,,,,,,,,,,,,0,,,,0,,,,,,19.9993267,,,,
,27295107.905,19.9994602,50737.46875,1.08637280370491E-5,5.97761145534333E-7,1,0.999253354069792,40.0298881530762,1.98424980919174,25.620000436902,0.000121336565113905,2.47159964353664E-5,0.25,2.46225715712429E-7,1.0850857725822E-5,3.26222674046534E-7,19.9994602,19.9994602,50727.40625,50747.53125,57.5653771843138,20.6573891577007,14.936333,0,0,0,40,4449,19.98295,50737.46875,,,,,,,,,,,,,0,,,,-0.00245,,,,,,19.9994602,,,,
,27295202.225,19.9992027,46022.24609375,1.17684980578255E-5,6.15343933065115E-7,1,0.999253354069792,40.0298881530762,1.98437878374626,25.620000436902,0.000133850702564946,1.30846233495822E-5,0.25,-9.52606952477723E-7,1.17578216376434E-5,-8.65141376767715E-7,19.9992027,19.9992027,46019.40234375,46025.08984375,57.586481154333,20.6577048538503,14.936333,0,0,0,40,4449,19.9831,46022.24609375,,,,,,,,,,,,,0,,,,0.0049,,,,,,19.9992027,,,,
,27295296.5,19.9998951,41312.056640625,1.16127709133454E-5,6.40131322864455E-7,1,0.999253354069792,40.0298881530762,1.98462068964352,25.620000436902,0.000134023252565407,1.82589586554356E-6,0.25,-1.92753178543279E-6,1.16035297860921E-5,-1.84008985244186E-6,19.9998951,19.9998951,41302.046875,41322.06640625,57.1511140691214,20.6537514221021,15.315984,0,0,0,40,4449,19.98375,41312.056640625,,,,,,,,,,,,,0,,,,0,,,,,,19.9998951,,,,
,27295388.73,19.9999008,36702.11328125,1.05675677060447E-5,7.3294701675516E-7,1,0.999253354069792,40.0298881530762,1.98449424851455,25.620000436902,0.000120701602970349,8.27091123467781E-6,0.25,-1.16230592558125E-6,1.05495808572253E-5,-1.08488743272364E-6,19.9999008,19.9999008,36694.40625,36709.8203125,57.2871174314676,20.6554346298372,14.936333,0,0,0,40,4449,19.98405,36702.11328125,,,,,,,,,,,,,0,,,,-0.00245,,,,,,19.9999008,,,,
,27295482.56,19.9984255,32012.2587890625,1.21480853435221E-5,6.0422283451801E-7,1,0.999253354069792,40.0298881530762,1.98453377213841,25.620000436902,0.000136632766040918,2.09236017355894E-5,0.25,-3.13772304586942E-7,1.21141121204446E-5,-2.29425849452042E-7,19.998354,19.998497,32007.271484375,32017.24609375,57.413741251583,20.6518265857381,14.556682,0,0,0,40,4449,19.9865,32012.2587890625,,,,,,,,,,,,,0,,,,0,,,,,,19.9984255,,,,
,27295576.665,19.9987583,27309.90625,1.08340658211887E-5,4.19273542543314E-7,1,0.999253354069792,40.0298881530762,1.98452179554745,25.620000436902,0.000121976045804569,1.76250591060873E-5,0.25,-3.69073897624639E-7,1.07989699050212E-5,-2.95864549058091E-7,19.9987583,19.9987583,27304.943359375,27314.869140625,57.4215575367753,20.6557490647763,15.315984,0,0,0,40,4449,19.98675,27309.90625,,,,,,,,,,,,,0,,,,0,,,,,,19.9987583,,,,
,27295671.04,19.99909685,22591.9306640625,1.16130169338225E-5,4.83792270995239E-7,1,0.999253354069792,40.0298881530762,1.98461982337745,25.620000436902,0.000130341171278222,2.08178305937765E-5,0.25,-2.19645930718689E-7,1.15685944699619E-5,-1.4476739649063E-7,19.9990768,19.9991169,22582.1015625,22601.759765625,57.4004535667561,20.6542022032945,14.936333,0,0,0,40,4449,19.98795,22591.9306640625,,,,,,,,,,,,,0,,,,0.00245,,,,,,19.99909685,,,,
,27295765.615,19.9982338,17866.87109375,1.14022156965023E-5,4.28691538258661E-7,1,0.999253354069792,40.0298881530762,1.98459476507028,25.620000436902,0.000127247432310997,2.4154696167827E-5,0.25,1.20871977558342E-7,1.13512489442306E-5,1.89574601054934E-7,19.9982338,19.9982338,17864.3984375,17869.34375,57.8006473686023,20.6592490394206,15.315984,0,0,0,40,4449,19.9896,17866.87109375,,,,,,,,,,,,,0,,,,-0.0049,,,,,,19.9982338,,,,
,27295859.25,19.9975967,13184.7021484375,1.18952247617308E-5,3.27121107526693E-7,1,0.999253354069792,40.0298881530762,1.9843923867706,25.620000436902,0.000132906439747553,2.39166264554584E-5,0.25,1.63878613212222E-8,1.18376583674766E-5,8.46628222623892E-8,19.9975967,19.9975967,13182.41796875,13186.986328125,57.5755383550638,20.6566684270975,15.315984,0,0,0,40,4449,19.9914,13184.7021484375,,,,,,,,,,,,,0,,,,0,,,,,,19.9975967,,,,
,27295953.14,19.9988747,8493.81494140625,1.13273599308695E-5,3.17646267536169E-7,1,0.999253354069792,40.0298881530762,1.98421072622989,25.620000436902,0.00012671036202884,2.15897886588032E-5,0.25,-8.56349413326538E-8,1.12687077054019E-5,-2.39716339798255E-8,19.9988747,19.9988747,8488.896484375,8498.7333984375,57.4653287338522,20.6582597801247,14.556682,0,0,0,40,4449,19.9933,8493.81494140625,,,,,,,,,,,,,0,,,,0,,,,,,19.9988747,,,,
,27296045.245,19.998642,3888.5625,1.12980920934918E-5,3.24566790186258E-7,1,0.999253354069792,40.0298881530762,1.98447455566608,25.620000436902,0.000126088370562509,2.30392127178091E-5,0.25,5.34792539000053E-8,1.12351552886337E-5,1.10507098983655E-7,19.998642,19.998642,3881.07421875,3896.05078125,57.5427099572561,20.6563754285134,15.315984,0,0,0,40,4449,19.9938,3888.5625,,,,,,,,,,,,,0,,,,0,,,,,,19.998642,,,,
,27296137.495,20.0003996,-721.629058837891,1.08367228254162E-5,3.10599447890226E-7,1,0.999253354069792,40.0298881530762,1.98439108209946,25.620000436902,0.000121654720171815,1.79179915967404E-5,0.25,-3.20469373465106E-7,1.07762587377262E-5,-2.6578787380003E-7,20.0002861,20.0005131,-726.332885742188,-716.925231933594,57.3566823696791,20.6574661387197,14.936333,0,0,0,40,4449,19.9929,-721.629058837891,,,,,,,,,,,,,0,,,,-0.0049,,,,,,20.0003996,,,,
,27296232.635,19.9992657,-5473.95043945313,1.01385350722787E-5,3.33337049121381E-7,1,0.999253354069792,40.0298881530762,1.98445112604546,25.620000436902,0.00011338409412151,1.94077061103421E-5,0.25,-6.67303601351169E-8,1.00837183952109E-5,-1.37997928382033E-8,19.9992657,19.9992657,-5476.28955078125,-5471.611328125,57.2269320354868,20.658142256667,14.936333,0,0,0,40,4449,19.9936,-5473.95043945313,,,,,,,,,,,,,0,,,,-0.0049,,,,,,19.9992657,,,,
,27296325.46,19.9997826,-10114.9609375,9.03354302250942E-6,3.71622942998175E-7,1,0.999253354069792,40.0298881530762,1.98437555980667,25.620000436902,0.000101283531672594,1.60376211479287E-5,0.25,-1.75317326157152E-7,8.98852920780586E-6,-1.24530146362489E-7,19.9997826,19.9997826,-10120.0234375,-10109.8984375,57.6959091470253,20.657916517576,14.936333,0,0,0,40,4449,19.9933,-10114.9609375,,,,,,,,,,,,,0,,,,0,,,,,,19.9997826,,,,
,27296416.625,20.0006275,-14670.384765625,6.52013406753226E-6,4.47501636413892E-7,1,0.999253354069792,40.0298881530762,1.98453184618094,25.620000436902,7.32912254534939E-5,1.07238596072492E-5,0.25,-2.05358431967321E-7,6.49069057999496E-6,-1.66236727192278E-7,20.0006275,20.0006275,-14702.6259765625,-14638.1435546875,57.2863358029484,20.6570943903437,14.556682,0,0,0,40,4449,19.9926,-14670.384765625,,,,,,,,,,,,,0,,,,0,,,,,,20.0006275,,,,
,27296511.4,20.0011177,-19407.5419921875,1.7489595767113E-6,3.25678325352039E-7,1,0.999253354069792,40.0298881530762,1.98442938254373,25.620000436902,2.07795719945929E-5,-3.33540480881919E-6,0.25,-6.11301116803277E-7,1.74528574922856E-6,-5.97900305694239E-7,20.0011177,20.0011177,-19414.962890625,-19400.12109375,57.3152560581599,20.6600673558861,14.936333,0,0,0,40,4449,19.99105,-19407.5419921875,,,,,,,,,,,,,0,,,,0,,,,,,20.0011177,,,,
,27296607.38,20.0011692,-24204.818359375,-3.01293631861302E-6,4.05154175961273E-7,1,0.999253354069792,40.0298881530762,1.98442916537904,25.620000436902,-3.1687519594971E-5,-1.72902067524826E-5,0.25,-1.00551209817091E-6,-2.9950328206957E-6,-1.02119629056836E-6,20.0011692,20.0011692,-24207.37109375,-24202.265625,57.5380201861407,20.6572410170349,15.315984,0,0,0,40,4449,19.98985,-24204.818359375,,,,,,,,,,,,,0,,,,-0.0049,,,,,,20.0011692,,,,
,27296704.635,20.0018616,-29064.8837890625,-6.51426992220636E-6,3.94199641797485E-7,1,0.999253354069792,40.0298881530762,1.98438652738001,25.620000436902,-7.27621564544327E-5,-1.38744400509204E-5,0.25,-7.02008293769371E-8,-6.49240997918896E-6,-1.13802365530275E-7,20.0018616,20.0018616,-29070.04296875,-29059.724609375,57.3394865422561,20.659058846196,15.315984,0,0,0,40,4449,19.9885,-29064.8837890625,,,,,,,,,,,,,0,,,,0.00245,,,,,,20.0018616,,,,
,27296800.11,20.0021439,-33837.029296875,-9.57441301758201E-6,5.05563398263516E-7,1,0.999253354069792,40.0298881530762,1.98440952186327,25.620000436902,-0.000105900007135173,-2.65100194423628E-5,0.25,-6.46614279559887E-7,-9.54329419597392E-6,-7.11299484889411E-7,20.0021439,20.0021439,-33847.18359375,-33826.875,57.3637170263522,20.6590733635707,15.315984,0,0,0,40,4449,19.9864,-33837.029296875,,,,,,,,,,,,,0,,,,0.0049,,,,,,20.0021439,,,,
,27296894.525,20.0010109,-38554.21875,-9.84574171901161E-6,5.26646880959246E-7,1,0.999253354069792,40.0298881530762,1.9844095254369,25.620000436902,-0.000110879841667187,-1.65743788094801E-5,0.25,2.919559624319E-7,-9.82535356011929E-6,2.21221580540976E-7,20.0010109,20.0010109,-38559.12109375,-38549.31640625,57.2902439455445,20.6605759846938,14.556682,0,0,0,40,4449,19.9847,-38554.21875,,,,,,,,,,,,,0,,,,0,,,,,,20.0010109,,,,
,27296991.17,20.0012836,-43384.37109375,-1.0245923783082E-5,4.51837742212139E-7,1,0.999253354069792,40.0298881530762,1.9844863892889,25.620000436902,-0.000114967907734127,-1.99360073173144E-5,0.25,6.6205677954309E-8,-1.02282341878727E-5,-8.22515691800636E-9,20.0012836,20.0012836,-43396.609375,-43372.1328125,57.7717271133907,20.6585694584447,14.936333,0,0,0,40,4449,19.98355,-43384.37109375,,,,,,,,,,,,,0,,,,0,,,,,,20.0012836,,,,
,27297083.32,20.0006981,-47989.162109375,-1.08884066501837E-5,6.1611869533147E-7,1,0.999253354069792,40.0298881530762,1.98443044646672,25.620000436902,-0.000120916711418528,-2.84981270056247E-5,0.25,-5.79924577138666E-7,-1.08700289297088E-5,-6.59166345806202E-7,20.0006981,20.0006981,-47999.2109375,-47979.11328125,57.5802281261792,20.6594561868483,15.315984,0,0,0,40,4449,19.9827,-47989.162109375,,,,,,,,,,,,,0,,,,0.00245,,,,,,20.0006981,,,,
,27297178,20.0014515,-52721.29296875,-1.09852300038977E-5,7.25354275927526E-7,1,0.999253354069792,40.0298881530762,1.98448753159773,25.620000436902,-0.000123133809041324,-2.27707665744593E-5,0.25,-5.0017362558177E-8,-1.0975865501656E-5,-1.31362436589103E-7,20.0014515,20.0014515,-52731.26953125,-52711.31640625,57.3066581444484,20.6609884037891,15.315984,0,0,0,40,4449,19.98215,-52721.29296875,,,,,,,,,,,,,0,,,,0,,,,,,20.0014515,,,,
,27297273.805,20.0019398,-57508.533203125,-1.18949580254958E-5,7.3678488463922E-7,1,0.999253354069792,40.0298881530762,1.98441702741352,25.620000436902,-0.000129351722941351,-4.70644677018854E-5,0.25,-2.04948632379797E-6,-1.18755322517677E-5,-2.13725509042278E-6,20.0019398,20.0019398,-57518.47265625,-57498.59375,57.4989387601791,20.6582725188941,14.936333,0,0,0,40,4449,19.98175,-57508.533203125,,,,,,,,,,,,,0,,,,0,,,,,,20.0019398,,,,
,27297368.83,20.001482,-62258.23046875,-1.0396692951658E-5,6.64821323995033E-7,1,0.999253354069792,40.0298881530762,1.98436900774117,25.620000436902,-0.000118592890709952,-1.07163988159888E-5,0.25,9.1953440195532E-7,-1.04045117286231E-5,8.42260187542809E-7,20.001482,20.001482,-62265.73828125,-62250.72265625,57.7498415148523,20.6593562575205,14.936333,0,0,0,40,4449,19.98105,-62258.23046875,,,,,,,,,,,,,0,,,,0.0049,,,,,,20.001482,,,,
,27297466.67,20.0014172,-67148.79296875,-1.0896657584989E-5,6.66857440835089E-7,1,0.999253354069792,40.0298881530762,1.9842438829564,25.620000436902,-0.000121642522788823,-2.62171335415882E-5,0.25,-3.70334366617642E-7,-1.08997012818397E-5,-4.51346894776567E-7,20.0014172,20.0014172,-67153.625,-67143.9609375,57.6630807492176,20.6589159770341,14.556682,0,0,0,40,4449,19.9802,-67148.79296875,,,,,,,,,,,,,0,,,,0.0049,,,,,,20.0014172,,,,
,27297562.795,20.0019455,-71950.42578125,-1.03661734407524E-5,7.34686606022543E-7,1,0.999253354069792,40.0298881530762,1.98445300748625,25.620000436902,-0.000118740468572647,-8.51925911362347E-6,0.25,1.10958232619638E-6,-1.03840851060475E-5,1.03422030415465E-6,20.0019455,20.0019455,-71960.375,-71940.4765625,57.5528711280061,20.6590082630598,14.936333,0,0,0,40,4449,19.97765,-71950.42578125,,,,,,,,,,,,,0,,,,-0.00245,,,,,,20.0019455,,,,
,27297658.66,20.0018158,-76742.71875,-1.01533964608318E-5,7.53767655367866E-7,1,0.999253354069792,40.0298881530762,1.9843745172252,25.620000436902,-0.000116655730483272,-6.60852899973325E-6,0.25,1.24077725348063E-6,-1.01759005646366E-5,1.16823942526602E-6,20.0018158,20.0018158,-76747.78125,-76737.65625,57.4864327038715,20.6591049922461,14.556682,0,0,0,40,4449,19.9756,-76742.71875,,,,,,,,,,,,,0,,,,0.0049,,,,,,20.0018158,,,,
,27297755.22,20.0019894,-81569.62890625,-9.26641541377409E-6,8.3472299052161E-7,1,0.999253354069792,40.0298881530762,1.98445565436497,25.620000436902,-0.000107389384504514,-1.13033361608325E-6,0.25,1.56757913467254E-6,-9.29338861744264E-6,1.50327401187263E-6,20.0019894,20.0019894,-81574.8125,-81564.4453125,57.3848209963715,20.6588304740983,14.556682,0,0,0,40,4449,19.97435,-81569.62890625,,,,,,,,,,,,,0,,,,0,,,,,,20.0019894,,,,
,27297846.255,20.00123215,-86119.61328125,-9.22043174945478E-6,7.22617798358011E-7,1,0.999253354069792,40.0298881530762,1.9842732028186,25.620000436902,-0.000102766167482114,-2.3989205768301E-5,0.25,-4.73533514076085E-7,-9.23560601771571E-6,-5.40295484798065E-7,20.0011425,20.0013218,-86157.28125,-86081.9453125,57.6927826329484,20.6599027098838,14.556682,0,0,0,40,4449,19.9737,-86119.61328125,,,,,,,,,,,,,0,,,,-0.00245,,,,,,20.00123215,,,,
,27297956.095,20.0009317,-89433.92578125,-9.48348935035337E-6,7.62305879333626E-7,1,0.999253354069792,40.0298881530762,1.98416067570646,25.620000436902,-0.000111384368409526,6.83834948918791E-6,0.25,2.31335205579245E-6,-9.52104256360044E-6,2.25150208899968E-6,20.0007877,20.0010757,-89441.2109375,-89426.640625,57.4223391652945,20.6627393618355,14.936333,0,0,0,40,4449,19.9717,-89433.92578125,,,,,,,,,,,,,0,,,,-0.0049,,,,,,20.0009317,,,,
,27298043.195,20.0004063,-85080.69921875,-8.80756083924617E-6,9.1967930595097E-7,1,0.999253354069792,40.0298881530762,1.98435392250318,25.620000436902,-9.98427564433757E-5,-1.35691310141237E-5,0.25,3.78608673054488E-7,-8.82735831797766E-6,3.16296140841841E-7,20.0004063,20.0004063,-85085.8671875,-85075.53125,57.3809128537753,20.6611960934586,15.315984,0,0,0,40,4449,19.9715,-85080.69921875,,,,,,,,,,,,,0,,,,0,,,,,,20.0004063,,,,
,27298138.26,19.9989395,-80328.78515625,-1.00293451296155E-5,8.60909230854398E-7,1,0.999253354069792,40.0298881530762,1.98433451116342,25.620000436902,-0.000113086267116794,-1.85964672241583E-5,0.25,1.51884613837984E-7,-1.00464616819667E-5,7.9441169299233E-8,19.9989395,19.9989395,-80333.75,-80323.8203125,57.4215575367753,20.6617973876278,14.936333,0,0,0,40,4449,19.97265,-80328.78515625,,,,,,,,,,,,,0,,,,0.00245,,,,,,19.9989395,,,,
,27298234.345,19.9999905,-75528.640625,-9.32791524725693E-6,6.88024221945653E-7,1,0.999253354069792,40.0298881530762,1.98443070240133,25.620000436902,-0.000106636487411158,-9.00206566425665E-6,0.25,8.79318406532589E-7,-9.34581231023435E-6,8.12081868722053E-7,19.9999905,19.9999905,-75531.4296875,-75525.8515625,57.4325003360445,20.6586367903877,15.315984,0,0,0,40,4449,19.9736,-75528.640625,,,,,,,,,,,,,0,,,,0,,,,,,19.9999905,,,,
,27298329.53,19.9996605,-70771.01171875,-1.18123549233222E-5,7.65053145004689E-7,1,0.999253354069792,40.0298881530762,1.98438707773031,25.620000436902,-0.000131375338707172,-3.14245788763898E-5,0.25,-6.68283659484232E-7,-1.18173533032539E-5,-7.56064120548042E-7,19.9996605,19.9996605,-70783.5078125,-70758.515625,57.8186248245446,20.6606033525507,14.936333,0,0,0,40,4449,19.9746,-70771.01171875,,,,,,,,,,,,,0,,,,-0.00245,,,,,,19.9996605,,,,
,27298425.055,19.9986343,-65996.5390625,-1.06986358575634E-5,7.12652330229526E-7,1,0.999253354069792,40.0298881530762,1.98436631473138,25.620000436902,-0.000121316415098874,-1.52555878255111E-5,0.25,5.6992847012935E-7,-1.07074707241081E-5,4.90741873417053E-7,19.9986343,19.9986343,-66006.3828125,-65986.6953125,57.6435400362369,20.6575499901178,15.315984,0,0,0,40,4449,19.976,-65996.5390625,,,,,,,,,,,,,0,,,,0.00245,,,,,,19.9986343,,,,
,27298520.79,19.9983368,-61211.5859375,-1.24190863099734E-5,7.08132541756861E-7,1,0.999253354069792,40.0298881530762,1.98443409879734,25.620000436902,-0.000139743015201009,-2.33948206117606E-5,0.25,1.5476480212138E-7,-1.24202067362353E-5,6.23319010818086E-8,19.9983368,19.9983368,-61223.9140625,-61199.2578125,57.6873112333138,20.6547209856227,14.936333,0,0,0,40,4449,19.9775,-61211.5859375,,,,,,,,,,,,,0,,,,-0.00245,,,,,,19.9983368,,,,
,27298616.075,19.9981918,-56449.41796875,-1.13080554033513E-5,6.85448921375509E-7,1,0.999253354069792,40.0298881530762,1.98458397790686,25.620000436902,-0.000123727106965359,-4.05235636721826E-5,0.25,-1.57258109191917E-6,-1.12912379611983E-5,-1.65594433018527E-6,19.9981918,19.9981918,-56457.08203125,-56441.75390625,57.5528711280061,20.6555743428405,14.936333,0,0,0,40,4449,19.9791,-56449.41796875,,,,,,,,,,,,,0,,,,-0.00245,,,,,,19.9981918,,,,
,27298712.82,19.9989643,-51614.974609375,-1.15377722883651E-5,6.56551095743977E-7,1,0.999253354069792,40.0298881530762,1.98452111480682,25.620000436902,-0.000128349634439166,-2.92710795985214E-5,0.25,-5.302477463661E-7,-1.15231295054257E-5,-6.15101538770235E-7,19.9989643,19.9989643,-51625,-51604.94921875,57.5044101598138,20.6574043062574,14.936333,0,0,0,40,4449,19.9796,-51614.974609375,,,,,,,,,,,,,0,,,,0,,,,,,19.9989643,,,,
,27298808.855,19.9997349,-46815.296875,-1.282095621292E-5,5.93551285673207E-7,1,0.999253354069792,40.0298881530762,1.98446826824108,25.620000436902,-0.000142944509487553,-3.03267331006597E-5,0.25,-3.95367244492374E-7,-1.27998904435698E-5,-4.88733567307463E-7,19.9997349,19.9997349,-46822.71484375,-46807.87890625,57.3457395704099,20.6569183659061,15.315984,0,0,0,40,4449,19.98005,-46815.296875,,,,,,,,,,,,,0,,,,0,,,,,,19.9997349,,,,
,27298904.815,19.99915315,-42020.4765625,-1.13998978417041E-5,7.53147692279069E-7,1,0.999253354069792,40.0298881530762,1.98452796201892,25.620000436902,-0.000125911435747649,-3.32277254613695E-5,0.25,-9.12676773059159E-7,-1.1371463659687E-5,-9.93217993916312E-7,19.999094,19.9992123,-42030.49609375,-42010.45703125,57.6935642614676,20.6555090750211,14.936333,0,0,0,40,4449,19.9801,-42020.4765625,,,,,,,,,,,,,0,,,,-0.0049,,,,,,19.99915315,,,,
,27298999.03,19.9990215,-37310.39453125,-1.30811637477755E-5,6.10244210151988E-7,1,0.999253354069792,40.0298881530762,1.98440026336145,25.620000436902,-0.000143695339898347,-4.2033254297554E-5,0.25,-1.39964930192154E-6,-1.30396900501391E-5,-1.4888189701019E-6,19.9990215,19.9990215,-37317.95703125,-37302.83203125,57.5466180998522,20.6561008157807,15.315984,0,0,0,40,4449,19.9811,-37310.39453125,,,,,,,,,,,,,0,,,,-0.0049,,,,,,19.9990215,,,,
,27299095.545,19.9995651,-32488.5908203125,-1.29858699039669E-5,5.14468362514687E-7,1,0.999253354069792,40.0298881530762,1.98464795164692,25.620000436902,-0.000143700892967498,-3.55584762622173E-5,0.25,-8.42331531073568E-7,-1.2942100910828E-5,-9.29304492139247E-7,19.9995651,19.9995651,-32491.28515625,-32485.896484375,57.0127658212176,20.6557221842434,14.556682,0,0,0,40,4449,19.9828,-32488.5908203125,,,,,,,,,,,,,0,,,,0,,,,,,19.9995651,,,,
,27299193.275,19.9981794,-27604.19921875,-1.22656181984686E-5,4.60369441758534E-7,1,0.999253354069792,40.0298881530762,1.98460045560042,25.620000436902,-0.000136690557763612,-2.78246766320542E-5,0.25,-2.85165742381663E-7,-1.2221586230209E-5,-3.65808961531182E-7,19.9981136,19.9982452,-27609.203125,-27599.1953125,57.7936127119292,20.6589921543127,15.315984,0,0,0,40,4449,19.98415,-27604.19921875,,,,,,,,,,,,,0,,,,0,,,,,,19.9981794,,,,
,27299294.28,19.9984207,-22554.056640625,-1.16158567474996E-5,3.82184440512429E-7,1,0.999253354069792,40.0298881530762,1.98455023072282,25.620000436902,-0.000129733721571389,-2.43631692056602E-5,0.25,-9.69029752868338E-8,-1.15693614655837E-5,-1.70523373329272E-7,19.9984207,19.9984207,-22556.494140625,-22551.619140625,57.3449579418907,20.6564437072972,15.315984,0,0,0,40,4449,19.9855,-22554.056640625,,,,,,,,,,,,,0,,,,0,,,,,,19.9984207,,,,
,27299393.01,19.9959202,-17621.9892578125,-1.13110680163079E-5,3.55102648181734E-7,1,0.999253354069792,40.0298881530762,1.98444327955491,25.620000436902,-0.000125210405337982,-2.9593728494873E-5,0.25,-6.24063031519105E-7,-1.1257195843966E-5,-6.89794449240834E-7,19.9959202,19.9959202,-17634.861328125,-17609.1171875,57.8014289971215,20.6549557880353,14.556682,0,0,0,40,4449,19.98605,-17621.9892578125,,,,,,,,,,,,,0,,,,-0.00245,,,,,,19.9959202,,,,
,27299485.655,19.9977398,-12989.1606445313,-1.15708029200241E-5,3.05135418202065E-7,1,0.999253354069792,40.0298881530762,1.98429671862047,25.620000436902,-0.000128435203573778,-2.79586608753916E-5,0.25,-4.36302224716984E-7,-1.15122000100971E-5,-5.00513884274245E-7,19.9977398,19.9977398,-12996.6923828125,-12981.62890625,57.7256110307561,20.6561519641203,14.936333,0,0,0,40,4449,19.9901,-12989.1606445313,,,,,,,,,,,,,0,,,,0,,,,,,19.9977398,,,,
,27299578.555,19.997057,-8346.04833984375,-1.09328588261707E-5,3.51921374198677E-7,1,0.999253354069792,40.0298881530762,1.98447292341367,25.620000436902,-0.000121617271754495,-2.47362455913227E-5,0.25,-2.66178546465003E-7,-1.08742421181711E-5,-3.23752173087376E-7,19.997057,19.997057,-8348.31640625,-8343.7802734375,57.2800827747945,20.657294376824,15.315984,0,0,0,40,4449,19.99285,-8346.04833984375,,,,,,,,,,,,,0,,,,-0.0049,,,,,,19.997057,,,,
,27299673.35,19.9987049,-3607.85791015625,-1.07347069961221E-5,3.46077464221871E-7,1,0.999253354069792,40.0298881530762,1.98430191044805,25.620000436902,-0.000118915800817254,-2.67977896323558E-5,0.25,-4.9061759330565E-7,-1.06724957718084E-5,-5.42148194025463E-7,19.9987049,19.9987049,-3615.31909179687,-3600.39672851562,57.4551675631022,20.6531342109947,14.936333,0,0,0,40,4449,19.9939,-3607.85791015625,,,,,,,,,,,,,0,,,,0,,,,,,19.9987049,,,,
,27299767.43,19.9993629,1093.94012451172,-1.02189201269353E-5,3.59482126687564E-7,1,0.999253354069792,40.0298881530762,1.98427426166307,25.620000436902,-0.000112913703734684,-2.70341559252984E-5,0.25,-6.05476752301989E-7,-1.01576417743205E-5,-6.52059545271475E-7,19.9993629,19.9993629,1086.45275878906,1101.42749023438,57.5403650716984,20.6568323442508,14.936333,0,0,0,40,4449,19.9939,1093.94012451172,,,,,,,,,,,,,0,,,,0.00245,,,,,,19.9993629,,,,
,27299867.875,19.9992905,6112.53564453125,-9.29780911139536E-6,3.58332257589965E-7,1,0.999253354069792,40.0298881530762,1.98429677901153,25.620000436902,-0.000103249989828595,-2.18927577067254E-5,0.25,-3.04977592916427E-7,-9.24604272714483E-6,-3.5196640654448E-7,19.9992905,19.9992905,6102.62255859375,6122.44873046875,57.4004535667561,20.6576006829901,14.936333,0,0,0,40,4449,19.99445,6112.53564453125,,,,,,,,,,,,,0,,,,-0.0049,,,,,,19.9992905,,,,
,27299969.86,19.9997444,11207.86328125,-7.72767501875286E-6,3.96561111331674E-7,1,0.999253354069792,40.0298881530762,1.98433810039034,25.620000436902,-8.56720424815276E-5,-1.9195196596251E-5,0.25,-3.3938091192207E-7,-7.68713365083742E-6,-3.80984097610052E-7,19.9997444,19.9997444,11200.2607421875,11215.4658203125,57.4786164186792,20.6568234617272,14.556682,0,0,0,40,4449,19.995,11207.86328125,,,,,,,,,,,,,0,,,,0,,,,,,19.9997444,,,,
,27300073.675,20.0008507,16397.7578125,-4.76717295407579E-6,4.46001866586635E-7,1,0.999253354069792,40.0298881530762,1.98429276046518,25.620000436902,-5.22510869564693E-5,-1.53263575004314E-5,0.25,-5.18917095451417E-7,-4.74241775482514E-6,-5.45031438464026E-7,20.0008507,20.0008507,16392.826171875,16402.689453125,57.4371901071599,20.6569123817621,15.315984,0,0,0,40,4449,19.9944,16397.7578125,,,,,,,,,,,,,0,,,,0,,,,,,20.0008507,,,,
,27300177.21,20.0007286,21572.4052734375,7.6032011180409E-7,4.12596598151512E-7,1,0.999253354069792,40.0298881530762,1.98423920100511,25.620000436902,8.69290774796357E-6,4.59577320590308E-7,0.25,-9.50833618050075E-8,7.57843187898117E-7,-8.9900170162933E-8,20.0007286,20.0007286,21564.87109375,21579.939453125,57.3942005386022,20.6533661163717,14.936333,0,0,0,40,4449,19.9929,21572.4052734375,,,,,,,,,,,,,0,,,,0,,,,,,20.0007286,,,,
,27300280.99,20.0015411,26760.419921875,5.76805378621194E-6,4.45157615846031E-7,1,0.999253354069792,40.0298881530762,1.98429428435104,25.620000436902,6.55054150733088E-5,6.17002193998902E-6,0.25,-4.8341153276802E-7,5.7509327602187E-6,-4.43580569330062E-7,20.0015411,20.0015411,26748.15234375,26772.6875,57.2527257766214,20.6549994733438,15.315984,0,0,0,40,4449,19.9919,26760.419921875,,,,,,,,,,,,,0,,,,0.00245,,,,,,20.0015411,,,,
,27300385.495,20.001339,31985.25390625,8.85527442020303E-6,6.56377578084554E-7,1,0.999253354069792,40.0298881530762,1.98436029911692,25.620000436902,9.92896109294757E-5,1.69173281652333E-5,0.25,-7.98416444071242E-8,8.82946284230445E-6,-1.88106119938159E-8,20.001339,20.001339,31980.08984375,31990.41796875,57.6325972369676,20.6542790950894,14.936333,0,0,0,40,4449,19.99095,31985.25390625,,,,,,,,,,,,,0,,,,0,,,,,,20.001339,,,,
,27300490.37,20.0016441,37222.451171875,1.0890189433843E-5,5.75541039942665E-7,1,0.999253354069792,40.0298881530762,1.98426399823063,25.620000436902,0.000123021754372214,1.60730557939704E-5,0.25,-5.23852761407608E-7,1.0867510368189E-5,-4.45569607147779E-7,20.0016441,20.0016441,37212.421875,37232.48046875,57.5169162161215,20.6572659583885,14.936333,0,0,0,40,4449,19.9885,37222.451171875,,,,,,,,,,,,,0,,,,0.0049,,,,,,20.0016441,,,,
,27300593.69,20.0021152,42387.224609375,1.07957338490968E-5,5.97625113903519E-7,1,0.999253354069792,40.0298881530762,1.98428425092571,25.620000436902,0.00012142398940377,1.92728634101522E-5,0.25,-2.2376799008962E-7,1.07770797639782E-5,-1.45315073061518E-7,20.0021152,20.0021152,42379.85546875,42394.59375,57.5130080735253,20.6509224972372,14.936333,0,0,0,40,4449,19.9882,42387.224609375,,,,,,,,,,,,,0,,,,0,,,,,,20.0021152,,,,
,27300689.275,20.0031223,47167.8125,1.17150877986835E-5,7.44325973262376E-7,1,0.999253354069792,40.0298881530762,1.984380784776,25.620000436902,0.000129646444749807,3.30822191637418E-5,0.25,8.40296598990883E-7,1.16927502250769E-5,9.25036828162014E-7,20.0031223,20.0031223,47157.703125,47177.921875,57.2769562607176,20.6517203654604,14.936333,0,0,0,40,4449,19.9863,47167.8125,,,,,,,,,,,,,0,,,,0,,,,,,20.0031223,,,,
,27300784.35,20.0018559,51917.87890625,1.28648316652387E-5,5.08209108513797E-7,1,0.999253354069792,40.0298881530762,1.98424020963783,25.620000436902,0.0001423549612472,3.67531403368973E-5,0.25,9.58417588082503E-7,1.28461759890219E-5,1.05276204609417E-6,20.0018559,20.0018559,51915.328125,51920.4296875,57.6990356611023,20.6533165124361,14.556682,0,0,0,40,4449,19.98435,51917.87890625,,,,,,,,,,,,,0,,,,-0.0098,,,,,,20.0018559,,,,
,27300879.595,20.001255,56677.986328125,1.15816746350607E-5,5.00816128624705E-7,1,0.999253354069792,40.0298881530762,1.98437026314868,25.620000436902,0.000131207587568268,1.65521321902677E-5,0.25,-6.12583550802185E-7,1.15812364791919E-5,-5.2619730925634E-7,20.001255,20.001255,56667.890625,56688.08203125,57.4067065949099,20.6553642972538,14.556682,0,0,0,40,4449,19.98285,56677.986328125,,,,,,,,,,,,,0,,,,-0.00245,,,,,,20.001255,,,,
,27300974.71,20.0014324,61433.083984375,1.28529815832523E-5,6.57241073435725E-7,1,0.999253354069792,40.0298881530762,1.98404879635768,25.620000436902,0.000144107015470888,2.69513307313119E-5,0.25,8.42071499218751E-8,1.28525861324741E-5,1.79866725028949E-7,20.0014324,20.0014324,61420.64453125,61445.5234375,57.3449579418907,20.6550781989662,14.936333,0,0,0,40,4449,19.98205,61433.083984375,,,,,,,,,,,,,0,,,,-0.0049,,,,,,20.0014324,,,,
,27301069.925,20.001524,66191.078125,1.01563223134328E-5,7.16294006081741E-7,1,0.999253354069792,40.0298881530762,1.98413787677781,25.620000436902,0.00011512643626382,1.46460431335941E-5,0.25,-5.26323325884684E-7,1.01647739036897E-5,-4.51166088294616E-7,20.001524,20.001524,66183.6953125,66198.4609375,57.4473512779099,20.654397279239,14.936333,0,0,0,40,4449,19.98025,66191.078125,,,,,,,,,,,,,0,,,,0,,,,,,20.001524,,,,
,27301167.235,20.0016956,71056.6953125,1.20037670847813E-5,7.02579208719133E-7,1,0.999253354069792,40.0298881530762,1.98405457163463,25.620000436902,0.000137712074195155,8.47496229651457E-6,0.25,-1.40849778070091E-6,1.20245432746385E-5,-1.32112105123655E-6,20.0016956,20.0016956,71051.625,71061.765625,57.4512594205061,20.6548276976581,15.315984,0,0,0,40,4449,19.9788,71056.6953125,,,,,,,,,,,,,0,,,,-0.00245,,,,,,20.0016956,,,,
,27301262.595,20.0019627,75822.34765625,1.27514251708295E-5,8.03647751086861E-7,1,0.999253354069792,40.0298881530762,1.98412838649871,25.620000436902,0.000144880585362862,1.71651567187283E-5,0.25,-7.69531790869751E-7,1.27730158294237E-5,-6.77159084111331E-7,20.0019627,20.0019627,75819.90625,75824.7890625,57.3559007411599,20.6565589297412,14.936333,0,0,0,40,4449,19.9771,75822.34765625,,,,,,,,,,,,,0,,,,-0.00245,,,,,,20.0019627,,,,
,27301358.195,20.002121,80598.38671875,1.30478252203676E-5,8.47798124555652E-7,1,0.999253354069792,40.0298881530762,1.98410012763918,25.620000436902,0.000147243855725787,2.34341750864872E-5,0.25,-2.64852234876163E-7,1.30708410220521E-5,-1.70780259093822E-7,20.002121,20.002121,80593.4375,80603.3359375,57.312129544083,20.6564729297869,15.315984,0,0,0,40,4449,19.9752,80598.38671875,,,,,,,,,,,,,0,,,,0,,,,,,20.002121,,,,
,27301454.055,20.0020676,85394.03125,1.1660803826877E-5,9.15623381072275E-7,1,0.999253354069792,40.0298881530762,1.98417084519182,25.620000436902,0.000129050402487578,3.53475724747216E-5,0.25,1.04428320406092E-6,1.16762130200181E-5,1.12973025970803E-6,20.0020676,20.0020676,85386.578125,85401.484375,57.3895107674868,20.6499347816277,14.936333,0,0,0,40,4449,19.97285,85394.03125,,,,,,,,,,,,,0,,,,0,,,,,,20.0020676,,,,
,27301544.32,20.0019407,89904.36328125,8.08562642627022E-6,9.19327365430506E-7,1,0.999253354069792,40.0298881530762,1.98397747053413,25.620000436902,9.3767559120361E-5,8.04322689383137E-7,0.25,-1.3825990088167E-6,8.11371209147218E-6,-1.32867308906167E-6,20.0018463,20.0020351,89899.1640625,89909.5625,57.3777863396984,20.6550600007958,14.936333,0,0,0,40,4449,19.972,89904.36328125,,,,,,,,,,,,,0,,,,0,,,,,,20.0019407,,,,
,27301652.12,20.0005741,85793.73046875,1.07425552609874E-5,9.78852594235661E-7,1,0.999253354069792,40.0298881530762,1.98398908132782,25.620000436902,0.000122073301094883,1.48205670381309E-5,0.25,-6.15223508830217E-7,1.07683251472948E-5,-5.39703393191013E-7,20.0005741,20.0005741,85788.984375,85798.4765625,57.3097846585253,20.6549832670282,15.315984,0,0,0,40,4449,19.9717,85793.73046875,,,,,,,,,,,,,0,,,,0,,,,,,20.0005741,,,,
,27301744.695,19.9991436,81162.7734375,9.21318314194167E-6,6.91563458859635E-7,1,0.999253354069792,40.0298881530762,1.98403436315562,25.620000436902,0.000104429246744564,1.40027307149258E-5,0.25,-4.13218905000517E-7,9.23145345766678E-6,-3.47269178550025E-7,19.9991436,19.9991436,81155.171875,81170.375,57.69121937591,20.6529671966091,14.936333,0,0,0,40,4449,19.972,81162.7734375,,,,,,,,,,,,,0,,,,0,,,,,,19.9991436,,,,
,27301842.155,19.9985199,76294.0078125,1.19669225721666E-5,6.4254626829341E-7,1,0.999253354069792,40.0298881530762,1.98385343217841,25.620000436902,0.000133782645452896,2.81640423142176E-5,0.25,3.50664411553956E-7,1.19797779473321E-5,4.38626693942969E-7,19.9985199,19.9985199,76281.65625,76306.359375,57.7756352559869,20.655385739195,14.936333,0,0,0,40,4449,19.9728,76294.0078125,,,,,,,,,,,,,0,,,,0,,,,,,19.9985199,,,,
,27301935.83,19.999218,71610.46484375,1.22808116453217E-5,6.97374595743704E-7,1,0.999253354069792,40.0298881530762,1.98402707518942,25.620000436902,0.000136780943372572,3.150437821556E-5,0.25,5.91386320213301E-7,1.22876361540203E-5,6.82488778111712E-7,19.999218,19.999218,71603.0390625,71617.890625,57.6341604940061,20.6530042188195,15.315984,0,0,0,40,4449,19.9746,71610.46484375,,,,,,,,,,,,,0,,,,-0.00245,,,,,,19.999218,,,,
,27302029.68,19.998558,66920.1953125,1.31219119672799E-5,7.12218768377087E-7,1,0.999253354069792,40.0298881530762,1.98393515651726,25.620000436902,0.000148257094006327,2.15884634551327E-5,0.25,-4.42494414283209E-7,1.31319050475794E-5,-3.45379235615407E-7,19.998558,19.998558,66910.2734375,66930.1171875,57.3957637956407,20.6535945913323,14.556682,0,0,0,40,4449,19.9755,66920.1953125,,,,,,,,,,,,,0,,,,-0.0049,,,,,,19.998558,,,,
,27302126.61,19.9982567,62074.181640625,1.3527489007721E-5,6.34360441806268E-7,1,0.999253354069792,40.0298881530762,1.98423915682914,25.620000436902,0.000152370504127977,2.46080150966948E-5,0.25,-2.46436362764009E-7,1.35303647555997E-5,-1.45793139952302E-7,19.9982567,19.9982567,62066.609375,62081.75390625,57.3043132588907,20.6517719143239,14.936333,0,0,0,40,4449,19.9774,62074.181640625,,,,,,,,,,,,,0,,,,-0.00245,,,,,,19.9982567,,,,
,27302223.42,19.9987316,57233.654296875,1.19783135065696E-5,9.2911150263715E-7,1,0.999253354069792,40.0298881530762,1.98431370868903,25.620000436902,0.000136406755583558,1.32242028921043E-5,0.25,-9.80685748619874E-7,1.19810836348211E-5,-8.91217601432415E-7,19.9987316,19.9987316,57228.6796875,57238.62890625,57.0831123879483,20.65148107372,14.936333,0,0,0,40,4449,19.9787,57233.654296875,,,,,,,,,,,,,0,,,,0.0049,,,,,,19.9987316,,,,
,27302316.71,19.9989681,52573.73046875,1.35553551312582E-5,5.94903543804149E-7,1,0.999253354069792,40.0298881530762,1.9842607523204,25.620000436902,0.000155080809148434,1.05762311765771E-5,0.25,-1.50006838111896E-6,1.35551689096174E-5,-1.39841045734592E-6,19.9989681,19.9989681,52561.10546875,52586.35546875,57.4262473078907,20.6502641101458,14.936333,0,0,0,40,4449,19.9787,52573.73046875,,,,,,,,,,,,,0,,,,-0.00245,,,,,,19.9989681,,,,
,27302411.475,19.9992695,47836.1875,1.11653835869749E-5,6.78009665120956E-7,1,0.999253354069792,40.0298881530762,1.98434899029971,25.620000436902,0.000127681001320721,8.71051438334152E-6,0.25,-1.23465858283305E-6,1.11597994612547E-5,-1.15103864097044E-6,19.9992695,19.9992695,47833.6484375,47838.7265625,57.6107116384292,20.6521344267906,14.936333,0,0,0,40,4449,19.98035,47836.1875,,,,,,,,,,,,,0,,,,0,,,,,,19.9992695,,,,
,27302507.34,19.9982719,43045.71875,1.07534143449113E-5,5.75119889466145E-7,1,0.999253354069792,40.0298881530762,1.98437735172938,25.620000436902,0.000121766540128947,1.47303902393784E-5,0.25,-6.21849352465116E-7,1.07384684056275E-5,-5.42819255766635E-7,19.9982719,19.9982719,43040.54296875,43050.89453125,57.3824761108138,20.6500031645583,15.315984,0,0,0,40,4449,19.98065,43045.71875,,,,,,,,,,,,,0,,,,0,,,,,,19.9982719,,,,
,27302604.605,19.9989815,38183.263671875,1.26927911219131E-5,5.84594943751358E-7,1,0.999253354069792,40.0298881530762,1.98459158168752,25.620000436902,0.000141554225435728,2.9122094151568E-5,0.25,3.1593452762461E-7,1.26610856422656E-5,4.05376329787163E-7,19.9989815,19.9989815,38178.3984375,38188.12890625,57.5896076684099,20.649345705701,14.936333,0,0,0,40,4449,19.98165,38183.263671875,,,,,,,,,,,,,0,,,,-0.00245,,,,,,19.9989815,,,,
,27302698.995,19.9990387,33465.7734375,1.1729078163093E-5,6.39972080855287E-7,1,0.999253354069792,40.0298881530762,1.98462577984314,25.620000436902,0.000132915036177071,1.48173426681236E-5,0.25,-7.84906873272581E-7,1.17014340037697E-5,-7.01427196446359E-7,19.9990387,19.9990387,33455.85546875,33475.69140625,57.241001348833,20.6464709006473,15.315984,0,0,0,40,4449,19.98305,33465.7734375,,,,,,,,,,,,,0,,,,-0.00245,,,,,,19.9990387,,,,
,27302794.86,19.9983711,28675.6943359375,1.14978456522707E-5,4.8965371535807E-7,1,0.999253354069792,40.0298881530762,1.9845162724767,25.620000436902,0.000129838217586121,1.66435336881832E-5,0.25,-5.76910948153288E-7,1.14634992583579E-5,-4.97851706762109E-7,19.9983711,19.9983711,28663.349609375,28688.0390625,57.5528711280061,20.6463087177524,14.936333,0,0,0,40,4449,19.98355,28675.6943359375,,,,,,,,,,,,,0,,,,0,,,,,,19.9983711,,,,
,27302889.275,19.9995899,23955.4814453125,1.21328633167578E-5,4.86901339800902E-7,1,0.999253354069792,40.0298881530762,1.98464679110508,25.620000436902,0.000136904637265236,1.78028512791538E-5,0.25,-5.83544612016659E-7,1.20904173227447E-5,-5.03018624002838E-7,19.9995899,19.9995899,23950.546875,23960.416015625,57.0315249056791,20.6484710498796,15.315984,0,0,0,40,4449,19.98515,23955.4814453125,,,,,,,,,,,,,0,,,,0.0049,,,,,,19.9995899,,,,
,27302987.525,19.9978218,19045.7763671875,1.20178503011678E-5,4.13636775642243E-7,1,0.999253354069792,40.0298881530762,1.98447157837044,25.620000436902,0.0001349973446333,2.05850582096711E-5,0.25,-3.09536632348099E-7,1.19681576349818E-5,-2.34296676996216E-7,19.9978218,19.9978218,19043.25,19048.302734375,57.2191157502945,20.6534836274477,14.936333,0,0,0,40,4449,19.9869,19045.7763671875,,,,,,,,,,,,,0,,,,-0.00245,,,,,,19.9978218,,,,
,27303084.62,19.9967594,14193.6875,1.10600525126818E-5,3.88270424055763E-7,1,0.999253354069792,40.0298881530762,1.98443587156687,25.620000436902,0.000124405132320159,1.76683195738671E-5,0.25,-3.94574343112195E-7,1.1009893454075E-5,-3.28351935885522E-7,19.9967594,19.9967594,14185.86328125,14201.51171875,57.6044586102753,20.6520073530339,14.556682,0,0,0,40,4449,19.9891,14193.6875,,,,,,,,,,,,,0,,,,0,,,,,,19.9967594,,,,
,27303179.36,19.9969044,9456.71337890625,1.0970350902583E-5,3.28179819841425E-7,1,0.999253354069792,40.0298881530762,1.98446543010045,25.620000436902,0.000122761344479515,2.08009141171224E-5,0.25,-9.37876723544511E-8,1.09144425126839E-5,-3.3243163402108E-8,19.9969044,19.9969044,9449.0322265625,9464.39453125,56.9815006804483,20.6549740201314,14.556682,0,0,0,40,4449,19.9915,9456.71337890625,,,,,,,,,,,,,0,,,,0,,,,,,19.9969044,,,,
,27303274.365,19.9982986,4708.21606445313,1.10657148170296E-5,3.19647852648545E-7,1,0.999253354069792,40.0298881530762,1.98437924113106,25.620000436902,0.000124735797771725,1.559618128528E-5,0.25,-5.72210968732252E-7,1.10078665845682E-5,-5.12293065917452E-7,19.9982986,19.9982986,4700.87060546875,4715.5615234375,57.4496961634676,20.6540710906335,14.936333,0,0,0,40,4449,19.993,4708.21606445313,,,,,,,,,,,,,0,,,,-0.00245,,,,,,19.9982986,,,,
,27303367.625,19.9995708,26.1970283389091,1.07013755320977E-5,3.39365006875102E-7,1,0.999253354069792,40.0298881530762,1.98439600364843,25.620000436902,0.000120288706158281,1.68130431824312E-5,0.25,-3.95007378911489E-7,1.06417578684553E-5,-3.40873395161073E-7,19.9995708,19.9995708,0.289251685142517,52.1048049926758,57.2370932062368,20.6538132441594,15.315984,0,0,0,40,4449,19.99305,26.1970283389091,,,,,,,,,,,,,0,,,,0.00245,,,,,,19.9995708,,,,
,27303370.035,19.9991665,0.228356599807739,1.08648362865621E-5,3.317419355002E-7,1,0.999253354069792,40.0298881530762,1.9843588094843,25.620000436902,0.000121518079621186,2.04803352177112E-5,0.25,-9.56020592462228E-8,1.0802822378307E-5,-4.2403569297531E-8,19.9991665,19.9991665,0.213132828474045,0.243580371141434,57.0901470446214,20.6537453823007,14.556682,0,0,0,40,4417,19.9935,0.228356599807739,,,,,,,,,,,,,0,,,,-0.0049,,,,,,19.9991665,,,,