File: data/looselyPackedNP/sc-ios-7/ppms/rawdata/ES_S17_HYST_30K_ZFC.DAT
[Header]
; VSM Data File (default extension .dat)
; Copyright (c) 2003-2013, Quantum Design, Inc. All rights reserved.
TITLE,
FILEOPENTIME,29383378.75,12/07/2018,10:04 am
BYAPP,VSM,2.0,2.0
INFO,PPMS VSM Option Release 1.4.10 Build 1,APPNAME
INFO,Quantum Design Linear Motor Servo Controller,MOTOR_MODULE_NAME
INFO,3101-100 M1,MOTOR_HW_VERSION
INFO,MMC1014,MOTOR_SERIAL_NUMBER
INFO,SRV No X-over 01.03.11,MOTOR_SOFTWARE_VERSION
INFO,Quantum Design VSM Detection Module,VSM_MODULE_NAME
INFO,3101-150 F0,VSM_HW_VERSION
INFO,VSM707,VSM_SERIAL_NUMBER
INFO,VSM No X-over 01.02.05 May 20 2008 13:51:47,VSM_SOFTWARE_VERSION
INFO,704,PREAMP_SERIAL_NUMBER
INFO,822,COIL_SERIAL_NUMBER
INFO,0,MOMENT_UNITS
INFO,Iron Oxide Spheres,SAMPLE_MATERIAL
INFO,7 nm diameter, collaboration Mainz,SAMPLE_COMMENT
INFO,,SAMPLE_MASS
INFO,,SAMPLE_VOLUME
INFO,,SAMPLE_MOLECULAR_WEIGHT
INFO,,SAMPLE_SIZE
INFO,,SAMPLE_SHAPE
DATATYPE,COMMENT,1
DATATYPE,TIME,2
STARTUPAXIS,X,2
STARTUPAXIS,Y1,5
[Data]
Comment,Time Stamp (sec),Temperature (K),Magnetic Field (Oe),Moment (emu),M. Std. Err. (emu),Transport Action,Averaging Time (sec),Frequency (Hz),Peak Amplitude (mm),Center Position (mm),Coil Signal' (mV),Coil Signal" (mV),Range (mV),M. Quad. Signal (emu),M. Raw' (emu),M. Raw" (emu),Min. Temperature (K),Max. Temperature (K),Min. Field (Oe),Max. Field (Oe),Mass (grams),Motor Lag (deg),Pressure (Torr),VSM Status (code),Motor Status (code),Measure Status (code),Measure Count,PPMS Status (code),System Temp. (K),System Field (Oe),Sample Position (deg),Bridge 1 Resistance (ohms),Bridge 1 Excitation (에),Bridge 2 Resistance (ohms),Bridge 2 Excitation (에),Bridge 3 Resistance (ohms),Bridge 3 Excitation (에),Bridge 4 Resistance (ohms),Bridge 4 Excitation (에),Signal 1 Vin (V),Signal 2 Vin (V),Digital Inputs (code),Drive 1 Iout (mA),Drive 1 Ipower (W),Drive 2 Iout (mA),Drive 2 Ipower (W),Pressure (),Map 20 (),Map 21 (),Map 22 (),Map 23 (),Map 24 (),Map 25 (),Map 26 (),Map 27 (),Map 28 (),Map 29 ()
,29383394.5,29.9992981,-0.0152237731963396,,,2,,,,16.730000397265,,,,,,,29.9992981,29.9992981,-0.0152237731963396,-0.0152237731963396,,,16.075285,,,,-99999999,4369,29.9958,-0.0152237731963396,,,,,,,,,,,,,,,,,,,,,,,29.9992981,,,,
,29383468.165,30.032095,338.467651367188,4.15703369877274E-5,3.12434669543017E-7,1,0.999253354069792,40.0298881530762,1.99163065379105,16.720000654459,0.000465589517809846,8.57053725084535E-5,0.25,2.34198466540053E-7,4.13535585472751E-5,4.61023912096664E-7,30.032095,30.032095,333.196838378906,343.738464355469,56.4406137451406,20.6637195550661,15.695635,0,0,0,40,4449,29.96565,338.467651367188,,,,,,,,,,,,,0,,,,0,,,,,,30.032095,,,,
,29383485.01,30.0322266,758.860900878906,7.03347465755667E-5,3.78990976314181E-7,1,0.999253354069792,40.0298881530762,1.99156481490833,16.7299993336201,0.000788033476090384,0.000143362998320272,0.25,2.48568381468346E-7,6.99699481081643E-5,6.34186411885186E-7,30.0322266,30.0322266,755.401977539063,762.31982421875,56.6500901882945,20.6649269139953,16.075285,0,0,0,40,4449,29.95125,758.860900878906,,,,,,,,,,,,,0,,,,0.00245,,,,,,30.0322266,,,,
,29383501.46,30.02278515,1168.47998046875,8.44160356169438E-5,3.25421832858283E-7,1,0.999253354069792,40.0298881530762,1.99166144721647,16.720000654459,0.000945105454839248,0.000176328927810372,0.25,6.76109063189309E-7,8.39777997716073E-5,1.13851826608921E-6,30.0226402,30.0229301,1163.41174316406,1173.54821777344,56.4101302328906,20.6637263192884,16.075285,0,0,0,40,4449,29.9503,1168.47998046875,,,,,,,,,,,,,0,,,,0,,,,,,30.02278515,,,,
,29383518.555,30.025774,1594.82208251953,9.22192589215637E-5,3.42016897638354E-7,1,0.999253354069792,40.0298881530762,1.99129578605672,16.7299993336201,0.0010322547197518,0.000192917160096497,0.25,7.65092906515543E-7,9.17424551354358E-5,1.2720243618317E-6,30.025774,30.025774,1589.89733886719,1599.74682617187,56.6797920720252,20.6707133358533,16.454937,0,0,0,40,4449,29.9536,1594.82208251953,,,,,,,,,,,,,0,,,,0,,,,,,30.025774,,,,
,29383534.615,30.0235271,1995.828125,9.59052683455147E-5,3.47881584370181E-7,1,0.999253354069792,40.0298881530762,1.99120114379946,16.720000654459,0.00107298257903674,0.000203458356553131,0.25,1.04676821788683E-6,9.54100354578206E-5,1.57451937247803E-6,30.0235271,30.0235271,1992.05078125,1999.60546875,56.8337728903137,20.6690534734401,16.454937,0,0,0,40,4449,29.9442,1995.828125,,,,,,,,,,,,,0,,,,-0.00245,,,,,,30.0235271,,,,
,29383551.305,30.0197411,2410.99291992187,9.88244687401869E-5,3.34685965392685E-7,1,0.999253354069792,40.0298881530762,1.9911940440844,16.7299993336201,0.00110527039862814,0.000211868919208799,0.25,1.2739769804305E-6,9.83154164551361E-5,1.81892276003973E-6,30.0197411,30.0197411,2404.72412109375,2417.26171875,56.6454004171791,20.6727875945976,16.454937,0,0,0,40,4449,29.94265,2410.99291992187,,,,,,,,,,,,,0,,,,0.00245,,,,,,30.0197411,,,,
,29383567.715,30.015625,2821.20483398438,9.91985495201894E-5,3.96747835931176E-7,1,0.999253354069792,40.0298881530762,1.99123686652647,16.720000654459,0.00110936262756061,0.000213478384152864,0.25,1.34776554149438E-6,9.86896591453024E-5,1.8966556701903E-6,30.015625,30.015625,2818.59912109375,2823.810546875,56.9955699937945,20.6702329617633,16.075285,0,0,0,40,4449,29.9472,2821.20483398438,,,,,,,,,,,,,0,,,,0,,,,,,30.015625,,,,
,29383583.095,30.0122814,3204.68859863281,9.98386878049915E-5,3.35892008806303E-7,1,0.999253354069792,40.0298881530762,1.99146328130504,16.720000654459,0.00111764220851234,0.000209428191478791,0.25,8.67785963375724E-7,9.93315759427017E-5,1.42474715578828E-6,30.0122814,30.0122814,3200.96630859375,3208.41088867188,56.9580518248714,20.6695532195127,16.075285,0,0,0,40,4449,29.94405,3204.68859863281,,,,,,,,,,,,,0,,,,-0.0049,,,,,,30.0122814,,,,
,29383599.625,30.0433311,3618.27355957031,9.95521552321993E-5,4.3899568422363E-7,1,0.999253354069792,40.0298881530762,1.98956800544329,16.720000654459,0.0011149381463052,0.000200305581982979,0.25,1.18810005769138E-7,9.90532519095765E-5,6.80157471333611E-7,30.0433311,30.0433311,3613.27099609375,3623.27612304687,56.8376810329099,20.6993972107773,16.454937,0,0,0,40,4449,29.94,3618.27355957031,,,,,,,,,,,,,0,,,,-0.00245,,,,,,30.0433311,,,,
,29383615.875,30.024786,4023.37817382812,9.93747153431058E-5,3.91527046743148E-7,1,0.999253354069792,40.0298881530762,1.99082421049841,16.720000654459,0.0011134027181143,0.000201450343245162,0.25,2.39410723609219E-7,9.8878355541068E-5,8.01152176068132E-7,30.024786,30.024786,4020.82885742188,4025.92749023438,56.8408075469868,20.6823906604797,15.695635,0,0,0,40,4449,29.9131,4023.37817382812,,,,,,,,,,,,,0,,,,-0.0049,,,,,,30.024786,,,,
,29383632.86,30.0256519,4449.60400390625,9.79062880840389E-5,3.74024435441116E-7,1,0.999253354069792,40.0298881530762,1.99006712232379,16.720000654459,0.0010957569336828,0.000203054269975509,0.25,6.4799138336536E-7,9.74179414833091E-5,1.20196820308955E-6,30.0256519,30.0256519,4448.35986328125,4450.84814453125,56.8986480574099,20.6947031114177,16.075285,0,0,0,40,4449,29.9352,4449.60400390625,,,,,,,,,,,,,0,,,,0.00245,,,,,,30.0256519,,,,
,29383649.43,30.0327415,4863.07739257812,9.6160022604719E-5,3.45198668583852E-7,1,0.999253354069792,40.0298881530762,1.9896960237214,16.720000654459,0.0010760056009207,0.00019965039041391,0.25,6.56438250217337E-7,9.56828020377774E-5,1.20259079348687E-6,30.0327415,30.0327415,4858.07470703125,4868.080078125,56.8931766577752,20.7019179823071,16.454937,0,0,0,40,4449,29.9201,4863.07739257812,,,,,,,,,,,,,0,,,,0.00245,,,,,,30.0327415,,,,
,29383666.765,30.0266495,5295.40966796875,9.40015724917411E-5,3.99111287079029E-7,1,0.999253354069792,40.0298881530762,1.98968610399433,16.720000654459,0.00105202424049352,0.000194358795867243,0.25,5.66707303840393E-7,9.35382078343264E-5,1.10325048245921E-6,30.0266495,30.0266495,5292.68359375,5298.1357421875,57.0221453634483,20.7093857891769,15.695635,0,0,0,40,4449,29.9106,5295.40966796875,,,,,,,,,,,,,0,,,,-0.0049,,,,,,30.0266495,,,,
,29383682.305,30.0252838,5685.10668945313,9.27623477126095E-5,4.59144922819392E-7,1,0.999253354069792,40.0298881530762,1.98945554490256,16.720000654459,0.00103908175249423,0.000186110047390642,0.25,5.09505711275502E-8,9.23105676291036E-5,5.85015309957746E-7,30.0252838,30.0252838,5680,5690.21337890625,57.0612267894099,20.7038599616946,15.695635,0,0,0,40,4449,29.91085,5685.10668945313,,,,,,,,,,,,,0,,,,0,,,,,,30.0252838,,,,
,29383699.16,30.0239048,6104.90234375,9.15676556701589E-5,3.67193913939401E-7,1,0.999253354069792,40.0298881530762,1.98964772501128,16.720000654459,0.00102361581287731,0.000196106858300591,0.25,1.15225495158497E-6,9.11180571773132E-5,1.67634113122771E-6,30.0239048,30.0239048,6099.5185546875,6110.2861328125,56.953362053756,20.7017334867849,16.454937,0,0,0,40,4449,29.90835,6104.90234375,,,,,,,,,,,,,0,,,,0,,,,,,30.0239048,,,,
,29383715.64,30.0203915,6517.4609375,9.08513669102668E-5,4.38500266876102E-7,1,0.999253354069792,40.0298881530762,1.98951212016627,16.720000654459,0.00101457818334833,0.000200134556574326,0.25,1.6381100787348E-6,9.04050892671588E-5,2.15792940095911E-6,30.0203915,30.0203915,6515.06884765625,6519.85302734375,56.9619599674676,20.7071510434727,16.075285,0,0,0,40,4449,29.90515,6517.4609375,,,,,,,,,,,,,0,,,,0,,,,,,30.0203915,,,,
,29383732.93,30.0197754,6949.330078125,8.92650794457291E-5,4.96676634032811E-7,1,0.999253354069792,40.0298881530762,1.98965594784286,16.720000654459,0.000999514071041079,0.000182382453018482,0.25,3.32992956944068E-7,8.88368450778689E-5,8.52150324714135E-7,30.0197754,30.0197754,6944.513671875,6954.146484375,57.0096393071407,20.7035156089155,16.075285,0,0,0,40,4449,29.90405,6949.330078125,,,,,,,,,,,,,0,,,,0,,,,,,30.0197754,,,,
,29383766.985,30.0152893,7271.6025390625,8.75609170873481E-5,5.05141665758195E-7,1,0.999253354069792,40.0298881530762,1.99001689304887,16.720000654459,0.000984069815557915,0.000159656646027112,0.25,-1.39533177729699E-6,8.7153027896506E-5,-8.76242379301112E-7,30.0152893,30.0152893,7269.3720703125,7273.8330078125,57.0330881627176,20.7013437132131,15.695635,0,0,0,40,4449,29.9019,7271.6025390625,,,,,,,,,,,,,0,,,,-0.0049,,,,,,30.0152893,,,,
,29383783.995,30.0126991,6850.58276367187,8.85537111410462E-5,4.51811483688679E-7,1,0.999253354069792,40.0298881530762,1.98953942469429,16.720000654459,0.000993662663006511,0.000168729640813363,0.25,-7.56948894061859E-7,8.81345555491217E-5,-2.37267159403294E-7,30.0126991,30.0126991,6847.0224609375,6854.14306640625,57.1878506095253,20.7050756324661,16.454937,0,0,0,40,4449,29.90155,6850.58276367187,,,,,,,,,,,,,0,,,,-0.00245,,,,,,30.0126991,,,,
,29383801.085,30.0175533,6424.08813476563,9.1104273514992E-5,3.97433083467886E-7,1,0.999253354069792,40.0298881530762,1.98928944824456,16.720000654459,0.00102032617994886,0.000183646257868122,0.25,1.23659989782773E-7,9.06648950021178E-5,6.51679283707882E-7,30.0175533,30.0175533,6420.31103515625,6427.865234375,57.1558038402368,20.7054881826602,16.075285,0,0,0,40,4449,29.89935,6424.08813476563,,,,,,,,,,,,,0,,,,0,,,,,,30.0175533,,,,
,29383817.63,30.0131683,6009.92260742188,9.32259056078552E-5,4.97085988345743E-7,1,0.999253354069792,40.0298881530762,1.98937186435485,16.720000654459,0.00104426691693549,0.000186970513775545,0.25,4.36716515845358E-8,9.27739216709568E-5,5.82076647266004E-7,30.0131683,30.0131683,6008.7421875,6011.10302734375,57.1198489283522,20.7057086311541,15.695635,0,0,0,40,4449,29.8947,6009.92260742188,,,,,,,,,,,,,0,,,,-0.0049,,,,,,30.0131683,,,,
,29383833.86,30.012207,5605.814453125,9.26636688918447E-5,5.18789894631218E-7,1,0.999253354069792,40.0298881530762,1.98934560017391,16.720000654459,0.00103720806534096,0.00018985602274129,0.25,4.0451071692947E-7,9.22096781959207E-5,9.35738862084018E-7,30.012207,30.012207,5602.1474609375,5609.4814453125,57.3887291389676,20.7061835829796,16.075285,0,0,0,40,4449,29.89725,5605.814453125,,,,,,,,,,,,,0,,,,0.0049,,,,,,30.012207,,,,
,29383850.025,30.0098057,5203.31420898438,9.47215035874891E-5,4.35917384415423E-7,1,0.999253354069792,40.0298881530762,1.98955147639049,16.720000654459,0.00106022309236256,0.000194609178401331,0.25,4.6241050296644E-7,9.42544780465814E-5,1.00297150991983E-6,30.0098057,30.0098057,5200.42529296875,5206.203125,57.1182856713137,20.7042654902578,15.695635,0,0,0,40,4449,29.89765,5203.31420898438,,,,,,,,,,,,,0,,,,0.00245,,,,,,30.0098057,,,,
,29383866.7,30.0081005,4785.6708984375,9.70382571744928E-5,4.83266273891879E-7,1,0.999253354069792,40.0298881530762,1.98937069371372,16.720000654459,0.00108730242895446,0.000192209787696657,0.25,-1.61004086082866E-7,9.65606268523847E-5,3.93548331847413E-7,30.0081005,30.0081005,4782.84326171875,4788.49853515625,57.1104693861214,20.7030071247917,16.075285,0,0,0,40,4449,29.8968,4785.6708984375,,,,,,,,,,,,,0,,,,-0.00245,,,,,,30.0081005,,,,
,29383884.085,30.0063667,4352.27587890625,9.79894511119853E-5,4.36994899292102E-7,1,0.999253354069792,40.0298881530762,1.98955740550576,16.720000654459,0.00109830700379566,0.000192531588896687,0.25,-3.00652697999623E-7,9.75050311489159E-5,2.57593215560246E-7,30.0063667,30.0063667,4348.2919921875,4356.259765625,56.9815006804483,20.6961124088453,16.075285,0,0,0,40,4449,29.89635,4352.27587890625,,,,,,,,,,,,,0,,,,-0.00245,,,,,,30.0063667,,,,
,29383901.6,30.0024319,3913.93090820313,9.86016904502669E-5,3.73979214401347E-7,1,0.999253354069792,40.0298881530762,1.98970524245948,16.720000654459,0.00110491413644081,0.000195428308586164,0.25,-1.49603644867027E-7,9.8110488326129E-5,4.0892150158533E-7,30.0024319,30.0024319,3908.64453125,3919.21728515625,57.119067299833,20.6990855895395,16.075285,0,0,0,40,4449,29.8951,3913.93090820313,,,,,,,,,,,,,0,,,,0.0049,,,,,,30.0024319,,,,
,29383919.805,30.0008183,3459.58349609375,9.98109746308022E-5,3.95773502627804E-7,1,0.999253354069792,40.0298881530762,1.9898344770872,16.720000654459,0.00111876446635816,0.000196362246996602,0.25,-2.80157449815244E-7,9.93116245373781E-5,2.83421877326285E-7,30.0008183,30.0008183,3456.82885742188,3462.33813476562,57.1862873524868,20.6985234916541,15.695635,0,0,0,40,4449,29.9034,3459.58349609375,,,,,,,,,,,,,0,,,,0,,,,,,30.0008183,,,,
,29383938.135,29.9976101,3001.34094238281,0.000100601736244389,4.09141257946353E-7,1,0.999253354069792,40.0298881530762,1.98999844298583,16.720000654459,0.00112591957096698,0.000207816776272877,0.25,6.02801640632833E-7,0.00010009054585535,1.16385402377432E-6,29.9976101,29.9976101,2997.38818359375,3005.29370117188,57.1581487257945,20.6966168544437,16.075285,0,0,0,40,4449,29.9023,3001.34094238281,,,,,,,,,,,,,0,,,,0,,,,,,29.9976101,,,,
,29383956.425,29.9966354,2544.32702636719,9.95510577396673E-5,3.91157215615656E-7,1,0.999253354069792,40.0298881530762,1.98992288401749,16.720000654459,0.0011153978415147,0.000198295973784153,0.25,-5.60036052706015E-8,9.90461094795945E-5,5.00067716697294E-7,29.9966354,29.9966354,2538.24536132813,2550.40869140625,56.9166255133522,20.6977635125438,16.454937,0,0,0,40,4449,29.90395,2544.32702636719,,,,,,,,,,,,,0,,,,-0.00245,,,,,,29.9966354,,,,
,29383974.57,30.0112476,2091.67456054687,9.75910256771716E-5,3.666338053407E-7,1,0.999253354069792,40.0298881530762,1.98885324609052,16.720000654459,0.0010939228966933,0.000188249287525484,0.25,-5.91786252386718E-7,9.70963832411197E-5,-4.6234998109732E-8,30.0112476,30.0112476,2087.76977539062,2095.57934570313,57.3097846585253,20.7051017271571,16.454937,0,0,0,40,4449,29.9023,2091.67456054687,,,,,,,,,,,,,0,,,,-0.00245,,,,,,30.0112476,,,,
,29383989.39,30.012866,1720.95965576172,9.45797988455854E-5,4.11651781634289E-7,1,0.999253354069792,40.0298881530762,1.988940996196,16.720000654459,0.00105968532058541,0.000185274311672809,0.25,-3.18907830519051E-7,9.40968893670628E-5,2.06635032415705E-7,30.0123272,30.0134048,1703.38098144531,1738.53833007813,57.1526773261599,20.7073604308556,16.075285,0,0,0,40,4449,29.8898,1720.95965576172,,,,,,,,,,,,,0,,,,0.00245,,,,,,30.012866,,,,
,29384006.78,30.006176,1285.82391357422,8.96877753995314E-5,3.23810511072951E-7,1,0.999253354069792,40.0298881530762,1.98885806427101,16.720000654459,0.00100384525227592,0.000181094863238305,0.25,1.8307495791118E-7,8.92250691257535E-5,6.77056124829128E-7,30.0058575,30.0064945,1283.35595703125,1288.29187011719,57.0018230219483,20.7005243940384,15.695635,0,0,0,40,4449,29.88965,1285.82391357422,,,,,,,,,,,,,0,,,,-0.00245,,,,,,30.006176,,,,
,29384024.43,30.0094585,844.793029785156,7.90101434309062E-5,3.22263360544214E-7,1,0.999253354069792,40.0298881530762,1.98888402775106,16.720000654459,0.000884761772536276,0.000157087599365123,0.25,-5.56047844382391E-8,7.86020036790611E-5,3.79126153638441E-7,30.0094585,30.0094585,835.793151855469,853.792907714844,57.2886806885061,20.6962952859557,16.454937,0,0,0,40,4449,29.89245,844.793029785156,,,,,,,,,,,,,0,,,,-0.00245,,,,,,30.0094585,,,,
,29384042.04,30.0065613,404.944473266602,5.86107714101151E-5,3.2326052824647E-7,1,0.999253354069792,40.0298881530762,1.98895631903285,16.720000654459,0.000655848357214819,0.000119275163960597,0.25,2.04882652930934E-7,5.83054807290089E-5,5.25016030105784E-7,30.0065613,30.0065613,401.081024169922,408.807922363281,57.088583787583,20.6955984717315,16.454937,0,0,0,40,4449,29.8883,404.944473266602,,,,,,,,,,,,,0,,,,0.0049,,,,,,30.0065613,,,,
,29384059.72,30.0078373,-37.7641735076904,9.63152495405493E-6,3.26544358849327E-7,1,0.999253354069792,40.0298881530762,1.9887967576866,16.720000654459,0.000108494051967606,1.55146136038565E-5,0.25,-3.31006529664742E-7,9.583225771871E-6,-2.76617351732218E-7,30.0078373,30.0078373,-38.9488906860352,-36.5794563293457,57.2863358029484,20.6987650496122,15.695635,0,0,0,40,4449,29.8888,-37.7641735076904,,,,,,,,,,,,,0,,,,-0.00245,,,,,,30.0078373,,,,
,29384076.86,30.0073185,-465.794845581055,-4.99548858046103E-5,3.5937695686886E-7,1,0.999253354069792,40.0298881530762,1.98889440858837,16.720000654459,-0.000558696704468608,-0.000103217124123553,0.25,-3.13814681651013E-7,-4.96940471106906E-5,-5.86066512585755E-7,30.0073185,30.0073185,-468.225982666016,-463.363708496094,57.1049979864868,20.6975240874293,15.695635,0,0,0,40,4449,29.88875,-465.794845581055,,,,,,,,,,,,,0,,,,-0.00245,,,,,,30.0073185,,,,
,29384095.36,30.0056877,-927.402801513672,-7.52741396932934E-5,3.50198436448374E-7,1,0.999253354069792,40.0298881530762,1.98899822976281,16.720000654459,-0.000841687410024866,-0.00015688932284541,0.25,-5.91680204426959E-7,-7.48820002336904E-5,-1.00274850927332E-6,30.0056877,30.0056877,-932.597045898438,-922.208557128906,57.3512109700445,20.6962289550122,15.695635,0,0,0,40,4449,29.8861,-927.402801513672,,,,,,,,,,,,,0,,,,0.00245,,,,,,30.0056877,,,,
,29384112.97,30.0062847,-1366.88409423828,-8.76847402862938E-5,2.8897072778488E-7,1,0.999253354069792,40.0298881530762,1.9889661437739,16.720000654459,-0.000981222807545186,-0.000178506794324022,0.25,-3.07862880585707E-7,-8.72319956717552E-5,-7.90457189201854E-7,30.0062847,30.0062847,-1369.57458496094,-1364.19360351562,57.2964969736984,20.7000105192042,16.454937,0,0,0,40,4449,29.88645,-1366.88409423828,,,,,,,,,,,,,0,,,,0.00245,,,,,,30.0062847,,,,
,29384130.83,30.0065212,-1812.39849853516,-9.3730494710572E-5,3.6993659995743E-7,1,0.999253354069792,40.0298881530762,1.98898829744279,16.720000654459,-0.00104935031602584,-0.000188370798504016,0.25,-1.08237288581917E-7,-9.32499951713871E-5,-6.27264136281663E-7,30.0065212,30.0065212,-1815.87670898438,-1808.92028808594,57.4215575367753,20.6990957517309,15.695635,0,0,0,40,4449,29.88455,-1812.39849853516,,,,,,,,,,,,,0,,,,-0.00245,,,,,,30.0065212,,,,
,29384149.45,30.0044708,-2276.30126953125,-9.68771525936047E-5,4.51559049135257E-7,1,0.999253354069792,40.0298881530762,1.98881485113221,16.720000654459,-0.00108391714889054,-0.000198045912858627,0.25,-4.09895046000683E-7,-9.63814017148265E-5,-9.47096298403521E-7,30.0044708,30.0044708,-2279.650390625,-2272.9521484375,57.1847240954484,20.6950528955918,15.695635,0,0,0,40,4449,29.88195,-2276.30126953125,,,,,,,,,,,,,0,,,,0.0049,,,,,,30.0044708,,,,
,29384167.36,30.0049286,-2724.5791015625,-9.7658616924863E-5,2.9087419266682E-7,1,0.999253354069792,40.0298881530762,1.98879987754948,16.720000654459,-0.00109281265314343,-0.000198918272728693,0.25,-3.45741491254401E-7,-9.71618829287019E-5,-8.89968624254558E-7,30.0049286,30.0049286,-2729.30029296875,-2719.85791015625,56.997133250833,20.7002271519661,16.454937,0,0,0,40,4449,29.8855,-2724.5791015625,,,,,,,,,,,,,0,,,,0.0049,,,,,,30.0049286,,,,
,29384185.52,30.0045681,-3177.8916015625,-9.84334961808766E-5,3.22387639966364E-7,1,0.999253354069792,40.0298881530762,1.98881647551344,16.720000654459,-0.00110037807281941,-0.000206923063980329,0.25,-9.19371144936745E-7,-9.79323400823222E-5,-1.46743955190785E-6,30.0045681,30.0045681,-3181.87573242188,-3173.90747070313,56.9158438848329,20.7004044169114,16.075285,0,0,0,40,4449,29.8834,-3177.8916015625,,,,,,,,,,,,,0,,,,0,,,,,,30.0045681,,,,
,29384203.495,30.0016403,-3626.97875976562,-9.829985335775E-5,4.88860527329798E-7,1,0.999253354069792,40.0298881530762,1.98899220957369,16.720000654459,-0.00110093560426125,-0.00019586461538227,0.25,4.87934147340075E-8,-9.78076377949252E-5,-5.05849589250453E-7,30.0016403,30.0016403,-3634.365234375,-3619.59228515625,57.2550706621791,20.6986750620921,16.075285,0,0,0,40,4449,29.8849,-3626.97875976562,,,,,,,,,,,,,0,,,,-0.0049,,,,,,30.0016403,,,,
,29384221.475,30.0023251,-4076.82055664063,-9.79257641793639E-5,4.50900831195799E-7,1,0.999253354069792,40.0298881530762,1.98885666650333,16.720000654459,-0.00109714523077408,-0.000192658068525445,0.25,2.70249755212263E-7,-9.74395732839512E-5,-2.85864994475227E-7,30.0017796,30.0028706,-4082.0751953125,-4071.56591796875,57.3621537693137,20.7004955553675,16.075285,0,0,0,40,4449,29.8861,-4076.82055664063,,,,,,,,,,,,,0,,,,-0.00245,,,,,,30.0023251,,,,
,29384240.21,30.0034676,-4545.64306640625,-9.64889826691522E-5,3.68791763174809E-7,1,0.999253354069792,40.0298881530762,1.98879974830392,16.720000654459,-0.00108317570289893,-0.000177935335527663,0.25,1.331215716528E-6,-9.60190121076758E-5,7.75439662836143E-7,30.0034676,30.0034676,-4549.1484375,-4542.1376953125,57.115940785756,20.6984975323672,16.075285,0,0,0,40,4449,29.8848,-4545.64306640625,,,,,,,,,,,,,0,,,,0,,,,,,30.0034676,,,,
,29384257.85,30.003767,-4986.93725585937,-9.43063160760243E-5,4.21434095467996E-7,1,0.999253354069792,40.0298881530762,1.98872381077137,16.720000654459,-0.00105855203389475,-0.000174554361132461,0.25,1.24586647512068E-6,-9.38495264468995E-5,7.00598872320817E-7,30.003767,30.003767,-4989.0439453125,-4984.83056640625,57.2230238928907,20.7020741107859,15.695635,0,0,0,40,4449,29.8829,-4986.93725585937,,,,,,,,,,,,,0,,,,0,,,,,,30.003767,,,,
,29384275.74,30.003437,-5433.197265625,-9.30391577123738E-5,4.38746190292726E-7,1,0.999253354069792,40.0298881530762,1.98877075116472,16.720000654459,-0.00104642258852982,-0.000160806688787219,0.25,2.25052353616862E-6,-9.25972938993131E-5,1.70523124570189E-6,30.003437,30.003437,-5434.255859375,-5432.138671875,57.2988418592561,20.7033014802512,16.454937,0,0,0,40,4449,29.8817,-5433.197265625,,,,,,,,,,,,,0,,,,-0.00245,,,,,,30.003437,,,,
,29384292.435,30.0022125,-5850.20971679688,-9.24756497290651E-5,4.30701180607357E-7,1,0.999253354069792,40.0298881530762,1.98876428851541,16.720000654459,-0.00103841630924027,-0.000169341986709732,0.25,1.39042545918627E-6,-9.2034389088244E-5,8.50356665327456E-7,30.0022125,30.0022125,-5854.060546875,-5846.35888671875,57.383257739333,20.7013029814687,16.075285,0,0,0,40,4449,29.8825,-5850.20971679688,,,,,,,,,,,,,0,,,,0,,,,,,30.0022125,,,,
,29384309.72,29.9994144,-6282.43823242188,-9.01465090408332E-5,4.38870902469873E-7,1,0.999253354069792,40.0298881530762,1.98895411238757,16.720000654459,-0.00101261185927712,-0.000163838521072759,0.25,1.47008539604062E-6,-8.97199035946424E-5,9.40803357508009E-7,29.9994144,29.9994144,-6283.53662109375,-6281.33984375,57.2198973788137,20.699559623366,16.454937,0,0,0,40,4449,29.88465,-6282.43823242188,,,,,,,,,,,,,0,,,,0,,,,,,29.9994144,,,,
,29384327.42,30.0003109,-6725.87036132813,-8.87176301630224E-5,5.42641950916999E-7,1,0.999253354069792,40.0298881530762,1.98891862680176,16.720000654459,-0.000996942524213949,-0.000159201260380085,0.25,1.63150371061871E-6,-8.83017984178977E-5,1.10744686097332E-6,30.0003109,30.0003109,-6731.24853515625,-6720.4921875,57.3136928011214,20.6991859729005,15.695635,0,0,0,40,4449,29.88545,-6725.87036132813,,,,,,,,,,,,,0,,,,-0.0049,,,,,,30.0003109,,,,
,29384344.405,30.000721,-7149.41235351562,-8.69718397228358E-5,3.94999331955666E-7,1,0.999253354069792,40.0298881530762,1.9887325243949,16.720000654459,-0.000978756848861537,-0.000147728940008011,0.25,2.3453829831239E-6,-8.65713230377842E-5,1.82596787506876E-6,30.000721,30.000721,-7153.23095703125,-7145.59375,57.1370447557753,20.6995322009962,16.075285,0,0,0,40,4449,29.884,-7149.41235351562,,,,,,,,,,,,,0,,,,-0.00245,,,,,,30.000721,,,,
,29384381.25,29.9990482,-7011.12158203125,-8.49578213271005E-5,5.30684366880166E-7,1,0.999253354069792,40.0298881530762,1.98881579702294,16.720000654459,-0.000955517262440433,-0.000147685685982201,0.25,1.98918774421011E-6,-8.45639336335357E-5,1.48390309934785E-6,29.9990482,29.9990482,-7016.15478515625,-7006.08837890625,57.5176978446407,20.7022860205582,16.454937,0,0,0,40,4449,29.88545,-7011.12158203125,,,,,,,,,,,,,0,,,,-0.00245,,,,,,29.9990482,,,,
,29384398.39,29.9993496,-6583.48828125,-8.8257450593487E-5,6.13622271227225E-7,1,0.999253354069792,40.0298881530762,1.98883036590613,16.720000654459,-0.00099590578886451,-0.000134922316435725,0.25,3.71560310164199E-6,-8.78549934662828E-5,3.18493495184245E-6,29.9993496,29.9993496,-6587.16455078125,-6579.81201171875,57.2238055214099,20.7000935031545,15.695635,0,0,0,40,4449,29.8855,-6583.48828125,,,,,,,,,,,,,0,,,,-0.00245,,,,,,29.9993496,,,,
,29384415.125,29.9988728,-6165.70288085938,-9.06383542957321E-5,5.24382374759447E-7,1,0.999253354069792,40.0298881530762,1.98894333937167,16.720000654459,-0.0010233733039305,-0.000135324482387177,0.25,4.10292228817945E-6,-9.02238032891989E-5,3.55868852505451E-6,29.9988728,29.9988728,-6170.6435546875,-6160.76220703125,57.3856026248907,20.6971934359837,16.075285,0,0,0,40,4449,29.8823,-6165.70288085938,,,,,,,,,,,,,0,,,,-0.00245,,,,,,29.9988728,,,,
,29384433.04,29.9997387,-5718.5361328125,-9.18435294157623E-5,4.05228020381818E-7,1,0.999253354069792,40.0298881530762,1.98898785133826,16.720000654459,-0.0010350292222426,-0.000147981875010494,0.25,3.1854873303783E-6,-9.14148287303866E-5,2.6410011078869E-6,29.9997387,29.9997387,-5721.08837890625,-5715.98388671875,57.210517836583,20.7025201496282,15.695635,0,0,0,40,4449,29.8849,-5718.5361328125,,,,,,,,,,,,,0,,,,0,,,,,,29.9997387,,,,
,29384450.41,29.995266,-5285.6787109375,-9.29925069947539E-5,3.60276530206047E-7,1,0.999253354069792,40.0298881530762,1.9892120819374,16.720000654459,-0.00104779197969964,-0.000151329451059891,0.25,3.09042040636793E-6,-9.255473692597E-5,2.54203322073242E-6,29.995266,29.995266,-5291.810546875,-5279.546875,57.4426615067945,20.6989506566007,16.075285,0,0,0,40,4449,29.88445,-5285.6787109375,,,,,,,,,,,,,0,,,,-0.0049,,,,,,29.995266,,,,
,29384467.865,29.9973507,-4850.2001953125,-9.56066743586141E-5,4.11930132293487E-7,1,0.999253354069792,40.0298881530762,1.98901534428374,16.720000654459,-0.00107462227664086,-0.000169512551444633,0.25,1.92948780000762E-6,-9.51465384476516E-5,1.37411386203681E-6,29.9973507,29.9973507,-4852.779296875,-4847.62109375,56.9517987967176,20.7013324747538,16.454937,0,0,0,40,4449,29.88805,-4850.2001953125,,,,,,,,,,,,,0,,,,0,,,,,,29.9973507,,,,
,29384486.1,29.9986534,-4392.72998046875,-9.58080407416396E-5,4.81927786619353E-7,1,0.999253354069792,40.0298881530762,1.98906899895544,16.720000654459,-0.00107479675258468,-0.000181534707457092,0.25,8.89376138749518E-7,-9.53379499274041E-5,3.40473223750633E-7,29.9986534,29.9986534,-4395.27880859375,-4390.18115234375,57.4199942797368,20.700225327879,16.454937,0,0,0,40,4449,29.8866,-4392.72998046875,,,,,,,,,,,,,0,,,,-0.00245,,,,,,29.9986534,,,,
,29384503.72,29.99826145,-3954.98522949219,-9.74080986589006E-5,4.44066980292969E-7,1,0.999253354069792,40.0298881530762,1.98895291160883,16.720000654459,-0.00109369014843698,-0.000178739030793324,0.25,1.420763373601E-6,-9.69302065061033E-5,8.62513877877382E-7,29.9980888,29.9984341,-3958.86474609375,-3951.10571289063,57.2034831799099,20.7018579339059,16.075285,0,0,0,40,4449,29.8855,-3954.98522949219,,,,,,,,,,,,,0,,,,0.00245,,,,,,29.99826145,,,,
,29384521.345,29.9966125,-3513.86791992188,-9.89451431296322E-5,4.16800517651258E-7,1,0.999253354069792,40.0298881530762,1.98907666616823,16.720000654459,-0.00110995274770884,-0.000187332096683616,0.25,9.25806516561522E-7,-9.8453948054807E-5,3.63719134263143E-7,29.9966125,29.9966125,-3519.01684570313,-3508.71899414063,57.4809613042369,20.6991874607167,16.075285,0,0,0,40,4449,29.8876,-3513.86791992188,,,,,,,,,,,,,0,,,,-0.00245,,,,,,29.9966125,,,,
,29384540.22,29.9943943,-3041.7431640625,-9.9283084398215E-5,3.41845580009094E-7,1,0.999253354069792,40.0298881530762,1.98935023539333,16.720000654459,-0.00111505913043253,-0.000181248867791951,0.25,1.52837217164184E-6,-9.87906106198843E-5,9.63864457277434E-7,29.9943943,29.9943943,-3046.62963867188,-3036.85668945313,57.2550706621791,20.6958139561558,16.075285,0,0,0,40,4449,29.8895,-3041.7431640625,,,,,,,,,,,,,0,,,,0.00245,,,,,,29.9943943,,,,
,29384558.165,30.0000877,-2593.55590820313,-9.91877155220522E-5,4.02138836598436E-7,1,0.999253354069792,40.0298881530762,1.98893717318028,16.720000654459,-0.00111200595134179,-0.000190733729798457,0.25,6.58307422508541E-7,-9.86881214640595E-5,1.01077509216037E-7,30.0000877,30.0000877,-2599.783203125,-2587.32861328125,57.6849663477561,20.7016199387013,15.695635,0,0,0,40,4449,29.89095,-2593.55590820313,,,,,,,,,,,,,0,,,,-0.0049,,,,,,30.0000877,,,,
,29384575.96,30.0046616,-2148.64978027344,-9.77731789572065E-5,4.28254507579443E-7,1,0.999253354069792,40.0298881530762,1.98883439943873,16.720000654459,-0.00109606655836022,-0.000187981104252579,0.25,6.48210554038802E-7,-9.72780572824781E-5,1.01242564681577E-7,30.0046616,30.0046616,-2150.25341796875,-2147.04614257813,57.2152076076984,20.7064432475233,15.695635,0,0,0,40,4449,29.88495,-2148.64978027344,,,,,,,,,,,,,0,,,,-0.0049,,,,,,30.0046616,,,,
,29384592.04,30.0036964,-1747.55651855469,-9.4229222250127E-5,3.56002899510246E-7,1,0.999253354069792,40.0298881530762,1.98884563172859,16.720000654459,-0.00105557666950576,-0.000185326932164397,0.25,2.51019237750902E-7,-9.37478144095644E-5,-2.72301262019874E-7,30.0036964,30.0036964,-1750.20129394531,-1744.91174316406,57.4629838482945,20.7091057170862,16.075285,0,0,0,40,4449,29.8838,-1747.55651855469,,,,,,,,,,,,,0,,,,0.00245,,,,,,30.0036964,,,,
,29384610.65,30.002327,-1281.17095947266,-8.92352661765426E-5,2.82280980621878E-7,1,0.999253354069792,40.0298881530762,1.98880923782844,16.720000654459,-0.000999332873293596,-0.000176942586929725,0.25,1.06641080492171E-7,-8.87764154863521E-5,-3.86266872536298E-7,30.002327,30.002327,-1284.73107910156,-1277.61083984375,57.088583787583,20.7098674130507,15.695635,0,0,0,40,4449,29.8843,-1281.17095947266,,,,,,,,,,,,,0,,,,-0.0049,,,,,,30.002327,,,,
,29384628.035,30.0033951,-847.763885498047,-7.98626823077219E-5,3.23175295967499E-7,1,0.999253354069792,40.0298881530762,1.98861046518238,16.720000654459,-0.000893645255446703,-0.000161819467764421,0.25,-2.16994220164833E-7,-7.94485732406578E-5,-6.54942904489674E-7,30.0033951,30.0033951,-850.211669921875,-845.316101074219,57.4387533641984,20.7100258995119,16.075285,0,0,0,40,4449,29.8837,-847.763885498047,,,,,,,,,,,,,0,,,,0,,,,,,30.0033951,,,,
,29384645.305,30.002594,-416.984817504883,-5.90711074082209E-5,2.75931602319903E-7,1,0.999253354069792,40.0298881530762,1.98870565925176,16.720000654459,-0.000660132050285909,-0.000124617306610424,0.25,-6.01278263240206E-7,-5.87612540882198E-5,-9.21874551743861E-7,30.002594,30.002594,-423.212188720703,-410.757446289063,57.4692368764484,20.7086365282872,16.075285,0,0,0,40,4449,29.8834,-416.984817504883,,,,,,,,,,,,,0,,,,0.00245,,,,,,30.002594,,,,
,29384663.585,30.0017014,41.9738883972168,-6.02995321881412E-6,3.43051042687529E-7,1,0.999253354069792,40.0298881530762,1.98877852152904,16.720000654459,-6.7585245300015E-5,-1.16114107618788E-5,0.25,3.76682766556235E-8,-5.99878440990088E-6,4.50247965910826E-9,30.0017014,30.0017014,39.5273666381836,44.42041015625,57.2159892362176,20.709041744346,15.695635,0,0,0,40,4449,29.8827,41.9738883972168,,,,,,,,,,,,,0,,,,0.0049,,,,,,30.0017014,,,,
,29384680.995,30.0031757,475.159957885742,5.00378255798019E-5,3.24839405340364E-7,1,0.999253354069792,40.0298881530762,1.98884331130565,16.720000654459,0.000560465216046659,9.8591339982955E-5,0.25,-1.13892574763442E-7,4.97788985480892E-5,1.61028513615849E-7,30.0031757,30.0031757,473.773040771484,476.546875,57.312129544083,20.7097349477862,15.695635,0,0,0,40,4449,29.8844,475.159957885742,,,,,,,,,,,,,0,,,,-0.00245,,,,,,30.0031757,,,,
,29384697.7,29.999588,892.132690429688,7.49767892642916E-5,3.21831163210782E-7,1,0.999253354069792,40.0298881530762,1.98896897161601,16.720000654459,0.000839813365125269,0.000148052423970512,0.25,-1.44137286075145E-7,7.45900675646381E-5,2.6894262136381E-7,29.999588,29.999588,888.809265136719,895.456115722656,57.5145713305638,20.7117935432269,15.695635,0,0,0,40,4449,29.88115,892.132690429688,,,,,,,,,,,,,0,,,,0,,,,,,29.999588,,,,
,29384715.3,29.9993534,1330.91064453125,8.71306895104293E-5,3.13361818848169E-7,1,0.999253354069792,40.0298881530762,1.98898768147273,16.720000654459,0.00097580252776006,0.000173051831844617,0.25,-8.04714239227457E-8,8.66827533435331E-5,4.00889861722317E-7,29.9993534,29.9993534,1327.03247070312,1334.78881835938,56.9807190519291,20.7085775133765,16.454937,0,0,0,40,4449,29.88385,1330.91064453125,,,,,,,,,,,,,0,,,,0,,,,,,29.9993534,,,,
,29384733.205,29.9985027,1779.01586914062,9.41310148626036E-5,3.42745778136301E-7,1,0.999253354069792,40.0298881530762,1.98907658057434,16.720000654459,0.00105508402099724,0.000182416229259476,0.25,-4.95478652622596E-7,9.36516631349923E-5,2.87237654803829E-8,29.9985027,29.9985027,1774.02600097656,1784.00573730469,57.4004535667561,20.7073010843352,15.695635,0,0,0,40,4449,29.8867,1779.01586914062,,,,,,,,,,,,,0,,,,-0.0049,,,,,,29.9985027,,,,
,29384752.835,29.9969482,2269.27648925781,9.730788121632E-5,3.14930267879189E-7,1,0.999253354069792,40.0298881530762,1.98874201598933,16.720000654459,0.00109013146644076,0.000190886381043425,0.25,-3.05781443418195E-7,9.68139627504258E-5,2.37496351257773E-7,29.9969482,29.9969482,2268.0087890625,2270.54418945313,57.2949337166599,20.7063955660015,16.075285,0,0,0,40,4449,29.8891,2269.27648925781,,,,,,,,,,,,,0,,,,-0.0049,,,,,,29.9969482,,,,
,29384769.985,30.0020161,2697.55151367187,9.93076487966123E-5,3.80873838961349E-7,1,0.999253354069792,40.0298881530762,1.98877261826251,16.720000654459,0.00111362078585391,0.000188979636188971,0.25,-8.35629626697139E-7,9.88090279316281E-5,-2.7631727333091E-7,30.0020161,30.0020161,2695.1220703125,2699.98095703125,57.2331850636407,20.7103011513923,16.075285,0,0,0,40,4449,29.8878,2697.55151367187,,,,,,,,,,,,,0,,,,0,,,,,,30.0020161,,,,
,29384787.16,30.0006294,3125.50244140625,9.98780207926641E-5,3.59628605489469E-7,1,0.999253354069792,40.0298881530762,1.98868735879252,16.720000654459,0.00111945782724658,0.000193104631111678,0.25,-5.70976930614652E-7,9.93776339770364E-5,-7.56564222978409E-9,30.0006294,30.0006294,3121.95483398438,3129.05004882812,57.2824276603522,20.7108645094697,15.695635,0,0,0,40,4449,29.884,3125.50244140625,,,,,,,,,,,,,0,,,,0,,,,,,30.0006294,,,,
,29384806.255,29.9992142,3603.30822753906,0.000100341466601726,3.73698931428822E-7,1,0.999253354069792,40.0298881530762,1.98853604846781,16.720000654459,0.00112603065608871,0.000186005113372367,0.25,-1.28969198090262E-6,9.98458890300671E-5,-7.17429519367274E-7,29.9992142,29.9992142,3599.5361328125,3607.08032226562,57.0487207331022,20.7098616106976,16.075285,0,0,0,40,4449,29.8868,3603.30822753906,,,,,,,,,,,,,0,,,,-0.00245,,,,,,29.9992142,,,,
,29384824.57,29.9988995,4062.09619140625,9.93525864557624E-5,3.76466454279321E-7,1,0.999253354069792,40.0298881530762,1.98852628674786,16.720000654459,0.00111323223305091,0.000193870966707554,0.25,-4.13689757101526E-7,9.88599934448439E-5,1.51129166356967E-7,29.9988995,29.9988995,4059.47900390625,4064.71337890625,57.2808644033138,20.7124392777797,15.695635,0,0,0,40,4449,29.8849,4062.09619140625,,,,,,,,,,,,,0,,,,0.0049,,,,,,29.9988995,,,,
,29384842.72,29.9986706,4514.95068359375,9.81552845800319E-5,4.09073679295546E-7,1,0.999253354069792,40.0298881530762,1.98875489571028,16.720000654459,0.00109978449956291,0.000192609986620668,0.25,-3.17634231326112E-7,9.76711348568135E-5,2.42470270092582E-7,29.9986706,29.9986706,4512.42431640625,4517.47705078125,57.1792526958137,20.7068721303385,16.075285,0,0,0,40,4449,29.8883,4514.95068359375,,,,,,,,,,,,,0,,,,0,,,,,,29.9986706,,,,
,29384860.49,29.9983673,4960.08447265625,9.5706788669582E-5,4.38962166971576E-7,1,0.999253354069792,40.0298881530762,1.9888357075783,16.720000654459,0.00107187715155136,0.000190883975717524,0.25,-3.83585938439454E-8,9.52360395388813E-5,5.08833387826659E-7,29.9983673,29.9983673,4955.19921875,4964.9697265625,57.2910255740638,20.7069411667848,15.695635,0,0,0,40,4449,29.8836,4960.08447265625,,,,,,,,,,,,,0,,,,0.0049,,,,,,29.9983673,,,,
,29384877.46,30.0010471,5383.416015625,9.46383047550403E-5,4.3208579529083E-7,1,0.999253354069792,40.0298881530762,1.98865418421873,16.720000654459,0.00106069738616054,0.000183994537088305,0.25,-4.64211003853337E-7,9.41780572474536E-5,8.12795768740225E-8,30.0010471,30.0010471,5376.9384765625,5389.8935546875,57.2746113751599,20.7078312752916,15.695635,0,0,0,40,4449,29.8839,5383.416015625,,,,,,,,,,,,,0,,,,-0.00245,,,,,,30.0010471,,,,
,29384895.5,29.9988747,5834.30102539063,9.222103663767E-5,4.80912765441642E-7,1,0.999253354069792,40.0298881530762,1.98857439527932,16.720000654459,0.00103626449835661,0.000164364731328343,0.25,-1.78797782574252E-6,9.17832191333996E-5,-1.24751542942652E-6,29.9988747,29.9988747,5829.12744140625,5839.474609375,57.4582940771792,20.707354558047,15.695635,0,0,0,40,4449,29.88425,5834.30102539063,,,,,,,,,,,,,0,,,,0.00245,,,,,,29.9988747,,,,
,29384913.82,30.0023594,6293.38793945313,9.09613656803674E-5,5.0924724687982E-7,1,0.999253354069792,40.0298881530762,1.98869937655202,16.720000654459,0.00101647348489744,0.000194236828014128,0.25,1.10049297654868E-6,9.05160154315992E-5,1.62215401324385E-6,30.0023594,30.0023594,6289.74462890625,6297.03125,57.2339666921599,20.7077594895303,15.695635,0,0,0,40,4449,29.8855,6293.38793945313,,,,,,,,,,,,,0,,,,0.0049,,,,,,30.0023594,,,,
,29384931.465,29.9997559,6733.89990234375,8.83434353440639E-5,5.53013092585109E-7,1,0.999253354069792,40.0298881530762,1.98867084863322,16.720000654459,0.000994402374306959,0.000148531369437803,0.25,-2.51576118011046E-6,8.79345848116043E-5,-1.98961119372721E-6,29.9997559,29.9997559,6728.81787109375,6738.98193359375,56.926005055583,20.7089459139413,16.075285,0,0,0,40,4449,29.88425,6733.89990234375,,,,,,,,,,,,,0,,,,-0.0049,,,,,,29.9997559,,,,
,29384950.375,30.0012741,7205.75903320312,8.60577700287927E-5,6.29696530156331E-7,1,0.999253354069792,40.0298881530762,1.98857897083795,16.720000654459,0.00096468488070315,0.000166981109546696,0.25,-4.62386448658204E-7,8.56509803266519E-5,4.3013241171371E-8,30.0012741,30.0012741,7201.0087890625,7210.50927734375,57.2886806885061,20.7115495201814,15.695635,0,0,0,40,4449,29.8852,7205.75903320312,,,,,,,,,,,,,0,,,,-0.0049,,,,,,30.0012741,,,,
,29384983.605,29.9997883,7007.90747070312,8.66834877476785E-5,5.02296828015036E-7,1,0.999253354069792,40.0298881530762,1.98847205661521,16.720000654459,0.000975006340574546,0.000149307529224029,0.25,-2.15040617239282E-6,8.62822872372809E-5,-1.63429414495206E-6,29.9997883,29.9997883,7004.17626953125,7011.638671875,57.3551191126407,20.7156778371199,15.315984,0,0,0,40,4449,29.8859,7007.90747070312,,,,,,,,,,,,,0,,,,0.0049,,,,,,29.9997883,,,,
,29385000.67,29.9986343,6584.18432617187,8.79989115418543E-5,5.53408167905892E-7,1,0.999253354069792,40.0298881530762,1.98825402887019,16.720000654459,0.000985935171040235,0.000172445102460596,0.25,-3.14900331790466E-7,8.75779527881792E-5,1.97938636033029E-7,29.9986343,29.9986343,6583.029296875,6585.33935546875,57.5450548428138,20.7163993658271,16.075285,0,0,0,40,4449,29.8866,6584.18432617187,,,,,,,,,,,,,0,,,,-0.0049,,,,,,29.9986343,,,,
,29385019.18,29.9952106,6121.23999023437,9.14825686967021E-5,6.40318015153767E-7,1,0.999253354069792,40.0298881530762,1.98861376690511,16.720000654459,0.00102591272345572,0.000174789089128788,0.25,-7.27389774049548E-7,9.10441514212838E-5,-1.94798998720669E-7,29.9952106,29.9952106,6116.42236328125,6126.0576171875,57.6130565239869,20.711831412862,15.315984,0,0,0,40,4449,29.8862,6121.23999023437,,,,,,,,,,,,,0,,,,-0.00245,,,,,,29.9952106,,,,
,29385037.75,29.9988976,5657.08837890625,9.33219993179612E-5,5.31291831301098E-7,1,0.999253354069792,40.0298881530762,1.98847129272987,16.720000654459,0.00104391776478655,0.00019237882904719,0.25,5.19128581325637E-7,9.28644116454056E-5,1.05380474009087E-6,29.9988976,29.9988976,5654.70263671875,5659.47412109375,57.5505262424484,20.7116962377113,15.315984,0,0,0,40,4449,29.89,5657.08837890625,,,,,,,,,,,,,0,,,,0,,,,,,29.9988976,,,,
,29385055.34,29.9974422,5219.078125,9.452624571389E-5,3.77424285528667E-7,1,0.999253354069792,40.0298881530762,1.98862683683347,16.720000654459,0.00105752328591848,0.000194371508127059,0.25,4.83773459657263E-7,9.40600428804517E-5,1.02309438580923E-6,29.9974422,29.9974422,5215.12353515625,5223.03271484375,57.5849178972945,20.711720242614,15.695635,0,0,0,40,4449,29.88595,5219.078125,,,,,,,,,,,,,0,,,,0.00245,,,,,,29.9974422,,,,
,29385072.885,29.9953213,4779.63793945313,9.73017980468614E-5,3.82352070458143E-7,1,0.999253354069792,40.0298881530762,1.9886318706127,16.720000654459,0.00108768639021862,0.000204883510576026,0.25,9.29981896153E-7,9.68165405361953E-5,1.48056442936277E-6,29.9953213,29.9953213,4778.32421875,4780.95166015625,57.4051433378714,20.7134536445133,15.695635,0,0,0,40,4449,29.89035,4779.63793945313,,,,,,,,,,,,,0,,,,-0.00245,,,,,,29.9953213,,,,
,29385089.98,29.9990864,4353.740234375,9.86668334823411E-5,5.2640415642146E-7,1,0.999253354069792,40.0298881530762,1.98840869213502,16.720000654459,0.00110527828551692,0.000193814076057616,0.25,-2.97426092031435E-7,9.81789548934189E-5,2.64581566814057E-7,29.9990864,29.9990864,4351.31689453125,4356.16357421875,57.1331366131791,20.7141612095513,16.075285,0,0,0,40,4449,29.88785,4353.740234375,,,,,,,,,,,,,0,,,,0.00245,,,,,,29.9990864,,,,
,29385107.93,29.9971409,3905.388671875,9.86047721550363E-5,5.05148679886876E-7,1,0.999253354069792,40.0298881530762,1.98861826525384,16.720000654459,0.00110476618958236,0.000193115602816583,0.25,-3.47450316343656E-7,9.81145348818217E-5,2.1195871232795E-7,29.9971409,29.9971409,3901.81787109375,3908.95947265625,57.3723149400638,20.7108534067752,15.315984,0,0,0,40,4449,29.88725,3905.388671875,,,,,,,,,,,,,0,,,,0,,,,,,29.9971409,,,,
,29385125.27,29.9989052,3473.66125488281,9.96028469886542E-5,4.51629698241044E-7,1,0.999253354069792,40.0298881530762,1.988587052262,16.720000654459,0.00111602267285467,0.000194377236801979,0.25,-4.09746768878985E-7,9.91052071053071E-5,1.53254600898689E-7,29.9989052,29.9989052,3467.09692382812,3480.2255859375,57.4825245612753,20.7102423815237,16.075285,0,0,0,40,4449,29.8895,3473.66125488281,,,,,,,,,,,,,0,,,,-0.00245,,,,,,29.9989052,,,,
,29385142.985,29.9972878,3029.63708496094,0.000100569346821528,4.2740515422015E-7,1,0.999253354069792,40.0298881530762,1.98851569044567,16.720000654459,0.00112579818753264,0.000201764608076426,0.25,8.11556767309067E-8,0.000100061300808452,6.44708267012961E-7,29.9972878,29.9972878,3027.33813476562,3031.93603515625,57.3488660844868,20.7118551771408,16.075285,0,0,0,40,4449,29.89155,3029.63708496094,,,,,,,,,,,,,0,,,,0,,,,,,29.9972878,,,,
,29385161.915,29.9993668,2556.68530273438,9.93873606783176E-5,3.51535080183141E-7,1,0.999253354069792,40.0298881530762,1.98866687700739,16.720000654459,0.00111185344348107,0.000203670330163633,0.25,4.63974523854379E-7,9.88802464364169E-5,1.01641087618521E-6,29.9993668,29.9993668,2555.63256835938,2557.73803710938,57.1839424669291,20.7077884999752,15.695635,0,0,0,40,4449,29.889,2556.68530273438,,,,,,,,,,,,,0,,,,0,,,,,,29.9993668,,,,
,29385179.67,29.9944286,2113.24780273438,9.82469605580454E-5,3.60685043396907E-7,1,0.999253354069792,40.0298881530762,1.98849648610556,16.720000654459,0.00109951459232654,0.000198300717800765,0.25,1.91913617175442E-7,9.77446560125018E-5,7.3714032978195E-7,29.9944286,29.9944286,2110.53344726562,2115.96215820313,57.5176978446407,20.7122369932052,15.315984,0,0,0,40,4449,29.894,2113.24780273438,,,,,,,,,,,,,0,,,,0.00245,,,,,,29.9944286,,,,
,29385197.035,29.9994106,1679.779296875,9.5099460592966E-5,3.34102889631856E-7,1,0.999253354069792,40.0298881530762,1.9884862063768,16.720000654459,0.00106478468868011,0.000188990331830648,0.25,-7.58319099702111E-8,9.46123724654704E-5,4.51184925599774E-7,29.9994106,29.9994106,1676.04541015625,1683.51318359375,57.2980602307368,20.713153205856,15.695635,0,0,0,40,4449,29.8934,1679.779296875,,,,,,,,,,,,,0,,,,0,,,,,,29.9994106,,,,
,29385215.035,29.9992924,1228.56939697266,8.86074969133009E-5,3.023572454356E-7,1,0.999253354069792,40.0298881530762,1.98839543195898,16.720000654459,0.000991280992871414,0.0001802736674718,0.25,3.06218448899438E-7,8.81493994626139E-5,7.93352164213325E-7,29.9992924,29.9992924,1226.21496582031,1230.923828125,57.5309855294676,20.7112374169045,16.075285,0,0,0,40,4449,29.8881,1228.56939697266,,,,,,,,,,,,,0,,,,0.0049,,,,,,29.9992924,,,,
,29385233.375,29.9996891,771.284149169922,7.69206583042243E-5,3.35317876301644E-7,1,0.999253354069792,40.0298881530762,1.98844714542999,16.720000654459,0.000860880821715735,0.000154577014142844,0.25,9.58800565660486E-8,7.65222048721279E-5,5.18075850602805E-7,29.9996891,29.9996891,763.716857910156,778.851440429688,57.4145228801022,20.7098073792017,15.695635,0,0,0,40,4449,29.89005,771.284149169922,,,,,,,,,,,,,0,,,,0,,,,,,29.9996891,,,,
,29385251.815,29.9995003,310.111968994141,5.32160566080367E-5,3.71218781806321E-7,1,0.999253354069792,40.0298881530762,1.98838991658884,16.720000654459,0.000595331761315438,0.000108189243452873,0.25,1.79272429586159E-7,5.29387079819671E-5,4.69792175091332E-7,29.9995003,29.9995003,309.007110595703,311.216827392578,57.4778347901599,20.7136239663323,15.695635,0,0,0,40,4449,29.889,310.111968994141,,,,,,,,,,,,,0,,,,0,,,,,,29.9995003,,,,
,29394258.19,30.0022984,7299.76904296875,,,2,,,,16.9099999052286,,,,,,,30.0022984,30.0022984,7299.76904296875,7299.76904296875,,,15.695635,,,,-99999999,4369,29.9993,7299.76904296875,,,,,,,,,,,,,,,,,,,,,,,30.0022984,,,,