File: data/looselyPackedNP/sc-ios-7/ppms/rawdata/ES_S17_HYST_150K.DAT
[Header]
; VSM Data File (default extension .dat)
; Copyright (c) 2003-2013, Quantum Design, Inc. All rights reserved.
TITLE,
FILEOPENTIME,29276021.64,12/06/2018,4:14 am
BYAPP,VSM,2.0,2.0
INFO,PPMS VSM Option Release 1.4.10 Build 1,APPNAME
INFO,Quantum Design Linear Motor Servo Controller,MOTOR_MODULE_NAME
INFO,3101-100 M1,MOTOR_HW_VERSION
INFO,MMC1014,MOTOR_SERIAL_NUMBER
INFO,SRV No X-over 01.03.11,MOTOR_SOFTWARE_VERSION
INFO,Quantum Design VSM Detection Module,VSM_MODULE_NAME
INFO,3101-150 F0,VSM_HW_VERSION
INFO,VSM707,VSM_SERIAL_NUMBER
INFO,VSM No X-over 01.02.05 May 20 2008 13:51:47,VSM_SOFTWARE_VERSION
INFO,704,PREAMP_SERIAL_NUMBER
INFO,822,COIL_SERIAL_NUMBER
INFO,0,MOMENT_UNITS
INFO,Iron Oxide Spheres,SAMPLE_MATERIAL
INFO,7 nm diameter, collaboration Mainz,SAMPLE_COMMENT
INFO,,SAMPLE_MASS
INFO,,SAMPLE_VOLUME
INFO,,SAMPLE_MOLECULAR_WEIGHT
INFO,,SAMPLE_SIZE
INFO,,SAMPLE_SHAPE
DATATYPE,COMMENT,1
DATATYPE,TIME,2
STARTUPAXIS,X,2
STARTUPAXIS,Y1,5
[Data]
Comment,Time Stamp (sec),Temperature (K),Magnetic Field (Oe),Moment (emu),M. Std. Err. (emu),Transport Action,Averaging Time (sec),Frequency (Hz),Peak Amplitude (mm),Center Position (mm),Coil Signal' (mV),Coil Signal" (mV),Range (mV),M. Quad. Signal (emu),M. Raw' (emu),M. Raw" (emu),Min. Temperature (K),Max. Temperature (K),Min. Field (Oe),Max. Field (Oe),Mass (grams),Motor Lag (deg),Pressure (Torr),VSM Status (code),Motor Status (code),Measure Status (code),Measure Count,PPMS Status (code),System Temp. (K),System Field (Oe),Sample Position (deg),Bridge 1 Resistance (ohms),Bridge 1 Excitation (에),Bridge 2 Resistance (ohms),Bridge 2 Excitation (에),Bridge 3 Resistance (ohms),Bridge 3 Excitation (에),Bridge 4 Resistance (ohms),Bridge 4 Excitation (에),Signal 1 Vin (V),Signal 2 Vin (V),Digital Inputs (code),Drive 1 Iout (mA),Drive 1 Ipower (W),Drive 2 Iout (mA),Drive 2 Ipower (W),Pressure (),Map 20 (),Map 21 (),Map 22 (),Map 23 (),Map 24 (),Map 25 (),Map 26 (),Map 27 (),Map 28 (),Map 29 ()
,29276035.97,150.2696533,-0.289251685142517,,,2,,,,16.509999653399,,,,,,,150.2696533,150.2696533,-0.289251685142517,-0.289251685142517,,,21.01075,,,,-99999999,4369,150.0244,-0.289251685142517,,,,,,,,,,,,,,,,,,,,,,,150.2696533,,,,
,29276185.12,150.14232635,4615.6533203125,8.55507537898868E-5,3.94078293149857E-7,1,0.999253354069792,40.0298881530762,2.00310773613964,16.499999910593,0.000972677956240209,0.000182238253311269,0.25,1.08821480053082E-6,8.5967667436555E-5,1.23084638565262E-6,150.141037,150.1436157,4605.58544921875,4625.72119140625,56.7173102409483,20.6914533861811,21.770052,0,0,0,40,4449,149.79815,4615.6533203125,,,,,,,,,,,,,0,,,,0,,,,,,150.14232635,,,,
,29276280.915,150.0584564,9402.21533203125,6.72101992101707E-5,6.4027263923566E-7,1,0.999253354069792,40.0298881530762,2.00344488201308,16.499999910593,0.000762547250804418,0.00015312863931357,0.25,1.72692483110073E-6,6.75365454361136E-5,1.84303992622355E-6,150.0584564,150.0584564,9397.1298828125,9407.30078125,57.0158923352945,20.6878517853974,21.770052,0,0,0,40,4449,149.7749,9402.21533203125,,,,,,,,,,,,,0,,,,0.0049,,,,,,150.0584564,,,,
,29276375.105,150.0167999,14112.1977539062,4.32273037891714E-5,7.81340491429226E-7,1,0.999253354069792,40.0298881530762,2.00302374750077,16.499999910593,0.000495673888736688,6.78911297456053E-5,0.25,-1.5725782426729E-6,4.3441578461514E-5,-1.51120832294617E-6,150.0167999,150.0167999,14099.755859375,14124.6396484375,57.1941036376791,20.7010527353046,21.3904,0,0,0,40,4449,149.7801,14112.1977539062,,,,,,,,,,,,,0,,,,0,,,,,,150.0167999,,,,
,29276472.055,149.9948578,18957.208984375,1.81475030758046E-5,7.25165421688595E-7,1,0.999253354069792,40.0298881530762,2.00324937355926,16.499999910593,0.000211398693865531,9.65217170129635E-6,0.25,-2.31448004419232E-6,1.82401209558441E-5,-2.2969033940323E-6,149.9948578,149.9948578,18947.29296875,18967.125,57.1815975813714,20.6971507608407,21.3904,0,0,0,40,4449,149.7931,18957.208984375,,,,,,,,,,,,,0,,,,0.00245,,,,,,149.9948578,,,,
,29276567.285,149.9865875,23717.1474609375,-1.31579811675315E-5,1.45361500249577E-6,1,0.999253354069792,40.0298881530762,2.00332904844556,16.499999910593,-0.00013904517805544,-8.87235202972514E-5,0.25,-5.4931841198534E-6,-1.32137481882689E-5,-5.54101696695741E-6,149.9865875,149.9865875,23704.75390625,23729.541015625,57.3457395704099,20.7005869000411,21.3904,0,0,0,40,4449,149.8103,23717.1474609375,,,,,,,,,,,,,0,,,,0,,,,,,149.9865875,,,,
,29276664.54,149.9827118,28577.4033203125,-4.72108082049262E-5,1.46107973588628E-6,1,0.999253354069792,40.0298881530762,2.00349480657842,16.499999910593,-0.000520371363801241,-0.000195308877691811,0.25,-8.91257268559967E-6,-4.7428154249367E-5,-9.03105610052E-6,149.9827118,149.9827118,28567.326171875,28587.48046875,57.2972786022176,20.7021175165701,21.770052,0,0,0,40,4449,149.8288,28577.4033203125,,,,,,,,,,,,,0,,,,-0.00245,,,,,,149.9827118,,,,
,29276759.68,149.9873199,33332.53125,-7.0496551504596E-5,1.22019190852877E-6,1,0.999253354069792,40.0298881530762,2.00374226407499,16.499999910593,-0.000794739044825322,-0.000190568444937312,0.25,-4.43859327548728E-6,-7.08352340719613E-5,-4.57170044994897E-6,149.9873199,149.9873199,33325.26171875,33339.80078125,57.5395834431792,20.6958469550958,22.149702,0,0,0,40,4449,149.83725,33332.53125,,,,,,,,,,,,,0,,,,-0.00245,,,,,,149.9873199,,,,
,29276855.61,149.9912872,38127.21875,-0.00011280884873263,1.52126722993365E-6,1,0.999253354069792,40.0298881530762,2.00383342843246,16.499999910593,-0.00127376455703742,-0.000293690631021784,0.25,-6.11439874399702E-6,-0.000113352506666599,-6.32200981172216E-6,149.9912872,149.9912872,38122.12109375,38132.31640625,57.2386564632753,20.6907576610858,21.3904,0,0,0,40,4449,149.8452,38127.21875,,,,,,,,,,,,,0,,,,0,,,,,,149.9912872,,,,
,29276952.335,149.994873,42959.7578125,-0.000139132450019715,1.51126420697127E-6,1,0.999253354069792,40.0298881530762,2.00339982727958,16.499999910593,-0.00157560088776097,-0.0003338471456139,0.25,-5.05859020156532E-6,-0.000139807038002222,-5.30178660243556E-6,149.994873,149.994873,42950.02734375,42969.48828125,57.1628384969099,20.6937611824766,21.770052,0,0,0,40,4449,149.85125,42959.7578125,,,,,,,,,,,,,0,,,,-0.00245,,,,,,149.994873,,,,
,29277047.585,149.99868775,47723.08984375,-0.000162467242946593,2.7920303902948E-6,1,0.999253354069792,40.0298881530762,2.00370631561051,16.499999910593,-0.00183333424321173,-0.000428886018387512,0.25,-9.32845311186472E-6,-0.000163249797836213,-9.62844324799244E-6,149.9981232,149.9992523,47718.0390625,47728.140625,57.2394380917945,20.6894887105071,21.770052,0,0,0,40,4449,149.8497,47723.08984375,,,,,,,,,,,,,0,,,,-0.00245,,,,,,149.99868775,,,,
,29277144.68,150.0011292,52575.298828125,-0.000202502545229003,2.01455920066842E-6,1,0.999253354069792,40.0298881530762,2.00342074609531,16.499999910593,-0.00229416962049024,-0.000480695418830288,0.25,-6.90712251024988E-6,-0.000203485561684529,-7.25687323356585E-6,150.0011292,150.0011292,52570.296875,52580.30078125,57.1589303543137,20.6943898054006,21.3904,0,0,0,40,4449,149.8472,52575.298828125,,,,,,,,,,,,,0,,,,-0.0049,,,,,,150.0011292,,,,
,29277241.61,150.0019989,57420.232421875,-0.000203810180527367,2.710184814489E-6,1,0.999253354069792,40.0298881530762,2.00370324529041,16.499999910593,-0.00228448034182374,-0.000626352278127727,0.25,-1.9453437707759E-5,-0.000204780361681075,-1.98657827371835E-5,150.0019226,150.0020752,57417.7734375,57422.69140625,57.5466180998522,20.6981888330931,21.3904,0,0,0,40,4449,149.84775,57420.232421875,,,,,,,,,,,,,0,,,,-0.0049,,,,,,150.0019989,,,,
,29277336.805,150.0036469,62178.154296875,-0.000239737110723217,2.41200238701783E-6,1,0.999253354069792,40.0298881530762,2.00357377846962,16.499999910593,-0.00268814888829653,-0.000730230122064505,0.25,-2.23145025475231E-5,-0.000240879552813694,-2.27955665107226E-5,150.0036469,150.0036469,62170.609375,62185.69921875,57.4371901071599,20.6930864955655,21.3904,0,0,0,40,4449,149.8457,62178.154296875,,,,,,,,,,,,,0,,,,0,,,,,,150.0036469,,,,
,29277431.875,150.0054626,66928.87890625,-0.000274266502391624,3.5486670564752E-6,1,0.999253354069792,40.0298881530762,2.00364617124578,16.499999910593,-0.00306862115558554,-0.000874554355732154,0.25,-2.89619147007993E-5,-0.000275568594574592,-2.95277763648026E-5,150.0054626,150.0054626,66923.71875,66934.0390625,57.3480844559676,20.696145314534,21.770052,0,0,0,40,4449,149.8414,66928.87890625,,,,,,,,,,,,,0,,,,0,,,,,,150.0054626,,,,
,29277523.875,150.0064087,71528.8125,-0.000304393655462737,2.0366981991387E-6,1,0.999253354069792,40.0298881530762,2.00328199181154,16.5100004523993,-0.00345375552553594,-0.000691144199772485,0.25,-7.63556813713843E-6,-0.000305876973223209,-8.14177854795887E-6,150.0064087,150.0064087,71521.4140625,71536.2109375,56.4445218877367,20.7069108969057,21.770052,0,0,0,40,4449,149.83195,71528.8125,,,,,,,,,,,,,0,,,,0,,,,,,150.0064087,,,,
,29277621.075,150.0077057,76387.16796875,-0.000365461413524811,3.62696240108593E-6,1,0.999253354069792,40.0298881530762,2.00360850335412,16.499999910593,-0.00413937471164224,-0.000875446366207766,0.25,-1.31624897943486E-5,-0.000367236616121678,-1.37880142155576E-5,150.0077057,150.0077057,76379.515625,76394.8203125,57.3308886285445,20.7030352787281,21.3904,0,0,0,40,4449,149.8227,76387.16796875,,,,,,,,,,,,,0,,,,0,,,,,,150.0077057,,,,
,29277714.9,150.0051422,81078.07421875,-0.000389319780178817,2.64430007962952E-6,1,0.999253354069792,40.0298881530762,2.00353535394243,16.499999910593,-0.00439923375814077,-0.000991273155031013,0.25,-1.91745440020749E-5,-0.000391203509614588,-1.98642556839464E-5,150.0051422,150.0051422,81073.2265625,81082.921875,57.4192126512176,20.6988112182531,21.3904,0,0,0,40,4449,149.8211,81078.07421875,,,,,,,,,,,,,0,,,,0,,,,,,150.0051422,,,,
,29277809.635,150.0090179,85813.44921875,-0.000418057013573037,3.1662955838479E-6,1,0.999253354069792,40.0298881530762,2.00341285581631,16.499999910593,-0.00475766280185425,-0.00086928500181611,0.25,-3.47358136822639E-6,-0.000420106386919108,-4.12797786376709E-6,150.0090179,150.0090179,85810.90625,85815.9921875,57.3738781971022,20.7156433279592,21.770052,0,0,0,40,4449,149.81255,85813.44921875,,,,,,,,,,,,,0,,,,-0.0049,,,,,,150.0090179,,,,
,29277916.125,150.0083313,89757.9765625,-0.000442601853656053,4.26035897943141E-6,1,0.999253354069792,40.0298881530762,2.00317872225716,16.499999910593,-0.00500667121318116,-0.00109115240514236,0.25,-1.86791529856825E-5,-0.000444749164116718,-1.94438249017207E-5,150.0083313,150.0083313,89753.2734375,89762.6796875,57.2949337166599,20.7130688001737,21.770052,0,0,0,40,4449,149.80755,89757.9765625,,,,,,,,,,,,,0,,,,-0.0049,,,,,,150.0083313,,,,
,29278004.86,150.0039215,85326.95703125,-0.000407441166754198,2.2317185410914E-6,1,0.999253354069792,40.0298881530762,2.00311059498563,16.499999910593,-0.00461227021667181,-0.000984406539792854,0.25,-1.54355209436738E-5,-0.000409420124748628,-1.61327793033874E-5,150.0039215,150.0039215,85324.5859375,85329.328125,57.2980602307368,20.7055617209824,22.149702,0,0,0,40,4449,149.8061,85326.95703125,,,,,,,,,,,,,0,,,,-0.0049,,,,,,150.0039215,,,,
,29278099.89,149.9943237,80575.7421875,-0.000399106444595947,2.01303796863811E-6,1,0.999253354069792,40.0298881530762,2.0031401448593,16.499999910593,-0.0045023004658326,-0.00105431624460258,0.25,-2.30186600848328E-5,-0.000401032432557637,-2.37425078437683E-5,149.9943237,149.9943237,80570.8203125,80580.6640625,57.3637170263522,20.7112496181537,21.3904,0,0,0,40,4449,149.8115,80575.7421875,,,,,,,,,,,,,0,,,,-0.00245,,,,,,149.9943237,,,,
,29278194.885,149.9940033,75826.87109375,-0.000353662424806597,2.57776847042742E-6,1,0.999253354069792,40.0298881530762,2.00323308714678,16.499999910593,-0.0039881860170774,-0.000943689375989405,0.25,-2.12191476435088E-5,-0.00035536736990801,-2.1866388407728E-5,149.9940033,149.9940033,75821.90625,75831.8359375,57.3598088837561,20.7129875196108,21.770052,0,0,0,40,4449,149.81815,75826.87109375,,,,,,,,,,,,,0,,,,0,,,,,,149.9940033,,,,
,29278290.455,149.9908905,71048.4296875,-0.000298431897452865,2.66678931323516E-6,1,0.999253354069792,40.0298881530762,2.00343972407713,16.499999910593,-0.00336339685327198,-0.00080955132560265,0.25,-1.905841936535E-5,-0.000299868424438332,-1.96117424319341E-5,149.9908905,149.9908905,71038.578125,71058.28125,57.3152560581599,20.7124897130356,21.3904,0,0,0,40,4449,149.82575,71048.4296875,,,,,,,,,,,,,0,,,,-0.0049,,,,,,149.9908905,,,,
,29278386.79,149.9923401,66232.828125,-0.000278203075699192,2.23463388031171E-6,1,0.999253354069792,40.0298881530762,2.00329418587601,16.499999910593,-0.00313128149357655,-0.000777074504350903,0.25,-1.97352030638895E-5,-0.00027953878652063,-2.02620764884437E-5,149.9923401,149.9923401,66225.1640625,66240.4921875,57.5958606965638,20.7147361623442,21.3904,0,0,0,40,4449,149.83425,66232.828125,,,,,,,,,,,,,0,,,,0,,,,,,149.9923401,,,,
,29278481.82,149.9922943,61484.6171875,-0.000248141057810162,2.3778173906494E-6,1,0.999253354069792,40.0298881530762,2.00337821716224,16.499999910593,-0.00279332296508494,-0.000691449773307528,0.25,-1.74537985463437E-5,-0.000249332317236249,-1.79242167160747E-5,149.9922943,149.9922943,61481.86328125,61487.37109375,57.5348936720638,20.7067089220049,21.770052,0,0,0,40,4449,149.8431,61484.6171875,,,,,,,,,,,,,0,,,,0.00245,,,,,,149.9922943,,,,
,29278577.115,149.9909058,56719.203125,-0.000222758207165796,1.84284706146071E-6,1,0.999253354069792,40.0298881530762,2.00330752001274,16.499999910593,-0.00250389578837712,-0.0006413945937751,0.25,-1.74833843000124E-5,-0.000223824482406161,-1.79156792969311E-5,149.9909058,149.9909058,56709.296875,56729.109375,57.627125837333,20.7126600555945,21.3904,0,0,0,40,4449,149.8493,56719.203125,,,,,,,,,,,,,0,,,,0.00245,,,,,,149.9909058,,,,
,29278674.275,149.9910431,51864.265625,-0.000190388666566816,1.95135553441181E-6,1,0.999253354069792,40.0298881530762,2.00311267815684,16.499999910593,-0.00212766537265553,-0.000618078286041013,0.25,-2.10794166445054E-5,-0.000191290145572674,-2.14799404176512E-5,149.9910431,149.9910431,51851.6171875,51876.9140625,57.4285921934484,20.7162383382318,21.3904,0,0,0,40,4449,149.85715,51864.265625,,,,,,,,,,,,,0,,,,0,,,,,,149.9910431,,,,
,29278770.93,149.9901733,47031.529296875,-0.000161201240241869,2.66456042523495E-6,1,0.999253354069792,40.0298881530762,2.00323720815053,16.499999910593,-0.00181555055565022,-0.000443198335566682,0.25,-1.08132198758364E-5,-0.000161975276277901,-1.11185952423945E-5,149.9901733,149.9901733,47024.0078125,47039.05078125,57.515352959083,20.721616917859,21.770052,0,0,0,40,4449,149.86435,47031.529296875,,,,,,,,,,,,,0,,,,0.00245,,,,,,149.9901733,,,,
,29278866.64,149.9897614,42248.828125,-0.000130477721182005,1.78406486290073E-6,1,0.999253354069792,40.0298881530762,2.00315398609558,16.499999910593,-0.00145655827583308,-0.000432797738198002,0.25,-1.52529467361841E-5,-0.000131093853183477,-1.55326206005555E-5,149.9897614,149.9897614,42246.38671875,42251.26953125,57.7240477737176,20.7254812937845,21.3904,0,0,0,40,4449,149.87305,42248.828125,,,,,,,,,,,,,0,,,,0,,,,,,149.9897614,,,,
,29278963.98,149.9921417,37383.71484375,-0.000102085481283005,1.33914708873442E-6,1,0.999253354069792,40.0298881530762,2.00336033314038,16.499999910593,-0.00113606493256283,-0.000359624925393775,0.25,-1.37736276953081E-5,-0.000102564475059782,-1.40019412511398E-5,149.9921417,149.9921417,37373.76171875,37393.66796875,57.4739266475638,20.7210101804089,21.770052,0,0,0,40,4449,149.87995,37383.71484375,,,,,,,,,,,,,0,,,,-0.00245,,,,,,149.9921417,,,,
,29279062.105,149.9876709,32479.0634765625,-7.30633956928764E-5,1.51157204533069E-6,1,0.999253354069792,40.0298881530762,2.00293647837378,16.499999910593,-0.000816042953776413,-0.000239437284539036,0.25,-8.28683519712709E-6,-7.34085843306328E-5,-8.44287373638413E-6,149.9876709,149.9876709,32471.68359375,32486.443359375,57.6239993232561,20.7269313454976,21.3904,0,0,0,40,4449,149.88585,32479.0634765625,,,,,,,,,,,,,0,,,,0,,,,,,149.9876709,,,,
,29279157.79,149.9915619,27696.759765625,-4.24569531055225E-5,1.85052649288239E-6,1,0.999253354069792,40.0298881530762,2.00345445692028,16.499999910593,-0.000464465138211169,-0.000195723765208574,0.25,-9.77744123014517E-6,-4.26496152234763E-5,-9.8926237444009E-6,149.9915619,149.9915619,27694.291015625,27699.228515625,57.5849178972945,20.7217761281592,21.770052,0,0,0,40,4449,149.8969,27696.759765625,,,,,,,,,,,,,0,,,,0.0049,,,,,,149.9915619,,,,
,29279251.945,149.9947968,22991.4326171875,-1.81770555855196E-5,1.31708838980864E-6,1,0.999253354069792,40.0298881530762,2.00376805099243,16.499999910593,-0.000195100675613318,-0.000105503930556961,0.25,-6.08937176705359E-6,-1.82564800570867E-5,-6.14808820644277E-6,149.9947968,149.9947968,22986.33984375,22996.525390625,57.657609349583,20.7179265910041,21.770052,0,0,0,40,4449,149.90165,22991.4326171875,,,,,,,,,,,,,0,,,,0,,,,,,149.9947968,,,,
,29279346.93,149.9890289,18244.2607421875,1.18983899701082E-5,8.02467518875849E-7,1,0.999253354069792,40.0298881530762,2.00354352415775,16.499999910593,0.000142549556082847,-1.62113518003275E-5,0.25,-3.4951879900564E-6,1.19622671683027E-5,-3.49337143614386E-6,149.9890289,149.9890289,18239.45703125,18249.064453125,57.576319983583,20.7213793353061,22.149702,0,0,0,40,4449,149.91335,18244.2607421875,,,,,,,,,,,,,0,,,,-0.00245,,,,,,149.9890289,,,,
,29279443.67,149.9947815,13409.203125,4.46151012175601E-5,6.71691639897316E-7,1,0.999253354069792,40.0298881530762,2.00320585529314,16.499999910593,0.00051864811121633,2.98046264867488E-5,0.25,-5.15705637972269E-6,4.4841936874959E-5,-5.1111011692828E-6,149.9947815,149.9947815,13401.525390625,13416.880859375,57.5974239536023,20.7254230322788,21.770052,0,0,0,40,4449,149.91605,13409.203125,,,,,,,,,,,,,0,,,,0,,,,,,149.9947815,,,,
,29279539.35,149.9915466,8629.0517578125,6.5624195346849E-5,4.50929609589444E-7,1,0.999253354069792,40.0298881530762,2.00334886079476,16.499999910593,0.000752414458705155,0.00010419804935528,0.25,-2.2896426359582E-6,6.59493539304148E-5,-2.19585535450102E-6,149.9915466,149.9915466,8624.6376953125,8633.4658203125,57.5739750980253,20.7224939580896,21.3904,0,0,0,40,4449,149.92485,8629.0517578125,,,,,,,,,,,,,0,,,,0,,,,,,149.9915466,,,,
,29279636.305,149.9942017,3780.8994140625,8.45164014124591E-5,3.98933617101652E-7,1,0.999253354069792,40.0298881530762,2.00319862621216,16.499999910593,0.000965678430427423,0.000152981551856128,0.25,-1.29963438027254E-6,8.49324631696518E-5,-1.17047525443324E-6,149.9942017,149.9942017,3771.03686523438,3790.76196289063,57.7279559163138,20.7254064835118,21.770052,0,0,0,40,4449,149.9256,3780.8994140625,,,,,,,,,,,,,0,,,,0,,,,,,149.9942017,,,,
,29279729.28,149.9954071,-863.778350830078,-5.3531354476182E-5,3.52324999450814E-7,1,0.999253354069792,40.0298881530762,2.00336833138016,16.499999910593,-0.000609875237850878,-0.000107347138390304,0.25,-9.31148066245709E-8,-5.37933907139274E-5,-1.794981630624E-7,149.9954071,149.9954071,-871.495849609375,-856.060852050781,57.5817913832176,20.714974898228,21.770052,0,0,0,40,4449,149.9295,-863.778350830078,,,,,,,,,,,,,0,,,,0,,,,,,149.9954071,,,,
,29279824.64,150.001236,-5628.96557617188,-8.11925036374402E-5,4.40072532902796E-7,1,0.999253354069792,40.0298881530762,2.00312966365748,16.499999910593,-0.00092673224462164,-0.000152339425981834,0.25,7.76348364450444E-7,-8.15914517604192E-5,6.50063245433922E-7,150.001236,150.001236,-5631.3291015625,-5626.60205078125,57.7052886892561,20.7205877903079,21.770052,0,0,0,40,4449,149.92975,-5628.96557617188,,,,,,,,,,,,,0,,,,0.0049,,,,,,150.001236,,,,
,29279920.735,150.0023956,-10435.2822265625,-6.03385017152305E-5,5.19738243836041E-7,1,0.999253354069792,40.0298881530762,2.00347254208928,16.499999910593,-0.000690616492114551,-0.00010290310301752,0.25,1.48286064798878E-6,-6.06364730288477E-5,1.39366451488224E-6,150.0023956,150.0023956,-10440.3623046875,-10430.2021484375,57.9116386183331,20.7222857709291,22.149702,0,0,0,40,4449,149.92605,-10435.2822265625,,,,,,,,,,,,,0,,,,-0.00245,,,,,,150.0023956,,,,
,29280016.86,150.0082855,-15237.5615234375,-3.10320990462662E-5,6.56022687650133E-7,1,0.999253354069792,40.0298881530762,2.0032590202328,16.499999910593,-0.000358365843002162,-3.44482078111922E-5,0.25,2.38325318778186E-6,-3.11879483888061E-5,2.34543919278677E-6,150.0082855,150.0082855,-15242.5908203125,-15232.5322265625,57.7951759689677,20.7256168689695,21.770052,0,0,0,40,4449,149.91735,-15237.5615234375,,,,,,,,,,,,,0,,,,0,,,,,,150.0082855,,,,
,29280114.54,150.0087738,-20119.9609375,-5.66733960287181E-6,6.73647379374084E-7,1,0.999253354069792,40.0298881530762,2.00330545884975,16.499999910593,-7.53343685294732E-5,5.04521899029317E-5,0.25,5.41446288437349E-6,-5.70372567185676E-6,5.43198224839812E-6,150.0087738,150.0087738,-20124.9375,-20114.984375,57.667770520333,20.7186439507846,22.149702,0,0,0,40,4449,149.9114,-20119.9609375,,,,,,,,,,,,,0,,,,-0.0049,,,,,,150.0087738,,,,
,29280210.775,150.0109558,-24929.4462890625,2.77373681378353E-5,1.37970234292166E-6,1,0.999253354069792,40.0298881530762,2.00347875672549,16.499999910593,0.000303543639140854,0.000127277801818688,0.25,6.33573448949955E-6,2.78632701728489E-5,6.41079456089263E-6,150.0109558,150.0109558,-24931.892578125,-24927,57.9585363294869,20.7217920736756,21.770052,0,0,0,40,4449,149.89605,-24929.4462890625,,,,,,,,,,,,,0,,,,0.0049,,,,,,150.0109558,,,,
,29280308.545,150.0100403,-29814.6162109375,6.10122147774395E-5,1.38871939536188E-6,1,0.999253354069792,40.0298881530762,2.00322784361297,16.499999910593,0.000683334833046365,0.000189652353591375,0.25,6.0142920867575E-6,6.13018103691712E-5,6.14030070210874E-6,150.0100403,150.0100403,-29819.69140625,-29809.541015625,57.7631291996792,20.7317762727572,21.770052,0,0,0,40,4449,149.887,-29814.6162109375,,,,,,,,,,,,,0,,,,0,,,,,,150.0100403,,,,
,29280406.68,150.0121765,-34719.00390625,0.000102047371015333,1.54513771324213E-6,1,0.999253354069792,40.0298881530762,2.00356414852306,16.499999910593,0.00115462297804202,0.000251176334483181,0.25,4.26184209024158E-6,0.000102541026599002,4.44371954448664E-6,150.0121765,150.0121765,-34726.45703125,-34711.55078125,57.8076820252753,20.7262426069557,21.3904,0,0,0,40,4449,149.87245,-34719.00390625,,,,,,,,,,,,,0,,,,0,,,,,,150.0121765,,,,
,29280504.335,150.01029205,-39598.595703125,0.000125816576563901,1.09682992832045E-6,1,0.999253354069792,40.0298881530762,2.00348049126885,16.499999910593,0.00141353106338527,0.000366937809172268,0.25,1.02799771411553E-5,0.000126417473470137,1.05282736673102E-5,150.010025,150.0105591,-39608.484375,-39588.70703125,58.0069972976792,20.7248423915135,21.770052,0,0,0,40,4449,149.86625,-39598.595703125,,,,,,,,,,,,,0,,,,-0.0049,,,,,,150.01029205,,,,
,29280601.61,150.0119019,-44461.041015625,0.000154898304309642,1.78623283168823E-6,1,0.999253354069792,40.0298881530762,2.00401141150537,16.499999910593,0.00173982195190798,0.000456922593817546,0.25,1.31002517002733E-5,0.000155637610943463,1.34073950274687E-5,150.0119019,150.0119019,-44465.98828125,-44456.09375,57.9546281868908,20.7161002779511,21.3904,0,0,0,40,4449,149.8555,-44461.041015625,,,,,,,,,,,,,0,,,,0,,,,,,150.0119019,,,,
,29280698.31,150.0116272,-49293.923828125,0.0001846904667606,2.40278107484567E-6,1,0.999253354069792,40.0298881530762,2.00378652233615,16.499999910593,0.00207969536063089,0.000513364261302746,0.25,1.28676130156957E-5,0.000185576534821479,1.32194632806497E-5,150.0116272,150.0116272,-49303.7734375,-49284.07421875,57.8991325620254,20.718754521758,21.770052,0,0,0,40,4449,149.84185,-49293.923828125,,,,,,,,,,,,,0,,,,0.00245,,,,,,150.0116272,,,,
,29280796.07,150.0111237,-54180.853515625,0.000203105360860698,1.99754379207021E-6,1,0.999253354069792,40.0298881530762,2.00376051370931,16.499999910593,0.00227960505446385,0.000607173557183553,0.25,1.78914902032222E-5,0.000204074235933777,1.8295789752804E-5,150.0111237,150.0111237,-54196.109375,-54165.59765625,57.931960959833,20.7181083268846,22.149702,0,0,0,40,4449,149.8329,-54180.853515625,,,,,,,,,,,,,0,,,,0,,,,,,150.0111237,,,,
,29280895.785,150.0121307,-59162.833984375,0.000235042090926339,1.91598683515317E-6,1,0.999253354069792,40.0298881530762,2.00365100821511,16.499999910593,0.00265131357754566,0.000625720224858381,0.25,1.39600235049478E-5,0.00023617414651561,1.43936084559201E-5,150.0121307,150.0121307,-59167.74609375,-59157.921875,58.0648378081023,20.7194457870764,22.149702,0,0,0,40,4449,149.8237,-59162.833984375,,,,,,,,,,,,,0,,,,0,,,,,,150.0121307,,,,
,29280994.235,150.0113068,-64082.7890625,0.000278037278031855,2.51138141443444E-6,1,0.999253354069792,40.0298881530762,2.003523383672,16.499999910593,0.00312983219647904,0.000776240074966475,0.25,1.96827707041665E-5,0.000279371897030322,2.02098494620982E-5,150.0113068,150.0113068,-64090.3046875,-64075.2734375,57.9921463558138,20.7192207826099,21.770052,0,0,0,40,4449,149.8092,-64082.7890625,,,,,,,,,,,,,0,,,,0,,,,,,150.0113068,,,,
,29281090.965,150.0100555,-68917.5078125,0.000306075032635483,1.82693688462606E-6,1,0.999253354069792,40.0298881530762,2.00365937619109,16.499999910593,0.00345363768144308,0.000808869805816967,0.25,1.76593641791091E-5,0.000307550868518767,1.82183983113659E-5,150.0100555,150.0100555,-68922.546875,-68912.46875,57.7850147982177,20.7228723277563,21.770052,0,0,0,40,4449,149.7972,-68917.5078125,,,,,,,,,,,,,0,,,,0.0049,,,,,,150.0100555,,,,
,29281187.925,150.0133514,-73764.14453125,0.00033191456307584,2.61045218360646E-6,1,0.999253354069792,40.0298881530762,2.00373738691841,16.499999910593,0.00372637780875253,0.000986102571480407,0.25,2.87067959016753E-5,0.000333500720971413,2.93582877243659E-5,150.0133514,150.0133514,-73769.1484375,-73759.140625,58.0187217254677,20.7202043524426,21.770052,0,0,0,40,4449,149.7879,-73764.14453125,,,,,,,,,,,,,0,,,,0,,,,,,150.0133514,,,,
,29281285,150.0097961,-78613.84375,0.000364140001226357,2.52127168839888E-6,1,0.999253354069792,40.0298881530762,2.00346654522094,16.499999910593,0.00409108058535088,0.00106200378264341,0.25,2.97671945116774E-5,0.000365883401019577,3.04716154619026E-5,150.0097961,150.0097961,-78621.28125,-78606.40625,57.8764653349677,20.7255801513822,21.770052,0,0,0,40,4449,149.7791,-78613.84375,,,,,,,,,,,,,0,,,,-0.00245,,,,,,150.0097961,,,,
,29281382.535,150.0091858,-83491.1875,0.000406068755113625,3.01112411581346E-6,1,0.999253354069792,40.0298881530762,2.00363226424645,16.499999910593,0.0045934637882846,0.00100665326404278,0.25,1.76039237433287E-5,0.000408037348728412,1.83107291831086E-5,150.0091858,150.0091858,-83493.59375,-83488.78125,57.8217513386215,20.7216804270625,21.770052,0,0,0,40,4449,149.7753,-83491.1875,,,,,,,,,,,,,0,,,,0.0049,,,,,,150.0091858,,,,
,29281477.385,150.01026915,-88230.234375,0.000451183434633841,2.84981750832154E-6,1,0.999253354069792,40.0298881530762,2.0037968682851,16.499999910593,0.00510065333471696,0.00113900037737743,0.25,2.13531860184414E-5,0.00045336856878784,2.21450938884603E-5,150.0101318,150.0104065,-88240.25,-88220.21875,57.8983509335061,20.7200857784845,21.3904,0,0,0,40,4449,149.7604,-88230.234375,,,,,,,,,,,,,0,,,,0,,,,,,150.01026915,,,,
,29281588.615,150.0068359,-87168.78125,0.000436525153712588,3.24585779143917E-6,1,0.999253354069792,40.0298881530762,2.00373208936093,16.499999910593,0.00493980023364995,0.00107317509161308,0.25,1.81334608425906E-5,0.000438643046068135,1.88877724496283E-5,150.0068359,150.0068359,-87173.640625,-87163.921875,57.8358206519677,20.7225977711381,21.770052,0,0,0,40,4449,149.75395,-87168.78125,,,,,,,,,,,,,0,,,,0,,,,,,150.0068359,,,,
,29281682.87,150.0009918,-82456.58984375,0.000411225994297991,3.44080513737094E-6,1,0.999253354069792,40.0298881530762,2.00375005583295,16.499999910593,0.00465037869061936,0.0010291669242473,0.25,1.86754113339448E-5,0.000413218240722195,1.93959408137774E-5,150.0009918,150.0009918,-82461.3828125,-82451.796875,57.69121937591,20.7199962542012,21.770052,0,0,0,40,4449,149.7555,-82456.58984375,,,,,,,,,,,,,0,,,,-0.0049,,,,,,150.0009918,,,,
,29281781.59,149.9960785,-77524.3203125,0.00037079522281273,3.55500109961082E-6,1,0.999253354069792,40.0298881530762,2.00373925690211,16.499999910593,0.0041746757414151,0.00103398763548095,0.25,2.61376833972968E-5,0.000372576865013778,2.68350494314445E-5,149.9960785,149.9960785,-77529.21875,-77519.421875,57.9296160742754,20.7206251044903,21.770052,0,0,0,40,4449,149.7539,-77524.3203125,,,,,,,,,,,,,0,,,,0,,,,,,149.9960785,,,,
,29281878.72,149.9942017,-72669.609375,0.000338900101667134,2.83028511535121E-6,1,0.999253354069792,40.0298881530762,2.00378099729012,16.499999910593,0.00381306646245716,0.000959888938595387,0.25,2.51882479332076E-5,0.000340526018681142,2.58337202908986E-5,149.9942017,149.9942017,-72672.0390625,-72667.1796875,57.7959575974869,20.7209188968914,21.770052,0,0,0,40,4449,149.765,-72669.609375,,,,,,,,,,,,,0,,,,0,,,,,,149.9942017,,,,
,29281976.75,149.9920197,-67770.32421875,0.000301438937733146,2.0962913983838E-6,1,0.999253354069792,40.0298881530762,2.00372449679671,16.499999910593,0.00340821102358276,0.000757715223808233,0.25,1.39762619308004E-5,0.000302897717641555,1.45105415131287E-5,149.9920197,149.9920197,-67780.53125,-67760.1171875,57.8115901678715,20.7239409205399,21.770052,0,0,0,40,4449,149.7715,-67770.32421875,,,,,,,,,,,,,0,,,,0,,,,,,149.9920197,,,,
,29282076.225,149.9867249,-62798.37109375,0.000288960510812807,2.23949251854238E-6,1,0.999253354069792,40.0298881530762,2.00349590295619,16.499999910593,0.00326570379512253,0.000732359824709826,0.25,1.39306485808424E-5,0.000290357735249197,1.44468979390026E-5,149.9867249,149.9867249,-62808.2578125,-62788.484375,57.9608812150446,20.7277411042822,21.770052,0,0,0,40,4449,149.78535,-62798.37109375,,,,,,,,,,,,,0,,,,0.00245,,,,,,149.9867249,,,,
,29282173.355,149.9922638,-57945.462890625,0.000245193010152396,1.50468069021256E-6,1,0.999253354069792,40.0298881530762,2.00376985119736,16.499999910593,0.00277185749472278,0.0006190024130625,0.25,1.15991552230986E-5,0.000246378582802824,1.20373565776091E-5,149.9922638,149.9922638,-57955.57421875,-57935.3515625,57.901477447583,20.7238238166985,22.149702,0,0,0,40,4449,149.78995,-57945.462890625,,,,,,,,,,,,,0,,,,0.00245,,,,,,149.9922638,,,,
,29282270.67,149.990921,-53080.900390625,0.000207163325568875,2.29997279231185E-6,1,0.999253354069792,40.0298881530762,2.00359206378873,16.499999910593,0.0023434608238918,0.000513060835858188,0.25,8.93148371320843E-6,0.000208166109014756,9.29847213100851E-6,149.990921,149.990921,-53088.375,-53073.42578125,57.7779801415446,20.7226784366333,21.770052,0,0,0,40,4449,149.80115,-53080.900390625,,,,,,,,,,,,,0,,,,0,,,,,,149.990921,,,,
,29282369.935,149.9867859,-48118.818359375,0.000177593660324255,2.35777995883835E-6,1,0.999253354069792,40.0298881530762,2.00386808089643,16.499999910593,0.00200602670414813,0.000458255068998194,0.25,9.26719642849246E-6,0.000178450580713027,9.59058832704423E-6,149.9867859,149.9867859,-48126.45703125,-48111.1796875,57.7943943404484,20.7191005593728,21.770052,0,0,0,40,4449,149.8106,-48118.818359375,,,,,,,,,,,,,0,,,,-0.00245,,,,,,149.9867859,,,,
,29282466.94,149.9901123,-43273.888671875,0.000148539860551115,1.71330862971191E-6,1,0.999253354069792,40.0298881530762,2.00376678887796,16.499999910593,0.00168116954032185,0.000363712380792062,0.25,6.03488017024456E-6,0.000149259078614674,6.29765725741428E-6,149.9901123,149.9901123,-43278.82421875,-43268.953125,57.8498899653138,20.7223208035384,22.149702,0,0,0,40,4449,149.8186,-43273.888671875,,,,,,,,,,,,,0,,,,0.00245,,,,,,149.9901123,,,,
,29282563.62,149.993866,-38439.310546875,0.000116429313466641,1.38616915621212E-6,1,0.999253354069792,40.0298881530762,2.00381774167323,16.499999910593,0.00130480470874576,0.000359545756055693,0.25,1.12612716412557E-5,0.000116982616602539,1.14998241070813E-5,149.993866,149.993866,-38446.92578125,-38431.6953125,57.8663041642177,20.7201606674649,21.770052,0,0,0,40,4449,149.82555,-38439.310546875,,,,,,,,,,,,,0,,,,-0.00245,,,,,,149.993866,,,,
,29282658.905,149.9897003,-33677.5859375,8.88535216775663E-5,2.06457956251753E-6,1,0.999253354069792,40.0298881530762,2.0039274775718,16.499999910593,0.000996075128446298,0.000272926422573972,0.25,8.46416399013663E-6,8.92758657639524E-5,8.6459765455995E-6,149.9897003,149.9897003,-33685.078125,-33670.09375,57.8022106256407,20.7177038777206,21.770052,0,0,0,40,4449,149.8355,-33677.5859375,,,,,,,,,,,,,0,,,,0,,,,,,149.9897003,,,,
,29282755.66,149.9914856,-28842.634765625,5.32628950135765E-5,1.28474289976116E-6,1,0.999253354069792,40.0298881530762,2.0036106999904,16.499999910593,0.000588610337916376,0.000211754669468897,0.25,9.3002775597197E-6,5.35092953572436E-5,9.43022332852159E-6,149.9914856,149.9914856,-28847.64453125,-28837.625,57.8874081342369,20.723730613967,21.770052,0,0,0,40,4449,149.8421,-28842.634765625,,,,,,,,,,,,,0,,,,0,,,,,,149.9914856,,,,
,29282853.57,149.990921,-23950.5732421875,2.24805890526528E-5,1.23395323176189E-6,1,0.999253354069792,40.0298881530762,2.00330615008941,16.499999910593,0.000246827716220199,9.83725473110993E-5,0.25,4.715936785728E-6,2.25832925293336E-5,4.77475390819003E-6,149.990921,149.990921,-23955.361328125,-23945.78515625,57.7005989181407,20.7240442193069,21.770052,0,0,0,40,4449,149.8526,-23950.5732421875,,,,,,,,,,,,,0,,,,0.0049,,,,,,149.990921,,,,
,29282949.465,149.9944153,-19158.0556640625,-1.43041945144409E-5,7.59978053999921E-7,1,0.999253354069792,40.0298881530762,2.00294175604559,16.499999910593,-0.000171002375515377,1.76411703466293E-5,0.25,4.0401979776446E-6,-1.43807278463744E-5,4.03721968294376E-6,149.9944153,149.9944153,-19163.2890625,-19152.822265625,57.8115901678715,20.7231097082017,21.770052,0,0,0,40,4449,149.8551,-19158.0556640625,,,,,,,,,,,,,0,,,,0.0049,,,,,,149.9944153,,,,
,29283045.745,149.9906006,-14345.9321289062,-3.42072808328325E-5,6.24341481247128E-7,1,0.999253354069792,40.0298881530762,2.00337050244534,16.499999910593,-0.000395746757422532,-3.40022242675097E-5,0.25,2.9757551860385E-6,-3.43796425354859E-5,2.9357274196992E-6,149.9906006,149.9906006,-14350.853515625,-14341.0107421875,57.7639108281984,20.7227136248718,21.770052,0,0,0,40,4449,149.86525,-14345.9321289062,,,,,,,,,,,,,0,,,,0.0049,,,,,,149.9906006,,,,
,29283140.515,149.9907074,-9608.36962890625,-6.1655803663087E-5,4.09453685658309E-7,1,0.999253354069792,40.0298881530762,2.00328138758596,16.499999910593,-0.000705604274632663,-0.000105286209930449,0.25,1.50250558382455E-6,-6.19602619782309E-5,1.41120694984437E-6,149.9907074,149.9907074,-9613.2509765625,-9603.48828125,57.7295191733523,20.7157731188136,21.770052,0,0,0,40,4449,149.8711,-9608.36962890625,,,,,,,,,,,,,0,,,,0,,,,,,149.9907074,,,,
,29283235.53,149.991333,-4859.97973632812,-8.07962738814346E-5,3.76481726097935E-7,1,0.999253354069792,40.0298881530762,2.0039694043429,16.499999910593,-0.000923286699509858,-0.000147591614857829,0.25,1.12925433461533E-6,-8.11938478056534E-5,1.00522977406695E-6,149.991333,149.991333,-4865.09912109375,-4854.8603515625,57.8076820252753,20.7126737499586,22.149702,0,0,0,40,4449,149.8824,-4859.97973632812,,,,,,,,,,,,,0,,,,0,,,,,,149.991333,,,,
,29283330.78,149.9927826,-98.4421768188477,-9.68533334059613E-6,4.09381377372179E-7,1,0.999253354069792,40.0298881530762,2.00400879096486,16.499999910593,-0.000110264905565189,-2.00730784755908E-5,0.25,-7.34201809532095E-8,-9.73265079961579E-6,-8.93360483550976E-8,149.9927826,149.9927826,-100.953094482422,-95.9312591552734,57.6497930643907,20.709715557544,21.770052,0,0,0,40,4449,149.8869,-98.4421768188477,,,,,,,,,,,,,0,,,,0,,,,,,149.9927826,,,,
,29283423.25,149.9965057,4523.28759765625,8.25516104523356E-5,4.02529857083739E-7,1,0.999253354069792,40.0298881530762,2.00344505279209,16.499999910593,0.000942766670562371,0.000152730472388415,0.25,-9.80942609851944E-7,8.29575297821124E-5,-8.53362900300731E-7,149.9965057,149.9965057,4513.11865234375,4533.45654296875,57.8147166819484,20.7187814561567,22.149702,0,0,0,40,4449,149.8863,4523.28759765625,,,,,,,,,,,,,0,,,,-0.00245,,,,,,149.9965057,,,,
,29283518.865,150.0028534,9301.76953125,6.47371252468741E-5,5.75930675722616E-7,1,0.999253354069792,40.0298881530762,2.00357245598145,16.499999910593,0.000740504404930863,0.000113236468573745,0.25,-1.34305568079221E-6,6.50564014031354E-5,-1.24604288885599E-6,150.0028534,150.0028534,9296.7255859375,9306.8134765625,57.69121937591,20.7130243766323,21.770052,0,0,0,40,4449,149.8845,9301.76953125,,,,,,,,,,,,,0,,,,0.00245,,,,,,150.0028534,,,,
,29283616.575,150.0052795,14181.869140625,3.66058386676946E-5,5.97793840939107E-7,1,0.999253354069792,40.0298881530762,2.00401064596057,16.499999910593,0.000425684262390914,2.4575879771297E-5,0.25,-4.22140535555442E-6,3.67919266651641E-5,-4.18365270332356E-6,150.0052795,150.0052795,14179.3515625,14184.38671875,57.7943943404484,20.7072342071478,21.770052,0,0,0,40,4449,149.87825,14181.869140625,,,,,,,,,,,,,0,,,,-0.0049,,,,,,150.0052795,,,,
,29283713.535,150.007782,19028.9990234375,8.05064170384554E-6,5.01368808599305E-7,1,0.999253354069792,40.0298881530762,2.00344210753211,16.499999910593,9.94564265374969E-5,-2.8245383438967E-5,0.25,-3.88086101999823E-6,8.09627153521608E-6,-3.88705981899768E-6,150.007782,150.007782,19026.314453125,19031.68359375,57.6935642614676,20.7104046405135,21.770052,0,0,0,40,4449,149.87205,19028.9990234375,,,,,,,,,,,,,0,,,,0,,,,,,150.007782,,,,
,29283808.515,150.0102844,23776.7763671875,-1.89659760919227E-5,9.39394530748314E-7,1,0.999253354069792,40.0298881530762,2.00347657652869,16.499999910593,-0.000206176621790542,-9.49331534132327E-5,0.25,-5.02572178416825E-6,-1.90509499991815E-5,-5.08047261857872E-6,150.0102844,150.0102844,23774.0234375,23779.529296875,57.7005989181407,20.710842895773,22.149702,0,0,0,40,4449,149.8649,23776.7763671875,,,,,,,,,,,,,0,,,,-0.0049,,,,,,150.0102844,,,,
,29283906.765,150.0116272,28687.0537109375,-4.75401663866263E-5,1.15632014440387E-6,1,0.999253354069792,40.0298881530762,2.00367868089075,16.499999910593,-0.000525117901711256,-0.000190542076397177,0.25,-8.43551979819899E-6,-4.77598524630258E-5,-8.55215913456922E-6,150.0116272,150.0116272,28682.205078125,28691.90234375,57.75218640041,20.7122001520685,22.149702,0,0,0,40,4449,149.8507,28687.0537109375,,,,,,,,,,,,,0,,,,0.00245,,,,,,150.0116272,,,,
,29284004.27,150.013382,33559.486328125,-7.87349208994037E-5,1.53622020219319E-6,1,0.999253354069792,40.0298881530762,2.00337918201285,16.499999910593,-0.000882315904774297,-0.000242331322461336,0.25,-7.54842919460485E-6,-7.91090380365415E-5,-7.70977451687052E-6,150.013382,150.013382,33549.48828125,33569.484375,57.6669888918138,20.7125375364541,21.770052,0,0,0,40,4449,149.8376,33559.486328125,,,,,,,,,,,,,0,,,,0.00245,,,,,,150.013382,,,,
,29284104.555,150.0097961,38574.3984375,-0.00010639448811531,1.73808296732322E-6,1,0.999253354069792,40.0298881530762,2.00349921083495,16.499999910593,-0.00118469602300615,-0.000371384152937933,0.25,-1.40527824195788E-5,-0.000106894141315096,-1.42891932685754E-5,150.0097961,150.0097961,38571.87890625,38576.91796875,57.6701154058907,20.7085735736091,22.149702,0,0,0,40,4449,149.8335,38574.3984375,,,,,,,,,,,,,0,,,,0,,,,,,150.0097961,,,,
,29284201.325,150.0111618,43409.5234375,-0.000138347189505628,1.29350804720243E-6,1,0.999253354069792,40.0298881530762,2.00360745941176,16.499999910593,-0.00155639794437133,-0.000392072145256661,0.25,-1.0300946453464E-5,-0.000139009633519363,-1.05686224685204E-5,150.0107727,150.0115509,43404.78515625,43414.26171875,57.8194064530638,20.7115270235962,22.149702,0,0,0,40,4449,149.8206,43409.5234375,,,,,,,,,,,,,0,,,,0.00245,,,,,,150.0111618,,,,
,29284297.605,150.0094147,48224.673828125,-0.000159442013669323,2.37559415637852E-6,1,0.999253354069792,40.0298881530762,2.00321603035651,16.499999910593,-0.00179808279014758,-0.000424781369053435,0.25,-9.50398503420322E-6,-0.000160209400240846,-9.80010738173944E-6,150.0094147,150.0094147,48222.23046875,48227.1171875,57.6966907755446,20.716873767531,22.149702,0,0,0,40,4449,149.81155,48224.673828125,,,,,,,,,,,,,0,,,,0,,,,,,150.0094147,,,,
,29284393.59,150.0104675,53019.9609375,-0.000194247523320104,1.98679957006619E-6,1,0.999253354069792,40.0298881530762,2.00349321763322,16.499999910593,-0.00219104792916836,-0.000516663428698786,0.25,-1.14993369073356E-5,-0.000195182805048835,-1.18587779804698E-5,150.0104675,150.0104675,53009.97265625,53029.94921875,57.6755868055253,20.712853424229,22.149702,0,0,0,40,4449,149.80405,53019.9609375,,,,,,,,,,,,,0,,,,0,,,,,,150.0104675,,,,
,29284490.335,150.0102692,57854.546875,-0.000232761870254342,1.92949068218594E-6,1,0.999253354069792,40.0298881530762,2.00354272619447,16.499999910593,-0.00263352759425092,-0.000573273396834974,0.25,-9.75797668082521E-6,-0.000233889162098124,-1.01678188155921E-5,150.0102692,150.0102692,57846.9296875,57862.1640625,57.596642325083,20.712616931647,22.149702,0,0,0,40,4449,149.79245,57854.546875,,,,,,,,,,,,,0,,,,0,,,,,,150.0102692,,,,
,29284586.525,150.0113525,62663.0546875,-0.000261529458831818,2.48209550791982E-6,1,0.999253354069792,40.0298881530762,2.00351325408211,16.499999910593,-0.00296857568339823,-0.000588985632657623,0.25,-6.12805507436328E-6,-0.000262803899665595,-6.56350377504461E-6,150.0113525,150.0113525,62660.5625,62665.546875,57.6146197810253,20.711322860589,22.149702,0,0,0,40,4449,149.7875,62663.0546875,,,,,,,,,,,,,0,,,,0.0049,,,,,,150.0113525,,,,
,29284683.52,150.0105438,67513.53125,-0.000284491763147306,2.78571225701424E-6,1,0.999253354069792,40.0298881530762,2.00339308914894,16.499999910593,-0.00320806112476577,-0.000761096077844756,0.25,-1.72348764154545E-5,-0.000285862108696656,-1.77590600203017E-5,150.0105438,150.0105438,67508.4765625,67518.5859375,57.5270773868715,20.7145339999208,22.149702,0,0,0,40,4449,149.7687,67513.53125,,,,,,,,,,,,,0,,,,-0.0049,,,,,,150.0105438,,,,
,29284780.665,150.0115509,72366.3515625,-0.000314869594512104,2.64902895664683E-6,1,0.999253354069792,40.0298881530762,2.00356441808185,16.499999910593,-0.00356592619764099,-0.000756212843663531,0.25,-1.15118896054153E-5,-0.000316398341421482,-1.20533108199245E-5,150.0115509,150.0115509,72361.2578125,72371.4453125,57.6544828355061,20.7082039262963,22.529354,0,0,0,40,4449,149.75905,72366.3515625,,,,,,,,,,,,,0,,,,0,,,,,,150.0115509,,,,
,29284877.525,150.0110016,77209.0078125,-0.000378559445174669,2.36601141376147E-6,1,0.999253354069792,40.0298881530762,2.00360481675562,16.499999910593,-0.00428697793853006,-0.000911085345393826,0.25,-1.40083760709757E-5,-0.000380397651432538,-1.46581949244287E-5,150.0110016,150.0110016,77203.6875,77214.328125,57.5583425276407,20.708647326849,22.529354,0,0,0,40,4449,149.7523,77209.0078125,,,,,,,,,,,,,0,,,,-0.00245,,,,,,150.0110016,,,,
,29284975.775,150.0124359,82119.859375,-0.000368526116138936,3.68073364392527E-6,1,0.999253354069792,40.0298881530762,2.0036407652937,16.499999910593,-0.0041919612544107,-0.000780555898472021,0.25,-4.30427444582201E-6,-0.000370330336292927,-4.88911767939962E-6,150.0124359,150.0124359,82112.53125,82127.1875,57.8022106256407,20.7070670153062,22.149702,0,0,0,40,4449,149.73855,82119.859375,,,,,,,,,,,,,0,,,,0,,,,,,150.0124359,,,,
,29285070.935,150.0111084,86875.66796875,-0.000389833784893517,3.5600415246288E-6,1,0.999253354069792,40.0298881530762,2.00373556592023,16.499999910593,-0.00441278004889185,-0.000950681779117246,0.25,-1.55175760703269E-5,-0.000391726069093176,-1.61881138546587E-5,150.0111084,150.0111084,86865.78125,86885.5546875,57.5700669554292,20.7004997258023,22.529354,0,0,0,40,4449,149.7337,86875.66796875,,,,,,,,,,,,,0,,,,0.00245,,,,,,150.0111084,,,,
,29285178.265,150.0101776,88705.34765625,-0.000428983471222438,3.48215420412398E-6,1,0.999253354069792,40.0298881530762,2.00362535048514,16.499999910593,-0.00485583047733014,-0.00104528322533951,0.25,-1.70049576800092E-5,-0.000431066100924721,-1.77417294889374E-5,150.0101776,150.0101776,88692.9453125,88717.75,57.6302523514099,20.7097956370899,22.529354,0,0,0,40,4449,149.7166,88705.34765625,,,,,,,,,,,,,0,,,,-0.0049,,,,,,150.0101776,,,,
,29285272.465,150.0029907,83994.69921875,-0.000405717030609242,2.57974424936533E-6,1,0.999253354069792,40.0298881530762,2.00370142093518,16.499999910593,-0.00457986882345696,-0.00106190572961432,0.25,-2.25095176395404E-5,-0.00040767644602728,-2.32399966939078E-5,150.0029907,150.0029907,83989.6640625,83999.734375,57.5544343850446,20.7058228450851,21.770052,0,0,0,40,4449,149.7182,83994.69921875,,,,,,,,,,,,,0,,,,-0.00245,,,,,,150.0029907,,,,
,29285369.835,149.9959869,79128.34765625,-0.000368002428741928,3.61928698652061E-6,1,0.999253354069792,40.0298881530762,2.00374216908074,16.499999910593,-0.00414592221158969,-0.00101079830501012,0.25,-2.45899835367766E-5,-0.000369772860656856,-2.52749807196675E-5,149.9957275,149.9962463,79120.8046875,79135.890625,57.6021137247176,20.7049815811791,22.149702,0,0,0,40,4449,149.7235,79128.34765625,,,,,,,,,,,,,0,,,,0.00245,,,,,,149.9959869,,,,
,29285464.85,149.9911804,74377.28125,-0.000355859743589792,2.59703282666687E-6,1,0.999253354069792,40.0298881530762,2.00382423591293,16.499999910593,-0.00400815703697125,-0.000983897094414541,0.25,-2.4339520695124E-5,-0.000357570444606519,-2.50064420077025E-5,149.9911804,149.9911804,74366.84375,74387.71875,57.7943943404484,20.7009991959229,22.149702,0,0,0,40,4449,149.73375,74377.28125,,,,,,,,,,,,,0,,,,-0.0049,,,,,,149.9911804,,,,
,29285562.35,149.9905548,69504.453125,-0.000333542423179638,2.44987646082805E-6,1,0.999253354069792,40.0298881530762,2.00382243993229,16.499999910593,-0.00376827892320159,-0.000856174858437583,0.25,-1.70199745226626E-5,-0.000335154296311964,-1.76183409251291E-5,149.9905548,149.9905548,69499.421875,69509.484375,57.6998172896215,20.7035437997138,21.770052,0,0,0,40,4449,149.7369,69504.453125,,,,,,,,,,,,,0,,,,-0.0049,,,,,,149.9905548,,,,
,29285659.625,149.9927826,64643.66796875,-0.000290545742945468,2.84409226408686E-6,1,0.999253354069792,40.0298881530762,2.0040296100896,16.499999910593,-0.00328116008312734,-0.000755480156233919,0.25,-1.56666927367645E-5,-0.000291948118537824,-1.61935218270106E-5,149.9927826,149.9927826,64641.515625,64645.8203125,57.7154498600061,20.6984688514705,22.149702,0,0,0,40,4449,149.7449,64643.66796875,,,,,,,,,,,,,0,,,,-0.00245,,,,,,149.9927826,,,,
,29285758.095,149.9940033,59720.802734375,-0.000238305959629651,2.37356105479978E-6,1,0.999253354069792,40.0298881530762,2.00390664751543,16.499999910593,-0.00268989512414147,-0.000626239809223707,0.25,-1.34303319887287E-5,-0.000239454952274459,-1.38664970344972E-5,149.9939728,149.9940338,59708.3359375,59733.26953125,57.7428068581792,20.6975054018615,22.149702,0,0,0,40,4449,149.7529,59720.802734375,,,,,,,,,,,,,0,,,,0.0049,,,,,,149.9940033,,,,
,29285854.38,149.9903564,54907.810546875,-0.000216197294620914,2.06000553789744E-6,1,0.999253354069792,40.0298881530762,2.00397821714598,16.499999910593,-0.00244582881909117,-0.000537117911791287,0.25,-9.46028008421287E-6,-0.000217243666970519,-9.84367452925377E-6,149.9903564,149.9903564,54900.21484375,54915.40625,57.677931691083,20.6991989270205,22.529354,0,0,0,40,4449,149.7603,54907.810546875,,,,,,,,,,,,,0,,,,0,,,,,,149.9903564,,,,
,29285950.455,149.991394,50105.669921875,-0.000180657225487541,2.96898037866851E-6,1,0.999253354069792,40.0298881530762,2.00351760056016,16.499999910593,-0.0020352651477987,-0.000494940018806881,0.25,-1.19592764919059E-5,-0.00018152501480959,-1.23004157157781E-5,149.991394,149.991394,50103.01953125,50108.3203125,57.6482298073523,20.7064650217821,22.149702,0,0,0,40,4449,149.7684,50105.669921875,,,,,,,,,,,,,0,,,,0,,,,,,149.991394,,,,
,29286047.775,149.9898529,45242.904296875,-0.000156697599471731,1.79118663489569E-6,1,0.999253354069792,40.0298881530762,2.0036442472953,16.499999910593,-0.00177180604376049,-0.00039279159289359,0.25,-7.16724564304764E-6,-0.000157455117327576,-7.44816875825045E-6,149.9898529,149.9898529,45240.12890625,45245.6796875,57.7162314885253,20.7054022042538,22.529354,0,0,0,40,4449,149.77675,45242.904296875,,,,,,,,,,,,,0,,,,0,,,,,,149.9898529,,,,
,29286145.245,149.9891663,40370.283203125,-0.000116554486994176,1.47319673232187E-6,1,0.999253354069792,40.0298881530762,2.00365047114496,16.499999910593,-0.00131508392737976,-0.000308352361504554,0.25,-6.75067979354482E-6,-0.000117115564847339,-6.96715205239545E-6,149.9891663,149.9891663,40362.875,40377.69140625,57.6818398336792,20.7001164566671,21.770052,0,0,0,40,4449,149.78675,40370.283203125,,,,,,,,,,,,,0,,,,0.0049,,,,,,149.9891663,,,,
,29286242.215,149.9930725,35523.359375,-0.000107026198453505,1.39929923152184E-6,1,0.999253354069792,40.0298881530762,2.00355534747776,16.499999910593,-0.00120774498913338,-0.00028183921354182,0.25,-6.08492702136164E-6,-0.000107541436383465,-6.28364604334482E-6,149.9930725,149.9930725,35510.39453125,35536.32421875,57.6411951506792,20.7071321066586,22.149702,0,0,0,40,4449,149.7919,35523.359375,,,,,,,,,,,,,0,,,,0,,,,,,149.9930725,,,,
,29286338.72,149.9902191,30702.5908203125,-6.74905836077715E-5,1.58846831682634E-6,1,0.999253354069792,40.0298881530762,2.00362526845132,16.499999910593,-0.000757356325275621,-0.000202248673612201,0.25,-5.98773276935367E-6,-6.78120083079464E-5,-6.12389734546172E-6,149.9902191,149.9902191,30697.4140625,30707.767578125,57.6341604940061,20.7062031844229,22.529354,0,0,0,40,4449,149.79725,30702.5908203125,,,,,,,,,,,,,0,,,,0.0049,,,,,,149.9902191,,,,
,29286433.56,149.9871674,25959.9580078125,-3.17688124357661E-5,1.4110715666272E-6,1,0.999253354069792,40.0298881530762,2.00327822169963,16.499999910593,-0.000350616050707743,-0.000128614338497618,0.25,-5.75177842639642E-6,-3.19154187496879E-5,-5.83038430730708E-6,149.9871674,149.9871674,25954.9765625,25964.939453125,57.6943458899869,20.7095086226928,21.770052,0,0,0,40,4449,149.81545,25959.9580078125,,,,,,,,,,,,,0,,,,0,,,,,,149.9871674,,,,
,29286529.275,149.9916229,21177.6396484375,-1.89285332326941E-6,8.77183819021315E-7,1,0.999253354069792,40.0298881530762,2.00349113477119,16.499999910593,-1.18347120686264E-5,-5.96582400351933E-5,0.25,-4.90478653695434E-6,-1.89432628619025E-6,-4.93183662803859E-6,149.9916229,149.9916229,21172.587890625,21182.69140625,57.8663041642177,20.7020132432952,22.149702,0,0,0,40,4449,149.82235,21177.6396484375,,,,,,,,,,,,,0,,,,-0.00245,,,,,,149.9916229,,,,
,29286626.355,149.9895477,16325.2543945313,1.80186585691847E-5,8.76676129574615E-7,1,0.999253354069792,40.0298881530762,2.00389922488242,16.499999910593,0.000206624213848704,2.8750255945528E-5,0.25,-6.16945537330619E-7,1.81079368993331E-5,-5.91224271368488E-7,149.9895477,149.9895477,16320.072265625,16330.4365234375,57.749059886333,20.7043683215489,22.149702,0,0,0,40,4449,149.83015,16325.2543945313,,,,,,,,,,,,,0,,,,0.00245,,,,,,149.9895477,,,,
,29286719.705,149.9913483,11660.6538085938,4.82987355208107E-5,5.12682901336968E-7,1,0.999253354069792,40.0298881530762,2.00378923196606,16.499999910593,0.000555185849467403,6.92411844187509E-5,0.25,-2.33988377979552E-6,4.85391056445845E-5,-2.27411678861624E-6,149.9913483,149.9913483,11653.107421875,11668.2001953125,57.6810582051599,20.7031429036314,22.149702,0,0,0,40,4449,149.83955,11660.6538085938,,,,,,,,,,,,,0,,,,-0.0049,,,,,,149.9913483,,,,
,29286816.47,149.9909897,6822.83178710937,7.48492782712315E-5,5.45301971576269E-7,1,0.999253354069792,40.0298881530762,2.00381677587897,16.499999910593,0.000856415536648315,0.000130122089771501,0.25,-1.6247453217254E-6,7.52185301698591E-5,-1.51274837191115E-6,149.9905548,149.9914246,6815.36279296875,6830.30078125,57.9296160742754,20.7032406183031,22.529354,0,0,0,40,4449,149.8483,6822.83178710937,,,,,,,,,,,,,0,,,,0,,,,,,149.9909897,,,,
,29286911.595,149.9942169,2067.30053710938,7.91497135828422E-5,3.3245246696112E-7,1,0.999253354069792,40.0298881530762,2.00337866494994,16.499999910593,0.000902620123551033,0.000153703310392237,0.25,-3.02635229577094E-7,7.95378511956781E-5,-1.77021974407675E-7,149.9942169,149.9942169,2062.17553710938,2072.42553710938,57.7983024830446,20.7123827516613,22.149702,0,0,0,40,4449,149.85105,2067.30053710938,,,,,,,,,,,,,0,,,,-0.0049,,,,,,149.9942169,,,,
,29286954.67,149.9953308,-0.235968485474586,3.60596440220973E-7,3.28803994705072E-7,1,0.999253354069792,40.0298881530762,2.00350759580727,16.499999910593,5.45286454076355E-6,-6.99317756662513E-6,0.25,-6.76419198763619E-7,3.63449285810492E-7,-6.79152535170576E-7,149.9953308,149.9953308,-0.243580371141434,-0.228356599807739,57.6208728091792,20.7081184648912,21.770052,0,0,0,40,4417,149.8509,-0.235968485474586,,,,,,,,,,,,,0,,,,0,,,,,,149.9953308,,,,