File: data/looselyPackedNP/sc-ios-7/ppms/rawdata/ES_S17_ZFCW_100OE.DAT
[Header]
; VSM Data File (default extension .dat)
; Copyright (c) 2003-2013, Quantum Design, Inc. All rights reserved.
TITLE,
FILEOPENTIME,29311427.78,12/06/2018,2:04 pm
BYAPP,VSM,2.0,2.0
INFO,PPMS VSM Option Release 1.4.10 Build 1,APPNAME
INFO,Quantum Design Linear Motor Servo Controller,MOTOR_MODULE_NAME
INFO,3101-100 M1,MOTOR_HW_VERSION
INFO,MMC1014,MOTOR_SERIAL_NUMBER
INFO,SRV No X-over 01.03.11,MOTOR_SOFTWARE_VERSION
INFO,Quantum Design VSM Detection Module,VSM_MODULE_NAME
INFO,3101-150 F0,VSM_HW_VERSION
INFO,VSM707,VSM_SERIAL_NUMBER
INFO,VSM No X-over 01.02.05 May 20 2008 13:51:47,VSM_SOFTWARE_VERSION
INFO,704,PREAMP_SERIAL_NUMBER
INFO,822,COIL_SERIAL_NUMBER
INFO,0,MOMENT_UNITS
INFO,Iron Oxide Spheres,SAMPLE_MATERIAL
INFO,7 nm diameter, collaboration Mainz,SAMPLE_COMMENT
INFO,,SAMPLE_MASS
INFO,,SAMPLE_VOLUME
INFO,,SAMPLE_MOLECULAR_WEIGHT
INFO,,SAMPLE_SIZE
INFO,,SAMPLE_SHAPE
DATATYPE,COMMENT,1
DATATYPE,TIME,2
STARTUPAXIS,X,2
STARTUPAXIS,Y1,5
[Data]
Comment,Time Stamp (sec),Temperature (K),Magnetic Field (Oe),Moment (emu),M. Std. Err. (emu),Transport Action,Averaging Time (sec),Frequency (Hz),Peak Amplitude (mm),Center Position (mm),Coil Signal' (mV),Coil Signal" (mV),Range (mV),M. Quad. Signal (emu),M. Raw' (emu),M. Raw" (emu),Min. Temperature (K),Max. Temperature (K),Min. Field (Oe),Max. Field (Oe),Mass (grams),Motor Lag (deg),Pressure (Torr),VSM Status (code),Motor Status (code),Measure Status (code),Measure Count,PPMS Status (code),System Temp. (K),System Field (Oe),Sample Position (deg),Bridge 1 Resistance (ohms),Bridge 1 Excitation (에),Bridge 2 Resistance (ohms),Bridge 2 Excitation (에),Bridge 3 Resistance (ohms),Bridge 3 Excitation (에),Bridge 4 Resistance (ohms),Bridge 4 Excitation (에),Signal 1 Vin (V),Signal 2 Vin (V),Digital Inputs (code),Drive 1 Iout (mA),Drive 1 Ipower (W),Drive 2 Iout (mA),Drive 2 Ipower (W),Pressure (),Map 20 (),Map 21 (),Map 22 (),Map 23 (),Map 24 (),Map 25 (),Map 26 (),Map 27 (),Map 28 (),Map 29 ()
,29316122.08,9.9682598,99.5482559204102,,,2,,,,16.679999550879,,,,,,,9.9682598,9.9682598,99.5482559204102,99.5482559204102,,,12.658426,,,,-99999999,4373,10.0566,99.5482559204102,,,,,,,,,,,,,,,,,,,,,,,9.9682598,,,,
,29316399.855,12.5347271,99.5482559204102,7.17976078382227E-6,3.74801613991016E-7,1,0.999253354069792,40.0298881530762,1.97917998557258,16.669999808073,7.99258833388972E-5,1.44935064224119E-5,0.25,2.61589328723515E-8,7.13837353072681E-6,6.06351884725794E-8,12.5347271,12.5347271,99.5482559204102,99.5482559204102,57.1362631272561,20.7101452435478,13.797379,0,0,0,40,4370,12.5351,99.5482559204102,,,,,,,,,,,,,0,,,,0.0049,,,,,,12.5347271,,,,
,29316540.17,16.0210533,99.5482559204102,8.67110200172238E-6,3.00624413794869E-7,1,0.999253354069792,40.0298881530762,1.97885410209958,16.6800003498793,9.66815629643821E-5,1.65438686640191E-5,0.25,-5.43548516004442E-8,8.62145314546331E-6,-1.22233337411423E-8,16.0210533,16.0210533,99.5482559204102,99.5482559204102,56.9807190519291,20.7326496571101,14.177031,0,0,0,40,4370,16.0736,99.5482559204102,,,,,,,,,,,,,0,,,,0,,,,,,16.0210533,,,,
,29316682.565,19.5336266,99.5482559204102,1.02056057407383E-5,3.6068638445955E-7,1,0.999253354069792,40.0298881530762,1.97905761449482,16.669999808073,0.000113433733528844,2.15512724824603E-5,0.25,1.22362458204229E-7,1.01463098777626E-5,1.71070960358717E-7,19.5336266,19.5336266,99.5482559204102,99.5482559204102,57.0807675023906,20.7314176620368,14.936333,0,0,0,40,4370,19.642,99.5482559204102,,,,,,,,,,,,,0,,,,0,,,,,,19.5336266,,,,
,29316824.07,23.0516243,99.5482559204102,1.22799326871949E-5,3.37752166588484E-7,1,0.999253354069792,40.0298881530762,2.00257188194213,16.6999995708466,0.000138089028370248,2.60067267194553E-5,0.25,1.26132010299316E-7,1.22097546027444E-5,1.86324559476272E-7,23.0258904,23.0773582,99.5482559204102,99.5482559204102,57.1769078102561,20.7275528672686,15.315984,0,0,0,40,4370,23.20295,99.5482559204102,,,,,,,,,,,,,0,,,,-0.00245,,,,,,23.0516243,,,,
,29316965.685,26.5215931,99.5482559204102,1.40117816745285E-5,2.93466445285546E-7,1,0.999253354069792,40.0298881530762,2.00238179982492,16.6999995708466,0.00015824879740653,2.59209105251962E-5,0.25,-1.92723925828662E-7,1.39361524462074E-5,-1.18972382195267E-7,26.5215931,26.5215931,99.5482559204102,99.5482559204102,57.3715333115445,20.7331871548583,15.695635,0,0,0,40,4370,26.7948,99.5482559204102,,,,,,,,,,,,,0,,,,-0.0049,,,,,,26.5215931,,,,
,29317104.4,30.0083008,99.5482559204102,1.62292206871482E-5,3.06704683223195E-7,1,0.999253354069792,40.0298881530762,2.00262129008601,16.6999995708466,0.000183460540141504,2.95390067471322E-5,0.25,-2.72535125670987E-7,1.61470168832199E-5,-1.81716981357417E-7,30.0083008,30.0083008,99.5482559204102,99.5482559204102,57.4317187075253,20.7281757558061,16.075285,0,0,0,40,4370,30.2692,99.5482559204102,,,,,,,,,,,,,0,,,,0,,,,,,30.0083008,,,,
,29317246.175,33.5139275,99.5482559204102,1.82755277488064E-5,3.31496978447498E-7,1,0.999253354069792,40.0298881530762,2.00144383633152,16.7100001126528,0.000206509803664325,3.36315041520873E-5,0.25,-2.81493377397234E-7,1.81915051367616E-5,-1.71988625027329E-7,33.5139275,33.5139275,99.5482559204102,99.5482559204102,57.1815975813714,20.7399468799968,16.454937,0,0,0,40,4370,33.8217,99.5482559204102,,,,,,,,,,,,,0,,,,0,,,,,,33.5139275,,,,
,29317388.3,37.0578079,99.5482559204102,1.99462634123886E-5,3.34731002986036E-7,1,0.999253354069792,40.0298881530762,2.00076160887165,16.7100001126528,0.000225693963510638,3.54355360972706E-5,0.25,-4.30120811771588E-7,1.98683829867224E-5,-3.01184567054359E-7,37.0578079,37.0578079,99.5482559204102,99.5482559204102,57.3113479155637,20.7464232697452,16.834587,0,0,0,40,4370,37.39885,99.5482559204102,,,,,,,,,,,,,0,,,,-0.00245,,,,,,37.0578079,,,,
,29317529.07,40.534914,99.5482559204102,2.09381633971304E-5,3.41038381493705E-7,1,0.999253354069792,40.0298881530762,1.99905869962024,16.7100001126528,0.000235946882949341,4.26305522472436E-5,0.25,2.13329856458304E-8,2.08705371770529E-5,1.63977001306278E-7,40.5011215,40.5687065,99.5482559204102,99.5482559204102,57.7467150007753,20.7592597855377,17.214239,0,0,0,40,4370,40.94295,99.5482559204102,,,,,,,,,,,,,0,,,,0,,,,,,40.534914,,,,
,29317671.11,44.0121574,99.5482559204102,2.19220740875047E-5,3.32566519069866E-7,1,0.999253354069792,40.0298881530762,1.99924471300192,16.6999995708466,0.000247548094177068,4.33160978078863E-5,0.25,-1.06548880624499E-7,2.18738918069316E-5,5.10388855316675E-8,44.0121574,44.0121574,99.5482559204102,99.5482559204102,57.3379232852176,20.7513168521975,17.214239,0,0,0,40,4370,44.5353,99.5482559204102,,,,,,,,,,,,,0,,,,0.0049,,,,,,44.0121574,,,,
,29317812.04,47.515789,99.5482559204102,2.17847545177418E-5,3.24201557266294E-7,1,0.999253354069792,40.0298881530762,2.00012751723993,16.6999995708466,0.000245626534171639,4.72435345072936E-5,0.25,2.55372792428113E-7,2.17580426888435E-5,4.16171395003729E-7,47.515789,47.515789,99.5482559204102,99.5482559204102,57.70138054666,20.7428345164228,17.593889,0,0,0,40,4370,48.11645,99.5482559204102,,,,,,,,,,,,,0,,,,0,,,,,,47.515789,,,,
,29317957.8,51.0594673,99.5482559204102,2.16757183382727E-5,3.37653360934146E-7,1,0.999253354069792,40.0298881530762,2.00003231282205,16.6999995708466,0.000245112115827791,4.46170268066542E-5,0.25,3.74997350329603E-8,2.1676061164668E-5,1.98605616644628E-7,51.0594673,51.0594673,99.5482559204102,99.5482559204102,57.7224845166792,20.750760312258,18.353191,0,0,0,40,4370,51.8347,99.5482559204102,,,,,,,,,,,,,0,,,,0,,,,,,51.0594673,,,,
,29318080.975,54.0413475,99.5482559204102,2.12166863445308E-5,3.2588425980794E-7,1,0.999253354069792,40.0298881530762,2.00019482928177,16.6900008916855,0.000240161674691072,4.37595116221262E-5,0.25,4.30511917444952E-8,2.12372760339962E-5,1.98317231788927E-7,54.0413475,54.0413475,99.5482559204102,99.5482559204102,57.3684067974676,20.7466430788788,19.112494,0,0,0,40,4374,55.0004,99.5482559204102,,,,,,,,,,,,,0,,,,-0.0049,,,,,,54.0413475,,,,
,29318223.29,57.5192528,99.5482559204102,2.09569789402799E-5,3.06810065928102E-7,1,0.999253354069792,40.0298881530762,1.99971673030197,16.6900008916855,0.000237392788738814,4.3319487708047E-5,0.25,5.38939794535787E-8,2.0998169521922E-5,2.01605766577053E-7,57.5192528,57.5192528,99.5482559204102,99.5482559204102,57.9022590761023,20.750301728082,19.492144,0,0,0,40,4374,58.6397,99.5482559204102,,,,,,,,,,,,,0,,,,0.0049,,,,,,57.5192528,,,,
,29318364.845,61.0090485,99.5482559204102,1.99507889472751E-5,3.52508975362156E-7,1,0.999253354069792,40.0298881530762,1.99931651795933,16.6900008916855,0.000227087394800583,3.59952969349908E-5,0.25,-4.06024787549031E-7,2.00098847749172E-5,-2.74007318011154E-7,61.0090485,61.0090485,99.5482559204102,99.5482559204102,57.4770531616407,20.7604195227752,19.492144,0,0,0,40,4374,62.2191,99.5482559204102,,,,,,,,,,,,,0,,,,0,,,,,,61.0090485,,,,
,29318507.2,64.5288086,99.5482559204102,1.95300655864476E-5,3.16324535935491E-7,1,0.999253354069792,40.0298881530762,2.00027300155354,16.6800003498793,0.000222256822618076,3.69291864028605E-5,0.25,-2.43567158786335E-7,1.96004462975501E-5,-1.22351596884153E-7,64.5288086,64.5288086,99.5482559204102,99.5482559204102,57.7873596837753,20.7548469282644,20.251448,0,0,0,40,4374,65.8182,99.5482559204102,,,,,,,,,,,,,0,,,,-0.00245,,,,,,64.5288086,,,,
,29318650.455,68.0307693,99.5482559204102,1.87607213054973E-5,3.8203773124354E-7,1,0.999253354069792,40.0298881530762,2.00018739901976,16.6800003498793,0.00021334562403597,3.6981080737527E-5,0.25,-9.46040611600711E-8,1.88380262234999E-5,1.39391084554388E-8,68.0307693,68.0307693,99.5482559204102,99.5482559204102,57.8170615675061,20.7547555185803,20.251448,0,0,0,40,4374,69.45025,99.5482559204102,,,,,,,,,,,,,0,,,,-0.00245,,,,,,68.0307693,,,,
,29318791.77,71.520752,99.5482559204102,1.82547218363435E-5,3.35730059892451E-7,1,0.999253354069792,40.0298881530762,2.00074492152988,16.6800003498793,0.000207741588829682,3.59750345008576E-5,0.25,-8.72019993157542E-8,1.83378103876505E-5,1.05995363018948E-8,71.520752,71.520752,99.5482559204102,99.5482559204102,58.0179400969485,20.7413640317152,19.871798,0,0,0,40,4374,73.0188,99.5482559204102,,,,,,,,,,,,,0,,,,0,,,,,,71.520752,,,,
,29318933.715,75.0073318,99.5482559204102,1.744518871682E-5,3.54133726038072E-7,1,0.999253354069792,40.0298881530762,2.0006631537924,16.6599992662668,0.00019801150852168,3.76289710301183E-5,0.25,2.08498011496657E-7,1.75289863303237E-5,2.96295361455142E-7,75.0073318,75.0073318,99.5482559204102,99.5482559204102,57.6748051770061,20.727309725987,20.251448,0,0,0,40,4374,76.6032,99.5482559204102,,,,,,,,,,,,,0,,,,0,,,,,,75.0073318,,,,
,29319076.33,78.5707397,99.5482559204102,1.69513021747485E-5,2.67584671270254E-7,1,0.999253354069792,40.0298881530762,1.99942748549239,16.6599992662668,0.000192949277390518,3.31261478298298E-5,0.25,-9.22693009310172E-8,1.7038516852466E-5,-1.47867805364095E-8,78.5707397,78.5707397,99.5482559204102,99.5482559204102,57.9772954139484,20.7592670835586,20.631098,0,0,0,40,4374,80.2177,99.5482559204102,,,,,,,,,,,,,0,,,,0,,,,,,78.5707397,,,,
,29319217.985,82.0307236,99.5482559204102,1.61295213376454E-5,4.03365844411235E-7,1,0.999253354069792,40.0298881530762,1.99949955678717,16.6599992662668,0.000183463225137414,3.25035990067385E-5,0.25,3.49058554782267E-9,1.62151772978046E-5,7.22209147041678E-8,82.0307236,82.0307236,99.5482559204102,99.5482559204102,57.8702123068138,20.7499198197333,20.631098,0,0,0,40,4374,83.80415,99.5482559204102,,,,,,,,,,,,,0,,,,0.0049,,,,,,82.0307236,,,,
,29319359.22,85.5233002,99.5482559204102,1.5468067005409E-5,3.51724337822015E-7,1,0.999253354069792,40.0298881530762,2.00073241249816,16.6400000452995,0.000176094912797429,3.10369631792809E-5,0.25,-5.68848996738622E-9,1.55524017051634E-5,5.5461637949347E-8,85.5233002,85.5233002,99.5482559204102,99.5482559204102,57.7951759689677,20.7389334540384,21.3904,0,0,0,40,4374,87.38275,99.5482559204102,,,,,,,,,,,,,0,,,,-0.0049,,,,,,85.5233002,,,,
,29319500.225,89.0301971,99.5482559204102,1.46884484160272E-5,2.97117676291447E-7,1,0.999253354069792,40.0298881530762,2.0012332507633,16.6400000452995,0.000167338495319283,2.91238760489094E-5,0.25,-3.29390644553111E-8,1.47700527182278E-5,2.10064460400398E-8,89.0301971,89.0301971,99.5482559204102,99.5482559204102,57.9436853876215,20.7400621026075,21.01075,0,0,0,40,4374,90.9157,99.5482559204102,,,,,,,,,,,,,0,,,,-0.00245,,,,,,89.0301971,,,,
,29319642.755,92.59334945,99.5482559204102,1.40527489642149E-5,3.04633341976953E-7,1,0.999253354069792,40.0298881530762,2.00136020373771,16.6400000452995,0.000160474827849902,2.58301729221116E-5,0.25,-2.06900045648396E-7,1.41323364282917E-5,-1.59722288552056E-7,92.5494537,92.6372452,99.5482559204102,99.5482559204102,57.7412436011407,20.7425285370283,21.3904,0,0,0,40,4374,94.49,99.5482559204102,,,,,,,,,,,,,0,,,,-0.0049,,,,,,92.59334945,,,,
,29319779.9,96.0363464,99.5482559204102,1.37010032290622E-5,3.21467628281317E-7,1,0.999253354069792,40.0298881530762,2.00150553780253,16.6200008243322,0.00015626689034951,2.6365392367089E-5,0.25,-9.53138234487264E-8,1.3778736707202E-5,-5.16339384787942E-8,96.0363464,96.0363464,99.5482559204102,99.5482559204102,57.9483751587369,20.7376633871503,21.3904,0,0,0,40,4374,97.93595,99.5482559204102,,,,,,,,,,,,,0,,,,0,,,,,,96.0363464,,,,
,29319922.49,99.5276718,99.5482559204102,1.29490745165289E-5,2.56051118278704E-7,1,0.999253354069792,40.0298881530762,2.00172601663726,16.6200008243322,0.000147950750901272,2.35456976747168E-5,0.25,-2.08278984350213E-7,1.30231513004107E-5,-1.70241414992162E-7,99.5276718,99.5276718,99.5482559204102,99.5482559204102,57.4895592179484,20.7315307194029,21.3904,0,0,0,40,4374,101.51755,99.5482559204102,,,,,,,,,,,,,0,,,,0.00245,,,,,,99.5276718,,,,
,29320063.02,103.0205688,99.5482559204102,1.25489305269499E-5,3.31136638877449E-7,1,0.999253354069792,40.0298881530762,2.00146960791067,16.6200008243322,0.000143069188261959,2.44794604394087E-5,0.25,-5.35606086121846E-8,1.26202926178378E-5,-1.80748556929125E-8,103.0205688,103.0205688,99.5482559204102,99.5482559204102,57.901477447583,20.7340791014121,21.3904,0,0,0,40,4374,105.0562,99.5482559204102,,,,,,,,,,,,,0,,,,0,,,,,,103.0205688,,,,
,29320184.92,106.0528488,99.5482559204102,1.22579809777985E-5,3.45620546363783E-7,1,0.999253354069792,40.0298881530762,2.00102316721615,16.5899991989136,0.000140398238122633,2.00439947639208E-5,0.25,-3.89743896108097E-7,1.23284811942015E-5,-3.58692594446139E-7,106.0528488,106.0528488,99.5482559204102,99.5482559204102,57.6497930643907,20.7241224321048,21.3904,0,0,0,40,4374,108.1156,99.5482559204102,,,,,,,,,,,,,0,,,,0,,,,,,106.0528488,,,,
,29320324.205,109.5195389,99.5482559204102,1.20041381151436E-5,3.69088880796202E-7,1,0.999253354069792,40.0298881530762,2.00158956727228,16.5899991989136,0.00013710366293763,2.20345645293068E-5,0.25,-1.69215806129241E-7,1.20723178702431E-5,-1.39338626710123E-7,109.5195389,109.5195389,99.5482559204102,99.5482559204102,57.6810582051599,20.7190097958394,21.3904,0,0,0,40,4374,111.6218,99.5482559204102,,,,,,,,,,,,,0,,,,0.00245,,,,,,109.5195389,,,,
,29320465.54,113.0289154,99.5482559204102,1.15869574701837E-5,3.52759472023501E-7,1,0.999253354069792,40.0298881530762,2.00122829752981,16.5899991989136,0.000132718450450243,1.89405105011386E-5,0.25,-3.65810611166038E-7,1.16528684658207E-5,-3.39645386944439E-7,113.0289154,113.0289154,99.5482559204102,99.5482559204102,57.9124202468523,20.7278393840465,21.3904,0,0,0,40,4374,115.1779,99.5482559204102,,,,,,,,,,,,,0,,,,-0.00245,,,,,,113.0289154,,,,
,29320604.305,116.510025,99.5482559204102,1.12665443686308E-5,3.1580557927883E-7,1,0.999253354069792,40.0298881530762,2.00139024986192,16.550000756979,0.000129016671720988,1.862276044986E-5,0.25,-3.36333864786762E-7,1.13300856857673E-5,-3.12106702134137E-7,116.510025,116.510025,99.5482559204102,99.5482559204102,57.2957153451791,20.7248077835055,21.770052,0,0,0,40,4374,118.66425,99.5482559204102,,,,,,,,,,,,,0,,,,0,,,,,,116.510025,,,,
,29320747.23,120.0513,99.5482559204102,1.14361594782819E-5,3.06913876332869E-7,1,0.999253354069792,40.0298881530762,2.00142627470118,16.550000756979,0.00013023086547758,2.30410857809538E-5,0.25,2.3172947466709E-8,1.14992599188362E-5,4.85193273299497E-8,120.0513,120.0513,99.5482559204102,99.5482559204102,57.627125837333,20.7262219003927,21.3904,0,0,0,40,4374,122.2607,99.5482559204102,,,,,,,,,,,,,0,,,,-0.00245,,,,,,120.0513,,,,
,29320885.915,123.5045242,99.5482559204102,1.06496815552221E-5,3.61088352378446E-7,1,0.999253354069792,40.0298881530762,2.00161154633176,16.550000756979,0.00012240909278267,1.49894066520915E-5,0.25,-5.45118992575841E-7,1.07090629951868E-5,-5.2566567745861E-7,123.5045242,123.5045242,99.5482559204102,99.5482559204102,57.5911709254484,20.7311637342952,21.770052,0,0,0,40,4374,125.742,99.5482559204102,,,,,,,,,,,,,0,,,,0,,,,,,123.5045242,,,,
,29321027.875,127.0246277,99.5482559204102,1.0218615037902E-5,3.20715543255625E-7,1,0.999253354069792,40.0298881530762,2.00174659339519,16.5199991315603,0.000116918526726124,1.74502388033232E-5,0.25,-2.52849889985352E-7,1.0274380489971E-5,-2.3363697376183E-7,127.0246277,127.0246277,99.5482559204102,99.5482559204102,57.2746113751599,20.721016173578,21.770052,0,0,0,40,4374,129.30905,99.5482559204102,,,,,,,,,,,,,0,,,,0.0049,,,,,,127.0246277,,,,
,29321168.67,130.5067902,99.5482559204102,9.74491978897723E-6,3.59396723228905E-7,1,0.999253354069792,40.0298881530762,2.00221772756365,16.5199991315603,0.00011172734426125,1.54344075087232E-5,0.25,-3.46463864278268E-7,9.79764960198112E-6,-3.29509194982454E-7,130.5067902,130.5067902,99.5482559204102,99.5482559204102,57.6787133196022,20.7179549150833,22.149702,0,0,0,40,4374,132.8445,99.5482559204102,,,,,,,,,,,,,0,,,,-0.0049,,,,,,130.5067902,,,,
,29321309.68,134.0181732,99.5482559204102,9.83227293957348E-6,3.59286939726143E-7,1,0.999253354069792,40.0298881530762,2.00263379542164,16.5199991315603,0.000112285716828549,1.81956906727056E-5,0.25,-1.18821897859654E-7,9.88433024254951E-6,-1.01237157108661E-7,134.0181732,134.0181732,99.5482559204102,99.5482559204102,57.6396318936407,20.7187890993573,22.149702,0,0,0,40,4374,136.3844,99.5482559204102,,,,,,,,,,,,,0,,,,0,,,,,,134.0181732,,,,
,29321428.095,137.0028534,99.5482559204102,9.31256259985379E-6,3.54875289196282E-7,1,0.999253354069792,40.0298881530762,2.00164891356302,16.4800006896257,0.000106881100005427,1.38579921370165E-5,0.25,-4.07566109942103E-7,9.36180215127377E-6,-3.93002807449081E-7,137.0028534,137.0028534,99.5482559204102,99.5482559204102,57.7342089444676,20.7180899870212,21.770052,0,0,0,40,4374,139.3507,99.5482559204102,,,,,,,,,,,,,0,,,,0.00245,,,,,,137.0028534,,,,
,29321570.375,140.5486908,99.5482559204102,9.2683561099087E-6,3.24162165604897E-7,1,0.999253354069792,40.0298881530762,2.00278971864694,16.4800006896257,0.000105952266351838,1.64984816611224E-5,0.25,-1.68081314175598E-7,9.316200233415E-6,-1.52965835243537E-7,140.5486908,140.5486908,99.5482559204102,99.5482559204102,57.6951275185061,20.7140592580484,22.149702,0,0,0,40,4374,142.9372,99.5482559204102,,,,,,,,,,,,,0,,,,0,,,,,,140.5486908,,,,
,29321709.845,144.0069427,99.5482559204102,9.11641364289849E-6,2.55305956145803E-7,1,0.999253354069792,40.0298881530762,2.00283483078028,16.4800006896257,0.000104607138823361,1.39436093714949E-5,0.25,-3.65159394231798E-7,9.1630697692987E-6,-3.51847571379538E-7,144.0069427,144.0069427,99.5482559204102,99.5482559204102,57.8577062505061,20.7133743629159,22.529354,0,0,0,40,4374,146.4375,99.5482559204102,,,,,,,,,,,,,0,,,,0,,,,,,144.0069427,,,,
,29321850.675,147.50354,99.5482559204102,8.8395364877538E-6,3.14124043643861E-7,1,0.999253354069792,40.0298881530762,2.00269661996085,16.440000385046,0.000100877869724169,1.65995556113066E-5,0.25,-8.31026274605078E-8,8.8835813338849E-6,-6.93285155517445E-8,147.50354,147.50354,99.5482559204102,99.5482559204102,57.5020652742561,20.7058764371204,22.529354,0,0,0,40,4374,149.9723,99.5482559204102,,,,,,,,,,,,,0,,,,-0.00245,,,,,,147.50354,,,,
,29321991.345,151.0405426,99.5482559204102,8.80394748532655E-6,3.33089256998059E-7,1,0.999253354069792,40.0298881530762,2.00271022625846,16.440000385046,0.000100639012320162,1.55239626896143E-5,0.25,-1.70728444248968E-7,8.84717535845443E-6,-1.57901789722348E-7,151.0405426,151.0405426,99.5482559204102,99.5482559204102,57.7396803441023,20.7124033979027,22.909004,0,0,0,40,4374,153.49255,99.5482559204102,,,,,,,,,,,,,0,,,,-0.00245,,,,,,151.0405426,,,,
,29322131.74,154.5454559,99.5482559204102,9.00890360497058E-6,2.91580584261307E-7,1,0.999253354069792,40.0298881530762,2.00303131664779,16.440000385046,0.000103020532522036,1.57016582442986E-5,0.25,-1.90468560680975E-7,9.05234736765754E-6,-1.77852126192839E-7,154.5454559,154.5454559,99.5482559204102,99.5482559204102,57.7162314885253,20.7116264229133,22.529354,0,0,0,40,4374,157.015,99.5482559204102,,,,,,,,,,,,,0,,,,-0.0049,,,,,,154.5454559,,,,
,29322271.245,158.019928,99.5482559204102,8.48904359754822E-6,3.28320206278013E-7,1,0.999253354069792,40.0298881530762,2.00312717514846,16.4000000804663,9.76685303896791E-5,1.13636511486884E-5,0.25,-4.80258436013321E-7,8.52963711084752E-6,-4.70160531835021E-7,158.019928,158.019928,99.5482559204102,99.5482559204102,57.5231692442753,20.7004797462721,22.529354,0,0,0,40,4374,160.51835,99.5482559204102,,,,,,,,,,,,,0,,,,-0.00245,,,,,,158.019928,,,,
,29322414.26,161.5618134,99.5482559204102,8.61566716278156E-6,3.43973842199871E-7,1,0.999253354069792,40.0298881530762,2.00326854337726,16.4000000804663,9.78796922527333E-5,1.86738487627701E-5,0.25,1.39759312202698E-7,8.65514005696417E-6,1.52560582081621E-7,161.5618134,161.5618134,99.5482559204102,99.5482559204102,57.891316276833,20.7066261857498,22.909004,0,0,0,40,4374,164.094,99.5482559204102,,,,,,,,,,,,,0,,,,0.0049,,,,,,161.5618134,,,,
,29322552.085,165.0266113,99.5482559204102,8.05601532201229E-6,3.11804286140261E-7,1,0.999253354069792,40.0298881530762,2.00357245718378,16.4000000804663,9.18529715996466E-5,1.558408233829E-5,0.25,-3.37982774493393E-8,8.09238732254375E-6,-2.29057236127923E-8,165.0266113,165.0266113,99.5482559204102,99.5482559204102,57.6732419199676,20.699970049289,22.909004,0,0,0,40,4374,167.5454,99.5482559204102,,,,,,,,,,,,,0,,,,0,,,,,,165.0266113,,,,
,29322692.81,168.552063,99.5482559204102,7.73229167851322E-6,3.74864656725607E-7,1,0.999253354069792,40.0298881530762,2.00240321527617,16.3599997758865,8.8123561251659E-5,1.48365059417957E-5,0.25,-4.19419902721053E-8,7.76644828060538E-6,-3.18225177228084E-8,168.552063,168.552063,99.5482559204102,99.5482559204102,57.749059886333,20.7109186870729,22.909004,0,0,0,40,4374,171.05575,99.5482559204102,,,,,,,,,,,,,0,,,,0,,,,,,168.552063,,,,
,29322832.595,172.0090332,99.5482559204102,7.37111329268107E-6,3.52029504322672E-7,1,0.999253354069792,40.0298881530762,2.00315764148699,16.3599997758865,8.51583729942945E-5,7.65409755544258E-6,0.25,-6.09831115152491E-7,7.40368362583617E-6,-6.0290326301647E-7,172.0090332,172.0090332,99.5482559204102,99.5482559204102,57.8389471660446,20.7012038711217,23.288654,0,0,0,40,4374,174.5619,99.5482559204102,,,,,,,,,,,,,0,,,,0,,,,,,172.0090332,,,,
,29322972.5,175.52902225,99.5482559204102,7.65337189713158E-6,3.43056885133272E-7,1,0.999253354069792,40.0298881530762,2.00230528011283,16.3599997758865,8.71702162112965E-5,1.48673193741472E-5,0.25,-2.46531463872293E-8,7.68561501328355E-6,-1.50938393550053E-8,175.4968262,175.5612183,99.5482559204102,99.5482559204102,57.769382227833,20.7181762052757,22.529354,0,0,0,40,4374,178.0581,99.5482559204102,,,,,,,,,,,,,0,,,,0.0049,,,,,,175.52902225,,,,
,29323111.875,179.0099335,99.5482559204102,7.2352025359947E-6,2.700018788811E-7,1,0.999253354069792,40.0298881530762,2.001555021155,16.3100007921457,8.28901379852914E-5,1.10532175533375E-5,0.25,-2.86325552773899E-7,7.26526153279554E-6,-2.78597290861714E-7,179.0099335,179.0099335,99.5482559204102,99.5482559204102,57.3918556530445,20.7101336008997,23.288654,0,0,0,40,4374,181.5374,99.5482559204102,,,,,,,,,,,,,0,,,,0,,,,,,179.0099335,,,,
,29323252.79,182.5191956,99.5482559204102,7.21131941525746E-6,4.0928513240569E-7,1,0.999253354069792,40.0298881530762,2.00177735271162,16.3100007921457,8.2012993945923E-5,1.44889786385225E-5,0.25,2.00030090546249E-8,7.24014364612331E-6,2.87368877862325E-8,182.5191956,182.5191956,99.5482559204102,99.5482559204102,57.5685036983907,20.720402228659,23.288654,0,0,0,40,4374,185.0552,99.5482559204102,,,,,,,,,,,,,0,,,,0,,,,,,182.5191956,,,,
,29323391.87,186.01220705,99.5482559204102,6.84832908384956E-6,3.84501238519442E-7,1,0.999253354069792,40.0298881530762,2.00038711195196,16.3100007921457,7.90401034152645E-5,6.75631082457862E-6,0.25,-5.95849037171617E-7,6.87569393755325E-6,-5.9014809382971E-7,185.9835205,186.0408936,99.5482559204102,99.5482559204102,57.8069003967561,20.7421161166124,23.288654,0,0,0,40,4374,188.5452,99.5482559204102,,,,,,,,,,,,,0,,,,0.00245,,,,,,186.01220705,,,,
,29323513.055,189.0426025,99.5482559204102,6.80109713624854E-6,3.79792990164356E-7,1,0.999253354069792,40.0298881530762,2.00004578801709,16.270000487566,7.73836569174642E-5,1.29873362316991E-5,0.25,-3.91453593628464E-8,6.82698907238427E-6,-3.14906492749923E-8,189.0426025,189.0426025,99.5482559204102,99.5482559204102,57.1425161554099,20.7254508300629,23.668306,0,0,0,40,4374,191.5821,99.5482559204102,,,,,,,,,,,,,0,,,,-0.0049,,,,,,189.0426025,,,,
,29323653.93,192.5208435,99.5482559204102,6.67871839883557E-6,3.18709659805445E-7,1,0.999253354069792,40.0298881530762,2.00019314298201,16.270000487566,7.59791303439301E-5,1.28061032994086E-5,0.25,-3.36073925560407E-8,6.70341305308935E-6,-2.62453574767888E-8,192.5208435,192.5208435,99.5482559204102,99.5482559204102,57.4770531616407,20.732108838946,22.909004,0,0,0,40,4374,195.1153,99.5482559204102,,,,,,,,,,,,,0,,,,0.0049,,,,,,192.5208435,,,,
,29323794.495,196.0337677,99.5482559204102,6.67692258856012E-6,3.59147768790402E-7,1,0.999253354069792,40.0298881530762,1.99991305594633,16.270000487566,7.63296167221048E-5,1.05573221022458E-5,0.25,-2.30745957860926E-7,6.70108478803598E-6,-2.24256338299077E-7,196.0337677,196.0337677,99.5482559204102,99.5482559204102,57.6044586102753,20.7467354879357,23.668306,0,0,0,40,4374,198.6433,99.5482559204102,,,,,,,,,,,,,0,,,,-0.0049,,,,,,196.0337677,,,,
,29323916.225,199.052948,99.5482559204102,6.52139848166613E-6,3.47467866716266E-7,1,0.999253354069792,40.0298881530762,2.00036227803317,16.2300001829863,7.44603397386996E-5,1.08890516733802E-5,0.25,-1.74516232525907E-7,6.54431025978986E-6,-1.68115529928881E-7,199.052948,199.052948,99.5482559204102,99.5482559204102,57.2128627221407,20.7293880165938,23.668306,0,0,0,40,4374,201.71225,99.5482559204102,,,,,,,,,,,,,0,,,,-0.00245,,,,,,199.052948,,,,
,29324053.845,202.5059738,99.5482559204102,6.4050007818183E-6,3.72725244049889E-7,1,0.999253354069792,40.0298881530762,2.0005558882339,16.2300001829863,7.3159361812799E-5,1.05249756388219E-5,0.25,-1.86174022934505E-7,6.42680235204796E-6,-1.80062655856358E-7,202.4779968,202.5339508,99.5482559204102,99.5482559204102,57.5880444113715,20.7308249759581,23.668306,0,0,0,40,4374,205.15565,99.5482559204102,,,,,,,,,,,,,0,,,,-0.0049,,,,,,202.5059738,,,,
,29324196.055,206.0472412,99.5482559204102,6.38224821365995E-6,3.85713900975302E-7,1,0.999253354069792,40.0298881530762,2.0012378310055,16.2300001829863,7.24129339635732E-5,1.33799390223894E-5,0.25,6.88802595009893E-8,6.40297067689546E-6,7.5677648939934E-8,206.0472412,206.0472412,99.5482559204102,99.5482559204102,57.6451032932753,20.729071702269,23.288654,0,0,0,40,4374,208.7221,99.5482559204102,,,,,,,,,,,,,0,,,,-0.0049,,,,,,206.0472412,,,,
,29324333.475,209.5031586,99.5482559204102,6.17487068541078E-6,3.44685810351828E-7,1,0.999253354069792,40.0298881530762,2.00091806819055,16.1799993366003,7.05401706961626E-5,1.00690683898324E-5,0.25,-1.86012624385511E-7,6.19447509712553E-6,-1.80365437817742E-7,209.5031586,209.5031586,99.5482559204102,99.5482559204102,57.2871174314676,20.7180676717867,23.668306,0,0,0,40,4374,212.1615,99.5482559204102,,,,,,,,,,,,,0,,,,0.0049,,,,,,209.5031586,,,,
,29324475.07,213.022583,99.5482559204102,6.33301821540769E-6,4.09511337602559E-7,1,0.999253354069792,40.0298881530762,2.00144565961338,16.1799993366003,7.28375986209864E-5,7.55722056404685E-6,0.25,-4.34459340734291E-7,6.35262345428568E-6,-4.2951187225506E-7,213.022583,213.022583,99.5482559204102,99.5482559204102,57.312129544083,20.7201083337957,23.668306,0,0,0,40,4374,215.69795,99.5482559204102,,,,,,,,,,,,,0,,,,0.00245,,,,,,213.022583,,,,
,29324617.86,216.5548096,99.5482559204102,6.26229298926428E-6,3.03225913369297E-7,1,0.999253354069792,40.0298881530762,2.00255123665915,16.1799993366003,7.23640899322282E-5,5.6867987726916E-6,0.25,-5.8682634184578E-7,6.28108456551521E-6,-5.82464881696534E-7,216.5548096,216.5548096,99.5482559204102,99.5482559204102,57.4770531616407,20.7039683665381,23.668306,0,0,0,40,4374,219.2859,99.5482559204102,,,,,,,,,,,,,0,,,,-0.0049,,,,,,216.5548096,,,,
,29324755.995,220.037735,99.5482559204102,6.11696192245328E-6,3.89693634527218E-7,1,0.999253354069792,40.0298881530762,2.00266749270139,16.1300003528595,7.06252616722475E-5,5.8712733876783E-6,0.25,-5.45232209892918E-7,6.13456319519996E-6,-5.40939030016951E-7,220.037735,220.037735,99.5482559204102,99.5482559204102,57.2628869473714,20.7171154111548,24.047956,0,0,0,40,4374,222.7515,99.5482559204102,,,,,,,,,,,,,0,,,,-0.0049,,,,,,220.037735,,,,
,29324896.775,223.5185547,99.5482559204102,5.54601393230021E-6,3.5066769055448E-7,1,0.999253354069792,40.0298881530762,2.00310993313499,16.1300003528595,6.27653653776181E-5,1.26634904083266E-5,0.25,1.51237244406978E-7,5.56070718871567E-6,1.56814975558755E-7,223.5185547,223.5185547,99.5482559204102,99.5482559204102,57.5216059872369,20.7075464320225,24.047956,0,0,0,40,4374,226.2786,99.5482559204102,,,,,,,,,,,,,0,,,,-0.00245,,,,,,223.5185547,,,,
,29325035.89,227.01293945,99.5482559204102,6.11861186242424E-6,3.42424880072291E-7,1,0.999253354069792,40.0298881530762,2.00305086497609,16.1300003528595,7.06645091555663E-5,5.73290430843741E-6,0.25,-5.57444922407442E-7,6.13475882047939E-6,-5.5326684066157E-7,226.9855804,227.0402985,99.5482559204102,99.5482559204102,57.4512594205061,20.7156985111196,24.047956,0,0,0,40,4374,229.7572,99.5482559204102,,,,,,,,,,,,,0,,,,0,,,,,,227.01293945,,,,
,29325177.71,230.5187683,99.5482559204102,5.5773773658232E-6,3.97719196926866E-7,1,0.999253354069792,40.0298881530762,2.0028048802705,16.0900000482798,6.39648098715237E-5,7.72338970349347E-6,0.25,-2.88201566840481E-7,5.59121890370703E-6,-2.83890644184182E-7,230.5187683,230.5187683,99.5482559204102,99.5482559204102,57.5497446139292,20.7142999457355,24.427608,0,0,0,40,4374,233.3237,99.5482559204102,,,,,,,,,,,,,0,,,,0,,,,,,230.5187683,,,,
,29325318.295,234.0166473,99.5482559204102,5.74902566183294E-6,3.65131446104562E-7,1,0.999253354069792,40.0298881530762,2.00378683855594,16.0900000482798,6.57088815395736E-5,9.38955313380699E-6,0.25,-1.71594350575434E-7,5.7624836942558E-6,-1.66917089789963E-7,234.0166473,234.0166473,99.5482559204102,99.5482559204102,57.5208243587176,20.7029811046087,24.047956,0,0,0,40,4374,236.8447,99.5482559204102,,,,,,,,,,,,,0,,,,0,,,,,,234.0166473,,,,
,29325458.495,237.5226898,99.5482559204102,5.25945435156972E-6,4.08938052370824E-7,1,0.999253354069792,40.0298881530762,2.00401821125656,16.0900000482798,6.01388176704285E-5,8.43867236386776E-6,0.25,-1.7019734634042E-7,5.2711356764317E-6,-1.66010180002117E-7,237.5226898,237.5226898,99.5482559204102,99.5482559204102,57.5950790680446,20.700701542869,23.668306,0,0,0,40,4374,240.36695,99.5482559204102,,,,,,,,,,,,,0,,,,0.00245,,,,,,237.5226898,,,,
,29325578.815,240.5270233,99.5482559204102,5.40161977406835E-6,3.86776676335095E-7,1,0.999253354069792,40.0298881530762,1.99155766147848,16.0399992018938,6.15061834055254E-5,7.95266191897226E-6,0.25,-2.33282219582114E-7,5.41309908380065E-6,-2.29155677695031E-7,240.5270233,240.5270233,99.5482559204102,99.5482559204102,57.5911709254484,20.6982332295353,24.047956,0,0,0,40,4374,243.3895,99.5482559204102,,,,,,,,,,,,,0,,,,0,,,,,,240.5270233,,,,
,29325716.905,244.0005188,99.5482559204102,5.3628181198714E-6,3.12867046108391E-7,1,0.999253354069792,40.0298881530762,1.99171785556975,16.0399992018938,6.12913911993895E-5,6.57032219495011E-6,0.25,-3.48758467845166E-7,5.37365821551312E-6,-3.44941007677018E-7,244.0005188,244.0005188,99.5482559204102,99.5482559204102,57.6114932669484,20.6999123634813,24.047956,0,0,0,40,4374,246.8498,99.5482559204102,,,,,,,,,,,,,0,,,,-0.00245,,,,,,244.0005188,,,,
,29325859.87,247.5431671,99.5482559204102,4.75294897226439E-6,3.95301295214465E-7,1,0.999253354069792,40.0298881530762,1.9918650594667,16.0399992018938,5.44239653306634E-5,5.21330710342683E-6,0.25,-3.62963294689289E-7,4.76200487235577E-6,-3.59709330043362E-7,247.5162048,247.5701294,99.5482559204102,99.5482559204102,57.5231692442753,20.6983710195053,24.047956,0,0,0,40,4374,250.43245,99.5482559204102,,,,,,,,,,,,,0,,,,0.0049,,,,,,247.5431671,,,,
,29325981.61,250.552063,99.5482559204102,5.06646174970887E-6,4.19946380016093E-7,1,0.999253354069792,40.0298881530762,1.99161322002573,16.0000007599592,5.82078891097589E-5,4.36096804429486E-6,0.25,-4.92608396441545E-7,5.07565906841113E-6,-4.89342510688575E-7,250.552063,250.552063,99.5482559204102,99.5482559204102,57.5810097546984,20.6969327700955,24.427608,0,0,0,40,4374,253.4711,99.5482559204102,,,,,,,,,,,,,0,,,,0,,,,,,250.552063,,,,
,29326121.025,254.0485535,99.5482559204102,5.2198426914389E-6,3.8980154352872E-7,1,0.999253354069792,40.0298881530762,1.9917852649736,15.990000218153,5.8930659059585E-5,1.04724566045343E-5,0.25,2.18176895982286E-8,5.22824279902434E-6,2.60297614234937E-8,254.0485535,254.0485535,99.5482559204102,99.5482559204102,57.4793980471984,20.7010858767945,24.047956,0,0,0,40,4374,256.9495,99.5482559204102,,,,,,,,,,,,,0,,,,0,,,,,,254.0485535,,,,
,29326261.8,257.5551147,99.5482559204102,5.01201789863426E-6,4.39286822479241E-7,1,0.999253354069792,40.0298881530762,1.99223555221257,15.990000218153,5.74374155719451E-5,5.166451796609E-6,0.25,-4.11765092614853E-7,5.01980128859448E-6,-4.08433511094434E-7,257.5551147,257.5551147,99.5482559204102,99.5482559204102,57.555997642083,20.6958422590628,24.427608,0,0,0,40,4374,260.5283,99.5482559204102,,,,,,,,,,,,,0,,,,-0.00245,,,,,,257.5551147,,,,
,29326399.705,261.0021973,99.5482559204102,4.8548230935236E-6,4.46789720019325E-7,1,0.999253354069792,40.0298881530762,1.99196396409833,15.939999371767,5.47914742780118E-5,9.79276570535205E-6,0.25,2.52131202134403E-8,4.86143394189543E-6,2.90087106811993E-8,261.0021973,261.0021973,99.5482559204102,99.5482559204102,57.3215090863138,20.6899984318937,24.427608,0,0,0,40,4374,263.9504,99.5482559204102,,,,,,,,,,,,,0,,,,0,,,,,,261.0021973,,,,
,29326539.93,264.5022888,99.5482559204102,5.09289895997444E-6,3.76148630729527E-7,1,0.999253354069792,40.0298881530762,1.99243646127519,15.939999371767,5.85830048170691E-5,3.93611911779918E-6,0.25,-5.34498958513396E-7,5.09962695383805E-6,-5.31279162560879E-7,264.5022888,264.5022888,99.5482559204102,99.5482559204102,57.5872627828522,20.6826519331706,24.427608,0,0,0,40,4374,267.4729,99.5482559204102,,,,,,,,,,,,,0,,,,0.0049,,,,,,264.5022888,,,,
,29326680.85,268.0119324,99.5482559204102,4.677075915859E-6,3.73855750391716E-7,1,0.999253354069792,40.0298881530762,1.9929724833762,15.939999371767,5.3626501813659E-5,4.65565052070199E-6,0.25,-3.98719098418463E-7,4.68259367924534E-6,-3.95653814154466E-7,268.0119324,268.0119324,99.5482559204102,99.5482559204102,57.5669404413522,20.6825324435486,24.047956,0,0,0,40,4374,271.00605,99.5482559204102,,,,,,,,,,,,,0,,,,-0.00245,,,,,,268.0119324,,,,
,29326822.685,271.52227785,99.5482559204102,4.58541607352898E-6,4.13819055430663E-7,1,0.999253354069792,40.0298881530762,1.99274433834695,15.8900003880262,5.12927782032622E-5,1.18923057593424E-5,0.25,2.57946819455263E-7,4.58976636287407E-6,2.61590299395759E-7,271.4945679,271.5499878,99.5482559204102,99.5482559204102,57.3926372815638,20.6799365578761,24.427608,0,0,0,40,4374,274.5423,99.5482559204102,,,,,,,,,,,,,0,,,,0,,,,,,271.52227785,,,,
,29326962.64,275.0058899,99.5482559204102,4.62844398773494E-6,3.93093804817225E-7,1,0.999253354069792,40.0298881530762,1.99297669901814,15.8900003880262,5.25150583905882E-5,7.72497601323228E-6,0.25,-1.18364419915135E-7,4.63253660773253E-6,-1.15099095606811E-7,274.9749451,275.0368347,99.5482559204102,99.5482559204102,57.4520410490253,20.6767007501731,24.807261,0,0,0,40,4374,278.0588,99.5482559204102,,,,,,,,,,,,,0,,,,0,,,,,,275.0058899,,,,
,29327104.905,278.5493469,99.5482559204102,5.11677081793763E-6,4.9689155045753E-7,1,0.999253354069792,40.0298881530762,1.99321966407247,15.8900003880262,5.82665035372139E-5,7.319966347241E-6,0.25,-2.38794658462278E-7,5.1207217549523E-6,-2.35304474021417E-7,278.5493469,278.5493469,99.5482559204102,99.5482559204102,57.5841362687753,20.6729918133978,24.427608,0,0,0,40,4374,281.61085,99.5482559204102,,,,,,,,,,,,,0,,,,-0.0049,,,,,,278.5493469,,,,
,29327244.18,282.0271912,99.5482559204102,4.7090358527843E-6,4.52195957844112E-7,1,0.999253354069792,40.0298881530762,1.99306981054048,15.8500000834465,5.36247812827814E-5,6.66693973239897E-6,0.25,-2.25773560418153E-7,4.71208704252704E-6,-2.22587261116667E-7,282.0271912,282.0271912,99.5482559204102,99.5482559204102,57.5059734168522,20.6705442867902,24.427608,0,0,0,40,4374,285.08365,99.5482559204102,,,,,,,,,,,,,0,,,,-0.00735,,,,,,282.0271912,,,,
,29327385.72,285.5504456,99.5482559204102,4.7630872761107E-6,4.77934172827794E-7,1,0.999253354069792,40.0298881530762,1.99334310632741,15.8500000834465,5.43115081121757E-5,6.33389356601384E-6,0.25,-2.6458316771133E-7,4.76559494421847E-6,-2.61398743894578E-7,285.5504456,285.5504456,99.5482559204102,99.5482559204102,57.4637654768138,20.6692725242136,24.427608,0,0,0,40,4374,288.6241,99.5482559204102,,,,,,,,,,,,,0,,,,0,,,,,,285.5504456,,,,
,29327523.695,289.0029907,99.5482559204102,4.88968131311906E-6,4.21092401486906E-7,1,0.999253354069792,40.0298881530762,1.99339225491008,15.8500000834465,5.55518406810904E-5,7.64165448168895E-6,0.25,-1.70611311641776E-7,4.89157884340726E-6,-1.67320092288072E-7,289.0029907,289.0029907,99.5482559204102,99.5482559204102,57.2972786022176,20.6645227132204,24.807261,0,0,0,40,4374,292.0697,99.5482559204102,,,,,,,,,,,,,0,,,,0,,,,,,289.0029907,,,,
,29327644.985,292.0202026,99.5482559204102,4.93152538567218E-6,4.8488225862831E-7,1,0.999253354069792,40.0298881530762,1.99344120554178,15.7900005578995,5.63084380061637E-5,6.05606495501317E-6,0.25,-3.18182382424881E-7,4.93300388154957E-6,-3.14923833697563E-7,292.0202026,292.0202026,99.5482559204102,99.5482559204102,57.6435400362369,20.6727662745563,24.807261,0,0,0,40,4374,295.12415,99.5482559204102,,,,,,,,,,,,,0,,,,0.00245,,,,,,292.0202026,,,,
,29327786.155,295.5054016,99.5482559204102,4.32621882977388E-6,3.8481498610071E-7,1,0.999253354069792,40.0298881530762,1.99377082149559,15.7900005578995,4.84221051665472E-5,1.09488951817999E-5,0.25,2.20017855670483E-7,4.32664049697947E-6,2.22935221020963E-7,295.5054016,295.5054016,99.5482559204102,99.5482559204102,57.4332819645638,20.6704370691143,24.427608,0,0,0,40,4374,298.66685,99.5482559204102,,,,,,,,,,,,,0,,,,0.00245,,,,,,295.5054016,,,,
,29327927.62,299.03125,99.5482559204102,4.31172264260396E-6,3.99296495053446E-7,1,0.999253354069792,40.0298881530762,1.99402834903641,15.7900005578995,4.9046803696841E-5,6.3694069987085E-6,0.25,-1.82972676040827E-7,4.31186649615815E-6,-1.80135201336902E-7,299.03125,299.03125,99.5482559204102,99.5482559204102,57.4020168237945,20.6665671988581,24.807261,0,0,0,40,4374,302.2085,99.5482559204102,,,,,,,,,,,,,0,,,,0.0049,,,,,,299.03125,,,,
,29328048.795,302.0334778,99.5482559204102,3.97897369810277E-6,5.10120502016772E-7,1,0.999253354069792,40.0298881530762,1.99410677857215,15.7399997115135,4.54251670483701E-5,4.91569302752846E-6,0.25,-2.53997243603283E-7,3.97873426295685E-6,-2.51382863959E-7,302.0334778,302.0334778,99.5482559204102,99.5482559204102,57.6873112333138,20.6585258384743,24.427608,0,0,0,40,4374,305.228,99.5482559204102,,,,,,,,,,,,,0,,,,0,,,,,,302.0334778,,,,
,29328190.065,305.5502319,99.5482559204102,4.0578412602031E-6,4.34275565500466E-7,1,0.999253354069792,40.0298881530762,1.99441834082277,15.7399997115135,4.62729015908793E-5,5.32333622857875E-6,0.25,-2.31534012390486E-7,4.05706880522664E-6,-2.28877593921983E-7,305.5502319,305.5502319,99.5482559204102,99.5482559204102,57.4567308201407,20.6609284125866,24.807261,0,0,0,40,4374,308.776,99.5482559204102,,,,,,,,,,,,,0,,,,0,,,,,,305.5502319,,,,
,29328331.18,309.0175781,99.5482559204102,3.83842476419428E-6,3.75465270416542E-7,1,0.999253354069792,40.0298881530762,1.99449885570972,15.7399997115135,4.39943897985162E-5,3.7229433868029E-6,0.25,-3.35193312919765E-7,3.83729272294729E-6,-3.32645791953775E-7,309.0175781,309.0175781,99.5482559204102,99.5482559204102,57.1526773261599,20.6566086607129,25.186911,0,0,0,40,4374,312.31395,99.5482559204102,,,,,,,,,,,,,0,,,,-0.0049,,,,,,309.0175781,,,,
,29328470.69,312.5239563,99.5482559204102,3.72096906038581E-6,4.21893072149795E-7,1,0.999253354069792,40.0298881530762,1.98312872510273,15.6900007277727,4.30370771202633E-5,-2.73990089757292E-8,0.25,-6.46988686489796E-7,3.71960760554336E-6,-6.44356624761751E-7,312.5239563,312.5239563,99.5482559204102,99.5482559204102,57.3942005386022,20.6516312176425,24.807261,0,0,0,40,4374,315.8241,99.5482559204102,,,,,,,,,,,,,0,,,,0,,,,,,312.5239563,,,,
,29328613.035,316.0680847,99.5482559204102,4.72389925103574E-6,5.01558421757762E-7,1,0.999253354069792,40.0298881530762,1.98354101828891,15.6900007277727,5.32759492468031E-5,7.84592785255362E-6,0.25,-1.1950215813939E-7,4.72113942009688E-6,-1.16517247714566E-7,316.0680847,316.0680847,99.5482559204102,99.5482559204102,57.2777378892368,20.6538896431491,25.186911,0,0,0,40,4374,319.39945,99.5482559204102,,,,,,,,,,,,,0,,,,-0.0049,,,,,,316.0680847,,,,
,29328753.75,319.5273438,99.5482559204102,3.21882812921829E-6,4.95124606519239E-7,1,0.999253354069792,40.0298881530762,1.98354344064639,15.6900007277727,3.53704159041235E-5,1.06976124209589E-5,0.25,3.95296486235035E-7,3.2162642949296E-6,3.96971330670121E-7,319.5273438,319.5273438,99.5482559204102,99.5482559204102,57.5090999309292,20.6573942149804,25.566563,0,0,0,40,4374,322.9077,99.5482559204102,,,,,,,,,,,,,0,,,,-0.0049,,,,,,319.5273438,,,,
,29328896.49,323.0630188,99.5482559204102,3.83028319153997E-6,4.89394195048172E-7,1,0.999253354069792,40.0298881530762,1.98354549583156,15.6399998813868,4.30265956762937E-5,7.28759668224359E-6,0.25,-1.42233375155585E-8,3.82705180204718E-6,-1.19081170759579E-8,323.0630188,323.0630188,99.5482559204102,99.5482559204102,57.413741251583,20.6497709310836,25.186911,0,0,0,40,4374,326.49455,99.5482559204102,,,,,,,,,,,,,0,,,,-0.0049,,,,,,323.0630188,,,,
,29329034.055,326.5137024,99.5482559204102,3.89435164808603E-6,4.38795902739159E-7,1,0.999253354069792,40.0298881530762,1.9835307197374,15.6399998813868,4.442075873571E-5,3.48184808016283E-6,0.25,-3.64262636820078E-7,3.8908039051186E-6,-3.61596657840399E-7,326.5137024,326.5137024,99.5482559204102,99.5482559204102,57.2824276603522,20.6552676938674,24.807261,0,0,0,40,4374,329.9621,99.5482559204102,,,,,,,,,,,,,0,,,,0,,,,,,326.5137024,,,,
,29329175.74,330.0369568,99.5482559204102,3.59967756054678E-6,4.70840940606765E-7,1,0.999253354069792,40.0298881530762,1.98354675513627,15.6399998813868,4.08375375893774E-5,4.47264897889072E-6,0.25,-2.24886616048318E-7,3.59588852126051E-6,-2.22528276689549E-7,330.0369568,330.0369568,99.5482559204102,99.5482559204102,57.4958122461022,20.6554518791529,25.566563,0,0,0,40,4374,333.5172,99.5482559204102,,,,,,,,,,,,,0,,,,0,,,,,,330.0369568,,,,
,29329315.04,333.5086975,99.5482559204102,3.70764113829345E-6,4.10530796520432E-7,1,0.999253354069792,40.0298881530762,2.00814038084653,15.5800003558397,4.25746750278912E-5,4.54631802920687E-6,0.25,-2.41683490561515E-7,3.7032964886981E-6,-2.39239149259094E-7,333.5086975,333.5086975,99.5482559204102,99.5482559204102,57.312129544083,20.6431027462393,24.807261,0,0,0,40,4374,337.00765,99.5482559204102,,,,,,,,,,,,,0,,,,0,,,,,,333.5086975,,,,
,29329457.11,337.0050964,99.5482559204102,3.66068848286988E-6,4.51106758895194E-7,1,0.999253354069792,40.0298881530762,2.00823233274151,15.5800003558397,4.26786822185381E-5,7.55496339645091E-7,0.25,-5.67375486314914E-7,3.65614443778942E-6,-5.64520019493094E-7,337.0050964,337.0050964,99.5482559204102,99.5482559204102,57.3613721407945,20.6472971891472,24.807261,0,0,0,40,4374,340.57535,99.5482559204102,,,,,,,,,,,,,0,,,,0,,,,,,337.0050964,,,,
,29329597.54,340.5166321,99.5482559204102,4.00879743447836E-6,3.74855577366072E-7,1,0.999253354069792,40.0298881530762,2.00827753081164,15.5800003558397,4.64155164634371E-5,2.65770955900724E-6,0.25,-4.6007054971071E-7,4.00324286030078E-6,-4.5712750998161E-7,340.4827271,340.5505371,99.5482559204102,99.5482559204102,57.7029438036984,20.651557956161,25.946213,0,0,0,40,4374,344.09325,99.5482559204102,,,,,,,,,,,,,0,,,,0,,,,,,340.5166321,,,,
,29329739.265,344.0447693,99.5482559204102,2.91619803766429E-6,3.92523734705005E-7,1,0.999253354069792,40.0298881530762,1.99583580446199,15.5300004407763,3.37900823921344E-5,6.00295945105592E-7,0.25,-4.51760302571364E-7,2.91187012626241E-6,-4.49412548533589E-7,344.0447693,344.0447693,99.5482559204102,99.5482559204102,57.1964485232368,20.6526612542271,25.566563,0,0,0,40,4374,347.62485,99.5482559204102,,,,,,,,,,,,,0,,,,0,,,,,,344.0447693,,,,
,29329879.59,347.5276794,99.5482559204102,3.07759283938872E-6,4.39765550149999E-7,1,0.999253354069792,40.0298881530762,1.99582127964825,15.5300004407763,3.52036586457257E-5,3.24396803050424E-6,0.25,-2.45375287787214E-7,3.07253060578613E-6,-2.43249608048154E-7,347.5276794,347.5276794,99.5482559204102,99.5482559204102,57.0401228193907,20.6520595391354,25.566563,0,0,0,40,4374,351.1437,99.5482559204102,,,,,,,,,,,,,0,,,,0,,,,,,347.5276794,,,,
,29330238.145,349.7797852,99.5482559204102,3.60472594210025E-6,4.2399136376112E-7,1,0.999253354069792,40.0298881530762,1.99583302393796,15.5300004407763,4.08209644160741E-5,6.16428662373789E-6,0.25,-7.77861841421595E-8,3.59840521036824E-6,-7.56423182340973E-8,349.7797852,349.7797852,99.5482559204102,99.5482559204102,57.423902422333,20.65734892844,25.566563,0,0,0,40,4369,350.71595,99.5482559204102,,,,,,,,,,,,,0,,,,0.00245,,,,,,349.7797852,,,,