File: data/looselyPackedNP/sc-ios-7/ppms/rawdata/ES_S17_HYST_200K.DAT
[Header]
; VSM Data File (default extension .dat)
; Copyright (c) 2003-2013, Quantum Design, Inc. All rights reserved.
TITLE,
FILEOPENTIME,29287657.67,12/06/2018,7:28 am
BYAPP,VSM,2.0,2.0
INFO,PPMS VSM Option Release 1.4.10 Build 1,APPNAME
INFO,Quantum Design Linear Motor Servo Controller,MOTOR_MODULE_NAME
INFO,3101-100 M1,MOTOR_HW_VERSION
INFO,MMC1014,MOTOR_SERIAL_NUMBER
INFO,SRV No X-over 01.03.11,MOTOR_SOFTWARE_VERSION
INFO,Quantum Design VSM Detection Module,VSM_MODULE_NAME
INFO,3101-150 F0,VSM_HW_VERSION
INFO,VSM707,VSM_SERIAL_NUMBER
INFO,VSM No X-over 01.02.05 May 20 2008 13:51:47,VSM_SOFTWARE_VERSION
INFO,704,PREAMP_SERIAL_NUMBER
INFO,822,COIL_SERIAL_NUMBER
INFO,0,MOMENT_UNITS
INFO,Iron Oxide Spheres,SAMPLE_MATERIAL
INFO,7 nm diameter, collaboration Mainz,SAMPLE_COMMENT
INFO,,SAMPLE_MASS
INFO,,SAMPLE_VOLUME
INFO,,SAMPLE_MOLECULAR_WEIGHT
INFO,,SAMPLE_SIZE
INFO,,SAMPLE_SHAPE
DATATYPE,COMMENT,1
DATATYPE,TIME,2
STARTUPAXIS,X,2
STARTUPAXIS,Y1,5
[Data]
Comment,Time Stamp (sec),Temperature (K),Magnetic Field (Oe),Moment (emu),M. Std. Err. (emu),Transport Action,Averaging Time (sec),Frequency (Hz),Peak Amplitude (mm),Center Position (mm),Coil Signal' (mV),Coil Signal" (mV),Range (mV),M. Quad. Signal (emu),M. Raw' (emu),M. Raw" (emu),Min. Temperature (K),Max. Temperature (K),Min. Field (Oe),Max. Field (Oe),Mass (grams),Motor Lag (deg),Pressure (Torr),VSM Status (code),Motor Status (code),Measure Status (code),Measure Count,PPMS Status (code),System Temp. (K),System Field (Oe),Sample Position (deg),Bridge 1 Resistance (ohms),Bridge 1 Excitation (에),Bridge 2 Resistance (ohms),Bridge 2 Excitation (에),Bridge 3 Resistance (ohms),Bridge 3 Excitation (에),Bridge 4 Resistance (ohms),Bridge 4 Excitation (에),Signal 1 Vin (V),Signal 2 Vin (V),Digital Inputs (code),Drive 1 Iout (mA),Drive 1 Ipower (W),Drive 2 Iout (mA),Drive 2 Ipower (W),Pressure (),Map 20 (),Map 21 (),Map 22 (),Map 23 (),Map 24 (),Map 25 (),Map 26 (),Map 27 (),Map 28 (),Map 29 ()
,29287673.39,200.228302,0.0152237731963396,,,2,,,,16.2399999257922,,,,,,,200.228302,200.228302,0.0152237731963396,0.0152237731963396,,,22.909004,,,,-99999999,4433,200.1001,0.0152237731963396,,,,,,,,,,,,,,,,,,,,,,,200.228302,,,,
,29287815.125,200.1782532,4683.1513671875,7.86779804342051E-5,3.92957545040109E-7,1,0.999253354069792,40.0298881530762,1.9992793352243,16.2300001829863,0.000897098536182295,0.000135537087726687,0.25,-1.73323981827781E-6,7.89509604005734E-5,-1.65376660012513E-6,200.1782532,200.1782532,4675.4501953125,4690.8525390625,56.668849272756,20.7556610727159,22.529354,0,0,0,40,4449,199.8667,4683.1513671875,,,,,,,,,,,,,0,,,,0,,,,,,200.1782532,,,,
,29287912.89,200.1052399,9567.224609375,6.10124681342982E-5,6.68087886342714E-7,1,0.999253354069792,40.0298881530762,1.99869795465701,16.2300001829863,0.000705949681693252,4.48117907546379E-5,0.25,-6.65103864227052E-6,6.12300697458606E-5,-6.60777962980982E-6,200.1052399,200.1052399,9557.177734375,9577.271484375,56.9947883652753,20.7582697422315,22.529354,0,0,0,40,4449,199.80275,9567.224609375,,,,,,,,,,,,,0,,,,-0.00245,,,,,,200.1052399,,,,
,29288010.51,200.0440521,14444.697265625,4.18098017216656E-5,6.64223297670136E-7,1,0.999253354069792,40.0298881530762,1.99918206775869,16.2300001829863,0.000485727916979544,2.00558156031808E-5,0.25,-5.49613562745363E-6,4.19600207844705E-5,-5.4698088355423E-6,200.0440521,200.0440521,14439.4912109375,14449.9033203125,57.1886322380445,20.7586978202625,22.909004,0,0,0,40,4449,199.79505,14444.697265625,,,,,,,,,,,,,0,,,,0,,,,,,200.0440521,,,,
,29288110.44,200.0207062,19439.0419921875,1.7999983047991E-5,8.94634543682485E-7,1,0.999253354069792,40.0298881530762,1.99906821630482,16.2300001829863,0.000222284655336994,-6.72494720599193E-5,0.25,-9.04744585581505E-6,1.80718954368964E-5,-9.05920722899271E-6,200.0207062,200.0207062,19436.544921875,19441.5390625,57.4090514804676,20.759719097742,22.529354,0,0,0,40,4449,199.7867,19439.0419921875,,,,,,,,,,,,,0,,,,-0.0049,,,,,,200.0207062,,,,
,29288207.24,200.004837,24276.7578125,-4.32676919662508E-7,1.1767448236658E-6,1,0.999253354069792,40.0298881530762,1.99832303264841,16.2300001829863,9.4066654048579E-6,-8.32962624957859E-5,0.25,-7.26140358315891E-6,-4.26331810715617E-7,-7.28693967730651E-6,200.004837,200.004837,24269.5546875,24283.9609375,57.2550706621791,20.7643163530682,22.909004,0,0,0,40,4449,199.79415,24276.7578125,,,,,,,,,,,,,0,,,,0.0049,,,,,,200.004837,,,,
,29288307.01,199.9798431,29264.220703125,-2.49501991171325E-5,2.12723723771874E-6,1,0.999253354069792,40.0298881530762,2.00098832440782,16.2300001829863,-0.000289002551209175,-1.83607148046974E-5,0.25,2.71830245104552E-6,-2.50392934311147E-5,2.70080864745194E-6,199.9798431,199.9798431,29256.6171875,29271.82421875,57.0901470446214,20.7347171943161,22.909004,0,0,0,40,4449,199.8088,29264.220703125,,,,,,,,,,,,,0,,,,0,,,,,,199.9798431,,,,
,29288403.855,199.981842,34104.705078125,-5.61107274314442E-5,1.94038390537077E-6,1,0.999253354069792,40.0298881530762,2.00010171937931,16.2300001829863,-0.000607738810672746,-0.000282676391612563,0.25,-1.5131002318879E-5,-5.62882500218958E-5,-1.52435951006799E-5,199.981842,199.981842,34099.51953125,34109.890625,57.3215090863138,20.745212273919,22.909004,0,0,0,40,4449,199.82595,34104.705078125,,,,,,,,,,,,,0,,,,0,,,,,,199.981842,,,,
,29288500.945,199.9870758,38956.828125,-8.6374640813373E-5,2.48636335425929E-6,1,0.999253354069792,40.0298881530762,1.99981946150646,16.2300001829863,-0.000965724006093489,-0.000260505956379998,0.25,-7.92695581592867E-6,-8.66644626733216E-5,-8.04702603439229E-6,199.9870758,199.9870758,38946.5703125,38967.0859375,57.2933704596215,20.7512355469404,22.529354,0,0,0,40,4449,199.8347,38956.828125,,,,,,,,,,,,,0,,,,-0.00245,,,,,,199.9870758,,,,
,29288598.97,199.9929962,43856.505859375,-0.00012541412485622,1.82543351628184E-6,1,0.999253354069792,40.0298881530762,2.00004267613049,16.2300001829863,-0.00139840407691339,-0.000401068902279202,0.25,-1.35147530154373E-5,-0.00012583283260504,-1.36957478719355E-5,199.9929962,199.9929962,43848.70703125,43864.3046875,57.3207274577945,20.751553507978,22.909004,0,0,0,40,4449,199.83755,43856.505859375,,,,,,,,,,,,,0,,,,0,,,,,,199.9929962,,,,
,29288698.925,199.9959869,48852.228515625,-0.000156980233079935,2.31147705017736E-6,1,0.999253354069792,40.0298881530762,1.99986067396621,16.2300001829863,-0.0017495424911059,-0.000505897868990019,0.25,-1.72621776377229E-5,-0.000157504031090755,-1.7489576317978E-5,199.9959869,199.9959869,48842.234375,48862.22265625,57.3504293415253,20.7478353613848,22.909004,0,0,0,40,4449,199.8382,48852.228515625,,,,,,,,,,,,,0,,,,-0.00245,,,,,,199.9959869,,,,
,29288798.675,200.0015717,53837.15234375,-0.000189936813694451,2.58348675278185E-6,1,0.999253354069792,40.0298881530762,1.99963304165438,16.2300001829863,-0.00212545920888851,-0.000561109649467369,0.25,-1.64036072097924E-5,-0.000190575432521626,-1.66628394434835E-5,200.0015717,200.0015717,53829.65234375,53844.65234375,57.4074882234292,20.7498149277346,23.288654,0,0,0,40,4449,199.8352,53837.15234375,,,,,,,,,,,,,0,,,,-0.0049,,,,,,200.0015717,,,,
,29288897.79,200.0046082,58792.337890625,-0.000203536805757909,2.88944502288762E-6,1,0.999253354069792,40.0298881530762,1.99966768694353,16.2300001829863,-0.00229056309948015,-0.000527152250638089,0.25,-1.10523439114044E-5,-0.00020422818276721,-1.1307136487054E-5,200.0046082,200.0046082,58787.359375,58797.31640625,57.3902923960061,20.7544977372686,22.909004,0,0,0,40,4449,199.8337,58792.337890625,,,,,,,,,,,,,0,,,,-0.0049,,,,,,200.0046082,,,,
,29288996,200.0081787,63700.146484375,-0.000196020505366645,2.13387226502515E-6,1,0.999253354069792,40.0298881530762,1.99933497241457,16.2300001829863,-0.00218117684500567,-0.000648390411993708,0.25,-2.30386659945754E-5,-0.000196673253568,-2.33264283349069E-5,200.0081787,200.0081787,63690.04296875,63710.25,57.4199942797368,20.7591449390292,22.909004,0,0,0,40,4449,199.8309,63700.146484375,,,,,,,,,,,,,0,,,,-0.0049,,,,,,200.0081787,,,,
,29289097.265,200.0068817,68762.7890625,-0.000244369949956537,2.77885640473582E-6,1,0.999253354069792,40.0298881530762,1.99929247414377,16.2300001829863,-0.00270646487574969,-0.000881184248910057,0.25,-3.51380277691133E-5,-0.000245177061741078,-3.55183818657028E-5,200.0068817,200.0068817,68757.7734375,68767.8046875,57.4379717356792,20.7608378252361,23.288654,0,0,0,40,4449,199.8222,68762.7890625,,,,,,,,,,,,,0,,,,0,,,,,,200.0068817,,,,
,29289194.22,200.013382,73610.48046875,-0.000219643651893325,4.36678508624558E-6,1,0.999253354069792,40.0298881530762,1.99912200697049,16.2300001829863,-0.00243755775002159,-0.000762358789103662,0.25,-2.89770644209433E-5,-0.000220371947925039,-2.93094362471469E-5,200.013382,200.013382,73600.546875,73620.4140625,57.4082698519484,20.7623208656398,23.288654,0,0,0,40,4449,199.8158,73610.48046875,,,,,,,,,,,,,0,,,,0,,,,,,200.013382,,,,
,29289289.58,200.0136566,78373.6171875,-0.000252102451249602,4.07211195953849E-6,1,0.999253354069792,40.0298881530762,1.99880753376524,16.2300001829863,-0.00277108135971639,-0.00102621214536831,0.25,-4.65848763634951E-5,-0.000252924462039735,-4.70118759147105E-5,200.0136566,200.0136566,78368.5859375,78378.6484375,57.1862873524868,20.7726839701944,22.529354,0,0,0,40,4449,199.79865,78373.6171875,,,,,,,,,,,,,0,,,,-0.0049,,,,,,200.0136566,,,,
,29289382.675,200.0162354,83027.1171875,-0.000313749911989335,3.82111580409865E-6,1,0.999253354069792,40.0298881530762,1.9989998438849,16.2300001829863,-0.0034662092511015,-0.00117830121305114,0.25,-4.92627738785055E-5,-0.000314782304145698,-4.97634093357416E-5,200.0162354,200.0162354,83022.0078125,83032.2265625,57.5591241561599,20.7630801020606,22.909004,0,0,0,40,4449,199.7857,83027.1171875,,,,,,,,,,,,,0,,,,0,,,,,,200.0162354,,,,
,29289474.275,200.0140533,87605.16015625,-0.000292900996850508,5.2627395254817E-6,1,0.999253354069792,40.0298881530762,1.99839636693399,16.2300001829863,-0.00319799134487857,-0.00131249738869752,0.25,-6.47330108088276E-5,-0.000293845301895748,-6.52645397044418E-5,200.0140533,200.0140533,87600.1328125,87610.1875,57.1143775287176,20.7691574743286,23.288654,0,0,0,40,4449,199.7785,87605.16015625,,,,,,,,,,,,,0,,,,-0.00245,,,,,,200.0140533,,,,
,29289583.315,200.0064392,87898.40625,-0.000299720606217394,3.10994650341036E-6,1,0.999253354069792,40.0298881530762,1.99913952661374,16.2300001829863,-0.00327615065624213,-0.00132891619003605,0.25,-6.49532805588113E-5,-0.000300688330735719,-6.54927393529905E-5,200.0064392,200.0064392,87893.4140625,87903.3984375,57.6826214621984,20.7624502189577,22.909004,0,0,0,40,4449,199.76365,87898.40625,,,,,,,,,,,,,0,,,,0.00245,,,,,,200.0064392,,,,
,29289675.135,200.0020294,83309.7578125,-0.00027181130696305,2.55294035649559E-6,1,0.999253354069792,40.0298881530762,1.9986462976486,16.2300001829863,-0.00300217037282952,-0.00102183135538801,0.25,-4.27839227263031E-5,-0.000272705718389838,-4.32180196865775E-5,200.0020294,200.0020294,83299.6484375,83319.8671875,57.1487691835637,20.7649198348162,22.529354,0,0,0,40,4449,199.7676,83309.7578125,,,,,,,,,,,,,0,,,,-0.00245,,,,,,200.0020294,,,,
,29289768.605,199.9940948,78636.09765625,-0.000239402218402751,3.06395174417505E-6,1,0.999253354069792,40.0298881530762,1.99856530839261,16.2300001829863,-0.00264153529349415,-0.000914768115053782,0.25,-3.89862585605689E-5,-0.000240188515599348,-3.9373623489057E-5,199.9940948,199.9940948,78631.0703125,78641.125,57.0018230219483,20.7636931110704,22.909004,0,0,0,40,4449,199.7794,78636.09765625,,,,,,,,,,,,,0,,,,-0.00245,,,,,,199.9940948,,,,
,29289864.835,199.9931793,73824.765625,-0.000226912138995657,2.71488503235587E-6,1,0.999253354069792,40.0298881530762,1.99905437430183,16.2300001829863,-0.00248997108655768,-0.000949779560306159,0.25,-4.42186289708176E-5,-0.000227649576520971,-4.46114061322316E-5,199.9931793,199.9931793,73816.703125,73832.828125,57.3058765159291,20.7618919553632,22.909004,0,0,0,40,4449,199.78165,73824.765625,,,,,,,,,,,,,0,,,,0.00245,,,,,,199.9931793,,,,
,29289958.54,199.9877167,69141.6796875,-0.000191248622993959,3.61015489540997E-6,1,0.999253354069792,40.0298881530762,1.99872349153411,16.2300001829863,-0.00207591827940996,-0.000929213629326096,0.25,-4.86138232657149E-5,-0.000191858033138762,-4.89844775210393E-5,199.9877167,199.9877167,69134.328125,69149.03125,57.2707032325638,20.762061620777,22.909004,0,0,0,40,4449,199.79655,69141.6796875,,,,,,,,,,,,,0,,,,0,,,,,,199.9877167,,,,
,29290053.215,199.9915009,64409.0234375,-0.000166655829672455,3.77787688522686E-6,1,0.999253354069792,40.0298881530762,1.99848827578456,16.2300001829863,-0.00180190751054983,-0.000849146249509728,0.25,-4.58420332553427E-5,-0.000167183012366382,-4.617739857147E-5,199.9915009,199.9915009,64406.23828125,64411.80859375,57.4473512779099,20.770312907569,22.529354,0,0,0,40,4449,199.7984,64409.0234375,,,,,,,,,,,,,0,,,,0.00245,,,,,,199.9915009,,,,
,29290146.69,199.9896698,59736.01953125,-0.000144549554752925,2.52277270755952E-6,1,0.999253354069792,40.0298881530762,1.9979920477023,16.2300001829863,-0.00156371395459706,-0.000729457622026087,0.25,-3.91550913537056E-5,-0.000145007334194909,-3.94441727279987E-5,199.9896698,199.9896698,59728.48046875,59743.55859375,57.5200427301984,20.7767887085857,22.529354,0,0,0,40,4449,199.80885,59736.01953125,,,,,,,,,,,,,0,,,,0,,,,,,199.9896698,,,,
,29290242.47,199.9958954,54950.08984375,-0.000142334680010417,3.55086209985907E-6,1,0.999253354069792,40.0298881530762,1.99753864433855,16.2300001829863,-0.00149321124221062,-0.000984186556242326,0.25,-6.19976760548603E-5,-0.000142760291499365,-6.23636064849596E-5,199.9958954,199.9958954,54945.046875,54955.1328125,57.4371901071599,20.7867718323027,22.909004,0,0,0,40,4449,199.8088,54950.08984375,,,,,,,,,,,,,0,,,,0.00245,,,,,,199.9958954,,,,
,29290339.54,199.9893341,50097.73046875,-0.000101320166605944,2.45650576704503E-6,1,0.999253354069792,40.0298881530762,1.99743257642151,16.2300001829863,-0.00106887326178052,-0.000666038851888993,0.25,-4.10913577829257E-5,-0.000101626279058145,-4.13415528899868E-5,199.9893341,199.9893341,50097.73046875,50097.73046875,56.8939582862945,20.779545642217,22.529354,0,0,0,40,4449,199.8137,50097.73046875,,,,,,,,,,,,,0,,,,-0.00245,,,,,,199.9893341,,,,
,29290433.435,199.9925232,45402.765625,-7.99981582069795E-5,2.59260200161382E-6,1,0.999253354069792,40.0298881530762,1.99771760229925,16.2300001829863,-0.000835364406165876,-0.000575966052987069,0.25,-3.68506217845235E-5,-8.02350354727732E-5,-3.70635381421651E-5,199.9925232,199.9925232,45395.36328125,45410.16796875,57.3473028274484,20.7743356029782,22.529354,0,0,0,40,4449,199.8196,45402.765625,,,,,,,,,,,,,0,,,,0.00245,,,,,,199.9925232,,,,
,29290527.95,199.9846039,40682.2265625,-6.627021350583E-5,2.40355981796943E-6,1,0.999253354069792,40.0298881530762,1.99823704057429,16.2300001829863,-0.000697385069530195,-0.000447300912256504,0.25,-2.78891466348302E-5,-6.64692081528553E-5,-2.80565454582563E-5,199.9846039,199.9846039,40672.1484375,40692.3046875,57.5223876157561,20.7782966830473,23.288654,0,0,0,40,4449,199.83365,40682.2265625,,,,,,,,,,,,,0,,,,0.00245,,,,,,199.9846039,,,,
,29290622.645,199.9822998,35947.166015625,-3.36671703384683E-5,3.26094704546777E-6,1,0.999253354069792,40.0298881530762,1.99886900030919,16.2300001829863,-0.000343945073484429,-0.00028749639822463,0.25,-1.94680987483232E-5,-3.37625382176259E-5,-1.95715075957093E-5,199.9822998,199.9822998,35939.61328125,35954.71875,57.6560460925446,20.7651397238161,23.288654,0,0,0,40,4449,199.8548,35947.166015625,,,,,,,,,,,,,0,,,,0,,,,,,199.9822998,,,,
,29290718.985,199.9881439,31132.322265625,-1.68667610607466E-5,1.6382257580906E-6,1,0.999253354069792,40.0298881530762,1.99863336735372,16.2300001829863,-0.000150077689956466,-0.000271916474423136,0.25,-2.101677870714E-5,-1.69023884503215E-5,-2.1107511416879E-5,199.9881439,199.9881439,31122.0234375,31142.62109375,57.7154498600061,20.7716428945031,22.909004,0,0,0,40,4449,199.8598,31132.322265625,,,,,,,,,,,,,0,,,,-0.00245,,,,,,199.9881439,,,,
,29290813.82,199.9928589,26391.8955078125,-1.36271990607441E-7,1.323090569143E-8,1,0.999253354069792,40.0298881530762,1.99824438023689,16.2300001829863,4.01839457399827E-5,-0.000240539532674161,0.25,-2.11633073607931E-5,-1.13924116555485E-7,-2.12365302316966E-5,199.9928589,199.9928589,26379.564453125,26404.2265625,57.8178431960254,20.7715468429961,22.909004,0,0,0,40,4449,199.8642,26391.8955078125,,,,,,,,,,,,,0,,,,0,,,,,,199.9928589,,,,
,29290908.32,199.9920807,21669.4365234375,2.54185064280401E-5,5.72306088554305E-7,1,0.999253354069792,40.0298881530762,1.99798674375455,16.2300001829863,0.000324482271883762,-0.00015679304974848,0.25,-1.82270261583929E-5,2.55259551248711E-5,-1.82625057490514E-5,199.9920807,199.9920807,21666.9765625,21671.896484375,57.555997642083,20.7774478794758,23.288654,0,0,0,40,4449,199.8703,21669.4365234375,,,,,,,,,,,,,0,,,,0,,,,,,199.9920807,,,,
,29291003.215,199.9880524,16927.326171875,4.29947320185117E-5,6.94722180371544E-7,1,0.999253354069792,40.0298881530762,1.99786218129998,16.2300001829863,0.000514038311404798,-6.4934381740429E-5,0.25,-1.31881666752352E-5,4.31574413333085E-5,-1.31871922125049E-5,199.9880524,199.9880524,16919.880859375,16934.771484375,57.5747567265446,20.7795491998825,22.529354,0,0,0,40,4449,199.891,16927.326171875,,,,,,,,,,,,,0,,,,-0.00245,,,,,,199.9880524,,,,
,29291097.235,199.99851225,12227.4716796875,6.03451317848401E-5,6.63083944157519E-7,1,0.999253354069792,40.0298881530762,1.99761317994792,16.2300001829863,0.000703921371814489,9.45310287982418E-6,0.25,-9.64838517180369E-6,6.05638964314676E-5,-9.61630906753918E-6,199.9979553,199.9990692,12222.6767578125,12232.2666015625,57.8209697101023,20.7726870379467,22.909004,0,0,0,40,4449,199.882,12227.4716796875,,,,,,,,,,,,,0,,,,-0.0049,,,,,,199.99851225,,,,
,29291191.945,199.996994,7494.51586914062,7.47178094786175E-5,4.96275276899465E-7,1,0.999253354069792,40.0298881530762,1.99753755279007,16.2300001829863,0.000857628350146309,9.18339755038736E-5,0.25,-4.88618818174009E-6,7.49810228458273E-5,-4.8219820966695E-6,199.996994,199.996994,7484.80029296875,7504.2314453125,58.0593664084677,20.7761173693498,23.288654,0,0,0,40,4449,199.8838,7494.51586914062,,,,,,,,,,,,,0,,,,-0.00245,,,,,,199.996994,,,,
,29291287.235,199.9871826,2731.67761230469,7.8030273780436E-5,3.37423851593003E-7,1,0.999253354069792,40.0298881530762,1.99814856677672,16.2300001829863,0.000890210732222497,0.000128752903221706,0.25,-2.21198379492422E-6,7.83020324790392E-5,-2.13484946075244E-6,199.9871826,199.9871826,2726.6748046875,2736.68041992187,57.6396318936407,20.7817180061038,22.909004,0,0,0,40,4449,199.89425,2731.67761230469,,,,,,,,,,,,,0,,,,0,,,,,,199.9871826,,,,
,29291379.345,199.9901733,-1870.54052734375,-6.8198366828145E-5,3.34329857905334E-7,1,0.999253354069792,40.0298881530762,1.99834162298256,16.2300001829863,-0.000776195801677584,-0.000123588337431517,0.25,9.60201361874365E-7,-6.84348177277223E-5,8.89411956235838E-7,199.9901733,199.9901733,-1877.99426269531,-1863.08679199219,57.525514129833,20.7787711017407,23.288654,0,0,0,40,4449,199.8938,-1870.54052734375,,,,,,,,,,,,,0,,,,-0.0049,,,,,,199.9901733,,,,
,29291473.34,199.9944,-6568.72729492188,-7.98625392400334E-5,4.97807218079018E-7,1,0.999253354069792,40.0298881530762,1.99844825303106,16.2300001829863,-0.000915692902881836,-0.000106184018006715,0.25,4.51946488132091E-6,-8.01431189797365E-5,4.44839776905038E-6,199.9944,199.9944,-6576.09521484375,-6561.359375,57.586481154333,20.7767411172006,22.909004,0,0,0,40,4449,199.90235,-6568.72729492188,,,,,,,,,,,,,0,,,,0,,,,,,199.9944,,,,
,29291570.255,200.0045776,-11411.607421875,-6.62201611172033E-5,4.67455401106445E-7,1,0.999253354069792,40.0298881530762,1.99908074799865,16.2300001829863,-0.000769456011869343,-3.07535272625527E-5,0.25,8.79399290463481E-6,-6.64582670691193E-5,8.7525843127895E-6,200.0045776,200.0045776,-11419.1259765625,-11404.0888671875,57.4371901071599,20.7757559343827,22.909004,0,0,0,40,4449,199.889,-11411.607421875,,,,,,,,,,,,,0,,,,0.00245,,,,,,200.0045776,,,,
,29291665.18,199.9970398,-16156.849609375,-5.52068847337842E-5,8.90095682100169E-7,1,0.999253354069792,40.0298881530762,1.99947158112166,16.2300001829863,-0.000650324093127746,2.45546407044718E-5,0.25,1.17502697651281E-5,-5.54101867692953E-5,1.17311032254858E-5,199.9970398,199.9970398,-16161.8662109375,-16151.8330078125,57.5997688391599,20.7675431669265,22.909004,0,0,0,40,4449,199.89665,-16156.849609375,,,,,,,,,,,,,0,,,,-0.0049,,,,,,199.9970398,,,,
,29291760.54,200.0069275,-20921.677734375,-3.09106695959617E-5,9.46862687466978E-7,1,0.999253354069792,40.0298881530762,1.99895726170366,16.2300001829863,-0.000367695396718074,3.48435769971737E-5,0.25,8.43675330817167E-6,-3.1026492692326E-5,8.43248857007556E-6,200.0069275,200.0069275,-20924.1484375,-20919.20703125,57.8217513386215,20.7714927843295,22.909004,0,0,0,40,4449,199.8883,-20921.677734375,,,,,,,,,,,,,0,,,,0.0049,,,,,,200.0069275,,,,
,29291856.275,200.0060883,-25706.23828125,-9.67764963052228E-6,6.4842576827503E-7,1,0.999253354069792,40.0298881530762,1.99948789138009,16.2300001829863,-0.00013492140341867,0.000124754155598907,0.25,1.26628101698368E-5,-9.72471655837958E-6,1.26960926259896E-5,200.0060883,200.0060883,-25711.205078125,-25701.271484375,57.5669404413522,20.7688912059901,23.288654,0,0,0,40,4449,199.8847,-25706.23828125,,,,,,,,,,,,,0,,,,0,,,,,,200.0060883,,,,
,29291950.905,200.0070496,-30436.099609375,8.50689681276188E-6,1.03448109665804E-6,1,0.999253354069792,40.0298881530762,1.99916792277519,16.2300001829863,5.97649471823356E-5,0.00022899740726661,0.25,1.86839471048059E-5,8.51615684929169E-6,1.87576151422893E-5,200.0070496,200.0070496,-30443.525390625,-30428.673828125,57.5497446139292,20.7663216818032,22.529354,0,0,0,40,4449,199.88095,-30436.099609375,,,,,,,,,,,,,0,,,,0,,,,,,200.0070496,,,,
,29292044.355,200.0153503,-35105.857421875,2.55555186784926E-5,9.92906774911739E-7,1,0.999253354069792,40.0298881530762,1.99859701697897,16.2300001829863,0.000226170530210823,0.00041897908523896,0.25,3.2459414542253E-5,2.56088747963038E-5,3.25989501113993E-5,200.0153503,200.0153503,-35110.92578125,-35100.7890625,57.7975208545254,20.7824993486169,22.909004,0,0,0,40,4449,199.8643,-35105.857421875,,,,,,,,,,,,,0,,,,0.0049,,,,,,200.0153503,,,,
,29292141.495,200.0117493,-39960.673828125,5.60439901491331E-5,1.5874826711737E-6,1,0.999253354069792,40.0298881530762,1.99911649230832,16.2300001829863,0.000598416327000099,0.000330080099970399,0.25,1.93280765501044E-5,5.62167884370952E-5,1.94549297054535E-5,200.0117493,200.0117493,-39963.11328125,-39958.234375,57.5630322987561,20.7666358034674,23.288654,0,0,0,40,4449,199.8559,-39960.673828125,,,,,,,,,,,,,0,,,,0,,,,,,200.0117493,,,,
,29292237.485,200.00937655,-44758.875,6.39455998107683E-5,2.68982994021148E-6,1,0.999253354069792,40.0298881530762,1.99939424647973,16.2300001829863,0.000650858287259769,0.000561033175882892,0.25,3.82833920637527E-5,6.4125456214461E-5,3.84840584827866E-5,200.0089417,200.0098114,-44766.46484375,-44751.28515625,57.7943943404484,20.7737123355346,23.288654,0,0,0,40,4449,199.8493,-44758.875,,,,,,,,,,,,,0,,,,-0.0049,,,,,,200.00937655,,,,
,29292335.385,200.01480105,-49650.8515625,0.00011356224466059,2.54554412243266E-6,1,0.999253354069792,40.0298881530762,1.99900487827319,16.2300001829863,0.00125764521652808,0.000408934761616816,0.25,1.62835022124918E-5,0.00011393705301244,1.6461069869344E-5,200.0147858,200.0148163,-49658.31640625,-49643.38671875,57.4629838482945,20.7850777454054,23.288654,0,0,0,40,4449,199.8351,-49650.8515625,,,,,,,,,,,,,0,,,,0.0049,,,,,,200.01480105,,,,
,29292431.87,200.0198364,-54472.751953125,0.000116654790047643,2.91754231540928E-6,1,0.999253354069792,40.0298881530762,1.99888694492924,16.2300001829863,0.00126709380545847,0.000562429250840192,0.25,2.92644357059543E-5,0.000117026485959596,2.94899027702162E-5,200.0198364,200.0198364,-54480.25,-54465.25390625,57.5231692442753,20.783422340662,22.909004,0,0,0,40,4449,199.81545,-54472.751953125,,,,,,,,,,,,,0,,,,0,,,,,,200.0198364,,,,
,29292529.965,200.0176239,-59375.126953125,0.000172905309333999,4.13048006616969E-6,1,0.999253354069792,40.0298881530762,1.9990936525722,16.2300001829863,0.00190576486243479,0.00067539008658142,0.25,2.94364404053831E-5,0.00017347123178554,2.97221163510919E-5,200.0176239,200.0176239,-59387.640625,-59362.61328125,57.5427099572561,20.7816617033858,22.909004,0,0,0,40,4449,199.8055,-59375.126953125,,,,,,,,,,,,,0,,,,-0.00245,,,,,,200.0176239,,,,
,29292624.33,200.01257325,-64092.6796875,0.000209189953085062,3.94249102758303E-6,1,0.999253354069792,40.0298881530762,1.9989815565258,16.2300001829863,0.00229313350697592,0.000888709692750045,0.25,4.19212343861344E-5,0.000209868114092199,4.22882176462514E-5,200.0123444,200.0128021,-64100.27734375,-64085.08203125,57.8850632486792,20.7846261158547,23.288654,0,0,0,40,4449,199.7982,-64092.6796875,,,,,,,,,,,,,0,,,,0.00245,,,,,,200.01257325,,,,
,29292721.065,200.0114746,-68927.0234375,0.00022945888662974,2.8876735410847E-6,1,0.999253354069792,40.0298881530762,1.99861873630615,16.2300001829863,0.00250731913354914,0.00101822973322607,0.25,4.98213761403323E-5,0.000230198872209892,5.0236686965297E-5,200.0114746,200.0114746,-68937.2109375,-68916.8359375,57.708415203333,20.7882614863987,23.668306,0,0,0,40,4449,199.78855,-68927.0234375,,,,,,,,,,,,,0,,,,0.00245,,,,,,200.0114746,,,,
,29292816.975,200.0127563,-73721.51171875,0.000268124643916453,3.24704384578733E-6,1,0.999253354069792,40.0298881530762,1.99963008556456,16.2300001829863,0.00295426953022776,0.00105777723805905,0.25,4.65448338589805E-5,0.00026900186855122,4.69892260160664E-5,200.0127563,200.0127563,-73729.0390625,-73713.984375,57.7959575974869,20.7741336213203,23.288654,0,0,0,40,4449,199.7751,-73721.51171875,,,,,,,,,,,,,0,,,,0.00245,,,,,,200.0127563,,,,
,29292916.015,200.0096283,-78668.5078125,0.000308735838846712,4.09307880963153E-6,1,0.999253354069792,40.0298881530762,2.00004096699881,16.2300001829863,0.00340531433441688,0.00120147597665492,0.25,5.21208154657029E-5,0.00030974774863834,5.26267228425225E-5,200.0096283,200.0096283,-78676.09375,-78660.921875,57.9608812150446,20.7682367922495,23.288654,0,0,0,40,4449,199.7708,-78668.5078125,,,,,,,,,,,,,0,,,,0.0049,,,,,,200.0096283,,,,
,29293014.39,200.00985715,-83585.51953125,0.000354440953047111,2.96825668478753E-6,1,0.999253354069792,40.0298881530762,1.99939605257175,16.2300001829863,0.00397099433909006,0.00101752371100079,0.25,2.80233097426745E-5,0.000355636418955572,2.84933500264048E-5,200.0096893,200.010025,-83592.9765625,-83578.0625,57.4887775894292,20.7806475953558,22.909004,0,0,0,40,4449,199.7657,-83585.51953125,,,,,,,,,,,,,0,,,,-0.00245,,,,,,200.00985715,,,,
,29293107.86,200.0172272,-88257.21875,0.000368544605255332,4.81207832708199E-6,1,0.999253354069792,40.0298881530762,1.99909331185129,16.2300001829863,0.00408868782960148,0.0012865987030047,0.25,4.92784463815598E-5,0.000369766565748168,4.98360014399423E-5,200.0172272,200.0172272,-88264.7421875,-88249.6953125,57.7154498600061,20.7808559615469,23.288654,0,0,0,40,4449,199.7478,-88257.21875,,,,,,,,,,,,,0,,,,0,,,,,,200.0172272,,,,
,29293216.775,200.00720215,-87281.63671875,0.000335792906161321,2.80098062839779E-6,1,0.999253354069792,40.0298881530762,2.00027199786103,16.2300001829863,0.0036957085670776,0.00135560313442846,0.25,6.09741036033178E-5,0.000336889435714151,6.15378649252842E-5,200.006897,200.0075073,-87289.109375,-87274.1640625,57.5888260398907,20.7636438287105,22.529354,0,0,0,40,4449,199.7374,-87281.63671875,,,,,,,,,,,,,0,,,,0,,,,,,200.00720215,,,,
,29293310.71,199.9991455,-82586.88671875,0.000273659591883122,3.94377396200356E-6,1,0.999253354069792,40.0298881530762,1.99998228268563,16.2300001829863,0.00302946577092957,0.00100091324038111,0.25,4.05645065422043E-5,0.000274562713917181,4.09930197688629E-5,199.9991455,199.9991455,-82592.0546875,-82581.71875,57.7560945430061,20.7737230829208,22.909004,0,0,0,40,4449,199.7423,-82586.88671875,,,,,,,,,,,,,0,,,,0,,,,,,199.9991455,,,,
,29293406.525,199.9934692,-77797.01171875,0.00026787832202241,3.33101149233777E-6,1,0.999253354069792,40.0298881530762,2.0001565206228,16.2300001829863,0.00296451559215593,0.000986733441971952,0.25,4.0312754130376E-5,0.00026876160082662,4.07349022010915E-5,199.9934692,199.9934692,-77799.625,-77794.3984375,57.7451517437369,20.7740850137656,23.668306,0,0,0,40,4449,199.7534,-77797.01171875,,,,,,,,,,,,,0,,,,-0.0049,,,,,,199.9934692,,,,
,29293504.115,199.9837952,-72922.34375,0.00025015771788704,3.03277685530309E-6,1,0.999253354069792,40.0298881530762,1.99988512895993,16.2300001829863,0.00277497294701732,0.000881466892083239,0.25,3.41361599844937E-5,0.000250986195899875,3.45188083643478E-5,199.9837952,199.9837952,-72932.03125,-72912.65625,57.6138381525061,20.772596418961,22.909004,0,0,0,40,4449,199.7707,-72922.34375,,,,,,,,,,,,,0,,,,0.0049,,,,,,199.9837952,,,,
,29293604.315,199.9911499,-67915.33203125,0.000229124673381709,2.5172614428508E-6,1,0.999253354069792,40.0298881530762,1.99989864884613,16.2300001829863,0.00251854745272938,0.000940501047761361,0.25,4.29834830758614E-5,0.000229870857783074,4.33749824792177E-5,199.9911499,199.9911499,-67920.5859375,-67910.078125,57.9663526146792,20.766481090475,23.288654,0,0,0,40,4449,199.76625,-67915.33203125,,,,,,,,,,,,,0,,,,-0.0049,,,,,,199.9911499,,,,
,29293702.04,199.9914703,-63028.5546875,0.000196820757284045,2.51642899915075E-6,1,0.999253354069792,40.0298881530762,1.99989513617193,16.2300001829863,0.00215563856019239,0.00085291494409758,0.25,4.08847367258637E-5,0.000197457381712571,4.12351513983545E-5,199.9914703,199.9914703,-63038.5859375,-63018.5234375,57.7553129144869,20.7637688909012,22.909004,0,0,0,40,4449,199.77845,-63028.5546875,,,,,,,,,,,,,0,,,,0,,,,,,199.9914703,,,,
,29293798.97,199.9876709,-58186.212890625,0.000161871518530614,2.5679484956665E-6,1,0.999253354069792,40.0298881530762,2.00004715012289,16.2300001829863,0.00177583400659251,0.000685148172171821,0.25,3.2184219357688E-5,0.000162396528037698,3.24677807015137E-5,199.9876709,199.9876709,-58196.2421875,-58176.18359375,57.9280528172369,20.766084152113,23.288654,0,0,0,40,4449,199.7888,-58186.212890625,,,,,,,,,,,,,0,,,,-0.00245,,,,,,199.9876709,,,,
,29293896.335,199.9894867,-53318.876953125,0.000138804466513181,2.30908210954934E-6,1,0.999253354069792,40.0298881530762,2.00021074568637,16.2300001829863,0.00152276011632602,0.000588313864355212,0.25,2.76640580445745E-5,0.000139254476775234,2.79077353047383E-5,199.9894867,199.9894867,-53323.953125,-53313.80078125,57.708415203333,20.7641885375915,23.288654,0,0,0,40,4449,199.7933,-53318.876953125,,,,,,,,,,,,,0,,,,0.0049,,,,,,199.9894867,,,,
,29293995.455,199.9880371,-48366.900390625,0.000118363036084703,2.00525171674322E-6,1,0.999253354069792,40.0298881530762,2.00073254793424,16.2300001829863,0.00128746245820597,0.000567245438038616,0.25,2.9347523179492E-5,0.00011874053438901,2.95754570284908E-5,199.9880371,199.9880371,-48371.64453125,-48362.15625,57.8670857927369,20.765833992971,23.288654,0,0,0,40,4449,199.8,-48366.900390625,,,,,,,,,,,,,0,,,,0,,,,,,199.9880371,,,,
,29294091.86,199.9887848,-43546.6171875,9.39127476061355E-5,2.29182043776529E-6,1,0.999253354069792,40.0298881530762,1.9994967723438,16.2300001829863,0.00100341985225914,0.00055049788491401,0.25,3.21489175082516E-5,9.4202692766368E-5,3.23605676738266E-5,199.9887848,199.9887848,-43554.06640625,-43539.16796875,57.75218640041,20.77135388968,23.288654,0,0,0,40,4449,199.8154,-43546.6171875,,,,,,,,,,,,,0,,,,0.00245,,,,,,199.9887848,,,,
,29294187.36,199.9961548,-38777.32421875,6.45873704808491E-5,2.63812825721782E-6,1,0.999253354069792,40.0298881530762,1.99936157825143,16.2300001829863,0.000667043797222662,0.000511006821026689,0.25,3.3768518132739E-5,6.47741813394808E-5,3.39544643829049E-5,199.9961548,199.9961548,-38782.44921875,-38772.19921875,57.9132018753715,20.7656275894345,22.909004,0,0,0,40,4449,199.8138,-38777.32421875,,,,,,,,,,,,,0,,,,0,,,,,,199.9961548,,,,
,29294281.48,199.99092105,-34070.189453125,4.24673300988646E-5,2.32542950310334E-6,1,0.999253354069792,40.0298881530762,1.99950587442481,16.2300001829863,0.000429738411707673,0.000387171850641303,0.25,2.67061923668558E-5,4.25852708605934E-5,2.68440866585094E-5,199.9906006,199.9912415,-34075.13671875,-34065.2421875,57.637287008083,20.770432950942,23.288654,0,0,0,40,4449,199.8202,-34070.189453125,,,,,,,,,,,,,0,,,,0,,,,,,199.99092105,,,,
,29294376.585,199.9881134,-29317.98828125,1.99817461615514E-5,1.1907503833018E-6,1,0.999253354069792,40.0298881530762,1.99920605402279,16.2300001829863,0.000178610077846211,0.000317803933492572,0.25,2.45091638482627E-5,2.00243463778807E-5,2.46153250947005E-5,199.9881134,199.9881134,-29322.908203125,-29313.068359375,57.7670373422753,20.7648385594178,23.288654,0,0,0,40,4449,199.83245,-29317.98828125,,,,,,,,,,,,,0,,,,0,,,,,,199.9881134,,,,
,29294471.965,199.9904938,-24550.7138671875,-2.99272996963709E-6,3.89156545273522E-7,1,0.999253354069792,40.0298881530762,1.99948523032302,16.2300001829863,-5.6498960135974E-5,0.000123651095350138,0.25,1.14046615809831E-5,-3.01537072598171E-6,1.14408111375597E-5,199.9904938,199.9904938,-24560.95703125,-24540.470703125,57.6693337773715,20.7635260097701,23.288654,0,0,0,40,4449,199.83605,-24550.7138671875,,,,,,,,,,,,,0,,,,-0.00245,,,,,,199.9904938,,,,
,29294568.43,199.984314,-19730.9228515625,-2.81091417918583E-5,9.56562761183111E-7,1,0.999253354069792,40.0298881530762,1.99984388711782,16.2300001829863,-0.000340401643110752,6.5609559221911E-5,0.25,1.0656724145942E-5,-2.82177174816571E-5,1.06631349975943E-5,199.984314,199.984314,-19733.349609375,-19728.49609375,57.76234757116,20.7596357021584,23.288654,0,0,0,40,4449,199.84445,-19730.9228515625,,,,,,,,,,,,,0,,,,0,,,,,,199.984314,,,,
,29294665.185,199.9908295,-14895.8134765625,-4.35984898791388E-5,5.63236716959223E-7,1,0.999253354069792,40.0298881530762,1.9989645322942,16.2300001829863,-0.000515411212798062,3.06451082370566E-5,0.25,1.02708667484203E-5,-4.37601278557332E-5,1.02591211408825E-5,199.9908295,199.9908295,-14900.68359375,-14890.943359375,57.7936127119292,20.7630417681296,22.529354,0,0,0,40,4449,199.8545,-14895.8134765625,,,,,,,,,,,,,0,,,,0,,,,,,199.9908295,,,,
,29294760.305,199.9923706,-10140.8203125,-6.70470265078533E-5,5.30557085023874E-7,1,0.999253354069792,40.0298881530762,1.99963158025019,16.2300001829863,-0.000774309998540768,-5.9697001330997E-5,0.25,6.39067799809688E-6,-6.72854069565995E-5,6.34003658564196E-6,199.9923706,199.9923706,-10148.3935546875,-10133.2470703125,57.6849663477561,20.7593626781716,22.909004,0,0,0,40,4449,199.85835,-10140.8203125,,,,,,,,,,,,,0,,,,-0.0049,,,,,,199.9923706,,,,
,29294855.245,199.9923859,-5395.39135742188,-8.03801091624791E-5,3.69579250049647E-7,1,0.999253354069792,40.0298881530762,1.99929352197108,16.2300001829863,-0.000917750208763779,-0.000131378720238481,0.25,2.39511455054567E-6,-8.06601696483498E-5,2.31610337949164E-6,199.9923859,199.9923859,-5400.34375,-5390.43896484375,57.6701154058907,20.7661497311437,22.909004,0,0,0,40,4449,199.8646,-5395.39135742188,,,,,,,,,,,,,0,,,,0,,,,,,199.9923859,,,,
,29294950.96,199.9916534,-611.138702392578,-3.51999421156252E-5,3.6498979496271E-7,1,0.999253354069792,40.0298881530762,1.99948620000864,16.2300001829863,-0.000399506619287689,-7.15295749607484E-5,0.25,-1.8271821454257E-7,-3.53212430161478E-5,-2.2161134199463E-7,199.9916534,199.9916534,-621.108825683594,-601.168579101562,57.403580080833,20.7702083670127,22.909004,0,0,0,40,4449,199.87445,-611.138702392578,,,,,,,,,,,,,0,,,,-0.00245,,,,,,199.9916534,,,,
,29295042.755,199.9904633,3974.59716796875,8.35498687839338E-5,4.34635139826473E-7,1,0.999253354069792,40.0298881530762,1.99982386807155,16.2300001829863,0.000951459995846428,0.00015227049389988,0.25,-1.10983885093604E-6,8.38394772416711E-5,-1.02292492310829E-6,199.9904633,199.9904633,3962.11938476562,3987.07495117188,57.312129544083,20.7678724752167,23.288654,0,0,0,40,4449,199.88225,3974.59716796875,,,,,,,,,,,,,0,,,,-0.0049,,,,,,199.9904633,,,,
,29295137.575,200.0043335,8715.63330078125,7.5692297563292E-5,6.0430081940128E-7,1,0.999253354069792,40.0298881530762,1.99910078855197,16.2300001829863,0.000866369751982577,0.000110906779531461,0.25,-3.38218888593192E-6,7.59572269798739E-5,-3.3117585759846E-6,200.0043335,200.0043335,8710.716796875,8720.5498046875,57.8553613649484,20.7736963014129,22.909004,0,0,0,40,4449,199.8749,8715.63330078125,,,,,,,,,,,,,0,,,,-0.00245,,,,,,200.0043335,,,,
,29295233.38,200.0074463,13504.1635742187,6.00924723864312E-5,4.90674424509071E-7,1,0.999253354069792,40.0298881530762,1.99870457753312,16.2300001829863,0.000697940291315071,2.8988532306614E-5,0.25,-7.88458757531148E-6,6.03084363791676E-5,-7.8467148433185E-6,200.0074463,200.0074463,13498.9306640625,13509.396484375,57.065134932006,20.7670511750333,23.668306,0,0,0,40,4449,199.8649,13504.1635742187,,,,,,,,,,,,,0,,,,-0.0049,,,,,,200.0074463,,,,
,29295327.86,200.0069122,18223.84375,3.94766267533894E-5,8.1128186539084E-7,1,0.999253354069792,40.0298881530762,1.99966164916003,16.2300001829863,0.000463180010780677,-6.69332099009889E-6,0.25,-7.44572350227226E-6,3.96209526438069E-5,-7.42873592692558E-6,200.0069122,200.0069122,18216.23828125,18231.44921875,57.5489629854099,20.765094419194,23.668306,0,0,0,40,4449,199.8638,18223.84375,,,,,,,,,,,,,0,,,,-0.0049,,,,,,200.0069122,,,,
,29295424.04,200.0119629,23031.6201171875,1.92939691805671E-5,4.68789426973972E-7,1,0.999253354069792,40.0298881530762,1.99919306895895,16.2300001829863,0.000252191547981991,-0.00015219381822909,0.25,-1.67504068677965E-5,1.93786582115031E-5,-1.67874010662683E-5,200.0119629,200.0119629,23019.1875,23044.052734375,57.5239508727946,20.7680872648535,22.909004,0,0,0,40,4449,199.85375,23031.6201171875,,,,,,,,,,,,,0,,,,0,,,,,,200.0119629,,,,
,29295519.215,200.0080109,27789.2783203125,-1.13649029294021E-5,1.56441576193739E-6,1,0.999253354069792,40.0298881530762,1.99957818646886,16.2300001829863,-9.73332112870699E-5,-0.000205382254755514,0.25,-1.61048858302072E-5,-1.13867827145064E-5,-1.61727371612074E-5,200.0080109,200.0080109,27781.83203125,27796.724609375,57.657609349583,20.7561453728133,23.288654,0,0,0,40,4449,199.8414,27789.2783203125,,,,,,,,,,,,,0,,,,0,,,,,,200.0080109,,,,
,29295614.65,200.008255,32559.4677734375,-2.66177843835375E-5,3.35477411844316E-6,1,0.999253354069792,40.0298881530762,1.99970880162838,16.2300001829863,-0.000262930898389821,-0.000279818458193158,0.25,-2.00064703783441E-5,-2.6688166334838E-5,-2.01041850031652E-5,200.008255,200.008255,32554.74609375,32564.189453125,57.2050464369484,20.7566520002091,23.668306,0,0,0,40,4449,199.83795,32559.4677734375,,,,,,,,,,,,,0,,,,0.00245,,,,,,200.008255,,,,
,29295709.02,200.0077057,37274.453125,-4.74189050884483E-5,2.26774802989377E-6,1,0.999253354069792,40.0298881530762,2.00006783115011,16.2300001829863,-0.000498272592249572,-0.00032707070516045,0.25,-2.05479730424399E-5,-4.75605803166983E-5,-2.06698507268402E-5,200.0077057,200.0077057,37266.98046875,37281.92578125,57.8326941378907,20.7562306829657,23.288654,0,0,0,40,4449,199.82675,37274.453125,,,,,,,,,,,,,0,,,,0,,,,,,200.0077057,,,,
,29295805.36,200.0060577,42092.140625,-7.8053882907202E-5,2.21468261547766E-6,1,0.999253354069792,40.0298881530762,2.00092638897035,16.2300001829863,-0.000842378383484478,-0.00041273070381231,0.25,-2.27510411989037E-5,-7.82990530506426E-5,-2.29132711645226E-5,200.0060577,200.0060577,42084.60546875,42099.67578125,57.7240477737176,20.7473352858347,23.288654,0,0,0,40,4449,199.82515,42092.140625,,,,,,,,,,,,,0,,,,-0.00245,,,,,,200.0060577,,,,
,29295901.615,200.0143433,46902.455078125,-0.000106841682381408,2.71691075868704E-6,1,0.999253354069792,40.0298881530762,1.99974469905003,16.2300001829863,-0.00115825350735898,-0.000531018144266793,0.25,-2.81833529155912E-5,-0.000107180508871176,-2.83949776559589E-5,200.0143433,200.0143433,46892.33984375,46912.5703125,57.8483267082754,20.7519540172976,23.288654,0,0,0,40,4449,199.81705,46902.455078125,,,,,,,,,,,,,0,,,,-0.00245,,,,,,200.0143433,,,,
,29295995.365,200.0071259,51587.62890625,-0.000150859673045993,1.83383102650855E-6,1,0.999253354069792,40.0298881530762,2.00085746735845,16.2300001829863,-0.00167696236469551,-0.000516150091575616,0.25,-1.92060501777165E-5,-0.000151360237890597,-1.94334645655255E-5,200.0071259,200.0071259,51585.37890625,51589.87890625,57.6599542351407,20.7399847926955,23.288654,0,0,0,40,4449,199.8049,51587.62890625,,,,,,,,,,,,,0,,,,0,,,,,,200.0071259,,,,
,29296090.765,200.0130005,56357.857421875,-0.000169002896627638,2.69913738513089E-6,1,0.999253354069792,40.0298881530762,1.99973318716724,16.2300001829863,-0.00186633527046744,-0.000642988910279318,0.25,-2.72438926204473E-5,-0.000169557622610277,-2.7518088467276E-5,200.0130005,200.0130005,56347.9921875,56367.72265625,57.5450548428138,20.7526451347591,22.909004,0,0,0,40,4449,199.79425,56357.857421875,,,,,,,,,,,,,0,,,,0,,,,,,200.0130005,,,,
,29296183.055,200.0106506,60968.0078125,-0.000178754999233666,2.49380100646657E-6,1,0.999253354069792,40.0298881530762,2.00025764949337,16.2300001829863,-0.00196848656802184,-0.000715033747042777,0.25,-3.187608217237E-5,-0.000179338607390173,-3.21763130322417E-5,200.0106506,200.0106506,60955.48046875,60980.53515625,57.5176978446407,20.7522602722598,23.288654,0,0,0,40,4449,199.784,60968.0078125,,,,,,,,,,,,,0,,,,-0.00245,,,,,,200.0106506,,,,
,29296279.665,200.0178528,65795.96875,-0.000199724270186407,3.41878535763871E-6,1,0.999253354069792,40.0298881530762,1.99919517669504,16.2300001829863,-0.00219659063527761,-0.000808297080182956,0.25,-3.6477678398616E-5,-0.000200375518416742,-3.68156725290619E-5,200.0178528,200.0178528,65788.4453125,65803.4921875,57.3277621144676,20.7704046893699,23.288654,0,0,0,40,4449,199.7736,65795.96875,,,,,,,,,,,,,0,,,,-0.00245,,,,,,200.0178528,,,,
,29296375.455,200.0134888,70583.609375,-0.000220089363607375,3.42616410479068E-6,1,0.999253354069792,40.0298881530762,1.99971990781661,16.2300001829863,-0.0024357765329819,-0.000806869712816146,0.25,-3.27979257166982E-5,-0.000220815041423482,-3.31443627326431E-5,200.0134888,200.0134888,70576.1796875,70591.0390625,57.1003082153714,20.755621890922,22.909004,0,0,0,40,4449,199.7571,70583.609375,,,,,,,,,,,,,0,,,,0.00245,,,,,,200.0134888,,,,
,29296468.76,200.0111542,75249.02734375,-0.000248935642465021,3.2890735158123E-6,1,0.999253354069792,40.0298881530762,2.00059606515251,16.2300001829863,-0.00274828484770253,-0.000958458340132616,0.25,-4.10962227795101E-5,-0.000249752384318307,-4.15013534397801E-5,200.0111542,200.0111542,75239.1328125,75258.921875,57.5403650716984,20.7470436022864,23.288654,0,0,0,40,4449,199.7529,75249.02734375,,,,,,,,,,,,,0,,,,0.00245,,,,,,200.0111542,,,,
,29296564.07,200.0116272,80012.23046875,-0.0002599296647947,4.52050059290911E-6,1,0.999253354069792,40.0298881530762,1.9998744740024,16.2300001829863,-0.00288490785530954,-0.000906966881269009,0.25,-3.46846862870499E-5,-0.000260791328597666,-3.50787168949413E-5,200.0116272,200.0116272,80002.1171875,80022.34375,57.4387533641984,20.7566573669743,23.288654,0,0,0,40,4449,199.74135,80012.23046875,,,,,,,,,,,,,0,,,,0,,,,,,200.0116272,,,,
,29296657.875,200.0120697,84703.34375,-0.000322386887944216,4.04019710238323E-6,1,0.999253354069792,40.0298881530762,1.99970428394599,16.2300001829863,-0.00354356345138739,-0.00132207097858778,0.25,-6.03826258744144E-5,-0.000323437514204658,-6.09306421354209E-5,200.0120697,200.0120697,84695.8671875,84710.8203125,57.2839909173907,20.7595099963816,23.668306,0,0,0,40,4449,199.7333,84703.34375,,,,,,,,,,,,,0,,,,0.0049,,,,,,200.0120697,,,,
,29296747.46,200.0123596,89181.65234375,-0.000342948861072814,4.42409692368098E-6,1,0.999253354069792,40.0298881530762,1.99984012056257,16.2300001829863,-0.00377925542922365,-0.00135215340688427,0.25,-5.94526857600439E-5,-0.000344071760399955,-6.00184079479989E-5,200.0123596,200.0123596,89178.9609375,89184.34375,57.1589303543137,20.7569226434753,23.668306,0,0,0,40,4449,199.7291,89181.65234375,,,,,,,,,,,,,0,,,,-0.00245,,,,,,200.0123596,,,,
,29296855.37,200.0127106,86311.578125,-0.000334717037554902,3.63596873166736E-6,1,0.999253354069792,40.0298881530762,1.99913861506947,16.2300001829863,-0.00370103242143304,-0.00124020749313588,0.25,-5.10655505528829E-5,-0.000335820144370678,-5.15941210471744E-5,200.0127106,200.0127106,86304.078125,86319.078125,57.5012836457369,20.7672960767131,22.909004,0,0,0,40,4449,199.717,86311.578125,,,,,,,,,,,,,0,,,,0,,,,,,200.0127106,,,,
,29296948.925,200.0040894,81635.71484375,-0.000273552798962473,3.35543219018702E-6,1,0.999253354069792,40.0298881530762,1.99978937246458,16.2300001829863,-0.00296842253147405,-0.00134352396873251,0.25,-7.07460598176394E-5,-0.000274423639645419,-7.1278934526236E-5,200.0040894,200.0040894,81625.6875,81645.7421875,57.3762230826599,20.7640137314398,22.909004,0,0,0,40,4449,199.71445,81635.71484375,,,,,,,,,,,,,0,,,,0,,,,,,200.0040894,,,,
,29297044.18,200.002655,76874.28515625,-0.000262762293642954,3.27965230011295E-6,1,0.999253354069792,40.0298881530762,1.99909090638034,16.2300001829863,-0.00286037641202447,-0.00123252173481527,0.25,-6.28856293580017E-5,-0.000263603907458965,-6.33805524989497E-5,200.002655,200.002655,76866.9375,76881.6328125,57.4215575367753,20.7721885877617,23.288654,0,0,0,40,4449,199.7123,76874.28515625,,,,,,,,,,,,,0,,,,-0.00245,,,,,,200.002655,,,,
,29297139.88,199.9970245,72091.125,-0.000244369212848284,2.48969205250576E-6,1,0.999253354069792,40.0298881530762,1.99904795483302,16.2300001829863,-0.00268115383019599,-0.00102497026278362,0.25,-4.78072833371579E-5,-0.000245163053630588,-4.82312078368309E-5,199.9970245,199.9970245,72078.5546875,72103.6953125,57.2183341217753,20.7703880842791,23.668306,0,0,0,40,4449,199.72015,72091.125,,,,,,,,,,,,,0,,,,0.00245,,,,,,199.9970245,,,,
,29297234.67,199.9903564,67350.3671875,-0.000192156887242131,2.95808919323059E-6,1,0.999253354069792,40.0298881530762,1.99915883380955,16.2300001829863,-0.00212019168579461,-0.000738143496806367,0.25,-3.1616655411049E-5,-0.000192787354270063,-3.19297696572523E-5,199.9903564,199.9903564,67345.265625,67355.46875,57.2456911199484,20.7720804744481,23.288654,0,0,0,40,4449,199.72985,67350.3671875,,,,,,,,,,,,,0,,,,-0.0049,,,,,,199.9903564,,,,
,29297329.35,199.9911499,62619.921875,-0.00019526202251602,2.7438017674772E-6,1,0.999253354069792,40.0298881530762,1.99893544688566,16.2300001829863,-0.00211200893345407,-0.000993055267038617,0.25,-5.35293179760205E-5,-0.000195879787533552,-5.392185714713E-5,199.9911499,199.9911499,62612.43359375,62627.41015625,57.738898715583,20.7705861122441,23.668306,0,0,0,40,4449,199.7341,62619.921875,,,,,,,,,,,,,0,,,,0,,,,,,199.9911499,,,,
,29297423.92,199.995285,57891.337890625,-0.000150010228567006,2.83046245021474E-6,1,0.999253354069792,40.0298881530762,1.99884279005183,16.2300001829863,-0.0015939184031911,-0.000927336097796633,0.25,-5.56047714909543E-5,-0.000150469243012233,-5.59566767816691E-5,199.995285,199.995285,57883.95703125,57898.71875,57.4059249663907,20.7767063541305,22.909004,0,0,0,40,4449,199.73615,57891.337890625,,,,,,,,,,,,,0,,,,-0.00245,,,,,,199.995285,,,,
,29297518.85,199.9928741,53146.232421875,-0.000124536072597941,4.09518375301622E-6,1,0.999253354069792,40.0298881530762,1.99874604712573,16.2300001829863,-0.00130498173672629,-0.000874624779285621,0.25,-5.53906793709248E-5,-0.000124907160667974,-5.57149614163197E-5,199.9928741,199.9928741,53136.16015625,53156.3046875,57.6224360662176,20.7800319060706,23.288654,0,0,0,40,4449,199.74195,53146.232421875,,,,,,,,,,,,,0,,,,0,,,,,,199.9928741,,,,
,29297614.36,199.988678,48370.9921875,-0.000102344123179028,2.58013202071973E-6,1,0.999253354069792,40.0298881530762,1.99879015635839,16.2300001829863,-0.0010749569897489,-0.000704402587859774,0.25,-4.42536057487787E-5,-0.000102650325987812,-4.45159345180006E-5,199.988678,199.988678,48368.46875,48373.515625,57.1651833824676,20.7786347317253,22.909004,0,0,0,40,4449,199.74995,48370.9921875,,,,,,,,,,,,,0,,,,-0.0049,,,,,,199.988678,,,,
,29297707.09,199.9851379,43738.349609375,-6.81618754154051E-5,3.30261096974037E-6,1,0.999253354069792,40.0298881530762,1.99915076527502,16.2300001829863,-0.000694957640537699,-0.000590669827018979,0.25,-4.01660652947357E-5,-6.83542812195082E-5,-4.03778427353016E-5,199.9851379,199.9851379,43725.9296875,43750.76953125,57.3965454241599,20.7738983976738,23.288654,0,0,0,40,4449,199.76365,43738.349609375,,,,,,,,,,,,,0,,,,-0.0049,,,,,,199.9851379,,,,
,29297804.07,199.9911194,38890.658203125,-4.39497693331137E-5,3.15562031545265E-6,1,0.999253354069792,40.0298881530762,1.99836394771318,16.2300001829863,-0.000436213800437949,-0.000448166730271235,0.25,-3.18395447248331E-5,-4.40673760133131E-5,-3.19966921912592E-5,199.9911194,199.9911194,38888.36328125,38892.953125,57.5364569291022,20.7839642930572,23.668306,0,0,0,40,4449,199.7717,38890.658203125,,,,,,,,,,,,,0,,,,0,,,,,,199.9911194,,,,
,29297898.32,199.9893188,34181.13671875,-2.30208014090415E-5,1.6509017816638E-6,1,0.999253354069792,40.0298881530762,1.9981863280955,16.2300001829863,-0.000212625814574202,-0.000325943880290753,0.25,-2.47119794585819E-5,-2.30737240380762E-5,-2.48220812647491E-5,199.9893188,199.9893188,34171.22265625,34191.05078125,57.271484861083,20.7801298544674,22.909004,0,0,0,40,4449,199.77945,34181.13671875,,,,,,,,,,,,,0,,,,0,,,,,,199.9893188,,,,
,29297990.765,199.987793,29561.2822265625,-5.89378611912457E-6,1.39500539011967E-6,1,0.999253354069792,40.0298881530762,1.99888189287752,16.2300001829863,-3.23512071357143E-5,-0.000210737828710958,0.25,-1.75327043397964E-5,-5.89524894406291E-6,-1.75995989765491E-5,199.987793,199.987793,29553.708984375,29568.85546875,57.8115901678715,20.7792944042747,23.288654,0,0,0,40,4449,199.79035,29561.2822265625,,,,,,,,,,,,,0,,,,0,,,,,,199.987793,,,,
,29298084.28,200.002121,24885.77734375,2.81745277719476E-5,9.12571120755166E-7,1,0.999253354069792,40.0298881530762,1.99650796911085,16.2300001829863,0.000365587989116916,-0.000209239674063464,0.25,-2.33388419082053E-5,2.82969897647965E-5,-2.33890098837849E-5,200.002121,200.002121,24880.861328125,24890.693359375,58.0882866636792,20.8035371543748,23.668306,0,0,0,40,4449,199.79,24885.77734375,,,,,,,,,,,,,0,,,,0.0049,,,,,,200.002121,,,,
,29298177.81,199.9987488,20210.599609375,4.10880405990401E-5,7.90417322248462E-7,1,0.999253354069792,40.0298881530762,1.99723986438676,16.2300001829863,0.000511252716127453,-0.000178088782959196,0.25,-2.28302341371835E-5,4.1254573707559E-5,-2.28646269077926E-5,199.9987488,199.9987488,20198.0546875,20223.14453125,57.2910255740638,20.7994378291801,23.288654,0,0,0,40,4449,199.78195,20210.599609375,,,,,,,,,,,,,0,,,,-0.00245,,,,,,199.9987488,,,,
,29298271.39,200.0014038,15533.8315429687,5.39101638132978E-5,7.89892209269094E-7,1,0.999253354069792,40.0298881530762,1.99720791646198,16.2300001829863,0.000646811353606933,-9.56235317624715E-5,0.25,-1.77903752061924E-5,5.41155265366117E-5,-1.77934038884166E-5,200.0014038,200.0014038,15531.318359375,15536.3447265625,57.566158812833,20.797188608644,22.909004,0,0,0,40,4449,199.7807,15533.8315429687,,,,,,,,,,,,,0,,,,0.0049,,,,,,200.0014038,,,,
,29298366.485,199.9862518,10781.2236328125,7.20072571195562E-5,5.96446536577788E-7,1,0.999253354069792,40.0298881530762,1.99905881180351,16.2300001829863,0.000834658175610159,4.51494850855135E-5,0.25,-8.53166427035825E-6,7.22650963142342E-5,-8.48302060656028E-6,199.9862518,199.9862518,10773.7060546875,10788.7412109375,57.4629838482945,20.7731642090757,22.909004,0,0,0,40,4449,199.79375,10781.2236328125,,,,,,,,,,,,,0,,,,0.00245,,,,,,199.9862518,,,,
,29298458.99,199.9814453,6158.1611328125,8.59846713696807E-5,4.6349565846092E-7,1,0.999253354069792,40.0298881530762,1.99885048544378,16.2300001829863,0.000987968662377629,0.000103461593786541,0.25,-5.82440808194418E-6,8.62878320059099E-5,-5.75114189951045E-6,199.9814453,199.9814453,6145.7294921875,6170.5927734375,57.5982055821215,20.7795994665295,23.668306,0,0,0,40,4449,199.8156,6158.1611328125,,,,,,,,,,,,,0,,,,0,,,,,,199.9814453,,,,
,29298551.67,199.9837799,1527.30065917969,6.55304996172276E-5,3.34539189335923E-7,1,0.999253354069792,40.0298881530762,1.99909276860192,16.2300001829863,0.000748122561572938,0.000107147507313492,0.25,-1.9482986268304E-6,6.57588246777422E-5,-1.88378180391219E-6,199.9837799,199.9837799,1517.25610351562,1537.34521484375,57.7514047718907,20.7789177507913,23.288654,0,0,0,40,4449,199.82235,1527.30065917969,,,,,,,,,,,,,0,,,,-0.00245,,,,,,199.9837799,,,,
,29298582.25,199.9871674,-0.327311143279076,3.91065583863948E-6,2.87705406832405E-7,1,0.999253354069792,40.0298881530762,1.99802164568458,16.2300001829863,4.64224458120776E-5,-3.97019912278336E-6,0.25,-1.02899060009821E-6,3.92527350998043E-6,-1.02829001648462E-6,199.9871674,199.9871674,-0.350146800279617,-0.304475486278534,57.3363600281791,20.7910576027577,23.668306,0,0,0,40,4417,199.831,-0.327311143279076,,,,,,,,,,,,,0,,,,0,,,,,,199.9871674,,,,