File: data/looselyPackedNP/sc-ios-7/ppms/rawdata/ES_S17_HYST_300K_INIT.DAT
[Header]
; VSM Data File (default extension .dat)
; Copyright (c) 2003-2013, Quantum Design, Inc. All rights reserved.
TITLE,
FILEOPENTIME,29213999.36,12/05/2018,11:01 am
BYAPP,VSM,2.0,2.0
INFO,PPMS VSM Option Release 1.4.10 Build 1,APPNAME
INFO,Quantum Design Linear Motor Servo Controller,MOTOR_MODULE_NAME
INFO,3101-100 M1,MOTOR_HW_VERSION
INFO,MMC1014,MOTOR_SERIAL_NUMBER
INFO,SRV No X-over 01.03.11,MOTOR_SOFTWARE_VERSION
INFO,Quantum Design VSM Detection Module,VSM_MODULE_NAME
INFO,3101-150 F0,VSM_HW_VERSION
INFO,VSM707,VSM_SERIAL_NUMBER
INFO,VSM No X-over 01.02.05 May 20 2008 13:51:47,VSM_SOFTWARE_VERSION
INFO,704,PREAMP_SERIAL_NUMBER
INFO,822,COIL_SERIAL_NUMBER
INFO,0,MOMENT_UNITS
INFO,Iron Oxide Spheres,SAMPLE_MATERIAL
INFO,7 nm diameter, collaboration Mainz,SAMPLE_COMMENT
INFO,,SAMPLE_MASS
INFO,,SAMPLE_VOLUME
INFO,,SAMPLE_MOLECULAR_WEIGHT
INFO,,SAMPLE_SIZE
INFO,,SAMPLE_SHAPE
DATATYPE,COMMENT,1
DATATYPE,TIME,2
STARTUPAXIS,X,2
STARTUPAXIS,Y1,5
[Data]
Comment,Time Stamp (sec),Temperature (K),Magnetic Field (Oe),Moment (emu),M. Std. Err. (emu),Transport Action,Averaging Time (sec),Frequency (Hz),Peak Amplitude (mm),Center Position (mm),Coil Signal' (mV),Coil Signal" (mV),Range (mV),M. Quad. Signal (emu),M. Raw' (emu),M. Raw" (emu),Min. Temperature (K),Max. Temperature (K),Min. Field (Oe),Max. Field (Oe),Mass (grams),Motor Lag (deg),Pressure (Torr),VSM Status (code),Motor Status (code),Measure Status (code),Measure Count,PPMS Status (code),System Temp. (K),System Field (Oe),Sample Position (deg),Bridge 1 Resistance (ohms),Bridge 1 Excitation (에),Bridge 2 Resistance (ohms),Bridge 2 Excitation (에),Bridge 3 Resistance (ohms),Bridge 3 Excitation (에),Bridge 4 Resistance (ohms),Bridge 4 Excitation (에),Signal 1 Vin (V),Signal 2 Vin (V),Digital Inputs (code),Drive 1 Iout (mA),Drive 1 Ipower (W),Drive 2 Iout (mA),Drive 2 Ipower (W),Pressure (),Map 20 (),Map 21 (),Map 22 (),Map 23 (),Map 24 (),Map 25 (),Map 26 (),Map 27 (),Map 28 (),Map 29 ()
,29214019.02,300.0195618,0.42626565694809,,,2,,,,15.5699999463558,,,,,,,300.0195618,300.0195618,0.42626565694809,0.42626565694809,,,23.668306,,,,-99999999,4369,300.187,0.42626565694809,,,,,,,,,,,,,,,,,,,,,,,300.0195618,,,,
,29214185.125,300.0221863,4921.4755859375,6.56799954741916E-5,8.22464066113214E-7,1,0.999253354069792,40.0298881530762,1.98381036355898,15.5600002035499,0.000736797638085573,0.00013489261484167,0.25,6.25132094986294E-7,6.5677569546341E-5,6.68674568299163E-7,300.0221863,300.0221863,4914.0400390625,4928.9111328125,56.4648442292367,20.6193878580961,24.047956,0,0,0,40,4449,300.14845,4921.4755859375,,,,,,,,,,,,,0,,,,-0.00245,,,,,,300.0221863,,,,
,29214284.17,300.0144043,9875.0361328125,4.89106798857421E-5,1.01077039656962E-6,1,0.999253354069792,40.0298881530762,1.98396294639882,15.5600002035499,0.00055260896347015,7.80140643213712E-5,0.25,-1.53184181443064E-6,4.89102132304336E-5,-1.49938107797273E-6,300.0144043,300.0144043,9872.3828125,9877.689453125,56.445303516256,20.6190062396901,24.047956,0,0,0,40,4449,300.1414,9875.0361328125,,,,,,,,,,,,,0,,,,0,,,,,,300.0144043,,,,
,29214379.86,300.0116577,14657.44921875,2.40276533483378E-5,1.4389595769876E-6,1,0.999253354069792,40.0298881530762,1.98407373360417,15.5600002035499,0.000272849998109744,3.04592308717452E-5,0.25,-1.45261155182967E-6,2.40278908286835E-5,-1.43665731576703E-6,300.0116577,300.0116577,14650.0693359375,14664.8291015625,56.3757385780444,20.619141326918,23.288654,0,0,0,40,4449,300.1346,14657.44921875,,,,,,,,,,,,,0,,,,0.0049,,,,,,300.0116577,,,,
,29214473.68,300.0038757,19345.005859375,-4.85639134393419E-6,1.97442934232103E-6,1,0.999253354069792,40.0298881530762,1.98422259773896,15.5600002035499,-4.27989939838152E-5,-7.74523031542404E-5,0.25,-6.05012283219628E-6,-4.85224395574734E-6,-6.05315530231709E-6,300.0038757,300.0038757,19337.66015625,19352.3515625,56.7587365524675,20.6198428507325,23.668306,0,0,0,40,4449,300.13595,19345.005859375,,,,,,,,,,,,,0,,,,0,,,,,,300.0038757,,,,
,29214568.46,300.001709,24082.7265625,-3.06537040739861E-5,3.70189999642453E-6,1,0.999253354069792,40.0298881530762,1.98413746020698,15.5600002035499,-0.000322703977033795,-0.000185463049562456,0.25,-1.11917749565498E-5,-3.06453971687155E-5,-1.12117030396152E-5,300.001709,300.001709,24075.33203125,24090.12109375,56.8501870892175,20.6218032908523,23.668306,0,0,0,40,4449,300.1362,24082.7265625,,,,,,,,,,,,,0,,,,0.00245,,,,,,300.001709,,,,
,29214664.315,300.0022583,28870.5625,-5.63344928535093E-5,3.57435064309227E-6,1,0.999253354069792,40.0298881530762,1.98403948225186,15.5600002035499,-0.000603228902417953,-0.000281946720902023,0.25,-1.53288540873659E-5,-5.63227014962713E-5,-1.5365596854024E-5,300.0022583,300.0022583,28868.154296875,28872.970703125,56.8236117195637,20.6223972222481,23.668306,0,0,0,40,4449,300.13085,28870.5625,,,,,,,,,,,,,0,,,,0.0049,,,,,,300.0022583,,,,
,29214757.93,300.00442505,33553.310546875,-7.95137028944587E-5,4.85710267516887E-6,1,0.999253354069792,40.0298881530762,1.98413555923199,15.5600002035499,-0.000847612129661354,-0.00042024706460901,0.25,-2.36179536562503E-5,-7.94957655517014E-5,-2.36697023139189E-5,300.004303,300.0045471,33545.54296875,33561.078125,56.8150138058522,20.6218919924626,23.668306,0,0,0,40,4449,300.12985,33553.310546875,,,,,,,,,,,,,0,,,,0,,,,,,300.00442505,,,,
,29214853.505,300.0086975,38328.4375,-0.000116991217444454,4.42215652986955E-6,1,0.999253354069792,40.0298881530762,1.98407819583545,15.5600002035499,-0.00126409018031421,-0.00052016318804001,0.25,-2.60167840567418E-5,-0.000116970592851364,-2.60931013260269E-5,300.0086975,300.0086975,38323.375,38333.5,56.8384626614291,20.6222891552582,24.047956,0,0,0,40,4449,300.11975,38328.4375,,,,,,,,,,,,,0,,,,-0.0049,,,,,,300.0086975,,,,
,29214950.585,300.0070496,43180.560546875,-0.000190730630889628,5.22920608286167E-6,1,0.999253354069792,40.0298881530762,1.9840473727803,15.5600002035499,-0.00205632614515247,-0.000873915694507395,0.25,-4.47205843303112E-5,-0.00019069554364438,-4.48448026671287E-5,300.0070496,300.0070496,43175.55859375,43185.5625,56.3882446343521,20.6231004578754,23.288654,0,0,0,40,4449,300.1191,43180.560546875,,,,,,,,,,,,,0,,,,0,,,,,,300.0070496,,,,
,29215043.725,300.0016785,47835.98046875,-0.000194202947901524,7.76541999481181E-6,1,0.999253354069792,40.0298881530762,1.98407310815043,15.5600002035499,-0.00211195630645886,-0.000784978160654663,0.25,-3.6204113517731E-5,-0.000194173438408943,-3.63307433165065E-5,300.0016785,300.0016785,47823.7109375,47848.25,56.9549253107945,20.62361894613,24.047956,0,0,0,40,4449,300.11365,47835.98046875,,,,,,,,,,,,,0,,,,0,,,,,,300.0016785,,,,
,29215138.225,300.0052185,52558.98046875,-0.000238821585816238,8.21628763876155E-6,1,0.999253354069792,40.0298881530762,1.98398303841866,15.5600002035499,-0.00258631246297017,-0.00102738659670275,0.25,-5.0048383403251E-5,-0.00023878168471889,-5.02037662625863E-5,300.0052185,300.0052185,52556.3984375,52561.5625,57.0823307594291,20.6239596723595,23.668306,0,0,0,40,4449,300.1125,52558.98046875,,,,,,,,,,,,,0,,,,0,,,,,,300.0052185,,,,
,29215233.54,300.0122375,57323.642578125,-0.000262061934772532,8.778421184795E-6,1,0.999253354069792,40.0298881530762,1.9840303171527,15.5600002035499,-0.0028497153938202,-0.00106010285777985,0.25,-4.89313255418308E-5,-0.000262022069919885,-4.91018050742326E-5,300.0122375,300.0122375,57318.5703125,57328.71484375,57.0026046504676,20.6251636030663,23.668306,0,0,0,40,4449,300.1027,57323.642578125,,,,,,,,,,,,,0,,,,0,,,,,,300.0122375,,,,
,29215326.96,300.00845335,61991.376953125,-0.000313070511366403,1.36810490435557E-5,1,0.999253354069792,40.0298881530762,1.9840925884749,15.5600002035499,-0.00336398426421064,-0.00150031687210998,0.25,-7.92629900199343E-5,-0.000313009356789583,-7.94658234184204E-5,300.0083313,300.0085754,61986.4921875,61996.26171875,57.1081245005637,20.6236867776297,24.047956,0,0,0,40,4449,300.0949,61991.376953125,,,,,,,,,,,,,0,,,,0.00245,,,,,,300.00845335,,,,
,29215422.61,300.0072632,66772.109375,-0.000336028520958795,1.38544973232127E-5,1,0.999253354069792,40.0298881530762,1.98396296941489,15.5600002035499,-0.00363655073736747,-0.0014595670309281,0.25,-7.16677639006051E-5,-0.000335971760451831,-7.18856166065602E-5,300.0072632,300.0072632,66764.7265625,66779.4921875,56.9760292808137,20.6258404673171,24.047956,0,0,0,40,4449,300.09015,66772.109375,,,,,,,,,,,,,0,,,,0,,,,,,300.0072632,,,,
,29215517.775,300.0101318,71529.89453125,-0.00048471872694952,1.67702857302355E-5,1,0.999253354069792,40.0298881530762,1.98388003947872,15.5600002035499,-0.00504467037414195,-0.00326446000444743,0.25,-0.000206534140332623,-0.000484569476071886,-0.000206844978695138,300.0101318,300.0101318,71497.671875,71562.1171875,57.149550812083,20.6265727328891,23.288654,0,0,0,40,4449,300.0923,71529.89453125,,,,,,,,,,,,,0,,,,0.0049,,,,,,300.0101318,,,,
,29215612.9,300.0097046,76283.03125,-0.000464732968418987,2.06333648204482E-5,1,0.999253354069792,40.0298881530762,1.98387066054801,15.5600002035499,-0.00494375094219226,-0.0025116601170598,0.25,-0.000143004621110345,-0.000464625981701562,-0.000143303925110695,300.0097046,300.0097046,76275.5078125,76290.5546875,56.8447156895829,20.6248463973035,23.668306,0,0,0,40,4449,300.0721,76283.03125,,,,,,,,,,,,,0,,,,0,,,,,,300.0097046,,,,
,29215711.31,300.0118408,81204.11328125,-0.000551283850529833,1.59320824869876E-5,1,0.999253354069792,40.0298881530762,1.98387209479526,15.5600002035499,-0.005800576479369,-0.00334822658998376,0.25,-0.000202458217851018,-0.000551135664506131,-0.000202811860750739,300.0118408,300.0118408,81194.171875,81214.0546875,57.0893654161022,20.625943597572,24.047956,0,0,0,40,4449,300.06135,81204.11328125,,,,,,,,,,,,,0,,,,0.0049,,,,,,300.0118408,,,,
,29215807.785,300.0092773,86027.00390625,-0.000588469446953951,2.43829329965866E-5,1,0.999253354069792,40.0298881530762,1.98382007537768,15.5600002035499,-0.00611000282842827,-0.00404548476862194,0.25,-0.000258076077025149,-0.000588284204561322,-0.000258451906784951,300.0092773,300.0092773,86017.1875,86036.8203125,56.8744175733137,20.6264870179166,23.668306,0,0,0,40,4449,300.06125,86027.00390625,,,,,,,,,,,,,0,,,,0,,,,,,300.0092773,,,,
,29215922.25,300.0142822,89261.69140625,-0.000576530212744151,1.89925692961466E-5,1,0.999253354069792,40.0298881530762,1.98369072116247,15.5600002035499,-0.00606019468488865,-0.00353297939895035,0.25,-0.000214554121126556,-0.000576373700765979,-0.000214923116940635,300.0142822,300.0142822,89256.6484375,89266.734375,56.7102755842752,20.6246245441031,23.288654,0,0,0,40,4449,300.04415,89261.69140625,,,,,,,,,,,,,0,,,,-0.00245,,,,,,300.0142822,,,,
,29216012.235,300.004425,84766.68359375,-0.000532373905189604,1.72124570341766E-5,1,0.999253354069792,40.0298881530762,1.98371421426279,15.5600002035499,-0.00560142063645043,-0.00323176826351722,0.25,-0.000195392469137833,-0.000532231160908706,-0.000195733744250025,300.004425,300.004425,84759.125,84774.2421875,56.9291315696599,20.6284895994671,24.047956,0,0,0,40,4449,300.0473,84766.68359375,,,,,,,,,,,,,0,,,,0.00245,,,,,,300.004425,,,,
,29216104.94,299.9973145,80132.21875,-0.000611350211849073,2.59666655080275E-5,1,0.999253354069792,40.0298881530762,1.98357098452217,15.5600002035499,-0.00642087726559929,-0.00377474942769532,0.25,-0.000230057605630719,-0.000611182527638294,-0.000230449858584559,299.9973145,299.9973145,80129.859375,80134.578125,57.0252718775253,20.6324919582593,23.288654,0,0,0,40,4449,300.0526,80132.21875,,,,,,,,,,,,,0,,,,-0.0049,,,,,,299.9973145,,,,
,29216198.675,299.99165345,75443.69140625,-0.000568415312195982,2.29367040915379E-5,1,0.999253354069792,40.0298881530762,1.98361677419093,15.5600002035499,-0.0059654396014023,-0.00353646621114275,0.25,-0.000216280125710218,-0.000568257762006866,-0.000216645229776224,299.9913635,299.9919434,75431.2578125,75456.125,57.078422616833,20.6306105632176,23.668306,0,0,0,40,4449,300.05905,75443.69140625,,,,,,,,,,,,,0,,,,-0.00245,,,,,,299.99165345,,,,
,29216294.165,299.9913635,70672.9453125,-0.000494371472269947,2.14640583325664E-5,1,0.999253354069792,40.0298881530762,1.98365294187156,15.5600002035499,-0.00523388522556138,-0.00281358414881137,0.25,-0.000164764452004755,-0.000494249533571391,-0.00016508304369895,299.9913635,299.9913635,70667.9453125,70677.9453125,57.0393411908714,20.6317533231497,23.288654,0,0,0,40,4449,300.0614,70672.9453125,,,,,,,,,,,,,0,,,,0,,,,,,299.9913635,,,,
,29216389.02,299.9782715,65929.93359375,-0.000413347032011534,1.57269475091388E-5,1,0.999253354069792,40.0298881530762,1.98366956610274,15.5600002035499,-0.00439949994385183,-0.00221752263828048,0.25,-0.00012574938570049,-0.000413253011359299,-0.000126016454653247,299.9782715,299.9782715,65925.0625,65934.8046875,57.2667950899676,20.6325107269764,24.047956,0,0,0,40,4449,300.08565,65929.93359375,,,,,,,,,,,,,0,,,,0,,,,,,299.9782715,,,,
,29216484.835,299.9854431,61139.146484375,-0.000379453317988264,1.64066408160128E-5,1,0.999253354069792,40.0298881530762,1.98355088508739,15.5600002035499,-0.00401177362538678,-0.00218992622321585,0.25,-0.000129176316389959,-0.000379357786375915,-0.000129421353640446,299.9854431,299.9854431,61136.6484375,61141.64453125,57.1792526958137,20.6361582146759,23.288654,0,0,0,40,4449,300.0822,61139.146484375,,,,,,,,,,,,,0,,,,0,,,,,,299.9854431,,,,
,29216579.485,299.9858093,56411.03515625,-0.000348232841948514,1.43008458618835E-5,1,0.999253354069792,40.0298881530762,1.98356128322341,15.5600002035499,-0.00369049924316705,-0.00195903550134537,0.25,-0.000114033493252713,-0.0003481480229741,-0.000114258735202542,299.9858093,299.9858093,56398.37890625,56423.69140625,57.1604936113522,20.6341906563792,23.288654,0,0,0,40,4449,300.10295,56411.03515625,,,,,,,,,,,,,0,,,,0.0049,,,,,,299.9858093,,,,
,29216674.465,299.986969,51663.62109375,-0.000271022705600958,1.35435253446024E-5,1,0.999253354069792,40.0298881530762,1.98354038488173,15.5600002035499,-0.00290432845119605,-0.00133929201455357,0.25,-7.22505428445483E-5,-0.000270967438936047,-7.24265052281462E-5,299.986969,299.986969,51651.125,51676.1171875,57.2120810936214,20.6377074592106,23.288654,0,0,0,40,4449,300.114,51663.62109375,,,,,,,,,,,,,0,,,,0,,,,,,299.986969,,,,
,29216769.06,299.9833679,46933.26953125,-0.000234333133172226,9.06092841928732E-6,1,0.999253354069792,40.0298881530762,1.98344518662358,15.5600002035499,-0.00250480255831027,-0.00119393966551688,0.25,-6.5674490078594E-5,-0.000234283211883374,-6.58267095590719E-5,299.9833679,299.9833679,46928.28515625,46938.25390625,56.9908802226791,20.6386714274934,23.668306,0,0,0,40,4449,300.1245,46933.26953125,,,,,,,,,,,,,0,,,,-0.00245,,,,,,299.9833679,,,,
,29216863.71,299.9915161,42203.228515625,-0.000186822809448239,6.91296907459491E-6,1,0.999253354069792,40.0298881530762,1.98339880093859,15.5600002035499,-0.00199770102517053,-0.000947318080976194,0.25,-5.19556219135629E-5,-0.000186783171359848,-5.20771054998269E-5,299.9915161,299.9915161,42190.74609375,42215.7109375,56.9861904515637,20.6411319806966,23.668306,0,0,0,40,4449,300.128,42203.228515625,,,,,,,,,,,,,0,,,,0,,,,,,299.9915161,,,,
,29216956.62,299.9913635,37560.568359375,-0.000151153099417253,5.64986599498594E-6,1,0.999253354069792,40.0298881530762,1.98349241322911,15.5600002035499,-0.00161252909262097,-0.00078857333747708,0.25,-4.40019735160132E-5,-0.000151119695975702,-4.41003073899934E-5,299.9913635,299.9913635,37552.94140625,37568.1953125,57.3676251689484,20.6394602120279,23.668306,0,0,0,40,4449,300.12885,37560.568359375,,,,,,,,,,,,,0,,,,0,,,,,,299.9913635,,,,
,29217051.305,299.9847412,32827.99609375,-9.9225009099457E-5,4.03378902144607E-6,1,0.999253354069792,40.0298881530762,1.9835188258849,15.5600002035499,-0.00106350928113309,-0.000489125969503832,0.25,-2.63446834189019E-5,-9.92047561941647E-5,-2.64093786899408E-5,299.9847412,299.9847412,32820.3671875,32835.625,57.2495992625445,20.6393365806953,23.668306,0,0,0,40,4449,300.1434,32827.99609375,,,,,,,,,,,,,0,,,,-0.00245,,,,,,299.9847412,,,,
,29217147.18,299.9858704,28037.828125,-6.82642363901028E-5,2.6307642009821E-6,1,0.999253354069792,40.0298881530762,1.98338638133284,15.5600002035499,-0.000734932513817954,-0.000317365193009335,0.25,-1.64225410696975E-5,-6.82514082904825E-5,-1.6467141622432E-5,299.9858704,299.9858704,28032.3046875,28043.3515625,57.3785679682176,20.6416351232464,24.047956,0,0,0,40,4449,300.15625,28037.828125,,,,,,,,,,,,,0,,,,0,,,,,,299.9858704,,,,
,29217243.795,299.9816589,23207.7314453125,-2.75040302536968E-5,3.43791261592668E-6,1,0.999253354069792,40.0298881530762,1.98338885514668,15.5600002035499,-0.000288492181462184,-0.000171828517799294,0.25,-1.05297602721028E-5,-2.74962734536058E-5,-1.0547635357267E-5,299.9816589,299.9816589,23195.0625,23220.400390625,57.1042163579676,20.6433193818433,23.668306,0,0,0,40,4449,300.1601,23207.7314453125,,,,,,,,,,,,,0,,,,-0.00245,,,,,,299.9816589,,,,
,29217341.265,299.9919434,18335.4111328125,-1.28837881466342E-6,1.54354958034299E-6,1,0.999253354069792,40.0298881530762,1.98326776605728,15.5600002035499,1.12260374530507E-5,-0.000150836391533321,0.25,-1.32040281261113E-5,-1.27960527955523E-6,-1.32044924653661E-5,299.9919434,299.9919434,18332.951171875,18337.87109375,57.251162519583,20.6449648399461,23.668306,0,0,0,40,4449,300.1791,18335.4111328125,,,,,,,,,,,,,0,,,,-0.0049,,,,,,299.9919434,,,,
,29217436.13,299.989563,13593.0864257813,2.48736937739421E-5,1.35209640303949E-6,1,0.999253354069792,40.0298881530762,1.98321679662167,15.5600002035499,0.000295359476797722,-4.36199840206361E-5,0.25,-8.19267217467574E-6,2.48783885984745E-5,-8.17596089487574E-6,299.989563,299.989563,13590.4990234375,13595.673828125,57.2793011462753,20.6471224455692,23.288654,0,0,0,40,4449,300.1831,13593.0864257813,,,,,,,,,,,,,0,,,,0.0049,,,,,,299.989563,,,,
,29217531.215,299.9894104,8842.5263671875,5.13220261739499E-5,8.88826673484923E-7,1,0.999253354069792,40.0298881530762,1.98321829077567,15.5600002035499,0.000586192673934413,4.4044160204184E-5,0.25,-4.97117320363176E-6,5.13238118728077E-5,-4.93701487815547E-6,299.9894104,299.9894104,8837.447265625,8847.60546875,57.2464727484676,20.6480281187487,24.047956,0,0,0,40,4449,300.1879,8842.5263671875,,,,,,,,,,,,,0,,,,0,,,,,,299.9894104,,,,
,29217622.07,299.9885559,4302.1767578125,6.31981913536429E-5,6.69309413988792E-7,1,0.999253354069792,40.0298881530762,1.98323998995338,15.5600002035499,0.000714308128386805,9.77548614495937E-5,0.25,-2.24758037993722E-6,6.31978233167986E-5,-2.20560309100391E-6,299.9885559,299.9885559,4299.69970703125,4304.65380859375,57.3082214014868,20.6475821065477,23.288654,0,0,0,40,4449,300.1986,4302.1767578125,,,,,,,,,,,,,0,,,,0.0049,,,,,,299.9885559,,,,
,29217710.28,299.9903717,-108.865093231201,-2.8438171101158E-6,4.21308895262846E-7,1,0.999253354069792,40.0298881530762,1.98312093687145,15.5600002035499,-3.16364491070804E-5,-7.30992415903888E-6,0.25,-1.58045705480732E-7,-2.84362833744323E-6,-1.59927962605888E-7,299.9901733,299.9905701,-113.989379882813,-103.74080657959,57.2996234877753,20.6488856132924,23.288654,0,0,0,40,4449,300.1978,-108.865093231201,,,,,,,,,,,,,0,,,,-0.0049,,,,,,299.9903717,,,,
,29217799.11,299.9902344,-4545.56762695313,-6.16018211624531E-5,6.36383504947387E-7,1,0.999253354069792,40.0298881530762,1.98317550068166,15.5600002035499,-0.000695348658784923,-0.000100445751566669,0.25,1.73116879112755E-6,-6.16011541327533E-5,1.69026919306967E-6,299.9902344,299.9902344,-4553.04541015625,-4538.08984375,57.413741251583,20.6489374771796,23.668306,0,0,0,40,4449,300.2139,-4545.56762695313,,,,,,,,,,,,,0,,,,0.00245,,,,,,299.9902344,,,,
,29217898.32,300.0010681,-9504.46142578125,-4.82776438405708E-5,9.84519217141299E-7,1,0.999253354069792,40.0298881530762,1.98322615298223,15.5600002035499,-0.000552465495141057,-3.54091328777897E-5,0.25,5.2124079545331E-6,-4.82796586017823E-5,5.18026307868972E-6,300.0010681,300.0010681,-9506.8056640625,-9502.1171875,57.301968373333,20.6482792808648,23.288654,0,0,0,40,4449,300.19965,-9504.46142578125,,,,,,,,,,,,,0,,,,0,,,,,,300.0010681,,,,
,29217997.83,300.0030365,-14479.4658203125,-2.30184259312197E-5,1.21274080388611E-6,1,0.999253354069792,40.0298881530762,1.98318413118192,15.5600002035499,-0.000271276986068587,2.85458604805086E-5,0.25,6.52935785951798E-6,-2.30220620890557E-5,6.5139238263023E-6,300.002655,300.003418,-14489.4482421875,-14469.4833984375,57.4465696493907,20.6474504537272,24.047956,0,0,0,40,4449,300.1911,-14479.4658203125,,,,,,,,,,,,,0,,,,0.0049,,,,,,300.0030365,,,,
,29218096.7,300.0050354,-19419.232421875,5.55369619297556E-6,2.37658911708772E-6,1,0.999253354069792,40.0298881530762,1.98294386504708,15.5600002035499,5.39262184756003E-5,5.95904890506651E-5,0.25,4.34327210355601E-6,5.55065770689581E-6,4.34681583444597E-6,300.0050354,300.0050354,-19426.58984375,-19411.875,57.3590272552368,20.652275082347,23.288654,0,0,0,40,4449,300.1892,-19419.232421875,,,,,,,,,,,,,0,,,,0.0049,,,,,,300.0050354,,,,
,29218195.115,300.0021057,-24338.896484375,3.31547942003599E-5,4.25404582728299E-6,1,0.999253354069792,40.0298881530762,1.98284213670236,15.5600002035499,0.00033543956139063,0.000277677653199985,0.25,1.8979249288867E-5,3.314126932457E-5,1.90005936100098E-5,300.0021057,300.0021057,-24343.841796875,-24333.951171875,57.3402681707753,20.6549751834028,23.668306,0,0,0,40,4449,300.1892,-24338.896484375,,,,,,,,,,,,,0,,,,-0.0049,,,,,,300.0021057,,,,
,29218292.89,300.0064697,-29223.6552734375,7.08367216196253E-5,4.40093864619438E-6,1,0.999253354069792,40.0298881530762,1.98290741968514,15.5600002035499,0.000744868756452062,0.000430732160861112,0.25,2.60769222095221E-5,7.0817399033894E-5,2.61229050082959E-5,300.0064697,300.0064697,-29231.103515625,-29216.20703125,57.3848209963715,20.6543837266409,23.668306,0,0,0,40,4449,300.1855,-29223.6552734375,,,,,,,,,,,,,0,,,,-0.00245,,,,,,300.0064697,,,,
,29218387.65,300.005127,-33960.908203125,0.000107723422509276,5.35114260497648E-6,1,0.999253354069792,40.0298881530762,1.98277670533581,15.5600002035499,0.00113858043316939,0.000620884578181119,0.25,3.66196502378229E-5,0.000107696078050798,3.66896008995169E-5,300.005127,300.005127,-33973.30078125,-33948.515625,57.4879959609099,20.6570298240227,24.047956,0,0,0,40,4449,300.1783,-33960.908203125,,,,,,,,,,,,,0,,,,0.0049,,,,,,300.005127,,,,
,29218485.395,300.0117493,-38845.693359375,0.000143035233286377,6.88102920069939E-6,1,0.999253354069792,40.0298881530762,1.98276981509484,15.5600002035499,0.00151961788340535,0.00077930167961459,0.25,4.46074141707278E-5,0.000143001578669668,4.47003088762053E-5,300.0117493,300.0117493,-38850.765625,-38840.62109375,57.3394865422561,20.6592162204947,23.668306,0,0,0,40,4449,300.1631,-38845.693359375,,,,,,,,,,,,,0,,,,-0.0049,,,,,,300.0117493,,,,
,29218580.585,300.0125122,-43602.916015625,0.000186836023446085,9.64001912388997E-6,1,0.999253354069792,40.0298881530762,1.98284390786128,15.5600002035499,0.00195718744156808,0.0011786960098451,0.25,7.25771396794247E-5,0.000186782694228182,7.26979243271905E-5,300.0125122,300.0125122,-43607.9609375,-43597.87109375,57.3238539718714,20.6579524728045,23.288654,0,0,0,40,4449,300.16,-43602.916015625,,,,,,,,,,,,,0,,,,0.00245,,,,,,300.0125122,,,,
,29218676.59,300.0122375,-48400.412109375,0.000221227552332736,1.5346311056283E-5,1,0.999253354069792,40.0298881530762,1.98286729362718,15.5600002035499,0.00232292446434724,0.00136425606037102,0.25,8.31390952875232E-5,0.000221166322887067,8.32820454503298E-5,300.0122375,300.0122375,-48410.28515625,-48390.5390625,57.3644986548715,20.6569522383758,24.047956,0,0,0,40,4449,300.15025,-48400.412109375,,,,,,,,,,,,,0,,,,0.00245,,,,,,300.0122375,,,,
,29218774.185,300.0087585,-53277.90234375,0.000247198144980698,1.31008063280019E-5,1,0.999253354069792,40.0298881530762,1.98271721876621,15.5600002035499,0.00262462742279486,0.00135579539681553,0.25,7.78951683583934E-5,0.0002471396947439,7.80551790683403E-5,300.0087585,300.0087585,-53282.9921875,-53272.8125,57.3621537693137,20.6598426944117,24.047956,0,0,0,40,4449,300.1402,-53277.90234375,,,,,,,,,,,,,0,,,,0.00245,,,,,,300.0087585,,,,
,29218871.235,300.0080872,-58127.501953125,0.00031705452472516,1.57305695929684E-5,1,0.999253354069792,40.0298881530762,1.98271835873306,15.5600002035499,0.00330857393405371,0.00207230343351943,0.25,0.000129591888640723,0.000316960192604307,0.000129796013192932,300.0080872,300.0080872,-58129.8359375,-58125.16796875,57.4903408464676,20.6583189754278,23.668306,0,0,0,40,4449,300.1339,-58127.501953125,,,,,,,,,,,,,0,,,,0,,,,,,300.0080872,,,,
,29218967.095,300.0086365,-62920.294921875,0.000363306155482366,2.10427030392531E-5,1,0.999253354069792,40.0298881530762,1.98286653482286,15.5600002035499,0.00379104436467362,0.00237739652328746,0.25,0.000148729956409038,0.000363198037569113,0.000148963586751827,300.0086365,300.0086365,-62922.84765625,-62917.7421875,57.4074882234292,20.6599110755606,23.668306,0,0,0,40,4449,300.12485,-62920.294921875,,,,,,,,,,,,,0,,,,0.0049,,,,,,300.0086365,,,,
,29219065.71,300.0051575,-67849.81640625,0.000418687080014294,1.38852365689749E-5,1,0.999253354069792,40.0298881530762,1.98269351974437,15.5600002035499,0.00442384468651214,0.00242054860516365,0.25,0.000142995447234692,0.000418581286585651,0.000143265219983722,300.0051575,300.0051575,-67855.0234375,-67844.609375,57.4903408464676,20.6626836460456,23.668306,0,0,0,40,4449,300.12315,-67849.81640625,,,,,,,,,,,,,0,,,,-0.0049,,,,,,300.0051575,,,,
,29219162.74,300.0152283,-72696.41796875,0.000446717382589918,1.77271594134606E-5,1,0.999253354069792,40.0298881530762,1.98252885060184,15.5600002035499,0.00471567797349975,0.00260525220074004,0.25,0.000154604569856621,0.000446603163828233,0.000154891951423087,300.0152283,300.0152283,-72701.3984375,-72691.4375,57.4989387601791,20.6659493901126,23.668306,0,0,0,40,4449,300.1142,-72696.41796875,,,,,,,,,,,,,0,,,,0,,,,,,300.0152283,,,,
,29219259.865,300.0154419,-77551.15234375,0.000528289172794777,2.59736603837502E-5,1,0.999253354069792,40.0298881530762,1.98258208311365,15.5600002035499,0.00557355805084672,0.00310045353560542,0.25,0.000184563340069498,0.000528153141527056,0.000184902753931556,300.0154419,300.0154419,-77558.640625,-77543.6640625,57.5645955557946,20.6651666137514,23.288654,0,0,0,40,4449,300.0967,-77551.15234375,,,,,,,,,,,,,0,,,,-0.00245,,,,,,300.0154419,,,,
,29219356.815,300.0190125,-82396.0546875,0.000515323220633396,3.02722621354615E-5,1,0.999253354069792,40.0298881530762,1.98257710724557,15.5600002035499,0.00542591518815373,0.00308690735988373,0.25,0.000185604492826648,0.000515187016023771,0.000185934977355726,300.0190125,300.0190125,-82406.2109375,-82385.8984375,57.5817913832176,20.6692950536757,24.047956,0,0,0,40,4449,300.0997,-82396.0546875,,,,,,,,,,,,,0,,,,0.00245,,,,,,300.0190125,,,,
,29219452.825,300.0169373,-87195.1484375,0.00055382711810971,2.05411447800421E-5,1,0.999253354069792,40.0298881530762,1.98226601777825,15.5600002035499,0.00582710812504278,0.00333638782546202,0.25,0.000201194439724274,0.000553679852436798,0.000201549159160581,300.0169373,300.0169373,-87197.734375,-87192.5625,57.515352959083,20.6765211129391,23.288654,0,0,0,40,4449,300.0885,-87195.1484375,,,,,,,,,,,,,0,,,,0,,,,,,300.0169373,,,,
,29219561.805,300.0091553,-88342.80078125,0.000560647493041233,2.3633555173421E-5,1,0.999253354069792,40.0298881530762,1.98205604526418,15.5600002035499,0.00594080623431912,0.00313163459389661,0.25,0.00018180543585802,0.00056051284497363,0.000182165131899581,300.0091553,300.0091553,-88347.703125,-88337.8984375,57.606803495833,20.6819279596423,24.047956,0,0,0,40,4449,300.0722,-88342.80078125,,,,,,,,,,,,,0,,,,0.0049,,,,,,300.0091553,,,,
,29219652.17,300.0003052,-83825.79296875,0.000529837166701325,2.62293378968884E-5,1,0.999253354069792,40.0298881530762,1.98192727595459,15.5600002035499,0.00554575221369655,0.00335317574256934,0.25,0.000206894090464659,0.000529687054445397,0.000207233459620997,300.0003052,300.0003052,-83830.7109375,-83820.875,57.7154498600061,20.6843518160618,24.047956,0,0,0,40,4449,300.0724,-83825.79296875,,,,,,,,,,,,,0,,,,0,,,,,,300.0003052,,,,
,29219747.53,299.9981995,-79058.71875,0.000477614878953413,1.24843222290985E-5,1,0.999253354069792,40.0298881530762,1.98201592010592,15.5600002035499,0.00510293119438356,0.00242498124762662,0.25,0.000133252093533966,0.00047751416462511,0.000133559929800654,299.9981995,299.9981995,-79069.0625,-79048.375,57.6216544376984,20.6830509709468,24.047956,0,0,0,40,4449,300.0753,-79058.71875,,,,,,,,,,,,,0,,,,0.0049,,,,,,299.9981995,,,,
,29219846.895,299.99183655,-74094.05078125,0.000418938492592508,1.60397532596582E-5,1,0.999253354069792,40.0298881530762,1.9819558514924,15.5600002035499,0.00443269109762984,0.00237635533170536,0.25,0.000139092266698324,0.00041883560885353,0.000139362009388944,299.9918213,299.9918518,-74096.4140625,-74091.6875,57.4692368764484,20.6809880723508,23.668306,0,0,0,40,4449,300.0801,-74094.05078125,,,,,,,,,,,,,0,,,,0.0049,,,,,,299.99183655,,,,
,29219944.495,299.9915466,-69217.1875,0.000395885371876337,1.94187648149277E-5,1,0.999253354069792,40.0298881530762,1.98186714652675,15.5600002035499,0.00422097315163136,0.00205858398739989,0.25,0.000114788372379425,0.000395798915855138,0.000115044050173531,299.9915466,299.9915466,-69224.671875,-69209.703125,57.5278590153907,20.6858554187374,24.047956,0,0,0,40,4449,300.0917,-69217.1875,,,,,,,,,,,,,0,,,,-0.00245,,,,,,299.9915466,,,,
,29220043.245,299.9898987,-64282.755859375,0.000347157713406848,1.30251653777463E-5,1,0.999253354069792,40.0298881530762,1.98183352409984,15.5600002035499,0.00372742313746375,0.00165481050474721,0.25,8.72650308861682E-5,0.000347090588906201,8.74898946250347E-5,299.9898987,299.9898987,-64287.89453125,-64277.6171875,57.7138866029676,20.685446988794,23.288654,0,0,0,40,4449,300.1006,-64282.755859375,,,,,,,,,,,,,0,,,,-0.00245,,,,,,299.9898987,,,,
,29220136.945,299.9873657,-59597.326171875,0.000301409751631644,1.7951365141316E-5,1,0.999253354069792,40.0298881530762,1.98186773793367,15.5600002035499,0.00324067372329371,0.00141141286178507,0.25,7.35067688120006E-5,0.000301352905847861,7.37022879966549E-5,299.9873657,299.9873657,-59599.8515625,-59594.80078125,57.637287008083,20.6826809010332,24.047956,0,0,0,40,4449,300.1101,-59597.326171875,,,,,,,,,,,,,0,,,,0.0049,,,,,,299.9873657,,,,
,29220233.94,299.9855347,-54752.955078125,0.000232488181169946,1.48914669623916E-5,1,0.999253354069792,40.0298881530762,1.98167711004638,15.5600002035499,0.00244817929280434,0.0013843187564097,0.25,8.30452403223153E-5,0.000232426997523473,8.31954670068325E-5,299.9855347,299.9855347,-54757.625,-54748.28515625,57.6021137247176,20.6849053467135,24.047956,0,0,0,40,4449,300.1232,-54752.955078125,,,,,,,,,,,,,0,,,,0.0049,,,,,,299.9855347,,,,
,29220330.74,299.9906616,-49913.486328125,0.000223219906037366,1.10900104900681E-5,1,0.999253354069792,40.0298881530762,1.98176958026518,15.5600002035499,0.00241214103756289,0.000974472365144835,0.25,4.81351071136496E-5,0.000223181814609809,4.82803981436573E-5,299.9906616,299.9906616,-49926.0546875,-49900.91796875,57.4762715331215,20.6841022462089,23.288654,0,0,0,40,4449,300.1426,-49913.486328125,,,,,,,,,,,,,0,,,,0,,,,,,299.9906616,,,,
,29220430.39,299.991333,-44933.7734375,0.000171552459237829,8.70536470748592E-6,1,0.999253354069792,40.0298881530762,1.98184471590424,15.5600002035499,0.001839231520025,0.00083351054183395,0.25,4.45265903008436E-5,0.000171518184396703,4.46381610661792E-5,299.991333,299.991333,-44943.8515625,-44923.6953125,57.5325487865061,20.6842159818597,24.047956,0,0,0,40,4449,300.14295,-44933.7734375,,,,,,,,,,,,,0,,,,-0.0049,,,,,,299.991333,,,,
,29220526.96,299.9841919,-40105.724609375,0.0001491558078529,5.302549440258E-6,1,0.999253354069792,40.0298881530762,1.98146462390408,15.5600002035499,0.00161932242426637,0.000606233982056821,0.25,2.81709853581769E-5,0.00014913295302892,2.82684053444977E-5,299.9841919,299.9841919,-40110.5859375,-40100.86328125,57.6177462951023,20.6888225116154,23.668306,0,0,0,40,4449,300.157,-40105.724609375,,,,,,,,,,,,,0,,,,-0.00245,,,,,,299.9841919,,,,
,29220621.99,299.9851685,-35356.029296875,0.000115354923756016,4.25556324812081E-6,1,0.999253354069792,40.0298881530762,1.98147034866808,15.5600002035499,0.00126003365211593,0.000424582963382849,0.25,1.78426148447504E-5,0.000115339822659364,1.79181487530255E-5,299.9851685,299.9851685,-35363.5078125,-35348.55078125,57.4942489890638,20.6881778255244,23.668306,0,0,0,40,4449,300.165,-35356.029296875,,,,,,,,,,,,,0,,,,0.0049,,,,,,299.9851685,,,,
,29220717.725,299.9880676,-30571.29296875,8.11733261001745E-5,3.62290948233874E-6,1,0.999253354069792,40.0298881530762,1.98170701740808,15.5600002035499,0.000887210947682085,0.000296234917016492,0.25,1.23264536172751E-5,8.11628292445572E-5,1.23796642102689E-5,299.9880676,299.9880676,-30581.552734375,-30561.033203125,57.5755383550638,20.684190195629,23.668306,0,0,0,40,4449,300.1745,-30571.29296875,,,,,,,,,,,,,0,,,,0,,,,,,299.9880676,,,,
,29220812.71,299.9880066,-25826.3583984375,4.97683797751723E-5,2.46372774073568E-6,1,0.999253354069792,40.0298881530762,1.98170755524669,15.5600002035499,0.000538417120408877,0.000213618562817645,0.25,1.04076046665041E-5,4.97600540761767E-5,1.0440175928156E-5,299.9880066,299.9880066,-25838.54296875,-25814.173828125,57.4817429327561,20.684738780977,23.288654,0,0,0,40,4449,300.1932,-25826.3583984375,,,,,,,,,,,,,0,,,,-0.00245,,,,,,299.9880066,,,,
,29220910.94,299.987915,-20917.2138671875,1.71905814937346E-5,1.62275873378688E-6,1,0.999253354069792,40.0298881530762,1.98183636701886,15.5600002035499,0.000172133434262178,0.000153750762766869,0.25,1.07177226254706E-5,1.71829927893087E-5,1.07287760461732E-5,299.987915,299.987915,-20927.23046875,-20907.197265625,57.7787617700638,20.6815958210141,23.668306,0,0,0,40,4449,300.19855,-20917.2138671875,,,,,,,,,,,,,0,,,,0,,,,,,299.987915,,,,
,29221005.35,299.9872437,-16197.2841796875,-1.4113424162727E-5,1.22206243294701E-6,1,0.999253354069792,40.0298881530762,1.98188315142044,15.5600002035499,-0.000172103692971055,5.14187869934161E-5,0.25,7.02555342581669E-6,-1.41176609799893E-5,7.01600786540221E-6,299.9872437,299.9872437,-16204.5888671875,-16189.9794921875,57.5528711280061,20.6798604202477,23.668306,0,0,0,40,4449,300.20685,-16197.2841796875,,,,,,,,,,,,,0,,,,0,,,,,,299.9872437,,,,
,29221101.665,299.9955444,-11384.6166992187,-3.72369097243289E-5,1.29064512233696E-6,1,0.999253354069792,40.0298881530762,1.98172173492655,15.5600002035499,-0.000429639049277474,-5.20327091419329E-6,0.25,5.9880947337941E-6,-3.72397743477386E-5,5.96325244000446E-6,299.9955444,299.9955444,-11397.0029296875,-11372.23046875,57.5325487865061,20.6833461499495,23.668306,0,0,0,40,4449,300.2052,-11384.6166992187,,,,,,,,,,,,,0,,,,0.0049,,,,,,299.9955444,,,,
,29221195.305,299.9891968,-6703.75708007812,-5.75373939526576E-5,7.58964979043852E-7,1,0.999253354069792,40.0298881530762,1.98181950446616,15.5600002035499,-0.000648851388595912,-9.48805282718997E-5,0.25,1.51686431768354E-6,-5.75367075473897E-5,1.47867938868632E-6,299.9891968,299.9891968,-6713.578125,-6693.93603515625,57.5583425276407,20.6799140116685,23.288654,0,0,0,40,4449,300.2167,-6703.75708007812,,,,,,,,,,,,,0,,,,0,,,,,,299.9891968,,,,
,29221285.895,299.99160765,-2175.36938476562,-5.24988893766163E-5,4.18161383287237E-7,1,0.999253354069792,40.0298881530762,1.98185501940599,15.5600002035499,-0.000589780156552105,-9.96282975159272E-5,0.25,2.21133722976616E-7,-5.24974857566198E-5,1.86304502008249E-7,299.9915466,299.9916687,-2180.24926757813,-2170.48950195313,57.5716302124676,20.6789646860764,23.288654,0,0,0,40,4449,300.2222,-2175.36938476562,,,,,,,,,,,,,0,,,,0.00245,,,,,,299.99160765,,,,
,29221375.645,299.9898682,2308.3720703125,5.30729267373621E-5,4.84902186302645E-7,1,0.999253354069792,40.0298881530762,1.9816259948359,15.5600002035499,0.000598135777858859,8.93213937781274E-5,0.25,-1.23784267348208E-6,5.30721840305788E-5,-1.20260517031734E-6,299.9898682,299.9898682,2303.46923828125,2313.27490234375,57.3605905122753,20.683908607915,24.047956,0,0,0,40,4449,300.2353,2308.3720703125,,,,,,,,,,,,,0,,,,0,,,,,,299.9898682,,,,
,29221468.915,299.9978943,6969.6640625,5.66995584637687E-5,7.84543952250196E-7,1,0.999253354069792,40.0298881530762,1.98130593920663,15.5600002035499,0.000641126276690055,8.26151774957112E-5,0.25,-2.46248115598743E-6,5.66995059377412E-5,-2.42482581035822E-6,299.9978943,299.9978943,6961.94970703125,6977.37841796875,57.2417829773522,20.6873753763406,24.047956,0,0,0,40,4449,300.22445,6969.6640625,,,,,,,,,,,,,0,,,,0.00245,,,,,,299.9978943,,,,
,29221562.98,300.0021057,11673.3408203125,3.39619621094647E-5,1.19544046767007E-6,1,0.999253354069792,40.0298881530762,1.9813833170915,15.5600002035499,0.0003879175241026,2.70882508674789E-5,0.25,-3.47065885897663E-6,3.39632480757745E-5,-3.44806326357897E-6,300.0021057,300.0021057,11670.9033203125,11675.7783203125,57.4840878183138,20.6849478545626,23.288654,0,0,0,40,4449,300.2341,11673.3408203125,,,,,,,,,,,,,0,,,,0,,,,,,300.0021057,,,,
,29221659.57,299.9987183,16500.7998046875,8.0871740990279E-6,1.71216550522456E-6,1,0.999253354069792,40.0298881530762,1.9813638577099,15.5600002035499,0.000103608361718606,-5.84040995851807E-5,0.25,-6.60499747605484E-6,8.09130506795679E-6,-6.59945018243142E-6,299.9987183,299.9987183,16493.283203125,16508.31640625,57.5341120435445,20.6873122276643,23.668306,0,0,0,40,4449,300.2172,16500.7998046875,,,,,,,,,,,,,0,,,,0,,,,,,299.9987183,,,,
,29221757.87,300.0074463,21410.2626953125,-2.5044518662655E-5,2.66921597189645E-6,1,0.999253354069792,40.0298881530762,1.98153121335922,15.5600002035499,-0.000266425296027334,-0.000133429396709893,0.25,-7.54849865409398E-6,-2.50387795373165E-5,-7.56482978008866E-6,300.0071106,300.007782,21405.55859375,21414.966796875,57.3981086811984,20.6831490080394,23.668306,0,0,0,40,4449,300.2145,21410.2626953125,,,,,,,,,,,,,0,,,,0,,,,,,300.0074463,,,,
,29221857.03,300.0074463,26367.958984375,-5.52272414309202E-5,2.83813405215153E-6,1,0.999253354069792,40.0298881530762,1.9814167588417,15.5600002035499,-0.000594242733305614,-0.000255178007027617,0.25,-1.31673745751162E-5,-5.52168974412796E-5,-1.32034549036582E-5,300.0074463,300.0074463,26367.958984375,26367.958984375,57.5677220698715,20.6850985889414,23.668306,0,0,0,40,4449,300.2152,26367.958984375,,,,,,,,,,,,,0,,,,-0.0049,,,,,,300.0074463,,,,
,29221954.705,300.0100098,31251.3896484375,-9.44423810845722E-5,3.89415818010373E-6,1,0.999253354069792,40.0298881530762,1.98143786810438,15.5600002035499,-0.00102491852824256,-0.000386091830137532,0.25,-1.80369625990136E-5,-9.44276591282126E-5,-1.80987353364235E-5,300.0100098,300.0100098,31246.361328125,31256.41796875,57.616964666583,20.6854466035606,23.288654,0,0,0,40,4449,300.19595,31251.3896484375,,,,,,,,,,,,,0,,,,0.0049,,,,,,300.0100098,,,,
,29222054.385,300.0082092,36231.193359375,-0.000127491913767939,5.13904985088303E-6,1,0.999253354069792,40.0298881530762,1.9819639516422,15.5600002035499,-0.0013823332740016,-0.000530572655316966,0.25,-2.51718509399204E-5,-0.000127471530690558,-2.52551305502801E-5,300.0082092,300.0082092,36223.609375,36238.77734375,57.7037254322177,20.6805350087292,23.668306,0,0,0,40,4449,300.1861,36231.193359375,,,,,,,,,,,,,0,,,,-0.0049,,,,,,300.0082092,,,,
,29222156.15,300.0138855,41318.787109375,-0.000171482331198673,4.81055392973636E-6,1,0.999253354069792,40.0298881530762,1.98117350672757,15.5600002035499,-0.00186535660138328,-0.000674325979853673,0.25,-3.03780591765607E-5,-0.000171457206792103,-3.04900472449052E-5,300.0138855,300.0138855,41316.3125,41321.26171875,57.5817913832176,20.6887387246567,23.668306,0,0,0,40,4449,300.1778,41318.787109375,,,,,,,,,,,,,0,,,,0.0049,,,,,,300.0138855,,,,
,29222255.86,300.0084534,46301.626953125,-0.000210587888457395,8.31243319663115E-6,1,0.999253354069792,40.0298881530762,1.98107736976559,15.5600002035499,-0.00230017748069608,-0.000772986748875566,0.25,-3.2397676061151E-5,-0.000210560344498298,-3.25352025854934E-5,300.0084534,300.0084534,46299.0859375,46304.16796875,57.5880444113715,20.6911836689411,23.288654,0,0,0,40,4449,300.1694,46301.626953125,,,,,,,,,,,,,0,,,,-0.0049,,,,,,300.0084534,,,,
,29222357.155,300.0166931,51366.384765625,-0.000278155640682282,9.04224164190994E-6,1,0.999253354069792,40.0298881530762,1.98113097633063,15.5600002035499,-0.00300881667818503,-0.00119105560943289,0.25,-5.79439876692524E-5,-0.000278109275728183,-5.81249670796412E-5,300.0166931,300.0166931,51361.41796875,51371.3515625,57.525514129833,20.6891313684203,23.288654,0,0,0,40,4449,300.1588,51366.384765625,,,,,,,,,,,,,0,,,,-0.00245,,,,,,300.0166931,,,,
,29222456.96,300.0086365,56353.875,-0.000317508019298001,9.17407113562501E-6,1,0.999253354069792,40.0298881530762,1.98106125796042,15.5600002035499,-0.00342818340618059,-0.0013952750954011,0.25,-6.9328498023182E-5,-0.000317453168861825,-6.95347660743759E-5,300.0086365,300.0086365,56348.87109375,56358.87890625,57.1917587521214,20.6895888114065,23.288654,0,0,0,40,4449,300.1535,56353.875,,,,,,,,,,,,,0,,,,-0.0049,,,,,,300.0086365,,,,
,29222555.905,300.0079956,61298.974609375,-0.000384217049700188,1.41429207896498E-5,1,0.999253354069792,40.0298881530762,1.98104293951014,15.5600002035499,-0.00418003704337102,-0.00150589314101113,0.25,-6.76299924277119E-5,-0.000384161433668284,-6.78797865819387E-5,300.0079956,300.0079956,61291.38671875,61306.5625,57.3785679682176,20.6889080762364,23.288654,0,0,0,40,4449,300.1463,61298.974609375,,,,,,,,,,,,,0,,,,0,,,,,,300.0079956,,,,
,29222654.925,300.007782,66249.2890625,-0.000431300926972568,1.78314268910301E-5,1,0.999253354069792,40.0298881530762,1.98101233457976,15.5600002035499,-0.00466694802594686,-0.00183622787421031,0.25,-8.89128240916534E-5,-0.00043123008166785,-8.91925193650323E-5,300.007782,300.007782,66244.171875,66254.40625,57.5497446139292,20.6906336430996,23.668306,0,0,0,40,4449,300.1354,66249.2890625,,,,,,,,,,,,,0,,,,0.0049,,,,,,300.007782,,,,
,29222754.335,300.0098877,71217.02734375,-0.00045752181013864,1.62030896526051E-5,1,0.999253354069792,40.0298881530762,1.98096690410922,15.5600002035499,-0.0048793781517879,-0.00235872006628125,0.25,-0.000130937060755433,-0.000457422791622903,-0.000131232320766253,300.0098877,300.0098877,71212.1953125,71221.859375,57.5575608991215,20.6905310000911,24.047956,0,0,0,40,4449,300.12775,71217.02734375,,,,,,,,,,,,,0,,,,0,,,,,,300.0098877,,,,
,29222854.32,300.0129089,76215.5546875,-0.000579503237441823,1.7156223798063E-5,1,0.999253354069792,40.0298881530762,1.98113476949543,15.5600002035499,-0.00617700734484119,-0.00300964570862202,0.25,-0.00016779123669504,-0.000579376659980142,-0.000168164691343617,300.0129089,300.0129089,76210.640625,76220.46875,57.3285437429868,20.6863868160159,23.288654,0,0,0,40,4449,300.11445,76215.5546875,,,,,,,,,,,,,0,,,,-0.0049,,,,,,300.0129089,,,,
,29222954.085,300.0135803,81203.8984375,-0.000620531719543507,1.86503222772727E-5,1,0.999253354069792,40.0298881530762,1.98124133484942,15.5600002035499,-0.00659795168520588,-0.00331943638170062,0.25,-0.000188273823073596,-0.000620390749883479,-0.000188672960292555,300.0135803,300.0135803,81199,81208.796875,57.2480360055061,20.6859896284326,23.668306,0,0,0,40,4449,300.1107,81203.8984375,,,,,,,,,,,,,0,,,,0,,,,,,300.0135803,,,,
,29223049.87,300.01438905,85991.6328125,-0.000650317135414043,1.79025022016331E-5,1,0.999253354069792,40.0298881530762,1.98107713821785,15.5600002035499,-0.0069448318860576,-0.00330114509639483,0.25,-0.000181507448115627,-0.000650179868151154,-0.000181925718763125,300.0138855,300.0148926,85981.484375,86001.78125,57.075296102756,20.6898778758334,24.047956,0,0,0,40,4449,300.09055,85991.6328125,,,,,,,,,,,,,0,,,,0,,,,,,300.01438905,,,,
,29223160.97,300.0143127,89371.69140625,-0.000703841851015594,2.20293343858745E-5,1,0.999253354069792,40.0298881530762,1.98097576115349,15.5600002035499,-0.00748499031513096,-0.00375203558400006,0.25,-0.000212431106115582,-0.000703683029369692,-0.000212882953387264,300.0143127,300.0143127,89366.5,89376.8828125,57.3902923960061,20.6893746423089,23.668306,0,0,0,40,4449,300.0824,89371.69140625,,,,,,,,,,,,,0,,,,-0.0049,,,,,,300.0143127,,,,
,29223254.705,300.0045471,84689.40234375,-0.000648218223754441,2.00676165324375E-5,1,0.999253354069792,40.0298881530762,1.98106998897597,15.5600002035499,-0.00687318201930261,-0.00357454242286348,0.25,-0.000206235033870033,-0.000648065071473594,-0.000206651451860957,300.0045471,300.0045471,84684.5546875,84694.25,57.3785679682176,20.6898085486246,23.288654,0,0,0,40,4449,300.0743,84689.40234375,,,,,,,,,,,,,0,,,,0,,,,,,300.0045471,,,,
,29223355.28,299.9977417,79660.4375,-0.000551329090598078,1.7720533406743E-5,1,0.999253354069792,40.0298881530762,1.98118452458072,15.5600002035499,-0.00592129956451334,-0.00260677377532822,0.25,-0.000136766983757677,-0.000551223986798606,-0.00013712277020753,299.9977417,299.9977417,79650.578125,79670.296875,57.5161345876022,20.6881577483759,23.668306,0,0,0,40,4449,300.07495,79660.4375,,,,,,,,,,,,,0,,,,0.00245,,,,,,299.9977417,,,,
,29223455.475,299.9914856,74652,-0.000528476678487317,1.54567740326738E-5,1,0.999253354069792,40.0298881530762,1.9810893551198,15.5600002035499,-0.00562478920256664,-0.00279190641162388,0.25,-0.000157233884075628,-0.000528358831783582,-0.000157574623533799,299.9914856,299.9914856,74642.1484375,74661.8515625,57.2667950899676,20.6892911349554,23.668306,0,0,0,40,4449,300.08635,74652,,,,,,,,,,,,,0,,,,-0.00245,,,,,,299.9914856,,,,
,29223553.94,299.9912415,69729,-0.000478049286046343,1.98757994458331E-5,1,0.999253354069792,40.0298881530762,1.98118135341278,15.5600002035499,-0.00508049670545346,-0.00257062215441101,0.25,-0.000146240834313636,-0.000477939922281198,-0.000146549307657235,299.9912415,299.9912415,69724.1328125,69733.8671875,57.4864327038715,20.6891542121103,23.668306,0,0,0,40,4449,300.1022,69729,,,,,,,,,,,,,0,,,,-0.00245,,,,,,299.9912415,,,,
,29223651.195,299.9901733,64868.35546875,-0.000412070092444001,1.16327528155051E-5,1,0.999253354069792,40.0298881530762,1.98117131538267,15.5600002035499,-0.00442756795574512,-0.00193708397792838,0.25,-0.000101218964808114,-0.000411991980235521,-0.000101485883222209,299.9901733,299.9901733,64860.9375,64875.7734375,57.3754414541407,20.6889026950293,23.288654,0,0,0,40,4449,300.11945,64868.35546875,,,,,,,,,,,,,0,,,,-0.0049,,,,,,299.9901733,,,,
,29223750.025,299.9848633,59925.57421875,-0.000355888037048533,1.36589906322801E-5,1,0.999253354069792,40.0298881530762,1.98126798255976,15.5600002035499,-0.0038366415712988,-0.00160059260062647,0.25,-8.09614045032109E-5,-0.000355824782052223,-8.11924067995209E-5,299.9848633,299.9848633,59918.23828125,59932.91015625,57.4051433378714,20.6871228887441,23.288654,0,0,0,40,4449,300.12385,59925.57421875,,,,,,,,,,,,,0,,,,0.00245,,,,,,299.9848633,,,,
,29223851.74,299.9930115,54842.701171875,-0.000312074096857309,1.24693378467995E-5,1,0.999253354069792,40.0298881530762,1.98130132282462,15.5600002035499,-0.00336141658176614,-0.00142054507661898,0.25,-7.25070126448686E-5,-0.000312017464717949,-7.27097592800088E-5,299.9930115,299.9930115,54830.09375,54855.30859375,57.4129596230638,20.6863387389942,23.668306,0,0,0,40,4449,300.12355,54842.701171875,,,,,,,,,,,,,0,,,,0.0049,,,,,,299.9930115,,,,
,29223949.34,299.9916687,49967.869140625,-0.000266860438200063,9.23874818315884E-6,1,0.999253354069792,40.0298881530762,1.98106921690828,15.5600002035499,-0.00287836327265161,-0.00118992432134752,0.25,-5.9803100145715E-5,-0.000266813404828953,-5.99767345834705E-5,299.9916687,299.9916687,49957.85546875,49977.8828125,57.6466665503138,20.6921498658007,23.288654,0,0,0,40,4449,300.1306,49967.869140625,,,,,,,,,,,,,0,,,,0,,,,,,299.9916687,,,,
,29224044.23,299.9825439,45222.654296875,-0.000219210466163489,1.05418113394619E-5,1,0.999253354069792,40.0298881530762,1.98134897999096,15.5600002035499,-0.00237086091326795,-0.000942192452600995,0.25,-4.5971027584946E-5,-0.000219173931173356,-4.61139095995691E-5,299.9825439,299.9825439,45215.20703125,45230.1015625,57.6255625802946,20.6881342752102,23.668306,0,0,0,40,4449,300.15355,45222.654296875,,,,,,,,,,,,,0,,,,-0.00245,,,,,,299.9825439,,,,
,29224144.125,299.9934998,40229.87109375,-0.000163144120521433,5.26658069678486E-6,1,0.999253354069792,40.0298881530762,1.98138912996737,15.5600002035499,-0.00176991594801415,-0.000670029026717719,0.25,-3.14335122450345E-5,-0.000163118659234073,-3.15400395459838E-5,299.9934998,299.9934998,40222.51953125,40237.22265625,57.6107116384292,20.6886815173789,23.288654,0,0,0,40,4449,300.15125,40229.87109375,,,,,,,,,,,,,0,,,,0,,,,,,299.9934998,,,,
,29224241.76,299.9847107,35349.771484375,-0.000119888056829351,4.39606646574933E-6,1,0.999253354069792,40.0298881530762,1.98154600513313,15.5600002035499,-0.00129651360230813,-0.000516800811691222,0.25,-2.52717571257969E-5,-0.000119867928620547,-2.53500653327797E-5,299.9834595,299.9859619,35339.796875,35359.74609375,57.4168677656599,20.6856089824736,23.288654,0,0,0,40,4449,300.1644,35349.771484375,,,,,,,,,,,,,0,,,,0,,,,,,299.9847107,,,,
,29224338.375,299.9894104,30519.6865234375,-8.30800714616651E-5,3.81054374597483E-6,1,0.999253354069792,40.0298881530762,1.9815964992272,15.5600002035499,-0.000897253968014999,-0.000365218010724775,0.25,-1.81432306052314E-5,-8.30656763328169E-5,-1.81975296113779E-5,299.9894104,299.9894104,30512.134765625,30527.23828125,57.545836471333,20.6841771715923,24.047956,0,0,0,40,4449,300.17625,30519.6865234375,,,,,,,,,,,,,0,,,,0,,,,,,299.9894104,,,,
,29224434.96,299.9819336,25694.470703125,-5.08701477191227E-5,2.79150491862469E-6,1,0.999253354069792,40.0298881530762,1.98157990131687,15.5600002035499,-0.000549499995545294,-0.000222967764842369,0.25,-1.10508087855807E-5,-5.08613748525468E-5,-1.10840955550169E-5,299.9819336,299.9819336,25689.421875,25699.51953125,57.434063593083,20.6860384289811,23.288654,0,0,0,40,4449,300.1688,25694.470703125,,,,,,,,,,,,,0,,,,-0.0049,,,,,,299.9819336,,,,
,29224533.125,299.9873657,20787.1806640625,-1.39963701535614E-5,1.71678101498498E-6,1,0.999253354069792,40.0298881530762,1.98146939896315,15.5600002035499,-0.00014146890459458,-0.000117398808626923,0.25,-8.03476063107779E-6,-1.3990648567625E-5,-8.04378117980745E-6,299.9873657,299.9873657,20782.248046875,20792.11328125,57.5669404413522,20.6886027171768,23.668306,0,0,0,40,4449,300.187,20787.1806640625,,,,,,,,,,,,,0,,,,0.0049,,,,,,299.9873657,,,,
,29224627.555,299.9914246,16067.8237304687,1.53804571900452E-5,1.42664718110752E-6,1,0.999253354069792,40.0298881530762,1.98157544975586,15.5600002035499,0.000185630539921233,-4.50838553833652E-5,0.25,-6.68137113772564E-6,1.53844270538217E-5,-6.67099558641345E-6,299.9914246,299.9914246,16055.5087890625,16080.138671875,57.6114932669484,20.6876197399893,23.668306,0,0,0,40,4449,300.20015,16067.8237304687,,,,,,,,,,,,,0,,,,-0.0049,,,,,,299.9914246,,,,
,29224722.57,299.9855957,11320.1948242187,4.05391152049301E-5,1.29924969021763E-6,1,0.999253354069792,40.0298881530762,1.98163823703573,15.5600002035499,0.000466133051601137,1.48307918678032E-5,0.25,-5.70251135854804E-6,4.0541707468596E-5,-5.67549172366389E-6,299.9855957,299.9855957,11312.8125,11327.5771484375,57.4903408464676,20.6860463011452,23.668306,0,0,0,40,4449,300.2035,11320.1948242187,,,,,,,,,,,,,0,,,,-0.0049,,,,,,299.9855957,,,,
,29224818.8,299.9902344,6509.986328125,5.94900785719734E-5,6.73384669742103E-7,1,0.999253354069792,40.0298881530762,1.98153017104026,15.5600002035499,0.000674152551756941,7.86116525781607E-5,0.25,-3.3034540204524E-6,5.94905167811266E-5,-3.26392083261734E-6,299.9897461,299.9907227,6499.77294921875,6520.19970703125,57.6318156084484,20.6866992876833,23.668306,0,0,0,40,4449,300.2168,6509.986328125,,,,,,,,,,,,,0,,,,-0.00735,,,,,,299.9902344,,,,
,29224913.305,299.9930725,1786.87768554687,4.76737527430349E-5,4.55620519063785E-7,1,0.999253354069792,40.0298881530762,1.98146980181919,15.5600002035499,0.000537308647341362,7.98679386089284E-5,0.25,-1.1440501426387E-6,4.76731011383213E-5,-1.11239207015802E-6,299.9930725,299.9930725,1781.7587890625,1791.99658203125,57.6810582051599,20.6891897036124,23.668306,0,0,0,40,4449,300.218,1786.87768554687,,,,,,,,,,,,,0,,,,-0.0049,,,,,,299.9930725,,,,
,29229637.53,10.0004911,-0.3349229991436,,,2,,,,16.6600003299117,,,,,,,10.0004911,10.0004911,-0.3349229991436,-0.3349229991436,,,12.658426,,,,-99999999,4369,10.0001,-0.3349229991436,,,,,,,,,,,,,,,,,,,,,,,10.0004911,,,,