File: data/looselyPackedNP/sc-ios-7/ppms/rawdata/ES_S17_HYST_20K.DAT
[Header]
; VSM Data File (default extension .dat)
; Copyright (c) 2003-2013, Quantum Design, Inc. All rights reserved.
TITLE,
FILEOPENTIME,29241079.86,12/05/2018,6:32 pm
BYAPP,VSM,2.0,2.0
INFO,PPMS VSM Option Release 1.4.10 Build 1,APPNAME
INFO,Quantum Design Linear Motor Servo Controller,MOTOR_MODULE_NAME
INFO,3101-100 M1,MOTOR_HW_VERSION
INFO,MMC1014,MOTOR_SERIAL_NUMBER
INFO,SRV No X-over 01.03.11,MOTOR_SOFTWARE_VERSION
INFO,Quantum Design VSM Detection Module,VSM_MODULE_NAME
INFO,3101-150 F0,VSM_HW_VERSION
INFO,VSM707,VSM_SERIAL_NUMBER
INFO,VSM No X-over 01.02.05 May 20 2008 13:51:47,VSM_SOFTWARE_VERSION
INFO,704,PREAMP_SERIAL_NUMBER
INFO,822,COIL_SERIAL_NUMBER
INFO,0,MOMENT_UNITS
INFO,Iron Oxide Spheres,SAMPLE_MATERIAL
INFO,7 nm diameter, collaboration Mainz,SAMPLE_COMMENT
INFO,,SAMPLE_MASS
INFO,,SAMPLE_VOLUME
INFO,,SAMPLE_MOLECULAR_WEIGHT
INFO,,SAMPLE_SIZE
INFO,,SAMPLE_SHAPE
DATATYPE,COMMENT,1
DATATYPE,TIME,2
STARTUPAXIS,X,2
STARTUPAXIS,Y1,5
[Data]
Comment,Time Stamp (sec),Temperature (K),Magnetic Field (Oe),Moment (emu),M. Std. Err. (emu),Transport Action,Averaging Time (sec),Frequency (Hz),Peak Amplitude (mm),Center Position (mm),Coil Signal' (mV),Coil Signal" (mV),Range (mV),M. Quad. Signal (emu),M. Raw' (emu),M. Raw" (emu),Min. Temperature (K),Max. Temperature (K),Min. Field (Oe),Max. Field (Oe),Mass (grams),Motor Lag (deg),Pressure (Torr),VSM Status (code),Motor Status (code),Measure Status (code),Measure Count,PPMS Status (code),System Temp. (K),System Field (Oe),Sample Position (deg),Bridge 1 Resistance (ohms),Bridge 1 Excitation (에),Bridge 2 Resistance (ohms),Bridge 2 Excitation (에),Bridge 3 Resistance (ohms),Bridge 3 Excitation (에),Bridge 4 Resistance (ohms),Bridge 4 Excitation (에),Signal 1 Vin (V),Signal 2 Vin (V),Digital Inputs (code),Drive 1 Iout (mA),Drive 1 Ipower (W),Drive 2 Iout (mA),Drive 2 Ipower (W),Pressure (),Map 20 (),Map 21 (),Map 22 (),Map 23 (),Map 24 (),Map 25 (),Map 26 (),Map 27 (),Map 28 (),Map 29 ()
,29241095.81,19.9972305,-0.319699227809906,,,2,,,,17.0599996504188,,,,,,,19.9972305,19.9972305,-0.319699227809906,-0.319699227809906,,,12.658426,,,,-99999999,4369,20.0152,-0.319699227809906,,,,,,,,,,,,,,,,,,,,,,,19.9972305,,,,
,29241367.825,20.012928,4358.7177734375,9.98093624319294E-5,3.49854925241044E-7,1,0.999253354069792,40.0298881530762,1.97508291326918,17.0499999076128,0.00111515905701421,0.000167321473665007,0.25,-2.70490357054763E-6,9.92723904305586E-5,-2.18054632315682E-6,20.012928,20.012928,4355.984375,4361.451171875,57.8045555111984,20.7807321802081,13.038077,0,0,0,40,4449,19.87785,4358.7177734375,,,,,,,,,,,,,0,,,,0.00245,,,,,,20.012928,,,,
,29241464.375,20.03514195,9182.220703125,7.36816800671998E-5,5.24946641431872E-7,1,0.999253354069792,40.0298881530762,1.97489940702771,17.0499999076128,0.000824209215510899,0.000119377555278726,0.25,-2.39818875772874E-6,7.33140752650271E-5,-1.98398353755118E-6,20.0300236,20.0402603,9176.57421875,9187.8671875,57.5419283287369,20.781071222928,12.658426,0,0,0,40,4449,19.9101,9182.220703125,,,,,,,,,,,,,0,,,,-0.00245,,,,,,20.03514195,,,,
,29241565.29,19.9959469,14224.7094726563,4.96706383927652E-5,8.30010576425946E-7,1,0.999253354069792,40.0298881530762,1.97645990432557,17.0499999076128,0.000560939007651274,5.45146059343254E-5,0.25,-3.97517685265541E-6,4.94582839899717E-5,-3.66726215713176E-6,19.9959469,19.9959469,14214.6884765625,14234.73046875,57.7357722015061,20.7609171842093,12.658426,0,0,0,40,4449,19.93385,14224.7094726563,,,,,,,,,,,,,0,,,,-0.00245,,,,,,19.9959469,,,,
,29241665.625,19.989296,19241.6240234375,1.13305575989984E-5,6.42613688858409E-7,1,0.999253354069792,40.0298881530762,1.97667164954299,17.0499999076128,0.000136199734799534,-3.31834503436311E-5,0.25,-5.00651736831324E-6,1.13129595873734E-5,-4.91529198174413E-6,19.989296,19.989296,19237.0625,19246.185546875,57.931960959833,20.7643571285342,13.417728,0,0,0,40,4449,19.911,19241.6240234375,,,,,,,,,,,,,0,,,,0.0049,,,,,,19.989296,,,,
,29241764.77,20.0387287,24194.7138671875,-2.17190679339791E-5,1.76101224833371E-6,1,0.999253354069792,40.0298881530762,1.97644618118997,17.0499999076128,-0.000227659171575078,-0.00012351813888678,0.25,-7.19086652089286E-6,-2.15903389514655E-5,-7.3041016065774E-6,20.0387287,20.0387287,24189.2109375,24200.216796875,57.6537012069869,20.7665452257714,13.038077,0,0,0,40,4449,19.92675,24194.7138671875,,,,,,,,,,,,,0,,,,-0.0049,,,,,,20.0387287,,,,
,29241858.235,19.9908829,28867.486328125,-4.13634255491004E-5,1.67934810990494E-6,1,0.999253354069792,40.0298881530762,1.97666565007569,17.0499999076128,-0.000439057641045818,-0.0002060236967671,0.25,-1.1052509959657E-5,-4.1152470692956E-5,-1.12938745720908E-5,19.9908829,19.9908829,28857.712890625,28877.259765625,57.4317187075253,20.7625143791748,13.038077,0,0,0,40,4449,19.92345,28867.486328125,,,,,,,,,,,,,0,,,,-0.00245,,,,,,19.9908829,,,,
,29241954.46,19.9962521,33677.36328125,-7.2096538650868E-5,2.01656915309216E-6,1,0.999253354069792,40.0298881530762,1.97679852898341,17.0499999076128,-0.000779774917675667,-0.000280830433043682,0.25,-1.22150408696305E-5,-7.18099885036335E-5,-1.26809744472398E-5,19.9962521,19.9962521,33665.08203125,33689.64453125,57.4895592179484,20.7637646565095,13.417728,0,0,0,40,4449,19.9181,33677.36328125,,,,,,,,,,,,,0,,,,0,,,,,,19.9962521,,,,
,29242050.785,19.9933624,38489.6953125,-0.000106047054321591,2.11406134554911E-6,1,0.999253354069792,40.0298881530762,1.97528074071881,17.0499999076128,-0.00114199766419834,-0.000439025234970975,0.25,-2.02843199977854E-5,-0.000105659972896367,-2.09923321349958E-5,19.9933624,19.9933624,38482.25390625,38497.13671875,57.7091968318523,20.7837195189253,13.038077,0,0,0,40,4449,19.9391,38489.6953125,,,,,,,,,,,,,0,,,,0,,,,,,19.9933624,,,,
,29242146.04,19.969593,43252.43359375,-0.00011110613226029,2.90586218818077E-6,1,0.999253354069792,40.0298881530762,1.9769115431467,17.0499999076128,-0.00120721199710962,-0.000409363303912148,0.25,-1.66527420404405E-5,-0.000110786761805486,-1.74284418380108E-5,19.969593,19.969593,43244.85546875,43260.01171875,57.8162799389869,20.7628627470335,13.417728,0,0,0,40,4449,19.92495,43252.43359375,,,,,,,,,,,,,0,,,,-0.00245,,,,,,19.969593,,,,
,29242243.725,19.97897815,48132.63671875,-0.000174491385202159,3.18182741408377E-6,1,0.999253354069792,40.0298881530762,1.97685216302888,17.0499999076128,-0.0019202084034913,-0.000513259008422319,0.25,-1.45048340763975E-5,-0.000174161033126838,-1.57685653104354E-5,19.9754028,19.9825535,48127.68359375,48137.58984375,57.8686490497754,20.7599994112978,12.658426,0,0,0,40,4449,19.9395,48132.63671875,,,,,,,,,,,,,0,,,,0,,,,,,19.97897815,,,,
,29242337.045,19.9675245,52798.041015625,-0.000188381767517297,2.66534788565683E-6,1,0.999253354069792,40.0298881530762,1.97679634843426,17.0499999076128,-0.00207614994798115,-0.000542312217769854,0.25,-1.4570690093472E-5,-0.00018812089723865,-1.59546480102751E-5,19.9661865,19.9688625,52790.4609375,52805.62109375,58.0882866636792,20.7592214409995,13.038077,0,0,0,40,4449,19.92095,52798.041015625,,,,,,,,,,,,,0,,,,0.00245,,,,,,19.9675245,,,,
,29242432.155,19.9545746,57552.96875,-0.00021701039845346,2.36084337939498E-6,1,0.999253354069792,40.0298881530762,1.97622085125213,17.0499999076128,-0.0024058742365239,-0.000548453872408873,0.25,-9.94582961621386E-6,-0.000216860900220177,-1.15567741149816E-5,19.9545746,19.9545746,57543.05078125,57562.88671875,57.6216544376984,20.7663463373409,13.417728,0,0,0,40,4449,19.8858,57552.96875,,,,,,,,,,,,,0,,,,0.00245,,,,,,19.9545746,,,,
,29242527.55,19.981657,62318.1328125,-0.000253723842741108,2.46089360022867E-6,1,0.999253354069792,40.0298881530762,1.9759289737564,17.0499999076128,-0.0027835490964019,-0.000809020846649997,0.25,-2.66156151614924E-5,-0.000253550869228785,-2.85061425958485E-5,19.9810104,19.9823036,62310.55078125,62325.71484375,57.677931691083,20.7699105876932,13.038077,0,0,0,40,4449,19.9087,62318.1328125,,,,,,,,,,,,,0,,,,0,,,,,,19.981657,,,,
,29242618.515,20.0052605,66866.4921875,-0.00030455536981332,2.97689229777303E-6,1,0.999253354069792,40.0298881530762,1.97586462356394,17.0499999076128,-0.00336406426061525,-0.000851683843217556,0.25,-2.12474960439622E-5,-0.000304551933011909,-2.3517644863336E-5,20.0052605,20.0052605,66853.984375,66879,57.5450548428138,20.770819792795,13.038077,0,0,0,40,4449,19.93065,66866.4921875,,,,,,,,,,,,,0,,,,0.00245,,,,,,20.0052605,,,,
,29242713.605,20.0112629,71619.2109375,-0.000362154423481755,2.9205791625358E-6,1,0.999253354069792,40.0298881530762,1.98583637181381,17.0499999076128,-0.00399627070133077,-0.00115652177281851,0.25,-3.75965837995799E-5,-0.00036220712556549,-4.03014991408586E-5,20.0112629,20.0112629,71611.8125,71626.609375,57.8123717963907,20.7863751089514,12.658426,0,0,0,40,4449,19.9215,71619.2109375,,,,,,,,,,,,,0,,,,0,,,,,,20.0112629,,,,
,29242812.125,19.9895191,76544.77734375,-0.00033388456364757,3.14128302795331E-6,1,0.999253354069792,40.0298881530762,1.98741300793211,17.0499999076128,-0.0037019351827077,-0.000993442472015703,0.25,-2.81082922604837E-5,-0.000334115793168795,-3.05854171968696E-5,19.9895191,19.9895191,76534.6484375,76554.90625,57.7240477737176,20.765873178719,13.417728,0,0,0,40,4449,19.9245,76544.77734375,,,,,,,,,,,,,0,,,,0,,,,,,19.9895191,,,,
,29242911.47,19.986454,81508.22265625,-0.000390414370850215,4.10918381692403E-6,1,0.999253354069792,40.0298881530762,1.98762216910979,17.0499999076128,-0.00430160477846197,-0.00132436748798204,0.25,-4.72979409882885E-5,-0.000390729988908611,-5.01988832262062E-5,19.986454,19.986454,81503.15625,81513.2890625,57.8491083367946,20.7669643833554,13.417728,0,0,0,40,4449,19.9315,81508.22265625,,,,,,,,,,,,,0,,,,-0.0049,,,,,,19.986454,,,,
,29243009.065,20.0866032,86388.578125,-0.000524644536440735,2.39572365389964E-6,1,0.999253354069792,40.0298881530762,1.98707024397347,17.0499999076128,-0.00588052127632543,-0.00122720198194017,0.25,-1.45499128668266E-5,-0.000525605919789212,-1.83211458773824E-5,20.0866032,20.0866032,86375.765625,86401.390625,57.5169162161215,20.7670217612256,12.658426,0,0,0,40,4449,19.9312,86388.578125,,,,,,,,,,,,,0,,,,0,,,,,,20.0866032,,,,
,29243121.855,20.0852871,88999.76953125,-0.000464704160198732,3.17697105466752E-6,1,0.999253354069792,40.0298881530762,1.98594262420296,17.0499999076128,-0.00515792040589841,-0.00135822259335096,0.25,-3.70350371007864E-5,-0.000465467498458997,-4.04053627335578E-5,20.0852871,20.0852871,88997.4296875,89002.109375,57.9327425883523,20.7736884439075,13.417728,0,0,0,40,4449,19.9267,88999.76953125,,,,,,,,,,,,,0,,,,-0.0049,,,,,,20.0852871,,,,
,29243214.41,19.9836788,84374.25,-0.000395075999052331,3.85056167841234E-6,1,0.999253354069792,40.0298881530762,1.98780157107681,17.0499999076128,-0.00439754724321719,-0.00110007573394196,0.25,-2.65391294902356E-5,-0.000395632444775244,-2.94229071594158E-5,19.9836788,19.9836788,84368.9765625,84379.5234375,57.5591241561599,20.757185679001,13.417728,0,0,0,40,4449,19.93115,84374.25,,,,,,,,,,,,,0,,,,-0.0049,,,,,,19.9836788,,,,
,29243306,19.9887409,79795.19140625,-0.00040814488857946,3.50953406266156E-6,1,0.999253354069792,40.0298881530762,1.98759320900426,17.0499999076128,-0.00453868465113635,-0.00114896806963562,0.25,-2.85358962622722E-5,-0.000408573206745773,-3.15420720276884E-5,19.9887409,19.9887409,79785.15625,79805.2265625,57.3136928011214,20.7572204398517,13.417728,0,0,0,40,4449,19.92885,79795.19140625,,,,,,,,,,,,,0,,,,0,,,,,,19.9887409,,,,
,29243395.695,19.9939842,75311.7421875,-0.000393658716726421,4.0063927419971E-6,1,0.999253354069792,40.0298881530762,1.98792991251241,17.0499999076128,-0.0043859599182442,-0.00105696053659285,0.25,-2.2963219093328E-5,-0.000393967113512091,-2.58753723378719E-5,19.9939842,19.9939842,75306.6796875,75316.8046875,57.6325972369676,20.7571248390717,12.658426,0,0,0,40,4449,19.9346,75311.7421875,,,,,,,,,,,,,0,,,,0,,,,,,19.9939842,,,,
,29243485.635,19.9800434,70815.54296875,-0.000335827942326535,3.33457722371095E-6,1,0.999253354069792,40.0298881530762,1.98789358944534,17.0499999076128,-0.00369698519792564,-0.00114112617484653,0.25,-4.08741961716369E-5,-0.000335809736267932,-4.33882051887066E-5,19.9800434,19.9800434,70808.2734375,70822.8125,57.93508747391,20.7639593208758,13.797379,0,0,0,40,4449,19.9404,70815.54296875,,,,,,,,,,,,,0,,,,0,,,,,,19.9800434,,,,
,29243578.115,19.9606075,66192.81640625,-0.00029561355880579,3.08278270313334E-6,1,0.999253354069792,40.0298881530762,1.98782484461543,17.0499999076128,-0.00322853089080687,-0.00113907500909493,0.25,-4.79690811073466E-5,-0.000295389665735921,-5.01849505486059E-5,19.9606075,19.9606075,66185.25,66200.3828125,57.7568761715253,20.7623385781809,13.038077,0,0,0,40,4449,19.9138,66192.81640625,,,,,,,,,,,,,0,,,,0,,,,,,19.9606075,,,,
,29243675.92,20.0341835,61302.009765625,-0.000300612336581605,2.58633426589528E-6,1,0.999253354069792,40.0298881530762,1.98645776440896,17.0499999076128,-0.0033549883472886,-0.000738288682236499,0.25,-1.15096639735061E-5,-0.000300527978526938,-1.37470759192821E-5,20.0341835,20.0341835,61296.99609375,61307.0234375,57.5419283287369,20.7783545715231,13.417728,0,0,0,40,4449,19.8413,61302.009765625,,,,,,,,,,,,,0,,,,-0.00245,,,,,,20.0341835,,,,
,29243774.6,19.9900513,56371.689453125,-0.000202899630305154,2.9279207016983E-6,1,0.999253354069792,40.0298881530762,1.9875669959927,17.0499999076128,-0.0022592463124136,-0.000528144372621678,0.25,-1.04208906097717E-5,-0.000202728585078509,-1.1924576920216E-5,19.9900513,19.9900513,56369.2109375,56374.16796875,57.90460396166,20.7670345918544,13.417728,0,0,0,40,4449,19.9397,56371.689453125,,,,,,,,,,,,,0,,,,0,,,,,,19.9900513,,,,
,29243873.795,19.9924755,51414.21875,-0.000199588409126551,2.63964826209734E-6,1,0.999253354069792,40.0298881530762,1.98770414044826,17.0499999076128,-0.00217789637942284,-0.000760932977624484,0.25,-3.17663111963935E-5,-0.000199163900128864,-3.32120447476383E-5,19.9924755,19.9924755,51411.6875,51416.75,57.8897530197946,20.7664211854654,13.038077,0,0,0,40,4449,19.9223,51414.21875,,,,,,,,,,,,,0,,,,0.0049,,,,,,19.9924755,,,,
,29243973.77,19.9916592,46417.001953125,-0.000160415407082949,1.85789447106628E-6,1,0.999253354069792,40.0298881530762,1.98780495771095,17.0499999076128,-0.00175491487854839,-0.000582115048519987,0.25,-2.29435527770178E-5,-0.000160013506155366,-2.40840763091426E-5,19.9916592,19.9916592,46414.546875,46419.45703125,57.8452001941984,20.7591494919188,13.038077,0,0,0,40,4449,19.9476,46417.001953125,,,,,,,,,,,,,0,,,,-0.00245,,,,,,19.9916592,,,,
,29244069.72,20.030798,41621.005859375,-0.000149958649702901,1.89613271380072E-6,1,0.999253354069792,40.0298881530762,1.98775251757248,17.0499999076128,-0.00166419973522802,-0.00040768842945323,0.25,-9.32881831545587E-6,-0.000149597614634891,-1.0391386705718E-5,20.030798,20.030798,41611.29296875,41630.71875,58.0585847799485,20.7671620946227,13.038077,0,0,0,40,4449,19.93,41621.005859375,,,,,,,,,,,,,0,,,,-0.00245,,,,,,20.030798,,,,
,29244166.42,19.9667072,36786.4296875,-0.000120149624724605,1.21301752561371E-6,1,0.999253354069792,40.0298881530762,1.9881769890247,17.0499999076128,-0.00133241287878974,-0.000329745228993668,0.25,-7.7771051384537E-6,-0.000119797985452626,-8.60568812972297E-6,19.9667072,19.9667072,36774.01171875,36798.84765625,57.7412436011407,20.7647628066964,13.417728,0,0,0,40,4449,19.9131,36786.4296875,,,,,,,,,,,,,0,,,,-0.00245,,,,,,19.9667072,,,,
,29244261.82,19.9618053,32019.298828125,-7.84701947492177E-5,2.32385301561437E-6,1,0.999253354069792,40.0298881530762,1.987707514789,17.0499999076128,-0.000858256284704297,-0.000278210070208048,0.25,-1.07134233426205E-5,-7.8163226344742E-5,-1.12203392200097E-5,19.9618053,19.9618053,32011.71484375,32026.8828125,57.6701154058907,20.7677146452563,13.038077,0,0,0,40,4449,19.9008,32019.298828125,,,,,,,,,,,,,0,,,,0,,,,,,19.9618053,,,,
,29244355.78,19.9914303,27324.29296875,-5.36170329106934E-5,1.4350595432402E-6,1,0.999253354069792,40.0298881530762,1.9877328350807,17.0499999076128,-0.000580399644112216,-0.000222132881016851,0.25,-1.01987511190023E-5,-5.33635290452395E-5,-1.05194009100342E-5,19.9914303,19.9914303,27314.4296875,27334.15625,57.6802765766407,20.7604317589428,13.038077,0,0,0,40,4449,19.92695,27324.29296875,,,,,,,,,,,,,0,,,,-0.0049,,,,,,19.9914303,,,,
,29244452.64,19.99050525,22483.8095703125,-6.28750108621887E-6,9.21856020351276E-7,1,0.999253354069792,40.0298881530762,1.98782804614524,17.0499999076128,-4.79946408339801E-5,-0.00013788950685171,0.25,-1.11818070527395E-5,-6.1914341280537E-6,-1.1177582310927E-5,19.9901276,19.9908829,22476.2421875,22491.376953125,57.8999141905446,20.7663714759408,13.038077,0,0,0,40,4449,19.93705,22483.8095703125,,,,,,,,,,,,,0,,,,0.00245,,,,,,19.99050525,,,,
,29244547.07,20.0121002,17764.0390625,1.20462752201182E-5,6.12071320525944E-7,1,0.999253354069792,40.0298881530762,1.98741790248408,17.0499999076128,0.000152201534860274,-7.27677382033522E-5,0.25,-8.65389026223534E-6,1.2045549626886E-5,-8.54261782748425E-6,20.0121002,20.0121002,17754.1328125,17773.9453125,57.8123717963907,20.7737754689067,13.417728,0,0,0,40,4449,19.9154,17764.0390625,,,,,,,,,,,,,0,,,,-0.00245,,,,,,20.0121002,,,,
,29244642.825,19.9979362,12979.1328125,4.27455046009919E-5,5.69037826507681E-7,1,0.999253354069792,40.0298881530762,1.98830565367242,17.0499999076128,0.000490629306912481,1.81016700548918E-5,0.25,-6.01392920696365E-6,4.25726397400179E-5,-5.73979243557742E-6,19.9979362,19.9979362,12976.7265625,12981.5390625,57.8647409071792,20.7630594416345,13.797379,0,0,0,40,4449,19.9434,12979.1328125,,,,,,,,,,,,,0,,,,0.00245,,,,,,19.9979362,,,,
,29244733.965,20.0961895,8421.4326171875,7.00197711860109E-5,4.95856361066666E-7,1,0.999253354069792,40.0298881530762,1.98626689825464,17.0499999076128,0.00078407219711342,0.000133331164351476,0.25,-5.51874155058539E-7,6.96568495876131E-5,-1.71014484621228E-7,20.0961895,20.0961895,8414.2978515625,8428.5673828125,58.0132503258331,20.7813208306811,13.417728,0,0,0,40,4449,19.94535,8421.4326171875,,,,,,,,,,,,,0,,,,0,,,,,,20.0961895,,,,
,29244829.25,19.9948921,3660.76586914063,9.87897358984364E-5,3.09323919183238E-7,1,0.999253354069792,40.0298881530762,1.98806774549394,17.0499999076128,0.00110797016536346,0.000181706148169405,0.25,-1.32650347495938E-6,9.8246974720641E-5,-8.19530004184788E-7,19.9948921,19.9948921,3650.91943359375,3670.6123046875,57.6263442088138,20.7617403690934,13.417728,0,0,0,40,4449,19.9377,3660.76586914063,,,,,,,,,,,,,0,,,,-0.0049,,,,,,19.9948921,,,,
,29244929.78,20.056282,-1362.36511230469,-8.23946248949911E-5,3.85832018689663E-7,1,0.999253354069792,40.0298881530762,1.98474559403871,17.0499999076128,-0.000920254462513198,-0.000163878806258551,0.25,-3.29960866139183E-8,-8.19252645160506E-5,-4.37403150583543E-7,20.056282,20.056282,-1364.9228515625,-1359.80737304688,58.0609296655062,20.7994861812938,13.417728,0,0,0,40,4449,19.9296,-1362.36511230469,,,,,,,,,,,,,0,,,,0,,,,,,20.056282,,,,
,29245027.345,19.9853954,-6236.70532226563,-9.03775230799598E-5,3.74757955943976E-7,1,0.999253354069792,40.0298881530762,1.98809957053766,17.0499999076128,-0.00101702958555745,-0.000148231010230624,0.25,2.84152277270396E-6,-8.99054128365777E-5,2.35278366084036E-6,19.9853954,19.9853954,-6246.7685546875,-6226.64208984375,57.9100753612946,20.7589163327913,13.417728,0,0,0,40,4449,19.92125,-6236.70532226563,,,,,,,,,,,,,0,,,,0,,,,,,19.9853954,,,,
,29245126.745,19.982708,-11207.1875,-6.41895426783898E-5,4.56105878912531E-7,1,0.999253354069792,40.0298881530762,1.98809988845487,17.0499999076128,-0.000726399700177772,-8.41553673056268E-5,0.25,3.93236602296028E-6,-6.38905463920397E-5,3.55309175604544E-6,19.982708,19.982708,-11214.630859375,-11199.744140625,58.0617112940254,20.7560324277823,13.417728,0,0,0,40,4449,19.9385,-11207.1875,,,,,,,,,,,,,0,,,,0,,,,,,19.982708,,,,
,29245230.665,19.99995325,-16399.498046875,-2.95275823856434E-5,7.07677929313261E-7,1,0.999253354069792,40.0298881530762,1.98835981803052,17.0499999076128,-0.000341312411318335,2.00782178053968E-7,0.25,5.29630865166533E-6,-2.94250572934163E-5,5.09590780971874E-6,19.9975891,20.0023174,-16406.919921875,-16392.076171875,58.0749989788523,20.7583385705457,12.658426,0,0,0,40,4449,19.9524,-16399.498046875,,,,,,,,,,,,,0,,,,0.0049,,,,,,19.99995325,,,,
,29245332.78,19.9967709,-21504.0625,-1.24370658821756E-5,5.82799844883945E-7,1,0.999253354069792,40.0298881530762,1.98820161111231,17.0499999076128,-0.000155493810484936,6.5208573134707E-5,0.25,8.04765187419497E-6,-1.24373835373103E-5,7.93659078617503E-6,19.9967709,19.9967709,-21508.97265625,-21499.15234375,58.0914131777561,20.763068264327,13.417728,0,0,0,40,4449,19.92805,-21504.0625,,,,,,,,,,,,,0,,,,0.0049,,,,,,19.9967709,,,,
,29245429.755,20.0245399,-26351.0673828125,9.16630251226515E-6,1.15991953460919E-6,1,0.999253354069792,40.0298881530762,1.98733494358566,17.0499999076128,0.000110069584915996,-2.26467627716483E-5,0.25,-3.66562488759436E-6,9.1577610910076E-6,-3.59217075839058E-6,20.0245399,20.0245399,-26360.982421875,-26341.15234375,57.9905830987754,20.7704353682842,13.797379,0,0,0,40,4449,19.8991,-26351.0673828125,,,,,,,,,,,,,0,,,,-0.00245,,,,,,20.0245399,,,,
,29245524.67,19.9891911,-31096.412109375,8.6493472226703E-5,1.44336619124556E-6,1,0.999253354069792,40.0298881530762,1.98421896030664,17.0499999076128,0.000949275638305973,0.000278621496437945,0.25,9.35613078276678E-6,8.61639647035038E-5,9.91769222271785E-6,19.9891911,19.9891911,-31098.8515625,-31093.97265625,57.7818882841407,20.8227697219098,13.417728,0,0,0,40,4449,19.9249,-31096.412109375,,,,,,,,,,,,,0,,,,0,,,,,,19.9891911,,,,
,29245623.055,20.0422783,-36013.634765625,0.000110277889140469,2.95221971726743E-6,1,0.999253354069792,40.0298881530762,1.98604194603855,17.0499999076128,0.00119896947709072,0.000428078440596228,0.25,1.83618910420624E-5,0.00010986742157728,1.9090087454037E-5,20.0422783,20.0422783,-36020.98828125,-36006.28125,57.5161345876022,20.7950585613661,13.038077,0,0,0,40,4449,19.9284,-36013.634765625,,,,,,,,,,,,,0,,,,0.00245,,,,,,20.0422783,,,,
,29245719.12,20.0309505,-40815.771484375,0.000116371708430804,1.43048196399823E-6,1,0.999253354069792,40.0298881530762,1.98680662225812,17.0499999076128,0.00127321618071549,0.000413700010531744,0.25,1.59332918970659E-5,0.000116019278787406,1.67368455195042E-5,20.0309505,20.0309505,-40828.44140625,-40803.1015625,58.1328394892754,20.7721235604151,13.417728,0,0,0,40,4449,19.87655,-40815.771484375,,,,,,,,,,,,,0,,,,0,,,,,,20.0309505,,,,
,29245812.24,19.9923401,-45466.455078125,0.000148412363572627,2.23056035615595E-6,1,0.999253354069792,40.0298881530762,1.98787521492418,17.0499999076128,0.00166269068083674,0.000320947861504725,0.25,1.85226241669667E-6,0.000148167688653524,2.93269812798646E-6,19.9923401,19.9923401,-45476.36328125,-45456.546875,57.9468119016984,20.7654021361577,13.038077,0,0,0,40,4449,19.91115,-45466.455078125,,,,,,,,,,,,,0,,,,-0.00245,,,,,,19.9923401,,,,
,29245901.32,20.0831547,-49921.478515625,0.000133427842868468,3.51572588929314E-6,1,0.999253354069792,40.0298881530762,1.98563872501182,17.0499999076128,0.00144774456261213,0.000544472313404447,0.25,2.44787028172632E-5,0.000133100418129567,2.54359127433706E-5,20.0831547,20.0831547,-49924.05859375,-49918.8984375,57.8069003967561,20.7936525004376,13.417728,0,0,0,40,4449,19.9285,-49921.478515625,,,,,,,,,,,,,0,,,,0,,,,,,20.0831547,,,,
,29245995.905,19.9863491,-54645.6875,0.000158746520078546,3.55205183486098E-6,1,0.999253354069792,40.0298881530762,1.98777920067347,17.0499999076128,0.00174536336054597,0.000535972359248161,0.25,1.90803722209936E-5,0.00015850494534481,2.02469924414739E-5,19.9863491,19.9863491,-54655.5703125,-54635.8046875,57.9085121042561,20.7686766357025,13.797379,0,0,0,40,4449,19.9238,-54645.6875,,,,,,,,,,,,,0,,,,0.00245,,,,,,19.9863491,,,,
,29246095.25,20.0491467,-59613.021484375,0.00018444158044556,3.14874721359972E-6,1,0.999253354069792,40.0298881530762,1.98768008697458,17.0499999076128,0.0020199350557621,0.000671829782771281,0.25,2.65098050185199E-5,0.000184216033653593,2.78785898376364E-5,20.0491467,20.0491467,-59623.0234375,-59603.01953125,58.0007442695254,20.7700100308282,13.417728,0,0,0,40,4449,19.8669,-59613.021484375,,,,,,,,,,,,,0,,,,0,,,,,,20.0491467,,,,
,29246193.705,19.9845657,-64532.9140625,0.000227826974904032,3.07315156929532E-6,1,0.999253354069792,40.0298881530762,1.98802569935895,17.0499999076128,0.00250375900891539,0.000790792890316816,0.25,2.9230248456003E-5,0.000227677980507686,3.0932369357132E-5,19.9845657,19.9845657,-64540.2890625,-64525.5390625,57.9991810124869,20.7678086404565,13.797379,0,0,0,40,4449,19.91885,-64532.9140625,,,,,,,,,,,,,0,,,,0.0049,,,,,,19.9845657,,,,
,29246293.28,20.1032696,-69507.21875,0.000303116392708271,4.00858907200449E-6,1,0.999253354069792,40.0298881530762,1.986550266586,17.0499999076128,0.00332471654205207,0.00108264697646109,0.25,4.1641231945136E-5,0.000303030674949089,4.39137792484849E-5,20.1032696,20.1032696,-69517.0625,-69497.375,58.0101238117561,20.7850263355116,13.038077,0,0,0,40,4449,19.9068,-69507.21875,,,,,,,,,,,,,0,,,,0,,,,,,20.1032696,,,,
,29246392.295,19.9808159,-74456.8828125,0.000317628036137975,4.17669010784276E-6,1,0.999253354069792,40.0298881530762,1.98844690436173,17.0499999076128,0.00351887894657177,0.000967432567689277,0.25,2.86876071177318E-5,0.000317780387827611,3.10514347074678E-5,19.9808159,19.9808159,-74464.3203125,-74449.4453125,57.9929279843331,20.7612372024223,13.417728,0,0,0,40,4449,19.90655,-74456.8828125,,,,,,,,,,,,,0,,,,0,,,,,,19.9808159,,,,
,29246492.11,19.9792175,-79443.62109375,0.000318290769036575,2.98600390901391E-6,1,0.999253354069792,40.0298881530762,1.98812184663499,17.0499999076128,0.00351661129795806,0.00102770971858181,0.25,3.39241938429898E-5,0.000318531468888305,3.62877342884438E-5,19.9792175,19.9792175,-79451.4765625,-79435.765625,57.80299225416,20.76895322314,13.417728,0,0,0,40,4449,19.9133,-79443.62109375,,,,,,,,,,,,,0,,,,-0.0049,,,,,,19.9792175,,,,
,29246591.54,20.0049419,-84413.23046875,0.000384254456528011,1.03004084679794E-5,1,0.999253354069792,40.0298881530762,1.98430962984409,17.0499999076128,0.00423955166095186,0.00123694953549402,0.25,4.0819174689185E-5,0.000384689019615559,4.3652154789986E-5,20.0049419,20.0049419,-84418.234375,-84408.2265625,57.9225814176023,20.8176072258696,13.417728,0,0,0,40,4449,19.9018,-84413.23046875,,,,,,,,,,,,,0,,,,0.0049,,,,,,20.0049419,,,,
,29246683.64,20.1127129,-89017.96484375,0.00049116324554449,4.70474220871023E-6,1,0.999253354069792,40.0298881530762,1.98525816393649,17.0499999076128,0.00543146622364522,0.00153708150996828,0.25,4.82045360960608E-5,0.000491906484518749,5.17866118217478E-5,20.1127129,20.1127129,-89020.65625,-89015.2734375,57.7326456874292,20.7984158262968,13.038077,0,0,0,40,4449,19.9278,-89017.96484375,,,,,,,,,,,,,0,,,,0.00245,,,,,,20.1127129,,,,
,29246791.58,19.9747219,-86674.640625,0.000404944052731044,4.57695739473143E-6,1,0.999253354069792,40.0298881530762,1.98768988252346,17.0499999076128,0.0044739328482678,0.00131635582796741,0.25,4.39654894298539E-5,0.000405460981542864,4.6941260130412E-5,19.9747219,19.9747219,-86684.8203125,-86664.4609375,58.1242415755638,20.7773231117624,13.797379,0,0,0,40,4449,19.9119,-86674.640625,,,,,,,,,,,,,0,,,,-0.00245,,,,,,19.9747219,,,,
,29246879.09,19.9859715,-82302.1015625,0.000357034752789736,3.14943046932115E-6,1,0.999253354069792,40.0298881530762,1.98740574270301,17.0499999076128,0.00395478830080505,0.00109365628953231,0.25,3.28337858815877E-5,0.000357419842372169,3.54658654267579E-5,19.9859715,19.9859715,-82312.203125,-82292,58.0359175528908,20.7837596574718,13.417728,0,0,0,40,4449,19.92645,-82302.1015625,,,,,,,,,,,,,0,,,,0.0049,,,,,,19.9859715,,,,
,29246974.795,19.9625759,-77519.671875,0.000305616058282317,3.01781896624131E-6,1,0.999253354069792,40.0298881530762,1.98780749475164,17.0499999076128,0.00338008083410918,0.000961387659150052,0.25,3.03343097221953E-5,0.000305817650238895,3.26054514197165E-5,19.9625759,19.9625759,-77525,-77514.34375,58.3524771031793,20.7664858533629,13.417728,0,0,0,40,4449,19.9114,-77519.671875,,,,,,,,,,,,,0,,,,0,,,,,,19.9625759,,,,
,29247073.99,20.0348969,-72562.28515625,0.00025575545075181,4.02171584011396E-6,1,0.999253354069792,40.0298881530762,1.98793233262921,17.0499999076128,0.00279003471622032,0.00101312809253517,0.25,4.39203181621241E-5,0.000255684968255425,4.58469461359936E-5,20.0348969,20.0348969,-72572.1953125,-72552.375,57.8960060479484,20.7706443944354,13.417728,0,0,0,40,4449,19.93975,-72562.28515625,,,,,,,,,,,,,0,,,,0,,,,,,20.0348969,,,,
,29247174.74,19.9853802,-67525.85546875,0.000250685376712616,4.19831284531378E-6,1,0.999253354069792,40.0298881530762,1.98762815324877,17.0499999076128,0.0027741142259456,0.000765107149848029,0.25,2.28272879379067E-5,0.000250657432566523,2.46986730428513E-5,19.9853802,19.9853802,-67530.8515625,-67520.859375,58.0179400969485,20.7780772670029,13.038077,0,0,0,40,4449,19.9073,-67525.85546875,,,,,,,,,,,,,0,,,,0,,,,,,19.9853802,,,,
,29247272.72,19.974575,-62628.4765625,0.000284925463964569,3.28099413562482E-6,1,0.999253354069792,40.0298881530762,1.98750941021037,17.0499999076128,0.00313880108998655,0.000939390813468733,0.25,3.21804633694298E-5,0.000284722311933204,3.43043888461643E-5,19.974575,19.974575,-62633.4765625,-62623.4765625,58.0421705810446,20.7667856967596,13.797379,0,0,0,40,4449,19.9159,-62628.4765625,,,,,,,,,,,,,0,,,,0.00245,,,,,,19.974575,,,,
,29247370.78,19.992033,-57731.001953125,0.000238321923580557,3.14142123792158E-6,1,0.999253354069792,40.0298881530762,1.98777067064109,17.0499999076128,0.00263434277753588,0.00073105321704507,0.25,2.20745651085284E-5,0.000238078875257229,2.38403454918231E-5,19.992033,19.992033,-57735.86328125,-57726.140625,58.0452970951215,20.773618992899,13.417728,0,0,0,40,4449,19.9185,-57731.001953125,,,,,,,,,,,,,0,,,,0,,,,,,19.992033,,,,
,29247467.64,19.9840679,-52888.701171875,0.000180925300355497,2.31584017557989E-6,1,0.999253354069792,40.0298881530762,1.98774217472124,17.0499999076128,0.00199263940797058,0.00058962141800152,0.25,1.98691578251174E-5,0.000180632810696694,2.11938975143457E-5,19.9840679,19.9840679,-52893.78125,-52883.62109375,58.0077789261985,20.7727325023516,13.797379,0,0,0,40,4449,19.9144,-52888.701171875,,,,,,,,,,,,,0,,,,0.00245,,,,,,19.9840679,,,,
,29247562.7,19.9677563,-48136.4765625,0.000144679288530691,1.93519882080258E-6,1,0.999253354069792,40.0298881530762,1.98770217154953,17.0499999076128,0.00157626383397362,0.000562242530740526,0.25,2.39979360592809E-5,0.000144317413135061,2.503040883659E-5,19.9677563,19.9677563,-48141.69140625,-48131.26171875,57.8686490497754,20.7688590207616,13.417728,0,0,0,40,4449,19.9126,-48136.4765625,,,,,,,,,,,,,0,,,,0.0049,,,,,,19.9677563,,,,
,29247656.525,19.9907017,-43446.76171875,9.99097479656201E-5,3.36559815336234E-6,1,0.999253354069792,40.0298881530762,1.98766424507797,17.0499999076128,0.00107451445123075,0.000462805723555033,0.25,2.32391744655957E-5,9.95645476493933E-5,2.39228636555764E-5,19.9907017,19.9907017,-43449.140625,-43444.3828125,57.6990356611023,20.7835888734611,13.038077,0,0,0,40,4449,19.9164,-43446.76171875,,,,,,,,,,,,,0,,,,0,,,,,,19.9907017,,,,
,29247753.55,19.96026325,-38599.322265625,9.54040884861232E-5,1.64311021399135E-6,1,0.999253354069792,40.0298881530762,1.98764481655937,17.0499999076128,0.00103943048001153,0.000364590219985554,0.25,1.53301218753349E-5,9.50775781525773E-5,1.59742268678541E-5,19.9506569,19.9698696,-38606.79296875,-38591.8515625,57.8999141905446,20.773705164275,13.417728,0,0,0,40,4449,19.8638,-38599.322265625,,,,,,,,,,,,,0,,,,0,,,,,,19.96026325,,,,
,29247849.795,20.0000114,-33789.826171875,4.57335799476432E-5,2.17466431095594E-6,1,0.999253354069792,40.0298881530762,1.98706552911215,17.0499999076128,0.000491814074691002,0.000208437358905426,0.25,1.03715953827914E-5,4.55341111080404E-5,1.06601475441388E-5,20.0000114,20.0000114,-33799.75390625,-33779.8984375,58.1242415755638,20.7834864518043,13.417728,0,0,0,40,4449,19.9207,-33789.826171875,,,,,,,,,,,,,0,,,,-0.00245,,,,,,20.0000114,,,,
,29247944.305,20.0387058,-29065.3349609375,4.4613055994916E-5,2.27056060097843E-6,1,0.999253354069792,40.0298881530762,1.98407518188588,17.0499999076128,0.000478490602044081,0.00020499221421946,0.25,1.03101915076103E-5,4.43971680941151E-5,1.05764962134465E-5,20.0387058,20.0387058,-29072.9609375,-29057.708984375,57.9343058453907,20.8200451716174,13.038077,0,0,0,40,4449,19.9357,-29065.3349609375,,,,,,,,,,,,,0,,,,-0.00245,,,,,,20.0387058,,,,
,29248037.94,19.9862366,-24385.287109375,2.1562727589242E-5,1.93598256980298E-6,1,0.999253354069792,40.0298881530762,1.98439061825682,17.0499999076128,0.00022471744281848,0.000135231591113133,0.25,8.22316625611219E-6,2.14282465737488E-5,8.33188069145183E-6,19.9862366,19.9862366,-24395.3125,-24375.26171875,58.0843785210831,20.8145952820064,13.417728,0,0,0,40,4449,19.93075,-24385.287109375,,,,,,,,,,,,,0,,,,-0.00245,,,,,,19.9862366,,,,
,29248132.545,19.9799175,-19657.4404296875,-2.08074168986194E-5,8.27351036869391E-7,1,0.999253354069792,40.0298881530762,1.98677730149852,17.0499999076128,-0.000237054511724655,-1.8641176267448E-5,0.25,2.05899391917251E-6,-2.073203365469E-5,1.9214926765639E-6,19.9799175,19.9799175,-19662.728515625,-19652.15234375,57.9358691024292,20.794155698689,13.797379,0,0,0,40,4449,19.9303,-19657.4404296875,,,,,,,,,,,,,0,,,,0.0049,,,,,,19.9799175,,,,
,29248223.7,20.0355492,-15103.046875,-3.8025153003267E-5,1.15754266947712E-6,1,0.999253354069792,40.0298881530762,1.98698472121046,17.0499999076128,-0.00043550027453865,-2.0373249734386E-5,0.25,4.97344483668638E-6,-3.78771097732188E-5,4.72661010470302E-6,20.0355492,20.0355492,-15110.3916015625,-15095.7021484375,57.7146682314869,20.79065633609,13.417728,0,0,0,40,4449,19.9238,-15103.046875,,,,,,,,,,,,,0,,,,-0.0049,,,,,,20.0355492,,,,
,29248318.3,19.98645305,-10375.1635742187,-7.40588414067274E-5,5.17914106625748E-7,1,0.999253354069792,40.0298881530762,1.9868199240015,17.0499999076128,-0.000835000184164759,-0.000111096204821205,0.25,3.27483548839735E-6,-7.37015134571976E-5,2.84784161161401E-6,19.9857082,19.9871979,-10382.7470703125,-10367.580078125,57.6154014095446,20.7938967003862,13.417728,0,0,0,40,4449,19.9378,-10375.1635742187,,,,,,,,,,,,,0,,,,-0.00245,,,,,,19.98645305,,,,
,29248409.82,19.986517,-5799.69140625,-9.52563219463031E-5,4.9499274270114E-7,1,0.999253354069792,40.0298881530762,1.9873201788894,17.0499999076128,-0.00106877132122726,-0.00017147682402502,0.25,1.62349307174533E-6,-9.47485617708007E-5,1.11868503609082E-6,19.986517,19.986517,-5814.87109375,-5784.51171875,57.5262957583522,20.7824902748757,13.797379,0,0,0,40,4449,19.9344,-5799.69140625,,,,,,,,,,,,,0,,,,0.0049,,,,,,19.986517,,,,
,29248503.51,20.0030937,-1115.67309570312,-8.60948398341319E-5,3.57930661920331E-7,1,0.999253354069792,40.0298881530762,1.98733554523898,17.0499999076128,-0.000961212781574746,-0.000180207281712925,0.25,-8.1874564629286E-7,-8.55995420551866E-5,-1.23565315326859E-6,20.0023384,20.003849,-1120.80419921875,-1110.5419921875,57.6974724040638,20.7847520236699,13.038077,0,0,0,40,4449,19.94045,-1115.67309570312,,,,,,,,,,,,,0,,,,0.00245,,,,,,20.0030937,,,,
,29248597.59,19.98526195,3582.228515625,9.71474762048646E-5,4.09604754494297E-7,1,0.999253354069792,40.0298881530762,1.98767168972925,17.0499999076128,0.0010870717465584,0.000191400211325133,0.25,-1.642122129308E-7,9.66074988120409E-5,3.27478204726062E-7,19.983923,19.9866009,3577.14306640625,3587.31396484375,57.891316276833,20.7732863584822,13.417728,0,0,0,40,4449,19.9397,3582.228515625,,,,,,,,,,,,,0,,,,0.0049,,,,,,19.98526195,,,,
,29248691.63,19.9971733,8284.0771484375,8.19366425874167E-5,4.3811627692796E-7,1,0.999253354069792,40.0298881530762,1.98716289522132,17.0499999076128,0.000921420788471497,0.000136334887757488,0.25,-2.41077480950118E-6,8.15206155827082E-5,-1.95667940310291E-6,19.9971733,19.9971733,8276.71484375,8291.439453125,58.0421705810446,20.7900201955879,13.797379,0,0,0,40,4449,19.941,8284.0771484375,,,,,,,,,,,,,0,,,,0,,,,,,19.9971733,,,,
,29248784.47,19.9853611,12924.810546875,5.58268396703606E-5,6.01535541571958E-7,1,0.999253354069792,40.0298881530762,1.9872678767763,17.0499999076128,0.000631696032817936,7.26848103063457E-5,0.25,-3.47068986396875E-6,5.55756654188701E-5,-3.13413248832487E-6,19.9853611,19.9853611,12914.873046875,12934.748046875,57.779543398583,20.780744748584,13.417728,0,0,0,40,4449,19.9325,12924.810546875,,,,,,,,,,,,,0,,,,0,,,,,,19.9853611,,,,
,29248880.51,19.9871273,17724.7197265625,2.78517708586326E-5,5.12630945749222E-7,1,0.999253354069792,40.0298881530762,1.98763183210248,17.0499999076128,0.00032493468088768,-1.73011922850763E-5,0.25,-6.52650555049724E-6,2.77682267734974E-5,-6.32882820546389E-6,19.9871273,19.9871273,17717.078125,17732.361328125,57.8733388208907,20.7701700710871,13.417728,0,0,0,40,4449,19.9285,17724.7197265625,,,,,,,,,,,,,0,,,,0,,,,,,19.9871273,,,,
,29248974.725,19.9752865,22432.6669921875,-6.2798575156617E-7,9.01806519098064E-8,1,0.999253354069792,40.0298881530762,1.98751366094154,17.0499999076128,1.63337493548963E-5,-0.00013168917507696,0.25,-1.16441785668644E-5,-5.51407835586976E-7,-1.1602029933153E-5,19.9752865,19.9752865,22425.341796875,22439.9921875,57.9600995865254,20.774270167696,13.417728,0,0,0,40,4449,19.91655,22432.6669921875,,,,,,,,,,,,,0,,,,0.0049,,,,,,19.9752865,,,,
,29249065.26,19.9841881,26960.7470703125,-3.39577232564283E-5,1.11180124445648E-6,1,0.999253354069792,40.0298881530762,1.98771240826167,17.0499999076128,-0.000362267504065724,-0.000170249294115601,0.25,-9.09848643572367E-6,-3.37785452190198E-5,-9.29142758027762E-6,19.9841881,19.9841881,26953.169921875,26968.32421875,57.8280043667753,20.7770583824466,13.797379,0,0,0,40,4449,19.9254,26960.7470703125,,,,,,,,,,,,,0,,,,0,,,,,,19.9841881,,,,
,29249159.59,19.98464965,31670.7412109375,-5.02969356249984E-5,1.81850075366104E-6,1,0.999253354069792,40.0298881530762,1.98734107835043,17.0499999076128,-0.000540637717431341,-0.000230393370452894,0.25,-1.15159962473221E-5,-5.00665863189526E-5,-1.18258831765192E-5,19.9802246,19.9890747,31660.955078125,31680.52734375,58.02653801066,20.7745550095698,13.038077,0,0,0,40,4449,19.9036,31670.7412109375,,,,,,,,,,,,,0,,,,0,,,,,,19.98464965,,,,
,29249256.285,20.0121136,36505.79296875,-9.76062442250804E-5,1.58439369022583E-6,1,0.999253354069792,40.0298881530762,1.98764547021704,17.0499999076128,-0.00107072768008709,-0.000331071896538928,0.25,-1.19595569252735E-5,-9.72780163429009E-5,-1.26174213752911E-5,20.0121136,20.0121136,36498.27734375,36513.30859375,57.9983993839677,20.7762155874198,13.417728,0,0,0,40,4449,19.9416,36505.79296875,,,,,,,,,,,,,0,,,,-0.00245,,,,,,20.0121136,,,,
,29249351.675,19.9951782,41273.19921875,-0.000119605508798382,2.57743401813371E-6,1,0.999253354069792,40.0298881530762,1.98772971806829,17.0499999076128,-0.00130576937255547,-0.000444685574001998,0.25,-1.80924554989768E-5,-0.000119236608686212,-1.89172889396994E-5,19.9951782,19.9951782,41265.84375,41280.5546875,57.8483267082754,20.7727547734849,13.797379,0,0,0,40,4449,19.9411,41273.19921875,,,,,,,,,,,,,0,,,,-0.00245,,,,,,19.9951782,,,,
,29249444.68,19.9977741,45924.044921875,-0.000153102397827665,2.333680883197E-6,1,0.999253354069792,40.0298881530762,1.98769287346283,17.0499999076128,-0.00167374068057289,-0.00056105681580132,0.25,-2.23921924332736E-5,-0.000152707581354612,-2.34773728113822E-5,19.9977741,19.9977741,45919.3359375,45928.75390625,57.9905830987754,20.7692473196729,13.038077,0,0,0,40,4449,19.9337,45924.044921875,,,,,,,,,,,,,0,,,,0,,,,,,19.9977741,,,,
,29249537.95,19.985218,50583.90234375,-0.00018934264986897,3.34278038017298E-6,1,0.999253354069792,40.0298881530762,1.98771254314658,17.0499999076128,-0.00209913618056744,-0.000537560679324542,0.25,-1.37349477112761E-5,-0.000189045532703464,-1.51189894669827E-5,19.985218,19.985218,50576.65625,50591.1484375,58.1007927199869,20.7667207247232,13.417728,0,0,0,40,4449,19.9192,50583.90234375,,,,,,,,,,,,,0,,,,0.0049,,,,,,19.985218,,,,
,29249636.43,19.996994,55506.341796875,-0.000218973501499759,2.81802036700073E-6,1,0.999253354069792,40.0298881530762,1.98760524265917,17.0499999076128,-0.00242795923839887,-0.000626017819168282,0.25,-1.62366548266762E-5,-0.000218733452634604,-1.78547981918526E-5,19.996994,19.996994,55498.84765625,55513.8359375,57.9124202468523,20.7675481657029,13.417728,0,0,0,40,4449,19.92555,55506.341796875,,,,,,,,,,,,,0,,,,-0.00245,,,,,,19.996994,,,,
,29249736.615,19.9944973,60514.154296875,-0.000240381570259875,2.11411020161876E-6,1,0.999253354069792,40.0298881530762,1.98752244478761,17.0499999076128,-0.0026693236688658,-0.000671833042168335,0.25,-1.64263127862251E-5,-0.00024024301907516,-1.82144442228334E-5,19.9944973,19.9944973,60506.58203125,60521.7265625,57.5622506702369,20.7653825827616,13.038077,0,0,0,40,4449,19.9364,60514.154296875,,,,,,,,,,,,,0,,,,0,,,,,,19.9944973,,,,
,29249836.665,20.02897645,65514.4609375,-0.000332099064908114,2.12504048444923E-6,1,0.999253354069792,40.0298881530762,1.98638304232693,17.0499999076128,-0.00370188440123986,-0.000848072569777178,0.25,-1.55828989331769E-5,-0.00033211176379574,-1.80555768132542E-5,20.0276623,20.0302906,65509.53515625,65519.38671875,57.6302523514099,20.7813974050133,13.417728,0,0,0,40,4449,19.89315,65514.4609375,,,,,,,,,,,,,0,,,,0.0049,,,,,,20.02897645,,,,
,29249936.96,19.9942169,70527.03515625,-0.000341986280397636,2.77195846113528E-6,1,0.999253354069792,40.0298881530762,1.98749574986518,17.0499999076128,-0.00381063314747039,-0.000902815400728758,0.25,-1.86077426102085E-5,-0.000342129311358871,-2.11490122267846E-5,19.9942169,19.9942169,70516.984375,70537.0859375,57.7435884866984,20.7659022523379,13.038077,0,0,0,40,4449,19.9352,70527.03515625,,,,,,,,,,,,,0,,,,0.00245,,,,,,19.9942169,,,,
,29250034.295,20.0021725,75394.62890625,-0.000357052000883623,2.21424584381248E-6,1,0.999253354069792,40.0298881530762,1.98726206290447,17.0499999076128,-0.00397121407689385,-0.000989689695515982,0.25,-2.36105700888433E-5,-0.0003573137051002,-2.6255020606981E-5,20.0021725,20.0021725,75389.609375,75399.6484375,57.7303008018715,20.7726291740117,13.417728,0,0,0,40,4449,19.9393,75394.62890625,,,,,,,,,,,,,0,,,,-0.00245,,,,,,20.0021725,,,,
,29250133.315,19.9842739,80341.171875,-0.000401991894720918,2.63169575670384E-6,1,0.999253354069792,40.0298881530762,1.98760403046679,17.0499999076128,-0.00449417771771121,-0.00100001594170325,0.25,-1.6417502948994E-5,-0.000402515134741592,-1.9357039594669E-5,19.9842739,19.9842739,80333.6015625,80348.7421875,57.3207274577945,20.7648197555189,13.797379,0,0,0,40,4449,19.92695,80341.171875,,,,,,,,,,,,,0,,,,0.0049,,,,,,19.9842739,,,,
,29250228.815,19.9982719,85116.6640625,-0.000419476311158405,1.9829960907727E-6,1,0.999253354069792,40.0298881530762,1.9875701472691,17.0499999076128,-0.00466914562770408,-0.00116643176983443,0.25,-2.80498339182202E-5,-0.000420090333049139,-3.11067723503352E-5,19.9982719,19.9982719,85106.53125,85126.796875,57.5411467002176,20.7655392465592,13.417728,0,0,0,40,4449,19.9353,85116.6640625,,,,,,,,,,,,,0,,,,0.00245,,,,,,19.9982719,,,,
,29250316.71,20.0074444,89509.5703125,-0.000485187755868817,2.73933033840391E-6,1,0.999253354069792,40.0298881530762,1.98772176570454,17.0499999076128,-0.00538796705641933,-0.00143104910270437,0.25,-3.97106493454997E-5,-0.000485994310621705,-4.32278127064249E-5,20.0074444,20.0074444,89504.8515625,89514.2890625,57.6357237510446,20.7628568250445,13.038077,0,0,0,40,4449,19.9271,89509.5703125,,,,,,,,,,,,,0,,,,0,,,,,,20.0074444,,,,
,29250426.68,19.9931984,86036.4609375,-0.000378424267972658,3.1532544625457E-6,1,0.999253354069792,40.0298881530762,1.98746742285695,17.0499999076128,-0.00423119370849095,-0.00094709181357106,0.25,-1.59743460900082E-5,-0.000379069456323216,-1.87079994954715E-5,19.9931984,19.9931984,86034.3203125,86038.6015625,57.6130565239869,20.7624979555031,13.038077,0,0,0,40,4449,19.9213,86036.4609375,,,,,,,,,,,,,0,,,,0,,,,,,19.9931984,,,,
,29250523.61,20.0223446,81190.3984375,-0.000367356689367684,3.45668020281853E-6,1,0.999253354069792,40.0298881530762,1.98710004188984,17.0499999076128,-0.00410080179360577,-0.000943832153858305,0.25,-1.7685276489929E-5,-0.000367838625218796,-2.03714396983698E-5,20.0223446,20.0223446,81185.3828125,81195.4140625,57.7467150007753,20.7686185611659,13.038077,0,0,0,40,4449,19.8805,81190.3984375,,,,,,,,,,,,,0,,,,-0.0049,,,,,,20.0223446,,,,
,29250616.835,19.9787998,76529.1484375,-0.000317789312484534,3.49432090430859E-6,1,0.999253354069792,40.0298881530762,1.98731917796802,17.0499999076128,-0.00352086956817964,-0.00095909331574425,0.25,-2.79599203793585E-5,-0.000318000169901233,-3.03192555498997E-5,19.9787998,19.9787998,76521.671875,76536.625,58.1781739433908,20.7662612098318,13.038077,0,0,0,40,4449,19.91285,76529.1484375,,,,,,,,,,,,,0,,,,0,,,,,,19.9787998,,,,
,29250707.61,20.0593987,71990.80859375,-0.000332913966077325,3.18486188404848E-6,1,0.999253354069792,40.0298881530762,1.98701689927157,17.0499999076128,-0.00368949048590551,-0.000987844907986713,0.25,-2.7813796870054E-5,-0.000333022383147706,-3.02935970728925E-5,20.0593987,20.0593987,71983.2734375,71998.34375,57.5184794731599,20.7825332862539,13.797379,0,0,0,40,4449,19.89195,71990.80859375,,,,,,,,,,,,,0,,,,-0.00245,,,,,,20.0593987,,,,
,29250806.505,19.9989014,67047.7109375,-0.000297085176176517,3.58527956900755E-6,1,0.999253354069792,40.0298881530762,1.98722481396218,17.0499999076128,-0.00331047677472307,-0.00077516088821722,0.25,-1.53739382388802E-5,-0.000297126239523621,-1.7585549480854E-5,19.9989014,19.9989014,67045.203125,67050.21875,57.7170131170446,20.772075272708,13.038077,0,0,0,40,4449,19.9217,67047.7109375,,,,,,,,,,,,,0,,,,-0.0049,,,,,,19.9989014,,,,
,29250905.985,19.9933662,62074.02734375,-0.000231020893689267,2.51586658478135E-6,1,0.999253354069792,40.0298881530762,1.98778433261117,17.0499999076128,-0.00255975415553459,-0.000680890525029739,0.25,-1.89035641941637E-5,-0.000230897876375846,-2.06241095013148E-5,19.9933662,19.9933662,62066.47265625,62081.58203125,57.8053371397177,20.7629999210619,13.038077,0,0,0,40,4449,19.91385,62074.02734375,,,,,,,,,,,,,0,,,,0.00245,,,,,,19.9933662,,,,
,29251003.12,19.9622078,57221.173828125,-0.000236644179203367,2.069365483926E-6,1,0.999253354069792,40.0298881530762,1.98738624059246,17.0499999076128,-0.00262101146270714,-0.000693420270379704,0.25,-1.90439982699066E-5,-0.000236412663635279,-2.07969667764522E-5,19.9622078,19.9622078,57208.8828125,57233.46484375,57.891316276833,20.7702254934499,13.417728,0,0,0,40,4449,19.89065,57221.173828125,,,,,,,,,,,,,0,,,,-0.00245,,,,,,19.9622078,,,,
,29251104.41,19.961607,52158.939453125,-0.000190389102121393,2.37126172184846E-6,1,0.999253354069792,40.0298881530762,1.98767813387615,17.0499999076128,-0.002074297772215,-0.000744454743897247,0.25,-3.19517798016594E-5,-0.000189985894378455,-3.33332487918032E-5,19.961607,19.961607,52151.56640625,52166.3125,57.7615659426407,20.762670325975,13.797379,0,0,0,40,4449,19.9143,52158.939453125,,,,,,,,,,,,,0,,,,-0.00245,,,,,,19.961607,,,,
,29251203.475,19.9678402,47206.4765625,-0.000165824550962122,2.41132965670362E-6,1,0.999253354069792,40.0298881530762,1.98783313100831,17.0499999076128,-0.00183991329365896,-0.000459388382263343,0.25,-1.10336947265383E-5,-0.000165515192872312,-1.22344843652573E-5,19.9678402,19.9678402,47204.203125,47208.75,57.6583909781023,20.7705951827026,13.797379,0,0,0,40,4449,19.9142,47206.4765625,,,,,,,,,,,,,0,,,,0,,,,,,19.9678402,,,,
,29251301.79,19.9864006,42293.603515625,-0.000119967444973053,2.64711981449329E-6,1,0.999253354069792,40.0298881530762,1.98773289158676,17.0499999076128,-0.00132471260457531,-0.000363572490839012,0.25,-1.0793170654012E-5,-0.000119662914471533,-1.16396096622354E-5,19.9864006,19.9864006,42285.9609375,42301.24609375,57.76234757116,20.7706124371161,13.417728,0,0,0,40,4449,19.9275,42293.603515625,,,,,,,,,,,,,0,,,,-0.00245,,,,,,19.9864006,,,,
,29251399.9,19.9991302,37388.78125,-9.97127070883726E-5,1.39089825946282E-6,1,0.999253354069792,40.0298881530762,1.98780573359454,17.0499999076128,-0.0011003654611541,-0.000302988796865678,0.25,-9.06948008006738E-6,-9.94086068502949E-5,-9.75335710299868E-6,19.9991302,19.9991302,37383.828125,37393.734375,57.6083667528715,20.7661872339557,13.417728,0,0,0,40,4449,19.9278,37388.78125,,,,,,,,,,,,,0,,,,-0.0049,,,,,,19.9991302,,,,
,29251496.61,19.996397,32553.8427734375,-6.45208480830434E-5,1.67167306648341E-6,1,0.999253354069792,40.0298881530762,1.98630090495344,17.0499999076128,-0.000680933019732069,-0.000363922379865248,0.25,-2.08828946552609E-5,-6.41887251698402E-5,-2.12664943985156E-5,19.996397,19.996397,32551.431640625,32556.25390625,57.7435884866984,20.7850587043157,13.038077,0,0,0,40,4449,19.9392,32553.8427734375,,,,,,,,,,,,,0,,,,-0.0049,,,,,,19.996397,,,,
,29251594.065,19.9874134,27684.5400390625,-2.87060204747333E-5,1.78254836602472E-6,1,0.999253354069792,40.0298881530762,1.98782576839377,17.0499999076128,-0.000297120001256121,-0.000194966558470949,0.25,-1.2243046669021E-5,-2.85261074872219E-5,-1.23922155733279E-5,19.986887,19.9879398,27674.427734375,27694.65234375,57.6920010044292,20.7685240627432,13.417728,0,0,0,40,4449,19.93405,27684.5400390625,,,,,,,,,,,,,0,,,,0,,,,,,19.9874134,,,,
,29251688.705,19.9970894,22954.1748046875,-7.93850601224007E-6,1.44855796028174E-6,1,0.999253354069792,40.0298881530762,1.98776255567767,17.0499999076128,-7.4939619323545E-5,-9.40423538433897E-5,0.25,-6.97179160484304E-6,-7.86288277470871E-6,-6.9952904049002E-6,19.9970894,19.9970894,22941.2421875,22967.107421875,58.0312277817754,20.7636898990137,13.417728,0,0,0,40,4449,19.93795,22954.1748046875,,,,,,,,,,,,,0,,,,0.00245,,,,,,19.9970894,,,,
,29251783.305,19.9938984,18226.7197265625,2.58513255500908E-5,7.66157657401353E-7,1,0.999253354069792,40.0298881530762,1.987938505869,17.0499999076128,0.000298004492983775,4.35989868300689E-6,0.25,-4.2351953180744E-6,2.57641118900514E-5,-4.05910105649779E-6,19.9938984,19.9938984,18224.330078125,18229.109375,58.0085605547177,20.7602405103501,13.417728,0,0,0,40,4449,19.9443,18226.7197265625,,,,,,,,,,,,,0,,,,0,,,,,,19.9938984,,,,
,29251876.925,19.9824505,13546.7421875,4.70173549619902E-5,5.36628769226479E-7,1,0.999253354069792,40.0298881530762,1.9879395662729,17.0499999076128,0.00053766112394432,3.0746747987537E-5,0.25,-5.64875232628508E-6,4.68242327184663E-5,-5.35027632374297E-6,19.9824505,19.9824505,13536.9580078125,13556.5263671875,57.8623960216215,20.7691303820754,13.417728,0,0,0,40,4449,19.93525,13546.7421875,,,,,,,,,,,,,0,,,,0.0049,,,,,,19.9824505,,,,
,29251970.985,19.987606,8846.4228515625,7.34799841105709E-5,4.03343595630308E-7,1,0.999253354069792,40.0298881530762,1.98789554670334,17.0499999076128,0.000827412874943507,0.000118030657678107,0.25,-2.54760964758182E-6,7.311230659263E-5,-2.13542487683527E-6,19.987606,19.987606,8833.88671875,8858.958984375,57.8561429934677,20.7693506493776,13.417728,0,0,0,40,4449,19.9534,8846.4228515625,,,,,,,,,,,,,0,,,,-0.00245,,,,,,19.987606,,,,
,29252062.935,20.0809269,4251.09228515625,9.1071643242533E-5,3.7411585069618E-7,1,0.999253354069792,40.0298881530762,1.98497113437954,17.0499999076128,0.00101983997208639,0.00016776391173345,0.25,-1.18214364572547E-6,9.05745637935942E-5,-7.11333078215881E-7,20.0582352,20.1036186,4241.1025390625,4261.08203125,58.2110023411985,20.8068946497864,13.038077,0,0,0,40,4449,19.951,4251.09228515625,,,,,,,,,,,,,0,,,,0,,,,,,20.0809269,,,,
,29252148.78,19.9907684,-0.266416028141975,2.05521364599248E-5,3.49425809383451E-7,1,0.999253354069792,40.0298881530762,1.98802191912044,17.0499999076128,0.000231758692239193,3.04327350294518E-5,0.25,-9.29610797674155E-7,2.04384389308367E-5,-8.24694974660284E-7,19.9907684,19.9907684,-0.274027913808823,-0.258804142475128,57.7545312859677,20.7725496084421,13.038077,0,0,0,40,4417,19.94275,-0.266416028141975,,,,,,,,,,,,,0,,,,-0.00245,,,,,,19.9907684,,,,