File: data/looselyPackedNP/sc-ios-7/ppms/rawdata/ES_S17_HYST_50K.DAT
[Header]
; VSM Data File (default extension .dat)
; Copyright (c) 2003-2013, Quantum Design, Inc. All rights reserved.
TITLE,
FILEOPENTIME,29252769.11,12/05/2018,9:47 pm
BYAPP,VSM,2.0,2.0
INFO,PPMS VSM Option Release 1.4.10 Build 1,APPNAME
INFO,Quantum Design Linear Motor Servo Controller,MOTOR_MODULE_NAME
INFO,3101-100 M1,MOTOR_HW_VERSION
INFO,MMC1014,MOTOR_SERIAL_NUMBER
INFO,SRV No X-over 01.03.11,MOTOR_SOFTWARE_VERSION
INFO,Quantum Design VSM Detection Module,VSM_MODULE_NAME
INFO,3101-150 F0,VSM_HW_VERSION
INFO,VSM707,VSM_SERIAL_NUMBER
INFO,VSM No X-over 01.02.05 May 20 2008 13:51:47,VSM_SOFTWARE_VERSION
INFO,704,PREAMP_SERIAL_NUMBER
INFO,822,COIL_SERIAL_NUMBER
INFO,0,MOMENT_UNITS
INFO,Iron Oxide Spheres,SAMPLE_MATERIAL
INFO,7 nm diameter, collaboration Mainz,SAMPLE_COMMENT
INFO,,SAMPLE_MASS
INFO,,SAMPLE_VOLUME
INFO,,SAMPLE_MOLECULAR_WEIGHT
INFO,,SAMPLE_SIZE
INFO,,SAMPLE_SHAPE
DATATYPE,COMMENT,1
DATATYPE,TIME,2
STARTUPAXIS,X,2
STARTUPAXIS,Y1,5
[Data]
Comment,Time Stamp (sec),Temperature (K),Magnetic Field (Oe),Moment (emu),M. Std. Err. (emu),Transport Action,Averaging Time (sec),Frequency (Hz),Peak Amplitude (mm),Center Position (mm),Coil Signal' (mV),Coil Signal" (mV),Range (mV),M. Quad. Signal (emu),M. Raw' (emu),M. Raw" (emu),Min. Temperature (K),Max. Temperature (K),Min. Field (Oe),Max. Field (Oe),Mass (grams),Motor Lag (deg),Pressure (Torr),VSM Status (code),Motor Status (code),Measure Status (code),Measure Count,PPMS Status (code),System Temp. (K),System Field (Oe),Sample Position (deg),Bridge 1 Resistance (ohms),Bridge 1 Excitation (에),Bridge 2 Resistance (ohms),Bridge 2 Excitation (에),Bridge 3 Resistance (ohms),Bridge 3 Excitation (에),Bridge 4 Resistance (ohms),Bridge 4 Excitation (에),Signal 1 Vin (V),Signal 2 Vin (V),Digital Inputs (code),Drive 1 Iout (mA),Drive 1 Ipower (W),Drive 2 Iout (mA),Drive 2 Ipower (W),Pressure (),Map 20 (),Map 21 (),Map 22 (),Map 23 (),Map 24 (),Map 25 (),Map 26 (),Map 27 (),Map 28 (),Map 29 ()
,29252784.7,50.0095291,-0.243580371141434,,,2,,,,17.0099997353554,,,,,,,50.0095291,50.0095291,-0.243580371141434,-0.243580371141434,,,16.075285,,,,-99999999,4369,50.0333,-0.243580371141434,,,,,,,,,,,,,,,,,,,,,,,50.0095291,,,,
,29252942.805,50.0336685,4797.9677734375,8.72940714743666E-5,4.25222037861106E-7,1,0.999253354069792,40.0298881530762,1.97334599647175,17.000000923872,0.000979528583435047,0.000147461007910532,0.25,-2.52497802099528E-6,8.72791672846794E-5,-1.87440447776107E-6,50.0336685,50.0336685,4790.5244140625,4805.4111328125,57.5403650716984,20.7888137677713,16.454937,0,0,0,40,4449,49.9393,4797.9677734375,,,,,,,,,,,,,0,,,,0,,,,,,50.0336685,,,,
,29253043.335,50.01114655,9824.44384765625,5.7334623583747E-5,4.83103720083152E-7,1,0.999253354069792,40.0298881530762,1.9741388962275,17.000000923872,0.000649342877140072,6.59580809534045E-5,0.25,-4.4295103165429E-6,5.73599694929259E-5,-4.00240174619593E-6,50.0106735,50.0116196,9817.1142578125,9831.7734375,57.9077304757369,20.7812117694519,16.834587,0,0,0,40,4449,49.94535,9824.44384765625,,,,,,,,,,,,,0,,,,-0.0049,,,,,,50.01114655,,,,
,29253146.86,50.0079079,14996.4619140625,2.64914215675526E-5,6.03878501807507E-7,1,0.999253354069792,40.0298881530762,1.97472535205328,17.000000923872,0.000316749973635547,-6.13544938568064E-5,0.25,-1.02643722913778E-5,2.65714422944045E-5,-1.00690945112089E-5,50.0079079,50.0079079,14988.7802734375,15004.1435546875,57.3551191126407,20.7841604450247,16.834587,0,0,0,40,4449,49.93975,14996.4619140625,,,,,,,,,,,,,0,,,,-0.00245,,,,,,50.0079079,,,,
,29253248.74,50.0089798,20088.8525390625,-6.7388719692264E-7,1.0202961202815E-7,1,0.999253354069792,40.0298881530762,1.97511664839777,17.000000923872,1.96326554908334E-5,-0.000152115863366907,0.25,-1.34827922864218E-5,-5.74347704660115E-7,-1.34934718438614E-5,50.0089798,50.0089798,20076.419921875,20101.28515625,57.6755868055253,20.780562396918,16.454937,0,0,0,40,4449,49.93365,20088.8525390625,,,,,,,,,,,,,0,,,,0,,,,,,50.0089798,,,,
,29253349.54,50.0020218,25126.5341796875,-4.40924166344918E-5,1.5305666724176E-6,1,0.999253354069792,40.0298881530762,1.97529214718703,17.000000923872,-0.000472060347980436,-0.000206206982257891,0.25,-1.04907841426141E-5,-4.40460500300695E-5,-1.08231126265688E-5,50.0020218,50.0020218,25118.986328125,25134.08203125,58.0624929225446,20.7773695277331,16.834587,0,0,0,40,4449,49.9361,25126.5341796875,,,,,,,,,,,,,0,,,,-0.00245,,,,,,50.0020218,,,,
,29253450.675,49.9983482,30181.42578125,-6.18678369668872E-5,1.75175301244096E-6,1,0.999253354069792,40.0298881530762,1.97442350472362,17.000000923872,-0.000650195945020702,-0.000356383004073267,0.25,-2.07211864054752E-5,-6.1776661296794E-5,-2.11947261094861E-5,49.9983482,49.9983482,30176.5546875,30186.296875,57.9194549035254,20.7834555896199,16.834587,0,0,0,40,4449,49.9365,30181.42578125,,,,,,,,,,,,,0,,,,-0.00245,,,,,,49.9983482,,,,
,29253555.435,50.0092392,35419.09375,-6.35280843453436E-5,2.26848579066257E-6,1,0.999253354069792,40.0298881530762,1.97411692979355,17.000000923872,-0.000671221673582066,-0.00034669142246034,0.25,-1.95549866164011E-5,-6.34659702780931E-5,-2.00414918453586E-5,50.0092392,50.0092392,35414.02734375,35424.16015625,57.779543398583,20.7789465531367,16.834587,0,0,0,40,4449,49.9267,35419.09375,,,,,,,,,,,,,0,,,,0.00245,,,,,,50.0092392,,,,
,29253656.75,50.0117645,40481.0546875,-9.6523780097294E-5,3.92186321259362E-6,1,0.999253354069792,40.0298881530762,1.97358404098997,17.000000923872,-0.00103852907637629,-0.000423119641734075,0.25,-2.04521143475221E-5,-9.65235532609201E-5,-2.11789754956319E-5,50.0117645,50.0117645,40475.640625,40486.46875,57.7631291996792,20.7858089072021,16.454937,0,0,0,40,4449,49.9191,40481.0546875,,,,,,,,,,,,,0,,,,-0.00245,,,,,,50.0117645,,,,
,29253751.055,50.0135422,45194.51953125,-0.00014492537461297,6.06246071648907E-6,1,0.999253354069792,40.0298881530762,1.97298058907937,17.000000923872,-0.0015795293749486,-0.000522470135132624,0.25,-2.06337713313103E-5,-0.00014503362273129,-2.17051631049765E-5,50.0135422,50.0135422,45184.6875,45204.3515625,57.6099300099099,20.7876267401192,16.454937,0,0,0,40,4449,49.9103,45194.51953125,,,,,,,,,,,,,0,,,,0.00245,,,,,,50.0135422,,,,
,29253843.815,49.9994278,49829.529296875,-0.000120716765563805,3.24261236589104E-6,1,0.999253354069792,40.0298881530762,1.98597128147817,17.000000923872,-0.00132831432740053,-0.000415584029074867,0.25,-1.52016187818465E-5,-0.00012084998595977,-1.60854156316742E-5,49.9994278,49.9994278,49821.703125,49837.35546875,57.2652318329291,20.762978332265,16.454937,0,0,0,40,4449,49.9149,49829.529296875,,,,,,,,,,,,,0,,,,-0.0049,,,,,,49.9994278,,,,
,29253937.75,49.9950294,54524.65625,-0.000186528755520984,3.16731279236088E-6,1,0.999253354069792,40.0298881530762,1.98577565688348,17.000000923872,-0.00204026743611664,-0.000711784491633763,0.25,-2.96803085836248E-5,-0.00018673525427002,-3.10503975420741E-5,49.9950294,49.9950294,54519.7421875,54529.5703125,57.9124202468523,20.7658263864463,16.834587,0,0,0,40,4449,49.92505,54524.65625,,,,,,,,,,,,,0,,,,-0.00245,,,,,,49.9950294,,,,
,29254032.7,50.005825,59269.912109375,-0.000181960361967674,4.15041138245799E-6,1,0.999253354069792,40.0298881530762,1.98667483833914,17.000000923872,-0.00200697249556117,-0.000609334923512466,0.25,-2.13831015385183E-5,-0.000182255861857689,-2.26924086402538E-5,50.005825,50.005825,59262.36328125,59277.4609375,57.9546281868908,20.7576977190041,16.834587,0,0,0,40,4449,49.91885,59269.912109375,,,,,,,,,,,,,0,,,,0.00245,,,,,,50.005825,,,,
,29254126.465,50.0013809,63957.740234375,-0.000220949673423618,5.99954149334783E-6,1,0.999253354069792,40.0298881530762,1.98498708064619,17.000000923872,-0.00239323125298562,-0.00097514729776554,0.25,-4.69141840969082E-5,-0.000221213223384057,-4.85457498881817E-5,50.0013809,50.0013809,63955.203125,63960.27734375,57.5786648691407,20.7690256672363,17.214239,0,0,0,40,4449,49.9157,63957.740234375,,,,,,,,,,,,,0,,,,0.0049,,,,,,50.0013809,,,,
,29254220.525,49.9962311,68658.0390625,-0.000339911043797491,3.22194664564224E-6,1,0.999253354069792,40.0298881530762,1.98537448406987,17.000000923872,-0.00375310616458425,-0.00111165117302826,0.25,-3.7663864855133E-5,-0.000340623178074662,-4.00595339178056E-5,49.9962311,49.9962311,68653.1796875,68662.8984375,58.2579000523523,20.7753657707998,17.214239,0,0,0,40,4449,49.9262,68658.0390625,,,,,,,,,,,,,0,,,,0,,,,,,49.9962311,,,,
,29254315.28,49.9982376,73395.8828125,-0.000261868351814289,6.96668228358275E-6,1,0.999253354069792,40.0298881530762,1.98668329364801,17.000000923872,-0.00284165340554675,-0.00114779184784461,0.25,-5.48208051831343E-5,-0.000262298011884383,-5.67258901446304E-5,49.9982376,49.9982376,73386.015625,73405.75,57.7068519462946,20.7606495864351,17.214239,0,0,0,40,4449,49.92025,73395.8828125,,,,,,,,,,,,,0,,,,0.00245,,,,,,49.9982376,,,,
,29254409.81,49.993927,78121.30859375,-0.000284298687245237,7.64186569069421E-6,1,0.999253354069792,40.0298881530762,1.98623597389018,17.000000923872,-0.00312368433687885,-0.00103040163016198,0.25,-4.04148717515185E-5,-0.00028494753832357,-4.24055444485625E-5,49.993927,49.993927,78113.7890625,78128.828125,57.8428553086407,20.7547917021083,17.214239,0,0,0,40,4449,49.9231,78121.30859375,,,,,,,,,,,,,0,,,,0,,,,,,49.993927,,,,
,29254504.845,49.994606,82872.5,-0.000321166456974287,6.97808002827257E-6,1,0.999253354069792,40.0298881530762,1.98691071180524,17.000000923872,-0.00351523918970166,-0.00125015068615282,0.25,-5.32702108523898E-5,-0.000321910651515016,-5.55215655847327E-5,49.994606,49.994606,82867.453125,82877.546875,57.657609349583,20.7536547837559,17.214239,0,0,0,40,4449,49.92395,82872.5,,,,,,,,,,,,,0,,,,-0.0049,,,,,,49.994606,,,,
,29254595.245,49.9830246,87390.58984375,-0.000336296215709239,5.99181788422926E-6,1,0.999253354069792,40.0298881530762,1.9884378361795,17.000000923872,-0.00367253456406286,-0.00137527072466184,0.25,-6.15729009939363E-5,-0.000337097748915533,-6.39279139905193E-5,49.9823685,49.9836807,87385.96875,87395.2109375,57.5833546402561,20.7388010747423,17.214239,0,0,0,40,4449,49.9452,87390.58984375,,,,,,,,,,,,,0,,,,-0.00245,,,,,,49.9830246,,,,
,29254705.575,49.9874916,88140.375,-0.000342405163710899,5.52685413860883E-6,1,0.999253354069792,40.0298881530762,1.9878315794223,17.000000923872,-0.00371464390128529,-0.00153181076380576,0.25,-7.43845304326995E-5,-0.000343157375197158,-7.68201516076634E-5,49.9874916,49.9874916,88137.8515625,88142.8984375,57.5427099572561,20.7469296822941,17.214239,0,0,0,40,4449,49.959,88140.375,,,,,,,,,,,,,0,,,,0,,,,,,49.9874916,,,,
,29254795.82,49.9906845,83631.91796875,-0.000335995669518225,4.14294902308821E-6,1,0.999253354069792,40.0298881530762,1.98826762571202,17.000000923872,-0.00368599733849877,-0.00127568041766337,0.25,-5.28046161496244E-5,-0.000336804192016427,-5.51457281312548E-5,49.9906845,49.9906845,83624.5703125,83639.265625,58.0226298680638,20.7412037933171,16.454937,0,0,0,40,4449,49.95245,83631.91796875,,,,,,,,,,,,,0,,,,-0.00245,,,,,,49.9906845,,,,
,29254890.445,49.9938469,78897.99609375,-0.000295596238174835,5.17229633463274E-6,1,0.999253354069792,40.0298881530762,1.9885028058689,17.000000923872,-0.00319128153143732,-0.00140829460212522,0.25,-7.17711275618084E-5,-0.000296087667532057,-7.39334179049699E-5,49.9938469,49.9938469,78890.484375,78905.5078125,57.8053371397177,20.7483213642787,17.214239,0,0,0,40,4449,49.96735,78897.99609375,,,,,,,,,,,,,0,,,,-0.00245,,,,,,49.9938469,,,,
,29254985.17,49.9975052,74164.65625,-0.000259527669687984,3.40274276275816E-6,1,0.999253354069792,40.0298881530762,1.98884219655165,17.000000923872,-0.00281998637186141,-0.00113488247820253,0.25,-5.39924712574374E-5,-0.000259966342531166,-5.5876613720086E-5,49.9975052,49.9975052,74152.3671875,74176.9453125,57.8366022804869,20.7400931699334,17.214239,0,0,0,40,4449,49.9722,74164.65625,,,,,,,,,,,,,0,,,,-0.00245,,,,,,49.9975052,,,,
,29255081.415,49.9978371,69351.8671875,-0.000263949127602924,9.3399597671349E-6,1,0.999253354069792,40.0298881530762,1.9876165242353,17.000000923872,-0.00294092297598601,-0.000734385968278116,0.25,-1.77422392743108E-5,-0.000264588980745122,-1.95661409029679E-5,49.9978371,49.9978371,69349.640625,69354.09375,57.98589332766,20.7491604198942,16.834587,0,0,0,40,4449,49.9691,69351.8671875,,,,,,,,,,,,,0,,,,0,,,,,,49.9978371,,,,
,29255175.86,49.9984932,64633.669921875,-0.000200217351144282,3.80555823954305E-6,1,0.999253354069792,40.0298881530762,1.98903575157892,17.000000923872,-0.00215881931912317,-0.000964251140566711,0.25,-4.95034917791001E-5,-0.000200416585307773,-5.09990341034171E-5,49.9984932,49.9984932,64626.27734375,64641.0625,58.1547250878138,20.7312424425254,17.214239,0,0,0,40,4449,49.9654,64633.669921875,,,,,,,,,,,,,0,,,,0,,,,,,49.9984932,,,,
,29255268.805,50.0000229,59987.697265625,-0.000165372533697358,3.7015498392909E-6,1,0.999253354069792,40.0298881530762,1.98875380099113,17.000000923872,-0.00179924085177706,-0.000702823509825569,0.25,-3.25985936175802E-5,-0.0001655574287661,-3.38192204130243E-5,50.0000229,50.0000229,59972.3125,60003.08203125,57.515352959083,20.734375705489,17.214239,0,0,0,40,4449,49.9721,59987.697265625,,,,,,,,,,,,,0,,,,0.00245,,,,,,50.0000229,,,,
,29255363.37,49.9979897,55260.05859375,-0.000161633729547178,3.85209116973499E-6,1,0.999253354069792,40.0298881530762,1.98900973083462,17.000000923872,-0.00175794827897272,-0.000689223961187429,0.25,-3.20569559109745E-5,-0.000161775647763684,-3.32570999211509E-5,49.9979897,49.9979897,55260.05859375,55260.05859375,58.1187701759292,20.7365564709347,16.834587,0,0,0,40,4449,49.9699,55260.05859375,,,,,,,,,,,,,0,,,,-0.0049,,,,,,49.9979897,,,,
,29255458.51,49.9981804,50504.892578125,-0.000129911950404457,2.32303542196968E-6,1,0.999253354069792,40.0298881530762,1.98907258456765,17.000000923872,-0.00140786246530009,-0.000580423144225489,0.25,-2.81119277296579E-5,-0.00012997824540914,-2.9085830345682E-5,49.9981804,49.9981804,50497.4375,50512.34765625,57.8756837064484,20.7362179899576,16.834587,0,0,0,40,4449,49.97115,50504.892578125,,,,,,,,,,,,,0,,,,0.00245,,,,,,49.9981804,,,,
,29255551.48,49.9993038,45856.97265625,-0.000106111473060438,3.25917097165446E-6,1,0.999253354069792,40.0298881530762,1.98921751555369,17.000000923872,-0.00114422938709656,-0.000504611739844824,0.25,-2.56683414719743E-5,-0.000106120469216493,-2.64711618966774E-5,49.9992256,49.999382,45854.546875,45859.3984375,57.8702123068138,20.7390690274,17.214239,0,0,0,40,4449,49.9706,45856.97265625,,,,,,,,,,,,,0,,,,0,,,,,,49.9993038,,,,
,29255646.115,50.0016289,41126.806640625,-9.11504863042294E-5,3.31044795216623E-6,1,0.999253354069792,40.0298881530762,1.98920759472502,17.000000923872,-0.000987733082279414,-0.000405080179772079,0.25,-1.95342480600994E-5,-9.11529258166198E-5,-2.0220800216846E-5,50.0016289,50.0016289,41116.73828125,41136.875,57.9944912413715,20.7403796581704,17.214239,0,0,0,40,4449,49.969,41126.806640625,,,,,,,,,,,,,0,,,,-0.00245,,,,,,50.0016289,,,,
,29255739.64,49.9999237,36451.845703125,-5.06173191666663E-5,2.31579100835034E-6,1,0.999253354069792,40.0298881530762,1.98903428877598,17.000000923872,-0.000533152329833623,-0.000309102427202869,0.25,-1.83201860030445E-5,-5.05514818610597E-5,-1.87117305387735E-5,49.9999237,49.9999237,36444.1796875,36459.51171875,57.6560460925446,20.7427786575065,17.214239,0,0,0,40,4449,49.972,36451.845703125,,,,,,,,,,,,,0,,,,-0.0049,,,,,,49.9999237,,,,
,29255833.645,49.9986877,31756.8759765625,-2.4074675329321E-5,3.59149781313459E-6,1,0.999253354069792,40.0298881530762,1.989195066486,17.000000923872,-0.000240991211310396,-0.000216607154491114,0.25,-1.48920622406878E-5,-2.39917313596172E-5,-1.50840186399102E-5,49.9986877,49.9986877,31752.09765625,31761.654296875,57.759221057083,20.7451370672002,16.834587,0,0,0,40,4449,49.97755,31756.8759765625,,,,,,,,,,,,,0,,,,0,,,,,,49.9986877,,,,
,29255924.995,50.001236,27189.818359375,2.08994595841224E-6,2.80143176597073E-7,1,0.999253354069792,40.0298881530762,1.98923017816331,17.000000923872,5.71899778712864E-5,-0.000182558702051915,0.25,-1.65859573198271E-5,2.21360678490464E-6,-1.65842912127374E-5,50.001236,50.001236,27179.546875,27200.08984375,57.779543398583,20.7443464607244,16.834587,0,0,0,40,4449,49.97605,27189.818359375,,,,,,,,,,,,,0,,,,-0.0049,,,,,,50.001236,,,,
,29256019.3,50.0083923,22476.7470703125,1.46079141946226E-5,7.60042327263496E-7,1,0.999253354069792,40.0298881530762,1.98931748248933,17.000000923872,0.000179493487920071,-5.3658653631556E-5,0.25,-7.39765303875042E-6,1.46708077366643E-5,-7.29390189469485E-6,50.0083923,50.0083923,22466.861328125,22486.6328125,57.8350390234484,20.7433371756266,17.214239,0,0,0,40,4449,49.9695,22476.7470703125,,,,,,,,,,,,,0,,,,0.0049,,,,,,50.0083923,,,,
,29256113.61,49.9973297,17764.1669921875,4.25160770992761E-5,7.69258325116474E-7,1,0.999253354069792,40.0298881530762,1.98948397346027,17.000000923872,0.000505046727267327,-6.02638846469838E-5,0.25,-1.3015286710778E-5,4.26255441400941E-5,-1.2704008577475E-5,49.9973297,49.9973297,17759.318359375,17769.015625,57.9006958190638,20.7398288697645,16.834587,0,0,0,40,4449,49.9741,17764.1669921875,,,,,,,,,,,,,0,,,,-0.00245,,,,,,49.9973297,,,,
,29256207.07,50.0077782,13094.078125,6.74435862698681E-5,5.27159587185525E-7,1,0.999253354069792,40.0298881530762,1.98918131964088,17.000000923872,0.000771748344816198,6.58710936814452E-5,0.25,-6.30252950667313E-6,6.74938505122056E-5,-5.80160431411966E-6,50.0077782,50.0077782,13081.7177734375,13106.4384765625,57.8545797364292,20.7427150215599,17.214239,0,0,0,40,4449,49.9774,13094.078125,,,,,,,,,,,,,0,,,,0,,,,,,50.0077782,,,,
,29256298.935,49.9986343,8501.0810546875,8.73276909939504E-5,4.79287832918147E-7,1,0.999253354069792,40.0298881530762,1.98968672180525,17.000000923872,0.000989085451753348,0.000141838920734852,0.25,-3.13660802964747E-6,8.73340595557354E-5,-2.48623497589362E-6,49.9986343,49.9986343,8493.376953125,8508.78515625,57.9718240143138,20.7390588127306,16.834587,0,0,0,40,4449,49.9673,8501.0810546875,,,,,,,,,,,,,0,,,,-0.0049,,,,,,49.9986343,,,,
,29256392.16,49.9986954,3837.912109375,0.000100485055498996,4.12346181042228E-7,1,0.999253354069792,40.0298881530762,1.98981408703596,17.000000923872,0.00113291133471991,0.000190986536689728,0.25,-1.13830360088802E-6,0.000100451559002926,-3.90100007973904E-7,49.9986954,49.9986954,3835.26342773438,3840.56079101562,57.8819367346023,20.7385565557069,17.593889,0,0,0,40,4449,49.97745,3837.912109375,,,,,,,,,,,,,0,,,,-0.0049,,,,,,49.9986954,,,,
,29256483.805,49.9990463,-741.742645263672,-7.05700034639239E-5,3.24617057095609E-7,1,0.999253354069792,40.0298881530762,1.9898794258447,17.000000923872,-0.000793300734921556,-0.000146648101082993,0.25,-3.14649693353411E-7,-7.05291911860466E-5,-8.39417520851751E-7,49.9990463,49.9990463,-746.738708496094,-736.74658203125,57.8006473686023,20.7349851069784,17.214239,0,0,0,40,4449,49.96955,-741.742645263672,,,,,,,,,,,,,0,,,,-0.0049,,,,,,49.9990463,,,,
,29256577.52,49.9988976,-5419.54516601562,-9.71839947532041E-5,5.14715244290254E-7,1,0.999253354069792,40.0298881530762,1.98854291487394,17.000000923872,-0.00109437399789163,-0.000188672386622649,0.25,7.39946703648999E-7,-9.71560389914722E-5,1.64770025885081E-8,49.9988976,49.9988976,-5422.01708984375,-5417.0732421875,57.4903408464676,20.7379411630821,17.214239,0,0,0,40,4449,49.9769,-5419.54516601562,,,,,,,,,,,,,0,,,,-0.00245,,,,,,49.9988976,,,,
,29256670.865,50.0002632,-10087.90625,-8.05288331497987E-5,6.72572309215477E-7,1,0.999253354069792,40.0298881530762,1.98979758953408,17.000000923872,-0.000909803459902003,-0.00014413199111363,0.25,1.70887124746359E-6,-8.05325122438433E-5,1.10965869932975E-6,50.0002632,50.0002632,-10090.5888671875,-10085.2236328125,58.0507684947561,20.7393860923155,16.834587,0,0,0,40,4449,49.9671,-10087.90625,,,,,,,,,,,,,0,,,,-0.0049,,,,,,50.0002632,,,,
,29256766.485,50.005249,-14865.6357421875,-6.02899634557491E-5,8.04673075585892E-7,1,0.999253354069792,40.0298881530762,1.9896855924973,17.000000923872,-0.000688928951731162,-6.55127504476665E-5,0.25,5.04658624771132E-6,-6.03360214166401E-5,4.5995407019298E-6,50.005249,50.005249,-14873.0322265625,-14858.2392578125,57.8960060479484,20.7395060985218,17.214239,0,0,0,40,4449,49.9617,-14865.6357421875,,,,,,,,,,,,,0,,,,-0.00245,,,,,,50.005249,,,,
,29256860.205,50.0018234,-19550.3984375,-3.81445694415663E-5,8.98987356314237E-7,1,0.999253354069792,40.0298881530762,1.98969738921127,17.000000923872,-0.000442080914063884,-7.66290296625712E-6,0.25,6.19348785153869E-6,-3.82058101099237E-5,5.91349641969874E-6,50.0018234,50.0018234,-19555.3984375,-19545.3984375,57.9280528172369,20.7383093185571,17.214239,0,0,0,40,4449,49.9727,-19550.3984375,,,,,,,,,,,,,0,,,,-0.00245,,,,,,50.0018234,,,,
,29256953.92,49.9992371,-24235.42578125,-8.32817874208842E-6,1.13020037275449E-6,1,0.999253354069792,40.0298881530762,1.98974876270792,17.000000923872,-0.000106429388706209,5.31734203354232E-5,0.25,6.22144722255567E-6,-8.37958017191419E-6,6.16414242263395E-6,49.9992371,49.9992371,-24242.8515625,-24228,58.0929764347946,20.7388815513901,17.214239,0,0,0,40,4449,49.9725,-24235.42578125,,,,,,,,,,,,,0,,,,0,,,,,,49.9992371,,,,
,29257050.755,50.0009041,-29072.80859375,9.8337853229314E-6,1.42277535874968E-6,1,0.999253354069792,40.0298881530762,1.99021124706076,17.000000923872,9.73002337389052E-5,9.49970847410706E-5,0.25,6.65858785115304E-6,9.79406303352069E-6,6.73689362550254E-6,50.0009041,50.0009041,-29080.158203125,-29065.458984375,57.9843300706215,20.7355979520207,17.214239,0,0,0,40,4449,49.96885,-29072.80859375,,,,,,,,,,,,,0,,,,0.0049,,,,,,50.0009041,,,,
,29257144.18,49.998642,-33745.166015625,2.40997309076999E-5,1.9532391856299E-6,1,0.999253354069792,40.0298881530762,1.99011804214975,17.000000923872,0.000254020263977113,0.000146748360105698,0.25,8.67960719940939E-6,2.40649321128373E-5,8.8654729795124E-6,49.998642,49.998642,-33752.60546875,-33737.7265625,57.9835484421023,20.7380578956262,17.593889,0,0,0,40,4449,49.9693,-33745.166015625,,,,,,,,,,,,,0,,,,0,,,,,,49.998642,,,,
,29257236.195,49.99920845,-38339.77734375,5.73800126211996E-5,2.55515518820687E-6,1,0.999253354069792,40.0298881530762,1.99012890079654,17.000000923872,0.000635926531001993,0.000177530042298162,0.25,5.41667048806775E-6,5.74225435541577E-5,5.83938517297793E-6,49.9991341,49.9992828,-38349.765625,-38329.7890625,58.1132987762946,20.7404148298473,17.593889,0,0,0,40,4449,49.9682,-38339.77734375,,,,,,,,,,,,,0,,,,0,,,,,,49.99920845,,,,
,29257329.515,50.001255,-43004.447265625,6.71083958960101E-5,2.82322341243925E-6,1,0.999253354069792,40.0298881530762,1.9903005502416,17.000000923872,0.000739541394914338,0.000232404328294819,0.25,8.53009872651241E-6,6.71589445860974E-5,9.02546060408202E-6,50.001255,50.001255,-43011.796875,-42997.09765625,58.1312762322369,20.7363695108405,17.214239,0,0,0,40,4449,49.967,-43004.447265625,,,,,,,,,,,,,0,,,,-0.0049,,,,,,50.001255,,,,
,29257424.7,50.0004539,-47762.27734375,9.8780904224018E-5,2.40891495898661E-6,1,0.999253354069792,40.0298881530762,1.99033128760597,17.000000923872,0.00109379557101054,0.000314747256463287,0.25,1.01315135036552E-5,9.88970225626487E-5,1.08520619296059E-5,50.0004539,50.0004539,-47769.6328125,-47754.921875,57.9194549035254,20.7360510288981,17.214239,0,0,0,40,4449,49.9715,-47762.27734375,,,,,,,,,,,,,0,,,,-0.00245,,,,,,50.0004539,,,,
,29257518.915,50.0004463,-52469.2421875,9.6882570028224E-5,4.73239229049746E-6,1,0.999253354069792,40.0298881530762,1.99029558029147,17.000000923872,0.00105554212401458,0.000405902640715276,0.25,1.85530427201136E-5,9.69586548794611E-5,1.92730570076145E-5,50.0004463,50.0004463,-52476.77734375,-52461.70703125,58.0726540932946,20.7398197976738,17.214239,0,0,0,40,4449,49.9678,-52469.2421875,,,,,,,,,,,,,0,,,,-0.00245,,,,,,50.0004463,,,,
,29257614.63,50.0030479,-57256.5703125,0.000120803549782293,2.93376715588304E-6,1,0.999253354069792,40.0298881530762,1.99009858246411,17.000000923872,0.00133916077427144,0.000379272339751729,0.25,1.1897495145866E-5,0.00012100517270889,1.27641083676045E-5,50.0030479,50.0030479,-57263.875,-57249.265625,57.90460396166,20.7385360883916,16.834587,0,0,0,40,4449,49.96585,-57256.5703125,,,,,,,,,,,,,0,,,,-0.00245,,,,,,50.0030479,,,,
,29257710.61,50.00736235,-62051.46484375,0.000162998135090318,1.84901080263648E-6,1,0.999253354069792,40.0298881530762,1.98996996436869,17.000000923872,0.0018229862731068,0.000423913399740776,0.25,8.27860653749051E-6,0.000163359697090412,9.41731269035297E-6,50.0059929,50.0087318,-62056.48046875,-62046.44921875,57.7177947455638,20.7486239092057,16.834587,0,0,0,40,4449,49.96395,-62051.46484375,,,,,,,,,,,,,0,,,,0,,,,,,50.00736235,,,,
,29257806.98,49.9999542,-66868.96875,0.000172261463210919,3.40281792323958E-6,1,0.999253354069792,40.0298881530762,1.9899047093504,17.000000923872,0.00189487273849819,0.000626649927074818,0.25,2.45822754601369E-5,0.00017257269142247,2.58157946585877E-5,49.9999542,49.9999542,-66879.09375,-66858.84375,57.8686490497754,20.7488089972887,17.593889,0,0,0,40,4449,49.96235,-66868.96875,,,,,,,,,,,,,0,,,,0,,,,,,49.9999542,,,,
,29257902.58,49.9995193,-71645.9609375,0.000222240760652933,3.2527576907571E-6,1,0.999253354069792,40.0298881530762,1.99047383712211,17.000000923872,0.00249854574261938,0.000515004543078388,0.25,5.71929750646006E-6,0.000222862076388634,7.21910490066989E-6,49.9995193,49.9995193,-71645.9609375,-71645.9609375,57.9092937327753,20.7443970881475,16.834587,0,0,0,40,4449,49.9634,-71645.9609375,,,,,,,,,,,,,0,,,,-0.00245,,,,,,49.9995193,,,,
,29257999.29,50.00066565,-76478.21875,0.000233326243231684,3.55091063448234E-6,1,0.999253354069792,40.0298881530762,1.99046773145269,17.000000923872,0.00262290253816027,0.000545038690903803,0.25,6.40300893922406E-6,0.000234020406013699,7.9575496873361E-6,50.000473,50.0008583,-76488.2421875,-76468.1953125,57.93508747391,20.742973912658,17.214239,0,0,0,40,4449,49.9622,-76478.21875,,,,,,,,,,,,,0,,,,0.00245,,,,,,50.00066565,,,,
,29258095.25,50.0013618,-81275.4921875,0.000265105136695049,3.16409713595704E-6,1,0.999253354069792,40.0298881530762,1.99044118294506,17.000000923872,0.00299248854380517,0.000553257145200304,0.25,1.44945114083461E-6,0.000265979533726358,3.17173559680788E-6,50.0013618,50.0013618,-81280.5703125,-81270.4140625,57.8256594812177,20.740771868536,16.834587,0,0,0,40,4449,49.9629,-81275.4921875,,,,,,,,,,,,,0,,,,0.00245,,,,,,50.0013618,,,,
,29258188.57,50.00087545,-85940.0703125,0.000259103556696624,2.75203911116583E-6,1,0.999253354069792,40.0298881530762,1.99060970076321,17.000000923872,0.00291424498566505,0.000603464715552589,0.25,6.98051530245713E-6,0.000259965397983806,8.65869404892824E-6,50.000843,50.0009079,-85952.5234375,-85927.6171875,57.9335242168715,20.7402100620746,17.214239,0,0,0,40,4449,49.9584,-85940.0703125,,,,,,,,,,,,,0,,,,-0.00245,,,,,,50.00087545,,,,
,29258295.44,49.9991722,-89703.46875,0.00032056659255837,2.4271696418564E-6,1,0.999253354069792,40.0298881530762,1.99049279558396,17.000000923872,0.00363837623708893,0.000564758381320956,0.25,-7.43262024418464E-6,0.000321775527112455,-5.43844219020932E-6,49.9991722,49.9991722,-89708.359375,-89698.578125,57.9507200442946,20.744249105275,17.593889,0,0,0,40,4449,49.9532,-89703.46875,,,,,,,,,,,,,0,,,,0,,,,,,49.9991722,,,,
,29258386.275,49.9989243,-85167.703125,0.000272021968179541,9.73251908463813E-6,1,0.999253354069792,40.0298881530762,1.98976827925205,17.000000923872,0.00303670151370331,0.000753444212793393,0.25,1.79610590177017E-5,0.000272851591421489,1.97638465376309E-5,49.9989243,49.9989243,-85175.1171875,-85160.2890625,57.8553613649484,20.7481866233611,16.834587,0,0,0,40,4449,49.966,-85167.703125,,,,,,,,,,,,,0,,,,-0.0049,,,,,,49.9989243,,,,
,29258481.955,49.996624,-80385.64453125,0.000282400086155587,2.58894305206373E-6,1,0.999253354069792,40.0298881530762,1.99038390356757,17.000000923872,0.00321313131646725,0.000446455619947788,0.25,-1.1105505712554E-5,0.000283404623585411,-9.30758094454907E-6,49.996624,49.996624,-80397.984375,-80373.3046875,57.9686975002369,20.7416017510929,17.593889,0,0,0,40,4449,49.9652,-80385.64453125,,,,,,,,,,,,,0,,,,0,,,,,,49.996624,,,,
,29258577.65,49.9986343,-75602.57421875,0.000208999029699761,5.55005345704291E-6,1,0.999253354069792,40.0298881530762,1.99035491746227,17.000000923872,0.00232383353453695,0.000629745233171552,0.25,1.82651229469915E-5,0.00020953114034809,1.97001808028637E-5,49.9986343,49.9986343,-75610.1015625,-75595.046875,58.0320094102946,20.7409196476173,17.214239,0,0,0,40,4449,49.96315,-75602.57421875,,,,,,,,,,,,,0,,,,0.0049,,,,,,49.9986343,,,,
,29258674.745,49.9991264,-70753.0859375,0.000213593616386477,3.3790768047272E-6,1,0.999253354069792,40.0298881530762,1.99043040941169,17.000000923872,0.00240487680946785,0.000474409003575871,0.25,3.67525093240646E-6,0.000214195136348661,5.11494718676612E-6,49.9991264,49.9991264,-70763.40625,-70742.765625,58.0484236091985,20.7425496813138,17.214239,0,0,0,40,4449,49.96115,-70753.0859375,,,,,,,,,,,,,0,,,,-0.00245,,,,,,49.9991264,,,,
,29258768.975,49.9992638,-66040.9453125,0.000211490069371017,2.55064017491727E-6,1,0.999253354069792,40.0298881530762,1.99039599067811,17.000000923872,0.0023571778246708,0.000600601588881895,0.25,1.52180922266885E-5,0.000211965934144909,1.6693809321437E-5,49.9992638,49.9992638,-66050.9296875,-66030.9609375,58.0312277817754,20.7385766969166,17.214239,0,0,0,40,4449,49.9662,-66040.9453125,,,,,,,,,,,,,0,,,,-0.0049,,,,,,49.9992638,,,,
,29258865.37,49.9988708,-61226.306640625,0.000149809394368678,3.43572295216693E-6,1,0.999253354069792,40.0298881530762,1.990381708459,17.000000923872,0.0016810182664706,0.000360363823895754,0.25,5.00992293393992E-6,0.000150154108532622,6.05188640715986E-6,49.9988708,49.9988708,-61233.8359375,-61218.77734375,57.9694791287561,20.7341567523276,17.214239,0,0,0,40,4449,49.967,-61226.306640625,,,,,,,,,,,,,0,,,,-0.00245,,,,,,49.9988708,,,,
,29258958.37,49.9991646,-56576.318359375,0.000104056866290283,2.3310346232681E-6,1,0.999253354069792,40.0298881530762,1.99034356698754,17.000000923872,0.00113997233331364,0.000402625473940911,0.25,1.6972209017355E-5,0.000104180372376731,1.77352309964602E-5,49.9991646,49.9991646,-56581.34375,-56571.29296875,58.0077789261985,20.7350365609733,17.593889,0,0,0,40,4449,49.963,-56576.318359375,,,,,,,,,,,,,0,,,,0,,,,,,49.9991646,,,,
,29259053.42,49.99812315,-51826.69140625,9.44866703252993E-5,2.44809554926019E-6,1,0.999253354069792,40.0298881530762,1.99021511405603,17.000000923872,0.00102376876487402,0.000426960608865447,0.25,2.08517111215358E-5,9.45383848787042E-5,2.15601626824918E-5,49.9978065,49.9984398,-51834.15625,-51819.2265625,58.0210666110254,20.7375300555002,17.593889,0,0,0,40,4449,49.96705,-51826.69140625,,,,,,,,,,,,,0,,,,0.00245,,,,,,49.99812315,,,,
,29259149.805,50.0006599,-47009.88671875,0.000102385502450481,2.43294458445209E-6,1,0.999253354069792,40.0298881530762,1.99040687037213,17.000000923872,0.00113075321932162,0.000342638223327158,0.25,1.19543127671205E-5,0.00010249140445814,1.27046977351512E-5,50.0006599,50.0006599,-47017.265625,-47002.5078125,57.8780285920061,20.7322607918377,17.593889,0,0,0,40,4449,49.9619,-47009.88671875,,,,,,,,,,,,,0,,,,0.00245,,,,,,50.0006599,,,,
,29259245.975,49.998642,-42202.29296875,6.82783073957996E-5,3.52266911142807E-6,1,0.999253354069792,40.0298881530762,1.98982198097539,17.000000923872,0.000733001967538977,0.000343226232282491,0.25,1.81533627270378E-5,6.82587620536297E-5,1.86731576562526E-5,49.998642,49.998642,-42209.59375,-42194.9921875,57.7779801415446,20.7371987095922,17.593889,0,0,0,40,4449,49.96395,-42202.29296875,,,,,,,,,,,,,0,,,,0.00245,,,,,,49.998642,,,,
,29259341.645,49.9988136,-37422.720703125,3.10899332938423E-5,1.50950253810704E-6,1,0.999253354069792,40.0298881530762,1.99006994843473,17.000000923872,0.000338113014362209,0.00013184875268636,0.25,6.09823676126579E-6,3.10885179926959E-5,6.33184300194444E-6,49.9988136,49.9988136,-37432.6640625,-37412.77734375,58.1234599470446,20.7358352526244,17.593889,0,0,0,40,4449,49.96635,-37422.720703125,,,,,,,,,,,,,0,,,,0,,,,,,49.9988136,,,,
,29259437.515,49.9985504,-32630.4560546875,1.4405296637097E-5,1.48177965321493E-6,1,0.999253354069792,40.0298881530762,1.99010039909811,17.000000923872,0.000145533657771206,0.000122649627438168,0.25,8.28794448031764E-6,1.43609243952919E-5,8.40237482635663E-6,49.9985504,49.9985504,-32635.421875,-32625.490234375,57.9772954139484,20.7421825269561,17.214239,0,0,0,40,4449,49.96445,-32630.4560546875,,,,,,,,,,,,,0,,,,0,,,,,,49.9985504,,,,
,29259533.64,50.0006962,-27826.0615234375,-1.45119267304517E-5,9.79558672121779E-7,1,0.999253354069792,40.0298881530762,1.9901422557619,17.000000923872,-0.000169911468518776,6.0382207147531E-6,0.25,3.15013973404419E-6,-1.45475119321538E-5,3.04622614718614E-6,49.9997063,50.0016861,-27833.521484375,-27818.6015625,57.9944912413715,20.7365260514599,17.214239,0,0,0,40,4449,49.96225,-27826.0615234375,,,,,,,,,,,,,0,,,,-0.00245,,,,,,50.0006962,,,,
,29259628,49.9993362,-23110.8427734375,-4.39459764797907E-5,1.14609483366274E-6,1,0.999253354069792,40.0298881530762,1.99030055593702,17.000000923872,-0.000503030135035508,-4.50796241847818E-5,0.25,3.91692164253829E-6,-4.40011465746761E-5,3.59476603180265E-6,49.9993362,49.9993362,-23120.8046875,-23100.880859375,57.9468119016984,20.7358465535821,17.214239,0,0,0,40,4449,49.9621,-23110.8427734375,,,,,,,,,,,,,0,,,,-0.0049,,,,,,49.9993362,,,,
,29259721.33,50.001133,-18445.794921875,-5.41172515993137E-5,9.69433387460296E-7,1,0.999253354069792,40.0298881530762,1.98994638133628,17.000000923872,-0.000612085945535017,-9.49229509642217E-5,0.25,1.32327613437974E-6,-5.414537052935E-5,9.22617006244512E-7,50.001133,50.001133,-18453.099609375,-18438.490234375,57.9913647272946,20.737518006991,17.214239,0,0,0,40,4449,49.95955,-18445.794921875,,,,,,,,,,,,,0,,,,0.00245,,,,,,50.001133,,,,
,29259816.69,49.9998169,-13681.2592773437,-7.28603040994166E-5,8.66534792816364E-7,1,0.999253354069792,40.0298881530762,1.99015871840458,17.000000923872,-0.000828326920648598,-0.00010347556052892,0.25,3.94164775695681E-6,-7.28952640239669E-5,3.40055585408623E-6,49.9998169,49.9998169,-13686.052734375,-13676.4658203125,57.9898014702561,20.7351704780264,17.214239,0,0,0,40,4449,49.96125,-13681.2592773437,,,,,,,,,,,,,0,,,,0,,,,,,49.9998169,,,,
,29259910.02,49.9976501,-9015.7900390625,-9.02119472358469E-5,7.13131247756509E-7,1,0.999253354069792,40.0298881530762,1.99044140032798,17.000000923872,-0.00102052331814192,-0.000155605775347985,0.25,2.43844015656214E-6,-9.02149561547321E-5,1.76685456433404E-6,49.9976501,49.9976501,-9028.296875,-9003.283203125,57.96557098616,20.7304664741599,17.214239,0,0,0,40,4449,49.9676,-9015.7900390625,,,,,,,,,,,,,0,,,,0.0049,,,,,,49.9976501,,,,
,29260003.9,49.9979706,-4322.30541992188,-0.000101360980546828,4.60743369306603E-7,1,0.999253354069792,40.0298881530762,1.99063452155893,17.000000923872,-0.00114257711789635,-0.000196500319242676,0.25,8.13322404890703E-7,-0.000101326457444937,5.8731640414262E-8,49.9979706,49.9979706,-4334.72509765625,-4309.8857421875,57.9726056428331,20.7293917673115,17.214239,0,0,0,40,4449,49.9626,-4322.30541992188,,,,,,,,,,,,,0,,,,-0.00245,,,,,,49.9979706,,,,
,29260094.925,49.9988174,226.641487121582,3.14526395865036E-5,4.93241044005949E-7,1,0.999253354069792,40.0298881530762,1.98996066838872,17.000000923872,0.000354920500328589,5.7908041157848E-5,0.25,-5.22251022847143E-7,3.14388168184059E-5,-2.88011615312882E-7,49.9988174,49.9988174,214.05891418457,239.224060058594,57.9577547009677,20.734251884344,17.973541,0,0,0,40,4449,49.9623,226.641487121582,,,,,,,,,,,,,0,,,,0.00245,,,,,,49.9988174,,,,
,29260188.89,49.9974518,4923.27001953125,0.000100280673765061,4.22664664256744E-7,1,0.999253354069792,40.0298881530762,1.99076000303073,17.000000923872,0.00113024746551337,0.000195833301675483,0.25,-6.79423991743953E-7,0.00010024860374259,6.70769047226744E-8,49.9974518,49.9974518,4913.16357421875,4933.37646484375,57.88428162016,20.7258386483641,17.214239,0,0,0,40,4449,49.9693,4923.27001953125,,,,,,,,,,,,,0,,,,0.00245,,,,,,49.9974518,,,,
,29260282.305,49.9991112,9591.80908203125,8.646032631012E-5,5.52254268014032E-7,1,0.999253354069792,40.0298881530762,1.9908125645171,17.000000923872,0.00097657920895359,0.000158635061046344,0.25,-1.49597066118526E-6,8.6459503005351E-5,-8.52559486325016E-7,49.9991112,49.9991112,9581.650390625,9601.9677734375,57.9499384157754,20.7282852449088,17.214239,0,0,0,40,4449,49.9665,9591.80908203125,,,,,,,,,,,,,0,,,,0,,,,,,49.9991112,,,,
,29260378.48,50.00170325,14396.9184570312,6.26118170416795E-5,1.13516473042204E-6,1,0.999253354069792,40.0298881530762,1.99094970816058,17.000000923872,0.000710550257525987,9.76273368286762E-5,0.25,-2.61738036821604E-6,6.26385795398979E-5,-2.15258068638617E-6,50.0013008,50.0021057,14384.466796875,14409.3701171875,57.8397287945638,20.7235253436393,17.973541,0,0,0,40,4449,49.9621,14396.9184570312,,,,,,,,,,,,,0,,,,0,,,,,,50.00170325,,,,
,29260474.195,49.9997864,19179.162109375,4.96664514123917E-5,1.36439557263966E-6,1,0.999253354069792,40.0298881530762,1.99047673728469,17.000000923872,0.000567315295221521,5.71603165141435E-5,0.25,-3.87593701233677E-6,4.97140554384264E-5,-3.50948642760239E-6,49.9997864,49.9997864,19166.537109375,19191.787109375,57.9429037591023,20.7333670963315,17.593889,0,0,0,40,4449,49.96485,19179.162109375,,,,,,,,,,,,,0,,,,-0.0049,,,,,,49.9997864,,,,
,29260568.5,49.9983845,23894.5009765625,3.20554853912258E-5,1.39527953594198E-6,1,0.999253354069792,40.0298881530762,1.99060104268974,17.000000923872,0.000370429810329037,1.38192011004995E-5,0.25,-4.54930654049164E-6,3.21096191099013E-5,-4.31571177998009E-6,49.9977417,49.9990273,23884.599609375,23904.40234375,57.8553613649484,20.7321576614174,17.593889,0,0,0,40,4449,49.96585,23894.5009765625,,,,,,,,,,,,,0,,,,0.00245,,,,,,49.9983845,,,,
,29260665.205,50.0011787,28727.4990234375,5.85922647052342E-6,1.49332570846344E-6,1,0.999253354069792,40.0298881530762,1.99086422223875,17.000000923872,7.52547518165503E-5,-3.92195101057843E-5,0.25,-4.53475467837851E-6,5.89781997903736E-6,-4.49587078864201E-6,50.0011787,50.0011787,28722.59375,28732.404296875,57.8999141905446,20.7279390629709,17.214239,0,0,0,40,4449,49.9639,28727.4990234375,,,,,,,,,,,,,0,,,,0,,,,,,50.0011787,,,,
,29260759.675,50.0026398,33449.86328125,-1.83628363312534E-5,1.90662603491348E-6,1,0.999253354069792,40.0298881530762,1.99112969178446,17.000000923872,-0.000192070002492535,-0.000120594840309372,0.25,-7.38730205223298E-6,-1.83303479140775E-5,-7.52977561146919E-6,50.0026398,50.0026398,33440.0390625,33459.6875,57.8076820252753,20.7203757805451,17.593889,0,0,0,40,4449,49.9654,33449.86328125,,,,,,,,,,,,,0,,,,0.00245,,,,,,50.0026398,,,,
,29260853.665,50.0037727,38147.076171875,-2.91704239603615E-5,2.0148185490591E-6,1,0.999253354069792,40.0298881530762,1.99056967232592,17.000000923872,-0.000319513180591466,-0.000111592899778528,0.25,-4.64455897340344E-6,-2.91780036161259E-5,-4.86217666357375E-6,50.0037727,50.0037727,38142.171875,38151.98046875,57.8647409071792,20.725583802091,17.214239,0,0,0,40,4449,49.9594,38147.076171875,,,,,,,,,,,,,0,,,,0.0049,,,,,,50.0037727,,,,
,29260949.05,50.0018311,42915.1484375,-3.61013115874859E-5,3.09248235163486E-6,1,0.999253354069792,40.0298881530762,1.990737756142,17.000000923872,-0.000385309076475123,-0.000195132324499392,0.25,-1.08016391548667E-5,-3.60837361061012E-5,-1.10784590316874E-5,50.0018311,50.0018311,42910.41015625,42919.88671875,57.7560945430061,20.7238652326887,17.593889,0,0,0,40,4449,49.96145,42915.1484375,,,,,,,,,,,,,0,,,,-0.0049,,,,,,50.0018311,,,,
,29261042.915,49.9997711,47605.5078125,-8.86501182625661E-5,4.28933012213906E-6,1,0.999253354069792,40.0298881530762,1.98988883100368,17.000000923872,-0.000982195454746453,-0.000277978568558308,0.25,-8.69973720388046E-6,-8.87561867700716E-5,-9.34583431097113E-6,49.9997711,49.9997711,47592.9296875,47618.0859375,57.7975208545254,20.7264304243518,17.593889,0,0,0,40,4449,49.95885,47605.5078125,,,,,,,,,,,,,0,,,,0,,,,,,49.9997711,,,,
,29261135.345,50.0016556,52225.638671875,-7.71046323865641E-5,3.09033922731955E-6,1,0.999253354069792,40.0298881530762,1.99080152529906,17.000000923872,-0.000859220596857499,-0.00021762259121163,0.25,-5.41820949262036E-6,-7.7229805336194E-5,-5.9716049776443E-6,50.0016556,50.0016556,52220.68359375,52230.59375,57.8022106256407,20.7237229267736,16.834587,0,0,0,40,4449,49.9595,52225.638671875,,,,,,,,,,,,,0,,,,0,,,,,,50.0016556,,,,
,29261226.165,49.9991455,56763.3671875,-0.00010100598931491,2.258380320353E-6,1,0.999253354069792,40.0298881530762,1.99089495728759,17.000000923872,-0.00111984568608686,-0.000318625403523946,0.25,-1.00703918629751E-5,-0.000101171238969074,-1.07959522116841E-5,49.9991455,49.9991455,56753.28125,56773.453125,57.8647409071792,20.7244699459589,17.214239,0,0,0,40,4449,49.9591,56763.3671875,,,,,,,,,,,,,0,,,,-0.00245,,,,,,49.9991455,,,,
,29261321.77,49.9998055,61543.515625,-0.000119625922522115,4.23082278632272E-6,1,0.999253354069792,40.0298881530762,1.99096461878013,17.000000923872,-0.00133796872461176,-0.000314289471257595,0.25,-6.34324561299515E-6,-0.000119886552225585,-7.18068195892397E-6,49.9998055,49.9998055,61536.1640625,61550.8671875,57.7052886892561,20.7216152526743,17.214239,0,0,0,40,4449,49.9547,61543.515625,,,,,,,,,,,,,0,,,,0.00245,,,,,,49.9998055,,,,
,29261416.735,50.0077591,66291.69140625,-0.000119907627886494,4.62822856399598E-6,1,0.999253354069792,40.0298881530762,1.99101015355328,17.000000923872,-0.00131688507321949,-0.000451794502329014,0.25,-1.84711857549531E-5,-0.000120111827906679,-1.93344922677161E-5,50.0077591,50.0077591,66284.265625,66299.1171875,57.7584394285638,20.7112994095979,17.593889,0,0,0,40,4449,49.9558,66291.69140625,,,,,,,,,,,,,0,,,,0.00245,,,,,,50.0077591,,,,
,29261512.84,50.0030403,71094.39453125,-0.000152488064960098,5.37987782838789E-6,1,0.999253354069792,40.0298881530762,1.99048538505314,17.000000923872,-0.00169618720633412,-0.000454402038130665,0.25,-1.28687793955693E-5,-0.000152851002376386,-1.39258389637568E-5,50.0030403,50.0030403,71087.0625,71101.7265625,57.7818882841407,20.7211783941904,17.593889,0,0,0,40,4449,49.95515,71094.39453125,,,,,,,,,,,,,0,,,,0,,,,,,50.0030403,,,,
,29261606.415,50.0005493,75769.94140625,-0.00019548726147261,4.63548377018689E-6,1,0.999253354069792,40.0298881530762,1.99134169784682,17.000000923872,-0.00217240047140174,-0.000601796107473004,0.25,-1.81892943472554E-5,-0.000195978795323188,-1.95345678890197E-5,50.0005493,50.0005493,75764.8359375,75775.046875,57.7803250271023,20.7138640918489,17.593889,0,0,0,40,4449,49.9555,75769.94140625,,,,,,,,,,,,,0,,,,0,,,,,,50.0005493,,,,
,29261701.395,50.0015106,80521.234375,-0.000189694445908119,7.00065148389165E-6,1,0.999253354069792,40.0298881530762,1.99120599601576,17.000000923872,-0.00203490364029579,-0.000993386468735018,0.25,-5.38858279280573E-5,-0.000189971475774185,-5.52958848937241E-5,50.0015106,50.0015106,80518.6484375,80523.8203125,57.6943458899869,20.7153113191398,17.214239,0,0,0,40,4449,49.9541,80521.234375,,,,,,,,,,,,,0,,,,0,,,,,,50.0015106,,,,
,29261793.96,50.0006104,85144.15234375,-0.000225836525055472,4.24893472877067E-6,1,0.999253354069792,40.0298881530762,1.99119475496605,17.000000923872,-0.00253214616146522,-0.000573962471567716,0.25,-1.03127872265776E-5,-0.000226554210816779,-1.17937846971726E-5,50.0006104,50.0006104,85131.6484375,85156.65625,57.2777378892368,20.7160075741459,17.973541,0,0,0,40,4449,49.95405,85144.15234375,,,,,,,,,,,,,0,,,,-0.00245,,,,,,50.0006104,,,,
,29261883.03,49.9993362,89599.39453125,-0.000247681946862451,4.38637598651137E-6,1,0.999253354069792,40.0298881530762,1.99116070119141,17.000000923872,-0.00276676161195128,-0.000689356016475783,0.25,-1.6621209979584E-5,-0.000248474048560477,-1.82435768476656E-5,49.9993362,49.9993362,89589.5078125,89609.28125,57.5567792706022,20.7110110496956,17.593889,0,0,0,40,4449,49.95045,89599.39453125,,,,,,,,,,,,,0,,,,0,,,,,,49.9993362,,,,
,29261994.27,49.9990005,85846.73828125,-0.000256174343489011,6.09532388101329E-6,1,0.999253354069792,40.0298881530762,1.99137235126336,17.000000923872,-0.00282341430900474,-0.000925818371598345,0.25,-3.59969686338691E-5,-0.000256839773496896,-3.77583670991883E-5,49.9990005,49.9990005,85844.3125,85849.1640625,57.7310824303907,20.7097280368398,17.593889,0,0,0,40,4449,49.956,85846.73828125,,,,,,,,,,,,,0,,,,0,,,,,,49.9990005,,,,
,29262088.18,49.9986267,81153.203125,-0.000216133174111913,5.41988505147241E-6,1,0.999253354069792,40.0298881530762,1.99116042633097,17.000000923872,-0.00237408027300612,-0.000821923155071982,0.25,-3.39793735450209E-5,-0.000216632365911275,-3.54932991864324E-5,49.9982109,49.9990425,81145.6640625,81160.7421875,57.65057469291,20.7171678063939,17.593889,0,0,0,40,4449,49.95685,81153.203125,,,,,,,,,,,,,0,,,,0,,,,,,49.9986267,,,,
,29262184.675,49.9992638,76329.3671875,-0.000187206882449758,4.48691773721263E-6,1,0.999253354069792,40.0298881530762,1.99134508258324,17.000000923872,-0.0020571681433668,-0.000706038179851394,0.25,-2.88988760919172E-5,-0.000187606199851715,-3.02216064591121E-5,49.9992638,49.9992638,76316.5546875,76342.1796875,57.7224845166792,20.7178353227549,17.973541,0,0,0,40,4449,49.95295,76329.3671875,,,,,,,,,,,,,0,,,,0.0049,,,,,,49.9992638,,,,
,29262279.875,49.9997711,71568.0859375,-0.000157753417841622,6.46298815612848E-6,1,0.999253354069792,40.0298881530762,1.99124378219957,17.000000923872,-0.00171057186245189,-0.000720263193569383,0.25,-3.54400558362435E-5,-0.000157984390333789,-3.65979482665586E-5,49.9997711,49.9997711,71562.8203125,71573.3515625,57.8194064530638,20.7155584100618,17.593889,0,0,0,40,4449,49.95775,71568.0859375,,,,,,,,,,,,,0,,,,-0.00245,,,,,,49.9997711,,,,
,29262375.475,49.9983883,66790.25,-0.000120675977240985,6.24522584588706E-6,1,0.999253354069792,40.0298881530762,1.99122631134258,17.000000923872,-0.00131447829138237,-0.000516080221673112,0.25,-2.40202364349341E-5,-0.000120847382142914,-2.49033631655476E-5,49.9980736,49.998703,66780.3515625,66800.1484375,57.7975208545254,20.7190289063139,17.973541,0,0,0,40,4449,49.9524,66790.25,,,,,,,,,,,,,0,,,,-0.00245,,,,,,49.9983883,,,,
,29262466.495,49.9999313,62241.67578125,-0.000122332295324994,2.62432228731105E-6,1,0.999253354069792,40.0298881530762,1.991240617837,17.000000923872,-0.00135861710794717,-0.000376264473357052,0.25,-1.13415510404771E-5,-0.00012256942583366,-1.22090349248824E-5,49.9999313,49.9999313,62236.59375,62246.7578125,57.7748536274677,20.7201365858354,17.593889,0,0,0,40,4449,49.95725,62241.67578125,,,,,,,,,,,,,0,,,,0,,,,,,49.9999313,,,,
,29262559.03,49.9994392,57613.705078125,-0.000103789525627776,3.23841631233101E-6,1,0.999253354069792,40.0298881530762,1.99124436953666,17.000000923872,-0.00113643728967834,-0.000408204118978742,0.25,-1.74990840410468E-5,-0.00010391389475384,-1.82604245536683E-5,49.9994392,49.9994392,57603.640625,57623.76953125,57.8522348508715,20.7201214224368,17.593889,0,0,0,40,4449,49.95835,57613.705078125,,,,,,,,,,,,,0,,,,-0.00245,,,,,,49.9994392,,,,
,29262654.505,49.9981575,52843.560546875,-9.22511846798293E-5,3.92638933003778E-6,1,0.999253354069792,40.0298881530762,1.99143488214607,17.000000923872,-0.00100481234063109,-0.000391372070658222,0.25,-1.80790281976195E-5,-9.2322314708099E-5,-1.87652732951276E-5,49.9981575,49.9981575,52836.09375,52851.02734375,57.7748536274677,20.7159212474822,17.214239,0,0,0,40,4449,49.95835,52843.560546875,,,,,,,,,,,,,0,,,,0,,,,,,49.9981575,,,,
,29262747.415,49.9976349,48201.177734375,-5.8865111596316E-5,2.83923175660188E-6,1,0.999253354069792,40.0298881530762,1.99136465811642,17.000000923872,-0.000631761291124384,-0.000300987239283471,0.25,-1.60785341765819E-5,-5.88642568574847E-5,-1.65269870830529E-5,49.9976349,49.9976349,48193.78515625,48208.5703125,57.7732903704292,20.7176956364535,17.593889,0,0,0,40,4449,49.9594,48201.177734375,,,,,,,,,,,,,0,,,,0.00245,,,,,,49.9976349,,,,
,29262843.29,49.9999886,43410.728515625,-4.66185767696197E-5,2.86124767480978E-6,1,0.999253354069792,40.0298881530762,1.99113680627686,17.000000923872,-0.000495013053011725,-0.000266787565555497,0.25,-1.52563770313774E-5,-4.65877218843319E-5,-1.56160659670077E-5,49.9999886,49.9999886,43405.609375,43415.84765625,57.8592695075446,20.716825241546,17.214239,0,0,0,40,4449,49.9555,43410.728515625,,,,,,,,,,,,,0,,,,0,,,,,,49.9999886,,,,
,29262937.72,50.0038033,38690.40625,-2.04615716801151E-5,2.68540872219933E-6,1,0.999253354069792,40.0298881530762,1.99113145759516,17.000000923872,-0.00021175848195705,-0.00014735148474444,0.25,-9.37968747859196E-6,-2.04232210757012E-5,-9.54110006135603E-6,50.0038033,50.0038033,38683.078125,38697.734375,57.7514047718907,20.7203840660695,17.593889,0,0,0,40,4449,49.9552,38690.40625,,,,,,,,,,,,,0,,,,-0.0049,,,,,,50.0038033,,,,
,29263032.35,49.9984665,33958.296875,-1.09366840951255E-5,1.44150191911172E-6,1,0.999253354069792,40.0298881530762,1.9912204589915,17.000000923872,-0.00010053013277182,-0.000148865193334706,0.25,-1.12307626682169E-5,-1.08678610061563E-5,-1.13237904355007E-5,49.9984665,49.9984665,33950.56640625,33966.02734375,57.9171100179677,20.7199507603135,17.593889,0,0,0,40,4449,49.95455,33958.296875,,,,,,,,,,,,,0,,,,-0.0049,,,,,,49.9984665,,,,
,29263127.525,49.99943925,29201.021484375,9.3906251205722E-6,8.59958581532725E-7,1,0.999253354069792,40.0298881530762,1.9913746024264,17.000000923872,0.000135685791911667,-0.000146382061726379,0.25,-1.46741038439796E-5,9.50699225500781E-6,-1.46188869779778E-5,49.9992752,49.9996033,29193.306640625,29208.736328125,57.7936127119292,20.7198481506311,17.593889,0,0,0,40,4449,49.9545,29201.021484375,,,,,,,,,,,,,0,,,,-0.00245,,,,,,49.99943925,,,,
,29263220.35,49.9985847,24563.064453125,3.12473369192699E-5,9.22312063385767E-7,1,0.999253354069792,40.0298881530762,1.99143561700424,17.000000923872,0.000371035652484512,-4.08467888469004E-5,0.25,-9.25348985409617E-6,3.13367204563653E-5,-9.02935065965743E-6,49.9985847,49.9985847,24550.466796875,24575.662109375,57.81315342491,20.7220847016073,17.214239,0,0,0,40,4449,49.95955,24563.064453125,,,,,,,,,,,,,0,,,,-0.00245,,,,,,49.9985847,,,,
,29263314.345,49.998497,19865.6591796875,4.90020721633959E-5,1.12665140285159E-6,1,0.999253354069792,40.0298881530762,1.99137646357433,17.000000923872,0.000557269866562328,7.15137823209499E-5,0.25,-2.48472236206927E-6,4.90410074802125E-5,-2.12294721372237E-6,49.998497,49.998497,19863.3671875,19867.951171875,57.8772469634869,20.7225488802162,17.593889,0,0,0,40,4449,49.9677,19865.6591796875,,,,,,,,,,,,,0,,,,0.0049,,,,,,49.998497,,,,
,29263407.395,49.996727,15215.9365234375,6.01579043402478E-5,9.10911671560404E-7,1,0.999253354069792,40.0298881530762,1.98973008389338,17.000000923872,0.000684615739606411,8.10864673565878E-5,0.25,-3.63953644803777E-6,6.0194669909342E-5,-3.19341891210484E-6,49.996727,49.996727,15211.2119140625,15220.6611328125,57.7779801415446,20.7270077036071,17.593889,0,0,0,40,4449,49.96315,15215.9365234375,,,,,,,,,,,,,0,,,,-0.0049,,,,,,49.996727,,,,
,29263501.935,49.9975777,10491.0283203125,8.58901376182197E-5,6.25497696683809E-7,1,0.999253354069792,40.0298881530762,1.99143712938164,17.000000923872,0.000974171085764186,0.00013712774169589,0.25,-3.30731522354309E-6,8.5906741831068E-5,-2.66815551177765E-6,49.9975777,49.9975777,10478.4775390625,10503.5791015625,57.9053855901792,20.7245453228667,17.593889,0,0,0,40,4449,49.96005,10491.0283203125,,,,,,,,,,,,,0,,,,-0.0049,,,,,,49.9975777,,,,
,29263592.165,50.0027924,5983.298828125,9.72761084158844E-5,4.75471533483583E-7,1,0.999253354069792,40.0298881530762,1.99135794602233,17.000000923872,0.00109813987208108,0.00018231617952804,0.25,-1.34399106886546E-6,9.72546772534896E-5,-6.19654881387002E-7,50.0027924,50.0027924,5975.95654296875,5990.64111328125,57.8076820252753,20.7213440925886,17.214239,0,0,0,40,4449,49.958,5983.298828125,,,,,,,,,,,,,0,,,,0,,,,,,50.0027924,,,,
,29263684.44,49.9990463,1366.90051269531,9.2084954237712E-5,3.00826706276509E-7,1,0.999253354069792,40.0298881530762,1.99130587027101,17.000000923872,0.00103719438643766,0.000184237370792274,0.25,-2.33848532496727E-7,9.20383397686794E-5,4.51305293494294E-7,49.9990463,49.9990463,1356.75317382812,1377.0478515625,57.8084636537946,20.7183427340777,17.593889,0,0,0,40,4449,49.9635,1366.90051269531,,,,,,,,,,,,,0,,,,0,,,,,,49.9990463,,,,
,29263712.95,50.0033264,-0.312087342143059,8.57431656352761E-6,3.89976728498885E-7,1,0.999253354069792,40.0298881530762,1.99155021699989,17.000000923872,9.70792391199879E-5,1.44055235291434E-5,0.25,-2.66069444600328E-7,8.57141388097643E-6,-2.0214374853168E-7,50.0033264,50.0033264,-0.3349229991436,-0.289251685142517,57.9530649298523,20.7168223730675,17.593889,0,0,0,40,4417,49.95805,-0.312087342143059,,,,,,,,,,,,,0,,,,0,,,,,,50.0033264,,,,