File: data/looselyPackedNP/sc-ios-7/ppms/rawdata/ES_S17_FCW_100OE.DAT
[Header]
; VSM Data File (default extension .dat)
; Copyright (c) 2003-2013, Quantum Design, Inc. All rights reserved.
TITLE,
FILEOPENTIME,29344178.17,12/06/2018,11:10 pm
BYAPP,VSM,2.0,2.0
INFO,PPMS VSM Option Release 1.4.10 Build 1,APPNAME
INFO,Quantum Design Linear Motor Servo Controller,MOTOR_MODULE_NAME
INFO,3101-100 M1,MOTOR_HW_VERSION
INFO,MMC1014,MOTOR_SERIAL_NUMBER
INFO,SRV No X-over 01.03.11,MOTOR_SOFTWARE_VERSION
INFO,Quantum Design VSM Detection Module,VSM_MODULE_NAME
INFO,3101-150 F0,VSM_HW_VERSION
INFO,VSM707,VSM_SERIAL_NUMBER
INFO,VSM No X-over 01.02.05 May 20 2008 13:51:47,VSM_SOFTWARE_VERSION
INFO,704,PREAMP_SERIAL_NUMBER
INFO,822,COIL_SERIAL_NUMBER
INFO,0,MOMENT_UNITS
INFO,Iron Oxide Spheres,SAMPLE_MATERIAL
INFO,7 nm diameter, collaboration Mainz,SAMPLE_COMMENT
INFO,,SAMPLE_MASS
INFO,,SAMPLE_VOLUME
INFO,,SAMPLE_MOLECULAR_WEIGHT
INFO,,SAMPLE_SIZE
INFO,,SAMPLE_SHAPE
DATATYPE,COMMENT,1
DATATYPE,TIME,2
STARTUPAXIS,X,2
STARTUPAXIS,Y1,5
[Data]
Comment,Time Stamp (sec),Temperature (K),Magnetic Field (Oe),Moment (emu),M. Std. Err. (emu),Transport Action,Averaging Time (sec),Frequency (Hz),Peak Amplitude (mm),Center Position (mm),Coil Signal' (mV),Coil Signal" (mV),Range (mV),M. Quad. Signal (emu),M. Raw' (emu),M. Raw" (emu),Min. Temperature (K),Max. Temperature (K),Min. Field (Oe),Max. Field (Oe),Mass (grams),Motor Lag (deg),Pressure (Torr),VSM Status (code),Motor Status (code),Measure Status (code),Measure Count,PPMS Status (code),System Temp. (K),System Field (Oe),Sample Position (deg),Bridge 1 Resistance (ohms),Bridge 1 Excitation (에),Bridge 2 Resistance (ohms),Bridge 2 Excitation (에),Bridge 3 Resistance (ohms),Bridge 3 Excitation (에),Bridge 4 Resistance (ohms),Bridge 4 Excitation (에),Signal 1 Vin (V),Signal 2 Vin (V),Digital Inputs (code),Drive 1 Iout (mA),Drive 1 Ipower (W),Drive 2 Iout (mA),Drive 2 Ipower (W),Pressure (),Map 20 (),Map 21 (),Map 22 (),Map 23 (),Map 24 (),Map 25 (),Map 26 (),Map 27 (),Map 28 (),Map 29 ()
,29344334.595,10.0390806,99.5482559204102,3.23981659950121E-5,2.81408946161168E-7,1,0.999253354069792,40.0298881530762,2.00120767287499,16.8299991637468,0.000364878802693128,6.3926309785455E-5,0.25,-7.46973175712845E-8,3.22124901830399E-5,8.19823859601519E-8,10.0390806,10.0390806,99.5482559204102,99.5482559204102,57.6466665503138,20.7462134578997,11.899124,0,0,0,40,4369,9.90675,99.5482559204102,,,,,,,,,,,,,0,,,,0.00245,,,,,,10.0390806,,,,
,29344457.44,13.0030336,99.5482559204102,3.22722345732523E-5,2.91072928383695E-7,1,0.999253354069792,40.0298881530762,1.99883772986369,16.8299991637468,0.000362761799130543,6.52154852917384E-5,0.25,6.87671614758805E-8,3.20864048576556E-5,2.2401442830227E-7,13.0030336,13.0030336,99.5482559204102,99.5482559204102,57.5497446139292,20.7607416375062,12.658426,0,0,0,40,4370,12.8936,99.5482559204102,,,,,,,,,,,,,0,,,,0.0049,,,,,,13.0030336,,,,
,29344602.085,16.6166115,99.5482559204102,3.21357059044767E-5,3.6175937123194E-7,1,0.999253354069792,40.0298881530762,1.99825381323018,16.8299991637468,0.000361332016421793,6.37426601264145E-5,0.25,-3.63278246274897E-8,3.19508475347419E-5,1.18863877348347E-7,16.6166115,16.6166115,99.5482559204102,99.5482559204102,57.3152560581599,20.7668235334765,13.797379,0,0,0,40,4370,16.52765,99.5482559204102,,,,,,,,,,,,,0,,,,-0.0049,,,,,,16.6166115,,,,
,29344740.765,20.0403233,99.5482559204102,3.23350946192946E-5,3.08517293885775E-7,1,0.999253354069792,40.0298881530762,1.99814205541168,16.8299991637468,0.000363644901812026,6.36479276861199E-5,0.25,-8.07766950424754E-8,3.214963543201E-5,7.64865679714134E-8,20.0403233,20.0403233,99.5482559204102,99.5482559204102,57.6294707228907,20.7679747531513,14.556682,0,0,0,40,4370,20.0179,99.5482559204102,,,,,,,,,,,,,0,,,,0.00245,,,,,,20.0403233,,,,
,29344883.405,23.5133419,99.5482559204102,3.17495351856182E-5,3.4587024706777E-7,1,0.999253354069792,40.0298881530762,1.99845738881506,16.8299991637468,0.000356971437888603,6.35146439571818E-5,0.25,5.74907197147966E-9,3.15702085455146E-5,1.63858262376324E-7,23.5133419,23.5133419,99.5482559204102,99.5482559204102,57.8154983104676,20.7678141072977,14.556682,0,0,0,40,4370,23.6233,99.5482559204102,,,,,,,,,,,,,0,,,,0.0049,,,,,,23.5133419,,,,
,29345025.84,27.0372677,99.5482559204102,3.13623971800406E-5,3.47276675968422E-7,1,0.999253354069792,40.0298881530762,1.99878221105776,16.8299991637468,0.000352413555203424,6.46438785310681E-5,0.25,1.65268518437611E-7,3.11910060044761E-5,3.28192931774887E-7,27.0372677,27.0372677,99.5482559204102,99.5482559204102,57.7975208545254,20.7647180538253,14.556682,0,0,0,40,4370,27.2322,99.5482559204102,,,,,,,,,,,,,0,,,,0.00245,,,,,,27.0372677,,,,
,29345145.44,30.0520115,99.5482559204102,3.07490693664003E-5,3.50680369256863E-7,1,0.999253354069792,40.0298881530762,1.99910558857967,16.8800000101328,0.000346139530282987,6.07825706200385E-5,0.25,-7.9972883538255E-8,3.05908593369268E-5,8.98038172899388E-8,30.0520115,30.0520115,99.5482559204102,99.5482559204102,57.6255625802946,20.7651081798889,14.936333,0,0,0,40,4370,30.2558,99.5482559204102,,,,,,,,,,,,,0,,,,0,,,,,,30.0520115,,,,
,29345287.695,33.5035057,99.5482559204102,3.00679703033651E-5,3.3702711592652E-7,1,0.999253354069792,40.0298881530762,2.00009564404142,16.8800000101328,0.000338961433622571,5.85648744698987E-5,0.25,-1.73084541577317E-7,2.99281655521382E-5,5.83117367150591E-9,33.5035057,33.5035057,99.5482559204102,99.5482559204102,57.4692368764484,20.7579281802003,15.695635,0,0,0,40,4370,33.85195,99.5482559204102,,,,,,,,,,,,,0,,,,0,,,,,,33.5035057,,,,
,29345429.485,37.0387917,99.5482559204102,2.91079731881763E-5,3.08369739395791E-7,1,0.999253354069792,40.0298881530762,2.00113295601267,16.8800000101328,0.000328048615081969,5.93768154952644E-5,0.25,5.12593860123112E-8,2.89901980330984E-5,2.36796466356564E-7,37.0387917,37.0387917,99.5482559204102,99.5482559204102,57.7474966292946,20.7488906994731,16.454937,0,0,0,40,4370,37.4313,99.5482559204102,,,,,,,,,,,,,0,,,,-0.00245,,,,,,37.0387917,,,,
,29345569.89,40.5340538,99.5482559204102,2.79935516588651E-5,3.27935119936852E-7,1,0.999253354069792,40.0298881530762,1.99983345314314,16.8699994683266,0.000315326350780355,5.8372322038863E-5,0.25,1.48717182003932E-7,2.79023995033859E-5,3.39075444871898E-7,40.5340538,40.5340538,99.5482559204102,99.5482559204102,57.5888260398907,20.7538357037146,16.075285,0,0,0,40,4370,40.9539,99.5482559204102,,,,,,,,,,,,,0,,,,0,,,,,,40.5340538,,,,
,29345713.37,44.0434303,99.5482559204102,2.6827424151083E-5,3.03833595116369E-7,1,0.999253354069792,40.0298881530762,2.00047420456531,16.8800000101328,0.000303365172669453,5.17018427741244E-5,0.25,-2.4914524437908E-7,2.67698578228372E-5,-5.58848189775916E-8,44.0434303,44.0434303,99.5482559204102,99.5482559204102,57.7912678263715,20.7543390041888,16.834587,0,0,0,40,4370,44.6031,99.5482559204102,,,,,,,,,,,,,0,,,,0,,,,,,44.0434303,,,,
,29345855.39,47.5405121,99.5482559204102,2.57513924977463E-5,3.10439913277132E-7,1,0.999253354069792,40.0298881530762,2.00018643321783,16.8699994683266,0.000290997174847797,5.23517494419744E-5,0.25,-7.68902446039277E-9,2.57227962783427E-5,1.82818468767417E-7,47.5405121,47.5405121,99.5482559204102,99.5482559204102,57.4856510753522,20.7544994249484,16.834587,0,0,0,40,4370,48.20005,99.5482559204102,,,,,,,,,,,,,0,,,,0.0049,,,,,,47.5405121,,,,
,29345998.145,51.0229416,99.5482559204102,2.43813118904159E-5,3.12163536522697E-7,1,0.999253354069792,40.0298881530762,1.99883275591856,16.8500002473593,0.000276191143559114,4.66007409381523E-5,0.25,-2.72434602786274E-7,2.43840807254882E-5,-9.12304404354227E-8,51.0229416,51.0229416,99.5482559204102,99.5482559204102,57.7873596837753,20.7701000055347,17.214239,0,0,0,40,4370,51.83915,99.5482559204102,,,,,,,,,,,,,0,,,,-0.00245,,,,,,51.0229416,,,,
,29346144.34,54.5466194,99.5482559204102,2.34551193728062E-5,3.20845872570467E-7,1,0.999253354069792,40.0298881530762,1.99871692639199,16.8500002473593,0.000265573526732144,4.71585674141695E-5,0.25,-5.68592605660823E-8,2.34827638358155E-5,1.13826912231581E-7,54.5466194,54.5466194,99.5482559204102,99.5482559204102,57.7326456874292,20.7749995954632,18.353191,0,0,0,40,4374,55.606,99.5482559204102,,,,,,,,,,,,,0,,,,0,,,,,,54.5466194,,,,
,29346286.345,58.00761795,99.5482559204102,2.21837369138079E-5,3.9323719463347E-7,1,0.999253354069792,40.0298881530762,1.99912024357297,16.8500002473593,0.000251844360971441,4.2573765215035E-5,0.25,-2.30742851180313E-7,2.2232724218485E-5,-7.62315436335211E-8,57.9821167,58.0331192,99.5482559204102,99.5482559204102,57.8092452823138,20.7758307709665,19.112494,0,0,0,40,4374,59.23735,99.5482559204102,,,,,,,,,,,,,0,,,,0,,,,,,58.00761795,,,,
,29346408.6,61.0143051,99.5482559204102,2.16301026189809E-5,3.4342708174764E-7,1,0.999253354069792,40.0298881530762,1.99929248687117,16.8299991637468,0.000246078140812928,3.97440102345914E-5,0.25,-3.7653257341672E-7,2.16944411546026E-5,-2.33582533058517E-7,61.0143051,61.0143051,99.5482559204102,99.5482559204102,57.5685036983907,20.7735762692286,19.112494,0,0,0,40,4374,62.3618,99.5482559204102,,,,,,,,,,,,,0,,,,-0.0049,,,,,,61.0143051,,,,
,29346553,64.5632401,99.5482559204102,2.01772976941171E-5,3.39773429649933E-7,1,0.999253354069792,40.0298881530762,1.99944169298725,16.8299991637468,0.000228928965677346,4.15431528012486E-5,0.25,4.86669513095729E-8,2.0248743002458E-5,1.74558601626206E-7,64.5632401,64.5632401,99.5482559204102,99.5482559204102,57.5896076684099,20.7700052273332,19.871798,0,0,0,40,4374,65.9818,99.5482559204102,,,,,,,,,,,,,0,,,,0,,,,,,64.5632401,,,,
,29346693.32,68.0259628,99.5482559204102,1.93932890188814E-5,3.5214986803907E-7,1,0.999253354069792,40.0298881530762,1.99956035166245,16.8299991637468,0.000220179838221572,3.98769196765404E-5,0.25,4.85522378978865E-8,1.9472618222191E-5,1.61141373969627E-7,68.0259628,68.0259628,99.5482559204102,99.5482559204102,57.7381170870638,20.7740860550698,20.251448,0,0,0,40,4374,69.54055,99.5482559204102,,,,,,,,,,,,,0,,,,-0.0049,,,,,,68.0259628,,,,
touchdown = 11.1499996855855 mm,29346829.325,71.3952713,99.5482559204102,1.88095181713694E-5,3.41782942167551E-7,1,0.999253354069792,40.0298881530762,1.99931682437412,16.8099999427795,0.000214366295671918,3.44773702996173E-5,0.25,-3.15701791853717E-7,1.88963362669083E-5,-2.15903898896681E-7,71.3952713,71.3952713,99.5482559204102,99.5482559204102,57.3441763133715,20.7681709023444,20.251448,0,0,0,40,4374,72.99795,99.5482559204102,,,,,,,,,,,,,0,,,,-0.0049,,,,,,71.3952713,,,,
,29346956.57,74.5430603,99.5482559204102,1.81641694182418E-5,3.53936611982226E-7,1,0.999253354069792,40.0298881530762,1.99993752277148,16.8099999427795,0.000206291747382152,3.80530266696883E-5,0.25,1.1848996339537E-7,1.82513084056333E-5,2.10232261374643E-7,74.5430603,74.5430603,99.5482559204102,99.5482559204102,57.789704569333,20.7812703102808,20.251448,0,0,0,40,4374,76.1948,99.5482559204102,,,,,,,,,,,,,0,,,,0.0049,,,,,,74.5430603,,,,
,29347098.14,78.031189,99.5482559204102,1.72723794276119E-5,3.23052952064E-7,1,0.999253354069792,40.0298881530762,2.00015099597768,16.8099999427795,0.000196619186002067,3.40338703960883E-5,0.25,-7.10782121134512E-8,1.73607057462752E-5,8.74243468492475E-9,78.031189,78.031189,99.5482559204102,99.5482559204102,57.7232661451984,20.7640376815346,19.871798,0,0,0,40,4374,79.782,99.5482559204102,,,,,,,,,,,,,0,,,,0,,,,,,78.031189,,,,
touchdown = 11.119999922812 mm,29347254.86,81.8906784,99.5482559204102,1.62223656656734E-5,3.3403650280561E-7,1,0.999253354069792,40.0298881530762,2.00013277273794,16.780000180006,0.000184962588483411,3.05108241211872E-5,0.25,-1.88987515978127E-7,1.63093426690893E-5,-1.20837508674249E-7,81.8906784,81.8906784,99.5482559204102,99.5482559204102,57.5388018146599,20.7613121421353,20.251448,0,0,0,40,4374,83.77225,99.5482559204102,,,,,,,,,,,,,0,,,,-0.00245,,,,,,81.8906784,,,,
,29347384.64,85.0656662,99.5482559204102,1.56544567964641E-5,3.12264482915795E-7,1,0.999253354069792,40.0298881530762,2.0007082998663,16.780000180006,0.000178193041044121,3.15237809426232E-5,0.25,3.76479166887234E-9,1.57396167340813E-5,6.61531261289467E-8,85.0656662,85.0656662,99.5482559204102,99.5482559204102,57.5098815594484,20.7570392546223,20.631098,0,0,0,40,4374,87.0288,99.5482559204102,,,,,,,,,,,,,0,,,,0.0049,,,,,,85.0656662,,,,
,29347521.32,88.5114212,99.5482559204102,1.46341993888691E-5,3.38152745716022E-7,1,0.999253354069792,40.0298881530762,2.00021579155172,16.780000180006,0.000167181054702591,2.59237027718023E-5,0.25,-3.03742899985183E-7,1.47163758077423E-5,-2.51012322272344E-7,88.4737625,88.5490799,99.5482559204102,99.5482559204102,57.7342089444676,20.7721389720014,20.631098,0,0,0,40,4374,90.46195,99.5482559204102,,,,,,,,,,,,,0,,,,-0.0049,,,,,,88.5114212,,,,
touchdown = 11.0900001600385 mm,29347676.005,92.3796844,99.5482559204102,1.43720603887758E-5,3.33731781802815E-7,1,0.999253354069792,40.0298881530762,2.00141854315992,16.7500004172325,0.000164083405007954,2.66578079777001E-5,0.25,-1.90664504678608E-7,1.44533759488178E-5,-1.42163200307549E-7,92.3796844,92.3796844,99.5482559204102,99.5482559204102,57.362935397833,20.7474100717015,21.01075,0,0,0,40,4374,94.3469,99.5482559204102,,,,,,,,,,,,,0,,,,0,,,,,,92.3796844,,,,
,29347803.87,95.5388565,99.5482559204102,1.37005431262951E-5,3.63375513659701E-7,1,0.999253354069792,40.0298881530762,2.0014969926167,16.7500004172325,0.000156544029610022,2.47548655138277E-5,0.25,-2.36908274158195E-7,1.37787242713298E-5,-1.93721944638877E-7,95.5388565,95.5388565,99.5482559204102,99.5482559204102,57.6802765766407,20.7509201740573,21.01075,0,0,0,40,4374,97.55405,99.5482559204102,,,,,,,,,,,,,0,,,,0.00245,,,,,,95.5388565,,,,
,29347944.92,99.0456085,99.5482559204102,1.32457586725967E-5,3.40996005048902E-7,1,0.999253354069792,40.0298881530762,2.00118465405019,16.7500004172325,0.000150912720303177,2.62919536992769E-5,0.25,-1.90596602938917E-8,1.33209451648014E-5,2.12455447799964E-8,99.0456085,99.0456085,99.5482559204102,99.5482559204102,57.6966907755446,20.7464776990833,21.01075,0,0,0,40,4374,101.0956,99.5482559204102,,,,,,,,,,,,,0,,,,0.0049,,,,,,99.0456085,,,,
touchdown = 11.0499998554587 mm,29348090.65,102.6731415,99.5482559204102,1.28402625519555E-5,3.45399210001588E-7,1,0.999253354069792,40.0298881530762,2.00178822808418,16.7100001126528,0.000146780878928244,2.29564482749334E-5,0.25,-2.38857327101353E-7,1.29138327975325E-5,-2.0342047491026E-7,102.6731415,102.6731415,99.5482559204102,99.5482559204102,57.5372385576215,20.7479497973489,21.3904,0,0,0,40,4374,104.77455,99.5482559204102,,,,,,,,,,,,,0,,,,0.00245,,,,,,102.6731415,,,,
,29348225.7,106.0122299,99.5482559204102,1.26178171644854E-5,3.40363723721766E-7,1,0.999253354069792,40.0298881530762,2.00208883799848,16.7100001126528,0.000144406820897977,2.17066994468613E-5,0.25,-3.07803930738883E-7,1.26901569091659E-5,-2.75345783594956E-7,106.0122299,106.0122299,99.5482559204102,99.5482559204102,57.6927826329484,20.7431550368425,21.3904,0,0,0,40,4374,108.17625,99.5482559204102,,,,,,,,,,,,,0,,,,-0.00245,,,,,,106.0122299,,,,
,29348367.09,109.5054321,99.5482559204102,1.19363614677189E-5,4.04976692928959E-7,1,0.999253354069792,40.0298881530762,2.00217461005005,16.7100001126528,0.000136589633737089,2.06502239855827E-5,0.25,-2.79307266892222E-7,1.20044616623882E-5,-2.50273579803281E-7,109.5054321,109.5054321,99.5482559204102,99.5482559204102,57.4887775894292,20.7389442573409,21.770052,0,0,0,40,4374,111.7236,99.5482559204102,,,,,,,,,,,,,0,,,,-0.0049,,,,,,109.5054321,,,,
touchdown = 11.0200000926852 mm,29348510.65,113.1080933,99.5482559204102,1.18012676621964E-5,3.32295808656152E-7,1,0.999253354069792,40.0298881530762,2.00072479564389,16.6800003498793,0.000134808210205095,2.11856254544484E-5,0.25,-2.05723181518975E-7,1.18679923964716E-5,-1.78206041798391E-7,113.1080933,113.1080933,99.5482559204102,99.5482559204102,57.4481329064291,20.7551260821974,22.149702,0,0,0,40,4374,115.3407,99.5482559204102,,,,,,,,,,,,,0,,,,0,,,,,,113.1080933,,,,
,29348649.87,116.551445,99.5482559204102,1.14014475454007E-5,3.07219452881912E-7,1,0.999253354069792,40.0298881530762,2.00092053793616,16.6900008916855,0.000130463994039406,1.92321760787755E-5,0.25,-3.06000717054311E-7,1.14656775683546E-5,-2.81354065189528E-7,116.551445,116.551445,99.5482559204102,99.5482559204102,57.6028953532369,20.7487237948536,21.770052,0,0,0,40,4374,118.8316,99.5482559204102,,,,,,,,,,,,,0,,,,0.00245,,,,,,116.551445,,,,
,29348788.94,120.0042648,99.5482559204102,1.08789157766617E-5,3.33839775810771E-7,1,0.999253354069792,40.0298881530762,2.00186831217491,16.6900008916855,0.000123851673170933,2.22651920092779E-5,0.25,5.20945817714838E-8,1.09388942824709E-5,7.63507281267598E-8,120.0042648,120.0042648,99.5482559204102,99.5482559204102,57.7131049744484,20.7368733343832,21.3904,0,0,0,40,4374,122.3269,99.5482559204102,,,,,,,,,,,,,0,,,,0,,,,,,120.0042648,,,,
touchdown = 10.9700001776218 mm,29348929.875,123.4942932,99.5482559204102,1.1048314228168E-5,3.46544251370456E-7,1,0.999253354069792,40.0298881530762,2.00123007539022,16.6299995034933,0.000125441316982936,2.42855315528923E-5,0.25,2.01655422245693E-7,1.11083181110666E-5,2.25990587326581E-7,123.4942932,123.4942932,99.5482559204102,99.5482559204102,57.2824276603522,20.7314547686701,22.149702,0,0,0,40,4374,125.88135,99.5482559204102,,,,,,,,,,,,,0,,,,0,,,,,,123.4942932,,,,
,29349050.43,126.52245715,99.5482559204102,1.05576588014936E-5,3.22779949512642E-7,1,0.999253354069792,40.0298881530762,2.00118205572656,16.6400000452995,0.000120361884667289,2.03410206446357E-5,0.25,-5.79610422734929E-8,1.06149676538568E-5,-3.69029515996759E-8,126.4957352,126.5491791,99.5482559204102,99.5482559204102,57.2863358029484,20.7409620282245,22.149702,0,0,0,40,4374,128.8954,99.5482559204102,,,,,,,,,,,,,0,,,,0,,,,,,126.52245715,,,,
,29349191.395,130.0237427,99.5482559204102,9.91860480801557E-6,3.64313250913875E-7,1,0.999253354069792,40.0298881530762,2.00078218379113,16.6299995034933,0.000113801271238215,1.47867036427693E-5,0.25,-4.32841231748283E-7,9.97253081069448E-6,-4.15925246500481E-7,130.0237427,130.0237427,99.5482559204102,99.5482559204102,57.3559007411599,20.7516594465037,22.529354,0,0,0,40,4374,132.441,99.5482559204102,,,,,,,,,,,,,0,,,,0,,,,,,130.0237427,,,,
,29349329.69,133.4576569,99.5482559204102,,,2,,,,16.5999998730421,,,,,,,133.4576569,133.4576569,99.5482559204102,99.5482559204102,,,22.149702,,,,-99999999,4374,135.902,99.5482559204102,,,,,,,,,,,,,,,,,,,,,,,133.4576569,,,,
,29349453.66,136.5414581,99.5482559204102,9.45892175384277E-6,3.6705930387806E-7,1,0.999253354069792,40.0298881530762,2.00332293899467,16.5899991989136,0.000108565405742376,1.45645689556593E-5,0.25,-3.72152500068813E-7,9.50896292431815E-6,-3.57085759770572E-7,136.5414581,136.5414581,99.5482559204102,99.5482559204102,57.5896076684099,20.7281841039961,22.909004,0,0,0,40,4374,139.0264,99.5482559204102,,,,,,,,,,,,,0,,,,0.00245,,,,,,136.5414581,,,,
,29349592.435,140.0090179,99.5482559204102,9.31570679570019E-6,2.79278302199474E-7,1,0.999253354069792,40.0298881530762,2.00260299093817,16.5899991989136,0.000107082880677426,1.3154873744023E-5,0.25,-4.6973544574672E-7,9.36443516082217E-6,-4.5601762977627E-7,140.0090179,140.0090179,99.5482559204102,99.5482559204102,57.5278590153907,20.743072667394,22.149702,0,0,0,40,4374,142.5009,99.5482559204102,,,,,,,,,,,,,0,,,,0,,,,,,140.0090179,,,,
,29349746.84,143.8254852,99.5482559204102,,,2,,,,16.5599995684624,,,,,,,143.8254852,143.8254852,99.5482559204102,99.5482559204102,,,22.529354,,,,-99999999,4374,146.3842,99.5482559204102,,,,,,,,,,,,,,,,,,,,,,,143.8254852,,,,
,29349875.11,147.054184,99.5482559204102,9.0312591100771E-6,3.0639918934301E-7,1,0.999253354069792,40.0298881530762,2.00316403965084,16.550000756979,0.000102862737202007,1.82675865580304E-5,0.25,2.94702724642385E-8,9.07617665347982E-6,4.41646166815141E-8,147.054184,147.054184,99.5482559204102,99.5482559204102,57.5856995258138,20.7291603326685,22.529354,0,0,0,40,4374,149.6005,99.5482559204102,,,,,,,,,,,,,0,,,,-0.0049,,,,,,147.054184,,,,
,29350014.685,150.5341034,99.5482559204102,8.60192062950821E-6,3.80270264539674E-7,1,0.999253354069792,40.0298881530762,2.00335512064597,16.550000756979,9.87566056789133E-5,1.29019184360118E-5,0.25,-3.66106753874192E-7,8.64458027163371E-6,-3.54501863610822E-7,150.5341034,150.5341034,99.5482559204102,99.5482559204102,57.6888744903523,20.7238150547468,22.909004,0,0,0,40,4374,153.09805,99.5482559204102,,,,,,,,,,,,,0,,,,0,,,,,,150.5341034,,,,
,29350163.55,154.2120514,99.5482559204102,,,2,,,,16.5200001952052,,,,,,,154.2120514,154.2120514,99.5482559204102,99.5482559204102,,,22.529354,,,,-99999999,4374,156.8268,99.5482559204102,,,,,,,,,,,,,,,,,,,,,,,154.2120514,,,,
,29350294.465,157.5068359,99.5482559204102,8.65591949775284E-6,3.47949897243542E-7,1,0.999253354069792,40.0298881530762,2.00328239768482,16.5199991315603,9.87694473004696E-5,1.63434898566044E-5,0.25,-7.23828642936165E-8,8.69682407085828E-6,-6.00808183127105E-8,157.5068359,157.5068359,99.5482559204102,99.5482559204102,57.4082698519484,20.7202057218757,22.909004,0,0,0,40,4374,160.10985,99.5482559204102,,,,,,,,,,,,,0,,,,0,,,,,,157.5068359,,,,
,29350435.4,161.0077209,99.5482559204102,8.19594358226995E-6,3.75184016916753E-7,1,0.999253354069792,40.0298881530762,2.00355845340709,16.5100004523993,9.3939692154943E-5,1.3089042688085E-5,0.25,-2.7762355078544E-7,8.23419958097629E-6,-2.67295716478406E-7,161.0077209,161.0077209,99.5482559204102,99.5482559204102,57.8280043667753,20.7265539105327,23.288654,0,0,0,40,4374,163.6391,99.5482559204102,,,,,,,,,,,,,0,,,,0.00245,,,,,,161.0077209,,,,
,29350579.38,164.622879,99.5482559204102,,,2,,,,16.4700002801418,,,,,,,164.622879,164.622879,99.5482559204102,99.5482559204102,,,23.288654,,,,-99999999,4374,167.2435,99.5482559204102,,,,,,,,,,,,,,,,,,,,,,,164.622879,,,,
,29350694.725,167.5344391,99.5482559204102,7.97071634146077E-6,3.12682721837223E-7,1,0.999253354069792,40.0298881530762,1.99077215310498,16.4700001478195,9.07754867648294E-5,1.27048698022511E-5,0.25,-2.64518233829172E-7,8.00645436498248E-6,-2.54991461843783E-7,167.5344391,167.5344391,99.5482559204102,99.5482559204102,57.6654256347753,20.7247947578898,22.909004,0,0,0,40,4374,170.13085,99.5482559204102,,,,,,,,,,,,,0,,,,-0.00245,,,,,,167.5344391,,,,
,29350835.695,171.002594,99.5482559204102,7.5869171230485E-6,3.34276599843978E-7,1,0.999253354069792,40.0298881530762,1.99076736770221,16.4599996060133,8.64699600895498E-5,1.16652176796601E-5,0.25,-2.89187273863942E-7,7.62022605931495E-6,-2.80537021805566E-7,171.002594,171.002594,99.5482559204102,99.5482559204102,57.6622991206984,20.7257492750065,23.288654,0,0,0,40,4374,173.6643,99.5482559204102,,,,,,,,,,,,,0,,,,-0.0049,,,,,,171.002594,,,,
,29350974.995,174.5185699,99.5482559204102,7.77579784517272E-6,3.35874473572299E-7,1,0.999253354069792,40.0298881530762,1.99084535119121,16.4599996060133,8.89114151075135E-5,1.02609647764971E-5,0.25,-4.45737662600522E-7,7.80932315302951E-6,-4.37741828644391E-7,174.5185699,174.5185699,99.5482559204102,99.5482559204102,57.8217513386215,20.7267268176288,23.288654,0,0,0,40,4374,177.1458,99.5482559204102,,,,,,,,,,,,,0,,,,0,,,,,,174.5185699,,,,
,29351096.445,177.574295,99.5482559204102,7.7254662375657E-6,3.23536445087099E-7,1,0.999253354069792,40.0298881530762,1.99063934500882,16.4100006222725,8.80746825386162E-5,1.15986121235476E-5,0.25,-3.18422835639934E-7,7.75791230020565E-6,-3.10142254736778E-7,177.574295,177.574295,99.5482559204102,99.5482559204102,57.3770047111791,20.7243004171273,22.909004,0,0,0,40,4374,180.18465,99.5482559204102,,,,,,,,,,,,,0,,,,0,,,,,,177.574295,,,,
,29351238.095,181.0739594,99.5482559204102,7.26500160145818E-6,3.7319636915112E-7,1,0.999253354069792,40.0298881530762,1.9902711006099,16.4199993014336,8.24442460266978E-5,1.29610965639295E-5,0.25,-1.17454795477531E-7,7.29452497923217E-6,-1.09129126107267E-7,181.0739594,181.0739594,99.5482559204102,99.5482559204102,57.6021137247176,20.7480260167521,23.288654,0,0,0,40,4374,183.7293,99.5482559204102,,,,,,,,,,,,,0,,,,0,,,,,,181.0739594,,,,
,29351374.1,184.507782,99.5482559204102,7.20159896306522E-6,3.62405331755274E-7,1,0.999253354069792,40.0298881530762,1.98744595975048,16.4100006222725,8.17840445022972E-5,1.18016360355849E-5,0.25,-2.07164107918353E-7,7.23021888340991E-6,-1.99462287519212E-7,184.507782,184.507782,99.5482559204102,99.5482559204102,57.4708001334869,20.7669923351727,23.288654,0,0,0,40,4374,187.12365,99.5482559204102,,,,,,,,,,,,,0,,,,0,,,,,,184.507782,,,,
,29351494.635,187.520813,99.5482559204102,6.95567448155742E-6,3.34362270535434E-7,1,0.999253354069792,40.0298881530762,2.00099455875289,16.3599997758865,7.93951281507496E-5,1.20626678162179E-5,0.25,-1.47959811070376E-7,6.98260868424273E-6,-1.40470444224043E-7,187.520813,187.520813,99.5482559204102,99.5482559204102,57.1651833824676,20.7404328256649,23.288654,0,0,0,40,4374,190.1424,99.5482559204102,,,,,,,,,,,,,0,,,,-0.0049,,,,,,187.520813,,,,
,29351635.32,191.00791935,99.5482559204102,7.11200935284024E-6,3.22043782520178E-7,1,0.999253354069792,40.0298881530762,1.99919748045376,16.3599997758865,8.1741609047425E-5,8.63603028071422E-6,0.25,-4.75511161730327E-7,7.13914174630435E-6,-4.69241409323226E-7,190.9765015,191.0393372,99.5482559204102,99.5482559204102,57.1894138665637,20.7670235432521,24.047956,0,0,0,40,4374,193.66805,99.5482559204102,,,,,,,,,,,,,0,,,,-0.0049,,,,,,191.00791935,,,,
,29351777.78,194.5470428,99.5482559204102,6.82602113499068E-6,3.82159800910695E-7,1,0.999253354069792,40.0298881530762,1.99879528363648,16.3599997758865,7.75575604996007E-5,1.33127426536995E-5,0.25,-1.36644539888938E-8,6.85080183849553E-6,-6.16739377463431E-9,194.5470428,194.5470428,99.5482559204102,99.5482559204102,57.6920010044292,20.7824604878422,23.668306,0,0,0,40,4374,197.24115,99.5482559204102,,,,,,,,,,,,,0,,,,-0.00245,,,,,,194.5470428,,,,
,29351917.32,198.0137024,99.5482559204102,6.98990159990713E-6,3.95439306715436E-7,1,0.999253354069792,40.0298881530762,2.00115081856139,16.3100007921457,7.98779341958856E-5,1.14710903636789E-5,0.25,-2.05130169441179E-7,7.01471336117713E-6,-1.98294818190501E-7,197.9873352,198.0400696,99.5482559204102,99.5482559204102,57.2980602307368,20.7441128079838,23.668306,0,0,0,40,4374,200.7641,99.5482559204102,,,,,,,,,,,,,0,,,,-0.00245,,,,,,198.0137024,,,,
,29352058.79,201.5814362,99.5482559204102,7.01056223741477E-6,3.47339939689834E-7,1,0.999253354069792,40.0298881530762,1.99976244371125,16.3100007921457,7.98982924355323E-5,1.23799505194631E-5,0.25,-1.27772461309237E-7,7.03455586870589E-6,-1.20791883792144E-7,201.5814362,201.5814362,99.5482559204102,99.5482559204102,57.4997203886984,20.7471356146572,23.288654,0,0,0,40,4374,204.2947,99.5482559204102,,,,,,,,,,,,,0,,,,0,,,,,,201.5814362,,,,
,29352196.61,205.0221558,99.5482559204102,6.2053544735898E-6,3.97750542601877E-7,1,0.999253354069792,40.0298881530762,1.99949417939898,16.3100007921457,7.14918689016281E-5,6.42098208616393E-6,0.25,-5.12182681341542E-7,6.22631013344108E-6,-5.0744031252244E-7,205.0221558,205.0221558,99.5482559204102,99.5482559204102,57.7193580026023,20.7605117110175,24.047956,0,0,0,40,4374,207.74275,99.5482559204102,,,,,,,,,,,,,0,,,,-0.0049,,,,,,205.0221558,,,,
,29352339.41,208.5441742,99.5482559204102,6.49961643778343E-6,3.75821498965898E-7,1,0.999253354069792,40.0298881530762,1.99997639154772,16.2599999457598,7.48266987197687E-5,7.09397884999575E-6,0.25,-5.03956037182935E-7,6.52077145452438E-6,-4.98965190255082E-7,208.5441742,208.5441742,99.5482559204102,99.5482559204102,57.1636201254291,20.7465411840339,24.047956,0,0,0,40,4374,211.3369,99.5482559204102,,,,,,,,,,,,,0,,,,0.0049,,,,,,208.5441742,,,,
,29352479.165,212.0701904,99.5482559204102,6.73888722456982E-6,4.13266530219098E-7,1,0.999253354069792,40.0298881530762,1.99961036018059,16.2599999457598,7.63416148638668E-5,1.43634402742549E-5,0.25,9.49469854826431E-8,6.75941102096301E-6,1.01935413169084E-7,212.0701904,212.0701904,99.5482559204102,99.5482559204102,57.2730481181214,20.7492082504375,24.047956,0,0,0,40,4374,214.81755,99.5482559204102,,,,,,,,,,,,,0,,,,-0.0049,,,,,,212.0701904,,,,
,29352617.36,215.5379028,99.5482559204102,6.23914763532721E-6,3.77070050261669E-7,1,0.999253354069792,40.0298881530762,2.00003984456224,16.270000487566,7.18867308402942E-5,6.38575480576969E-6,0.25,-5.20718918168109E-7,6.25802320396676E-6,-5.16171210267338E-7,215.5379028,215.5379028,99.5482559204102,99.5482559204102,57.474708276083,20.7590873500276,24.047956,0,0,0,40,4374,218.2818,99.5482559204102,,,,,,,,,,,,,0,,,,-0.00245,,,,,,215.5379028,,,,
,29352758.71,219.0569458,99.5482559204102,5.75825828135742E-6,3.22245596044203E-7,1,0.999253354069792,40.0298881530762,1.9767845348833,16.2099990993738,6.47319231555649E-5,1.08363086381947E-5,0.25,-3.44435598874728E-8,5.77456307748765E-6,-2.90380828084417E-8,219.0569458,219.0569458,99.5482559204102,99.5482559204102,57.2253687784484,20.7496205059116,23.668306,0,0,0,40,4374,221.8215,99.5482559204102,,,,,,,,,,,,,0,,,,-0.00245,,,,,,219.0569458,,,,
,29352899.415,222.5376282,99.5482559204102,6.12020047239238E-6,3.8654317832052E-7,1,0.999253354069792,40.0298881530762,1.97707774420108,16.2099990993738,6.99079361070316E-5,5.14717036048899E-6,0.25,-6.03765906301468E-7,6.13734077167326E-6,-5.99663575593818E-7,222.5376282,222.5376282,99.5482559204102,99.5482559204102,57.3957637956407,20.7487046690062,24.047956,0,0,0,40,4374,225.3498,99.5482559204102,,,,,,,,,,,,,0,,,,-0.00245,,,,,,222.5376282,,,,
,29353039.705,226.0376587,99.5482559204102,5.87789923583366E-6,3.60928153080485E-7,1,0.999253354069792,40.0298881530762,1.97782013481389,16.2099990993738,6.59632354868196E-5,1.18198571993713E-5,0.25,3.23040220632103E-8,5.89308717841077E-6,3.77952081559213E-8,226.0376587,226.0376587,99.5482559204102,99.5482559204102,57.4192126512176,20.7580968986259,24.427608,0,0,0,40,4374,228.8704,99.5482559204102,,,,,,,,,,,,,0,,,,-0.00245,,,,,,226.0376587,,,,
,29353159.44,229.04776,99.5482559204102,5.84108798984308E-6,3.91802705070396E-7,1,0.999253354069792,40.0298881530762,1.98912083502583,16.160000115633,6.59969772658405E-5,1.12561340338195E-5,0.25,-1.67466511240695E-8,5.85562328464244E-6,-1.14984219854065E-8,229.04776,229.04776,99.5482559204102,99.5482559204102,57.0432493334676,20.7375808652932,24.047956,0,0,0,40,4374,231.8613,99.5482559204102,,,,,,,,,,,,,0,,,,-0.0049,,,,,,229.04776,,,,
,29353300.32,232.5350342,99.5482559204102,6.14614447667412E-6,3.28640451256476E-7,1,0.999253354069792,40.0298881530762,1.98935138017287,16.160000115633,7.10478448304278E-5,2.59411698941487E-6,0.25,-8.36588079075626E-7,6.16142899814279E-6,-8.33102208419728E-7,232.5350342,232.5350342,99.5482559204102,99.5482559204102,57.190195495083,20.7396136731808,24.047956,0,0,0,40,4374,235.40315,99.5482559204102,,,,,,,,,,,,,0,,,,-0.00245,,,,,,232.5350342,,,,
,29353440.345,236.0002441,99.5482559204102,5.23614227788025E-6,3.95903193837047E-7,1,0.999253354069792,40.0298881530762,1.98965404136927,16.160000115633,6.04265947585745E-5,2.80544578961063E-6,0.25,-6.59921181743995E-7,5.24847844698108E-6,-6.5682977590526E-7,236.0002441,236.0002441,99.5482559204102,99.5482559204102,57.4825245612753,20.7517896339855,24.427608,0,0,0,40,4374,238.9136,99.5482559204102,,,,,,,,,,,,,0,,,,0,,,,,,236.0002441,,,,
,29353559.51,239.0162201,99.5482559204102,5.62895859780131E-6,4.25175657905517E-7,1,0.999253354069792,40.0298881530762,1.98997518627887,16.1099992692471,6.43624579806109E-5,6.4776753145505E-6,0.25,-4.02853006074857E-7,5.64135674755607E-6,-3.98872130523459E-7,239.0162201,239.0162201,99.5482559204102,99.5482559204102,57.2581971762561,20.7313907247074,24.047956,0,0,0,40,4374,241.90745,99.5482559204102,,,,,,,,,,,,,0,,,,-0.00245,,,,,,239.0162201,,,,
,29353703.08,242.5544739,99.5482559204102,5.72212023834352E-6,4.1966140626196E-7,1,0.999253354069792,40.0298881530762,1.99047669082216,16.1099992692471,6.54782563691477E-5,6.33791950531584E-6,0.25,-4.31365958289387E-7,5.73402888881178E-6,-4.27399502016179E-7,242.5544739,242.5544739,99.5482559204102,99.5482559204102,57.4942489890638,20.7391978333659,24.047956,0,0,0,40,4374,245.5091,99.5482559204102,,,,,,,,,,,,,0,,,,-0.0049,,,,,,242.5544739,,,,
,29353841.2,246.00602725,99.5482559204102,5.39675245587588E-6,3.76809481238717E-7,1,0.999253354069792,40.0298881530762,1.99055511888644,16.1099992692471,6.0877348461298E-5,1.10079583100963E-5,0.25,3.86732487828389E-8,5.40695465452252E-6,4.32321135537664E-8,245.9687195,246.043335,99.5482559204102,99.5482559204102,57.4825245612753,20.7292661524359,24.427608,0,0,0,40,4374,248.9685,99.5482559204102,,,,,,,,,,,,,0,,,,0,,,,,,246.00602725,,,,
,29353980.98,249.5153503,99.5482559204102,5.05883637840315E-6,3.45800836359755E-7,1,0.999253354069792,40.0298881530762,2.00370453721691,16.0600002855062,5.80237765837538E-5,6.89032997312243E-6,0.25,-2.70970655910783E-7,5.06802636151296E-6,-2.67316561962999E-7,249.5153503,249.5153503,99.5482559204102,99.5482559204102,57.3574639981984,20.7038796334111,24.427608,0,0,0,40,4374,252.47665,99.5482559204102,,,,,,,,,,,,,0,,,,0.0049,,,,,,249.5153503,,,,
,29354123.32,253.0478363,99.5482559204102,5.27741904011058E-6,4.12477603059056E-7,1,0.999253354069792,40.0298881530762,2.00415944409291,16.0600002855062,6.09004825674315E-5,5.08905678214602E-6,0.25,-4.67349045815046E-7,5.28649215879754E-6,-4.63878262527453E-7,253.0478363,253.0478363,99.5482559204102,99.5482559204102,57.4887775894292,20.7011668118819,24.807261,0,0,0,40,4374,256.041,99.5482559204102,,,,,,,,,,,,,0,,,,0,,,,,,253.0478363,,,,
,29354263.57,256.5360107,99.5482559204102,5.20866130916172E-6,3.85886618721895E-7,1,0.999253354069792,40.0298881530762,2.00469854808773,16.0600002855062,5.94505822899028E-5,8.85515404117421E-6,0.25,-1.24094049637438E-7,5.21669992828211E-6,-1.20165663722048E-7,256.5360107,256.5360107,99.5482559204102,99.5482559204102,57.4051433378714,20.7008039835787,25.186911,0,0,0,40,4374,259.5607,99.5482559204102,,,,,,,,,,,,,0,,,,-0.00245,,,,,,256.5360107,,,,
,29354403.475,260.0470886,99.5482559204102,5.62416684260455E-6,4.56929381468431E-7,1,0.999253354069792,40.0298881530762,1.99197953378794,16.0099994391203,6.29190362037846E-5,1.45627720539417E-5,0.25,3.14026291626788E-7,5.63179491141417E-6,3.18840927399253E-7,260.0470886,260.0470886,99.5482559204102,99.5482559204102,57.4895592179484,20.6910095065225,24.427608,0,0,0,40,4374,263.0536,99.5482559204102,,,,,,,,,,,,,0,,,,0.0049,,,,,,260.0470886,,,,
,29354545.24,263.5431213,99.5482559204102,4.78574971366567E-6,4.2694217348721E-7,1,0.999253354069792,40.0298881530762,1.99219115993724,16.0099994391203,5.38464414816404E-5,1.06138786115595E-5,0.25,1.09904604818962E-7,4.79176869007137E-6,1.13708006467143E-7,263.5431213,263.5431213,99.5482559204102,99.5482559204102,57.4958122461022,20.6924818913806,25.186911,0,0,0,40,4374,266.6059,99.5482559204102,,,,,,,,,,,,,0,,,,0,,,,,,263.5431213,,,,
,29354683.98,267.0243225,99.5482559204102,5.51457965786878E-6,4.17064190477161E-7,1,0.999253354069792,40.0298881530762,1.99306923472237,16.0099994391203,6.21158541266368E-5,1.19418949828101E-5,0.25,1.00863592697278E-7,5.52085123620805E-6,1.0513572043409E-7,267.0243225,267.0243225,99.5482559204102,99.5482559204102,57.6333788654869,20.6793816990014,24.427608,0,0,0,40,4374,270.0687,99.5482559204102,,,,,,,,,,,,,0,,,,0,,,,,,267.0243225,,,,
,29354826.51,270.5400085,99.5482559204102,4.78713562355832E-6,4.52742251573703E-7,1,0.999253354069792,40.0298881530762,1.99338129523687,15.9499999135733,5.48598217578949E-5,4.96392582831649E-6,0.25,-3.90518226490405E-7,4.79233425962591E-6,-3.87367887716263E-7,270.5400085,270.5400085,99.5482559204102,99.5482559204102,57.034651419756,20.6782667641314,25.186911,0,0,0,40,4374,273.66295,99.5482559204102,,,,,,,,,,,,,0,,,,-0.00245,,,,,,270.5400085,,,,
,29354966.2,274.019989,99.5482559204102,4.9598389927315E-6,4.21619228227883E-7,1,0.999253354069792,40.0298881530762,1.99293687365431,15.9499999135733,5.70686276154111E-5,3.70543802208405E-6,0.25,-5.31657782044875E-7,4.96469591040507E-6,-5.28513642527948E-7,274.019989,274.019989,99.5482559204102,99.5482559204102,57.5989872106407,20.6838475830216,25.186911,0,0,0,40,4374,277.1537,99.5482559204102,,,,,,,,,,,,,0,,,,-0.0049,,,,,,274.019989,,,,
,29355106.815,277.5369873,99.5482559204102,4.389739572372E-6,3.79277532698194E-7,1,0.999253354069792,40.0298881530762,1.99319817734261,15.9499999135733,5.02073382678782E-5,5.01938514497652E-6,0.25,-3.16477555765366E-7,4.39336932376981E-6,-3.13564538342297E-7,277.5369873,277.5369873,99.5482559204102,99.5482559204102,57.4348452216022,20.6795850848827,25.186911,0,0,0,40,4374,280.6729,99.5482559204102,,,,,,,,,,,,,0,,,,0.0049,,,,,,277.5369873,,,,
,29355246.65,281.0097961,99.5482559204102,4.3191332820665E-6,4.80937921912486E-7,1,0.999253354069792,40.0298881530762,1.99334109350107,15.9000009298325,4.87377661301291E-5,8.74215166358019E-6,0.25,2.54053889214689E-8,4.32192521292447E-6,2.84834017233402E-8,281.0097961,281.0097961,99.5482559204102,99.5482559204102,57.4160861371407,20.6628471343701,25.186911,0,0,0,40,4374,284.1689,99.5482559204102,,,,,,,,,,,,,0,,,,-0.0049,,,,,,281.0097961,,,,
,29355387.155,284.5289917,99.5482559204102,4.92890112524812E-6,3.8892597316457E-7,1,0.999253354069792,40.0298881530762,1.9936618408928,15.9000009298325,5.56786876171142E-5,9.63806551096191E-6,0.25,-9.29086883342882E-10,4.93148679155709E-6,2.5128378854871E-9,284.5289917,284.5289917,99.5482559204102,99.5482559204102,57.4809613042369,20.6602697071691,25.186911,0,0,0,40,4374,287.6797,99.5482559204102,,,,,,,,,,,,,0,,,,-0.0049,,,,,,284.5289917,,,,
,29355527.515,288.014679,99.5482559204102,4.54146196312733E-6,3.18859661920239E-7,1,0.999253354069792,40.0298881530762,1.99406962440931,15.9000009298325,5.26759029458722E-5,9.73550741452774E-7,0.25,-7.00789401150414E-7,4.5437589389258E-6,-6.9794372758524E-7,288.014679,288.014679,99.5482559204102,99.5482559204102,57.5294222724292,20.6623931870038,25.186911,0,0,0,40,4374,291.2037,99.5482559204102,,,,,,,,,,,,,0,,,,-0.0049,,,,,,288.014679,,,,
,29355668.49,291.5281067,99.5482559204102,4.58201820657415E-6,5.39162996634836E-7,1,0.999253354069792,40.0298881530762,1.98251634850719,15.8500000834465,5.20331141511801E-5,5.66503089394089E-6,0.25,-2.8962551173519E-7,4.58346900379506E-6,-2.86596669529643E-7,291.5281067,291.5281067,99.5482559204102,99.5482559204102,57.2449094914291,20.6562620252342,25.186911,0,0,0,40,4374,294.74505,99.5482559204102,,,,,,,,,,,,,0,,,,-0.0049,,,,,,291.5281067,,,,
,29355808.59,295.0248413,99.5482559204102,4.63733563409598E-6,4.04450742162468E-7,1,0.999253354069792,40.0298881530762,1.98281973664631,15.8500000834465,5.21472036261143E-5,8.70684127070797E-6,0.25,-2.83886501873943E-8,4.63804382947601E-6,-2.52913605440321E-8,295.0248413,295.0248413,99.5482559204102,99.5482559204102,57.3301070000253,20.6533362035859,25.566563,0,0,0,40,4374,298.23815,99.5482559204102,,,,,,,,,,,,,0,,,,0.00245,,,,,,295.0248413,,,,
,29355951.175,298.5496216,99.5482559204102,4.34029846253838E-6,4.32991081044956E-7,1,0.999253354069792,40.0298881530762,1.98305008365973,15.8500000834465,4.9260994448242E-5,5.52438889285986E-6,0.25,-2.60182492452186E-7,4.3405683116748E-6,-2.5732662831071E-7,298.5496216,298.5496216,99.5482559204102,99.5482559204102,57.3715333115445,20.6521360909203,25.186911,0,0,0,40,4374,301.8134,99.5482559204102,,,,,,,,,,,,,0,,,,0,,,,,,298.5496216,,,,
,29356070.65,301.5216675,99.5482559204102,4.4937114422102E-6,4.03557653605136E-7,1,0.999253354069792,40.0298881530762,2.00688356650451,15.7900005578995,5.10121179871498E-5,9.07194750394289E-6,0.25,2.00146166573844E-8,4.49332348520144E-6,2.29412127986562E-8,301.5216675,301.5216675,99.5482559204102,99.5482559204102,57.2355299491984,20.6309355209953,25.566563,0,0,0,40,4374,304.80395,99.5482559204102,,,,,,,,,,,,,0,,,,-0.0049,,,,,,301.5216675,,,,
,29356212.17,305.0329132,99.5482559204102,4.25173175999298E-6,4.10654164814352E-7,1,0.999253354069792,40.0298881530762,2.00724606836759,15.7900005578995,4.97019351815663E-5,3.03554061338768E-7,0.25,-7.09846756106523E-7,4.25130134897524E-6,-7.06965837805518E-7,305.0068359,305.0589905,99.5482559204102,99.5482559204102,57.1409528983714,20.6388422730646,25.186911,0,0,0,40,4374,308.33825,99.5482559204102,,,,,,,,,,,,,0,,,,0,,,,,,305.0329132,,,,
,29356351.29,308.5204468,99.5482559204102,4.37067452701822E-6,4.32860403868706E-7,1,0.999253354069792,40.0298881530762,2.00723235422301,15.7900005578995,5.00061585303851E-5,6.5433242903265E-6,0.25,-1.81122923569068E-7,4.3693359186066E-6,-1.7829046515019E-7,308.5204468,308.5204468,99.5482559204102,99.5482559204102,57.2112994651022,20.6431604494051,25.946213,0,0,0,40,4374,311.8246,99.5482559204102,,,,,,,,,,,,,0,,,,0.00245,,,,,,308.5204468,,,,
,29356493.155,312.0335999,99.5482559204102,4.0799761250368E-6,4.45888834332164E-7,1,0.999253354069792,40.0298881530762,1.98329660617234,15.7399997115135,4.61455725707789E-5,6.02265674518447E-6,0.25,-1.70392651037153E-7,4.07821757681917E-6,-1.67761242149347E-7,312.0335999,312.0335999,99.5482559204102,99.5482559204102,57.2120810936214,20.644060259405,25.186911,0,0,0,40,4374,315.387,99.5482559204102,,,,,,,,,,,,,0,,,,0,,,,,,312.0335999,,,,
,29356636,315.5397644,99.5482559204102,4.03972251604783E-6,4.14710079059945E-7,1,0.999253354069792,40.0298881530762,1.98372371875079,15.7399997115135,4.49164427445192E-5,1.04527881902627E-5,0.25,2.31061867981149E-7,4.03723209736491E-6,2.33422720525978E-7,315.5397644,315.5397644,99.5482559204102,99.5482559204102,57.4098331089868,20.6491850305985,25.946213,0,0,0,40,4374,318.9777,99.5482559204102,,,,,,,,,,,,,0,,,,0.00245,,,,,,315.5397644,,,,
,29356776.05,319.0286865,99.5482559204102,4.06742842389342E-6,3.54879663603959E-7,1,0.999253354069792,40.0298881530762,1.98436803049809,15.7399997115135,4.68805349705624E-5,1.01429607637189E-6,0.25,-6.14196441546937E-7,4.06493885760427E-6,-6.11283457976457E-7,319.0286865,319.0286865,99.5482559204102,99.5482559204102,57.3942005386022,20.6445449096887,25.566563,0,0,0,40,4374,322.5033,99.5482559204102,,,,,,,,,,,,,0,,,,-0.0049,,,,,,319.0286865,,,,
,29356917.265,322.5395813,99.5482559204102,4.14200375261512E-6,3.6538342006407E-7,1,0.999253354069792,40.0298881530762,1.98416702380653,15.6800001859665,4.70414815128016E-5,5.00518547274439E-6,0.25,-2.71671697318136E-7,4.13873981129089E-6,-2.68952305187304E-7,322.5395813,322.5395813,99.5482559204102,99.5482559204102,57.3035316303714,20.6492222382847,25.946213,0,0,0,40,4374,326.0413,99.5482559204102,,,,,,,,,,,,,0,,,,0,,,,,,322.5395813,,,,
,29357056.35,326.0080261,99.5482559204102,4.05306818726119E-6,4.08705871470118E-7,1,0.999253354069792,40.0298881530762,1.9841897472784,15.6800001859665,4.54281986248901E-5,8.35068799165437E-6,0.25,4.17607960443376E-8,4.04919736596881E-6,4.41329178978155E-8,326.0080261,326.0080261,99.5482559204102,99.5482559204102,57.2112994651022,20.6455943373353,25.946213,0,0,0,40,4374,329.5309,99.5482559204102,,,,,,,,,,,,,0,,,,-0.0049,,,,,,326.0080261,,,,
,29357198.39,329.5359192,99.5482559204102,4.25703338647322E-6,5.56501203677813E-7,1,0.999253354069792,40.0298881530762,1.98435460085063,15.6800001859665,4.72265560986423E-5,1.1574934575415E-5,0.25,2.93662045908605E-7,4.25229779673623E-6,2.95850237064957E-7,329.5359192,329.5359192,99.5482559204102,99.5482559204102,57.2980602307368,20.6457025182814,25.186911,0,0,0,40,4374,333.07975,99.5482559204102,,,,,,,,,,,,,0,,,,0.0049,,,,,,329.5359192,,,,
,29357340.365,333.0602112,99.5482559204102,3.54702871165193E-6,4.41257396441534E-7,1,0.999253354069792,40.0298881530762,1.98436315276201,15.6299993395805,3.98066326604776E-5,6.97927810075793E-6,0.25,7.41384339850429E-9,3.54278884874757E-6,9.4660894497615E-9,333.0602112,333.0602112,99.5482559204102,99.5482559204102,56.9158438848329,20.6465823739695,25.946213,0,0,0,40,4374,336.6593,99.5482559204102,,,,,,,,,,,,,0,,,,0,,,,,,333.0602112,,,,
,29357479.045,336.5179138,99.5482559204102,4.04039321106649E-6,3.74190231803673E-7,1,0.999253354069792,40.0298881530762,1.98442264460908,15.6299993395805,4.59178700417224E-5,4.60831333277168E-6,0.25,-2.89153599045406E-7,4.03525241288479E-6,-2.86451886724257E-7,336.5179138,336.5179138,99.5482559204102,99.5482559204102,57.1307917276214,20.6457916954623,25.946213,0,0,0,40,4374,340.1231,99.5482559204102,,,,,,,,,,,,,0,,,,-0.0049,,,,,,336.5179138,,,,
,29357619.265,340.0116577,99.5482559204102,3.25525680087041E-6,4.34898499061172E-7,1,0.999253354069792,40.0298881530762,1.98414796982475,15.6299993395805,3.75102913965431E-5,6.82276033054347E-7,0.25,-5.02896213878603E-7,3.25087642274313E-6,-5.00324855600369E-7,340.0116577,340.0116577,99.5482559204102,99.5482559204102,57.4387533641984,20.6511494004756,25.566563,0,0,0,40,4374,343.6267,99.5482559204102,,,,,,,,,,,,,0,,,,-0.00245,,,,,,340.0116577,,,,
,29357741.82,343.048645,99.5482559204102,3.23120549372052E-6,4.38320226552676E-7,1,0.999253354069792,40.0298881530762,1.98451660468643,15.5699998140335,3.60159884728694E-5,7.72212961933983E-6,0.25,1.28517991091014E-7,3.22616613843704E-6,1.30140339645219E-7,343.048645,343.048645,99.5482559204102,99.5482559204102,56.9580518248714,20.6415311908799,25.946213,0,0,0,40,4374,346.6976,99.5482559204102,,,,,,,,,,,,,0,,,,0,,,,,,343.048645,,,,
,29357882.225,346.5304565,99.5482559204102,4.4804676337892E-6,4.79789976088452E-7,1,0.999253354069792,40.0298881530762,1.98443393936474,15.5699998140335,5.02073973665258E-5,9.1198293573641E-6,0.25,3.68849357285171E-8,4.47302987076483E-6,3.93216113061707E-8,346.5304565,346.5304565,99.5482559204102,99.5482559204102,57.0612267894099,20.6406335935961,25.946213,0,0,0,40,4374,350.2249,99.5482559204102,,,,,,,,,,,,,0,,,,0,,,,,,346.5304565,,,,
,29358292,349.788269,99.5482559204102,3.57616060097841E-6,4.93084754768319E-7,1,0.999253354069792,40.0298881530762,1.9836630693711,15.5699998140335,4.06922142541732E-5,3.59312206040083E-6,0.25,-2.98871180678444E-7,3.57001233858394E-6,-2.96353090935682E-7,349.788269,349.788269,99.5482559204102,99.5482559204102,57.352774227083,20.6626250766239,25.946213,0,0,0,40,4369,350.7656,99.5482559204102,,,,,,,,,,,,,0,,,,0,,,,,,349.788269,,,,