File: data/looselyPackedNP/sc-ios-7/ppms/rawdata/ES_S17_HYST_300K.DAT
[Header]
; VSM Data File (default extension .dat)
; Copyright (c) 2003-2013, Quantum Design, Inc. All rights reserved.
TITLE,
FILEOPENTIME,29299665.33,12/06/2018,10:48 am
BYAPP,VSM,2.0,2.0
INFO,PPMS VSM Option Release 1.4.10 Build 1,APPNAME
INFO,Quantum Design Linear Motor Servo Controller,MOTOR_MODULE_NAME
INFO,3101-100 M1,MOTOR_HW_VERSION
INFO,MMC1014,MOTOR_SERIAL_NUMBER
INFO,SRV No X-over 01.03.11,MOTOR_SOFTWARE_VERSION
INFO,Quantum Design VSM Detection Module,VSM_MODULE_NAME
INFO,3101-150 F0,VSM_HW_VERSION
INFO,VSM707,VSM_SERIAL_NUMBER
INFO,VSM No X-over 01.02.05 May 20 2008 13:51:47,VSM_SOFTWARE_VERSION
INFO,704,PREAMP_SERIAL_NUMBER
INFO,822,COIL_SERIAL_NUMBER
INFO,0,MOMENT_UNITS
INFO,Iron Oxide Spheres,SAMPLE_MATERIAL
INFO,7 nm diameter, collaboration Mainz,SAMPLE_COMMENT
INFO,,SAMPLE_MASS
INFO,,SAMPLE_VOLUME
INFO,,SAMPLE_MOLECULAR_WEIGHT
INFO,,SAMPLE_SIZE
INFO,,SAMPLE_SHAPE
DATATYPE,COMMENT,1
DATATYPE,TIME,2
STARTUPAXIS,X,2
STARTUPAXIS,Y1,5
[Data]
Comment,Time Stamp (sec),Temperature (K),Magnetic Field (Oe),Moment (emu),M. Std. Err. (emu),Transport Action,Averaging Time (sec),Frequency (Hz),Peak Amplitude (mm),Center Position (mm),Coil Signal' (mV),Coil Signal" (mV),Range (mV),M. Quad. Signal (emu),M. Raw' (emu),M. Raw" (emu),Min. Temperature (K),Max. Temperature (K),Min. Field (Oe),Max. Field (Oe),Mass (grams),Motor Lag (deg),Pressure (Torr),VSM Status (code),Motor Status (code),Measure Status (code),Measure Count,PPMS Status (code),System Temp. (K),System Field (Oe),Sample Position (deg),Bridge 1 Resistance (ohms),Bridge 1 Excitation (에),Bridge 2 Resistance (ohms),Bridge 2 Excitation (에),Bridge 3 Resistance (ohms),Bridge 3 Excitation (에),Bridge 4 Resistance (ohms),Bridge 4 Excitation (에),Signal 1 Vin (V),Signal 2 Vin (V),Digital Inputs (code),Drive 1 Iout (mA),Drive 1 Ipower (W),Drive 2 Iout (mA),Drive 2 Ipower (W),Pressure (),Map 20 (),Map 21 (),Map 22 (),Map 23 (),Map 24 (),Map 25 (),Map 26 (),Map 27 (),Map 28 (),Map 29 ()
,29299681.61,300.207428,-0.213132828474045,,,2,,,,15.7599999961257,,,,,,,300.207428,300.207428,-0.213132828474045,-0.213132828474045,,,24.807261,,,,-99999999,4369,300.5645,-0.213132828474045,,,,,,,,,,,,,,,,,,,,,,,300.207428,,,,
,29299826.88,300.1785278,4446.39794921875,6.63097167002735E-5,6.19598229164398E-7,1,0.999253354069792,40.0298881530762,1.99406371086949,15.7500002533197,0.000750416092518836,0.000120191776752957,0.25,-8.44721484336419E-7,6.63078762328816E-5,-8.00741159004908E-7,300.1781921,300.1788635,4436.23095703125,4456.56494140625,56.6000659630637,20.6387393734403,24.427608,0,0,0,40,4449,300.33515,4446.39794921875,,,,,,,,,,,,,0,,,,0,,,,,,300.1785278,,,,
,29299918.845,300.1196899,9039.7841796875,5.6908730471242E-5,6.28433880370495E-7,1,0.999253354069792,40.0298881530762,1.99438771244526,15.7500002533197,0.000645799458769689,9.35205081082602E-5,0.25,-1.5791783674705E-6,5.6907838373375E-5,-1.54142165486882E-6,300.1196899,300.1196899,9032.2314453125,9047.3369140625,56.8525319747752,20.6433102527331,24.427608,0,0,0,40,4449,300.2568,9039.7841796875,,,,,,,,,,,,,0,,,,-0.0049,,,,,,300.1196899,,,,
,29300014.42,300.071106,13817.6948242187,3.52033908001411E-5,9.06866850964997E-7,1,0.999253354069792,40.0298881530762,1.99452631203096,15.7500002533197,0.000405597580081661,2.27469685663911E-5,0.25,-4.08529715451984E-6,3.52049593518831E-5,-4.06185872299525E-6,300.071106,300.071106,13815.6279296875,13819.76171875,56.4929828559291,20.6435045906787,24.047956,0,0,0,40,4449,300.2185,13817.6948242187,,,,,,,,,,,,,0,,,,0.00245,,,,,,300.071106,,,,
,29300107.28,300.0336304,18457.66796875,1.31765744277365E-5,9.09786486225818E-7,1,0.999253354069792,40.0298881530762,1.99455250546805,15.7500002533197,0.000172839875801336,-0.000112826278547078,0.25,-1.22723331959156E-5,1.31842857023796E-5,-1.22632379730079E-5,300.0336304,300.0336304,18452.4140625,18462.921875,56.9861904515637,20.6474440954234,24.427608,0,0,0,40,4449,300.2083,18457.66796875,,,,,,,,,,,,,0,,,,-0.00245,,,,,,300.0336304,,,,
,29300200.495,300.007019,23117.68359375,-1.1526211677678E-5,1.50014280592179E-6,1,0.999253354069792,40.0298881530762,1.99472743866523,15.7500002533197,-0.00010350176003949,-0.000176625288862955,0.25,-1.3639678736528E-5,-1.15168532750304E-5,-1.36468888010306E-5,300.007019,300.007019,23110.5078125,23124.859375,57.1792526958137,20.6451152578768,24.427608,0,0,0,40,4449,300.2103,23117.68359375,,,,,,,,,,,,,0,,,,0,,,,,,300.007019,,,,
,29300293.68,299.9962769,27775.916015625,-3.38093062873137E-5,2.39291405487116E-6,1,0.999253354069792,40.0298881530762,1.99460499322448,15.7500002533197,-0.00033659545150493,-0.000327496406805043,0.25,-2.31373300563724E-5,-3.37930355050569E-5,-2.31589713634699E-5,299.9962769,299.9962769,27768.103515625,27783.728515625,57.0221453634483,20.6447443856242,24.427608,0,0,0,40,4449,300.21205,27775.916015625,,,,,,,,,,,,,0,,,,-0.00245,,,,,,299.9962769,,,,
,29300389.63,299.9857788,32568.130859375,-6.20491979099953E-5,2.32290586786261E-6,1,0.999253354069792,40.0298881530762,1.99454952748095,15.7500002533197,-0.000660768719771907,-0.000352604058852223,0.25,-2.04683498936579E-5,-6.20339000063851E-5,-2.05086802907632E-5,299.9857788,299.9857788,32560.6171875,32575.64453125,57.1003082153714,20.6446530651855,24.427608,0,0,0,40,4449,300.21955,32568.130859375,,,,,,,,,,,,,0,,,,-0.00245,,,,,,299.9857788,,,,
,29300486.36,299.9815369,37405.26171875,-8.64637084927994E-5,3.91111735803929E-6,1,0.999253354069792,40.0298881530762,1.99454889553663,15.7500002533197,-0.000919038549294343,-0.000501288893154757,0.25,-2.94026639904515E-5,-8.64418512207831E-5,-2.9458780027764E-5,299.9815369,299.9815369,37397.390625,37413.1328125,57.1573670972753,20.6461200193339,24.047956,0,0,0,40,4449,300.23345,37405.26171875,,,,,,,,,,,,,0,,,,0.00245,,,,,,299.9815369,,,,
,29300579.945,299.9829254,42083.162109375,-0.000104274772101158,4.80707534974851E-6,1,0.999253354069792,40.0298881530762,1.99452086679889,15.7500002533197,-0.00107047935999941,-0.000823075929764732,0.25,-5.48081294302354E-5,-0.000104235708716432,-5.48751708858148E-5,299.982666,299.9831848,42075.71484375,42090.609375,57.2464727484676,20.6460226870862,24.807261,0,0,0,40,4449,300.2551,42083.162109375,,,,,,,,,,,,,0,,,,0,,,,,,299.9829254,,,,
,29300675.65,299.9908447,46865.7734375,-0.000123122228780194,5.07066999530641E-6,1,0.999253354069792,40.0298881530762,1.99459652724085,15.7500002533197,-0.00124411155504776,-0.00108674570792423,0.25,-7.48843631735497E-5,-0.000123069442091446,-7.4963121200002E-5,299.9908447,299.9908447,46858.390625,46873.15625,57.2894623170253,20.6442834529375,24.047956,0,0,0,40,4449,300.2637,46865.7734375,,,,,,,,,,,,,0,,,,0,,,,,,299.9908447,,,,
,29300773.71,299.993042,51768.76171875,-0.000147457760573681,5.56985767165571E-6,1,0.999253354069792,40.0298881530762,1.99476791041394,15.7500002533197,-0.00148516412702878,-0.00133035723026119,0.25,-9.22268916362682E-5,-0.000147392939954863,-9.23210277713279E-5,299.993042,299.993042,51761.6328125,51775.890625,57.3871658819292,20.6404017690289,24.807261,0,0,0,40,4449,300.26905,51768.76171875,,,,,,,,,,,,,0,,,,0,,,,,,299.993042,,,,
,29300870.62,299.9925232,56608.595703125,-0.000160869073365823,7.860161660359E-6,1,0.999253354069792,40.0298881530762,1.99470218427,15.7500002533197,-0.00160802657215698,-0.00152151551883102,0.25,-0.000106830611591691,-0.000160794372608966,-0.00010693301518697,299.9923706,299.9926758,56598.9453125,56618.24609375,57.098744958333,20.6397901703189,24.427608,0,0,0,40,4449,300.2707,56608.595703125,,,,,,,,,,,,,0,,,,-0.00245,,,,,,299.9925232,,,,
,29300968.14,300.0011292,61485.796875,-0.000187145814794568,6.45587304411081E-6,1,0.999253354069792,40.0298881530762,1.99472865640493,15.7500002533197,-0.00187093502811451,-0.00176876602991568,0.25,-0.000124165666916276,-0.000187059040640818,-0.000124284623614967,300.0011292,300.0011292,61480.76953125,61490.82421875,57.126101956506,20.6377968646434,24.427608,0,0,0,40,4449,300.27335,61485.796875,,,,,,,,,,,,,0,,,,0.0049,,,,,,300.0011292,,,,
,29301065.35,300.0002747,66343.83203125,-0.000192379199163796,6.92952498408771E-6,1,0.999253354069792,40.0298881530762,1.9946549459051,15.7500002533197,-0.00188479357331729,-0.0020397749579123,0.25,-0.000147257888733795,-0.000192277281700041,-0.000147379465775814,300.0002747,300.0002747,66338.6328125,66349.03125,57.2198973788137,20.6438909115088,24.047956,0,0,0,40,4449,300.26895,66343.83203125,,,,,,,,,,,,,0,,,,-0.0049,,,,,,300.0002747,,,,
,29301162.485,300.0067749,71198.85546875,-0.000222473992996545,6.37278743580733E-6,1,0.999253354069792,40.0298881530762,1.99461641911971,15.7500002533197,-0.00218585742488265,-0.00232271527237323,0.25,-0.000167097521809648,-0.000222358317630937,-0.000167238008917304,300.0067749,300.0067749,71191.34375,71206.3671875,57.180034324333,20.645625205724,24.047956,0,0,0,40,4449,300.26325,71198.85546875,,,,,,,,,,,,,0,,,,0,,,,,,300.0067749,,,,
,29301259.32,300.0063782,76039.75390625,-0.000238011821528016,1.16571433444514E-5,1,0.999253354069792,40.0298881530762,1.99460000418543,15.7500002533197,-0.00231968177762398,-0.00259355722082037,0.25,-0.000188386475758417,-0.000237881951511707,-0.00018853632153679,300.0063782,300.0063782,76034.859375,76044.6484375,57.4325003360445,20.6472775952976,24.427608,0,0,0,40,4449,300.2581,76039.75390625,,,,,,,,,,,,,0,,,,0,,,,,,300.0063782,,,,
,29301355.615,300.0059509,80853.0390625,-0.000267701038558218,1.35533642813665E-5,1,0.999253354069792,40.0298881530762,1.99450689634884,15.7500002533197,-0.00261141717995647,-0.00290253629462546,0.25,-0.000210610066569211,-0.000267555991233763,-0.000210778446554133,300.0059509,300.0059509,80848.15625,80857.921875,57.2558522906984,20.6515224024243,24.427608,0,0,0,40,4449,300.2526,80853.0390625,,,,,,,,,,,,,0,,,,0.00245,,,,,,300.0059509,,,,
,29301451.69,300.0122986,85656.15234375,-0.000307209866213369,7.09877564311573E-6,1,0.999253354069792,40.0298881530762,1.99453144639315,15.7500002533197,-0.00304449916304719,-0.00305597972002568,0.25,-0.000217348095072922,-0.00030705939829784,-0.000217541761127541,300.0122986,300.0122986,85646.4140625,85665.890625,57.2378748347561,20.6535585091865,24.807261,0,0,0,40,4449,300.2346,85656.15234375,,,,,,,,,,,,,0,,,,0,,,,,,300.0122986,,,,
,29301560.915,300.0106812,89870.1875,-0.000312429597711168,1.13309742570247E-5,1,0.999253354069792,40.0298881530762,1.99429793690669,15.7500002533197,-0.00307759853733967,-0.00321310113097298,0.25,-0.000230387025140656,-0.000312270700016142,-0.000230583503558578,300.0106812,300.0106812,89860.6171875,89879.7578125,57.383257739333,20.66035511559,24.807261,0,0,0,40,4449,300.2464,89870.1875,,,,,,,,,,,,,0,,,,0,,,,,,300.0106812,,,,
,29301654.335,300.0087891,85209.203125,-0.000315542923471079,7.04211703616448E-6,1,0.999253354069792,40.0298881530762,1.9941604313159,15.7500002533197,-0.00316010194935261,-0.00294451215941939,0.25,-0.000206081504329814,-0.000315399563222864,-0.000206280980877469,300.0087891,300.0087891,85204.3671875,85214.0390625,57.2707032325638,20.6620315630955,24.427608,0,0,0,40,4449,300.224,85209.203125,,,,,,,,,,,,,0,,,,-0.00245,,,,,,300.0087891,,,,
,29301750.35,300.0034485,80408.34375,-0.00028949394496073,8.71843980708666E-6,1,0.999253354069792,40.0298881530762,1.99425182381456,15.7500002533197,-0.00296787750840294,-0.00230601812180974,0.25,-0.000154044017346415,-0.000289385137825495,-0.000154228294551411,300.0034485,300.0034485,80401.109375,80415.578125,57.2769562607176,20.6618795905607,24.427608,0,0,0,40,4449,300.22925,80408.34375,,,,,,,,,,,,,0,,,,-0.00245,,,,,,300.0034485,,,,
,29301847.16,299.9938965,75566.70703125,-0.00025815007660237,1.01084161259001E-5,1,0.999253354069792,40.0298881530762,1.99421334827258,15.7500002533197,-0.00264681987164981,-0.00205441520992293,0.25,-0.000137197912622229,-0.000258053117364814,-0.000137362490549766,299.9938965,299.9938965,75561.6328125,75571.78125,57.5497446139292,20.6555888212352,24.807261,0,0,0,40,4449,300.2277,75566.70703125,,,,,,,,,,,,,0,,,,0.00245,,,,,,299.9938965,,,,
,29301947.27,299.9833069,70563.4375,-0.000240710974896676,7.94660358458094E-6,1,0.999253354069792,40.0298881530762,1.9943728836569,15.7500002533197,-0.00245806063207219,-0.0019743272592949,0.25,-0.00013311370734189,-0.000240617147788009,-0.000133267255257284,299.9833069,299.9833069,70558.3828125,70568.4921875,57.2386564632753,20.6588240143122,24.427608,0,0,0,40,4449,300.2349,70563.4375,,,,,,,,,,,,,0,,,,0,,,,,,299.9833069,,,,
,29302046.08,299.9909973,65623.4921875,-0.000211685165886036,7.32218478610104E-6,1,0.999253354069792,40.0298881530762,1.99427821284245,15.7500002533197,-0.00219277674520572,-0.00155598764429516,0.25,-0.000101106670843466,-0.000211612927542469,-0.00010124228866246,299.9909973,299.9909973,65615.9609375,65631.0234375,57.3590272552368,20.6544251112568,24.427608,0,0,0,40,4449,300.2417,65623.4921875,,,,,,,,,,,,,0,,,,0,,,,,,299.9909973,,,,
,29302144.66,299.995636,60694.96875,-0.000207063252985489,5.39503728463915E-6,1,0.999253354069792,40.0298881530762,1.99424882759999,15.7500002533197,-0.00217650980223674,-0.00133935963370722,0.25,-8.27267648792119E-5,-0.000207003066576386,-8.28600172663097E-5,299.995636,299.995636,60687.67578125,60702.26171875,57.5513078709676,20.6540497525961,24.807261,0,0,0,40,4449,300.26965,60694.96875,,,,,,,,,,,,,0,,,,0,,,,,,299.995636,,,,
,29302242.325,299.9872437,55817.369140625,-0.000167972923950825,4.5239438844519E-6,1,0.999253354069792,40.0298881530762,1.99433238813814,15.7500002533197,-0.00180492529698123,-0.000860083495370936,0.25,-4.70559573951131E-5,-0.000167937238121551,-4.71647781572364E-5,299.9872437,299.9872437,55814.87890625,55819.859375,57.3332335141022,20.6616015393112,24.807261,0,0,0,40,4449,300.2643,55817.369140625,,,,,,,,,,,,,0,,,,0,,,,,,299.9872437,,,,
,29302339.92,299.9840393,50937.232421875,-0.000143851865721156,4.71406228112714E-6,1,0.999253354069792,40.0298881530762,1.99432188763588,15.7500002533197,-0.00157683251106824,-0.000557041199577725,0.25,-2.44017000213519E-5,-0.000143831720139963,-2.44954578430513E-5,299.9840393,299.9840393,50927.234375,50947.23046875,57.7545312859677,20.6575884314675,24.427608,0,0,0,40,4449,300.2757,50937.232421875,,,,,,,,,,,,,0,,,,-0.0049,,,,,,299.9840393,,,,
,29302437.475,299.9947205,46062.314453125,-0.000115785740934803,3.94237360799189E-6,1,0.999253354069792,40.0298881530762,1.99396153616711,15.7500002533197,-0.00128871148418007,-0.000334313770664909,0.25,-9.54737152666849E-6,-0.000115776093999336,-9.62320944358356E-6,299.9947205,299.9947205,46054.75,46069.87890625,57.4934673605446,20.6688052171482,24.427608,0,0,0,40,4449,300.27425,46062.314453125,,,,,,,,,,,,,0,,,,0,,,,,,299.9947205,,,,
,29302534.87,299.9919434,41191.966796875,-0.000103194328488087,3.96507036913344E-6,1,0.999253354069792,40.0298881530762,1.99399657938058,15.7500002533197,-0.00115469931952271,-0.000262680889097327,0.25,-5.38441954415915E-6,-0.000103187783939889,-5.45217996578602E-6,299.9919434,299.9919434,41181.9375,41201.99609375,57.7506231433715,20.6698439998645,24.047956,0,0,0,40,4449,300.26565,41191.966796875,,,,,,,,,,,,,0,,,,-0.0049,,,,,,299.9919434,,,,
,29302632.14,299.9892273,36332.162109375,-7.0999348559363E-5,2.69933397775856E-6,1,0.999253354069792,40.0298881530762,1.99359775634997,15.7500002533197,-0.000800422756394558,-0.000145354146982674,0.25,-5.74172211705557E-7,-7.09969084132311E-5,-6.20930449242631E-7,299.9891968,299.9892578,36324.58203125,36339.7421875,57.6693337773715,20.6738113142751,24.807261,0,0,0,40,4449,300.28925,36332.162109375,,,,,,,,,,,,,0,,,,0.00245,,,,,,299.9892273,,,,
,29302730.88,299.9930725,31397.015625,-5.05012641608633E-5,1.73376931394027E-6,1,0.999253354069792,40.0298881530762,1.99365818404208,15.7500002533197,-0.00057537567542365,-6.86166923783898E-5,0.25,2.67188899417579E-6,-5.05015495665669E-5,2.63850525991832E-6,299.9930725,299.9930725,31387.220703125,31406.810546875,57.5489629854099,20.6755508001157,24.047956,0,0,0,40,4449,300.29775,31397.015625,,,,,,,,,,,,,0,,,,-0.00245,,,,,,299.9930725,,,,
,29302828.425,299.9940491,26521.6201171875,-2.42708934734543E-5,1.70541261153436E-6,1,0.999253354069792,40.0298881530762,1.9934813673055,15.7500002533197,-0.000269993139823523,-7.05418613325815E-5,0.25,-2.0437154192024E-6,-2.42688321122835E-5,-2.05967922744304E-6,299.9940491,299.9940491,26513.8984375,26529.341796875,57.6583909781023,20.6755826537407,24.807261,0,0,0,40,4449,300.29045,26521.6201171875,,,,,,,,,,,,,0,,,,0.00245,,,,,,299.9940491,,,,
,29302927.41,299.9964294,21574.5576171875,1.7951013624783E-6,1.12237070631871E-6,1,0.999253354069792,40.0298881530762,1.99351390988028,15.7500002533197,2.24178531760903E-5,-8.91508574574688E-6,0.25,-1.10072764572334E-6,1.79577586780638E-6,-1.09950887287904E-6,299.9964294,299.9964294,21571.40625,21577.708984375,57.6083667528715,20.6792543364115,24.807261,0,0,0,40,4449,300.2952,21574.5576171875,,,,,,,,,,,,,0,,,,-0.0049,,,,,,299.9964294,,,,
,29303024.18,299.993866,16737.345703125,2.27797077224819E-5,8.14973391513992E-7,1,0.999253354069792,40.0298881530762,1.99352545679493,15.7500002533197,0.000259791537396447,2.93781244101801E-5,0.25,-1.3444182090649E-6,2.27799262406742E-5,-1.3293106134034E-6,299.993866,299.993866,16729.888671875,16744.802734375,57.5067550453715,20.6775818301446,24.807261,0,0,0,40,4449,300.3057,16737.345703125,,,,,,,,,,,,,0,,,,0,,,,,,299.993866,,,,
,29303121.375,299.9929504,11880.2451171875,4.54176300639248E-5,7.86200555240352E-7,1,0.999253354069792,40.0298881530762,1.99364237131193,15.7500002533197,0.000518431792709415,5.60561373858061E-5,0.25,-2.90375477587895E-6,4.54182142395223E-5,-2.87360039547557E-6,299.9929504,299.9929504,11878.0361328125,11882.4541015625,57.5896076684099,20.67815011215,24.807261,0,0,0,40,4449,300.30995,11880.2451171875,,,,,,,,,,,,,0,,,,-0.00245,,,,,,299.9929504,,,,
,29303218.48,299.993988,7027.36206054687,6.36272680760985E-5,6.96711565392465E-7,1,0.999253354069792,40.0298881530762,1.99366157688184,15.7500002533197,0.000720585507229544,0.000111498403230416,0.25,-1.14798933659473E-6,6.36261484429277E-5,-1.10579653411144E-6,299.993988,299.993988,7019.83251953125,7034.8916015625,57.6794949481215,20.68057284969,24.427608,0,0,0,40,4449,300.3135,7027.36206054687,,,,,,,,,,,,,0,,,,0,,,,,,299.993988,,,,
,29303313.735,299.9936523,2264.24377441406,5.63380785433332E-5,4.46379602154271E-7,1,0.999253354069792,40.0298881530762,1.99385715374457,15.7500002533197,0.000637125501809236,0.000104326511895073,0.25,-5.212143089187E-7,5.63367576378403E-5,-4.83844245703764E-7,299.9936523,299.9936523,2256.89331054687,2271.59423828125,57.6036769817561,20.6756631655374,24.807261,0,0,0,40,4449,300.31825,2264.24377441406,,,,,,,,,,,,,0,,,,-0.00245,,,,,,299.9936523,,,,
,29303407.735,299.9937439,-2426.58044433594,-5.724045974269E-5,4.48184470241731E-7,1,0.999253354069792,40.0298881530762,1.99326844584501,15.7500002533197,-0.000644715486799855,-0.000120007591050879,0.25,-7.14266762719087E-7,-5.7238293006797E-5,-7.52196362808184E-7,299.9937439,299.9937439,-2436.51391601562,-2416.64697265625,57.4129596230638,20.6843825902691,24.807261,0,0,0,40,4449,300.32785,-2426.58044433594,,,,,,,,,,,,,0,,,,0,,,,,,299.9937439,,,,
,29303502.165,299.9980164,-7148.37353515625,-6.29054260773419E-5,5.82800508011404E-7,1,0.999253354069792,40.0298881530762,1.99346215883882,15.7500002533197,-0.000711830164169746,-0.000113179652004023,0.25,8.73043996245294E-7,-6.29041367628522E-5,8.31340990790296E-7,299.9980164,299.9980164,-7151.01708984375,-7145.72998046875,57.4410982497561,20.6863054344703,24.807261,0,0,0,40,4449,300.32985,-7148.37353515625,,,,,,,,,,,,,0,,,,0,,,,,,299.9980164,,,,
,29303599.04,300.0030212,-11991.4721679688,-4.38841151140818E-5,6.6909982575747E-7,1,0.999253354069792,40.0298881530762,1.99323814669377,15.7500002533197,-0.000496431658411341,-7.95385124229194E-5,0.25,5.56712496958954E-7,-4.38831748143739E-5,5.27643358311534E-7,300.0030212,300.0030212,-11993.9404296875,-11989.00390625,57.6630807492176,20.6853450883624,24.807261,0,0,0,40,4449,300.3137,-11991.4721679688,,,,,,,,,,,,,0,,,,-0.0049,,,,,,300.0030212,,,,
,29303699.205,300.0088501,-16996.201171875,-1.81252143779649E-5,1.01245744969682E-6,1,0.999253354069792,40.0298881530762,1.99362037965312,15.7500002533197,-0.000204566145337224,-3.57997412618989E-5,0.25,-3.07027377161992E-8,-1.8124650670442E-5,-4.26902562785538E-8,300.0088501,300.0088501,-17006.279296875,-16986.123046875,57.5059734168522,20.680074991723,24.427608,0,0,0,40,4449,300.30945,-16996.201171875,,,,,,,,,,,,,0,,,,0,,,,,,300.0088501,,,,
,29303797.55,300.0079956,-21913.46875,9.05327159529812E-6,1.51505235901497E-6,1,0.999253354069792,40.0298881530762,1.99362415777048,15.7500002533197,9.57896930891566E-5,5.47526907048083E-5,0.25,3.28128439134362E-6,9.05083274467118E-6,3.28716858083692E-6,300.0076294,300.0083618,-21923.5625,-21903.375,57.7029438036984,20.6796641471811,24.427608,0,0,0,40,4449,300.308,-21913.46875,,,,,,,,,,,,,0,,,,-0.00245,,,,,,300.0079956,,,,
,29303895.79,300.0057983,-26823.6953125,3.61881337096345E-5,1.21068373655869E-6,1,0.999253354069792,40.0298881530762,1.99364823574627,15.7500002533197,0.000410273111912161,6.08667921708625E-5,0.25,-8.78499856830981E-7,3.61876368217992E-5,-8.54584092970229E-7,300.0057983,300.0057983,-26836.2578125,-26811.1328125,57.6458849217946,20.6834567365601,24.427608,0,0,0,40,4449,300.2952,-26823.6953125,,,,,,,,,,,,,0,,,,-0.0049,,,,,,300.0057983,,,,
,29303995.915,300.010498,-31825.9306640625,5.76016906431113E-5,1.67191114340059E-6,1,0.999253354069792,40.0298881530762,1.99351037516409,15.7500002533197,0.000642154083901179,0.000159479249845188,0.25,4.1471272591393E-6,5.75972357313772E-5,4.18498860938294E-6,300.010498,300.010498,-31833.427734375,-31818.43359375,57.6318156084484,20.6812263147769,24.427608,0,0,0,40,4449,300.295,-31825.9306640625,,,,,,,,,,,,,0,,,,-0.00245,,,,,,300.010498,,,,
,29304093.47,300.0152588,-36700.29296875,8.67619793828825E-5,1.43470540486443E-6,1,0.999253354069792,40.0298881530762,1.99358195863125,15.7500002533197,0.000967790088802587,0.000237228248527207,0.25,5.9814202108144E-6,8.67554382567178E-5,6.03839878513944E-6,300.0152588,300.0152588,-36705.54296875,-36695.04296875,57.6951275185061,20.6818742376982,24.807261,0,0,0,40,4449,300.27515,-36700.29296875,,,,,,,,,,,,,0,,,,0,,,,,,300.0152588,,,,
,29304194.29,300.0144043,-41742.40234375,0.000116065755229394,1.94040513555111E-6,1,0.999253354069792,40.0298881530762,1.99366309671466,15.7500002533197,0.00129847576272133,0.000295633165516239,0.25,6.07688566319998E-6,0.000116058288167459,6.15308408929689E-6,300.0144043,300.0144043,-41747.26953125,-41737.53515625,57.698254032583,20.6830263393259,24.427608,0,0,0,40,4449,300.261,-41742.40234375,,,,,,,,,,,,,0,,,,-0.00245,,,,,,300.0144043,,,,
,29304293.515,300.0092468,-46699.703125,0.000146937789083572,2.86065675264657E-6,1,0.999253354069792,40.0298881530762,1.99393373880002,15.7500002533197,0.00164998199945105,0.000340178804981149,0.25,4.67000641397384E-6,0.000146930365742153,4.76645594040515E-6,300.0092468,300.0092468,-46699.703125,-46699.703125,57.5184794731599,20.683656595462,25.186911,0,0,0,40,4449,300.2542,-46699.703125,,,,,,,,,,,,,0,,,,0,,,,,,300.0092468,,,,
,29304392.305,300.0136566,-51636.771484375,0.000175140852377383,2.31700417451786E-6,1,0.999253354069792,40.0298881530762,1.99381668350604,15.7500002533197,0.00197744981819317,0.000342636219485732,0.25,3.19089409707058E-9,0.000175135644941416,1.18187833686002E-7,300.0132751,300.0140381,-51641.75,-51631.79296875,57.616964666583,20.6872774235931,24.807261,0,0,0,40,4449,300.2447,-51636.771484375,,,,,,,,,,,,,0,,,,-0.0049,,,,,,300.0136566,,,,
,29304493.84,300.0137329,-56711.62890625,0.000205253013863497,2.47668765233256E-6,1,0.999253354069792,40.0298881530762,1.99344387870415,15.7500002533197,0.00229415844699041,0.000533438155863714,0.25,1.1693850014541E-5,0.000205239257978406,1.1828113554312E-5,300.0137329,300.0137329,-56723.91796875,-56699.33984375,57.5919525539676,20.6899282606907,25.186911,0,0,0,40,4449,300.23325,-56711.62890625,,,,,,,,,,,,,0,,,,0.0049,,,,,,300.0137329,,,,
,29304594.18,300.0209045,-61725.8046875,0.000232040669857672,2.58975217514415E-6,1,0.999253354069792,40.0298881530762,1.99368569365748,15.7500002533197,0.0026130165329136,0.000492613975565063,0.25,3.43156473063132E-6,0.000232031496320982,3.58346840049548E-6,300.0209045,300.0209045,-61730.8515625,-61720.7578125,57.5419283287369,20.6894789704329,24.807261,0,0,0,40,4449,300.20935,-61725.8046875,,,,,,,,,,,,,0,,,,-0.0049,,,,,,300.0209045,,,,
,29304695.425,300.0116272,-66785.61328125,0.000261515238019606,2.98448489866924E-6,1,0.999253354069792,40.0298881530762,1.9937434063551,15.7500002533197,0.00295339605812765,0.000506816620906774,0.25,-4.17999374348587E-7,0.000261507812611123,-2.4688895715444E-7,300.0116272,300.0116272,-66793.109375,-66778.1171875,57.6435400362369,20.6901471202533,24.807261,0,0,0,40,4449,300.21145,-66785.61328125,,,,,,,,,,,,,0,,,,0.00245,,,,,,300.0116272,,,,
,29304797.165,300.0153809,-71870.01171875,0.000298874163910915,3.24273155712168E-6,1,0.999253354069792,40.0298881530762,1.99377931634239,15.7500002533197,0.00336323259138385,0.000649245873902856,0.25,5.72401449327039E-6,0.000298861605587344,5.91914833654145E-6,300.0153809,300.0153809,-71875.046875,-71864.9765625,57.8272227382561,20.6875950335649,24.427608,0,0,0,40,4449,300.1952,-71870.01171875,,,,,,,,,,,,,0,,,,0.00245,,,,,,300.0153809,,,,
,29304899.225,300.0162048,-76972.01953125,0.000332161486775779,2.54201821486707E-6,1,0.999253354069792,40.0298881530762,1.99367599408946,15.7500002533197,0.00371454400671222,0.000854775545049919,0.25,1.81648208367795E-5,0.000332139844966985,1.83810751671694E-5,300.0162048,300.0162048,-76976.8515625,-76967.1875,57.5309855294676,20.6874510843477,24.807261,0,0,0,40,4449,300.17505,-76972.01953125,,,,,,,,,,,,,0,,,,0,,,,,,300.0162048,,,,
,29304999.125,300.013031,-81964.33984375,0.000340947422435789,3.1003400817677E-6,1,0.999253354069792,40.0298881530762,1.99375159188122,15.7500002533197,0.00380039923836697,0.000949777505687632,0.25,2.50546528735749E-5,0.000340921110068488,2.52761584065509E-5,300.013031,300.013031,-81969.296875,-81959.3828125,57.8522348508715,20.6900912371546,24.807261,0,0,0,40,4449,300.1732,-81964.33984375,,,,,,,,,,,,,0,,,,0.0049,,,,,,300.013031,,,,
,29305096.1,300.0187073,-86808.51953125,0.000387484778722391,4.1072549993811E-6,1,0.999253354069792,40.0298881530762,1.99374909246178,15.7500002533197,0.00432929287930097,0.00102073285953696,0.25,2.32771837166447E-5,0.000387458228934895,2.352876730238E-5,300.0187073,300.0187073,-86815.828125,-86801.2109375,57.5341120435445,20.6901531531723,24.807261,0,0,0,40,4449,300.15915,-86808.51953125,,,,,,,,,,,,,0,,,,-0.00245,,,,,,300.0187073,,,,
,29305209.405,300.018219,-88472.84375,0.000381682072301285,4.51061550536297E-6,1,0.999253354069792,40.0298881530762,1.99386728981157,15.7500002533197,0.0042678723845633,0.000987203936996783,0.25,2.13079334912985E-5,0.000381656997405735,2.15556907508711E-5,300.018219,300.018219,-88477.8671875,-88467.8203125,57.69121937591,20.6875503384156,25.186911,0,0,0,40,4449,300.1579,-88472.84375,,,,,,,,,,,,,0,,,,-0.00245,,,,,,300.018219,,,,
,29305305.055,300.0119019,-83693.7265625,0.000355843210207612,3.35767728194579E-6,1,0.999253354069792,40.0298881530762,1.99372446773807,15.7500002533197,0.0040136099408371,0.000718674955134663,0.25,2.00580357231014E-6,0.000355831507177562,2.23761817615283E-6,300.0119019,300.0119019,-83701.171875,-83686.28125,57.7756352559869,20.6922935613354,25.186911,0,0,0,40,4449,300.1409,-83693.7265625,,,,,,,,,,,,,0,,,,0.0049,,,,,,300.0119019,,,,
,29305400.765,299.9983215,-78911.52734375,0.000334962160747807,2.64874858492308E-6,1,0.999253354069792,40.0298881530762,1.99361530475982,15.7500002533197,0.00378389564594676,0.000641822892514799,0.25,-1.18089910025839E-6,0.000334953285257647,-9.62334659694429E-7,299.9983215,299.9983215,-78923.9453125,-78899.109375,57.6107116384292,20.6944783857145,25.186911,0,0,0,40,4449,300.1492,-78911.52734375,,,,,,,,,,,,,0,,,,-0.00245,,,,,,299.9983215,,,,
,29305497.73,299.9915466,-74064.27734375,0.000316357575794058,3.57086348615996E-6,1,0.999253354069792,40.0298881530762,1.99365453980688,15.7500002533197,0.00355882536974381,0.000692602477917517,0.25,6.53882417421396E-6,0.000316344249801543,6.74527556939909E-6,299.9915466,299.9915466,-74076.8125,-74051.7421875,57.8874081342369,20.6919759524361,24.807261,0,0,0,40,4449,300.1626,-74064.27734375,,,,,,,,,,,,,0,,,,0.00245,,,,,,299.9915466,,,,
,29305596.08,299.9903564,-69149.6015625,0.000273803991632401,2.53289692581167E-6,1,0.999253354069792,40.0298881530762,1.99383692152366,15.7500002533197,0.00309859351983477,0.000494438468949436,0.25,-3.64531057956403E-6,0.000273798530675969,-3.46614098621648E-6,299.9903564,299.9903564,-69154.5859375,-69144.6171875,57.6638623777369,20.6916680232944,24.427608,0,0,0,40,4449,300.1639,-69149.6015625,,,,,,,,,,,,,0,,,,-0.0049,,,,,,299.9903564,,,,
,29305694.98,299.9927368,-64207.734375,0.000249381875856989,2.95799132722001E-6,1,0.999253354069792,40.0298881530762,1.99371757375472,15.7500002533197,0.00281818262521512,0.000472638406094838,0.25,-1.34275285619074E-6,0.000249375571026214,-1.1794241005904E-6,299.9927368,299.9927368,-64212.58984375,-64202.87890625,57.7177947455638,20.6928646088548,24.807261,0,0,0,40,4449,300.1714,-64207.734375,,,,,,,,,,,,,0,,,,0.00245,,,,,,299.9927368,,,,
,29305794.025,299.9885559,-59255.193359375,0.000233494808245105,2.71993088610077E-6,1,0.999253354069792,40.0298881530762,1.99345190871479,15.7500002533197,0.00260973686704951,0.000607410250115837,0.25,1.33534920639406E-5,0.000233479347380983,1.35061736805998E-5,299.9885559,299.9885559,-59265.0859375,-59245.30078125,57.7091968318523,20.6933223613299,24.807261,0,0,0,40,4449,300.18655,-59255.193359375,,,,,,,,,,,,,0,,,,0.00245,,,,,,299.9885559,,,,
,29305894.415,299.9898834,-54238.4140625,0.000196492573434231,2.66678798393782E-6,1,0.999253354069792,40.0298881530762,1.99394271931782,15.7500002533197,0.00220590315501733,0.000458062116328252,0.25,6.52463496876658E-6,0.000196482623090061,6.65341560663886E-6,299.9895935,299.9901733,-54243.33984375,-54233.48828125,57.5950790680446,20.688800650123,24.807261,0,0,0,40,4449,300.18,-54238.4140625,,,,,,,,,,,,,0,,,,-0.00245,,,,,,299.9898834,,,,
,29305994.42,299.9854431,-49241.609375,0.000172706070865887,2.20760438066899E-6,1,0.999253354069792,40.0298881530762,1.9937680697071,15.7500002533197,0.00192493167367301,0.000482072776772315,0.25,1.27756121494294E-5,0.000172692709779526,1.28887333570905E-5,299.9854431,299.9854431,-49246.59765625,-49236.62109375,57.6060218673138,20.6929738125823,25.186911,0,0,0,40,4449,300.1868,-49241.609375,,,,,,,,,,,,,0,,,,-0.00245,,,,,,299.9854431,,,,
,29306095.29,299.9834595,-44199.1015625,0.000141088502651126,1.4578276822388E-6,1,0.999253354069792,40.0298881530762,1.9938964301798,15.7500002533197,0.00157433942636759,0.000383965191388991,0.25,9.56181759993248E-6,0.000141078157196403,9.65435280130702E-6,299.9834595,299.9834595,-44204.10546875,-44194.09765625,57.7873596837753,20.6868588148445,25.186911,0,0,0,40,4449,300.2181,-44199.1015625,,,,,,,,,,,,,0,,,,0,,,,,,299.9834595,,,,
,29306194.655,299.9918213,-39233.982421875,0.000110384459330404,2.23166507857286E-6,1,0.999253354069792,40.0298881530762,1.99388586791661,15.7500002533197,0.00122996230830299,0.000310554273593652,0.25,8.37983092704144E-6,0.000110375727367192,8.45228086218408E-6,299.9918213,299.9918213,-39241.4765625,-39226.48828125,57.7670373422753,20.686239263986,24.807261,0,0,0,40,4449,300.22205,-39233.982421875,,,,,,,,,,,,,0,,,,0.00245,,,,,,299.9918213,,,,
,29306294.73,299.9898376,-34232.466796875,8.40743626210949E-5,1.583856785077E-6,1,0.999253354069792,40.0298881530762,1.99374914077774,15.7500002533197,0.000926415016326131,0.000296111335140425,0.25,1.16606927091477E-5,8.40642278139644E-5,1.17157825630992E-5,299.9898376,299.9898376,-34239.8203125,-34225.11328125,57.7177947455638,20.686675616647,24.807261,0,0,0,40,4449,300.2218,-34232.466796875,,,,,,,,,,,,,0,,,,-0.00245,,,,,,299.9898376,,,,
,29306391.165,299.9866333,-29412.875,5.36140959790124E-5,1.58044518164454E-6,1,0.999253354069792,40.0298881530762,1.99376077323643,15.7500002533197,0.000582006184660102,0.000239452649031365,0.25,1.19196042211245E-5,5.36046720464679E-5,1.19546409031512E-5,299.9866333,299.9866333,-29417.98046875,-29407.76953125,57.8420736801215,20.6871535989002,24.427608,0,0,0,40,4449,300.2306,-29412.875,,,,,,,,,,,,,0,,,,-0.00245,,,,,,299.9866333,,,,
,29306490.535,299.983078,-24448.2333984375,2.53824623625364E-5,2.0438947128127E-6,1,0.999253354069792,40.0298881530762,1.994123546036,15.7500002533197,0.000271310567249146,0.00013806250564043,0.25,7.82853663069166E-6,2.53765549979053E-5,7.84507798586073E-6,299.9823914,299.9837646,-24460.92578125,-24435.541015625,57.6740235484869,20.6850683942067,24.807261,0,0,0,40,4449,300.23915,-24448.2333984375,,,,,,,,,,,,,0,,,,0,,,,,,299.983078,,,,
,29306590.81,299.9892578,-19436.1689453125,-1.68582357140843E-6,1.08608581907326E-6,1,0.999253354069792,40.0298881530762,1.99384724923181,15.7500002533197,-2.48645291297746E-5,3.03525500546762E-5,0.25,2.98033173700565E-6,-1.68774503583786E-6,2.97912974519513E-6,299.9892578,299.9892578,-19448.494140625,-19423.84375,57.9288344457561,20.6860834139892,25.186911,0,0,0,40,4449,300.2488,-19436.1689453125,,,,,,,,,,,,,0,,,,0.0049,,,,,,299.9892578,,,,
,29306688.21,299.9916382,-14566.1923828125,-2.84203654447257E-5,7.82202042752302E-7,1,0.999253354069792,40.0298881530762,1.99375151222105,15.7500002533197,-0.000328737430650456,-1.02116599348536E-5,0.25,4.01960479642995E-6,-2.84221902720003E-5,4.00067618359565E-6,299.9916382,299.9916382,-14571.3603515625,-14561.0244140625,57.7983024830446,20.6848097929481,24.807261,0,0,0,40,4449,300.2571,-14566.1923828125,,,,,,,,,,,,,0,,,,0.0049,,,,,,299.9916382,,,,
,29306787.805,299.9968872,-9588.99072265625,-5.24326074004526E-5,6.76694328529218E-7,1,0.999253354069792,40.0298881530762,1.99374098678697,15.7500002533197,-0.000595135163666148,-8.43362306174217E-5,0.25,1.61458875624247E-6,-5.24321227185577E-5,1.57980673718902E-6,299.9968872,299.9968872,-9598.6591796875,-9579.322265625,57.6537012069869,20.6849203364292,24.807261,0,0,0,40,4449,300.258,-9588.99072265625,,,,,,,,,,,,,0,,,,0,,,,,,299.9968872,,,,
,29306882.21,299.9940186,-4873.1123046875,-6.48545967796138E-5,5.03646799362696E-7,1,0.999253354069792,40.0298881530762,1.99387201181861,15.7500002533197,-0.000733146610333147,-0.000121813161180327,0.25,4.48111422958025E-7,-6.48529751221812E-5,4.05102612287202E-7,299.9940186,299.9940186,-4875.59326171875,-4870.63134765625,57.779543398583,20.6845349876351,25.186911,0,0,0,40,4449,300.2603,-4873.1123046875,,,,,,,,,,,,,0,,,,0,,,,,,299.9940186,,,,
,29306976.23,299.9981689,-171.412109375,-9.89032339050848E-6,4.42243620726924E-7,1,0.999253354069792,40.0298881530762,1.99376193101206,15.7500002533197,-0.000111442722106057,-2.06313527162176E-5,0.25,-1.13746741959481E-7,-9.88995350630373E-6,-1.20304052831869E-7,299.9981689,299.9981689,-176.558013916016,-166.266204833984,57.7365538300253,20.6863592245105,24.807261,0,0,0,40,4449,300.2621,-171.412109375,,,,,,,,,,,,,0,,,,0,,,,,,299.9981689,,,,
,29307070.555,299.9914856,4539.87768554687,6.54040965296436E-5,3.8424772096211E-7,1,0.999253354069792,40.0298881530762,1.99373684496501,15.7500002533197,0.00074196824930075,0.000107498377846149,0.25,-1.81051346073777E-6,6.54033677202923E-5,-1.76709933138285E-6,299.9914856,299.9914856,4532.41064453125,4547.3447265625,57.6716786629292,20.687242983388,25.186911,0,0,0,40,4449,300.26775,4539.87768554687,,,,,,,,,,,,,0,,,,0.00245,,,,,,299.9914856,,,,
,29307167.565,299.9985046,9388.47509765625,5.33827028263393E-5,6.0384118891992E-7,1,0.999253354069792,40.0298881530762,1.99344728458228,15.7500002533197,0.000606101346470716,8.43090526789748E-5,0.25,-1.78055719177606E-6,5.33822968630799E-5,-1.74514142699994E-6,299.9985046,299.9985046,9381.1220703125,9395.828125,57.8076820252753,20.6900322975544,24.807261,0,0,0,40,4449,300.2715,9388.47509765625,,,,,,,,,,,,,0,,,,0,,,,,,299.9985046,,,,
,29307263.15,300.0050964,14168.8251953125,3.00920542215818E-5,7.67157491975524E-7,1,0.999253354069792,40.0298881530762,1.99356576350251,15.7500002533197,0.000342511777769193,4.27341559316499E-5,0.25,-1.42833220093706E-6,3.0092100244261E-5,-1.40837184747785E-6,300.0050964,300.0050964,14163.9794921875,14173.6708984375,57.4410982497561,20.6891088567813,24.427608,0,0,0,40,4449,300.2655,14168.8251953125,,,,,,,,,,,,,0,,,,-0.0049,,,,,,300.0050964,,,,
,29307359.135,300.0074768,18963.359375,4.82188314504789E-6,5.47450653133985E-7,1,0.999253354069792,40.0298881530762,1.99336126798212,15.7500002533197,6.10605282554802E-5,-2.88373666375878E-5,0.25,-3.39007881980491E-6,4.82398073693568E-6,-3.38678867216513E-6,300.0074768,300.0074768,18955.833984375,18970.884765625,57.7474966292946,20.6886548962693,24.807261,0,0,0,40,4449,300.2593,18963.359375,,,,,,,,,,,,,0,,,,0,,,,,,300.0074768,,,,
,29307458.54,300.0061951,23933.455078125,-2.33871838248635E-5,9.18653657608113E-7,1,0.999253354069792,40.0298881530762,1.99345998914437,15.7500002533197,-0.000254499121357163,-0.000100644918579549,0.25,-4.86352890231035E-6,-2.33832733806444E-5,-4.87883481238441E-6,300.0061951,300.0061951,23928.3515625,23938.55859375,57.7201396311215,20.685063620573,24.807261,0,0,0,40,4449,300.2527,23933.455078125,,,,,,,,,,,,,0,,,,-0.0049,,,,,,300.0061951,,,,
,29307556.25,300.0092468,28816.2451171875,-4.8791240503856E-5,1.53818664756914E-6,1,0.999253354069792,40.0298881530762,1.99337295464651,15.7500002533197,-0.000536654836884441,-0.000176881948580212,0.25,-7.21615830161475E-6,-4.87850207770633E-5,-7.24814426422706E-6,300.0092468,300.0092468,28811.232421875,28821.2578125,57.7076335748138,20.6864018979153,24.807261,0,0,0,40,4449,300.2518,28816.2451171875,,,,,,,,,,,,,0,,,,0,,,,,,300.0092468,,,,
,29307655.18,300.0119324,33761.162109375,-7.79829914865247E-5,1.64073964554437E-6,1,0.999253354069792,40.0298881530762,1.99382591385186,15.7500002533197,-0.000867076791499923,-0.000229926125133545,0.25,-6.85319127420213E-6,-7.79761410879048E-5,-6.90440253439605E-6,300.0119324,300.0119324,33753.51171875,33768.8125,57.6146197810253,20.6782226692656,24.427608,0,0,0,40,4449,300.2336,33761.162109375,,,,,,,,,,,,,0,,,,0,,,,,,300.0119324,,,,
,29307754.29,300.0075989,38713.509765625,-0.000106060026686526,2.48413193113091E-6,1,0.999253354069792,40.0298881530762,1.99354960683248,15.7500002533197,-0.0011719653259512,-0.000353870097130358,0.25,-1.29704190646493E-5,-0.00010604833583826,-1.30398872437022E-5,300.0075989,300.0075989,38705.88671875,38721.1328125,57.5481813568907,20.6854351625494,25.186911,0,0,0,40,4449,300.2257,38713.509765625,,,,,,,,,,,,,0,,,,0,,,,,,300.0075989,,,,
,29307852.115,300.0148468,43603.291015625,-0.000131195518596506,1.61996889484642E-6,1,0.999253354069792,40.0298881530762,1.99339878300788,15.7500002533197,-0.00146364381963272,-0.00035669112250879,0.25,-8.86783303967042E-6,-0.000131185763889572,-8.95388440292526E-6,300.01474,300.0149536,43598.23046875,43608.3515625,57.616964666583,20.6853707616395,24.427608,0,0,0,40,4449,300.2114,43603.291015625,,,,,,,,,,,,,0,,,,0,,,,,,300.0148468,,,,
,29307950.23,300.00819395,48506.27734375,-0.000165161771015151,1.85140755764059E-6,1,0.999253354069792,40.0298881530762,1.99340462936706,15.7500002533197,-0.00184360336342388,-0.0004431556772269,0.25,-1.06426240729415E-5,-0.000165149891692352,-1.07508520795943E-5,300.0080566,300.0083313,48501.2421875,48511.3125,57.6239993232561,20.6851077076471,24.807261,0,0,0,40,4449,300.2033,48506.27734375,,,,,,,,,,,,,0,,,,0,,,,,,300.00819395,,,,
,29308048.575,300.0148621,53423.78515625,-0.000200759605056822,2.35128211149589E-6,1,0.999253354069792,40.0298881530762,1.99345517619374,15.7500002533197,-0.00223362562943175,-0.000581333862523207,0.25,-1.67147709390667E-5,-0.000200742660680882,-1.68460574530001E-5,300.0148621,300.0148621,53413.7109375,53433.859375,57.6294707228907,20.6839988232305,24.807261,0,0,0,40,4449,300.20225,53423.78515625,,,,,,,,,,,,,0,,,,0.0049,,,,,,300.0148621,,,,
,29308147.51,300.0144653,58366.681640625,-0.000229573091007245,2.57287465644151E-6,1,0.999253354069792,40.0298881530762,1.99350097352095,15.7500002533197,-0.00256295844625593,-0.000614559643523374,0.25,-1.46649988574074E-5,-0.000229556664238328,-1.48150916525009E-5,300.0144653,300.0144653,58356.62109375,58376.7421875,57.5450548428138,20.6831685986996,24.427608,0,0,0,40,4449,300.1848,58366.681640625,,,,,,,,,,,,,0,,,,0,,,,,,300.0144653,,,,
,29308247.79,300.0134277,63379.646484375,-0.00025249099492392,3.11509335222904E-6,1,0.999253354069792,40.0298881530762,1.99373975130301,15.7500002533197,-0.00282171854442064,-0.000661087648436507,0.25,-1.48094690985382E-5,-0.000252473832050684,-1.49743887284796E-5,300.0134277,300.0134277,63369.73828125,63389.5546875,57.6200911806599,20.680189859237,24.807261,0,0,0,40,4449,300.1749,63379.646484375,,,,,,,,,,,,,0,,,,0,,,,,,300.0134277,,,,
,29308347.18,300.0135803,68347.17578125,-0.000265480509255351,3.69944065275557E-6,1,0.999253354069792,40.0298881530762,1.99368585946901,15.7500002533197,-0.00297707484265032,-0.000635813307449208,0.25,-1.03220749148596E-5,-0.000265465926069059,-1.04954287925137E-5,300.0135803,300.0135803,68342.0859375,68352.265625,57.3543374841214,20.6793463591622,25.186911,0,0,0,40,4449,300.1612,68347.17578125,,,,,,,,,,,,,0,,,,0,,,,,,300.0135803,,,,
,29308446.24,300.0195313,73300.16796875,-0.000300829774438815,3.19316996793239E-6,1,0.999253354069792,40.0298881530762,1.99382219029995,15.7500002533197,-0.00336108392409738,-0.000793329862699434,0.25,-1.81453694223046E-5,-0.000300809002153871,-1.83413755378152E-5,300.0195313,300.0195313,73295.203125,73305.1328125,57.4098331089868,20.6787152591067,24.807261,0,0,0,40,4449,300.14965,73300.16796875,,,,,,,,,,,,,0,,,,-0.0049,,,,,,300.0195313,,,,
,29308546.295,300.0198059,78300.29296875,-0.000321284179763566,3.6246202953181E-6,1,0.999253354069792,40.0298881530762,1.99362046634359,15.7500002533197,-0.00359835744137958,-0.000794728987016877,0.25,-1.4732622091459E-5,-0.000321265062690803,-1.49418337943585E-5,300.0198059,300.0198059,78297.84375,78302.7421875,57.5294222724292,20.6795577136488,24.807261,0,0,0,40,4449,300.1396,78300.29296875,,,,,,,,,,,,,0,,,,0,,,,,,300.0198059,,,,
,29308645.07,300.0137634,83238.59765625,-0.000355071391469293,4.28621823622036E-6,1,0.999253354069792,40.0298881530762,1.99365808436276,15.7500002533197,-0.00395914796886956,-0.000980466742286657,0.25,-2.53298226951706E-5,-0.000355044483654036,-2.5560484081436E-5,300.0137634,300.0137634,83231.296875,83245.8984375,57.2785195177561,20.6788420414685,24.807261,0,0,0,40,4449,300.1346,83238.59765625,,,,,,,,,,,,,0,,,,0,,,,,,300.0137634,,,,
,29308741,300.0110779,88034.3203125,-0.000381107265505346,3.24049042877413E-6,1,0.999253354069792,40.0298881530762,1.99357489673057,15.7500002533197,-0.0042265646486436,-0.00118347480783404,0.25,-3.8805126550981E-5,-0.000381070906086547,-3.90520721242913E-5,300.0110779,300.0110779,88029.40625,88039.234375,57.4473512779099,20.6798231891399,25.566563,0,0,0,40,4449,300.118,88034.3203125,,,,,,,,,,,,,0,,,,0.00245,,,,,,300.0110779,,,,
,29308854.245,300.0087891,87301.12109375,-0.000395208325569488,2.78642514445837E-6,1,0.999253354069792,40.0298881530762,1.99342827554568,15.7500002533197,-0.00440753240389039,-0.0010835023577476,0.25,-2.75133845712234E-5,-0.000395178928948003,-2.7769897885509E-5,300.0087891,300.0087891,87298.625,87303.6171875,57.4356268501215,20.6790498930843,25.186911,0,0,0,40,4449,300.1094,87301.12109375,,,,,,,,,,,,,0,,,,0.0049,,,,,,300.0087891,,,,
,29308952.535,300.002533,82387.265625,-0.000356889912033134,2.95165013888882E-6,1,0.999253354069792,40.0298881530762,1.99348731334617,15.7500002533197,-0.00397296523781802,-0.00102082442752327,0.25,-2.85967491520303E-5,-0.000356860952904082,-2.88285877417806E-5,300.002533,300.002533,82379.703125,82394.828125,57.4817429327561,20.6778985500815,25.186911,0,0,0,40,4449,300.1066,82387.265625,,,,,,,,,,,,,0,,,,-0.00245,,,,,,300.002533,,,,
,29309053.04,299.9941711,77363.6953125,-0.000335701815581211,2.59499464324501E-6,1,0.999253354069792,40.0298881530762,1.99337930076555,15.7500002533197,-0.00375228185742589,-0.000871400744068786,0.25,-1.90349128933135E-5,-0.000335679763284512,-1.92534948538684E-5,299.9941711,299.9941711,77351.203125,77376.1875,57.5802281261792,20.6810645071712,25.566563,0,0,0,40,4449,300.11665,77363.6953125,,,,,,,,,,,,,0,,,,0,,,,,,299.9941711,,,,
,29309152.665,299.99816895,72382.95703125,-0.00030545827157118,2.55009894743489E-6,1,0.999253354069792,40.0298881530762,1.99342169233802,15.7500002533197,-0.00341875050207471,-0.000767254126380761,0.25,-1.50469083229069E-5,-0.000305439611120546,-1.52461119930267E-5,299.9977417,299.9985962,72367.828125,72398.0859375,57.555997642083,20.6822160030561,25.566563,0,0,0,40,4449,300.11885,72382.95703125,,,,,,,,,,,,,0,,,,0.00245,,,,,,299.99816895,,,,
,29309251.265,299.9931793,67455.1484375,-0.000270132932876934,2.95191819838274E-6,1,0.999253354069792,40.0298881530762,1.99343228496984,15.7500002533197,-0.00302761944431175,-0.000654159450579595,0.25,-1.11479751778434E-5,-0.000270117862830327,-1.13244124442744E-5,299.992218,299.9941406,67445.5,67464.796875,57.190195495083,20.681062788328,25.186911,0,0,0,40,4449,300.13665,67455.1484375,,,,,,,,,,,,,0,,,,-0.00245,,,,,,299.9931793,,,,
,29309344.985,299.9875793,62770.107421875,-0.000245139685171985,2.73538717988737E-6,1,0.999253354069792,40.0298881530762,1.99323551687081,15.7500002533197,-0.0027464871322248,-0.000597921086965945,0.25,-1.05010053587321E-5,-0.000245125783534203,-1.06612881059468E-5,299.9875793,299.9875793,62762.4921875,62777.72265625,57.5872627828522,20.6844560998601,24.807261,0,0,0,40,4449,300.14895,62770.107421875,,,,,,,,,,,,,0,,,,0,,,,,,299.9875793,,,,
,29309440.385,299.9860535,58004.46875,-0.000224316652989144,2.41765931374627E-6,1,0.999253354069792,40.0298881530762,1.9932901546157,15.7500002533197,-0.00250909752280936,-0.000571150917175966,0.25,-1.17354766848131E-5,-0.000224302527645322,-1.18822522599051E-5,299.9860535,299.9860535,57999.61328125,58009.32421875,57.3105662870445,20.6868500755136,25.566563,0,0,0,40,4449,300.1543,58004.46875,,,,,,,,,,,,,0,,,,-0.00245,,,,,,299.9860535,,,,
,29309534.25,299.9887695,53311.275390625,-0.000182535755206719,2.26377564152735E-6,1,0.999253354069792,40.0298881530762,1.99363351085193,15.7500002533197,-0.00203085635973368,-0.000529696351390077,0.25,-1.52937686093647E-5,-0.000182520452843739,-1.54131721353705E-5,299.9887695,299.9887695,53306.2421875,53316.30859375,57.830349252333,20.6786105833977,25.566563,0,0,0,40,4449,300.1598,53311.275390625,,,,,,,,,,,,,0,,,,0,,,,,,299.9887695,,,,
,29309630.895,299.9864197,48480.876953125,-0.00015543505178038,2.53932973847882E-6,1,0.999253354069792,40.0298881530762,1.99351481410177,15.7500002533197,-0.00172686433638521,-0.000464745514802877,0.25,-1.42381581259023E-5,-0.000155421216270789,-1.43399123925461E-5,299.9864197,299.9864197,48473.58203125,48488.171875,57.5098815594484,20.681894115119,25.186911,0,0,0,40,4449,300.1702,48480.876953125,,,,,,,,,,,,,0,,,,0,,,,,,299.9864197,,,,
,29309729.43,299.9867554,43552.8515625,-0.000124613297331617,2.04972096727494E-6,1,0.999253354069792,40.0298881530762,1.99365279385953,15.7500002533197,-0.00139121187517389,-0.000334045534126244,0.25,-7.99849562129216E-6,-0.000124604434992132,-8.08026360767906E-6,299.9867554,299.9867554,43545.140625,43560.5625,57.5700669554292,20.6817667150526,25.186911,0,0,0,40,4449,300.17335,43552.8515625,,,,,,,,,,,,,0,,,,-0.0049,,,,,,299.9867554,,,,
,29309828.115,299.9923096,38623.318359375,-0.000102814835103368,2.00326862483295E-6,1,0.999253354069792,40.0298881530762,1.99352660290606,15.7500002533197,-0.00115195140643911,-0.000251512486551505,0.25,-4.46603834577172E-6,-0.000102808896857884,-4.53363418570364E-6,299.9919739,299.9926453,38618.703125,38627.93359375,57.6482298073523,20.6814237934851,24.807261,0,0,0,40,4449,300.19275,38623.318359375,,,,,,,,,,,,,0,,,,0,,,,,,299.9923096,,,,
,29309926.555,299.9891357,33703.79296875,-7.56929735330503E-5,1.63048116011989E-6,1,0.999253354069792,40.0298881530762,1.99365602117476,15.7500002533197,-0.000846360268545661,-0.000195373632431317,0.25,-4.19107603778658E-6,-7.56880076959193E-5,-4.24086806411137E-6,299.9891357,299.9891357,33696.40234375,33711.18359375,57.4371901071599,20.6805379105206,25.186911,0,0,0,40,4449,300.198,33703.79296875,,,,,,,,,,,,,0,,,,-0.0049,,,,,,299.9891357,,,,
,29310020.3,299.9936218,29018.943359375,-5.31456821072131E-5,1.55544495542316E-6,1,0.999253354069792,40.0298881530762,1.99355392345159,15.7500002533197,-0.000594468131651041,-0.000135729889637111,0.25,-2.81510467600899E-6,-5.31422660305658E-5,-2.85010284332296E-6,299.9936218,299.9936218,29013.822265625,29024.064453125,57.6075851243522,20.6834455212331,25.186911,0,0,0,40,4449,300.2021,29018.943359375,,,,,,,,,,,,,0,,,,-0.0098,,,,,,299.9936218,,,,
,29310114.89,299.9881897,24291.568359375,-2.48955011162473E-5,1.4020823106039E-6,1,0.999253354069792,40.0298881530762,1.99362395459196,15.7500002533197,-0.000277021505740555,-7.20090163860787E-5,0.25,-2.06501396882716E-6,-2.48934104321822E-5,-2.0814024650926E-6,299.9881897,299.9881897,24286.888671875,24296.248046875,57.7654740852369,20.6825007339795,24.807261,0,0,0,40,4449,300.2134,24291.568359375,,,,,,,,,,,,,0,,,,0,,,,,,299.9881897,,,,
,29310209.01,299.9884949,19586.765625,1.79511529327917E-6,9.86574147783421E-7,1,0.999253354069792,40.0298881530762,1.993786935598,15.7500002533197,2.27685141167376E-5,-1.09222621185279E-5,0.25,-1.27840325290436E-6,1.79590822900018E-6,-1.27717874254654E-6,299.9884949,299.9884949,19578.79296875,19594.73828125,57.6107116384292,20.6838011127591,25.566563,0,0,0,40,4449,300.2241,19586.765625,,,,,,,,,,,,,0,,,,0.0049,,,,,,299.9884949,,,,
,29310307.705,299.9918823,14654.2265625,2.71873824179277E-5,9.59135944542776E-7,1,0.999253354069792,40.0298881530762,1.99352959448449,15.7500002533197,0.000310901078063587,3.02056290646257E-5,0.25,-2.03479936052394E-6,2.7187929568975E-5,-2.01674399294061E-6,299.9916992,299.9920654,14646.564453125,14661.888671875,57.3738781971022,20.6848429741485,25.566563,0,0,0,40,4449,300.23665,14654.2265625,,,,,,,,,,,,,0,,,,0.0049,,,,,,299.9918823,,,,
,29310404.715,299.9888306,9804.54443359375,4.94677245297157E-5,7.72690071414728E-7,1,0.999253354069792,40.0298881530762,1.99358559191895,15.7500002533197,0.000562907722077874,7.10942510990888E-5,0.25,-2.2733000747635E-6,4.94677783598648E-5,-2.24046192625931E-6,299.9888306,299.9888306,9799.6591796875,9809.4296875,57.8217513386215,20.6786195443551,24.807261,0,0,0,40,4449,300.2382,9804.54443359375,,,,,,,,,,,,,0,,,,-0.0049,,,,,,299.9888306,,,,
,29310501.245,299.9933167,4981.57836914063,6.48368994545193E-5,4.72226782734737E-7,1,0.999253354069792,40.0298881530762,1.99379551956536,15.7500002533197,0.000732500792621271,0.000124193414712843,0.25,-2.33833848547399E-7,6.48351377269095E-5,-1.90841118392577E-7,299.9933167,299.9933167,4976.62060546875,4986.5361328125,57.5317671579869,20.6807493225284,24.807261,0,0,0,40,4449,300.2444,4981.57836914063,,,,,,,,,,,,,0,,,,0.0049,,,,,,299.9933167,,,,
,29310594.225,299.9926147,332.360534667969,1.35963574236626E-5,4.44177054225349E-7,1,0.999253354069792,40.0298881530762,1.99359939183337,15.7500002533197,0.000154627224626678,2.0064109403288E-5,0.25,-5.7846427075954E-7,1.35963390863918E-5,-5.69427802215454E-7,299.9926147,299.9926147,327.354583740234,337.366485595703,57.5817913832176,20.6862663934405,25.566563,0,0,0,40,4449,300.25075,332.360534667969,,,,,,,,,,,,,0,,,,-0.0049,,,,,,299.9926147,,,,
,29310600.565,299.9915161,-0.365370571613312,3.67651706622256E-6,3.3034435550967E-7,1,0.999253354069792,40.0298881530762,1.99354596952896,15.7500002533197,4.22893168285015E-5,2.66366982667281E-6,0.25,-4.01044513479761E-7,3.67667452980715E-6,-3.98593742265764E-7,299.9915161,299.9915161,-0.42626565694809,-0.304475486278534,57.71154171741,20.6823452801321,24.807261,0,0,0,40,4417,300.2517,-0.365370571613312,,,,,,,,,,,,,0,,,,0,,,,,,299.9915161,,,,