File: data/looselyPackedNP/sc-ios-7/ppms/rawdata/ES_S17_FCC_100OE.DAT
[Header]
; VSM Data File (default extension .dat)
; Copyright (c) 2003-2013, Quantum Design, Inc. All rights reserved.
TITLE,
FILEOPENTIME,29330244.69,12/06/2018,7:18 pm
BYAPP,VSM,2.0,2.0
INFO,PPMS VSM Option Release 1.4.10 Build 1,APPNAME
INFO,Quantum Design Linear Motor Servo Controller,MOTOR_MODULE_NAME
INFO,3101-100 M1,MOTOR_HW_VERSION
INFO,MMC1014,MOTOR_SERIAL_NUMBER
INFO,SRV No X-over 01.03.11,MOTOR_SOFTWARE_VERSION
INFO,Quantum Design VSM Detection Module,VSM_MODULE_NAME
INFO,3101-150 F0,VSM_HW_VERSION
INFO,VSM707,VSM_SERIAL_NUMBER
INFO,VSM No X-over 01.02.05 May 20 2008 13:51:47,VSM_SOFTWARE_VERSION
INFO,704,PREAMP_SERIAL_NUMBER
INFO,822,COIL_SERIAL_NUMBER
INFO,0,MOMENT_UNITS
INFO,Iron Oxide Spheres,SAMPLE_MATERIAL
INFO,7 nm diameter, collaboration Mainz,SAMPLE_COMMENT
INFO,,SAMPLE_MASS
INFO,,SAMPLE_VOLUME
INFO,,SAMPLE_MOLECULAR_WEIGHT
INFO,,SAMPLE_SIZE
INFO,,SAMPLE_SHAPE
DATATYPE,COMMENT,1
DATATYPE,TIME,2
STARTUPAXIS,X,2
STARTUPAXIS,Y1,5
[Data]
Comment,Time Stamp (sec),Temperature (K),Magnetic Field (Oe),Moment (emu),M. Std. Err. (emu),Transport Action,Averaging Time (sec),Frequency (Hz),Peak Amplitude (mm),Center Position (mm),Coil Signal' (mV),Coil Signal" (mV),Range (mV),M. Quad. Signal (emu),M. Raw' (emu),M. Raw" (emu),Min. Temperature (K),Max. Temperature (K),Min. Field (Oe),Max. Field (Oe),Mass (grams),Motor Lag (deg),Pressure (Torr),VSM Status (code),Motor Status (code),Measure Status (code),Measure Count,PPMS Status (code),System Temp. (K),System Field (Oe),Sample Position (deg),Bridge 1 Resistance (ohms),Bridge 1 Excitation (에),Bridge 2 Resistance (ohms),Bridge 2 Excitation (에),Bridge 3 Resistance (ohms),Bridge 3 Excitation (에),Bridge 4 Resistance (ohms),Bridge 4 Excitation (에),Signal 1 Vin (V),Signal 2 Vin (V),Digital Inputs (code),Drive 1 Iout (mA),Drive 1 Ipower (W),Drive 2 Iout (mA),Drive 2 Ipower (W),Pressure (),Map 20 (),Map 21 (),Map 22 (),Map 23 (),Map 24 (),Map 25 (),Map 26 (),Map 27 (),Map 28 (),Map 29 ()
,29330379.02,349.6208191,99.5482559204102,3.36295168364154E-6,4.17381968781099E-7,1,0.999253354069792,40.0298881530762,1.99590074620778,15.5300004407763,3.80005146372206E-5,6.23597482531695E-6,0.25,-2.95918358812407E-8,3.35704886510003E-6,-2.76653869004653E-8,349.6208191,349.6208191,99.5482559204102,99.5482559204102,57.4176493941791,20.6568500378198,25.566563,0,0,0,40,4369,350.2614,99.5482559204102,,,,,,,,,,,,,0,,,,-0.0049,,,,,,349.6208191,,,,
,29330509.535,347.4937744,99.5482559204102,3.91569293098615E-6,4.65835245849605E-7,1,0.999253354069792,40.0298881530762,1.99544897351154,15.5300004407763,4.4549878164111E-5,5.4701092360331E-6,0.25,-1.93139687987359E-7,3.90918951440091E-6,-1.90601919910474E-7,347.4937744,347.4937744,99.5482559204102,99.5482559204102,57.2605420618137,20.6597597195569,25.566563,0,0,0,40,4374,345.6961,99.5482559204102,,,,,,,,,,,,,0,,,,0,,,,,,347.4937744,,,,
,29330637.095,344.4714966,99.5482559204102,3.89961805122338E-6,4.56462214846949E-7,1,0.999253354069792,40.0298881530762,1.9957929854363,15.5300004407763,4.39807890121232E-5,7.74787103916147E-6,0.25,1.13523283382272E-8,3.89342551073932E-6,1.35579852913087E-8,344.4714966,344.4714966,99.5482559204102,99.5482559204102,57.4481329064291,20.658442458889,25.946213,0,0,0,40,4374,342.55395,99.5482559204102,,,,,,,,,,,,,0,,,,0,,,,,,344.4714966,,,,
,29330766.06,341.4517822,99.5482559204102,3.45905430814998E-6,4.87898021364617E-7,1,0.999253354069792,40.0298881530762,1.99581658054602,15.5300004407763,3.84201645980759E-5,1.03167562351317E-5,0.25,3.15176268624841E-7,3.45374107834858E-6,3.16702420267711E-7,341.4517822,341.4517822,99.5482559204102,99.5482559204102,57.3261988574291,20.658803341046,25.566563,0,0,0,40,4374,339.12435,99.5482559204102,,,,,,,,,,,,,0,,,,-0.00245,,,,,,341.4517822,,,,
,29330889.705,338.4758911,99.5482559204102,3.50228978731551E-6,4.38642199226514E-7,1,0.999253354069792,40.0298881530762,1.99600481882189,15.5300004407763,4.01078066377089E-5,3.51856296066941E-6,0.25,-2.94790852127447E-7,3.49762243963954E-6,-2.92344153972214E-7,338.4758911,338.4758911,99.5482559204102,99.5482559204102,57.4387533641984,20.6499220146018,25.566563,0,0,0,40,4374,335.9462,99.5482559204102,,,,,,,,,,,,,0,,,,-0.00245,,,,,,338.4758911,,,,
,29331012.53,335.480011,99.5482559204102,4.13433911659053E-6,4.7276395599293E-7,1,0.999253354069792,40.0298881530762,1.99594242146954,15.5300004407763,4.64358261625661E-5,9.42936015953617E-6,0.25,1.19332248791025E-7,4.12898256100017E-6,1.21612067666491E-7,335.480011,335.480011,99.5482559204102,99.5482559204102,57.6138381525061,20.6495164193041,25.946213,0,0,0,40,4374,332.8194,99.5482559204102,,,,,,,,,,,,,0,,,,0,,,,,,335.480011,,,,
,29331146.97,332.1899414,99.5482559204102,,,2,,,,15.4999998790026,,,,,,,332.1899414,332.1899414,99.5482559204102,99.5482559204102,,,25.946213,,,,-99999999,4374,329.3752,99.5482559204102,,,,,,,,,,,,,,,,,,,,,,,332.1899414,,,,
,29331255.855,329.4880676,99.5482559204102,4.10109936548957E-6,4.48765061623572E-7,1,0.999253354069792,40.0298881530762,2.00854627916715,15.4900001361966,4.72579440117978E-5,4.16705054768024E-6,0.25,-3.43428804827391E-7,4.0969125086235E-6,-3.4059658715454E-7,329.4880676,329.4880676,99.5482559204102,99.5482559204102,57.4903408464676,20.6444367826137,25.946213,0,0,0,40,4374,326.62995,99.5482559204102,,,,,,,,,,,,,0,,,,0,,,,,,329.4880676,,,,
,29331378.68,326.4633789,99.5482559204102,3.71782549578912E-6,4.19892724030218E-7,1,0.999253354069792,40.0298881530762,2.00844395196871,15.4900001361966,4.30597487724155E-5,2.53130815471093E-6,0.25,-4.21095086937401E-7,3.71449027323975E-6,-4.18429817020334E-7,326.437439,326.4893188,99.5482559204102,99.5482559204102,57.2972786022176,20.6498158396778,25.566563,0,0,0,40,4374,323.5257,99.5482559204102,,,,,,,,,,,,,0,,,,-0.00245,,,,,,326.4633789,,,,
,29331498.13,323.4950562,99.5482559204102,4.22246182965064E-6,3.73809060653024E-7,1,0.999253354069792,40.0298881530762,2.00822530163022,15.4900001361966,4.91884536973505E-5,1.23535739841283E-6,0.25,-6.22616659986761E-7,4.2192037943671E-6,-6.19487084480499E-7,323.4950562,323.4950562,99.5482559204102,99.5482559204102,57.1401712698522,20.6572663763791,25.186911,0,0,0,40,4374,320.52715,99.5482559204102,,,,,,,,,,,,,0,,,,0.0049,,,,,,323.4950562,,,,
,29331621.715,320.4425354,99.5482559204102,3.68824844738925E-6,3.35807179253761E-7,1,0.999253354069792,40.0298881530762,2.00809144405611,15.4999997466803,4.28553645064953E-5,1.72470686349522E-6,0.25,-4.87038742443942E-7,3.68576599454862E-6,-4.84380310433794E-7,320.4425354,320.4425354,99.5482559204102,99.5482559204102,57.3535558556022,20.6557074097147,25.566563,0,0,0,40,4374,317.4046,99.5482559204102,,,,,,,,,,,,,0,,,,-0.0049,,,,,,320.4425354,,,,
,29331740.47,317.4910278,99.5482559204102,3.84638287469117E-6,3.94582236085165E-7,1,0.999253354069792,40.0298881530762,2.00785024436929,15.4999997466803,4.54724918562336E-5,-2.70495526082424E-6,0.25,-9.04408862917214E-7,3.84444588282168E-6,-9.01404528608274E-7,317.4910278,317.4910278,99.5482559204102,99.5482559204102,57.5192611016792,20.656775261017,25.946213,0,0,0,40,4374,314.4314,99.5482559204102,,,,,,,,,,,,,0,,,,0.0049,,,,,,317.4910278,,,,
,29331862.85,314.4850464,99.5482559204102,3.70615943659061E-6,3.91210755615663E-7,1,0.999253354069792,40.0298881530762,2.00776916458476,15.4999997466803,4.26875175318098E-5,3.91810069848695E-6,0.25,-2.97126588587027E-7,3.70432763909152E-6,-2.94610131487392E-7,314.4850464,314.4850464,99.5482559204102,99.5482559204102,57.342613056333,20.6569640752857,25.946213,0,0,0,40,4374,311.3453,99.5482559204102,,,,,,,,,,,,,0,,,,-0.0049,,,,,,314.4850464,,,,
,29331990.72,311.3514709,99.5482559204102,,,2,,,,15.5200000312924,,,,,,,311.3514709,311.3514709,99.5482559204102,99.5482559204102,,,25.946213,,,,-99999999,4374,308.1163,99.5482559204102,,,,,,,,,,,,,,,,,,,,,,,311.3514709,,,,
,29332105.735,308.4692078,99.5482559204102,3.9417594555414E-6,3.92483478385559E-7,1,0.999253354069792,40.0298881530762,2.00770322114123,15.5100002884865,4.61093561064398E-5,1.28102476796973E-7,0.25,-6.71622878659652E-7,3.94088709325911E-6,-6.68836107188194E-7,308.4692078,308.4692078,99.5482559204102,99.5482559204102,57.2027015513907,20.6526181400614,25.946213,0,0,0,40,4374,305.23225,99.5482559204102,,,,,,,,,,,,,0,,,,0.0049,,,,,,308.4692078,,,,
,29332226.465,305.493927,99.5482559204102,4.16573965460475E-6,4.75015061814457E-7,1,0.999253354069792,40.0298881530762,2.00752813853428,15.5100002884865,4.78677442999152E-5,5.11544982042529E-6,0.25,-2.71529598304535E-7,4.1649751809183E-6,-2.68726272190523E-7,305.493927,305.493927,99.5482559204102,99.5482559204102,57.1151591572368,20.6580067548879,25.946213,0,0,0,40,4374,302.1975,99.5482559204102,,,,,,,,,,,,,0,,,,-0.00245,,,,,,305.493927,,,,
,29332348.015,302.4714966,99.5482559204102,4.32853528194644E-6,4.38101857748198E-7,1,0.999253354069792,40.0298881530762,2.00763182578663,15.5100002884865,4.97993441264836E-5,5.00963298313495E-6,0.25,-3.09151652863741E-7,4.3282269279044E-6,-3.06231085359738E-7,302.4714966,302.4714966,99.5482559204102,99.5482559204102,57.6107116384292,20.6545914090287,25.946213,0,0,0,40,4374,299.14145,99.5482559204102,,,,,,,,,,,,,0,,,,-0.00735,,,,,,302.4714966,,,,
,29332446.55,299.9986267,99.5482559204102,4.17110955836605E-6,5.24048820324714E-7,1,0.999253354069792,40.0298881530762,1.99455467982203,15.5199998989701,4.68804611384529E-5,9.49372712609423E-6,0.25,1.17826848414038E-7,4.17090244239604E-6,1.20629734622493E-7,299.9986267,299.9986267,99.5482559204102,99.5482559204102,56.8666012881214,20.6572996282242,25.946213,0,0,0,40,4374,296.6895,99.5482559204102,,,,,,,,,,,,,0,,,,-0.0049,,,,,,299.9986267,,,,
,29332570.165,296.9359741,99.5482559204102,4.88756528850219E-6,4.92412804027857E-7,1,0.999253354069792,40.0298881530762,1.99455120527338,15.5199998989701,5.51215359010217E-5,1.0071287621122E-5,0.25,4.46851797101185E-8,4.88791935829879E-6,4.80192096335975E-8,296.9359741,296.9359741,99.5482559204102,99.5482559204102,57.4004535667561,20.6696893103481,25.946213,0,0,0,40,4374,293.5723,99.5482559204102,,,,,,,,,,,,,0,,,,0.00245,,,,,,296.9359741,,,,
,29332689.955,293.9514771,99.5482559204102,4.05661578809884E-6,3.36858591761781E-7,1,0.999253354069792,40.0298881530762,1.99417591093356,15.5199998989701,4.58425370172804E-5,7.80605357940621E-6,0.25,-1.18503327931957E-8,4.0573758019315E-6,-9.05391933927045E-9,293.9514771,293.9514771,99.5482559204102,99.5482559204102,57.7646924567176,20.6797245504324,25.946213,0,0,0,40,4374,290.57395,99.5482559204102,,,,,,,,,,,,,0,,,,0,,,,,,293.9514771,,,,
,29332809.305,290.9997253,99.5482559204102,4.61058294900419E-6,3.45714330991652E-7,1,0.999253354069792,40.0298881530762,1.99400565749848,15.5199998989701,5.35036550788214E-5,7.95580217598388E-7,0.25,-7.28560381465204E-7,4.61243316403294E-6,-7.25551612372275E-7,290.9997253,290.9997253,99.5482559204102,99.5482559204102,57.7646924567176,20.6796453068735,25.946213,0,0,0,40,4374,287.57685,99.5482559204102,,,,,,,,,,,,,0,,,,0.0049,,,,,,290.9997253,,,,
,29332910.585,288.4732361,99.5482559204102,4.95888891006485E-6,4.51195112026443E-7,1,0.999253354069792,40.0298881530762,1.99335819513024,15.54000005126,5.54411931286233E-5,1.29257554889462E-5,0.25,2.85215192363636E-7,4.96057853301831E-6,2.88825342027744E-7,288.4732361,288.4732361,99.5482559204102,99.5482559204102,57.3574639981984,20.674518062175,25.946213,0,0,0,40,4374,285.02635,99.5482559204102,,,,,,,,,,,,,0,,,,0,,,,,,288.4732361,,,,
,29333031.695,285.4701538,99.5482559204102,4.87553497325435E-6,4.38968279856757E-7,1,0.999253354069792,40.0298881530762,1.9928961371543,15.54000005126,5.47637384017534E-5,1.12028814570885E-5,0.25,1.47164702600446E-7,4.87781316082581E-6,1.50723847025744E-7,285.4701538,285.4701538,99.5482559204102,99.5482559204102,57.5403650716984,20.6822785588098,25.566563,0,0,0,40,4374,281.99235,99.5482559204102,,,,,,,,,,,,,0,,,,-0.0049,,,,,,285.4701538,,,,
,29333152.075,282.4705505,99.5482559204102,4.79383597425137E-6,4.27759510700413E-7,1,0.999253354069792,40.0298881530762,1.99264671173922,15.54000005126,5.42036379997214E-5,8.94812314399068E-6,0.25,-3.83982598189605E-8,4.79672225593797E-6,-3.49476686352792E-8,282.4705505,282.4705505,99.5482559204102,99.5482559204102,57.5638139272753,20.6857188544243,25.946213,0,0,0,40,4374,278.9762,99.5482559204102,,,,,,,,,,,,,0,,,,0,,,,,,282.4705505,,,,
,29333273.585,279.4789429,99.5482559204102,5.35488435724196E-6,3.37649906531273E-7,1,0.999253354069792,40.0298881530762,1.99190069648226,15.5600002035499,6.16721140115475E-5,3.41654163135649E-6,0.25,-6.25515887299651E-7,5.35911020021057E-6,-6.22024377702738E-7,279.4789429,279.4789429,99.5482559204102,99.5482559204102,57.2972786022176,20.6957092403166,25.946213,0,0,0,40,4374,275.9409,99.5482559204102,,,,,,,,,,,,,0,,,,0,,,,,,279.4789429,,,,
,29333393.69,276.4584045,99.5482559204102,4.8052855861724E-6,4.68245954801076E-7,1,0.999253354069792,40.0298881530762,1.99185470362955,15.5600002035499,5.46586117137967E-5,7.03866875869009E-6,0.25,-2.09482244403914E-7,4.80934105297849E-6,-2.06077243726202E-7,276.4584045,276.4584045,99.5482559204102,99.5482559204102,57.4020168237945,20.6967093995285,25.566563,0,0,0,40,4374,272.9259,99.5482559204102,,,,,,,,,,,,,0,,,,-0.00245,,,,,,276.4584045,,,,
,29333515.645,273.4378357,99.5482559204102,4.91533564227042E-6,4.02845801534829E-7,1,0.999253354069792,40.0298881530762,1.99180946223416,15.5600002035499,5.53122263916255E-5,1.06790587190023E-5,0.25,9.3772080168182E-8,4.91978498395274E-6,9.75651208635961E-8,273.4378357,273.4378357,99.5482559204102,99.5482559204102,57.3910740245253,20.7004929240135,26.325863,0,0,0,40,4374,269.87025,99.5482559204102,,,,,,,,,,,,,0,,,,0,,,,,,273.4378357,,,,
,29333633.135,270.4966125,99.5482559204102,4.84324432151363E-6,3.9524449424798E-7,1,0.999253354069792,40.0298881530762,1.99155202413482,15.5600002035499,5.57295790383184E-5,3.42956545703059E-6,0.25,-5.35871776329854E-7,4.84861679698462E-6,-5.32719874775026E-7,270.4966125,270.4966125,99.5482559204102,99.5482559204102,57.4176493941791,20.7025290495808,25.566563,0,0,0,40,4374,266.9257,99.5482559204102,,,,,,,,,,,,,0,,,,0,,,,,,270.4966125,,,,
,29333755.625,267.4837341,99.5482559204102,4.76932855949933E-6,4.85467587749362E-7,1,0.999253354069792,40.0298881530762,1.99115023430529,15.5800003558397,5.43519577822968E-5,6.39058581433302E-6,0.25,-2.6079332006094E-7,4.77493090179049E-6,-2.57393173043959E-7,267.4837341,267.4837341,99.5482559204102,99.5482559204102,57.2277136640061,20.7003765405981,25.946213,0,0,0,40,4374,263.8678,99.5482559204102,,,,,,,,,,,,,0,,,,0,,,,,,267.4837341,,,,
,29333876.87,264.4391785,99.5482559204102,5.0841301409868E-6,4.21945879041838E-7,1,0.999253354069792,40.0298881530762,1.99132435793783,15.5800003558397,5.78374659022375E-5,7.46643415586242E-6,0.25,-2.20254190522259E-7,5.09061189992225E-6,-2.1653290817029E-7,264.4391785,264.4391785,99.5482559204102,99.5482559204102,57.464547105333,20.7020877433147,26.325863,0,0,0,40,4374,260.8332,99.5482559204102,,,,,,,,,,,,,0,,,,0.0049,,,,,,264.4391785,,,,
,29333996.18,261.4939575,99.5482559204102,4.80622449574733E-6,4.08980749326044E-7,1,0.999253354069792,40.0298881530762,1.99109112518181,15.5899999663234,5.5174436239403E-5,4.18155017311085E-6,0.25,-4.63042539963181E-7,4.81306112321061E-6,-4.59836734925882E-7,261.4939575,261.4939575,99.5482559204102,99.5482559204102,57.4285921934484,20.7085187552574,26.325863,0,0,0,40,4374,257.84665,99.5482559204102,,,,,,,,,,,,,0,,,,0,,,,,,261.4939575,,,,
,29334115.68,258.4884033,99.5482559204102,5.62371513812173E-6,4.23266615157301E-7,1,0.999253354069792,40.0298881530762,1.99063652041448,15.6100001186132,6.28301575922069E-5,1.48213333449591E-5,0.25,3.37602664423791E-7,5.63161093574032E-6,3.42636216888711E-7,258.4884033,258.4884033,99.5482559204102,99.5482559204102,57.1456426694868,20.7101767952625,25.946213,0,0,0,40,4374,254.8714,99.5482559204102,,,,,,,,,,,,,0,,,,0.00245,,,,,,258.4884033,,,,
,29334237.54,255.47084045,99.5482559204102,5.29661034705661E-6,4.44815303452103E-7,1,0.999253354069792,40.0298881530762,1.99014875573914,15.6100001186132,6.06382668544578E-5,5.47971838688792E-6,0.25,-4.33108651255313E-7,5.30522538366436E-6,-4.2944220752763E-7,255.4416351,255.5000458,99.5482559204102,99.5482559204102,57.2988418592561,20.7160253704266,25.946213,0,0,0,40,4374,251.7955,99.5482559204102,,,,,,,,,,,,,0,,,,0.00245,,,,,,255.47084045,,,,
,29334355.63,252.4922638,99.5482559204102,5.37040701917007E-6,3.47840665146606E-7,1,0.999253354069792,40.0298881530762,1.9899846900328,15.6199997290969,6.05372750750074E-5,1.10196974260951E-5,0.25,4.47716723616599E-8,5.37931074850776E-6,4.93115213826339E-8,252.4922638,252.4922638,99.5482559204102,99.5482559204102,57.0659165605253,20.7272264602647,26.325863,0,0,0,40,4374,248.8418,99.5482559204102,,,,,,,,,,,,,0,,,,-0.0049,,,,,,252.4922638,,,,
,29334476.82,249.4962006,99.5482559204102,5.71262311606867E-6,3.88752775910724E-7,1,0.999253354069792,40.0298881530762,1.98954826535638,15.6100001186132,6.45112656700989E-5,1.10109451332459E-5,0.25,-1.53235748613451E-8,5.72275039308837E-6,-1.05300528109512E-8,249.4962006,249.4962006,99.5482559204102,99.5482559204102,57.0971817012945,20.7256157934288,26.325863,0,0,0,40,4374,245.8006,99.5482559204102,,,,,,,,,,,,,0,,,,0,,,,,,249.4962006,,,,
,29334577.795,246.9590759,99.5482559204102,5.48475240322439E-6,3.92270294120971E-7,1,0.999253354069792,40.0298881530762,2.00183651577624,15.6399998813868,6.35629004733871E-5,3.40386970019674E-6,0.25,-6.51590548128272E-7,5.49550959909123E-6,-6.4811634762776E-7,246.9590759,246.9590759,99.5482559204102,99.5482559204102,57.1792526958137,20.7269317977768,26.325863,0,0,0,40,4374,243.28585,99.5482559204102,,,,,,,,,,,,,0,,,,0.0049,,,,,,246.9590759,,,,
,29334698.26,243.9552917,99.5482559204102,5.83604112183417E-6,4.58255132534509E-7,1,0.999253354069792,40.0298881530762,2.00195627621122,15.6399998813868,6.70366366152455E-5,7.12993047724041E-6,0.25,-3.8455877454618E-7,5.84784330617985E-6,-3.80253130996168E-7,243.9552917,243.9552917,99.5482559204102,99.5482559204102,57.0706063316407,20.7268604794004,25.566563,0,0,0,40,4374,240.2814,99.5482559204102,,,,,,,,,,,,,0,,,,-0.0049,,,,,,243.9552917,,,,
,29334816.51,240.9737701,99.5482559204102,5.83139440019474E-6,4.16851137640867E-7,1,0.999253354069792,40.0298881530762,2.0013479670281,15.6399998813868,6.64820804524751E-5,9.94043554007634E-6,0.25,-1.36193565293774E-7,5.84358156104816E-6,-1.31341816301547E-7,240.9737701,240.9737701,99.5482559204102,99.5482559204102,57.0596635323714,20.7334687941484,25.946213,0,0,0,40,4374,237.3178,99.5482559204102,,,,,,,,,,,,,0,,,,-0.0049,,,,,,240.9737701,,,,
touchdown = 10.0400000810623 mm,29334930.775,238.112915,99.5482559204102,5.61304036759628E-6,3.63031187929417E-7,1,0.999253354069792,40.0298881530762,2.00081932094725,15.6999994069338,6.43872161496931E-5,7.23656896386818E-6,0.25,-3.36415954837206E-7,5.62551547402914E-6,-3.32131577611173E-7,238.112915,238.112915,99.5482559204102,99.5482559204102,57.1737812961791,20.7419005219178,25.946213,0,0,0,40,4374,234.4641,99.5482559204102,,,,,,,,,,,,,0,,,,-0.0049,,,,,,238.112915,,,,
,29335035.74,235.4902344,99.5482559204102,5.65075323705671E-6,4.39447289411516E-7,1,0.999253354069792,40.0298881530762,2.00072322260225,15.6999994069338,6.45028971298915E-5,9.12916098304052E-6,0.25,-1.76359616866052E-7,5.66368339148595E-6,-1.71640845773435E-7,235.4902344,235.4902344,99.5482559204102,99.5482559204102,57.2761746321984,20.7493805020055,25.946213,0,0,0,40,4374,231.8235,99.5482559204102,,,,,,,,,,,,,0,,,,-0.0049,,,,,,235.4902344,,,,
,29335158.42,232.4728699,99.5482559204102,5.75693048113694E-6,3.62498014206558E-7,1,0.999253354069792,40.0298881530762,2.00012362280567,15.6999994069338,6.63408517135706E-5,5.62293878877873E-6,0.25,-5.03602126723268E-7,5.77100427418164E-6,-4.99494300864091E-7,232.4728699,232.4728699,99.5482559204102,99.5482559204102,57.0588819038522,20.7448924535103,25.566563,0,0,0,40,4374,228.7504,99.5482559204102,,,,,,,,,,,,,0,,,,0,,,,,,232.4728699,,,,
,29335279.295,229.4436493,99.5482559204102,5.77076583845502E-6,3.93731483415329E-7,1,0.999253354069792,40.0298881530762,1.99980233405881,15.6999994069338,6.60396289754568E-5,8.27226473840689E-6,0.25,-2.72659642512466E-7,5.78526496167845E-6,-2.6793554447354E-7,229.4436493,229.4436493,99.5482559204102,99.5482559204102,57.024490249006,20.751463476273,25.946213,0,0,0,40,4374,225.7447,99.5482559204102,,,,,,,,,,,,,0,,,,0.00245,,,,,,229.4436493,,,,
,29335396.075,226.4917755,99.5482559204102,5.85533615609108E-6,3.43928247841277E-7,1,0.999253354069792,40.0298881530762,1.99952074631653,15.7200004905462,6.64106668106519E-5,1.18190572585577E-5,0.25,2.50843047304977E-8,5.87035654831397E-6,3.07126740792533E-8,226.4917755,226.4917755,99.5482559204102,99.5482559204102,57.1542405831984,20.7525828633862,25.566563,0,0,0,40,4374,222.81585,99.5482559204102,,,,,,,,,,,,,0,,,,0,,,,,,226.4917755,,,,
,29335515.695,223.4887238,99.5482559204102,6.11648533582879E-6,3.52467324322552E-7,1,0.999253354069792,40.0298881530762,2.0000374082036,15.7200004905462,6.83638013589273E-5,1.83018363599488E-5,0.25,5.50257892826407E-7,6.132294076326E-6,5.57636378880281E-7,223.4887238,223.4887238,99.5482559204102,99.5482559204102,57.3199458292753,20.7505479744402,25.946213,0,0,0,40,4374,219.8326,99.5482559204102,,,,,,,,,,,,,0,,,,0.00245,,,,,,223.4887238,,,,
,29335635.815,220.4951935,99.5482559204102,5.80757475418405E-6,3.93277888749148E-7,1,0.999253354069792,40.0298881530762,1.99988789450233,15.7200004905462,6.57552277691384E-5,1.25257510046363E-5,0.25,9.50332335208393E-8,5.82358450241518E-6,1.01002291381541E-7,220.4951935,220.4951935,99.5482559204102,99.5482559204102,57.1909771236022,20.7485442725236,26.325863,0,0,0,40,4374,216.82255,99.5482559204102,,,,,,,,,,,,,0,,,,-0.00245,,,,,,220.4951935,,,,
touchdown = 10.0999996066093 mm,29335762.64,217.2761383,99.5482559204102,6.18889650353645E-6,3.57222821790676E-7,1,0.999253354069792,40.0298881530762,1.9989483324826,15.760000795126,7.17261859601867E-5,3.68151850120868E-6,0.25,-7.50073890364977E-7,6.20747726133129E-6,-7.46044193834509E-7,217.2761383,217.2761383,99.5482559204102,99.5482559204102,57.2480360055061,20.7617013159273,25.946213,0,0,0,40,4374,213.668,99.5482559204102,,,,,,,,,,,,,0,,,,0,,,,,,217.2761383,,,,
,29335876.985,214.4587555,99.5482559204102,6.24829096536448E-6,3.83144790645071E-7,1,0.999253354069792,40.0298881530762,2.00016953042825,15.760000795126,7.13364882885685E-5,1.02117092329575E-5,0.25,-1.85784856042015E-7,6.267069215904E-6,-1.79982744749029E-7,214.4587555,214.4587555,99.5482559204102,99.5482559204102,57.2292769210445,20.753231334261,25.946213,0,0,0,40,4374,210.80945,99.5482559204102,,,,,,,,,,,,,0,,,,0,,,,,,214.4587555,,,,
,29335995.465,211.4865112,99.5482559204102,6.7623173492452E-6,3.31688054441116E-7,1,0.999253354069792,40.0298881530762,2.00105462816131,15.760000795126,7.72013333810672E-5,1.13110019514219E-5,0.25,-1.78886557778833E-7,6.78328798716703E-6,-1.7243761332509E-7,211.4865112,211.4865112,99.5482559204102,99.5482559204102,57.4027984523138,20.7463330704137,25.946213,0,0,0,40,4374,207.8601,99.5482559204102,,,,,,,,,,,,,0,,,,0,,,,,,211.4865112,,,,
,29336115.595,208.4868164,99.5482559204102,6.77841440433012E-6,3.82111700336387E-7,1,0.999253354069792,40.0298881530762,2.00059740772302,15.769999474287,7.83192525865572E-5,5.9043124661587E-6,0.25,-6.57514044742024E-7,6.80061194762239E-6,-6.52456082686628E-7,208.4868164,208.4868164,99.5482559204102,99.5482559204102,57.2027015513907,20.7333974996807,25.946213,0,0,0,40,4374,204.8533,99.5482559204102,,,,,,,,,,,,,0,,,,0,,,,,,208.4868164,,,,
,29336236.01,205.4734802,99.5482559204102,6.95859273074627E-6,3.56288366241621E-7,1,0.999253354069792,40.0298881530762,1.99943424421408,15.8099997788668,7.92145900326174E-5,1.26794379524645E-5,0.25,-9.21753819226404E-8,6.98145313980835E-6,-8.50060368997267E-8,205.4734802,205.4734802,99.5482559204102,99.5482559204102,57.1792526958137,20.7448827990971,25.946213,0,0,0,40,4374,201.8472,99.5482559204102,,,,,,,,,,,,,0,,,,-0.00245,,,,,,205.4734802,,,,
,29336357.01,202.4399872,99.5482559204102,6.45111488613115E-6,3.66822298703586E-7,1,0.999253354069792,40.0298881530762,1.99918845751776,15.8099997788668,7.27887889778843E-5,1.54817809130305E-5,0.25,2.42595973406923E-7,6.47258520938115E-6,2.50472211134717E-7,202.4399872,202.4399872,99.5482559204102,99.5482559204102,57.1339182416984,20.7537727576815,25.946213,0,0,0,40,4374,198.8253,99.5482559204102,,,,,,,,,,,,,0,,,,0.0049,,,,,,202.4399872,,,,
,29336475.06,199.4802856,99.5482559204102,6.67359277469492E-6,3.0925305478136E-7,1,0.999253354069792,40.0298881530762,1.99995951359834,15.7999992370605,7.67047468866529E-5,8.13163535516852E-6,0.25,-4.43692233315675E-7,6.69720755718808E-6,-4.37787493711043E-7,199.4802856,199.4802856,99.5482559204102,99.5482559204102,57.3066581444484,20.7450718335747,25.186911,0,0,0,40,4374,195.87695,99.5482559204102,,,,,,,,,,,,,0,,,,0.00245,,,,,,199.4802856,,,,
touchdown = 10.1800002157688 mm,29336594.6,196.4596863,99.5482559204102,6.94746536653802E-6,3.98476686128836E-7,1,0.999253354069792,40.0298881530762,1.99831346044491,15.8399995416403,7.9281670566277E-5,1.14291430621644E-5,0.25,-2.00519514401485E-7,6.97243051635257E-6,-1.93333006193906E-7,196.4596863,196.4596863,99.5482559204102,99.5482559204102,57.3418314278138,20.7788782528753,25.566563,0,0,0,40,4374,192.893,99.5482559204102,,,,,,,,,,,,,0,,,,-0.0049,,,,,,196.4596863,,,,
,29336716.255,193.4428406,99.5482559204102,6.85509473582395E-6,3.68250085237386E-7,1,0.999253354069792,40.0298881530762,1.99841324051611,15.8399995416403,7.81041935829848E-5,1.20532328524871E-5,0.25,-1.29819528467101E-7,6.88030514749214E-6,-1.22336811051778E-7,193.4428406,193.4428406,99.5482559204102,99.5482559204102,57.0182372208522,20.7651798097893,25.186911,0,0,0,40,4374,189.8317,99.5482559204102,,,,,,,,,,,,,0,,,,0,,,,,,193.4428406,,,,
,29336837.275,190.4438019,99.5482559204102,7.02577095806404E-6,3.37325661317733E-7,1,0.999253354069792,40.0298881530762,1.99811156481534,15.8399995416403,7.99250008983025E-5,1.30418756480637E-5,0.25,-7.25324222452446E-8,7.05219751886066E-6,-6.44772579561947E-8,190.4438019,190.4438019,99.5482559204102,99.5482559204102,57.1784710672945,20.7743349722661,25.186911,0,0,0,40,4374,186.8006,99.5482559204102,,,,,,,,,,,,,0,,,,0.00245,,,,,,190.4438019,,,,
,29336955.965,187.4781342,99.5482559204102,7.27190376194043E-6,3.14342324469275E-7,1,0.999253354069792,40.0298881530762,1.99731636348068,15.8399995416403,8.38112904805345E-5,7.10805162511544E-6,0.25,-6.37857670306157E-7,7.30060437805749E-6,-6.31506022378948E-7,187.4781342,187.4781342,99.5482559204102,99.5482559204102,57.3504293415253,20.7854010486262,25.186911,0,0,0,40,4374,183.82275,99.5482559204102,,,,,,,,,,,,,0,,,,0,,,,,,187.4781342,,,,
,29337056.365,184.9787292,99.5482559204102,7.17680302062499E-6,3.4517120109323E-7,1,0.999253354069792,40.0298881530762,2.00788913642873,15.8900003880262,8.32274742352172E-5,6.54430900036001E-6,0.25,-6.74085836698192E-7,7.20574455967977E-6,-6.67881644400026E-7,184.9787292,184.9787292,99.5482559204102,99.5482559204102,57.6122748954676,20.8004119531616,25.186911,0,0,0,40,4374,181.31575,99.5482559204102,,,,,,,,,,,,,0,,,,-0.00245,,,,,,184.9787292,,,,
,29337177.015,181.9930573,99.5482559204102,7.21825042499352E-6,3.77297509508325E-7,1,0.999253354069792,40.0298881530762,1.99560913606666,15.8900003880262,8.21754094909759E-5,1.25941178564533E-5,0.25,-1.449127710817E-7,7.24735588537531E-6,-1.36395376188073E-7,181.9930573,181.9930573,99.5482559204102,99.5482559204102,57.4215575367753,20.8053547387788,25.566563,0,0,0,40,4374,178.2619,99.5482559204102,,,,,,,,,,,,,0,,,,0,,,,,,181.9930573,,,,
,29337297.02,178.9670258,99.5482559204102,7.60738800643551E-6,3.50902569314566E-7,1,0.999253354069792,40.0298881530762,1.99327675361576,15.8900003880262,8.68131731266155E-5,1.15546288660151E-5,0.25,-3.03371759993205E-7,7.63894733656756E-6,-2.9480720963279E-7,178.9670258,178.9670258,99.5482559204102,99.5482559204102,57.1753445532176,20.829896494506,24.807261,0,0,0,40,4374,175.2765,99.5482559204102,,,,,,,,,,,,,0,,,,0,,,,,,178.9670258,,,,
touchdown = 10.2800000458956 mm,29337427.815,175.591156,99.5482559204102,7.96593367595852E-6,3.25400998330771E-7,1,0.999253354069792,40.0298881530762,1.99339531716115,15.939999371767,9.11665796592319E-5,1.0678069176485E-5,0.25,-4.43474348191351E-7,7.99994865192902E-6,-4.34806131591419E-7,175.591156,175.591156,99.5482559204102,99.5482559204102,56.7571732954291,20.8156943853829,25.186911,0,0,0,40,4374,172.0663,99.5482559204102,,,,,,,,,,,,,0,,,,0,,,,,,175.591156,,,,
,29337535.08,172.9397125,99.5482559204102,7.89776062251097E-6,3.91037291490544E-7,1,0.999253354069792,40.0298881530762,1.99211963603903,15.939999371767,8.95874041659657E-5,1.48968091079462E-5,0.25,-5.89446946134829E-8,7.93158786201561E-6,-4.85314551890037E-8,172.9397125,172.9397125,99.5482559204102,99.5482559204102,56.9955699937945,20.8475996737489,25.566563,0,0,0,40,4374,169.38285,99.5482559204102,,,,,,,,,,,,,0,,,,0,,,,,,172.9397125,,,,
,29337652.79,169.968338,99.5482559204102,7.49654384591094E-6,3.76256867416907E-7,1,0.999253354069792,40.0298881530762,1.99583668219671,15.939999371767,8.48223210950183E-5,1.6307818478161E-5,0.25,1.32480665312317E-7,7.52902906781049E-6,1.43426238132344E-7,169.968338,169.968338,99.5482559204102,99.5482559204102,57.2300585495638,20.8106467439811,25.186911,0,0,0,40,4374,166.46405,99.5482559204102,,,,,,,,,,,,,0,,,,0.0049,,,,,,169.968338,,,,
,29337770.705,166.9985046,99.5482559204102,8.30766856238711E-6,4.11051101904233E-7,1,0.999253354069792,40.0298881530762,1.9944896315035,15.939999371767,9.49531654336767E-5,1.22820967479925E-5,0.25,-3.63026486789957E-7,8.34507811118465E-6,-3.52862154792489E-7,166.9985046,166.9985046,99.5482559204102,99.5482559204102,57.2824276603522,20.8125101382738,24.427608,0,0,0,40,4374,163.5391,99.5482559204102,,,,,,,,,,,,,0,,,,0.00245,,,,,,166.9985046,,,,
,29337891.99,163.9719391,99.5482559204102,8.14862678936409E-6,3.89652976361398E-7,1,0.999253354069792,40.0298881530762,1.98148025446074,16.0099994391203,9.28100625983167E-5,1.05534165163312E-5,0.25,-4.82299590161123E-7,8.18619502116791E-6,-4.72621504830634E-7,163.9719391,163.9719391,99.5482559204102,99.5482559204102,57.3363600281791,20.8284961528821,24.807261,0,0,0,40,4374,160.49205,99.5482559204102,,,,,,,,,,,,,0,,,,-0.00245,,,,,,163.9719391,,,,
,29338011.04,160.9644318,99.5482559204102,8.29435130338921E-6,3.73791729367552E-7,1,0.999253354069792,40.0298881530762,1.98254902850452,16.0000007599592,9.43564221641489E-5,1.17245850440325E-5,0.25,-4.04722758054235E-7,8.33315485695374E-6,-3.94190597102384E-7,160.9644318,160.9644318,99.5482559204102,99.5482559204102,57.6411951506792,20.8132850352437,24.427608,0,0,0,40,4374,157.52585,99.5482559204102,,,,,,,,,,,,,0,,,,0.00245,,,,,,160.9644318,,,,
,29338130.9,157.9484711,99.5482559204102,8.50114514940938E-6,4.09592373367145E-7,1,0.999253354069792,40.0298881530762,1.98442984624655,16.0000007599592,9.68135933912492E-5,1.19761200035117E-5,0.25,-4.19826387359782E-7,8.54161827748768E-6,-4.08736165512478E-7,157.9484711,157.9484711,99.5482559204102,99.5482559204102,57.586481154333,20.7831858791126,24.807261,0,0,0,40,4374,154.55355,99.5482559204102,,,,,,,,,,,,,0,,,,0,,,,,,157.9484711,,,,
touchdown = 10.3900004178286 mm,29338259.605,154.7137299,99.5482559204102,8.71197333615788E-6,3.81388713763998E-7,1,0.999253354069792,40.0298881530762,2.00942811056244,16.0499997437,0.000100155946857842,1.39125699324645E-5,0.25,-3.00186452281836E-7,8.75399131002658E-6,-2.87826611331172E-7,154.7137299,154.7137299,99.5482559204102,99.5482559204102,57.73186405891,20.7806604890124,24.427608,0,0,0,40,4374,151.3705,99.5482559204102,,,,,,,,,,,,,0,,,,0,,,,,,154.7137299,,,,
,29338368.615,151.9818726,99.5482559204102,8.85230014167122E-6,3.55814876858143E-7,1,0.999253354069792,40.0298881530762,1.99908605318619,16.0499997437,0.000100668456178476,1.75581012411912E-5,0.25,1.47460988627084E-9,8.89511638598537E-6,1.58747257796601E-8,151.9818726,151.9818726,99.5482559204102,99.5482559204102,57.7803250271023,20.7804232944764,24.427608,0,0,0,40,4374,148.6394,99.5482559204102,,,,,,,,,,,,,0,,,,0.00245,,,,,,151.9818726,,,,
,29338489.515,148.9837189,99.5482559204102,9.21198211774635E-6,3.77736393635571E-7,1,0.999253354069792,40.0298881530762,1.99876241048295,16.0499997437,0.000105381077627152,1.46504911371968E-5,0.25,-3.1722772217073E-7,9.25774614387713E-6,-3.03345563316522E-7,148.9837189,148.9837189,99.5482559204102,99.5482559204102,57.7357722015061,20.7811331541557,24.047956,0,0,0,40,4374,145.6282,99.5482559204102,,,,,,,,,,,,,0,,,,-0.0049,,,,,,148.9837189,,,,
,29338606.735,145.9892273,99.5482559204102,9.09368114761584E-6,3.75449520914503E-7,1,0.999253354069792,40.0298881530762,1.99855891610763,16.0499997437,0.000104239143533998,1.32349913994926E-5,0.25,-4.2152995325838E-7,9.13970809034641E-6,-4.07916405897352E-7,145.9892273,145.9892273,99.5482559204102,99.5482559204102,57.7834515411792,20.7708917305971,24.427608,0,0,0,40,4374,142.7022,99.5482559204102,,,,,,,,,,,,,0,,,,0,,,,,,145.9892273,,,,
,29338727.535,142.9528809,99.5482559204102,9.0739786689449E-6,3.5661460404601E-7,1,0.999253354069792,40.0298881530762,1.99739437443839,16.1099992692471,0.000103104257827594,1.81233499212983E-5,0.25,1.20699833947935E-8,9.11978866633331E-6,2.83257121476581E-8,142.9528809,142.9528809,99.5482559204102,99.5482559204102,57.6865296047946,20.7811300291791,24.427608,0,0,0,40,4374,139.69705,99.5482559204102,,,,,,,,,,,,,0,,,,0,,,,,,142.9528809,,,,
,29338846.7,139.9739075,99.5482559204102,9.69375821546612E-6,3.86294648354522E-7,1,0.999253354069792,40.0298881530762,1.9987838081611,16.1099992692471,0.000110505043188244,1.7781102555993E-5,0.25,-1.27853211046531E-7,9.74359181208332E-6,-1.10627315109464E-7,139.9739075,139.9739075,99.5482559204102,99.5482559204102,57.860832764583,20.7612818959761,24.427608,0,0,0,40,4374,136.7385,99.5482559204102,,,,,,,,,,,,,0,,,,-0.0049,,,,,,139.9739075,,,,
,29338965.405,136.9831238,99.5482559204102,9.70663539936009E-6,3.61966609557244E-7,1,0.999253354069792,40.0298881530762,1.99844513017169,16.1099992692471,0.000110873241721094,1.64722799733164E-5,0.25,-2.45654155287657E-7,9.75737987925462E-6,-2.28400760039521E-7,136.9831238,136.9831238,99.5482559204102,99.5482559204102,58.03669918141,20.777381894975,24.427608,0,0,0,40,4374,133.7717,99.5482559204102,,,,,,,,,,,,,0,,,,-0.00245,,,,,,136.9831238,,,,
touchdown = 10.5100004002452 mm,29339087.75,133.8808136,99.5482559204102,1.00902692371133E-5,3.68645352282004E-7,1,0.999253354069792,40.0298881530762,2.00752470200759,16.1700006574392,0.00011583342541484,1.67906422567675E-5,0.25,-2.91785818220708E-7,1.01437393264372E-5,-2.73349051425227E-7,133.8808136,133.8808136,99.5482559204102,99.5482559204102,57.86395927866,20.8075787362962,24.047956,0,0,0,40,4374,130.74045,99.5482559204102,,,,,,,,,,,,,0,,,,0.00245,,,,,,133.8808136,,,,
,29339205.42,130.9675751,99.5482559204102,1.00598339010259E-5,3.38306876154469E-7,1,0.999253354069792,40.0298881530762,2.00729287243088,16.1700006574392,0.000114779930641638,2.0734536073952E-5,0.25,5.81850587824891E-8,1.01129971247479E-5,7.9137245810139E-8,130.9675751,130.9675751,99.5482559204102,99.5482559204102,58.2579000523523,20.8105011332784,23.668306,0,0,0,40,4374,127.7907,99.5482559204102,,,,,,,,,,,,,0,,,,0,,,,,,130.9675751,,,,
,29339324.5,127.9488678,99.5482559204102,1.01964163046104E-5,3.37062841081881E-7,1,0.999253354069792,40.0298881530762,2.0086387874093,16.1700006574392,0.000116593823606584,2.00294455141999E-5,0.25,-2.94231524138214E-8,1.02510312816444E-5,-7.85048916139079E-9,127.9488678,127.9488678,99.5482559204102,99.5482559204102,57.6771500625638,20.7989819095316,24.047956,0,0,0,40,4374,124.8343,99.5482559204102,,,,,,,,,,,,,0,,,,-0.00245,,,,,,127.9488678,,,,
,29339445.34,124.9368973,99.5482559204102,1.09659569561681E-5,3.47290931110981E-7,1,0.999253354069792,40.0298881530762,1.9987307464022,16.1700006574392,0.000125180338609423,1.93189898280649E-5,0.25,-2.19104857308138E-7,1.10256479796356E-5,-1.95970903215748E-7,124.9368973,124.9368973,99.5482559204102,99.5482559204102,57.6404135221599,20.749554034815,24.047956,0,0,0,40,4374,121.83625,99.5482559204102,,,,,,,,,,,,,0,,,,-0.00245,,,,,,124.9368973,,,,
,29339563.43,121.9547653,99.5482559204102,1.06541975632593E-5,3.52089490372291E-7,1,0.999253354069792,40.0298881530762,1.99851215687673,16.2400007247925,0.000121364595972162,2.01965376148781E-5,0.25,-8.83061844226171E-8,1.07123943826177E-5,-6.41945309639952E-8,121.9547653,121.9547653,99.5482559204102,99.5482559204102,57.8162799389869,20.767578699914,23.288654,0,0,0,40,4374,118.9159,99.5482559204102,,,,,,,,,,,,,0,,,,0,,,,,,121.9547653,,,,
,29339681.41,118.9488373,99.5482559204102,1.11979736999753E-5,3.49697584084562E-7,1,0.999253354069792,40.0298881530762,1.99942444244488,16.2400007247925,0.000127295333411251,2.30900702714866E-5,0.25,6.88933546096818E-8,1.12592052386432E-5,9.62156220575868E-8,118.9488373,118.9488373,99.5482559204102,99.5482559204102,58.0781254929292,20.7627762500952,23.288654,0,0,0,40,4374,115.99575,99.5482559204102,,,,,,,,,,,,,0,,,,-0.00245,,,,,,118.9488373,,,,
,29339798.595,115.9963608,99.5482559204102,1.11658718319143E-5,3.06980004225987E-7,1,0.999253354069792,40.0298881530762,1.99813776279622,16.2400007247925,0.000128508244880477,1.35802617218356E-5,0.25,-7.61643712853266E-7,1.12293717974318E-5,-7.37795881307376E-7,115.9963608,115.9963608,99.5482559204102,99.5482559204102,57.9241446746407,20.7846106207668,24.047956,0,0,0,40,4374,113.07975,99.5482559204102,,,,,,,,,,,,,0,,,,-0.00245,,,,,,115.9963608,,,,
touchdown = 10.6499996036291 mm,29339913.795,113.0878372,99.5482559204102,1.1383302435418E-5,3.11419280894973E-7,1,0.999253354069792,40.0298881530762,1.99752451202853,16.3100007921457,0.000129190820685581,2.40309187048937E-5,0.25,1.18461837143419E-7,1.14460764996817E-5,1.48987234864279E-7,113.0878372,113.0878372,99.5482559204102,99.5482559204102,57.8209697101023,20.7867830696063,23.288654,0,0,0,40,4374,110.23065,99.5482559204102,,,,,,,,,,,,,0,,,,0.0049,,,,,,113.0878372,,,,
,29340018.94,110.4479141,99.5482559204102,1.15491494304102E-5,2.90987450989484E-7,1,0.999253354069792,40.0298881530762,1.99865231598014,16.3100007921457,0.000132220998445116,1.82637062842662E-5,0.25,-4.20021247317389E-7,1.16144987229488E-5,-3.90764914358077E-7,110.4479141,110.4479141,99.5482559204102,99.5482559204102,57.8069003967561,20.782689072844,23.288654,0,0,0,40,4374,107.60325,99.5482559204102,,,,,,,,,,,,,0,,,,-0.00245,,,,,,110.4479141,,,,
,29340138.5,107.4401855,99.5482559204102,1.2338905941102E-5,3.18231354642437E-7,1,0.999253354069792,40.0298881530762,1.99787824494966,16.3100007921457,0.000140777181089132,2.19871847302266E-5,0.25,-2.32205086529697E-7,1.24083056516601E-5,-1.98064013870111E-7,107.4401855,107.4401855,99.5482559204102,99.5482559204102,57.6451032932753,20.7803488714913,23.288654,0,0,0,40,4374,104.6354,99.5482559204102,,,,,,,,,,,,,0,,,,0,,,,,,107.4401855,,,,
,29340254.665,104.4827499,99.5482559204102,1.24829802513226E-5,2.71297009513903E-7,1,0.999253354069792,40.0298881530762,1.99786670415452,16.3100007921457,0.00014269172829734,2.07023417734651E-5,0.25,-3.7227784148469E-7,1.25536657383035E-5,-3.36699591068607E-7,104.4827499,104.4827499,99.5482559204102,99.5482559204102,57.3418314278138,20.7687390120553,22.529354,0,0,0,40,4374,101.7479,99.5482559204102,,,,,,,,,,,,,0,,,,-0.0049,,,,,,104.4827499,,,,
,29340375.685,101.4611206,99.5482559204102,1.31232998027208E-5,3.58018312910559E-7,1,0.999253354069792,40.0298881530762,1.9969981379149,16.3700003176928,0.000150135149197062,2.06912224646415E-5,0.25,-4.87127261468767E-7,1.31978349994049E-5,-4.48091892282506E-7,101.4611206,101.4611206,99.5482559204102,99.5482559204102,57.83347576641,20.7802659850183,23.288654,0,0,0,40,4374,98.7344,99.5482559204102,,,,,,,,,,,,,0,,,,0,,,,,,101.4611206,,,,
,29340495.39,98.3804092,99.5482559204102,1.33428226302026E-5,3.46164722298039E-7,1,0.999253354069792,40.0298881530762,1.9985532133583,16.3700003176928,0.000152717293077279,2.12825930805157E-5,0.25,-4.7739491963315E-7,1.3418339777096E-5,-4.3525350564912E-7,98.3804092,98.3804092,99.5482559204102,99.5482559204102,57.484869446833,20.7471552353173,22.909004,0,0,0,40,4374,95.7932,99.5482559204102,,,,,,,,,,,,,0,,,,0,,,,,,98.3804092,,,,
,29340612.11,95.45401,99.5482559204102,1.40758713213303E-5,3.32464159879777E-7,1,0.999253354069792,40.0298881530762,1.99838656317257,16.3700003176928,0.000160837636927835,2.38790480671289E-5,0.25,-3.80549890640643E-7,1.41546410236182E-5,-3.32742288047037E-7,95.45401,95.45401,99.5482559204102,99.5482559204102,57.291807202583,20.7546669648592,22.909004,0,0,0,40,4374,92.90285,99.5482559204102,,,,,,,,,,,,,0,,,,0.00245,,,,,,95.45401,,,,
touchdown = 10.7899997383356 mm,29340746.33,92.0812302,99.5482559204102,1.39290517715358E-5,2.98139230279212E-7,1,0.999253354069792,40.0298881530762,1.99866735118309,16.4500009268522,0.000158394422906801,2.80378163524223E-5,0.25,7.57278534599786E-9,1.40047021697263E-5,6.02819428325059E-8,92.0812302,92.0812302,99.5482559204102,99.5482559204102,57.7959575974869,20.7601975213535,22.529354,0,0,0,40,4374,89.6115,99.5482559204102,,,,,,,,,,,,,0,,,,0.00245,,,,,,92.0812302,,,,
,29340847.03,89.4876404,99.5482559204102,1.46478725003117E-5,3.07248884498663E-7,1,0.999253354069792,40.0298881530762,1.99860309842654,16.4500009268522,0.000166908767982716,2.74609900279996E-5,0.25,-1.72624874990268E-7,1.47271077060063E-5,-1.15277179012579E-7,89.4876404,89.4876404,99.5482559204102,99.5482559204102,57.166746639506,20.7504671675391,22.529354,0,0,0,40,4374,87.09545,99.5482559204102,,,,,,,,,,,,,0,,,,0.00245,,,,,,89.4876404,,,,
,29340968.825,86.4298172,99.5482559204102,1.48792398442001E-5,2.87015724482448E-7,1,0.999253354069792,40.0298881530762,1.99869725087607,16.4500009268522,0.00016943261953977,2.8468848846233E-5,0.25,-1.2850029216918E-7,1.49579007399545E-5,-6.61717418975302E-8,86.4298172,86.4298172,99.5482559204102,99.5482559204102,57.7943943404484,20.7558251993803,22.529354,0,0,0,40,4374,84.0883,99.5482559204102,,,,,,,,,,,,,0,,,,-0.0049,,,,,,86.4298172,,,,
,29341084.675,83.4767761,99.5482559204102,1.57117239520842E-5,3.3328010548501E-7,1,0.999253354069792,40.0298881530762,1.99827900795592,16.4500009268522,0.000178325545698375,3.30250191033036E-5,0.25,1.21767742296671E-7,1.57914777129556E-5,1.9309129761652E-7,83.4767761,83.4767761,99.5482559204102,99.5482559204102,57.6732419199676,20.756541103574,22.149702,0,0,0,40,4374,81.2245,99.5482559204102,,,,,,,,,,,,,0,,,,-0.00245,,,,,,83.4767761,,,,
,29341203.335,80.4789734,99.5482559204102,1.61277409359312E-5,3.3618344228649E-7,1,0.999253354069792,40.0298881530762,1.9974992188586,16.5199991315603,0.000183723762764092,2.94977582408375E-5,0.25,-2.65594701378002E-7,1.62085084026869E-5,-1.89602046361251E-7,80.4789734,80.4789734,99.5482559204102,99.5482559204102,57.9733872713523,20.781576055254,22.149702,0,0,0,40,4374,78.3051,99.5482559204102,,,,,,,,,,,,,0,,,,0,,,,,,80.4789734,,,,
,29341320.615,77.4754868,99.5482559204102,1.65697148298483E-5,3.77404630258986E-7,1,0.999253354069792,40.0298881530762,1.99869361175241,16.5199991315603,0.00018877393768315,3.06036106834604E-5,0.25,-2.52792721357048E-7,1.66489159860332E-5,-1.69391398476972E-7,77.4754868,77.4754868,99.5482559204102,99.5482559204102,57.5286406439099,20.7612771589067,21.3904,0,0,0,40,4374,75.4157,99.5482559204102,,,,,,,,,,,,,0,,,,-0.0049,,,,,,77.4754868,,,,
,29341440.42,74.46702955,99.5482559204102,1.75661040841938E-5,3.28220325080375E-7,1,0.999253354069792,40.0298881530762,1.99713780881829,16.5199991315603,0.000199256100680539,3.61347901784878E-5,0.25,5.41489558314061E-8,1.76432319932163E-5,1.50065091883964E-7,74.4302368,74.5038223,99.5482559204102,99.5482559204102,57.7560945430061,20.7812822322365,21.3904,0,0,0,40,4374,72.441,99.5482559204102,,,,,,,,,,,,,0,,,,0,,,,,,74.46702955,,,,
touchdown = 10.9299998730421 mm,29341565.22,71.2499084,99.5482559204102,1.79375509983779E-5,2.52073671618789E-7,1,0.999253354069792,40.0298881530762,1.9971963043513,16.5899991989136,0.000203392228930436,3.69329155855689E-5,0.25,5.28762099238686E-8,1.80096760023224E-5,1.57300779157543E-7,71.2499084,71.2499084,99.5482559204102,99.5482559204102,57.5755383550638,20.7698935393156,21.01075,0,0,0,40,4374,69.4203,99.5482559204102,,,,,,,,,,,,,0,,,,0.00245,,,,,,71.2499084,,,,
,29341676.47,68.452713,99.5482559204102,1.88452575476731E-5,3.10204709544965E-7,1,0.999253354069792,40.0298881530762,1.99756109832402,16.5899991989136,0.000213987874581147,3.68110347573218E-5,0.25,-1.25582893785236E-7,1.89142730849149E-5,-1.01547426954522E-8,68.452713,68.452713,99.5482559204102,99.5482559204102,57.2574155477368,20.78218617371,21.770052,0,0,0,40,4374,66.6474,99.5482559204102,,,,,,,,,,,,,0,,,,-0.00245,,,,,,68.452713,,,,
,29341793.525,65.4394455,99.5482559204102,1.96138961764103E-5,3.40471483696308E-7,1,0.999253354069792,40.0298881530762,1.99792611170553,16.5899991989136,0.000222913031623959,3.67814534730998E-5,0.25,-2.71458254980926E-7,1.96765485116977E-5,-1.44887583295405E-7,65.4394455,65.4394455,99.5482559204102,99.5482559204102,57.6716786629292,20.7769704479131,21.01075,0,0,0,40,4374,63.76755,99.5482559204102,,,,,,,,,,,,,0,,,,0,,,,,,65.4394455,,,,
,29341909.3,62.4841957,99.5482559204102,2.0799512422338E-5,2.7905556604412E-7,1,0.999253354069792,40.0298881530762,1.99755785578157,16.5899991989136,0.000236725686228183,3.60808791143036E-5,0.25,-5.50056657774388E-7,2.0855326816259E-5,-4.09674588763758E-7,62.4841957,62.4841957,99.5482559204102,99.5482559204102,57.7818882841407,20.7933288682279,21.3904,0,0,0,40,4374,60.9305,99.5482559204102,,,,,,,,,,,,,0,,,,-0.0049,,,,,,62.4841957,,,,
,29342030.125,59.4575272,99.5482559204102,2.1275653133356E-5,3.3671123269574E-7,1,0.999253354069792,40.0298881530762,1.97269447688973,16.6500005871058,0.000238000451734995,4.25172679502278E-5,0.25,-2.56431848787332E-8,2.13135769467147E-5,1.25439945091415E-7,59.4575272,59.4575272,99.5482559204102,99.5482559204102,57.7381170870638,20.8058443829526,20.251448,0,0,0,40,4374,57.95895,99.5482559204102,,,,,,,,,,,,,0,,,,-0.0049,,,,,,59.4575272,,,,
,29342146.565,56.4832535,99.5482559204102,2.2550860078695E-5,3.26634151161636E-7,1,0.999253354069792,40.0298881530762,1.98551465350875,16.6500005871058,0.000254295366832647,4.16279669378442E-5,0.25,-3.59415507918052E-7,2.25756737437658E-5,-1.94908680257723E-7,56.4832535,56.4832535,99.5482559204102,99.5482559204102,57.8905346483138,20.7819146968284,21.01075,0,0,0,40,4374,55.0936,99.5482559204102,,,,,,,,,,,,,0,,,,-0.00245,,,,,,56.4832535,,,,
,29342262.045,53.4950371,99.5482559204102,2.34493935506857E-5,3.48763647500871E-7,1,0.999253354069792,40.0298881530762,1.98507366300883,16.6500005871058,0.000263937619195362,4.44165310345962E-5,0.25,-2.71891041668959E-7,2.34546943725829E-5,-9.78390020642284E-8,53.4950371,53.4950371,99.5482559204102,99.5482559204102,57.6857479762753,20.7813463041441,20.251448,0,0,0,40,4374,52.2692,99.5482559204102,,,,,,,,,,,,,0,,,,0,,,,,,53.4950371,,,,
touchdown = 11.0499998554587 mm,29342386.905,50.294838,99.5482559204102,2.47537252463944E-5,3.15260974228864E-7,1,0.999253354069792,40.0298881530762,2.00813206737989,16.7100001126528,0.000281198839455685,4.87170520673174E-5,0.25,-1.67868705231348E-7,2.47352473861057E-5,1.61143280689001E-8,50.294838,50.294838,99.5482559204102,99.5482559204102,57.8467634512369,20.7808452649643,20.251448,0,0,0,40,4374,49.2635,99.5482559204102,,,,,,,,,,,,,0,,,,0,,,,,,50.294838,,,,
,29342497.435,47.4784851,99.5482559204102,2.59093965303177E-5,3.56564075946048E-7,1,0.999253354069792,40.0298881530762,1.9987257329524,16.7100001126528,0.000293021370095771,4.92841531742907E-5,0.25,-3.00344537982242E-7,2.58689783896165E-5,-1.10203454950254E-7,47.4784851,47.4784851,99.5482559204102,99.5482559204102,57.6630807492176,20.7699898781608,18.732843,0,0,0,40,4374,46.5399,99.5482559204102,,,,,,,,,,,,,0,,,,0.0049,,,,,,47.4784851,,,,
,29342615.445,44.4539032,99.5482559204102,2.65518411276296E-5,3.22852901338126E-7,1,0.999253354069792,40.0298881530762,1.99895368288934,16.7100001126528,0.000299314287155882,5.46121697276881E-5,0.25,6.53792595826155E-8,2.64848725334586E-5,2.53704720305109E-7,44.4539032,44.4539032,99.5482559204102,99.5482559204102,57.4840878183138,20.7625877844645,18.732843,0,0,0,40,4370,43.64,99.5482559204102,,,,,,,,,,,,,0,,,,0,,,,,,44.4539032,,,,
,29342731.35,41.4805012,99.5482559204102,2.75561718900201E-5,3.16506392572671E-7,1,0.999253354069792,40.0298881530762,1.99921853124246,16.7100001126528,0.000310088589451969,5.8584037366755E-5,0.25,2.4828945257329E-7,2.74644636162797E-5,4.34866167565257E-7,41.4494019,41.5116005,99.5482559204102,99.5482559204102,57.6662072632946,20.7627171696733,17.973541,0,0,0,40,4370,40.8081,99.5482559204102,,,,,,,,,,,,,0,,,,-0.00245,,,,,,41.4805012,,,,
,29342850.375,38.4894753,99.5482559204102,2.84601964643442E-5,3.45586187998539E-7,1,0.999253354069792,40.0298881530762,1.99937568145156,16.7599990963936,0.000320806638467889,5.6325474828097E-5,0.25,-1.01034029523828E-7,2.834822580957E-5,8.24825426388885E-8,38.4894753,38.4894753,99.5482559204102,99.5482559204102,57.3816944822945,20.7595046525871,17.593889,0,0,0,40,4370,37.8433,99.5482559204102,,,,,,,,,,,,,0,,,,-0.00245,,,,,,38.4894753,,,,
,29342968.715,35.4403229,99.5482559204102,2.95553960088127E-5,3.48065460527943E-7,1,0.999253354069792,40.0298881530762,2.00072997107791,16.7599990963936,0.000333297385405482,5.78399215442866E-5,0.25,-1.52297535838838E-7,2.94229151216551E-5,2.74740986927564E-8,35.4403229,35.4403229,99.5482559204102,99.5482559204102,57.5481813568907,20.7522223415081,17.214239,0,0,0,40,4370,34.93215,99.5482559204102,,,,,,,,,,,,,0,,,,0,,,,,,35.4403229,,,,
,29343088.455,32.4502831,99.5482559204102,2.98826570135126E-5,3.23436925049153E-7,1,0.999253354069792,40.0298881530762,2.00096193795616,16.7599990963936,0.000336693053879748,5.94714178957672E-5,0.25,-5.34699475781589E-8,2.97348056529428E-5,1.17070871602866E-7,32.4502831,32.4502831,99.5482559204102,99.5482559204102,57.9429037591023,20.7511109158831,16.834587,0,0,0,40,4370,31.9771,99.5482559204102,,,,,,,,,,,,,0,,,,0.00245,,,,,,32.4502831,,,,
touchdown = 11.1400000751019 mm,29343210.665,29.3439121,99.5482559204102,3.08663881187981E-5,3.50326421858834E-7,1,0.999253354069792,40.0298881530762,2.00124887990213,16.8099999427795,0.000348102720757924,5.9192600962957E-5,0.25,-2.42882375104566E-7,3.07043102427797E-5,-7.5564543833423E-8,29.3439121,29.3439121,99.5482559204102,99.5482559204102,57.4043617093522,20.7331759872943,16.454937,0,0,0,40,4370,28.9748,99.5482559204102,,,,,,,,,,,,,0,,,,0,,,,,,29.3439121,,,,
,29343326.335,26.4348106,99.5482559204102,3.11415567148404E-5,3.04074329874464E-7,1,0.999253354069792,40.0298881530762,2.00043865694874,16.7999994009733,0.000350662099202413,6.15191101138615E-5,0.25,-7.42878865747103E-8,3.09699921868342E-5,8.59791111337427E-8,26.4348106,26.4348106,99.5482559204102,99.5482559204102,57.4989387601791,20.7515172052775,16.075285,0,0,0,40,4370,26.0678,99.5482559204102,,,,,,,,,,,,,0,,,,0,,,,,,26.4348106,,,,
,29343445.525,23.4584408,99.5482559204102,3.15979487198273E-5,2.89183400750161E-7,1,0.999253354069792,40.0298881530762,1.99925998479887,16.7999994009733,0.00035565502670246,6.17718104866201E-5,0.25,-1.23486217008243E-7,3.14194058152042E-5,3.37958510699807E-8,23.4584408,23.4584408,99.5482559204102,99.5482559204102,57.5685036983907,20.7559041185155,15.315984,0,0,0,40,4370,23.1106,99.5482559204102,,,,,,,,,,,,,0,,,,0,,,,,,23.4584408,,,,
,29343565.64,20.4407425,99.5482559204102,3.21651727090815E-5,3.24951477512958E-7,1,0.999253354069792,40.0298881530762,1.99843479775242,16.7999994009733,0.00036201830189693,6.20062201500759E-5,0.25,-1.97479647798298E-7,3.19812598424838E-5,-4.03045780492168E-8,20.4407425,20.4407425,99.5482559204102,99.5482559204102,57.5012836457369,20.7649107389543,14.936333,0,0,0,40,4374,20.11065,99.5482559204102,,,,,,,,,,,,,0,,,,-0.0049,,,,,,20.4407425,,,,
,29343682.74,17.480051,99.5482559204102,3.20192172634375E-5,3.3900571171566E-7,1,0.999253354069792,40.0298881530762,1.9984743804076,16.8299991637468,0.00036052551719032,6.08916033732976E-5,0.25,-2.69811864985871E-7,3.18360640724217E-5,-1.13837258005997E-7,17.480051,17.480051,99.5482559204102,99.5482559204102,57.5481813568907,20.7647417961313,14.177031,0,0,0,40,4370,17.18325,99.5482559204102,,,,,,,,,,,,,0,,,,0,,,,,,17.480051,,,,
,29343806.66,14.4370699,99.5482559204102,3.20943418740105E-5,2.79756445187718E-7,1,0.999253354069792,40.0298881530762,1.99801466617234,16.8299991637468,0.000361024097557574,6.25496096303081E-5,0.25,-1.34510184755687E-7,3.19104005792541E-5,2.1047486591048E-8,14.4370699,14.4370699,99.5482559204102,99.5482559204102,57.6521379499484,20.7696215001967,13.797379,0,0,0,40,4374,14.0657,99.5482559204102,,,,,,,,,,,,,0,,,,-0.0049,,,,,,14.4370699,,,,
,29343926.485,11.4632034,99.5482559204102,3.24353749523721E-5,3.00167925891956E-7,1,0.999253354069792,40.0298881530762,1.99844854053022,16.8299991637468,0.000364914260431513,6.33639550662506E-5,0.25,-1.23828530852981E-7,3.2249641984929E-5,3.33126621921579E-8,11.4632034,11.4632034,99.5482559204102,99.5482559204102,57.7615659426407,20.7590082153204,12.658426,0,0,0,40,4374,11.0616,99.5482559204102,,,,,,,,,,,,,0,,,,0,,,,,,11.4632034,,,,
,29344140.65,10.028966,99.5482559204102,3.25624837998194E-5,2.6958983054405E-7,1,0.999253354069792,40.0298881530762,2.00101336240085,16.8299991637468,0.000366473551320155,6.54940911050479E-5,0.25,3.592548077711E-8,3.23753314448132E-5,1.92762447962842E-7,10.028966,10.028966,99.5482559204102,99.5482559204102,57.4528226775445,20.7506041226973,12.658426,0,0,0,40,4369,9.89175,99.5482559204102,,,,,,,,,,,,,0,,,,-0.0049,,,,,,10.028966,,,,