File: data/looselyPackedNP/sc-ios-7/ppms/rawdata/ES_S17_HYST_10K_REMEASURE.DAT
[Header]
; VSM Data File (default extension .dat)
; Copyright (c) 2003-2013, Quantum Design, Inc. All rights reserved.
TITLE,
FILEOPENTIME,29397222.80,12/07/2018,1:54 pm
BYAPP,VSM,2.0,2.0
INFO,PPMS VSM Option Release 1.4.10 Build 1,APPNAME
INFO,Quantum Design Linear Motor Servo Controller,MOTOR_MODULE_NAME
INFO,3101-100 M1,MOTOR_HW_VERSION
INFO,MMC1014,MOTOR_SERIAL_NUMBER
INFO,SRV No X-over 01.03.11,MOTOR_SOFTWARE_VERSION
INFO,Quantum Design VSM Detection Module,VSM_MODULE_NAME
INFO,3101-150 F0,VSM_HW_VERSION
INFO,VSM707,VSM_SERIAL_NUMBER
INFO,VSM No X-over 01.02.05 May 20 2008 13:51:47,VSM_SOFTWARE_VERSION
INFO,704,PREAMP_SERIAL_NUMBER
INFO,822,COIL_SERIAL_NUMBER
INFO,0,MOMENT_UNITS
INFO,Iron Oxide Spheres,SAMPLE_MATERIAL
INFO,7 nm diameter, collaboration Mainz,SAMPLE_COMMENT
INFO,,SAMPLE_MASS
INFO,,SAMPLE_VOLUME
INFO,,SAMPLE_MOLECULAR_WEIGHT
INFO,,SAMPLE_SIZE
INFO,,SAMPLE_SHAPE
DATATYPE,COMMENT,1
DATATYPE,TIME,2
STARTUPAXIS,X,2
STARTUPAXIS,Y1,5
[Data]
Comment,Time Stamp (sec),Temperature (K),Magnetic Field (Oe),Moment (emu),M. Std. Err. (emu),Transport Action,Averaging Time (sec),Frequency (Hz),Peak Amplitude (mm),Center Position (mm),Coil Signal' (mV),Coil Signal" (mV),Range (mV),M. Quad. Signal (emu),M. Raw' (emu),M. Raw" (emu),Min. Temperature (K),Max. Temperature (K),Min. Field (Oe),Max. Field (Oe),Mass (grams),Motor Lag (deg),Pressure (Torr),VSM Status (code),Motor Status (code),Measure Status (code),Measure Count,PPMS Status (code),System Temp. (K),System Field (Oe),Sample Position (deg),Bridge 1 Resistance (ohms),Bridge 1 Excitation (에),Bridge 2 Resistance (ohms),Bridge 2 Excitation (에),Bridge 3 Resistance (ohms),Bridge 3 Excitation (에),Bridge 4 Resistance (ohms),Bridge 4 Excitation (에),Signal 1 Vin (V),Signal 2 Vin (V),Digital Inputs (code),Drive 1 Iout (mA),Drive 1 Ipower (W),Drive 2 Iout (mA),Drive 2 Ipower (W),Pressure (),Map 20 (),Map 21 (),Map 22 (),Map 23 (),Map 24 (),Map 25 (),Map 26 (),Map 27 (),Map 28 (),Map 29 ()
,29397237.31,10.0006771,0.350146800279617,,,2,,,,17.0099997353554,,,,,,,10.0006771,10.0006771,0.350146800279617,0.350146800279617,,,11.139823,,,,-99999999,4369,10.0066,0.350146800279617,,,,,,,,,,,,,,,,,,,,,,,10.0006771,,,,
,29397544.91,10.0070801,4930.81469726562,9.46165619783508E-5,4.17572147449408E-7,1,0.999253354069792,40.0298881530762,2.00295427814473,17.000000923872,0.00106720518729305,0.000184517310076798,0.25,-4.57871515623719E-7,9.41010959822714E-5,2.93257132130279E-8,10.0070801,10.0070801,4920.78662109375,4940.8427734375,57.0565370182945,20.6977810035452,11.519473,0,0,0,40,4449,9.9036,4930.81469726562,,,,,,,,,,,,,0,,,,0,,,,,,10.0070801,,,,
,29397643.77,10.00032285,9872.20068359375,7.00116573174589E-5,6.4269121423745E-7,1,0.999253354069792,40.0298881530762,2.00299726904631,17.000000923872,0.000790339181832326,0.000134635790250216,0.25,-5.37275972409162E-7,6.96572073808174E-5,-1.50550008513662E-7,9.9994755,10.0011702,9837.4130859375,9906.98828125,57.3113479155637,20.6944749298511,11.899124,0,0,0,40,4449,9.89065,9872.20068359375,,,,,,,,,,,,,0,,,,0,,,,,,10.00032285,,,,
,29397744.735,9.9978094,14914.7836914062,3.89628771013395E-5,6.8077267451362E-7,1,0.999253354069792,40.0298881530762,2.00297241663883,17.000000923872,0.000444135379621319,5.19623524493164E-5,0.25,-2.35251167148792E-6,3.87945621453317E-5,-2.11353143164497E-6,9.9978094,9.9978094,14909.666015625,14919.9013671875,57.2839909173907,20.6950150530418,11.519473,0,0,0,40,4449,9.9005,14914.7836914062,,,,,,,,,,,,,0,,,,0.00245,,,,,,9.9978094,,,,
,29397847.595,9.9964142,20056.6650390625,1.00649854017222E-5,6.76149619326272E-7,1,0.999253354069792,40.0298881530762,2.00279494229298,17.000000923872,0.00012257350823634,-3.01184014479087E-5,0.25,-4.47139197900234E-6,1.00505357984962E-5,-4.39024543219166E-6,9.9964142,9.9964142,20051.701171875,20061.62890625,57.3637170263522,20.6974689680999,11.519473,0,0,0,40,4449,9.89175,20056.6650390625,,,,,,,,,,,,,0,,,,-0.00245,,,,,,9.9964142,,,,
,29397948.32,9.9979601,25091.6767578125,-2.04052812789343E-5,9.10472623978298E-7,1,0.999253354069792,40.0298881530762,2.00293471554276,17.000000923872,-0.000221996847299718,-8.76838031182627E-5,0.25,-4.10970412476549E-6,-2.03032969816892E-5,-4.22732145806918E-6,9.9979601,9.9979601,25083.94140625,25099.412109375,57.2284952925253,20.6965506969362,11.139823,0,0,0,40,4449,9.89825,25091.6767578125,,,,,,,,,,,,,0,,,,-0.0049,,,,,,9.9979601,,,,
,29398051.18,9.9984226,30232.013671875,-5.57023923405133E-5,1.32819190907262E-6,1,0.999253354069792,40.0298881530762,2.00363189178076,17.000000923872,-0.000626245265304038,-0.000129615527594092,0.25,-1.47090455840832E-6,-5.55167320406466E-5,-1.84368397663296E-6,9.9984226,9.9984226,30222.234375,30241.79296875,57.8115901678715,20.6905785023855,11.519473,0,0,0,40,4449,9.8954,30232.013671875,,,,,,,,,,,,,0,,,,-0.00245,,,,,,9.9984226,,,,
,29398155.695,9.9890833,35456.439453125,-8.63484318824946E-5,1.2477043925661E-6,1,0.999253354069792,40.0298881530762,2.00371113477479,17.000000923872,-0.000966437907920837,-0.000228418546659662,0.25,-4.68290208811901E-6,-8.60910055801655E-5,-5.27521843853586E-6,9.9890833,9.9890833,35448.6328125,35464.24609375,57.3230723433522,20.7004157091098,11.139823,0,0,0,40,4449,9.8874,35456.439453125,,,,,,,,,,,,,0,,,,0.0049,,,,,,9.9890833,,,,
,29398256.55,9.9868193,40496.673828125,-0.000121429537039765,1.58583445604572E-6,1,0.999253354069792,40.0298881530762,2.00373897839184,17.000000923872,-0.00136152053246615,-0.00031190067045716,0.25,-5.72567783765982E-6,-0.00012113748064103,-6.58465700456721E-6,9.9868193,9.9868193,40491.8125,40501.53515625,57.6896561188715,20.6996393177256,10.760172,0,0,0,40,4449,9.88805,40496.673828125,,,,,,,,,,,,,0,,,,-0.00245,,,,,,9.9868193,,,,
,29398356.935,10.0000134,45517.36328125,-0.000151149080085207,1.51204185241358E-6,1,0.999253354069792,40.0298881530762,2.00320417753301,17.000000923872,-0.00169751404140096,-0.000375513740688271,0.25,-5.97438326310315E-6,-0.000150872685034929,-7.06818336360787E-6,10.0000134,10.0000134,45510.1171875,45524.609375,57.5927341824868,20.6990351532349,11.139823,0,0,0,40,4449,9.88335,45517.36328125,,,,,,,,,,,,,0,,,,0.00245,,,,,,10.0000134,,,,
,29398459.105,10.0005617,50621.75,-0.000185784292361704,1.83032946971345E-6,1,0.999253354069792,40.0298881530762,2.0032546218724,17.000000923872,-0.00209406658492946,-0.000426104769272082,0.25,-4.17285815155166E-6,-0.000185564665265218,-5.54035812084064E-6,10.0005617,10.0005617,50617.03125,50626.46875,57.7709454848715,20.7005383972915,11.519473,0,0,0,40,4449,9.8866,50621.75,,,,,,,,,,,,,0,,,,0.00245,,,,,,10.0005617,,,,
,29398564.985,10.0017538,55913.74609375,-0.000224674010366349,2.06111819813483E-6,1,0.999253354069792,40.0298881530762,2.00328099765127,17.000000923872,-0.0025357298384967,-0.0005047265630141,0.25,-4.07808821510344E-6,-0.000224533425336675,-5.74583011013842E-6,10.0017538,10.0017538,55903.75,55923.7421875,57.8600511360638,20.6955315699996,11.899124,0,0,0,40,4449,9.88955,55913.74609375,,,,,,,,,,,,,0,,,,-0.00245,,,,,,10.0017538,,,,
,29398669.335,10.0146799,61128.771484375,-0.000253385376173261,2.11412392709759E-6,1,0.999253354069792,40.0298881530762,2.00289643489532,17.000000923872,-0.00286416089709368,-0.000550037790550634,0.25,-2.88747265912542E-6,-0.000253365303998684,-4.77349301205728E-6,10.0146799,10.0146799,61126.19921875,61131.34375,58.0296645247369,20.7052871415181,10.760172,0,0,0,40,4449,9.8885,61128.771484375,,,,,,,,,,,,,0,,,,0.0049,,,,,,10.0146799,,,,
,29398772.045,10.0034466,66261.5,-0.00028786570387663,2.15925075733414E-6,1,0.999253354069792,40.0298881530762,2.00263701192707,17.000000923872,-0.00325359463439054,-0.000633030837922025,0.25,-3.98694672906561E-6,-0.000287971669194877,-6.12587874655142E-6,10.0034466,10.0034466,66253.90625,66269.09375,57.8600511360638,20.7059176215327,11.519473,0,0,0,40,4449,9.8735,66261.5,,,,,,,,,,,,,0,,,,-0.00245,,,,,,10.0034466,,,,
,29398874.68,10.0120525,71391.5390625,-0.000316495939548759,3.28415777170967E-6,1,0.999253354069792,40.0298881530762,2.00250457838319,17.000000923872,-0.00358491643585204,-0.000660846531751061,0.25,-1.27528731299403E-6,-0.000316774952461966,-3.61167349405056E-6,10.0120525,10.0120525,71386.4609375,71396.6171875,57.8326941378907,20.7055686451921,11.519473,0,0,0,40,4449,9.8572,71391.5390625,,,,,,,,,,,,,0,,,,-0.0049,,,,,,10.0120525,,,,
,29398974.39,10.0083609,76377.67578125,-0.000339892176597672,4.3410626804213E-6,1,0.999253354069792,40.0298881530762,2.00237087707472,17.000000923872,-0.00382831074561065,-0.00083719037927183,0.25,-1.26150307112121E-5,-0.000340246868860105,-1.51173294659258E-5,10.0083609,10.0083609,76370.1953125,76385.15625,57.9577547009677,20.7022194687665,11.519473,0,0,0,40,4449,9.8528,76377.67578125,,,,,,,,,,,,,0,,,,0,,,,,,10.0083609,,,,
,29399071.015,10.0079079,81208.02734375,-0.000339143518484173,6.20004391391447E-6,1,0.999253354069792,40.0298881530762,2.00215829013654,17.000000923872,-0.00379442998924943,-0.000982633799447778,0.25,-2.55810130262499E-5,-0.000339529251470322,-2.80773390284739E-5,10.0079079,10.0079079,81197.765625,81218.2890625,57.7498415148523,20.7100620180595,11.139823,0,0,0,40,4449,9.83795,81208.02734375,,,,,,,,,,,,,0,,,,-0.0049,,,,,,10.0079079,,,,
,29399161.265,10.0107203,85718.96875,-0.000366230251040022,7.57920075911046E-6,1,0.999253354069792,40.0298881530762,2.00169486244109,17.000000923872,-0.00403929450351462,-0.0013870868554804,0.25,-5.63827270314244E-5,-0.000366562087085918,-5.91134865736121E-5,10.0107203,10.0107203,85716.5703125,85721.3671875,58.0492052377177,20.7156353352791,11.899124,0,0,0,40,4449,9.8251,85718.96875,,,,,,,,,,,,,0,,,,0,,,,,,10.0107203,,,,
,29399271.575,10.0021019,89765.296875,-0.000434344643819676,4.888276989096E-6,1,0.999253354069792,40.0298881530762,2.00166796019863,17.000000923872,-0.00490249273025992,-0.00103037213095552,0.25,-1.26945729137999E-5,-0.000435245481690904,-1.57908936216255E-5,10.0021019,10.0021019,89762.8046875,89767.7890625,57.8647409071792,20.7149689263093,11.899124,0,0,0,40,4449,9.8346,89765.296875,,,,,,,,,,,,,0,,,,-0.00245,,,,,,10.0021019,,,,
,29399359.625,10.0063038,85369.078125,-0.00035883846015273,7.55625381391882E-6,1,0.999253354069792,40.0298881530762,2.00226345905891,17.000000923872,-0.00396296868296243,-0.00133592172698112,0.25,-5.31706988423389E-5,-0.000359169294007491,-5.58434140413758E-5,10.0062962,10.0063114,85363.84375,85374.3125,57.8772469634869,20.7077681867852,11.139823,0,0,0,40,4449,9.82695,85369.078125,,,,,,,,,,,,,0,,,,0.0049,,,,,,10.0063038,,,,
,29399452.215,10.0058928,80740.65625,-0.000372404634390735,4.57234755587857E-6,1,0.999253354069792,40.0298881530762,2.0020972863768,17.000000923872,-0.00415072009340121,-0.00116545760206017,0.25,-3.57154392139044E-5,-0.00037275984608972,-3.84712830228605E-5,10.0058928,10.0058928,80735.625,80745.6875,57.94524864466,20.7101713247537,11.139823,0,0,0,40,4449,9.8273,80740.65625,,,,,,,,,,,,,0,,,,-0.0049,,,,,,10.0058928,,,,
,29399544.615,10.0081234,76119.16796875,-0.000345451286684482,4.25918024334661E-6,1,0.999253354069792,40.0298881530762,2.00195660652343,17.000000923872,-0.00386918907439737,-0.000966671253543931,0.25,-2.30499640523755E-5,-0.00034572986348923,-2.56074931138182E-5,10.0081234,10.0081234,76116.6328125,76121.703125,58.0765622358908,20.7162402002615,11.139823,0,0,0,40,4449,9.8254,76119.16796875,,,,,,,,,,,,,0,,,,0,,,,,,10.0081234,,,,
,29399636.82,10.0182056,71510.4765625,-0.000291619667798921,6.43527948190914E-6,1,0.999253354069792,40.0298881530762,2.00162398229947,17.0099996030331,-0.00320488248292844,-0.0011465165625301,0.25,-4.86457505667459E-5,-0.000291529445973835,-5.08418534725007E-5,10.0182056,10.0182056,71503.125,71517.828125,57.8444185656792,20.7129423501421,11.519473,0,0,0,40,4449,9.81325,71510.4765625,,,,,,,,,,,,,0,,,,0,,,,,,10.0182056,,,,
,29399729.555,10.0317035,66875.125,-0.000271698290141304,7.85509740466098E-6,1,0.999253354069792,40.0298881530762,2.00118390705253,17.000000923872,-0.0029767515486661,-0.00110841232262353,0.25,-4.89194149581405E-5,-0.000271477934363795,-5.09609956211818E-5,10.0271521,10.0362549,66870.0390625,66880.2109375,57.9882382132177,20.7236511369839,11.519473,0,0,0,40,4449,9.8078,66875.125,,,,,,,,,,,,,0,,,,-0.0049,,,,,,10.0317035,,,,
,29399822.1,9.9950304,62251.685546875,-0.000256157244830791,5.45266491124108E-6,1,0.999253354069792,40.0298881530762,2.00173684611417,17.000000923872,-0.00284165318524169,-0.000847296904683765,0.25,-2.86658339182998E-5,-0.000255971973822812,-3.05751443006782E-5,9.9950304,9.9950304,62246.83984375,62256.53125,57.9765137854292,20.7136232007261,11.139823,0,0,0,40,4449,9.8025,62251.685546875,,,,,,,,,,,,,0,,,,0,,,,,,9.9950304,,,,
,29399915.445,10.0139074,57583.33203125,-0.000221166612238446,3.38728044301716E-6,1,0.999253354069792,40.0298881530762,2.00126935129054,17.000000923872,-0.00248129688298634,-0.000567788632970654,0.25,-1.03181369388534E-5,-0.000221016990390157,-1.19600370344519E-5,10.0139074,10.0139074,57583.33203125,57583.33203125,57.6411951506792,20.7197772591932,11.899124,0,0,0,40,4449,9.7892,57583.33203125,,,,,,,,,,,,,0,,,,-0.0049,,,,,,10.0139074,,,,
,29400008.89,9.9985209,52913.236328125,-0.000196605256789236,3.90553647521614E-6,1,0.999253354069792,40.0298881530762,2.00157006606501,17.0099996030331,-0.00216772840591738,-0.000711663000746816,0.25,-2.74863314886525E-5,-0.000196247008598546,-2.89214252892632E-5,9.9985209,9.9985209,52905.93359375,52920.5390625,57.8287859952946,20.7203118126776,11.139823,0,0,0,40,4449,9.78345,52913.236328125,,,,,,,,,,,,,0,,,,-0.00245,,,,,,9.9985209,,,,
,29400104.32,10.0110083,48145.66015625,-0.000168013866282157,2.84879029323857E-6,1,0.999253354069792,40.0298881530762,2.00157358668107,17.000000923872,-0.0018562402268832,-0.000582175746132806,0.25,-2.12254834858554E-5,-0.000167644775266797,-2.24329283634101E-5,10.0110083,10.0110083,48142.515625,48148.8046875,57.799865740083,20.720009182496,11.519473,0,0,0,40,4449,9.7776,48145.66015625,,,,,,,,,,,,,0,,,,0,,,,,,10.0110083,,,,
,29400194.87,10.00453,43617.673828125,-0.000142337648829783,2.68336670056682E-6,1,0.999253354069792,40.0298881530762,2.00134588212935,17.000000923872,-0.00155278393353038,-0.00059781962671807,0.25,-2.72779685301163E-5,-0.000141892304163768,-2.82631686463338E-5,10.00453,10.00453,43610.140625,43625.20703125,57.9944912413715,20.7234566259909,11.139823,0,0,0,40,4449,9.77395,43617.673828125,,,,,,,,,,,,,0,,,,0,,,,,,10.00453,,,,
,29400287.51,10.0284624,38987.537109375,-0.000102477569753432,2.66030728936317E-6,1,0.999253354069792,40.0298881530762,2.00130137083012,17.000000923872,-0.00109355696119022,-0.000562700275795342,0.25,-3.13851353283401E-5,-0.000102025750820826,-3.20453969026747E-5,10.0284624,10.0284624,38982.71484375,38992.359375,58.0148135828715,20.7221233957489,11.519473,0,0,0,40,4449,9.7675,38987.537109375,,,,,,,,,,,,,0,,,,0,,,,,,10.0284624,,,,
,29400379.685,10.0034132,34382.716796875,-7.26214090262989E-5,2.49310832463046E-6,1,0.999253354069792,40.0298881530762,2.00130613137711,17.000000923872,-0.000784243450837666,-0.000345034757287884,0.25,-1.75103073978468E-5,-7.23023554973025E-5,-1.79680905580167E-5,10.0023289,10.0044975,34375.30078125,34390.1328125,58.16879440116,20.7256277525104,11.139823,0,0,0,40,4449,9.76345,34382.716796875,,,,,,,,,,,,,0,,,,0,,,,,,10.0034132,,,,
,29400471.655,9.9893494,29785.6376953125,-4.52483578488511E-5,1.41602248510751E-6,1,0.999253354069792,40.0298881530762,2.00174895815357,17.000000923872,-0.000493252033031724,-0.000188625909834672,0.25,-8.58887104675912E-6,-4.50455077491204E-5,-8.86699108269552E-6,9.9893494,9.9893494,29783.03515625,29788.240234375,57.9561914439292,20.7212915364111,11.519473,0,0,0,40,4449,9.7626,29785.6376953125,,,,,,,,,,,,,0,,,,-0.0049,,,,,,9.9893494,,,,
,29400560.5,9.995532,25341.857421875,-1.84068046872178E-5,1.2142712317643E-6,1,0.999253354069792,40.0298881530762,2.00149914101818,17.000000923872,-0.000192615866811555,-0.000120903473919167,0.25,-7.41804527954601E-6,-1.829102905383E-5,-7.51090974839285E-6,9.995532,9.995532,25339.375,25344.33984375,58.0452970951215,20.7250713982914,11.519473,0,0,0,40,4449,9.7695,25341.857421875,,,,,,,,,,,,,0,,,,-0.0049,,,,,,9.995532,,,,
,29400654.29,9.990448,20657.1708984375,5.26811977604155E-6,5.3176155993144E-7,1,0.999253354069792,40.0298881530762,2.00133276205381,17.000000923872,7.63133123552552E-5,-8.38798309867128E-5,0.25,-8.38337698516832E-6,5.29865959526383E-6,-8.31587051597169E-6,9.990448,9.990448,20652.048828125,20662.29296875,58.0335726673331,20.7233414858331,10.760172,0,0,0,40,4449,9.75255,20657.1708984375,,,,,,,,,,,,,0,,,,-0.00245,,,,,,9.990448,,,,
,29400745.93,10.0131912,16077.6870117188,3.40836374029992E-5,7.65966223811934E-7,1,0.999253354069792,40.0298881530762,2.00113090152396,17.000000923872,0.000399831767065981,-1.95521017170198E-5,0.25,-7.82657813402973E-6,3.39744030292275E-5,-7.58860961283903E-6,10.0131912,10.0131912,16070.130859375,16085.2431640625,57.7295191733523,20.7239224307585,11.899124,0,0,0,40,4449,9.7538,16077.6870117188,,,,,,,,,,,,,0,,,,0,,,,,,10.0131912,,,,
,29400837.395,10.0023031,11504.7475585938,5.99715251039295E-5,5.6209298407553E-7,1,0.999253354069792,40.0298881530762,2.00093714382113,17.000000923872,0.000688082532939482,4.98931934211213E-5,0.25,-6.26826265037344E-6,5.97085737046255E-5,-5.90097179434687E-6,10.0023031,10.0023031,11502.3916015625,11507.103515625,58.1390925174292,20.7255507546433,11.139823,0,0,0,40,4449,9.7478,11504.7475585938,,,,,,,,,,,,,0,,,,-0.00245,,,,,,10.0023031,,,,
,29400928.415,10.0113525,6957.02612304687,8.5888601487764E-5,4.51750864824449E-7,1,0.999253354069792,40.0298881530762,2.00052656589062,17.000000923872,0.000974850258793718,0.000127617114080788,0.25,-3.95553569525594E-6,8.54516786352763E-5,-3.48187807639364E-6,10.0113525,10.0113525,6954.548828125,6959.50341796875,57.9647893576408,20.7326377405282,11.139823,0,0,0,40,4449,9.7454,6957.02612304687,,,,,,,,,,,,,0,,,,0,,,,,,10.0113525,,,,
,29401018.485,9.9985037,2453.80517578125,0.000101362802324555,3.81660758599275E-7,1,0.999253354069792,40.0298881530762,2.00070242961774,17.0099996030331,0.00114293594570569,0.000191549898741748,0.25,-9.95782518437275E-7,0.000100797239472206,-4.88069940923131E-7,9.9985037,9.9985037,2446.29345703125,2461.31689453125,57.6857479762753,20.7311402196047,11.139823,0,0,0,40,4449,9.74565,2453.80517578125,,,,,,,,,,,,,0,,,,0.00245,,,,,,9.9985037,,,,
,29401108.45,10.0040073,-2038.05853271484,-8.94074043331967E-5,3.20775781808384E-7,1,0.999253354069792,40.0298881530762,2.00048101487573,17.000000923872,-0.00100683393285026,-0.000175497700865298,0.25,2.9289328724387E-7,-8.89035470135065E-5,-1.49290309068106E-7,10.0040073,10.0040073,-2043.15637207031,-2032.96069335938,58.2078758271215,20.7358842166684,11.519473,0,0,0,40,4449,9.7505,-2038.05853271484,,,,,,,,,,,,,0,,,,-0.0049,,,,,,10.0040073,,,,
,29401199.695,10.0129576,-6601.34448242188,-8.62016612615203E-5,5.49193103124314E-7,1,0.999253354069792,40.0298881530762,2.00027647404819,17.000000923872,-0.000976429882362425,-0.000138344355033704,0.25,3.05435825957065E-6,-8.57560033039601E-5,2.58601905765996E-6,10.0129576,10.0129576,-6611.345703125,-6591.34326171875,57.8076820252753,20.738558702491,11.899124,0,0,0,40,4449,9.7578,-6601.34448242188,,,,,,,,,,,,,0,,,,0.0049,,,,,,10.0129576,,,,
,29401293.265,9.9826632,-11277.1782226562,-6.25090033208765E-5,6.35587575351648E-7,1,0.999253354069792,40.0298881530762,2.0003707431576,17.000000923872,-0.000715672501152786,-5.93616556882599E-5,0.25,5.87768606073203E-6,-6.22299624490436E-5,5.49904728390959E-6,9.9826632,9.9826632,-11279.5576171875,-11274.798828125,57.6427584077176,20.7408587902214,11.519473,0,0,0,40,4449,9.7568,-11277.1782226562,,,,,,,,,,,,,0,,,,-0.0049,,,,,,9.9826632,,,,
,29401387.21,10.0214863,-15972.3388671875,-3.74768159803839E-5,6.80975077431799E-7,1,0.999253354069792,40.0298881530762,2.00084213136585,17.000000923872,-0.000444597086971905,4.9617799958474E-5,0.25,1.1101501449632E-5,-3.73710696191446E-5,1.08286109425016E-5,10.0214863,10.0214863,-15977.3330078125,-15967.3447265625,58.1015743485062,20.7348529080334,11.139823,0,0,0,40,4449,9.7333,-15972.3388671875,,,,,,,,,,,,,0,,,,-0.0049,,,,,,10.0214863,,,,
,29401481.845,10.0226564,-20702.07421875,-6.6092115081601E-6,4.59901450405361E-7,1,0.999253354069792,40.0298881530762,2.00063427097845,17.000000923872,-0.000100163040656345,0.000130075439255085,0.25,1.27248792839084E-5,-6.66136323350952E-6,1.2631104196886E-5,10.0226564,10.0226564,-20709.615234375,-20694.533203125,58.2188186263908,20.7335344850212,11.139823,0,0,0,40,4449,9.72255,-20702.07421875,,,,,,,,,,,,,0,,,,0.0049,,,,,,10.0226564,,,,
,29401572.725,9.979784,-25244.4794921875,1.72221738113851E-5,1.82486015266717E-6,1,0.999253354069792,40.0298881530762,2.00131621413252,17.000000923872,0.00017235744393088,0.000156859813220993,0.25,1.08196619358615E-5,1.70884429672441E-5,1.08921431919183E-5,9.979784,9.979784,-25252.173828125,-25236.78515625,57.9898014702561,20.72537804362,11.139823,0,0,0,40,4449,9.7499,-25244.4794921875,,,,,,,,,,,,,0,,,,0,,,,,,9.979784,,,,
,29401665.42,10.0075769,-29877.2783203125,4.70090075210504E-5,1.76760419491965E-6,1,0.999253354069792,40.0298881530762,2.00107494891255,17.000000923872,0.000493880389301424,0.000298397202797998,0.25,1.80073981567943E-5,4.67372782120387E-5,1.82676426911287E-5,10.0075769,10.0075769,-29879.626953125,-29874.9296875,58.0632745510638,20.7268642019012,11.519473,0,0,0,40,4449,9.7414,-29877.2783203125,,,,,,,,,,,,,0,,,,0.0049,,,,,,10.0075769,,,,
,29401760.42,10.0149345,-34624.146484375,7.46662382898289E-5,2.00973136367391E-6,1,0.999253354069792,40.0298881530762,2.00071088891429,17.000000923872,0.000803805355222976,0.000367508951260653,0.25,1.91413481908719E-5,7.43320084485438E-5,1.96101435632401E-5,10.0149345,10.0149345,-34626.79296875,-34621.5,58.1312762322369,20.7321563758692,11.519473,0,0,0,40,4449,9.7361,-34624.146484375,,,,,,,,,,,,,0,,,,-0.0049,,,,,,10.0149345,,,,
,29401854.54,10.0042467,-39329.1015625,0.000103087702446719,2.45577439139562E-6,1,0.999253354069792,40.0298881530762,2.00088875837462,17.000000923872,0.00114491963874435,0.000315712216589137,0.25,9.40893889589904E-6,0.000102794738044822,1.01239439160665E-5,10.00352,10.0049734,-39334.515625,-39323.6875,58.1515985737369,20.7339350138838,11.139823,0,0,0,40,4449,9.7391,-39329.1015625,,,,,,,,,,,,,0,,,,-0.0049,,,,,,10.0042467,,,,
,29401948.355,9.9839392,-44018.8203125,0.000124563314514981,3.08545824290489E-6,1,0.999253354069792,40.0298881530762,2.00098271328607,17.000000923872,0.00139708389862249,0.000309950894551222,0.25,5.00385948314594E-6,0.000124315650067549,5.90023025410083E-6,9.9839392,9.9839392,-44021.54296875,-44016.09765625,58.1140804048138,20.7275716214863,10.760172,0,0,0,40,4449,9.745,-44018.8203125,,,,,,,,,,,,,0,,,,0.0049,,,,,,9.9839392,,,,
,29402040.47,9.9890623,-48621.431640625,0.000157181697520781,3.17844118343893E-6,1,0.999253354069792,40.0298881530762,2.00090557978288,17.000000923872,0.00173878563986143,0.000529561873018107,0.25,1.85346613200562E-5,0.000156853643680561,1.96680641701976E-5,9.9890623,9.9890623,-48624.01171875,-48618.8515625,58.1961513993331,20.7303765243848,11.139823,0,0,0,40,4449,9.75045,-48621.431640625,,,,,,,,,,,,,0,,,,0,,,,,,9.9890623,,,,
,29402134.585,10.00362585,-53323.880859375,0.000194018424445863,5.43104084584945E-6,1,0.999253354069792,40.0298881530762,2.00078152868642,17.000000923872,0.00220706511713905,0.000321562109637029,0.25,-6.52793423802791E-6,0.000193922177977601,-5.08478605851984E-6,10.003396,10.0038557,-53331.39453125,-53316.3671875,58.3774892157946,20.7347232753352,11.139823,0,0,0,40,4449,9.75205,-53323.880859375,,,,,,,,,,,,,0,,,,0.0049,,,,,,10.00362585,,,,
,29402229.39,9.9975863,-58063.455078125,0.000207073270949152,3.74182845442887E-6,1,0.999253354069792,40.0298881530762,2.00060050088078,17.000000923872,0.00233875609772989,0.00044154196491616,0.25,1.71070604980963E-6,0.000207001851577179,3.25097750818561E-6,9.9975863,9.9975863,-58068.28125,-58058.62890625,58.2360144538139,20.7353480167612,11.139823,0,0,0,40,4449,9.74995,-58063.455078125,,,,,,,,,,,,,0,,,,0,,,,,,9.9975863,,,,
,29402323.505,9.9872828,-62766.095703125,0.00024603273795212,4.60437930583672E-6,1,0.999253354069792,40.0298881530762,2.00056581354338,17.000000923872,0.00272155880383023,0.000848815643219895,0.25,3.06636370081152E-5,0.000245843146196892,3.24989526692741E-5,9.9872828,9.9872828,-62770.9140625,-62761.27734375,58.2922917071985,20.7347585255476,11.139823,0,0,0,40,4449,9.75045,-62766.095703125,,,,,,,,,,,,,0,,,,0.0049,,,,,,9.9872828,,,,
,29402416.095,10.0043616,-67396.11328125,0.000288396254732936,4.94465690564256E-6,1,0.999253354069792,40.0298881530762,2.0007961887146,17.000000923872,0.00325638539260944,0.000637429335472716,0.25,4.32579970196242E-6,0.000288528701887957,6.46696618835834E-6,10.0033693,10.0053539,-67408.7890625,-67383.4375,58.2453939960446,20.7407971168954,11.519473,0,0,0,40,4449,9.75955,-67396.11328125,,,,,,,,,,,,,0,,,,0,,,,,,10.0043616,,,,
,29402508.25,10.0037727,-72000.53125,0.000309140951464147,5.05400368100166E-6,1,0.999253354069792,40.0298881530762,2.00081493149996,17.000000923872,0.00348572352852657,0.000718496949945342,0.25,7.73659869854826E-6,0.000309381287282254,1.0022857171792E-5,10.0037727,10.0037727,-72010.515625,-71990.546875,58.3141773057369,20.738657416418,11.519473,0,0,0,40,4449,9.75975,-72000.53125,,,,,,,,,,,,,0,,,,-0.00245,,,,,,10.0037727,,,,
,29402603.51,9.9904051,-76760.24609375,0.00034411096513787,3.69793232549287E-6,1,0.999253354069792,40.0298881530762,2.00081378215386,17.000000923872,0.00387952887561999,0.00081111205816764,0.25,9.60835094178025E-6,0.000344503572512555,1.21358590016661E-5,9.9904051,9.9904051,-76767.7265625,-76752.765625,58.375144330237,20.7359577888839,11.139823,0,0,0,40,4449,9.7616,-76760.24609375,,,,,,,,,,,,,0,,,,0,,,,,,9.9904051,,,,
,29402696.87,9.995904,-81425.0234375,0.000355112401828668,4.24630304879426E-6,1,0.999253354069792,40.0298881530762,2.00087062422618,17.0099996030331,0.004022673278492,0.000739692023616699,0.25,1.32755870813737E-6,0.000355706148703662,3.89721633476892E-6,9.995904,9.995904,-81435.3359375,-81414.7109375,58.1617597444869,20.7413459966494,10.760172,0,0,0,40,4449,9.7644,-81425.0234375,,,,,,,,,,,,,0,,,,0,,,,,,9.995904,,,,
,29402788.355,9.9979181,-85996.984375,0.000399700456026215,6.40372553909183E-6,1,0.999253354069792,40.0298881530762,2.00071031703147,17.0099996030331,0.00443383290481294,0.00136109587287567,0.25,4.81254247026169E-5,0.000400166464896414,5.1077518852203E-5,9.9979181,9.9979181,-86002.03125,-85991.9375,58.3446608179869,20.7445885446091,11.139823,0,0,0,40,4449,9.7559,-85996.984375,,,,,,,,,,,,,0,,,,0,,,,,,9.9979181,,,,
,29402891.78,10.0070658,-89789.78515625,0.000432520578592678,6.24544459885294E-6,1,0.999253354069792,40.0298881530762,2.00073573773207,17.000000923872,0.00476029501529382,0.0016897768596122,0.25,7.12028170746398E-5,0.000433004799715062,7.44195612674701E-5,10.0070658,10.0070658,-89792.1328125,-89787.4375,58.2938549642369,20.7394741565422,11.519473,0,0,0,40,4449,9.76135,-89789.78515625,,,,,,,,,,,,,0,,,,0.0049,,,,,,10.0070658,,,,
,29402982.4,9.99420785,-85268.00390625,0.000377037127571438,7.3673997211484E-6,1,0.999253354069792,40.0298881530762,2.00050257400735,17.000000923872,0.00411859065040888,0.00163499157733706,0.25,7.63754518716106E-5,0.000377235199678711,7.92245894434833E-5,9.9800768,10.0083389,-85275.4375,-85260.5703125,58.3782708443139,20.7400605817627,11.139823,0,0,0,40,4449,9.7925,-85268.00390625,,,,,,,,,,,,,0,,,,-0.00245,,,,,,9.99420785,,,,
,29403075.315,10.006175,-80623.59375,0.000355602675142662,6.6513511854014E-6,1,0.999253354069792,40.0298881530762,2.00009265780656,17.000000923872,0.00388930471250146,0.001502415642611,0.25,6.85774787654968E-5,0.000355688965206568,7.12659476564604E-5,10.006175,10.006175,-80628.5703125,-80618.6171875,57.9819851850638,20.7446715506785,10.760172,0,0,0,40,4449,9.7772,-80623.59375,,,,,,,,,,,,,0,,,,-0.00245,,,,,,10.006175,,,,
,29403169.845,9.9824123,-75898.0859375,0.000333489491848722,5.12317580181691E-6,1,0.999253354069792,40.0298881530762,2.00051682974239,17.000000923872,0.00372401453562855,0.000980117263875512,0.25,2.64502528656495E-5,0.000333721813526588,2.89252781185539E-5,9.9824123,9.9824123,-75910.7734375,-75885.3984375,57.7068519462946,20.7377739274062,11.519473,0,0,0,40,4449,9.76035,-75898.0859375,,,,,,,,,,,,,0,,,,0.00245,,,,,,9.9824123,,,,
,29403262.4,10.0117378,-71273.1796875,0.000289837764356338,4.92901468669792E-6,1,0.999253354069792,40.0298881530762,2.00001885736359,17.000000923872,0.00319860145867656,0.00105090566429202,0.25,4.06005000286332E-5,0.000289799412409402,4.27760080281232E-5,10.0117378,10.0117378,-71283.2109375,-71263.1484375,57.5896076684099,20.7388863869998,11.519473,0,0,0,40,4449,9.7611,-71273.1796875,,,,,,,,,,,,,0,,,,0,,,,,,10.0117378,,,,
,29403357.03,10.0139141,-66543.59375,0.000275029693731522,4.81357515162785E-6,1,0.999253354069792,40.0298881530762,1.99983191465391,17.000000923872,0.00305820012843188,0.000860569086327938,0.25,2.6482129135369E-5,0.000274969498771683,2.85365090765838E-5,10.0139141,10.0139141,-66551.0703125,-66536.1171875,57.7209212596407,20.7462483439612,11.139823,0,0,0,40,4449,9.75765,-66543.59375,,,,,,,,,,,,,0,,,,0,,,,,,10.0139141,,,,
,29403451.54,9.9993,-61821.21875,0.000259085072069635,2.81772968120865E-6,1,0.999253354069792,40.0298881530762,2.00030810871873,17.0099996030331,0.00288586138823171,0.000779801356831931,0.25,2.22259005823794E-5,0.000258937743663808,2.41556346718155E-5,9.9993,9.9993,-61823.796875,-61818.640625,57.5473997283715,20.7419544148728,11.519473,0,0,0,40,4449,9.7622,-61821.21875,,,,,,,,,,,,,0,,,,0.0049,,,,,,9.9993,,,,
,29403545.4,9.99322705,-57128.92578125,0.000211895652972488,3.29708663862831E-6,1,0.999253354069792,40.0298881530762,2.00022769408421,17.000000923872,0.00238258858861098,0.000507143524010545,0.25,6.65368235802744E-6,0.00021176710270332,8.22718331934684E-6,9.9897633,9.9966908,-57136.55859375,-57121.29296875,57.8397287945638,20.745012118703,11.139823,0,0,0,40,4449,9.7719,-57128.92578125,,,,,,,,,,,,,0,,,,-0.00245,,,,,,9.99322705,,,,
,29403639.47,10.0167847,-52429.603515625,0.000191324707461166,3.50215655963386E-6,1,0.999253354069792,40.0298881530762,1.99980495576159,17.000000923872,0.00211508462575241,0.000650571287570988,0.25,2.30888666440168E-5,0.000190994068734288,2.44862584772E-5,10.0167847,10.0167847,-52434.65234375,-52424.5546875,57.8264411097369,20.7512761380679,11.139823,0,0,0,40,4449,9.7574,-52429.603515625,,,,,,,,,,,,,0,,,,-0.00245,,,,,,10.0167847,,,,
,29403733.63,9.9931698,-47722.28125,0.000161344221438168,2.5791641661861E-6,1,0.999253354069792,40.0298881530762,2.00012265369142,17.000000923872,0.00179499740063635,0.000482312614082663,0.25,1.36263994726544E-5,0.000161032505594375,1.47927274179976E-5,9.9931698,9.9931698,-47722.28125,-47722.28125,57.5880444113715,20.7462266910827,11.519473,0,0,0,40,4449,9.752,-47722.28125,,,,,,,,,,,,,0,,,,-0.0049,,,,,,9.9931698,,,,
,29403825.65,9.9873705,-43124.623046875,0.00013102701266455,2.85866325691738E-6,1,0.999253354069792,40.0298881530762,2.00018070146076,17.000000923872,0.00146052773192952,0.000372270998297584,0.25,9.37452907295078E-6,0.000130724558872461,1.03067325542989E-5,9.9873705,9.9873705,-43134.6796875,-43114.56640625,57.6302523514099,20.7394715008554,11.519473,0,0,0,40,4449,9.756,-43124.623046875,,,,,,,,,,,,,0,,,,0,,,,,,9.9873705,,,,
,29403916.735,9.9973011,-38572.3828125,0.000102370147454654,1.95330413456649E-6,1,0.999253354069792,40.0298881530762,2.00023435805106,17.000000923872,0.00111703622407749,0.000421604462117635,0.25,1.89329425056627E-5,0.000102003043170448,1.96179573874371E-5,9.9973011,9.9973011,-38577.6875,-38567.078125,57.8514532223523,20.7405508629084,10.760172,0,0,0,40,4449,9.7598,-38572.3828125,,,,,,,,,,,,,0,,,,0.0049,,,,,,9.9973011,,,,
,29404008.91,9.9916315,-33965.177734375,7.11186358915375E-5,1.65666428143404E-6,1,0.999253354069792,40.0298881530762,2.00046516656127,17.000000923872,0.000787144413774022,0.000229438899191322,0.25,7.5504258465753E-6,7.08699487534751E-5,8.02325661337717E-6,9.9916315,9.9916315,-33975.2265625,-33955.12890625,57.688092861833,20.7394294330173,11.519473,0,0,0,40,4449,9.7505,-33965.177734375,,,,,,,,,,,,,0,,,,-0.00245,,,,,,9.9916315,,,,
,29404102.21,9.9908972,-29302.607421875,4.74113584993908E-5,1.96349400530741E-6,1,0.999253354069792,40.0298881530762,2.00016783843897,17.000000923872,0.000505830984162381,0.000256449050211918,0.25,1.42295029147318E-5,4.71614244903702E-5,1.45023338524112E-5,9.9908972,9.9908972,-29307.73046875,-29297.484375,57.6286890943715,20.7459226383421,10.760172,0,0,0,40,4449,9.7484,-29302.607421875,,,,,,,,,,,,,0,,,,0,,,,,,9.9908972,,,,
,29404194.315,10.00172615,-24698.3701171875,1.47878453895439E-5,1.32342105067513E-6,1,0.999253354069792,40.0298881530762,2.00031068932677,17.000000923872,0.000142290543473565,0.000166009704111248,0.25,1.20757299847165E-5,1.46544202380333E-5,1.21266055273031E-5,10.0006819,10.0027704,-24705.98046875,-24690.759765625,57.6630807492176,20.7394691725881,11.139823,0,0,0,40,4449,9.75885,-24698.3701171875,,,,,,,,,,,,,0,,,,0.0049,,,,,,10.00172615,,,,
,29404285.625,10.0114393,-20135.595703125,-1.09481433314693E-5,7.24160426897345E-7,1,0.999253354069792,40.0298881530762,1.99995122599628,17.000000923872,-0.000144169588223859,9.42815172657253E-5,0.25,1.0328455635808E-5,-1.09664474412384E-5,1.0217313302089E-5,10.0114393,10.0114393,-20138.34765625,-20132.84375,57.5833546402561,20.7422657937251,11.519473,0,0,0,40,4449,9.7549,-20135.595703125,,,,,,,,,,,,,0,,,,0,,,,,,10.0114393,,,,
,29404377.17,9.9977331,-15560.84765625,-3.6928936042778E-5,9.44042633266327E-7,1,0.999253354069792,40.0298881530762,2.00018574322014,17.000000923872,-0.000430400331950112,6.6794534229257E-6,0.25,7.19164902834429E-6,-3.68009324047974E-5,6.94069388887707E-6,9.9977331,9.9977331,-15565.9326171875,-15555.7626953125,57.5247325013138,20.7415017696005,11.139823,0,0,0,40,4449,9.757,-15560.84765625,,,,,,,,,,,,,0,,,,0,,,,,,9.9977331,,,,
,29404469.585,9.9933577,-10940.7182617187,-6.55793375226103E-5,5.51813274977951E-7,1,0.999253354069792,40.0298881530762,2.00023648629538,17.000000923872,-0.000746301444663569,-8.72382909970765E-5,0.25,3.94730886246978E-6,-6.52722554432402E-5,3.56265701870478E-6,9.9933577,9.9933577,-10948.2802734375,-10933.15625,57.6161830380638,20.7403068731401,11.519473,0,0,0,40,4449,9.75795,-10940.7182617187,,,,,,,,,,,,,0,,,,-0.0049,,,,,,9.9933577,,,,
,29404561.845,9.9937754,-6329.74926757812,-9.1186909961053E-5,4.25915083106714E-7,1,0.999253354069792,40.0298881530762,2.00019819850807,17.0099996030331,-0.00103055268861253,-0.000159184397043671,0.25,2.08774628941937E-6,-9.07076591932833E-5,1.60021074404723E-6,9.9937754,9.9937754,-6339.56982421875,-6319.9287109375,57.6161830380638,20.7389147560265,11.139823,0,0,0,40,4449,9.7605,-6329.74926757812,,,,,,,,,,,,,0,,,,0,,,,,,9.9937754,,,,
,29404655.125,10.0004129,-1666.35052490234,-9.20879817623207E-5,3.31595666393115E-7,1,0.999253354069792,40.0298881530762,2.00012190570409,17.000000923872,-0.00103583345753948,-0.000186287243088133,0.25,-1.94760401332259E-7,-9.15647293514759E-5,-6.45291020201226E-7,10.0004129,10.0004129,-1671.41540527344,-1661.28564453125,57.76234757116,20.7441551979386,10.760172,0,0,0,40,4449,9.7686,-1666.35052490234,,,,,,,,,,,,,0,,,,0,,,,,,10.0004129,,,,
,29404745.295,9.9864626,2834.07385253906,9.93869677745256E-5,3.25497713254922E-7,1,0.999253354069792,40.0298881530762,2.00058118685296,17.000000923872,0.00112154801894955,0.000182575119791453,0.25,-1.44388268121582E-6,9.88369882485825E-5,-9.41004936023978E-7,9.9864626,9.9864626,2831.68334960938,2836.46435546875,57.4684552479292,20.7407230679469,11.139823,0,0,0,40,4449,9.7758,2834.07385253906,,,,,,,,,,,,,0,,,,0,,,,,,9.9864626,,,,
,29404838.95,10.010848,7518.88110351562,8.19661635440622E-5,3.62483487532465E-7,1,0.999253354069792,40.0298881530762,2.00041050502146,17.000000923872,0.000930736973444631,0.000119442761821652,0.25,-3.98657117690165E-6,8.15538934268783E-5,-3.53019863510124E-6,10.010848,10.010848,7511.27783203125,7526.484375,57.7967392260061,20.7446371836509,11.139823,0,0,0,40,4449,9.7657,7518.88110351562,,,,,,,,,,,,,0,,,,-0.00245,,,,,,10.010848,,,,
,29404930.835,9.9971523,12112.021484375,5.75192363751538E-5,6.9819658413237E-7,1,0.999253354069792,40.0298881530762,2.00024354555965,17.000000923872,0.000662062699932752,3.49638545918714E-5,0.25,-7.15802481076143E-6,5.72767345960483E-5,-6.79786552087963E-6,9.9971523,9.9971523,12104.578125,12119.46484375,57.8123717963907,20.7411686891147,10.760172,0,0,0,40,4449,9.76,12112.021484375,,,,,,,,,,,,,0,,,,0,,,,,,9.9971523,,,,
,29405022.915,10.0064259,16711.9990234375,3.15446591029365E-5,6.51578306756756E-7,1,0.999253354069792,40.0298881530762,2.00025467409865,17.000000923872,0.000365433723881895,6.99679330899877E-6,0.25,-5.01797040314617E-6,3.14324278033499E-5,-4.8068009473408E-6,10.0064259,10.0064259,16701.986328125,16722.01171875,57.5833546402561,20.7421068549806,11.139823,0,0,0,40,4449,9.7652,16711.9990234375,,,,,,,,,,,,,0,,,,-0.0049,,,,,,10.0064259,,,,
,29405116.4,10.0079126,21384.44140625,2.4939319484681E-6,2.01762546929718E-7,1,0.999253354069792,40.0298881530762,2.00008863050206,17.000000923872,6.18189777183465E-5,-0.000183247033885895,0.25,-1.67093613146243E-5,2.58882810762573E-6,-1.66258437489548E-5,10.0079126,10.0079126,21379.453125,21389.4296875,57.4473512779099,20.7455624421546,11.519473,0,0,0,40,4449,9.7625,21384.44140625,,,,,,,,,,,,,0,,,,0,,,,,,10.0079126,,,,
,29405208.515,10.0166702,25987.0810546875,-2.80236377993338E-5,1.94887367689657E-6,1,0.999253354069792,40.0298881530762,1.99986903212994,17.000000923872,-0.000286157242830485,-0.000222297234878299,0.25,-1.46957978242237E-5,-2.78265135200672E-5,-1.48267025125288E-5,10.0166702,10.0166702,25982.205078125,25991.95703125,57.3910740245253,20.7438587959358,10.760172,0,0,0,40,4449,9.74745,25987.0810546875,,,,,,,,,,,,,0,,,,0.0049,,,,,,10.0166702,,,,
,29405302.145,10.0068531,30670.27734375,-5.1727878372821E-5,2.14312924822165E-6,1,0.999253354069792,40.0298881530762,1.99989335106406,17.000000923872,-0.000537280725626489,-0.000361083400428295,0.25,-2.27298611600382E-5,-5.14126221979494E-5,-2.30107781606567E-5,10.0068531,10.0068531,30665.28125,30675.2734375,57.3613721407945,20.743123806925,11.519473,0,0,0,40,4449,9.7428,30670.27734375,,,,,,,,,,,,,0,,,,0.0049,,,,,,10.0068531,,,,
,29405393.445,9.9968615,35232.70703125,-7.84585389829661E-5,3.1691674270767E-6,1,0.999253354069792,40.0298881530762,2.00004035955572,17.000000923872,-0.000825973514951878,-0.000488611818103398,0.25,-2.91997762454234E-5,-7.80483909335399E-5,-2.96717041880166E-5,9.9968615,9.9968615,35227.6015625,35237.8125,57.2878990599868,20.7420656383092,11.139823,0,0,0,40,4449,9.7505,35232.70703125,,,,,,,,,,,,,0,,,,-0.00245,,,,,,9.9968615,,,,
,29405486.34,10.01605465,39875.18359375,-9.90600333205154E-5,3.70051686817751E-6,1,0.999253354069792,40.0298881530762,1.99993961789918,17.000000923872,-0.00104537144505229,-0.000605423019955953,0.25,-3.58102633749153E-5,-9.85926174153779E-5,-3.64424383718646E-5,10.014719,10.0173903,39870.21875,39880.1484375,57.4059249663907,20.7399796725127,11.139823,0,0,0,40,4449,9.74235,39875.18359375,,,,,,,,,,,,,0,,,,0,,,,,,10.01605465,,,,
,29405580.39,10.0103092,44575.89453125,-0.000130981566745143,7.22239356686187E-6,1,0.999253354069792,40.0298881530762,1.99975929240572,17.000000923872,-0.00139302815844274,-0.000743701486616422,0.25,-4.22743508165423E-5,-0.000130459351017986,-4.31582498213702E-5,10.0103092,10.0103092,44573.296875,44578.4921875,57.4106147375061,20.7400698138454,11.519473,0,0,0,40,4449,9.7393,44575.89453125,,,,,,,,,,,,,0,,,,0,,,,,,10.0103092,,,,
,29405670.995,9.9780369,49103.587890625,-0.000171030845046157,3.60239557772939E-6,1,0.999253354069792,40.0298881530762,1.999920399825,17.000000923872,-0.00186962616793546,-0.000695668541628359,0.25,-3.07607711691238E-5,-0.00017060417952121,-3.19839182689991E-5,9.9780369,9.9780369,49096.10546875,49111.0703125,57.3887291389676,20.7414188495863,10.760172,0,0,0,40,4449,9.7408,49103.587890625,,,,,,,,,,,,,0,,,,-0.00245,,,,,,9.9780369,,,,
,29405765.25,9.976552,53816.28125,-0.000191631736135342,5.13783612157144E-6,1,0.999253354069792,40.0298881530762,2.00006735287645,17.000000923872,-0.00206370374733018,-0.000958782088429684,0.25,-5.02825761436969E-5,-0.000191125271298193,-5.16689543153762E-5,9.976552,9.976552,53813.65625,53818.90625,57.3043132588907,20.7390450292732,10.760172,0,0,0,40,4449,9.7501,53816.28125,,,,,,,,,,,,,0,,,,0,,,,,,9.976552,,,,
,29405859.235,10.0263348,58514.4453125,-0.000237555050179415,3.66437697205907E-6,1,0.999253354069792,40.0298881530762,1.9997696363403,17.000000923872,-0.002591382226558,-0.00100953048209191,0.25,-4.64624691860374E-5,-0.000237152170275516,-4.82191181627627E-5,10.0263348,10.0263348,58512.01953125,58516.87109375,57.6091483813907,20.7444205920987,11.519473,0,0,0,40,4449,9.76385,58514.4453125,,,,,,,,,,,,,0,,,,0,,,,,,10.0263348,,,,
,29405952.845,9.9973059,63192.169921875,-0.000236055109688445,7.46970662160785E-6,1,0.999253354069792,40.0298881530762,2.0000547588493,17.000000923872,-0.00250898759872636,-0.00137827040139592,0.25,-7.92756074643693E-5,-0.00023551155994912,-8.10470817933365E-5,9.9973059,9.9973059,63179.515625,63204.82421875,57.5473997283715,20.7373302795251,11.139823,0,0,0,40,4449,9.76075,63192.169921875,,,,,,,,,,,,,0,,,,-0.00245,,,,,,9.9973059,,,,
,29406047.32,10.0002737,67912.53515625,-0.000276882247038434,5.94325508041202E-6,1,0.999253354069792,40.0298881530762,2.00013780079658,17.000000923872,-0.00299113081405882,-0.00135761957207776,0.25,-7.00442865223808E-5,-0.000276533487716503,-7.21395892874882E-5,10.0002737,10.0002737,67907.6015625,67917.46875,57.3308886285445,20.7402472193697,11.139823,0,0,0,40,4449,9.768,67912.53515625,,,,,,,,,,,,,0,,,,0,,,,,,10.0002737,,,,
,29406144.245,9.9980507,72757.2890625,-0.00032082764470229,6.9175458519201E-6,1,0.999253354069792,40.0298881530762,2.00042983539746,17.000000923872,-0.00344196145357055,-0.00171746522257596,0.25,-9.38490597466991E-5,-0.000320465309078168,-9.63072593473466E-5,9.9980507,9.9980507,72754.6015625,72759.9765625,57.728737544833,20.7330439041528,11.139823,0,0,0,40,4449,9.7863,72757.2890625,,,,,,,,,,,,,0,,,,0,,,,,,9.9980507,,,,
,29406239.47,10.0004215,77518.3671875,-0.000355853381015218,8.70160916510508E-6,1,0.999253354069792,40.0298881530762,2.00013257797778,17.000000923872,-0.00381348967391382,-0.00193445912188994,0.25,-0.000106681912044486,-0.000355574646025702,-0.000109427920934842,10.0004215,10.0004215,77513.1484375,77523.5859375,57.2034831799099,20.7398328302899,11.139823,0,0,0,40,4449,9.7794,77518.3671875,,,,,,,,,,,,,0,,,,0,,,,,,10.0004215,,,,
,29406334.465,10.0095177,82266.59765625,-0.000357258098216585,9.7398653849063E-6,1,0.999253354069792,40.0298881530762,2.00013657116564,17.000000923872,-0.00377020700017862,-0.00227506350992469,0.25,-0.000136452373830309,-0.000356902675123036,-0.000139270038366901,10.0095177,10.0095177,82261.703125,82271.4921875,57.3598088837561,20.7372225443264,11.139823,0,0,0,40,4449,9.78325,82266.59765625,,,,,,,,,,,,,0,,,,-0.0049,,,,,,10.0095177,,,,
,29406424.75,10.003767,86779.82421875,-0.000365940721872312,1.07128893381626E-5,1,0.999253354069792,40.0298881530762,2.00004226545439,17.000000923872,-0.00372554599178483,-0.00309522807968459,0.25,-0.000207219012377882,-0.000365225198433895,-0.00021025759089001,10.003767,10.003767,86769.7734375,86789.875,57.8584878790253,20.7389118263687,11.139823,0,0,0,40,4449,9.7816,86779.82421875,,,,,,,,,,,,,0,,,,0,,,,,,10.003767,,,,
,29406530.33,10.0092306,88917.78125,-0.000397324051288534,1.55081162377649E-5,1,0.999253354069792,40.0298881530762,2.00012549215284,17.0099996030331,-0.00417115440595268,-0.00266498485077316,0.25,-0.000163591515051681,-0.000397049498478495,-0.000166768649197083,10.0092306,10.0092306,88917.78125,88917.78125,57.5880444113715,20.731956919075,11.139823,0,0,0,40,4449,9.791,88917.78125,,,,,,,,,,,,,0,,,,0,,,,,,10.0092306,,,,
,29406618.62,9.998374,84504.33984375,-0.000395772764360771,6.51952929864125E-6,1,0.999253354069792,40.0298881530762,2.00039280202245,17.000000923872,-0.00430524459439281,-0.00181348862166698,0.25,-8.87601197810346E-5,-0.000395896595332043,-9.17690275965183E-5,9.998374,9.998374,84499.4296875,84509.25,57.6122748954676,20.7377352411658,11.519473,0,0,0,40,4449,9.7916,84504.33984375,,,,,,,,,,,,,0,,,,0,,,,,,9.998374,,,,
,29406714.11,10.0145359,79730.6484375,-0.00037136983080811,5.31230249975749E-6,1,0.999253354069792,40.0298881530762,1.99949440472657,17.000000923872,-0.00405893486806908,-0.00157611878935452,0.25,-7.22869190982251E-5,-0.000371429157612313,-7.50966017964273E-5,10.0145359,10.0145359,79725.8125,79735.484375,57.5247325013138,20.7444964984036,11.139823,0,0,0,40,4449,9.77925,79730.6484375,,,,,,,,,,,,,0,,,,0.00245,,,,,,10.0145359,,,,
,29406807.68,10.0068502,75054.55078125,-0.000302255043945828,8.60893509137484E-6,1,0.999253354069792,40.0298881530762,2.00011683898461,17.000000923872,-0.0031879177683265,-0.00192310324937354,0.25,-0.000115355322756227,-0.000301775014390191,-0.00011771116053106,10.0068502,10.0068502,75047.1640625,75061.9375,57.4278105649292,20.7408214992323,11.139823,0,0,0,40,4449,9.77135,75054.55078125,,,,,,,,,,,,,0,,,,0.00245,,,,,,10.0068502,,,,
,29406900.73,10.001462,70401.53515625,-0.00030819698867316,6.79666894762666E-6,1,0.999253354069792,40.0298881530762,1.99987515963484,17.000000923872,-0.00333590440873204,-0.00147704832496138,0.25,-7.49479704146893E-5,-0.000307898479185568,-7.72873051349772E-5,10.001462,10.001462,70388.8984375,70414.171875,57.3504293415253,20.742287666898,11.519473,0,0,0,40,4449,9.76835,70401.53515625,,,,,,,,,,,,,0,,,,-0.00245,,,,,,10.001462,,,,
,29406993.58,10.0108404,65763.30859375,-0.00026519582568139,6.92431203657268E-6,1,0.999253354069792,40.0298881530762,1.99941536571427,17.000000923872,-0.00289164784202418,-0.00114258266942268,0.25,-5.32019685925719E-5,-0.000264913890477087,-5.51942547496968E-5,10.0108404,10.0108404,65755.625,65770.9921875,57.5677220698715,20.7459041375087,11.139823,0,0,0,40,4449,9.75145,65763.30859375,,,,,,,,,,,,,0,,,,-0.00245,,,,,,10.0108404,,,,
,29407086.255,9.9933319,61130.29296875,-0.000235981893690825,7.74447938712274E-6,1,0.999253354069792,40.0298881530762,1.9999649199708,17.000000923872,-0.00249434965371132,-0.0014511475117398,0.25,-8.57588681044809E-5,-0.000235344934965746,-8.7515829532775E-5,9.9933319,9.9933319,61127.69140625,61132.89453125,57.5317671579869,20.7432438221655,11.519473,0,0,0,40,4449,9.7643,61130.29296875,,,,,,,,,,,,,0,,,,0.0049,,,,,,9.9933319,,,,
,29407178.24,9.9994717,56529.734375,-0.000213434853933281,8.56152304129948E-6,1,0.999253354069792,40.0298881530762,1.99982957620472,17.000000923872,-0.00228504146430085,-0.00114460839555103,0.25,-6.27738652375599E-5,-0.000212876136917835,-6.43336918206766E-5,9.998148,10.0007954,56525.01171875,56534.45703125,57.566158812833,20.7431401662222,11.519473,0,0,0,40,4449,9.7497,56529.734375,,,,,,,,,,,,,0,,,,0.00245,,,,,,9.9994717,,,,
,29407271.47,9.9982138,51869.734375,-0.000179336933877027,6.41341884538365E-6,1,0.999253354069792,40.0298881530762,1.99996135827899,17.000000923872,-0.0019279761639995,-0.000912920260424834,0.25,-4.84639747159478E-5,-0.000178818653235664,-4.97476368577359E-5,9.9982138,9.9982138,51867.421875,51872.046875,57.444224763833,20.7414894004421,10.760172,0,0,0,40,4449,9.7598,51869.734375,,,,,,,,,,,,,0,,,,0,,,,,,9.9982138,,,,
,29407365.18,9.99114035,47187.056640625,-0.000154387270689008,6.54176092336467E-6,1,0.999253354069792,40.0298881530762,2.00004815435987,17.000000923872,-0.00164637612524041,-0.00085598251055611,0.25,-4.79644047212258E-5,-0.000153824600866873,-4.90305006592379E-5,9.9896545,9.9926262,47184.20703125,47189.90625,57.6920010044292,20.7425781269424,11.139823,0,0,0,40,4449,9.7493,47187.056640625,,,,,,,,,,,,,0,,,,-0.00245,,,,,,9.99114035,,,,
,29407456.59,10.0019922,42618.947265625,-0.000118069291389193,1.08091600189717E-5,1,0.999253354069792,40.0298881530762,2.00010365374392,17.000000923872,-0.00122047726912814,-0.000865828642688168,0.25,-5.5423600785527E-5,-0.000117450951856475,-5.6175064730704E-5,10.0019922,10.0019922,42611.62890625,42626.265625,57.4809613042369,20.7406340646209,10.760172,0,0,0,40,4449,9.7518,42618.947265625,,,,,,,,,,,,,0,,,,-0.0049,,,,,,10.0019922,,,,
,29407549.305,9.9909558,37986.330078125,-8.99961741080232E-5,8.55408685355729E-6,1,0.999253354069792,40.0298881530762,2.00002515153897,17.000000923872,-0.000910952527573891,-0.000764713872063731,0.25,-5.15695922920522E-5,-8.94204844922152E-5,-5.20875355691226E-5,9.9903135,9.9915981,37978.7578125,37993.90234375,57.5278590153907,20.7402112287635,11.139823,0,0,0,40,4449,9.75215,37986.330078125,,,,,,,,,,,,,0,,,,0,,,,,,9.9909558,,,,
,29407639.71,10.0048637,33466.8515625,-6.77630025075849E-5,4.22523261083498E-6,1,0.999253354069792,40.0298881530762,1.9999227739454,17.000000923872,-0.000720377643971547,-0.000382089785213004,0.25,-2.16943060298824E-5,-6.74222648597003E-5,-2.21022609215881E-5,10.0048637,10.0048637,33462.06640625,33471.63671875,57.6740235484869,20.7416852455138,11.519473,0,0,0,40,4449,9.7547,33466.8515625,,,,,,,,,,,,,0,,,,-0.00245,,,,,,10.0048637,,,,
,29407732.5,9.997818,28829.3837890625,-3.32711712332728E-5,3.56128442942091E-6,1,0.999253354069792,40.0298881530762,2.00013436283826,17.000000923872,-0.000321825254476841,-0.000364470961133525,0.25,-2.63502829475513E-5,-3.29846124824166E-5,-2.64864429413457E-5,9.997818,9.997818,28819.470703125,28839.296875,57.6708970344099,20.7449238136966,11.519473,0,0,0,40,4449,9.7513,28829.3837890625,,,,,,,,,,,,,0,,,,0,,,,,,9.997818,,,,
,29407825.15,9.9977655,24198.876953125,-1.38561507182453E-5,1.41478790166777E-6,1,0.999253354069792,40.0298881530762,2.0000746519699,17.000000923872,-0.000123148232225,-0.000212199799293976,0.25,-1.6343765104421E-5,-1.36982920978261E-5,-1.63714603629695E-5,9.9977655,9.9977655,24191.2421875,24206.51171875,57.5247325013138,20.7429625592781,11.519473,0,0,0,40,4449,9.7578,24198.876953125,,,,,,,,,,,,,0,,,,-0.0049,,,,,,9.9977655,,,,
,29407915.11,9.9949245,19701.3984375,1.0348179930703E-5,6.81799917505198E-7,1,0.999253354069792,40.0298881530762,1.99986762789398,17.000000923872,0.000142701637546209,-0.000125129926583543,0.25,-1.29598243293689E-5,1.03845224398716E-5,-1.28411441513816E-5,9.9949245,9.9949245,19693.650390625,19709.146484375,57.7334273159484,20.745661733623,11.139823,0,0,0,40,4449,9.745,19701.3984375,,,,,,,,,,,,,0,,,,0,,,,,,9.9949245,,,,
,29408005.875,9.9968386,15166.4248046875,3.87983669617837E-5,4.65060724292814E-7,1,0.999253354069792,40.0298881530762,2.00013827375394,17.000000923872,0.000456949769694354,-3.38317887367786E-5,0.25,-9.93551411775188E-6,3.86762507822757E-5,-9.66159488978602E-6,9.9968386,9.9968386,15161.43359375,15171.416015625,57.7803250271023,20.7435613311485,11.139823,0,0,0,40,4449,9.7495,15166.4248046875,,,,,,,,,,,,,0,,,,0,,,,,,9.9968386,,,,
,29408097.875,9.9949284,10566.5927734375,6.35529557163525E-5,6.57074583238213E-7,1,0.999253354069792,40.0298881530762,2.00004058613375,17.0099996030331,0.000720076073257896,0.000101768941154889,0.25,-2.29248478022466E-6,6.32448102819794E-5,-1.92909159213666E-6,9.9949284,9.9949284,10554.3056640625,10578.8798828125,57.5497446139292,20.7427095348873,11.519473,0,0,0,40,4449,9.76575,10566.5927734375,,,,,,,,,,,,,0,,,,0,,,,,,9.9949284,,,,
,29408191.04,9.9836216,5911.05102539063,9.1005926431316E-5,5.25269354247857E-7,1,0.999253354069792,40.0298881530762,2.00056237823089,17.000000923872,0.00102335252171601,0.000188683463685855,0.25,5.65642086398461E-7,9.0511096733185E-5,1.03518513559968E-6,9.9836216,9.9836216,5906.1123046875,5915.98974609375,57.6865296047946,20.7390980477604,11.139823,0,0,0,40,4449,9.7758,5911.05102539063,,,,,,,,,,,,,0,,,,0.00245,,,,,,9.9836216,,,,
,29408284.055,9.9991312,1260.24267578125,9.38516254935979E-5,3.35326085272103E-7,1,0.999253354069792,40.0298881530762,2.00024734030975,17.000000923872,0.00105733862496319,0.000180707692504624,0.25,-6.12791958212974E-7,9.33203605424374E-5,-1.512613249912E-7,9.9991312,9.9991312,1247.80908203125,1272.67626953125,57.7498415148523,20.7427669749743,11.519473,0,0,0,40,4449,9.78005,1260.24267578125,,,,,,,,,,,,,0,,,,0.0049,,,,,,9.9991312,,,,
,29408310.355,10.002142,-0.418653771281242,3.95412237863958E-5,3.35906230113759E-7,1,0.999253354069792,40.0298881530762,2.00050481777167,17.000000923872,0.000445715918963602,7.49534289835315E-5,0.25,-3.6125439798201E-7,3.93158172375034E-5,-1.6859302415284E-7,10.002142,10.002142,-0.441489428281784,-0.395818114280701,57.4457880208715,20.738851561862,11.519473,0,0,0,40,4417,9.7755,-0.418653771281242,,,,,,,,,,,,,0,,,,0,,,,,,10.002142,,,,