File: data/looselyPackedNP/sc-ios-7/ppms/rawdata/ES_S17_HYST_100K.DAT
[Header]
; VSM Data File (default extension .dat)
; Copyright (c) 2003-2013, Quantum Design, Inc. All rights reserved.
TITLE,
FILEOPENTIME,29264349.89,12/06/2018,1:00 am
BYAPP,VSM,2.0,2.0
INFO,PPMS VSM Option Release 1.4.10 Build 1,APPNAME
INFO,Quantum Design Linear Motor Servo Controller,MOTOR_MODULE_NAME
INFO,3101-100 M1,MOTOR_HW_VERSION
INFO,MMC1014,MOTOR_SERIAL_NUMBER
INFO,SRV No X-over 01.03.11,MOTOR_SOFTWARE_VERSION
INFO,Quantum Design VSM Detection Module,VSM_MODULE_NAME
INFO,3101-150 F0,VSM_HW_VERSION
INFO,VSM707,VSM_SERIAL_NUMBER
INFO,VSM No X-over 01.02.05 May 20 2008 13:51:47,VSM_SOFTWARE_VERSION
INFO,704,PREAMP_SERIAL_NUMBER
INFO,822,COIL_SERIAL_NUMBER
INFO,0,MOMENT_UNITS
INFO,Iron Oxide Spheres,SAMPLE_MATERIAL
INFO,7 nm diameter, collaboration Mainz,SAMPLE_COMMENT
INFO,,SAMPLE_MASS
INFO,,SAMPLE_VOLUME
INFO,,SAMPLE_MOLECULAR_WEIGHT
INFO,,SAMPLE_SIZE
INFO,,SAMPLE_SHAPE
DATATYPE,COMMENT,1
DATATYPE,TIME,2
STARTUPAXIS,X,2
STARTUPAXIS,Y1,5
[Data]
Comment,Time Stamp (sec),Temperature (K),Magnetic Field (Oe),Moment (emu),M. Std. Err. (emu),Transport Action,Averaging Time (sec),Frequency (Hz),Peak Amplitude (mm),Center Position (mm),Coil Signal' (mV),Coil Signal" (mV),Range (mV),M. Quad. Signal (emu),M. Raw' (emu),M. Raw" (emu),Min. Temperature (K),Max. Temperature (K),Min. Field (Oe),Max. Field (Oe),Mass (grams),Motor Lag (deg),Pressure (Torr),VSM Status (code),Motor Status (code),Measure Status (code),Measure Count,PPMS Status (code),System Temp. (K),System Field (Oe),Sample Position (deg),Bridge 1 Resistance (ohms),Bridge 1 Excitation (에),Bridge 2 Resistance (ohms),Bridge 2 Excitation (에),Bridge 3 Resistance (ohms),Bridge 3 Excitation (에),Bridge 4 Resistance (ohms),Bridge 4 Excitation (에),Signal 1 Vin (V),Signal 2 Vin (V),Digital Inputs (code),Drive 1 Iout (mA),Drive 1 Ipower (W),Drive 2 Iout (mA),Drive 2 Ipower (W),Pressure (),Map 20 (),Map 21 (),Map 22 (),Map 23 (),Map 24 (),Map 25 (),Map 26 (),Map 27 (),Map 28 (),Map 29 ()
,29264365.38,100.1819,-0.258804142475128,,,2,,,,16.8000004646182,,,,,,,100.1819,100.1819,-0.258804142475128,-0.258804142475128,,,19.871798,,,,-99999999,4369,100.0093,-0.258804142475128,,,,,,,,,,,,,,,,,,,,,,,100.1819,,,,
,29264539.265,100.0754166,4628.6962890625,9.0095059360303E-5,3.75775990491274E-7,1,0.999253354069792,40.0298881530762,1.99000158977649,16.7900007218122,0.00102120593825977,0.000176446066771071,0.25,-2.60406376027589E-7,9.06026547232298E-5,1.80631821982331E-8,100.0754166,100.0754166,4621.3515625,4636.041015625,56.8877052581406,20.7175030646484,19.492144,0,0,0,40,4449,99.8606,4628.6962890625,,,,,,,,,,,,,0,,,,0,,,,,,100.0754166,,,,
,29264641.12,100.0323563,9719.85302734375,6.98192581074869E-5,5.91542469653018E-7,1,0.999253354069792,40.0298881530762,1.990712171162,16.7900007218122,0.000793503392888944,0.000126297536865137,0.25,-1.1261513861004E-6,7.02160064012235E-5,-9.16580860286004E-7,100.0323563,100.0323563,9707.2333984375,9732.47265625,56.9986965078714,20.7173317872164,19.112494,0,0,0,40,4449,99.84435,9719.85302734375,,,,,,,,,,,,,0,,,,-0.00245,,,,,,100.0323563,,,,
,29264745.36,100.0266418,14929.0107421875,5.09363661098807E-5,1.22475116727123E-6,1,0.999253354069792,40.0298881530762,1.98970207963912,16.7900007218122,0.000591381403962669,1.94828473041266E-5,0.25,-7.2309544312975E-6,5.12459213500379E-5,-7.11512321993295E-6,100.0266418,100.0266418,14919.0087890625,14939.0126953125,57.4606389627369,20.7108064459499,19.871798,0,0,0,40,4449,99.84615,14929.0107421875,,,,,,,,,,,,,0,,,,-0.0049,,,,,,100.0266418,,,,
,29264846.18,100.0119705,19969.005859375,6.79741199109776E-6,8.55468684419171E-7,1,0.999253354069792,40.0298881530762,1.990716228105,16.7900007218122,8.2579325342956E-5,-1.80075732956843E-5,0.25,-2.78328083588724E-6,6.844320048359E-6,-2.77822210539612E-6,100.0119705,100.0119705,19956.654296875,19981.357421875,57.2550706621791,20.7222177899403,19.112494,0,0,0,40,4449,99.83675,19969.005859375,,,,,,,,,,,,,0,,,,-0.00245,,,,,,100.0119705,,,,
,29264946.555,100.007843,24983.849609375,-8.23151718395242E-6,8.32919565081509E-7,1,0.999253354069792,40.0298881530762,1.99027863680096,16.7900007218122,-8.23440658480265E-5,-7.85834665119253E-5,0.25,-5.489061041966E-6,-8.26140546485222E-6,-5.54512936309605E-6,100.007843,100.007843,24968.775390625,24998.923828125,57.2566339192176,20.7296621535829,19.492144,0,0,0,40,4449,99.8316,24983.849609375,,,,,,,,,,,,,0,,,,0,,,,,,100.007843,,,,
,29265047.17,100.0089645,30014.2783203125,-2.06283511046742E-5,1.59513082640511E-6,1,0.999253354069792,40.0298881530762,1.99019855723907,16.7900007218122,-0.00023291234816441,-4.57360946352049E-5,0.25,-4.12675844006749E-7,-2.07439808729279E-5,-4.77311072417392E-7,100.0089645,100.0089645,29996.796875,30031.759765625,57.4113963660253,20.7318410067093,19.492144,0,0,0,40,4449,99.82445,30014.2783203125,,,,,,,,,,,,,0,,,,0,,,,,,100.0089645,,,,
,29265150.57,100.0033951,35181.53515625,-4.25084374490476E-5,1.53679457247954E-6,1,0.999253354069792,40.0298881530762,1.99069181494612,16.7900007218122,-0.000477230358647821,-0.000110471141345812,0.25,-2.28067977983334E-6,-4.27428259129885E-5,-2.42113645070083E-6,100.0033951,100.0033951,35169.0625,35194.0078125,57.4145228801022,20.7232888264892,19.492144,0,0,0,40,4449,99.8245,35181.53515625,,,,,,,,,,,,,0,,,,-0.00245,,,,,,100.0033951,,,,
,29265250.525,100.0005798,40179.16015625,-6.16315033908902E-5,2.09455958792164E-6,1,0.999253354069792,40.0298881530762,1.99057687837287,16.7900007218122,-0.000685088775105104,-0.000198875943255847,0.25,-6.72401319538708E-6,-6.19617583216404E-5,-6.94588493704771E-6,100.0005798,100.0005798,40171.60546875,40186.71484375,57.5325487865061,20.7303975757808,19.492144,0,0,0,40,4449,99.82365,40179.16015625,,,,,,,,,,,,,0,,,,0,,,,,,100.0005798,,,,
,29265347.85,100.0101318,45044.482421875,-0.000114939671722021,2.39459552082284E-6,1,0.999253354069792,40.0298881530762,1.99029581998837,16.7900007218122,-0.00130887076801159,-0.000192192292764428,0.25,3.223843889015E-6,-0.000115603443328215,2.90192194572499E-6,100.0096359,100.0106277,45034.6953125,45054.26953125,57.3574639981984,20.7253745700883,19.871798,0,0,0,40,4449,99.8205,45044.482421875,,,,,,,,,,,,,0,,,,-0.00245,,,,,,100.0101318,,,,
,29265445.6,100.0110168,49927.041015625,-0.000173099300077407,2.51482299632305E-6,1,0.999253354069792,40.0298881530762,1.99076071511164,16.7900007218122,-0.00192800325952339,-0.000537886158429243,0.25,-1.70619931578073E-5,-0.000174035820243551,-1.76683723758548E-5,100.0110168,100.0110168,49922.05859375,49932.0234375,57.5083183024099,20.7273275848584,19.492144,0,0,0,40,4449,99.8076,49927.041015625,,,,,,,,,,,,,0,,,,0,,,,,,100.0110168,,,,
,29265543.485,100.0072098,54821.884765625,-0.000185196694394122,2.93390231849164E-6,1,0.999253354069792,40.0298881530762,1.98939323150258,16.7900007218122,-0.0020687849395561,-0.000533125005436835,0.25,-1.45518558836824E-5,-0.000186211451088769,-1.51759270897138E-5,100.0072098,100.0072098,54804.50390625,54839.265625,57.5020652742561,20.7362038179966,19.871798,0,0,0,40,4449,99.807,54821.884765625,,,,,,,,,,,,,0,,,,0,,,,,,100.0072098,,,,
,29265641.025,100.0060043,59696.923828125,-0.000209821596536522,2.08398922887296E-6,1,0.999253354069792,40.0298881530762,1.99023874673371,16.7900007218122,-0.00233325284141328,-0.000670256304245236,0.25,-2.2314610341081E-5,-0.00021095646698214,-2.3050975678482E-5,100.0060043,100.0060043,59687.1875,59706.66015625,57.3355783996599,20.7326195060973,19.871798,0,0,0,40,4449,99.80055,59696.923828125,,,,,,,,,,,,,0,,,,0,,,,,,100.0060043,,,,
,29265737.235,100.0063324,64507.498046875,-0.000231267325599458,3.46284501338069E-6,1,0.999253354069792,40.0298881530762,1.99007756665357,16.7900007218122,-0.00260480751889358,-0.000549303801397492,0.25,-7.88390640884271E-6,-0.000232568754605415,-8.59550011905296E-6,100.0063324,100.0063324,64495.078125,64519.91796875,57.5364569291022,20.7395744055691,20.251448,0,0,0,40,4449,99.7971,64507.498046875,,,,,,,,,,,,,0,,,,0,,,,,,100.0063324,,,,
,29265834.125,100.0004196,69347.65625,-0.000213089804781363,3.85457471841144E-6,1,0.999253354069792,40.0298881530762,1.99057258560065,16.7900007218122,-0.00240124551266897,-0.000502931661564015,0.25,-6.97538872211866E-6,-0.000214291725083743,-7.62519376499412E-6,100.0004196,100.0004196,69342.59375,69352.71875,57.4653287338522,20.7316899037566,20.251448,0,0,0,40,4449,99.7968,69347.65625,,,,,,,,,,,,,0,,,,0,,,,,,100.0004196,,,,
,29265930.455,100.004364,74160.19921875,-0.000263718409471474,4.67063113046296E-6,1,0.999253354069792,40.0298881530762,1.99043006601502,16.7900007218122,-0.00298422876211875,-0.000550349160429955,0.25,-2.2814996370791E-6,-0.000265226272276172,-3.04405461480866E-6,100.004364,100.004364,74145.1953125,74175.203125,57.7263926592753,20.7264824926892,19.871798,0,0,0,40,4449,99.79565,74160.19921875,,,,,,,,,,,,,0,,,,0,,,,,,100.004364,,,,
,29266030.29,100.0143127,79153.19921875,-0.000410191964928966,6.03203400254357E-6,1,0.999253354069792,40.0298881530762,1.98964938478652,16.7900007218122,-0.0046208148221485,-0.000965146970508967,0.25,-1.32168060610807E-5,-0.000412513391387766,-1.44503408298611E-5,100.0143127,100.0143127,79143.171875,79163.2265625,57.3191642007561,20.7396219378051,19.871798,0,0,0,40,4449,99.7795,79153.19921875,,,,,,,,,,,,,0,,,,0,,,,,,100.0143127,,,,
,29266128.735,100.0045547,84074.171875,-0.000335553880363548,3.1177360489179E-6,1,0.999253354069792,40.0298881530762,1.99024714924049,16.7900007218122,-0.0037536450917643,-0.000946452054530263,0.25,-2.46453232421562E-5,-0.000337417270244641,-2.57272405389696E-5,100.0045547,100.0045547,84056.6015625,84091.7421875,57.5169162161215,20.7352360241966,20.251448,0,0,0,40,4449,99.78615,84074.171875,,,,,,,,,,,,,0,,,,0,,,,,,100.0045547,,,,
,29266224.095,100.0104446,88839.625,-0.000433396403478811,5.71702846808597E-6,1,0.999253354069792,40.0298881530762,1.98936828257224,16.7900007218122,-0.00486465824270729,-0.00111642277936714,0.25,-2.25268374990114E-5,-0.000435832952441021,-2.38624770582154E-5,100.0104446,100.0104446,88824.4296875,88854.8203125,57.3684067974676,20.7300092311078,20.251448,0,0,0,40,4449,99.77645,88839.625,,,,,,,,,,,,,0,,,,0,,,,,,100.0104446,,,,
,29266341.695,100.0043945,86656.13671875,-0.000377573036744248,4.05646028867686E-6,1,0.999253354069792,40.0298881530762,1.99041487990415,16.7900007218122,-0.00424634936692849,-0.000937948326745353,0.25,-1.65196599599033E-5,-0.000379702919758012,-1.76686793254021E-5,100.0043945,100.0043945,86648.828125,86663.4453125,57.291807202583,20.7294382071691,20.251448,0,0,0,40,4449,99.77745,86656.13671875,,,,,,,,,,,,,0,,,,0,,,,,,100.0043945,,,,
,29266436.83,100.0036926,81900.33203125,-0.000334920243422705,3.19153222334884E-6,1,0.999253354069792,40.0298881530762,1.99035893356274,16.7900007218122,-0.00375193115298563,-0.000915132752724846,0.25,-2.19857174163345E-5,-0.000336785968999153,-2.30535707954915E-5,100.0036926,100.0036926,81890.3046875,81910.359375,57.5348936720638,20.7352745592961,19.871798,0,0,0,40,4449,99.7792,81900.33203125,,,,,,,,,,,,,0,,,,0.00245,,,,,,100.0036926,,,,
,29266532.99,99.9922409,77094.07421875,-0.000272570968144481,2.24949155999037E-6,1,0.999253354069792,40.0298881530762,1.99026011129185,16.7900007218122,-0.00305218611075619,-0.000751041737760702,0.25,-1.84446636820421E-5,-0.000274085360958382,-1.93220350478106E-5,99.9922409,99.9922409,77081.2578125,77106.890625,57.5294222724292,20.7332361740932,19.492144,0,0,0,40,4449,99.79085,77094.07421875,,,,,,,,,,,,,0,,,,0,,,,,,99.9922409,,,,
,29266629.29,99.9924088,72280.59375,-0.000294061814603606,1.898040644854E-6,1,0.999253354069792,40.0298881530762,1.99065471749465,16.7900007218122,-0.00329913068037878,-0.000777910112535284,0.25,-1.7026362027517E-5,-0.000295701019510606,-1.7962031462572E-5,99.9924088,99.9924088,72262.9453125,72298.2421875,57.5724118409869,20.7295221300664,19.871798,0,0,0,40,4449,99.7975,72280.59375,,,,,,,,,,,,,0,,,,-0.00245,,,,,,99.9924088,,,,
,29266724.905,99.9971695,67502.8046875,-0.000256286195804378,2.47190052353421E-6,1,0.999253354069792,40.0298881530762,1.99020514887689,16.7900007218122,-0.00289344926537113,-0.000570846021107695,0.25,-5.39336425595958E-6,-0.000257739506130371,-6.15963071925087E-6,99.9971695,99.9971695,67494.890625,67510.71875,57.6646440062561,20.7411432347842,19.871798,0,0,0,40,4449,99.7988,67502.8046875,,,,,,,,,,,,,0,,,,0,,,,,,99.9971695,,,,
,29266821.425,99.9935837,62674.51953125,-0.000204342465924518,2.82883783589395E-6,1,0.999253354069792,40.0298881530762,1.99020920253104,16.7900007218122,-0.00228695930969117,-0.000569278356863858,0.25,-1.43683416161548E-5,-0.000205470379266641,-1.50409017616034E-5,99.9935837,99.9935837,62662.1484375,62686.890625,57.637287008083,20.732359833639,20.251448,0,0,0,40,4449,99.8053,62674.51953125,,,,,,,,,,,,,0,,,,0,,,,,,99.9935837,,,,
,29266916.195,99.991066,57938.708984375,-0.000197335619371934,2.07095580129063E-6,1,0.999253354069792,40.0298881530762,1.9903559702569,16.7900007218122,-0.00220602354117256,-0.000564895240390447,0.25,-1.52046676161152E-5,-0.000198419135674131,-1.58654307091397E-5,99.991066,99.991066,57928.9765625,57948.44140625,57.6849663477561,20.7333529535599,19.871798,0,0,0,40,4449,99.813,57938.708984375,,,,,,,,,,,,,0,,,,-0.00245,,,,,,99.991066,,,,
,29267013.07,100.0031281,53096.056640625,-0.000183591861989541,2.3866087143463E-6,1,0.999253354069792,40.0298881530762,1.98994067014139,16.7900007218122,-0.00205848821468163,-0.000488212305293573,0.25,-1.08560552445819E-5,-0.000184607645158796,-1.14555885069251E-5,100.0031281,100.0031281,53081.203125,53110.91015625,57.4825245612753,20.7345340821708,20.251448,0,0,0,40,4449,99.8092,53096.056640625,,,,,,,,,,,,,0,,,,-0.0049,,,,,,100.0031281,,,,
,29267110.795,99.99471665,48213.05859375,-0.000127627633045373,1.78818308335888E-6,1,0.999253354069792,40.0298881530762,1.99047150682126,16.7900007218122,-0.00141935784602139,-0.000407775865837604,0.25,-1.35712979165955E-5,-0.000128314824490572,-1.40248242130916E-5,99.9946823,99.994751,48198.07421875,48228.04296875,57.8858448771984,20.7275115138724,19.871798,0,0,0,40,4449,99.8192,48213.05859375,,,,,,,,,,,,,0,,,,-0.00245,,,,,,99.99471665,,,,
,29267204.45,99.9915924,43532.62890625,-9.77366576971873E-5,1.91488991803574E-6,1,0.999253354069792,40.0298881530762,1.99006201678663,16.7900007218122,-0.00107829012998225,-0.000360173380773064,0.25,-1.46243248414164E-5,-9.82493797287485E-5,-1.49974436202035E-5,99.9913254,99.9918594,43520,43545.2578125,57.5192611016792,20.7293857992003,19.871798,0,0,0,40,4449,99.827,43532.62890625,,,,,,,,,,,,,0,,,,-0.00245,,,,,,99.9915924,,,,
,29267300.905,99.9918594,38713.005859375,-8.62499903772924E-5,2.34444997571008E-6,1,0.999253354069792,40.0298881530762,1.9896330179057,16.7900007218122,-0.000961314570669824,-0.000261073307416813,0.25,-7.89845204526754E-6,-8.67164383873985E-5,-8.20080599578307E-6,99.9918594,99.9918594,38707.921875,38718.08984375,57.6873112333138,20.7383578053093,19.871798,0,0,0,40,4449,99.8333,38713.005859375,,,,,,,,,,,,,0,,,,0.0049,,,,,,99.9918594,,,,
,29267391.385,99.9909286,34188.29296875,-6.8964720206943E-5,1.46063357669566E-6,1,0.999253354069792,40.0298881530762,1.99012497905354,16.7900007218122,-0.000767399133685031,-0.000216962026192888,0.25,-7.03474948011904E-6,-6.93348881642677E-5,-7.28174803486463E-6,99.9909286,99.9909286,34175.57421875,34201.01171875,57.7005989181407,20.7354060944267,20.251448,0,0,0,40,4449,99.842,34188.29296875,,,,,,,,,,,,,0,,,,-0.00245,,,,,,99.9909286,,,,
,29267486.845,99.9904099,29418.30078125,-3.08015497717924E-5,1.86083651117134E-6,1,0.999253354069792,40.0298881530762,1.99026853526957,16.7900007218122,-0.000333862103781206,-0.000147568468518856,0.25,-7.61236962046953E-6,-3.09530661574393E-5,-7.74855046269292E-6,99.9904099,99.9904099,29408.3984375,29428.203125,57.9624444720831,20.7362322311327,19.871798,0,0,0,40,4449,99.8495,29418.30078125,,,,,,,,,,,,,0,,,,-0.00245,,,,,,99.9904099,,,,
,29267582.305,99.9902725,24645.2783203125,-6.76247926018306E-6,1.0046681843736E-6,1,0.999253354069792,40.0298881530762,1.99023349145193,16.7900007218122,-6.60310513928462E-5,-7.37559769620698E-5,0.25,-5.3212531350889E-6,-6.78456991572608E-6,-5.37190936439681E-6,99.9902725,99.9902725,24630.21484375,24660.341796875,57.7990841115638,20.7260920335742,19.492144,0,0,0,40,4449,99.8581,24645.2783203125,,,,,,,,,,,,,0,,,,0.00245,,,,,,99.9902725,,,,
,29267677.06,99.9883957,19910.509765625,1.38321574651204E-5,7.68183738048555E-7,1,0.999253354069792,40.0298881530762,1.98977469126502,16.7900007218122,0.000165230469429378,-2.10579479027788E-5,0.25,-4.28931740346359E-6,1.39234190834074E-5,-4.27128474658417E-6,99.9881287,99.9886627,19898.126953125,19922.892578125,57.6263442088138,20.739428378475,19.871798,0,0,0,40,4449,99.869,19910.509765625,,,,,,,,,,,,,0,,,,-0.00245,,,,,,99.9883957,,,,
,29267771.89,99.9926376,15170.60546875,4.32790564530048E-5,9.36816609038451E-7,1,0.999253354069792,40.0298881530762,1.98950600601247,16.7900007218122,0.000492040649635524,7.56863582034865E-5,0.25,-9.23004697657811E-7,4.35260969065241E-5,-7.95238816884037E-7,99.9926376,99.9926376,15155.724609375,15185.486328125,57.6552644640253,20.7410294727188,19.492144,0,0,0,40,4449,99.87395,15170.60546875,,,,,,,,,,,,,0,,,,0,,,,,,99.9926376,,,,
,29267866.235,99.9971161,10455.7685546875,7.17651282566444E-5,6.1263719006837E-7,1,0.999253354069792,40.0298881530762,1.98965235383741,16.7900007218122,0.000814610454185841,0.000133139697183877,0.25,-8.58151058087653E-7,7.21721918398516E-5,-6.41350224169247E-7,99.9971161,99.9971161,10443.314453125,10468.22265625,57.9061672186984,20.7404099707914,20.251448,0,0,0,40,4449,99.87595,10455.7685546875,,,,,,,,,,,,,0,,,,0,,,,,,99.9971161,,,,
,29267960.925,99.9930496,5723.1357421875,8.69970843565704E-5,4.06679022410345E-7,1,0.999253354069792,40.0298881530762,1.98951652184219,16.7900007218122,0.000989227945176188,0.0001512067597293,0.25,-1.94032288208666E-6,8.74927852205845E-5,-1.68130806741195E-6,99.9930496,99.9930496,5710.69970703125,5735.57177734375,57.9702607572754,20.7424786449201,20.251448,0,0,0,40,4449,99.88145,5723.1357421875,,,,,,,,,,,,,0,,,,-0.00245,,,,,,99.9930496,,,,
,29268054.655,99.9898987,1037.12838745117,7.42095901630617E-5,3.81995867770449E-7,1,0.999253354069792,40.0298881530762,1.98972398633204,16.7900007218122,0.000841420733858034,0.000143118998068125,0.25,-4.08955612831356E-7,7.46281775394673E-5,-1.80138968517337E-7,99.9898987,99.9898987,1022.06927490234,1052.1875,57.8170615675061,20.7409135850907,19.871798,0,0,0,40,4449,99.8935,1037.12838745117,,,,,,,,,,,,,0,,,,0,,,,,,99.9898987,,,,
,29268147.705,99.9946976,-3608.54541015625,-9.13756996785422E-5,3.86191875824128E-7,1,0.999253354069792,40.0298881530762,1.98993670525626,16.7900007218122,-0.00103723334704764,-0.000170172309483646,0.25,1.03889771458123E-6,-9.1893036820547E-5,7.60753074073289E-7,99.9946976,99.9946976,-3621.0517578125,-3596.0390625,57.6904377473907,20.7443033061984,20.251448,0,0,0,40,4449,99.89665,-3608.54541015625,,,,,,,,,,,,,0,,,,0.0049,,,,,,99.9946976,,,,
,29268241.14,99.9994278,-8280.37548828125,-8.06824176958063E-5,6.36159920689729E-7,1,0.999253354069792,40.0298881530762,1.98993944832319,16.7900007218122,-0.000918802555679178,-0.000133500364240436,0.25,2.39551353111145E-6,-8.114427195707E-5,2.15935148645745E-6,99.9994278,99.9994278,-8290.3955078125,-8270.35546875,57.83347576641,20.7367678070122,20.251448,0,0,0,40,4449,99.8954,-8280.37548828125,,,,,,,,,,,,,0,,,,0,,,,,,99.9994278,,,,
,29268335.24,100.005661,-12983.3271484375,-5.37115662375748E-5,6.05098216137279E-7,1,0.999253354069792,40.0298881530762,1.99021977603826,16.7900007218122,-0.000610899846847489,-9.37095967300186E-5,0.25,1.16818532536612E-6,-5.40180557623251E-5,1.00938540514624E-6,100.005661,100.005661,-12993.3466796875,-12973.3076171875,57.6771500625638,20.7391250748849,20.251448,0,0,0,40,4449,99.88965,-12983.3271484375,,,,,,,,,,,,,0,,,,-0.00245,,,,,,100.005661,,,,
,29268428.795,100.00785445,-17658.7568359375,-3.5353684214205E-5,9.90923057385873E-7,1,0.999253354069792,40.0298881530762,1.99012610444777,16.7900007218122,-0.000408600871089558,-2.46092140609634E-5,0.25,4.04014445315219E-6,-3.55656805060734E-5,3.95465515318958E-6,100.007782,100.0079269,-17666.173828125,-17651.33984375,57.6966907755446,20.7397370331814,20.251448,0,0,0,40,4449,99.8796,-17658.7568359375,,,,,,,,,,,,,0,,,,0.00245,,,,,,100.00785445,,,,
,29268526.18,100.0087967,-22526.2333984375,-1.66269617126945E-6,9.19948544762441E-7,1,0.999253354069792,40.0298881530762,1.9900551109818,16.7900007218122,-2.47938580336573E-5,3.05890368857961E-5,0.25,2.99201938086057E-6,-1.68121111651158E-6,3.00387209367915E-6,100.0087967,100.0087967,-22538.80078125,-22513.666015625,57.8584878790253,20.7456876324633,20.251448,0,0,0,40,4449,99.871,-22526.2333984375,,,,,,,,,,,,,0,,,,0,,,,,,100.0087967,,,,
,29268623.3,100.0100861,-27381.111328125,2.23755520381993E-5,1.06163815110683E-6,1,0.999253354069792,40.0298881530762,1.99018127559007,16.7900007218122,0.00025597521241467,3.0606072636605E-5,0.25,-1.22971991447261E-6,2.25059690345702E-5,-1.16892584724376E-6,100.0100861,100.0100861,-27396.013671875,-27366.208984375,57.7959575974869,20.7464697332258,20.251448,0,0,0,40,4449,99.8622,-27381.111328125,,,,,,,,,,,,,0,,,,-0.00245,,,,,,100.0100861,,,,
,29268721.97,100.0112228,-32313.130859375,8.44062354233628E-5,1.32400117954009E-6,1,0.999253354069792,40.0298881530762,1.98961387515838,16.7900007218122,0.000944761963175612,0.000232609980655938,0.25,5.70796925460403E-6,8.48676556279207E-5,5.99439117632076E-6,100.0112228,100.0112228,-32317.95703125,-32308.3046875,57.7748536274677,20.7459651415972,20.251448,0,0,0,40,4449,99.8458,-32313.130859375,,,,,,,,,,,,,0,,,,0.0049,,,,,,100.0112228,,,,
,29268819.71,100.0098038,-37195.138671875,8.22977702057396E-5,1.58306771861957E-6,1,0.999253354069792,40.0298881530762,1.98964875336834,16.7900007218122,0.0009231614852691,0.000215558342589163,0.25,4.57408408354543E-6,8.27514235403911E-5,4.84621157991981E-6,100.0098038,100.0098038,-37200.3203125,-37189.95703125,57.9022590761023,20.747027354895,19.871798,0,0,0,40,4449,99.8393,-37195.138671875,,,,,,,,,,,,,0,,,,-0.0049,,,,,,100.0098038,,,,
,29268915.8,100.0083542,-41997.330078125,0.000100135721373153,1.77759750112249E-6,1,0.999253354069792,40.0298881530762,1.98964002911971,16.7900007218122,0.00113957351267291,0.000169399574209473,0.25,-2.6319390928309E-6,0.000100713003716302,-2.34929219789889E-6,100.0083542,100.0083542,-42007.0703125,-41987.58984375,57.7271742877946,20.7478952553281,19.871798,0,0,0,40,4449,99.83315,-41997.330078125,,,,,,,,,,,,,0,,,,-0.00245,,,,,,100.0083542,,,,
,29269013.385,100.0130005,-46875.052734375,0.000160691265259201,1.74122934614537E-6,1,0.999253354069792,40.0298881530762,1.98977690307434,16.7900007218122,0.00182819760720363,0.000275559940153183,0.25,-3.89404005970503E-6,0.000161617908325026,-3.44167946941395E-6,100.0130005,100.0130005,-46890.02734375,-46860.078125,57.6708970344099,20.7445687235231,20.251448,0,0,0,40,4449,99.81875,-46875.052734375,,,,,,,,,,,,,0,,,,-0.00245,,,,,,100.0130005,,,,
,29269111.735,100.0086937,-51789.638671875,0.000179204992804602,1.88697431927175E-6,1,0.999253354069792,40.0298881530762,1.98995093932277,16.7900007218122,0.00201507787984378,0.000443673404592769,0.25,7.6941526127053E-6,0.000180204527412293,8.26374434475983E-6,100.0085831,100.0088043,-51802.22265625,-51777.0546875,57.92492630316,20.7511694880616,19.871798,0,0,0,40,4449,99.80855,-51789.638671875,,,,,,,,,,,,,0,,,,0,,,,,,100.0086937,,,,
,29269209.255,100.006218,-56664.166015625,0.000201648512627131,1.96387212839954E-6,1,0.999253354069792,40.0298881530762,1.9897425393568,16.7900007218122,0.00227500965930864,0.000454931949568075,0.25,4.75477613299868E-6,0.000202786474535346,5.36952386855297E-6,100.006218,100.006218,-56669.30859375,-56659.0234375,57.820188081583,20.7496989584498,20.251448,0,0,0,40,4449,99.8008,-56664.166015625,,,,,,,,,,,,,0,,,,0,,,,,,100.006218,,,,
,29269307.245,100.0069275,-61561.248046875,0.000220951918017475,2.96204266225913E-6,1,0.999253354069792,40.0298881530762,1.98961925441501,16.7900007218122,0.00249029935327895,0.000511939112162445,0.25,6.4044627919595E-6,0.000222197317614885,7.08055208129967E-6,100.0069275,100.0069275,-61571.2265625,-61551.26953125,57.7943943404484,20.7471784485755,20.251448,0,0,0,40,4449,99.79355,-61561.248046875,,,,,,,,,,,,,0,,,,0.00245,,,,,,100.0069275,,,,
,29269405.065,100.0072708,-66448.8125,0.000317361638869969,3.13698737396523E-6,1,0.999253354069792,40.0298881530762,1.989679107811,16.7900007218122,0.00356161985395141,0.000823232249513584,0.25,1.69630382714232E-5,0.000319130967982749,1.79723892521191E-5,100.0072708,100.0072708,-66458.7734375,-66438.8515625,57.9546281868908,20.752793632625,19.871798,0,0,0,40,4449,99.7858,-66448.8125,,,,,,,,,,,,,0,,,,0,,,,,,100.0072708,,,,
,29269501.46,100.0079803,-71268.03125,0.000313614824416009,3.23632920795615E-6,1,0.999253354069792,40.0298881530762,1.98958288309082,16.7900007218122,0.00352111077218577,0.000803965213456425,0.25,1.59287513347658E-5,0.000315368535271485,1.69153911773737E-5,100.0079803,100.0079803,-71280.515625,-71255.546875,57.9616628435638,20.7521365591609,19.871798,0,0,0,40,4449,99.77815,-71268.03125,,,,,,,,,,,,,0,,,,-0.00245,,,,,,100.0079803,,,,
,29269598.265,100.0065918,-76105.53515625,0.000322530848640084,3.56848317130982E-6,1,0.999253354069792,40.0298881530762,1.98967200778343,16.7900007218122,0.00360343388036046,0.000929265654296214,0.25,2.54267115058182E-5,0.00032431174343468,2.64871359289156E-5,100.0065918,100.0065918,-76112.9765625,-76098.09375,57.8123717963907,20.7508685852889,20.251448,0,0,0,40,4449,99.7715,-76105.53515625,,,,,,,,,,,,,0,,,,-0.00245,,,,,,100.0065918,,,,
,29269697.36,100.0105972,-81057.75390625,0.000358004185174381,3.61051927314457E-6,1,0.999253354069792,40.0298881530762,1.98974268359034,16.7900007218122,0.00403322873240824,0.000841731422123348,0.25,1.14793030893794E-5,0.000360031562440952,1.2553085876325E-5,100.0105972,100.0105972,-81069.96875,-81045.5390625,57.9952728698907,20.7429652904381,19.871798,0,0,0,40,4449,99.76085,-81057.75390625,,,,,,,,,,,,,0,,,,0,,,,,,100.0105972,,,,
,29269793.375,100.0078888,-85857.01953125,0.000427404137713823,2.87165488987672E-6,1,0.999253354069792,40.0298881530762,1.99016526764143,16.7900007218122,0.00483118282082355,0.000919129216854498,0.25,6.1250649094986E-6,0.000429849423892416,7.35505604340615E-6,100.0078888,100.0078888,-85871.9453125,-85842.09375,57.8491083367946,20.7449139360291,19.871798,0,0,0,40,4449,99.75605,-85857.01953125,,,,,,,,,,,,,0,,,,0,,,,,,100.0078888,,,,
,29269907.03,100.0045776,-89716.203125,0.000418047275543895,2.94894848121129E-6,1,0.999253354069792,40.0298881530762,1.98955302206411,16.7900007218122,0.00468586566318276,0.00111647576440538,0.25,2.52163731062069E-5,0.000420388382327622,2.6523767629483E-5,100.0045776,100.0045776,-89728.4453125,-89703.9609375,57.7834515411792,20.755893190877,20.631098,0,0,0,40,4449,99.7527,-89716.203125,,,,,,,,,,,,,0,,,,0,,,,,,100.0045776,,,,
,29269999.07,100.002655,-85120.8359375,0.000350033587667646,2.77610123497093E-6,1,0.999253354069792,40.0298881530762,1.98955272006824,16.7900007218122,0.003918354282541,0.000963980817998468,0.25,2.36808860354621E-5,0.000351983535716101,2.47968785728401E-5,100.002655,100.002655,-85130.9296875,-85110.7421875,57.9303977027946,20.7432053373382,20.251448,0,0,0,40,4449,99.75005,-85120.8359375,,,,,,,,,,,,,0,,,,-0.0049,,,,,,100.002655,,,,
,29270096.585,100.0017548,-80245.8828125,0.000373469992197913,2.89037949803285E-6,1,0.999253354069792,40.0298881530762,1.9896794236267,16.7900007218122,0.00419869627826955,0.000927272785731338,0.25,1.63170530345593E-5,0.00037557212819556,1.74636608823021E-5,100.0017548,100.0017548,-80263.40625,-80228.359375,57.9882382132177,20.7490293038529,19.871798,0,0,0,40,4449,99.7472,-80245.8828125,,,,,,,,,,,,,0,,,,-0.00245,,,,,,100.0017548,,,,
,29270192.53,99.9952011,-75450.6640625,0.000375088222375305,2.5528094802776E-6,1,0.999253354069792,40.0298881530762,1.99003823569715,16.7900007218122,0.00424612055807872,0.00076879778530077,0.25,2.02656388556836E-6,0.000377236959724923,3.10281669002873E-6,99.9952011,99.9952011,-75465.546875,-75435.78125,57.9139835038908,20.7448990777585,20.631098,0,0,0,40,4449,99.75645,-75450.6640625,,,,,,,,,,,,,0,,,,0.00245,,,,,,99.9952011,,,,
,29270289.845,99.99575425,-70588.9296875,0.000316256154668302,2.43734351853794E-6,1,0.999253354069792,40.0298881530762,1.98987377657274,16.7900007218122,0.00351136216658484,0.00103816179570978,0.25,3.6124619004456E-5,0.000317966818315476,3.7235799447039E-5,99.9955597,99.9959488,-70598.890625,-70578.96875,57.8756837064484,20.7489867520022,20.251448,0,0,0,40,4449,99.7577,-70588.9296875,,,,,,,,,,,,,0,,,,0,,,,,,99.99575425,,,,
,29270386.615,99.9941254,-65752.02734375,0.000283393619996289,2.50160724633474E-6,1,0.999253354069792,40.0298881530762,1.99006628700332,16.7900007218122,0.00319427301157686,0.000659616777270239,0.25,8.47095164866067E-6,0.000284992334496622,9.33513606042552E-6,99.9941254,99.9941254,-65766.9140625,-65737.140625,57.7545312859677,20.739143212481,20.631098,0,0,0,40,4449,99.7623,-65752.02734375,,,,,,,,,,,,,0,,,,0,,,,,,99.9941254,,,,
,29270484.26,99.9946365,-60871.931640625,0.000234524399097952,2.37227844353158E-6,1,0.999253354069792,40.0298881530762,1.98983588468792,16.7900007218122,0.0026508734694597,0.000501679032369513,0.25,3.11070642214857E-6,0.000235856595612467,3.8082278438141E-6,99.9946365,99.9946365,-60879.23828125,-60864.625,57.9343058453907,20.7451569225993,20.251448,0,0,0,40,4449,99.7636,-60871.931640625,,,,,,,,,,,,,0,,,,0,,,,,,99.9946365,,,,
,29270582.075,99.9940186,-55984.734375,0.000209718374431719,1.71641909164422E-6,1,0.999253354069792,40.0298881530762,1.99011740311858,16.7900007218122,0.00235475434377063,0.00053998830343364,0.25,1.0836531489061E-5,0.000210884347947607,1.15103849508023E-5,99.9940186,99.9940186,-55997.30859375,-55972.16015625,57.7357722015061,20.7415273810997,20.251448,0,0,0,40,4449,99.7727,-55984.734375,,,,,,,,,,,,,0,,,,-0.00245,,,,,,99.9940186,,,,
,29270677.03,99.9945526,-51237.78515625,0.000168686657108662,2.15100734247578E-6,1,0.999253354069792,40.0298881530762,1.9898243125111,16.7900007218122,0.00190114377321531,0.000392217198822669,0.25,5.00086504880205E-6,0.000169633843185597,5.5249010143288E-6,99.9945526,99.9945526,-51245.59375,-51229.9765625,57.8209697101023,20.7407977995948,20.251448,0,0,0,40,4449,99.7734,-51237.78515625,,,,,,,,,,,,,0,,,,0,,,,,,99.9945526,,,,
,29270773.72,99.9955292,-46408.142578125,0.000124809938691421,2.16064900811995E-6,1,0.999253354069792,40.0298881530762,1.98982761063563,16.7900007218122,0.00141750085075581,0.000228298593927871,0.25,-1.7658920592655E-6,0.000125525802695692,-1.40690707845519E-6,99.9955292,99.9955292,-46418.01953125,-46398.265625,57.7709454848715,20.7415913554465,20.631098,0,0,0,40,4449,99.78185,-46408.142578125,,,,,,,,,,,,,0,,,,0.00245,,,,,,99.9955292,,,,
,29270869.775,99.9936981,-41605.26953125,0.000105067787743142,1.60819055558512E-6,1,0.999253354069792,40.0298881530762,1.99006036182946,16.7900007218122,0.00118191770422345,0.00025762929451563,0.25,4.2855580343751E-6,0.000105652392115078,4.62261250521885E-6,99.9936981,99.9936981,-41620.08984375,-41590.44921875,57.7435884866984,20.7361434230142,20.251448,0,0,0,40,4449,99.7854,-41605.26953125,,,,,,,,,,,,,0,,,,0,,,,,,99.9936981,,,,
,29270967.26,99.9992599,-36733.4765625,9.74158636936053E-5,1.58273129449142E-6,1,0.999253354069792,40.0298881530762,1.98968357723114,16.7900007218122,0.00109019431222531,0.000269779418886883,0.25,6.70441776215131E-6,9.79487805001706E-5,7.0343110868905E-6,99.9992599,99.9992599,-36743.44921875,-36723.50390625,57.8764653349677,20.7376854124487,19.871798,0,0,0,40,4449,99.78165,-36733.4765625,,,,,,,,,,,,,0,,,,0.0049,,,,,,99.9992599,,,,
,29271063.54,99.9908028,-31921.6728515625,3.90270556148441E-5,1.44970267806823E-6,1,0.999253354069792,40.0298881530762,1.98983865990824,16.7900007218122,0.00044343843376429,7.02151799732081E-5,0.25,-6.57733366135714E-7,3.92502757274386E-5,-5.4383461465373E-7,99.990593,99.9910126,-31936.462890625,-31906.8828125,57.6615174921792,20.7279955173157,20.251448,0,0,0,40,4449,99.7963,-31921.6728515625,,,,,,,,,,,,,0,,,,-0.00245,,,,,,99.9908028,,,,
,29271156.97,99.9957199,-27251.8544921875,1.83471091969297E-5,2.00657204414283E-6,1,0.999253354069792,40.0298881530762,1.98567239132209,16.7900007218122,0.000189547324541617,0.000138247741172494,0.25,9.00453449702628E-6,1.84236750396691E-5,9.11112683251471E-6,99.9957199,99.9957199,-27259.208984375,-27244.5,57.4051433378714,20.757384448142,20.251448,0,0,0,40,4449,99.8089,-27251.8544921875,,,,,,,,,,,,,0,,,,0.00245,,,,,,99.9957199,,,,
,29271254.445,99.9907455,-22379.166015625,2.49355676795644E-6,1.20293114982934E-6,1,0.999253354069792,40.0298881530762,1.98964371528654,16.7900007218122,2.07139718041261E-5,4.7829493988938E-5,0.25,3.78430705104489E-6,2.49610926915537E-6,3.8133042774898E-6,99.9907455,99.9907455,-22391.46484375,-22366.8671875,57.7076335748138,20.7182022894806,20.631098,0,0,0,40,4449,99.80285,-22379.166015625,,,,,,,,,,,,,0,,,,0.0049,,,,,,99.9907455,,,,
,29271349.7,99.98509215,-17619.6787109375,-1.79519763456385E-5,7.46529380474639E-7,1,0.999253354069792,40.0298881530762,1.99034551876614,16.7900007218122,-0.000219243433974154,5.43219723470593E-5,0.25,7.94852146286835E-6,-1.80776969777595E-5,7.9383417931563E-6,99.9848633,99.985321,-17634.6640625,-17604.693359375,57.799865740083,20.7173723432421,20.251448,0,0,0,40,4449,99.82105,-17619.6787109375,,,,,,,,,,,,,0,,,,-0.00245,,,,,,99.98509215,,,,
,29271445.93,99.9859848,-12809.353515625,-5.14390214763129E-5,6.1747832750731E-7,1,0.999253354069792,40.0298881530762,1.99010933553203,16.7900007218122,-0.000587491973304055,-7.56784379560405E-5,0.25,2.36005334147863E-6,-5.17363080560593E-5,2.21477729292296E-6,99.9859848,99.9859848,-12816.7568359375,-12801.9501953125,57.9585363294869,20.7116753747614,20.251448,0,0,0,40,4449,99.8313,-12809.353515625,,,,,,,,,,,,,0,,,,0,,,,,,99.9859848,,,,
,29271541.245,99.9884415,-8046.40112304687,-7.71172016216086E-5,4.76847656414464E-7,1,0.999253354069792,40.0298881530762,1.99007517870917,16.7900007218122,-0.00087703788844811,-0.000134553336128477,0.25,1.67703009254221E-6,-7.75566458560379E-5,1.44756754095747E-6,99.9884415,99.9884415,-8058.88232421875,-8033.919921875,57.9976177554484,20.7149551267898,19.871798,0,0,0,40,4449,99.84135,-8046.40112304687,,,,,,,,,,,,,0,,,,0,,,,,,99.9884415,,,,
,29271637.305,99.9907455,-3245.95812988281,-9.09000057880472E-5,3.85380068632283E-7,1,0.999253354069792,40.0298881530762,1.99007787060051,16.7900007218122,-0.00103103567186452,-0.000174226531468117,0.25,5.98748280547282E-7,-9.14131635179654E-5,3.19290669592218E-7,99.9907455,99.9907455,-3261.19506835937,-3230.72119140625,58.0304461532561,20.7230664615484,19.871798,0,0,0,40,4449,99.8512,-3245.95812988281,,,,,,,,,,,,,0,,,,0.00245,,,,,,99.9907455,,,,
,29271731.23,99.9925079,1447.72131347656,8.15640636922973E-5,3.79614803395956E-7,1,0.999253354069792,40.0298881530762,1.99002905326904,16.7900007218122,0.000925385053662827,0.00015481527543824,0.25,-6.71164101235704E-7,8.20247768380271E-5,-4.2082007969504E-7,99.9925079,99.9925079,1445.20031738281,1450.24230957031,57.8600511360638,20.7235706889609,20.631098,0,0,0,40,4449,99.8557,1447.72131347656,,,,,,,,,,,,,0,,,,0.00245,,,,,,99.9925079,,,,
,29271825.735,99.9980698,6172.21166992188,8.59474545656727E-5,4.10588112270567E-7,1,0.999253354069792,40.0298881530762,1.99019169335696,16.7900007218122,0.000977872456582113,0.000147933296137986,0.25,-2.04910900927625E-6,8.64375648984061E-5,-1.79393747133744E-6,99.9980698,99.9980698,6157.28857421875,6187.134765625,57.840510423083,20.7160146887029,19.871798,0,0,0,40,4449,99.85175,6172.21166992188,,,,,,,,,,,,,0,,,,0.00245,,,,,,99.9980698,,,,
,29271920.09,100.0034485,10885.3940429688,6.08101199721682E-5,5.50093948051306E-7,1,0.999253354069792,40.0298881530762,1.99000436902654,16.7900007218122,0.000692672107665393,9.97694311789399E-5,0.25,-1.88041107219937E-6,6.1158597427579E-5,-1.7032008764825E-6,100.0034485,100.0034485,10875.4140625,10895.3740234375,57.7670373422753,20.7173168447049,19.871798,0,0,0,40,4449,99.84895,10885.3940429688,,,,,,,,,,,,,0,,,,-0.00245,,,,,,100.0034485,,,,
,29272015.23,100.007576,15640.7016601562,3.96734064943966E-5,8.20613599871649E-7,1,0.999253354069792,40.0298881530762,1.99004675497573,16.7900007218122,0.000451828256351499,6.56233695469574E-5,0.25,-1.17935050907502E-6,3.99008747100231E-5,-1.06410317404401E-6,100.007576,100.007576,15628.275390625,15653.1279296875,57.6904377473907,20.722774219784,20.631098,0,0,0,40,4449,99.8404,15640.7016601562,,,,,,,,,,,,,0,,,,0.00245,,,,,,100.007576,,,,
,29272111.305,100.0114746,20442.806640625,7.70469596723757E-6,6.75198133786933E-7,1,0.999253354069792,40.0298881530762,1.98999715352793,16.7900007218122,9.13609932511049E-5,-7.8359255107687E-6,0.25,-2.0454213419707E-6,7.75447554796556E-6,-2.03343275187818E-6,100.0114746,100.0114746,20430.435546875,20455.177734375,57.7060703177753,20.7273989301154,20.631098,0,0,0,40,4449,99.8305,20442.806640625,,,,,,,,,,,,,0,,,,0.00245,,,,,,100.0114746,,,,
,29272206.085,100.0097504,25180.53515625,-2.34210088465412E-5,1.17070673619731E-6,1,0.999253354069792,40.0298881530762,1.99002939487626,16.7900007218122,-0.000257560343389015,-9.09683165995504E-5,0.25,-3.91438638343389E-6,-2.35416172795941E-5,-4.00770049269134E-6,100.0097504,100.0097504,25173.201171875,25187.869140625,57.9780770424677,20.7283100465368,20.251448,0,0,0,40,4449,99.82135,25180.53515625,,,,,,,,,,,,,0,,,,-0.00245,,,,,,100.0097504,,,,
,29272301.79,100.0091629,29963.265625,-4.73401576660538E-5,1.05101306920723E-6,1,0.999253354069792,40.0298881530762,1.99005724239262,16.7900007218122,-0.000521792590827153,-0.000177151580882287,0.25,-7.3193929645844E-6,-4.75862484686817E-5,-7.50386698969184E-6,100.0091629,100.0091629,29955.869140625,29970.662109375,58.0585847799485,20.7247167915193,19.871798,0,0,0,40,4449,99.81165,29963.265625,,,,,,,,,,,,,0,,,,0.00245,,,,,,100.0091629,,,,
,29272396.605,100.009346,34705.861328125,-7.23710601762947E-5,1.39501368711307E-6,1,0.999253354069792,40.0298881530762,1.99010172559907,16.7900007218122,-0.000797430919932265,-0.000272438814064038,0.25,-1.13329695542858E-5,-7.2747629006812E-5,-1.16145665208608E-5,100.009346,100.009346,34688.3046875,34723.41796875,57.9186732750061,20.7254248273045,19.871798,0,0,0,40,4449,99.80565,34705.861328125,,,,,,,,,,,,,0,,,,0,,,,,,100.009346,,,,
,29272494.515,100.01091,39598.119140625,-0.000101436099704761,1.91457536178657E-6,1,0.999253354069792,40.0298881530762,1.99033819579567,16.7900007218122,-0.00114207233588052,-0.000243858162502147,0.25,-3.70438163856715E-6,-0.000102001378067046,-4.02809366739164E-6,100.01091,100.01091,39585.44140625,39610.796875,57.9272711887177,20.719589233336,20.631098,0,0,0,40,4449,99.79205,39598.119140625,,,,,,,,,,,,,0,,,,0.00245,,,,,,100.01091,,,,
,29272591.705,100.0067444,44453.388671875,-0.000139340290629076,1.42604611681002E-6,1,0.999253354069792,40.0298881530762,1.99016737381721,16.7900007218122,-0.00156325102183126,-0.000366113478761638,0.25,-7.84091140389566E-6,-0.000140109911999453,-8.29862664092906E-6,100.0067444,100.0067444,44448.44140625,44458.3359375,57.8006473686023,20.7174426180151,20.631098,0,0,0,40,4449,99.78315,44453.388671875,,,,,,,,,,,,,0,,,,-0.00245,,,,,,100.0067444,,,,
,29272689.135,100.0104904,49323.9921875,-0.00015234192448956,2.47097140374905E-6,1,0.999253354069792,40.0298881530762,1.99036571669178,16.7900007218122,-0.00170537172567383,-0.000422655544210758,0.25,-1.05467769911561E-5,-0.000153178985928769,-1.10555511128642E-5,100.0104904,100.0104904,49316.5,49331.484375,57.7787617700638,20.7196564562348,20.251448,0,0,0,40,4449,99.77695,49323.9921875,,,,,,,,,,,,,0,,,,-0.00245,,,,,,100.0104904,,,,
,29272786.18,100.0094986,54173.927734375,-0.000177006518805922,2.34193821503744E-6,1,0.999253354069792,40.0298881530762,1.99001226715838,16.7900007218122,-0.00197741656126122,-0.000512323367652155,0.25,-1.41391964404209E-5,-0.000177975305557669,-1.47377668047282E-5,100.0094986,100.0094986,54164.07421875,54183.78125,57.6873112333138,20.7202270265082,20.251448,0,0,0,40,4449,99.76735,54173.927734375,,,,,,,,,,,,,0,,,,0.00245,,,,,,100.0094986,,,,
,29272884.725,100.0070343,59099.072265625,-0.00021930467929799,3.05932359062E-6,1,0.999253354069792,40.0298881530762,1.9898814641154,16.7900007218122,-0.00247202314967879,-0.000508233086418264,0.25,-6.3585099185356E-6,-0.000220539627029811,-7.03210423266079E-6,100.0070343,100.0070343,59086.703125,59111.44140625,57.7787617700638,20.7237068505007,20.251448,0,0,0,40,4449,99.76095,59099.072265625,,,,,,,,,,,,,0,,,,0,,,,,,100.0070343,,,,
,29272983.6,100.00941845,64042.0546875,-0.000291794050568191,3.3452025040317E-6,1,0.999253354069792,40.0298881530762,1.98962189714781,16.7900007218122,-0.0032660258570496,-0.000805604090032003,0.25,-1.98936508989968E-5,-0.000293406836158654,-2.08495586698392E-5,100.0090942,100.0097427,64029.4453125,64054.6640625,57.7779801415446,20.7253218339791,19.871798,0,0,0,40,4449,99.75295,64042.0546875,,,,,,,,,,,,,0,,,,0.00245,,,,,,100.00941845,,,,
,29273080.94,100.0093994,68907.28515625,-0.000274281973354977,2.42028881897775E-6,1,0.999253354069792,40.0298881530762,1.98992196907596,16.7900007218122,-0.0030802824374151,-0.000701556463633686,0.25,-1.37789338870536E-5,-0.000275814719801455,-1.46439864206785E-5,100.0093994,100.0093994,68902.3515625,68912.21875,57.759221057083,20.7246748272687,20.251448,0,0,0,40,4449,99.7456,68907.28515625,,,,,,,,,,,,,0,,,,0.00245,,,,,,100.0093994,,,,
,29273178.44,100.0064697,73782.40234375,-0.00029469633830688,3.47849089799019E-6,1,0.999253354069792,40.0298881530762,1.99011140265852,16.7900007218122,-0.00330761936080362,-0.000766696292191763,0.25,-1.59442120032097E-5,-0.000296342665831776,-1.68744657449686E-5,100.0064697,100.0064697,73764.9609375,73799.84375,57.7217028881599,20.7218645896457,20.631098,0,0,0,40,4449,99.73755,73782.40234375,,,,,,,,,,,,,0,,,,0.00245,,,,,,100.0064697,,,,
,29273276.94,100.0066299,78705.39453125,-0.000343649978747844,3.39928405239364E-6,1,0.999253354069792,40.0298881530762,1.99042753849582,16.7900007218122,-0.00384650491629513,-0.000957927768210852,0.25,-2.42227545057186E-5,-0.000345557112093137,-2.53331241903817E-5,100.0066299,100.0066299,78698,78712.7890625,57.7310824303907,20.7190071591939,20.251448,0,0,0,40,4449,99.73235,78705.39453125,,,,,,,,,,,,,0,,,,0,,,,,,100.0066299,,,,
,29273375.48,100.0067139,83631.01171875,-0.000355469424958695,3.67614490693255E-6,1,0.999253354069792,40.0298881530762,1.99030952038228,16.7900007218122,-0.003961526431482,-0.00108821941471235,0.25,-3.36568463487933E-5,-0.000357421460608455,-3.48479550188967E-5,100.0067139,100.0067139,83621.0703125,83640.953125,57.6802765766407,20.7205398954958,20.631098,0,0,0,40,4449,99.72745,83631.01171875,,,,,,,,,,,,,0,,,,0,,,,,,100.0067139,,,,
,29273468.75,100.0054779,88294.31640625,-0.000366312125991447,3.86473885908077E-6,1,0.999253354069792,40.0298881530762,1.99033903026422,16.7900007218122,-0.00406710234390248,-0.00120897668757055,0.25,-4.24145481314093E-5,-0.000368305654443275,-4.36798613841481E-5,100.0054779,100.0054779,88283.90625,88304.7265625,57.6990356611023,20.7075830951142,20.631098,0,0,0,40,4449,99.72135,88294.31640625,,,,,,,,,,,,,0,,,,-0.00245,,,,,,100.0054779,,,,
,29273584.585,100.0007324,87233.40234375,-0.000378184530002444,4.42645416600003E-6,1,0.999253354069792,40.0298881530762,1.99016324994432,16.7900007218122,-0.00423240579134977,-0.00105510933813433,0.25,-2.67612728177542E-5,-0.000380289383739862,-2.79710194543414E-5,100.0007324,100.0007324,87223.375,87243.4296875,57.7005989181407,20.724549141914,20.631098,0,0,0,40,4449,99.72295,87233.40234375,,,,,,,,,,,,,0,,,,0,,,,,,100.0007324,,,,
,29273680.565,100.0011978,82434.96875,-0.000367563267492924,4.01877620156364E-6,1,0.999253354069792,40.0298881530762,1.98976651567997,16.7900007218122,-0.0041137758815445,-0.00101924214133267,0.25,-2.5470224588017E-5,-0.000369607059931077,-2.66499288841768E-5,100.0011902,100.0012054,82419.8515625,82450.0859375,57.5622506702369,20.722039573351,20.251448,0,0,0,40,4449,99.72595,82434.96875,,,,,,,,,,,,,0,,,,-0.00245,,,,,,100.0011978,,,,
,29273776.88,100.0002594,77618.77734375,-0.000317489060560558,3.3316407673413E-6,1,0.999253354069792,40.0298881530762,1.98968740572168,16.7900007218122,-0.00357773772176731,-0.000740372740679692,0.25,-9.63888696741137E-6,-0.00031928636661228,-1.05930265196791E-5,100.0002594,100.0002594,77611.3125,77626.2421875,57.7748536274677,20.7170456205166,20.631098,0,0,0,40,4449,99.7235,77618.77734375,,,,,,,,,,,,,0,,,,0,,,,,,100.0002594,,,,
,29273873.82,99.9986496,72772.6328125,-0.000290322480070293,5.42359235528851E-6,1,0.999253354069792,40.0298881530762,1.99001322584089,16.7900007218122,-0.00325228907179619,-0.00078991634158669,0.25,-1.87629927246145E-5,-0.000291935050195725,-1.9698350956195E-5,99.9986496,99.9986496,72767.6875,72777.578125,57.7936127119292,20.7257027136588,20.631098,0,0,0,40,4449,99.72315,72772.6328125,,,,,,,,,,,,,0,,,,0.0049,,,,,,99.9986496,,,,
,29273969.835,99.997345,67974.59765625,-0.0002711824228231,4.83267935211895E-6,1,0.999253354069792,40.0298881530762,1.98991521950599,16.7900007218122,-0.00305689372770671,-0.00062846856995923,0.25,-7.87126621432989E-6,-0.000272713829924364,-8.69483549238584E-6,99.997345,99.997345,67969.5,67979.6953125,57.9530649298523,20.7220950618101,20.251448,0,0,0,40,4449,99.72735,67974.59765625,,,,,,,,,,,,,0,,,,0,,,,,,99.997345,,,,
,29274068.25,100.0078354,63054.546875,-0.000257918613257508,4.5958899238558E-6,1,0.999253354069792,40.0298881530762,1.98757692666421,16.7900007218122,-0.00287085351315656,-0.000786386002652352,0.25,-2.42105164297966E-5,-0.000259324366464617,-2.50946547901539E-5,100.0078354,100.0078354,63047.171875,63061.921875,57.9272711887177,20.7458464605212,19.871798,0,0,0,40,4449,99.73025,63054.546875,,,,,,,,,,,,,0,,,,-0.00245,,,,,,100.0078354,,,,
,29274166.34,99.9902573,58151.376953125,-0.000180041232262067,3.96286297963057E-6,1,0.999253354069792,40.0298881530762,1.99028367642411,16.7900007218122,-0.00200648408902005,-0.000550300190367511,0.25,-1.69541647324902E-5,-0.00018102058640239,-1.75750825715708E-5,99.9902573,99.9902573,58138.71484375,58164.0390625,58.0046524121215,20.719164740883,20.251448,0,0,0,40,4449,99.7398,58151.376953125,,,,,,,,,,,,,0,,,,0.00245,,,,,,99.9902573,,,,
,29274262,99.9892883,53370.91015625,-0.000170971502708826,3.89123179216317E-6,1,0.999253354069792,40.0298881530762,1.99033239554098,16.7900007218122,-0.00190836203554491,-0.000505893703130593,0.25,-1.46238044822373E-5,-0.000171904127277615,-1.520819280296E-5,99.9892883,99.9892883,53360.91015625,53380.91015625,57.89444279091,20.7228334332743,19.871798,0,0,0,40,4449,99.74725,53370.91015625,,,,,,,,,,,,,0,,,,0.0049,,,,,,99.9892883,,,,
,29274356.885,99.9926529,48628.3046875,-0.000137835932105506,2.48477894692079E-6,1,0.999253354069792,40.0298881530762,1.9901066766617,16.7900007218122,-0.00155389484810884,-0.000319133774102086,0.25,-3.96168982240715E-6,-0.000138609522960784,-4.39076077537418E-6,99.9926529,99.9926529,48618.23046875,48638.37890625,57.9468119016984,20.7249966003331,20.251448,0,0,0,40,4449,99.75345,48628.3046875,,,,,,,,,,,,,0,,,,0.00245,,,,,,99.9926529,,,,
,29274454.03,99.9909744,43773.0078125,-0.000115920572738069,2.05494308485019E-6,1,0.999253354069792,40.0298881530762,1.99053512184822,16.7900007218122,-0.00131868184456488,-0.000202433708437893,0.25,2.49523450635904E-6,-0.000116587433201612,2.16532546368306E-6,99.9909744,99.9909744,43765.1328125,43780.8828125,58.0851601496023,20.7207927396631,20.251448,0,0,0,40,4449,99.76275,43773.0078125,,,,,,,,,,,,,0,,,,-0.0049,,,,,,99.9909744,,,,
,29274550.295,99.9926987,38960.5703125,-9.83201069208833E-5,1.67825757824905E-6,1,0.999253354069792,40.0298881530762,1.99039898108387,16.7900007218122,-0.00110721610773598,-0.000235257355205345,0.25,-3.49170950573361E-6,-9.88681793281443E-5,-3.80527760773461E-6,99.9926987,99.9926987,38947.89453125,38973.24609375,58.1054824911023,20.7135837937492,20.251448,0,0,0,40,4449,99.76875,38960.5703125,,,,,,,,,,,,,0,,,,-0.00245,,,,,,99.9926987,,,,
,29274645.65,99.9909439,34198.1953125,-5.97116511055295E-5,1.69536497098298E-6,1,0.999253354069792,40.0298881530762,1.99044238167234,16.7900007218122,-0.000662852849156314,-0.000197464735301285,0.25,-6.93647292100574E-6,-6.00295069724715E-5,-7.1553113136697E-6,99.9909439,99.9909439,34185.78515625,34210.60546875,57.9624444720831,20.7068840261195,20.631098,0,0,0,40,4449,99.7781,34198.1953125,,,,,,,,,,,,,0,,,,-0.00245,,,,,,99.9909439,,,,
,29274742.34,99.9927216,29363.4052734375,-3.20961227273854E-5,1.31260497681311E-6,1,0.999253354069792,40.0298881530762,1.99029372827613,16.7900007218122,-0.000361874382461464,-7.42113186932129E-5,0.25,-9.10793193478166E-7,-3.22751638278203E-5,-1.01302788258375E-6,99.9927216,99.9927216,29353.333984375,29373.4765625,57.92492630316,20.7212585610608,20.251448,0,0,0,40,4449,99.78495,29363.4052734375,,,,,,,,,,,,,0,,,,0,,,,,,99.9927216,,,,
,29274836.395,99.9900055,24662.9716796875,-9.80748803533126E-6,1.04129614743548E-6,1,0.999253354069792,40.0298881530762,1.99039082894298,16.7900007218122,-0.000114584067006913,1.08180172489989E-7,0.25,1.73265805184838E-6,-9.86823324313159E-6,1.71262337047192E-6,99.9900055,99.9900055,24650.5390625,24675.404296875,58.1742658007946,20.7184346176579,20.631098,0,0,0,40,4449,99.7936,24662.9716796875,,,,,,,,,,,,,0,,,,-0.00245,,,,,,99.9900055,,,,
,29274931.985,99.9902496,19885.9599609375,1.71382559834112E-5,7.49956160142028E-7,1,0.999253354069792,40.0298881530762,1.99006110221771,16.7900007218122,0.000199413409816198,4.28302978219591E-6,0.25,-2.63334989496694E-6,1.72431177158068E-5,-2.59578942402103E-6,99.9902496,99.9902496,19878.501953125,19893.41796875,58.1883351141408,20.7080119884497,20.631098,0,0,0,40,4449,99.8001,19885.9599609375,,,,,,,,,,,,,0,,,,0,,,,,,99.9902496,,,,
,29275026.57,99.9894409,15158.6967773438,4.35429300269377E-5,1.01166165837037E-6,1,0.999253354069792,40.0298881530762,1.99045655188297,16.7900007218122,0.000493899281710474,8.39585609905439E-5,0.25,-2.42560025837362E-7,4.37893027967364E-5,-1.09990063948138E-7,99.9894409,99.9894409,15146.189453125,15171.2041015625,58.1250232040831,20.7135422877267,20.251448,0,0,0,40,4449,99.80885,15158.6967773438,,,,,,,,,,,,,0,,,,0,,,,,,99.9894409,,,,
,29275119.905,99.9904175,10493.6484375,6.63248706844385E-5,6.98331031922132E-7,1,0.999253354069792,40.0298881530762,1.99023844647881,16.7900007218122,0.000748590138600806,0.000148564295522868,0.25,1.45577903725003E-6,6.66940446929645E-5,1.66901546263806E-6,99.9904175,99.9904175,10488.69921875,10498.59765625,58.1031376055446,20.7197673359152,20.251448,0,0,0,40,4449,99.8181,10493.6484375,,,,,,,,,,,,,0,,,,-0.0049,,,,,,99.9904175,,,,
,29275212.65,99.9925919,5858.14819335938,8.57698524857872E-5,4.73206642536549E-7,1,0.999253354069792,40.0298881530762,1.99033074031347,16.7900007218122,0.000970295965932264,0.000179613194306428,0.25,7.76948422679354E-7,8.62501084932437E-5,1.04767699122671E-6,99.9925919,99.9925919,5850.60595703125,5865.6904296875,58.0749989788523,20.7189054342831,20.251448,0,0,0,40,4449,99.82555,5858.14819335938,,,,,,,,,,,,,0,,,,-0.00245,,,,,,99.9925919,,,,
,29275304.885,99.9935379,1247.23706054688,7.9171766789282E-5,3.16567242878859E-7,1,0.999253354069792,40.0298881530762,1.99015660878316,16.7900007218122,0.000897165093589125,0.000156726197234464,0.25,-8.29700485400048E-8,7.96171316103779E-5,1.63363844624912E-7,99.9935379,99.9935379,1242.06689453125,1252.4072265625,58.0241931251023,20.7269919509268,20.631098,0,0,0,40,4449,99.8326,1247.23706054688,,,,,,,,,,,,,0,,,,0.0049,,,,,,99.9935379,,,,
,29275330.12,99.9955826,-0.426265642046928,2.95974979682595E-6,3.42872254465512E-7,1,0.999253354069792,40.0298881530762,1.99015320746713,16.7900007218122,3.47441278733697E-5,-9.94621069863244E-7,0.25,-6.08032644996451E-7,2.97828308810369E-6,-6.02216970798372E-7,99.9954071,99.9957581,-0.441489428281784,-0.411041855812073,57.9952728698907,20.7127645291518,19.871798,0,0,0,40,4417,99.8308,-0.426265642046928,,,,,,,,,,,,,0,,,,0,,,,,,99.9955826,,,,