File: data/looselyPackedNP/sc-ios-7/ppms/rawdata/ES_S17_HYST_30K_FC.DAT
[Header]
; VSM Data File (default extension .dat)
; Copyright (c) 2003-2013, Quantum Design, Inc. All rights reserved.
TITLE,
FILEOPENTIME,29394259.69,12/07/2018,1:05 pm
BYAPP,VSM,2.0,2.0
INFO,PPMS VSM Option Release 1.4.10 Build 1,APPNAME
INFO,Quantum Design Linear Motor Servo Controller,MOTOR_MODULE_NAME
INFO,3101-100 M1,MOTOR_HW_VERSION
INFO,MMC1014,MOTOR_SERIAL_NUMBER
INFO,SRV No X-over 01.03.11,MOTOR_SOFTWARE_VERSION
INFO,Quantum Design VSM Detection Module,VSM_MODULE_NAME
INFO,3101-150 F0,VSM_HW_VERSION
INFO,VSM707,VSM_SERIAL_NUMBER
INFO,VSM No X-over 01.02.05 May 20 2008 13:51:47,VSM_SOFTWARE_VERSION
INFO,704,PREAMP_SERIAL_NUMBER
INFO,822,COIL_SERIAL_NUMBER
INFO,0,MOMENT_UNITS
INFO,Iron Oxide Spheres,SAMPLE_MATERIAL
INFO,7 nm diameter, collaboration Mainz,SAMPLE_COMMENT
INFO,,SAMPLE_MASS
INFO,,SAMPLE_VOLUME
INFO,,SAMPLE_MOLECULAR_WEIGHT
INFO,,SAMPLE_SIZE
INFO,,SAMPLE_SHAPE
DATATYPE,COMMENT,1
DATATYPE,TIME,2
STARTUPAXIS,X,2
STARTUPAXIS,Y1,5
[Data]
Comment,Time Stamp (sec),Temperature (K),Magnetic Field (Oe),Moment (emu),M. Std. Err. (emu),Transport Action,Averaging Time (sec),Frequency (Hz),Peak Amplitude (mm),Center Position (mm),Coil Signal' (mV),Coil Signal" (mV),Range (mV),M. Quad. Signal (emu),M. Raw' (emu),M. Raw" (emu),Min. Temperature (K),Max. Temperature (K),Min. Field (Oe),Max. Field (Oe),Mass (grams),Motor Lag (deg),Pressure (Torr),VSM Status (code),Motor Status (code),Measure Status (code),Measure Count,PPMS Status (code),System Temp. (K),System Field (Oe),Sample Position (deg),Bridge 1 Resistance (ohms),Bridge 1 Excitation (에),Bridge 2 Resistance (ohms),Bridge 2 Excitation (에),Bridge 3 Resistance (ohms),Bridge 3 Excitation (에),Bridge 4 Resistance (ohms),Bridge 4 Excitation (에),Signal 1 Vin (V),Signal 2 Vin (V),Digital Inputs (code),Drive 1 Iout (mA),Drive 1 Ipower (W),Drive 2 Iout (mA),Drive 2 Ipower (W),Pressure (),Map 20 (),Map 21 (),Map 22 (),Map 23 (),Map 24 (),Map 25 (),Map 26 (),Map 27 (),Map 28 (),Map 29 ()
,29394327.45,30.0442276,0.251192256808281,3.27932012855483E-5,3.77010935040128E-7,1,0.999253354069792,40.0298881530762,1.989294891992,16.8999992311001,0.000367612365977544,6.33554868813389E-5,0.25,-1.87767821693214E-7,3.26236882568555E-5,-7.39956817690754E-9,30.0442276,30.0442276,0.228356599807739,0.274027913808823,56.3647957787752,20.6812914589286,16.454937,0,0,0,40,4417,29.9174,0.251192256808281,,,,,,,,,,,,,0,,,,0.0049,,,,,,30.0442276,,,,
,29394360.535,30.045023,400.189361572266,6.66120664221742E-5,3.07890582398656E-7,1,0.999253354069792,40.0298881530762,1.98952409926629,16.8999992311001,0.000745813362449596,0.000134329975212318,0.25,1.19631529776696E-7,6.62659472449164E-5,4.84281001685271E-7,30.045023,30.045023,396.281066894531,404.09765625,56.5093970548329,20.6845168417445,16.454937,0,0,0,40,4449,29.92305,400.189361572266,,,,,,,,,,,,,0,,,,-0.0049,,,,,,30.045023,,,,
,29394377.86,30.0414753,833.229156494141,8.41777991768681E-5,3.92720140993542E-7,1,0.999253354069792,40.0298881530762,1.98945668161929,16.9099997729063,0.000942424170124036,0.000170028480867239,0.25,1.74483240985315E-7,8.37419016456538E-5,6.36658280517244E-7,30.0414753,30.0414753,830.746398925781,835.7119140625,56.5516049948714,20.686479292928,16.454937,0,0,0,40,4449,29.9229,833.229156494141,,,,,,,,,,,,,0,,,,0,,,,,,30.0414753,,,,
,29394397.07,30.0383282,1312.47253417969,9.25639474175443E-5,3.53494573306234E-7,1,0.999253354069792,40.0298881530762,1.98926591742787,16.8999992311001,0.00103661439023618,0.000184866412400978,0.25,3.42685959101471E-9,9.20878294992326E-5,5.14586094638268E-7,30.0383282,30.0383282,1307.47009277344,1317.47497558594,56.5156500829868,20.6909103011442,16.454937,0,0,0,40,4449,29.9181,1312.47253417969,,,,,,,,,,,,,0,,,,-0.0049,,,,,,30.0383282,,,,
,29394413.965,30.036725,1734.4189453125,9.68688481921484E-5,3.16280886145794E-7,1,0.999253354069792,40.0298881530762,1.98932154028353,16.8999992311001,0.00108525554790501,0.000191354662145457,0.25,-1.87530130300425E-7,9.63737859415506E-5,3.50305243483383E-7,30.0362186,30.0372314,1729.22058105469,1739.61730957031,56.6938613853714,20.6906722497505,16.075285,0,0,0,40,4449,29.9127,1734.4189453125,,,,,,,,,,,,,0,,,,0,,,,,,30.036725,,,,
,29394431.25,30.0319481,2165.93872070313,9.81029879290427E-5,3.06755074460564E-7,1,0.999253354069792,40.0298881530762,1.98933722504156,16.8999992311001,0.00109877196750408,0.000195736526682193,0.25,-1.90457604531697E-8,9.76030726333117E-5,5.26906124706095E-7,30.0319481,30.0319481,2160.978515625,2170.89892578125,56.5711457078521,20.6954049830544,16.075285,0,0,0,40,4449,29.9129,2165.93872070313,,,,,,,,,,,,,0,,,,0.00245,,,,,,30.0319481,,,,
,29394449.97,30.0293808,2632.36755371094,9.89757549985757E-5,3.1300588541842E-7,1,0.999253354069792,40.0298881530762,1.98918595643318,16.8999992311001,0.00110968664089698,0.00019079873134492,0.25,-6.17170610473456E-7,9.84774096429246E-5,-6.09664570352718E-8,30.0293808,30.0293808,2627.24633789062,2637.48876953125,56.9885353371214,20.6985522602084,16.454937,0,0,0,40,4449,29.90795,2632.36755371094,,,,,,,,,,,,,0,,,,0,,,,,,30.0293808,,,,
,29394467.865,30.0258102,3080.69079589844,9.93774662848091E-5,3.61797751832732E-7,1,0.999253354069792,40.0298881530762,1.98926242501247,16.8999992311001,0.00111374959017776,0.000194456837488807,0.25,-3.6562823817188E-7,9.88783591470711E-5,1.93873065583787E-7,30.0258102,30.0258102,3077.03344726562,3084.34814453125,56.7587365524675,20.6992231215317,16.075285,0,0,0,40,4449,29.90225,3080.69079589844,,,,,,,,,,,,,0,,,,0,,,,,,30.0258102,,,,
,29394485.325,30.023489,3515.93359375,9.83938169144291E-5,3.86937056013067E-7,1,0.999253354069792,40.0298881530762,1.98917729780779,16.8999992311001,0.00110358575629688,0.000187628736933312,0.25,-8.01949082022394E-7,9.79048557808319E-5,-2.43434018431442E-7,30.023489,30.023489,3513.41479492188,3518.45239257812,56.8220484625252,20.7001459430152,16.075285,0,0,0,40,4449,29.9029,3515.93359375,,,,,,,,,,,,,0,,,,0,,,,,,30.023489,,,,
,29394503.32,30.0204754,3964.06005859375,9.69106587336941E-5,3.94404034558639E-7,1,0.999253354069792,40.0298881530762,1.98922980612495,16.9099997729063,0.00108536007548998,0.00019405811513892,0.25,3.33738411348584E-8,9.64272480273508E-5,5.8176105886017E-7,30.0204754,30.0204754,3960.26684570313,3967.85327148438,56.8650380310829,20.7019529744569,16.075285,0,0,0,40,4449,29.90245,3964.06005859375,,,,,,,,,,,,,0,,,,0,,,,,,30.0204754,,,,
,29394521.735,30.0211277,4424.60888671875,9.4948863827879E-5,3.92328796926035E-7,1,0.999253354069792,40.0298881530762,1.98915451080511,16.8999992311001,0.00106488742900601,0.000181701917002708,0.25,-7.2217663765916E-7,9.44824647596429E-5,-1.7865725804447E-7,30.0211277,30.0211277,4422.05126953125,4427.16650390625,56.9385111118906,20.7030423873518,16.075285,0,0,0,40,4449,29.9043,4424.60888671875,,,,,,,,,,,,,0,,,,-0.0049,,,,,,30.0211277,,,,
,29394539.515,30.0186119,4867.63842773438,9.40613601353593E-5,4.14710598291413E-7,1,0.999253354069792,40.0298881530762,1.98914914647884,16.8999992311001,0.00105518305178492,0.000178771765425908,0.25,-8.28137039466387E-7,9.36027282137425E-5,-2.8685776228485E-7,30.0186119,30.0186119,4864.07763671875,4871.19921875,56.8626931455252,20.7044497948236,16.075285,0,0,0,40,4449,29.8952,4867.63842773438,,,,,,,,,,,,,0,,,,-0.0049,,,,,,30.0186119,,,,
,29394555.665,30.0166969,5272.54736328125,9.15805671936194E-5,3.57355671828076E-7,1,0.999253354069792,40.0298881530762,1.98907182075863,16.8999992311001,0.00102833152519637,0.000168527900159442,0.25,-1.30194733044654E-6,9.11394761598848E-5,-7.70391495026276E-7,30.0166969,30.0166969,5271.17822265625,5273.91650390625,57.1049979864868,20.7051319684945,16.075285,0,0,0,40,4449,29.8957,5272.54736328125,,,,,,,,,,,,,0,,,,0,,,,,,30.0166969,,,,
,29394571.585,30.0081062,5668.53125,8.97876182973688E-5,4.18409109176259E-7,1,0.999253354069792,40.0298881530762,1.98948542378586,16.8999992311001,0.00100620453623111,0.000177719295854789,0.25,-1.66887916986402E-7,8.93513095314065E-5,3.50880932610987E-7,30.0081062,30.0081062,5666.0078125,5671.0546875,57.1651833824676,20.7033108641863,16.454937,0,0,0,40,4449,29.89445,5668.53125,,,,,,,,,,,,,0,,,,-0.0049,,,,,,30.0081062,,,,
,29394587.875,29.9964485,6076.70263671875,8.81892699223183E-5,4.61772162112042E-7,1,0.999253354069792,40.0298881530762,1.99001812904381,16.9099997729063,0.000990983552856419,0.000161121595238287,0.25,-1.36938862546229E-6,8.77703866108263E-5,-8.52825935860162E-7,29.9964485,29.9964485,6073.09521484375,6080.31005859375,56.9893169656406,20.6956212249058,15.695635,0,0,0,40,4449,29.90375,6076.70263671875,,,,,,,,,,,,,0,,,,0.00245,,,,,,29.9964485,,,,
,29394604.75,30.0057201,6497.95629882813,8.65064023868939E-5,4.67302007300691E-7,1,0.999253354069792,40.0298881530762,1.98933688281585,16.8999992311001,0.000969348109325131,0.000171652808044249,0.25,-1.26740492033701E-7,8.60911754668306E-5,3.76249241420411E-7,30.0057201,30.0057201,6495.2080078125,6500.70458984375,57.3004051162945,20.7066749002982,15.695635,0,0,0,40,4449,29.908,6497.95629882813,,,,,,,,,,,,,0,,,,0,,,,,,30.0057201,,,,
,29394622.76,30.0027218,6948.58178710937,8.39461661762632E-5,4.3070649112926E-7,1,0.999253354069792,40.0298881530762,1.98947292474054,16.8999992311001,0.000944069282478701,0.000148011599544963,0.25,-1.78325776416345E-6,8.35555873775825E-5,-1.28509922600422E-6,30.0027218,30.0027218,6944.861328125,6952.30224609375,57.1167224142753,20.7066601800304,16.075285,0,0,0,40,4449,29.8941,6948.58178710937,,,,,,,,,,,,,0,,,,0.0049,,,,,,30.0027218,,,,
,29394657.72,30.0082874,7271.80224609375,8.64786741369697E-5,4.91308766594637E-7,1,0.999253354069792,40.0298881530762,1.98904130921853,16.8999992311001,0.000970790605413286,0.0001613068651206,0.25,-1.04794499466276E-6,8.60738303445439E-5,-5.36892154213187E-7,30.0082874,30.0082874,7269.6337890625,7273.970703125,57.1018714724099,20.7078375032708,16.075285,0,0,0,40,4449,29.89485,7271.80224609375,,,,,,,,,,,,,0,,,,-0.00245,,,,,,30.0082874,,,,
,29394673.585,30.0089588,6878.13305664062,8.54203366314021E-5,4.43622336881904E-7,1,0.999253354069792,40.0298881530762,1.9889779719526,16.8999992311001,0.000958820859635141,0.000159497838685872,0.25,-1.01754604298503E-6,8.50178098309585E-5,-5.14784602921192E-7,30.0089588,30.0089588,6876.7236328125,6879.54248046875,57.2777378892368,20.7115082769169,16.454937,0,0,0,40,4449,29.89575,6878.13305664062,,,,,,,,,,,,,0,,,,0,,,,,,30.0089588,,,,
,29394689.385,30.0075207,6484.236328125,8.79604246290344E-5,3.77488525692683E-7,1,0.999253354069792,40.0298881530762,1.98923669724583,16.8999992311001,0.000986713511769602,0.000168244309528781,0.25,-6.89727552144768E-7,8.7541239293771E-5,-1.75772264904251E-7,30.0075207,30.0075207,6480.68212890625,6487.79052734375,57.0002597649099,20.7101498272581,16.075285,0,0,0,40,4449,29.8933,6484.236328125,,,,,,,,,,,,,0,,,,-0.00245,,,,,,30.0075207,,,,
,29394705.845,30.0060062,6072.60180664062,9.07992771856194E-5,3.4744454245183E-7,1,0.999253354069792,40.0298881530762,1.98897360996144,16.8999992311001,0.00102011409671176,0.000164045965958424,0.25,-1.56704735318913E-6,9.03688037527435E-5,-1.03451135604944E-6,30.0060062,30.0060062,6071.39501953125,6073.80859375,57.0588819038522,20.7144965206777,15.695635,0,0,0,40,4449,29.8971,6072.60180664062,,,,,,,,,,,,,0,,,,-0.0049,,,,,,30.0060062,,,,
,29394721.61,30.0041618,5679.42895507812,9.14502613143855E-5,4.34101301450148E-7,1,0.999253354069792,40.0298881530762,1.98916838784932,16.8999992311001,0.00102685027567589,0.00016883965075897,0.25,-1.25417631382766E-6,9.10122238920219E-5,-7.21455134357612E-7,30.0041618,30.0041618,5674.5439453125,5684.31396484375,57.1096877576022,20.7103926331059,15.695635,0,0,0,40,4449,29.89775,5679.42895507812,,,,,,,,,,,,,0,,,,-0.0049,,,,,,30.0041618,,,,
,29394739.21,30.0030327,5240.48657226562,9.28027439890947E-5,3.31132611946182E-7,1,0.999253354069792,40.0298881530762,1.98926109889107,16.8999992311001,0.00104053433140278,0.000179829277149707,0.25,-5.12371126130427E-7,9.23509564290569E-5,2.21701120558822E-8,30.0030327,30.0030327,5235.58447265625,5245.388671875,57.1503324406022,20.7108825476548,16.075285,0,0,0,40,4449,29.8975,5240.48657226562,,,,,,,,,,,,,0,,,,0.00245,,,,,,30.0030327,,,,
,29394756.64,30.0054922,4804.54223632812,9.53111046613503E-5,3.49794061110042E-7,1,0.999253354069792,40.0298881530762,1.98923511139275,16.8999992311001,0.00106875466512963,0.000183885359970497,0.25,-5.94917073930373E-7,9.48445782037939E-5,-4.79912239634404E-8,30.0048504,30.006134,4800.6474609375,4808.43701171875,57.2777378892368,20.7096017979638,16.454937,0,0,0,40,4449,29.89535,4804.54223632812,,,,,,,,,,,,,0,,,,-0.0049,,,,,,30.0054922,,,,
,29394773.69,30.0027428,4378.7333984375,9.61970734511041E-5,3.51425483039378E-7,1,0.999253354069792,40.0298881530762,1.98918999920972,16.8999992311001,0.00108026630866402,0.000176438562676934,0.25,-1.41472109725014E-6,9.57280122087075E-5,-8.61021695136129E-7,30.0027428,30.0027428,4376.16015625,4381.306640625,57.1448610409676,20.7111263969899,15.695635,0,0,0,40,4449,29.8928,4378.7333984375,,,,,,,,,,,,,0,,,,0,,,,,,30.0027428,,,,
,29394791.85,30.0005474,3925.57885742188,9.74861301822353E-5,3.94836539838979E-7,1,0.999253354069792,40.0298881530762,1.98923344180655,16.8999992311001,0.00109333588869436,0.000186620552657628,0.25,-7.33034779118987E-7,9.70038463854489E-5,-1.77866820069666E-7,30.0005474,30.0005474,3922.1435546875,3929.01416015625,57.2707032325638,20.710921270724,15.695635,0,0,0,40,4449,29.8928,3925.57885742188,,,,,,,,,,,,,0,,,,-0.0049,,,,,,30.0005474,,,,
,29394808.875,30.0015469,3499.26086425781,9.95933681221975E-5,3.60158713477977E-7,1,0.999253354069792,40.0298881530762,1.98914844771835,16.8999992311001,0.0011158443702471,0.000196516200082581,0.25,-2.21983818755394E-7,9.90949444064311E-5,3.40217512911458E-7,30.0015469,30.0015469,3494.16430664063,3504.357421875,57.2597604332945,20.7114853079245,16.075285,0,0,0,40,4449,29.89525,3499.26086425781,,,,,,,,,,,,,0,,,,0.00245,,,,,,30.0015469,,,,
,29394826.99,30.0053787,3047.55053710937,0.00010012744185714,3.88194570001865E-7,1,0.999253354069792,40.0298881530762,1.9891189755043,16.8999992311001,0.0011221040979431,0.000195743057904165,0.25,-3.83061906245159E-7,9.96243652590312E-5,1.80477728567526E-7,30.0053787,30.0053787,3044.86889648438,3050.23217773438,57.2894623170253,20.7106187149967,16.454937,0,0,0,40,4449,29.89415,3047.55053710937,,,,,,,,,,,,,0,,,,-0.0049,,,,,,30.0053787,,,,
,29394844.49,30.0011883,2611.5556640625,0.000100834567036285,4.46740314689155E-7,1,0.999253354069792,40.0298881530762,1.98908745611149,16.8999992311001,0.00113016601624586,0.000196080518946999,0.25,-4.75983959358047E-7,0.000100325750162498,8.9649962002392E-8,30.0011883,30.0011883,2610.2109375,2612.900390625,57.2331850636407,20.7139263978514,16.075285,0,0,0,40,4449,29.8947,2611.5556640625,,,,,,,,,,,,,0,,,,0.0049,,,,,,30.0011883,,,,
,29394861.815,30.0009613,2178.39697265625,9.9383048016747E-5,3.37332377659082E-7,1,0.999253354069792,40.0298881530762,1.98924630650651,16.8999992311001,0.00111287286830433,0.000199326016660883,0.25,7.40683047944838E-8,9.88759858625858E-5,6.26557528479575E-7,30.0009613,30.0009613,2173.3408203125,2183.453125,57.0612267894099,20.7108527551549,16.075285,0,0,0,40,4449,29.89525,2178.39697265625,,,,,,,,,,,,,0,,,,0.00245,,,,,,30.0009613,,,,
,29394880.245,29.9984341,1717.37280273438,9.78998040865082E-5,3.58579496023262E-7,1,0.999253354069792,40.0298881530762,1.98923730045141,16.8999992311001,0.00109617025752648,0.000196682195631476,0.25,1.05321121211243E-7,9.73975940588598E-5,6.47129003561975E-7,29.9984341,29.9984341,1713.37573242187,1721.36987304687,57.1034347294484,20.7141664779595,16.075285,0,0,0,40,4449,29.8965,1717.37280273438,,,,,,,,,,,,,0,,,,0.0049,,,,,,29.9984341,,,,
,29394897.17,30.0017815,1294.66528320312,9.38193425844245E-5,3.01023846639661E-7,1,0.999253354069792,40.0298881530762,1.98922086453348,16.8999992311001,0.00105021296494873,0.000189804900087895,0.25,2.21284635574845E-7,9.33352615201262E-5,7.37961031034014E-7,30.0017815,30.0017815,1291.00085449219,1298.32971191406,57.1315733561406,20.713875622015,16.075285,0,0,0,40,4449,29.8953,1294.66528320312,,,,,,,,,,,,,0,,,,0,,,,,,30.0017815,,,,
,29394913.76,30.00029565,878.543853759766,8.6464549938255E-5,3.44099412200352E-7,1,0.999253354069792,40.0298881530762,1.98909680783085,16.8999992311001,0.000968305808847044,0.000172104518390985,0.25,-4.50815083695354E-8,8.60179810579913E-5,4.30728948208444E-7,30.0001278,30.0004635,876.135498046875,880.952209472656,57.166746639506,20.7129397971109,16.075285,0,0,0,40,4449,29.8945,878.543853759766,,,,,,,,,,,,,0,,,,0.0049,,,,,,30.00029565,,,,
,29394930.515,30.0016823,461.461212158203,7.30919397977676E-5,3.27503417072885E-7,1,0.999253354069792,40.0298881530762,1.98903210381633,16.8999992311001,0.000818126255903555,0.000147615311502912,0.25,1.53852256908704E-7,7.27120401479493E-5,5.53850301635974E-7,30.0016823,30.0016823,459.209930419922,463.712493896484,57.5184794731599,20.7134573389676,16.075285,0,0,0,40,4449,29.8993,461.461212158203,,,,,,,,,,,,,0,,,,0.0049,,,,,,30.0016823,,,,
,29394947.515,30.0000725,35.3561153411865,3.6697774377972E-5,3.81278839106108E-7,1,0.999253354069792,40.0298881530762,1.98916646367367,16.8999992311001,0.000410777340433028,7.4144562378876E-5,0.25,8.01792028004592E-8,3.65064287795206E-5,2.80447277521683E-7,30.0000725,30.0000725,34.1283493041992,36.5838813781738,57.3676251689484,20.7119645545319,16.075285,0,0,0,40,4449,29.8932,35.3561153411865,,,,,,,,,,,,,0,,,,0,,,,,,30.0000725,,,,
,29394965.13,30.0000744,-402.931106567383,-3.09165739618423E-5,3.21768642157435E-7,1,0.999253354069792,40.0298881530762,1.98905252633281,16.8999992311001,-0.000344753347465683,-6.97421452446727E-5,0.25,-7.17362031037688E-7,-3.07522285716485E-5,-8.83095992569717E-7,30.0000744,30.0000744,-410.555816650391,-395.306396484375,57.6263442088138,20.7150906846928,16.075285,0,0,0,40,4449,29.89795,-402.931106567383,,,,,,,,,,,,,0,,,,0,,,,,,30.0000744,,,,
,29394982.395,30.0006466,-834.899749755859,-6.52003135623484E-5,3.01011053244169E-7,1,0.999253354069792,40.0298881530762,1.98909502350697,16.8999992311001,-0.000729038641539001,-0.000136113578457392,0.25,-5.31882171152689E-7,-6.48603167815272E-5,-8.87622452506576E-7,30.0006466,30.0006466,-839.88427734375,-829.915222167969,57.4473512779099,20.7156483383469,15.695635,0,0,0,40,4449,29.8938,-834.899749755859,,,,,,,,,,,,,0,,,,-0.00245,,,,,,30.0006466,,,,
,29395001.375,29.9979725,-1309.21490478516,-8.20880773717652E-5,3.24970648746424E-7,1,0.999253354069792,40.0298881530762,1.98915585968741,16.8999992311001,-0.000918532852656714,-0.00016793297281369,0.25,-3.60206950009626E-7,-8.16636981104775E-5,-8.11501701529906E-7,29.9979725,29.9979725,-1314.00805664062,-1304.42175292969,57.5075366738907,20.7135062210302,16.075285,0,0,0,40,4449,29.8983,-1309.21490478516,,,,,,,,,,,,,0,,,,-0.00245,,,,,,29.9979725,,,,
,29395020.1,29.9972839,-1775.50610351562,-9.04331114858225E-5,3.75765548054298E-7,1,0.999253354069792,40.0298881530762,1.98917564040592,16.8999992311001,-0.00101147004225576,-0.000187677153242602,0.25,-6.32847506329447E-7,-8.99665236177329E-5,-1.13084790065372E-6,29.9972839,29.9972839,-1780.89111328125,-1770.12109375,57.495030617583,20.7151391140874,15.315984,0,0,0,40,4449,29.89615,-1775.50610351562,,,,,,,,,,,,,0,,,,0,,,,,,29.9972839,,,,
,29395038.14,30.0007935,-2226.30480957031,-9.40773194738131E-5,2.88166639226696E-7,1,0.999253354069792,40.0298881530762,1.98888425352986,16.8999992311001,-0.00105321109706174,-0.000189042816381624,0.25,-1.04697788871469E-7,-9.35974440520628E-5,-6.27789978310099E-7,30.0007935,30.0007935,-2229.99926757813,-2222.6103515625,57.3512109700445,20.7178252890321,15.695635,0,0,0,40,4449,29.89975,-2226.30480957031,,,,,,,,,,,,,0,,,,-0.00245,,,,,,30.0007935,,,,
,29395055.695,29.9925003,-2664.38977050781,-9.63573580868192E-5,3.28081039709384E-7,1,0.999253354069792,40.0298881530762,1.98896467853008,16.8999992311001,-0.0010793613794798,-0.000190527627369626,0.25,1.72667690188989E-7,-9.58699463023202E-5,-3.66756287361166E-7,29.9900932,29.9949074,-2666.8642578125,-2661.91528320313,57.3035316303714,20.7136025453773,15.695635,0,0,0,40,4449,29.90175,-2664.38977050781,,,,,,,,,,,,,0,,,,-0.00245,,,,,,29.9925003,,,,
,29395074,29.9969177,-3122.76257324219,-9.72616327570724E-5,3.26655865539623E-7,1,0.999253354069792,40.0298881530762,1.98911647774098,16.8999992311001,-0.00108973878245526,-0.000191561779925977,0.25,2.45706449233981E-7,-9.67727593140637E-5,-3.01506432206138E-7,29.9969177,29.9969177,-3126.52197265625,-3119.00317382812,57.6279074658522,20.7168940994962,15.695635,0,0,0,40,4449,29.8988,-3122.76257324219,,,,,,,,,,,,,0,,,,0,,,,,,29.9969177,,,,
,29395092.56,29.9966812,-3586.56762695313,-9.70414055433331E-5,3.20004758181016E-7,1,0.999253354069792,40.0298881530762,1.98878945099949,16.8999992311001,-0.00108739689686189,-0.000189625505657959,0.25,3.79644534108286E-7,-9.65572735341092E-5,-1.69481306291982E-7,29.9966812,29.9966812,-3589.23876953125,-3583.896484375,57.6380686366023,20.7189335708873,15.695635,0,0,0,40,4449,29.8999,-3586.56762695313,,,,,,,,,,,,,0,,,,-0.0049,,,,,,29.9966812,,,,
,29395109.71,30.0027103,-4014.95922851562,-9.55831191232801E-5,3.68702916746923E-7,1,0.999253354069792,40.0298881530762,1.98901904420272,16.8999992311001,-0.0010715040466563,-0.000185120648278212,0.25,5.26304475924312E-7,-9.51097688517626E-5,-1.75801842350914E-8,30.0027103,30.0027103,-4016.22094726562,-4013.69750976562,57.3801312252561,20.7142585848995,16.075285,0,0,0,40,4449,29.89685,-4014.95922851562,,,,,,,,,,,,,0,,,,0.0049,,,,,,30.0027103,,,,
,29395128.485,29.9972286,-4483.98461914063,-9.59539882833646E-5,3.18322731928887E-7,1,0.999253354069792,40.0298881530762,1.98907352657933,16.8999992311001,-0.00107605175063617,-0.000184011754587214,0.25,6.94981562651818E-7,-9.54827567493332E-5,1.45641502382288E-7,29.9972286,29.9972286,-4488.9423828125,-4479.02685546875,57.5450548428138,20.7171949816617,15.315984,0,0,0,40,4449,29.89515,-4483.98461914063,,,,,,,,,,,,,0,,,,0,,,,,,29.9972286,,,,
,29395146.335,30.00145915,-4929.95166015625,-9.40201141512184E-5,3.69999685356637E-7,1,0.999253354069792,40.0298881530762,1.98903881634611,16.8999992311001,-0.00105414721918986,-0.000181611127672823,0.25,5.66851379629291E-7,-9.35606404147279E-5,2.67344492308121E-8,30.0011139,30.0018044,-4933.62451171875,-4926.27880859375,57.4903408464676,20.7159394109326,16.075285,0,0,0,40,4449,29.8981,-4929.95166015625,,,,,,,,,,,,,0,,,,0,,,,,,30.00145915,,,,
,29395164.315,30.0021324,-5380.25244140625,-9.29907161670113E-5,4.55140652250499E-7,1,0.999253354069792,40.0298881530762,1.98911823338746,16.8999992311001,-0.00104122631387616,-0.000187768529070062,0.25,-1.63110105738704E-7,-9.25350215149572E-5,-6.96154075718445E-7,30.0021324,30.0021324,-5386.5986328125,-5373.90625,57.5466180998522,20.7136884446448,16.075285,0,0,0,40,4449,29.89505,-5380.25244140625,,,,,,,,,,,,,0,,,,0.00245,,,,,,30.0021324,,,,
,29395182.31,29.9975204,-5828.74951171875,-9.09526543498982E-5,4.14775781772264E-7,1,0.999253354069792,40.0298881530762,1.98908413636854,16.8999992311001,-0.00101910417794488,-0.000179839261705566,0.25,1.83664076621945E-7,-9.05118798221501E-5,-3.41794054136935E-7,29.9975204,29.9975204,-5831.1708984375,-5826.328125,57.4387533641984,20.7146637490053,15.695635,0,0,0,40,4449,29.9005,-5828.74951171875,,,,,,,,,,,,,0,,,,-0.0049,,,,,,29.9975204,,,,
,29395199.5,29.9975834,-6258.69775390625,-8.95465066181628E-5,3.66035319335463E-7,1,0.999253354069792,40.0298881530762,1.98875136591898,16.8999992311001,-0.00100637950037022,-0.000159342910964742,0.25,1.76294357675467E-6,-8.91245031180284E-5,1.23571709482284E-6,29.9975834,29.9975834,-6261.1044921875,-6256.291015625,57.5856995258138,20.7187023423197,15.695635,0,0,0,40,4449,29.9009,-6258.69775390625,,,,,,,,,,,,,0,,,,0,,,,,,29.9975834,,,,
,29395216.925,30.0030575,-6694.71508789063,-8.67672227264261E-5,3.58451501362968E-7,1,0.999253354069792,40.0298881530762,1.98888876415236,16.8999992311001,-0.000974135181762771,-0.000160599288457352,0.25,1.15805318041281E-6,-8.635790575754E-5,6.47676786752863E-7,30.0030022,30.0031128,-6700.9765625,-6688.45361328125,57.5395834431792,20.7133923149091,15.695635,0,0,0,40,4449,29.89795,-6694.71508789063,,,,,,,,,,,,,0,,,,-0.00245,,,,,,30.0030575,,,,
,29395234.78,30.0004959,-7140.7841796875,-8.49988729605336E-5,4.21245279199495E-7,1,0.999253354069792,40.0298881530762,1.9888796053046,16.8999992311001,-0.000955341031375305,-0.000151557547334912,0.25,1.65210620064318E-6,-8.46037493807045E-5,1.14748646562418E-6,30.0004959,30.0004959,-7143.1943359375,-7138.3740234375,57.3543374841214,20.7163742507776,16.075285,0,0,0,40,4449,29.8947,-7140.7841796875,,,,,,,,,,,,,0,,,,0.00245,,,,,,30.0004959,,,,
,29395272.5,29.9991093,-7004.32495117187,-8.5111656422655E-5,3.74786152064623E-7,1,0.999253354069792,40.0298881530762,1.98877239583134,16.8999992311001,-0.000953362897029078,-0.000169590905642717,0.25,6.06250346750899E-8,-8.4705859382638E-5,-4.36415317459909E-7,29.9991093,29.9991093,-7005.99072265625,-7002.6591796875,57.4231207938138,20.7195857487241,15.695635,0,0,0,40,4449,29.8983,-7004.32495117187,,,,,,,,,,,,,0,,,,0,,,,,,29.9991093,,,,
,29395290.42,30.0006027,-6558.99389648438,-8.7515876042479E-5,3.98963386649412E-7,1,0.999253354069792,40.0298881530762,1.98913096050751,16.8999992311001,-0.000981433240523153,-0.00016878441378689,0.25,5.61867925384972E-7,-8.70986187010064E-5,5.06911964994219E-8,30.0006027,30.0006027,-6562.65283203125,-6555.3349609375,57.6552644640253,20.7162499007631,15.315984,0,0,0,40,4449,29.89775,-6558.99389648438,,,,,,,,,,,,,0,,,,-0.00245,,,,,,30.0006027,,,,
,29395308.065,30.0000324,-6118.01245117187,-9.04855158453402E-5,3.99545362272171E-7,1,0.999253354069792,40.0298881530762,1.98917957180696,16.8999992311001,-0.00101522774103937,-0.000171701618130365,0.25,8.29307711961496E-7,-9.0052599868946E-5,3.01918050821108E-7,30.0000324,30.0000324,-6123.3193359375,-6112.70556640625,57.4199942797368,20.7174769515834,15.695635,0,0,0,40,4449,29.89715,-6118.01245117187,,,,,,,,,,,,,0,,,,0,,,,,,30.0000324,,,,
,29395325.345,30.0020714,-5686.9033203125,-9.20816391051031E-5,4.63861956282967E-7,1,0.999253354069792,40.0298881530762,1.98897334022005,16.8999992311001,-0.00103145246635735,-0.000183381059632966,0.25,6.7201101002872E-8,-9.16337386155714E-5,-4.63413400714004E-7,30.0020714,30.0020714,-5692.49072265625,-5681.31591796875,57.3238539718714,20.7167573651078,15.695635,0,0,0,40,4449,29.89735,-5686.9033203125,,,,,,,,,,,,,0,,,,0,,,,,,30.0020714,,,,
,29395342.575,30.0002193,-5255.8447265625,-9.27634415710801E-5,4.06124223264408E-7,1,0.999253354069792,40.0298881530762,1.98952740030659,16.8999992311001,-0.00103992062455563,-0.000181495211167125,0.25,3.58774324258246E-7,-9.23110427765531E-5,-1.74850647176451E-7,30.0002193,30.0002193,-5256.79248046875,-5254.89697265625,57.5184794731599,20.7089170521209,16.075285,0,0,0,40,4449,29.8951,-5255.8447265625,,,,,,,,,,,,,0,,,,-0.0049,,,,,,30.0002193,,,,
,29395360.56,29.9876251,-4807.00561523438,-9.3803424058685E-5,3.64942089305799E-7,1,0.999253354069792,40.0298881530762,1.98957979804235,16.8999992311001,-0.00105013052560195,-0.00019161412404225,0.25,-3.61270232636452E-7,-9.33389835160609E-5,-8.94960266279415E-7,29.9876251,29.9876251,-4810.74853515625,-4803.2626953125,57.4958122461022,20.7136554889531,16.075285,0,0,0,40,4449,29.9033,-4807.00561523438,,,,,,,,,,,,,0,,,,0,,,,,,29.9876251,,,,
,29395378.135,30.0041771,-4367.79052734375,-9.63045800549524E-5,3.12174474761589E-7,1,0.999253354069792,40.0298881530762,1.98895237140752,16.8999992311001,-0.0010773969047812,-0.000198769676307257,0.25,-5.61872870250487E-7,-9.58237870551043E-5,-1.10641018558743E-6,30.0041771,30.0041771,-4373.0810546875,-4362.5,57.5630322987561,20.7177035910589,15.695635,0,0,0,40,4449,29.90265,-4367.79052734375,,,,,,,,,,,,,0,,,,-0.00245,,,,,,30.0041771,,,,
,29395395.81,29.9994478,-3927.27722167969,-9.69974448861707E-5,4.08517709251249E-7,1,0.999253354069792,40.0298881530762,1.98897748150995,16.8999992311001,-0.00108663262160047,-0.000191767175982801,0.25,1.8426581787236E-7,-9.65145380039049E-5,-3.65435364942022E-7,29.9992504,29.9996452,-3931.197265625,-3923.35717773438,57.5262957583522,20.7165874188684,15.695635,0,0,0,40,4449,29.8957,-3927.27722167969,,,,,,,,,,,,,0,,,,0,,,,,,29.9994478,,,,
,29395412.74,29.9968929,-3504.02368164063,-9.8167582078078E-5,3.51427788855045E-7,1,0.999253354069792,40.0298881530762,1.98911013872761,16.8999992311001,-0.00109935197855079,-0.000196496202152847,0.25,-3.08142021152922E-8,-9.7675003349709E-5,-5.83812158250392E-7,29.9968929,29.9968929,-3511.61376953125,-3496.43359375,57.5528711280061,20.7156250212178,15.315984,0,0,0,40,4449,29.9028,-3504.02368164063,,,,,,,,,,,,,0,,,,-0.00245,,,,,,29.9968929,,,,
,29395429.86,30.0023708,-3077.10717773438,-9.86030321300112E-5,3.49543855425453E-7,1,0.999253354069792,40.0298881530762,1.98815090019412,16.8999992311001,-0.00110399800787399,-0.000195541648257748,0.25,1.21246136385406E-7,-9.81064232081571E-5,-4.32632946957153E-7,30.0023708,30.0023708,-3079.73095703125,-3074.4833984375,57.4426615067945,20.7283204182714,15.695635,0,0,0,40,4449,29.89965,-3077.10717773438,,,,,,,,,,,,,0,,,,-0.00245,,,,,,30.0023708,,,,
,29395447.86,29.99757,-2626.19348144531,-9.80862638661733E-5,3.3411870185438E-7,1,0.999253354069792,40.0298881530762,1.98875261398352,16.8999992311001,-0.00109800508274265,-0.000197333292377307,0.25,-1.28802389920976E-7,-9.75881167259972E-5,-6.76110412842849E-7,29.99757,29.99757,-2629.931640625,-2622.45532226562,57.596642325083,20.717273241395,15.315984,0,0,0,40,4449,29.8964,-2626.19348144531,,,,,,,,,,,,,0,,,,0.00245,,,,,,29.99757,,,,
,29395465.32,29.9995384,-2190.35229492187,-9.57418663932011E-5,3.18461952555463E-7,1,0.999253354069792,40.0298881530762,1.98878593650921,16.8999992311001,-0.00107136493100803,-0.000194782720026533,0.25,-3.2142400225124E-7,-9.52521606903497E-5,-8.5254759973097E-7,29.9995384,29.9995384,-2192.79467773438,-2187.90991210938,57.5059734168522,20.7191609672778,15.695635,0,0,0,40,4449,29.9049,-2190.35229492187,,,,,,,,,,,,,0,,,,-0.0049,,,,,,29.9995384,,,,
,29395482.8,29.9985809,-1754.08837890625,-9.20237450287636E-5,2.99598123008725E-7,1,0.999253354069792,40.0298881530762,1.98855761704447,16.8999992311001,-0.00102965984333401,-0.000186968223574889,0.25,-2.90910751013873E-7,-9.15508569317489E-5,-7.99433746070981E-7,29.9985809,29.9985809,-1757.81372070313,-1750.36303710938,57.5278590153907,20.7236029921554,15.695635,0,0,0,40,4449,29.90195,-1754.08837890625,,,,,,,,,,,,,0,,,,0,,,,,,29.9985809,,,,
,29395500.75,29.9977055,-1305.35021972656,-8.58016502697605E-5,2.68652376507948E-7,1,0.999253354069792,40.0298881530762,1.98879639817956,16.8999992311001,-0.000959723629732167,-0.000176605123947718,0.25,-4.75212538217637E-7,-8.53575391769463E-5,-9.46425839625677E-7,29.9977055,29.9977055,-1307.90344238281,-1302.79699707031,57.3433946848522,20.714695942999,15.315984,0,0,0,40,4449,29.9013,-1305.35021972656,,,,,,,,,,,,,0,,,,0,,,,,,29.9977055,,,,
,29395518.06,29.9984913,-871.848480224609,-7.37163980741612E-5,3.03313508834311E-7,1,0.999253354069792,40.0298881530762,1.98869566189713,16.8999992311001,-0.000824411334955994,-0.000152147445062759,0.25,-4.47961577030424E-7,-7.33330262692637E-5,-8.51134036441205E-7,29.9984913,29.9984913,-875.394348144531,-868.302612304687,57.4934673605446,20.7209636157134,15.695635,0,0,0,40,4449,29.9011,-871.848480224609,,,,,,,,,,,,,0,,,,0.00245,,,,,,29.9984913,,,,
,29395534.97,30.0014133,-449.632232666016,-5.12465668182043E-5,3.88013337717601E-7,1,0.999253354069792,40.0298881530762,1.98860829200942,16.8999992311001,-0.000572623357950456,-0.000108345685085962,0.25,-5.42918536182126E-7,-5.09777931203727E-5,-8.21081655769015E-7,30.0014133,30.0014133,-453.236083984375,-446.028381347656,57.3566823696791,20.7246957749559,16.075285,0,0,0,40,4449,29.89825,-449.632232666016,,,,,,,,,,,,,0,,,,0,,,,,,30.0014133,,,,
,29395552.53,29.9989548,-10.7361471652985,-1.59368195009007E-6,3.50170992400922E-7,1,0.999253354069792,40.0298881530762,1.98836240959577,16.8999992311001,-1.72397004344828E-5,-6.54180089939906E-6,0.25,-3.00362521711709E-7,-1.58374894344132E-6,-3.07515334993284E-7,29.9989548,29.9989548,-16.1349449157715,-5.33734941482544,57.3996719382368,20.7258688993685,15.695635,0,0,0,40,4449,29.899,-10.7361471652985,,,,,,,,,,,,,0,,,,-0.00245,,,,,,29.9989548,,,,
,29395570.085,29.9949894,427.675262451172,5.81494435719987E-5,3.53482410682634E-7,1,0.999253354069792,40.0298881530762,1.98851328063268,16.8999992311001,0.000650904002865985,0.000116322705063932,0.25,2.54742659186507E-8,5.78476854827236E-5,3.44149372789544E-7,29.9949894,29.9949894,421.502563476562,433.847961425781,57.6310339799292,20.7242644282721,16.075285,0,0,0,40,4449,29.9032,427.675262451172,,,,,,,,,,,,,0,,,,-0.00245,,,,,,29.9949894,,,,
,29395586.765,29.9919243,844.089569091797,7.96197010635026E-5,3.19836997047573E-7,1,0.999253354069792,40.0298881530762,1.9886988355595,16.8999992311001,0.000891129258987201,0.000160420409610667,0.25,1.34529318029396E-7,7.9207493271278E-5,5.71738548987662E-7,29.9919243,29.9919243,840.218078613281,847.961059570312,57.4840878183138,20.7273295054809,15.315984,0,0,0,40,4449,29.90625,844.089569091797,,,,,,,,,,,,,0,,,,0,,,,,,29.9919243,,,,
,29395605.15,30.0028267,1303.57379150391,9.04849434033094E-5,3.74972429075538E-7,1,0.999253354069792,40.0298881530762,1.9885694454361,16.8999992311001,0.00101287593085405,0.000181300624285912,0.25,6.130618445597E-8,9.00190460893806E-5,5.60529481659579E-7,30.0028267,30.0028267,1297.42126464844,1309.72631835938,57.5411467002176,20.7229507459846,15.315984,0,0,0,40,4449,29.90505,1303.57379150391,,,,,,,,,,,,,0,,,,0,,,,,,30.0028267,,,,
,29395623.775,29.9998684,1767.7958984375,9.60159594975813E-5,3.15826525570483E-7,1,0.999253354069792,40.0298881530762,1.98844126052038,16.8999992311001,0.0010747291229681,0.000192490868931744,0.25,7.32322557880764E-8,9.55238774978098E-5,6.05036540519778E-7,29.9998684,29.9998684,1763.9462890625,1771.6455078125,57.3301070000253,20.7257877891625,15.695635,0,0,0,40,4449,29.8994,1767.7958984375,,,,,,,,,,,,,0,,,,0,,,,,,29.9998684,,,,
,29395641.55,30.0015373,2210.34741210938,9.81655746775204E-5,2.90710383585864E-7,1,0.999253354069792,40.0298881530762,1.98840164040669,16.8999992311001,0.00109957496523416,0.000192442750207653,0.25,-3.16726488194957E-7,9.76671511308342E-5,2.31210255878819E-7,30.0015373,30.0015373,2207.78344726562,2212.91137695313,57.3535558556022,20.7225471121696,15.695635,0,0,0,40,4449,29.90215,2210.34741210938,,,,,,,,,,,,,0,,,,0.0049,,,,,,30.0015373,,,,
,29395659.205,29.9991493,2652.14379882813,9.95469201658981E-5,2.85902785286254E-7,1,0.999253354069792,40.0298881530762,1.9884719065128,16.8999992311001,0.00111487578577869,0.000196500061901148,0.25,-2.03956021173825E-7,9.90433930010383E-5,3.53348071301217E-7,29.9991493,29.9991493,2647.3310546875,2656.95654296875,57.383257739333,20.725646474267,15.695635,0,0,0,40,4449,29.8976,2652.14379882813,,,,,,,,,,,,,0,,,,0.0049,,,,,,29.9991493,,,,
,29395677.93,29.9985313,3119.46618652344,0.000100112864688296,3.51605321728456E-7,1,0.999253354069792,40.0298881530762,1.98863677109176,16.8999992311001,0.00112096630750443,0.0001997107051395,0.25,-2.26082621464941E-8,9.96083751057573E-5,5.39493226970298E-7,29.9985313,29.9985313,3114.23779296875,3124.69458007812,57.6302523514099,20.7224482329387,16.075285,0,0,0,40,4449,29.90145,3119.46618652344,,,,,,,,,,,,,0,,,,0.00245,,,,,,29.9985313,,,,
,29395695.205,30.0005226,3551.8837890625,9.92415431634063E-5,4.09229602590969E-7,1,0.999253354069792,40.0298881530762,1.98856374207385,16.8999992311001,0.00111232968631094,0.000191650896621796,0.25,-5.89261598179538E-7,9.87473745099694E-5,-2.68415964400517E-8,30.0005226,30.0005226,3546.6943359375,3557.0732421875,57.4817429327561,20.7255835667755,15.315984,0,0,0,40,4449,29.9027,3551.8837890625,,,,,,,,,,,,,0,,,,-0.00245,,,,,,30.0005226,,,,
,29395712.795,29.9991474,3992.12878417969,9.89619027404125E-5,3.84461930113894E-7,1,0.999253354069792,40.0298881530762,1.98855177387579,16.8999992311001,0.00111003077440857,0.000186578877535102,0.25,-9.95190049192579E-7,9.84742848261924E-5,-4.29908478194674E-7,29.9991474,29.9991474,3989.41235351562,3994.84521484375,57.3988903097176,20.7273023737621,16.075285,0,0,0,40,4449,29.9025,3992.12878417969,,,,,,,,,,,,,0,,,,0,,,,,,29.9991474,,,,
,29395731.085,29.9993477,4448.46557617188,9.78261936265154E-5,3.55435693775098E-7,1,0.999253354069792,40.0298881530762,1.98849241589271,16.8999992311001,0.00109646890750754,0.000189064417127544,0.25,-5.73106115057296E-7,9.73448402382229E-5,-1.38480402326872E-8,29.9993477,29.9993477,4442.00146484375,4454.9296875,57.6341604940061,20.7266550050123,15.315984,0,0,0,40,4449,29.90245,4448.46557617188,,,,,,,,,,,,,0,,,,0,,,,,,29.9993477,,,,
,29395748.6,29.9990005,4887.11645507812,9.50489698417722E-5,3.17925979774208E-7,1,0.999253354069792,40.0298881530762,1.98873037340166,16.8999992311001,0.00106681612632754,0.000176321423241928,0.25,-1.22022614646317E-6,9.45879246386794E-5,-6.71211830102483E-7,29.9990005,29.9990005,4884.7724609375,4889.46044921875,57.5638139272753,20.7208019577546,15.315984,0,0,0,40,4449,29.90185,4887.11645507812,,,,,,,,,,,,,0,,,,-0.00245,,,,,,29.9990005,,,,
,29395765.655,29.9977036,5313.169921875,9.32927485267876E-5,4.22066448873228E-7,1,0.999253354069792,40.0298881530762,1.98881003595025,16.8999992311001,0.001047424867605,0.000171684937960323,0.25,-1.32416256347189E-6,9.2843774464352E-5,-7.82386668122584E-7,29.9977036,29.9977036,5309.1142578125,5317.2255859375,57.5739750980253,20.7204625377968,15.315984,0,0,0,40,4449,29.9047,5313.169921875,,,,,,,,,,,,,0,,,,-0.0049,,,,,,29.9977036,,,,
,29395784.09,29.9986649,5774.06469726563,9.26668715946722E-5,4.02833652936315E-7,1,0.999253354069792,40.0298881530762,1.98868807767213,16.8999992311001,0.00104079359297775,0.000168167381429448,0.25,-1.52865100654784E-6,9.22252199374538E-5,-9.87014077694713E-7,29.9986649,29.9986649,5768.939453125,5779.18994140625,57.5653771843138,20.723928860935,15.695635,0,0,0,40,4449,29.90635,5774.06469726563,,,,,,,,,,,,,0,,,,-0.0049,,,,,,29.9986649,,,,
,29395803.24,29.9986782,6252.69213867187,9.07254969370551E-5,3.52296703804176E-7,1,0.999253354069792,40.0298881530762,1.98828431663416,16.8999992311001,0.00102134717551888,0.000150505017209409,0.25,-2.75959595304369E-6,9.03035499244512E-5,-2.22074869877023E-6,29.9986782,29.9986782,6249.00341796875,6256.380859375,57.5755383550638,20.7294824820906,16.075285,0,0,0,40,4449,29.90235,6252.69213867187,,,,,,,,,,,,,0,,,,-0.00245,,,,,,29.9986782,,,,
,29395820.905,30.0009689,6693.76708984375,8.73717774178849E-5,4.02162209117762E-7,1,0.999253354069792,40.0298881530762,1.98848395109733,16.8999992311001,0.000983606114659005,0.0001455963516385,0.25,-2.60304876619685E-6,8.69680073319362E-5,-2.08219810533616E-6,30.0009689,30.0009689,6691.4267578125,6696.107421875,57.5341120435445,20.7262239583518,15.695635,0,0,0,40,4449,29.9023,6693.76708984375,,,,,,,,,,,,,0,,,,-0.0049,,,,,,30.0009689,,,,
,29395834.905,30.0014496,7043.2099609375,8.65030635489743E-5,4.50992353133201E-7,1,0.999253354069792,40.0298881530762,1.98855850332119,16.8999992311001,0.000972669720886124,0.000150973628182244,0.25,-1.97030775384484E-6,8.61020491115945E-5,-1.45582384230416E-6,30.0014496,30.0014496,7038.6142578125,7047.8056640625,57.5669404413522,20.7233307580055,15.695635,0,0,0,40,4449,29.9005,7043.2099609375,,,,,,,,,,,,,0,,,,-0.00245,,,,,,30.0014496,,,,
,29395870.775,29.998867,7147.580078125,8.43215255264954E-5,4.52024052106211E-7,1,0.999253354069792,40.0298881530762,1.98841817806559,16.8999992311001,0.000948804028674809,0.000143125525663339,0.25,-2.28121615884757E-6,8.39334298056699E-5,-1.77746613674151E-6,29.998867,29.998867,7143.6142578125,7151.5458984375,57.423902422333,20.7255344664409,15.695635,0,0,0,40,4449,29.90305,7147.580078125,,,,,,,,,,,,,0,,,,0,,,,,,29.998867,,,,
,29395888.965,29.9998741,6693.48999023437,8.68853406088345E-5,4.57264110790056E-7,1,0.999253354069792,40.0298881530762,1.98855236097203,16.8999992311001,0.000978140987656242,0.000144907447244416,0.25,-2.57809685956707E-6,8.64837394397918E-5,-2.06021027267349E-6,29.9998741,29.9998741,6689.59326171875,6697.38671875,57.3762230826599,20.7243965994559,15.695635,0,0,0,40,4449,29.9006,6693.48999023437,,,,,,,,,,,,,0,,,,0,,,,,,29.9998741,,,,
,29395906.245,29.9968014,6262.05078125,8.99869904205903E-5,3.47587651544894E-7,1,0.999253354069792,40.0298881530762,1.98868618958957,16.8999992311001,0.00101368979962296,0.000146731537808041,0.25,-2.96731151272867E-6,8.95698666347427E-5,-2.43169859875238E-6,29.9968014,29.9968014,6258.23876953125,6265.86279296875,57.5044101598138,20.7229212507774,15.695635,0,0,0,40,4449,29.9015,6262.05078125,,,,,,,,,,,,,0,,,,0,,,,,,29.9968014,,,,
,29395924.005,29.9978313,5819.14965820312,9.25909624376204E-5,4.35657982019442E-7,1,0.999253354069792,40.0298881530762,1.98889938220329,16.8999992311001,0.00104082317426429,0.000163714877511007,0.25,-1.91443995778845E-6,9.21521786923172E-5,-1.37115057428933E-6,29.9978313,29.9978313,5813.74853515625,5824.55078125,57.5958606965638,20.7216661943512,15.695635,0,0,0,40,4449,29.90355,5819.14965820312,,,,,,,,,,,,,0,,,,0.00245,,,,,,29.9978313,,,,
,29395941.82,29.9978333,5375.20922851562,9.26256480693579E-5,3.95652320499677E-7,1,0.999253354069792,40.0298881530762,1.98890063737904,16.8999992311001,0.00104061719441274,0.000166924806004585,0.25,-1.63118021569912E-6,9.21821182207081E-5,-1.0913966409347E-6,29.9978333,29.9978333,5370.41748046875,5380.0009765625,57.4715817620061,20.7210338399641,15.695635,0,0,0,40,4449,29.90545,5375.20922851562,,,,,,,,,,,,,0,,,,-0.00245,,,,,,29.9978333,,,,
,29395959.56,29.99812315,4931.83081054687,9.54757076027017E-5,3.7701501506099E-7,1,0.999253354069792,40.0298881530762,1.98883469839798,16.8999992311001,0.00107348455326281,0.000166919213846691,0.25,-2.13709314990624E-6,9.50181396239328E-5,-1.58085528268147E-6,29.9971962,29.9990501,4928.126953125,4935.53466796875,57.5552160135638,20.722495984949,15.315984,0,0,0,40,4449,29.9055,4931.83081054687,,,,,,,,,,,,,0,,,,0,,,,,,29.99812315,,,,
,29395978.08,29.9938126,4469.00732421875,9.58008792314693E-5,3.33192987288636E-7,1,0.999253354069792,40.0298881530762,1.98880457646157,16.8999992311001,0.00107649045413539,0.000170837932224355,0.25,-1.84193644898574E-6,9.53369246624598E-5,-1.28779447279945E-6,29.9938126,29.9938126,4461.3408203125,4476.673828125,57.5645955557946,20.7212600724277,15.695635,0,0,0,40,4449,29.9034,4469.00732421875,,,,,,,,,,,,,0,,,,0.00245,,,,,,29.9938126,,,,
,29395995.575,29.9983025,4032.92858886719,9.89716306628033E-5,3.0441307257305E-7,1,0.999253354069792,40.0298881530762,1.98894011675717,16.8999992311001,0.00111131312384816,0.000181240371703981,0.25,-1.47709227382501E-6,9.84870447381E-5,-9.09062980792366E-7,29.9983025,29.9983025,4031.40942382812,4034.44775390625,57.6365053795638,20.7206238109546,15.695635,0,0,0,40,4449,29.90975,4032.92858886719,,,,,,,,,,,,,0,,,,0,,,,,,29.9983025,,,,
,29396012.705,30.002018,3604.4169921875,9.89709220384495E-5,3.76092508828292E-7,1,0.999253354069792,40.0298881530762,1.98901556412008,16.8999992311001,0.00110985157847442,0.000189431110006553,0.25,-7.43277626166821E-7,9.84793387864182E-5,-1.81304422208034E-7,30.002018,30.002018,3601.88037109375,3606.95361328125,57.4700185049676,20.719284012074,16.075285,0,0,0,40,4449,29.9049,3604.4169921875,,,,,,,,,,,,,0,,,,-0.0049,,,,,,30.002018,,,,
,29396030.2,29.9925594,3167.32348632812,9.88781758268235E-5,3.34649927461735E-7,1,0.999253354069792,40.0298881530762,1.98919256016273,16.8999992311001,0.00110878421915109,0.000189771225842376,0.25,-6.94960914100135E-7,9.83840387525578E-5,-1.3610032104513E-7,29.9925594,29.9925594,3162.49658203125,3172.150390625,57.5896076684099,20.7167480931764,15.315984,0,0,0,40,4449,29.9062,3167.32348632812,,,,,,,,,,,,,0,,,,-0.00735,,,,,,29.9925594,,,,
,29396047.15,29.9976902,2743.85864257813,9.95425743697268E-5,3.2857100818005E-7,1,0.999253354069792,40.0298881530762,1.98890458705266,16.8999992311001,0.00111543316408544,0.00019447992290245,0.25,-3.87981751806485E-7,9.90408107003959E-5,1.70851909588605E-7,29.9976902,29.9976902,2737.8564453125,2749.86083984375,57.6966907755446,20.7194321910746,15.315984,0,0,0,40,4449,29.91165,2743.85864257813,,,,,,,,,,,,,0,,,,0.00245,,,,,,29.9976902,,,,
,29396065.81,29.9970875,2276.48986816406,9.96401205029527E-5,4.17559447522973E-7,1,0.999253354069792,40.0298881530762,1.9885417493178,16.8999992311001,0.00111643001063046,0.000193898669616224,0.25,-4.5126377777947E-7,9.91353606478068E-5,1.05938854357405E-7,29.9970875,29.9970875,2272.86547851562,2280.1142578125,57.3801312252561,20.7230837243512,15.315984,0,0,0,40,4449,29.9057,2276.48986816406,,,,,,,,,,,,,0,,,,0,,,,,,29.9970875,,,,
,29396084.63,29.9960194,1807.09234619141,9.73738898744305E-5,2.77039879125635E-7,1,0.999253354069792,40.0298881530762,1.98909256658375,16.8999992311001,0.0010905783447264,0.000193565323788841,0.25,-7.87009068231648E-8,9.68760334728223E-5,4.61707229559738E-7,29.9960194,29.9960194,1803.32678222656,1810.85791015625,57.5497446139292,20.7205376494235,15.695635,0,0,0,40,4449,29.9106,1807.09234619141,,,,,,,,,,,,,0,,,,0,,,,,,29.9960194,,,,
,29396101.555,29.9999809,1383.53558349609,9.41022523418932E-5,2.8336277001957E-7,1,0.999253354069792,40.0298881530762,1.98872502073362,16.8999992311001,0.00105393690170809,0.000185839022226002,0.25,-1.7996380703926E-7,9.36195057392928E-5,3.4085665782696E-7,29.9999809,29.9999809,1378.68298339844,1388.38818359375,57.6826214621984,20.7224521040701,15.315984,0,0,0,40,4449,29.90825,1383.53558349609,,,,,,,,,,,,,0,,,,0,,,,,,29.9999809,,,,
,29396119.98,29.9930878,922.295837402344,8.69289179070672E-5,3.34244828184939E-7,1,0.999253354069792,40.0298881530762,1.98930291275843,16.8999992311001,0.000973502020936095,0.000173628815389014,0.25,6.40920091419086E-9,8.64799574064729E-5,4.84769500523661E-7,29.9930878,29.9930878,918.311279296875,926.280395507812,57.4356268501215,20.7167757475166,15.695635,0,0,0,40,4449,29.9052,922.295837402344,,,,,,,,,,,,,0,,,,0.0049,,,,,,29.9930878,,,,
,29396137.265,29.99724865,490.916244506836,7.42892003089564E-5,3.10408619227534E-7,1,0.999253354069792,40.0298881530762,1.9891726715409,16.8999992311001,0.000831774221288844,0.000148985231291657,0.25,6.16759410886329E-8,7.39037813121269E-5,4.68884490081285E-7,29.9969769,29.9975204,485.616973876953,496.215515136719,57.4653287338522,20.718038541424,15.315984,0,0,0,40,4449,29.9101,490.916244506836,,,,,,,,,,,,,0,,,,0.00245,,,,,,29.99724865,,,,
,29396154.87,30.0025158,51.52685546875,3.91576917760732E-5,3.55389917012062E-7,1,0.999253354069792,40.0298881530762,1.98890706456684,16.8999992311001,0.000438588847631879,7.72534403545337E-5,0.25,-7.98854054514968E-8,3.89545074930191E-5,1.34744334868709E-7,30.0025158,30.0025158,49.0476455688477,54.0060653686523,57.3699700545061,20.7201450247692,15.695635,0,0,0,40,4449,29.9085,51.52685546875,,,,,,,,,,,,,0,,,,0,,,,,,30.0025158,,,,
,29396157.405,30.0000114,0.258804142475128,3.12511785869144E-5,3.60175045173643E-7,1,0.999253354069792,40.0298881530762,1.98896644949473,16.8999992311001,0.000350461448282872,5.92960807032797E-5,0.25,-2.74519058846488E-7,3.1090121929059E-5,-1.02177174463239E-7,30.0000114,30.0000114,0.228356599807739,0.289251685142517,57.5802281261792,20.7210179306415,15.695635,0,0,0,40,4417,29.9042,0.258804142475128,,,,,,,,,,,,,0,,,,-0.0049,,,,,,30.0000114,,,,