File: data/looselyPackedNP/sc-ios-7/ppms/rawdata/ES_S17_HYST_10K.DAT
[Header]
; VSM Data File (default extension .dat)
; Copyright (c) 2003-2013, Quantum Design, Inc. All rights reserved.
TITLE,
FILEOPENTIME,29229639.31,12/05/2018,3:21 pm
BYAPP,VSM,2.0,2.0
INFO,PPMS VSM Option Release 1.4.10 Build 1,APPNAME
INFO,Quantum Design Linear Motor Servo Controller,MOTOR_MODULE_NAME
INFO,3101-100 M1,MOTOR_HW_VERSION
INFO,MMC1014,MOTOR_SERIAL_NUMBER
INFO,SRV No X-over 01.03.11,MOTOR_SOFTWARE_VERSION
INFO,Quantum Design VSM Detection Module,VSM_MODULE_NAME
INFO,3101-150 F0,VSM_HW_VERSION
INFO,VSM707,VSM_SERIAL_NUMBER
INFO,VSM No X-over 01.02.05 May 20 2008 13:51:47,VSM_SOFTWARE_VERSION
INFO,704,PREAMP_SERIAL_NUMBER
INFO,822,COIL_SERIAL_NUMBER
INFO,0,MOMENT_UNITS
INFO,Iron Oxide Spheres,SAMPLE_MATERIAL
INFO,7 nm diameter, collaboration Mainz,SAMPLE_COMMENT
INFO,,SAMPLE_MASS
INFO,,SAMPLE_VOLUME
INFO,,SAMPLE_MOLECULAR_WEIGHT
INFO,,SAMPLE_SIZE
INFO,,SAMPLE_SHAPE
DATATYPE,COMMENT,1
DATATYPE,TIME,2
STARTUPAXIS,X,2
STARTUPAXIS,Y1,5
[Data]
Comment,Time Stamp (sec),Temperature (K),Magnetic Field (Oe),Moment (emu),M. Std. Err. (emu),Transport Action,Averaging Time (sec),Frequency (Hz),Peak Amplitude (mm),Center Position (mm),Coil Signal' (mV),Coil Signal" (mV),Range (mV),M. Quad. Signal (emu),M. Raw' (emu),M. Raw" (emu),Min. Temperature (K),Max. Temperature (K),Min. Field (Oe),Max. Field (Oe),Mass (grams),Motor Lag (deg),Pressure (Torr),VSM Status (code),Motor Status (code),Measure Status (code),Measure Count,PPMS Status (code),System Temp. (K),System Field (Oe),Sample Position (deg),Bridge 1 Resistance (ohms),Bridge 1 Excitation (에),Bridge 2 Resistance (ohms),Bridge 2 Excitation (에),Bridge 3 Resistance (ohms),Bridge 3 Excitation (에),Bridge 4 Resistance (ohms),Bridge 4 Excitation (에),Signal 1 Vin (V),Signal 2 Vin (V),Digital Inputs (code),Drive 1 Iout (mA),Drive 1 Ipower (W),Drive 2 Iout (mA),Drive 2 Ipower (W),Pressure (),Map 20 (),Map 21 (),Map 22 (),Map 23 (),Map 24 (),Map 25 (),Map 26 (),Map 27 (),Map 28 (),Map 29 ()
,29229891.89,10.0560999,-0.1674614995718,-3.71965262016361E-6,3.47651211619153E-7,1,0.999253354069792,40.0298881530762,1.99834153886597,16.6500005871058,-4.10678234430361E-5,-1.16474149005675E-5,0.25,-3.75523612822281E-7,-3.69647445392426E-6,-3.91294825751226E-7,10.0560999,10.0560999,-0.1674614995718,-0.1674614995718,56.1342153656021,20.7393046829337,11.899124,0,0,0,40,4417,9.7627,-0.1674614995718,,,,,,,,,,,,,0,,,,0,,,,,,10.0560999,,,,
,29230004.305,10.0378609,4633.58447265625,9.82994535321953E-5,1.27193370544584E-6,1,0.999253354069792,40.0298881530762,1.99869689006312,16.6500005871058,0.00110446544741498,0.000202601125639125,0.25,5.30623757904146E-7,9.77568188933273E-5,1.02919693850334E-6,10.0378609,10.0378609,4626.087890625,4641.0810546875,57.0862389020253,20.7461431736602,12.658426,0,0,0,40,4449,9.73025,4633.58447265625,,,,,,,,,,,,,0,,,,-0.00245,,,,,,10.0378609,,,,
,29230099.075,10.0192051,9369.82666015625,7.76863088074388E-5,2.65659617709127E-6,1,0.999253354069792,40.0298881530762,1.99905565027601,16.6500005871058,0.000885148389025878,9.38109775659881E-5,0.25,-5.50782263912502E-6,7.73166123456806E-5,-5.05629628395853E-6,10.0192051,10.0192051,9362.466796875,9377.1865234375,57.1808159528522,20.7484228653554,12.278775,0,0,0,40,4449,9.7145,9369.82666015625,,,,,,,,,,,,,0,,,,0,,,,,,10.0192051,,,,
,29230196.61,10.01429985,14244.9194335938,4.59923231442264E-5,2.67596875605026E-6,1,0.999253354069792,40.0298881530762,1.99807180717527,16.6500005871058,0.000550272868493891,-9.14882510662249E-5,0.25,-1.63456751394524E-5,4.58694969590017E-5,-1.60013824142819E-5,10.0138273,10.0147724,14234.990234375,14254.8486328125,56.8290831191983,20.755168365146,12.658426,0,0,0,40,4449,9.70525,14244.9194335938,,,,,,,,,,,,,0,,,,0,,,,,,10.01429985,,,,
,29230293.695,10.00808095,19097.236328125,1.45717793803621E-5,3.06884980344691E-6,1,0.999253354069792,40.0298881530762,1.99824963369662,16.6500005871058,0.000164757738357762,2.52068100550889E-5,0.25,-3.67897362285314E-7,1.45116249315531E-5,-2.7687898152389E-7,10.0077467,10.0084152,19087.296875,19107.17578125,57.2761746321984,20.7529875253227,12.658426,0,0,0,40,4449,9.6961,19097.236328125,,,,,,,,,,,,,0,,,,-0.00245,,,,,,10.00808095,,,,
,29230390.225,10.0029135,23922.353515625,-1.49319985627543E-5,5.29352741059068E-6,1,0.999253354069792,40.0298881530762,1.99809051902954,16.6500005871058,-0.000146466456221925,-0.000151000638742134,0.25,-1.07342552061696E-5,-1.48060418629263E-5,-1.07895479161105E-5,10.0029135,10.0029135,23909.8984375,23934.80859375,56.9783741663714,20.7559282736293,12.658426,0,0,0,40,4449,9.69565,23922.353515625,,,,,,,,,,,,,0,,,,-0.0049,,,,,,10.0029135,,,,
,29230484.87,10.0006933,28650.322265625,-5.12705706569902E-5,8.09635042332917E-6,1,0.999253354069792,40.0298881530762,1.99761519603833,16.6500005871058,-0.000556564935276796,-0.000219820800540583,0.25,-1.03151721919393E-5,-5.10312737540461E-5,-1.06243289579003E-5,10.0006933,10.0006933,28647.95703125,28652.6875,57.0455942190253,20.7539356858967,12.658426,0,0,0,40,4449,9.6962,28650.322265625,,,,,,,,,,,,,0,,,,0,,,,,,10.0006933,,,,
,29230581.665,9.997139,33488.189453125,-7.55262347106062E-5,1.13269195903763E-5,1,0.999253354069792,40.0298881530762,1.99846318527563,16.6500005871058,-0.000793030797927648,-0.000477416696917166,0.25,-2.87793835738188E-5,-7.51147730860701E-5,-2.92212711692678E-5,9.997139,9.997139,33475.3828125,33500.99609375,57.3058765159291,20.7482334879164,12.658426,0,0,0,40,4449,9.6949,33488.189453125,,,,,,,,,,,,,0,,,,0.0049,,,,,,9.997139,,,,
,29230676.07,9.9955368,38207.873046875,-0.000130034917923667,1.76933984682781E-5,1,0.999253354069792,40.0298881530762,1.99788687715695,16.6500005871058,-0.00136518901644128,-0.000824375377967778,0.25,-4.97249138842009E-5,-0.000129381587211205,-5.05332530980175E-5,9.9955368,9.9955368,38197.73828125,38218.0078125,57.0049495360253,20.76276289324,12.278775,0,0,0,40,4449,9.6978,38207.873046875,,,,,,,,,,,,,0,,,,0.00245,,,,,,9.9955368,,,,
,29230772.85,9.9947901,43045.904296875,-0.000163470487798928,1.36191308989679E-5,1,0.999253354069792,40.0298881530762,1.99782305782216,16.6500005871058,-0.00176860753803002,-0.000749920043780061,0.25,-3.70516971563482E-5,-0.000162908219298638,-3.81687041376621E-5,9.9947901,9.9947901,43041.24609375,43050.5625,57.4434431353138,20.7656213285368,12.278775,0,0,0,40,4449,9.7012,43045.904296875,,,,,,,,,,,,,0,,,,-0.00735,,,,,,9.9947901,,,,
,29230866.94,9.9967146,47748.38671875,-0.000232844609257007,1.68081036211366E-5,1,0.999253354069792,40.0298881530762,1.99777855400076,16.6500005871058,-0.00257665699790126,-0.000755838632971121,0.25,-2.50318582751034E-5,-0.000232355976967141,-2.67081800765186E-5,9.9967146,9.9967146,47743.29296875,47753.48046875,57.1628384969099,20.7556281596075,12.658426,0,0,0,40,4449,9.7061,47748.38671875,,,,,,,,,,,,,0,,,,0.0049,,,,,,9.9967146,,,,
,29230962.845,9.997529,52540.806640625,-0.000280401593216811,1.84562215154055E-5,1,0.999253354069792,40.0298881530762,1.99740398927079,16.6500005871058,-0.00308762697472358,-0.00100054801141196,0.25,-3.81053151418404E-5,-0.000279888502541531,-4.01504859487908E-5,9.997529,9.997529,52531.01953125,52550.59375,56.7321611828137,20.7640391698086,12.658426,0,0,0,40,4449,9.7056,52540.806640625,,,,,,,,,,,,,0,,,,0,,,,,,9.997529,,,,
,29231057.125,10.000659,57253.251953125,-0.000345195381545489,2.61389815651758E-5,1,0.999253354069792,40.0298881530762,1.99733922150684,16.6500005871058,-0.00376492915429297,-0.00144197533088663,0.25,-6.5469678595975E-5,-0.000344583745896627,-6.8013603871477E-5,10.000659,10.000659,57248.34765625,57258.15625,56.9603967104291,20.7673182909361,11.899124,0,0,0,40,4449,9.7039,57253.251953125,,,,,,,,,,,,,0,,,,0,,,,,,10.000659,,,,
,29231152.8,9.9973259,62036.30859375,-0.000422622753096121,2.8064593896058E-5,1,0.999253354069792,40.0298881530762,1.99751000102837,16.6500005871058,-0.00458915150566341,-0.00189232255838701,0.25,-9.13035262630986E-5,-0.000421981169284081,-9.44568153439718E-5,9.9973259,9.9973259,62031.6171875,62041,56.6930797568522,20.76305082448,12.658426,0,0,0,40,4449,9.7066,62036.30859375,,,,,,,,,,,,,0,,,,0.00245,,,,,,9.9973259,,,,
,29231248.18,9.996336,66804.19921875,-0.000517679661540123,3.86386879635941E-5,1,0.999253354069792,40.0298881530762,1.99755027513971,16.6500005871058,-0.00561764709305297,-0.00235368799639408,0.25,-0.0001149220482781,-0.000517095450154042,-0.000118822915227026,9.996336,9.996336,66794.09375,66814.3046875,56.6532167023714,20.7690580469916,11.899124,0,0,0,40,4449,9.7109,66804.19921875,,,,,,,,,,,,,0,,,,-0.00245,,,,,,9.996336,,,,
,29231345.085,9.9991493,71647.04296875,-0.000783622255598809,4.13048628856977E-5,1,0.999253354069792,40.0298881530762,1.99744981832428,16.6500005871058,-0.0086153372431356,-0.00296144902204513,0.25,-0.000120699416487108,-0.000783462836119819,-0.000126591588011204,9.9991493,9.9991493,71642.1015625,71651.984375,57.2433462343907,20.7614489796159,12.278775,0,0,0,40,4449,9.70915,71647.04296875,,,,,,,,,,,,,0,,,,0.00245,,,,,,9.9991493,,,,
,29231438.025,9.9985514,76293.09375,-0.000664128282611091,4.34961368607029E-5,1,0.999253354069792,40.0298881530762,1.99755936371176,16.6500005871058,-0.007154571605854,-0.00334495808344081,0.25,-0.000176057767122046,-0.000663709416852917,-0.000181145870296426,9.9985514,9.9985514,76285.2578125,76300.9296875,57.3637170263522,20.761596193525,11.899124,0,0,0,40,4449,9.7079,76293.09375,,,,,,,,,,,,,0,,,,-0.0049,,,,,,9.9985514,,,,
,29231534.615,9.9994116,81118.953125,-0.000737613548685764,5.5084705313372E-5,1,0.999253354069792,40.0298881530762,1.99734834261182,16.6500005871058,-0.00788699887527219,-0.00405780662599245,0.25,-0.000225795225757812,-0.000737216405949212,-0.000231510630344732,9.9994116,9.9994116,81113.9609375,81123.9453125,57.5192611016792,20.771267694992,12.278775,0,0,0,40,4449,9.7057,81118.953125,,,,,,,,,,,,,0,,,,0,,,,,,9.9994116,,,,
,29231627.04,10.0045538,85739.51953125,-0.00101130697946194,4.19069637921095E-5,1,0.999253354069792,40.0298881530762,1.99707122929202,16.6500005871058,-0.0108727724306475,-0.00524880315921686,0.25,-0.000281765867030823,-0.00101132379272269,-0.000289559519916669,10.0045538,10.0045538,85732.1796875,85746.859375,57.251162519583,20.7790440817329,11.899124,0,0,0,40,4449,9.70935,85739.51953125,,,,,,,,,,,,,0,,,,-0.00245,,,,,,10.0045538,,,,
,29231737.465,10.0008607,89874.703125,-0.00100790032773433,5.28001615362056E-5,1,0.999253354069792,40.0298881530762,1.99700178162987,16.6500005871058,-0.0108172771972522,-0.00535374010515536,0.25,-0.000291619219562255,-0.00100814728499139,-0.000299401773769392,10.0003157,10.0014057,89865.3984375,89884.0078125,56.4421770021791,20.7734258849825,11.899124,0,0,0,40,4449,9.70765,89874.703125,,,,,,,,,,,,,0,,,,-0.00245,,,,,,10.0008607,,,,
,29231827.64,10.0053749,85374.14453125,-0.000878376069876861,4.27915280496277E-5,1,0.999253354069792,40.0298881530762,1.99700981564313,16.6500005871058,-0.00938380268200795,-0.0048879800617857,0.25,-0.000273822954457416,-0.00087815834148283,-0.000280650084204444,10.0053749,10.0053749,85364.1953125,85384.09375,57.180034324333,20.7792883223205,11.899124,0,0,0,40,4449,9.7011,85374.14453125,,,,,,,,,,,,,0,,,,0.00245,,,,,,10.0053749,,,,
,29231923.62,10.0069351,80575.4375,-0.000780015564274594,4.74242523238246E-5,1,0.999253354069792,40.0298881530762,1.99665487408777,16.6500005871058,-0.00846813991527588,-0.00356250408184296,0.25,-0.000174502122734218,-0.000780027478968479,-0.000180438800613098,10.0069351,10.0069351,80570.5234375,80580.3515625,57.0878021590637,20.7772460359018,12.278775,0,0,0,40,4449,9.6915,80575.4375,,,,,,,,,,,,,0,,,,0.00245,,,,,,10.0069351,,,,
,29232020.97,10.0009632,75708.84765625,-0.000637429576674811,1.64916208985651E-5,1,0.999253354069792,40.0298881530762,1.99677987818467,16.6500005871058,-0.00697496340665455,-0.00259341268029602,0.25,-0.000114525068879635,-0.000637395495254006,-0.000119337549214937,10.0009632,10.0009632,75701.4609375,75716.234375,57.2589788047753,20.7782046483221,11.899124,0,0,0,40,4449,9.70165,75708.84765625,,,,,,,,,,,,,0,,,,-0.00245,,,,,,10.0009632,,,,
,29232115.78,9.99019905,70968.0078125,-0.000529142959118761,1.71009275815765E-5,1,0.999253354069792,40.0298881530762,1.99655480632389,16.6500005871058,-0.00575351582875184,-0.00233835070558098,0.25,-0.000111544135034323,-0.000528782922038959,-0.000115548503839987,9.9845943,9.9958038,70962.8984375,70973.1171875,57.2331850636407,20.7780190824657,11.899124,0,0,0,40,4449,9.6922,70968.0078125,,,,,,,,,,,,,0,,,,0,,,,,,9.99019905,,,,
,29232213.825,10.0045261,66067.578125,-0.00049614915973117,1.36690322568972E-5,1,0.999253354069792,40.0298881530762,1.99664687115797,16.6500005871058,-0.00551895513444373,-0.00149104951632918,0.25,-4.25515064907175E-5,-0.000496058359643506,-4.62547350573172E-5,10.0045261,10.0045261,66060.3046875,66074.8515625,57.5630322987561,20.7811438296637,11.519473,0,0,0,40,4449,9.68425,66067.578125,,,,,,,,,,,,,0,,,,0,,,,,,10.0045261,,,,
,29232309.975,9.9960909,61264.267578125,-0.000462421344152624,9.67609852409117E-6,1,0.999253354069792,40.0298881530762,1.99673667055677,16.6500005871058,-0.00523066956512681,-0.000895853259822514,0.25,4.02903844881485E-6,-0.000462459759031525,5.8727180850809E-7,9.9960909,9.9960909,61256.96484375,61271.5703125,58.0851601496023,20.7746378191188,12.278775,0,0,0,40,4449,9.6953,61264.267578125,,,,,,,,,,,,,0,,,,0,,,,,,9.9960909,,,,
,29232405.8,9.9848356,56471.439453125,-0.000366731612318095,8.43977481632814E-6,1,0.999253354069792,40.0298881530762,1.99697358692223,16.6500005871058,-0.0041688088090636,-0.00058845547072265,0.25,1.39796086943656E-5,-0.000366675415203896,1.12469638810188E-5,9.9848356,9.9848356,56469.046875,56473.83203125,57.3691884259868,20.776384882042,12.278775,0,0,0,40,4449,9.69975,56471.439453125,,,,,,,,,,,,,0,,,,0,,,,,,9.9848356,,,,
,29232503.015,10.0069399,51613.876953125,-0.000259135453619556,7.72400160695837E-6,1,0.999253354069792,40.0298881530762,1.99632948339525,16.6500005871058,-0.00295155287065921,-0.000370174171443961,0.25,1.388489195445E-5,-0.000259000691546551,1.19557027512675E-5,10.0069399,10.0069399,51611.28125,51616.47265625,57.1745629246983,20.7794829336573,12.278775,0,0,0,40,4449,9.6856,51613.876953125,,,,,,,,,,,,,0,,,,0,,,,,,10.0069399,,,,
,29232597.6,10.0248241,46886.029296875,-0.000204907367554232,6.45079816596748E-6,1,0.999253354069792,40.0298881530762,1.99667206104312,16.6500005871058,-0.00232009121528717,-0.000365059395971386,0.25,4.54163679399816E-6,-0.000204654095976596,3.0344319739651E-6,10.0248241,10.0248241,46883.625,46888.43359375,57.5262957583522,20.7795486950081,11.519473,0,0,0,40,4449,9.6756,46886.029296875,,,,,,,,,,,,,0,,,,-0.00245,,,,,,10.0248241,,,,
,29232695.955,10.0056648,41970.8046875,-0.000177110447647634,5.45033722901382E-6,1,0.999253354069792,40.0298881530762,1.99577508331222,16.6500005871058,-0.00201864313695482,-0.000230904515270061,0.25,1.13912893138435E-5,-0.000176854067974789,1.00920498629422E-5,10.0056648,10.0056648,41966.1640625,41975.4453125,57.4012351952753,20.7939273652934,12.278775,0,0,0,40,4449,9.6807,41970.8046875,,,,,,,,,,,,,0,,,,-0.00245,,,,,,10.0056648,,,,
,29232793.06,10.0123224,37118.2109375,-0.000160580403627824,3.29197541166078E-6,1,0.999253354069792,40.0298881530762,1.99574420987283,16.6500005871058,-0.0018370263400834,-0.000166015880120951,0.25,1.41426193820891E-5,-0.00016029084654742,1.29743081571145E-5,10.0105791,10.0140657,37108.2890625,37128.1328125,57.8850632486792,20.7913810653387,11.899124,0,0,0,40,4449,9.66655,37118.2109375,,,,,,,,,,,,,0,,,,0.00245,,,,,,10.0123224,,,,
,29232887.81,10.0031738,32381.0517578125,-0.000123577548489138,2.85433177386157E-6,1,0.999253354069792,40.0298881530762,1.99575452407351,16.6500005871058,-0.00138304221004108,-0.00029434565808195,0.25,-3.94450226352654E-6,-0.000123188646194974,-4.78244810725481E-6,10.0031738,10.0031738,32375.958984375,32386.14453125,57.5098815594484,20.7947445555576,11.899124,0,0,0,40,4449,9.6658,32381.0517578125,,,,,,,,,,,,,0,,,,-0.00245,,,,,,10.0031738,,,,
,29232984.955,10.0149765,27528.4375,-8.31871718994886E-5,3.28819951436298E-6,1,0.999253354069792,40.0298881530762,1.99541087333618,16.6500005871058,-0.000913778942356715,-0.00029053650387966,0.25,-1.08999128363999E-5,-8.28289192574999E-5,-1.14148128756805E-5,10.0149765,10.0149765,27523.63671875,27533.23828125,57.4809613042369,20.8044035763935,11.899124,0,0,0,40,4449,9.6693,27528.4375,,,,,,,,,,,,,0,,,,0,,,,,,10.0149765,,,,
,29233080.43,9.9905233,22755.7119140625,-2.98389674758835E-5,2.65166138039872E-6,1,0.999253354069792,40.0298881530762,1.99561447253484,16.6500005871058,-0.000315554142408903,-0.000171699927022151,0.25,-9.92246946741522E-6,-2.96586836583366E-5,-1.00736014827379E-5,9.9905233,9.9905233,22740.671875,22770.751953125,56.9322580837368,20.8055363399875,11.899124,0,0,0,40,4449,9.6857,22755.7119140625,,,,,,,,,,,,,0,,,,-0.00245,,,,,,9.9905233,,,,
,29233175.095,10.00173135,18023.39453125,-3.70705534147733E-6,1.42298884626258E-6,1,0.999253354069792,40.0298881530762,1.99556387507167,16.6500005871058,-3.39562513801061E-5,-5.05721762936562E-5,0.25,-3.83613710600273E-6,-3.66752581257809E-6,-3.84180216201535E-6,10.0003614,10.0031013,18018.302734375,18028.486328125,57.2058280654676,20.8048544369217,12.278775,0,0,0,40,4449,9.67375,18023.39453125,,,,,,,,,,,,,0,,,,-0.00245,,,,,,10.00173135,,,,
,29233272.04,9.9950352,13178.3642578125,3.38551072346004E-5,1.11294150392698E-6,1,0.999253354069792,40.0298881530762,1.99577407225383,16.6500005871058,0.000400230981264353,-4.29904358391924E-5,0.25,-9.86918324199086E-6,3.37482039047605E-5,-9.62765652797601E-6,9.9950352,9.9950352,13170.791015625,13185.9375,57.2871174314676,20.7999330291417,11.519473,0,0,0,40,4449,9.66445,13178.3642578125,,,,,,,,,,,,,0,,,,-0.00245,,,,,,9.9950352,,,,
,29233367.33,10.001749,8415.5751953125,7.71171976605081E-5,9.01365808676702E-7,1,0.999253354069792,40.0298881530762,1.99558412851992,16.6500005871058,0.000875288979519589,0.000103335698838068,0.25,-4.53844188490165E-6,7.67390644732147E-5,-4.10010827845067E-6,10.001749,10.001749,8408.1044921875,8423.0458984375,57.9257079316792,20.7962747782504,11.519473,0,0,0,40,4449,9.66545,8415.5751953125,,,,,,,,,,,,,0,,,,-0.00245,,,,,,10.001749,,,,
,29233462.92,9.9940243,3637.50341796875,9.92405061910618E-5,4.17296297523319E-7,1,0.999253354069792,40.0298881530762,1.99581244147798,16.6500005871058,0.00111537931520053,0.000193287517328382,0.25,-4.3317723717453E-7,9.86912067801426E-5,6.86427289687555E-8,9.9940243,9.9940243,3634.982421875,3640.0244140625,57.4817429327561,20.7930112637282,11.899124,0,0,0,40,4449,9.6689,3637.50341796875,,,,,,,,,,,,,0,,,,0.0049,,,,,,9.9940243,,,,
,29233557.015,9.9990578,-1064.33917236328,-7.08906041137879E-5,3.28432818269836E-7,1,0.999253354069792,40.0298881530762,1.99581165348752,16.6500005871058,-0.000796450143424188,-0.000139078215475981,0.25,2.0638457571866E-7,-7.04873812083045E-5,-1.3998978448798E-7,9.9990578,9.9990578,-1071.79467773438,-1056.88366699219,57.7779801415446,20.7969038913213,11.519473,0,0,0,40,4449,9.6679,-1064.33917236328,,,,,,,,,,,,,0,,,,-0.0049,,,,,,9.9990578,,,,
,29233648.29,9.9950123,-5625.23388671875,-9.03337122584053E-5,7.14441121940625E-7,1,0.999253354069792,40.0298881530762,1.99575122144651,16.6500005871058,-0.00101968404750501,-0.000151774216351905,0.25,2.56024612893075E-6,-8.98568848164877E-5,2.07911252182539E-6,9.9950123,9.9950123,-5632.78369140625,-5617.68408203125,57.4606389627369,20.8021573339686,11.899124,0,0,0,40,4449,9.67135,-5625.23388671875,,,,,,,,,,,,,0,,,,0,,,,,,9.9950123,,,,
,29233741.61,9.9954033,-10288.7353515625,-7.08420304700917E-5,9.08285303645674E-7,1,0.999253354069792,40.0298881530762,1.99634335803147,16.6500005871058,-0.000811928572316216,-5.32243637911957E-5,0.25,7.89430701548919E-6,-7.05263264963318E-5,7.46355634780844E-6,9.9954033,9.9954033,-10326.025390625,-10251.4453125,57.5622506702369,20.7975365103728,11.139823,0,0,0,40,4449,9.66995,-10288.7353515625,,,,,,,,,,,,,0,,,,0,,,,,,9.9954033,,,,
,29233837.395,10.0111418,-15076.4721679687,-4.16584509482195E-5,1.47064874109937E-6,1,0.999253354069792,40.0298881530762,1.99628344883218,16.6500005871058,-0.000494637859826937,6.37459295948222E-5,0.25,1.31128115036538E-5,-4.15412589441682E-5,1.28074879174774E-5,10.0111418,10.0111418,-15088.9833984375,-15063.9609375,57.4926857320253,20.7974612640739,11.899124,0,0,0,40,4449,9.6689,-15076.4721679687,,,,,,,,,,,,,0,,,,-0.00245,,,,,,10.0111418,,,,
,29233932.61,10.0073051,-19836.1328125,-1.49047459185622E-5,1.1339912745202E-6,1,0.999253354069792,40.0298881530762,1.99638823191481,16.6500005871058,-0.000187752707211647,8.24492639738703E-5,0.25,9.99878146670778E-6,-1.49038275321934E-5,9.86446199642311E-6,10.0073051,10.0073051,-19841.109375,-19831.15625,57.5231692442753,20.7975066557824,11.899124,0,0,0,40,4449,9.6679,-19836.1328125,,,,,,,,,,,,,0,,,,-0.0049,,,,,,10.0073051,,,,
,29234029.24,9.9940834,-24666.009765625,2.36760243175489E-5,2.29315821507673E-6,1,0.999253354069792,40.0298881530762,1.9963071911036,16.6500005871058,0.000232449630991314,0.000236993931597772,0.25,1.68196683450241E-5,2.34786603799934E-5,1.69103948371085E-5,9.9940834,9.9940834,-24673.203125,-24658.81640625,57.5958606965638,20.8008257733716,11.899124,0,0,0,40,4449,9.66605,-24666.009765625,,,,,,,,,,,,,0,,,,0,,,,,,9.9940834,,,,
,29234125.235,10.00035,-29463.4951171875,6.10133695835791E-5,5.99723699338839E-6,1,0.999253354069792,40.0298881530762,1.99595087197774,16.6500005871058,0.000619670493791868,0.000496338465959811,0.25,3.31481518009701E-5,6.05926401715167E-5,3.34520562086147E-5,9.9991846,10.0015154,-29470.970703125,-29456.01953125,57.6638623777369,20.8077608402429,11.519473,0,0,0,40,4449,9.6681,-29463.4951171875,,,,,,,,,,,,,0,,,,0,,,,,,10.00035,,,,
,29234219.725,10.0006337,-34185.58984375,0.000116651080549842,4.59522980085108E-6,1,0.999253354069792,40.0298881530762,1.9963641155212,16.6500005871058,0.00125297452541026,0.000573800971834422,0.25,2.99827376831208E-5,0.00011612347278412,3.07114724122503E-5,10.0001287,10.0011387,-34198.1875,-34172.9921875,57.8092452823138,20.8021686709161,11.139823,0,0,0,40,4449,9.6772,-34185.58984375,,,,,,,,,,,,,0,,,,0,,,,,,10.0006337,,,,
,29234316.735,10.0023575,-39032.6328125,0.000120982241266958,6.88324853795971E-6,1,0.999253354069792,40.0298881530762,1.99618839903301,16.6500005871058,0.00128536371303183,0.000676684822365863,0.25,3.82942939996068E-5,0.00012044051580084,3.9071374811052E-5,10.0023575,10.0023575,-39040.1875,-39025.078125,57.6388502651215,20.8027377835979,11.899124,0,0,0,40,4449,9.68095,-39032.6328125,,,,,,,,,,,,,0,,,,0,,,,,,10.0023575,,,,
,29234411.29,9.99658875,-43757.359375,0.000163007331868641,8.74492157583232E-6,1,0.999253354069792,40.0298881530762,1.99629985449403,16.6500005871058,0.00172873303265751,0.00093448015016921,0.25,5.35491421374865E-5,0.000162337670750533,5.46399529217882E-5,9.9943314,9.9988461,-43766.88671875,-43747.83203125,57.1784710672945,20.8029883081806,11.519473,0,0,0,40,4449,9.68375,-43757.359375,,,,,,,,,,,,,0,,,,0,,,,,,9.99658875,,,,
,29234505.475,10.0013266,-48467.927734375,0.000216966155575859,1.023229020211E-5,1,0.999253354069792,40.0298881530762,1.99624774810618,16.6500005871058,0.00234775187444687,0.000990304957453916,0.25,4.87254101222282E-5,0.000216339837689868,5.02603741864336E-5,10.0013266,10.0013266,-48480.390625,-48455.46484375,57.8678674212561,20.8027512733088,11.899124,0,0,0,40,4449,9.68705,-48467.927734375,,,,,,,,,,,,,0,,,,0.00245,,,,,,10.0013266,,,,
,29234599.82,9.9949217,-53182.5859375,0.000202272833773635,1.21920933729862E-5,1,0.999253354069792,40.0298881530762,1.99624657873178,16.6500005871058,0.00219528733720532,0.000893073466676804,0.25,4.27019777704264E-5,0.00020180270509766,4.41687570979425E-5,9.9949217,9.9949217,-53192.36328125,-53172.80859375,57.5872627828522,20.799868893782,11.519473,0,0,0,40,4449,9.68725,-53182.5859375,,,,,,,,,,,,,0,,,,0.00245,,,,,,9.9949217,,,,
,29234696.86,10.0017958,-58032.400390625,0.000289416132199811,9.83847361383495E-6,1,0.999253354069792,40.0298881530762,1.99608592009241,16.6500005871058,0.00320907848731524,0.00090780835432972,0.25,2.82635105423779E-5,0.000289122945916279,3.04088305235054E-5,10.0017958,10.0017958,-58039.859375,-58024.94140625,57.2847725459099,20.8045142248877,11.139823,0,0,0,40,4449,9.68225,-58032.400390625,,,,,,,,,,,,,0,,,,0,,,,,,10.0017958,,,,
,29234791.835,10.0053864,-62777.646484375,0.000309676390424449,1.23556274047377E-5,1,0.999253354069792,40.0298881530762,1.99592461237573,16.6500005871058,0.0034023522516022,0.00115277718733963,0.25,4.62792710910066E-5,0.000309380908568282,4.85905868277131E-5,10.0053864,10.0053864,-62782.55078125,-62772.7421875,57.2042648084291,20.8028288641998,11.899124,0,0,0,40,4449,9.68465,-62777.646484375,,,,,,,,,,,,,0,,,,0.00245,,,,,,10.0053864,,,,
,29234879.765,10.0024099,-67172.36328125,0.000380217961704934,8.33079404451061E-6,1,0.999253354069792,40.0298881530762,1.99591616311867,16.6500005871058,0.00417562110472999,0.00143477980896175,0.25,5.85003838521358E-5,0.000379993517299103,6.13528819549591E-5,10.0024099,10.0024099,-67184.9609375,-67159.765625,57.4004535667561,20.8072004727112,11.519473,0,0,0,40,4449,9.67875,-67172.36328125,,,,,,,,,,,,,0,,,,-0.00245,,,,,,10.0024099,,,,
,29234971.895,9.9991856,-71777.0390625,0.000412126516817084,7.60864956302065E-6,1,0.999253354069792,40.0298881530762,1.99577218372251,16.6500005871058,0.00453184397387696,0.00153181834419864,0.25,6.13155875023768E-5,0.000412063170284983,6.44124627558385E-5,9.9991856,9.9991856,-71781.9921875,-71772.0859375,57.6286890943715,20.8062175993907,11.519473,0,0,0,40,4449,9.6791,-71777.0390625,,,,,,,,,,,,,0,,,,0,,,,,,9.9991856,,,,
,29235063.36,9.9914761,-76346.671875,0.000426560644296659,9.19983376323509E-6,1,0.999253354069792,40.0298881530762,1.99572869529025,16.6500005871058,0.00469077582372639,0.00159415990843211,0.25,6.42094385958413E-5,0.000426650924159367,6.74134514636913E-5,9.9914761,9.9914761,-76359.34375,-76334,57.3621537693137,20.8076915254238,11.519473,0,0,0,40,4449,9.69515,-76346.671875,,,,,,,,,,,,,0,,,,-0.00245,,,,,,9.9914761,,,,
,29235152.225,10.010355,-80789.453125,0.000504760270765854,9.87001428405066E-6,1,0.999253354069792,40.0298881530762,1.99568221357562,16.6500005871058,0.00562738834786604,0.00147124405851896,0.25,3.92467368842673E-5,0.000505309941093238,4.29666338873841E-5,10.010355,10.010355,-80801.921875,-80776.984375,57.5739750980253,20.8046710409827,11.139823,0,0,0,40,4449,9.69775,-80789.453125,,,,,,,,,,,,,0,,,,0.00245,,,,,,10.010355,,,,
,29235244.235,9.997057,-85386.75,0.00055255862031318,7.80081042452502E-6,1,0.999253354069792,40.0298881530762,1.99624452373873,16.6500005871058,0.0061985587745235,0.00141952855865439,0.25,2.60414706482676E-5,0.000553468219896872,3.0046230159686E-5,9.997057,9.997057,-85394.3984375,-85379.1015625,57.9366507309484,20.8010625221035,11.139823,0,0,0,40,4449,9.6898,-85386.75,,,,,,,,,,,,,0,,,,0.00245,,,,,,9.997057,,,,
,29235331.45,9.9649477,-89745.62890625,0.000500897358114357,7.98536321250685E-6,1,0.999253354069792,40.0298881530762,1.99711977472438,16.6500005871058,0.00560760035230281,0.00137369114292545,0.25,3.12457034941128E-5,0.000501818321532472,3.48545059952495E-5,9.9649477,9.9649477,-89755.84375,-89735.4140625,57.9335242168715,20.7957802355578,11.519473,0,0,0,40,4453,9.8275,-89745.62890625,,,,,,,,,,,,,0,,,,0.0049,,,,,,9.9649477,,,,
,29235434.785,9.972436,-86091.96484375,0.000425391084254488,6.48581089991851E-6,1,0.999253354069792,40.0298881530762,1.99647670606586,16.6500005871058,0.00480515125833511,0.000913035878877944,0.25,4.14967295769057E-6,0.000426226029351832,7.1953636531004E-6,9.972436,9.972436,-86094.453125,-86089.4765625,57.6537012069869,20.8094299450407,11.519473,0,0,0,40,4453,9.7224,-86091.96484375,,,,,,,,,,,,,0,,,,0.0049,,,,,,9.972436,,,,
,29235528.605,9.9384379,-81402.58203125,0.000342378690743361,5.36982281911266E-6,1,0.999253354069792,40.0298881530762,1.9989873890017,16.6500005871058,0.00385692053922126,0.000812611829903868,0.25,1.01171375308765E-5,0.000342886716084717,1.26097893035901E-5,9.9333286,9.9435472,-81412.4140625,-81392.75,57.8733388208907,20.7806851140884,11.899124,0,0,0,40,4453,9.8601,-81402.58203125,,,,,,,,,,,,,0,,,,-0.00245,,,,,,9.9384379,,,,
,29235624.22,9.9745026,-76624.7734375,0.000328597605621994,5.42872914918714E-6,1,0.999253354069792,40.0298881530762,1.99763865835383,16.6500005871058,0.00369649405520948,0.000787171251330846,0.25,1.03948808126127E-5,0.000328960104907117,1.28106459963068E-5,9.9745026,9.9745026,-76639.921875,-76609.625,57.4934673605446,20.7798279241325,11.899124,0,0,0,40,4453,9.86065,-76624.7734375,,,,,,,,,,,,,0,,,,-0.00245,,,,,,9.9745026,,,,
,29235716.905,9.9871931,-71992.59765625,0.000291592254384776,6.00040468517057E-6,1,0.999253354069792,40.0298881530762,1.99730945347382,16.6500005871058,0.00327112587316109,0.000738894662327478,0.25,1.28084875748336E-5,0.000291778137602078,1.49702842685219E-5,9.9871931,9.9871931,-71997.7109375,-71987.484375,58.2336695682562,20.7897833602131,11.519473,0,0,0,40,4453,9.83085,-71992.59765625,,,,,,,,,,,,,0,,,,-0.0049,,,,,,9.9871931,,,,
,29235810.725,9.9726219,-67303.18359375,0.000282987212210077,6.72242520396781E-6,1,0.999253354069792,40.0298881530762,1.9982985989766,16.6500005871058,0.00320232533693299,0.000564533947667607,0.25,-1.07813967977181E-6,0.000283154368336946,1.02003776468147E-6,9.9726219,9.9726219,-67315.5078125,-67290.859375,58.0343542958523,20.7770036760367,11.899124,0,0,0,40,4449,9.8641,-67303.18359375,,,,,,,,,,,,,0,,,,0.0049,,,,,,9.9726219,,,,
,29235904.735,10.0013599,-62606.046875,0.000272194189342024,3.10621652210761E-6,1,0.999253354069792,40.0298881530762,1.99717392361676,16.6500005871058,0.00309725002616572,0.000431484615618682,0.25,-1.08694629038688E-5,0.000272313716531608,-8.84573232471234E-6,10.0013599,10.0013599,-62613.40234375,-62598.69140625,57.9483751587369,20.783703827669,11.139823,0,0,0,40,4449,9.8533,-62606.046875,,,,,,,,,,,,,0,,,,-0.0049,,,,,,10.0013599,,,,
,29235998.25,9.9349365,-57930.458984375,0.000231290659699107,2.80111348327985E-6,1,0.999253354069792,40.0298881530762,1.99855874284799,16.6500005871058,0.00266260349033427,0.000199186361946708,0.25,-2.40632394155338E-5,0.000231401222014343,-2.23352522463106E-5,9.9349365,9.9349365,-57940.43359375,-57920.484375,57.799865740083,20.773181735929,11.519473,0,0,0,40,4453,9.8362,-57930.458984375,,,,,,,,,,,,,0,,,,-0.00245,,,,,,9.9349365,,,,
,29236093.36,10.0560846,-53178.443359375,0.000247235685722761,3.14036338771713E-6,1,0.999253354069792,40.0298881530762,1.99762057052462,16.6500005871058,0.00275560084506212,0.000700766193827891,0.25,1.75128740815398E-5,0.000246917979756935,1.93320234070038E-5,10.0560846,10.0560846,-53188.59765625,-53168.2890625,57.5583425276407,20.7819301253588,11.139823,0,0,0,40,4453,9.86535,-53178.443359375,,,,,,,,,,,,,0,,,,0.00245,,,,,,10.0560846,,,,
,29236185.32,10.0562229,-48583.318359375,0.000186074037967345,2.03334319525061E-6,1,0.999253354069792,40.0298881530762,1.99822551641826,16.6500005871058,0.00212570052364212,0.000237911880273098,0.25,-1.24479980148084E-5,0.00018593785245428,-1.10643723487503E-5,10.0562229,10.0562229,-48595.75,-48570.88671875,57.5630322987561,20.7855567378051,11.519473,0,0,0,40,4453,9.85165,-48583.318359375,,,,,,,,,,,,,0,,,,0.00245,,,,,,10.0562229,,,,
,29236280.23,10.0260849,-43840.71875,0.000177072817237006,6.03170475050631E-6,1,0.999253354069792,40.0298881530762,1.99556780137548,16.6500005871058,0.0019596115493894,0.000557443255439462,0.25,1.75840441810728E-5,0.000176641449549119,1.88394444124679E-5,10.0260849,10.0260849,-43848.20703125,-43833.23046875,57.8498899653138,20.8055365666011,11.519473,0,0,0,40,4454,9.69755,-43840.71875,,,,,,,,,,,,,0,,,,0,,,,,,10.0260849,,,,
,29236370.58,10.1183233,-39326.197265625,0.000118227573902754,9.82990455180621E-6,1,0.999253354069792,40.0298881530762,1.99386169761302,16.6500005871058,0.00124848236305865,0.000695305652639974,0.25,4.05086084463617E-5,0.000117679468346695,4.12634914126243E-5,10.1183233,10.1183233,-39336.296875,-39316.09765625,57.5739750980253,20.8345793418551,11.519473,0,0,0,40,4454,9.59005,-39326.197265625,,,,,,,,,,,,,0,,,,0.00245,,,,,,10.1183233,,,,
,29236455.735,10.0554895,-35068.474609375,7.00770887505846E-5,9.04165355390403E-6,1,0.999253354069792,40.0298881530762,1.99467122235368,16.6500005871058,0.000713759786614206,0.000558074499090552,0.25,3.69918020375894E-5,6.96334707806702E-5,3.73835732405279E-5,10.0554895,10.0554895,-35073.55078125,-35063.3984375,57.6568277210638,20.8250435850394,11.519473,0,0,0,40,4453,9.56955,-35068.474609375,,,,,,,,,,,,,0,,,,-0.0049,,,,,,10.0554895,,,,
,29236548.055,10.0229034,-30453.9287109375,7.89361051398122E-5,3.44375778211021E-6,1,0.999253354069792,40.0298881530762,1.99513009613234,16.6500005871058,0.00084910027911398,0.000376604509338436,0.25,1.9297124321645E-5,7.8558012435389E-5,1.97723830422435E-5,10.0229034,10.0229034,-30461.515625,-30446.341796875,57.5388018146599,20.8215366125087,11.139823,0,0,0,40,4449,9.5462,-30453.9287109375,,,,,,,,,,,,,0,,,,0.00245,,,,,,10.0229034,,,,
,29236645.69,10.0147533,-25576.7138671875,2.75439798977303E-5,1.75664374779953E-6,1,0.999253354069792,40.0298881530762,1.99572303451856,16.6500005871058,0.00030773801563169,6.72552815820736E-5,0.25,1.03925544943789E-6,2.74369881740248E-5,1.21544864518094E-6,10.0147533,10.0147533,-25584.236328125,-25569.19140625,57.9178916464869,20.8126392432101,10.760172,0,0,0,40,4453,9.57015,-25576.7138671875,,,,,,,,,,,,,0,,,,0,,,,,,10.0147533,,,,
,29236741.595,10.0245943,-20781.9814453125,1.02232564134969E-5,1.64179176439128E-6,1,0.999253354069792,40.0298881530762,1.99571916446394,16.6400000452995,7.22741171750593E-5,0.000258926564630338,0.25,2.11979456088027E-5,1.00487141949448E-5,2.117448754367E-5,10.0141373,10.0350513,-20792.03515625,-20771.927734375,57.6028953532369,20.8080023661354,11.139823,0,0,0,40,4453,9.5646,-20781.9814453125,,,,,,,,,,,,,0,,,,-0.0049,,,,,,10.0245943,,,,
,29236834.96,9.908803,-16117.1411132812,-2.57257678753167E-5,9.25593140308854E-7,1,0.999253354069792,40.0298881530762,1.99743454654714,16.6500005871058,-0.000307151731527429,4.77207028937384E-5,0.25,8.84016471484047E-6,-2.56608419857182E-5,8.64711782781689E-6,9.908803,9.908803,-16124.73046875,-16109.5517578125,57.8866265057177,20.7839350683592,10.760172,0,0,0,40,4454,9.65045,-16117.1411132812,,,,,,,,,,,,,0,,,,0,,,,,,9.908803,,,,
,29236932.51,9.92945,-11239.3779296875,-5.66442136212805E-5,8.06837915408489E-7,1,0.999253354069792,40.0298881530762,1.99779122069851,16.6500005871058,-0.00064944535654615,-4.40840140496778E-5,0.25,6.18338725547933E-6,-5.639595190675E-5,5.83613513914555E-6,9.9175386,9.9413614,-11241.8603515625,-11236.8955078125,57.4426615067945,20.7845834431977,11.139823,0,0,0,40,4453,9.6687,-11239.3779296875,,,,,,,,,,,,,0,,,,-0.00245,,,,,,9.92945,,,,
,29237024.61,9.8977032,-6636.31176757812,-8.44318050097599E-5,4.30387879397242E-7,1,0.999253354069792,40.0298881530762,1.99800661610116,16.6500005871058,-0.000957890301847001,-0.000121083134160897,0.25,4.26136675442485E-6,-8.40021947344174E-5,3.79563875648219E-6,9.8862553,9.9091511,-6643.69580078125,-6628.927734375,57.6411951506792,20.7838058011945,11.139823,0,0,0,40,4453,9.6464,-6636.31176757812,,,,,,,,,,,,,0,,,,0,,,,,,9.8977032,,,,
,29237120.285,9.9488726,-1852.62493896484,-9.58547910894113E-5,4.45307944222717E-7,1,0.999253354069792,40.0298881530762,1.99747203948364,16.6500005871058,-0.0010783679260146,-0.000185128192465239,0.25,5.57884223835227E-7,-9.53148329454357E-5,8.35302383741483E-8,9.9488726,9.9488726,-1860.30541992187,-1844.94445800781,57.7021621751792,20.791816641446,11.519473,0,0,0,40,4453,9.6479,-1852.62493896484,,,,,,,,,,,,,0,,,,-0.0049,,,,,,9.9488726,,,,
,29237214.07,9.8805084,2827.71862792969,9.93827940919798E-5,3.14902730645687E-7,1,0.999253354069792,40.0298881530762,1.99771195179953,16.6500005871058,0.0011200716292159,0.000181721646134312,0.25,-1.49679489842865E-6,9.88330794886171E-5,-9.93682511900068E-7,9.8805084,9.8805084,2822.56225585938,2832.875,57.7428068581792,20.7803467343201,10.760172,0,0,0,40,4454,9.7243,2827.71862792969,,,,,,,,,,,,,0,,,,0,,,,,,9.8805084,,,,
,29237308.265,9.9319754,7537.31713867187,8.2949803408083E-5,5.57102512356105E-7,1,0.999253354069792,40.0298881530762,1.99813321549876,16.6500005871058,0.000937179869353126,0.000141548473199116,0.25,-2.18457523809707E-6,8.25228898039738E-5,-1.73239861839839E-6,9.9319754,9.9319754,7527.46337890625,7547.1708984375,57.8834999916407,20.7857697819353,11.139823,0,0,0,40,4453,9.7497,7537.31713867187,,,,,,,,,,,,,0,,,,0,,,,,,9.9319754,,,,
,29237403.78,10.0733719,12312.7431640625,4.62042706985959E-5,5.7842938046211E-7,1,0.999253354069792,40.0298881530762,1.99789840027814,16.6500005871058,0.000531822819244973,2.47849944463235E-5,0.25,-6.04133603350427E-6,4.60119940498933E-5,-5.75001807168026E-6,10.0733719,10.0733719,12305.23828125,12320.248046875,57.9311793313138,20.7886349060691,11.139823,0,0,0,40,4454,9.7565,12312.7431640625,,,,,,,,,,,,,0,,,,-0.0049,,,,,,10.0733719,,,,
,29237498.485,9.9120779,17045.8408203125,3.19506369910267E-5,1.04944248161054E-6,1,0.999253354069792,40.0298881530762,1.99793790924703,16.6500005871058,0.000383099372109946,-6.76378438009165E-5,0.25,-1.1723534929267E-5,3.18779223581045E-5,-1.14793385728004E-5,9.9120779,9.9120779,17038.21875,17053.462890625,57.9444670161407,20.7786812659537,11.139823,0,0,0,40,4453,9.6682,17045.8408203125,,,,,,,,,,,,,0,,,,0.00245,,,,,,9.9120779,,,,
,29237592.705,9.9415483,21755.54296875,4.48518490523158E-6,4.39605866111607E-7,1,0.999253354069792,40.0298881530762,1.99897421550642,16.6599992662668,7.47551531493724E-5,-0.000126300879394521,0.25,-1.20178227614268E-5,4.54295231545334E-6,-1.19411768510846E-5,9.9415483,9.9415483,21750.40625,21760.6796875,57.5200427301984,20.7665012243146,11.139823,0,0,0,40,4453,9.7579,21755.54296875,,,,,,,,,,,,,0,,,,0,,,,,,9.9415483,,,,
,29237685.91,10.0627079,26413.1591796875,-4.09053758769727E-5,1.55981290901381E-6,1,0.999253354069792,40.0298881530762,1.99850810580397,16.6500005871058,-0.00043349882959478,-0.00023475042102929,0.25,-1.35018831887899E-5,-4.06712355899606E-5,-1.3723091940469E-5,10.0627079,10.0627079,26403.25390625,26423.064453125,57.8053371397177,20.7706071872656,11.139823,0,0,0,40,4453,9.7639,26413.1591796875,,,,,,,,,,,,,0,,,,-0.00245,,,,,,10.0627079,,,,
,29237782.845,10.0198526,31258.71875,-4.25560742489618E-5,2.15189684634588E-6,1,0.999253354069792,40.0298881530762,1.99874802887611,16.6500005871058,-0.000438679873130166,-0.000314264928903554,0.25,-2.02378079076839E-5,-4.22883449835914E-5,-2.04665527157985E-5,10.0198526,10.0198526,31255.98828125,31261.44921875,57.3035316303714,20.7673481574872,11.139823,0,0,0,40,4454,9.72575,31258.71875,,,,,,,,,,,,,0,,,,-0.0049,,,,,,10.0198526,,,,
,29237877.33,10.0819387,35981.318359375,-9.67842347385241E-5,2.18296419958056E-6,1,0.999253354069792,40.0298881530762,1.99883917319744,16.6500005871058,-0.00104927902940364,-0.000430637526035975,0.25,-2.07825431519676E-5,-9.6391917133159E-5,-2.14091128954704E-5,10.0819387,10.0819387,35973.83984375,35988.796875,57.9483751587369,20.7728589149684,10.760172,0,0,0,40,4454,9.7467,35981.318359375,,,,,,,,,,,,,0,,,,0.0049,,,,,,10.0819387,,,,
,29237973.125,10.1018925,40769.138671875,-0.000141916153604395,4.30036010331731E-6,1,0.999253354069792,40.0298881530762,1.99473018752809,16.6500005871058,-0.00152674605968689,-0.000683515212597331,0.25,-3.51578431444278E-5,-0.000141374464083134,-3.61050362625597E-5,10.1018925,10.1018925,40761.609375,40776.66796875,57.5888260398907,20.8184867018428,11.139823,0,0,0,40,4453,9.79105,40769.138671875,,,,,,,,,,,,,0,,,,0,,,,,,10.1018925,,,,
,29238066.855,9.9260635,45454.568359375,-0.000132316887083046,2.31239175223196E-6,1,0.999253354069792,40.0298881530762,1.99907319688589,16.6500005871058,-0.0014452022708455,-0.000538387309695191,0.25,-2.38598605512111E-5,-0.000131938161411942,-2.4788359736462E-5,9.9260635,9.9260635,45449.3984375,45459.73828125,57.870993935333,20.7663024534725,10.760172,0,0,0,40,4454,9.79215,45454.568359375,,,,,,,,,,,,,0,,,,0,,,,,,9.9260635,,,,
,29238159.25,9.90292835,50072.29296875,-0.000157469291921647,1.98614987602081E-6,1,0.999253354069792,40.0298881530762,1.99840172503256,16.6500005871058,-0.00174126016110405,-0.000523762814950462,0.25,-1.80151245260478E-5,-0.000157167627558389,-1.91573376717774E-5,9.8836727,9.922184,50062.52734375,50082.05859375,57.3238539718714,20.7701793771687,11.139823,0,0,0,40,4454,9.74055,50072.29296875,,,,,,,,,,,,,0,,,,0.0049,,,,,,9.90292835,,,,
,29238255.105,9.9306097,54861.978515625,-0.000185682541688012,2.65907699487382E-6,1,0.999253354069792,40.0298881530762,1.99950093376143,16.6500005871058,-0.0020474061695946,-0.000661947012442559,0.25,-2.51032259142282E-5,-0.000185385933786495,-2.64670835649504E-5,9.9306097,9.9306097,54854.5390625,54869.41796875,57.2753930036791,20.7608584542585,11.139823,0,0,0,40,4453,9.79915,54861.978515625,,,,,,,,,,,,,0,,,,0,,,,,,9.9306097,,,,
,29238352.135,9.9084454,59712.466796875,-0.0002328410390221,3.2752801242382E-6,1,0.999253354069792,40.0298881530762,1.99881641171392,16.6500005871058,-0.00255626846426099,-0.000893868885449202,0.25,-3.71099355042276E-5,-0.000232535292414941,-3.88383666599177E-5,9.9084454,9.9084454,59702.52734375,59722.40625,57.5012836457369,20.7625903706604,10.760172,0,0,0,40,4453,9.75235,59712.466796875,,,,,,,,,,,,,0,,,,0,,,,,,9.9084454,,,,
,29238447.64,9.957571,64485.583984375,-0.000254452354644474,3.52456372907681E-6,1,0.999253354069792,40.0298881530762,1.99834166734836,16.6500005871058,-0.00281607125726471,-0.000855312435628199,0.25,-2.97905172215847E-5,-0.000254310478150459,-3.16913499923154E-5,9.957571,9.957571,64480.890625,64490.27734375,57.6255625802946,20.7656965523853,11.139823,0,0,0,40,4453,9.8431,64485.583984375,,,,,,,,,,,,,0,,,,0,,,,,,9.957571,,,,
,29238540.915,9.9496441,69148.03125,-0.000266168017788428,2.985906195595E-6,1,0.999253354069792,40.0298881530762,1.99927408724955,16.6500005871058,-0.00296067942078728,-0.000826537856160335,0.25,-2.50806675148428E-5,-0.000266174539308558,-2.70687256091984E-5,9.9496441,9.9496441,69142.9765625,69153.0859375,57.799865740083,20.7700475555142,10.38052,0,0,0,40,4453,9.8072,69148.03125,,,,,,,,,,,,,0,,,,-0.00245,,,,,,9.9496441,,,,
,29238634.985,9.9329042,73851.0234375,-0.000281655532502765,2.98266689765184E-6,1,0.999253354069792,40.0298881530762,1.99916793232326,16.6500005871058,-0.0031025060471594,-0.00104995254025481,0.25,-4.20175474314847E-5,-0.000281660402472963,-4.41341095199691E-5,9.9329042,9.9329042,73846.015625,73856.03125,57.9139835038908,20.7640963730111,10.760172,0,0,0,40,4453,9.86345,73851.0234375,,,,,,,,,,,,,0,,,,-0.00245,,,,,,9.9329042,,,,
,29238730.085,9.9598951,78604.1953125,-0.00039387398706798,3.78426248979523E-6,1,0.999253354069792,40.0298881530762,1.99634174347732,16.6500005871058,-0.00433388147611906,-0.00146990638127502,0.25,-5.90569733870901E-5,-0.000394030031838623,-6.20115953232943E-5,9.9598951,9.9598951,78599.2578125,78609.1328125,57.2269320354868,20.7910635525921,11.519473,0,0,0,40,4453,9.8582,78604.1953125,,,,,,,,,,,,,0,,,,0,,,,,,9.9598951,,,,
,29238825.68,9.9689789,83382.60546875,-0.000381820415431839,2.79271613189945E-6,1,0.999253354069792,40.0298881530762,1.99898244058773,16.6500005871058,-0.00420583487540329,-0.00143980715395835,0.25,-5.83928963985927E-5,-0.000382103457040857,-6.12470332544607E-5,9.9689789,9.9689789,83377.3671875,83387.84375,57.7217028881599,20.7709193949003,11.519473,0,0,0,40,4453,9.8344,83382.60546875,,,,,,,,,,,,,0,,,,0,,,,,,9.9689789,,,,
,29238915.07,9.9425507,87850.9765625,-0.000442747506867795,5.37885088876627E-6,1,0.999253354069792,40.0298881530762,1.99564207553726,16.6500005871058,-0.00486573107488299,-0.00169539555050546,0.25,-7.02240355733425E-5,-0.000443201828025881,-7.35201997477614E-5,9.9425507,9.9425507,87846.03125,87855.921875,58.0562398943908,20.8049240025941,10.760172,0,0,0,40,4453,9.8655,87850.9765625,,,,,,,,,,,,,0,,,,-0.00245,,,,,,9.9425507,,,,
,29239020.445,10.211874,87893.53515625,-0.000457625808869551,3.39344308662848E-6,1,0.999253354069792,40.0298881530762,1.99784391055818,16.6500005871058,-0.00512872102069997,-0.00123071011285731,0.25,-2.6356642456644E-5,-0.000458424909722795,-2.96637052506482E-5,10.211874,10.211874,87883.2265625,87903.84375,57.2159892362176,20.7823022135158,10.760172,0,0,0,40,4454,9.8147,87893.53515625,,,,,,,,,,,,,0,,,,-0.00245,,,,,,10.211874,,,,
,29239112.1,9.9163132,83311.98046875,-0.000371509213709119,3.29544638587549E-6,1,0.999253354069792,40.0298881530762,1.99945723434425,16.6500005871058,-0.0041534564624577,-0.00106622587857228,0.25,-2.72458277250431E-5,-0.000371995432769381,-2.99688015097304E-5,9.9163132,9.9163132,83304.3828125,83319.578125,57.5098815594484,20.7594535734631,10.760172,0,0,0,40,4453,9.83435,83311.98046875,,,,,,,,,,,,,0,,,,0,,,,,,9.9163132,,,,
,29239208.5,9.9634113,78493.19140625,-0.000324232308571774,3.42390776575069E-6,1,0.999253354069792,40.0298881530762,1.99908258532171,16.6500005871058,-0.00359754497174461,-0.00107106845592038,0.25,-3.62049087864736E-5,-0.000324448270333318,-3.86189383275331E-5,9.9634113,9.9634113,78485.7734375,78500.609375,57.7193580026023,20.7591957740021,11.139823,0,0,0,40,4453,9.87575,78493.19140625,,,,,,,,,,,,,0,,,,-0.00245,,,,,,9.9634113,,,,
,29239304.77,10.0356379,73679.58984375,-0.000347851413560232,3.74460537725697E-6,1,0.999253354069792,40.0298881530762,1.99886335211736,16.6500005871058,-0.00388044734872729,-0.00102234987207576,0.25,-2.76677506641511E-5,-0.000348030495305289,-3.02551662629271E-5,10.0356379,10.0356379,73677.125,73682.0546875,57.931960959833,20.7622355758116,10.760172,0,0,0,40,4454,9.81535,73679.58984375,,,,,,,,,,,,,0,,,,-0.0049,,,,,,10.0356379,,,,
,29239400.83,10.086215,68879.12890625,-0.000184294038245598,3.08636792779375E-6,1,0.999253354069792,40.0298881530762,1.99842959277947,16.6500005871058,-0.00195446874988052,-0.00109713597085505,0.25,-6.37894303288743E-5,-0.000183950524600739,-6.51984352612714E-5,10.086215,10.086215,68874.09375,68884.1640625,57.4395349927176,20.7728737496513,10.760172,0,0,0,40,4454,9.8104,68879.12890625,,,,,,,,,,,,,0,,,,0,,,,,,10.086215,,,,
,29239495.12,9.8717413,64163.625,-0.000241041089360071,2.82640510017762E-6,1,0.999253354069792,40.0298881530762,1.99949339911238,16.6500005871058,-0.00264884650507394,-0.000922667726721674,0.25,-3.81224678843483E-5,-0.000240826067004022,-3.99254592001289E-5,9.8717413,9.8717413,64151.18359375,64176.06640625,57.8874081342369,20.7558168179008,10.38052,0,0,0,40,4454,9.76575,64163.625,,,,,,,,,,,,,0,,,,-0.00245,,,,,,9.8717413,,,,
,29239592.62,10.0070896,59293.142578125,-0.000202890795812879,3.24589849873943E-6,1,0.999253354069792,40.0298881530762,1.99898834969055,16.6500005871058,-0.00223141707914421,-0.000757476386971598,0.25,-3.04391496427842E-5,-0.000202630451011215,-3.19442039818147E-5,10.0070896,10.0070896,59288.1640625,59298.12109375,57.6411951506792,20.7615460324092,10.760172,0,0,0,40,4453,9.82235,59293.142578125,,,,,,,,,,,,,0,,,,-0.00245,,,,,,10.0070896,,,,
,29239687.265,10.0055656,54560.318359375,-0.000188755674206789,2.63809374277881E-6,1,0.999253354069792,40.0298881530762,1.99954862666659,16.6500005871058,-0.00208245160774,-0.000666384268671638,0.25,-2.49427165482194E-5,-0.000188452870442787,-2.63283419689415E-5,10.0055656,10.0055656,54550.4453125,54570.19140625,57.4528226775445,20.7557321399342,10.38052,0,0,0,40,4454,9.7945,54560.318359375,,,,,,,,,,,,,0,,,,0,,,,,,10.0055656,,,,
,29239784.6,10.097702,49697.85546875,-0.000157254266688273,1.74416594526439E-6,1,0.999253354069792,40.0298881530762,1.99935858282036,16.6500005871058,-0.00172678632982461,-0.000594442419256383,0.25,-2.42926894620636E-5,-0.000156900625871918,-2.5424829513437E-5,10.097702,10.097702,49693.01953125,49702.69140625,58.0843785210831,20.7634643829033,10.38052,0,0,0,40,4453,9.8435,49697.85546875,,,,,,,,,,,,,0,,,,0.0049,,,,,,10.097702,,,,
,29239879.515,9.9836645,44950.435546875,-0.000139880030802854,1.78593956208563E-6,1,0.999253354069792,40.0298881530762,1.99962169742351,16.6500005871058,-0.00154477902863207,-0.000476845844467567,0.25,-1.70387614255947E-5,-0.000139532205710071,-1.80305846832243E-5,9.9836645,9.9836645,44945.41796875,44955.453125,57.9679158717177,20.7614005863415,10.760172,0,0,0,40,4453,9.8616,44950.435546875,,,,,,,,,,,,,0,,,,0.0049,,,,,,9.9836645,,,,
,29239973.08,9.9805937,40274.685546875,-0.000103559886021709,1.4398738952843E-6,1,0.999253354069792,40.0298881530762,1.99956788076644,16.6599992662668,-0.00115208766844096,-0.000302900578244598,0.25,-8.20068618827666E-6,-0.000103284641264707,-8.92552706756411E-6,9.9805937,9.9805937,40272.1875,40277.18359375,57.6388502651215,20.755327623157,10.38052,0,0,0,40,4453,9.8667,40274.685546875,,,,,,,,,,,,,0,,,,0.0049,,,,,,9.9805937,,,,
,29240069.76,10.0028658,35444.755859375,-8.85014052500906E-5,1.74491568284007E-6,1,0.999253354069792,40.0298881530762,1.9998265410481,16.6500005871058,-0.000961569816345161,-0.000384566681952169,0.25,-1.81742384687163E-5,-8.81438254948324E-5,-1.87464656602093E-5,9.9959517,10.0097799,35434.66015625,35454.8515625,57.7779801415446,20.7635661504278,10.760172,0,0,0,40,4453,9.896,35444.755859375,,,,,,,,,,,,,0,,,,0.00245,,,,,,10.0028658,,,,
,29240163.15,10.0047865,30777.0419921875,-4.21239290330384E-5,1.70980242059352E-6,1,0.999253354069792,40.0298881530762,1.99983298983517,16.6599992662668,-0.000449237592957332,-0.000228793482967502,0.25,-1.27236175786615E-5,-4.19069389608239E-5,-1.29707165302241E-5,10.0047865,10.0047865,30772.00390625,30782.080078125,57.6630807492176,20.7648530521756,10.760172,0,0,0,40,4453,9.8762,30777.0419921875,,,,,,,,,,,,,0,,,,0,,,,,,10.0047865,,,,
,29240254.955,10.0036983,26186.6650390625,-3.0649127115319E-5,1.44227870604946E-6,1,0.999253354069792,40.0298881530762,1.99905092425754,16.6500005871058,-0.000316884719945829,-0.000220535538767009,0.25,-1.40755199352513E-5,-3.04471043388003E-5,-1.42264959349621E-5,10.0036983,10.0036983,26179.73828125,26193.591796875,58.1101722622177,20.7701018379978,11.139823,0,0,0,40,4453,9.7879,26186.6650390625,,,,,,,,,,,,,0,,,,0,,,,,,10.0036983,,,,
,29240347.945,9.9078722,21539.255859375,-8.48376944206104E-7,1.08049512213466E-6,1,0.999253354069792,40.0298881530762,1.99920780696413,16.6500005871058,-4.20416814359647E-6,-3.15918439547479E-5,0.25,-2.65290339882855E-6,-8.28245754124741E-7,-2.6475136392871E-6,9.9078722,9.9078722,21531.734375,21546.77734375,58.2891651931215,20.7698947033213,10.38052,0,0,0,40,4453,9.79925,21539.255859375,,,,,,,,,,,,,0,,,,0,,,,,,9.9078722,,,,
,29240440.935,9.9494419,16891.64453125,3.12807045745509E-5,6.32862619731525E-7,1,0.999253354069792,40.0298881530762,1.99986787220988,16.6500005871058,0.000365102067862677,-8.64739733548754E-6,0.25,-6.36013932178299E-6,3.11782898624931E-5,-6.14421608362689E-6,9.9494419,9.9494419,16883.97265625,16899.31640625,57.9132018753715,20.7555511618075,10.760172,0,0,0,40,4453,9.8301,16891.64453125,,,,,,,,,,,,,0,,,,-0.00245,,,,,,9.9494419,,,,
,29240535.24,10.00836135,12179.5561523437,6.04987317141178E-5,5.93106377666214E-7,1,0.999253354069792,40.0298881530762,1.99976185859861,16.6500005871058,0.000693983420669887,4.92002774518018E-5,0.25,-6.4246699328668E-6,6.02378095688942E-5,-6.05102409716349E-6,10.0033188,10.0134039,12167.056640625,12192.0556640625,57.3410497992945,20.755873148685,11.139823,0,0,0,40,4453,9.8718,12179.5561523437,,,,,,,,,,,,,0,,,,-0.00245,,,,,,10.00836135,,,,
,29240626.555,10.0177135,7616.75170898438,7.98282050546252E-5,4.05109185658826E-7,1,0.999253354069792,40.0298881530762,1.99960427381708,16.6500005871058,0.000905410093474457,0.00012026183415217,0.25,-3.52963635405107E-6,7.94254253183338E-5,-3.08648441575261E-6,10.0177135,10.0177135,7614.09521484375,7619.408203125,57.6990356611023,20.7686585342808,11.139823,0,0,0,40,4453,9.7698,7616.75170898438,,,,,,,,,,,,,0,,,,0,,,,,,10.0177135,,,,
,29240719.195,9.9725342,2983.70751953125,0.000103047765432443,3.20719525062764E-7,1,0.999253354069792,40.0298881530762,2.00021896547821,16.6500005871058,0.00116140221554014,0.000196394032322789,0.25,-8.64969285532535E-7,0.000102475311443201,-3.4609980934513E-7,9.9725342,9.9725342,2971.38452148438,2996.03051757812,57.9475935302177,20.7490175871446,11.519473,0,0,0,40,4453,9.8736,2983.70751953125,,,,,,,,,,,,,0,,,,-0.0049,,,,,,9.9725342,,,,
,29240780.835,9.9440203,-0.327311143279076,1.84515379588582E-5,2.92209595144381E-7,1,0.999253354069792,40.0298881530762,1.99986602655622,16.6599992662668,0.00020793249194991,3.49277556736855E-5,0.25,-1.71944566675957E-7,1.83463720023997E-5,-8.20216346534065E-8,9.9440203,9.9440203,-0.350146800279617,-0.304475486278534,57.6232176947369,20.7583123212515,11.139823,0,0,0,40,4421,9.83135,-0.327311143279076,,,,,,,,,,,,,0,,,,-0.00245,,,,,,9.9440203,,,,