File: data/monolayers/nanoparticles/Ac_CoFe_C/vsm/rawdata/DD226_2_HYST_100K.DAT
[Header]
; VSM Data File (default extension .dat)
; Copyright (c) 2003-2013, Quantum Design, Inc. All rights reserved.
TITLE,
FILEOPENTIME,27315548.63,11/13/2018,11:39 am
BYAPP,VSM,2.0,2.0
INFO,PPMS VSM Option Release 1.4.10 Build 1,APPNAME
INFO,Quantum Design Linear Motor Servo Controller,MOTOR_MODULE_NAME
INFO,3101-100 M1,MOTOR_HW_VERSION
INFO,MMC1014,MOTOR_SERIAL_NUMBER
INFO,SRV No X-over 01.03.11,MOTOR_SOFTWARE_VERSION
INFO,Quantum Design VSM Detection Module,VSM_MODULE_NAME
INFO,3101-150 F0,VSM_HW_VERSION
INFO,VSM707,VSM_SERIAL_NUMBER
INFO,VSM No X-over 01.02.05 May 20 2008 13:51:47,VSM_SOFTWARE_VERSION
INFO,704,PREAMP_SERIAL_NUMBER
INFO,822,COIL_SERIAL_NUMBER
INFO,0,MOMENT_UNITS
INFO,CoFe2O4 AH11,SAMPLE_MATERIAL
INFO,Quick Dry Monolayer Conc,SAMPLE_COMMENT
INFO,27.96,SAMPLE_MASS
INFO,,SAMPLE_VOLUME
INFO,,SAMPLE_MOLECULAR_WEIGHT
INFO,,SAMPLE_SIZE
INFO,,SAMPLE_SHAPE
DATATYPE,COMMENT,1
DATATYPE,TIME,2
STARTUPAXIS,X,2
STARTUPAXIS,Y1,5
[Data]
Comment,Time Stamp (sec),Temperature (K),Magnetic Field (Oe),Moment (emu),M. Std. Err. (emu),Transport Action,Averaging Time (sec),Frequency (Hz),Peak Amplitude (mm),Center Position (mm),Coil Signal' (mV),Coil Signal" (mV),Range (mV),M. Quad. Signal (emu),M. Raw' (emu),M. Raw" (emu),Min. Temperature (K),Max. Temperature (K),Min. Field (Oe),Max. Field (Oe),Mass (grams),Motor Lag (deg),Pressure (Torr),VSM Status (code),Motor Status (code),Measure Status (code),Measure Count,PPMS Status (code),System Temp. (K),System Field (Oe),Sample Position (deg),Bridge 1 Resistance (ohms),Bridge 1 Excitation (에),Bridge 2 Resistance (ohms),Bridge 2 Excitation (에),Bridge 3 Resistance (ohms),Bridge 3 Excitation (에),Bridge 4 Resistance (ohms),Bridge 4 Excitation (에),Signal 1 Vin (V),Signal 2 Vin (V),Digital Inputs (code),Drive 1 Iout (mA),Drive 1 Ipower (W),Drive 2 Iout (mA),Drive 2 Ipower (W),Pressure (),Map 20 (),Map 21 (),Map 22 (),Map 23 (),Map 24 (),Map 25 (),Map 26 (),Map 27 (),Map 28 (),Map 29 ()
,27315563.69,100.172226,-0.106566414237022,,,2,,,,25.3299998635054,,,,,,,100.172226,100.172226,-0.106566414237022,-0.106566414237022,,,21.3904,,,,-99999999,4369,99.983,-0.106566414237022,,,,,,,,,,,,,,,,,,,,,,,100.172226,,,,
,27315732.225,100.05609515,4788.34497070313,9.48716208232775E-6,5.1022499231964E-7,1,0.999253354069792,40.0298881530762,1.98436322226736,25.3199990838766,0.000108246311261092,1.28261521782663E-5,0.25,-5.32224041278201E-7,9.54219268303717E-6,-5.05759931461328E-7,100.0553589,100.0568314,4776.3115234375,4800.37841796875,56.7790588939676,20.6307972369029,21.770052,0,0,0,40,4449,99.88895,4788.34497070313,,,,,,,,,,,,,0,,,,0.0049,,,,,,100.05609515,,,,
,27315834.01,100.0238876,9874.154296875,1.00748514131039E-5,8.4665765080306E-7,1,0.999253354069792,40.0298881530762,1.98438218895405,25.3199990838766,0.000113271987724132,2.31890316463794E-5,0.25,2.81801882171142E-7,1.01307410389076E-5,3.14522051765203E-7,100.0238876,100.0238876,9861.734375,9886.57421875,56.9361662263329,20.634381106497,21.770052,0,0,0,40,4449,99.8784,9874.154296875,,,,,,,,,,,,,0,,,,0,,,,,,100.0238876,,,,
,27315938.36,100.0117798,15089.5053710938,8.42215272366078E-6,7.76178170630079E-7,1,0.999253354069792,40.0298881530762,1.98425015747264,25.3199990838766,9.61057793539354E-5,1.13011391644339E-5,0.25,-4.79702488843445E-7,8.47114520636677E-6,-4.56530831772097E-7,100.0117798,100.0117798,15074.2607421875,15104.75,56.8814522299868,20.6372769802294,21.770052,0,0,0,40,4449,99.87635,15089.5053710938,,,,,,,,,,,,,0,,,,-0.00245,,,,,,100.0117798,,,,
,27316038.875,100.0086136,20113.8916015625,8.50990938737723E-6,1.16576915651399E-6,1,0.999253354069792,40.0298881530762,1.98418031499732,25.3199990838766,9.58655150284907E-5,1.84705366903342E-5,0.25,1.39640829081445E-7,8.55756517691649E-6,1.6642692690832E-7,100.0086136,100.0086136,20106.2109375,20121.572265625,56.9580518248714,20.6404091159564,21.01075,0,0,0,40,4449,99.8713,20113.8916015625,,,,,,,,,,,,,0,,,,0,,,,,,100.0086136,,,,
,27316144.21,100.0066833,25378.7822265625,5.77072243157672E-6,1.31665129624171E-6,1,0.999253354069792,40.0298881530762,1.98406924304718,25.3199990838766,6.73868993583983E-5,-1.03167863875065E-6,0.25,-1.10516049981742E-6,5.80673313322199E-6,-1.09389713666336E-6,100.0066833,100.0066833,25369.00390625,25388.560546875,57.4575124486599,20.6411519816677,21.01075,0,0,0,40,4449,99.86665,25378.7822265625,,,,,,,,,,,,,0,,,,0,,,,,,100.0066833,,,,
,27316250.045,100.0043335,30666.6669921875,5.9882343721188E-6,1.26897798150886E-6,1,0.999253354069792,40.0298881530762,1.98392714761116,25.3199990838766,7.16704825246765E-5,-1.10214460263056E-5,0.25,-2.02756949065681E-6,6.02828913322153E-6,-2.02100435339188E-6,100.0042114,100.0044556,30656.9765625,30676.357421875,56.9525804252368,20.6434814597918,21.3904,0,0,0,40,4449,99.86325,30666.6669921875,,,,,,,,,,,,,0,,,,0.0049,,,,,,100.0043335,,,,
,27316353.18,100.0053177,35824.28125,2.26098776801771E-6,1.55672834970891E-6,1,0.999253354069792,40.0298881530762,1.98405316994578,25.3199990838766,3.40396884573411E-5,-4.38850924749456E-5,0.25,-4.28164262943912E-6,2.2866482505848E-6,-4.29917558221424E-6,100.0053177,100.0053177,35809.0625,35839.5,57.0666981890445,20.6420975177793,21.3904,0,0,0,40,4449,99.85865,35824.28125,,,,,,,,,,,,,0,,,,0,,,,,,100.0053177,,,,
,27316454.8,100.0045853,40901.619140625,4.23249140626254E-6,1.35682653334113E-6,1,0.999253354069792,40.0298881530762,1.98374121330084,25.3199990838766,4.77278328502321E-5,8.8633226868208E-6,0.25,4.13187748025129E-8,4.25643265428451E-6,5.4146477067904E-8,100.0045853,100.0045853,40891.76171875,40911.4765625,57.3261988574291,20.6466397738439,21.3904,0,0,0,40,4449,99.85815,40901.619140625,,,,,,,,,,,,,0,,,,0.00245,,,,,,100.0045853,,,,
,27316551.365,100.0044174,45729.228515625,6.85829217356165E-7,2.32540277158543E-6,1,0.999253354069792,40.0298881530762,1.98398218445933,25.3199990838766,1.48134944699958E-5,-3.88742608639962E-5,0.25,-3.5614443159877E-6,7.0026200436874E-7,-3.57969569736085E-6,100.0044174,100.0044174,45714.2578125,45744.19921875,57.2433462343907,20.6437747878985,21.770052,0,0,0,40,4449,99.85385,45729.228515625,,,,,,,,,,,,,0,,,,0,,,,,,100.0044174,,,,
,27316650.205,100.00305175,50669.439453125,9.26674009953308E-6,2.07685238602642E-6,1,0.999253354069792,40.0298881530762,1.98377032696221,25.3199990838766,0.000108154013306256,-1.40450086563845E-6,0.25,-1.75142945690778E-6,9.32472693171562E-6,-1.73420961428868E-6,100.0024948,100.0036087,50656.76953125,50682.109375,57.2964969736984,20.6464204336295,21.3904,0,0,0,40,4449,99.85165,50669.439453125,,,,,,,,,,,,,0,,,,-0.00245,,,,,,100.00305175,,,,
,27316749.185,100.0027924,55616.580078125,3.23114164850369E-6,2.05837454432219E-6,1,0.999253354069792,40.0298881530762,1.98380240237128,25.3199990838766,4.55636165855851E-5,-4.52115493916335E-5,0.25,-4.56948585301552E-6,3.26292001568142E-6,-4.58616091123313E-6,100.0027924,100.0027924,55609.1484375,55624.01171875,57.271484861083,20.6463988238498,21.01075,0,0,0,40,4449,99.8469,55616.580078125,,,,,,,,,,,,,0,,,,-0.00245,,,,,,100.0027924,,,,
,27316846.03,100.0035934,60457.025390625,-1.04928595202326E-5,2.32788150602068E-6,1,0.999253354069792,40.0298881530762,1.98385594545784,25.3199990838766,-0.000105251878648104,-9.64970111895715E-5,0.25,-6.69982616858264E-6,-1.05334722553301E-5,-6.7685343936306E-6,100.0035934,100.0035934,60442.0546875,60471.99609375,57.0026046504676,20.6500435744791,21.3904,0,0,0,40,4449,99.84915,60457.025390625,,,,,,,,,,,,,0,,,,-0.00245,,,,,,100.0035934,,,,
,27316944.485,100.002861,65377.58984375,1.72830108401815E-6,2.49753839479096E-6,1,0.999253354069792,40.0298881530762,1.98381866792553,25.3199990838766,1.98118649115537E-5,1.79042057224434E-6,0.25,-1.44869987822483E-7,1.73861765301429E-6,-1.4072933651061E-7,100.002861,100.002861,65364.91015625,65390.26953125,57.2957153451791,20.6471085144912,21.3904,0,0,0,40,4449,99.8447,65377.58984375,,,,,,,,,,,,,0,,,,0,,,,,,100.002861,,,,
,27317042.53,100.0032654,70280.06640625,-7.80950366696522E-6,2.89187421015614E-6,1,0.999253354069792,40.0298881530762,1.98381959429296,25.3199990838766,-6.60974025120188E-5,-0.0001415651821834,0.25,-1.11604878582666E-5,-7.8224311723104E-6,-1.12468126980155E-5,100.0032654,100.0032654,70272.625,70287.5078125,57.1214121853907,20.6469549414732,21.01075,0,0,0,40,4449,99.8425,70280.06640625,,,,,,,,,,,,,0,,,,0.0049,,,,,,100.0032654,,,,
,27317139.455,100.0041504,75120.1796875,5.76585688734953E-6,3.68014547909947E-6,1,0.999253354069792,40.0298881530762,1.98424056837266,25.3199990838766,5.96053599102835E-5,4.30387100657273E-5,0.25,2.79708305612507E-6,5.7910480514566E-6,2.82950304591489E-6,100.0041504,100.0041504,75105.296875,75135.0625,57.1839424669291,20.6416297027627,21.01075,0,0,0,40,4449,99.83985,75120.1796875,,,,,,,,,,,,,0,,,,0.00245,,,,,,100.0041504,,,,
,27317238.135,100.0039902,80056.015625,4.54560251943052E-6,2.86589727887168E-6,1,0.999253354069792,40.0298881530762,1.9839710029025,25.3199990838766,8.1763418599543E-5,-0.000164281860797499,0.25,-1.53380879034363E-5,4.61494241725861E-6,-1.54135287293009E-5,100.0039902,100.0039902,80043.484375,80068.546875,57.2566339192176,20.6451049724479,21.01075,0,0,0,40,4449,99.8336,80056.015625,,,,,,,,,,,,,0,,,,0,,,,,,100.0039902,,,,
,27317334.485,100.0025406,84872.16015625,-4.80525771828025E-7,3.58945432023581E-6,1,0.999253354069792,40.0298881530762,1.98434409176554,25.3199990838766,1.23617189823769E-5,-0.000102364820293717,0.25,-8.97422773950074E-6,-4.58202086046585E-7,-9.02727282948516E-6,100.0025406,100.0025406,84867.125,84877.1953125,56.9283499411406,20.6423685156394,21.3904,0,0,0,40,4449,99.83175,84872.16015625,,,,,,,,,,,,,0,,,,-0.0049,,,,,,100.0025406,,,,
,27317429.92,100.0034256,89642.6953125,-2.9430175178827E-6,2.45630150658018E-6,1,0.999253354069792,40.0298881530762,1.9841584526825,25.3199990838766,-1.89971052841358E-5,-8.71095199736632E-5,0.25,-7.19288603314455E-6,-2.9400248363481E-6,-7.24255293485206E-6,100.0034256,100.0034256,89630.15625,89655.234375,57.2284952925253,20.6416529867517,21.3904,0,0,0,40,4449,99.8293,89642.6953125,,,,,,,,,,,,,0,,,,0,,,,,,100.0034256,,,,
,27317549.44,100.0000458,85739.35546875,-4.26149458851598E-6,2.39723128801875E-6,1,0.999253354069792,40.0298881530762,1.98372555504466,25.3199990838766,-5.28417206407407E-5,1.83411994715099E-5,0.25,2.37116644830123E-6,-4.29267335226887E-6,2.37292993965459E-6,100.0000458,100.0000458,85729.4296875,85749.28125,57.2269320354868,20.6508097852017,21.3904,0,0,0,40,4449,99.82885,85739.35546875,,,,,,,,,,,,,0,,,,0.00245,,,,,,100.0000458,,,,
,27317648.37,99.9979172,80795.71875,-6.38978009716328E-6,2.8121654682618E-6,1,0.999253354069792,40.0298881530762,1.98406332692713,25.3199990838766,-6.8414517529318E-5,-3.42221641069424E-5,0.25,-1.9077081266031E-6,-6.42118282813927E-6,-1.9366595085809E-6,99.9979172,99.9979172,80785.6953125,80805.7421875,57.0166739638137,20.6470453088961,21.3904,0,0,0,40,4449,99.83015,80795.71875,,,,,,,,,,,,,0,,,,0.0049,,,,,,99.9979172,,,,
,27317746.885,99.9967957,75869.3828125,-6.12914082816618E-6,2.5477622467185E-6,1,0.999253354069792,40.0298881530762,1.98382268881145,25.3199990838766,-6.31537152720099E-5,-4.68501428859094E-5,0.25,-3.07148668688738E-6,-6.15565821074577E-6,-3.10649944851292E-6,99.9967957,99.9967957,75851.890625,75886.875,57.149550812083,20.6522102897841,21.770052,0,0,0,40,4449,99.8365,75869.3828125,,,,,,,,,,,,,0,,,,0,,,,,,99.9967957,,,,
,27317842.195,99.9967422,71105.6171875,-4.11288399150866E-6,2.47634666747801E-6,1,0.999253354069792,40.0298881530762,1.98386738021589,25.3199990838766,-3.99804651806323E-5,-4.5103434858354E-5,0.25,-3.27056124462386E-6,-4.1271543967907E-6,-3.30105997112831E-6,99.9967422,99.9967422,71093.0859375,71118.1484375,57.4567308201407,20.6488208625896,22.149702,0,0,0,40,4449,99.8389,71105.6171875,,,,,,,,,,,,,0,,,,0.00245,,,,,,99.9967422,,,,
,27317939.11,99.9950333,66260.390625,-8.74045510699568E-7,2.97048191473825E-6,1,0.999253354069792,40.0298881530762,1.98400261326482,25.3199990838766,-2.17831211374087E-5,6.61118958089353E-5,0.25,6.00504847842261E-6,-8.96303041134947E-7,6.03694511675132E-6,99.9950333,99.9950333,66245.3203125,66275.4609375,57.2738297466407,20.6473031483416,21.770052,0,0,0,40,4449,99.8403,66260.390625,,,,,,,,,,,,,0,,,,-0.0049,,,,,,99.9950333,,,,
,27318035.185,99.9941025,61459.5625,3.40166891830844E-6,1.73117638001106E-6,1,0.999253354069792,40.0298881530762,1.9842264318486,25.3199990838766,2.69355722022862E-5,7.22607508673374E-5,0.25,5.79813581050247E-6,3.40436353684215E-6,5.8411477752903E-6,99.9941025,99.9941025,61447.12890625,61471.99609375,57.1964485232368,20.6411710241818,22.149702,0,0,0,40,4449,99.8468,61459.5625,,,,,,,,,,,,,0,,,,-0.0049,,,,,,99.9941025,,,,
,27318132.595,99.9948196,56589.17578125,4.29715430839886E-6,1.99625441718971E-6,1,0.999253354069792,40.0298881530762,1.98409320281498,25.3199990838766,5.18743281632741E-5,-1.04103160199516E-5,0.25,-1.67581704331188E-6,4.3265842155581E-6,-1.67287871472857E-6,99.9948196,99.9948196,56584.3203125,56594.03125,57.2269320354868,20.6441506304948,21.3904,0,0,0,40,4449,99.85155,56589.17578125,,,,,,,,,,,,,0,,,,0,,,,,,99.9948196,,,,
,27318230.35,99.9951935,51704.111328125,5.80619690080323E-7,1.5042800761159E-6,1,0.999253354069792,40.0298881530762,1.98399011935019,25.3199990838766,-1.89408440444235E-6,4.92988175539886E-5,0.25,4.2617265405394E-6,5.71438339704157E-7,4.28774047913434E-6,99.9951935,99.9951935,51691.73046875,51716.4921875,57.0932735586983,20.6469314133562,21.770052,0,0,0,40,4449,99.85655,51704.111328125,,,,,,,,,,,,,0,,,,-0.00245,,,,,,99.9951935,,,,
,27318325.38,99.99346545,46956.43359375,4.07840155998669E-6,1.55017597648681E-6,1,0.999253354069792,40.0298881530762,1.98381667613564,25.3199990838766,5.17673516687637E-5,-2.43459301030524E-5,0.25,-2.8713437658305E-6,4.11010653717123E-6,-2.87566647796416E-6,99.993454,99.9934769,46944.0703125,46968.796875,57.3254172289099,20.6492991387953,21.3904,0,0,0,40,4449,99.862,46956.43359375,,,,,,,,,,,,,0,,,,0,,,,,,99.99346545,,,,
,27318423.98,99.9928818,42026.14453125,6.30081905352051E-6,1.50264750880482E-6,1,0.999253354069792,40.0298881530762,1.98410502817023,25.3199990838766,7.57277714692251E-5,-1.33589745111732E-5,0.25,-2.2889754161267E-6,6.34345707674975E-6,-2.28328088891248E-6,99.9928818,99.9928818,42021.203125,42031.0859375,57.6920010044292,20.6446859745896,22.149702,0,0,0,40,4449,99.8703,42026.14453125,,,,,,,,,,,,,0,,,,-0.00245,,,,,,99.9928818,,,,
,27318519.735,99.99323275,37238.6640625,6.48512001617294E-6,1.23685509166118E-6,1,0.999253354069792,40.0298881530762,1.98440539530964,25.3199990838766,7.31689454866313E-5,1.34919957459641E-5,0.25,5.50031611290929E-8,6.52178976678381E-6,7.46997452661444E-8,99.9931641,99.9933014,37228.6875,37248.640625,57.4825245612753,20.6390314747179,21.3904,0,0,0,40,4449,99.8752,37238.6640625,,,,,,,,,,,,,0,,,,-0.00245,,,,,,99.99323275,,,,
,27318617.615,99.9910812,32346.015625,7.37445917682988E-6,1.22248495309416E-6,1,0.999253354069792,40.0298881530762,1.98406425048821,25.3199990838766,8.69991564017699E-5,-6.35320942418119E-6,0.25,-1.85774412299576E-6,7.42187144910858E-6,-1.84609845726823E-6,99.9910812,99.9910812,32330.947265625,32361.083984375,57.383257739333,20.644392054973,21.770052,0,0,0,40,4449,99.8823,32346.015625,,,,,,,,,,,,,0,,,,-0.00245,,,,,,99.9910812,,,,
,27318715.56,99.991684,27454.2880859375,6.74146903954445E-6,1.29905670986593E-6,1,0.999253354069792,40.0298881530762,1.98466993176027,25.3199990838766,7.93232157107328E-5,-4.49325950772582E-6,0.25,-1.58193566966358E-6,6.78443556576107E-6,-1.57049234890068E-6,99.991684,99.991684,27444.62109375,27463.955078125,57.4168677656599,20.6329446625987,21.770052,0,0,0,40,4449,99.89115,27454.2880859375,,,,,,,,,,,,,0,,,,0,,,,,,99.991684,,,,
,27318812.27,99.9911728,22618.7998046875,9.81143811365842E-6,1.04859121410944E-6,1,0.999253354069792,40.0298881530762,1.98430307117002,25.3199990838766,0.000111802857457166,1.40781613306347E-5,0.25,-4.77804155273319E-7,9.86837985106085E-6,-4.5063860464291E-7,99.9911728,99.9911728,22611.4140625,22626.185546875,57.3676251689484,20.6423586169636,21.3904,0,0,0,40,4449,99.9,22618.7998046875,,,,,,,,,,,,,0,,,,0,,,,,,99.9911728,,,,
,27318909.34,99.9915085,17766.3759765625,1.10455687010566E-5,8.65812250915741E-7,1,0.999253354069792,40.0298881530762,1.98406586242347,25.3199990838766,0.000126759173904643,1.06770263950637E-5,0.25,-9.9573950692471E-7,1.11109976199638E-5,-9.67547118914778E-7,99.9915085,99.9915085,17753.623046875,17779.12890625,57.3269804859484,20.645697031809,21.3904,0,0,0,40,4449,99.9078,17766.3759765625,,,,,,,,,,,,,0,,,,-0.00245,,,,,,99.9915085,,,,
,27319003.11,99.9926758,13081.2890625,1.07596693267095E-5,6.36447868127904E-7,1,0.999253354069792,40.0298881530762,1.98416679779395,25.3199990838766,0.000125546061146489,-1.33613949422641E-6,0.25,-2.00906316479041E-6,1.08265396791611E-5,-1.98728179177941E-6,99.9926758,99.9926758,13071.1435546875,13091.4345703125,57.4364084786407,20.6461493559844,22.149702,0,0,0,40,4449,99.9145,13081.2890625,,,,,,,,,,,,,0,,,,-0.0049,,,,,,99.9926758,,,,
,27319096.725,99.9922791,8400.91650390625,1.02649255062806E-5,6.07786686339928E-7,1,0.999253354069792,40.0298881530762,1.98428350374227,25.3199990838766,0.000116520133637016,1.72714561792671E-5,0.25,-2.75298232808356E-7,1.03236037836006E-5,-2.45104906823436E-7,99.9922791,99.9922791,8388.5361328125,8413.296875,57.5927341824868,20.6431728685464,21.3904,0,0,0,40,4449,99.92155,8400.91650390625,,,,,,,,,,,,,0,,,,-0.0049,,,,,,99.9922791,,,,
,27319190.89,99.9938126,3695.41186523438,1.00159662031206E-5,3.9990084456473E-7,1,0.999253354069792,40.0298881530762,1.98451493446571,25.3199990838766,0.000114603957434049,1.17460615894395E-5,0.25,-7.20849191859725E-7,1.00745669929578E-5,-6.93795358047358E-7,99.9938126,99.9938126,3685.18823242188,3705.63549804687,57.3332335141022,20.6376049187258,21.770052,0,0,0,40,4449,99.92665,3695.41186523438,,,,,,,,,,,,,0,,,,-0.0049,,,,,,99.9938126,,,,
,27319284.53,99.9938126,-983.828857421875,1.03452380533529E-5,2.87919870060875E-7,1,0.999253354069792,40.0298881530762,1.98418726687129,25.3199990838766,0.000116966937301593,2.0013640909897E-5,0.25,-4.68078072194744E-8,1.04035675755264E-5,-1.48711507734941E-8,99.9938126,99.9938126,-1001.27209472656,-966.385620117187,57.3793495967368,20.6461657508376,22.149702,0,0,0,40,4449,99.92895,-983.828857421875,,,,,,,,,,,,,0,,,,-0.00245,,,,,,99.9938126,,,,
,27319377.1,99.9986725,-5609.84448242188,8.65284883379284E-6,3.76981260926671E-7,1,0.999253354069792,40.0298881530762,1.98421442889612,25.3199990838766,9.74517903258506E-5,1.89144724651047E-5,0.25,1.53434166551984E-7,8.70108537071812E-6,1.81126567485012E-7,99.9986725,99.9986725,-5617.29052734375,-5602.3984375,57.4387533641984,20.6446839075389,21.3904,0,0,0,40,4449,99.92905,-5609.84448242188,,,,,,,,,,,,,0,,,,-0.00245,,,,,,99.9986725,,,,
,27319473.335,100.0046616,-10417.890625,4.20909678746872E-6,5.81297848953543E-7,1,0.999253354069792,40.0298881530762,1.98435732977327,25.3199990838766,4.52120548980579E-5,2.16974977226649E-5,0.25,1.18069061263939E-6,4.22917676422205E-6,1.20033388999441E-6,100.0046616,100.0046616,-10430.501953125,-10405.279296875,57.1706547821022,20.6435100420052,21.770052,0,0,0,40,4449,99.92475,-10417.890625,,,,,,,,,,,,,0,,,,0,,,,,,100.0046616,,,,
,27319567.985,100.0069427,-15150.9311523438,-1.31283570609767E-6,6.67422614094304E-7,1,0.999253354069792,40.0298881530762,1.9842344910888,25.3199990838766,-1.57296142019717E-5,2.4999600264128E-6,0.25,4.51970744777063E-7,-1.3216320451943E-6,4.50490491696942E-7,100.0069427,100.0069427,-15158.5302734375,-15143.33203125,57.4754899046022,20.6456942474063,21.770052,0,0,0,40,4449,99.91555,-15150.9311523438,,,,,,,,,,,,,0,,,,0.0049,,,,,,100.0069427,,,,
,27319664.905,100.0089417,-19992.9453125,-3.70641224595161E-6,7.44825253026691E-7,1,0.999253354069792,40.0298881530762,1.98425680279047,25.3199990838766,-4.28660773080069E-5,-1.72089086214987E-6,0.25,4.98919382284591E-7,-3.7288800014081E-6,4.90421551354171E-7,100.0089417,100.0089417,-20005.607421875,-19980.283203125,57.2269320354868,20.6475114295072,22.149702,0,0,0,40,4449,99.90855,-19992.9453125,,,,,,,,,,,,,0,,,,0,,,,,,100.0089417,,,,
,27319761.165,100.012413,-24805.1328125,-7.29138289104511E-6,9.90608810116339E-7,1,0.999253354069792,40.0298881530762,1.98416549465962,25.3199990838766,-8.13859250541793E-5,-2.01107104909064E-5,0.25,-4.99054064149286E-7,-7.33112618090386E-6,-5.24015487968565E-7,100.012413,100.012413,-24817.736328125,-24792.529296875,57.027616763083,20.6463033217852,21.770052,0,0,0,40,4449,99.8974,-24805.1328125,,,,,,,,,,,,,0,,,,0.00245,,,,,,100.012413,,,,
,27319857.19,100.0107651,-29602.7685546875,-4.98695032145624E-6,9.84154555428783E-7,1,0.999253354069792,40.0298881530762,1.98422919492343,25.3199990838766,-5.67248313117533E-5,-7.72910202083323E-6,0.25,1.9195603610607E-7,-5.01578820610291E-6,1.77991481201001E-7,100.0107651,100.0107651,-29615.12109375,-29590.416015625,57.3113479155637,20.6442437015092,21.770052,0,0,0,40,4449,99.88725,-29602.7685546875,,,,,,,,,,,,,0,,,,-0.00245,,,,,,100.0107651,,,,
,27319953.485,100.0103683,-34415.17578125,-5.53798273182684E-6,1.25835985320933E-6,1,0.999253354069792,40.0298881530762,1.98437481676743,25.3199990838766,-6.76889190041385E-5,1.81250099405013E-5,0.25,2.57684885797744E-6,-5.57713918181459E-6,2.57485688443524E-6,100.0103683,100.0103683,-34427.64453125,-34402.70703125,57.5223876157561,20.6450356865515,21.3904,0,0,0,40,4449,99.8769,-34415.17578125,,,,,,,,,,,,,0,,,,0,,,,,,100.0103683,,,,
,27320051.795,100.0106049,-39329.501953125,-2.95142649763986E-6,1.6763681404088E-6,1,0.999253354069792,40.0298881530762,1.98420217597009,25.3199990838766,-3.32578627891668E-5,-6.36017424361168E-6,0.25,-4.4567158313382E-8,-2.96806634968842E-6,-5.36188643537636E-8,100.0106049,100.0106049,-39339.5,-39319.50390625,57.2832092888714,20.6446332879439,21.3904,0,0,0,40,4449,99.86765,-39329.501953125,,,,,,,,,,,,,0,,,,0,,,,,,100.0106049,,,,
,27320151.13,100.010582,-44294.138671875,-4.3648914579865E-6,1.65236449842935E-6,1,0.999253354069792,40.0298881530762,1.98421846153537,25.3199990838766,-5.51630771852501E-5,2.46286918510139E-5,0.25,2.94632488757814E-6,-4.39845969798494E-6,2.95016642376205E-6,100.010582,100.010582,-44306.6171875,-44281.66015625,57.2824276603522,20.6442997768963,21.770052,0,0,0,40,4449,99.8579,-44294.138671875,,,,,,,,,,,,,0,,,,0,,,,,,100.010582,,,,
,27320248.685,100.0100708,-49169.71484375,-7.18595520644364E-6,1.75866016037368E-6,1,0.999253354069792,40.0298881530762,1.984312548468,25.3199990838766,-8.41922804813675E-5,2.80802317568787E-6,0.25,1.51030461646651E-6,-7.23135706949961E-6,1.49776890215338E-6,100.0100708,100.0100708,-49174.65234375,-49164.77734375,57.3551191126407,20.6445397296972,22.149702,0,0,0,40,4449,99.84645,-49169.71484375,,,,,,,,,,,,,0,,,,-0.0049,,,,,,100.0100708,,,,
,27320345.78,100.0088806,-54021.529296875,-2.5042139982471E-6,2.12535042162403E-6,1,0.999253354069792,40.0298881530762,1.98401990237442,25.3199990838766,-4.52653717563587E-5,9.17076703780181E-5,0.25,8.55699220881287E-6,-2.54352024254512E-6,8.59851641291976E-6,100.0088806,100.0088806,-54031.4140625,-54011.64453125,57.352774227083,20.6475932660351,21.770052,0,0,0,40,4449,99.8381,-54021.529296875,,,,,,,,,,,,,0,,,,-0.0049,,,,,,100.0088806,,,,
,27320443.75,100.0077362,-58918.7890625,-2.12595903505824E-6,2.32873402167129E-6,1,0.999253354069792,40.0298881530762,1.98435759266054,25.3199990838766,-3.61938789508617E-5,6.51136392462173E-5,0.25,6.13561472775065E-6,-2.15592479898859E-6,6.16451730214448E-6,100.0077362,100.0077362,-58928.80859375,-58908.76953125,57.4926857320253,20.6430713181811,22.149702,0,0,0,40,4449,99.83225,-58918.7890625,,,,,,,,,,,,,0,,,,0,,,,,,100.0077362,,,,
,27320540.025,100.0080261,-63731.095703125,-5.38999422469845E-6,2.55562421449095E-6,1,0.999253354069792,40.0298881530762,1.9842636848595,25.3199990838766,-6.58570590746529E-5,1.75300619412041E-5,0.25,2.49753091680429E-6,-5.42805277241522E-6,2.49628582877989E-6,100.0080261,100.0080261,-63736.00390625,-63726.1875,57.4325003360445,20.6430500555573,22.149702,0,0,0,40,4449,99.82485,-63731.095703125,,,,,,,,,,,,,0,,,,0,,,,,,100.0080261,,,,
,27320638.1,100.0073547,-68630.87109375,1.74831470933602E-6,2.74592353968968E-6,1,0.999253354069792,40.0298881530762,1.9842420554123,25.3199990838766,1.91635289999479E-5,6.83642305200386E-6,0.25,2.98179220414002E-7,1.75748416444932E-6,3.04895390947838E-7,100.0073547,100.0073547,-68643.375,-68618.3671875,57.4723633905253,20.641245692723,22.149702,0,0,0,40,4449,99.81845,-68630.87109375,,,,,,,,,,,,,0,,,,-0.0049,,,,,,100.0073547,,,,
,27320733.53,100.0076828,-73400.3046875,5.68912341593422E-6,2.50406220749228E-6,1,0.999253354069792,40.0298881530762,1.98436405450913,25.3199990838766,6.07674266592718E-5,3.13435189193987E-5,0.25,1.77533391207314E-6,5.71673562137737E-6,1.80170886682762E-6,100.0076828,100.0076828,-73410.25,-73390.359375,57.3387049137368,20.6409596635618,22.149702,0,0,0,40,4449,99.80785,-73400.3046875,,,,,,,,,,,,,0,,,,0,,,,,,100.0076828,,,,
,27320830.92,100.0070038,-78267.11328125,-6.26033903284002E-6,2.72530707745874E-6,1,0.999253354069792,40.0298881530762,1.9841908296649,25.3199990838766,-6.18152360211731E-5,-6.3261827846938E-5,0.25,-4.50020822294318E-6,-6.28362114174025E-6,-4.54376411904615E-6,100.0070038,100.0070038,-78277.203125,-78257.0234375,57.3902923960061,20.6448376577523,21.770052,0,0,0,40,4449,99.80355,-78267.11328125,,,,,,,,,,,,,0,,,,-0.00245,,,,,,100.0070038,,,,
,27320929.455,100.0064468,-83194.49609375,4.7078103636716E-6,2.60807376201495E-6,1,0.999253354069792,40.0298881530762,1.98444194315231,25.3199990838766,6.20043431819892E-5,-4.08343699232351E-5,0.25,-4.43937030101498E-6,4.74736559570789E-6,-4.45172877468051E-6,100.0064468,100.0064468,-83209.46875,-83179.5234375,57.2081729510253,20.6428287344864,22.149702,0,0,0,40,4449,99.8012,-83194.49609375,,,,,,,,,,,,,0,,,,0,,,,,,100.0064468,,,,
,27321024.44,100.0074692,-87938.8125,8.79182108439565E-6,3.11874387376274E-6,1,0.999253354069792,40.0298881530762,1.98432392759158,25.3199990838766,8.58317849498762E-5,9.44898971222673E-5,0.25,6.81934228517354E-6,8.82351809849959E-6,6.88314425651473E-6,100.0074692,100.0074692,-87951.3515625,-87926.2734375,57.3566823696791,20.645206769093,21.770052,0,0,0,40,4449,99.7942,-87938.8125,,,,,,,,,,,,,0,,,,0.00245,,,,,,100.0074692,,,,
,27321138.43,100.0024567,-87571.046875,5.91137214904759E-7,3.21882228754591E-6,1,0.999253354069792,40.0298881530762,1.98432309388549,25.3199990838766,-4.53354787990023E-6,6.50919407129382E-5,0.25,5.656480369165E-6,5.78781479986733E-7,5.69073646389597E-6,100.0024567,100.0024567,-87578.46875,-87563.625,57.3637170263522,20.643043824917,22.149702,0,0,0,40,4449,99.78755,-87571.046875,,,,,,,,,,,,,0,,,,-0.00245,,,,,,100.0024567,,,,
,27321231.645,100.0018692,-82912.046875,9.04105804192609E-7,2.7963206322203E-6,1,0.999253354069792,40.0298881530762,1.98438259603311,25.3199990838766,-7.38734900156448E-6,0.000102129445177946,0.25,8.87896033244511E-6,8.84397048019477E-7,8.93261418188596E-6,100.0018692,100.0018692,-82916.8828125,-82907.2109375,57.7342089444676,20.6441381844502,21.770052,0,0,0,40,4449,99.7899,-82912.046875,,,,,,,,,,,,,0,,,,0,,,,,,100.0018692,,,,
,27321327.64,99.9985046,-78114.41796875,-2.87355562719101E-7,2.49367485749433E-6,1,0.999253354069792,40.0298881530762,1.98431131822448,25.3199990838766,2.97876605948476E-6,-3.60506938905309E-5,0.25,-3.13990264695965E-6,-2.80135158656527E-7,-3.15876615798141E-6,99.9985046,99.9985046,-78119.5,-78109.3359375,57.3504293415253,20.6444942605584,21.770052,0,0,0,40,4449,99.79135,-78114.41796875,,,,,,,,,,,,,0,,,,0,,,,,,99.9985046,,,,
,27321425.215,99.9984818,-73239.578125,3.96970310956746E-6,2.71209886581699E-6,1,0.999253354069792,40.0298881530762,1.98433330295959,25.3199990838766,3.67014842221897E-5,5.43479685486824E-5,0.25,4.11290660645369E-6,3.98078787663231E-6,4.14781486070345E-6,99.9984818,99.9984818,-73252.3515625,-73226.8046875,57.1487691835637,20.6425667906174,22.149702,0,0,0,40,4449,99.79335,-73239.578125,,,,,,,,,,,,,0,,,,0,,,,,,99.9984818,,,,
,27321521.055,99.9968643,-68447.81640625,-6.3009751143665E-6,2.74318594642496E-6,1,0.999253354069792,40.0298881530762,1.9847949488532,25.3199990838766,-8.23169852662463E-5,5.07499149705531E-5,0.25,5.59609810286781E-6,-6.35313199847281E-6,5.61012252277807E-6,99.9968643,99.9968643,-68455.3828125,-68440.25,57.1753445532176,20.641677893492,22.149702,0,0,0,40,4449,99.79485,-68447.81640625,,,,,,,,,,,,,0,,,,0,,,,,,99.9968643,,,,
,27321617.18,99.9967575,-63645.341796875,-2.10304011622109E-6,2.53310857219023E-6,1,0.999253354069792,40.0298881530762,1.98442699335467,25.3199990838766,-4.26992436452189E-5,0.000103696776160895,0.25,9.54566145956373E-6,-2.14261989785639E-6,9.59423655806488E-6,99.9967575,99.9967575,-63657.82421875,-63632.859375,57.3199458292753,20.6399937709356,22.149702,0,0,0,40,4449,99.79925,-63645.341796875,,,,,,,,,,,,,0,,,,0,,,,,,99.9967575,,,,
,27321715.485,99.994339,-58730.724609375,-1.33857190277406E-5,1.92310857306904E-6,1,0.999253354069792,40.0298881530762,1.98444740678132,25.3199990838766,-0.000164673813595956,4.98456226173915E-5,0.25,6.76093402067754E-6,-1.34818731322022E-5,6.76069097384728E-6,99.994339,99.994339,-58745.82421875,-58715.625,57.4012351952753,20.6405625226041,22.149702,0,0,0,40,4449,99.80525,-58730.724609375,,,,,,,,,,,,,0,,,,0,,,,,,99.994339,,,,
,27321811.845,99.9943085,-53915.86328125,-5.70154056918382E-6,8.81139321937717E-7,1,0.999253354069792,40.0298881530762,1.98444733279385,25.3199990838766,-8.92983337959708E-5,0.000130341061439777,0.25,1.25355553872844E-5,-5.77074677608347E-6,1.25904275021604E-5,99.9943085,99.9943085,-53923.4140625,-53908.3125,57.2667950899676,20.6408888258636,21.770052,0,0,0,40,4449,99.80935,-53915.86328125,,,,,,,,,,,,,0,,,,-0.00245,,,,,,99.9943085,,,,
,27321907.54,99.99433135,-49133.904296875,-9.06107267343662E-6,1.98383156199545E-6,1,0.999253354069792,40.0298881530762,1.9843900798319,25.3199990838766,-0.000107941798114647,1.36566607154881E-5,0.25,2.79965153043837E-6,-9.12095709809191E-6,2.78893122586247E-6,99.9942627,99.9944,-49146.24609375,-49121.5625,57.4434431353138,20.6402205263956,21.3904,0,0,0,40,4449,99.8154,-49133.904296875,,,,,,,,,,,,,0,,,,-0.00245,,,,,,99.99433135,,,,
,27322003.665,99.99366,-44328.689453125,-1.09506752846672E-5,1.95024238598961E-6,1,0.999253354069792,40.0298881530762,1.98448930887042,25.3199990838766,-0.000108481835023756,-0.000108634631200273,0.25,-7.69056189052774E-6,-1.09902067911861E-5,-7.76677892791553E-6,99.99366,99.99366,-44338.62109375,-44318.7578125,57.4629838482945,20.6408938793726,21.3904,0,0,0,40,4449,99.8219,-44328.689453125,,,,,,,,,,,,,0,,,,0,,,,,,99.99366,,,,
,27322102.495,99.9923172,-39391.330078125,-1.02084265164055E-5,1.30156517410678E-6,1,0.999253354069792,40.0298881530762,1.98429129125613,25.3199990838766,-0.000129553056371514,6.06473942528765E-5,0.25,7.1605084425977E-6,-1.02877948824594E-5,7.17074779077112E-6,99.9923172,99.9923172,-39401.3515625,-39381.30859375,57.1831608384099,20.6420122571523,22.149702,0,0,0,40,4449,99.82715,-39391.330078125,,,,,,,,,,,,,0,,,,0,,,,,,99.9923172,,,,
,27322200.29,99.9911957,-34501.892578125,-8.89213800647554E-6,1.23660459996072E-6,1,0.999253354069792,40.0298881530762,1.98438462986524,25.3199990838766,-0.000100604282033435,-1.69081245546903E-5,0.25,6.55258194592567E-8,-8.94279037033757E-6,3.92046693965942E-8,99.9911957,99.9911957,-34514.45703125,-34489.328125,57.3668435404292,20.6415505732526,21.770052,0,0,0,40,4449,99.8355,-34501.892578125,,,,,,,,,,,,,0,,,,-0.0049,,,,,,99.9911957,,,,
,27322293.575,99.9932938,-29839.9072265625,-7.19653270274729E-6,9.67941151776608E-7,1,0.999253354069792,40.0298881530762,1.98452683362416,25.3199990838766,-9.28974368769321E-5,5.16194250426253E-5,0.25,5.83236169861566E-6,-7.25492208201302E-6,5.84367761058667E-6,99.9932938,99.9932938,-29847.24609375,-29832.568359375,57.3004051162945,20.6402062665755,22.529354,0,0,0,40,4449,99.8423,-29839.9072265625,,,,,,,,,,,,,0,,,,-0.0049,,,,,,99.9932938,,,,
,27322389.14,99.99004365,-25064.5224609375,-1.1768079400183E-5,1.12840861753716E-6,1,0.999253354069792,40.0298881530762,1.98443482460835,25.3199990838766,-0.000142165851256778,2.89778425393619E-5,0.25,4.63210129653317E-6,-1.1848737576966E-5,4.62256537979183E-6,99.9896393,99.990448,-25079.466796875,-25049.578125,57.78266991266,20.6429080028671,21.770052,0,0,0,40,4449,99.85145,-25064.5224609375,,,,,,,,,,,,,0,,,,0.00245,,,,,,99.99004365,,,,
,27322483.5,99.9903564,-20350.009765625,-1.1000507337857E-5,9.86890506926782E-7,1,0.999253354069792,40.0298881530762,1.98488555695293,25.3199990838766,-0.000125144854652007,-1.71674341763637E-5,0.25,4.13830445588508E-7,-1.10639310526613E-5,3.825647217341E-7,99.9903564,99.9903564,-20362.646484375,-20337.373046875,57.2519441481022,20.6382638943225,22.149702,0,0,0,40,4449,99.85765,-20350.009765625,,,,,,,,,,,,,0,,,,-0.00735,,,,,,99.9903564,,,,
,27322579,99.9916458,-15575.0454101562,-8.6060681858305E-6,9.65823309964733E-7,1,0.999253354069792,40.0298881530762,1.98474447781221,25.3199990838766,-0.000102577041606867,1.31991810376003E-5,0.25,2.68028684112344E-6,-8.66286495473913E-6,2.66897852837825E-6,99.9916458,99.9916458,-15585.0029296875,-15565.087890625,57.4004535667561,20.6357104789591,22.149702,0,0,0,40,4449,99.86635,-15575.0454101562,,,,,,,,,,,,,0,,,,-0.0049,,,,,,99.9916458,,,,
,27322676.225,99.9916992,-10717.810546875,-8.18221764489968E-6,7.67500042882561E-7,1,0.999253354069792,40.0298881530762,1.98505747613476,25.3199990838766,-9.4933827066519E-5,-2.27629066807207E-6,0.25,1.23654313924047E-6,-8.23214811906616E-6,1.21824864856199E-6,99.9916992,99.9916992,-10727.6494140625,-10707.9716796875,57.6396318936407,20.6335933249984,22.149702,0,0,0,40,4449,99.87445,-10717.810546875,,,,,,,,,,,,,0,,,,0.0049,,,,,,99.9916992,,,,
,27322765.86,99.9922256,-6236.79931640625,-1.05463833844799E-5,5.22313425442505E-7,1,0.999253354069792,40.0298881530762,1.984607530156,25.3199990838766,-0.000119116929344254,-2.12545462736102E-5,0.25,-2.74054692037992E-8,-1.06056682669314E-5,-6.02674211538205E-8,99.9922256,99.9922256,-6239.24658203125,-6234.35205078125,57.2542890336599,20.6341470427395,22.149702,0,0,0,40,4449,99.8812,-6236.79931640625,,,,,,,,,,,,,0,,,,0,,,,,,99.9922256,,,,
,27322858.655,99.99107745,-1598.02313232422,-9.25277135721066E-6,3.97155322796625E-7,1,0.999253354069792,40.0298881530762,1.98461578942451,25.3199990838766,-0.000104556093908409,-1.83622702063328E-5,0.25,1.30559085880137E-9,-9.30481164527375E-6,-2.74950312392077E-8,99.9910355,99.9911194,-1605.56433105469,-1590.48193359375,57.0354330482753,20.6381687296298,22.149702,0,0,0,40,4449,99.88805,-1598.02313232422,,,,,,,,,,,,,0,,,,0.00245,,,,,,99.99107745,,,,
,27322951.39,99.9959869,3032.04089355469,-8.97137205294099E-6,3.95810640094185E-7,1,0.999253354069792,40.0298881530762,1.98448383551577,25.3199990838766,-0.000100509114543046,-2.27007617053091E-5,0.25,-4.32259420386265E-7,-9.02049563349793E-6,-4.62590219562615E-7,99.9959869,99.9959869,3022.07348632812,3042.00830078125,57.3574639981984,20.6391659631552,22.149702,0,0,0,40,4449,99.8904,3032.04089355469,,,,,,,,,,,,,0,,,,-0.0049,,,,,,99.9959869,,,,
,27323046.715,100.00060655,7799.32495117187,-6.30346385479601E-6,6.76069345028114E-7,1,0.999253354069792,40.0298881530762,1.98489283168818,25.3199990838766,-6.98276271964428E-5,-2.05418850735375E-5,0.25,-7.09825858116452E-7,-6.33676461451392E-6,-7.33339953072345E-7,100.0003586,100.0008545,7786.70751953125,7811.9423828125,57.4778347901599,20.6356678744792,22.149702,0,0,0,40,4449,99.88825,7799.32495117187,,,,,,,,,,,,,0,,,,0.0049,,,,,,100.00060655,,,,
,27323141.57,100.0047684,12539.904296875,1.92437199760862E-6,7.5962470375541E-7,1,0.999253354069792,40.0298881530762,1.98514568952107,25.3199990838766,2.41764436927764E-5,-9.98063073271008E-6,0.25,-1.22119897040252E-6,1.93898495831273E-6,-1.22215557730426E-6,100.0047684,100.0047684,12529.94140625,12549.8671875,57.3738781971022,20.6326805872683,22.149702,0,0,0,40,4449,99.8834,12539.904296875,,,,,,,,,,,,,0,,,,0.00245,,,,,,100.0047684,,,,
,27323238.625,100.0072403,17392.3955078125,4.72903227235503E-6,6.23744739333283E-7,1,0.999253354069792,40.0298881530762,1.9844873895123,25.3199990838766,5.82796303336955E-5,-1.81816531523787E-5,0.25,-2.4400589713518E-6,4.76320934120265E-6,-2.43934276760477E-6,100.0072403,100.0072403,17377.390625,17407.400390625,57.4043617093522,20.6369776336872,21.770052,0,0,0,40,4449,99.8752,17392.3955078125,,,,,,,,,,,,,0,,,,0.0049,,,,,,100.0072403,,,,
,27323335.76,100.0080032,22245.2646484375,7.33041391559868E-6,1.06201574634824E-6,1,0.999253354069792,40.0298881530762,1.98449704812608,25.3199990838766,8.4387326941169E-5,5.69013606913141E-6,0.25,-7.84371132227134E-7,7.3742474679253E-6,-7.66467896071805E-7,100.0080032,100.0080032,22235.294921875,22255.234375,57.3355783996599,20.6369075502809,22.149702,0,0,0,40,4449,99.86735,22245.2646484375,,,,,,,,,,,,,0,,,,0,,,,,,100.0080032,,,,
,27323433.95,100.0081635,27155.44921875,9.75056427765272E-6,1.1290833265772E-6,1,0.999253354069792,40.0298881530762,1.98454579277608,25.3199990838766,0.000114207241671378,-3.5646773163632E-6,0.25,-2.02844225164566E-6,9.81191362481113E-6,-2.01039013974743E-6,100.0081635,100.0081635,27147.86328125,27163.03515625,57.0229269919676,20.6362304384604,22.149702,0,0,0,40,4449,99.85865,27155.44921875,,,,,,,,,,,,,0,,,,-0.0049,,,,,,100.0081635,,,,
,27323532.375,100.0098267,32072.947265625,6.5567834118174E-6,1.29213177533156E-6,1,0.999253354069792,40.0298881530762,1.98459557624652,25.3199990838766,7.47573808928272E-5,9.23681682441001E-6,0.25,-3.34377861007403E-7,6.59496607708771E-6,-3.16532441421056E-7,100.0098267,100.0098267,32060.365234375,32085.529296875,57.2925888311022,20.6383866803948,22.149702,0,0,0,40,4449,99.8467,32072.947265625,,,,,,,,,,,,,0,,,,0,,,,,,100.0098267,,,,
,27323630.875,100.01225665,36995.626953125,8.91897296745394E-6,1.41852469858742E-6,1,0.999253354069792,40.0298881530762,1.98443462070126,25.3199990838766,0.000100787449699961,1.7661356006166E-5,0.25,-3.5323278075502E-9,8.96962673741112E-6,2.31321578660776E-8,100.0120087,100.0125046,36983.0859375,37008.16796875,57.0158923352945,20.6386548036209,22.149702,0,0,0,40,4449,99.8376,36995.626953125,,,,,,,,,,,,,0,,,,0.0049,,,,,,100.01225665,,,,
,27323730.28,100.00951005,41965.55859375,6.71770947983259E-6,1.37753230727953E-6,1,0.999253354069792,40.0298881530762,1.98467743659887,25.3199990838766,8.30638333299991E-5,-2.73622493175038E-5,0.25,-3.60099845203943E-6,6.76661490533418E-6,-3.60150847529166E-6,100.0093994,100.0096207,41955.42578125,41975.69140625,57.0299616486406,20.6349849204774,22.149702,0,0,0,40,4449,99.8295,41965.55859375,,,,,,,,,,,,,0,,,,-0.00245,,,,,,100.00951005,,,,
,27323831.185,100.0096741,47008.349609375,7.47982033117732E-6,1.12077492471596E-6,1,0.999253354069792,40.0298881530762,1.98448482354547,25.3199990838766,9.28123709610198E-5,-3.23648897258158E-5,0.25,-4.17759177264941E-6,7.53475500923118E-6,-4.17930068178682E-6,100.0096741,100.0096741,46998.4375,47018.26171875,57.4317187075253,20.6359996622704,22.149702,0,0,0,40,4449,99.82025,47008.349609375,,,,,,,,,,,,,0,,,,0.00245,,,,,,100.0096741,,,,
,27323930.375,100.0089417,51965.638671875,4.99341515034463E-6,1.55258148764875E-6,1,0.999253354069792,40.0298881530762,1.98456055481686,25.3199990838766,7.14587860342622E-5,-7.56934136435696E-5,0.25,-7.57489892509705E-6,5.04411209772474E-6,-7.60346132999263E-6,100.0089417,100.0089417,51955.5703125,51975.70703125,57.2050464369484,20.6341980350662,21.770052,0,0,0,40,4449,99.8113,51965.638671875,,,,,,,,,,,,,0,,,,0.0049,,,,,,100.0089417,,,,
,27324034.145,100.0098877,57153.009765625,8.04231079661332E-6,2.2627725623117E-6,1,0.999253354069792,40.0298881530762,1.98476324246286,25.3199990838766,0.00010304216617762,-5.32435136576162E-5,0.25,-6.12293376196158E-6,8.10608395879432E-6,-6.13449529270195E-6,100.0098877,100.0098877,57148.09765625,57157.921875,57.3535558556022,20.6355377406497,22.149702,0,0,0,40,4449,99.80285,57153.009765625,,,,,,,,,,,,,0,,,,0,,,,,,100.0098877,,,,
,27324133.98,100.0085297,62143.380859375,4.04894087376768E-6,1.94950632071053E-6,1,0.999253354069792,40.0298881530762,1.98472229488913,25.3199990838766,5.5685504830608E-5,-4.85084156353362E-5,0.25,-5.00284266666134E-6,4.08657283295561E-6,-5.01975803671934E-6,100.0085297,100.0085297,62135.73046875,62151.03125,57.3058765159291,20.6327891731418,21.770052,0,0,0,40,4449,99.79495,62143.380859375,,,,,,,,,,,,,0,,,,-0.00245,,,,,,100.0085297,,,,
,27324235.96,100.0073013,67241.65234375,3.19873645656376E-6,1.23873604934308E-6,1,0.999253354069792,40.0298881530762,1.98481697420728,25.3199990838766,4.68711333722324E-5,-5.47169526810635E-5,0.25,-5.40259057207729E-6,3.23257556481915E-6,-5.42436552391805E-6,100.0073013,100.0073013,67224.21875,67259.0859375,57.3504293415253,20.6318446543637,22.529354,0,0,0,40,4449,99.78935,67241.65234375,,,,,,,,,,,,,0,,,,0.0049,,,,,,100.0073013,,,,
,27324335.07,100.00650785,72194.234375,5.55956288618683E-7,2.2501418186009E-6,1,0.999253354069792,40.0298881530762,1.98494304531372,25.3199990838766,1.72715690083299E-5,-6.15047549716989E-5,0.25,-5.53888975577793E-6,5.74935888954284E-7,-5.56909054964736E-6,100.0062332,100.0067825,72181.6875,72206.78125,57.0940551872176,20.6270661755546,22.149702,0,0,0,40,4449,99.7826,72194.234375,,,,,,,,,,,,,0,,,,0.00245,,,,,,100.00650785,,,,
,27324433.215,100.0079803,77099.5859375,8.06434112498275E-6,1.8992249155756E-6,1,0.999253354069792,40.0298881530762,1.98493192318905,25.3199990838766,0.000103786909814764,-5.59964178073479E-5,0.25,-6.36906974686736E-6,8.12871415119055E-6,-6.38284469662726E-6,100.0079803,100.0079803,77084.6171875,77114.5546875,57.0409044479099,20.6295732345689,22.149702,0,0,0,40,4449,99.77515,77099.5859375,,,,,,,,,,,,,0,,,,-0.00245,,,,,,100.0079803,,,,
,27324532.235,100.0060425,82047.9921875,2.54509036517201E-6,2.45692130987484E-6,1,0.999253354069792,40.0298881530762,1.98477638609551,25.3199990838766,4.166146240641E-5,-6.84485061185721E-5,0.25,-6.50252895275605E-6,2.57801250549542E-6,-6.53279950360952E-6,100.0060425,100.0060425,82037.8828125,82058.1015625,57.1612752398714,20.6322876433956,22.149702,0,0,0,40,4449,99.7697,82047.9921875,,,,,,,,,,,,,0,,,,0,,,,,,100.0060425,,,,
,27324633.43,100.006073,87108.6640625,2.89432028473373E-6,1.99249482537798E-6,1,0.999253354069792,40.0298881530762,1.9845881777494,25.3199990838766,4.69817329782213E-5,-7.56072206311838E-5,0.25,-7.19763534432929E-6,2.93108150647823E-6,-7.2310450550451E-6,100.006073,100.006073,87101.296875,87116.03125,57.0362146767945,20.6333957562356,22.149702,0,0,0,40,4449,99.76385,87108.6640625,,,,,,,,,,,,,0,,,,0,,,,,,100.006073,,,,
,27324757.77,100.0005875,88097.9375,7.93083306964895E-6,1.86960003761563E-6,1,0.999253354069792,40.0298881530762,1.98449402287954,25.3199990838766,9.66854734063599E-5,-2.45036418098062E-5,0.25,-3.55953204793515E-6,7.98647276232332E-6,-3.55795980988675E-6,100.0005875,100.0005875,88082.8828125,88112.9921875,56.9064643426022,20.633159742253,22.529354,0,0,0,40,4449,99.76015,88097.9375,,,,,,,,,,,,,0,,,,0.00245,,,,,,100.0005875,,,,
,27324856.29,99.9995346,83174.85546875,4.41974680701448E-6,1.95251389668818E-6,1,0.999253354069792,40.0298881530762,1.98437947769909,25.3199990838766,5.61018477339634E-5,-2.63264253534082E-5,0.25,-3.10511828320196E-6,4.4539048649571E-6,-3.11059249931739E-6,99.9995346,99.9995346,83169.6875,83180.0234375,57.3949821671215,20.6364683967937,22.149702,0,0,0,40,4449,99.76175,83174.85546875,,,,,,,,,,,,,0,,,,-0.0049,,,,,,99.9995346,,,,
,27324953.895,99.9970627,78296.2109375,3.6804502616078E-6,1.98033153635315E-6,1,0.999253354069792,40.0298881530762,1.98447088368819,25.3199990838766,5.19707281313101E-5,-5.18476002165565E-5,0.25,-5.2337448194687E-6,3.71640013875899E-6,-5.25343182094652E-6,99.9970627,99.9970627,78281.328125,78311.09375,57.251162519583,20.6374016862417,21.770052,0,0,0,40,4449,99.765,78296.2109375,,,,,,,,,,,,,0,,,,-0.0049,,,,,,99.9970627,,,,
,27325055.03,99.9963837,73235.1015625,3.6651398940748E-6,2.15684221153739E-6,1,0.999253354069792,40.0298881530762,1.9846193334842,25.3199990838766,4.360242766285E-5,-5.15686920931602E-6,0.25,-1.09950475886059E-6,3.68930932938197E-6,-1.09538198354821E-6,99.9963837,99.9963837,73222.5703125,73247.6328125,57.2230238928907,20.636467941565,22.529354,0,0,0,40,4449,99.76895,73235.1015625,,,,,,,,,,,,,0,,,,0,,,,,,99.9963837,,,,
,27325156.48,99.99556355,68167.19140625,5.11582988313358E-6,1.5784907256061E-6,1,0.999253354069792,40.0298881530762,1.98498763589852,25.3199990838766,6.16251268224812E-5,-1.14945296345897E-5,0.25,-1.91481086281493E-6,5.15064352887738E-6,-1.91111502132224E-6,99.995369,99.9957581,68154.5703125,68179.8125,57.4254656793715,20.6317547723231,22.529354,0,0,0,40,4449,99.77215,68167.19140625,,,,,,,,,,,,,0,,,,0,,,,,,99.99556355,,,,
,27325258.36,99.9934845,63074.470703125,8.04519905841285E-6,2.03400657074314E-6,1,0.999253354069792,40.0298881530762,1.98478075606058,25.3199990838766,0.000102935679821575,-5.24447241589371E-5,0.25,-6.0524662576059E-6,8.10872468961745E-6,-6.06386593398652E-6,99.9934845,99.9934845,63062.0625,63086.87890625,57.1440794124484,20.6348785071362,21.770052,0,0,0,40,4449,99.77875,63074.470703125,,,,,,,,,,,,,0,,,,0,,,,,,99.9934845,,,,
,27325358.15,99.9931297,58086.447265625,5.21094087960306E-6,1.84343944045842E-6,1,0.999253354069792,40.0298881530762,1.98481665046006,25.3199990838766,7.05288222659958E-5,-5.59280853131506E-5,0.25,-5.86323888897641E-6,5.25777382999343E-6,-5.88158595685371E-6,99.9929733,99.9932861,58078.765625,58094.12890625,57.4911224749868,20.6329917403111,21.770052,0,0,0,40,4449,99.7839,58086.447265625,,,,,,,,,,,,,0,,,,0.00245,,,,,,99.9931297,,,,
,27325455.35,99.9936447,53228.6328125,7.26448585553663E-6,1.82572723412244E-6,1,0.999253354069792,40.0298881530762,1.98494942795491,25.3199990838766,8.67033585628377E-5,-1.17508842943313E-5,0.25,-2.31511929962928E-6,7.31271717710782E-6,-2.30705605897619E-6,99.9936447,99.9936447,53215.921875,53241.34375,56.8939582862945,20.6338742270132,21.770052,0,0,0,40,4449,99.7928,53228.6328125,,,,,,,,,,,,,0,,,,-0.00245,,,,,,99.9936447,,,,
,27325554.28,99.9938126,48283.51171875,9.34049230216425E-6,1.29583548731589E-6,1,0.999253354069792,40.0298881530762,1.98484563063641,25.3199990838766,0.000114861142310903,-3.43907507413443E-5,0.25,-4.68303128190963E-6,9.40751699979554E-6,-4.68217252540359E-6,99.9938126,99.9938126,48278.45703125,48288.56640625,57.4715817620061,20.6327135188334,22.149702,0,0,0,40,4449,99.7965,48283.51171875,,,,,,,,,,,,,0,,,,0.0049,,,,,,99.9938126,,,,
,27325654.46,99.9921341,43278.462890625,6.83173976365044E-6,1.03863494566522E-6,1,0.999253354069792,40.0298881530762,1.98482237396285,25.3199990838766,8.95914128524343E-5,-5.69357168442501E-5,0.25,-6.23751750806503E-6,6.88911976450561E-6,-6.2527226406262E-6,99.9921341,99.9921341,43265.90625,43291.01953125,57.4231207938138,20.6318484757838,22.149702,0,0,0,40,4449,99.8045,43278.462890625,,,,,,,,,,,,,0,,,,0.00245,,,,,,99.9921341,,,,
,27325752.44,99.992157,38380.677734375,8.47751133320557E-6,1.39451521462641E-6,1,0.999253354069792,40.0298881530762,1.98473354781763,25.3199990838766,9.61779828459606E-5,1.47103538066449E-5,0.25,-1.87307924749823E-7,8.52622697851959E-6,-1.63044565372E-7,99.992157,99.992157,38373.13671875,38388.21875,57.1143775287176,20.6347261169312,22.529354,0,0,0,40,4449,99.8134,38380.677734375,,,,,,,,,,,,,0,,,,-0.0049,,,,,,99.992157,,,,
,27325849.49,99.9923477,33528.443359375,9.86833742740481E-6,1.0270479169398E-6,1,0.999253354069792,40.0298881530762,1.98466081738059,25.3199990838766,0.000116681742734688,-9.80181979818536E-6,0.25,-2.60080783988902E-6,9.93213086359145E-6,-2.58588928054279E-6,99.9923477,99.9923477,33515.92578125,33540.9609375,57.0229269919676,20.6371091233904,22.149702,0,0,0,40,4449,99.817,33528.443359375,,,,,,,,,,,,,0,,,,0,,,,,,99.9923477,,,,
,27325949.41,99.991066,28536.33203125,1.0679970392563E-5,9.04946029006616E-7,1,0.999253354069792,40.0298881530762,1.98471972535042,25.3199990838766,0.000125076237504751,-3.74737951753789E-6,0.25,-2.20782105208297E-6,1.07471380951515E-5,-2.18801179752133E-6,99.991066,99.991066,28528.982421875,28543.681640625,56.7548284098714,20.6336371334039,22.149702,0,0,0,40,4449,99.82565,28536.33203125,,,,,,,,,,,,,0,,,,0,,,,,,99.991066,,,,
,27326048.325,99.9909286,23590.982421875,9.22586033910664E-6,8.03754762861258E-7,1,0.999253354069792,40.0298881530762,1.98474062240186,25.3199990838766,0.000108122309700127,-3.66383520266381E-6,0.25,-1.94515067211821E-6,9.28395748279659E-6,-1.92806682951724E-6,99.9909286,99.9909286,23580.984375,23600.98046875,57.1784710672945,20.6347411421158,21.770052,0,0,0,40,4449,99.8321,23590.982421875,,,,,,,,,,,,,0,,,,0,,,,,,99.9909286,,,,
,27326149.02,99.9926987,18558.91015625,1.0070796703521E-5,6.42462483109654E-7,1,0.999253354069792,40.0298881530762,1.98494124016696,25.3199990838766,0.000116527997888006,4.57905274570655E-6,0.25,-1.36442094367765E-6,1.01318466045287E-5,-1.3412868659344E-6,99.9926987,99.9926987,18543.95703125,18573.86328125,57.1964485232368,20.6313618574221,22.149702,0,0,0,40,4449,99.83985,18558.91015625,,,,,,,,,,,,,0,,,,0,,,,,,99.9926987,,,,
,27326247,99.9911346,13659.1391601562,9.22370965189453E-6,8.1140891380098E-7,1,0.999253354069792,40.0298881530762,1.98490338899092,25.3199990838766,0.000107166731879751,1.67415516124316E-6,0.25,-1.47275966784187E-6,9.28026241445837E-6,-1.4526651971558E-6,99.9911346,99.9911346,13651.46484375,13666.8134765625,57.1331366131791,20.6380001618556,22.149702,0,0,0,40,4449,99.8491,13659.1391601562,,,,,,,,,,,,,0,,,,0,,,,,,99.9911346,,,,
,27326346.045,99.9914551,8711.12939453125,9.78004854536823E-6,5.30181574837699E-7,1,0.999253354069792,40.0298881530762,1.98483548303933,25.3199990838766,0.000111931787019736,1.14172270021152E-5,0.25,-7.08539232460324E-7,9.83732567239788E-6,-6.82260326624324E-7,99.9914551,99.9914551,8698.5634765625,8723.6953125,57.3043132588907,20.6388487634911,22.149702,0,0,0,40,4449,99.8566,8711.12939453125,,,,,,,,,,,,,0,,,,-0.00245,,,,,,99.9914551,,,,
,27326446.625,99.99233625,3683.41442871094,9.49092776889346E-6,3.88133613985343E-7,1,0.999253354069792,40.0298881530762,1.98488120211961,25.3199990838766,0.000107268581584999,1.87950068103557E-5,0.25,-5.04797605844524E-9,9.5443357355092E-6,2.44363120091287E-8,99.9922409,99.9924316,3670.94677734375,3695.88208007812,57.0792042453522,20.634200311681,22.149702,0,0,0,40,4449,99.8632,3683.41442871094,,,,,,,,,,,,,0,,,,0.00245,,,,,,99.99233625,,,,
,27326523.31,99.9947395,-0.357758671045303,9.51192694428726E-6,3.34408937421851E-7,1,0.999253354069792,40.0298881530762,1.98498947086705,25.3199990838766,0.000107594998840601,1.83603517915794E-5,0.25,-4.73534083458101E-8,9.56554991043548E-6,-1.79666385468272E-8,99.9944839,99.9949951,-0.365370541810989,-0.350146800279617,56.8751992018329,20.6353325516177,21.770052,0,0,0,40,4417,99.8705,-0.357758671045303,,,,,,,,,,,,,0,,,,0.00245,,,,,,99.9947395,,,,