File: data/monolayers/nanoparticles/Ac_CoFe_C/vsm/rawdata/DD226_2_HYST_50K.DAT
[Header]
; VSM Data File (default extension .dat)
; Copyright (c) 2003-2013, Quantum Design, Inc. All rights reserved.
TITLE,
FILEOPENTIME,27303984.55,11/13/2018,8:26 am
BYAPP,VSM,2.0,2.0
INFO,PPMS VSM Option Release 1.4.10 Build 1,APPNAME
INFO,Quantum Design Linear Motor Servo Controller,MOTOR_MODULE_NAME
INFO,3101-100 M1,MOTOR_HW_VERSION
INFO,MMC1014,MOTOR_SERIAL_NUMBER
INFO,SRV No X-over 01.03.11,MOTOR_SOFTWARE_VERSION
INFO,Quantum Design VSM Detection Module,VSM_MODULE_NAME
INFO,3101-150 F0,VSM_HW_VERSION
INFO,VSM707,VSM_SERIAL_NUMBER
INFO,VSM No X-over 01.02.05 May 20 2008 13:51:47,VSM_SOFTWARE_VERSION
INFO,704,PREAMP_SERIAL_NUMBER
INFO,822,COIL_SERIAL_NUMBER
INFO,0,MOMENT_UNITS
INFO,CoFe2O4 AH11,SAMPLE_MATERIAL
INFO,Quick Dry Monolayer Conc,SAMPLE_COMMENT
INFO,27.96,SAMPLE_MASS
INFO,,SAMPLE_VOLUME
INFO,,SAMPLE_MOLECULAR_WEIGHT
INFO,,SAMPLE_SIZE
INFO,,SAMPLE_SHAPE
DATATYPE,COMMENT,1
DATATYPE,TIME,2
STARTUPAXIS,X,2
STARTUPAXIS,Y1,5
[Data]
Comment,Time Stamp (sec),Temperature (K),Magnetic Field (Oe),Moment (emu),M. Std. Err. (emu),Transport Action,Averaging Time (sec),Frequency (Hz),Peak Amplitude (mm),Center Position (mm),Coil Signal' (mV),Coil Signal" (mV),Range (mV),M. Quad. Signal (emu),M. Raw' (emu),M. Raw" (emu),Min. Temperature (K),Max. Temperature (K),Min. Field (Oe),Max. Field (Oe),Mass (grams),Motor Lag (deg),Pressure (Torr),VSM Status (code),Motor Status (code),Measure Status (code),Measure Count,PPMS Status (code),System Temp. (K),System Field (Oe),Sample Position (deg),Bridge 1 Resistance (ohms),Bridge 1 Excitation (에),Bridge 2 Resistance (ohms),Bridge 2 Excitation (에),Bridge 3 Resistance (ohms),Bridge 3 Excitation (에),Bridge 4 Resistance (ohms),Bridge 4 Excitation (에),Signal 1 Vin (V),Signal 2 Vin (V),Digital Inputs (code),Drive 1 Iout (mA),Drive 1 Ipower (W),Drive 2 Iout (mA),Drive 2 Ipower (W),Pressure (),Map 20 (),Map 21 (),Map 22 (),Map 23 (),Map 24 (),Map 25 (),Map 26 (),Map 27 (),Map 28 (),Map 29 ()
,27303998.5,50.0118294,0.228356599807739,,,2,,,,25.5200008445978,,,,,,,50.0118294,50.0118294,0.228356599807739,0.228356599807739,,,18.353191,,,,-99999999,4369,50.0072,0.228356599807739,,,,,,,,,,,,,,,,,,,,,,,50.0118294,,,,
,27304150.405,50.003933,4594.08764648438,1.05142258924912E-5,3.71539682276708E-7,1,0.999253354069792,40.0298881530762,2.007947105517,25.5100000649691,0.000120245963432491,1.64530515383722E-5,0.25,-4.4558403371316E-7,1.05136353714302E-5,-3.67175828479457E-7,50.003933,50.003933,4591.7412109375,4596.43408203125,57.4504777919868,20.6431103297343,18.353191,0,0,0,40,4449,50.014,4594.08764648438,,,,,,,,,,,,,0,,,,0,,,,,,50.003933,,,,
,27304246.5,49.9995766,9397.5888671875,1.03817767472688E-5,5.03575710087311E-7,1,0.999253354069792,40.0298881530762,2.00819428183919,25.5100000649691,0.000118410522651218,1.82633408741077E-5,0.25,-2.62735549550594E-7,1.03823234830924E-5,-1.8546746702447E-7,49.9995766,49.9995766,9392.541015625,9402.63671875,57.271484861083,20.6438081888367,18.732843,0,0,0,40,4449,50.00835,9397.5888671875,,,,,,,,,,,,,0,,,,0,,,,,,49.9995766,,,,
,27304342.67,49.99970625,14203.0537109375,9.94327474585274E-6,6.80575538838152E-7,1,0.999253354069792,40.0298881530762,2.00809153075641,25.5100000649691,0.000114528271145542,1.1415643581688E-5,0.25,-7.86891879311912E-7,9.95030556496077E-6,-7.13124452763248E-7,49.9994125,50,14195.4091796875,14210.6982421875,57.1675282680253,20.6468991214641,18.353191,0,0,0,40,4449,50.00625,14203.0537109375,,,,,,,,,,,,,0,,,,-0.0049,,,,,,49.99970625,,,,
,27304437.37,49.9996414,18934.70703125,9.87090261801982E-6,6.12859293152156E-7,1,0.999253354069792,40.0298881530762,2.00826190914684,25.5100000649691,0.000113769198010773,1.11364087847537E-5,0.25,-7.98548791232235E-7,9.88055651826316E-6,-7.25726834449949E-7,49.9993019,49.9999809,18932.44921875,18936.96484375,57.2542890336599,20.6495942594409,18.353191,0,0,0,40,4449,50.0076,18934.70703125,,,,,,,,,,,,,0,,,,-0.0049,,,,,,49.9996414,,,,
,27304534.385,50.0002098,23785.1162109375,9.68342948055798E-6,5.87221427197783E-7,1,0.999253354069792,40.0298881530762,2.00818635423928,25.5100000649691,0.00011274886532253,4.73996872859026E-6,0.25,-1.32760068577022E-6,9.69948715695477E-6,-1.25701912460637E-6,50.0002098,50.0002098,23780.37109375,23789.861328125,57.291807202583,20.6496706273046,18.732843,0,0,0,40,4449,50.0086,23785.1162109375,,,,,,,,,,,,,0,,,,0,,,,,,50.0002098,,,,
,27304631.35,50.0007591,28632.5693359375,8.41969789898677E-6,7.90802527138178E-7,1,0.999253354069792,40.0298881530762,2.00819149035652,25.5100000649691,9.88407259779345E-5,-2.09953895141515E-7,0.25,-1.53515889385373E-6,8.4386453569891E-6,-1.47477967577199E-6,50.0007591,50.0007591,28628.044921875,28637.09375,57.2824276603522,20.6495772379017,17.973541,0,0,0,40,4449,50.0063,28632.5693359375,,,,,,,,,,,,,0,,,,0,,,,,,50.0007591,,,,
,27304729.075,50.0014076,33515.69140625,8.57238488330847E-6,6.55455402546759E-7,1,0.999253354069792,40.0298881530762,2.00808385419448,25.5100000649691,9.95122000121994E-5,6.12488748395464E-6,0.25,-1.00497186908622E-6,8.5898047992758E-6,-9.43681997774981E-7,50.0014076,50.0014076,33510.5703125,33520.8125,57.3668435404292,20.6507837112534,18.353191,0,0,0,40,4449,50.01,33515.69140625,,,,,,,,,,,,,0,,,,0,,,,,,50.0014076,,,,
,27304826.405,50.0006676,38379.984375,8.0500450987536E-6,8.76437770772381E-7,1,0.999253354069792,40.0298881530762,2.0079437057629,25.5100000649691,9.4198212270688E-5,1.68346428736279E-6,0.25,-1.30112242360527E-6,8.07099732616321E-6,-1.24478639385598E-6,50.0006676,50.0006676,38377.41796875,38382.55078125,57.4168677656599,20.6515638822317,18.353191,0,0,0,40,4449,50.0051,38379.984375,,,,,,,,,,,,,0,,,,-0.00245,,,,,,50.0006676,,,,
,27304924.08,50.0015182,43262.9140625,8.05186509883309E-6,1.01517675009493E-6,1,0.999253354069792,40.0298881530762,2.00808368051371,25.5100000649691,9.51964359320476E-5,-3.58397889490431E-6,0.25,-1.76402861974162E-6,8.07807828171752E-6,-1.70931978635795E-6,50.0015182,50.0015182,43255.42578125,43270.40234375,57.576319983583,20.6517542825937,18.353191,0,0,0,40,4449,50.0073,43262.9140625,,,,,,,,,,,,,0,,,,-0.0049,,,,,,50.0015182,,,,
,27305023.575,50.0004539,48235.720703125,6.59586022423311E-6,9.87001398425156E-7,1,0.999253354069792,40.0298881530762,2.00815149869151,25.5100000649691,7.8776410039105E-5,-7.23816797576448E-6,0.25,-1.82257835265221E-6,6.62153661318838E-6,-1.77934073645201E-6,50.0004539,50.0004539,48228.0234375,48243.41796875,57.5403650716984,20.6551905019283,18.732843,0,0,0,40,4449,50.00735,48235.720703125,,,,,,,,,,,,,0,,,,-0.00245,,,,,,50.0004539,,,,
,27305119.235,50.0010223,53015.7578125,3.66991029970547E-6,1.1207226997307E-6,1,0.999253354069792,40.0298881530762,2.00809312831892,25.5100000649691,4.69476882219659E-5,-2.1320228032433E-5,0.25,-2.5332601188693E-6,3.69561131335081E-6,-2.51300329990877E-6,50.0010223,50.0010223,53005.78515625,53025.73046875,57.3043132588907,20.6535591987177,18.353191,0,0,0,40,4449,50.003,53015.7578125,,,,,,,,,,,,,0,,,,-0.00245,,,,,,50.0010223,,,,
,27305218.86,50.0016098,57995.736328125,5.67513961788258E-6,8.22680173838297E-7,1,0.999253354069792,40.0298881530762,2.00775840898288,25.5100000649691,6.98590258041401E-5,-1.77143747880873E-5,0.25,-2.5762872400489E-6,5.70656050729036E-6,-2.5431402504423E-6,50.0016098,50.0016098,57983.25,58008.22265625,57.4270289364099,20.6577796548729,18.732843,0,0,0,40,4449,50.0007,57995.736328125,,,,,,,,,,,,,0,,,,0.00245,,,,,,50.0016098,,,,
,27305317.35,50.0014458,62919.294921875,3.69057853185658E-6,9.54440092034841E-7,1,0.999253354069792,40.0298881530762,2.00778665138725,25.5100000649691,4.74106955865765E-5,-2.25035106416838E-5,0.25,-2.63962114788489E-6,3.71825704154104E-6,-2.62127552161405E-6,50.0014458,50.0014458,62917.10546875,62921.484375,57.1847240954484,20.6553271690432,18.353191,0,0,0,40,4449,49.99775,62919.294921875,,,,,,,,,,,,,0,,,,0,,,,,,50.0014458,,,,
,27305415.32,50.001339,67814.29296875,4.92101049946059E-6,6.87322515343404E-7,1,0.999253354069792,40.0298881530762,2.0078339710937,25.5100000649691,6.55556414713882E-5,-4.29801469172133E-5,0.25,-4.65793062994511E-6,4.96628765848195E-6,-4.63786215325403E-6,50.001339,50.001339,67809.2265625,67819.359375,57.4262473078907,20.6547526910422,18.353191,0,0,0,40,4449,50.0001,67814.29296875,,,,,,,,,,,,,0,,,,-0.0049,,,,,,50.001339,,,,
,27305513.46,50.0019035,72719.23046875,3.05714180934167E-6,1.01266762486569E-6,1,0.999253354069792,40.0298881530762,2.00773799066895,25.5100000649691,4.31163893141093E-5,-4.00129495845505E-5,0.25,-4.06186345211107E-6,3.09336465024567E-6,-4.05378685302158E-6,50.0019035,50.0019035,72711.6328125,72726.828125,57.2808644033138,20.6554143848049,18.732843,0,0,0,40,4449,50.00365,72719.23046875,,,,,,,,,,,,,0,,,,-0.00245,,,,,,50.0019035,,,,
,27305607.245,50.0018234,77409.91015625,2.26790641338216E-6,9.63430172158633E-7,1,0.999253354069792,40.0298881530762,2.0077137138553,25.5100000649691,3.2366162362477E-5,-3.18003669421762E-5,0.25,-3.19841836787926E-6,2.29611747199713E-6,-3.1937708941824E-6,50.0018234,50.0018234,77404.953125,77414.8671875,57.4989387601791,20.6535668761384,18.353191,0,0,0,40,4449,49.99465,77409.91015625,,,,,,,,,,,,,0,,,,-0.0049,,,,,,50.0018234,,,,
,27305706.985,50.0028648,82393.4453125,1.09811878366069E-6,1.07790246658403E-6,1,0.999253354069792,40.0298881530762,2.00790265098439,25.5100000649691,2.19733431865938E-5,-5.05527526325164E-5,0.25,-4.63352811363463E-6,1.13172898316062E-6,-4.64209409326721E-6,50.0028648,50.0028648,82383.4375,82403.453125,57.2089545795445,20.6520435960523,19.112494,0,0,0,40,4449,49.998,82393.4453125,,,,,,,,,,,,,0,,,,0,,,,,,50.0028648,,,,
,27305805.335,50.0028648,87311.19140625,-2.07379908828711E-6,1.24542472584794E-6,1,0.999253354069792,40.0298881530762,2.00790412387529,25.5100000649691,-1.82145373359E-5,-3.44896486310718E-5,0.25,-2.65497484742988E-6,-2.06429492632094E-6,-2.67756985875289E-6,50.0028648,50.0028648,87305.9453125,87316.4375,57.3551191126407,20.6501392521985,18.353191,0,0,0,40,4449,49.994,87311.19140625,,,,,,,,,,,,,0,,,,0,,,,,,50.0028648,,,,
,27305919.22,50.0000458,88065.58203125,3.86692317003958E-7,1.1877699609853E-6,1,0.999253354069792,40.0298881530762,2.00805180961907,25.5100000649691,1.30066655510778E-5,-4.72289948941673E-5,0.25,-4.21309113428276E-6,4.14769707548102E-7,-4.2257007866164E-6,50.0000458,50.0000458,88063.3828125,88067.78125,57.4199942797368,20.6490327675533,18.353191,0,0,0,40,4449,49.9938,88065.58203125,,,,,,,,,,,,,0,,,,0,,,,,,50.0000458,,,,
,27306013.51,50.0005913,83350.22265625,2.30821546353731E-6,1.05049265255762E-6,1,0.999253354069792,40.0298881530762,2.00795673025769,25.5100000649691,4.06549162497231E-5,-7.538875320427E-5,0.25,-7.02964512253161E-6,2.36131707201635E-6,-7.03877719176671E-6,50.0005913,50.0005913,83344.859375,83355.5859375,57.1362631272561,20.6479104819016,18.353191,0,0,0,40,4449,49.9938,83350.22265625,,,,,,,,,,,,,0,,,,0.0049,,,,,,50.0005913,,,,
,27306110.195,50.0002632,78515.93359375,3.59072198321777E-6,1.11012596242263E-6,1,0.999253354069792,40.0298881530762,2.00808236164523,25.5100000649691,4.97534099820425E-5,-4.19883199193878E-5,0.25,-4.32912217688427E-6,3.63062230401079E-6,-4.31967448496683E-6,50.0002632,50.0002632,78505.96875,78525.8984375,57.66073586366,20.6498219760768,18.732843,0,0,0,40,4449,49.9929,78515.93359375,,,,,,,,,,,,,0,,,,0,,,,,,50.0002632,,,,
,27306207.135,50.0003662,73669.71875,3.5591078382936E-6,1.01222877721526E-6,1,0.999253354069792,40.0298881530762,2.00826134243358,25.5100000649691,4.81695533526908E-5,-3.52267318254396E-5,0.25,-3.73070427919438E-6,3.59470307063693E-6,-3.71849187262179E-6,50.0003662,50.0003662,73662.0234375,73677.4140625,57.3043132588907,20.6533894172978,19.112494,0,0,0,40,4449,49.995,73669.71875,,,,,,,,,,,,,0,,,,0.00245,,,,,,50.0003662,,,,
,27306306.085,50.0008125,68724.15234375,4.78566639967066E-6,1.02758008906911E-6,1,0.999253354069792,40.0298881530762,2.00807501226223,25.5100000649691,6.24212228370775E-5,-3.43382510733692E-5,0.25,-3.87414581876263E-6,4.82538441285524E-6,-3.85300576868627E-6,50.0008125,50.0008125,68719.1484375,68729.15625,57.3988903097176,20.6519274710613,18.353191,0,0,0,40,4449,49.9935,68724.15234375,,,,,,,,,,,,,0,,,,-0.0098,,,,,,50.0008125,,,,
,27306403.775,49.9996567,63843.98828125,5.33870055330726E-6,5.87277837846583E-7,1,0.999253354069792,40.0298881530762,2.00830408604547,25.5100000649691,7.04975572389379E-5,-4.31176018449911E-5,0.25,-4.74524186197102E-6,5.38520720624896E-6,-4.72140255872397E-6,49.9996567,49.9996567,63836.5390625,63851.4375,57.3551191126407,20.6518612048428,18.732843,0,0,0,40,4449,49.997,63843.98828125,,,,,,,,,,,,,0,,,,0,,,,,,49.9996567,,,,
,27306501.625,49.9997597,58950.78125,5.70850995731582E-6,7.90482696150744E-7,1,0.999253354069792,40.0298881530762,2.00829301782588,25.5100000649691,7.35118400621993E-5,-3.57542485393688E-5,0.25,-4.1663085316355E-6,5.75119128599784E-6,-4.13699847609877E-6,49.9997597,49.9997597,58943.19921875,58958.36328125,57.3090030300061,20.6532123389861,18.732843,0,0,0,40,4449,49.98945,58950.78125,,,,,,,,,,,,,0,,,,-0.00245,,,,,,49.9997597,,,,
,27306597.185,50.0008049,54175.83203125,6.40831291848614E-6,7.34425784289837E-7,1,0.999253354069792,40.0298881530762,2.00827231658704,25.5100000649691,7.7683308905717E-5,-1.32816260463407E-5,0.25,-2.31894333558438E-6,6.43872803114602E-6,-2.27926454101316E-6,50.0008049,50.0008049,54170.9296875,54180.734375,57.4520410490253,20.6507871605781,18.353191,0,0,0,40,4449,49.9944,54175.83203125,,,,,,,,,,,,,0,,,,0.0049,,,,,,50.0008049,,,,
,27306693.58,50.0006676,49358.08203125,6.8009939657203E-6,5.52100654421406E-7,1,0.999253354069792,40.0298881530762,2.00819862712601,25.5100000649691,8.39073683724131E-5,-2.23389930190609E-5,0.25,-3.18642409889189E-6,6.83703370002554E-6,-3.14464708769126E-6,50.0006676,50.0006676,49347.84375,49368.3203125,57.5028469027753,20.6524609610666,18.732843,0,0,0,40,4449,49.99085,49358.08203125,,,,,,,,,,,,,0,,,,-0.00245,,,,,,50.0006676,,,,
,27306789.99,50.00029375,44537.576171875,8.20580679888549E-6,9.10684248869323E-7,1,0.999253354069792,40.0298881530762,2.00813447690868,25.5100000649691,9.78953908411048E-5,-8.49332347197707E-6,0.25,-2.22312087711709E-6,8.23603815221171E-6,-2.16836670037192E-6,50.0001793,50.0004082,44529.9921875,44545.16015625,57.2222422643714,20.654962839776,18.353191,0,0,0,40,4449,49.99595,44537.576171875,,,,,,,,,,,,,0,,,,0.00245,,,,,,50.00029375,,,,
,27306885.42,50.0003662,39767.28515625,8.61761587093266E-6,7.32209572483676E-7,1,0.999253354069792,40.0298881530762,2.00812332594723,25.5100000649691,0.000103195660045122,-1.12010294532857E-5,0.25,-2.53611109944954E-6,8.64886808077196E-6,-2.47776913672396E-6,50.0003662,50.0003662,39757.3515625,39777.21875,57.4528226775445,20.6529327306268,19.112494,0,0,0,40,4449,49.99365,39767.28515625,,,,,,,,,,,,,0,,,,-0.00245,,,,,,50.0003662,,,,
,27306983.395,50.0012169,34872.49609375,9.54582749737362E-6,6.78431769458201E-7,1,0.999253354069792,40.0298881530762,2.00828218268926,25.5100000649691,0.00011357958113515,-8.44749358766209E-6,0.25,-2.46182845496791E-6,9.5756258317415E-6,-2.39546537197102E-6,50.0012169,50.0012169,34864.91796875,34880.07421875,57.515352959083,20.6517750749961,18.732843,0,0,0,40,4449,49.99105,34872.49609375,,,,,,,,,,,,,0,,,,0,,,,,,50.0012169,,,,
,27307083.3,49.9982643,29877.69140625,9.98347753557104E-6,6.59728509845133E-7,1,0.999253354069792,40.0298881530762,2.00834489717299,25.5100000649691,0.000117265705700519,-5.35148135430422E-7,0.25,-1.84533507956133E-6,1.00067547737123E-5,-1.77399668846493E-6,49.9982643,49.9982643,29872.845703125,29882.537109375,57.3254172289099,20.6509099173278,18.732843,0,0,0,40,4449,49.99395,29877.69140625,,,,,,,,,,,,,0,,,,0,,,,,,49.9982643,,,,
,27307178.615,49.99939725,25112.8955078125,9.07875125235804E-6,5.81949424694972E-7,1,0.999253354069792,40.0298881530762,2.00836042895991,25.5100000649691,0.000106292420746532,1.29116636084833E-6,0.25,-1.5220907322995E-6,9.09647177784346E-6,-1.45628903978702E-6,49.9990997,49.9996948,25105.25,25120.541015625,57.4528226775445,20.6509573469156,18.353191,0,0,0,40,4449,49.9954,25112.8955078125,,,,,,,,,,,,,0,,,,0.00245,,,,,,49.99939725,,,,
,27307276.375,50.0004272,20227.7021484375,1.05343669471014E-5,4.83411999527219E-7,1,0.999253354069792,40.0298881530762,2.0082445066222,25.5100000649691,0.000122070034588697,8.29691348313444E-6,0.25,-1.1680315769402E-6,1.05477228158251E-5,-1.09058679341819E-6,50.0004272,50.0004272,20222.43359375,20232.970703125,57.5599057846792,20.6521729468439,18.732843,0,0,0,40,4449,49.9972,20227.7021484375,,,,,,,,,,,,,0,,,,0.0049,,,,,,50.0004272,,,,
,27307371.07,49.99922755,15495.7016601562,1.14416513196165E-5,4.72431269835123E-7,1,0.999253354069792,40.0298881530762,2.00826196621453,25.5100000649691,0.000131940171328918,1.23939809701419E-5,0.25,-9.70906827142084E-7,1.14509770081326E-5,-8.86143673748548E-7,49.9990349,49.9994202,15485.517578125,15505.8857421875,57.4997203886984,20.6533209202648,18.732843,0,0,0,40,4449,49.9907,15495.7016601562,,,,,,,,,,,,,0,,,,-0.00245,,,,,,49.99922755,,,,
,27307466.32,50.0003014,10735.6259765625,1.14240412028722E-5,4.84656032705261E-7,1,0.999253354069792,40.0298881530762,2.00817434206577,25.5100000649691,0.000131097116678975,1.57057526639582E-5,0.25,-6.75913072146598E-7,1.14282634877541E-5,-5.90901903969682E-7,50.0003014,50.0003014,10728.26953125,10742.982421875,57.3684067974676,20.6536217344786,19.112494,0,0,0,40,4449,49.9926,10735.6259765625,,,,,,,,,,,,,0,,,,-0.0049,,,,,,50.0003014,,,,
,27307559.01,50.0002022,6102.45043945313,1.11184248136419E-5,3.85344098564137E-7,1,0.999253354069792,40.0298881530762,2.00833079273623,25.5100000649691,0.000126686557124463,2.01811282444379E-5,0.25,-2.26457415978792E-7,1.11167042455355E-5,-1.43648140154371E-7,50.0002022,50.0002022,6095.1337890625,6109.76708984375,57.5395834431792,20.6537765372256,19.112494,0,0,0,40,4449,49.9931,6102.45043945313,,,,,,,,,,,,,0,,,,0,,,,,,50.0002022,,,,
,27307653.435,50.0003929,1381.48522949219,1.08041628783689E-5,3.34959261312478E-7,1,0.999253354069792,40.0298881530762,2.00828896737448,25.5100000649691,0.000122838880982253,2.09300693893431E-5,0.25,-1.03408524158265E-7,1.07993582205949E-5,-2.29791389043142E-8,50.0003929,50.0003929,1376.48522949219,1386.48522949219,57.4223391652945,20.655576598062,18.353191,0,0,0,40,4449,49.9903,1381.48522949219,,,,,,,,,,,,,0,,,,-0.00245,,,,,,50.0003929,,,,
,27307747.385,50.0003414,-3308.86218261719,1.07701585571408E-5,3.94420387365926E-7,1,0.999253354069792,40.0298881530762,2.00821522213964,25.5100000649691,0.000121970805749458,2.35657935284468E-5,0.25,1.34841877932848E-7,1.07644455368229E-5,2.14922866100907E-7,50.0003166,50.0003662,-3316.265625,-3301.45874023438,57.4231207938138,20.6576219647247,18.353191,0,0,0,40,4449,49.9896,-3308.86218261719,,,,,,,,,,,,,0,,,,-0.0049,,,,,,50.0003414,,,,
,27307842.18,49.9987411,-8048.20776367187,9.78117422018288E-6,3.58696244382809E-7,1,0.999253354069792,40.0298881530762,2.00826183255526,25.5100000649691,0.000110897242966322,2.08586796754009E-5,0.25,7.41656382004098E-8,9.7785737171569E-6,1.46929651934831E-7,49.9987411,49.9987411,-8055.673828125,-8040.74169921875,57.4559491916215,20.6545835819643,18.732843,0,0,0,40,4449,49.9932,-8048.20776367187,,,,,,,,,,,,,0,,,,0,,,,,,49.9987411,,,,
,27307936.25,50.00118065,-12749.0771484375,6.88859173918584E-6,4.55129113581274E-7,1,0.999253354069792,40.0298881530762,2.0082352158847,25.5100000649691,7.71762244142411E-5,1.99289913000202E-5,0.25,5.13326255933401E-7,6.88502629133334E-6,5.6454636032142E-7,50.0010719,50.0012894,-12754.080078125,-12744.07421875,57.5466180998522,20.6527907951322,18.353191,0,0,0,40,4449,49.99105,-12749.0771484375,,,,,,,,,,,,,0,,,,0,,,,,,50.00118065,,,,
,27308033.16,50.0009232,-17593.888671875,2.59848746306046E-6,4.97947277371973E-7,1,0.999253354069792,40.0298881530762,2.00827070910135,25.5100000649691,2.7641516817505E-5,1.57250895619709E-5,0.25,9.1604482445649E-7,2.59247309209499E-6,9.35587504925222E-7,50.0009232,50.0009232,-17601.298828125,-17586.478515625,57.5567792706022,20.6540501426757,19.112494,0,0,0,40,4449,49.98855,-17593.888671875,,,,,,,,,,,,,0,,,,0,,,,,,50.0009232,,,,
,27308127.22,50.0020714,-22296.66015625,-3.03095335254034E-6,4.65907352800598E-7,1,0.999253354069792,40.0298881530762,2.00819824888927,25.5100000649691,-3.66754004411396E-5,6.21581285025759E-6,0.25,1.09322743008417E-6,-3.04072770000395E-6,1.07144519423603E-6,50.0020714,50.0020714,-22304.041015625,-22289.279296875,57.5716302124676,20.6558072011491,18.353191,0,0,0,40,4449,49.991,-22296.66015625,,,,,,,,,,,,,0,,,,0,,,,,,50.0020714,,,,
,27308223.875,50.0015106,-27126.5185546875,-6.74021586337339E-6,5.39348048555137E-7,1,0.999253354069792,40.0298881530762,2.00822068362334,25.5100000649691,-7.80153519059289E-5,-5.96020264117461E-6,0.25,6.8982321759634E-7,-6.75085259077055E-6,6.40840633551155E-7,50.0015106,50.0015106,-27136.45703125,-27116.580078125,57.7686005993138,20.6554514054154,18.353191,0,0,0,40,4449,49.98895,-27126.5185546875,,,,,,,,,,,,,0,,,,0,,,,,,50.0015106,,,,
,27308316.9,50.0012436,-31773.6875,-7.99088325376623E-6,5.88849963019905E-7,1,0.999253354069792,40.0298881530762,2.00821441620219,25.5100000649691,-9.3076317169678E-5,-3.94569263434469E-6,0.25,1.09209605200184E-6,-8.00748592240161E-6,1.03488136297893E-6,50.0012436,50.0012436,-31783.521484375,-31763.853515625,57.6161830380638,20.6584575591544,19.112494,0,0,0,40,4449,49.989,-31773.6875,,,,,,,,,,,,,0,,,,0,,,,,,50.0012436,,,,
,27308408.485,50.0009766,-36350.955078125,-8.48949400489229E-6,6.79419732824985E-7,1,0.999253354069792,40.0298881530762,2.008169210061,25.5100000649691,-9.87504823770468E-5,-5.05235762703778E-6,0.25,1.08418738903987E-6,-8.50859095399795E-6,1.02401947345166E-6,50.0009766,50.0009766,-36355.828125,-36346.08203125,57.5427099572561,20.6580060519836,18.353191,0,0,0,40,4449,49.98415,-36350.955078125,,,,,,,,,,,,,0,,,,0,,,,,,50.0009766,,,,
,27308503.01,50.0017948,-41075.607421875,-8.45217316593556E-6,5.89612501685362E-7,1,0.999253354069792,40.0298881530762,2.00812101647141,25.5100000649691,-0.000101718649056242,1.37538546010453E-5,0.25,2.73056574165746E-6,-8.4850972770457E-6,2.67403867153513E-6,50.0017776,50.001812,-41083.046875,-41068.16796875,57.5935158110061,20.6606255478092,19.112494,0,0,0,40,4449,49.9905,-41075.607421875,,,,,,,,,,,,,0,,,,0,,,,,,50.0017948,,,,
,27308596.08,50.0014839,-45726.40234375,-7.1006396699431E-6,7.61988080943919E-7,1,0.999253354069792,40.0298881530762,2.00827636647502,25.5100000649691,-8.67717118199024E-5,1.87492803486128E-5,0.25,2.9255128872323E-6,-7.1343157718053E-6,2.8801718066247E-6,50.0014763,50.0014915,-45736.34375,-45716.4609375,57.4614205912561,20.6552014539838,18.732843,0,0,0,40,4449,49.9847,-45726.40234375,,,,,,,,,,,,,0,,,,-0.00245,,,,,,50.0014839,,,,
,27308692.05,50.0012436,-50525.998046875,-8.77648696278689E-6,9.02092636693175E-7,1,0.999253354069792,40.0298881530762,2.00835671055246,25.5100000649691,-0.000103602459037691,2.74794609239155E-6,0.25,1.81979169787412E-6,-8.80723372119213E-6,1.76158989323465E-6,50.0012436,50.0012436,-50538.4921875,-50513.50390625,57.4199942797368,20.6546099742819,19.112494,0,0,0,40,4449,49.98415,-50525.998046875,,,,,,,,,,,,,0,,,,-0.00245,,,,,,50.0012436,,,,
,27308787.755,50.0010605,-55307.83984375,-7.56176278799462E-6,7.57348695797229E-7,1,0.999253354069792,40.0298881530762,2.00811330515041,25.5100000649691,-8.96022958665094E-5,4.20864197835089E-6,0.25,1.72901595399842E-6,-7.59095786582872E-6,1.68019158591056E-6,50.0010605,50.0010605,-55320.171875,-55295.5078125,57.5450548428138,20.6544017764075,18.732843,0,0,0,40,4449,49.9825,-55307.83984375,,,,,,,,,,,,,0,,,,-0.00245,,,,,,50.0010605,,,,
,27308882.635,50.0004539,-60050.40234375,-6.95577160956462E-6,8.10701727691277E-7,1,0.999253354069792,40.0298881530762,2.00834888164392,25.5100000649691,-8.23171415851068E-5,3.15010726186168E-6,0.25,1.52637797037926E-6,-6.98354929211553E-6,1.48223316527488E-6,50.0004539,50.0004539,-60058.140625,-60042.6640625,57.6802765766407,20.6568712573741,18.732843,0,0,0,40,4449,49.9828,-60050.40234375,,,,,,,,,,,,,0,,,,0,,,,,,50.0004539,,,,
,27308977.495,50.0022049,-64790.240234375,-6.65316302049251E-6,7.61705693603309E-7,1,0.999253354069792,40.0298881530762,2.00843154592584,25.5100000649691,-8.30558151881932E-5,2.69716000823607E-5,0.25,3.56305247687512E-6,-6.69528296253083E-6,3.52736370490844E-6,50.0022049,50.0022049,-64795.26953125,-64785.2109375,57.3473028274484,20.6574868389884,19.112494,0,0,0,40,4449,49.98175,-64790.240234375,,,,,,,,,,,,,0,,,,0,,,,,,50.0022049,,,,
,27309072.995,50.0017967,-69562.46484375,-6.43159495921685E-6,8.60960907753502E-7,1,0.999253354069792,40.0298881530762,2.00839000416421,25.5100000649691,-7.93054487633756E-5,2.05346486550361E-5,0.25,2.95708233642517E-6,-6.47000331570288E-6,2.92244838442914E-6,50.0017967,50.0017967,-69567.390625,-69557.5390625,57.4731450190445,20.657399378795,19.112494,0,0,0,40,4449,49.98125,-69562.46484375,,,,,,,,,,,,,0,,,,-0.0049,,,,,,50.0017967,,,,
,27309168.655,50.0025215,-74341.6953125,-4.53683228249015E-6,6.93216666896664E-7,1,0.999253354069792,40.0298881530762,2.0082153469322,25.5100000649691,-5.73534380189415E-5,2.23358468246957E-5,0.25,2.77445959502583E-6,-4.56914650188369E-6,2.75297017894351E-6,50.0025215,50.0025215,-74354.2421875,-74329.1484375,57.637287008083,20.6592799286106,19.112494,0,0,0,40,4449,49.9801,-74341.6953125,,,,,,,,,,,,,0,,,,-0.0049,,,,,,50.0025215,,,,
,27309266.29,50.001339,-79223.66796875,-4.45027698705036E-6,9.28203997419532E-7,1,0.999253354069792,40.0298881530762,2.00784352501871,25.5100000649691,-5.76709050047251E-5,2.97997166384795E-5,0.25,3.41359439365198E-6,-4.48704122229398E-6,3.39571227292166E-6,50.001339,50.001339,-79231.1015625,-79216.234375,57.4074882234292,20.6641823047848,19.112494,0,0,0,40,4449,49.97875,-79223.66796875,,,,,,,,,,,,,0,,,,-0.0049,,,,,,50.001339,,,,
,27309362.45,50.0019608,-84028.5859375,-4.48240869751026E-6,9.83772292390659E-7,1,0.999253354069792,40.0298881530762,2.00785978688735,25.5100000649691,-5.92249450714111E-5,3.63337994668994E-5,0.25,3.99181664861248E-6,-4.52343085607307E-6,3.97674283720001E-6,50.0019608,50.0019608,-84033.6328125,-84023.5390625,57.7498415148523,20.6633401535798,19.112494,0,0,0,40,4449,49.97795,-84028.5859375,,,,,,,,,,,,,0,,,,-0.00245,,,,,,50.0019608,,,,
,27309453.32,50.0003815,-88568.140625,-2.15214276253684E-6,1.17249700358721E-6,1,0.999253354069792,40.0298881530762,2.00754798657937,25.5100000649691,-2.9808326489884E-5,2.51208660319329E-5,0.25,2.58997560632059E-6,-2.17625467837391E-6,2.58565606831788E-6,50.0003815,50.0003815,-88575.5859375,-88560.6953125,57.7459333722561,20.6680416939356,19.112494,0,0,0,40,4449,49.9764,-88568.140625,,,,,,,,,,,,,0,,,,-0.0049,,,,,,50.0003815,,,,
,27309563.165,49.9985504,-86914.1796875,-2.94047721563541E-6,1.02474732355874E-6,1,0.999253354069792,40.0298881530762,2.00795543754414,25.5100000649691,-3.73348543262911E-5,1.5348261684612E-5,0.25,1.87344132749976E-6,-2.96278554502117E-6,1.86135689759381E-6,49.9985504,49.9985504,-86919.0625,-86909.296875,57.8717755638523,20.6639740309775,19.112494,0,0,0,40,4449,49.9781,-86914.1796875,,,,,,,,,,,,,0,,,,0.00245,,,,,,49.9985504,,,,
,27309654.045,49.9997482,-82371.953125,-3.62118302098966E-6,9.29742402145406E-7,1,0.999253354069792,40.0298881530762,2.00767879549459,25.5100000649691,-4.85884725011135E-5,3.3524006352014E-5,0.25,3.59148399287484E-6,-3.65658853173185E-6,3.58023600241183E-6,49.9997482,49.9997482,-82377.109375,-82366.796875,57.4309370790061,20.6691277952904,19.112494,0,0,0,40,4449,49.9858,-82371.953125,,,,,,,,,,,,,0,,,,0.00245,,,,,,49.9997482,,,,
,27309746.57,50.000576,-77746.921875,-5.46176003912828E-6,7.89347788421426E-7,1,0.999253354069792,40.0298881530762,2.00782496160897,25.5100000649691,-6.70865730645263E-5,1.59962259941645E-5,0.25,2.38354826650545E-6,-5.49487941707508E-6,2.35542024000257E-6,50.000576,50.000576,-77754.28125,-77739.5625,57.66073586366,20.6675106405232,19.112494,0,0,0,40,4449,49.98095,-77746.921875,,,,,,,,,,,,,0,,,,-0.00245,,,,,,50.000576,,,,
,27309836.8,50.0007248,-73236.98046875,-6.70240941305981E-6,6.94972800775812E-7,1,0.999253354069792,40.0298881530762,2.00764342351179,25.5100000649691,-7.98447307061804E-5,5.89808610600007E-6,0.25,1.720321319144E-6,-6.73415816435412E-6,1.68103778510271E-6,50.0007248,50.0007248,-73247.1171875,-73226.84375,57.7232661451984,20.6641381331983,18.732843,0,0,0,40,4449,49.98105,-73236.98046875,,,,,,,,,,,,,0,,,,-0.00245,,,,,,50.0007248,,,,
,27309932.77,49.9992943,-68442.4609375,-5.74299112038399E-6,7.61979005971125E-7,1,0.999253354069792,40.0298881530762,2.0080482871907,25.5100000649691,-7.25720697248284E-5,2.82016181078036E-5,0.25,3.50723976487515E-6,-5.78291927505555E-6,3.47853156692633E-6,49.9992943,49.9992943,-68449.7265625,-68435.1953125,57.8936611623907,20.6587180324872,19.492144,0,0,0,40,4449,49.9832,-68442.4609375,,,,,,,,,,,,,0,,,,0,,,,,,49.9992943,,,,
,27310027.205,49.9993744,-63722.78515625,-7.74411063809774E-6,8.72703773652527E-7,1,0.999253354069792,40.0298881530762,2.00800054012258,25.5100000649691,-9.05388797624205E-5,-2.65036459839765E-6,0.25,1.15800608861054E-6,-7.77246942946227E-6,1.10822368579099E-6,49.9993744,49.9993744,-63733.03125,-63712.5390625,57.5380201861407,20.6594625596281,19.112494,0,0,0,40,4449,49.98145,-63722.78515625,,,,,,,,,,,,,0,,,,0,,,,,,49.9993744,,,,
,27310124.29,49.9994926,-58870.349609375,-7.85203950090643E-6,9.64027107553882E-7,1,0.999253354069792,40.0298881530762,2.00823826706327,25.5100000649691,-9.14022258932749E-5,-4.86073313713296E-6,0.25,9.83934048084981E-7,-7.87790524403564E-6,9.32045581093617E-7,49.9994926,49.9994926,-58880.46875,-58860.23046875,57.4692368764484,20.6574376880506,18.732843,0,0,0,40,4449,49.9788,-58870.349609375,,,,,,,,,,,,,0,,,,-0.00245,,,,,,49.9994926,,,,
,27310220.15,49.9990883,-54080.1484375,-7.9857115215877E-6,8.69626145130112E-7,1,0.999253354069792,40.0298881530762,2.00857250371463,25.5100000649691,-9.16073479996488E-5,-1.24326220817587E-5,0.25,3.43449190576924E-7,-8.00575538850228E-6,2.88341326329882E-7,49.9990883,49.9990883,-54088.12890625,-54072.16796875,57.8467634512369,20.6546953031607,19.112494,0,0,0,40,4449,49.98335,-54080.1484375,,,,,,,,,,,,,0,,,,0,,,,,,49.9990883,,,,
,27310316.13,49.9997406,-49283.689453125,-8.59298955057199E-6,6.43601060257356E-7,1,0.999253354069792,40.0298881530762,2.00821972191209,25.5100000649691,-0.000101266879854272,1.81600434449826E-6,0.25,1.70510159333265E-6,-8.62206937461919E-6,1.64768628011348E-6,49.9997406,49.9997406,-49286.09765625,-49281.28125,57.820188081583,20.6563813472918,19.112494,0,0,0,40,4449,49.9834,-49283.689453125,,,,,,,,,,,,,0,,,,0,,,,,,49.9997406,,,,
,27310413.385,50.0001907,-44420.93359375,-8.33222905588917E-6,8.2390931744619E-7,1,0.999253354069792,40.0298881530762,2.00816742980261,25.5100000649691,-9.55421087022986E-5,-1.28401902659716E-5,0.25,3.70505895224224E-7,-8.34936472244621E-6,3.11583490491871E-7,50.0001907,50.0001907,-44428.32421875,-44413.54296875,57.7920494548907,20.6595391545328,19.112494,0,0,0,40,4449,49.9784,-44420.93359375,,,,,,,,,,,,,0,,,,0,,,,,,50.0001907,,,,
,27310506.79,49.9989624,-39753.3125,-8.77984556292176E-6,7.2444283987592E-7,1,0.999253354069792,40.0298881530762,2.00814214833632,25.5100000649691,-0.000102745773543446,-1.88336061129909E-6,0.25,1.41479504137185E-6,-8.80322610638648E-6,1.35358448326679E-6,49.9989624,49.9989624,-39765.3203125,-39741.3046875,57.3480844559676,20.6604218212138,19.112494,0,0,0,40,4449,49.98155,-39753.3125,,,,,,,,,,,,,0,,,,-0.00245,,,,,,49.9989624,,,,
,27310603.385,49.999588,-34926.13671875,-9.7328965466566E-6,9.48883447784957E-7,1,0.999253354069792,40.0298881530762,2.00799527758991,25.5100000649691,-0.000112631429152143,-8.9282566551716E-6,0.25,9.67237607373782E-7,-9.75207491752344E-6,8.97657542363817E-7,49.999588,49.999588,-34928.65625,-34923.6171875,57.6146197810253,20.6608478752708,19.112494,0,0,0,40,4449,49.9866,-34926.13671875,,,,,,,,,,,,,0,,,,0,,,,,,49.999588,,,,
,27310696.955,49.99820325,-30251.4638671875,-1.0032796963165E-5,6.03708860843335E-7,1,0.999253354069792,40.0298881530762,2.0081550019815,25.5100000649691,-0.000115376401302697,-1.31198492408886E-5,0.25,6.52871052258924E-7,-1.00475628907618E-5,5.80049582903463E-7,49.9980659,49.9983406,-30256.556640625,-30246.37109375,57.3637170263522,20.6579335259147,18.732843,0,0,0,40,4449,49.9837,-30251.4638671875,,,,,,,,,,,,,0,,,,-0.0049,,,,,,49.99820325,,,,
,27310791.165,49.9993401,-25541.734375,-9.6537462608235E-6,5.48939863798918E-7,1,0.999253354069792,40.0298881530762,2.00811190993115,25.5100000649691,-0.000109995797807539,-1.81215991569736E-5,0.25,1.44541854280976E-7,-9.66193254673306E-6,7.3548725940814E-8,49.9993401,49.9993401,-25543.826171875,-25539.642578125,57.5692853269099,20.6547493795268,19.492144,0,0,0,40,4449,49.9857,-25541.734375,,,,,,,,,,,,,0,,,,0.0049,,,,,,49.9993401,,,,
,27310885.3,49.9991531,-20837.056640625,-1.01613852060659E-5,6.43929113759606E-7,1,0.999253354069792,40.0298881530762,2.00826708110001,25.5100000649691,-0.000114999577690412,-2.32816552439236E-5,0.25,-2.18120265642292E-7,-1.01646187501063E-5,-2.93398582742814E-7,49.9991531,49.9991531,-20841.8984375,-20832.21484375,57.5028469027753,20.653225933813,19.112494,0,0,0,40,4449,49.98295,-20837.056640625,,,,,,,,,,,,,0,,,,-0.00245,,,,,,49.9991531,,,,
,27310979.88,49.9984283,-16109.453125,-1.05819264193234E-5,4.9843562868219E-7,1,0.999253354069792,40.0298881530762,2.00824496151385,25.5100000649691,-0.000119611357610437,-2.48783028082215E-5,0.25,-2.83193725134777E-7,-1.05821290915613E-5,-3.61790977604396E-7,49.9984283,49.9984283,-16119.3759765625,-16099.5302734375,57.6310339799292,20.6518409379185,19.112494,0,0,0,40,4449,49.9876,-16109.453125,,,,,,,,,,,,,0,,,,-0.00245,,,,,,49.9984283,,,,
,27311073.98,49.9990654,-11406.90625,-1.00878059219705E-5,4.11324253412277E-7,1,0.999253354069792,40.0298881530762,2.00839558423241,25.5100000649691,-0.000115507645765649,-1.53776116476784E-5,0.25,4.64135587332329E-7,-1.00908979680982E-5,3.89106419525061E-7,49.9990654,49.9990654,-11412.0390625,-11401.7734375,57.4754899046022,20.6515933396564,19.112494,0,0,0,40,4449,49.99025,-11406.90625,,,,,,,,,,,,,0,,,,-0.0049,,,,,,49.9990654,,,,
,27311167.535,49.9993019,-6731.38671875,-1.04843837502972E-5,3.78441976751304E-7,1,0.999253354069792,40.0298881530762,2.00834478926802,25.5100000649691,-0.000118620460101417,-2.37234280863934E-5,0.25,-1.99785564443579E-7,-1.04799826718324E-5,-2.77750159105395E-7,49.9993019,49.9993019,-6738.85498046875,-6723.91845703125,57.6544828355061,20.6503713657451,19.112494,0,0,0,40,4449,49.98505,-6731.38671875,,,,,,,,,,,,,0,,,,-0.00245,,,,,,49.9993019,,,,
,27311260.565,50.0005112,-2080.19604492187,-1.01826970242852E-5,3.33959339846468E-7,1,0.999253354069792,40.0298881530762,2.00827314996415,25.5100000649691,-0.00011454211005021,-2.65676781014433E-5,0.25,-5.05268796816506E-7,-1.01739517633045E-5,-5.8078038660167E-7,50.0005112,50.0005112,-2089.96752929687,-2070.42456054687,57.6818398336792,20.6480341347647,18.732843,0,0,0,40,4449,49.9877,-2080.19604492187,,,,,,,,,,,,,0,,,,0,,,,,,50.0005112,,,,
,27311354.545,50.0002022,2612.78881835938,-1.0157818438133E-5,3.59822819718394E-7,1,0.999253354069792,40.0298881530762,2.00843794701901,25.5100000649691,-0.000114275867732289,-2.649231444311E-5,0.25,-5.02880826757926E-7,-1.01493085315521E-5,-5.78222850661966E-7,50.0002022,50.0002022,2607.76538085938,2617.81225585938,57.2871174314676,20.6480015110979,19.112494,0,0,0,40,4449,49.98255,2612.78881835938,,,,,,,,,,,,,0,,,,-0.00245,,,,,,50.0002022,,,,
,27311445.445,49.9997253,7159.85864257812,-9.26315762753986E-6,4.21037002845624E-7,1,0.999253354069792,40.0298881530762,2.00866322802774,25.5100000649691,-0.000103705870657507,-2.71536103038568E-5,0.25,-7.21642309153198E-7,-9.25541297732931E-6,-7.90387977552799E-7,49.9997253,49.9997253,7152.37060546875,7167.3466796875,57.4739266475638,20.6463467312431,19.112494,0,0,0,40,4449,49.98615,7159.85864257812,,,,,,,,,,,,,0,,,,0,,,,,,49.9997253,,,,
,27311537.63,50.0012169,11765.7783203125,-7.24489677710788E-6,4.52011379384269E-7,1,0.999253354069792,40.0298881530762,2.0085834547554,25.5100000649691,-8.01963308838316E-5,-2.64028722764965E-5,0.25,-1.01891346671463E-6,-7.2371827029133E-6,-1.07276202676365E-6,50.0012169,50.0012169,11755.80078125,11775.755859375,57.6154014095446,20.6530367011945,19.112494,0,0,0,40,4449,49.9818,11765.7783203125,,,,,,,,,,,,,0,,,,0,,,,,,50.0012169,,,,
,27311633.57,50.0015182,16560.96875,-2.51563307721462E-6,4.65897725442851E-7,1,0.999253354069792,40.0298881530762,2.0086155860955,25.5100000649691,-2.61565661772969E-5,-1.8589728278995E-5,0.25,-1.18297826116608E-6,-2.50746260867531E-6,-1.2019294944193E-6,50.0015182,50.0015182,16548.302734375,16573.634765625,57.2331850636407,20.6506380397526,18.732843,0,0,0,40,4449,49.98355,16560.96875,,,,,,,,,,,,,0,,,,0,,,,,,50.0015182,,,,
,27311726.51,49.999897,21205.611328125,1.9667272637454E-6,5.61590724264026E-7,1,0.999253354069792,40.0298881530762,2.00845862169286,25.5100000649691,2.54885496755371E-5,-1.34068773663178E-5,0.25,-1.53432133231993E-6,1.97905375752284E-6,-1.52053972356105E-6,49.999897,49.999897,21195.5234375,21215.69921875,57.8795918490446,20.6505212489316,19.112494,0,0,0,40,4449,49.98445,21205.611328125,,,,,,,,,,,,,0,,,,-0.00245,,,,,,49.999897,,,,
,27311820.66,50.0011711,25913.5615234375,6.6135937747508E-6,5.63630028832808E-7,1,0.999253354069792,40.0298881530762,2.00823707621149,25.5100000649691,7.65639225345139E-5,5.74441066890769E-6,0.25,-6.86041833984048E-7,6.62365919412974E-6,-6.37872838053171E-7,50.0011711,50.0011711,25903.462890625,25923.66015625,57.6013320961984,20.6521601662798,19.112494,0,0,0,40,4449,49.986,25913.5615234375,,,,,,,,,,,,,0,,,,0,,,,,,50.0011711,,,,
,27311915.29,49.9998627,30641.2353515625,8.29311068942264E-6,6.85890353567748E-7,1,0.999253354069792,40.0298881530762,2.00830865320196,25.5100000649691,9.78214395406108E-5,-2.71434971717692E-6,0.25,-1.73249776797247E-6,8.31421487850356E-6,-1.67355714269775E-6,49.9998627,49.9998627,30636.1328125,30646.337890625,57.5114448164869,20.6497767788674,19.492144,0,0,0,40,4449,49.9809,30641.2353515625,,,,,,,,,,,,,0,,,,0,,,,,,49.9998627,,,,
,27312009.86,50.0002937,35369.140625,9.56099141952446E-6,6.75171365942959E-7,1,0.999253354069792,40.0298881530762,2.00832544414968,25.5100000649691,0.000111824008571973,2.31853585042952E-6,0.25,-1.517659510047E-6,9.58417376183763E-6,-1.45010056973638E-6,50.0002937,50.0002937,35359.13671875,35379.14453125,57.5427099572561,20.6484150617691,19.112494,0,0,0,40,4449,49.9855,35369.140625,,,,,,,,,,,,,0,,,,0,,,,,,50.0002937,,,,
,27312104.46,50.0005112,40094.416015625,8.71856743693672E-6,6.2517046046468E-7,1,0.999253354069792,40.0298881530762,2.00834038817449,25.5100000649691,0.000102262240986486,6.35394094977181E-7,0.25,-1.51346541973313E-6,8.7427101037493E-6,-1.45290878313727E-6,50.0005112,50.0005112,40086.90625,40101.92578125,57.3910740245253,20.6491702660366,19.492144,0,0,0,40,4449,49.9788,40094.416015625,,,,,,,,,,,,,0,,,,0.00245,,,,,,50.0005112,,,,
,27312198.185,50.0013351,44782.306640625,7.77807970575627E-6,6.41646419290621E-7,1,0.999253354069792,40.0298881530762,2.00826790785711,25.5100000649691,9.15673121206511E-5,-1.20406952130557E-6,0.25,-1.50534204618455E-6,7.80250544481757E-6,-1.45242651262784E-6,50.0013351,50.0013351,44774.81640625,44789.796875,57.4403166212368,20.6489682272538,19.112494,0,0,0,40,4449,49.98335,44782.306640625,,,,,,,,,,,,,0,,,,-0.00245,,,,,,50.0013351,,,,
,27312293.36,50.0011253,49537.380859375,8.03945289326129E-6,6.98702680580327E-7,1,0.999253354069792,40.0298881530762,2.008371047564,25.5100000649691,9.80296245198508E-5,-1.99267184449784E-5,0.25,-3.19699489341282E-6,8.07807009803267E-6,-3.14651596003614E-6,50.0011253,50.0011253,49532.421875,49542.33984375,57.4223391652945,20.6474214439972,19.112494,0,0,0,40,4449,49.9781,49537.380859375,,,,,,,,,,,,,0,,,,0,,,,,,50.0011253,,,,
,27312388.075,49.9999352,54272.541015625,8.1600539691297E-6,8.99697146174438E-7,1,0.999253354069792,40.0298881530762,2.00846180639554,25.5100000649691,9.99689798217448E-5,-2.27072699752223E-5,0.25,-3.46179429801397E-6,8.20235795804009E-6,-3.41241102163329E-6,49.9999352,49.9999352,54265.1796875,54279.90234375,56.9947883652753,20.6458825378265,19.112494,0,0,0,40,4449,49.9814,54272.541015625,,,,,,,,,,,,,0,,,,0.00245,,,,,,49.9999352,,,,
,27312484.93,50.0001831,59112.896484375,8.28439741767282E-6,6.68525317235941E-7,1,0.999253354069792,40.0298881530762,2.00838811688715,25.5100000649691,9.87862394412971E-5,-7.91225240985697E-6,0.25,-2.18351470080869E-6,8.31968806778442E-6,-2.13161164868739E-6,50.0001831,50.0001831,59107.73828125,59118.0546875,57.362935397833,20.6461385879702,18.732843,0,0,0,40,4449,49.9808,59112.896484375,,,,,,,,,,,,,0,,,,0.00245,,,,,,50.0001831,,,,
,27312582.485,50.0009689,63988.234375,7.36073560174765E-6,8.40471090359667E-7,1,0.999253354069792,40.0298881530762,2.00863389195991,25.5100000649691,9.03547864728762E-5,-2.12640499588354E-5,0.25,-3.1889518543978E-6,7.40200365454318E-6,-3.14721909274192E-6,50.0009689,50.0009689,63980.78125,63995.6875,57.2902439455445,20.6485716146381,19.112494,0,0,0,40,4449,49.97715,63988.234375,,,,,,,,,,,,,0,,,,0,,,,,,50.0009689,,,,
,27312677.94,50.0008698,68761.26953125,6.68254834930699E-6,7.15163055309966E-7,1,0.999253354069792,40.0298881530762,2.00866529748448,25.5100000649691,8.11856283505484E-5,-1.45251240880965E-5,0.25,-2.47452821045031E-6,6.71825956256791E-6,-2.43662975707388E-6,50.0008698,50.0008698,68758.890625,68763.6484375,57.2832092888714,20.6478052450714,18.732843,0,0,0,40,4449,49.9781,68761.26953125,,,,,,,,,,,,,0,,,,0,,,,,,50.0008698,,,,
,27312775.18,50.0022621,73618.55078125,6.56568274353531E-6,7.33703030954252E-7,1,0.999253354069792,40.0298881530762,2.0087555610371,25.5100000649691,8.01465930069837E-5,-1.63073625021883E-5,0.25,-2.60898621587983E-6,6.60299201732107E-6,-2.57339051431871E-6,50.0022621,50.0022621,73615.9140625,73621.1875,57.4356268501215,20.6492568774507,19.112494,0,0,0,40,4449,49.9762,73618.55078125,,,,,,,,,,,,,0,,,,0,,,,,,50.0022621,,,,
,27312870.42,50.0023422,78381.859375,4.56944097204025E-6,1.05643998712258E-6,1,0.999253354069792,40.0298881530762,2.00870604022986,25.5100000649691,5.63953887059117E-5,-1.47533437782835E-5,0.25,-2.1138109561401E-6,4.59801130238595E-6,-2.09076678630021E-6,50.0023422,50.0023422,78374.3984375,78389.3203125,57.2339666921599,20.6517278127144,18.732843,0,0,0,40,4449,49.97355,78381.859375,,,,,,,,,,,,,0,,,,0.0049,,,,,,50.0023422,,,,
,27312967.07,50.00029755,83212.8828125,4.12357190509876E-6,5.29372284554021E-7,1,0.999253354069792,40.0298881530762,2.00867442519617,25.5100000649691,5.27961461097651E-5,-2.39063103875476E-5,0.25,-2.83620187757752E-6,4.15587062016237E-6,-2.81931265118467E-6,50.000248,50.0003471,83207.8828125,83217.8828125,57.4551675631022,20.646856837436,18.732843,0,0,0,40,4449,49.9773,83212.8828125,,,,,,,,,,,,,0,,,,0,,,,,,50.00029755,,,,
,27313057.085,50.0021172,87711.38671875,4.71673035468965E-6,7.05726266026754E-7,1,0.999253354069792,40.0298881530762,2.00855850961197,25.5100000649691,5.95367094336953E-5,-2.25661319300626E-5,0.25,-2.82423180168585E-6,4.75144364270047E-6,-2.80436066801209E-6,50.0021172,50.0021172,87706.5,87716.2734375,57.1948852661984,20.6495963653573,19.492144,0,0,0,40,4449,49.9748,87711.38671875,,,,,,,,,,,,,0,,,,0,,,,,,50.0021172,,,,
,27313164.72,49.9998779,87888.27734375,3.25339076603731E-6,1.11119426336345E-6,1,0.999253354069792,40.0298881530762,2.0084855998309,25.5100000649691,4.35083839826051E-5,-2.92106663455999E-5,0.25,-3.14507050712981E-6,3.28493755221291E-6,-3.13565751246833E-6,49.9998779,49.9998779,87878.1640625,87898.390625,57.2378748347561,20.6485903866794,19.492144,0,0,0,40,4449,49.97535,87888.27734375,,,,,,,,,,,,,0,,,,0.00245,,,,,,49.9998779,,,,
,27313255.5,49.9997711,83349.98828125,5.9266327244871E-6,7.68794847130979E-7,1,0.999253354069792,40.0298881530762,2.00864222578391,25.5100000649691,7.37086729304659E-5,-2.22376852121252E-5,0.25,-3.01290890922434E-6,5.96622788409805E-6,-2.98504421904495E-6,49.9997711,49.9997711,83345.0546875,83354.921875,57.474708276083,20.6504752023332,19.112494,0,0,0,40,4449,49.9759,83349.98828125,,,,,,,,,,,,,0,,,,0,,,,,,49.9997711,,,,
,27313349.375,50.0002823,78661.23046875,6.06679019798948E-6,9.34212543805516E-7,1,0.999253354069792,40.0298881530762,2.00858640161857,25.5100000649691,7.25983924951967E-5,-6.90677245754265E-6,0.25,-1.69376806943446E-6,6.09750282966324E-6,-1.65963207380223E-6,50.0002823,50.0002823,78651.015625,78671.4453125,57.3238539718714,20.6488822510814,19.112494,0,0,0,40,4449,49.97345,78661.23046875,,,,,,,,,,,,,0,,,,0,,,,,,50.0002823,,,,
,27313445.375,49.999157,73859.92578125,5.84262380767841E-6,5.35024941931077E-7,1,0.999253354069792,40.0298881530762,2.00909938714715,25.5100000649691,7.4959095583411E-5,-3.47306031834434E-5,0.25,-4.09555230999859E-6,5.88762456055068E-6,-4.06934810391836E-6,49.999157,49.999157,73857.34375,73862.5078125,57.3902923960061,20.6474726723396,19.492144,0,0,0,40,4449,49.9757,73859.92578125,,,,,,,,,,,,,0,,,,0,,,,,,49.999157,,,,
,27313540.505,50.0005569,69104.2421875,6.25567383817553E-6,6.23114328007598E-7,1,0.999253354069792,40.0298881530762,2.008995156304,25.5100000649691,7.79486271880692E-5,-2.43873965961561E-5,0.25,-3.2632333000132E-6,6.295540868617E-6,-3.23054590560257E-6,50.0005569,50.0005569,69094.5,69113.984375,57.2253687784484,20.6490905730965,18.732843,0,0,0,40,4449,49.9801,69104.2421875,,,,,,,,,,,,,0,,,,0.0049,,,,,,50.0005569,,,,
,27313634.97,49.9997711,64381.27734375,7.41457654957403E-6,6.89093031456594E-7,1,0.999253354069792,40.0298881530762,2.00885341880247,25.5100000649691,8.9982542861095E-5,-1.56092256267205E-5,0.25,-2.70188415608861E-6,7.4527720980187E-6,-2.65859352411449E-6,49.9997711,49.9997711,64376.390625,64386.1640625,57.2738297466407,20.6460667829978,19.112494,0,0,0,40,4449,49.97815,64381.27734375,,,,,,,,,,,,,0,,,,0,,,,,,49.9997711,,,,
,27313730.43,49.9987526,59610.1875,7.72618941167995E-6,7.19838513913977E-7,1,0.999253354069792,40.0298881530762,2.00863644641241,25.5100000649691,9.12042026400593E-5,-2.15752628771185E-6,0.25,-1.57766171737214E-6,7.75608411062879E-6,-1.52823666840771E-6,49.9987526,49.9987526,59602.76171875,59617.61328125,57.4364084786407,20.6498160070492,18.732843,0,0,0,40,4449,49.9748,59610.1875,,,,,,,,,,,,,0,,,,-0.0049,,,,,,49.9987526,,,,
,27313822.71,49.99948885,54997.732421875,8.06845681878871E-6,7.43205093109821E-7,1,0.999253354069792,40.0298881530762,2.00873313684556,25.5100000649691,9.83523989756399E-5,-1.96195694175733E-5,0.25,-3.17368739174355E-6,8.10876773124068E-6,-3.12450523708255E-6,49.9993668,49.9996109,54985.17578125,55010.2890625,57.3433946848522,20.6524575917796,18.732843,0,0,0,40,4449,49.97435,54997.732421875,,,,,,,,,,,,,0,,,,-0.00245,,,,,,49.99948885,,,,
,27313917.6,49.9988708,50254.84765625,7.83046884905485E-6,7.16170582297006E-7,1,0.999253354069792,40.0298881530762,2.00871427958241,25.5100000649691,9.44621676963492E-5,-1.36428423024954E-5,0.25,-2.60687348775329E-6,7.86473904531007E-6,-2.55687729809022E-6,49.9988708,49.9988708,50247.51171875,50262.18359375,57.1362631272561,20.6499313675951,19.112494,0,0,0,40,4449,49.97795,50254.84765625,,,,,,,,,,,,,0,,,,0.0049,,,,,,49.9988708,,,,
,27314011.625,49.999588,45555.21875,8.66409204279166E-6,4.38717519154353E-7,1,0.999253354069792,40.0298881530762,2.00861894100324,25.5100000649691,0.000105219876109792,-1.91349751587917E-5,0.25,-3.24047049208407E-6,8.70276358406006E-6,-3.18449665713068E-6,49.999588,49.999588,45545.31640625,45565.12109375,57.3074397729676,20.6507473295578,19.112494,0,0,0,40,4449,49.98015,45555.21875,,,,,,,,,,,,,0,,,,-0.00245,,,,,,49.999588,,,,
,27314106.195,49.9989815,40832.189453125,9.39194277939005E-6,6.40834065101508E-7,1,0.999253354069792,40.0298881530762,2.00858606245037,25.5100000649691,0.000110204855256718,5.31605155425263E-7,0.25,-1.64370514229123E-6,9.41839261601167E-6,-1.57864904181085E-6,49.9989815,49.9989815,40827.14453125,40837.234375,57.1761261817368,20.6501486979846,19.492144,0,0,0,40,4449,49.981,40832.189453125,,,,,,,,,,,,,0,,,,-0.0049,,,,,,49.9989815,,,,
,27314201.36,49.9981194,36072.265625,9.5002555838491E-6,4.69007771404002E-7,1,0.999253354069792,40.0298881530762,2.00874898714898,25.5100000649691,0.000111789274034308,-1.30235198348905E-6,0.25,-1.82504994265528E-6,9.52592538154607E-6,-1.7584663072146E-6,49.9981194,49.9981194,36069.9296875,36074.6015625,57.5575608991215,20.6489714427559,19.112494,0,0,0,40,4449,49.9811,36072.265625,,,,,,,,,,,,,0,,,,0,,,,,,49.9981194,,,,
,27314295.325,49.9984512,31374.9521484375,8.55045240035399E-6,4.85517672927937E-7,1,0.999253354069792,40.0298881530762,2.00857298361232,25.5100000649691,9.94248960916543E-5,5.24324354444864E-6,0.25,-1.07884457763628E-6,8.56736234400991E-6,-1.01746163902924E-6,49.9984512,49.9984512,31367.625,31382.279296875,57.3699700545061,20.6475965317862,18.732843,0,0,0,40,4449,49.97905,31374.9521484375,,,,,,,,,,,,,0,,,,0,,,,,,49.9984512,,,,
,27314391.315,49.9984474,26579.2744140625,1.01210610850261E-5,5.36126676234844E-7,1,0.999253354069792,40.0298881530762,2.00867448933468,25.5100000649691,0.000117452747920479,7.37559204780554E-6,0.25,-1.17451941912183E-6,1.01377324849365E-5,-1.1009936814183E-6,49.9984474,49.9984474,26574.427734375,26584.12109375,57.4793980471984,20.6499666578095,19.112494,0,0,0,40,4449,49.98035,26579.2744140625,,,,,,,,,,,,,0,,,,0,,,,,,49.9984474,,,,
,27314484.08,50.0007515,21944.021484375,1.04058299052937E-5,3.9076413575186E-7,1,0.999253354069792,40.0298881530762,2.00861323755077,25.5100000649691,0.000119638474022261,1.36035268363311E-5,0.25,-6.77974758734171E-7,1.0416444664651E-5,-6.01429560186984E-7,50.0007515,50.0007515,21936.51953125,21951.5234375,57.5927341824868,20.6491007029342,19.112494,0,0,0,40,4449,49.984,21944.021484375,,,,,,,,,,,,,0,,,,0,,,,,,50.0007515,,,,
,27314577.025,49.9993858,17296.9404296875,1.10675425243787E-5,4.55299315382555E-7,1,0.999253354069792,40.0298881530762,2.00862846599391,25.5100000649691,0.000126774727111399,1.69071558432073E-5,0.25,-5.06432895360833E-7,1.10744157250076E-5,-4.24490942927311E-7,49.9993858,49.9993858,17294.38671875,17299.494140625,57.3590272552368,20.6517478256225,19.112494,0,0,0,40,4449,49.98305,17296.9404296875,,,,,,,,,,,,,0,,,,0,,,,,,49.9993858,,,,
,27314671.07,49.9994125,12599.5571289062,1.107289004345E-5,4.63541681942996E-7,1,0.999253354069792,40.0298881530762,2.00857646574526,25.5100000649691,0.000126857769949715,1.65928542875934E-5,0.25,-5.3485860727749E-7,1.10771485742735E-5,-4.52564002446734E-7,49.9994125,49.9994125,12591.9052734375,12607.208984375,57.4676736194099,20.6509168903954,19.112494,0,0,0,40,4449,49.98175,12599.5571289062,,,,,,,,,,,,,0,,,,0.00245,,,,,,49.9994125,,,,
,27314763.065,49.9994736,7998.85986328125,1.07097047125435E-5,4.0999856244084E-7,1,0.999253354069792,40.0298881530762,2.00859295803876,25.5100000649691,0.000122377442197356,1.76599370232776E-5,0.25,-3.75185925566179E-7,1.07102062624898E-5,-2.95416424684364E-7,49.9994736,49.9994736,7994.00390625,8003.7158203125,57.6998172896215,20.6503234936652,19.112494,0,0,0,40,4449,49.9871,7998.85986328125,,,,,,,,,,,,,0,,,,-0.0049,,,,,,49.9994736,,,,
,27314854.415,49.9988251,3433.42919921875,1.07469722595763E-5,3.1080950030299E-7,1,0.999253354069792,40.0298881530762,2.00856110436486,25.5100000649691,0.000122271791350707,2.05063628423551E-5,0.25,-1.30825209554647E-7,1.07432935540452E-5,-5.08004730942918E-8,49.9988251,49.9988251,3430.79663085937,3436.06176757812,57.677931691083,20.6504388178094,19.492144,0,0,0,40,4449,49.9862,3433.42919921875,,,,,,,,,,,,,0,,,,-0.00245,,,,,,49.9988251,,,,
,27314923.775,50.000515,-0.228356599807739,1.10373157572308E-5,3.59048966963696E-7,1,0.999253354069792,40.0298881530762,2.0085918673307,25.5100000649691,0.000126085085234243,1.81494577703518E-5,0.25,-3.90569236984555E-7,1.10340260051591E-5,-3.08253638304265E-7,50.0003357,50.0006943,-0.243580371141434,-0.213132828474045,57.5067550453715,20.6518415068204,19.112494,0,0,0,40,4417,49.98275,-0.228356599807739,,,,,,,,,,,,,0,,,,0.0049,,,,,,50.000515,,,,