File: data/monolayers/nanoparticles/Ac_CoFe_C/vsm/rawdata/DD226_2_HYST_350K_REPEAT.DAT
[Header]
; VSM Data File (default extension .dat)
; Copyright (c) 2003-2013, Quantum Design, Inc. All rights reserved.
TITLE,
FILEOPENTIME,27495638.61,11/15/2018,1:40 pm
BYAPP,VSM,2.0,2.0
INFO,PPMS VSM Option Release 1.4.10 Build 1,APPNAME
INFO,Quantum Design Linear Motor Servo Controller,MOTOR_MODULE_NAME
INFO,3101-100 M1,MOTOR_HW_VERSION
INFO,MMC1014,MOTOR_SERIAL_NUMBER
INFO,SRV No X-over 01.03.11,MOTOR_SOFTWARE_VERSION
INFO,Quantum Design VSM Detection Module,VSM_MODULE_NAME
INFO,3101-150 F0,VSM_HW_VERSION
INFO,VSM707,VSM_SERIAL_NUMBER
INFO,VSM No X-over 01.02.05 May 20 2008 13:51:47,VSM_SOFTWARE_VERSION
INFO,704,PREAMP_SERIAL_NUMBER
INFO,822,COIL_SERIAL_NUMBER
INFO,0,MOMENT_UNITS
INFO,CoFe2O4 AH11,SAMPLE_MATERIAL
INFO,Quick Dry Monolayer Conc,SAMPLE_COMMENT
INFO,27.96,SAMPLE_MASS
INFO,,SAMPLE_VOLUME
INFO,,SAMPLE_MOLECULAR_WEIGHT
INFO,,SAMPLE_SIZE
INFO,,SAMPLE_SHAPE
DATATYPE,COMMENT,1
DATATYPE,TIME,2
STARTUPAXIS,X,2
STARTUPAXIS,Y1,5
[Data]
Comment,Time Stamp (sec),Temperature (K),Magnetic Field (Oe),Moment (emu),M. Std. Err. (emu),Transport Action,Averaging Time (sec),Frequency (Hz),Peak Amplitude (mm),Center Position (mm),Coil Signal' (mV),Coil Signal" (mV),Range (mV),M. Quad. Signal (emu),M. Raw' (emu),M. Raw" (emu),Min. Temperature (K),Max. Temperature (K),Min. Field (Oe),Max. Field (Oe),Mass (grams),Motor Lag (deg),Pressure (Torr),VSM Status (code),Motor Status (code),Measure Status (code),Measure Count,PPMS Status (code),System Temp. (K),System Field (Oe),Sample Position (deg),Bridge 1 Resistance (ohms),Bridge 1 Excitation (에),Bridge 2 Resistance (ohms),Bridge 2 Excitation (에),Bridge 3 Resistance (ohms),Bridge 3 Excitation (에),Bridge 4 Resistance (ohms),Bridge 4 Excitation (에),Signal 1 Vin (V),Signal 2 Vin (V),Digital Inputs (code),Drive 1 Iout (mA),Drive 1 Ipower (W),Drive 2 Iout (mA),Drive 2 Ipower (W),Pressure (),Map 20 (),Map 21 (),Map 22 (),Map 23 (),Map 24 (),Map 25 (),Map 26 (),Map 27 (),Map 28 (),Map 29 ()
sample offset = 36.12 mm touchdown = 10.3900004178286 mm,27495655.945,349.9787903,0.159849621355534,-5.48185198057204E-7,4.71294980347657E-7,1,0.999253354069792,40.0298881530762,1.99734945301716,15.429999679327,-6.53941318294512E-6,9.51256896281033E-7,0.25,1.79173779879706E-7,-5.47313482387051E-7,1.7855096100823E-7,349.9787903,349.9787903,0.152237743139267,0.1674614995718,55.1165350335635,20.4608600092475,29.363071,0,0,0,40,4417,350.54785,0.159849621355534,,,,,,,,,,,,,0,,,,0,,,,,,349.9787903,,,,
,27495731.445,349.9778748,2898.20544433594,1.9424367345901E-5,6.26120980578105E-7,1,0.999253354069792,40.0298881530762,1.99717931473098,15.429999679327,0.000218608181011298,4.18959350925696E-5,0.25,3.47759789432312E-7,1.93897505615673E-5,3.57957817957119E-7,349.9778748,349.9778748,2890.478515625,2905.93237304687,55.4721760098136,20.4706881748948,28.983419,0,0,0,40,4449,350.55745,2898.20544433594,,,,,,,,,,,,,0,,,,0,,,,,,349.9778748,,,,
,27495796.665,349.9809875,6151.39770507812,1.41470182954032E-5,5.16111968058817E-7,1,0.999253354069792,40.0298881530762,1.99723995498412,15.429999679327,0.000159735107010025,2.75380016605025E-5,0.25,-1.03436666175591E-8,1.41219519649431E-5,-2.45232774443223E-9,349.9809875,349.9809875,6148.86083984375,6153.9345703125,55.7324583067174,20.4761787227395,28.983419,0,0,0,40,4449,350.5634,6151.39770507812,,,,,,,,,,,,,0,,,,0.0049,,,,,,349.9809875,,,,
,27495856.455,349.982605,9142.96533203125,5.30247940489773E-6,6.1180194497735E-7,1,0.999253354069792,40.0298881530762,1.99728108607477,15.429999679327,5.83162461088555E-5,1.93061303389839E-5,0.25,7.91911962486398E-7,5.29264136209731E-6,7.93458086515227E-7,349.982605,349.982605,9137.7939453125,9148.13671875,55.8614270123905,20.4767675358348,28.983419,0,0,0,40,4449,350.57605,9142.96533203125,,,,,,,,,,,,,0,,,,0,,,,,,349.982605,,,,
,27495919.64,349.9861755,12298.3583984375,-4.24266553928837E-6,7.99430678518486E-7,1,0.999253354069792,40.0298881530762,1.9971858999778,15.429999679327,-4.94703996389856E-5,7.93690052689014E-7,0.25,8.04923558679899E-7,-4.23559343977483E-6,8.01137862979169E-7,349.9861755,349.9861755,12295.7353515625,12300.9814453125,55.9122328661405,20.4805306998583,29.363071,0,0,0,40,4449,350.5697,12298.3583984375,,,,,,,,,,,,,0,,,,0,,,,,,349.9861755,,,,
,27495983.79,349.9909668,15507.0952148438,-1.49534004828654E-5,9.00621298865666E-7,1,0.999253354069792,40.0298881530762,1.99709768845967,15.429999679327,-0.000169668487074483,-2.42545173609882E-5,0.25,4.40651170964534E-7,-1.49271400178929E-5,4.31560115171213E-7,349.9909668,349.9909668,15499.4931640625,15514.697265625,56.1834579623136,20.4827865887616,29.363071,0,0,0,40,4449,350.59415,15507.0952148438,,,,,,,,,,,,,0,,,,-0.00245,,,,,,349.9909668,,,,
,27496049.22,349.9935913,18775.4384765625,-2.57893511805673E-5,9.26914795392834E-7,1,0.999253354069792,40.0298881530762,1.99709301169836,15.429999679327,-0.000294195852624669,-3.27161944001825E-5,0.25,1.56732538965135E-6,-2.57445076030988E-5,1.5502217577312E-6,349.9935913,349.9935913,18767.91796875,18782.958984375,56.3093001539098,20.4858870536185,29.363071,0,0,0,40,4449,350.57135,18775.4384765625,,,,,,,,,,,,,0,,,,-0.00245,,,,,,349.9935913,,,,
,27496114.86,349.9953613,22058.53125,-3.69972018324225E-5,1.12523409509746E-6,1,0.999253354069792,40.0298881530762,1.99709536817602,15.429999679327,-0.000420706461395074,-5.47026670928351E-5,0.25,1.56033017265978E-6,-3.69324855141633E-5,1.53702475547793E-6,349.9953613,349.9953613,22051.14453125,22065.91796875,56.2209761312367,20.4854328092556,29.742722,0,0,0,40,4449,350.5826,22058.53125,,,,,,,,,,,,,0,,,,0.00245,,,,,,349.9953613,,,,
,27496180.875,349.99453735,25354.4580078125,-4.95758551665192E-5,1.02940827839926E-6,1,0.999253354069792,40.0298881530762,1.99711275851123,15.429999679327,-0.000560484056262329,-9.2145542967621E-5,0.25,4.21574889119275E-7,-4.9488211669193E-5,3.93319915418288E-7,349.9943848,349.9946899,25344.486328125,25364.4296875,56.1897109904675,20.4876085714164,29.363071,0,0,0,40,4449,350.5815,25354.4580078125,,,,,,,,,,,,,0,,,,0.00245,,,,,,349.99453735,,,,
,27496244.595,349.9981384,28540.673828125,-5.94868059483158E-5,1.2498017696952E-6,1,0.999253354069792,40.0298881530762,1.99707020662967,15.429999679327,-0.000674921568493172,-9.66911819069114E-5,0.25,1.73479295077558E-6,-5.93823166960703E-5,1.69872864774446E-6,349.9981384,349.9981384,28538.1171875,28543.23046875,56.272563613506,20.48821075546,29.742722,0,0,0,40,4449,350.5798,28540.673828125,,,,,,,,,,,,,0,,,,0.0049,,,,,,349.9981384,,,,
,27496311.31,350.0084534,31876.4072265625,-7.21833936193562E-5,1.21770438191656E-6,1,0.999253354069792,40.0298881530762,1.99706453921105,15.429999679327,-0.000820895225122035,-0.000106216165992547,0.25,3.08938157953212E-6,-7.20571241341704E-5,3.04389652855856E-6,350.0084534,350.0084534,31871.453125,31881.361328125,56.2639656997944,20.4898177449132,28.983419,0,0,0,40,4449,350.5725,31876.4072265625,,,,,,,,,,,,,0,,,,0.0049,,,,,,350.0084534,,,,
,27496378.425,350.0108643,35229.587890625,-8.33049061005502E-5,1.56683688959599E-6,1,0.999253354069792,40.0298881530762,1.99708620862516,15.429999679327,-0.000947180402058535,-0.000123751193208309,0.25,3.46181494560343E-6,-8.31591186533644E-5,3.40953290894788E-6,350.0108643,350.0108643,35224.90234375,35234.2734375,56.3898078913906,20.4894393888503,29.363071,0,0,0,40,4449,350.5724,35229.587890625,,,,,,,,,,,,,0,,,,0,,,,,,350.0108643,,,,
,27496442.155,350.0089722,38415.34765625,-9.39790610105432E-5,1.43240100591275E-6,1,0.999253354069792,40.0298881530762,1.997118616068,15.429999679327,-0.00107085697419893,-0.000126359304859716,0.25,5.07913531553229E-6,-9.38152500879869E-5,5.01810319390712E-6,350.0089722,350.0089722,38402.79296875,38427.90234375,56.485948199256,20.4856838084699,29.742722,0,0,0,40,4449,350.5693,38415.34765625,,,,,,,,,,,,,0,,,,0.00245,,,,,,350.0089722,,,,
,27496510.495,350.0069275,41828.994140625,-0.000106347063181766,1.58167314579979E-6,1,0.999253354069792,40.0298881530762,1.99703581670936,15.429999679327,-0.00120520989950775,-0.000180685386033836,0.25,2.40765540101422E-6,-0.000106159854383087,2.34454925958972E-6,350.0069275,350.0069275,41826.125,41831.86328125,56.3851181202752,20.4851693075836,28.983419,0,0,0,40,4449,350.5638,41828.994140625,,,,,,,,,,,,,0,,,,0.00245,,,,,,350.0069275,,,,
,27496574.445,350.0117188,45028.158203125,-0.000120051852752211,1.84820426648037E-6,1,0.999253354069792,40.0298881530762,1.99698491014304,15.429999679327,-0.00136142402476767,-0.000198571975907311,0.25,3.19564731458207E-6,-0.000119840765384061,3.12359978358514E-6,350.0117188,350.0117188,45020.73046875,45035.5859375,56.5398805670829,20.4888531583564,29.742722,0,0,0,40,4449,350.5558,45028.158203125,,,,,,,,,,,,,0,,,,0.0049,,,,,,350.0117188,,,,
,27496637.975,350.0047913,48203.328125,-0.000131427638179185,1.51085383536382E-6,1,0.999253354069792,40.0298881530762,1.99710520212912,15.429999679327,-0.00148758344919308,-0.000234331113939385,0.25,1.99867305725333E-6,-0.000131195752905763,1.92250348499176E-6,350.0047913,350.0047913,48193.375,48213.28125,56.4984542555637,20.4858166311993,29.363071,0,0,0,40,4449,350.563,48203.328125,,,,,,,,,,,,,0,,,,0,,,,,,350.0047913,,,,
,27496704.715,350.012207,51539.34375,-0.000142153214471748,2.10516057451485E-6,1,0.999253354069792,40.0298881530762,1.9970078722369,15.429999679327,-0.00161101295124779,-0.000241281423371706,0.25,3.23905088298078E-6,-0.000141902967665348,3.15480258140209E-6,350.0120544,350.0123596,51531.67578125,51547.01171875,56.3921527769483,20.483677977373,29.742722,0,0,0,40,4449,350.5507,51539.34375,,,,,,,,,,,,,0,,,,0,,,,,,350.012207,,,,
,27496769.94,350.0175171,54800.349609375,-0.00015372170482769,1.86720257444179E-6,1,0.999253354069792,40.0298881530762,1.99697107193568,15.429999679327,-0.00174163706288687,-0.000263510757241074,0.25,3.27241056380222E-6,-0.000153450940824421,3.18176401137114E-6,350.0175171,350.0175171,54795.015625,54805.68359375,56.4468667732944,20.4872726568211,29.742722,0,0,0,40,4449,350.5347,54800.349609375,,,,,,,,,,,,,0,,,,0.00245,,,,,,350.0175171,,,,
,27496835.425,350.0155945,58073.6484375,-0.0001672054651291,1.64210700319617E-6,1,0.999253354069792,40.0298881530762,1.99695398548098,15.429999679327,-0.00189482165271985,-0.000284130171861872,0.25,3.7801782412484E-6,-0.000166911086549936,3.68124524081156E-6,350.0155945,350.0155945,58068.68359375,58078.61328125,56.3561978650637,20.4861559857999,29.742722,0,0,0,40,4449,350.5196,58073.6484375,,,,,,,,,,,,,0,,,,-0.00245,,,,,,350.0155945,,,,
,27496900.535,350.0133057,61326.421875,-0.00017934596097393,2.01108165392045E-6,1,0.999253354069792,40.0298881530762,1.99680312714733,15.429999679327,-0.00203070108066708,-0.000313713011363193,0.25,3.25948016538829E-6,-0.000179029786993484,3.15483868067671E-6,350.0133057,350.0133057,61321.49609375,61331.34765625,56.320242953179,20.4870995276111,29.363071,0,0,0,40,4449,350.5215,61326.421875,,,,,,,,,,,,,0,,,,0,,,,,,350.0133057,,,,
,27496966.295,350.0140381,64613.267578125,-0.000189459555878565,2.26400497907485E-6,1,0.999253354069792,40.0298881530762,1.99683256881104,15.429999679327,-0.00214425448577645,-0.000337132730635128,0.25,2.93608150183074E-6,-0.000189125272104176,2.82650602113303E-6,350.0140381,350.0140381,64605.95703125,64620.578125,56.4570279440444,20.4862233972317,29.363071,0,0,0,40,4449,350.51645,64613.267578125,,,,,,,,,,,,,0,,,,0,,,,,,350.0140381,,,,
,27497031.99,350.0255127,67897.04296875,-0.00020109535624936,2.81363482774966E-6,1,0.999253354069792,40.0298881530762,1.9967984250024,15.429999679327,-0.00227997076381648,-0.000334364579416351,0.25,5.19544027093392E-6,-0.000200741613030687,5.07551711110038E-6,350.0255127,350.0255127,67889.6953125,67904.390625,56.3475999513521,20.4861129083908,28.983419,0,0,0,40,4449,350.5031,67897.04296875,,,,,,,,,,,,,0,,,,0,,,,,,350.0255127,,,,
,27497097.525,350.0152283,71172.5546875,-0.000212949924583777,2.16533386669632E-6,1,0.999253354069792,40.0298881530762,1.99675580396871,15.429999679327,-0.00240916770367033,-0.000383864224541452,0.25,2.86179904941975E-6,-0.000212573953440088,2.73956499285965E-6,350.0152283,350.0152283,71167.484375,71177.625,56.3390020376406,20.4848919303604,29.363071,0,0,0,40,4449,350.49515,71172.5546875,,,,,,,,,,,,,0,,,,0,,,,,,350.0152283,,,,
,27497162.6,350.0143433,74426.234375,-0.000225472832180752,2.20517090290583E-6,1,0.999253354069792,40.0298881530762,1.99686102000014,15.429999679327,-0.00255179068203664,-0.000401727930203195,0.25,3.44910935898729E-6,-0.000225074993309327,3.31902292769133E-6,350.0143433,350.0143433,74421.1796875,74431.2890625,56.3733936924867,20.4878317378789,28.983419,0,0,0,40,4449,350.4807,74426.234375,,,,,,,,,,,,,0,,,,0.0049,,,,,,350.0143433,,,,
,27497228.46,350.0169373,77717.640625,-0.00023980083850612,3.18243116553841E-6,1,0.999253354069792,40.0298881530762,1.99666707941413,15.429999679327,-0.0027169895935927,-0.000408195898268721,0.25,5.35345660949839E-6,-0.000239378628717083,5.21220708277287E-6,350.0169373,350.0169373,77715.2265625,77720.0546875,56.3561978650637,20.4890730781407,29.363071,0,0,0,40,4449,350.483,77717.640625,,,,,,,,,,,,,0,,,,0,,,,,,350.0169373,,,,
,27497293.625,350.009552,80974.12890625,-0.000251893687074461,2.78347544374954E-6,1,0.999253354069792,40.0298881530762,1.99665565808892,15.429999679327,-0.00284917662526934,-0.000456573091185737,0.25,3.16069220855366E-6,-0.000251448901060498,3.01677729860309E-6,350.009552,350.009552,80969.2421875,80979.015625,56.4601544581214,20.4887628037419,29.363071,0,0,0,40,4449,350.4721,80974.12890625,,,,,,,,,,,,,0,,,,0.00245,,,,,,350.009552,,,,
,27497356.195,350.0119324,84102.7578125,-0.000262033144329241,2.52426539502251E-6,1,0.999253354069792,40.0298881530762,1.99670658421881,15.429999679327,-0.0029730752658735,-0.000422180169856943,0.25,7.96434616573387E-6,-0.000261573005181038,7.80644042201836E-6,350.0119324,350.0119324,84072.8828125,84132.6328125,56.2967940976021,20.4903183407874,28.983419,0,0,0,40,4449,350.46455,84102.7578125,,,,,,,,,,,,,0,,,,-0.0049,,,,,,350.0119324,,,,
,27497418.81,350.0180359,87231.5703125,-0.000270545729377033,2.83210077180233E-6,1,0.999253354069792,40.0298881530762,1.99662563510381,15.429999679327,-0.00306725692698583,-0.000449071617634453,0.25,7.0540370747024E-6,-0.0002700699491775,6.89316692465819E-6,350.0180359,350.0180359,87226.640625,87236.5,56.2366087016213,20.4904249804106,29.742722,0,0,0,40,4449,350.45305,87231.5703125,,,,,,,,,,,,,0,,,,0,,,,,,350.0180359,,,,
,27497498.65,350.01487735,89765.34375,-0.000281429563478474,2.91205433108803E-6,1,0.999253354069792,40.0298881530762,1.9966704020597,15.429999679327,-0.00318324202035924,-0.000510330541262427,0.25,3.51168044872983E-6,-0.000280932579879481,3.35120382384914E-6,350.0143433,350.0154114,89757.7265625,89772.9609375,56.2811615272175,20.4886832258932,29.742722,0,0,0,40,4449,350.4474,89765.34375,,,,,,,,,,,,,0,,,,0,,,,,,350.01487735,,,,
,27497560.51,350.010437,86678.37109375,-0.000272546491775172,2.39088146868522E-6,1,0.999253354069792,40.0298881530762,1.9968043776708,15.429999679327,-0.00308317585646821,-0.000493028564055869,0.25,3.50951775166126E-6,-0.000272065289197898,3.35381303431156E-6,350.010437,350.010437,86673.3046875,86683.4375,56.2858512983329,20.4890816865451,29.742722,0,0,0,40,4449,350.44195,86678.37109375,,,,,,,,,,,,,0,,,,-0.00245,,,,,,350.010437,,,,
,27497625.565,350.0111084,83424.44140625,-0.000256432678941889,2.30837106315551E-6,1,0.999253354069792,40.0298881530762,1.99668906066103,15.429999679327,-0.0029057519312225,-0.000434841511382939,0.25,5.87258486382257E-6,-0.000255981325768402,5.72143445726232E-6,350.0111084,350.0111084,83419.390625,83429.4921875,56.4257628032752,20.4913571235507,29.742722,0,0,0,40,4449,350.4497,83424.44140625,,,,,,,,,,,,,0,,,,0,,,,,,350.0111084,,,,
,27497690.575,350.0047913,80177.73046875,-0.000248242877674239,2.5161595717323E-6,1,0.999253354069792,40.0298881530762,1.99666286564045,15.429999679327,-0.00281971508225119,-0.000381674310535534,0.25,9.16487090624126E-6,-0.000247807898677058,9.01228303548201E-6,350.0047913,350.0047913,80175.1953125,80180.265625,56.4124751184483,20.4927756038649,29.742722,0,0,0,40,4449,350.4385,80177.73046875,,,,,,,,,,,,,0,,,,0.0049,,,,,,350.0047913,,,,
,27497754.645,350.0023499,76970.93359375,-0.000235222133324886,2.00542095537713E-6,1,0.999253354069792,40.0298881530762,1.99672957731058,15.429999679327,-0.00266974429698018,-0.000374127226774076,0.25,7.58024006141963E-6,-0.000234809379109414,7.43752675205587E-6,350.0023499,350.0023499,76965.9375,76975.9296875,56.3968425480637,20.4930023205384,29.363071,0,0,0,40,4449,350.44115,76970.93359375,,,,,,,,,,,,,0,,,,-0.0049,,,,,,350.0023499,,,,
,27497819.805,349.9917603,73716.7265625,-0.000222092413236935,2.48349052351E-6,1,0.999253354069792,40.0298881530762,1.99672863770014,15.429999679327,-0.00251414899334088,-0.000391213617359187,0.25,3.79316360514512E-6,-0.000221700924219267,3.66429957685768E-6,349.9917603,349.9917603,73711.6796875,73721.7734375,56.3491632083906,20.4927640756635,29.742722,0,0,0,40,4449,350.44805,73716.7265625,,,,,,,,,,,,,0,,,,0.00245,,,,,,349.9917603,,,,
,27497885.62,349.992157,70425.8671875,-0.000209537519324537,1.64873403288576E-6,1,0.999253354069792,40.0298881530762,1.99677822619973,15.429999679327,-0.00237774214353353,-0.000336406247405963,0.25,6.47597732485828E-6,-0.000209169748346672,6.34918565127197E-6,349.992157,349.992157,70418.4296875,70433.3046875,56.4257628032752,20.4940015330517,29.363071,0,0,0,40,4449,350.4498,70425.8671875,,,,,,,,,,,,,0,,,,0,,,,,,349.992157,,,,
,27497950.915,349.9870605,67162.1328125,-0.00019865239017231,1.51875944879342E-6,1,0.999253354069792,40.0298881530762,1.99686426059319,15.429999679327,-0.00225581021802927,-0.000310310366910306,0.25,6.90447755988413E-6,-0.000198304176570087,6.78284672224606E-6,349.9870605,349.9870605,67154.8046875,67169.4609375,56.3882446343521,20.4933472572795,29.363071,0,0,0,40,4449,350.456,67162.1328125,,,,,,,,,,,,,0,,,,0.00245,,,,,,349.9870605,,,,
,27498016.625,349.9909363,63876.119140625,-0.000187189749778384,1.67624224373828E-6,1,0.999253354069792,40.0298881530762,1.99689419186523,15.429999679327,-0.00212430262259492,-0.000300338347942987,0.25,5.80366964046335E-6,-0.000186861214567487,5.69023410997323E-6,349.9909363,349.9909363,63871.08984375,63881.1484375,56.4976726270444,20.4945507838516,30.122374,0,0,0,40,4449,350.4628,63876.119140625,,,,,,,,,,,,,0,,,,-0.0049,,,,,,349.9909363,,,,
,27498082.525,349.9898987,60584.66796875,-0.000175936493967907,1.8157350661466E-6,1,0.999253354069792,40.0298881530762,1.99687499694515,15.429999679327,-0.0019924825225632,-0.000305933678332486,0.25,3.35933750766985E-6,-0.00017562655731104,3.25637357572431E-6,349.9898987,349.9898987,60582.06640625,60587.26953125,56.475787028506,20.4942691594353,29.363071,0,0,0,40,4449,350.4734,60584.66796875,,,,,,,,,,,,,0,,,,-0.0049,,,,,,349.9898987,,,,
,27498147.67,349.9824829,57325.75390625,-0.000163530286725847,1.50755409082519E-6,1,0.999253354069792,40.0298881530762,1.99691760768108,15.429999679327,-0.00185859096454192,-0.000246417560651824,0.25,6.4844183596264E-6,-0.000163244098083167,6.382702999229E-6,349.9824829,349.9824829,57318.453125,57333.0546875,56.445303516256,20.4938961748768,29.742722,0,0,0,40,4449,350.48555,57325.75390625,,,,,,,,,,,,,0,,,,0,,,,,,349.9824829,,,,
,27498213.03,349.9876404,54060.12109375,-0.000151390592166216,1.82799601945774E-6,1,0.999253354069792,40.0298881530762,1.9968587851327,15.429999679327,-0.00171941488860468,-0.000234786675223244,0.25,5.41232674028477E-6,-0.000151125294413327,5.31915472240517E-6,349.9876404,349.9876404,54050.21875,54070.0234375,56.3890262628713,20.4942458387678,29.742722,0,0,0,40,4449,350.48785,54060.12109375,,,,,,,,,,,,,0,,,,0,,,,,,349.9876404,,,,
,27498276.055,349.9909058,50911.751953125,-0.000140384870041772,1.52334429909155E-6,1,0.999253354069792,40.0298881530762,1.99678918128593,15.429999679327,-0.00159789535152755,-0.000197318351211316,0.25,6.82561289017009E-6,-0.000140139839522881,6.73596375230519E-6,349.9909058,349.9909058,50901.75390625,50921.75,56.5414438241214,20.4921166273932,30.122374,0,0,0,40,4449,350.48665,50911.751953125,,,,,,,,,,,,,0,,,,-0.00245,,,,,,349.9909058,,,,
,27498340.225,349.9919739,47703.001953125,-0.00012834299059981,1.9121411076908E-6,1,0.999253354069792,40.0298881530762,1.99702299163629,15.429999679327,-0.00145757625029496,-0.000200157127779054,0.25,4.49112496173536E-6,-0.000128118005532067,4.41221879772318E-6,349.9919739,349.9919739,47692.72265625,47713.28125,56.5414438241214,20.4895785872575,30.122374,0,0,0,40,4449,350.47355,47703.001953125,,,,,,,,,,,,,0,,,,-0.00245,,,,,,349.9919739,,,,
,27498407.295,349.9901123,44349.24609375,-0.000114895433069528,1.40996273732069E-6,1,0.999253354069792,40.0298881530762,1.99697875884574,15.429999679327,-0.00130925646627808,-0.000153595724721918,0.25,6.28714965767353E-6,-0.000114695280988603,6.21245866986407E-6,349.9901123,349.9901123,44344.15625,44354.3359375,56.5398805670829,20.4934028926159,30.122374,0,0,0,40,4449,350.5012,44349.24609375,,,,,,,,,,,,,0,,,,0,,,,,,349.9901123,,,,
,27498471.43,349.9899902,41143.6328125,-0.000105971322578563,1.83521244812027E-6,1,0.999253354069792,40.0298881530762,1.99703818056826,15.429999679327,-0.0012072061691869,-0.00014393693069769,0.25,5.59801219493027E-6,-0.000105786605188674,5.52944212480322E-6,349.9899902,349.9899902,41136.54296875,41150.72265625,56.4906379703714,20.4962544895562,29.742722,0,0,0,40,4449,350.4948,41143.6328125,,,,,,,,,,,,,0,,,,0.00245,,,,,,349.9899902,,,,
,27498534.45,349.9848938,37995.3984375,-9.21013027243601E-5,1.44465892623345E-6,1,0.999253354069792,40.0298881530762,1.99713121274227,15.429999679327,-0.0010460185163407,-0.000143756280189796,0.25,3.2130492632208E-6,-9.19398622766615E-5,3.15635442974019E-6,349.9848938,349.9848938,37992.92578125,37997.87109375,56.6563432164483,20.4951801186927,29.742722,0,0,0,40,4449,350.50345,37995.3984375,,,,,,,,,,,,,0,,,,-0.0049,,,,,,349.9848938,,,,
,27498599.665,349.9855347,34734.521484375,-8.25316180030531E-5,1.22242296083032E-6,1,0.999253354069792,40.0298881530762,1.99712893538815,15.429999679327,-0.000939754665772299,-0.000114827789631909,0.25,4.11861350724649E-6,-8.23876357291454E-5,4.0655871344868E-6,349.9855347,349.9855347,34729.5859375,34739.45703125,56.7259081546598,20.4967927831468,29.742722,0,0,0,40,4449,350.5138,34734.521484375,,,,,,,,,,,,,0,,,,-0.00245,,,,,,349.9855347,,,,
,27498663.935,349.9935913,31523.9033203125,-7.0773648635366E-5,1.0503616768032E-6,1,0.999253354069792,40.0298881530762,1.997119531784,15.429999679327,-0.000803090659086523,-0.00011450557810526,0.25,2.11125569425095E-6,-7.06493716357469E-5,2.06827880322628E-6,349.9935913,349.9935913,31516.583984375,31531.22265625,56.526592882256,20.4967840982023,29.742722,0,0,0,40,4449,350.5179,31523.9033203125,,,,,,,,,,,,,0,,,,0,,,,,,349.9935913,,,,
,27498726.32,349.99134825,28403.0849609375,-6.10167606121062E-5,1.06415264827423E-6,1,0.999253354069792,40.0298881530762,1.9971542722116,15.429999679327,-0.000694359114425969,-8.73360465462216E-5,0.25,2.82873635540884E-6,-6.09101796887202E-5,2.78987849698218E-6,349.9913025,349.991394,28398.044921875,28408.125,56.6782288149868,20.4968131483916,29.742722,0,0,0,40,4449,350.51965,28403.0849609375,,,,,,,,,,,,,0,,,,-0.0049,,,,,,349.99134825,,,,
,27498786.97,349.9899292,25374.1123046875,-4.86890752043421E-5,7.29795600481537E-7,1,0.999253354069792,40.0298881530762,1.99720029981775,15.429999679327,-0.000553280374221076,-7.43371722569799E-5,0.25,1.84581325731868E-6,-4.8603801262848E-5,1.81552162640621E-6,349.9899292,349.9899292,25364.1875,25384.037109375,56.5781803645252,20.4972395971333,30.122374,0,0,0,40,4449,350.5224,25374.1123046875,,,,,,,,,,,,,0,,,,0.00245,,,,,,349.9899292,,,,
,27498853.365,349.9896545,22055.64453125,-3.81705794153105E-5,9.71734240750986E-7,1,0.999253354069792,40.0298881530762,1.99716852598307,15.429999679327,-0.000435091210853491,-5.051025396768E-5,0.25,2.13503589763973E-6,-3.8104109480257E-5,2.11005790077199E-6,349.9896545,349.9896545,22050.6328125,22060.65625,56.6500901882945,20.4989422254757,29.742722,0,0,0,40,4449,350.5354,22055.64453125,,,,,,,,,,,,,0,,,,0,,,,,,349.9896545,,,,
,27498918.445,349.9789124,18803.029296875,-2.55190541544697E-5,9.53525770590801E-7,1,0.999253354069792,40.0298881530762,1.99716621061187,15.429999679327,-0.000291620510034269,-2.94995779465337E-5,0.25,1.80555547252982E-6,-2.54748346724859E-5,1.78817866308219E-6,349.9789124,349.9789124,18798.115234375,18807.943359375,56.7845302936022,20.4969479945077,29.742722,0,0,0,40,4449,350.5217,18803.029296875,,,,,,,,,,,,,0,,,,-0.0049,,,,,,349.9789124,,,,
,27498980.145,349.9930725,15717.076171875,-1.47784530683969E-5,7.67509177180361E-7,1,0.999253354069792,40.0298881530762,1.99719660037714,15.429999679327,-0.000169083368481423,-1.59325879768752E-5,0.25,1.14760621649608E-6,-1.47528945282148E-5,1.13735790632993E-6,349.9930725,349.9930725,15709.6298828125,15724.5224609375,56.607882248256,20.4971021963325,29.742722,0,0,0,40,4449,350.5267,15717.076171875,,,,,,,,,,,,,0,,,,-0.00245,,,,,,349.9930725,,,,
,27499045.875,349.9966125,12433.4921875,-4.96248060160174E-6,7.984081777786E-7,1,0.999253354069792,40.0298881530762,1.99723583233081,15.429999679327,-5.72139664948468E-5,-2.83132720727092E-6,0.25,6.08465545457993E-7,-4.95402173268019E-6,6.04627389647616E-7,349.9966125,349.9966125,12425.9501953125,12441.0341796875,56.7720242372945,20.4971633931569,30.122374,0,0,0,40,4449,350.53615,12433.4921875,,,,,,,,,,,,,0,,,,-0.00245,,,,,,349.9966125,,,,
,27499109.49,350.0012207,9253.27099609375,5.64791420810916E-6,7.07976548743718E-7,1,0.999253354069792,40.0298881530762,1.9972547825841,15.429999679327,6.1474938791542E-5,2.4257184999603E-5,0.25,1.17066731408011E-6,5.63724964783104E-6,1.17173382802603E-6,350.0012207,350.0012207,9248.201171875,9258.3408203125,56.8658196596022,20.4992620947678,30.122374,0,0,0,40,4449,350.5435,9253.27099609375,,,,,,,,,,,,,0,,,,0,,,,,,350.0012207,,,,
,27499173.47,349.9894714,6054.162109375,1.47440706775513E-5,4.34065536334544E-7,1,0.999253354069792,40.0298881530762,1.99737413474139,15.429999679327,0.000165795624590731,3.26955093913124E-5,0.25,3.42926093083364E-7,1.47177453711631E-5,3.50523785610919E-7,349.9894714,349.9894714,6049.11865234375,6059.20556640625,56.8869236296214,20.4981664500153,29.742722,0,0,0,40,4449,350.5561,6054.162109375,,,,,,,,,,,,,0,,,,0,,,,,,349.9894714,,,,
,27499236.44,349.9900818,2910.51611328125,2.01252520159482E-5,4.95318715951972E-7,1,0.999253354069792,40.0298881530762,1.99733320782356,15.429999679327,0.000227383317004941,3.83829240351826E-5,0.25,-8.5027924327679E-8,2.00896257934103E-5,-7.36725053996516E-8,349.9900818,349.9900818,2900.48266601562,2920.54956054687,56.7735874943329,20.4975064682145,30.122374,0,0,0,40,4449,350.5513,2910.51611328125,,,,,,,,,,,,,0,,,,0,,,,,,349.9900818,,,,
,27499298.42,349.9982605,-188.81217956543,-8.23478453122478E-6,4.68424266285119E-7,1,0.999253354069792,40.0298881530762,1.99744876039721,15.429999679327,-9.23837350919815E-5,-1.9525662532763E-5,0.25,-3.03483758484364E-7,-8.22001636477735E-6,-3.07531652152915E-7,349.9982605,349.9982605,-193.764068603516,-183.860290527344,56.8587850029291,20.4981309919671,29.742722,0,0,0,40,4449,350.5474,-188.81217956543,,,,,,,,,,,,,0,,,,0.0049,,,,,,349.9982605,,,,
,27499359.75,349.993988,-3249.63439941406,-1.96768686709492E-5,5.0995448248446E-7,1,0.999253354069792,40.0298881530762,1.99734472659832,15.429999679327,-0.000220901571656438,-4.57111184357026E-5,0.25,-6.41667413498326E-7,-1.9641630102919E-5,-6.51484606138882E-7,349.993988,349.993988,-3257.091796875,-3242.17700195313,56.9111541137176,20.4990641324985,30.122374,0,0,0,40,4449,350.55025,-3249.63439941406,,,,,,,,,,,,,0,,,,-0.00245,,,,,,349.993988,,,,
,27499421.615,349.9915161,-6344.95263671875,-1.3954556351051E-5,6.30344792608186E-7,1,0.999253354069792,40.0298881530762,1.9974127395392,15.429999679327,-0.000155053982234415,-4.17250065763369E-5,0.25,-1.27931580358081E-6,-1.39291084713218E-5,-1.28481378729862E-6,349.9915161,349.9915161,-6347.43505859375,-6342.47021484375,56.7876568076791,20.4982087917889,29.742722,0,0,0,40,4449,350.56325,-6344.95263671875,,,,,,,,,,,,,0,,,,0.0049,,,,,,349.9915161,,,,
,27499484.985,349.9980621,-9511.79736328125,-4.79001000344664E-6,6.68586797838102E-7,1,0.999253354069792,40.0298881530762,1.99742462624237,15.429999679327,-5.19007607002218E-5,-2.1963356489893E-5,0.25,-1.1158777023272E-6,-4.78089750090878E-6,-1.11656398261302E-6,349.9976196,349.9985046,-9541.775390625,-9481.8193359375,56.7345060683714,20.4988278794188,30.122374,0,0,0,40,4449,350.5615,-9511.79736328125,,,,,,,,,,,,,0,,,,0,,,,,,349.9980621,,,,
,27499549.94,350.0041809,-12757.404296875,6.01661249001091E-6,8.31785321788339E-7,1,0.999253354069792,40.0298881530762,1.99742280420252,15.429999679327,7.15907205188935E-5,-9.37177550321307E-6,0.25,-1.87182790557439E-6,6.00698582853913E-6,-1.86516377320687E-6,350.0041809,350.0041809,-12770.0654296875,-12744.7431640625,56.7939098358329,20.4988638472516,30.502024,0,0,0,40,4449,350.54995,-12757.404296875,,,,,,,,,,,,,0,,,,0,,,,,,350.0041809,,,,
,27499616.205,350.0007629,-16071.0893554687,1.65412471728273E-5,7.43192886335761E-7,1,0.999253354069792,40.0298881530762,1.99750407830577,15.429999679327,0.000190772434466009,9.21417250617476E-6,0.25,-2.04806081575871E-6,1.65130600435668E-5,-2.03523682294136E-6,350.0007629,350.0007629,-16078.4541015625,-16063.724609375,56.7360693254098,20.4996313681425,30.502024,0,0,0,40,4449,350.5373,-16071.0893554687,,,,,,,,,,,,,0,,,,0.00245,,,,,,350.0007629,,,,
,27499681.04,350.004425,-19311.701171875,2.82375261014658E-5,8.97982669178389E-7,1,0.999253354069792,40.0298881530762,1.99739157213488,15.429999679327,0.000322177397074979,3.57820797472759E-5,0.25,-1.72009183454331E-6,2.81884174301086E-5,-1.70135742014225E-6,350.004425,350.004425,-19321.470703125,-19301.931640625,56.8251749766022,20.499660609074,30.122374,0,0,0,40,4449,350.553,-19311.701171875,,,,,,,,,,,,,0,,,,0,,,,,,350.004425,,,,
,27499746.805,350.0135498,-22597.263671875,3.98850563365697E-5,1.46465738097378E-6,1,0.999253354069792,40.0298881530762,1.99734340201094,15.429999679327,0.000453467049393961,5.9739339873381E-5,0.25,-1.61482217712825E-6,3.98152266613989E-5,-1.5898157298262E-6,350.0135498,350.0135498,-22605.0625,-22589.46484375,56.8548768603329,20.501716074434,30.502024,0,0,0,40,4449,350.5473,-22597.263671875,,,,,,,,,,,,,0,,,,0.00245,,,,,,350.0135498,,,,
,27499815.58,350.0116577,-26032.2041015625,5.17664792168922E-5,1.0240293787342E-6,1,0.999253354069792,40.0298881530762,1.99727473171878,15.429999679327,0.000588789289756286,7.60455615884722E-5,0.25,-2.2275678335622E-6,5.16759247916585E-5,-2.1948942092424E-6,350.0116577,350.0116577,-26037.00390625,-26027.404296875,56.8400259184676,20.5016129426911,29.742722,0,0,0,40,4449,350.5329,-26032.2041015625,,,,,,,,,,,,,0,,,,0,,,,,,350.0116577,,,,
,27499881.815,350.0187683,-29343.716796875,6.34052510815686E-5,1.65038055666248E-6,1,0.999253354069792,40.0298881530762,1.99739111304421,15.429999679327,0.000720785337019968,9.55893966334832E-5,0.25,-2.5121609915278E-6,6.32942025868813E-5,-2.47254325394261E-6,350.0187683,350.0187683,-29351.091796875,-29336.341796875,56.7008960420445,20.5021151996462,30.502024,0,0,0,40,4449,350.5233,-29343.716796875,,,,,,,,,,,,,0,,,,0,,,,,,350.0187683,,,,
,27499949.51,350.0127563,-32729.16796875,7.46480902822517E-5,1.46198382007469E-6,1,0.999253354069792,40.0298881530762,1.99743235300072,15.429999679327,0.000849875615748461,0.000105230998626359,0.25,-3.60504821416075E-6,7.45177258131984E-5,-3.55728152182338E-6,350.0127563,350.0127563,-32734.44921875,-32723.88671875,56.7470121246791,20.5009536723226,30.502024,0,0,0,40,4449,350.5117,-32729.16796875,,,,,,,,,,,,,0,,,,0,,,,,,350.0127563,,,,
,27500016.19,350.0179443,-36062.20703125,8.62566650259305E-5,1.64711482966622E-6,1,0.999253354069792,40.0298881530762,1.99747884004672,15.429999679327,0.000978419995456443,0.000142632213615639,0.25,-2.30273224715016E-6,8.6104981257145E-5,-2.25086951660703E-6,350.0179443,350.0179443,-36071.99609375,-36052.41796875,56.9619599674676,20.4991792170244,30.502024,0,0,0,40,4449,350.5167,-36062.20703125,,,,,,,,,,,,,0,,,,0.00245,,,,,,350.0179443,,,,
,27500084.57,350.0045166,-39477.185546875,9.80279202937728E-5,2.00332013382032E-6,1,0.999253354069792,40.0298881530762,1.99744733189643,15.429999679327,0.00110954620978122,0.000175842168065204,0.25,-1.39934860830128E-6,9.78549086265236E-5,-1.34260241037988E-6,350.0045166,350.0045166,-39479.484375,-39474.88671875,56.9674313671022,20.5007163562099,30.881676,0,0,0,40,4449,350.5192,-39477.185546875,,,,,,,,,,,,,0,,,,0,,,,,,350.0045166,,,,
,27500152.235,350.0067444,-42860.76953125,0.000112470399727741,1.43311345475446E-6,1,0.999253354069792,40.0298881530762,1.99752249688988,15.429999679327,0.00127462157390768,0.000192746738645772,0.25,-2.40340506293112E-6,0.000112272333444974,-2.33692107443268E-6,350.0067444,350.0067444,-42868.24609375,-42853.29296875,56.8290831191983,20.5006147857321,30.122374,0,0,0,40,4449,350.5086,-42860.76953125,,,,,,,,,,,,,0,,,,0,,,,,,350.0067444,,,,
,27500219.54,350.00935365,-46224.478515625,0.000125640522028556,2.02377845380362E-6,1,0.999253354069792,40.0298881530762,1.99745179859443,15.429999679327,0.00142163681496334,0.000227974872676155,0.25,-1.56308235110602E-6,0.00012541863346745,-1.49084429882381E-6,350.0090637,350.0096436,-46231.89453125,-46217.0625,56.607882248256,20.5012835869843,30.502024,0,0,0,40,4449,350.5003,-46224.478515625,,,,,,,,,,,,,0,,,,0.0049,,,,,,350.00935365,,,,
,27500287.07,350.01373295,-49597.66015625,0.000137809266575337,1.63690794476484E-6,1,0.999253354069792,40.0298881530762,1.99736211360462,15.429999679327,0.00156248664013923,0.000231412098265676,0.25,-3.36470921532822E-6,0.000137566781805482,-3.28259704400193E-6,350.0129395,350.0145264,-49630.171875,-49565.1484375,56.994006736756,20.5014624343917,30.122374,0,0,0,40,4449,350.4976,-49597.66015625,,,,,,,,,,,,,0,,,,-0.00245,,,,,,350.01373295,,,,
,27500356.1,350.0091553,-53050.125,0.000147560488769061,2.49765784163386E-6,1,0.999253354069792,40.0298881530762,1.99737139930976,15.429999679327,0.00167409787966647,0.000241759239798425,0.25,-4.13668719253367E-6,0.000147301166281471,-4.04787032688525E-6,350.0091553,350.0091553,-53057.43359375,-53042.81640625,56.8830154870253,20.5010324378884,30.502024,0,0,0,40,4449,350.48365,-53050.125,,,,,,,,,,,,,0,,,,0,,,,,,350.0091553,,,,
,27500424.81,350.0222168,-56483.33203125,0.000160677940091549,2.26134326506765E-6,1,0.999253354069792,40.0298881530762,1.99737448401461,15.429999679327,0.00181871946028339,0.00028750756142922,0.25,-2.35591553620446E-6,0.000160394311286525,-2.26306944412076E-6,350.0222168,350.0222168,-56490.7734375,-56475.890625,56.953362053756,20.5018353885973,30.502024,0,0,0,40,4449,350.47695,-56483.33203125,,,,,,,,,,,,,0,,,,-0.00245,,,,,,350.0222168,,,,
,27500493.35,350.0144653,-59909.29296875,0.000174442381046889,2.14289003360429E-6,1,0.999253354069792,40.0298881530762,1.99741289645211,15.429999679327,0.0019783949482286,0.000289973589966605,0.25,-4.52117131277433E-6,0.000174135587478228,-4.41695415730296E-6,350.0144653,350.0144653,-59914.359375,-59904.2265625,56.6547799594098,20.503073524961,30.881676,0,0,0,40,4449,350.46805,-59909.29296875,,,,,,,,,,,,,0,,,,0,,,,,,350.0144653,,,,
,27500560.115,350.0166321,-63245.291015625,0.000186382323495733,2.32167717877288E-6,1,0.999253354069792,40.0298881530762,1.99749444598868,15.429999679327,0.00211041098858821,0.000329932561379663,0.25,-3.05045137073531E-6,0.000186053539514923,-2.94232268299767E-6,350.0166321,350.0166321,-63252.73828125,-63237.84375,57.0033862789868,20.5001909873074,30.881676,0,0,0,40,4449,350.4571,-63245.291015625,,,,,,,,,,,,,0,,,,0,,,,,,350.0166321,,,,
,27500627.07,350.0143433,-66590.1171875,0.000197186140002692,1.9029620140623E-6,1,0.999253354069792,40.0298881530762,1.99749802296733,15.429999679327,0.00223508972264074,0.000335526851840772,0.25,-4.42559887255142E-6,0.000196838977263227,-4.30915127334218E-6,350.0143433,350.0143433,-66595.1875,-66585.046875,56.882233858506,20.5031990463169,30.502024,0,0,0,40,4449,350.4554,-66590.1171875,,,,,,,,,,,,,0,,,,-0.00245,,,,,,350.0143433,,,,
,27500692.61,350.0141296,-69865.7890625,0.000209614503980587,2.4662818112042E-6,1,0.999253354069792,40.0298881530762,1.9974966506028,15.429999679327,0.00237813951538463,0.000344102601759294,0.25,-5.81789682231645E-6,0.000209246078226052,-5.69220948158353E-6,350.0141296,350.0141296,-69873.2578125,-69858.3203125,56.750138638756,20.5018539119557,30.502024,0,0,0,40,4449,350.4436,-69865.7890625,,,,,,,,,,,,,0,,,,-0.00245,,,,,,350.0141296,,,,
,27500759.805,350.0122986,-73223.7109375,0.000221948853218166,2.41947326777532E-6,1,0.999253354069792,40.0298881530762,1.99743179592002,15.429999679327,0.00250975960171087,0.000411923884211857,0.25,-1.94566691886991E-6,0.000221556447590365,-1.82013791797721E-6,350.0122986,350.0122986,-73226.2421875,-73221.1796875,56.9385111118906,20.5034786492824,30.502024,0,0,0,40,4449,350.43575,-73223.7109375,,,,,,,,,,,,,0,,,,-0.00245,,,,,,350.0122986,,,,
,27500828.93,350.0093384,-76679.171875,0.00023570897369827,2.22075279025653E-6,1,0.999253354069792,40.0298881530762,1.99746715047837,15.429999679327,0.00266472459720938,0.000441381926273477,0.25,-1.71967082255466E-6,0.000235292079206968,-1.5870650850754E-6,350.0093384,350.0093384,-76689.21875,-76669.125,56.9119357422368,20.5043844626303,30.502024,0,0,0,40,4449,350.42955,-76679.171875,,,,,,,,,,,,,0,,,,0.0049,,,,,,350.0093384,,,,
,27500898.875,350.0111084,-80174.4453125,0.000247188611348458,2.50834128358481E-6,1,0.999253354069792,40.0298881530762,1.99743544090333,15.429999679327,0.00279630885286566,0.000452199870790161,0.25,-2.74847789369046E-6,0.000246751924043007,-2.60783837862557E-6,350.0111084,350.0111084,-80182.0625,-80166.828125,56.9775925378522,20.5025086120409,30.502024,0,0,0,40,4449,350.43015,-80174.4453125,,,,,,,,,,,,,0,,,,0,,,,,,350.0111084,,,,
,27500965.32,350.0202942,-83495.09765625,0.000259121447439311,2.75276769770851E-6,1,0.999253354069792,40.0298881530762,1.99739108971725,15.429999679327,0.00293727130494981,0.000439159096389197,0.25,-5.96863878202925E-6,0.000258665299755101,-5.81583035164895E-6,350.0202942,350.0202942,-83500,-83490.1953125,56.8525319747752,20.5045834102583,30.122374,0,0,0,40,4449,350.4183,-83495.09765625,,,,,,,,,,,,,0,,,,0.0049,,,,,,350.0202942,,,,
,27501031.435,350.0230103,-86800.5078125,0.00027230908590685,2.88476775948891E-6,1,0.999253354069792,40.0298881530762,1.99738215927054,15.429999679327,0.00308048066409865,0.000497695727906419,0.25,-3.0670932725159E-6,0.000271827945074697,-2.9122880575447E-6,350.0230103,350.0230103,-86808.109375,-86792.90625,56.8830154870253,20.5059679780963,30.502024,0,0,0,40,4449,350.3993,-86800.5078125,,,,,,,,,,,,,0,,,,0,,,,,,350.0230103,,,,
,27501096.66,350.01576235,-89999.54296875,0.000280831126773703,2.86407410241126E-6,1,0.999253354069792,40.0298881530762,1.99730572067576,15.429999679327,0.00317563838890414,0.000519791823257491,0.25,-2.58377638298173E-6,0.000280334686624146,-2.42526550714264E-6,350.0154114,350.0161133,-89999.5546875,-89999.53125,56.8071975206598,20.5046248374789,30.502024,0,0,0,40,4417,350.4124,-89999.54296875,,,,,,,,,,,,,0,,,,0.00245,,,,,,350.01576235,,,,
,27501178.815,350.00698855,-86839.57421875,0.000273140375243099,2.18802551381397E-6,1,0.999253354069792,40.0298881530762,1.99734572553402,15.429999679327,0.00309330662288934,0.000479141330886786,0.25,-4.85368102201028E-6,0.000272658888329647,-4.69525747620681E-6,350.0062256,350.0077515,-86844.53125,-86834.6171875,56.9572701963522,20.5056432721622,30.502024,0,0,0,40,4449,350.40315,-86839.57421875,,,,,,,,,,,,,0,,,,-0.00245,,,,,,350.00698855,,,,
,27501244.66,350.0051575,-83546.42578125,0.000260458745299476,2.49609827048135E-6,1,0.999253354069792,40.0298881530762,1.99736419191586,15.429999679327,0.00294052542529644,0.000509966770502896,0.25,7.18194909497365E-8,0.000259997043478014,2.14661624539235E-7,350.0051575,350.0051575,-83551.328125,-83541.5234375,56.8478422036599,20.5063177325584,30.881676,0,0,0,40,4449,350.39075,-83546.42578125,,,,,,,,,,,,,0,,,,-0.00245,,,,,,350.0051575,,,,
,27501314.485,349.996521,-80058.02734375,0.000245654639908422,2.48668509277691E-6,1,0.999253354069792,40.0298881530762,1.99737902267099,15.429999679327,0.00278046255805889,0.000440255037301947,0.25,-3.53980086288714E-6,0.000245221226427891,-3.39858499644713E-6,349.996521,349.996521,-80063.140625,-80052.9140625,56.882233858506,20.5045266667488,30.881676,0,0,0,40,4449,350.39155,-80058.02734375,,,,,,,,,,,,,0,,,,0.00245,,,,,,349.996521,,,,
,27501381.735,349.9952087,-76697.59375,0.000232334345731822,2.02176752039465E-6,1,0.999253354069792,40.0298881530762,1.9973762058978,15.429999679327,0.0026284484836907,0.000423565468935166,0.25,-2.71172249053339E-6,0.000231924088917478,-2.57920483042628E-6,349.9952087,349.9952087,-76705.046875,-76690.140625,56.9682129956214,20.505599215344,30.502024,0,0,0,40,4449,350.4016,-76697.59375,,,,,,,,,,,,,0,,,,0,,,,,,349.9952087,,,,
,27501448.845,349.9943237,-73344.57421875,0.000222817957872505,2.90856467653053E-6,1,0.999253354069792,40.0298881530762,1.99738766199822,15.429999679327,0.00251798948482819,0.000422458539957919,0.25,-1.16234790787593E-6,0.000222423715401356,-1.03772425649465E-6,349.9943237,349.9943237,-73352.15625,-73336.9921875,56.8032893780637,20.5044376384004,30.881676,0,0,0,40,4449,350.4093,-73344.57421875,,,,,,,,,,,,,0,,,,-0.00245,,,,,,349.9943237,,,,
,27501518.22,349.9954224,-69873.94921875,0.000211020051317722,2.31444988795076E-6,1,0.999253354069792,40.0298881530762,1.99742771388206,15.429999679327,0.00238766037402901,0.000383062610323594,0.25,-2.60965171325315E-6,0.000210647500281355,-2.48886765463771E-6,349.9954224,349.9954224,-69884.265625,-69863.6328125,56.7657712091406,20.5048348924981,30.502024,0,0,0,40,4449,350.40395,-69873.94921875,,,,,,,,,,,,,0,,,,-0.00245,,,,,,349.9954224,,,,
,27501585.65,349.9966431,-66508.67578125,0.000197936098295113,1.94782349436889E-6,1,0.999253354069792,40.0298881530762,1.99739826608271,15.429999679327,0.00224210630694255,0.000344748837361905,0.25,-3.73727565497101E-6,0.000197587344266249,-3.62162295557965E-6,349.9966431,349.9966431,-66516.0703125,-66501.28125,56.8157954343714,20.5037671312686,30.122374,0,0,0,40,4449,350.4133,-66508.67578125,,,,,,,,,,,,,0,,,,-0.0049,,,,,,349.9966431,,,,
,27501655.005,349.9934692,-63040.83984375,0.000185301554236224,2.00395470261021E-6,1,0.999253354069792,40.0298881530762,1.99733512984409,15.429999679327,0.0020978097421968,0.000329182083989633,0.25,-2.92760657238626E-6,0.000184974762781914,-2.82027820958464E-6,349.9934692,349.9934692,-63048.20703125,-63033.47265625,56.963523224506,20.5049281760749,31.261326,0,0,0,40,4449,350.418,-63040.83984375,,,,,,,,,,,,,0,,,,-0.0049,,,,,,349.9934692,,,,
,27501720.65,349.9902344,-59759.986328125,0.000174394766839207,1.81305399930005E-6,1,0.999253354069792,40.0298881530762,1.99730181550571,15.429999679327,0.00197381561130039,0.000312611397310399,0.25,-2.50647781304545E-6,0.000174087088410057,-2.40584675408145E-6,349.9902344,349.9902344,-59764.87109375,-59755.1015625,56.7110572127945,20.5043545704049,30.881676,0,0,0,40,4449,350.4258,-59759.986328125,,,,,,,,,,,,,0,,,,0,,,,,,349.9902344,,,,
,27501786.29,349.9910889,-56479.0703125,0.000161014665164106,1.98913052546198E-6,1,0.999253354069792,40.0298881530762,1.99732616895841,15.429999679327,0.00182399176717577,0.000279434343972463,0.25,-3.12874155783347E-6,0.000160731034031306,-3.03432674052159E-6,349.9910889,349.9910889,-56481.5859375,-56476.5546875,56.7141837268714,20.5034890773224,30.881676,0,0,0,40,4449,350.4141,-56479.0703125,,,,,,,,,,,,,0,,,,0,,,,,,349.9910889,,,,
,27501852.42,349.9898071,-53173.5703125,0.000147737914037563,2.07374118827449E-6,1,0.999253354069792,40.0298881530762,1.99755513103829,15.429999679327,0.00168048696531294,0.000217653122390881,0.25,-6.30422687414811E-6,0.000147479570135737,-6.21146508760192E-6,349.9898071,349.9898071,-53178.640625,-53168.5,56.8892685151791,20.4998084959877,30.881676,0,0,0,40,4449,350.43895,-53173.5703125,,,,,,,,,,,,,0,,,,0,,,,,,349.9898071,,,,
,27501919.075,349.9872437,-49843.45703125,0.000135960946591643,1.77430470552608E-6,1,0.999253354069792,40.0298881530762,1.99743598868056,15.429999679327,0.0015428936544394,0.000220764965396568,0.25,-3.98843005445993E-6,0.000135722204707213,-3.90622585858855E-6,349.9872437,349.9872437,-49851.05859375,-49835.85546875,56.9932251082368,20.5017598153852,31.261326,0,0,0,40,4449,350.42865,-49843.45703125,,,,,,,,,,,,,0,,,,0,,,,,,349.9872437,,,,
,27501986.95,349.986145,-46450.48046875,0.000124648467698705,1.92834982312644E-6,1,0.999253354069792,40.0298881530762,1.99747065161194,15.429999679327,0.00141003191740752,0.000228449608526224,0.25,-1.34947149353713E-6,0.000124428316967019,-1.27815288861673E-6,349.986145,349.986145,-46462.58984375,-46438.37109375,56.8556584888522,20.5007674289807,30.881676,0,0,0,40,4449,350.4393,-46450.48046875,,,,,,,,,,,,,0,,,,0,,,,,,349.986145,,,,
,27502055.555,349.9947205,-43021.71875,0.00011321346342271,1.71769652404117E-6,1,0.999253354069792,40.0298881530762,1.99735736081904,15.429999679327,0.0012856657411736,0.00017827398093589,0.25,-3.81261090674862E-6,0.000113014904966667,-3.74320954625852E-6,349.9947205,349.9947205,-43029.01953125,-43014.41796875,56.9119357422368,20.5013126163922,30.881676,0,0,0,40,4449,350.4439,-43021.71875,,,,,,,,,,,,,0,,,,-0.00245,,,,,,349.9947205,,,,
,27502122.21,349.9857788,-39688.208984375,0.000101012297571276,1.13342099052761E-6,1,0.999253354069792,40.0298881530762,1.9973516415186,15.429999679327,0.00114413450275009,0.000176216764823929,0.25,-1.88221204426501E-6,0.000100834325982766,-1.82295302348233E-6,349.9852295,349.9863281,-39695.390625,-39681.02734375,56.9220969129868,20.5019088124313,31.261326,0,0,0,40,4449,350.4677,-39688.208984375,,,,,,,,,,,,,0,,,,-0.00245,,,,,,349.9857788,,,,
,27502189.495,349.9801941,-36328.2890625,8.79097997762188E-5,1.39816155122507E-6,1,0.999253354069792,40.0298881530762,1.99725277377544,15.429999679327,0.000997923386055355,0.000140394318100822,0.25,-2.7858504224629E-6,8.77555638953552E-5,-2.73221348117698E-6,349.9801941,349.9801941,-36333.359375,-36323.21875,56.8728543162753,20.5045466250742,30.881676,0,0,0,40,4449,350.4608,-36328.2890625,,,,,,,,,,,,,0,,,,0,,,,,,349.9801941,,,,
,27502253.505,349.9854431,-33127.958984375,7.64314446256938E-5,1.46323684272739E-6,1,0.999253354069792,40.0298881530762,1.99721486034521,15.429999679327,0.000870066859109011,0.000107865504600322,0.25,-3.679517117716E-6,7.6298029675334E-5,-3.6306310618525E-6,349.9854431,349.9854431,-33130.29296875,-33125.625,57.0096393071407,20.5033760756251,30.502024,0,0,0,40,4449,350.4676,-33127.958984375,,,,,,,,,,,,,0,,,,0.00245,,,,,,349.9854431,,,,
,27502319.735,349.987854,-29819.2431640625,6.5203459768914E-5,8.66163968420516E-7,1,0.999253354069792,40.0298881530762,1.9972334827845,15.429999679327,0.00074126717320794,9.77443375472273E-5,0.25,-2.63201329597527E-6,6.50893568222296E-5,-2.59118706513719E-6,349.987854,349.987854,-29826.65625,-29811.830078125,56.8884868866599,20.5030667651523,31.261326,0,0,0,40,4449,350.4797,-29819.2431640625,,,,,,,,,,,,,0,,,,0,,,,,,349.987854,,,,
,27502384.935,349.9860535,-26558.7451171875,5.29529044607999E-5,1.04916268436832E-6,1,0.999253354069792,40.0298881530762,1.99714288657617,15.429999679327,0.000599386037807635,9.43021092796259E-5,0.25,-8.15400484529642E-7,5.28595083771815E-5,-7.84571146823051E-7,349.9860535,349.9860535,-26563.626953125,-26553.86328125,57.0088576786214,20.5049332625549,31.261326,0,0,0,40,4449,350.47565,-26558.7451171875,,,,,,,,,,,,,0,,,,0.00245,,,,,,349.9860535,,,,
,27502451.375,349.9841614,-23240.6640625,4.14710421599061E-5,8.75091524612795E-7,1,0.999253354069792,40.0298881530762,1.99721612492886,15.429999679327,0.000469720831199239,7.22158558585374E-5,0.25,-7.83977566237249E-7,4.13979800003571E-5,-7.59564418709008E-7,349.9841614,349.9841614,-23245.369140625,-23235.958984375,56.9588334533906,20.5020280201465,31.261326,0,0,0,40,4449,350.50525,-23240.6640625,,,,,,,,,,,,,0,,,,0.00245,,,,,,349.9841614,,,,
,27502517.85,349.9868164,-19917.697265625,2.92410560807211E-5,1.20799815694825E-6,1,0.999253354069792,40.0298881530762,1.99722700277144,15.429999679327,0.000333922059844023,3.51976746851244E-5,0.25,-1.94537160638955E-6,2.91903106914468E-5,-1.92568042051242E-6,349.9868164,349.9868164,-19927.81640625,-19907.578125,56.912717370756,20.5026086938526,31.261326,0,0,0,40,4449,350.49455,-19917.697265625,,,,,,,,,,,,,0,,,,0,,,,,,349.9868164,,,,
,27502584.09,349.9904633,-16606.953125,1.87201245589695E-5,8.81886128498224E-7,1,0.999253354069792,40.0298881530762,1.99712798904841,15.429999679327,0.000212093401197668,3.21967261600409E-5,0.25,-3.89359251467298E-7,1.86871592391038E-5,-3.78265147152994E-7,349.9900208,349.9909058,-16619.365234375,-16594.541015625,56.8071975206598,20.5032729136621,31.640976,0,0,0,40,4449,350.50945,-16606.953125,,,,,,,,,,,,,0,,,,0,,,,,,349.9904633,,,,
,27502651.43,349.996521,-13240.92578125,7.47508762799797E-6,6.87710656393344E-7,1,0.999253354069792,40.0298881530762,1.9971845370826,15.429999679327,8.70263952040838E-5,-6.206869134267E-7,0.25,-1.34929454696207E-6,7.46258650540865E-6,-1.3427460587239E-6,349.996521,349.996521,-13245.8701171875,-13235.9814453125,56.7087123272368,20.5020163585036,30.881676,0,0,0,40,4449,350.507,-13240.92578125,,,,,,,,,,,,,0,,,,-0.0049,,,,,,349.996521,,,,
,27502718.29,349.9952393,-9900.57861328125,-4.08496116753025E-6,6.32091425224272E-7,1,0.999253354069792,40.0298881530762,1.99723831658509,15.429999679327,-4.45278675715054E-5,-1.71672522480758E-5,0.25,-8.13306506148772E-7,-4.07726721010902E-6,-8.14137328018761E-7,349.9952393,349.9952393,-9908.09375,-9893.0634765625,56.8611298884868,20.5044041601939,30.881676,0,0,0,40,4449,350.50125,-9900.57861328125,,,,,,,,,,,,,0,,,,0.0049,,,,,,349.9952393,,,,
,27502784.43,349.99014285,-6593.94091796875,-1.2854932817411E-5,5.87848187691434E-7,1,0.999253354069792,40.0298881530762,1.99733637233604,15.429999679327,-0.000143824273004945,-3.26961527577058E-5,0.25,-6.70140892067699E-7,-1.28317736241092E-5,-6.76107692617304E-7,349.9900818,349.9902039,-6598.90576171875,-6588.97607421875,56.8705094307176,20.5012255894487,31.640976,0,0,0,40,4449,350.507,-6593.94091796875,,,,,,,,,,,,,0,,,,0,,,,,,349.99014285,,,,
,27502850.015,349.9945679,-3315.09802246094,-1.89520720318711E-5,5.12811027949678E-7,1,0.999253354069792,40.0298881530762,1.9974648817189,15.429999679327,-0.000213366918798832,-4.06222352214241E-5,0.25,-3.16225007186749E-7,-1.89182990238265E-5,-3.26216724244724E-7,349.9945679,349.9945679,-3325.20556640625,-3304.99047851562,56.8533136032945,20.4995534200209,30.881676,0,0,0,40,4449,350.50945,-3315.09802246094,,,,,,,,,,,,,0,,,,-0.00245,,,,,,349.9945679,,,,
,27502912.88,349.9913635,-170.341384887695,-8.85618542860817E-6,4.34579626925318E-7,1,0.999253354069792,40.0298881530762,1.99741570234188,15.429999679327,-9.91328602398633E-5,-2.22730715887E-5,0.25,-4.39249915608108E-7,-8.84024199356983E-6,-4.43403774249071E-7,349.9913635,349.9913635,-180.267562866211,-160.41520690918,56.8798889729483,20.4994711838733,31.261326,0,0,0,40,4449,350.51165,-170.341384887695,,,,,,,,,,,,,0,,,,0.00245,,,,,,349.9913635,,,,
,27502956.985,349.9954224,2029.49267578125,2.0357180578459E-5,4.58507394865159E-7,1,0.999253354069792,40.0298881530762,1.99760992552025,15.429999679327,0.000230465427735402,3.63393911504413E-5,0.25,-3.06615191691998E-7,2.03212628077697E-5,-2.94735577928984E-7,349.9954224,349.9954224,2019.48657226562,2039.49877929687,56.9119357422368,20.4959666615345,31.261326,0,0,0,40,4449,350.5146,2029.49267578125,,,,,,,,,,,,,0,,,,-0.00245,,,,,,349.9954224,,,,