File: data/monolayers/nanoparticles/Ac_CoFe_C/vsm/rawdata/DD226_2_HYST_10K.DAT
[Header]
; VSM Data File (default extension .dat)
; Copyright (c) 2003-2013, Quantum Design, Inc. All rights reserved.
TITLE,
FILEOPENTIME,27281182.36,11/13/2018,2:06 am
BYAPP,VSM,2.0,2.0
INFO,PPMS VSM Option Release 1.4.10 Build 1,APPNAME
INFO,Quantum Design Linear Motor Servo Controller,MOTOR_MODULE_NAME
INFO,3101-100 M1,MOTOR_HW_VERSION
INFO,MMC1014,MOTOR_SERIAL_NUMBER
INFO,SRV No X-over 01.03.11,MOTOR_SOFTWARE_VERSION
INFO,Quantum Design VSM Detection Module,VSM_MODULE_NAME
INFO,3101-150 F0,VSM_HW_VERSION
INFO,VSM707,VSM_SERIAL_NUMBER
INFO,VSM No X-over 01.02.05 May 20 2008 13:51:47,VSM_SOFTWARE_VERSION
INFO,704,PREAMP_SERIAL_NUMBER
INFO,822,COIL_SERIAL_NUMBER
INFO,0,MOMENT_UNITS
INFO,CoFe2O4 AH11,SAMPLE_MATERIAL
INFO,Quick Dry Monolayer Conc,SAMPLE_COMMENT
INFO,27.96,SAMPLE_MASS
INFO,,SAMPLE_VOLUME
INFO,,SAMPLE_MOLECULAR_WEIGHT
INFO,,SAMPLE_SIZE
INFO,,SAMPLE_SHAPE
DATATYPE,COMMENT,1
DATATYPE,TIME,2
STARTUPAXIS,X,2
STARTUPAXIS,Y1,5
[Data]
Comment,Time Stamp (sec),Temperature (K),Magnetic Field (Oe),Moment (emu),M. Std. Err. (emu),Transport Action,Averaging Time (sec),Frequency (Hz),Peak Amplitude (mm),Center Position (mm),Coil Signal' (mV),Coil Signal" (mV),Range (mV),M. Quad. Signal (emu),M. Raw' (emu),M. Raw" (emu),Min. Temperature (K),Max. Temperature (K),Min. Field (Oe),Max. Field (Oe),Mass (grams),Motor Lag (deg),Pressure (Torr),VSM Status (code),Motor Status (code),Measure Status (code),Measure Count,PPMS Status (code),System Temp. (K),System Field (Oe),Sample Position (deg),Bridge 1 Resistance (ohms),Bridge 1 Excitation (에),Bridge 2 Resistance (ohms),Bridge 2 Excitation (에),Bridge 3 Resistance (ohms),Bridge 3 Excitation (에),Bridge 4 Resistance (ohms),Bridge 4 Excitation (에),Signal 1 Vin (V),Signal 2 Vin (V),Digital Inputs (code),Drive 1 Iout (mA),Drive 1 Ipower (W),Drive 2 Iout (mA),Drive 2 Ipower (W),Pressure (),Map 20 (),Map 21 (),Map 22 (),Map 23 (),Map 24 (),Map 25 (),Map 26 (),Map 27 (),Map 28 (),Map 29 ()
sample offset = 34.78 mm touchdown = 19.0999992191792 mm,27281237.995,10.0054188,-0.129402078688145,3.56907346771063E-7,2.99191356059699E-7,1,0.999253354069792,40.0298881530762,1.9977830542496,25.4800003021955,4.45109328418106E-6,-1.7638456598758E-6,0.25,-2.20312490938621E-7,3.55918951925316E-7,-2.17326617228773E-7,10.0054188,10.0054188,-0.152237743139267,-0.106566414237022,56.1092032529867,20.5913892835581,13.797379,0,0,0,40,4417,10.0006,-0.129402078688145,,,,,,,,,,,,,0,,,,0.00245,,,,,,10.0054188,,,,
,27281354.945,10.0071774,4805.20483398438,1.54247453454176E-6,2.99399437378893E-7,1,0.999253354069792,40.0298881530762,1.99687953784859,25.4800003021955,1.83812280591958E-5,-2.81229520299613E-6,0.25,-5.24643990403651E-7,1.53670286193759E-6,-5.1388045595162E-7,10.0071774,10.0071774,4800.15966796875,4810.25,56.472660514429,20.612366223461,13.417728,0,0,0,40,4449,9.9976,4805.20483398438,,,,,,,,,,,,,0,,,,-0.0049,,,,,,10.0071774,,,,
,27281454.77,10.0094252,9796.67626953125,2.54379125416973E-6,3.7647084073992E-7,1,0.999253354069792,40.0298881530762,1.99655195633514,25.4800003021955,2.86458740906886E-5,4.77475138291629E-6,0.25,-2.85856260118776E-8,2.53094678539505E-6,-1.45021537838942E-8,10.0094252,10.0094252,9791.6884765625,9801.6640625,56.6844818431406,20.6233147138204,13.797379,0,0,0,40,4449,9.9961,9796.67626953125,,,,,,,,,,,,,0,,,,0.0049,,,,,,10.0094252,,,,
,27281553.475,10.0047255,14726.6274414062,4.09269506766505E-6,4.79296849218095E-7,1,0.999253354069792,40.0298881530762,1.9962989452465,25.4800003021955,4.69308751973186E-5,3.04646796300428E-6,0.25,-4.60042657256501E-7,4.07618558565339E-6,-4.33991744116386E-7,10.0047255,10.0047255,14719.08203125,14734.1728515625,57.0127658212176,20.6268463803487,14.177031,0,0,0,40,4449,9.9845,14726.6274414062,,,,,,,,,,,,,0,,,,0.00245,,,,,,10.0047255,,,,
,27281650.59,10.005374,19581.7080078125,6.16294939663875E-6,3.7735331684034E-7,1,0.999253354069792,40.0298881530762,1.99604992035231,25.4800003021955,7.084261592554E-5,3.77568057410057E-6,0.25,-7.67164971333862E-7,6.14157400227513E-6,-7.25890416718425E-7,10.005374,10.005374,19571.810546875,19591.60546875,57.2425646058714,20.6322555273303,13.417728,0,0,0,40,4449,9.9823,19581.7080078125,,,,,,,,,,,,,0,,,,0,,,,,,10.005374,,,,
,27281746.85,10.0027399,24391.5986328125,9.16664752636919E-6,7.2085459170227E-7,1,0.999253354069792,40.0298881530762,1.99619886070843,25.4800003021955,0.00010445060028609,1.10937072474282E-5,0.25,-6.57188363895432E-7,9.13644204190924E-6,-5.95441098736828E-7,10.0027399,10.0027399,24389.234375,24393.962890625,56.6414922745829,20.6262660477922,13.417728,0,0,0,40,4449,9.98005,24391.5986328125,,,,,,,,,,,,,0,,,,0,,,,,,10.0027399,,,,
,27281843.01,10.0023251,29199.5576171875,1.18318480256874E-5,7.13588764942931E-7,1,0.999253354069792,40.0298881530762,1.99617649570473,25.4800003021955,0.000135880663956364,8.79748127885897E-6,0.25,-1.34256029255269E-6,1.1802276893414E-5,-1.25860707409837E-6,10.0023251,10.0023251,29192.208984375,29206.90625,57.1831608384099,20.6285331084309,13.417728,0,0,0,40,4449,9.9754,29199.5576171875,,,,,,,,,,,,,0,,,,0.00245,,,,,,10.0023251,,,,
,27281939.445,10.0014019,34019.431640625,1.39899205193701E-5,9.02808421894589E-7,1,0.999253354069792,40.0298881530762,1.996223159857,25.4800003021955,0.000159292448652562,1.85405687061206E-5,0.25,-8.68268231022057E-7,1.39574198618394E-5,-7.68735028650835E-7,10.0014019,10.0014019,34009.3515625,34029.51171875,56.9244417985445,20.6308769266713,13.417728,0,0,0,40,4449,9.976,34019.431640625,,,,,,,,,,,,,0,,,,-0.00245,,,,,,10.0014019,,,,
,27282036.555,9.9988737,38871.7734375,1.47415070634861E-5,9.19679862114804E-7,1,0.999253354069792,40.0298881530762,1.9959869698885,25.4800003021955,0.00016804779744684,1.88341503996841E-5,0.25,-9.80576086704159E-7,1.47154829193236E-5,-8.73402393362964E-7,9.9988737,9.9988737,38866.8203125,38876.7265625,57.1323549846599,20.6371281397297,13.797379,0,0,0,40,4449,9.97625,38871.7734375,,,,,,,,,,,,,0,,,,0,,,,,,9.9988737,,,,
,27282130.83,9.9984932,43584.55078125,1.56064263320265E-5,8.86886754193786E-7,1,0.999253354069792,40.0298881530762,1.99589152070971,25.4800003021955,0.000178534955648814,1.69207969839527E-5,0.25,-1.30878818105732E-6,1.55887348362166E-5,-1.19330029929045E-6,9.9984932,9.9984932,43574.41015625,43594.69140625,56.8939582862945,20.6352511295789,13.797379,0,0,0,40,4449,9.97785,43584.55078125,,,,,,,,,,,,,0,,,,-0.00245,,,,,,9.9984932,,,,
,27282226.305,9.9968071,48354.984375,1.50184945800778E-5,9.78774610830933E-7,1,0.999253354069792,40.0298881530762,1.99576844379607,25.4800003021955,0.000170265764124709,2.52814847275899E-5,0.25,-4.63427261819018E-7,1.50031704995241E-5,-3.52458649293873E-7,9.9968071,9.9968071,48342.78125,48367.1875,56.7266897831791,20.6398419623324,13.417728,0,0,0,40,4449,9.98055,48354.984375,,,,,,,,,,,,,0,,,,0,,,,,,9.9968071,,,,
,27282321.89,9.9960279,53132.4453125,1.55337900618072E-5,9.29325929788445E-7,1,0.999253354069792,40.0298881530762,1.99569061717907,25.4800003021955,0.000177190852100247,2.05886363333128E-5,0.25,-9.74223878928158E-7,1.55291348230009E-5,-8.58352467483817E-7,9.9960279,9.9960279,53124.90625,53139.984375,57.1925403806407,20.6379004622971,14.177031,0,0,0,40,4449,9.9838,53132.4453125,,,,,,,,,,,,,0,,,,0,,,,,,9.9960279,,,,
,27282417.805,9.9951839,57927.572265625,1.79765326819776E-5,9.46365380634569E-7,1,0.999253354069792,40.0298881530762,1.99540603293403,25.4800003021955,0.000206305465270057,1.72753807155449E-5,0.25,-1.70918598591581E-6,1.79839207893983E-5,-1.57492938818967E-6,9.9951839,9.9951839,57922.3671875,57932.77734375,57.7842331696984,20.6417938139008,13.797379,0,0,0,40,4449,9.98705,57927.572265625,,,,,,,,,,,,,0,,,,0,,,,,,9.9951839,,,,
,27282514.16,9.9958115,62743.880859375,1.6849327307601E-5,7.63415693508052E-7,1,0.999253354069792,40.0298881530762,1.99551815414992,25.4800003021955,0.000192025727960689,2.41952097246889E-5,0.25,-8.93733532883067E-7,1.68585823629522E-5,-7.6850980262207E-7,9.9958115,9.9958115,62736.46484375,62751.296875,56.8931766577752,20.6375325706402,13.797379,0,0,0,40,4449,9.99085,62743.880859375,,,,,,,,,,,,,0,,,,-0.0049,,,,,,9.9958115,,,,
,27282610.315,9.9962654,67551.046875,1.63254519613619E-5,9.92861797519189E-7,1,0.999253354069792,40.0298881530762,1.99518819365798,25.4800003021955,0.000186267754729276,2.25488297257604E-5,0.25,-9.45217649658122E-7,1.6341994509151E-5,-8.24722123539282E-7,9.9962654,9.9962654,67543.6875,67558.40625,57.4692368764484,20.6428517321895,13.797379,0,0,0,40,4449,9.9975,67551.046875,,,,,,,,,,,,,0,,,,0.00245,,,,,,9.9962654,,,,
,27282703.94,9.9951868,72228.75,1.71397025554012E-5,7.42983422823998E-7,1,0.999253354069792,40.0298881530762,1.99498907211892,25.4800003021955,0.00019512899697283,2.63856110775156E-5,0.25,-7.52036568243538E-7,1.71620546319673E-5,-6.2647551759118E-7,9.9951868,9.9951868,72221.109375,72236.390625,58.1218966900062,20.6417921008794,13.797379,0,0,0,40,4449,10.00075,72228.75,,,,,,,,,,,,,0,,,,0.00245,,,,,,9.9951868,,,,
,27282802.755,9.9956207,77168.87890625,1.62606826856568E-5,8.97809307232792E-7,1,0.999253354069792,40.0298881530762,1.99465646160863,25.4800003021955,0.000188792273058837,4.8961481515836E-6,0.25,-2.4951014817045E-6,1.63012880931317E-5,-2.37981376814401E-6,9.9956207,9.9956207,77163.75,77174.0078125,57.3301070000253,20.6512022356941,13.797379,0,0,0,40,4449,10.0035,77168.87890625,,,,,,,,,,,,,0,,,,-0.0049,,,,,,9.9956207,,,,
,27282899.52,9.9953299,82005.21875,1.58733347104198E-5,9.66224438629372E-7,1,0.999253354069792,40.0298881530762,1.9946555164289,25.4800003021955,0.000182192639239697,1.68192274048572E-5,0.25,-1.36920718988632E-6,1.5910864328627E-5,-1.25699795399104E-6,9.9953299,9.9953299,82002.7578125,82007.6796875,57.139389641333,20.6507806622102,13.417728,0,0,0,40,4449,10.00755,82005.21875,,,,,,,,,,,,,0,,,,0,,,,,,9.9953299,,,,
,27282995.11,9.9945335,86783.140625,1.4721422702709E-5,1.26817082442077E-6,1,0.999253354069792,40.0298881530762,1.99507117908317,25.4800003021955,0.000170313703961294,8.63997958841762E-6,0.25,-1.88449421070373E-6,1.47654717787546E-5,-1.78351346431459E-6,9.9945335,9.9945335,86770.53125,86795.75,56.9189703989099,20.6450213754277,13.038077,0,0,0,40,4449,10.0122,86783.140625,,,,,,,,,,,,,0,,,,0,,,,,,9.9945335,,,,
,27283108.27,9.9964581,88635.08984375,1.41961693255116E-5,8.97770889582776E-7,1,0.999253354069792,40.0298881530762,1.9950595543404,25.4800003021955,0.000169687245749834,-2.18645896552243E-5,0.25,-4.48661815735215E-6,1.42592729443423E-5,-4.39591035617085E-6,9.9964581,9.9964581,88627.5859375,88642.59375,56.9619599674676,20.6443294896681,13.417728,0,0,0,40,4449,10.0163,88635.08984375,,,,,,,,,,,,,0,,,,0.0049,,,,,,9.9964581,,,,
,27283201.705,9.999835,83966.7734375,1.49045672965662E-5,1.16757258612484E-6,1,0.999253354069792,40.0298881530762,1.99552096743891,25.4800003021955,0.000171456199020872,1.41980727965878E-5,0.25,-1.42685412055032E-6,1.49428825896123E-5,-1.322493166204E-6,9.999835,9.999835,83959.3125,83974.234375,57.3027500018522,20.6386889999619,13.797379,0,0,0,40,4449,10.0152,83966.7734375,,,,,,,,,,,,,0,,,,0.00245,,,,,,9.999835,,,,
,27283303.25,10.001153,78888.27734375,1.33803404321367E-5,7.49504764891777E-7,1,0.999253354069792,40.0298881530762,1.99579802693159,25.4800003021955,0.000159505633065819,-1.84628619075206E-5,0.25,-4.04236902056085E-6,1.34299356361311E-5,-3.95114429952655E-6,10.001153,10.001153,78875.7265625,78900.828125,57.4989387601791,20.6408733344448,13.417728,0,0,0,40,4449,10.0129,78888.27734375,,,,,,,,,,,,,0,,,,0,,,,,,10.001153,,,,
,27283402.04,10.0023384,73949.1484375,1.22615280598695E-5,1.02438642645297E-6,1,0.999253354069792,40.0298881530762,1.99600160502234,25.4800003021955,0.000145062342000307,-1.09907533436704E-5,0.25,-3.18126441297945E-6,1.22986517957852E-5,-3.09474260748824E-6,10.0023384,10.0023384,73941.8828125,73956.4140625,56.9705578811791,20.6405735134575,13.038077,0,0,0,40,4449,10.01045,73949.1484375,,,,,,,,,,,,,0,,,,0.00245,,,,,,10.0023384,,,,
,27283501.78,10.0022888,68966.72265625,1.27172347248394E-5,1.19124196605206E-6,1,0.999253354069792,40.0298881530762,1.99616170730053,25.4800003021955,0.000146663038174269,9.37034926339105E-6,0.25,-1.46235670450699E-6,1.27370424052804E-5,-1.36924629824703E-6,10.0022888,10.0022888,68953.984375,68979.4609375,57.4708001334869,20.6355043221924,13.797379,0,0,0,40,4449,10.00835,68966.72265625,,,,,,,,,,,,,0,,,,0,,,,,,10.0022888,,,,
,27283601.54,10.003087,63978.541015625,1.41101247964836E-5,9.76100437940582E-7,1,0.999253354069792,40.0298881530762,1.996182686747,25.4800003021955,0.000161669219849976,1.58759992387149E-5,0.25,-1.13748109244935E-6,1.41223496001072E-5,-1.03286324375973E-6,10.003087,10.003087,63966.1875,63990.89453125,56.6774471864675,20.6385206382407,13.038077,0,0,0,40,4449,10.005,63978.541015625,,,,,,,,,,,,,0,,,,0,,,,,,10.003087,,,,
,27283701.74,10.0034142,58971.052734375,1.42249416986218E-5,1.16732956111524E-6,1,0.999253354069792,40.0298881530762,1.99606750890396,25.4800003021955,0.000165987366806232,-1.12929784889603E-6,0.25,-2.66412617169916E-6,1.42419671411501E-5,-2.55773096155717E-6,10.0034142,10.0034142,58958.73046875,58983.375,57.3488660844868,20.6386451451193,13.038077,0,0,0,40,4449,10.00275,58971.052734375,,,,,,,,,,,,,0,,,,0,,,,,,10.0034142,,,,
,27283800.485,10.0035353,54032.64453125,1.2769033821927E-5,9.22815997662935E-7,1,0.999253354069792,40.0298881530762,1.99616444805285,25.4800003021955,0.0001477539368258,5.5329958475247E-6,0.25,-1.81099700179377E-6,1.27738469757907E-5,-1.71503854189796E-6,10.0035353,10.0035353,54025.1640625,54040.125,57.7021621751792,20.6369170888963,13.417728,0,0,0,40,4449,9.9979,54032.64453125,,,,,,,,,,,,,0,,,,-0.00245,,,,,,10.0035353,,,,
,27283896.515,10.0032492,49234.984375,1.31211998438297E-5,7.51258314589009E-7,1,0.999253354069792,40.0298881530762,1.99627687357777,25.4800003021955,0.00015223935066129,3.03780982560007E-6,0.25,-2.09480613693078E-6,1.31214426538017E-5,-1.995755790499E-6,10.0032492,10.0032492,49232.609375,49237.359375,57.6263442088138,20.6423486768145,13.417728,0,0,0,40,4449,9.9957,49234.984375,,,,,,,,,,,,,0,,,,0,,,,,,10.0032492,,,,
,27283991.97,10.0031738,44464.48046875,1.19123779711728E-5,8.90006086618156E-7,1,0.999253354069792,40.0298881530762,1.99628764310211,25.4800003021955,0.000136258951880975,1.32265105070592E-5,0.25,-9.71983960805702E-7,1.18997944626685E-5,-8.83723547435174E-7,10.0031738,10.0031738,44454.328125,44474.6328125,57.4911224749868,20.6433729636827,13.797379,0,0,0,40,4449,9.9939,44464.48046875,,,,,,,,,,,,,0,,,,-0.0049,,,,,,10.0031738,,,,
,27284088.485,10.0032558,39639.236328125,1.26236058973211E-5,8.66942206982606E-7,1,0.999253354069792,40.0298881530762,1.99603857138303,25.4800003021955,0.000142889057612587,2.18588803606503E-5,0.25,-3.31485738146495E-7,1.25987359475876E-5,-2.40568518315562E-7,10.0032558,10.0032558,39626.9140625,39651.55859375,57.078422616833,20.6472238580654,13.417728,0,0,0,40,4449,9.9913,39639.236328125,,,,,,,,,,,,,0,,,,0,,,,,,10.0032558,,,,
,27284186.735,10.0028458,34727.330078125,1.20386668888497E-5,6.84326847317448E-7,1,0.999253354069792,40.0298881530762,1.99606802329954,25.4800003021955,0.000135237784902889,2.61761192481013E-5,0.25,1.60216691965009E-7,1.20052981776338E-5,2.43724038554776E-7,10.0028458,10.0028458,34719.5078125,34735.15234375,57.4489145349484,20.6481961147758,13.797379,0,0,0,40,4449,9.98875,34727.330078125,,,,,,,,,,,,,0,,,,0,,,,,,10.0028458,,,,
,27284282.595,10.0016694,29937.15234375,1.1610039009238E-5,6.70174055140991E-7,1,0.999253354069792,40.0298881530762,1.99609919734671,25.4800003021955,0.000129641367801447,2.9226329249373E-5,0.25,5.11830338681431E-7,1.15695989191515E-5,5.88700952752646E-7,10.001668,10.0016708,29931.783203125,29942.521484375,57.7615659426407,20.6439426924518,13.417728,0,0,0,40,4449,9.988,29937.15234375,,,,,,,,,,,,,0,,,,0.0049,,,,,,10.0016694,,,,
,27284377.815,10.0001335,25179.5078125,1.19324987166323E-5,5.90832515303345E-7,1,0.999253354069792,40.0298881530762,1.9961024387594,25.4800003021955,0.000134650187687259,2.18109453135149E-5,0.25,-2.00981931724485E-7,1.18899139209445E-5,-1.22541671245204E-7,10.0001335,10.0001335,25174.51953125,25184.49609375,57.2738297466407,20.6450631138173,13.797379,0,0,0,40,4449,9.98685,25179.5078125,,,,,,,,,,,,,0,,,,-0.00245,,,,,,10.0001335,,,,
,27284472.71,10.0002041,20436.9013671875,1.18441726500131E-5,6.18248107472212E-7,1,0.999253354069792,40.0298881530762,1.99603287624351,25.4800003021955,0.000134884857668127,1.43744887727758E-5,0.25,-8.42073911825297E-7,1.18002230129367E-5,-7.64844572362409E-7,10.0002041,10.0002041,20432.03125,20441.771484375,57.9374323594677,20.6483038703163,13.417728,0,0,0,40,4449,9.9875,20436.9013671875,,,,,,,,,,,,,0,,,,0,,,,,,10.0002041,,,,
,27284568.305,9.9998817,15657.5317382812,1.14439636926695E-5,4.73492516198709E-7,1,0.999253354069792,40.0298881530762,1.99631341909417,25.4800003021955,0.000129064118583032,2.07006965981525E-5,0.25,-2.03588685281167E-7,1.13924571552396E-5,-1.35088741890651E-7,9.9998817,9.9998817,15649.9228515625,15665.140625,57.2605420618137,20.6472093025693,13.417728,0,0,0,40,4449,9.98795,15657.5317382812,,,,,,,,,,,,,0,,,,0,,,,,,9.9998817,,,,
,27284665.79,9.9987879,10785.447265625,1.143186057919E-5,4.06471759799148E-7,1,0.999253354069792,40.0298881530762,1.99650387488981,25.4800003021955,0.000129304459155549,1.83100533625454E-5,0.25,-4.09487249899719E-7,1.13766280962961E-5,-3.43957774390802E-7,9.9987879,9.9987879,10778.109375,10792.78515625,57.2933704596215,20.6473067138591,13.038077,0,0,0,40,4449,9.9891,10785.447265625,,,,,,,,,,,,,0,,,,0,,,,,,9.9987879,,,,
,27284757.22,9.9983644,6214.62133789063,1.1348650706255E-5,3.7505644727429E-7,1,0.999253354069792,40.0298881530762,1.99501724305728,25.4800003021955,0.000127461326505991,2.2446450077085E-5,0.25,-2.06554526603123E-8,1.1287662541662E-5,3.86401419741403E-8,9.9983644,9.9983644,6204.7109375,6224.53173828125,57.596642325083,20.6594131140411,13.417728,0,0,0,40,4449,9.99075,6214.62133789063,,,,,,,,,,,,,0,,,,0,,,,,,9.9983644,,,,
,27284853.46,9.99955795,1403.58953857422,1.0753549665474E-5,3.40416600176955E-7,1,0.999253354069792,40.0298881530762,1.9948436055041,25.4800003021955,0.000121081306479827,1.92866943886073E-5,0.25,-1.91971768094128E-7,1.06933505538422E-5,-1.38308508057887E-7,9.9993124,9.9998035,1395.97387695312,1411.20520019531,57.769382227833,20.6617235638756,12.658426,0,0,0,40,4449,9.9904,1403.58953857422,,,,,,,,,,,,,0,,,,-0.0049,,,,,,9.99955795,,,,
,27284947.24,9.9993744,-3279.08203125,1.10846079578139E-5,3.37084197285436E-7,1,0.999253354069792,40.0298881530762,1.99446989561802,25.4800003021955,0.000124483775685049,2.16593381999046E-5,0.25,-4.05792768940568E-8,1.10229675501633E-5,1.51589921884965E-8,9.9993744,9.9993744,-3286.59252929687,-3271.57153320313,57.9538465583715,20.6706675245772,13.038077,0,0,0,40,4449,9.9901,-3279.08203125,,,,,,,,,,,,,0,,,,-0.00245,,,,,,9.9993744,,,,
,27285039.275,9.9988642,-7878.6240234375,1.03093371249978E-5,4.03317621680668E-7,1,0.999253354069792,40.0298881530762,1.99462556608416,25.4800003021955,0.000115696374661885,2.08649163199109E-5,0.25,2.23240440032891E-8,1.02549816409024E-5,7.72289825737145E-8,9.9988642,9.9988642,-7886.208984375,-7871.0390625,57.677931691083,20.6760002336258,13.417728,0,0,0,40,4449,9.9914,-7878.6240234375,,,,,,,,,,,,,0,,,,0,,,,,,9.9988642,,,,
,27285133.745,10.0003185,-12599.3452148438,8.96015439306558E-6,4.58084420221518E-7,1,0.999253354069792,40.0298881530762,1.99500754826405,25.4800003021955,0.000100315209198094,1.98103576616706E-5,0.25,1.64582300494909E-7,8.91551718868652E-6,2.14717440455039E-7,10.0003185,10.0003185,-12604.115234375,-12594.5751953125,57.4082698519484,20.667668592565,12.658426,0,0,0,40,4449,9.99045,-12599.3452148438,,,,,,,,,,,,,0,,,,0.0049,,,,,,10.0003185,,,,
,27285228.555,10.0002756,-17339.609375,7.03308669019998E-6,4.00719067597543E-7,1,0.999253354069792,40.0298881530762,1.99448457804013,25.4800003021955,7.97062267286287E-5,1.02277053202935E-5,0.25,-3.471554585321E-7,7.00387896750006E-6,-3.03270477283832E-7,10.0002756,10.0002756,-17342.052734375,-17337.166015625,57.3363600281791,20.6752483712815,13.038077,0,0,0,40,4449,9.9893,-17339.609375,,,,,,,,,,,,,0,,,,-0.0049,,,,,,10.0002756,,,,
,27285325.875,10.0007286,-22201.5283203125,1.93468133733233E-6,4.7979326009441E-7,1,0.999253354069792,40.0298881530762,1.99453768438673,25.4800003021955,2.14455393703965E-5,5.55915629631216E-6,0.25,1.4806798623029E-7,1.92604488494748E-6,1.59736768467254E-7,10.0007286,10.0007286,-22204.07421875,-22198.982421875,57.6787133196022,20.6734520088188,12.658426,0,0,0,40,4449,9.9897,-22201.5283203125,,,,,,,,,,,,,0,,,,-0.0049,,,,,,10.0007286,,,,
,27285421.38,10.0006361,-26976.736328125,-4.10699678137302E-6,5.47137010673698E-7,1,0.999253354069792,40.0298881530762,1.99459846296148,25.4800003021955,-4.40823918724195E-5,-1.99749246959322E-5,0.25,-1.03961179659712E-6,-4.08577567400259E-6,-1.06312975037563E-6,10.0006361,10.0006361,-26981.7578125,-26971.71484375,56.9338213407753,20.6742572252079,12.658426,0,0,0,40,4449,9.9887,-26976.736328125,,,,,,,,,,,,,0,,,,-0.0049,,,,,,10.0006361,,,,
,27285514.73,9.999238,-31641.873046875,-6.80863370971717E-6,6.27843305050073E-7,1,0.999253354069792,40.0298881530762,1.99460457049351,25.4800003021955,-7.55314946535531E-5,-1.96629309622104E-5,0.25,-5.24753217365584E-7,-6.78457911864163E-6,-5.69755325793045E-7,9.999238,9.999238,-31644.259765625,-31639.486328125,57.6028953532369,20.6758471926567,13.038077,0,0,0,40,4449,9.98905,-31641.873046875,,,,,,,,,,,,,0,,,,-0.00245,,,,,,9.999238,,,,
,27285610.265,9.9996614,-36416.095703125,-8.23237869999489E-6,8.81129756588982E-7,1,0.999253354069792,40.0298881530762,1.99447187751172,25.4800003021955,-9.45803537887526E-5,-5.90748802180524E-6,0.25,9.5566378426454E-7,-8.21852500083599E-6,8.95346268222494E-7,9.9996614,9.9996614,-36426.16015625,-36406.03125,57.69121937591,20.6768227313877,13.417728,0,0,0,40,4449,9.98925,-36416.095703125,,,,,,,,,,,,,0,,,,0.0049,,,,,,9.9996614,,,,
,27285705.995,9.9984212,-41201.130859375,-7.7051605435916E-6,8.78073424549286E-7,1,0.999253354069792,40.0298881530762,1.99457033846208,25.4800003021955,-8.93368309927245E-5,-1.29491550642577E-6,0.25,1.27197654689279E-6,-7.69895471792452E-6,1.21402927014011E-6,9.9982777,9.9985647,-41208.4765625,-41193.78515625,57.6224360662176,20.6758504511608,12.658426,0,0,0,40,4449,9.9903,-41201.130859375,,,,,,,,,,,,,0,,,,-0.00245,,,,,,9.9984212,,,,
,27285803.12,9.9978743,-46053.6640625,-9.03822245005582E-6,7.12333784641167E-7,1,0.999253354069792,40.0298881530762,1.99518103747528,25.4800003021955,-0.000102995367183865,-1.19773626761277E-5,0.25,5.6510218043383E-7,-9.02893530659886E-6,4.98208122548287E-7,9.9978743,9.9978743,-46061.203125,-46046.125,57.4426615067945,20.6655605632712,13.038077,0,0,0,40,4449,9.99255,-46053.6640625,,,,,,,,,,,,,0,,,,-0.00245,,,,,,9.9978743,,,,
,27285897.495,9.9967575,-50770.83203125,-8.60432903167142E-6,9.21216371241806E-7,1,0.999253354069792,40.0298881530762,1.99534310351383,25.4800003021955,-9.93192515305877E-5,-4.67869138407139E-6,0.25,1.13552712736106E-6,-8.60410033221702E-6,1.07084355395953E-6,9.9967575,9.9967575,-50778.27734375,-50763.38671875,57.6622991206984,20.6613120940163,13.417728,0,0,0,40,4449,9.9953,-50770.83203125,,,,,,,,,,,,,0,,,,0,,,,,,9.9967575,,,,
,27285995.155,9.996829,-55653.14453125,-7.70310284033676E-6,7.79013665207256E-7,1,0.999253354069792,40.0298881530762,1.99570700911846,25.4800003021955,-8.80188358080073E-5,-9.4997610820159E-6,0.25,5.46408712809477E-7,-7.70318638585762E-6,4.88889694920217E-7,9.996829,9.996829,-55660.62109375,-55645.66796875,57.4192126512176,20.6569499512313,13.038077,0,0,0,40,4449,9.999,-55653.14453125,,,,,,,,,,,,,0,,,,0.0049,,,,,,9.996829,,,,
,27286094.185,9.9962111,-60602.537109375,-6.95607680496606E-6,6.25739806773309E-7,1,0.999253354069792,40.0298881530762,1.99557341984153,25.4800003021955,-8.2500813180125E-5,7.97937182071424E-6,0.25,1.96081532851259E-6,-6.9703702839977E-6,1.90895211553E-6,9.9962111,9.9962111,-60617.578125,-60587.49609375,57.332451885583,20.6530921775521,13.038077,0,0,0,40,4449,10.0026,-60602.537109375,,,,,,,,,,,,,0,,,,0,,,,,,9.9962111,,,,
,27286191.805,9.9961004,-65482.568359375,-6.92783098095609E-6,8.62407616975204E-7,1,0.999253354069792,40.0298881530762,1.99588249244162,25.4800003021955,-8.0413552740091E-5,-2.0385404111066E-6,0.25,1.06811978755468E-6,-6.9385497218899E-6,1.01708552408922E-6,9.9959831,9.9962177,-65490.05859375,-65475.078125,57.5880444113715,20.6544802120962,12.658426,0,0,0,40,4449,10.00595,-65482.568359375,,,,,,,,,,,,,0,,,,0,,,,,,9.9961004,,,,
,27286289.87,9.9956541,-70379.28515625,-4.23307678175397E-6,8.36429102312786E-7,1,0.999253354069792,40.0298881530762,1.99594639780721,25.4800003021955,-5.00464766414627E-5,3.6918814303843E-6,0.25,1.08950794085603E-6,-4.24462569531643E-6,1.05912933212067E-6,9.9956541,9.9956541,-70391.7421875,-70366.828125,57.6669888918138,20.6541854826488,13.038077,0,0,0,40,4449,10.0104,-70379.28515625,,,,,,,,,,,,,0,,,,0,,,,,,9.9956541,,,,
,27286386.1,9.9955235,-75191.390625,-6.28240579733666E-6,8.21827013391409E-7,1,0.999253354069792,40.0298881530762,1.99588864069668,25.4800003021955,-7.57544207587204E-5,1.35492304369293E-5,0.25,2.33035410539409E-6,-6.30715998408123E-6,2.28714719221941E-6,9.9955235,9.9955235,-75199.03125,-75183.75,58.3149589342562,20.6528721793203,13.038077,0,0,0,40,4449,10.0149,-75191.390625,,,,,,,,,,,,,0,,,,-0.0049,,,,,,9.9955235,,,,
,27286485.69,9.9954338,-80168.40625,-3.26971307261799E-6,9.97906200269353E-7,1,0.999253354069792,40.0298881530762,1.99596273503575,25.4800003021955,-4.06819509746154E-5,1.39407262014499E-5,0.25,1.82151881528549E-6,-3.28817305480419E-6,1.80073152604626E-6,9.9954338,9.9954338,-80170.8828125,-80165.9296875,57.8178431960254,20.6542848082737,13.417728,0,0,0,40,4449,10.0184,-80168.40625,,,,,,,,,,,,,0,,,,-0.00245,,,,,,9.9954338,,,,
,27286584.345,9.995389,-85098.5,-1.73225125145806E-6,1.17684319857026E-6,1,0.999253354069792,40.0298881530762,1.99613548943039,25.4800003021955,-1.77614467452729E-5,-1.37271556951844E-5,0.25,-9.01683441204728E-7,-1.72919589662028E-6,-9.15856429552675E-7,9.995389,9.995389,-85108.40625,-85088.59375,57.8467634512369,20.6575442313555,13.417728,0,0,0,40,4449,10.02235,-85098.5,,,,,,,,,,,,,0,,,,0,,,,,,9.995389,,,,
,27286674.57,9.9957209,-89605.09765625,-1.03983867406836E-6,9.82277266592643E-7,1,0.999253354069792,40.0298881530762,1.99611511964685,25.4800003021955,-1.91054978033001E-5,3.8685920250019E-5,0.25,3.60552750391314E-6,-1.06767410745353E-6,3.60636452140299E-6,9.9957209,9.9957209,-89610.109375,-89600.0859375,57.2011382943522,20.6557314700054,12.658426,0,0,0,40,4449,10.02745,-89605.09765625,,,,,,,,,,,,,0,,,,0,,,,,,9.9957209,,,,
,27286778.745,9.9986458,-86214.95703125,-1.88313016291726E-6,8.02084927891507E-7,1,0.999253354069792,40.0298881530762,1.99618128295471,25.4800003021955,-2.5110532089383E-5,1.73114890753406E-5,0.25,1.86888074528235E-6,-1.90031237325821E-6,1.85925426017003E-6,9.9986458,9.9986458,-86220.0703125,-86209.84375,57.3793495967368,20.655977259391,13.038077,0,0,0,40,4449,10.02675,-86214.95703125,,,,,,,,,,,,,0,,,,0,,,,,,9.9986458,,,,
,27286865.595,10.0008087,-81872.10546875,-1.15809339843007E-6,9.99073497248177E-7,1,0.999253354069792,40.0298881530762,1.99649010844354,25.4800003021955,-1.71274259786481E-5,2.0011748241295E-5,0.25,1.97750657442081E-6,-1.174380014597E-6,1.97256790759188E-6,10.0008087,10.0008087,-81876.9609375,-81867.25,57.4403166212368,20.6534660466952,12.658426,0,0,0,40,4449,10.0254,-81872.10546875,,,,,,,,,,,,,0,,,,-0.0049,,,,,,10.0008087,,,,
,27286957.265,10.0027628,-77292.453125,-3.76461821647449E-6,1.05314400956207E-6,1,0.999253354069792,40.0298881530762,1.99626099642654,25.4800003021955,-4.56636234064461E-5,9.5329330489424E-6,0.25,1.52108539237624E-6,-3.78094042756039E-6,1.49571509280047E-6,10.0027628,10.0027628,-77300,-77284.90625,57.5583425276407,20.6544126925558,13.038077,0,0,0,40,4449,10.0229,-77292.453125,,,,,,,,,,,,,0,,,,0.0049,,,,,,10.0027628,,,,
,27287049.915,10.0033569,-72662.4375,-4.11681658412904E-6,8.31767539569642E-7,1,0.999253354069792,40.0298881530762,1.99642310815752,25.4800003021955,-4.63544159882847E-5,-9.38273889141169E-6,0.25,-8.83822372635534E-8,-4.12035050556055E-6,-1.18786603646577E-7,10.0033569,10.0033569,-72672.546875,-72652.328125,57.7975208545254,20.6483739300273,13.038077,0,0,0,40,4449,10.01925,-72662.4375,,,,,,,,,,,,,0,,,,-0.00245,,,,,,10.0033569,,,,
,27287139.125,10.0035896,-68203.0859375,-4.73457730324982E-6,1.0277361514505E-6,1,0.999253354069792,40.0298881530762,1.9963820950637,25.4800003021955,-5.30570225224745E-5,-1.20745506108227E-5,0.25,-2.15419137271474E-7,-4.7360139465966E-6,-2.50637632307653E-7,10.0035896,10.0035896,-68210.671875,-68195.5,57.7842331696984,20.6530989162931,13.038077,0,0,0,40,4449,10.01705,-68203.0859375,,,,,,,,,,,,,0,,,,0.00245,,,,,,10.0035896,,,,
,27287228.405,10.0036621,-63740.591796875,-3.95564283967002E-6,6.29345886744351E-7,1,0.999253354069792,40.0298881530762,1.9961569657531,25.4800003021955,-4.32809745495796E-5,-1.57683983285353E-5,0.25,-6.83297399385205E-7,-3.95153198990223E-6,-7.12882614500447E-7,10.0036621,10.0036621,-63743.0859375,-63738.09765625,57.7639108281984,20.652622081554,13.038077,0,0,0,40,4449,10.01405,-63740.591796875,,,,,,,,,,,,,0,,,,-0.00245,,,,,,10.0036621,,,,
,27287318.785,10.0032454,-59225.154296875,-5.64553517502082E-6,8.31138347991572E-7,1,0.999253354069792,40.0298881530762,1.99621791374898,25.4800003021955,-5.90180603787757E-5,-3.76351960105781E-5,0.25,-2.3162360922026E-6,-5.62731918312871E-6,-2.35785494544342E-6,10.0032454,10.0032454,-59230.41796875,-59219.890625,57.1425161554099,20.6501618831067,13.417728,0,0,0,40,4449,10.0104,-59225.154296875,,,,,,,,,,,,,0,,,,0,,,,,,10.0032454,,,,
,27287411.57,10.00330305,-54585.8203125,-4.80510063935164E-6,7.57043058222285E-7,1,0.999253354069792,40.0298881530762,1.99608998437548,25.4800003021955,-5.66724148882269E-5,3.85569203092028E-6,0.25,1.20777491012061E-6,-4.81108353938005E-6,1.17135501884031E-6,10.0032549,10.0033512,-54598.25,-54573.390625,57.1487691835637,20.6559614051601,13.417728,0,0,0,40,4449,10.00825,-54585.8203125,,,,,,,,,,,,,0,,,,-0.00245,,,,,,10.00330305,,,,
,27287508.54,10.0036554,-49744.146484375,-6.66052446147666E-6,8.01602081324061E-7,1,0.999253354069792,40.0298881530762,1.99617034300127,25.4800003021955,-7.48467514278799E-5,-1.504181728041E-5,0.25,-1.33583288310197E-7,-6.65217767233901E-6,-1.82534273668801E-7,10.0036554,10.0036554,-49756.54296875,-49731.75,57.6732419199676,20.6528064533339,13.038077,0,0,0,40,4449,10.0046,-49744.146484375,,,,,,,,,,,,,0,,,,0.00245,,,,,,10.0036554,,,,
,27287607.255,10.0035524,-44809.23828125,-7.41432785934394E-6,8.15232930483734E-7,1,0.999253354069792,40.0298881530762,1.996080838297,25.4800003021955,-8.5155292729006E-5,-6.27577136268817E-6,0.25,7.78547152397112E-7,-7.40803126037176E-6,7.23297858239274E-7,10.0035524,10.0035524,-44819.2421875,-44799.234375,57.3215090863138,20.6538680909092,12.278775,0,0,0,40,4449,10.0005,-44809.23828125,,,,,,,,,,,,,0,,,,-0.00245,,,,,,10.0035524,,,,
,27287704.665,10.0038309,-39941.736328125,-8.03306404960331E-6,8.25510326615927E-7,1,0.999253354069792,40.0298881530762,1.99599217873535,25.4800003021955,-9.02804193859945E-5,-1.75125293140793E-5,0.25,-1.08745412735538E-7,-8.0152098898407E-6,-1.65988950789506E-7,10.0038309,10.0038309,-39946.59765625,-39936.875,57.5567792706022,20.6547030933323,12.658426,0,0,0,40,4449,9.9985,-39941.736328125,,,,,,,,,,,,,0,,,,0,,,,,,10.0038309,,,,
,27287802.445,10.0019445,-35051.7890625,-7.20287268829221E-6,5.77401672077488E-7,1,0.999253354069792,40.0298881530762,1.99593262778222,25.4800003021955,-7.76656430145455E-5,-3.37158884391341E-5,0.25,-1.6991948270464E-6,-7.17195530371829E-6,-1.74501345507694E-6,10.0019445,10.0019445,-35059.01953125,-35044.55859375,57.6161830380638,20.6512351158943,12.658426,0,0,0,40,4449,9.9966,-35051.7890625,,,,,,,,,,,,,0,,,,0,,,,,,10.0019445,,,,
,27287897.78,10.0010977,-30289.45703125,-9.07139351895203E-6,9.18124588823677E-7,1,0.999253354069792,40.0298881530762,1.99627020977421,25.4800003021955,-0.000101822373350808,-1.99632422800091E-5,0.25,-1.44343635260295E-7,-9.04185723215689E-6,-2.05378516123974E-7,10.0010977,10.0010977,-30296.958984375,-30281.955078125,57.5302039009484,20.6522525903076,12.658426,0,0,0,40,4449,9.99555,-30289.45703125,,,,,,,,,,,,,0,,,,-0.00245,,,,,,10.0010977,,,,
,27287994.96,10.0007439,-25432.546875,-9.6956081992893E-6,6.35291811091166E-7,1,0.999253354069792,40.0298881530762,1.99610708865771,25.4800003021955,-0.000108870566008294,-2.07392135416658E-5,0.25,-1.04674354689154E-7,-9.65951086074395E-6,-1.67565313759273E-7,10.0007439,10.0007439,-25440.09375,-25425,57.2527257766214,20.6520738255521,13.038077,0,0,0,40,4449,9.9947,-25432.546875,,,,,,,,,,,,,0,,,,0.00245,,,,,,10.0007439,,,,
,27288092.205,10.0004902,-20572.77734375,-9.72961194265802E-6,4.99694653476785E-7,1,0.999253354069792,40.0298881530762,1.99594729367534,25.4800003021955,-0.000109391033762224,-1.96814906691438E-5,0.25,-8.37735807857343E-9,-9.68927959382407E-6,-6.89957409885229E-8,10.0004902,10.0004902,-20577.75390625,-20567.80078125,57.7037254322177,20.6542343018887,12.658426,0,0,0,40,4449,9.994,-20572.77734375,,,,,,,,,,,,,0,,,,-0.0049,,,,,,10.0004902,,,,
,27288190.155,10.0003643,-15675.765625,-1.0746430316072E-5,4.66128269664315E-7,1,0.999253354069792,40.0298881530762,1.99593452595105,25.4800003021955,-0.000120881853274357,-2.10795699970316E-5,0.25,4.49220168264871E-8,-1.06972176878563E-5,-1.87427457160952E-8,10.0003643,10.0003643,-15685.53515625,-15665.99609375,57.166746639506,20.6560657130392,12.658426,0,0,0,40,4449,9.99455,-15675.765625,,,,,,,,,,,,,0,,,,0.00245,,,,,,10.0003643,,,,
,27288286.77,9.9994707,-10850.771484375,-1.06671465570953E-5,4.23136287975863E-7,1,0.999253354069792,40.0298881530762,1.99594984248847,25.4800003021955,-0.000118915781721752,-2.66572780120389E-5,0.25,-4.7014323741747E-7,-1.06109324135021E-5,-5.27056087267756E-7,9.9994707,9.9994707,-10858.2373046875,-10843.3056640625,57.5059734168522,20.6554373333645,13.038077,0,0,0,40,4449,9.99615,-10850.771484375,,,,,,,,,,,,,0,,,,0.00245,,,,,,9.9994707,,,,
,27288380.72,9.9991884,-6152.4951171875,-1.1491475181635E-5,4.169004202302E-7,1,0.999253354069792,40.0298881530762,1.99599111782885,25.4800003021955,-0.000128601195846132,-2.56825607622957E-5,0.25,-2.41144932595385E-7,-1.14283029578219E-5,-2.99722990592238E-7,9.9991884,9.9991884,-6164.91015625,-6140.080078125,57.8561429934677,20.6567661727383,12.278775,0,0,0,40,4449,9.99605,-6152.4951171875,,,,,,,,,,,,,0,,,,0,,,,,,9.9991884,,,,
,27288475.93,10.0005417,-1393.45349121094,-1.14351273592997E-5,3.43725333145264E-7,1,0.999253354069792,40.0298881530762,1.99582216509503,25.4800003021955,-0.000127981301880381,-2.52166296452417E-5,0.25,-2.1422969989283E-7,-1.13690616268436E-5,-2.68908776063054E-7,10.0005417,10.0005417,-1400.84716796875,-1386.05981445312,57.5106631879676,20.6593061367013,12.658426,0,0,0,40,4449,9.99575,-1393.45349121094,,,,,,,,,,,,,0,,,,0,,,,,,10.0005417,,,,
,27288568.445,9.9992075,3226.66430664063,-1.20155777044449E-5,3.09688764456268E-7,1,0.999253354069792,40.0298881530762,1.99579113524488,25.4800003021955,-0.000133797784669039,-3.03898579453429E-5,0.25,-5.70175957054675E-7,-1.19456480238429E-5,-6.27124777478082E-7,9.9992075,9.9992075,3226.66430664063,3226.66430664063,57.6787133196022,20.6556919760045,13.038077,0,0,0,40,4449,9.9943,3226.66430664063,,,,,,,,,,,,,0,,,,-0.0049,,,,,,9.9992075,,,,
,27288663.225,9.9989185,7966.09375,-1.16992947832962E-5,3.29262938796464E-7,1,0.999253354069792,40.0298881530762,1.99579936533623,25.4800003021955,-0.000130289429020389,-2.97570240378136E-5,0.25,-5.65224099887121E-7,-1.16348034729946E-5,-6.24770576605196E-7,9.9989185,9.9989185,7956.0556640625,7976.1318359375,57.2191157502945,20.6558918393264,12.278775,0,0,0,40,4449,9.9959,7966.09375,,,,,,,,,,,,,0,,,,0,,,,,,9.9989185,,,,
,27288757.86,9.9998989,12697.0629882812,-1.10272243468119E-5,3.4281949845903E-7,1,0.999253354069792,40.0298881530762,1.99568309435302,25.4800003021955,-0.000121922821015392,-3.32169714381285E-5,0.25,-9.88177290153374E-7,-1.09679091553995E-5,-1.04613335228296E-6,9.9998989,9.9998989,12689.5810546875,12704.544921875,57.8319125093715,20.6547600325989,12.658426,0,0,0,40,4449,9.99485,12697.0629882812,,,,,,,,,,,,,0,,,,0,,,,,,9.9998989,,,,
,27288853.09,10.0002346,17454.552734375,-8.4906085551138E-6,3.76941558457413E-7,1,0.999253354069792,40.0298881530762,1.99561636508047,25.4800003021955,-9.41526947679138E-5,-2.42370219316848E-5,0.25,-6.38026664986801E-7,-8.44907047505706E-6,-6.86375393606234E-7,10.0002346,10.0002346,17442.001953125,17467.103515625,57.5630322987561,20.6528505391889,13.038077,0,0,0,40,4449,9.99535,17454.552734375,,,,,,,,,,,,,0,,,,-0.0049,,,,,,10.0002346,,,,
,27288948.835,9.9998703,22242.2109375,-3.58514643363833E-6,4.87145194133908E-7,1,0.999253354069792,40.0298881530762,1.99589394326466,25.4800003021955,-3.76597793264724E-5,-2.20690195707307E-5,0.25,-1.32011870366445E-6,-3.56252783418303E-6,-1.33759526610185E-6,9.9998703,9.9998703,22234.5859375,22249.8359375,57.1315733561406,20.6560312985827,13.038077,0,0,0,40,4449,9.9951,22242.2109375,,,,,,,,,,,,,0,,,,0.0049,,,,,,9.9998703,,,,
,27289043.125,10.0006099,26955.0849609375,9.43839507708068E-7,4.26948763996503E-7,1,0.999253354069792,40.0298881530762,1.99597918692431,25.4800003021955,1.16144060652506E-5,-3.6390521867499E-6,0.25,-4.92765383517813E-7,9.43796855030483E-7,-4.84804386384454E-7,10.0005255,10.0006943,26942.6796875,26967.490234375,57.7842331696984,20.6517151122997,12.658426,0,0,0,40,4449,9.99445,26955.0849609375,,,,,,,,,,,,,0,,,,0.0049,,,,,,10.0006099,,,,
,27289141.37,9.9995737,31862.759765625,3.84837577747213E-6,6.82557620011298E-7,1,0.999253354069792,40.0298881530762,1.99595239676475,25.4800003021955,4.47680376408764E-5,-2.7581228846608E-7,0.25,-7.15906815971137E-7,3.84180328904053E-6,-6.87405836334093E-7,9.9995737,9.9995737,31855.35546875,31870.1640625,57.5075366738907,20.651207738913,12.278775,0,0,0,40,4449,9.9947,31862.759765625,,,,,,,,,,,,,0,,,,0.00245,,,,,,9.9995737,,,,
,27289236.15,9.9991255,36602.94921875,5.62285214131351E-6,7.40868841945549E-7,1,0.999253354069792,40.0298881530762,1.99592630892032,25.4800003021955,6.46984363666946E-5,3.7477390235804E-6,0.25,-6.78528842958938E-7,5.61368754748448E-6,-6.37241642963947E-7,9.9990988,9.9991522,36592.96484375,36612.93359375,57.5294222724292,20.650171628334,12.658426,0,0,0,40,4449,9.9952,36602.94921875,,,,,,,,,,,,,0,,,,0.00245,,,,,,9.9991255,,,,
,27289332.67,9.998539,41425.259765625,5.95533451309608E-6,5.68157362434216E-7,1,0.999253354069792,40.0298881530762,1.99595991928278,25.4800003021955,7.11056021417609E-5,-1.01607458527634E-5,0.25,-1.97380658360066E-6,5.95781593104709E-6,-1.92705425993794E-6,9.998539,9.998539,41420.28125,41430.23828125,57.8936611623907,20.6505192934356,12.278775,0,0,0,40,4449,9.9952,41425.259765625,,,,,,,,,,,,,0,,,,0,,,,,,9.998539,,,,
,27289428.415,9.9977617,46210.71875,5.99614841924801E-6,6.14530297169646E-7,1,0.999253354069792,40.0298881530762,1.99618299633236,25.4800003021955,7.25083083363462E-5,-1.50622525890324E-5,0.25,-2.41605857385732E-6,6.0050099726198E-6,-2.36867014581486E-6,9.9977617,9.9977617,46203.390625,46218.046875,57.2652318329291,20.6492780870899,12.658426,0,0,0,40,4449,9.9989,46210.71875,,,,,,,,,,,,,0,,,,0,,,,,,9.9977617,,,,
,27289524.09,9.9965734,50993.01171875,5.4218785148513E-6,1.10565268991129E-6,1,0.999253354069792,40.0298881530762,1.99596373982569,25.4800003021955,6.58796785263269E-5,-1.52262861731387E-5,0.25,-2.32707316051036E-6,5.43376442287818E-6,-2.28473739876239E-6,9.9965734,9.9965734,50980.609375,51005.4140625,57.1346998702176,20.6486366901591,13.038077,0,0,0,40,4449,10.002,50993.01171875,,,,,,,,,,,,,0,,,,0,,,,,,9.9965734,,,,
,27289621.095,9.996541,55840.673828125,4.52273530756583E-6,7.13240562090915E-7,1,0.999253354069792,40.0298881530762,1.99600101610075,25.4800003021955,5.55987863157571E-5,-1.61251170080251E-5,0.25,-2.24422225154206E-6,4.53716107740826E-6,-2.20949430285086E-6,9.996541,9.996541,55833.19140625,55848.15625,57.3050948874099,20.6497876227866,12.658426,0,0,0,40,4449,10.0062,55840.673828125,,,,,,,,,,,,,0,,,,0,,,,,,9.996541,,,,
,27289718.595,9.9955778,60715.76171875,1.03547439833859E-6,9.62928564781226E-7,1,0.999253354069792,40.0298881530762,1.9961080928718,25.4800003021955,1.45674169434497E-5,-1.38546072535358E-5,0.25,-1.41382871432038E-6,1.04596426554421E-6,-1.40607470163057E-6,9.9955778,9.9955778,60715.76171875,60715.76171875,57.3230723433522,20.6502583720868,12.658426,0,0,0,40,4449,10.0098,60715.76171875,,,,,,,,,,,,,0,,,,0,,,,,,9.9955778,,,,
,27289816.82,9.9962997,65623.953125,1.87722596616725E-6,7.02008886801137E-7,1,0.999253354069792,40.0298881530762,1.99600505357871,25.4800003021955,2.29827008644577E-5,-6.05899187279001E-6,0.25,-8.74801258833282E-7,1.88450176935007E-6,-8.61220347444907E-7,9.9962997,9.9962997,65618.9296875,65628.9765625,57.5176978446407,20.6520551045834,12.658426,0,0,0,40,4449,10.0129,65623.953125,,,,,,,,,,,,,0,,,,-0.00245,,,,,,9.9962997,,,,
,27289910.415,9.9958239,70301.66015625,8.07388412653677E-7,7.84065784587401E-7,1,0.999253354069792,40.0298881530762,1.9962894911519,25.4800003021955,9.61097055530966E-6,-1.05911492559424E-6,0.25,-2.39206432556893E-7,8.09818102967679E-7,-2.33435965038236E-7,9.9958239,9.9958239,70296.7578125,70306.5625,57.4489145349484,20.6487148860788,12.658426,0,0,0,40,4449,10.0152,70301.66015625,,,,,,,,,,,,,0,,,,-0.0049,,,,,,9.9958239,,,,
,27289996.75,9.9965286,74619.57421875,-9.27779767218771E-7,7.69445639026048E-7,1,0.999253354069792,40.0298881530762,1.99593346462541,25.4800003021955,-6.41209003641464E-6,-2.45071852351586E-5,0.25,-2.00113604737156E-6,-9.14185297306697E-7,-2.0102965757022E-6,9.9965286,9.9965286,74614.546875,74624.6015625,57.2902439455445,20.6502606071706,12.658426,0,0,0,40,4449,10.0183,74619.57421875,,,,,,,,,,,,,0,,,,0.0049,,,,,,9.9965286,,,,
,27290086.195,9.9956465,79090.4375,-2.46629684971874E-6,8.61996649609907E-7,1,0.999253354069792,40.0298881530762,1.9959873097189,25.4800003021955,-2.30945284664752E-5,-3.16346286883524E-5,0.25,-2.35369108986237E-6,-2.45294440247506E-6,-2.37521009844036E-6,9.9956465,9.9956465,79082.703125,79098.171875,57.6708970344099,20.6518777308233,13.038077,0,0,0,40,4449,10.02185,79090.4375,,,,,,,,,,,,,0,,,,0,,,,,,9.9956465,,,,
,27290176.12,9.995368,83584.12890625,-4.63376468560442E-6,9.15316977990578E-7,1,0.999253354069792,40.0298881530762,1.99611077715708,25.4800003021955,-4.76488714175517E-5,-3.59179903162415E-5,0.25,-2.34134861060694E-6,-4.62553073514265E-6,-2.37900866580804E-6,9.995368,9.995368,83571.671875,83596.5859375,57.769382227833,20.6518017181547,12.658426,0,0,0,40,4449,10.0253,83584.12890625,,,,,,,,,,,,,0,,,,0,,,,,,9.995368,,,,
,27290261.455,9.9954481,87850.40234375,-5.60225784941134E-6,8.86091036750234E-7,1,0.999253354069792,40.0298881530762,1.99611147326137,25.4800003021955,-5.68033308547351E-5,-4.80214595821363E-5,0.25,-3.23623163877612E-6,-5.59132961507852E-6,-3.28299300814356E-6,9.9954481,9.9954481,87845.9140625,87854.890625,57.3355783996599,20.6509330310807,13.038077,0,0,0,40,4449,10.0299,87850.40234375,,,,,,,,,,,,,0,,,,0.0049,,,,,,9.9954481,,,,
,27290362.625,9.997005,88123.11328125,-5.41123953596304E-6,9.8988271333113E-7,1,0.999253354069792,40.0298881530762,1.99611733016898,25.4800003021955,-5.46064212766721E-5,-4.78387109347252E-5,0.25,-3.25438139591794E-6,-5.39988956710547E-6,-3.29985350988552E-6,9.9966345,9.9973755,88118.6328125,88127.59375,57.3136928011214,20.6507581413755,12.658426,0,0,0,40,4449,10.03175,88123.11328125,,,,,,,,,,,,,0,,,,0,,,,,,9.997005,,,,
,27290446.375,9.9994631,83936.57421875,-3.58151144529813E-6,5.82871845128244E-7,1,0.999253354069792,40.0298881530762,1.99601608945513,25.4800003021955,-3.60818343879744E-5,-3.19070287148241E-5,0.25,-2.17622072354778E-6,-3.57261683633227E-6,-2.20603946713419E-6,9.9994631,9.9994631,83923.9453125,83949.203125,57.7514047718907,20.6502370823923,12.658426,0,0,0,40,4449,10.03115,83936.57421875,,,,,,,,,,,,,0,,,,-0.0049,,,,,,9.9994631,,,,
,27290539.005,10.0014019,79307.921875,-1.37946821873356E-6,7.75670119327542E-7,1,0.999253354069792,40.0298881530762,1.99519381877842,25.4800003021955,-6.35682244065257E-6,-5.40979942912469E-5,0.25,-4.53779406583794E-6,-1.34861894202209E-6,-4.55481073934005E-6,10.0014019,10.0014019,79300.5078125,79315.3359375,57.4778347901599,20.6595389917361,13.038077,0,0,0,40,4449,10.0284,79307.921875,,,,,,,,,,,,,0,,,,0.00245,,,,,,10.0014019,,,,
,27290629.595,10.00337125,74776.73046875,-1.37892324216482E-6,8.55643726330202E-7,1,0.999253354069792,40.0298881530762,1.99530347708173,25.4800003021955,-9.22471652340575E-6,-3.80937320045746E-5,0.25,-3.12290779487982E-6,-1.35765120397127E-6,-3.13673385750992E-6,10.0033188,10.0034237,74766.78125,74786.6796875,57.4285921934484,20.657285267676,13.038077,0,0,0,40,4449,10.02595,74776.73046875,,,,,,,,,,,,,0,,,,-0.00245,,,,,,10.00337125,,,,
,27290717.275,10.0034122,70396,5.2586969497601E-7,7.5315862435147E-7,1,0.999253354069792,40.0298881530762,1.99502957917207,25.4800003021955,1.28919654625659E-5,-3.75165519352726E-5,0.25,-3.41663359100964E-6,5.51550591373397E-7,-3.41557630699552E-6,10.0034122,10.0034122,70388.6640625,70403.3359375,57.6138381525061,20.6636903811396,13.038077,0,0,0,40,4449,10.02175,70396,,,,,,,,,,,,,0,,,,0,,,,,,10.0034122,,,,
,27290806.555,10.0042171,65932.796875,-2.01127391475745E-7,7.53603113410713E-7,1,0.999253354069792,40.0298881530762,1.99490199786529,25.4800003021955,3.72181042506476E-7,-1.50717827297276E-5,0.25,-1.29887701443087E-6,-1.9157098257432E-7,-1.30094447324361E-6,10.0042171,10.0042171,65925.40625,65940.1875,58.0578031514292,20.6660054631479,12.658426,0,0,0,40,4449,10.019,65932.796875,,,,,,,,,,,,,0,,,,0,,,,,,10.0042171,,,,
,27290895.61,10.0043116,61481.92578125,1.09447934116718E-6,6.17960845416565E-7,1,0.999253354069792,40.0298881530762,1.99554739614887,25.4800003021955,1.46174069711392E-5,-1.03302212034144E-5,0.25,-1.1124679038865E-6,1.10280125477031E-6,-1.10436462047574E-6,10.0043116,10.0043116,61477.3828125,61486.46875,57.8358206519677,20.6571066443121,12.658426,0,0,0,40,4449,10.0158,61481.92578125,,,,,,,,,,,,,0,,,,0,,,,,,10.0043116,,,,
,27290986.475,10.0040331,56938.771484375,2.61071605308076E-6,7.02637915095897E-7,1,0.999253354069792,40.0298881530762,1.9951235345327,25.4800003021955,3.14990633540736E-5,-6.05993389145284E-6,0.25,-1.00778433977947E-6,2.61718868291971E-6,-9.87974489703858E-7,10.0040331,10.0040331,56933.953125,56943.58984375,57.271484861083,20.6599982155608,12.278775,0,0,0,40,4449,10.0118,56938.771484375,,,,,,,,,,,,,0,,,,0.0049,,,,,,10.0040331,,,,
,27291076.705,10.0039644,52431.19921875,4.02507237542047E-6,7.24332369325225E-7,1,0.999253354069792,40.0298881530762,1.99445517181334,25.4800003021955,4.82254606685978E-5,-7.66749190411475E-6,0.25,-1.40562269332793E-6,4.03212175690089E-6,-1.37464616071446E-6,10.0039644,10.0039644,52426.37109375,52436.02734375,57.657609349583,20.6714090835875,13.038077,0,0,0,40,4449,10.0085,52431.19921875,,,,,,,,,,,,,0,,,,-0.00245,,,,,,10.0039644,,,,
,27291166.375,10.0046949,47946.166015625,4.0839630049475E-6,5.35746117712854E-7,1,0.999253354069792,40.0298881530762,1.9946075524695,25.4800003021955,4.87285491321295E-5,-6.76194541077775E-6,0.25,-1.3358789770409E-6,4.08850827880557E-6,-1.30416634644605E-6,10.0046949,10.0046949,47938.859375,47953.47265625,57.7615659426407,20.6713990678381,12.278775,0,0,0,40,4449,10.00535,47946.166015625,,,,,,,,,,,,,0,,,,0,,,,,,10.0046949,,,,
,27291255.505,10.0038071,43492.837890625,5.99099446126542E-6,5.1388318396614E-7,1,0.999253354069792,40.0298881530762,1.99464302706612,25.4800003021955,6.85323094704755E-5,6.28106910769443E-6,0.25,-5.21098267864623E-7,5.98427977602194E-6,-4.76740524257322E-7,10.0038071,10.0038071,43490.06640625,43495.609375,57.7607843141215,20.6709084643809,12.658426,0,0,0,40,4449,10.00305,43492.837890625,,,,,,,,,,,,,0,,,,0,,,,,,10.0038071,,,,
,27291347.38,10.0033159,38900.330078125,6.4376238890622E-6,6.74986996079241E-7,1,0.999253354069792,40.0298881530762,1.99416138260123,25.4800003021955,7.43038124909549E-5,2.76527688262942E-6,0.25,-9.12670745538121E-7,6.42972932988363E-6,-8.647800513355E-7,10.0033159,10.0033159,38897.5546875,38903.10546875,57.8358206519677,20.6773286032009,13.038077,0,0,0,40,4449,9.9998,38900.330078125,,,,,,,,,,,,,0,,,,0,,,,,,10.0033159,,,,
,27291434.875,10.0027409,34527.720703125,7.97709297134343E-6,4.66525073885842E-7,1,0.999253354069792,40.0298881530762,1.9944002533607,25.4800003021955,9.25134833216368E-5,7.81060470691826E-7,0.25,-1.36467502820907E-6,7.96505733159219E-6,-1.30543535099486E-6,10.0027409,10.0027409,34520.4375,34535.00390625,57.4450063923522,20.6754927066312,12.658426,0,0,0,40,4449,9.99775,34527.720703125,,,,,,,,,,,,,0,,,,-0.00245,,,,,,10.0027409,,,,
,27291522.995,10.0020075,30122.453125,8.07438926323212E-6,4.69771374566624E-7,1,0.999253354069792,40.0298881530762,1.99459936703309,25.4800003021955,9.30961635450691E-5,3.61761229289903E-6,0.25,-1.12835611432248E-6,8.05646782949077E-6,-1.07011738719748E-6,10.0020075,10.0020075,30112.453125,30132.453125,57.9186732750061,20.6723570277346,12.658426,0,0,0,40,4449,9.9964,30122.453125,,,,,,,,,,,,,0,,,,0.00245,,,,,,10.0020075,,,,
,27291611.46,10.001132,25702.3359375,8.84840360349094E-6,5.21591288923676E-7,1,0.999253354069792,40.0298881530762,1.99464326328504,25.4800003021955,0.000101174323260329,8.41108758919611E-6,0.25,-8.38800312742673E-7,8.8218151396009E-6,-7.77881699225092E-7,10.001132,10.001132,25694.908203125,25709.763671875,57.5473997283715,20.6749226718557,13.038077,0,0,0,40,4449,9.99725,25702.3359375,,,,,,,,,,,,,0,,,,0.0049,,,,,,10.001132,,,,
,27291695.555,10.0016909,21499.3701171875,1.0350585238984E-5,3.32482949967457E-7,1,0.999253354069792,40.0298881530762,1.99456097782769,25.4800003021955,0.000116096087569231,2.20990501567792E-5,0.25,1.12719199169876E-7,1.03079685928929E-5,1.77392910109314E-7,10.0016909,10.0016909,21496.921875,21501.818359375,57.8373839090061,20.6734502368866,13.038077,0,0,0,40,4449,9.9973,21499.3701171875,,,,,,,,,,,,,0,,,,-0.0049,,,,,,10.0016909,,,,
,27291781.57,10.0010176,17202.369140625,1.05440140815533E-5,3.17124801118589E-7,1,0.999253354069792,40.0298881530762,1.99494340443291,25.4800003021955,0.000119874394202959,1.335632873804E-5,0.25,-6.96592956712655E-7,1.05011440473984E-5,-6.30106578258793E-7,10.0010176,10.0010176,17199.802734375,17204.935546875,57.616964666583,20.6671889127154,12.278775,0,0,0,40,4449,9.9958,17202.369140625,,,,,,,,,,,,,0,,,,0.00245,,,,,,10.0010176,,,,
,27291865.585,10.0007844,13001.9340820312,1.0513667879462E-5,3.87407052675425E-7,1,0.999253354069792,40.0298881530762,1.99525440660661,25.4800003021955,0.000118435089857431,1.92752535382632E-5,0.25,-1.6087572394519E-7,1.04636746132549E-5,-1.00019739731047E-7,10.000679,10.0008898,12996.8095703125,13007.05859375,57.4622022197753,20.6625908658316,12.658426,0,0,0,40,4449,9.9954,13001.9340820312,,,,,,,,,,,,,0,,,,-0.0049,,,,,,10.0007844,,,,
,27291950.89,9.9990835,8738.916015625,1.17786994444255E-5,3.22678403934998E-7,1,0.999253354069792,40.0298881530762,1.99478513733786,25.4800003021955,0.0001330520803432,1.90889498323742E-5,0.25,-3.98566004788242E-7,1.17196652923079E-5,-3.32882178489946E-7,9.9990835,9.9990835,8728.896484375,8748.935546875,57.4160861371407,20.6683510959817,12.658426,0,0,0,40,4449,9.99635,8738.916015625,,,,,,,,,,,,,0,,,,0.0049,,,,,,9.9990835,,,,
,27292035.64,9.999527,4503.5126953125,1.18429199657249E-5,2.94164458642674E-7,1,0.999253354069792,40.0298881530762,1.99513807797241,25.4800003021955,0.00013302404646929,2.33127367416081E-5,0.25,-2.98896511972243E-8,1.17779215046498E-5,3.05844634736724E-8,9.999527,9.999527,4495.92724609375,4511.09814453125,57.6857479762753,20.6664997144008,12.658426,0,0,0,40,4449,9.9965,4503.5126953125,,,,,,,,,,,,,0,,,,0.0049,,,,,,9.999527,,,,
,27292122.75,10.0026941,147.339385986328,1.24452783035044E-5,3.40802524463777E-7,1,0.999253354069792,40.0298881530762,1.99512865705208,25.4800003021955,0.000139921921510176,2.35546778270461E-5,0.25,-1.11611786227414E-7,1.23743728983822E-5,-5.09279696034949E-8,10.0026941,10.0026941,137.440551757812,157.238220214844,57.6138381525061,20.6641430164167,12.278775,0,0,0,40,4449,9.9955,147.339385986328,,,,,,,,,,,,,0,,,,0,,,,,,10.0026941,,,,
,27292126.745,10.0034342,-0.19790904968977,1.30653883796355E-5,3.38469762930539E-7,1,0.999253354069792,40.0298881530762,1.99516043960607,25.4800003021955,0.000147146369097831,2.33155286693452E-5,0.25,-2.42996915993541E-7,1.29915043705488E-5,-1.78626711755795E-7,10.0034342,10.0034342,-0.228356599807739,-0.1674614995718,57.5270773868715,20.663807931299,12.278775,0,0,0,40,4417,9.99295,-0.19790904968977,,,,,,,,,,,,,0,,,,-0.00245,,,,,,10.0034342,,,,