File: data/monolayers/nanoparticles/Ac_CoFe_C/vsm/rawdata/DD226_2_FCW_100OE.DAT
[Header]
; VSM Data File (default extension .dat)
; Copyright (c) 2003-2013, Quantum Design, Inc. All rights reserved.
TITLE,
FILEOPENTIME,27407600.61,11/14/2018,1:13 pm
BYAPP,VSM,2.0,2.0
INFO,PPMS VSM Option Release 1.4.10 Build 1,APPNAME
INFO,Quantum Design Linear Motor Servo Controller,MOTOR_MODULE_NAME
INFO,3101-100 M1,MOTOR_HW_VERSION
INFO,MMC1014,MOTOR_SERIAL_NUMBER
INFO,SRV No X-over 01.03.11,MOTOR_SOFTWARE_VERSION
INFO,Quantum Design VSM Detection Module,VSM_MODULE_NAME
INFO,3101-150 F0,VSM_HW_VERSION
INFO,VSM707,VSM_SERIAL_NUMBER
INFO,VSM No X-over 01.02.05 May 20 2008 13:51:47,VSM_SOFTWARE_VERSION
INFO,704,PREAMP_SERIAL_NUMBER
INFO,822,COIL_SERIAL_NUMBER
INFO,0,MOMENT_UNITS
INFO,CoFe2O4 AH11,SAMPLE_MATERIAL
INFO,Quick Dry Monolayer Conc,SAMPLE_COMMENT
INFO,27.96,SAMPLE_MASS
INFO,,SAMPLE_VOLUME
INFO,,SAMPLE_MOLECULAR_WEIGHT
INFO,,SAMPLE_SIZE
INFO,,SAMPLE_SHAPE
DATATYPE,COMMENT,1
DATATYPE,TIME,2
STARTUPAXIS,X,2
STARTUPAXIS,Y1,5
[Data]
Comment,Time Stamp (sec),Temperature (K),Magnetic Field (Oe),Moment (emu),M. Std. Err. (emu),Transport Action,Averaging Time (sec),Frequency (Hz),Peak Amplitude (mm),Center Position (mm),Coil Signal' (mV),Coil Signal" (mV),Range (mV),M. Quad. Signal (emu),M. Raw' (emu),M. Raw" (emu),Min. Temperature (K),Max. Temperature (K),Min. Field (Oe),Max. Field (Oe),Mass (grams),Motor Lag (deg),Pressure (Torr),VSM Status (code),Motor Status (code),Measure Status (code),Measure Count,PPMS Status (code),System Temp. (K),System Field (Oe),Sample Position (deg),Bridge 1 Resistance (ohms),Bridge 1 Excitation (에),Bridge 2 Resistance (ohms),Bridge 2 Excitation (에),Bridge 3 Resistance (ohms),Bridge 3 Excitation (에),Bridge 4 Resistance (ohms),Bridge 4 Excitation (에),Signal 1 Vin (V),Signal 2 Vin (V),Digital Inputs (code),Drive 1 Iout (mA),Drive 1 Ipower (W),Drive 2 Iout (mA),Drive 2 Ipower (W),Pressure (),Map 20 (),Map 21 (),Map 22 (),Map 23 (),Map 24 (),Map 25 (),Map 26 (),Map 27 (),Map 28 (),Map 29 ()
,27407730.05,10.0041161,99.7004928588867,9.94822896598417E-6,2.59625963845515E-7,1,0.999253354069792,40.0298881530762,2.00781172142498,21.7000003904104,0.000112205229039354,2.07479750905281E-5,0.25,7.06490386964398E-8,9.89076431388923E-6,1.18222014960397E-7,10.0041161,10.0041161,99.7004928588867,99.7004928588867,56.892395029256,20.6473867782025,13.038077,0,0,0,40,4369,9.9911,99.7004928588867,,,,,,,,,,,,,0,,,,-0.0049,,,,,,10.0041161,,,,
,27407861.225,13.0510511,99.7004928588867,1.01124710928662E-5,2.99711874459869E-7,1,0.999253354069792,40.0298881530762,2.00766895732856,21.7000003904104,0.000114587869928236,1.80560118875375E-5,0.25,-1.96769705746405E-7,1.00552933714373E-5,-1.46868194764734E-7,13.0510511,13.0510511,99.7004928588867,99.7004928588867,57.0674798175637,20.6496764392611,14.556682,0,0,0,40,4370,13.16345,99.7004928588867,,,,,,,,,,,,,0,,,,-0.00245,,,,,,13.0510511,,,,
,27408001.525,16.5477982,99.7004928588867,1.00014767259273E-5,3.48990682562443E-7,1,0.999253354069792,40.0298881530762,2.00752851462077,21.7000003904104,0.000113156631525235,1.87848794604613E-5,0.25,-1.12387248337531E-7,9.94443367572877E-6,-6.35054583209944E-8,16.5477982,16.5477982,99.7004928588867,99.7004928588867,57.6896561188715,20.6487364487284,15.315984,0,0,0,40,4370,16.69215,99.7004928588867,,,,,,,,,,,,,0,,,,0,,,,,,16.5477982,,,,
,27408139.54,20.0105495,99.7004928588867,9.95250033261774E-6,3.27141049522257E-7,1,0.999253354069792,40.0298881530762,2.00749599989125,21.7000003904104,0.000113055917836142,1.61386363478152E-5,0.25,-3.38341005301051E-7,9.89696595133803E-6,-2.88105194429203E-7,20.0105495,20.0105495,99.7004928588867,99.7004928588867,57.2699216040445,20.6501042243466,15.315984,0,0,0,40,4370,20.15655,99.7004928588867,,,,,,,,,,,,,0,,,,0,,,,,,20.0105495,,,,
,27408282.68,23.5473557,99.7004928588867,1.01616433334216E-5,3.44388093736355E-7,1,0.999253354069792,40.0298881530762,1.9947566943899,21.7199996113777,0.000114393969540919,1.83561499504941E-5,0.25,-1.70749887227214E-7,1.01051731131463E-5,-1.19100077936603E-7,23.5473557,23.5473557,99.7004928588867,99.7004928588867,57.2527257766214,20.6487339961988,15.695635,0,0,0,40,4370,23.75895,99.7004928588867,,,,,,,,,,,,,0,,,,0,,,,,,23.5473557,,,,
,27408422.135,27.0029125,99.7004928588867,1.00998158344824E-5,3.18570264077347E-7,1,0.999253354069792,40.0298881530762,1.99471652577675,21.7199996113777,0.000113465924996605,1.9675889746666E-5,0.25,-4.49303880177947E-8,1.00451720566525E-5,8.10662637851339E-9,27.0029125,27.0029125,99.7004928588867,99.7004928588867,57.2355299491984,20.648740671911,16.454937,0,0,0,40,4370,27.2753,99.7004928588867,,,,,,,,,,,,,0,,,,0,,,,,,27.0029125,,,,
,27408565.3,30.5626316,99.7004928588867,1.00448904725273E-5,3.34006730386494E-7,1,0.999253354069792,40.0298881530762,1.99465564862342,21.7199996113777,0.000113149261435765,1.80933132340474E-5,0.25,-1.80135049983573E-7,9.99476702033944E-6,-1.23234432959525E-7,30.5626316,30.5626316,99.7004928588867,99.7004928588867,57.2073913225061,20.6485671586447,16.834587,0,0,0,40,4370,30.8666,99.7004928588867,,,,,,,,,,,,,0,,,,-0.00245,,,,,,30.5626316,,,,
,27408705.345,34.00865745,99.7004928588867,9.98264855381499E-6,3.68804744469194E-7,1,0.999253354069792,40.0298881530762,1.99484828316005,21.7199996113777,0.000112621809863355,1.73984250338054E-5,0.25,-2.36039667229526E-7,9.93820239482636E-6,-1.75126541555453E-7,33.9780197,34.0392952,99.7004928588867,99.7004928588867,56.8384626614291,20.6461894539024,17.214239,0,0,0,40,4370,34.4106,99.7004928588867,,,,,,,,,,,,,0,,,,0,,,,,,34.00865745,,,,
,27408848.65,37.5307159,99.7004928588867,1.01517151980322E-5,3.4963473324744E-7,1,0.999253354069792,40.0298881530762,1.9948437850447,21.7199996113777,0.000114255441704559,1.9678972321111E-5,0.25,-6.91574700032059E-8,1.01124671511213E-5,-3.34015466185763E-9,37.5307159,37.5307159,99.7004928588867,99.7004928588867,57.3254172289099,20.6419133583751,17.214239,0,0,0,40,4370,38.01915,99.7004928588867,,,,,,,,,,,,,0,,,,-0.0049,,,,,,37.5307159,,,,
,27408990.515,41.0532722,99.7004928588867,1.00554998803021E-5,3.92160990657647E-7,1,0.999253354069792,40.0298881530762,1.99490367600295,21.7199996113777,0.000113288751716793,1.94295565877523E-5,0.25,-7.99782709120388E-8,1.00253905624526E-5,-1.04384732893942E-8,41.0532722,41.0532722,99.7004928588867,99.7004928588867,56.8376810329099,20.643769758408,17.973541,0,0,0,40,4370,41.6089,99.7004928588867,,,,,,,,,,,,,0,,,,-0.0049,,,,,,41.0532722,,,,
,27409131.21,44.5061531,99.7004928588867,1.00650715245514E-5,3.73953648605512E-7,1,0.999253354069792,40.0298881530762,1.98314414548625,21.7099990695715,0.000112704515462418,2.02896291122381E-5,0.25,-1.85838033102399E-10,1.00444816319874E-5,7.25594180615651E-8,44.5061531,44.5061531,99.7004928588867,99.7004928588867,57.3566823696791,20.6479888287146,18.353191,0,0,0,40,4370,45.1627,99.7004928588867,,,,,,,,,,,,,0,,,,-0.00245,,,,,,44.5061531,,,,
,27409274.69,48.0539703,99.7004928588867,9.87759647310838E-6,2.99027470996523E-7,1,0.999253354069792,40.0298881530762,1.98296837533806,21.7099990695715,0.000111032799151306,1.82014170204238E-5,0.25,-1.56411304079231E-7,9.8696696115341E-6,-8.3009080312018E-8,48.0539703,48.0539703,99.7004928588867,99.7004928588867,57.1323549846599,20.6491535877583,18.353191,0,0,0,40,4370,48.8106,99.7004928588867,,,,,,,,,,,,,0,,,,0,,,,,,48.0539703,,,,
,27409418.275,51.5345764,99.7004928588867,9.81968441165947E-6,3.7067108586048E-7,1,0.999253354069792,40.0298881530762,1.98294211718219,21.7199996113777,0.000110738323945785,1.68330066484205E-5,0.25,-2.6970509646093E-7,9.82392393679427E-6,-1.96909592130444E-7,51.5345764,51.5345764,99.7004928588867,99.7004928588867,57.2746113751599,20.6522094544433,19.492144,0,0,0,40,4370,52.474,99.7004928588867,,,,,,,,,,,,,0,,,,-0.0049,,,,,,51.5345764,,,,
,27409559.68,55.0006752,99.7004928588867,9.69422094715394E-6,3.40705858057423E-7,1,0.999253354069792,40.0298881530762,1.99458696872327,21.7000003904104,0.000109341113550316,2.06837074183924E-5,0.25,8.55531082057718E-8,9.70616398138579E-6,1.55935029521226E-7,54.9709358,55.0304146,99.7004928588867,99.7004928588867,57.2081729510253,20.6446522034721,20.251448,0,0,0,40,4374,56.0814,99.7004928588867,,,,,,,,,,,,,0,,,,-0.0049,,,,,,55.0006752,,,,
,27409703.325,58.5582504,99.7004928588867,9.62515578752172E-6,2.97435806385062E-7,1,0.999253354069792,40.0298881530762,1.99467687053582,21.7000003904104,0.000109738050013328,1.46175097769971E-5,0.25,-4.3722431307639E-7,9.64987714556846E-6,-3.71407620981594E-7,58.5582504,58.5582504,99.7004928588867,99.7004928588867,57.5825730117369,20.6461839749222,20.251448,0,0,0,40,4374,59.7189,99.7004928588867,,,,,,,,,,,,,0,,,,0,,,,,,58.5582504,,,,
,27409844.28,62.0180244,99.7004928588867,1.02382245910753E-5,3.50734012753815E-7,1,0.999253354069792,40.0298881530762,1.9947752645458,21.7000003904104,0.000116623495328391,1.66773725849021E-5,0.25,-3.62453615154721E-7,1.02718204486612E-5,-2.96471755111711E-7,62.0180244,62.0180244,99.7004928588867,99.7004928588867,57.2488176340253,20.6471004614491,20.631098,0,0,0,40,4374,63.2863,99.7004928588867,,,,,,,,,,,,,0,,,,0,,,,,,62.0180244,,,,
,27409965.22,65.0042801,99.7004928588867,1.04211529888435E-5,2.61784708296335E-7,1,0.999253354069792,40.0298881530762,1.98322905252962,21.679999306798,0.000117706805503251,1.91771621749304E-5,0.25,-1.62100051820458E-7,1.04598412751189E-5,-9.8213784358308E-8,65.0042801,65.0042801,99.7004928588867,99.7004928588867,56.9705578811791,20.6449169959797,21.01075,0,0,0,40,4374,66.3427,99.7004928588867,,,,,,,,,,,,,0,,,,0.0049,,,,,,65.0042801,,,,
,27410107.04,68.5008774,99.7004928588867,9.81027405854936E-6,3.23238865257943E-7,1,0.999253354069792,40.0298881530762,1.98300850781954,21.679999306798,0.000110823012553245,1.82327187321212E-5,0.25,-1.33008542283858E-7,9.85181127618255E-6,-7.71720891676901E-8,68.5008774,68.5008774,99.7004928588867,99.7004928588867,57.4254656793715,20.6513318414614,21.01075,0,0,0,40,4374,69.9294,99.7004928588867,,,,,,,,,,,,,0,,,,0,,,,,,68.5008774,,,,
,27410249.62,72.0024719,99.7004928588867,1.02732044966396E-5,3.03540511067524E-7,1,0.999253354069792,40.0298881530762,1.98317273054942,21.679999306798,0.000116471107267791,1.70737969738486E-5,0.25,-3.14786577421975E-7,1.03219412425714E-5,-2.61589532322541E-7,72.0024719,72.0024719,99.7004928588867,99.7004928588867,57.1151591572368,20.6481781691074,21.01075,0,0,0,40,4374,73.54025,99.7004928588867,,,,,,,,,,,,,0,,,,0,,,,,,72.0024719,,,,
,27410372.195,75.0336151,99.7004928588867,9.82734595456957E-6,3.21908339055575E-7,1,0.999253354069792,40.0298881530762,1.98316110830358,21.6499995440245,0.000110804606798646,1.9946152657596E-5,0.25,2.2253203795729E-8,9.87505521724735E-6,7.12107333054491E-8,75.0336151,75.0336151,99.7004928588867,99.7004928588867,57.126101956506,20.6455093743814,21.3904,0,0,0,40,4374,76.639,99.7004928588867,,,,,,,,,,,,,0,,,,0,,,,,,75.0336151,,,,
,27410515.79,78.5774994,99.7004928588867,9.9347524936271E-6,3.40532779419023E-7,1,0.999253354069792,40.0298881530762,1.98317185805789,21.6499995440245,0.000111851339449131,2.12616354978615E-5,0.25,1.23046496604767E-7,9.98510191005798E-6,1.69301128663593E-7,78.5774994,78.5774994,99.7004928588867,99.7004928588867,57.1026531009291,20.649908309762,21.770052,0,0,0,40,4374,80.2822,99.7004928588867,,,,,,,,,,,,,0,,,,-0.00245,,,,,,78.5774994,,,,
,27410655.08,82.0313492,99.7004928588867,1.01480862464094E-5,2.51666243132372E-7,1,0.999253354069792,40.0298881530762,1.98326396257039,21.6499995440245,0.000114890137898318,1.8274272814124E-5,0.25,-1.76516621403153E-7,1.02027479967816E-5,-1.34236754983525E-7,82.0313492,82.0313492,99.7004928588867,99.7004928588867,57.115940785756,20.6460992777559,21.770052,0,0,0,40,4374,83.81875,99.7004928588867,,,,,,,,,,,,,0,,,,-0.00245,,,,,,82.0313492,,,,
,27410796.46,85.5393524,99.7004928588867,1.02357408537806E-5,2.90052877709905E-7,1,0.999253354069792,40.0298881530762,1.99474428924057,21.6300003230572,0.000117016421917221,1.58285134744391E-5,0.25,-4.13519906137656E-7,1.02931553095629E-5,-3.75270059311354E-7,85.5393524,85.5393524,99.7004928588867,99.7004928588867,57.3902923960061,20.6454287014649,22.149702,0,0,0,40,4374,87.36135,99.7004928588867,,,,,,,,,,,,,0,,,,-0.00245,,,,,,85.5393524,,,,
,27410936.01,89.01047895,99.7004928588867,9.9100316896821E-6,3.00387173252616E-7,1,0.999253354069792,40.0298881530762,1.99450092774493,21.6300003230572,0.000112872345486602,1.76880652726617E-5,0.25,-1.89476719634107E-7,9.96568934906903E-6,-1.53973130751479E-7,88.970787,89.0501709,99.7004928588867,99.7004928588867,57.2839909173907,20.6466392294066,21.770052,0,0,0,40,4374,90.8669,99.7004928588867,,,,,,,,,,,,,0,,,,0,,,,,,89.01047895,,,,
,27411078.645,92.5866013,99.7004928588867,1.01616017411661E-5,3.43857450117973E-7,1,0.999253354069792,40.0298881530762,1.99462251365388,21.6300003230572,0.000115322657124263,2.05734047012825E-5,0.25,2.26064305956036E-8,1.02185466233084E-5,5.7714340680521E-8,92.5866013,92.5866013,99.7004928588867,99.7004928588867,57.7748536274677,20.6463423366045,22.149702,0,0,0,40,4374,94.44925,99.7004928588867,,,,,,,,,,,,,0,,,,0,,,,,,92.5866013,,,,
,27411219.47,96.0611649,99.7004928588867,9.83615150386327E-6,3.79863273973053E-7,1,0.999253354069792,40.0298881530762,1.98342858975542,21.5900000184774,0.000111597787357878,1.66104817880107E-5,0.25,-2.59163286009928E-7,9.89258229377938E-6,-2.28914012913601E-7,96.0611649,96.0611649,99.7004928588867,99.7004928588867,57.2503808910638,20.6464049703593,22.149702,0,0,0,40,4374,97.98995,99.7004928588867,,,,,,,,,,,,,0,,,,0.00245,,,,,,96.0611649,,,,
,27411359.565,99.5500565,99.7004928588867,9.72788274240169E-6,3.24078405704027E-7,1,0.999253354069792,40.0298881530762,1.98359659568945,21.5900000184774,0.000110569615361331,1.53486489403529E-5,0.25,-3.50092802883034E-7,9.78411067109896E-6,-3.22606674479685E-7,99.5500565,99.5500565,99.7004928588867,99.7004928588867,56.9009929429675,20.6448211353471,22.529354,0,0,0,40,4374,101.5006,99.7004928588867,,,,,,,,,,,,,0,,,,0,,,,,,99.5500565,,,,
,27411501.055,103.0387344,99.7004928588867,1.01722107725097E-5,3.26413271990883E-7,1,0.999253354069792,40.0298881530762,1.98348385128598,21.5900000184774,0.00011496736559734,1.97291534464489E-5,0.25,-3.84289393266464E-8,1.02300405993203E-5,-9.63965442452357E-9,103.0387344,103.0387344,99.7004928588867,99.7004928588867,56.9908802226791,20.6440003620652,22.529354,0,0,0,40,4374,105.0643,99.7004928588867,,,,,,,,,,,,,0,,,,0.00245,,,,,,103.0387344,,,,
,27411641.545,106.5244141,99.7004928588867,9.7288809366731E-6,3.91220772528805E-7,1,0.999253354069792,40.0298881530762,1.98376056412819,21.5600002557039,0.000110045982954008,1.84387897393398E-5,0.25,-7.35290314162334E-8,9.78417235010849E-6,-4.77498020720819E-8,106.5244141,106.5244141,99.7004928588867,99.7004928588867,57.6724602914484,20.6421758961479,22.529354,0,0,0,40,4374,108.59625,99.7004928588867,,,,,,,,,,,,,0,,,,0,,,,,,106.5244141,,,,
,27411782.075,110.046875,99.7004928588867,9.66865938440743E-6,2.81299493170754E-7,1,0.999253354069792,40.0298881530762,1.98372042011112,21.5600002557039,0.000109453491402046,1.77898092927548E-5,0.25,-1.18963110151127E-7,9.72348446442764E-6,-9.49952362627007E-8,110.046875,110.046875,99.7004928588867,99.7004928588867,57.126101956506,20.6487076454719,22.909004,0,0,0,40,4374,112.1382,99.7004928588867,,,,,,,,,,,,,0,,,,-0.00245,,,,,,110.046875,,,,
,27411921.29,113.5149612,99.7004928588867,1.02043005392686E-5,3.59481407428469E-7,1,0.999253354069792,40.0298881530762,1.98333528164724,21.5600002557039,0.000116209576366798,1.4670583820414E-5,0.25,-4.87328731684346E-7,1.02626838635159E-5,-4.65375169230921E-7,113.5149612,113.5149612,99.7004928588867,99.7004928588867,57.4332819645638,20.6473967320984,22.529354,0,0,0,40,4374,115.63495,99.7004928588867,,,,,,,,,,,,,0,,,,0.0049,,,,,,113.5149612,,,,
,27412064.79,117.0450058,99.7004928588867,9.74142321654104E-6,3.03253325664286E-7,1,0.999253354069792,40.0298881530762,1.98351292846058,21.5199999511242,0.00011074154065851,1.51539760239586E-5,0.25,-3.62374762291195E-7,9.79645954242234E-6,-3.42007747810044E-7,117.0450058,117.0450058,99.7004928588867,99.7004928588867,57.3738781971022,20.642283779406,22.909004,0,0,0,40,4374,119.251,99.7004928588867,,,,,,,,,,,,,0,,,,0,,,,,,117.0450058,,,,
,27412205.1,120.5507622,99.7004928588867,9.89527067333185E-6,3.06508289744391E-7,1,0.999253354069792,40.0298881530762,1.98346865172889,21.5199999511242,0.000112097176083318,1.75938618384973E-5,0.25,-1.72094233511621E-7,9.95021702755012E-6,-1.51370834104499E-7,120.5233765,120.5781479,99.7004928588867,99.7004928588867,57.2456911199484,20.6423074685754,22.909004,0,0,0,40,4374,122.76975,99.7004928588867,,,,,,,,,,,,,0,,,,0,,,,,,120.5507622,,,,
,27412344.385,124.0364227,99.7004928588867,9.64762470493823E-6,3.15106938662451E-7,1,0.999253354069792,40.0298881530762,1.98335651421531,21.5199999511242,0.000109233224400202,1.74171586308409E-5,0.25,-1.43335090121143E-7,9.70059324727051E-6,-1.23933950922153E-7,124.0364227,124.0364227,99.7004928588867,99.7004928588867,57.1346998702176,20.6428028712822,23.668306,0,0,0,40,4374,126.2792,99.7004928588867,,,,,,,,,,,,,0,,,,0,,,,,,124.0364227,,,,
,27412484.82,127.5134201,99.7004928588867,9.66851788384126E-6,3.27971531858531E-7,1,0.999253354069792,40.0298881530762,2.00757940459988,21.4799996465445,0.000110445693326705,1.93352273360474E-5,0.25,4.10574899037001E-9,9.72070559537971E-6,2.3482668753404E-8,127.5134201,127.5134201,99.7004928588867,99.7004928588867,57.4590757056984,20.6341485052484,22.909004,0,0,0,40,4374,129.8014,99.7004928588867,,,,,,,,,,,,,0,,,,-0.00245,,,,,,127.5134201,,,,
,27412626.82,131.0124054,99.7004928588867,9.69547645108188E-6,3.34627393620733E-7,1,0.999253354069792,40.0298881530762,2.00768310314711,21.4799996465445,0.000110742185914631,1.94440255607469E-5,0.25,9.75559091619031E-9,9.74715956170033E-6,2.84047777465062E-8,131.0124054,131.0124054,99.7004928588867,99.7004928588867,57.159711982833,20.6333576727269,23.668306,0,0,0,40,4374,133.35815,99.7004928588867,,,,,,,,,,,,,0,,,,0,,,,,,131.0124054,,,,
,27412769.29,134.5658722,99.7004928588867,9.68970142111323E-6,3.49737241390105E-7,1,0.999253354069792,40.0298881530762,2.00765469873411,21.4799996465445,0.000110513635282784,2.03088439560968E-5,0.25,8.7360386866325E-8,9.74051627592352E-6,1.05655524467844E-7,134.5658722,134.5658722,99.7004928588867,99.7004928588867,57.2331850636407,20.6370164754396,24.047956,0,0,0,40,4374,136.935,99.7004928588867,,,,,,,,,,,,,0,,,,0,,,,,,134.5658722,,,,
,27412888.125,137.5322418,99.7004928588867,9.44733298537729E-6,3.33910229219037E-7,1,0.999253354069792,40.0298881530762,1.98361220748614,21.4399993419647,0.000106851003022207,1.76222870244514E-5,0.25,-8.70349413209266E-8,9.49659267394918E-6,-7.06644807060138E-8,137.5322418,137.5322418,99.7004928588867,99.7004928588867,57.0565370182945,20.6379011708781,23.668306,0,0,0,40,4374,139.9187,99.7004928588867,,,,,,,,,,,,,0,,,,-0.0049,,,,,,137.5322418,,,,
,27413028.155,141.0488586,99.7004928588867,9.90772850081557E-6,3.52936447785797E-7,1,0.999253354069792,40.0298881530762,1.9833453637854,21.4399993419647,0.000111829722067308,1.96544920420742E-5,0.25,1.364648983749E-8,9.95842767240804E-6,3.07064867039638E-8,141.0488586,141.0488586,99.7004928588867,99.7004928588867,57.8889713912754,20.6416840517579,23.288654,0,0,0,40,4374,143.4388,99.7004928588867,,,,,,,,,,,,,0,,,,-0.00245,,,,,,141.0488586,,,,
,27413168.73,144.541748,99.7004928588867,9.91326739907396E-6,3.17657414556436E-7,1,0.999253354069792,40.0298881530762,1.98376714558442,21.4399993419647,0.000112073143713906,1.87085705590123E-5,0.25,-7.07041537060281E-8,9.96333324146778E-6,-5.46677070870778E-8,144.541748,144.541748,99.7004928588867,99.7004928588867,57.8561429934677,20.6416940519524,24.047956,0,0,0,40,4374,146.9683,99.7004928588867,,,,,,,,,,,,,0,,,,-0.0049,,,,,,144.541748,,,,
,27413288.73,147.5158691,99.7004928588867,9.7434321278441E-6,3.88303160059423E-7,1,0.999253354069792,40.0298881530762,1.98370633812327,21.4000009000301,0.000110860105580914,1.42644658688437E-5,0.25,-4.3408911632641E-7,9.79252749387584E-6,-4.20609671932509E-7,147.5158691,147.5158691,99.7004928588867,99.7004928588867,57.2019199228714,20.6388971050758,24.427608,0,0,0,40,4374,149.9849,99.7004928588867,,,,,,,,,,,,,0,,,,0,,,,,,147.5158691,,,,
,27413428.57,151.0105591,99.7004928588867,9.69297031812065E-6,3.77076260665813E-7,1,0.999253354069792,40.0298881530762,1.98361396047633,21.4000009000301,0.000109394771232602,1.92212928310799E-5,0.25,1.44691716550417E-8,9.74025713139738E-6,2.95805323104575E-8,150.9806519,151.0404663,99.7004928588867,99.7004928588867,57.3762230826599,20.6409857284386,23.668306,0,0,0,40,4374,153.48155,99.7004928588867,,,,,,,,,,,,,0,,,,-0.00245,,,,,,151.0105591,,,,
,27413569.725,154.5167084,99.7004928588867,9.32108828774521E-6,2.7723551822889E-7,1,0.999253354069792,40.0298881530762,1.98344782132975,21.4000009000301,0.000104690876230702,2.12895733760629E-5,0.25,2.63232155049918E-7,9.36535419701226E-6,2.78490054779026E-7,154.5167084,154.5167084,99.7004928588867,99.7004928588867,57.4715817620061,20.6415111561429,24.047956,0,0,0,40,4374,157.0234,99.7004928588867,,,,,,,,,,,,,0,,,,0.00245,,,,,,154.5167084,,,,
,27413691.37,157.5603943,99.7004928588867,9.81058209362788E-6,3.7815604907734E-7,1,0.999253354069792,40.0298881530762,1.98364543130509,21.3500000536442,0.000111254407218195,1.6296463206863E-5,0.25,-2.63997193652368E-7,9.85719263893374E-6,-2.50905366775942E-7,157.5603943,157.5603943,99.7004928588867,99.7004928588867,57.7811066556215,20.6424904011906,24.047956,0,0,0,40,4374,160.06255,99.7004928588867,,,,,,,,,,,,,0,,,,0,,,,,,157.5603943,,,,
,27413828.93,161.0041351,99.7004928588867,9.80224089094775E-6,3.79645331782186E-7,1,0.999253354069792,40.0298881530762,1.98359120740057,21.3500000536442,0.000111414461865705,1.47413614001461E-5,0.25,-3.99742076642818E-7,9.84808924406002E-6,-3.87688073694257E-7,161.0041351,161.0041351,99.7004928588867,99.7004928588867,57.4958122461022,20.6437243736321,24.427608,0,0,0,40,4374,163.51415,99.7004928588867,,,,,,,,,,,,,0,,,,-0.00245,,,,,,161.0041351,,,,
,27413970.635,164.5030975,99.7004928588867,1.01166812607548E-5,4.17017357070783E-7,1,0.999253354069792,40.0298881530762,1.98357624552715,21.3500000536442,0.000114461769720132,1.81709086446921E-5,0.25,-1.500080366183E-7,1.01626529023528E-5,-1.36760545489237E-7,164.5030975,164.5030975,99.7004928588867,99.7004928588867,57.2230238928907,20.6454584093312,24.427608,0,0,0,40,4374,167.05705,99.7004928588867,,,,,,,,,,,,,0,,,,-0.0049,,,,,,164.5030975,,,,
,27414111.015,168.0348663,99.7004928588867,9.72915187213264E-6,3.72647342091225E-7,1,0.999253354069792,40.0298881530762,1.98355424012721,21.2999992072582,0.000109983506794055,1.79421799937956E-5,0.25,-1.02302987643696E-7,9.77233891842484E-6,-8.97396707663172E-8,168.0348663,168.0348663,99.7004928588867,99.7004928588867,56.9338213407753,20.6460566785036,24.427608,0,0,0,40,4374,170.569,99.7004928588867,,,,,,,,,,,,,0,,,,0,,,,,,168.0348663,,,,
,27414251.62,171.5589447,99.7004928588867,9.68642888747701E-6,3.42872253489965E-7,1,0.999253354069792,40.0298881530762,1.98332786255854,21.2999992072582,0.000109622812169676,1.70246546233478E-5,0.25,-1.75516501189711E-7,9.72854441344502E-6,-1.63670424513138E-7,171.5589447,171.5589447,99.7004928588867,99.7004928588867,56.922878541506,20.6472088414888,24.427608,0,0,0,40,4374,174.08795,99.7004928588867,,,,,,,,,,,,,0,,,,-0.0049,,,,,,171.5589447,,,,
,27414390.69,175.0465698,99.7004928588867,9.67431244881443E-6,3.99090000059648E-7,1,0.999253354069792,40.0298881530762,1.98324315088776,21.2999992072582,0.000109172519949236,1.8712412062252E-5,0.25,-2.32447184936522E-8,9.71519645814004E-6,-1.10829675169747E-8,175.0465698,175.0465698,99.7004928588867,99.7004928588867,57.3902923960061,20.6504515179702,24.047956,0,0,0,40,4374,177.5649,99.7004928588867,,,,,,,,,,,,,0,,,,-0.0049,,,,,,175.0465698,,,,
,27414529.065,178.5205994,99.7004928588867,9.74142599912396E-6,3.9928683578616E-7,1,0.999253354069792,40.0298881530762,1.98334241298294,21.2500002235174,0.000111289644533825,1.0985001337494E-5,0.25,-7.19597444351244E-7,9.78245335506148E-6,-7.10529674257193E-7,178.5205994,178.5205994,99.7004928588867,99.7004928588867,56.8705094307176,20.6446031692921,24.807261,0,0,0,40,4374,181.026,99.7004928588867,,,,,,,,,,,,,0,,,,0,,,,,,178.5205994,,,,
,27414671.28,182.0552216,99.7004928588867,9.87492675493666E-6,3.88261382512738E-7,1,0.999253354069792,40.0298881530762,1.98356404041634,21.2500002235174,0.000111840891539112,1.6738087450785E-5,0.25,-2.32452815871106E-7,9.91484898375275E-6,-2.21497129934878E-7,182.0552216,182.0552216,99.7004928588867,99.7004928588867,57.2347483206791,20.6446106043538,24.807261,0,0,0,40,4374,184.59545,99.7004928588867,,,,,,,,,,,,,0,,,,0,,,,,,182.0552216,,,,
,27414809.85,185.5252686,99.7004928588867,9.80429270160731E-6,3.16326671710123E-7,1,0.999253354069792,40.0298881530762,1.98337622157943,21.2500002235174,0.000110958401641518,1.69644433047685E-5,0.25,-1.99532379007196E-7,9.84285096478262E-6,-1.88791251137336E-7,185.5252686,185.5252686,99.7004928588867,99.7004928588867,57.3355783996599,20.6461893022067,25.186911,0,0,0,40,4374,188.0678,99.7004928588867,,,,,,,,,,,,,0,,,,0,,,,,,185.5252686,,,,
,27414952.08,189.0509338,99.7004928588867,9.59532941644908E-6,4.00378894820907E-7,1,0.999253354069792,40.0298881530762,1.98337731226291,21.1999993771315,0.000108466234385583,1.72658016334995E-5,0.25,-1.36062691898041E-7,9.63194979293348E-6,-1.25574164004856E-7,189.0509338,189.0509338,99.7004928588867,99.7004928588867,57.1941036376791,20.6405488730094,24.427608,0,0,0,40,4374,191.6358,99.7004928588867,,,,,,,,,,,,,0,,,,0.0049,,,,,,189.0509338,,,,
,27415090.99,192.519104,99.7004928588867,9.92653866418577E-6,3.61208516516086E-7,1,0.999253354069792,40.0298881530762,1.98331763046826,21.2099999189377,0.00011302082171601,1.31050329962953E-5,0.25,-5.62176944427897E-7,9.96381694111962E-6,-5.53126435125804E-7,192.519104,192.519104,99.7004928588867,99.7004928588867,57.166746639506,20.6429666059891,25.186911,0,0,0,40,4374,195.1226,99.7004928588867,,,,,,,,,,,,,0,,,,0,,,,,,192.519104,,,,
,27415232.5,196.0457306,99.7004928588867,9.86960461118208E-6,4.07259764343857E-7,1,0.999253354069792,40.0298881530762,1.98341695871651,21.1999993771315,0.000111690328647201,1.69150058656376E-5,0.25,-2.14022012312129E-7,9.90517762154715E-6,-2.03976912752051E-7,196.0457306,196.0457306,99.7004928588867,99.7004928588867,57.5395834431792,20.643911433276,25.186911,0,0,0,40,4374,198.6827,99.7004928588867,,,,,,,,,,,,,0,,,,-0.00245,,,,,,196.0457306,,,,
,27415372.215,199.5320587,99.7004928588867,1.01682523831605E-5,3.76259507612096E-7,1,0.999253354069792,40.0298881530762,1.98365964445326,21.1500003933907,0.000115516152670376,1.48616495402492E-5,0.25,-4.47792982179097E-7,1.02040077189611E-5,-4.38450233980016E-7,199.5320587,199.5320587,99.7004928588867,99.7004928588867,56.9080275996406,20.6399661982537,24.807261,0,0,0,40,4374,202.1842,99.7004928588867,,,,,,,,,,,,,0,,,,-0.00245,,,,,,199.5320587,,,,
,27415512.79,203.0323029,99.7004928588867,9.83872960763851E-6,3.92304578497184E-7,1,0.999253354069792,40.0298881530762,1.98363740637643,21.1500003933907,0.00011097982025667,1.88636375307501E-5,0.25,-3.5165316966613E-8,9.87178735503475E-6,-2.49655900928207E-8,203.0323029,203.0323029,99.7004928588867,99.7004928588867,57.6818398336792,20.6366391312463,24.807261,0,0,0,40,4374,205.70745,99.7004928588867,,,,,,,,,,,,,0,,,,-0.00245,,,,,,203.0323029,,,,
,27415652.335,206.5199432,99.7004928588867,9.65092360240052E-6,3.88093824368034E-7,1,0.999253354069792,40.0298881530762,1.98375402975671,21.1500003933907,0.000109905304823885,1.24543519233017E-5,0.25,-5.70836016314237E-7,9.68280336814114E-6,-5.62776010891031E-7,206.5199432,206.5199432,99.7004928588867,99.7004928588867,57.2472543769868,20.6362535767248,25.186911,0,0,0,40,4374,209.2038,99.7004928588867,,,,,,,,,,,,,0,,,,-0.00245,,,,,,206.5199432,,,,
,27415772.015,209.510025,99.7004928588867,9.62906817375245E-6,3.7466622020368E-7,1,0.999253354069792,40.0298881530762,2.00786632971766,21.0999995470047,0.000109785216611493,1.90896306781928E-5,0.25,2.51245517333275E-9,9.65934192567618E-6,1.22369315559641E-8,209.510025,209.510025,99.7004928588867,99.7004928588867,57.2730481181214,20.6271344426701,24.807261,0,0,0,40,4374,212.19225,99.7004928588867,,,,,,,,,,,,,0,,,,-0.00245,,,,,,209.510025,,,,
,27415915.07,213.0486145,99.7004928588867,9.27421516337041E-6,4.03177381446415E-7,1,0.999253354069792,40.0298881530762,2.00798493697143,21.0999995470047,0.000106155699469251,1.59499023278842E-5,0.25,-2.10972745867731E-7,9.30249727526974E-6,-2.02444462657504E-7,213.0486145,213.0486145,99.7004928588867,99.7004928588867,57.322290714833,20.6292987892458,25.566563,0,0,0,40,4374,215.7885,99.7004928588867,,,,,,,,,,,,,0,,,,0,,,,,,213.0486145,,,,
,27416054.525,216.5591125,99.7004928588867,9.65807637248247E-6,3.80956867649525E-7,1,0.999253354069792,40.0298881530762,2.00789566196517,21.0999995470047,0.000110793306638867,1.51010178263708E-5,0.25,-3.51666513731588E-7,9.68652008374723E-6,-3.43329261423037E-7,216.5591125,216.5591125,99.7004928588867,99.7004928588867,57.7005989181407,20.6332292514861,25.566563,0,0,0,40,4374,219.2777,99.7004928588867,,,,,,,,,,,,,0,,,,0,,,,,,216.5591125,,,,
,27416175.055,219.539505,99.7004928588867,9.47096970336392E-6,3.57855547258627E-7,1,0.999253354069792,40.0298881530762,1.98393755324436,21.0400000214577,0.000107686442728369,1.29786695744864E-5,0.25,-4.91982111753737E-7,9.49804784341896E-6,-4.84337142761263E-7,219.539505,219.539505,99.7004928588867,99.7004928588867,57.3043132588907,20.6283956172726,25.186911,0,0,0,40,4374,222.2969,99.7004928588867,,,,,,,,,,,,,0,,,,0,,,,,,219.539505,,,,
,27416313.93,223.022644,99.7004928588867,9.30210672970886E-6,4.14862453427227E-7,1,0.999253354069792,40.0298881530762,1.98381357948414,21.0400000214577,0.000105146376051097,1.62094787596074E-5,0.25,-1.75544801460868E-7,9.32730870453413E-6,-1.67317232755478E-7,223.022644,223.022644,99.7004928588867,99.7004928588867,57.1143775287176,20.6337866150764,25.566563,0,0,0,40,4374,225.7805,99.7004928588867,,,,,,,,,,,,,0,,,,0,,,,,,223.022644,,,,
,27416454.77,226.5454712,99.7004928588867,9.37146416294377E-6,3.57662030986137E-7,1,0.999253354069792,40.0298881530762,1.98376877852699,21.0400000214577,0.000105587662010021,1.82165160016041E-5,0.25,-9.05050054270649E-9,9.39557175919783E-6,-4.71757384089013E-10,226.5454712,226.5454712,99.7004928588867,99.7004928588867,57.301968373333,20.6309167541754,25.566563,0,0,0,40,4374,229.2989,99.7004928588867,,,,,,,,,,,,,0,,,,0,,,,,,226.5454712,,,,
touchdown = 14.6099999547005 mm,27416586.99,229.8437958,99.7004928588867,9.64387339078325E-6,4.55831775458095E-7,1,0.999253354069792,40.0298881530762,1.98412159661444,20.9899991750717,0.000108500804872275,1.96823811662601E-5,0.25,7.38577506026162E-8,9.66751612948245E-6,8.27385720359724E-8,229.8437958,229.8437958,99.7004928588867,99.7004928588867,57.2495992625445,20.6237135891875,25.566563,0,0,0,40,4374,232.6217,99.7004928588867,,,,,,,,,,,,,0,,,,0,,,,,,229.8437958,,,,
,27416714.28,233.014389,99.7004928588867,8.99838135689154E-6,3.47836756453952E-7,1,0.999253354069792,40.0298881530762,1.98400614165171,20.9899991750717,0.000101597152104886,1.61988873734237E-5,0.25,-1.22990725090018E-7,9.01962964764658E-6,-1.15295069649338E-7,233.014389,233.014389,99.7004928588867,99.7004928588867,57.3895107674868,20.629152637434,25.946213,0,0,0,40,4374,235.8097,99.7004928588867,,,,,,,,,,,,,0,,,,-0.00245,,,,,,233.014389,,,,
,27416854.215,236.5128326,99.7004928588867,9.70211145328761E-6,4.09206092477844E-7,1,0.999253354069792,40.0298881530762,1.98402173234907,20.9899991750717,0.000109320047664184,1.8675449765996E-5,0.25,-2.48735997680682E-8,9.72374975351671E-6,-1.64721058478456E-8,236.5128326,236.5128326,99.7004928588867,99.7004928588867,57.2839909173907,20.6347547485374,25.946213,0,0,0,40,4374,239.32055,99.7004928588867,,,,,,,,,,,,,0,,,,-0.00245,,,,,,236.5128326,,,,
touchdown = 14.5600000396371 mm,27417005.915,240.2762909,99.7004928588867,9.32522352781352E-6,3.56615424156569E-7,1,0.999253354069792,40.0298881530762,1.98405409127597,20.9400001913309,0.000106061269646934,1.2182933954808E-5,0.25,-5.35680205274984E-7,9.34523686906389E-6,-5.28828634442416E-7,240.2762909,240.2762909,99.7004928588867,99.7004928588867,57.1010898438907,20.6246422030683,25.946213,0,0,0,40,4374,243.1378,99.7004928588867,,,,,,,,,,,,,0,,,,0,,,,,,240.2762909,,,,
,27417136.555,243.5382233,99.7004928588867,9.24111218047168E-6,4.11984333416934E-7,1,0.999253354069792,40.0298881530762,1.98413119504706,20.9400001913309,0.000104296110664211,1.66867086074623E-5,0.25,-1.20921040910109E-7,9.25953854232329E-6,-1.1338364261723E-7,243.5382233,243.5382233,99.7004928588867,99.7004928588867,56.8142321773329,20.6315928495078,25.946213,0,0,0,40,4374,246.4003,99.7004928588867,,,,,,,,,,,,,0,,,,0,,,,,,243.5382233,,,,
,27417277.22,247.0279694,99.7004928588867,9.55373936156407E-6,4.02133877409475E-7,1,0.999253354069792,40.0298881530762,1.98406040557695,20.9500007331371,0.000108731026773314,1.19237862999236E-5,0.25,-5.97815927125763E-7,9.57200801018557E-6,-5.91024212951906E-7,247.0279694,247.0279694,99.7004928588867,99.7004928588867,57.4833061897945,20.6292211486153,25.566563,0,0,0,40,4374,249.92875,99.7004928588867,,,,,,,,,,,,,0,,,,-0.00245,,,,,,247.0279694,,,,
touchdown = 14.4999995827675 mm,27417424.275,250.7230225,99.7004928588867,9.04885232662577E-6,4.5555600034112E-7,1,0.999253354069792,40.0298881530762,1.98434375643384,20.8800006657839,0.000101937548712963,1.73367029662194E-5,0.25,-2.93631506875904E-8,9.06453253029115E-6,-2.20587106301502E-8,250.7230225,250.7230225,99.7004928588867,99.7004928588867,56.5852150211983,20.6204609719987,25.946213,0,0,0,40,4374,253.6227,99.7004928588867,,,,,,,,,,,,,0,,,,-0.0049,,,,,,250.7230225,,,,
,27417558.345,254.0516205,99.7004928588867,9.24346592011889E-6,3.69195309072199E-7,1,0.999253354069792,40.0298881530762,1.98440833043875,20.8800006657839,0.000104419554147359,1.59857749514582E-5,0.25,-1.82859410347605E-7,9.25851738860449E-6,-1.7575841591967E-7,254.0516205,254.0516205,99.7004928588867,99.7004928588867,57.0393411908714,20.6228062675575,25.946213,0,0,0,40,4374,256.9702,99.7004928588867,,,,,,,,,,,,,0,,,,-0.0049,,,,,,254.0516205,,,,
,27417697.88,257.5246887,99.7004928588867,9.31309186704224E-6,3.67160747314622E-7,1,0.999253354069792,40.0298881530762,1.98423721126639,20.8800006657839,0.000105595357407576,1.37330444790243E-5,0.25,-3.94663635621387E-7,9.32727304729719E-6,-3.87919528096535E-7,257.5246887,257.5246887,99.7004928588867,99.7004928588867,57.1128142716791,20.6256845746731,26.705515,0,0,0,40,4374,260.4514,99.7004928588867,,,,,,,,,,,,,0,,,,0.0049,,,,,,257.5246887,,,,
touchdown = 14.4400000572205 mm,27417841.475,261.121521,99.7004928588867,9.5088483901928E-6,4.52817985926302E-7,1,0.999253354069792,40.0298881530762,2.00851482599829,20.8199992775917,0.000108941341739706,1.48659053801519E-5,0.25,-3.42909099355569E-7,9.52206003592348E-6,-3.36013042689394E-7,261.121521,261.121521,99.7004928588867,99.7004928588867,57.0463758475445,20.6193936321511,26.325863,0,0,0,40,4374,264.06435,99.7004928588867,,,,,,,,,,,,,0,,,,-0.00245,,,,,,261.121521,,,,
,27417979.715,264.5522461,99.7004928588867,8.63833989118112E-6,3.16921443464842E-7,1,0.999253354069792,40.0298881530762,2.00837308951278,20.8199992775917,9.83906744152274E-5,1.67246371315921E-5,0.25,-2.83533108600374E-8,8.64906654497855E-6,-2.18031358142198E-8,264.5522461,264.5522461,99.7004928588867,99.7004928588867,57.0995265868522,20.6228718016762,26.325863,0,0,0,40,4374,267.50885,99.7004928588867,,,,,,,,,,,,,0,,,,0.00245,,,,,,264.5522461,,,,
,27418119,268.0072937,99.7004928588867,9.2421074667445E-6,3.32374576319086E-7,1,0.999253354069792,40.0298881530762,2.00840216738867,20.8199992775917,0.000105103285329063,1.87729975665773E-5,0.25,4.72064615730169E-8,9.25238561300068E-6,5.41953982962329E-8,268.0072937,268.0072937,99.7004928588867,99.7004928588867,57.2847725459099,20.6225559887198,26.325863,0,0,0,40,4374,271.0053,99.7004928588867,,,,,,,,,,,,,0,,,,0,,,,,,268.0072937,,,,
touchdown = 14.3900001421571 mm,27418263.045,271.5674133,99.7004928588867,8.89632513282013E-6,4.46003315581852E-7,1,0.999253354069792,40.0298881530762,1.98451791064803,20.7700002938509,0.000101142028779577,1.13301859654086E-5,0.25,-5.35080170659386E-7,8.90551603252899E-6,-5.29038932656938E-7,271.5674133,271.5674133,99.7004928588867,99.7004928588867,57.0260535060445,20.6160169920294,26.325863,0,0,0,40,4374,274.64625,99.7004928588867,,,,,,,,,,,,,0,,,,0,,,,,,271.5674133,,,,
,27418399.67,275.0021362,99.7004928588867,8.16227945346342E-6,3.50826096993405E-7,1,0.999253354069792,40.0298881530762,1.98440300438733,20.7700002938509,9.11630938227059E-5,1.97227521219446E-5,0.25,3.38452051967218E-7,8.1690997185372E-6,3.44684481998574E-7,275.0021362,275.0021362,99.7004928588867,99.7004928588867,56.9119357422368,20.6230719238853,26.705515,0,0,0,40,4374,278.04655,99.7004928588867,,,,,,,,,,,,,0,,,,-0.0049,,,,,,275.0021362,,,,
,27418540.22,278.5061951,99.7004928588867,8.3896655150088E-6,3.55523146511565E-7,1,0.999253354069792,40.0298881530762,1.98424455685023,20.7700002938509,9.50470002823874E-5,1.24030704931543E-5,0.25,-3.51302760305188E-7,8.39612780723585E-6,-3.45549639863531E-7,278.5061951,278.5061951,99.7004928588867,99.7004928588867,56.9689946241406,20.6219286634595,25.946213,0,0,0,40,4374,281.56055,99.7004928588867,,,,,,,,,,,,,0,,,,0,,,,,,278.5061951,,,,
touchdown = 14.3299996852875 mm,27418676.545,281.8809509,99.7004928588867,8.62638702178488E-6,4.03051643947916E-7,1,0.999253354069792,40.0298881530762,1.98443351592936,20.7100007683039,9.72115446157715E-5,1.57204144367318E-5,0.25,-9.7257397120062E-8,8.63179841002144E-6,-9.12239181284622E-8,281.8809509,281.8809509,99.7004928588867,99.7004928588867,56.7477937531983,20.6205559490263,27.085165,0,0,0,40,4374,284.9746,99.7004928588867,,,,,,,,,,,,,0,,,,-0.00245,,,,,,281.8809509,,,,
,27418801.685,285.00125125,99.7004928588867,8.58056808721187E-6,3.81687754269986E-7,1,0.999253354069792,40.0298881530762,1.98444001621485,20.7100007683039,9.6843166499863E-5,1.47207399494601E-5,0.25,-1.77978865166978E-7,8.58504699679722E-6,-1.72086763555764E-7,284.970459,285.0320435,99.7004928588867,99.7004928588867,56.5813068786021,20.624172040968,26.705515,0,0,0,40,4374,288.0928,99.7004928588867,,,,,,,,,,,,,0,,,,0.00245,,,,,,285.00125125,,,,
,27418943.58,288.5534058,99.7004928588867,8.58637259742563E-6,3.4148771831935E-7,1,0.999253354069792,40.0298881530762,1.98428437048317,20.7100007683039,9.64812664180133E-5,1.7081097029362E-5,0.25,3.12943447485108E-8,8.58961601470948E-6,3.72056370417203E-8,288.5534058,288.5534058,99.7004928588867,99.7004928588867,57.108906129083,20.6243482027551,26.705515,0,0,0,40,4374,291.6227,99.7004928588867,,,,,,,,,,,,,0,,,,-0.0049,,,,,,288.5534058,,,,
,27419081.41,291.9458008,99.7004928588867,,,2,,,,20.6600001597404,,,,,,,291.9458008,291.9458008,99.7004928588867,99.7004928588867,,,26.705515,,,,-99999999,4374,295.096,99.7004928588867,,,,,,,,,,,,,,,,,,,,,,,291.9458008,,,,
,27419202.925,295.0245361,99.7004928588867,8.16545980707846E-6,4.48050793721916E-7,1,0.999253354069792,40.0298881530762,1.98429947276362,20.6499993801117,9.20665544843126E-5,1.4303952196124E-5,0.25,-1.42333389621041E-7,8.16676849198646E-6,-1.36891150029929E-7,295.0245361,295.0245361,99.7004928588867,99.7004928588867,57.3301070000253,20.6217346713768,26.705515,0,0,0,40,4374,298.1357,99.7004928588867,,,,,,,,,,,,,0,,,,0,,,,,,295.0245361,,,,
,27419345.8,298.5449219,99.7004928588867,7.98610682212681E-6,4.45103437184442E-7,1,0.999253354069792,40.0298881530762,1.98445892876183,20.6499993801117,8.97998849541746E-5,1.53743780812871E-5,0.25,-1.58917682170923E-8,7.98629934092305E-6,-1.06244961553351E-8,298.5449219,298.5449219,99.7004928588867,99.7004928588867,56.997133250833,20.618518378562,26.325863,0,0,0,40,4374,301.7152,99.7004928588867,,,,,,,,,,,,,0,,,,0.00245,,,,,,298.5449219,,,,
,27419499.16,302.3282776,99.7004928588867,,,2,,,,20.6100002446771,,,,,,,302.3282776,302.3282776,99.7004928588867,99.7004928588867,,,26.325863,,,,-99999999,4374,305.5567,99.7004928588867,,,,,,,,,,,,,,,,,,,,,,,302.3282776,,,,
,27419625.7,305.5292358,99.7004928588867,7.8429392247097E-6,4.81690387490573E-7,1,0.999253354069792,40.0298881530762,1.9844981220576,20.6000003963709,8.80333457889022E-5,1.58825668066518E-5,0.25,5.45861920328198E-8,7.84112984881535E-6,5.96075675102455E-8,305.5292358,305.5292358,99.7004928588867,99.7004928588867,57.4262473078907,20.6185449399437,27.085165,0,0,0,40,4374,308.7235,99.7004928588867,,,,,,,,,,,,,0,,,,0.0049,,,,,,305.5292358,,,,
,27419769.06,309.0548706,99.7004928588867,7.26019364664452E-6,3.9661160189889E-7,1,0.999253354069792,40.0298881530762,1.98461567122787,20.6000003963709,8.29972149481391E-5,5.98168554510993E-6,0.25,-7.25371391544263E-7,7.25810062622191E-6,-7.20519774935237E-7,309.0548706,309.0548706,99.7004928588867,99.7004928588867,57.0065127930637,20.6172442051177,26.705515,0,0,0,40,4374,312.3055,99.7004928588867,,,,,,,,,,,,,0,,,,0.0049,,,,,,309.0548706,,,,
,27419918.42,312.7474976,99.7004928588867,,,2,,,,20.5499997878075,,,,,,,312.7474976,312.7474976,99.7004928588867,99.7004928588867,,,27.085165,,,,-99999999,4374,316.0523,99.7004928588867,,,,,,,,,,,,,,,,,,,,,,,312.7474976,,,,
,27420049.195,316.0412292,99.7004928588867,7.41371665869926E-6,4.00206209351844E-7,1,0.999253354069792,40.0298881530762,1.98496452491832,20.5400008708239,8.40516809549172E-5,1.01125878279802E-5,0.25,-3.84168032250858E-7,7.40951366102194E-6,-3.79365187637361E-7,316.0412292,316.0412292,99.7004928588867,99.7004928588867,57.0831123879483,20.6167260040826,27.085165,0,0,0,40,4374,319.35525,99.7004928588867,,,,,,,,,,,,,0,,,,0,,,,,,316.0412292,,,,
,27420190.09,319.52890015,99.7004928588867,7.78787228357568E-6,4.41124723203394E-7,1,0.999253354069792,40.0298881530762,1.98484667511149,20.5400008708239,8.80487338848995E-5,1.19429946320683E-5,0.25,-2.85826209881673E-7,7.78242517427024E-6,-2.80876908721007E-7,319.4919434,319.5658569,99.7004928588867,99.7004928588867,57.3433946848522,20.6172705114936,27.085165,0,0,0,40,4374,322.87865,99.7004928588867,,,,,,,,,,,,,0,,,,0.00245,,,,,,319.52890015,,,,
,27420336.81,323.1796265,99.7004928588867,,,2,,,,20.4900002622604,,,,,,,323.1796265,323.1796265,99.7004928588867,99.7004928588867,,,26.705515,,,,-99999999,4374,326.5618,99.7004928588867,,,,,,,,,,,,,,,,,,,,,,,323.1796265,,,,
,27420471.415,326.5182495,99.7004928588867,7.40033525181359E-6,4.17824635564375E-7,1,0.999253354069792,40.0298881530762,1.98485791736807,20.4799994826317,8.36833172684039E-5,1.11373376163516E-5,0.25,-2.90069076099072E-7,7.3933534397834E-6,-2.85391236544912E-7,326.5182495,326.5182495,99.7004928588867,99.7004928588867,57.2230238928907,20.6138817777546,27.085165,0,0,0,40,4374,329.9358,99.7004928588867,,,,,,,,,,,,,0,,,,0.00245,,,,,,326.5182495,,,,
,27420612.01,330.0224609,99.7004928588867,6.98766113519005E-6,4.99437163178057E-7,1,0.999253354069792,40.0298881530762,1.98460439207569,20.4799994826317,7.83866381993018E-5,1.40407806859173E-5,0.25,4.02573881591545E-8,6.98002941187625E-6,4.43169300509669E-8,330.0224609,330.0224609,99.7004928588867,99.7004928588867,57.0291800201214,20.61821612475,26.705515,0,0,0,40,4374,333.4498,99.7004928588867,,,,,,,,,,,,,0,,,,0,,,,,,330.0224609,,,,
,27420756.2,333.5955505,99.7004928588867,,,2,,,,20.4299998053908,,,,,,,333.5955505,333.5955505,99.7004928588867,99.7004928588867,,,27.085165,,,,-99999999,4374,337.0554,99.7004928588867,,,,,,,,,,,,,,,,,,,,,,,333.5955505,,,,
,27420894.295,337.0394897,99.7004928588867,6.35754286617235E-6,3.91629210061088E-7,1,0.999253354069792,40.0298881530762,2.008676097106,20.4199999570847,7.24013987331852E-5,1.13285639611382E-5,0.25,-1.03368794850192E-7,6.34913745972988E-6,-9.95822272109082E-8,337.0394897,337.0394897,99.7004928588867,99.7004928588867,57.1096877576022,20.6201677916567,27.464817,0,0,0,40,4374,340.52095,99.7004928588867,,,,,,,,,,,,,0,,,,-0.00245,,,,,,337.0394897,,,,
,27421033.745,340.513031,99.7004928588867,7.18610618634598E-6,4.3896573432562E-7,1,0.999253354069792,40.0298881530762,2.00844488760696,20.4199999570847,8.15470863407379E-5,1.43696920728067E-5,0.25,2.12762447254676E-8,7.17566973402697E-6,2.53254879928586E-8,340.4881287,340.5379333,99.7004928588867,99.7004928588867,57.1049979864868,20.6200589497159,27.464817,0,0,0,40,4374,344.0191,99.7004928588867,,,,,,,,,,,,,0,,,,0,,,,,,340.513031,,,,
,27421174.23,343.9569092,99.7004928588867,,,2,,,,20.3700002798438,,,,,,,343.9569092,343.9569092,99.7004928588867,99.7004928588867,,,27.464817,,,,-99999999,4374,347.5363,99.7004928588867,,,,,,,,,,,,,,,,,,,,,,,343.9569092,,,,
,27421294.8,347.00486755,99.7004928588867,6.20147487407393E-6,4.09682639735371E-7,1,0.999253354069792,40.0298881530762,2.00841607277564,20.3600004315376,7.05874852142473E-5,1.10671892974725E-5,0.25,-9.88013487170198E-8,6.19116397517657E-6,-9.5182445216224E-8,346.973175,347.0365601,99.7004928588867,99.7004928588867,56.9244417985445,20.613991474052,27.844467,0,0,0,40,4374,350.5679,99.7004928588867,,,,,,,,,,,,,0,,,,0,,,,,,347.00486755,,,,
,27421666.23,349.7583008,99.7004928588867,6.51292789178767E-6,4.76700234048024E-7,1,0.999253354069792,40.0298881530762,2.00846696068624,20.3600004315376,7.39310978390297E-5,1.27560690538432E-5,0.25,-3.86468391441662E-9,6.50143637815453E-6,-2.32233679027873E-10,349.7583008,349.7583008,99.7004928588867,99.7004928588867,57.1073428720445,20.6142865321082,27.085165,0,0,0,40,4369,350.6897,99.7004928588867,,,,,,,,,,,,,0,,,,0,,,,,,349.7583008,,,,