File: data/doubleLayers/monolayer/ppms/DD205_4/rawdata/DD205_4_ZFCW_100OE.DAT
[Header]
; VSM Data File (default extension .dat)
; Copyright (c) 2003-2013, Quantum Design, Inc. All rights reserved.
TITLE,
FILEOPENTIME,3735540972.28662,05/15/2018,10:15 am
BYAPP,VSM,1.0,1.0
INFO,DYNACOOL VSM Option Release 1.4.10 Build 1,APPNAME
INFO,Quantum Design Linear Motor Servo Controller,MOTOR_MODULE_NAME
INFO,3101-100 J0,MOTOR_HW_VERSION
INFO,MMC654,MOTOR_SERIAL_NUMBER
INFO,SRV No X-over 01.03.11,MOTOR_SOFTWARE_VERSION
INFO,Quantum Design VSM Detection Module,VSM_MODULE_NAME
INFO,3101-150 F0,VSM_HW_VERSION
INFO,VSM507,VSM_SERIAL_NUMBER
INFO,VSM No X-over 01.02.05 May 20 2008 13:51:47,VSM_SOFTWARE_VERSION
INFO,494,PREAMP_SERIAL_NUMBER
INFO,Quantum Design VSM Oven,OVEN_MODULE_NAME
INFO,3101-201 A1,OVEN_HW_VERSION
INFO,OVB210,OVEN_SERIAL_NUMBER
INFO,01.06.24,OVEN_SOFTWARE_VERSION
INFO,593,COIL_SERIAL_NUMBER
INFO,0,MOMENT_UNITS
INFO,,SAMPLE_MATERIAL
INFO,,SAMPLE_COMMENT
INFO,,SAMPLE_MASS
INFO,,SAMPLE_VOLUME
INFO,,SAMPLE_MOLECULAR_WEIGHT
INFO,,SAMPLE_SIZE
INFO,,SAMPLE_SHAPE
DATATYPE,COMMENT,1
DATATYPE,TIME,2
STARTUPAXIS,X,2
STARTUPAXIS,Y1,5
[Data]
Comment,Time Stamp (sec),Temperature (K),Magnetic Field (Oe),Moment (emu),M. Std. Err. (emu),Transport Action,Averaging Time (sec),Frequency (Hz),Peak Amplitude (mm),Center Position (mm),Coil Signal' (mV),Coil Signal" (mV),Range (mV),M. Quad. Signal (emu),M. Raw' (emu),M. Raw" (emu),Min. Temperature (K),Max. Temperature (K),Min. Field (Oe),Max. Field (Oe),Mass (grams),Motor Lag (deg),Pressure (Torr),VSM Status (code),Motor Status (code),Measure Status (code),Measure Count,System Temp. (K),Temp. Status (code),Field Status (code),Chamber Status (code),Motor Current (amps),Motor Heatsink Temp. (C),Map 01,Map 02,Map 03,Map 04,Map 05,Map 06,Map 07,Map 08,Map 09,Map 10,Map 11,Map 12,Map 13,Map 14,Map 15,Map 16
,3735543607.304,5.00302171707153,99.7414436340332,-1.08157999221491E-6,2.05429471709754E-7,1,0.999253354069792,40.0298881530762,1.9989249170533,14.5600000396371,-9.44020571808918E-6,-1.40580148709706E-5,0.25,-1.11780106296061E-6,-1.06977722037303E-6,-1.11638878878215E-6,5.00385522842407,5.00385522842407,99.7232971191406,99.7595901489258,54.5631420419481,19.6835530172744,3.91194748878479,0,0,0,40,5.00140810012817,1,4,1,2.15484619140625,33.2355842590332,,,,,,,,,,,,,,,,
,3735543731.162,8.00818109512329,99.7353897094727,-1.15517309588683E-6,2.50475771612625E-7,1,0.999253354069792,40.0298881530762,1.99834462584899,14.5600000396371,-1.040344997952E-5,-1.32066383583501E-5,0.25,-1.02548465313478E-6,-1.14337689992111E-6,-1.0249725995203E-6,7.99129772186279,7.99129772186279,99.7353897094727,99.7353897094727,54.779653141775,19.6997278561677,10.989803314209,0,0,0,40,8.0688009262085,2,4,1,2.1551513671875,39.5894432067871,,,,,,,,,,,,,,,,
,3735543871.063,11.5003533363342,99.7293434143066,-1.37232922911914E-6,2.41840817476927E-7,1,0.999253354069792,40.0298881530762,1.99795637832177,14.5600000396371,-1.25791787076517E-5,-1.44472494541447E-5,0.25,-1.10257552697587E-6,-1.3588664215458E-6,-1.10264773576762E-6,11.4832801818848,11.4832801818848,99.6990966796875,99.7595901489258,54.7163412317173,19.7048563574976,12.346700668335,0,0,0,40,11.5988330841064,2,4,1,2.15576171875,41.055721282959,,,,,,,,,,,,,,,,
,3735544012.0905,15.0291657447815,99.7353935241699,-1.17784071994693E-6,2.42692514409369E-7,1,0.999253354069792,40.0298881530762,1.9979186693062,14.5600000396371,-1.10004642945848E-5,-1.12610325675006E-5,0.25,-8.40026961684653E-7,-1.16678883105365E-6,-8.40712992038325E-7,15.0199060440063,15.0199060440063,99.7111968994141,99.7595901489258,54.8054468829097,19.7090656533898,13.5495357513428,0,0,0,40,15.134801864624,2,4,1,2.15774536132813,42.5219955444336,,,,,,,,,,,,,,,,
,3735544150.87,18.5081434249878,99.7293434143066,-1.38498630477138E-6,2.43364296870058E-7,1,0.999253354069792,40.0298881530762,1.99765129748306,14.5600000396371,-1.2718985873364E-5,-1.44339368211079E-5,0.25,-1.09927521399422E-6,-1.37143812467218E-6,-1.09941422783842E-6,18.496898651123,18.496898651123,99.7232971191406,99.7353897094727,54.728847288025,19.7092432428969,14.3916254043579,0,0,0,40,18.6926555633545,2,4,1,2.14950561523438,42.5219955444336,,,,,,,,,,,,,,,,
,3735544294.834,22.0208034515381,99.7535438537598,-1.16293087226349E-6,2.5578773049201E-7,1,0.999253354069792,40.0298881530762,1.99747210986527,14.5600000396371,-1.05161487338957E-5,-1.30242084022419E-5,0.25,-1.00743837754534E-6,-1.15113117400177E-6,-1.0072071979397E-6,22.0141220092773,22.0141220092773,99.7232971191406,99.7837905883789,54.8445283088712,19.7126591062714,15.5433397293091,0,0,0,40,22.2085380554199,2,4,1,2.14553833007813,43.0107536315918,,,,,,,,,,,,,,,,
,3735544434.779,25.5148181915283,99.7172470092773,-1.34901808929981E-6,2.2462811726969E-7,1,0.999253354069792,40.0298881530762,1.99748630368736,14.5600000396371,-1.21357131198367E-5,-1.54597396552769E-5,0.25,-1.20102266929568E-6,-1.33515306023725E-6,-1.20099588637164E-6,25.5067539215088,25.5067539215088,99.7111968994141,99.7232971191406,54.6553742072173,19.7131161847231,16.4770736694336,0,0,0,40,25.7134819030762,2,4,1,2.16217041015625,44.4770278930664,,,,,,,,,,,,,,,,
,3735544576.5155,29.0289106369019,99.7293434143066,-1.20407637230031E-6,2.6074348178073E-7,1,0.999253354069792,40.0298881530762,1.9975057803935,14.5600000396371,-1.02802507677059E-5,-1.68638011203514E-5,0.25,-1.35745629616644E-6,-1.19017595996655E-6,-1.35650544403679E-6,29.0120658874512,29.0120658874512,99.6990966796875,99.7595901489258,54.7530777721212,19.712972309683,17.3307456970215,0,0,0,40,29.2906799316406,2,4,1,2.1636962890625,43.49951171875,,,,,,,,,,,,,,,,
,3735544716.4415,32.5023059844971,99.7353935241699,-1.35301387137213E-6,2.53274729015E-7,1,0.999253354069792,40.0298881530762,1.99758982134434,14.5600000396371,-1.31733885818102E-5,-9.96498072129818E-6,0.25,-6.85754329904449E-7,-1.34220074699998E-6,-6.90066658645645E-7,32.4941444396973,32.4941444396973,99.7111968994141,99.7595901489258,54.7171228602366,19.7163036918766,18.1083126068115,0,0,0,40,32.8286170959473,2,4,1,2.16705322265625,43.49951171875,,,,,,,,,,,,,,,,
,3735544858.492,36.0147972106934,99.7777366638184,-1.22574471520462E-6,2.45416666495707E-7,1,0.999253354069792,40.0298881530762,1.99758141904038,14.5600000396371,-1.16788926158729E-5,-1.04654860215174E-5,0.25,-7.54390546077936E-7,-1.21554786366003E-6,-7.58588032704776E-7,36.0077133178711,36.0077133178711,99.7595901489258,99.7958831787109,54.8492180799866,19.7168676905613,18.8249435424805,0,0,0,40,36.415771484375,2,4,1,2.159423828125,43.9882698059082,,,,,,,,,,,,,,,,
,3735544999.328,39.5085582733154,99.7535438537598,-1.12296360980792E-6,2.58291418882432E-7,1,0.999253354069792,40.0298881530762,1.9975017104074,14.5600000396371,-1.05282881946123E-5,-1.05623634069355E-5,0.25,-7.80887275448976E-7,-1.11354680585285E-6,-7.85406074667242E-7,39.5003395080566,39.5003395080566,99.7474975585938,99.7595901489258,54.7835612843712,19.7175726616311,19.4698734283447,0,0,0,40,39.9614524841309,2,4,1,2.159423828125,43.9882698059082,,,,,,,,,,,,,,,,
,3735545140.2785,43.0060729980469,99.7898368835449,-1.43065878280846E-6,2.38027938543116E-7,1,0.999253354069792,40.0298881530762,1.99754732774638,14.5600000396371,-1.34952748526396E-5,-1.30618172588574E-5,0.25,-9.56443836036952E-7,-1.41983269390684E-6,-9.63773101084918E-7,43.0060729980469,43.0060729980469,99.7595901489258,99.8200836181641,54.8093550255058,19.7140072578794,20.0893840789795,0,0,0,40,43.5255737304687,2,4,1,2.16049194335938,43.9882698059082,,,,,,,,,,,,,,,,
,3735545282.1215,46.5253810882568,99.7595939636231,-8.55911846861646E-7,2.40129939273696E-7,1,0.999253354069792,40.0298881530762,1.99749059791859,14.5600000396371,-7.11833083961595E-6,-1.31064544588579E-5,0.25,-1.0636404181618E-6,-8.46565671840509E-7,-1.06796119714903E-6,46.5151329040527,46.5151329040527,99.7474975585938,99.7716903686523,54.7905959410442,19.7183352789067,20.6748905181885,0,0,0,40,47.111141204834,2,4,1,2.15911865234375,43.9882698059082,,,,,,,,,,,,,,,,
,3735545422.9235,50.0065956115723,99.7656364440918,-1.3860746283999E-6,2.00463766772716E-7,1,0.999253354069792,40.0298881530762,1.99747624734403,14.5600000396371,-1.33669766911215E-5,-1.12057697417921E-5,0.25,-7.89025111927614E-7,-1.37918442337809E-6,-7.98751421378529E-7,49.9984397888184,49.9984397888184,99.7353897094727,99.7958831787109,54.7905959410442,19.7197305504293,21.2161998748779,0,0,0,40,50.6782684326172,2,4,1,2.16079711914062,43.9882698059082,,,,,,,,,,,,,,,,
,3735545564.905,53.5187072753906,99.7535438537598,-1.23011379637E-6,2.221871863041E-7,1,0.999253354069792,40.0298881530762,1.99746856252274,14.5600000396371,-1.13439568377059E-5,-1.28791030179304E-5,0.25,-9.71722561183263E-7,-1.22336841961569E-6,-9.81147308662208E-7,53.5099945068359,53.5099945068359,99.7474975585938,99.7595901489258,54.9828765567751,19.7206559259715,21.7295570373535,0,0,0,40,54.2806968688965,2,4,1,2.16049194335938,44.4770278930664,,,,,,,,,,,,,,,,
,3735545705.859,57.0054607391357,99.7232971191406,-1.13450889470274E-6,2.5440646292103E-7,1,0.999253354069792,40.0298881530762,1.99736343894885,14.5600000396371,-9.94806208263486E-6,-1.47834748002808E-5,0.25,-1.16482368561359E-6,-1.12768193604617E-6,-1.17454713466646E-6,56.9959754943848,56.9959754943848,99.6990966796875,99.7474975585938,54.8656322788904,19.7207560549704,22.1895160675049,0,0,0,40,57.8509826660156,2,4,1,2.16232299804687,44.4770278930664,,,,,,,,,,,,,,,,
,3735545847.7185,60.5271110534668,99.7837867736816,-1.19629441273058E-6,2.32071228946065E-7,1,0.999253354069792,40.0298881530762,1.9971197669302,14.5600000396371,-1.06921417997048E-5,-1.4555680960962E-5,0.25,-1.13174151159102E-6,-1.19122330613517E-6,-1.14248823966054E-6,60.5179214477539,60.5179214477539,99.7716903686523,99.7958831787109,54.6811679483519,19.724351938448,22.6682758331299,0,0,0,40,61.4566345214844,2,4,1,2.14584350585938,44.4770278930664,,,,,,,,,,,,,,,,
,3735545988.466,64.0108604431152,99.7474899291992,-1.15834505563709E-6,2.0001620499392E-7,1,0.999253354069792,40.0298881530762,1.99704299071419,14.5600000396371,-1.02252619884273E-5,-1.48758533001967E-5,0.25,-1.16770335801786E-6,-1.15426183797325E-6,-1.17868922331637E-6,64.0026016235352,64.0026016235352,99.7353897094727,99.7595901489258,54.7108698320827,19.7250181557601,23.1147651672363,0,0,0,40,65.0583419799805,2,4,1,2.14736938476562,43.49951171875,,,,,,,,,,,,,,,,
,3735546129.5045,67.5127563476563,99.7656440734863,-1.1721211357244E-6,2.37721150819239E-7,1,0.999253354069792,40.0298881530762,1.99690635336455,14.5600000396371,-1.07484871695284E-5,-1.2900291017947E-5,0.25,-9.82048115304051E-7,-1.17041391379201E-6,-9.92671554381522E-7,67.5055694580078,67.5055694580078,99.7474975585938,99.7837905883789,54.6538109501788,19.7226775897619,23.5231189727783,0,0,0,40,68.6437835693359,2,4,1,2.16415405273438,43.9882698059082,,,,,,,,,,,,,,,,
,3735546270.262,71.0225486755371,99.7414436340332,-1.32475759700018E-6,2.78900504136477E-7,1,0.999253354069792,40.0298881530762,1.996976456121,14.5600000396371,-1.18186150945267E-5,-1.64806968669429E-5,0.25,-1.28548812906445E-6,-1.32296440780463E-6,-1.29819001935921E-6,71.0153427124023,71.0153427124023,99.7232971191406,99.7595901489258,54.7562042861981,19.7261695079419,23.9037532806396,0,0,0,40,72.2193756103516,2,4,1,2.154541015625,43.0107536315918,,,,,,,,,,,,,,,,
,3735546411.258,74.5161476135254,99.7474975585938,-1.14811252463227E-6,2.66779619227679E-7,1,0.999253354069792,40.0298881530762,1.9968176812235,14.5600000396371,-1.04573656208316E-5,-1.3139095325134E-5,0.25,-1.00830009073752E-6,-1.14800168412191E-6,-1.0187890510111E-6,74.5084686279297,74.5084686279297,99.7474975585938,99.7474975585938,54.884391363352,19.7219254906432,24.2759609222412,0,0,0,40,75.8150100708008,6,4,1,2.15255737304687,43.9882698059082,,,,,,,,,,,,,,,,
,3735546551.014,78.0043716430664,99.7172431945801,-1.52874217360186E-6,2.26961383884828E-7,1,0.999253354069792,40.0298881530762,1.99674033094412,14.5600000396371,-1.42650343628687E-5,-1.5651615866414E-5,0.25,-1.17228501203469E-6,-1.53037614097999E-6,-1.18524890814485E-6,77.9971771240234,77.9971771240234,99.6990966796875,99.7353897094727,54.8937709055827,19.7238331209831,24.6164608001709,0,0,0,40,79.3724517822266,6,4,1,2.1533203125,44.4770278930664,,,,,,,,,,,,,,,,
,3735546691.939,81.5094451904297,99.7293434143066,-9.4302985193863E-7,2.3840172646176E-7,1,0.999253354069792,40.0298881530762,1.9967406765062,14.5600000396371,-8.22967614387499E-6,-1.28668911199274E-5,0.25,-1.02000386458924E-6,-9.43175448258299E-7,-1.02931214979053E-6,81.4927749633789,81.4927749633789,99.6990966796875,99.7595901489258,54.7562042861981,19.726891128361,24.9454097747803,0,0,0,40,82.972282409668,6,4,1,2.1636962890625,44.4770278930664,,,,,,,,,,,,,,,,
,3735546832.834,85.0201301574707,99.7535438537598,-1.08067178449079E-6,2.70081213117288E-7,1,0.999253354069792,40.0298881530762,1.99658743408479,14.5600000396371,-1.0103426498076E-5,-1.10112375123526E-5,0.25,-8.24106942098276E-7,-1.08282434981333E-6,-8.32844705695939E-7,85.0125427246094,85.0125427246094,99.7474975585938,99.7595901489258,54.8523445940635,19.7267690215115,25.2534618377686,0,0,0,40,86.5399398803711,6,4,1,2.14706420898438,43.9882698059082,,,,,,,,,,,,,,,,
,3735546972.711,88.5063285827637,99.7716903686523,-9.93633592318753E-7,2.45051718052966E-7,1,0.999253354069792,40.0298881530762,1.99674342739969,14.5600000396371,-8.74829766580591E-6,-1.3184141635202E-5,0.25,-1.04039725904139E-6,-9.94857281139291E-7,-1.04973017468859E-6,88.4977798461914,88.4977798461914,99.7595901489258,99.7837905883789,54.7773082562173,19.7280638421903,25.5376834869385,0,0,0,40,90.0866165161133,6,4,1,2.15042114257813,44.4770278930664,,,,,,,,,,,,,,,,
,3735547113.6125,92.02197265625,99.7353897094727,-1.56535108280766E-6,2.62119188636282E-7,1,0.999253354069792,40.0298881530762,1.99668853062379,14.5600000396371,-1.48872488336557E-5,-1.45981862959858E-5,0.25,-1.06926480397809E-6,-1.56989303946129E-6,-1.08064477618728E-6,92.012580871582,92.012580871582,99.7353897094727,99.7353897094727,54.8656322788904,19.7268226243727,25.8309688568115,0,0,0,40,93.6622085571289,6,4,1,2.1630859375,43.9882698059082,,,,,,,,,,,,,,,,
,3735547253.484,95.5005187988281,99.7353935241699,-1.11128463172342E-6,2.61761589187844E-7,1,0.999253354069792,40.0298881530762,1.99660473816025,14.5600000396371,-1.04898031780337E-5,-1.08199576339838E-5,0.25,-8.01448435454314E-7,-1.11460378452832E-6,-8.09542693793521E-7,95.4805603027344,95.4805603027344,99.7111968994141,99.7595901489258,54.7921591980827,19.7293293387574,26.1469306945801,0,0,0,40,97.2071914672852,6,4,1,2.14767456054687,44.4770278930664,,,,,,,,,,,,,,,,
,3735547393.5555,99.0062828063965,99.9047660827637,-1.05108778090913E-6,2.44742432420073E-7,1,0.999253354069792,40.0298881530762,1.99655800207391,14.5600000396371,-9.33012800544236E-6,-1.35726384239768E-5,0.25,-1.06652370068715E-6,-1.05344423703538E-6,-1.07566688124287E-6,98.9991073608398,98.9991073608398,99.8684692382813,99.9410629272461,54.7741817421404,19.730241002116,26.4258422851562,0,0,0,40,100.745269775391,6,4,1,2.16522216796875,43.9882698059082,,,,,,,,,,,,,,,,
,3735547534.4485,102.521003723145,99.8624229431152,-1.48888538425917E-6,2.53260261268404E-7,1,0.999253354069792,40.0298881530762,1.99651570783761,14.5600000396371,-1.39285875924172E-5,-1.52306366939864E-5,0.25,-1.14207514567216E-6,-1.49362710669127E-6,-1.15275064389341E-6,102.511436462402,102.511436462402,99.8321762084961,99.8926696777344,54.9070585904097,19.7271909302647,26.6791152954102,0,0,0,40,104.308219909668,6,4,1,2.16522216796875,44.4770278930664,,,,,,,,,,,,,,,,
,3735547674.305,106.004596710205,99.8866195678711,-1.50698559567174E-6,2.28825770722468E-7,1,0.999253354069792,40.0298881530762,1.99639766508328,14.5600000396371,-1.47731612718821E-5,-1.16149354068826E-5,0.25,-8.05284719475616E-7,-1.51296216569414E-6,-8.13916626797719E-7,105.995491027832,105.995491027832,99.8442764282227,99.9289627075195,54.8249875958904,19.7279805019843,26.8973064422607,0,0,0,40,107.851119995117,6,4,1,2.1484375,44.4770278930664,,,,,,,,,,,,,,,,
,3735547815.0585,109.519355773926,99.8745231628418,-1.4473510216879E-6,2.64985833817648E-7,1,0.999253354069792,40.0298881530762,1.99650690907807,14.5600000396371,-1.42425318287379E-5,-1.08615162052621E-5,0.25,-7.46453267543515E-7,-1.45326035187623E-6,-7.54362135753071E-7,109.513305664062,109.513305664062,99.8442764282227,99.9047698974609,54.894552534102,19.7313411202063,27.149040222168,0,0,0,40,111.404640197754,6,4,1,2.16384887695313,44.4770278930664,,,,,,,,,,,,,,,,
,3735547954.9745,113.008640289307,99.8926696777344,-6.52246157065269E-7,2.50508968065854E-7,1,0.999253354069792,40.0298881530762,1.99631969790012,14.5600000396371,-5.4364216405434E-6,-1.04392931953609E-5,0.25,-8.48528168396161E-7,-6.53651295979691E-7,-8.54771877210084E-7,112.99991607666,112.99991607666,99.8805694580078,99.9047698974609,54.9359788456212,19.7282577344032,27.3821964263916,0,0,0,40,114.939277648926,6,4,1,2.16506958007813,44.4770278930664,,,,,,,,,,,,,,,,
,3735548095.991,116.531665802002,99.9289627075195,-1.70988404926637E-6,2.17595262645479E-7,1,0.999253354069792,40.0298881530762,1.99636064122783,14.5600000396371,-1.69996630374531E-5,-1.18504127805895E-5,0.25,-7.91804144556099E-7,-1.7172102085602E-6,-8.00154334407209E-7,116.515991210938,116.515991210938,99.916862487793,99.9410629272461,54.8015387403135,19.7316963870701,27.604076385498,0,0,0,40,118.497314453125,6,4,1,2.16552734375,43.9882698059082,,,,,,,,,,,,,,,,
,3735548235.935,120.019165039062,99.8926696777344,-1.34579340145223E-6,3.13723432798501E-7,1,0.999253354069792,40.0298881530762,1.99642338963877,14.5600000396371,-1.27211212710563E-5,-1.30565063387136E-5,0.25,-9.67740526212087E-7,-1.3507900496608E-6,-9.75974196666889E-7,120.00106048584,120.00106048584,99.8805694580078,99.9047698974609,54.7991938547558,19.7322989667604,27.8429794311523,0,0,0,40,122.028610229492,6,4,1,2.14767456054687,44.9657897949219,,,,,,,,,,,,,,,,
,3735548375.7445,123.503150939941,99.8987159729004,-9.94867998554451E-7,2.33266661296934E-7,1,0.999253354069792,40.0298881530762,1.99634201676323,14.5600000396371,-8.56137995731448E-6,-1.44199888515744E-5,0.25,-1.15588996233492E-6,-9.97631764021663E-7,-1.1641706951092E-6,123.495346069336,123.495346069336,99.8684692382813,99.9289627075195,54.8210794532943,19.7332766005657,28.0950984954834,0,0,0,40,125.560646057129,6,4,1,2.16110229492187,43.9882698059082,,,,,,,,,,,,,,,,
,3735548515.5315,127.002487182617,99.8987159729004,-1.08622498819238E-6,2.62114211618468E-7,1,0.999253354069792,40.0298881530762,1.99635060469153,14.5600000396371,-9.6639338661614E-6,-1.3956620525814E-5,0.25,-1.09710847226225E-6,-1.08964475196082E-6,-1.10511021271395E-6,126.994850158691,126.994850158691,99.8442764282227,99.9531555175781,54.6975821472558,19.7303966935652,28.2734870910645,0,0,0,40,129.08137512207,6,4,1,2.16476440429687,43.9882698059082,,,,,,,,,,,,,,,,
,3735548656.4095,130.520500183105,99.9168663024902,-1.13923816679881E-6,2.6486723456854E-7,1,0.999253354069792,40.0298881530762,1.99627288493751,14.5600000396371,-1.02405640217022E-5,-1.404227852874E-5,0.25,-1.09586850217698E-6,-1.1429652199928E-6,-1.10380519488708E-6,130.512649536133,130.512649536133,99.9047698974609,99.9289627075195,54.894552534102,19.7347371427328,28.5327816009521,0,0,0,40,132.638946533203,6,4,1,2.16461181640625,44.4770278930664,,,,,,,,,,,,,,,,
,3735548796.301,134.0126953125,99.8684692382813,-1.44517904771536E-6,2.5735537420369E-7,1,0.999253354069792,40.0298881530762,1.99624475725146,14.5600000396371,-1.4326257327383E-5,-1.02424218260131E-5,0.25,-6.91096654294054E-7,-1.45125454419767E-6,-6.97381248366493E-7,133.99592590332,133.99592590332,99.8563690185547,99.8805694580078,54.718686117275,19.7343815402536,28.7676563262939,0,0,0,40,136.164093017578,6,4,1,2.147216796875,43.9882698059082,,,,,,,,,,,,,,,,
,3735548936.2195,137.512275695801,99.8866195678711,-9.52899605161812E-7,3.22346623851678E-7,1,0.999253354069792,40.0298881530762,1.99637699357349,14.5600000396371,-8.38069651818863E-6,-1.27976491415694E-5,0.25,-1.01402476491015E-6,-9.55851812469758E-7,-1.02088155859165E-6,137.496856689453,137.496856689453,99.8684692382813,99.9047698974609,54.7218126313519,19.7326602711452,28.9844017028809,0,0,0,40,139.698303222656,6,4,1,2.16476440429687,44.9657897949219,,,,,,,,,,,,,,,,
,3735549076.112,141.003929138184,99.8926658630371,-1.02556986439318E-6,3.23089975095776E-7,1,0.999253354069792,40.0298881530762,1.99649677558119,14.5600000396371,-1.00846717160088E-5,-7.73628700209042E-6,0.25,-5.33791108256328E-7,-1.02972764427663E-6,-5.38248481790344E-7,140.987426757812,140.987426757812,99.8684692382813,99.916862487793,54.7882510554866,19.7324049325035,29.1366195678711,0,0,0,40,143.202850341797,6,4,1,2.16506958007813,44.4770278930664,,,,,,,,,,,,,,,,
,3735549216.119,144.509803771973,99.8987159729004,-7.72140751699667E-7,2.94526419814436E-7,1,0.999253354069792,40.0298881530762,1.99633887235407,14.5600000396371,-7.11661720358182E-6,-8.52028264641602E-6,0.25,-6.51039309125743E-7,-7.74814461287592E-7,-6.55533462269822E-7,144.499328613281,144.499328613281,99.8805694580078,99.916862487793,55.0618210372174,19.7298632057351,29.2900562286377,0,0,0,40,146.746551513672,6,4,1,2.1466064453125,43.9882698059082,,,,,,,,,,,,,,,,
,3735549357.012,148.021919250488,99.9410591125488,-1.14073711949467E-6,3.04684314590647E-7,1,0.999253354069792,40.0298881530762,1.99623609696896,14.5600000396371,-1.05553095877539E-5,-1.23465935840926E-5,0.25,-9.39766747285828E-7,-1.14468817710937E-6,-9.46154310252894E-7,148.013656616211,148.013656616211,99.9289627075195,99.9531555175781,54.7351003161789,19.7305267518929,29.5233173370361,0,0,0,40,150.27131652832,6,4,1,2.15072631835938,44.4770278930664,,,,,,,,,,,,,,,,
,3735549496.981,151.509010314941,99.9047660827637,-1.20513373021089E-6,2.67423159275566E-7,1,0.999253354069792,40.0298881530762,1.99609977304772,14.5600000396371,-1.12762034568554E-5,-1.23256849979192E-5,0.25,-9.26717333516338E-7,-1.20936656862771E-6,-9.33003972151001E-7,151.499710083008,151.499710083008,99.8926696777344,99.916862487793,54.5373483008135,19.7313230955835,29.6970882415771,0,0,0,40,153.801986694336,6,4,1,2.15087890625,44.9657897949219,,,,,,,,,,,,,,,,
,3735549636.846,155.022468566895,99.8745193481445,-8.26122823824683E-7,2.84420566962584E-7,1,0.999253354069792,40.0298881530762,1.99626500120684,14.5600000396371,-6.61098758853037E-6,-1.48070262856722E-5,0.25,-1.22278040179814E-6,-8.28087304225134E-7,-1.22971907067006E-6,155.013488769531,155.013488769531,99.8563690185547,99.8926696777344,54.678041434275,19.7294041001912,29.9033870697022,0,0,0,40,157.31787109375,6,4,1,2.16445922851562,43.9882698059082,,,,,,,,,,,,,,,,
,3735549776.671,158.503257751465,99.9047660827637,-1.23409455509225E-6,2.9569672150919E-7,1,0.999253354069792,40.0298881530762,1.99637143442598,14.5600000396371,-1.01329794232574E-5,-2.06602519725141E-5,0.25,-1.69193167848937E-6,-1.23720712602157E-6,-1.70146336227485E-6,158.49462890625,158.49462890625,99.8684692382813,99.9410629272461,54.7655838284289,19.7311818291119,30.1111679077148,0,0,0,40,160.837631225586,6,4,1,2.16506958007813,43.9882698059082,,,,,,,,,,,,,,,,
,3735549916.561,162.003807067871,99.8987159729004,-1.09783172281572E-6,2.73810556982074E-7,1,0.999253354069792,40.0298881530762,1.99627475836165,14.5600000396371,-1.02943703005499E-5,-1.10972594538529E-5,0.25,-8.32424763129879E-7,-1.10153460734906E-6,-8.37715947057515E-7,161.988540649414,161.988540649414,99.8684692382813,99.9289627075195,54.8015387403135,19.7321915742718,30.2369232177734,0,0,0,40,164.352508544922,6,4,1,2.1636962890625,44.4770278930664,,,,,,,,,,,,,,,,
,3735550057.362,165.518013000488,99.8987159729004,-5.89876670512616E-7,3.22614492404145E-7,1,0.999253354069792,40.0298881530762,1.99624900039669,14.5600000396371,-4.56306599725016E-6,-1.14643667478723E-5,0.25,-9.55850443784803E-7,-5.91121042128161E-7,-9.60848291968E-7,165.502990722656,165.502990722656,99.8805694580078,99.916862487793,54.6842944624289,19.7310627497033,30.3470287322998,0,0,0,40,167.913055419922,6,4,1,2.16537475585938,44.4770278930664,,,,,,,,,,,,,,,,
,3735550197.258,169.016799926758,99.8745193481445,-6.64939344992529E-7,2.86239909619025E-7,1,0.999253354069792,40.0298881530762,1.99624478289869,14.5600000396371,-5.39172196090926E-6,-1.15115802948933E-5,0.25,-9.47133661144154E-7,-6.66497982428933E-7,-9.52081549415754E-7,169.007690429687,169.007690429687,99.8684692382813,99.8805694580078,54.3872756251211,19.7290833370985,30.4749431610107,0,0,0,40,171.433242797852,6,4,1,2.16537475585938,44.4770278930664,,,,,,,,,,,,,,,,
,3735550337.1495,172.503089904785,99.910816192627,-8.52126092397071E-7,2.6984908430816E-7,1,0.999253354069792,40.0298881530762,1.99633520699457,14.5600000396371,-7.05996311255752E-6,-1.38966069317751E-5,0.25,-1.13476711190456E-6,-8.54190198255022E-7,-1.14062886838121E-6,172.494384765625,172.494384765625,99.9047698974609,99.916862487793,54.8359303951596,19.7316474375068,30.646577835083,0,0,0,40,174.949554443359,6,4,1,2.1636962890625,43.9882698059082,,,,,,,,,,,,,,,,
,3735550477.0595,176.007690429687,99.8805694580078,-9.48250266598972E-7,3.39772507192852E-7,1,0.999253354069792,40.0298881530762,1.99621717432878,14.5600000396371,-8.47139369484955E-6,-1.19588541427499E-5,0.25,-9.38941908378622E-7,-9.50912916423008E-7,-9.43986040493949E-7,175.99934387207,175.99934387207,99.8805694580078,99.8805694580078,54.6483395505442,19.7306542969471,30.9774303436279,0,0,0,40,178.479522705078,6,4,1,2.15103149414062,44.4770278930664,,,,,,,,,,,,,,,,
,3735550616.9665,179.505630493164,99.9168663024902,-8.87708053685759E-7,2.43525164405415E-7,1,0.999253354069792,40.0298881530762,1.99632488899357,14.5600000396371,-8.3938473743146E-6,-8.55812254294272E-6,0.25,-6.35242028653911E-7,-8.90445030401189E-7,-6.38876909037363E-7,179.487258911133,179.487258911133,99.9047698974609,99.9289627075195,54.921909532275,19.7311866246669,31.2732028961182,0,0,0,40,181.998229980469,6,4,1,2.16476440429687,43.9882698059082,,,,,,,,,,,,,,,,
,3735550756.8835,183.000587463379,99.910816192627,-9.34986374389681E-7,3.24213497869452E-7,1,0.999253354069792,40.0298881530762,1.99622790529244,14.5600000396371,-8.28634934064964E-6,-1.21623969123847E-5,0.25,-9.60361822389819E-7,-9.37440064538146E-7,-9.65221382698757E-7,182.992095947266,182.992095947266,99.9047698974609,99.916862487793,54.8374936521981,19.7315434462308,31.5606079101562,0,0,0,40,185.511428833008,6,4,1,2.16598510742187,43.9882698059082,,,,,,,,,,,,,,,,
,3735550896.8655,186.505569458008,99.9047698974609,-6.14236402200568E-7,3.239368842867E-7,1,0.999253354069792,40.0298881530762,1.99612957864115,14.5600000396371,-5.03866176434403E-6,-1.02908099694217E-5,0.25,-8.43814209945431E-7,-6.15550506243386E-7,-8.4772574016615E-7,186.497863769531,186.497863769531,99.9047698974609,99.9047698974609,54.8984606766981,19.7324921214607,31.829662322998,0,0,0,40,189.024002075195,6,4,1,2.14981079101562,43.9882698059082,,,,,,,,,,,,,,,,
,3735551037.628,190.015975952148,99.8624229431152,-7.41297232566665E-7,3.30763202118193E-7,1,0.999253354069792,40.0298881530762,1.99629224149029,14.5600000396371,-5.86478551758339E-6,-1.365074502015E-5,0.25,-1.13227889230253E-6,-7.42701801661822E-7,-1.13728876721014E-6,189.995880126953,189.995880126953,99.8442764282227,99.8805694580078,54.8163896821789,19.7346341711246,32.0884628295898,0,0,0,40,192.559814453125,6,4,1,2.14828491210938,44.4770278930664,,,,,,,,,,,,,,,,
,3735551177.619,193.519912719727,99.9531555175781,-3.51964822126413E-7,2.5600480107168E-7,1,0.999253354069792,40.0298881530762,1.99633997039846,14.5600000396371,-2.15346829994557E-6,-1.00737872394592E-5,0.25,-8.6993477579457E-7,-3.52232277070125E-7,-8.73429469094744E-7,193.50959777832,193.50959777832,99.916862487793,99.9894485473633,54.9867846993712,19.7337411156555,32.364803314209,0,0,0,40,196.065444946289,6,4,1,2.16537475585938,43.9882698059082,,,,,,,,,,,,,,,,
,3735551317.5175,197.02717590332,99.9229125976563,-3.51713276497583E-7,2.78460688037114E-7,1,0.999253354069792,40.0298881530762,1.99612033843638,14.5600000396371,-2.4243630704576E-6,-8.51182509465988E-6,0.25,-7.25681947916449E-7,-3.52123808660295E-7,-7.2857562193278E-7,197.017990112305,197.017990112305,99.8926696777344,99.9531555175781,54.901587190775,19.7366878095663,32.5798835754395,0,0,0,40,199.569381713867,6,4,1,2.16522216796875,43.9882698059082,,,,,,,,,,,,,,,,
,3735551456.4685,200.50715637207,99.8987159729004,-7.41092672287148E-7,2.98263506313796E-7,1,0.999253354069792,40.0298881530762,1.99614586580652,14.5600000396371,-6.09521069230506E-6,-1.23124255808867E-5,0.25,-1.00902884240449E-6,-7.42477510707081E-7,-1.01320413770014E-6,200.498184204102,200.498184204102,99.8684692382813,99.9289627075195,54.9875663278904,19.7386388039773,32.8470497131348,0,0,0,40,203.059768676758,6,4,1,2.14889526367187,44.4770278930664,,,,,,,,,,,,,,,,
,3735551597.2665,204.019424438477,99.8987197875977,-1.51665871888515E-7,3.19863405827773E-7,1,0.999253354069792,40.0298881530762,1.99584446852648,14.5600000396371,-3.58343492388847E-7,-7.58189797502218E-6,0.25,-6.75028277450361E-7,-1.51441015414762E-7,-6.77370841470394E-7,204.003890991211,204.003890991211,99.8926696777344,99.9047698974609,54.5975336967942,19.7389656085233,33.0839920043945,0,0,0,40,206.599563598633,6,4,1,2.1649169921875,44.4770278930664,,,,,,,,,,,,,,,,
,3735551737.1045,207.520668029785,99.8987159729004,4.75018503168695E-7,2.83120081235037E-7,1,0.999253354069792,40.0298881530762,1.99578370343576,14.5600000396371,7.31858508774383E-6,-1.1554781717199E-5,0.25,-1.15284320266233E-6,4.77696723345009E-7,-1.15594872771595E-6,207.512878417969,207.512878417969,99.8684692382813,99.9289627075195,54.5881541545635,19.7382280766563,33.3168830871582,0,0,0,40,210.110229492187,6,4,1,2.16506958007813,43.9882698059082,,,,,,,,,,,,,,,,
,3735551877.0415,211.0126953125,99.8866195678711,8.60462319617653E-8,2.94774105675995E-7,1,0.999253354069792,40.0298881530762,1.99597091812881,14.5600000396371,2.84154185595125E-6,-1.07302403319901E-5,0.25,-1.00826715386567E-6,8.7329446335302E-8,-1.01121385047739E-6,210.997573852539,210.997573852539,99.8684692382813,99.9047698974609,55.1470185458135,19.7387265736761,33.5233306884766,0,0,0,40,213.622924804687,6,4,1,2.15133666992187,44.9657897949219,,,,,,,,,,,,,,,,
,3735552017.0005,214.511085510254,99.9229164123535,1.14594017244535E-7,2.80641458831272E-7,1,0.999253354069792,40.0298881530762,1.99599246628978,14.5600000396371,2.29785990448967E-6,-5.82246743225312E-6,0.25,-5.59076816202225E-7,1.15482460419174E-7,-5.60581922052903E-7,214.490142822266,214.490142822266,99.9047698974609,99.9410629272461,55.0094519264289,19.7392953664866,33.7451591491699,0,0,0,40,217.123291015625,6,4,1,2.16567993164062,43.49951171875,,,,,,,,,,,,,,,,
,3735552156.8085,218.015266418457,99.9047660827637,2.26624648882442E-7,3.31306938883542E-7,1,0.999253354069792,40.0298881530762,1.99575764169069,14.5600000396371,4.59951750975847E-6,-1.18338818489295E-5,0.25,-1.13543299750348E-6,2.28363191062197E-7,-1.13837063755268E-6,217.999710083008,217.999710083008,99.8805694580078,99.9289627075195,54.4232305370057,19.7393855372285,33.9753532409668,0,0,0,40,220.642852783203,6,4,1,2.16476440429687,43.49951171875,,,,,,,,,,,,,,,,
,3735552296.6885,221.509620666504,99.9047698974609,4.78161254793538E-7,3.05288423541247E-7,1,0.999253354069792,40.0298881530762,1.99583982954684,14.5600000396371,6.97202389960892E-6,-9.39873285211852E-6,0.25,-9.54159174003813E-7,4.80349919663888E-7,-9.5624659134366E-7,221.494064331055,221.494064331055,99.9047698974609,99.9047698974609,54.515462702275,19.7366082953403,34.1987991333008,0,0,0,40,224.142944335938,6,4,1,2.13592529296875,43.9882698059082,,,,,,,,,,,,,,,,
,3735552436.5645,225.012985229492,99.9168663024902,7.76967946530568E-7,2.52681655502065E-7,1,0.999253354069792,40.0298881530762,1.9959555210487,14.5600000396371,9.8890912390987E-6,-7.06955328810352E-6,0.25,-7.90939551162426E-7,7.79693134350333E-7,-7.92228118874078E-7,225.005477905273,225.005477905273,99.9047698974609,99.9289627075195,54.7648021999096,19.7376163323158,34.4489631652832,0,0,0,40,227.635635375977,6,4,1,2.13623046875,44.4770278930664,,,,,,,,,,,,,,,,
,3735552576.675,228.520294189453,99.910816192627,1.42482996661372E-6,2.14988866104182E-7,1,0.999253354069792,40.0298881530762,1.99594447713959,14.5600000396371,1.71301583640452E-5,-7.24882705045891E-6,0.25,-9.21249132174272E-7,1.42914828792558E-6,-9.22179273000199E-7,228.510040283203,228.510040283203,99.9047698974609,99.916862487793,54.6256723234865,19.7348579552365,34.677806854248,0,0,0,40,231.158081054687,6,4,1,2.15042114257813,44.4770278930664,,,,,,,,,,,,,,,,
,3735552716.3375,232.007209777832,99.8805694580078,9.37907641387045E-7,3.17630066293937E-7,1,0.999253354069792,40.0298881530762,1.99591649255838,14.5600000396371,1.19696518363773E-5,-8.73425812354882E-6,0.25,-9.73489515023849E-7,9.40962763361133E-7,-9.7489770573108E-7,231.988784790039,231.988784790039,99.8805694580078,99.8805694580078,54.5084280456019,19.7362568315338,34.8907318115234,0,0,0,40,234.670806884766,6,4,1,2.15286254882813,44.9657897949219,,,,,,,,,,,,,,,,
,3735552856.3125,235.511795043945,99.8684730529785,1.12032440567012E-6,3.58373310078207E-7,1,0.999253354069792,40.0298881530762,1.99590144483771,14.5600000396371,1.41267251530389E-5,-9.46836234423945E-6,0.25,-1.07356722790561E-6,1.12374343813161E-6,-1.07493399516495E-6,235.495178222656,235.495178222656,99.8442764282227,99.8926696777344,54.8679771644481,19.7352047662915,35.0853042602539,0,0,0,40,238.172439575195,6,4,1,2.14859008789062,44.4770278930664,,,,,,,,,,,,,,,,
,3735552996.3005,239.017753601074,99.8624229431152,1.82802676013055E-6,2.77454965484977E-7,1,0.999253354069792,40.0298881530762,1.99591689680334,14.5600000396371,2.10390736163505E-5,-3.99402359065212E-6,0.25,-6.90587860245283E-7,1.83243513712819E-6,-6.90429933241523E-7,239.007553100586,239.007553100586,99.8321762084961,99.8926696777344,55.1040289772558,19.7356000704687,35.3125267028809,0,0,0,40,241.681488037109,6,4,1,2.15072631835938,44.9657897949219,,,,,,,,,,,,,,,,
,3735553136.0235,242.506019592285,99.862419128418,1.95938767157152E-6,2.32909641254098E-7,1,0.999253354069792,40.0298881530762,1.99596787234259,14.5600000396371,2.24770618784772E-5,-3.87215970713491E-6,0.25,-7.02336358099398E-7,1.96383696733518E-6,-7.02034595585526E-7,242.498382568359,242.498382568359,99.8563690185547,99.8684692382813,54.7397900872942,19.7360712493838,35.4871292114258,0,0,0,40,245.187698364258,6,4,1,2.14996337890625,43.9882698059082,,,,,,,,,,,,,,,,
,3735553275.9165,246.00407409668,99.8805694580078,2.18345586540068E-6,2.7840985463948E-7,1,0.999253354069792,40.0298881530762,1.99604624489943,14.5600000396371,2.55733182164439E-5,-7.32625790320549E-6,0.25,-1.06167571664681E-6,2.18837715498469E-6,-1.0617925590936E-6,245.997680664062,245.997680664062,99.8684692382813,99.8926696777344,54.7046168039289,19.7360694011126,35.697624206543,0,0,0,40,248.704162597656,6,4,1,2.15133666992187,44.4770278930664,,,,,,,,,,,,,,,,
,3735553416.832,249.52530670166,99.8866195678711,2.64383934929259E-6,3.0407225927785E-7,1,0.999253354069792,40.0298881530762,1.99594519719653,14.5600000396371,3.09594720225698E-5,-8.86619689040873E-6,0.25,-1.28518318066138E-6,2.64946079488277E-6,-1.28520681611251E-6,249.515655517578,249.515655517578,99.8684692382813,99.9047698974609,55.0235212397751,19.7355540237167,35.9043388366699,0,0,0,40,252.266296386719,6,4,1,2.15118408203125,43.9882698059082,,,,,,,,,,,,,,,,
,3735553556.7545,253.023002624512,99.8442764282227,2.77011242181738E-6,2.64130505060957E-7,1,0.999253354069792,40.0298881530762,1.99599935118265,14.5600000396371,3.11466524890323E-5,-1.94027275378644E-6,0.25,-6.65441814053597E-7,2.77509569803307E-6,-6.64250882645578E-7,253.007522583008,253.007522583008,99.8442764282227,99.8442764282227,54.8218610818135,19.7344655642232,36.1526145935059,0,0,0,40,255.771240234375,6,4,1,2.1478271484375,44.4770278930664,,,,,,,,,,,,,,,,
,3735553696.6075,256.511108398438,99.862419128418,3.71681115656647E-6,3.25926877311215E-7,1,0.999253354069792,40.0298881530762,1.99597604462413,14.5600000396371,4.2092702137877E-5,-4.35526280314627E-6,0.25,-1.05523189075134E-6,3.72316884875393E-6,-1.05381684743588E-6,256.494445800781,256.494445800781,99.8563690185547,99.8684692382813,54.8828281063135,19.7353672294805,36.4157333374023,0,0,0,40,259.282012939453,6,4,1,2.14996337890625,44.9657897949219,,,,,,,,,,,,,,,,
,3735553836.5525,260.012435913086,99.856372833252,3.53130811123075E-6,3.27150363937665E-7,1,0.999253354069792,40.0298881530762,1.99602828399148,14.5600000396371,3.9833057708526E-5,-3.25403946928576E-6,0.25,-9.2061860327007E-7,3.53684346776314E-6,-9.19087037317075E-7,260.004028320313,260.004028320313,99.8321762084961,99.8805694580078,54.7171228602366,19.7380775537993,36.6855964660645,0,0,0,40,262.811889648438,6,4,1,2.16445922851562,44.4770278930664,,,,,,,,,,,,,,,,
,3735553976.56,263.519943237305,99.8321800231934,4.20489149768971E-6,3.82129517689236E-7,1,0.999253354069792,40.0298881530762,1.99608955569301,14.5600000396371,4.66387544245502E-5,6.20439622863283E-7,0.25,-6.79444414813182E-7,4.2106343897781E-6,-6.77023580392117E-7,263.510467529297,263.510467529297,99.8200836181641,99.8442764282227,54.7460431154481,19.7353598302918,36.9659843444824,0,0,0,40,266.317626953125,6,4,1,2.15011596679687,43.9882698059082,,,,,,,,,,,,,,,,
,3735554116.2895,267.001724243164,99.8382263183594,4.16983445151476E-6,2.59148230389042E-7,1,0.999253354069792,40.0298881530762,1.99604676949148,14.5600000396371,4.69223019791898E-5,-3.25925360835769E-6,0.25,-1.03298459687963E-6,4.17529166983521E-6,-1.03095535694282E-6,266.986877441406,266.986877441406,99.8079833984375,99.8684692382813,54.7429166013712,19.7354932406277,37.253662109375,0,0,0,40,269.8515625,6,4,1,2.15133666992187,44.4770278930664,,,,,,,,,,,,,,,,
,3735554256.1925,270.50212097168,99.8442726135254,5.2043694982541E-6,3.12749115633298E-7,1,0.999253354069792,40.0298881530762,1.99615804147368,14.5600000396371,5.85460623398281E-5,-3.99074605510389E-6,0.25,-1.28207760894864E-6,5.21052646553615E-6,-1.27944268813537E-6,270.493011474609,270.493011474609,99.8321762084961,99.8563690185547,54.7022719183712,19.7356106763787,37.5799255371094,0,0,0,40,273.366607666016,6,4,1,2.16461181640625,43.9882698059082,,,,,,,,,,,,,,,,
,3735554397.173,274.031127929687,99.8745193481445,4.96744072780441E-6,2.97472798090836E-7,1,0.999253354069792,40.0298881530762,1.99624810351826,14.5600000396371,5.55276343401116E-5,-1.81991933267433E-6,0.25,-1.03920919733857E-6,4.97255620229842E-6,-1.0364403340626E-6,274.021423339844,274.021423339844,99.8563690185547,99.8926696777344,54.8750118211212,19.7368479883192,37.9288597106934,0,0,0,40,276.887359619141,6,4,1,2.15103149414062,44.4770278930664,,,,,,,,,,,,,,,,
,3735554536.956,277.523849487305,99.8503227233887,5.5394712113215E-6,2.95001359254517E-7,1,0.999253354069792,40.0298881530762,1.99652839493906,14.5600000396371,6.21551457701367E-5,-3.35691363140449E-6,0.25,-1.28191525047834E-6,5.54457825990563E-6,-1.27884126413116E-6,277.517883300781,277.517883300781,99.8442764282227,99.8563690185547,54.8890811344673,19.7335059809591,38.3439102172852,0,0,0,40,280.393218994141,6,4,1,2.14797973632813,44.4770278930664,,,,,,,,,,,,,,,,
,3735554676.887,281.015441894531,99.8563690185547,5.88724444834945E-6,3.66315939034241E-7,1,0.999253354069792,40.0298881530762,1.9966210358126,14.5600000396371,6.56468755866202E-5,-1.25499595678051E-6,0.25,-1.14786838157455E-6,5.89178643998087E-6,-1.14436427181662E-6,281.000396728516,281.000396728516,99.8563690185547,99.8563690185547,54.6960188902173,19.7336426528098,38.7964744567871,0,0,0,40,283.926025390625,6,4,1,2.14889526367187,44.4770278930664,,,,,,,,,,,,,,,,
,3735554816.7595,284.513549804687,99.8442764282227,6.21368426351883E-6,3.91524157658187E-7,1,0.999253354069792,40.0298881530762,1.99673381237945,14.5600000396371,6.90623356851269E-5,-7.04467970456882E-8,0.25,-1.09513538402285E-6,6.21762481769197E-6,-1.09129590997005E-6,284.504180908203,284.504180908203,99.8442764282227,99.8442764282227,54.8718853070443,19.7327053187368,39.3040885925293,0,0,0,40,287.452392578125,6,4,1,2.16323852539062,44.9657897949219,,,,,,,,,,,,,,,,
,3735554956.722,288.015365600586,99.856372833252,6.28715816507774E-6,3.40388614824616E-7,1,0.999253354069792,40.0298881530762,1.99682470796804,14.5600000396371,7.01377700131251E-5,-1.58075404364126E-6,0.25,-1.24803371134195E-6,6.29046370934693E-6,-1.24413278890361E-6,288.006988525391,288.006988525391,99.8442764282227,99.8684692382813,54.7382268302558,19.7311320565583,39.8635177612305,0,0,0,40,290.958099365234,6,4,1,2.16522216796875,44.4770278930664,,,,,,,,,,,,,,,,
,3735555096.6825,291.514068603516,99.8926696777344,6.66709484334969E-6,3.05200969063813E-7,1,0.999253354069792,40.0298881530762,1.99701468057631,14.5600000396371,7.44232433493012E-5,-1.95876812512963E-6,0.25,-1.34959288124666E-6,6.66979177455737E-6,-1.3453688136383E-6,291.503784179687,291.503784179687,99.8805694580078,99.9047698974609,54.7116514606019,19.7300383225043,40.5165863037109,0,0,0,40,294.494140625,6,4,1,2.16506958007813,44.4770278930664,,,,,,,,,,,,,,,,
,3735555236.4505,295.002960205078,99.856372833252,7.21043744419891E-6,3.75480863370778E-7,1,0.999253354069792,40.0298881530762,1.99714651304571,14.5600000396371,7.94788494952835E-5,3.61761658151839E-6,0.25,-9.27415027656109E-7,7.21210325205093E-6,-9.22663121163353E-7,294.995361328125,294.995361328125,99.8442764282227,99.8684692382813,54.8038836258712,19.730767389262,41.2875900268555,0,0,0,40,298.015411376953,6,4,1,2.16217041015625,44.4770278930664,,,,,,,,,,,,,,,,
,3735555377.453,298.518859863281,99.8140335083008,6.80997779123524E-6,3.98160578963557E-7,1,0.999253354069792,40.0298881530762,1.99696370867926,14.5600000396371,7.49013937587487E-5,4.25801791113679E-6,0.25,-7.97713546477863E-7,6.81065757012609E-6,-7.93181820124227E-7,298.501983642578,298.501983642578,99.8079833984375,99.8200836181641,54.8116999110635,19.7326776017261,42.1436004638672,0,0,0,40,301.575805664063,6,4,1,2.14614868164062,44.4770278930664,,,,,,,,,,,,,,,,
,3735555517.387,302.008010864258,99.8261299133301,6.61314918817843E-6,3.18558449377868E-7,1,0.999253354069792,40.0298881530762,1.99698873753052,14.5600000396371,7.28422393544094E-5,3.48505325480285E-6,0.25,-8.34860448822233E-7,6.61304034663702E-6,-8.30420786060158E-7,301.996948242188,301.996948242188,99.8079833984375,99.8442764282227,54.6749149201981,19.732045759464,42.6663246154785,0,0,0,40,305.122833251953,6,4,1,2.16094970703125,44.9657897949219,,,,,,,,,,,,,,,,
,3735555658.1425,305.515716552734,99.8563690185547,7.58228673985624E-6,2.88389922056611E-7,1,0.999253354069792,40.0298881530762,1.99713839534846,14.5600000396371,8.37741340641169E-5,2.50311059053978E-6,0.25,-1.09563718815282E-6,7.58132112348858E-6,-1.09046814923414E-6,305.507598876953,305.507598876953,99.8563690185547,99.8563690185547,55.036808924602,19.7309689988151,43.1450653076172,0,0,0,40,308.686920166016,6,4,1,2.16079711914062,44.4770278930664,,,,,,,,,,,,,,,,
,3735555798.0115,309.007659912109,99.8624229431152,7.26823556149633E-6,4.14161802498161E-7,1,0.999253354069792,40.0298881530762,1.99721659380548,14.5600000396371,8.00059080415575E-5,4.06411553774857E-6,0.25,-8.95680219108661E-7,7.26632362470829E-6,-8.90714554720196E-7,309.00048828125,309.00048828125,99.8442764282227,99.8805694580078,54.8625057648135,19.7302443287635,43.6915397644043,0,0,0,40,312.228851318359,6,4,1,2.16156005859375,45.9433059692383,,,,,,,,,,,,,,,,
,3735555938.9945,312.51545715332,99.8140335083008,7.16877152881695E-6,2.90858665969897E-7,1,0.999253354069792,40.0298881530762,1.99724218823547,14.5600000396371,7.8735129101219E-5,4.96307897516403E-6,0.25,-7.94719866350226E-7,7.16595433155532E-6,-7.89817155998364E-7,312.507934570313,312.507934570313,99.7837905883789,99.8442764282227,54.8124815395827,19.7315722993945,44.3006248474121,0,0,0,40,315.803466796875,6,4,1,2.15988159179687,44.4770278930664,,,,,,,,,,,,,,,,
,3735556078.824,316.003173828125,99.8503227233887,6.18890429650911E-6,4.01677565282248E-7,1,0.999253354069792,40.0298881530762,1.99730253214212,14.5600000396371,6.76944800048254E-5,5.8400543343952E-6,0.25,-5.41629476349445E-7,6.1856335659937E-6,-5.37449468095177E-7,315.997161865234,315.997161865234,99.8321762084961,99.8684692382813,54.8156080536596,19.7281431252797,44.922119140625,0,0,0,40,319.328460693359,6,4,1,2.16033935546875,44.9657897949219,,,,,,,,,,,,,,,,
,3735556216.712,319.510192871094,99.8382263183594,6.63998294156066E-6,3.82805591885472E-7,1,0.999253354069792,40.0298881530762,1.99730966175693,14.5600000396371,7.34556826713234E-5,1.49153409470627E-6,0.25,-1.02419922569467E-6,6.6359435287018E-6,-1.01938595757978E-6,319.493408203125,319.493408203125,99.8200836181641,99.8563690185547,54.8797015922366,19.729392173299,45.5085334777832,0,0,0,40,322.936767578125,6,4,1,2.16033935546875,44.4770278930664,,,,,,,,,,,,,,,,
,3735556353.6885,323.004669189453,99.8563690185547,6.86703474246911E-6,3.78446908033085E-7,1,0.999253354069792,40.0298881530762,1.99724624297565,14.5600000396371,7.486205242163E-5,7.79016914307286E-6,0.25,-4.79055687770287E-7,6.86167568873771E-6,-4.74481586777298E-7,322.997741699219,322.997741699219,99.8563690185547,99.8563690185547,54.8249875958904,19.7264261230845,46.0015754699707,0,0,0,40,326.489135742188,6,4,1,2.161865234375,44.4770278930664,,,,,,,,,,,,,,,,
,3735556490.623,326.508483886719,99.8624229431152,6.24630888460371E-6,3.74733247106006E-7,1,0.999253354069792,40.0298881530762,1.9973497968151,14.5600000396371,6.85441219442469E-5,4.49351260807963E-6,0.25,-6.76387889864682E-7,6.24083051202569E-6,-6.71995194976112E-7,326.499237060547,326.499237060547,99.8321762084961,99.8926696777344,54.7022719183712,19.7276387529758,46.4603462219238,0,0,0,40,330.007049560547,6,4,1,2.15957641601562,45.4545478820801,,,,,,,,,,,,,,,,
,3735556628.5405,330.026748657227,99.8321762084961,6.1857635354089E-6,4.29059778745612E-7,1,0.999253354069792,40.0298881530762,1.99746730002145,14.5600000396371,6.82544132116327E-5,2.28464010906891E-6,0.25,-8.70835428567231E-7,6.17971498778768E-6,-8.66236868209362E-7,330.017395019531,330.017395019531,99.8321762084961,99.8321762084961,54.8984606766981,19.7256109636214,46.8430137634277,0,0,0,40,333.547912597656,6,4,1,2.16018676757813,46.4320640563965,,,,,,,,,,,,,,,,
,3735556766.3975,333.53466796875,99.8382263183594,5.89819153018967E-6,4.21881597782056E-7,1,0.999253354069792,40.0298881530762,1.99745148591389,14.5600000396371,6.56703055805884E-5,-1.23337921453611E-6,0.25,-1.14714982700556E-6,5.89190615445365E-6,-1.14233408265606E-6,333.526336669922,333.526336669922,99.8321762084961,99.8442764282227,54.894552534102,19.7265037694848,47.2437629699707,0,0,0,40,337.083740234375,6,4,1,2.16079711914062,44.4770278930664,,,,,,,,,,,,,,,,
,3735556903.2015,337.001266479492,99.856372833252,5.95600079139154E-6,3.56151537904609E-7,1,0.999253354069792,40.0298881530762,1.99748039954481,14.5600000396371,6.64478081080037E-5,-2.04936636377783E-6,0.25,-1.23303304339149E-6,5.94899616068113E-6,-1.22797801209897E-6,336.985687255859,336.985687255859,99.8442764282227,99.8684692382813,54.8867362489097,19.7255343581826,47.6283187866211,0,0,0,40,340.587677001953,6,4,1,2.1600341796875,44.4770278930664,,,,,,,,,,,,,,,,
,3735557041.0645,340.500961303711,99.9047660827637,6.40616007311265E-6,5.0315503135832E-7,1,0.999253354069792,40.0298881530762,1.99760233230623,14.5600000396371,7.1224036623169E-5,-8.23795764636198E-7,0.25,-1.19796762272113E-6,6.39779506797619E-6,-1.19259800072034E-6,340.492126464844,340.492126464844,99.8926696777344,99.916862487793,54.8288957384866,19.7250159309437,48.0026206970215,0,0,0,40,344.111907958984,6,4,1,2.16171264648438,44.4770278930664,,,,,,,,,,,,,,,,
,3735557180.0025,344.015533447266,99.8442764282227,6.30061975915339E-6,4.549112541102E-7,1,0.999253354069792,40.0298881530762,1.99762440652973,14.5600000396371,7.00869285060586E-5,-1.06050472008015E-6,0.25,-1.201449923634E-6,6.29166307039341E-6,-1.19603482173974E-6,344.0068359375,344.0068359375,99.8442764282227,99.8442764282227,54.8734485640827,19.7252520416707,48.3761100769043,0,0,0,40,347.673065185547,2,4,1,2.15850830078125,44.4770278930664,,,,,,,,,,,,,,,,
,3735557317.876,347.505767822266,99.8261299133301,5.68169541846612E-6,4.17481155243056E-7,1,0.999253354069792,40.0298881530762,1.99766472804919,14.5600000396371,6.29084305541251E-5,6.86472120498161E-7,0.25,-9.30775537535302E-7,5.67287188330616E-6,-9.26052194535655E-7,347.490783691406,347.490783691406,99.8200836181641,99.8321762084961,54.9054953333712,19.7244759840384,48.7504119873047,0,0,0,40,351.191223144531,2,4,1,2.16033935546875,44.4770278930664,,,,,,,,,,,,,,,,
,3735557539.7775,350.240707397461,99.862419128418,5.7068970371079E-6,3.83065241808985E-7,1,0.999253354069792,40.0298881530762,1.99776610495131,14.5600000396371,6.30728782301586E-5,1.32882312262014E-6,0.25,-8.75477269820563E-7,5.69748488725757E-6,-8.70777477156249E-7,350.240692138672,350.240692138672,99.8563690185547,99.8684692382813,54.759330800275,19.7233972368232,49.2245635986328,0,0,0,40,351.494079589844,1,4,1,2.16110229492187,44.4770278930664,,,,,,,,,,,,,,,,