File: data/doubleLayers/monolayer/ppms/DD205_4/rawdata/DD205_4_HYST_100OE_10K.DAT
[Header]
; VSM Data File (default extension .dat)
; Copyright (c) 2003-2013, Quantum Design, Inc. All rights reserved.
TITLE,
FILEOPENTIME,3735580552.635,05/15/2018,9:14 pm
BYAPP,VSM,1.0,1.0
INFO,DYNACOOL VSM Option Release 1.4.10 Build 1,APPNAME
INFO,Quantum Design Linear Motor Servo Controller,MOTOR_MODULE_NAME
INFO,3101-100 J0,MOTOR_HW_VERSION
INFO,MMC654,MOTOR_SERIAL_NUMBER
INFO,SRV No X-over 01.03.11,MOTOR_SOFTWARE_VERSION
INFO,Quantum Design VSM Detection Module,VSM_MODULE_NAME
INFO,3101-150 F0,VSM_HW_VERSION
INFO,VSM507,VSM_SERIAL_NUMBER
INFO,VSM No X-over 01.02.05 May 20 2008 13:51:47,VSM_SOFTWARE_VERSION
INFO,494,PREAMP_SERIAL_NUMBER
INFO,Quantum Design VSM Oven,OVEN_MODULE_NAME
INFO,3101-201 A1,OVEN_HW_VERSION
INFO,OVB210,OVEN_SERIAL_NUMBER
INFO,01.06.24,OVEN_SOFTWARE_VERSION
INFO,593,COIL_SERIAL_NUMBER
INFO,0,MOMENT_UNITS
INFO,,SAMPLE_MATERIAL
INFO,,SAMPLE_COMMENT
INFO,,SAMPLE_MASS
INFO,,SAMPLE_VOLUME
INFO,,SAMPLE_MOLECULAR_WEIGHT
INFO,,SAMPLE_SIZE
INFO,,SAMPLE_SHAPE
DATATYPE,COMMENT,1
DATATYPE,TIME,2
STARTUPAXIS,X,2
STARTUPAXIS,Y1,5
[Data]
Comment,Time Stamp (sec),Temperature (K),Magnetic Field (Oe),Moment (emu),M. Std. Err. (emu),Transport Action,Averaging Time (sec),Frequency (Hz),Peak Amplitude (mm),Center Position (mm),Coil Signal' (mV),Coil Signal" (mV),Range (mV),M. Quad. Signal (emu),M. Raw' (emu),M. Raw" (emu),Min. Temperature (K),Max. Temperature (K),Min. Field (Oe),Max. Field (Oe),Mass (grams),Motor Lag (deg),Pressure (Torr),VSM Status (code),Motor Status (code),Measure Status (code),Measure Count,System Temp. (K),Temp. Status (code),Field Status (code),Chamber Status (code),Motor Current (amps),Motor Heatsink Temp. (C),Map 01,Map 02,Map 03,Map 04,Map 05,Map 06,Map 07,Map 08,Map 09,Map 10,Map 11,Map 12,Map 13,Map 14,Map 15,Map 16
,3735580909.9835,9.99498605728149,-0.514162320643663,3.72531766419535E-5,3.54364629341483E-7,1,0.999253354069792,40.0298881530762,1.99569526249078,14.5600000396371,0.000399862122395865,6.43731749030168E-5,0.25,-6.68976162177222E-7,3.7035264517437E-5,-4.8548175200882E-7,9.99621677398682,9.99621677398682,-0.93154114484787,-0.0967834964394569,54.7562042861981,19.7566098150523,7.80248355865479,0,0,0,40,9.98888397216797,1,4,1,2.15179443359375,44.4770278930664,,,,,,,,,,,,,,,,
,3735581000.9765,10.0003643035889,4138.85791015625,3.076133712405E-5,3.59559728724347E-7,1,0.999253354069792,40.0298881530762,1.99558948115398,14.5600000396371,0.000330057280605204,5.41769334339653E-5,0.25,-4.65411015381157E-7,3.0587845816002E-5,-3.069143588791E-7,10.0003700256348,10.0003700256348,4113.876953125,4163.8388671875,54.7960673406789,19.7569933047768,7.80942630767822,0,0,0,40,9.99832916259766,1,6,1,2.15225219726562,43.9882698059082,,,,,,,,,,,,,,,,
,3735581085.0845,10.0005793571472,8343.1650390625,2.30414478610256E-5,4.93163784715611E-7,1,0.999253354069792,40.0298881530762,1.99557350180972,14.5600000396371,0.000248018214606981,3.66035741947894E-5,0.25,-7.28349315686136E-7,2.29205454512425E-5,-6.00661763100804E-7,10.0006399154663,10.0006399154663,8328.16015625,8358.169921875,54.7702735995443,19.7577308798931,7.81345129013062,0,0,0,40,9.99814414978027,1,6,1,2.15286254882813,43.9882698059082,,,,,,,,,,,,,,,,
,3735581168.9525,9.9999098777771,12535.8251953125,1.4643609607233E-5,6.50192621968349E-7,1,0.999253354069792,40.0298881530762,1.99553090893517,14.5600000396371,0.000158867658713389,1.66674299702945E-5,0.25,-1.0841863349352E-6,1.45754592102416E-5,-9.95520544861737E-7,9.99990653991699,9.99990653991699,12518.30859375,12553.341796875,54.6084764960635,19.7567663242388,7.82196855545044,0,0,0,40,9.99728012084961,1,6,1,2.15255737304687,43.9882698059082,,,,,,,,,,,,,,,,
,3735581252.725,10.0006947517395,16725.4150390625,6.24735408350091E-6,9.55073292147625E-7,1,0.999253354069792,40.0298881530762,1.99564985357111,14.5600000396371,6.52628124240555E-5,2.12034255434194E-5,0.25,8.51120118630752E-7,6.21291010399814E-6,8.84460177522451E-7,10.0008153915405,10.0008153915405,16702.869140625,16747.9609375,54.5123361881981,19.7561289110448,7.83596658706665,0,0,0,40,9.99693870544434,1,6,1,2.15347290039062,44.4770278930664,,,,,,,,,,,,,,,,
,3735581336.878,10.0000381469727,20933.220703125,-2.33329792713624E-6,7.52489779340454E-7,1,0.999253354069792,40.0298881530762,1.99552797750438,14.5600000396371,-2.82204161393857E-5,1.32897347710421E-5,0.25,1.66269454368057E-6,-2.33367432617342E-6,1.64095484524203E-6,10.0000381469727,10.0000381469727,20918.27734375,20948.1640625,54.5584522708327,19.7585367855659,7.84149932861328,0,0,0,40,9.99538421630859,1,6,1,2.15484619140625,44.9657897949219,,,,,,,,,,,,,,,,
,3735581420.609,10.000910282135,25121.240234375,-1.06872581059767E-5,8.76716513144059E-7,1,0.999253354069792,40.0298881530762,1.99545800686135,14.5600000396371,-0.000113484240611436,-2.65525848339355E-5,0.25,-5.41046115430581E-7,-1.06423104564385E-5,-6.08492501845809E-7,10.0007553100586,10.0007553100586,25098.75,25143.73046875,54.4591854488904,19.7583201105595,7.84628486633301,0,0,0,40,9.99616813659668,1,6,1,2.15362548828125,43.49951171875,,,,,,,,,,,,,,,,
,3735581504.711,9.99993181228638,29336.0556640625,-1.65848715975994E-5,9.9170816671816E-7,1,0.999253354069792,40.0298881530762,1.99551494341929,14.5600000396371,-0.000177608485167935,-3.34009329091865E-5,0.25,-1.06269685611579E-7,-1.65271033726942E-5,-2.17533636705313E-7,9.99987602233887,9.99987602233887,29321.025390625,29351.0859375,55.2955279644674,19.755996301614,7.84724807739258,0,0,0,40,9.99747180938721,1,6,1,2.15545654296875,43.9882698059082,,,,,,,,,,,,,,,,
,3735581588.548,9.99976062774658,33547.197265625,-2.58435584501584E-5,1.40542665733438E-6,1,0.999253354069792,40.0298881530762,1.99553843395034,14.5600000396371,-0.000273612424929519,-7.00988175768055E-5,0.25,-1.84143055164667E-6,-2.57533784516059E-5,-2.01482384782594E-6,10.0000295639038,10.0000295639038,33522.109375,33572.28515625,54.5529808711981,19.7587853545229,7.84545040130615,0,0,0,40,10.000599861145,1,6,1,2.13760375976562,44.4770278930664,,,,,,,,,,,,,,,,
,3735581672.4285,9.99938201904297,37756.498046875,-3.49733918954094E-5,1.83233614166213E-6,1,0.999253354069792,40.0298881530762,1.99539139523875,14.5600000396371,-0.000372190764600368,-8.5094047695228E-5,0.25,-1.57274427652558E-6,-3.48730884451686E-5,-1.81644477899957E-6,9.99938106536865,9.99938106536865,37733.89453125,37779.1015625,54.6819495768712,19.7583415588237,7.84536075592041,0,0,0,40,10.003098487854,1,6,1,2.1368408203125,43.9882698059082,,,,,,,,,,,,,,,,
,3735581756.3715,9.99947309494019,41969.896484375,-4.34860031039114E-5,1.80698256737375E-6,1,0.999253354069792,40.0298881530762,1.99543172308942,14.5600000396371,-0.000465325269506441,-9.30535892859284E-5,0.25,-7.57543411717182E-7,-4.33890559169902E-5,-1.06954484296789E-6,9.99951553344727,9.99951553344727,41944.80078125,41994.9921875,54.9109667330058,19.7586693953781,7.85054397583008,0,0,0,40,10.0046234130859,1,6,1,2.15164184570313,43.9882698059082,,,,,,,,,,,,,,,,
,3735581840.2995,9.99914073944092,46186.25390625,-5.30839784197841E-5,2.14757374692998E-6,1,0.999253354069792,40.0298881530762,1.9954641132862,14.5600000396371,-0.000566101608974546,-0.000125656775170381,0.25,-2.03829893632999E-6,-5.29807990585393E-5,-2.42293502935426E-6,9.99942398071289,9.99942398071289,46161.15625,46211.3515625,54.789814312525,19.7589499759825,7.85001611709595,0,0,0,40,10.0103397369385,1,6,1,2.15316772460938,44.4770278930664,,,,,,,,,,,,,,,,
,3735581924.322,9.99978113174439,50402.4765625,-6.50011794304741E-5,2.05813084771242E-6,1,0.999253354069792,40.0298881530762,1.99538734620282,14.5600000396371,-0.000693029284074075,-0.000156309252840212,0.25,-2.71330222633801E-6,-6.49011488090731E-5,-3.18962056658518E-6,9.99975204467773,9.99975204467773,50377.37109375,50427.58203125,55.0336824105251,19.7593544348289,7.8526086807251,0,0,0,40,10.0148639678955,1,6,1,2.15164184570313,43.9882698059082,,,,,,,,,,,,,,,,
,3735582008.1785,9.99927854537964,54630.078125,-7.05270495435584E-5,1.85413351203079E-6,1,0.999253354069792,40.0298881530762,1.9953957097498,14.5600000396371,-0.000751889792050896,-0.000171727806132777,0.25,-3.13264817317034E-6,-7.04467514498786E-5,-3.65358585053665E-6,9.99946212768555,9.99946212768555,54602.296875,54657.859375,55.1126268909674,19.7582206794308,7.85382413864136,0,0,0,40,10.0196809768677,1,6,1,2.16766357421875,43.9882698059082,,,,,,,,,,,,,,,,
,3735582092.2595,10.0005826950073,58882.62109375,-7.83717150355453E-5,1.94890567653891E-6,1,0.999253354069792,40.0298881530762,1.99546411467982,14.5600000396371,-0.000844225511554129,-0.000145163068378198,0.25,7.74929337561515E-7,-7.83462950091608E-5,1.91456553134889E-7,10.0007944107056,10.0007944107056,58864.97265625,58900.26953125,54.2239152646019,19.7583425851346,7.85538196563721,0,0,0,40,10.0244312286377,1,6,1,2.15606689453125,43.49951171875,,,,,,,,,,,,,,,,
,3735582176.0355,9.99892377853394,63120.08203125,-9.32265683695088E-5,2.5956902904612E-6,1,0.999253354069792,40.0298881530762,1.99548935655826,14.5600000396371,-0.000996144534757172,-0.000219451864521111,0.25,-3.42046418599968E-6,-9.32007926656324E-5,-4.1138351546775E-6,9.99915027618408,9.99915027618408,63097.33984375,63142.82421875,54.996164241602,19.7595097502227,7.8578028678894,0,0,0,40,10.0259256362915,1,6,1,2.15362548828125,43.9882698059082,,,,,,,,,,,,,,,,
,3735582259.998,9.99896764755249,67365.3046875,-0.00010543287507503,2.60542259843806E-6,1,0.999253354069792,40.0298881530762,1.99532072534203,14.5600000396371,-0.00113324511100006,-0.000213463355954171,0.25,-6.37313571928393E-7,-0.000105467701078327,-1.41929926390313E-6,9.99904632568359,9.99904632568359,67340.1015625,67390.5078125,54.3982184243904,19.7592941754204,7.85678911209106,0,0,0,40,10.0348281860352,1,6,1,2.15438842773438,44.4770278930664,,,,,,,,,,,,,,,,
,3735582344.062,9.99977111816406,71614.9609375,-0.000111547331326371,2.30420946666615E-6,1,0.999253354069792,40.0298881530762,1.99520551527677,14.5600000396371,-0.00119789905333004,-0.000233795440347321,0.25,-1.41143938746815E-6,-0.00011161915301598,-2.23507959100257E-6,9.99972152709961,9.99972152709961,71597.3359375,71632.5859375,54.9078402189289,19.761850348141,7.86093902587891,0,0,0,40,10.0390062332153,1,6,1,2.1551513671875,43.9882698059082,,,,,,,,,,,,,,,,
,3735582427.853,9.99931144714355,75855.14453125,-0.000126480015514254,3.33953655685262E-6,1,0.999253354069792,40.0298881530762,1.99534778336339,14.5600000396371,-0.00136166414757745,-0.000249572266789595,0.25,-1.5614408765313E-7,-0.000126615598433107,-1.08208478751733E-6,9.99943351745606,9.99943351745606,75829.8125,75880.4765625,55.0102335549481,19.7597661599976,7.8563928604126,0,0,0,40,10.0453729629517,1,6,1,2.15225219726562,43.9882698059082,,,,,,,,,,,,,,,,
,3735582511.874,9.99905490875244,80103.390625,-0.000134462876406748,3.07729834218662E-6,1,0.999253354069792,40.0298881530762,1.99537048444099,14.5600000396371,-0.00144288038824701,-0.000294071084159266,0.25,-2.83577644931083E-6,-0.000134631631368675,-3.81486444222737E-6,9.99910640716553,9.99910640716553,80083.1484375,80123.6328125,54.7952857121596,19.7581280541486,7.86514091491699,0,0,0,40,10.0517377853394,1,6,1,2.15362548828125,44.9657897949219,,,,,,,,,,,,,,,,
,3735582595.726,9.99891042709351,84342.8125,-0.000144917291052366,2.75742013527183E-6,1,0.999253354069792,40.0298881530762,1.99529680078762,14.5600000396371,-0.0015572612936476,-0.000307284126279752,0.25,-2.16417556260682E-6,-0.000145150577755182,-3.20745740032036E-6,9.99910640716553,9.99910640716553,84320.09375,84365.53125,54.5881541545635,19.758475232562,7.86713409423828,0,0,0,40,10.0574445724487,1,6,1,2.139892578125,44.4770278930664,,,,,,,,,,,,,,,,
,3735582679.656,9.99886131286621,88587.8125,-0.000156158099284255,3.3618864458105E-6,1,0.999253354069792,40.0298881530762,1.99520503369587,14.5600000396371,-0.00168333400701939,-0.000304446753512764,0.25,1.36397958887686E-7,-0.000156472830699168,-9.6990522940396E-7,9.99905204772949,9.99905204772949,88562.4921875,88613.1328125,54.8249875958904,19.760738598742,7.86962556838989,0,0,0,40,10.0632762908936,1,6,1,2.1563720703125,43.9882698059082,,,,,,,,,,,,,,,,
,3735582771.6765,10.0012488365173,87366.015625,-0.000156394455883329,3.42172992657831E-6,1,0.999253354069792,40.0298881530762,1.99531882358827,14.5600000396371,-0.00167051431545174,-0.000389176031621645,0.25,-7.67888840721585E-6,-0.00015664119003459,-8.80599108805092E-6,10.0011787414551,10.0011787414551,87346.0625,87385.96875,54.7476063724866,19.758078945412,7.87350940704346,0,0,0,40,10.0612363815308,1,6,1,2.15316772460938,44.4770278930664,,,,,,,,,,,,,,,,
,3735582855.516,10.0010142326355,83188.39453125,-0.000138079186477291,1.82276841124453E-6,1,0.999253354069792,40.0298881530762,1.99537537516667,14.5600000396371,-0.00149658931130103,-0.000221975446829918,0.25,4.51172504415993E-6,-0.000138337340368994,3.52551242353919E-6,10.0009746551514,10.0009746551514,83165.8515625,83210.9375,55.2572281670251,19.760058042385,7.8741021156311,0,0,0,40,10.0557746887207,1,6,1,2.15164184570313,44.4770278930664,,,,,,,,,,,,,,,,
,3735582939.5415,10.0005583763123,79000.94140625,-0.000126207693505278,2.69239537045117E-6,1,0.999253354069792,40.0298881530762,1.99522343697635,14.5600000396371,-0.00136708898371161,-0.000204527958631921,0.25,3.97440118598544E-6,-0.000126403788837292,3.06207800782484E-6,10.0003566741943,10.0003566741943,78981.078125,79020.8046875,54.8124815395827,19.7610452593058,7.87189245223999,0,0,0,40,10.0497217178345,1,6,1,2.13699340820313,43.9882698059082,,,,,,,,,,,,,,,,
,3735583023.5005,10.0013556480408,74815.546875,-0.00012322766907081,2.733984132577E-6,1,0.999253354069792,40.0298881530762,1.99518743472802,14.5600000396371,-0.00131957832553577,-0.000280807368058813,0.25,-3.65103093843202E-6,-0.000123323912609979,-4.55845605745208E-6,10.0015468597412,10.0015468597412,74795.6328125,74835.4609375,54.5436013289673,19.7587849367955,7.8772554397583,0,0,0,40,10.0444221496582,1,6,1,2.15225219726562,43.9882698059082,,,,,,,,,,,,,,,,
,3735583107.3375,10.0004930496216,70639.984375,-0.000105996024504219,1.97035996502825E-6,1,0.999253354069792,40.0298881530762,1.99535106696047,14.5600000396371,-0.00114698913275422,-0.000174271847893331,0.25,3.10885994886416E-6,-0.000106088479994753,2.32811086542206E-6,10.0006074905396,10.0006074905396,70615.0859375,70664.8828125,54.8445283088712,19.7587629742218,7.87566900253296,0,0,0,40,10.0387449264526,1,6,1,2.16705322265625,44.4770278930664,,,,,,,,,,,,,,,,
,3735583191.2635,10.0006489753723,66457.859375,-9.96470504085911E-5,2.26514784803133E-6,1,0.999253354069792,40.0298881530762,1.99538985637518,14.5600000396371,-0.00106879401302375,-0.000213887230776042,0.25,-1.73060470357467E-6,-9.96636620157371E-5,-2.47060430389379E-6,10.0006704330444,10.0006704330444,66430.4140625,66485.3046875,54.9578644441597,19.757529989652,7.88222408294678,0,0,0,40,10.0324783325195,1,6,1,2.15469360351562,43.49951171875,,,,,,,,,,,,,,,,
,3735583275.217,10.0010857582092,62275.1484375,-9.19861256783575E-5,1.68261936263395E-6,1,0.999253354069792,40.0298881530762,1.99529321802294,14.5600000396371,-0.000991221186513365,-0.000169833554206207,0.25,9.63788228991626E-7,-9.19858488419333E-5,2.79340039261687E-7,10.0009546279907,10.0009546279907,62250.2578125,62300.0390625,55.1243513187558,19.7595051718849,7.88413190841675,0,0,0,40,10.0289497375488,1,6,1,2.15164184570313,43.9882698059082,,,,,,,,,,,,,,,,
,3735583359.2745,10.0009622573853,58087.00390625,-8.16519015118048E-5,2.37586207883626E-6,1,0.999253354069792,40.0298881530762,1.99530360382232,14.5600000396371,-0.000875659006926812,-0.000171896813267343,0.25,-1.11636423867853E-6,-8.16049184926966E-5,-1.7232654929818E-6,10.0009622573853,10.0009622573853,58069.578125,58104.4296875,54.8148264251404,19.7591507041589,7.8813624382019,0,0,0,40,10.0230255126953,1,6,1,2.15347290039062,43.9882698059082,,,,,,,,,,,,,,,,
,3735583443.102,10.0011262893677,53909.9140625,-6.95485035815606E-5,1.55426633184955E-6,1,0.999253354069792,40.0298881530762,1.99535008871656,14.5600000396371,-0.00074558187272439,-0.000146306533709935,0.25,-9.47264461894899E-7,-6.94802852520202E-5,-1.4622538181587E-6,10.0010929107666,10.0010929107666,53885.01953125,53934.80859375,54.4263570510827,19.7591404215672,7.88443183898926,0,0,0,40,10.0180025100708,1,6,1,2.15591430664062,43.9882698059082,,,,,,,,,,,,,,,,
,3735583527.0655,10.0007901191711,49725.515625,-5.9648620753794E-5,1.82894984587038E-6,1,0.999253354069792,40.0298881530762,1.99524379441578,14.5600000396371,-0.000636989984202069,-0.000137291064796234,0.25,-1.92000594498141E-6,-5.95569528741713E-5,-2.35711526675295E-6,10.0009603500366,10.0009603500366,49700.65625,49750.375,54.9570828156404,19.7597058237108,7.8884391784668,0,0,0,40,10.013111114502,1,6,1,2.1551513671875,43.9882698059082,,,,,,,,,,,,,,,,
,3735583611.1335,10.0011291503906,45537.287109375,-5.07251464424928E-5,1.78266897908583E-6,1,0.999253354069792,40.0298881530762,1.99535326696007,14.5600000396371,-0.000536793044862607,-0.000142522222408583,0.25,-4.04032540391322E-6,-5.06078924476083E-5,-4.40344777548348E-6,10.0013074874878,10.0013074874878,45519.90234375,45554.671875,55.0930861779866,19.7582401694955,7.8887505531311,0,0,0,40,10.0082998275757,1,6,1,2.15347290039062,43.9882698059082,,,,,,,,,,,,,,,,
,3735583695.0365,9.99939727783203,41357.80078125,-4.22171560826498E-5,1.64538150356391E-6,1,0.999253354069792,40.0298881530762,1.99536432962586,14.5600000396371,-0.000453788116491936,-7.88738425219658E-5,0.25,3.31163417596956E-7,-4.21280004715569E-5,2.6707903720658E-8,9.99934387207031,9.99934387207031,41340.3515625,41375.25,55.0665108083327,19.7606229933499,7.88999795913696,0,0,0,40,10.0032567977905,1,6,1,2.1527099609375,43.9882698059082,,,,,,,,,,,,,,,,
,3735583778.94,9.99979496002197,37178.033203125,-3.3072871905877E-5,1.39443084529716E-6,1,0.999253354069792,40.0298881530762,1.99531684893941,14.5600000396371,-0.000354633830112772,-6.559442505755E-5,0.25,-1.02160222239006E-7,-3.2985801089776E-5,-3.35477871556973E-7,9.99988746643066,9.99988746643066,37160.37890625,37195.6875,55.1767204295443,19.7587412869427,7.88705968856812,0,0,0,40,10.0008754730225,1,6,1,2.15240478515625,43.9882698059082,,,,,,,,,,,,,,,,
,3735583862.843,10.0007119178772,32995.162109375,-2.27083551492126E-5,1.04643106516295E-6,1,0.999253354069792,40.0298881530762,1.99537204391297,14.5600000396371,-0.000240048681472738,-6.34461231600598E-5,0.25,-1.79197016434791E-6,-2.26266254611953E-5,-1.94317211533205E-6,10.0005922317505,10.0005922317505,32975.2265625,33015.09765625,54.9398869882174,19.758566612814,7.89058065414429,0,0,0,40,9.99999809265137,1,6,1,2.152099609375,43.9882698059082,,,,,,,,,,,,,,,,
,3735583946.846,9.99973392486572,28810.2294921875,-1.56238545713891E-5,9.63566213641663E-7,1,0.999253354069792,40.0298881530762,1.99542173799261,14.5600000396371,-0.000168311168474269,-2.58895824658278E-5,0.25,4.19307792130685E-7,-1.55720600416452E-5,3.13090658009473E-7,9.99965858459473,9.99965858459473,28795.236328125,28825.22265625,55.0282110108904,19.7591470013072,7.88968563079834,0,0,0,40,9.99708080291748,1,6,1,2.15164184570313,44.4770278930664,,,,,,,,,,,,,,,,
,3735584030.78,10.00075340271,24628.427734375,-6.50077034405073E-6,9.91857974105235E-7,1,0.999253354069792,40.0298881530762,1.99538210381092,14.5600000396371,-6.67847333849702E-5,-2.85067689945627E-5,0.25,-1.48240524130649E-6,-6.46564034341029E-6,-1.51870315220947E-6,10.0006265640259,10.0006265640259,24611.02734375,24645.828125,54.8523445940635,19.7580645868428,7.88882541656494,0,0,0,40,9.9950647354126,1,6,1,2.15301513671875,43.9882698059082,,,,,,,,,,,,,,,,
,3735584114.648,10.0002989768982,20448.869140625,1.22700757005121E-6,8.19928294967159E-7,1,0.999253354069792,40.0298881530762,1.99551169938481,14.5600000396371,1.59559553073739E-5,-1.31616394292946E-5,0.25,-1.45058149088434E-6,1.23070714099995E-6,-1.43664260005289E-6,10.0000772476196,10.0000772476196,20421.416015625,20476.322265625,54.7546410291596,19.7580354836913,7.88937854766846,0,0,0,40,9.99485683441162,1,6,1,2.166748046875,43.49951171875,,,,,,,,,,,,,,,,
,3735584198.522,10.0008039474487,16271.720703125,1.02658136103348E-5,6.59410775967055E-7,1,0.999253354069792,40.0298881530762,1.99547251939548,14.5600000396371,0.000111067579677451,1.35829870142632E-5,0.25,-5.85888352004288E-7,1.02206257147217E-5,-5.22075521587254E-7,10.0008182525635,10.0008182525635,16246.759765625,16296.681640625,54.8062285114289,19.7589232851169,7.88976526260376,0,0,0,40,9.99561214447021,1,6,1,2.15301513671875,43.0107536315918,,,,,,,,,,,,,,,,
,3735584282.4385,9.99967479705811,12090.4663085938,1.76894654580057E-5,5.44856899296284E-7,1,0.999253354069792,40.0298881530762,1.99548359711265,14.5600000396371,0.00018982116304203,3.16604719089819E-5,0.25,-2.32324440381358E-7,1.76003397279237E-5,-1.31249103494915E-7,9.99982929229736,9.99982929229736,12065.501953125,12115.4306640625,54.7327554306212,19.7583507744692,7.89034366607666,0,0,0,40,9.99584102630615,1,6,1,2.16461181640625,43.49951171875,,,,,,,,,,,,,,,,
,3735584366.575,9.99929571151733,7891.12036132813,2.57372320230932E-5,3.76467485317758E-7,1,0.999253354069792,40.0298881530762,1.99546970457915,14.5600000396371,0.000277540170101479,3.79481660317608E-5,0.25,-1.0868922901775E-6,2.56027262972018E-5,-9.43606593111779E-7,9.99957370758057,9.99957370758057,7873.67138671875,7908.5693359375,54.8898627629866,19.7583540348953,7.89437532424927,0,0,0,40,9.99580860137939,1,6,1,2.16583251953125,43.49951171875,,,,,,,,,,,,,,,,
,3735584450.425,10.0002880096436,3703.73986816406,3.27042688535857E-5,3.68247062876753E-7,1,0.999253354069792,40.0298881530762,1.99535730264475,14.5600000396371,0.000351064066783088,5.64292972753978E-5,0.25,-6.02384897891353E-7,3.25194380014116E-5,-4.34228705035997E-7,10.0002937316895,10.0002937316895,3683.71240234375,3723.76733398438,55.1087187483712,19.759717069923,7.89548683166504,0,0,0,40,9.99971866607666,1,6,1,2.15255737304687,43.49951171875,,,,,,,,,,,,,,,,
,3735584540.377,10.0000581741333,-792.114379882813,3.77478966752874E-5,2.88850914852122E-7,1,0.999253354069792,40.0298881530762,1.99541193345288,14.5600000396371,0.000405855577665975,6.11791188068586E-5,0.25,-1.05701606412674E-6,3.75300767344222E-5,-8.67552873985945E-7,10.0001592636108,10.0001592636108,-814.581420898438,-769.647338867187,54.5178075878327,19.7587480303547,7.89159059524536,0,0,0,40,10.0009632110596,1,6,1,2.15423583984375,43.9882698059082,,,,,,,,,,,,,,,,
,3735584627.191,10.0007410049438,-5133.384765625,4.33760765641728E-5,3.062251290544E-7,1,0.999253354069792,40.0298881530762,1.99541590134919,14.5600000396371,0.000465595890282796,7.5312575692654E-5,0.25,-7.60278738627339E-7,4.3134884404943E-5,-5.33197319106773E-7,10.0008773803711,10.0008773803711,-5158.3662109375,-5108.4033203125,54.4576221918519,19.7596018273431,7.88995027542114,0,0,0,40,9.99942874908447,1,6,1,2.15408325195313,44.4770278930664,,,,,,,,,,,,,,,,
,3735584714.2235,10.0005578994751,-9486.5048828125,4.88891630904808E-5,4.65484520796728E-7,1,0.999253354069792,40.0298881530762,1.99541479226912,14.5600000396371,0.000525229325338553,8.33462995847876E-5,0.25,-1.01887765824328E-6,4.86342733850741E-5,-7.46760271967784E-7,10.0005569458008,10.0005569458008,-9504.0126953125,-9468.9970703125,55.2204916266212,19.7578020032502,7.88306379318237,0,0,0,40,9.99687576293945,1,6,1,2.15194702148438,43.9882698059082,,,,,,,,,,,,,,,,
,3735584798.1565,10.0007734298706,-13681.3891601562,5.28040779912515E-5,5.84329457550705E-7,1,0.999253354069792,40.0298881530762,1.99557363937352,14.5600000396371,0.000566460362570409,9.60265492379396E-5,0.25,-5.59412733764315E-7,5.2544615239143E-5,-2.52364683268873E-7,10.0009269714355,10.0009269714355,-13698.8251953125,-13663.953125,54.9305074459866,19.7545927827987,7.88299417495727,0,0,0,40,9.99572849273682,1,6,1,2.15087890625,43.9882698059082,,,,,,,,,,,,,,,,
,3735584882.027,10.0000810623169,-17875.8037109375,5.26476592021471E-5,7.22688479735625E-7,1,0.999253354069792,40.0298881530762,1.99547801385498,14.5600000396371,0.000564023553373242,0.000101050478479004,0.25,-8.05910836907106E-8,5.24064270357276E-5,2.38579765892096E-7,10.000168800354,10.000168800354,-17903.298828125,-17848.30859375,55.649605683679,19.7576209597698,7.87961196899414,0,0,0,40,9.99445819854736,1,6,1,2.15545654296875,44.4770278930664,,,,,,,,,,,,,,,,
,3735584965.988,9.99849414825439,-22073.0283203125,4.62029831725875E-5,7.08931852530488E-7,1,0.999253354069792,40.0298881530762,1.99549477499273,14.5600000396371,0.00049655469691371,8.1169620725216E-5,0.25,-7.87721499353168E-7,4.60146678751536E-5,-4.92109616698625E-7,9.99843788146973,9.99843788146973,-22093.01953125,-22053.037109375,54.6592823498135,19.7546167964573,7.88042116165161,0,0,0,40,9.99592113494873,1,6,1,2.15362548828125,43.49951171875,,,,,,,,,,,,,,,,
,3735585049.849,10.0000867843628,-26268.736328125,4.0669457870792E-5,1.3584240342833E-6,1,0.999253354069792,40.0298881530762,1.9953525509239,14.5600000396371,0.00043565400352196,8.02457918069376E-5,0.25,1.15171208814842E-7,4.0515839669162E-5,3.81980697380695E-7,10.000147819519,10.000147819519,-26293.857421875,-26243.615234375,54.6139478956981,19.7590841082748,7.87973403930664,0,0,0,40,9.9955358505249,1,6,1,2.154541015625,43.9882698059082,,,,,,,,,,,,,,,,
,3735585133.86,9.99957370758057,-30483.9970703125,3.66991278681621E-5,1.12655140597302E-6,1,0.999253354069792,40.0298881530762,1.99541535762753,14.5600000396371,0.000396259643319352,5.61874813801589E-5,0.25,-1.42022853849222E-6,3.65869382349069E-5,-1.16646228732383E-6,9.99974918365479,9.99974918365479,-30509.126953125,-30458.8671875,54.4083795951404,19.7551029563015,7.88312196731567,0,0,0,40,9.99830532073975,1,6,1,2.166748046875,43.9882698059082,,,,,,,,,,,,,,,,
,3735585217.746,9.99875783920288,-34693.7109375,3.85852991238429E-5,1.3857305320198E-6,1,0.999253354069792,40.0298881530762,1.99538376783787,14.5600000396371,0.000416983906355095,5.81374710523511E-5,0.25,-1.59005602016667E-6,3.84854632584759E-5,-1.31656226190544E-6,9.99875926971436,9.99875926971436,-34718.7890625,-34668.6328125,54.7546410291596,19.75781283015,7.88088417053223,0,0,0,40,9.99889087677002,1,6,1,2.15545654296875,43.49951171875,,,,,,,,,,,,,,,,
,3735585301.886,9.99953031539917,-38916.259765625,4.49959336426891E-5,1.57621750323324E-6,1,0.999253354069792,40.0298881530762,1.9954974476103,14.5600000396371,0.00048501793705782,7.60413538015058E-5,0.25,-1.09590011043882E-6,4.48945562622266E-5,-7.72810346545724E-7,9.99972057342529,9.99972057342529,-38928.765625,-38903.75390625,54.7093065750442,19.7585061536102,7.8817343711853,0,0,0,40,10.0029640197754,1,6,1,2.15377807617187,43.49951171875,,,,,,,,,,,,,,,,
,3735585385.787,9.99967002868652,-43126.373046875,5.22737463342701E-5,1.48316244787985E-6,1,0.999253354069792,40.0298881530762,1.99544310982989,14.5600000396371,0.000565977902491055,7.58861881264939E-5,0.25,-2.44282737262162E-6,5.21878185971492E-5,-2.05945441296811E-6,9.99954891204834,9.99954891204834,-43143.95703125,-43108.7890625,54.769491971025,19.754233048177,7.88179779052734,0,0,0,40,10.0073575973511,1,6,1,2.1514892578125,43.9882698059082,,,,,,,,,,,,,,,,
,3735585469.552,9.99942827224731,-47331.03125,5.80038970677519E-5,1.6561535867931E-6,1,0.999253354069792,40.0298881530762,1.99535875337339,14.5600000396371,0.000630303925925411,7.30785530640863E-5,0.25,-3.75476932711418E-6,5.79418245937704E-5,-3.32372518479606E-6,9.99949836730957,9.99949836730957,-47353.61328125,-47308.44921875,54.5904990401212,19.7582635990552,7.88687944412231,0,0,0,40,10.0110120773315,1,6,1,2.1539306640625,44.4770278930664,,,,,,,,,,,,,,,,
,3735585553.599,9.99897766113281,-51549.130859375,6.83064651339374E-5,1.9679243575149E-6,1,0.999253354069792,40.0298881530762,1.99532760852711,14.5600000396371,0.000732252129055983,0.000142749357637935,0.25,8.4722022350815E-7,6.82240261175144E-5,1.35129559455352E-6,9.99874782562256,9.99874782562256,-51569.2421875,-51529.01953125,54.3067678876404,19.7605835115885,7.88558197021484,0,0,0,40,10.0133075714111,1,6,1,2.15499877929687,43.9882698059082,,,,,,,,,,,,,,,,
,3735585637.5175,9.99954795837402,-55789.447265625,7.85017731915851E-5,1.97551345467828E-6,1,0.999253354069792,40.0298881530762,1.99529884228724,14.5600000396371,0.000845575321674198,0.000143882337187583,0.25,-9.11974823076172E-7,7.845395857392E-5,-3.28093863755123E-7,9.99962425231934,9.99962425231934,-55812.16796875,-55766.7265625,54.5654869275058,19.7598636280672,7.89531755447388,0,0,0,40,10.0197372436523,1,6,1,2.15286254882813,43.9882698059082,,,,,,,,,,,,,,,,
,3735585721.552,9.99962377548218,-60035.482421875,8.85902299384399E-5,2.05735076039037E-6,1,0.999253354069792,40.0298881530762,1.99533451136871,14.5600000396371,0.000953290116170121,0.00016988950145787,0.25,-3.3740823273973E-7,8.85671303963865E-5,3.21991804643113E-7,9.99985313415527,9.99985313415527,-60053.09375,-60017.87109375,55.0117968119866,19.7603759067596,7.89770460128784,0,0,0,40,10.0241212844849,1,6,1,2.15179443359375,44.4770278930664,,,,,,,,,,,,,,,,
,3735585805.434,9.99893522262573,-64277.380859375,9.81960675265884E-5,2.38128525638944E-6,1,0.999253354069792,40.0298881530762,1.99535005345422,14.5600000396371,0.00105996060804111,0.000172545875403615,0.25,-1.84525466656876E-6,9.82197313170513E-5,-1.11553156742384E-6,9.99878978729248,9.99878978729248,-64295.0546875,-64259.70703125,55.0782352361212,19.7615068040767,7.90053415298462,0,0,0,40,10.0297002792358,1,6,1,2.1539306640625,44.4770278930664,,,,,,,,,,,,,,,,
,3735585889.2305,10.0003018379211,-68516.37109375,0.000109076595189816,2.14493437484946E-6,1,0.999253354069792,40.0298881530762,1.99528468184629,14.5600000396371,0.00116889299443537,0.000240701560469813,0.25,2.50434065223407E-6,0.000109109850743595,3.31328039914752E-6,10.0004940032959,10.0004940032959,-68541.625,-68491.1171875,55.3181951915251,19.7618502068089,7.89794254302979,0,0,0,40,10.0359954833984,1,6,1,2.1539306640625,43.9882698059082,,,,,,,,,,,,,,,,
,3735585973.341,9.99884986877441,-72767.70703125,0.000119754495610989,2.21544915076534E-6,1,0.999253354069792,40.0298881530762,1.99540454242919,14.5600000396371,0.00129085697948184,0.000225902048011101,0.25,-8.18433624035578E-7,0.000119860201633707,6.23840441908722E-8,9.9989767074585,9.9989767074585,-72782.9140625,-72752.5,54.8797015922366,19.7609010596691,7.90279722213745,0,0,0,40,10.0390090942383,1,6,1,2.15133666992187,43.49951171875,,,,,,,,,,,,,,,,
,3735586057.195,9.99922895431519,-77005.86328125,0.000131265445300473,2.48361369315319E-6,1,0.999253354069792,40.0298881530762,1.99536205932275,14.5600000396371,0.00141144804319755,0.000269327500090827,0.25,1.11964441794042E-6,0.000131411020507382,2.07949986965293E-6,9.99901390075684,9.99901390075684,-77028.578125,-76983.1484375,54.6202009238519,19.7598644131717,7.90035915374756,0,0,0,40,10.0465230941772,1,6,1,2.15179443359375,43.49951171875,,,,,,,,,,,,,,,,
,3735586141.2345,9.99922323226929,-81254.63671875,0.000141876139974674,3.37691070733843E-6,1,0.999253354069792,40.0298881530762,1.99538814681972,14.5600000396371,0.00152479245012153,0.000298114136544333,0.25,1.862719744249E-6,0.000142074571169253,2.89147953630684E-6,9.99923324584961,9.99923324584961,-81269.875,-81239.3984375,54.8984606766981,19.7598335541097,7.90622663497925,0,0,0,40,10.0522108078003,1,6,1,2.13592529296875,43.49951171875,,,,,,,,,,,,,,,,
,3735586224.991,9.99942779541016,-85485.5234375,0.000155503590600375,2.99108450557942E-6,1,0.999253354069792,40.0298881530762,1.99537308641666,14.5600000396371,0.001673131853635,0.000319229597594475,0.25,1.34778994078084E-6,0.000155773435427668,2.46219195248245E-6,9.99915885925293,9.99915885925293,-85510.765625,-85460.28125,55.0282110108904,19.7605635788112,7.9057092666626,0,0,0,40,10.0580501556396,1,6,1,2.15438842773438,43.49951171875,,,,,,,,,,,,,,,,
,3735586308.9295,9.99829006195068,-89731.21875,0.000158734682538769,3.72464504421352E-6,1,0.999253354069792,40.0298881530762,1.99532788180589,14.5600000396371,0.00171550140386066,0.000286603502707561,0.25,-2.25979333629186E-6,0.000159081629800724,-1.14360742345587E-6,9.99835300445557,9.99835300445557,-89756.4765625,-89705.9609375,54.6155111527366,19.761577309618,7.90667724609375,0,0,0,40,10.0642776489258,1,6,1,2.15194702148438,43.9882698059082,,,,,,,,,,,,,,,,
,3735586402.8405,10.0010704994202,-86141.75390625,0.000149781550229531,3.50316963865905E-6,1,0.999253354069792,40.0298881530762,1.99535359218824,14.5600000396371,0.0016213484615988,0.000254010425098967,0.25,-3.66260084656356E-6,0.000150083719094999,-2.60028097287837E-6,10.0011758804321,10.0011758804321,-86166.6640625,-86116.84375,55.0930861779866,19.7621541027307,7.90748882293701,0,0,0,40,10.0602159500122,1,6,1,2.15362548828125,43.49951171875,,,,,,,,,,,,,,,,
,3735586486.779,10.0005450248718,-81958.6875,0.000145550757282438,3.61414992917828E-6,1,0.999253354069792,40.0298881530762,1.99524244127551,14.5600000396371,0.00156727546818978,0.000289236720011034,0.25,3.72603858102473E-7,0.000145772985097615,1.42387134246345E-6,10.0007219314575,10.0007219314575,-81983.53125,-81933.84375,54.5178075878327,19.7628679946414,7.910240650177,0,0,0,40,10.054708480835,1,6,1,2.14096069335938,43.49951171875,,,,,,,,,,,,,,,,
,3735586570.6995,10.0012125968933,-77779.23828125,0.000124878184195275,2.54454801389089E-6,1,0.999253354069792,40.0298881530762,1.99519488966547,14.5600000396371,0.0013442119005093,0.000248138125759231,0.25,3.16515732784738E-7,0.000125029633954386,1.22730303942684E-6,10.0011959075928,10.0011959075928,-77804.1640625,-77754.3125,55.3971396719674,19.7646154083826,7.90635824203491,0,0,0,40,10.0477333068848,1,6,1,2.15438842773438,43.49951171875,,,,,,,,,,,,,,,,
,3735586654.641,10.0011072158813,-73600.9296875,0.000117691099060473,3.00340638166922E-6,1,0.999253354069792,40.0298881530762,1.9952267941684,14.5600000396371,0.00126942116921344,0.000217460901929201,0.25,-1.22522437753592E-6,0.000117806072975387,-3.61247951808464E-7,10.0008430480957,10.0008430480957,-73625.8671875,-73575.9921875,54.810136654025,19.7631967601296,7.89775562286377,0,0,0,40,10.0430688858032,1,6,1,2.15423583984375,44.4770278930664,,,,,,,,,,,,,,,,
,3735586738.5825,10.0003905296326,-69417.46875,0.000113230332912314,1.81581841454583E-6,1,0.999253354069792,40.0298881530762,1.99515601574348,14.5600000396371,0.00121722472574353,0.000229004448453147,0.25,6.61616127276316E-7,0.000113287956527628,1.49957226572713E-6,10.0005693435669,10.0005693435669,-69442.3671875,-69392.5703125,55.1493634313712,19.7612552154891,7.89480876922607,0,0,0,40,10.0372629165649,1,6,1,2.15408325195313,43.9882698059082,,,,,,,,,,,,,,,,
,3735586822.6575,10.0003018379211,-65227.943359375,9.82665825871166E-5,2.38898817993153E-6,1,0.999253354069792,40.0298881530762,1.99514843236343,14.5600000396371,0.00106124858179696,0.000169711337566901,0.25,-2.1208949945938E-6,9.83006687434554E-5,-1.39131713666662E-6,10.0002164840698,10.0002164840698,-65242.85546875,-65213.03125,55.3674377882366,19.763119535639,7.88884353637695,0,0,0,40,10.0321607589722,1,6,1,2.15667724609375,43.9882698059082,,,,,,,,,,,,,,,,
,3735586906.504,9.99998426437378,-61051.095703125,9.33276689983668E-5,2.20165931156855E-6,1,0.999253354069792,40.0298881530762,1.99512169752445,14.5600000396371,0.00100441470998851,0.000178132868263497,0.25,-4.33517590811992E-7,9.33127744042348E-5,2.61098319585817E-7,10.0002126693726,10.0002126693726,-61078.52734375,-61023.6640625,54.820297824775,19.7642629897102,7.88587665557861,0,0,0,40,10.0260696411133,1,6,1,2.15682983398438,43.49951171875,,,,,,,,,,,,,,,,
,3735586990.5125,10.0008163452148,-56867.318359375,7.441644824627E-5,2.06139226168877E-6,1,0.999253354069792,40.0298881530762,1.99526028618121,14.5600000396371,0.000803218418412901,0.00012773918325086,0.25,-1.67112749836374E-6,7.43849033145811E-5,-1.11685011269489E-6,10.0009469985962,10.0009469985962,-56884.7109375,-56849.92578125,54.7272840309866,19.7642334430557,7.88001203536987,0,0,0,40,10.0209636688232,1,6,1,2.15286254882813,43.9882698059082,,,,,,,,,,,,,,,,
,3735587074.4275,10.0002641677856,-52688.48046875,6.79403506291028E-5,2.73983075846874E-6,1,0.999253354069792,40.0298881530762,1.9951970628952,14.5600000396371,0.000732424073300912,0.000119703847453917,0.25,-1.2323586738737E-6,6.78814600757441E-5,-7.27980600770492E-7,10.0000905990601,10.0000905990601,-52705.890625,-52671.0703125,54.9305074459866,19.7630579206386,7.87988758087158,0,0,0,40,10.0166921615601,1,6,1,2.15286254882813,44.4770278930664,,,,,,,,,,,,,,,,
,3735587158.4475,10.0002751350403,-48504.595703125,6.07792144519561E-5,1.93703661335572E-6,1,0.999253354069792,40.0298881530762,1.99524313926365,14.5600000396371,0.000658748300968312,8.62369491889673E-5,0.25,-3.03652063131893E-6,6.07149775755038E-5,-2.58538796049574E-6,10.0004396438599,10.0004396438599,-48521.99609375,-48487.1953125,54.8421834233135,19.7598053360685,7.87544107437134,0,0,0,40,10.0124845504761,1,6,1,2.1368408203125,42.5219955444336,,,,,,,,,,,,,,,,
,3735587242.203,10.0003337860107,-44328.720703125,4.95245503799937E-5,1.68722438880919E-6,1,0.999253354069792,40.0298881530762,1.99521017372675,14.5600000396371,0.000538815474659392,5.76380343926529E-5,0.25,-3.64381830392386E-6,4.94591076042142E-5,-3.27700964064893E-6,10.0006465911865,10.0006465911865,-44353.62109375,-44303.8203125,54.5568890137942,19.7612912160213,7.87345886230469,0,0,0,40,10.0071811676025,1,6,1,2.15194702148438,43.49951171875,,,,,,,,,,,,,,,,
,3735587326.32,10.0007672309875,-40139.927734375,4.0859410633455E-5,1.56226921049925E-6,1,0.999253354069792,40.0298881530762,1.99504205430161,14.5600000396371,0.000439900449802987,7.17469297607928E-5,0.25,-7.44864561384971E-7,4.07708928708477E-5,-4.50625883901448E-7,10.0007486343384,10.0007486343384,-40154.8203125,-40125.03515625,54.8335855096019,19.7623418983512,7.86536121368408,0,0,0,40,10.0030965805054,1,6,1,2.15255737304687,43.9882698059082,,,,,,,,,,,,,,,,
,3735587410.194,10.000232219696,-35963.65234375,3.2587390388117E-5,1.41269730971374E-6,1,0.999253354069792,40.0298881530762,1.99512246406316,14.5600000396371,0.000349410415838864,6.42875717156158E-5,0.25,7.13427963023257E-8,3.24976062079146E-5,2.9986430466594E-7,10.0002040863037,10.0002040863037,-35981.05859375,-35946.24609375,54.9742786430635,19.7635548173364,7.86813831329346,0,0,0,40,10.0012788772583,1,6,1,2.1539306640625,43.9882698059082,,,,,,,,,,,,,,,,
,3735587494.003,10.0006022453308,-31789.552734375,2.32114660032199E-5,1.21422358137878E-6,1,0.999253354069792,40.0298881530762,1.99511614927991,14.5600000396371,0.00025170195068978,2.96101100970328E-5,0.25,-1.45246182692078E-6,2.31475493306343E-5,-1.28892118275705E-6,10.0004577636719,10.0004577636719,-31811.955078125,-31767.150390625,54.2332948068327,19.7635563160823,7.86775684356689,0,0,0,40,9.99790954589844,1,6,1,2.15621948242187,43.49951171875,,,,,,,,,,,,,,,,
,3735587577.955,10.0004944801331,-27606.09765625,1.4448636989262E-5,1.22609371112416E-6,1,0.999253354069792,40.0298881530762,1.99510210940189,14.5600000396371,0.000158037425182933,1.05347350964021E-5,0.25,-1.63722615235848E-6,1.44072030334129E-5,-1.53532017897115E-6,10.000319480896,10.000319480896,-27628.513671875,-27583.681640625,54.8992423052174,19.761694975479,7.86558723449707,0,0,0,40,9.99802303314209,1,6,1,2.14218139648438,43.9882698059082,,,,,,,,,,,,,,,,
,3735587661.9735,10.0003342628479,-23422.154296875,3.83754649916764E-6,1.04275255791383E-6,1,0.999253354069792,40.0298881530762,1.99514907515638,14.5600000396371,4.15365429047051E-5,5.11482562185887E-6,0.25,-2.17582183624594E-7,3.82340397619123E-6,-1.92108491338158E-7,10.0001058578491,10.0001058578491,-23444.60546875,-23399.703125,54.7061800609673,19.76204707213,7.86824369430542,0,0,0,40,9.99455165863037,1,6,1,2.1527099609375,43.9882698059082,,,,,,,,,,,,,,,,
,3735587745.9665,9.99985265731812,-19237.51953125,-3.18979622372599E-6,8.0056205004769E-7,1,0.999253354069792,40.0298881530762,1.99510022990686,14.5600000396371,-3.21028146172704E-5,-1.75600256745381E-5,0.25,-1.06284367114212E-6,-3.16903305575464E-6,-1.07770684439977E-6,9.99998378753662,9.99998378753662,-19264.869140625,-19210.169921875,54.627235580525,19.7583549698364,7.86542987823486,0,0,0,40,9.99357032775879,1,6,1,2.14065551757813,43.0107536315918,,,,,,,,,,,,,,,,
,3735587829.77,9.99933767318726,-15061.2583007813,-1.22930442423451E-5,5.88179406653248E-7,1,0.999253354069792,40.0298881530762,1.99516692186007,14.5600000396371,-0.00013052270364372,-2.97925652720353E-5,0.25,-5.63357776968121E-7,-1.22301013551195E-5,-6.32669444422728E-7,9.99952125549316,9.99952125549316,-15086.154296875,-15036.3623046875,54.7046168039289,19.7618738538791,7.86456537246704,0,0,0,40,9.99537944793701,1,6,1,2.1539306640625,43.9882698059082,,,,,,,,,,,,,,,,
,3735587913.719,10.0000562667847,-10878.5537109375,-2.00442087817215E-5,4.99392708187398E-7,1,0.999253354069792,40.0298881530762,1.99510239072559,14.5600000396371,-0.000212476871722702,-5.00192081530839E-5,0.25,-1.06106712615577E-6,-1.99337964810232E-5,-1.16693587119529E-6,9.99987411499023,9.99987411499023,-10903.4169921875,-10853.6904296875,54.6936740046596,19.762557851141,7.86585426330566,0,0,0,40,9.99430561065674,1,6,1,2.15164184570313,43.49951171875,,,,,,,,,,,,,,,,
,3735587997.73,10.0002346038818,-6683.24438476563,-2.80065935586052E-5,4.38095645107101E-7,1,0.999253354069792,40.0298881530762,1.99507130882629,14.5600000396371,-0.000297249116099365,-6.72795162396934E-5,0.25,-1.24952360224792E-6,-2.78448428305386E-5,-1.38958585653686E-6,10.0002193450928,10.0002193450928,-6700.6962890625,-6665.79248046875,54.8750118211212,19.7606504240721,7.85916519165039,0,0,0,40,9.99592208862305,1,6,1,2.15408325195313,43.9882698059082,,,,,,,,,,,,,,,,
,3735588084.8065,9.99908065795898,-2332.27868652344,-3.47940509327972E-5,2.34674099076862E-7,1,0.999253354069792,40.0298881530762,1.99508157340154,14.5600000396371,-0.000370243412798851,-7.76875883090377E-5,0.25,-1.01374444580617E-6,-3.45863046068135E-5,-1.17988830117394E-6,9.99907875061035,9.99907875061035,-2344.72290039062,-2319.83447265625,54.7366635732173,19.7609646820569,7.86090517044067,0,0,0,40,9.99819183349609,1,6,1,2.15240478515625,43.9882698059082,,,,,,,,,,,,,,,,
,3735588171.607,9.99943351745606,2005.80206298828,-3.97623529138278E-5,3.18209836046088E-7,1,0.999253354069792,40.0298881530762,1.9950983967007,14.5600000396371,-0.000423258368477045,-8.79366207950733E-5,0.25,-1.08048896256278E-6,-3.95246250683058E-5,-1.2699730623242E-6,9.99909019470215,9.99909019470215,1988.30041503906,2023.3037109375,55.128259461352,19.7605273811202,7.86190366744995,0,0,0,40,9.99837589263916,1,6,1,2.15164184570313,43.9882698059082,,,,,,,,,,,,,,,,
,3735588258.4265,10.0001440048218,6348.61279296875,-4.52638777502591E-5,3.40333680245414E-7,1,0.999253354069792,40.0298881530762,1.99507614051253,14.5600000396371,-0.000482315978600317,-9.80821027596856E-5,0.25,-1.02499934024178E-6,-4.50066082492995E-5,-1.25574649335052E-6,9.9999418258667,9.9999418258667,6323.591796875,6373.6337890625,54.7812163988135,19.7604696168375,7.85772514343262,0,0,0,40,9.99820709228516,1,6,1,2.1539306640625,43.9882698059082,,,,,,,,,,,,,,,,
,3735588345.3835,10.0000295639038,10696.400390625,-5.03701168958575E-5,5.10753422794145E-7,1,0.999253354069792,40.0298881530762,1.99512959343585,14.5600000396371,-0.000536797553930893,-0.000109856863845977,0.25,-1.18717700672126E-6,-5.01001362330722E-5,-1.46023909036346E-6,10.0001678466797,10.0001678466797,10673.8330078125,10718.9677734375,54.2958250883711,19.7608239321374,7.84743309020996,0,0,0,40,9.99387264251709,1,6,1,2.15347290039062,43.49951171875,,,,,,,,,,,,,,,,
,3735588429.3215,9.99968147277832,14893.5307617188,-5.22722456696927E-5,5.97770382524816E-7,1,0.999253354069792,40.0298881530762,1.99511076142254,14.5600000396371,-0.000557804933985551,-0.000111047040440758,0.25,-9.36057188218714E-7,-5.20123744463912E-5,-1.23722867830031E-6,9.99953937530518,9.99953937530518,14868.5478515625,14918.513671875,54.5475094715635,19.7615056719396,7.84468555450439,0,0,0,40,9.9935941696167,1,6,1,2.16873168945313,44.4770278930664,,,,,,,,,,,,,,,,
,3735588513.3175,10.0007085800171,19093.7412109375,-5.08110780315289E-5,7.65686960182957E-7,1,0.999253354069792,40.0298881530762,1.99509704506011,14.5600000396371,-0.000540971021070852,-0.00011600075290593,0.25,-1.64385188985081E-6,-5.05736014630774E-5,-1.94830565400617E-6,10.0005931854248,10.0005931854248,19073.755859375,19113.7265625,54.5404748148904,19.7612597726562,7.84526205062866,0,0,0,40,9.9947681427002,1,6,1,2.13897705078125,43.49951171875,,,,,,,,,,,,,,,,
,3735588597.3675,10.0001521110535,23297.228515625,-4.47165050503655E-5,1.32227076804843E-6,1,0.999253354069792,40.0298881530762,1.99511101308421,14.5600000396371,-0.000477554042587442,-9.51037557333068E-5,0.25,-7.79132007531318E-7,-4.45299139090658E-5,-1.0621990958896E-6,10.0000448226929,10.0000448226929,23279.662109375,23314.794921875,54.820297824775,19.7603208293798,7.84429788589478,0,0,0,40,9.99486064910889,1,6,1,2.152099609375,43.9882698059082,,,,,,,,,,,,,,,,
,3735588681.118,9.99995565414429,27490.1279296875,-3.84925879435168E-5,1.13263661832971E-6,1,0.999253354069792,40.0298881530762,1.9950452592851,14.5600000396371,-0.000410989051386296,-8.33283218281397E-5,0.25,-7.95045252440267E-7,-3.83474904418631E-5,-1.04761922436999E-6,10.0001068115234,10.0001068115234,27465.017578125,27515.23828125,54.5310952726596,19.7604007973179,7.84810638427734,0,0,0,40,9.99633884429932,1,6,1,2.15499877929687,43.0107536315918,,,,,,,,,,,,,,,,
,3735588765.058,10.0002055168152,31703.2841796875,-3.68252682005478E-5,1.23469622839382E-6,1,0.999253354069792,40.0298881530762,1.99510756859454,14.5600000396371,-0.000393767149608704,-7.75776496261571E-5,0.25,-5.49899413836166E-7,-3.67039887100278E-5,-8.0012797738576E-7,10.0002918243408,10.0002918243408,31680.705078125,31725.86328125,54.1269933282173,19.7583138243883,7.84976530075073,0,0,0,40,9.99727916717529,1,6,1,2.137451171875,43.9882698059082,,,,,,,,,,,,,,,,
,3735588848.97,9.99949169158936,35917.755859375,-3.86022313976985E-5,1.69988842348026E-6,1,0.999253354069792,40.0298881530762,1.995122702699,14.5600000396371,-0.000412189327659178,-8.55728234074512E-5,0.25,-9.62748064619456E-7,-3.8489524853975E-5,-1.23097178604752E-6,9.99959754943848,9.99959754943848,35892.69921875,35942.8125,54.6796046913135,19.7585414755776,7.85054779052734,0,0,0,40,9.99991416931152,1,6,1,2.152099609375,43.0107536315918,,,,,,,,,,,,,,,,
,3735588932.9755,9.99898910522461,40133.619140625,-4.48060716999956E-5,1.30910478726445E-6,1,0.999253354069792,40.0298881530762,1.9950605115969,14.5600000396371,-0.000481050979287925,-8.60672022939402E-5,0.25,1.28171659881477E-7,-4.4704043863558E-5,-1.92897747122639E-7,9.99906063079834,9.99906063079834,40108.4609375,40158.77734375,54.8570343651789,19.757964400852,7.85065698623657,0,0,0,40,10.0025272369385,1,6,1,2.15316772460938,43.9882698059082,,,,,,,,,,,,,,,,
,3735589016.9985,9.99957084655762,44349.8515625,-5.40738289553431E-5,1.50513241664916E-6,1,0.999253354069792,40.0298881530762,1.99509843868944,14.5600000396371,-0.000580030122904995,-0.000108266295209346,0.25,-2.4453298877523E-7,-5.39717921630566E-5,-6.37223633959239E-7,9.99939441680908,9.99939441680908,44334.7890625,44364.9140625,55.3299196193135,19.7557507267184,7.85717725753784,0,0,0,40,10.0048360824585,1,6,1,2.15316772460938,43.0107536315918,,,,,,,,,,,,,,,,
,3735589100.7935,9.99959993362427,48556.095703125,-6.12325053352647E-5,2.3474560100616E-6,1,0.999253354069792,40.0298881530762,1.99516304733065,14.5600000396371,-0.000654418999467385,-0.000137521867623423,0.25,-1.65615228655728E-6,-6.11334470736471E-5,-2.10399366976857E-6,9.99970626831055,9.99970626831055,48530.95703125,48581.234375,54.925036046352,19.7550425346562,7.85470581054687,0,0,0,40,10.0095252990723,1,6,1,2.1539306640625,43.9882698059082,,,,,,,,,,,,,,,,
,3735589184.765,9.99985408782959,52778.1328125,-6.96867485109084E-5,1.88099112866415E-6,1,0.999253354069792,40.0298881530762,1.99506459941823,14.5600000396371,-0.000746117051487889,-0.000150741157922065,0.25,-1.33886207573793E-6,-6.96076896545487E-5,-1.8536728056074E-6,9.9999885559082,9.9999885559082,52752.796875,52803.46875,54.9539563015635,19.7574911660749,7.85667705535889,0,0,0,40,10.014497756958,1,6,1,2.15347290039062,43.49951171875,,,,,,,,,,,,,,,,
,3735589268.6615,9.99889850616455,57020.318359375,-7.63180280817764E-5,2.51893384552973E-6,1,0.999253354069792,40.0298881530762,1.99506907057591,14.5600000396371,-0.000820054046921107,-0.000150902615719831,0.25,-1.38368255851606E-7,-7.62730327992588E-5,-7.05765165423884E-7,9.99912071228027,9.99912071228027,56995.015625,57045.62109375,54.8070101399481,19.7544658145629,7.85771179199219,0,0,0,40,10.0195865631104,1,6,1,2.15530395507813,43.49951171875,,,,,,,,,,,,,,,,
,3735589352.764,9.99979782104492,61272.94140625,-8.86406349386511E-5,2.27266307687441E-6,1,0.999253354069792,40.0298881530762,1.99517516193819,14.5600000396371,-0.000958413333043667,-0.00014505099216453,0.25,2.65687034211842E-6,-8.86450230682916E-5,1.99677764227361E-6,9.99974250793457,9.99974250793457,61252.734375,61293.1484375,55.2970912215058,19.7555959737753,7.8588490486145,0,0,0,40,10.0253953933716,1,6,1,2.15484619140625,43.9882698059082,,,,,,,,,,,,,,,,
,3735589436.5965,9.9997878074646,65513.3203125,-9.68773615758506E-5,3.56434809964459E-6,1,0.999253354069792,40.0298881530762,1.99512089309392,14.5600000396371,-0.00104231468250916,-0.000188966977955695,0.25,7.79324779422216E-8,-9.68984757478499E-5,-6.41550784299896E-7,9.9997501373291,9.9997501373291,65485.375,65541.265625,54.7366635732173,19.7572524278711,7.86520099639893,0,0,0,40,10.0296230316162,1,6,1,2.15347290039062,43.49951171875,,,,,,,,,,,,,,,,
,3735589520.4685,9.99900054931641,69752.9375,-0.000111520136200711,2.69421274051755E-6,1,0.999253354069792,40.0298881530762,1.99513570118601,14.5600000396371,-0.00119972467540798,-0.000220816254583633,0.25,-2.12143187327855E-7,-0.000111583325295455,-1.03684867049844E-6,9.99931049346924,9.99931049346924,69727.6015625,69778.2734375,54.8124815395827,19.7582236914522,7.86738300323486,0,0,0,40,10.0348558425903,1,6,1,2.15118408203125,43.9882698059082,,,,,,,,,,,,,,,,
,3735589604.4825,9.99925374984741,74002.69921875,-0.00012085735717368,2.64283729250323E-6,1,0.999253354069792,40.0298881530762,1.99514397669635,14.5600000396371,-0.00130962110224999,-0.000190032262892481,0.25,4.34862352165108E-6,-0.000121002052109612,3.46496017471525E-6,9.99912738800049,9.99912738800049,73979.9453125,74025.453125,54.7499512580443,19.755664807346,7.86599254608154,0,0,0,40,10.0409021377563,1,6,1,2.15286254882813,43.9882698059082,,,,,,,,,,,,,,,,
,3735589688.4005,9.99789714813232,78248.52734375,-0.000128852941665861,3.23072641425406E-6,1,0.999253354069792,40.0298881530762,1.99503356840529,14.5600000396371,-0.00138460702201949,-0.000268847783492094,0.25,-1.51826951734141E-6,-0.000129005188092564,-2.45860183940174E-6,9.99806118011475,9.99806118011475,78223.203125,78273.8515625,55.2744239944482,19.7548174256724,7.86046028137207,0,0,0,40,10.0445594787598,1,6,1,2.15591430664062,43.0107536315918,,,,,,,,,,,,,,,,
,3735589772.391,9.99896144866943,82493.2265625,-0.000136998333084597,3.20198000377485E-6,1,0.999253354069792,40.0298881530762,1.99505263819036,14.5600000396371,-0.00148110427010402,-0.000239259598750838,0.25,2.70830189731255E-6,-0.000137234895102434,1.72499180419007E-6,9.99917697906494,9.99917697906494,82475.4453125,82511.0078125,55.0657291798135,19.7551572956704,7.85685920715332,0,0,0,40,10.0498161315918,1,6,1,2.15347290039062,43.0107536315918,,,,,,,,,,,,,,,,
,3735589856.229,9.99826288223267,86732.94921875,-0.000152984228022552,3.49075280323682E-6,1,0.999253354069792,40.0298881530762,1.9951041562526,14.5600000396371,-0.00164964742907465,-0.000293739152988444,0.25,5.54371245620372E-7,-0.000153276338687083,-5.34654039258249E-7,9.99814128875732,9.99814128875732,86707.4921875,86758.40625,55.1603062306404,19.7554280311208,7.85601186752319,0,0,0,40,10.056004524231,1,6,1,2.15240478515625,43.49951171875,,,,,,,,,,,,,,,,
,3735589924.1685,9.99913835525513,90004.84375,-0.00016579193442908,2.51787058151576E-6,1,0.999253354069792,40.0298881530762,1.99506953519413,14.5600000396371,-0.00179058660307951,-0.000304796738554763,0.25,1.85058502689627E-6,-0.000166153678358971,6.84741229656988E-7,9.99898147583008,9.99898147583008,90000.5234375,90009.1640625,54.7108698320827,19.7534697773761,7.8493127822876,0,0,0,40,10.0613536834717,1,4,1,2.1527099609375,43.49951171875,,,,,,,,,,,,,,,,