File: data/doubleLayers/monolayer/ppms/DD205_4/rawdata/DD205_4_HYST_100OE_20K.DAT
[Header]
; VSM Data File (default extension .dat)
; Copyright (c) 2003-2013, Quantum Design, Inc. All rights reserved.
TITLE,
FILEOPENTIME,3735589995.17126,05/15/2018,11:52 pm
BYAPP,VSM,1.0,1.0
INFO,DYNACOOL VSM Option Release 1.4.10 Build 1,APPNAME
INFO,Quantum Design Linear Motor Servo Controller,MOTOR_MODULE_NAME
INFO,3101-100 J0,MOTOR_HW_VERSION
INFO,MMC654,MOTOR_SERIAL_NUMBER
INFO,SRV No X-over 01.03.11,MOTOR_SOFTWARE_VERSION
INFO,Quantum Design VSM Detection Module,VSM_MODULE_NAME
INFO,3101-150 F0,VSM_HW_VERSION
INFO,VSM507,VSM_SERIAL_NUMBER
INFO,VSM No X-over 01.02.05 May 20 2008 13:51:47,VSM_SOFTWARE_VERSION
INFO,494,PREAMP_SERIAL_NUMBER
INFO,Quantum Design VSM Oven,OVEN_MODULE_NAME
INFO,3101-201 A1,OVEN_HW_VERSION
INFO,OVB210,OVEN_SERIAL_NUMBER
INFO,01.06.24,OVEN_SOFTWARE_VERSION
INFO,593,COIL_SERIAL_NUMBER
INFO,0,MOMENT_UNITS
INFO,,SAMPLE_MATERIAL
INFO,,SAMPLE_COMMENT
INFO,,SAMPLE_MASS
INFO,,SAMPLE_VOLUME
INFO,,SAMPLE_MOLECULAR_WEIGHT
INFO,,SAMPLE_SIZE
INFO,,SAMPLE_SHAPE
DATATYPE,COMMENT,1
DATATYPE,TIME,2
STARTUPAXIS,X,2
STARTUPAXIS,Y1,5
[Data]
Comment,Time Stamp (sec),Temperature (K),Magnetic Field (Oe),Moment (emu),M. Std. Err. (emu),Transport Action,Averaging Time (sec),Frequency (Hz),Peak Amplitude (mm),Center Position (mm),Coil Signal' (mV),Coil Signal" (mV),Range (mV),M. Quad. Signal (emu),M. Raw' (emu),M. Raw" (emu),Min. Temperature (K),Max. Temperature (K),Min. Field (Oe),Max. Field (Oe),Mass (grams),Motor Lag (deg),Pressure (Torr),VSM Status (code),Motor Status (code),Measure Status (code),Measure Count,System Temp. (K),Temp. Status (code),Field Status (code),Chamber Status (code),Motor Current (amps),Motor Heatsink Temp. (C),Map 01,Map 02,Map 03,Map 04,Map 05,Map 06,Map 07,Map 08,Map 09,Map 10,Map 11,Map 12,Map 13,Map 14,Map 15,Map 16
,3735590352.845,19.9913606643677,-0.272203586995602,3.70106506197518E-5,3.2658532468648E-7,1,0.999253354069792,40.0298881530762,1.99545914153691,14.5600000396371,0.000397673675796869,6.13769351065319E-5,0.25,-9.05787644072697E-7,3.67951536716858E-5,-7.21096380547121E-7,19.991512298584,19.991512298584,-0.387133985757828,-0.157273188233376,54.7280656595058,19.7567299635761,9.66485595703125,0,0,0,40,20.0033321380615,1,4,1,2.15194702148438,43.49951171875,,,,,,,,,,,,,,,,
,3735590443.898,19.9977712631226,4141.44360351562,2.88036447966727E-5,3.64217643925809E-7,1,0.999253354069792,40.0298881530762,1.99541829955914,14.5600000396371,0.000308857279879684,5.1660977701431E-5,0.25,-3.48991915073899E-7,2.86406361981849E-5,-2.00375505901186E-7,19.9976806640625,19.9976806640625,4118.93603515625,4163.951171875,54.6608456068519,19.7569584075262,9.75288486480713,0,0,0,40,20.0108795166016,1,6,1,2.152099609375,43.9882698059082,,,,,,,,,,,,,,,,
,3735590527.862,19.9990901947021,8340.69287109375,1.97178733498718E-5,4.10075668355438E-7,1,0.999253354069792,40.0298881530762,1.99544661821118,14.5600000396371,0.000212847667923917,2.78894017714618E-5,0.25,-9.44430520339444E-7,1.96160686741665E-5,-8.32989069980522E-7,19.9990386962891,19.9990386962891,8323.2353515625,8358.150390625,54.4974852463327,19.7567009073273,9.80757713317871,0,0,0,40,20.0118026733398,1,6,1,2.15362548828125,43.49951171875,,,,,,,,,,,,,,,,
,3735590611.6485,19.9990558624268,12528.3725585938,9.77965987026195E-6,5.68547035982684E-7,1,0.999253354069792,40.0298881530762,1.99538665866943,14.5600000396371,0.000104821945536291,1.81679763847303E-5,0.25,-6.68604937659979E-8,9.73036883727225E-6,-1.07952361289253E-8,19.9990425109863,19.9990425109863,12503.423828125,12553.3212890625,54.4396447359096,19.754722418917,9.85023021697998,0,0,0,40,20.0132484436035,1,6,1,2.15469360351562,43.49951171875,,,,,,,,,,,,,,,,
,3735590695.584,19.9994277954102,16723.0341796875,1.59533820843238E-6,5.79465862142925E-7,1,0.999253354069792,40.0298881530762,1.99541094723268,14.5600000396371,1.5803430724292E-5,1.0174989712142E-5,0.25,6.61913266963841E-7,1.58386731339226E-6,6.68361886151263E-7,19.999532699585,19.999532699585,16698.001953125,16748.06640625,55.2369058255251,19.7566541630645,9.88208675384521,0,0,0,40,20.0122032165527,1,6,1,2.16690063476562,43.9882698059082,,,,,,,,,,,,,,,,
,3735590779.5245,20.0005044937134,20920.8583984375,-8.20102910425912E-6,7.66941923943758E-7,1,0.999253354069792,40.0298881530762,1.99537661974458,14.5600000396371,-8.6342827013534E-5,-2.42418721333065E-5,0.25,-7.78909802389122E-7,-8.16086464321672E-6,-8.26973715381923E-7,20.0004234313965,20.0004234313965,20898.337890625,20943.37890625,54.7202493743135,19.7555806329893,9.90897846221924,0,0,0,40,20.0126266479492,1,6,1,2.15362548828125,43.9882698059082,,,,,,,,,,,,,,,,
,3735590863.5385,20.0009164810181,25123.849609375,-1.78651867455667E-5,8.02219221055031E-7,1,0.999253354069792,40.0298881530762,1.99535525077145,14.5600000396371,-0.000189927041252426,-4.30969786921106E-5,0.25,-7.8412924667445E-7,-1.77907389803084E-5,-8.97557381288222E-7,20.0009384155273,20.0009384155273,25103.8671875,25143.83203125,54.7632389428712,19.7545607533189,9.93121337890625,0,0,0,40,20.0129566192627,1,6,1,2.1527099609375,43.49951171875,,,,,,,,,,,,,,,,
,3735590947.393,20.0002603530884,29331.15625,-2.75419097968081E-5,1.28960989463706E-6,1,0.999253354069792,40.0298881530762,1.99535919940338,14.5600000396371,-0.000295138320692689,-5.42841428733318E-5,0.25,-6.62216175185508E-8,-2.74465435781196E-5,-2.51639657109153E-7,20.0002250671387,20.0002250671387,29306.052734375,29356.259765625,54.6342702371981,19.7559803295721,9.9484691619873,0,0,0,40,20.0133113861084,1,6,1,2.15560913085938,43.9882698059082,,,,,,,,,,,,,,,,
,3735591031.4655,20.0004711151123,33549.962890625,-3.67029831067937E-5,1.19581410086797E-6,1,0.999253354069792,40.0298881530762,1.99532483344119,14.5600000396371,-0.00039274169039117,-7.64203829155195E-5,0.25,-4.58884445035586E-7,-3.65895964020809E-5,-7.11889401204148E-7,20.0004692077637,20.0004692077637,33532.3828125,33567.54296875,54.5787746123327,19.7567366600608,9.96382999420166,0,0,0,40,20.0127506256104,1,6,1,2.1661376953125,43.49951171875,,,,,,,,,,,,,,,,
,3735591115.318,19.9998617172241,37759.359375,-4.61570766224453E-5,1.14353735081433E-6,1,0.999253354069792,40.0298881530762,1.99533921159189,14.5600000396371,-0.000495146100684838,-9.05555907592788E-5,0.25,-4.86379168212989E-8,-4.60387065429617E-5,-3.75720436654786E-7,19.9998302459717,19.9998302459717,37734.31640625,37784.40234375,54.6499028075827,19.7538150566746,9.9780216217041,0,0,0,40,20.0114612579346,1,6,1,2.15438842773438,43.49951171875,,,,,,,,,,,,,,,,
,3735591199.354,20.0002164840698,41980.1640625,-5.6717671211373E-5,1.12067272480717E-6,1,0.999253354069792,40.0298881530762,1.99533168177019,14.5600000396371,-0.000602277619764248,-0.000146647315350328,0.25,-3.34353053292197E-6,-5.65737713319082E-5,-3.74575196471381E-6,20.00022315979,20.00022315979,41960.1171875,42000.2109375,54.7429166013712,19.7548638166402,9.98864936828613,0,0,0,40,20.0129489898682,1,6,1,2.15530395507813,43.0107536315918,,,,,,,,,,,,,,,,
,3735591283.257,20.0002279281616,46188.99609375,-6.70395916317299E-5,1.53020993650485E-6,1,0.999253354069792,40.0298881530762,1.99525151486689,14.5600000396371,-0.000717153046955668,-0.000146011976475301,0.25,-1.39479472120873E-6,-6.69172310653575E-5,-1.88270570684109E-6,20.0002918243408,20.0002918243408,46171.41796875,46206.57421875,55.0954310635443,19.7537809962663,10.0003223419189,0,0,0,40,20.0112953186035,1,6,1,2.15423583984375,43.9882698059082,,,,,,,,,,,,,,,,
,3735591367.202,19.9993906021118,50402.798828125,-7.73961750485708E-5,1.70708038321263E-6,1,0.999253354069792,40.0298881530762,1.99534195091666,14.5600000396371,-0.000827540449194674,-0.000173007591372934,0.25,-2.01098441938005E-6,-7.72851704576476E-5,-2.57975275467027E-6,19.9994716644287,19.9994716644287,50382.765625,50422.83203125,54.227823407198,19.7532339715227,10.0090370178223,0,0,0,40,20.0126895904541,1,6,1,2.15347290039062,43.49951171875,,,,,,,,,,,,,,,,
,3735591451.004,20.0000295639038,54627.919921875,-8.84140198529362E-5,1.73734975072706E-6,1,0.999253354069792,40.0298881530762,1.99526550197432,14.5600000396371,-0.000949642034253962,-0.000176117725768981,0.25,-2.84493740569883E-7,-8.83392332360248E-5,-9.40567030087589E-7,19.9999446868896,19.9999446868896,54602.63671875,54653.203125,54.1402810130442,19.7555172190154,10.0201454162598,0,0,0,40,20.0111598968506,1,6,1,2.15103149414062,42.5219955444336,,,,,,,,,,,,,,,,
,3735591535.0715,19.9998168945313,58880.36328125,-9.79738210125805E-5,1.75811872096497E-6,1,0.999253354069792,40.0298881530762,1.99522239462333,14.5600000396371,-0.00105193173763686,-0.000199631858487783,0.25,-7.2261468050462E-7,-9.79280453365799E-5,-1.45134223061958E-6,19.9999160766602,19.9999160766602,58860.109375,58900.6171875,54.884391363352,19.756070923713,10.0273523330688,0,0,0,40,20.011116027832,1,6,1,2.15316772460938,43.49951171875,,,,,,,,,,,,,,,,
,3735591618.9845,20.0005540847778,63125.513671875,-0.000108983148747067,1.44554392152652E-6,1,0.999253354069792,40.0298881530762,1.99534124149003,14.5600000396371,-0.00116978947879525,-0.000226969716479878,0.25,-1.25131092752847E-6,-0.000108971820644397,-2.06179116892079E-6,20.0005588531494,20.0005588531494,63107.73828125,63143.2890625,54.5521992426788,19.75481797117,10.0349283218384,0,0,0,40,20.0115451812744,1,6,1,2.15362548828125,43.49951171875,,,,,,,,,,,,,,,,
,3735591702.812,20.0005340576172,67365.86328125,-0.000119502753583523,2.191882451264E-6,1,0.999253354069792,40.0298881530762,1.99515294118612,14.5600000396371,-0.00128349008168583,-0.000246654739551814,0.25,-1.1619497664877E-6,-0.000119536985192044,-2.04829879675246E-6,20.0005187988281,20.0005187988281,67340.6015625,67391.125,55.1610878591597,19.7538900225224,10.0398092269897,0,0,0,40,20.0108127593994,1,6,1,2.15133666992187,43.49951171875,,,,,,,,,,,,,,,,
,3735591786.754,20.0003433227539,71607.8046875,-0.000130175772722317,2.24282450084499E-6,1,0.999253354069792,40.0298881530762,1.99525418110626,14.5600000396371,-0.00140021472400464,-0.000260431077363589,0.25,-4.94417192578634E-7,-0.000130265697332485,-1.4545589815854E-6,20.000467300415,20.000467300415,71582.5,71633.109375,54.5318769011788,19.7559995227294,10.0469779968262,0,0,0,40,20.0108489990234,1,6,1,2.15194702148438,43.49951171875,,,,,,,,,,,,,,,,
,3735591870.798,20.0003957748413,75860.609375,-0.000141513993067767,2.35994126468856E-6,1,0.999253354069792,40.0298881530762,1.99516336349162,14.5600000396371,-0.00152014985354441,-0.000296821517259679,0.25,-1.8108239522537E-6,-0.00014165111230941,-2.84829666393311E-6,20.0003223419189,20.0003223419189,75840.2890625,75880.9296875,54.8257692244096,19.7543790779857,10.0530862808228,0,0,0,40,20.0108795166016,1,6,1,2.15545654296875,43.9882698059082,,,,,,,,,,,,,,,,
,3735591954.6125,19.9998731613159,80098.578125,-0.000154582036353128,2.62280752615142E-6,1,0.999253354069792,40.0298881530762,1.99515928707154,14.5600000396371,-0.00166138777170427,-0.000322557580748404,0.25,-1.8237362819844E-6,-0.000154783336400636,-2.94697166381835E-6,19.9999160766602,19.9999160766602,80073.296875,80123.859375,54.6522476931404,19.755572373668,10.0622367858887,0,0,0,40,20.0105018615723,1,6,1,2.1527099609375,43.49951171875,,,,,,,,,,,,,,,,
,3735592038.657,19.9998073577881,84348.26953125,-0.000161753812138494,2.4186582882271E-6,1,0.999253354069792,40.0298881530762,1.99522552279258,14.5600000396371,-0.00174231759074172,-0.000319717522177247,0.25,-2.58228302333774E-7,-0.000162026380971106,-1.41865964432375E-6,19.9998931884766,19.9998931884766,84325.515625,84371.0234375,54.8656322788904,19.7551766086744,10.0688810348511,0,0,0,40,20.0094051361084,1,6,1,2.15377807617187,44.4770278930664,,,,,,,,,,,,,,,,
,3735592122.664,19.9997730255127,88593.28125,-0.000174546416500616,2.35626017685787E-6,1,0.999253354069792,40.0298881530762,1.99518173511589,14.5600000396371,-0.00188209905303317,-0.000336953067131429,0.25,4.61322123880355E-7,-0.000174896686772542,-7.74258180123099E-7,19.9997024536133,19.9997024536133,88578.078125,88608.484375,54.4685649911211,19.755493624774,10.0735282897949,0,0,0,40,20.0099315643311,1,6,1,2.15408325195313,43.9882698059082,,,,,,,,,,,,,,,,
,3735592216.546,20.0000686645508,87318.82421875,-0.00016870279863842,2.53391719885551E-6,1,0.999253354069792,40.0298881530762,1.99522736956935,14.5600000396371,-0.00181469336164449,-0.00034919262092627,0.25,-1.73387296889028E-6,-0.000169011386086533,-2.93683267516934E-6,20.0000076293945,20.0000076293945,87296.3671875,87341.28125,54.3466309421211,19.7567016195171,10.0813446044922,0,0,0,40,20.0087375640869,1,6,1,2.15377807617187,43.9882698059082,,,,,,,,,,,,,,,,
,3735592300.3825,20.0006828308105,83140.8203125,-0.000162236377555403,2.4581675286051E-6,1,0.999253354069792,40.0298881530762,1.99517077581076,14.5600000396371,-0.00174715702988032,-0.000321532320449655,0.25,-3.38371705772311E-7,-0.000162495232389509,-1.50614919871947E-6,20.0006446838379,20.0006446838379,83115.921875,83165.71875,54.8398385377558,19.7577163903458,10.0859956741333,0,0,0,40,20.0101337432861,1,6,1,2.1539306640625,43.9882698059082,,,,,,,,,,,,,,,,
,3735592384.2915,19.9996042251587,78961.02734375,-0.000150205048651098,2.29421828389516E-6,1,0.999253354069792,40.0298881530762,1.99517033991161,14.5600000396371,-0.00161529021030307,-0.00030749547501276,0.25,-1.22093579066159E-6,-0.000150391766298575,-2.31439644424561E-6,19.9996719360352,19.9996719360352,78936.125,78985.9296875,54.3607002554673,19.757924586696,10.0896511077881,0,0,0,40,20.0105781555176,1,6,1,2.15423583984375,43.9882698059082,,,,,,,,,,,,,,,,
,3735592468.3375,19.9996156692505,74770.640625,-0.000138909155599482,1.94045923094411E-6,1,0.999253354069792,40.0298881530762,1.99518337903576,14.5600000396371,-0.00149824852324975,-0.000257303165750408,0.25,1.38576302487281E-6,-0.000139054912171837,3.68478459316366E-7,19.9995727539062,19.9995727539062,74750.7421875,74790.5390625,54.6803863198327,19.7545818661913,10.0917558670044,0,0,0,40,20.0109748840332,1,6,1,2.13714599609375,43.49951171875,,,,,,,,,,,,,,,,
,3735592552.173,19.9999485015869,70595.10546875,-0.000129083990159089,2.00063262783382E-6,1,0.999253354069792,40.0298881530762,1.99521556351734,14.5600000396371,-0.0013881706401837,-0.000259087227481121,0.25,-5.6930850303019E-7,-0.000129161671318403,-1.52283749786882E-6,20.0001525878906,20.0001525878906,70570.2265625,70619.984375,54.6819495768712,19.7558285635557,10.0929040908813,0,0,0,40,20.0113162994385,1,6,1,2.154541015625,43.49951171875,,,,,,,,,,,,,,,,
,3735592636.172,19.9999408721924,66410.4296875,-0.000118307560677023,1.69042884989927E-6,1,0.999253354069792,40.0298881530762,1.9951247278979,14.5600000396371,-0.00127062131674656,-0.00024366401801099,0.25,-1.10295350714426E-6,-0.000118331913931322,-1.98113992386651E-6,20.0002098083496,20.0002098083496,66385.5546875,66435.3046875,54.7585491717558,19.7552194959481,10.0943212509155,0,0,0,40,20.0111713409424,1,6,1,2.15530395507813,43.9882698059082,,,,,,,,,,,,,,,,
,3735592720.1885,19.9998445510864,62222.66015625,-0.000106776176457543,1.47718257150326E-6,1,0.999253354069792,40.0298881530762,1.99525849784769,14.5600000396371,-0.00114949011841301,-0.000202970116448596,0.25,5.7599667783741E-7,-0.00010676967966736,-2.18426783234251E-7,19.9997806549072,19.9997806549072,62205.203125,62240.1171875,54.813263168102,19.753954500579,10.0951595306396,0,0,0,40,20.0112266540527,1,6,1,2.15377807617187,43.49951171875,,,,,,,,,,,,,,,,
,3735592804.0035,20.0001001358032,58046.8828125,-9.73493792827757E-5,1.12058790403868E-6,1,0.999253354069792,40.0298881530762,1.99523536523881,14.5600000396371,-0.00104403323867868,-0.000204481151335616,0.25,-1.28889247313816E-6,-9.7291945926107E-5,-2.01247266537577E-6,20.0000114440918,20.0000114440918,58024.41015625,58069.35546875,54.2692497187173,19.7547077332943,10.0971593856812,0,0,0,40,20.0114231109619,1,6,1,2.15164184570313,43.49951171875,,,,,,,,,,,,,,,,
,3735592887.937,20.0003538131714,53864.90234375,-8.67447026173554E-5,1.89035175212837E-6,1,0.999253354069792,40.0298881530762,1.99523666316068,14.5600000396371,-0.000926554627652897,-0.000200641302971195,0.25,-2.87250020310048E-6,-8.664558841416E-5,-3.51334193209991E-6,20.0002613067627,20.0002613067627,53839.94921875,53889.85546875,54.7874694269673,19.7535049522741,10.1001663208008,0,0,0,40,20.0117015838623,1,6,1,2.15560913085938,43.9882698059082,,,,,,,,,,,,,,,,
,3735592971.9675,20.0001277923584,49677.9375,-7.6212467204738E-5,1.2710219570369E-6,1,0.999253354069792,40.0298881530762,1.99518299441582,14.5600000396371,-0.00081535105416343,-0.000167103938666681,0.25,-1.6800221580496E-6,-7.60998038730595E-5,-2.23959371032855E-6,20.0000801086426,20.0000801086426,49660.57421875,49695.30078125,54.7163412317173,19.753467334767,10.1029891967773,0,0,0,40,20.0121994018555,1,6,1,2.1539306640625,43.49951171875,,,,,,,,,,,,,,,,
,3735593055.7905,20.0001230239868,45502.255859375,-6.58824512609767E-5,1.61104731373197E-6,1,0.999253354069792,40.0298881530762,1.99528834353146,14.5600000396371,-0.00070480929075979,-0.000143086384376806,0.25,-1.33455944109829E-6,-6.57578031686248E-5,-1.81310668197711E-6,20.0001029968262,20.0001029968262,45479.81640625,45524.6953125,54.7132147176404,19.7553180252777,10.1055355072021,0,0,0,40,20.0122947692871,1,6,1,2.15362548828125,43.49951171875,,,,,,,,,,,,,,,,
,3735593139.793,19.9991016387939,41317.7734375,-5.59120460489382E-5,9.92023209544494E-7,1,0.999253354069792,40.0298881530762,1.99517836748929,14.5600000396371,-0.00059917054283773,-0.000114132745294585,0.25,-4.63466492069974E-7,-5.57867454647761E-5,-8.64922325085061E-7,19.9990234375,19.9990234375,41295.40234375,41340.14453125,54.5224973589481,19.7551737076752,10.1069116592407,0,0,0,40,20.0125160217285,1,6,1,2.16964721679687,43.9882698059082,,,,,,,,,,,,,,,,
,3735593223.714,19.9996900558472,37135.234375,-4.53137952819159E-5,1.59884905144184E-6,1,0.999253354069792,40.0298881530762,1.99506927611364,14.5600000396371,-0.000486397228537963,-8.67265275485519E-5,0.25,1.52398361970697E-7,-4.51960091146081E-5,-1.68258207075417E-7,19.9997043609619,19.9997043609619,37110.26953125,37160.19921875,54.9508297874866,19.7563661757299,10.1110248565674,0,0,0,40,20.0132102966309,1,6,1,2.15179443359375,43.49951171875,,,,,,,,,,,,,,,,
,3735593307.6255,19.9996786117554,32955.171875,-3.55616275782501E-5,1.26705564128188E-6,1,0.999253354069792,40.0298881530762,1.9951693129196,14.5600000396371,-0.000379943388940258,-7.69688703699313E-5,0.25,-7.19194057626777E-7,-3.54476465441089E-5,-9.62575744574546E-7,19.9997673034668,19.9997673034668,32930.37109375,32979.97265625,54.4677833626019,19.755543537851,10.1129007339478,0,0,0,40,20.013204574585,1,6,1,2.15362548828125,43.9882698059082,,,,,,,,,,,,,,,,
,3735593391.5285,19.9996995925903,28775.134765625,-2.69997947984461E-5,8.53622804857719E-7,1,0.999253354069792,40.0298881530762,1.99515958064992,14.5600000396371,-0.000287330573061236,-6.39787027589435E-5,0.25,-1.07051747351623E-6,-2.68979904501095E-5,-1.24801682866235E-6,19.9995098114014,19.9995098114014,28750.34765625,28799.921875,54.6858577194673,19.7566187592767,10.1145687103271,0,0,0,40,20.0125980377197,1,6,1,2.15545654296875,43.9882698059082,,,,,,,,,,,,,,,,
,3735593475.5995,19.9999904632568,24583.255859375,-1.51576650552102E-5,9.33722296794162E-7,1,0.999253354069792,40.0298881530762,1.99519063600793,14.5600000396371,-0.000160978361074714,-3.73516669790592E-5,0.25,-7.39575783722311E-7,-1.50932043837887E-5,-8.35020803746988E-7,20.0000743865967,20.0000743865967,24565.791015625,24600.720703125,54.8023203688327,19.7574206000443,10.115216255188,0,0,0,40,20.011791229248,1,6,1,2.15530395507813,43.49951171875,,,,,,,,,,,,,,,,
,3735593559.533,19.9995880126953,20403.650390625,-6.69119412309241E-6,8.38944358744908E-7,1,0.999253354069792,40.0298881530762,1.99520136687696,14.5600000396371,-6.9399212931521E-5,-2.55154349906374E-5,0.25,-1.17154795289157E-6,-6.65476302135122E-6,-1.20817917748462E-6,19.9994354248047,19.9994354248047,20386.08203125,20421.21875,55.2204916266212,19.755453016754,10.1179885864258,0,0,0,40,20.012243270874,1,6,1,2.1527099609375,43.49951171875,,,,,,,,,,,,,,,,
,3735593643.3855,19.9993581771851,16224.0078125,3.55743569660797E-6,6.82420619729046E-7,1,0.999253354069792,40.0298881530762,1.99511065717622,14.5600000396371,4.00637492095803E-5,-4.05256492850331E-6,0.25,-1.02112503082061E-6,3.54662452669298E-6,-9.95074866646848E-7,19.9992923736572,19.9992923736572,16201.6416015625,16246.3740234375,54.8414017947943,19.755259129631,10.1209106445312,0,0,0,40,20.0135536193848,1,6,1,2.1527099609375,43.0107536315918,,,,,,,,,,,,,,,,
,3735593727.559,19.9998483657837,12030.1318359375,1.25297846531797E-5,4.16415346848372E-7,1,0.999253354069792,40.0298881530762,1.99513625077376,14.5600000396371,0.000136378620337948,1.16189536898147E-5,0.25,-1.174036220769E-6,1.24722583407115E-5,-1.09707860164813E-6,19.9998626708984,19.9998626708984,12010.1962890625,12050.0673828125,54.962554215275,19.7559281866211,10.1232213973999,0,0,0,40,20.0128860473633,1,6,1,2.15545654296875,43.0107536315918,,,,,,,,,,,,,,,,
,3735593811.2635,19.9998121261597,7853.373046875,2.21890460377576E-5,3.77262924065142E-7,1,0.999253354069792,40.0298881530762,1.99513412156436,14.5600000396371,0.000238542823575819,3.65738042530622E-5,0.25,-5.76501865738844E-7,2.20710129575781E-5,-4.54500655173306E-7,19.9997215270996,19.9997215270996,7828.45263671875,7878.29345703125,54.7265024024673,19.7586037439851,10.1267757415771,0,0,0,40,20.0141677856445,1,6,1,2.15408325195313,43.49951171875,,,,,,,,,,,,,,,,
,3735593895.294,20.0000524520874,3655.83142089844,3.08946652089232E-5,2.83828775479033E-7,1,0.999253354069792,40.0298881530762,1.99504349881139,14.5600000396371,0.00033164728190437,5.29626199644152E-5,0.25,-6.01118876806659E-7,3.07200003757967E-5,-4.41424049079917E-7,20.0000667572021,20.0000667572021,3638.32763671875,3673.33520507812,54.6702251490827,19.7568066736296,10.1291084289551,0,0,0,40,20.013614654541,1,6,1,2.15225219726562,43.49951171875,,,,,,,,,,,,,,,,
,3735593985.1685,19.9996738433838,-835.012908935547,3.75564607297627E-5,2.61777528828558E-7,1,0.999253354069792,40.0298881530762,1.99509532346084,14.5600000396371,0.000403037663925823,6.47469034516761E-5,0.25,-6.89283094040663E-7,3.73378946888996E-5,-5.01867759585366E-7,19.99973487854,19.99973487854,-855.03955078125,-814.986267089844,55.0508782379481,19.7572942843428,10.1331462860107,0,0,0,40,20.0125179290771,1,6,1,2.1551513671875,43.49951171875,,,,,,,,,,,,,,,,
,3735594072.2235,19.9991159439087,-5188.84521484375,4.49260415860215E-5,2.85196541071075E-7,1,0.999253354069792,40.0298881530762,1.99500232863224,14.5600000396371,0.000481802317714631,7.98553956717741E-5,0.25,-6.14172410580128E-7,4.46753272723595E-5,-3.78714884880487E-7,19.9992427825928,19.9992427825928,-5203.88134765625,-5173.80908203125,55.0149233260635,19.7560163366464,10.1387615203857,0,0,0,40,20.0115623474121,1,6,1,2.15362548828125,43.49951171875,,,,,,,,,,,,,,,,
,3735594159.0385,19.9997758865356,-9531.90625,5.23128889683914E-5,4.56773521459281E-7,1,0.999253354069792,40.0298881530762,1.99500848910452,14.5600000396371,0.000561144817773191,9.3372236666669E-5,0.25,-6.98435725103392E-7,5.20380023024252E-5,-4.08062693641256E-7,19.9996757507324,19.9996757507324,-9554.41015625,-9509.40234375,54.7030535468904,19.7566912585126,10.1429815292358,0,0,0,40,20.0131587982178,1,6,1,2.15576171875,43.49951171875,,,,,,,,,,,,,,,,
,3735594242.9155,20.0004043579102,-13724.232421875,5.52510970160022E-5,5.0816968052946E-7,1,0.999253354069792,40.0298881530762,1.99498140001317,14.5600000396371,0.000593996432052871,9.23985286839375E-5,0.25,-1.33857211683096E-6,5.49839652104459E-5,-1.01234080804928E-6,20.0004634857178,20.0004634857178,-13749.2021484375,-13699.2626953125,54.7710552280635,19.7588296312543,10.1451082229614,0,0,0,40,20.0119361877441,1,6,1,2.15240478515625,43.49951171875,,,,,,,,,,,,,,,,
,3735594326.8725,20.0003442764282,-17921.26171875,5.47826709884377E-5,7.34193604376054E-7,1,0.999253354069792,40.0298881530762,1.99494777921534,14.5600000396371,0.000589254436320227,9.12567040067729E-5,0.25,-1.37982446710616E-6,5.45395358547459E-5,-1.04070136174882E-6,20.0002784729004,20.0002784729004,-17948.6796875,-17893.84375,54.9805316712174,19.7582379016175,10.1464805603027,0,0,0,40,20.0131874084473,1,6,1,2.1533203125,43.49951171875,,,,,,,,,,,,,,,,
,3735594410.824,19.9994840621948,-22118.55859375,5.00531418962846E-5,7.51297445826818E-7,1,0.999253354069792,40.0298881530762,1.99497344206139,14.5600000396371,0.000537984600663733,8.68911293351139E-5,0.25,-9.49484790102162E-7,4.98497536189655E-5,-6.28005063831828E-7,19.999490737915,19.999490737915,-22138.55859375,-22098.55859375,54.718686117275,19.7599048757535,10.1442241668701,0,0,0,40,20.012622833252,1,6,1,2.13775634765625,43.49951171875,,,,,,,,,,,,,,,,
,3735594494.6985,20.0007038116455,-26314.4140625,4.47216786451507E-5,6.24314862741233E-7,1,0.999253354069792,40.0298881530762,1.99503464347488,14.5600000396371,0.000482175545678776,7.06495743686731E-5,0.25,-1.51437756093652E-6,4.45635354884731E-5,-1.21418834197766E-6,20.000789642334,20.000789642334,-26339.50390625,-26289.32421875,54.6061316105058,19.7614052258857,10.1454486846924,0,0,0,40,20.0127830505371,1,6,1,2.13775634765625,43.9882698059082,,,,,,,,,,,,,,,,
,3735594578.666,20.0001010894775,-30529.595703125,4.41120274496007E-5,7.70746011166596E-7,1,0.999253354069792,40.0298881530762,1.99500649406871,14.5600000396371,0.000476234535018398,6.7374353617347E-5,0.25,-1.72153860428195E-6,4.39772382473993E-5,-1.41595663363646E-6,19.9998836517334,19.9998836517334,-30554.708984375,-30504.482421875,55.0024172697558,19.7590636765458,10.1449718475342,0,0,0,40,20.0127220153809,1,6,1,2.15225219726562,43.49951171875,,,,,,,,,,,,,,,,
,3735594662.5935,19.9999122619629,-34739.28515625,4.79416172989315E-5,1.1128226981093E-6,1,0.999253354069792,40.0298881530762,1.99500758265843,14.5600000396371,0.00051533734472622,8.68882753776406E-5,0.25,-6.08499140189204E-7,4.78079433707329E-5,-2.72176462233602E-7,19.9999027252197,19.9999027252197,-34764.265625,-34714.3046875,54.5553257567558,19.7613279227518,10.145131111145,0,0,0,40,20.0132637023926,1,6,1,2.15316772460938,43.49951171875,,,,,,,,,,,,,,,,
,3735594746.6345,19.9999771118164,-38957.21484375,5.43293634027658E-5,1.03416731950138E-6,1,0.999253354069792,40.0298881530762,1.9949294181862,14.5600000396371,0.000585534281175706,9.14013970315453E-5,0.25,-1.35975409922206E-6,5.42070180327408E-5,-9.69177361869985E-7,19.9998893737793,19.9998893737793,-38980,-38934.4296875,54.9140932470827,19.7607701823757,10.1453695297241,0,0,0,40,20.0127696990967,1,6,1,2.156982421875,43.9882698059082,,,,,,,,,,,,,,,,
,3735594830.45,19.9999675750732,-43164.474609375,6.37303993284434E-5,9.26551760928474E-7,1,0.999253354069792,40.0298881530762,1.99501683354872,14.5600000396371,0.000685938498600193,0.000114147118885972,0.25,-9.61655451505496E-7,6.3610696928731E-5,-4.9793462494669E-7,20.0000877380371,20.0000877380371,-43189.47265625,-43139.4765625,54.8546894796212,19.7590497738224,10.1449909210205,0,0,0,40,20.0122241973877,1,6,1,2.15652465820313,43.49951171875,,,,,,,,,,,,,,,,
,3735594914.3895,20.0000762939453,-47374.16796875,7.10889124809414E-5,1.39038734573675E-6,1,0.999253354069792,40.0298881530762,1.99505255528454,14.5600000396371,0.000765162341855363,0.000129176066737251,0.25,-9.11976792826982E-7,7.09853463641826E-5,-3.89141839474691E-7,20.0000648498535,20.0000648498535,-47399.1953125,-47349.140625,54.6874209765058,19.7589486329399,10.1466550827026,0,0,0,40,20.012674331665,1,6,1,2.15545654296875,43.49951171875,,,,,,,,,,,,,,,,
,3735594998.5155,20.0001964569092,-51599.75390625,8.2334848068037E-5,1.26262555509662E-6,1,0.999253354069792,40.0298881530762,1.9950837642484,14.5600000396371,0.000888674051076622,0.00013830130678675,0.25,-2.11996299553203E-6,8.22581398543007E-5,-1.50867060295645E-6,20.0001602172852,20.0001602172852,-51614.81640625,-51584.69140625,54.5287503871019,19.7593778621776,10.1477670669556,0,0,0,40,20.0125141143799,1,6,1,2.15286254882813,43.0107536315918,,,,,,,,,,,,,,,,
,3735595082.263,20.0003576278687,-55827.818359375,9.26641872707187E-5,1.73611605536496E-6,1,0.999253354069792,40.0298881530762,1.99505512360599,14.5600000396371,0.000998697688069092,0.000165983461443172,0.25,-1.43343474482885E-6,9.26095159952659E-5,-7.43879420415769E-7,20.0002517700195,20.0002517700195,-55853.10546875,-55802.53125,55.189226485852,19.756186583038,10.1513767242432,0,0,0,40,20.0121212005615,1,6,1,2.15286254882813,43.49951171875,,,,,,,,,,,,,,,,
,3735595166.32,20.0009765625,-60079.0625,0.000102529975668864,1.27975456209512E-6,1,0.999253354069792,40.0298881530762,1.99511680672718,14.5600000396371,0.00110632527934713,0.00017924960615693,0.25,-2.004118049362E-6,0.000102514177429651,-1.24049066426885E-6,20.0009384155273,20.0009384155273,-60099.28125,-60058.84375,54.5850276404865,19.7555685526561,10.1535902023315,0,0,0,40,20.0120849609375,1,6,1,2.15286254882813,43.49951171875,,,,,,,,,,,,,,,,
,3735595250.1625,20.0004110336304,-64318.30078125,0.000113593880480276,1.9743966467773E-6,1,0.999253354069792,40.0298881530762,1.99502346175061,14.5600000396371,0.00122869183120154,0.00018459140924743,0.25,-3.52700528088174E-6,0.000113630226156891,-2.68306577824775E-6,20.0002727508545,20.0002727508545,-64346.125,-64290.4765625,54.9203462752366,19.7604910869282,10.1546850204468,0,0,0,40,20.011510848999,1,6,1,2.154541015625,43.49951171875,,,,,,,,,,,,,,,,
,3735595334.2295,19.9994115829468,-68567.421875,0.000126030649009683,1.53413980184844E-6,1,0.999253354069792,40.0298881530762,1.99497004380882,14.5600000396371,0.00135856521713738,0.000232997133245148,0.25,-1.2952493887894E-6,0.00012609850504247,-3.62761740282811E-7,19.9993381500244,19.9993381500244,-68582.53125,-68552.3125,54.8171713106981,19.7586812224866,10.1556997299194,0,0,0,40,20.0098667144775,1,6,1,2.1368408203125,43.9882698059082,,,,,,,,,,,,,,,,
,3735595418.295,19.9998111724854,-72818.82421875,0.00013347576974572,1.87146746288962E-6,1,0.999253354069792,40.0298881530762,1.99504078941495,14.5600000396371,0.00143665214980959,0.000261843724342844,0.25,2.69033944889744E-8,0.000133584818111026,1.00912666204981E-6,19.9998111724854,19.9998111724854,-72833.8203125,-72803.828125,55.1540532024866,19.7597902922802,10.158522605896,0,0,0,40,20.0106925964355,1,6,1,2.1533203125,43.49951171875,,,,,,,,,,,,,,,,
,3735595501.95,20.0003423690796,-77046.94921875,0.000144273236656168,1.58715730484496E-6,1,0.999253354069792,40.0298881530762,1.99506284806507,14.5600000396371,0.00156133756959184,0.000239551110788841,0.25,-4.00870480197376E-6,0.00014446918670785,-2.96016259235695E-6,20.0003337860107,20.0003337860107,-77069.6640625,-77024.234375,55.2376874540443,19.7603284668854,10.158314704895,0,0,0,40,20.0110530853271,1,6,1,2.15423583984375,43.49951171875,,,,,,,,,,,,,,,,
,3735595585.88,20.0006809234619,-81290.4609375,0.000158520309116937,2.1293520832013E-6,1,0.999253354069792,40.0298881530762,1.99514500732112,14.5600000396371,0.00170341286528286,0.000333225474165454,0.25,2.09858855534013E-6,0.000158739129480017,3.24760768794217E-6,20.0005588531494,20.0005588531494,-81315.765625,-81265.15625,55.0180498401404,19.7585423774449,10.1574583053589,0,0,0,40,20.0105991363525,1,6,1,2.15423583984375,43.49951171875,,,,,,,,,,,,,,,,
,3735595669.8025,20.0000162124634,-85531.46875,0.000167324858728486,2.03368329805757E-6,1,0.999253354069792,40.0298881530762,1.99507951146374,14.5600000396371,0.00180467179395063,0.000317959764748612,0.25,-9.14368911508088E-7,0.000167629142978969,2.8001433851816E-7,20.0001659393311,20.0001659393311,-85556.8125,-85506.125,55.0235212397751,19.7588960879456,10.1582136154175,0,0,0,40,20.0099143981934,1,6,1,2.15347290039062,44.9657897949219,,,,,,,,,,,,,,,,
,3735595753.8855,19.999942779541,-89784.84765625,0.000177017030322368,1.81419347014588E-6,1,0.999253354069792,40.0298881530762,1.99515454952379,14.5600000396371,0.00191014651930195,0.000334688488245265,0.25,-1.11786095260705E-6,0.000177390790164735,1.29249825731197E-7,19.999942779541,19.999942779541,-89802.5,-89767.1953125,54.9953826130827,19.7584748644262,10.1603527069092,0,0,0,40,20.0101509094238,1,6,1,2.15194702148438,43.49951171875,,,,,,,,,,,,,,,,
,3735595846.7285,19.9995231628418,-86126.8515625,0.000167968914767658,1.91639639814987E-6,1,0.999253354069792,40.0298881530762,1.99511652113109,14.5600000396371,0.00181548092358905,0.000298541337979892,0.25,-2.83324039412696E-6,0.000168294952779756,-1.63981391721266E-6,19.9994869232178,19.9994869232178,-86151.6640625,-86102.0390625,54.9578644441597,19.7590599453462,10.1615333557129,0,0,0,40,20.0088272094727,1,6,1,2.1514892578125,43.49951171875,,,,,,,,,,,,,,,,
,3735595930.6265,19.9991245269775,-81948.60546875,0.000157662139834772,2.19942943741346E-6,1,0.999253354069792,40.0298881530762,1.99507214016285,14.5600000396371,0.00170101591903121,0.00029403248081349,0.25,-1.3822552512007E-6,0.00015791243774495,-2.46529654649499E-7,19.9989891052246,19.9989891052246,-81973.6328125,-81923.578125,54.7116514606019,19.7588029776374,10.1620206832886,0,0,0,40,20.0099868774414,1,6,1,2.15484619140625,43.49951171875,,,,,,,,,,,,,,,,
,3735596014.829,19.9998836517334,-77756.796875,0.000145672118327586,1.66231864493106E-6,1,0.999253354069792,40.0298881530762,1.99510681176035,14.5600000396371,0.00157032921473718,0.000276324859198953,0.25,-8.48342659081327E-7,0.000145854596515684,2.12400088242147E-7,20.0000057220459,20.0000057220459,-77779.21875,-77734.375,54.8460915659097,19.7598330735023,10.1650915145874,0,0,0,40,20.009973526001,1,6,1,2.15347290039062,43.49951171875,,,,,,,,,,,,,,,,
,3735596098.631,20.0001430511475,-73581.03125,0.000134880280873252,1.96102140439834E-6,1,0.999253354069792,40.0298881530762,1.99499926952431,14.5600000396371,0.00145551135881116,0.0002443905910414,0.25,-1.84985104419021E-6,0.000135012635391566,-8.60241782066616E-7,20.0001430511475,20.0001430511475,-73595.9921875,-73566.0703125,54.9578644441597,19.7573011085685,10.1650524139404,0,0,0,40,20.0108280181885,1,6,1,2.17086791992187,43.49951171875,,,,,,,,,,,,,,,,
,3735596182.439,19.9996194839478,-69407.515625,0.00012747367739426,1.8068656842918E-6,1,0.999253354069792,40.0298881530762,1.99510553820963,14.5600000396371,0.00137442918687139,0.000235029518834693,0.25,-1.37106316176001E-6,0.000127551898021429,-4.29002244871001E-7,19.9996528625488,19.9996528625488,-69432.421875,-69382.609375,55.311160534852,19.7584147969014,10.1655082702637,0,0,0,40,20.0103969573975,1,6,1,2.15240478515625,43.49951171875,,,,,,,,,,,,,,,,
,3735596266.3605,20.0000658035278,-65227.9140625,0.000116147155562168,1.59201084766466E-6,1,0.999253354069792,40.0298881530762,1.99503905276197,14.5600000396371,0.00125381083423628,0.000203086634484825,0.25,-2.27353340991752E-6,0.000116183844305131,-1.41122673942732E-6,20.0000476837158,20.0000476837158,-65252.8359375,-65202.9921875,54.830458995525,19.7579602241948,10.1650323867798,0,0,0,40,20.0103378295898,1,6,1,2.156982421875,43.49951171875,,,,,,,,,,,,,,,,
,3735596350.294,19.9998207092285,-61046.041015625,0.000105536898003901,1.61578459194242E-6,1,0.999253354069792,40.0298881530762,1.99503076155828,14.5600000396371,0.00113687089568129,0.000195252767519355,0.25,-1.06419722315318E-6,0.000105522709587189,-2.78617878252713E-7,19.9997615814209,19.9997615814209,-61068.56640625,-61023.515625,54.8414017947943,19.7609632655054,10.1663064956665,0,0,0,40,20.0100898742676,1,6,1,2.15560913085938,43.49951171875,,,,,,,,,,,,,,,,
,3735596434.2755,20.0002174377441,-56859.76171875,9.56635389488138E-5,1.61972987446903E-6,1,0.999253354069792,40.0298881530762,1.99507210467793,14.5600000396371,0.00102797098093309,0.000188745041944387,0.25,1.35864798593429E-7,9.56046353088067E-5,8.47080113317324E-7,20.0000801086426,20.0000801086426,-56884.69140625,-56834.83203125,54.7327554306212,19.7590634396836,10.1667098999023,0,0,0,40,20.0112037658691,1,6,1,2.13760375976562,43.0107536315918,,,,,,,,,,,,,,,,
,3735596518.315,19.9999952316284,-52675.984375,8.29366778680917E-5,1.37146284802741E-6,1,0.999253354069792,40.0298881530762,1.995053307576,14.5600000396371,0.00089225543065949,0.000155787264865228,0.25,-6.0412434212892E-7,8.28569983109524E-5,1.07873213956116E-8,20.0000114440918,20.0000114440918,-52690.8828125,-52661.0859375,55.1704674013905,19.7560616265273,10.16614818573,0,0,0,40,20.0112285614014,1,6,1,2.15362548828125,43.49951171875,,,,,,,,,,,,,,,,
,3735596602.1585,19.9998025894165,-48499.56640625,7.34585318099078E-5,1.20124720393434E-6,1,0.999253354069792,40.0298881530762,1.99513113231383,14.5600000396371,0.000791443416357726,0.0001299068534333,0.25,-1.27847908676445E-6,7.33624692242018E-5,-7.3645779831747E-7,20.0000381469727,20.0000381469727,-48521.95703125,-48477.17578125,54.9312890745058,19.7577470100553,10.1671190261841,0,0,0,40,20.0111713409424,1,6,1,2.1539306640625,43.9882698059082,,,,,,,,,,,,,,,,
,3735596686.0555,19.9991245269775,-44321.212890625,6.308355236912E-5,1.20558409743972E-6,1,0.999253354069792,40.0298881530762,1.99509974032794,14.5600000396371,0.000677873050473008,0.000119670706850189,0.25,-3.32809121036638E-7,6.29682049360791E-5,1.26649814838651E-7,19.9992599487305,19.9992599487305,-44343.56640625,-44298.859375,54.9899112134481,19.7548824717478,10.1689748764038,0,0,0,40,20.0117874145508,1,6,1,2.15133666992187,45.4545478820801,,,,,,,,,,,,,,,,
,3735596770.118,19.9998044967651,-40132.404296875,5.26291802838335E-5,1.2332089825666E-6,1,0.999253354069792,40.0298881530762,1.99519802702926,14.5600000396371,0.000568893392124142,8.01016819897396E-5,0.25,-2.10757806086575E-6,5.25229046505827E-5,-1.72566733618599E-6,19.9998474121094,19.9998474121094,-40149.83203125,-40114.9765625,54.5686134415827,19.75493276001,10.1688461303711,0,0,0,40,20.0111427307129,1,6,1,2.15621948242187,43.49951171875,,,,,,,,,,,,,,,,
,3735596853.9085,20.0003700256348,-35958.5625,4.300472500772E-5,1.05179559333571E-6,1,0.999253354069792,40.0298881530762,1.99522764202567,14.5600000396371,0.000464335717409898,6.71873178306071E-5,0.25,-1.55198120992706E-6,4.28974628081051E-5,-1.24559947544292E-6,20.0004806518555,20.0004806518555,-35981.02734375,-35936.09765625,54.0691528177942,19.7543636339684,10.1695699691772,0,0,0,40,20.0119857788086,1,6,1,2.14096069335938,44.9657897949219,,,,,,,,,,,,,,,,
,3735596937.937,19.9999446868896,-31771.9833984375,3.24185601983858E-5,8.88803357026901E-7,1,0.999253354069792,40.0298881530762,1.99512390360863,14.5600000396371,0.000350617805074016,4.64400536019268E-5,0.25,-1.55460732794471E-6,3.23257916436544E-5,-1.32743443381855E-6,20.0000419616699,20.0000419616699,-31791.876953125,-31752.08984375,54.8320222525635,19.7549206267046,10.1688070297241,0,0,0,40,20.0107822418213,1,6,1,2.1533203125,43.49951171875,,,,,,,,,,,,,,,,
,3735597021.7975,19.9997806549072,-27596.013671875,2.23271428327872E-5,8.99155743048959E-7,1,0.999253354069792,40.0298881530762,1.99514260132042,14.5600000396371,0.00024203345983261,2.83083896353028E-5,0.25,-1.40785220187906E-6,2.22555310084109E-5,-1.25420267170679E-6,19.9997940063477,19.9997940063477,-27618.421875,-27573.60546875,54.4185407658904,19.7523034254673,10.1692247390747,0,0,0,40,20.013069152832,1,6,1,2.15255737304687,43.49951171875,,,,,,,,,,,,,,,,
,3735597105.7345,19.999831199646,-23417.037109375,1.25615361522176E-5,9.53991302406356E-7,1,0.999253354069792,40.0298881530762,1.99512611142783,14.5600000396371,0.000136899402528738,1.15582312472275E-5,0.25,-1.19625378022079E-6,1.2518293804238E-5,-1.11074348585975E-6,19.9998989105225,19.9998989105225,-23439.490234375,-23394.583984375,54.8148264251404,19.752453464513,10.171181678772,0,0,0,40,20.0126342773438,1,6,1,2.1527099609375,43.49951171875,,,,,,,,,,,,,,,,
,3735597189.6665,20.0000991821289,-19234.75390625,3.33741468921019E-6,4.49150854903585E-7,1,0.999253354069792,40.0298881530762,1.99517957302169,14.5600000396371,3.84641383435312E-5,-8.58131713403357E-6,0.25,-1.40482556765429E-6,3.33116580375227E-6,-1.37798847908165E-6,20.0001926422119,20.0001926422119,-19259.65234375,-19209.85546875,54.383367482525,19.7539736599653,10.1728401184082,0,0,0,40,20.012279510498,1,6,1,2.15591430664062,43.9882698059082,,,,,,,,,,,,,,,,
,3735597273.687,19.9999380111694,-15048.6459960938,-6.54056000321083E-6,6.25919572875209E-7,1,0.999253354069792,40.0298881530762,1.99519521522764,14.5600000396371,-6.65960650158963E-5,-3.16333084781645E-5,0.25,-1.77371203662899E-6,-6.49836823939488E-6,-1.80354078858623E-6,19.9997882843018,19.9997882843018,-15071.0419921875,-15026.25,54.9234727893135,19.7534013255764,10.1753950119019,0,0,0,40,20.0126838684082,1,6,1,2.15576171875,43.9882698059082,,,,,,,,,,,,,,,,
,3735597357.664,19.9993286132813,-10863.328125,-1.63378898497029E-5,4.29546467496404E-7,1,0.999253354069792,40.0298881530762,1.99514848596326,14.5600000396371,-0.000171540214122236,-4.99297857573071E-5,0.25,-1.72030408664114E-6,-1.62430186355626E-5,-1.80244288227323E-6,19.9993152618408,19.9993152618408,-10883.1826171875,-10843.4736328125,54.4591854488904,19.7541414848171,10.1758975982666,0,0,0,40,20.0127639770508,1,6,1,2.15713500976562,43.0107536315918,,,,,,,,,,,,,,,,
,3735597441.4915,19.9999866485596,-6675.54736328125,-2.53248284477695E-5,4.41190323543196E-7,1,0.999253354069792,40.0298881530762,1.99518010073357,14.5600000396371,-0.000268246503276919,-6.3907652510418E-5,0.25,-1.41600748556971E-6,-2.51769093120763E-5,-1.54163022514324E-6,20.0000286102295,20.0000286102295,-6700.52978515625,-6650.56494140625,54.8070101399481,19.7548666571352,10.1779708862305,0,0,0,40,20.0123424530029,1,6,1,2.1563720703125,43.49951171875,,,,,,,,,,,,,,,,
,3735597528.529,19.9988813400269,-2329.5908203125,-3.42288725624283E-5,2.84013284532919E-7,1,0.999253354069792,40.0298881530762,1.99521663612349,14.5600000396371,-0.000363717547321156,-7.93987889111876E-5,0.25,-1.27392366095575E-6,-3.402293278913E-5,-1.43660302714682E-6,19.9987163543701,19.9987163543701,-2349.60107421875,-2309.58056640625,55.1337308609866,19.7539697271095,10.1786880493164,0,0,0,40,20.0123634338379,1,6,1,2.152099609375,43.9882698059082,,,,,,,,,,,,,,,,
,3735597615.459,19.9994440078735,2016.03991699219,-4.01118472455878E-5,2.34309756660895E-7,1,0.999253354069792,40.0298881530762,1.99523588628387,14.5600000396371,-0.000427002919385413,-8.87239918110232E-5,0.25,-1.08978771845754E-6,-3.98718331200537E-5,-1.28197146253771E-6,19.9993190765381,19.9993190765381,1998.50427246094,2033.57556152344,54.9203462752366,19.7518525521324,10.1774587631226,0,0,0,40,20.0125770568848,1,6,1,2.1539306640625,43.49951171875,,,,,,,,,,,,,,,,
,3735597702.325,19.9993190765381,6358.92749023437,-4.73919543944438E-5,2.95701439574148E-7,1,0.999253354069792,40.0298881530762,1.99520794030656,14.5600000396371,-0.000505049188971092,-0.000102546611281263,0.25,-1.05777040018421E-6,-4.71224734945373E-5,-1.30057457928543E-6,19.9992961883545,19.9992961883545,6333.92626953125,6383.9287109375,55.0891780353904,19.7527881557576,10.1768493652344,0,0,0,40,20.0113258361816,1,6,1,2.1563720703125,43.49951171875,,,,,,,,,,,,,,,,
,3735597789.2125,20.0001087188721,10704.1708984375,-5.39483996801608E-5,3.99579386153246E-7,1,0.999253354069792,40.0298881530762,1.99518312174454,14.5600000396371,-0.000575921435158642,-0.000112240530480624,0.25,-7.63664673543201E-7,-5.36618534664246E-5,-1.0599173308715E-6,20.0001792907715,20.0001792907715,10679.1083984375,10729.2333984375,54.772618485102,19.7536497094416,10.1754331588745,0,0,0,40,20.0118103027344,1,6,1,2.1514892578125,43.9882698059082,,,,,,,,,,,,,,,,
,3735597873.1595,20.000804901123,14901.2827148438,-5.68569995294395E-5,4.42882576390551E-7,1,0.999253354069792,40.0298881530762,1.99509222010314,14.5600000396371,-0.000606365812225408,-0.000122758111770794,0.25,-1.20136436202521E-6,-5.65730505710637E-5,-1.52911387377061E-6,20.0007209777832,20.0007209777832,14878.79296875,14923.7724609375,54.7984122262366,19.7528629827927,10.1731786727905,0,0,0,40,20.0132865905762,1,6,1,2.15103149414062,43.9882698059082,,,,,,,,,,,,,,,,
,3735597957.117,20.0003137588501,19099.1162109375,-5.46512109142026E-5,6.65559333498507E-7,1,0.999253354069792,40.0298881530762,1.99512527861242,14.5600000396371,-0.000584918129499287,-0.000107864848989472,0.25,-1.88790670082446E-7,-5.44052692289173E-5,-5.24191213551038E-7,20.00022315979,20.00022315979,19074.021484375,19124.2109375,54.5482911000827,19.7528730863252,10.1739854812622,0,0,0,40,20.0118427276611,1,6,1,2.152099609375,43.49951171875,,,,,,,,,,,,,,,,
,3735598041.0245,19.9995651245117,23297.4453125,-4.87515659309847E-5,5.94566831642055E-7,1,0.999253354069792,40.0298881530762,1.99499383558653,14.5600000396371,-0.000521466050404728,-9.898137839044E-5,0.25,-4.10256622227871E-7,-4.85507119727413E-5,-7.21290228700383E-7,19.9996719360352,19.9996719360352,23274.962890625,23319.927734375,54.9273809319096,19.7548307218309,10.1721467971802,0,0,0,40,20.0117893218994,1,6,1,2.15225219726562,43.49951171875,,,,,,,,,,,,,,,,
,3735598125.063,20.0002450942993,27505.44921875,-4.45644323408812E-5,8.77020833604039E-7,1,0.999253354069792,40.0298881530762,1.99513395204559,14.5600000396371,-0.000477613111535469,-8.6681880182966E-5,0.25,-6.07400124516432E-9,-4.44023435451516E-5,-3.02331226477172E-7,20.0002975463867,20.0002975463867,27485.341796875,27525.556640625,54.3309983717365,19.7527563619294,10.1715908050537,0,0,0,40,20.0122146606445,1,6,1,2.15438842773438,43.49951171875,,,,,,,,,,,,,,,,
,3735598208.901,20.0001602172852,31713.58203125,-4.51930166642253E-5,7.79052914475088E-7,1,0.999253354069792,40.0298881530762,1.99519823417469,14.5600000396371,-0.000482870248897992,-9.73588549402612E-5,0.25,-8.74925355599593E-7,-4.50425650834583E-5,-1.18178695909039E-6,20.0001831054687,20.0001831054687,31690.96484375,31736.19921875,54.7632389428712,19.7529337119135,10.1711740493774,0,0,0,40,20.0121917724609,1,6,1,2.15087890625,43.49951171875,,,,,,,,,,,,,,,,
,3735598292.9305,19.9997959136963,35933.0703125,-4.99653135301119E-5,1.18839339557191E-6,1,0.999253354069792,40.0298881530762,1.99520029417219,14.5600000396371,-0.000535590897558048,-9.94768781421852E-5,0.25,-1.93371443371321E-7,-4.98265289883409E-5,-5.43809167618356E-7,19.9999523162842,19.9999523162842,35912.8984375,35953.2421875,54.1957766379096,19.7549621205904,10.1692781448364,0,0,0,40,20.0123443603516,1,6,1,2.13775634765625,43.49951171875,,,,,,,,,,,,,,,,
,3735598376.8725,20.000171661377,40146.451171875,-5.75113257804224E-5,1.29058462204514E-6,1,0.999253354069792,40.0298881530762,1.9952039848324,14.5600000396371,-0.000616077643925721,-0.000118278326877647,0.25,-5.61917333256662E-7,-5.73747510164382E-5,-9.72673520217899E-7,20.0002098083496,20.0002098083496,40123.87890625,40169.0234375,54.4302651936788,19.7520160040127,10.1670532226562,0,0,0,40,20.0120258331299,1,6,1,2.13760375976562,43.49951171875,,,,,,,,,,,,,,,,
,3735598460.699,20.0000085830688,44355.189453125,-6.58957049056486E-5,1.55080971020119E-6,1,0.999253354069792,40.0298881530762,1.99513150803701,14.5600000396371,-0.000706810444337138,-0.000132119485567809,0.25,-3.14754067795394E-7,-6.57706311057961E-5,-7.93509983926409E-7,19.9999656677246,19.9999656677246,44329.9765625,44380.40234375,55.0618210372174,19.7523177901323,10.1688318252563,0,0,0,40,20.0121231079102,1,6,1,2.15469360351562,43.49951171875,,,,,,,,,,,,,,,,
,3735598544.638,19.9996786117554,48566.365234375,-7.61174789785191E-5,1.64016173461413E-6,1,0.999253354069792,40.0298881530762,1.99515950060566,14.5600000396371,-0.000815705406248849,-0.00015879145039079,0.25,-9.26491401302155E-7,-7.60019024150846E-5,-1.48498666149119E-6,19.9997577667236,19.9997577667236,48541.20703125,48591.5234375,55.2994361070635,19.7514871634869,10.1686849594116,0,0,0,40,20.0118198394775,1,6,1,2.154541015625,43.49951171875,,,,,,,,,,,,,,,,
,3735598628.627,19.99937915802,52788.509765625,-8.64004050209565E-5,1.37719141066057E-6,1,0.999253354069792,40.0298881530762,1.99514576468725,14.5600000396371,-0.000925924779279295,-0.000182321256561033,0.25,-1.23370647711579E-6,-8.63045628289693E-5,-1.87251584514023E-6,19.9994716644287,19.9994716644287,52768.28125,52808.73828125,54.8750118211212,19.7508849539817,10.1706848144531,0,0,0,40,20.0113067626953,1,6,1,2.15225219726562,43.49951171875,,,,,,,,,,,,,,,,
,3735598712.53,20.0009775161743,57030.671875,-9.4197510002763E-5,1.33682305915537E-6,1,0.999253354069792,40.0298881530762,1.99521725126055,14.5600000396371,-0.00101304379284422,-0.000181807758095283,0.25,2.44031207868018E-7,-9.41438675897907E-5,-4.56572977909264E-7,20.0011234283447,20.0011234283447,57005.359375,57055.984375,54.3364697713711,19.7531377121398,10.1725301742554,0,0,0,40,20.010669708252,1,6,1,2.15362548828125,43.49951171875,,,,,,,,,,,,,,,,
,3735598796.4485,20.0005807876587,61273.1484375,-0.000106108058313812,1.85704574125993E-6,1,0.999253354069792,40.0298881530762,1.99516970211403,14.5600000396371,-0.00114047143702237,-0.000210885845187665,0.25,-2.84002292410629E-7,-0.000106085950452774,-1.07352752358746E-6,20.0006351470947,20.0006351470947,61247.92578125,61298.37109375,54.7507328865635,19.7539135916393,10.1732378005981,0,0,0,40,20.0113010406494,1,6,1,2.15469360351562,43.49951171875,,,,,,,,,,,,,,,,
,3735598880.5995,19.9996843338013,65528.87890625,-0.000117149791464619,1.89173075152971E-6,1,0.999253354069792,40.0298881530762,1.99515304954855,14.5600000396371,-0.00126175816675278,-0.000221210911907386,0.25,7.72649708291135E-7,-0.000117178632969732,-9.71386863853179E-8,19.9997634887695,19.9997634887695,65511.09375,65546.6640625,54.8062285114289,19.7520956554596,10.174370765686,0,0,0,40,20.0106449127197,1,6,1,2.15591430664062,43.49951171875,,,,,,,,,,,,,,,,
,3735598964.318,19.9999685287476,69763.265625,-0.000126964447126482,1.61912192279679E-6,1,0.999253354069792,40.0298881530762,1.99510751768042,14.5600000396371,-0.00136623142599501,-0.000249198833882225,0.25,-3.81379840922997E-8,-0.000127035805638511,-9.76750350894471E-7,20.000057220459,20.000057220459,69737.875,69788.65625,54.1715461538134,19.7531544586315,10.174503326416,0,0,0,40,20.0095920562744,1,6,1,2.139892578125,43.9882698059082,,,,,,,,,,,,,,,,
,3735599048.4215,19.9997434616089,74018.14453125,-0.000138363927615151,1.77782431053845E-6,1,0.999253354069792,40.0298881530762,1.99515024914243,14.5600000396371,-0.00149210986615096,-0.00025706850803318,0.25,1.30797051595797E-6,-0.000138500244765616,2.93120437319888E-7,19.99973487854,19.99973487854,74000.3828125,74035.90625,54.322400458025,19.7540596457405,10.1728296279907,0,0,0,40,20.0107078552246,1,6,1,2.13699340820313,43.49951171875,,,,,,,,,,,,,,,,
,3735599132.2085,20.0003356933594,78253.828125,-0.00015014051395596,1.71011779154913E-6,1,0.999253354069792,40.0298881530762,1.99510049325381,14.5600000396371,-0.00161288876862772,-0.000315947365424157,0.25,-2.01821105034681E-6,-0.000150313246378783,-3.11387340483892E-6,20.0002250671387,20.0002250671387,78228.5234375,78279.1328125,55.0117968119866,19.751751890132,10.1725406646729,0,0,0,40,20.0099391937256,1,6,1,2.15118408203125,43.9882698059082,,,,,,,,,,,,,,,,
,3735599216.24,20.0005264282227,82503.62890625,-0.000160169868756773,2.18013359051884E-6,1,0.999253354069792,40.0298881530762,1.99525161338311,14.5600000396371,-0.00172174208692013,-0.000334740259260714,0.25,-1.93846882233297E-6,-0.000160406502880987,-3.09578716714698E-6,20.0005130767822,20.0005130767822,82485.9140625,82521.34375,54.6585007212942,19.7503955446222,10.1717834472656,0,0,0,40,20.0097789764404,1,6,1,2.15438842773438,43.49951171875,,,,,,,,,,,,,,,,
,3735599300.234,20.0010662078857,86753.4453125,-0.000169932723471308,2.12203948002312E-6,1,0.999253354069792,40.0298881530762,1.99516979311998,14.5600000396371,-0.00183107918207309,-0.000333693606959728,0.25,-7.21097784754118E-8,-0.000170248920407637,-1.28265225559894E-6,20.0011882781982,20.0011882781982,86738.0859375,86768.8046875,54.4709098766788,19.7520975941256,10.1719455718994,0,0,0,40,20.0088405609131,1,6,1,2.15469360351562,43.49951171875,,,,,,,,,,,,,,,,
,3735599368.0125,20.0007772445679,90001.171875,-0.000182592310031852,2.2313699937905E-6,1,0.999253354069792,40.0298881530762,1.99518152357033,14.5600000396371,-0.00196746536301542,-0.000361173251769758,0.25,-3.26123591168721E-7,-0.000182969991131634,-1.61470675463118E-6,20.0007228851318,20.0007228851318,90000.2578125,90002.0859375,54.2973883454096,19.7532788095052,10.1732044219971,0,0,0,40,20.0085906982422,1,4,1,2.15484619140625,43.49951171875,,,,,,,,,,,,,,,,