File: data/doubleLayers/monolayer/ppms/DD205_4/rawdata/DD205_4_HYST_100OE_300K.DAT
[Header]
; VSM Data File (default extension .dat)
; Copyright (c) 2003-2013, Quantum Design, Inc. All rights reserved.
TITLE,
FILEOPENTIME,3735608881.15859,05/16/2018,5:07 am
BYAPP,VSM,1.0,1.0
INFO,DYNACOOL VSM Option Release 1.4.10 Build 1,APPNAME
INFO,Quantum Design Linear Motor Servo Controller,MOTOR_MODULE_NAME
INFO,3101-100 J0,MOTOR_HW_VERSION
INFO,MMC654,MOTOR_SERIAL_NUMBER
INFO,SRV No X-over 01.03.11,MOTOR_SOFTWARE_VERSION
INFO,Quantum Design VSM Detection Module,VSM_MODULE_NAME
INFO,3101-150 F0,VSM_HW_VERSION
INFO,VSM507,VSM_SERIAL_NUMBER
INFO,VSM No X-over 01.02.05 May 20 2008 13:51:47,VSM_SOFTWARE_VERSION
INFO,494,PREAMP_SERIAL_NUMBER
INFO,Quantum Design VSM Oven,OVEN_MODULE_NAME
INFO,3101-201 A1,OVEN_HW_VERSION
INFO,OVB210,OVEN_SERIAL_NUMBER
INFO,01.06.24,OVEN_SOFTWARE_VERSION
INFO,593,COIL_SERIAL_NUMBER
INFO,0,MOMENT_UNITS
INFO,,SAMPLE_MATERIAL
INFO,,SAMPLE_COMMENT
INFO,,SAMPLE_MASS
INFO,,SAMPLE_VOLUME
INFO,,SAMPLE_MOLECULAR_WEIGHT
INFO,,SAMPLE_SIZE
INFO,,SAMPLE_SHAPE
DATATYPE,COMMENT,1
DATATYPE,TIME,2
STARTUPAXIS,X,2
STARTUPAXIS,Y1,5
[Data]
Comment,Time Stamp (sec),Temperature (K),Magnetic Field (Oe),Moment (emu),M. Std. Err. (emu),Transport Action,Averaging Time (sec),Frequency (Hz),Peak Amplitude (mm),Center Position (mm),Coil Signal' (mV),Coil Signal" (mV),Range (mV),M. Quad. Signal (emu),M. Raw' (emu),M. Raw" (emu),Min. Temperature (K),Max. Temperature (K),Min. Field (Oe),Max. Field (Oe),Mass (grams),Motor Lag (deg),Pressure (Torr),VSM Status (code),Motor Status (code),Measure Status (code),Measure Count,System Temp. (K),Temp. Status (code),Field Status (code),Chamber Status (code),Motor Current (amps),Motor Heatsink Temp. (C),Map 01,Map 02,Map 03,Map 04,Map 05,Map 06,Map 07,Map 08,Map 09,Map 10,Map 11,Map 12,Map 13,Map 14,Map 15,Map 16
,3735610630.47,300.254486083984,0.133077308535576,2.98242143938216E-7,3.64483790312028E-7,1,0.999253354069792,40.0298881530762,1.99612277544196,14.5600000396371,4.92525498978852E-6,-9.21401040737582E-6,0.25,-9.07548908884547E-7,2.98832627920927E-7,-9.07315908166991E-7,300.254455566406,300.254455566406,0.133077308535576,0.133077308535576,55.0102335549481,19.7253083069829,38.6723365783691,0,0,0,40,301.616058349609,1,4,1,2.14767456054687,43.49951171875,,,,,,,,,,,,,,,,
,3735610721.68,300.390655517578,4127.07666015625,1.91748741524787E-5,4.96298081082149E-7,1,0.999253354069792,40.0298881530762,1.99604301518303,14.5600000396371,0.000208224536406257,2.66522962408208E-5,0.25,-8.84277461173209E-7,1.91746272170381E-5,-8.7153232036362E-7,300.390350341797,300.390350341797,4109.6279296875,4144.525390625,54.5858092690058,19.7315748141244,39.0801010131836,0,0,0,40,301.410400390625,1,6,1,2.14996337890625,43.49951171875,,,,,,,,,,,,,,,,
,3735610805.3425,300.44108581543,8309.01904296875,8.5762331284473E-6,5.43636594720118E-7,1,0.999253354069792,40.0298881530762,1.99602485585327,14.5600000396371,9.32828467701488E-5,1.10500764340112E-5,0.25,-4.76303332516817E-7,8.57616126854252E-6,-4.70603428724623E-7,300.44091796875,300.44091796875,8284.0029296875,8334.03515625,54.6045683534673,19.7298477766547,39.6964721679687,0,0,0,40,301.222625732422,1,6,1,2.15179443359375,43.49951171875,,,,,,,,,,,,,,,,
,3735610889.381,300.456008911133,12511.654296875,-4.23523030090099E-6,6.51954136137953E-7,1,0.999253354069792,40.0298881530762,1.99613852200723,14.5600000396371,-4.33383483093314E-5,-2.10458440163911E-5,0.25,-1.21183981472161E-6,-4.23423533041788E-6,-1.21458648936963E-6,300.456573486328,300.456573486328,12494.1435546875,12529.1650390625,54.9328523315443,19.7275217358198,40.5238761901855,0,0,0,40,301.098754882812,1,6,1,2.1490478515625,43.49951171875,,,,,,,,,,,,,,,,
,3735610973.4035,300.453353881836,16713.7802734375,-1.91326439210254E-5,6.40726307348838E-7,1,0.999253354069792,40.0298881530762,1.9961692759978,14.5600000396371,-0.000203015003194727,-5.37895049465921E-5,0.25,-1.64204146928011E-6,-1.91306881239534E-5,-1.65461488156555E-6,300.453002929687,300.453002929687,16693.736328125,16733.82421875,54.8984606766981,19.7213965963592,41.3895988464355,0,0,0,40,301.01123046875,1,6,1,2.14981079101562,43.49951171875,,,,,,,,,,,,,,,,
,3735611057.1965,300.444412231445,20904.298828125,-3.50601470480069E-5,6.4803632379718E-7,1,0.999253354069792,40.0298881530762,1.99616012379454,14.5600000396371,-0.000376202151245337,-7.46840897419428E-5,0.25,-7.91998287722327E-7,-3.50580417066421E-5,-8.15121728873482E-7,300.443908691406,300.443908691406,20879.3046875,20929.29296875,55.0250844968135,19.7220123705588,42.1946029663086,0,0,0,40,300.934631347656,1,6,1,2.14584350585938,43.49951171875,,,,,,,,,,,,,,,,
,3735611141.146,300.425933837891,25102.1708984375,-4.9207202272826E-5,8.55284594955867E-7,1,0.999253354069792,40.0298881530762,1.99618123481837,14.5600000396371,-0.000528739393127356,-0.000100647609256414,0.25,-7.24218821938072E-7,-4.92045377311879E-5,-7.56665335796007E-7,300.426147460937,300.426147460937,25079.654296875,25124.6875,54.6835128339096,19.7208737198278,42.8811378479004,0,0,0,40,300.887237548828,1,6,1,2.15057373046875,43.9882698059082,,,,,,,,,,,,,,,,
,3735611225.0515,300.405944824219,29309.2841796875,-6.38711077326044E-5,6.38884735531804E-7,1,0.999253354069792,40.0298881530762,1.99609547566838,14.5600000396371,-0.000686464201103464,-0.000129572144084992,0.25,-8.41345039843092E-7,-6.38677624331844E-5,-8.83431745856062E-7,300.406036376953,300.406036376953,29281.66796875,29336.900390625,54.9305074459866,19.7202530601319,43.5101928710937,0,0,0,40,300.844818115234,1,6,1,2.16461181640625,43.49951171875,,,,,,,,,,,,,,,,
,3735611309.2185,300.385131835937,33535.6953125,-7.96661860556745E-5,6.99289075976501E-7,1,0.999253354069792,40.0298881530762,1.9962322725793,14.5600000396371,-0.000855490411282992,-0.000166137181161854,0.25,-1.46823790125209E-6,-7.9661799963299E-5,-1.52067159609587E-6,300.385162353516,300.385162353516,33518.12109375,33553.26953125,54.8453099373904,19.7220805645292,44.0736656188965,0,0,0,40,300.810089111328,1,6,1,2.15042114257813,43.49951171875,,,,,,,,,,,,,,,,
,3735611392.909,300.361465454102,37737.380859375,-9.38692489876681E-5,7.59164733931107E-7,1,0.999253354069792,40.0298881530762,1.99622417879017,14.5600000396371,-0.00100875278213001,-0.00019149283532798,0.25,-1.33433946738172E-6,-9.38644247252186E-5,-1.3960874521031E-6,300.361145019531,300.361145019531,37714.83203125,37759.9296875,54.772618485102,19.7208444282,44.5677871704102,0,0,0,40,300.783508300781,1,6,1,2.1502685546875,43.0107536315918,,,,,,,,,,,,,,,,
,3735611476.8695,300.342208862305,41950.8828125,-0.000109696620342579,7.55460047871507E-7,1,0.999253354069792,40.0298881530762,1.99624895647413,14.5600000396371,-0.00117920067791226,-0.000221805120790596,0.25,-1.37575896045779E-6,-0.000109691183862803,-1.44786357414022E-6,300.341949462891,300.341949462891,41925.8359375,41975.9296875,54.9516114160058,19.7238116874444,44.9903945922852,0,0,0,40,300.758819580078,1,6,1,2.16445922851562,43.49951171875,,,,,,,,,,,,,,,,
,3735611560.861,300.322128295898,46167.1484375,-0.000125238722203338,8.44093537155411E-7,1,0.999253354069792,40.0298881530762,1.99622455415856,14.5600000396371,-0.0013472285557413,-0.000247688316813193,0.25,-1.05651685282869E-6,-0.000125232948858212,-1.13878576089715E-6,300.322479248047,300.322479248047,46147.12890625,46187.16796875,54.8875178774289,19.7230341460396,45.2235565185547,0,0,0,40,300.733917236328,1,6,1,2.16384887695313,43.9882698059082,,,,,,,,,,,,,,,,
,3735611644.87,300.302597045898,50383.376953125,-0.000141288565977718,6.77674624028109E-7,1,0.999253354069792,40.0298881530762,1.9961835121209,14.5600000396371,-0.00151822998138534,-0.000288690514235277,0.25,-2.05203788239148E-6,-0.000141281592766525,-2.14473163238913E-6,300.302093505859,300.302093505859,50368.39453125,50398.359375,54.9078402189289,19.7238544907478,45.2267951965332,0,0,0,40,300.707214355469,1,6,1,2.16537475585938,43.49951171875,,,,,,,,,,,,,,,,
,3735611728.84,300.281784057617,54618.44921875,-0.000156459041670247,7.65350088107515E-7,1,0.999253354069792,40.0298881530762,1.99628543692126,14.5600000396371,-0.00168225663101529,-0.000314405717101014,0.25,-1.78071141080463E-6,-0.000156451766059736,-1.88328338139781E-6,300.281677246094,300.281677246094,54603.2890625,54633.609375,54.7272840309866,19.7213790854579,45.2510833740234,0,0,0,40,300.690155029297,1,6,1,2.14981079101562,43.49951171875,,,,,,,,,,,,,,,,
,3735611812.68,300.266098022461,58858.28125,-0.000172670772944608,9.06468552364195E-7,1,0.999253354069792,40.0298881530762,1.99623363582035,14.5600000396371,-0.00185655911579337,-0.000346759815583164,0.25,-1.94536031029931E-6,-0.000172662862196207,-2.05845298786619E-6,300.265747070313,300.265747070313,58835.53125,58881.03125,54.6717884061212,19.7247344665851,45.3120727539063,0,0,0,40,300.677154541016,1,6,1,2.14630126953125,43.49951171875,,,,,,,,,,,,,,,,
,3735611896.541,300.249099731445,63098.267578125,-0.000187607642637814,1.06326723768761E-6,1,0.999253354069792,40.0298881530762,1.99621985846347,14.5600000396371,-0.00201852344149055,-0.000368904556885058,0.25,-1.38515430657655E-6,-0.00018759964810098,-1.50793912472149E-6,300.249816894531,300.249816894531,63072.9375,63123.59765625,54.7100882035635,19.7262774837441,45.4022102355957,0,0,0,40,300.655395507812,1,6,1,2.16705322265625,43.9882698059082,,,,,,,,,,,,,,,,
,3735611980.5445,300.233749389648,67346.07421875,-0.000203883562735959,9.032018861558E-7,1,0.999253354069792,40.0298881530762,1.99626378381759,14.5600000396371,-0.00219206271061044,-0.000410196685061794,0.25,-2.36675470270899E-6,-0.000203874433431192,-2.50002761820861E-6,300.233032226562,300.233032226562,67325.875,67366.2734375,54.8343671381212,19.7246641192513,45.5366020202637,0,0,0,40,300.643920898438,1,6,1,2.15011596679687,45.4545478820801,,,,,,,,,,,,,,,,
,3735612064.395,300.221237182617,71588.015625,-0.000220872384178826,1.03117875320739E-6,1,0.999253354069792,40.0298881530762,1.99631558692898,14.5600000396371,-0.00237641748744064,-0.000435029882382465,0.25,-1.69551175988645E-6,-0.000220863173075203,-1.83977582538421E-6,300.222106933594,300.222106933594,71562.7578125,71613.2734375,54.792940826602,19.7219375556135,45.6577682495117,0,0,0,40,300.621459960937,1,6,1,2.14874267578125,43.9882698059082,,,,,,,,,,,,,,,,
,3735612148.4065,300.207504272461,75835.7421875,-0.000236464128309173,1.19399744361177E-6,1,0.999253354069792,40.0298881530762,1.99641587024576,14.5600000396371,-0.00254710897291757,-0.000449698064140427,0.25,-3.24415312276637E-7,-0.000236455368981185,-4.78759464096029E-7,300.208221435547,300.208221435547,75815.484375,75856,54.5951888112365,19.7223014323374,45.7962112426758,0,0,0,40,300.612976074219,1,6,1,2.1661376953125,43.49951171875,,,,,,,,,,,,,,,,
,3735612232.364,300.193923950195,80081.41015625,-0.000251195142623528,1.03537102687775E-6,1,0.999253354069792,40.0298881530762,1.99647511844391,14.5600000396371,-0.00270352225513295,-0.000491098171337743,0.25,-1.58582342002039E-6,-0.000251185162871374,-1.7495685757031E-6,300.193969726562,300.193969726562,80063.671875,80099.1484375,54.6233274379289,19.7203635476965,45.970272064209,0,0,0,40,300.604431152344,1,6,1,2.14813232421875,43.49951171875,,,,,,,,,,,,,,,,
,3735612316.3095,300.181045532227,84325.92578125,-0.000268303376848811,1.12529961423022E-6,1,0.999253354069792,40.0298881530762,1.99637055710468,14.5600000396371,-0.00288891894947443,-0.000516473023479599,0.25,-9.47152972132456E-7,-0.000268293342080387,-1.1218936152522E-6,300.1806640625,300.1806640625,84305.78125,84346.0703125,54.7952857121596,19.7218572017065,46.1740188598633,0,0,0,40,300.592651367188,1,6,1,2.15011596679687,43.49951171875,,,,,,,,,,,,,,,,
,3735612400.1445,300.170379638672,88563.32421875,-0.000284478554074996,9.92834372310374E-7,1,0.999253354069792,40.0298881530762,1.99637130869369,14.5600000396371,-0.0030613790033232,-0.000557352907080799,0.25,-1.90874606240923E-6,-0.000284467450100697,-2.09379253439412E-6,300.170654296875,300.170654296875,88537.921875,88588.7265625,54.6162927812558,19.7196360772422,46.3537483215332,0,0,0,40,300.582885742188,1,6,1,2.16461181640625,43.49951171875,,,,,,,,,,,,,,,,
,3735612494.076,300.1591796875,87326.24609375,-0.000278142489198202,1.28444412828003E-6,1,0.999253354069792,40.0298881530762,1.99638998225396,14.5600000396371,-0.00299402065205989,-0.000540384029345269,0.25,-1.44290746815044E-6,-0.000278132010709791,-1.62391441183462E-6,300.160095214844,300.160095214844,87301.2890625,87351.203125,54.6030050964288,19.7216482633173,46.5019035339355,0,0,0,40,300.572967529297,1,6,1,2.1649169921875,44.4770278930664,,,,,,,,,,,,,,,,
,3735612578.161,300.148223876953,83136.01171875,-0.000264579353009087,1.22343029799399E-6,1,0.999253354069792,40.0298881530762,1.99633161915866,14.5600000396371,-0.00284914714651976,-0.000507150191262364,0.25,-7.34803860773655E-7,-0.000264569884120061,-9.07202413440059E-7,300.147857666016,300.147857666016,83121.09375,83150.9296875,54.945358387852,19.7229574778251,46.6846046447754,0,0,0,40,300.560150146484,1,6,1,2.14828491210938,43.9882698059082,,,,,,,,,,,,,,,,
,3735612661.957,300.139404296875,78961.046875,-0.000249155273766515,1.03640650096927E-6,1,0.999253354069792,40.0298881530762,1.99634136554481,14.5600000396371,-0.00268427229845798,-0.000470691860118232,0.25,-5.17637045651035E-8,-0.000249146834862807,-2.14314977931563E-7,300.139190673828,300.139190673828,78936.15625,78985.9375,54.7046168039289,19.7246399627532,46.8864593505859,0,0,0,40,300.552856445313,1,6,1,2.16522216796875,43.49951171875,,,,,,,,,,,,,,,,
,3735612745.9575,300.129760742188,74775.63671875,-0.000232113266679374,9.90870594115758E-7,1,0.999253354069792,40.0298881530762,1.99634612104989,14.5600000396371,-0.00249873744912152,-0.000449570856680319,0.25,-1.07579713112393E-6,-0.000232104797162363,-1.22736402119298E-6,300.129211425781,300.129211425781,74745.8046875,74805.46875,54.823424338852,19.7238041384547,47.0556640625,0,0,0,40,300.545989990234,1,6,1,2.164306640625,43.9882698059082,,,,,,,,,,,,,,,,
,3735612829.9485,300.122894287109,70590.13671875,-0.000216906134943915,1.16341447279912E-6,1,0.999253354069792,40.0298881530762,1.99626248474141,14.5600000396371,-0.00233378527228126,-0.000426679480591351,0.25,-1.61586095921684E-6,-0.000216897858772945,-1.75763208969561E-6,300.123870849609,300.123870849609,70575.25,70605.0234375,55.0375905531212,19.7270437317541,47.2256813049316,0,0,0,40,300.535308837891,1,6,1,2.16323852539062,43.49951171875,,,,,,,,,,,,,,,,
,3735612913.864,300.115005493164,66410.37109375,-0.000201043426763772,7.84503208268878E-7,1,0.999253354069792,40.0298881530762,1.99629519536897,14.5600000396371,-0.00216199653948861,-0.000402043924423453,0.25,-2.10662535423079E-6,-0.000201035399036972,-2.23815085133247E-6,300.115509033203,300.115509033203,66390.4453125,66430.296875,54.7827796558519,19.7249787712515,47.3886795043945,0,0,0,40,300.531524658203,1,6,1,2.15011596679687,43.49951171875,,,,,,,,,,,,,,,,
,3735612997.7455,300.108779907227,62230.0859375,-0.00018595860697523,1.03062721878815E-6,1,0.999253354069792,40.0298881530762,1.99637765326874,14.5600000396371,-0.00200321802652264,-0.000352690605998279,0.25,-1.66229785374581E-7,-0.000185952377097851,-2.88074929079602E-7,300.109069824219,300.109069824219,62205.1171875,62255.0546875,54.7452614869289,19.7229018005275,47.5392608642578,0,0,0,40,300.515289306641,1,6,1,2.1649169921875,43.49951171875,,,,,,,,,,,,,,,,
,3735613081.6175,300.100769042969,58049.4375,-0.000170027274103618,9.48036739910722E-7,1,0.999253354069792,40.0298881530762,1.9963933845596,14.5600000396371,-0.00183170182513915,-0.000321974258638379,0.25,-1.05153688132403E-7,-0.000170021645712735,-2.16679547370232E-7,300.100250244141,300.100250244141,58024.53125,58074.34375,54.8210794532943,19.7240901558463,47.7071189880371,0,0,0,40,300.516754150391,1,6,1,2.1514892578125,43.49951171875,,,,,,,,,,,,,,,,
,3735613165.5785,300.094955444336,53867.33984375,-0.000154832758536988,9.60149545571943E-7,1,0.999253354069792,40.0298881530762,1.99636016530309,14.5600000396371,-0.00166487007443342,-0.000310983454819883,0.25,-1.74657966775751E-6,-0.000154826571192627,-1.84819042968796E-6,300.095855712891,300.095855712891,53844.91015625,53889.76953125,54.7319738021019,19.724066699753,47.886848449707,0,0,0,40,300.506927490234,1,6,1,2.15057373046875,43.49951171875,,,,,,,,,,,,,,,,
,3735613249.586,300.088989257812,49680.33984375,-0.000138954484653534,8.55685801194782E-7,1,0.999253354069792,40.0298881530762,1.99642209996341,14.5600000396371,-0.00149519150604321,-0.000273325004772232,0.25,-1.0313734595043E-6,-0.000138949303818035,-1.12267483168547E-6,300.088745117188,300.088745117188,49660.453125,49700.2265625,54.8226427103327,19.7252939071336,48.0447196960449,0,0,0,40,300.507446289063,1,6,1,2.149658203125,43.49951171875,,,,,,,,,,,,,,,,
,3735613333.436,300.082336425781,45504.69921875,-0.000124275751136966,6.98942956660124E-7,1,0.999253354069792,40.0298881530762,1.99647238430345,14.5600000396371,-0.0013363375393874,-0.000249817192407145,0.25,-1.41976381122583E-6,-0.000124270811315909,-1.50148676573096E-6,300.082397460937,300.082397460937,45479.796875,45529.6015625,54.8992423052174,19.7251526481461,48.1923332214355,0,0,0,40,300.495361328125,1,6,1,2.16537475585938,43.49951171875,,,,,,,,,,,,,,,,
,3735613417.5295,300.078430175781,41312.748046875,-0.000107765885160322,8.30198548665849E-7,1,0.999253354069792,40.0298881530762,1.99646546005866,14.5600000396371,-0.00115988244515056,-0.000210466350634674,0.25,-6.5915121493324E-7,-0.000107761986005113,-7.30105571387771E-7,300.077911376953,300.077911376953,41295.3203125,41330.17578125,54.799975483275,19.7238482828926,48.3313140869141,0,0,0,40,300.490295410156,1,6,1,2.14630126953125,43.49951171875,,,,,,,,,,,,,,,,
,3735613501.443,300.072036743164,37135.216796875,-9.22630290851427E-5,7.58904809035245E-7,1,0.999253354069792,40.0298881530762,1.99639555789948,14.5600000396371,-0.000992619642403661,-0.000182312599199302,0.25,-7.6189285603924E-7,-9.22595755942386E-5,-8.22692724890587E-7,300.071014404297,300.071014404297,37115.2265625,37155.20703125,55.0258661253327,19.7264029769213,48.4435768127441,0,0,0,40,300.492340087891,1,6,1,2.16552734375,43.49951171875,,,,,,,,,,,,,,,,
,3735613585.294,300.067886352539,32955.046875,-7.75301409473291E-5,8.40975478431275E-7,1,0.999253354069792,40.0298881530762,1.99656102213223,14.5600000396371,-0.000834108496806899,-0.00015362295494829,0.25,-6.78289046376938E-7,-7.75272203487127E-5,-7.29427195047274E-7,300.067260742188,300.067260742188,32925.23046875,32984.86328125,55.0751087220443,19.7248984205871,48.5571899414063,0,0,0,40,300.486511230469,1,6,1,2.16629028320313,43.49951171875,,,,,,,,,,,,,,,,
,3735613669.445,300.062637329102,28762.6318359375,-6.27592826941657E-5,7.40444728094791E-7,1,0.999253354069792,40.0298881530762,1.99666181961605,14.5600000396371,-0.000674330663551317,-0.000129487959591369,0.25,-1.02481551615099E-6,-6.27566120379081E-5,-1.06623429750449E-6,300.062530517578,300.062530517578,28750.263671875,28775,54.9054953333712,19.7199003306313,48.6492118835449,0,0,0,40,300.488983154297,1,6,1,2.1649169921875,43.49951171875,,,,,,,,,,,,,,,,
,3735613753.2715,300.056732177734,24585.7451171875,-4.71356189017106E-5,7.55499272763339E-7,1,0.999253354069792,40.0298881530762,1.99649532228256,14.5600000396371,-0.000506391446762762,-9.74006910844705E-5,0.25,-7.84134789322724E-7,-4.71336103050712E-5,-8.152702540611E-7,300.056518554687,300.056518554687,24570.783203125,24600.70703125,54.8804832207558,19.7246876613543,48.6729621887207,0,0,0,40,300.486846923828,1,6,1,2.149658203125,43.49951171875,,,,,,,,,,,,,,,,
,3735613837.171,300.050659179687,20406.0478515625,-3.21830004849201E-5,7.84579017585234E-7,1,0.999253354069792,40.0298881530762,1.9966555158387,14.5600000396371,-0.00034486193670035,-7.17358436420913E-5,0.25,-1.02054774962586E-6,-3.2181312914341E-5,-1.04180966667883E-6,300.051239013672,300.051239013672,20386.08984375,20426.005859375,54.8992423052174,19.7227106313188,48.6451644897461,0,0,0,40,300.488891601562,1,6,1,2.14859008789062,43.49951171875,,,,,,,,,,,,,,,,
,3735613921.1245,300.04817199707,16221.4741210938,-1.72039279994842E-5,6.81205120340112E-7,1,0.999253354069792,40.0298881530762,1.99649959397221,14.5600000396371,-0.000183294052173995,-4.43032187280408E-5,0.25,-1.09855279478064E-6,-1.72026600345917E-5,-1.1099107445418E-6,300.048278808594,300.048278808594,16201.568359375,16241.3798828125,55.0938678065058,19.7247254807012,48.6092720031738,0,0,0,40,300.491333007812,1,6,1,2.1649169921875,43.49951171875,,,,,,,,,,,,,,,,
,3735614004.9325,300.043151855469,12045.16015625,-3.18177844029031E-6,4.8551040188982E-7,1,0.999253354069792,40.0298881530762,1.99649993415959,14.5600000396371,-3.29659956321276E-5,-1.35223416933523E-5,0.25,-6.97725229712389E-7,-3.18121648360514E-6,-6.99812050373672E-7,300.043518066406,300.043518066406,12020.142578125,12070.177734375,54.9437951308135,19.7255433400828,48.573112487793,0,0,0,40,300.489349365234,1,6,1,2.14874267578125,43.49951171875,,,,,,,,,,,,,,,,
,3735614088.953,300.03825378418,7853.3740234375,1.04409457192019E-5,4.83040322356207E-7,1,0.999253354069792,40.0298881530762,1.9965300125198,14.5600000396371,0.000114008548433088,1.1089629418258E-5,0.25,-7.99505221115062E-7,1.04411506045009E-5,-7.92555655228248E-7,300.038909912109,300.038909912109,7833.4248046875,7873.3232421875,54.8367120236789,19.7276161332194,48.5310134887695,0,0,0,40,300.485504150391,1,6,1,2.1649169921875,43.49951171875,,,,,,,,,,,,,,,,
,3735614172.98,300.035919189453,3653.35205078125,2.02499906669292E-5,5.64476140268538E-7,1,0.999253354069792,40.0298881530762,1.99646289922946,14.5600000396371,0.000219568117345035,3.03111721032256E-5,0.25,-7.33541136589318E-7,2.02498473081315E-5,-7.20079244871309E-7,300.035919189453,300.035919189453,3638.375,3668.3291015625,55.0289926394097,19.7253665488695,48.4978179931641,0,0,0,40,300.486053466797,1,6,1,2.16506958007813,43.49951171875,,,,,,,,,,,,,,,,
,3735614262.7545,300.036178588867,-830.050201416016,-1.77073899393278E-5,4.57236135114857E-7,1,0.999253354069792,40.0298881530762,1.99641843032287,14.5600000396371,-0.000188965224047891,-4.38026430833577E-5,0.25,-9.64040508152969E-7,-1.77061983240386E-5,-9.75766330044782E-7,300.036468505859,300.036468505859,-855.049133300781,-805.05126953125,54.874230192602,19.728253823164,48.4354820251465,0,0,0,40,300.479370117188,1,6,1,2.1502685546875,43.49951171875,,,,,,,,,,,,,,,,
,3735614349.677,300.033615112305,-5176.31616210937,-1.71541827724297E-5,5.2305271275312E-7,1,0.999253354069792,40.0298881530762,1.99643856565317,14.5600000396371,-0.000183511047057267,-3.98789575723761E-5,0.25,-6.96733668196379E-7,-1.71531882444737E-5,-7.08094111904413E-7,300.032989501953,300.032989501953,-5198.8779296875,-5153.75439453125,54.8429650518327,19.7272706299488,48.386905670166,0,0,0,40,300.476776123047,1,6,1,2.16552734375,43.49951171875,,,,,,,,,,,,,,,,
,3735614436.6085,300.031814575195,-9524.55810546875,-4.55618256987844E-6,6.47418340096301E-7,1,0.999253354069792,40.0298881530762,1.99646804097416,14.5600000396371,-4.65667498516096E-5,-2.30090338240237E-5,0.25,-1.33749062922761E-6,-4.55515486035723E-6,-1.34047025340603E-6,300.032196044922,300.032196044922,-9549.5859375,-9499.5302734375,54.7624573143519,19.7286464177008,48.3380584716797,0,0,0,40,300.474060058594,1,6,1,2.16354370117187,43.0107536315918,,,,,,,,,,,,,,,,
,3735614520.5495,300.029586791992,-13721.849609375,8.47176439368214E-6,4.54948393644707E-7,1,0.999253354069792,40.0298881530762,1.99653659761186,14.5600000396371,9.41174644990812E-5,-1.987475452558E-7,0.25,-1.50225862471214E-6,8.47249880418329E-6,-1.4965992963894E-6,300.029998779297,300.029998779297,-13744.3017578125,-13699.3974609375,55.0149233260635,19.7273830055447,48.2881355285645,0,0,0,40,300.480102539063,1,6,1,2.16583251953125,43.49951171875,,,,,,,,,,,,,,,,
,3735614604.5205,300.027740478516,-17918.916015625,2.2862390600836E-5,6.70455867930299E-7,1,0.999253354069792,40.0298881530762,1.99643566369508,14.5600000396371,0.000248610560669025,3.01123419475023E-5,0.25,-1.20948223770203E-6,2.2862489722438E-5,-1.19430933440395E-6,300.029022216797,300.029022216797,-17938.83203125,-17899,54.8257692244096,19.7272005457018,48.2503547668457,0,0,0,40,300.467071533203,1,6,1,2.1490478515625,43.49951171875,,,,,,,,,,,,,,,,
,3735614688.411,300.026321411133,-22113.5849609375,3.81003207581536E-5,5.12087441382885E-7,1,0.999253354069792,40.0298881530762,1.99638663023232,14.5600000396371,0.00041335860500457,5.55644092623366E-5,0.25,-1.51595098102031E-6,3.81001580884837E-5,-1.49070158674984E-6,300.026702880859,300.026702880859,-22138.583984375,-22088.5859375,54.9633358437943,19.7284048299526,48.2152709960937,0,0,0,40,300.471862792969,1,6,1,2.1484375,43.0107536315918,,,,,,,,,,,,,,,,
,3735614772.37,300.024200439453,-26314.3974609375,5.26707514021718E-5,4.90272835069245E-7,1,0.999253354069792,40.0298881530762,1.99635906597191,14.5600000396371,0.000570788589701384,8.04684178800799E-5,0.25,-1.7563276823627E-6,5.2670307637024E-5,-1.72146281316473E-6,300.024749755859,300.024749755859,-26339.5078125,-26289.287109375,55.1009024631789,19.7300806124232,48.1801910400391,0,0,0,40,300.469146728516,1,6,1,2.16384887695313,43.9882698059082,,,,,,,,,,,,,,,,
,3735614856.4265,300.022933959961,-30532.2001953125,6.748235349759E-5,6.62858775740872E-7,1,0.999253354069792,40.0298881530762,1.99648924577639,14.5600000396371,0.000728567847841606,0.000118965915825473,0.25,-7.77984692173592E-7,6.7480818001728E-5,-7.33400131075446E-7,300.022857666016,300.022857666016,-30549.763671875,-30514.63671875,54.881264849275,19.7303635306484,48.1440277099609,0,0,0,40,300.473480224609,1,6,1,2.16567993164062,43.49951171875,,,,,,,,,,,,,,,,
,3735614940.325,300.022018432617,-34741.861328125,8.26193321406494E-5,6.13886609625228E-7,1,0.999253354069792,40.0298881530762,1.99643906401353,14.5600000396371,0.000890010162614567,0.000156847694039474,0.25,8.70539080203743E-8,8.2616772946176E-5,1.41557723628453E-7,300.022827148438,300.022827148438,-34764.40234375,-34719.3203125,54.8961157911404,19.7289828090296,48.0911331176758,0,0,0,40,300.463165283203,1,6,1,2.16354370117187,43.9882698059082,,,,,,,,,,,,,,,,
,3735615024.3465,300.019607543945,-38959.716796875,9.91234470443712E-5,7.06060245794262E-7,1,0.999253354069792,40.0298881530762,1.9965380067151,14.5600000396371,0.00106974725704268,0.000177355450933754,0.25,-9.00901976789704E-7,9.91210531527039E-5,-8.35541147313956E-7,300.019500732422,300.019500732422,-38974.9609375,-38944.47265625,55.0414986957174,19.7262491393343,48.0649566650391,0,0,0,40,300.464172363281,1,6,1,2.1649169921875,43.49951171875,,,,,,,,,,,,,,,,
,3735615108.1145,300.018844604492,-43164.580078125,0.000115320574497163,7.24871079792955E-7,1,0.999253354069792,40.0298881530762,1.99652390330612,14.5600000396371,0.00124655855772138,0.000194806835288524,0.25,-2.11791697120387E-6,0.000115318502809201,-2.04191659105327E-6,300.019470214844,300.019470214844,-43189.66015625,-43139.5,54.7210310028327,19.7279988255716,48.030143737793,0,0,0,40,300.465026855469,1,6,1,2.16293334960938,43.0107536315918,,,,,,,,,,,,,,,,
,3735615192.0265,300.017181396484,-47374.1796875,0.000130121664386236,7.3874650874728E-7,1,0.999253354069792,40.0298881530762,1.99652751570436,14.5600000396371,0.00140517678992501,0.000227671271687971,0.25,-1.66008585569703E-6,0.000130118860289644,-1.57443644900451E-6,300.017883300781,300.017883300781,-47399.24609375,-47349.11328125,54.7014902898519,19.7271021287955,47.9934425354004,0,0,0,40,300.464874267578,1,6,1,2.16598510742187,43.49951171875,,,,,,,,,,,,,,,,
,3735615275.9485,300.018753051758,-51587.298828125,0.000144881126792826,7.54796808107147E-7,1,0.999253354069792,40.0298881530762,1.99644385674394,14.5600000396371,0.00156384556008686,0.00025722832367013,0.25,-1.50091168974351E-6,0.000144877775628781,-1.40565316766534E-6,300.018432617188,300.018432617188,-51609.76953125,-51564.828125,54.7788715132558,19.7295386311721,47.9648399353027,0,0,0,40,300.463104248047,1,6,1,2.16461181640625,43.49951171875,,,,,,,,,,,,,,,,
,3735615359.9395,300.01611328125,-55827.890625,0.000161583138482996,8.95571720400852E-7,1,0.999253354069792,40.0298881530762,1.99636521887855,14.5600000396371,0.0017437407530107,0.000288704505675924,0.25,-1.50366284404435E-6,0.000161579312566966,-1.39753518663977E-6,300.016693115234,300.016693115234,-55853.1484375,-55802.6328125,54.9789684141789,19.7307351330528,47.925708770752,0,0,0,40,300.463195800781,1,6,1,2.14996337890625,43.49951171875,,,,,,,,,,,,,,,,
,3735615443.8505,300.015808105469,-60071.45703125,0.000177812433431067,9.94162573626856E-7,1,0.999253354069792,40.0298881530762,1.99641269465606,14.5600000396371,0.00191907190840444,0.000316866397185528,0.25,-1.73277258300444E-6,0.000177808285973167,-1.61610383908649E-6,300.016052246094,300.016052246094,-60094.2734375,-60048.640625,54.9164381326404,19.7300447338232,47.8881950378418,0,0,0,40,300.463470458984,1,6,1,2.14981079101562,44.9657897949219,,,,,,,,,,,,,,,,
,3735615527.8925,300.014221191406,-64318.392578125,0.00019340470020913,7.92945180945148E-7,1,0.999253354069792,40.0298881530762,1.99647839229863,14.5600000396371,0.00208617549406759,0.000351767205228289,0.25,-1.22524446870864E-6,0.000193399778217325,-1.09849698211209E-6,300.014373779297,300.014373779297,-64336.06640625,-64300.71875,54.7116514606019,19.7288869753813,47.8342247009277,0,0,0,40,300.457458496094,1,6,1,2.16293334960938,43.0107536315918,,,,,,,,,,,,,,,,
,3735615611.888,300.012466430664,-68567.56640625,0.000209186619886604,1.04301061571576E-6,1,0.999253354069792,40.0298881530762,1.99643186397042,14.5600000396371,0.00225345548619791,0.000397039881798612,0.25,2.13445845251843E-7,0.0002091803140246,3.50345962192794E-7,300.01220703125,300.01220703125,-68582.703125,-68552.4296875,54.6913291191019,19.7305652575224,47.8010292053223,0,0,0,40,300.459716796875,1,6,1,2.16476440429687,43.0107536315918,,,,,,,,,,,,,,,,
,3735615695.659,300.013137817383,-72803.7578125,0.00022561132069827,1.09173466019961E-6,1,0.999253354069792,40.0298881530762,1.99655567383446,14.5600000396371,0.00243593346043147,0.00039740645492394,0.25,-2.63116650355661E-6,0.000225606399332829,-2.48359155576286E-6,300.013427734375,300.013427734375,-72828.96875,-72778.546875,54.8492180799866,19.7306120456871,47.7726936340332,0,0,0,40,300.458190917969,1,6,1,2.1490478515625,43.49951171875,,,,,,,,,,,,,,,,
,3735615779.5795,300.008804321289,-77044.4296875,0.000241464979863889,9.72538951540271E-7,1,0.999253354069792,40.0298881530762,1.99655536307894,14.5600000396371,0.00260600985186865,0.00043159165160949,0.25,-2.23496265476156E-6,0.000241459382752857,-2.07720346221851E-6,300.008483886719,300.008483886719,-77069.7109375,-77019.1484375,54.7562042861981,19.7309114446303,47.7538032531738,0,0,0,40,300.455993652344,1,6,1,2.14691162109375,44.9657897949219,,,,,,,,,,,,,,,,
,3735615863.515,300.010711669922,-81288,0.000257605342883018,8.57269127918757E-7,1,0.999253354069792,40.0298881530762,1.9965926053212,14.5600000396371,0.00278085609241821,0.000457010701184331,0.25,-2.70325445088207E-6,0.000257599577209215,-2.53512608579993E-6,300.011322021484,300.011322021484,-81310.7265625,-81265.2734375,54.8781383351981,19.7291489261199,47.7265472412109,0,0,0,40,300.457183837891,1,6,1,2.14874267578125,43.49951171875,,,,,,,,,,,,,,,,
,3735615947.672,300.009750366211,-85541.72265625,0.000272620855465291,8.71209036647342E-7,1,0.999253354069792,40.0298881530762,1.99655417208147,14.5600000396371,0.00294113308944122,0.000493702582181016,0.25,-1.92679498682403E-6,0.000272614169563552,-1.749090329424E-6,300.009613037109,300.009613037109,-85556.890625,-85526.5546875,54.8312406240443,19.7309073484404,47.7054977416992,0,0,0,40,300.458801269531,1,6,1,2.16415405273438,43.49951171875,,,,,,,,,,,,,,,,
,3735616031.413,300.010955810547,-89774.8046875,0.000290389174903718,1.21149529037245E-6,1,0.999253354069792,40.0298881530762,1.99650211089533,14.5600000396371,0.0031326274099018,0.000526547512854894,0.25,-1.98901396647258E-6,0.000290382016951143,-1.79994034219002E-6,300.011413574219,300.011413574219,-89802.6953125,-89746.9140625,54.6225458094096,19.728241268345,47.6687965393066,0,0,0,40,300.45458984375,1,6,1,2.15164184570313,43.49951171875,,,,,,,,,,,,,,,,
,3735616124.3515,300.008743286133,-86126.91015625,0.000275297980568598,1.10040480427579E-6,1,0.999253354069792,40.0298881530762,1.99649627552426,14.5600000396371,0.00297120848992585,0.000491254948037331,0.25,-2.62153436626462E-6,0.000275291681209353,-2.44209185626898E-6,300.009094238281,300.009094238281,-86151.796875,-86102.0234375,54.8695404214866,19.7302166699461,47.6269683837891,0,0,0,40,300.456024169922,1,6,1,2.14675903320313,43.0107536315918,,,,,,,,,,,,,,,,
,3735616208.261,300.010055541992,-81946.06640625,0.000259008709723542,9.83745137114572E-7,1,0.999253354069792,40.0298881530762,1.99650809601035,14.5600000396371,0.00279190415395239,0.000482257675552927,0.25,-6.04150104186237E-7,0.000259001542073751,-4.35196029040491E-7,300.010131835937,300.010131835937,-81968.5078125,-81923.625,54.840620166275,19.7294498977013,47.6002502441406,0,0,0,40,300.453826904297,1,6,1,2.164306640625,43.9882698059082,,,,,,,,,,,,,,,,
,3735616292.2105,300.007278442383,-77764.40234375,0.000243172651403163,1.22918509394305E-6,1,0.999253354069792,40.0298881530762,1.99661759549107,14.5600000396371,0.00262418560709192,0.000436553736200424,0.25,-2.07469898337323E-6,0.000243166914981287,-1.91585780457785E-6,300.007843017578,300.007843017578,-77789.2734375,-77739.53125,54.7835612843712,19.7279868306862,47.5611228942871,0,0,0,40,300.452911376953,1,6,1,2.16552734375,43.49951171875,,,,,,,,,,,,,,,,
,3735616376.1445,300.008117675781,-73585.9921875,0.000227799474706538,1.02202448985853E-6,1,0.999253354069792,40.0298881530762,1.99661483184166,14.5600000396371,0.00245848159734939,0.000407822304877277,0.25,-2.04877829815703E-6,0.000227794150312165,-1.89981703402257E-6,300.007965087891,300.007965087891,-73610.8828125,-73561.1015625,54.7499512580443,19.7294580508945,47.5414199829102,0,0,0,40,300.453399658203,1,6,1,2.164306640625,43.49951171875,,,,,,,,,,,,,,,,
,3735616460.209,300.006164550781,-69400.06640625,0.000212300931056346,9.12657662741208E-7,1,0.999253354069792,40.0298881530762,1.99660199932887,14.5600000396371,0.00228836292126062,0.000396287250364784,0.25,-4.0481006141436E-7,0.000212294987055821,-2.6587926286222E-7,300.006286621094,300.006286621094,-69417.5390625,-69382.59375,54.9180013896789,19.7304478026411,47.5152435302734,0,0,0,40,300.451293945313,1,6,1,2.161865234375,43.0107536315918,,,,,,,,,,,,,,,,
,3735616543.9905,300.005966186523,-65222.91796875,0.000197121958033383,9.79004864477608E-7,1,0.999253354069792,40.0298881530762,1.99662270676001,14.5600000396371,0.00212650426741976,0.000358064715505359,0.25,-1.29407936682603E-6,0.00019711703007908,-1.16491969998321E-6,300.005828857422,300.005828857422,-65247.8203125,-65198.015625,54.7757449991789,19.7293788238598,47.484748840332,0,0,0,40,300.454711914063,1,6,1,2.16522216796875,43.0107536315918,,,,,,,,,,,,,,,,
,3735616627.9445,300.004745483398,-61041.072265625,0.000181150079923921,9.02370474549311E-7,1,0.999253354069792,40.0298881530762,1.99657401796089,14.5600000396371,0.00195216070060196,0.000340449601095648,0.25,-1.30907272355695E-7,0.000181144854851994,-1.21203403048053E-8,300.004364013672,300.004364013672,-61063.4609375,-61018.68359375,54.8054468829097,19.7308030289005,47.435905456543,0,0,0,40,300.454284667969,1,6,1,2.16384887695313,40.5669593811035,,,,,,,,,,,,,,,,
,3735616711.9985,300.004791259766,-56857.314453125,0.000165943869488346,1.11740159117291E-6,1,0.999253354069792,40.0298881530762,1.99656563273003,14.5600000396371,0.00179093712442015,0.000296721598788929,0.25,-1.52591447112245E-6,0.000165939995792367,-1.41694618955751E-6,300.00390625,300.00390625,-56874.75390625,-56839.875,54.8906443915058,19.7285106718173,47.4129676818848,0,0,0,40,300.456176757812,1,6,1,2.16506958007813,43.9882698059082,,,,,,,,,,,,,,,,
,3735616795.935,300.005722045898,-52673.50390625,0.000149708457640015,9.47634560542248E-7,1,0.999253354069792,40.0298881530762,1.99660793219521,14.5600000396371,0.00161368758674885,0.000279472503339789,0.25,-2.8386876039579E-7,0.000149704232158922,-1.85494841846534E-7,300.006195068359,300.006195068359,-52695.81640625,-52651.19140625,54.9265993033904,19.7269905633185,47.3927268981934,0,0,0,40,300.451965332031,1,6,1,2.164306640625,43.49951171875,,,,,,,,,,,,,,,,
,3735616879.87,300.003921508789,-48492.197265625,0.000133728192379511,9.94730184179177E-7,1,0.999253354069792,40.0298881530762,1.99663146812858,14.5600000396371,0.0014439117162677,0.000235614450628203,0.25,-1.55562403788347E-6,0.000133725275040129,-1.46762449622564E-6,300.00439453125,300.00439453125,-48512.0859375,-48472.30859375,54.9813132997366,19.7277186952815,47.3894882202148,0,0,0,40,300.451141357422,1,6,1,2.1624755859375,43.9882698059082,,,,,,,,,,,,,,,,
,3735616963.7045,300.003860473633,-44318.7265625,0.000118565746748077,8.34711451549268E-7,1,0.999253354069792,40.0298881530762,1.99668219467005,14.5600000396371,0.00128163667964303,0.00020086284773582,0.25,-2.12563693766324E-6,0.000118563645902933,-2.0475167785207E-6,300.004455566406,300.004455566406,-44343.59375,-44293.859375,54.8492180799866,19.7264371983076,47.3719482421875,0,0,0,40,300.453704833984,1,6,1,2.14996337890625,44.9657897949219,,,,,,,,,,,,,,,,
,3735617047.623,300.004638671875,-40137.388671875,0.000104230587540944,7.61722138060404E-7,1,0.999253354069792,40.0298881530762,1.99667821058004,14.5600000396371,0.0011259113005588,0.000180957779629691,0.25,-1.46218010036859E-6,0.000104228465313398,-1.39345122554091E-6,300.004638671875,300.004638671875,-40159.82421875,-40114.953125,54.884391363352,19.7283479174138,47.3441505432129,0,0,0,40,300.452850341797,1,6,1,2.16461181640625,43.49951171875,,,,,,,,,,,,,,,,
,3735617131.5815,300.004898071289,-35956.078125,8.7697243920536E-5,6.92216457554252E-7,1,0.999253354069792,40.0298881530762,1.99654665528042,14.5600000396371,0.000948179964220722,0.0001469730562098,0.25,-1.71950321045948E-6,8.76957761381492E-5,-1.66160735891093E-6,300.005340576172,300.005340576172,-35981.0390625,-35931.1171875,54.8296773670058,19.7278737146048,47.3314666748047,0,0,0,40,300.449188232422,1,6,1,2.14736938476562,43.9882698059082,,,,,,,,,,,,,,,,
,3735617215.5085,300.004165649414,-31774.552734375,7.2112049818281E-5,5.46439581430584E-7,1,0.999253354069792,40.0298881530762,1.99667132942133,14.5600000396371,0.000780226575038826,0.000117966126750978,0.25,-1.68259440947594E-6,7.21110190345794E-5,-1.63493562387008E-6,300.004058837891,300.004058837891,-31796.986328125,-31752.119140625,54.9602093297174,19.7270777519078,47.301513671875,0,0,0,40,300.449157714844,1,6,1,2.16522216796875,43.0107536315918,,,,,,,,,,,,,,,,
,3735617299.4665,300.004608154297,-27593.607421875,5.73896285950576E-5,6.6044260691097E-7,1,0.999253354069792,40.0298881530762,1.99671017071561,14.5600000396371,0.000621872397401475,8.85985452475037E-5,0.25,-1.82958848856094E-6,5.73891292444497E-5,-1.79161111235222E-6,300.004577636719,300.004577636719,-27618.458984375,-27568.755859375,54.9140932470827,19.7272976858316,47.2745246887207,0,0,0,40,300.450103759766,1,6,1,2.16415405273438,44.4770278930664,,,,,,,,,,,,,,,,
,3735617383.5805,300.002960205078,-23402.1376953125,4.19394542437586E-5,7.17135117668381E-7,1,0.999253354069792,40.0298881530762,1.9968218034071,14.5600000396371,0.0004548591133036,6.2579125335532E-5,0.25,-1.53849694330773E-6,4.19392235731797E-5,-1.51071328965929E-6,300.003326416016,300.003326416016,-23424.5703125,-23379.705078125,54.8671955359289,19.7267958937221,47.2588729858398,0,0,0,40,300.453399658203,1,6,1,2.16522216796875,43.49951171875,,,,,,,,,,,,,,,,
,3735617467.4085,300.003128051758,-19227.4404296875,2.7953179760207E-5,5.22954017207255E-7,1,0.999253354069792,40.0298881530762,1.99671258354374,14.5600000396371,0.000303672344388312,3.87459076321136E-5,0.25,-1.30029080471338E-6,2.79532069666103E-5,-1.28174887812438E-6,300.002532958984,300.002532958984,-19244.833984375,-19210.046875,54.904713704852,19.7261935651113,47.2429504394531,0,0,0,40,300.453643798828,1,6,1,2.1636962890625,43.49951171875,,,,,,,,,,,,,,,,
,3735617551.454,300.003677368164,-15038.7143554687,1.24523909020401E-5,5.48079079286801E-7,1,0.999253354069792,40.0298881530762,1.99677552471626,14.5600000396371,0.000136774997866354,8.73612837861385E-6,0.25,-1.37031879300055E-6,1.24529265543727E-5,-1.36202854699253E-6,300.00390625,300.00390625,-15061.1357421875,-15016.29296875,54.8007571117943,19.7259402499792,47.2194747924805,0,0,0,40,300.449096679687,1,6,1,2.16476440429687,43.49951171875,,,,,,,,,,,,,,,,
,3735617635.3015,300.002685546875,-10858.419921875,-4.8745544731224E-7,5.58662756010345E-7,1,0.999253354069792,40.0298881530762,1.99663338697797,14.5600000396371,-3.56611479168686E-6,-1.05484561499813E-5,0.25,-8.93561284145987E-7,-4.86848466368186E-7,-8.93857740700314E-7,300.003265380859,300.003265380859,-10878.328125,-10838.51171875,54.8343671381212,19.7272337789982,47.1995048522949,0,0,0,40,300.450378417969,1,6,1,2.1466064453125,43.49951171875,,,,,,,,,,,,,,,,
,3735617719.3495,300.001586914063,-6663.15014648438,-1.36128712956808E-5,5.37076268809461E-7,1,0.999253354069792,40.0298881530762,1.99668087953783,14.5600000396371,-0.000143531991935712,-4.37082323060861E-5,0.25,-1.67192455398673E-6,-1.36113550397164E-5,-1.68090596728413E-6,300.001586914063,300.001586914063,-6675.52392578125,-6650.7763671875,54.8617241362943,19.7253387192392,47.182502746582,0,0,0,40,300.447814941406,1,6,1,2.14797973632813,43.0107536315918,,,,,,,,,,,,,,,,
,3735617806.0545,300.001663208008,-2332.19226074219,-2.13629626080628E-5,4.8581037897893E-7,1,0.999253354069792,40.0298881530762,1.99666876276202,14.5600000396371,-0.000227538742245393,-5.55040608639892E-5,0.25,-1.40919974962112E-6,-2.1361387464179E-5,-1.42333973896127E-6,300.001525878906,300.001525878906,-2354.6923828125,-2309.69213867187,54.7530777721212,19.7276020311456,47.1628036499023,0,0,0,40,300.450378417969,1,6,1,2.16522216796875,43.49951171875,,,,,,,,,,,,,,,,
,3735617893.013,300.001937866211,2013.22576904297,-1.36776846878248E-5,3.49375298812745E-5,1,0.999253354069792,40.0298881530762,1.99663598969275,14.5600000396371,-0.000167741720187876,9.04238511377112E-5,0.25,1.07873206744522E-5,-1.36844366430728E-5,1.07779170315798E-5,300.001922607422,300.001922607422,1988.57702636719,2037.87451171875,55.016486583102,19.7270670826815,47.1379737854004,0,0,0,40,300.451232910156,1,6,1,2.16506958007813,43.49951171875,,,,,,,,,,,,,,,,
,3735617979.9315,300.001373291016,6361.30249023437,1.42120203613996E-5,5.43844318579128E-7,1,0.999253354069792,40.0298881530762,1.99671662437469,14.5600000396371,0.000155760310465663,1.18990048295269E-5,0.25,-1.38499044744276E-6,1.42125143982131E-5,-1.37551967489581E-6,300.001129150391,300.001129150391,6338.880859375,6383.72412109375,54.8062285114289,19.7269932534241,47.0969543457031,0,0,0,40,300.447845458984,1,6,1,2.16522216796875,43.49951171875,,,,,,,,,,,,,,,,
,3735618066.887,300.001113891602,10708.9985351562,1.22618343281348E-6,5.19223329050829E-7,1,0.999253354069792,40.0298881530762,1.99668611638979,14.5600000396371,1.53918135007549E-5,-1.01258394837956E-5,0.25,-1.15445845175962E-6,1.22691224101137E-6,-1.15361104505815E-6,300.001525878906,300.001525878906,10683.9599609375,10734.037109375,55.0618210372174,19.7266294239503,47.0707778930664,0,0,0,40,300.4521484375,1,6,1,2.16232299804687,43.49951171875,,,,,,,,,,,,,,,,
,3735618150.941,300.000274658203,14911.17578125,-1.25936002479049E-5,5.57543457456212E-7,1,0.999253354069792,40.0298881530762,1.9968829629147,14.5600000396371,-0.000134834154003529,-2.88127899642656E-5,0.25,-4.67878461797226E-7,-1.25929153949392E-5,-4.76207687204927E-7,300.000030517578,300.000030517578,14893.7490234375,14928.6025390625,54.830458995525,19.7256906413851,47.0529670715332,0,0,0,40,300.451690673828,1,6,1,2.16522216796875,43.49951171875,,,,,,,,,,,,,,,,
,3735618234.7175,300.001907348633,19103.9873046875,-2.77490935101384E-5,5.77421238917018E-7,1,0.999253354069792,40.0298881530762,1.99676688738414,14.5600000396371,-0.000298348040989803,-5.62490228460832E-5,0.25,-3.59615178720521E-7,-2.77480291837474E-5,-3.77973069647943E-7,300.002288818359,300.002288818359,19078.943359375,19129.03125,54.8015387403135,19.726009130617,47.0205841064453,0,0,0,40,300.448211669922,1,6,1,2.16400146484375,43.0107536315918,,,,,,,,,,,,,,,,
,3735618318.6615,300.000915527344,23299.8486328125,-4.25849747143276E-5,6.34862080070459E-7,1,0.999253354069792,40.0298881530762,1.99677091188405,14.5600000396371,-0.0004566503732615,-9.32224351099127E-5,0.25,-1.19221420488478E-6,-4.25829217466322E-5,-1.22034442249456E-6,300.000427246094,300.000427246094,23274.85546875,23324.841796875,54.7476063724866,19.7262602497461,46.9787559509277,0,0,0,40,300.450225830078,1,6,1,2.1649169921875,43.49951171875,,,,,,,,,,,,,,,,
,3735618402.798,300.001129150391,27512.92578125,-5.75092830956261E-5,6.02464368224533E-7,1,0.999253354069792,40.0298881530762,1.99669651929464,14.5600000396371,-0.000617987317268343,-0.000118344720803509,0.25,-9.09983571384575E-7,-5.75069767558406E-5,-9.47959746767564E-7,300.0009765625,300.0009765625,27500.337890625,27525.513671875,54.8906443915058,19.7241984521311,46.9342269897461,0,0,0,40,300.451293945313,1,6,1,2.16415405273438,43.9882698059082,,,,,,,,,,,,,,,,
,3735618486.6415,300.001205444336,31721.1103515625,-7.33294097201567E-5,6.10994257225374E-7,1,0.999253354069792,40.0298881530762,1.99672243424806,14.5600000396371,-0.000789571555614149,-0.000141918259693078,0.25,-3.26678183624144E-7,-7.33270237347697E-5,-3.75082167935935E-7,300.001251220703,300.001251220703,31701.025390625,31741.1953125,54.7671470854673,19.7257251818536,46.8926696777344,0,0,0,40,300.448364257812,1,6,1,2.16262817382813,43.49951171875,,,,,,,,,,,,,,,,
,3735618570.647,300.000671386719,35937.984375,-8.86018904986554E-5,7.41235611110843E-7,1,0.999253354069792,40.0298881530762,1.99676137975697,14.5600000396371,-0.000954263781098801,-0.000170173757546363,0.25,-2.73638086574644E-7,-8.85990941925541E-5,-3.32072756801367E-7,300.000518798828,300.000518798828,35922.90625,35953.0625,55.2040774277174,19.725213654643,46.8721580505371,0,0,0,40,300.450378417969,1,6,1,2.16476440429687,43.0107536315918,,,,,,,,,,,,,,,,
,3735618654.6125,300.002655029297,40153.93359375,-0.000104911861089127,6.92193710603705E-7,1,0.999253354069792,40.0298881530762,1.99672123530143,14.5600000396371,-0.0011286196853611,-0.000208831477225048,0.25,-1.00483144530636E-6,-0.000104908100239253,-1.07393657873992E-6,300.0029296875,300.0029296875,40133.8203125,40174.046875,54.7663654569481,19.7254468021806,46.8743171691895,0,0,0,40,300.445373535156,1,6,1,2.16583251953125,43.9882698059082,,,,,,,,,,,,,,,,
,3735618738.4195,300.001373291016,44360.138671875,-0.000118963396165,6.50037118357142E-7,1,0.999253354069792,40.0298881530762,1.99673964993103,14.5600000396371,-0.00128094050657165,-0.000230260491585481,0.25,-5.32281596679621E-7,-0.000118959544095896,-6.10585144668382E-7,300.001129150391,300.001129150391,44335.015625,44385.26171875,54.9977274986404,19.7266164272311,46.8667602539063,0,0,0,40,300.4453125,1,6,1,2.16506958007813,43.49951171875,,,,,,,,,,,,,,,,
,3735618822.28,300.002578735352,48568.865234375,-0.000135293463222432,8.81752770617074E-7,1,0.999253354069792,40.0298881530762,1.99666265693739,14.5600000396371,-0.00145667854657297,-0.000262103469358458,0.25,-6.28152812517701E-7,-0.000135289069940694,-7.17116385661655E-7,300.003112792969,300.003112792969,48546.27734375,48591.453125,54.5701766986212,19.7262621061151,46.827091217041,0,0,0,40,300.448791503906,1,6,1,2.16217041015625,43.0107536315918,,,,,,,,,,,,,,,,
,3735618906.2085,300.002258300781,52788.416015625,-0.000150681570948599,6.95276162392973E-7,1,0.999253354069792,40.0298881530762,1.99667808235865,14.5600000396371,-0.00162373285822966,-0.000284143285085552,0.25,2.17131898439107E-8,-0.000150677162919325,-7.72910081769028E-8,300.002349853516,300.002349853516,52763.08984375,52813.7421875,54.7077433180058,19.7245371283933,46.7704200744629,0,0,0,40,300.449401855469,1,6,1,2.16262817382813,43.0107536315918,,,,,,,,,,,,,,,,
,3735618990.3355,300.000091552734,57040.705078125,-0.000164436918129056,8.19947224014761E-7,1,0.999253354069792,40.0298881530762,1.99680608570608,14.5600000396371,-0.00177255286427124,-0.000307330521740229,0.25,2.80671672727606E-7,-0.000164432298622336,1.7273197848202E-7,300.000946044922,300.000946044922,57025.5390625,57055.87109375,54.9484849019289,19.7240178801704,46.7350692749023,0,0,0,40,300.449127197266,1,6,1,2.16140747070313,43.9882698059082,,,,,,,,,,,,,,,,
,3735619074.081,300.000030517578,61278.146484375,-0.000182517488612392,9.23154118294953E-7,1,0.999253354069792,40.0298881530762,1.99677195095095,14.5600000396371,-0.00196616529843145,-0.000348287474113806,0.25,-3.5396131860523E-7,-0.000182511936050282,-4.73625960207773E-7,299.999298095703,299.999298095703,61252.9453125,61303.34765625,54.8968974196597,19.7255427737111,46.7091598510742,0,0,0,40,300.447784423828,1,6,1,2.1478271484375,43.49951171875,,,,,,,,,,,,,,,,
,3735619158.023,300.000244140625,65526.23046875,-0.000197557289831578,9.64206106011699E-7,1,0.999253354069792,40.0298881530762,1.99669727573391,14.5600000396371,-0.00212771607169702,-0.000379198033464109,0.25,-5.89688157330581E-7,-0.000197551155362398,-7.1907103256917E-7,300.000701904297,300.000701904297,65500.9609375,65551.5,54.8124815395827,19.7246340128749,46.7007942199707,0,0,0,40,300.449127197266,1,6,1,2.15866088867187,42.0332374572754,,,,,,,,,,,,,,,,
,3735619242.1305,300.001129150391,69775.84375,-0.000213860334394845,9.54712299769503E-7,1,0.999253354069792,40.0298881530762,1.99670609225948,14.5600000396371,-0.00230536288236927,-0.000398780058231843,0.25,4.48408428862691E-7,-0.000213854411895593,3.08466534146732E-7,300.002380371094,300.002380371094,69758.09375,69793.59375,54.7819980273327,19.7247213695556,46.6873016357422,0,0,0,40,300.446502685547,1,6,1,2.16476440429687,43.9882698059082,,,,,,,,,,,,,,,,
,3735619325.8925,300.000595092773,74012.98046875,-0.00023040981635414,9.11454766664076E-7,1,0.999253354069792,40.0298881530762,1.99655870366191,14.5600000396371,-0.00248197427021588,-0.000438824490956977,0.25,-3.72283065393826E-7,-0.000230402894781583,-5.22867912416726E-7,300.000610351562,300.000610351562,73990.15625,74035.8046875,54.7343186876596,19.7248750308551,46.6816329956055,0,0,0,40,300.449615478516,1,6,1,2.16476440429687,43.49951171875,,,,,,,,,,,,,,,,
,3735619409.8275,300.001266479492,78256.27734375,-0.000246184392073343,1.00656415106411E-6,1,0.999253354069792,40.0298881530762,1.99670732467696,14.5600000396371,-0.0026511231858642,-0.000474397102302434,0.25,-9.07987810703541E-7,-0.000246176673569201,-1.06869217060688E-6,300.000915527344,300.000915527344,78233.53125,78279.0234375,54.7108698320827,19.7240091566298,46.682445526123,0,0,0,40,300.450103759766,1,6,1,2.16567993164062,43.49951171875,,,,,,,,,,,,,,,,
,3735619493.767,300.000762939453,82503.40234375,-0.000262082569642434,1.11548641956503E-6,1,0.999253354069792,40.0298881530762,1.99665225776457,14.5600000396371,-0.00282244203186932,-0.000503949103792441,0.25,-8.67459563296604E-7,-0.000262074439299075,-1.03835731803402E-6,300.001403808594,300.001403808594,82480.640625,82526.1640625,54.7608940573135,19.7273757530671,46.6535682678223,0,0,0,40,300.448181152344,1,6,1,2.1466064453125,43.49951171875,,,,,,,,,,,,,,,,
,3735619577.778,300.000534057617,86748.13671875,-0.000277622081287545,1.33161219042598E-6,1,0.999253354069792,40.0298881530762,1.99669939075653,14.5600000396371,-0.00299094697995092,-0.000527628113240753,0.25,-3.4248784262605E-7,-0.000277613865007141,-5.23334815101806E-7,300.000762939453,300.000762939453,86727.8125,86768.4609375,54.7100882035635,19.7283098500372,46.6276626586914,0,0,0,40,300.443908691406,1,6,1,2.16064453125,43.49951171875,,,,,,,,,,,,,,,,
,3735619645.652,300.000152587891,90001.2890625,-0.000292418963657456,1.1860889888386E-6,1,0.999253354069792,40.0298881530762,1.99679127352504,14.5600000396371,-0.0031520724121959,-0.00054678720899365,0.25,4.73070046992381E-7,-0.000292410870679645,2.82722897758563E-7,300.000335693359,300.000335693359,90000.578125,90002,54.6467762935058,19.7261161628762,46.6130905151367,0,0,0,40,300.447479248047,1,4,1,2.16537475585938,43.9882698059082,,,,,,,,,,,,,,,,