File: data/doubleLayers/monolayer/ppms/DD205_4/rawdata/DD205_4_HYST_100OE_5K.DAT
[Header]
; VSM Data File (default extension .dat)
; Copyright (c) 2003-2013, Quantum Design, Inc. All rights reserved.
TITLE,
FILEOPENTIME,3735571520.27299,05/15/2018,6:44 pm
BYAPP,VSM,1.0,1.0
INFO,DYNACOOL VSM Option Release 1.4.10 Build 1,APPNAME
INFO,Quantum Design Linear Motor Servo Controller,MOTOR_MODULE_NAME
INFO,3101-100 J0,MOTOR_HW_VERSION
INFO,MMC654,MOTOR_SERIAL_NUMBER
INFO,SRV No X-over 01.03.11,MOTOR_SOFTWARE_VERSION
INFO,Quantum Design VSM Detection Module,VSM_MODULE_NAME
INFO,3101-150 F0,VSM_HW_VERSION
INFO,VSM507,VSM_SERIAL_NUMBER
INFO,VSM No X-over 01.02.05 May 20 2008 13:51:47,VSM_SOFTWARE_VERSION
INFO,494,PREAMP_SERIAL_NUMBER
INFO,Quantum Design VSM Oven,OVEN_MODULE_NAME
INFO,3101-201 A1,OVEN_HW_VERSION
INFO,OVB210,OVEN_SERIAL_NUMBER
INFO,01.06.24,OVEN_SOFTWARE_VERSION
INFO,593,COIL_SERIAL_NUMBER
INFO,0,MOMENT_UNITS
INFO,,SAMPLE_MATERIAL
INFO,,SAMPLE_COMMENT
INFO,,SAMPLE_MASS
INFO,,SAMPLE_VOLUME
INFO,,SAMPLE_MOLECULAR_WEIGHT
INFO,,SAMPLE_SIZE
INFO,,SAMPLE_SHAPE
DATATYPE,COMMENT,1
DATATYPE,TIME,2
STARTUPAXIS,X,2
STARTUPAXIS,Y1,5
[Data]
Comment,Time Stamp (sec),Temperature (K),Magnetic Field (Oe),Moment (emu),M. Std. Err. (emu),Transport Action,Averaging Time (sec),Frequency (Hz),Peak Amplitude (mm),Center Position (mm),Coil Signal' (mV),Coil Signal" (mV),Range (mV),M. Quad. Signal (emu),M. Raw' (emu),M. Raw" (emu),Min. Temperature (K),Max. Temperature (K),Min. Field (Oe),Max. Field (Oe),Mass (grams),Motor Lag (deg),Pressure (Torr),VSM Status (code),Motor Status (code),Measure Status (code),Measure Count,System Temp. (K),Temp. Status (code),Field Status (code),Chamber Status (code),Motor Current (amps),Motor Heatsink Temp. (C),Map 01,Map 02,Map 03,Map 04,Map 05,Map 06,Map 07,Map 08,Map 09,Map 10,Map 11,Map 12,Map 13,Map 14,Map 15,Map 16
,3735571467.1485,5.00196194648743,-0.647239625453949,6.09662948275928E-6,3.60175941119526E-7,1,0.999253354069792,40.0298881530762,1.99541540204546,14.5600000396371,6.52240708256627E-5,1.16842785231163E-5,0.25,-1.91511897239352E-9,6.06047606111628E-6,2.74760872269254E-8,5.00184535980225,5.00184535980225,-0.689582407474518,-0.60489684343338,54.9594277011981,19.767852486329,6.32005214691162,0,0,0,40,4.99139928817749,1,4,1,2.15621948242187,43.9882698059082,,,,,,,,,,,,,,,,
,3735571558.084,4.99995470046997,4134.39868164063,6.0066335797029E-6,3.52502021340406E-7,1,0.999253354069792,40.0298881530762,1.9952828621399,14.5600000396371,6.65796116735957E-5,-1.32945370054315E-6,0.25,-1.20377048106296E-6,5.97841924801781E-6,-1.16646635374026E-6,4.9997181892395,4.9997181892395,4109.48779296875,4159.3095703125,54.9711521289866,19.7692967009468,6.25034809112549,0,0,0,40,4.9894552230835,1,6,1,2.15484619140625,44.4770278930664,,,,,,,,,,,,,,,,
,3735571642.2135,5.00042343139648,8343.7685546875,1.85008678645505E-6,2.25683172717419E-7,1,0.999253354069792,40.0298881530762,1.99541700753839,14.5600000396371,2.20789377902068E-5,-9.09214644436406E-6,0.25,-1.18262688306268E-6,1.84642460404251E-6,-1.16629014015946E-6,5.00042343139648,5.00042343139648,8328.7099609375,8358.8271484375,54.9539563015635,19.765480797034,6.20178842544556,0,0,0,40,4.98791074752808,1,6,1,2.1685791015625,44.4770278930664,,,,,,,,,,,,,,,,
,3735571726.0195,5.00122618675232,12533.8916015625,-1.36049129809939E-6,3.80695951419407E-7,1,0.999253354069792,40.0298881530762,1.9955566999395,14.5600000396371,-9.63082364465717E-6,-2.99889602320389E-5,0.25,-2.5557249099304E-6,-1.33907923039665E-6,-2.55049343800596E-6,5.00118494033814,5.00118494033814,12513.8974609375,12553.8857421875,54.8015387403135,19.7640413730632,6.1274938583374,0,0,0,40,4.98971509933472,1,6,1,2.1527099609375,43.9882698059082,,,,,,,,,,,,,,,,
,3735571809.8815,4.99977469444275,16723.556640625,-3.58156449023244E-6,4.76837201074476E-7,1,0.999253354069792,40.0298881530762,1.99548636259253,14.5600000396371,-3.54708423100331E-5,-2.28995165913338E-5,0.25,-1.49124243819154E-6,-3.55583691732168E-6,-1.5056474789171E-6,4.99950885772705,4.99950885772705,16698.568359375,16748.544921875,54.9391053596981,19.7629048586998,6.06787586212158,0,0,0,40,4.98825120925903,1,6,1,2.15484619140625,44.4770278930664,,,,,,,,,,,,,,,,
,3735571893.829,4.99975657463074,20923.873046875,-5.03494098400588E-6,7.07273314291334E-7,1,0.999253354069792,40.0298881530762,1.99538560030391,14.5600000396371,-5.08467097901552E-5,-2.68393795322735E-5,0.25,-1.59435774413545E-6,-5.00335409074179E-6,-1.61900708453483E-6,4.99982500076294,4.99982500076294,20898.865234375,20948.880859375,54.6452130364673,19.7641553600813,6.04438018798828,0,0,0,40,4.98592042922974,1,6,1,2.1539306640625,44.4770278930664,,,,,,,,,,,,,,,,
,3735571977.7575,5.00028705596924,25119.3369140625,-5.81767790947527E-6,1.10073517219173E-6,1,0.999253354069792,40.0298881530762,1.99537543810793,14.5600000396371,-6.08068708273828E-5,-1.97892180828354E-5,0.25,-7.9241004862645E-7,-5.78999543947453E-6,-8.27197888677965E-7,5.00034618377686,5.00034618377686,25094.30859375,25144.365234375,55.3236665911597,19.7640619771433,6.01165246963501,0,0,0,40,4.9896502494812,1,6,1,2.15179443359375,44.4770278930664,,,,,,,,,,,,,,,,
,3735572061.689,5.00014805793762,29328.9736328125,-8.55585169198313E-6,1.04163356711812E-6,1,0.999253354069792,40.0298881530762,1.99541344673269,14.5600000396371,-8.757878272628E-5,-3.95101379265937E-5,0.25,-2.13297391053914E-6,-8.51209497032593E-6,-2.18322932678077E-6,4.99991178512573,4.99991178512573,29306.365234375,29351.58203125,54.8937709055827,19.7636880194155,4.98265266418457,0,0,0,40,4.98908805847168,1,6,1,2.15591430664062,43.9882698059082,,,,,,,,,,,,,,,,
,3735572145.7395,5.00005006790161,33550.384765625,-1.36278572490631E-5,1.49138992660769E-6,1,0.999253354069792,40.0298881530762,1.99540782370627,14.5600000396371,-0.000139908255089737,-6.09955395847393E-5,0.25,-3.21177404724509E-6,-1.35648560538755E-5,-3.29651198835903E-6,4.999671459198,4.999671459198,33532.78515625,33567.984375,55.0016356412366,19.761416420519,4.95632839202881,0,0,0,40,4.98934364318848,1,6,1,2.15560913085938,44.4770278930664,,,,,,,,,,,,,,,,
,3735572229.571,4.99875068664551,37759.625,-1.46831458804194E-5,1.43439345643136E-6,1,0.999253354069792,40.0298881530762,1.99564580396075,14.5600000396371,-0.000154282062677163,-4.67170538918834E-5,0.25,-1.68412213987814E-6,-1.46338534112233E-5,-1.78383668170213E-6,4.99891519546509,4.99891519546509,37734.5703125,37784.6796875,54.9133116185635,19.7585490211928,4.93130779266357,0,0,0,40,4.99131059646606,1,6,1,2.15484619140625,43.9882698059082,,,,,,,,,,,,,,,,
,3735572313.5455,5.00042247772217,41975.3359375,-2.56075244747046E-5,1.78146898555906E-6,1,0.999253354069792,40.0298881530762,1.9954915592785,14.5600000396371,-0.000266009798828929,-9.88537306544974E-5,0.25,-4.55002767663704E-6,-2.55209685729714E-5,-4.72514920944062E-6,5.00023555755615,5.00023555755615,41950.2890625,42000.3828125,54.7749633706596,19.761143671952,4.90686559677124,0,0,0,40,4.99215126037598,1,6,1,2.15362548828125,44.4770278930664,,,,,,,,,,,,,,,,
,3735572397.4845,4.99932098388672,46186.7109375,-3.60330511457015E-5,1.73548609296679E-6,1,0.999253354069792,40.0298881530762,1.99556159683846,14.5600000396371,-0.000379724982942772,-0.000110354922772423,0.25,-3.71653443321506E-6,-3.59461233172627E-5,-3.97376139743112E-6,4.99922227859497,4.99922227859497,46161.57421875,46211.84765625,54.9375421026597,19.7600393798911,4.8849720954895,0,0,0,40,4.99560308456421,1,6,1,2.15591430664062,45.4545478820801,,,,,,,,,,,,,,,,
,3735572481.557,4.99960279464722,50407.984375,-4.53697769052213E-5,1.85030624536252E-6,1,0.999253354069792,40.0298881530762,1.99557627152999,14.5600000396371,-0.000486676558759376,-9.31453351876334E-5,0.25,-4.07829970339386E-7,-4.53111510552924E-5,-7.42128468636379E-7,4.99911832809448,4.99911832809448,50387.87109375,50428.09765625,54.864069021852,19.76102998542,4.86444520950317,0,0,0,40,4.9966835975647,1,6,1,2.154541015625,44.4770278930664,,,,,,,,,,,,,,,,
,3735572565.309,4.99975776672363,54630.505859375,-4.84430881353973E-5,2.49911609119304E-6,1,0.999253354069792,40.0298881530762,1.99549408380127,14.5600000396371,-0.000506404276050934,-0.000173277060851255,0.25,-7.29810589479315E-6,-4.83499543645922E-5,-7.65179566490469E-6,4.99999713897705,4.99999713897705,54607.76171875,54653.25,55.0391538101597,19.7595737377216,4.84357929229736,0,0,0,40,5.0014820098877,1,6,1,2.15530395507813,44.4770278930664,,,,,,,,,,,,,,,,
,3735572649.302,4.99939823150635,58875.470703125,-5.9372024655349E-5,2.69148836531767E-6,1,0.999253354069792,40.0298881530762,1.9953556342272,14.5600000396371,-0.000624145806580359,-0.000194420773304123,0.25,-7.26761044056801E-6,-5.92945461137068E-5,-7.70653494863412E-6,4.99963092803955,4.99963092803955,58850.3046875,58900.63671875,55.3181951915251,19.7611327921702,4.82649993896484,0,0,0,40,5.00348711013794,1,6,1,2.13653564453125,43.9882698059082,,,,,,,,,,,,,,,,
,3735572733.3295,5.00002527236938,63125.580078125,-7.9559767881938E-5,2.41232577593768E-6,1,0.999253354069792,40.0298881530762,1.9953955537716,14.5600000396371,-0.000833142631168357,-0.000280255161262849,0.25,-1.15631559210167E-5,-7.94738752609223E-5,-1.21549080245008E-5,4.99966096878052,4.99966096878052,63107.92578125,63143.234375,55.1642143732366,19.7610938046279,4.80864715576172,0,0,0,40,5.00826978683472,1,6,1,2.15255737304687,43.9882698059082,,,,,,,,,,,,,,,,
,3735572817.3745,4.9998095035553,67375.8515625,-9.03314859110673E-5,2.22278694347185E-6,1,0.999253354069792,40.0298881530762,1.99540468833174,14.5600000396371,-0.000952101714885897,-0.000286515323664355,0.25,-1.01752646981412E-5,-9.02904147853922E-5,-1.08489078466179E-5,4.99920177459717,4.99920177459717,67360.6484375,67391.0546875,54.9500481589674,19.7597484025087,4.7926082611084,0,0,0,40,5.01037883758545,1,6,1,2.13821411132813,43.9882698059082,,,,,,,,,,,,,,,,
,3735572901.1195,4.99928164482117,71612.7109375,-9.55312501155335E-5,2.37528192686384E-6,1,0.999253354069792,40.0298881530762,1.99568149995379,14.5600000396371,-0.00102396678477518,-0.000212212556714459,0.25,-2.31775283148752E-6,-9.5584991920581E-5,-3.02396697551235E-6,4.99997997283936,4.99997997283936,71587.3671875,71638.0546875,54.9133116185635,19.7539097944355,4.77649545669556,0,0,0,40,5.01326417922974,1,6,1,2.15240478515625,44.4770278930664,,,,,,,,,,,,,,,,
,3735572985.035,4.999840259552,75855.36328125,-0.000110616566784447,3.14369643481264E-6,1,0.999253354069792,40.0298881530762,1.99541638693368,14.5600000396371,-0.00117785050050721,-0.000290112823761023,0.25,-6.80725176218991E-6,-0.000110686816165924,-7.62430358899244E-6,4.999915599823,4.999915599823,75830.078125,75880.6484375,54.7421349728519,19.7555396924351,4.76279067993164,0,0,0,40,5.01995086669922,1,6,1,2.1563720703125,43.9882698059082,,,,,,,,,,,,,,,,
,3735573068.9345,5.00057196617126,80098.47265625,-0.000110830941970617,3.76781477362925E-6,1,0.999253354069792,40.0298881530762,1.99581917512355,14.5600000396371,-0.00116875420414922,-0.000356756352616598,0.25,-1.29473302062272E-5,-0.000110893551980306,-1.37693476585746E-5,5.00087547302246,5.00087547302246,80073.21875,80123.7265625,54.6178560382942,19.7541522031064,4.74753904342651,0,0,0,40,5.02228260040283,1,6,1,2.1527099609375,44.4770278930664,,,,,,,,,,,,,,,,
,3735573152.892,4.99948740005493,84345.52734375,-0.000122541704268768,2.80764698790709E-6,1,0.999253354069792,40.0298881530762,1.99576568245263,14.5600000396371,-0.00129331439971472,-0.000390785030332235,0.25,-1.39744074559648E-5,-0.000122652426765397,-1.48775177721077E-5,4.99919652938843,4.99919652938843,84320.1875,84370.8671875,54.6076948675442,19.7509692205241,4.73402118682861,0,0,0,40,5.02392864227295,1,6,1,2.15301513671875,44.4770278930664,,,,,,,,,,,,,,,,
,3735573236.8325,4.99976110458374,88590.50390625,-0.000148405136891943,2.59086518676076E-6,1,0.999253354069792,40.0298881530762,1.99553168634219,14.5600000396371,-0.00158310953132761,-0.000382392775362138,0.25,-8.49909228220468E-6,-0.000148643790166081,-9.56784285021018E-6,4.99952411651611,4.99952411651611,88562.625,88618.3828125,55.1579613450827,19.7518359490872,4.72343063354492,0,0,0,40,5.02802753448486,1,6,1,2.13790893554687,45.9433059692383,,,,,,,,,,,,,,,,
,3735573329.932,5.00028657913208,87328.76171875,-0.000144042846970505,2.71595800889318E-6,1,0.999253354069792,40.0298881530762,1.99538710507939,14.5600000396371,-0.00153664154917106,-0.000369416097985904,0.25,-8.08955402019599E-6,-0.000144263136018943,-9.12973390344964E-6,4.99966049194336,4.99966049194336,87311.265625,87346.2578125,55.013360069025,19.7553961240907,4.71150302886963,0,0,0,40,5.02847051620483,1,6,1,2.15530395507813,44.4770278930664,,,,,,,,,,,,,,,,
,3735573413.669,5.00082564353943,83155.91796875,-0.000121764404320198,3.09739221990561E-6,1,0.999253354069792,40.0298881530762,1.99536404079946,14.5600000396371,-0.00129541163476548,-0.000329592649097236,0.25,-8.44363271453035E-6,-0.000121902924687022,-9.33372033099866E-6,5.00058698654175,5.00058698654175,83130.9765625,83180.859375,55.1556164595251,19.7553648317482,4.69886302947998,0,0,0,40,5.02670192718506,1,6,1,2.15362548828125,43.9882698059082,,,,,,,,,,,,,,,,
,3735573497.785,5.00036072731018,78966.09765625,-0.000116421867162113,2.23855541844751E-6,1,0.999253354069792,40.0298881530762,1.99554631164823,14.5600000396371,-0.0012538732244668,-0.000229430909749173,0.25,-1.14986537643795E-7,-0.000116575480669252,-9.6165117080857E-7,5.0003137588501,5.0003137588501,78951.1875,78981.0078125,54.6741332916789,19.7539471962958,4.68391752243042,0,0,0,40,5.01866722106934,1,6,1,2.13699340820313,44.4770278930664,,,,,,,,,,,,,,,,
,3735573581.612,5.00038290023804,74788.10546875,-0.000100114098759189,2.32827150399973E-6,1,0.999253354069792,40.0298881530762,1.99550369002299,14.5600000396371,-0.00107562416001879,-0.000209534183363925,0.25,-1.23536952739306E-6,-0.000100205213343264,-1.97090673018453E-6,5.00051498413086,5.00051498413086,74765.796875,74810.4140625,54.9781867856597,19.7551067618297,4.6710729598999,0,0,0,40,5.01812171936035,1,6,1,2.15225219726562,44.4770278930664,,,,,,,,,,,,,,,,
,3735573665.6085,4.99970388412476,70602.58984375,-8.73351554898562E-5,2.16804992344878E-6,1,0.999253354069792,40.0298881530762,1.99544240593587,14.5600000396371,-0.000941133287246397,-0.000165389382669475,0.25,5.37049744512011E-7,-8.7396500218698E-5,-1.07610184827849E-7,4.99987173080444,4.99987173080444,70585.1640625,70620.015625,55.1188799191212,19.7530728580719,4.65891408920288,0,0,0,40,5.01169967651367,1,6,1,2.15087890625,44.4770278930664,,,,,,,,,,,,,,,,
,3735573749.55,5.00029730796814,66420.46875,-8.3884648115502E-5,2.71801346996896E-6,1,0.999253354069792,40.0298881530762,1.99569841858651,14.5600000396371,-0.000909810850836572,-0.000125458505870329,0.25,3.61891320824394E-6,-8.39364004704343E-5,2.9974495166276E-6,4.99987268447876,4.99987268447876,66400.5234375,66440.4140625,54.9133116185635,19.7530953498034,4.64360427856445,0,0,0,40,5.00769376754761,1,6,1,2.15164184570313,43.9882698059082,,,,,,,,,,,,,,,,
,3735573833.3575,5.00044083595276,62245.134765625,-7.73721898311568E-5,2.75228125679694E-6,1,0.999253354069792,40.0298881530762,1.99570779361502,14.5600000396371,-0.000830541461977196,-0.000161379562961854,0.25,-9.08995692804659E-7,-7.73592959716556E-5,-1.48457500853134E-6,5.00040292739868,5.00040292739868,62220.17578125,62270.09375,55.087614778352,19.7520423243221,4.63135433197022,0,0,0,40,5.00516319274902,1,6,1,2.15118408203125,44.4770278930664,,,,,,,,,,,,,,,,
,3735573917.3125,4.99915719032288,58061.939453125,-5.29600762979797E-5,2.79274095047489E-6,1,0.999253354069792,40.0298881530762,1.99574958644567,14.5600000396371,-0.000576091167684631,-6.75423467984064E-5,0.25,3.36534955589588E-6,-5.29601354219391E-5,2.96978024058545E-6,4.99905061721802,4.99905061721802,58039.48828125,58084.390625,54.9031504478135,19.7510696865483,4.62109422683716,0,0,0,40,5.00134944915771,1,6,1,2.15225219726562,43.9882698059082,,,,,,,,,,,,,,,,
,3735574001.2715,5.00073337554932,53879.900390625,-4.84059665831731E-5,2.52010912491421E-6,1,0.999253354069792,40.0298881530762,1.99581599184198,14.5600000396371,-0.000521892173899275,-8.62095393224092E-5,0.25,7.95938076136479E-7,-4.836935253403E-5,4.36235077217675E-7,5.00082349777222,5.00082349777222,53859.96875,53899.83203125,54.6624088638904,19.7513560501642,4.6100640296936,0,0,0,40,5.00009298324585,1,6,1,2.15103149414062,44.4770278930664,,,,,,,,,,,,,,,,
,3735574085.171,4.99995231628418,49697.970703125,-4.1615738931914E-5,2.34187269985889E-6,1,0.999253354069792,40.0298881530762,1.99580260367484,14.5600000396371,-0.000443886058239336,-9.93763740862221E-5,0.25,-1.67137938768396E-6,-4.15494087490263E-5,-1.9758990259313E-6,4.99982023239136,4.99982023239136,49675.546875,49720.39453125,54.7757449991789,19.7516831387905,4.59951639175415,0,0,0,40,4.99473762512207,1,6,1,2.16445922851562,43.9882698059082,,,,,,,,,,,,,,,,
,3735574169.2075,4.99959874153137,45509.896484375,-2.56586122145699E-5,1.60568404605803E-6,1,0.999253354069792,40.0298881530762,1.995792332792,14.5600000396371,-0.000279542869942966,-2.8393642983259E-5,0.25,2.02636847467482E-6,-2.56290389652233E-5,1.83566235266531E-6,4.99946308135986,4.99946308135986,45489.96484375,45529.828125,55.0274293823712,19.7557325546293,4.58932304382324,0,0,0,40,4.99104785919189,1,6,1,2.15103149414062,44.4770278930664,,,,,,,,,,,,,,,,
,3735574253.273,5.00064611434937,41320.3671875,-2.45036370088789E-5,1.80916921362032E-6,1,0.999253354069792,40.0298881530762,1.99575917471676,14.5600000396371,-0.000263072259921655,-4.77931258704783E-5,0.25,5.46263056932184E-9,-2.44505585786746E-5,-1.70819350100179E-7,5.00064611434937,5.00064611434937,41305.39453125,41335.33984375,54.925036046352,19.7548235266115,4.57932806015015,0,0,0,40,4.98900699615479,1,6,1,2.16934204101562,44.9657897949219,,,,,,,,,,,,,,,,
,3735574336.9675,4.9999852180481,37152.8984375,-2.05529830283772E-5,1.74124516211981E-6,1,0.999253354069792,40.0298881530762,1.9958386442273,14.5600000396371,-0.00022104118189722,-3.74702849039974E-5,0.25,2.44305893530677E-7,-2.05010839316806E-5,9.85261294710286E-8,5.00022172927856,5.00022172927856,37130.234375,37175.5625,54.6287988375635,19.7537442247171,4.56987619400024,0,0,0,40,4.98692798614502,1,6,1,2.149658203125,44.4770278930664,,,,,,,,,,,,,,,,
,3735574421.0355,4.99995279312134,32962.759765625,-6.13451202794276E-6,1.73571434636818E-6,1,0.999253354069792,40.0298881530762,1.99576887119606,14.5600000396371,-6.52200961803551E-5,-1.51593944426707E-5,0.25,-2.99192274772458E-7,-6.11371576221395E-6,-3.40595263340264E-7,4.99976396560669,4.99976396560669,32945.35546875,32980.1640625,54.8750118211212,19.7566617352524,4.5614185333252,0,0,0,40,4.98732995986938,1,6,1,2.15194702148438,44.9657897949219,,,,,,,,,,,,,,,,
,3735574504.938,5.00032687187195,28782.623046875,5.00223275773965E-6,1.51260447638936E-6,1,0.999253354069792,40.0298881530762,1.99570371621155,14.5600000396371,5.610295037304E-5,-3.88185297146976E-6,0.25,-1.2694759732872E-6,4.99326732618355E-6,-1.23150997528237E-6,5.00009155273438,5.00009155273438,28760.259765625,28804.986328125,54.6295804660827,19.7593609576746,4.55220127105713,0,0,0,40,4.9842267036438,1,6,1,2.15179443359375,44.4770278930664,,,,,,,,,,,,,,,,
,3735574588.8915,4.99928593635559,24600.9013671875,6.26544642097785E-6,1.37702005534521E-6,1,0.999253354069792,40.0298881530762,1.99583670402888,14.5600000396371,7.00797837002513E-5,-3.97262112193789E-6,0.25,-1.50576932668044E-6,6.25060895788522E-6,-1.45927517332438E-6,4.99942588806152,4.99942588806152,24580.96484375,24620.837890625,54.779653141775,19.7568695670799,4.54372024536133,0,0,0,40,4.98561477661133,1,6,1,2.15301513671875,44.4770278930664,,,,,,,,,,,,,,,,
,3735574672.8405,5.00017404556274,20416.328125,1.62108231713899E-5,9.82906568118631E-7,1,0.999253354069792,40.0298881530762,1.99574144494534,14.5600000396371,0.000175601008838797,2.08107901648385E-5,0.25,-9.9033114606829E-7,1.6146589317863E-5,-8.85155775152301E-7,4.99965000152588,4.99965000152588,20396.412109375,20436.244140625,54.6491211790635,19.7574663675268,4.53682565689087,0,0,0,40,4.98436689376831,1,6,1,2.13653564453125,44.4770278930664,,,,,,,,,,,,,,,,
,3735574756.681,5.00070548057556,16241.6953125,2.17747476125689E-5,9.61890503141192E-7,1,0.999253354069792,40.0298881530762,1.99565674252085,14.5600000396371,0.000229936130569828,6.02021651836402E-5,0.25,1.6881878307782E-6,2.16615145514461E-5,1.80960306163921E-6,5.00099229812622,5.00099229812622,16216.783203125,16266.607421875,54.5647052989865,19.7573579564769,4.53087615966797,0,0,0,40,4.98651838302612,1,6,1,2.1527099609375,44.4770278930664,,,,,,,,,,,,,,,,
,3735574840.5945,4.99967455863953,12060.4916992187,2.71930812256894E-5,6.92760279587886E-7,1,0.999253354069792,40.0298881530762,1.99578621858513,14.5600000396371,0.000289671106298618,6.07312075574905E-5,0.25,7.68740822546809E-7,2.70497689306376E-5,9.18305101189268E-7,4.99964380264282,4.99964380264282,12035.4921875,12085.4912109375,54.8953341626212,19.7575319542134,4.52438020706177,0,0,0,40,4.98417186737061,1,6,1,2.15179443359375,44.9657897949219,,,,,,,,,,,,,,,,
,3735574924.528,5.00014162063599,7868.69995117187,3.1880660911719E-5,4.94864969726404E-7,1,0.999253354069792,40.0298881530762,1.99581528400384,14.5600000396371,0.000341837671497722,5.81717832200963E-5,0.25,-3.03907116819567E-7,3.17085727795044E-5,-1.3215497326019E-7,5.0004734992981,5.0004734992981,7843.7451171875,7893.65478515625,54.6225458094096,19.7591867773436,4.51854705810547,0,0,0,40,4.98540067672729,1,6,1,2.15240478515625,44.4770278930664,,,,,,,,,,,,,,,,
,3735575008.5515,5.00033092498779,3673.77404785156,3.58181385354106E-5,2.8149903581184E-7,1,0.999253354069792,40.0298881530762,1.99596360736669,14.5600000396371,0.000385380470641208,5.74875450792502E-5,0.25,-1.06449477639536E-6,3.56178375846052E-5,-8.78078349991615E-7,5.00015640258789,5.00015640258789,3653.78759765625,3693.76049804687,54.8328038810827,19.7573846238547,4.51324701309204,0,0,0,40,4.98595762252808,1,6,1,2.152099609375,44.9657897949219,,,,,,,,,,,,,,,,
,3735575098.399,5.00039744377136,-819.702484130859,3.68756320140795E-5,2.48765341704669E-7,1,0.999253354069792,40.0298881530762,1.99572516633695,14.5600000396371,0.000396284120808625,6.11928447154201E-5,0.25,-9.00101214400706E-7,3.66624140057208E-5,-7.15749349210196E-7,4.999924659729,4.999924659729,-844.647888183594,-794.757080078125,54.8156080536596,19.759354298161,4.50842952728271,0,0,0,40,4.98583793640137,1,6,1,2.15103149414062,44.4770278930664,,,,,,,,,,,,,,,,
,3735575185.4055,4.9996931552887,-5168.43041992188,3.90742114335344E-5,3.54189515979886E-7,1,0.999253354069792,40.0298881530762,1.99574921317557,14.5600000396371,0.000419757609367186,6.63633341225982E-5,0.25,-8.2432220942771E-7,3.88579255097352E-5,-6.18880811364609E-7,5.00024509429932,5.00024509429932,-5188.46240234375,-5148.3984375,54.8288957384866,19.7595754131603,4.50276613235474,0,0,0,40,4.98186206817627,1,6,1,2.15255737304687,44.4770278930664,,,,,,,,,,,,,,,,
,3735575272.257,5.00064659118652,-9511.509765625,4.21543980843646E-5,6.3351018785305E-7,1,0.999253354069792,40.0298881530762,1.99570367332424,14.5600000396371,0.000453514455680189,6.86929128967861E-5,0.25,-1.17588322245826E-6,4.19365171873785E-5,-9.39596024680724E-7,5.00088357925415,5.00088357925415,-9534.0048828125,-9489.0146484375,55.148581802852,19.7564012638534,4.49737215042114,0,0,0,40,4.98468732833862,1,6,1,2.15469360351562,44.9657897949219,,,,,,,,,,,,,,,,
,3735575356.206,5.00021243095398,-13708.8544921875,4.22331879910681E-5,9.37013471928843E-7,1,0.999253354069792,40.0298881530762,1.99558101668169,14.5600000396371,0.000456403336993075,5.83024375570387E-5,0.25,-2.17543155124256E-6,4.20359192007756E-5,-1.92118572547188E-6,5.0003776550293,5.0003776550293,-13733.796875,-13683.912109375,54.7851245414096,19.7601336628148,4.49273014068604,0,0,0,40,4.98486661911011,1,6,1,2.15194702148438,44.4770278930664,,,,,,,,,,,,,,,,
,3735575440.282,4.99930620193481,-17913.345703125,3.93117179477558E-5,7.8296017397247E-7,1,0.999253354069792,40.0298881530762,1.99568564435843,14.5600000396371,0.000427041254681824,4.31347738679896E-5,0.25,-3.07830190896507E-6,3.91501898540487E-5,-2.82604568378855E-6,4.99911069869995,4.99911069869995,-17933.40234375,-17893.2890625,54.874230192602,19.7598400826709,4.48730897903442,0,0,0,40,4.98272800445557,1,6,1,2.15286254882813,44.9657897949219,,,,,,,,,,,,,,,,
,3735575524.082,4.99981284141541,-22103.08203125,3.08645537214406E-5,1.13752164883622E-6,1,0.999253354069792,40.0298881530762,1.9956736854339,14.5600000396371,0.000334566219318376,3.86133783790081E-5,0.25,-1.98351830875247E-6,3.07482088822808E-5,-1.77990329547015E-6,5.00016689300537,5.00016689300537,-22128.150390625,-22078.013671875,54.9070585904097,19.7615871860692,4.48247146606445,0,0,0,40,4.98267412185669,1,6,1,2.15057373046875,43.9882698059082,,,,,,,,,,,,,,,,
,3735575608.0335,4.99969506263733,-26301.3447265625,2.64649952324291E-5,1.41989957483145E-6,1,0.999253354069792,40.0298881530762,1.99571491948569,14.5600000396371,0.000287076437412462,3.27521864338797E-5,0.25,-1.74196706566176E-6,2.63771799053726E-5,-1.56148161710061E-6,4.99917078018188,4.99917078018188,-26323.921875,-26278.767578125,54.3997816814288,19.7608636872485,4.47883462905884,0,0,0,40,4.98637723922729,1,6,1,2.1551513671875,44.4770278930664,,,,,,,,,,,,,,,,
,3735575692.1135,4.9991819858551,-30521.451171875,1.68624418581463E-5,1.32200281352518E-6,1,0.999253354069792,40.0298881530762,1.99575836607646,14.5600000396371,0.00018489099202285,1.04647360533617E-5,0.25,-2.08457182455862E-6,1.6820756701262E-5,-1.96320520717957E-6,4.99939060211182,4.99939060211182,-30539.048828125,-30503.853515625,54.9672439863904,19.761481089811,4.47430992126465,0,0,0,40,4.98425817489624,1,6,1,2.15133666992187,44.4770278930664,,,,,,,,,,,,,,,,
,3735575776.0805,5.00042629241943,-34733.71875,1.88717515623773E-5,1.48787581843482E-6,1,0.999253354069792,40.0298881530762,1.99572249686308,14.5600000396371,0.000209521780302438,-2.07433646356105E-6,0.25,-3.62193476179326E-6,1.88429161374859E-5,-3.47999608443556E-6,5.00068378448486,5.00068378448486,-34748.79296875,-34718.64453125,54.7648021999096,19.7586145222489,4.47005605697632,0,0,0,40,4.98764085769653,1,6,1,2.1533203125,44.4770278930664,,,,,,,,,,,,,,,,
,3735575859.985,4.99950170516968,-38944.005859375,2.83734040871589E-5,1.70098264808773E-6,1,0.999253354069792,40.0298881530762,1.9957907598095,14.5600000396371,0.000305273885674756,5.13245552264909E-5,0.25,-3.77322409035115E-7,2.83074542891122E-5,-1.74327245373035E-7,4.99967098236084,4.99967098236084,-38964.2265625,-38923.78515625,55.0274293823712,19.7604560633049,4.46856212615967,0,0,0,40,4.99033832550049,1,6,1,2.152099609375,43.9882698059082,,,,,,,,,,,,,,,,
,3735575943.7925,5.00070571899414,-43148.892578125,2.43125634067367E-5,2.7157670382E-6,1,0.999253354069792,40.0298881530762,1.99591812078095,14.5600000396371,0.00026541015527406,2.36956760983468E-5,0.25,-2.21708724124821E-6,2.42805931447888E-5,-2.03663829247443E-6,5.00050163269043,5.00050163269043,-43173.87890625,-43123.90625,55.3361726474674,19.7578390856096,4.46468019485474,0,0,0,40,4.98878622055054,1,6,1,2.15072631835938,44.4770278930664,,,,,,,,,,,,,,,,
,3735576027.6975,4.9993941783905,-47358.443359375,2.81830854987529E-5,1.89564518173974E-6,1,0.999253354069792,40.0298881530762,1.99582462194937,14.5600000396371,0.000317758977842865,-2.72996924606799E-5,0.25,-7.67177745685125E-6,2.81960043340318E-5,-7.4533491804671E-6,4.99948930740356,4.99948930740356,-47383.4921875,-47333.39453125,54.9789684141789,19.759123208179,4.46062660217285,0,0,0,40,4.99322414398193,1,6,1,2.152099609375,44.4770278930664,,,,,,,,,,,,,,,,
,3735576111.7315,4.99920558929443,-51576.615234375,5.23177143832526E-5,3.38595631589416E-6,1,0.999253354069792,40.0298881530762,1.99578056441829,14.5600000396371,0.000561517960029574,0.000106385063712854,0.25,3.72083124752122E-7,5.2256997358696E-5,7.58497416216312E-7,4.9989275932312,4.9989275932312,-51594.0546875,-51559.17578125,55.0782352361212,19.7590339090412,4.45889711380005,0,0,0,40,4.99559783935547,1,6,1,2.15255737304687,44.4770278930664,,,,,,,,,,,,,,,,
,3735576195.5625,4.99942231178284,-55812.0078125,5.8143817095595E-5,2.38945151472699E-6,1,0.999253354069792,40.0298881530762,1.99563609504837,14.5600000396371,0.000620158654243384,0.000140833138647341,0.25,2.51006933815616E-6,5.80851223107408E-5,2.94034261385821E-6,4.99955558776855,4.99955558776855,-55837.1796875,-55786.8359375,55.199387656602,19.7614985065419,4.45765781402588,0,0,0,40,4.99679946899414,1,6,1,2.15316772460938,38.6119270324707,,,,,,,,,,,,,,,,
,3735576279.496,4.99891352653503,-60058.1015625,7.10860522202993E-5,2.34553805263638E-6,1,0.999253354069792,40.0298881530762,1.995990397345,14.5600000396371,0.00073892103712406,0.000280516231061268,0.25,1.31303754387544E-5,7.09682524871156E-5,1.36557027606926E-5,4.99891805648804,4.99891805648804,-60083.37890625,-60032.82421875,55.0735454650058,19.7528743513309,4.45652675628662,0,0,0,40,5.00150060653687,1,6,1,2.15316772460938,44.9657897949219,,,,,,,,,,,,,,,,
,3735576363.578,4.99932909011841,-64307.47265625,5.9792149940719E-5,2.46932784550443E-6,1,0.999253354069792,40.0298881530762,1.99579262645447,14.5600000396371,0.000661818594357644,1.5802468756466E-5,0.25,-9.42151470713384E-6,5.9868668083595E-5,-8.9780965084544E-6,4.99935483932495,4.99935483932495,-64325.2265625,-64289.71875,55.1431104032174,19.7546422709079,4.45586109161377,0,0,0,40,5.00498247146606,1,6,1,2.14996337890625,43.9882698059082,,,,,,,,,,,,,,,,
,3735576447.5125,4.99955272674561,-68551.48828125,8.98128602864094E-5,2.51992996694904E-6,1,0.999253354069792,40.0298881530762,1.99590981080801,14.5600000396371,0.000986842625777555,6.59591018916806E-5,0.25,-1.022764906722E-5,8.99319237871273E-5,-9.5675115134738E-6,4.99907445907593,4.99907445907593,-68571.671875,-68531.3046875,54.769491971025,19.7556867325727,4.45617580413818,0,0,0,40,5.00956678390503,1,6,1,2.15072631835938,44.4770278930664,,,,,,,,,,,,,,,,
,3735576531.472,5.00012993812561,-72795.375,9.05272515810153E-5,4.39696871372179E-6,1,0.999253354069792,40.0298881530762,1.9958384608087,14.5600000396371,0.000967370404384179,0.000218311734441501,0.25,3.79315547728326E-6,9.0575296393096E-5,4.4626713561124E-6,4.99970293045044,4.99970293045044,-72818.1171875,-72772.6328125,55.0579128946212,19.7545497158559,4.45526599884033,0,0,0,40,5.01531553268433,1,6,1,2.1514892578125,44.4770278930664,,,,,,,,,,,,,,,,
,3735576615.2465,4.99958968162537,-77030.96484375,0.000102197623093372,3.44942876724665E-6,1,0.999253354069792,40.0298881530762,1.9958433683217,14.5600000396371,0.00111328171689636,0.00013209494066327,0.25,-6.33602663323379E-6,0.000102364250937594,-5.59724372039036E-6,4.99867630004883,4.99867630004883,-77053.6875,-77008.2421875,55.1376390035828,19.7566226756673,4.45354270935059,0,0,0,40,5.01595211029053,1,6,1,2.15011596679687,44.4770278930664,,,,,,,,,,,,,,,,
,3735576699.196,4.99924898147583,-81274.50390625,0.000114300147503594,4.29936833131274E-6,1,0.999253354069792,40.0298881530762,1.99565751859359,14.5600000396371,0.00122519949710178,0.000258833130393603,0.25,3.22980678906462E-6,0.000114448187486051,4.06117471989239E-6,4.99977493286133,4.99977493286133,-81299.8125,-81249.1953125,55.0329007820058,19.75853367209,4.45338296890259,0,0,0,40,5.02309513092041,1,6,1,2.1514892578125,44.4770278930664,,,,,,,,,,,,,,,,
,3735576783.154,4.99993395805359,-85518.09765625,0.000127930285061163,3.9864448805334E-6,1,0.999253354069792,40.0298881530762,1.99571530439911,14.5600000396371,0.00137541933391751,0.000269670081885821,0.25,1.75838954808764E-6,0.000128148502989053,2.6762896130743E-6,4.99999761581421,4.99999761581421,-85540.8984375,-85495.296875,55.1157534050443,19.7568449861871,4.45334482192993,0,0,0,40,5.02340316772461,1,6,1,2.1533203125,44.4770278930664,,,,,,,,,,,,,,,,
,3735576867.093,4.99937987327576,-89761.30078125,0.000162199675156308,3.39641841599745E-6,1,0.999253354069792,40.0298881530762,1.99581938569898,14.5600000396371,0.00172943779920622,0.000424621259152205,0.25,9.90489548595023E-6,0.000162469002578738,1.10708770528871E-5,4.99992609024048,4.99992609024048,-89786.578125,-89736.0234375,55.0563496375827,19.7578644894392,4.45244884490967,0,0,0,40,5.0297966003418,1,6,1,2.15408325195313,44.4770278930664,,,,,,,,,,,,,,,,
,3735576960.131,5.00022315979004,-86126.8828125,0.000130137401634452,3.54509277070683E-6,1,0.999253354069792,40.0298881530762,1.99570589467821,14.5600000396371,0.00144405298453381,2.76476079251709E-5,0.25,-2.10960297271168E-5,0.000130528258198736,-2.02060772398875E-5,4.99970483779907,4.99970483779907,-86141.8046875,-86111.9609375,54.9305074459866,19.7564674526871,4.4514889717102,0,0,0,40,5.02511262893677,1,6,1,2.152099609375,44.4770278930664,,,,,,,,,,,,,,,,
,3735577044.1255,5.00030016899109,-81943.703125,0.000112861653923116,3.71784204071359E-6,1,0.999253354069792,40.0298881530762,1.99566946158688,14.5600000396371,0.0012151796083349,0.000226272029029201,0.25,4.69704072826399E-7,0.000113033049576999,1.28518402107431E-6,4.99960851669312,4.99960851669312,-81958.6875,-81928.71875,54.8148264251404,19.7582632241045,4.44890642166138,0,0,0,40,5.0241641998291,1,6,1,2.15316772460938,44.4770278930664,,,,,,,,,,,,,,,,
,3735577127.855,5.00008773803711,-77774.3828125,0.000103484472625647,3.03312464919673E-6,1,0.999253354069792,40.0298881530762,1.99567554675904,14.5600000396371,0.00113117103043543,0.000112338823217538,0.25,-8.40277215124913E-6,0.000103673573944519,-7.65871002903483E-6,4.99990606307983,4.99990606307983,-77799.3046875,-77749.4609375,55.1360757465443,19.7574840636325,4.44548559188843,0,0,0,40,5.01936388015747,1,6,1,2.16781616210938,44.4770278930664,,,,,,,,,,,,,,,,
,3735577211.9685,4.99972224235535,-73583.61328125,8.72741989653175E-5,3.66325757310088E-6,1,0.999253354069792,40.0298881530762,1.99563083997902,14.5600000396371,0.000953103260129734,9.77013137375957E-5,0.25,-6.81410023158949E-6,8.74031369722834E-5,-6.17873179156338E-6,4.99985933303833,4.99985933303833,-73601.046875,-73566.1796875,55.1978243995635,19.7575250640719,4.44188070297241,0,0,0,40,5.01772403717041,1,6,1,2.1533203125,44.9657897949219,,,,,,,,,,,,,,,,
,3735577295.8675,5.00003528594971,-69405.19921875,7.57203250482145E-5,3.42367296955549E-6,1,0.999253354069792,40.0298881530762,1.99580842612596,14.5600000396371,0.00081213588607027,0.000164791507866063,0.25,1.52016662195883E-6,7.57511475030436E-5,2.08114310665421E-6,5.00041913986206,5.00041913986206,-69422.703125,-69387.6953125,55.3377359045058,19.7557229850184,4.43794107437134,0,0,0,40,5.00960636138916,1,6,1,2.1490478515625,44.4770278930664,,,,,,,,,,,,,,,,
,3735577379.678,5.00029158592224,-65230.4375,7.47064305592999E-5,3.34274780905028E-6,1,0.999253354069792,40.0298881530762,1.99561571736124,14.5600000396371,0.000821920447317621,4.70719400349994E-5,0.25,-9.23138156829331E-6,7.47892936342754E-5,-8.67818872326759E-6,5.00036096572876,5.00036096572876,-65252.8203125,-65208.0546875,54.8875178774289,19.7585538232735,4.43436479568481,0,0,0,40,5.00709009170532,1,6,1,2.15301513671875,44.9657897949219,,,,,,,,,,,,,,,,
,3735577463.6965,4.99968075752258,-61043.8515625,5.70649977003771E-5,2.41248432954002E-6,1,0.999253354069792,40.0298881530762,1.99558814500035,14.5600000396371,0.000627200087957897,3.80436958805668E-5,0.25,-6.85699468989216E-6,5.71051640957952E-5,-6.43101724894057E-6,4.99936389923096,4.99936389923096,-61063.796875,-61023.90625,55.3174135630059,19.7567852437925,4.43151378631592,0,0,0,40,5.00501441955566,1,6,1,2.15255737304687,44.4770278930664,,,,,,,,,,,,,,,,
,3735577547.604,4.99981236457825,-56867.462890625,6.02725594928469E-5,3.39472548879555E-6,1,0.999253354069792,40.0298881530762,1.99557272331451,14.5600000396371,0.000633172085079401,0.000199463567262446,0.25,7.5744992344389E-6,6.01809005462468E-5,8.01818930085434E-6,4.99952411651611,4.99952411651611,-56889.8984375,-56845.02734375,54.8523445940635,19.7574661511517,4.42768001556396,0,0,0,40,5.00169849395752,1,6,1,2.15438842773438,43.9882698059082,,,,,,,,,,,,,,,,
,3735577631.488,4.99993371963501,-52688.673828125,4.14017425978762E-5,2.2527663820087E-6,1,0.999253354069792,40.0298881530762,1.99563664708581,14.5600000396371,0.000439832978077518,0.000109146368775153,0.25,2.61596010953605E-6,4.13411072522693E-5,2.91996236615019E-6,5.00007104873657,5.00007104873657,-52711.1171875,-52666.23046875,55.1118452624481,19.758181599317,4.42428922653198,0,0,0,40,4.9970383644104,1,6,1,2.15255737304687,44.4770278930664,,,,,,,,,,,,,,,,
,3735577715.5265,4.9998025894165,-48499.892578125,2.83567111735782E-5,1.95709108522775E-6,1,0.999253354069792,40.0298881530762,1.99566538589842,14.5600000396371,0.00033167672866747,-9.30801948650885E-5,0.25,-1.38269985537517E-5,2.84180861760461E-5,-1.35989035347435E-5,4.99973821640015,4.99973821640015,-48517.2890625,-48482.49609375,54.9078402189289,19.7570869954971,4.42124366760254,0,0,0,40,4.99820327758789,1,6,1,2.13714599609375,43.9882698059082,,,,,,,,,,,,,,,,
,3735577799.3765,5.00002646446228,-44326.458984375,2.93453145324689E-5,3.02670511286897E-6,1,0.999253354069792,40.0298881530762,1.99566033043576,14.5600000396371,0.000312533939267077,7.15602567772546E-5,0.25,1.3237205981405E-6,2.92813411226102E-5,1.53460947790799E-6,4.99978017807007,4.99978017807007,-44353.8359375,-44299.08203125,54.8046652543904,19.7569663894637,4.41796779632568,0,0,0,40,4.99466133117676,1,6,1,2.1661376953125,44.4770278930664,,,,,,,,,,,,,,,,
,3735577883.282,4.99977374076843,-40145.208984375,1.38408672294839E-5,1.54186543913184E-6,1,0.999253354069792,40.0298881530762,1.99563546397255,14.5600000396371,0.000160154681761893,-3.67127335689717E-5,0.25,-5.93754549901881E-6,1.38516558239526E-5,-5.82484276262348E-6,4.9996452331543,4.9996452331543,-40170.1484375,-40120.26953125,54.6381783797942,19.7584920070745,4.4148588180542,0,0,0,40,4.99160385131836,1,6,1,2.15011596679687,44.4770278930664,,,,,,,,,,,,,,,,
,3735577967.245,4.99964475631714,-35963.8984375,9.3932450863029E-6,2.03259401708545E-6,1,0.999253354069792,40.0298881530762,1.995621772145,14.5600000396371,0.000102265818186132,1.01457133005119E-5,0.25,-7.61375729412822E-7,9.37289535136085E-6,-6.93365565425431E-7,4.99925184249878,4.99925184249878,-35986.33984375,-35941.45703125,54.6819495768712,19.7575494790391,4.41263675689697,0,0,0,40,4.99126625061035,1,6,1,2.15530395507813,44.4770278930664,,,,,,,,,,,,,,,,
,3735578051.194,5.00040888786316,-31782.33203125,-2.88546910344054E-6,1.51614833297881E-6,1,0.999253354069792,40.0298881530762,1.99569965392121,14.5600000396371,-2.11505380656999E-5,-5.95776113724605E-5,0.25,-5.03112332272118E-6,-2.84185353898133E-6,-5.03488716166447E-6,5.00051736831665,5.00051736831665,-31807.263671875,-31757.400390625,55.0110151834674,19.758155512878,4.41059494018555,0,0,0,40,4.98838090896606,1,6,1,2.152099609375,44.4770278930664,,,,,,,,,,,,,,,,
,3735578135.0995,4.99928498268127,-27601.4482421875,-7.84875768082835E-6,1.23213156859379E-6,1,0.999253354069792,40.0298881530762,1.99559398882714,14.5600000396371,-8.68707341179877E-5,-2.01237429832701E-7,0.25,1.40454391309163E-6,-7.82970314461088E-6,1.34732891638611E-6,4.9995059967041,4.9995059967041,-27623.869140625,-27579.02734375,55.2947463359481,19.7601580670171,4.40687608718872,0,0,0,40,4.98569679260254,1,6,1,2.16293334960938,43.9882698059082,,,,,,,,,,,,,,,,
,3735578219.1295,4.99961161613464,-23417.3916015625,-1.69304754907091E-5,1.32736729350162E-6,1,0.999253354069792,40.0298881530762,1.9955509521698,14.5600000396371,-0.000171680441449691,-8.66560958050888E-5,0.25,-5.02059713924063E-6,-1.68298242989357E-5,-5.10878451932906E-6,4.9996976852417,4.9996976852417,-23434.783203125,-23400,55.2056406847558,19.7617093927021,4.40618896484375,0,0,0,40,4.98498821258545,1,6,1,2.15316772460938,44.4770278930664,,,,,,,,,,,,,,,,
,3735578302.9965,5.00023722648621,-19235.30078125,-1.77471712642697E-5,1.2427193263652E-6,1,0.999253354069792,40.0298881530762,1.99565675174207,14.5600000396371,-0.000182987072636,-7.37949057207528E-5,0.25,-3.67945426736169E-6,-1.76454563477843E-5,-3.77212881924311E-6,5.00097465515137,5.00097465515137,-19260.1875,-19210.4140625,54.8523445940635,19.7569942013575,4.40345621109009,0,0,0,40,4.98426294326782,1,6,1,2.13958740234375,44.4770278930664,,,,,,,,,,,,,,,,
,3735578386.908,4.99960803985596,-15058.9887695313,-2.36322341836298E-5,9.03936948715693E-7,1,0.999253354069792,40.0298881530762,1.99560389481301,14.5600000396371,-0.00024735138930302,-7.7334898694812E-5,0.25,-2.95529168780439E-6,-2.3500360478117E-5,-3.0794626734486E-6,4.99919700622559,4.99919700622559,-15086.427734375,-15031.5498046875,55.2619179381405,19.7579429513515,4.40150022506714,0,0,0,40,4.98467350006103,1,6,1,2.15057373046875,43.9882698059082,,,,,,,,,,,,,,,,
,3735578470.8555,4.99877882003784,-10873.8232421875,-3.00670270466861E-5,6.01553344666133E-7,1,0.999253354069792,40.0298881530762,1.99561487208229,14.5600000396371,-0.000318448276868972,-7.70120212997114E-5,0.25,-1.77499897780087E-6,-2.9900508440609E-5,-1.93284727318274E-6,4.99908590316772,4.99908590316772,-10898.6982421875,-10848.9482421875,54.5420380719289,19.7586280014678,4.40041399002075,0,0,0,40,4.98453903198242,1,6,1,2.15484619140625,43.9882698059082,,,,,,,,,,,,,,,,
,3735578554.7975,5.00030064582825,-6683.6298828125,-3.34055648795772E-5,4.39733668958963E-7,1,0.999253354069792,40.0298881530762,1.99558888626979,14.5600000396371,-0.000353420018116374,-8.70526761190429E-5,0.25,-2.12421801969049E-6,-3.32094559080031E-5,-2.28777985809227E-6,5.00037384033203,5.00037384033203,-6706.0107421875,-6661.2490234375,54.3810225969673,19.7599324810117,4.40007734298706,0,0,0,40,4.98833084106445,1,6,1,2.154541015625,44.4770278930664,,,,,,,,,,,,,,,,
,3735578641.8145,4.99935269355774,-2335.15686035156,-3.76178742536189E-5,3.18522184320144E-7,1,0.999253354069792,40.0298881530762,1.99551436478007,14.5600000396371,-0.000398941736246594,-9.1997117328674E-5,0.25,-1.8424977600479E-6,-3.73897497010206E-5,-2.01779231620679E-6,4.99879121780396,4.99879121780396,-2355.11450195313,-2315.19921875,54.5959704397558,19.7601519490693,4.39967584609985,0,0,0,40,4.98852729797363,1,6,1,2.15530395507813,43.9882698059082,,,,,,,,,,,,,,,,
,3735578728.736,5.00000286102295,2010.48638916016,-3.77481176140161E-5,2.77248662941192E-7,1,0.999253354069792,40.0298881530762,1.99564855461222,14.5600000396371,-0.000401989891338021,-8.31412221573105E-5,0.25,-9.91809320367927E-7,-3.75227770023E-5,-1.17190967372703E-6,5.0003457069397,5.0003457069397,1988.01171875,2032.96105957031,54.5342217867365,19.7589916003181,4.39752960205078,0,0,0,40,4.98426246643066,1,6,1,2.15301513671875,43.9882698059082,,,,,,,,,,,,,,,,
,3735578815.594,4.99916481971741,6353.271484375,-4.05774388454329E-5,4.49020147945563E-7,1,0.999253354069792,40.0298881530762,1.99563611237181,14.5600000396371,-0.000433046289769636,-8.48940572580191E-5,0.25,-6.33225869008728E-7,-4.03484923575189E-5,-8.41689921913653E-7,4.99931144714355,4.99931144714355,6328.22265625,6378.3203125,54.4232305370057,19.7590399129676,4.39563369750977,0,0,0,40,4.9826283454895,1,6,1,2.15469360351562,44.4770278930664,,,,,,,,,,,,,,,,
,3735578902.5515,5.00084733963013,10701.0263671875,-4.29986471688131E-5,6.64674150414176E-7,1,0.999253354069792,40.0298881530762,1.9955830454071,14.5600000396371,-0.000458654178652537,-9.20603294477255E-5,0.25,-8.50868610178395E-7,-4.2769286200073E-5,-1.08483909364709E-6,5.00076389312744,5.00076389312744,10678.533203125,10723.51953125,54.9539563015635,19.7574306196554,4.39459180831909,0,0,0,40,4.98438167572022,1,6,1,2.15423583984375,43.9882698059082,,,,,,,,,,,,,,,,
,3735578986.6935,4.99934411048889,14908.2387695313,-4.10799711210324E-5,9.00269177422397E-7,1,0.999253354069792,40.0298881530762,1.99558456632113,14.5600000396371,-0.000440124210554793,-7.81385119617392E-5,0.25,1.19069149193217E-7,-4.08809789162269E-5,-1.21819834526299E-7,4.99958801269531,4.99958801269531,14893.2177734375,14923.259765625,54.7030535468904,19.7581495576915,4.39254522323608,0,0,0,40,4.98328542709351,1,6,1,2.166748046875,44.4770278930664,,,,,,,,,,,,,,,,
,3735579070.5345,5.00044202804565,19100.8994140625,-3.95315220833651E-5,1.02715680518002E-6,1,0.999253354069792,40.0298881530762,1.99557033135129,14.5600000396371,-0.000429056774277244,-4.55926589390466E-5,0.25,2.89197687730153E-6,-3.9372563448484E-5,2.63643840130312E-6,5.00044202804565,5.00044202804565,19083.412109375,19118.38671875,54.6256723234865,19.7600693059385,4.39210844039917,0,0,0,40,4.98328351974487,1,6,1,2.15377807617187,43.9882698059082,,,,,,,,,,,,,,,,
,3735579154.36,5.00053572654724,23294.2919921875,-2.85981627902697E-5,1.0256440489181E-6,1,0.999253354069792,40.0298881530762,1.99551897152082,14.5600000396371,-0.000311525988801048,-2.74349288926148E-5,0.25,2.61869431866597E-6,-2.84989002658262E-5,2.42501684844026E-6,5.00062656402588,5.00062656402588,23269.306640625,23319.27734375,54.9992907556789,19.7595279824396,4.3919849395752,0,0,0,40,4.98468112945557,1,6,1,2.15316772460938,44.4770278930664,,,,,,,,,,,,,,,,
,3735579238.2565,4.99982070922852,27494.724609375,-2.20610672292264E-5,1.32160579346835E-6,1,0.999253354069792,40.0298881530762,1.99552387035974,14.5600000396371,-0.00024240153985323,-1.02776472057157E-5,0.25,3.0417296824439E-6,-2.20012290160866E-5,2.88427827230429E-6,5.00020790100098,5.00020790100098,27469.65625,27519.79296875,54.7757449991789,19.75907921581,4.39129972457886,0,0,0,40,4.9839563369751,1,6,1,2.15591430664062,44.9657897949219,,,,,,,,,,,,,,,,
,3735579322.3205,4.99929642677307,31712.8837890625,-1.86618144639921E-5,1.28480720545403E-6,1,0.999253354069792,40.0298881530762,1.99547649993887,14.5600000396371,-0.000199682097856316,-3.87816754207868E-5,0.25,-2.28381193225476E-7,-1.86008003569673E-5,-3.55359052836744E-7,4.99965333938599,4.99965333938599,31695.30078125,31730.466796875,54.4427712499865,19.7599096764441,4.3911657333374,0,0,0,40,4.98891687393188,1,6,1,2.15347290039062,43.9882698059082,,,,,,,,,,,,,,,,
,3735579406.278,5.00041270256042,35927.345703125,-1.7864932083257E-5,1.18882979964508E-6,1,0.999253354069792,40.0298881530762,1.99547645468921,14.5600000396371,-0.00019370804632168,-2.35658579185982E-5,0.25,1.04990435567515E-6,-1.7823363862845E-5,9.21665873024573E-7,5.00005674362183,5.00005674362183,35912.23828125,35942.453125,54.9383237311789,19.7613740388517,4.39116048812866,0,0,0,40,4.98938226699829,1,6,1,2.15347290039062,43.9882698059082,,,,,,,,,,,,,,,,
,3735579490.077,5.00018429756165,40135.623046875,-3.03784744723077E-5,2.52205825815845E-6,1,0.999253354069792,40.0298881530762,1.99560832750487,14.5600000396371,-0.00031474928643397,-0.00012154374307689,0.25,-5.7988205924063E-6,-3.02673044084648E-5,-6.00301239406464E-6,4.99977493286133,4.99977493286133,40113.03125,40158.21484375,54.8226427103327,19.757851779211,4.3913893699646,0,0,0,40,4.99037218093872,1,6,1,2.1514892578125,43.9882698059082,,,,,,,,,,,,,,,,
,3735579574.173,5.0007700920105,44356.962890625,-2.63177690467723E-5,2.21925523488913E-6,1,0.999253354069792,40.0298881530762,1.99556042135549,14.5600000396371,-0.000280118723708463,-6.50468926490289E-5,0.25,-1.26837384547271E-6,-2.62598882413E-5,-1.45737735066481E-6,5.00115728378296,5.00115728378296,44339.35546875,44374.5703125,54.7843429128904,19.7582749169389,4.39135837554932,0,0,0,40,4.99255800247192,1,6,1,2.1527099609375,44.4770278930664,,,,,,,,,,,,,,,,
,3735579658.087,4.99810171127319,48568.173828125,-3.68839116235506E-5,2.76657542289702E-6,1,0.999253354069792,40.0298881530762,1.99563124176108,14.5600000396371,-0.000399547438799569,-5.3951533698902E-5,0.25,1.69303942268181E-6,-3.68442360798927E-5,1.41946201209873E-6,4.99756050109863,4.99756050109863,48550.6015625,48585.74609375,55.0680740653712,19.7582355249637,4.39152240753174,0,0,0,40,4.99514007568359,1,6,1,2.15255737304687,43.9882698059082,,,,,,,,,,,,,,,,
,3735579741.893,4.99992704391479,52782.666015625,-3.63028139908406E-5,2.3763149137669E-6,1,0.999253354069792,40.0298881530762,1.99569303863017,14.5600000396371,-0.00039296393378741,-5.57018062307029E-5,0.25,1.42855406919892E-6,-3.62775543962808E-5,1.15826190060528E-6,4.99967670440674,4.99967670440674,52757.39453125,52807.9375,55.4588883249866,19.7570800393766,4.39115810394287,0,0,0,40,4.99785709381103,1,6,1,2.13699340820313,44.4770278930664,,,,,,,,,,,,,,,,
,3735579826.044,4.99974250793457,57034.904296875,-5.34274728334592E-5,3.47140525929558E-6,1,0.999253354069792,40.0298881530762,1.99563858421144,14.5600000396371,-0.0005690718988584,-0.000134095195271315,0.25,-2.74057046169785E-6,-5.33766296196831E-5,-3.13628239907261E-6,4.99970817565918,4.99970817565918,57019.73046875,57050.078125,55.128259461352,19.7565342270285,4.39209127426147,0,0,0,40,4.99838447570801,1,6,1,2.152099609375,44.9657897949219,,,,,,,,,,,,,,,,
,3735579909.767,4.99941611289978,61269.771484375,-6.86610750006451E-5,2.89221778780136E-6,1,0.999253354069792,40.0298881530762,1.9956210359176,14.5600000396371,-0.000725359162441479,-0.000206751382150779,0.25,-6.71576490894612E-6,-6.85994699240016E-5,-7.22558098943805E-6,4.99985408782959,4.99985408782959,61246.984375,61292.55859375,54.810136654025,19.7588371857767,4.39323949813843,0,0,0,40,5.00292921066284,1,6,1,2.15164184570313,43.9882698059082,,,,,,,,,,,,,,,,
,3735579993.713,4.99832630157471,65517.8203125,-7.75847445076828E-5,2.7839798779976E-6,1,0.999253354069792,40.0298881530762,1.99554282549448,14.5600000396371,-0.000828079675240169,-0.000188897672621634,0.25,-3.42570863744513E-6,-7.75761267158281E-5,-4.00266729283356E-6,4.99768924713135,4.99768924713135,65495.03125,65540.609375,55.013360069025,19.7568380041149,4.39535093307495,0,0,0,40,5.0076413154602,1,6,1,2.16812133789062,44.4770278930664,,,,,,,,,,,,,,,,
,3735580077.628,5.00036692619324,69757.3125,-7.99503452669966E-5,2.39889222514111E-6,1,0.999253354069792,40.0298881530762,1.99574026473222,14.5600000396371,-0.000894792489353048,3.0791044811327E-5,0.25,1.74184785899453E-5,-8.01259514606755E-5,1.68375238945317E-5,4.999831199646,4.999831199646,69732.0546875,69782.5703125,55.1563980880443,19.7548003110453,4.39555358886719,0,0,0,40,5.01044607162476,1,6,1,2.15438842773438,44.4770278930664,,,,,,,,,,,,,,,,
,3735580161.6975,5.00124263763428,74009.68359375,-9.23305195798129E-5,3.52458895338789E-6,1,0.999253354069792,40.0298881530762,1.99551281112983,14.5600000396371,-0.00099179645060122,-0.000194019286494275,0.25,-1.21140643883713E-6,-9.24082272063961E-5,-1.89072257698274E-6,5.00125789642334,5.00125789642334,73989.46875,74029.8984375,55.1829734576981,19.7573548330395,4.39786338806152,0,0,0,40,5.01640844345093,1,6,1,2.15164184570313,44.4770278930664,,,,,,,,,,,,,,,,
,3735580245.6885,4.99932360649109,78258.0703125,-9.7978772124465E-5,3.56591112836023E-6,1,0.999253354069792,40.0298881530762,1.99557239913135,14.5600000396371,-0.00104398733858928,-0.000254672497207792,0.25,-5.81391629409642E-6,-9.80611171906348E-5,-6.53486129284465E-6,4.99897480010986,4.99897480010986,78242.8125,78273.328125,54.8953341626212,19.7571567332387,4.39767169952393,0,0,0,40,5.0159740447998,1,6,1,2.154541015625,44.9657897949219,,,,,,,,,,,,,,,,
,3735580329.585,5.00034666061401,82502.6484375,-0.000133272403744102,4.00224027988855E-6,1,0.999253354069792,40.0298881530762,1.99560667278345,14.5600000396371,-0.00144262679298019,-0.000225029771018499,0.25,3.35714177680665E-6,-0.000133508429015802,2.40175571994337E-6,4.99996614456177,4.99996614456177,82484.875,82520.421875,54.8617241362943,19.7534666704137,4.39935159683228,0,0,0,40,5.02189874649048,1,6,1,2.1368408203125,44.4770278930664,,,,,,,,,,,,,,,,
,3735580413.357,5.00116848945618,86737.31640625,-0.000128935169590074,3.62128118130035E-6,1,0.999253354069792,40.0298881530762,1.99546677324856,14.5600000396371,-0.00140874141435965,-0.000147658535490801,0.25,9.74068658355574E-6,-0.000129248053993569,8.84037724947792E-6,5.0011568069458,5.0011568069458,86711.8984375,86762.734375,55.1775020580635,19.7561148122032,4.40133762359619,0,0,0,40,5.02840280532837,1,6,1,2.149658203125,44.4770278930664,,,,,,,,,,,,,,,,
,3735580481.472,4.99935793876648,90001.01171875,-0.000127377208044072,3.30794545592049E-6,1,0.999253354069792,40.0298881530762,1.99547134194335,14.5600000396371,-0.00140541671281662,-7.21781257254902E-5,0.25,1.6452877700457E-5,-0.000127761727003235,1.55888328274134E-5,4.99958276748657,4.99958276748657,90000.3515625,90001.671875,55.0250844968135,19.7561458914392,4.40307998657227,0,0,0,40,5.02932214736938,1,4,1,2.15408325195313,44.4770278930664,,,,,,,,,,,,,,,,