File: data/doubleLayers/monolayer/ppms/DD205_4/rawdata/DD205_4_HYST_100OE_50K.DAT
[Header]
; VSM Data File (default extension .dat)
; Copyright (c) 2003-2013, Quantum Design, Inc. All rights reserved.
TITLE,
FILEOPENTIME,3735599438.75485,05/16/2018,2:29 am
BYAPP,VSM,1.0,1.0
INFO,DYNACOOL VSM Option Release 1.4.10 Build 1,APPNAME
INFO,Quantum Design Linear Motor Servo Controller,MOTOR_MODULE_NAME
INFO,3101-100 J0,MOTOR_HW_VERSION
INFO,MMC654,MOTOR_SERIAL_NUMBER
INFO,SRV No X-over 01.03.11,MOTOR_SOFTWARE_VERSION
INFO,Quantum Design VSM Detection Module,VSM_MODULE_NAME
INFO,3101-150 F0,VSM_HW_VERSION
INFO,VSM507,VSM_SERIAL_NUMBER
INFO,VSM No X-over 01.02.05 May 20 2008 13:51:47,VSM_SOFTWARE_VERSION
INFO,494,PREAMP_SERIAL_NUMBER
INFO,Quantum Design VSM Oven,OVEN_MODULE_NAME
INFO,3101-201 A1,OVEN_HW_VERSION
INFO,OVB210,OVEN_SERIAL_NUMBER
INFO,01.06.24,OVEN_SOFTWARE_VERSION
INFO,593,COIL_SERIAL_NUMBER
INFO,0,MOMENT_UNITS
INFO,,SAMPLE_MATERIAL
INFO,,SAMPLE_COMMENT
INFO,,SAMPLE_MASS
INFO,,SAMPLE_VOLUME
INFO,,SAMPLE_MOLECULAR_WEIGHT
INFO,,SAMPLE_SIZE
INFO,,SAMPLE_SHAPE
DATATYPE,COMMENT,1
DATATYPE,TIME,2
STARTUPAXIS,X,2
STARTUPAXIS,Y1,5
[Data]
Comment,Time Stamp (sec),Temperature (K),Magnetic Field (Oe),Moment (emu),M. Std. Err. (emu),Transport Action,Averaging Time (sec),Frequency (Hz),Peak Amplitude (mm),Center Position (mm),Coil Signal' (mV),Coil Signal" (mV),Range (mV),M. Quad. Signal (emu),M. Raw' (emu),M. Raw" (emu),Min. Temperature (K),Max. Temperature (K),Min. Field (Oe),Max. Field (Oe),Mass (grams),Motor Lag (deg),Pressure (Torr),VSM Status (code),Motor Status (code),Measure Status (code),Measure Count,System Temp. (K),Temp. Status (code),Field Status (code),Chamber Status (code),Motor Current (amps),Motor Heatsink Temp. (C),Map 01,Map 02,Map 03,Map 04,Map 05,Map 06,Map 07,Map 08,Map 09,Map 10,Map 11,Map 12,Map 13,Map 14,Map 15,Map 16
,3735599796.7035,49.989709854126,-0.514162346720695,3.5532490917634E-5,3.38500580115836E-7,1,0.999253354069792,40.0298881530762,1.99567962514231,14.5600000396371,0.000383406593234257,6.1726839698603E-5,0.25,-7.30043008924611E-7,3.55114607741744E-5,-4.6525261851433E-7,49.9896202087402,49.9896202087402,-0.762170076370239,-0.266154617071152,54.4357365933135,19.7518054311046,15.1976938247681,0,0,0,40,50.0195846557617,1,4,1,2.15286254882813,43.49951171875,,,,,,,,,,,,,,,,
,3735599887.6515,49.9934635162354,4138.84497070313,2.86198853710109E-5,3.40731468732534E-7,1,0.999253354069792,40.0298881530762,1.99553621718018,14.5600000396371,0.000309521976762096,4.60105611752755E-5,0.25,-9.33373450574962E-7,2.86100966497518E-5,-7.19895599810992E-7,49.9935150146484,49.9935150146484,4113.904296875,4163.78564453125,54.7773082562173,19.7568261426178,15.2858619689941,0,0,0,40,50.0228080749512,1,6,1,2.15362548828125,43.9882698059082,,,,,,,,,,,,,,,,
,3735599971.571,49.9958038330078,8333.18505859375,2.05364893982315E-5,4.16941337690921E-7,1,0.999253354069792,40.0298881530762,1.99571491691615,14.5600000396371,0.00022349070843128,2.57466738621403E-5,0.25,-1.34648467647201E-6,2.05387030527569E-5,-1.19319933937766E-6,49.9956245422363,49.9956245422363,8308.166015625,8358.2041015625,54.7351003161789,19.751072526988,15.3637247085571,0,0,0,40,50.0236320495605,1,6,1,2.15225219726562,43.49951171875,,,,,,,,,,,,,,,,
,3735600055.522,49.9964160919189,12528.3120117188,1.36960813788054E-5,3.77544565753005E-7,1,0.999253354069792,40.0298881530762,1.99568138468776,14.5600000396371,0.000149091088905951,1.71108633911029E-5,0.25,-9.03767996632153E-7,1.37006094882604E-5,-8.01835564878869E-7,49.9962730407715,49.9962730407715,12503.35546875,12553.2685546875,54.728847288025,19.7502345429351,15.4361057281494,0,0,0,40,50.0241889953613,1,6,1,2.15194702148438,43.9882698059082,,,,,,,,,,,,,,,,
,3735600139.528,49.9965381622314,16730.5634765625,4.89152080186958E-6,4.37903958276128E-7,1,0.999253354069792,40.0298881530762,1.99565880663696,14.5600000396371,5.46089216573939E-5,-1.29978731990696E-6,0.25,-1.01164544674831E-6,4.89935955570162E-6,-9.75431796312937E-7,49.9964637756348,49.9964637756348,16713.060546875,16748.06640625,54.8281141099673,19.7523182415962,15.501802444458,0,0,0,40,50.0277442932129,1,6,1,2.15118408203125,43.9882698059082,,,,,,,,,,,,,,,,
,3735600223.5295,49.9983673095703,20930.8154296875,-2.44129740800193E-6,4.09672337088225E-7,1,0.999253354069792,40.0298881530762,1.99563257668931,14.5600000396371,-2.61618669571246E-5,-5.38438532670378E-6,0.25,-5.58084899576841E-8,-2.44161811622571E-6,-7.38801962214589E-8,49.9983901977539,49.9983901977539,20913.322265625,20948.30859375,54.9742786430635,19.7508994947663,15.5508346557617,0,0,0,40,50.0285034179687,1,6,1,2.15438842773438,43.9882698059082,,,,,,,,,,,,,,,,
,3735600307.4315,49.9983940124512,25126.2431640625,-1.06164271815603E-5,5.57195195715334E-7,1,0.999253354069792,40.0298881530762,1.99553330843092,14.5600000396371,-0.000112436982633968,-3.08546492108723E-5,0.25,-9.3383193500679E-7,-1.06151971804167E-5,-1.01253404436254E-6,49.9983825683594,49.9983825683594,25108.73828125,25143.748046875,55.0157049545827,19.7533430117215,15.604248046875,0,0,0,40,50.0285301208496,1,6,1,2.15499877929687,43.49951171875,,,,,,,,,,,,,,,,
,3735600391.296,49.9981956481934,29330.9775390625,-1.96806103806026E-5,6.51578401647447E-7,1,0.999253354069792,40.0298881530762,1.99552660875395,14.5600000396371,-0.000211168053489757,-4.24564986286136E-5,0.25,-3.61361148350516E-7,-1.96929700245175E-5,-5.05895708056657E-7,49.9981346130371,49.9981346130371,29310.896484375,29351.05859375,54.7882510554866,19.7527465652089,15.65944480896,0,0,0,40,50.0290489196777,1,6,1,2.15103149414062,43.9882698059082,,,,,,,,,,,,,,,,
,3735600475.184,49.9990997314453,33544.728515625,-2.74025699351121E-5,5.09317713645679E-7,1,0.999253354069792,40.0298881530762,1.99553267877602,14.5600000396371,-0.000293101321006055,-6.45657737102998E-5,0.25,-1.00930756466338E-6,-2.74223622688034E-5,-1.20997920912932E-6,49.999195098877,49.999195098877,33522.16015625,33567.296875,54.8546894796212,19.7518038971593,15.7096557617188,0,0,0,40,50.0295486450195,1,6,1,2.15072631835938,43.49951171875,,,,,,,,,,,,,,,,
,3735600559.1835,49.999454498291,37761.67578125,-3.71028969057858E-5,7.54983523453464E-7,1,0.999253354069792,40.0298881530762,1.99540441112837,14.5600000396371,-0.000397075508250735,-8.65937305302299E-5,0.25,-1.29030433546763E-6,-3.71386176790431E-5,-1.56037738228189E-6,49.9993705749512,49.9993705749512,37734.07421875,37789.27734375,54.7835612843712,19.7531845788253,15.7485666275024,0,0,0,40,50.0300903320313,1,6,1,2.15423583984375,43.9882698059082,,,,,,,,,,,,,,,,
,3735600643.055,50.0003776550293,41969.923828125,-4.52243253643235E-5,8.26242691010616E-7,1,0.999253354069792,40.0298881530762,1.99557936715146,14.5600000396371,-0.000486106622554608,-9.47537662066413E-5,0.25,-5.70415938302535E-7,-4.52850179398884E-5,-8.95997001929753E-7,50.0004692077637,50.0004692077637,41944.82421875,41995.0234375,54.799975483275,19.7545646353315,15.7844953536987,0,0,0,40,50.0297927856445,1,6,1,2.15362548828125,43.49951171875,,,,,,,,,,,,,,,,
,3735600727.098,49.999195098877,46188.912109375,-5.44177572291231E-5,8.77433824625949E-7,1,0.999253354069792,40.0298881530762,1.9955865665226,14.5600000396371,-0.000582556003916108,-0.000127765236727349,0.25,-1.96342395577128E-6,-5.44932985483722E-5,-2.35411843811137E-6,49.9993133544922,49.9993133544922,46171.32421875,46206.5,54.2583069194481,19.7528211814208,15.8250608444214,0,0,0,40,50.0313110351562,1,6,1,2.15240478515625,43.49951171875,,,,,,,,,,,,,,,,
,3735600811.0315,49.9996681213379,50402.794921875,-6.3680570526578E-5,1.10215872979292E-6,1,0.999253354069792,40.0298881530762,1.99556305887925,14.5600000396371,-0.000685015410121902,-0.000132128665421769,0.25,-6.86262794153243E-7,-6.37936188841687E-5,-1.13675955948606E-6,49.9998550415039,49.9998550415039,50382.671875,50422.91796875,54.7812163988135,19.7518125358799,15.8629503250122,0,0,0,40,50.0311470031738,1,6,1,2.15179443359375,43.49951171875,,,,,,,,,,,,,,,,
,3735600894.866,49.9995784759521,54632.84765625,-7.12003299338815E-5,1.1963818230163E-6,1,0.999253354069792,40.0298881530762,1.99553875928805,14.5600000396371,-0.000766980526315856,-0.000142637922712932,0.25,-2.97356949892668E-7,-7.1344316517836E-5,-7.95234437113107E-7,49.9998588562012,49.9998588562012,54607.51953125,54658.17578125,54.5733032126981,19.7513684487332,15.9061183929443,0,0,0,40,50.0287895202637,1,6,1,2.15591430664062,43.49951171875,,,,,,,,,,,,,,,,
,3735600978.823,50.0010948181152,58875.271484375,-7.95989992938705E-5,8.43116113371666E-7,1,0.999253354069792,40.0298881530762,1.99556742866422,14.5600000396371,-0.000854520306553037,-0.000176621324806144,0.25,-1.92664347909438E-6,-7.9764426583351E-5,-2.48097323062684E-6,50.0010986328125,50.0010986328125,58850.0625,58900.48046875,54.6545925786981,19.7517365740859,15.9566955566406,0,0,0,40,50.0304489135742,1,6,1,2.13851928710938,43.49951171875,,,,,,,,,,,,,,,,
,3735601062.7545,50.0007801055908,63120.34375,-8.78680164467188E-5,1.37998590071385E-6,1,0.999253354069792,40.0298881530762,1.99541750395606,14.5600000396371,-0.00094296828313902,-0.000197373520478906,0.25,-2.3545387953593E-6,-8.80656515999745E-5,-2.96059026548851E-6,50.000804901123,50.000804901123,63097.515625,63143.171875,54.8836097348327,19.7514766081056,15.9918842315674,0,0,0,40,50.0296363830566,1,6,1,2.15362548828125,43.49951171875,,,,,,,,,,,,,,,,
,3735601146.686,49.9995937347412,67365.65234375,-9.63661657502647E-5,1.24295146117817E-6,1,0.999253354069792,40.0298881530762,1.99561740901914,14.5600000396371,-0.00103962410681202,-0.000188016843390354,0.25,5.24237809261539E-8,-9.66182162048036E-5,-5.98089229517569E-7,49.999626159668,49.999626159668,67340.3671875,67390.9375,54.9969458701212,19.7506285624268,16.0170097351074,0,0,0,40,50.0311660766602,1,6,1,2.15362548828125,43.49951171875,,,,,,,,,,,,,,,,
,3735601230.7395,49.9998760223389,71615.1796875,-0.000104059506205101,1.37330213219079E-6,1,0.999253354069792,40.0298881530762,1.99561180659802,14.5600000396371,-0.00111805262464544,-0.00022930788030152,0.25,-2.38476151461757E-6,-0.000104333379233148,-3.0853862153451E-6,49.9998168945313,49.9998168945313,71597.5234375,71632.8359375,54.952393044525,19.7479825753247,16.025074005127,0,0,0,40,50.0302085876465,1,6,1,2.15530395507813,43.49951171875,,,,,,,,,,,,,,,,
,3735601314.684,49.9993438720703,75860.48046875,-0.000113354908355431,1.32892904827962E-6,1,0.999253354069792,40.0298881530762,1.99548028697254,14.5600000396371,-0.00121604178637482,-0.000260910041448599,0.25,-3.63547087762712E-6,-0.000113665399144885,-4.39259656107252E-6,49.9992599487305,49.9992599487305,75840.2265625,75880.734375,55.1438920317366,19.7539951765743,16.0395660400391,0,0,0,40,50.0311698913574,1,6,1,2.152099609375,43.49951171875,,,,,,,,,,,,,,,,
,3735601398.615,50.0002117156982,80106.140625,-0.000121586617113691,9.07034695104562E-7,1,0.999253354069792,40.0298881530762,1.99567136585522,14.5600000396371,-0.00131514293757219,-0.000222155529750218,0.25,1.44252554890786E-6,-0.000121974018609938,6.56870221140528E-7,50.000072479248,50.000072479248,80088.4375,80123.84375,54.5162443307942,19.7508614629752,16.0726757049561,0,0,0,40,50.0311126708984,1,6,1,2.16506958007813,43.49951171875,,,,,,,,,,,,,,,,
,3735601482.3955,49.999698638916,84340.60546875,-0.000128483566627187,1.67830314362944E-6,1,0.999253354069792,40.0298881530762,1.99557617008307,14.5600000396371,-0.00138714912744316,-0.00024991180037625,0.25,1.11466694571726E-7,-0.000128903223113873,-7.11973614125391E-7,49.9997215270996,49.9997215270996,84315.3515625,84365.859375,54.6913291191019,19.7512100611562,16.1148147583008,0,0,0,40,50.0308837890625,1,6,1,2.15194702148438,43.49951171875,,,,,,,,,,,,,,,,
,3735601566.3605,50.0004863739014,88588.10546875,-0.00014151334513658,1.9030378105948E-6,1,0.999253354069792,40.0298881530762,1.99537594593303,14.5600000396371,-0.00153052343542183,-0.000260759798901757,0.25,1.45429398008556E-6,-0.000142004571493473,5.6434913506366E-7,50.0003662109375,50.0003662109375,88562.8125,88613.3984375,54.4154142518134,19.7528834387927,16.1479625701904,0,0,0,40,50.0303497314453,1,6,1,2.16506958007813,43.9882698059082,,,,,,,,,,,,,,,,
,3735601659.3,49.9987087249756,87333.4375,-0.000136646189514866,1.66455344868924E-6,1,0.999253354069792,40.0298881530762,1.99534112772661,14.5600000396371,-0.00147223217891861,-0.000282521206670932,0.25,-1.44026347595906E-6,-0.000137096690151098,-2.31280119654943E-6,49.9985504150391,49.9985504150391,87311.03125,87355.84375,55.0375905531212,19.7556393174135,16.1807918548584,0,0,0,40,50.0317611694336,1,6,1,2.15606689453125,43.0107536315918,,,,,,,,,,,,,,,,
,3735601743.236,49.9988555908203,83150.6328125,-0.000126012837649821,1.34636620594311E-6,1,0.999253354069792,40.0298881530762,1.99555276287521,14.5600000396371,-0.00135274129469022,-0.000287400319090585,0.25,-3.80707424438832E-6,-0.000126393924236769,-4.63038485365568E-6,49.9987716674805,49.9987716674805,83125.7265625,83175.5390625,54.8906443915058,19.7535515566687,16.2013835906982,0,0,0,40,50.0316963195801,1,6,1,2.15362548828125,43.9882698059082,,,,,,,,,,,,,,,,
,3735601827.1645,49.999568939209,78968.25390625,-0.000115604363632828,1.78109940957137E-6,1,0.999253354069792,40.0298881530762,1.99542819245895,14.5600000396371,-0.00125005249081318,-0.000212222554782115,0.25,1.27875371410148E-6,-0.00011596728187689,5.287281884883E-7,49.9994735717773,49.9994735717773,78945.75,78990.7578125,54.8499997085058,19.7534048959231,16.2145481109619,0,0,0,40,50.0326271057129,1,6,1,2.15408325195313,43.9882698059082,,,,,,,,,,,,,,,,
,3735601911.106,49.9986896514893,74785.3203125,-0.000107468174169829,1.62852292494242E-6,1,0.999253354069792,40.0298881530762,1.99538543279047,14.5600000396371,-0.00115728362021551,-0.000222548850401958,0.25,-1.14670921420355E-6,-0.000107773214666108,-1.86000447194496E-6,49.9987907409668,49.9987907409668,74760.4765625,74810.1640625,54.5998785823519,19.7525583072465,16.2346649169922,0,0,0,40,50.0315856933594,1,6,1,2.15728759765625,43.9882698059082,,,,,,,,,,,,,,,,
,3735601995.0355,49.9995994567871,70604.8515625,-9.70577459161297E-5,8.74369222571055E-7,1,0.999253354069792,40.0298881530762,1.99544606183933,14.5600000396371,-0.00104440112089098,-0.000204463854818457,0.25,-1.35200203641479E-6,-9.73150527067168E-5,-2.00492931203764E-6,49.9995956420898,49.9995956420898,70580.03125,70629.671875,54.7335370591404,19.7560083477452,16.2447090148926,0,0,0,40,50.030834197998,1,6,1,2.15286254882813,43.9882698059082,,,,,,,,,,,,,,,,
,3735602079.092,49.9999523162842,66415.1171875,-8.81457778827854E-5,1.16789074469727E-6,1,0.999253354069792,40.0298881530762,1.99532695777151,14.5600000396371,-0.000948489981600957,-0.000184522017444123,0.25,-1.1163023359716E-6,-8.83649577549939E-5,-1.71592347106494E-6,49.9999847412109,49.9999847412109,66395.171875,66435.0625,54.4662201055634,19.752804818454,16.2577114105225,0,0,0,40,50.0329742431641,1,6,1,2.15545654296875,44.9657897949219,,,,,,,,,,,,,,,,
,3735602162.887,49.9995861053467,62239.912109375,-7.98154640202775E-5,1.13853079862344E-6,1,0.999253354069792,40.0298881530762,1.99555711569421,14.5600000396371,-0.000858415751982881,-0.00016914985719202,0.25,-1.19712324554387E-6,-7.99983405688784E-5,-1.74660768508457E-6,49.9995002746582,49.9995002746582,62214.94140625,62264.8828125,54.8476548229481,19.7564615213643,16.2879257202148,0,0,0,40,50.0307540893555,1,6,1,2.1514892578125,43.49951171875,,,,,,,,,,,,,,,,
,3735602246.83,49.9991645812988,58056.689453125,-6.97128566649657E-5,1.08060144500998E-6,1,0.999253354069792,40.0298881530762,1.99538882384246,14.5600000396371,-0.000751598798850969,-0.000136488361539075,0.25,-2.75179415428399E-10,-6.98668053753282E-5,-4.82996008492851E-7,49.9989967346191,49.9989967346191,58034.28125,58079.09765625,54.7632389428712,19.7580043693855,16.3044700622559,0,0,0,40,50.031364440918,1,6,1,2.15530395507813,43.49951171875,,,,,,,,,,,,,,,,
,3735602330.8435,50.0000152587891,53872.173828125,-6.27638127779868E-5,1.0517640955983E-6,1,0.999253354069792,40.0298881530762,1.99548337511983,14.5600000396371,-0.000672070649210587,-0.00014768508144609,0.25,-2.29810848454559E-6,-6.28742661148822E-5,-2.74189799043021E-6,49.9999351501465,49.9999351501465,53849.69140625,53894.65625,54.3067678876404,19.7590822727804,16.3282985687256,0,0,0,40,50.0322914123535,1,6,1,2.15316772460938,43.9882698059082,,,,,,,,,,,,,,,,
,3735602414.963,50.000545501709,49682.587890625,-5.23775265316127E-5,8.32785045906726E-7,1,0.999253354069792,40.0298881530762,1.99537987965181,14.5600000396371,-0.000563138829887859,-0.000109876120862096,0.25,-6.76396193696833E-7,-5.24678992827042E-5,-1.04771805179946E-6,50.0005493164063,50.0005493164063,49665.12109375,49700.0546875,54.3692981691788,19.7580184214971,16.3516006469727,0,0,0,40,50.0304870605469,1,6,1,2.15225219726562,43.49951171875,,,,,,,,,,,,,,,,
,3735602498.654,50.0005569458008,45509.48828125,-4.45417484371867E-5,1.10543080040833E-6,1,0.999253354069792,40.0298881530762,1.99536747690627,14.5600000396371,-0.000473406838639202,-0.000123033516271201,0.25,-3.32089474203128E-6,-4.4589848444659E-5,-3.64384131834218E-6,50.0006446838379,50.0006446838379,45484.546875,45534.4296875,54.647557922025,19.7583736662199,16.3762683868408,0,0,0,40,50.030632019043,1,6,1,2.15438842773438,43.49951171875,,,,,,,,,,,,,,,,
,3735602582.869,50.0003814697266,41312.56640625,-3.47995452657269E-5,8.87566585369788E-7,1,0.999253354069792,40.0298881530762,1.99530988845695,14.5600000396371,-0.000375988539449239,-6.19238017398932E-5,0.25,5.80376736748875E-7,-3.48524004123791E-5,3.30972179502726E-7,50.0001907348633,50.0001907348633,41300.12109375,41325.01171875,54.7679287139866,19.7577291799931,16.3966197967529,0,0,0,40,50.0325469970703,1,6,1,2.13943481445313,43.49951171875,,,,,,,,,,,,,,,,
,3735602666.5455,50.0000495910645,37145.00390625,-2.82512859263918E-5,8.07027290884696E-7,1,0.999253354069792,40.0298881530762,1.99538103946485,14.5600000396371,-0.000303997277024799,-5.67806351262252E-5,0.25,-1.32496315511423E-7,-2.82837231369931E-5,-3.37317310499315E-7,49.9999465942383,49.9999465942383,37125.00390625,37165.00390625,54.7741817421404,19.7617054548649,16.4209213256836,0,0,0,40,50.0305252075195,1,6,1,2.13790893554687,43.9882698059082,,,,,,,,,,,,,,,,
,3735602750.492,50.0008163452148,32962.40625,-1.88459868783013E-5,7.46236882667212E-7,1,0.999253354069792,40.0298881530762,1.99535389018153,14.5600000396371,-0.000201427734811722,-4.51023238797271E-5,0.25,-7.59285665594504E-7,-1.88585378186671E-5,-8.9745649441007E-7,50.0008430480957,50.0008430480957,32935.0390625,32989.7734375,55.3893233867751,19.7588975275002,16.44602394104,0,0,0,40,50.0306587219238,1,6,1,2.15301513671875,43.9882698059082,,,,,,,,,,,,,,,,
,3735602834.39,50.0003433227539,28782.2841796875,-1.1878777065909E-5,6.80537010857656E-7,1,0.999253354069792,40.0298881530762,1.99526669516301,14.5600000396371,-0.000127750547923913,-2.38981512057594E-5,0.25,-5.79109184731766E-8,-1.18870615054798E-5,-1.45084984257742E-7,50.0002861022949,50.0002861022949,28759.890625,28804.677734375,54.3677349121404,19.7611718856198,16.4718971252441,0,0,0,40,50.0324020385742,1,6,1,2.13775634765625,43.49951171875,,,,,,,,,,,,,,,,
,3735602918.3275,50.0006084442139,24600.404296875,-4.63928255249009E-6,5.8582140286261E-7,1,0.999253354069792,40.0298881530762,1.995299073161,14.5600000396371,-4.7443850414891E-5,-2.2726293855201E-5,0.25,-1.2671200408811E-6,-4.63228002555484E-6,-1.30195167859292E-6,50.0008354187012,50.0008354187012,24575.453125,24625.35546875,54.4810710474288,19.7575733927692,16.5004863739014,0,0,0,40,50.0319557189941,1,6,1,2.13882446289062,43.49951171875,,,,,,,,,,,,,,,,
,3735603002.3775,49.9999408721924,20413.2958984375,2.51351829609155E-6,4.90793973640992E-7,1,0.999253354069792,40.0298881530762,1.99533820242831,14.5600000396371,3.00577850315514E-5,-1.16267455710564E-5,0.25,-1.53832119305449E-6,2.52558415167994E-6,-1.52014328514864E-6,49.9996910095215,49.9996910095215,20395.970703125,20430.62109375,54.6522476931404,19.7572080060136,16.5122413635254,0,0,0,40,50.0310935974121,1,6,1,2.1551513671875,43.49951171875,,,,,,,,,,,,,,,,
,3735603086.4255,49.999698638916,16226.3022460938,1.11468216987391E-5,4.45311642271594E-7,1,0.999253354069792,40.0298881530762,1.99540426610653,14.5600000396371,0.000121454041830408,1.33500942652105E-5,0.25,-7.89020447643879E-7,1.11531405959717E-5,-7.06348821305347E-7,49.9996109008789,49.9996109008789,16211.3828125,16241.2216796875,54.9836581852943,19.7559883837558,16.5243358612061,0,0,0,40,50.0296745300293,1,6,1,2.15179443359375,43.9882698059082,,,,,,,,,,,,,,,,
,3735603170.16,49.999303817749,12052.4877929688,1.78274132614443E-5,3.61593240312474E-7,1,0.999253354069792,40.0298881530762,1.99541328121791,14.5600000396371,0.0001941556021497,2.16005247132564E-5,0.25,-1.2385494635651E-6,1.78333316555033E-5,-1.10580919388181E-6,49.9991798400879,49.9991798400879,12030.0673828125,12074.908203125,54.5264055015442,19.7593215186147,16.5315093994141,0,0,0,40,50.031135559082,1,6,1,2.16812133789062,43.9882698059082,,,,,,,,,,,,,,,,
,3735603254.079,49.9991970062256,7865.60327148438,2.45056841488171E-5,3.95513514796235E-7,1,0.999253354069792,40.0298881530762,1.9953806575322,14.5600000396371,0.000265729520905565,3.57016983500342E-5,0.25,-1.14316923190048E-6,2.45043205413224E-5,-9.6039861764416E-7,49.9992370605469,49.9992370605469,7843.0751953125,7888.13134765625,55.1392022606212,19.7547388403113,16.5311698913574,0,0,0,40,50.0323944091797,1,6,1,2.1533203125,43.49951171875,,,,,,,,,,,,,,,,
,3735603338.0535,50.0006732940674,3670.62487792969,3.16194071548455E-5,3.15388516445017E-7,1,0.999253354069792,40.0298881530762,1.99536315265223,14.5600000396371,0.00034130509480963,5.42414602636929E-5,0.25,-7.13622054374721E-7,3.16056320723167E-5,-4.77949163022435E-7,50.0007400512695,50.0007400512695,3643.126953125,3698.12280273438,54.5568890137942,19.7543519706163,16.5318450927734,0,0,0,40,50.0317001342773,1,6,1,2.15377807617187,43.0107536315918,,,,,,,,,,,,,,,,
,3735603425.0975,49.9997062683105,-667.989135742188,,,1,0.999253354069792,40.0298881530762,1.99539892364735,14.5600000396371,-0.000523483675682848,-0.00282252389254991,0.25,,,,49.9996109008789,49.9996109008789,-694.344909667969,-641.633361816406,55.026647753852,19.754264974429,16.5249786376953,1,0,,40,50.0313873291016,1,6,1,2.15423583984375,43.9882698059082,,,,,,,,,,,,,,,,
,3735603515.015,49.9999370574951,-5176.59985351562,4.03573291845351E-5,3.82668192190038E-7,1,0.999253354069792,40.0298881530762,1.99535474023001,14.5600000396371,0.000434346578951038,7.64025822389493E-5,0.25,-2.44158538102714E-7,4.03375771797633E-5,5.62431618721549E-8,50.0000877380371,50.0000877380371,-5194.0859375,-5159.11376953125,55.341644047102,19.7554516522751,16.5229167938232,0,0,0,40,50.0307922363281,1,6,1,2.15286254882813,43.49951171875,,,,,,,,,,,,,,,,
,3735603598.8985,49.999532699585,-9372.0771484375,4.25967847683725E-5,3.60509872173158E-7,1,0.999253354069792,40.0298881530762,1.99540282710972,14.5600000396371,0.000458583812952825,8.05033177877224E-5,0.25,-2.72196406322966E-7,4.25849458465401E-5,4.47250508221084E-8,49.9994812011719,49.9994812011719,-9394.5380859375,-9349.6162109375,54.7679287139866,19.7573416587201,16.525369644165,0,0,0,40,50.0301780700684,1,6,1,2.15438842773438,43.0107536315918,,,,,,,,,,,,,,,,
,3735603682.7645,50.000904083252,-13564.5678710938,4.1186507229619E-5,4.17121582908435E-7,1,0.999253354069792,40.0298881530762,1.99547350812869,14.5600000396371,0.000444458291319751,7.26779435453477E-5,0.25,-7.44344893646039E-7,4.1187803988128E-5,-4.38295162835349E-7,50.0009307861328,50.0009307861328,-13589.57421875,-13539.5615234375,54.7077433180058,19.7583948193696,16.5368251800537,0,0,0,40,50.0307312011719,1,6,1,2.13699340820313,43.49951171875,,,,,,,,,,,,,,,,
,3735603766.7115,50.0005302429199,-17761.43359375,3.35581914605272E-5,5.34034371005933E-7,1,0.999253354069792,40.0298881530762,1.9954862876977,14.5600000396371,0.000362017417942738,6.03617917571047E-5,0.25,-5.0076132488806E-7,3.35661375300368E-5,-2.52066074779414E-7,50.0004539489746,50.0004539489746,-17788.95703125,-17733.91015625,54.3286534861788,19.7556699012189,16.549898147583,0,0,0,40,50.0298271179199,1,6,1,2.15103149414062,43.0107536315918,,,,,,,,,,,,,,,,
,3735603850.609,50.0000228881836,-21958.8349609375,2.53107123939352E-5,5.04153393724187E-7,1,0.999253354069792,40.0298881530762,1.9954557638927,14.5600000396371,0.000272196361523571,5.0525474478694E-5,0.25,8.65496142139818E-8,2.53191258433439E-5,2.73604026612102E-7,50.0001029968262,50.0001029968262,-21983.75390625,-21933.916015625,55.260354681102,19.7567029685401,16.5643672943115,0,0,0,40,50.0308876037598,1,6,1,2.15362548828125,43.49951171875,,,,,,,,,,,,,,,,
,3735603934.565,50.0002307891846,-26156.560546875,2.09545511602492E-5,6.75994351833578E-7,1,0.999253354069792,40.0298881530762,1.99547795301627,14.5600000396371,0.000225838336846086,3.94533135276714E-5,0.25,-1.49378654565121E-7,2.09679979913758E-5,4.71874968192083E-9,50.0001106262207,50.0001106262207,-26179.1015625,-26134.01953125,54.5537624997173,19.7561377241112,16.5800628662109,0,0,0,40,50.031063079834,1,6,1,2.15286254882813,43.49951171875,,,,,,,,,,,,,,,,
,3735604018.4935,50.0011882781982,-30366.69921875,2.24469920488781E-5,7.3341251431049E-7,1,0.999253354069792,40.0298881530762,1.99556694018308,14.5600000396371,0.000241972543096928,4.23651453055368E-5,0.25,-1.50729325575309E-7,2.24664939961617E-5,1.34554055044356E-8,50.0011177062988,50.0011177062988,-30389.25390625,-30344.14453125,54.4935771037365,19.7542090894405,16.597261428833,0,0,0,40,50.0305366516113,1,6,1,2.15316772460938,43.49951171875,,,,,,,,,,,,,,,,
,3735604102.5525,50.0009098052978,-34586.458984375,2.5371288077798E-5,7.51908520031285E-7,1,0.999253354069792,40.0298881530762,1.99548693515699,14.5600000396371,0.000274923463403537,4.03294759479156E-5,0.25,-8.71572244068077E-7,2.54041862804959E-5,-6.87913697023326E-7,50.0009574890137,50.0009574890137,-34604.0078125,-34568.91015625,54.5498543571212,19.7562178489881,16.6119251251221,0,0,0,40,50.0298500061035,1,6,1,2.14126586914062,43.49951171875,,,,,,,,,,,,,,,,
,3735604186.375,49.9993114471436,-38789.01171875,3.2669753067964E-5,9.11751899006553E-7,1,0.999253354069792,40.0298881530762,1.99541216178298,14.5600000396371,0.000351621463296986,6.5425815418077E-5,0.25,1.31458796798799E-7,3.27102325320076E-5,3.6762393814341E-7,49.9993553161621,49.9993553161621,-38814.1328125,-38763.890625,54.8367120236789,19.7532574132272,16.6232776641846,0,0,0,40,50.0300636291504,1,6,1,2.15133666992187,43.49951171875,,,,,,,,,,,,,,,,
,3735604270.3065,50.0004825592041,-43004.1796875,3.90577988091315E-5,8.35187172859092E-7,1,0.999253354069792,40.0298881530762,1.99545160437584,14.5600000396371,0.00042227535493013,6.83336940475161E-5,0.25,-7.59802117135327E-7,3.91212579280011E-5,-4.8101607177018E-7,50.0003204345703,50.0003204345703,-43029.2109375,-42979.1484375,54.7327554306212,19.7525525003673,16.6288509368896,0,0,0,40,50.0297813415527,1,6,1,2.15286254882813,43.49951171875,,,,,,,,,,,,,,,,
,3735604354.253,50.0001201629639,-47216.33203125,4.66501637503707E-5,7.128440218671E-7,1,0.999253354069792,40.0298881530762,1.99536215401548,14.5600000396371,0.000504407739033691,8.1832063134108E-5,0.25,-8.85826118803952E-7,4.67355802542769E-5,-5.55901988221808E-7,50.0002326965332,50.0002326965332,-47238.94921875,-47193.71484375,54.4435528785058,19.7564899704916,16.6308727264404,0,0,0,40,50.029972076416,1,6,1,2.15484619140625,43.49951171875,,,,,,,,,,,,,,,,
,3735604438.324,50.0004253387451,-51434.482421875,5.50760682504397E-5,1.18177230664035E-6,1,0.999253354069792,40.0298881530762,1.99535833199565,14.5600000396371,0.000598109671156632,8.30018558635881E-5,0.25,-2.30671480340213E-6,5.51969931724641E-5,-1.92349909631382E-6,50.0002937316895,50.0002937316895,-51449.54296875,-51419.421875,54.4998301318904,19.753936135714,16.646125793457,0,0,0,40,50.0302658081055,1,6,1,2.15408325195313,43.49951171875,,,,,,,,,,,,,,,,
,3735604522.1035,49.9996128082275,-55668.951171875,6.41022315931039E-5,1.12245019501723E-6,1,0.999253354069792,40.0298881530762,1.99552947633382,14.5600000396371,0.000691646320480917,0.000122380935625168,0.25,-2.91631475725142E-7,6.4238841526702E-5,1.5430811250892E-7,49.9994888305664,49.9994888305664,-55691.7734375,-55646.12890625,54.6600639783327,19.7540189546352,16.6624279022217,0,0,0,40,50.0306053161621,1,6,1,2.13775634765625,43.49951171875,,,,,,,,,,,,,,,,
,3735604606.2045,49.9999771118164,-59920.1640625,7.19150417872228E-5,9.55879721641027E-7,1,0.999253354069792,40.0298881530762,1.99558006528985,14.5600000396371,0.000776065772377714,0.000137578899182056,0.25,-2.98256346339386E-7,7.20819251561627E-5,1.96622162483162E-7,49.9999694824219,49.9999694824219,-59937.88671875,-59902.44140625,54.853907851102,19.7549647455395,16.6683330535889,0,0,0,40,50.0300941467285,1,6,1,2.15087890625,43.9882698059082,,,,,,,,,,,,,,,,
,3735604690.1945,50.0006828308105,-64167.005859375,8.04259232780419E-5,1.15748496507299E-6,1,0.999253354069792,40.0298881530762,1.99550567481579,14.5600000396371,0.000871825355984332,0.000133020751203168,0.25,-2.26159362170785E-6,8.0640566698603E-5,-1.71929041150646E-6,50.0006065368652,50.0006065368652,-64184.6796875,-64149.33203125,55.1368573750635,19.7544553068428,16.6762599945068,0,0,0,40,50.0300064086914,1,6,1,2.14981079101562,43.9882698059082,,,,,,,,,,,,,,,,
,3735604773.927,50.0002994537354,-68395.91796875,8.93912337163605E-5,9.1865021232342E-7,1,0.999253354069792,40.0298881530762,1.99547076834358,14.5600000396371,0.000973011618911415,0.00012665349563812,0.25,-4.4734745801593E-6,8.96586395639644E-5,-3.88357301055854E-6,50.0002326965332,50.0002326965332,-68421.171875,-68370.6640625,54.8140447966212,19.7548443407688,16.6681022644043,0,0,0,40,50.030445098877,1,6,1,2.15484619140625,43.0107536315918,,,,,,,,,,,,,,,,
,3735604858.0435,50.0006656646729,-72652.33984375,9.91238627971393E-5,1.14694122444E-6,1,0.999253354069792,40.0298881530762,1.9955093917381,14.5600000396371,0.00107265700965729,0.000176276891903946,0.25,-1.63328006718692E-6,9.94148388609795E-5,-9.78864518672792E-7,50.0005836486816,50.0005836486816,-72667.5625,-72637.1171875,55.3854152441789,19.7522712794356,16.6564273834229,0,0,0,40,50.0307922363281,1,6,1,2.16278076171875,42.5219955444336,,,,,,,,,,,,,,,,
,3735604941.992,50.0006904602051,-76893.02734375,0.000105546230192069,1.46719006232617E-6,1,0.999253354069792,40.0298881530762,1.99547606505366,14.5600000396371,0.00114425420851414,0.000177062911379652,0.25,-2.7181612423379E-6,0.000105879620256709,-2.0335089984139E-6,50.0006790161133,50.0006790161133,-76908.2109375,-76877.84375,54.8249875958904,19.7520675448376,16.6569976806641,0,0,0,40,50.0292816162109,1,6,1,2.15438842773438,43.49951171875,,,,,,,,,,,,,,,,
,3735605025.879,49.9993324279785,-81136.640625,0.000114230532726182,1.03991943699551E-6,1,0.999253354069792,40.0298881530762,1.99538058610662,14.5600000396371,0.00123372717212158,0.00021820653424347,0.25,-4.71386927236409E-7,0.000114593015685513,2.67067998496496E-7,49.9992446899414,49.9992446899414,-81154.3125,-81118.96875,54.596752068275,19.7542267539108,16.6722393035889,0,0,0,40,50.0297622680664,1,6,1,2.154541015625,43.9882698059082,,,,,,,,,,,,,,,,
,3735605109.7945,49.9991493225098,-85377.796875,0.000122537464534715,1.42326892219517E-6,1,0.999253354069792,40.0298881530762,1.99553398958617,14.5600000396371,0.00132749909252335,0.000213353788282688,0.25,-2.41922840533065E-6,0.000122956898500691,-1.64414395851595E-6,49.9991340637207,49.9991340637207,-85395.4609375,-85360.1328125,54.7679287139866,19.754521569126,16.6840209960938,0,0,0,40,50.0295104980469,1,6,1,2.1551513671875,43.0107536315918,,,,,,,,,,,,,,,,
,3735605193.6825,50.0008125305176,-89615.9375,0.000130206901475055,1.10118275036774E-6,1,0.999253354069792,40.0298881530762,1.99547031722671,14.5600000396371,0.00141086285782892,0.000226061015170148,0.25,-2.62128996193321E-6,0.000130671401905268,-1.80969317915707E-6,50.0007553100586,50.0007553100586,-89636.1328125,-89595.7421875,54.8906443915058,19.7543525582626,16.6877136230469,0,0,0,40,50.0295715332031,1,6,1,2.15530395507813,43.49951171875,,,,,,,,,,,,,,,,
,3735605286.5975,50,-86283.66796875,0.000124568350762208,1.28630596224295E-6,1,0.999253354069792,40.0298881530762,1.99547615412826,14.5600000396371,0.00134865108691842,0.000221606736475773,0.25,-2.02007220128592E-6,0.000124995793126655,-1.23309744176975E-6,49.9999198913574,49.9999198913574,-86301.1015625,-86266.234375,55.2173651125443,19.7536140978751,16.701997756958,0,0,0,40,50.0314903259277,1,6,1,2.15560913085938,43.49951171875,,,,,,,,,,,,,,,,
,3735605370.639,49.9999599456787,-82095.546875,0.000117204053587261,1.57492147042925E-6,1,0.999253354069792,40.0298881530762,1.99544021154854,14.5600000396371,0.0012648484331837,0.000229826018521402,0.25,6.76678166864904E-8,0.000117576459011085,8.24775230210985E-7,49.9998893737793,49.9998893737793,-82112.9375,-82078.15625,54.6155111527366,19.7532518710085,16.7104721069336,0,0,0,40,50.0311546325684,1,6,1,2.15087890625,43.49951171875,,,,,,,,,,,,,,,,
,3735605454.4435,49.9988174438477,-77921.38671875,0.000107815756246855,1.46606398047485E-6,1,0.999253354069792,40.0298881530762,1.99550276780371,14.5600000396371,0.00116592021561552,0.000197421876232055,0.25,-1.24143655100781E-6,0.000108150359224994,-5.39748262935357E-7,49.9987754821777,49.9987754821777,-77948.984375,-77893.7890625,54.9164381326404,19.7547798647053,16.6999435424805,0,0,0,40,50.0318794250488,1,6,1,2.14889526367187,43.9882698059082,,,,,,,,,,,,,,,,
,3735605538.3505,49.9998683929443,-73742.68359375,9.71694585781429E-5,1.43233763640674E-6,1,0.999253354069792,40.0298881530762,1.99539226139153,14.5600000396371,0.00104580938232818,0.000204152192468893,0.25,1.30707382399137E-6,9.74395364418793E-5,1.95476148797613E-6,49.999927520752,49.999927520752,-73765.0390625,-73720.328125,55.0969943205828,19.7550083425218,16.6804428100586,0,0,0,40,50.031852722168,1,6,1,2.152099609375,43.49951171875,,,,,,,,,,,,,,,,
,3735605622.331,50.0003871917725,-69559.16796875,9.09358072855712E-5,1.03808811713271E-6,1,0.999253354069792,40.0298881530762,1.99535362518774,14.5600000396371,0.00098242946516364,0.000169559130278168,0.25,-7.73881672189943E-7,9.11867141806503E-5,-1.65852169084294E-7,50.0007820129395,50.0007820129395,-69581.5859375,-69536.75,54.874230192602,19.7545320529611,16.6715393066406,0,0,0,40,50.0307006835937,1,6,1,2.15240478515625,43.49951171875,,,,,,,,,,,,,,,,
,3735605706.3875,50.0002841949463,-65372.123046875,8.27968568863206E-5,1.0474797308013E-6,1,0.999253354069792,40.0298881530762,1.99538644376293,14.5600000396371,0.000893954585038221,0.000156594123973634,0.25,-5.0412768219147E-7,8.30096279065556E-5,5.67755986937699E-8,50.0003356933594,50.0003356933594,-65392.07421875,-65352.171875,54.3794593399288,19.7542900097203,16.6651420593262,0,0,0,40,50.0320243835449,1,6,1,2.15408325195313,43.49951171875,,,,,,,,,,,,,,,,
,3735605790.1535,49.9992637634277,-61200.376953125,7.41360390392423E-5,1.2245526803404E-6,1,0.999253354069792,40.0298881530762,1.99544731143456,14.5600000396371,0.000803137915125337,0.000124694146851297,0.25,-1.89453725709351E-6,7.43231549364367E-5,-1.38984408841443E-6,49.9993782043457,49.9993782043457,-61222.87109375,-61177.8828125,55.0938678065058,19.7580321691194,16.6548957824707,0,0,0,40,50.031810760498,1,6,1,2.15164184570313,43.49951171875,,,,,,,,,,,,,,,,
,3735605874.176,50.0006370544434,-57013.884765625,6.53627047098377E-5,1.01370284855144E-6,1,0.999253354069792,40.0298881530762,1.99557298105469,14.5600000396371,0.000704569776734001,0.000128842817589501,0.25,7.93842328857999E-8,6.55034194488381E-5,5.33351497693496E-7,50.0008926391602,50.0008926391602,-57043.7890625,-56983.98046875,54.4920138466981,19.7563324649649,16.6427745819092,0,0,0,40,50.030948638916,1,6,1,2.15408325195313,43.49951171875,,,,,,,,,,,,,,,,
,3735605958.047,50.0002670288086,-52835.216796875,5.66601657662624E-5,9.61693567073429E-7,1,0.999253354069792,40.0298881530762,1.99542546442342,14.5600000396371,0.000612123670689306,0.000103277711913803,0.25,-7.12883654225923E-7,5.67766348192949E-5,-3.16849779283671E-7,50.0002784729004,50.0002784729004,-52860.0859375,-52810.34765625,54.2426743490634,19.751505460424,16.6349182128906,0,0,0,40,50.0311965942383,1,6,1,2.15606689453125,43.9882698059082,,,,,,,,,,,,,,,,
,3735606042.007,50.000114440918,-48653.849609375,4.82976326558478E-5,1.24960669896724E-6,1,0.999253354069792,40.0298881530762,1.9954661796617,14.5600000396371,0.000520892353655502,9.23855083766573E-5,0.25,-2.0582873669448E-7,4.83844127733781E-5,1.35860850231503E-7,49.999942779541,49.999942779541,-48681.2734375,-48626.42578125,54.5912806686404,19.7542242892031,16.6312885284424,0,0,0,40,50.0310554504395,1,6,1,2.15194702148438,43.49951171875,,,,,,,,,,,,,,,,
,3735606126.0675,50.0004787445068,-44468.0703125,4.02456831515876E-5,7.21067411341483E-7,1,0.999253354069792,40.0298881530762,1.99547080297658,14.5600000396371,0.000434750077710391,7.26397786548759E-5,0.25,-5.75811649010851E-7,4.03125531132285E-5,-2.89128906318098E-7,50.000373840332,50.000373840332,-44483.01171875,-44453.12890625,54.7734001136212,19.7569533914661,16.6341419219971,0,0,0,40,50.0312728881836,1,6,1,2.1533203125,43.49951171875,,,,,,,,,,,,,,,,
,3735606209.903,50.0007133483887,-40294.09375,3.15031112918398E-5,6.63209058178886E-7,1,0.999253354069792,40.0298881530762,1.9955859260507,14.5600000396371,0.000340820470810878,5.374849750957E-5,0.25,-7.40643892965482E-7,3.15508669107083E-5,-5.14694146896904E-7,50.0007019042969,50.0007019042969,-40313.9453125,-40274.2421875,54.9312890745058,19.752304110786,16.6315383911133,0,0,0,40,50.0318908691406,1,6,1,2.15438842773438,43.49951171875,,,,,,,,,,,,,,,,
,3735606293.91,49.9998970031738,-36107.849609375,2.5001385135348E-5,9.20682564491698E-7,1,0.999253354069792,40.0298881530762,1.99552663003127,14.5600000396371,0.000267658606397376,5.77911592322673E-5,0.25,8.171819682708E-7,2.50236406668562E-5,9.99539109207277E-7,49.9999198913574,49.9999198913574,-36130.2109375,-36085.48828125,54.8781383351981,19.7561103625027,16.6402072906494,0,0,0,40,50.0313835144043,1,6,1,2.15362548828125,43.49951171875,,,,,,,,,,,,,,,,
,3735606377.7185,50.0001125335693,-31931.3974609375,1.68601077973986E-5,7.38853479522127E-7,1,0.999253354069792,40.0298881530762,1.99546365782703,14.5600000396371,0.000181584770655738,3.27505733789113E-5,0.25,-2.66836594809421E-8,1.68755461503615E-5,9.64374796722997E-8,49.9999771118164,49.9999771118164,-31956.2890625,-31906.505859375,54.8335855096019,19.7544885090686,16.6404056549072,0,0,0,40,50.0318756103516,1,6,1,2.1533203125,43.49951171875,,,,,,,,,,,,,,,,
,3735606461.657,49.99977684021,-27752.7958984375,8.96595136780435E-6,5.58346010721497E-7,1,0.999253354069792,40.0298881530762,1.99545805738459,14.5600000396371,9.7213115132403E-5,1.37249742228976E-5,0.25,-3.57111715874377E-7,8.97464181656054E-6,-2.91503512952061E-7,49.999584197998,49.999584197998,-27777.720703125,-27727.87109375,54.5092096741211,19.7558028133109,16.6246776580811,0,0,0,40,50.0316772460937,1,6,1,2.1527099609375,43.0107536315918,,,,,,,,,,,,,,,,
,3735606545.61,50.000617980957,-23568.857421875,1.34268574650085E-6,5.41101738831634E-7,1,0.999253354069792,40.0298881530762,1.99547211973853,14.5600000396371,1.59315606383981E-5,-5.50654261409383E-6,0.25,-7.561357593004E-7,1.34886441129194E-6,-7.46567172846458E-7,50.0004081726074,50.0004081726074,-23593.755859375,-23543.958984375,54.7976305977173,19.754061206598,16.6078681945801,0,0,0,40,50.0318832397461,1,6,1,2.15484619140625,43.9882698059082,,,,,,,,,,,,,,,,
,3735606629.5215,50.0004749298096,-19389.099609375,-6.16242783566063E-6,4.53782564760148E-7,1,0.999253354069792,40.0298881530762,1.99547754319695,14.5600000396371,-6.64421829536856E-5,-1.13173029643677E-5,0.25,7.03508372487282E-8,-6.16427886515976E-6,2.47365906233137E-8,50.0004539489746,50.0004539489746,-19414.009765625,-19364.189453125,54.8797015922366,19.7568947911028,16.6190433502197,0,0,0,40,50.0312538146973,1,6,1,2.15301513671875,43.0107536315918,,,,,,,,,,,,,,,,
,3735606713.493,50.0009174346924,-15205.517578125,-1.38232481190436E-5,4.44615450613289E-7,1,0.999253354069792,40.0298881530762,1.99543820322926,14.5600000396371,-0.000146506441550211,-3.9087075886429E-5,0.25,-1.11617309134707E-6,-1.3814772343898E-5,-1.21877468346908E-6,50.0009651184082,50.0009651184082,-15230.3564453125,-15180.6787109375,54.4865424470635,19.7571623010095,16.598949432373,0,0,0,40,50.0315093994141,1,6,1,2.16766357421875,43.9882698059082,,,,,,,,,,,,,,,,
,3735606797.4935,50.0001239776611,-11018.0620117187,-2.04821221771728E-5,4.24429157969266E-7,1,0.999253354069792,40.0298881530762,1.99544299827164,14.5600000396371,-0.000219244943303454,-4.5754436958407E-5,0.25,-5.23933324061476E-7,-2.04733286723333E-5,-6.76097989039789E-7,50.0001525878906,50.0001525878906,-11038.06640625,-10998.0576171875,55.2111120843905,19.7537177563151,16.5821094512939,0,0,0,40,50.0307731628418,1,6,1,2.15530395507813,43.0107536315918,,,,,,,,,,,,,,,,
,3735606881.4895,50.0000762939453,-6825.2607421875,-2.73682058786719E-5,3.91167468862124E-7,1,0.999253354069792,40.0298881530762,1.99551019399379,14.5600000396371,-0.00029324012959329,-5.92654688049378E-5,0.25,-5.26882181638058E-7,-2.73518473416056E-5,-7.30265020633334E-7,50.0002059936523,50.0002059936523,-6845.2421875,-6805.279296875,54.9140932470827,19.7595148631519,16.6140480041504,0,0,0,40,50.0309867858887,1,6,1,2.1539306640625,43.0107536315918,,,,,,,,,,,,,,,,
,3735606965.49,49.9997711181641,-2629.42651367187,-3.38991994969946E-5,3.028063258783E-7,1,0.999253354069792,40.0298881530762,1.99557505307147,14.5600000396371,-0.000362938030308445,-7.46029981113931E-5,0.25,-7.64850377408691E-7,-3.38715098132842E-5,-1.01653415653848E-6,49.9997711181641,49.9997711181641,-2644.419921875,-2614.43310546875,54.9000239337366,19.760851619598,16.6208400726318,0,0,0,40,50.030689239502,1,6,1,2.15072631835938,43.49951171875,,,,,,,,,,,,,,,,
,3735607055.336,50.0013160705566,1861.35150146484,-3.73477005658462E-5,3.54275170144765E-7,1,0.999253354069792,40.0298881530762,1.99565007560861,14.5600000396371,-0.000398415069180965,-9.01309652981306E-5,0.25,-1.58107919488554E-6,-3.7310551916232E-5,-1.85781515140735E-6,50.0013008117676,50.0013008117676,1843.89135742187,1878.81164550781,54.7452614869289,19.7557011412083,16.6278285980225,0,0,0,40,50.0309143066406,1,6,1,2.1551513671875,43.9882698059082,,,,,,,,,,,,,,,,
,3735607142.25,50.000280380249,6208.91821289063,-4.20299916843563E-5,3.83387455864252E-7,1,0.999253354069792,40.0298881530762,1.9956071244012,14.5600000396371,-0.000449026818694029,-9.82421427977001E-5,0.25,-1.48109550611848E-6,-4.19985996122473E-5,-1.79309270175958E-6,50.0003280639648,50.0003280639648,6188.904296875,6228.93212890625,54.6084764960635,19.7507582204281,16.6350574493408,0,0,0,40,50.0296669006348,1,6,1,2.15301513671875,43.49951171875,,,,,,,,,,,,,,,,
,3735607226.224,49.9999351501465,10406.5541992187,-4.34292558300929E-5,4.05710567521684E-7,1,0.999253354069792,40.0298881530762,1.99557940413447,14.5600000396371,-0.000464414943420769,-9.96327403705523E-5,0.25,-1.35393599785656E-6,-4.34074010491165E-5,-1.67652522459797E-6,50.0000381469727,50.0000381469727,10389.0380859375,10424.0703125,54.996164241602,19.7480856370818,16.6312389373779,0,0,0,40,50.0303802490234,1,6,1,2.15240478515625,43.0107536315918,,,,,,,,,,,,,,,,
,3735607310.0005,50.0002555847168,14598.9194335938,-4.04229180189113E-5,4.9400580502235E-7,1,0.999253354069792,40.0298881530762,1.99550944325665,14.5600000396371,-0.000431815451526466,-9.5683898610834E-5,0.25,-1.53313316780479E-6,-4.04096364876969E-5,-1.83322830506187E-6,50.0002250671387,50.0002250671387,14574.0625,14623.7763671875,54.7132147176404,19.7499559692863,16.6280937194824,0,0,0,40,50.0315246582031,1,6,1,2.1551513671875,43.0107536315918,,,,,,,,,,,,,,,,
,3735607394.026,50.0007133483887,18796.650390625,-3.19936443394926E-5,6.57731458523554E-7,1,0.999253354069792,40.0298881530762,1.99559923049227,14.5600000396371,-0.000340847820329352,-8.13305550498466E-5,0.25,-1.73253995389402E-6,-3.1986672580094E-5,-1.96985349248287E-6,50.0006370544434,50.0006370544434,18779.2890625,18814.01171875,54.5733032126981,19.7494686193335,16.628345489502,0,0,0,40,50.0295066833496,1,6,1,2.15423583984375,43.9882698059082,,,,,,,,,,,,,,,,
,3735607477.9155,50.0003356933594,22994.8466796875,-2.40392242716126E-5,6.1804792329988E-7,1,0.999253354069792,40.0298881530762,1.99554431489702,14.5600000396371,-0.000254911650908583,-6.79647296076034E-5,0.25,-1.9382313756109E-6,-2.40348921280906E-5,-2.11649604014451E-6,50.0003433227539,50.0003433227539,22969.666015625,23020.02734375,54.3638267695442,19.7484600488555,16.6206016540527,0,0,0,40,50.0292091369629,1,6,1,2.15225219726562,42.0332374572754,,,,,,,,,,,,,,,,
,3735607561.8795,49.9999866485596,27199.3173828125,-2.08385735094914E-5,5.81861421864593E-7,1,0.999253354069792,40.0298881530762,1.9956404655095,14.5600000396371,-0.000223272361344793,-4.66353107750839E-5,0.25,-5.38594667268597E-7,-2.08480865788244E-5,-6.92091436436739E-7,50.0000305175781,50.0000305175781,27174.251953125,27224.3828125,54.2192254934865,19.7528873453327,16.6114120483398,0,0,0,40,50.0297431945801,1,6,1,2.15316772460938,43.49951171875,,,,,,,,,,,,,,,,
,3735607645.765,49.9995059967041,31405.0361328125,-2.2057759724924E-5,8.49859427220686E-7,1,0.999253354069792,40.0298881530762,1.99551414022858,14.5600000396371,-0.000233950571838438,-6.26944790552713E-5,0.25,-1.80836172507616E-6,-2.20638539535528E-5,-1.97117477244085E-6,49.9995460510254,49.9995460510254,31380.03125,31430.041015625,54.8632873933327,19.7493693195511,16.6091690063477,0,0,0,40,50.0308113098145,1,6,1,2.154541015625,43.49951171875,,,,,,,,,,,,,,,,
,3735607729.8195,49.9996910095215,35629.443359375,-2.75543766236432E-5,1.07686919729376E-6,1,0.999253354069792,40.0298881530762,1.99548121194574,14.5600000396371,-0.000291987461898906,-8.01165973098515E-5,0.25,-2.4258371908999E-6,-2.75671226823516E-5,-2.62863042021569E-6,49.9996757507324,49.9996757507324,35611.90234375,35646.984375,54.7788715132558,19.7498051376065,16.6102771759033,0,0,0,40,50.0286903381348,1,6,1,2.14889526367187,43.49951171875,,,,,,,,,,,,,,,,
,3735607813.6265,49.9999961853027,39832.900390625,-3.55158464864498E-5,1.00128417552508E-6,1,0.999253354069792,40.0298881530762,1.99539027405079,14.5600000396371,-0.000377475404344647,-9.74904280804815E-5,0.25,-2.59082141146793E-6,-3.55441369109639E-5,-2.85032126103037E-6,49.999927520752,49.999927520752,39807.82421875,39857.9765625,54.3091127731981,19.7531885063546,16.6062812805176,0,0,0,40,50.0305328369141,1,6,1,2.13668823242187,42.5219955444336,,,,,,,,,,,,,,,,
,3735607897.5605,50.0000953674316,44048.640625,-4.1061483051014E-5,8.1579568042515E-7,1,0.999253354069792,40.0298881530762,1.99550249793,14.5600000396371,-0.000438710931240121,-0.000100779824605352,0.25,-1.88741312865092E-6,-4.11111420133597E-5,-2.18397735735693E-6,50.0001754760742,50.0001754760742,44023.51953125,44073.76171875,54.8953341626212,19.755993715448,16.6042728424072,0,0,0,40,50.0294990539551,1,6,1,2.13943481445313,43.49951171875,,,,,,,,,,,,,,,,
,3735607981.5485,49.9986915588379,48262.861328125,-4.79382676617042E-5,8.83419325353244E-7,1,0.999253354069792,40.0298881530762,1.99539375575242,14.5600000396371,-0.000515805745142322,-9.82017924872308E-5,0.25,-3.99385167122092E-7,-4.80191961683549E-5,-7.39888785435279E-7,49.9986000061035,49.9986000061035,48240.296875,48285.42578125,55.1720306584289,19.7505903684859,16.6162948608398,0,0,0,40,50.0310592651367,1,6,1,2.15118408203125,43.49951171875,,,,,,,,,,,,,,,,
,3735608065.4235,49.9996738433838,52477.65234375,-5.722191837369E-5,1.16619521316074E-6,1,0.999253354069792,40.0298881530762,1.99541762597731,14.5600000396371,-0.000614555102858512,-0.000124248925319776,0.25,-1.13054448084807E-6,-5.7325582238569E-5,-1.53446910990174E-6,49.9997062683105,49.9997062683105,52454.87890625,52500.42578125,54.180144067525,19.7493895980188,16.6356620788574,0,0,0,40,50.0294952392578,1,6,1,2.15316772460938,43.49951171875,,,,,,,,,,,,,,,,
,3735608149.4425,50.0002956390381,56724.720703125,-6.48281391582441E-5,7.87232442479604E-7,1,0.999253354069792,40.0298881530762,1.99547111459706,14.5600000396371,-0.000694487177653956,-0.000151331603871445,0.25,-2.26281818790514E-6,-6.4951668915912E-5,-2.7180932952355E-6,50.0001754760742,50.0001754760742,56707,56742.44140625,54.8210794532943,19.7530896196088,16.670223236084,0,0,0,40,50.0306587219238,1,6,1,2.15194702148438,43.9882698059082,,,,,,,,,,,,,,,,
,3735608233.2855,50.0000514984131,60964.8984375,-7.25941765925217E-5,1.25618704933958E-6,1,0.999253354069792,40.0298881530762,1.9955498855764,14.5600000396371,-0.000780542370160311,-0.000154730049312741,0.25,-1.16991104781626E-6,-7.27558775289311E-5,-1.67150885059963E-6,50.0001831054687,50.0001831054687,60939.58984375,60990.20703125,54.4693466196404,19.7507591589221,16.6939487457275,0,0,0,40,50.0296058654785,1,6,1,2.1527099609375,43.49951171875,,,,,,,,,,,,,,,,
,3735608317.4445,49.9999408721924,65222.701171875,-8.25463362533648E-5,9.59694894001721E-7,1,0.999253354069792,40.0298881530762,1.99569488908986,14.5600000396371,-0.000890619363058876,-0.00016030703547305,0.25,1.16734000059814E-7,-8.27553179298657E-5,-4.4368403022287E-7,49.9999198913574,49.9999198913574,65207.4609375,65237.94140625,54.8562527366597,19.7485189817492,16.6927051544189,0,0,0,40,50.0287628173828,1,6,1,2.15087890625,43.0107536315918,,,,,,,,,,,,,,,,
,3735608401.2215,50.0003147125244,69460.07421875,-9.07858527732986E-5,1.26125220176365E-6,1,0.999253354069792,40.0298881530762,1.99590187722241,14.5600000396371,-0.000977451647679599,-0.000189227568312231,0.25,-1.07199025319122E-6,-9.10236011775458E-5,-1.68417263509348E-6,50.0003662109375,50.0003662109375,69434.8359375,69485.3125,54.5693950701019,19.7444696799503,16.6987724304199,0,0,0,40,50.028751373291,1,6,1,2.15087890625,43.0107536315918,,,,,,,,,,,,,,,,
,3735608485.1025,49.9998359680176,73699.7734375,-9.83315541971997E-5,1.27095225256656E-6,1,0.999253354069792,40.0298881530762,1.99575341150545,14.5600000396371,-0.00105812795480663,-0.000208665002436442,0.25,-1.51130327293664E-6,-9.86034459074401E-5,-2.16735963711937E-6,49.9999198913574,49.9999198913574,73677.109375,73722.4375,54.7624573143519,19.7489448620293,16.7046756744385,0,0,0,40,50.0291061401367,1,6,1,2.152099609375,43.49951171875,,,,,,,,,,,,,,,,
,3735608569.208,50.0001239776611,77953.0859375,-0.000107330107156782,1.02777464098023E-6,1,0.999253354069792,40.0298881530762,1.9955842609817,14.5600000396371,-0.00115753282806018,-0.000214102724177309,0.25,-3.91583708910125E-7,-0.00010765269800698,-1.09496151754023E-6,50.0001449584961,50.0001449584961,77935.375,77970.796875,54.7194677457943,19.7504593377008,16.7108325958252,0,0,0,40,50.0291481018066,1,6,1,2.15301513671875,43.9882698059082,,,,,,,,,,,,,,,,
,3735608652.972,50.0003147125244,82187.5546875,-0.0001162765596835,1.43657445169914E-6,1,0.999253354069792,40.0298881530762,1.99542502894343,14.5600000396371,-0.00125094444819865,-0.00024948404298567,0.25,-2.05732833211223E-6,-0.00011663355720364,-2.81456011045528E-6,50.0002861022949,50.0002861022949,82162.2890625,82212.8203125,54.5701766986212,19.7555014907198,16.7121162414551,0,0,0,40,50.0297431945801,1,6,1,2.13958740234375,43.49951171875,,,,,,,,,,,,,,,,
,3735608736.946,50.0006084442139,86437.265625,-0.000125436239692815,1.1443150566323E-6,1,0.999253354069792,40.0298881530762,1.99557929952357,14.5600000396371,-0.00135316152819361,-0.000250562523527914,0.25,-5.04325074741562E-7,-0.000125851155867568,-1.30482988864356E-6,50.0006446838379,50.0006446838379,86409.53125,86465,54.8116999110635,19.7519869460012,16.7228527069092,0,0,0,40,50.0284767150879,1,6,1,2.15286254882813,43.49951171875,,,,,,,,,,,,,,,,
,3735608810.872,49.999979019165,90002.40234375,-0.000133403076283535,1.59770915504445E-6,1,0.999253354069792,40.0298881530762,1.99552587470053,14.5600000396371,-0.00144142644420724,-0.000254417077861064,0.25,5.72986807267705E-7,-0.000133867354052396,-2.64728553220931E-7,49.9999198913574,49.9999198913574,90000.6328125,90004.171875,54.3685165406596,19.7517358501014,16.7282695770264,0,0,0,40,50.0287475585937,1,4,1,2.15240478515625,40.5669593811035,,,,,,,,,,,,,,,,