File: data/doubleLayers/monolayer/ppms/DD205_4/rawdata/DD205_4_FCC_100OE.DAT
[Header]
; VSM Data File (default extension .dat)
; Copyright (c) 2003-2013, Quantum Design, Inc. All rights reserved.
TITLE,
FILEOPENTIME,3735557605.30678,05/15/2018,2:52 pm
BYAPP,VSM,1.0,1.0
INFO,DYNACOOL VSM Option Release 1.4.10 Build 1,APPNAME
INFO,Quantum Design Linear Motor Servo Controller,MOTOR_MODULE_NAME
INFO,3101-100 J0,MOTOR_HW_VERSION
INFO,MMC654,MOTOR_SERIAL_NUMBER
INFO,SRV No X-over 01.03.11,MOTOR_SOFTWARE_VERSION
INFO,Quantum Design VSM Detection Module,VSM_MODULE_NAME
INFO,3101-150 F0,VSM_HW_VERSION
INFO,VSM507,VSM_SERIAL_NUMBER
INFO,VSM No X-over 01.02.05 May 20 2008 13:51:47,VSM_SOFTWARE_VERSION
INFO,494,PREAMP_SERIAL_NUMBER
INFO,Quantum Design VSM Oven,OVEN_MODULE_NAME
INFO,3101-201 A1,OVEN_HW_VERSION
INFO,OVB210,OVEN_SERIAL_NUMBER
INFO,01.06.24,OVEN_SOFTWARE_VERSION
INFO,593,COIL_SERIAL_NUMBER
INFO,0,MOMENT_UNITS
INFO,,SAMPLE_MATERIAL
INFO,,SAMPLE_COMMENT
INFO,,SAMPLE_MASS
INFO,,SAMPLE_VOLUME
INFO,,SAMPLE_MOLECULAR_WEIGHT
INFO,,SAMPLE_SIZE
INFO,,SAMPLE_SHAPE
DATATYPE,COMMENT,1
DATATYPE,TIME,2
STARTUPAXIS,X,2
STARTUPAXIS,Y1,5
[Data]
Comment,Time Stamp (sec),Temperature (K),Magnetic Field (Oe),Moment (emu),M. Std. Err. (emu),Transport Action,Averaging Time (sec),Frequency (Hz),Peak Amplitude (mm),Center Position (mm),Coil Signal' (mV),Coil Signal" (mV),Range (mV),M. Quad. Signal (emu),M. Raw' (emu),M. Raw" (emu),Min. Temperature (K),Max. Temperature (K),Min. Field (Oe),Max. Field (Oe),Mass (grams),Motor Lag (deg),Pressure (Torr),VSM Status (code),Motor Status (code),Measure Status (code),Measure Count,System Temp. (K),Temp. Status (code),Field Status (code),Chamber Status (code),Motor Current (amps),Motor Heatsink Temp. (C),Map 01,Map 02,Map 03,Map 04,Map 05,Map 06,Map 07,Map 08,Map 09,Map 10,Map 11,Map 12,Map 13,Map 14,Map 15,Map 16
,3735557555.7065,350.253646850586,99.8503227233887,6.13545026876061E-6,4.2674586963211E-7,1,0.999253354069792,40.0298881530762,1.99773377879164,14.5600000396371,6.84514677027842E-5,-2.2464009887658E-6,0.25,-1.28267102544984E-6,6.12551902459293E-6,-1.27702555221439E-6,350.253143310547,350.253143310547,99.8442764282227,99.8563690185547,54.853907851102,19.7241037262771,49.2520904541016,0,0,0,40,351.445281982422,1,4,1,2.16094970703125,44.4770278930664,,,,,,,,,,,,,,,,
,3735557706.5765,346.996597290039,99.8745193481445,6.07742347615028E-6,4.02476430792051E-7,1,0.999253354069792,40.0298881530762,1.99780760975065,14.5600000396371,6.78263238910581E-5,-2.29702234191987E-6,0.25,-1.2772200373506E-6,6.06824654578292E-6,-1.27172072880106E-6,347.012268066406,347.012268066406,99.8684692382813,99.8805694580078,54.9070585904097,19.724873619733,49.4083404541016,0,0,0,40,345.350219726562,6,4,1,2.15957641601562,44.4770278930664,,,,,,,,,,,,,,,,
,3735557850.569,343.491317749023,99.8503265380859,6.48743874815077E-6,4.57247285209785E-7,1,0.999253354069792,40.0298881530762,1.99769281814099,14.5600000396371,7.10083086008818E-5,5.53674440783342E-6,0.25,-6.2131323568248E-7,6.47798010763068E-6,-6.16684466390904E-7,343.499237060547,343.499237060547,99.8079833984375,99.8926696777344,54.9156565041212,19.7244740706239,49.5295104980469,0,0,0,40,341.581115722656,6,4,1,2.16293334960938,43.9882698059082,,,,,,,,,,,,,,,,
,3735557993.359,339.983489990234,99.9229125976563,6.6136172412115E-6,3.56023395367453E-7,1,0.999253354069792,40.0298881530762,1.99767682908707,14.5600000396371,7.29871194864951E-5,2.2760165303668E-6,0.25,-9.46365978730732E-7,6.60492959181681E-6,-9.41242956140142E-7,339.999542236328,339.999542236328,99.916862487793,99.9289627075195,54.7905959410442,19.7242080760035,49.5454330444336,0,0,0,40,337.900024414063,6,4,1,2.15911865234375,43.9882698059082,,,,,,,,,,,,,,,,
,3735558134.263,336.495147705078,99.8200836181641,6.38286318529509E-6,4.33962110327008E-7,1,0.999253354069792,40.0298881530762,1.99788549110319,14.5600000396371,7.05223644388169E-5,1.81702277206028E-6,0.25,-9.48681739439571E-7,6.37524935471017E-6,-9.43757552154348E-7,336.501708984375,336.501708984375,99.8200836181641,99.8200836181641,54.7968489691981,19.7254710650876,49.5143966674805,0,0,0,40,334.298614501953,6,4,1,2.1612548828125,43.9882698059082,,,,,,,,,,,,,,,,
,3735558276.141,332.971038818359,99.8382263183594,5.88582285444125E-6,3.20436653463148E-7,1,0.999253354069792,40.0298881530762,1.99768455421027,14.5600000396371,6.57223329576376E-5,-2.26601932942333E-6,0.25,-1.24086854729954E-6,5.87972017233256E-6,-1.2359665594043E-6,332.985443115234,332.985443115234,99.8200836181641,99.8563690185547,54.9195646467173,19.7261227052703,49.4946975708008,0,0,0,40,330.691436767578,6,4,1,2.15988159179687,44.4770278930664,,,,,,,,,,,,,,,,
,3735558416.042,329.495758056641,99.8563690185547,6.98885427063801E-6,4.51394786547635E-7,1,0.999253354069792,40.0298881530762,1.99761364381192,14.5600000396371,7.58720871257739E-5,9.72390596368803E-6,0.25,-3.20701991344784E-7,6.98175243938664E-6,-3.16208580418802E-7,329.510559082031,329.510559082031,99.8563690185547,99.8563690185547,54.8351487666404,19.7268628776427,49.4061813354492,0,0,0,40,327.151306152344,6,4,1,2.16156005859375,43.9882698059082,,,,,,,,,,,,,,,,
,3735558556.925,325.997177124023,99.8745231628418,6.44511877918673E-6,3.94241538132169E-7,1,0.999253354069792,40.0298881530762,1.99775955282683,14.5600000396371,7.08559805039173E-5,3.97968441215612E-6,0.25,-7.58994130702761E-7,6.43961557848466E-6,-7.54410346321911E-7,326.004333496094,326.004333496094,99.8442764282227,99.9047698974609,54.993037727525,19.7243217623593,49.314697265625,0,0,0,40,323.609039306641,6,4,1,2.16201782226562,44.4770278930664,,,,,,,,,,,,,,,,
,3735558697.841,322.492126464844,99.8563690185547,6.76748039217958E-6,4.04675752686798E-7,1,0.999253354069792,40.0298881530762,1.99773041812243,14.5600000396371,7.46076858558264E-5,3.03797359626517E-6,0.25,-9.02941597318902E-7,6.76258064823729E-6,-8.9808754998894E-7,322.500183105469,322.500183105469,99.8563690185547,99.8563690185547,55.0352456675635,19.7252024841986,49.2180862426758,0,0,0,40,320.055419921875,6,4,1,2.16079711914062,44.4770278930664,,,,,,,,,,,,,,,,
,3735558838.871,318.985397338867,99.8261299133301,7.0560613222607E-6,3.68842300862402E-7,1,0.999253354069792,40.0298881530762,1.99776188738641,14.5600000396371,7.81524867487605E-5,1.15326512887199E-6,0.25,-1.12849185473164E-6,7.05192167980183E-6,-1.12336073080081E-6,318.994415283203,318.994415283203,99.8079833984375,99.8442764282227,55.0946494350251,19.7257342273412,49.0569801330566,0,0,0,40,316.505065917969,6,4,1,2.16079711914062,44.9657897949219,,,,,,,,,,,,,,,,
,3735558979.724,315.478729248047,99.8261299133301,7.2852358985382E-6,3.73171618156321E-7,1,0.999253354069792,40.0298881530762,1.99776108945763,14.5600000396371,8.00280012659212E-5,5.03186471591151E-6,0.25,-8.0874667232739E-7,7.28162493908488E-6,-8.03732107644391E-7,315.486236572266,315.486236572266,99.8200836181641,99.8321762084961,54.9484849019289,19.7267339867709,48.9444465637207,0,0,0,40,312.947296142578,6,4,1,2.16293334960938,44.4770278930664,,,,,,,,,,,,,,,,
,3735559120.5715,311.978363037109,99.8261299133301,6.86962178261283E-6,4.11686827618826E-7,1,0.999253354069792,40.0298881530762,1.99778400429604,14.5600000396371,7.58521459813374E-5,2.57743449465516E-6,0.25,-9.63836425363257E-7,6.8671785197058E-6,-9.59053653999468E-7,311.993682861328,311.993682861328,99.8200836181641,99.8321762084961,54.8882995059481,19.7242719139658,48.7790184020996,0,0,0,40,309.407867431641,6,4,1,2.15927124023438,44.4770278930664,,,,,,,,,,,,,,,,
,3735559261.469,308.478561401367,99.8926658630371,6.64281792739212E-6,2.8699129980545E-7,1,0.999253354069792,40.0298881530762,1.99777890806747,14.5600000396371,7.34513835836813E-5,1.95156389625646E-6,0.25,-9.82273007621076E-7,6.64129818139394E-6,-9.77687955191721E-7,308.486053466797,308.486053466797,99.8563690185547,99.9289627075195,54.843746680352,19.7261130811962,48.624927520752,0,0,0,40,305.867614746094,6,4,1,2.1630859375,43.9882698059082,,,,,,,,,,,,,,,,
,3735559401.287,304.996459960937,99.8926696777344,6.80041042919092E-6,3.45455266339484E-7,1,0.999253354069792,40.0298881530762,1.99777847755068,14.5600000396371,7.56245773902838E-5,-4.08626731281647E-7,0.25,-1.2289070470441E-6,6.79982833280718E-6,-1.22422970390804E-6,305.002746582031,305.002746582031,99.8805694580078,99.9047698974609,54.8085733969866,19.7262609737584,48.4449272155762,0,0,0,40,302.360656738281,6,4,1,2.161865234375,44.4770278930664,,,,,,,,,,,,,,,,
,3735559542.229,301.479614257812,99.8321800231934,7.50115877511015E-6,3.60912185488473E-7,1,0.999253354069792,40.0298881530762,1.99775862016929,14.5600000396371,8.19485775294216E-5,7.98938836498113E-6,0.25,-5.72707581631993E-7,7.50092713930512E-6,-5.67709205462041E-7,301.495361328125,301.495361328125,99.8200836181641,99.8442764282227,54.9500481589674,19.727286033804,48.2592582702637,0,0,0,40,298.814331054687,6,4,1,2.1600341796875,43.9882698059082,,,,,,,,,,,,,,,,
,3735559683.139,297.967529296875,99.8745193481445,7.76081922240196E-6,4.26661442728469E-7,1,0.999253354069792,40.0298881530762,1.99773283262769,14.5600000396371,8.53346364799987E-5,5.18412752759169E-6,0.25,-8.78524993816869E-7,7.76172355654228E-6,-8.73365214505038E-7,297.976104736328,297.976104736328,99.8684692382813,99.8805694580078,54.8281141099673,19.7279380696713,48.0627975463867,0,0,0,40,295.283020019531,6,4,1,2.16217041015625,43.9882698059082,,,,,,,,,,,,,,,,
,3735559823.0645,294.485122680664,99.8926696777344,7.83296240023449E-6,4.03694725198816E-7,1,0.999253354069792,40.0298881530762,1.99779279294257,14.5600000396371,8.68866599481427E-5,9.75503539705358E-7,0.25,-1.28159614557509E-6,7.83510078581903E-6,-1.27648531313783E-6,294.493927001953,294.493927001953,99.8805694580078,99.9047698974609,54.904713704852,19.7292391312821,47.8501472473145,0,0,0,40,291.795196533203,6,4,1,2.16110229492187,43.9882698059082,,,,,,,,,,,,,,,,
,3735559962.976,290.993011474609,99.8503227233887,7.9086677489053E-6,3.65052071708991E-7,1,0.999253354069792,40.0298881530762,1.99778261381787,14.5600000396371,8.73823622011066E-5,3.00839106081924E-6,0.25,-1.10644811123314E-6,7.9116722955402E-6,-1.10131457821446E-6,291.010772705078,291.010772705078,99.8442764282227,99.8563690185547,54.9164381326404,19.7263183186033,47.6304779052734,0,0,0,40,288.284729003906,6,4,1,2.158203125,43.9882698059082,,,,,,,,,,,,,,,,
,3735560103.744,287.483856201172,99.8503227233887,7.31902145095643E-6,3.50948688596288E-7,1,0.999253354069792,40.0298881530762,1.99775211554105,14.5600000396371,8.01153069522348E-5,7.12791926206007E-6,0.25,-6.2132132920117E-7,7.3224262327319E-6,-6.16458247032704E-7,287.491577148438,287.491577148438,99.8442764282227,99.8563690185547,54.8328038810827,19.7275254551048,47.4132347106934,0,0,0,40,284.774291992187,6,4,1,2.16033935546875,44.4770278930664,,,,,,,,,,,,,,,,
,3735560243.6495,283.995040893555,99.8261299133301,7.89909023356829E-6,3.63194092585099E-7,1,0.999253354069792,40.0298881530762,1.99771637754686,14.5600000396371,8.69707297340745E-5,4.85816092667861E-6,0.25,-9.33510642940024E-7,7.90391932260957E-6,-9.28400664021676E-7,284.002532958984,284.002532958984,99.8079833984375,99.8442764282227,54.8054468829097,19.7283742753647,47.1528167724609,0,0,0,40,281.262939453125,6,4,1,2.16217041015625,44.4770278930664,,,,,,,,,,,,,,,,
,3735560384.708,280.471252441406,99.8926658630371,7.93717669146571E-6,3.87902397544257E-7,1,0.999253354069792,40.0298881530762,1.99777781766617,14.5600000396371,8.7823408403363E-5,2.48551729712404E-6,0.25,-1.16026135974929E-6,7.94317457408324E-6,-1.15530125699665E-6,280.480224609375,280.480224609375,99.8684692382813,99.916862487793,54.9234727893135,19.7288011250211,46.8586654663086,0,0,0,40,277.739959716797,6,4,1,2.1600341796875,44.4770278930664,,,,,,,,,,,,,,,,
,3735560524.458,276.988296508789,99.8926696777344,7.55723979300954E-6,3.34137746991655E-7,1,0.999253354069792,40.0298881530762,1.99769597504814,14.5600000396371,8.34253007083561E-5,3.51501831012268E-6,0.25,-9.98378659762608E-7,7.56380261115635E-6,-9.93625513382958E-7,277.004638671875,277.004638671875,99.8805694580078,99.9047698974609,55.0579128946212,19.7288492746179,46.5734176635742,0,0,0,40,274.260223388672,6,4,1,2.1636962890625,43.9882698059082,,,,,,,,,,,,,,,,
,3735560664.349,273.49543762207,99.8745193481445,7.95988197611917E-6,4.0132889591798E-7,1,0.999253354069792,40.0298881530762,1.99773415609354,14.5600000396371,8.65277659415035E-5,1.14341925466914E-5,0.25,-3.35187279524232E-7,7.96724335980382E-6,-3.29579105308107E-7,273.502990722656,273.502990722656,99.8684692382813,99.8805694580078,54.7757449991789,19.7300492817176,46.2447242736816,0,0,0,40,270.767333984375,6,4,1,2.16064453125,44.4770278930664,,,,,,,,,,,,,,,,
,3735560805.393,269.980041503906,99.8503227233887,8.20687573426131E-6,3.58863105342091E-7,1,0.999253354069792,40.0298881530762,1.9976928592081,14.5600000396371,9.02512684366202E-5,5.91623656036298E-6,0.25,-8.89975355641776E-7,8.21588423360237E-6,-8.84692855691982E-7,269.9892578125,269.9892578125,99.8442764282227,99.8563690185547,55.1016840916981,19.7302307093628,45.9162979125977,0,0,0,40,267.256011962891,6,4,1,2.16171264648438,43.9882698059082,,,,,,,,,,,,,,,,
,3735560945.119,266.485946655273,99.8382263183594,8.60486587787455E-6,3.34102974822104E-7,1,0.999253354069792,40.0298881530762,1.99760499943024,14.5600000396371,9.52146126657449E-5,2.89993695544948E-6,0.25,-1.23934071654903E-6,8.6156020711094E-6,-1.23416112654408E-6,266.495300292969,266.495300292969,99.8321762084961,99.8442764282227,54.9344155885827,19.7307294893905,45.6037979125977,0,0,0,40,263.774719238281,6,4,1,2.16018676757813,44.4770278930664,,,,,,,,,,,,,,,,
,3735561085.1535,262.9892578125,99.8987197875977,8.14381912746956E-6,3.55409592198437E-7,1,0.999253354069792,40.0298881530762,1.99753507189172,14.5600000396371,9.05116045395884E-5,5.16843071445165E-7,0.25,-1.37945128605935E-6,8.15514345663729E-6,-1.37485158177269E-6,262.997711181641,262.997711181641,99.8926696777344,99.9047698974609,54.8499997085058,19.7324496499282,45.289134979248,0,0,0,40,260.300384521484,6,4,1,2.16506958007813,44.4770278930664,,,,,,,,,,,,,,,,
,3735561224.918,259.492874145508,99.856372833252,8.27786489452571E-6,3.3348486270772E-7,1,0.999253354069792,40.0298881530762,1.99746752094931,14.5600000396371,9.06927383496608E-5,8.03934035723462E-6,0.25,-7.06182668947596E-7,8.2898455138855E-6,-7.00612162818156E-7,259.508575439453,259.508575439453,99.8442764282227,99.8684692382813,55.0008540127174,19.7319494948304,44.9903945922852,0,0,0,40,256.800170898438,6,4,1,2.14553833007813,44.4770278930664,,,,,,,,,,,,,,,,
,3735561364.9715,255.998718261719,99.8624229431152,7.99719778250859E-6,3.37190455428225E-7,1,0.999253354069792,40.0298881530762,1.99730867761647,14.5600000396371,8.89231973592689E-5,3.42792596687557E-7,0.25,-1.37009221971286E-6,8.0102994007985E-6,-1.36572119121001E-6,256.006805419922,256.006805419922,99.8079833984375,99.916862487793,55.1649960017558,19.7344994228023,44.6797828674316,0,0,0,40,253.326507568359,6,4,1,2.1533203125,44.4770278930664,,,,,,,,,,,,,,,,
,3735561505.872,252.486976623535,99.8503227233887,8.75365068204276E-6,4.24746279273291E-7,1,0.999253354069792,40.0298881530762,1.9971319494141,14.5600000396371,9.6245359408491E-5,6.60922307794045E-6,0.25,-9.22345727782366E-7,8.76859927906187E-6,-9.16688656772814E-7,252.493896484375,252.493896484375,99.8321762084961,99.8684692382813,54.9305074459866,19.7349103070668,44.3732147216797,0,0,0,40,249.804962158203,6,4,1,2.16537475585938,44.4770278930664,,,,,,,,,,,,,,,,
,3735561645.7325,248.996200561523,99.8321800231934,8.86133356876523E-6,3.06945190199544E-7,1,0.999253354069792,40.0298881530762,1.99724725278338,14.5600000396371,9.79238542292726E-5,3.9687958629447E-6,0.25,-1.18599789755414E-6,8.87775114199763E-6,-1.18070032219697E-6,249.004486083984,249.004486083984,99.7837905883789,99.8805694580078,55.0633842942558,19.7349044756568,44.076904296875,0,0,0,40,246.293518066406,6,4,1,2.16461181640625,44.4770278930664,,,,,,,,,,,,,,,,
,3735561785.5755,245.499031066895,99.8866195678711,8.67397366598797E-6,3.49196368777323E-7,1,0.999253354069792,40.0298881530762,1.99782844554827,14.5600000396371,9.48519020247596E-5,9.81596266532881E-6,0.25,-6.12096061782876E-7,8.69063516139568E-6,-6.05904279782802E-7,245.507797241211,245.507797241211,99.8805694580078,99.8926696777344,54.932070703025,19.7313204302341,43.7992172241211,0,0,0,40,242.814834594727,6,4,1,2.161865234375,43.9882698059082,,,,,,,,,,,,,,,,
,3735561926.363,241.978050231934,99.8805694580078,8.66749724587606E-6,3.37518350240994E-7,1,0.999253354069792,40.0298881530762,1.99763092910277,14.5600000396371,9.54457854137293E-5,6.03269216766356E-6,0.25,-9.61356255339375E-7,8.68549667527332E-6,-9.55806897134148E-7,241.986358642578,241.986358642578,99.8563690185547,99.9047698974609,54.9711521289866,19.7319320642446,43.5371780395508,0,0,0,40,239.291778564453,6,4,1,2.16384887695313,44.4770278930664,,,,,,,,,,,,,,,,
,3735562065.3615,238.498291015625,99.9047698974609,8.12929378779626E-6,3.58001037485073E-7,1,0.999253354069792,40.0298881530762,1.99771375481178,14.5600000396371,8.98718712678654E-5,3.72870659436778E-6,0.25,-1.08045729040118E-6,8.14730603951466E-6,-1.07561130464272E-6,238.507385253906,238.507385253906,99.9047698974609,99.9047698974609,54.9672439863904,19.7316484714222,43.2808074951172,0,0,0,40,235.830368041992,6,4,1,2.16171264648438,44.4770278930664,,,,,,,,,,,,,,,,
,3735562206.301,234.974044799805,99.8503227233887,9.24769335984542E-6,3.14394479859904E-7,1,0.999253354069792,40.0298881530762,1.99759329587761,14.5600000396371,0.000102216635223682,4.39017299801429E-6,0.25,-1.21553247572972E-6,9.26929231362046E-6,-1.20998937217448E-6,234.982299804687,234.982299804687,99.8442764282227,99.8563690185547,54.9500481589674,19.7344115677493,43.0284843444824,0,0,0,40,232.314254760742,6,4,1,2.16201782226562,43.9882698059082,,,,,,,,,,,,,,,,
,3735562346.1145,231.492866516113,99.8866195678711,8.17556654469121E-6,3.27566874936469E-7,1,0.999253354069792,40.0298881530762,1.99750340214658,14.5600000396371,9.07814680499959E-5,1.55312828638099E-6,0.25,-1.29023563869607E-6,8.19583121297579E-6,-1.28583191557623E-6,231.499664306641,231.499664306641,99.8684692382813,99.9047698974609,55.0837066357558,19.7322160548103,42.7640151977539,0,0,0,40,228.813980102539,6,4,1,2.16339111328125,44.4770278930664,,,,,,,,,,,,,,,,
,3735562485.947,227.989967346191,99.8442764282227,8.41422106316877E-6,3.56080544892464E-7,1,0.999253354069792,40.0298881530762,1.99736541462491,14.5600000396371,9.34828331228469E-5,1.334500351688E-6,0.25,-1.35248065308846E-6,8.43610775024321E-6,-1.34802187277016E-6,228.007934570313,228.007934570313,99.8442764282227,99.8442764282227,54.8335855096019,19.7339119415361,42.5251884460449,0,0,0,40,225.331481933594,6,4,1,2.16415405273438,44.4770278930664,,,,,,,,,,,,,,,,
,3735562625.838,224.491172790527,99.862419128418,9.10126513154082E-6,3.21328842076968E-7,1,0.999253354069792,40.0298881530762,1.99724293273397,14.5600000396371,9.94118835863947E-5,1.11919496617996E-5,0.25,-5.60950261561824E-7,9.12517331123432E-6,-5.53820993364793E-7,224.506271362305,224.506271362305,99.8563690185547,99.8684692382813,55.0837066357558,19.7336373525874,42.2836570739746,0,0,0,40,221.858306884766,6,4,1,2.16262817382813,44.4770278930664,,,,,,,,,,,,,,,,
,3735562765.8145,220.99976348877,99.8684730529785,8.92092844207096E-6,3.76618083543825E-7,1,0.999253354069792,40.0298881530762,1.99728807162982,14.5600000396371,9.88097627682611E-5,3.25295998082157E-6,0.25,-1.26420083306978E-6,8.94608677441014E-6,-1.25903169445532E-6,221.007110595703,221.007110595703,99.8442764282227,99.8926696777344,55.0289926394097,19.7329021931906,42.038890838623,0,0,0,40,218.36279296875,6,4,1,2.16537475585938,42.0332374572754,,,,,,,,,,,,,,,,
,3735562906.806,217.477096557617,99.8926696777344,8.94924615413632E-6,3.31543526578541E-7,1,0.999253354069792,40.0298881530762,1.99724867849287,14.5600000396371,9.90208638519187E-5,3.90402974720358E-6,0.25,-1.20913442277741E-6,8.97548414339563E-6,-1.20375950017994E-6,217.484786987305,217.484786987305,99.8805694580078,99.9047698974609,54.9633358437943,19.7318888129144,41.7927742004395,0,0,0,40,214.852096557617,6,4,1,2.16567993164062,43.9882698059082,,,,,,,,,,,,,,,,
,3735563045.688,213.992874145508,99.8805694580078,8.73411111448254E-6,3.7108229323331E-7,1,0.999253354069792,40.0298881530762,1.99715226054008,14.5600000396371,9.61741597236667E-5,6.50597042527301E-6,0.25,-9.30866133558341E-7,8.76048283560019E-6,-9.24857040035892E-7,214.000823974609,214.000823974609,99.8684692382813,99.8926696777344,55.0805801216789,19.7337493306215,41.5245323181152,0,0,0,40,211.391571044922,6,4,1,2.16552734375,44.4770278930664,,,,,,,,,,,,,,,,
,3735563185.5515,210.499717712402,99.8805694580078,9.10871274690123E-6,3.0439797423852E-7,1,0.999253354069792,40.0298881530762,1.99714511542201,14.5600000396371,0.000100087651995135,8.05361201534744E-6,0.25,-8.53695977759872E-7,9.13714312567194E-6,-8.46997756957345E-7,210.508285522461,210.508285522461,99.8684692382813,99.8926696777344,55.0868331498328,19.7329145251584,41.2686996459961,0,0,0,40,207.92497253418,6,4,1,2.16232299804687,44.4770278930664,,,,,,,,,,,,,,,,
,3735563326.4585,206.98120880127,99.8745193481445,8.79379957288468E-6,3.15404443554956E-7,1,0.999253354069792,40.0298881530762,1.9970770765544,14.5600000396371,9.71278295914829E-5,4.9696959678136E-6,0.25,-1.08392912998842E-6,8.82252518261014E-6,-1.07818114357976E-6,206.990447998047,206.990447998047,99.8563690185547,99.8926696777344,54.853907851102,19.733276804376,41.0252838134766,0,0,0,40,204.407989501953,6,4,1,2.16552734375,44.4770278930664,,,,,,,,,,,,,,,,
,3735563466.2995,203.481094360352,99.856372833252,8.65337979185439E-6,2.99435390126235E-7,1,0.999253354069792,40.0298881530762,1.99710311667186,14.5600000396371,9.53927774011883E-5,6.00815958242716E-6,0.25,-9.63489682121512E-7,8.68252131379019E-6,-9.57423102115185E-7,203.490386962891,203.490386962891,99.8442764282227,99.8684692382813,54.8875178774289,19.7338299770791,40.8066940307617,0,0,0,40,200.934219360352,6,4,1,2.1539306640625,44.4770278930664,,,,,,,,,,,,,,,,
,3735563606.1095,199.981597900391,99.8805694580078,8.73135471133982E-6,2.95078469477421E-7,1,0.999253354069792,40.0298881530762,1.99705995236672,14.5600000396371,9.63854176018754E-5,5.35521085011682E-6,0.25,-1.03781855693347E-6,8.76181225474502E-6,-1.03182025844678E-6,199.990661621094,199.990661621094,99.8805694580078,99.8805694580078,55.2462853677558,19.7326972679382,40.5387153625488,0,0,0,40,197.43196105957,6,4,1,2.1478271484375,45.4545478820801,,,,,,,,,,,,,,,,
,3735563745.9955,196.47802734375,99.9168663024902,9.01893599258735E-6,3.38283963062342E-7,1,0.999253354069792,40.0298881530762,1.99704367722066,14.5600000396371,9.99413806860936E-5,3.41929754463746E-6,0.25,-1.26759959094868E-6,9.05162205589258E-6,-1.26197730570185E-6,196.484909057617,196.484909057617,99.9047698974609,99.9289627075195,55.036808924602,19.7330973025458,40.3004264831543,0,0,0,40,193.961700439453,6,4,1,2.16140747070313,43.9882698059082,,,,,,,,,,,,,,,,
,3735563885.905,192.978271484375,99.9471092224121,8.85460076269879E-6,3.11047953305984E-7,1,0.999253354069792,40.0298881530762,1.99714456487632,14.5600000396371,9.74016625014756E-5,7.53815963790911E-6,0.25,-8.58210045776689E-7,8.88723631454042E-6,-8.51214921966503E-7,192.994003295898,192.994003295898,99.9410629272461,99.9531555175781,54.8359303951596,19.7333870753962,40.0545806884766,0,0,0,40,190.478759765625,6,4,1,2.16400146484375,44.4770278930664,,,,,,,,,,,,,,,,
,3735564025.813,189.482734680176,99.9350128173828,8.8073148207286E-6,3.29351882512844E-7,1,0.999253354069792,40.0298881530762,1.99709892880943,14.5600000396371,9.68939598554379E-5,7.47547124051042E-6,0.25,-8.55999058743539E-7,8.84073649882418E-6,-8.48902723123264E-7,189.491363525391,189.491363525391,99.9289627075195,99.9410629272461,54.7757449991789,19.7365436796752,39.799560546875,0,0,0,40,187.004043579102,6,4,1,2.1630859375,44.4770278930664,,,,,,,,,,,,,,,,
,3735564165.6835,185.988433837891,99.9289627075195,8.82536797289475E-6,3.34396957222419E-7,1,0.999253354069792,40.0298881530762,1.99681402622161,14.5600000396371,9.62424127378409E-5,1.231381656128E-5,0.25,-4.12088772715436E-7,8.85927557891103E-6,-4.03129504782443E-7,186.008117675781,186.008117675781,99.9289627075195,99.9289627075195,54.9680256149097,19.7352720350216,39.54345703125,0,0,0,40,183.528076171875,6,4,1,2.1649169921875,44.4770278930664,,,,,,,,,,,,,,,,
,3735564305.7565,182.485656738281,99.9350128173828,8.74611241269799E-6,2.37324092855814E-7,1,0.999253354069792,40.0298881530762,1.99679546776773,14.5600000396371,9.69658753025512E-5,3.22062403961652E-6,0.25,-1.23913990165704E-6,8.78164862402627E-6,-1.23327241659689E-6,182.494979858398,182.494979858398,99.9289627075195,99.9410629272461,55.0344640390443,19.7365024091483,39.286548614502,0,0,0,40,180.010971069336,6,4,1,2.16537475585938,44.4770278930664,,,,,,,,,,,,,,,,
,3735564445.6215,178.999610900879,99.9350128173828,8.70664623689812E-6,2.95590815058433E-7,1,0.999253354069792,40.0298881530762,1.99650971868883,14.5600000396371,9.58523952848091E-5,7.03519996829865E-6,0.25,-8.79827177235043E-7,8.74250178723909E-6,-8.72424973455989E-7,179.008239746094,179.008239746094,99.9289627075195,99.9410629272461,55.1009024631789,19.7376144746832,39.026668548584,0,0,0,40,176.530807495117,6,4,1,2.147216796875,43.49951171875,,,,,,,,,,,,,,,,
,3735564585.402,175.497383117676,99.9410629272461,8.59955956818046E-6,3.37034889114338E-7,1,0.999253354069792,40.0298881530762,1.99651165256729,14.5600000396371,9.5353266720135E-5,3.13840141081857E-6,0.25,-1.22157654249185E-6,8.63632061743275E-6,-1.21550726082701E-6,175.51383972168,175.51383972168,99.9410629272461,99.9410629272461,55.1196615476404,19.7352466297859,38.7592315673828,0,0,0,40,173.051513671875,6,4,1,2.16506958007813,44.4770278930664,,,,,,,,,,,,,,,,
,3735564725.3245,171.998336791992,99.9229125976563,8.71517568013757E-6,2.4441734402953E-7,1,0.999253354069792,40.0298881530762,1.9964152191934,14.5600000396371,9.6090558001927E-5,6.31018663611941E-6,0.25,-9.49048758002565E-7,8.75295237496158E-6,-9.41500153199687E-7,172.006851196289,172.006851196289,99.916862487793,99.9289627075195,54.9805316712174,19.7347965027648,38.483699798584,0,0,0,40,169.568405151367,6,4,1,2.14675903320313,44.4770278930664,,,,,,,,,,,,,,,,
,3735564865.305,168.495147705078,99.9289627075195,8.41556364293708E-6,2.90638009051245E-7,1,0.999253354069792,40.0298881530762,1.99668348160166,14.5600000396371,9.33982446980787E-5,2.74023115722596E-6,0.25,-1.22673503825532E-6,8.45331414970341E-6,-1.22054833179293E-6,168.503814697266,168.503814697266,99.916862487793,99.9410629272461,55.2314344258905,19.7397414154283,38.2114105224609,0,0,0,40,166.090850830078,6,4,1,2.14767456054687,44.9657897949219,,,,,,,,,,,,,,,,
,3735565006.1645,164.981491088867,99.9168663024902,8.63897985614992E-6,2.81395242119049E-7,1,0.999253354069792,40.0298881530762,1.99645927238095,14.5600000396371,9.54764544764236E-5,5.0912182824172E-6,0.25,-1.04910738525055E-6,8.67831224742877E-6,-1.04160831706119E-6,164.99072265625,164.99072265625,99.9047698974609,99.9289627075195,55.0938678065058,19.7414706090752,37.9221153259277,0,0,0,40,162.589309692383,6,4,1,2.16583251953125,44.4770278930664,,,,,,,,,,,,,,,,
,3735565145.9385,161.482635498047,99.9047698974609,8.92626503611116E-6,2.86159635028785E-7,1,0.999253354069792,40.0298881530762,1.9962606751342,14.5600000396371,9.94159469406744E-5,9.17358919486871E-7,0.25,-1.4857596133974E-6,8.96836029097225E-6,-1.47952992321166E-6,161.490600585938,161.490600585938,99.9047698974609,99.9047698974609,55.1220064331981,19.7449139273448,37.6522521972656,0,0,0,40,159.110656738281,6,4,1,2.15133666992187,44.4770278930664,,,,,,,,,,,,,,,,
,3735565284.96,157.999000549316,99.9229164123535,8.57094880379267E-6,3.52532943284682E-7,1,0.999253354069792,40.0298881530762,1.99613905013696,14.5600000396371,9.47428519405368E-5,4.96938810292604E-6,0.25,-1.04917641982143E-6,8.61164529813765E-6,-1.0412125302788E-6,158.007553100586,158.007553100586,99.9047698974609,99.9410629272461,55.0321191534866,19.7467341279135,37.3570175170898,0,0,0,40,155.649536132813,6,4,1,2.15057373046875,44.4770278930664,,,,,,,,,,,,,,,,
,3735565425.741,154.484359741211,99.9047660827637,8.97271204325632E-6,2.87007403969039E-7,1,0.999253354069792,40.0298881530762,1.99654697857204,14.5600000396371,9.91114411142027E-5,5.77820566130648E-6,0.25,-1.0457314531546E-6,9.01608536642726E-6,-1.03680923543881E-6,154.503387451172,154.503387451172,99.8926696777344,99.916862487793,55.0524414949866,19.7379304788843,37.071231842041,0,0,0,40,152.135879516602,6,4,1,2.16522216796875,44.4770278930664,,,,,,,,,,,,,,,,
,3735565565.679,150.98779296875,99.910816192627,9.13011504571023E-6,2.83619726525495E-7,1,0.999253354069792,40.0298881530762,1.9967191361754,14.5600000396371,0.000101247758091826,3.72171423087979E-6,0.25,-1.26397817095361E-6,9.17540551641128E-6,-1.25546396812978E-6,151.003402709961,151.003402709961,99.9047698974609,99.916862487793,54.9328523315443,19.738865494231,36.762508392334,0,0,0,40,148.680892944336,6,4,1,2.16690063476562,43.9882698059082,,,,,,,,,,,,,,,,
,3735565705.6985,147.475532531738,99.9229164123535,8.80822384894179E-6,2.62570420918103E-7,1,0.999253354069792,40.0298881530762,1.9962437616817,14.5600000396371,9.68122782909894E-5,8.43044534906577E-6,0.25,-7.7271463353791E-7,8.85198627315463E-6,-7.61954063073981E-7,147.484252929687,147.484252929687,99.9047698974609,99.9410629272461,54.9054953333712,19.7432778248913,36.4702453613281,0,0,0,40,145.218109130859,6,4,1,2.1661376953125,43.49951171875,,,,,,,,,,,,,,,,
,3735565845.589,143.970672607422,99.8866195678711,8.94161714281232E-6,2.77165381500601E-7,1,0.999253354069792,40.0298881530762,1.99628287614859,14.5600000396371,9.95150613368813E-5,1.59913218164182E-6,0.25,-1.42791022978626E-6,8.98790494850719E-6,-1.41966808609752E-6,143.979782104492,143.979782104492,99.8805694580078,99.8926696777344,55.0422803242366,19.7403994005075,36.1642189025879,0,0,0,40,141.736282348633,6,4,1,2.16567993164062,44.4770278930664,,,,,,,,,,,,,,,,
,3735565984.3825,140.49723815918,99.8866195678711,8.70979746363628E-6,3.11626192120754E-7,1,0.999253354069792,40.0298881530762,1.9965706984611,14.5600000396371,9.63087674163491E-5,5.23362561388707E-6,0.25,-1.05197473325249E-6,8.75504074215545E-6,-1.04180540759673E-6,140.506500244141,140.506500244141,99.8805694580078,99.8926696777344,55.1259145757943,19.7344079696485,35.8484802246094,0,0,0,40,138.286865234375,6,4,1,2.16522216796875,43.9882698059082,,,,,,,,,,,,,,,,
,3735566124.215,136.996025085449,99.8805694580078,8.81244342480763E-6,2.82455821383081E-7,1,0.999253354069792,40.0298881530762,1.99647706677281,14.5600000396371,9.72405961305416E-5,6.46814669140239E-6,0.25,-9.56687016138087E-7,8.8587444662066E-6,-9.45316169187652E-7,137.004440307617,137.004440307617,99.8684692382813,99.8926696777344,54.9531746730443,19.7360461301785,35.5343551635742,0,0,0,40,134.824768066406,6,4,1,2.16506958007813,44.4770278930664,,,,,,,,,,,,,,,,
,3735566264.2535,133.494560241699,99.8926658630371,8.77993436836531E-6,2.90148924017724E-7,1,0.999253354069792,40.0298881530762,1.99649162765344,14.5600000396371,9.70544843585878E-5,5.51292773931989E-6,0.25,-1.03989041894671E-6,8.82691464817812E-6,-1.02840830349168E-6,133.502960205078,133.502960205078,99.8684692382813,99.916862487793,54.9516114160058,19.7368157690894,35.206470489502,0,0,0,40,131.361694335938,6,4,1,2.15087890625,44.4770278930664,,,,,,,,,,,,,,,,
,3735566404.075,129.98583984375,99.9047660827637,8.45909359319787E-6,2.88282212065364E-7,1,0.999253354069792,40.0298881530762,1.99647311137554,14.5600000396371,9.37081998106963E-5,4.21197134051234E-6,0.25,-1.10416278448144E-6,8.50519798040186E-6,-1.09300094448105E-6,129.995986938477,129.995986938477,99.8926696777344,99.916862487793,55.2611363096212,19.7384548356128,34.8572692871094,0,0,0,40,127.895172119141,6,4,1,2.16461181640625,44.4770278930664,,,,,,,,,,,,,,,,
,3735566543.882,126.486824035645,99.8684730529785,8.23717634575885E-6,2.52531654178783E-7,1,0.999253354069792,40.0298881530762,1.99638527522438,14.5600000396371,9.07017911175073E-5,7.22044757817799E-6,0.25,-7.87912146732873E-7,8.28206643868454E-6,-7.7486508017327E-7,126.503913879395,126.503913879395,99.8442764282227,99.8926696777344,55.0446252097943,19.7362206747662,34.5272254943848,0,0,0,40,124.429824829102,6,4,1,2.15103149414062,44.4770278930664,,,,,,,,,,,,,,,,
,3735566683.802,122.989860534668,99.8866195678711,8.33263934573289E-6,2.69366643738446E-7,1,0.999253354069792,40.0298881530762,1.99644222590258,14.5600000396371,9.20942497729606E-5,5.42081917045496E-6,0.25,-9.71829743010514E-7,8.37896779252169E-6,-9.58792683013544E-7,123.00528717041,123.00528717041,99.8805694580078,99.8926696777344,54.8390569092366,19.7377369768984,34.1726226806641,0,0,0,40,120.97241973877,6,4,1,2.14691162109375,43.9882698059082,,,,,,,,,,,,,,,,
,3735566823.767,119.476760864258,99.9047660827637,8.31773893208929E-6,2.38193242083025E-7,1,0.999253354069792,40.0298881530762,1.99623479129258,14.5600000396371,9.24383560770735E-5,2.51399078173983E-6,0.25,-1.23851941751872E-6,8.36511165273259E-6,-1.2261026563033E-6,119.485855102539,119.485855102539,99.8805694580078,99.9289627075195,55.2924014503905,19.740483882366,33.7910346984863,0,0,0,40,117.51016998291,6,4,1,2.15087890625,44.9657897949219,,,,,,,,,,,,,,,,
,3735566963.6795,115.977870941162,99.8442764282227,8.42970846492273E-6,2.83710680285047E-7,1,0.999253354069792,40.0298881530762,1.9961911065785,14.5600000396371,9.35928695723469E-5,3.07606244313436E-6,0.25,-1.20741654119076E-6,8.47810325605382E-6,-1.19364504695753E-6,115.985504150391,115.985504150391,99.8442764282227,99.8442764282227,55.2720791088905,19.7409810890042,33.384349822998,0,0,0,40,114.050773620605,6,4,1,2.16720581054687,43.0107536315918,,,,,,,,,,,,,,,,
,3735567102.5985,112.493457794189,99.8805694580078,8.25009838003564E-6,2.39413843588099E-7,1,0.999253354069792,40.0298881530762,1.99627144318151,14.5600000396371,9.10278436074902E-5,6.28147971224608E-6,0.25,-8.80722867140366E-7,8.29712716092509E-6,-8.64598585175609E-7,112.509048461914,112.509048461914,99.8684692382813,99.8926696777344,54.8460915659097,19.7385124079092,32.9817123413086,0,0,0,40,110.611473083496,6,4,1,2.149658203125,44.4770278930664,,,,,,,,,,,,,,,,
,3735567242.4825,108.987453460693,99.8684730529785,8.60405547172219E-6,2.63541588702638E-7,1,0.999253354069792,40.0298881530762,1.99628663558581,14.5600000396371,9.43608105167388E-5,9.80660888270495E-6,0.25,-6.19117265963424E-7,8.65263941588091E-6,-5.99475034924884E-7,108.996047973633,108.996047973633,99.8442764282227,99.8926696777344,54.9359788456212,19.7423309007556,32.6014747619629,0,0,0,40,107.173858642578,6,4,1,2.1661376953125,44.4770278930664,,,,,,,,,,,,,,,,
,3735567382.252,105.483417510986,99.8503227233887,8.42039137614954E-6,2.68388001199568E-7,1,0.999253354069792,40.0298881530762,1.99607968860768,14.5600000396371,9.264746118281E-5,7.86153069575991E-6,0.25,-7.67453964932558E-7,8.46859914801478E-6,-7.47808951878482E-7,105.492004394531,105.492004394531,99.8442764282227,99.8563690185547,55.7168257363328,19.7435266319733,32.1934394836426,0,0,0,40,103.711982727051,6,4,1,2.15240478515625,43.9882698059082,,,,,,,,,,,,,,,,
,3735567521.2205,101.99885559082,99.8684692382813,8.5107824986693E-6,3.20426657973294E-7,1,0.999253354069792,40.0298881530762,1.99604649835929,14.5600000396371,9.44794404250929E-5,3.22908291466971E-6,0.25,-1.21280395538325E-6,8.56094951015772E-6,-1.19387636850216E-6,102.014427185059,102.014427185059,99.8684692382813,99.8684692382813,54.8054468829097,19.7421180445065,31.7794666290283,0,0,0,40,100.29704284668,6,4,1,2.152099609375,44.4770278930664,,,,,,,,,,,,,,,,
,3735567661.0585,98.484188079834,99.8382263183594,8.63888894549303E-6,2.31128171587857E-7,1,0.999253354069792,40.0298881530762,1.99575452443867,14.5600000396371,9.54920549993788E-5,5.51227863487532E-6,0.25,-1.02627864546148E-6,8.68924910014689E-6,-1.00427106558472E-6,98.5014190673828,98.5014190673828,99.8079833984375,99.8684692382813,54.6452130364673,19.7450935739077,31.344446182251,0,0,0,40,96.8405914306641,6,4,1,2.1514892578125,44.9657897949219,,,,,,,,,,,,,,,,
,3735567801.087,94.9741020202637,99.8382263183594,8.66399655316394E-6,2.36527955588489E-7,1,0.999253354069792,40.0298881530762,1.99563356160054,14.5600000396371,9.50873622748517E-5,9.32498239352828E-6,0.25,-6.80315693635506E-7,8.71321817872384E-6,-6.54472373464887E-7,94.9844284057617,94.9844284057617,99.8321762084961,99.8442764282227,54.9688072434289,19.7500565854993,30.8832473754883,0,0,0,40,93.399658203125,6,4,1,2.15240478515625,44.4770278930664,,,,,,,,,,,,,,,,
,3735567939.95,91.4929046630859,99.856372833252,8.72891287302502E-6,2.29335673311464E-7,1,0.999253354069792,40.0298881530762,1.99549136780646,14.5600000396371,9.65104426524019E-5,5.34791647949014E-6,0.25,-1.06133045182726E-6,8.77951019386304E-6,-1.03521386405058E-6,91.5007247924805,91.5007247924805,99.8321762084961,99.8805694580078,54.4294835651596,19.7476493399188,30.3885879516602,0,0,0,40,89.984992980957,6,4,1,2.154541015625,44.9657897949219,,,,,,,,,,,,,,,,
,3735568079.7595,87.9805450439453,99.8684692382813,8.13581339293955E-6,2.84405304737869E-7,1,0.999253354069792,40.0298881530762,1.99555578425797,14.5600000396371,8.97298226637366E-5,6.22102947200545E-6,0.25,-8.77104732414541E-7,8.18205989465681E-6,-8.49936657924532E-7,87.9894256591797,87.9894256591797,99.8684692382813,99.8684692382813,54.6022234679096,19.7570334963208,29.8421497344971,0,0,0,40,86.5295867919922,6,4,1,2.15362548828125,44.4770278930664,,,,,,,,,,,,,,,,
,3735568218.69,84.4980354309082,99.8805694580078,8.58945571951102E-6,2.50557117947458E-7,1,0.999253354069792,40.0298881530762,1.99542511343459,14.5600000396371,9.47260782181814E-5,6.52324433365806E-6,0.25,-9.32562829531002E-7,8.63748935692316E-6,-9.01298516239468E-7,84.5058670043945,84.5058670043945,99.8563690185547,99.9047698974609,54.830458995525,19.755700653677,29.1642837524414,0,0,0,40,83.1183319091797,6,4,1,2.1533203125,44.9657897949219,,,,,,,,,,,,,,,,
,3735568358.7005,80.9708824157715,99.8503227233887,8.36189004919241E-6,3.02709879640493E-7,1,0.999253354069792,40.0298881530762,1.99548905593803,14.5600000396371,9.15108755700261E-5,1.02338555990169E-5,0.25,-5.51502187985889E-7,8.40586831860932E-6,-5.16410175566214E-7,80.9802627563477,80.9802627563477,99.8321762084961,99.8684692382813,55.1509266884097,19.7593237291374,28.4646453857422,0,0,0,40,79.6734848022461,6,4,1,2.154541015625,43.9882698059082,,,,,,,,,,,,,,,,
,3735568497.4935,77.4909057617187,99.856372833252,8.36117334919718E-6,2.70668711133432E-7,1,0.999253354069792,40.0298881530762,1.99566827407132,14.5600000396371,9.27870782055222E-5,3.01611223613027E-6,0.25,-1.22168735747018E-6,8.40667827740275E-6,-1.18667812296782E-6,77.5066070556641,77.5066070556641,99.8442764282227,99.8684692382813,55.0149233260635,19.7530042996097,27.7744140625,0,0,0,40,76.2666702270508,6,4,1,2.15164184570313,44.4770278930664,,,,,,,,,,,,,,,,
,3735568637.4475,73.9792251586914,99.8019332885742,8.26702950702611E-6,2.1884794767169E-7,1,0.999253354069792,40.0298881530762,1.99583784638559,14.5600000396371,9.17124797976833E-5,3.0630318736751E-6,0.25,-1.20368496732656E-6,8.30993285884401E-6,-1.16546668471968E-6,73.9867553710937,73.9867553710937,99.7958831787109,99.8079833984375,55.0031988982751,19.7508653392865,27.0444507598877,0,0,0,40,72.8172454833984,6,4,1,2.15042114257813,44.4770278930664,,,,,,,,,,,,,,,,
,3735568776.1725,70.4912796020508,99.7595939636231,8.66969350429614E-6,3.34510373527027E-7,1,0.999253354069792,40.0298881530762,1.99585605317558,14.5600000396371,9.55301226526894E-5,6.64129120810204E-6,0.25,-9.48528472453531E-7,8.7100020061727E-6,-9.03116110894012E-7,70.5008926391602,70.5008926391602,99.7474975585938,99.7716903686523,54.5576706423135,19.7485942076949,26.2696495056152,0,0,0,40,69.407958984375,6,4,1,2.15408325195313,43.9882698059082,,,,,,,,,,,,,,,,
,3735568915.245,66.9955520629883,99.7777404785156,8.11547792452724E-6,2.22698489867421E-7,1,0.999253354069792,40.0298881530762,1.99570409407654,14.5600000396371,9.0129513036489E-5,2.04628922735633E-6,0.25,-1.27730770031271E-6,8.15187329188547E-6,-1.23225842972385E-6,67.0059356689453,67.0059356689453,99.7716903686523,99.7837905883789,54.8695404214866,19.755493258546,25.4810314178467,0,0,0,40,66.0012664794922,6,4,1,2.1514892578125,44.4770278930664,,,,,,,,,,,,,,,,
,3735569054.173,63.4992542266846,99.8019332885742,8.23325838016269E-6,2.52289934919419E-7,1,0.999253354069792,40.0298881530762,1.99539838315433,14.5600000396371,9.1352099843482E-5,2.19049823223764E-6,0.25,-1.28866962947222E-6,8.26548581873697E-6,-1.23866310455099E-6,63.5085105895996,63.5085105895996,99.7958831787109,99.8079833984375,54.7116514606019,19.760580876213,24.6528911590576,0,0,0,40,62.5891494750977,6,4,1,2.1527099609375,44.4770278930664,,,,,,,,,,,,,,,,
,3735569193.8945,59.9915809631348,99.8866195678711,8.21282248802138E-6,2.79085459850482E-7,1,0.999253354069792,40.0298881530762,1.99541205474631,14.5600000396371,9.02609603344612E-5,6.59279393823713E-6,0.25,-8.79746309763497E-7,8.2363207768851E-6,-8.24847479467618E-7,60.0022850036621,60.0022850036621,99.8684692382813,99.9047698974609,54.8882995059481,19.7595778547194,23.8084850311279,0,0,0,40,59.1457786560059,6,4,1,2.13973999023438,44.4770278930664,,,,,,,,,,,,,,,,
,3735569333.773,56.4789581298828,99.8866195678711,7.92804842014896E-6,2.66989356695046E-7,1,0.999253354069792,40.0298881530762,1.99567798874196,14.5600000396371,8.70981912343981E-5,6.18329018489691E-6,0.25,-8.68109971818071E-7,7.94390538880527E-6,-8.11924038597459E-7,56.4872207641602,56.4872207641602,99.8805694580078,99.8926696777344,54.7827796558519,19.7608682005003,22.9196224212646,0,0,0,40,55.7003326416016,6,4,1,2.15469360351562,44.4770278930664,,,,,,,,,,,,,,,,
,3735569471.7115,52.9893836975098,99.8745193481445,8.44835137558849E-6,2.79053670493093E-7,1,0.999253354069792,40.0298881530762,1.99517095282876,14.5600000396371,9.25811565408688E-5,7.23036390516828E-6,0.25,-8.66349470017466E-7,8.45636876676333E-6,-8.03966249878678E-7,53.0052909851074,53.0052909851074,99.8563690185547,99.8926696777344,54.8828281063135,19.7642512823301,22.02366065979,0,0,0,40,52.2966575622559,6,4,1,2.15469360351562,44.4770278930664,,,,,,,,,,,,,,,,
,3735569610.566,49.4855842590332,99.8805694580078,8.11163113456282E-6,2.4836083904622E-7,1,0.999253354069792,40.0298881530762,1.9952766741785,14.5600000396371,8.97639226420857E-5,1.63741554221334E-6,0.25,-1.32506876763632E-6,8.1141633537364E-6,-1.26360476165995E-6,49.4958534240723,49.4958534240723,99.8563690185547,99.9047698974609,54.6499028075827,19.7646117882172,21.0990581512451,0,0,0,40,48.877311706543,6,4,1,2.1527099609375,44.4770278930664,,,,,,,,,,,,,,,,
,3735569749.598,45.981819152832,99.8805694580078,7.81082215956228E-6,2.21985451024277E-7,1,0.999253354069792,40.0298881530762,1.99531548786738,14.5600000396371,8.56071190890295E-5,5.60379101538336E-6,0.25,-8.99525340534686E-7,7.80181303419731E-6,-8.40840457581085E-7,45.9890022277832,45.9890022277832,99.8684692382813,99.8926696777344,55.2759872514866,19.7657699328812,20.1534671783447,0,0,0,40,45.4353446960449,6,4,1,2.14035034179687,44.9657897949219,,,,,,,,,,,,,,,,
,3735569888.3975,42.4710597991943,99.8805694580078,7.86364027460578E-6,2.59463544978474E-7,1,0.999253354069792,40.0298881530762,1.99561877901032,14.5600000396371,8.65532914198031E-5,3.18253409540786E-6,0.25,-1.13204624850656E-6,7.84787161918327E-6,-1.07372935820297E-6,42.4783210754395,42.4783210754395,99.8684692382813,99.8926696777344,54.6381783797942,19.7671796480332,19.1717739105225,0,0,0,40,42.0089797973633,6,4,1,2.15225219726562,43.9882698059082,,,,,,,,,,,,,,,,
,3735570026.2445,38.9974803924561,99.8745193481445,8.1504246897477E-6,2.05953508479093E-7,1,0.999253354069792,40.0298881530762,1.99551213045123,14.5600000396371,8.96466467041524E-5,3.1551564353193E-6,0.25,-1.18309654521905E-6,8.12654396921366E-6,-1.12487472680661E-6,39.0066719055176,39.0066719055176,99.8684692382813,99.8805694580078,54.871103678525,19.7583838160381,18.1593971252441,0,0,0,40,38.6047706604004,6,4,1,2.15087890625,44.4770278930664,,,,,,,,,,,,,,,,
,3735570165.2475,35.4965324401855,99.8684692382813,8.33171811331335E-6,2.1496319715602E-7,1,0.999253354069792,40.0298881530762,1.99558535366124,14.5600000396371,9.13490452151742E-5,4.45574298148685E-6,0.25,-1.09051071874515E-6,8.30008021502658E-6,-1.03441873520872E-6,35.5043640136719,35.5043640136719,99.8684692382813,99.8684692382813,54.3614818839865,19.7616545793593,17.1312961578369,0,0,0,40,35.157299041748,6,4,1,2.15225219726562,43.9882698059082,,,,,,,,,,,,,,,,
,3735570304.1525,31.9952707290649,99.8866195678711,8.05184609866632E-6,2.87456238796077E-7,1,0.999253354069792,40.0298881530762,1.99554531124219,14.5600000396371,8.79841828865708E-5,5.64188329278942E-6,0.25,-9.25327148307344E-7,8.01572184465846E-6,-8.74680654044631E-7,32.0045318603516,32.0045318603516,99.8805694580078,99.8926696777344,54.9578644441597,19.766441075517,16.0673599243164,0,0,0,40,31.7143287658691,6,4,1,2.15286254882813,43.9882698059082,,,,,,,,,,,,,,,,
,3735570443.9605,28.4759244918823,99.9047660827637,8.25283878298603E-6,2.41869612889609E-7,1,0.999253354069792,40.0298881530762,1.9954817262105,14.5600000396371,9.00879876307608E-5,6.06272870217919E-6,0.25,-9.18934631164835E-7,8.21213053869726E-6,-8.69859418099415E-7,28.4838600158691,28.4838600158691,99.8684692382813,99.9410629272461,54.6819495768712,19.7662187939376,14.9746570587158,0,0,0,40,28.2426910400391,6,4,1,2.15103149414062,44.4770278930664,,,,,,,,,,,,,,,,
,3735570582.97,24.9875650405884,99.8442726135254,8.23960895800974E-6,2.67781617729227E-7,1,0.999253354069792,40.0298881530762,1.99539147538557,14.5600000396371,8.99989259449198E-5,5.58148877681263E-6,0.25,-9.59076033620483E-7,8.19689399471304E-6,-9.11857852416854E-7,24.9969635009766,24.9969635009766,99.8321762084961,99.8563690185547,54.7483880010058,19.766011582286,13.8596868515015,0,0,0,40,24.79931640625,6,4,1,2.14859008789062,44.4770278930664,,,,,,,,,,,,,,,,
,3735570721.83,21.4970560073853,99.8745193481445,8.49434971029466E-6,2.36704072687896E-7,1,0.999253354069792,40.0298881530762,1.995393943067,14.5600000396371,9.32503974333135E-5,3.06002688750932E-6,0.25,-1.23901045858119E-6,8.45021381362741E-6,-1.19015969434893E-6,21.5058193206787,21.5058193206787,99.8684692382813,99.8805694580078,55.0235212397751,19.7654496217272,12.7120056152344,0,0,0,40,21.348819732666,6,4,1,2.1551513671875,43.9882698059082,,,,,,,,,,,,,,,,
,3735570861.615,17.9815702438354,99.8805694580078,8.09625738878447E-6,2.31709882691673E-7,1,0.999253354069792,40.0298881530762,1.99532087682889,14.5600000396371,8.84957761751201E-5,5.01345027562911E-6,0.25,-9.8433539584117E-7,8.05279745714036E-6,-9.39442087062784E-7,17.9907855987549,17.9907855987549,99.8805694580078,99.8805694580078,54.8374936521981,19.7681641384349,11.4861249923706,0,0,0,40,17.8669242858887,6,4,1,2.14096069335938,44.4770278930664,,,,,,,,,,,,,,,,
,3735571001.745,14.464216709137,99.8987197875977,8.43823306489263E-6,2.65203118209187E-7,1,0.999253354069792,40.0298881530762,1.99552161211749,14.5600000396371,9.16200298087881E-5,8.70035003023489E-6,0.25,-7.01137225779207E-7,8.39146750459769E-6,-6.56282500393629E-7,14.4720420837402,14.4720420837402,99.8926696777344,99.9047698974609,54.6491211790635,19.7696280154196,10.2138090133667,0,0,0,40,14.3886709213257,6,4,1,2.13775634765625,44.4770278930664,,,,,,,,,,,,,,,,
,3735571140.453,10.9907336235046,99.8926658630371,8.22197226155672E-6,2.1594280334967E-7,1,0.999253354069792,40.0298881530762,1.99563686019419,14.5600000396371,8.92398798203077E-5,8.68758348738184E-6,0.25,-6.6356947831142E-7,8.17637300033588E-6,-6.19985512461543E-7,11.0071229934692,11.0071229934692,99.8684692382813,99.916862487793,54.7351003161789,19.7633108105493,3.70280289649963,0,0,0,40,10.9192762374878,6,4,1,2.15362548828125,43.9882698059082,,,,,,,,,,,,,,,,
,3735571282.288,7.47962737083435,99.8926658630371,8.24468246274203E-6,2.4632462329582E-7,1,0.999253354069792,40.0298881530762,1.99551342536368,14.5600000396371,9.07126069558998E-5,1.85149714688245E-6,0.25,-1.30659029882294E-6,8.20208728545685E-6,-1.25908625644912E-6,7.4950270652771,7.4950270652771,99.8563690185547,99.9289627075195,54.8554711081404,19.7679721361781,7.9688549041748,0,0,0,40,7.42098426818848,6,4,1,2.1533203125,44.9657897949219,,,,,,,,,,,,,,,,
,3735571455.1785,4.99973964691162,99.8866195678711,8.20254448202917E-6,2.71338716821648E-7,1,0.999253354069792,40.0298881530762,1.9953993448995,14.5600000396371,8.94685293059058E-5,6.16402867661795E-6,0.25,-8.95892427476488E-7,8.15823060054317E-6,-8.51028460874356E-7,4.99984645843506,4.99984645843506,99.8805694580078,99.8926696777344,54.8570343651789,19.7682091467245,6.33427095413208,0,0,0,40,4.99128150939941,1,4,1,2.15377807617187,44.9657897949219,,,,,,,,,,,,,,,,