File: defense/images/np_vsm/data_dispersion/AH11_HYST_100OE_10K.DAT
[Header]
; VSM Data File (default extension .dat)
; Copyright (c) 2003-2013, Quantum Design, Inc. All rights reserved.
TITLE,
FILEOPENTIME,20366662.36,08/25/2018,2:23 am
BYAPP,VSM,2.0,2.0
INFO,PPMS VSM Option Release 1.4.10 Build 1,APPNAME
INFO,Quantum Design Linear Motor Servo Controller,MOTOR_MODULE_NAME
INFO,3101-100 M1,MOTOR_HW_VERSION
INFO,MMC1014,MOTOR_SERIAL_NUMBER
INFO,SRV No X-over 01.03.11,MOTOR_SOFTWARE_VERSION
INFO,Quantum Design VSM Detection Module,VSM_MODULE_NAME
INFO,3101-150 F0,VSM_HW_VERSION
INFO,VSM707,VSM_SERIAL_NUMBER
INFO,VSM No X-over 01.02.05 May 20 2008 13:51:47,VSM_SOFTWARE_VERSION
INFO,704,PREAMP_SERIAL_NUMBER
INFO,822,COIL_SERIAL_NUMBER
INFO,0,MOMENT_UNITS
INFO,CoFe2O4,SAMPLE_MATERIAL
INFO,Cobalt deficient,SAMPLE_COMMENT
INFO,,SAMPLE_MASS
INFO,27,SAMPLE_VOLUME
INFO,,SAMPLE_MOLECULAR_WEIGHT
INFO,,SAMPLE_SIZE
INFO,,SAMPLE_SHAPE
DATATYPE,COMMENT,1
DATATYPE,TIME,2
STARTUPAXIS,X,2
STARTUPAXIS,Y1,5
[Data]
Comment,Time Stamp (sec),Temperature (K),Magnetic Field (Oe),Moment (emu),M. Std. Err. (emu),Transport Action,Averaging Time (sec),Frequency (Hz),Peak Amplitude (mm),Center Position (mm),Coil Signal' (mV),Coil Signal" (mV),Range (mV),M. Quad. Signal (emu),M. Raw' (emu),M. Raw" (emu),Min. Temperature (K),Max. Temperature (K),Min. Field (Oe),Max. Field (Oe),Mass (grams),Motor Lag (deg),Pressure (Torr),VSM Status (code),Motor Status (code),Measure Status (code),Measure Count,PPMS Status (code),System Temp. (K),System Field (Oe),Sample Position (deg),Bridge 1 Resistance (ohms),Bridge 1 Excitation (에),Bridge 2 Resistance (ohms),Bridge 2 Excitation (에),Bridge 3 Resistance (ohms),Bridge 3 Excitation (에),Bridge 4 Resistance (ohms),Bridge 4 Excitation (에),Signal 1 Vin (V),Signal 2 Vin (V),Digital Inputs (code),Drive 1 Iout (mA),Drive 1 Ipower (W),Drive 2 Iout (mA),Drive 2 Ipower (W),Pressure (),Map 20 (),Map 21 (),Map 22 (),Map 23 (),Map 24 (),Map 25 (),Map 26 (),Map 27 (),Map 28 (),Map 29 ()
,20366679.78,9.9618988,99.4721298217773,,,2,,,,23.9799995416403,,,,,,,9.9618988,9.9618988,99.4721298217773,99.4721298217773,,,6.204359,,,,-99999999,4885,9.8448,99.4721298217773,,,,,,,,,,,,,,,,,,,,,,,9.9618988,,,,
,20366901.225,9.84495,3268.64013671875,0.00119884774808296,3.8861839563031E-7,1,0.999253354069792,40.0298881530762,2.0004660890759,23.9599999040365,0.013483184692665,0.00245553186609156,0.25,5.05314141933656E-6,0.0011921333094649,1.10279508146218E-5,9.8457,9.8457,3243.79125976562,3293.48901367188,54.7468247439673,19.7174612004718,6.58401,0,0,0,40,4961,9.84495,3268.64013671875,,,,,,,,,,,,,0,,,,,,,,,,,,,,
,20366970.58,9.8453,6727.87548828125,0.00147604061650427,3.64182985412837E-7,1,0.999253354069792,40.0298881530762,1.99967584335998,23.9599999040365,0.0165970636126599,0.00303011327208133,0.25,6.50382410981428E-6,0.00146811513389194,1.42220289013202E-5,9.8448,9.8448,6693.0546875,6762.6962890625,55.0031988982751,19.737634599102,6.58401,0,0,0,40,4961,9.8453,6727.87548828125,,,,,,,,,,,,,0,,,,,,,,,,,,,,
,20367039.07,9.84425,10154.2827148438,0.00176310844131098,4.93551056621524E-7,1,0.999253354069792,40.0298881530762,2.00048520060936,23.9599999040365,0.0198379548451224,0.00362137091419594,0.25,7.2861632127345E-6,0.00175410863499007,1.69557778882978E-5,9.8447,9.8447,10131.6611328125,10176.904296875,55.1188799191212,19.7104157400111,6.58401,0,0,0,40,4961,9.84425,10154.2827148438,,,,,,,,,,,,,0,,,,,,,,,,,,,,
,20367106.7,9.84425,13535.021484375,0.00208974222090432,7.03661906160162E-7,1,0.999253354069792,40.0298881530762,2.00038992586111,23.9599999040365,0.0235148157071396,0.00431584050003816,0.25,1.01208021559843E-5,0.0020796621842783,2.20939660892758E-5,9.8445,9.8445,13510.0244140625,13560.0185546875,55.250193510352,19.7237708521231,6.58401,0,0,0,40,4961,9.84425,13535.021484375,,,,,,,,,,,,,0,,,,,,,,,,,,,,
,20367174.7,9.84705,16932.869140625,0.00248761294042928,5.27969354964238E-7,1,0.999253354069792,40.0298881530762,2.00040578544748,23.9499993622303,0.0279992112469606,0.00514768489714851,0.25,1.22091468955952E-5,0.00247637572197686,2.7060851694831E-5,9.8474,9.8474,16902.87109375,16962.8671875,55.9708550050828,19.7109912620516,6.58401,0,0,0,40,4961,9.84705,16932.869140625,,,,,,,,,,,,,0,,,,,,,,,,,,,,
,20367242.58,9.84865,20323.6103515625,0.0029758974049656,9.00630509477043E-7,1,0.999253354069792,40.0298881530762,2.00013803751988,23.9599999040365,0.0335032376941689,0.00615072905146282,0.25,1.31744903889088E-5,0.0029634236388504,3.16234802290045E-5,9.8487,9.8487,20296.109375,20351.111328125,54.9289441889481,19.7190244667571,6.58401,0,0,0,40,4961,9.84865,20323.6103515625,,,,,,,,,,,,,0,,,,,,,,,,,,,,
,20367309.915,9.84685,23692.2021484375,0.00351568021338635,9.64014499976634E-7,1,0.999253354069792,40.0298881530762,1.99979551766139,23.9599999040365,0.0395835305470708,0.00728737719280339,0.25,1.65900475350459E-5,0.00350211081792945,3.91172386424062E-5,9.8469,9.8469,23669.73046875,23714.673828125,55.3994845575251,19.7296426298874,6.963661,0,0,0,40,4961,9.84685,23692.2021484375,,,,,,,,,,,,,0,,,,,,,,,,,,,,
,20367378.92,9.8502,27140.607421875,0.004044810340812,1.01990652229615E-6,1,0.999253354069792,40.0298881530762,2.00025283937219,23.9599999040365,0.0455636147926627,0.00840878188748622,0.25,2.00668602709382E-5,0.00403061571989705,4.67714287652575E-5,9.8504,9.8504,27137.8515625,27143.36328125,55.9309919506021,19.7118535448211,6.204359,0,0,0,40,4961,9.8502,27140.607421875,,,,,,,,,,,,,0,,,,,,,,,,,,,,
,20367446.39,9.8498,30511.2646484375,0.00447133058583398,1.18980480190397E-6,1,0.999253354069792,40.0298881530762,2.00026705998283,23.9599999040365,0.0503845764656828,0.00930890602286437,0.25,2.23269331406962E-5,0.00445720800216503,5.26126199031064E-5,9.8501,9.8501,30481.328125,30541.201171875,55.1814102006597,19.7117148567406,6.58401,0,0,0,40,4961,9.8498,30511.2646484375,,,,,,,,,,,,,0,,,,,,,,,,,,,,
,20367515.485,9.8535,33964.484375,0.00480461787350005,1.26454012225777E-6,1,0.999253354069792,40.0298881530762,2.00010777957256,23.9599999040365,0.0541558557619812,0.0100059062361696,0.25,2.32878924561109E-5,0.00479119691593012,5.65746634268467E-5,9.8541,9.8541,33939.56640625,33989.40234375,55.5409593195059,19.7194602977317,6.58401,0,0,0,40,4961,9.8535,33964.484375,,,,,,,,,,,,,0,,,,,,,,,,,,,,
,20367584.265,9.85325,37402.62109375,0.00505854689631522,1.16801989425332E-6,1,0.999253354069792,40.0298881530762,2.00018385354776,23.9599999040365,0.0570366534066716,0.0105631548311912,0.25,2.60128065805314E-5,0.00504624918486656,6.17243370055764E-5,9.8533,9.8533,37372.5390625,37432.703125,55.1352941180251,19.7225643069415,6.204359,0,0,0,40,4961,9.85325,37402.62109375,,,,,,,,,,,,,0,,,,,,,,,,,,,,
,20367653.41,9.85615,40856.02734375,0.00525682025032237,9.74205332606748E-7,1,0.999253354069792,40.0298881530762,2.00168862566003,23.9599999040365,0.0593363887946803,0.0109900428499656,0.25,2.65512258746358E-5,0.00524596435631444,6.42508404470861E-5,9.8559,9.8559,40831.0625,40880.9921875,54.5365666722942,19.7097842490753,6.58401,0,0,0,40,4961,9.85615,40856.02734375,,,,,,,,,,,,,0,,,,,,,,,,,,,,
,20367722.85,9.86225,44328.77734375,0.00541644220884644,1.43162830249033E-6,1,0.999253354069792,40.0298881530762,2.00054044252956,23.9599999040365,0.0611235216021359,0.0113411228249759,0.25,2.86053480349179E-5,0.00540722202584267,6.79430064687767E-5,9.8618,9.8618,44298.91015625,44358.64453125,54.6999270328135,19.7112179949312,6.58401,0,0,0,40,4961,9.86225,44328.77734375,,,,,,,,,,,,,0,,,,,,,,,,,,,,
,20367790.495,9.8614,47709.9921875,0.00554051067254783,1.40501526354051E-6,1,0.999253354069792,40.0298881530762,2.0002817069904,23.9599999040365,0.0625363642655628,0.0116118620212007,0.25,2.96336133352919E-5,0.0055330174817783,7.02588402308231E-5,9.8616,9.8616,47682.640625,47737.34375,55.2619179381405,19.7192016997596,6.58401,0,0,0,40,4961,9.8614,47709.9921875,,,,,,,,,,,,,0,,,,,,,,,,,,,,
,20367859.71,9.8662,51168.130859375,0.00565391851587205,1.38853930185061E-6,1,0.999253354069792,40.0298881530762,2.00200232433602,23.9599999040365,0.0638889878499164,0.0118763896817567,0.25,3.11103143828678E-5,0.00564825544883665,7.28649114949491E-5,9.8661,9.8661,51135.625,51200.63671875,54.6499028075827,19.68586950476,6.204359,0,0,0,40,4961,9.8662,51168.130859375,,,,,,,,,,,,,0,,,,,,,,,,,,,,
,20367935.81,9.8782,54970.90234375,0.005759490826741,1.5164099939021E-6,1,0.999253354069792,40.0298881530762,2.00097798637497,23.9599999040365,0.0650757091146623,0.012091815896413,0.25,3.10587436778762E-5,0.00575590377491934,7.38111370017798E-5,9.8774,9.8774,54938.54296875,55003.26171875,55.9833610613905,19.713609482135,6.58401,0,0,0,40,4961,9.8782,54970.90234375,,,,,,,,,,,,,0,,,,,,,,,,,,,,
,20368011.495,9.88365,58754.4375,0.00584562266825573,1.96060771714478E-6,1,0.999253354069792,40.0298881530762,2.00137984094794,23.9599999040365,0.0660822700330288,0.0122985691588734,0.25,3.31312193717899E-5,0.00584410529303382,7.66283851653884E-5,9.8839,9.8839,58726.76171875,58782.11328125,55.1352941180251,19.6989385514117,6.58401,0,0,0,40,4961,9.88365,58754.4375,,,,,,,,,,,,,0,,,,,,,,,,,,,,
,20368087.27,9.8876,62542.8203125,0.00591428504620233,1.74941644184915E-6,1,0.999253354069792,40.0298881530762,2.0016919908871,23.9599999040365,0.066887597533917,0.0124741470011517,0.25,3.57409453124144E-5,0.00591482571102076,7.97523260670195E-5,9.8875,9.8875,62510.3828125,62575.2578125,55.2064223132751,19.6963394337446,6.58401,0,0,0,40,4961,9.8876,62542.8203125,,,,,,,,,,,,,0,,,,,,,,,,,,,,
,20368162.62,9.89185,66310.5859375,0.00597898906555698,2.27980142839412E-6,1,0.999253354069792,40.0298881530762,2.0017208403833,23.9599999040365,0.0676434508376682,0.0126137798587762,0.25,3.61365143522659E-5,0.00598156340773778,8.05385574066668E-5,9.8925,9.8925,66278.203125,66342.96875,55.5534653758136,19.6847729716013,6.204359,0,0,0,40,4961,9.89185,66310.5859375,,,,,,,,,,,,,0,,,,,,,,,,,,,,
,20368239.29,9.9021,70138.81640625,0.00602802808578033,1.53466505898583E-6,1,0.999253354069792,40.0298881530762,2.0011522917041,23.9499993622303,0.0682018750147305,0.0127204368796664,0.25,3.68551512357845E-5,0.00603261582021762,8.14418377357182E-5,9.9021,9.9021,70136.421875,70141.2109375,55.2861484222366,19.6961830682138,6.204359,0,0,0,40,4961,9.9021,70138.81640625,,,,,,,,,,,,,0,,,,,,,,,,,,,,
,20368316.32,9.90015,73991.3125,0.00606670458509934,1.79309013496175E-6,1,0.999253354069792,40.0298881530762,2.00104298138287,23.9599999040365,0.0686571314846961,0.0128088462274692,0.25,3.7676595787304E-5,0.00607325259624794,8.22895846275686E-5,9.9005,9.9005,73988.9609375,73993.6640625,54.7538594006404,19.7067807097803,6.58401,0,0,0,40,4961,9.90015,73991.3125,,,,,,,,,,,,,0,,,,,,,,,,,,,,
,20368391.46,9.9032,77748.38671875,0.00609932642981693,2.43463009577252E-6,1,0.999253354069792,40.0298881530762,2.00091418325979,23.9599999040365,0.0690413639629185,0.0128872842154602,0.25,3.88015385787175E-5,0.00610771592105976,8.3334088243571E-5,9.9033,9.9033,77718.46875,77778.3046875,55.4667046101789,19.7047949269404,6.204359,0,0,0,40,4961,9.9032,77748.38671875,,,,,,,,,,,,,0,,,,,,,,,,,,,,
,20368468.72,9.90855,81609.47265625,0.00612160646702628,1.99251887363686E-6,1,0.999253354069792,40.0298881530762,2.00112815524077,23.9599999040365,0.0693272991174186,0.0129030964580471,0.25,3.61522662470097E-5,0.00613182986690446,8.04519298562145E-5,9.9082,9.9082,81576.7265625,81642.21875,55.4729576383328,19.7041452341102,6.204359,0,0,0,40,4961,9.90855,81609.47265625,,,,,,,,,,,,,0,,,,,,,,,,,,,,
,20368544.14,9.91345,85380.24609375,0.00613663341750895,2.0677490990676E-6,1,0.999253354069792,40.0298881530762,2.00165729211612,23.9599999040365,0.0695213215787804,0.0130106633353318,0.25,4.27902757311541E-5,0.00614849624911326,8.67785926512399E-5,9.913,9.913,85345.234375,85415.2578125,55.7176073648521,19.700853956651,6.58401,0,0,0,40,4961,9.91345,85380.24609375,,,,,,,,,,,,,0,,,,,,,,,,,,,,
,20368616.085,9.91865,88976.0234375,0.00614896675462382,1.89775212276209E-6,1,0.999253354069792,40.0298881530762,2.0019681616227,23.9599999040365,0.0696976723195146,0.01299050849386,0.25,3.88156180704552E-5,0.0061623937078557,8.24322550996393E-5,9.9176,9.9176,88943.3203125,89008.7265625,54.2723762327942,19.6937999071316,6.58401,0,0,0,40,4961,9.91865,88976.0234375,,,,,,,,,,,,,0,,,,,,,,,,,,,,
,20368703.72,9.92305,87383.44921875,0.00615173698015625,2.20148764747661E-6,1,0.999253354069792,40.0298881530762,2.00239915696165,23.9599999040365,0.0697390627926382,0.0129802731952229,0.25,3.70898315424301E-5,0.00616452176314192,8.09269921246268E-5,9.9234,9.9234,87348.40625,87418.4921875,54.7921591980827,19.6757646488119,6.204359,0,0,0,40,4961,9.92305,87383.44921875,,,,,,,,,,,,,0,,,,,,,,,,,,,,
,20368775.085,9.92125,83819.484375,0.0061418808773487,1.76403124540165E-6,1,0.999253354069792,40.0298881530762,2.00149353293977,23.9599999040365,0.0695732016228508,0.0129886774285545,0.25,3.99298471374023E-5,0.00615309622024342,8.41344927843882E-5,9.9209,9.9209,83789.4140625,83849.5546875,55.1102820054097,19.6796728406424,6.58401,0,0,0,40,4961,9.92125,83819.484375,,,,,,,,,,,,,0,,,,,,,,,,,,,,
,20368852.165,9.92295,79962.6640625,0.00612802225262294,2.38483994262251E-6,1,0.999253354069792,40.0298881530762,2.00249528494543,23.9599999040365,0.0694363439447299,0.0129255278757976,0.25,3.61888625203445E-5,0.00613750572849548,8.07089235398464E-5,9.9232,9.9232,79935.3203125,79990.0078125,55.3166319344866,19.6835057476883,6.204359,0,0,0,40,4961,9.92295,79962.6640625,,,,,,,,,,,,,0,,,,,,,,,,,,,,
,20368929.415,9.9186,76104.171875,0.00610291878223618,1.98555328639237E-6,1,0.999253354069792,40.0298881530762,2.00242043042952,23.9599999040365,0.0691262687444718,0.0128831703766087,0.25,3.69624911668407E-5,0.00611054303269597,8.16670792042966E-5,9.9189,9.9189,76101.6796875,76106.6640625,55.4596699535059,19.6660980661182,6.963661,0,0,0,40,4961,9.9186,76104.171875,,,,,,,,,,,,,0,,,,,,,,,,,,,,
,20369006,9.9207,72273.34765625,0.00607971299320971,1.66190431178517E-6,1,0.999253354069792,40.0298881530762,2.00253068800054,23.9599999040365,0.0688529719634495,0.012791044679449,0.25,3.29831026140307E-5,0.00608545598501763,7.7812426533799E-5,9.9207,9.9207,72268.3125,72278.3828125,54.3044230020827,19.6791877370254,6.204359,0,0,0,40,4961,9.9207,72273.34765625,,,,,,,,,,,,,0,,,,,,,,,,,,,,
,20369083.35,9.9186,68407.2734375,0.00604116110499608,2.08343990285706E-6,1,0.999253354069792,40.0298881530762,2.00316058391462,23.9599999040365,0.068403189793071,0.0127729244014566,0.25,3.81068829344077E-5,0.00604485585067289,8.28831452796303E-5,9.9186,9.9186,68404.7421875,68409.8046875,55.4393476120059,19.6704612652531,6.204359,0,0,0,40,4961,9.9186,68407.2734375,,,,,,,,,,,,,0,,,,,,,,,,,,,,
,20369158,9.9145,64676.154296875,0.00600029222041719,1.72689528560086E-6,1,0.999253354069792,40.0298881530762,2.00264237257875,23.9599999040365,0.0679140135334667,0.0126091293582652,0.25,3.14973226932761E-5,0.00600203776189491,7.61065035125075E-5,9.9144,9.9144,64651.30859375,64701,55.2822402796405,19.6833514615112,6.58401,0,0,0,40,4961,9.9145,64676.154296875,,,,,,,,,,,,,0,,,,,,,,,,,,,,
,20369233.835,9.9099,60885.220703125,0.00594346675260436,1.88493740468711E-6,1,0.999253354069792,40.0298881530762,2.00321329258609,23.9599999040365,0.0672589341443795,0.0125268988083357,0.25,3.44852038742554E-5,0.0059431095985289,7.87243875152614E-5,9.9102,9.9102,60852.609375,60917.83203125,55.3189768200443,19.6787286397317,6.58401,0,0,0,40,4961,9.9099,60885.220703125,,,,,,,,,,,,,0,,,,,,,,,,,,,,
,20369309.99,9.9071,57079.111328125,0.0058790466541521,1.77215618246923E-6,1,0.999253354069792,40.0298881530762,2.00247691746471,23.9599999040365,0.0664841847429802,0.0123734760962831,0.25,3.33513400491214E-5,0.00587657755476577,7.70632729819159E-5,9.9071,9.9071,57048.98828125,57109.234375,55.1540532024866,19.6797071819146,6.963661,0,0,0,40,4961,9.9071,57079.111328125,,,,,,,,,,,,,0,,,,,,,,,,,,,,
,20369386.62,9.9047,53248.828125,0.0058055709634391,1.99835139159734E-6,1,0.999253354069792,40.0298881530762,2.00296179502577,23.9599999040365,0.0656476101384352,0.0121959385950457,0.25,3.11959929009907E-5,0.00580096934318494,7.42059515396219E-5,9.904,9.904,53241.34765625,53256.30859375,54.7366635732173,19.6933511268458,6.204359,0,0,0,40,4961,9.9047,53248.828125,,,,,,,,,,,,,0,,,,,,,,,,,,,,
,20369463.57,9.90425,49400.9453125,0.00571466877493892,1.63921150691336E-6,1,0.999253354069792,40.0298881530762,2.00315671182203,23.9599999040365,0.0646058202910602,0.0119727990398536,0.25,2.84223791136803E-5,0.00570794404637416,7.04876991152942E-5,9.9038,9.9038,49368.09765625,49433.79296875,54.5983153253135,19.6717012290172,6.204359,0,0,0,40,4961,9.90425,49400.9453125,,,,,,,,,,,,,0,,,,,,,,,,,,,,
,20369541.93,9.9007,45485.34375,0.00560757971485115,1.3660472689016E-6,1,0.999253354069792,40.0298881530762,2.00324231801361,23.9599999040365,0.0633706523161754,0.0117523806356146,0.25,2.89910572203956E-5,0.00559871366359901,6.98635515135914E-5,9.9009,9.9009,45480.26171875,45490.42578125,55.1915713714097,19.6706195275942,6.58401,0,0,0,40,4961,9.9007,45485.34375,,,,,,,,,,,,,0,,,,,,,,,,,,,,
,20369617.5,9.90005,41709.416015625,0.0054968448685945,1.48906093235721E-6,1,0.999253354069792,40.0298881530762,2.00348301009137,23.9599999040365,0.0621049021803254,0.0114995474935087,0.25,2.73556522013998E-5,0.00548599016295459,6.69114457623292E-5,9.8997,9.8997,41706.98046875,41711.8515625,55.2392507110828,19.6769711817917,6.58401,0,0,0,40,4961,9.90005,41709.416015625,,,,,,,,,,,,,0,,,,,,,,,,,,,,
,20369692.505,9.89765,37961.10546875,0.00536865166180742,1.64759347942877E-6,1,0.999253354069792,40.0298881530762,2.00381954527288,23.9599999040365,0.0606399130205479,0.0112410478908829,0.25,2.84113288514272E-5,0.00535591172369931,6.64148977160444E-5,9.8976,9.8976,37933.66015625,37988.55078125,55.0985575776212,19.677155538321,6.58401,0,0,0,40,4961,9.89765,37961.10546875,,,,,,,,,,,,,0,,,,,,,,,,,,,,
,20369767.86,9.8954,34193.51171875,0.00522416228247106,1.51003708762957E-6,1,0.999253354069792,40.0298881530762,2.00357428680272,23.9599999040365,0.05898723256767,0.0108777092338792,0.25,2.34876632072264E-5,0.00520970845622475,5.97355742898769E-5,9.8947,9.8947,34165.9375,34221.0859375,55.2720791088905,19.6872849152638,6.58401,0,0,0,40,4961,9.8954,34193.51171875,,,,,,,,,,,,,0,,,,,,,,,,,,,,
,20369843.1,9.89395,30435.41796875,0.00506236919193536,1.24616585493827E-6,1,0.999253354069792,40.0298881530762,2.00320364074146,23.9599999040365,0.0571235626195704,0.0105568030086558,0.25,2.5537976997364E-5,0.00504633744280499,5.98077472500324E-5,9.8941,9.8941,30402.958984375,30467.876953125,55.3072523922559,19.6913080610134,6.58401,0,0,0,40,4961,9.89395,30435.41796875,,,,,,,,,,,,,0,,,,,,,,,,,,,,
,20369918.86,9.8927,26647.322265625,0.00488464062642311,1.22827625975169E-6,1,0.999253354069792,40.0298881530762,2.00343397720014,23.9599999040365,0.0551056712669209,0.0101643041656216,0.25,2.38927634725074E-5,0.00486725225628573,5.60126852172632E-5,9.8935,9.8935,26619.8125,26674.83203125,55.3400807900636,19.6817668173632,6.963661,0,0,0,40,4961,9.8927,26647.322265625,,,,,,,,,,,,,0,,,,,,,,,,,,,,
,20369995.865,9.8901,22799.7646484375,0.00468863129858676,9.68713684132541E-7,1,0.999253354069792,40.0298881530762,2.00355075956397,23.9499993622303,0.0528800325050924,0.00973366181575008,0.25,2.22346251323211E-5,0.00467011400431063,5.20251667005835E-5,9.8897,9.8897,22767.486328125,22832.04296875,55.8778412112944,19.6716768451822,6.58401,0,0,0,40,4961,9.8901,22799.7646484375,,,,,,,,,,,,,0,,,,,,,,,,,,,,
,20370070.485,9.8914,19071.498046875,0.00447840277446255,8.86669706318838E-7,1,0.999253354069792,40.0298881530762,2.0034734794667,23.9599999040365,0.0504910830125052,0.00927933849966438,0.25,2.10369471216068E-5,0.00445908188970061,4.8427956085579E-5,9.8914,9.8914,19039.13671875,19103.859375,55.6613301114674,19.6865947227081,6.963661,0,0,0,40,4961,9.8914,19071.498046875,,,,,,,,,,,,,0,,,,,,,,,,,,,,
,20370147.585,9.8919,15216.4340820313,0.00424591703317197,7.34153227045712E-7,1,0.999253354069792,40.0298881530762,2.00384070678226,23.9499993622303,0.0478641239291317,0.00877841038486433,0.25,1.95032716736147E-5,0.00422607702816595,4.43477226426616E-5,9.8919,9.8919,15211.3681640625,15221.5,55.128259461352,19.6753753615318,6.963661,0,0,0,40,4961,9.8919,15216.4340820313,,,,,,,,,,,,,0,,,,,,,,,,,,,,
,20370222.55,9.89125,11468.521484375,0.00400168973708351,7.07431967836826E-7,1,0.999253354069792,40.0298881530762,2.0035713045566,23.9599999040365,0.0450933627620695,0.00825259274308168,0.25,1.79456904916248E-5,0.00398168758393129,4.02749051534463E-5,9.8913,9.8913,11438.294921875,11498.748046875,55.3908866438135,19.6705961314579,6.58401,0,0,0,40,4961,9.89125,11468.521484375,,,,,,,,,,,,,0,,,,,,,,,,,,,,
,20370298.54,9.88605,7672.54077148438,0.00373716394132254,5.56791784683391E-7,1,0.999253354069792,40.0298881530762,2.00374041345603,23.9599999040365,0.0421051950538798,0.00769350801434431,0.25,1.67568639483888E-5,0.00371735633376007,3.65574264242064E-5,9.8867,9.8867,7644.93896484375,7700.142578125,55.8950370387175,19.6799793143328,6.58401,0,0,0,40,4961,9.88605,7672.54077148438,,,,,,,,,,,,,0,,,,,,,,,,,,,,
,20370375.795,9.8847,3809.51440429687,0.00344947893742747,4.1806218554215E-7,1,0.999253354069792,40.0298881530762,2.00394972107666,23.9599999040365,0.0388582595519847,0.00709458038778058,0.25,1.59406464800293E-5,0.00343026779595467,3.32519344581299E-5,9.8847,9.8847,3807.03247070313,3811.99633789063,56.272563613506,19.6677419750487,6.58401,0,0,0,40,4961,9.8847,3809.51440429687,,,,,,,,,,,,,0,,,,,,,,,,,,,,
,20370452.68,9.8764,-34.3511333465576,0.00313615791473771,3.73124455502217E-7,1,0.999253354069792,40.0298881530762,2.00446517695479,23.9499993622303,0.035330729634564,0.00644833089984813,0.25,1.500462225544E-5,0.00311807241697197,3.00370419570829E-5,9.8764,9.8764,-36.9379081726074,-31.7643585205078,55.6050528580828,19.6670099590242,6.58401,0,0,0,40,4961,9.8764,-34.3511333465576,,,,,,,,,,,,,0,,,,,,,,,,,,,,
,20370528.305,9.8829,-3808.02966308594,0.00279000900532469,4.29120299798891E-7,1,0.999253354069792,40.0298881530762,2.00458044295646,23.9499993622303,0.0314387192499267,0.00574034628555754,0.25,1.29273204969175E-5,0.00277447021552337,2.69285677832116E-5,9.8832,9.8832,-3835.71752929687,-3780.341796875,55.5300165202367,19.6729571496176,6.963661,0,0,0,40,4961,9.8829,-3808.02966308594,,,,,,,,,,,,,0,,,,,,,,,,,,,,
,20370603.45,9.88415,-7564.97412109375,0.00240372880976355,6.38628285197785E-7,1,0.999253354069792,40.0298881530762,2.00402615371249,23.9599999040365,0.0270856209781658,0.00494757683614349,0.25,1.06649174403829E-5,0.00239096987684997,2.33820183263797E-5,9.884,9.884,-7594.80419921875,-7535.14404296875,55.1681225158328,19.6746142787198,6.58401,0,0,0,40,4961,9.88415,-7564.97412109375,,,,,,,,,,,,,0,,,,,,,,,,,,,,
,20370679.615,9.88755,-11373.9262695312,0.00189690790984154,6.54811131780645E-7,1,0.999253354069792,40.0298881530762,2.00400343662412,23.9499993622303,0.0213811123998535,0.00390473213137731,0.25,7.81145267557778E-6,0.00188741527257802,1.83863145778086E-5,9.8876,9.8876,-11404.17578125,-11343.6767578125,55.7676315900828,19.6733443851231,6.58401,0,0,0,40,4961,9.88755,-11373.9262695312,,,,,,,,,,,,,0,,,,,,,,,,,,,,
,20370755.165,9.88675,-15149.2827148438,0.00118563308903109,8.29120371439754E-7,1,0.999253354069792,40.0298881530762,2.00355929883939,23.9599999040365,0.0133661854727163,0.00243726941818081,0.25,4.23926960365994E-6,0.0011800928569584,1.11768119968182E-5,9.8867,9.8867,-15181.751953125,-15116.8134765625,55.9223940368905,19.6794675521066,6.204359,0,0,0,40,4961,9.88675,-15149.2827148438,,,,,,,,,,,,,0,,,,,,,,,,,,,,
,20370829.455,9.88855,-18862.1015625,0.000147506947134405,1.17632937115821E-6,1,0.999253354069792,40.0298881530762,2.00427663754801,23.9599999040365,0.00166612114769145,0.000291921792637498,0.25,-5.29929130195894E-7,0.00014687510035853,3.75468112435848E-7,9.8881,9.8881,-18864.783203125,-18859.419921875,55.3260114767174,19.6768565686696,6.58401,0,0,0,40,4961,9.88855,-18862.1015625,,,,,,,,,,,,,0,,,,,,,,,,,,,,
,20370905.165,9.89095,-22644.98828125,-0.00123171238968869,1.31328185768646E-6,1,0.999253354069792,40.0298881530762,2.00417462582998,23.9499993622303,-0.0138971238786696,-0.00254924064799893,0.25,-5.09703960793914E-6,-0.00122683356601393,-1.29143564228029E-5,9.8907,9.8907,-22677.986328125,-22611.990234375,56.0232241158713,19.6681021627962,6.58401,0,0,0,40,4961,9.89095,-22644.98828125,,,,,,,,,,,,,0,,,,,,,,,,,,,,
,20370979.115,9.89405,-26339.943359375,-0.00259675723902303,1.18522454114915E-6,1,0.999253354069792,40.0298881530762,2.00397046387146,23.9599999040365,-0.0293021401508936,-0.00540201239435457,0.25,-1.2504733622028E-5,-0.0025874324880186,-2.95371338879302E-5,9.8938,9.8938,-26369.900390625,-26309.986328125,55.7660683330444,19.6692999429548,6.58401,0,0,0,40,4961,9.89405,-26339.943359375,,,,,,,,,,,,,0,,,,,,,,,,,,,,
,20371055.065,9.8962,-30140.51953125,-0.00371340564847395,1.55633674193345E-6,1,0.999253354069792,40.0298881530762,2.0045169733369,23.9499993622303,-0.0419277388028644,-0.00774320900869969,0.25,-1.83299181499805E-5,-0.00370153377240317,-4.34163382346344E-5,9.8964,9.8964,-30173.015625,-30108.0234375,56.2756901275829,19.6722451525061,6.58401,0,0,0,40,4961,9.8962,-30140.51953125,,,,,,,,,,,,,0,,,,,,,,,,,,,,
,20371131.595,9.89905,-33960.783203125,-0.00447597244137298,1.48660972002168E-6,1,0.999253354069792,40.0298881530762,2.00454911422138,23.9599999040365,-0.0505572591834715,-0.00934724868581631,0.25,-2.22284486923976E-5,-0.00446346373665597,-5.32361732921773E-5,9.899,9.899,-33995.7265625,-33925.83984375,55.4416924975636,19.6591220804777,6.58401,0,0,0,40,4961,9.89905,-33960.783203125,,,,,,,,,,,,,0,,,,,,,,,,,,,,
,20371207.455,9.90165,-37753.576171875,-0.00496078637518346,1.24841675603405E-6,1,0.999253354069792,40.0298881530762,2.00431698204555,23.9599999040365,-0.0560420941735746,-0.0104055969108741,0.25,-2.77303893984242E-5,-0.00494889473670453,-6.28076396083367E-5,9.9018,9.9018,-37783.52734375,-37723.625,54.9906928419674,19.6667707016151,6.58401,0,0,0,40,4961,9.90165,-37753.576171875,,,,,,,,,,,,,0,,,,,,,,,,,,,,
,20371283.395,9.9035,-41548.943359375,-0.00527817272586226,1.3940102813873E-6,1,0.999253354069792,40.0298881530762,2.00445083353549,23.9599999040365,-0.0596589760273446,-0.0110568425238193,0.25,-2.7161758079816E-5,-0.00526765419231301,-6.5118528598374E-5,9.9035,9.9035,-41551.58984375,-41546.296875,55.2337793114482,19.6662880291831,6.204359,0,0,0,40,4961,9.9035,-41548.943359375,,,,,,,,,,,,,0,,,,,,,,,,,,,,
,20371358.14,9.90395,-45281.9375,-0.00550088987300974,1.64943267292586E-6,1,0.999253354069792,40.0298881530762,2.00431595799422,23.9599999040365,-0.0621938242807353,-0.0115433241308713,0.25,-2.92482559478108E-5,-0.0054920703064762,-6.93175964448085E-5,9.9038,9.9038,-45309.39453125,-45254.48046875,55.954440806179,19.6697667372276,6.204359,0,0,0,40,4961,9.90395,-45281.9375,,,,,,,,,,,,,0,,,,,,,,,,,,,,
,20371432.055,9.9074,-48979.849609375,-0.00566234069179456,1.85849463533644E-6,1,0.999253354069792,40.0298881530762,2.00487846212304,23.9599999040365,-0.0640528766089831,-0.0119339394059148,0.25,-3.36322321433059E-5,-0.00565539416864787,-7.52686920564429E-5,9.907,9.907,-49012.2890625,-48947.41015625,55.4268415556982,19.660314243853,6.963661,0,0,0,40,4961,9.9074,-48979.849609375,,,,,,,,,,,,,0,,,,,,,,,,,,,,
,20371508.595,9.91015,-52801.828125,-0.00578766713562099,1.55294506927324E-6,1,0.999253354069792,40.0298881530762,2.00464389234304,23.9499993622303,-0.0654959230313307,-0.01216058837573,0.25,-3.05098376822487E-5,-0.00578282673348291,-7.33618235395037E-5,9.9094,9.9094,-52834.20703125,-52769.44921875,55.0688556938904,19.6599597557653,6.204359,0,0,0,40,4961,9.91015,-52801.828125,,,,,,,,,,,,,0,,,,,,,,,,,,,,
,20371584.555,9.91115,-56600.478515625,-0.00588587408997016,1.95407751042993E-6,1,0.999253354069792,40.0298881530762,2.00480826586948,23.9599999040365,-0.0666368598964409,-0.0123753747388087,0.25,-3.11361718181601E-5,-0.00588314677307747,-7.48862448278647E-5,9.9111,9.9111,-56633.12890625,-56567.828125,55.8387597853328,19.6721127639625,6.963661,0,0,0,40,4961,9.91115,-56600.478515625,,,,,,,,,,,,,0,,,,,,,,,,,,,,
,20371662.11,9.9171,-60473.04296875,-0.00596228180537092,2.10966243576925E-6,1,0.999253354069792,40.0298881530762,2.00553852629405,23.9599999040365,-0.0675541496687776,-0.0125234618941368,0.25,-2.96073522266406E-5,-0.00596173111448893,-7.39866336656774E-5,9.9173,9.9173,-60500.87109375,-60445.21484375,55.7504357626598,19.6567126502322,6.204359,0,0,0,40,4961,9.9171,-60473.04296875,,,,,,,,,,,,,0,,,,,,,,,,,,,,
,20371738.115,9.9213,-64273.2109375,-0.00602525847572098,2.47532408103751E-6,1,0.999253354069792,40.0298881530762,2.0043097596487,23.9599999040365,-0.068240411833182,-0.0127148780009983,0.25,-3.54686778358655E-5,-0.00602676422153635,-8.02747281671795E-5,9.921,9.921,-64303.109375,-64243.3125,55.5698795747174,19.6630031213167,6.58401,0,0,0,40,4961,9.9213,-64273.2109375,,,,,,,,,,,,,0,,,,,,,,,,,,,,
,20371814.085,9.92415,-68071.1640625,-0.00608429758799427,1.84714743195634E-6,1,0.999253354069792,40.0298881530762,2.00481841551016,23.9599999040365,-0.0689567363975634,-0.0128032659034823,0.25,-3.21332904677618E-5,-0.00608788812840299,-7.72413029065222E-5,9.9246,9.9246,-68100.8671875,-68041.4609375,55.8317251286598,19.6687239048867,6.58401,0,0,0,40,4961,9.92415,-68071.1640625,,,,,,,,,,,,,0,,,,,,,,,,,,,,
,20371889.315,9.92775,-71831.36328125,-0.00612547592402231,1.97037581327521E-6,1,0.999253354069792,40.0298881530762,2.00539742571566,23.9599999040365,-0.0694621588466235,-0.0129115300138016,0.25,-3.38217251084186E-5,-0.00613103354809961,-7.90193870095821E-5,9.9278,9.9278,-71853.8671875,-71808.859375,55.1165350335635,19.660664470859,6.204359,0,0,0,40,4961,9.92775,-71831.36328125,,,,,,,,,,,,,0,,,,,,,,,,,,,,
,20371966.345,9.93335,-75678.546875,-0.00616111857930775,2.37968842771087E-6,1,0.999253354069792,40.0298881530762,2.00532424731532,23.9599999040365,-0.0698819733062757,-0.0130108124301633,0.25,-3.61505745818432E-5,-0.00616861651439859,-8.13169340684925E-5,9.9333,9.9333,-75705.84375,-75651.25,55.5933284302943,19.6647227910858,6.204359,0,0,0,40,4961,9.93335,-75678.546875,,,,,,,,,,,,,0,,,,,,,,,,,,,,
,20372041.875,9.93775,-79453.76171875,-0.00619614958062845,2.50930283461161E-6,1,0.999253354069792,40.0298881530762,2.00541643947398,23.9599999040365,-0.0702994508003555,-0.0131082816190951,0.25,-3.84173035812032E-5,-0.00620548731405967,-8.34874873602493E-5,9.9374,9.9374,-79488.578125,-79418.9453125,55.7504357626598,19.6598971378462,6.963661,0,0,0,40,4961,9.93775,-79453.76171875,,,,,,,,,,,,,0,,,,,,,,,,,,,,
,20372118.32,9.9528,-83274.15625,-0.00621732399190912,2.34715402499132E-6,1,0.999253354069792,40.0298881530762,1.99358477441707,23.9499993622303,-0.0701548825648764,-0.0131234488287408,0.25,-4.25953652740562E-5,-0.00622841787423746,-8.74104245176033E-5,9.9527,9.9527,-83296.75,-83251.5625,55.6691463966597,19.6309915915616,6.58401,0,0,0,40,4961,9.9528,-83274.15625,,,,,,,,,,,,,0,,,,,,,,,,,,,,
,20372191.195,9.96345,-86916.87109375,-0.00622475231801129,3.4045741626826E-6,1,0.999253354069792,40.0298881530762,1.99375569113991,23.9599999040365,-0.070274014392619,-0.0130788266253279,0.25,-3.73812400941694E-5,-0.00623749095061874,-8.17978209374208E-5,9.9639,9.9639,-86944.265625,-86889.4765625,55.5222002350443,19.6291705094049,6.204359,0,0,0,40,4961,9.96345,-86916.87109375,,,,,,,,,,,,,0,,,,,,,,,,,,,,
,20372278.07,9.9716,-89493.859375,-0.00622847821635152,2.85600591206096E-6,1,0.999253354069792,40.0298881530762,1.99384257340854,23.9599999040365,-0.0703230883462844,-0.0131343558564997,0.25,-4.17239665878606E-5,-0.00624227562799469,-8.58413078115457E-5,9.9713,9.9713,-89521.265625,-89466.453125,56.0927890540829,19.6177713425338,6.963661,0,0,0,40,4961,9.9716,-89493.859375,,,,,,,,,,,,,0,,,,,,,,,,,,,,
,20372348.1,9.97485,-85995.17578125,-0.00622418829051237,3.31971321171612E-6,1,0.999253354069792,40.0298881530762,1.99411771407948,23.9599999040365,-0.0702724429243085,-0.01309536998361,0.25,-3.86985469866329E-5,-0.00623652031977052,-8.32294033437971E-5,9.9748,9.9748,-86025.1796875,-85965.171875,55.8293802431021,19.6318354345585,6.58401,0,0,0,40,4961,9.97485,-85995.17578125,,,,,,,,,,,,,0,,,,,,,,,,,,,,
,20372422.36,9.9765,-82285.2421875,-0.00621384373345315,2.52666346038643E-6,1,0.999253354069792,40.0298881530762,1.99421242763079,23.9599999040365,-0.0701569849175469,-0.0129784897828746,0.25,-3.00093949209175E-5,-0.00622457638823525,-7.48895845084933E-5,9.9763,9.9763,-82317.9453125,-82252.5390625,55.5933284302943,19.6285865856595,6.58401,0,0,0,40,4961,9.9765,-82285.2421875,,,,,,,,,,,,,0,,,,,,,,,,,,,,
,20372498.965,9.97495,-78457.125,-0.00619286923366814,2.61299503120098E-6,1,0.999253354069792,40.0298881530762,1.99425071964599,23.9599999040365,-0.069884436592703,-0.0130260813561086,0.25,-3.7878971182705E-5,-0.00620173553627017,-8.30239707922246E-5,9.9745,9.9745,-78489.453125,-78424.796875,55.544867462102,19.6269506354836,6.58401,0,0,0,40,4961,9.97495,-78457.125,,,,,,,,,,,,,0,,,,,,,,,,,,,,
,20372575.29,9.97245,-74641.93359375,-0.00616967708271632,2.47099712925732E-6,1,0.999253354069792,40.0298881530762,1.994352752059,23.9599999040365,-0.0696063187482397,-0.0129686277097491,0.25,-3.68901898704712E-5,-0.00617666963538771,-8.22068730080348E-5,9.972,9.972,-74646.890625,-74636.9765625,55.2056406847558,19.6209767831968,6.58401,0,0,0,40,4961,9.97245,-74641.93359375,,,,,,,,,,,,,0,,,,,,,,,,,,,,
,20372649.955,9.9735,-70911.62890625,-0.00613710085039098,2.51841883990805E-6,1,0.999253354069792,40.0298881530762,1.99476005216797,23.9599999040365,-0.069234382776224,-0.0128806645394254,0.25,-3.48029189355965E-5,-0.00614219072424735,-8.01471859268139E-5,9.9729,9.9729,-70939.328125,-70883.9296875,55.8153109297559,19.6140345058154,6.204359,0,0,0,40,4961,9.9735,-70911.62890625,,,,,,,,,,,,,0,,,,,,,,,,,,,,
,20372725.265,9.97525,-67146.75,-0.00609840851260276,2.206211958386E-6,1,0.999253354069792,40.0298881530762,1.99526014916573,23.9599999040365,-0.0687951082210745,-0.0127821467817728,0.25,-3.29223194018742E-5,-0.00610151084228552,-7.817648462283E-5,9.9752,9.9752,-67171.75,-67121.75,55.8004599878905,19.6126036799961,6.204359,0,0,0,40,4961,9.97525,-67146.75,,,,,,,,,,,,,0,,,,,,,,,,,,,,
,20372800.54,9.97415,-63386.494140625,-0.00604753916247831,1.76006600935286E-6,1,0.999253354069792,40.0298881530762,1.99565302809632,23.9599999040365,-0.0682121084626484,-0.0126686634136824,0.25,-3.20665328593199E-5,-0.00604859060368674,-7.705591146787E-5,9.9742,9.9742,-63419.0390625,-63353.94921875,56.0318220295829,19.5969512272219,6.58401,0,0,0,40,4961,9.97415,-63386.494140625,,,,,,,,,,,,,0,,,,,,,,,,,,,,
,20372878.57,9.9752,-59485.83984375,-0.00599033274913921,1.94629018854231E-6,1,0.999253354069792,40.0298881530762,1.99573005437914,23.9599999040365,-0.0675434029942299,-0.0125531891665414,0.25,-3.24642666521592E-5,-0.00598920296712779,-7.7046952867972E-5,9.9752,9.9752,-59490.8828125,-59480.796875,55.7731029897174,19.595101336609,6.963661,0,0,0,40,4961,9.9752,-59485.83984375,,,,,,,,,,,,,0,,,,,,,,,,,,,,
,20372955.39,9.9766,-55648.037109375,-0.00591805294795914,1.95793663259726E-6,1,0.999253354069792,40.0298881530762,1.99646961421545,23.9599999040365,-0.0667319235487597,-0.0123765662517142,0.25,-2.99202440314918E-5,-0.00591477286546015,-7.38779696785252E-5,9.9768,9.9768,-55668.0234375,-55628.05078125,54.8859546203904,19.585893706323,6.58401,0,0,0,40,4961,9.9766,-55648.037109375,,,,,,,,,,,,,0,,,,,,,,,,,,,,
,20373033.945,9.97815,-51720.666015625,-0.00583407660488169,1.73299466240523E-6,1,0.999253354069792,40.0298881530762,1.99684433407661,23.9599999040365,-0.0657771041551247,-0.0121655518553845,0.25,-2.67650845657774E-5,-0.00582859562473063,-6.98945360327687E-5,9.9782,9.9782,-51725.390625,-51715.94140625,55.4323129553328,19.5727726074327,6.58401,0,0,0,40,4961,9.97815,-51720.666015625,,,,,,,,,,,,,0,,,,,,,,,,,,,,
,20373109.905,9.97825,-47925.404296875,-0.00574201876351639,1.73658842932803E-6,1,0.999253354069792,40.0298881530762,1.9971345860325,23.9599999040365,-0.0647165417213216,-0.0120073772114187,0.25,-2.98929544440841E-5,-0.0057343850727952,-7.20187503623621E-5,9.9776,9.9776,-47952.95703125,-47897.8515625,55.5253267491212,19.5722837895871,6.963661,0,0,0,40,4961,9.97825,-47925.404296875,,,,,,,,,,,,,0,,,,,,,,,,,,,,
,20373187.085,9.98025,-44067.142578125,-0.00563007952637534,1.68246780866668E-6,1,0.999253354069792,40.0298881530762,1.99717479298791,23.9599999040365,-0.0634380976862367,-0.0117276784543784,0.25,-2.60853208907166E-5,-0.00562036735995489,-6.69458808711945E-5,9.98,9.98,-44099.6015625,-44034.68359375,56.218631245679,19.5695761401841,6.204359,0,0,0,40,4961,9.98025,-44067.142578125,,,,,,,,,,,,,0,,,,,,,,,,,,,,
,20373264.18,9.98035,-40214.67578125,-0.00550374118643853,1.36190070251001E-6,1,0.999253354069792,40.0298881530762,1.99747209118215,23.9599999040365,-0.0619919076187699,-0.0114962204539225,0.25,-2.91297678959882E-5,-0.00549199220575508,-6.84919445800994E-5,9.9806,9.9806,-40242.05078125,-40187.30078125,55.5706612032367,19.557024332553,6.963661,0,0,0,40,4961,9.98035,-40214.67578125,,,,,,,,,,,,,0,,,,,,,,,,,,,,
,20373341.625,9.97985,-36344.39453125,-0.00536606658300738,1.48747860904822E-6,1,0.999253354069792,40.0298881530762,1.99748901355656,23.9599999040365,-0.0604259210964286,-0.0111534685156417,0.25,-2.45842196407658E-5,-0.00535243945189366,-6.2267778320465E-5,9.9803,9.9803,-36374.5,-36314.2890625,55.5558102613713,19.5581455470465,6.204359,0,0,0,40,4961,9.97985,-36344.39453125,,,,,,,,,,,,,0,,,,,,,,,,,,,,
,20373417.795,9.97725,-32536.9951171875,-0.00521331960207742,1.11112004744492E-6,1,0.999253354069792,40.0298881530762,1.99745874984245,23.9599999040365,-0.0586823806508525,-0.0108250947925513,0.25,-2.41070298057859E-5,-0.00519797732876575,-5.99097210817638E-5,9.9776,9.9776,-32566.984375,-32507.005859375,55.1118452624481,19.5567846986446,6.58401,0,0,0,40,4961,9.97725,-32536.9951171875,,,,,,,,,,,,,0,,,,,,,,,,,,,,
,20373495.135,9.9738,-28674.3984375,-0.00504497362779043,1.82793132361297E-6,1,0.999253354069792,40.0298881530762,1.997355931381,23.9599999040365,-0.056760432996387,-0.0104766707707471,0.25,-2.47611698148129E-5,-0.00502807236429075,-5.8475497362577E-5,9.9744,9.9744,-28704.455078125,-28644.341796875,55.666801511102,19.5685728053938,6.58401,0,0,0,40,4961,9.9738,-28674.3984375,,,,,,,,,,,,,0,,,,,,,,,,,,,,
,20373572.75,9.9734,-24793.7783203125,-0.00485069553192815,1.37229444403159E-6,1,0.999253354069792,40.0298881530762,1.99726577768526,23.9700004458427,-0.0545514766259179,-0.0100623431401813,0.25,-2.42454652280485E-5,-0.00483250424875243,-5.56351496326827E-5,9.9734,9.9734,-24816.056640625,-24771.5,55.6949401377944,19.5642985155485,6.963661,0,0,0,40,4961,9.9734,-24793.7783203125,,,,,,,,,,,,,0,,,,,,,,,,,,,,
,20373642.66,9.9719,-21300.669921875,-0.0046642686097677,1.03108123301823E-6,1,0.999253354069792,40.0298881530762,1.99731102560234,23.9700004458427,-0.0524386056493006,-0.00966657932966345,0.25,-2.37665438350395E-5,-0.00464514337297097,-5.29612742364707E-5,9.9717,9.9717,-21328.205078125,-21273.134765625,55.4252782986597,19.5642745498933,6.204359,0,0,0,40,4961,9.9719,-21300.669921875,,,,,,,,,,,,,0,,,,,,,,,,,,,,
,20373710.775,9.97025,-17898.029296875,-0.00446816211557816,1.16732031403115E-6,1,0.999253354069792,40.0298881530762,1.99715934197255,23.9599999040365,-0.0502191289483208,-0.00922554801082158,0.25,-2.1009380309434E-5,-0.00444838647955351,-4.79852684049828E-5,9.9702,9.9702,-17925.544921875,-17870.513671875,55.3940131578905,19.5665523865363,6.963661,0,0,0,40,4961,9.97025,-17898.029296875,,,,,,,,,,,,,0,,,,,,,,,,,,,,
,20373780.29,9.968,-14422.8017578125,-0.00425202720256751,9.45277009325479E-7,1,0.999253354069792,40.0298881530762,1.99717713429952,23.9599999040365,-0.0477783442300089,-0.0087575774931739,0.25,-1.93309635378163E-5,-0.00423185677466578,-4.3971240783763E-5,9.9676,9.9676,-14452.9033203125,-14392.7001953125,55.087614778352,19.5642713070541,6.58401,0,0,0,40,4961,9.968,-14422.8017578125,,,,,,,,,,,,,0,,,,,,,,,,,,,,
,20373848.415,9.965,-11017.0888671875,-0.0040286559345513,8.10495318510957E-7,1,0.999253354069792,40.0298881530762,1.9972395905604,23.9599999040365,-0.0452591483592874,-0.00827981806291954,0.25,-1.79318240289479E-5,-0.00400836808447745,-4.02777836045687E-5,9.9654,9.9654,-11049.46484375,-10984.712890625,55.4541985538713,19.5655853463339,6.204359,0,0,0,40,4961,9.965,-11017.0888671875,,,,,,,,,,,,,0,,,,,,,,,,,,,,
,20373919.065,9.9618,-7486.0224609375,-0.00377909043713879,6.23135238087714E-7,1,0.999253354069792,40.0298881530762,1.99700547238497,23.9599999040365,-0.0424409454251635,-0.00775167011065041,0.25,-1.67221842811717E-5,-0.00375900862985292,-3.66938975903395E-5,9.9612,9.9612,-7515.7275390625,-7456.3173828125,55.4237150416212,19.5718294233546,6.58401,0,0,0,40,4961,9.9618,-7486.0224609375,,,,,,,,,,,,,0,,,,,,,,,,,,,,
,20373988.29,9.9576,-4026.67663574219,-0.00351763968291034,5.37653137351574E-7,1,0.999253354069792,40.0298881530762,1.99701622666556,23.9599999040365,-0.0394954806566707,-0.00721279251002498,0.25,-1.63640640191683E-5,-0.00349809651941281,-3.40698201908405E-5,9.9578,9.9578,-4056.48510742188,-3996.8681640625,55.2650444522174,19.5683475616898,6.58401,0,0,0,40,4961,9.9576,-4026.67663574219,,,,,,,,,,,,,0,,,,,,,,,,,,,,
,20374057.165,9.95145,-582.538177490234,-0.00323515890843285,4.26764582002403E-7,1,0.999253354069792,40.0298881530762,1.99697853802477,23.9599999040365,-0.036316912077964,-0.00662802191048228,0.25,-1.53769479361367E-5,-0.0032165665312868,-3.09600984169005E-5,9.9521,9.9521,-607.488159179688,-557.588195800781,55.8684616690636,19.5716467906905,6.963661,0,0,0,40,4961,9.95145,-582.538177490234,,,,,,,,,,,,,0,,,,,,,,,,,,,,
,20374125.79,9.9513,2842.35327148438,-0.00293005724488285,4.28702333651681E-7,1,0.999253354069792,40.0298881530762,1.99674191261779,23.9700004458427,-0.0328917977542633,-0.00600486762225541,0.25,-1.36988611676825E-5,-0.00291356460835715,-2.82105272113361E-5,9.9517,9.9517,2809.72875976562,2874.97778320313,55.0790168646404,19.5737576463726,6.204359,0,0,0,40,4961,9.9513,2842.35327148438,,,,,,,,,,,,,0,,,,,,,,,,,,,,
,20374194.28,9.95665,6267.94995117187,-0.0025840865065562,4.64226624575434E-7,1,0.999253354069792,40.0298881530762,1.99717496759931,23.9599999040365,-0.0290199302387595,-0.00530217307974963,0.25,-1.18198858356332E-5,-0.00257012331050322,-2.52426056727707E-5,9.957,9.957,6240.57373046875,6295.326171875,54.9070585904097,19.5643006562167,6.58401,0,0,0,40,4961,9.95665,6267.94995117187,,,,,,,,,,,,,0,,,,,,,,,,,,,,
,20374262.625,9.95625,9684.8603515625,-0.0021697755878199,6.66855043409139E-7,1,0.999253354069792,40.0298881530762,1.99696692575888,23.9599999040365,-0.0243684047985675,-0.00446771184933644,0.25,-1.07064067211279E-5,-0.00215860818652076,-2.25217992385368E-5,9.956,9.956,9654.81640625,9714.904296875,55.7011931659482,19.5682078676247,6.58401,0,0,0,40,4961,9.95625,9684.8603515625,,,,,,,,,,,,,0,,,,,,,,,,,,,,
,20374332.15,9.95725,13159.9135742187,-0.0015969778758093,8.46228374600685E-7,1,0.999253354069792,40.0298881530762,1.99703711461661,23.9599999040365,-0.0179422008456015,-0.00328407618429608,0.25,-7.00391486157231E-6,-0.00158922644695395,-1.61137836517422E-5,9.9572,9.9572,13132.4599609375,13187.3671875,55.7301134211597,19.5634975305555,6.963661,0,0,0,40,4961,9.95725,13159.9135742187,,,,,,,,,,,,,0,,,,,,,,,,,,,,
,20374401.745,9.9603,16635.7265625,-0.000774101248209943,1.12860102915737E-6,1,0.999253354069792,40.0298881530762,1.99691609048824,23.9700004458427,-0.00869838997365407,-0.00159760064737729,0.25,-3.67665604091269E-6,-0.00077058370580624,-8.28284926108799E-6,9.9598,9.9598,16605.97265625,16665.48046875,55.3049075066982,19.5697518199566,6.58401,0,0,0,40,4961,9.9603,16635.7265625,,,,,,,,,,,,,0,,,,,,,,,,,,,,
,20374469.9,9.96135,20043.736328125,0.000325434457640977,1.17911808694659E-6,1,0.999253354069792,40.0298881530762,1.99697432010596,23.9599999040365,0.0036562475225475,0.000682349857587596,0.25,2.40301582260455E-6,0.000324055496719086,4.41059574467851E-6,9.9609,9.9609,20013.255859375,20074.216796875,55.3549317319289,19.561522508985,6.963661,0,0,0,40,4961,9.96135,20043.736328125,,,,,,,,,,,,,0,,,,,,,,,,,,,,
,20374539.93,9.96255,23542.408203125,0.00164622655724209,1.62661817729997E-6,1,0.999253354069792,40.0298881530762,1.99692697465151,23.9599999040365,0.018509330094653,0.00340819523021985,0.25,7.8348256904975E-6,0.00163984711792946,1.83682756774282E-5,9.962,9.962,23517.533203125,23567.283203125,55.1642143732366,19.5599978948467,6.58401,0,0,0,40,4961,9.96255,23542.408203125,,,,,,,,,,,,,0,,,,,,,,,,,,,,
,20374608.755,9.9631,26983.203125,0.0028734323506856,1.434357887351E-6,1,0.999253354069792,40.0298881530762,1.99689384569318,23.9599999040365,0.0323166072299668,0.00596039175500241,0.25,1.39655433254711E-5,0.00286330323493639,3.29130942672756E-5,9.9638,9.9638,26955.55078125,27010.85546875,55.5096941787366,19.557894541265,6.204359,0,0,0,40,4961,9.9631,26983.203125,,,,,,,,,,,,,0,,,,,,,,,,,,,,
,20374675.945,9.96515,30343.763671875,0.00380428770036087,1.48347263115401E-6,1,0.999253354069792,40.0298881530762,1.99674011243452,23.9599999040365,0.0428014099738245,0.00787210616632059,0.25,1.59522917012565E-5,0.00379222508226497,4.16988889551072E-5,9.9655,9.9655,30313.771484375,30373.755859375,55.7598153048905,19.5585668693363,6.963661,0,0,0,40,4961,9.96515,30343.763671875,,,,,,,,,,,,,0,,,,,,,,,,,,,,
,20374742.9,9.9667,33689.6484375,0.00446058174106446,1.63044625114502E-6,1,0.999253354069792,40.0298881530762,1.99699901596839,23.9599999040365,0.0502053512462551,0.00925647402693404,0.25,1.99920143340009E-5,0.00444800258327921,5.0848540684035E-5,9.9673,9.9673,33662.0625,33717.234375,56.0208792303136,19.5611364432301,6.58401,0,0,0,40,4961,9.9667,33689.6484375,,,,,,,,,,,,,0,,,,,,,,,,,,,,
,20374810.04,9.96745,37042.658203125,0.0049054389949332,1.75454159580406E-6,1,0.999253354069792,40.0298881530762,1.99692867273489,23.9599999040365,0.0552274082050264,0.0101986467900812,0.25,2.27581745852634E-5,0.00489334289564824,5.7331707076492E-5,9.967,9.967,37010.1796875,37075.13671875,55.7848274175059,19.5581529810919,6.204359,0,0,0,40,4961,9.96745,37042.658203125,,,,,,,,,,,,,0,,,,,,,,,,,,,,
,20374877.595,9.97185,40421.388671875,0.00521553622827686,1.98546372091489E-6,1,0.999253354069792,40.0298881530762,1.99701567019395,23.9599999040365,0.0587336191745769,0.0108950895031048,0.25,2.78400213716597E-5,0.0052045147071456,6.51731398405371E-5,9.9725,9.9725,40394.12109375,40448.65625,55.2666077092559,19.5617252692949,6.204359,0,0,0,40,4961,9.97185,40421.388671875,,,,,,,,,,,,,0,,,,,,,,,,,,,,
,20374946.385,9.97325,43856.26953125,0.0054392688905352,1.97672385636046E-6,1,0.999253354069792,40.0298881530762,1.99704433567168,23.9599999040365,0.0612747992040485,0.0113743720461392,0.25,2.92284066003459E-5,0.00542973681891151,6.86697567377831E-5,9.9736,9.9736,43825.6953125,43886.84375,55.4002661860443,19.5592897489099,6.204359,0,0,0,40,4961,9.97325,43856.26953125,,,,,,,,,,,,,0,,,,,,,,,,,,,,
,20375014.285,9.9763,47252.513671875,0.00559985507932747,1.8542346290617E-6,1,0.999253354069792,40.0298881530762,1.99688866919779,23.9599999040365,0.0631079492542624,0.0116774502060656,0.25,2.65163296333024E-5,0.00559204222294425,6.75344513282519E-5,9.9763,9.9763,47244.95703125,47260.0703125,56.0544892566406,19.5563320332278,6.963661,0,0,0,40,4961,9.9763,47252.513671875,,,,,,,,,,,,,0,,,,,,,,,,,,,,
,20375082.135,9.98075,50643.619140625,0.00572754900813457,2.40793620368984E-6,1,0.999253354069792,40.0298881530762,1.99700242106149,23.9599999040365,0.0645618751704323,0.0120097795735684,0.25,3.22631040352568E-5,0.00572150259126137,7.4521444519184E-5,9.9807,9.9807,50613.33984375,50673.8984375,55.3564949889674,19.5583159521833,6.963661,0,0,0,40,4961,9.98075,50643.619140625,,,,,,,,,,,,,0,,,,,,,,,,,,,,
,20375149.985,9.98325,54034.515625,0.00583013634594927,2.63800851188914E-6,1,0.999253354069792,40.0298881530762,1.99742192845402,23.9599999040365,0.0657595016825337,0.0121995301669839,0.25,2.98182893129534E-5,0.00582597929286856,7.30529580996117E-5,9.9828,9.9828,54007.2578125,54061.7734375,56.0380750577367,19.5630042860218,6.963661,0,0,0,40,4961,9.98325,54034.515625,,,,,,,,,,,,,0,,,,,,,,,,,,,,
,20375218.28,9.98485,57447.169921875,0.00591162918078155,2.17001754104133E-6,1,0.999253354069792,40.0298881530762,1.99732632818846,23.9700004458427,0.0666956819748036,0.0123855060710983,0.25,3.11878803015887E-5,0.00590937254909248,7.51521642638419E-5,9.9851,9.9851,57424.6171875,57469.72265625,56.0685585699867,19.5630588271826,6.963661,0,0,0,40,4961,9.98485,57447.169921875,,,,,,,,,,,,,0,,,,,,,,,,,,,,
,20375286.695,9.9869,60865.875,0.00598146812514785,2.05319375940868E-6,1,0.999253354069792,40.0298881530762,1.99718304358496,23.9700004458427,0.0675034295907479,0.0125206618573346,0.25,3.02709182943619E-5,0.0059811302000117,7.47930487675226E-5,9.9871,9.9871,60843.27734375,60888.47265625,55.913796123179,19.5631857434634,6.58401,0,0,0,40,4961,9.9869,60865.875,,,,,,,,,,,,,0,,,,,,,,,,,,,,
,20375354.845,9.99295,64274.970703125,0.00604272433578132,2.27726472230951E-6,1,0.999253354069792,40.0298881530762,1.99730222799422,23.9599999040365,0.0682223046984736,0.0126403835981459,0.25,2.94821514697486E-5,0.00604428000602704,7.44162453838287E-5,9.9928,9.9928,64247.7109375,64302.23046875,55.700411537429,19.5645856224229,6.58401,0,0,0,40,4961,9.99295,64274.970703125,,,,,,,,,,,,,0,,,,,,,,,,,,,,
,20375423.685,9.99445,67715.6796875,0.0060891882675779,1.99368801195826E-6,1,0.999253354069792,40.0298881530762,1.99724788194683,23.9599999040365,0.0687548774320635,0.0128029924244812,0.25,3.53254355138002E-5,0.00609256970386571,8.0487977371813E-5,9.9945,9.9945,67690.8046875,67740.5546875,55.4010478145636,19.5557544514793,6.58401,0,0,0,40,4961,9.99445,67715.6796875,,,,,,,,,,,,,0,,,,,,,,,,,,,,
,20375492.275,9.9966,71143.9375,0.00613226045808603,2.42656274455726E-6,1,0.999253354069792,40.0298881530762,1.99736005735855,23.9599999040365,0.0692747719111046,0.0128446456292239,0.25,3.10665423341265E-5,0.00613749284222615,7.63570158350754E-5,9.9967,9.9967,71114.109375,71173.765625,55.3549317319289,19.5709986267494,6.204359,0,0,0,40,4961,9.9966,71143.9375,,,,,,,,,,,,,0,,,,,,,,,,,,,,
,20375559.5,10.0016,74505.0625,0.00615635839850906,2.65678612331077E-6,1,0.999253354069792,40.0298881530762,1.99745969009946,23.9700004458427,0.0695631479860528,0.0129342899369036,0.25,3.4549378901025E-5,0.00616328445120964,7.97766570301666E-5,10.0019,10.0019,74482.6796875,74527.4453125,55.0868331498328,19.5648983492027,6.58401,0,0,0,40,4961,10.0016,74505.0625,,,,,,,,,,,,,0,,,,,,,,,,,,,,
,20375630.38,10.00135,78045.7578125,0.00619378810310736,2.43508799255886E-6,1,0.999253354069792,40.0298881530762,1.99746017506901,23.9700004458427,0.0699931753922607,0.013085285749959,0.25,4.11717251888826E-5,0.00620243580156052,8.63680981979821E-5,10.0007,10.0007,78021.0078125,78070.5078125,55.0282110108904,19.5622007371919,6.204359,0,0,0,40,4961,10.00135,78045.7578125,,,,,,,,,,,,,0,,,,,,,,,,,,,,
,20375700.73,10.0063,81562.37890625,0.00620953240910295,3.31591741494322E-6,1,0.999253354069792,40.0298881530762,1.99753538108758,23.9599999040365,0.070206760662114,0.0130413024201644,0.25,3.44878639398722E-5,0.00621989596572389,7.94252444057751E-5,10.0062,10.0062,81559.9140625,81564.84375,55.0688556938904,19.5703121928065,6.58401,0,0,0,40,4961,10.0063,81562.37890625,,,,,,,,,,,,,0,,,,,,,,,,,,,,
,20375768.325,10.0094,84943.44921875,0.00622261461565864,2.31617411236048E-6,1,0.999253354069792,40.0298881530762,1.9973575790396,23.9599999040365,0.0703719134388173,0.0130366517421653,0.25,3.19506355897181E-5,0.00623453375951055,7.65858944915293E-5,10.009,10.009,84918.2265625,84968.671875,55.4198068990251,19.5591983015361,6.58401,0,0,0,40,4961,10.0094,84943.44921875,,,,,,,,,,,,,0,,,,,,,,,,,,,,
,20375834.44,10.0138,88246.2265625,0.00622552538295731,3.3887531754264E-6,1,0.999253354069792,40.0298881530762,1.99762914618257,23.9599999040365,0.0704295260677241,0.0130495722134504,0.25,3.2590827806951E-5,0.00623886164114572,7.68315733352769E-5,10.0134,10.0134,88226.2109375,88266.2421875,55.3221033341212,19.5682820190931,6.58401,0,0,0,40,4961,10.0138,88246.2265625,,,,,,,,,,,,,0,,,,,,,,,,,,,,
,20375870.16,10.01625,89999.60546875,0.00623109773145071,2.52501857492636E-6,1,0.999253354069792,40.0298881530762,1.99758593988167,23.9599999040365,0.0705055287252937,0.0130278541515021,0.25,2.98022042942168E-5,0.00624519276634402,7.38429766363604E-5,10.0162,10.0162,89999.5703125,89999.640625,55.6034896010443,19.5535402579084,6.204359,0,0,0,40,4929,10.01625,89999.60546875,,,,,,,,,,,,,0,,,,,,,,,,,,,,