File: defense/images/np_vsm/data_dispersion/AH11_HYST_100OE_20K.DAT
[Header]
; VSM Data File (default extension .dat)
; Copyright (c) 2003-2013, Quantum Design, Inc. All rights reserved.
TITLE,
FILEOPENTIME,20376167.28,08/25/2018,5:01 am
BYAPP,VSM,2.0,2.0
INFO,PPMS VSM Option Release 1.4.10 Build 1,APPNAME
INFO,Quantum Design Linear Motor Servo Controller,MOTOR_MODULE_NAME
INFO,3101-100 M1,MOTOR_HW_VERSION
INFO,MMC1014,MOTOR_SERIAL_NUMBER
INFO,SRV No X-over 01.03.11,MOTOR_SOFTWARE_VERSION
INFO,Quantum Design VSM Detection Module,VSM_MODULE_NAME
INFO,3101-150 F0,VSM_HW_VERSION
INFO,VSM707,VSM_SERIAL_NUMBER
INFO,VSM No X-over 01.02.05 May 20 2008 13:51:47,VSM_SOFTWARE_VERSION
INFO,704,PREAMP_SERIAL_NUMBER
INFO,822,COIL_SERIAL_NUMBER
INFO,0,MOMENT_UNITS
INFO,CoFe2O4,SAMPLE_MATERIAL
INFO,Cobalt deficient,SAMPLE_COMMENT
INFO,,SAMPLE_MASS
INFO,27,SAMPLE_VOLUME
INFO,,SAMPLE_MOLECULAR_WEIGHT
INFO,,SAMPLE_SIZE
INFO,,SAMPLE_SHAPE
DATATYPE,COMMENT,1
DATATYPE,TIME,2
STARTUPAXIS,X,2
STARTUPAXIS,Y1,5
[Data]
Comment,Time Stamp (sec),Temperature (K),Magnetic Field (Oe),Moment (emu),M. Std. Err. (emu),Transport Action,Averaging Time (sec),Frequency (Hz),Peak Amplitude (mm),Center Position (mm),Coil Signal' (mV),Coil Signal" (mV),Range (mV),M. Quad. Signal (emu),M. Raw' (emu),M. Raw" (emu),Min. Temperature (K),Max. Temperature (K),Min. Field (Oe),Max. Field (Oe),Mass (grams),Motor Lag (deg),Pressure (Torr),VSM Status (code),Motor Status (code),Measure Status (code),Measure Count,PPMS Status (code),System Temp. (K),System Field (Oe),Sample Position (deg),Bridge 1 Resistance (ohms),Bridge 1 Excitation (에),Bridge 2 Resistance (ohms),Bridge 2 Excitation (에),Bridge 3 Resistance (ohms),Bridge 3 Excitation (에),Bridge 4 Resistance (ohms),Bridge 4 Excitation (에),Signal 1 Vin (V),Signal 2 Vin (V),Digital Inputs (code),Drive 1 Iout (mA),Drive 1 Ipower (W),Drive 2 Iout (mA),Drive 2 Ipower (W),Pressure (),Map 20 (),Map 21 (),Map 22 (),Map 23 (),Map 24 (),Map 25 (),Map 26 (),Map 27 (),Map 28 (),Map 29 ()
,20376183.89,19.9816513,31342.763671875,,,2,,,,24.1799992018938,,,,,,,19.9816513,19.9816513,31342.763671875,31342.763671875,,,6.58401,,,,-99999999,4961,20.0806,31342.763671875,,,,,,,,,,,,,,,,,,,,,,,19.9816513,,,,
,20376451.42,20.0321,3959.65234375,0.00322251741289274,4.65295971163653E-7,1,0.999253354069792,40.0298881530762,1.99649463024369,24.15999956429,0.0361715098984934,0.00661175296234239,0.25,1.5442022501846E-5,0.00320458164869966,3.17251157231528E-5,20.0321,20.0321,3957.20483398438,3962.09985351562,55.7645050760059,19.5489438686802,6.963661,0,0,0,40,4961,20.0321,3959.65234375,,,,,,,,,,,,,0,,,,,,,,,,,,,,
,20376532.75,20.0386,8019.29711914062,0.00337557547447624,5.41714826351942E-7,1,0.999253354069792,40.0298881530762,1.99635969802103,24.15999956429,0.0378966009273745,0.00693529779745256,0.25,1.59016747476677E-5,0.00335775289029654,3.39460742323186E-5,20.0386,20.0386,8016.8662109375,8021.72802734375,54.5819011264096,19.543046949395,6.58401,0,0,0,40,4961,20.0386,8019.29711914062,,,,,,,,,,,,,0,,,,,,,,,,,,,,
,20376613.775,20.0396,12070.2333984375,0.00352596444020522,7.42928606517235E-7,1,0.999253354069792,40.0298881530762,1.9962840640884,24.15999956429,0.0395948371150877,0.00725626802575822,0.25,1.64435929561054E-5,0.00350849953770022,3.63432271496703E-5,20.0396,20.0396,12065.22265625,12075.244140625,55.2462853677558,19.5391812590356,6.58401,0,0,0,40,4961,20.0396,12070.2333984375,,,,,,,,,,,,,0,,,,,,,,,,,,,,
,20376695.405,20.0385,16150.517578125,0.00367858513174315,8.39152178899021E-7,1,0.999253354069792,40.0298881530762,1.99662364176662,24.1700001060963,0.0413265489970487,0.00759612560606149,0.25,1.80312548843282E-5,0.00366168558454251,3.98587641176015E-5,20.039,20.039,16148.0185546875,16153.0166015625,55.0508782379481,19.5404346232112,6.963661,0,0,0,40,4961,20.0385,16150.517578125,,,,,,,,,,,,,0,,,,,,,,,,,,,,
,20376774.85,20.0367,20120.55859375,0.00382413300266519,9.26737715460694E-7,1,0.999253354069792,40.0298881530762,1.99671962908044,24.15999956429,0.0429808001694979,0.00789504426339837,0.25,1.72958866575285E-5,0.00380800739738842,4.10105337552997E-5,20.036,20.036,20115.62109375,20125.49609375,55.6980666518713,19.5428872086016,6.58401,0,0,0,40,4961,20.0367,20120.55859375,,,,,,,,,,,,,0,,,,,,,,,,,,,,
,20376848.7,20.02745,23811.6171875,0.00395781631070776,9.23403325192585E-7,1,0.999253354069792,40.0298881530762,1.99547565567096,24.1700001060963,0.0444689747508216,0.00819287011562038,0.25,1.91194422648392E-5,0.00394256354109998,4.45580602252761E-5,20.0272,20.0272,23784.2890625,23838.9453125,55.2275262832943,19.566765175925,6.963661,0,0,0,40,4961,20.02745,23811.6171875,,,,,,,,,,,,,0,,,,,,,,,,,,,,
,20376922.235,20.02665,27487.0087890625,0.00408275324777173,1.40133445110382E-6,1,0.999253354069792,40.0298881530762,1.99605945449813,24.15999956429,0.0458996197974964,0.00847522497619279,0.25,2.05165625886527E-5,0.00406854504244847,4.75916269447851E-5,20.027,20.027,27462.326171875,27511.69140625,55.8598637553521,19.5482884737399,6.58401,0,0,0,40,4961,20.02665,27487.0087890625,,,,,,,,,,,,,0,,,,,,,,,,,,,,
,20376994.335,20.02715,31090.0546875,0.00419740350219115,1.01062783890383E-6,1,0.999253354069792,40.0298881530762,1.99636078112814,24.15999956429,0.0472111404707108,0.00872915422592854,0.25,2.13719314963686E-5,0.00418436975944117,4.99545943602261E-5,20.0287,20.0287,31065.056640625,31115.052734375,55.2955279644674,19.5429197402389,6.963661,0,0,0,40,4961,20.02715,31090.0546875,,,,,,,,,,,,,0,,,,,,,,,,,,,,
,20377068.975,20.02555,34820.625,0.0043090739130128,1.1431308305561E-6,1,0.999253354069792,40.0298881530762,1.99617724221647,24.15999956429,0.048479492423781,0.00897855590476229,0.25,2.25483090812616E-5,0.00429738281964903,5.25800332510003E-5,20.0258,20.0258,34798.234375,34843.015625,55.4885902087174,19.5463364619066,6.58401,0,0,0,40,4961,20.02555,34820.625,,,,,,,,,,,,,0,,,,,,,,,,,,,,
,20377142.165,20.02235,38478.265625,0.00440296352653112,1.85560010762156E-6,1,0.999253354069792,40.0298881530762,1.99626932670871,24.15999956429,0.0495592766830754,0.00916679742914327,0.25,2.14656338463947E-5,0.00439273106041365,5.27405620345556E-5,20.0216,20.0216,38450.6484375,38505.8828125,55.4182436419866,19.5457938841407,6.58401,0,0,0,40,4961,20.02235,38478.265625,,,,,,,,,,,,,0,,,,,,,,,,,,,,
,20377216.74,20.0212,42206.96484375,0.00449099945836191,1.42875749210299E-6,1,0.999253354069792,40.0298881530762,1.99610630954077,24.15999956429,0.0505545550247514,0.00941764824067466,0.25,2.71489733031821E-5,0.00448228738452979,5.95384721447965E-5,20.0207,20.0207,42184.48828125,42229.44140625,55.5433042050636,19.55055239693,6.58401,0,0,0,40,4961,20.0212,42206.96484375,,,,,,,,,,,,,0,,,,,,,,,,,,,,
,20377289.235,20.0181,45830.111328125,0.00456869794894833,1.55727001090912E-6,1,0.999253354069792,40.0298881530762,1.99570128313776,24.15999956429,0.0514444015010687,0.00955071724832735,0.25,2.44420393946062E-5,0.00456158202388507,5.77888869038249E-5,20.0174,20.0174,45802.98046875,45857.2421875,55.4033927001213,19.5547888835651,6.963661,0,0,0,40,4961,20.0181,45830.111328125,,,,,,,,,,,,,0,,,,,,,,,,,,,,
,20377362.945,20.01875,49513.470703125,0.00463350086256184,1.82740232753144E-6,1,0.999253354069792,40.0298881530762,1.99633033424466,24.15999956429,0.0521956384843718,0.00976993203356199,0.25,3.13498316858385E-5,0.00462798440755063,6.54647075163293E-5,20.0185,20.0185,49490.4765625,49536.46484375,55.9630387198905,19.5515022942982,6.58401,0,0,0,40,4961,20.01875,49513.470703125,,,,,,,,,,,,,0,,,,,,,,,,,,,,
,20377435.595,20.0183,53143.86328125,0.00469475756832798,1.6217672375124E-6,1,0.999253354069792,40.0298881530762,1.99619677466399,24.15999956429,0.0529132512655344,0.00983740154814445,0.25,2.58459499841886E-5,0.00469092093755992,6.0626547080459E-5,20.0202,20.0202,53114.0390625,53173.6875,55.3033442496597,19.5461156372892,6.58401,0,0,0,40,4961,20.0183,53143.86328125,,,,,,,,,,,,,0,,,,,,,,,,,,,,
,20377507.46,20.01895,56737.119140625,0.00475146474172086,2.13198274119636E-6,1,0.999253354069792,40.0298881530762,1.99641758155933,24.15999956429,0.0535655487875213,0.0100235714831522,0.25,3.16213250337589E-5,0.00474920973119751,6.69413789591008E-5,20.0192,20.0192,56712.44140625,56761.796875,54.9820949282558,19.54467906928,7.343312,0,0,0,40,4961,20.01895,56737.119140625,,,,,,,,,,,,,0,,,,,,,,,,,,,,
,20377581.04,20.0179,60415.5625,0.00479766059243733,2.04057158183334E-6,1,0.999253354069792,40.0298881530762,1.99617172081323,24.15999956429,0.0541083219522359,0.0100708586029134,0.25,2.72563037854682E-5,0.00479709219511476,6.29650449607278E-5,20.0177,20.0177,60385.4921875,60445.6328125,54.7718368565827,19.5397937210842,6.963661,0,0,0,40,4961,20.0179,60415.5625,,,,,,,,,,,,,0,,,,,,,,,,,,,,
,20377654.71,20.0168,64096.708984375,0.00483537008009977,2.63485645109237E-6,1,0.999253354069792,40.0298881530762,1.99620432561999,24.15999956429,0.0545445277147021,0.0101998511682453,0.25,3.16204478619938E-5,0.00483639822682078,6.75778866023791E-5,20.0164,20.0164,64069.2421875,64124.17578125,54.8273324814481,19.5436169528211,6.58401,0,0,0,40,4961,20.0168,64096.708984375,,,,,,,,,,,,,0,,,,,,,,,,,,,,
,20377728.985,20.0143,67810.203125,0.00487625081847234,2.16710308656E-6,1,0.999253354069792,40.0298881530762,1.99594863868009,24.15999956429,0.055009187093146,0.0103314164385108,0.25,3.5838675214907E-5,0.00487885771917783,7.19997089655563E-5,20.0144,20.0144,67807.5859375,67812.8203125,55.4370027264482,19.5554461513855,6.963661,0,0,0,40,4961,20.0143,67810.203125,,,,,,,,,,,,,0,,,,,,,,,,,,,,
,20377801.9,20.0127,71453.2265625,0.00490184405894645,2.25059098982664E-6,1,0.999253354069792,40.0298881530762,1.99653292365221,24.15999956429,0.0553377490556541,0.0103511522828055,0.25,3.26187724838839E-5,0.00490600542276655,6.88048103933304E-5,20.0126,20.0126,71430.46875,71475.984375,55.8856574964867,19.5356557887646,6.963661,0,0,0,40,4961,20.0127,71453.2265625,,,,,,,,,,,,,0,,,,,,,,,,,,,,
,20377875.93,20.01,75153.78515625,0.00492827930163458,2.65776976575364E-6,1,0.999253354069792,40.0298881530762,1.99619188015876,24.15999956429,0.055645776193016,0.0103975545300695,0.25,3.20770674321973E-5,0.00493395196777401,6.82357016747965E-5,20.0117,20.0117,75123.8359375,75183.734375,55.4565434394289,19.5443392070385,6.963661,0,0,0,40,4961,20.01,75153.78515625,,,,,,,,,,,,,0,,,,,,,,,,,,,,
,20377950.17,20.0085,78865.0703125,0.00494986156886002,2.84530145694674E-6,1,0.999253354069792,40.0298881530762,1.99608081500123,24.15999956429,0.0559001999182906,0.0104587887449787,0.25,3.36813629985562E-5,0.00495697723888668,6.97277117307171E-5,20.0085,20.0085,78862.4296875,78867.7109375,55.4096457282751,19.545055175939,6.963661,0,0,0,40,4961,20.0085,78865.0703125,,,,,,,,,,,,,0,,,,,,,,,,,,,,
,20378023.32,20.00825,82521.40625,0.00496997410513805,2.87803062545094E-6,1,0.999253354069792,40.0298881530762,1.99593683077748,24.15999956429,0.0561414461027043,0.010487926962338,0.25,3.27795023164358E-5,0.00497847545714853,6.86590728050116E-5,20.0087,20.0087,82491.625,82551.1875,55.0454068383135,19.5508619836703,7.343312,0,0,0,40,4961,20.00825,82521.40625,,,,,,,,,,,,,0,,,,,,,,,,,,,,
,20378094.665,20.0032,86087.5078125,0.00497823614743407,2.79630878167977E-6,1,0.999253354069792,40.0298881530762,1.9961461065622,24.15999956429,0.0562528569169011,0.010518497419349,0.25,3.40239499388914E-5,0.00498800055203073,6.96266027540823E-5,20.0037,20.0037,86065.0234375,86109.9921875,55.0391538101597,19.5532168091856,6.963661,0,0,0,40,4961,20.0032,86087.5078125,,,,,,,,,,,,,0,,,,,,,,,,,,,,
,20378164.945,20.00345,89598.51953125,0.0049885867278456,3.04253304672065E-6,1,0.999253354069792,40.0298881530762,1.99612947406327,24.15999956429,0.0563781075460553,0.0105682051645726,0.25,3.67202636349891E-5,0.00499953611208253,7.2040288711832E-5,20.0042,20.0042,89573.4765625,89623.5625,55.3307012478328,19.5461460709915,6.58401,0,0,0,40,4961,20.00345,89598.51953125,,,,,,,,,,,,,0,,,,,,,,,,,,,,
,20378249.86,20.00375,86906.44140625,0.00498009837729147,2.75381219644784E-6,1,0.999253354069792,40.0298881530762,1.99631406772822,24.1700001060963,0.0562784700891869,0.0105411343341813,0.25,3.56484605703834E-5,0.00499013551440028,7.11856827396244E-5,20.0041,20.0041,86879.0078125,86933.875,55.0344640390443,19.5372292493618,7.343312,0,0,0,40,4961,20.00375,86906.44140625,,,,,,,,,,,,,0,,,,,,,,,,,,,,
,20378321.425,20.0023,83327.91796875,0.00497440501621406,2.93998185028177E-6,1,0.999253354069792,40.0298881530762,1.99609803239462,24.15999956429,0.0561961920693659,0.0105147765783346,0.25,3.43081040995763E-5,0.00498319247980951,7.01486089511269E-5,20.0004,20.0004,83295.328125,83360.5078125,55.168904144352,19.5468767872544,6.963661,0,0,0,40,4961,20.0023,83327.91796875,,,,,,,,,,,,,0,,,,,,,,,,,,,,
,20378393.705,20.0041,79713.484375,0.00495533000633544,2.5618622597423E-6,1,0.999253354069792,40.0298881530762,1.99641726483024,24.15999956429,0.0559788326059451,0.010448841992884,0.25,3.16822042169052E-5,0.0049627860682783,6.76966739286723E-5,20.0048,20.0048,79680.8984375,79746.0703125,54.6788230627943,19.5431194148434,6.963661,0,0,0,40,4961,20.0041,79713.484375,,,,,,,,,,,,,0,,,,,,,,,,,,,,
,20378466.77,20.00255,76062.47265625,0.00493281208892213,3.4154989778281E-6,1,0.999253354069792,40.0298881530762,1.99618589553312,24.15999956429,0.0557050584385989,0.010384137679258,0.25,3.0077550492979E-5,0.00493885939339192,6.62046279910188E-5,20.0023,20.0023,76032.4453125,76092.5,55.4119906138328,19.5534266520995,6.58401,0,0,0,40,4961,20.00255,76062.47265625,,,,,,,,,,,,,0,,,,,,,,,,,,,,
,20378539.805,20.0029,72411.3828125,0.00490676473233467,2.51371729548098E-6,1,0.999253354069792,40.0298881530762,1.99606317965253,24.15999956429,0.0554025173523173,0.0102641159726214,0.25,2.42213702246794E-5,0.00491138085656751,6.03834480359877E-5,20.0024,20.0024,72383.9765625,72438.7890625,54.6670986350058,19.5405091273352,6.58401,0,0,0,40,4961,20.0029,72411.3828125,,,,,,,,,,,,,0,,,,,,,,,,,,,,
,20378614.305,20.0038,68685.2890625,0.00487994857784157,2.39511351946488E-6,1,0.999253354069792,40.0298881530762,1.996562334056,24.15999956429,0.055082023571013,0.0102830152554159,0.25,3.05906723162344E-5,0.00488296434216764,6.67422654454895E-5,20.0037,20.0037,68660.375,68710.203125,55.1782836865828,19.5407141891321,6.58401,0,0,0,40,4961,20.0038,68685.2890625,,,,,,,,,,,,,0,,,,,,,,,,,,,,
,20378688.01,20.00665,65004.416015625,0.00485151025443136,2.29731845231269E-6,1,0.999253354069792,40.0298881530762,1.99671099537953,24.15999956429,0.0547433320577887,0.0102425727643882,0.25,3.22250759397043E-5,0.00485293253467294,6.82839587096552E-5,20.0064,20.0064,64972.05078125,65036.78125,55.7121359652174,19.5389370113893,6.963661,0,0,0,40,4961,20.00665,65004.416015625,,,,,,,,,,,,,0,,,,,,,,,,,,,,
,20378761.78,20.0062,61315.779296875,0.0048108723215787,2.0018990923638E-6,1,0.999253354069792,40.0298881530762,1.99659874282834,24.15999956429,0.0542666290785091,0.0101364962483722,0.25,3.0437101239021E-5,0.00481068126607019,6.62429213454818E-5,20.0069,20.0069,61288.37890625,61343.1796875,55.9560040632175,19.5384213056669,6.204359,0,0,0,40,4961,20.0062,61315.779296875,,,,,,,,,,,,,0,,,,,,,,,,,,,,
,20378834.61,20.00665,57674.67578125,0.0047667976671853,1.70249430876378E-6,1,0.999253354069792,40.0298881530762,1.99671896526604,24.1700001060963,0.053762411106475,0.00999486264552081,0.25,2.60939380777884E-5,0.00476500575188839,6.15488195847545E-5,20.0062,20.0062,57644.47265625,57704.87890625,55.0180498401404,19.5356127249575,6.963661,0,0,0,40,4961,20.00665,57674.67578125,,,,,,,,,,,,,0,,,,,,,,,,,,,,
,20378907.445,20.00705,54034.26953125,0.00471812452042159,1.93903373579159E-6,1,0.999253354069792,40.0298881530762,1.99673156401147,24.15999956429,0.0531860047064309,0.00993905346198327,0.25,3.03098792091158E-5,0.0047146510012438,6.52981990861503E-5,20.0073,20.0073,54007.0703125,54061.46875,54.9781867856597,19.5285592744421,7.343312,0,0,0,40,4961,20.00705,54034.26953125,,,,,,,,,,,,,0,,,,,,,,,,,,,,
,20378981.475,20.0076,50336.36328125,0.00466084591035659,2.00766730031993E-6,1,0.999253354069792,40.0298881530762,1.99693352667838,24.15999956429,0.0525297673289669,0.009794761491853,0.25,2.82517366575219E-5,0.00465570868902078,6.26265336813281E-5,20.0076,20.0076,50309.0390625,50363.6875,54.8343671381212,19.5292113284719,6.963661,0,0,0,40,4961,20.0076,50336.36328125,,,,,,,,,,,,,0,,,,,,,,,,,,,,
,20379056.215,20.0068,46600.693359375,0.00459934479062621,1.75702745604085E-6,1,0.999253354069792,40.0298881530762,1.99667996840847,24.15999956429,0.0518196260834344,0.00961023896579427,0.25,2.36697180127819E-5,0.00459255331045809,5.73124277986878E-5,20.0076,20.0076,46576.0234375,46625.36328125,55.4244966701405,19.5375941650383,6.963661,0,0,0,40,4961,20.0068,46600.693359375,,,,,,,,,,,,,0,,,,,,,,,,,,,,
,20379137.14,20.0066,42557.60546875,0.0045235935277572,1.53890046786604E-6,1,0.999253354069792,40.0298881530762,1.9966135570741,24.15999956429,0.0509419896355645,0.00945361289228661,0.25,2.41984572526794E-5,0.00451500639638012,5.68705546537827E-5,20.006,20.006,42527.46484375,42587.74609375,55.1173166620828,19.5366732937796,6.58401,0,0,0,40,4961,20.0066,42557.60546875,,,,,,,,,,,,,0,,,,,,,,,,,,,,
,20379209.465,20.0085,38939.13671875,0.00445062399942087,1.64280813365268E-6,1,0.999253354069792,40.0298881530762,1.99650076173457,24.15999956429,0.0501017015866104,0.00927872876011419,0.25,2.26301854070485E-5,0.0044404899926867,5.43082529291689E-5,20.0079,20.0079,38914.53125,38963.7421875,54.5998785823519,19.5467503886642,7.343312,0,0,0,40,4961,20.0085,38939.13671875,,,,,,,,,,,,,0,,,,,,,,,,,,,,
,20379283.18,20.0089,35256.505859375,0.00436379900387321,1.391719469547E-6,1,0.999253354069792,40.0298881530762,1.99664652148797,24.15999956429,0.0491099926496582,0.00908651894771877,0.25,2.20060652590077E-5,0.00435216535027572,5.24955300927194E-5,20.0088,20.0088,35231.57421875,35281.4375,54.7343186876596,19.5439513190217,6.58401,0,0,0,40,4961,20.0089,35256.505859375,,,,,,,,,,,,,0,,,,,,,,,,,,,,
,20379355.43,20.00915,31643.6201171875,0.0042755185797945,1.38419753006963E-6,1,0.999253354069792,40.0298881530762,1.99663233543026,24.15999956429,0.0480972660960481,0.00890181345993044,0.25,2.24224670520981E-5,0.00426248526476103,5.16428970356714E-5,20.0081,20.0081,31613.576171875,31673.6640625,55.2728607374097,19.5375474407732,6.58401,0,0,0,40,4961,20.00915,31643.6201171875,,,,,,,,,,,,,0,,,,,,,,,,,,,,
,20379428.195,20.00975,28008.1552734375,0.00417835286747097,1.12809195217505E-6,1,0.999253354069792,40.0298881530762,1.99672131400797,24.15999956429,0.0469908654935753,0.00868202087168869,0.25,2.13420350858883E-5,0.00416403388761163,4.91628851622082E-5,20.0086,20.0086,27975.95703125,28040.353515625,55.3697826737943,19.5304928677922,6.58401,0,0,0,40,4961,20.00975,28008.1552734375,,,,,,,,,,,,,0,,,,,,,,,,,,,,
,20379501.205,20.0109,24359.88671875,0.00406912963853468,1.03462652876119E-6,1,0.999253354069792,40.0298881530762,1.99662407663385,24.15999956429,0.0457427880741961,0.00845363394482631,0.25,2.17734045774373E-5,0.00405365827267386,4.80489269939099E-5,20.012,20.012,24332.384765625,24387.388671875,55.0336824105251,19.5321632351495,6.58401,0,0,0,40,4961,20.0109,24359.88671875,,,,,,,,,,,,,0,,,,,,,,,,,,,,
,20379573.425,20.01405,20749.2421875,0.00395749584265786,9.57805694672382E-7,1,0.999253354069792,40.0298881530762,1.99691324114448,24.15999956429,0.0444796785962857,0.00821005742218479,0.25,2.11585264657685E-5,0.003941028287162,4.58446588349017E-5,20.0152,20.0152,20724.1875,20774.296875,55.2353425684866,19.5337601196494,7.343312,0,0,0,40,4961,20.01405,20749.2421875,,,,,,,,,,,,,0,,,,,,,,,,,,,,
,20379644.865,20.0143,17178.6533203125,0.00383409396151,8.89438597347332E-7,1,0.999253354069792,40.0298881530762,1.99698249207828,24.15999956429,0.043080667217052,0.0079441258916871,0.25,2.07281943023279E-5,0.00381683136427246,4.37399093057736E-5,20.0146,20.0146,17151.2421875,17206.064453125,55.2931830789097,19.5290795618754,6.58401,0,0,0,40,4961,20.0143,17178.6533203125,,,,,,,,,,,,,0,,,,,,,,,,,,,,
,20379718.14,20.0128,13518.865234375,0.00369967059069109,6.04479513042506E-7,1,0.999253354069792,40.0298881530762,1.99685533329361,24.15999956429,0.0415593085138769,0.0076320637955532,0.25,1.82291815174882E-5,0.00368179972664773,3.9491060562105E-5,20.0133,20.0133,13488.9658203125,13548.7646484375,55.2017325421597,19.5371478810674,6.963661,0,0,0,40,4961,20.0128,13518.865234375,,,,,,,,,,,,,0,,,,,,,,,,,,,,
,20379791.235,20.0111,9865.60302734375,0.00355325140595022,6.352546007108E-7,1,0.999253354069792,40.0298881530762,1.99684305756576,24.15999956429,0.0399045775924413,0.0073129604292144,0.25,1.71374549632104E-5,0.00353499983442631,3.66115997706053E-5,20.0109,20.0109,9830.5791015625,9900.626953125,54.8687587929673,19.5336797406576,6.58401,0,0,0,40,4961,20.0111,9865.60302734375,,,,,,,,,,,,,0,,,,,,,,,,,,,,
,20379864.83,20.00905,6184.33374023437,0.00339549186265382,4.84591105690513E-7,1,0.999253354069792,40.0298881530762,1.99683770968773,24.15999956429,0.0381249077280877,0.00697000777627235,0.25,1.58414597414561E-5,0.0033771049701221,3.35355444070599E-5,20.0095,20.0095,6161.52294921875,6207.14453125,55.1071554913327,19.5323060210171,6.963661,0,0,0,40,4961,20.00905,6184.33374023437,,,,,,,,,,,,,0,,,,,,,,,,,,,,
,20379936.47,20.0024,2606.23986816406,0.00322374571035585,4.78792250048827E-7,1,0.999253354069792,40.0298881530762,1.99720403702369,24.15999956429,0.0361955112552488,0.00661044392589929,0.25,1.52506143941783E-5,0.00320553651343772,3.12463513369715E-5,20.003,20.003,2573.94750976562,2638.5322265625,55.1024657202174,19.5290441695972,6.58401,0,0,0,40,4961,20.0024,2606.23986816406,,,,,,,,,,,,,0,,,,,,,,,,,,,,
,20380007.96,20.009,-966.110687255859,0.00302865887599485,5.12847306288406E-7,1,0.999253354069792,40.0298881530762,1.99703679263733,24.15999956429,0.033999626323494,0.0062081520699047,0.25,1.45184657521943E-5,0.00301128726704615,2.92454024030851E-5,20.0082,20.0082,-993.434143066406,-938.787231445313,54.6420865223904,19.5410599326467,6.58401,0,0,0,40,4961,20.009,-966.110687255859,,,,,,,,,,,,,0,,,,,,,,,,,,,,
,20380081.49,20.00255,-4639.77685546875,0.00277868916458412,5.47101198376885E-7,1,0.999253354069792,40.0298881530762,1.99684792230398,24.15999956429,0.0311963249136252,0.00570253893296134,0.25,1.32024273685282E-5,0.00276334589341981,2.73736226140278E-5,20.0016,20.0016,-4664.5869140625,-4614.966796875,54.8171713106981,19.5330604083749,6.963661,0,0,0,40,4961,20.00255,-4639.77685546875,,,,,,,,,,,,,0,,,,,,,,,,,,,,
,20380154.515,20.0045,-8290.662109375,0.00245618886040272,5.00098322140398E-7,1,0.999253354069792,40.0298881530762,1.99672617338861,24.15999956429,0.0275806588297543,0.0050453976563115,0.25,1.13490115156687E-5,0.00244327131095859,2.45274714998057E-5,20.0043,20.0043,-8313.2197265625,-8268.1044921875,54.850781337025,19.5374231282002,6.963661,0,0,0,40,4961,20.0045,-8290.662109375,,,,,,,,,,,,,0,,,,,,,,,,,,,,
,20380227.835,20.00815,-11954.0903320312,0.00197430022007963,6.65353147059907E-7,1,0.999253354069792,40.0298881530762,1.99697529673839,24.15999956429,0.0221773036957616,0.00406547949959601,0.25,9.32832838334035E-6,0.00196450002287785,2.04524250788614E-5,20.0085,20.0085,-11986.673828125,-11921.5068359375,55.4581066964674,19.5345129669161,6.963661,0,0,0,40,4961,20.00815,-11954.0903320312,,,,,,,,,,,,,0,,,,,,,,,,,,,,
,20380300.85,20.0097,-15605.0595703125,0.00121178856359189,8.81450323117805E-7,1,0.999253354069792,40.0298881530762,1.99682195870912,24.15999956429,0.013614940014317,0.00249865014439426,0.25,5.6521673291783E-6,0.00120616240592708,1.27972470320141E-5,20.0093,20.0093,-15629.9384765625,-15580.1806640625,55.4690494957366,19.5294358368268,6.963661,0,0,0,40,4961,20.0097,-15605.0595703125,,,,,,,,,,,,,0,,,,,,,,,,,,,,
,20380374.91,20.0095,-19305.244140625,8.18512967116885E-5,1.14896799494977E-6,1,0.999253354069792,40.0298881530762,1.99677882464832,24.1700001060963,0.00092150969375066,0.000160029936286981,0.25,-4.20830440012278E-7,8.15045520809801E-5,8.57691668231962E-8,20.009,20.009,-19332.90625,-19277.58203125,54.5334401582173,19.5327711414159,7.343312,0,0,0,40,4961,20.0095,-19305.244140625,,,,,,,,,,,,,0,,,,,,,,,,,,,,
,20380447.51,20.0127,-22933.111328125,-0.00122536751875954,1.01447818335265E-6,1,0.999253354069792,40.0298881530762,1.99683030547702,24.15999956429,-0.0137756757838226,-0.00253756203166234,0.25,-5.9449548126742E-6,-0.00122053679243835,-1.3756601534079E-5,20.0127,20.0127,-22965.64453125,-22900.578125,55.0712005794481,19.5361469109343,6.963661,0,0,0,40,4961,20.0127,-22933.111328125,,,,,,,,,,,,,0,,,,,,,,,,,,,,
,20380521.07,20.0151,-26610.5224609375,-0.00240648129278775,1.17654076037961E-6,1,0.999253354069792,40.0298881530762,1.99713844709141,24.15999956429,-0.0270600519568697,-0.00503038457251898,0.25,-1.51123486635703E-5,-0.00239786900259412,-3.09475574206333E-5,20.0137,20.0137,-26643.267578125,-26577.77734375,55.5393960624674,19.5307367184582,6.963661,0,0,0,40,4961,20.0151,-26610.5224609375,,,,,,,,,,,,,0,,,,,,,,,,,,,,
,20380594.82,20.0125,-30296.064453125,-0.00324658821576262,1.39410063200119E-6,1,0.999253354069792,40.0298881530762,1.99682853862859,24.15999956429,-0.036520059193215,-0.00676217888908774,0.25,-1.74885669241686E-5,-0.00323622973321799,-3.94720186222283E-5,20.0125,20.0125,-30301.201171875,-30290.927734375,55.2931830789097,19.5249538723267,6.963661,0,0,0,40,4961,20.0125,-30296.064453125,,,,,,,,,,,,,0,,,,,,,,,,,,,,
,20380667.275,20.0139,-33917.0546875,-0.00377866449410374,1.60725089769794E-6,1,0.999253354069792,40.0298881530762,1.99702106008963,24.15999956429,-0.0425207751009733,-0.00790015610240504,0.25,-2.20697790191073E-5,-0.00376803532486248,-4.82601943995948E-5,20.0127,20.0127,-33949.7578125,-33884.3515625,55.2267446547751,19.5311965199198,6.963661,0,0,0,40,4961,20.0139,-33917.0546875,,,,,,,,,,,,,0,,,,,,,,,,,,,,
,20380741.79,20.01465,-37642.078125,-0.00411303490702503,1.62563419178493E-6,1,0.999253354069792,40.0298881530762,1.99704715884142,24.15999956429,-0.0463063104759648,-0.00858040361147738,0.25,-2.14780421420021E-5,-0.00410310232415862,-5.05737594995706E-5,20.0143,20.0143,-37672.0625,-37612.09375,55.4479455257174,19.5363961952374,6.58401,0,0,0,40,4961,20.01465,-37642.078125,,,,,,,,,,,,,0,,,,,,,,,,,,,,
,20380814.515,20.01195,-41274.84765625,-0.00431887031029519,1.6763475835272E-6,1,0.999253354069792,40.0298881530762,1.99686320184606,24.15999956429,-0.0486335306457453,-0.00903800279841611,0.25,-2.43441116318625E-5,-0.00431008199993413,-5.53847708748375E-5,20.0117,20.0117,-41299.46875,-41250.2265625,55.3736908163905,19.5295695546916,6.963661,0,0,0,40,4961,20.01195,-41274.84765625,,,,,,,,,,,,,0,,,,,,,,,,,,,,
,20380888.02,20.01205,-44950.845703125,-0.00446635846460873,1.8620974669734E-6,1,0.999253354069792,40.0298881530762,1.99691729486687,24.15999956429,-0.0503171783571473,-0.00933862385610369,0.25,-2.37311978933922E-5,-0.00445899598199584,-5.62473898638406E-5,20.0126,20.0126,-44978.10546875,-44923.5859375,54.4771629048327,19.5336480846996,6.963661,0,0,0,40,4961,20.01205,-44950.845703125,,,,,,,,,,,,,0,,,,,,,,,,,,,,
,20380961.805,20.01045,-48635.869140625,-0.0045720241570783,1.74842516895546E-6,1,0.999253354069792,40.0298881530762,1.996851549442,24.15999956429,-0.0515157426506617,-0.00961738827407104,0.25,-2.88231162919377E-5,-0.00456618809745044,-6.24249483531691E-5,20.0107,20.0107,-48665.8984375,-48605.83984375,54.5381299293327,19.5420372342805,6.963661,0,0,0,40,4961,20.01045,-48635.869140625,,,,,,,,,,,,,0,,,,,,,,,,,,,,
,20381035.155,20.0099,-52303.83984375,-0.00464999408180686,1.78271479361538E-6,1,0.999253354069792,40.0298881530762,1.99678805571939,24.1700001060963,-0.0524194958077222,-0.00974371315461323,0.25,-2.54721323563393E-5,-0.00464580656705001,-5.98814101828459E-5,20.0099,20.0099,-52328.68359375,-52278.99609375,54.9977274986404,19.5388981874408,6.963661,0,0,0,40,4961,20.0099,-52303.83984375,,,,,,,,,,,,,0,,,,,,,,,,,,,,
,20381109.065,20.011,-55994.00390625,-0.00471136237098868,2.10571647036934E-6,1,0.999253354069792,40.0298881530762,1.99680532653663,24.15999956429,-0.0531243480600702,-0.00991309138690226,0.25,-2.89757577239141E-5,-0.00470880544808956,-6.39802017056185E-5,20.0119,20.0119,-56021.625,-55966.3828125,55.2267446547751,19.5369910274603,6.963661,0,0,0,40,4961,20.011,-55994.00390625,,,,,,,,,,,,,0,,,,,,,,,,,,,,
,20381182.61,20.01085,-59672.001953125,-0.0047704224574622,2.38103914098289E-6,1,0.999253354069792,40.0298881530762,1.99673723072916,24.15999956429,-0.0538090976617739,-0.0100313880503589,0.25,-2.84895543555185E-5,-0.00476951465843263,-6.39930016655871E-5,20.0107,20.0107,-59699.625,-59644.37890625,55.3557133604482,19.5427660034689,6.58401,0,0,0,40,4961,20.01085,-59672.001953125,,,,,,,,,,,,,0,,,,,,,,,,,,,,
,20381255.905,20.00825,-63334.98828125,-0.00481094427061005,2.10269281261165E-6,1,0.999253354069792,40.0298881530762,1.99682928212228,24.15999956429,-0.054292988605879,-0.0100867819537341,0.25,-2.57888372112334E-5,-0.00481167795709853,-6.15759698566419E-5,20.0079,20.0079,-63357.51171875,-63312.46484375,55.4979697509482,19.5379666274765,6.963661,0,0,0,40,4961,20.00825,-63334.98828125,,,,,,,,,,,,,0,,,,,,,,,,,,,,
,20381330.555,20.00775,-67065.1953125,-0.00484842262718868,2.04778822698316E-6,1,0.999253354069792,40.0298881530762,1.99690372248199,24.15999956429,-0.0547311537784401,-0.0101962475565384,0.25,-2.85038166337174E-5,-0.00485075329982351,-6.44802818208827E-5,20.0075,20.0075,-67090.484375,-67039.90625,54.8218610818135,19.5328880011669,6.963661,0,0,0,40,4961,20.00775,-67065.1953125,,,,,,,,,,,,,0,,,,,,,,,,,,,,
,20381404.73,20.00535,-70769.91796875,-0.0048779009235583,2.50287258454664E-6,1,0.999253354069792,40.0298881530762,1.99682342877344,24.15999956429,-0.0550764037892232,-0.0102767828616752,0.25,-3.023989641562E-5,-0.00488178002503687,-6.62820340207591E-5,20.0038,20.0038,-70792.421875,-70747.4140625,55.3330461333905,19.5362659224129,6.58401,0,0,0,40,4961,20.00535,-70769.91796875,,,,,,,,,,,,,0,,,,,,,,,,,,,,
,20381478.595,20.00545,-74462.8359375,-0.00491070904789329,2.10511859388284E-6,1,0.999253354069792,40.0298881530762,1.99706781295346,24.1700001060963,-0.0554647482966694,-0.0103798305731324,0.25,-3.32912854797253E-5,-0.00491608055870279,-6.93677449501571E-5,20.0056,20.0056,-74490.375,-74435.296875,55.1446736602558,19.5380149748504,6.58401,0,0,0,40,4961,20.00545,-74462.8359375,,,,,,,,,,,,,0,,,,,,,,,,,,,,
,20381552.705,20.00355,-78165.578125,-0.0049343045675116,2.55947081805478E-6,1,0.999253354069792,40.0298881530762,1.99670965099224,24.15999956429,-0.0557419356034419,-0.0104082951652981,0.25,-3.17309962100118E-5,-0.0049411477757669,-6.7716074271886E-5,20.0039,20.0039,-78192.953125,-78138.203125,55.2220548836597,19.5415078763406,6.58401,0,0,0,40,4961,20.00355,-78165.578125,,,,,,,,,,,,,0,,,,,,,,,,,,,,
,20381627.8,20.0024,-81918.66796875,-0.0049472784623762,2.58086437278353E-6,1,0.999253354069792,40.0298881530762,1.99702829084871,24.15999956429,-0.0559159048104649,-0.0104221989743343,0.25,-3.05557593595179E-5,-0.00495553884593006,-6.63217177741543E-5,20.0018,20.0018,-81946.234375,-81891.1015625,55.832506757179,19.5404442549928,6.963661,0,0,0,40,4961,20.0024,-81918.66796875,,,,,,,,,,,,,0,,,,,,,,,,,,,,
,20381699.91,20.0025,-85523.84375,-0.00496091052635081,2.57775594846623E-6,1,0.999253354069792,40.0298881530762,1.99693681791115,24.15999956429,-0.0560771287122671,-0.0104796674323589,0.25,-3.33371073169479E-5,-0.00497045085669988,-6.88701316745755E-5,20.0025,20.0025,-85548.6015625,-85499.0859375,55.5808223739866,19.5308690088599,7.343312,0,0,0,40,4961,20.0025,-85523.84375,,,,,,,,,,,,,0,,,,,,,,,,,,,,
,20381770.69,20.00175,-89058.625,-0.0049647028658601,2.68438800060846E-6,1,0.999253354069792,40.0298881530762,1.99709312540787,24.15999956429,-0.0561365350866543,-0.0104970911638275,0.25,-3.42777832830319E-5,-0.00497543839042068,-6.94807402509908E-5,20.0015,20.0015,-89081.171875,-89036.078125,55.2798953940828,19.5328817561319,6.963661,0,0,0,40,4961,20.00175,-89058.625,,,,,,,,,,,,,0,,,,,,,,,,,,,,
,20381857.065,20.001,-87401.47265625,-0.00496441674897265,3.46016276021985E-6,1,0.999253354069792,40.0298881530762,1.99712344372292,24.15999956429,-0.0561246887917812,-0.0105132692942898,0.25,-3.56687977583956E-5,-0.00497458890680457,-7.10443017973796E-5,20.0017,20.0017,-87428.9140625,-87374.03125,56.056052513679,19.5362129554016,6.963661,0,0,0,40,4961,20.001,-87401.47265625,,,,,,,,,,,,,0,,,,,,,,,,,,,,
,20381930.065,20.00135,-83751.05859375,-0.00495341772158627,2.36414130312836E-6,1,0.999253354069792,40.0298881530762,1.99700454829801,24.15999956429,-0.0559949286668788,-0.0104203288208239,0.25,-2.93496897045577E-5,-0.00496235266112098,-6.49909072154005E-5,20.0022,20.0022,-83776.0546875,-83726.0625,55.8215639579098,19.5398440370006,6.963661,0,0,0,40,4961,20.00135,-83751.05859375,,,,,,,,,,,,,0,,,,,,,,,,,,,,
,20382003.665,19.99975,-80075.9375,-0.00494074283001998,2.56394309309884E-6,1,0.999253354069792,40.0298881530762,1.99699067231864,24.15999956429,-0.0558149480196661,-0.0105095915215325,0.25,-3.94318866435919E-5,-0.0049482543402498,-7.53228240613296E-5,19.999,19.999,-80103.046875,-80048.828125,55.3338277619097,19.5362472388829,6.58401,0,0,0,40,4961,19.99975,-80075.9375,,,,,,,,,,,,,0,,,,,,,,,,,,,,
,20382078.15,20.00085,-76350.9453125,-0.004918991445455,2.27397394442302E-6,1,0.999253354069792,40.0298881530762,1.99717981815469,24.15999956429,-0.0555716329166002,-0.0103879918242966,0.25,-3.24723211483684E-5,-0.00492511511387694,-6.84810345265913E-5,20,20,-76370.9296875,-76330.9609375,55.1274778328328,19.5356880827182,6.963661,0,0,0,40,4961,20.00085,-76350.9453125,,,,,,,,,,,,,0,,,,,,,,,,,,,,
,20382151.885,20.00055,-72667.76171875,-0.00490054563657756,2.12087743988522E-6,1,0.999253354069792,40.0298881530762,1.99705878236626,24.15999956429,-0.0553372590042179,-0.0103813196860309,0.25,-3.52724012161801E-5,-0.004905177396289,-7.13850038364281E-5,19.9996,19.9996,-72692.5546875,-72642.96875,55.8074946445636,19.5386041024342,6.963661,0,0,0,40,4961,20.00055,-72667.76171875,,,,,,,,,,,,,0,,,,,,,,,,,,,,
,20382226.155,20.0026,-68955.4140625,-0.00487382865582922,2.40154141733634E-6,1,0.999253354069792,40.0298881530762,1.99717672295143,24.15999956429,-0.0550218402233155,-0.0103207257379848,0.25,-3.47540630795703E-5,-0.00487692226260714,-7.08521023744175E-5,20.0034,20.0034,-68960.453125,-68950.375,55.629283342179,19.5341900482315,6.58401,0,0,0,40,4961,20.0026,-68955.4140625,,,,,,,,,,,,,0,,,,,,,,,,,,,,
,20382299.775,20.0024,-65277.56640625,-0.00484222428071055,1.99846026749452E-6,1,0.999253354069792,40.0298881530762,1.99709372499527,24.15999956429,-0.0546524543399775,-0.0102107723286504,0.25,-3.09046718918386E-5,-0.00484377090804545,-6.68876547942071E-5,20.0026,20.0026,-65307.55078125,-65247.58203125,55.1845367147366,19.5338917511733,7.343312,0,0,0,40,4961,20.0024,-65277.56640625,,,,,,,,,,,,,0,,,,,,,,,,,,,,
,20382373.02,20.0045,-61614.484375,-0.00480550314767681,2.07981679926591E-6,1,0.999253354069792,40.0298881530762,1.99722998192519,24.15999956429,-0.0542250228304283,-0.0101223815917647,0.25,-2.98630753701157E-5,-0.0048054488939776,-6.56275897706058E-5,20.0045,20.0045,-61644.55078125,-61584.41796875,55.2611363096212,19.5318790034113,6.963661,0,0,0,40,4961,20.0045,-61614.484375,,,,,,,,,,,,,0,,,,,,,,,,,,,,
,20382447.1,20.00465,-57911.3984375,-0.00476245268414401,1.61634687577919E-6,1,0.999253354069792,40.0298881530762,1.99713535742413,24.15999956429,-0.0537195694462244,-0.0100198200374869,0.25,-2.88886658584028E-5,-0.00476074903328309,-6.43141698741779E-5,20.0031,20.0031,-57936.46484375,-57886.33203125,55.1931346284481,19.5318985315889,7.343312,0,0,0,40,4961,20.00465,-57911.3984375,,,,,,,,,,,,,0,,,,,,,,,,,,,,
,20382521.32,20.00625,-54201.4375,-0.00471386309468734,1.54467980075677E-6,1,0.999253354069792,40.0298881530762,1.99676397627001,24.15999956429,-0.0531487286907474,-0.00988010314662548,0.25,-2.58210542083262E-5,-0.00471050329384421,-6.07873250522645E-5,20.0059,20.0059,-54233.7265625,-54169.1484375,54.9430135022943,19.5300967448303,6.58401,0,0,0,40,4961,20.00625,-54201.4375,,,,,,,,,,,,,0,,,,,,,,,,,,,,
,20382594.695,20.0069,-50536.3984375,-0.00466092744704863,1.72520080590492E-6,1,0.999253354069792,40.0298881530762,1.99699032153578,24.15999956429,-0.0525383550806005,-0.00976664412532055,0.25,-2.56926054467825E-5,-0.00465590304950403,-6.00832954133109E-5,20.0089,20.0089,-50561.41796875,-50511.37890625,54.7812163988135,19.5337231110946,6.963661,0,0,0,40,4961,20.0069,-50536.3984375,,,,,,,,,,,,,0,,,,,,,,,,,,,,
,20382669.165,20.0043,-46816.10546875,-0.0046016108893384,1.61596334033907E-6,1,0.999253354069792,40.0298881530762,1.99688713305262,24.15999956429,-0.0518446635593868,-0.00965377832646903,0.25,-2.70007938371592E-5,-0.00459489371858277,-6.06743931766967E-5,20.0054,20.0054,-46843.7578125,-46788.453125,55.608961000679,19.5354540295019,6.963661,0,0,0,40,4961,20.0043,-46816.10546875,,,,,,,,,,,,,0,,,,,,,,,,,,,,
,20382744.965,20.0036,-43027.76171875,-0.00453428995578842,1.39097664097686E-6,1,0.999253354069792,40.0298881530762,1.99674677280327,24.15999956429,-0.0510595119277591,-0.00952538501986734,0.25,-2.84923075365851E-5,-0.00452587472209017,-6.12886543930191E-5,20.003,20.003,-43035.1640625,-43020.359375,54.1949950093904,19.5355292346304,6.963661,0,0,0,40,4961,20.0036,-43027.76171875,,,,,,,,,,,,,0,,,,,,,,,,,,,,
,20382817.405,20.00425,-39407.548828125,-0.00446059412744959,1.69440888728523E-6,1,0.999253354069792,40.0298881530762,1.99684428392891,24.15999956429,-0.0502251180147896,-0.00929903895266986,0.25,-2.23982964869554E-5,-0.00445065970112412,-5.42144431399536E-5,20.006,20.006,-39432.58203125,-39382.515625,55.0923045494674,19.5379318343027,7.343312,0,0,0,40,4961,20.00425,-39407.548828125,,,,,,,,,,,,,0,,,,,,,,,,,,,,
,20382892.94,20.00545,-35632.484375,-0.00437575266312821,1.13579340342129E-6,1,0.999253354069792,40.0298881530762,1.99676862117681,24.15999956429,-0.0492492651549134,-0.00911282315489453,0.25,-2.20510757737106E-5,-0.00436426100064896,-5.26873144470309E-5,20.0052,20.0052,-35664.8671875,-35600.1015625,55.5222002350443,19.5335827631108,6.963661,0,0,0,40,4961,20.00545,-35632.484375,,,,,,,,,,,,,0,,,,,,,,,,,,,,
,20382965.885,20.0059,-31987.658203125,-0.00428666601414566,9.13619130952002E-7,1,0.999253354069792,40.0298881530762,1.9968083294264,24.15999956429,-0.048225510188013,-0.00894261538843573,0.25,-2.38830603342262E-5,-0.00427374393448366,-5.32417804476648E-5,20.006,20.006,-32017.75,-31957.56640625,55.3690010452751,19.527453206616,6.58401,0,0,0,40,4961,20.0059,-31987.658203125,,,,,,,,,,,,,0,,,,,,,,,,,,,,
,20383040.205,20.007,-28272.1591796875,-0.00419031221357397,8.58778672277215E-7,1,0.999253354069792,40.0298881530762,1.99690337848298,24.15999956429,-0.0471269751303113,-0.008728959004737,0.25,-2.32208668342878E-5,-0.00417605457914507,-5.11721077176585E-5,20.0066,20.0066,-28299.767578125,-28244.55078125,55.0203947256981,19.5320622200785,6.58401,0,0,0,40,4961,20.007,-28272.1591796875,,,,,,,,,,,,,0,,,,,,,,,,,,,,
,20383118.165,20.0068,-24376.7138671875,-0.00407484880416981,8.61370305834841E-7,1,0.999253354069792,40.0298881530762,1.99692399688004,24.15999956429,-0.0458138758272529,-0.00846588869731471,0.25,-2.17243445581878E-5,-0.00405936290080076,-4.80408938038601E-5,20.0061,20.0061,-24406.81640625,-24346.611328125,55.1704674013905,19.5357755635704,6.58401,0,0,0,40,4961,20.0068,-24376.7138671875,,,,,,,,,,,,,0,,,,,,,,,,,,,,
,20383192.455,20.00675,-20661.19921875,-0.00395800553295196,7.70720995331941E-7,1,0.999253354069792,40.0298881530762,1.99693327321062,24.15999956429,-0.0444863232448373,-0.00820620486206177,0.25,-2.07464413689298E-5,-0.00394150402050394,-4.54149482923656E-5,20.0063,20.0063,-20688.5859375,-20633.8125,55.2541016529482,19.5350732254701,6.58401,0,0,0,40,4961,20.00675,-20661.19921875,,,,,,,,,,,,,0,,,,,,,,,,,,,,
,20383267.155,20.01015,-16930.9755859375,-0.00382817605918885,8.04917037020999E-7,1,0.999253354069792,40.0298881530762,1.99664977105849,24.15999956429,-0.0430086659507439,-0.00791735609238194,0.25,-1.95990291373345E-5,-0.00381085830474422,-4.25150204889136E-5,20.0097,20.0097,-16960.96484375,-16900.986328125,55.3971396719674,19.5322464898624,6.963661,0,0,0,40,4961,20.01015,-16930.9755859375,,,,,,,,,,,,,0,,,,,,,,,,,,,,
,20383338.695,20.00785,-13355.33984375,-0.00369501454030227,6.74713818607662E-7,1,0.999253354069792,40.0298881530762,1.99661239063926,24.15999956429,-0.0415021531883254,-0.00761828179195895,0.25,-1.79666602250032E-5,-0.00367711454028324,-3.91591411379598E-5,20.0085,20.0085,-13377.7666015625,-13332.9130859375,54.9367604741404,19.5338883810864,6.963661,0,0,0,40,4961,20.00785,-13355.33984375,,,,,,,,,,,,,0,,,,,,,,,,,,,,
,20383412.105,20.00715,-9684.9013671875,-0.00354492760827855,5.43392304170552E-7,1,0.999253354069792,40.0298881530762,1.99667724347044,24.15999956429,-0.0398047527894141,-0.00730975987445477,0.25,-1.844496586352E-5,-0.00352665989725778,-3.78190931379667E-5,20.0079,20.0079,-9714.916015625,-9654.88671875,54.6405232653519,19.5352153914036,6.963661,0,0,0,40,4961,20.00715,-9684.9013671875,,,,,,,,,,,,,0,,,,,,,,,,,,,,
,20383486.39,20.0036,-5971.11743164062,-0.00337985975933574,4.31092976726346E-7,1,0.999253354069792,40.0298881530762,1.99693461380465,24.15999956429,-0.0379477434857498,-0.00695398562745519,0.25,-1.7231339782756E-5,-0.00336149861365889,-3.4783548546442E-5,20.0027,20.0027,-5991.09814453125,-5951.13671875,55.2032957991982,19.5322560090849,6.963661,0,0,0,40,4961,20.0036,-5971.11743164062,,,,,,,,,,,,,0,,,,,,,,,,,,,,
,20383559.725,19.998,-2307.35363769531,-0.0031961910748847,4.36865592199229E-7,1,0.999253354069792,40.0298881530762,1.99676454185097,24.15999956429,-0.0358753442320588,-0.00656724851203175,0.25,-1.64987606688348E-5,-0.00317807580341568,-3.22883783456229E-5,19.9975,19.9975,-2332.2978515625,-2282.40942382813,54.474818019275,19.5338257298432,6.963661,0,0,0,40,4961,19.998,-2307.35363769531,,,,,,,,,,,,,0,,,,,,,,,,,,,,
,20383634.64,20.007,1436.53283691406,-0.00298025493753482,5.27188252348808E-7,1,0.999253354069792,40.0298881530762,1.99675634393776,24.15999956429,-0.0334513708908198,-0.0061148404806577,0.25,-1.47935067891562E-5,-0.00296322712713474,-2.93613498675409E-5,20.007,20.007,1429.15502929688,1443.91064453125,55.6933768807559,19.5355769717056,6.963661,0,0,0,40,4961,20.007,1436.53283691406,,,,,,,,,,,,,0,,,,,,,,,,,,,,
,20383707.585,19.9982,5081.24951171875,-0.00271926973558532,5.18297557958384E-7,1,0.999253354069792,40.0298881530762,1.99667951517001,24.15999956429,-0.0305262306988468,-0.00558843886758899,0.25,-1.35589112640615E-5,-0.00270433148792807,-2.75083017770937E-5,19.9985,19.9985,5051.236328125,5111.2626953125,55.3799438445443,19.5362993286341,6.58401,0,0,0,40,4961,19.9982,5081.24951171875,,,,,,,,,,,,,0,,,,,,,,,,,,,,
,20383781.485,20.0042,8774.2607421875,-0.00236949082175318,5.31101123756426E-7,1,0.999253354069792,40.0298881530762,1.99672766941951,24.15999956429,-0.0266066232552993,-0.00487603574759523,0.25,-1.16244855252491E-5,-0.00235711404429089,-2.44187345337435E-5,20.0034,20.0034,8744.185546875,8804.3359375,55.5698795747174,19.525818755325,6.963661,0,0,0,40,4961,20.0042,8774.2607421875,,,,,,,,,,,,,0,,,,,,,,,,,,,,
,20383855.285,20.00575,12465.673828125,-0.00184035660783962,6.69187167983743E-7,1,0.999253354069792,40.0298881530762,1.99666736363036,24.15999956429,-0.0206699043242737,-0.00379306110003924,0.25,-8.96459745122686E-6,-0.00183129975505144,-1.94011732470925E-5,20.0054,20.0054,12433.3173828125,12498.0302734375,54.6905474905827,19.5365646182789,6.204359,0,0,0,40,4961,20.00575,12465.673828125,,,,,,,,,,,,,0,,,,,,,,,,,,,,
,20383927.985,20.00775,16098.6811523438,-0.0010411897176225,7.385179318359E-7,1,0.999253354069792,40.0298881530762,1.99677494830854,24.15999956429,-0.011699076322322,-0.00214348916038498,0.25,-4.51472615102175E-6,-0.00103640453042277,-1.06912803926687E-5,20.0064,20.0064,16076.0244140625,16121.337890625,55.7809192749097,19.5352913742636,7.343312,0,0,0,40,4961,20.00775,16098.6811523438,,,,,,,,,,,,,0,,,,,,,,,,,,,,
,20383999.955,20.00895,19691.689453125,8.56365043719424E-5,1.136077076269E-6,1,0.999253354069792,40.0298881530762,1.99680831069639,24.15999956429,0.000962250042855613,0.000178192886994824,0.25,5.13584893352009E-7,8.52710227305006E-5,1.04170432832865E-6,20.0099,20.0099,19663.931640625,19719.447265625,55.3729091878712,19.5298052044329,6.58401,0,0,0,40,4961,20.00895,19691.689453125,,,,,,,,,,,,,0,,,,,,,,,,,,,,
,20384072.485,20.01075,23319.78515625,0.00137842762781967,1.01394319949503E-6,1,0.999253354069792,40.0298881530762,1.99677745683481,24.15999956429,0.0154950076318587,0.00286346049815963,0.25,7.44653979676576E-6,0.00137304191356177,1.62628812343642E-5,20.0097,20.0097,23287.4453125,23352.125,55.2611363096212,19.5334891861663,7.343312,0,0,0,40,4961,20.01075,23319.78515625,,,,,,,,,,,,,0,,,,,,,,,,,,,,
,20384145.535,20.01345,26970.740234375,0.00250646925061669,1.1748740435219E-6,1,0.999253354069792,40.0298881530762,1.99688069279201,24.15999956429,0.0281890374419055,0.00519950180802398,0.25,1.21886059520388E-5,0.00249761538786969,2.87428703776261E-5,20.0127,20.0127,26945.650390625,26995.830078125,55.3854152441789,19.5274952896913,6.58401,0,0,0,40,4961,20.01345,26970.740234375,,,,,,,,,,,,,0,,,,,,,,,,,,,,
,20384218.525,20.01225,30618.5673828125,0.00330248897470866,9.86062472757225E-7,1,0.999253354069792,40.0298881530762,1.99655325706539,24.15999956429,0.037143537567438,0.00688745466297348,0.25,1.85854181787361E-5,0.00329205819034751,4.09954341058934E-5,20.012,20.012,30593.703125,30643.431640625,54.8765750781596,19.5295447424914,6.963661,0,0,0,40,4961,20.01225,30618.5673828125,,,,,,,,,,,,,0,,,,,,,,,,,,,,
,20384291.89,20.01235,34284.376953125,0.00381323354138021,1.1446705489185E-6,1,0.999253354069792,40.0298881530762,1.99685911410143,24.15999956429,0.0429097425497846,0.00796313534160829,0.25,2.14180843359707E-5,0.0038026608653531,4.79077847169976E-5,20.0122,20.0122,34256.6328125,34312.12109375,55.0508782379481,19.5320627421831,6.963661,0,0,0,40,4961,20.01235,34284.376953125,,,,,,,,,,,,,0,,,,,,,,,,,,,,
,20384365.635,20.0112,37969.791015625,0.00412404003984716,1.45053839310889E-6,1,0.999253354069792,40.0298881530762,1.99683444779055,24.15999956429,0.0464174707573147,0.00865633293163477,0.25,2.62428936642532E-5,0.00411419012987089,5.54516994271769E-5,20.0119,20.0119,37939.921875,37999.66015625,54.678041434275,19.5285429497288,6.963661,0,0,0,40,4961,20.0112,37969.791015625,,,,,,,,,,,,,0,,,,,,,,,,,,,,
,20384439.015,20.0093,41638.138671875,0.00432810462333163,1.40561152604123E-6,1,0.999253354069792,40.0298881530762,1.99690590779453,24.15999956429,0.0487404581459328,0.00905740029114647,0.25,2.43136087870058E-5,0.0043194631188413,5.54647248505747E-5,20.0101,20.0101,41613.2109375,41663.06640625,55.077453607602,19.5221362358014,7.343312,0,0,0,40,4961,20.0093,41638.138671875,,,,,,,,,,,,,0,,,,,,,,,,,,,,
,20384513.865,20.01035,45378.970703125,0.00446931915682822,1.43199717597279E-6,1,0.999253354069792,40.0298881530762,1.99675237201896,24.15999956429,0.0503410072104771,0.0093877904233096,0.25,2.75474901987723E-5,0.00446212241642714,6.01208248364286E-5,20.0102,20.0102,45351.4453125,45406.49609375,55.4448190116405,19.5248905115552,6.963661,0,0,0,40,4961,20.01035,45378.970703125,,,,,,,,,,,,,0,,,,,,,,,,,,,,
,20384587.43,20.01025,49059.736328125,0.00457057589675271,1.77064816229327E-6,1,0.999253354069792,40.0298881530762,1.99680465875705,24.15999956429,0.0515075095118284,0.00957562594093191,0.25,2.53358565474278E-5,0.00456496454217939,5.8962139224723E-5,20.0113,20.0113,49034.6796875,49084.79296875,55.0844882642751,19.5276883587254,7.343312,0,0,0,40,4961,20.01025,49059.736328125,,,,,,,,,,,,,0,,,,,,,,,,,,,,
,20384662.32,20.0111,52797.474609375,0.00464729069121748,1.66124885373562E-6,1,0.999253354069792,40.0298881530762,1.99683850390671,24.15999956429,0.052391994518284,0.00974356931093219,0.25,2.58623049442655E-5,0.00464333085769235,6.02751638862403E-5,20.0109,20.0109,52767.4453125,52827.50390625,55.9630387198905,19.5314904061364,7.343312,0,0,0,40,4961,20.0111,52797.474609375,,,,,,,,,,,,,0,,,,,,,,,,,,,,
,20384737.315,20.0104,56548.103515625,0.00471350824801802,1.73160847403801E-6,1,0.999253354069792,40.0298881530762,1.99674166068318,24.15999956429,0.0531486171191482,0.00992427479714367,0.25,2.95485937745283E-5,0.00471119858076993,6.45828537808625E-5,20.0104,20.0104,56520.78515625,56575.421875,54.8351487666404,19.5368752438065,6.963661,0,0,0,40,4961,20.0104,56548.103515625,,,,,,,,,,,,,0,,,,,,,,,,,,,,
,20384811.76,20.0112,60268.701171875,0.00476699848857593,1.96887682696768E-6,1,0.999253354069792,40.0298881530762,1.99663564069263,24.15999956429,0.0537640219116983,0.0100622608929205,0.25,3.18356158542288E-5,0.00476633277093606,6.73154948138111E-5,20.0132,20.0132,60243.67578125,60293.7265625,55.8371965282944,19.5277879046772,6.58401,0,0,0,40,4961,20.0112,60268.701171875,,,,,,,,,,,,,0,,,,,,,,,,,,,,
,20384886.925,20.0118,64024.767578125,0.00481083005446235,2.01874539612069E-6,1,0.999253354069792,40.0298881530762,1.99682578749906,24.15999956429,0.0542805456675632,0.0101673162890333,0.25,3.28994251932924E-5,0.0048118109724777,6.86760524051766E-5,20.0118,20.0118,63997.62890625,64051.90625,55.5433042050636,19.5260924095651,6.963661,0,0,0,40,4961,20.0118,64024.767578125,,,,,,,,,,,,,0,,,,,,,,,,,,,,
,20384959.335,20.0085,67645.7265625,0.00484796310216348,1.98744086478065E-6,1,0.999253354069792,40.0298881530762,1.99676803790031,24.15999956429,0.0547174399679673,0.0102380765874215,0.25,3.23244766704152E-5,0.00485051013731729,6.82797092579221E-5,20.0086,20.0086,67615.6015625,67675.8515625,54.9187830181981,19.523353787931,6.963661,0,0,0,40,4961,20.0085,67645.7265625,,,,,,,,,,,,,0,,,,,,,,,,,,,,
,20385034.96,20.00695,71426.1640625,0.0048779155265355,2.23366180203463E-6,1,0.999253354069792,40.0298881530762,1.99669780052613,24.15999956429,0.0550729921078495,0.0102949681316005,0.25,3.1887940939215E-5,0.00488204970581938,6.78982635573173E-5,20.0079,20.0079,71418.734375,71433.59375,54.972715386025,19.5249267957837,6.963661,0,0,0,40,4961,20.00695,71426.1640625,,,,,,,,,,,,,0,,,,,,,,,,,,,,
,20385108.99,20.00545,75124.27734375,0.00490592511878082,2.24857721433095E-6,1,0.999253354069792,40.0298881530762,1.99681989184927,24.15999956429,0.0554117141300592,0.0103432647899858,0.25,3.10264113909133E-5,0.00491156709681967,6.70219425871811E-5,20.0051,20.0051,75096.921875,75151.6328125,55.1110636339289,19.5237117455949,6.963661,0,0,0,40,4961,20.00545,75124.27734375,,,,,,,,,,,,,0,,,,,,,,,,,,,,
,20385182.695,20.00685,78807.80859375,0.00492713448651588,1.88675768701487E-6,1,0.999253354069792,40.0298881530762,1.99682841207467,24.15999956429,0.0556659730302533,0.0103989629236781,0.25,3.21532354780621E-5,0.00493420600482834,6.80365770348655E-5,20.0079,20.0079,78780.15625,78835.4609375,54.7804347702943,19.525700965006,6.963661,0,0,0,40,4961,20.00685,78807.80859375,,,,,,,,,,,,,0,,,,,,,,,,,,,,
,20385257.875,20.0045,82566.6328125,0.00494684010187607,2.27050616270706E-6,1,0.999253354069792,40.0298881530762,1.99694194646013,24.15999956429,0.0558928121846046,0.010523881897991,0.25,3.96768737561614E-5,0.00495526725832111,7.53978078421889E-5,20.005,20.005,82544.359375,82588.90625,54.9969458701212,19.533299161845,7.343312,0,0,0,40,4961,20.0045,82566.6328125,,,,,,,,,,,,,0,,,,,,,,,,,,,,
,20385329.86,20.00405,86165.328125,0.0049568131151048,1.76224771395952E-6,1,0.999253354069792,40.0298881530762,1.99676274315534,24.15999956429,0.0560209461385834,0.0105133384822954,0.25,3.71516031362272E-5,0.00496653880805769,7.25999398143734E-5,20.0051,20.0051,86137.9140625,86192.7421875,55.8207823293905,19.5240409722688,6.963661,0,0,0,40,4961,20.00405,86165.328125,,,,,,,,,,,,,0,,,,,,,,,,,,,,
,20385400.155,20.0027,89678.82421875,0.00495942391954576,2.73857367778136E-6,1,0.999253354069792,40.0298881530762,1.99682492546846,24.15999956429,0.056069672422016,0.0104976684091348,0.25,3.54274761384199E-5,0.00497034316309813,7.05300793464786E-5,20.0028,20.0028,89646.265625,89711.3828125,54.853907851102,19.5262989752144,7.343312,0,0,0,40,4961,20.0027,89678.82421875,,,,,,,,,,,,,0,,,,,,,,,,,,,,
,20385406.615,20.0045,89996.07421875,0.00496206360422016,2.06741701752178E-6,1,0.999253354069792,40.0298881530762,1.99690190233358,24.15999956429,0.0561039360611186,0.0104972357299403,0.25,3.48963886251493E-5,0.00497309604096703,6.99825837350331E-5,20.0036,20.0036,89992.6875,89999.4609375,54.8875178774289,19.527553461488,7.343312,0,0,0,40,4929,20.0045,89996.07421875,,,,,,,,,,,,,0,,,,,,,,,,,,,,