File: defense/images/np_vsm/data_dispersion/AH11_FCC_100OE.DAT
[Header]
; VSM Data File (default extension .dat)
; Copyright (c) 2003-2013, Quantum Design, Inc. All rights reserved.
TITLE,
FILEOPENTIME,20353630.64,08/24/2018,10:46 pm
BYAPP,VSM,2.0,2.0
INFO,PPMS VSM Option Release 1.4.10 Build 1,APPNAME
INFO,Quantum Design Linear Motor Servo Controller,MOTOR_MODULE_NAME
INFO,3101-100 M1,MOTOR_HW_VERSION
INFO,MMC1014,MOTOR_SERIAL_NUMBER
INFO,SRV No X-over 01.03.11,MOTOR_SOFTWARE_VERSION
INFO,Quantum Design VSM Detection Module,VSM_MODULE_NAME
INFO,3101-150 F0,VSM_HW_VERSION
INFO,VSM707,VSM_SERIAL_NUMBER
INFO,VSM No X-over 01.02.05 May 20 2008 13:51:47,VSM_SOFTWARE_VERSION
INFO,704,PREAMP_SERIAL_NUMBER
INFO,822,COIL_SERIAL_NUMBER
INFO,0,MOMENT_UNITS
INFO,CoFe2O4,SAMPLE_MATERIAL
INFO,Cobalt deficient,SAMPLE_COMMENT
INFO,,SAMPLE_MASS
INFO,27,SAMPLE_VOLUME
INFO,,SAMPLE_MOLECULAR_WEIGHT
INFO,,SAMPLE_SIZE
INFO,,SAMPLE_SHAPE
DATATYPE,COMMENT,1
DATATYPE,TIME,2
STARTUPAXIS,X,2
STARTUPAXIS,Y1,5
[Data]
Comment,Time Stamp (sec),Temperature (K),Magnetic Field (Oe),Moment (emu),M. Std. Err. (emu),Transport Action,Averaging Time (sec),Frequency (Hz),Peak Amplitude (mm),Center Position (mm),Coil Signal' (mV),Coil Signal" (mV),Range (mV),M. Quad. Signal (emu),M. Raw' (emu),M. Raw" (emu),Min. Temperature (K),Max. Temperature (K),Min. Field (Oe),Max. Field (Oe),Mass (grams),Motor Lag (deg),Pressure (Torr),VSM Status (code),Motor Status (code),Measure Status (code),Measure Count,PPMS Status (code),System Temp. (K),System Field (Oe),Sample Position (deg),Bridge 1 Resistance (ohms),Bridge 1 Excitation (에),Bridge 2 Resistance (ohms),Bridge 2 Excitation (에),Bridge 3 Resistance (ohms),Bridge 3 Excitation (에),Bridge 4 Resistance (ohms),Bridge 4 Excitation (에),Signal 1 Vin (V),Signal 2 Vin (V),Digital Inputs (code),Drive 1 Iout (mA),Drive 1 Ipower (W),Drive 2 Iout (mA),Drive 2 Ipower (W),Pressure (),Map 20 (),Map 21 (),Map 22 (),Map 23 (),Map 24 (),Map 25 (),Map 26 (),Map 27 (),Map 28 (),Map 29 ()
,20354059.31,319.8799133,99.4721298217773,0.000299991841471182,4.8007478325397E-6,1,0.999253354069792,40.0298881530762,1.99843567322648,23.9599999040365,0.00301280452548405,0.00277812907958202,0.25,0.00019372294308685,0.000299652843953239,0.000193764404956794,319.8799133,319.8799133,99.4721298217773,99.4721298217773,55.128259461352,19.5406590557973,8.861917,0,0,0,40,4881,321.26415,99.4721298217773,,,,,,,,,,,,,0,,,,0,,,,,,319.8799133,,,,
,20354215.25,317.4686584,99.4721298217773,0.000307755207038416,5.19593401295984E-6,1,0.999253354069792,40.0298881530762,1.99828973648076,23.9700004458427,0.00309571542654385,0.0028215954689338,0.25,0.000196214736230314,0.000307432106451439,0.000196279983265275,317.4686584,317.4686584,99.4721298217773,99.4721298217773,55.3049075066982,19.535603101163,8.482265,0,0,0,40,4886,314.9974,99.4721298217773,,,,,,,,,,,,,0,,,,-0.00245,,,,,,317.4686584,,,,
,20354341.5,314.4794922,99.4721298217773,0.000304530839415965,5.56183359359369E-6,1,0.999253354069792,40.0298881530762,1.99817466727184,23.9599999040365,0.00305263518010442,0.00285443032667003,0.25,0.000199662240919336,0.000304238310002318,0.000199746534750298,314.4794922,314.4794922,99.4721298217773,99.4721298217773,54.9023688192943,19.5411662250535,9.241568,0,0,0,40,4886,311.8655,99.4721298217773,,,,,,,,,,,,,0,,,,0,,,,,,314.4794922,,,,
,20354472.38,311.4944153,99.4721298217773,0.000298995591389639,4.82868165248604E-6,1,0.999253354069792,40.0298881530762,1.99806158103245,23.9700004458427,0.00298622018532958,0.00286655700185102,0.25,0.000201678118333685,0.000298734575360081,0.000201781689683494,311.4944153,311.4944153,99.4721298217773,99.4721298217773,55.0008540127174,19.5408698851257,8.861917,0,0,0,40,4886,308.2713,99.4721298217773,,,,,,,,,,,,,0,,,,-0.0049,,,,,,311.4944153,,,,
,20354600.64,308.4867554,99.4721298217773,0.00030552025836,5.57739201032791E-6,1,0.999253354069792,40.0298881530762,1.99783894326033,23.9599999040365,0.00305165808605566,0.00292742665682828,0.25,0.000205927879228359,0.000305284473995093,0.00020605829257011,308.4867554,308.4867554,99.4721298217773,99.4721298217773,55.0258661253327,19.5414110727,9.241568,0,0,0,40,4886,304.9161,99.4721298217773,,,,,,,,,,,,,0,,,,0,,,,,,308.4867554,,,,
,20354726.765,305.4606934,99.4721298217773,0.000304790914105559,4.29268967810234E-6,1,0.999253354069792,40.0298881530762,1.9977876690544,23.9599999040365,0.0030465524803807,0.00290944505825727,0.25,0.000204440599494476,0.000304587374748363,0.000204595574316828,305.4606934,305.4606934,99.4721298217773,99.4721298217773,54.945358387852,19.5427873713437,8.861917,0,0,0,40,4886,301.6438,99.4721298217773,,,,,,,,,,,,,0,,,,0,,,,,,305.4606934,,,,
,20354850.885,302.47273255,99.4721298217773,0.000304103144361503,5.0059216659633E-6,1,0.999253354069792,40.0298881530762,1.99755734357435,23.9599999040365,0.00302927369279732,0.00296273654218181,0.25,0.000209270403067231,0.000303927130397732,0.000209448665917894,302.4490967,302.4963684,99.4721298217773,99.4721298217773,54.8281141099673,19.5468776356158,8.861917,0,0,0,40,4886,298.4362,99.4721298217773,,,,,,,,,,,,,0,,,,0.00245,,,,,,302.47273255,,,,
,20354973.42,299.4885254,99.4721298217773,0.000313925400919823,7.55270973083178E-6,1,0.999253354069792,40.0298881530762,1.99747485203892,23.8799992948771,0.00311542340173463,0.00312720522112888,0.25,0.000222089798817717,0.000313771165023955,0.000222299380912587,299.4659424,299.5111084,99.4721298217773,99.4721298217773,54.9101851044866,19.550085377316,9.241568,0,0,0,40,4886,295.3165,99.4721298217773,,,,,,,,,,,,,0,,,,0,,,,,,299.4885254,,,,
,20355095.54,296.4562683,99.4721298217773,0.000312913028644335,5.04936556967506E-6,1,0.999253354069792,40.0298881530762,1.99736544136118,23.8799992948771,0.00311376997185558,0.00306973328823939,0.25,0.000217166430013469,0.000312794144347954,0.000217401585484023,296.4562683,296.4562683,99.4721298217773,99.4721298217773,54.8804832207558,19.5537854377152,8.482265,0,0,0,40,4886,292.2311,99.4721298217773,,,,,,,,,,,,,0,,,,-0.0049,,,,,,296.4562683,,,,
,20355216.725,293.4646301,99.4721298217773,0.000315826285821567,5.51899776365548E-6,1,0.999253354069792,40.0298881530762,1.99728906726399,23.8899998366833,0.00312740293679671,0.0031882977366599,0.25,0.000227121412250681,0.000315732642628735,0.000227386554187337,293.4646301,293.4646301,99.4721298217773,99.4721298217773,54.7655838284289,19.5599383027319,8.861917,0,0,0,40,4886,289.1712,99.4721298217773,,,,,,,,,,,,,0,,,,-0.00245,,,,,,293.4646301,,,,
touchdown = 15.650000423193 mm,20355339.82,290.4395447,99.4721298217773,0.000319344309604939,6.67208590602127E-6,1,0.999253354069792,40.0298881530762,1.99691632887015,23.7700007855892,0.00314286388176012,0.00333397356379578,0.25,0.000239407880524002,0.000319275213820804,0.000239706772630513,290.4395447,290.4395447,99.4721298217773,99.4721298217773,55.1478001743328,19.5566962185039,9.241568,0,0,0,40,4886,286.0432,99.4721298217773,,,,,,,,,,,,,0,,,,-0.00245,,,,,,290.4395447,,,,
,20355460.515,287.4726868,99.4721298217773,0.000320048197668134,6.6208669547003E-6,1,0.999253354069792,40.0298881530762,1.99685914969629,23.7700007855892,0.00315163893349476,0.00333221164703201,0.25,0.000239104399818937,0.000320011341830499,0.000239431989340509,287.4726868,287.4726868,99.4721298217773,99.4721298217773,55.0860515213135,19.5637457959431,9.241568,0,0,0,40,4886,283.00805,99.4721298217773,,,,,,,,,,,,,0,,,,-0.0049,,,,,,287.4726868,,,,
,20355582.565,284.4923401,99.4721298217773,0.000322580722016839,7.2913073758882E-6,1,0.999253354069792,40.0298881530762,1.99646749140285,23.7700007855892,0.00316753895855781,0.00340883089935164,0.25,0.00024546039176229,0.000322572492224827,0.000245821667643789,284.4923401,284.4923401,99.4721298217773,99.4721298217773,54.8617241362943,19.5748913116267,8.482265,0,0,0,40,4886,279.93015,99.4721298217773,,,,,,,,,,,,,0,,,,0.0049,,,,,,284.4923401,,,,
,20355703.845,281.48202515,99.4721298217773,0.000322529560471871,4.94143183216734E-6,1,0.999253354069792,40.0298881530762,1.99616895749203,23.7700007855892,0.00317139405349963,0.00338223422655969,0.25,0.000243125678614931,0.000322555412454827,0.000243515002036782,281.4559021,281.5081482,99.4721298217773,99.4721298217773,54.8038836258712,19.5745282748199,8.861917,0,0,0,40,4886,276.87055,99.4721298217773,,,,,,,,,,,,,0,,,,0.0049,,,,,,281.48202515,,,,
,20355804.25,278.9914551,99.4721298217773,0.000331772729900162,6.34791207267312E-6,1,0.999253354069792,40.0298881530762,1.99564609161615,23.700000718236,0.00325366074206474,0.00352517092226829,0.25,0.000254208709422328,0.000331823832059214,0.000254637146294413,278.9914551,278.9914551,99.4721298217773,99.4721298217773,55.0837066357558,19.5721925812577,8.861917,0,0,0,40,4886,274.34605,99.4721298217773,,,,,,,,,,,,,0,,,,0,,,,,,278.9914551,,,,
,20355926.655,275.9767456,99.4721298217773,0.000335512151143896,7.64456889787491E-6,1,0.999253354069792,40.0298881530762,1.99503729320988,23.700000718236,0.00327664767679204,0.0036395404458641,0.25,0.000263729911482407,0.000335592425166467,0.000264199828121059,275.9767456,275.9767456,99.4721298217773,99.4721298217773,55.311160534852,19.5772825402766,9.241568,0,0,0,40,4886,271.2582,99.4721298217773,,,,,,,,,,,,,0,,,,0.00245,,,,,,275.9767456,,,,
,20356047.345,272.98373415,99.4721298217773,0.000335826424365685,6.45011038832333E-6,1,0.999253354069792,40.0298881530762,1.99494398878523,23.700000718236,0.00327770945867655,0.00365575565988618,0.25,0.000265086466986509,0.000335939181800959,0.000265589548145363,272.9555664,273.0119019,99.4721298217773,99.4721298217773,55.0962126920635,19.5905056935344,8.861917,0,0,0,40,4886,268.22655,99.4721298217773,,,,,,,,,,,,,0,,,,-0.00245,,,,,,272.98373415,,,,
,20356166.13,270.0999451,99.4721298217773,,,2,,,,23.6700004407763,,,,,,,270.0999451,270.0999451,99.4721298217773,99.4721298217773,,,8.482265,,,,-99999999,4886,265.2337,99.4721298217773,,,,,,,,,,,,,,,,,,,,,,,270.0999451,,,,
,20356268.835,267.48181155,99.4721298217773,0.000338340108638006,6.82770189576432E-6,1,0.999253354069792,40.0298881530762,1.99352252800659,23.64999987185,0.00328522183784082,0.00376994976621909,0.25,0.000274905563645775,0.000338508918426784,0.000275480314978577,267.4563904,267.5072327,99.4721298217773,99.4721298217773,54.7655838284289,19.5862765798211,8.861917,0,0,0,40,4886,262.67395,99.4721298217773,,,,,,,,,,,,,0,,,,-0.00245,,,,,,267.48181155,,,,
,20356390.205,264.4734955,99.4721298217773,0.000342752170908822,7.89982757917342E-6,1,0.999253354069792,40.0298881530762,1.99283211134151,23.64999987185,0.0033438652599465,0.00372262055578431,0.25,0.000270023317236107,0.000342963561240776,0.000270628713357733,264.4459839,264.5010071,99.4721298217773,99.4721298217773,55.1149717765251,19.5916280029439,8.861917,0,0,0,40,4886,259.6265,99.4721298217773,,,,,,,,,,,,,0,,,,-0.00245,,,,,,264.4734955,,,,
,20356489.57,261.98767085,99.4721298217773,0.00034220501346417,6.06298024447811E-6,1,0.999253354069792,40.0298881530762,1.99198027621618,23.64999987185,0.00332260848712923,0.0038009731212743,0.25,0.000277157322320103,0.000342437828342235,0.000277798797913537,261.9598083,262.0155334,99.4721298217773,99.4721298217773,55.4659229816597,19.5912187589856,9.241568,0,0,0,40,4886,257.144,99.4721298217773,,,,,,,,,,,,,0,,,,-0.0049,,,,,,261.98767085,,,,
,20356610.65,258.9611816,99.4721298217773,0.00035136655871627,7.06835448314952E-6,1,0.999253354069792,40.0298881530762,1.99218525782653,23.6099995672703,0.00341569181953072,0.00388354869372954,0.25,0.00028280490121183,0.000351641581794661,0.000283495636752025,258.9611816,258.9611816,99.4721298217773,99.4721298217773,54.9891295849289,19.5839676494623,9.241568,0,0,0,40,4886,254.1237,99.4721298217773,,,,,,,,,,,,,0,,,,-0.0049,,,,,,258.9611816,,,,
,20356730.345,255.9671173,99.4721298217773,0.000351240551474206,6.0891480421171E-6,1,0.999253354069792,40.0298881530762,1.99197473738057,23.6099995672703,0.00339746985941882,0.00398006646522673,0.25,0.00029136431268216,0.000351542341043201,0.000292102273891701,255.9671173,255.9671173,99.4721298217773,99.4721298217773,55.1712490299097,19.5876723445516,9.241568,0,0,0,40,4886,251.1162,99.4721298217773,,,,,,,,,,,,,0,,,,0,,,,,,255.9671173,,,,
,20356850.89,252.9846802,99.4721298217773,0.000350035384059345,5.65120293734485E-6,1,0.999253354069792,40.0298881530762,1.99086571172525,23.6099995672703,0.00338263224040948,0.00397450218483601,0.25,0.000291227266162946,0.000350368850340755,0.000291998965767403,252.9846802,252.9846802,99.4721298217773,99.4721298217773,55.6167772858713,19.599807662066,8.861917,0,0,0,40,4886,248.09955,99.4721298217773,,,,,,,,,,,,,0,,,,0,,,,,,252.9846802,,,,
,20356971.075,249.9863739,99.4721298217773,0.000353351820437479,6.53106353287345E-6,1,0.999253354069792,40.0298881530762,1.99099485456657,23.6099995672703,0.00341223901396928,0.00402996964205906,0.25,0.000295500152375496,0.000353720920084371,0.00029631727567061,249.9863739,249.9863739,99.4721298217773,99.4721298217773,55.1610878591597,19.5898705762878,8.861917,0,0,0,40,4886,245.0931,99.4721298217773,,,,,,,,,,,,,0,,,,0,,,,,,249.9863739,,,,
,20357091.395,246.9746094,99.4721298217773,0.000362056052490099,5.97792932227705E-6,1,0.999253354069792,40.0298881530762,1.97953266443991,23.5600005835295,0.00348307784850473,0.00407417095382955,0.25,0.000299856164359993,0.000362471272288017,0.000300724662783477,246.9470673,247.0021515,99.4721298217773,99.4721298217773,55.4698311242559,19.5852881211649,8.861917,0,0,0,40,4886,242.0812,99.4721298217773,,,,,,,,,,,,,0,,,,-0.00245,,,,,,246.9746094,,,,
,20357210.215,243.9691772,99.4721298217773,0.000370946122699741,5.67881832386857E-6,1,0.999253354069792,40.0298881530762,1.97939600969766,23.5699992626905,0.00358097082691096,0.00410362369622464,0.25,0.00030091740422372,0.000371412192137342,0.000301831998623044,243.9691772,243.9691772,99.4721298217773,99.4721298217773,55.3666561597174,19.5833937368952,8.861917,0,0,0,40,4886,239.121,99.4721298217773,,,,,,,,,,,,,0,,,,0,,,,,,243.9691772,,,,
,20357330.115,240.9866333,99.4721298217773,0.00037228949582359,7.75842407574951E-6,1,0.999253354069792,40.0298881530762,1.97932877024978,23.5600005835295,0.00357928446204154,0.00420446690730653,0.25,0.000309629500221747,0.000372785263230885,0.000310599618584392,240.9628754,241.0103912,99.4721298217773,99.4721298217773,55.2759872514866,19.5835129769963,9.241568,0,0,0,40,4886,236.12655,99.4721298217773,,,,,,,,,,,,,0,,,,-0.00245,,,,,,240.9866333,,,,
,20357429.995,238.4958801,99.4721298217773,0.000376001411685958,6.53849855028213E-6,1,0.999253354069792,40.0298881530762,1.99038535756341,23.5500000417233,0.00363062885653289,0.0042919012711066,0.25,0.000314703844944007,0.000376529326272617,0.000315719382024713,238.4677429,238.5240173,99.4721298217773,99.4721298217773,54.813263168102,19.579654824589,8.861917,0,0,0,40,4886,233.60395,99.4721298217773,,,,,,,,,,,,,0,,,,0.00245,,,,,,238.4958801,,,,
,20357549.645,235.4856186,99.4721298217773,0.00038174184601141,6.27176081454676E-6,1,0.999253354069792,40.0298881530762,1.9901845308931,23.5500000417233,0.00369018050943613,0.00433357054840999,0.25,0.000317389094337685,0.000382315148935138,0.000318454062858351,235.4579926,235.5132446,99.4721298217773,99.4721298217773,54.7687103425058,19.5857345851659,9.621219,0,0,0,40,4886,230.63305,99.4721298217773,,,,,,,,,,,,,0,,,,-0.00245,,,,,,235.4856186,,,,
,20357669.615,232.4901428,99.4721298217773,0.000392661900921618,6.58060806301503E-6,1,0.999253354069792,40.0298881530762,1.99051679867384,23.5500000417233,0.00380856473787309,0.00439023772818731,0.25,0.000320403823388108,0.000393293082495941,0.000321524419691092,232.4901428,232.4901428,99.4721298217773,99.4721298217773,55.7871723030636,19.5785167077212,8.861917,0,0,0,40,4886,227.6346,99.4721298217773,,,,,,,,,,,,,0,,,,0,,,,,,232.4901428,,,,
,20357790.51,229.45748905,99.4721298217773,0.000399523334765925,7.90992484002445E-6,1,0.999253354069792,40.0298881530762,1.99022358536937,23.5500000417233,0.00388811289927893,0.00439075191676938,0.25,0.000319267748589454,0.000400208582099733,0.000320431356039968,229.4337769,229.4812012,99.4721298217773,99.4721298217773,55.4393476120059,19.5812566853725,9.241568,0,0,0,40,4886,224.6084,99.4721298217773,,,,,,,,,,,,,0,,,,0.00245,,,,,,229.45748905,,,,
,20357890,226.9768143,99.4721298217773,0.000407463390582368,5.84028845816242E-6,1,0.999253354069792,40.0298881530762,1.99029691774611,23.5500000417233,0.00397288315574848,0.00443780466711316,0.25,0.000322002652983581,0.000408196098825275,0.000323213036469623,226.9509583,227.0026703,99.4721298217773,99.4721298217773,55.4526352968328,19.5825527794642,8.482265,0,0,0,40,4886,222.12295,99.4721298217773,,,,,,,,,,,,,0,,,,-0.00245,,,,,,226.9768143,,,,
,20358008.79,223.9877701,99.4721298217773,0.000415170428717978,5.04709217928188E-6,1,0.999253354069792,40.0298881530762,1.99014889335905,23.5500000417233,0.00406372279484246,0.00443183389416229,0.25,0.000320119085874992,0.000415961816211177,0.000321371133193889,223.9589844,224.0165558,99.4721298217773,99.4721298217773,55.4573250679482,19.5819906406597,8.861917,0,0,0,40,4886,219.16425,99.4721298217773,,,,,,,,,,,,,0,,,,-0.00245,,,,,,223.9877701,,,,
,20358129.03,220.9607849,99.4721298217773,0.000416951618780813,6.46956867902075E-6,1,0.999253354069792,40.0298881530762,1.99021217378633,23.5500000417233,0.00405820030214867,0.0045864499504966,0.25,0.000333432497875628,0.000417772042105133,0.000334762663931114,220.9607849,220.9607849,99.4721298217773,99.4721298217773,55.700411537429,19.5888719140968,8.861917,0,0,0,40,4886,216.1614,99.4721298217773,,,,,,,,,,,,,0,,,,-0.0049,,,,,,220.9607849,,,,
touchdown = 15.429999679327 mm,20358257.79,217.7312469,99.4721298217773,0.000433911871953173,5.43086308038519E-6,1,0.999253354069792,40.0298881530762,2.00367968998527,23.5500000417233,0.00428445145855015,0.00461128049801707,0.25,0.000330016817764273,0.000434823448723029,0.000331398149182113,217.7312469,217.7312469,99.4721298217773,99.4721298217773,54.8390569092366,19.5865036562194,8.861917,0,0,0,40,4886,212.9266,99.4721298217773,,,,,,,,,,,,,0,,,,0,,,,,,217.7312469,,,,
,20358367.48,214.99568175,99.4721298217773,0.000436217026554323,5.46655472819856E-6,1,0.999253354069792,40.0298881530762,2.00402227412995,23.5500000417233,0.00429848998168618,0.0046931470442918,0.25,0.000336702075887883,0.000437162966544987,0.000338142667316788,214.9698639,215.0214996,99.4721298217773,99.4721298217773,55.3658745311982,19.584648274254,8.861917,0,0,0,40,4886,210.20945,99.4721298217773,,,,,,,,,,,,,0,,,,0,,,,,,214.99568175,,,,
,20358488.165,211.99087525,99.4721298217773,0.000439998462925438,4.43505554564497E-6,1,0.999253354069792,40.0298881530762,2.00385656288591,23.539999499917,0.00437222505042906,0.00452397822670577,0.25,0.000321163518285688,0.000441009392533701,0.000322602195626156,211.967926,212.0138245,99.4721298217773,99.4721298217773,55.4713943812943,19.5975515966857,8.861917,0,0,0,40,4886,207.19135,99.4721298217773,,,,,,,,,,,,,0,,,,0,,,,,,211.99087525,,,,
,20358607.74,208.9983215,99.4721298217773,0.00044478797954016,4.02455983689288E-6,1,0.999253354069792,40.0298881530762,2.00370628847103,23.5500000417233,0.00445562912824943,0.00436740538906968,0.25,0.000306554600990833,0.000445866778455701,0.000307992284300764,208.9983215,208.9983215,99.4721298217773,99.4721298217773,55.2884933077943,19.5967530835421,9.241568,0,0,0,40,4886,204.20635,99.4721298217773,,,,,,,,,,,,,0,,,,0.00245,,,,,,208.9983215,,,,
,20358727.475,205.9752808,99.4721298217773,0.000448748610503772,1.4798017961924E-5,1,0.999253354069792,40.0298881530762,1.98950372161094,23.530000820756,0.00455059035501728,0.00388560197314019,0.25,0.000265811361910435,0.000449922162256884,0.000267159824216558,205.9752808,205.9752808,99.4721298217773,99.4721298217773,55.5495572332174,19.6022513997952,8.861917,0,0,0,40,4886,201.2269,99.4721298217773,,,,,,,,,,,,,0,,,,-0.00245,,,,,,205.9752808,,,,
,20358845.9,202.99323275,99.4721298217773,0.000455470904190499,1.50296119918825E-5,1,0.999253354069792,40.0298881530762,1.98982907719504,23.530000820756,0.0046506098182891,0.00376779520253914,0.25,0.000254129251217549,0.000456717854835992,0.000255480741897509,202.9662323,203.0202332,99.4721298217773,99.4721298217773,55.290838193352,19.6062116590843,8.482265,0,0,0,40,4886,198.28495,99.4721298217773,,,,,,,,,,,,,0,,,,0,,,,,,202.99323275,,,,
,20358966.77,199.9415131,99.4721298217773,0.000456373676117264,1.30214818686871E-5,1,0.999253354069792,40.0298881530762,1.99060551183235,23.530000820756,0.00470470393551726,0.00353097778255488,0.25,0.00023287115841548,0.000457686783005872,0.000234185094856279,199.9415131,199.9415131,99.4721298217773,99.4721298217773,55.4620148390636,19.5970329779343,8.861917,0,0,0,40,4886,195.2765,99.4721298217773,,,,,,,,,,,,,0,,,,0.00245,,,,,,199.9415131,,,,
touchdown = 15.4100004583597 mm,20359086.905,196.9575348,99.4721298217773,0.000447455555959986,1.35382238171903E-5,1,0.999253354069792,40.0298881530762,1.98013517180834,23.5200002789497,0.00462054769996124,0.00326890056236324,0.25,0.000212674348290591,0.000448798267535534,0.000213938899281658,196.9575348,196.9575348,99.4721298217773,99.4721298217773,55.240032339602,19.5900084879793,8.482265,0,0,0,40,4886,192.267,99.4721298217773,,,,,,,,,,,,,0,,,,0.0049,,,,,,196.9575348,,,,
,20359204.955,193.9981689,99.4721298217773,0.000463642216389411,1.03031787158603E-5,1,0.999253354069792,40.0298881530762,1.98117133078281,23.530000820756,0.00484484383069675,0.00307630026807674,0.25,0.000192578995002305,0.000465104136746026,0.000193819387670608,193.9981689,193.9981689,99.4721298217773,99.4721298217773,55.3830703586212,19.5858211467196,8.861917,0,0,0,40,4886,189.33205,99.4721298217773,,,,,,,,,,,,,0,,,,0,,,,,,193.9981689,,,,
,20359325.155,190.97000885,99.4721298217773,0.000494218160299714,1.37094473571593E-5,1,0.999253354069792,40.0298881530762,1.98065928359457,23.530000820756,0.00513814303806773,0.0034245841920859,0.25,0.000218225549181978,0.000495802834216912,0.000219627519184801,190.945694,190.9943237,99.4721298217773,99.4721298217773,55.6073977436405,19.5910274740033,9.241568,0,0,0,40,4886,186.3292,99.4721298217773,,,,,,,,,,,,,0,,,,0.00245,,,,,,190.97000885,,,,
,20359445.705,187.9767456,99.4721298217773,0.000483672584502977,1.60894576546949E-5,1,0.999253354069792,40.0298881530762,1.98026742971965,23.530000820756,0.00504646961642127,0.00324467388472759,0.25,0.00020409801457835,0.000485274172836993,0.000205465973332427,187.9767456,187.9767456,99.4721298217773,99.4721298217773,55.5519021187751,19.5950407116824,9.241568,0,0,0,40,4886,183.31465,99.4721298217773,,,,,,,,,,,,,0,,,,0.0049,,,,,,187.9767456,,,,
,20359543.635,185.4990997,99.4721298217773,0.000532439015947899,1.52905428120281E-5,1,0.999253354069792,40.0298881530762,1.99243996211403,23.539999499917,0.00559440386596694,0.0035576996290274,0.25,0.000221543980867554,0.000534241433459597,0.00022306618435443,185.4990997,185.4990997,99.4721298217773,99.4721298217773,55.3056891352174,19.5709034014962,8.861917,0,0,0,40,4886,180.87345,99.4721298217773,,,,,,,,,,,,,0,,,,-0.00245,,,,,,185.4990997,,,,
,20359665.14,182.4473572,99.4721298217773,0.000552865366290827,1.60733323371336E-5,1,0.999253354069792,40.0298881530762,1.99116437103715,23.539999499917,0.00583497881931911,0.00352522273717326,0.25,0.000215273000072555,0.000554800132945106,0.000216831370354517,182.4473572,182.4473572,99.4721298217773,99.4721298217773,55.3627480171212,19.5990833839012,8.861917,0,0,0,40,4886,177.8388,99.4721298217773,,,,,,,,,,,,,0,,,,0,,,,,,182.4473572,,,,
,20359783.415,179.49990845,99.4721298217773,0.000593885824569065,1.52950669233431E-5,1,0.999253354069792,40.0298881530762,1.99238121505783,23.539999499917,0.00628775338051688,0.00369897029775438,0.25,0.000223253760648763,0.000596020032420701,0.000224932493841183,179.4721832,179.5276337,99.4721298217773,99.4721298217773,55.6753994248136,19.5698867652979,9.241568,0,0,0,40,4886,174.88535,99.4721298217773,,,,,,,,,,,,,0,,,,0.00245,,,,,,179.49990845,,,,
,20359905.14,176.5103455,99.4721298217773,,,2,,,,23.5600000688434,,,,,,,176.5103455,176.5103455,99.4721298217773,99.4721298217773,,,9.241568,,,,-99999999,4886,171.7901,99.4721298217773,,,,,,,,,,,,,,,,,,,,,,,176.5103455,,,,
,20360002.26,173.9685822,99.4721298217773,0.000643639206946822,1.64539122299602E-5,1,0.999253354069792,40.0298881530762,2.00543623956207,23.539999499917,0.00687387916655151,0.00394367118916117,0.25,0.000233950191198797,0.000646053464762126,0.000235811199266223,173.9685822,173.9685822,99.4721298217773,99.4721298217773,55.3791622160251,19.5826261987124,8.861917,0,0,0,40,4886,169.4457,99.4721298217773,,,,,,,,,,,,,0,,,,-0.0049,,,,,,173.9685822,,,,
,20360119.22,170.994812,99.4721298217773,0.000652773269383504,1.4545872536364E-5,1,0.999253354069792,40.0298881530762,2.00576269008498,23.539999499917,0.00697061425516899,0.00401439027789472,0.25,0.000238460307344128,0.000655268169426456,0.000240394048182586,170.994812,170.994812,99.4721298217773,99.4721298217773,55.2353425684866,19.5777800200505,8.482265,0,0,0,40,4886,166.5745,99.4721298217773,,,,,,,,,,,,,0,,,,0,,,,,,170.994812,,,,
,20360241.18,167.9708099,99.4721298217773,0.000709149733313274,1.29412062384481E-5,1,0.999253354069792,40.0298881530762,2.0056575050568,23.539999499917,0.00758724546776836,0.0042781283102461,0.25,0.000251742664605681,0.000711921352904807,0.000253858728478786,167.9708099,167.9708099,99.4721298217773,99.4721298217773,55.6011447154867,19.590628586397,8.861917,0,0,0,40,4886,163.5127,99.4721298217773,,,,,,,,,,,,,0,,,,0,,,,,,167.9708099,,,,
,20360363.285,164.987915,99.4721298217773,0.000901160999462763,3.15535943845612E-7,1,0.999253354069792,40.0298881530762,2.00534005528805,23.5500000417233,0.0102706358482165,0.00181768383152839,0.25,2.54237472891014E-6,0.000905206801968567,3.86658540376579E-6,164.987915,164.987915,99.4721298217773,99.4721298217773,56.0380750577367,19.5834068069524,8.482265,0,0,0,40,4886,160.387,99.4721298217773,,,,,,,,,,,,,0,,,,0,,,,,,164.987915,,,,
,20360481.885,161.9796219,99.4721298217773,0.000902488767936499,3.68107980476593E-7,1,0.999253354069792,40.0298881530762,2.00472612203258,23.539999499917,0.0102831455347288,0.00182258855821283,0.25,2.74069557752539E-6,0.000906613823797985,4.10261737087949E-6,161.9539032,162.0053406,99.4721298217773,99.4721298217773,56.1514111930252,19.5897269568493,8.861917,0,0,0,40,4886,157.47365,99.4721298217773,,,,,,,,,,,,,0,,,,0.00245,,,,,,161.9796219,,,,
,20360601.68,158.9828949,99.4721298217773,0.000903659158025658,2.58309414900249E-7,1,0.999253354069792,40.0298881530762,2.00400123343485,23.539999499917,0.0102939266993163,0.00182340735364114,0.25,2.61383875027383E-6,0.000907861374704866,4.01487946679479E-6,158.9828949,158.9828949,99.4721298217773,99.4721298217773,56.2280107879098,19.5944346668918,9.241568,0,0,0,40,4886,154.4791,99.4721298217773,,,,,,,,,,,,,0,,,,-0.0049,,,,,,158.9828949,,,,
,20360733.61,155.667923,99.4721298217773,,,2,,,,23.5800002211332,,,,,,,155.667923,155.667923,99.4721298217773,99.4721298217773,,,8.861917,,,,-99999999,4886,151.195,99.4721298217773,,,,,,,,,,,,,,,,,,,,,,,155.667923,,,,
,20360841.17,152.9317169,99.4721298217773,0.000905763440366366,2.96767066463528E-7,1,0.999253354069792,40.0298881530762,1.97961654045798,23.5600005835295,0.0101987891846224,0.00181116668231149,0.25,2.93536324309915E-6,0.000910114994766819,4.42381828283266E-6,152.9317169,152.9317169,99.4721298217773,99.4721298217773,55.6613301114674,19.5921717873255,8.861917,0,0,0,40,4886,148.5234,99.4721298217773,,,,,,,,,,,,,0,,,,-0.00245,,,,,,152.9317169,,,,
,20360959.32,149.9664383,99.4721298217773,0.000906823280595292,3.66614806111862E-7,1,0.999253354069792,40.0298881530762,1.97969899788439,23.5600005835295,0.0102116505287017,0.00181473890206587,0.25,3.00547163755969E-6,0.000911245690339891,4.54075545861422E-6,149.9405365,149.9923401,99.4721298217773,99.4721298217773,55.8520474701598,19.5904910790943,8.861917,0,0,0,40,4886,145.579,99.4721298217773,,,,,,,,,,,,,0,,,,-0.00245,,,,,,149.9664383,,,,
,20361079.05,146.9656525,99.4721298217773,0.000908997555319331,2.81161626884802E-7,1,0.999253354069792,40.0298881530762,1.97928590126227,23.5500000417233,0.0102347359356646,0.00181934496992624,0.25,3.00842832081679E-6,0.000913495402247617,4.59553034624549E-6,146.9656525,146.9656525,99.4721298217773,99.4721298217773,55.8028048734482,19.5911115714709,9.241568,0,0,0,40,4886,142.6089,99.4721298217773,,,,,,,,,,,,,0,,,,-0.0049,,,,,,146.9656525,,,,
,20361197.78,143.9813232,99.4721298217773,0.000908299647588417,3.14348977587089E-7,1,0.999253354069792,40.0298881530762,1.97900950133152,23.5699992626905,0.0102265496045746,0.00181588960456573,0.25,2.78336826105328E-6,0.000912856656950847,4.41923580572134E-6,143.9813232,143.9813232,99.4721298217773,99.4721298217773,56.7688977232175,19.593402830122,8.861917,0,0,0,40,4886,139.6492,99.4721298217773,,,,,,,,,,,,,0,,,,0,,,,,,143.9813232,,,,
,20361318.4,140.9232025,99.4721298217773,0.000910280879898729,3.72048612095061E-7,1,0.999253354069792,40.0298881530762,1.97962575245166,23.5799998044968,0.0102521919935348,0.00182284095697091,0.25,2.94111085955921E-6,0.000914909196319512,4.63663769084537E-6,140.9232025,140.9232025,99.4721298217773,99.4721298217773,55.5675346891597,19.594752202785,8.482265,0,0,0,40,4886,136.65455,99.4721298217773,,,,,,,,,,,,,0,,,,-0.0049,,,,,,140.9232025,,,,
,20361435.79,137.98040005,99.4721298217773,0.00091193413019901,3.83578181088587E-7,1,0.999253354069792,40.0298881530762,1.97962962359396,23.5799998044968,0.0102712847492333,0.00182732146868994,0.25,2.9829678932521E-6,0.000916627552388717,4.73927768095935E-6,137.9533386,138.0074615,99.4721298217773,99.4721298217773,56.0544892566406,19.5881935080579,8.102614,0,0,0,40,4886,133.74725,99.4721298217773,,,,,,,,,,,,,0,,,,-0.0049,,,,,,137.98040005,,,,
,20361561.09,134.8477631,99.4721298217773,,,2,,,,23.6199995943904,,,,,,,134.8477631,134.8477631,99.4721298217773,99.4721298217773,,,8.482265,,,,-99999999,4886,130.622,99.4721298217773,,,,,,,,,,,,,,,,,,,,,,,134.8477631,,,,
,20361673.375,131.98336795,99.4721298217773,0.000913691025903734,3.44482362815875E-7,1,0.999253354069792,40.0298881530762,1.99030209111828,23.6000008881092,0.0103443301644788,0.00184587848441216,0.25,3.33611107510654E-6,0.000918500058264414,5.22762554202575E-6,131.956543,132.0101929,99.4721298217773,99.4721298217773,55.6621117399866,19.5836471636056,8.102614,0,0,0,40,4886,127.8344,99.4721298217773,,,,,,,,,,,,,0,,,,-0.0049,,,,,,131.98336795,,,,
,20361792.98,128.9655914,99.4721298217773,0.000915384266806577,3.44433700039256E-7,1,0.999253354069792,40.0298881530762,1.98991949827929,23.590000346303,0.0103617009309429,0.00185164189918849,0.25,3.49823441033777E-6,0.00092025096550651,5.46685963409821E-6,128.9655914,128.9655914,99.4721298217773,99.4721298217773,56.137341879679,19.6086309883116,8.482265,0,0,0,40,4886,124.8648,99.4721298217773,,,,,,,,,,,,,0,,,,0.0049,,,,,,128.9655914,,,,
,20361912.105,125.98284915,99.4721298217773,0.000917434810325111,3.58030270405879E-7,1,0.999253354069792,40.0298881530762,1.99043059620983,23.6000008881092,0.0103880217043687,0.00185600331692468,0.25,3.39928523395928E-6,0.000922357293769374,5.44993440415417E-6,125.9573441,126.0083542,99.4721298217773,99.4721298217773,55.8778412112944,19.6039653120071,8.102614,0,0,0,40,4886,121.90815,99.4721298217773,,,,,,,,,,,,,0,,,,-0.00245,,,,,,125.98284915,,,,
,20362011.52,123.4847679,99.4721298217773,0.000917110384455077,4.59975642167547E-7,1,0.999253354069792,40.0298881530762,1.99008632850228,23.6099995672703,0.0103827662775395,0.0018565641176882,0.25,3.45720025737687E-6,0.000922065237163419,5.57728088117403E-6,123.4574585,123.5120773,99.4721298217773,99.4721298217773,55.9294286935636,19.6108328765051,8.102614,0,0,0,40,4886,119.4425,99.4721298217773,,,,,,,,,,,,,0,,,,0.00245,,,,,,123.4847679,,,,
,20362130.275,120.47322845,99.4721298217773,0.000919093563744821,3.02774276105602E-7,1,0.999253354069792,40.0298881530762,1.98983667967438,23.6200001090765,0.010403679685161,0.00186451794012096,0.25,3.73661133948155E-6,0.000924095847100701,5.95228077902179E-6,120.4462814,120.5001755,99.4721298217773,99.4721298217773,55.6941585092751,19.6071739910532,8.482265,0,0,0,40,4886,116.50375,99.4721298217773,,,,,,,,,,,,,0,,,,0,,,,,,120.47322845,,,,
,20362248.625,117.4570541,99.4721298217773,0.0009209511636061,3.39139626728798E-7,1,0.999253354069792,40.0298881530762,1.99036610580458,23.6099995672703,0.0104278674080363,0.0018680009841007,0.25,3.57543099547255E-6,0.000925996378447556,5.891231355217E-6,117.4570541,117.4570541,99.4721298217773,99.4721298217773,55.9513142921021,19.5896553170467,8.482265,0,0,0,40,4886,113.5781,99.4721298217773,,,,,,,,,,,,,0,,,,0.0049,,,,,,117.4570541,,,,
,20362365.66,114.4967918,99.4721298217773,0.000922692397053222,3.52890007944439E-7,1,0.999253354069792,40.0298881530762,1.99133522280521,23.6200001090765,0.0104528169386994,0.00187198424922265,0.25,3.43790599868757E-6,0.000927773357931459,5.86073230372026E-6,114.4704971,114.5230865,99.4721298217773,99.4721298217773,55.964601976929,19.5884787064899,8.861917,0,0,0,40,4886,110.6887,99.4721298217773,,,,,,,,,,,,,0,,,,0.00245,,,,,,114.4967918,,,,
,20362464.345,111.9913712,99.4721298217773,0.000920560159777815,3.43435293901118E-7,1,0.999253354069792,40.0298881530762,1.97918137398697,23.6600004136562,0.0103665814992233,0.0018651677391314,0.25,4.07906046872788E-6,0.000925644461277,6.59361310287866E-6,111.9913712,111.9913712,99.4721298217773,99.4721298217773,55.7879539315828,19.6080652053363,8.482265,0,0,0,40,4886,108.25195,99.4721298217773,,,,,,,,,,,,,0,,,,-0.0049,,,,,,111.9913712,,,,
,20362582.39,108.9743805,99.4721298217773,0.000922710429172384,3.33757485872871E-7,1,0.999253354069792,40.0298881530762,1.98003633508814,23.6600004136562,0.010395456276044,0.00186911772493502,0.25,3.86192667328245E-6,0.000927821142876443,6.50145828107375E-6,108.9743805,108.9743805,99.4721298217773,99.4721298217773,55.7559071622943,19.607366566554,8.482265,0,0,0,40,4886,105.3586,99.4721298217773,,,,,,,,,,,,,0,,,,-0.0049,,,,,,108.9743805,,,,
,20362699.935,105.984169,99.4721298217773,0.000924548634079165,2.72473749838764E-7,1,0.999253354069792,40.0298881530762,1.98001878428925,23.6600004136562,0.0104160819455035,0.00187313981090212,0.25,3.76630122227365E-6,0.000929674595069895,6.54155715782493E-6,105.984169,105.984169,99.4721298217773,99.4721298217773,55.3447705611789,19.6081407124245,8.482265,0,0,0,40,4886,102.4673,99.4721298217773,,,,,,,,,,,,,0,,,,0,,,,,,105.984169,,,,
,20362818.78,102.9494858,99.4721298217773,0.000922783103903042,3.91935996239645E-7,1,0.999253354069792,40.0298881530762,1.98953492562486,23.700000718236,0.0104421780195892,0.00188767533323664,0.25,4.45744032901143E-6,0.000927891524403677,7.3761359343686E-6,102.9494858,102.9494858,99.4721298217773,99.4721298217773,55.2447221107174,19.6269347404432,8.861917,0,0,0,40,4886,99.52825,99.4721298217773,,,,,,,,,,,,,0,,,,0.0049,,,,,,102.9494858,,,,
,20362938.715,99.9339218,99.4721298217773,0.000924947324147677,3.30354797295645E-7,1,0.999253354069792,40.0298881530762,1.99009203180477,23.700000718236,0.0104685371906526,0.00189665737417346,0.25,4.6690159633171E-6,0.000930047833804101,7.75606618635971E-6,99.9339218,99.9339218,99.4721298217773,99.4721298217773,55.6863422240828,19.6422130218365,8.102614,0,0,0,40,4886,96.55325,99.4721298217773,,,,,,,,,,,,,0,,,,0,,,,,,99.9339218,,,,
,20363054.915,96.9965897,99.4721298217773,0.000926923059627618,2.86833828934579E-7,1,0.999253354069792,40.0298881530762,1.98898128724953,23.6900001764297,0.0104849037921882,0.00189984439898799,0.25,4.52742076042393E-6,0.000932001903615105,7.79145022872786E-6,96.9965897,96.9965897,99.4721298217773,99.4721298217773,56.0208792303136,19.6541476845213,8.482265,0,0,0,40,4886,93.6531,99.4721298217773,,,,,,,,,,,,,0,,,,0,,,,,,96.9965897,,,,
,20363175.51,93.9911194,99.4721298217773,0.000928769645362535,2.80632013076157E-7,1,0.999253354069792,40.0298881530762,1.98918045410924,23.6900001764297,0.0105057662153903,0.00190629373639474,0.25,4.57282641323313E-6,0.00093380677377413,8.03624728079263E-6,93.9911194,93.9911194,99.4721298217773,99.4721298217773,55.5440858335828,19.6494244722199,8.102614,0,0,0,40,4886,90.6746,99.4721298217773,,,,,,,,,,,,,0,,,,0,,,,,,93.9911194,,,,
,20363294.44,90.9353638,99.4721298217773,0.000928873593163288,3.05730895769193E-7,1,0.999253354069792,40.0298881530762,1.97607356737181,23.7199999392033,0.0104395803277497,0.00189689201934332,0.25,4.59178893188127E-6,0.000933841871829902,8.26239866015929E-6,90.9353638,90.9353638,99.4721298217773,99.4721298217773,55.2978728500251,19.6681956966292,8.482265,0,0,0,40,4886,87.75435,99.4721298217773,,,,,,,,,,,,,0,,,,-0.00245,,,,,,90.9353638,,,,
,20363409.345,87.9852066,99.4721298217773,0.000931129378445954,3.17452003413816E-7,1,0.999253354069792,40.0298881530762,1.97824247818326,23.709999397397,0.0104747641419194,0.00190421742859776,0.25,4.46760919069459E-6,0.000936021252386476,8.36234603958275E-6,87.9852066,87.9852066,99.4721298217773,99.4721298217773,55.7183889933713,19.6519878838472,8.482265,0,0,0,40,4886,84.9619,99.4721298217773,,,,,,,,,,,,,0,,,,0,,,,,,87.9852066,,,,
,20363524.875,84.9793472,99.4721298217773,0.00093277488696324,3.24534576903729E-7,1,0.999253354069792,40.0298881530762,1.97775650968777,23.709999397397,0.01048866190475,0.0019117027541672,0.25,4.66524389191923E-6,0.000937557398325615,8.80514911087991E-6,84.9793472,84.9793472,99.4721298217773,99.4721298217773,55.4096457282751,19.6472518383616,8.861917,0,0,0,40,4886,82.1408,99.4721298217773,,,,,,,,,,,,,0,,,,0,,,,,,84.9793472,,,,
,20363642.715,81.9845047,99.4721298217773,0.000932008654562203,2.99218642621755E-7,1,0.999253354069792,40.0298881530762,1.98876570000268,23.7499997019768,0.0105331122687105,0.00192525515748165,0.25,4.8670190104061E-6,0.000936632147793941,9.26556835059114E-6,81.9845047,81.9845047,99.4721298217773,99.4721298217773,55.636317998852,19.6464357496628,8.482265,0,0,0,40,4886,79.27245,99.4721298217773,,,,,,,,,,,,,0,,,,0,,,,,,81.9845047,,,,
,20363760.585,78.9602203,99.4721298217773,0.000933873992928559,4.21883840269196E-7,1,0.999253354069792,40.0298881530762,1.98885700882694,23.7399991601706,0.0105514861950471,0.00193421122145076,0.25,5.07138800386139E-6,0.000938308141822343,9.7638403221465E-6,78.9308929,78.9895477,99.4721298217773,99.4721298217773,55.1478001743328,19.6699190705568,8.102614,0,0,0,40,4886,76.37835,99.4721298217773,,,,,,,,,,,,,0,,,,0,,,,,,78.9602203,,,,
,20363877.555,75.9719086,99.4721298217773,0.000936267495713829,3.46802408974477E-7,1,0.999253354069792,40.0298881530762,1.98971847738534,23.7499997019768,0.0105797922943896,0.00194147520005907,0.25,4.95957580272151E-6,0.000940467188407302,9.96478813252607E-6,75.9719086,75.9719086,99.4721298217773,99.4721298217773,55.4823371805636,19.6644401996555,8.861917,0,0,0,40,4886,73.5079,99.4721298217773,,,,,,,,,,,,,0,,,,0.00245,,,,,,75.9719086,,,,
,20363995.61,72.9783707,99.4721298217773,0.000937987223071636,3.05419029281021E-7,1,0.999253354069792,40.0298881530762,1.98895211459042,23.7499997019768,0.0105918099580061,0.00194399811281276,0.25,4.67333443203121E-6,0.000941886616969335,1.00071515074704E-5,72.9783707,72.9783707,99.4721298217773,99.4721298217773,55.2611363096212,19.6641259719427,8.482265,0,0,0,40,4886,70.60695,99.4721298217773,,,,,,,,,,,,,0,,,,-0.00245,,,,,,72.9783707,,,,
,20364113.43,69.9754028,99.4721298217773,0.000935115369908823,2.8647718152039E-7,1,0.999253354069792,40.0298881530762,1.97646627940687,23.8000005483627,0.0104898231475825,0.00193673792552117,0.25,5.3131947532704E-6,0.000938617673374439,1.09642108924171E-5,69.9491348,70.0016708,99.4721298217773,99.4721298217773,55.8606453838713,19.7093281746143,8.482265,0,0,0,40,4886,67.68805,99.4721298217773,,,,,,,,,,,,,0,,,,0.00245,,,,,,69.9754028,,,,
,20364230.535,66.9914551,99.4721298217773,0.000937299364676336,2.71596599404764E-7,1,0.999253354069792,40.0298881530762,1.97640751985598,23.7900000065565,0.0105082065272494,0.00194424966151133,0.25,5.3487924171897E-6,0.000940350938368435,1.13408099477181E-5,66.9914551,66.9914551,99.4721298217773,99.4721298217773,55.2634811951789,19.7035988294189,8.482265,0,0,0,40,4886,64.7936,99.4721298217773,,,,,,,,,,,,,0,,,,0,,,,,,66.9914551,,,,
,20364350.315,63.9447556,99.4721298217773,0.000939338140611043,2.84886489361466E-7,1,0.999253354069792,40.0298881530762,1.97561806214702,23.8000005483627,0.0105198928869205,0.00195204419106406,0.25,5.52428941058922E-6,0.00094184060220465,1.18463684559087E-5,63.9447556,63.9447556,99.4721298217773,99.4721298217773,55.7324583067174,19.7148373826414,8.482265,0,0,0,40,4886,61.86,99.4721298217773,,,,,,,,,,,,,0,,,,0,,,,,,63.9447556,,,,
,20364465.585,60.9944115,99.4721298217773,0.000937482111603046,3.6205998640911E-7,1,0.999253354069792,40.0298881530762,2.00038575441831,23.8300003111362,0.0106165276862139,0.00197735028708466,0.25,5.86669737402186E-6,0.000939359367906892,1.24459944115216E-5,60.9944115,60.9944115,99.4721298217773,99.4721298217773,55.2642628236982,19.7243886074892,8.102614,0,0,0,40,4886,59.0455,99.4721298217773,,,,,,,,,,,,,0,,,,0,,,,,,60.9944115,,,,
,20364583.41,57.97601315,99.4721298217773,0.000939577519080494,3.45807173527024E-7,1,0.999253354069792,40.0298881530762,1.99681335113827,23.81999976933,0.0106143695762352,0.00197487626671733,0.25,5.47397330387042E-6,0.000940741088550609,1.22867762049118E-5,57.9472389,58.0047874,99.4721298217773,99.4721298217773,55.1001208346597,19.7648969765611,8.102614,0,0,0,40,4886,56.1549,99.4721298217773,,,,,,,,,,,,,0,,,,0.00245,,,,,,57.97601315,,,,
,20364700.71,54.9968491,99.4721298217773,0.000941362319989755,3.46593014483823E-7,1,0.999253354069792,40.0298881530762,1.9975932273462,23.81999976933,0.0106289655752511,0.00198132449672456,0.25,5.65576783316554E-6,0.000941739002240512,1.26194881956579E-5,54.9968491,54.9968491,99.4721298217773,99.4721298217773,55.473739266852,19.7490230850205,7.722963,0,0,0,40,4886,53.2861,99.4721298217773,,,,,,,,,,,,,0,,,,-0.00245,,,,,,54.9968491,,,,
,20364816.785,51.9997787,99.4721298217773,0.00094268030806267,3.10483140456468E-7,1,0.999253354069792,40.0298881530762,1.99970941218729,23.8300003111362,0.0106455112811852,0.00198309328459791,0.25,5.50133458978906E-6,0.000942232950832651,1.251356296332E-5,51.9997787,51.9997787,99.4721298217773,99.4721298217773,55.4065192141982,19.7374328434285,8.482265,0,0,0,40,4886,50.44605,99.4721298217773,,,,,,,,,,,,,0,,,,0,,,,,,51.9997787,,,,
,20364914.275,49.4975243,99.4721298217773,0.000941361254591225,3.29140074153954E-7,1,0.999253354069792,40.0298881530762,1.97557849995369,23.8499995321035,0.0104997166278032,0.00195889073381603,0.25,5.79032305567632E-6,0.000940210780868445,1.27426244006334E-5,49.4975243,49.4975243,99.4721298217773,99.4721298217773,55.3494603322943,19.7318697366942,7.722963,0,0,0,40,4886,48.0668,99.4721298217773,,,,,,,,,,,,,0,,,,-0.0049,,,,,,49.4975243,,,,
,20365031.685,46.4521255,99.4721298217773,0.000942559973699805,3.15972417264633E-7,1,0.999253354069792,40.0298881530762,1.9761598691996,23.8499995321035,0.0105082817464321,0.00195275030206462,0.25,5.27149000920612E-6,0.000940597328667752,1.20782921713107E-5,46.4521255,46.4521255,99.4721298217773,99.4721298217773,55.2126753414289,19.7236631609868,7.343312,0,0,0,40,4886,45.2387,99.4721298217773,,,,,,,,,,,,,0,,,,0,,,,,,46.4521255,,,,
,20365144.695,43.4760284,99.4721298217773,0.000943953703575316,3.57402967854726E-7,1,0.999253354069792,40.0298881530762,1.97627503994481,23.8600000739098,0.0105170469528252,0.00194981527846861,0.25,5.10758284857076E-6,0.000941261162061753,1.16918980456276E-5,43.4760284,43.4760284,99.4721298217773,99.4721298217773,55.0602577801789,19.7046622841068,7.343312,0,0,0,40,4886,42.53485,99.4721298217773,,,,,,,,,,,,,0,,,,-0.00245,,,,,,43.4760284,,,,
touchdown = 15.760000795126 mm,20365256.04,40.6116982,99.4721298217773,0.000943064514866824,3.97670995958315E-7,1,0.999253354069792,40.0298881530762,1.97834886101176,23.8799992948771,0.0105110344650988,0.00194504524198972,0.25,5.06941654152017E-6,0.000939725943596826,1.13568188441243E-5,40.6116982,40.6116982,99.4721298217773,99.4721298217773,55.3471154467366,19.6799578272912,7.722963,0,0,0,40,4882,39.8484,99.4721298217773,,,,,,,,,,,,,0,,,,-0.0049,,,,,,40.6116982,,,,
,20365357.65,37.9945679,99.4721298217773,0.00094440763259443,2.69524936783882E-7,1,0.999253354069792,40.0298881530762,1.97759670296836,23.8799992948771,0.0105172750318687,0.00194082811816815,0.25,4.90349024078872E-6,0.000940545285264022,1.09021149193759E-5,37.9945679,37.9945679,99.4721298217773,99.4721298217773,54.5396931863712,19.6782039435643,6.963661,0,0,0,40,4882,37.3665,99.4721298217773,,,,,,,,,,,,,0,,,,0,,,,,,37.9945679,,,,
,20365476.605,34.9586906,99.4721298217773,0.00094551465324191,2.85031068013196E-7,1,0.999253354069792,40.0298881530762,1.97735461935129,23.8799992948771,0.0105239726886427,0.00193459541644916,0.25,4.61296833020186E-6,0.000941142641139804,1.02629600628726E-5,34.9586906,34.9586906,99.4721298217773,99.4721298217773,55.3252298481982,19.6873196604743,6.963661,0,0,0,40,4882,34.4484,99.4721298217773,,,,,,,,,,,,,0,,,,0.0049,,,,,,34.9586906,,,,
,20365594.775,31.9560127,99.4721298217773,0.000946984976458121,3.25487049562913E-7,1,0.999253354069792,40.0298881530762,1.97663347763905,23.8799992948771,0.0105331715422512,0.00193070606349272,0.25,4.46699495395083E-6,0.00094221021904646,9.79164615780548E-6,31.9560127,31.9560127,99.4721298217773,99.4721298217773,55.4495087827559,19.695977247717,7.343312,0,0,0,40,4882,31.5245,99.4721298217773,,,,,,,,,,,,,0,,,,-0.0049,,,,,,31.9560127,,,,
,20365691.935,29.4880104,99.4721298217773,0.000946697311071344,2.71538152415544E-7,1,0.999253354069792,40.0298881530762,1.98696186597842,23.8899998366833,0.0105798147956653,0.00193870834176092,0.25,4.65812504908487E-6,0.000941673899090516,9.73893529775327E-6,29.4880104,29.4880104,99.4721298217773,99.4721298217773,55.0485333523904,19.7013701230714,6.58401,0,0,0,40,4882,29.1178,99.4721298217773,,,,,,,,,,,,,0,,,,-0.0049,,,,,,29.4880104,,,,
,20365813.63,26.4666805,99.4721298217773,0.000948481362120695,3.5774766720418E-7,1,0.999253354069792,40.0298881530762,1.98556961969779,23.9000003784895,0.0105917638746869,0.00193121576916261,0.25,4.07297079210165E-6,0.00094322453004146,8.92054257973628E-6,26.4666805,26.4666805,99.4721298217773,99.4721298217773,54.9852214423327,19.7261674573521,7.343312,0,0,0,40,4882,26.0864,99.4721298217773,,,,,,,,,,,,,0,,,,0,,,,,,26.4666805,,,,
,20365932.37,23.47023865,99.4721298217773,0.000949604949487604,2.91584725268926E-7,1,0.999253354069792,40.0298881530762,1.98678267891394,23.9000003784895,0.0106091219984035,0.00193315927141479,0.25,4.141315090533E-6,0.000944201171535182,8.8245587827258E-6,23.439455,23.5010223,99.4721298217773,99.4721298217773,54.860942507775,19.7119919067549,6.58401,0,0,0,40,4882,23.1329,99.4721298217773,,,,,,,,,,,,,0,,,,-0.00245,,,,,,23.47023865,,,,
,20366050.945,20.4932604,99.4721298217773,0.000950742740041674,3.67858351406976E-7,1,0.999253354069792,40.0298881530762,1.9861002404176,23.9000003784895,0.0106172517024359,0.0019362085221995,0.25,4.38092477207882E-6,0.000945258162207055,8.969549352872E-6,20.4635239,20.5229969,99.4721298217773,99.4721298217773,55.3682194167559,19.725769670356,6.58401,0,0,0,40,4882,20.18285,99.4721298217773,,,,,,,,,,,,,0,,,,-0.0049,,,,,,20.4932604,,,,
,20366150.95,17.955019,99.4721298217773,0.000950177784058768,3.01955998832683E-7,1,0.999253354069792,40.0298881530762,2.00068310180677,23.9199995994568,0.0106839072024852,0.00195539614530755,0.25,5.01410675732885E-6,0.000944676722570381,9.56578346434488E-6,17.955019,17.955019,99.4721298217773,99.4721298217773,54.9484849019289,19.7000159149087,6.963661,0,0,0,40,4882,17.7048,99.4721298217773,,,,,,,,,,,,,0,,,,-0.0049,,,,,,17.955019,,,,
,20366271.89,14.9470634,99.4721298217773,0.000951030704554723,2.8432967952866E-7,1,0.999253354069792,40.0298881530762,2.00009936358041,23.9199995994568,0.0106915385069258,0.00195157296399439,0.25,4.56741454614192E-6,0.00094553751578498,9.12774431247503E-6,14.9470634,14.9470634,99.4721298217773,99.4721298217773,55.3963580434482,19.7159535478051,6.58401,0,0,0,40,4882,14.6757,99.4721298217773,,,,,,,,,,,,,0,,,,0.00245,,,,,,14.9470634,,,,
,20366390.97,11.9891272,99.4721298217773,0.000952924659474118,3.17311764075334E-7,1,0.999253354069792,40.0298881530762,2.00006357031438,23.9199995994568,0.0107129450457307,0.00195419965675408,0.25,4.46625657287824E-6,0.00094742789421381,9.0363675595586E-6,11.9891272,11.9891272,99.4721298217773,99.4721298217773,55.6511689407174,19.7217970513311,6.963661,0,0,0,40,4886,11.6878,99.4721298217773,,,,,,,,,,,,,0,,,,0,,,,,,11.9891272,,,,
,20366658.265,10.0397511,99.4721298217773,0.000954568453676909,3.40809460923794E-7,1,0.999253354069792,40.0298881530762,2.00036037608323,23.9199995994568,0.0107327733388243,0.00195903260884919,0.25,4.57862694304344E-6,0.000949065065794936,9.15605244134837E-6,10.0397511,10.0397511,99.4721298217773,99.4721298217773,55.1032473487366,19.7205903178761,6.963661,0,0,0,40,4881,9.858,99.4721298217773,,,,,,,,,,,,,0,,,,-0.0049,,,,,,10.0397511,,,,