File: defense/images/np_vsm/data_dispersion/AH11_HYST_100OE_50K.DAT
[Header]
; VSM Data File (default extension .dat)
; Copyright (c) 2003-2013, Quantum Design, Inc. All rights reserved.
TITLE,
FILEOPENTIME,20385974.72,08/25/2018,7:45 am
BYAPP,VSM,2.0,2.0
INFO,PPMS VSM Option Release 1.4.10 Build 1,APPNAME
INFO,Quantum Design Linear Motor Servo Controller,MOTOR_MODULE_NAME
INFO,3101-100 M1,MOTOR_HW_VERSION
INFO,MMC1014,MOTOR_SERIAL_NUMBER
INFO,SRV No X-over 01.03.11,MOTOR_SOFTWARE_VERSION
INFO,Quantum Design VSM Detection Module,VSM_MODULE_NAME
INFO,3101-150 F0,VSM_HW_VERSION
INFO,VSM707,VSM_SERIAL_NUMBER
INFO,VSM No X-over 01.02.05 May 20 2008 13:51:47,VSM_SOFTWARE_VERSION
INFO,704,PREAMP_SERIAL_NUMBER
INFO,822,COIL_SERIAL_NUMBER
INFO,0,MOMENT_UNITS
INFO,CoFe2O4,SAMPLE_MATERIAL
INFO,Cobalt deficient,SAMPLE_COMMENT
INFO,,SAMPLE_MASS
INFO,27,SAMPLE_VOLUME
INFO,,SAMPLE_MOLECULAR_WEIGHT
INFO,,SAMPLE_SIZE
INFO,,SAMPLE_SHAPE
DATATYPE,COMMENT,1
DATATYPE,TIME,2
STARTUPAXIS,X,2
STARTUPAXIS,Y1,5
[Data]
Comment,Time Stamp (sec),Temperature (K),Magnetic Field (Oe),Moment (emu),M. Std. Err. (emu),Transport Action,Averaging Time (sec),Frequency (Hz),Peak Amplitude (mm),Center Position (mm),Coil Signal' (mV),Coil Signal" (mV),Range (mV),M. Quad. Signal (emu),M. Raw' (emu),M. Raw" (emu),Min. Temperature (K),Max. Temperature (K),Min. Field (Oe),Max. Field (Oe),Mass (grams),Motor Lag (deg),Pressure (Torr),VSM Status (code),Motor Status (code),Measure Status (code),Measure Count,PPMS Status (code),System Temp. (K),System Field (Oe),Sample Position (deg),Bridge 1 Resistance (ohms),Bridge 1 Excitation (에),Bridge 2 Resistance (ohms),Bridge 2 Excitation (에),Bridge 3 Resistance (ohms),Bridge 3 Excitation (에),Bridge 4 Resistance (ohms),Bridge 4 Excitation (에),Signal 1 Vin (V),Signal 2 Vin (V),Digital Inputs (code),Drive 1 Iout (mA),Drive 1 Ipower (W),Drive 2 Iout (mA),Drive 2 Ipower (W),Pressure (),Map 20 (),Map 21 (),Map 22 (),Map 23 (),Map 24 (),Map 25 (),Map 26 (),Map 27 (),Map 28 (),Map 29 ()
,20385991.33,50.0259819,-22687.572265625,,,2,,,,24.1599999809265,,,,,,,50.0259819,50.0259819,-22687.572265625,-22687.572265625,,,8.102614,,,,-99999999,4961,50.2574,-22687.572265625,,,,,,,,,,,,,,,,,,,,,,,50.0259819,,,,
,20386220.835,50.022007,4207.5498046875,-0.000956863758068712,3.79447878497215E-7,1,0.999253354069792,40.0298881530762,1.97989550333616,24.1400003433228,-0.0107024966426803,-0.00200522452964993,0.25,-6.57914301832797E-6,-0.000956498890086037,-1.36976864455786E-5,50.0218697,50.0221443,4177.47119140625,4237.62841796875,55.923957293929,19.6114075493678,7.722963,0,0,0,40,4961,50.2011,4207.5498046875,,,,,,,,,,,,,0,,,,0,,,,,,50.022007,,,,
,20386307.525,50.0170174,8543.560546875,-0.000528385838265633,5.10808623998575E-7,1,0.999253354069792,40.0298881530762,1.98109626356733,24.1400003433228,-0.00591448199879329,-0.00110901476607918,0.25,-3.71086504854935E-6,-0.000528293462594146,-7.6410077229117E-6,50.0170174,50.0170174,8540.982421875,8546.138671875,54.7382268302558,19.6045898740806,8.102614,0,0,0,40,4961,50.1949,8543.560546875,,,,,,,,,,,,,0,,,,0.0049,,,,,,50.0170174,,,,
,20386394.72,50.0176926,12901.751953125,0.000202091523956686,8.00125639153926E-7,1,0.999253354069792,40.0298881530762,1.98109164654816,24.1400003433228,0.00226241631496052,0.000425310537282082,0.25,1.51546704674046E-6,0.000202100293368914,3.01704294429166E-6,50.0176926,50.0176926,12898.931640625,12904.572265625,54.4834159329865,19.6185033738473,8.102614,0,0,0,40,4961,50.17705,12901.751953125,,,,,,,,,,,,,0,,,,-0.0049,,,,,,50.0176926,,,,
,20386481.87,50.0168686,17256.9462890625,0.00137405518611923,1.25083137581024E-6,1,0.999253354069792,40.0298881530762,1.98146782985404,24.1400003433228,0.0153923582016919,0.00287385210051701,0.25,8.62626116266082E-6,0.0013744458784142,1.88142506921173E-5,50.0168686,50.0168686,17251.716796875,17262.17578125,54.454495677775,19.612388407679,8.102614,0,0,0,40,4961,50.16605,17256.9462890625,,,,,,,,,,,,,0,,,,0.0049,,,,,,50.0168686,,,,
,20386568.67,50.01581955,21594.2880859375,0.00273324382718359,1.58246187503323E-6,1,0.999253354069792,40.0298881530762,1.98097126602188,24.1400003433228,0.0306154092953233,0.00573088321764901,0.25,1.85065876602052E-5,0.00273464921070906,3.87102356088842E-5,50.015686,50.0159531,21559.216796875,21629.359375,55.7027564229867,19.6154819517333,8.482265,0,0,0,40,4961,50.15185,21594.2880859375,,,,,,,,,,,,,0,,,,-0.00245,,,,,,50.01581955,,,,
,20386653.68,50.0100708,25842.1396484375,0.00336102036314656,1.2731835203756E-6,1,0.999253354069792,40.0298881530762,1.98105149661655,24.1400003433228,0.0376582697364338,0.00704401508390216,0.25,2.2419026331001E-5,0.00336352803619183,4.7161957510996E-5,50.0100708,50.0100708,25812.38671875,25871.892578125,55.0805801216789,19.6196200555307,8.102614,0,0,0,40,4961,50.1456,25842.1396484375,,,,,,,,,,,,,0,,,,0,,,,,,50.0100708,,,,
,20386731.3,50.0094242,29723.400390625,0.00351443631433332,1.32185660772095E-6,1,0.999253354069792,40.0298881530762,1.9809971396078,24.1400003433228,0.0393900257442838,0.0073358991367463,0.25,2.08085606006532E-5,0.0035178172499418,4.65595196643949E-5,50.0093384,50.00951,29690.833984375,29755.966796875,54.6670986350058,19.6152811391683,7.722963,0,0,0,40,4961,50.1429,29723.400390625,,,,,,,,,,,,,0,,,,0.00245,,,,,,50.0094242,,,,
,20386809.885,50.0055275,33651.0078125,0.00360422465936396,1.14176197605393E-6,1,0.999253354069792,40.0298881530762,1.98090776304049,24.150000885129,0.0403987079749923,0.00754884108742987,0.25,2.36570788019577E-5,0.00360843011273433,4.99246777354554E-5,50.0055275,50.0055275,33648.546875,33653.46875,54.1152689004288,19.6217792383855,8.102614,0,0,0,40,4961,50.1371,33651.0078125,,,,,,,,,,,,,0,,,,-0.0049,,,,,,50.0055275,,,,
,20386889.085,50.005352,37609.07421875,0.00365988660777582,1.25437177442574E-6,1,0.999253354069792,40.0298881530762,1.98094844127119,24.1400003433228,0.0410372951702347,0.00763736823015708,0.25,2.15459214327788E-5,0.00366493717764741,4.80479225414467E-5,50.005352,50.005352,37601.89453125,37616.25390625,54.8328038810827,19.6052049988474,7.722963,0,0,0,40,4961,50.135,37609.07421875,,,,,,,,,,,,,0,,,,-0.0049,,,,,,50.005352,,,,
,20386966.255,50.00444605,41466.962890625,0.00369797728277185,1.62573811446531E-6,1,0.999253354069792,40.0298881530762,1.98109529681739,24.1400003433228,0.0414678181920156,0.00776200288725876,0.25,2.57999484779643E-5,0.00370378843110819,5.23997368110682E-5,50.0042534,50.0046387,41444.46875,41489.45703125,55.6652382540636,19.6069567883983,8.102614,0,0,0,40,4961,50.1358,41466.962890625,,,,,,,,,,,,,0,,,,0.00245,,,,,,50.00444605,,,,
,20387045.18,50.0035439,45410.470703125,0.00371995204385331,1.37365385746251E-6,1,0.999253354069792,40.0298881530762,1.9811540935885,24.1400003433228,0.0417279294973278,0.0077860327095187,0.25,2.40442320220114E-5,0.00372654697840001,5.0593505331219E-5,50.0035439,50.0035439,45407.875,45413.06640625,54.6889842335442,19.6013939751703,8.102614,0,0,0,40,4961,50.13145,45410.470703125,,,,,,,,,,,,,0,,,,0.00245,,,,,,50.0035439,,,,
,20387121.43,50.0030994,49223.697265625,0.00373092734568268,1.31055968855538E-6,1,0.999253354069792,40.0298881530762,1.98054171557191,24.1400003433228,0.0418463872556286,0.00780869061024194,0.25,2.43875685343138E-5,0.00373823825994131,5.08001363380772E-5,50.0030479,50.0031509,49196.1328125,49251.26171875,55.1829734576981,19.6102399089835,7.722963,0,0,0,40,4961,50.13285,49223.697265625,,,,,,,,,,,,,0,,,,-0.00245,,,,,,50.0030994,,,,
,20387200.29,50.002903,53163.802734375,0.00373841226868943,1.93945644359976E-6,1,0.999253354069792,40.0298881530762,1.98091370936071,24.1400003433228,0.0419391703347714,0.0078634415108024,0.25,2.79063865523056E-5,0.00374641362284987,5.41430738217165E-5,50.002903,50.002903,53133.6875,53193.91796875,55.1204431761597,19.5951169466137,8.102614,0,0,0,40,4961,50.13125,53163.802734375,,,,,,,,,,,,,0,,,,0,,,,,,50.002903,,,,
,20387278.205,50.0033417,57056.572265625,0.0037377692363659,1.73328853668967E-6,1,0.999253354069792,40.0298881530762,1.98057361694649,24.1400003433228,0.0419319163909374,0.00786568096718046,0.25,2.84653687966771E-5,0.00374643394161343,5.44541095223776E-5,50.0033417,50.0033417,57051.42578125,57061.71875,54.7147779746789,19.6079287239032,8.102614,0,0,0,40,4961,50.1271,57056.572265625,,,,,,,,,,,,,0,,,,-0.00245,,,,,,50.0033417,,,,
,20387353.795,50.0035439,60835.015625,0.00372468565195015,2.0178966184906E-6,1,0.999253354069792,40.0298881530762,1.98079128626288,24.1400003433228,0.0418063546008583,0.00778564100310759,0.25,2.3758984945349E-5,0.00373397978996513,4.93972690938352E-5,50.0035439,50.0035439,60805.15234375,60864.87890625,55.5237634920828,19.607045623345,8.482265,0,0,0,40,4961,50.1263,60835.015625,,,,,,,,,,,,,0,,,,0.00245,,,,,,50.0035439,,,,
,20387433.28,50.0028038,64808.560546875,0.00371376298578984,1.66151080197792E-6,1,0.999253354069792,40.0298881530762,1.98144091636551,24.150000885129,0.0417036193330491,0.00776815980816136,0.25,2.41086243803516E-5,0.00372366173915935,4.94032946726836E-5,50.0028038,50.0028038,64803.515625,64813.60546875,54.7773082562173,19.5900943662097,8.102614,0,0,0,40,4961,50.1231,64808.560546875,,,,,,,,,,,,,0,,,,0,,,,,,50.0028038,,,,
,20387510.68,50.00406835,68679.09375,0.00369743945418847,1.80483082228188E-6,1,0.999253354069792,40.0298881530762,1.98119685386021,24.1400003433228,0.0415240279801551,0.00772334263274667,0.25,2.33008721850119E-5,0.00370789295641998,4.8213094601474E-5,50.0040245,50.0041122,68676.5,68681.6875,55.487026951679,19.5986901728021,7.722963,0,0,0,40,4961,50.1196,68679.09375,,,,,,,,,,,,,0,,,,0.0049,,,,,,50.00406835,,,,
,20387588.84,50.0021362,72582.26171875,0.00366952749781753,1.81721067833851E-6,1,0.999253354069792,40.0298881530762,1.98196718828037,24.1400003433228,0.0412344458473684,0.00765709661456516,0.25,2.23437355881151E-5,0.00368048254329851,4.67879902365818E-5,50.0021362,50.0021362,72579.59375,72584.9296875,54.6248906949673,19.5905069955401,8.102614,0,0,0,40,4961,50.1213,72582.26171875,,,,,,,,,,,,,0,,,,-0.0049,,,,,,50.0021362,,,,
,20387665.72,50.00301745,76426.02734375,0.00364840225499279,2.16073203565464E-6,1,0.999253354069792,40.0298881530762,1.98131659476089,24.1400003433228,0.0409859099061477,0.00763583970447559,0.25,2.46391893164772E-5,0.00365981821718438,4.86743439338183E-5,50.0029297,50.0031052,76393.7109375,76458.34375,55.0024172697558,19.5912713857477,8.102614,0,0,0,40,4961,50.11825,76426.02734375,,,,,,,,,,,,,0,,,,0,,,,,,50.00301745,,,,
,20387744.415,50.00211525,80359.6796875,0.00361614395586595,2.28356793499566E-6,1,0.999253354069792,40.0298881530762,1.98148514052768,24.1400003433228,0.0406367227809569,0.00754775606498697,0.25,2.27317062784029E-5,0.00362799902480791,4.62636138747124E-5,50.0019417,50.0022888,80332.1328125,80387.2265625,54.8898627629866,19.5855652649789,8.102614,0,0,0,40,4961,50.11955,80359.6796875,,,,,,,,,,,,,0,,,,-0.00245,,,,,,50.00211525,,,,
,20387823.015,50.0019875,84290.140625,0.00358360124416822,1.99659765778137E-6,1,0.999253354069792,40.0298881530762,1.98106229960698,24.1400003433228,0.0402721563704655,0.00745834807631667,0.25,2.09505585184922E-5,0.00359586023090772,4.39808385328111E-5,50.0019875,50.0019875,84260.171875,84320.109375,53.8041807497749,19.5935468432917,8.102614,0,0,0,40,4961,50.1143,84290.140625,,,,,,,,,,,,,0,,,,-0.0049,,,,,,50.0019875,,,,
,20387897.965,50.002224,88036.01953125,0.0035583725668948,2.39065773156685E-6,1,0.999253354069792,40.0298881530762,1.98112067063918,24.1400003433228,0.0399906365397388,0.00743069573575704,0.25,2.31875643913006E-5,0.00357098868577545,4.57906129725493E-5,50.002224,50.002224,88008.59375,88063.4453125,54.5264055015442,19.5996558273134,8.102614,0,0,0,40,4961,50.1179,88036.01953125,,,,,,,,,,,,,0,,,,-0.00245,,,,,,50.002224,,,,
,20387987.415,50.0010796,88197.8984375,0.00354811876820815,2.08866032049565E-6,1,0.999253354069792,40.0298881530762,1.98085605072652,24.1400003433228,0.0398760816334796,0.00737724002092049,0.25,2.03641718750383E-5,0.00356073350462967,4.2881515715419E-5,50.0010796,50.0010796,88192.984375,88202.8125,54.136372870448,19.5996745688214,7.722963,0,0,0,40,4961,50.1131,88197.8984375,,,,,,,,,,,,,0,,,,-0.0049,,,,,,50.0010796,,,,
,20388062.73,50.0012741,84431.66796875,0.00357781969991435,2.58361018259338E-6,1,0.999253354069792,40.0298881530762,1.98050397218718,24.1400003433228,0.0401964331806119,0.00744510379320205,0.25,2.09950857687236E-5,0.003590077361999,4.39774335104965E-5,50.0012741,50.0012741,84399.21875,84464.1171875,55.4541985538713,19.6027450155892,8.102614,0,0,0,40,4961,50.11735,84431.66796875,,,,,,,,,,,,,0,,,,0,,,,,,50.0012741,,,,
,20388142.75,50.000721,80433.6640625,0.00360447292549921,1.98442947025392E-6,1,0.999253354069792,40.0298881530762,1.98077441153188,24.150000885129,0.0404921491127961,0.00751867331951012,0.25,2.24702130137505E-5,0.0036162976818084,4.59218489178389E-5,50.000721,50.000721,80406.203125,80461.125,54.5725215841788,19.6053361882977,8.102614,0,0,0,40,4961,50.11255,80433.6640625,,,,,,,,,,,,,0,,,,0,,,,,,50.000721,,,,
,20388223.065,50.0002308,76416.984375,0.00362727636494071,1.6508487663856E-6,1,0.999253354069792,40.0298881530762,1.98124364225063,24.1400003433228,0.040748166697502,0.00758546838149771,0.25,2.39716436152072E-5,0.00363862629120345,4.78677911503586E-5,50.0001068,50.0003548,76392.1015625,76441.8671875,54.7108698320827,19.5924686962273,8.102614,0,0,0,40,4961,50.1134,76416.984375,,,,,,,,,,,,,0,,,,0,,,,,,50.0002308,,,,
,20388299.85,49.99897575,72578.1328125,0.00364902687221423,1.99052488521309E-6,1,0.999253354069792,40.0298881530762,1.98121750932673,24.1400003433228,0.0409898693252009,0.00760792127064423,0.25,2.18933336428575E-5,0.00365991880650332,4.62021293290179E-5,49.9988403,49.9991112,72548.046875,72608.21875,55.1634327447174,19.6003163811482,8.482265,0,0,0,40,4961,50.114,72578.1328125,,,,,,,,,,,,,0,,,,0,,,,,,49.99897575,,,,
,20388378.1,49.99978255,68667.625,0.00366409340570647,1.86023633686071E-6,1,0.999253354069792,40.0298881530762,1.98132080132436,24.1400003433228,0.041151356412415,0.00765747318906541,0.25,2.33855147650886E-5,0.00367444702843366,4.80756858214704E-5,49.9997673,49.9997978,68635.0546875,68700.1953125,55.2275262832943,19.5928673856365,8.102614,0,0,0,40,4961,50.11565,68667.625,,,,,,,,,,,,,0,,,,0,,,,,,49.99978255,,,,
,20388455.83,49.99824715,64784.224609375,0.00368210643230107,1.41914010243034E-6,1,0.999253354069792,40.0298881530762,1.98165249011405,24.1400003433228,0.0413496001615438,0.00771762173164063,0.25,2.52258244532353E-5,0.00369190518490143,5.03114598207612E-5,49.9981575,49.9983368,64751.6953125,64816.75390625,55.0883964068712,19.5894886194971,8.102614,0,0,0,40,4961,50.1177,64784.224609375,,,,,,,,,,,,,0,,,,0,,,,,,49.99824715,,,,
,20388534.96,49.9973774,60828.26953125,0.0036955379006335,1.32808521008878E-6,1,0.999253354069792,40.0298881530762,1.98143883966519,24.1400003433228,0.0414873406328169,0.00775359953509619,0.25,2.59269207182246E-5,0.00370473827707316,5.13726448141806E-5,49.997303,49.9974518,60793.4296875,60863.109375,54.9312890745058,19.5877356545585,7.722963,0,0,0,40,4961,50.11955,60828.26953125,,,,,,,,,,,,,0,,,,-0.00245,,,,,,49.9973774,,,,
,20388613.835,49.999157,56884.80078125,0.00370535917043785,1.55030166407601E-6,1,0.999253354069792,40.0298881530762,1.98140686026364,24.1400003433228,0.0415889724368987,0.00777650284915112,0.25,2.60660927847182E-5,0.00371392942923056,5.1837474930452E-5,49.999157,49.999157,56859.71875,56909.8828125,54.6905474905827,19.5820514415671,8.102614,0,0,0,40,4961,50.1184,56884.80078125,,,,,,,,,,,,,0,,,,0,,,,,,49.999157,,,,
,20388693.785,49.9987869,52891.87109375,0.00370800560719861,2.01437302487452E-6,1,0.999253354069792,40.0298881530762,1.98173122473185,24.1400003433228,0.0416167040165044,0.00778648682359275,0.25,2.62392783700687E-5,0.00371589634320268,5.22789861776366E-5,49.9987869,49.9987869,52886.83203125,52896.91015625,55.5573735184097,19.5887407029961,8.482265,0,0,0,40,4961,50.1186,52891.87109375,,,,,,,,,,,,,0,,,,-0.0049,,,,,,49.9987869,,,,
,20388770.825,49.9989052,49041.515625,0.00370458676561956,1.35967995227846E-6,1,0.999253354069792,40.0298881530762,1.98134610475347,24.1400003433228,0.041563852949122,0.00777189175225893,0.25,2.55732973729266E-5,0.00371179626055185,5.18151113890846E-5,49.9989052,49.9989052,49013.87890625,49069.15234375,54.7327554306212,19.5916848444747,8.482265,0,0,0,40,4961,50.1219,49041.515625,,,,,,,,,,,,,0,,,,-0.00245,,,,,,49.9989052,,,,
,20388850.095,50.0004845,45078.310546875,0.00369963025841638,1.54472163600631E-6,1,0.999253354069792,40.0298881530762,1.98117486741632,24.1400003433228,0.041497379216878,0.00775578384051242,0.25,2.49914353548208E-5,0.00370611103403647,5.14182806813159E-5,50.0004845,50.0004845,45045.921875,45110.69921875,55.1157534050443,19.592925974278,8.102614,0,0,0,40,4961,50.1188,45078.310546875,,,,,,,,,,,,,0,,,,-0.00245,,,,,,50.0004845,,,,
,20388928.765,50.0001183,41145.63671875,0.00368548337036748,1.39638113996844E-6,1,0.999253354069792,40.0298881530762,1.98145694884838,24.1400003433228,0.0413323402045097,0.00774673440771233,0.25,2.65615826529307E-5,0.00369119479261395,5.3092333998292E-5,50.0001183,50.0001183,41118.03515625,41173.23828125,55.2001692851212,19.5971941704147,7.722963,0,0,0,40,4961,50.1183,41145.63671875,,,,,,,,,,,,,0,,,,-0.00245,,,,,,50.0001183,,,,
,20389006.915,50.0002079,37240.107421875,0.00366739195856767,1.44178446127678E-6,1,0.999253354069792,40.0298881530762,1.98147840982102,24.1400003433228,0.0411212564520621,0.00770926071608941,0.25,2.64192386351068E-5,0.00367233708867317,5.30013385287872E-5,50.0001907,50.0002251,37215.015625,37265.19921875,55.5808223739866,19.5950522906108,8.482265,0,0,0,40,4961,50.12235,37240.107421875,,,,,,,,,,,,,0,,,,0.00245,,,,,,50.0002079,,,,
,20389084.49,49.99938015,33362.33984375,0.00363965170246243,1.05648857202985E-6,1,0.999253354069792,40.0298881530762,1.98186892369264,24.1400003433228,0.0408136333674841,0.00762798053365839,0.25,2.40125449617651E-5,0.0036438262377369,5.05530709756342E-5,49.9991837,49.9995766,33337.28125,33387.3984375,54.9125299900443,19.5964821818411,7.722963,0,0,0,40,4961,50.1188,33362.33984375,,,,,,,,,,,,,0,,,,-0.00245,,,,,,49.99938015,,,,
,20389161.735,49.99967765,29501.927734375,0.00360577904676856,9.2605280144062E-7,1,0.999253354069792,40.0298881530762,1.98146968697007,24.1400003433228,0.0404133620741768,0.00757785811373568,0.25,2.57669818078097E-5,0.00360915327362309,5.22025437989186E-5,49.999649,49.9997063,29469.423828125,29534.431640625,54.8523445940635,19.5889878680064,8.102614,0,0,0,40,4961,50.121,29501.927734375,,,,,,,,,,,,,0,,,,0,,,,,,49.99967765,,,,
,20389239.32,49.9995842,25626.1298828125,0.00356044656143244,1.1655837475948E-6,1,0.999253354069792,40.0298881530762,1.98189323558827,24.1400003433228,0.0399059489680997,0.0074773536605496,0.25,2.48517221159418E-5,0.00356303060534684,5.10729992893142E-5,49.9995842,49.9995842,25601.26953125,25650.990234375,55.0930861779866,19.5961752561073,8.102614,0,0,0,40,4961,50.12085,25626.1298828125,,,,,,,,,,,,,0,,,,-0.00245,,,,,,49.9995842,,,,
,20389317.95,49.99928285,21695.7939453125,0.00350619430615926,9.84914028117667E-7,1,0.999253354069792,40.0298881530762,1.98183777978392,24.1400003433228,0.0392901881793033,0.00735163041043144,0.25,2.34735079676695E-5,0.00350799133520217,4.93914820625021E-5,49.9992485,49.9993172,21668.09375,21723.494140625,55.483900437602,19.595864382414,8.482265,0,0,0,40,4961,50.12225,21695.7939453125,,,,,,,,,,,,,0,,,,-0.00245,,,,,,49.99928285,,,,
,20389395.25,49.9996147,17830.7509765625,0.00344368864024872,9.72960430353279E-7,1,0.999253354069792,40.0298881530762,1.98176201023949,24.1400003433228,0.0385803315117974,0.0072179874801286,0.25,2.29016884266182E-5,0.00344472595238016,4.84298962602166E-5,49.9996147,49.9996147,17800.8515625,17860.650390625,55.2509751388712,19.5864101151543,8.102614,0,0,0,40,4961,50.12385,17830.7509765625,,,,,,,,,,,,,0,,,,-0.00245,,,,,,49.9996147,,,,
,20389472.565,49.9996796,13965.8569335938,0.00337252128318348,7.66428144896022E-7,1,0.999253354069792,40.0298881530762,1.98168024154387,24.1400003433228,0.0377723795208951,0.00707380698247383,0.25,2.29703803013911E-5,0.00337282339571781,4.80212201740154E-5,49.9996796,49.9996796,13932.96875,13998.7451171875,55.1954795140058,19.5865105058493,8.102614,0,0,0,40,4961,50.1221,13965.8569335938,,,,,,,,,,,,,0,,,,0,,,,,,49.9996796,,,,
,20389550.32,49.9997025,10082.8803710938,0.00328534291716377,5.7901114605834E-7,1,0.999253354069792,40.0298881530762,1.98160649435181,24.1400003433228,0.0367888810218019,0.0068790823071786,0.25,2.14286432924851E-5,0.00328496294603196,4.58607767002982E-5,49.9997025,49.9997025,10050.408203125,10115.3525390625,55.1798469436212,19.5890619011885,7.722963,0,0,0,40,4961,50.1168,10082.8803710938,,,,,,,,,,,,,0,,,,0.00245,,,,,,49.9997025,,,,
,20389627.9,50.0007515,6204.58227539063,0.0031808146775363,4.8225625456473E-7,1,0.999253354069792,40.0298881530762,1.98149591261231,24.1400003433228,0.0356092833678441,0.00665998488956935,0.25,2.08557625373326E-5,0.00317982551394814,4.45201121907915E-5,50.0007515,50.0007515,6177.12744140625,6232.037109375,55.6449159125636,19.5974297040392,7.722963,0,0,0,40,4961,50.1184,6204.58227539063,,,,,,,,,,,,,0,,,,0,,,,,,50.0007515,,,,
,20389706.835,50.0018158,2258.49353027344,0.00304859064217868,3.29510785354145E-7,1,0.999253354069792,40.0298881530762,1.98188704603072,24.1400003433228,0.0341292210464267,0.00638399496148664,0.25,2.00576902216273E-5,0.00304709709296888,4.27330166632644E-5,50.0018158,50.0018158,2228.68139648438,2288.3056640625,55.4854636946405,19.5751106389927,8.482265,0,0,0,40,4961,50.1167,2258.49353027344,,,,,,,,,,,,,0,,,,-0.00245,,,,,,50.0018158,,,,
,20389782.595,49.9980831,-1524.93267822266,0.00287715883770696,4.76430187130944E-7,1,0.999253354069792,40.0298881530762,1.98175461070511,24.150000885129,0.0322078475348143,0.00602020924885868,0.25,1.85519749621584E-5,0.00287567272674433,3.99505005978449E-5,49.9980011,49.9981651,-1557.45202636719,-1492.41333007813,54.5178075878327,19.5871556903987,8.102614,0,0,0,40,4961,50.12015,-1524.93267822266,,,,,,,,,,,,,0,,,,0,,,,,,49.9980831,,,,
,20389859.89,49.99697685,-5387.26318359375,0.0026192790049252,5.57656705817479E-7,1,0.999253354069792,40.0298881530762,1.98152781558198,24.1400003433228,0.0293225348037793,0.00548237181995103,0.25,1.70166812405549E-5,0.00261836637009036,3.65033919793794E-5,49.9969559,49.9969978,-5414.7958984375,-5359.73046875,55.4596699535059,19.590133100253,8.482265,0,0,0,40,4961,50.12235,-5387.26318359375,,,,,,,,,,,,,0,,,,0,,,,,,49.99697685,,,,
,20389944.12,49.9969254,-9600.93994140625,0.00212998999213041,5.6081559317821E-7,1,0.999253354069792,40.0298881530762,1.98181351927928,24.1400003433228,0.0238530636329158,0.00446111959998908,0.25,1.39668914820682E-5,0.00212969493883766,2.98083020645356E-5,49.9969254,49.9969254,-9628.416015625,-9573.4638671875,55.3260114767174,19.5834293435339,8.102614,0,0,0,40,4961,50.1245,-9600.93994140625,,,,,,,,,,,,,0,,,,-0.00245,,,,,,49.9969254,,,,
,20390032.05,49.998394,-13994.146484375,0.00118809987701396,8.50527784810645E-7,1,0.999253354069792,40.0298881530762,1.98158295159506,24.1400003433228,0.0133065206130826,0.00248996254825375,0.25,7.91890170091277E-6,0.00118820990555631,1.67438664686824E-5,49.998394,49.998394,-13997.0859375,-13991.20703125,54.9211279037558,19.5841053697501,8.102614,0,0,0,40,4961,50.1235,-13994.146484375,,,,,,,,,,,,,0,,,,-0.00245,,,,,,49.998394,,,,
,20390121.04,50.0000343,-18441.7275390625,-0.00025274156479107,9.89792307566377E-7,1,0.999253354069792,40.0298881530762,1.98145493799908,24.1400003433228,-0.00283154980558015,-0.000527695058728834,0.25,-1.50407480319181E-6,-0.00025282756566085,-3.37684419547713E-6,50.0000343,50.0000343,-18474.33984375,-18409.115234375,54.9265993033904,19.5952939030622,8.102614,0,0,0,40,4961,50.1254,-18441.7275390625,,,,,,,,,,,,,0,,,,0.00245,,,,,,50.0000343,,,,
,20390207.095,50.0013542,-22741.3203125,-0.00167416623988969,1.1415189279687E-6,1,0.999253354069792,40.0298881530762,1.98195550646856,24.1400003433228,-0.0187602710908375,-0.00352455713424484,0.25,-1.24543149270179E-5,-0.00167511340413787,-2.4819036099449E-5,50.0013542,50.0013542,-22746.515625,-22736.125,54.5936255541981,19.5918397947678,7.722963,0,0,0,40,4961,50.1271,-22741.3203125,,,,,,,,,,,,,0,,,,-0.00245,,,,,,50.0013542,,,,
,20390283.61,50.0029411,-26566.1796875,-0.00258995225818831,9.90141175576339E-7,1,0.999253354069792,40.0298881530762,1.98177812099449,24.1400003433228,-0.0290286402774915,-0.00543780115722902,0.25,-1.79763468730386E-5,-0.00259196507103504,-3.70308111563465E-5,50.0029411,50.0029411,-26588.59765625,-26543.76171875,55.4823371805636,19.5912963859702,8.482265,0,0,0,40,4961,50.1198,-26566.1796875,,,,,,,,,,,,,0,,,,0.00245,,,,,,50.0029411,,,,
,20390362.925,50.0035305,-30529.1845703125,-0.00311964379648212,8.92299311358111E-7,1,0.999253354069792,40.0298881530762,1.98185774070456,24.1400003433228,-0.0349759272051092,-0.00654296780159515,0.25,-2.10053871540968E-5,-0.00312274498854389,-4.38451126910901E-5,50.0034523,50.0036087,-30561.9296875,-30496.439453125,55.260354681102,19.5805346965864,8.482265,0,0,0,40,4961,50.12,-30529.1845703125,,,,,,,,,,,,,0,,,,0,,,,,,50.0035305,,,,
,20390440.805,50.0023804,-34424.314453125,-0.00339010462964043,1.12099945191878E-6,1,0.999253354069792,40.0298881530762,1.98183162110944,24.1400003433228,-0.0380177211292024,-0.00710006885821032,0.25,-2.19466713005682E-5,-0.00339418922321994,-4.66270720528751E-5,50.0023804,50.0023804,-34454.45703125,-34394.171875,54.9703705004673,19.5789670214725,7.722963,0,0,0,40,4961,50.1209,-34424.314453125,,,,,,,,,,,,,0,,,,-0.00245,,,,,,50.0023804,,,,
,20390520.72,50.0022068,-38417.181640625,-0.00353051616058306,1.00155377738898E-6,1,0.999253354069792,40.0298881530762,1.98198044917097,24.150000885129,-0.0396025551255955,-0.00740100947703654,0.25,-2.34591414494557E-5,-0.00353550223865849,-4.89964620234042E-5,50.0021973,50.0022163,-38447.48828125,-38386.875,54.5060831600442,19.5887062333515,7.722963,0,0,0,40,4961,50.11525,-38417.181640625,,,,,,,,,,,,,0,,,,0,,,,,,50.0022068,,,,
,20390601.835,50.0012894,-42471.8359375,-0.00360145142893749,1.35432806733388E-6,1,0.999253354069792,40.0298881530762,1.9820035114743,24.1400003433228,-0.0404068477648161,-0.00755282604951606,0.25,-2.42629988652308E-5,-0.00360728755751867,-5.01214561770237E-5,50.0012894,50.0012894,-42504.0859375,-42439.5859375,55.168904144352,19.5863035833147,8.102614,0,0,0,40,4961,50.11755,-42471.8359375,,,,,,,,,,,,,0,,,,0,,,,,,50.0012894,,,,
,20390679.145,50.0008507,-46335.37109375,-0.00363661653391881,1.50049320249494E-6,1,0.999253354069792,40.0298881530762,1.98221169357676,24.1400003433228,-0.0408127769385805,-0.00763196371322114,0.25,-2.49912050953886E-5,-0.003643209634657,-5.09019484758357E-5,50.0008507,50.0008507,-46368.12109375,-46302.62109375,54.9719337575058,19.5800151395976,8.102614,0,0,0,40,4961,50.1172,-46335.37109375,,,,,,,,,,,,,0,,,,0,,,,,,50.0008507,,,,
,20390758.555,50.00069425,-50302.95703125,-0.00365070120239063,1.70617265565435E-6,1,0.999253354069792,40.0298881530762,1.98206358817648,24.1400003433228,-0.0409771175805178,-0.00765500365696918,0.25,-2.46568637220414E-5,-0.00365802606426825,-5.04453751391096E-5,50.000576,50.0008125,-50335.41015625,-50270.50390625,55.2970912215058,19.5795775432708,8.482265,0,0,0,40,4961,50.11385,-50302.95703125,,,,,,,,,,,,,0,,,,-0.00245,,,,,,50.00069425,,,,
,20390838.445,50.0007858,-54295.248046875,-0.0036518502664548,1.45687389708361E-6,1,0.999253354069792,40.0298881530762,1.98234830621771,24.1400003433228,-0.0410097970089105,-0.00762412228851283,0.25,-2.17291437937583E-5,-0.00365988907865332,-4.72804761450478E-5,50.0007858,50.0007858,-54327.75,-54262.74609375,55.4659229816597,19.5788813089153,7.722963,0,0,0,40,4961,50.11765,-54295.248046875,,,,,,,,,,,,,0,,,,0,,,,,,50.0007858,,,,
,20390917.86,50.0009747,-58262.853515625,-0.00364751068962447,1.35686356667483E-6,1,0.999253354069792,40.0298881530762,1.98196451626076,24.1400003433228,-0.0409595984457375,-0.00762220132640057,0.25,-2.25983451201561E-5,-0.00365619600795483,-4.78723237760832E-5,50.0009499,50.0009995,-58295.3203125,-58230.38671875,54.8445283088712,19.5846362023784,8.102614,0,0,0,40,4961,50.11925,-58262.853515625,,,,,,,,,,,,,0,,,,-0.00245,,,,,,50.0009747,,,,
,20390995.4,50.0007477,-62137.6796875,-0.00363559494224602,1.45638902487811E-6,1,0.999253354069792,40.0298881530762,1.98193150581556,24.1400003433228,-0.0408304971955514,-0.00760706423696777,0.25,-2.35470667652871E-5,-0.003644862629629,-4.84908461186279E-5,50.0007477,50.0007477,-62142.6171875,-62132.7421875,55.3041258781789,19.5859121386321,7.722963,0,0,0,40,4961,50.1114,-62137.6796875,,,,,,,,,,,,,0,,,,-0.0049,,,,,,50.0007477,,,,
,20391073.445,50.0024109,-66038.50390625,-0.00361825105704123,1.94573135645208E-6,1,0.999253354069792,40.0298881530762,1.98245589776969,24.1400003433228,-0.040650788021002,-0.00758473578486774,0.25,-2.46631421654776E-5,-0.00362806970249504,-4.92295597557193E-5,50.0024109,50.0024109,-66070.9765625,-66006.03125,54.9500481589674,19.5809000424062,7.722963,0,0,0,40,4961,50.11375,-66038.50390625,,,,,,,,,,,,,0,,,,0.00245,,,,,,50.0024109,,,,
,20391151.64,50.0028992,-69948.59375,-0.00360016477277346,1.5815019818541E-6,1,0.999253354069792,40.0298881530762,1.98237748626814,24.150000885129,-0.0404499592906589,-0.00756207289210133,0.25,-2.60882709357743E-5,-0.00361050320089286,-5.02686541535683E-5,50.0027733,50.0030251,-69978.578125,-69918.609375,54.9813132997366,19.5837504347669,8.102614,0,0,0,40,4961,50.1138,-69948.59375,,,,,,,,,,,,,0,,,,-0.00245,,,,,,50.0028992,,,,
,20391231.295,50.0020866,-73930.52734375,-0.00357489140810226,1.93943920856419E-6,1,0.999253354069792,40.0298881530762,1.98221700214185,24.1400003433228,-0.0401678750701461,-0.00751682541706134,0.25,-2.68321470835715E-5,-0.00358571384554631,-5.05694733331369E-5,50.0020866,50.0020866,-73935.8125,-73925.2421875,55.3244482196789,19.5844663088255,7.722963,0,0,0,40,4961,50.1109,-73930.52734375,,,,,,,,,,,,,0,,,,0.0049,,,,,,50.0020866,,,,
,20391309.22,50.0028419,-77821.05078125,-0.00354724320545352,1.80822443857797E-6,1,0.999253354069792,40.0298881530762,1.98198063853718,24.1400003433228,-0.0398609551766224,-0.00744552590961065,0.25,-2.57122812628648E-5,-0.00355851414779049,-4.89897628752592E-5,50.0028419,50.0028419,-77853.6328125,-77788.46875,54.9641174723135,19.5920311308799,8.102614,0,0,0,40,4961,50.111,-77821.05078125,,,,,,,,,,,,,0,,,,0.0049,,,,,,50.0028419,,,,
,20391387.575,50.0019035,-81738.6953125,-0.00351137320292265,1.94605254828623E-6,1,0.999253354069792,40.0298881530762,1.98200162973394,24.1400003433228,-0.039467555737926,-0.00735091662705388,0.25,-2.39174417164091E-5,-0.00352304315089449,-4.66786031972767E-5,50.0019035,50.0019035,-81766.0625,-81711.328125,55.0493149809097,19.5863357408534,7.722963,0,0,0,40,4961,50.10795,-81738.6953125,,,,,,,,,,,,,0,,,,0,,,,,,50.0019035,,,,
,20391466.19,50.0023346,-85666.4609375,-0.00347921759042306,2.22972965704919E-6,1,0.999253354069792,40.0298881530762,1.98250228840193,24.1400003433228,-0.0391197196193092,-0.00729317603363294,0.25,-2.45872875603162E-5,-0.00349125642029267,-4.6865155382044E-5,50.0023079,50.0023613,-85698.9765625,-85633.9453125,54.8992423052174,19.5886563975563,7.722963,0,0,0,40,4961,50.1085,-85666.4609375,,,,,,,,,,,,,0,,,,0,,,,,,50.0023346,,,,
,20391540.765,50.0023899,-89393.80078125,-0.00344399668793613,1.47661928474693E-6,1,0.999253354069792,40.0298881530762,1.98236022804317,24.1400003433228,-0.0387297878401235,-0.00719796684046381,0.25,-2.26702827147201E-5,-0.00345635746841967,-4.44544787006413E-5,50.0022049,50.0025749,-89421.34375,-89366.2578125,55.2025141706789,19.5819165361195,7.722963,0,0,0,40,4961,50.1052,-89393.80078125,,,,,,,,,,,,,0,,,,0,,,,,,50.0023899,,,,
,20391631.83,49.99970245,-86884.5390625,-0.00346887016426734,1.72328500620734E-6,1,0.999253354069792,40.0298881530762,1.98229031758597,24.1400003433228,-0.0390011032101782,-0.00727049608479292,0.25,-2.4553250744971E-5,-0.00348101757845712,-4.6678881002368E-5,49.9996338,49.9997711,-86904.5546875,-86864.5234375,55.3236665911597,19.592528210539,8.102614,0,0,0,40,4961,50.10755,-86884.5390625,,,,,,,,,,,,,0,,,,0,,,,,,49.99970245,,,,
,20391708.68,49.99949835,-83044.26171875,-0.00349656219638721,1.35893248954044E-6,1,0.999253354069792,40.0298881530762,1.98278557686958,24.1400003433228,-0.0393174998531651,-0.00732444392112538,0.25,-2.40379291353118E-5,-0.00350834484065416,-4.6611127683094E-5,49.9993477,49.999649,-83076.7578125,-83011.765625,55.3088156492943,19.5819444746023,8.102614,0,0,0,40,4961,50.10875,-83044.26171875,,,,,,,,,,,,,0,,,,-0.00245,,,,,,49.99949835,,,,
,20391787.395,49.9982643,-79108.8828125,-0.00353043383496125,1.91154089916608E-6,1,0.999253354069792,40.0298881530762,1.98260587940194,24.1400003433228,-0.0396891442658585,-0.00739469219337046,0.25,-2.40715166613143E-5,-0.00354182888558224,-4.71435237394727E-5,49.998127,49.9984016,-79133.8984375,-79083.8671875,54.9094034759674,19.5841520012344,8.102614,0,0,0,40,4961,50.10765,-79108.8828125,,,,,,,,,,,,,0,,,,-0.00245,,,,,,49.9982643,,,,
,20391867.01,49.99835015,-75128.77734375,-0.00355743080151422,1.64221182932437E-6,1,0.999253354069792,40.0298881530762,1.98286402165355,24.1400003433228,-0.0399908788737337,-0.00745543178591454,0.25,-2.43559493245952E-5,-0.00356837905998845,-4.78869281247916E-5,49.9981804,49.9985199,-75161.296875,-75096.2578125,55.0712005794481,19.5864248741138,8.102614,0,0,0,40,4961,50.10735,-75128.77734375,,,,,,,,,,,,,0,,,,0,,,,,,49.99835015,,,,
,20391945.445,49.9981995,-71211.38671875,-0.00358271565263017,1.49822531156483E-6,1,0.999253354069792,40.0298881530762,1.98250374680366,24.1400003433228,-0.040259494059089,-0.00752004763784634,0.25,-2.54991672546899E-5,-0.00359318814796774,-4.94739890180679E-5,49.9981995,49.9981995,-71243.796875,-71178.9765625,55.7222971359674,19.5809840743301,8.482265,0,0,0,40,4961,50.1123,-71211.38671875,,,,,,,,,,,,,0,,,,0,,,,,,49.9981995,,,,
,20392025.065,49.9979744,-67231.8125,-0.00360500935178494,1.33457484117471E-6,1,0.999253354069792,40.0298881530762,1.98285298264342,24.1400003433228,-0.0405097313251928,-0.00757006362009708,0.25,-2.56569290671895E-5,-0.00361496249437692,-5.0056184150149E-5,49.9979744,49.9979744,-67261.6875,-67201.9375,54.8296773670058,19.5848912681306,8.482265,0,0,0,40,4961,50.1105,-67231.8125,,,,,,,,,,,,,0,,,,-0.00245,,,,,,49.9979744,,,,
,20392104.41,49.9986248,-63266.326171875,-0.00362200733903445,1.56551710385892E-6,1,0.999253354069792,40.0298881530762,1.98270883401158,24.1400003433228,-0.0406891997682939,-0.00761478396662082,0.25,-2.64646239986922E-5,-0.0036313967423916,-5.12482666428226E-5,49.9985428,49.9987068,-63299.02734375,-63233.625,54.860942507775,19.5847242788473,8.102614,0,0,0,40,4961,50.1116,-63266.326171875,,,,,,,,,,,,,0,,,,-0.00245,,,,,,49.9986248,,,,
,20392184.195,49.9992294,-59278.37109375,-0.00364142189264113,1.68058267132978E-6,1,0.999253354069792,40.0298881530762,1.98249880823581,24.1400003433228,-0.0409026310577281,-0.0076168885204489,0.25,-2.30809509065598E-5,-0.00365024973583724,-4.82506789388339E-5,49.9992294,49.9992294,-59305.74609375,-59250.99609375,55.6605484829482,19.5838413983754,8.102614,0,0,0,40,4961,50.11115,-59278.37109375,,,,,,,,,,,,,0,,,,-0.00245,,,,,,49.9992294,,,,
,20392260.845,49.9994087,-55445.697265625,-0.00364841684063501,1.51385533176942E-6,1,0.999253354069792,40.0298881530762,1.98230833095604,24.1400003433228,-0.0409700725865392,-0.00763109295539978,0.25,-2.30159475472053E-5,-0.00365662857609207,-4.84769595224774E-5,49.9994087,49.9994087,-55448.15625,-55443.23828125,55.585512145102,19.5797969295324,8.102614,0,0,0,40,4961,50.1105,-55445.697265625,,,,,,,,,,,,,0,,,,0,,,,,,49.9994087,,,,
,20392339.455,49.9984016,-51518.275390625,-0.00365787955361797,1.43594838340421E-6,1,0.999253354069792,40.0298881530762,1.98263185148735,24.1400003433228,-0.0410661500669492,-0.00770130468560031,0.25,-2.73326123154002E-5,-0.00366541282643844,-5.31062397110253E-5,49.9984016,49.9984016,-51540.7578125,-51495.79296875,55.3775989589866,19.5741314587728,8.482265,0,0,0,40,4961,50.11395,-51518.275390625,,,,,,,,,,,,,0,,,,0,,,,,,49.9984016,,,,
,20392420.41,49.9988346,-47475.6875,-0.00366118435760067,1.63402828057198E-6,1,0.999253354069792,40.0298881530762,1.98279850128635,24.1400003433228,-0.0411073287051868,-0.00765867799687465,0.25,-2.27832692037827E-5,-0.00366804249259063,-4.88024824683127E-5,49.9987602,49.998909,-47508.1171875,-47443.2578125,55.1767204295443,19.576559602332,8.482265,0,0,0,40,4961,50.1145,-47475.6875,,,,,,,,,,,,,0,,,,-0.0049,,,,,,49.9988346,,,,
,20392500.545,49.9990273,-43467.630859375,-0.0036563456758611,1.36822321462839E-6,1,0.999253354069792,40.0298881530762,1.98295404757356,24.1400003433228,-0.0410456129926822,-0.00766044471140592,0.25,-2.36711469066252E-5,-0.00366245897644274,-4.98722453791938E-5,49.9990273,49.9990273,-43469.9921875,-43465.26953125,55.2822402796405,19.5745281011883,7.722963,0,0,0,40,4961,50.1137,-43467.630859375,,,,,,,,,,,,,0,,,,0,,,,,,49.9990273,,,,
,20392575.655,49.99866295,-39714.873046875,-0.00364557248798883,1.22528207201907E-6,1,0.999253354069792,40.0298881530762,1.98308424384609,24.1400003433228,-0.0409157181341268,-0.00765762626530326,0.25,-2.52523017040456E-5,-0.00365095919971772,-5.15631887520305E-5,49.9986229,49.998703,-39742.609375,-39687.13671875,55.2329976829289,19.5770470774361,8.482265,0,0,0,40,4961,50.11555,-39714.873046875,,,,,,,,,,,,,0,,,,0,,,,,,49.99866295,,,,
,20392653.675,49.9983215,-35814.7734375,-0.00362811946396139,9.93086762737648E-7,1,0.999253354069792,40.0298881530762,1.98329338195223,24.1400003433228,-0.0407136291451127,-0.00763166007432337,0.25,-2.59686491890113E-5,-0.0036327374272326,-5.23280627269117E-5,49.9983215,49.9983215,-35844.7421875,-35784.8046875,55.2845851651982,19.5785882957847,8.102614,0,0,0,40,4961,50.1178,-35814.7734375,,,,,,,,,,,,,0,,,,-0.00245,,,,,,49.9983215,,,,
,20392731.845,49.9993477,-31909.955078125,-0.00360209458844188,1.05945478780963E-6,1,0.999253354069792,40.0298881530762,1.98316950088416,24.1400003433228,-0.0404137137606348,-0.00755849514720163,0.25,-2.41580022156324E-5,-0.00360593940026357,-5.04808974285998E-5,49.9993477,49.9993477,-31912.431640625,-31907.478515625,55.3994845575251,19.5839206677163,8.102614,0,0,0,40,4961,50.11455,-31909.955078125,,,,,,,,,,,,,0,,,,0,,,,,,49.9993477,,,,
,20392809.035,49.9975586,-28052.1982421875,-0.0035675401164457,9.56575997353465E-7,1,0.999253354069792,40.0298881530762,1.98307141800646,24.1400003433228,-0.0400159894320759,-0.00748321947521356,0.25,-2.37085423519252E-5,-0.00357060761748302,-4.99095207319745E-5,49.9975586,49.9975586,-28084.806640625,-28019.58984375,54.8585976222173,19.5797670305187,8.482265,0,0,0,40,4961,50.1174,-28052.1982421875,,,,,,,,,,,,,0,,,,0.00245,,,,,,49.9975586,,,,
,20392885.99,49.99943355,-24206.775390625,-0.00352530928334307,8.67572165438333E-7,1,0.999253354069792,40.0298881530762,1.982568287137,24.1400003433228,-0.0395217666461516,-0.0074059674378053,0.25,-2.46159276446723E-5,-0.00352758967777385,-5.06167073127737E-5,49.9993935,49.9994736,-24236.79296875,-24176.7578125,55.3916682723328,19.5787336605592,8.482265,0,0,0,40,4961,50.1167,-24206.775390625,,,,,,,,,,,,,0,,,,-0.00245,,,,,,49.99943355,,,,
,20392963.65,49.9988403,-20326.658203125,-0.00347303896342958,8.17125107274084E-7,1,0.999253354069792,40.0298881530762,1.98276000998593,24.1400003433228,-0.0389296585252884,-0.00730313588574113,0.25,-2.48534378496503E-5,-0.00347454016694882,-5.05560569993743E-5,49.9988403,49.9988403,-20353.8671875,-20299.44921875,55.189226485852,19.5747889066381,8.102614,0,0,0,40,4961,50.1162,-20326.658203125,,,,,,,,,,,,,0,,,,0,,,,,,49.9988403,,,,
,20393040.835,49.99973105,-16466.279296875,-0.00340831576509149,7.18711271591208E-7,1,0.999253354069792,40.0298881530762,1.98301944365635,24.1400003433228,-0.0382049712955993,-0.00714373838309755,0.25,-2.22952437734245E-5,-0.00340908460259682,-4.75818951873477E-5,49.9996948,49.9997673,-16491.189453125,-16441.369140625,55.3353910189482,19.5819480861833,8.482265,0,0,0,40,4961,50.11695,-16466.279296875,,,,,,,,,,,,,0,,,,-0.00245,,,,,,49.99973105,,,,
,20393118.005,49.9999237,-12610.7905273437,-0.00333245360413841,6.516409780094E-7,1,0.999253354069792,40.0298881530762,1.98303861205819,24.1400003433228,-0.0373468475830703,-0.00698524069871513,0.25,-2.19161948580377E-5,-0.00333251142633994,-4.66819930207685E-5,49.9999237,49.9999237,-12638.1962890625,-12583.384765625,54.8828281063135,19.5760226345172,8.482265,0,0,0,40,4961,50.11745,-12610.7905273437,,,,,,,,,,,,,0,,,,0,,,,,,49.9999237,,,,
,20393195.85,49.99866485,-8719.82080078125,-0.00324232335094416,5.39650644690036E-7,1,0.999253354069792,40.0298881530762,1.98296445842369,24.1400003433228,-0.0363272337788066,-0.0067994023499683,0.25,-2.17123457036749E-5,-0.00324171827140675,-4.58298750080925E-5,49.9983597,49.99897,-8749.912109375,-8689.7294921875,54.749169629525,19.5717652883606,8.102614,0,0,0,40,4961,50.11855,-8719.82080078125,,,,,,,,,,,,,0,,,,-0.00245,,,,,,49.99866485,,,,
,20393273.775,50.0004826,-4824.28344726562,-0.00313155867398721,4.26840056015878E-7,1,0.999253354069792,40.0298881530762,1.98292712639721,24.1400003433228,-0.0350790785190467,-0.00656479214966343,0.25,-2.08729096989758E-5,-0.0031303786632891,-4.41702795800376E-5,50.0001984,50.0007668,-4856.84912109375,-4791.7177734375,54.6999270328135,19.566972371948,7.722963,0,0,0,40,4961,50.12025,-4824.28344726562,,,,,,,,,,,,,0,,,,-0.00245,,,,,,50.0004826,,,,
,20393352.725,49.9999752,-877.764923095703,-0.0029864855152332,4.67923669695044E-7,1,0.999253354069792,40.0298881530762,1.98336083634775,24.1400003433228,-0.0334545998562192,-0.0062656284555551,0.25,-2.03256393111131E-5,-0.0029848624287361,-4.2534787953764E-5,49.9999428,50.0000076,-907.794860839844,-847.734985351562,54.9125299900443,19.5696880207214,8.102614,0,0,0,40,4961,50.11685,-877.764923095703,,,,,,,,,,,,,0,,,,0,,,,,,49.9999752,,,,
,20393429.025,49.9999886,2930.32580566406,-0.0027902754769989,4.38512020510786E-7,1,0.999253354069792,40.0298881530762,1.98321470348658,24.1400003433228,-0.0312579780017482,-0.00584831730489955,0.25,-1.84783446565267E-5,-0.00278898513658605,-3.92338211230369E-5,49.9999886,49.9999886,2905.02783203125,2955.62377929687,55.1571797165635,19.5702531161348,8.102614,0,0,0,40,4961,50.11615,2930.32580566406,,,,,,,,,,,,,0,,,,-0.00245,,,,,,49.9999886,,,,
,20393507.7,49.9990349,6865.5908203125,-0.00246687219132601,4.90255036044647E-7,1,0.999253354069792,40.0298881530762,1.9834251122315,24.1400003433228,-0.0276433927847044,-0.00516924392255398,0.25,-1.60997649863466E-5,-0.00246618311679126,-3.44522622012499E-5,49.9990349,49.9990349,6835.45751953125,6895.72412109375,55.1728122869481,19.5613385864393,8.482265,0,0,0,40,4961,50.1155,6865.5908203125,,,,,,,,,,,,,0,,,,-0.0049,,,,,,49.9990349,,,,
,20393585.995,49.998394,10776.271484375,-0.00191876475105,6.53809214086209E-7,1,0.999253354069792,40.0298881530762,1.98339721647359,24.1400003433228,-0.0215060823914533,-0.00401778039648415,0.25,-1.22079520241398E-5,-0.00191861696125703,-2.64750204105E-5,49.998394,49.998394,10773.8466796875,10778.6962890625,55.0329007820058,19.5617345609815,7.722963,0,0,0,40,4961,50.1209,10776.271484375,,,,,,,,,,,,,0,,,,0,,,,,,49.998394,,,,
,20393661.555,49.9985886,14554.3120117188,-0.00100434541341898,9.26553783501006E-7,1,0.999253354069792,40.0298881530762,1.98333824279581,24.1400003433228,-0.011260202151556,-0.00209644068315242,0.25,-5.78198246510164E-6,-0.00100447488631033,-1.32401589320419E-5,49.9985886,49.9985886,14526.822265625,14581.8017578125,55.6034896010443,19.5543673000356,8.482265,0,0,0,40,4961,50.1213,14554.3120117188,,,,,,,,,,,,,0,,,,0,,,,,,49.9985886,,,,
,20393739.835,49.9996414,18467.35546875,0.000281423811814891,1.00742304857304E-6,1,0.999253354069792,40.0298881530762,1.98333011810349,24.1400003433228,0.00315440528751988,0.000595509655947509,0.25,2.33380431296675E-6,0.00028151479673321,4.419348085812E-6,49.9996414,49.9996414,18435.009765625,18499.701171875,55.0594761516597,19.5610930036057,8.102614,0,0,0,40,4961,50.1217,18467.35546875,,,,,,,,,,,,,0,,,,-0.0049,,,,,,49.9996414,,,,
,20393818.095,50.0002708,22380.1943359375,0.00158476936520436,8.96766539660951E-7,1,0.999253354069792,40.0298881530762,1.98319332898762,24.1400003433228,0.0177669479488949,0.00334805853849835,0.25,1.2656429550241E-5,0.00158562410997937,2.43656565069373E-5,50.0002708,50.0002708,22377.818359375,22382.5703125,54.749169629525,19.5614299443191,8.102614,0,0,0,40,4961,50.1176,22380.1943359375,,,,,,,,,,,,,0,,,,0,,,,,,50.0002708,,,,
,20393895.91,50.0015335,26268.0361328125,0.00252583826214079,1.06203418222018E-6,1,0.999253354069792,40.0298881530762,1.98310477198244,24.1400003433228,0.0283262751894101,0.00531426073376413,0.25,1.82162790357823E-5,0.00252775424920457,3.68058686984478E-5,50.0014763,50.0015907,26240.654296875,26295.41796875,55.036808924602,19.5672206375264,8.102614,0,0,0,40,4961,50.1185,26268.0361328125,,,,,,,,,,,,,0,,,,-0.00245,,,,,,50.0015335,,,,
,20393973.5,50.00182725,30146.3955078125,0.00306400710839814,9.42324289084016E-7,1,0.999253354069792,40.0298881530762,1.98332111280973,24.1400003433228,0.0343746951765799,0.0064359420774929,0.25,2.10870734789811E-5,0.00306698323614864,4.35318364333858E-5,50.0018044,50.0018501,30113.736328125,30179.0546875,54.728847288025,19.5603813976885,8.102614,0,0,0,40,4961,50.11585,30146.3955078125,,,,,,,,,,,,,0,,,,0,,,,,,50.00182725,,,,
,20394050.48,50.0001526,33994.75,0.00334018927784147,1.29238595543114E-6,1,0.999253354069792,40.0298881530762,1.98284636699817,24.1400003433228,0.0374706484441515,0.0070251294199993,0.25,2.3951257952608E-5,0.00334411768448971,4.82876653421809E-5,50.0001526,50.0001526,33967.265625,34022.234375,54.6139478956981,19.5639139469269,7.722963,0,0,0,40,4961,50.11715,33994.75,,,,,,,,,,,,,0,,,,0,,,,,,50.0001526,,,,
,20394125.945,50.0013008,37765.029296875,0.00348278463861103,1.17182851222654E-6,1,0.999253354069792,40.0298881530762,1.98322601293573,24.1400003433228,0.0390859886111513,0.00732312682045157,0.25,2.4717510781073E-5,0.00348757056112842,4.99407114243178E-5,50.0013008,50.0013008,37740.296875,37789.76171875,54.975841900102,19.5666993519236,8.102614,0,0,0,40,4961,50.11135,37765.029296875,,,,,,,,,,,,,0,,,,-0.00245,,,,,,50.0013008,,,,
,20394205.435,50.00162505,41740.26171875,0.00355902077702084,1.39985334168057E-6,1,0.999253354069792,40.0298881530762,1.98307708808936,24.1400003433228,0.0399461777785961,0.00748840124648505,0.25,2.5805850557532E-5,0.00356464067021055,5.13987080017077E-5,50.001503,50.0017471,41712.79296875,41767.73046875,55.2306527973712,19.5655255811108,8.102614,0,0,0,40,4961,50.115,41740.26171875,,,,,,,,,,,,,0,,,,-0.00245,,,,,,50.00162505,,,,
,20394283.565,50.0023918,45643.958984375,0.00359471686588574,1.15452729697403E-6,1,0.999253354069792,40.0298881530762,1.98328470435245,24.1400003433228,0.040360367748505,0.00755670686991579,0.25,2.54679381659258E-5,0.00360110188158748,5.1119241576576E-5,50.0023918,50.0023918,45621.55859375,45666.359375,55.5558102613713,19.5666778375156,8.102614,0,0,0,40,4961,50.11235,45643.958984375,,,,,,,,,,,,,0,,,,0,,,,,,50.0023918,,,,
,20394362.5,50.0008774,49589.36328125,0.00361193429773739,1.3859033643808E-6,1,0.999253354069792,40.0298881530762,1.98331706927838,24.1400003433228,0.0405627320505181,0.00759107439059599,0.25,2.5512573451573E-5,0.00361904863352636,5.10704025263019E-5,50.0008774,50.0008774,49559.14453125,49619.58203125,55.0758903505635,19.5625006350351,8.102614,0,0,0,40,4961,50.11265,49589.36328125,,,,,,,,,,,,,0,,,,-0.0049,,,,,,50.0008774,,,,
,20394439.58,50.0015907,53439.44140625,0.00361479072081266,1.37451644403423E-6,1,0.999253354069792,40.0298881530762,1.98326665524009,24.1400003433228,0.040601783935982,0.00759520072835094,0.25,2.54924554328623E-5,0.00362257338715369,5.08457870865846E-5,50.0015907,50.0015907,53407.0234375,53471.859375,54.556107385275,19.5692005453979,8.102614,0,0,0,40,4961,50.1139,53439.44140625,,,,,,,,,,,,,0,,,,0,,,,,,50.0015907,,,,
,20394515.26,50.00095175,57222.189453125,0.00360641510371262,1.64480196018692E-6,1,0.999253354069792,40.0298881530762,1.98300137969788,24.1400003433228,0.0405166658337216,0.00753832069415864,0.25,2.21491427347048E-5,0.00361482995354824,4.72052097604914E-5,50.0006866,50.0012169,57194.5,57249.87890625,54.3810225969673,19.5630423929777,8.102614,0,0,0,40,4961,50.11175,57222.189453125,,,,,,,,,,,,,0,,,,0,,,,,,50.00095175,,,,
,20394593.835,50.0021362,61150.466796875,0.00359514422506853,1.25757578286187E-6,1,0.999253354069792,40.0298881530762,1.98304831398178,24.1400003433228,0.0403968712222639,0.00752243486259822,0.25,2.28882159499044E-5,0.00360415609708886,4.761801532496E-5,50.0021362,50.0021362,61118.0234375,61182.91015625,55.3291379907943,19.5702824790671,8.102614,0,0,0,40,4961,50.1105,61150.466796875,,,,,,,,,,,,,0,,,,0,,,,,,50.0021362,,,,
,20394674.335,50.0022697,65176.599609375,0.00357963928685153,1.47463814959325E-6,1,0.999253354069792,40.0298881530762,1.98312706892332,24.1400003433228,0.0402273230287394,0.00751260846749024,0.25,2.49315674013089E-5,0.0035892174523967,4.92960084755302E-5,50.0022697,50.0022697,65171.41796875,65181.78125,55.2494118818328,19.5699378149798,8.102614,0,0,0,40,4961,50.10955,65176.599609375,,,,,,,,,,,,,0,,,,0.0049,,,,,,50.0022697,,,,
,20394752.97,50.0029755,69104.59375,0.00355524898748063,2.32560883212065E-6,1,0.999253354069792,40.0298881530762,1.98292195473595,24.1400003433228,0.0399609593509372,0.00743291449867213,0.25,2.24578186563035E-5,0.00356535711220676,4.63854171368275E-5,50.0029755,50.0029755,69074.6484375,69134.5390625,54.9836581852943,19.5785922759555,8.102614,0,0,0,40,4961,50.11025,69104.59375,,,,,,,,,,,,,0,,,,-0.00245,,,,,,50.0029755,,,,
,20394829.735,50.0039864,72939.87890625,0.0035305339801296,1.91916956582983E-6,1,0.999253354069792,40.0298881530762,1.98326301507877,24.1400003433228,0.0396945418292113,0.00739003370177992,0.25,2.31428804233975E-5,0.00354110479494667,4.66454480100359E-5,50.0039864,50.0039864,72907.7109375,72972.046875,54.5615787849096,19.5784854437537,8.102614,0,0,0,40,4961,50.10475,72939.87890625,,,,,,,,,,,,,0,,,,0.00245,,,,,,50.0039864,,,,
,20394908.225,50.0026722,76863.875,0.00350385956886259,2.15622697229846E-6,1,0.999253354069792,40.0298881530762,1.98299021795607,24.1400003433228,0.0393928856218211,0.00734825173529845,0.25,2.44821949780165E-5,0.00351487071809783,4.75399450917575E-5,50.002594,50.0027504,76831.4375,76896.3125,54.9813132997366,19.5604373989598,8.102614,0,0,0,40,4961,50.1066,76863.875,,,,,,,,,,,,,0,,,,0,,,,,,50.0026722,,,,
,20394986.68,50.0024757,80787.84765625,0.00347054807954887,1.60616754099941E-6,1,0.999253354069792,40.0298881530762,1.9828044010952,24.1400003433228,0.0390221755173309,0.00726945700635953,0.25,2.36990125395759E-5,0.00348196156880052,4.62631027473573E-5,50.0024757,50.0024757,80755.6171875,80820.078125,54.9359788456212,19.5700882192723,8.102614,0,0,0,40,4961,50.105,80787.84765625,,,,,,,,,,,,,0,,,,-0.00245,,,,,,50.0024757,,,,
,20395062.955,50.0033379,84598.328125,0.00343661947035756,1.80542205642997E-6,1,0.999253354069792,40.0298881530762,1.98311577884317,24.150000885129,0.0386548862752445,0.00718254585695382,0.25,2.21488920869771E-5,0.00344839505398837,4.42226600934105E-5,50.0031586,50.0035172,84568.328125,84628.328125,54.6248906949673,19.5619958013761,8.102614,0,0,0,40,4961,50.10305,84598.328125,,,,,,,,,,,,,0,,,,-0.00245,,,,,,50.0033379,,,,
,20395137.3,50.0016022,88316.73046875,0.00339798511098276,1.91342430178039E-6,1,0.999253354069792,40.0298881530762,1.98311945644323,24.1400003433228,0.0382256191652977,0.00710054035740512,0.25,2.19705158870394E-5,0.00341006072415156,4.35376501072574E-5,50.0016022,50.0016022,88286.7265625,88346.734375,54.6655353779673,19.5697509907244,8.102614,0,0,0,40,4961,50.10405,88316.73046875,,,,,,,,,,,,,0,,,,0,,,,,,50.0016022,,,,
,20395171.185,50.0034256,89995.99609375,0.00338579797313145,2.12957984808491E-6,1,0.999253354069792,40.0298881530762,1.98311193090383,24.1400003433228,0.0380755012060428,0.00715913913960093,0.25,2.94414194498293E-5,0.00339797129476881,5.08423222646575E-5,50.0034256,50.0034256,89992.59375,89999.3984375,55.1009024631789,19.563873858881,8.102614,0,0,0,40,4929,50.10235,89995.99609375,,,,,,,,,,,,,0,,,,0.00245,,,,,,50.0034256,,,,