File: defense/images/np_vsm/data_dispersion/AH11_HYST_INIT_300K.DAT
[Header]
; VSM Data File (default extension .dat)
; Copyright (c) 2003-2013, Quantum Design, Inc. All rights reserved.
TITLE,
FILEOPENTIME,20327486.64,08/24/2018,3:30 pm
BYAPP,VSM,2.0,2.0
INFO,PPMS VSM Option Release 1.4.10 Build 1,APPNAME
INFO,Quantum Design Linear Motor Servo Controller,MOTOR_MODULE_NAME
INFO,3101-100 M1,MOTOR_HW_VERSION
INFO,MMC1014,MOTOR_SERIAL_NUMBER
INFO,SRV No X-over 01.03.11,MOTOR_SOFTWARE_VERSION
INFO,Quantum Design VSM Detection Module,VSM_MODULE_NAME
INFO,3101-150 F0,VSM_HW_VERSION
INFO,VSM707,VSM_SERIAL_NUMBER
INFO,VSM No X-over 01.02.05 May 20 2008 13:51:47,VSM_SOFTWARE_VERSION
INFO,704,PREAMP_SERIAL_NUMBER
INFO,822,COIL_SERIAL_NUMBER
INFO,0,MOMENT_UNITS
INFO,CoFe2O4,SAMPLE_MATERIAL
INFO,Cobalt deficient,SAMPLE_COMMENT
INFO,,SAMPLE_MASS
INFO,27,SAMPLE_VOLUME
INFO,,SAMPLE_MOLECULAR_WEIGHT
INFO,,SAMPLE_SIZE
INFO,,SAMPLE_SHAPE
DATATYPE,COMMENT,1
DATATYPE,TIME,2
STARTUPAXIS,X,2
STARTUPAXIS,Y1,5
[Data]
Comment,Time Stamp (sec),Temperature (K),Magnetic Field (Oe),Moment (emu),M. Std. Err. (emu),Transport Action,Averaging Time (sec),Frequency (Hz),Peak Amplitude (mm),Center Position (mm),Coil Signal' (mV),Coil Signal" (mV),Range (mV),M. Quad. Signal (emu),M. Raw' (emu),M. Raw" (emu),Min. Temperature (K),Max. Temperature (K),Min. Field (Oe),Max. Field (Oe),Mass (grams),Motor Lag (deg),Pressure (Torr),VSM Status (code),Motor Status (code),Measure Status (code),Measure Count,PPMS Status (code),System Temp. (K),System Field (Oe),Sample Position (deg),Bridge 1 Resistance (ohms),Bridge 1 Excitation (에),Bridge 2 Resistance (ohms),Bridge 2 Excitation (에),Bridge 3 Resistance (ohms),Bridge 3 Excitation (에),Bridge 4 Resistance (ohms),Bridge 4 Excitation (에),Signal 1 Vin (V),Signal 2 Vin (V),Digital Inputs (code),Drive 1 Iout (mA),Drive 1 Ipower (W),Drive 2 Iout (mA),Drive 2 Ipower (W),Pressure (),Map 20 (),Map 21 (),Map 22 (),Map 23 (),Map 24 (),Map 25 (),Map 26 (),Map 27 (),Map 28 (),Map 29 ()
,20327501.94,300.0588379,-0.137013956904411,,,2,,,,24.1400007599592,,,,,,,300.0588379,300.0588379,-0.137013956904411,-0.137013956904411,,,8.102614,,,,-99999999,4881,300.7981,-0.137013956904411,,,,,,,,,,,,,,,,,,,,,,,300.0588379,,,,
,20327630.305,300.0498962,3639.41552734375,0.00185077626305675,3.54308668160694E-5,1,0.999253354069792,40.0298881530762,1.98415310309237,24.1199992597103,0.0182251676342856,0.0184632540208114,0.25,0.00132221416555545,0.00184984288805468,0.00132339743850991,300.0498962,300.0498962,3606.80712890625,3672.02392578125,53.8885966298519,19.5186813155963,7.722963,0,0,0,40,4961,300.73285,3639.41552734375,,,,,,,,,,,,,0,,,,0,,,,,,300.0498962,,,,
,20327705.3,300.0334167,7382.56640625,0.00193893422965751,3.60053765436907E-5,1,0.999253354069792,40.0298881530762,1.98417991999084,24.1299998015165,0.0191179954501432,0.0192018850504757,0.25,0.00137264156701631,0.00193796638675279,0.00137388178255564,300.0334167,300.0334167,7352.59375,7412.5390625,54.3661716551019,19.5259232144029,7.722963,0,0,0,40,4961,300.72045,7382.56640625,,,,,,,,,,,,,0,,,,0.00245,,,,,,300.0334167,,,,
,20327785.07,300.0227661,11371.0541992187,0.00193236353397034,3.68452600900508E-5,1,0.999253354069792,40.0298881530762,1.98438199473656,24.1299998015165,0.0189224533097182,0.0199041504035439,0.25,0.00143609502819721,0.00193135534253418,0.00143732872264533,300.0227661,300.0227661,11341.115234375,11400.9931640625,53.8737456879865,19.5295750070839,8.102614,0,0,0,40,4961,300.71105,11371.0541992187,,,,,,,,,,,,,0,,,,0.00245,,,,,,300.0227661,,,,
,20327865.55,300.0140991,15393.9755859375,0.0019218538266437,3.60301189185085E-5,1,0.999253354069792,40.0298881530762,1.98440391793022,24.1199992597103,0.0187982713923617,0.0199200877715722,0.25,0.00143931532530902,0.00192084517187022,0.00144054159133741,300.0135803,300.0146179,15374.0009765625,15413.9501953125,54.5443829574865,19.5211646567517,7.722963,0,0,0,40,4961,300.70245,15393.9755859375,,,,,,,,,,,,,0,,,,0,,,,,,300.0140991,,,,
,20327945.145,300.0119934,19374.248046875,0.00191279458333821,4.18696670643972E-5,1,0.999253354069792,40.0298881530762,1.98421784522581,24.1299998015165,0.0186577572440797,0.0201143742550444,0.25,0.00145833148406059,0.00191177458836496,0.00145955042392323,300.0117493,300.0122375,19346.72265625,19401.7734375,54.6585007212942,19.5289698715229,7.343312,0,0,0,40,4961,300.69765,19374.248046875,,,,,,,,,,,,,0,,,,-0.00245,,,,,,300.0119934,,,,
,20328024.25,300.0081787,23324.7626953125,0.00187615492211682,3.90892215199851E-5,1,0.999253354069792,40.0298881530762,1.98426045159713,24.1299998015165,0.0182184989654573,0.020204252702982,0.25,0.00147264038008038,0.00187512768122164,0.00147383400940504,300.0080566,300.0083008,23299.734375,23349.791015625,54.2442376061019,19.5257450201348,7.722963,0,0,0,40,4961,300.6945,23324.7626953125,,,,,,,,,,,,,0,,,,0.00245,,,,,,300.0081787,,,,
,20328104.79,300.0074463,27350.4111328125,0.00185049135346093,4.47244056702253E-5,1,0.999253354069792,40.0298881530762,1.98427546189099,24.1199992597103,0.0179123959081266,0.0202572294267995,0.25,0.00148178811798044,0.00184945978573263,0.00148296365442356,300.0074463,300.0074463,27317.828125,27382.994140625,54.7327554306212,19.5270083732198,7.722963,0,0,0,40,4961,300.69145,27350.4111328125,,,,,,,,,,,,,0,,,,0,,,,,,300.0074463,,,,
,20328184.92,300.0056763,31355.9619140625,0.00180525682321135,4.48444407465144E-5,1,0.999253354069792,40.0298881530762,1.98418553245702,24.1199992597103,0.0174488563471417,0.0199051047517396,0.25,0.00145837214107197,0.00180424304720116,0.00145951772341519,300.005127,300.0062256,31325.962890625,31385.9609375,54.7702735995443,19.526400812392,7.722963,0,0,0,40,4961,300.68865,31355.9619140625,,,,,,,,,,,,,0,,,,-0.00245,,,,,,300.0056763,,,,
,20328264.66,300.006012,35338.505859375,0.00174854697864146,4.12816792987982E-5,1,0.999253354069792,40.0298881530762,1.98416222330413,24.1299998015165,0.0167391203808349,0.020211303970014,0.25,0.00149546373893621,0.00174751136527499,0.00149656995318663,300.006012,300.006012,35308.796875,35368.21484375,54.9578644441597,19.5285296524309,7.343312,0,0,0,40,4961,300.68455,35338.505859375,,,,,,,,,,,,,0,,,,0.0049,,,,,,300.006012,,,,
,20328345.015,300.0059509,39356.017578125,0.00172278139638792,3.62197575288941E-5,1,0.999253354069792,40.0298881530762,1.98409721920458,24.1299998015165,0.016454513871195,0.0201289768935368,0.25,0.00149265906212573,0.00172174935024761,0.0014937474873645,300.0059509,300.0059509,39331.1796875,39380.85546875,54.0910384163326,19.5242973845764,8.102614,0,0,0,40,4961,300.68075,39356.017578125,,,,,,,,,,,,,0,,,,-0.00245,,,,,,300.0059509,,,,
,20328424.305,300.00784305,43321.81640625,0.00170395383621626,4.95783734357429E-5,1,0.999253354069792,40.0298881530762,1.98430290155887,24.1299998015165,0.0163517524018878,0.0194755242799884,0.25,0.00143760409198092,0.00170295934285167,0.00143868075368155,300.0077515,300.0079346,43289.40625,43354.2265625,53.9683227388134,19.5287068662507,8.102614,0,0,0,40,4961,300.6754,43321.81640625,,,,,,,,,,,,,0,,,,0.0049,,,,,,300.00784305,,,,
,20328505.25,300.0089111,47365.107421875,0.00160897109274999,4.35997247014397E-5,1,0.999253354069792,40.0298881530762,1.98419543092805,24.1299998015165,0.0152527293470728,0.0194668372351778,0.25,0.00145337763364942,0.00160796994056678,0.00145439050431729,300.0089111,300.0089111,47362.69140625,47367.5234375,54.6756965487173,19.5227676630483,7.343312,0,0,0,40,4961,300.6692,47365.107421875,,,,,,,,,,,,,0,,,,0.0049,,,,,,300.0089111,,,,
,20328586.29,300.0086365,51418.138671875,0.00160524451738325,5.49013178494096E-5,1,0.999253354069792,40.0298881530762,1.98417560019455,24.1299998015165,0.0152117493510602,0.0194534189592687,0.25,0.00145284656791529,0.0016042448090527,0.00145385612671979,300.0086365,300.0086365,51415.91796875,51420.359375,54.5733032126981,19.5256332583657,8.102614,0,0,0,40,4961,300.6617,51418.138671875,,,,,,,,,,,,,0,,,,0.0049,,,,,,300.0086365,,,,
,20328664.11,300.0103607,55305.87109375,0.00154750552577031,5.89839071730886E-5,1,0.999253354069792,40.0298881530762,1.98461189405724,24.1199992597103,0.0145487678077453,0.0194440410679033,0.25,0.00146165297984911,0.00154650259292482,0.00146262350037085,300.0103149,300.0104065,55283.3046875,55328.4375,54.9305074459866,19.5257200106669,7.343312,0,0,0,40,4961,300.6542,55305.87109375,,,,,,,,,,,,,0,,,,0.0049,,,,,,300.0103607,,,,
,20328744.045,300.01101685,59301.16796875,0.00149648367386979,4.56530693523767E-5,1,0.999253354069792,40.0298881530762,1.9843697068047,24.1299998015165,0.0140243669349187,0.0190495034251633,0.25,0.00143559241849397,0.00149550023759018,0.00143652941731541,300.0109558,300.0110779,59266.18359375,59336.15234375,54.6561558357366,19.5217467620022,7.722963,0,0,0,40,4961,300.64545,59301.16796875,,,,,,,,,,,,,0,,,,0,,,,,,300.01101685,,,,
,20328824.085,300.0109711,63302.763671875,0.00145889254712883,5.02151249456978E-5,1,0.999253354069792,40.0298881530762,1.98446090455952,24.1199992597103,0.013641823519503,0.0187499709094683,0.25,0.00141538274312954,0.00145792441445913,0.00141629490330412,300.0105591,300.0113831,63280.27734375,63325.25,55.2791137655635,19.5215618248063,7.722963,0,0,0,40,4961,300.6398,63302.763671875,,,,,,,,,,,,,0,,,,-0.00245,,,,,,300.0109711,,,,
,20328904.075,300.0102844,67300.375,0.00142021254172809,5.40733642235268E-5,1,0.999253354069792,40.0298881530762,1.98455200424221,24.1299998015165,0.0132406943821981,0.0184847229780085,0.25,0.00139841413825746,0.00141925763164623,0.00139930072988042,300.0102844,300.0102844,67268.0390625,67332.7109375,54.6835128339096,19.5218014927909,7.722963,0,0,0,40,4961,300.6319,67300.375,,,,,,,,,,,,,0,,,,0,,,,,,300.0102844,,,,
,20328983.715,300.01361085,71278.265625,0.00134570258136784,4.90727022040668E-5,1,0.999253354069792,40.0298881530762,1.98444769744571,24.1199992597103,0.012379956434704,0.0184690909088561,0.25,0.0014100155543579,0.00134474307627165,0.00141085220820323,300.0133057,300.013916,71250.7421875,71305.7890625,54.2254785216404,19.5255843875622,8.102614,0,0,0,40,4961,300.62235,71278.265625,,,,,,,,,,,,,0,,,,0,,,,,,300.01361085,,,,
,20329064.055,300.0138245,75296.44140625,0.00128117837491943,5.7650651862556E-5,1,0.999253354069792,40.0298881530762,1.98460221702606,24.1199992597103,0.0117015434097662,0.0180795142234529,0.25,0.0013864154208063,0.00128023711357553,0.00138720991392479,300.0138245,300.0138245,75274.1015625,75318.78125,54.2536171483327,19.5187424572885,7.722963,0,0,0,40,4961,300.6128,75296.44140625,,,,,,,,,,,,,0,,,,0,,,,,,300.0138245,,,,
,20329144.225,300.01301575,79304.44921875,0.00124229192599431,6.27982841470067E-5,1,0.999253354069792,40.0298881530762,1.98488116893497,24.1199992597103,0.0112557691605923,0.0180649719973318,0.25,0.0013916434976906,0.00124134940243232,0.00139241180744952,300.0130005,300.013031,79271.859375,79337.0390625,54.7960673406789,19.5242779428591,7.722963,0,0,0,40,4961,300.6037,79304.44921875,,,,,,,,,,,,,0,,,,0.00245,,,,,,300.01301575,,,,
,20329225.355,300.0127563,83358.40234375,0.00121598991825339,6.16688510522647E-5,1,0.999253354069792,40.0298881530762,1.9848315308608,24.1199992597103,0.0109933883693691,0.0178195662207248,0.25,0.00137440996876324,0.00121506036733597,0.0013751609504632,300.0127563,300.0127563,83355.7265625,83361.078125,54.5537624997173,19.5239335010935,7.722963,0,0,0,40,4961,300.59285,83358.40234375,,,,,,,,,,,,,0,,,,0.0049,,,,,,300.0127563,,,,
,20329302.5,300.0149536,87214.3984375,0.00115341413231157,5.58940899012132E-5,1,0.999253354069792,40.0298881530762,1.98483030125537,24.1299998015165,0.0103684890017813,0.0172441080752341,0.25,0.00133406470642853,0.00115251346139088,0.00133477540138153,300.0148315,300.0150757,87189.46875,87239.328125,54.2497090057365,19.5240702255753,8.102614,0,0,0,40,4961,300.5823,87214.3984375,,,,,,,,,,,,,0,,,,-0.00245,,,,,,300.0149536,,,,
,20329394.32,300.0153503,88952.59765625,0.0010907887474563,8.81435960040258E-5,1,0.999253354069792,40.0298881530762,1.98505077354649,24.1199992597103,0.0096389021236646,0.017277358458577,0.25,0.00134770915737927,0.00108988141429213,0.00134837846911307,300.0153503,300.0153503,88927.5859375,88977.609375,54.484979190025,19.5245244008933,8.102614,0,0,0,40,4961,300.57295,88952.59765625,,,,,,,,,,,,,0,,,,0,,,,,,300.0153503,,,,
,20329470.13,300.0104065,85161.9375,0.00115029409956072,7.27349419008135E-5,1,0.999253354069792,40.0298881530762,1.9853518359001,24.1299998015165,0.0103309205129712,0.0172716919562553,0.25,0.00133667281378974,0.00114939145316813,0.00133738202471054,300.0101624,300.0106506,85129.46875,85194.40625,54.5451645860058,19.5245169320629,7.722963,0,0,0,40,4961,300.56625,85161.9375,,,,,,,,,,,,,0,,,,-0.00245,,,,,,300.0104065,,,,
,20329549.16,300.0041504,81210.359375,0.00120384951802703,6.51170438185278E-5,1,0.999253354069792,40.0298881530762,1.98524987866302,24.1199992597103,0.0108284979234422,0.0179760711798943,0.25,0.00139011189984066,0.00120290984412101,0.00139085541402254,300.0041504,300.0041504,81210.359375,81210.359375,54.312239287275,19.5282215268948,8.102614,0,0,0,40,4961,300.56835,81210.359375,,,,,,,,,,,,,0,,,,-0.0049,,,,,,300.0041504,,,,
,20329629.845,299.9979706,77179.078125,0.00124705809002478,5.85322246593031E-5,1,0.999253354069792,40.0298881530762,1.98517696225173,24.1299998015165,0.0113252146149223,0.0179945608106729,0.25,0.00138432569168609,0.00124612020675513,0.00138509856352357,299.997345,299.9985962,77151.6015625,77206.5546875,54.586590897525,19.529822181212,7.722963,0,0,0,40,4961,300.5697,77179.078125,,,,,,,,,,,,,0,,,,0,,,,,,299.9979706,,,,
,20329709.535,299.9944458,73192.73828125,0.00131438795108419,5.45940460717127E-5,1,0.999253354069792,40.0298881530762,1.98523598981541,24.1199992597103,0.0121054834919178,0.0179941638298745,0.25,0.0013725793671335,0.00131345498551809,0.00137339740115605,299.9944458,299.9944458,73167.8671875,73217.609375,54.7882510554866,19.5301378400163,7.722963,0,0,0,40,4961,300.57425,73192.73828125,,,,,,,,,,,,,0,,,,0.00245,,,,,,299.9944458,,,,
,20329789.22,299.99220275,69209.18359375,0.0013528451165689,5.31355951002425E-5,1,0.999253354069792,40.0298881530762,1.98515790410862,24.1199992597103,0.0124744535206874,0.0184318798352164,0.25,0.00140490545302703,0.00135188910749083,0.00140574853654985,299.9915466,299.9928589,69179.265625,69239.1015625,54.6545925786981,19.5280860999397,7.722963,0,0,0,40,4961,300.5835,69209.18359375,,,,,,,,,,,,,0,,,,-0.00245,,,,,,299.99220275,,,,
,20329869.565,299.9922485,65193.462890625,0.00141470191546134,4.76443222319945E-5,1,0.999253354069792,40.0298881530762,1.98527836068779,24.1199992597103,0.0131814887777436,0.0184912605658038,0.25,0.00139937401191755,0.00141374676033406,0.00140025847222454,299.9922485,299.9922485,65191,65195.92578125,54.6874209765058,19.5281307575989,7.343312,0,0,0,40,4961,300.5872,65193.462890625,,,,,,,,,,,,,0,,,,-0.0049,,,,,,299.9922485,,,,
,20329947.8,299.99058535,61284.783203125,0.00145369990019465,5.33582339157442E-5,1,0.999253354069792,40.0298881530762,1.98523194043102,24.1199992597103,0.0135799124922052,0.0187964007687761,0.25,0.00141979103261958,0.00145272942269505,0.0014207012913622,299.9900818,299.9910889,61257.265625,61312.30078125,54.8562527366597,19.5315372979166,8.102614,0,0,0,40,4961,300.59505,61284.783203125,,,,,,,,,,,,,0,,,,-0.0049,,,,,,299.99058535,,,,
,20330027.27,299.9912109,57311.654296875,0.00151015769126861,5.00071482768772E-5,1,0.999253354069792,40.0298881530762,1.98527065710777,24.1299998015165,0.0141933479570047,0.019031662116079,0.25,0.00143090032328106,0.00150917732606975,0.00143184801922881,299.9912109,299.9912109,57289.1953125,57334.11328125,54.9195646467173,19.5313015422652,7.343312,0,0,0,40,4961,300.60155,57311.654296875,,,,,,,,,,,,,0,,,,-0.00245,,,,,,299.9912109,,,,
,20330107.29,299.9921875,53311.287109375,0.00158413156213777,4.39554300742684E-5,1,0.999253354069792,40.0298881530762,1.98510048438116,24.1199992597103,0.01501735010497,0.0192120188579688,0.25,0.001434263100285,0.00158314583205457,0.0014352599931756,299.9921875,299.9921875,53276.46875,53346.10546875,54.7265024024673,19.5379141794995,8.102614,0,0,0,40,4961,300.60505,53311.287109375,,,,,,,,,,,,,0,,,,-0.00245,,,,,,299.9921875,,,,
,20330186.54,299.9912415,49353.603515625,0.00162030352211735,4.58806622232659E-5,1,0.999253354069792,40.0298881530762,1.98500747405774,24.1199992597103,0.0154493471498009,0.0191315649373554,0.25,0.00142091603282799,0.00161932460726186,0.00142193796780336,299.9912415,299.9912415,49328.78515625,49378.421875,54.4365182218327,19.540153907124,7.343312,0,0,0,40,4961,300.6102,49353.603515625,,,,,,,,,,,,,0,,,,-0.0049,,,,,,299.9912415,,,,
,20330267.445,299.99194335,45307.99609375,0.00166808826179323,4.05171621741503E-5,1,0.999253354069792,40.0298881530762,1.98498472576478,24.1299998015165,0.0159835416893133,0.0192409661331702,0.25,0.00142238579644142,0.00166710600910287,0.00142343993498956,299.9914856,299.9924011,45280.38671875,45335.60546875,54.830458995525,19.5391473636168,7.722963,0,0,0,40,4961,300.61605,45307.99609375,,,,,,,,,,,,,0,,,,0,,,,,,299.99194335,,,,
,20330347.61,299.99247745,41299.685546875,0.00168916495392346,4.29070485335561E-5,1,0.999253354069792,40.0298881530762,1.98475188512238,24.1299998015165,0.0161338400587754,0.0197695259047041,0.25,0.00146594324916149,0.00168815250283097,0.00146701085894732,299.9924622,299.9924927,41267.05078125,41332.3203125,54.7890326840058,19.5393765112972,8.482265,0,0,0,40,4961,300.62185,41299.685546875,,,,,,,,,,,,,0,,,,0.0049,,,,,,299.99247745,,,,
,20330426.72,299.9924927,37349.146484375,0.00170867200591894,4.67035716959639E-5,1,0.999253354069792,40.0298881530762,1.98469052643813,24.1199992597103,0.0164026870131344,0.0195180568861738,0.25,0.00144024469785343,0.00170767497068759,0.00144132677216188,299.9924927,299.9924927,37319.125,37379.16796875,54.6076948675442,19.5412175380871,8.102614,0,0,0,40,4961,300.6286,37349.146484375,,,,,,,,,,,,,0,,,,-0.00245,,,,,,299.9924927,,,,
,20330507.79,299.9925232,33294.2578125,0.00176575980976929,4.70299689425087E-5,1,0.999253354069792,40.0298881530762,1.98470270990808,24.1199992597103,0.0170377093642384,0.0196686541329792,0.25,0.00144373970764204,0.00176475787488951,0.00144486019018955,299.9925232,299.9925232,33291.55078125,33296.96484375,54.7280656595058,19.5358287893238,7.722963,0,0,0,40,4961,300.63005,33294.2578125,,,,,,,,,,,,,0,,,,-0.0049,,,,,,299.9925232,,,,
,20330587.735,299.9934387,29301.45703125,0.00179178590734599,3.7197510329536E-5,1,0.999253354069792,40.0298881530762,1.98463698782852,24.1199992597103,0.0173413016728859,0.0196518680742127,0.25,0.00143779190561263,0.00179078618226715,0.00143893057428629,299.9928894,299.993988,29273.9921875,29328.921875,54.5920622971596,19.5380868965978,8.482265,0,0,0,40,4961,300.63465,29301.45703125,,,,,,,,,,,,,0,,,,0,,,,,,299.9934387,,,,
,20330666.585,299.994339,25358.236328125,0.00178727297021842,4.02819427560948E-5,1,0.999253354069792,40.0298881530762,1.9844599354816,24.1199992597103,0.017249794534785,0.0198681967751554,0.25,0.00145796832272628,0.00178625915079724,0.0014591042757392,299.9941406,299.9945374,25325.603515625,25390.869140625,54.7116514606019,19.5330258841941,8.102614,0,0,0,40,4961,300.63745,25358.236328125,,,,,,,,,,,,,0,,,,-0.00245,,,,,,299.994339,,,,
,20330746.64,299.9938049,21357.71875,0.00184350605376627,3.17768359273891E-5,1,0.999253354069792,40.0298881530762,1.9842758869164,24.1199992597103,0.017977291610695,0.0194159126004028,0.25,0.00140813926177564,0.00184252265508647,0.0014093146891495,299.9936218,299.993988,21332.8984375,21382.5390625,54.6405232653519,19.5292775423138,8.102614,0,0,0,40,4961,300.64215,21357.71875,,,,,,,,,,,,,0,,,,0,,,,,,299.9938049,,,,
,20330825.49,299.9951477,17414.716796875,0.00183375294095065,4.38606432525909E-5,1,0.999253354069792,40.0298881530762,1.98426117090846,24.1199992597103,0.0178752244052905,0.0193524246129114,0.25,0.0014041917322784,0.00183277154626252,0.00140536164022043,299.9951172,299.9951782,17384.833984375,17444.599609375,54.5326585296981,19.5312818138606,7.722963,0,0,0,40,4961,300.64335,17414.716796875,,,,,,,,,,,,,0,,,,-0.00245,,,,,,299.9951477,,,,
,20330904.175,299.9951935,13485.2583007813,0.00185905327493078,3.67835433414762E-5,1,0.999253354069792,40.0298881530762,1.98425162938075,24.1199992597103,0.0182037123420595,0.0191463155904238,0.25,0.00138147663153305,0.00185808539679989,0.00138266474506638,299.9945984,299.9957886,13452.4560546875,13518.060546875,54.657719092775,19.5271172984207,7.343312,0,0,0,40,4961,300.6475,13485.2583007813,,,,,,,,,,,,,0,,,,0,,,,,,299.9951935,,,,
,20330984.04,299.9958496,9492.158203125,0.00187577724414308,4.53163203922456E-5,1,0.999253354069792,40.0298881530762,1.98397529304004,24.1299998015165,0.0184323192149871,0.0189275510349431,0.25,0.00135933760384236,0.00187482275903112,0.00136053819925383,299.9953003,299.9963989,9459.7841796875,9524.5322265625,54.1402810130442,19.5335767155682,8.102614,0,0,0,40,4961,300.6505,9492.158203125,,,,,,,,,,,,,0,,,,-0.00245,,,,,,299.9958496,,,,
,20331061.51,299.9979553,5618.7421875,0.00182434427562798,3.34970925306554E-5,1,0.999253354069792,40.0298881530762,1.98387415741335,24.1199992597103,0.0179713942724529,0.0181458485928531,0.25,0.00129876453727494,0.00182343062415158,0.00129993351668816,299.9979553,299.9979553,5586.35693359375,5651.12744140625,54.2700313472365,19.5310274743287,8.102614,0,0,0,40,4961,300.65035,5618.7421875,,,,,,,,,,,,,0,,,,0,,,,,,299.9979553,,,,
,20331138.56,299.9963684,1767.42095947266,0.00169394518373888,3.19297329522456E-5,1,0.999253354069792,40.0298881530762,1.98371086917245,24.1199992597103,0.0167423654864461,0.016519482989301,0.25,0.00117673768982197,0.00169311578520177,0.00117782460952811,299.9963684,299.9963684,1737.55932617187,1797.28259277344,54.7061800609673,19.5359812533042,7.722963,0,0,0,40,4961,300.6517,1767.42095947266,,,,,,,,,,,,,0,,,,0.0049,,,,,,299.9963684,,,,
,20331214.15,299.99798585,-2006.74877929687,-0.00170165521414946,3.37327553705781E-5,1,0.999253354069792,40.0298881530762,1.98375395086719,24.1299998015165,-0.016788055040003,-0.0167731422134005,0.25,-0.0011979466021738,-0.00170081148115852,-0.00119903788586653,299.9969177,299.999054,-2036.81311035156,-1976.68444824219,54.6874209765058,19.5328673227141,8.102614,0,0,0,40,4961,300.6548,-2006.74877929687,,,,,,,,,,,,,0,,,,0.00245,,,,,,299.99798585,,,,
,20331291.98,300.0000305,-5895.46069335938,-0.00184259108043178,3.64910592180455E-5,1,0.999253354069792,40.0298881530762,1.98363636674899,24.1199992597103,-0.0181619347455579,-0.0182509438147211,0.25,-0.00130514198803496,-0.00184167257502077,-0.00130632270520418,300.0000305,300.0000305,-5920.43994140625,-5870.4814453125,54.8851729918712,19.5319239458868,7.722963,0,0,0,40,4961,300.6512,-5895.46069335938,,,,,,,,,,,,,0,,,,0.00245,,,,,,300.0000305,,,,
,20331369.885,300.0045929,-9789.56689453125,-0.00184955591365308,3.59564397287577E-5,1,0.999253354069792,40.0298881530762,1.98368082412863,24.1199992597103,-0.0182030688933387,-0.0184814136172973,0.25,-0.00132441340785967,-0.00184862475961017,-0.00132559723032302,300.0041809,300.0050049,-9819.3837890625,-9759.75,54.9039320763327,19.5354506925646,7.722963,0,0,0,40,4961,300.6472,-9789.56689453125,,,,,,,,,,,,,0,,,,0,,,,,,300.0045929,,,,
,20331447.61,300.0074463,-13675.5078125,-0.00185702674629514,4.12269041437221E-5,1,0.999253354069792,40.0298881530762,1.98360984156284,24.1199992597103,-0.0181963770431643,-0.0190148595837129,0.25,-0.0013706549159463,-0.00185606528272169,-0.0013718413835381,300.0074463,300.0074463,-13707.8955078125,-13643.1201171875,55.0031988982751,19.5337704341427,8.102614,0,0,0,40,4961,300.64335,-13675.5078125,,,,,,,,,,,,,0,,,,0,,,,,,300.0074463,,,,
,20331528.19,300.0105591,-17702.8447265625,-0.00185446964080758,4.41110353721339E-5,1,0.999253354069792,40.0298881530762,1.98388579041182,24.1199992597103,-0.0180598236124296,-0.0196487090549119,0.25,-0.00142728161439715,-0.00185347137811097,-0.00142846371621857,300.0105591,300.0105591,-17725.22265625,-17680.466796875,54.7249391454289,19.5330763815565,7.722963,0,0,0,40,4961,300.6336,-17702.8447265625,,,,,,,,,,,,,0,,,,0,,,,,,300.0105591,,,,
,20331607.235,300.0103302,-21652.77734375,-0.00183679949671054,4.18249438400124E-5,1,0.999253354069792,40.0298881530762,1.98371027221531,24.1299998015165,-0.0179134940541814,-0.0193025366723739,0.25,-0.00139968234085139,-0.00183582077922139,-0.00140085276596708,300.0099487,300.0107117,-21687.49609375,-21618.05859375,54.2770660039096,19.5335231296804,8.482265,0,0,0,40,4961,300.6253,-21652.77734375,,,,,,,,,,,,,0,,,,0.00245,,,,,,300.0103302,,,,
,20331687.92,300.01223755,-25685.7490234375,-0.00180202622065023,4.13968302988415E-5,1,0.999253354069792,40.0298881530762,1.98364435122206,24.1199992597103,-0.0175075713284654,-0.019318860193084,0.25,-0.00140721526677433,-0.00180104427485646,-0.00140836153646848,300.0119019,300.0125732,-25710.58203125,-25660.916015625,54.7249391454289,19.5340981787102,7.722963,0,0,0,40,4961,300.61855,-25685.7490234375,,,,,,,,,,,,,0,,,,0,,,,,,300.01223755,,,,
,20331767.58,300.0127716,-29666.2353515625,-0.00178486565777814,4.09751327294761E-5,1,0.999253354069792,40.0298881530762,1.98372839742805,24.1299998015165,-0.0172727006950622,-0.0195331006044961,0.25,-0.00142918677371965,-0.00178387054202826,-0.00143032016543528,300.0127563,300.0127869,-29698.7421875,-29633.728515625,54.3794593399288,19.5352663913493,8.482265,0,0,0,40,4961,300.6089,-29666.2353515625,,,,,,,,,,,,,0,,,,0,,,,,,300.0127716,,,,
,20331848.11,300.014328,-33690.88671875,-0.00172772175949779,4.32676813442935E-5,1,0.999253354069792,40.0298881530762,1.98374582503745,24.1199992597103,-0.0166450529702181,-0.0193396102145712,0.25,-0.0014218532108138,-0.0017267339509637,-0.00142294821175981,300.013916,300.01474,-33721.12109375,-33660.65234375,54.4458977640635,19.5370350567314,8.102614,0,0,0,40,4961,300.59845,-33690.88671875,,,,,,,,,,,,,0,,,,0.00245,,,,,,300.014328,,,,
,20331928.305,300.0132141,-37698.50390625,-0.0017066226769855,3.84730115072482E-5,1,0.999253354069792,40.0298881530762,1.98384424523704,24.1199992597103,-0.0164002186343367,-0.0193487982994288,0.25,-0.00142624550634237,-0.00170563356035643,-0.00142732565686204,300.0132141,300.0132141,-37728.5,-37668.5078125,54.7522961436019,19.5388065340006,8.102614,0,0,0,40,4961,300.58895,-37698.50390625,,,,,,,,,,,,,0,,,,-0.00245,,,,,,300.0132141,,,,
,20332008.77,300.0150604,-41718.802734375,-0.0016615334825094,4.93382673730698E-5,1,0.999253354069792,40.0298881530762,1.98375531462686,24.1199992597103,-0.0159398764798456,-0.0189890062056921,0.25,-0.00140211130099154,-0.00166056236007458,-0.00140316154127989,300.0145874,300.0155334,-41746.37890625,-41691.2265625,54.972715386025,19.5368190640043,8.102614,0,0,0,40,4961,300.57795,-41718.802734375,,,,,,,,,,,,,0,,,,0,,,,,,300.0150604,,,,
,20332089.78,300.0146179,-45766.9609375,-0.00159044037354573,4.48575169064454E-5,1,0.999253354069792,40.0298881530762,1.98376874995808,24.1199992597103,-0.0151575143285447,-0.0187563668740742,0.25,-0.00139371395301727,-0.00158947781548933,-0.00139471688072926,300.0146179,300.0146179,-45769.82421875,-45764.09765625,54.7374452017366,19.5424008226252,8.102614,0,0,0,40,4961,300.5672,-45766.9609375,,,,,,,,,,,,,0,,,,0,,,,,,300.0146179,,,,
,20332169.305,300.014801,-49742.375,-0.00154279542846809,5.68262441624737E-5,1,0.999253354069792,40.0298881530762,1.98370485763199,24.1199992597103,-0.0145979180290924,-0.0188004295543742,0.25,-0.00140594220484417,-0.00154182715376217,-0.00140691264043992,300.014801,300.014801,-49767.19140625,-49717.55859375,54.5013933889288,19.5429042316859,7.722963,0,0,0,40,4961,300.55745,-49742.375,,,,,,,,,,,,,0,,,,-0.00245,,,,,,300.014801,,,,
,20332249.29,300.0157013,-53741.982421875,-0.00149707261598883,4.59230765753798E-5,1,0.999253354069792,40.0298881530762,1.98372936070614,24.1199992597103,-0.0140437728304699,-0.0189458754744362,0.25,-0.00142678927645778,-0.00149609290676204,-0.00142772822900063,300.015564,300.0158386,-53769.41015625,-53714.5546875,54.5639236704673,19.5400498655802,7.722963,0,0,0,40,4961,300.54715,-53741.982421875,,,,,,,,,,,,,0,,,,0,,,,,,300.0157013,,,,
,20332329.57,300.0153656,-57754.677734375,-0.00147760682872004,5.10967048204196E-5,1,0.999253354069792,40.0298881530762,1.98376191990732,24.1199992597103,-0.01388580614872,-0.0185589296785006,0.25,-0.00139569880072234,-0.00147664902361883,-0.00139662511074798,300.0151672,300.015564,-57787.0625,-57722.29296875,54.9602093297174,19.539374519959,8.102614,0,0,0,40,4961,300.5368,-57754.677734375,,,,,,,,,,,,,0,,,,0,,,,,,300.0153656,,,,
,20332410.96,300.0166168,-61819.580078125,-0.00142717160802384,4.11227044333771E-5,1,0.999253354069792,40.0298881530762,1.98367754446003,24.1199992597103,-0.0133940336469119,-0.0180244253657367,0.25,-0.00135693318560277,-0.00142624153781813,-0.00135782674601448,300.0156555,300.0175781,-61849.60546875,-61789.5546875,54.3466309421211,19.5403727757183,8.102614,0,0,0,40,4961,300.52415,-61819.580078125,,,,,,,,,,,,,0,,,,0.00245,,,,,,300.0166168,,,,
,20332491.68,300.0154114,-65854.91015625,-0.0013592437141889,5.98518011562651E-5,1,0.999253354069792,40.0298881530762,1.98381715546398,24.1199992597103,-0.0126324414548947,-0.0178889338405023,0.25,-0.00135653636987795,-0.00135831690192723,-0.00135738478008459,300.0154114,300.0154114,-65877.453125,-65832.3671875,54.8148264251404,19.5414607037967,8.482265,0,0,0,40,4961,300.5142,-65854.91015625,,,,,,,,,,,,,0,,,,-0.00245,,,,,,300.0154114,,,,
,20332572.26,300.0158691,-69880.015625,-0.00130561840346024,6.09429016600946E-5,1,0.999253354069792,40.0298881530762,1.9837727359718,24.1199992597103,-0.0120158499176428,-0.017863693199678,0.25,-0.00136361528511792,-0.00130468946805873,-0.00136442765779285,300.0158691,300.0158691,-69910.0546875,-69849.9765625,54.7616756858327,19.5452261483471,8.102614,0,0,0,40,4961,300.5058,-69880.015625,,,,,,,,,,,,,0,,,,0,,,,,,300.0158691,,,,
,20332651.86,300.01605225,-73859.546875,-0.0012768690793584,4.80244762507128E-5,1,0.999253354069792,40.0298881530762,1.98406426673579,24.1199992597103,-0.0117531519465394,-0.0174714799783918,0.25,-0.00133347266465412,-0.00127596156979659,-0.00133426642021883,300.0159607,300.0161438,-73887.1015625,-73831.9921875,54.8648506503712,19.5585742619787,8.102614,0,0,0,40,4961,300.49295,-73859.546875,,,,,,,,,,,,,0,,,,-0.00245,,,,,,300.01605225,,,,
,20332731.18,300.015625,-77825.13671875,-0.00121307357981943,5.58384709607622E-5,1,0.999253354069792,40.0298881530762,1.98399217325217,24.1299998015165,-0.0110620324699389,-0.0171955456280045,0.25,-0.00132002493529539,-0.00121217764471386,-0.0013207767930076,300.015625,300.015625,-77850.2578125,-77800.015625,54.9789684141789,19.5659579056928,8.102614,0,0,0,40,4961,300.4825,-77825.13671875,,,,,,,,,,,,,0,,,,0,,,,,,300.015625,,,,
,20332811.925,300.0154114,-81857.578125,-0.00119684166173061,4.64822356949406E-5,1,0.999253354069792,40.0298881530762,1.98413958832078,24.1199992597103,-0.010910107442418,-0.0169937379091043,0.25,-0.00130477193792731,-0.00119595706904868,-0.00130551297256304,300.0154114,300.0154114,-81882.578125,-81832.578125,54.7413533443327,19.5714174567732,8.102614,0,0,0,40,4961,300.4713,-81857.578125,,,,,,,,,,,,,0,,,,-0.00245,,,,,,300.0154114,,,,
,20332889.81,300.0167542,-85750.4453125,-0.00111187896392301,6.85713129663203E-5,1,0.999253354069792,40.0298881530762,1.98428669267392,24.1199992597103,-0.00994781403837677,-0.0168766545137919,0.25,-0.00130896749079027,-0.00111099496152076,-0.00130965239294897,300.0167542,300.0167542,-85780.359375,-85720.53125,55.3580582460059,19.573253685872,8.102614,0,0,0,40,4961,300.4598,-85750.4453125,,,,,,,,,,,,,0,,,,-0.00245,,,,,,300.0167542,,,,
,20332967.655,300.01623535,-89640.12890625,-0.00103327566626197,6.40830435021937E-5,1,0.999253354069792,40.0298881530762,1.98408826857565,24.1199992597103,-0.00911894053296569,-0.0164021415113121,0.25,-0.00128050538072698,-0.00103241337522086,-0.00128113942375506,300.0154114,300.0170593,-89667.609375,-89612.6484375,54.678041434275,19.5778431524636,8.102614,0,0,0,40,4961,300.45015,-89640.12890625,,,,,,,,,,,,,0,,,,0,,,,,,300.01623535,,,,
,20333059.915,300.01275635,-86572.2578125,-0.00110867029185439,6.82731828284569E-5,1,0.999253354069792,40.0298881530762,1.98404779416123,24.1199992597103,-0.00992377360669864,-0.0167925121119291,0.25,-0.00130220853701189,-0.00110779106823759,-0.00130289164538983,300.0125122,300.0130005,-86604.6328125,-86539.8828125,55.1306043469097,19.5739912652706,8.482265,0,0,0,40,4961,300.4409,-86572.2578125,,,,,,,,,,,,,0,,,,-0.00245,,,,,,300.01275635,,,,
,20333138.46,300.00645445,-82646.98046875,-0.00113478367023976,6.73419605694301E-5,1,0.999253354069792,40.0298881530762,1.98405827931745,24.1199992597103,-0.0101798568561284,-0.0170594216445532,0.25,-0.00132142690737468,-0.00113389049255028,-0.00132212741933478,300.0061035,300.0068054,-82676.84375,-82617.1171875,54.8773567066789,19.5770312769465,7.722963,0,0,0,40,4961,300.4396,-82646.98046875,,,,,,,,,,,,,0,,,,-0.0049,,,,,,300.00645445,,,,
,20333219.88,300.00019835,-78579.58203125,-0.00121560311865001,6.00720221360629E-5,1,0.999253354069792,40.0298881530762,1.984035081824,24.1199992597103,-0.0110586802613059,-0.0173856209422502,0.25,-0.00133646821770521,-0.00121469710702391,-0.00133722195083662,299.9999695,300.0004272,-78609.5625,-78549.6015625,54.6819495768712,19.5781372972815,7.722963,0,0,0,40,4961,300.44375,-78579.58203125,,,,,,,,,,,,,0,,,,0,,,,,,300.00019835,,,,
,20333298.275,299.9950714,-74661.64453125,-0.00125208508491733,5.45868119916717E-5,1,0.999253354069792,40.0298881530762,1.98382640243448,24.1199992597103,-0.011475090846545,-0.0174110570789721,0.25,-0.0013325660610329,-0.00125117985743862,-0.00133334466538657,299.9948425,299.9953003,-74691.5625,-74631.7265625,54.3247453435827,19.5772606146465,8.102614,0,0,0,40,4961,300.4452,-74661.64453125,,,,,,,,,,,,,0,,,,0.00245,,,,,,299.9950714,,,,
,20333380.27,299.9914856,-70561.6640625,-0.00128631387228382,4.91222729940328E-5,1,0.999253354069792,40.0298881530762,1.98392835982728,24.1199992597103,-0.011839880685691,-0.0175963007660255,0.25,-0.00134304395910885,-0.0012854000405767,-0.00134384552904396,299.9914856,299.9914856,-70589.4375,-70533.890625,54.637396751275,19.574094146434,8.102614,0,0,0,40,4961,300.45485,-70561.6640625,,,,,,,,,,,,,0,,,,-0.00245,,,,,,299.9914856,,,,
,20333461.845,299.9901123,-66486.88671875,-0.00134884568253195,6.24843383654694E-5,1,0.999253354069792,40.0298881530762,1.98385778849005,24.1199992597103,-0.0124975158139845,-0.0179749336267039,0.25,-0.00136595860011488,-0.00134791420521277,-0.00136680120941417,299.9901123,299.9901123,-66512.4921875,-66461.28125,55.2494118818328,19.5819974504409,8.482265,0,0,0,40,4961,300.46345,-66486.88671875,,,,,,,,,,,,,0,,,,0,,,,,,299.9901123,,,,
,20333541.32,299.98934935,-62514.453125,-0.00142620740917786,5.50427605020995E-5,1,0.999253354069792,40.0298881530762,1.98374042591083,24.1199992597103,-0.0133504724131295,-0.0182144276106451,0.25,-0.00137395991614385,-0.00142526758379167,-0.00137485372267844,299.988739,299.9899597,-62539.42578125,-62489.48046875,54.7249391454289,19.5777381129746,8.102614,0,0,0,40,4961,300.46965,-62514.453125,,,,,,,,,,,,,0,,,,0.00245,,,,,,299.98934935,,,,
,20333622.025,299.9890442,-58481.755859375,-0.00143739569753667,4.6385797264657E-5,1,0.999253354069792,40.0298881530762,1.98365925208771,24.1199992597103,-0.013478363448215,-0.0182198237692002,0.25,-0.00137256448444835,-0.00143645552705467,-0.00137346650224225,299.9890442,299.9890442,-58506.6171875,-58456.89453125,55.0383721816404,19.5827564496315,8.482265,0,0,0,40,4961,300.4742,-58481.755859375,,,,,,,,,,,,,0,,,,0,,,,,,299.9890442,,,,
,20333701.2,299.9904175,-54523.98828125,-0.00149232358485,4.63588802812023E-5,1,0.999253354069792,40.0298881530762,1.98359693702539,24.1199992597103,-0.0141059210615429,-0.0182636489527721,0.25,-0.00136699685662946,-0.0014913844969522,-0.00136793577628539,299.9904175,299.9904175,-54548.95703125,-54499.01953125,54.8937709055827,19.5814670826111,8.102614,0,0,0,40,4961,300.4812,-54523.98828125,,,,,,,,,,,,,0,,,,0.00245,,,,,,299.9904175,,,,
,20333780.055,299.9901733,-50584.0390625,-0.00154155100202127,4.68108151092305E-5,1,0.999253354069792,40.0298881530762,1.98366205081673,24.1199992597103,-0.0146671242473943,-0.0183158129424085,0.25,-0.0013630591102171,-0.00154061219502275,-0.00136403127437471,299.9901733,299.9901733,-50611.703125,-50556.375,54.6178560382942,19.5840725940762,8.102614,0,0,0,40,4961,300.48875,-50584.0390625,,,,,,,,,,,,,0,,,,0.00245,,,,,,299.9901733,,,,
,20333859.875,299.99230955,-46596.55078125,-0.00161595323950725,4.87495116156241E-5,1,0.999253354069792,40.0298881530762,1.9836157186324,24.1199992597103,-0.0154358396261068,-0.0188463270633097,0.25,-0.00139742215207391,-0.00161498867908417,-0.00139844294270358,299.9916992,299.9929199,-46624.3359375,-46568.765625,55.0938678065058,19.583105102069,8.102614,0,0,0,40,4961,300.4918,-46596.55078125,,,,,,,,,,,,,0,,,,0.00245,,,,,,299.99230955,,,,
,20333940.06,299.9902954,-42585.83984375,-0.0016491638709656,4.96322067101918E-5,1,0.999253354069792,40.0298881530762,1.98352048814329,24.1199992597103,-0.0158197676878869,-0.0188435901412748,0.25,-0.00139150075835594,-0.00164820144032152,-0.00139254454029893,299.9902954,299.9902954,-42590.4140625,-42581.265625,55.2103304558712,19.5826875471723,8.482265,0,0,0,40,4961,300.4974,-42585.83984375,,,,,,,,,,,,,0,,,,0,,,,,,299.9902954,,,,
,20334021.705,299.9907227,-38505.6875,-0.00166583225551538,4.71837960971184E-5,1,0.999253354069792,40.0298881530762,1.98356836288147,24.1199992597103,-0.0159681996557017,-0.0191027010069477,0.25,-0.00141163584255155,-0.00166485517089281,-0.00141269087491398,299.9907227,299.9907227,-38507.6640625,-38503.7109375,54.5389115578519,19.5832975174032,8.102614,0,0,0,40,4961,300.5077,-38505.6875,,,,,,,,,,,,,0,,,,0,,,,,,299.9907227,,,,
,20334101.075,299.9906769,-34540.61328125,-0.00173343551979529,4.35610497117348E-5,1,0.999253354069792,40.0298881530762,1.98349365217621,24.1199992597103,-0.0167837329522943,-0.0189068782740712,0.25,-0.00138255372980783,-0.00173247473186403,-0.00138365500581806,299.9905396,299.9908142,-34565.49609375,-34515.73046875,55.0102335549481,19.5897744151105,8.482265,0,0,0,40,4961,300.5116,-34540.61328125,,,,,,,,,,,,,0,,,,0,,,,,,299.9906769,,,,
,20334182.895,299.990509,-30452.974609375,-0.00171487077122449,4.52606858396501E-5,1,0.999253354069792,40.0298881530762,1.98343052092699,24.1199992597103,-0.0165151090872281,-0.0192138108870953,0.25,-0.00141314112717478,-0.00171388949434668,-0.00141423020753171,299.990509,299.990509,-30483.0390625,-30422.91015625,55.2236181406982,19.5852349459127,8.482265,0,0,0,40,4961,300.51695,-30452.974609375,,,,,,,,,,,,,0,,,,0.00245,,,,,,299.990509,,,,
,20334262.82,299.9910126,-26455.2314453125,-0.00178367281223464,4.56361952416774E-5,1,0.999253354069792,40.0298881530762,1.98339426169819,24.1199992597103,-0.0173667429680395,-0.0188914762372079,0.25,-0.00137255790539222,-0.00178271541124959,-0.00137369439370684,299.9905396,299.9914856,-26485.0625,-26425.400390625,54.874230192602,19.5826195484733,8.102614,0,0,0,40,4961,300.5223,-26455.2314453125,,,,,,,,,,,,,0,,,,0,,,,,,299.9910126,,,,
,20334341.58,299.99235535,-22520.5869140625,-0.00178524918053743,4.00305548590838E-5,1,0.999253354069792,40.0298881530762,1.98331887452707,24.1199992597103,-0.0173808058858098,-0.0189112024228478,0.25,-0.00137410115391403,-0.00178428982612209,-0.00137523944104694,299.9916992,299.9930115,-22548.154296875,-22493.01953125,54.8695404214866,19.5871830218939,7.722963,0,0,0,40,4961,300.52675,-22520.5869140625,,,,,,,,,,,,,0,,,,0,,,,,,299.99235535,,,,
,20334421.86,299.99217225,-18510.4921875,-0.00181164236993292,4.02478622935995E-5,1,0.999253354069792,40.0298881530762,1.98331763083696,24.1199992597103,-0.0177262961284713,-0.0186796765425539,0.25,-0.00134891900532596,-0.00181069810213241,-0.0013500763300158,299.9921265,299.992218,-18540.646484375,-18480.337890625,54.4482426496212,19.5868046849292,8.102614,0,0,0,40,4961,300.532,-18510.4921875,,,,,,,,,,,,,0,,,,0.00245,,,,,,299.99217225,,,,
,20334500.185,299.9941101,-14592.5810546875,-0.00182371188290372,4.23732785061408E-5,1,0.999253354069792,40.0298881530762,1.98329839774203,24.1199992597103,-0.0178244457695254,-0.0189180635540812,0.25,-0.00136806326787673,-0.00182275374226997,-0.00136922873646273,299.9933472,299.994873,-14622.701171875,-14562.4609375,55.1290410898712,19.5831368758177,7.722963,0,0,0,40,4961,300.53515,-14592.5810546875,,,,,,,,,,,,,0,,,,0,,,,,,299.9941101,,,,
,20334579.14,299.9931183,-10647.0473632813,-0.00180485046684756,3.85412003374437E-5,1,0.999253354069792,40.0298881530762,1.98317429683865,24.1199992597103,-0.0176603726835821,-0.0185981480993853,0.25,-0.00134295138335452,-0.00180390884812236,-0.00134410595175805,299.9930115,299.9932251,-10679.46875,-10614.6259765625,54.7522961436019,19.5810219083475,8.482265,0,0,0,40,4961,300.53785,-10647.0473632813,,,,,,,,,,,,,0,,,,-0.00245,,,,,,299.9931183,,,,
,20334656.85,299.9938965,-6763.47290039063,-0.00178824587090369,3.35046367881641E-5,1,0.999253354069792,40.0298881530762,1.98311877755171,24.1199992597103,-0.01758347019371,-0.0179299050371019,0.25,-0.00128638163112691,-0.00178734150868607,-0.00128752754653957,299.9938965,299.9938965,-6795.9130859375,-6731.03271484375,54.6803863198327,19.5854528317667,8.102614,0,0,0,40,4961,300.542,-6763.47290039063,,,,,,,,,,,,,0,,,,-0.0049,,,,,,299.9938965,,,,
,20334734.75,299.9942017,-2869.82946777344,-0.00171961786426023,3.49188289956596E-5,1,0.999253354069792,40.0298881530762,1.98322969281991,24.1199992597103,-0.0169254635100555,-0.0171509443673651,0.25,-0.00122884293899253,-0.00171875307774244,-0.00122994571156134,299.9942017,299.9942017,-2872.46118164062,-2867.19775390625,54.9836581852943,19.5928959407818,8.102614,0,0,0,40,4961,300.5445,-2869.82946777344,,,,,,,,,,,,,0,,,,-0.0049,,,,,,299.9942017,,,,
,20334809.76,299.9970856,878.397918701172,0.00142899175873668,2.39231943886018E-5,1,0.999253354069792,40.0298881530762,1.98314373003269,24.1199992597103,0.0141216738918767,0.0139209900145761,0.25,0.000991716285871863,0.00142829230465133,0.000992633662856113,299.9969788,299.9971924,845.728271484375,911.067565917969,55.0735454650058,19.5904477188053,7.722963,0,0,0,40,4961,300.5457,878.397918701172,,,,,,,,,,,,,0,,,,-0.00245,,,,,,299.9970856,,,,
,20334886.9,299.99757385,4733.70068359375,0.00177507958388168,2.8587665734893E-5,1,0.999253354069792,40.0298881530762,1.98321687138759,24.1199992597103,0.0175030309758352,0.0175205177084738,0.25,0.0012521433148803,0.001774197774852,0.00125328167308296,299.997406,299.9977417,4706.44384765625,4760.95751953125,54.7671470854673,19.5876540510837,8.482265,0,0,0,40,4961,300.5491,4733.70068359375,,,,,,,,,,,,,0,,,,0,,,,,,299.99757385,,,,
,20334963.875,300.00175475,8579.4716796875,0.00178936752816357,3.46439748044809E-5,1,0.999253354069792,40.0298881530762,1.98310859602895,24.1199992597103,0.0175847377378702,0.0179968921410347,0.25,0.001292159427735,0.00178845910230893,0.00129330520550255,300.001709,300.0018005,8549.5126953125,8609.4306640625,54.7890326840058,19.5878624263782,7.722963,0,0,0,40,4961,300.54545,8579.4716796875,,,,,,,,,,,,,0,,,,0.00245,,,,,,300.00175475,,,,
,20335042.15,300.0055542,12492.8989257813,0.00185632555752378,3.31482771071535E-5,1,0.999253354069792,40.0298881530762,1.98309869718449,24.1199992597103,0.0182549359183017,0.018599481081167,0.25,0.00133421294448213,0.00185538771637486,0.00133540083616198,300.0055542,300.0055542,12467.865234375,12517.9326171875,54.5264055015442,19.5836577611685,8.482265,0,0,0,40,4961,300.54145,12492.8989257813,,,,,,,,,,,,,0,,,,0,,,,,,300.0055542,,,,
,20335121.175,300.0070496,16443.6826171875,0.00183777683428971,4.52209698129579E-5,1,0.999253354069792,40.0298881530762,1.98309048306305,24.1199992597103,0.0180253081709127,0.0186857361232081,0.25,0.00134511294834801,0.00183683294820863,0.00134628736863038,300.0070496,300.0070496,16416.091796875,16471.2734375,54.7905959410442,19.5916514642045,8.482265,0,0,0,40,4961,300.5353,16443.6826171875,,,,,,,,,,,,,0,,,,0.00245,,,,,,300.0070496,,,,
,20335200.03,300.008194,20381.025390625,0.00180372470053507,4.39211826342464E-5,1,0.999253354069792,40.0298881530762,1.98301097683369,24.1199992597103,0.0175451244102346,0.0191787327649677,0.25,0.00139496854769275,0.00180274957249918,0.00139611809151444,300.0072632,300.0091248,20348.927734375,20413.123046875,54.7968489691981,19.5872922279576,8.102614,0,0,0,40,4961,300.52925,20381.025390625,,,,,,,,,,,,,0,,,,-0.00245,,,,,,300.008194,,,,
,20335279.095,300.0107727,24334.12109375,0.00176862476573523,3.63940499957489E-5,1,0.999253354069792,40.0298881530762,1.98294854164855,24.1199992597103,0.0172186870921827,0.0187155156866649,0.25,0.00135986076201196,0.00176767447577742,0.00136098721516207,300.0107727,300.0107727,24311.673828125,24356.568359375,54.7335370591404,19.5924859983092,8.102614,0,0,0,40,4961,300.52045,24334.12109375,,,,,,,,,,,,,0,,,,0,,,,,,300.0107727,,,,
,20335358.88,300.01008605,28325.2939453125,0.00173631031244381,3.54028455463614E-5,1,0.999253354069792,40.0298881530762,1.98291204885888,24.1199992597103,0.0167971279505504,0.0189889208793675,0.25,0.00138983175583114,0.00173534207990879,0.00139093516061913,300.0099487,300.0102234,28295.419921875,28355.16796875,54.9516114160058,19.5901191723285,8.482265,0,0,0,40,4961,300.5143,28325.2939453125,,,,,,,,,,,,,0,,,,-0.00245,,,,,,300.01008605,,,,
,20335437.97,300.0120697,32275.6845703125,0.00172856688327864,4.4984757968863E-5,1,0.999253354069792,40.0298881530762,1.98282579815427,24.1199992597103,0.0167825709304906,0.0185511381566499,0.25,0.00135226532258131,0.00172762433601107,0.00135336378541064,300.0114746,300.0126648,32248.48046875,32302.888671875,54.5803378693712,19.5887666670793,8.482265,0,0,0,40,4961,300.505,32275.6845703125,,,,,,,,,,,,,0,,,,-0.0049,,,,,,300.0120697,,,,
,20335520.82,300.0123749,36418.35546875,0.00168402898555857,3.436096470747E-5,1,0.999253354069792,40.0298881530762,1.98288218937043,24.1299998015165,0.0162253040538076,0.0187968825374002,0.25,0.0013818175343705,0.0016830691640475,0.00138288485583007,300.0122986,300.0124512,36390.734375,36445.9765625,54.5107729311596,19.5860095767828,8.482265,0,0,0,40,4961,300.49585,36418.35546875,,,,,,,,,,,,,0,,,,-0.00245,,,,,,300.0123749,,,,
,20335601.96,300.01313785,40473.8671875,0.00164672598278291,3.55752450496191E-5,1,0.999253354069792,40.0298881530762,1.9828308284356,24.1199992597103,0.0158270116334363,0.0186022842633056,0.25,0.00137099611999406,0.00164577522164449,0.0013720382983856,300.0129395,300.0133362,40443.875,40503.859375,54.7859061699289,19.5903566179676,8.482265,0,0,0,40,4961,300.48515,40473.8671875,,,,,,,,,,,,,0,,,,-0.0049,,,,,,300.01313785,,,,
,20335682.64,300.0127869,44504.1015625,0.00159256578010254,4.51413635125572E-5,1,0.999253354069792,40.0298881530762,1.98286381374723,24.1199992597103,0.0152119383932548,0.0185378200112624,0.25,0.00137461432719343,0.00159161516069204,0.00137561993471693,300.0127869,300.0127869,44471.30859375,44536.89453125,55.0860515213135,19.5911033151573,8.861917,0,0,0,40,4961,300.47635,44504.1015625,,,,,,,,,,,,,0,,,,0,,,,,,300.0127869,,,,
,20335763.28,300.0134583,48534.0703125,0.00158460348282008,5.53617507588313E-5,1,0.999253354069792,40.0298881530762,1.98277864368794,24.1199992597103,0.0151638079055694,0.0182796776591649,0.25,0.00135307743050586,0.00158366811008295,0.00135407753594985,300.0134583,300.0134583,48534.0703125,48534.0703125,54.9680256149097,19.5890577816511,8.102614,0,0,0,40,4961,300.46935,48534.0703125,,,,,,,,,,,,,0,,,,0,,,,,,300.0134583,,,,
,20335844.105,300.0141754,52574.94140625,0.00151099990621565,5.1528266413764E-5,1,0.999253354069792,40.0298881530762,1.98265405032397,24.1199992597103,0.0143312872205132,0.018164409830963,0.25,0.00135566389093496,0.00151006588496892,0.00135661472221203,300.0136108,300.01474,52552.5234375,52597.359375,54.5326585296981,19.5936228125241,8.102614,0,0,0,40,4961,300.46025,52574.94140625,,,,,,,,,,,,,0,,,,-0.00245,,,,,,300.0141754,,,,
,20335926.025,300.0132141,56668.126953125,0.0014695084794151,5.88757032852897E-5,1,0.999253354069792,40.0298881530762,1.98283733076805,24.1199992597103,0.013847568775941,0.0181949069953835,0.25,0.00136542554034934,0.00146857026064338,0.00136634808341874,300.0132141,300.0132141,56665.95703125,56670.296875,54.7139963461596,19.5928363832823,8.482265,0,0,0,40,4961,300.4491,56668.126953125,,,,,,,,,,,,,0,,,,0,,,,,,300.0132141,,,,
,20336006.26,300.0140076,60678.849609375,0.00140323947768329,4.8853024589467E-5,1,0.999253354069792,40.0298881530762,1.98279783785159,24.1199992597103,0.0130839478120705,0.0181758356227583,0.25,0.00137524016879392,0.00140229767824386,0.00137611816334686,300.0140076,300.0140076,60658.92578125,60698.7734375,54.7648021999096,19.5895477955201,8.482265,0,0,0,40,4961,300.4411,60678.849609375,,,,,,,,,,,,,0,,,,-0.00245,,,,,,300.0140076,,,,
,20336088.375,300.0137177,64784.81640625,0.00133897207612054,5.74321968966171E-5,1,0.999253354069792,40.0298881530762,1.98275696238063,24.1199992597103,0.0124185446816917,0.0177236132896349,0.25,0.0013461409494988,0.00133805217314472,0.00134697696878345,300.0134583,300.0139771,64752.19921875,64817.43359375,54.5693950701019,19.5924856329891,8.482265,0,0,0,40,4961,300.43065,64784.81640625,,,,,,,,,,,,,0,,,,0,,,,,,300.0137177,,,,
,20336170.165,300.0152893,68870.40234375,0.00129377839341908,4.69034130483651E-5,1,0.999253354069792,40.0298881530762,1.98270671123787,24.1199992597103,0.0118751939079019,0.0178402077724387,0.25,0.00136439153092002,0.00129284875662289,0.00136519662985063,300.0149536,300.015625,68845.734375,68895.0703125,55.0344640390443,19.5938197581105,8.482265,0,0,0,40,4961,300.41895,68870.40234375,,,,,,,,,,,,,0,,,,0,,,,,,300.0152893,,,,
,20336251.72,300.0133362,72947.9921875,0.00125772680894042,5.66319078534323E-5,1,0.999253354069792,40.0298881530762,1.98266906379208,24.1199992597103,0.011546272341743,0.0173301725602769,0.25,0.00132525106670832,0.0012568248315552,0.00132603311626463,300.0123291,300.0143433,72917.5859375,72978.3984375,54.248145748698,19.5919344032334,8.102614,0,0,0,40,4961,300.4102,72947.9921875,,,,,,,,,,,,,0,,,,0.00245,,,,,,300.0133362,,,,
,20336333.82,300.0137329,77051.50390625,0.00124227914960162,5.86644099447713E-5,1,0.999253354069792,40.0298881530762,1.98277444929406,24.1199992597103,0.0114292425050259,0.0169785388805242,0.25,0.00129654026353106,0.0012413972743485,0.00129731231267905,300.0137329,300.0137329,77021.703125,77081.3046875,54.8851729918712,19.5943058711319,8.102614,0,0,0,40,4961,300.4004,77051.50390625,,,,,,,,,,,,,0,,,,-0.0049,,,,,,300.0137329,,,,
,20336415.795,300.0145569,81150.3671875,0.00116096738128314,6.22997838290342E-5,1,0.999253354069792,40.0298881530762,1.98280928552243,24.1199992597103,0.0105490948420116,0.016630857311338,0.25,0.00127964567524187,0.00116009978864786,0.0012803644657922,300.0145569,300.0145569,81120.0078125,81180.7265625,54.7069616894866,19.5913094395038,8.482265,0,0,0,40,4961,300.3904,81150.3671875,,,,,,,,,,,,,0,,,,0,,,,,,300.0145569,,,,
,20336496.465,300.015625,85181.078125,0.00109961080134222,6.85923304557936E-5,1,0.999253354069792,40.0298881530762,1.9826565348395,24.1199992597103,0.00985434096190191,0.0165387342382807,0.25,0.00128218202515504,0.00109874421772654,0.00128286007562315,300.015625,300.015625,85148.625,85213.53125,54.6139478956981,19.592026705651,8.861917,0,0,0,40,4961,300.38045,85181.078125,,,,,,,,,,,,,0,,,,0.00245,,,,,,300.015625,,,,
,20336574.73,300.0140991,89091.8515625,0.00104295072006958,7.91012603491851E-5,1,0.999253354069792,40.0298881530762,1.98248774189838,24.1199992597103,0.00929416924248686,0.0159834103499181,0.25,0.00124266571448201,0.00104211242399747,0.00124330751920796,300.0140991,300.0140991,89061.921875,89121.78125,54.8828281063135,19.5933113841709,8.861917,0,0,0,40,4961,300.37045,89091.8515625,,,,,,,,,,,,,0,,,,0,,,,,,300.0140991,,,,
,20336594.11,300.0140381,89999.6484375,0.00102545791371641,7.9308383623562E-5,1,0.999253354069792,40.0298881530762,1.98255429704115,24.1199992597103,0.00908484890539021,0.0160259706289123,0.25,0.00124944068043318,0.00102461592392001,0.00125007078238111,300.0140381,300.0140381,89999.640625,89999.65625,54.8171713106981,19.5948007597028,8.861917,0,0,0,40,4929,300.36755,89999.6484375,,,,,,,,,,,,,0,,,,-0.00245,,,,,,300.0140381,,,,