File: data/monolayers/magneticStructure/ML_Ac_CoFe_C-2/PPMS/BackupJuelich/data/DD175_23_ZFCW_100OE.DAT
[Header]
; VSM Data File (default extension .dat)
; Copyright (c) 2003-2013, Quantum Design, Inc. All rights reserved.
TITLE,
FILEOPENTIME,31832311.61,01/04/2019,6:20 pm
BYAPP,VSM,2.0,2.0
INFO,PPMS VSM Option Release 1.4.10 Build 1,APPNAME
INFO,Quantum Design Linear Motor Servo Controller,MOTOR_MODULE_NAME
INFO,3101-100 M1,MOTOR_HW_VERSION
INFO,MMC1014,MOTOR_SERIAL_NUMBER
INFO,SRV No X-over 01.03.11,MOTOR_SOFTWARE_VERSION
INFO,Quantum Design VSM Detection Module,VSM_MODULE_NAME
INFO,3101-150 F0,VSM_HW_VERSION
INFO,VSM707,VSM_SERIAL_NUMBER
INFO,VSM No X-over 01.02.05 May 20 2008 13:51:47,VSM_SOFTWARE_VERSION
INFO,704,PREAMP_SERIAL_NUMBER
INFO,822,COIL_SERIAL_NUMBER
INFO,0,MOMENT_UNITS
INFO,CoFe2O4 Monolayer,SAMPLE_MATERIAL
INFO,from YF45,SAMPLE_COMMENT
INFO,29.98,SAMPLE_MASS
INFO,,SAMPLE_VOLUME
INFO,,SAMPLE_MOLECULAR_WEIGHT
INFO,,SAMPLE_SIZE
INFO,,SAMPLE_SHAPE
DATATYPE,COMMENT,1
DATATYPE,TIME,2
STARTUPAXIS,X,2
STARTUPAXIS,Y1,5
[Data]
Comment,Time Stamp (sec),Temperature (K),Magnetic Field (Oe),Moment (emu),M. Std. Err. (emu),Transport Action,Averaging Time (sec),Frequency (Hz),Peak Amplitude (mm),Center Position (mm),Coil Signal' (mV),Coil Signal" (mV),Range (mV),M. Quad. Signal (emu),M. Raw' (emu),M. Raw" (emu),Min. Temperature (K),Max. Temperature (K),Min. Field (Oe),Max. Field (Oe),Mass (grams),Motor Lag (deg),Pressure (Torr),VSM Status (code),Motor Status (code),Measure Status (code),Measure Count,PPMS Status (code),System Temp. (K),System Field (Oe),Sample Position (deg),Bridge 1 Resistance (ohms),Bridge 1 Excitation (에),Bridge 2 Resistance (ohms),Bridge 2 Excitation (에),Bridge 3 Resistance (ohms),Bridge 3 Excitation (에),Bridge 4 Resistance (ohms),Bridge 4 Excitation (에),Signal 1 Vin (V),Signal 2 Vin (V),Digital Inputs (code),Drive 1 Iout (mA),Drive 1 Ipower (W),Drive 2 Iout (mA),Drive 2 Ipower (W),Pressure (),Map 20 (),Map 21 (),Map 22 (),Map 23 (),Map 24 (),Map 25 (),Map 26 (),Map 27 (),Map 28 (),Map 29 ()
,31845366.86,4.9927125,99.6243667602539,,,2,,,,22.1100005489588,,,,,,,4.9927125,4.9927125,99.6243667602539,99.6243667602539,,,9.241568,,,,-99999999,4369,5.0078,99.6243667602539,,,,,,,,,,,,,,,,,,,,,,,4.9927125,,,,
,31845486.555,7.5366178,99.6243667602539,-2.92136888536731E-7,2.97543841011161E-7,1,0.999253354069792,40.0298881530762,1.98522123718824,22.0999997109175,-3.20550072332998E-6,-9.0741403355188E-7,0.25,-2.93464697038227E-8,-2.90318762851453E-7,-3.0586979564972E-8,7.5366178,7.5366178,99.6243667602539,99.6243667602539,56.2850696698137,20.4900294916537,10.00087,0,0,0,40,4370,7.5911,99.6243667602539,,,,,,,,,,,,,0,,,,-0.00245,,,,,,7.5366178,,,,
,31845626.575,11.0262561,99.6243667602539,-2.57329715310703E-7,2.5920856156503E-7,1,0.999253354069792,40.0298881530762,1.98473633757058,22.0999997109175,-1.78266208350028E-6,-6.65711088441889E-6,0.25,-5.50326987661024E-7,-2.53197524884456E-7,-5.48407052262939E-7,10.9984303,11.0540819,99.6243667602539,99.6243667602539,56.5195582255829,20.5051712110915,11.519473,0,0,0,40,4370,11.1128,99.6243667602539,,,,,,,,,,,,,0,,,,-0.00245,,,,,,11.0262561,,,,
,31845767.63,14.5044165,99.6243667602539,-5.14900220579211E-7,3.07681536430978E-7,1,0.999253354069792,40.0298881530762,1.98348104355929,22.0999997109175,-5.37768610981203E-6,-3.10328306201993E-6,0.25,-1.86578459430456E-7,-5.11038862299779E-7,-1.87988576548453E-7,14.4784346,14.5303984,99.6243667602539,99.6243667602539,56.7931282073137,20.539030271718,12.278775,0,0,0,40,4370,14.65955,99.6243667602539,,,,,,,,,,,,,0,,,,0.00245,,,,,,14.5044165,,,,
,31845908.43,18.0043411,99.6243667602539,-1.60968435827185E-7,2.78543798789891E-7,1,0.999253354069792,40.0298881530762,1.98327441499332,21.4099995791912,-1.61411717415677E-6,-1.34663134466818E-6,0.25,-9.2069097533018E-8,-1.59596846373057E-7,-9.23149906790772E-8,18.0043411,18.0043411,99.6243667602539,99.6243667602539,56.2334821875444,20.5258615701719,13.038077,0,0,0,40,4370,18.196,99.6243667602539,,,,,,,,,,,,,0,,,,0,,,,,,18.0043411,,,,
,31846048.885,21.5225773,99.6243667602539,-3.1778640008606E-7,2.71309937757016E-7,1,0.999253354069792,40.0298881530762,1.98363652087534,21.4099995791912,-3.26680647936205E-6,-2.21091249860748E-6,0.25,-1.41591885509011E-7,-3.15277786738135E-7,-1.42339604090194E-7,21.5225773,21.5225773,99.6243667602539,99.6243667602539,56.3991874336214,20.5309058379499,13.797379,0,0,0,40,4370,21.7225,99.6243667602539,,,,,,,,,,,,,0,,,,0,,,,,,21.5225773,,,,
,31846190.805,25.0063972,99.6243667602539,-3.82947019858618E-7,2.79628025451633E-7,1,0.999253354069792,40.0298881530762,1.98340354044954,21.4099995791912,-4.24266692892609E-6,-9.42440124902192E-7,0.25,-1.63168152357997E-8,-3.80733490863907E-7,-1.81714591017583E-8,25.0063972,25.0063972,99.6243667602539,99.6243667602539,56.4507749158906,20.5335642322534,14.177031,0,0,0,40,4370,25.3035,99.6243667602539,,,,,,,,,,,,,0,,,,-0.0049,,,,,,25.0063972,,,,
,31846330.85,28.5042591,99.6243667602539,-2.09400859020826E-7,2.72736339625692E-7,1,0.999253354069792,40.0298881530762,2.0072517959899,21.4099995791912,-1.66937969401245E-6,-4.32622540177621E-6,0.25,-3.45750233453415E-7,-2.06435433373797E-7,-3.4504053522655E-7,28.5042591,28.5042591,99.6243667602539,99.6243667602539,56.424981174756,20.5214501429252,14.936333,0,0,0,40,4370,28.8328,99.6243667602539,,,,,,,,,,,,,0,,,,0,,,,,,28.5042591,,,,
,31846472.075,32.0074425,99.6243667602539,-2.15026569603212E-7,3.30945372330701E-7,1,0.999253354069792,40.0298881530762,2.00731200363068,21.4099995791912,-2.01951143592141E-6,-2.72979708716263E-6,0.25,-2.03223835667999E-7,-2.12805754789095E-7,-2.03463859459436E-7,32.0074425,32.0074425,99.6243667602539,99.6243667602539,56.5797436215637,20.5274285244903,14.936333,0,0,0,40,4370,32.3821,99.6243667602539,,,,,,,,,,,,,0,,,,0,,,,,,32.0074425,,,,
,31846614.96,35.5458527,99.6243667602539,-4.64739364802289E-8,2.84067185347946E-7,1,0.999253354069792,40.0298881530762,2.00738135454427,21.4099995791912,4.25942791796483E-7,-5.40883892495044E-6,0.25,-4.70155959146832E-7,-4.33607400493112E-8,-4.68413783889515E-7,35.5458527,35.5458527,99.6243667602539,99.6243667602539,56.9603967104291,20.5273976541887,15.315984,0,0,0,40,4370,35.9885,99.6243667602539,,,,,,,,,,,,,0,,,,0,,,,,,35.5458527,,,,
,31846754.835,39.0075588,99.6243667602539,-2.61362616173427E-7,3.38149178531094E-7,1,0.999253354069792,40.0298881530762,2.00716799286582,21.4000009000301,-2.30295514234906E-6,-4.17081743947393E-6,0.25,-3.2184425834713E-7,-2.58290341994382E-7,-3.22431781968834E-7,38.9832649,39.0318527,99.6243667602539,99.6243667602539,56.2334821875444,20.5304430379654,16.075285,0,0,0,40,4370,39.5199,99.6243667602539,,,,,,,,,,,,,0,,,,-0.00245,,,,,,39.0075588,,,,
,31846899.345,42.5468674,99.6243667602539,-2.42348267604914E-8,3.35134380505913E-7,1,0.999253354069792,40.0298881530762,2.00740951096982,21.4000009000301,7.7230784670821E-8,-2.00420991849317E-6,0.25,-1.72658686769642E-7,-2.29531865036058E-8,-1.72376918752678E-7,42.5468674,42.5468674,99.6243667602539,99.6243667602539,56.5648926796983,20.5265844694814,16.834587,0,0,0,40,4370,43.1759,99.6243667602539,,,,,,,,,,,,,0,,,,0,,,,,,42.5468674,,,,
,31847039.87,46.0014687,99.6243667602539,-1.68094537236778E-7,2.50397879786901E-7,1,0.999253354069792,40.0298881530762,2.0073657552178,21.4000009000301,-1.40928342675384E-6,-3.09528169027135E-6,0.25,-2.4283215195335E-7,-1.66050940063008E-7,-2.43683930419659E-7,46.0014687,46.0014687,99.6243667602539,99.6243667602539,56.8353361473522,20.5303710893778,16.075285,0,0,0,40,4370,46.73715,99.6243667602539,,,,,,,,,,,,,0,,,,0.00245,,,,,,46.0014687,,,,
,31847163.665,49.0436707,99.6243667602539,-1.66789171695345E-7,2.97585944578662E-7,1,0.999253354069792,40.0298881530762,2.00728796431076,21.3799998164177,-1.13906396132869E-6,-4.51844757381385E-6,0.25,-3.68251241869063E-7,-1.63953944139098E-7,-3.69278734297958E-7,49.0436707,49.0436707,99.6243667602539,99.6243667602539,56.0896625400059,20.5273911440238,17.214239,0,0,0,40,4370,49.8928,99.6243667602539,,,,,,,,,,,,,0,,,,-0.0049,,,,,,49.0436707,,,,
,31847306.59,52.50621795,99.6243667602539,-3.97341623010763E-7,3.03719915400313E-7,1,0.999253354069792,40.0298881530762,1.99497403062851,21.3799998164177,-3.60250276223931E-6,-5.71242066842462E-6,0.25,-4.34356789987724E-7,-3.94354965916667E-7,-4.37533066332241E-7,52.4795074,52.5329285,99.6243667602539,99.6243667602539,56.9603967104291,20.5301843667098,17.593889,0,0,0,40,4374,53.5498,99.6243667602539,,,,,,,,,,,,,0,,,,0.00245,,,,,,52.50621795,,,,
,31847450.645,56.0167732,99.6243667602539,-2.90905046635411E-7,2.91807897196257E-7,1,0.999253354069792,40.0298881530762,1.99484763916004,21.3799998164177,-3.35315700261398E-6,-2.28807409179251E-7,0.25,3.21036964741314E-8,-2.91606263631583E-7,3.00721649635933E-8,56.0167732,56.0167732,99.6243667602539,99.6243667602539,56.6110087623329,20.5337777577557,19.112494,0,0,0,40,4374,57.25035,99.6243667602539,,,,,,,,,,,,,0,,,,0,,,,,,56.0167732,,,,
,31847573.48,59.0095787,99.6243667602539,-9.23519671512686E-8,3.37664533073279E-7,1,0.999253354069792,40.0298881530762,1.99472668370551,21.3500000536442,-7.91608259781165E-7,-1.59591647783212E-6,0.25,-1.24502846832022E-7,-9.17189036196406E-8,-1.2543804570873E-7,59.0095787,59.0095787,99.6243667602539,99.6243667602539,56.5734905934098,20.5334245373374,18.732843,0,0,0,40,4374,60.37285,99.6243667602539,,,,,,,,,,,,,0,,,,-0.0049,,,,,,59.0095787,,,,
,31847714.015,62.5105019,99.6243667602539,-7.28488765947466E-8,3.08894291077313E-7,1,0.999253354069792,40.0298881530762,1.99467075626406,21.3500000536442,-1.08063457806529E-6,1.28034395280174E-6,0.25,1.26159964341759E-7,-7.38976515318334E-8,1.26088943026596E-7,62.5105019,62.5105019,99.6243667602539,99.6243667602539,56.9916618511983,20.5372476928488,19.112494,0,0,0,40,4374,63.92225,99.6243667602539,,,,,,,,,,,,,0,,,,0,,,,,,62.5105019,,,,
,31847857.61,66.0517616,99.6243667602539,-2.4744738541819E-7,3.20772899273136E-7,1,0.999253354069792,40.0298881530762,1.99461478011539,21.3500000536442,-2.78448807190785E-6,-6.05012840383258E-7,0.25,-9.17083389271347E-9,-2.48335818709717E-7,-1.07001262105671E-8,66.0238876,66.0796356,99.6243667602539,99.6243667602539,56.5985027060252,20.5405103630265,19.492144,0,0,0,40,4374,67.55,99.6243667602539,,,,,,,,,,,,,0,,,,0,,,,,,66.0517616,,,,
,31847998.61,69.5128403,99.6243667602539,-1.42152460706972E-7,3.15158757427443E-7,1,0.999253354069792,40.0298881530762,1.99448979852118,21.3300008326769,-1.36824807935557E-6,-1.64918236137999E-6,0.25,-1.20161774206848E-7,-1.42091681734676E-7,-1.21476390632964E-7,69.5128403,69.5128403,99.6243667602539,99.6243667602539,56.9377294833714,20.5368327513492,19.871798,0,0,0,40,4374,71.11625,99.6243667602539,,,,,,,,,,,,,0,,,,-0.0049,,,,,,69.5128403,,,,
,31848139.68,73.0099564,99.6243667602539,-1.70960939431042E-8,3.21332112285677E-7,1,0.999253354069792,40.0298881530762,1.99461635055981,21.3300008326769,-7.05381415616874E-7,2.84085401900558E-6,0.25,2.53567941287224E-7,-1.84918128338259E-8,2.54669935663615E-7,73.0099564,73.0099564,99.6243667602539,99.6243667602539,56.7767140084099,20.5404258095284,19.871798,0,0,0,40,4374,74.68335,99.6243667602539,,,,,,,,,,,,,0,,,,0,,,,,,73.0099564,,,,
,31848281.775,76.5177155,99.6243667602539,-3.60446184863503E-8,3.09427153726295E-7,1,0.999253354069792,40.0298881530762,1.99450113197975,21.3300008326769,8.79848062858946E-8,-2.87174137433613E-6,0.25,-2.46774512035495E-7,-3.50409985510558E-8,-2.48179652283206E-7,76.5177155,76.5177155,99.6243667602539,99.6243667602539,56.7204367550252,20.5446410128458,20.251448,0,0,0,40,4374,78.2773,99.6243667602539,,,,,,,,,,,,,0,,,,-0.0049,,,,,,76.5177155,,,,
,31848426.135,80.0372849,99.6243667602539,-2.24087019463017E-8,3.35541117356954E-7,1,0.999253354069792,40.0298881530762,1.99460093516118,21.2900005280972,1.92656288302311E-7,-2.56833995839076E-6,0.25,-2.22378579437636E-7,-2.15404782435319E-8,-2.2363942313993E-7,80.0372849,80.0372849,99.6243667602539,99.6243667602539,56.5375356815252,20.5395074822552,20.251448,0,0,0,40,4374,81.95295,99.6243667602539,,,,,,,,,,,,,0,,,,0.0049,,,,,,80.0372849,,,,
,31848566.055,83.5441437,99.6243667602539,-2.78156259856171E-8,2.52118448882238E-7,1,0.999253354069792,40.0298881530762,1.99461758530138,21.2900005280972,6.08256718773134E-7,-5.28194392324561E-6,0.25,-4.60476257452565E-7,-2.60708913320285E-8,-4.63069848172343E-7,83.5441437,83.5441437,99.6243667602539,99.6243667602539,56.5320642818906,20.5446873681784,20.631098,0,0,0,40,4374,85.46935,99.6243667602539,,,,,,,,,,,,,0,,,,-0.00245,,,,,,83.5441437,,,,
,31848707.04,87.0320816,99.6243667602539,-6.73163855044241E-8,3.24047903450479E-7,1,0.999253354069792,40.0298881530762,1.99449092463923,21.2900005280972,-5.98731926781599E-7,-1.07170446275396E-6,0.25,-8.25369740669377E-8,-6.73710400919506E-8,-8.3248668362711E-8,87.0320816,87.0320816,99.6243667602539,99.6243667602539,56.8978664288906,20.5484739066472,20.631098,0,0,0,40,4374,89.0307,99.6243667602539,,,,,,,,,,,,,0,,,,0.0049,,,,,,87.0320816,,,,
,31848826.63,90.0087891,99.6243667602539,-1.22500526420961E-7,2.91918243267955E-7,1,0.999253354069792,40.0298881530762,2.00715924916269,21.2500002235174,-8.91903971301884E-7,-3.12357348960345E-6,0.25,-2.51909238701851E-7,-1.22274679008751E-7,-2.5375493606194E-7,90.0087891,90.0087891,99.6243667602539,99.6243667602539,56.9150622563137,20.5422320415553,21.3904,0,0,0,40,4374,92.01745,99.6243667602539,,,,,,,,,,,,,0,,,,0,,,,,,90.0087891,,,,
,31848968.48,93.5489044,99.6243667602539,-2.57284089148662E-7,2.59329687419215E-7,1,0.999253354069792,40.0298881530762,2.00715897690123,21.2500002235174,-2.67096967066463E-6,-2.03783436116428E-6,0.25,-1.33127426447104E-7,-2.58283864261718E-7,-1.34744067717983E-7,93.5489044,93.5489044,99.6243667602539,99.6243667602539,56.4343607169867,20.540688700966,21.3904,0,0,0,40,4374,95.5769,99.6243667602539,,,,,,,,,,,,,0,,,,0,,,,,,93.5489044,,,,
,31849107.495,97.0129166,99.6243667602539,5.84076791201577E-8,3.25171010175573E-7,1,0.999253354069792,40.0298881530762,2.0072797786983,21.2500002235174,7.562077513747E-7,-3.88942874656849E-7,0.25,-4.43176217147164E-8,5.88785467839552E-8,-4.43838691726132E-8,97.0129166,97.0129166,99.6243667602539,99.6243667602539,57.1995750373137,20.5447219771486,21.3904,0,0,0,40,4374,99.0701,99.6243667602539,,,,,,,,,,,,,0,,,,0,,,,,,97.0129166,,,,
,31849229.53,100.0471497,99.6243667602539,-9.14732378513789E-9,2.95407266856327E-7,1,0.999253354069792,40.0298881530762,1.99451939544082,21.1999993771315,7.77857792354E-8,-1.05240729307196E-6,0.25,-9.10809452574546E-8,-8.92630274314707E-9,-9.16252709781165E-8,100.0471497,100.0471497,99.6243667602539,99.6243667602539,56.7509202672752,20.5404198397928,21.770052,0,0,0,40,4374,102.1333,99.6243667602539,,,,,,,,,,,,,0,,,,0,,,,,,100.0471497,,,,
,31849369.84,103.5132675,99.6243667602539,1.48121758155461E-7,2.8922937831247E-7,1,0.999253354069792,40.0298881530762,1.99448280625996,21.1999993771315,1.99088192661921E-6,-1.46608161752697E-6,0.25,-1.5510993803118E-7,1.49400403788767E-7,-1.55572117144321E-7,103.5132675,103.5132675,99.6243667602539,99.6243667602539,57.1808159528522,20.5403181476346,21.770052,0,0,0,40,4374,105.6665,99.6243667602539,,,,,,,,,,,,,0,,,,0,,,,,,103.5132675,,,,
,31849511.015,107.0028992,99.6243667602539,4.39324378666333E-8,3.00642480166695E-7,1,0.999253354069792,40.0298881530762,1.99472009504764,21.1999993771315,1.01678049624031E-6,-2.86669485346717E-6,0.25,-2.60141926902549E-7,4.48747309507939E-8,-2.61497903139439E-7,106.9801636,107.0256348,99.6243667602539,99.6243667602539,57.1511140691214,20.5418012444686,21.3904,0,0,0,40,4374,109.2245,99.6243667602539,,,,,,,,,,,,,0,,,,-0.00245,,,,,,107.0028992,,,,
,31849652.275,110.5183029,99.6243667602539,2.87660339141204E-7,2.67705750945499E-7,1,0.999253354069792,40.0298881530762,1.9945830914316,21.1699996143579,3.8153406225265E-6,-2.56153885349724E-6,0.25,-2.75970528136488E-7,2.89978478499492E-7,-2.76800235148636E-7,110.5183029,110.5183029,99.6243667602539,99.6243667602539,56.5281561392944,20.5386957302384,22.149702,0,0,0,40,4374,112.7746,99.6243667602539,,,,,,,,,,,,,0,,,,-0.0049,,,,,,110.5183029,,,,
,31849793.375,114.0200577,99.6243667602539,7.02124458350829E-9,3.08035327616408E-7,1,0.999253354069792,40.0298881530762,1.99485067717976,21.1699996143579,5.20642274339379E-7,-2.50506540612939E-6,0.25,-2.21813353072553E-7,7.59185037710601E-9,-2.23039240315968E-7,114.0200577,114.0200577,99.6243667602539,99.6243667602539,56.5117419403906,20.5408327907642,22.529354,0,0,0,40,4374,116.3233,99.6243667602539,,,,,,,,,,,,,0,,,,-0.00245,,,,,,114.0200577,,,,
,31849933.87,117.5215454,99.6243667602539,-3.23226047131453E-7,3.17375927056363E-7,1,0.999253354069792,40.0298881530762,1.99495703659991,21.1699996143579,-2.86179608486579E-6,-5.26738976824143E-6,0.25,-4.0727312549812E-7,-3.24094926646347E-7,-4.10273729297721E-7,117.5215454,117.5215454,99.6243667602539,99.6243667602539,56.7563916669098,20.5415693182175,22.149702,0,0,0,40,4374,119.85575,99.6243667602539,,,,,,,,,,,,,0,,,,0.00245,,,,,,117.5215454,,,,
,31850074.565,121.0132141,99.6243667602539,-1.99895350679401E-7,2.99378110485387E-7,1,0.999253354069792,40.0298881530762,1.98348123979677,21.1200006306171,-1.75552014052016E-6,-3.26708194074228E-6,0.25,-2.54332190037701E-7,-2.0044407610717E-7,-2.56167549940893E-7,121.0132141,121.0132141,99.6243667602539,99.6243667602539,56.9478906541214,20.5376418163453,22.149702,0,0,0,40,4374,123.3853,99.6243667602539,,,,,,,,,,,,,0,,,,-0.00245,,,,,,121.0132141,,,,
,31850214.96,124.5115738,99.6243667602539,3.02785297107055E-7,3.30736869046516E-7,1,0.999253354069792,40.0298881530762,1.98369352350384,21.1200006306171,4.17168556880221E-6,-3.70582274901144E-6,0.25,-3.80998243119435E-7,3.0522680579686E-7,-3.82447358837288E-7,124.4838486,124.539299,99.6243667602539,99.6243667602539,56.6086638767752,20.5459784723752,22.149702,0,0,0,40,4374,126.92345,99.6243667602539,,,,,,,,,,,,,0,,,,-0.0049,,,,,,124.5115738,,,,
,31850354.74,128.0052643,99.6243667602539,3.00071856540189E-7,2.4868630220285E-7,1,0.999253354069792,40.0298881530762,1.9835129906819,21.1200006306171,3.9457579685438E-6,-2.59802237116988E-6,0.25,-2.82446889262418E-7,3.02250455847889E-7,-2.83373303433518E-7,128.0052643,128.0052643,99.6243667602539,99.6243667602539,57.1448610409676,20.5477436290546,22.149702,0,0,0,40,4374,130.4307,99.6243667602539,,,,,,,,,,,,,0,,,,0,,,,,,128.0052643,,,,
,31850476.28,131.0427094,99.6243667602539,-6.19092382192421E-8,2.67831394252333E-7,1,0.999253354069792,40.0298881530762,1.99491489195436,21.0699997842312,-8.43348078308963E-8,-3.66703671756925E-6,0.25,-3.12146837312088E-7,-6.16414467607556E-8,-3.13929945934832E-7,131.0427094,131.0427094,99.6243667602539,99.6243667602539,56.8494054606983,20.534659303051,22.529354,0,0,0,40,4374,133.4743,99.6243667602539,,,,,,,,,,,,,0,,,,0,,,,,,131.0427094,,,,
,31850616.325,134.5000458,99.6243667602539,3.06287048592215E-7,3.44903889605802E-7,1,0.999253354069792,40.0298881530762,1.99498341704765,21.0699997842312,3.9124905496515E-6,-1.88531654124523E-6,0.25,-2.19477264344932E-7,3.08302699676848E-7,-2.20068954362408E-7,134.5000458,134.5000458,99.6243667602539,99.6243667602539,56.9220969129868,20.5359310951927,22.909004,0,0,0,40,4374,136.9962,99.6243667602539,,,,,,,,,,,,,0,,,,0,,,,,,134.5000458,,,,
,31850757.32,138.0423279,99.6243667602539,3.87896604352437E-7,2.93112768861062E-7,1,0.999253354069792,40.0298881530762,1.99497788821827,21.0699997842312,4.12067948785934E-6,2.39304613945989E-6,0.25,1.43127077404955E-7,3.8965549495459E-7,1.44555610993191E-7,138.0423279,138.0423279,99.6243667602539,99.6243667602539,56.8173586914099,20.5356633632817,23.288654,0,0,0,40,4374,140.53405,99.6243667602539,,,,,,,,,,,,,0,,,,0.0049,,,,,,138.0423279,,,,
,31850877.365,141.00671385,99.6243667602539,-6.31322892364614E-8,3.21078308382339E-7,1,0.999253354069792,40.0298881530762,2.00751898989501,21.0200008004904,-7.48308340556173E-7,3.06914704914828E-8,0.25,1.36932328188431E-8,-6.34790507836166E-8,1.3655221522099E-8,140.9812164,141.0322113,99.6243667602539,99.6243667602539,56.496109370006,20.5345498691179,22.529354,0,0,0,40,4374,143.54995,99.6243667602539,,,,,,,,,,,,,0,,,,0,,,,,,141.00671385,,,,
,31851017.485,144.514061,99.6243667602539,3.0393643164825E-7,3.14700459998929E-7,1,0.999253354069792,40.0298881530762,1.99486293434265,21.0200008004904,3.97275486775704E-6,-2.39738768070876E-6,0.25,-2.64159893326277E-7,3.05904602181146E-7,-2.64989039189423E-7,144.4885712,144.5395508,99.6243667602539,99.6243667602539,56.7579549239483,20.5374394525591,23.288654,0,0,0,40,4374,147.058,99.6243667602539,,,,,,,,,,,,,0,,,,-0.00245,,,,,,144.514061,,,,
,31851157.97,148.0070496,99.6243667602539,4.24993199469272E-7,2.89170822022851E-7,1,0.999253354069792,40.0298881530762,1.99494999478355,21.0200008004904,5.82528138736645E-6,-4.90580050822515E-6,0.25,-5.06219039651367E-7,4.27906888710383E-7,-5.0804975810511E-7,148.0070496,148.0070496,99.6243667602539,99.6243667602539,56.9861904515637,20.5403562924722,23.668306,0,0,0,40,4374,150.5943,99.6243667602539,,,,,,,,,,,,,0,,,,-0.0049,,,,,,148.0070496,,,,
,31851278.07,151.00228885,99.6243667602539,2.83997416837101E-7,3.45589699301153E-7,1,0.999253354069792,40.0298881530762,1.983552669088,20.9699999541044,3.29836954313914E-6,2.76290932954252E-8,0.25,-4.70150760477732E-8,2.8545658887538E-7,-4.68043564068075E-8,150.9770508,151.0275269,99.6243667602539,99.6243667602539,56.6438371601406,20.5364257589112,22.909004,0,0,0,40,4374,153.5941,99.6243667602539,,,,,,,,,,,,,0,,,,0,,,,,,151.00228885,,,,
,31851419.38,154.5172119,99.6243667602539,5.46836695286813E-7,3.51343827230987E-7,1,0.999253354069792,40.0298881530762,1.98368844081558,20.9699999541044,5.84063467102934E-6,2.98326955195059E-6,0.25,1.69064536561809E-7,5.49203370058185E-7,1.70694944415055E-7,154.4919128,154.542511,99.6243667602539,99.6243667602539,56.7212183835445,20.5426138553432,23.668306,0,0,0,40,4374,157.13585,99.6243667602539,,,,,,,,,,,,,0,,,,-0.00245,,,,,,154.5172119,,,,
,31851560.455,158.0544434,99.6243667602539,9.0577504378951E-7,3.01814358672614E-7,1,0.999253354069792,40.0298881530762,1.98347170409161,20.9699999541044,1.05628309070849E-5,-1.7371431017978E-7,0.25,-1.73057003286384E-7,9.10282735607216E-7,-1.72553708135228E-7,158.0544434,158.0544434,99.6243667602539,99.6243667602539,56.3225878387367,20.5375740175914,23.288654,0,0,0,40,4374,160.67275,99.6243667602539,,,,,,,,,,,,,0,,,,0.0049,,,,,,158.0544434,,,,
,31851699.43,161.5329132,99.6243667602539,7.46967211079606E-7,2.92825672028151E-7,1,0.999253354069792,40.0298881530762,1.98363872621673,20.9100004285574,8.42812878483804E-6,1.48043447106988E-6,0.25,1.18217547137789E-9,7.50405613635395E-7,2.24124016794971E-9,161.5329132,161.5329132,99.6243667602539,99.6243667602539,56.5992843345444,20.5317828014064,22.909004,0,0,0,40,4374,164.14365,99.6243667602539,,,,,,,,,,,,,0,,,,-0.0049,,,,,,161.5329132,,,,
,31851840.09,165.0521088,99.6243667602539,6.72186828783854E-7,3.08205191269156E-7,1,0.999253354069792,40.0298881530762,1.98370695484927,20.9100004285574,8.3122047513389E-6,-2.8540260818974E-6,0.25,-3.69838690306037E-7,6.75723996469267E-7,-3.70585567451903E-7,165.0521088,165.0521088,99.6243667602539,99.6243667602539,56.8783257159099,20.5347178030574,23.668306,0,0,0,40,4374,167.6761,99.6243667602539,,,,,,,,,,,,,0,,,,-0.0049,,,,,,165.0521088,,,,
,31851979.47,168.5164337,99.6243667602539,7.09304969705954E-7,3.34089566230943E-7,1,0.999253354069792,40.0298881530762,1.98342531078053,20.9100004285574,8.26143052157291E-6,-9.29209781833091E-8,0.25,-1.31613495357812E-7,7.12609281336239E-7,-1.31249677178527E-7,168.5164337,168.5164337,99.6243667602539,99.6243667602539,56.6375841319868,20.5353511854905,23.668306,0,0,0,40,4374,171.16675,99.6243667602539,,,,,,,,,,,,,0,,,,-0.00245,,,,,,168.5164337,,,,
,31852118.68,172.00364685,99.6243667602539,6.34213837904245E-7,3.47826197760305E-7,1,0.999253354069792,40.0298881530762,1.98340328101142,20.8599995821714,7.85894595342091E-6,-2.80282023197615E-6,0.25,-3.58728929461745E-7,6.37413204021642E-7,-3.59453838085426E-7,171.979538,172.0277557,99.6243667602539,99.6243667602539,56.3999690621406,20.5331515047982,23.668306,0,0,0,40,4374,174.6379,99.6243667602539,,,,,,,,,,,,,0,,,,-0.0049,,,,,,172.00364685,,,,
,31852260.17,175.52306365,99.6243667602539,7.72480444970094E-7,3.65962291679223E-7,1,0.999253354069792,40.0298881530762,1.98335878676472,20.8700001239777,8.45055404951418E-6,3.03034461539298E-6,0.25,1.34322690806552E-7,7.75562561466457E-7,1.35862534977862E-7,175.4975128,175.5486145,99.6243667602539,99.6243667602539,55.7504357626598,20.5468187663499,23.668306,0,0,0,40,4374,178.1792,99.6243667602539,,,,,,,,,,,,,0,,,,-0.0049,,,,,,175.52306365,,,,
,31852399.255,179.016571,99.6243667602539,1.46166754069404E-6,3.41575614423853E-7,1,0.999253354069792,40.0298881530762,1.98322503746493,20.8599995821714,1.71537810295121E-5,-9.76973466616679E-7,0.25,-3.40714296453664E-7,1.46808781382156E-6,-3.40315974809057E-7,179.016571,179.016571,99.6243667602539,99.6243667602539,56.4195097751214,20.5397858798187,24.047956,0,0,0,40,4374,181.6561,99.6243667602539,,,,,,,,,,,,,0,,,,-0.00245,,,,,,179.016571,,,,
,31852518.74,182.0089264,99.6243667602539,9.31270393974486E-7,3.75547939770157E-7,1,0.999253354069792,40.0298881530762,1.9944329754439,20.8000000566244,1.05952672699688E-5,1.62854939668737E-6,0.25,-1.82369074351668E-8,9.35032312521731E-7,-1.71893910865126E-8,181.9844971,182.0333557,99.6243667602539,99.6243667602539,56.2921043264867,20.5326700651076,24.047956,0,0,0,40,4374,184.65155,99.6243667602539,,,,,,,,,,,,,0,,,,-0.00245,,,,,,182.0089264,,,,
,31852659.65,185.51142885,99.6243667602539,1.30219171596307E-6,2.85023046119534E-7,1,0.999253354069792,40.0298881530762,1.9945467953862,20.8000000566244,1.52590944396577E-5,-2.81010221558229E-7,0.25,-2.51081373466613E-7,1.30757740975642E-6,-2.50533932961022E-7,185.4858246,185.5370331,99.6243667602539,99.6243667602539,56.6063189912175,20.5334329179618,24.047956,0,0,0,40,4374,188.18025,99.6243667602539,,,,,,,,,,,,,0,,,,-0.00245,,,,,,185.51142885,,,,
,31852799.93,189.00672915,99.6243667602539,1.52895140301999E-6,2.77893458469164E-7,1,0.999253354069792,40.0298881530762,1.99462766326489,20.8000000566244,1.80247868276567E-5,-9.62112202730278E-7,0.25,-3.50522178060709E-7,1.53516591592281E-6,-3.50101781613172E-7,188.9797516,189.0337067,99.6243667602539,99.6243667602539,56.4531198014483,20.5386091479796,24.427608,0,0,0,40,4374,191.69485,99.6243667602539,,,,,,,,,,,,,0,,,,0.0049,,,,,,189.00672915,,,,
touchdown = 16.0900000482798 mm,31852934.53,192.363205,99.6243667602539,1.38281116905654E-6,2.88595308977012E-7,1,0.999253354069792,40.0298881530762,1.99458062200203,20.7499992102385,1.65802846834163E-5,-2.48466872844523E-6,0.25,-4.59416190213716E-7,1.38843843788642E-6,-4.59564322342118E-7,192.363205,192.363205,99.6243667602539,99.6243667602539,56.1936191330636,20.5386820818091,24.047956,0,0,0,40,4374,195.08295,99.6243667602539,,,,,,,,,,,,,0,,,,0,,,,,,192.363205,,,,
,31853061.405,195.52584075,99.6243667602539,1.581304370403E-6,3.59597490559673E-7,1,0.999253354069792,40.0298881530762,1.99474158705931,20.7499992102385,1.74014327527302E-5,6.12960817519081E-6,0.25,2.66052507934862E-7,1.58670035603906E-6,2.68746359638741E-7,195.502594,195.5490875,99.6243667602539,99.6243667602539,56.7946914643522,20.5348309742324,24.427608,0,0,0,40,4374,198.26525,99.6243667602539,,,,,,,,,,,,,0,,,,0,,,,,,195.52584075,,,,
,31853201.68,199.0065002,99.6243667602539,1.34330769483843E-6,3.57196156167902E-7,1,0.999253354069792,40.0298881530762,1.99494301090555,20.7499992102385,1.55939002232396E-5,5.33751607948565E-7,0.25,-1.86218702097324E-7,1.34819073847438E-6,-1.85424887758335E-7,199.0065002,199.0065002,99.6243667602539,99.6243667602539,56.8916134007368,20.5371080026535,24.427608,0,0,0,40,4374,201.79115,99.6243667602539,,,,,,,,,,,,,0,,,,0,,,,,,199.0065002,,,,
touchdown = 16.0700008273125 mm,31853349.03,202.7008667,99.6243667602539,1.51784715365553E-6,3.43366464077033E-7,1,0.999253354069792,40.0298881530762,2.00753031040014,20.7299999892712,1.7619824306013E-5,1.20629542549692E-6,0.25,-1.57789942815078E-7,1.5231235284673E-6,-1.56727282280385E-7,202.7008667,202.7008667,99.6243667602539,99.6243667602539,56.2436433582944,20.528612321097,24.047956,0,0,0,40,4374,205.4802,99.6243667602539,,,,,,,,,,,,,0,,,,0,,,,,,202.7008667,,,,
,31853482.045,206.01099395,99.6243667602539,2.23833899480664E-6,3.29732742724297E-7,1,0.999253354069792,40.0298881530762,1.99488760239298,20.7299999892712,2.55465438249384E-5,3.36953745775134E-6,0.25,-9.13267477222891E-8,2.24572840861763E-6,-8.93203179089727E-8,205.9836426,206.0383453,99.6243667602539,99.6243667602539,56.9056827140829,20.5345580262941,24.427608,0,0,0,40,4374,208.806,99.6243667602539,,,,,,,,,,,,,0,,,,0,,,,,,206.01099395,,,,
,31853623.625,209.5279999,99.6243667602539,2.05886990865555E-6,4.12769218730062E-7,1,0.999253354069792,40.0298881530762,1.99448612430455,20.7299999892712,2.39761581490251E-5,3.03873429457999E-7,0.25,-3.3062272903923E-7,2.06567586308829E-6,-3.29586401100288E-7,209.5279999,209.5279999,99.6243667602539,99.6243667602539,56.6438371601406,20.5314253662538,24.427608,0,0,0,40,4374,212.34625,99.6243667602539,,,,,,,,,,,,,0,,,,-0.0049,,,,,,209.5279999,,,,
touchdown = 15.990000218153 mm,31853764.03,213.0325623,99.6243667602539,2.2586059674223E-6,3.85383744526735E-7,1,0.999253354069792,40.0298881530762,1.99453723634297,20.6499993801117,2.55103305451036E-5,4.8803702493548E-6,0.25,3.87324629665541E-8,2.26540601139307E-6,4.10811172180993E-8,213.0325623,213.0325623,99.6243667602539,99.6243667602539,56.4632809721983,20.5280909289485,24.807261,0,0,0,40,4374,215.8748,99.6243667602539,,,,,,,,,,,,,0,,,,0,,,,,,213.0325623,,,,
,31853902.785,216.5235138,99.6243667602539,2.77566905722724E-6,3.86540811143154E-7,1,0.999253354069792,40.0298881530762,1.99456741780128,20.6499993801117,3.12633333208137E-5,6.48039488575865E-6,0.25,9.03249178314365E-8,2.7836616454693E-6,9.32770393844933E-8,216.5235138,216.5235138,99.6243667602539,99.6243667602539,56.5273745107752,20.5360687815994,24.807261,0,0,0,40,4374,219.3432,99.6243667602539,,,,,,,,,,,,,0,,,,0,,,,,,216.5235138,,,,
,31854044.02,220.0281982,99.6243667602539,3.19049696585821E-6,4.45326828648325E-7,1,0.999253354069792,40.0298881530762,1.9944814528006,20.6499993801117,3.63328533934463E-5,5.1265202547813E-6,0.25,-1.01068866107327E-7,3.19950443938178E-6,-9.83198687804673E-8,220.0281982,220.0281982,99.6243667602539,99.6243667602539,56.8329912617945,20.5342109559673,24.427608,0,0,0,40,4374,222.882,99.6243667602539,,,,,,,,,,,,,0,,,,-0.00245,,,,,,220.0281982,,,,
touchdown = 15.930000692606 mm,31854179.66,223.4277496,99.6243667602539,3.19648938545392E-6,3.96660977687081E-7,1,0.999253354069792,40.0298881530762,1.99490890511185,20.5899998545647,3.61954188477713E-5,6.34050857241847E-6,0.25,5.08587183108061E-9,3.20504458002712E-6,8.0810913730648E-9,223.4277496,223.4277496,99.6243667602539,99.6243667602539,56.3429101802367,20.5353032066514,24.807261,0,0,0,40,4374,226.28035,99.6243667602539,,,,,,,,,,,,,0,,,,0,,,,,,223.4277496,,,,
,31854304.47,226.5498199,99.6243667602539,3.5659428360662E-6,4.00737643881819E-7,1,0.999253354069792,40.0298881530762,1.99451159684663,20.5899998545647,4.00254349194006E-5,9.03947963429026E-6,0.25,1.79548842294258E-7,3.57494783314822E-6,1.83281964739855E-7,226.5498199,226.5498199,99.6243667602539,99.6243667602539,56.8087607776983,20.5303523208201,24.807261,0,0,0,40,4374,229.4003,99.6243667602539,,,,,,,,,,,,,0,,,,-0.0049,,,,,,226.5498199,,,,
,31854443.865,230.0112305,99.6243667602539,3.7243234447542E-6,4.45790472532902E-7,1,0.999253354069792,40.0298881530762,1.9943093446532,20.5899998545647,4.24205919468701E-5,5.82863809851428E-6,0.25,-1.31321321334009E-7,3.73357673943937E-6,-1.28288785885852E-7,229.9889069,230.0335541,99.6243667602539,99.6243667602539,56.2522412720059,20.5394533549697,24.427608,0,0,0,40,4374,232.90235,99.6243667602539,,,,,,,,,,,,,0,,,,-0.00245,,,,,,230.0112305,,,,
touchdown = 15.8699993044138 mm,31854594.3,233.7722015,99.6243667602539,3.94625426723722E-6,3.27515967232704E-7,1,0.999253354069792,40.0298881530762,1.99458636941309,20.5300003290176,4.50176377691572E-5,5.77763851418305E-6,0.25,-1.74264995295496E-7,3.95557567594146E-6,-1.71183717895727E-7,233.7722015,233.7722015,99.6243667602539,99.6243667602539,56.6477453027368,20.5316157771979,24.807261,0,0,0,40,4374,236.6813,99.6243667602539,,,,,,,,,,,,,0,,,,-0.0049,,,,,,233.7722015,,,,
,31854724.775,237.0150146,99.6243667602539,4.38676733241039E-6,3.61088687556557E-7,1,0.999253354069792,40.0298881530762,1.99435946282901,20.5400008708239,4.99080711387493E-5,7.1343876759472E-6,0.25,-1.30640912286522E-7,4.39657843960297E-6,-1.27117791468461E-7,237.0150146,237.0150146,99.6243667602539,99.6243667602539,56.1224909378136,20.5441547890639,25.186911,0,0,0,40,4374,239.9376,99.6243667602539,,,,,,,,,,,,,0,,,,0,,,,,,237.0150146,,,,
,31854865.775,240.50777435,99.6243667602539,4.64112071682539E-6,3.65613710418033E-7,1,0.999253354069792,40.0298881530762,1.99440327987684,20.5300003290176,5.35776306744017E-5,3.04398481307009E-6,0.25,-5.36056326239361E-7,4.65127367034384E-6,-5.33213944479666E-7,240.4823914,240.5331573,99.6243667602539,99.6243667602539,56.4367056025444,20.5452300716837,25.186911,0,0,0,40,4374,243.48865,99.6243667602539,,,,,,,,,,,,,0,,,,0.00245,,,,,,240.50777435,,,,
touchdown = 15.8099997788668 mm,31855011.54,244.1782379,99.6243667602539,5.36732714236227E-6,4.12870567048458E-7,1,0.999253354069792,40.0298881530762,1.99454711221176,20.4799994826317,6.11860239772006E-5,7.96677748496304E-6,0.25,-2.2692058538838E-7,5.37804035237565E-6,-2.22864595211506E-7,244.1782379,244.1782379,99.6243667602539,99.6243667602539,56.2874145553713,20.5446232397757,25.186911,0,0,0,40,4374,247.13685,99.6243667602539,,,,,,,,,,,,,0,,,,0,,,,,,244.1782379,,,,
,31855145.685,247.50521085,99.6243667602539,5.59688494579173E-6,3.38679857870339E-7,1,0.999253354069792,40.0298881530762,1.99444346994625,20.4700008034706,6.35854663705913E-5,9.49862428885712E-6,0.25,-1.31158662043699E-7,5.60731202665194E-6,-1.26782885107375E-7,247.4777679,247.5326538,99.6243667602539,99.6243667602539,56.7173102409483,20.5432558494074,25.186911,0,0,0,40,4374,250.5039,99.6243667602539,,,,,,,,,,,,,0,,,,-0.00245,,,,,,247.50521085,,,,
,31855287.285,251.0526886,99.6243667602539,6.02348798896637E-6,4.26807470656471E-7,1,0.999253354069792,40.0298881530762,1.99425425388932,20.4700008034706,6.85399457811223E-5,9.51306792392395E-6,0.25,-2.03601756999318E-7,6.03400510518471E-6,-1.99065223346995E-7,251.0526886,251.0526886,99.6243667602539,99.6243667602539,56.5375356815252,20.5477125800937,25.186911,0,0,0,40,4374,254.04065,99.6243667602539,,,,,,,,,,,,,0,,,,0,,,,,,251.0526886,,,,
touchdown = 15.7500002533197 mm,31855429.61,254.599762,99.6243667602539,6.54787926722266E-6,3.83148861803392E-7,1,0.999253354069792,40.0298881530762,1.9942781078136,20.4099994152784,7.49449466218206E-5,7.76457520677165E-6,0.25,-4.48932881075797E-7,6.55866903192451E-6,-4.44425135600831E-7,254.599762,254.599762,99.6243667602539,99.6243667602539,56.2280107879098,20.5486919646469,25.566563,0,0,0,40,4374,257.6299,99.6243667602539,,,,,,,,,,,,,0,,,,-0.0049,,,,,,254.599762,,,,
,31855567.89,258.0267029,99.6243667602539,6.7877281248345E-6,3.61857343000422E-7,1,0.999253354069792,40.0298881530762,1.99427940547774,20.4099994152784,7.75116937166611E-5,9.02294605027701E-6,0.25,-3.79089904294E-7,6.79801432736045E-6,-3.74319260752322E-7,258.0267029,258.0267029,99.6243667602539,99.6243667602539,56.6399290175445,20.5460299036504,25.566563,0,0,0,40,4374,261.0721,99.6243667602539,,,,,,,,,,,,,0,,,,-0.0049,,,,,,258.0267029,,,,
,31855707.83,261.5067444,99.6243667602539,7.56812414742419E-6,3.61050532285481E-7,1,0.999253354069792,40.0298881530762,1.99439080348104,20.4099994152784,8.55876785679404E-5,1.48442999226142E-5,0.25,5.02589406987893E-10,7.5783242160389E-6,6.34954654765694E-9,261.5067444,261.5067444,99.6243667602539,99.6243667602539,57.0315249056791,20.5446347703412,25.186911,0,0,0,40,4374,264.58665,99.6243667602539,,,,,,,,,,,,,0,,,,-0.00245,,,,,,261.5067444,,,,
touchdown = 15.6900007277727 mm,31855848.365,264.9987183,99.6243667602539,7.61491688290467E-6,3.28828764855732E-7,1,0.999253354069792,40.0298881530762,1.99430007305681,20.3499998897314,8.62952281524556E-5,1.38213473135086E-5,0.25,-9.77669377089714E-8,7.62430708815958E-6,-9.2096689851439E-8,264.9987183,264.9987183,99.6243667602539,99.6243667602539,56.0920074255636,20.5453794295161,25.186911,0,0,0,40,4374,268.0956,99.6243667602539,,,,,,,,,,,,,0,,,,0,,,,,,264.9987183,,,,
,31855968.385,268.0041199,99.6243667602539,7.71318595873352E-6,4.10300933183393E-7,1,0.999253354069792,40.0298881530762,1.99431843872779,20.3499998897314,8.68891456378846E-5,1.69467035358151E-5,0.25,1.61825554213518E-7,7.72167311365703E-6,1.67792334226199E-7,268.0041199,268.0041199,99.6243667602539,99.6243667602539,56.5930313063906,20.5483582092119,25.946213,0,0,0,40,4374,271.10815,99.6243667602539,,,,,,,,,,,,,0,,,,0,,,,,,268.0041199,,,,
,31856110.255,271.5345764,99.6243667602539,8.75473288129113E-6,4.29495906975838E-7,1,0.999253354069792,40.0298881530762,1.99447160656769,20.3499998897314,9.81181735803605E-5,2.21119088098912E-5,0.25,4.38328186417024E-7,8.76307529352439E-6,4.45227607706011E-7,271.5345764,271.5345764,99.6243667602539,99.6243667602539,56.9619599674676,20.5486910747836,25.566563,0,0,0,40,4374,274.65245,99.6243667602539,,,,,,,,,,,,,0,,,,0,,,,,,271.5345764,,,,
,31856252.59,275.0484009,99.6243667602539,,,2,,,,20.2999993395805,,,,,,,275.0484009,275.0484009,99.6243667602539,99.6243667602539,,,25.566563,,,,-99999999,4374,278.2193,99.6243667602539,,,,,,,,,,,,,,,,,,,,,,,275.0484009,,,,
,31856370.69,278.01690675,99.6243667602539,9.106264180441E-6,4.547890905333E-7,1,0.999253354069792,40.0298881530762,1.99459355405999,20.2799998223782,0.000102780840078951,1.87232438703524E-5,0.25,7.81334107175701E-8,9.11310894914896E-6,8.47303074920271E-8,277.9909363,278.0428772,99.6243667602539,99.6243667602539,56.7305979257752,20.5444359359938,25.946213,0,0,0,40,4374,281.1718,99.6243667602539,,,,,,,,,,,,,0,,,,0,,,,,,278.01690675,,,,
,31856510.38,281.50958255,99.6243667602539,9.31664934486978E-6,3.60653548592732E-7,1,0.999253354069792,40.0298881530762,1.99450875543013,20.2799998223782,0.000105891481662999,1.48049897568045E-5,0.25,-3.04651318242523E-7,9.32275914661575E-6,-2.9825355395676E-7,281.4810486,281.5381165,99.6243667602539,99.6243667602539,56.4804767996214,20.5448643059679,25.566563,0,0,0,40,4374,284.64515,99.6243667602539,,,,,,,,,,,,,0,,,,0,,,,,,281.50958255,,,,
,31856652.045,285.0290527,99.6243667602539,9.05855562125164E-6,3.86867083920104E-7,1,0.999253354069792,40.0298881530762,1.99453508771999,20.2799998223782,0.000101689067153193,2.16482210335955E-5,0.25,3.45888399977838E-7,9.06290314577187E-6,3.52376554985377E-7,285.0290527,285.0290527,99.6243667602539,99.6243667602539,56.8666012881214,20.5452921090679,25.946213,0,0,0,40,4374,288.1973,99.6243667602539,,,,,,,,,,,,,0,,,,0.0049,,,,,,285.0290527,,,,
,31856773.065,288.0405884,99.6243667602539,9.74375512250764E-6,4.50993267698181E-7,1,0.999253354069792,40.0298881530762,1.99467961368192,20.2300008386374,0.000110425274636771,1.72339561448245E-5,0.25,-1.63333963182726E-7,9.74775184078972E-6,-1.5669361111204E-7,288.0405884,288.0405884,99.6243667602539,99.6243667602539,56.2412984727367,20.5394103460249,25.946213,0,0,0,40,4374,291.2304,99.6243667602539,,,,,,,,,,,,,0,,,,0.0049,,,,,,288.0405884,,,,
,31856912.51,291.5164795,99.6243667602539,1.00381652153581E-5,4.06701881980799E-7,1,0.999253354069792,40.0298881530762,1.99463258449096,20.2300008386374,0.000114084076672359,1.57955993442097E-5,0.25,-3.41334414125553E-7,1.00411488986206E-5,-3.34618321847793E-7,291.4895325,291.5434265,99.6243667602539,99.6243667602539,56.4945461129675,20.540391870166,26.325863,0,0,0,40,4374,294.72805,99.6243667602539,,,,,,,,,,,,,0,,,,-0.0049,,,,,,291.5164795,,,,
,31857052.56,295.01049805,99.6243667602539,9.56603176116217E-6,4.74897522825222E-7,1,0.999253354069792,40.0298881530762,1.99453020877726,20.2300008386374,0.000107225440256674,2.35564932789736E-5,0.25,4.27825441140204E-7,9.56717225702151E-6,4.34287348370216E-7,294.9870911,295.033905,99.6243667602539,99.6243667602539,56.8986480574099,20.5383305397248,25.946213,0,0,0,40,4374,298.22965,99.6243667602539,,,,,,,,,,,,,0,,,,0,,,,,,295.01049805,,,,
,31857194.53,298.5395203,99.6243667602539,8.98912198367671E-6,3.86865173882124E-7,1,0.999253354069792,40.0298881530762,1.99464398418706,20.1699994504452,0.000102682561642966,1.0989651233847E-5,0.25,-5.84514336308533E-7,8.98971421702379E-6,-5.78600296825701E-7,298.5395203,298.5395203,99.6243667602539,99.6243667602539,56.7571732954291,20.535292436179,25.946213,0,0,0,40,4374,301.7899,99.6243667602539,,,,,,,,,,,,,0,,,,-0.0049,,,,,,298.5395203,,,,
,31857333.86,302.0023499,99.6243667602539,9.33023237026737E-6,4.12878151585676E-7,1,0.999253354069792,40.0298881530762,1.99452153877126,20.1699994504452,0.000105405283281591,1.80673323617704E-5,0.25,-1.66586459593826E-8,9.32930481700912E-6,-1.05883185739342E-8,302.0023499,302.0023499,99.6243667602539,99.6243667602539,56.5070521692752,20.5375681325543,25.946213,0,0,0,40,4374,305.2791,99.6243667602539,,,,,,,,,,,,,0,,,,-0.00245,,,,,,302.0023499,,,,
,31857475.835,305.5252533,99.6243667602539,9.58032693848164E-6,4.62901707991494E-7,1,0.999253354069792,40.0298881530762,1.9944605754088,20.1699994504452,0.000108819706230778,1.50518016979227E-5,0.25,-3.26705650358388E-7,9.57837075028106E-6,-3.20485983258846E-7,305.4991455,305.5513611,99.6243667602539,99.6243667602539,56.4429586306983,20.541590565514,26.325863,0,0,0,40,4374,308.8518,99.6243667602539,,,,,,,,,,,,,0,,,,0.00245,,,,,,305.5252533,,,,
,31857616.185,309.0185089,99.6243667602539,9.59755223642386E-6,4.31524035493483E-7,1,0.999253354069792,40.0298881530762,2.00735897040766,20.1099999248981,0.000109667148127899,1.52112991987094E-5,0.25,-3.23577038565843E-7,9.5943956903021E-6,-3.17388813324058E-7,308.9899902,309.0470276,99.6243667602539,99.6243667602539,56.4976726270444,20.532007774354,25.946213,0,0,0,40,4374,312.3746,99.6243667602539,,,,,,,,,,,,,0,,,,0.00245,,,,,,309.0185089,,,,
,31857756.68,312.5202637,99.6243667602539,9.42699101070992E-6,4.45101083238849E-7,1,0.999253354069792,40.0298881530762,2.00731611054849,20.1099999248981,0.000107710896036014,1.48910044387274E-5,0.25,-3.21958199045491E-7,9.42272006854704E-6,-3.1591635462821E-7,312.5202637,312.5202637,99.6243667602539,99.6243667602539,56.6086638767752,20.5333398049464,26.325863,0,0,0,40,4374,315.8859,99.6243667602539,,,,,,,,,,,,,0,,,,0,,,,,,312.5202637,,,,
,31857898.905,316.0431061,99.6243667602539,9.7592782071046E-6,4.72114463200521E-7,1,0.999253354069792,40.0298881530762,2.0072742231608,20.1099999248981,0.000109804525456012,2.51524269160786E-5,0.25,5.24286324990125E-7,9.75310981025094E-6,5.29989626367956E-7,316.0163269,316.0698853,99.6243667602539,99.6243667602539,57.0393411908714,20.5340183612108,26.325863,0,0,0,40,4374,319.45675,99.6243667602539,,,,,,,,,,,,,0,,,,0,,,,,,316.0431061,,,,
,31858039.17,319.50920105,99.6243667602539,8.92661433356937E-6,4.15791319554498E-7,1,0.999253354069792,40.0298881530762,2.00749722882873,20.0699996203184,0.000101802076889938,1.51096375565826E-5,0.25,-2.15679522439602E-7,8.92030889424646E-6,-2.10089225880298E-7,319.4840698,319.5343323,99.6243667602539,99.6243667602539,56.5305010248521,20.5312619823964,25.946213,0,0,0,40,4374,322.9696,99.6243667602539,,,,,,,,,,,,,0,,,,0,,,,,,319.50920105,,,,
,31858179.625,323.0090942,99.6243667602539,9.56148054109177E-6,4.87317387263333E-7,1,0.999253354069792,40.0298881530762,2.0074069315761,20.0699996203184,0.000108577208700746,1.87623516153708E-5,0.25,-3.66365228449517E-9,9.55341307301303E-6,2.08898280712827E-9,323.0090942,323.0090942,99.6243667602539,99.6243667602539,56.8017261210252,20.5334897708928,26.705515,0,0,0,40,4374,326.4888,99.6243667602539,,,,,,,,,,,,,0,,,,0,,,,,,323.0090942,,,,
,31858320.4,326.5130463,99.6243667602539,9.34500166345969E-6,4.31538526587474E-7,1,0.999253354069792,40.0298881530762,2.00743405113888,20.0699996203184,0.000106935669337789,1.35524591982221E-5,0.25,-4.24793081474992E-7,9.33622168906444E-6,-4.18831152875104E-7,326.4849854,326.5411072,99.6243667602539,99.6243667602539,56.9510171681983,20.5332670688223,26.325863,0,0,0,40,4374,330.0228,99.6243667602539,,,,,,,,,,,,,0,,,,-0.00245,,,,,,326.5130463,,,,
,31858442.76,329.5511627,99.6243667602539,9.11922666757657E-6,4.05153114204205E-7,1,0.999253354069792,40.0298881530762,2.00751005059905,20.0100000947714,0.000105065774448001,9.06095856056171E-6,0.25,-7.81177408671482E-7,9.10990660767769E-6,-7.74978127116295E-7,329.5244751,329.5778503,99.6243667602539,99.6243667602539,56.7173102409483,20.5270486665121,26.705515,0,0,0,40,4374,333.0887,99.6243667602539,,,,,,,,,,,,,0,,,,0,,,,,,329.5511627,,,,
,31858582.53,333.0201416,99.6243667602539,8.78262244202073E-6,4.7213360338882E-7,1,0.999253354069792,40.0298881530762,2.00727487392834,20.0100000947714,0.000100598135697239,1.19925474812281E-5,0.25,-4.64355396008191E-7,8.7724170276705E-6,-4.58697214599267E-7,333.0201416,333.0201416,99.6243667602539,99.6243667602539,56.7759323798906,20.5296439026394,26.325863,0,0,0,40,4374,336.602,99.6243667602539,,,,,,,,,,,,,0,,,,0,,,,,,333.0201416,,,,
,31858721.655,336.5065002,99.6243667602539,8.57171204405447E-6,4.6902509428745E-7,1,0.999253354069792,40.0298881530762,2.00719304918556,20.0100000947714,9.71096745614651E-5,1.78063248408506E-5,0.25,8.46872892572961E-8,8.56040793860697E-6,8.95027788462306E-8,336.5065002,336.5065002,99.6243667602539,99.6243667602539,56.6289862182752,20.5284328692609,26.705515,0,0,0,40,4374,340.0752,99.6243667602539,,,,,,,,,,,,,0,,,,0,,,,,,336.5065002,,,,
,31858843.775,339.5051575,99.6243667602539,8.73115347746516E-6,4.99354773462994E-7,1,0.999253354069792,40.0298881530762,2.00776554677315,19.9400000274181,0.000100157244432284,1.10690536584216E-5,0.25,-5.36710655105337E-7,8.71909486773607E-6,-5.30979799067099E-7,339.5051575,339.5051575,99.6243667602539,99.6243667602539,56.760299809506,20.5299509660923,26.325863,0,0,0,40,4374,343.1327,99.6243667602539,,,,,,,,,,,,,0,,,,0,,,,,,339.5051575,,,,
,31858984.93,343.02502445,99.6243667602539,8.60771660379461E-6,4.13339408137709E-7,1,0.999253354069792,40.0298881530762,2.00730536208271,19.9400000274181,9.9098041676399E-5,8.65493347082065E-6,0.25,-7.27714593509922E-7,8.59490174992607E-6,-7.21748153013172E-7,342.9983826,343.0516663,99.6243667602539,99.6243667602539,56.4617177151598,20.5317542424157,26.705515,0,0,0,40,4374,346.6777,99.6243667602539,,,,,,,,,,,,,0,,,,0,,,,,,343.02502445,,,,
,31859125.835,346.5079956,99.6243667602539,8.8809995712879E-6,5.57061633069182E-7,1,0.999253354069792,40.0298881530762,2.00723826556236,19.9400000274181,0.000101488824383437,1.32021765958082E-5,0.25,-3.74051211268034E-7,8.86651279348337E-6,-3.68481114661992E-7,346.5079956,346.5079956,99.6243667602539,99.6243667602539,56.7860935506406,20.5341884241462,27.085165,0,0,0,40,4374,350.2076,99.6243667602539,,,,,,,,,,,,,0,,,,0.00245,,,,,,346.5079956,,,,
,31859546.01,349.77774045,99.6243667602539,8.19039593639148E-6,4.46454416625792E-7,1,0.999253354069792,40.0298881530762,2.00741223591204,19.8800005018711,9.25064584066269E-5,1.8457321181221E-5,0.25,2.08798470655874E-7,8.1758205325324E-6,2.12987547838129E-7,349.7743835,349.7810974,99.6243667602539,99.6243667602539,56.6430555316214,20.5348736822694,26.325863,0,0,0,40,4369,350.82695,99.6243667602539,,,,,,,,,,,,,0,,,,-0.00245,,,,,,349.77774045,,,,