File: data/monolayers/magneticStructure/ML_Ac_CoFe_C-2/PPMS/BackupJuelich/data/DD175_23_HYST_100OE_10K.DAT
[Header]
; VSM Data File (default extension .dat)
; Copyright (c) 2003-2013, Quantum Design, Inc. All rights reserved.
TITLE,
FILEOPENTIME,31907355.64,01/05/2019,3:11 pm
BYAPP,VSM,2.0,2.0
INFO,PPMS VSM Option Release 1.4.10 Build 1,APPNAME
INFO,Quantum Design Linear Motor Servo Controller,MOTOR_MODULE_NAME
INFO,3101-100 M1,MOTOR_HW_VERSION
INFO,MMC1014,MOTOR_SERIAL_NUMBER
INFO,SRV No X-over 01.03.11,MOTOR_SOFTWARE_VERSION
INFO,Quantum Design VSM Detection Module,VSM_MODULE_NAME
INFO,3101-150 F0,VSM_HW_VERSION
INFO,VSM707,VSM_SERIAL_NUMBER
INFO,VSM No X-over 01.02.05 May 20 2008 13:51:47,VSM_SOFTWARE_VERSION
INFO,704,PREAMP_SERIAL_NUMBER
INFO,822,COIL_SERIAL_NUMBER
INFO,0,MOMENT_UNITS
INFO,CoFe2O4 Monolayer,SAMPLE_MATERIAL
INFO,from YF45,SAMPLE_COMMENT
INFO,29.98,SAMPLE_MASS
INFO,,SAMPLE_VOLUME
INFO,,SAMPLE_MOLECULAR_WEIGHT
INFO,,SAMPLE_SIZE
INFO,,SAMPLE_SHAPE
DATATYPE,COMMENT,1
DATATYPE,TIME,2
STARTUPAXIS,X,2
STARTUPAXIS,Y1,5
[Data]
Comment,Time Stamp (sec),Temperature (K),Magnetic Field (Oe),Moment (emu),M. Std. Err. (emu),Transport Action,Averaging Time (sec),Frequency (Hz),Peak Amplitude (mm),Center Position (mm),Coil Signal' (mV),Coil Signal" (mV),Range (mV),M. Quad. Signal (emu),M. Raw' (emu),M. Raw" (emu),Min. Temperature (K),Max. Temperature (K),Min. Field (Oe),Max. Field (Oe),Mass (grams),Motor Lag (deg),Pressure (Torr),VSM Status (code),Motor Status (code),Measure Status (code),Measure Count,PPMS Status (code),System Temp. (K),System Field (Oe),Sample Position (deg),Bridge 1 Resistance (ohms),Bridge 1 Excitation (에),Bridge 2 Resistance (ohms),Bridge 2 Excitation (에),Bridge 3 Resistance (ohms),Bridge 3 Excitation (에),Bridge 4 Resistance (ohms),Bridge 4 Excitation (에),Signal 1 Vin (V),Signal 2 Vin (V),Digital Inputs (code),Drive 1 Iout (mA),Drive 1 Ipower (W),Drive 2 Iout (mA),Drive 2 Ipower (W),Pressure (),Map 20 (),Map 21 (),Map 22 (),Map 23 (),Map 24 (),Map 25 (),Map 26 (),Map 27 (),Map 28 (),Map 29 ()
,31907370.17,9.9996834,-0.274027913808823,,,2,,,,21.5699992311001,,,,,,,9.9996834,9.9996834,-0.274027913808823,-0.274027913808823,,,9.241568,,,,-99999999,4369,10.0235,-0.274027913808823,,,,,,,,,,,,,,,,,,,,,,,9.9996834,,,,
,31907436.07,9.9995203,920.347320556641,4.71685671526553E-5,2.90804751504481E-7,1,0.999253354069792,40.0298881530762,1.99296417266058,21.5600002557039,0.000528143261657395,9.84154786817583E-5,0.25,3.98420578293877E-7,4.68973471949402E-5,6.25458406305056E-7,9.9995203,9.9995203,900.4853515625,940.209289550781,55.7887355601021,20.5479518680182,9.621219,0,0,0,40,4449,10.02335,920.347320556641,,,,,,,,,,,,,0,,,,0.00245,,,,,,9.9995203,,,,
,31907456.715,9.9981947,1947.5478515625,4.38589067613523E-5,2.5729147462901E-7,1,0.999253354069792,40.0298881530762,1.99308073551859,21.5600002557039,0.000491877569172215,8.73596487095175E-5,0.25,-3.13066863342651E-9,4.36108290985828E-5,2.12741890081553E-7,9.9980774,9.998312,1927.58850097656,1967.50720214844,55.9817978043521,20.5470691318512,9.621219,0,0,0,40,4449,10.02435,1947.5478515625,,,,,,,,,,,,,0,,,,-0.00245,,,,,,9.9981947,,,,
,31907477.61,9.99802495,2989.50500488281,4.0589934153309E-5,2.68433970046166E-7,1,0.999253354069792,40.0298881530762,1.99302111119582,21.5600002557039,0.000454747882506303,8.3566671526398E-5,0.25,2.36523706804946E-7,4.03615808049524E-5,4.37688351510989E-7,9.9976635,9.9983864,2964.728515625,3014.28149414063,55.9786712902751,20.5498288752825,9.241568,0,0,0,40,4449,10.02445,2989.50500488281,,,,,,,,,,,,,0,,,,-0.00245,,,,,,9.99802495,,,,
,31907498.57,9.9979172,4036.50329589844,3.72218365571756E-5,2.79938739072855E-7,1,0.999253354069792,40.0298881530762,1.99297508140641,21.5600002557039,0.000417117188427432,7.61545387886194E-5,0.25,1.71338508694426E-7,3.70150712160653E-5,3.58727136577088E-7,9.9979172,9.9979172,4016.44091796875,4056.56567382812,56.1467214219098,20.5500577686557,9.621219,0,0,0,40,4449,10.0232,4036.50329589844,,,,,,,,,,,,,0,,,,0,,,,,,9.9979172,,,,
,31907519.58,9.99881935,5081.998046875,3.38531409046813E-5,2.80880813789651E-7,1,0.999253354069792,40.0298881530762,1.99302305517509,21.5600002557039,0.000379914431535235,6.63874560993833E-5,0.25,-1.03543515974681E-7,3.36687499847864E-5,7.08057710026804E-8,9.9988155,9.9988232,5054.50732421875,5109.48876953125,55.8418862994097,20.5532483085973,10.00087,0,0,0,40,4449,10.0263,5081.998046875,,,,,,,,,,,,,0,,,,0.00245,,,,,,9.99881935,,,,
,31907540.515,9.9995966,6128.28247070312,3.07328785212263E-5,3.33429330521442E-7,1,0.999253354069792,40.0298881530762,1.99301527522406,21.5600002557039,0.000345406510907726,5.75485985476541E-5,0.25,-3.39173875290178E-7,3.05690044132679E-5,-1.77263536852989E-7,9.9995966,9.9995966,6098.263671875,6158.30126953125,55.9286470650444,20.5543405131315,10.00087,0,0,0,40,4449,10.02525,6128.28247070312,,,,,,,,,,,,,0,,,,0,,,,,,9.9995966,,,,
,31907561.635,9.99850135,7184.91040039063,2.66243183980646E-5,3.36891821104868E-7,1,0.999253354069792,40.0298881530762,1.9930161900816,21.5600002557039,0.000298835754346583,5.22083389931762E-5,0.25,-8.64630048781334E-8,2.6483322404062E-5,5.47340490993886E-8,9.9983521,9.9986506,7162.5048828125,7207.31591796875,56.127180708929,20.5535711902726,9.241568,0,0,0,40,4449,10.0252,7184.91040039063,,,,,,,,,,,,,0,,,,-0.0049,,,,,,9.99850135,,,,
,31907582.555,9.99851515,8229.3759765625,2.32428009171281E-5,3.37324606612242E-7,1,0.999253354069792,40.0298881530762,1.99304517462961,21.5600002557039,0.0002602154773722,4.94553670176164E-5,0.25,2.68019709622908E-7,2.31197079015004E-5,3.91268933326403E-7,9.9984274,9.9986029,8201.7861328125,8256.9658203125,56.0740299696213,20.5550320374898,9.241568,0,0,0,40,4449,10.02535,8229.3759765625,,,,,,,,,,,,,0,,,,0,,,,,,9.99851515,,,,
,31907603.535,9.99915265,9277.26806640625,1.98705516012997E-5,3.99153137241147E-7,1,0.999253354069792,40.0298881530762,1.99308658501747,21.5600002557039,0.000223113817045689,3.87499544856724E-5,0.25,-8.74210550933376E-8,1.97686469542276E-5,2.11361062046254E-8,9.9990883,9.999217,9257.267578125,9297.2685546875,56.8079791491791,20.556049631607,10.00087,0,0,0,40,4449,10.02555,9277.26806640625,,,,,,,,,,,,,0,,,,0.00245,,,,,,9.99915265,,,,
,31907624.325,9.998889,10319.20703125,1.62694768005784E-5,3.85440314461188E-7,1,0.999253354069792,40.0298881530762,1.993106943492,21.5600002557039,0.000182499961367924,3.28352323852574E-5,0.25,2.56324054987942E-8,1.61868722933983E-5,1.15270867833821E-7,9.9985228,9.9992552,10296.7109375,10341.703125,56.6414922745829,20.5535207657161,9.241568,0,0,0,40,4449,10.0261,10319.20703125,,,,,,,,,,,,,0,,,,-0.00245,,,,,,9.998889,,,,
,31907645.47,9.9989386,11375.6694335938,1.31176883205457E-5,4.30917127032806E-7,1,0.999253354069792,40.0298881530762,1.99303925168882,21.5600002557039,0.000148111664206172,2.11041899399241E-5,0.25,-4.59059740103048E-7,1.3054914433742E-5,-3.83373953157711E-7,9.9989386,9.9989386,11345.560546875,11405.7783203125,56.7431039820829,20.5567740229623,9.621219,0,0,0,40,4449,10.026,11375.6694335938,,,,,,,,,,,,,0,,,,0,,,,,,9.9989386,,,,
,31907666.455,9.9986086,12425.2158203125,9.66761782246029E-6,4.68729469801488E-7,1,0.999253354069792,40.0298881530762,1.99306563719569,21.5600002557039,0.000108395596985715,1.98860368803392E-5,0.25,4.68576581580486E-8,9.62005529432612E-6,1.01465549068697E-7,9.9985447,9.9986725,12400.3857421875,12450.0458984375,56.4632809721983,20.5536823555947,9.621219,0,0,0,40,4449,10.0266,12425.2158203125,,,,,,,,,,,,,0,,,,0,,,,,,9.9986086,,,,
,31907687.555,10.0001192,13477.451171875,5.8325640996082E-6,4.92366675190343E-7,1,0.999253354069792,40.0298881530762,1.9930443720706,21.5600002557039,6.53059660795848E-5,1.25330326140435E-5,0.25,7.54629459895778E-8,5.80412810430922E-6,1.08629527836026E-7,10.0001192,10.0001192,13449.9814453125,13504.9208984375,56.3147715535444,20.5562686331438,10.00087,0,0,0,40,4449,10.02555,13477.451171875,,,,,,,,,,,,,0,,,,-0.00245,,,,,,10.0001192,,,,
,31907708.475,10.0001335,14524.2109375,2.95300769009899E-6,4.66045711758184E-7,1,0.999253354069792,40.0298881530762,1.99300492802854,21.5600002557039,3.40833119872218E-5,6.53663221440916E-7,0.25,-4.6919049035042E-7,2.94183655075089E-6,-4.49784214201238E-7,10.0001335,10.0001335,14499.205078125,14549.216796875,56.689171614256,20.5606230821162,10.00087,0,0,0,40,4449,10.02575,14524.2109375,,,,,,,,,,,,,0,,,,-0.00245,,,,,,10.0001335,,,,
,31907729.425,9.99981785,15571.3388671875,-1.04428539569804E-6,4.35702389275151E-7,1,0.999253354069792,40.0298881530762,1.99297100781445,21.5600002557039,-1.17657557329805E-5,-1.84506153279734E-6,0.25,2.2214243212142E-8,-1.03959843777886E-6,1.59528744885728E-8,9.9997015,9.9999342,15548.8310546875,15593.8466796875,56.3655774072944,20.5598578301101,10.00087,0,0,0,40,4449,10.02515,15571.3388671875,,,,,,,,,,,,,0,,,,-0.00245,,,,,,9.99981785,,,,
,31907750.335,9.9999561,16615.7626953125,-3.94392346847399E-6,5.9332178987285E-7,1,0.999253354069792,40.0298881530762,1.99301771791337,21.5600002557039,-4.41581484559739E-5,-8.55006137235461E-6,0.25,-5.66625672993105E-8,-3.92576816211934E-6,-7.99535641823014E-8,9.9999561,9.9999561,16593.470703125,16638.0546875,56.6297678467945,20.558548928909,10.00087,0,0,0,40,4449,10.02545,16615.7626953125,,,,,,,,,,,,,0,,,,-0.00245,,,,,,9.9999561,,,,
,31907771.2,10.00012875,17660.265625,-8.42432051527857E-6,5.41681460681762E-7,1,0.999253354069792,40.0298881530762,1.99293807549733,21.5600002557039,-9.35205589092459E-5,-2.27822293421499E-5,0.25,-5.22895626074545E-7,-8.38392648846124E-6,-5.71483743712409E-7,9.9999075,10.00035,17632.68359375,17687.84765625,56.4288893173521,20.5607491882823,9.621219,0,0,0,40,4449,10.02655,17660.265625,,,,,,,,,,,,,0,,,,-0.0049,,,,,,10.00012875,,,,
,31907792.38,9.9996357,18717.140625,-1.11979707106025E-5,5.65378769860467E-7,1,0.999253354069792,40.0298881530762,1.99293234265246,21.5600002557039,-0.000124850060570349,-2.73414285493016E-5,0.25,-4.31983718960979E-7,-1.11469598332118E-5,-4.9856991520676E-7,9.9996357,9.9996357,18697.244140625,18737.037109375,56.5148684544675,20.5612758777482,9.621219,0,0,0,40,4449,10.0261,18717.140625,,,,,,,,,,,,,0,,,,-0.00245,,,,,,9.9996357,,,,
,31907813.295,10.0003166,19763.888671875,-1.41797232681096E-5,6.12510028745039E-7,1,0.999253354069792,40.0298881530762,1.99293063736748,21.5700007975101,-0.000157154242343562,-3.99663379034707E-5,0.25,-1.02174364570566E-6,-1.4113586452212E-5,-1.10508839411941E-6,10.0003166,10.0003166,19736.39453125,19791.3828125,56.3460366943136,20.5601888350012,9.621219,0,0,0,40,4449,10.0254,19763.888671875,,,,,,,,,,,,,0,,,,-0.00245,,,,,,10.0003166,,,,
,31907834.16,9.99994515,20806.03125,-1.79315167404471E-5,7.01279016859362E-7,1,0.999253354069792,40.0298881530762,1.99307587830502,21.5600002557039,-0.000200082573364974,-4.32112787737941E-5,0.25,-6.37420619159756E-7,-1.78537079932965E-5,-7.46845325988909E-7,9.9998684,10.0000219,20780.91015625,20831.15234375,56.6188250475252,20.5614062580881,9.621219,0,0,0,40,4449,10.0258,20806.03125,,,,,,,,,,,,,0,,,,-0.0049,,,,,,9.99994515,,,,
,31907855.43,9.99914835,21867.59375,-2.06496137842299E-5,7.39799508308691E-7,1,0.999253354069792,40.0298881530762,1.99300702533786,21.5600002557039,-0.000230963646157612,-4.67726656265132E-5,0.25,-4.66236580807442E-7,-2.05638167343311E-5,-5.94774670551963E-7,9.9987621,9.9995346,21840.0390625,21895.1484375,56.5602029085829,20.5620133213093,9.241568,0,0,0,40,4449,10.02655,21867.59375,,,,,,,,,,,,,0,,,,0,,,,,,9.99914835,,,,
,31907876.795,9.9995785,22937.453125,-2.55509346214971E-5,6.4366642067095E-7,1,0.999253354069792,40.0298881530762,1.99297431392088,21.5600002557039,-0.00028689321700753,-5.18355963263031E-5,0.25,-3.70882296363837E-8,-2.54509074938996E-5,-1.99975679200244E-7,9.9995785,9.9995785,22915.04296875,22959.86328125,56.607882248256,20.5595842629155,9.241568,0,0,0,40,4449,10.0268,22937.453125,,,,,,,,,,,,,0,,,,0,,,,,,9.9995785,,,,
,31907897.525,9.9992971,23971.794921875,-2.84645593859818E-5,7.03264787908472E-7,1,0.999253354069792,40.0298881530762,1.99311882400135,21.5600002557039,-0.000320003688645916,-5.58608773200486E-5,0.25,1.29180341955825E-7,-2.83571885759029E-5,-5.46836184190116E-8,9.9992971,9.9992971,23954.33984375,23989.25,56.8736359447945,20.5614775359822,9.621219,0,0,0,40,4449,10.02665,23971.794921875,,,,,,,,,,,,,0,,,,0.00245,,,,,,9.9992971,,,,
,31907919.175,9.9993186,25056.150390625,-3.15699920299875E-5,9.70768025793581E-7,1,0.999253354069792,40.0298881530762,1.99297780480914,21.5600002557039,-0.000353282447877986,-7.11522549938545E-5,0.25,-6.7324858063663E-7,-3.14490852288986E-5,-8.76117347281277E-7,9.9991617,9.9994755,25033.611328125,25078.689453125,56.2952308405636,20.5642720870664,10.00087,0,0,0,40,4449,10.02625,25056.150390625,,,,,,,,,,,,,0,,,,-0.00245,,,,,,9.9993186,,,,
,31907940.09,9.9994745,26100.54296875,-3.61466990923904E-5,7.21795107150873E-7,1,0.999253354069792,40.0298881530762,1.99290539083067,21.5600002557039,-0.000404075897701802,-8.39876859785218E-5,0.25,-9.92593410029345E-7,-3.60106327380305E-5,-1.22627088638983E-6,9.9994745,9.9994745,26078.21875,26122.8671875,56.699332785006,20.5603128365144,9.621219,0,0,0,40,4449,10.0269,26100.54296875,,,,,,,,,,,,,0,,,,0.00245,,,,,,9.9994745,,,,
,31907961.12,9.9994688,27150.7216796875,-3.81803478857468E-5,8.02284532704193E-7,1,0.999253354069792,40.0298881530762,1.99292377933552,21.5600002557039,-0.00042821958327709,-8.11418343739342E-5,0.25,-3.71502142078545E-7,-3.80451857352665E-5,-6.22963482602413E-7,9.9994688,9.9994688,27123.208984375,27178.234375,56.7509202672752,20.5622686866217,10.00087,0,0,0,40,4449,10.02735,27150.7216796875,,,,,,,,,,,,,0,,,,-0.00245,,,,,,9.9994688,,,,
,31907982.35,9.9990187,28212.7216796875,-4.24636244948232E-5,8.20673931550562E-7,1,0.999253354069792,40.0298881530762,1.99299253400004,21.5600002557039,-0.000474664698510987,-9.95241900344606E-5,0.25,-1.2354968528468E-6,-4.2312469456479E-5,-1.51480516759091E-6,9.9990187,9.9990187,28187.421875,28238.021484375,56.6039741056598,20.5586484363169,9.241568,0,0,0,40,4449,10.02705,28212.7216796875,,,,,,,,,,,,,0,,,,0,,,,,,9.9990187,,,,
,31908003.515,9.9987841,29269.595703125,-4.56083118484247E-5,8.06316979880367E-7,1,0.999253354069792,40.0298881530762,1.99302121462159,21.5600002557039,-0.000510728144067489,-0.000102179904747768,0.25,-9.0389007546724E-7,-4.5453771324094E-5,-1.2078377259768E-6,9.9987841,9.9987841,29252.181640625,29287.009765625,57.0229269919676,20.5650227787021,9.621219,0,0,0,40,4449,10.0274,29269.595703125,,,,,,,,,,,,,0,,,,0.00245,,,,,,9.9987841,,,,
,31908025.045,9.998539,30348.919921875,-4.91847383941673E-5,8.86003825995741E-7,1,0.999253354069792,40.0298881530762,1.99286835208711,21.5600002557039,-0.000548986182566668,-0.000120292732554185,0.25,-1.8705554557117E-6,-4.90175216640154E-5,-2.19821023574834E-6,9.998539,9.998539,30326.4140625,30371.42578125,56.5320642818906,20.5618945989169,9.621219,0,0,0,40,4449,10.0268,30348.919921875,,,,,,,,,,,,,0,,,,0.00245,,,,,,9.998539,,,,
,31908046.25,9.9987483,31406.1865234375,-5.20626558272853E-5,9.27070226149636E-7,1,0.999253354069792,40.0298881530762,1.99290956083616,21.5700007975101,-0.000579530425876345,-0.000136553734107877,0.25,-2.79650334981669E-6,-5.18857756347394E-5,-3.14364254577374E-6,9.998354,9.9991426,31381.333984375,31431.0390625,56.5195582255829,20.5595687338867,10.00087,0,0,0,40,4449,10.0271,31406.1865234375,,,,,,,,,,,,,0,,,,-0.00245,,,,,,9.9987483,,,,
,31908067.19,9.9992018,32452.8515625,-5.63951478804538E-5,9.08193163841011E-7,1,0.999253354069792,40.0298881530762,1.99306377821898,21.5600002557039,-0.000630918703375425,-0.000130987524116601,0.25,-1.51824295204805E-6,-5.62200318381558E-5,-1.90165740823345E-6,9.9992018,9.9992018,32430.59375,32475.109375,56.7462304961599,20.5624206665702,9.241568,0,0,0,40,4449,10.0275,32452.8515625,,,,,,,,,,,,,0,,,,-0.0049,,,,,,9.9992018,,,,
,31908088.125,9.9995432,33499.875,-5.89623207063041E-5,1.01230319806651E-6,1,0.999253354069792,40.0298881530762,1.99298611044664,21.5600002557039,-0.000661953652270424,-0.000124349404387824,0.25,-4.63044731815304E-7,-5.87934800130645E-5,-8.69891919375124E-7,9.9995432,9.9995432,33474.7890625,33524.9609375,57.0330881627176,20.5619423868909,10.00087,0,0,0,40,4449,10.0273,33499.875,,,,,,,,,,,,,0,,,,0.00245,,,,,,9.9995432,,,,
,31908108.915,9.9993429,34539.359375,-6.31244069576077E-5,9.04331698177603E-7,1,0.999253354069792,40.0298881530762,1.9930166061461,21.5600002557039,-0.000706470035620724,-0.000145931095868038,0.25,-1.63035205409524E-6,-6.29426826022192E-5,-2.06559800463252E-6,9.9990692,9.9996166,34514.296875,34564.421875,56.729816297256,20.560610620971,9.621219,0,0,0,40,4449,10.028,34539.359375,,,,,,,,,,,,,0,,,,0,,,,,,9.9993429,,,,
,31908130.34,9.9989004,35608.9296875,-6.56568885193555E-5,8.44021987152066E-7,1,0.999253354069792,40.0298881530762,1.99310019469116,21.5600002557039,-0.000736917323246289,-0.000140731278852284,0.25,-7.07992637058882E-7,-6.54821781242373E-5,-1.1661889614635E-6,9.9989004,9.9989004,35583.91796875,35633.94140625,56.3968425480637,20.5626062548976,10.00087,0,0,0,40,4449,10.02765,35608.9296875,,,,,,,,,,,,,0,,,,-0.0049,,,,,,9.9989004,,,,
,31908151.205,9.9992418,36653.48828125,-6.88518880499684E-5,1.03970104592073E-6,1,0.999253354069792,40.0298881530762,1.99307048169683,21.5600002557039,-0.000772208298510603,-0.000151173188518443,0.25,-1.05808080202599E-6,-6.8674060920286E-5,-1.54054695537854E-6,9.9992418,9.9992418,36633.5,36673.4765625,56.9150622563137,20.5622513824916,9.241568,0,0,0,40,4449,10.0276,36653.48828125,,,,,,,,,,,,,0,,,,-0.00245,,,,,,9.9992418,,,,
,31908172.04,9.99850085,37692.78125,-7.26042662619958E-5,1.0463028240183E-6,1,0.999253354069792,40.0298881530762,1.99302361693068,21.5600002557039,-0.00081367218182958,-0.000163275294392829,0.25,-1.45536624757253E-6,-7.24223133834572E-5,-1.96610879895793E-6,9.9984932,9.9985085,37672.75390625,37712.80859375,57.0065127930637,20.5625920671856,9.621219,0,0,0,40,4449,10.02845,37692.78125,,,,,,,,,,,,,0,,,,0.00245,,,,,,9.99850085,,,,
,31908193.11,9.9982014,38747.099609375,-7.55401419075714E-5,1.07073445997466E-6,1,0.999253354069792,40.0298881530762,1.99281837122653,21.5600002557039,-0.000847751550102359,-0.000163400391904302,0.25,-9.35531350427787E-7,-7.5363346370355E-5,-1.47106054585975E-6,9.9981785,9.9982243,38717.19921875,38777,56.4273260603137,20.5667678798261,10.00087,0,0,0,40,4449,10.02905,38747.099609375,,,,,,,,,,,,,0,,,,0,,,,,,9.9982014,,,,
,31908214.855,9.9984808,39833.935546875,-7.97141163995238E-5,1.21712306891882E-6,1,0.999253354069792,40.0298881530762,1.99286363044714,21.5600002557039,-0.000892747337590935,-0.000183395043197159,0.25,-1.95728625495228E-6,-7.95297595053671E-5,-2.52317738485403E-6,9.9984388,9.9985228,39806.3515625,39861.51953125,56.7563916669098,20.5638746295741,10.00087,0,0,0,40,4449,10.0298,39833.935546875,,,,,,,,,,,,,0,,,,0,,,,,,9.9984808,,,,
,31908235.87,9.9987965,40883.865234375,-8.29761591772519E-5,9.75922618600143E-7,1,0.999253354069792,40.0298881530762,1.99294232889455,21.5600002557039,-0.000929538725597855,-0.000190257935809964,0.25,-1.97528071027987E-6,-8.27938525298774E-5,-2.56726384529471E-6,9.9987965,9.9987965,40861.328125,40906.40234375,56.7282530402175,20.5652220906119,9.621219,0,0,0,40,4449,10.03035,40883.865234375,,,,,,,,,,,,,0,,,,-0.00245,,,,,,9.9987965,,,,
,31908256.945,9.99885605,41937.9375,-8.53496485799155E-5,1.17874050566843E-6,1,0.999253354069792,40.0298881530762,1.9930229075551,21.5600002557039,-0.000956764784009294,-0.000192984753257175,0.25,-1.78542126378664E-6,-8.51733336021649E-5,-2.39753828696649E-6,9.9984159,9.9992962,41915.32421875,41960.55078125,56.5688008222944,20.563123133684,10.00087,0,0,0,40,4449,10.03085,41937.9375,,,,,,,,,,,,,0,,,,-0.00245,,,,,,9.99885605,,,,
,31908277.775,9.9965591,42980.11328125,-8.95190410736995E-5,1.0668733329325E-6,1,0.999253354069792,40.0298881530762,1.99296469238561,21.5600002557039,-0.00100157858992331,-0.000213573691278604,0.25,-2.86066257303699E-6,-8.9336721469111E-5,-3.50353129120156E-6,9.9965591,9.9965591,42955.06640625,43005.16015625,56.5133051974291,20.5633940948014,9.621219,0,0,0,40,4449,10.0295,42980.11328125,,,,,,,,,,,,,0,,,,0.00245,,,,,,9.9965591,,,,
,31908299.17,9.9978032,44048.947265625,-9.49092162637749E-5,9.55154281709888E-7,1,0.999253354069792,40.0298881530762,1.99291242491069,21.5600002557039,-0.00106667370854287,-0.000200378349635287,0.25,-7.13614515874158E-7,-9.47433204064175E-5,-1.40191758599203E-6,9.9974966,9.9981098,44023.828125,44074.06640625,56.5609845371021,20.564472118755,9.621219,0,0,0,40,4449,10.031,44048.947265625,,,,,,,,,,,,,0,,,,0,,,,,,9.9978032,,,,
,31908320.2,9.9977512,45099.421875,-9.66514209091334E-5,1.1831187560014E-6,1,0.999253354069792,40.0298881530762,1.99301751764112,21.5600002557039,-0.00108610396919994,-0.000205889181378563,0.25,-8.84413537528829E-7,-9.6491910717167E-5,-1.58746248074154E-6,9.9977512,9.9977512,45074.7109375,45124.1328125,56.5250296252175,20.5673540289801,10.00087,0,0,0,40,4449,10.0323,45099.421875,,,,,,,,,,,,,0,,,,0.00245,,,,,,9.9977512,,,,
,31908340.925,9.9978294,46133.546875,-9.9890871311229E-5,1.30441512844763E-6,1,0.999253354069792,40.0298881530762,1.99295569087888,21.5600002557039,-0.00112313532875523,-0.000209802770353925,0.25,-6.45146223629055E-7,-9.97386957386135E-5,-1.37439818987925E-6,9.9977226,9.9979362,46108.4921875,46158.6015625,57.0440309619868,20.5628798929287,9.621219,0,0,0,40,4449,10.03285,46133.546875,,,,,,,,,,,,,0,,,,0,,,,,,9.9978294,,,,
,31908361.895,9.9975777,47183.33203125,-0.000103758592646891,8.97722884654511E-7,1,0.999253354069792,40.0298881530762,1.99300123749731,21.5600002557039,-0.00116706384208507,-0.000216350441343059,0.25,-5.25633370929105E-7,-0.000103612835147363,-1.28546898766305E-6,9.9975777,9.9975777,47158.23046875,47208.43359375,56.8587850029291,20.5626430816992,9.621219,0,0,0,40,4449,10.0328,47183.33203125,,,,,,,,,,,,,0,,,,0,,,,,,9.9975777,,,,
,31908382.99,9.99765635,48237.681640625,-0.000109194684752082,1.14207721346638E-6,1,0.999253354069792,40.0298881530762,1.9929348478121,21.5600002557039,-0.00122645658443603,-0.000237949872655174,0.25,-1.46136844354454E-6,-0.000109046449590027,-2.26193243307144E-6,9.9974365,9.9978762,48207.48828125,48267.875,56.9267866841022,20.5633023475499,9.621219,0,0,0,40,4449,10.03345,48237.681640625,,,,,,,,,,,,,0,,,,-0.00245,,,,,,9.99765635,,,,
,31908403.76,9.9971609,49277.048828125,-0.000114852574332709,1.15071523516389E-6,1,0.999253354069792,40.0298881530762,1.99299624090483,21.5600002557039,-0.00129098224534747,-0.000245861704419667,0.25,-1.13997880542978E-6,-0.000114711767061587,-1.98452673945473E-6,9.9971609,9.9971609,49252.1484375,49301.94921875,56.7446672391214,20.5622211292227,10.00087,0,0,0,40,4449,10.0354,49277.048828125,,,,,,,,,,,,,0,,,,-0.00245,,,,,,9.9971609,,,,
,31908424.8,9.99692725,50326.96875,-0.000115850664641823,1.2567072510848E-6,1,0.999253354069792,40.0298881530762,1.99302796981503,21.5600002557039,-0.00130610179224701,-0.000227263217278344,0.25,6.95616807649197E-7,-0.000115734599990614,-1.60046778547173E-7,9.9968309,9.9970236,50301.84765625,50352.08984375,56.5969394489868,20.5641062236912,9.241568,0,0,0,40,4449,10.03425,50326.96875,,,,,,,,,,,,,0,,,,-0.00245,,,,,,9.99692725,,,,
,31908445.75,9.9962902,51373.5859375,-0.000121057598965296,1.09214767514659E-6,1,0.999253354069792,40.0298881530762,1.99299550808613,21.5600002557039,-0.00136210648747949,-0.000253157517789979,0.25,-6.61892292790785E-7,-0.000120938855666868,-1.55622660361685E-6,9.9962902,9.9962902,51346.5546875,51400.6171875,56.6031924771406,20.5621356947694,9.621219,0,0,0,40,4449,10.0348,51373.5859375,,,,,,,,,,,,,0,,,,0.00245,,,,,,9.9962902,,,,
,31908466.875,9.996212,52430.623046875,-0.000124453971485806,9.49128030723951E-7,1,0.999253354069792,40.0298881530762,1.99288826116851,21.5600002557039,-0.00140079899305721,-0.000258050349341137,0.25,-4.81654759567323E-7,-0.000124346553840799,-1.40277214331934E-6,9.996171,9.996253,52400.73046875,52460.515625,56.8150138058522,20.5633911675816,10.00087,0,0,0,40,4449,10.03705,52430.623046875,,,,,,,,,,,,,0,,,,0,,,,,,9.996212,,,,
,31908487.98,9.9960651,53485.20703125,-0.000127571125067992,1.31764391251182E-6,1,0.999253354069792,40.0298881530762,1.99299130097402,21.5600002557039,-0.00143769014274065,-0.000255765381609938,0.25,2.87671418056003E-7,-0.000127480198761978,-6.5842163316861E-7,9.9960651,9.9960651,53455.28515625,53515.12890625,56.7227816405829,20.5636964353066,9.621219,0,0,0,40,4449,10.03785,53485.20703125,,,,,,,,,,,,,0,,,,-0.00245,,,,,,9.9960651,,,,
,31908508.735,9.99551725,54521.9765625,-0.000132539596632866,9.26161751802691E-7,1,0.999253354069792,40.0298881530762,1.99299710124087,21.5600002557039,-0.00149283048605895,-0.000271359907170488,0.25,-1.97645193673395E-7,-0.000132455021432132,-1.18135249831464E-6,9.9953632,9.9956713,54494.6015625,54549.3515625,56.5836517641598,20.5656141250295,9.621219,0,0,0,40,4449,10.0379,54521.9765625,,,,,,,,,,,,,0,,,,0,,,,,,9.99551725,,,,
,31908529.86,9.996129,55576.265625,-0.000134960121057637,9.83355944841608E-7,1,0.999253354069792,40.0298881530762,1.99293567579336,21.5600002557039,-0.00152195953935736,-0.000266607385524456,0.25,6.6304749047881E-7,-0.000134894366461219,-3.40043224824386E-7,9.996129,9.996129,55553.69140625,55598.83984375,56.7782772654483,20.5667415767889,10.00087,0,0,0,40,4449,10.03905,55576.265625,,,,,,,,,,,,,0,,,,0,,,,,,9.996129,,,,
,31908550.725,9.9959049,56618.228515625,-0.000138528804409642,1.4733299486342E-6,1,0.999253354069792,40.0298881530762,1.99295241509189,21.5600002557039,-0.00156171416032233,-0.00027735265054411,0.25,3.55935818180004E-7,-0.000138472929833343,-6.74229719774593E-7,9.9959049,9.9959049,56593.40625,56643.05078125,56.391371148429,20.5649705418927,9.241568,0,0,0,40,4449,10.0399,56618.228515625,,,,,,,,,,,,,0,,,,0,,,,,,9.9959049,,,,
,31908571.64,9.9956174,57665.224609375,-0.000142651730115241,8.94153448460845E-7,1,0.999253354069792,40.0298881530762,1.99293508828957,21.5600002557039,-0.00161313867140484,-0.000259029568995995,0.25,2.7277497476553E-6,-0.000142626151605363,1.6656217546969E-6,9.9954939,9.9957409,57642.48828125,57687.9609375,56.841589175506,20.5640135387155,9.621219,0,0,0,40,4449,10.0414,57665.224609375,,,,,,,,,,,,,0,,,,-0.00245,,,,,,9.9956174,,,,
,31908592.775,9.9950342,58722.80078125,-0.000146466583904372,1.23613330748116E-6,1,0.999253354069792,40.0298881530762,1.99299024798696,21.5600002557039,-0.00165275698276588,-0.000286695504305896,0.25,9.63942080815019E-7,-0.000146441451120573,-1.26297157975008E-7,9.9950342,9.9950342,58697.72265625,58747.87890625,56.8337728903137,20.5621228752459,9.241568,0,0,0,40,4449,10.04125,58722.80078125,,,,,,,,,,,,,0,,,,0,,,,,,9.9950342,,,,
,31908613.815,9.9953575,59774.529296875,-0.000152271353415538,1.29095427912168E-6,1,0.999253354069792,40.0298881530762,1.99288733254809,21.5600002557039,-0.00171646846765186,-0.000308485638737067,0.25,7.84036994482014E-8,-0.000152253500435823,-1.05503316621017E-6,9.9951868,9.9955282,59752.21484375,59796.84375,57.1354814987368,20.5632126667508,10.00087,0,0,0,40,4449,10.04205,59774.529296875,,,,,,,,,,,,,0,,,,0,,,,,,9.9953575,,,,
,31908635.07,9.995492,60836.265625,-0.000154212479780773,1.30313768597316E-6,1,0.999253354069792,40.0298881530762,1.99303104975946,21.5600002557039,-0.00174235310221954,-0.000291884052044307,0.25,1.90543595094595E-6,-0.000154223331945779,7.5752046577765E-7,9.995492,9.995492,60805.98828125,60866.54296875,56.7384142109675,20.5647812696532,9.241568,0,0,0,40,4449,10.04355,60836.265625,,,,,,,,,,,,,0,,,,0,,,,,,9.995492,,,,
,31908655.835,9.996172,61875.70703125,-0.000159311864782247,1.43043101262323E-6,1,0.999253354069792,40.0298881530762,1.99298113257716,21.5600002557039,-0.00179761482804608,-0.000315336304205487,0.25,7.4598047370635E-7,-0.000159329338018414,-4.39591145045944E-7,9.996172,9.996172,61851,61900.4140625,56.6758839294291,20.5627610758543,10.00087,0,0,0,40,4449,10.04405,61875.70703125,,,,,,,,,,,,,0,,,,0.00245,,,,,,9.996172,,,,
,31908676.645,9.9954419,62913.41796875,-0.000161860068953205,1.20747792268829E-6,1,0.999253354069792,40.0298881530762,1.99290770767312,21.5600002557039,-0.00182940489321545,-0.000304158587320757,0.25,2.19784616263726E-6,-0.000161903959464534,9.94032092261575E-7,9.9954252,9.9954586,62885.80078125,62941.03515625,56.8462789466214,20.5642081957838,10.00087,0,0,0,40,4449,10.0446,62913.41796875,,,,,,,,,,,,,0,,,,0.0049,,,,,,9.9954419,,,,
,31908697.625,9.9962263,63963.04296875,-0.000165348736022049,1.41873087385832E-6,1,0.999253354069792,40.0298881530762,1.99302736926512,21.5600002557039,-0.00186486815317492,-0.000334353555251299,0.25,1.5236548953612E-7,-0.00016539377786117,-1.07712144951737E-6,9.9962263,9.9962263,63935.578125,63990.5078125,56.8408075469868,20.5623722493366,9.621219,0,0,0,40,4449,10.045,63963.04296875,,,,,,,,,,,,,0,,,,0,,,,,,9.9962263,,,,
,31908718.64,9.9954243,65014.654296875,-0.000170430975904943,1.34582890685737E-6,1,0.999253354069792,40.0298881530762,1.99288132569798,21.5600002557039,-0.0019231692003482,-0.000339454763995834,0.25,6.15808159167906E-7,-0.000170496929825147,-6.50453899356229E-7,9.9953976,9.995451,64989.703125,65039.60546875,56.658688102006,20.5631328626162,10.00087,0,0,0,40,4449,10.0457,65014.654296875,,,,,,,,,,,,,0,,,,0,,,,,,9.9954243,,,,
,31908739.6,9.9959459,66059.26953125,-0.000171727221419839,1.2670458272255E-6,1,0.999253354069792,40.0298881530762,1.992999595854,21.5600002557039,-0.00194091820704772,-0.00032637270245734,0.25,2.01270132767273E-6,-0.000171819969465872,7.38525572729172E-7,9.9959459,9.9959459,66034.5078125,66084.03125,56.607882248256,20.5620586690502,9.621219,0,0,0,40,4449,10.0472,66059.26953125,,,,,,,,,,,,,0,,,,0,,,,,,9.9959459,,,,
,31908760.51,9.9953117,67106.64453125,-0.000177264983883177,1.45475276025668E-6,1,0.999253354069792,40.0298881530762,1.99296855448768,21.5600002557039,-0.0019986723845941,-0.000364611032842568,0.25,-3.78485228969188E-7,-0.000177358824095149,-1.69364000426724E-6,9.9953117,9.9953117,67084.1875,67129.1015625,56.3014838687175,20.5642949889093,9.621219,0,0,0,40,4449,10.04765,67106.64453125,,,,,,,,,,,,,0,,,,-0.00245,,,,,,9.9953117,,,,
,31908781.595,9.99561215,68160.78515625,-0.000179542347673056,1.37152951867171E-6,1,0.999253354069792,40.0298881530762,1.99288619021425,21.5600002557039,-0.00202445776751222,-0.000369301063250208,0.25,-3.83747665987639E-7,-0.000179653857184773,-1.71436107972686E-6,9.9954805,9.9957438,68138.234375,68183.3359375,57.0870205305445,20.5649985166905,9.621219,0,0,0,40,4449,10.04995,68160.78515625,,,,,,,,,,,,,0,,,,0,,,,,,9.99561215,,,,
,31908802.49,9.9952707,69205.13671875,-0.00018425705241303,1.50866375711874E-6,1,0.999253354069792,40.0298881530762,1.99304240794476,21.5600002557039,-0.00207737534224018,-0.000382311096287919,0.25,-6.83702192529254E-7,-0.000184385895083847,-2.04781817734493E-6,9.9952707,9.9952707,69182.921875,69227.3515625,56.7540467813522,20.5592801067301,9.241568,0,0,0,40,4449,10.0505,69205.13671875,,,,,,,,,,,,,0,,,,-0.0049,,,,,,9.9952707,,,,
,31908823.485,9.9963546,70252.08203125,-0.000187720236997103,1.38239555733971E-6,1,0.999253354069792,40.0298881530762,1.99290403438638,21.5600002557039,-0.0021189195347803,-0.000375901639458833,0.25,5.07213860152657E-7,-0.000187877106760256,-8.79716561615341E-7,9.995924,9.9967852,70227.25,70276.9140625,56.9557069393137,20.5648243461932,9.621219,0,0,0,40,4449,10.05065,70252.08203125,,,,,,,,,,,,,0,,,,0.00245,,,,,,9.9963546,,,,
,31908844.405,9.9954481,71299.44140625,-0.000191560546144292,1.15445360104194E-6,1,0.999253354069792,40.0298881530762,1.99297800780181,21.5600002557039,-0.00216346388439803,-0.000378477946355975,0.25,9.72733298086826E-7,-0.000191740826447318,-4.39987649167871E-7,9.9952936,9.9956026,71271.9609375,71326.921875,57.0330881627176,20.5609408269545,10.00087,0,0,0,40,4449,10.0525,71299.44140625,,,,,,,,,,,,,0,,,,0,,,,,,9.9954481,,,,
,31908865.5,9.9948158,72353.89453125,-0.000195077121071759,1.37774805115638E-6,1,0.999253354069792,40.0298881530762,1.99282102377071,21.5700007975101,-0.00220157776389475,-0.000394469106898902,0.25,1.87077043845398E-7,-0.00019527184379947,-1.24992803088988E-6,9.9946632,9.9949684,72336.40625,72371.3828125,56.618043419006,20.5632048823091,9.621219,0,0,0,40,4449,10.05295,72353.89453125,,,,,,,,,,,,,0,,,,0,,,,,,9.9948158,,,,
,31908886.32,9.9949665,73393.609375,-0.000197234507414079,1.21364624182229E-6,1,0.999253354069792,40.0298881530762,1.99304716249683,21.5600002557039,-0.00222228396420692,-0.000421510404483717,0.25,-1.81614139544954E-6,-0.000197433436869292,-3.26865613386138E-6,9.9949064,9.9950266,73366.046875,73421.171875,56.6969878994483,20.5628158041921,9.621219,0,0,0,40,4449,10.0539,73393.609375,,,,,,,,,,,,,0,,,,0,,,,,,9.9949665,,,,
,31908907.63,9.99504425,74460.5,-0.000201769814565546,1.49509599210301E-6,1,0.999253354069792,40.0298881530762,1.99306863190181,21.5600002557039,-0.00227469079807971,-0.000425209863836281,0.25,-1.32620543057824E-6,-0.000201994666041994,-2.80883710952496E-6,9.9942894,9.9957991,74430.5859375,74490.4140625,56.7141837268714,20.5650366034995,9.241568,0,0,0,40,4449,10.0535,74460.5,,,,,,,,,,,,,0,,,,-0.0049,,,,,,9.99504425,,,,
,31908928.355,9.9955492,75497.91796875,-0.00020689569085873,1.16007806119137E-6,1,0.999253354069792,40.0298881530762,1.99295110688379,21.5600002557039,-0.00233736211287114,-0.00040925277113999,0.25,1.00875175149014E-6,-0.000207160775079266,-5.0572360070249E-7,9.9955492,9.9955492,75475.53125,75520.3046875,56.8150138058522,20.5655630024646,10.00087,0,0,0,40,4449,10.05615,75497.91796875,,,,,,,,,,,,,0,,,,0.00245,,,,,,9.9955492,,,,
,31908949.535,9.9956837,76557.57421875,-0.000209079677410718,1.30005569236415E-6,1,0.999253354069792,40.0298881530762,1.99289533640323,21.5600002557039,-0.00236505476936323,-0.000397572675418873,0.25,2.43554432751836E-6,-0.000209375371324106,9.10295826982821E-7,9.9956236,9.9957438,76529.9609375,76585.1875,56.8681645451599,20.5662652490224,9.621219,0,0,0,40,4449,10.0566,76557.57421875,,,,,,,,,,,,,0,,,,-0.0049,,,,,,9.9956837,,,,
,31908970.795,9.9954433,77619.3046875,-0.000212286763826303,1.12128602165776E-6,1,0.999253354069792,40.0298881530762,1.99303955265758,21.5600002557039,-0.00239792214236384,-0.0004246869737115,0.25,6.13229210917395E-7,-0.000212590933117983,-9.34370117354916E-7,9.9954433,9.9954433,77594.4140625,77644.1953125,56.7102755842752,20.5645742634828,9.621219,0,0,0,40,4449,10.05705,77619.3046875,,,,,,,,,,,,,0,,,,-0.0049,,,,,,9.9954433,,,,
,31908991.47,9.995512,78651.33984375,-0.000215791019418157,1.46942807327238E-6,1,0.999253354069792,40.0298881530762,1.99293325632404,21.5600002557039,-0.00243791877307782,-0.00042979213786575,0.25,7.89479407690653E-7,-0.000216118517686629,-7.79791492340389E-7,9.9953279,9.9956961,78623.7890625,78678.890625,56.9033378285253,20.5612092887812,9.241568,0,0,0,40,4449,10.05975,78651.33984375,,,,,,,,,,,,,0,,,,-0.0049,,,,,,9.995512,,,,
,31909012.26,9.99527265,79690.8515625,-0.000219235554152597,1.64518278837139E-6,1,0.999253354069792,40.0298881530762,1.99301058534408,21.5600002557039,-0.00247779972890186,-0.000432927448554271,0.25,1.13253172873444E-6,-0.000219587945133686,-4.57396662350999E-7,9.9952555,9.9952898,79668.3046875,79713.3984375,57.2370932062368,20.5625788734176,10.00087,0,0,0,40,4449,10.05965,79690.8515625,,,,,,,,,,,,,0,,,,0,,,,,,9.99527265,,,,
,31909033.325,9.99521015,80743.43359375,-0.000226425679021503,1.27059207871509E-6,1,0.999253354069792,40.0298881530762,1.99298319942299,21.5600002557039,-0.00255771749569062,-0.000455553824283138,0.25,4.21656771440753E-7,-0.000226802018833498,-1.21742199928619E-6,9.9951267,9.9952936,80718.59375,80768.2734375,56.7477937531983,20.5646659586087,9.621219,0,0,0,40,4449,10.05965,80743.43359375,,,,,,,,,,,,,0,,,,0.00245,,,,,,9.99521015,,,,
,31909054.25,9.9946518,81787.8984375,-0.000226911878144316,1.44762164548743E-6,1,0.999253354069792,40.0298881530762,1.99280814056045,21.5600002557039,-0.00256599263339687,-0.000440967861130965,0.25,1.79620971289747E-6,-0.000227316432172574,1.60269295386979E-7,9.9946518,9.9946518,81763.140625,81812.65625,56.709493955756,20.5636128972252,9.241568,0,0,0,40,4449,10.06025,81787.8984375,,,,,,,,,,,,,0,,,,0,,,,,,9.9946518,,,,
,31909075.22,9.9940157,82837.45703125,-0.000230251844015002,1.46641892693683E-6,1,0.999253354069792,40.0298881530762,1.99296680983725,21.5600002557039,-0.00259991540425262,-0.000471096638760122,0.25,-2.68904473599862E-7,-0.000230664843792453,-1.92807646883602E-6,9.9940157,9.9940157,82812.421875,82862.4921875,56.8462789466214,20.5626099029504,9.241568,0,0,0,40,4449,10.06095,82837.45703125,,,,,,,,,,,,,0,,,,0,,,,,,9.9940157,,,,
,31909096.42,9.9944782,83896.87890625,-0.00023495625277712,1.40897253285044E-6,1,0.999253354069792,40.0298881530762,1.99300367866937,21.5600002557039,-0.00265451975058797,-0.000473898944332003,0.25,3.28772094409075E-7,-0.000235399900552696,-1.35843659171724E-6,9.9944782,9.9944782,83872.0390625,83921.71875,56.5320642818906,20.5625179273798,10.00087,0,0,0,40,4449,10.0638,83896.87890625,,,,,,,,,,,,,0,,,,0,,,,,,9.9944782,,,,
,31909117.18,9.9945688,84934.37109375,-0.000238696366980828,1.58348701186907E-6,1,0.999253354069792,40.0298881530762,1.99300547630362,21.5600002557039,-0.00269819753128964,-0.000474683767363613,0.25,9.30529880920007E-7,-0.000239168877229609,-7.77490571963296E-7,9.9945688,9.9945688,84906.703125,84962.0390625,56.8056342636214,20.5636314011681,10.00087,0,0,0,40,4449,10.0649,84934.37109375,,,,,,,,,,,,,0,,,,0.00245,,,,,,9.9945688,,,,
,31909138.165,9.9938393,85983.80078125,-0.000244612865579955,1.52278285488695E-6,1,0.999253354069792,40.0298881530762,1.9929113191642,21.5600002557039,-0.00276497439485509,-0.000487460321799404,0.25,8.60038974130443E-7,-0.000245114323048458,-8.85274162988637E-7,9.9938393,9.9938393,85956.3671875,86011.234375,56.2545861575636,20.5620846076309,9.621219,0,0,0,40,4449,10.0644,85983.80078125,,,,,,,,,,,,,0,,,,0,,,,,,9.9938393,,,,
,31909159.19,9.9948721,87033.46484375,-0.000247544536249127,1.6276384139867E-6,1,0.999253354069792,40.0298881530762,1.99286077680459,21.5600002557039,-0.00279772387314995,-0.000496227249962482,0.25,6.0806350515195E-7,-0.000248068003927807,-1.15330364565986E-6,9.9948721,9.9948721,87010.875,87056.0546875,56.7829670365637,20.562133699697,10.00087,0,0,0,40,4449,10.067,87033.46484375,,,,,,,,,,,,,0,,,,0,,,,,,9.9948721,,,,
,31909180.12,9.99500275,88080.21484375,-0.00024912495210992,1.41375983156263E-6,1,0.999253354069792,40.0298881530762,1.99292061279182,21.5700007975101,-0.00281520507029725,-0.000503115250779209,0.25,2.81483886984288E-7,-0.000249667099970769,-1.48631300946365E-6,9.9949608,9.9950447,88055.203125,88105.2265625,56.6719757868329,20.5640360596746,10.00087,0,0,0,40,4449,10.0678,88080.21484375,,,,,,,,,,,,,0,,,,-0.00245,,,,,,9.99500275,,,,
,31909201.1,9.9945631,89129.87109375,-0.000253117437434977,1.47707765088747E-6,1,0.999253354069792,40.0298881530762,1.99290959313282,21.5600002557039,-0.00286046474394629,-0.000511443007757608,0.25,2.59661035640945E-7,-0.000253685855572901,-1.53079866406186E-6,9.9945631,9.9945631,89105.109375,89154.6328125,56.8634747740445,20.5612302087887,10.00087,0,0,0,40,4449,10.0682,89129.87109375,,,,,,,,,,,,,0,,,,0,,,,,,9.9945631,,,,
,31909235.155,9.9949646,89877.41015625,-0.000256400065572809,1.32704004276604E-6,1,0.999253354069792,40.0298881530762,1.99290670569998,21.5600002557039,-0.00289741347507221,-0.000519693418415082,0.25,1.17795773562187E-7,-0.000256987490785036,-1.69201855148105E-6,9.9947233,9.9952059,89851.2109375,89903.609375,56.6188250475252,20.5647168317848,10.00087,0,0,0,40,4449,10.0701,89877.41015625,,,,,,,,,,,,,0,,,,-0.00735,,,,,,9.9949646,,,,
,31909256.095,9.9955788,88837.6484375,-0.000253743262216375,1.44826027444277E-6,1,0.999253354069792,40.0298881530762,1.9928527670856,21.5600002557039,-0.00286974552850054,-0.000499662977734075,0.25,1.41438226286188E-6,-0.000254316325624766,-3.79552440325244E-7,9.9952822,9.9958754,88812.7890625,88862.5078125,57.1589303543137,20.5635690034878,9.621219,0,0,0,40,4449,10.06965,88837.6484375,,,,,,,,,,,,,0,,,,-0.00245,,,,,,9.9955788,,,,
,31909277.025,9.9967175,87793.34375,-0.000251054939201243,1.63819678521874E-6,1,0.999253354069792,40.0298881530762,1.99294832406547,21.5600002557039,-0.00283648073049043,-0.000509883266103886,0.25,3.08953107028811E-8,-0.000251594629929226,-1.75267283051158E-6,9.9967175,9.9967175,87768.2265625,87818.4609375,56.3491632083906,20.5644033752901,9.621219,0,0,0,40,4449,10.06995,87793.34375,,,,,,,,,,,,,0,,,,-0.0049,,,,,,9.9967175,,,,
,31909298.045,9.9976053,86741.265625,-0.000247265801797637,1.54081613988173E-6,1,0.999253354069792,40.0298881530762,1.99298823627947,21.5600002557039,-0.00279181318987415,-0.000511671559662191,0.25,-8.05815032607123E-7,-0.000247773663253329,-2.56964636345817E-6,9.9976053,9.9976053,86713.75,86768.78125,56.4875114562944,20.5613832292958,9.621219,0,0,0,40,4449,10.0706,86741.265625,,,,,,,,,,,,,0,,,,0.00245,,,,,,9.9976053,,,,
,31909319.04,9.99887845,85691.84375,-0.000240959057494887,1.3613030506556E-6,1,0.999253354069792,40.0298881530762,1.9929005219977,21.5600002557039,-0.00272490532630277,-0.000472938033392107,0.25,1.48859952675552E-6,-0.000241452725689448,-2.30802456272794E-7,9.998661,9.9990959,85664.390625,85719.296875,57.1784710672945,20.5626037032169,9.621219,0,0,0,40,4449,10.0692,85691.84375,,,,,,,,,,,,,0,,,,0.00245,,,,,,9.99887845,,,,
,31909340.025,9.9985018,84644.328125,-0.000237284262987342,1.44921286124415E-6,1,0.999253354069792,40.0298881530762,1.99284557106712,21.5600002557039,-0.00268459561001021,-0.000457268706650929,0.25,2.21560224206746E-6,-0.000237758385289238,5.1879731036481E-7,9.9985018,9.9985018,84619.1953125,84669.4609375,57.1378263842945,20.5627442836072,9.621219,0,0,0,40,4449,10.0696,84644.328125,,,,,,,,,,,,,0,,,,0,,,,,,9.9985018,,,,
,31909361.475,10.0001297,83572.09375,-0.000235837543766513,1.50643015282038E-6,1,0.999253354069792,40.0298881530762,1.99298016666888,21.5600002557039,-0.0026663114127376,-0.000464955958478464,0.25,1.27923514607932E-6,-0.000236284207749263,-4.14025269656532E-7,10.0000372,10.0002222,83544.8828125,83599.3046875,56.9893169656406,20.5619259587851,9.241568,0,0,0,40,4449,10.06935,83572.09375,,,,,,,,,,,,,0,,,,0,,,,,,10.0001297,,,,
,31909382.93,10.0004015,82497.39453125,-0.000229322165874031,1.0688873548741E-6,1,0.999253354069792,40.0298881530762,1.99287496663297,21.5600002557039,-0.00259409637635448,-0.000442183796579229,0.25,2.12259813515785E-6,-0.000229745078492292,4.72920821498785E-7,10.0004015,10.0004015,82475.1875,82519.6015625,56.5836517641598,20.5652019428864,9.621219,0,0,0,40,4449,10.06855,82497.39453125,,,,,,,,,,,,,0,,,,0,,,,,,10.0004015,,,,
,31909404.08,10.0013676,81440.42578125,-0.000225787366298701,1.59518462170553E-6,1,0.999253354069792,40.0298881530762,1.99306796262486,21.5600002557039,-0.00255092850193792,-0.000453273115437745,0.25,5.09512551892435E-7,-0.000226174922435663,-1.12196255312954E-6,10.0013676,10.0013676,81410.4765625,81470.375,56.4593728296021,20.5637462781092,9.621219,0,0,0,40,4449,10.0686,81440.42578125,,,,,,,,,,,,,0,,,,0,,,,,,10.0013676,,,,
,31909425.045,10.0021386,80393.27734375,-0.000223018262332423,1.45736418403E-6,1,0.999253354069792,40.0298881530762,1.99300215501099,21.5600002557039,-0.00251937437219312,-0.000447636253683174,0.25,5.10104455871451E-7,-0.000223383810153673,-1.1055361435799E-6,10.0020027,10.0022745,80375.5703125,80410.984375,56.7509202672752,20.5617473999351,10.00087,0,0,0,40,4449,10.06735,80393.27734375,,,,,,,,,,,,,0,,,,0.00245,,,,,,10.0021386,,,,
,31909445.945,10.0018196,79348.03125,-0.000216873682971389,1.29892724375706E-6,1,0.999253354069792,40.0298881530762,1.99283628171934,21.5600002557039,-0.00245145092945454,-0.000424812809802178,0.25,1.42311181867214E-6,-0.000217218869624737,-1.50508255197703E-7,10.0018196,10.0018196,79320.71875,79375.34375,56.2569310431213,20.5648523235637,10.00087,0,0,0,40,4449,10.0669,79348.03125,,,,,,,,,,,,,0,,,,0,,,,,,10.0018196,,,,
,31909467.08,10.0029292,78290.890625,-0.00021522539432159,1.54290926811591E-6,1,0.999253354069792,40.0298881530762,1.99307377632729,21.5600002557039,-0.00243135021419587,-0.000430210962623881,0.25,6.53352972973658E-7,-0.000215545125184786,-9.13285506609331E-7,10.0028677,10.0029907,78265.75,78316.03125,56.8056342636214,20.5627282749361,10.00087,0,0,0,40,4449,10.0657,78290.890625,,,,,,,,,,,,,0,,,,0.00245,,,,,,10.0029292,,,,
,31909488.21,10.0023975,77233.8359375,-0.000211786160964405,1.37679259270009E-6,1,0.999253354069792,40.0298881530762,1.99285819150834,21.5600002557039,-0.00239576389317278,-0.000402672148741865,0.25,2.4702106801766E-6,-0.000212096853359323,9.27536756133607E-7,10.0023975,10.0023975,77206.1953125,77261.4765625,57.187068981006,20.565662928701,9.621219,0,0,0,40,4449,10.0655,77233.8359375,,,,,,,,,,,,,0,,,,-0.00245,,,,,,10.0023975,,,,
,31909509.31,10.00294685,76179.30859375,-0.000205130261257005,1.23429303666079E-6,1,0.999253354069792,40.0298881530762,1.99287730165709,21.5600002557039,-0.0023202166566923,-0.000390462478168031,0.25,2.3539999906371E-6,-0.000205414026434314,8.56290186029538E-7,10.0028515,10.0030422,76156.734375,76201.8828125,56.9338213407753,20.564834492337,9.241568,0,0,0,40,4449,10.065,76179.30859375,,,,,,,,,,,,,0,,,,-0.00245,,,,,,10.00294685,,,,
,31909530.365,10.0036001,75126.59375,-0.000203273028573413,1.6091941000376E-6,1,0.999253354069792,40.0298881530762,1.99280707672297,21.5600002557039,-0.00230171227471923,-0.00037149921995464,0.25,3.69886257932435E-6,-0.000203547319559894,2.21310061076777E-6,10.0036001,10.0036001,75106.71875,75146.46875,57.0495023616214,20.5628190267821,9.621219,0,0,0,40,4449,10.0645,75126.59375,,,,,,,,,,,,,0,,,,-0.0049,,,,,,10.0036001,,,,
,31909551.365,10.00370595,74077.13671875,-0.000200451161613003,1.14472897879412E-6,1,0.999253354069792,40.0298881530762,1.99303557318702,21.5600002557039,-0.00226893324671711,-0.000371262310814492,0.25,3.21539194574497E-6,-0.00020070163870031,1.74659238652921E-6,10.00354,10.0038719,74052.1171875,74102.15625,57.0706063316407,20.5653034863488,9.621219,0,0,0,40,4449,10.06235,74077.13671875,,,,,,,,,,,,,0,,,,-0.00245,,,,,,10.00370595,,,,
,31909572.365,10.0035801,73027.70703125,-0.00019667677235642,1.20607025939624E-6,1,0.999253354069792,40.0298881530762,1.9930329433881,21.5600002557039,-0.00222095603580338,-0.000392341619628082,0.25,6.67580802503492E-7,-0.000196887495121755,-7.79083732508928E-7,10.0035801,10.0035801,73007.8125,73047.6015625,56.7431039820829,20.5665068101167,9.621219,0,0,0,40,4449,10.06245,73027.70703125,,,,,,,,,,,,,0,,,,0.00245,,,,,,10.0035801,,,,
,31909593.155,10.0044675,71987.921875,-0.000192767606805015,1.50819910044713E-6,1,0.999253354069792,40.0298881530762,1.99294254129576,21.5600002557039,-0.00217918536387219,-0.00036976740590681,0.25,1.96191632769904E-6,-0.000192967292876334,5.42796787099896E-7,10.0042105,10.0047245,71967.9453125,72007.8984375,56.4327974599483,20.5657652088822,10.00087,0,0,0,40,4449,10.0611,71987.921875,,,,,,,,,,,,,0,,,,-0.00245,,,,,,10.0044675,,,,
,31909614.35,10.00312425,70928.21875,-0.000187708839835314,1.23110441255954E-6,1,0.999253354069792,40.0298881530762,1.99295644307887,21.5600002557039,-0.00212082956372237,-0.000365557898668646,0.25,1.42323242208311E-6,-0.000187883138713201,3.85392996111301E-8,10.0029831,10.0032654,70898.0390625,70958.3984375,56.5922496778714,20.5641474271618,10.00087,0,0,0,40,4449,10.06055,70928.21875,,,,,,,,,,,,,0,,,,-0.00245,,,,,,10.00312425,,,,
,31909635.99,10.0035934,69848.8515625,-0.00018255443478471,1.33309910457094E-6,1,0.999253354069792,40.0298881530762,1.99294572679995,21.5700007975101,-0.00206198181443696,-0.000357776702353173,0.25,1.18323026190798E-6,-0.000182705856595391,-1.65745571854749E-7,10.0035934,10.0035934,69823.9921875,69873.7109375,56.2069068178906,20.5684872032037,10.00087,0,0,0,40,4449,10.06,69848.8515625,,,,,,,,,,,,,0,,,,0,,,,,,10.0035934,,,,
,31909657.11,10.0044632,68792.01953125,-0.000180853908598538,1.22245231044273E-6,1,0.999253354069792,40.0298881530762,1.99292607470338,21.5600002557039,-0.00204422340528939,-0.000345239123537566,0.25,1.98695671667697E-6,-0.000180993645634524,6.4922100804066E-7,10.0044088,10.0045176,68769.8515625,68814.1875,56.5047072837175,20.5652839387631,9.241568,0,0,0,40,4449,10.05955,68792.01953125,,,,,,,,,,,,,0,,,,0.00245,,,,,,10.0044632,,,,
,31909678.04,10.0041809,67744.98828125,-0.000176627204962172,1.55875793205824E-6,1,0.999253354069792,40.0298881530762,1.9930191948836,21.5600002557039,-0.00199505796709443,-0.000344364443117649,0.25,1.30308838563293E-6,-0.000176742992657375,-5.49068618159176E-9,10.0041809,10.0041809,67725.125,67764.8515625,56.5852150211983,20.5656192333392,9.241568,0,0,0,40,4449,10.0586,67744.98828125,,,,,,,,,,,,,0,,,,0,,,,,,10.0041809,,,,
,31909698.98,10.00366545,66700.03125,-0.000172836175314825,1.48585742301157E-6,1,0.999253354069792,40.0298881530762,1.99303512204474,21.5700007975101,-0.0019504778172794,-0.000345802394630151,0.25,4.91300214569498E-7,-0.00017292789012046,-7.91042987668672E-7,10.003582,10.0037489,66670.3515625,66729.7109375,56.6164801619675,20.5629273518427,10.00087,0,0,0,40,4449,10.0576,66700.03125,,,,,,,,,,,,,0,,,,0,,,,,,10.00366545,,,,
,31909720.04,10.0040183,65645.70703125,-0.000168288898828514,1.30978524785406E-6,1,0.999253354069792,40.0298881530762,1.99298483666384,21.5600002557039,-0.00190135697128347,-0.00032324791762634,0.25,1.66928611357043E-6,-0.000168371370079568,4.20002110072308E-7,10.0039692,10.0040674,65620.734375,65670.6796875,57.105779615006,20.5626936762995,9.621219,0,0,0,40,4449,10.05675,65645.70703125,,,,,,,,,,,,,0,,,,0,,,,,,10.0040183,,,,
,31909740.87,10.0045748,64603.392578125,-0.000165800850163379,1.30031051385064E-6,1,0.999253354069792,40.0298881530762,1.99280543333187,21.5600002557039,-0.0018734263567953,-0.000315554953971156,0.25,1.89900677985994E-6,-0.000165868561276904,6.67203195742585E-7,10.0045748,10.0045748,64576.31640625,64630.46875,57.017455592333,20.5649178472882,9.241568,0,0,0,40,4449,10.057,64603.392578125,,,,,,,,,,,,,0,,,,-0.00245,,,,,,10.0045748,,,,
,31909761.885,10.0043926,63553.806640625,-0.000161648425461777,1.24909717992076E-6,1,0.999253354069792,40.0298881530762,1.99300416303038,21.5600002557039,-0.00182758379598261,-0.000301683657848282,0.25,2.38158866554274E-6,-0.000161703068825881,1.17986347819247E-6,10.0043926,10.0043926,63536.30859375,63571.3046875,57.1558038402368,20.567033217042,9.621219,0,0,0,40,4449,10.0548,63553.806640625,,,,,,,,,,,,,0,,,,-0.00245,,,,,,10.0043926,,,,
,31909783.02,10.0046892,62499.779296875,-0.000157792217811452,1.58025541662243E-6,1,0.999253354069792,40.0298881530762,1.99297044754549,21.5600002557039,-0.00178353390020689,-0.00029585010950732,0.25,2.20155679454575E-6,-0.000157829467657559,1.0277440462516E-6,10.0044355,10.0049429,62472.3125,62527.24609375,56.7305979257752,20.5647815352989,9.621219,0,0,0,40,4449,10.05425,62499.779296875,,,,,,,,,,,,,0,,,,-0.00245,,,,,,10.0046892,,,,
,31909803.67,10.0041113,61464.2421875,-0.000155366590872526,1.21692490522941E-6,1,0.999253354069792,40.0298881530762,1.99298655537906,21.5700007975101,-0.00175522572303574,-0.000295366323946733,0.25,1.80537610999286E-6,-0.000155385739365818,6.49074793868841E-7,10.0041113,10.0041113,61436.703125,61491.78125,56.1639172493329,20.5659767819837,9.621219,0,0,0,40,4449,10.0534,61464.2421875,,,,,,,,,,,,,0,,,,0,,,,,,10.0041113,,,,
,31909819.695,10.0040512,60664.90625,-0.000152343780638504,9.53751914590298E-7,1,0.999253354069792,40.0298881530762,1.99303774213202,21.5600002557039,-0.00172170948569424,-0.000285615562271258,0.25,2.1243555169444E-6,-0.000152353865037863,9.90296970117239E-7,10.0040512,10.0040512,60647.45703125,60682.35546875,56.6680676442368,20.5651867553341,9.621219,0,0,0,40,4449,10.05275,60664.90625,,,,,,,,,,,,,0,,,,-0.0049,,,,,,10.0040512,,,,