File: data/monolayers/magneticStructure/ML_Ac_CoFe_C-2/PPMS/BackupJuelich/data/DD175_23_FCW_100OE.DAT
[Header]
; VSM Data File (default extension .dat)
; Copyright (c) 2003-2013, Quantum Design, Inc. All rights reserved.
TITLE,
FILEOPENTIME,31874157.91,01/05/2019,5:58 am
BYAPP,VSM,2.0,2.0
INFO,PPMS VSM Option Release 1.4.10 Build 1,APPNAME
INFO,Quantum Design Linear Motor Servo Controller,MOTOR_MODULE_NAME
INFO,3101-100 M1,MOTOR_HW_VERSION
INFO,MMC1014,MOTOR_SERIAL_NUMBER
INFO,SRV No X-over 01.03.11,MOTOR_SOFTWARE_VERSION
INFO,Quantum Design VSM Detection Module,VSM_MODULE_NAME
INFO,3101-150 F0,VSM_HW_VERSION
INFO,VSM707,VSM_SERIAL_NUMBER
INFO,VSM No X-over 01.02.05 May 20 2008 13:51:47,VSM_SOFTWARE_VERSION
INFO,704,PREAMP_SERIAL_NUMBER
INFO,822,COIL_SERIAL_NUMBER
INFO,0,MOMENT_UNITS
INFO,CoFe2O4 Monolayer,SAMPLE_MATERIAL
INFO,from YF45,SAMPLE_COMMENT
INFO,29.98,SAMPLE_MASS
INFO,,SAMPLE_VOLUME
INFO,,SAMPLE_MOLECULAR_WEIGHT
INFO,,SAMPLE_SIZE
INFO,,SAMPLE_SHAPE
DATATYPE,COMMENT,1
DATATYPE,TIME,2
STARTUPAXIS,X,2
STARTUPAXIS,Y1,5
[Data]
Comment,Time Stamp (sec),Temperature (K),Magnetic Field (Oe),Moment (emu),M. Std. Err. (emu),Transport Action,Averaging Time (sec),Frequency (Hz),Peak Amplitude (mm),Center Position (mm),Coil Signal' (mV),Coil Signal" (mV),Range (mV),M. Quad. Signal (emu),M. Raw' (emu),M. Raw" (emu),Min. Temperature (K),Max. Temperature (K),Min. Field (Oe),Max. Field (Oe),Mass (grams),Motor Lag (deg),Pressure (Torr),VSM Status (code),Motor Status (code),Measure Status (code),Measure Count,PPMS Status (code),System Temp. (K),System Field (Oe),Sample Position (deg),Bridge 1 Resistance (ohms),Bridge 1 Excitation (에),Bridge 2 Resistance (ohms),Bridge 2 Excitation (에),Bridge 3 Resistance (ohms),Bridge 3 Excitation (에),Bridge 4 Resistance (ohms),Bridge 4 Excitation (에),Signal 1 Vin (V),Signal 2 Vin (V),Digital Inputs (code),Drive 1 Iout (mA),Drive 1 Ipower (W),Drive 2 Iout (mA),Drive 2 Ipower (W),Pressure (),Map 20 (),Map 21 (),Map 22 (),Map 23 (),Map 24 (),Map 25 (),Map 26 (),Map 27 (),Map 28 (),Map 29 ()
sample offset = 36.5 mm,31874170.805,5.0013113,99.6243667602539,1.36599129495513E-5,3.74059027590257E-7,1,0.999253354069792,40.0298881530762,1.99285448155019,21.2200004607439,0.000153123114677392,2.74488744102621E-5,0.25,2.22946613322134E-8,1.35814311125204E-5,8.80464972328829E-8,5.0013113,5.0013113,99.6243667602539,99.6243667602539,56.9893169656406,20.5770641413987,9.241568,0,0,0,40,4369,4.9997,99.6243667602539,,,,,,,,,,,,,0,,,,0,,,,,,5.0013113,,,,
,31874298.345,8.0438795,99.6243667602539,1.33872062497109E-5,3.5431088718041E-7,1,0.999253354069792,40.0298881530762,1.99281209876332,21.2200004607439,0.000150214766819009,2.60445565658711E-5,0.25,-5.44683109868325E-8,1.33106321899427E-5,1.04087101020629E-8,8.0438795,8.0438795,99.6243667602539,99.6243667602539,57.0706063316407,20.5784698110046,10.38052,0,0,0,40,4370,8.09675,99.6243667602539,,,,,,,,,,,,,0,,,,0,,,,,,8.0438795,,,,
,31874438.53,11.5255537,99.6243667602539,1.32870196753295E-5,3.28182184961449E-7,1,0.999253354069792,40.0298881530762,1.99284729129203,21.229999139905,0.000149196761312105,2.52618435563868E-5,0.25,-1.06509873270787E-7,1.32112023874669E-5,-4.18171211710085E-8,11.4982662,11.5528412,99.6243667602539,99.6243667602539,56.7243448976214,20.5777714292401,11.899124,0,0,0,40,4370,11.62275,99.6243667602539,,,,,,,,,,,,,0,,,,0.0049,,,,,,11.5255537,,,,
,31874579.775,15.04479265,99.6243667602539,1.33128325421003E-5,3.51100071363964E-7,1,0.999253354069792,40.0298881530762,1.99273231796048,21.2200004607439,0.000149442067917655,2.5506683697715E-5,0.25,-8.91134030050497E-8,1.32366716602777E-5,-2.43958936667974E-8,15.0156479,15.0739374,99.6243667602539,99.6243667602539,57.0588819038522,20.5794006078433,12.658426,0,0,0,40,4370,15.173,99.6243667602539,,,,,,,,,,,,,0,,,,0.0049,,,,,,15.04479265,,,,
,31874719.155,18.5185413,99.6243667602539,1.35673058247966E-5,3.07676911319662E-7,1,0.999253354069792,40.0298881530762,1.99297420230267,21.2200004607439,0.000152436374046021,2.53147092487216E-5,0.25,-1.51735548326183E-7,1.34898868406355E-5,-8.536417199911E-8,18.5185413,18.5185413,99.6243667602539,99.6243667602539,56.8603482599676,20.5755450569846,13.038077,0,0,0,40,4370,18.6754,99.6243667602539,,,,,,,,,,,,,0,,,,0,,,,,,18.5185413,,,,
,31874860.405,22.0121193,99.6243667602539,1.34063925946965E-5,3.27710304161303E-7,1,0.999253354069792,40.0298881530762,1.99266584434643,21.2200004607439,0.000151736655337655,1.87044160903439E-5,0.25,-7.13731721513335E-7,1.33335186576573E-5,-6.43751884426873E-7,21.9885178,22.0357208,99.6243667602539,99.6243667602539,57.4082698519484,20.5848505847408,14.177031,0,0,0,40,4370,22.21925,99.6243667602539,,,,,,,,,,,,,0,,,,0,,,,,,22.0121193,,,,
touchdown = 16.6800003498793 mm,31875008.83,25.6911011,99.6243667602539,1.36502003024874E-5,2.93725498672039E-7,1,0.999253354069792,40.0298881530762,1.99308750567404,21.339999511838,0.000153707568775933,2.38219155125032E-5,0.25,-3.04295167068114E-7,1.35763473382637E-5,-2.32649121385619E-7,25.6911011,25.6911011,99.6243667602539,99.6243667602539,56.5750538504483,20.5739636424857,14.556682,0,0,0,40,4370,25.96135,99.6243667602539,,,,,,,,,,,,,0,,,,0.00245,,,,,,25.6911011,,,,
,31875141.59,29.008564,99.6243667602539,1.33888357388516E-5,3.60234248126266E-7,1,0.999253354069792,40.0298881530762,1.99308796970673,21.339999511838,0.00015048891073264,2.5154484279444E-5,0.25,-1.43454113261638E-7,1.3319242605361E-5,-7.02310069201461E-8,29.008564,29.008564,99.6243667602539,99.6243667602539,56.9236601700253,20.5755106532129,15.315984,0,0,0,40,4370,29.32,99.6243667602539,,,,,,,,,,,,,0,,,,0,,,,,,29.008564,,,,
,31875286.325,32.5779343,99.6243667602539,1.34400361322271E-5,3.21785833749256E-7,1,0.999253354069792,40.0298881530762,1.99340964293086,21.339999511838,0.000151884930414567,2.11798776755936E-5,0.25,-5.13413365800742E-7,1.33782672350849E-5,-4.32804846868651E-7,32.5779343,32.5779343,99.6243667602539,99.6243667602539,56.5695824508137,20.5683656033391,15.695635,0,0,0,40,4370,32.95435,99.6243667602539,,,,,,,,,,,,,0,,,,-0.0049,,,,,,32.5779343,,,,
touchdown = 16.6800003498793 mm,31875429.235,36.1080322,99.6243667602539,1.34316506422081E-5,3.11437399277157E-7,1,0.999253354069792,40.0298881530762,1.99343924742722,21.339999511838,0.000151672887973046,2.23817063276705E-5,0.25,-4.12202629692947E-7,1.33776789286394E-5,-3.26281417236638E-7,36.1080322,36.1080322,99.6243667602539,99.6243667602539,56.6477453027368,20.5698139122011,15.315984,0,0,0,40,4370,36.5527,99.6243667602539,,,,,,,,,,,,,0,,,,-0.0049,,,,,,36.1080322,,,,
,31875567.93,39.52493285,99.6243667602539,1.34672704904258E-5,2.97949693812361E-7,1,0.999253354069792,40.0298881530762,1.99319993211245,21.339999511838,0.000151822505088671,2.44349291028817E-5,0.25,-2.43148752076338E-7,1.34225627188052E-5,-1.51920977373085E-7,39.4975548,39.5523109,99.6243667602539,99.6243667602539,57.0354330482753,20.5767713268509,16.454937,0,0,0,40,4370,40.06295,99.6243667602539,,,,,,,,,,,,,0,,,,-0.00245,,,,,,39.52493285,,,,
,31875708.825,43.0022068,99.6243667602539,1.32627181057583E-5,2.94486475887532E-7,1,0.999253354069792,40.0298881530762,1.99324770930529,21.339999511838,0.000149633198479405,2.42538447093401E-5,0.25,-2.29698714290539E-7,1.32312468294707E-5,-1.34994330539222E-7,42.977829,43.0265846,99.6243667602539,99.6243667602539,57.2245871499291,20.5776411316759,16.454937,0,0,0,40,4370,43.62285,99.6243667602539,,,,,,,,,,,,,0,,,,0.00245,,,,,,43.0022068,,,,
touchdown = 16.6599992662668 mm,31875848.86,46.434166,99.6243667602539,1.31756386377566E-5,3.62021111582839E-7,1,0.999253354069792,40.0298881530762,1.99290662021141,21.3200002908707,0.000148876198690094,2.36170685348336E-5,0.25,-2.75851926367258E-7,1.31588278363093E-5,-1.78560462166999E-7,46.434166,46.434166,99.6243667602539,99.6243667602539,56.7610814380252,20.5769516764256,16.834587,0,0,0,40,4370,47.1803,99.6243667602539,,,,,,,,,,,,,0,,,,0,,,,,,46.434166,,,,
,31875974.61,49.5143242,99.6243667602539,1.33179400284328E-5,3.49302209137684E-7,1,0.999253354069792,40.0298881530762,1.99284549376709,21.3200002908707,0.000150675122243213,2.36536533719216E-5,0.25,-3.01355558810772E-7,1.33145266511135E-5,-2.02127869947512E-7,49.5143242,49.5143242,99.6243667602539,99.6243667602539,56.976810909333,20.5799544614502,17.973541,0,0,0,40,4370,50.38065,99.6243667602539,,,,,,,,,,,,,0,,,,0,,,,,,49.5143242,,,,
,31876117.86,53.0052967,99.6243667602539,1.3112080661576E-5,3.10206815548354E-7,1,0.999253354069792,40.0298881530762,1.99294623753854,21.3200002908707,0.000148312578257681,2.44704399454202E-5,0.25,-1.93199297916742E-7,1.31227593306231E-5,-9.67728293948787E-8,52.9818001,53.0287933,99.6243667602539,99.6243667602539,56.8142321773329,20.5779865549661,17.973541,0,0,0,40,4374,54.0479,99.6243667602539,,,,,,,,,,,,,0,,,,0.00245,,,,,,53.0052967,,,,
,31876263.16,56.4864197,99.6243667602539,,,2,,,,21.3100000452995,,,,,,,56.4864197,56.4864197,99.6243667602539,99.6243667602539,,,18.732843,,,,-99999999,4374,57.7926,99.6243667602539,,,,,,,,,,,,,,,,,,,,,,,56.4864197,,,,
,31876385.93,59.5111542,99.6243667602539,1.30155643365181E-5,2.93148560872232E-7,1,0.999253354069792,40.0298881530762,1.99277968357058,21.2999992072582,0.000147162384079938,2.60843984468449E-5,0.25,-2.95001420017529E-8,1.30488106071523E-5,5.91588559637507E-8,59.5111542,59.5111542,99.6243667602539,99.6243667602539,56.7118388413137,20.5806484466285,19.871798,0,0,0,40,4374,60.91395,99.6243667602539,,,,,,,,,,,,,0,,,,-0.00245,,,,,,59.5111542,,,,
,31876528.145,63.0389977,99.6243667602539,1.30840130394329E-5,2.74731940132531E-7,1,0.999253354069792,40.0298881530762,1.99293009800544,21.2999992072582,0.000148480774832707,2.38795350897499E-5,0.25,-2.33194200464E-7,1.3128557801794E-5,-1.50107203740571E-7,63.0389977,63.0389977,99.6243667602539,99.6243667602539,56.9846271945253,20.5802217987938,19.871798,0,0,0,40,4374,64.50525,99.6243667602539,,,,,,,,,,,,,0,,,,0,,,,,,63.0389977,,,,
,31876684.64,66.8742828,99.6243667602539,,,2,,,,21.280000282526,,,,,,,66.8742828,66.8742828,99.6243667602539,99.6243667602539,,,20.251448,,,,-99999999,4374,68.4509,99.6243667602539,,,,,,,,,,,,,,,,,,,,,,,66.8742828,,,,
,31876810.89,70.0157318,99.6243667602539,1.33354116809933E-5,2.87463644694209E-7,1,0.999253354069792,40.0298881530762,1.99309439224191,21.2699994444847,0.000151458534324758,2.46333664868111E-5,0.25,-2.02451588413267E-7,1.33948767563483E-5,-1.2945468374249E-7,70.0157318,70.0157318,99.6243667602539,99.6243667602539,56.882233858506,20.5720335282959,19.871798,0,0,0,40,4374,71.65385,99.6243667602539,,,,,,,,,,,,,0,,,,0,,,,,,70.0157318,,,,
,31876954.075,73.559433,99.6243667602539,1.32184360154365E-5,3.45682403810598E-7,1,0.999253354069792,40.0298881530762,1.99290262061735,21.2699994444847,0.000149764986342227,2.67065021995044E-5,0.25,6.29439770483902E-9,1.3281187269091E-5,7.40351486363322E-8,73.559433,73.559433,99.6243667602539,99.6243667602539,57.1151591572368,20.5737880053078,20.631098,0,0,0,40,4374,75.2631,99.6243667602539,,,,,,,,,,,,,0,,,,0.00245,,,,,,73.559433,,,,
,31877105.92,77.3057327,99.6243667602539,,,2,,,,21.2500005197525,,,,,,,77.3057327,77.3057327,99.6243667602539,99.6243667602539,,,20.631098,,,,-99999999,4374,79.1204,99.6243667602539,,,,,,,,,,,,,,,,,,,,,,,77.3057327,,,,
,31877238.75,80.5575867,99.6243667602539,1.36281122491889E-5,3.38390547814187E-7,1,0.999253354069792,40.0298881530762,1.99314378772753,21.2399996817112,0.000155103531869112,2.41490843023199E-5,0.25,-2.83424756099634E-7,1.37009227888681E-5,-2.25222706237678E-7,80.5575867,80.5575867,99.6243667602539,99.6243667602539,57.0799858738714,20.5737882649493,21.01075,0,0,0,40,4374,82.4925,99.6243667602539,,,,,,,,,,,,,0,,,,0.0049,,,,,,80.5575867,,,,
,31877379.22,84.0625534,99.6243667602539,1.38403647760161E-5,3.56677413229603E-7,1,0.999253354069792,40.0298881530762,1.99332044448216,21.2399996817112,0.000156946735213103,2.79745036804874E-5,0.25,2.00728742668435E-8,1.39150929341525E-5,7.64802533819696E-8,84.0625534,84.0625534,99.6243667602539,99.6243667602539,56.8728543162753,20.5782671785849,21.01075,0,0,0,40,4374,86.01775,99.6243667602539,,,,,,,,,,,,,0,,,,0,,,,,,84.0625534,,,,
,31877527.53,87.732811,99.6243667602539,,,2,,,,21.220000756979,,,,,,,87.732811,87.732811,99.6243667602539,99.6243667602539,,,21.3904,,,,-99999999,4374,89.7443,99.6243667602539,,,,,,,,,,,,,,,,,,,,,,,87.732811,,,,
,31877659.195,91.005661,99.6243667602539,1.33980346861528E-5,3.77682900716391E-7,1,0.999253354069792,40.0298881530762,1.99326534005889,21.2099999189377,0.000152428293371575,2.43986388582981E-5,0.25,-2.10220924752049E-7,1.34737120025248E-5,-1.6403053196127E-7,91.005661,91.005661,99.6243667602539,99.6243667602539,56.8853603725829,20.5716294957722,21.3904,0,0,0,40,4374,93.0519,99.6243667602539,,,,,,,,,,,,,0,,,,0.0049,,,,,,91.005661,,,,
,31877801.335,94.5457916,99.6243667602539,1.34921742348171E-5,3.59480524501748E-7,1,0.999253354069792,40.0298881530762,1.99355201843817,21.2099999189377,0.000153221787902673,2.63106926662619E-5,0.25,-5.56293403041678E-8,1.35684873458248E-5,-1.13377543453633E-8,94.5457916,94.5457916,99.6243667602539,99.6243667602539,57.0573186468137,20.5671484922168,21.770052,0,0,0,40,4374,96.61825,99.6243667602539,,,,,,,,,,,,,0,,,,0,,,,,,94.5457916,,,,
,31877945.84,98.1258926,99.6243667602539,,,2,,,,21.1800004523993,,,,,,,98.1258926,98.1258926,99.6243667602539,99.6243667602539,,,22.149702,,,,-99999999,4374,100.2389,99.6243667602539,,,,,,,,,,,,,,,,,,,,,,,98.1258926,,,,
,31878060.625,101.01686095,99.6243667602539,1.34777978706072E-5,2.76361207624869E-7,1,0.999253354069792,40.0298881530762,1.99349420977157,21.1699996143579,0.000152640073870584,2.86696071609886E-5,0.25,1.59573608462742E-7,1.35538441888909E-5,2.0018235497299E-7,100.9912338,101.0424881,99.6243667602539,99.6243667602539,56.7110572127945,20.5665533127995,21.3904,0,0,0,40,4374,103.1323,99.6243667602539,,,,,,,,,,,,,0,,,,-0.00245,,,,,,101.01686095,,,,
,31878200.91,104.501976,99.6243667602539,1.31260339659216E-5,2.88069369898534E-7,1,0.999253354069792,40.0298881530762,1.99334045359425,21.1699996143579,0.000149267401146539,2.43708269796844E-5,0.25,-1.55074140872416E-7,1.32009317398684E-5,-1.19496220614064E-7,104.501976,104.501976,99.6243667602539,99.6243667602539,56.7923465787945,20.5693369536086,22.529354,0,0,0,40,4374,106.6656,99.6243667602539,,,,,,,,,,,,,0,,,,0,,,,,,104.501976,,,,
,31878344.08,108.0270004,99.6243667602539,1.33752941342214E-5,3.16830545664976E-7,1,0.999253354069792,40.0298881530762,1.99320785621815,21.1699996143579,0.000152044167671309,2.50898261800377E-5,0.25,-1.33202281939173E-7,1.34513011773024E-5,-9.88767384879893E-8,108.0270004,108.0270004,99.6243667602539,99.6243667602539,56.9517987967176,20.5692355653285,22.149702,0,0,0,40,4374,110.2686,99.6243667602539,,,,,,,,,,,,,0,,,,0.00245,,,,,,108.0270004,,,,
,31878462.985,111.0072937,99.6243667602539,1.33790885888701E-5,3.0487880187186E-7,1,0.999253354069792,40.0298881530762,1.99307392050892,21.1299993097782,0.000151927067935578,2.59322053961144E-5,0.25,-5.78721241441672E-8,1.34545965276374E-5,-2.46784981848588E-8,111.0072937,111.0072937,99.6243667602539,99.6243667602539,56.6915164998137,20.5663393381618,22.149702,0,0,0,40,4374,113.26385,99.6243667602539,,,,,,,,,,,,,0,,,,-0.0049,,,,,,111.0072937,,,,
,31878604.74,114.5104027,99.6243667602539,1.31928337478526E-5,3.50383368914379E-7,1,0.999253354069792,40.0298881530762,1.99311636677368,21.1299993097782,0.000150001168686816,2.44762514136649E-5,0.25,-1.51852963809108E-7,1.32670351810774E-5,-1.21333334058427E-7,114.4835358,114.5372696,99.6243667602539,99.6243667602539,56.8916134007368,20.5696496915673,22.529354,0,0,0,40,4374,116.82855,99.6243667602539,,,,,,,,,,,,,0,,,,0,,,,,,114.5104027,,,,
,31878745.445,118.0310135,99.6243667602539,1.32534287253277E-5,3.04999913587494E-7,1,0.999253354069792,40.0298881530762,1.99332923916017,21.1299993097782,0.00015077408477885,2.41581149647713E-5,0.25,-1.89097396711661E-7,1.33274425139464E-5,-1.60158789161127E-7,118.0310135,118.0310135,99.6243667602539,99.6243667602539,57.0995265868522,20.5645666072665,22.529354,0,0,0,40,4374,120.363,99.6243667602539,,,,,,,,,,,,,0,,,,0,,,,,,118.0310135,,,,
,31878886.17,121.5006866,99.6243667602539,1.34271962393427E-5,3.4415792511012E-7,1,0.999253354069792,40.0298881530762,1.99349037114618,21.0900008678436,0.000152159528259321,2.78808970929089E-5,0.25,1.09904481538683E-7,1.35008312968295E-5,1.39479811709144E-7,121.5006866,121.5006866,99.6243667602539,99.6243667602539,57.4309370790061,20.5650888378931,22.529354,0,0,0,40,4374,123.9013,99.6243667602539,,,,,,,,,,,,,0,,,,0.0049,,,,,,121.5006866,,,,
,31879027.135,125.0188522,99.6243667602539,1.32842060191505E-5,3.47929035086215E-7,1,0.999253354069792,40.0298881530762,1.99332479081413,21.0900008678436,0.000151098305202118,2.42619000416232E-5,0.25,-1.8243745541164E-7,1.33568993990051E-5,-1.56044836871365E-7,125.0188522,125.0188522,99.6243667602539,99.6243667602539,56.4023139476983,20.5619429890998,22.909004,0,0,0,40,4374,127.43835,99.6243667602539,,,,,,,,,,,,,0,,,,0.00245,,,,,,125.0188522,,,,
,31879168.28,128.5245514,99.6243667602539,1.2952654288004E-5,3.19075537004191E-7,1,0.999253354069792,40.0298881530762,1.99321056939403,21.0900008678436,0.000147734065615576,2.12228653741138E-5,0.25,-3.9098267081365E-7,1.30231239740737E-5,-3.67528582348392E-7,128.5245514,128.5245514,99.6243667602539,99.6243667602539,56.9306948266983,20.5636101661082,22.529354,0,0,0,40,4374,130.9856,99.6243667602539,,,,,,,,,,,,,0,,,,0,,,,,,128.5245514,,,,
,31879306.545,132.0020294,99.6243667602539,1.32870952456619E-5,3.05603193965752E-7,1,0.999253354069792,40.0298881530762,1.99334366525776,21.0400000214577,0.000151804161362259,2.03012579888715E-5,0.25,-5.29541900366473E-7,1.33587003469128E-5,-5.0719354103198E-7,132.0020294,132.0020294,99.6243667602539,99.6243667602539,56.9385111118906,20.5629306980343,22.529354,0,0,0,40,4374,134.4537,99.6243667602539,,,,,,,,,,,,,0,,,,-0.00245,,,,,,132.0020294,,,,
,31879448.035,135.5061264,99.6243667602539,1.35237975170522E-5,3.35160981085674E-7,1,0.999253354069792,40.0298881530762,1.99328635990751,21.0400000214577,0.000153713564260475,2.51273137373532E-5,0.25,-1.44270291387906E-7,1.35949480348692E-5,-1.20429813191656E-7,135.4794769,135.5327759,99.6243667602539,99.6243667602539,57.1331366131791,20.5663831589607,23.288654,0,0,0,40,4374,138.0018,99.6243667602539,,,,,,,,,,,,,0,,,,-0.00245,,,,,,135.5061264,,,,
,31879589.125,139.0292969,99.6243667602539,1.35320302672094E-5,3.31843691998907E-7,1,0.999253354069792,40.0298881530762,1.99317806622402,21.0400000214577,0.000153667327791848,2.58277220253568E-5,0.25,-8.27496874548265E-8,1.36020736119874E-5,-5.94996770177275E-8,139.0056458,139.052948,99.6243667602539,99.6243667602539,56.5789619930445,20.5671192915466,23.288654,0,0,0,40,4374,141.5404,99.6243667602539,,,,,,,,,,,,,0,,,,0.00245,,,,,,139.0292969,,,,
,31879729.665,142.5088654,99.6243667602539,1.29196593682275E-5,3.33284922380251E-7,1,0.999253354069792,40.0298881530762,1.99336765091514,20.9899991750717,0.000146783344021228,2.42677604585947E-5,0.25,-1.12696527976214E-7,1.2985567610319E-5,-9.14866283696586E-8,142.5088654,142.5088654,99.6243667602539,99.6243667602539,56.6493085597752,20.5680554606245,23.288654,0,0,0,40,4374,145.0661,99.6243667602539,,,,,,,,,,,,,0,,,,0,,,,,,142.5088654,,,,
,31879870.595,146.0196991,99.6243667602539,1.36548459407619E-5,3.67569891399523E-7,1,0.999253354069792,40.0298881530762,1.99333999829442,20.9899991750717,0.000155026286357344,2.61901390661843E-5,0.25,-7.03539196162521E-8,1.37232887286123E-5,-4.84944538349552E-8,146.0196991,146.0196991,99.6243667602539,99.6243667602539,56.7493570102368,20.5635082112695,23.668306,0,0,0,40,4374,148.61045,99.6243667602539,,,,,,,,,,,,,0,,,,0.00245,,,,,,146.0196991,,,,
,31880011.765,149.5438232,99.6243667602539,1.34432710905091E-5,3.35502446005623E-7,1,0.999253354069792,40.0298881530762,1.99337473616637,20.9899991750717,0.000153646909818928,1.98506256066778E-5,0.25,-5.91516446356153E-7,1.35103130182005E-5,-5.73299814059629E-7,149.5438232,149.5438232,99.6243667602539,99.6243667602539,56.4296709458714,20.5666670344973,24.047956,0,0,0,40,4374,152.1509,99.6243667602539,,,,,,,,,,,,,0,,,,0.00245,,,,,,149.5438232,,,,
,31880131.71,152.5252686,99.6243667602539,1.31689755831601E-5,3.7338467684769E-7,1,0.999253354069792,40.0298881530762,1.99330956751367,20.9400001913309,0.000149501135049216,2.51546316659265E-5,0.25,-7.53002738341422E-8,1.32328668804638E-5,-5.55480063712062E-8,152.5252686,152.5252686,99.6243667602539,99.6243667602539,56.6430555316214,20.5633715677721,24.047956,0,0,0,40,4374,155.1562,99.6243667602539,,,,,,,,,,,,,0,,,,-0.00245,,,,,,152.5252686,,,,
,31880270.005,156.0079041,99.6243667602539,1.33407583392181E-5,3.53677739677876E-7,1,0.999253354069792,40.0298881530762,1.99313881857058,20.9400001913309,0.000151240719994715,2.65386137144445E-5,0.25,1.78462756331189E-8,1.3404139148349E-5,3.76764548716859E-8,156.0079041,156.0079041,99.6243667602539,99.6243667602539,56.4499932873714,20.5681703458816,24.047956,0,0,0,40,4374,158.6234,99.6243667602539,,,,,,,,,,,,,0,,,,0.0049,,,,,,156.0079041,,,,
,31880411.555,159.52151485,99.6243667602539,1.33410502375123E-5,3.73930395602279E-7,1,0.999253354069792,40.0298881530762,1.99324997813849,20.9400001913309,0.000151146190191427,2.70660472948592E-5,0.25,6.50048290852194E-8,1.34031238514715E-5,8.44466491310526E-8,159.4957275,159.5473022,99.6243667602539,99.6243667602539,57.3644986548715,20.5715939215233,23.668306,0,0,0,40,4374,162.17,99.6243667602539,,,,,,,,,,,,,0,,,,0,,,,,,159.52151485,,,,
,31880531.795,162.5195465,99.6243667602539,1.34367205156573E-5,3.51651571790024E-7,1,0.999253354069792,40.0298881530762,1.99329499268408,20.889999344945,0.000152726959155007,2.43512839054836E-5,0.25,-1.90451009818406E-7,1.34985078595887E-5,-1.72535030889543E-7,162.5195465,162.5195465,99.6243667602539,99.6243667602539,56.7212183835445,20.5657666986174,24.047956,0,0,0,40,4374,165.1788,99.6243667602539,,,,,,,,,,,,,0,,,,0.00245,,,,,,162.5195465,,,,
,31880672.86,166.0728149,99.6243667602539,1.34086677540025E-5,3.38201451565103E-7,1,0.999253354069792,40.0298881530762,1.99310227209731,20.889999344945,0.000152821314464814,2.17534179186812E-5,0.25,-4.13788364835089E-7,1.34693033392059E-5,-3.97431506500821E-7,166.0728149,166.0728149,99.6243667602539,99.6243667602539,56.5813068786021,20.5674482053021,24.427608,0,0,0,40,4374,168.7014,99.6243667602539,,,,,,,,,,,,,0,,,,0.0049,,,,,,166.0728149,,,,
,31880811.155,169.5018234,99.6243667602539,1.29343930940259E-5,3.13880730002703E-7,1,0.999253354069792,40.0298881530762,1.99328124138328,20.889999344945,0.000146448013916535,2.65385887649885E-5,0.25,9.13314510700836E-8,1.2990970308072E-5,1.08817220121698E-7,169.4752502,169.5283966,99.6243667602539,99.6243667602539,57.2808644033138,20.5695511101754,24.047956,0,0,0,40,4374,172.1724,99.6243667602539,,,,,,,,,,,,,0,,,,-0.00245,,,,,,169.5018234,,,,
,31880952.08,173.0194092,99.6243667602539,1.34739492441256E-5,2.98457746289859E-7,1,0.999253354069792,40.0298881530762,1.9819249327428,20.8400003612041,0.000152314735543004,2.40243292367837E-5,0.25,-2.12015543636911E-7,1.35319219973011E-5,-1.95604984873684E-7,173.0194092,173.0194092,99.6243667602539,99.6243667602539,56.7321611828137,20.5682639586108,24.427608,0,0,0,40,4374,175.6959,99.6243667602539,,,,,,,,,,,,,0,,,,0,,,,,,173.0194092,,,,
,31881091.315,176.5250854,99.6243667602539,1.32274772357049E-5,3.74190306897714E-7,1,0.999253354069792,40.0298881530762,1.98161918510062,20.8400003612041,0.000149866234762685,2.14214194574433E-5,0.25,-3.99130546693513E-7,1.32832643559882E-5,-3.84235397666014E-7,176.5250854,176.5250854,99.6243667602539,99.6243667602539,56.9744660237753,20.5721261137738,24.427608,0,0,0,40,4374,179.1691,99.6243667602539,,,,,,,,,,,,,0,,,,-0.0049,,,,,,176.5250854,,,,
,31881231.68,180.0415802,99.6243667602539,1.31206724930764E-5,4.05375293459438E-7,1,0.999253354069792,40.0298881530762,1.98145268604945,20.8400003612041,0.000148766768181375,2.04495993525429E-5,0.25,-4.66035736576642E-7,1.31747103954702E-5,-4.51921697849203E-7,180.0415802,180.0415802,99.6243667602539,99.6243667602539,56.7384142109675,20.5691669633159,24.427608,0,0,0,40,4374,182.6868,99.6243667602539,,,,,,,,,,,,,0,,,,0,,,,,,180.0415802,,,,
,31881371.8,183.5166931,99.6243667602539,1.30742276513663E-5,3.50229003458901E-7,1,0.999253354069792,40.0298881530762,1.99307503563788,20.7899995148182,0.000149420117226796,1.83869077615484E-5,0.25,-6.4953323193485E-7,1.31269102089333E-5,-6.36548193862883E-7,183.4888916,183.5444946,99.6243667602539,99.6243667602539,56.7251265261406,20.5592924877298,24.427608,0,0,0,40,4374,186.2011,99.6243667602539,,,,,,,,,,,,,0,,,,-0.0049,,,,,,183.5166931,,,,
,31881512.315,187.0260773,99.6243667602539,1.31717319638127E-5,3.55394528309207E-7,1,0.999253354069792,40.0298881530762,1.99314908091313,20.7899995148182,0.000149097348976232,2.67297063603696E-5,0.25,7.03577119430277E-8,1.32225321285027E-5,8.59338792698212E-8,187.0260773,187.0260773,99.6243667602539,99.6243667602539,56.7556100383906,20.5618155643575,24.047956,0,0,0,40,4374,189.7189,99.6243667602539,,,,,,,,,,,,,0,,,,0,,,,,,187.0260773,,,,
,31881653.545,190.54545595,99.6243667602539,1.32751077479028E-5,3.82403778209365E-7,1,0.999253354069792,40.0298881530762,1.99292027237646,20.8000000566244,0.000150630003995614,2.46585336482549E-5,0.25,-1.29574976837024E-7,1.33250876544378E-5,-1.14999031455712E-7,190.5178986,190.5730133,99.6243667602539,99.6243667602539,56.6719757868329,20.5687123941018,24.427608,0,0,0,40,4374,193.26165,99.6243667602539,,,,,,,,,,,,,0,,,,0.00245,,,,,,190.54545595,,,,
,31881794.805,194.0504303,99.6243667602539,1.30245325281218E-5,3.86233567310352E-7,1,0.999253354069792,40.0298881530762,1.99316491548784,20.7299999892712,0.000148477645903519,2.02224672578744E-5,0.25,-4.77331316771679E-7,1.30725215781623E-5,-4.64631365024126E-7,194.0504303,194.0504303,99.6243667602539,99.6243667602539,56.9369478548522,20.5670287211439,24.807261,0,0,0,40,4374,196.8129,99.6243667602539,,,,,,,,,,,,,0,,,,0.0049,,,,,,194.0504303,,,,
,31881933.22,197.5181274,99.6243667602539,1.30127968793841E-5,3.85016710070775E-7,1,0.999253354069792,40.0298881530762,1.99311251157355,20.7299999892712,0.000147755557228388,2.34726945937307E-5,0.25,-1.87773580424197E-7,1.30589847943009E-5,-1.74325725164297E-7,197.5181274,197.5181274,99.6243667602539,99.6243667602539,56.8486238321791,20.5649257053054,24.807261,0,0,0,40,4374,200.27925,99.6243667602539,,,,,,,,,,,,,0,,,,-0.0049,,,,,,197.5181274,,,,
,31882073.47,201.0111618,99.6243667602539,1.26650956493006E-5,4.46004501652425E-7,1,0.999253354069792,40.0298881530762,1.99291866823533,20.7299999892712,0.000143448198602984,2.47403055710462E-5,0.25,-1.47221235631489E-8,1.27084473941077E-5,-1.33506339493288E-9,200.985321,201.0370026,99.6243667602539,99.6243667602539,56.8431524325445,20.5668042438603,25.186911,0,0,0,40,4374,203.79715,99.6243667602539,,,,,,,,,,,,,0,,,,0,,,,,,201.0111618,,,,
,31882194.755,204.0492554,99.6243667602539,1.30677466322141E-5,3.53106697234965E-7,1,0.999253354069792,40.0298881530762,1.99334273084423,20.6799991428852,0.000147825866741309,2.6672094590436E-5,0.25,8.59475327095537E-8,1.31110847794808E-5,9.98444679494504E-8,204.0492554,204.0492554,99.6243667602539,99.6243667602539,56.8189219484483,20.5630249460172,25.186911,0,0,0,40,4374,206.8317,99.6243667602539,,,,,,,,,,,,,0,,,,0,,,,,,204.0492554,,,,
,31882335.195,207.5469208,99.6243667602539,1.30581930622752E-5,4.11455085158574E-7,1,0.999253354069792,40.0298881530762,1.9933414011352,20.6799991428852,0.000147782362539644,2.61802913182831E-5,0.25,4.47246235205347E-8,1.31000507569074E-5,5.81880941024274E-8,207.5469208,207.5469208,99.6243667602539,99.6243667602539,56.9056827140829,20.5636449612642,24.807261,0,0,0,40,4374,210.3463,99.6243667602539,,,,,,,,,,,,,0,,,,-0.0049,,,,,,207.5469208,,,,
,31882475.165,211.01537325,99.6243667602539,1.30664178048685E-5,3.46227249476803E-7,1,0.999253354069792,40.0298881530762,1.99307073893885,20.6799991428852,0.000148027072574853,2.51095315919171E-5,0.25,-5.04529306925076E-8,1.31069039056266E-5,-3.75501499440654E-8,210.988266,211.0424805,99.6243667602539,99.6243667602539,56.7673344661791,20.5662711682328,24.427608,0,0,0,40,4374,213.8561,99.6243667602539,,,,,,,,,,,,,0,,,,0,,,,,,211.01537325,,,,
,31882593.515,214.0060883,99.6243667602539,1.26621512395802E-5,3.86781598725176E-7,1,0.999253354069792,40.0298881530762,1.99368087212624,20.6199996173382,0.000142724746789922,2.86588698779529E-5,0.25,3.32961504600926E-7,1.26997500082657E-5,3.46401280654842E-7,214.0060883,214.0060883,99.6243667602539,99.6243667602539,56.7462304961599,20.5516373180103,25.566563,0,0,0,40,4374,216.8224,99.6243667602539,,,,,,,,,,,,,0,,,,-0.0049,,,,,,214.0060883,,,,
,31882733.66,217.5057983,99.6243667602539,1.27822343153135E-5,3.52111870125254E-7,1,0.999253354069792,40.0298881530762,1.9933294743271,20.6199996173382,0.000145239844150798,2.19939668094802E-5,0.25,-2.75678936689369E-7,1.2819288262411E-5,-2.64156664137854E-7,217.5057983,217.5057983,99.6243667602539,99.6243667602539,56.7657712091406,20.5605164611034,24.807261,0,0,0,40,4374,220.33745,99.6243667602539,,,,,,,,,,,,,0,,,,0.0049,,,,,,217.5057983,,,,
,31882876.25,221.0444183,99.6243667602539,1.2770827904739E-5,3.18478300882174E-7,1,0.999253354069792,40.0298881530762,1.99335909770537,20.6199996173382,0.000144837935885522,2.34530958999732E-5,0.25,-1.44349904791171E-7,1.28061960258733E-5,-1.3268178596737E-7,221.0444183,221.0444183,99.6243667602539,99.6243667602539,56.7431039820829,20.5613425333837,24.807261,0,0,0,40,4374,223.9014,99.6243667602539,,,,,,,,,,,,,0,,,,0,,,,,,221.0444183,,,,
,31883014.95,224.51112365,99.6243667602539,1.24614219121916E-5,3.7001577764339E-7,1,0.999253354069792,40.0298881530762,1.99336151436512,20.5700006335974,0.000141490897726179,2.18536480188344E-5,0.25,-2.31516494408859E-7,1.24945479808947E-5,-2.20572729115702E-7,224.4834442,224.5388031,99.6243667602539,99.6243667602539,56.8634747740445,20.5598691143382,25.566563,0,0,0,40,4374,227.3843,99.6243667602539,,,,,,,,,,,,,0,,,,0,,,,,,224.51112365,,,,
,31883155.285,228.0124359,99.6243667602539,1.25149235209568E-5,3.75394024655472E-7,1,0.999253354069792,40.0298881530762,1.99364082350924,20.5700006335974,0.000141935799090077,2.28962754618404E-5,0.25,-1.48495218045185E-7,1.25466140349119E-5,-1.37478211831475E-7,228.0124359,228.0124359,99.6243667602539,99.6243667602539,56.8353361473522,20.5575059953492,24.807261,0,0,0,40,4374,230.8934,99.6243667602539,,,,,,,,,,,,,0,,,,0,,,,,,228.0124359,,,,
,31883295.205,231.5122986,99.6243667602539,1.27695761422767E-5,3.77339020784334E-7,1,0.999253354069792,40.0298881530762,1.99355503142749,20.5700006335974,0.000144749864985753,2.36504747016458E-5,0.25,-1.25498205819391E-7,1.28003494875952E-5,-1.14386432607895E-7,231.5122986,231.5122986,99.6243667602539,99.6243667602539,56.7446672391214,20.5632535740375,25.566563,0,0,0,40,4374,234.40305,99.6243667602539,,,,,,,,,,,,,0,,,,0,,,,,,231.5122986,,,,
,31883436.065,235.0065155,99.6243667602539,1.22186588771514E-5,4.40215393302236E-7,1,0.999253354069792,40.0298881530762,1.99359124317509,20.5099992454052,0.000138305761589149,2.36933861126412E-5,0.25,-2.57148009565863E-8,1.22465443406028E-5,-1.50483844874963E-8,235.0065155,235.0065155,99.6243667602539,99.6243667602539,56.7157469839098,20.5567212912804,25.946213,0,0,0,40,4374,237.94055,99.6243667602539,,,,,,,,,,,,,0,,,,0.0049,,,,,,235.0065155,,,,
,31883576.445,238.5098877,99.6243667602539,1.27822537813796E-5,3.96312912054921E-7,1,0.999253354069792,40.0298881530762,1.99345888457193,20.5099992454052,0.000144839272200845,2.37394016855E-5,0.25,-1.18836703494008E-7,1.28099487091613E-5,-1.08070213972865E-7,238.5098877,238.5098877,99.6243667602539,99.6243667602539,56.7610814380252,20.5577691965718,25.566563,0,0,0,40,4374,241.4585,99.6243667602539,,,,,,,,,,,,,0,,,,-0.00245,,,,,,238.5098877,,,,
,31883717.35,242.00280765,99.6243667602539,1.2195450706989E-5,2.97381554851835E-7,1,0.999253354069792,40.0298881530762,1.993607783598,20.5099992454052,0.000137867823107172,2.44659529389159E-5,0.25,4.74639353700881E-8,1.22202496844909E-5,5.78951921615085E-8,241.9779053,242.02771,99.6243667602539,99.6243667602539,56.800944492506,20.5559886802487,25.186911,0,0,0,40,4374,244.99235,99.6243667602539,,,,,,,,,,,,,0,,,,0,,,,,,242.00280765,,,,
,31883858.025,245.5233917,99.6243667602539,1.23051544963811E-5,4.01163263024532E-7,1,0.999253354069792,40.0298881530762,1.99380403935075,20.4499997198582,0.000140751429771152,1.51861161179913E-5,0.25,-7.91664085443834E-7,1.23293581101793E-5,-7.82929148629155E-7,245.4971771,245.5496063,99.6243667602539,99.6243667602539,56.6031924771406,20.5581983142064,25.566563,0,0,0,40,4374,248.5202,99.6243667602539,,,,,,,,,,,,,0,,,,0,,,,,,245.5233917,,,,
,31883999.06,249.0286713,99.6243667602539,1.19115731692032E-5,3.93659495915824E-7,1,0.999253354069792,40.0298881530762,1.99361685735708,20.4499997198582,0.000134934722519691,2.21108498344469E-5,0.25,-1.10674717374105E-7,1.19329858647698E-5,-1.01117873691034E-7,249.0286713,249.0286713,99.6243667602539,99.6243667602539,56.6422739031022,20.5599817027278,25.186911,0,0,0,40,4374,252.04945,99.6243667602539,,,,,,,,,,,,,0,,,,0.0049,,,,,,249.0286713,,,,
,31884138.695,252.5150299,99.6243667602539,1.2050062500315E-5,3.88017243646325E-7,1,0.999253354069792,40.0298881530762,1.99359481162506,20.4499997198582,0.000136927801539825,1.98131059424486E-5,0.25,-3.37459998272408E-7,1.20704209398093E-5,-3.28316161208139E-7,252.4898834,252.5401764,99.6243667602539,99.6243667602539,56.9408559974483,20.5595607059189,25.566563,0,0,0,40,4374,255.542,99.6243667602539,,,,,,,,,,,,,0,,,,0,,,,,,252.5150299,,,,
,31884258.32,255.5048828,99.6243667602539,1.15231882961791E-5,3.909107964423E-7,1,0.999253354069792,40.0298881530762,1.98252962108321,20.3799996525049,0.000130133419069871,1.94178006583276E-5,0.25,-2.7159140053375E-7,1.15413924511138E-5,-2.62863231902943E-7,255.5048828,255.5048828,99.6243667602539,99.6243667602539,56.5555131374675,20.5585254803548,25.946213,0,0,0,40,4374,258.55165,99.6243667602539,,,,,,,,,,,,,0,,,,-0.00245,,,,,,255.5048828,,,,
,31884399.475,259.0254822,99.6243667602539,1.14715633755811E-5,4.01734239677531E-7,1,0.999253354069792,40.0298881530762,1.98266816465285,20.3799996525049,0.000128525733161199,2.5196075561424E-5,0.25,2.51387330663702E-7,1.1487841058898E-5,2.60711982160334E-7,259.0254822,259.0254822,99.6243667602539,99.6243667602539,56.7665528376599,20.5601752042754,25.946213,0,0,0,40,4374,262.0826,99.6243667602539,,,,,,,,,,,,,0,,,,-0.00245,,,,,,259.0254822,,,,
,31884540.48,262.5333862,99.6243667602539,1.16901036653003E-5,3.5267520479382E-7,1,0.999253354069792,40.0298881530762,1.98249952878856,20.3799996525049,0.000131982470406947,1.96998047437444E-5,0.25,-2.74703322005533E-7,1.17056435623868E-5,-2.66074775788323E-7,262.5082092,262.5585632,99.6243667602539,99.6243667602539,56.6344576179098,20.5600622465489,25.566563,0,0,0,40,4374,265.6059,99.6243667602539,,,,,,,,,,,,,0,,,,-0.0049,,,,,,262.5333862,,,,
,31884660.14,265.5084839,99.6243667602539,1.17204747236749E-5,4.52087981106339E-7,1,0.999253354069792,40.0298881530762,1.99402308155337,20.3200001269579,0.000131775974956354,2.71826419590842E-5,0.25,3.72540014594833E-7,1.17343173664475E-5,3.81880622085881E-7,265.5084839,265.5084839,99.6243667602539,99.6243667602539,56.5437887096791,20.5497634442138,25.946213,0,0,0,40,4374,268.5912,99.6243667602539,,,,,,,,,,,,,0,,,,0,,,,,,265.5084839,,,,
,31884801.24,269.0317078,99.6243667602539,1.15557267994865E-5,3.72901613957121E-7,1,0.999253354069792,40.0298881530762,1.99421963322121,20.3200001269579,0.0001303453202018,2.43439266169304E-5,0.25,1.50213461088596E-7,1.15680875230406E-5,1.59004490487772E-7,269.0317078,269.0317078,99.6243667602539,99.6243667602539,56.8157954343714,20.5487182061353,25.566563,0,0,0,40,4374,272.1463,99.6243667602539,,,,,,,,,,,,,0,,,,-0.0049,,,,,,269.0317078,,,,
,31884942.93,272.5418091,99.6243667602539,1.14752401406075E-5,3.84219740132985E-7,1,0.999253354069792,40.0298881530762,1.99446121163035,20.3200001269579,0.000129948189958155,2.12203949306598E-5,0.25,-1.11976714502373E-7,1.14862681408393E-5,-1.03647061960468E-7,272.5418091,272.5418091,99.6243667602539,99.6243667602539,56.7649895806214,20.5450159489352,25.566563,0,0,0,40,4374,275.6846,99.6243667602539,,,,,,,,,,,,,0,,,,-0.00245,,,,,,272.5418091,,,,
,31885082.47,276.0289001,99.6243667602539,1.12893725661322E-5,3.76933748903061E-7,1,0.999253354069792,40.0298881530762,1.99457120401304,20.2699992805719,0.000128051463008601,1.9621392126579E-5,0.25,-2.20951193944092E-7,1.12988916851232E-5,-2.12959455897938E-7,276.0289001,276.0289001,99.6243667602539,99.6243667602539,56.6657227586791,20.5415809465819,26.705515,0,0,0,40,4374,279.1753,99.6243667602539,,,,,,,,,,,,,0,,,,-0.0049,,,,,,276.0289001,,,,
,31885223.105,279.5368347,99.6243667602539,1.09946760022658E-5,3.19426440299719E-7,1,0.999253354069792,40.0298881530762,1.9947073159094,20.2699992805719,0.000125036185280298,1.71755182552447E-5,0.25,-3.86029893272273E-7,1.10026845423868E-5,-3.78458867100662E-7,279.5368347,279.5368347,99.6243667602539,99.6243667602539,56.8587850029291,20.5408801902618,26.325863,0,0,0,40,4374,282.6852,99.6243667602539,,,,,,,,,,,,,0,,,,-0.0049,,,,,,279.5368347,,,,
,31885362.435,283.00328065,99.6243667602539,1.18512216631866E-5,4.20320641205287E-7,1,0.999253354069792,40.0298881530762,1.99454683709682,20.2699992805719,0.000134039385081207,2.26107049717736E-5,0.25,-5.31186995375536E-8,1.18581225637281E-5,-4.48200612394284E-8,282.9755249,283.0310364,99.6243667602539,99.6243667602539,57.0393411908714,20.5450705303395,26.325863,0,0,0,40,4374,286.1777,99.6243667602539,,,,,,,,,,,,,0,,,,-0.00245,,,,,,283.00328065,,,,
,31885504.05,286.5281067,99.6243667602539,1.08432483415967E-5,3.96655885657966E-7,1,0.999253354069792,40.0298881530762,1.98345450775061,20.2099997550249,0.000122639651279194,1.67237609587359E-5,0.25,-3.91139606920223E-7,1.08484294270603E-5,-3.83807854475623E-7,286.5281067,286.5281067,99.6243667602539,99.6243667602539,56.7962547213906,20.5480440527505,25.946213,0,0,0,40,4374,289.72205,99.6243667602539,,,,,,,,,,,,,0,,,,-0.0049,,,,,,286.5281067,,,,
,31885644.61,290.0210876,99.6243667602539,1.07827833302499E-5,4.31683311316468E-7,1,0.999253354069792,40.0298881530762,1.98363418913194,20.2099997550249,0.000120490206063227,2.50603371021032E-5,0.25,3.61221198576354E-7,1.07860705624374E-5,3.68698227224606E-7,290.0210876,290.0210876,99.6243667602539,99.6243667602539,56.9947883652753,20.5475474701578,26.705515,0,0,0,40,4374,293.2658,99.6243667602539,,,,,,,,,,,,,0,,,,0,,,,,,290.0210876,,,,
,31885784.965,293.5301666,99.6243667602539,1.01307456561363E-5,4.08146305176623E-7,1,0.999253354069792,40.0298881530762,1.98355085010603,20.2099997550249,0.00011495673763926,1.33180692117847E-5,0.25,-5.70226676174768E-7,1.01331767083426E-5,-5.63526116643801E-7,293.5050659,293.5552673,99.6243667602539,99.6243667602539,57.1948852661984,20.5465210209667,25.946213,0,0,0,40,4374,296.76915,99.6243667602539,,,,,,,,,,,,,0,,,,-0.00245,,,,,,293.5301666,,,,
,31885905.18,296.507782,99.6243667602539,1.06269793278469E-5,3.38978453259671E-7,1,0.999253354069792,40.0298881530762,1.99471647808942,20.1600007712841,0.000121056317956584,1.50049527794751E-5,0.25,-5.13011523451383E-7,1.06283363343542E-5,-5.05995784484972E-7,296.507782,296.507782,99.6243667602539,99.6243667602539,56.770460980256,20.537883737537,25.946213,0,0,0,40,4374,299.742,99.6243667602539,,,,,,,,,,,,,0,,,,0,,,,,,296.507782,,,,
,31886045.915,300.0198059,99.6243667602539,1.01450814544566E-5,4.27862167290837E-7,1,0.999253354069792,40.0298881530762,1.9946653833847,20.1600007712841,0.000114784504667144,1.87375757164068E-5,0.25,-9.87644753939078E-8,1.01448434222187E-5,-9.21113908442906E-8,300.0198059,300.0198059,99.6243667602539,99.6243667602539,56.7556100383906,20.5407299813852,26.325863,0,0,0,40,4374,303.2946,99.6243667602539,,,,,,,,,,,,,0,,,,0.0049,,,,,,300.0198059,,,,
,31886186.97,303.5063782,99.6243667602539,1.0135055245873E-5,3.43822564448386E-7,1,0.999253354069792,40.0298881530762,1.99509963620899,20.1600007712841,0.000114730895335542,1.84304392771934E-5,0.25,-1.24264653330547E-7,1.01335730215688E-5,-1.1769310592385E-7,303.4806824,303.532074,99.6243667602539,99.6243667602539,56.9033378285253,20.5401463064451,27.085165,0,0,0,40,4374,306.8358,99.6243667602539,,,,,,,,,,,,,0,,,,-0.0049,,,,,,303.5063782,,,,
,31886307.165,306.5218811,99.6243667602539,1.02259031746846E-5,4.70300724260964E-7,1,0.999253354069792,40.0298881530762,1.98354172828454,20.0800001621246,0.000114086418156923,2.43791181447287E-5,0.25,3.98919377249807E-7,1.02229739067637E-5,4.05350444971319E-7,306.5218811,306.5218811,99.6243667602539,99.6243667602539,56.5101786833521,20.544915333031,26.705515,0,0,0,40,4374,309.8314,99.6243667602539,,,,,,,,,,,,,0,,,,0,,,,,,306.5218811,,,,
,31886448.96,310.0133667,99.6243667602539,1.0024558687913E-5,4.26011867865265E-7,1,0.999253354069792,40.0298881530762,1.98378217478161,20.0800001621246,0.000113803942963633,1.2556910859015E-5,0.25,-6.1860343048509E-7,1.00210839389284E-5,-6.12044307188462E-7,309.9871521,310.0395813,99.6243667602539,99.6243667602539,56.6266413327175,20.5442062383868,26.325863,0,0,0,40,4374,313.40505,99.6243667602539,,,,,,,,,,,,,0,,,,-0.00245,,,,,,310.0133667,,,,
,31886589.83,313.5419312,99.6243667602539,9.23586196791741E-6,4.56737648880636E-7,1,0.999253354069792,40.0298881530762,1.9837018869894,20.0800001621246,0.000104533097576674,1.32986275731037E-5,0.25,-4.15677547616059E-7,9.23140530532196E-6,-4.09717603122955E-7,313.5419312,313.5419312,99.6243667602539,99.6243667602539,56.8673829166406,20.5440328762562,26.705515,0,0,0,40,4374,316.91925,99.6243667602539,,,,,,,,,,,,,0,,,,-0.0049,,,,,,313.5419312,,,,
,31886729.99,317.0317078,99.6243667602539,9.47298182772942E-6,4.73126107985369E-7,1,0.999253354069792,40.0298881530762,2.00757377991047,20.0299993157387,0.000108489518929437,1.3478220000228E-5,0.25,-4.54163008861966E-7,9.4672567541214E-6,-4.48055249558132E-7,317.0317078,317.0317078,99.6243667602539,99.6243667602539,56.5625477941406,20.532594503825,26.705515,0,0,0,40,4374,320.4449,99.6243667602539,,,,,,,,,,,,,0,,,,0,,,,,,317.0317078,,,,
,31886870.61,320.5091858,99.6243667602539,9.34350590751497E-6,4.31035779543881E-7,1,0.999253354069792,40.0298881530762,2.00753968703409,20.0299993157387,0.000105620080862748,2.12119857797706E-5,0.25,2.49490577973704E-7,9.33628863096544E-6,2.54970417016247E-7,320.483429,320.5349426,99.6243667602539,99.6243667602539,56.8673829166406,20.5331006229057,27.085165,0,0,0,40,4374,323.965,99.6243667602539,,,,,,,,,,,,,0,,,,-0.00245,,,,,,320.5091858,,,,
,31887011.615,324.0002136,99.6243667602539,9.70830485894547E-6,4.9923806599558E-7,1,0.999253354069792,40.0298881530762,2.00764307637225,20.0299993157387,0.00011028128089754,1.88888652824974E-5,0.25,-1.80598252303217E-8,9.69978506095988E-6,-1.22266793083072E-8,324.0002136,324.0002136,99.6243667602539,99.6243667602539,56.7563916669098,20.5324623194867,26.705515,0,0,0,40,4374,327.5041,99.6243667602539,,,,,,,,,,,,,0,,,,0.0049,,,,,,324.0002136,,,,
,31887152.24,327.5158386,99.6243667602539,9.48317123941735E-6,4.13560724321682E-7,1,0.999253354069792,40.0298881530762,1.98382287907013,19.9699997901917,0.000106571685421733,1.77708177945193E-5,0.25,-5.93312381222901E-8,9.47370876316226E-6,-5.36577633319628E-8,327.5158386,327.5158386,99.6243667602539,99.6243667602539,56.432015831429,20.5341254803554,26.705515,0,0,0,40,4374,331.038,99.6243667602539,,,,,,,,,,,,,0,,,,-0.0049,,,,,,327.5158386,,,,
,31887294.565,331.0279236,99.6243667602539,9.15430855815431E-6,3.84932089794284E-7,1,0.999253354069792,40.0298881530762,1.98390381826135,19.9699997901917,0.000103331877056467,1.44708248121854E-5,0.25,-2.96169983568773E-7,9.14419525913245E-6,-2.90481773332349E-7,331.0279236,331.0279236,99.6243667602539,99.6243667602539,56.8494054606983,20.5387167763246,26.705515,0,0,0,40,4374,334.59365,99.6243667602539,,,,,,,,,,,,,0,,,,0,,,,,,331.0279236,,,,
,31887434.72,334.5141296,99.6243667602539,9.7819971882686E-6,4.29636362066961E-7,1,0.999253354069792,40.0298881530762,1.98391760035539,19.9699997901917,0.000109698936678593,1.95353732511396E-5,0.25,4.65793096834803E-8,9.76979775625448E-6,5.21786713414786E-8,334.5141296,334.5141296,99.6243667602539,99.6243667602539,56.7790588939676,20.5376889794602,27.085165,0,0,0,40,4374,338.12365,99.6243667602539,,,,,,,,,,,,,0,,,,-0.00245,,,,,,334.5141296,,,,
,31887575.08,338.0200195,99.6243667602539,8.728583292413E-6,4.52846143384356E-7,1,0.999253354069792,40.0298881530762,1.98426232388627,19.9100002646446,9.90600042515352E-5,1.06757492106173E-5,0.25,-5.60357463013148E-7,8.71698806237572E-6,-5.54600199252416E-7,338.0200195,338.0200195,99.6243667602539,99.6243667602539,56.8095424062176,20.5341069679587,26.705515,0,0,0,40,4374,341.64225,99.6243667602539,,,,,,,,,,,,,0,,,,0,,,,,,338.0200195,,,,
,31887715.025,341.5033875,99.6243667602539,8.45065292400055E-6,4.58335652261922E-7,1,0.999253354069792,40.0298881530762,1.98408431058679,19.9100002646446,9.56426375139632E-5,1.17395647268958E-5,0.25,-4.17184070941294E-7,8.43834423800199E-6,-4.11782767319673E-7,341.5033875,341.5033875,99.6243667602539,99.6243667602539,56.8197035769676,20.5383226922021,27.085165,0,0,0,40,4374,345.1292,99.6243667602539,,,,,,,,,,,,,0,,,,-0.0049,,,,,,341.5033875,,,,
,31887857.03,345.0408325,99.6243667602539,8.75685416367638E-6,4.28944372808303E-7,1,0.999253354069792,40.0298881530762,1.98396338566119,19.9100002646446,9.85240124265663E-5,1.5433754006652E-5,0.25,-1.40712232759767E-7,8.7428786665215E-6,-1.35583156543032E-7,345.0408325,345.0408325,99.6243667602539,99.6243667602539,56.7368509539291,20.5389417327793,26.705515,0,0,0,40,4374,348.6969,99.6243667602539,,,,,,,,,,,,,0,,,,0.00245,,,,,,345.0408325,,,,
,31887977.085,348.0066833,99.6243667602539,8.29362392895318E-6,5.64016756259492E-7,1,0.999253354069792,40.0298881530762,1.98420555472592,19.8500007390976,9.36694560535789E-5,1.25627091176824E-5,0.25,-3.16369575424336E-7,8.27965585128392E-6,-3.11226212165565E-7,348.0066833,348.0066833,99.6243667602539,99.6243667602539,56.4202914036406,20.5366489684356,27.085165,0,0,0,40,4374,351.7265,99.6243667602539,,,,,,,,,,,,,0,,,,0.0049,,,,,,348.0066833,,,,
,31888332.33,349.7776947,99.6243667602539,8.75872235726076E-6,4.18294927084773E-7,1,0.999253354069792,40.0298881530762,1.98385188556894,19.8500007390976,9.86361778654663E-5,1.47852995887362E-5,0.25,-1.98518977336729E-7,8.74337029453853E-6,-1.93294280960925E-7,349.7750549,349.7803345,99.6243667602539,99.6243667602539,56.8744175733137,20.5426814503409,27.844467,0,0,0,40,4369,350.80565,99.6243667602539,,,,,,,,,,,,,0,,,,0,,,,,,349.7776947,,,,