File: data/doubleLayers/monolayer/ppms/DD205_4/ppms_cologne_data/DD205_4_KOELNPPMS_FCC_100OE.DAT
[Header]
; VSM Data File (default extension .dat)
; Copyright (c) 2003-2013, Quantum Design, Inc. All rights reserved.
TITLE,
FILEOPENTIME,19664514.27,08/16/2018,2:20 pm
BYAPP,VSM,2.0,2.0
INFO,PPMS VSM Option Release 1.4.10 Build 1,APPNAME
INFO,Quantum Design Linear Motor Servo Controller,MOTOR_MODULE_NAME
INFO,3101-100 M1,MOTOR_HW_VERSION
INFO,MMC1014,MOTOR_SERIAL_NUMBER
INFO,SRV No X-over 01.03.11,MOTOR_SOFTWARE_VERSION
INFO,Quantum Design VSM Detection Module,VSM_MODULE_NAME
INFO,3101-150 F0,VSM_HW_VERSION
INFO,VSM707,VSM_SERIAL_NUMBER
INFO,VSM No X-over 01.02.05 May 20 2008 13:51:47,VSM_SOFTWARE_VERSION
INFO,704,PREAMP_SERIAL_NUMBER
INFO,822,COIL_SERIAL_NUMBER
INFO,0,MOMENT_UNITS
INFO,,SAMPLE_MATERIAL
INFO,,SAMPLE_COMMENT
INFO,,SAMPLE_MASS
INFO,,SAMPLE_VOLUME
INFO,,SAMPLE_MOLECULAR_WEIGHT
INFO,,SAMPLE_SIZE
INFO,,SAMPLE_SHAPE
DATATYPE,COMMENT,1
DATATYPE,TIME,2
STARTUPAXIS,X,2
STARTUPAXIS,Y1,5
[Data]
Comment,Time Stamp (sec),Temperature (K),Magnetic Field (Oe),Moment (emu),M. Std. Err. (emu),Transport Action,Averaging Time (sec),Frequency (Hz),Peak Amplitude (mm),Center Position (mm),Coil Signal' (mV),Coil Signal" (mV),Range (mV),M. Quad. Signal (emu),M. Raw' (emu),M. Raw" (emu),Min. Temperature (K),Max. Temperature (K),Min. Field (Oe),Max. Field (Oe),Mass (grams),Motor Lag (deg),Pressure (Torr),VSM Status (code),Motor Status (code),Measure Status (code),Measure Count,PPMS Status (code),System Temp. (K),System Field (Oe),Sample Position (deg),Bridge 1 Resistance (ohms),Bridge 1 Excitation (에),Bridge 2 Resistance (ohms),Bridge 2 Excitation (에),Bridge 3 Resistance (ohms),Bridge 3 Excitation (에),Bridge 4 Resistance (ohms),Bridge 4 Excitation (에),Signal 1 Vin (V),Signal 2 Vin (V),Digital Inputs (code),Drive 1 Iout (mA),Drive 1 Ipower (W),Drive 2 Iout (mA),Drive 2 Ipower (W),Pressure (),Map 20 (),Map 21 (),Map 22 (),Map 23 (),Map 24 (),Map 25 (),Map 26 (),Map 27 (),Map 28 (),Map 29 ()
,19665038.49,351.66285,99.6700439453125,8.67617794746082E-6,5.18442675078404E-7,1,0.999253354069792,40.0298881530762,1.98320598985505,14.2400003969669,9.72355171832945E-5,1.71498029856596E-5,0.25,2.71458922178554E-8,8.66029564904801E-6,3.19126967498447E-8,351.6646,351.6646,99.6700439453125,99.6700439453125,54.0949465589288,19.570274989239,27.844467,0,0,0,40,4369,351.66285,99.6700439453125,,,,,,,,,,,,,0,,,,,,,,,,,,,,
,19665118.02,347.43205,99.6700439453125,7.99525808381015E-6,5.03757721431564E-7,1,0.999253354069792,40.0298881530762,1.98319343106148,14.2400003969669,8.92901394217872E-5,1.76911657157817E-5,0.25,1.9305648961409E-7,7.98166635637466E-6,1.97223748678132E-7,347.4445,347.4445,99.6700439453125,99.6700439453125,54.2442376061019,19.5696656283296,27.844467,0,0,0,40,4374,347.43205,99.6700439453125,,,,,,,,,,,,,0,,,,,,,,,,,,,,
,19665241.05,344.45635,99.6700439453125,7.36730461889737E-6,4.24365879657804E-7,1,0.999253354069792,40.0298881530762,1.98342741184577,14.2400003969669,8.3165911485252E-5,1.12745547531983E-5,0.25,-2.70617786562248E-7,7.35577676676391E-6,-2.66011773731401E-7,344.4594,344.4594,99.6700439453125,99.6700439453125,54.1520054408327,19.5660093291264,28.224119,0,0,0,40,4374,344.45635,99.6700439453125,,,,,,,,,,,,,0,,,,,,,,,,,,,,
,19665351.365,341.44005,99.6700439453125,7.12005841498495E-6,5.15598249715795E-7,1,0.999253354069792,40.0298881530762,1.98357021371403,14.2400003969669,7.88734915452061E-5,1.96479633452868E-5,0.25,5.18339999324255E-7,7.10920423338654E-6,5.21645770235287E-7,341.4454,341.4454,99.6700439453125,99.6700439453125,54.1551319549096,19.5644848270291,27.844467,0,0,0,40,4374,341.44005,99.6700439453125,,,,,,,,,,,,,0,,,,,,,,,,,,,,
,19665460.82,338.49555,99.6700439453125,7.48005460989459E-6,4.31928468401725E-7,1,0.999253354069792,40.0298881530762,1.98332255614152,14.2400003969669,8.30605041126565E-5,1.94823157225097E-5,0.25,4.41228356624031E-7,7.46946252229163E-6,4.44938921671266E-7,338.5004,338.5004,99.6700439453125,99.6700439453125,54.1269933282173,19.5655691729871,27.844467,0,0,0,40,4374,338.49555,99.6700439453125,,,,,,,,,,,,,0,,,,,,,,,,,,,,
,19665576.045,335.49345,99.6700439453125,7.94411554856036E-6,3.88743933113957E-7,1,0.999253354069792,40.0298881530762,1.98336213096571,14.2400003969669,9.01243499438341E-5,9.72207582957721E-6,0.25,-5.09269796432598E-7,7.9342544127871E-6,-5.0398545470143E-7,335.4984,335.4984,99.6700439453125,99.6700439453125,54.055083504448,19.5654643742893,27.464817,0,0,0,40,4374,335.49345,99.6700439453125,,,,,,,,,,,,,0,,,,,,,,,,,,,,
,19665692.775,332.49285,99.6700439453125,8.31741952401145E-6,4.55835111496658E-7,1,0.999253354069792,40.0298881530762,1.98359750206545,14.2400003969669,9.48710008756727E-5,7.34563446361507E-6,0.25,-7.85908556268914E-7,8.30810933140184E-6,-7.8008581988319E-7,332.4966,332.4966,99.6700439453125,99.6700439453125,54.078532360025,19.5613452343988,27.464817,0,0,0,40,4374,332.49285,99.6700439453125,,,,,,,,,,,,,0,,,,,,,,,,,,,,
,19665809.935,329.4821,99.6700439453125,7.44658510987699E-6,4.66457365099525E-7,1,0.999253354069792,40.0298881530762,1.98334952068358,14.2400003969669,8.37773276457778E-5,1.32711705582359E-5,0.25,-1.07123170949739E-7,7.43867692746782E-6,-1.02577262051515E-7,329.4877,329.4877,99.6700439453125,99.6700439453125,54.1176137859865,19.5650255250862,27.844467,0,0,0,40,4374,329.4821,99.6700439453125,,,,,,,,,,,,,0,,,,,,,,,,,,,,
,19665928.095,326.4617,99.6700439453125,8.69167282658023E-6,3.43632339415884E-7,1,0.999253354069792,40.0298881530762,1.98323601957791,14.2400003969669,9.85685401704808E-5,1.09962085007483E-5,0.25,-5.255789759023E-7,8.68359853391391E-6,-5.19845257848065E-7,326.4665,326.4665,99.6700439453125,99.6700439453125,54.2028112945827,19.5640161700352,28.224119,0,0,0,40,4374,326.4617,99.6700439453125,,,,,,,,,,,,,0,,,,,,,,,,,,,,
,19666046.525,323.46815,99.6700439453125,7.73099752819554E-6,3.484021475669E-7,1,0.999253354069792,40.0298881530762,1.98320247183989,14.2400003969669,8.64264177197225E-5,1.70293476080394E-5,0.25,1.78191363004635E-7,7.72423545909263E-6,1.82735936691933E-7,323.4714,323.4714,99.6700439453125,99.6700439453125,54.095728187448,19.5642509543979,27.844467,0,0,0,40,4374,323.46815,99.6700439453125,,,,,,,,,,,,,0,,,,,,,,,,,,,,
,19666164.135,320.4888,99.6700439453125,8.615760440531E-6,4.46440251529792E-7,1,0.999253354069792,40.0298881530762,1.98322488942172,14.2400003969669,9.66794695603458E-5,1.6953976102857E-5,0.25,1.80024789087866E-8,8.60923464757295E-6,2.32806418319591E-8,320.4888,320.4888,99.6700439453125,99.6700439453125,54.0621181611211,19.5636461563104,28.224119,0,0,0,40,4374,320.4888,99.6700439453125,,,,,,,,,,,,,0,,,,,,,,,,,,,,
,19666282.235,317.4954,99.6700439453125,8.81361295664173E-6,4.18050293092338E-7,1,0.999253354069792,40.0298881530762,1.98333231363123,14.2400003969669,0.000100074452815638,1.06533145727203E-5,0.25,-5.77767452310897E-7,8.80823582000455E-6,-5.71918770570453E-7,317.4954,317.4954,99.6700439453125,99.6700439453125,53.8878150013326,19.5605514968664,27.844467,0,0,0,40,4374,317.4954,99.6700439453125,,,,,,,,,,,,,0,,,,,,,,,,,,,,
,19666401.78,314.4607,99.6700439453125,9.04290985721529E-6,4.19083752348453E-7,1,0.999253354069792,40.0298881530762,1.98353357637937,14.2400003969669,0.000101739293479333,1.64730837336759E-5,0.25,-9.94776149171373E-8,9.03805574551769E-6,-9.37450125295271E-8,314.4664,314.4664,99.6700439453125,99.6700439453125,53.9722308814096,19.5564358353626,28.224119,0,0,0,40,4374,314.4607,99.6700439453125,,,,,,,,,,,,,0,,,,,,,,,,,,,,
,19666519.94,311.4606,99.6700439453125,8.90205316551574E-6,4.50893700855904E-7,1,0.999253354069792,40.0298881530762,1.98326466570108,14.2400003969669,9.99718909830129E-5,1.7257133356701E-5,0.25,-5.28334355878546E-9,8.898161592465E-6,3.72468682215306E-10,311.4606,311.4606,99.6700439453125,99.6700439453125,54.0566467614865,19.5597108539859,28.224119,0,0,0,40,4374,311.4606,99.6700439453125,,,,,,,,,,,,,0,,,,,,,,,,,,,,
,19666637.08,308.4959,99.6700439453125,9.18468538009814E-6,3.94890680541047E-7,1,0.999253354069792,40.0298881530762,1.98316745727219,14.2400003969669,0.000102936461611217,1.90498446460131E-5,0.25,1.05240685715117E-7,9.18156502894589E-6,1.11105066651675E-7,308.5014,308.5014,99.6700439453125,99.6700439453125,53.9065740857942,19.5580917028674,28.224119,0,0,0,40,4374,308.4959,99.6700439453125,,,,,,,,,,,,,0,,,,,,,,,,,,,,
,19666756.195,305.4874,99.6700439453125,9.081882917841E-6,5.28748061266999E-7,1,0.999253354069792,40.0298881530762,1.9830646731901,14.2400003969669,0.000101735506653256,1.91531285913706E-5,0.25,1.32081908397256E-7,9.07974967495914E-6,1.37953763290566E-7,305.4914,305.4914,99.6700439453125,99.6700439453125,53.8643661457557,19.5563377411648,28.224119,0,0,0,40,4374,305.4874,99.6700439453125,,,,,,,,,,,,,0,,,,,,,,,,,,,,
,19666875.035,302.48205,99.6700439453125,9.19395126096829E-6,4.05549868046141E-7,1,0.999253354069792,40.0298881530762,1.98296277388563,14.2400003969669,0.000104769903077753,9.15680091637712E-6,0.25,-7.7757124713121E-7,9.19337381965699E-6,-7.71433887223899E-7,302.4872,302.4872,99.6700439453125,99.6700439453125,53.8667110313134,19.5565282848729,28.224119,0,0,0,40,4374,302.48205,99.6700439453125,,,,,,,,,,,,,0,,,,,,,,,,,,,,
,19666994.17,299.4697,99.6700439453125,9.19240171602428E-6,4.8172567871117E-7,1,0.999253354069792,40.0298881530762,1.98297818915182,14.2400003969669,0.000103496819221887,1.64719981711787E-5,0.25,-1.26201426239634E-7,9.19238484248392E-6,-1.20083020782141E-7,299.4749,299.4749,99.6700439453125,99.6700439453125,53.8979761720826,19.5517516928367,27.844467,0,0,0,40,4374,299.4697,99.6700439453125,,,,,,,,,,,,,0,,,,,,,,,,,,,,
,19667112.065,296.4815,99.6700439453125,9.38876882741063E-6,3.80819964279991E-7,1,0.999253354069792,40.0298881530762,1.98294515232733,14.2400003969669,0.00010548179895014,1.81846648638278E-5,0.25,-7.96847328124715E-9,9.38967323791804E-6,-1.64601064449012E-9,296.4878,296.4878,99.6700439453125,99.6700439453125,53.7103853274672,19.5498665005245,28.224119,0,0,0,40,4374,296.4815,99.6700439453125,,,,,,,,,,,,,0,,,,,,,,,,,,,,
,19667231.89,293.45625,99.6700439453125,9.74253055388466E-6,3.30084451318573E-7,1,0.999253354069792,40.0298881530762,1.98309125870347,14.2400003969669,0.000110274926744337,1.42615333323069E-5,0.25,-4.18815817182711E-7,9.74480290587163E-6,-4.12258453084439E-7,293.4608,293.4608,99.6700439453125,99.6700439453125,53.7377423256403,19.5444824269892,27.844467,0,0,0,40,4374,293.45625,99.6700439453125,,,,,,,,,,,,,0,,,,,,,,,,,,,,
,19667350.225,290.46455,99.6700439453125,9.2809588917817E-6,3.18217308044984E-7,1,0.999253354069792,40.0298881530762,1.98316235543942,14.2400003969669,0.000104985173491667,1.40502697502724E-5,0.25,-3.57893834547387E-7,9.28409226505526E-6,-3.51598636413052E-7,290.4696,290.4696,99.6700439453125,99.6700439453125,53.5353005391595,19.5486724816621,28.224119,0,0,0,40,4374,290.46455,99.6700439453125,,,,,,,,,,,,,0,,,,,,,,,,,,,,
,19667469.1,287.47455,99.6700439453125,8.82003795047357E-6,3.10866957366843E-7,1,0.999253354069792,40.0298881530762,1.98334785917583,14.2400003969669,9.97222691158781E-5,1.37512420635817E-5,0.25,-3.04949853300281E-7,8.82393842253528E-6,-2.98912714199885E-7,287.4782,287.4782,99.6700439453125,99.6700439453125,53.8331010049865,19.5499015076998,28.224119,0,0,0,40,4374,287.47455,99.6700439453125,,,,,,,,,,,,,0,,,,,,,,,,,,,,
,19667588.08,284.47905,99.6700439453125,1.00835494366116E-5,4.13710862109287E-7,1,0.999253354069792,40.0298881530762,1.98325879012566,14.2400003969669,0.000113185509787208,2.05103308994936E-5,0.25,7.72787185278897E-8,1.00887923055992E-5,8.44565311508488E-8,284.4828,284.4828,99.6700439453125,99.6700439453125,54.0152204499673,19.5534612174299,28.224119,0,0,0,40,4374,284.47905,99.6700439453125,,,,,,,,,,,,,0,,,,,,,,,,,,,,
,19667706.275,281.4998,99.6700439453125,9.81080126562092E-6,3.4029719802948E-7,1,0.999253354069792,40.0298881530762,1.98326253566109,14.2400003969669,0.00011045019652534,1.81443510840634E-5,0.25,-8.62177637746341E-8,9.8170644893098E-6,-7.92394553995139E-8,281.4998,281.4998,99.6700439453125,99.6700439453125,53.8799987161403,19.5570172052591,27.464817,0,0,0,40,4374,281.4998,99.6700439453125,,,,,,,,,,,,,0,,,,,,,,,,,,,,
,19667826.205,278.4845,99.6700439453125,9.90098403917379E-6,3.88801275797292E-7,1,0.999253354069792,40.0298881530762,1.98348924279023,14.2400003969669,0.000111482524526496,1.83564619969178E-5,0.25,-8.34247430355496E-8,9.90837245330174E-6,-7.6296319737185E-8,278.4845,278.4845,99.6700439453125,99.6700439453125,54.1004179585634,19.5616359869055,28.224119,0,0,0,40,4374,278.4845,99.6700439453125,,,,,,,,,,,,,0,,,,,,,,,,,,,,
,19667945.93,275.47615,99.6700439453125,9.86276824904413E-6,3.86938163240955E-7,1,0.999253354069792,40.0298881530762,1.9834873093431,14.2400003969669,0.000111552642160164,1.54689690157344E-5,0.25,-3.33860386303126E-7,9.87137584568047E-6,-3.26886662293317E-7,275.4802,275.4802,99.6700439453125,99.6700439453125,54.0910384163326,19.5653249460152,28.224119,0,0,0,40,4374,275.47615,99.6700439453125,,,,,,,,,,,,,0,,,,,,,,,,,,,,
,19668064.95,272.49385,99.6700439453125,9.63018900774428E-6,3.40348546842452E-7,1,0.999253354069792,40.0298881530762,1.9836591454354,14.2400003969669,0.000109487464319014,1.19645145003481E-5,0.25,-6.05501067145922E-7,9.63983286850145E-6,-5.98899845170458E-7,272.512,272.512,99.6700439453125,99.6700439453125,54.1402810130442,19.56181064704,28.224119,0,0,0,40,4374,272.49385,99.6700439453125,,,,,,,,,,,,,0,,,,,,,,,,,,,,
,19668185.96,269.4623,99.6700439453125,9.8747208736045E-6,3.82589790108107E-7,1,0.999253354069792,40.0298881530762,1.98360587105472,14.2400003969669,0.000111200032770803,1.84815284701196E-5,0.25,-6.86594986467035E-8,9.88526886847025E-6,-6.1271099245169E-8,269.4682,269.4682,99.6700439453125,99.6700439453125,54.0847853881788,19.5651310398806,28.224119,0,0,0,40,4374,269.4623,99.6700439453125,,,,,,,,,,,,,0,,,,,,,,,,,,,,
,19668306,266.4545,99.6700439453125,9.80627450195274E-6,3.51113251465901E-7,1,0.999253354069792,40.0298881530762,1.98366131978782,14.2400003969669,0.000110855863752773,1.59805152117543E-5,0.25,-2.79446061315676E-7,9.81796514330283E-6,-2.7226260227397E-7,266.4545,266.4545,99.6700439453125,99.6700439453125,54.0261632492365,19.5637560954379,27.844467,0,0,0,40,4374,266.4545,99.6700439453125,,,,,,,,,,,,,0,,,,,,,,,,,,,,
,19668425.935,263.4622,99.6700439453125,1.02906304622696E-5,3.34725293837503E-7,1,0.999253354069792,40.0298881530762,1.98352365979947,14.2400003969669,0.00011579855027442,1.98705920934143E-5,0.25,-1.77793507479514E-8,1.03037857603813E-5,-9.81270080444987E-9,263.4622,263.4622,99.6700439453125,99.6700439453125,53.9863001947557,19.5603508671198,27.844467,0,0,0,40,4374,263.4622,99.6700439453125,,,,,,,,,,,,,0,,,,,,,,,,,,,,
,19668546.28,260.4523,99.6700439453125,1.03999537512092E-5,3.51593062278774E-7,1,0.999253354069792,40.0298881530762,1.98342299971372,14.2400003969669,0.000117736594724216,1.60398862571015E-5,0.25,-3.77452887102052E-7,1.04146463110693E-5,-3.69788691957125E-7,260.4568,260.4568,99.6700439453125,99.6700439453125,54.1965582664288,19.5621953405801,28.224119,0,0,0,40,4374,260.4523,99.6700439453125,,,,,,,,,,,,,0,,,,,,,,,,,,,,
,19668665.415,257.4802,99.6700439453125,1.03897306725039E-5,4.18550182081804E-7,1,0.999253354069792,40.0298881530762,1.98324050306974,14.2400003969669,0.000117081237026267,1.91486397263291E-5,0.25,-9.9491465279287E-8,1.04052884850279E-5,-9.13473541502626E-8,257.4841,257.4841,99.6700439453125,99.6700439453125,54.146534041198,19.5630436087584,28.224119,0,0,0,40,4374,257.4802,99.6700439453125,,,,,,,,,,,,,0,,,,,,,,,,,,,,
,19668786.585,254.4495,99.6700439453125,9.62234645284288E-6,3.61116942717647E-7,1,0.999253354069792,40.0298881530762,1.9835819637448,14.2400003969669,0.00010824701284411,1.89853336575636E-5,0.25,1.84876501863349E-8,9.63770048195293E-6,2.63072125651691E-8,254.4495,254.4495,99.6700439453125,99.6700439453125,54.1097975007942,19.5591769552761,28.224119,0,0,0,40,4374,254.4495,99.6700439453125,,,,,,,,,,,,,0,,,,,,,,,,,,,,
,19668906.13,251.4629,99.6700439453125,1.0097483842557E-5,4.38764455344241E-7,1,0.999253354069792,40.0298881530762,1.98347858272877,14.2400003969669,0.000114335803018338,1.56718830222635E-5,0.25,-3.58542394665218E-7,1.01149725759879E-5,-3.50861306386315E-7,251.4629,251.4629,99.6700439453125,99.6700439453125,54.1652931256596,19.5627028789309,27.464817,0,0,0,40,4374,251.4629,99.6700439453125,,,,,,,,,,,,,0,,,,,,,,,,,,,,
,19669025.015,248.4963,99.6700439453125,1.04121325723568E-5,4.34388226911581E-7,1,0.999253354069792,40.0298881530762,1.98356695085472,14.2400003969669,0.000117654031191592,1.76731907501943E-5,0.25,-2.35629843706165E-7,1.04311482416573E-5,-2.27382785463879E-7,248.4963,248.4963,99.6700439453125,99.6700439453125,54.1527870693519,19.5603322923037,27.844467,0,0,0,40,4374,248.4963,99.6700439453125,,,,,,,,,,,,,0,,,,,,,,,,,,,,
,19669146.745,245.4503,99.6700439453125,1.04950007125897E-5,4.23404935199644E-7,1,0.999253354069792,40.0298881530762,1.98342672488185,14.2400003969669,0.000118102821452029,2.06528875698853E-5,0.25,1.45281697562626E-8,1.05150815147616E-5,2.34286752644881E-8,245.4503,245.4503,99.6700439453125,99.6700439453125,54.2020296660634,19.5632077967852,27.844467,0,0,0,40,4374,245.4503,99.6700439453125,,,,,,,,,,,,,0,,,,,,,,,,,,,,
,19669266.475,242.4575,99.6700439453125,1.03944103815186E-5,3.93672658298262E-7,1,0.999253354069792,40.0298881530762,1.98364977824053,14.2400003969669,0.000117444968997924,1.78690009098955E-5,0.25,-2.15817400797985E-7,1.04155860804383E-5,-2.0733480802023E-7,242.4622,242.4622,99.6700439453125,99.6700439453125,54.2364213209096,19.5617587933555,27.844467,0,0,0,40,4374,242.4575,99.6700439453125,,,,,,,,,,,,,0,,,,,,,,,,,,,,
,19669386.52,239.4658,99.6700439453125,1.08014854266744E-5,3.93502295617216E-7,1,0.999253354069792,40.0298881530762,1.98352578156261,14.2400003969669,0.000122105065528299,1.82517369712286E-5,0.25,-2.52643400711803E-7,1.08246462459049E-5,-2.43772603004268E-7,239.4658,239.4658,99.6700439453125,99.6700439453125,54.1246484426596,19.5616958248472,27.464817,0,0,0,40,4374,239.4658,99.6700439453125,,,,,,,,,,,,,0,,,,,,,,,,,,,,
,19669505.88,236.4884,99.6700439453125,1.04673048980929E-5,3.90226732767647E-7,1,0.999253354069792,40.0298881530762,1.98351768921746,14.2400003969669,0.000118117350917022,1.89672212777381E-5,0.25,-1.31428691097106E-7,1.04907359692778E-5,-1.22466492403025E-7,236.4927,236.4927,99.6700439453125,99.6700439453125,54.1340279848903,19.5628788637226,27.844467,0,0,0,40,4374,236.4884,99.6700439453125,,,,,,,,,,,,,0,,,,,,,,,,,,,,
,19669626.005,233.48395,99.6700439453125,1.08052148039015E-5,3.3948550741761E-7,1,0.999253354069792,40.0298881530762,1.98346951102167,14.2400003969669,0.000121811539663389,2.03233373689915E-5,0.25,-6.99062606410733E-8,1.0830469330921E-5,-6.03668546088802E-8,233.4888,233.4888,99.6700439453125,99.6700439453125,54.1848338386403,19.5646598113736,27.844467,0,0,0,40,4374,233.48395,99.6700439453125,,,,,,,,,,,,,0,,,,,,,,,,,,,,
,19669746.36,230.47375,99.6700439453125,1.06385568830271E-5,3.01495474893413E-7,1,0.999253354069792,40.0298881530762,1.98336294209551,14.2400003969669,0.000120672132698468,1.57857702086289E-5,0.25,-4.44169064195455E-7,1.06648691953308E-5,-4.35546830096134E-7,230.4783,230.4783,99.6700439453125,99.6700439453125,54.149660555275,19.5623422128095,28.224119,0,0,0,40,4374,230.47375,99.6700439453125,,,,,,,,,,,,,0,,,,,,,,,,,,,,
,19669865.93,227.4905,99.6700439453125,1.08680840181022E-5,3.47371023174663E-7,1,0.999253354069792,40.0298881530762,1.98370662793707,14.2400003969669,0.000122931823742178,1.83025517061161E-5,0.25,-2.61098182309339E-7,1.08959043435405E-5,-2.5168969967766E-7,227.4905,227.4905,99.6700439453125,99.6700439453125,54.1129240148711,19.560333084985,27.464817,0,0,0,40,4374,227.4905,99.6700439453125,,,,,,,,,,,,,0,,,,,,,,,,,,,,
,19669986.955,224.46715,99.6700439453125,1.07201490346544E-5,3.75353704169493E-7,1,0.999253354069792,40.0298881530762,1.98356707749861,14.2400003969669,0.000121488683170746,1.67528680175801E-5,0.25,-3.73217329281111E-7,1.07488096219881E-5,-3.64106157213094E-7,224.4697,224.4697,99.6700439453125,99.6700439453125,54.0496121048134,19.5614327609193,28.224119,0,0,0,40,4374,224.46715,99.6700439453125,,,,,,,,,,,,,0,,,,,,,,,,,,,,
,19670105.69,221.4998,99.6700439453125,1.12858641984247E-5,3.50192381615914E-7,1,0.999253354069792,40.0298881530762,1.98365001833964,14.2400003969669,0.000127974643715939,1.7311981039178E-5,0.25,-4.2214883540438E-7,1.13172078545945E-5,-4.1250285214756E-7,221.5042,221.5042,99.6700439453125,99.6700439453125,54.1223035571019,19.5620559702536,28.224119,0,0,0,40,4374,221.4998,99.6700439453125,,,,,,,,,,,,,0,,,,,,,,,,,,,,
,19670226.665,218.4836,99.6700439453125,1.06925239800628E-5,2.92412990249207E-7,1,0.999253354069792,40.0298881530762,1.98325059966129,14.2400003969669,0.000121288405734967,1.60960750214272E-5,0.25,-4.27136270461508E-7,1.07233408402948E-5,-4.17942474720444E-7,218.4866,218.4866,99.6700439453125,99.6700439453125,54.2825374035442,19.5664560259688,27.844467,0,0,0,40,4374,218.4836,99.6700439453125,,,,,,,,,,,,,0,,,,,,,,,,,,,,
,19670347.735,215.4553,99.6700439453125,1.09500915588219E-5,3.48017487232299E-7,1,0.999253354069792,40.0298881530762,1.98318465921742,14.2400003969669,0.000123777308894521,1.90281155918049E-5,0.25,-2.11869652762688E-7,1.09825465219291E-5,-2.01650605796902E-7,215.4553,215.4553,99.6700439453125,99.6700439453125,54.1957766379096,19.5631216744364,27.464817,0,0,0,40,4374,215.4553,99.6700439453125,,,,,,,,,,,,,0,,,,,,,,,,,,,,
,19670466.74,212.48325,99.6700439453125,1.09839003799014E-5,3.5526946069789E-7,1,0.999253354069792,40.0298881530762,1.98329244855795,14.2400003969669,0.000124337217897871,1.81739173408815E-5,0.25,-2.93989784513468E-7,1.1017628464699E-5,-2.83820613433782E-7,212.5009,212.5009,99.6700439453125,99.6700439453125,54.1207403000634,19.561393789831,27.464817,0,0,0,40,4374,212.48325,99.6700439453125,,,,,,,,,,,,,0,,,,,,,,,,,,,,
,19670587.42,209.48035,99.6700439453125,1.06221831342293E-5,3.09947161643991E-7,1,0.999253354069792,40.0298881530762,1.98330097491179,14.2400003969669,0.000120863385391649,1.40736246105401E-5,0.25,-5.95411964613779E-7,1.06561794192417E-5,-5.86393793954661E-7,209.4837,209.4837,99.6700439453125,99.6700439453125,54.0316346488711,19.5625086969791,28.224119,0,0,0,40,4374,209.48035,99.6700439453125,,,,,,,,,,,,,0,,,,,,,,,,,,,,
,19670707.655,206.47655,99.6700439453125,1.05102908852599E-5,3.17265213546218E-7,1,0.999253354069792,40.0298881530762,1.98329822714058,14.2400003969669,0.000119027382661648,1.72355592143389E-5,0.25,-2.95732880207622E-7,1.05446700774138E-5,-2.85721640322462E-7,206.4801,206.4801,99.6700439453125,99.6700439453125,54.0167837070057,19.5600224063006,27.844467,0,0,0,40,4374,206.47655,99.6700439453125,,,,,,,,,,,,,0,,,,,,,,,,,,,,
,19670828.95,203.4586,99.6700439453125,1.08491177162517E-5,3.4398373888397E-7,1,0.999253354069792,40.0298881530762,1.98313546186461,14.2400003969669,0.000123202218430958,1.5861410308019E-5,0.25,-4.76739209425641E-7,1.08858596895107E-5,-4.6679785498672E-7,203.4586,203.4586,99.6700439453125,99.6700439453125,53.9831736806788,19.5628555430814,27.844467,0,0,0,40,4374,203.4586,99.6700439453125,,,,,,,,,,,,,0,,,,,,,,,,,,,,
,19670949.255,200.45515,99.6700439453125,1.0975775556989E-5,3.32473055705141E-7,1,0.999253354069792,40.0298881530762,1.98323328209854,14.2400003969669,0.000124797335927386,1.52499979887791E-5,0.25,-5.53401646849327E-7,1.10140977054795E-5,-5.43415462470559E-7,200.4604,200.4604,99.6700439453125,99.6700439453125,54.0699344463134,19.5618805437731,27.844467,0,0,0,40,4374,200.45515,99.6700439453125,,,,,,,,,,,,,0,,,,,,,,,,,,,,
,19671068.82,197.4737,99.6700439453125,1.07993115891881E-5,3.67718223255989E-7,1,0.999253354069792,40.0298881530762,1.98319746197685,14.2400003969669,0.000122111628517059,1.89721395179043E-5,0.25,-1.9288053555277E-7,1.08376713783912E-5,-1.81641336789592E-7,197.4936,197.4936,99.6700439453125,99.6700439453125,54.0378876770249,19.5607990657441,27.085165,0,0,0,40,4374,197.4737,99.6700439453125,,,,,,,,,,,,,0,,,,,,,,,,,,,,
,19671189.865,194.46455,99.6700439453125,1.06554434968983E-5,3.589408132417E-7,1,0.999253354069792,40.0298881530762,1.98311805285891,14.2400003969669,0.000120166828444819,2.05907589995825E-5,0.25,-2.46314268748965E-8,1.06941267068579E-5,-1.27272596469368E-8,194.4701,194.4701,99.6700439453125,99.6700439453125,53.9253331702557,19.5631475880434,27.844467,0,0,0,40,4374,194.46455,99.6700439453125,,,,,,,,,,,,,0,,,,,,,,,,,,,,
,19671309.11,191.493,99.6700439453125,1.07829242871087E-5,2.90227625510438E-7,1,0.999253354069792,40.0298881530762,1.98304341003567,14.2400003969669,0.00012351222788602,9.89878305601667E-6,0.25,-9.95532914476057E-7,1.08241912039606E-5,-9.86858819068221E-7,191.4971,191.4971,99.6700439453125,99.6700439453125,53.9261147987749,19.5618925923623,27.464817,0,0,0,40,4374,191.493,99.6700439453125,,,,,,,,,,,,,0,,,,,,,,,,,,,,
,19671429.925,188.4702,99.6700439453125,1.06546795521352E-5,2.89063595029749E-7,1,0.999253354069792,40.0298881530762,1.98282114942803,14.2400003969669,0.000121004878134335,1.57482932687728E-5,0.25,-4.54615152589247E-7,1.06958598578058E-5,-4.43864745207439E-7,188.4745,188.4745,99.6700439453125,99.6700439453125,54.1652931256596,19.5654432790123,27.085165,0,0,0,40,4374,188.4702,99.6700439453125,,,,,,,,,,,,,0,,,,,,,,,,,,,,
,19671551.015,185.4573,99.6700439453125,1.08012385980247E-5,2.85930551237931E-7,1,0.999253354069792,40.0298881530762,1.98276571507089,14.2400003969669,0.000122542262442313,1.67441604922097E-5,0.25,-3.92110624646831E-7,1.08439144444592E-5,-3.80718620102313E-7,185.4573,185.4573,99.6700439453125,99.6700439453125,54.1613849830634,19.5649889517691,27.844467,0,0,0,40,4374,185.4573,99.6700439453125,,,,,,,,,,,,,0,,,,,,,,,,,,,,
,19671670.75,182.47265,99.6700439453125,1.07849335462293E-5,3.37025730249766E-7,1,0.999253354069792,40.0298881530762,1.98279942513905,14.2400003969669,0.000122307450498969,1.7082981132571E-5,0.25,-3.59661478797775E-7,1.0828493570661E-5,-3.47917720388287E-7,182.4767,182.4767,99.6700439453125,99.6700439453125,54.1559135834288,19.5647158771566,27.085165,0,0,0,40,4374,182.47265,99.6700439453125,,,,,,,,,,,,,0,,,,,,,,,,,,,,
,19671791.045,179.4713,99.6700439453125,1.05921745969517E-5,3.37023764597574E-7,1,0.999253354069792,40.0298881530762,1.98274289722002,14.2400003969669,0.000119101770239963,2.26874964920996E-5,0.25,1.70501529641987E-7,1.06352647289497E-5,1.84431359668037E-7,179.476,179.476,99.6700439453125,99.6700439453125,54.0988547015249,19.5648412482437,26.705515,0,0,0,40,4374,179.4713,99.6700439453125,,,,,,,,,,,,,0,,,,,,,,,,,,,,
,19671912.03,176.4496,99.6700439453125,1.06080397844949E-5,2.94526928968571E-7,1,0.999253354069792,40.0298881530762,1.98262204063977,14.2400003969669,0.000120958929177131,1.30886983166593E-5,0.25,-6.83865360229559E-7,1.06532302220596E-5,-6.73166538227344E-7,176.4496,176.4496,99.6700439453125,99.6700439453125,53.7994909786595,19.5625543636911,26.705515,0,0,0,40,4374,176.4496,99.6700439453125,,,,,,,,,,,,,0,,,,,,,,,,,,,,
,19672031.485,173.48165,99.6700439453125,1.10073262422591E-5,3.60165420912899E-7,1,0.999253354069792,40.0298881530762,1.98259183555375,14.2400003969669,0.00012487555790127,1.72938908437387E-5,0.25,-3.80802527880295E-7,1.10547618601531E-5,-3.68035924892392E-7,173.4855,173.4855,99.6700439453125,99.6700439453125,53.953471796948,19.5608591744438,27.464817,0,0,0,40,4374,173.48165,99.6700439453125,,,,,,,,,,,,,0,,,,,,,,,,,,,,
,19672150.895,170.493,99.6700439453125,1.08790057571506E-5,3.19921672203526E-7,1,0.999253354069792,40.0298881530762,1.98254326295932,14.2400003969669,0.000123254501438155,1.80884531872745E-5,0.25,-2.88464101684446E-7,1.09267169579789E-5,-2.75156919034907E-7,170.493,170.493,99.6700439453125,99.6700439453125,54.1152689004288,19.5649136312774,27.464817,0,0,0,40,4374,170.493,99.6700439453125,,,,,,,,,,,,,0,,,,,,,,,,,,,,
,19672273.27,167.48465,99.6700439453125,1.10204135026262E-5,3.40185708588472E-7,1,0.999253354069792,40.0298881530762,1.98240196061,14.2500000074506,0.000125394127204661,1.52468862965256E-5,0.25,-5.65415610666046E-7,1.10700668639982E-5,-5.52807735163588E-7,167.489,167.489,99.6700439453125,99.6700439453125,53.8917231439288,19.5644929004007,27.464817,0,0,0,40,4374,167.48465,99.6700439453125,,,,,,,,,,,,,0,,,,,,,,,,,,,,
,19672394.89,164.4965,99.6700439453125,1.07735456379283E-5,2.96613126902251E-7,1,0.999253354069792,40.0298881530762,1.98218334279859,14.2500000074506,0.000121596742455353,2.05703885977733E-5,0.25,-5.07550109141334E-8,1.08222947758124E-5,-3.58344485893002E-8,164.4965,164.4965,99.6700439453125,99.6700439453125,54.0441407051788,19.5678778332176,27.085165,0,0,0,40,4374,164.4965,99.6700439453125,,,,,,,,,,,,,0,,,,,,,,,,,,,,
,19672515.505,161.4921,99.6700439453125,1.07446055395815E-5,3.60637918551979E-7,1,0.999253354069792,40.0298881530762,1.98219207865668,14.2400003969669,0.000121994386799806,1.64156602043206E-5,0.25,-4.14651365737634E-7,1.07946316276385E-5,-4.01055027310566E-7,161.4921,161.4921,99.6700439453125,99.6700439453125,54.3208372009865,19.5716846378481,27.085165,0,0,0,40,4374,161.4921,99.6700439453125,,,,,,,,,,,,,0,,,,,,,,,,,,,,
,19672637.235,158.44755,99.6700439453125,1.08050788013787E-5,3.6478511842511E-7,1,0.999253354069792,40.0298881530762,1.98209320505429,14.2400003969669,0.000122363162007006,1.8358896026526E-5,0.25,-2.533559651061E-7,1.08560398839628E-5,-2.38525709439499E-7,158.4522,158.4522,99.6700439453125,99.6700439453125,54.1066709867173,19.5693854910281,26.705515,0,0,0,40,4374,158.44755,99.6700439453125,,,,,,,,,,,,,0,,,,,,,,,,,,,,
,19672755.69,155.4894,99.6700439453125,1.11861233468032E-5,2.97942753487013E-7,1,0.999253354069792,40.0298881530762,1.9822257837074,14.2400003969669,0.000126608157030654,1.95153019880011E-5,0.25,-2.17857941714016E-7,1.12396902554831E-5,-2.01860722926713E-7,155.4894,155.4894,99.6700439453125,99.6700439453125,54.0175653355249,19.5683249309746,26.325863,0,0,0,40,4374,155.4894,99.6700439453125,,,,,,,,,,,,,0,,,,,,,,,,,,,,
,19672875.61,152.4965,99.6700439453125,1.05825676340523E-5,3.09960968392431E-7,1,0.999253354069792,40.0298881530762,1.98223872869895,14.2400003969669,0.000120426279478367,1.47930821809928E-5,0.25,-5.31957904934091E-7,1.06345730099944E-5,-5.17956071937253E-7,152.5016,152.5016,99.6700439453125,99.6700439453125,53.9909899658711,19.5724943337458,27.085165,0,0,0,40,4374,152.4965,99.6700439453125,,,,,,,,,,,,,0,,,,,,,,,,,,,,
,19672996.15,149.4904,99.6700439453125,1.03185935063913E-5,2.5600533967284E-7,1,0.999253354069792,40.0298881530762,1.98211636995518,14.2400003969669,0.000117078981359929,1.64071192894394E-5,0.25,-3.43400771416507E-7,1.03698155200152E-5,-3.28448913226054E-7,149.4946,149.4946,99.6700439453125,99.6700439453125,54.1449707841596,19.5750337491692,27.085165,0,0,0,40,4374,149.4904,99.6700439453125,,,,,,,,,,,,,0,,,,,,,,,,,,,,
,19673118.06,146.4626,99.6700439453125,1.06012102073155E-5,2.90007439465622E-7,1,0.999253354069792,40.0298881530762,1.9820700790746,14.2400003969669,0.000120343688927877,1.65605680282608E-5,0.25,-3.79637751253134E-7,1.06546741467924E-5,-3.63910566265472E-7,146.4626,146.4626,99.6700439453125,99.6700439453125,54.1066709867173,19.5766909190548,25.946213,0,0,0,40,4374,146.4626,99.6700439453125,,,,,,,,,,,,,0,,,,,,,,,,,,,,
,19673239.07,143.4634,99.6700439453125,1.05245333730545E-5,2.87857467473015E-7,1,0.999253354069792,40.0298881530762,1.981993166273,14.2400003969669,0.000118886225824332,1.98325711841091E-5,0.25,-7.68461862358029E-8,1.05778562825289E-5,-5.91925407633313E-8,143.4634,143.4634,99.6700439453125,99.6700439453125,53.9792655380826,19.579756645372,26.325863,0,0,0,40,4374,143.4634,99.6700439453125,,,,,,,,,,,,,0,,,,,,,,,,,,,,
,19673358.22,140.4972,99.6700439453125,1.068580653717E-5,4.25911178859567E-7,1,0.999253354069792,40.0298881530762,1.98216547219591,14.2400003969669,0.000120517261193204,2.13372760865348E-5,0.25,2.75453928168945E-8,1.0740482084994E-5,4.65940399705786E-8,140.5018,140.5018,99.6700439453125,99.6700439453125,54.0292897633134,19.5768550307053,26.705515,0,0,0,40,4374,140.4972,99.6700439453125,,,,,,,,,,,,,0,,,,,,,,,,,,,,
,19673480.465,137.4596,99.6700439453125,1.03926560135062E-5,3.24461850649032E-7,1,0.999253354069792,40.0298881530762,1.98208990909152,14.2400003969669,0.000117069837742342,2.15816287016955E-5,0.25,9.96462897020211E-8,1.04463843466101E-5,1.19178839293143E-7,137.4596,137.4596,99.6700439453125,99.6700439453125,54.1316830993327,19.5782718720644,26.325863,0,0,0,40,4374,137.4596,99.6700439453125,,,,,,,,,,,,,0,,,,,,,,,,,,,,
,19673599.875,134.4889,99.6700439453125,1.05124701858969E-5,3.29360306463305E-7,1,0.999253354069792,40.0298881530762,1.98218082658703,14.2400003969669,0.000118763013958663,1.99355747757765E-5,0.25,-6.79824413057046E-8,1.0567781755014E-5,-4.8440945682941E-8,134.4889,134.4889,99.6700439453125,99.6700439453125,53.9659778532557,19.5717161585261,25.566563,0,0,0,40,4374,134.4889,99.6700439453125,,,,,,,,,,,,,0,,,,,,,,,,,,,,
,19673720.875,131.4842,99.6700439453125,1.00553884879839E-5,3.38978109588867E-7,1,0.999253354069792,40.0298881530762,1.98228011345893,14.2400003969669,0.000114694397793948,1.28677899159263E-5,0.25,-6.15347414837512E-7,1.01099773672847E-5,-5.98893192444482E-7,131.489,131.489,99.6700439453125,99.6700439453125,54.2184438649673,19.5713742266832,25.946213,0,0,0,40,4374,131.4842,99.6700439453125,,,,,,,,,,,,,0,,,,,,,,,,,,,,
,19673842.4,128.4651,99.6700439453125,1.0486948348459E-5,2.76478971765095E-7,1,0.999253354069792,40.0298881530762,1.98229123114993,14.2400003969669,0.000118787313466654,1.82157584317115E-5,0.25,-2.1769108836978E-7,1.05436556598875E-5,-1.9751757629417E-7,128.4651,128.4651,99.6700439453125,99.6700439453125,54.1379361274865,19.5695522296672,26.325863,0,0,0,40,4374,128.4651,99.6700439453125,,,,,,,,,,,,,0,,,,,,,,,,,,,,
,19673962.42,125.4795,99.6700439453125,1.06506560876805E-5,3.41350309867506E-7,1,0.999253354069792,40.0298881530762,1.98223437832037,14.2400003969669,0.000121473634770454,1.37574641837885E-5,0.25,-6.42174305042571E-7,1.07097100022247E-5,-6.23142183735808E-7,125.4834,125.4834,99.6700439453125,99.6700439453125,54.2833190320634,19.5700833777034,25.946213,0,0,0,40,4374,125.4795,99.6700439453125,,,,,,,,,,,,,0,,,,,,,,,,,,,,
,19674083.555,122.4774,99.6700439453125,1.03978683373681E-5,3.33385254841329E-7,1,0.999253354069792,40.0298881530762,1.98213011188776,14.2400003969669,0.000117988117008706,1.68786259933062E-5,0.25,-3.22338898923662E-7,1.04554049458484E-5,-3.0123946586531E-7,122.4774,122.4774,99.6700439453125,99.6700439453125,54.4482426496212,19.5690739076023,25.566563,0,0,0,40,4374,122.4774,99.6700439453125,,,,,,,,,,,,,0,,,,,,,,,,,,,,
,19674206.11,119.4416,99.6700439453125,1.03080164711855E-5,2.61689147910139E-7,1,0.999253354069792,40.0298881530762,1.98205000101742,14.2400003969669,0.000116886518205578,1.7207261309515E-5,0.25,-2.78475838634931E-7,1.03654445818247E-5,-2.56388719419846E-7,119.4416,119.4416,99.6700439453125,99.6700439453125,54.3536655987942,19.5710985424794,25.566563,0,0,0,40,4374,119.4416,99.6700439453125,,,,,,,,,,,,,0,,,,,,,,,,,,,,
,19674326.13,116.4877,99.6700439453125,1.02386861959899E-5,2.51188430547735E-7,1,0.999253354069792,40.0298881530762,1.981872202177,14.2500000074506,0.000116692495892115,1.36774442816581E-5,0.25,-5.8005395181852E-7,1.02968655220953E-5,-5.58807966899131E-7,116.4877,116.4877,99.6700439453125,99.6700439453125,54.0300713918326,19.5711775919066,25.566563,0,0,0,40,4374,116.4877,99.6700439453125,,,,,,,,,,,,,0,,,,,,,,,,,,,,
,19674447.86,113.482,99.6700439453125,1.01304269057205E-5,2.70826035291119E-7,1,0.999253354069792,40.0298881530762,1.98205401582858,14.2400003969669,0.000114342017359356,1.99935344016045E-5,0.25,-2.73003848041567E-9,1.01869550032555E-5,2.25511757761536E-8,113.482,113.482,99.6700439453125,99.6700439453125,54.2848822891019,19.5702727911762,25.186911,0,0,0,40,4374,113.482,99.6700439453125,,,,,,,,,,,,,0,,,,,,,,,,,,,,
,19674570.815,110.44945,99.6700439453125,1.02601059930327E-5,2.69379538669617E-7,1,0.999253354069792,40.0298881530762,1.98171734701791,14.2500000074506,0.000116339184016408,1.71126812995428E-5,0.25,-2.81693514810836E-7,1.03183527154329E-5,-2.56440463505157E-7,110.4536,110.4536,99.6700439453125,99.6700439453125,54.0175653355249,19.5792532050266,25.186911,0,0,0,40,4374,110.44945,99.6700439453125,,,,,,,,,,,,,0,,,,,,,,,,,,,,
,19674690.2,107.4926,99.6700439453125,1.02912502847791E-5,2.60310990209379E-7,1,0.999253354069792,40.0298881530762,1.98183455437787,14.2400003969669,0.000117010829678277,1.54016814759132E-5,0.25,-4.40165384223451E-7,1.03503221966057E-5,-4.14437998842666E-7,107.4926,107.4926,99.6700439453125,99.6700439453125,54.1676380112173,19.5803469841969,25.186911,0,0,0,40,4374,107.4926,99.6700439453125,,,,,,,,,,,,,0,,,,,,,,,,,,,,
,19674814.275,104.44595,99.6700439453125,1.02454091776136E-5,2.86361822130002E-7,1,0.999253354069792,40.0298881530762,1.98190439546076,14.2400003969669,0.000115847016488348,1.90273258321666E-5,0.25,-1.12361441302325E-7,1.03034332987197E-5,-8.34765856683641E-8,104.4503,104.4503,99.6700439453125,99.6700439453125,54.3669532836211,19.5747622043871,24.427608,0,0,0,40,4374,104.44595,99.6700439453125,,,,,,,,,,,,,0,,,,,,,,,,,,,,
,19674935.27,101.46225,99.6700439453125,1.02561930487242E-5,2.7991897941688E-7,1,0.999253354069792,40.0298881530762,1.98174490420165,14.2500000074506,0.00011612492138328,1.81076907277859E-5,0.25,-1.97156766160859E-7,1.03145355123194E-5,-1.67175269726819E-7,101.4664,101.4664,99.6700439453125,99.6700439453125,54.2364213209096,19.573336514053,24.427608,0,0,0,40,4374,101.46225,99.6700439453125,,,,,,,,,,,,,0,,,,,,,,,,,,,,
,19675057.085,98.44815,99.6700439453125,1.0201200619466E-5,3.19750499268017E-7,1,0.999253354069792,40.0298881530762,1.9818122996205,14.2400003969669,0.000116020193392198,1.50805184040633E-5,0.25,-4.57483177130114E-7,1.02599569408011E-5,-4.27433790177258E-7,98.4512,98.4512,99.6700439453125,99.6700439453125,54.1785808104865,19.571851813208,24.807261,0,0,0,40,4374,98.44815,99.6700439453125,,,,,,,,,,,,,0,,,,,,,,,,,,,,
,19675177.41,95.45895,99.6700439453125,1.04107174875269E-5,3.0711835597316E-7,1,0.999253354069792,40.0298881530762,1.98203112249245,14.2400003969669,0.000118459384900672,1.51295949396798E-5,0.25,-4.91964443058609E-7,1.04705563074357E-5,-4.59549319003178E-7,95.4674,95.4674,99.6700439453125,99.6700439453125,54.0832221311403,19.5736680306542,24.047956,0,0,0,40,4374,95.45895,99.6700439453125,,,,,,,,,,,,,0,,,,,,,,,,,,,,
,19675299.985,92.41575,99.6700439453125,1.03900201924466E-5,2.99962393711132E-7,1,0.999253354069792,40.0298881530762,1.98198178287836,14.2400003969669,0.000117699279928573,1.80351773449275E-5,0.25,-2.32818415262554E-7,1.04484342748974E-5,-1.96925364728863E-7,92.4217,92.4217,99.6700439453125,99.6700439453125,54.0167837070057,19.5768671376995,24.047956,0,0,0,40,4374,92.41575,99.6700439453125,,,,,,,,,,,,,0,,,,,,,,,,,,,,
,19675421.345,89.4355,99.6700439453125,1.02832405236701E-5,2.76191760961935E-7,1,0.999253354069792,40.0298881530762,1.9820385639147,14.2400003969669,0.000116775544440483,1.62077315666571E-5,0.25,-3.78126695739069E-7,1.03409864745857E-5,-3.41176081856077E-7,89.4458,89.4458,99.6700439453125,99.6700439453125,53.9761390240057,19.574838720738,24.047956,0,0,0,40,4374,89.4355,99.6700439453125,,,,,,,,,,,,,0,,,,,,,,,,,,,,
,19675543.71,86.4573,99.6700439453125,1.04231755036812E-5,3.11769897591043E-7,1,0.999253354069792,40.0298881530762,1.98208796920699,14.2400003969669,0.000118207610101909,1.72780482428941E-5,0.25,-3.10322463808539E-7,1.04805604812959E-5,-2.6997905772326E-7,86.4631,86.4631,99.6700439453125,99.6700439453125,54.085567016698,19.5728277352527,24.427608,0,0,0,40,4374,86.4573,99.6700439453125,,,,,,,,,,,,,0,,,,,,,,,,,,,,
,19675666.485,83.4577,99.6700439453125,1.03572182464166E-5,3.0717201913061E-7,1,0.999253354069792,40.0298881530762,1.98200091683827,14.2400003969669,0.000117621007392807,1.61520127341158E-5,0.25,-4.0095301684898E-7,1.04134619266607E-5,-3.58619796650606E-7,83.4665,83.4665,99.6700439453125,99.6700439453125,54.1551319549096,19.5751415876743,23.668306,0,0,0,40,4374,83.4577,99.6700439453125,,,,,,,,,,,,,0,,,,,,,,,,,,,,
,19675788.96,80.47,99.6700439453125,1.01772089946541E-5,3.11146711451805E-7,1,0.999253354069792,40.0298881530762,1.98198227923356,14.2400003969669,0.000114914658822506,1.95039785429058E-5,0.25,-7.45010728839819E-8,1.02295255074131E-5,-2.83342703782308E-8,80.4737,80.4737,99.6700439453125,99.6700439453125,54.5326585296981,19.5752618540145,23.668306,0,0,0,40,4374,80.47,99.6700439453125,,,,,,,,,,,,,0,,,,,,,,,,,,,,
,19675910.415,77.49795,99.6700439453125,1.05164663504744E-5,2.84951280162456E-7,1,0.999253354069792,40.0298881530762,1.98193064706092,14.2400003969669,0.000118604492832833,2.07955481999548E-5,0.25,-2.28939927397261E-8,1.05681818354105E-5,2.82961133153749E-8,77.5054,77.5054,99.6700439453125,99.6700439453125,54.0605549040826,19.5755695171958,23.668306,0,0,0,40,4374,77.49795,99.6700439453125,,,,,,,,,,,,,0,,,,,,,,,,,,,,
,19676032.825,74.49145,99.6700439453125,1.02129900637541E-5,3.50507950776782E-7,1,0.999253354069792,40.0298881530762,1.98186638900695,14.2400003969669,0.000115328346576226,1.91831175532624E-5,0.25,-1.14930530338352E-7,1.02610876497822E-5,-6.22619196459334E-8,74.4957,74.4957,99.6700439453125,99.6700439453125,53.9769206525249,19.5751181643064,22.909004,0,0,0,40,4374,74.49145,99.6700439453125,,,,,,,,,,,,,0,,,,,,,,,,,,,,
,19676155.165,71.49345,99.6700439453125,1.01699226321398E-5,3.2224595463875E-7,1,0.999253354069792,40.0298881530762,1.98194241600952,14.2400003969669,0.000115987628625901,1.24934095533058E-5,0.25,-7.04160293331747E-7,1.02178827623499E-5,-6.50671962899366E-7,71.5019,71.5019,99.6700439453125,99.6700439453125,53.9628513391788,19.5769993677371,23.288654,0,0,0,40,4374,71.49345,99.6700439453125,,,,,,,,,,,,,0,,,,,,,,,,,,,,
,19676277.12,68.4796,99.6700439453125,1.06134493478601E-5,3.22456466323085E-7,1,0.999253354069792,40.0298881530762,1.98202066284499,14.2400003969669,0.000120194015837593,1.75783716752047E-5,0.25,-3.35226410560118E-7,1.06571744501068E-5,-2.7366198873415E-7,68.4796,68.4796,99.6700439453125,99.6700439453125,54.2833190320634,19.5792252094886,22.909004,0,0,0,40,4374,68.4796,99.6700439453125,,,,,,,,,,,,,0,,,,,,,,,,,,,,
,19676397.645,65.4918,99.6700439453125,1.00169880131414E-5,3.02375805585547E-7,1,0.999253354069792,40.0298881530762,1.98202710079434,14.2400003969669,0.000113012435722622,1.86730991153943E-5,0.25,-1.34344305894928E-7,1.00523929385387E-5,-7.18001967799259E-8,65.4918,65.4918,99.6700439453125,99.6700439453125,53.9526901684288,19.5769718197863,22.909004,0,0,0,40,4374,65.4918,99.6700439453125,,,,,,,,,,,,,0,,,,,,,,,,,,,,
,19676519.695,62.4989,99.6700439453125,1.0227863021587E-5,2.95035349843327E-7,1,0.999253354069792,40.0298881530762,1.98196572871436,14.2500000074506,0.000116482363031348,1.25879113354781E-5,0.25,-7.15765219375738E-7,1.02619659860464E-5,-6.49875715278212E-7,62.4989,62.4989,99.6700439453125,99.6700439453125,54.3114576587558,19.5769608628941,22.909004,0,0,0,40,4374,62.4989,99.6700439453125,,,,,,,,,,,,,0,,,,,,,,,,,,,,
,19676642.915,59.47275,99.6700439453125,1.02650213181669E-5,2.95959458731378E-7,1,0.999253354069792,40.0298881530762,1.98185161617541,14.2400003969669,0.000115716372278045,1.87726344766145E-5,0.25,-1.7466666683777E-7,1.02885943483365E-5,-1.0355710798084E-7,59.4769,59.4769,99.6700439453125,99.6700439453125,53.5853247643903,19.5795021401775,22.529354,0,0,0,40,4374,59.47275,99.6700439453125,,,,,,,,,,,,,0,,,,,,,,,,,,,,
,19676765.135,56.4735,99.6700439453125,1.01996387680458E-5,2.9901824882621E-7,1,0.999253354069792,40.0298881530762,1.98188694572286,14.2400003969669,0.000115367568343871,1.59962475283078E-5,0.25,-4.11556785823331E-7,1.02168109166397E-5,-3.38476616297198E-7,56.4735,56.4735,99.6700439453125,99.6700439453125,54.187178724198,19.5832063870005,22.149702,0,0,0,40,4374,56.4735,99.6700439453125,,,,,,,,,,,,,0,,,,,,,,,,,,,,
,19676888.185,53.449,99.6700439453125,1.00942507791362E-5,3.01571513571698E-7,1,0.999253354069792,40.0298881530762,1.98168687512026,14.2400003969669,0.000113898869764919,1.67396495715792E-5,0.25,-3.26701659828682E-7,1.01018546592369E-5,-2.52282852997025E-7,53.449,53.449,99.6700439453125,99.6700439453125,53.7557197815826,19.5814249306483,21.3904,0,0,0,40,4374,53.449,99.6700439453125,,,,,,,,,,,,,0,,,,,,,,,,,,,,
,19677009.91,50.4704,99.6700439453125,1.00781793721408E-5,2.4863529625273E-7,1,0.999253354069792,40.0298881530762,1.98166072393366,14.2400003969669,0.000112870624450047,2.080921173212E-5,0.25,4.00960789167681E-8,1.00737892160064E-5,1.15074884998795E-7,50.4704,50.4704,99.6700439453125,99.6700439453125,53.2367184448133,19.5818292495274,21.3904,0,0,0,40,4374,50.4704,99.6700439453125,,,,,,,,,,,,,0,,,,,,,,,,,,,,
,19677133.665,47.4459,99.6700439453125,1.02030753221882E-5,2.74908052699162E-7,1,0.999253354069792,40.0298881530762,1.98170500854939,14.2400003969669,0.000114785799707577,1.75928028950165E-5,0.25,-2.67252102334237E-7,1.0191218256227E-5,-1.91725115616288E-7,47.4492,47.4492,99.6700439453125,99.6700439453125,53.8166868060826,19.579731269056,21.01075,0,0,0,40,4370,47.4459,99.6700439453125,,,,,,,,,,,,,0,,,,,,,,,,,,,,
,19677255.22,44.48175,99.6700439453125,9.80598600683387E-6,3.05410512625824E-7,1,0.999253354069792,40.0298881530762,1.9817767228658,14.2500000074506,0.000110223857896369,1.68850949827374E-5,0.25,-2.55752172106403E-7,9.78572235346428E-6,-1.84835553904185E-7,44.4876,44.4876,99.6700439453125,99.6700439453125,54.088693530775,19.5811483860881,20.251448,0,0,0,40,4370,44.48175,99.6700439453125,,,,,,,,,,,,,0,,,,,,,,,,,,,,
,19677376.38,41.49765,99.6700439453125,1.0161856410643E-5,3.0924672513273E-7,1,0.999253354069792,40.0298881530762,1.98176262897885,14.2400003969669,0.00011404118409328,1.79614381267332E-5,0.25,-2.19298979213546E-7,1.01320326687734E-5,-1.48720087612237E-7,41.5044,41.5044,99.6700439453125,99.6700439453125,53.8393540331403,19.5774212991564,19.871798,0,0,0,40,4370,41.49765,99.6700439453125,,,,,,,,,,,,,0,,,,,,,,,,,,,,
,19677498.375,38.4915,99.6700439453125,1.00541407223016E-5,2.8802178506051E-7,1,0.999253354069792,40.0298881530762,1.98189718302282,14.2400003969669,0.000112892906666935,1.69964816564757E-5,0.25,-2.81624323643222E-7,1.00176594547888E-5,-2.15029221396498E-7,38.4915,38.4915,99.6700439453125,99.6700439453125,53.9784839095634,19.5805936471527,19.112494,0,0,0,40,4370,38.4915,99.6700439453125,,,,,,,,,,,,,0,,,,,,,,,,,,,,
,19677620.555,35.47955,99.6700439453125,9.96818611665275E-6,3.20995610265526E-7,1,0.999253354069792,40.0298881530762,1.98190532754047,14.2400003969669,0.000112286090757581,1.44536585435854E-5,0.25,-4.8915297129295E-7,9.9271836457273E-6,-4.25895933861655E-7,35.4841,35.4841,99.6700439453125,99.6700439453125,54.2137540938519,19.5800215803623,18.732843,0,0,0,40,4370,35.47955,99.6700439453125,,,,,,,,,,,,,0,,,,,,,,,,,,,,
,19677741.025,32.4989,99.6700439453125,9.98411523449431E-6,2.77950417624294E-7,1,0.999253354069792,40.0298881530762,1.98183629859896,14.2500000074506,0.000112352141742741,1.47727671728772E-5,0.25,-4.59038639516238E-7,9.93798996952685E-6,-3.9929588038868E-7,32.5031,32.5031,99.6700439453125,99.6700439453125,53.9816104236403,19.5796248991756,17.973541,0,0,0,40,4370,32.4989,99.6700439453125,,,,,,,,,,,,,0,,,,,,,,,,,,,,
,19677864.27,29.44545,99.6700439453125,1.00306775522318E-5,3.04504695979601E-7,1,0.999253354069792,40.0298881530762,1.98177373827657,14.2400003969669,0.000112655275035812,1.58152730531736E-5,0.25,-3.70020228710587E-7,9.98007020824273E-6,-3.13662309223494E-7,29.4503,29.4503,99.6700439453125,99.6700439453125,53.8776538305826,19.5760615392357,17.973541,0,0,0,40,4370,29.44545,99.6700439453125,,,,,,,,,,,,,0,,,,,,,,,,,,,,
,19677983.885,26.48115,99.6700439453125,9.81065365533804E-6,2.49549822064629E-7,1,0.999253354069792,40.0298881530762,1.98152355608459,14.2400003969669,0.000109532617915851,1.88892399153968E-5,0.25,-5.21201673730911E-8,9.75704073666312E-6,-1.17154793993072E-9,26.4854,26.4854,99.6700439453125,99.6700439453125,53.6400387607364,19.579843199782,17.214239,0,0,0,40,4370,26.48115,99.6700439453125,,,,,,,,,,,,,0,,,,,,,,,,,,,,
,19678105.535,23.44965,99.6700439453125,9.53710137786568E-6,2.56079898319709E-7,1,0.999253354069792,40.0298881530762,1.98156689298514,14.2400003969669,0.000107255137724226,1.39034345076856E-5,0.25,-4.48412070897384E-7,9.4853992412889E-6,-3.98457485513906E-7,23.4545,23.4545,99.6700439453125,99.6700439453125,53.4821497998518,19.5780073171031,16.834587,0,0,0,40,4370,23.44965,99.6700439453125,,,,,,,,,,,,,0,,,,,,,,,,,,,,
,19678225.71,20.4585,99.6700439453125,9.83906895858234E-6,2.52652565400981E-7,1,0.999253354069792,40.0298881530762,1.98133075471326,14.2400003969669,0.000110264020352103,1.63917941942032E-5,0.25,-2.77557413346855E-7,9.78393630025566E-6,-2.2815156980488E-7,20.4585,20.4585,99.6700439453125,99.6700439453125,54.0199102210826,19.5779625702399,16.075285,0,0,0,40,4370,20.4585,99.6700439453125,,,,,,,,,,,,,0,,,,,,,,,,,,,,
,19678345.15,17.4906,99.6700439453125,9.80956917578355E-6,2.5926086156516E-7,1,0.999253354069792,40.0298881530762,1.9815927321383,14.2400003969669,0.00010993059485128,1.64237186822245E-5,0.25,-2.69219715135847E-7,9.75433525054008E-6,-2.20383811876665E-7,17.4946,17.4946,99.6700439453125,99.6700439453125,54.190305238275,19.576055131685,15.695635,0,0,0,40,4370,17.4906,99.6700439453125,,,,,,,,,,,,,0,,,,,,,,,,,,,,
,19678467.22,14.45695,99.6700439453125,9.69894797524695E-6,2.56079520958265E-7,1,0.999253354069792,40.0298881530762,1.98164351849897,14.2400003969669,0.000109288239913681,1.28974075091618E-5,0.25,-5.6584358833216E-7,9.64589312061298E-6,-5.15813163737749E-7,14.4616,14.4616,99.6700439453125,99.6700439453125,54.7827796558519,19.5729832264788,14.556682,0,0,0,40,4370,14.45695,99.6700439453125,,,,,,,,,,,,,0,,,,,,,,,,,,,,
,19678585.98,11.4911,99.6700439453125,9.73743778073489E-6,2.99420031114509E-7,1,0.999253354069792,40.0298881530762,1.98164764458193,14.2400003969669,0.000108885749241885,1.76631169199255E-5,0.25,-1.45370856394327E-7,9.68220013071557E-6,-9.7573834987125E-8,11.4965,11.4965,99.6700439453125,99.6700439453125,54.241111092025,19.5738846029876,13.417728,0,0,0,40,4370,11.4911,99.6700439453125,,,,,,,,,,,,,0,,,,,,,,,,,,,,
,19678948.445,5.995,99.6700439453125,9.81340465330954E-6,2.56376636588114E-7,1,0.999253354069792,40.0298881530762,1.98131271255471,14.2400003969669,0.000109791760775076,1.73842007113463E-5,0.25,-1.83628670582906E-7,9.75798154122345E-6,-1.35246415416059E-7,5.995,5.995,99.6700439453125,99.6700439453125,54.1340279848903,19.5791909018749,9.621219,0,0,0,40,4370,5.995,99.6700439453125,,,,,,,,,,,,,0,,,,,,,,,,,,,,
,19679415.28,5.0219,99.6700439453125,9.66608915652153E-6,2.31232192066236E-7,1,0.999253354069792,40.0298881530762,1.98164061562669,14.2400003969669,0.000108121709202744,1.73457837398438E-5,0.25,-1.61160695112469E-7,9.61140678439485E-6,-1.13617885841334E-7,5.0219,5.0219,99.6700439453125,99.6700439453125,54.3216188295057,19.573066111318,8.861917,0,0,0,40,4369,5.0219,99.6700439453125,,,,,,,,,,,,,0,,,,,,,,,,,,,,