File: data/doubleLayers/monolayer/ppms/DD205_4/ppms_cologne_data/DD205_4_KOELNPPMS_ZFCW_100OE.DAT
[Header]
; VSM Data File (default extension .dat)
; Copyright (c) 2003-2013, Quantum Design, Inc. All rights reserved.
TITLE,
FILEOPENTIME,19645386.45,08/16/2018,9:01 am
BYAPP,VSM,2.0,2.0
INFO,PPMS VSM Option Release 1.4.10 Build 1,APPNAME
INFO,Quantum Design Linear Motor Servo Controller,MOTOR_MODULE_NAME
INFO,3101-100 M1,MOTOR_HW_VERSION
INFO,MMC1014,MOTOR_SERIAL_NUMBER
INFO,SRV No X-over 01.03.11,MOTOR_SOFTWARE_VERSION
INFO,Quantum Design VSM Detection Module,VSM_MODULE_NAME
INFO,3101-150 F0,VSM_HW_VERSION
INFO,VSM707,VSM_SERIAL_NUMBER
INFO,VSM No X-over 01.02.05 May 20 2008 13:51:47,VSM_SOFTWARE_VERSION
INFO,704,PREAMP_SERIAL_NUMBER
INFO,822,COIL_SERIAL_NUMBER
INFO,0,MOMENT_UNITS
INFO,,SAMPLE_MATERIAL
INFO,,SAMPLE_COMMENT
INFO,,SAMPLE_MASS
INFO,,SAMPLE_VOLUME
INFO,,SAMPLE_MOLECULAR_WEIGHT
INFO,,SAMPLE_SIZE
INFO,,SAMPLE_SHAPE
DATATYPE,COMMENT,1
DATATYPE,TIME,2
STARTUPAXIS,X,2
STARTUPAXIS,Y1,5
[Data]
Comment,Time Stamp (sec),Temperature (K),Magnetic Field (Oe),Moment (emu),M. Std. Err. (emu),Transport Action,Averaging Time (sec),Frequency (Hz),Peak Amplitude (mm),Center Position (mm),Coil Signal' (mV),Coil Signal" (mV),Range (mV),M. Quad. Signal (emu),M. Raw' (emu),M. Raw" (emu),Min. Temperature (K),Max. Temperature (K),Min. Field (Oe),Max. Field (Oe),Mass (grams),Motor Lag (deg),Pressure (Torr),VSM Status (code),Motor Status (code),Measure Status (code),Measure Count,PPMS Status (code),System Temp. (K),System Field (Oe),Sample Position (deg),Bridge 1 Resistance (ohms),Bridge 1 Excitation (에),Bridge 2 Resistance (ohms),Bridge 2 Excitation (에),Bridge 3 Resistance (ohms),Bridge 3 Excitation (에),Bridge 4 Resistance (ohms),Bridge 4 Excitation (에),Signal 1 Vin (V),Signal 2 Vin (V),Digital Inputs (code),Drive 1 Iout (mA),Drive 1 Ipower (W),Drive 2 Iout (mA),Drive 2 Ipower (W),Pressure (),Map 20 (),Map 21 (),Map 22 (),Map 23 (),Map 24 (),Map 25 (),Map 26 (),Map 27 (),Map 28 (),Map 29 ()
,19650185.94,5.00965,99.6700439453125,9.35217266635719E-7,2.42633103882918E-7,1,0.999253354069792,40.0298881530762,1.98203104086374,14.2400003969669,1.10793377261679E-5,-1.79225660230643E-6,0.25,-3.2674424192671E-7,9.31427258140359E-7,-3.20359116171841E-7,5.0094,5.0094,99.6700439453125,99.6700439453125,53.435252088698,19.5747825554506,8.102614,0,0,0,40,4369,5.00965,99.6700439453125,,,,,,,,,,,,,0,,,,,,,,,,,,,,
,19650290.56,7.5082,99.6700439453125,7.17094647052194E-7,2.8539570650583E-7,1,0.999253354069792,40.0298881530762,1.98195643649942,14.2400003969669,8.54740348257106E-6,-1.66950589573995E-6,0.25,-2.77012146389884E-7,7.14315202298204E-7,-2.71963925662637E-7,7.5082,7.5082,99.6700439453125,99.6700439453125,53.5837615073518,19.5788486415193,8.102614,0,0,0,40,4370,7.5082,99.6700439453125,,,,,,,,,,,,,0,,,,,,,,,,,,,,
,19650409.15,10.53005,99.6700439453125,3.11760076412234E-7,1.99068024248214E-7,1,0.999253354069792,40.0298881530762,1.98208863087707,14.2400003969669,4.5326700304605E-6,-5.32348300508037E-6,0.25,-5.32589502837142E-7,3.12538234588813E-7,-5.2802729068483E-7,10.5243,10.5243,99.6700439453125,99.6700439453125,53.8893782583711,19.5772938580708,9.241568,0,0,0,40,4370,10.53005,99.6700439453125,,,,,,,,,,,,,0,,,,,,,,,,,,,,
,19650527.055,13.5005,99.6700439453125,4.09067941281586E-7,2.57905296624685E-7,1,0.999253354069792,40.0298881530762,1.98211820359889,14.2500000074506,4.78294347262765E-6,-4.27201952801682E-7,0.25,-1.10937272928254E-7,4.07251200808589E-7,-1.08326632221871E-7,13.5005,13.5005,99.6700439453125,99.6700439453125,53.7932379505057,19.5817846718359,10.38052,0,0,0,40,4374,13.5005,99.6700439453125,,,,,,,,,,,,,0,,,,,,,,,,,,,,
,19650645.615,16.52115,99.6700439453125,3.81085649107818E-7,2.51117557988396E-7,1,0.999253354069792,40.0298881530762,1.98253811841754,14.2400003969669,4.99662230706268E-6,-3.4389628874805E-6,0.25,-3.75898334456696E-7,3.80704387371084E-7,-3.71896188917628E-7,16.4966,16.4966,99.6700439453125,99.6700439453125,54.0965098159673,19.5781533803995,10.38052,0,0,0,40,4374,16.52115,99.6700439453125,,,,,,,,,,,,,0,,,,,,,,,,,,,,
,19650765.79,19.5283,99.6700439453125,3.69290941918286E-7,2.95780040678222E-7,1,0.999253354069792,40.0298881530762,1.98277761571173,14.2400003969669,4.58614622891266E-6,-1.8887390266377E-6,0.25,-2.34847523677122E-7,3.6830269213465E-7,-2.31709020611953E-7,19.5283,19.5283,99.6700439453125,99.6700439453125,54.0503937333326,19.5757980526407,11.139823,0,0,0,40,4374,19.5283,99.6700439453125,,,,,,,,,,,,,0,,,,,,,,,,,,,,
,19650886.88,22.5327,99.6700439453125,4.76786460108741E-7,2.42700707538932E-7,1,0.999253354069792,40.0298881530762,1.98274690427373,14.2400003969669,5.59223782130686E-6,-5.84312754722366E-7,0.25,-1.37081210285391E-7,4.74749993393026E-7,-1.33951120768008E-7,22.5327,22.5327,99.6700439453125,99.6700439453125,54.004277650698,19.5793475401519,11.139823,0,0,0,40,4370,22.5327,99.6700439453125,,,,,,,,,,,,,0,,,,,,,,,,,,,,
,19651004.56,25.54075,99.6700439453125,3.02771979301965E-7,3.01256548365008E-7,1,0.999253354069792,40.0298881530762,1.98255665528518,14.2400003969669,4.39934640806715E-6,-5.1377485811307E-6,0.25,-5.14257961610552E-7,3.03711794952496E-7,-5.09860012443632E-7,25.5345,25.5345,99.6700439453125,99.6700439453125,54.3724246832557,19.580533419217,11.899124,0,0,0,40,4374,25.54075,99.6700439453125,,,,,,,,,,,,,0,,,,,,,,,,,,,,
,19651121.76,28.5239,99.6700439453125,4.42235459326642E-7,2.8948729156747E-7,1,0.999253354069792,40.0298881530762,1.98260654083172,14.2400003969669,5.4068460125953E-6,-1.76466586582253E-6,0.25,-2.36869472600243E-7,4.41141397097471E-7,-2.3324639191289E-7,28.5195,28.5195,99.6700439453125,99.6700439453125,53.6814650722557,19.5799913702789,12.658426,0,0,0,40,4374,28.5239,99.6700439453125,,,,,,,,,,,,,0,,,,,,,,,,,,,,
,19651240.14,31.5083,99.6700439453125,3.49774550628717E-7,2.26972612077377E-7,1,0.999253354069792,40.0298881530762,1.9828349590593,14.2400003969669,4.61710427113294E-6,-3.29175297445506E-6,0.25,-3.5722024948023E-7,3.50036970867708E-7,-3.53454637139933E-7,31.5035,31.5035,99.6700439453125,99.6700439453125,54.0199102210826,19.576992936023,13.417728,0,0,0,40,4374,31.5083,99.6700439453125,,,,,,,,,,,,,0,,,,,,,,,,,,,,
,19651358.525,34.50125,99.6700439453125,8.95059635577165E-8,2.96283437340487E-7,1,0.999253354069792,40.0298881530762,1.98290756463887,14.2400003969669,1.58769508113606E-6,-3.1093596614145E-6,0.25,-2.94366449922583E-7,9.08634111065393E-8,-2.92480165313077E-7,34.4925,34.4925,99.6700439453125,99.6700439453125,54.1676380112173,19.5819354577501,13.797379,0,0,0,40,4374,34.50125,99.6700439453125,,,,,,,,,,,,,0,,,,,,,,,,,,,,
,19651478.37,37.53055,99.6700439453125,4.96923465598958E-7,2.43098382860977E-7,1,0.999253354069792,40.0298881530762,1.98309487079986,14.2400003969669,7.07451182437003E-6,-7.49004749322274E-6,0.25,-7.59191646343721E-7,4.99781319240331E-7,-7.52964270245214E-7,37.5268,37.5268,99.6700439453125,99.6700439453125,54.0402325625826,19.5798221200787,13.797379,0,0,0,40,4374,37.53055,99.6700439453125,,,,,,,,,,,,,0,,,,,,,,,,,,,,
,19651595.815,40.5015,99.6700439453125,3.15103292204094E-7,2.28085225057642E-7,1,0.999253354069792,40.0298881530762,1.98332328728959,14.2400003969669,3.7020090737668E-6,-3.56174572213979E-7,0.25,-8.84285969106542E-8,3.14649739165925E-7,-8.60020050824023E-8,40.5015,40.5015,99.6700439453125,99.6700439453125,54.0996363300442,19.5757553512404,14.556682,0,0,0,40,4374,40.5015,99.6700439453125,,,,,,,,,,,,,0,,,,,,,,,,,,,,
,19651713.865,43.5027,99.6700439453125,3.03255456932489E-7,2.27352378224416E-7,1,0.999253354069792,40.0298881530762,1.98357441474808,14.2400003969669,4.31751482893861E-6,-4.51807048689703E-6,0.25,-4.58148482152393E-7,3.0573294281641E-7,-4.54837753555668E-7,43.5027,43.5027,99.6700439453125,99.6700439453125,54.1379361274865,19.576185405734,14.556682,0,0,0,40,4374,43.5027,99.6700439453125,,,,,,,,,,,,,0,,,,,,,,,,,,,,
,19651832.16,46.52385,99.6700439453125,6.1570853428072E-7,3.35439593296754E-7,1,0.999253354069792,40.0298881530762,1.98363026063445,14.2400003969669,7.68261971032514E-6,-3.10890734197148E-6,0.25,-3.88379103781046E-7,6.17541185634452E-7,-3.83235912457004E-7,46.5192,46.5192,99.6700439453125,99.6700439453125,53.9519085399096,19.5720578047062,14.936333,0,0,0,40,4374,46.52385,99.6700439453125,,,,,,,,,,,,,0,,,,,,,,,,,,,,
,19651950.205,49.5415,99.6700439453125,4.46353004620785E-7,2.70052991305954E-7,1,0.999253354069792,40.0298881530762,1.98382265577545,14.2400003969669,5.68589386097967E-6,-2.86814593521768E-6,0.25,-3.36173257773678E-7,4.48539965680208E-7,-3.32621150218323E-7,49.5387,49.5387,99.6700439453125,99.6700439453125,54.1434075271211,19.5673673122932,15.315984,0,0,0,40,4374,49.5415,99.6700439453125,,,,,,,,,,,,,0,,,,,,,,,,,,,,
,19652066.305,52.5177,99.6700439453125,1.02600167608378E-7,2.74725092326591E-7,1,0.999253354069792,40.0298881530762,1.9838455096422,14.2400003969669,2.55217912136265E-6,-7.56237045783356E-6,0.25,-6.92106055845098E-7,1.0775808925417E-7,-6.91504562199848E-7,52.5145,52.5145,99.6700439453125,99.6700439453125,53.9988062510634,19.5742397322986,16.454937,0,0,0,40,4374,52.5177,99.6700439453125,,,,,,,,,,,,,0,,,,,,,,,,,,,,
,19652184.195,55.5326,99.6700439453125,2.71789569165946E-7,3.02625478337658E-7,1,0.999253354069792,40.0298881530762,1.98362493170185,14.2400003969669,3.49463813136964E-6,-1.89842650715054E-6,0.25,-2.17907603532112E-7,2.7368326667562E-7,-2.16173386180725E-7,55.5326,55.5326,99.6700439453125,99.6700439453125,54.0808772455826,19.5742869347826,16.454937,0,0,0,40,4374,55.5326,99.6700439453125,,,,,,,,,,,,,0,,,,,,,,,,,,,,
,19652302.45,58.5543,99.6700439453125,3.84709982950891E-7,2.25238803961294E-7,1,0.999253354069792,40.0298881530762,1.98359492148002,14.2400003969669,5.24351552479587E-6,-4.32330555489586E-6,0.25,-4.53641280260493E-7,3.88657790923687E-7,-4.51812194670345E-7,58.5543,58.5543,99.6700439453125,99.6700439453125,54.0675895607557,19.5758779165119,16.834587,0,0,0,40,4374,58.5543,99.6700439453125,,,,,,,,,,,,,0,,,,,,,,,,,,,,
,19652418.105,61.502,99.6700439453125,2.27264654394973E-7,2.62100943847775E-7,1,0.999253354069792,40.0298881530762,1.98355169918246,14.2400003969669,3.27426200458876E-6,-3.5334056741362E-6,0.25,-3.54782608123898E-7,2.30263866171425E-7,-3.54188991248468E-7,61.502,61.502,99.6700439453125,99.6700439453125,54.0910384163326,19.5749568813813,17.214239,0,0,0,40,4374,61.502,99.6700439453125,,,,,,,,,,,,,0,,,,,,,,,,,,,,
,19652535.655,64.51025,99.6700439453125,3.41849683295245E-7,2.81279256667015E-7,1,0.999253354069792,40.0298881530762,1.98352451664024,14.2400003969669,4.74383359971624E-6,-4.30182697014233E-6,0.25,-4.4325975110843E-7,3.45808295126627E-7,-4.42518929998904E-7,64.5059,64.5059,99.6700439453125,99.6700439453125,54.1004179585634,19.5736737148434,17.593889,0,0,0,40,4374,64.51025,99.6700439453125,,,,,,,,,,,,,0,,,,,,,,,,,,,,
,19652655.125,67.5552,99.6700439453125,4.07792251561266E-7,3.39486390966266E-7,1,0.999253354069792,40.0298881530762,1.9833855762501,14.2400003969669,5.35278914429634E-6,-3.42013063399426E-6,0.25,-3.76463398374717E-7,4.11612229032562E-7,-3.75429091860237E-7,67.5552,67.5552,99.6700439453125,99.6700439453125,54.2708129757557,19.5743607297482,18.353191,0,0,0,40,4374,67.5552,99.6700439453125,,,,,,,,,,,,,0,,,,,,,,,,,,,,
,19652770.565,70.5248,99.6700439453125,5.50298683413762E-7,2.76683712015562E-7,1,0.999253354069792,40.0298881530762,1.9832681101016,14.2400003969669,6.5673387786879E-6,-9.37270096801396E-7,0.25,-1.81328488762038E-7,5.53645663549948E-7,-1.78968885040121E-7,70.5248,70.5248,99.6700439453125,99.6700439453125,54.2262601501596,19.5786834769839,19.112494,0,0,0,40,4374,70.5248,99.6700439453125,,,,,,,,,,,,,0,,,,,,,,,,,,,,
,19652887.485,73.5079,99.6700439453125,3.49940182315948E-7,2.78065176683728E-7,1,0.999253354069792,40.0298881530762,1.98323858270888,14.2400003969669,4.52487524885418E-6,-2.54952383824559E-6,0.25,-2.88406370452973E-7,3.5306861265108E-7,-2.87857182398753E-7,73.5059,73.5059,99.6700439453125,99.6700439453125,54.251272262775,19.5806939127247,19.492144,0,0,0,40,4374,73.5079,99.6700439453125,,,,,,,,,,,,,0,,,,,,,,,,,,,,
,19653006.64,76.5421,99.6700439453125,6.28379948236067E-7,2.57852197811517E-7,1,0.999253354069792,40.0298881530762,1.98310979834201,14.2400003969669,7.87821682133299E-6,-3.19079726497073E-6,0.25,-3.9455181910606E-7,6.33381514450271E-7,-3.93328185266197E-7,76.5372,76.5372,99.6700439453125,99.6700439453125,54.1082342437557,19.5826480253795,19.112494,0,0,0,40,4374,76.5421,99.6700439453125,,,,,,,,,,,,,0,,,,,,,,,,,,,,
,19653125.395,79.5457,99.6700439453125,3.41490910943326E-7,2.56369734516295E-7,1,0.999253354069792,40.0298881530762,1.98297159349907,14.2400003969669,4.46600106563611E-6,-2.77599508681547E-6,0.25,-3.06637866934851E-7,3.44646154791675E-7,-3.06592994024361E-7,79.5412,79.5412,99.6700439453125,99.6700439453125,54.156695211948,19.5830047437426,19.492144,0,0,0,40,4374,79.5457,99.6700439453125,,,,,,,,,,,,,0,,,,,,,,,,,,,,
,19653243.71,82.54865,99.6700439453125,4.29144518309401E-7,2.68930686204951E-7,1,0.999253354069792,40.0298881530762,1.98294916751572,14.2400003969669,5.82811581668646E-6,-4.71014637045095E-6,0.25,-4.93415872546871E-7,4.33543402990162E-7,-4.94114481341543E-7,82.5445,82.5445,99.6700439453125,99.6700439453125,53.8534233464865,19.5831255851247,19.492144,0,0,0,40,4374,82.54865,99.6700439453125,,,,,,,,,,,,,0,,,,,,,,,,,,,,
,19653363.395,85.56125,99.6700439453125,6.04209365551637E-7,2.47652003755501E-7,1,0.999253354069792,40.0298881530762,1.98296620379318,14.2400003969669,7.98563006624724E-6,-5.39386435494684E-6,0.25,-5.84751286553989E-7,6.09844645085249E-7,-5.85400282681008E-7,85.5595,85.5595,99.6700439453125,99.6700439453125,54.105889358198,19.5840673483287,20.251448,0,0,0,40,4374,85.56125,99.6700439453125,,,,,,,,,,,,,0,,,,,,,,,,,,,,
,19653482.065,88.558,99.6700439453125,-1.09026312843676E-7,2.15091224353504E-7,1,0.999253354069792,40.0298881530762,1.98277546465788,14.2400003969669,-5.86164175656744E-7,-3.86715796596967E-6,0.25,-3.23394662125273E-7,-1.08371770683915E-7,-3.255789101004E-7,88.5548,88.5548,99.6700439453125,99.6700439453125,54.119177043025,19.5866315703748,20.251448,0,0,0,40,4374,88.558,99.6700439453125,,,,,,,,,,,,,0,,,,,,,,,,,,,,
,19653598.96,91.5091,99.6700439453125,3.30929795480115E-7,2.97174686776332E-7,1,0.999253354069792,40.0298881530762,1.9827409089974,14.2400003969669,4.31167355686318E-6,-2.61040957049806E-6,0.25,-2.89614524407099E-7,3.33812805674612E-7,-2.90009053926807E-7,91.5053,91.5053,99.6700439453125,99.6700439453125,54.0355427914673,19.5859009323219,20.631098,0,0,0,40,4374,91.5091,99.6700439453125,,,,,,,,,,,,,0,,,,,,,,,,,,,,
,19653718.25,94.5395,99.6700439453125,4.18632067817902E-7,2.40136560333156E-7,1,0.999253354069792,40.0298881530762,1.9826702371025,14.2400003969669,5.83530284919339E-6,-5.4700422337857E-6,0.25,-5.58311461130872E-7,4.22885091324601E-7,-5.59986114125808E-7,94.5395,94.5395,99.6700439453125,99.6700439453125,54.1238668141403,19.5845799548914,20.631098,0,0,0,40,4374,94.5395,99.6700439453125,,,,,,,,,,,,,0,,,,,,,,,,,,,,
,19653835.37,97.5323,99.6700439453125,5.88772778493595E-7,2.47603336046468E-7,1,0.999253354069792,40.0298881530762,1.98272382089463,14.2400003969669,7.0234864156434E-6,-9.73090415600386E-7,0.25,-1.89768002631692E-7,5.92692358901924E-7,-1.88918367975772E-7,97.5286,97.5286,99.6700439453125,99.6700439453125,53.9659778532557,19.5864861501309,20.631098,0,0,0,40,4374,97.5323,99.6700439453125,,,,,,,,,,,,,0,,,,,,,,,,,,,,
,19653953.945,100.53745,99.6700439453125,4.63803383355281E-7,3.04935876743252E-7,1,0.999253354069792,40.0298881530762,1.9826899615543,14.2400003969669,6.48905677513593E-6,-6.21015081661874E-6,0.25,-6.31596302662224E-7,4.68359251224251E-7,-6.33721607805631E-7,100.5328,100.5328,99.6700439453125,99.6700439453125,54.4599670774096,19.5863772457619,20.631098,0,0,0,40,4374,100.53745,99.6700439453125,,,,,,,,,,,,,0,,,,,,,,,,,,,,
,19654071.145,103.5151,99.6700439453125,5.44105400726673E-7,2.93732362746646E-7,1,0.999253354069792,40.0298881530762,1.98262369941743,14.2500000074506,6.81376904395694E-6,-2.74431858197037E-6,0.25,-3.38621172096631E-7,5.48161086462927E-7,-3.38936094345056E-7,103.5151,103.5151,99.6700439453125,99.6700439453125,54.1121423863519,19.5842942191659,21.01075,0,0,0,40,4374,103.5151,99.6700439453125,,,,,,,,,,,,,0,,,,,,,,,,,,,,
,19654189.945,106.5126,99.6700439453125,3.35062671751308E-8,2.8100924080131E-7,1,0.999253354069792,40.0298881530762,1.98266512392034,14.2400003969669,7.48830363211602E-7,-2.04590157177788E-6,0.25,-1.87095489098009E-7,3.42157323924749E-8,-1.88054942495465E-7,106.5126,106.5126,99.6700439453125,99.6700439453125,54.1348096134096,19.5857678704641,21.3904,0,0,0,40,4374,106.5126,99.6700439453125,,,,,,,,,,,,,0,,,,,,,,,,,,,,
,19654309.61,109.52105,99.6700439453125,4.38248601751502E-7,2.83932148879534E-7,1,0.999253354069792,40.0298881530762,1.98263785251781,14.2400003969669,5.96481253782723E-6,-4.9350278689717E-6,0.25,-5.13949750674413E-7,4.4207157831292E-7,-5.15670988832967E-7,109.5169,109.5169,99.6700439453125,99.6700439453125,54.1989031519865,19.5843955206698,21.01075,0,0,0,40,4374,109.52105,99.6700439453125,,,,,,,,,,,,,0,,,,,,,,,,,,,,
,19654429.015,112.5225,99.6700439453125,6.45253910179595E-7,2.31379431400492E-7,1,0.999253354069792,40.0298881530762,1.98241660288309,14.2400003969669,7.57511748342946E-6,-3.86394975141414E-7,0.25,-1.47259755620387E-7,6.4923286441202E-7,-1.4644802026767E-7,112.5225,112.5225,99.6700439453125,99.6700439453125,54.1019812156019,19.588140691851,21.3904,0,0,0,40,4374,112.5225,99.6700439453125,,,,,,,,,,,,,0,,,,,,,,,,,,,,
,19654549.49,115.55385,99.6700439453125,7.46069667940336E-7,2.92235251898981E-7,1,0.999253354069792,40.0298881530762,1.98246927431382,14.2400003969669,9.1285798293312E-6,-2.56136200902806E-6,0.25,-3.57503211978642E-7,7.51081912262008E-7,-3.57683220797924E-7,115.5486,115.5486,99.6700439453125,99.6700439453125,54.0386693055442,19.5870541122096,21.3904,0,0,0,40,4374,115.55385,99.6700439453125,,,,,,,,,,,,,0,,,,,,,,,,,,,,
,19654668.695,118.5446,99.6700439453125,6.7310204407878E-7,2.70691048372503E-7,1,0.999253354069792,40.0298881530762,1.98245085576231,14.2400003969669,7.69079357336966E-6,7.99982444746395E-7,0.25,-4.68937269520601E-8,6.76927253121593E-7,-4.55907505502432E-8,118.5446,118.5446,99.6700439453125,99.6700439453125,54.0597732755634,19.5889495028274,21.770052,0,0,0,40,4374,118.5446,99.6700439453125,,,,,,,,,,,,,0,,,,,,,,,,,,,,
,19654787.705,121.53675,99.6700439453125,5.96408187281419E-7,3.39726880362449E-7,1,0.999253354069792,40.0298881530762,1.98244080221336,14.2400003969669,7.80501991735925E-6,-4.95799688753037E-6,0.25,-5.43515455108406E-7,6.00886423475917E-7,-5.45165653527438E-7,121.5331,121.5331,99.6700439453125,99.6700439453125,54.4458977640635,19.5911849530474,22.149702,0,0,0,40,4374,121.53675,99.6700439453125,,,,,,,,,,,,,0,,,,,,,,,,,,,,
,19654906.255,124.51685,99.6700439453125,3.41995222589957E-7,2.67208502087174E-7,1,0.999253354069792,40.0298881530762,1.98228065292316,14.2400003969669,4.46533052417589E-6,-2.78891950243811E-6,0.25,-3.0686736803832E-7,3.44510060992895E-7,-3.07802689961184E-7,124.5132,124.5132,99.6700439453125,99.6700439453125,54.0206918496019,19.5960381852684,21.770052,0,0,0,40,4374,124.51685,99.6700439453125,,,,,,,,,,,,,0,,,,,,,,,,,,,,
,19655026.09,127.52885,99.6700439453125,4.32071606885771E-7,2.73385754851928E-7,1,0.999253354069792,40.0298881530762,1.98236472882484,14.2400003969669,5.91425821503935E-6,-5.08767126242632E-6,0.25,-5.26240911662688E-7,4.35480533828756E-7,-5.28183429597694E-7,127.5251,127.5251,99.6700439453125,99.6700439453125,53.8831252302172,19.5923131130891,22.529354,0,0,0,40,4374,127.52885,99.6700439453125,,,,,,,,,,,,,0,,,,,,,,,,,,,,
,19655145.095,130.53295,99.6700439453125,4.38558236688662E-7,2.41576522481496E-7,1,0.999253354069792,40.0298881530762,1.98234793793458,14.2500000074506,5.34425668602826E-6,-1.39560546768253E-6,0.25,-2.00232242844107E-7,4.41291658283654E-7,-2.0042880573413E-7,130.5281,130.5281,99.6700439453125,99.6700439453125,53.892504772448,19.5925114506199,22.909004,0,0,0,40,4374,130.53295,99.6700439453125,,,,,,,,,,,,,0,,,,,,,,,,,,,,
,19655263.415,133.5095,99.6700439453125,4.73649945039218E-7,2.79003854803761E-7,1,0.999253354069792,40.0298881530762,1.98232030460215,14.2500000074506,5.93200417765547E-6,-2.42790660973459E-6,0.25,-2.97804357133934E-7,4.76715800404854E-7,-2.98466646640212E-7,133.5095,133.5095,99.6700439453125,99.6700439453125,54.109015872275,19.5897638529436,22.149702,0,0,0,40,4374,133.5095,99.6700439453125,,,,,,,,,,,,,0,,,,,,,,,,,,,,
,19655382.33,136.5084,99.6700439453125,4.77422337191779E-7,3.13715342174402E-7,1,0.999253354069792,40.0298881530762,1.98230973702718,14.2400003969669,5.84751207488673E-6,-1.69558669276337E-6,0.25,-2.33549188376795E-7,4.8034046171753E-7,-2.33882423122484E-7,136.5084,136.5084,99.6700439453125,99.6700439453125,54.0089674218134,19.5893166505134,22.149702,0,0,0,40,4374,136.5084,99.6700439453125,,,,,,,,,,,,,0,,,,,,,,,,,,,,
,19655502.115,139.5198,99.6700439453125,3.56608861277358E-7,3.32099840619799E-7,1,0.999253354069792,40.0298881530762,1.98227672467221,14.2400003969669,4.26192301178795E-6,-6.62197524397451E-7,0.25,-1.20879903694994E-7,3.58659009754176E-7,-1.20863815681491E-7,139.5198,139.5198,99.6700439453125,99.6700439453125,54.2794108894673,19.5916915345128,22.529354,0,0,0,40,4374,139.5198,99.6700439453125,,,,,,,,,,,,,0,,,,,,,,,,,,,,
,19655621.4,142.5239,99.6700439453125,1.67665130505434E-7,3.21012525102849E-7,1,0.999253354069792,40.0298881530762,1.98230183772662,14.2400003969669,2.45367158972909E-6,-2.89238266178055E-6,0.25,-2.8556700781301E-7,1.69010545433736E-7,-2.86726132563874E-7,142.5203,142.5203,99.6700439453125,99.6700439453125,53.9855185662365,19.5917477159331,22.909004,0,0,0,40,4374,142.5239,99.6700439453125,,,,,,,,,,,,,0,,,,,,,,,,,,,,
,19655742.15,145.55545,99.6700439453125,1.9977513782138E-7,2.95669677814E-7,1,0.999253354069792,40.0298881530762,1.98238625498897,14.2400003969669,2.98851515825817E-6,-3.82046861518886E-6,0.25,-3.73411863550629E-7,2.01401435834807E-7,-3.74945747235913E-7,145.5508,145.5508,99.6700439453125,99.6700439453125,53.9206433991403,19.589067211445,22.909004,0,0,0,40,4374,145.55545,99.6700439453125,,,,,,,,,,,,,0,,,,,,,,,,,,,,
,19655860.505,148.53765,99.6700439453125,4.20379745011165E-7,2.97903051887108E-7,1,0.999253354069792,40.0298881530762,1.98222347566189,14.2500000074506,5.46922521574031E-6,-3.34348755431195E-6,0.25,-3.6960999031931E-7,4.23055380609085E-7,-3.70749277790705E-7,148.5343,148.5343,99.6700439453125,99.6700439453125,54.2012480375442,19.5920016154696,23.288654,0,0,0,40,4374,148.53765,99.6700439453125,,,,,,,,,,,,,0,,,,,,,,,,,,,,
,19655979.51,151.5249,99.6700439453125,6.03312534474226E-7,3.17657999774666E-7,1,0.999253354069792,40.0298881530762,1.98243419895967,14.2400003969669,7.51382312686153E-6,-2.87358567948646E-6,0.25,-3.59795721842471E-7,6.06813369934464E-7,-3.60590578493938E-7,151.5205,151.5205,99.6700439453125,99.6700439453125,54.2528355198134,19.5862811707004,23.668306,0,0,0,40,4374,151.5249,99.6700439453125,,,,,,,,,,,,,0,,,,,,,,,,,,,,
,19656100.23,154.5533,99.6700439453125,4.78378358575391E-7,3.09831546750488E-7,1,0.999253354069792,40.0298881530762,1.98251751576468,14.2400003969669,6.06584825919061E-6,-2.90062245715079E-6,0.25,-3.40414405319528E-7,4.81189422386938E-7,-3.41307834642468E-7,154.5484,154.5484,99.6700439453125,99.6700439453125,54.5748664697366,19.5865634998201,23.288654,0,0,0,40,4374,154.5533,99.6700439453125,,,,,,,,,,,,,0,,,,,,,,,,,,,,
,19656217.985,157.502,99.6700439453125,3.66813587003728E-7,2.52662912982078E-7,1,0.999253354069792,40.0298881530762,1.98244503445405,14.2400003969669,5.18472509777211E-6,-5.29187245815712E-6,0.25,-5.32973245195235E-7,3.69336810869487E-7,-5.34933337318287E-7,157.502,157.502,99.6700439453125,99.6700439453125,54.1097975007942,19.5866268600914,23.668306,0,0,0,40,4374,157.502,99.6700439453125,,,,,,,,,,,,,0,,,,,,,,,,,,,,
,19656338.595,160.5344,99.6700439453125,3.11784386892612E-7,2.33541112123166E-7,1,0.999253354069792,40.0298881530762,1.98238594499203,14.2400003969669,4.15742399029052E-6,-3.06815743944784E-6,0.25,-3.2628189836034E-7,3.13701478399121E-7,-3.27337617149129E-7,160.5301,160.5301,99.6700439453125,99.6700439453125,54.0433590766596,19.5884870924367,23.288654,0,0,0,40,4374,160.5344,99.6700439453125,,,,,,,,,,,,,0,,,,,,,,,,,,,,
,19656458.785,163.5368,99.6700439453125,3.75393390423765E-7,3.2653832172574E-7,1,0.999253354069792,40.0298881530762,1.98239646528528,14.2400003969669,4.67305444457001E-6,-1.78611291215494E-6,0.25,-2.23690201594378E-7,3.77416543887033E-7,-2.24174584330976E-7,163.5326,163.5326,99.6700439453125,99.6700439453125,54.0253816207173,19.5878925004514,23.288654,0,0,0,40,4374,163.5368,99.6700439453125,,,,,,,,,,,,,0,,,,,,,,,,,,,,
,19656577.97,166.5291,99.6700439453125,5.84558031375225E-7,3.56586047204131E-7,1,0.999253354069792,40.0298881530762,1.98234290513425,14.2400003969669,7.69252060444903E-6,-5.17549013894307E-6,0.25,-5.6062592243466E-7,5.87941336996187E-7,-5.62319262489029E-7,166.525,166.525,99.6700439453125,99.6700439453125,54.3012964880057,19.5904072827755,24.047956,0,0,0,40,4374,166.5291,99.6700439453125,,,,,,,,,,,,,0,,,,,,,,,,,,,,
,19656699.025,169.5608,99.6700439453125,7.19751780668671E-7,2.87597038726603E-7,1,0.999253354069792,40.0298881530762,1.98241703379076,14.2400003969669,8.74478655935307E-6,-2.19825930627631E-6,0.25,-3.20138263848476E-7,7.23333618434565E-7,-3.20568734795556E-7,169.5608,169.5608,99.6700439453125,99.6700439453125,54.3036413735634,19.5891108610244,24.047956,0,0,0,40,4374,169.5608,99.6700439453125,,,,,,,,,,,,,0,,,,,,,,,,,,,,
,19656816.925,172.5185,99.6700439453125,8.88825448629034E-7,2.67621704549759E-7,1,0.999253354069792,40.0298881530762,1.98240459420926,14.2400003969669,9.64080626237703E-6,3.9381438288459E-6,0.25,1.94652706775689E-7,8.9238393656748E-7,1.96658956843348E-7,172.5147,172.5147,99.6700439453125,99.6700439453125,54.2356396923903,19.5891693228152,23.668306,0,0,0,40,4374,172.5185,99.6700439453125,,,,,,,,,,,,,0,,,,,,,,,,,,,,
,19656936.73,175.52215,99.6700439453125,1.06238976184716E-6,2.65016504209645E-7,1,0.999253354069792,40.0298881530762,1.98246640733918,14.2400003969669,1.21829468710408E-5,9.108418632833E-7,0.25,-1.03966285986098E-7,1.06699072861979E-6,-1.03036222920152E-7,175.5185,175.5185,99.6700439453125,99.6700439453125,54.187178724198,19.5885683095625,24.427608,0,0,0,40,4374,175.52215,99.6700439453125,,,,,,,,,,,,,0,,,,,,,,,,,,,,
,19657056.445,178.5212,99.6700439453125,8.21644086178096E-7,3.33201877124995E-7,1,0.999253354069792,40.0298881530762,1.98244804848519,14.2400003969669,1.01443383541482E-5,-3.45443476978716E-6,0.25,-4.49248716749477E-7,8.25591573043065E-7,-4.50064295745145E-7,178.5166,178.5166,99.6700439453125,99.6700439453125,53.638475503698,19.5879507649834,24.047956,0,0,0,40,4374,178.5212,99.6700439453125,,,,,,,,,,,,,0,,,,,,,,,,,,,,
,19657175.505,181.50575,99.6700439453125,7.80482844968083E-7,3.63043347337569E-7,1,0.999253354069792,40.0298881530762,1.98228463654408,14.2400003969669,9.33130901599863E-6,-1.53733772722097E-6,0.25,-2.7205530398432E-7,7.83960960308623E-7,-2.721903297031E-7,181.5007,181.5007,99.6700439453125,99.6700439453125,54.3302167432173,19.5925189955575,24.427608,0,0,0,40,4374,181.50575,99.6700439453125,,,,,,,,,,,,,0,,,,,,,,,,,,,,
,19657296.18,184.5267,99.6700439453125,8.26540626994037E-7,2.30243165168708E-7,1,0.999253354069792,40.0298881530762,1.9825210856313,14.2500000074506,9.88129021694199E-6,-1.62340222444659E-6,0.25,-2.87670473500828E-7,8.30140331886497E-7,-2.87807217843913E-7,184.5222,184.5222,99.6700439453125,99.6700439453125,54.0222551066403,19.5875214422119,24.427608,0,0,0,40,4374,184.5267,99.6700439453125,,,,,,,,,,,,,0,,,,,,,,,,,,,,
,19657414.845,187.5064,99.6700439453125,9.35829980547414E-7,2.5234751756744E-7,1,0.999253354069792,40.0298881530762,1.98241505885863,14.2400003969669,1.19972808599062E-5,-6.50510874993668E-6,0.25,-7.39764413448786E-7,9.40300599132381E-7,-7.41504729542271E-7,187.5018,187.5018,99.6700439453125,99.6700439453125,54.1277749567365,19.5882516547067,24.047956,0,0,0,40,4374,187.5064,99.6700439453125,,,,,,,,,,,,,0,,,,,,,,,,,,,,
,19657535.165,190.5256,99.6700439453125,9.68732720119749E-7,3.00103179881791E-7,1,0.999253354069792,40.0298881530762,1.98240361874609,14.2400003969669,1.17909004949118E-5,-3.12619986589878E-6,0.25,-4.45710114014877E-7,9.72881681388102E-7,-4.46262734187074E-7,190.5256,190.5256,99.6700439453125,99.6700439453125,54.1934317523519,19.5860891557699,24.807261,0,0,0,40,4374,190.5256,99.6700439453125,,,,,,,,,,,,,0,,,,,,,,,,,,,,
,19657654.305,193.5153,99.6700439453125,7.92520199132195E-7,3.45239885602615E-7,1,0.999253354069792,40.0298881530762,1.98244984235062,14.2400003969669,9.76768042598963E-6,-3.2614394979775E-6,0.25,-4.27091413681111E-7,7.9590271903895E-7,-4.27755943465502E-7,193.5153,193.5153,99.6700439453125,99.6700439453125,53.9972429940249,19.5884150357979,24.807261,0,0,0,40,4374,193.5153,99.6700439453125,,,,,,,,,,,,,0,,,,,,,,,,,,,,
,19657773.955,196.5216,99.6700439453125,1.24038135149734E-6,2.81839230788195E-7,1,0.999253354069792,40.0298881530762,1.98252326244985,14.2400003969669,1.43868127891355E-5,7.43733219528253E-8,0.25,-2.08875032756631E-7,1.24503235708023E-6,-2.08241600691502E-7,196.5158,196.5158,99.6700439453125,99.6700439453125,53.9034475717172,19.586043649149,24.427608,0,0,0,40,4374,196.5216,99.6700439453125,,,,,,,,,,,,,0,,,,,,,,,,,,,,
,19657892.995,199.5081,99.6700439453125,8.28359398681217E-7,2.73542948902616E-7,1,0.999253354069792,40.0298881530762,1.98263975440391,14.2400003969669,1.14274783851266E-5,-1.04284176205352E-5,0.25,-1.069318383643E-6,8.32396725891948E-7,-1.07212345895194E-6,199.5081,199.5081,99.6700439453125,99.6700439453125,53.9605064536211,19.5847452765693,25.186911,0,0,0,40,4374,199.5081,99.6700439453125,,,,,,,,,,,,,0,,,,,,,,,,,,,,
,19658012.265,202.5067,99.6700439453125,8.03018791908392E-7,2.60709330793143E-7,1,0.999253354069792,40.0298881530762,1.98262785010822,14.2400003969669,9.31861888683896E-6,1.34799282924285E-8,0.25,-1.38267503039215E-7,8.05873423079336E-7,-1.37874853134717E-7,202.5067,202.5067,99.6700439453125,99.6700439453125,54.329435114698,19.5826682649277,24.427608,0,0,0,40,4374,202.5067,99.6700439453125,,,,,,,,,,,,,0,,,,,,,,,,,,,,
,19658132.43,205.52405,99.6700439453125,1.19997134906269E-6,3.25068327940583E-7,1,0.999253354069792,40.0298881530762,1.9825371309835,14.2400003969669,1.42153470114746E-5,-1.66316876677329E-6,0.25,-3.56007836131173E-7,1.20427226704598E-6,-3.55913274782291E-7,205.5194,205.5194,99.6700439453125,99.6700439453125,54.1129240148711,19.5824216737211,25.186911,0,0,0,40,4374,205.52405,99.6700439453125,,,,,,,,,,,,,0,,,,,,,,,,,,,,
,19658251.49,208.5085,99.6700439453125,1.3736213928527E-6,3.84848845979046E-7,1,0.999253354069792,40.0298881530762,1.9825628993671,14.2400003969669,1.57946928096715E-5,8.39487934065957E-7,0.25,-1.63987904698713E-7,1.378151754019E-6,-1.63092226986706E-7,208.5002,208.5002,99.6700439453125,99.6700439453125,54.2262601501596,19.5818733666465,24.807261,0,0,0,40,4374,208.5085,99.6700439453125,,,,,,,,,,,,,0,,,,,,,,,,,,,,
,19658372.635,211.54775,99.6700439453125,1.27811234708767E-6,2.21962945736204E-7,1,0.999253354069792,40.0298881530762,1.98257634765433,14.2400003969669,1.46194750396609E-5,1.21644794285411E-6,0.25,-1.13907746873038E-7,1.28215757370802E-6,-1.12963520242766E-7,211.5437,211.5437,99.6700439453125,99.6700439453125,54.0730609603903,19.5846823505738,25.186911,0,0,0,40,4374,211.54775,99.6700439453125,,,,,,,,,,,,,0,,,,,,,,,,,,,,
,19658491.875,214.5344,99.6700439453125,1.6194852060541E-6,3.2489519520092E-7,1,0.999253354069792,40.0298881530762,1.98270827391945,14.2400003969669,1.90861481101831E-5,-1.69962844125119E-6,0.25,-4.32035576572898E-7,1.62473402100094E-6,-4.31708985483909E-7,214.5344,214.5344,99.6700439453125,99.6700439453125,54.0331979059096,19.5842163120412,25.566563,0,0,0,40,4374,214.5344,99.6700439453125,,,,,,,,,,,,,0,,,,,,,,,,,,,,
,19658611.03,217.5294,99.6700439453125,1.89250573711783E-6,2.82458746634897E-7,1,0.999253354069792,40.0298881530762,1.9827099111472,14.2400003969669,2.17251960093083E-5,1.33395349599895E-6,0.25,-2.10063546844321E-7,1.89815278307127E-6,-2.0881544737226E-7,217.5252,217.5252,99.6700439453125,99.6700439453125,54.105889358198,19.5825815313692,25.186911,0,0,0,40,4374,217.5294,99.6700439453125,,,,,,,,,,,,,0,,,,,,,,,,,,,,
,19658731.03,220.5376,99.6700439453125,1.55810713284943E-6,2.72752107190438E-7,1,0.999253354069792,40.0298881530762,1.98297056564238,14.2400003969669,1.79716469551336E-5,6.09675006671797E-7,0.25,-2.16301885237007E-7,1.56263743923471E-6,-2.154024724273E-7,220.5339,220.5339,99.6700439453125,99.6700439453125,54.0730609603903,19.5795605290269,25.186911,0,0,0,40,4374,220.5376,99.6700439453125,,,,,,,,,,,,,0,,,,,,,,,,,,,,
,19658850.805,223.542,99.6700439453125,1.9437754143844E-6,3.52586473629528E-7,1,0.999253354069792,40.0298881530762,1.98297960141536,14.2400003969669,2.28531002599665E-5,-1.74756311677424E-6,0.25,-4.92516103093268E-7,1.94943577265301E-6,-4.91992237900728E-7,223.5378,223.5378,99.6700439453125,99.6700439453125,54.1426258986019,19.5781771783227,24.807261,0,0,0,40,4374,223.542,99.6700439453125,,,,,,,,,,,,,0,,,,,,,,,,,,,,
,19658970.29,226.5397,99.6700439453125,2.04333162494251E-6,3.21815740136984E-7,1,0.999253354069792,40.0298881530762,1.98302178388909,14.2400003969669,2.28863307792742E-5,4.70480546379906E-6,0.25,6.32116331921583E-8,2.04852424487034E-6,6.52772187936852E-8,226.535,226.535,99.6700439453125,99.6700439453125,54.1223035571019,19.5781092801181,25.186911,0,0,0,40,4374,226.5397,99.6700439453125,,,,,,,,,,,,,0,,,,,,,,,,,,,,
,19659090.3,229.5442,99.6700439453125,2.43212010431054E-6,2.79214589458293E-7,1,0.999253354069792,40.0298881530762,1.98295671001712,14.2400003969669,2.78360205306366E-5,2.1488774457869E-6,0.25,-2.31167139009104E-7,2.43833242057933E-6,-2.29508138572131E-7,229.5442,229.5442,99.6700439453125,99.6700439453125,54.1004179585634,19.578034042,25.186911,0,0,0,40,4374,229.5442,99.6700439453125,,,,,,,,,,,,,0,,,,,,,,,,,,,,
,19659209.695,232.53855,99.6700439453125,2.62742594228506E-6,2.9808168502268E-7,1,0.999253354069792,40.0298881530762,1.98318805438134,14.2400003969669,3.00853402459267E-5,2.24195674920286E-6,0.25,-2.56753490289226E-7,2.63386908878073E-6,-2.54989617174128E-7,232.5341,232.5341,99.6700439453125,99.6700439453125,54.2114092082942,19.5819131911885,25.566563,0,0,0,40,4374,232.53855,99.6700439453125,,,,,,,,,,,,,0,,,,,,,,,,,,,,
,19659328.34,235.51775,99.6700439453125,2.33077391669736E-6,3.06408927233917E-7,1,0.999253354069792,40.0298881530762,1.98312493976192,14.2400003969669,2.65343391521602E-5,2.85660277715776E-6,0.25,-1.50628582939766E-7,2.33617778803065E-6,-1.48898091477619E-7,235.5144,235.5144,99.6700439453125,99.6700439453125,54.1340279848903,19.5796849296968,25.566563,0,0,0,40,4374,235.51775,99.6700439453125,,,,,,,,,,,,,0,,,,,,,,,,,,,,
,19659449.1,238.5502,99.6700439453125,2.79154282678617E-6,3.11231946039719E-7,1,0.999253354069792,40.0298881530762,1.98315289016759,14.2400003969669,3.20400103795902E-5,1.90461228975235E-6,0.25,-3.15073754606134E-7,2.7978363477001E-6,-3.13310468336631E-7,238.5502,238.5502,99.6700439453125,99.6700439453125,54.1840522101211,19.5808452805378,25.566563,0,0,0,40,4374,238.5502,99.6700439453125,,,,,,,,,,,,,0,,,,,,,,,,,,,,
,19659568.215,241.54405,99.6700439453125,2.97423629701509E-6,3.3286004509544E-7,1,0.999253354069792,40.0298881530762,1.98302433540802,14.2400003969669,3.492286601441E-5,-2.53521248904971E-6,0.25,-7.41165569203412E-7,2.98097628009504E-6,-7.40122423110731E-7,241.5402,241.5402,99.6700439453125,99.6700439453125,54.0628997896403,19.5790463354294,25.566563,0,0,0,40,4374,241.54405,99.6700439453125,,,,,,,,,,,,,0,,,,,,,,,,,,,,
,19659687.18,244.5273,99.6700439453125,2.76854137466054E-6,3.14815033190527E-7,1,0.999253354069792,40.0298881530762,1.98311095035069,14.2400003969669,3.19545501882383E-5,8.16731912623726E-7,0.25,-4.07633999336643E-7,2.77427768891219E-6,-4.06076408337614E-7,244.5273,244.5273,99.6700439453125,99.6700439453125,54.0605549040826,19.5798743849115,25.946213,0,0,0,40,4374,244.5273,99.6700439453125,,,,,,,,,,,,,0,,,,,,,,,,,,,,
,19659805.975,247.50235,99.6700439453125,3.53616968436138E-6,2.84673540900932E-7,1,0.999253354069792,40.0298881530762,1.98303022074168,14.2400003969669,4.04748384904474E-5,2.96749704182197E-6,0.25,-3.4959632088989E-7,3.54297744472152E-6,-3.47280682000149E-7,247.4973,247.4973,99.6700439453125,99.6700439453125,54.0355427914673,19.5789694045275,25.566563,0,0,0,40,4374,247.50235,99.6700439453125,,,,,,,,,,,,,0,,,,,,,,,,,,,,
,19659926.99,250.53785,99.6700439453125,3.55153403519165E-6,3.51022975040725E-7,1,0.999253354069792,40.0298881530762,1.9831253862423,14.2400003969669,3.95548556816682E-5,9.28448106107683E-6,0.25,2.09191391146562E-7,3.55752512882268E-6,2.12483767359873E-7,250.5347,250.5347,99.6700439453125,99.6700439453125,54.2395478349865,19.5772750207267,25.566563,0,0,0,40,4374,250.53785,99.6700439453125,,,,,,,,,,,,,0,,,,,,,,,,,,,,
,19660045.835,253.51165,99.6700439453125,3.82145166142162E-6,3.74949111250724E-7,1,0.999253354069792,40.0298881530762,1.98325476901634,14.2400003969669,4.32548203404223E-5,5.9786379095032E-6,0.25,-1.31343639838153E-7,3.82778901237759E-6,-1.28450250917193E-7,253.508,253.508,99.6700439453125,99.6700439453125,54.119177043025,19.5787200377555,25.946213,0,0,0,40,4374,253.51165,99.6700439453125,,,,,,,,,,,,,0,,,,,,,,,,,,,,
,19660165.975,256.5276,99.6700439453125,3.75579335103544E-6,3.48697812394754E-7,1,0.999253354069792,40.0298881530762,1.98312934193054,14.2400003969669,4.30550502841617E-5,2.70002485543298E-6,0.25,-4.11257392763866E-7,3.76184529343938E-6,-4.08872975997988E-7,256.5276,256.5276,99.6700439453125,99.6700439453125,54.0628997896403,19.5780075095031,26.325863,0,0,0,40,4374,256.5276,99.6700439453125,,,,,,,,,,,,,0,,,,,,,,,,,,,,
,19660285.89,259.53605,99.6700439453125,4.26217323640701E-6,3.22411679176255E-7,1,0.999253354069792,40.0298881530762,1.98298597341554,14.2400003969669,4.89830437507697E-5,2.30405307638583E-6,0.25,-5.3417747912473E-7,4.2686339924557E-6,-5.31564915560611E-7,259.5322,259.5322,99.6700439453125,99.6700439453125,54.1152689004288,19.5780678294976,25.946213,0,0,0,40,4374,259.53605,99.6700439453125,,,,,,,,,,,,,0,,,,,,,,,,,,,,
,19660405.14,262.5276,99.6700439453125,4.45512212158388E-6,4.22050592397636E-7,1,0.999253354069792,40.0298881530762,1.98298079888624,14.2400003969669,5.05805282190588E-5,5.95144973250146E-6,0.25,-2.43258453004311E-7,4.46114945226847E-6,-2.40103543869185E-7,262.5276,262.5276,99.6700439453125,99.6700439453125,54.302078116525,19.5800731920194,25.566563,0,0,0,40,4374,262.5276,99.6700439453125,,,,,,,,,,,,,0,,,,,,,,,,,,,,
,19660525.25,265.5234,99.6700439453125,4.95134598959331E-6,2.93458983915451E-7,1,0.999253354069792,40.0298881530762,1.98293011255551,14.2400003969669,5.58514881201221E-5,8.66367583229881E-6,0.25,-8.79862435196871E-8,4.95737287012166E-6,-8.42839485900339E-8,265.5192,265.5192,99.6700439453125,99.6700439453125,54.3599186269481,19.5801389637954,26.325863,0,0,0,40,4374,265.5234,99.6700439453125,,,,,,,,,,,,,0,,,,,,,,,,,,,,
,19660645.08,268.52785,99.6700439453125,5.27165159222468E-6,3.71275258631837E-7,1,0.999253354069792,40.0298881530762,1.98281763649209,14.2400003969669,6.0024869081147E-5,5.93511975638353E-6,0.25,-3.86014222417131E-7,5.27772385879598E-6,-3.82437431864759E-7,268.5216,268.5216,99.6700439453125,99.6700439453125,54.159821726025,19.581115865352,26.325863,0,0,0,40,4374,268.52785,99.6700439453125,,,,,,,,,,,,,0,,,,,,,,,,,,,,
,19660764.96,271.5288,99.6700439453125,5.33150298298539E-6,3.44965291583295E-7,1,0.999253354069792,40.0298881530762,1.98293850871581,14.2400003969669,6.04787947106486E-5,7.29758171823025E-6,0.25,-2.75127954191182E-7,5.33698214498225E-6,-2.71408470045739E-7,271.5288,271.5288,99.6700439453125,99.6700439453125,53.9495636543519,19.57695616881,26.325863,0,0,0,40,4374,271.5288,99.6700439453125,,,,,,,,,,,,,0,,,,,,,,,,,,,,
,19660885.155,274.5395,99.6700439453125,6.35615171787985E-6,3.89688987238667E-7,1,0.999253354069792,40.0298881530762,1.98286718006771,14.2400003969669,7.1450826140563E-5,1.23966738275611E-5,0.25,1.00207835135598E-9,6.36175300469685E-6,5.69889426308391E-9,274.5395,274.5395,99.6700439453125,99.6700439453125,53.9159536280249,19.5787164792871,25.946213,0,0,0,40,4374,274.5395,99.6700439453125,,,,,,,,,,,,,0,,,,,,,,,,,,,,
,19661004.26,277.5269,99.6700439453125,6.53940964904264E-6,3.28324059027654E-7,1,0.999253354069792,40.0298881530762,1.98312201179596,14.2400003969669,7.41055859036095E-5,9.32984241432982E-6,0.25,-3.03526939270971E-7,6.54469514491501E-6,-2.9899327043697E-7,277.5269,277.5269,99.6700439453125,99.6700439453125,54.0863486452173,19.576209396584,26.325863,0,0,0,40,4374,277.5269,99.6700439453125,,,,,,,,,,,,,0,,,,,,,,,,,,,,
,19661124.265,280.5417,99.6700439453125,6.37586410154017E-6,4.45426166525315E-7,1,0.999253354069792,40.0298881530762,1.98314334526166,14.2400003969669,7.1748766690388E-5,1.19597875561307E-5,0.25,-4.10712627634236E-8,6.38014269293294E-6,-3.65093217768781E-8,280.5417,280.5417,99.6700439453125,99.6700439453125,54.1137056433903,19.5773463754203,25.946213,0,0,0,40,4374,280.5417,99.6700439453125,,,,,,,,,,,,,0,,,,,,,,,,,,,,
,19661242.885,283.51885,99.6700439453125,6.66147985247794E-6,4.57238677684946E-7,1,0.999253354069792,40.0298881530762,1.9828338523252,14.2400003969669,7.56427782280383E-5,8.45852495088284E-6,0.25,-4.01803044582075E-7,6.66549429054794E-6,-3.97293669759321E-7,283.5147,283.5147,99.6700439453125,99.6700439453125,54.146534041198,19.5798121468112,26.325863,0,0,0,40,4374,283.51885,99.6700439453125,,,,,,,,,,,,,0,,,,,,,,,,,,,,
,19661361.67,286.5015,99.6700439453125,6.84063510887143E-6,3.13130594409597E-7,1,0.999253354069792,40.0298881530762,1.98290440556179,14.2400003969669,7.80158041379035E-5,6.69823306655792E-6,0.25,-5.89388054609248E-7,6.84414697463927E-6,-5.84854283441893E-7,286.4967,286.4967,99.6700439453125,99.6700439453125,54.1715461538134,19.5793868212977,26.325863,0,0,0,40,4374,286.5015,99.6700439453125,,,,,,,,,,,,,0,,,,,,,,,,,,,,
,19661482.3,289.5271,99.6700439453125,6.99824743873935E-6,3.22791665880059E-7,1,0.999253354069792,40.0298881530762,1.98286212652301,14.2400003969669,8.0227150684284E-5,4.40406986363934E-6,0.25,-8.20751265537319E-7,7.00122749784253E-6,-8.16184455346425E-7,289.5271,289.5271,99.6700439453125,99.6700439453125,53.9542534254672,19.5796422003213,27.085165,0,0,0,40,4374,289.5271,99.6700439453125,,,,,,,,,,,,,0,,,,,,,,,,,,,,
,19661601.325,292.5197,99.6700439453125,7.72771145582403E-6,3.82471056911064E-7,1,0.999253354069792,40.0298881530762,1.98289869214023,14.2400003969669,8.72251059692336E-5,1.26911474429136E-5,0.25,-2.09416941282182E-7,7.72968964105159E-6,-2.04177380815405E-7,292.5145,292.5145,99.6700439453125,99.6700439453125,54.2129724653327,19.578675965892,26.325863,0,0,0,40,4374,292.5197,99.6700439453125,,,,,,,,,,,,,0,,,,,,,,,,,,,,
,19661720.19,295.5294,99.6700439453125,7.4254210529991E-6,3.82859608766666E-7,1,0.999253354069792,40.0298881530762,1.983148147519,14.2400003969669,8.27633509112539E-5,1.82589255949813E-5,0.25,3.3859894115652E-7,7.42615586917479E-6,3.43663159546752E-7,295.5294,295.5294,99.6700439453125,99.6700439453125,54.2543987768519,19.5741387688548,26.705515,0,0,0,40,4374,295.5294,99.6700439453125,,,,,,,,,,,,,0,,,,,,,,,,,,,,
,19661838.46,298.51185,99.6700439453125,7.30422965665701E-6,3.52634557186587E-7,1,0.999253354069792,40.0298881530762,1.98275528453799,14.2400003969669,8.32660104331022E-5,7.11957299529087E-6,0.25,-6.31666689292694E-7,7.30482125445449E-6,-6.26802128424704E-7,298.5057,298.5057,99.6700439453125,99.6700439453125,54.2254785216404,19.5761938824795,26.705515,0,0,0,40,4374,298.51185,99.6700439453125,,,,,,,,,,,,,0,,,,,,,,,,,,,,
,19661958.125,301.5218,99.6700439453125,7.61822434610823E-6,4.4214036847669E-7,1,0.999253354069792,40.0298881530762,1.98286035421591,14.2400003969669,8.60407983800361E-5,1.20406992471151E-5,0.25,-2.47791922471639E-7,7.61774656573052E-6,-2.42742804600812E-7,301.5176,301.5176,99.6700439453125,99.6700439453125,54.3231820865442,19.5739571281033,26.325863,0,0,0,40,4374,301.5218,99.6700439453125,,,,,,,,,,,,,0,,,,,,,,,,,,,,
,19662077.085,304.5092,99.6700439453125,7.78867020815837E-6,3.84319260415752E-7,1,0.999253354069792,40.0298881530762,1.98280503084195,14.2400003969669,8.80123623916481E-5,1.19721328832784E-5,0.25,-2.83226129718255E-7,7.78737024105618E-6,-2.78091504109228E-7,304.5092,304.5092,99.6700439453125,99.6700439453125,54.2426743490634,19.5749825624605,27.085165,0,0,0,40,4374,304.5092,99.6700439453125,,,,,,,,,,,,,0,,,,,,,,,,,,,,
,19662197.165,307.53905,99.6700439453125,7.53101966588658E-6,2.46083130464243E-7,1,0.999253354069792,40.0298881530762,1.98264501575718,14.2400003969669,8.57842137347766E-5,7.53869066020022E-6,0.25,-6.33216563784904E-7,7.5291807258495E-6,-6.28172557643685E-7,307.5346,307.5346,99.6700439453125,99.6700439453125,54.159821726025,19.578296037953,26.705515,0,0,0,40,4374,307.53905,99.6700439453125,,,,,,,,,,,,,0,,,,,,,,,,,,,,
,19662315.575,310.52825,99.6700439453125,7.90063078138285E-6,3.88425046830915E-7,1,0.999253354069792,40.0298881530762,1.98269619251116,14.2400003969669,9.05965894123306E-5,4.3890584498263E-6,0.25,-9.77692486671366E-7,7.89805819630432E-6,-9.72261707145174E-7,310.5242,310.5242,99.6700439453125,99.6700439453125,54.0910384163326,19.5777664006263,26.705515,0,0,0,40,4374,310.52825,99.6700439453125,,,,,,,,,,,,,0,,,,,,,,,,,,,,
,19662434.97,313.54615,99.6700439453125,7.68894279144778E-6,3.85979896555735E-7,1,0.999253354069792,40.0298881530762,1.98265573310657,14.2400003969669,8.63881478484825E-5,1.44875668149833E-5,0.25,-4.12660484121081E-8,7.68503697670528E-6,-3.64001062728585E-8,313.5427,313.5427,99.6700439453125,99.6700439453125,54.2473641201788,19.5781182428168,27.085165,0,0,0,40,4374,313.54615,99.6700439453125,,,,,,,,,,,,,0,,,,,,,,,,,,,,
,19662552.61,316.5126,99.6700439453125,8.09157120919123E-6,4.22040078565918E-7,1,0.999253354069792,40.0298881530762,1.98283031722306,14.2400003969669,9.13989987552632E-5,1.24225342998842E-5,0.25,-2.94901265412683E-7,8.08676940165575E-6,-2.89677009024044E-7,316.5126,316.5126,99.6700439453125,99.6700439453125,54.2700313472365,19.5740866046875,27.085165,0,0,0,40,4374,316.5126,99.6700439453125,,,,,,,,,,,,,0,,,,,,,,,,,,,,
,19662672.305,319.53675,99.6700439453125,9.01970927730265E-6,3.72188705215418E-7,1,0.999253354069792,40.0298881530762,1.98285230725938,14.2400003969669,0.000101489075565208,1.60629165716843E-5,0.25,-1.31155101878982E-7,9.01327181975379E-6,-1.25501294973781E-7,319.5311,319.5311,99.6700439453125,99.6700439453125,54.230949921275,19.5742902361079,27.085165,0,0,0,40,4374,319.53675,99.6700439453125,,,,,,,,,,,,,0,,,,,,,,,,,,,,
,19662789.565,322.5012,99.6700439453125,7.92131175269324E-6,3.93919656688286E-7,1,0.999253354069792,40.0298881530762,1.98266706544807,14.2400003969669,8.98472464864141E-5,9.86342974331561E-6,0.25,-4.93036573867903E-7,7.91506322557797E-6,-4.87798748411803E-7,322.4972,322.4972,99.6700439453125,99.6700439453125,54.1254300711788,19.5782577151042,27.464817,0,0,0,40,4374,322.5012,99.6700439453125,,,,,,,,,,,,,0,,,,,,,,,,,,,,
,19662908.29,325.50505,99.6700439453125,8.40918523189004E-6,3.62836548914397E-7,1,0.999253354069792,40.0298881530762,1.98268596120262,14.2400003969669,9.61907039723755E-5,5.74138554684473E-6,0.25,-9.44769479032757E-7,8.40191853267333E-6,-9.38815583073361E-7,325.4991,325.4991,99.6700439453125,99.6700439453125,54.200466409025,19.5752591483999,27.464817,0,0,0,40,4374,325.50505,99.6700439453125,,,,,,,,,,,,,0,,,,,,,,,,,,,,
,19663026.985,328.5028,99.6700439453125,8.17405013672517E-6,2.94992385757908E-7,1,0.999253354069792,40.0298881530762,1.98281217359958,14.2400003969669,9.14105131834356E-5,1.76271514368883E-5,0.25,1.55371806851458E-7,8.16548515134652E-6,1.60091251307946E-7,328.5028,328.5028,99.6700439453125,99.6700439453125,54.1879603527173,19.5739385038752,27.085165,0,0,0,40,4374,328.5028,99.6700439453125,,,,,,,,,,,,,0,,,,,,,,,,,,,,
,19663146.485,331.51935,99.6700439453125,8.13062037950084E-6,4.22293505773915E-7,1,0.999253354069792,40.0298881530762,1.98288012496243,14.2400003969669,9.18828518523267E-5,1.19626901469144E-5,0.25,-3.41836200788891E-7,8.12154303329233E-6,-3.36641135097714E-7,331.5142,331.5142,99.6700439453125,99.6700439453125,54.2395478349865,19.5732915329442,27.464817,0,0,0,40,4374,331.51935,99.6700439453125,,,,,,,,,,,,,0,,,,,,,,,,,,,,
,19663265.125,334.5081,99.6700439453125,7.67493835708248E-6,3.12173948870228E-7,1,0.999253354069792,40.0298881530762,1.98290946448733,14.2400003969669,8.71371367405704E-5,8.91421719507423E-6,0.25,-5.34522726146208E-7,7.66569809112521E-6,-5.29366740498605E-7,334.5081,334.5081,99.6700439453125,99.6700439453125,54.1957766379096,19.5752439065866,27.464817,0,0,0,40,4374,334.5081,99.6700439453125,,,,,,,,,,,,,0,,,,,,,,,,,,,,
,19663386.055,337.5499,99.6700439453125,7.95524632129778E-6,4.20907560105958E-7,1,0.999253354069792,40.0298881530762,1.98284285589118,14.2400003969669,8.94802858046618E-5,1.40135145654309E-5,0.25,-1.28292310848362E-7,7.94458508032253E-6,-1.23510427754512E-7,337.5499,337.5499,99.6700439453125,99.6700439453125,54.0621181611211,19.5753214392687,27.085165,0,0,0,40,4374,337.5499,99.6700439453125,,,,,,,,,,,,,0,,,,,,,,,,,,,,
,19663504.015,340.5157,99.6700439453125,8.06129835867648E-6,4.97225066990605E-7,1,0.999253354069792,40.0298881530762,1.98265287291462,14.2400003969669,9.1271022685316E-5,1.06437710317308E-5,0.25,-4.4685417537265E-7,8.04985628914602E-6,-4.41579367214142E-7,340.5157,340.5157,99.6700439453125,99.6700439453125,54.1019812156019,19.576158588451,27.085165,0,0,0,40,4374,340.5157,99.6700439453125,,,,,,,,,,,,,0,,,,,,,,,,,,,,
,19663623.72,343.5177,99.6700439453125,7.79313719565201E-6,4.69043473943952E-7,1,0.999253354069792,40.0298881530762,1.982977651845,14.2400003969669,8.78994082292335E-5,1.22548124270854E-5,0.25,-2.56777367014435E-7,7.78117550746088E-6,-2.51947421763827E-7,343.5177,343.5177,99.6700439453125,99.6700439453125,54.0269448777557,19.5727757987694,27.464817,0,0,0,40,4374,343.5177,99.6700439453125,,,,,,,,,,,,,0,,,,,,,,,,,,,,
,19663743.3,346.5308,99.6700439453125,8.37566211703511E-6,4.9247350224895E-7,1,0.999253354069792,40.0298881530762,1.98359433350104,14.2400003969669,9.4703088089553E-5,1.19319528469144E-5,0.25,-3.86601243695871E-7,8.36201052883405E-6,-3.81241909350265E-7,346.5282,346.5282,99.6700439453125,99.6700439453125,54.2364213209096,19.5697864052317,27.464817,0,0,0,40,4374,346.5308,99.6700439453125,,,,,,,,,,,,,0,,,,,,,,,,,,,,
,19663863.12,349.5378,99.6700439453125,7.32400119004234E-6,4.33504094883831E-7,1,0.999253354069792,40.0298881530762,1.98330578474119,14.2400003969669,8.37107745672368E-5,5.12554766453169E-6,0.25,-8.11129742961014E-7,7.31158274533997E-6,-8.05613764036887E-7,349.5378,349.5378,99.6700439453125,99.6700439453125,54.129338213775,19.5669310394149,27.844467,0,0,0,40,4374,349.5378,99.6700439453125,,,,,,,,,,,,,0,,,,,,,,,,,,,,
,19664508.495,352.2477,99.6700439453125,7.22647366269129E-6,5.12829550982882E-7,1,0.999253354069792,40.0298881530762,1.98332289211922,14.2400003969669,7.98317459275992E-5,2.09821331728252E-5,0.25,6.19867037581661E-7,7.21277253912413E-6,6.22726359781454E-7,352.2472,352.2472,99.6700439453125,99.6700439453125,54.0308530203519,19.5695861039915,27.844467,0,0,0,40,4369,352.2477,99.6700439453125,,,,,,,,,,,,,0,,,,,,,,,,,,,,