File: data/doubleLayers/monolayer/ppms/DD205_4/ppms_cologne_data/DD205_4_KOELNPPMS_HYST_100OE_50K.DAT
[Header]
; VSM Data File (default extension .dat)
; Copyright (c) 2003-2013, Quantum Design, Inc. All rights reserved.
TITLE,
FILEOPENTIME,19708058.20,08/17/2018,2:26 am
BYAPP,VSM,2.0,2.0
INFO,PPMS VSM Option Release 1.4.10 Build 1,APPNAME
INFO,Quantum Design Linear Motor Servo Controller,MOTOR_MODULE_NAME
INFO,3101-100 M1,MOTOR_HW_VERSION
INFO,MMC1014,MOTOR_SERIAL_NUMBER
INFO,SRV No X-over 01.03.11,MOTOR_SOFTWARE_VERSION
INFO,Quantum Design VSM Detection Module,VSM_MODULE_NAME
INFO,3101-150 F0,VSM_HW_VERSION
INFO,VSM707,VSM_SERIAL_NUMBER
INFO,VSM No X-over 01.02.05 May 20 2008 13:51:47,VSM_SOFTWARE_VERSION
INFO,704,PREAMP_SERIAL_NUMBER
INFO,822,COIL_SERIAL_NUMBER
INFO,0,MOMENT_UNITS
INFO,,SAMPLE_MATERIAL
INFO,,SAMPLE_COMMENT
INFO,,SAMPLE_MASS
INFO,,SAMPLE_VOLUME
INFO,,SAMPLE_MOLECULAR_WEIGHT
INFO,,SAMPLE_SIZE
INFO,,SAMPLE_SHAPE
DATATYPE,COMMENT,1
DATATYPE,TIME,2
STARTUPAXIS,X,2
STARTUPAXIS,Y1,5
[Data]
Comment,Time Stamp (sec),Temperature (K),Magnetic Field (Oe),Moment (emu),M. Std. Err. (emu),Transport Action,Averaging Time (sec),Frequency (Hz),Peak Amplitude (mm),Center Position (mm),Coil Signal' (mV),Coil Signal" (mV),Range (mV),M. Quad. Signal (emu),M. Raw' (emu),M. Raw" (emu),Min. Temperature (K),Max. Temperature (K),Min. Field (Oe),Max. Field (Oe),Mass (grams),Motor Lag (deg),Pressure (Torr),VSM Status (code),Motor Status (code),Measure Status (code),Measure Count,PPMS Status (code),System Temp. (K),System Field (Oe),Sample Position (deg),Bridge 1 Resistance (ohms),Bridge 1 Excitation (에),Bridge 2 Resistance (ohms),Bridge 2 Excitation (에),Bridge 3 Resistance (ohms),Bridge 3 Excitation (에),Bridge 4 Resistance (ohms),Bridge 4 Excitation (에),Signal 1 Vin (V),Signal 2 Vin (V),Digital Inputs (code),Drive 1 Iout (mA),Drive 1 Ipower (W),Drive 2 Iout (mA),Drive 2 Ipower (W),Pressure (),Map 20 (),Map 21 (),Map 22 (),Map 23 (),Map 24 (),Map 25 (),Map 26 (),Map 27 (),Map 28 (),Map 29 ()
,19708108.005,50.2336,-0.50999641418457,3.6910287203308E-5,6.10726257363609E-7,1,0.999253354069792,40.0298881530762,1.99440593634281,14.2400003969669,0.000419072433873332,5.89844726284668E-5,0.25,-1.42195426893669E-6,3.69030692968835E-5,-1.14664996247058E-6,50.2353,50.2353,-0.62417471408844,-0.395818114280701,53.3523994656595,19.545287270914,17.593889,0,0,0,40,4417,50.2336,-0.50999641418457,,,,,,,,,,,,,0,,,,,,,,,,,,,,
,19708204.43,50.21635,3852.62097167969,2.99021413402454E-5,3.42283836404975E-7,1,0.999253354069792,40.0298881530762,1.99449022784658,14.2400003969669,0.000337115942961016,6.13756235801431E-5,0.25,5.23539893355271E-8,2.98914841876106E-5,2.74858681811749E-7,50.2152,50.2152,3847.36181640625,3857.88012695313,53.5712554510441,19.5523115914095,17.593889,0,0,0,40,4449,50.21635,3852.62097167969,,,,,,,,,,,,,0,,,,,,,,,,,,,,
,19708282.23,50.2079,7737.44653320312,1.68550400508753E-5,3.47652909120714E-7,1,0.999253354069792,40.0298881530762,1.99447718123316,14.2400003969669,0.000188050630605113,4.57313452751059E-5,0.25,1.01626118556372E-6,1.6844761905027E-5,1.14149518324159E-6,50.2073,50.2073,7732.4794921875,7742.41357421875,53.6126817625634,19.552504660644,18.353191,0,0,0,40,4449,50.2079,7737.44653320312,,,,,,,,,,,,,0,,,,,,,,,,,,,,
,19708360.445,50.21365,11648.154296875,3.44241402293145E-6,4.60536396947074E-7,1,0.999253354069792,40.0298881530762,1.99440890566591,14.2400003969669,3.70587543421556E-5,1.68570877952874E-5,0.25,8.73768737140463E-7,3.43606244858671E-6,8.99390353930339E-7,50.2153,50.2153,11640.623046875,11655.685546875,53.6330041040634,19.5541243684419,18.732843,0,0,0,40,4449,50.21365,11648.154296875,,,,,,,,,,,,,0,,,,,,,,,,,,,,
,19708442.32,50.22275,15738.5078125,-1.08478711004772E-5,4.6056009847892E-7,1,0.999253354069792,40.0298881530762,1.99439131743085,14.2400003969669,-0.00012419982761294,-1.21079303407995E-5,0.25,8.82012971417392E-7,-1.08572598947074E-5,8.01774412325717E-7,50.2222,50.2222,15733.662109375,15743.353515625,53.709603698948,19.5549016807678,17.973541,0,0,0,40,4449,50.22275,15738.5078125,,,,,,,,,,,,,0,,,,,,,,,,,,,,
,19708525.075,50.2255,19876.1318359375,-2.67777913299738E-5,4.94657480955325E-7,1,0.999253354069792,40.0298881530762,1.99430002646918,14.2400003969669,-0.000305840140198765,-3.43342286977444E-5,0.25,1.78314619655822E-6,-2.68040459541008E-5,1.58595310040842E-6,50.2255,50.2255,19866.47265625,19885.791015625,53.8557682320442,19.5597549669053,18.732843,0,0,0,40,4449,50.2255,19876.1318359375,,,,,,,,,,,,,0,,,,,,,,,,,,,,
,19708605,50.2235,23866.595703125,-4.19326993485805E-5,6.29829814908659E-7,1,0.999253354069792,40.0298881530762,1.99429405162973,14.2400003969669,-0.000476194169792816,-6.95290361798189E-5,0.25,1.39570237402957E-6,-4.19725565404173E-5,1.08767385508571E-6,50.2235,50.2235,23859.265625,23873.92578125,53.8245030912749,19.5587909983947,17.973541,0,0,0,40,4449,50.2235,23866.595703125,,,,,,,,,,,,,0,,,,,,,,,,,,,,
,19708686.045,50.214,27919.599609375,-5.80012682263684E-5,7.03276766919102E-7,1,0.999253354069792,40.0298881530762,1.99423602839493,14.2400003969669,-0.000657959071320366,-0.000100834125411624,0.25,1.5172051094089E-6,-5.80659431027011E-5,1.09314701897707E-6,50.214,50.214,27917.162109375,27922.037109375,53.8971945435634,19.5572496994989,18.353191,0,0,0,40,4449,50.214,27919.599609375,,,,,,,,,,,,,0,,,,,,,,,,,,,,
,19708766.96,50.2103,31965.11328125,-7.3341681393954E-5,6.97647336022184E-7,1,0.999253354069792,40.0298881530762,1.99429792224244,14.2400003969669,-0.000832393468027228,-0.000126361882429794,0.25,2.01922632561658E-6,-7.34400057462186E-5,1.48649934792671E-6,50.2103,50.2103,31960.037109375,31970.189453125,53.8674926598326,19.555287774784,18.353191,0,0,0,40,4449,50.2103,31965.11328125,,,,,,,,,,,,,0,,,,,,,,,,,,,,
,19708848.005,50.2083,36013.171875,-8.97686175347206E-5,8.13255514374101E-7,1,0.999253354069792,40.0298881530762,1.99418305215279,14.2400003969669,-0.00102095123377179,-0.000143801138435378,0.25,3.43106161040492E-6,-8.99149794002177E-5,2.78499988735439E-6,50.2083,50.2083,36008.15234375,36018.19140625,53.8174684346018,19.5581320793953,18.732843,0,0,0,40,4449,50.2083,36013.171875,,,,,,,,,,,,,0,,,,,,,,,,,,,,
,19708923.26,50.2036,39773.244140625,-0.000107367073462121,9.15235770819681E-7,1,0.999253354069792,40.0298881530762,1.99425584359978,14.2400003969669,-0.00122068907550498,-0.000175854460551166,0.25,3.76001444502507E-6,-0.000107560273614921,2.99269046292652E-6,50.2036,50.2036,39770.67578125,39775.8125,53.912827113948,19.5589647318772,18.732843,0,0,0,40,4449,50.2036,39773.244140625,,,,,,,,,,,,,0,,,,,,,,,,,,,,
,19708996.125,50.2021,43416.47265625,-0.000122225159315681,8.20200178008498E-7,1,0.999253354069792,40.0298881530762,1.99422497099106,14.2400003969669,-0.0013898878084663,-0.000199999319091968,0.25,4.29385846927275E-6,-0.000122467511178837,3.42734629735767E-6,50.2021,50.2021,43414,43418.9453125,53.7158567271018,19.5588927641128,18.732843,0,0,0,40,4449,50.2021,43416.47265625,,,,,,,,,,,,,0,,,,,,,,,,,,,,
,19709071.085,50.1968,47162.34375,-0.0001384766265927,8.79094701469996E-7,1,0.999253354069792,40.0298881530762,1.99434865348668,14.2500000074506,-0.00157127140157108,-0.000247770013494192,0.25,2.98804188794683E-6,-0.000138763131481718,2.0113304568916E-6,50.1968,50.1968,47157.53125,47167.15625,53.8948496580057,19.5575286088774,18.732843,0,0,0,40,4449,50.1968,47162.34375,,,,,,,,,,,,,0,,,,,,,,,,,,,,
,19709144.43,50.19355,50828.197265625,-0.000154627744509517,9.30907713318139E-7,1,0.999253354069792,40.0298881530762,1.99434489107623,14.2400003969669,-0.00175492929959714,-0.000276204904092398,0.25,3.37260631828611E-6,-0.000154974925564503,2.29162324044518E-6,50.1916,50.1916,50820.5859375,50835.80859375,53.892504772448,19.5599148905213,19.112494,0,0,0,40,4449,50.19355,50828.197265625,,,,,,,,,,,,,0,,,,,,,,,,,,,,
,19709220.065,50.1922,54608.59375,-0.000172549752294887,9.36345060535174E-7,1,0.999253354069792,40.0298881530762,1.99408689867717,14.2400003969669,-0.00195766901386835,-0.000312481640377359,0.25,3.37667896649447E-6,-0.000172964702831503,2.18110963205342E-6,50.1903,50.1903,54603.60546875,54613.58203125,53.8839068587365,19.5637991301628,19.112494,0,0,0,40,4449,50.1922,54608.59375,,,,,,,,,,,,,0,,,,,,,,,,,,,,
,19709294.125,50.1916,58311.955078125,-0.000190850724099018,9.50006554946065E-7,1,0.999253354069792,40.0298881530762,1.99410852983035,14.2400003969669,-0.00216615637120923,-0.000343058652843038,0.25,3.95449255319799E-6,-0.000191342985958143,2.64565776281647E-6,50.1916,50.1916,58306.9453125,58316.96484375,53.9581615680634,19.5628476202355,18.732843,0,0,0,40,4449,50.1916,58311.955078125,,,,,,,,,,,,,0,,,,,,,,,,,,,,
,19709370.265,50.1913,62117.15625,-0.000208554721439305,1.0836866101298E-6,1,0.999253354069792,40.0298881530762,1.99395752047491,14.2400003969669,-0.00236425060144779,-0.000391979523090322,0.25,2.79790662418147E-6,-0.000209116743894387,1.37884962516695E-6,50.191,50.191,62114.63671875,62119.67578125,53.963632967698,19.5641914556057,18.732843,0,0,0,40,4449,50.1913,62117.15625,,,,,,,,,,,,,0,,,,,,,,,,,,,,
,19709443.61,50.18725,65783.1640625,-0.00022549173823237,1.09578504186243E-6,1,0.999253354069792,40.0298881530762,1.99386397394202,14.2500000074506,-0.00255570514675695,-0.000428462306816154,0.25,2.60244918904983E-6,-0.00022613127747364,1.08290797002665E-6,50.1886,50.1886,65773.375,65792.953125,53.8487335753711,19.5595627228453,18.732843,0,0,0,40,4449,50.18725,65783.1640625,,,,,,,,,,,,,0,,,,,,,,,,,,,,
,19709518.755,50.1816,69538.9453125,-0.000244836059298237,1.25279481928864E-6,1,0.999253354069792,40.0298881530762,1.99384871359572,14.2400003969669,-0.00277778501475995,-0.000451729368918046,0.25,4.00628234025566E-6,-0.000245575676079922,2.37787312000052E-6,50.1816,50.1816,69536.2890625,69541.6015625,53.8393540331403,19.5614798965562,18.353191,0,0,0,40,4449,50.1816,69538.9453125,,,,,,,,,,,,,0,,,,,,,,,,,,,,
,19709592.545,50.18425,73227.44140625,-0.00026314905518259,9.36625407083415E-7,1,0.999253354069792,40.0298881530762,1.99407454529944,14.2400003969669,-0.00298374739261006,-0.000499914275548867,0.25,3.02507108575656E-6,-0.00026397367292526,1.29072356777329E-6,50.1859,50.1859,73219.9609375,73234.921875,53.9909899658711,19.5608463669498,19.112494,0,0,0,40,4449,50.18425,73227.44140625,,,,,,,,,,,,,0,,,,,,,,,,,,,,
,19709668.22,50.1808,77008.2734375,-0.000281378668341688,1.01139788676951E-6,1,0.999253354069792,40.0298881530762,1.99406059304688,14.2400003969669,-0.00319365647497586,-0.000519120158494583,0.25,4.58263689774861E-6,-0.000282309442803141,2.75415593172865E-6,50.1808,50.1808,77003.1640625,77013.3828125,53.7932379505057,19.5611196723002,18.732843,0,0,0,40,4449,50.1808,77008.2734375,,,,,,,,,,,,,0,,,,,,,,,,,,,,
,19709744.39,50.1792,80817.27734375,-0.000302714260534934,1.26319745613602E-6,1,0.999253354069792,40.0298881530762,1.99402384939287,14.2400003969669,-0.00343333941786051,-0.000574665074577876,0.25,3.48271322989564E-6,-0.000303748129486067,1.5348127996515E-6,50.1759,50.1759,80807.3984375,80827.15625,53.8917231439288,19.5597953938972,18.353191,0,0,0,40,4449,50.1792,80817.27734375,,,,,,,,,,,,,0,,,,,,,,,,,,,,
,19709818.525,50.1773,84523.08984375,-0.000321515111052442,1.29860680931904E-6,1,0.999253354069792,40.0298881530762,1.99414107961886,14.2400003969669,-0.00365034803477426,-0.000593179190538972,0.25,5.20170278055305E-6,-0.000322664548452295,3.16291913896086E-6,50.177,50.177,84510.3046875,84535.875,53.9097005998711,19.5589221783621,19.112494,0,0,0,40,4449,50.1773,84523.08984375,,,,,,,,,,,,,0,,,,,,,,,,,,,,
,19709888.58,50.1728,88023.86328125,-0.000340584253334136,1.05967937831445E-6,1,0.999253354069792,40.0298881530762,1.99415850000139,14.2500000074506,-0.00386183688445522,-0.000659139374960952,0.25,2.77405925234359E-6,-0.000341824589232837,6.29713613810106E-7,50.1728,50.1728,88018.8203125,88028.90625,53.8549866035249,19.557210463705,18.732843,0,0,0,40,4449,50.1728,88023.86328125,,,,,,,,,,,,,0,,,,,,,,,,,,,,
,19709978.415,50.17555,88440.2109375,-0.00034803710959254,1.11336869973908E-6,1,0.999253354069792,40.0298881530762,1.9941110748666,14.2400003969669,-0.00394855428325671,-0.000661019864505359,0.25,3.93898983329438E-6,-0.000349316459873827,1.7548059775243E-6,50.1739,50.1739,88427.4609375,88452.9609375,53.7072588133903,19.5601481063592,18.732843,0,0,0,40,4449,50.17555,88440.2109375,,,,,,,,,,,,,0,,,,,,,,,,,,,,
,19710048.985,50.1764,84912.05859375,-0.000334225830707964,1.1961666422831E-6,1,0.999253354069792,40.0298881530762,1.99409334772199,14.2500000074506,-0.00378891286503039,-0.00064850099173122,0.25,2.58883343694818E-6,-0.00033540712407351,4.62357078095012E-7,50.1753,50.1753,84909.671875,84914.4453125,53.8041807497749,19.5605253680171,19.112494,0,0,0,40,4449,50.1764,84912.05859375,,,,,,,,,,,,,0,,,,,,,,,,,,,,
,19710121.205,50.1722,81303.37890625,-0.000321526787473241,1.03563021743341E-6,1,0.999253354069792,40.0298881530762,1.99413588295636,14.2500000074506,-0.00364578953421669,-0.000616974057147298,0.25,3.11716657556876E-6,-0.00032262648221201,1.04936047796825E-6,50.1722,50.1722,81300.859375,81305.8984375,53.9440922547172,19.5611107308199,19.112494,0,0,0,40,4449,50.1722,81303.37890625,,,,,,,,,,,,,0,,,,,,,,,,,,,,
,19710195.57,50.1744,77586.54296875,-0.000308513134615294,1.23224243389641E-6,1,0.999253354069792,40.0298881530762,1.99419755013472,14.2400003969669,-0.0034961453256471,-0.000601520620806627,0.25,2.16802054942345E-6,-0.000309521361873356,1.57580589439497E-7,50.1769,50.1769,77576.71875,77596.3671875,53.9792655380826,19.5603685073601,18.732843,0,0,0,40,4449,50.1744,77586.54296875,,,,,,,,,,,,,0,,,,,,,,,,,,,,
,19710269.885,50.1757,73870.2109375,-0.000294418009736313,9.72074110162767E-7,1,0.999253354069792,40.0298881530762,1.99422303064266,14.2400003969669,-0.00333724247276002,-0.000566994740015736,0.25,2.70712500804209E-6,-0.000295343114167145,7.6827699732235E-7,50.1757,50.1757,73867.515625,73872.90625,53.679120186698,19.5612115461602,19.112494,0,0,0,40,4449,50.1757,73870.2109375,,,,,,,,,,,,,0,,,,,,,,,,,,,,
,19710345.925,50.17435,70069.51953125,-0.000278668022803236,1.06985613044626E-6,1,0.999253354069792,40.0298881530762,1.99412956390447,14.2400003969669,-0.00315935909252059,-0.000529580642699967,0.25,3.20030121400821E-6,-0.000279506380301755,1.34572919482367E-6,50.1749,50.1749,70059.609375,70079.4296875,53.7518116389865,19.5603337562634,19.112494,0,0,0,40,4449,50.17435,70069.51953125,,,,,,,,,,,,,0,,,,,,,,,,,,,,
,19710423.375,50.1726,66198.71484375,-0.00026123778817902,1.00259490279617E-6,1,0.999253354069792,40.0298881530762,1.99417083193927,14.2400003969669,-0.00296466659103398,-0.000477867061117649,0.25,4.65718493110027E-6,-0.000261993790500439,2.90316653349688E-6,50.1726,50.1726,66191.3984375,66206.03125,53.8073072638518,19.5614918177711,19.112494,0,0,0,40,4449,50.1726,66198.71484375,,,,,,,,,,,,,0,,,,,,,,,,,,,,
,19710499.165,50.1744,62410.357421875,-0.000246935564283755,8.633241749039E-7,1,0.999253354069792,40.0298881530762,1.99424535397998,14.2500000074506,-0.00280018431014754,-0.000461841517352174,0.25,3.51893880495609E-6,-0.000247604921709756,1.8403601205812E-6,50.1755,50.1755,62402.65625,62418.05859375,53.7580646671403,19.5624539097152,19.492144,0,0,0,40,4449,50.1744,62410.357421875,,,,,,,,,,,,,0,,,,,,,,,,,,,,
,19710572.48,50.1747,58747.064453125,-0.00023132315887064,7.42125170673411E-7,1,0.999253354069792,40.0298881530762,1.99436196814854,14.2400003969669,-0.00261961710501276,-0.00045072627009867,0.25,1.70914793927326E-6,-0.00023190237317247,1.1681376642647E-7,50.1747,50.1747,58739.5390625,58754.58984375,53.9112638569095,19.5596896978805,18.732843,0,0,0,40,4449,50.1747,58747.064453125,,,,,,,,,,,,,0,,,,,,,,,,,,,,
,19710646.95,50.1732,55021.201171875,-0.000215644800637352,1.03753380172429E-6,1,0.999253354069792,40.0298881530762,1.99428470592583,14.2400003969669,-0.00244397539656339,-0.0004067020878759,0.25,2.79186200930807E-6,-0.000216156830938557,1.29576011112716E-6,50.1732,50.1732,55016.33984375,55026.0625,53.8760905735442,19.5613906531208,19.492144,0,0,0,40,4449,50.1732,55021.201171875,,,,,,,,,,,,,0,,,,,,,,,,,,,,
,19710723.395,50.1728,51203.3125,-0.000199033575690711,1.1585871989208E-6,1,0.999253354069792,40.0298881530762,1.99418655516563,14.2400003969669,-0.00225681105188896,-0.000366389179902702,0.25,3.37717857533817E-6,-0.000199476483328909,1.98475009500096E-6,50.1703,50.1703,51198.21875,51208.40625,54.0066225362557,19.5620982518826,19.492144,0,0,0,40,4449,50.1728,51203.3125,,,,,,,,,,,,,0,,,,,,,,,,,,,,
,19710797.465,50.1737,47500.240234375,-0.000181388514936823,9.1025076262146E-7,1,0.999253354069792,40.0298881530762,1.99421103613294,14.2400003969669,-0.00205551558639193,-0.000338760971205952,0.25,2.65442826037536E-6,-0.000181757077111101,1.3733573422122E-6,50.1737,50.1737,47495.48828125,47504.9921875,54.169982896775,19.5624716902166,19.492144,0,0,0,40,4449,50.1737,47500.240234375,,,,,,,,,,,,,0,,,,,,,,,,,,,,
,19710871.04,50.1762,43821.47265625,-0.000164807750097218,6.89006156415669E-7,1,0.999253354069792,40.0298881530762,1.99430527587476,14.2400003969669,-0.00186809705199778,-0.000303707857926704,0.25,2.77906151429219E-6,-0.000165115510396614,1.60620393524113E-6,50.1762,50.1762,43816.5,43826.4453125,53.9816104236403,19.5610080231485,19.492144,0,0,0,40,4449,50.1762,43821.47265625,,,,,,,,,,,,,0,,,,,,,,,,,,,,
,19710946.105,50.1761,40070.94921875,-0.000147986318301888,7.48429696262508E-7,1,0.999253354069792,40.0298881530762,1.99427333007782,14.2400003969669,-0.00167532501559723,-0.000282428778134858,0.25,1.63819579405937E-6,-0.00014822851150802,5.75469864597461E-7,50.1761,50.1761,40063.4453125,40078.453125,54.1629482401019,19.5609106965673,19.492144,0,0,0,40,4449,50.1761,40070.94921875,,,,,,,,,,,,,0,,,,,,,,,,,,,,
,19711018.455,50.17405,36456.28125,-0.000130109153038129,5.71746122402757E-7,1,0.999253354069792,40.0298881530762,1.99420194946931,14.2400003969669,-0.00147485518694856,-0.000235818273444443,0.25,2.54761246220551E-6,-0.000130305758953052,1.6084484814013E-6,50.1702,50.1702,36446.22265625,36466.33984375,54.1379361274865,19.5608470080245,19.492144,0,0,0,40,4449,50.17405,36456.28125,,,,,,,,,,,,,0,,,,,,,,,,,,,,
,19711093.955,50.1729,32680.7529296875,-0.000112279125107074,7.88351479083319E-7,1,0.999253354069792,40.0298881530762,1.99411886602142,14.2400003969669,-0.00127126111844958,-0.000209997637508642,0.25,1.62409710634665E-6,-0.000112422273361258,8.07588358077197E-7,50.1729,50.1729,32673.255859375,32688.25,53.8815619731788,19.564092492565,18.732843,0,0,0,40,4449,50.1729,32680.7529296875,,,,,,,,,,,,,0,,,,,,,,,,,,,,
,19711165.295,50.1726,29117.751953125,-9.61192377750637E-5,8.01694536494863E-7,1,0.999253354069792,40.0298881530762,1.99423026538791,14.2400003969669,-0.00108868053208187,-0.000176772911205739,0.25,1.65757606125244E-6,-9.62253992529326E-5,9.55045754055683E-7,50.1726,50.1726,29115.173828125,29120.330078125,54.1051077296788,19.563709299506,19.112494,0,0,0,40,4449,50.1726,29117.751953125,,,,,,,,,,,,,0,,,,,,,,,,,,,,
,19711238.305,50.17305,25466.740234375,-7.75481267728804E-5,5.7771291369549E-7,1,0.999253354069792,40.0298881530762,1.99421059280999,14.2400003969669,-0.000878296025188528,-0.000141812663169473,0.25,1.40875746705335E-6,-7.76189765567404E-5,8.39221954700814E-7,50.1706,50.1706,25456.849609375,25476.630859375,53.8002726071788,19.5639701350762,19.112494,0,0,0,40,4449,50.17305,25466.740234375,,,,,,,,,,,,,0,,,,,,,,,,,,,,
,19711311.78,50.1747,21796.291015625,-6.03626190849606E-5,5.9919651610133E-7,1,0.999253354069792,40.0298881530762,1.99434038224575,14.2400003969669,-0.000685563749765629,-9.92623345251542E-5,0.25,2.08241982788498E-6,-6.04129896567199E-5,1.63779539364985E-6,50.1747,50.1747,21788.763671875,21803.818359375,53.8284112338711,19.5620871271353,19.112494,0,0,0,40,4449,50.1747,21796.291015625,,,,,,,,,,,,,0,,,,,,,,,,,,,,
,19711384.975,50.1761,18138.708984375,-4.29381487108506E-5,5.17040134445858E-7,1,0.999253354069792,40.0298881530762,1.99435819002001,14.2400003969669,-0.000487320979816034,-7.19995500317466E-5,0.25,1.35789006568523E-6,-4.29645240564974E-5,1.04033099250135E-6,50.1761,50.1761,18136.36328125,18141.0546875,54.1942133808711,19.5619107884401,18.732843,0,0,0,40,4449,50.1761,18138.708984375,,,,,,,,,,,,,0,,,,,,,,,,,,,,
,19711458.205,50.17615,14478.3349609375,-2.49195479930368E-5,4.37173797527322E-7,1,0.999253354069792,40.0298881530762,1.99428507127482,14.2400003969669,-0.00028317085470916,-3.94706324056593E-5,0.25,9.928305524364E-7,-2.49314419772318E-5,8.08005521970422E-7,50.1731,50.1731,14473.119140625,14483.55078125,54.2215703790442,19.5654705176071,19.112494,0,0,0,40,4449,50.17615,14478.3349609375,,,,,,,,,,,,,0,,,,,,,,,,,,,,
,19711531.03,50.1734,10838.37109375,-8.43481106760386E-6,3.81916033373676E-7,1,0.999253354069792,40.0298881530762,1.99435278876568,14.2400003969669,-9.66877214669485E-5,-8.61428349734676E-6,0.25,7.56674997131479E-7,-8.44033041522446E-6,6.93953168285592E-7,50.1734,50.1734,10836.072265625,10840.669921875,53.7674442093711,19.5648390651883,18.732843,0,0,0,40,4449,50.1734,10838.37109375,,,,,,,,,,,,,0,,,,,,,,,,,,,,
,19711603.94,50.1721,7194.2783203125,8.8354028147176E-6,4.2504344047693E-7,1,0.999253354069792,40.0298881530762,1.99433127915212,14.2400003969669,9.90995112539342E-5,2.10068042469463E-5,0.25,2.70000748010265E-7,8.83163665394832E-6,3.35687345212018E-7,50.1721,50.1721,7186.728515625,7201.828125,54.2543987768519,19.5637138638623,18.732843,0,0,0,40,4449,50.1721,7194.2783203125,,,,,,,,,,,,,0,,,,,,,,,,,,,,
,19711675.99,50.17355,3590.58203125,2.56808850088175E-5,3.73282938295049E-7,1,0.999253354069792,40.0298881530762,1.99434920575691,14.2400003969669,0.000289706755233573,5.15532993255783E-5,0.25,-5.72984960828306E-8,2.56718575890754E-5,1.3382983601986E-7,50.1749,50.1749,3583.30151367188,3597.86254882812,54.1606033545442,19.5645903303695,18.732843,0,0,0,40,4449,50.17355,3590.58203125,,,,,,,,,,,,,0,,,,,,,,,,,,,,
,19711747.985,50.1722,-7.81341391801834,3.46501526660095E-5,2.84820272082317E-7,1,0.999253354069792,40.0298881530762,1.99431523403415,14.2400003969669,0.000391051282246386,6.83253081036598E-5,0.25,-1.85753097182906E-7,3.46341609853233E-5,7.21281521713109E-8,50.1722,50.1722,-15.3832960128784,-0.243531823158264,54.0894751592942,19.5634088079203,19.492144,0,0,0,40,4449,50.1722,-7.81341391801834,,,,,,,,,,,,,0,,,,,,,,,,,,,,
,19711822.95,50.1694,-3748.72009277344,4.19845439692503E-5,3.00855046250604E-7,1,0.999253354069792,40.0298881530762,1.99439540464448,14.2400003969669,0.000474199227627132,8.11929243688341E-5,0.25,-3.67832626316454E-7,4.19720656365014E-5,-5.52654011633912E-8,50.1694,50.1694,-3758.88940429687,-3738.55078125,54.1277749567365,19.563231832372,18.732843,0,0,0,40,4449,50.1694,-3748.72009277344,,,,,,,,,,,,,0,,,,,,,,,,,,,,
,19711898.06,50.1753,-7505.56518554687,5.76996551964266E-5,2.71259601361107E-7,1,0.999253354069792,40.0298881530762,1.99449629123817,14.2400003969669,0.000653084818200351,0.000104726105478559,0.25,-1.11561842514824E-6,5.76974264408668E-5,-6.86115203665714E-7,50.1766,50.1766,-7512.92431640625,-7498.2060546875,53.9097005998711,19.5624181819898,19.112494,0,0,0,40,4449,50.1753,-7505.56518554687,,,,,,,,,,,,,0,,,,,,,,,,,,,,
,19711970.915,50.1685,-11146.8862304688,6.95043044059217E-5,3.78078067396226E-7,1,0.999253354069792,40.0298881530762,1.99444530069256,14.2400003969669,0.000787098417917959,0.000124649161015603,0.25,-1.4783386541423E-6,6.95154419580262E-5,-9.61626335893663E-7,50.1685,50.1685,-11151.953125,-11141.8193359375,53.8964129150442,19.5659970870047,19.492144,0,0,0,40,4449,50.1685,-11146.8862304688,,,,,,,,,,,,,0,,,,,,,,,,,,,,
,19712046.105,50.16735,-14905.0546875,7.79722935702176E-5,5.14579725114251E-7,1,0.999253354069792,40.0298881530762,1.99437005691583,14.2400003969669,0.000883301610206359,0.000138951783968567,0.25,-1.73779175156239E-6,7.80009468800284E-5,-1.15938070890669E-6,50.1682,50.1682,-14909.96875,-14900.140625,54.2872271746596,19.5669507424087,19.492144,0,0,0,40,4449,50.16735,-14905.0546875,,,,,,,,,,,,,0,,,,,,,,,,,,,,
,19712120.83,50.1705,-18637.9462890625,8.27187400831987E-5,5.44360402071755E-7,1,0.999253354069792,40.0298881530762,1.99451422688453,14.2400003969669,0.000939579783768784,0.000134945370035408,0.25,-2.95000252797866E-6,8.27741488837594E-5,-2.33864716956195E-6,50.1705,50.1705,-18642.861328125,-18633.03125,54.1817073245634,19.5642157827014,19.492144,0,0,0,40,4449,50.1705,-18637.9462890625,,,,,,,,,,,,,0,,,,,,,,,,,,,,
,19712195.86,50.1677,-22388.158203125,8.76458349548994E-5,6.81623036670169E-7,1,0.999253354069792,40.0298881530762,1.99440093888874,14.2400003969669,0.00099389285781067,0.000152999708859582,0.25,-2.23808770245717E-6,8.77158449900593E-5,-1.59244649461124E-6,50.1669,50.1669,-22390.677734375,-22385.638671875,54.0824405026211,19.5666245024227,19.492144,0,0,0,40,4449,50.1677,-22388.158203125,,,,,,,,,,,,,0,,,,,,,,,,,,,,
,19712268.91,50.16885,-26038.0576171875,9.4843116727482E-5,5.24198035234791E-7,1,0.999253354069792,40.0298881530762,1.99435679836915,14.2400003969669,0.00107657501391913,0.000160736629626055,0.25,-2.84921658041839E-6,9.49408987322519E-5,-2.15406218932356E-6,50.1683,50.1683,-26043.044921875,-26033.0703125,54.1910868667942,19.5693250945937,19.112494,0,0,0,40,4449,50.16885,-26038.0576171875,,,,,,,,,,,,,0,,,,,,,,,,,,,,
,19712341.08,50.172,-29646.537109375,0.000108337434126175,6.42608133615855E-7,1,0.999253354069792,40.0298881530762,1.99453536303614,14.2400003969669,0.00122877906815657,0.000190966626046366,0.25,-2.60367098262807E-6,0.00010846554194973,-1.81318745573281E-6,50.172,50.172,-29651.587890625,-29641.486328125,54.1082342437557,19.5663332229607,18.732843,0,0,0,40,4449,50.172,-29646.537109375,,,,,,,,,,,,,0,,,,,,,,,,,,,,
,19712414.125,50.1657,-33296.962890625,0.000122233974301197,5.53224475399288E-7,1,0.999253354069792,40.0298881530762,1.99446928398214,14.2400003969669,0.00138787654955814,0.000208513281988269,0.25,-3.5510921865496E-6,0.000122406600664038,-2.66517728882249E-6,50.1646,50.1646,-33299.4375,-33294.48828125,53.9800471666019,19.5656449990522,19.492144,0,0,0,40,4449,50.1657,-33296.962890625,,,,,,,,,,,,,0,,,,,,,,,,,,,,
,19712489.805,50.1657,-37077.1640625,0.000138760296475668,8.39818980327501E-7,1,0.999253354069792,40.0298881530762,1.99452840327029,14.2400003969669,0.00157590620789068,0.00023659121451122,0.25,-4.03958170284681E-6,0.000138983783094665,-3.04091055482412E-6,50.1657,50.1657,-37081.8515625,-37072.4765625,54.1238668141403,19.5665478385022,19.492144,0,0,0,40,4449,50.1657,-37077.1640625,,,,,,,,,,,,,0,,,,,,,,,,,,,,
,19712564.22,50.16685,-40794.357421875,0.00015765082782886,9.06509836169664E-7,1,0.999253354069792,40.0298881530762,1.99460682744214,14.2400003969669,0.00178887319205864,0.000279868637803623,0.25,-3.60759500014111E-6,0.000157927749337755,-2.47995409787646E-6,50.1707,50.1707,-40799.109375,-40789.60546875,54.1989031519865,19.568162076331,19.112494,0,0,0,40,4449,50.16685,-40794.357421875,,,,,,,,,,,,,0,,,,,,,,,,,,,,
,19712639.055,50.16465,-44534.74609375,0.000174363218218787,7.01480647904715E-7,1,0.999253354069792,40.0298881530762,1.99449382365424,14.2400003969669,0.00197613126460694,0.00032425125706778,0.25,-2.68230989230513E-6,0.000174692774923715,-1.44278982675814E-6,50.1652,50.1652,-44542.25,-44527.2421875,54.1285565852557,19.5639061855024,19.492144,0,0,0,40,4449,50.16465,-44534.74609375,,,,,,,,,,,,,0,,,,,,,,,,,,,,
,19712713.515,50.163,-48257.830078125,0.000191660060870722,7.74676766344964E-7,1,0.999253354069792,40.0298881530762,1.99464732730562,14.2400003969669,0.00217637063714759,0.000336192132611634,0.25,-4.73434243673905E-6,0.000192069809670154,-3.38675368407969E-6,50.1616,50.1616,-48265.1328125,-48250.52734375,54.3513207132365,19.5675395919335,19.112494,0,0,0,40,4449,50.163,-48257.830078125,,,,,,,,,,,,,0,,,,,,,,,,,,,,
,19712789.23,50.16145,-52043.365234375,0.00021168495810608,1.00787000950722E-6,1,0.999253354069792,40.0298881530762,1.99463295189881,14.2400003969669,0.00240171433770684,0.000385055893576824,0.25,-4.00647120826822E-6,0.000212166868778403,-2.52934028849791E-6,50.1617,50.1617,-52053.38671875,-52033.34375,54.271594604275,19.5664289494965,19.112494,0,0,0,40,4449,50.16145,-52043.365234375,,,,,,,,,,,,,0,,,,,,,,,,,,,,
,19712866.31,50.1587,-55893.048828125,0.000230734509995529,8.92147028885518E-7,1,0.999253354069792,40.0298881530762,1.99467295612042,14.2400003969669,0.00262091464824376,0.000405550873112871,0.25,-5.61063233295634E-6,0.000231309235270137,-4.01930846173937E-6,50.1565,50.1565,-55900.9609375,-55885.13671875,54.0503937333326,19.5669217826503,19.112494,0,0,0,40,4449,50.1587,-55893.048828125,,,,,,,,,,,,,0,,,,,,,,,,,,,,
,19712942.125,50.1578,-59683.671875,0.000249870389030558,9.78854856934451E-7,1,0.999253354069792,40.0298881530762,1.99462327896615,14.2400003969669,0.00283839998691724,0.000440847385392123,0.25,-5.91750296796577E-6,0.000250533776582439,-4.21164889681138E-6,50.1578,50.1578,-59688.265625,-59679.078125,54.0941649304096,19.5680704150723,19.112494,0,0,0,40,4449,50.1578,-59683.671875,,,,,,,,,,,,,0,,,,,,,,,,,,,,
,19713017.065,50.1577,-63429.240234375,0.000268755973018895,8.99768440422744E-7,1,0.999253354069792,40.0298881530762,1.9945602540003,14.2400003969669,0.00305366377230942,0.000472355851118199,0.25,-6.5115402970919E-6,0.000269513783562984,-4.69670577973712E-6,50.1577,50.1577,-63431.640625,-63426.83984375,54.4857608185442,19.5704202791024,19.112494,0,0,0,40,4449,50.1577,-63429.240234375,,,,,,,,,,,,,0,,,,,,,,,,,,,,
,19713089.515,50.1605,-67049.48046875,0.000286640227428027,9.58738762702263E-7,1,0.999253354069792,40.0298881530762,1.99462777423086,14.2400003969669,0.003252335077487,0.000532439545120544,0.25,-4.40091402472285E-6,0.000287474508979444,-2.47894820483722E-6,50.1583,50.1583,-67059.6015625,-67039.359375,54.2504906342557,19.5689857614854,18.732843,0,0,0,40,4449,50.1605,-67049.48046875,,,,,,,,,,,,,0,,,,,,,,,,,,,,
,19713165.335,50.15695,-70838.87109375,0.000307725658078858,8.4729633688859E-7,1,0.999253354069792,40.0298881530762,1.99481699777588,14.2400003969669,0.00348852038767158,0.000593491876458307,0.25,-2.7803433624103E-6,0.00030865512478396,-7.34529295980374E-7,50.1583,50.1583,-70846.3515625,-70831.390625,54.0292897633134,19.5671827930074,19.492144,0,0,0,40,4449,50.15695,-70838.87109375,,,,,,,,,,,,,0,,,,,,,,,,,,,,
,19713241.145,50.1555,-74629.17578125,0.000328897776384624,1.03982228866266E-6,1,0.999253354069792,40.0298881530762,1.99470854763478,14.2400003969669,0.0037347835585106,0.000601523577133553,0.25,-5.84986054557571E-6,0.000329958636061877,-3.69734116966024E-6,50.1555,50.1555,-74634.4921875,-74623.859375,54.2082826942173,19.5681519336403,19.112494,0,0,0,40,4449,50.1555,-74629.17578125,,,,,,,,,,,,,0,,,,,,,,,,,,,,
,19713314.41,50.1562,-78286.74609375,0.000346398514271489,1.12037147941407E-6,1,0.999253354069792,40.0298881530762,1.99477932384937,14.2400003969669,0.00393310647126809,0.000639621325882904,0.25,-5.60689676532763E-6,0.000347559508694283,-3.36441196527581E-6,50.1548,50.1548,-78296.7734375,-78276.71875,54.1934317523519,19.5662955546879,19.871798,0,0,0,40,4449,50.1562,-78286.74609375,,,,,,,,,,,,,0,,,,,,,,,,,,,,
,19713391.24,50.1519,-82127.45703125,0.000367950147594164,1.09163136501777E-6,1,0.999253354069792,40.0298881530762,1.99457523991143,14.2400003969669,0.00417674140705066,0.000686312488762415,0.25,-5.32003298830439E-6,0.000369229898964976,-2.96540147460274E-6,50.1519,50.1519,-82130.078125,-82124.8359375,54.2450192346211,19.5705270967058,19.492144,0,0,0,40,4449,50.1519,-82127.45703125,,,,,,,,,,,,,0,,,,,,,,,,,,,,
,19713465.995,50.1502,-85864.953125,0.00038693086009947,1.34830340971623E-6,1,0.999253354069792,40.0298881530762,1.99455594401594,14.2400003969669,0.00439455359202109,0.000711571443503804,0.25,-6.46798760016479E-6,0.00038833215549062,-4.025402589557E-6,50.1532,50.1532,-85872.578125,-85857.328125,54.4208856514481,19.5689269611521,19.112494,0,0,0,40,4449,50.1502,-85864.953125,,,,,,,,,,,,,0,,,,,,,,,,,,,,
,19713537.79,50.1508,-89452.109375,0.000404515505308997,1.01446942321106E-6,1,0.999253354069792,40.0298881530762,1.99453564911282,14.2400003969669,0.00459609360796857,0.000736597466229429,0.25,-7.38449341508959E-6,0.000406032661292544,-4.86404207750271E-6,50.1508,50.1508,-89459.4921875,-89444.7265625,54.1277749567365,19.5717546107812,19.112494,0,0,0,40,4449,50.1508,-89452.109375,,,,,,,,,,,,,0,,,,,,,,,,,,,,
,19713629.995,50.1503,-86921.94921875,0.000393194413640341,1.02005278156978E-6,1,0.999253354069792,40.0298881530762,1.99458492103828,14.2400003969669,0.00446383237942782,0.000734734390070044,0.25,-5.538919300835E-6,0.000394625833295681,-3.06195251997083E-6,50.1525,50.1525,-86929.421875,-86914.4765625,54.0660263037173,19.5711968924058,19.492144,0,0,0,40,4449,50.1503,-86921.94921875,,,,,,,,,,,,,0,,,,,,,,,,,,,,
,19713701.18,50.1483,-83364.3828125,0.000374712083019015,1.56882109462347E-6,1,0.999253354069792,40.0298881530762,1.99452343827035,14.2400003969669,0.00425304317111022,0.000701904293257352,0.25,-5.14628151487806E-6,0.00037602971429639,-2.75710287890262E-6,50.1483,50.1483,-83366.8359375,-83361.9296875,54.3872756251211,19.5701238850173,19.112494,0,0,0,40,4449,50.1483,-83364.3828125,,,,,,,,,,,,,0,,,,,,,,,,,,,,
,19713776.385,50.15075,-79605.9453125,0.00035569923604879,8.61596614553672E-7,1,0.999253354069792,40.0298881530762,1.99453218142513,14.2400003969669,0.00403577823962374,0.000671497167995658,0.25,-4.44513392570492E-6,0.000356899745334698,-2.14778941428347E-6,50.1488,50.1488,-79613.1484375,-79598.7421875,54.2950434598519,19.5691332684251,19.492144,0,0,0,40,4449,50.15075,-79605.9453125,,,,,,,,,,,,,0,,,,,,,,,,,,,,
,19713851.81,50.1527,-75838.3671875,0.000336047222526876,8.07541159698896E-7,1,0.999253354069792,40.0298881530762,1.99457854275234,14.2400003969669,0.00381737898324273,0.00060635985443094,0.25,-6.69584875598586E-6,0.000337151111537564,-4.50715667793572E-6,50.1535,50.1535,-75846.2734375,-75830.4609375,54.3653900265827,19.5666737297494,19.112494,0,0,0,40,4449,50.1527,-75838.3671875,,,,,,,,,,,,,0,,,,,,,,,,,,,,
,19713925.88,50.1528,-72138.41015625,0.000316818931697038,1.3506628035461E-6,1,0.999253354069792,40.0298881530762,1.99464671565825,14.2400003969669,0.00359884332555319,0.000570047618273741,0.25,-6.47372869211825E-6,0.000317815930986203,-4.38649801589803E-6,50.1528,50.1528,-72143.296875,-72133.5234375,54.241111092025,19.5646476350837,19.112494,0,0,0,40,4449,50.1528,-72138.41015625,,,,,,,,,,,,,0,,,,,,,,,,,,,,
,19714000.865,50.1553,-68386.0078125,0.000299362719867215,8.57454048859093E-7,1,0.999253354069792,40.0298881530762,1.99451726960659,14.2400003969669,0.00339913728356756,0.000542445031001927,0.25,-5.79286265743758E-6,0.000300258165104754,-3.796867596747E-6,50.1553,50.1553,-68391.0390625,-68380.9765625,54.2270417786788,19.5669159207168,19.112494,0,0,0,40,4449,50.1553,-68386.0078125,,,,,,,,,,,,,0,,,,,,,,,,,,,,
,19714076.82,50.1562,-64591.044921875,0.000280660985495199,7.81520457163822E-7,1,0.999253354069792,40.0298881530762,1.9945826426304,14.2400003969669,0.00318416507620812,0.000520899625356547,0.25,-4.35509797516684E-6,0.000281449394128687,-2.45969114537896E-6,50.1562,50.1562,-64593.5078125,-64588.58203125,54.2262601501596,19.5652054382743,19.492144,0,0,0,40,4449,50.1562,-64591.044921875,,,,,,,,,,,,,0,,,,,,,,,,,,,,
,19714154.22,50.1517,-60722.80078125,0.000259132369407756,1.05931023452631E-6,1,0.999253354069792,40.0298881530762,1.99453462024768,14.2400003969669,0.00294097271503797,0.000471904779094125,0.25,-4.83102922352818E-6,0.00025982286745915,-3.06369744324618E-6,50.1517,50.1517,-60725.46484375,-60720.13671875,54.2387662064673,19.5650052002642,19.112494,0,0,0,40,4449,50.1517,-60722.80078125,,,,,,,,,,,,,0,,,,,,,,,,,,,,
,19714232.29,50.1569,-56822.28515625,0.000238471166944689,1.02415287888356E-6,1,0.999253354069792,40.0298881530762,1.99449722650243,14.2400003969669,0.00270655795464535,0.000430936922635233,0.25,-4.75094760764136E-6,0.000239067805956628,-3.10788074203748E-6,50.1569,50.1569,-56822.28515625,-56822.28515625,54.1246484426596,19.5663082838804,19.492144,0,0,0,40,4449,50.1569,-56822.28515625,,,,,,,,,,,,,0,,,,,,,,,,,,,,
,19714309.13,50.15765,-52982.73828125,0.000220853762073916,1.10062160907895E-6,1,0.999253354069792,40.0298881530762,1.99451989159774,14.2400003969669,0.00250836862160497,0.000386957301133925,0.25,-5.48298308567354E-6,0.000221375199559499,-3.94831512979181E-6,50.1571,50.1571,-52990.375,-52975.1015625,54.1199586715442,19.5644486963461,19.112494,0,0,0,40,4449,50.15765,-52982.73828125,,,,,,,,,,,,,0,,,,,,,,,,,,,,
,19714384,50.1545,-49239.9765625,0.000201218378646956,1.14638762119246E-6,1,0.999253354069792,40.0298881530762,1.99463191917917,14.2400003969669,0.00228460175726895,0.000355162085822627,0.25,-4.77363779028899E-6,0.00020165634113092,-3.36169698749722E-6,50.1556,50.1556,-49242.35546875,-49237.59765625,54.2551804053711,19.5617642351945,19.112494,0,0,0,40,4449,50.1545,-49239.9765625,,,,,,,,,,,,,0,,,,,,,,,,,,,,
,19714459.63,50.1551,-45462.845703125,0.000181925808281532,1.11153959273074E-6,1,0.999253354069792,40.0298881530762,1.99449828648777,14.2400003969669,0.00206689435477632,0.000310770883116392,0.25,-5.23451266665942E-6,0.000182295028559185,-3.94820329339484E-6,50.1565,50.1565,-45475.21875,-45450.47265625,54.4224489084865,19.5626613012208,19.492144,0,0,0,40,4449,50.1551,-45462.845703125,,,,,,,,,,,,,0,,,,,,,,,,,,,,
,19714534.08,50.1583,-41739.43359375,0.000164446415611944,8.15303171777693E-7,1,0.999253354069792,40.0298881530762,1.99459377885418,14.2400003969669,0.00186465116008407,0.000299756951587045,0.25,-3.06964077553249E-6,0.000164737880895467,-1.89449322639571E-6,50.1583,50.1583,-41741.76171875,-41737.10546875,54.3497574561981,19.5623116222537,19.112494,0,0,0,40,4449,50.1583,-41739.43359375,,,,,,,,,,,,,0,,,,,,,,,,,,,,
,19714611.14,50.1546,-37889.177734375,0.00014467656370824,6.62465443180681E-7,1,0.999253354069792,40.0298881530762,1.99462375111031,14.2400003969669,0.00164458886887749,0.000239192432136774,0.25,-4.87480806677485E-6,0.000144920110048629,-3.83607355319822E-6,50.1546,50.1546,-37894.0625,-37884.29296875,54.2215703790442,19.5615641502945,19.112494,0,0,0,40,4449,50.1546,-37889.177734375,,,,,,,,,,,,,0,,,,,,,,,,,,,,
,19714686.055,50.1617,-34146.46484375,0.000124662867679061,8.0216622697708E-7,1,0.999253354069792,40.0298881530762,1.99456023863228,14.2400003969669,0.0014141375511468,0.000220677250239176,0.25,-2.91205502365289E-6,0.000124839239760872,-2.0089874886738E-6,50.1636,50.1636,-34156.546875,-34136.3828125,54.2536171483327,19.5614001971617,19.112494,0,0,0,40,4449,50.1617,-34146.46484375,,,,,,,,,,,,,0,,,,,,,,,,,,,,
,19714763.86,50.1593,-30258.875,0.000105065779210634,8.24913574895645E-7,1,0.999253354069792,40.0298881530762,1.99450719332805,14.2400003969669,0.00119592916575183,0.000161671721062043,0.25,-4.60803416393949E-6,0.000105208398570483,-3.84423755614346E-6,50.1593,50.1593,-30268.95703125,-30248.79296875,54.129338213775,19.5610494391853,19.871798,0,0,0,40,4449,50.1593,-30258.875,,,,,,,,,,,,,0,,,,,,,,,,,,,,
,19714841.335,50.15935,-26383.7373046875,8.70520266537463E-5,9.32458719391723E-7,1,0.999253354069792,40.0298881530762,1.99445912447033,14.2400003969669,0.000990897572509707,0.000132579696539989,0.25,-3.94012934409309E-6,8.71529474260085E-5,-3.30344133960758E-6,50.1599,50.1599,-26391.564453125,-26375.91015625,54.227823407198,19.5629829403152,19.112494,0,0,0,40,4449,50.15935,-26383.7373046875,,,,,,,,,,,,,0,,,,,,,,,,,,,,
,19714916.335,50.1612,-22636.5517578125,6.75612908598359E-5,6.89209359802295E-7,1,0.999253354069792,40.0298881530762,1.99457647856798,14.2400003969669,0.000770323675753038,9.51201711456621E-5,0.25,-3.74743453722384E-6,6.76309871350035E-5,-3.25112737962765E-6,50.1612,50.1612,-22639.71875,-22633.384765625,54.0331979059096,19.5584888765921,19.492144,0,0,0,40,4449,50.1612,-22636.5517578125,,,,,,,,,,,,,0,,,,,,,,,,,,,,
,19714992.235,50.15955,-18843.291015625,4.88915189101566E-5,4.62589192748146E-7,1,0.999253354069792,40.0298881530762,1.99442043186076,14.2400003969669,0.000559473213142866,5.67395988742229E-5,0.25,-3.78312868510798E-6,4.89397746060346E-5,-3.42268148824501E-6,50.1601,50.1601,-18850.9453125,-18835.63671875,54.2551804053711,19.5594455037646,19.112494,0,0,0,40,4449,50.15955,-18843.291015625,,,,,,,,,,,,,0,,,,,,,,,,,,,,
,19715070.525,50.16345,-14930.6118164062,2.93454766758768E-5,4.0016073024839E-7,1,0.999253354069792,40.0298881530762,1.99446685853886,14.2400003969669,0.0003371087594193,2.64649808797672E-5,0.25,-2.9434614878712E-6,2.93732628772936E-5,-2.7262359841827E-6,50.1637,50.1637,-14937.990234375,-14923.2333984375,54.1777991819673,19.5593532523702,19.492144,0,0,0,40,4449,50.16345,-14930.6118164062,,,,,,,,,,,,,0,,,,,,,,,,,,,,
,19715147.39,50.1597,-11090.0688476562,1.10193777629183E-5,3.4781392675621E-7,1,0.999253354069792,40.0298881530762,1.99452861451285,14.2400003969669,0.000127967110735207,2.15121670414373E-6,0.25,-1.79547727283301E-6,1.10326888359347E-5,-1.71354711992977E-6,50.1597,50.1597,-11094.974609375,-11085.1630859375,54.0543018759288,19.5588229065093,19.112494,0,0,0,40,4449,50.1597,-11090.0688476562,,,,,,,,,,,,,0,,,,,,,,,,,,,,
,19715223.235,50.1634,-7296.6318359375,-7.31765586396237E-6,4.17371421697739E-7,1,0.999253354069792,40.0298881530762,1.99452293102002,14.2400003969669,-7.94899759645526E-5,-3.17906465282286E-5,0.25,-1.4994677277239E-6,-7.30506177319692E-6,-1.55362032588731E-6,50.1634,50.1634,-7301.8369140625,-7291.4267578125,53.9378392265634,19.5594169523985,19.112494,0,0,0,40,4449,50.1634,-7296.6318359375,,,,,,,,,,,,,0,,,,,,,,,,,,,,
,19715297.76,50.1595,-3572.69213867188,-2.46292117560298E-5,2.6489640024749E-7,1,0.999253354069792,40.0298881530762,1.99440983343718,14.2400003969669,-0.000275882695698671,-6.03543490567162E-5,0.25,-9.12617861545286E-7,-2.46132278974544E-5,-1.09555765128263E-6,50.1595,50.1595,-3582.75830078125,-3562.6259765625,53.7088220704288,19.5601024734436,19.112494,0,0,0,40,4449,50.1595,-3572.69213867188,,,,,,,,,,,,,0,,,,,,,,,,,,,,
,19715373.095,50.16095,191.232093811035,-3.35665078666417E-5,2.39732567247353E-7,1,0.999253354069792,40.0298881530762,1.9944872167745,14.2400003969669,-0.000377372287239642,-7.44081638569608E-5,0.25,-5.48538779617119E-7,-3.35456083791066E-5,-7.97990218272226E-7,50.1626,50.1626,181.324401855469,201.139785766602,53.8964129150442,19.5605083172063,19.492144,0,0,0,40,4449,50.16095,191.232093811035,,,,,,,,,,,,,0,,,,,,,,,,,,,,
,19715449.32,50.1599,3999.71411132812,-4.32662424166193E-5,3.67909900849147E-7,1,0.999253354069792,40.0298881530762,1.99444527117339,14.2400003969669,-0.000488148063843988,-8.66876484365429E-5,0.25,1.11849221239756E-7,-4.325175346543E-5,-2.1016362399229E-7,50.1599,50.1599,3994.65087890625,4004.77734375,54.0316346488711,19.5595717669608,19.492144,0,0,0,40,4449,50.1599,3999.71411132812,,,,,,,,,,,,,0,,,,,,,,,,,,,,
,19715525.15,50.16415,7788.951171875,-5.90948132914494E-5,3.68862785041191E-7,1,0.999253354069792,40.0298881530762,1.99443025527467,14.2400003969669,-0.000667365018318425,-0.000115562746834265,0.25,4.06117295451163E-7,-5.90876907177721E-5,-3.36194247966514E-8,50.1644,50.1644,7784.14794921875,7793.75439453125,54.0965098159673,19.5598613184664,19.492144,0,0,0,40,4449,50.16415,7788.951171875,,,,,,,,,,,,,0,,,,,,,,,,,,,,
,19715602.62,50.1605,11662.634765625,-7.12204304650486E-5,4.91185701583441E-7,1,0.999253354069792,40.0298881530762,1.99449049653567,14.2400003969669,-0.000806723899208849,-0.000126879238308769,0.25,1.59040365327395E-6,-7.1234171329035E-5,1.06105450088031E-6,50.1602,50.1602,11652.642578125,11672.626953125,54.0933833018903,19.5586867915716,19.871798,0,0,0,40,4449,50.1605,11662.634765625,,,,,,,,,,,,,0,,,,,,,,,,,,,,
,19715678.32,50.1583,15445.443359375,-8.11471761368212E-5,5.6774298669084E-7,1,0.999253354069792,40.0298881530762,1.99440061052841,14.2400003969669,-0.000919105938343213,-0.000145724987858447,0.25,1.71005760653759E-6,-8.11784278008154E-5,1.10827904152677E-6,50.1583,50.1583,15440.46875,15450.41796875,53.9651962247365,19.5557862995597,19.492144,0,0,0,40,4449,50.1583,15445.443359375,,,,,,,,,,,,,0,,,,,,,,,,,,,,
,19715753.62,50.1602,19208.2265625,-8.60247950187674E-5,4.82605417370905E-7,1,0.999253354069792,40.0298881530762,1.99458316804861,14.2400003969669,-0.000974924160148946,-0.000152933493335768,0.25,1.95253371700757E-6,-8.60765992092865E-5,1.31659373271191E-6,50.1602,50.1602,19198.310546875,19218.142578125,54.1629482401019,19.5551936027747,19.492144,0,0,0,40,4449,50.1602,19208.2265625,,,,,,,,,,,,,0,,,,,,,,,,,,,,
,19715828.485,50.1578,22948.673828125,-9.18529955791788E-5,6.29526904691268E-7,1,0.999253354069792,40.0298881530762,1.99441931942137,14.2400003969669,-0.00104362136840145,-0.00014935269667738,0.25,3.3193729948953E-6,-9.19361313007889E-5,2.64376097655116E-6,50.1578,50.1578,22945.796875,22951.55078125,53.9902083373519,19.5574016329418,19.112494,0,0,0,40,4449,50.1578,22948.673828125,,,,,,,,,,,,,0,,,,,,,,,,,,,,
,19715905.1,50.1643,26779.9345703125,-0.000101763517143141,6.08546336182119E-7,1,0.999253354069792,40.0298881530762,1.99443211285418,14.2400003969669,-0.00115491293504381,-0.00017416024858273,0.25,2.90746504850824E-6,-0.0001018713142346,2.16221052732472E-6,50.1643,50.1643,26775.095703125,26784.7734375,54.1027628441211,19.5562571031781,18.732843,0,0,0,40,4449,50.1643,26779.9345703125,,,,,,,,,,,,,0,,,,,,,,,,,,,,
,19715985.265,50.15865,30785.091796875,-0.000114155254563497,6.73873507444153E-7,1,0.999253354069792,40.0298881530762,1.99439995432343,14.2400003969669,-0.00129756869076873,-0.000185606559318376,0.25,4.12478332795357E-6,-0.000114306954380235,3.2947178798009E-6,50.1592,50.1592,30782.576171875,30787.607421875,53.9425289976788,19.5539631230476,19.871798,0,0,0,40,4449,50.15865,30785.091796875,,,,,,,,,,,,,0,,,,,,,,,,,,,,
,19716062.68,50.1568,34652.9140625,-0.000132252278501863,7.63770336361866E-7,1,0.999253354069792,40.0298881530762,1.99446096856015,14.2400003969669,-0.00150095308774156,-0.000229905056292118,0.25,3.46054470739556E-6,-0.000132445470675994,2.5037913932308E-6,50.1576,50.1576,34640.4921875,34665.3359375,54.1715461538134,19.5563296967666,19.871798,0,0,0,40,4449,50.1568,34652.9140625,,,,,,,,,,,,,0,,,,,,,,,,,,,,
,19716138.71,50.1579,38453.353515625,-0.000150636911067577,7.49783047685247E-7,1,0.999253354069792,40.0298881530762,1.99450350574669,14.2400003969669,-0.00171077362931246,-0.000257487738189036,0.25,4.32677494861665E-6,-0.000150889559896869,3.24541485898574E-6,50.1579,50.1579,38443.3984375,38463.30859375,54.0128755644096,19.5529865237797,19.492144,0,0,0,40,4449,50.1579,38453.353515625,,,,,,,,,,,,,0,,,,,,,,,,,,,,
,19716217.57,50.1555,42396.2421875,-0.000169061862458382,7.69715767877247E-7,1,0.999253354069792,40.0298881530762,1.99446992265353,14.2400003969669,-0.00191827181534647,-0.000300727986180529,0.25,3.8120486863739E-6,-0.00016937171590171,2.60664827315035E-6,50.1555,50.1555,42391.50390625,42400.98046875,54.1199586715442,19.5529203246629,19.112494,0,0,0,40,4449,50.1555,42396.2421875,,,,,,,,,,,,,0,,,,,,,,,,,,,,
,19716294.57,50.156,46244.658203125,-0.000189064072298973,7.41446179719396E-7,1,0.999253354069792,40.0298881530762,1.99451595686625,14.2400003969669,-0.00214882955149373,-0.000318890580647295,0.25,5.79938160332336E-6,-0.000189457602758301,4.46572161848008E-6,50.156,50.156,46239.3046875,46250.01171875,54.1301198422942,19.5523052991576,19.871798,0,0,0,40,4449,50.156,46244.658203125,,,,,,,,,,,,,0,,,,,,,,,,,,,,
,19716371.33,50.1513,50080.27734375,-0.000209410162268499,8.21266569871136E-7,1,0.999253354069792,40.0298881530762,1.99455076119901,14.2400003969669,-0.00237515171574229,-0.000383296805863614,0.25,3.75551649738815E-6,-0.000209865668978835,2.28658915435876E-6,50.1513,50.1513,50077.91796875,50082.63671875,54.1246484426596,19.5509763264999,19.871798,0,0,0,40,4449,50.1513,50080.27734375,,,,,,,,,,,,,0,,,,,,,,,,,,,,
,19716448.97,50.1556,53963.2890625,-0.000229815728126981,9.59653896497641E-7,1,0.999253354069792,40.0298881530762,1.99453183503816,14.2400003969669,-0.00260433117729308,-0.000435809030842827,0.25,2.77184920553329E-6,-0.000230348150634229,1.17239562646057E-6,50.1556,50.1556,53960.8828125,53965.6953125,54.0503937333326,19.5524231273132,19.871798,0,0,0,40,4449,50.1556,53963.2890625,,,,,,,,,,,,,0,,,,,,,,,,,,,,
,19716526.76,50.1506,57851.048828125,-0.000249639512882562,1.15078960912268E-6,1,0.999253354069792,40.0298881530762,1.99442299734579,14.2400003969669,-0.00283379707802502,-0.000448583762385802,0.25,5.1934906818954E-6,-0.000250276860539439,3.47866574001113E-6,50.1506,50.1506,57843.66015625,57858.4375,54.1121423863519,19.5504445015414,19.871798,0,0,0,40,4449,50.1506,57851.048828125,,,,,,,,,,,,,0,,,,,,,,,,,,,,
,19716604.215,50.1504,61721.388671875,-0.000270631880515178,9.36869289952902E-7,1,0.999253354069792,40.0298881530762,1.9943908886538,14.2400003969669,-0.00307128513909446,-0.000493496482445319,0.25,4.98181066909944E-6,-0.000271364219146247,3.1410409025016E-6,50.1504,50.1504,61716.48828125,61726.2890625,54.126211699698,19.5523293418267,19.492144,0,0,0,40,4449,50.1504,61721.388671875,,,,,,,,,,,,,0,,,,,,,,,,,,,,
,19716679.085,50.15095,65467.875,-0.000289237959533559,8.85371708889784E-7,1,0.999253354069792,40.0298881530762,1.99450056717958,14.2400003969669,-0.00328210267832876,-0.000533243197453469,0.25,4.79925984107788E-6,-0.000290062958756137,2.85163994721926E-6,50.1507,50.1507,65460.34375,65475.40625,54.1410626415634,19.5486247785073,19.492144,0,0,0,40,4449,50.15095,65467.875,,,,,,,,,,,,,0,,,,,,,,,,,,,,
,19716755.425,50.1486,69278.25390625,-0.000309180481027348,1.35822556784996E-6,1,0.999253354069792,40.0298881530762,1.99440549767745,14.2400003969669,-0.00350738218291859,-0.000577865176286308,0.25,4.41851897985445E-6,-0.000310105630522534,2.35795620597341E-6,50.1508,50.1508,69273.1328125,69283.375,53.9722308814096,19.5511881467098,19.492144,0,0,0,40,4449,50.1486,69278.25390625,,,,,,,,,,,,,0,,,,,,,,,,,,,,
,19716833.23,50.1463,73168.9140625,-0.000330367519203428,1.26489042235454E-6,1,0.999253354069792,40.0298881530762,1.99437842999711,14.2400003969669,-0.00374618877153609,-0.000629051142542538,0.25,3.67954167229374E-6,-0.000331399716834616,1.5005467221636E-6,50.1463,50.1463,73166.25,73171.578125,53.7955828360634,19.5526109135089,19.871798,0,0,0,40,4449,50.1463,73168.9140625,,,,,,,,,,,,,0,,,,,,,,,,,,,,
,19716911.39,50.14585,77074.85546875,-0.000347806422525637,1.27514907203629E-6,1,0.999253354069792,40.0298881530762,1.99433154949662,14.2400003969669,-0.0039496055653635,-0.000633469148529369,0.25,6.39702968022739E-6,-0.000348961206984786,4.13885696355331E-6,50.1478,50.1478,77069.9296875,77079.78125,53.6970976426403,19.5510903470579,19.492144,0,0,0,40,4449,50.14585,77074.85546875,,,,,,,,,,,,,0,,,,,,,,,,,,,,
,19716988.265,50.1454,80916.2890625,-0.000370779459821343,1.2427834983079E-6,1,0.999253354069792,40.0298881530762,1.99437677586799,14.2400003969669,-0.00420678566030717,-0.000699807867798059,0.25,4.63596449895556E-6,-0.000372048161133809,2.25121902464771E-6,50.1468,50.1468,80908.703125,80923.875,53.9112638569095,19.5533673718502,19.492144,0,0,0,40,4449,50.1454,80916.2890625,,,,,,,,,,,,,0,,,,,,,,,,,,,,
,19717066.855,50.1462,84846.890625,-0.000391561343414361,1.04699988221785E-6,1,0.999253354069792,40.0298881530762,1.99428784084134,14.2500000074506,-0.0044420054130374,-0.000744605102381929,0.25,4.37781253323486E-6,-0.000392951818719019,1.889893077725E-6,50.1462,50.1462,84836.9609375,84856.8203125,54.1840522101211,19.550604061851,19.871798,0,0,0,40,4449,50.1462,84846.890625,,,,,,,,,,,,,0,,,,,,,,,,,,,,
,19717140.56,50.1442,88530.2109375,-0.000410412837327611,1.53592798760089E-6,1,0.999253354069792,40.0298881530762,1.99434206160415,14.2400003969669,-0.00465754562098447,-0.000775048332702319,0.25,5.04478556306186E-6,-0.00041192401226417,2.47050761824377E-6,50.1442,50.1442,88525.203125,88535.21875,53.8362275190634,19.5500781546933,19.492144,0,0,0,40,4449,50.1442,88530.2109375,,,,,,,,,,,,,0,,,,,,,,,,,,,,
,19717172.1,50.142,89999.53515625,-0.000418703794842608,1.26544008823934E-6,1,0.999253354069792,40.0298881530762,1.99440612111032,14.2400003969669,-0.00474871682218932,-0.000809144225414055,0.25,3.5111520046192E-6,-0.000420255297258599,8.91850074941962E-7,50.1409,50.1409,89999.515625,89999.5546875,53.933149455448,19.5518014205801,19.871798,0,0,0,40,4417,50.142,89999.53515625,,,,,,,,,,,,,0,,,,,,,,,,,,,,