File: data/doubleLayers/monolayer/ppms/DD205_4/ppms_cologne_data/DD205_4_KOELNPPMS_HYST_100OE_50K_2.DAT
[Header]
; VSM Data File (default extension .dat)
; Copyright (c) 2003-2013, Quantum Design, Inc. All rights reserved.
TITLE,
FILEOPENTIME,19798269.23,08/18/2018,3:29 am
BYAPP,VSM,2.0,2.0
INFO,PPMS VSM Option Release 1.4.10 Build 1,APPNAME
INFO,Quantum Design Linear Motor Servo Controller,MOTOR_MODULE_NAME
INFO,3101-100 M1,MOTOR_HW_VERSION
INFO,MMC1014,MOTOR_SERIAL_NUMBER
INFO,SRV No X-over 01.03.11,MOTOR_SOFTWARE_VERSION
INFO,Quantum Design VSM Detection Module,VSM_MODULE_NAME
INFO,3101-150 F0,VSM_HW_VERSION
INFO,VSM707,VSM_SERIAL_NUMBER
INFO,VSM No X-over 01.02.05 May 20 2008 13:51:47,VSM_SOFTWARE_VERSION
INFO,704,PREAMP_SERIAL_NUMBER
INFO,822,COIL_SERIAL_NUMBER
INFO,0,MOMENT_UNITS
INFO,,SAMPLE_MATERIAL
INFO,,SAMPLE_COMMENT
INFO,,SAMPLE_MASS
INFO,,SAMPLE_VOLUME
INFO,,SAMPLE_MOLECULAR_WEIGHT
INFO,,SAMPLE_SIZE
INFO,,SAMPLE_SHAPE
DATATYPE,COMMENT,1
DATATYPE,TIME,2
STARTUPAXIS,X,2
STARTUPAXIS,Y1,5
[Data]
Comment,Time Stamp (sec),Temperature (K),Magnetic Field (Oe),Moment (emu),M. Std. Err. (emu),Transport Action,Averaging Time (sec),Frequency (Hz),Peak Amplitude (mm),Center Position (mm),Coil Signal' (mV),Coil Signal" (mV),Range (mV),M. Quad. Signal (emu),M. Raw' (emu),M. Raw" (emu),Min. Temperature (K),Max. Temperature (K),Min. Field (Oe),Max. Field (Oe),Mass (grams),Motor Lag (deg),Pressure (Torr),VSM Status (code),Motor Status (code),Measure Status (code),Measure Count,PPMS Status (code),System Temp. (K),System Field (Oe),Sample Position (deg),Bridge 1 Resistance (ohms),Bridge 1 Excitation (에),Bridge 2 Resistance (ohms),Bridge 2 Excitation (에),Bridge 3 Resistance (ohms),Bridge 3 Excitation (에),Bridge 4 Resistance (ohms),Bridge 4 Excitation (에),Signal 1 Vin (V),Signal 2 Vin (V),Digital Inputs (code),Drive 1 Iout (mA),Drive 1 Ipower (W),Drive 2 Iout (mA),Drive 2 Ipower (W),Pressure (),Map 20 (),Map 21 (),Map 22 (),Map 23 (),Map 24 (),Map 25 (),Map 26 (),Map 27 (),Map 28 (),Map 29 ()
sample offset = 35.68 mm,19798308.695,49.9998341,0.502384543418884,5.70815519100721E-7,1.61390398528762E-7,1,0.999253354069792,40.0298881530762,1.99363970395298,14.2400003969669,6.87645261660166E-6,-1.29732810837615E-6,0.25,-2.17994904875913E-7,5.72135304681242E-7,-2.13633307639191E-7,49.9995499,50.0001183,0.502384543418884,0.502384543418884,53.1030599680249,19.4932987879513,21.770052,0,0,0,40,4417,50.08225,0.502384543418884,,,,,,,,,,,,,0,,,,0.00245,,,,,,49.9998341,,,,
,19798440.07,49.9964218,5663.8193359375,-1.27030383821297E-5,2.82484813941002E-7,1,0.999253354069792,40.0298881530762,1.99390520732275,14.2400003969669,-0.000140095248750964,-4.31841169401721E-5,0.25,-1.54035368630972E-6,-1.26878281447306E-5,-1.63443086389046E-6,49.9964218,49.9964218,5658.7021484375,5668.9365234375,53.6173715336788,19.5092094969792,21.3904,0,0,0,40,4449,50.0966,5663.8193359375,,,,,,,,,,,,,0,,,,0,,,,,,49.9964218,,,,
,19798552.135,50.0120392,11264.001953125,-3.06692679187537E-5,5.88749861554116E-7,1,0.999253354069792,40.0298881530762,1.99409430850822,14.2400003969669,-0.000347019700839903,-5.62556243636128E-5,0.25,5.40327483201896E-7,-3.06727349116439E-5,3.12284153855063E-7,50.0120392,50.0120392,11256.2099609375,11271.7939453125,53.7447769823134,19.5147084669392,21.01075,0,0,0,40,4449,50.0751,11264.001953125,,,,,,,,,,,,,0,,,,0.00245,,,,,,50.0120392,,,,
,19798658.245,50.0118484,16568.9912109375,-4.69202271745878E-5,6.79565386895339E-7,1,0.999253354069792,40.0298881530762,1.99386323949605,14.2400003969669,-0.000529508079884246,-9.42898280364228E-5,0.25,9.7879612835402E-8,-4.69332978886497E-5,-2.50157559680108E-7,50.0118484,50.0118484,16563.982421875,16574,53.9980246225442,19.5216702810994,21.3904,0,0,0,40,4449,50.059,16568.9912109375,,,,,,,,,,,,,0,,,,0,,,,,,50.0118484,,,,
,19798770.085,50.0083656,22155.6455078125,-5.90912265577143E-5,8.32212514527011E-7,1,0.999253354069792,40.0298881530762,1.99398478047958,14.2400003969669,-0.000672560775739287,-8.85075247263699E-5,0.25,2.80483591933515E-6,-5.91455779984587E-5,2.36990092681161E-6,50.0083656,50.0083656,22150.7578125,22160.533203125,53.6447285318518,19.5242117793056,21.3904,0,0,0,40,4449,50.05495,22155.6455078125,,,,,,,,,,,,,0,,,,0,,,,,,50.0083656,,,,
,19798881.705,49.9979095,27738.3076171875,-7.80084263001646E-5,9.63521729426705E-7,1,0.999253354069792,40.0298881530762,1.99419987300718,14.2400003969669,-0.000882760657574691,-0.00014727370715419,0.25,1.00790117231616E-6,-7.80842712060241E-5,4.35936501192549E-7,49.9979095,49.9979095,27728.37109375,27748.244140625,53.6220613047941,19.5284907915172,21.3904,0,0,0,40,4449,50.06105,27738.3076171875,,,,,,,,,,,,,0,,,,0.00245,,,,,,49.9979095,,,,
,19798997.925,49.9999428,33545.08203125,-0.000101766231505235,1.36300544139083E-6,1,0.999253354069792,40.0298881530762,1.9941647569897,14.2400003969669,-0.00115547421063933,-0.000172609298991994,0.25,3.04191131062907E-6,-0.000101909597160797,2.30416718756946E-6,49.9999428,49.9999428,33540.24609375,33549.91796875,53.8573314890826,19.5333405119697,20.631098,0,0,0,40,4449,50.06005,33545.08203125,,,,,,,,,,,,,0,,,,0,,,,,,49.9999428,,,,
,19799108.65,50.0014076,39079.357421875,-0.000129267083760277,7.09452166056613E-7,1,0.999253354069792,40.0298881530762,1.99418296075869,14.2400003969669,-0.00146794798000525,-0.000220497937157572,0.25,3.75072835090255E-6,-0.000129485737643476,2.82321347196144E-6,50.0014076,50.0014076,39066.890625,39091.82421875,53.7838584082749,19.5325098867837,21.3904,0,0,0,40,4449,50.05755,39079.357421875,,,,,,,,,,,,,0,,,,0.00245,,,,,,50.0014076,,,,
,19799217.07,50.002182,44499.37890625,-0.000156832041765775,7.2603425186559E-7,1,0.999253354069792,40.0298881530762,1.99426015385399,14.2400003969669,-0.00177728136553623,-0.000291185908622683,0.25,2.45134461222626E-6,-0.00015712524976193,1.3353496004766E-6,50.002182,50.002182,44494.390625,44504.3671875,53.7588462956595,19.5358314471127,21.01075,0,0,0,40,4449,50.05405,44499.37890625,,,,,,,,,,,,,0,,,,0,,,,,,50.002182,,,,
,19799323.19,50.0014839,49802.15234375,-0.000185244633952024,8.38454984182611E-7,1,0.999253354069792,40.0298881530762,1.99407183289573,14.2400003969669,-0.00210335331085243,-0.000323224455452583,0.25,4.71785868982567E-6,-0.000185651943826125,3.41920725839425E-6,50.0014839,50.0014839,49797.296875,49807.0078125,53.7025690422749,19.5330266120676,21.01075,0,0,0,40,4449,50.0549,49802.15234375,,,,,,,,,,,,,0,,,,-0.0049,,,,,,50.0014839,,,,
,19799439.965,49.9990082,55638.423828125,-0.000216003175848943,7.39233205662882E-7,1,0.999253354069792,40.0298881530762,1.99437494990417,14.2400003969669,-0.00245331823503422,-0.000378734592722148,0.25,5.33087116965586E-6,-0.000216535769288802,3.83874195021704E-6,49.9990082,49.9990082,55633.59765625,55643.25,53.6087736199672,19.5316887683133,21.01075,0,0,0,40,4449,50.0542,55638.423828125,,,,,,,,,,,,,0,,,,-0.00245,,,,,,49.9990082,,,,
,19799557.595,49.9999084,61518.25390625,-0.00025148037002034,1.09807682236599E-6,1,0.999253354069792,40.0298881530762,1.99421361254596,14.2400003969669,-0.00285215047928657,-0.000466806184262889,0.25,3.89962383739821E-6,-0.000252150327468192,2.18460216634126E-6,49.9999084,49.9999084,61510.74609375,61525.76171875,53.6838099578134,19.5336093350979,21.01075,0,0,0,40,4449,50.0555,61518.25390625,,,,,,,,,,,,,0,,,,0.00245,,,,,,49.9999084,,,,
,19799676.275,49.9989891,67451.05859375,-0.000285505395665243,7.45795562150066E-7,1,0.999253354069792,40.0298881530762,1.99438916645608,14.2400003969669,-0.00323949285803621,-0.000528087623016397,0.25,4.57639310059211E-6,-0.000286338708537701,2.66283638696826E-6,49.9989891,49.9989891,67443.5546875,67458.5625,53.7182016126595,19.5313240402599,21.01075,0,0,0,40,4449,50.05965,67451.05859375,,,,,,,,,,,,,0,,,,-0.00245,,,,,,49.9989891,,,,
,19799793.825,50.0006866,73325.66796875,-0.000319825801742815,1.05659686846317E-6,1,0.999253354069792,40.0298881530762,1.99414849856925,14.2400003969669,-0.00362555370801044,-0.000612716332301471,0.25,3.22665046873422E-6,-0.000320821453946264,1.11517209923004E-6,50.0006866,50.0006866,73315.96875,73335.3671875,53.7783870086403,19.5381491024935,20.631098,0,0,0,40,4449,50.05585,73325.66796875,,,,,,,,,,,,,0,,,,0,,,,,,50.0006866,,,,
,19799900.11,49.9981995,78638.0625,-0.000353401978825633,1.26978942718255E-6,1,0.999253354069792,40.0298881530762,1.99400662832207,14.2400003969669,-0.00400460905738074,-0.000688811142411881,0.25,2.49514121321271E-6,-0.000354566320193369,1.97019770888898E-7,49.9981995,49.9981995,78627.90625,78648.21875,53.8354458905442,19.537067829394,21.3904,0,0,0,40,4449,50.05785,78638.0625,,,,,,,,,,,,,0,,,,-0.0049,,,,,,49.9981995,,,,
,19800016.98,50.0013657,84480.953125,-0.000391396740273823,1.3633413396196E-6,1,0.999253354069792,40.0298881530762,1.99403587199203,14.2400003969669,-0.00444043989476249,-0.000738994180923316,0.25,4.84002501850885E-6,-0.000392781343959551,2.34935026325418E-6,50.0013657,50.0013657,84470.8671875,84491.0390625,53.7744788660441,19.5385651440046,21.01075,0,0,0,40,4449,50.05575,84480.953125,,,,,,,,,,,,,0,,,,0,,,,,,50.0013657,,,,
,19800119.085,50.0079918,89581.484375,-0.000421676867141031,1.15174920346228E-6,1,0.999253354069792,40.0298881530762,1.99394774251286,14.2400003969669,-0.00478720378596378,-0.000781633248075752,0.25,6.46235516840873E-6,-0.000423248739507573,3.82884081130224E-6,50.0079918,50.0079918,89579.0390625,89583.9296875,53.7330525545249,19.5390494657812,20.631098,0,0,0,40,4449,50.0514,89581.484375,,,,,,,,,,,,,0,,,,0.00245,,,,,,50.0079918,,,,
,19800238.22,50.0029755,85409.171875,-0.000405958755937431,8.02664646497237E-7,1,0.999253354069792,40.0298881530762,1.99416194144636,14.2400003969669,-0.00460686587746665,-0.00076210575807218,0.25,5.40578190484909E-6,-0.000407410002539006,2.83153265871223E-6,50.0029755,50.0029755,85404.0625,85414.28125,53.780731894198,19.5371379780784,21.01075,0,0,0,40,4449,50.04875,85409.171875,,,,,,,,,,,,,0,,,,0.00245,,,,,,50.0029755,,,,
,19800345.625,49.9946442,80037.6640625,-0.000380214969279444,9.3500176235131E-7,1,0.999253354069792,40.0298881530762,1.99408607982076,14.2400003969669,-0.00431570277117891,-0.000702765736060099,0.25,6.06387170785534E-6,-0.000381508938407993,3.61340403751869E-6,49.9946442,49.9946442,80025.234375,80050.09375,53.9268964272942,19.5385438534214,21.3904,0,0,0,40,4449,50.05395,80037.6640625,,,,,,,,,,,,,0,,,,0,,,,,,49.9946442,,,,
,19800456.375,50.0004005,74502.07421875,-0.000357663619190795,1.23174048317541E-6,1,0.999253354069792,40.0298881530762,1.99381010021476,14.2400003969669,-0.00405722541606773,-0.00066719174751159,0.25,5.18501026624839E-6,-0.00035880358930445,2.83707016042994E-6,50.0004005,50.0004005,74492.1171875,74512.03125,53.9284596843326,19.5420489855862,20.631098,0,0,0,40,4449,50.05255,74502.07421875,,,,,,,,,,,,,0,,,,0,,,,,,50.0004005,,,,
,19800566.415,49.9999809,69001.921875,-0.000328900297178373,1.15615374919447E-6,1,0.999253354069792,40.0298881530762,1.99425376079015,14.2400003969669,-0.00372993979789472,-0.000619050107889367,0.25,4.31662984633394E-6,-0.000329874064412071,2.1193985580179E-6,49.9999809,49.9999809,68989,69014.84375,53.7658809523326,19.5366452548675,20.631098,0,0,0,40,4449,50.04765,69001.921875,,,,,,,,,,,,,0,,,,0,,,,,,49.9999809,,,,
,19800679.245,49.9917526,63359.7109375,-0.000300552398321267,1.21253984578968E-6,1,0.999253354069792,40.0298881530762,1.99407472322835,14.2400003969669,-0.00340949341139959,-0.000553744838451261,0.25,5.017602111374E-6,-0.000301379916227407,2.97973924154687E-6,49.9917526,49.9917526,63357.26953125,63362.15234375,53.7494667534288,19.5432464986673,20.251448,0,0,0,40,4449,50.0673,63359.7109375,,,,,,,,,,,,,0,,,,0,,,,,,49.9917526,,,,
,19800790.41,49.9981384,57806.287109375,-0.000270228053385485,1.09877163701472E-6,1,0.999253354069792,40.0298881530762,1.99406808008096,14.2400003969669,-0.00306358171453085,-0.000504182944623253,0.25,3.97048035287781E-6,-0.000270902353773965,2.10834458277426E-6,49.9981384,49.9981384,57798.9453125,57813.62890625,53.9792655380826,19.5444391825212,20.631098,0,0,0,40,4449,50.05975,57806.287109375,,,,,,,,,,,,,0,,,,-0.0049,,,,,,49.9981384,,,,
,19800897.98,49.9974899,52428.99609375,-0.000239961246359167,8.94155828612965E-7,1,0.999253354069792,40.0298881530762,1.99402380839956,14.2400003969669,-0.0027212632120316,-0.000439016676381173,0.25,4.30698371484951E-6,-0.000240506337061123,2.63205114144401E-6,49.9973564,49.9976234,52426.4609375,52431.53125,53.8409172901788,19.5476132278901,20.631098,0,0,0,40,4449,50.06195,52428.99609375,,,,,,,,,,,,,0,,,,-0.00245,,,,,,49.9974899,,,,
,19801004.625,49.997963,47096.669921875,-0.000211638855565591,7.65164935254579E-7,1,0.999253354069792,40.0298881530762,1.99418390768717,14.2500000074506,-0.00239945957026401,-0.000388185183622188,0.25,3.72378594017424E-6,-0.000212065041878009,2.22737166160434E-6,49.997963,49.997963,47084.14453125,47109.1953125,53.8424805472172,19.5471485245001,21.01075,0,0,0,40,4449,50.0631,47096.669921875,,,,,,,,,,,,,0,,,,-0.0049,,,,,,49.997963,,,,
,19801111.25,49.9978905,41769.28125,-0.000183586822309551,9.32667795072808E-7,1,0.999253354069792,40.0298881530762,1.99414477044796,14.2400003969669,-0.00208066316155243,-0.000337559308568494,0.25,3.16321985363428E-6,-0.000183907236442401,1.84987125957056E-6,49.9978905,49.9978905,41756.71484375,41781.84765625,54.1480972982365,19.5454451643209,20.251448,0,0,0,40,4449,50.0623,41769.28125,,,,,,,,,,,,,0,,,,0.00245,,,,,,49.9978905,,,,
,19801218.68,49.9956818,36399.712890625,-0.000153174995145159,8.04354698105786E-7,1,0.999253354069792,40.0298881530762,1.99429767374563,14.2400003969669,-0.00173736149504619,-0.00027204213055107,0.25,3.49493468154683E-6,-0.000153406269335714,2.38891110466468E-6,49.9956818,49.9956818,36394.77734375,36404.6484375,54.1473156697173,19.5435894579039,20.631098,0,0,0,40,4449,50.0684,36399.712890625,,,,,,,,,,,,,0,,,,0,,,,,,49.9956818,,,,
,19801325.275,49.996727,31072.55078125,-0.000122720786093513,6.40359419829536E-7,1,0.999253354069792,40.0298881530762,1.99423410077862,14.2400003969669,-0.00139140177604413,-0.000218463629493135,0.25,2.75655894665232E-6,-0.000122871112539061,1.86227524911229E-6,49.996727,49.996727,31067.38671875,31077.71484375,53.963632967698,19.5436963000074,21.01075,0,0,0,40,4449,50.0704,31072.55078125,,,,,,,,,,,,,0,,,,0,,,,,,49.996727,,,,
,19801431.945,49.9956779,25737.537109375,-9.30358410093588E-5,6.81279286514348E-7,1,0.999253354069792,40.0298881530762,1.99426671898975,14.2400003969669,-0.00105515988846583,-0.000162185680419166,0.25,2.39471287276868E-6,-9.31252970381534E-5,1.7118233155476E-6,49.9956779,49.9956779,25730.123046875,25744.951171875,53.9925532229096,19.5458549653343,20.631098,0,0,0,40,4449,50.0773,25737.537109375,,,,,,,,,,,,,0,,,,0,,,,,,49.9956779,,,,
,19801535.6,49.9943314,20560.3388671875,-6.56021951654361E-5,6.5784717461787E-7,1,0.999253354069792,40.0298881530762,1.99410709109504,14.2400003969669,-0.000745681873802407,-0.00010362973048195,0.25,2.6384974642628E-6,-6.56536783662497E-5,2.15452918913657E-6,49.9943314,49.9943314,20547.689453125,20572.98828125,54.0910384163326,19.5504728223979,20.631098,0,0,0,40,4449,50.0766,20560.3388671875,,,,,,,,,,,,,0,,,,0,,,,,,49.9943314,,,,
,19801644.085,49.9950294,15138.7719726562,-3.65097976054836E-5,4.58747301791976E-7,1,0.999253354069792,40.0298881530762,1.99401800122217,14.2400003969669,-0.000416315002277505,-4.95657515199862E-5,0.25,2.18643853349285E-6,-3.65330532259898E-5,1.91582884105712E-6,49.9950294,49.9950294,15131.2294921875,15146.314453125,54.0988547015249,19.5511764963982,20.631098,0,0,0,40,4449,50.0835,15138.7719726562,,,,,,,,,,,,,0,,,,-0.0049,,,,,,49.9950294,,,,
,19801749.905,49.9965248,9849.576171875,-7.92375556764973E-6,3.54212216015083E-7,1,0.999253354069792,40.0298881530762,1.99406824461288,14.2400003969669,-9.27878755015252E-5,2.88088354099247E-6,0.25,1.68367003424045E-6,-7.93557740345396E-6,1.6245852457394E-6,49.9965248,49.9965248,9844.5498046875,9854.6025390625,53.8737456879865,19.5510963663336,20.251448,0,0,0,40,4449,50.08625,9849.576171875,,,,,,,,,,,,,0,,,,0.0049,,,,,,49.9965248,,,,
,19801855.82,49.9980011,4556.810546875,1.99918089614801E-5,3.06776448899177E-7,1,0.999253354069792,40.0298881530762,1.99403432451709,14.2500000074506,0.000224878585616236,4.3565272929308E-5,0.25,2.60306797433042E-7,1.99828780542075E-5,4.08988662153507E-7,49.9980011,49.9980011,4551.64892578125,4561.97216796875,54.1676380112173,19.5540323688095,20.631098,0,0,0,40,4449,50.0878,4556.810546875,,,,,,,,,,,,,0,,,,0,,,,,,49.9980011,,,,
,19801963.65,49.9978371,-833.038055419922,3.50943217795911E-5,3.164770125165E-7,1,0.999253354069792,40.0298881530762,1.99404591606255,14.2400003969669,0.000396614122110895,6.58533252331237E-5,0.25,-4.84298564190593E-7,3.50802678723478E-5,-2.22964760650119E-7,49.9978371,49.9978371,-840.235229492188,-825.840881347656,54.2692497187173,19.5540285711092,21.01075,0,0,0,40,4449,50.0897,-833.038055419922,,,,,,,,,,,,,0,,,,-0.0049,,,,,,49.9978371,,,,
,19802070.43,49.998951,-6165.60961914062,5.6747721159512E-5,3.01232692114129E-7,1,0.999253354069792,40.0298881530762,1.99420924353037,14.2400003969669,0.000641633588964402,0.000105917030732049,0.25,-8.36420042579103E-7,5.67384623968786E-5,-4.13902549406733E-7,49.998951,49.998951,-6170.494140625,-6160.72509765625,54.0160020784865,19.5509898161864,20.631098,0,0,0,40,4449,50.0903,-6165.60961914062,,,,,,,,,,,,,0,,,,-0.0049,,,,,,49.998951,,,,
,19802182.185,49.99746705,-11753.4174804687,7.86157876160458E-5,4.00465148560727E-7,1,0.999253354069792,40.0298881530762,1.99412594960874,14.2400003969669,0.000890019073613303,0.000141724056332567,0.25,-1.6052259561035E-6,7.86287803678575E-5,-1.0208273724789E-6,49.997448,49.9974861,-11758.162109375,-11748.6728515625,54.2606518050057,19.5532881502006,20.631098,0,0,0,40,4449,50.09315,-11753.4174804687,,,,,,,,,,,,,0,,,,0,,,,,,49.99746705,,,,
,19802292.25,49.9998894,-17255.41015625,9.03335244433609E-5,5.1650733221485E-7,1,0.999253354069792,40.0298881530762,1.99408173971292,14.2400003969669,0.00102493927792268,0.000151902623661733,0.25,-2.8165957287228E-6,9.03824650155293E-5,-2.14771460502808E-6,49.9998894,49.9998894,-17260.3046875,-17250.515625,54.1762359249288,19.5541736766366,20.631098,0,0,0,40,4449,50.0938,-17255.41015625,,,,,,,,,,,,,0,,,,0,,,,,,49.9998894,,,,
,19802400.01,49.9989548,-22642.416015625,0.000100263797318307,7.13181776191337E-7,1,0.999253354069792,40.0298881530762,1.99404826186314,14.2400003969669,0.00113874260537761,0.000164119910341703,0.25,-3.52406583479344E-6,0.000100350631973501,-2.78597754831642E-6,49.9989548,49.9989548,-22652.01953125,-22632.8125,54.3145841728327,19.5571143409671,20.631098,0,0,0,40,4449,50.09445,-22642.416015625,,,,,,,,,,,,,0,,,,0,,,,,,49.9989548,,,,
,19802508.995,49.9996567,-28086.75390625,0.000118025167216806,9.52528706561861E-7,1,0.999253354069792,40.0298881530762,1.99400271048637,14.2500000074506,0.00134122525674665,0.00019107934749377,0.25,-4.33483132913329E-6,0.000118163814644829,-3.47259174791941E-6,49.9996567,49.9996567,-28094.044921875,-28079.462890625,54.0300713918326,19.5544222624239,20.251448,0,0,0,40,4449,50.0963,-28086.75390625,,,,,,,,,,,,,0,,,,-0.00245,,,,,,49.9996567,,,,
,19802619.215,50.0006142,-33593.57421875,0.000140112371715732,1.00044170957677E-6,1,0.999253354069792,40.0298881530762,1.99411237726191,14.2400003969669,0.00158969089307166,0.0002440321928845,0.25,-3.62231932992848E-6,0.000140307121127622,-2.60626604941596E-6,50.0006142,50.0006142,-33596.2578125,-33590.890625,54.2239152646019,19.5536229323154,20.251448,0,0,0,40,4449,50.0946,-33593.57421875,,,,,,,,,,,,,0,,,,-0.0049,,,,,,50.0006142,,,,
,19802727.055,49.9996758,-38985.201171875,0.000169201000427981,1.05836471716229E-6,1,0.999253354069792,40.0298881530762,1.99422920266523,14.2400003969669,0.00192197663629597,0.00028588497071438,0.25,-5.15161841789863E-6,0.000169489527164519,-3.93809214698706E-6,49.9996758,49.9996758,-38992.8203125,-38977.58203125,54.2426743490634,19.555449337983,20.251448,0,0,0,40,4449,50.09565,-38985.201171875,,,,,,,,,,,,,0,,,,0,,,,,,49.9996758,,,,
,19802837.08,50.0003357,-44484.390625,0.000196700887269435,1.0504684103724E-6,1,0.999253354069792,40.0298881530762,1.99437259267156,14.2400003969669,0.00223162684105074,0.000351895651642864,0.25,-4.25411297222414E-6,0.00019707854526277,-2.8569592410423E-6,50.0002632,50.0004082,-44494.49609375,-44474.28515625,54.1606033545442,19.5546457294643,20.251448,0,0,0,40,4449,50.0952,-44484.390625,,,,,,,,,,,,,0,,,,0,,,,,,50.0003357,,,,
,19802943.695,49.999752,-49814.58984375,0.000226368274988695,9.07250756811252E-7,1,0.999253354069792,40.0298881530762,1.99430876471082,14.2400003969669,0.0025684480261897,0.000407007218647512,0.25,-4.70477286563419E-6,0.000226860363816843,-3.11634085531874E-6,49.999752,49.999752,-49821.75390625,-49807.42578125,54.2497090057365,19.5580574784019,20.631098,0,0,0,40,4449,50.09525,-49814.58984375,,,,,,,,,,,,,0,,,,-0.0049,,,,,,49.999752,,,,
,19803054.52,49.9995575,-55350.80859375,0.000255143705325055,1.50916233390194E-6,1,0.999253354069792,40.0298881530762,1.99414705225151,14.2400003969669,0.00289300873733999,0.000472491112602018,0.25,-4.07036469757834E-6,0.000255755764354509,-2.30214437878099E-6,49.9993477,49.9997673,-55363.45703125,-55338.16015625,54.329435114698,19.5583923152057,20.631098,0,0,0,40,4449,50.09555,-55350.80859375,,,,,,,,,,,,,0,,,,0.0049,,,,,,49.9995575,,,,
,19803173.6,50.0006676,-61302.216796875,0.000289906883494284,1.2830342265209E-6,1,0.999253354069792,40.0298881530762,1.99408362689891,14.2400003969669,0.0032844273777452,0.000556581204090632,0.25,-2.86168081996725E-6,0.000290667048596616,-8.8001097119281E-7,50.0006676,50.0006676,-61309.8515625,-61294.58203125,54.027726506275,19.5607009433925,20.251448,0,0,0,40,4449,50.094,-61302.216796875,,,,,,,,,,,,,0,,,,0,,,,,,50.0006676,,,,
,19803292.85,50.0009155,-67261.6328125,0.000321934668696482,1.65575040402652E-6,1,0.999253354069792,40.0298881530762,1.99425870419825,14.2400003969669,0.00365129744615041,0.000602683281497881,0.25,-4.51967563366652E-6,0.000322869026401685,-2.3596972467716E-6,50.0009155,50.0009155,-67271.734375,-67251.53125,54.5889357830827,19.5583776145539,20.251448,0,0,0,40,4449,50.0929,-67261.6328125,,,,,,,,,,,,,0,,,,0.00245,,,,,,50.0009155,,,,
,19803405.625,50.0010529,-72897.8046875,0.000351424570470921,1.11892900261125E-6,1,0.999253354069792,40.0298881530762,1.99442278406355,14.2400003969669,0.00398793217140495,0.000652721803707058,0.25,-5.36887412193035E-6,0.000352526547304434,-3.05215532841767E-6,50.0010529,50.0010529,-72907.8203125,-72887.7890625,54.1512238123134,19.5563722909765,20.251448,0,0,0,40,4449,50.0922,-72897.8046875,,,,,,,,,,,,,0,,,,0.00245,,,,,,50.0010529,,,,
,19803526.005,50.001133,-78913.90234375,0.000384058521951851,1.42203713089772E-6,1,0.999253354069792,40.0298881530762,1.99453267691427,14.2400003969669,0.00435347802590835,0.000746957054351717,0.25,-2.86802057781077E-6,0.000385330367667957,-3.74124416247743E-7,50.001133,50.001133,-78918.7109375,-78909.09375,54.2723762327942,19.5538009185057,20.251448,0,0,0,40,4449,50.0918,-78913.90234375,,,,,,,,,,,,,0,,,,0,,,,,,50.001133,,,,
,19803640.405,50.0005951,-84630.1640625,0.000414255317731116,1.19497609918011E-6,1,0.999253354069792,40.0298881530762,1.99439434678947,14.2400003969669,0.00470358669165851,0.000765748553066697,0.25,-6.58181479243847E-6,0.000415733930671434,-3.95305267236799E-6,50.0005951,50.0005951,-84630.1640625,-84630.1640625,54.5224973589481,19.5568860090816,20.251448,0,0,0,40,4449,50.0918,-84630.1640625,,,,,,,,,,,,,0,,,,-0.0049,,,,,,50.0005951,,,,
,19803775.14,49.9997787,-89704.05078125,0.000441949412397257,1.43964358156214E-6,1,0.999253354069792,40.0298881530762,1.99443670265565,14.2400003969669,0.00501491121586635,0.00083983714355267,0.25,-4.96690295285443E-6,0.000443589093125761,-2.20253063504681E-6,49.9997787,49.9997787,-89708.6953125,-89699.40625,54.1230851856211,19.5546638912379,20.251448,0,0,0,40,4449,50.091,-89704.05078125,,,,,,,,,,,,,0,,,,0,,,,,,49.9997787,,,,
,19803889.335,49.9978981,-84003.59765625,0.000410165254716727,1.45036693553799E-6,1,0.999253354069792,40.0298881530762,1.99454918947774,14.2400003969669,0.004647947550691,0.000810949156465298,0.25,-1.86586443888993E-6,0.000411590689657053,7.58336452145076E-7,49.9978981,49.9978981,-84016.1171875,-83991.078125,54.3802409684481,19.5511050123877,20.251448,0,0,0,40,4449,50.09435,-84003.59765625,,,,,,,,,,,,,0,,,,-0.0049,,,,,,49.9978981,,,,
,19804006.58,49.9972305,-78144.80078125,0.000376266555513505,1.60708236433098E-6,1,0.999253354069792,40.0298881530762,1.99458217754165,14.2400003969669,0.00426947934869649,0.00070757728203523,0.25,-4.95536064848221E-6,0.000377516214208956,-2.51319124107217E-6,49.9972305,49.9972305,-78160.1015625,-78129.5,54.0941649304096,19.5506831003771,20.251448,0,0,0,40,4449,50.0972,-78144.80078125,,,,,,,,,,,,,0,,,,-0.0049,,,,,,49.9972305,,,,
,19804126.275,49.9979248,-72163.3984375,0.00034546932287991,1.45286281956866E-6,1,0.999253354069792,40.0298881530762,1.9946838322212,14.2400003969669,0.00392090029134958,0.000640803945963425,0.25,-5.36401106114622E-6,0.000346543700885095,-3.08183516791089E-6,49.9979248,49.9979248,-72168.1015625,-72158.6953125,54.0472672192557,19.551855473017,20.251448,0,0,0,40,4449,50.10045,-72163.3984375,,,,,,,,,,,,,0,,,,0,,,,,,49.9979248,,,,
,19804244.495,49.9977417,-66254.5234375,0.000312948591450131,1.23278145699348E-6,1,0.999253354069792,40.0298881530762,1.99457666472943,14.2400003969669,0.00355305785562009,0.000567664688358904,0.25,-6.01342680365327E-6,0.00031385534766348,-3.91224794368209E-6,49.9977417,49.9977417,-66267.046875,-66242,54.058210018525,19.553337588851,20.251448,0,0,0,40,4449,50.10405,-66254.5234375,,,,,,,,,,,,,0,,,,-0.00245,,,,,,49.9977417,,,,
,19804363.85,49.9970551,-60290.349609375,0.000281191791446661,1.52480477982208E-6,1,0.999253354069792,40.0298881530762,1.99458463880237,14.2400003969669,0.00319510348228349,0.000491079256517201,0.25,-7.10171990260301E-6,0.000281947033787195,-5.18542127514413E-6,49.9970551,49.9970551,-60295.4296875,-60285.26953125,54.1887419812365,19.5551386222892,19.871798,0,0,0,40,4449,50.10715,-60290.349609375,,,,,,,,,,,,,0,,,,-0.00245,,,,,,49.9970551,,,,
,19804480.825,49.9984016,-54441.541015625,0.000246630335894283,1.59522993065177E-6,1,0.999253354069792,40.0298881530762,1.99455302459985,14.2400003969669,0.00279579508952117,0.00046300318586584,0.25,-3.38937944278448E-6,0.000247208378205405,-1.67511045395456E-6,49.9984016,49.9984016,-54444.140625,-54438.94140625,54.1121423863519,19.5558046176726,20.251448,0,0,0,40,4449,50.1072,-54441.541015625,,,,,,,,,,,,,0,,,,0,,,,,,49.9984016,,,,
,19804598.64,49.9988327,-48552.5625,0.000214155962314179,1.5523492737441E-6,1,0.999253354069792,40.0298881530762,1.99456690682399,14.2400003969669,0.00242992033479042,0.000385758985775321,0.25,-4.39464348904933E-6,0.000214608707656863,-2.88742677304792E-6,49.9988327,49.9988327,-48557.296875,-48547.828125,54.2598701764865,19.5587173871816,19.871798,0,0,0,40,4449,50.1094,-48552.5625,,,,,,,,,,,,,0,,,,-0.0049,,,,,,49.9988327,,,,
,19804716.89,49.9972,-42645.939453125,0.000184107269268057,1.00671777237341E-6,1,0.999253354069792,40.0298881530762,1.99455185448495,14.2400003969669,0.00208715051549455,0.000338222419220761,0.25,-3.20279425658657E-6,0.000184438926827006,-1.88874992763658E-6,49.9972,49.9972,-42651.109375,-42640.76953125,54.1606033545442,19.5543901991458,19.871798,0,0,0,40,4449,50.1133,-42645.939453125,,,,,,,,,,,,,0,,,,0,,,,,,49.9972,,,,
,19804833.665,49.9987984,-36806.9140625,0.000149936327601606,1.13565363664415E-6,1,0.999253354069792,40.0298881530762,1.99421737101834,14.2400003969669,0.00170008590030294,0.000269228822893923,0.25,-3.15958234189736E-6,0.000150165524989605,-2.07779593249101E-6,49.9987984,49.9987984,-36809.38671875,-36804.44140625,54.1223035571019,19.5591375378929,19.492144,0,0,0,40,4449,50.1138,-36806.9140625,,,,,,,,,,,,,0,,,,0,,,,,,49.9987984,,,,
,19804942.82,49.9985771,-31355.7666015625,0.000118999156610328,1.07014354194136E-6,1,0.999253354069792,40.0298881530762,1.99436374120248,14.2400003969669,0.00135244830913392,0.000194514172357312,0.25,-4.20803577486624E-6,0.000119159230108526,-3.34320609705988E-6,49.9985771,49.9985771,-31363.0546875,-31348.478515625,54.1434075271211,19.5538274626815,20.251448,0,0,0,40,4449,50.1155,-31355.7666015625,,,,,,,,,,,,,0,,,,-0.00245,,,,,,49.9985771,,,,
,19805051.215,49.9977951,-25938.126953125,8.94014619030163E-5,7.48340893591201E-7,1,0.999253354069792,40.0298881530762,1.99430864511552,14.2400003969669,0.00101717126256122,0.000138156200862618,0.25,-3.86870536981227E-6,8.95008369811164E-5,-3.21406989767478E-6,49.9977951,49.9977951,-25945.60546875,-25930.6484375,54.1527870693519,19.5550602283392,19.871798,0,0,0,40,4449,50.11695,-25938.126953125,,,,,,,,,,,,,0,,,,0.00245,,,,,,49.9977951,,,,
,19805159.885,49.996376,-20506.7548828125,6.15614065232644E-5,6.65854228192123E-7,1,0.999253354069792,40.0298881530762,1.99446113981965,14.2400003969669,0.000701177015820161,9.00447891759151E-5,0.25,-3.11551724979625E-6,6.16149928183793E-5,-2.66175921928083E-6,49.996376,49.996376,-20509.287109375,-20504.22265625,54.0840037596596,19.549671999967,20.251448,0,0,0,40,4449,50.1201,-20506.7548828125,,,,,,,,,,,,,0,,,,0.0049,,,,,,49.996376,,,,
,19805270.73,49.9992943,-14967.3994140625,3.25045716986661E-5,4.76051644607378E-7,1,0.999253354069792,40.0298881530762,1.99465300419153,14.2400003969669,0.00037206933717384,3.68623188966152E-5,0.25,-2.59165609245853E-6,3.25301179243236E-5,-2.35086527412774E-6,49.9992943,49.9992943,-14972.3974609375,-14962.4013671875,54.4193223944096,19.546363274855,19.871798,0,0,0,40,4449,50.12155,-14967.3994140625,,,,,,,,,,,,,0,,,,0,,,,,,49.9992943,,,,
,19805378.43,49.9988708,-9585.49267578125,5.35327410406134E-6,3.12469203579197E-7,1,0.999253354069792,40.0298881530762,1.99462393374502,14.2400003969669,6.50376178111021E-5,-1.48946408983445E-5,0.25,-2.28522731811339E-6,5.36978325352305E-6,-2.24520149663906E-6,49.9988708,49.9988708,-9590.3759765625,-9580.609375,53.8917231439288,19.5446866492648,19.492144,0,0,0,40,4449,50.1224,-9585.49267578125,,,,,,,,,,,,,0,,,,0,,,,,,49.9988708,,,,
,19805483.755,49.9993362,-4319.458984375,-2.12521721844392E-5,2.66393820290736E-7,1,0.999253354069792,40.0298881530762,1.99473717963002,14.2400003969669,-0.000236893224152422,-5.8771402162841E-5,0.25,-1.38002822021384E-6,-2.12344703060877E-5,-1.53769778060138E-6,49.9993362,49.9993362,-4327.005859375,-4311.912109375,54.2223520075634,19.5448835590209,20.251448,0,0,0,40,4449,50.1226,-4319.458984375,,,,,,,,,,,,,0,,,,-0.00245,,,,,,49.9993362,,,,
,19805593.215,50.000248,1152.00152587891,-3.41976279030727E-5,2.85865206181407E-7,1,0.999253354069792,40.0298881530762,1.99462695741171,14.2400003969669,-0.000385458042233678,-7.05046674275984E-5,0.25,-8.80408397922318E-8,-3.4180521089346E-5,-3.42434143397453E-7,50.000248,50.000248,1144.58728027344,1159.41577148438,54.0480488477749,19.5462619025666,20.251448,0,0,0,40,4449,50.12375,1152.00152587891,,,,,,,,,,,,,0,,,,0.00245,,,,,,50.000248,,,,
,19805705.675,49.999321,6769.83276367187,-5.69027618273193E-5,3.55964471195065E-7,1,0.999253354069792,40.0298881530762,1.99469976235034,14.2400003969669,-0.000642994426927843,-0.000109391252415866,0.25,5.58903885228116E-7,-5.68936574029419E-5,1.35353462505137E-7,49.999321,49.999321,6764.73974609375,6774.92578125,54.0863486452173,19.5439951865663,20.251448,0,0,0,40,4449,50.1232,6769.83276367187,,,,,,,,,,,,,0,,,,-0.00245,,,,,,49.999321,,,,
,19805821.425,49.9980812,12554.9775390625,-7.81027325857195E-5,4.84116504309703E-7,1,0.999253354069792,40.0298881530762,1.99500212564423,14.2400003969669,-0.000884429744909226,-0.000141960729287712,0.25,1.49746500031888E-6,-7.81189453665245E-5,9.17155623106695E-7,49.9980812,49.9980812,12542.5234375,12567.431640625,54.0394509340634,19.5401188400098,19.871798,0,0,0,40,4449,50.12365,12554.9775390625,,,,,,,,,,,,,0,,,,0,,,,,,49.9980812,,,,
,19805936.745,50,18319.2939453125,-8.93886932765609E-5,6.53828924910288E-7,1,0.999253354069792,40.0298881530762,1.99452045227101,14.2400003969669,-0.00101249923779132,-0.000161455247850491,0.25,1.80303446585555E-6,-8.94357873475058E-5,1.14150597203728E-6,50,50,18304.2890625,18334.298828125,53.9003210576403,19.5443483533182,20.251448,0,0,0,40,4449,50.12455,18319.2939453125,,,,,,,,,,,,,0,,,,-0.0049,,,,,,50,,,,
,19806050.795,50.0007782,24019.0361328125,-9.8123834813181E-5,9.16542491841284E-7,1,0.999253354069792,40.0298881530762,1.99429325264174,14.2400003969669,-0.00111214992726212,-0.00017459005321599,0.25,2.21272107413133E-6,-9.8207899079083E-5,1.49091230459002E-6,50.0007782,50.0007782,24016.54296875,24021.529296875,54.2895720602173,19.550939547558,19.871798,0,0,0,40,4449,50.1261,24019.0361328125,,,,,,,,,,,,,0,,,,0,,,,,,50.0007782,,,,
,19806164.415,50.0001183,29699.009765625,-0.00011761681621186,7.12150577578063E-7,1,0.999253354069792,40.0298881530762,1.99425162240226,14.2400003969669,-0.00133280871195992,-0.000213004707002509,0.25,2.32111639180457E-6,-0.000117751426628659,1.46221897622754E-6,50.0001183,50.0001183,29689.140625,29708.87890625,54.024599992198,19.5485948281148,19.871798,0,0,0,40,4449,50.1259,29699.009765625,,,,,,,,,,,,,0,,,,-0.00245,,,,,,50.0001183,,,,
,19806281.92,49.9997673,35570.634765625,-0.000141696437831833,9.79727677895235E-7,1,0.999253354069792,40.0298881530762,1.99447525932208,14.2400003969669,-0.00160901040018346,-0.00024192265151978,0.25,4.09689190196791E-6,-0.000141912311248159,3.07379123802447E-6,49.9997673,49.9997673,35565.55859375,35575.7109375,54.1918684953134,19.5449291464481,19.871798,0,0,0,40,4449,50.1255,35570.634765625,,,,,,,,,,,,,0,,,,0,,,,,,49.9997673,,,,
,19806400.09,50.0008583,41477.560546875,-0.000172198503900689,1.20723212524319E-6,1,0.999253354069792,40.0298881530762,1.99428167888756,14.2400003969669,-0.00195345941652718,-0.000306969292629176,0.25,3.82296021690383E-6,-0.000172504863997401,2.59237519002445E-6,50.0008583,50.0008583,41467.30859375,41487.8125,54.3192739439481,19.5486316626928,20.251448,0,0,0,40,4449,50.1241,41477.560546875,,,,,,,,,,,,,0,,,,0,,,,,,50.0008583,,,,
,19806511.415,50.0018845,47042.5234375,-0.000200684135005104,1.32409825989434E-6,1,0.999253354069792,40.0298881530762,1.99408582567902,14.2400003969669,-0.00227079971820199,-0.000392392986081916,0.25,1.3789585276625E-6,-0.000201074767347927,-4.34865501426517E-8,50.0018845,50.0018845,47030.08984375,47054.95703125,53.9308045698903,19.5491922766593,19.492144,0,0,0,40,4449,50.12275,47042.5234375,,,,,,,,,,,,,0,,,,0,,,,,,50.0018845,,,,
,19806618.905,50.0005379,52411.73046875,-0.000232080267154802,1.38223950950165E-6,1,0.999253354069792,40.0298881530762,1.99402191664061,14.2400003969669,-0.00262924212553705,-0.000439455912803477,0.25,2.85066567869373E-6,-0.000232600502707537,1.22875949878766E-6,50.0005379,50.0005379,52406.76953125,52416.69140625,54.1129240148711,19.5505004351912,19.871798,0,0,0,40,4449,50.1209,52411.73046875,,,,,,,,,,,,,0,,,,-0.0049,,,,,,50.0005379,,,,
,19806724.26,50.0019302,57676.84375,-0.000261726881037185,1.61259832759503E-6,1,0.999253354069792,40.0298881530762,1.99404458939615,14.2400003969669,-0.00296531951169586,-0.000498692093256076,0.25,2.92764637534984E-6,-0.000262374790813195,1.12237879248315E-6,50.0019302,50.0019302,57664.30859375,57689.37890625,53.6259694473903,19.5465615886702,20.251448,0,0,0,40,4449,50.12165,57676.84375,,,,,,,,,,,,,0,,,,0,,,,,,50.0019302,,,,
,19806830.86,50.0005245,63007.3203125,-0.000286353409442402,1.64512635638873E-6,1,0.999253354069792,40.0298881530762,1.99388838646864,14.2500000074506,-0.00324945999354047,-0.000519997512390313,0.25,5.44779944609365E-6,-0.000287144393737763,3.50707394422399E-6,50.0005035,50.0005455,62997.375,63017.265625,53.9620697106595,19.5505561922185,19.871798,0,0,0,40,4449,50.1202,63007.3203125,,,,,,,,,,,,,0,,,,0,,,,,,50.0005245,,,,
,19806939.72,50.0015373,68449.35546875,-0.000311714390463725,2.09011145400767E-6,1,0.999253354069792,40.0298881530762,1.99432114567872,14.2500000074506,-0.00353554073906566,-0.000584321575749723,0.25,4.3044629896617E-6,-0.000312634854145812,2.22076033664626E-6,50.0015373,50.0015373,68439.5390625,68459.171875,54.1004179585634,19.549675516657,19.871798,0,0,0,40,4449,50.11835,68449.35546875,,,,,,,,,,,,,0,,,,-0.00245,,,,,,50.0015373,,,,
,19807045.76,50.0019798,73749.328125,-0.00034413949319533,1.60017392803057E-6,1,0.999253354069792,40.0298881530762,1.994274446145,14.2500000074506,-0.00390071509575078,-0.000663746941235267,0.25,3.07922185859884E-6,-0.000345216579563945,8.10392596645763E-7,50.0019798,50.0019798,73746.7109375,73751.9453125,53.8080888923711,19.5482511475057,19.871798,0,0,0,40,4449,50.1152,73749.328125,,,,,,,,,,,,,0,,,,-0.00245,,,,,,50.0019798,,,,
,19807149.945,50.002388,78957.078125,-0.00036941756892873,1.67237840776549E-6,1,0.999253354069792,40.0298881530762,1.99417883926121,14.2400003969669,-0.00419630119004598,-0.000665504557830757,0.25,7.42792568705031E-6,-0.000370672959613382,5.04526174790723E-6,50.002388,50.002388,78954.484375,78959.671875,53.892504772448,19.5474037615405,20.251448,0,0,0,40,4449,50.1146,78957.078125,,,,,,,,,,,,,0,,,,0.00245,,,,,,50.002388,,,,
,19807256.98,50.0022736,84307.53515625,-0.000397001857910998,1.91995316078143E-6,1,0.999253354069792,40.0298881530762,1.99414598207998,14.2400003969669,-0.0044976712370332,-0.000786450158050575,0.25,1.65559398146632E-6,-0.000398385640591754,-8.81883237808667E-7,50.0022736,50.0022736,84302.484375,84312.5859375,53.7877665508711,19.5469048072457,20.251448,0,0,0,40,4449,50.1139,84307.53515625,,,,,,,,,,,,,0,,,,0,,,,,,50.0022736,,,,
,19807359.245,50.0023079,89418.328125,-0.000422946104128943,1.77165974801074E-6,1,0.999253354069792,40.0298881530762,1.99417975716596,14.2400003969669,-0.00479968416322476,-0.000797854361699834,0.25,5.26449881253329E-6,-0.000424515485745932,2.61891002618573E-6,50.0023079,50.0023079,89410.484375,89426.171875,54.0081857932942,19.5480922307633,19.871798,0,0,0,40,4449,50.1129,89418.328125,,,,,,,,,,,,,0,,,,-0.00245,,,,,,50.0023079,,,,
,19807473.805,49.9986801,85793.92578125,-0.000405809488254363,1.69485494961593E-6,1,0.999253354069792,40.0298881530762,1.9940124941691,14.2400003969669,-0.00460942995764796,-0.000736697262368681,0.25,7.61501282241741E-6,-0.000407282582815421,5.05458167182348E-6,49.9986801,49.9986801,85788.875,85798.9765625,53.9198617706211,19.5484174624472,19.112494,0,0,0,40,4449,50.11465,85793.92578125,,,,,,,,,,,,,0,,,,0,,,,,,49.9986801,,,,
,19807579.525,49.99795915,80506.171875,-0.000379676140481137,1.67771093609751E-6,1,0.999253354069792,40.0298881530762,1.99418750728543,14.2400003969669,-0.00431185251829542,-0.000690930298336417,0.25,7.0121125662105E-6,-0.000380983756475363,4.5737052536432E-6,49.9979286,49.9979897,80496.15625,80516.1875,54.2262601501596,19.5490980814885,20.251448,0,0,0,40,4449,50.1177,80506.171875,,,,,,,,,,,,,0,,,,0,,,,,,49.99795915,,,,
,19807683.695,49.9977951,75301.8203125,-0.000351890119308842,1.81023199473833E-6,1,0.999253354069792,40.0298881530762,1.99419126079554,14.2400003969669,-0.00399106518560556,-0.00066521123486669,0.25,4.3302084155242E-6,-0.000353020310427516,2.02514618147546E-6,49.9977951,49.9977951,75266.6484375,75336.9921875,54.0980730730057,19.5489616551692,19.871798,0,0,0,40,4449,50.1178,75301.8203125,,,,,,,,,,,,,0,,,,0.00245,,,,,,49.9977951,,,,
,19807791.96,49.99854465,69889.3671875,-0.000318419655088218,1.77217429292852E-6,1,0.999253354069792,40.0298881530762,1.99424669311652,14.2400003969669,-0.0036121073092908,-0.000594489062488655,0.25,4.60145696088219E-6,-0.000319379839872834,2.48273672408709E-6,49.9983749,49.9987144,69884.3359375,69894.3984375,54.078532360025,19.5492502501299,19.871798,0,0,0,40,4449,50.12,69889.3671875,,,,,,,,,,,,,0,,,,0,,,,,,49.99854465,,,,
,19807896.965,49.9975395,64639.1015625,-0.000292927254703165,1.60192569278641E-6,1,0.999253354069792,40.0298881530762,1.99442613016214,14.2400003969669,-0.00331815937736225,-0.000570999546336472,0.25,2.12600066593373E-6,-0.000293733250185018,1.40785309603002E-7,49.9975395,49.9975395,64636.66015625,64641.54296875,54.0941649304096,19.5504216272776,19.492144,0,0,0,40,4449,50.1216,64639.1015625,,,,,,,,,,,,,0,,,,0,,,,,,49.9975395,,,,
,19808002.285,49.9976234,59376.05078125,-0.000263270563454,1.5534160441264E-6,1,0.999253354069792,40.0298881530762,1.99438975348506,14.2400003969669,-0.00298411410741901,-0.000498490893231023,0.25,3.22529144818029E-6,-0.000263944255685476,1.41833975564549E-6,49.9976234,49.9976234,59363.484375,59388.6171875,54.014438821448,19.5495153058306,19.871798,0,0,0,40,4449,50.1241,59376.05078125,,,,,,,,,,,,,0,,,,-0.00245,,,,,,49.9976234,,,,
,19808108.21,49.9980164,54083.744140625,-0.000233688870343785,1.15254143162105E-6,1,0.999253354069792,40.0298881530762,1.99444708584675,14.2400003969669,-0.00264924778563845,-0.000436865889127823,0.25,3.3731246268953E-6,-0.000234234609366431,1.74798012494883E-6,49.9980164,49.9980164,54076.3359375,54091.15234375,54.271594604275,19.5546851402368,19.492144,0,0,0,40,4449,50.1256,54083.744140625,,,,,,,,,,,,,0,,,,0.00245,,,,,,49.9980164,,,,
,19808213.995,49.9990082,48796.24609375,-0.000205062789117142,8.99326753456498E-7,1,0.999253354069792,40.0298881530762,1.99432269442578,14.2400003969669,-0.00232652953672937,-0.000369218981428856,0.25,4.21788147169522E-6,-0.000205499455507311,2.77575347933538E-6,49.9990082,49.9990082,48793.81640625,48798.67578125,54.0714977033519,19.5555928678811,19.492144,0,0,0,40,4449,50.1266,48796.24609375,,,,,,,,,,,,,0,,,,-0.0049,,,,,,49.9990082,,,,
,19808317.915,49.99887465,43598.458984375,-0.000179673326474052,1.19145621278511E-6,1,0.999253354069792,40.0298881530762,1.99445450623801,14.2400003969669,-0.00203960684920705,-0.000314994580316568,0.25,4.45767465300695E-6,-0.000180015640957594,3.18033753942668E-6,49.9986496,49.9990997,43590.8515625,43606.06640625,54.3356881428519,19.5523998452914,19.492144,0,0,0,40,4449,50.1278,43598.458984375,,,,,,,,,,,,,0,,,,0,,,,,,49.99887465,,,,
,19808423.955,49.998127,38298.982421875,-0.000148627804570292,1.08156098228274E-6,1,0.999253354069792,40.0298881530762,1.99433558598897,14.2400003969669,-0.00169059116502225,-0.000238524416364257,0.25,5.64208770438824E-6,-0.000148885169186914,4.57657230266297E-6,49.998127,49.998127,38294.21484375,38303.75,54.2426743490634,19.5522048883549,19.492144,0,0,0,40,4449,50.1297,38298.982421875,,,,,,,,,,,,,0,,,,-0.0049,,,,,,49.998127,,,,
,19808527.865,49.9983826,33107.5859375,-0.000121288216470976,1.0978518418308E-6,1,0.999253354069792,40.0298881530762,1.9945544976134,14.2400003969669,-0.00137366382697915,-0.000226386397403826,0.25,1.7993837855297E-6,-0.000121444974390993,9.17761240035278E-7,49.9983826,49.9983826,33102.5,33112.671875,53.7142934700634,19.5529259853915,19.871798,0,0,0,40,4449,50.13115,33107.5859375,,,,,,,,,,,,,0,,,,-0.00245,,,,,,49.9983826,,,,
,19808632.725,49.99939915,27865.5478515625,-9.76298214703847E-5,9.71787892443164E-7,1,0.999253354069792,40.0298881530762,1.99449579843425,14.2400003969669,-0.00110585955590828,-0.000179490379429163,0.25,1.69118737035331E-6,-9.77303152999925E-5,9.76178158864318E-7,49.9992561,49.9995422,27860.90234375,27870.193359375,54.187178724198,19.5523528787365,19.871798,0,0,0,40,4449,50.13245,27865.5478515625,,,,,,,,,,,,,0,,,,0,,,,,,49.99939915,,,,
,19808743.025,49.9986877,22353.3896484375,-6.68229086388589E-5,8.75993689290831E-7,1,0.999253354069792,40.0298881530762,1.99447942346468,14.2400003969669,-0.000761774981732293,-9.45094873943228E-5,0.25,3.66812957192699E-6,-6.6890157332992E-5,3.1769488616367E-6,49.9986877,49.9986877,22348.20703125,22358.572265625,54.4333917077558,19.5536683246147,19.492144,0,0,0,40,4449,50.13335,22353.3896484375,,,,,,,,,,,,,0,,,,0.0049,,,,,,49.9986877,,,,
,19808852.22,49.9987526,16898.73828125,-3.98502710209619E-5,5.46069875247255E-7,1,0.999253354069792,40.0298881530762,1.99443701976253,14.2400003969669,-0.000454419928390305,-5.48226215414155E-5,0.25,2.32363335883696E-6,-3.98795767961417E-5,2.02885151994798E-6,49.9987526,49.9987526,16891.4921875,16905.984375,53.9300229413711,19.5572882275356,19.112494,0,0,0,40,4449,50.1359,16898.73828125,,,,,,,,,,,,,0,,,,0,,,,,,49.9987526,,,,
,19808963.24,49.9987812,11346.7607421875,-1.21809243033671E-5,4.82609410547068E-7,1,0.999253354069792,40.0298881530762,1.99443158494926,14.2400003969669,-0.000140281114022,-8.86646375930452E-6,0.25,1.40956400024699E-6,-1.21914613003997E-5,1.319014376418E-6,49.9986343,49.9989281,11334.373046875,11359.1484375,54.2121908368134,19.5573909380035,19.871798,0,0,0,40,4449,50.13595,11346.7607421875,,,,,,,,,,,,,0,,,,-0.00245,,,,,,49.9987812,,,,
,19809074.245,49.9984665,5799.55859375,1.48474578951594E-5,3.33919209179607E-7,1,0.999253354069792,40.0298881530762,1.99457776302409,14.2400003969669,0.000164681726564647,4.5604138652475E-5,0.25,1.36707947375679E-6,1.48331884500814E-5,1.47719028940479E-6,49.9984665,49.9984665,5792.212890625,5806.904296875,54.207501065698,19.5560046245458,19.492144,0,0,0,40,4449,50.1369,5799.55859375,,,,,,,,,,,,,0,,,,0,,,,,,49.9984665,,,,
,19809185.735,50.0001221,228.865661621094,3.549856062316E-5,2.7591882580307E-7,1,0.999253354069792,40.0298881530762,1.99465780141892,14.2400003969669,0.000401018695594352,6.81855006059269E-5,0.25,-3.52038867003692E-7,3.54832110600254E-5,-8.77656836852256E-8,49.9997063,50.0005379,223.67985534668,234.051467895508,54.1246484426596,19.554968105173,19.871798,0,0,0,40,4449,50.1368,228.865661621094,,,,,,,,,,,,,0,,,,-0.00245,,,,,,50.0001221,,,,
,19809300.045,49.9988708,-5484.82470703125,5.05781950237441E-5,3.96412466441447E-7,1,0.999253354069792,40.0298881530762,1.99452141858678,14.2400003969669,0.000571864721677743,9.4894204805855E-5,0.25,-7.02945659622351E-7,5.05687079213679E-5,-3.26356756782966E-7,49.9988708,49.9988708,-5494.91162109375,-5474.73779296875,54.0011511366211,19.5566758812728,19.871798,0,0,0,40,4449,50.1366,-5484.82470703125,,,,,,,,,,,,,0,,,,-0.00245,,,,,,49.9988708,,,,
,19809415.085,49.9998379,-11235.0009765625,7.18395073873743E-5,3.50404274174709E-7,1,0.999253354069792,40.0298881530762,1.99465208073547,14.2400003969669,0.000813640630158661,0.000128743688729317,0.25,-1.53740448187972E-6,7.18508876822573E-5,-1.00331152991067E-6,49.9996758,50,-11242.521484375,-11227.48046875,53.9089189713519,19.5571141332862,19.871798,0,0,0,40,4449,50.13745,-11235.0009765625,,,,,,,,,,,,,0,,,,0,,,,,,49.9998379,,,,
,19809530.365,50.0003815,-16994.265625,8.42713792784054E-5,6.74139517390388E-7,1,0.999253354069792,40.0298881530762,1.99459152057767,14.2500000074506,0.000956075950044602,0.000143479054242048,0.25,-2.47376188155975E-6,8.43157468221164E-5,-1.84970346562345E-6,50.0003815,50.0003815,-17004.26953125,-16984.26171875,54.3716430547365,19.5583753432656,19.492144,0,0,0,40,4449,50.13805,-16994.265625,,,,,,,,,,,,,0,,,,0.00245,,,,,,50.0003815,,,,
,19809645.86,50.0000725,-22766.1142578125,9.20188846790387E-5,7.65117492679027E-7,1,0.999253354069792,40.0298881530762,1.99459680329025,14.2400003969669,0.00104560320861421,0.000149509317803994,0.25,-3.33652878965448E-6,9.21010103263325E-5,-2.65947378755878E-6,50.0000725,50.0000725,-22771.337890625,-22760.890625,54.3990000529096,19.5574420006935,19.492144,0,0,0,40,4449,50.1378,-22766.1142578125,,,,,,,,,,,,,0,,,,0,,,,,,50.0000725,,,,
,19809761.145,50.00058365,-28530.2080078125,0.000108791012904573,9.45870399880768E-7,1,0.999253354069792,40.0298881530762,1.99441526751936,14.2400003969669,0.00123584953049739,0.000180199891464731,0.25,-3.63815602246383E-6,0.000108919885979178,-2.84381181691497E-6,50.0005112,50.0006561,-28537.380859375,-28523.03515625,54.2973883454096,19.5607157372465,19.871798,0,0,0,40,4449,50.1368,-28530.2080078125,,,,,,,,,,,,,0,,,,-0.00245,,,,,,50.00058365,,,,
,19809877.565,50.0009232,-34346.62890625,0.000134837638396283,7.71687645206703E-7,1,0.999253354069792,40.0298881530762,1.99439283003069,14.2400003969669,0.00153165988809386,0.000226366835483328,0.25,-4.2388990510374E-6,0.000135037196038549,-3.2636437857949E-6,50.0009232,50.0009232,-34359.25,-34334.0078125,53.9628513391788,19.5618679233915,19.492144,0,0,0,40,4449,50.1362,-34346.62890625,,,,,,,,,,,,,0,,,,0,,,,,,50.0009232,,,,
,19809991.16,50.0008392,-40023.09375,0.000160669534163339,1.19061852311391E-6,1,0.999253354069792,40.0298881530762,1.99450379144958,14.2400003969669,0.00182470993085726,0.000275458090644567,0.25,-4.54093334324925E-6,0.000160950867670305,-3.39090473790808E-6,50.0008392,50.0008392,-40030.66796875,-40015.51953125,54.241111092025,19.5613676349672,19.492144,0,0,0,40,4449,50.13465,-40023.09375,,,,,,,,,,,,,0,,,,0,,,,,,50.0008392,,,,
,19810106.25,50.0018501,-45774.9609375,0.000191107981002763,1.34911525299144E-6,1,0.999253354069792,40.0298881530762,1.99463015346324,14.2400003969669,0.00216840065263646,0.00034303922671427,0.25,-4.03316622483046E-6,0.000191487853055196,-2.67996100609153E-6,50.0018501,50.0018501,-45782.46875,-45767.453125,54.268468090198,19.5608646647769,19.492144,0,0,0,40,4449,50.13395,-45774.9609375,,,,,,,,,,,,,0,,,,0,,,,,,50.0018501,,,,
,19810222.965,50.0015831,-51609.279296875,0.000221237373914035,1.11811709837099E-6,1,0.999253354069792,40.0298881530762,1.99464695355769,14.2400003969669,0.0025139664493777,0.000380646668548871,0.25,-6.11538336221862E-6,0.00022174931471876,-4.57358468775832E-6,50.0015831,50.0015831,-51614.35546875,-51604.203125,54.1066709867173,19.5635931450062,19.871798,0,0,0,40,4449,50.1328,-51609.279296875,,,,,,,,,,,,,0,,,,-0.00245,,,,,,50.0015831,,,,
,19810332.72,50.0012741,-57093.326171875,0.000251546779958807,1.17240833091915E-6,1,0.999253354069792,40.0298881530762,1.99471709633883,14.2400003969669,0.00285267138047,0.000469180724030652,0.25,-3.72310228323066E-6,0.000252169573572397,-1.98769261001961E-6,50.0012741,50.0012741,-57096.02734375,-57090.625,54.177017553448,19.5620431836782,19.492144,0,0,0,40,4449,50.1305,-57093.326171875,,,,,,,,,,,,,0,,,,0.00245,,,,,,50.0012741,,,,
,19810439.725,50.0007477,-62439.900390625,0.000277428972567549,1.46872714600893E-6,1,0.999253354069792,40.0298881530762,1.99475776624308,14.2400003969669,0.00314683605914749,0.000518415837843344,0.25,-4.00566697278613E-6,0.000278180302422021,-2.11924172374905E-6,50.0007477,50.0007477,-62442.52734375,-62437.2734375,54.2317315497942,19.5636739354662,19.492144,0,0,0,40,4449,50.12995,-62439.900390625,,,,,,,,,,,,,0,,,,-0.00245,,,,,,50.0007477,,,,
,19810546.375,50.0015488,-67772.4765625,0.000303376216303126,1.42557434397278E-6,1,0.999253354069792,40.0298881530762,1.99471765565465,14.2400003969669,0.00344378019985583,0.000556251621853178,0.25,-5.30066819241081E-6,0.000304271593099543,-3.27196616490617E-6,50.0015488,50.0015488,-67784.828125,-67760.125,54.2911353172557,19.561648649385,19.112494,0,0,0,40,4449,50.1276,-67772.4765625,,,,,,,,,,,,,0,,,,0,,,,,,50.0015488,,,,
,19810653.115,50.0023422,-73103.578125,0.000330397201652752,1.23515702607523E-6,1,0.999253354069792,40.0298881530762,1.99474908048033,14.2400003969669,0.00375026354396008,0.000612008115948832,0.25,-5.2011480517537E-6,0.000331438371203286,-3.02568622157201E-6,50.0023422,50.0023422,-73111.0859375,-73096.0703125,54.2528355198134,19.5631866271487,19.112494,0,0,0,40,4449,50.12585,-73103.578125,,,,,,,,,,,,,0,,,,0.00245,,,,,,50.0023422,,,,
,19810759.275,50.0015182,-78410.25390625,0.000361560098414764,1.6577772620631E-6,1,0.999253354069792,40.0298881530762,1.99467765243289,14.2400003969669,0.00410463629198053,0.000669979087986072,0.25,-5.64079838163158E-6,0.000362771383299769,-3.29961578420616E-6,50.0015182,50.0015182,-78417.8125,-78402.6953125,54.3708614262173,19.5644281246447,19.112494,0,0,0,40,4449,50.1246,-78410.25390625,,,,,,,,,,,,,0,,,,0.00245,,,,,,50.0015182,,,,
,19810866.085,50.0013924,-83746.828125,0.000387563427548756,1.70339707088078E-6,1,0.999253354069792,40.0298881530762,1.99469950899442,14.2500000074506,0.00439756750108196,0.000735894642241078,0.25,-4.45069087679792E-6,0.000388925368699041,-1.9790474824431E-6,50.0013924,50.0013924,-83754.109375,-83739.546875,54.0918200448519,19.5646301865046,19.492144,0,0,0,40,4449,50.1239,-83746.828125,,,,,,,,,,,,,0,,,,0,,,,,,50.0013924,,,,
,19810968.125,50.0013351,-88848.5234375,0.000414673462777721,1.59820870052321E-6,1,0.999253354069792,40.0298881530762,1.99458562161801,14.2400003969669,0.00470102957496163,0.000813697644490247,0.25,-2.4014385814363E-6,0.000416187393334187,2.07106392936721E-7,50.0013351,50.0013351,-88851.015625,-88846.03125,54.0691528177942,19.5666323460647,19.492144,0,0,0,40,4449,50.1228,-88848.5234375,,,,,,,,,,,,,0,,,,0.0049,,,,,,50.0013351,,,,
,19810992.18,50.00120735,-89999.7109375,0.000418673834054815,1.7906387276153E-6,1,0.999253354069792,40.0298881530762,1.99471244681532,14.2400003969669,0.00475464562913884,0.000778068216508618,0.25,-6.26051477272053E-6,0.000420242326950681,-3.65090328398969E-6,50.0007782,50.0016365,-89999.71875,-89999.703125,54.3763328258519,19.5672708457845,19.871798,0,0,0,40,4417,50.12245,-89999.7109375,,,,,,,,,,,,,0,,,,0.00245,,,,,,50.00120735,,,,