File: data/doubleLayers/monolayer/ppms/DD205_4/ppms_cologne_data/DD205_4_KOELNPPMS_HYST_100OE_50K_3.DAT
[Header]
; VSM Data File (default extension .dat)
; Copyright (c) 2003-2013, Quantum Design, Inc. All rights reserved.
TITLE,
FILEOPENTIME,19811012.91,08/18/2018,7:02 am
BYAPP,VSM,2.0,2.0
INFO,PPMS VSM Option Release 1.4.10 Build 1,APPNAME
INFO,Quantum Design Linear Motor Servo Controller,MOTOR_MODULE_NAME
INFO,3101-100 M1,MOTOR_HW_VERSION
INFO,MMC1014,MOTOR_SERIAL_NUMBER
INFO,SRV No X-over 01.03.11,MOTOR_SOFTWARE_VERSION
INFO,Quantum Design VSM Detection Module,VSM_MODULE_NAME
INFO,3101-150 F0,VSM_HW_VERSION
INFO,VSM707,VSM_SERIAL_NUMBER
INFO,VSM No X-over 01.02.05 May 20 2008 13:51:47,VSM_SOFTWARE_VERSION
INFO,704,PREAMP_SERIAL_NUMBER
INFO,822,COIL_SERIAL_NUMBER
INFO,0,MOMENT_UNITS
INFO,,SAMPLE_MATERIAL
INFO,,SAMPLE_COMMENT
INFO,,SAMPLE_MASS
INFO,,SAMPLE_VOLUME
INFO,,SAMPLE_MOLECULAR_WEIGHT
INFO,,SAMPLE_SIZE
INFO,,SAMPLE_SHAPE
DATATYPE,COMMENT,1
DATATYPE,TIME,2
STARTUPAXIS,X,2
STARTUPAXIS,Y1,5
[Data]
Comment,Time Stamp (sec),Temperature (K),Magnetic Field (Oe),Moment (emu),M. Std. Err. (emu),Transport Action,Averaging Time (sec),Frequency (Hz),Peak Amplitude (mm),Center Position (mm),Coil Signal' (mV),Coil Signal" (mV),Range (mV),M. Quad. Signal (emu),M. Raw' (emu),M. Raw" (emu),Min. Temperature (K),Max. Temperature (K),Min. Field (Oe),Max. Field (Oe),Mass (grams),Motor Lag (deg),Pressure (Torr),VSM Status (code),Motor Status (code),Measure Status (code),Measure Count,PPMS Status (code),System Temp. (K),System Field (Oe),Sample Position (deg),Bridge 1 Resistance (ohms),Bridge 1 Excitation (에),Bridge 2 Resistance (ohms),Bridge 2 Excitation (에),Bridge 3 Resistance (ohms),Bridge 3 Excitation (에),Bridge 4 Resistance (ohms),Bridge 4 Excitation (에),Signal 1 Vin (V),Signal 2 Vin (V),Digital Inputs (code),Drive 1 Iout (mA),Drive 1 Ipower (W),Drive 2 Iout (mA),Drive 2 Ipower (W),Pressure (),Map 20 (),Map 21 (),Map 22 (),Map 23 (),Map 24 (),Map 25 (),Map 26 (),Map 27 (),Map 28 (),Map 29 ()
,19811486.41,49.9984283,-0.471936970949173,-3.4992641478305E-5,3.28064756845029E-7,1,0.999253354069792,40.0298881530762,1.99457886226229,14.2400003969669,-0.000394454418086872,-7.18298759756124E-5,0.25,-6.26016765374213E-8,-3.49743282952142E-5,-3.22897627505318E-7,49.9984283,49.9984283,-0.487160742282867,-0.456713199615479,54.0996363300442,19.5571472086468,19.112494,0,0,0,40,4417,50.14005,-0.471936970949173,,,,,,,,,,,,,0,,,,0,,,,,,49.9984283,,,,
,19811611.03,49.9990273,5312.47241210937,-4.98342626408603E-5,3.38226079435483E-7,1,0.999253354069792,40.0298881530762,1.99454938901745,14.2400003969669,-0.000562895520957674,-9.66126235712233E-5,0.25,4.16540377202131E-7,-4.98224892505093E-5,4.55661147317072E-8,49.9990273,49.9990273,5307.65185546875,5317.29296875,54.2692497187173,19.5582420263013,19.871798,0,0,0,40,4449,50.13885,5312.47241210937,,,,,,,,,,,,,0,,,,-0.00245,,,,,,49.9990273,,,,
,19811718.81,49.9991188,10700.12890625,-7.00931056232858E-5,5.93349211565769E-7,1,0.999253354069792,40.0298881530762,1.99463332992483,14.2400003969669,-0.00079289441209162,-0.000130816231647674,0.25,1.03860930185841E-6,-7.00989059970707E-5,5.1739336907418E-7,49.9990463,49.9991913,10694.98828125,10705.26953125,54.0136571929288,19.5566822532653,19.492144,0,0,0,40,4449,50.1418,10700.12890625,,,,,,,,,,,,,0,,,,0,,,,,,49.9991188,,,,
,19811828.155,49.9996414,16164.6494140625,-8.30604327447635E-5,6.8743950063646E-7,1,0.999253354069792,40.0298881530762,1.99450923423755,14.2400003969669,-0.000940559299475197,-0.000150836767760789,0.25,1.60278108185515E-6,-8.3094313862954E-5,9.8705787657144E-7,49.9996414,49.9996414,16157.1630859375,16172.1357421875,53.9722308814096,19.5568056697873,19.492144,0,0,0,40,4449,50.1418,16164.6494140625,,,,,,,,,,,,,0,,,,0,,,,,,49.9996414,,,,
,19811936.875,50.0006218,21598.8974609375,-8.84219302281794E-5,6.90365360897012E-7,1,0.999253354069792,40.0298881530762,1.99456660639827,14.2400003969669,-0.00100124441627254,-0.000162575463487724,0.25,1.53064075606228E-6,-8.84829203753621E-5,8.78212676021494E-7,50.0006218,50.0006218,21594.08203125,21603.712890625,53.9175168850634,19.5545703774158,19.871798,0,0,0,40,4449,50.1416,21598.8974609375,,,,,,,,,,,,,0,,,,0.0049,,,,,,50.0006218,,,,
,19812047.475,49.9999428,27126.962890625,-0.000104111781442755,8.78485189872184E-7,1,0.999253354069792,40.0298881530762,1.99453688221257,14.2400003969669,-0.00118187525481553,-0.000176884356004312,0.25,3.09001796073495E-6,-0.00010422444380045,2.32792590581104E-6,49.9999428,49.9999428,27121.998046875,27131.927734375,54.2020296660634,19.5549390766359,19.112494,0,0,0,40,4449,50.1408,27126.962890625,,,,,,,,,,,,,0,,,,-0.0049,,,,,,49.9999428,,,,
,19812155.02,50.0017014,32501.3955078125,-0.000122960981172734,7.62688685341225E-7,1,0.999253354069792,40.0298881530762,1.99452394392472,14.2400003969669,-0.00139788897059715,-0.000199831952618418,0.25,4.45151952803643E-6,-0.000123135330940099,3.55994654564781E-6,50.0017014,50.0017014,32493.80859375,32508.982421875,54.1152689004288,19.5550692769213,19.871798,0,0,0,40,4449,50.1395,32501.3955078125,,,,,,,,,,,,,0,,,,-0.00245,,,,,,50.0017014,,,,
,19812263.695,50.0008888,37930.75,-0.000149493710234071,1.03409653776638E-6,1,0.999253354069792,40.0298881530762,1.99457328164441,14.2400003969669,-0.00169630723207735,-0.00026381181823405,0.25,3.56254516317081E-6,-0.000149734754649525,2.48705043130101E-6,50.0008888,50.0008888,37925.77734375,37935.72265625,54.0511753618519,19.556593638724,19.112494,0,0,0,40,4449,50.13855,37930.75,,,,,,,,,,,,,0,,,,-0.00245,,,,,,50.0008888,,,,
,19812373.085,50.0001984,43400.294921875,-0.000176508352399993,1.03580774203695E-6,1,0.999253354069792,40.0298881530762,1.9945462230709,14.2400003969669,-0.00200134675858456,-0.00032281769494357,0.25,3.19738545957602E-6,-0.000176834774039209,1.94007528256614E-6,50.0001984,50.0001984,43392.72265625,43407.8671875,54.1223035571019,19.5535664077999,19.492144,0,0,0,40,4449,50.13725,43400.294921875,,,,,,,,,,,,,0,,,,0,,,,,,50.0001984,,,,
,19812484.455,50.0020866,48968.146484375,-0.000206063586119493,1.19298658677424E-6,1,0.999253354069792,40.0298881530762,1.99458638665934,14.2400003969669,-0.00233222820188107,-0.000404289734979239,0.25,1.29944446632003E-6,-0.000206483681250585,-1.54851925492088E-7,50.0020866,50.0020866,48960.6953125,48975.59765625,53.9011026861596,19.5535509201735,19.871798,0,0,0,40,4449,50.1364,48968.146484375,,,,,,,,,,,,,0,,,,0,,,,,,50.0020866,,,,
,19812595.76,50.0015221,54530.3984375,-0.000234210934605607,1.28645559429876E-6,1,0.999253354069792,40.0298881530762,1.99448297703236,14.2400003969669,-0.00266212793776043,-0.000399714450900537,0.25,6.7519921348578E-6,-0.000234786681870136,5.13285674357622E-6,50.0015221,50.0015221,54527.8125,54532.984375,53.7041322993134,19.5559815469691,19.112494,0,0,0,40,4449,50.1366,54530.3984375,,,,,,,,,,,,,0,,,,0,,,,,,50.0015221,,,,
,19812703.4,50.00057605,59910.0546875,-0.000263402179857677,1.34932236392502E-6,1,0.999253354069792,40.0298881530762,1.99434586681622,14.2400003969669,-0.00298805911242536,-0.00048515788750723,0.25,4.42520902221785E-6,-0.000264091143269319,2.6231820385635E-6,50.0004845,50.0006676,59879.80078125,59940.30859375,54.2520538912942,19.5549602455491,19.492144,0,0,0,40,4449,50.1358,59910.0546875,,,,,,,,,,,,,0,,,,-0.0049,,,,,,50.00057605,,,,
,19812814.595,50.0011978,65467.701171875,-0.000294531724062092,1.3826500712558E-6,1,0.999253354069792,40.0298881530762,1.9944376093679,14.2400003969669,-0.00334882568191351,-0.000505358601765797,0.25,8.21336805090424E-6,-0.000295394129760088,6.23887087752025E-6,50.0011978,50.0011978,65462.6640625,65472.73828125,54.1340279848903,19.5550544052556,19.492144,0,0,0,40,4449,50.1343,65467.701171875,,,,,,,,,,,,,0,,,,-0.00245,,,,,,50.0011978,,,,
,19812924.85,50.00220105,70979.75,-0.000321380839472738,1.91184254871867E-6,1,0.999253354069792,40.0298881530762,1.99443910732552,14.2400003969669,-0.00364729246031542,-0.000593995582965191,0.25,5.17646480791328E-6,-0.000322367949001244,3.04694983128582E-6,50.0019035,50.0024986,70974.7578125,70984.7421875,54.2114092082942,19.5554824975692,19.492144,0,0,0,40,4449,50.1318,70979.75,,,,,,,,,,,,,0,,,,0.00245,,,,,,50.00220105,,,,
,19813035.655,50.0008621,76520.296875,-0.000351821350311594,1.6169849165629E-6,1,0.999253354069792,40.0298881530762,1.9943128828658,14.2400003969669,-0.00399540790931391,-0.000638929200871762,0.25,6.63720680860745E-6,-0.000352983171013224,4.34904723060711E-6,50.0008621,50.0008621,76512.6875,76527.90625,54.1019812156019,19.555802030002,19.492144,0,0,0,40,4449,50.1302,76520.296875,,,,,,,,,,,,,0,,,,-0.0049,,,,,,50.0008621,,,,
,19813147.15,50.0004578,82090.55859375,-0.000379912759313639,1.64538856822593E-6,1,0.999253354069792,40.0298881530762,1.99435916399532,14.2500000074506,-0.00430478025681094,-0.000749273099431178,0.25,1.89675077130319E-6,-0.000381210057865631,-5.47483580137825E-7,50.0004578,50.0004578,82080.6328125,82100.484375,54.0308530203519,19.5539995530999,19.492144,0,0,0,40,4449,50.1291,82090.55859375,,,,,,,,,,,,,0,,,,0.00245,,,,,,50.0004578,,,,
,19813255.075,50.0015373,87485.83203125,-0.000411020025364622,1.65338375506187E-6,1,0.999253354069792,40.0298881530762,1.99433537291608,14.2400003969669,-0.0046659602927335,-0.00076667196040443,0.25,5.90008672330884E-6,-0.000412524489975977,3.31551114502012E-6,50.0015373,50.0015373,87483.328125,87488.3359375,54.2520538912942,19.5552472357908,19.492144,0,0,0,40,4449,50.128,87485.83203125,,,,,,,,,,,,,0,,,,0,,,,,,50.0015373,,,,
,19813379.625,49.9985657,87328.56640625,-0.000406937109261727,1.48066336625498E-6,1,0.999253354069792,40.0298881530762,1.99434301884284,14.2400003969669,-0.00461469234947687,-0.000786477388661436,0.25,3.42097839687449E-6,-0.000408409160289212,8.52099665797744E-7,49.9985657,49.9985657,87323.34375,87333.7890625,53.9823920521596,19.554515017779,19.871798,0,0,0,40,4449,50.1282,87328.56640625,,,,,,,,,,,,,0,,,,-0.0049,,,,,,49.9985657,,,,
,19813486.385,49.998539,81993.21875,-0.000382326236912928,1.91244488701641E-6,1,0.999253354069792,40.0298881530762,1.99436128758061,14.2400003969669,-0.00434098791858692,-0.000704531635599894,0.25,6.28199658334542E-6,-0.000383658711602981,3.83626136595007E-6,49.998539,49.998539,81985.703125,82000.734375,53.9863001947557,19.5551536026212,19.871798,0,0,0,40,4449,50.1298,81993.21875,,,,,,,,,,,,,0,,,,0,,,,,,49.998539,,,,
,19813595.585,49.998394,76534.83984375,-0.000352743508084311,1.64004741455254E-6,1,0.999253354069792,40.0298881530762,1.9943770470703,14.2400003969669,-0.00400409248787804,-0.000651296027611649,0.25,5.71158111348648E-6,-0.00035390244336704,3.41456530081063E-6,49.998394,49.998394,76532.2578125,76537.421875,54.169982896775,19.5556506039154,19.112494,0,0,0,40,4449,50.1315,76534.83984375,,,,,,,,,,,,,0,,,,-0.0049,,,,,,49.998394,,,,
,19813706.285,49.9984665,70999.11328125,-0.000321278934305939,1.52546562796961E-6,1,0.999253354069792,40.0298881530762,1.99436020269094,14.2400003969669,-0.00364778367566131,-0.00058385456454642,0.25,6.05228929216069E-6,-0.000322271893924379,3.9262023742434E-6,49.9984665,49.9984665,70989.203125,71009.0234375,54.2723762327942,19.5567438212787,19.492144,0,0,0,40,4449,50.1329,70999.11328125,,,,,,,,,,,,,0,,,,0,,,,,,49.9984665,,,,
,19813814.765,49.9981003,65579.09375,-0.000296442908341291,1.11848063344806E-6,1,0.999253354069792,40.0298881530762,1.99445930997172,14.2400003969669,-0.00336231492724679,-0.00055482784381639,0.25,4.18396950366932E-6,-0.000297284645453145,2.18613878172876E-6,49.9981003,49.9981003,65576.4609375,65581.7265625,54.1348096134096,19.5543641616037,19.492144,0,0,0,40,4449,50.135,65579.09375,,,,,,,,,,,,,0,,,,-0.0049,,,,,,49.9981003,,,,
,19813924.795,49.9981918,60078.865234375,-0.00026486746729595,1.43026221371328E-6,1,0.999253354069792,40.0298881530762,1.9944095759609,14.2400003969669,-0.00300140409900176,-0.000506752759336105,0.25,2.77995834570193E-6,-0.000265550758607636,9.64572481934662E-7,49.9981918,49.9981918,60074.02734375,60083.703125,54.1113607578326,19.5583733164109,19.492144,0,0,0,40,4449,50.13625,60078.865234375,,,,,,,,,,,,,0,,,,-0.00245,,,,,,49.9981918,,,,
,19814033.275,49.999218,54656.154296875,-0.000237766248312296,1.26865342493645E-6,1,0.999253354069792,40.0298881530762,1.99441315183405,14.2400003969669,-0.00269652071947343,-0.000438839196830199,0.25,3.92948387448795E-6,-0.000238331763104901,2.27972689457475E-6,49.999218,49.999218,54646.24609375,54666.0625,54.0699344463134,19.5602684943015,19.492144,0,0,0,40,4449,50.13805,54656.154296875,,,,,,,,,,,,,0,,,,0.00245,,,,,,49.999218,,,,
,19814142.465,49.99987605,49199.416015625,-0.000208591625377281,1.10089136545112E-6,1,0.999253354069792,40.0298881530762,1.99442713590287,14.2500000074506,-0.00237167905182164,-0.000348107215849533,0.25,6.72094186397589E-6,-0.00020905745585485,5.26044507547405E-6,49.9998169,49.9999352,49189.3671875,49209.46484375,54.1660747541788,19.5617775889571,19.492144,0,0,0,40,4449,50.1378,49199.416015625,,,,,,,,,,,,,0,,,,0,,,,,,49.99987605,,,,
,19814251.515,49.9994583,43746.73046875,-0.000180827595454496,1.2254932754631E-6,1,0.999253354069792,40.0298881530762,1.99445332244808,14.2400003969669,-0.00204584876233903,-0.000355256029319742,0.25,1.10258668830376E-6,-0.000181149679418798,-1.88280161730796E-7,49.9994583,49.9994583,43741.703125,43751.7578125,53.7361790686018,19.5599874924836,19.492144,0,0,0,40,4449,50.1394,43746.73046875,,,,,,,,,,,,,0,,,,-0.00245,,,,,,49.9994583,,,,
,19814360.23,49.9993172,38312.4453125,-0.000150897226171336,9.40619357218498E-7,1,0.999253354069792,40.0298881530762,1.99445102031167,14.2400003969669,-0.00171138098071355,-0.000270644822462621,0.25,3.2087438035922E-6,-0.000151140764985589,2.12340805864601E-6,49.9993172,49.9993172,38300.16796875,38324.72265625,54.0160020784865,19.5614174811911,19.492144,0,0,0,40,4449,50.1401,38312.4453125,,,,,,,,,,,,,0,,,,-0.0049,,,,,,49.9993172,,,,
,19814470.42,49.9987049,32808.388671875,-0.000122471922805709,1.23796790621472E-6,1,0.999253354069792,40.0298881530762,1.99445946200358,14.2400003969669,-0.00139034952225225,-0.000209919071127708,0.25,3.46967840820219E-6,-0.000122640630310057,2.58102568124696E-6,49.9984131,49.9989967,32798.44140625,32818.3359375,54.4466793925827,19.5597576491073,19.112494,0,0,0,40,4449,50.14235,32808.388671875,,,,,,,,,,,,,0,,,,-0.0049,,,,,,49.9987049,,,,
,19814578.185,49.9984665,27421.474609375,-9.49880816230404E-5,1.03101386912135E-6,1,0.999253354069792,40.0298881530762,1.99456757610923,14.2400003969669,-0.00107629342369963,-0.00017273085668426,0.25,1.81448452141826E-6,-9.5085053939112E-5,1.11859526054645E-6,49.9984665,49.9984665,27411.44921875,27431.5,54.0238183636788,19.5608274261106,19.492144,0,0,0,40,4449,50.14265,27421.474609375,,,,,,,,,,,,,0,,,,0.00245,,,,,,49.9984665,,,,
,19814688.075,49.9998169,21931.23828125,-6.58644256822999E-5,7.86424837538094E-7,1,0.999253354069792,40.0298881530762,1.99461381266601,14.2400003969669,-0.000742942801681426,-0.00013721701535304,0.25,-2.87222141934156E-7,-6.59005699070959E-5,-7.73862201358124E-7,49.9998169,49.9998169,21923.431640625,21939.044921875,54.0746242174288,19.561118664518,19.871798,0,0,0,40,4449,50.14485,21931.23828125,,,,,,,,,,,,,0,,,,0.00245,,,,,,49.9998169,,,,
,19814797.065,49.9989967,16482.4677734375,-3.87701910751321E-5,6.59873287306126E-7,1,0.999253354069792,40.0298881530762,1.99455852789099,14.2400003969669,-0.000441961295762651,-5.42215504629752E-5,0.25,2.18250060782686E-6,-3.87973415882825E-5,1.89557473830447E-6,49.9989967,49.9989967,16477.322265625,16487.61328125,54.2606518050057,19.5634709746245,19.492144,0,0,0,40,4449,50.1444,16482.4677734375,,,,,,,,,,,,,0,,,,0.00245,,,,,,49.9989967,,,,
,19814903.78,49.9990807,11150.3657226562,-1.18116552546773E-5,4.43563004072823E-7,1,0.999253354069792,40.0298881530762,1.99459149553215,14.2400003969669,-0.000137029275338835,-3.09770158210123E-6,0.25,1.8543921673835E-6,-1.18254094404254E-5,1.76657206524762E-6,49.9990807,49.9990807,11145.2314453125,11155.5,54.3012964880057,19.5643155392263,19.492144,0,0,0,40,4449,50.1454,11150.3657226562,,,,,,,,,,,,,0,,,,-0.0049,,,,,,49.9990807,,,,
,19815011.865,49.9987869,5745.54052734375,1.46777436850379E-5,2.86311335669169E-7,1,0.999253354069792,40.0298881530762,1.99452445216683,14.2400003969669,0.00016462119179144,3.49518651678292E-5,0.25,4.53294587827357E-7,1.46703290580391E-5,5.623947626389E-7,49.9987869,49.9987869,5738.1337890625,5752.947265625,54.3364697713711,19.5653797654975,19.492144,0,0,0,40,4449,50.1469,5745.54052734375,,,,,,,,,,,,,0,,,,-0.00245,,,,,,49.9987869,,,,
,19815119.585,50.0007324,362.447067260742,3.5702441352507E-5,3.10700426553708E-7,1,0.999253354069792,40.0298881530762,1.99451776845637,14.2400003969669,0.000403009578588751,7.01700855580673E-5,0.25,-2.12424156513409E-7,3.56861803214088E-5,5.32991915275325E-8,50.0007324,50.0007324,359.98193359375,364.912200927734,54.3239637150634,19.5642668504542,19.492144,0,0,0,40,4449,50.1455,362.447067260742,,,,,,,,,,,,,0,,,,0,,,,,,50.0007324,,,,
,19815228.445,49.9998398,-5074.01220703125,4.89306376500335E-5,4.25492947422212E-7,1,0.999253354069792,40.0298881530762,1.99455822133683,14.2400003969669,0.000553545952085201,9.0088771191252E-5,0.25,-8.32063150768145E-7,4.89217640510449E-5,-4.67679942687197E-7,49.9998398,49.9998398,-5084.0439453125,-5063.98046875,54.1309014708134,19.5647551684728,19.112494,0,0,0,40,4449,50.1445,-5074.01220703125,,,,,,,,,,,,,0,,,,-0.00245,,,,,,49.9998398,,,,
,19815337.415,49.9982758,-10522.0375976562,6.94858312647856E-5,4.46609390902092E-7,1,0.999253354069792,40.0298881530762,1.99448150916442,14.2400003969669,0.000785941022872349,0.000129787634321353,0.25,-1.01942551613909E-6,6.94909732469212E-5,-5.0269646714652E-7,49.9982758,49.9982758,-10532.083984375,-10511.9912109375,54.3864939966019,19.5657128046704,19.492144,0,0,0,40,4449,50.1472,-10522.0375976562,,,,,,,,,,,,,0,,,,-0.00245,,,,,,49.9982758,,,,
,19815447.54,50.0007858,-16026.6748046875,8.24033414322261E-5,6.34822555727677E-7,1,0.999253354069792,40.0298881530762,1.99455311608559,14.2400003969669,0.000934348441796131,0.00014289859098166,0.25,-2.18804560271169E-6,8.24408879074094E-5,-1.57729840771056E-6,50.0007858,50.0007858,-16034.2568359375,-16019.0927734375,54.2778476324288,19.5680236316648,19.871798,0,0,0,40,4449,50.1467,-16026.6748046875,,,,,,,,,,,,,0,,,,0,,,,,,50.0007858,,,,
,19815558.095,50.0001335,-21550.4677734375,9.03173194886581E-5,6.20622229449648E-7,1,0.999253354069792,40.0298881530762,1.99469013735908,14.2400003969669,0.00102403918063212,0.000159004738974869,0.25,-2.18932332156629E-6,9.03841345630904E-5,-1.52324609985477E-6,50.0001335,50.0001335,-21560.1015625,-21540.833984375,54.0863486452173,19.567287843937,19.492144,0,0,0,40,4449,50.14705,-21550.4677734375,,,,,,,,,,,,,0,,,,0,,,,,,50.0001335,,,,
,19815668.68,50.0013542,-27077.52734375,0.000103264275552148,9.55950349180773E-7,1,0.999253354069792,40.0298881530762,1.99455018962881,14.2400003969669,0.00117183183825529,0.000177823022716669,0.25,-2.85431787685707E-6,0.000103374325843695,-2.09821955602193E-6,50.0013542,50.0013542,-27082.6875,-27072.3671875,54.4224489084865,19.5684005921075,19.492144,0,0,0,40,4449,50.1458,-27077.52734375,,,,,,,,,,,,,0,,,,0,,,,,,50.0013542,,,,
,19815777.07,50.0009422,-32494.5810546875,0.000123202500638529,1.10717262249481E-6,1,0.999253354069792,40.0298881530762,1.99459894369739,14.2400003969669,0.00139804341738046,0.000214906205478672,0.25,-3.16108676832988E-6,0.000123367817006915,-2.2662858902335E-6,50.0009422,50.0009422,-32504.65234375,-32484.509765625,54.3818042254865,19.5711645337635,19.112494,0,0,0,40,4449,50.1444,-32494.5810546875,,,,,,,,,,,,,0,,,,-0.00245,,,,,,50.0009422,,,,
,19815886.875,50.00078965,-37983.412109375,0.000148762999462843,1.07137505015704E-6,1,0.999253354069792,40.0298881530762,1.99453005455892,14.2400003969669,0.00168403068128999,0.000284497299020396,0.25,-1.59962491757041E-6,0.000148989374374671,-5.26731860930995E-7,50.0006027,50.0009766,-37985.76171875,-37981.0625,54.3560104843519,19.5705051688113,19.492144,0,0,0,40,4449,50.1436,-37983.412109375,,,,,,,,,,,,,0,,,,-0.0049,,,,,,50.00078965,,,,
,19815993.245,50.0011368,-43297.970703125,0.000176238897463851,1.22953683485095E-6,1,0.999253354069792,40.0298881530762,1.9945712321297,14.2400003969669,0.00199473388508773,0.000342188819539273,0.25,-1.43534382033464E-6,0.000176551566986271,-1.76730567328818E-7,50.0011368,50.0011368,-43328.21484375,-43267.7265625,54.4271386796019,19.5720126843655,19.112494,0,0,0,40,4449,50.14345,-43297.970703125,,,,,,,,,,,,,0,,,,0.00245,,,,,,50.0011368,,,,
,19816107.055,50.0017776,-48987.06640625,0.00020516835710966,1.07422049143205E-6,1,0.999253354069792,40.0298881530762,1.99462164633726,14.2400003969669,0.0023242760487538,0.000390659911861761,0.25,-2.34458475205193E-6,0.000205594416975926,-8.98824669769722E-7,50.0017776,50.0017776,-48994.6796875,-48979.453125,54.4779445333519,19.5727534646862,19.871798,0,0,0,40,4449,50.14085,-48987.06640625,,,,,,,,,,,,,0,,,,-0.00245,,,,,,50.0017776,,,,
,19816216.235,49.9998512,-54441.685546875,0.000231230896202548,1.14717773801692E-6,1,0.999253354069792,40.0298881530762,1.99443478993786,14.2400003969669,0.00262292584866093,0.000423886265309607,0.25,-4.07798051334217E-6,0.000231780534116303,-2.47332103002653E-6,49.9998512,49.9998512,-54451.62890625,-54431.7421875,54.2606518050057,19.5743185735999,19.871798,0,0,0,40,4449,50.1419,-54441.685546875,,,,,,,,,,,,,0,,,,0.00245,,,,,,49.9998512,,,,
,19816330.4,50.0013809,-60145.6640625,0.000259730977254243,1.61937861887292E-6,1,0.999253354069792,40.0298881530762,1.99441473703048,14.2400003969669,0.00294612127469201,0.000480758591978799,0.25,-4.1552962261741E-6,0.000260411758535379,-2.37909458762878E-6,50.0013809,50.0013809,-60153.37109375,-60137.95703125,54.4670017340827,19.5744361831936,19.492144,0,0,0,40,4449,50.14,-60145.6640625,,,,,,,,,,,,,0,,,,0,,,,,,50.0013809,,,,
,19816443.82,50.0014076,-65814.69921875,0.000291235054427398,1.40638894875544E-6,1,0.999253354069792,40.0298881530762,1.99450509214802,14.2400003969669,0.00330195624022503,0.00055287901107336,0.25,-3.42134210976185E-6,0.000292060387605998,-1.45815376656482E-6,50.0014076,50.0014076,-65824.90625,-65804.4921875,54.4216672799673,19.5758993230618,19.112494,0,0,0,40,4449,50.1398,-65814.69921875,,,,,,,,,,,,,0,,,,0,,,,,,50.0014076,,,,
,19816555.89,50.0028839,-71416.1015625,0.000320954877870406,1.07253736649816E-6,1,0.999253354069792,40.0298881530762,1.99463117939393,14.2400003969669,0.00364347946079322,0.000589808854857556,0.25,-5.47283305633513E-6,0.00032194843620611,-3.35000120865971E-6,50.0028839,50.0028839,-71421.1015625,-71411.1015625,54.3661716551019,19.5747603672392,19.871798,0,0,0,40,4449,50.1368,-71416.1015625,,,,,,,,,,,,,0,,,,0.0049,,,,,,50.0028839,,,,
,19816666.805,50.0012093,-76957.6328125,0.000351843139194453,1.35610252952933E-6,1,0.999253354069792,40.0298881530762,1.99455508634951,14.2400003969669,0.00398943282927374,0.000676715826420033,0.25,-3.30717629342528E-6,0.000352989192093628,-1.01158975634387E-6,50.0012093,50.0012093,-76962.5703125,-76952.6953125,54.4498059066596,19.5752159806859,19.492144,0,0,0,40,4449,50.13615,-76957.6328125,,,,,,,,,,,,,0,,,,0.0049,,,,,,50.0012093,,,,
,19816777.61,50.0010452,-82494.2890625,0.000379229139142621,1.2762563387245E-6,1,0.999253354069792,40.0298881530762,1.99458299051568,14.2500000074506,0.00430138074603196,0.000726680648929838,0.25,-3.77444142654345E-6,0.000380541823753057,-1.34426619865938E-6,50.0010452,50.0010452,-82499.21875,-82489.359375,54.2528355198134,19.5760085569468,19.492144,0,0,0,40,4449,50.13315,-82494.2890625,,,,,,,,,,,,,0,,,,0,,,,,,50.0010452,,,,
,19816885.655,50.00224305,-87898.23828125,0.000407316739460061,1.6536007425063E-6,1,0.999253354069792,40.0298881530762,1.99453360005909,14.2400003969669,0.00462584218298936,0.00075192794442567,0.25,-6.54260175436771E-6,0.000408817845924896,-3.9874946702674E-6,50.0021248,50.0023613,-87900.7265625,-87895.75,54.3028597450442,19.5763931639117,19.492144,0,0,0,40,4449,50.13265,-87898.23828125,,,,,,,,,,,,,0,,,,-0.00245,,,,,,50.00224305,,,,
,19817011.025,49.9984322,-86819.43359375,0.000404544471375177,1.58129721119632E-6,1,0.999253354069792,40.0298881530762,1.99450967853627,14.2400003969669,0.0045924200909495,0.000756386841293612,0.25,-5.65833072814694E-6,0.000406015500283547,-3.10838131857035E-6,49.9984322,49.9984322,-86824.4765625,-86814.390625,54.5037382744865,19.5749819915032,19.112494,0,0,0,40,4449,50.1333,-86819.43359375,,,,,,,,,,,,,0,,,,0,,,,,,49.9984322,,,,
,19817123.75,49.9990273,-81188.26953125,0.000377501218347823,1.68786826148463E-6,1,0.999253354069792,40.0298881530762,1.99462654986715,14.2400003969669,0.00427908803595106,0.00073778548891584,0.25,-2.49250849334156E-6,0.000378782313756876,-5.89364930833479E-8,49.9990273,49.9990273,-81193.359375,-81183.1796875,54.5490727286019,19.5709825549265,19.492144,0,0,0,40,4449,50.1347,-81188.26953125,,,,,,,,,,,,,0,,,,0.0049,,,,,,49.9990273,,,,
,19817236.31,49.9988403,-75561.0859375,0.000344819220186777,1.52284742192988E-6,1,0.999253354069792,40.0298881530762,1.99476995868246,14.2400003969669,0.00391175985573849,0.000653367367347045,0.25,-4.12306466708463E-6,0.000345930111014955,-1.86622154742834E-6,49.9988403,49.9988403,-75566.3828125,-75555.7890625,54.2653415761211,19.5708445564363,19.492144,0,0,0,40,4449,50.1363,-75561.0859375,,,,,,,,,,,,,0,,,,0.0049,,,,,,49.9988403,,,,
,19817347.12,49.9998627,-70024.9921875,0.000316243086751145,1.33527987262778E-6,1,0.999253354069792,40.0298881530762,1.99456733393961,14.2400003969669,0.00359193913857633,0.000568541486335177,0.25,-6.51103203373576E-6,0.000317212149139757,-4.4137115111583E-6,49.9998627,49.9998627,-70034.7421875,-70015.2421875,54.3763328258519,19.5749073336152,19.112494,0,0,0,40,4449,50.13685,-70024.9921875,,,,,,,,,,,,,0,,,,0.0049,,,,,,49.9998627,,,,
,19817458.97,49.9994278,-64433.423828125,0.000285354717613357,1.45953557898405E-6,1,0.999253354069792,40.0298881530762,1.99452053376819,14.2400003969669,0.00323273949013596,0.000554964674005416,0.25,-2.18635333441485E-6,0.000286138886541337,-2.51966118068374E-7,49.9994278,49.9994278,-64443.4296875,-64423.41796875,54.5451645860058,19.5750310256038,19.112494,0,0,0,40,4449,50.13795,-64433.423828125,,,,,,,,,,,,,0,,,,0,,,,,,49.9994278,,,,
,19817569.98,49.9967537,-58886.45703125,0.000255196450028281,1.16947814379009E-6,1,0.999253354069792,40.0298881530762,1.99453815704231,14.2400003969669,0.00289578248908857,0.000466331475875665,0.25,-4.62227486208593E-6,0.000255854955567064,-2.87237840650439E-6,49.9967537,49.9967537,-58896.6171875,-58876.296875,54.3966551673519,19.5730101401734,19.112494,0,0,0,40,4449,50.1402,-58886.45703125,,,,,,,,,,,,,0,,,,0,,,,,,49.9967537,,,,
,19817682.785,49.9992237,-53249.568359375,0.00022709439258925,1.22683514177604E-6,1,0.999253354069792,40.0298881530762,1.99470988911897,14.2400003969669,0.00257346805870222,0.000431544201386784,0.25,-2.66477690072745E-6,0.000227612319638831,-1.08105737841876E-6,49.9991722,49.9992752,-53254.96484375,-53244.171875,54.4208856514481,19.5696609067955,19.492144,0,0,0,40,4449,50.1419,-53249.568359375,,,,,,,,,,,,,0,,,,0.00245,,,,,,49.9992237,,,,
,19817793.805,49.9986115,-47700.509765625,0.000195864266133809,1.01045463031344E-6,1,0.999253354069792,40.0298881530762,1.99462271722265,14.2400003969669,0.00222053412025852,0.0003629373947683,0.25,-3.12544026049574E-6,0.000196265208757151,-1.74288899385149E-6,49.9986115,49.9986115,-47708.078125,-47692.94140625,54.1121423863519,19.5701821818183,19.492144,0,0,0,40,4449,50.14325,-47700.509765625,,,,,,,,,,,,,0,,,,-0.00245,,,,,,49.9986115,,,,
,19817905.54,49.9990273,-42116.955078125,0.000168743500965108,1.00376185692321E-6,1,0.999253354069792,40.0298881530762,1.99455847853151,14.2400003969669,0.00191543801526086,0.000296138371435478,0.25,-4.16241621238688E-6,0.000169052842639537,-2.95904058912841E-6,49.9990273,49.9990273,-42121.453125,-42112.45703125,54.2098459512557,19.5709617602812,19.112494,0,0,0,40,4449,50.1437,-42116.955078125,,,,,,,,,,,,,0,,,,0,,,,,,49.9990273,,,,
,19818017.06,49.99886515,-36542.11328125,0.00013915599672113,1.12203821401171E-6,1,0.999253354069792,40.0298881530762,1.9944907740358,14.2400003969669,0.00157675695208379,0.000257063787851439,0.25,-2.29874109160551E-6,0.000139363152057799,-1.29361724223501E-6,49.9986115,49.9991188,-36549.63671875,-36534.58984375,54.3825858540058,19.5685475502959,19.112494,0,0,0,40,4449,50.14435,-36542.11328125,,,,,,,,,,,,,0,,,,0,,,,,,49.99886515,,,,
,19818128.055,49.9986496,-30995.5859375,0.000112204242570555,7.92972295517533E-7,1,0.999253354069792,40.0298881530762,1.99463517498011,14.2400003969669,0.00127530220354358,0.000183822859521708,0.25,-3.93314992625077E-6,0.000112353570722632,-3.11735465103778E-6,49.9986496,49.9986496,-31003.142578125,-30988.029296875,54.2880088031788,19.5680706961655,19.492144,0,0,0,40,4449,50.14555,-30995.5859375,,,,,,,,,,,,,0,,,,0,,,,,,49.9986496,,,,
,19818238.75,49.9988785,-25461.5009765625,8.43515732079742E-5,8.22416667960128E-7,1,0.999253354069792,40.0298881530762,1.99458807783798,14.2400003969669,0.000958729133376988,0.000136459216895873,0.25,-3.11089288208479E-6,8.44398208180027E-5,-2.49251475613359E-6,49.9988785,49.9988785,-25466.44140625,-25456.560546875,54.0558651329673,19.5688859449141,19.871798,0,0,0,40,4449,50.1466,-25461.5009765625,,,,,,,,,,,,,0,,,,0,,,,,,49.9988785,,,,
,19818351.775,49.9985657,-19815.0087890625,5.49039767072003E-5,5.75878836939117E-7,1,0.999253354069792,40.0298881530762,1.99459121909086,14.2400003969669,0.00062341798951469,9.11409218315073E-5,0.25,-1.81919420491522E-6,5.49430145598281E-5,-1.41379390335369E-6,49.9985657,49.9985657,-19820.275390625,-19809.7421875,54.0503937333326,19.5676164042158,19.112494,0,0,0,40,4449,50.1481,-19815.0087890625,,,,,,,,,,,,,0,,,,0.0049,,,,,,49.9985657,,,,
,19818460.88,49.9995384,-14363.4506835938,2.73707917994928E-5,5.25152912311804E-7,1,0.999253354069792,40.0298881530762,1.99456601957074,14.2400003969669,0.000311938221118533,3.85040703156217E-5,0.25,-1.52073557436661E-6,2.73867110630523E-5,-1.31776203212814E-6,49.9995384,49.9995384,-14368.6455078125,-14358.255859375,54.2536171483327,19.5656513488541,19.871798,0,0,0,40,4449,50.1479,-14363.4506835938,,,,,,,,,,,,,0,,,,0,,,,,,49.9995384,,,,
,19818576.625,49.9988785,-8577.9853515625,-7.74430177122058E-7,4.03692631540036E-7,1,0.999253354069792,40.0298881530762,1.99450872808598,14.2400003969669,-5.32073137929885E-6,-2.05197495034356E-5,0.25,-1.67953760007897E-6,-7.61831542378937E-7,-1.6850727445216E-6,49.9988785,49.9988785,-8585.443359375,-8570.52734375,54.0613365326019,19.5684750644544,19.492144,0,0,0,40,4449,50.14945,-8577.9853515625,,,,,,,,,,,,,0,,,,-0.00245,,,,,,49.9988785,,,,
,19818691.495,49.9999237,-2835.24145507813,-2.82509257785391E-5,3.09809771394966E-7,1,0.999253354069792,40.0298881530762,1.99448192550407,14.2400003969669,-0.000316723571900235,-6.77204774914905E-5,0.25,-9.12999533793247E-7,-2.82326528998036E-5,-1.12285261465029E-6,49.9999237,49.9999237,-2842.91650390625,-2827.56640625,54.1824889530827,19.5677710892941,19.112494,0,0,0,40,4449,50.1501,-2835.24145507813,,,,,,,,,,,,,0,,,,0,,,,,,49.9999237,,,,
,19818803.11,50.0002098,2739.87194824219,-3.85996152359641E-5,3.06194729817948E-7,1,0.999253354069792,40.0298881530762,1.99465157265392,14.2400003969669,-0.000434922887997604,-8.06301116034455E-5,0.25,-1.91866587709055E-7,-3.85823540761343E-5,-4.79018191751835E-7,50.0002098,50.0002098,2724.955078125,2754.78881835938,54.2833190320634,19.5657355194842,19.492144,0,0,0,40,4449,50.15055,2739.87194824219,,,,,,,,,,,,,0,,,,0,,,,,,50.0002098,,,,
,19818916,49.9999428,8383.5859375,-6.18570416588498E-5,4.4728280904014E-7,1,0.999253354069792,40.0298881530762,1.99470479996192,14.2400003969669,-0.000698471248476624,-0.000122085837542322,0.25,3.27343732910975E-7,-6.18505352070433E-5,-1.32886512943734E-7,49.9999428,49.9999428,8373.400390625,8393.771484375,54.2426743490634,19.5629717862434,19.492144,0,0,0,40,4449,50.14905,8383.5859375,,,,,,,,,,,,,0,,,,0.00245,,,,,,49.9999428,,,,
,19819025.665,49.9991913,13864.0942382812,-7.81145984384597E-5,5.81054629913421E-7,1,0.999253354069792,40.0298881530762,1.99472470525006,14.2400003969669,-0.000883137720020457,-0.000149617195289151,0.25,8.20005366662309E-7,-7.81318349027742E-5,2.39979916605503E-7,49.9991913,49.9991913,13856.52734375,13871.6611328125,54.4052530810634,19.5664824908635,19.112494,0,0,0,40,4449,50.1495,13864.0942382812,,,,,,,,,,,,,0,,,,0,,,,,,49.9991913,,,,
,19819135.58,50.0008125,19358.4765625,-8.65358120763206E-5,7.23795980863553E-7,1,0.999253354069792,40.0298881530762,1.99477014975651,14.2400003969669,-0.000978860841845322,-0.000164674259880235,0.25,1.00576702229979E-6,-8.65814395814934E-5,3.65686680201835E-7,50.0008125,50.0008125,19353.642578125,19363.310546875,54.0879119022557,19.5631205594167,19.871798,0,0,0,40,4449,50.1496,19358.4765625,,,,,,,,,,,,,0,,,,-0.00245,,,,,,50.0008125,,,,
,19819245.255,50.0010681,24837.919921875,-9.64148532338829E-5,8.12238191257921E-7,1,0.999253354069792,40.0298881530762,1.99477379864519,14.2400003969669,-0.00109548861642573,-0.000158264352406614,0.25,3.35426250458279E-6,-9.65110087991212E-5,2.64670133883541E-6,50.0010681,50.0010681,24830.4296875,24845.41015625,54.078532360025,19.5599691707711,19.112494,0,0,0,40,4449,50.1483,24837.919921875,,,,,,,,,,,,,0,,,,0.0049,,,,,,50.0010681,,,,
,19819359.6,50.0006409,30555.142578125,-0.000116250634219527,8.48720233194479E-7,1,0.999253354069792,40.0298881530762,1.99472498957761,14.2400003969669,-0.00131836254010952,-0.000206876260426856,0.25,2.62171701010348E-6,-0.000116392083623621,1.77437554049978E-6,50.0006409,50.0006409,30548.072265625,30562.212890625,54.3036413735634,19.56021655404,19.112494,0,0,0,40,4449,50.1492,30555.142578125,,,,,,,,,,,,,0,,,,-0.00245,,,,,,50.0006409,,,,
,19819468.38,50.0005569,35992.7421875,-0.000141126041218072,1.08518226431991E-6,1,0.999253354069792,40.0298881530762,1.99462712910402,14.2400003969669,-0.00160154834706554,-0.000247330246915468,0.25,3.51677453411088E-6,-0.000141340768612374,2.4980230325954E-6,50.0005569,50.0005569,35985.30859375,36000.17578125,54.2731578613134,19.5601087676936,19.492144,0,0,0,40,4449,50.1474,35992.7421875,,,,,,,,,,,,,0,,,,0,,,,,,50.0005569,,,,
,19819579.91,50.0011597,41564.703125,-0.000168164113008922,1.15884066606033E-6,1,0.999253354069792,40.0298881530762,1.99471578712631,14.2400003969669,-0.00190805984853693,-0.000300101492203039,0.25,3.71003414619589E-6,-0.000168464694718859,2.50870590900025E-6,50.0011597,50.0011597,41556.8046875,41572.6015625,54.1707645252942,19.5615078295877,19.112494,0,0,0,40,4449,50.14755,41564.703125,,,,,,,,,,,,,0,,,,0,,,,,,50.0011597,,,,
,19819695.665,50.00133515,47351.970703125,-0.000196716008223275,1.51840682698078E-6,1,0.999253354069792,40.0298881530762,1.99475442166039,14.2400003969669,-0.00223265144788369,-0.000351431127711982,0.25,4.29897870695077E-6,-0.000197123715566773,2.91156508133241E-6,50.001133,50.0015373,47344.48828125,47359.453125,54.1918684953134,19.5606629299155,19.492144,0,0,0,40,4449,50.1466,47351.970703125,,,,,,,,,,,,,0,,,,-0.00245,,,,,,50.00133515,,,,
,19819807.5,50.0011177,52941.10546875,-0.000227310945912083,1.17923501570266E-6,1,0.999253354069792,40.0298881530762,1.99476189508087,14.2400003969669,-0.00258152196302026,-0.000400972040265003,0.25,5.40877495728949E-6,-0.000227845429015595,3.82836409667305E-6,50.0011177,50.0011177,52936.125,52946.0859375,53.8565498605634,19.5609500368885,19.112494,0,0,0,40,4449,50.14505,52941.10546875,,,,,,,,,,,,,0,,,,0,,,,,,50.0011177,,,,
,19819923.44,50.0011253,58735.935546875,-0.000256519764396811,1.37329956455314E-6,1,0.999253354069792,40.0298881530762,1.99471184285698,14.2400003969669,-0.00291270714569945,-0.00045941309072747,0.25,5.4754841897518E-6,-0.000257185871074035,3.71789749960266E-6,50.0011253,50.0011253,58733.34765625,58738.5234375,54.2192254934865,19.5605651225977,19.492144,0,0,0,40,4449,50.1445,58735.935546875,,,,,,,,,,,,,0,,,,0.00245,,,,,,50.0011253,,,,
,19820037.835,50.002243,64453.34375,-0.000284898382031812,1.32256232866883E-6,1,0.999253354069792,40.0298881530762,1.99472220998008,14.2400003969669,-0.00323255788709749,-0.000528114332831004,0.25,4.48213506158245E-6,-0.000285697354810469,2.55724066789922E-6,50.002243,50.002243,64445.76953125,64460.91796875,54.3982184243904,19.5600941171747,19.492144,0,0,0,40,4449,50.14245,64453.34375,,,,,,,,,,,,,0,,,,0,,,,,,50.002243,,,,
,19820154.2,50.0019417,70267.609375,-0.000316750052685646,1.66883931284969E-6,1,0.999253354069792,40.0298881530762,1.99477489230709,14.2400003969669,-0.00359990738785144,-0.000559388697410681,0.25,7.41464937320867E-6,-0.000317729785716821,5.31820610660255E-6,50.0019417,50.0019417,70257.703125,70277.515625,54.200466409025,19.5587279944796,19.492144,0,0,0,40,4449,50.1391,70267.609375,,,,,,,,,,,,,0,,,,0.00245,,,,,,50.0019417,,,,
,19820266.69,50.0010681,75890.62890625,-0.000348416498820041,1.55521715398346E-6,1,0.999253354069792,40.0298881530762,1.99467313881512,14.2400003969669,-0.00395834981385777,-0.000627181556558491,0.25,7.07717021047109E-6,-0.00034956254035242,4.80837765047655E-6,50.0010681,50.0010681,75885.71875,75895.5390625,54.2536171483327,19.5577223250683,19.112494,0,0,0,40,4449,50.1384,75890.62890625,,,,,,,,,,,,,0,,,,0.00245,,,,,,50.0010681,,,,
,19820381.83,50.0006332,81645.8671875,-0.000377449122601203,1.61758300882565E-6,1,0.999253354069792,40.0298881530762,1.99472165494939,14.2400003969669,-0.0042885694318277,-0.000683010905250718,0.25,7.32120183180558E-6,-0.00037876753098056,4.90788062624374E-6,50.0006332,50.0006332,81643.421875,81648.3125,53.8049623782942,19.5558555155599,19.112494,0,0,0,40,4449,50.13775,81645.8671875,,,,,,,,,,,,,0,,,,0,,,,,,50.0006332,,,,
,19820494.8,50.0010262,87293.3359375,-0.00040932511670837,1.474975614889E-6,1,0.999253354069792,40.0298881530762,1.99475405659546,14.2400003969669,-0.004651655187444,-0.000741156137116293,0.25,7.8641640532488E-6,-0.000410833719165631,5.29589127467373E-6,50.0010262,50.0010262,87286,87300.671875,54.146534041198,19.5572581957684,19.112494,0,0,0,40,4449,50.13625,87293.3359375,,,,,,,,,,,,,0,,,,-0.00245,,,,,,50.0010262,,,,
,19820627.4,50.0004272,87206.3359375,-0.00040640431897898,1.92218887883805E-6,1,0.999253354069792,40.0298881530762,1.99470331753003,14.2400003969669,-0.00461009271616257,-0.000781883006016134,0.25,3.74380945787554E-6,-0.000407875208905881,1.17864581440367E-6,50.0004272,50.0004272,87193.625,87219.046875,53.9691043673326,19.5575233880624,19.112494,0,0,0,40,4449,50.1366,87206.3359375,,,,,,,,,,,,,0,,,,0,,,,,,50.0004272,,,,
,19820746.055,49.9994545,81276.0625,-0.000376024714482825,1.50609084582E-6,1,0.999253354069792,40.0298881530762,1.9947074891629,14.2400003969669,-0.0042670031401254,-0.000709981759909308,0.25,4.68550584241926E-6,-0.000377316393796697,2.26962268558465E-6,49.9992943,49.9996147,81266.25,81285.875,54.0636814181596,19.5579732013649,19.492144,0,0,0,40,4449,50.13855,81276.0625,,,,,,,,,,,,,0,,,,0.00245,,,,,,49.9994545,,,,
,19820857.6,50.0023804,75697.75,-0.000346866000596721,1.65769167470439E-6,1,0.999253354069792,40.0298881530762,1.99478054648759,14.2400003969669,-0.00393629520828971,-0.000650134207906008,0.25,4.77539265503219E-6,-0.000347989340955439,2.5080737052617E-6,50.0023804,50.0023804,75693.0078125,75702.4921875,54.177017553448,19.5583668832783,19.871798,0,0,0,40,4449,50.1351,75697.75,,,,,,,,,,,,,0,,,,0.0049,,,,,,50.0023804,,,,
,19820967.57,50.0002251,70202.0390625,-0.000319133968460557,1.61549919197664E-6,1,0.999253354069792,40.0298881530762,1.99481876697132,14.2400003969669,-0.00361999434737286,-0.000603014080494761,0.25,3.98924895371233E-6,-0.000320096785489085,1.86629347149201E-6,50.0002251,50.0002251,70194.578125,70209.5,54.0394509340634,19.5568849835784,19.492144,0,0,0,40,4449,50.135,70202.0390625,,,,,,,,,,,,,0,,,,0.00245,,,,,,50.0002251,,,,
,19821077.56,49.9997787,64702.25,-0.000289659550556923,1.5017995946034E-6,1,0.999253354069792,40.0298881530762,1.99475664086032,14.2400003969669,-0.00328425564903258,-0.000550368769776016,0.25,3.37019905315797E-6,-0.000290466517074545,1.41117770744339E-6,49.9997787,49.9997787,64697.1328125,64707.3671875,53.9620697106595,19.5590832119041,19.492144,0,0,0,40,4449,50.1349,64702.25,,,,,,,,,,,,,0,,,,0,,,,,,49.9997787,,,,
,19821189,49.9983482,59131.595703125,-0.000262281348965796,1.61687205943547E-6,1,0.999253354069792,40.0298881530762,1.99480749813369,14.2400003969669,-0.0029718283013387,-0.000505854537408226,0.25,2.40596783103214E-6,-0.000262944706434313,6.02876506383651E-7,49.9983482,49.9983482,59124.22265625,59138.96875,54.291916945775,19.5592673516892,19.112494,0,0,0,40,4449,50.13805,59131.595703125,,,,,,,,,,,,,0,,,,0,,,,,,49.9983482,,,,
,19821299.085,49.9985504,53629.50390625,-0.000233656500085856,1.40384860847771E-6,1,0.999253354069792,40.0298881530762,1.99475652303472,14.2400003969669,-0.00265268081846544,-0.000417631074241367,0.25,5.07482029814578E-6,-0.000234209684837624,3.45199983666374E-6,49.9985504,49.9985504,53622.06640625,53636.94140625,54.302078116525,19.5603725840864,19.112494,0,0,0,40,4449,50.13835,53629.50390625,,,,,,,,,,,,,0,,,,-0.00245,,,,,,49.9985504,,,,
,19821406.58,49.9999619,48256.94921875,-0.000203408864274637,8.4572922151695E-7,1,0.999253354069792,40.0298881530762,1.99474448170472,14.2400003969669,-0.00230734475539047,-0.000370927940810392,0.25,3.77669135234584E-6,-0.00020383426601763,2.34370692081996E-6,49.9999619,49.9999619,48254.71484375,48259.18359375,54.2246968931211,19.5618127320707,19.112494,0,0,0,40,4449,50.1376,48256.94921875,,,,,,,,,,,,,0,,,,0,,,,,,49.9999619,,,,
,19821516.485,49.9993629,42764.615234375,-0.000174475014860765,1.13992628274502E-6,1,0.999253354069792,40.0298881530762,1.99482395742416,14.2400003969669,-0.00197732634598304,-0.000325609548032532,0.25,2.5890106073311E-6,-0.000174788047374709,1.34353938313347E-6,49.9993629,49.9993629,42761.82421875,42767.40625,54.0464855907365,19.5618046515492,19.492144,0,0,0,40,4449,50.1379,42764.615234375,,,,,,,,,,,,,0,,,,-0.00245,,,,,,49.9993629,,,,
,19821626.15,49.9990005,37285.595703125,-0.000146293415833828,9.20529108015716E-7,1,0.999253354069792,40.0298881530762,1.99484693213591,14.2400003969669,-0.00165990885210594,-0.000259561425228849,0.25,3.36608696925122E-6,-0.000146523566447237,2.31214474249557E-6,49.9990005,49.9990005,37270.4609375,37300.73046875,54.1582584689865,19.562731128408,19.112494,0,0,0,40,4449,50.13925,37285.595703125,,,,,,,,,,,,,0,,,,-0.00245,,,,,,49.9990005,,,,
,19821736.17,49.9982758,31783.6748046875,-0.000119104710559455,8.51071537227631E-7,1,0.999253354069792,40.0298881530762,1.99478375088369,14.2400003969669,-0.00134828512009895,-0.00022623664993102,0.25,1.4219774458414E-6,-0.000119247999669997,5.54067969181402E-7,49.9982758,49.9982758,31773.49609375,31793.853515625,53.8729640594672,19.5626655947628,19.871798,0,0,0,40,4449,50.141,31783.6748046875,,,,,,,,,,,,,0,,,,0,,,,,,49.9982758,,,,
,19821847.785,49.9971466,26206.3994140625,-9.02199996903235E-5,7.85869349141691E-7,1,0.999253354069792,40.0298881530762,1.9948613226232,14.2500000074506,-0.00102432842367199,-0.000153055383277039,0.25,2.70000078861609E-6,-9.03133432638152E-5,2.03877048096569E-6,49.9971466,49.9971466,26201.36328125,26211.435546875,54.1004179585634,19.5670228058857,19.871798,0,0,0,40,4449,50.1431,26206.3994140625,,,,,,,,,,,,,0,,,,-0.00245,,,,,,49.9971466,,,,
,19821959.275,49.9982033,20634.5166015625,-6.02048709534094E-5,7.7644729853534E-7,1,0.999253354069792,40.0298881530762,1.99483844201425,14.2400003969669,-0.000683594565732743,-0.000100646569244217,0.25,1.93340802095456E-6,-6.02498672504406E-5,1.4892162449951E-6,49.9982033,49.9982033,20629.9453125,20639.087890625,54.1738910393711,19.5657156724182,19.871798,0,0,0,40,4449,50.145,20634.5166015625,,,,,,,,,,,,,0,,,,-0.00245,,,,,,49.9982033,,,,
,19822067.57,49.9986572,15223.0166015625,-3.28297177433378E-5,5.94667531804223E-7,1,0.999253354069792,40.0298881530762,1.99482408390683,14.2400003969669,-0.000371929832601578,-5.88734162693791E-5,0.25,7.00181055664568E-7,-3.28419671608901E-5,4.56673014051557E-7,49.9986572,49.9986572,15212.8154296875,15233.2177734375,54.2012480375442,19.5659458193348,19.112494,0,0,0,40,4449,50.14565,15223.0166015625,,,,,,,,,,,,,0,,,,-0.00245,,,,,,49.9986572,,,,
,19822177.31,49.9983406,9738.69384765625,-5.26957327840015E-6,4.38593973548669E-7,1,0.999253354069792,40.0298881530762,1.99481644243235,14.2400003969669,-6.09178498314594E-5,-2.58936137746041E-6,0.25,7.20314148442674E-7,-5.27453005924265E-6,6.81067204444676E-7,49.9983406,49.9983406,9731.2744140625,9746.11328125,54.3638267695442,19.5668414326801,19.492144,0,0,0,40,4449,50.1464,9738.69384765625,,,,,,,,,,,,,0,,,,-0.0049,,,,,,49.9983406,,,,
,19822285.72,49.9993095,4320.9599609375,2.14340848123027E-5,3.82865910565193E-7,1,0.999253354069792,40.0298881530762,1.99484037850618,14.2400003969669,0.000241003843931478,4.77981942558485E-5,0.25,3.7409071134668E-7,2.14239704296551E-5,5.33469073944112E-7,49.9993095,49.9993095,4318.32470703125,4323.59521484375,53.9370575980442,19.5663935854995,19.112494,0,0,0,40,4449,50.1467,4320.9599609375,,,,,,,,,,,,,0,,,,-0.0049,,,,,,49.9993095,,,,
,19822393.15,50.0010147,-1047.92584228516,3.3681006127814E-5,2.59808225338072E-7,1,0.999253354069792,40.0298881530762,1.99482583166515,14.2400003969669,0.00037987625911268,6.83166349417078E-5,0.25,-1.34706732065585E-8,3.36650387004096E-5,2.37130417830384E-7,50.0010147,50.0010147,-1057.84216308594,-1038.00952148438,54.0535202474096,19.5652793495204,19.112494,0,0,0,40,4449,50.14755,-1047.92584228516,,,,,,,,,,,,,0,,,,0,,,,,,50.0010147,,,,
,19822501.96,49.9982948,-6485.87524414062,5.52564692707669E-5,3.60312770839806E-7,1,0.999253354069792,40.0298881530762,1.99484397261394,14.2400003969669,0.00062475609369055,0.000104426276860791,0.25,-7.02902938336374E-7,5.52484504344811E-5,-2.91559933520173E-7,49.9982948,49.9982948,-6493.67431640625,-6478.076171875,54.0941649304096,19.5696690973277,19.871798,0,0,0,40,4449,50.1463,-6485.87524414062,,,,,,,,,,,,,0,,,,0,,,,,,49.9982948,,,,
,19822610.5,50.0000534,-11908.7724609375,7.50940069381812E-5,5.03756216065098E-7,1,0.999253354069792,40.0298881530762,1.99485164156389,14.2400003969669,0.000850892953664347,0.000133047213066248,0.25,-1.74398373543422E-6,7.51097869793053E-5,-1.18589545246945E-6,50.0000534,50.0000534,-11916.2421875,-11901.302734375,54.5271871300635,19.569143836889,19.492144,0,0,0,40,4449,50.1464,-11908.7724609375,,,,,,,,,,,,,0,,,,0.00245,,,,,,50.0000534,,,,
,19822720.455,50.0000877,-17405.8017578125,8.64560044554278E-5,8.09360940288701E-7,1,0.999253354069792,40.0298881530762,1.99485429581582,14.2400003969669,0.000980902478694874,0.000147809117686357,0.25,-2.4855563858512E-6,8.65032699869216E-5,-1.84555302137855E-6,50.0000877,50.0000877,-17408.36328125,-17403.240234375,54.3208372009865,19.5687551745569,19.112494,0,0,0,40,4449,50.1463,-17405.8017578125,,,,,,,,,,,,,0,,,,-0.0049,,,,,,50.0000877,,,,
,19822828.25,50.0002708,-22792.884765625,9.52530633382621E-5,9.24229027019524E-7,1,0.999253354069792,40.0298881530762,1.99484366437084,14.2400003969669,0.00108500722448135,0.000140784792752598,0.25,-4.69356265389003E-6,9.53475967194068E-5,-3.99355276011603E-6,50.0002708,50.0002708,-22800.3359375,-22785.43359375,54.1981215234673,19.5691126356255,19.492144,0,0,0,40,4449,50.14705,-22792.884765625,,,,,,,,,,,,,0,,,,0.0049,,,,,,50.0002708,,,,
,19822937.945,50.000988,-28274.796875,0.000112051729879175,8.32694189654149E-7,1,0.999253354069792,40.0298881530762,1.994878420781,14.2400003969669,0.00127219873688416,0.000190964589168511,0.25,-3.27598084081988E-6,0.00011217968119796,-2.45711693997156E-6,50.000988,50.000988,-28277.216796875,-28272.376953125,54.2184438649673,19.5693755181079,19.492144,0,0,0,40,4449,50.1446,-28274.796875,,,,,,,,,,,,,0,,,,0.0049,,,,,,50.000988,,,,
,19823048.13,50.0011978,-33781.396484375,0.000132518584544697,1.03042074666804E-6,1,0.999253354069792,40.0298881530762,1.99488297481253,14.2400003969669,0.0015030111283986,0.000237051438402658,0.25,-2.88055513172886E-6,0.000132701619728407,-1.9195739151211E-6,50.0011978,50.0011978,-33783.8046875,-33778.98828125,54.3685165406596,19.5688439167132,19.492144,0,0,0,40,4449,50.1432,-33781.396484375,,,,,,,,,,,,,0,,,,0,,,,,,50.0011978,,,,
,19823160.735,50.0004272,-39407.669921875,0.000159933076597336,1.01053780362563E-6,1,0.999253354069792,40.0298881530762,1.99491620929241,14.2400003969669,0.00181786878533753,0.000267473112699638,0.25,-5.12029314114455E-6,0.000160212670570632,-3.97506782007571E-6,50.0004272,50.0004272,-39410.046875,-39405.29296875,54.3255269721019,19.5699344674663,19.871798,0,0,0,40,4449,50.142,-39407.669921875,,,,,,,,,,,,,0,,,,0,,,,,,50.0004272,,,,
,19823271.55,50.0016594,-44947.482421875,0.000189288866667402,1.41285970657899E-6,1,0.999253354069792,40.0298881530762,1.99484820383076,14.2400003969669,0.00214649991536556,0.000347575896528614,0.25,-3.30886634596615E-6,0.000189652744607757,-1.96488089021638E-6,50.0016594,50.0016594,-44952.41796875,-44942.546875,54.4998301318904,19.5708286948303,19.871798,0,0,0,40,4449,50.14015,-44947.482421875,,,,,,,,,,,,,0,,,,-0.0049,,,,,,50.0016594,,,,
,19823380.925,50.0010605,-50414.30859375,0.000220897877006722,1.10530856332008E-6,1,0.999253354069792,40.0298881530762,1.99486839355852,14.2400003969669,0.00250960865764001,0.000383577308888206,0.25,-5.80118832173964E-6,0.000221394729555245,-4.25656641922375E-6,50.0010605,50.0010605,-50419.3828125,-50409.234375,54.373206311775,19.5712639094785,19.112494,0,0,0,40,4449,50.13965,-50414.30859375,,,,,,,,,,,,,0,,,,0.00245,,,,,,50.0010605,,,,
,19823490.375,50.0003395,-55883.263671875,0.000248022798891307,1.52087417859125E-6,1,0.999253354069792,40.0298881530762,1.99488545163788,14.2400003969669,0.00281789402415446,0.00043419462826881,0.25,-6.18934002869112E-6,0.00024864115862074,-4.4787636376002E-6,50.0003395,50.0003395,-55890.6875,-55875.83984375,54.3927470247558,19.5695653636249,19.492144,0,0,0,40,4449,50.1386,-55883.263671875,,,,,,,,,,,,,0,,,,0.00245,,,,,,50.0003395,,,,
,19823601.035,50.0009346,-61414.72265625,0.000275785326448976,1.08471295089407E-6,1,0.999253354069792,40.0298881530762,1.99493607449341,14.2400003969669,0.0031289178032243,0.000512075252696707,0.25,-4.27795318584616E-6,0.000276522466122714,-2.39824957427818E-6,50.0009346,50.0009346,-61422.53515625,-61406.91015625,54.1504421837942,19.5730110593383,19.492144,0,0,0,40,4449,50.13945,-61414.72265625,,,,,,,,,,,,,0,,,,-0.00245,,,,,,50.0009346,,,,
,19823710.67,50.0014763,-66891.875,0.000304667642951881,1.34153846890107E-6,1,0.999253354069792,40.0298881530762,1.99490873843824,14.2400003969669,0.00345793605160218,0.000562554933709493,0.25,-4.98331474398346E-6,0.000305553965189177,-2.93987069456043E-6,50.0014763,50.0014763,-66894.2890625,-66889.4609375,54.342722799525,19.5741550564304,19.112494,0,0,0,40,4449,50.1367,-66891.875,,,,,,,,,,,,,0,,,,-0.0049,,,,,,50.0014763,,,,
,19823824.045,50.0020332,-72557.984375,0.000336407493743481,1.42214742247883E-6,1,0.999253354069792,40.0298881530762,1.99480452506535,14.2400003969669,0.00381799791485209,0.000626002196958647,0.25,-5.04684208541635E-6,0.000337459221346807,-2.82750680447082E-6,50.0020332,50.0020332,-72565.5,-72550.46875,54.4802894189096,19.5745670873752,19.492144,0,0,0,40,4449,50.13455,-72557.984375,,,,,,,,,,,,,0,,,,0,,,,,,50.0020332,,,,
,19823937.4,50.0013161,-78224.44921875,0.00036423158093877,1.36493173731438E-6,1,0.999253354069792,40.0298881530762,1.99488966926198,14.2400003969669,0.00413709587401818,0.000665312680554971,0.25,-6.53874629421626E-6,0.000365455289278984,-4.18183886808143E-6,50.0013161,50.0013161,-78226.890625,-78222.0078125,54.413850994775,19.5774585929297,19.112494,0,0,0,40,4449,50.1328,-78224.44921875,,,,,,,,,,,,,0,,,,0,,,,,,50.0013161,,,,
,19824050.63,50.0013199,-83883.17578125,0.000394832969040039,1.56531558714385E-6,1,0.999253354069792,40.0298881530762,1.99490249008764,14.2400003969669,0.00448362127893524,0.000732424276280749,0.25,-6.06497988618238E-6,0.000396232462319465,-3.5535711720217E-6,50.0013199,50.0013199,-83893.2421875,-83873.109375,54.2762843753904,19.5779217791802,19.492144,0,0,0,40,4449,50.131,-83883.17578125,,,,,,,,,,,,,0,,,,0,,,,,,50.0013199,,,,
,19824160.2,50.0018883,-89357.234375,0.000427828210100458,1.77381448792902E-6,1,0.999253354069792,40.0298881530762,1.99485561255845,14.2400003969669,0.00485769324118426,0.000801535651332425,0.25,-5.83646769349594E-6,0.000429418805872923,-3.16211703575324E-6,50.0018883,50.0018883,-89364.7890625,-89349.6796875,54.3106760302365,19.5770378824028,19.492144,0,0,0,40,4449,50.12945,-89357.234375,,,,,,,,,,,,,0,,,,0.00245,,,,,,50.0018883,,,,
,19824173.56,50.0019035,-89999.53125,0.000431753859845444,1.53524002415956E-6,1,0.999253354069792,40.0298881530762,1.99488043028598,14.2400003969669,0.00490181321881708,0.000812340945301688,0.25,-5.58193382626798E-6,0.000433366146646964,-2.8877911278318E-6,50.0019035,50.0019035,-89999.5703125,-89999.4921875,54.3145841728327,19.5769679010022,19.492144,0,0,0,40,4417,50.1291,-89999.53125,,,,,,,,,,,,,0,,,,0,,,,,,50.0019035,,,,