File: data/doubleLayers/monolayer/ppms/DD205_4/ppms_cologne_data/INITIALTEST_300K_HYS3T.DAT
[Header]
; VSM Data File (default extension .dat)
; Copyright (c) 2003-2013, Quantum Design, Inc. All rights reserved.
TITLE,
FILEOPENTIME,19641481.02,08/16/2018,7:56 am
BYAPP,VSM,2.0,2.0
INFO,PPMS VSM Option Release 1.4.10 Build 1,APPNAME
INFO,Quantum Design Linear Motor Servo Controller,MOTOR_MODULE_NAME
INFO,3101-100 M1,MOTOR_HW_VERSION
INFO,MMC1014,MOTOR_SERIAL_NUMBER
INFO,SRV No X-over 01.03.11,MOTOR_SOFTWARE_VERSION
INFO,Quantum Design VSM Detection Module,VSM_MODULE_NAME
INFO,3101-150 F0,VSM_HW_VERSION
INFO,VSM707,VSM_SERIAL_NUMBER
INFO,VSM No X-over 01.02.05 May 20 2008 13:51:47,VSM_SOFTWARE_VERSION
INFO,704,PREAMP_SERIAL_NUMBER
INFO,822,COIL_SERIAL_NUMBER
INFO,0,MOMENT_UNITS
INFO,,SAMPLE_MATERIAL
INFO,,SAMPLE_COMMENT
INFO,,SAMPLE_MASS
INFO,,SAMPLE_VOLUME
INFO,,SAMPLE_MOLECULAR_WEIGHT
INFO,,SAMPLE_SIZE
INFO,,SAMPLE_SHAPE
DATATYPE,COMMENT,1
DATATYPE,TIME,2
STARTUPAXIS,X,2
STARTUPAXIS,Y1,5
[Data]
Comment,Time Stamp (sec),Temperature (K),Magnetic Field (Oe),Moment (emu),M. Std. Err. (emu),Transport Action,Averaging Time (sec),Frequency (Hz),Peak Amplitude (mm),Center Position (mm),Coil Signal' (mV),Coil Signal" (mV),Range (mV),M. Quad. Signal (emu),M. Raw' (emu),M. Raw" (emu),Min. Temperature (K),Max. Temperature (K),Min. Field (Oe),Max. Field (Oe),Mass (grams),Motor Lag (deg),Pressure (Torr),VSM Status (code),Motor Status (code),Measure Status (code),Measure Count,PPMS Status (code),System Temp. (K),System Field (Oe),Sample Position (deg),Bridge 1 Resistance (ohms),Bridge 1 Excitation (에),Bridge 2 Resistance (ohms),Bridge 2 Excitation (에),Bridge 3 Resistance (ohms),Bridge 3 Excitation (에),Bridge 4 Resistance (ohms),Bridge 4 Excitation (에),Signal 1 Vin (V),Signal 2 Vin (V),Digital Inputs (code),Drive 1 Iout (mA),Drive 1 Ipower (W),Drive 2 Iout (mA),Drive 2 Ipower (W),Pressure (),Map 20 (),Map 21 (),Map 22 (),Map 23 (),Map 24 (),Map 25 (),Map 26 (),Map 27 (),Map 28 (),Map 29 ()
sample offset = 35.68 mm touchdown = 8.75999964773655 mm,19641517.405,300.0386963,-29999.693359375,5.42674217840578E-5,3.27264499519639E-6,1,0.999253354069792,40.0298881530762,1.99788592797786,14.2400003969669,0.000612851137041645,0.000112460733572672,0.25,5.38983431457373E-7,5.4265388388446E-5,5.74777847031483E-7,300.0386963,300.0386963,-29999.693359375,-29999.693359375,52.8443409281594,19.5182216991852,29.363071,0,0,0,40,4417,300.2197,-29999.693359375,,,,,,,,,,,,,0,,,,0,,,,,,300.0386963,,,,
,19641540.845,300.03497315,-29485.2060546875,5.39199455209781E-5,3.21649913495131E-6,1,0.999253354069792,40.0298881530762,1.99797537593731,14.2400003969669,0.000608324987496221,0.000115370902303871,0.25,8.5599416022303E-7,5.39177204450539E-5,8.91553744666633E-7,300.0346985,300.0352478,-29515.16015625,-29455.251953125,53.178096305871,19.5256510286944,29.363071,0,0,0,40,4449,300.21805,-29485.2060546875,,,,,,,,,,,,,0,,,,0,,,,,,300.03497315,,,,
,19641552.945,300.0319519,-28884.248046875,5.2774014913072E-5,3.15583713367961E-6,1,0.999253354069792,40.0298881530762,1.9979522427926,14.2400003969669,0.000591569874472695,0.000134967130472424,0.25,2.78682791528075E-6,5.27705557975974E-5,2.82157725486906E-6,300.0319519,300.0319519,-28914.0625,-28854.43359375,53.1827860769864,19.5249667929621,28.983419,0,0,0,40,4449,300.21265,-28884.248046875,,,,,,,,,,,,,0,,,,0.00245,,,,,,300.0319519,,,,
,19641565.685,300.0297852,-28249.435546875,4.94090168954309E-5,2.93952757431189E-6,1,0.999253354069792,40.0298881530762,1.99795435229863,14.2400003969669,0.000561766109004737,8.06745554928799E-5,0.25,-1.42930955418957E-6,4.94084475972861E-5,-1.39664764559951E-6,300.0297852,300.0297852,-28281.751953125,-28217.119140625,52.974872890871,19.5274898190744,28.983419,0,0,0,40,4449,300.21245,-28249.435546875,,,,,,,,,,,,,0,,,,0,,,,,,300.0297852,,,,
,19641578.315,300.0284119,-27618.45703125,4.55034755785433E-5,2.6872263070495E-6,1,0.999253354069792,40.0298881530762,1.99799098639479,14.2400003969669,0.000518567019042116,6.73918418744296E-5,0.25,-1.92686695563206E-6,4.550335638499E-5,-1.89676404959517E-6,300.0284119,300.0284119,-27623.69140625,-27613.22265625,53.228902159621,19.5288564624421,29.742722,0,0,0,40,4449,300.21135,-27618.45703125,,,,,,,,,,,,,0,,,,-0.00245,,,,,,300.0284119,,,,
,19641589.46,300.02545165,-27061.650390625,4.16677594854113E-5,2.38256532679028E-6,1,0.999253354069792,40.0298881530762,1.99794210349644,14.2400003969669,0.000472934530292469,7.27269887412663E-5,0.25,-7.90571250286059E-7,4.16670115326226E-5,-7.63032432937599E-7,300.0248108,300.0260925,-27093.876953125,-27029.423828125,53.0436562005633,19.5309787070249,29.742722,0,0,0,40,4449,300.2108,-27061.650390625,,,,,,,,,,,,,0,,,,-0.00245,,,,,,300.02545165,,,,
,19641600.995,300.02160645,-26483.5888671875,4.34261304117073E-5,2.51196205674786E-6,1,0.999253354069792,40.0298881530762,1.99799192717635,14.2400003969669,0.000489611173221175,9.48037039353043E-5,0.25,8.56031330353542E-7,4.34242471628298E-5,8.84684753908226E-7,300.0209656,300.0222473,-26518.67578125,-26448.501953125,53.0108278027556,19.5337690612845,29.363071,0,0,0,40,4449,300.2101,-26483.5888671875,,,,,,,,,,,,,0,,,,0.00245,,,,,,300.02160645,,,,
,19641612.975,300.02075195,-25886.205078125,4.00085560327256E-5,2.82937439686233E-6,1,0.999253354069792,40.0298881530762,1.99798213059765,14.2400003969669,0.00044795021194279,0.000105391641660091,0.25,2.38408125628487E-6,4.00057680954352E-5,2.41043456426573E-6,300.0206909,300.020813,-25918.72265625,-25853.6875,53.6728671585441,19.5365656650181,29.363071,0,0,0,40,4449,300.2108,-25886.205078125,,,,,,,,,,,,,0,,,,0,,,,,,300.02075195,,,,
,19641625.75,300.01817325,-25249.5185546875,3.85981715263282E-5,2.44558628232793E-6,1,0.999253354069792,40.0298881530762,1.9979656664595,14.2400003969669,0.000438764244831908,6.35324352676908E-5,0.25,-1.07156482552806E-6,3.85977121715362E-5,-1.04603493612127E-6,300.0178528,300.0184937,-25279.572265625,-25219.46484375,53.3617790078903,19.5364720254755,28.983419,0,0,0,40,4449,300.21025,-25249.5185546875,,,,,,,,,,,,,0,,,,-0.00245,,,,,,300.01817325,,,,
,19641638.23,300.0162659,-24625.013671875,3.85991647382349E-5,2.58969846702136E-6,1,0.999253354069792,40.0298881530762,1.9979284645869,14.2400003969669,0.000441375408176183,4.84822443269118E-5,0.25,-2.40200069418565E-6,3.8599586776582E-5,-2.37642674047537E-6,300.0162659,300.0162659,-24655.044921875,-24594.982421875,53.5095067980249,19.5384847742587,29.363071,0,0,0,40,4449,300.21005,-24625.013671875,,,,,,,,,,,,,0,,,,0,,,,,,300.0162659,,,,
,19641650.645,300.0126343,-24005.1787109375,3.67151932286051E-5,2.15944765520907E-6,1,0.999253354069792,40.0298881530762,1.99787366407864,14.2400003969669,0.000417432661174202,5.99028086863711E-5,0.25,-1.06593478930041E-6,3.67147940190071E-5,-1.04164283267373E-6,300.0126343,300.0126343,-24010.263671875,-24000.09375,53.6783385581788,19.5362129654716,29.363071,0,0,0,40,4449,300.2096,-24005.1787109375,,,,,,,,,,,,,0,,,,0.0049,,,,,,300.0126343,,,,
,19641661.595,300.0118103,-23455.7109375,3.62421488816197E-5,1.80152191020546E-6,1,0.999253354069792,40.0298881530762,1.99791271481303,14.2400003969669,0.000414856211204457,4.30051157237619E-5,0.25,-2.4777585066122E-6,3.62426977856966E-5,-2.45373424785233E-6,300.0118103,300.0118103,-23485.345703125,-23426.076171875,53.4633907153903,19.5388373205942,29.363071,0,0,0,40,4449,300.2118,-23455.7109375,,,,,,,,,,,,,0,,,,0,,,,,,300.0118103,,,,
,19641673.68,300.009964,-22853.78515625,2.99597565482946E-5,1.78428787542182E-6,1,0.999253354069792,40.0298881530762,1.9978763560031,14.2400003969669,0.000340265564595221,5.09690140669157E-5,0.25,-6.85239215589685E-7,2.99593114070186E-5,-6.65417945726972E-7,300.0093994,300.0105286,-22876.361328125,-22831.208984375,53.6978792711595,19.5385670843917,29.363071,0,0,0,40,4449,300.21135,-22853.78515625,,,,,,,,,,,,,0,,,,0,,,,,,300.009964,,,,
,19641685.7,300.0066528,-22253.9501953125,2.76073923662252E-5,1.22312643081539E-6,1,0.999253354069792,40.0298881530762,1.99794738405757,14.2400003969669,0.000314519642943328,4.14266477742885E-5,0.25,-1.12131875017801E-6,2.76073091191148E-5,-1.10303700067419E-6,300.0057678,300.0075378,-22276.43359375,-22231.466796875,53.4204011468326,19.538500813899,28.983419,0,0,0,40,4449,300.2112,-22253.9501953125,,,,,,,,,,,,,0,,,,0,,,,,,300.0066528,,,,
,19641697.635,300.0049744,-21654.0849609375,2.80527222899685E-5,9.17550698360906E-7,1,0.999253354069792,40.0298881530762,1.99792489751716,14.2400003969669,0.000317864999188011,5.2048923905416E-5,0.25,-2.59482338146958E-7,2.80520575956356E-5,-2.40929832382632E-7,300.0049744,300.0049744,-21656.61328125,-21651.556640625,53.5173230832172,19.5421214358847,29.363071,0,0,0,40,4449,300.2126,-21654.0849609375,,,,,,,,,,,,,0,,,,0,,,,,,300.0049744,,,,
,19641709.24,300.00283815,-21074.349609375,2.57128924698483E-5,1.04582844018453E-6,1,0.999253354069792,40.0298881530762,1.99793928521505,14.2400003969669,0.00029233589142922,4.20432717016328E-5,0.25,-7.38566425629809E-7,2.57126160907159E-5,-7.21544612802356E-7,300.0027771,300.0028992,-21096.8125,-21051.88671875,53.239063330371,19.5374169976381,29.363071,0,0,0,40,4449,300.21435,-21074.349609375,,,,,,,,,,,,,0,,,,-0.0049,,,,,,300.00283815,,,,
,19641720.7,300.0014954,-20504.7919921875,2.28293234926965E-5,1.16527171061124E-6,1,0.999253354069792,40.0298881530762,1.99795509241769,14.2400003969669,0.000261384144840264,2.6764861454152E-5,0.25,-1.58951138891123E-6,2.28296965317046E-5,-1.57436919010677E-6,300.0014954,300.0014954,-20532.267578125,-20477.31640625,53.5345189106403,19.5384695243911,28.983419,0,0,0,40,4449,300.2165,-20504.7919921875,,,,,,,,,,,,,0,,,,-0.0049,,,,,,300.0014954,,,,
,19641733.605,300.0005188,-19857.943359375,2.14563493144102E-5,8.98184547403833E-7,1,0.999253354069792,40.0298881530762,1.99792348834847,14.2400003969669,0.000242296743553962,4.45700747221478E-5,0.25,2.22293699476971E-7,2.14555657083971E-5,2.36476129545995E-7,300.0005188,300.0005188,-19887.8984375,-19827.98828125,53.7291444119288,19.5403927227792,29.363071,0,0,0,40,4449,300.21595,-19857.943359375,,,,,,,,,,,,,0,,,,0.00245,,,,,,300.0005188,,,,
,19641745.75,299.9977112,-19250.5673828125,1.92967946869053E-5,8.31656963940877E-7,1,0.999253354069792,40.0298881530762,1.99792719067949,14.2400003969669,0.000219716871471107,2.96570827198772E-5,0.25,-7.2178774767133E-7,1.92967013402318E-5,-7.0900397967894E-7,299.9970703,299.9983521,-19283.078125,-19218.056640625,53.7275811548903,19.5412437957189,29.363071,0,0,0,40,4449,300.21655,-19250.5673828125,,,,,,,,,,,,,0,,,,0.00245,,,,,,299.9977112,,,,
,19641757.68,299.99620055,-18656.0869140625,1.71710946524157E-5,8.97358160348634E-7,1,0.999253354069792,40.0298881530762,1.99787644049134,14.2400003969669,0.000194489094705426,3.22733782627788E-5,0.25,-1.22158405487177E-7,1.71706684261476E-5,-1.10797043858439E-7,299.9959106,299.9964905,-18683.697265625,-18628.4765625,53.7932379505057,19.541047532232,28.983419,0,0,0,40,4449,300.21895,-18656.0869140625,,,,,,,,,,,,,0,,,,0,,,,,,299.99620055,,,,
,19641770.9,299.9941711,-17994.0458984375,1.43190917028308E-5,8.18569861766498E-7,1,0.999253354069792,40.0298881530762,1.99789210822322,14.2400003969669,0.000162943967644082,2.25441332444193E-5,0.25,-4.88078741941256E-7,1.43189927058942E-5,-4.78591887626632E-7,299.9941711,299.9941711,-17999.12890625,-17988.962890625,53.7236730122941,19.5442654239798,29.363071,0,0,0,40,4449,300.2205,-17994.0458984375,,,,,,,,,,,,,0,,,,0,,,,,,299.9941711,,,,
,19641782.275,299.9942627,-17424.3623046875,1.25330182528736E-5,8.96228310338081E-7,1,0.999253354069792,40.0298881530762,1.99791348074896,14.2400003969669,0.000143148199139002,1.66884108137083E-5,0.25,-6.96267562888602E-7,1.2533109531532E-5,-6.87955296205101E-7,299.9942627,299.9942627,-17454.15625,-17394.568359375,53.7369606971211,19.5433350099577,29.363071,0,0,0,40,4449,300.22375,-17424.3623046875,,,,,,,,,,,,,0,,,,0,,,,,,299.9942627,,,,
,19641794.195,299.99209595,-16829.5576171875,1.05405530314122E-5,7.2479937227152E-7,1,0.999253354069792,40.0298881530762,1.9978679509046,14.2400003969669,0.000120571259010578,1.2978909718029E-5,0.25,-6.78935724880106E-7,1.05406923654981E-5,-6.71941458958269E-7,299.991272,299.9929199,-16859.466796875,-16799.6484375,53.9605064536211,19.5436116752128,28.983419,0,0,0,40,4449,300.22525,-16829.5576171875,,,,,,,,,,,,,0,,,,0,,,,,,299.99209595,,,,
,19641807,299.9907837,-16189.8901367188,9.36630607011397E-6,7.64592239129011E-7,1,0.999253354069792,40.0298881530762,1.99786252034417,14.2400003969669,0.000106412973322175,1.57234918298299E-5,0.25,-2.3287107879959E-7,9.36618517677216E-6,-2.26666171036552E-7,299.9907837,299.9907837,-16195.01953125,-16184.7607421875,53.6447285318518,19.542212236144,29.363071,0,0,0,40,4449,300.2267,-16189.8901367188,,,,,,,,,,,,,0,,,,0.00245,,,,,,299.9907837,,,,
,19641818.455,299.9890442,-15620.3911132812,7.00215417302626E-6,7.71167981824595E-7,1,0.999253354069792,40.0298881530762,1.99785605984635,14.2400003969669,8.08224728317455E-5,4.42766068896665E-6,0.25,-8.21785976386128E-7,7.00249285109815E-6,-8.17127794765805E-7,299.9890442,299.9890442,-15650.5302734375,-15590.251953125,53.6494183029672,19.5443168004395,29.363071,0,0,0,40,4449,300.2275,-15620.3911132812,,,,,,,,,,,,,0,,,,-0.0049,,,,,,299.9890442,,,,
,19641830.795,299.9894104,-15000.5541992187,4.4719729282304E-6,7.22885586806965E-7,1,0.999253354069792,40.0298881530762,1.99778952034001,14.2400003969669,5.12398198245009E-5,4.99988624575251E-6,0.25,-3.32813637735775E-7,4.47206207899508E-6,-3.29843962965706E-7,299.9894104,299.9894104,-15025.6181640625,-14975.490234375,53.7815135227172,19.5431004752941,29.742722,0,0,0,40,4449,300.23,-15000.5541992187,,,,,,,,,,,,,0,,,,0,,,,,,299.9894104,,,,
,19641842.6,299.9877167,-14411.2138671875,2.5010052489729E-6,6.61718921131149E-7,1,0.999253354069792,40.0298881530762,1.99781883271651,14.2400003969669,2.89271682003078E-5,1.23634702649272E-6,0.25,-3.24028043984543E-7,2.50114653862894E-6,-3.22363021424549E-7,299.9874878,299.9879456,-14436.189453125,-14386.23828125,53.7174199841403,19.5452744470055,29.363071,0,0,0,40,4449,300.2319,-14411.2138671875,,,,,,,,,,,,,0,,,,0.00245,,,,,,299.9877167,,,,
,19641854.74,299.9891968,-13804.0727539062,1.24480854368166E-6,5.98477850453216E-7,1,0.999253354069792,40.0298881530762,1.99777610483829,14.2400003969669,1.49562041968329E-5,-2.60973892231304E-6,0.25,-4.46377986150189E-7,1.24506754718409E-6,-4.45540806495036E-7,299.9891968,299.9891968,-13826.3837890625,-13781.76171875,53.8698375453903,19.5462373525094,29.363071,0,0,0,40,4449,300.2333,-13804.0727539062,,,,,,,,,,,,,0,,,,0,,,,,,299.9891968,,,,
,19641866.445,299.987442,-13218.9443359375,-1.17043151177822E-6,5.23779072354343E-7,1,0.999253354069792,40.0298881530762,1.99776964245811,14.2400003969669,-1.30952701294601E-5,-3.12896243987888E-6,0.25,-7.38176899062155E-8,-1.17034837836132E-6,-7.4590457003375E-8,299.9873047,299.9875793,-13251.5,-13186.388671875,53.6752120441018,19.5470233095049,29.742722,0,0,0,40,4449,300.23485,-13218.9443359375,,,,,,,,,,,,,0,,,,0,,,,,,299.987442,,,,
,19641877.695,299.9848938,-12659.3041992187,-2.76530993258938E-6,5.92541104746918E-7,1,0.999253354069792,40.0298881530762,1.99781621770086,14.2400003969669,-2.98730565362513E-5,-1.35515570441069E-5,0.25,-7.18837624578356E-7,-2.76475324862319E-6,-7.20647694872846E-7,299.9848938,299.9848938,-12686.958984375,-12631.6494140625,53.6416020177749,19.5452266999627,29.742722,0,0,0,40,4449,300.23675,-12659.3041992187,,,,,,,,,,,,,0,,,,0,,,,,,299.9848938,,,,
,19641890.135,299.9852295,-12034.6552734375,-4.85243566616281E-6,7.12958288890157E-7,1,0.999253354069792,40.0298881530762,1.99774306312579,14.2400003969669,-5.40044974115594E-5,-1.46219905736043E-5,0.25,-4.51895617768573E-7,-4.85199470554616E-6,-4.55095792971541E-7,299.9852295,299.9852295,-12037.013671875,-12032.296875,53.7064771848711,19.5460513558451,29.742722,0,0,0,40,4449,300.2391,-12034.6552734375,,,,,,,,,,,,,0,,,,0.00245,,,,,,299.9852295,,,,
,19641901.975,299.9847565,-11442.4028320312,-6.1756260430013E-6,6.18538412533671E-7,1,0.999253354069792,40.0298881530762,1.99774207664478,14.2400003969669,-6.94171999931092E-5,-1.46470609620104E-5,0.25,-2.24857762718506E-7,-6.17529684637797E-6,-2.28941192143179E-7,299.9841309,299.9853821,-11472.609375,-11412.1962890625,53.8057440068134,19.5484649864103,29.363071,0,0,0,40,4449,300.24235,-11442.4028320312,,,,,,,,,,,,,0,,,,0,,,,,,299.9847565,,,,
,19641915.055,299.9841614,-10790.4526367187,-8.61913003122723E-6,8.41517960906445E-7,1,0.999253354069792,40.0298881530762,1.99774354270826,14.2400003969669,-9.7420894216729E-5,-1.73408129444864E-5,0.25,-3.96322926322865E-8,-8.61885230197901E-6,-4.5340022972012E-8,299.9841614,299.9841614,-10792.9140625,-10787.9912109375,53.9378392265634,19.5474287558776,29.363071,0,0,0,40,4449,300.2445,-10790.4526367187,,,,,,,,,,,,,0,,,,0,,,,,,299.9841614,,,,
,19641925.565,299.9834137,-10265.5922851562,-9.67078194082083E-6,6.04614542945008E-7,1,0.999253354069792,40.0298881530762,1.99768517588667,14.2400003969669,-0.000107928428377679,-2.73985542267486E-5,0.25,-7.4662194446404E-7,-9.6700054195733E-6,-7.53006180832341E-7,299.9827881,299.9840393,-10298.1826171875,-10233.001953125,53.8104337779288,19.548569161096,28.983419,0,0,0,40,4449,300.2458,-10265.5922851562,,,,,,,,,,,,,0,,,,-0.00245,,,,,,299.9834137,,,,
,19641937.83,299.9837341,-9651.05810546875,-1.14141207728675E-5,7.53110377380227E-7,1,0.999253354069792,40.0298881530762,1.99773923696721,14.2400003969669,-0.000129299568963043,-2.13044849791135E-5,0.25,9.42232688844535E-8,-1.14138502170414E-5,8.66589972452634E-8,299.9837341,299.9837341,-9653.2763671875,-9648.83984375,53.9245515417365,19.5468050386097,28.983419,0,0,0,40,4449,300.2487,-9651.05810546875,,,,,,,,,,,,,0,,,,0,,,,,,299.9837341,,,,
,19641948.765,299.9834595,-9103.923828125,-1.39364765685347E-5,8.24611307827848E-7,1,0.999253354069792,40.0298881530762,1.99773101573184,14.2400003969669,-0.000155889823328781,-3.74545538682339E-5,0.25,-8.96479494122481E-7,-1.39354761298918E-5,-9.05686670269162E-7,299.9834595,299.9834595,-9133.833984375,-9074.013671875,53.9417473691596,19.545548187716,29.363071,0,0,0,40,4449,300.25005,-9103.923828125,,,,,,,,,,,,,0,,,,0,,,,,,299.9834595,,,,
,19641960.805,299.98338315,-8501.0419921875,-1.51987538955392E-5,5.82380174573514E-7,1,0.999253354069792,40.0298881530762,1.99769606883141,14.2400003969669,-0.000171555493911746,-3.19058902623721E-5,0.25,-1.87305217949894E-7,-1.51981864351464E-5,-1.97370297464982E-7,299.9830627,299.9837036,-8533.6123046875,-8468.4716796875,53.9714492528903,19.5470886029376,29.363071,0,0,0,40,4449,300.2526,-8501.0419921875,,,,,,,,,,,,,0,,,,0.00245,,,,,,299.98338315,,,,
,19641972.215,299.9815063,-7933.68481445313,-1.62409129615759E-5,4.57637999117017E-7,1,0.999253354069792,40.0298881530762,1.99769590736669,14.2400003969669,-0.000184489978417493,-2.73341278090474E-5,0.25,3.97424335131886E-7,-1.62407035690958E-5,3.86650739591573E-7,299.9815063,299.9815063,-7963.64990234375,-7903.7197265625,53.8323193764672,19.5455120163931,29.742722,0,0,0,40,4449,300.25395,-7933.68481445313,,,,,,,,,,,,,0,,,,-0.00245,,,,,,299.9815063,,,,
,19641983.515,299.9818115,-7369.20288085938,-1.81131882910675E-5,5.79011101931352E-7,1,0.999253354069792,40.0298881530762,1.99768138937413,14.2400003969669,-0.000203496933674683,-4.35283701672978E-5,0.25,-7.09858658227046E-7,-1.81121903360867E-5,-7.21841640444953E-7,299.9818115,299.9818115,-7394.171875,-7344.23388671875,53.6548897026018,19.5484063578541,29.742722,0,0,0,40,4449,300.257,-7369.20288085938,,,,,,,,,,,,,0,,,,0.00245,,,,,,299.9818115,,,,
,19641995.32,299.9816895,-6779.34130859375,-1.97185545193849E-5,6.06758472282489E-7,1,0.999253354069792,40.0298881530762,1.9977199849335,14.2400003969669,-0.000221416289234681,-4.80832049672569E-5,0.25,-8.34305787801171E-7,-1.97174272604309E-5,-8.47350265069485E-7,299.9816895,299.9816895,-6809.48388671875,-6749.19873046875,53.8362275190634,19.5477738612022,29.363071,0,0,0,40,4449,300.2571,-6779.34130859375,,,,,,,,,,,,,0,,,,0,,,,,,299.9816895,,,,
,19642006.865,299.980484,-6199.68359375,-2.1577652922768E-5,6.85628755875615E-7,1,0.999253354069792,40.0298881530762,1.997713936739,14.2400003969669,-0.000244220263269446,-4.14818662576623E-5,0.25,7.13734889495325E-8,-2.15770725951929E-5,5.70692321031286E-8,299.9795837,299.9813843,-6229.74169921875,-6169.62548828125,54.1684196397365,19.54699917255,28.983419,0,0,0,40,4449,300.25815,-6199.68359375,,,,,,,,,,,,,0,,,,-0.00245,,,,,,299.980484,,,,
,19642018.94,299.9801025,-5597.43334960937,-2.28335719844321E-5,5.37060535568752E-7,1,0.999253354069792,40.0298881530762,1.99760868846408,14.2400003969669,-0.000256919076093263,-5.25686154797344E-5,0.25,-6.91370792635934E-7,-2.28324497266051E-5,-7.06486542879121E-7,299.9801025,299.9801025,-5629.81103515625,-5565.0556640625,53.9425289976788,19.5483684813536,29.742722,0,0,0,40,4449,300.2615,-5597.43334960937,,,,,,,,,,,,,0,,,,0.00245,,,,,,299.9801025,,,,
,19642030.15,299.9808807,-5037.91870117188,-2.38486340487388E-5,5.26885870815163E-7,1,0.999253354069792,40.0298881530762,1.9976533013533,14.2400003969669,-0.000268633655976636,-5.32468828027452E-5,0.25,-5.75364917879779E-7,-2.38475583840857E-5,-5.91157947183291E-7,299.9808044,299.980957,-5070.4658203125,-5005.37158203125,53.780731894198,19.5479359170934,29.363071,0,0,0,40,4449,300.2661,-5037.91870117188,,,,,,,,,,,,,0,,,,-0.00245,,,,,,299.9808807,,,,
,19642042.505,299.980835,-4417.77514648438,-2.44449740162859E-5,4.47352185881571E-7,1,0.999253354069792,40.0298881530762,1.99771338953405,14.2400003969669,-0.000276510103121652,-4.79349278759887E-5,0.25,-2.30911543216031E-9,-2.44442607838078E-5,-1.85156995776851E-8,299.980835,299.980835,-4445.2373046875,-4390.31298828125,53.9401841121211,19.5478337677946,29.363071,0,0,0,40,4449,300.26535,-4417.77514648438,,,,,,,,,,,,,0,,,,0,,,,,,299.980835,,,,
,19642054.03,299.9811401,-3842.87194824219,-2.57142549939213E-5,4.99108383326397E-7,1,0.999253354069792,40.0298881530762,1.99774500419913,14.2400003969669,-0.000289256246362823,-5.97503064556943E-5,0.25,-8.26838792826495E-7,-2.57129577280817E-5,-8.43864069791638E-7,299.9807739,299.9815063,-3875.41430664063,-3810.32958984375,53.9581615680634,19.5500297206699,29.742722,0,0,0,40,4449,300.2687,-3842.87194824219,,,,,,,,,,,,,0,,,,-0.00245,,,,,,299.9811401,,,,
,19642065.655,299.9808044,-3263.19470214844,-2.6433666874777E-5,4.91638821148238E-7,1,0.999253354069792,40.0298881530762,1.99765409371637,14.2400003969669,-0.000297388408632145,-6.11162379905453E-5,0.25,-8.23178841540723E-7,-2.64323512276718E-5,-8.40682630569851E-7,299.9808044,299.9808044,-3290.79174804687,-3235.59765625,53.5884512784672,19.5469065046504,29.363071,0,0,0,40,4449,300.26905,-3263.19470214844,,,,,,,,,,,,,0,,,,-0.00245,,,,,,299.9808044,,,,
,19642076.86,299.9794922,-2703.7001953125,-2.71000026612663E-5,3.84980028725505E-7,1,0.999253354069792,40.0298881530762,1.99766762935746,14.2400003969669,-0.000306382363729192,-5.40259944136253E-5,0.25,-8.0874433460835E-8,-2.7099160987975E-5,-9.88428537366193E-8,299.9792786,299.9797058,-2736.06787109375,-2671.33251953125,53.9159536280249,19.5499107040854,29.742722,0,0,0,40,4449,300.2718,-2703.7001953125,,,,,,,,,,,,,0,,,,0.00245,,,,,,299.9794922,,,,
,19642087.875,299.98072815,-2153.63708496094,-2.63654306553668E-5,4.97794395969462E-7,1,0.999253354069792,40.0298881530762,1.99772718217436,14.2400003969669,-0.000296883710071586,-5.95025063811104E-5,0.25,-6.92151247934594E-7,-2.63642036805827E-5,-7.09615918911416E-7,299.9803772,299.9810791,-2180.9111328125,-2126.36303710938,53.7408688397172,19.5490193867634,29.363071,0,0,0,40,4449,300.27295,-2153.63708496094,,,,,,,,,,,,,0,,,,-0.00245,,,,,,299.98072815,,,,
,19642099.345,299.9800415,-1578.51171875,-2.61458656630235E-5,5.35893918548669E-7,1,0.999253354069792,40.0298881530762,1.99763708121375,14.2400003969669,-0.00029577905395566,-5.10372955904727E-5,0.25,1.79666124902327E-8,-2.61451165758104E-5,6.25933889509281E-10,299.9797668,299.9803162,-1610.88000488281,-1546.14343261719,53.8073072638518,19.5522863559775,29.363071,0,0,0,40,4449,300.27735,-1578.51171875,,,,,,,,,,,,,0,,,,0,,,,,,299.9800415,,,,
,19642111.79,299.9817505,-956.277374267578,-2.37453132446261E-5,3.74084326460456E-7,1,0.999253354069792,40.0298881530762,1.99767483434204,14.2400003969669,-0.00026846948375404,-4.72628872144881E-5,0.25,-6.4191819496384E-8,-2.37445779797216E-5,-7.9939138095043E-8,299.9817505,299.9817505,-961.366394042969,-951.188354492188,53.8080888923711,19.5516369379196,28.983419,0,0,0,40,4449,300.27765,-956.277374267578,,,,,,,,,,,,,0,,,,0,,,,,,299.9817505,,,,
,19642122.515,299.9807587,-418.705841064453,-1.91512571249439E-5,3.48469140848796E-7,1,0.999253354069792,40.0298881530762,1.99770059417442,14.2400003969669,-0.000215331399693451,-4.50418281410899E-5,0.25,-6.63753614946869E-7,-1.91502588170503E-5,-6.76437070612249E-7,299.9806519,299.9808655,-451.192932128906,-386.21875,53.9886450803134,19.5466162174495,29.363071,0,0,0,40,4449,300.27875,-418.705841064453,,,,,,,,,,,,,0,,,,-0.00245,,,,,,299.9807587,,,,
,19642133.33,299.98091125,121.155693054199,4.54271565561069E-6,4.86390339776516E-7,1,0.999253354069792,40.0298881530762,1.99763563692465,14.2400003969669,5.169783446594E-5,7.09144135097935E-6,0.25,-1.60135990457027E-7,4.54268947409654E-6,-1.57118144604268E-7,299.9806824,299.9811401,93.5610504150391,148.750335693359,54.0980730730057,19.548603810316,29.363071,0,0,0,40,4449,300.2808,121.155693054199,,,,,,,,,,,,,0,,,,0,,,,,,299.98091125,,,,
,19642144.585,299.9805908,682.671325683594,1.9255370279152E-5,3.93331017975088E-7,1,0.999253354069792,40.0298881530762,1.99767634921443,14.2400003969669,0.000219445628346783,2.82821428436587E-5,0.25,-8.35886456608483E-7,1.92553637691758E-5,-8.23090733201872E-7,299.9801025,299.9810791,657.550537109375,707.792114257812,53.7955828360634,19.5501756481327,29.363071,0,0,0,40,4449,300.2818,682.671325683594,,,,,,,,,,,,,0,,,,-0.0049,,,,,,299.9805908,,,,
,19642155.73,299.9822998,1238.31408691406,2.35920843715451E-5,4.04049329465829E-7,1,0.999253354069792,40.0298881530762,1.99769315641358,14.2400003969669,0.000267269160844618,4.3900565069998E-5,0.25,-2.06540552211968E-7,2.35915327610276E-5,-1.90888012991425E-7,299.9820557,299.9825439,1205.83215332031,1270.79602050781,54.0597732755634,19.5502457470807,28.983419,0,0,0,40,4449,300.2867,1238.31408691406,,,,,,,,,,,,,0,,,,-0.0049,,,,,,299.9822998,,,,
,19642167.39,299.98101805,1819.08679199219,2.55508873453727E-5,3.65932119951495E-7,1,0.999253354069792,40.0298881530762,1.9976969542064,14.2400003969669,0.000288847987922072,5.10809531065371E-5,0.25,8.8850913204018E-8,2.5550083939104E-5,1.05792794180831E-7,299.9804077,299.9816284,1788.93090820313,1849.24267578125,54.0503937333326,19.5469761854462,29.363071,0,0,0,40,4449,300.28625,1819.08679199219,,,,,,,,,,,,,0,,,,0.00245,,,,,,299.98101805,,,,
,19642178.635,299.98236085,2382.4521484375,2.54452882751334E-5,4.59156392531925E-7,1,0.999253354069792,40.0298881530762,1.99766904222875,14.2400003969669,0.000288255622649168,4.73757881757306E-5,0.25,-2.20349383272568E-7,2.54446918712617E-5,-2.03469765318887E-7,299.9822388,299.9824829,2352.22900390625,2412.67529296875,53.7393055826788,19.5470717494023,29.363071,0,0,0,40,4449,300.28695,2382.4521484375,,,,,,,,,,,,,0,,,,-0.00245,,,,,,299.98236085,,,,
,19642190.485,299.9816589,2971.45458984375,2.67436740521003E-5,4.55589891326451E-7,1,0.999253354069792,40.0298881530762,1.99766342376621,14.2400003969669,0.000302693638789542,5.13507150998703E-5,0.25,-9.3887202072252E-8,2.67429567072904E-5,-7.61518220771557E-8,299.9816589,299.9816589,2946.23583984375,2996.67333984375,53.8651477742749,19.550797109086,29.742722,0,0,0,40,4449,300.2889,2971.45458984375,,,,,,,,,,,,,0,,,,-0.00245,,,,,,299.9816589,,,,
,19642202.69,299.98349,3583.9052734375,2.59925670069492E-5,4.48928445252079E-7,1,0.999253354069792,40.0298881530762,1.99763260886146,14.2400003969669,0.000294609203910957,4.7476802183773E-5,0.25,-3.06164205084328E-7,2.59920107283311E-5,-2.88922287476989E-7,299.98349,299.98349,3581.57861328125,3586.23193359375,53.9683227388134,19.5493095108538,29.363071,0,0,0,40,4449,300.2915,3583.9052734375,,,,,,,,,,,,,0,,,,0,,,,,,299.98349,,,,
,19642214.45,299.9834137,4172.03662109375,2.5808898125555E-5,4.89886567335472E-7,1,0.999253354069792,40.0298881530762,1.99767907422036,14.2400003969669,0.000292296898921516,4.85104370767904E-5,0.25,-1.83054633852595E-7,2.58082657868805E-5,-1.65939594966821E-7,299.9830933,299.9837341,4142.17333984375,4201.89990234375,53.8753089450249,19.5496907376645,29.742722,0,0,0,40,4449,300.2925,4172.03662109375,,,,,,,,,,,,,0,,,,0.00245,,,,,,299.9834137,,,,
,19642226.745,299.9833069,4784.9765625,2.40742311936688E-5,4.92691353924317E-7,1,0.999253354069792,40.0298881530762,1.9976144940853,14.2400003969669,0.000272890012104933,4.38207952462867E-5,0.25,-2.96975602013206E-7,2.40737252406317E-5,-2.8100867655408E-7,299.9833069,299.9833069,4782.4013671875,4787.5517578125,53.6947527570826,19.5504518872846,28.983419,0,0,0,40,4449,300.2928,4784.9765625,,,,,,,,,,,,,0,,,,0,,,,,,299.9833069,,,,
,19642237.68,299.98480225,5332.37036132812,2.30123657490135E-5,4.93715362489778E-7,1,0.999253354069792,40.0298881530762,1.99766620269786,14.2400003969669,0.000260902043048858,4.16452782294583E-5,0.25,-3.05420140212778E-7,2.30118952567465E-5,-2.90158138113947E-7,299.984436,299.9851685,5302.5390625,5362.20166015625,53.9792655380826,19.5491415336815,29.363071,0,0,0,40,4449,300.2934,5332.37036132812,,,,,,,,,,,,,0,,,,0.00245,,,,,,299.98480225,,,,
,19642250.22,299.9857178,5959.4033203125,2.16790756411976E-5,4.952620618024E-7,1,0.999253354069792,40.0298881530762,1.9976017072644,14.2400003969669,0.000245570404638367,4.04312742489641E-5,0.25,-1.81628393898464E-7,2.16785615018578E-5,-1.67255323657548E-7,299.9857178,299.9857178,5932.04052734375,5986.76611328125,53.9995878795826,19.5481928525677,28.983419,0,0,0,40,4449,300.2968,5959.4033203125,,,,,,,,,,,,,0,,,,0,,,,,,299.9857178,,,,
,19642261.57,299.9857788,6526.81396484375,2.01649224193383E-5,5.60385334958065E-7,1,0.999253354069792,40.0298881530762,1.99762827298567,14.2400003969669,0.000227785703829524,4.127856942716E-5,0.25,1.55575866967681E-7,2.01642291890167E-5,1.68934364294263E-7,299.9854431,299.9861145,6496.80078125,6556.8271484375,53.6705222729865,19.5470279412056,29.742722,0,0,0,40,4449,300.29695,6526.81396484375,,,,,,,,,,,,,0,,,,0.00245,,,,,,299.9857788,,,,
,19642273.075,299.98506165,7104.06298828125,1.88123599234153E-5,5.90860395113825E-7,1,0.999253354069792,40.0298881530762,1.99756569938701,14.2400003969669,0.000212772088254175,3.69418723281115E-5,0.25,6.62203798266248E-9,1.88118055834874E-5,1.90873210683221E-8,299.9845581,299.9855652,7076.50341796875,7131.62255859375,53.5595310232557,19.5472460901257,28.983419,0,0,0,40,4449,300.29885,7104.06298828125,,,,,,,,,,,,,0,,,,-0.00245,,,,,,299.98506165,,,,
,19642284.595,299.9855042,7678.708984375,1.74695115376321E-5,4.20277240542402E-7,1,0.999253354069792,40.0298881530762,1.99757582932361,14.2400003969669,0.000199207239824513,2.4942695448713E-5,0.25,-8.21575672690558E-7,1.7469545006781E-5,-8.09977107044568E-7,299.9855042,299.9855042,7651.447265625,7705.970703125,53.9386208550826,19.5498424477611,29.742722,0,0,0,40,4449,300.3,7678.708984375,,,,,,,,,,,,,0,,,,-0.00245,,,,,,299.9855042,,,,
,19642296.26,299.98709105,8260.91064453125,1.52726489715473E-5,6.53214906210175E-7,1,0.999253354069792,40.0298881530762,1.9976027016677,14.2400003969669,0.000171225270103991,3.87351421879949E-5,0.25,7.78394424964024E-7,1.52716858817778E-5,7.8848963521484E-7,299.9867859,299.9873962,8230.865234375,8290.9560546875,54.1840522101211,19.5498263665397,29.742722,0,0,0,40,4449,300.30015,8260.91064453125,,,,,,,,,,,,,0,,,,-0.00245,,,,,,299.98709105,,,,
,19642307.83,299.9872131,8838.259765625,1.41971153626835E-5,5.60719902179243E-7,1,0.999253354069792,40.0298881530762,1.99760019515696,14.2400003969669,0.000160918240180633,2.58997531224074E-5,0.25,-1.70014651271911E-7,1.41968121027701E-5,-1.60605097623832E-7,299.9872131,299.9872131,8810.708984375,8865.810546875,54.0410141911019,19.5483261728928,29.742722,0,0,0,40,4449,300.30005,8838.259765625,,,,,,,,,,,,,0,,,,0,,,,,,299.9872131,,,,
,19642319.475,299.98742675,9423.4853515625,1.36215619508747E-5,6.06962061714295E-7,1,0.999253354069792,40.0298881530762,1.9975615708936,14.2400003969669,0.000155270003823326,1.97802236528781E-5,0.25,-6.11281270931592E-7,1.36215677952248E-5,-6.02240968147563E-7,299.9873657,299.9874878,9390.8515625,9456.119140625,54.1559135834288,19.5482206307928,29.363071,0,0,0,40,4449,300.30055,9423.4853515625,,,,,,,,,,,,,0,,,,-0.00245,,,,,,299.98742675,,,,
,19642331.475,299.9889984,10022.9931640625,1.17420401469756E-5,6.71124310888413E-7,1,0.999253354069792,40.0298881530762,1.99755754020084,14.2400003969669,0.000134334021332949,1.42305382113949E-5,0.25,-7.76283466409497E-7,1.17422097009427E-5,-7.68484083751068E-7,299.9888611,299.9891357,9990.59375,10055.392578125,53.9902083373519,19.5502555054294,29.742722,0,0,0,40,4449,300.30275,10022.9931640625,,,,,,,,,,,,,0,,,,0,,,,,,299.9889984,,,,
,19642343.515,299.988678,10622.666015625,8.61533352457341E-6,7.42516266973971E-7,1,0.999253354069792,40.0298881530762,1.99758503482963,14.2400003969669,9.79676699902022E-5,1.38857110179508E-5,0.25,-2.65055763730545E-7,8.61525638468713E-6,-2.59342735125507E-7,299.9886475,299.9887085,10590.1611328125,10655.1708984375,54.1441891556403,19.5465394048295,29.742722,0,0,0,40,4449,300.3016,10622.666015625,,,,,,,,,,,,,0,,,,0,,,,,,299.988678,,,,
,19642355.39,299.98854065,11217.2607421875,6.87897581345011E-6,8.34306437494121E-7,1,0.999253354069792,40.0298881530762,1.99753985057897,14.2400003969669,7.82200536478704E-5,1.1094169995175E-5,0.25,-2.10993138356253E-7,6.87891385942749E-6,-2.06432063973122E-7,299.9883728,299.9887085,11184.9794921875,11249.5419921875,53.9823920521596,19.5485506932184,29.742722,0,0,0,40,4449,300.30365,11217.2607421875,,,,,,,,,,,,,0,,,,0,,,,,,299.98854065,,,,
,19642366.675,299.98950195,11779.6225585938,5.69045298957032E-6,9.23770591982799E-7,1,0.999253354069792,40.0298881530762,1.99753099634891,14.2400003969669,6.37974358896775E-5,1.44167952730385E-5,0.25,2.88692037587432E-7,5.69009487051845E-6,2.92451096810225E-7,299.9890442,299.9899597,11749.8564453125,11809.388671875,53.9136087424672,19.5479478344344,29.742722,0,0,0,40,4449,300.304,11779.6225585938,,,,,,,,,,,,,0,,,,-0.00245,,,,,,299.98950195,,,,
,19642378.495,299.9903259,12371.5268554687,3.76170086114919E-6,9.55563460476353E-7,1,0.999253354069792,40.0298881530762,1.99755019015789,14.2400003969669,4.25141254441113E-5,7.56716882961787E-6,0.25,1.72726076998272E-8,3.76157895556575E-6,1.97623707714779E-8,299.9901428,299.990509,12343.7783203125,12399.275390625,53.9816104236403,19.5502033729431,29.363071,0,0,0,40,4449,300.3049,12371.5268554687,,,,,,,,,,,,,0,,,,0,,,,,,299.9903259,,,,
,19642390.83,299.9907227,12988.73828125,2.87596304821101E-6,8.62421860775417E-7,1,0.999253354069792,40.0298881530762,1.99756004661017,14.2400003969669,3.16578262776697E-5,1.06682272776862E-5,0.25,4.44897148241847E-7,2.87558407886031E-6,4.46787758061878E-7,299.9907227,299.9907227,12963.5908203125,13013.8857421875,53.8760905735442,19.5481690290644,29.742722,0,0,0,40,4449,300.30685,12988.73828125,,,,,,,,,,,,,0,,,,0,,,,,,299.9907227,,,,
,19642403.13,299.9905243,13603.572265625,4.74943090301599E-7,9.38441361613953E-7,1,0.999253354069792,40.0298881530762,1.99753731867102,14.2400003969669,7.07563495103367E-6,-8.90234941401631E-6,0.25,-8.69356616279176E-7,4.75504533087402E-7,-8.69016748161444E-7,299.9898071,299.9912415,13573.8095703125,13633.3349609375,53.9143903709865,19.5503489901506,29.742722,0,0,0,40,4449,300.30625,13603.572265625,,,,,,,,,,,,,0,,,,0,,,,,,299.9905243,,,,
,19642414.7,299.9900208,14180.8588867188,-1.30423799913325E-6,8.35276319416383E-7,1,0.999253354069792,40.0298881530762,1.99748594919701,14.2400003969669,-1.39725710214956E-5,-7.05199061189373E-6,0.25,-3.97521183591338E-7,-1.30393666678172E-6,-3.98372639784779E-7,299.9900208,299.9900208,14158.263671875,14203.4541015625,53.8971945435634,19.548212492562,29.363071,0,0,0,40,4449,300.30795,14180.8588867188,,,,,,,,,,,,,0,,,,-0.00245,,,,,,299.9900208,,,,
,19642426.11,299.99157715,14750.5170898438,-3.0572205054916E-6,8.00204593846589E-7,1,0.999253354069792,40.0298881530762,1.99748235965201,14.2400003969669,-3.26386046029736E-5,-1.71881262766121E-5,0.25,-9.89976624985604E-7,-3.05647558639225E-6,-9.91970535389667E-7,299.9906616,299.9924927,14718.314453125,14782.7197265625,53.9354943410057,19.5487298344008,29.742722,0,0,0,40,4449,300.3066,14750.5170898438,,,,,,,,,,,,,0,,,,0.00245,,,,,,299.99157715,,,,
,19642437.375,299.99263,15315.3813476562,-5.56888089171222E-6,7.69256822653879E-7,1,0.999253354069792,40.0298881530762,1.9975750086174,14.2400003969669,-6.09294060547782E-5,-2.28033778298995E-5,0.25,-1.0511869234105E-6,-5.56802156599175E-6,-1.05484058771369E-6,299.9920654,299.9931946,15283.11328125,15347.6494140625,54.078532360025,19.5496331019654,29.363071,0,0,0,40,4449,300.3081,15315.3813476562,,,,,,,,,,,,,0,,,,0,,,,,,299.99263,,,,
,19642449.245,299.991806,15909.9453125,-7.38259118922999E-6,1.0855059671469E-6,1,0.999253354069792,40.0298881530762,1.99750081230147,14.2400003969669,-8.30013272834734E-5,-1.73529870595245E-5,0.25,-2.55133907921139E-7,-7.38220549743107E-6,-2.60010458869253E-7,299.9915161,299.9920959,15882.6787109375,15937.2119140625,53.7783870086403,19.5469707539136,29.742722,0,0,0,40,4449,300.30875,15909.9453125,,,,,,,,,,,,,0,,,,0.00245,,,,,,299.991806,,,,
,19642461.47,299.9919434,16519.8037109375,-1.06081314593206E-5,1.04654225136521E-6,1,0.999253354069792,40.0298881530762,1.99744950984781,14.2400003969669,-0.000119581033045594,-2.30964936628883E-5,0.25,-2.04133764505874E-7,-1.06076847756561E-5,-2.11144896674828E-7,299.9919434,299.9919434,16497.318359375,16542.2890625,53.5806349932749,19.5480484033161,28.983419,0,0,0,40,4449,300.30875,16519.8037109375,,,,,,,,,,,,,0,,,,0,,,,,,299.9919434,,,,
,19642473.055,299.9938812,17098.931640625,-1.01749300966521E-5,1.04347135167032E-6,1,0.999253354069792,40.0298881530762,1.99748038478909,14.2400003969669,-0.00011625289626215,-1.31873721360549E-5,0.25,5.96942534029038E-7,-1.01750253550272E-5,5.90195118061372E-7,299.9931335,299.9946289,17066.44140625,17131.421875,54.251272262775,19.548764462653,29.742722,0,0,0,40,4449,300.30815,17098.931640625,,,,,,,,,,,,,0,,,,-0.00245,,,,,,299.9938812,,,,
,19642484.98,299.9944153,17696.3779296875,-1.21739812208803E-5,9.48162059391107E-7,1,0.999253354069792,40.0298881530762,1.9975095295317,14.2400003969669,-0.000138771543512385,-1.76444685439319E-5,0.25,5.49246130885774E-7,-1.21739858872158E-5,5.41178899524764E-7,299.9944153,299.9944153,17666.26953125,17726.486328125,54.0402325625826,19.5485129835118,29.742722,0,0,0,40,4449,300.31,17696.3779296875,,,,,,,,,,,,,0,,,,0,,,,,,299.9944153,,,,
,19642496.4,299.99435425,18266.3115234375,-1.42188720224128E-5,1.00761347855052E-6,1,0.999253354069792,40.0298881530762,1.99750761581953,14.2400003969669,-0.000160325087796417,-3.07438454207975E-5,0.25,-2.54612903614316E-7,-1.42182849840131E-5,-2.6400777492172E-7,299.9942627,299.9944458,18241.232421875,18291.390625,53.9190801421018,19.547970056305,29.742722,0,0,0,40,4449,300.30995,18266.3115234375,,,,,,,,,,,,,0,,,,-0.0049,,,,,,299.99435425,,,,
,19642508.6,299.994751,18875.689453125,-1.66095901028195E-5,1.04075060266326E-6,1,0.999253354069792,40.0298881530762,1.99745436563326,14.2400003969669,-0.000185009237734043,-4.9000464851595E-5,0.25,-1.45462909882388E-6,-1.66081391356854E-5,-1.46556824321698E-6,299.994751,299.994751,18845.748046875,18905.630859375,53.9948981084673,19.5479808053571,28.983419,0,0,0,40,4449,300.309,18875.689453125,,,,,,,,,,,,,0,,,,-0.0049,,,,,,299.994751,,,,
,19642521.335,299.9937134,19512.8251953125,-1.99871555283542E-5,1.14660021456677E-6,1,0.999253354069792,40.0298881530762,1.99749049725683,14.2400003969669,-0.000223772678128042,-5.23980816922669E-5,0.25,-1.16976113569934E-6,-1.99857944376489E-5,-1.18294017135593E-6,299.9937134,299.9937134,19510.365234375,19515.28515625,53.8471703183326,19.5481915718207,29.363071,0,0,0,40,4449,300.31065,19512.8251953125,,,,,,,,,,,,,0,,,,0,,,,,,299.9937134,,,,
,19642532.465,299.9960938,20067.40234375,-2.12007946808823E-5,1.42376072670822E-6,1,0.999253354069792,40.0298881530762,1.99745593095406,14.2400003969669,-0.000237107230753637,-5.70171419442358E-5,0.25,-1.36796048005642E-6,-2.11992652899255E-5,-1.38193441282568E-6,299.9960938,299.9960938,20034.8359375,20099.96875,53.9675411102942,19.546533390637,28.983419,0,0,0,40,4449,300.3099,20067.40234375,,,,,,,,,,,,,0,,,,0,,,,,,299.9960938,,,,
,19642544.615,299.9955902,20672.0869140625,-2.28471508078088E-5,1.32064006058158E-6,1,0.999253354069792,40.0298881530762,1.99745857332089,14.2400003969669,-0.000257809454790107,-4.82319878164277E-5,0.25,-3.05975598897412E-7,-2.28462754686288E-5,-3.21067351972287E-7,299.9955444,299.995636,20644.400390625,20699.7734375,53.9558166825057,19.5485148973042,29.742722,0,0,0,40,4449,300.30935,20672.0869140625,,,,,,,,,,,,,0,,,,-0.00245,,,,,,299.9955902,,,,
,19642557.255,299.9965973,21306.5498046875,-2.40460514376257E-5,1.1814963934262E-6,1,0.999253354069792,40.0298881530762,1.99750166753154,14.2400003969669,-0.00027575134040015,-2.53232606717882E-5,0.25,1.9272543895262E-6,-2.40466159754926E-5,1.91130648182671E-6,299.9964905,299.9967041,21284.08203125,21329.017578125,54.0089674218134,19.5502077561768,29.742722,0,0,0,40,4449,300.3107,21306.5498046875,,,,,,,,,,,,,0,,,,0.00245,,,,,,299.9965973,,,,
,19642568.645,299.9957886,21876.1953125,-2.53727191589752E-5,1.47976107018951E-6,1,0.999253354069792,40.0298881530762,1.99741492958096,14.2400003969669,-0.000287675916193183,-4.56340209948148E-5,0.25,3.61208097163139E-7,-2.53722105215193E-5,3.44431598566744E-7,299.9957886,299.9957886,21848.66015625,21903.73046875,53.8987578006019,19.549598069239,28.983419,0,0,0,40,4449,300.3112,21876.1953125,,,,,,,,,,,,,0,,,,-0.00245,,,,,,299.9957886,,,,
,19642580.785,299.9966431,22483.6435546875,-2.73447388814901E-5,1.96936236796875E-6,1,0.999253354069792,40.0298881530762,1.99744195226478,14.2400003969669,-0.000309901064404479,-4.99756701519336E-5,0.25,3.19056253017839E-7,-2.73441436358333E-5,3.00980055585074E-7,299.9966431,299.9966431,22453.56640625,22513.720703125,54.2129724653327,19.5502481320075,29.363071,0,0,0,40,4449,300.3101,22483.6435546875,,,,,,,,,,,,,0,,,,0,,,,,,299.9966431,,,,
,19642592.39,299.9985046,23060.9931640625,-2.90585293259519E-5,1.37135362816566E-6,1,0.999253354069792,40.0298881530762,1.99744710555481,14.2400003969669,-0.00032872379263116,-5.65747392053599E-5,0.25,3.25334785567732E-8,-2.90576925103862E-5,1.33356499390431E-8,299.9985046,299.9985046,23038.568359375,23083.41796875,53.8768722020634,19.5497856028007,29.363071,0,0,0,40,4449,300.3098,23060.9931640625,,,,,,,,,,,,,0,,,,0,,,,,,299.9985046,,,,
,19642604.39,299.9961243,23660.4052734375,-3.17535911200506E-5,1.37198111607999E-6,1,0.999253354069792,40.0298881530762,1.99741268378299,14.2400003969669,-0.000359662933999178,-5.91819225397482E-5,0.25,2.68869552013844E-7,-3.1752833752132E-5,2.47886879905155E-7,299.9961243,299.9961243,23632.935546875,23687.875,54.0503937333326,19.5490385383688,29.363071,0,0,0,40,4449,300.3095,23660.4052734375,,,,,,,,,,,,,0,,,,0.00245,,,,,,299.9961243,,,,
,19642616.405,299.9974213,24260.1123046875,-3.46856420913167E-5,1.60630655432841E-6,1,0.999253354069792,40.0298881530762,1.99743262667072,14.2400003969669,-0.000390819242592579,-7.65246288738136E-5,0.25,-7.56453828958532E-7,-3.46841198323094E-5,-7.79340058427278E-7,299.9971619,299.9976807,24232.865234375,24287.359375,54.0535202474096,19.5492291208734,29.742722,0,0,0,40,4449,300.31125,24260.1123046875,,,,,,,,,,,,,0,,,,0.00245,,,,,,299.9974213,,,,
,19642628.32,299.9994507,24857.2080078125,-3.78207508906117E-5,2.01441320758991E-6,1,0.999253354069792,40.0298881530762,1.99740074235346,14.2400003969669,-0.000430289513652108,-5.94753558300995E-5,0.25,1.29406666569376E-6,-3.78204878959222E-5,1.26905225446588E-6,299.9994507,299.9994507,24827.171875,24887.244140625,53.8682742883518,19.5510271546503,29.742722,0,0,0,40,4449,300.3102,24857.2080078125,,,,,,,,,,,,,0,,,,0,,,,,,299.9994507,,,,
,19642640.51,299.9984131,25469.6298828125,-3.84533953648097E-5,1.76173604307527E-6,1,0.999253354069792,40.0298881530762,1.99737374716334,14.2400003969669,-0.000435017705911267,-7.46901118733805E-5,0.25,5.83436564787204E-8,-3.84522993524302E-5,3.2951300210336E-8,299.9984131,299.9984131,25466.9765625,25472.283203125,53.9651962247365,19.5469966200884,29.363071,0,0,0,40,4449,300.3112,25469.6298828125,,,,,,,,,,,,,0,,,,0.0049,,,,,,299.9984131,,,,
,19642651.765,299.9984131,26029.140625,-3.99605222278929E-5,1.79987931318875E-6,1,0.999253354069792,40.0298881530762,1.997372327733,14.2400003969669,-0.000451450105620334,-8.11798068538306E-5,0.25,-2.54351635333419E-7,-3.99591755655329E-5,-2.80726918898564E-7,299.9978943,299.9989319,25996.6171875,26061.6640625,54.0902567878134,19.5499376659088,29.363071,0,0,0,40,4449,300.31045,26029.140625,,,,,,,,,,,,,0,,,,0,,,,,,299.9984131,,,,
,19642664.445,299.9984436,26663.740234375,-4.30251559539246E-5,9.93362590951767E-7,1,0.999253354069792,40.0298881530762,1.99737268577911,14.2400003969669,-0.000485935358910831,-8.81977124927374E-5,0.25,-3.43896866011656E-7,-4.30236600879546E-5,-3.72289140275509E-7,299.9984436,299.9984436,26641.15234375,26686.328125,54.0136571929288,19.5481577380665,29.363071,0,0,0,40,4449,300.30985,26663.740234375,,,,,,,,,,,,,0,,,,0.00245,,,,,,299.9984436,,,,
,19642676.525,299.9985046,27266.5498046875,-4.7072310890775E-5,1.3473498264084E-6,1,0.999253354069792,40.0298881530762,1.99735978494136,14.2400003969669,-0.000528804760033485,-0.000112866611274152,0.25,-1.82394739613533E-6,-4.70697190113037E-5,-1.85496398717514E-6,299.9983215,299.9986877,27236.650390625,27296.44921875,54.0316346488711,19.5492616508458,29.363071,0,0,0,40,4449,300.308,27266.5498046875,,,,,,,,,,,,,0,,,,0,,,,,,299.9985046,,,,
,19642689.045,299.99986265,27893.587890625,-4.72618689075814E-5,1.68457583598698E-6,1,0.999253354069792,40.0298881530762,1.99737774990386,14.2400003969669,-0.000534053427205569,-9.53449413503541E-5,0.25,-2.41791910656529E-7,-4.72603138549549E-5,-2.72975933615509E-7,299.9998474,299.9998779,27861.4140625,27925.76171875,54.0511753618519,19.5483420268555,29.363071,0,0,0,40,4449,300.3096,27893.587890625,,,,,,,,,,,,,0,,,,-0.00245,,,,,,299.99986265,,,,
,19642700.64,299.9985962,28473.251953125,-4.99714945719221E-5,1.49066986959788E-6,1,0.999253354069792,40.0298881530762,1.99736909659861,14.2400003969669,-0.000565755289240782,-9.45442931609662E-5,0.25,2.98421919552623E-7,-4.99702186422889E-5,2.65437686360229E-7,299.9985962,299.9985962,28445.8046875,28500.69921875,53.9464371402749,19.5496766471324,29.363071,0,0,0,40,4449,300.30905,28473.251953125,,,,,,,,,,,,,0,,,,-0.00245,,,,,,299.9985962,,,,
,19642712.785,300.0001831,29077.8701171875,-4.96983861796629E-5,1.81114553152087E-6,1,0.999253354069792,40.0298881530762,1.99736411464415,14.2400003969669,-0.000563098840871403,-9.15054687283401E-5,0.25,5.19768462900011E-7,-4.96972618560314E-5,4.86962021466862E-7,300.0001831,300.0001831,29050.416015625,29105.32421875,53.983955309198,19.5511136001756,29.363071,0,0,0,40,4449,300.30825,29077.8701171875,,,,,,,,,,,,,0,,,,-0.0049,,,,,,300.0001831,,,,
,19642725.43,299.9997559,29709.85546875,-5.25046198177831E-5,1.61416729361169E-6,1,0.999253354069792,40.0298881530762,1.99736993697301,14.2400003969669,-0.00059140384039599,-0.00011682893847187,0.25,-1.23307690686074E-6,-5.25022574872654E-5,-1.26767816588623E-6,299.9997559,299.9997559,29705.00390625,29714.70703125,53.9284596843326,19.5517473938828,28.983419,0,0,0,40,4449,300.31075,29709.85546875,,,,,,,,,,,,,0,,,,0,,,,,,299.9997559,,,,
,19642731.52,300.001297,29997.3955078125,-5.52370152243301E-5,1.38374840346143E-6,1,0.999253354069792,40.0298881530762,1.99727814529155,14.2400003969669,-0.000623431864573526,-0.000115526678781877,0.25,-6.44979444412314E-7,-5.52349574200251E-5,-6.81398455243339E-7,300.0010986,300.0014954,29995.38671875,29999.404296875,53.882343601698,19.5487469234363,29.742722,0,0,0,40,4417,300.31,29997.3955078125,,,,,,,,,,,,,0,,,,0.00245,,,,,,300.001297,,,,