File: data/monolayers/magneticStructure/ML_Ac_CoFe_C/PPMS/ZFC_FC/DD205_4_KOELNPPMS_ZFCW_100OE_TOUCHDOWN.DAT
[Header]
; VSM Data File (default extension .dat)
; Copyright (c) 2003-2013, Quantum Design, Inc. All rights reserved.
TITLE,
FILEOPENTIME,19824194.41,08/18/2018,10:41 am
BYAPP,VSM,2.0,2.0
INFO,PPMS VSM Option Release 1.4.10 Build 1,APPNAME
INFO,Quantum Design Linear Motor Servo Controller,MOTOR_MODULE_NAME
INFO,3101-100 M1,MOTOR_HW_VERSION
INFO,MMC1014,MOTOR_SERIAL_NUMBER
INFO,SRV No X-over 01.03.11,MOTOR_SOFTWARE_VERSION
INFO,Quantum Design VSM Detection Module,VSM_MODULE_NAME
INFO,3101-150 F0,VSM_HW_VERSION
INFO,VSM707,VSM_SERIAL_NUMBER
INFO,VSM No X-over 01.02.05 May 20 2008 13:51:47,VSM_SOFTWARE_VERSION
INFO,704,PREAMP_SERIAL_NUMBER
INFO,822,COIL_SERIAL_NUMBER
INFO,0,MOMENT_UNITS
INFO,,SAMPLE_MATERIAL
INFO,,SAMPLE_COMMENT
INFO,,SAMPLE_MASS
INFO,,SAMPLE_VOLUME
INFO,,SAMPLE_MOLECULAR_WEIGHT
INFO,,SAMPLE_SIZE
INFO,,SAMPLE_SHAPE
DATATYPE,COMMENT,1
DATATYPE,TIME,2
STARTUPAXIS,X,2
STARTUPAXIS,Y1,5
[Data]
Comment,Time Stamp (sec),Temperature (K),Magnetic Field (Oe),Moment (emu),M. Std. Err. (emu),Transport Action,Averaging Time (sec),Frequency (Hz),Peak Amplitude (mm),Center Position (mm),Coil Signal' (mV),Coil Signal" (mV),Range (mV),M. Quad. Signal (emu),M. Raw' (emu),M. Raw" (emu),Min. Temperature (K),Max. Temperature (K),Min. Field (Oe),Max. Field (Oe),Mass (grams),Motor Lag (deg),Pressure (Torr),VSM Status (code),Motor Status (code),Measure Status (code),Measure Count,PPMS Status (code),System Temp. (K),System Field (Oe),Sample Position (deg),Bridge 1 Resistance (ohms),Bridge 1 Excitation (에),Bridge 2 Resistance (ohms),Bridge 2 Excitation (에),Bridge 3 Resistance (ohms),Bridge 3 Excitation (에),Bridge 4 Resistance (ohms),Bridge 4 Excitation (에),Signal 1 Vin (V),Signal 2 Vin (V),Digital Inputs (code),Drive 1 Iout (mA),Drive 1 Ipower (W),Drive 2 Iout (mA),Drive 2 Ipower (W),Pressure (),Map 20 (),Map 21 (),Map 22 (),Map 23 (),Map 24 (),Map 25 (),Map 26 (),Map 27 (),Map 28 (),Map 29 ()
,19832085.47,4.9982357,99.8070526123047,,,2,,,,16.1200003826618,,,,,,,4.9982357,4.9982357,99.8070526123047,99.8070526123047,,,7.343312,,,,-99999999,4373,5.004,99.8070526123047,,,,,,,,,,,,,,,,,,,,,,,4.9982357,,,,
,19832293.21,7.5419517,99.8070526123047,5.35175776466018E-7,2.16282940739674E-7,1,0.999253354069792,40.0298881530762,1.98163340718416,16.1099992692471,6.56291156516952E-6,-2.28691916747138E-6,0.25,-3.00091513868043E-7,5.33551665848986E-7,-2.95788196161457E-7,7.5419517,7.5419517,99.8070526123047,99.8070526123047,53.6165899051595,19.5735499277173,8.482265,0,0,0,40,4370,7.64855,99.8070526123047,,,,,,,,,,,,,0,,,,0.0049,,,,,,7.5419517,,,,
,19832433.975,11.0132475,99.8070526123047,7.66052849379411E-7,3.17094375471419E-7,1,0.999253354069792,40.0298881530762,1.98153045214579,16.1199998110533,9.21150026912676E-6,-2.24747057570817E-6,0.25,-3.37563561934748E-7,7.63280796827206E-7,-3.31930118290203E-7,11.0132475,11.0132475,99.8070526123047,99.8070526123047,53.6752120441018,19.5783363312191,9.621219,0,0,0,40,4370,11.20105,99.8070526123047,,,,,,,,,,,,,0,,,,0.00245,,,,,,11.0132475,,,,
,19832577.805,14.5187016,99.8070526123047,5.7058597775753E-7,2.7597777629324E-7,1,0.999253354069792,40.0298881530762,1.98145420244361,16.1099992692471,7.67051481384567E-6,-6.23387543505176E-6,0.25,-6.60339587464765E-7,5.70488822554452E-7,-6.53789700725404E-7,14.5187016,14.5187016,99.8070526123047,99.8070526123047,54.1027628441211,19.5816211743029,10.38052,0,0,0,40,4374,14.84615,99.8070526123047,,,,,,,,,,,,,0,,,,0,,,,,,14.5187016,,,,
,19832720.1,18.0443363,99.8070526123047,6.68440763011881E-7,2.16264272617575E-7,1,0.999253354069792,40.0298881530762,1.99406036736103,16.0499997437,8.21904606624938E-6,-2.72126184983956E-6,0.25,-3.61256184340139E-7,6.6633311037712E-7,-3.55949832190587E-7,18.0443363,18.0443363,99.8070526123047,99.8070526123047,53.7877665508711,19.5789456870239,10.38052,0,0,0,40,4374,18.41165,99.8070526123047,,,,,,,,,,,,,0,,,,-0.0049,,,,,,18.0443363,,,,
,19832858.475,21.5108852,99.8070526123047,8.56721886587498E-7,2.58690232160181E-7,1,0.999253354069792,40.0298881530762,1.99403140984734,16.0499997437,1.02153345219652E-5,-1.68871345405967E-6,0.25,-3.02722005626912E-7,8.53317595726944E-7,-2.96793285355676E-7,21.5108852,21.5108852,99.8070526123047,99.8070526123047,54.0746242174288,19.5837097486069,11.519473,0,0,0,40,4374,21.88925,99.8070526123047,,,,,,,,,,,,,0,,,,0,,,,,,21.5108852,,,,
,19833001.59,25.0258121,99.8070526123047,3.8324334089614E-7,3.05008109532213E-7,1,0.999253354069792,40.0298881530762,1.99405484691255,16.0499997437,5.07299779155983E-6,-3.5792929587443E-6,0.25,-3.87145656877365E-7,3.83089138024109E-7,-3.83044372319084E-7,25.0258121,25.0258121,99.8070526123047,99.8070526123047,53.780731894198,19.5814433460846,11.899124,0,0,0,40,4374,25.53,99.8070526123047,,,,,,,,,,,,,0,,,,-0.0049,,,,,,25.0258121,,,,
,19833144.545,28.5696564,99.8070526123047,5.45114292198102E-7,2.56699638558028E-7,1,0.999253354069792,40.0298881530762,1.98135714451965,16.0399992018938,7.1914371244226E-6,-5.14970663458141E-6,0.25,-5.58761402369757E-7,5.45256351106243E-7,-5.5287488163432E-7,28.5696564,28.5696564,99.8070526123047,99.8070526123047,53.6408203892557,19.5815585065193,12.658426,0,0,0,40,4374,29.151,99.8070526123047,,,,,,,,,,,,,0,,,,-0.0049,,,,,,28.5696564,,,,
,19833284.23,32.0205307,99.8070526123047,6.6048306549052E-7,2.81458307336277E-7,1,0.999253354069792,40.0298881530762,1.98157833079652,16.0499997437,7.93610792661794E-6,-1.8472336718803E-6,0.25,-2.83455664789535E-7,6.58913916471704E-7,-2.78261755387463E-7,32.0205307,32.0205307,99.8070526123047,99.8070526123047,54.0191285925634,19.5818992918908,13.038077,0,0,0,40,4374,32.6713,99.8070526123047,,,,,,,,,,,,,0,,,,0,,,,,,32.0205307,,,,
,19833426.065,35.5064201,99.8070526123047,3.13147337529915E-7,2.27895320101693E-7,1,0.999253354069792,40.0298881530762,1.98140747982916,16.0399992018938,4.47945897662131E-6,-4.86543324988571E-6,0.25,-4.91828967395138E-7,3.14876080786E-7,-4.87780777259068E-7,35.5064201,35.5064201,99.8070526123047,99.8070526123047,53.9831736806788,19.5830274465737,13.797379,0,0,0,40,4374,36.26075,99.8070526123047,,,,,,,,,,,,,0,,,,-0.00245,,,,,,35.5064201,,,,
,19833569.345,39.0433884,99.8070526123047,7.03507351627023E-7,3.15348186818675E-7,1,0.999253354069792,40.0298881530762,1.9817591854023,16.0199999809265,8.52128066034036E-6,-2.26339612717019E-6,0.25,-3.28819611125438E-7,7.0325867898578E-7,-3.22968117413373E-7,39.0433884,39.0433884,99.8070526123047,99.8070526123047,53.9597248251019,19.5805148231009,13.797379,0,0,0,40,4374,39.88775,99.8070526123047,,,,,,,,,,,,,0,,,,0,,,,,,39.0433884,,,,
,19833710.625,42.5301704,99.8070526123047,3.22704515664043E-7,2.61412117434054E-7,1,0.999253354069792,40.0298881530762,1.98167124445283,16.0199999809265,4.43962862968195E-6,-3.96651448627566E-6,0.25,-4.12701668254606E-7,3.24809466749429E-7,-4.09369312997299E-7,42.5301704,42.5301704,99.8070526123047,99.8070526123047,54.0699344463134,19.5846586538281,14.936333,0,0,0,40,4374,43.47155,99.8070526123047,,,,,,,,,,,,,0,,,,0,,,,,,42.5301704,,,,
,19833853.4,46.020546,99.8070526123047,8.45834299965875E-7,2.63889601465352E-7,1,0.999253354069792,40.0298881530762,1.98172792477463,16.0199999809265,9.42777302268667E-6,1.94218526337854E-6,0.25,2.10739454957477E-8,8.44454538136455E-7,2.7260968684599E-8,46.020546,46.020546,99.8070526123047,99.8070526123047,54.0527386188903,19.5809460528203,15.315984,0,0,0,40,4374,47.11025,99.8070526123047,,,,,,,,,,,,,0,,,,-0.0049,,,,,,46.020546,,,,
,19833997.705,49.5256996,99.8070526123047,7.33540058619799E-7,2.53848937975014E-7,1,0.999253354069792,40.0298881530762,1.98172803488733,15.939999371767,9.00130861344228E-6,-2.83884628985351E-6,0.25,-3.85480990657867E-7,7.36199819036024E-7,-3.79912473167024E-7,49.5256996,49.5256996,99.8070526123047,99.8070526123047,53.8018358642172,19.5844512822189,15.695635,0,0,0,40,4374,50.81195,99.8070526123047,,,,,,,,,,,,,0,,,,0,,,,,,49.5256996,,,,
,19834143.79,53.0843391,99.8070526123047,4.20616338066517E-7,2.70175741871176E-7,1,0.999253354069792,40.0298881530762,1.9819326690511,15.9499999135733,5.14122620412994E-6,-1.48378221069157E-6,0.25,-2.07973524442368E-7,4.22504334381934E-7,-2.05064724064317E-7,53.0843391,53.0843391,99.8070526123047,99.8070526123047,54.0339795344288,19.5806292674614,16.454937,0,0,0,40,4374,54.5489,99.8070526123047,,,,,,,,,,,,,0,,,,0.0049,,,,,,53.0843391,,,,
,19834286.535,56.5308342,99.8070526123047,5.8465096089516E-7,2.60056786300925E-7,1,0.999253354069792,40.0298881530762,1.98175458195671,15.939999371767,6.65356463283398E-6,7.06650830224918E-7,0.25,-4.2258148311733E-8,5.86046469598505E-7,-3.81960509999749E-8,56.5308342,56.5308342,99.8070526123047,99.8070526123047,53.8737456879865,19.5832051479486,16.075285,0,0,0,40,4374,58.1918,99.8070526123047,,,,,,,,,,,,,0,,,,0,,,,,,56.5308342,,,,
,19834408.16,59.5235214,99.8070526123047,9.91795583604996E-7,2.59542274846666E-7,1,0.999253354069792,40.0298881530762,1.98175576422089,15.9499999135733,1.15716636994068E-5,-3.39712162880503E-7,0.25,-2.08285943982873E-7,9.9581653566355E-7,-2.02113192108033E-7,59.5235214,59.5235214,99.8070526123047,99.8070526123047,53.9159536280249,19.5788380356067,17.214239,0,0,0,40,4374,61.298,99.8070526123047,,,,,,,,,,,,,0,,,,-0.0049,,,,,,59.5235214,,,,
,19834551.005,63.0049667,99.8070526123047,9.69813711363447E-7,2.96710330912024E-7,1,0.999253354069792,40.0298881530762,1.98178263310724,15.9600004553795,1.10361504397637E-5,1.26769438155956E-6,0.25,-6.10447658055199E-8,9.73478586866648E-7,-5.50867642004687E-8,63.0049667,63.0049667,99.8070526123047,99.8070526123047,54.1324647278519,19.579962761532,17.973541,0,0,0,40,4374,64.946,99.8070526123047,,,,,,,,,,,,,0,,,,0,,,,,,63.0049667,,,,
,19834696.445,66.5162354,99.8070526123047,5.61915160984882E-7,2.68666006082008E-7,1,0.999253354069792,40.0298881530762,1.98171303854364,15.9499999135733,7.28678346833283E-6,-4.24105824877301E-6,0.25,-4.77020382192106E-7,5.66973564953628E-7,-4.75608404825825E-7,66.5162354,66.5162354,99.8070526123047,99.8070526123047,54.2825374035442,19.582399631987,18.732843,0,0,0,40,4374,68.66995,99.8070526123047,,,,,,,,,,,,,0,,,,-0.0049,,,,,,66.5162354,,,,
,19834840.88,70.0068741,99.8070526123047,7.42326134322548E-7,2.99267289315943E-7,1,0.999253354069792,40.0298881530762,1.98178598677149,15.9099996089935,8.72581783476781E-6,-5.42463225766569E-7,0.25,-1.80409191092702E-7,7.46628655499244E-7,-1.77167639696061E-7,70.0068741,70.0068741,99.8070526123047,99.8070526123047,54.1840522101211,19.577448165251,19.492144,0,0,0,40,4374,72.38855,99.8070526123047,,,,,,,,,,,,,0,,,,0,,,,,,70.0068741,,,,
,19834982.68,73.5150604,99.8070526123047,6.49501366598589E-7,2.86083475927514E-7,1,0.999253354069792,40.0298881530762,1.98185838341976,15.9099996089935,7.9213114415506E-6,-2.07497190359895E-6,0.25,-2.99529682727816E-7,6.54145931273941E-7,-2.97700504845647E-7,73.5150604,73.5150604,99.8070526123047,99.8070526123047,54.136372870448,19.5813273374392,19.492144,0,0,0,40,4374,75.9899,99.8070526123047,,,,,,,,,,,,,0,,,,0,,,,,,73.5150604,,,,
,19835125.705,77.0453949,99.8070526123047,4.31959262533752E-7,2.42956971771069E-7,1,0.999253354069792,40.0298881530762,1.98178357215701,15.9099996089935,4.94895492184076E-6,4.21484149901539E-7,0.25,-3.92289183309824E-8,4.34343957367351E-7,-3.74162691228433E-8,77.0453949,77.0453949,99.8070526123047,99.8070526123047,54.126211699698,19.5787843745147,19.492144,0,0,0,40,4374,79.6134,99.8070526123047,,,,,,,,,,,,,0,,,,0,,,,,,77.0453949,,,,
,19835269.46,80.58656695,99.8070526123047,6.63936785397579E-7,2.71268466748479E-7,1,0.999253354069792,40.0298881530762,1.98170238847737,15.8699993044138,8.12619593021333E-6,-2.28144470921457E-6,0.25,-3.19806985999158E-7,6.68834909480998E-7,-3.18640537311888E-7,80.5473862,80.6257477,99.8070526123047,99.8070526123047,54.1879603527173,19.5810404021768,20.251448,0,0,0,40,4374,83.2482,99.8070526123047,,,,,,,,,,,,,0,,,,0.00245,,,,,,80.58656695,,,,
,19835408.585,84.037323,99.8070526123047,9.68732312170499E-7,2.81174685109079E-7,1,0.999253354069792,40.0298881530762,1.98164994663858,15.8699993044138,1.19132454194487E-5,-3.6506048455222E-6,0.25,-4.94798192298886E-7,9.75989727496345E-7,-4.93611774535022E-7,84.037323,84.037323,99.8070526123047,99.8070526123047,54.4271386796019,19.5823827513228,19.492144,0,0,0,40,4374,86.76,99.8070526123047,,,,,,,,,,,,,0,,,,-0.0049,,,,,,84.037323,,,,
,19835550.625,87.5410843,99.8070526123047,1.21606861489946E-6,2.25082158463453E-7,1,0.999253354069792,40.0298881530762,1.98160768952362,15.8699993044138,1.38137337966768E-5,1.88216872496135E-6,0.25,-4.76704674004421E-8,1.22299694156388E-6,-4.34027191152105E-8,87.5410843,87.5410843,99.8070526123047,99.8070526123047,54.0996363300442,19.5851697657637,19.871798,0,0,0,40,4374,90.34205,99.8070526123047,,,,,,,,,,,,,0,,,,0,,,,,,87.5410843,,,,
,19835694.85,91.0823517,99.8070526123047,1.06617886687296E-6,2.45202548323886E-7,1,0.999253354069792,40.0298881530762,1.99427100080285,15.8099997788668,1.30499368392415E-5,-3.24604660594927E-6,0.25,-4.73748182169526E-7,1.07382124278089E-6,-4.72711301429239E-7,91.0823517,91.0823517,99.8070526123047,99.8070526123047,54.2184438649673,19.5788308008199,20.631098,0,0,0,40,4374,93.9986,99.8070526123047,,,,,,,,,,,,,0,,,,-0.00245,,,,,,91.0823517,,,,
,19835835.405,94.5578232,99.8070526123047,8.19383103369041E-7,2.73671439723031E-7,1,0.999253354069792,40.0298881530762,1.99436861549605,15.8099997788668,1.00011954727889E-5,-2.33600930872036E-6,0.25,-3.49894797397784E-7,8.25166056096274E-7,-3.49217704132961E-7,94.5578232,94.5578232,99.8070526123047,99.8070526123047,54.220788750525,19.5802360605536,21.01075,0,0,0,40,4374,97.58855,99.8070526123047,,,,,,,,,,,,,0,,,,-0.00245,,,,,,94.5578232,,,,
,19835977.67,98.0274811,99.8070526123047,1.21049868709599E-6,2.905635838781E-7,1,0.999253354069792,40.0298881530762,1.99440982664567,15.8099997788668,1.42903107213716E-5,-6.95475956691837E-7,0.25,-2.73935524632224E-7,1.21822705976412E-6,-2.71808820699827E-7,98.0274811,98.0274811,99.8070526123047,99.8070526123047,54.1348096134096,19.5830227327031,21.3904,0,0,0,40,4374,101.19715,99.8070526123047,,,,,,,,,,,,,0,,,,-0.00245,,,,,,98.0274811,,,,
,19836119.465,101.5418701,99.8070526123047,8.14054984168114E-7,2.6637409925408E-7,1,0.999253354069792,40.0298881530762,1.99439459187996,15.760000795126,9.12359058348128E-6,2.30229789029155E-6,0.25,5.98942797267425E-8,8.18523903839416E-7,6.25679366825618E-8,101.5418701,101.5418701,99.8070526123047,99.8070526123047,54.2145357223711,19.5797179954702,21.01075,0,0,0,40,4374,104.78565,99.8070526123047,,,,,,,,,,,,,0,,,,0.0049,,,,,,101.5418701,,,,
,19836259.43,105.0099106,99.8070526123047,5.16374150506798E-7,3.17934309602954E-7,1,0.999253354069792,40.0298881530762,1.99433699137792,15.760000795126,5.83727955895248E-6,1.17452383706751E-6,0.25,1.28997830517795E-8,5.19277922711005E-7,1.43700532922102E-8,105.0099106,105.0099106,99.8070526123047,99.8070526123047,54.2567436624096,19.5797358979019,21.3904,0,0,0,40,4374,108.3055,99.8070526123047,,,,,,,,,,,,,0,,,,0,,,,,,105.0099106,,,,
,19836400.32,108.5110016,99.8070526123047,5.45196062456321E-7,2.65328401624838E-7,1,0.999253354069792,40.0298881530762,1.99440598148564,15.760000795126,6.14893877813911E-6,1.32140252079408E-6,0.25,2.08591185423177E-8,5.48233503017212E-7,2.23728946666544E-8,108.5110016,108.5110016,99.8070526123047,99.8070526123047,54.0081857932942,19.5819152141331,21.3904,0,0,0,40,4374,111.84795,99.8070526123047,,,,,,,,,,,,,0,,,,-0.00245,,,,,,108.5110016,,,,
,19836522.03,111.5074844,99.8070526123047,1.21257259981155E-6,2.66594140411745E-7,1,0.999253354069792,40.0298881530762,1.98151353741325,15.6399998813868,1.43345612031292E-5,-1.32542588138351E-6,0.25,-3.29755970242159E-7,1.22022125956651E-6,-3.28652261786296E-7,111.5074844,111.5074844,99.8070526123047,99.8070526123047,53.9386208550826,19.5785761334591,21.770052,0,0,0,40,4374,114.91485,99.8070526123047,,,,,,,,,,,,,0,,,,0,,,,,,111.5074844,,,,
,19836663.92,115.0356903,99.8070526123047,9.18466146351038E-7,2.36763948315142E-7,1,0.999253354069792,40.0298881530762,1.98168040705495,15.6399998813868,1.13810777468529E-5,-3.99467758078699E-6,0.25,-5.14671721593599E-7,9.24807896439811E-7,-5.15422129430304E-7,115.0356903,115.0356903,99.8070526123047,99.8070526123047,54.0503937333326,19.5771656466471,21.770052,0,0,0,40,4374,118.4793,99.8070526123047,,,,,,,,,,,,,0,,,,0,,,,,,115.0356903,,,,
,19836804.29,118.5568161,99.8070526123047,8.0728036285761E-7,2.07586283952492E-7,1,0.999253354069792,40.0298881530762,1.98157893814537,15.6399998813868,9.94976457760896E-6,-3.21320396024831E-6,0.25,-4.25901605630482E-7,8.12707632613927E-7,-4.26481275095863E-7,118.5568161,118.5568161,99.8070526123047,99.8070526123047,54.4841975615058,19.5825040044334,22.149702,0,0,0,40,4374,122.0028,99.8070526123047,,,,,,,,,,,,,0,,,,0,,,,,,118.5568161,,,,
,19836944.06,122.0028763,99.8070526123047,5.28396005770442E-7,2.77738237205427E-7,1,0.999253354069792,40.0298881530762,1.99399860230918,15.5800003558397,6.31403764309686E-6,-7.60648946271799E-7,0.25,-1.59342440156707E-7,5.31640386212309E-7,-1.59103009009243E-7,122.0028763,122.0028763,99.8070526123047,99.8070526123047,53.9612880821403,19.582919882052,22.149702,0,0,0,40,4374,125.5217,99.8070526123047,,,,,,,,,,,,,0,,,,0.0049,,,,,,122.0028763,,,,
,19837086.74,125.5344391,99.8070526123047,1.02717893128998E-6,2.76653331585866E-7,1,0.999253354069792,40.0298881530762,1.99406546695026,15.5800003558397,1.2312487570006E-5,-1.70164053627661E-6,0.25,-3.29300863626851E-7,1.03343492624387E-6,-3.29019546490813E-7,125.5344391,125.5344391,99.8070526123047,99.8070526123047,54.1246484426596,19.5850194329806,22.529354,0,0,0,40,4374,129.1142,99.8070526123047,,,,,,,,,,,,,0,,,,0.00245,,,,,,125.5344391,,,,
,19837228.99,129.0605621,99.8070526123047,7.12267301223609E-7,2.72042974587388E-7,1,0.999253354069792,40.0298881530762,1.99431739101506,15.5800003558397,8.38891145749726E-6,-3.26009011531422E-7,0.25,-1.53049997665109E-7,7.16393970098452E-7,-1.52496110641142E-7,129.0605621,129.0605621,99.8070526123047,99.8070526123047,54.146534041198,19.5754542690055,22.149702,0,0,0,40,4374,132.69325,99.8070526123047,,,,,,,,,,,,,0,,,,-0.00245,,,,,,129.0605621,,,,
,19837368.44,132.5351257,99.8070526123047,1.07978891065523E-6,3.20952667530309E-7,1,0.999253354069792,40.0298881530762,1.98146741436474,15.6100001186132,1.23413678169069E-5,1.20983553080819E-6,0.25,-8.11593342760505E-8,1.08567282913169E-6,-7.95859671339713E-8,132.5351257,132.5351257,99.8070526123047,99.8070526123047,54.1011995870826,19.5834664365389,22.529354,0,0,0,40,4374,136.19745,99.8070526123047,,,,,,,,,,,,,0,,,,-0.00245,,,,,,132.5351257,,,,
,19837506.945,136.014267,99.8070526123047,9.24693748220835E-7,3.24368635165824E-7,1,0.999253354069792,40.0298881530762,1.98143097191391,15.6100001186132,1.08745925722892E-5,-7.23623604999757E-7,0.25,-2.25420044363999E-7,9.29938565455494E-7,-2.24949553846707E-7,136.014267,136.014267,99.8070526123047,99.8070526123047,54.0636814181596,19.5837644959365,22.909004,0,0,0,40,4374,139.68045,99.8070526123047,,,,,,,,,,,,,0,,,,0.00245,,,,,,136.014267,,,,
,19837649.67,139.5492706,99.8070526123047,9.90227489287947E-7,2.74704144100853E-7,1,0.999253354069792,40.0298881530762,1.98147625945554,15.6100001186132,1.18574779750308E-5,-1.99679924237644E-6,0.25,-3.49653010834349E-7,9.95936861834976E-7,-3.49755888540861E-7,139.5492706,139.5492706,99.8070526123047,99.8070526123047,53.7994909786595,19.5858615231369,23.288654,0,0,0,40,4374,143.2767,99.8070526123047,,,,,,,,,,,,,0,,,,0,,,,,,139.5492706,,,,
,19837791.345,143.0552368,99.8070526123047,7.39073810125989E-7,2.74011070296986E-7,1,0.999253354069792,40.0298881530762,1.99421721107392,15.4699999839067,8.97125436992581E-6,-1.88829905059666E-6,0.25,-2.95192014028245E-7,7.4331619070911E-7,-2.95467435039251E-7,143.0552368,143.0552368,99.8070526123047,99.8070526123047,54.0136571929288,19.5768976450897,23.288654,0,0,0,40,4374,146.83845,99.8070526123047,,,,,,,,,,,,,0,,,,0,,,,,,143.0552368,,,,
,19837930.01,146.5130463,99.8070526123047,1.26812303789879E-6,2.74283746856276E-7,1,0.999253354069792,40.0298881530762,1.99435589868258,15.4699999839067,1.49105659041796E-5,-4.73356727509471E-7,0.25,-2.62638405777438E-7,1.27487910414158E-6,-2.61922299221875E-7,146.5130463,146.5130463,99.8070526123047,99.8070526123047,53.8698375453903,19.5774816951916,23.288654,0,0,0,40,4374,150.3249,99.8070526123047,,,,,,,,,,,,,0,,,,0.00245,,,,,,146.5130463,,,,
,19838071.86,150.0364227,99.8070526123047,1.06208890884187E-6,2.46773766104347E-7,1,0.999253354069792,40.0298881530762,1.99440198261114,15.4699999839067,1.31824602053098E-5,-4.38916374599529E-6,0.25,-5.71757463561968E-7,1.0681871320846E-6,-5.72922606546691E-7,150.0364227,150.0364227,99.8070526123047,99.8070526123047,54.1387177560057,19.5746936889434,22.909004,0,0,0,40,4374,153.8831,99.8070526123047,,,,,,,,,,,,,0,,,,0.00245,,,,,,150.0364227,,,,
,19838211.775,153.540741,99.8070526123047,1.52180783149139E-6,2.94774668222614E-7,1,0.999253354069792,40.0298881530762,1.98178716866143,15.4900001361966,1.78730622656755E-5,-1.08645397174605E-6,0.25,-3.6129373209172E-7,1.5296842682034E-6,-3.60757725478609E-7,153.540741,153.540741,99.8070526123047,99.8070526123047,54.2590885479673,19.5800331767297,23.668306,0,0,0,40,4374,157.39325,99.8070526123047,,,,,,,,,,,,,0,,,,0,,,,,,153.540741,,,,
,19838352.705,157.0391693,99.8070526123047,1.28352659898023E-6,3.00463212633178E-7,1,0.999253354069792,40.0298881530762,1.98160500660323,15.4900001361966,1.44120200462777E-5,2.87359180028037E-6,0.25,3.14149330765809E-8,1.28955088552682E-6,3.34250335763167E-8,157.0391693,157.0391693,99.8070526123047,99.8070526123047,54.129338213775,19.5786269056326,23.668306,0,0,0,40,4374,160.92005,99.8070526123047,,,,,,,,,,,,,0,,,,0.00245,,,,,,157.0391693,,,,
,19838492.61,160.5367737,99.8070526123047,9.65991550416676E-7,2.2834076544336E-7,1,0.999253354069792,40.0298881530762,1.98147882162797,15.4900001361966,1.19978737418099E-5,-4.46300557158711E-6,0.25,-5.63938868567049E-7,9.71262833073722E-7,-5.6519364437936E-7,160.5367737,160.5367737,99.8070526123047,99.8070526123047,54.1152689004288,19.5839308165775,23.288654,0,0,0,40,4374,164.4313,99.8070526123047,,,,,,,,,,,,,0,,,,-0.0049,,,,,,160.5367737,,,,
,19838614.41,163.5521851,99.8070526123047,3.14060008499586E-7,2.70449369396291E-7,1,0.999253354069792,40.0298881530762,1.99464356235763,15.3900003060699,4.11285648661487E-6,-2.53948946518618E-6,0.25,-2.784733975714E-7,3.15871919805619E-7,-2.79310443725248E-7,163.5521851,163.5521851,99.8070526123047,99.8070526123047,53.8276296053519,19.5749736933849,24.047956,0,0,0,40,4374,167.4807,99.8070526123047,,,,,,,,,,,,,0,,,,-0.0049,,,,,,163.5521851,,,,
,19838751.705,167.0077667,99.8070526123047,8.01135572227903E-7,2.35180604279646E-7,1,0.999253354069792,40.0298881530762,1.99472612262941,15.3900003060699,9.76989618932707E-6,-2.3344372343659E-6,0.25,-3.45122444863905E-7,8.05166292825987E-7,-3.45591671277275E-7,167.0077667,167.0077667,99.8070526123047,99.8070526123047,53.9401841121211,19.5796798695358,23.668306,0,0,0,40,4374,170.9215,99.8070526123047,,,,,,,,,,,,,0,,,,-0.0049,,,,,,167.0077667,,,,
,19838893.055,170.5153656,99.8070526123047,7.60764440081363E-7,2.93852075223515E-7,1,0.999253354069792,40.0298881530762,1.99441208717876,15.3900003060699,9.61190745199731E-6,-4.15287405208104E-6,0.25,-4.98446854937521E-7,7.64725719048368E-7,-4.99631412006402E-7,170.5153656,170.5153656,99.8070526123047,99.8070526123047,54.0433590766596,19.5804770168315,24.047956,0,0,0,40,4374,174.4718,99.8070526123047,,,,,,,,,,,,,0,,,,-0.00245,,,,,,170.5153656,,,,
,19839035.5,174.0522461,99.8070526123047,1.07822615033741E-6,3.09323812808201E-7,1,0.999253354069792,40.0298881530762,1.99487885390241,15.3799997642636,1.13376468991406E-5,7.26457357886792E-6,0.25,4.52936980339444E-7,1.08224144077323E-6,4.56225628743761E-7,174.0522461,174.0522461,99.8070526123047,99.8070526123047,54.3005148594865,19.5774128070392,24.047956,0,0,0,40,4374,178.03625,99.8070526123047,,,,,,,,,,,,,0,,,,0,,,,,,174.0522461,,,,
,19839173.86,177.5045013,99.8070526123047,1.09656196380063E-6,2.69456529316859E-7,1,0.999253354069792,40.0298881530762,1.99487463181991,15.3799997642636,1.23035668452521E-5,2.93417125595866E-6,0.25,6.8062162962688E-8,1.10103201852369E-6,6.9694699310605E-8,177.5045013,177.5045013,99.8070526123047,99.8070526123047,54.1996847805057,19.5755390364172,24.047956,0,0,0,40,4374,181.5007,99.8070526123047,,,,,,,,,,,,,0,,,,0,,,,,,177.5045013,,,,
,19839314.815,181.0503235,99.8070526123047,1.62765672173533E-6,3.21471944650777E-7,1,0.999253354069792,40.0298881530762,1.99482907285648,15.3799997642636,1.89559984596137E-5,3.51611556380523E-7,0.25,-2.51896586670499E-7,1.63454582080352E-6,-2.50962340210628E-7,181.0503235,181.0503235,99.8070526123047,99.8070526123047,54.1082342437557,19.573698605341,24.047956,0,0,0,40,4374,185.0352,99.8070526123047,,,,,,,,,,,,,0,,,,0.0049,,,,,,181.0503235,,,,
,19839454.36,184.5279999,99.8070526123047,1.17712021171052E-6,3.04051259106835E-7,1,0.999253354069792,40.0298881530762,1.98208265899019,15.3200002387166,1.27884586273106E-5,5.05968798449131E-6,0.25,2.44362351845774E-7,1.18147333173167E-6,2.46704282162852E-7,184.5279999,184.5279999,99.8070526123047,99.8070526123047,54.0191285925634,19.5685484719381,24.807261,0,0,0,40,4374,188.5391,99.8070526123047,,,,,,,,,,,,,0,,,,0.00245,,,,,,184.5279999,,,,
,19839594.44,188.0050354,99.8070526123047,1.76547355163181E-6,2.27773434677355E-7,1,0.999253354069792,40.0298881530762,1.98216051969424,15.3200002387166,2.0920059332932E-5,-2.43099334899793E-6,0.25,-5.22455342924434E-7,1.77284064920374E-6,-5.22439194166858E-7,188.0050354,188.0050354,99.8070526123047,99.8070526123047,53.9222066561788,19.5710526243514,24.427608,0,0,0,40,4374,192.05055,99.8070526123047,,,,,,,,,,,,,0,,,,-0.00245,,,,,,188.0050354,,,,
,19839733.735,191.5054016,99.8070526123047,8.96858001086763E-7,3.00216719563085E-7,1,0.999253354069792,40.0298881530762,1.98227955810313,15.3200002387166,1.0757476360481E-5,-1.98745794020753E-6,0.25,-3.32162291227737E-7,9.00570398152406E-7,-3.32397158690568E-7,191.5054016,191.5054016,99.8070526123047,99.8070526123047,54.1215219285826,19.5691894644401,24.427608,0,0,0,40,4374,195.5402,99.8070526123047,,,,,,,,,,,,,0,,,,0,,,,,,191.5054016,,,,
,19839878.1,195.0468597,99.8070526123047,1.32440645414019E-6,3.35011918739616E-7,1,0.999253354069792,40.0298881530762,1.98214584779548,15.2500001713634,1.54143870131899E-5,-2.37537605155373E-7,0.25,-2.51127555579579E-7,1.32946682406659E-6,-2.50588733434196E-7,195.0468597,195.0468597,99.8070526123047,99.8070526123047,54.1371544989673,19.5713204286629,24.807261,0,0,0,40,4374,199.1737,99.8070526123047,,,,,,,,,,,,,0,,,,-0.00245,,,,,,195.0468597,,,,
,19840017.76,198.5463867,99.8070526123047,1.34063571561282E-6,3.59067182363867E-7,1,0.999253354069792,40.0298881530762,1.98234122801685,15.2500001713634,1.51959786046374E-5,2.10281303001765E-6,0.25,-4.62055301853036E-8,1.34538029401012E-6,-4.49351074545593E-8,198.5463867,198.5463867,99.8070526123047,99.8070526123047,54.1676380112173,19.5699655164311,24.807261,0,0,0,40,4374,202.6838,99.8070526123047,,,,,,,,,,,,,0,,,,0.00245,,,,,,198.5463867,,,,
,19840156.685,202.0127563,99.8070526123047,1.56006651842471E-6,2.72034369048965E-7,1,0.999253354069792,40.0298881530762,1.98207115633008,15.2500001713634,1.75542838243879E-5,3.1641628680282E-6,0.25,9.98382985075819E-9,1.56534561742518E-6,1.16492038619634E-8,202.0127563,202.0127563,99.8070526123047,99.8070526123047,54.0074041647749,19.5666149772068,24.807261,0,0,0,40,4374,206.1706,99.8070526123047,,,,,,,,,,,,,0,,,,0.0049,,,,,,202.0127563,,,,
,19840278.375,205.050354,99.8070526123047,1.74992593728497E-6,3.10538239051577E-7,1,0.999253354069792,40.0298881530762,1.98212701444227,15.1800001040101,2.03285862865818E-5,-1.33301855429634E-7,0.25,-3.1567569300104E-7,1.75601059729312E-6,-3.14917769946221E-7,205.050354,205.050354,99.8070526123047,99.8070526123047,53.8291928623903,19.5736260129036,25.186911,0,0,0,40,4374,209.21215,99.8070526123047,,,,,,,,,,,,,0,,,,0.0049,,,,,,205.050354,,,,
,19840418.6,208.5224304,99.8070526123047,2.08287697864117E-6,3.22521026686508E-7,1,0.999253354069792,40.0298881530762,1.98178460789914,15.1800001040101,2.41178268599071E-5,2.54750738779252E-7,0.25,-3.38984775329187E-7,2.0898374401555E-6,-3.37966832270905E-7,208.5224304,208.5224304,99.8070526123047,99.8070526123047,53.9519085399096,19.5779634831263,25.186911,0,0,0,40,4374,212.7393,99.8070526123047,,,,,,,,,,,,,0,,,,-0.0049,,,,,,208.5224304,,,,
,19840559.035,212.0594025,99.8070526123047,2.33074978192992E-6,3.07659633231134E-7,1,0.999253354069792,40.0298881530762,1.98187020179505,15.1899997144938,2.74379308677306E-5,-2.31928965852645E-6,0.25,-6.10566553534694E-7,2.33848621014548E-6,-6.10137783047646E-7,212.0594025,212.0594025,99.8070526123047,99.8070526123047,53.8737456879865,19.5736177071894,25.566563,0,0,0,40,4374,216.2596,99.8070526123047,,,,,,,,,,,,,0,,,,-0.0049,,,,,,212.0594025,,,,
,19840678.95,215.0382538,99.8070526123047,2.02461344249048E-6,3.15351125960348E-7,1,0.999253354069792,40.0298881530762,1.99456538457114,15.1300001889467,2.30913936637404E-5,3.07748700143536E-6,0.25,-7.97430439511979E-8,2.0306871943109E-6,-7.80167963894961E-8,215.0382538,215.0382538,99.8070526123047,99.8070526123047,53.8284112338711,19.5713255399492,24.807261,0,0,0,40,4374,219.2695,99.8070526123047,,,,,,,,,,,,,0,,,,-0.0049,,,,,,215.0382538,,,,
,19840821.455,218.5656433,99.8070526123047,2.5110592010995E-6,3.2222844061166E-7,1,0.999253354069792,40.0298881530762,1.99475640758238,15.1300001889467,2.92412178279057E-5,3.45051140026303E-7,0.25,-4.05340346951322E-7,2.51858438592188E-6,-4.04106463437809E-7,218.5656433,218.5656433,99.8070526123047,99.8070526123047,53.8784354591019,19.5695656709943,24.807261,0,0,0,40,4374,222.8395,99.8070526123047,,,,,,,,,,,,,0,,,,-0.0049,,,,,,218.5656433,,,,
,19840960.05,222.0554047,99.8070526123047,2.71019956899081E-6,3.34719882857725E-7,1,0.999253354069792,40.0298881530762,1.99462101262791,15.1300001889467,3.12245570623462E-5,2.27281436211609E-6,0.25,-2.69634313788197E-7,2.71783745315069E-6,-2.67841449190615E-7,222.0554047,222.0554047,99.8070526123047,99.8070526123047,54.0011511366211,19.5741536992299,25.566563,0,0,0,40,4374,226.3095,99.8070526123047,,,,,,,,,,,,,0,,,,0,,,,,,222.0554047,,,,
,19841079.865,225.0415497,99.8070526123047,2.76669628742442E-6,4.08380122968319E-7,1,0.999253354069792,40.0298881530762,1.98168265416628,15.0699997320771,3.17782402437655E-5,1.70900291186583E-6,0.25,-3.28223026666212E-7,2.77425690740121E-6,-3.26544730379852E-7,225.0415497,225.0415497,99.8070526123047,99.8070526123047,53.9581615680634,19.5745708935328,25.566563,0,0,0,40,4374,229.3116,99.8070526123047,,,,,,,,,,,,,0,,,,-0.00245,,,,,,225.0415497,,,,
,19841222.555,228.5630798,99.8070526123047,2.75287755647982E-6,3.50189641770919E-7,1,0.999253354069792,40.0298881530762,1.98141007420017,15.0699997320771,3.1754555913781E-5,8.75520618675E-7,0.25,-3.99816811939754E-7,2.76012918841753E-6,-3.98337860482092E-7,228.5630798,228.5630798,99.8070526123047,99.8070526123047,54.1152689004288,19.5797207040429,25.566563,0,0,0,40,4374,232.895,99.8070526123047,,,,,,,,,,,,,0,,,,0,,,,,,228.5630798,,,,
,19841360.89,232.0281677,99.8070526123047,2.86648340348604E-6,2.91930345927088E-7,1,0.999253354069792,40.0298881530762,1.98137750474834,15.0800002738833,3.26750198376603E-5,3.13335031453045E-6,0.25,-2.18775379942663E-7,2.87351100170506E-6,-2.16760472694108E-7,232.0281677,232.0281677,99.8070526123047,99.8070526123047,53.9472187687942,19.5862061927775,25.566563,0,0,0,40,4374,236.3625,99.8070526123047,,,,,,,,,,,,,0,,,,0,,,,,,232.0281677,,,,
,19841501.735,235.5352631,99.8070526123047,3.45230434930682E-6,3.27031334654122E-7,1,0.999253354069792,40.0298881530762,1.99399437214567,15.0199998170137,3.93648302169801E-5,5.07824566474628E-6,0.25,-1.50147604085547E-7,3.46024660927266E-6,-1.47486724306076E-7,235.5352631,235.5352631,99.8070526123047,99.8070526123047,54.0441407051788,19.5830176585147,25.186911,0,0,0,40,4374,239.9001,99.8070526123047,,,,,,,,,,,,,0,,,,-0.00245,,,,,,235.5352631,,,,
,19841642.67,239.014801,99.8070526123047,3.73061116468206E-6,3.84626583990175E-7,1,0.999253354069792,40.0298881530762,1.99372677774042,15.0199998170137,4.25377201227864E-5,5.42794956897885E-6,0.25,-1.67349026514266E-7,3.73874425718627E-6,-1.64521580536097E-7,239.014801,239.014801,99.8070526123047,99.8070526123047,54.0660263037173,19.5886497306157,25.946213,0,0,0,40,4374,243.4364,99.8070526123047,,,,,,,,,,,,,0,,,,0.0049,,,,,,239.014801,,,,
,19841782.79,242.5172882,99.8070526123047,3.91240141190775E-6,3.26325457095809E-7,1,0.999253354069792,40.0298881530762,1.99370431813902,15.0199998170137,4.43073669972236E-5,7.40544446287519E-6,0.25,-2.39594150289333E-8,3.9203223652937E-6,-2.07239086602418E-8,242.5172882,242.5172882,99.8070526123047,99.8070526123047,54.1183954145057,19.5891248750155,25.566563,0,0,0,40,4374,246.9557,99.8070526123047,,,,,,,,,,,,,0,,,,0,,,,,,242.5172882,,,,
,19841923.01,246.0335999,99.8070526123047,3.95466838569075E-6,3.62649191952828E-7,1,0.999253354069792,40.0298881530762,1.99417619719813,14.919999986887,4.48657936255883E-5,7.05283259707359E-6,0.25,-6.24678402063123E-8,3.9622182909346E-6,-5.93228751519396E-8,246.0335999,246.0335999,99.8070526123047,99.8070526123047,53.7424320967557,19.570260910576,25.566563,0,0,0,40,4374,250.4703,99.8070526123047,,,,,,,,,,,,,0,,,,0,,,,,,246.0335999,,,,
,19842064.285,249.5444336,99.8070526123047,4.62317725442763E-6,3.29708693087616E-7,1,0.999253354069792,40.0298881530762,1.99354156238004,14.9299995973706,5.29513073278603E-5,5.22164525941079E-6,0.25,-3.39993633209863E-7,4.63164750939203E-6,-3.36845199444428E-7,249.5444336,249.5444336,99.8070526123047,99.8070526123047,53.7463402393518,19.5852691554729,25.566563,0,0,0,40,4374,254.0185,99.8070526123047,,,,,,,,,,,,,0,,,,0,,,,,,249.5444336,,,,
,19842203.78,253.0101471,99.8070526123047,4.76022016809592E-6,3.21247947139712E-7,1,0.999253354069792,40.0298881530762,1.99350147916285,14.9299995973706,5.41841594289841E-5,7.27302589112995E-6,0.25,-1.82214526887246E-7,4.7682200303619E-6,-1.78715870665958E-7,253.0101471,253.0101471,99.8070526123047,99.8070526123047,54.0378876770249,19.5846171513265,25.946213,0,0,0,40,4374,257.5119,99.8070526123047,,,,,,,,,,,,,0,,,,0,,,,,,253.0101471,,,,
,19842343.635,256.510437,99.8070526123047,5.19627762710868E-6,3.89473187124157E-7,1,0.999253354069792,40.0298881530762,1.99302330195594,14.9100003764033,5.85592217574148E-5,1.12098361598232E-5,0.25,9.07447352767366E-8,5.2041356822737E-6,9.49638251133719E-8,256.510437,256.510437,99.8070526123047,99.8070526123047,53.8260663483134,19.5893279935687,25.946213,0,0,0,40,4374,261.007,99.8070526123047,,,,,,,,,,,,,0,,,,-0.0049,,,,,,256.510437,,,,
,19842483.375,260.0193481,99.8070526123047,5.57126515609989E-6,3.59638475371038E-7,1,0.999253354069792,40.0298881530762,1.99301975789682,14.8999998345971,6.41830188281878E-5,3.90866824634003E-6,0.25,-6.20068940626063E-7,5.57955120335727E-6,-6.16632257160572E-7,260.0193481,260.0193481,99.8070526123047,99.8070526123047,53.8237214627557,19.5927927272398,25.946213,0,0,0,40,4374,264.504,99.8070526123047,,,,,,,,,,,,,0,,,,0,,,,,,260.0193481,,,,
,19842625.88,263.5510559,99.8070526123047,5.994546813822E-6,3.72758942739868E-7,1,0.999253354069792,40.0298881530762,1.99287194561263,14.9100003764033,6.83276016592594E-5,8.34718723746211E-6,0.25,-3.00524737868369E-7,6.00242138033085E-6,-2.9634947702546E-7,263.5510559,263.5510559,99.8070526123047,99.8070526123047,53.7955828360634,19.5935577628031,25.946213,0,0,0,40,4374,268.0707,99.8070526123047,,,,,,,,,,,,,0,,,,0,,,,,,263.5510559,,,,
,19842745.19,266.5265808,99.8070526123047,6.06527345808353E-6,3.09037474487009E-7,1,0.999253354069792,40.0298881530762,2.00404862470929,14.8499999195337,6.89018480950861E-5,1.19193282007625E-5,0.25,-2.11247201392534E-9,6.0723673565824E-6,2.43645190879521E-9,266.5265808,266.5265808,99.8070526123047,99.8070526123047,53.8885966298519,19.5905879395495,26.705515,0,0,0,40,4374,271.0488,99.8070526123047,,,,,,,,,,,,,0,,,,0,,,,,,266.5265808,,,,
,19842886.225,270.0019836,99.8070526123047,6.73615446422316E-6,3.66352567411061E-7,1,0.999253354069792,40.0298881530762,2.00397394540629,14.8499999195337,7.72287496870007E-5,9.09415807528764E-6,0.25,-3.66910988090849E-7,6.74346591846293E-6,-3.62318015722505E-7,270.0019836,270.0019836,99.8070526123047,99.8070526123047,53.9339310839672,19.584526698429,26.325863,0,0,0,40,4374,274.58745,99.8070526123047,,,,,,,,,,,,,0,,,,0.0049,,,,,,270.0019836,,,,
,19843027.93,273.5222778,99.8070526123047,6.72079167794894E-6,3.05855936680532E-7,1,0.999253354069792,40.0298881530762,2.00427291353306,14.8499999195337,7.67126890022552E-5,1.10418372523294E-5,0.25,-1.92700875832669E-7,6.72710976220824E-6,-1.87989266455905E-7,273.5222778,273.5222778,99.8070526123047,99.8070526123047,53.8143419205249,19.5830305057805,26.705515,0,0,0,40,4374,278.1421,99.8070526123047,,,,,,,,,,,,,0,,,,-0.0049,,,,,,273.5222778,,,,
,19843167.15,277.0057068,99.8070526123047,7.251925844882E-6,3.53184192739152E-7,1,0.999253354069792,40.0298881530762,2.00444639578914,14.7799998521805,8.25201603837938E-5,1.33651289209963E-5,0.25,-8.00772932400284E-8,7.25774471615902E-6,-7.49444903638287E-8,277.0057068,277.0057068,99.8070526123047,99.8070526123047,53.9659778532557,19.5754255578717,25.946213,0,0,0,40,4374,281.63195,99.8070526123047,,,,,,,,,,,,,0,,,,0,,,,,,277.0057068,,,,
,19843310.075,280.5519409,99.8070526123047,7.19894587605306E-6,3.97395942154807E-7,1,0.999253354069792,40.0298881530762,2.00472890165252,14.7799998521805,8.20149743928739E-5,1.27074374690566E-5,0.25,-1.28734922527553E-7,7.20384142230031E-6,-1.23740357134264E-7,280.5519409,280.5519409,99.8070526123047,99.8070526123047,53.8987578006019,19.5764307992134,26.705515,0,0,0,40,4374,285.2152,99.8070526123047,,,,,,,,,,,,,0,,,,0,,,,,,280.5519409,,,,
,19843451.345,284.0557556,99.8070526123047,7.37069439459541E-6,4.05618950531347E-7,1,0.999253354069792,40.0298881530762,2.00535952753958,14.7799998521805,8.38862904910276E-5,1.35898886877332E-5,0.25,-8.09337743985996E-8,7.37474446354703E-6,-7.58529017770156E-8,284.0557556,284.0557556,99.8070526123047,99.8070526123047,53.8635845172365,19.5672219881732,27.085165,0,0,0,40,4374,288.7685,99.8070526123047,,,,,,,,,,,,,0,,,,0,,,,,,284.0557556,,,,
,19843592.59,287.5291443,99.8070526123047,8.03999552233127E-6,4.07350308910187E-7,1,0.999253354069792,40.0298881530762,1.99409913775283,14.7200003266335,9.05763284124514E-5,1.71989420035454E-5,0.25,1.29222906451046E-7,8.04326281746116E-6,1.34785174290308E-7,287.5291443,287.5291443,99.8070526123047,99.8070526123047,54.0136571929288,19.570219203887,26.325863,0,0,0,40,4374,292.3275,99.8070526123047,,,,,,,,,,,,,0,,,,-0.00245,,,,,,287.5291443,,,,
,19843732.7,291.0144043,99.8070526123047,8.06670233266437E-6,3.72568637279026E-7,1,0.999253354069792,40.0298881530762,1.99445534050094,14.7200003266335,9.18514532546856E-5,1.1658233950895E-5,0.25,-3.65823559030217E-7,8.06930931259856E-6,-3.60482996868514E-7,291.0144043,291.0144043,99.8070526123047,99.8070526123047,54.1113607578326,19.5642827066504,26.705515,0,0,0,40,4374,295.855,99.8070526123047,,,,,,,,,,,,,0,,,,-0.00245,,,,,,291.0144043,,,,
,19843876.125,294.5525513,99.8070526123047,8.25899884696578E-6,3.11377274724165E-7,1,0.999253354069792,40.0298881530762,1.99486190926963,14.7200003266335,9.36450562693524E-5,1.42590434355452E-5,0.25,-1.68942039340728E-7,8.2604816738136E-6,-1.63473339871919E-7,294.5525513,294.5525513,99.8070526123047,99.8070526123047,54.1762359249288,19.5601273977166,26.705515,0,0,0,40,4374,299.4759,99.8070526123047,,,,,,,,,,,,,0,,,,-0.0049,,,,,,294.5525513,,,,
,19844017.49,298.0309448,99.8070526123047,7.85771896186231E-6,4.66082442046598E-7,1,0.999253354069792,40.0298881530762,1.98177247415824,14.6500002592802,8.91268397009855E-5,1.00100182554899E-5,0.25,-4.69713468107042E-7,7.85835390021501E-6,-4.64576684916689E-7,298.0309448,298.0309448,99.8070526123047,99.8070526123047,53.8104337779288,19.5580217659383,27.085165,0,0,0,40,4374,303.03675,99.8070526123047,,,,,,,,,,,,,0,,,,-0.00245,,,,,,298.0309448,,,,
,19844159.4,301.5258789,99.8070526123047,8.61458355691059E-6,3.95313259034952E-7,1,0.999253354069792,40.0298881530762,1.98171151313241,14.6500002592802,9.74547096863231E-5,1.23683144241449E-5,0.25,-3.90525472474364E-7,8.61411968600143E-6,-3.84918433021732E-7,301.5258789,301.5258789,99.8070526123047,99.8070526123047,53.9589431965826,19.559865923848,26.705515,0,0,0,40,4374,306.61295,99.8070526123047,,,,,,,,,,,,,0,,,,0.00245,,,,,,301.5258789,,,,
,19844302.515,305.0594788,99.8070526123047,8.58199236368125E-6,4.90091021947362E-7,1,0.999253354069792,40.0298881530762,1.98168793650239,14.6500002592802,9.70268496160689E-5,1.25841795464944E-5,0.25,-3.65417615217622E-7,8.58043108501935E-6,-3.59864147899877E-7,305.0594788,305.0594788,99.8070526123047,99.8070526123047,53.8667110313134,19.5607372471238,26.325863,0,0,0,40,4374,310.2174,99.8070526123047,,,,,,,,,,,,,0,,,,0.0049,,,,,,305.0594788,,,,
,19844442.865,308.5466614,99.8070526123047,8.31279874376186E-6,4.5713563360096E-7,1,0.999253354069792,40.0298881530762,1.98166439511371,14.5899998024106,9.34777694475188E-5,1.50329646697366E-5,0.25,-1.00340843026855E-7,8.31009293254478E-6,-9.50726509608073E-8,308.5466614,308.5466614,99.8070526123047,99.8070526123047,53.8323193764672,19.560273136876,26.705515,0,0,0,40,4374,313.75705,99.8070526123047,,,,,,,,,,,,,0,,,,-0.00245,,,,,,308.5466614,,,,
,19844585.195,312.0440521,99.8070526123047,8.54181266074298E-6,3.70607470744548E-7,1,0.999253354069792,40.0298881530762,1.98239393626665,14.5899998024106,9.5894574094948E-5,1.64916147807119E-5,0.25,-1.02894035151127E-8,8.53791417098392E-6,-4.97702405737459E-9,312.0163269,312.0717773,99.8070526123047,99.8070526123047,54.0238183636788,19.556821823947,26.705515,0,0,0,40,4374,317.3532,99.8070526123047,,,,,,,,,,,,,0,,,,0.00245,,,,,,312.0440521,,,,
,19844724.93,315.5084839,99.8070526123047,9.43255702218302E-6,3.30237126467248E-7,1,0.999253354069792,40.0298881530762,1.98221976352425,14.5899998024106,0.000106464651596775,1.47896740013218E-5,0.25,-3.15866744521731E-7,9.42728281051697E-6,-3.09897313949335E-7,315.5084839,315.5084839,99.8070526123047,99.8070526123047,54.2051561801404,19.5574108424397,27.085165,0,0,0,40,4374,320.8824,99.8070526123047,,,,,,,,,,,,,0,,,,0.0049,,,,,,315.5084839,,,,
,19844848.175,318.5281677,99.8070526123047,8.45336581994399E-6,4.21105723523334E-7,1,0.999253354069792,40.0298881530762,1.98173261511072,14.5300002768636,9.57790448636023E-5,1.09458846227937E-5,0.25,-4.88399119306628E-7,8.44786152671883E-6,-4.82935627772012E-7,318.5281677,318.5281677,99.8070526123047,99.8070526123047,53.9394024836019,19.5585975893429,27.085165,0,0,0,40,4374,323.99195,99.8070526123047,,,,,,,,,,,,,0,,,,0,,,,,,318.5281677,,,,
,19844990.71,322.0205078,99.8070526123047,8.34981975692378E-6,3.4347943000339E-7,1,0.999253354069792,40.0298881530762,1.98199032787619,14.5300002768636,9.45071204802756E-5,1.1382313659731E-5,0.25,-4.31498388960467E-7,8.34332364212519E-6,-4.26147277718269E-7,321.9885864,322.0524292,99.8070526123047,99.8070526123047,54.2200071220057,19.5565707223388,27.464817,0,0,0,40,4374,327.5953,99.8070526123047,,,,,,,,,,,,,0,,,,-0.0049,,,,,,322.0205078,,,,
,19845132.455,325.5455322,99.8070526123047,8.44986939525474E-6,4.28862606680554E-7,1,0.999253354069792,40.0298881530762,1.98203141626065,14.5300002768636,9.46437381306446E-5,1.72098045222994E-5,0.25,7.08678905785625E-8,8.44194876213238E-6,7.5802160060145E-8,325.5455322,325.5455322,99.8070526123047,99.8070526123047,54.0738425889096,19.5545506852694,27.464817,0,0,0,40,4374,331.1776,99.8070526123047,,,,,,,,,,,,,0,,,,0.0049,,,,,,325.5455322,,,,
,19845255.27,328.5562439,99.8070526123047,8.69646985965997E-6,4.58692167419686E-7,1,0.999253354069792,40.0298881530762,1.98141943549692,14.4800003618002,9.73718705124173E-5,1.76759707922689E-5,0.25,7.04021683508758E-8,8.68740662554185E-6,7.54226129144992E-8,328.5562439,328.5562439,99.8070526123047,99.8070526123047,53.9011026861596,19.560671764642,27.085165,0,0,0,40,4374,334.26415,99.8070526123047,,,,,,,,,,,,,0,,,,0.00245,,,,,,328.5562439,,,,
,19845395.125,332.0513,99.8070526123047,8.25046346184359E-6,4.7968232527781E-7,1,0.999253354069792,40.0298881530762,1.98147515202186,14.4800003618002,9.25094701053508E-5,1.59585672569643E-5,0.25,-5.33831993553409E-9,8.24090543858213E-6,-5.5505697790082E-10,332.0513,332.0513,99.8070526123047,99.8070526123047,53.912827113948,19.5640629630132,27.464817,0,0,0,40,4374,337.7878,99.8070526123047,,,,,,,,,,,,,0,,,,0.00245,,,,,,332.0513,,,,
,19845537.065,335.5414124,99.8070526123047,7.93929106382478E-6,4.95022400291769E-7,1,0.999253354069792,40.0298881530762,1.98143671055218,14.4800003618002,9.04157070189919E-5,7.22536660823729E-6,0.25,-7.30268052465903E-7,7.92955065813103E-6,-7.24788365480333E-7,335.5414124,335.5414124,99.8070526123047,99.8070526123047,53.9253331702557,19.5636732920207,27.464817,0,0,0,40,4374,341.35355,99.8070526123047,,,,,,,,,,,,,0,,,,-0.00245,,,,,,335.5414124,,,,
,19845678.985,339.0453186,99.8070526123047,8.5669745200055E-6,4.60633539668187E-7,1,0.999253354069792,40.0298881530762,1.99419565556336,14.4100002944469,9.71567132565046E-5,1.35913014016979E-5,0.25,-2.78284578535363E-7,8.55513803704539E-6,-2.73043579599139E-7,339.0453186,339.0453186,99.8070526123047,99.8070526123047,53.6134633910826,19.5550484118393,27.844467,0,0,0,40,4374,344.9112,99.8070526123047,,,,,,,,,,,,,0,,,,-0.00245,,,,,,339.0453186,,,,
,19845818,342.5014038,99.8070526123047,8.66001550958157E-6,5.33390518560465E-7,1,0.999253354069792,40.0298881530762,1.99489770010699,14.4100002944469,9.83459847772038E-5,1.30907247106541E-5,0.25,-3.38985246170704E-7,8.64705741663297E-6,-3.33617172504859E-7,342.5014038,342.5014038,99.8070526123047,99.8070526123047,54.0386693055442,19.5515342948481,27.464817,0,0,0,40,4374,348.4123,99.8070526123047,,,,,,,,,,,,,0,,,,0,,,,,,342.5014038,,,,
,19845959.5,346.0088501,99.8070526123047,7.67048543000463E-6,5.16821010595309E-7,1,0.999253354069792,40.0298881530762,1.99490501291524,14.4100002944469,8.67891737207065E-5,1.3379683277708E-5,0.25,-1.41845395898181E-7,7.65800359973568E-6,-1.37357816138638E-7,346.0088501,346.0088501,99.8070526123047,99.8070526123047,54.0793139885442,19.5533635710358,27.464817,0,0,0,40,4374,351.97325,99.8070526123047,,,,,,,,,,,,,0,,,,0.00245,,,,,,346.0088501,,,,
,19846274.985,349.0047607,99.8070526123047,8.43048770849837E-6,4.59608318997868E-7,1,0.999253354069792,40.0298881530762,1.98178840862424,14.3499998375773,9.59117742086321E-5,8.07329502414902E-6,0.25,-7.39326570416309E-7,8.41623611519804E-6,-7.33363677058597E-7,349.0047607,349.0047607,99.8070526123047,99.8070526123047,53.9823920521596,19.5552722717107,27.085165,0,0,0,40,4374,351.92285,99.8070526123047,,,,,,,,,,,,,0,,,,-0.00245,,,,,,349.0047607,,,,
,19846503.55,349.8647156,99.8070526123047,7.83662960705859E-6,4.55837261600019E-7,1,0.999253354069792,40.0298881530762,1.98179157479488,14.3499998375773,8.84785160793218E-5,1.14005086595095E-5,0.25,-3.39571557508764E-7,7.82296141228079E-6,-3.34627112282651E-7,349.8647156,349.8647156,99.8070526123047,99.8070526123047,53.9425289976788,19.5551592936127,27.464817,0,0,0,40,4369,352.213,99.8070526123047,,,,,,,,,,,,,0,,,,0,,,,,,349.8647156,,,,