File: data/monolayers/magneticStructure/ML_Ac_CoFe_C-2/PPMS/data/DD175_23_HYST_0OE_5K_2ND.DAT
[Header]
; VSM Data File (default extension .dat)
; Copyright (c) 2003-2013, Quantum Design, Inc. All rights reserved.
TITLE,
FILEOPENTIME,32024396.69,01/06/2019,11:42 pm
BYAPP,VSM,2.0,2.0
INFO,PPMS VSM Option Release 1.4.10 Build 1,APPNAME
INFO,Quantum Design Linear Motor Servo Controller,MOTOR_MODULE_NAME
INFO,3101-100 M1,MOTOR_HW_VERSION
INFO,MMC1014,MOTOR_SERIAL_NUMBER
INFO,SRV No X-over 01.03.11,MOTOR_SOFTWARE_VERSION
INFO,Quantum Design VSM Detection Module,VSM_MODULE_NAME
INFO,3101-150 F0,VSM_HW_VERSION
INFO,VSM707,VSM_SERIAL_NUMBER
INFO,VSM No X-over 01.02.05 May 20 2008 13:51:47,VSM_SOFTWARE_VERSION
INFO,704,PREAMP_SERIAL_NUMBER
INFO,822,COIL_SERIAL_NUMBER
INFO,0,MOMENT_UNITS
INFO,CoFe2O4 Monolayer,SAMPLE_MATERIAL
INFO,from YF45,SAMPLE_COMMENT
INFO,29.98,SAMPLE_MASS
INFO,,SAMPLE_VOLUME
INFO,,SAMPLE_MOLECULAR_WEIGHT
INFO,,SAMPLE_SIZE
INFO,,SAMPLE_SHAPE
DATATYPE,COMMENT,1
DATATYPE,TIME,2
STARTUPAXIS,X,2
STARTUPAXIS,Y1,5
[Data]
Comment,Time Stamp (sec),Temperature (K),Magnetic Field (Oe),Moment (emu),M. Std. Err. (emu),Transport Action,Averaging Time (sec),Frequency (Hz),Peak Amplitude (mm),Center Position (mm),Coil Signal' (mV),Coil Signal" (mV),Range (mV),M. Quad. Signal (emu),M. Raw' (emu),M. Raw" (emu),Min. Temperature (K),Max. Temperature (K),Min. Field (Oe),Max. Field (Oe),Mass (grams),Motor Lag (deg),Pressure (Torr),VSM Status (code),Motor Status (code),Measure Status (code),Measure Count,PPMS Status (code),System Temp. (K),System Field (Oe),Sample Position (deg),Bridge 1 Resistance (ohms),Bridge 1 Excitation (에),Bridge 2 Resistance (ohms),Bridge 2 Excitation (에),Bridge 3 Resistance (ohms),Bridge 3 Excitation (에),Bridge 4 Resistance (ohms),Bridge 4 Excitation (에),Signal 1 Vin (V),Signal 2 Vin (V),Digital Inputs (code),Drive 1 Iout (mA),Drive 1 Ipower (W),Drive 2 Iout (mA),Drive 2 Ipower (W),Pressure (),Map 20 (),Map 21 (),Map 22 (),Map 23 (),Map 24 (),Map 25 (),Map 26 (),Map 27 (),Map 28 (),Map 29 ()
,32024410.78,4.9995918,-0.456713199615479,,,2,,,,21.5200002473593,,,,,,,4.9995918,4.9995918,-0.456713199615479,-0.456713199615479,,,8.102614,,,,-99999999,4369,5.0103,-0.456713199615479,,,,,,,,,,,,,,,,,,,,,,,4.9995918,,,,
,32024497.21,5.0052152,1950.24438476562,-6.74838507241765E-6,3.35034927451095E-7,1,0.999253354069792,40.0298881530762,2.00716949635397,21.509999409318,-7.56805732314523E-5,-1.64214518781527E-5,0.25,-2.55401745114962E-7,-6.70898685152228E-6,-2.87172195541926E-7,5.0052152,5.0052152,1927.66027832031,1972.82849121094,55.5941100588136,20.5180565827091,8.482265,0,0,0,40,4449,5.00395,1950.24438476562,,,,,,,,,,,,,0,,,,0,,,,,,5.0052152,,,,
,32024539.225,5.0043306,4046.55603027344,-1.30293006083588E-5,4.1506888803736E-7,1,0.999253354069792,40.0298881530762,1.99456909644018,21.509999409318,-0.000145955823831124,-2.76115839696829E-5,0.25,-1.43146470095985E-7,-1.29565705852302E-5,-2.08290903766361E-7,5.0043306,5.0043306,4026.67163085937,4066.4404296875,55.7121359652174,20.5165284397974,7.722963,0,0,0,40,4449,5.0028,4046.55603027344,,,,,,,,,,,,,0,,,,-0.00245,,,,,,5.0043306,,,,
,32024581.14,5.0039635,6138.4306640625,-1.90284057570601E-5,4.15968327258881E-7,1,0.999253354069792,40.0298881530762,1.99478716839488,21.509999409318,-0.000214525289793332,-3.29503696827025E-5,0.25,4.51545101250449E-7,-1.89283016363117E-5,3.49983615514306E-7,5.0039635,5.0039635,6113.3896484375,6163.4716796875,55.9911773465829,20.5155445073253,8.482265,0,0,0,40,4449,5.00225,6138.4306640625,,,,,,,,,,,,,0,,,,-0.0049,,,,,,5.0039635,,,,
,32024623.085,5.0031524,8234.619140625,-2.53207912689424E-5,5.66910213010379E-7,1,0.999253354069792,40.0298881530762,1.99464889401058,21.509999409318,-0.000285746804734358,-4.24217935499743E-5,0.25,7.32029476944941E-7,-2.51923114201736E-5,5.92394739137698E-7,5.0031524,5.0031524,8207.23828125,8262,56.4867298277752,20.5157949920308,8.482265,0,0,0,40,4449,5.00135,8234.619140625,,,,,,,,,,,,,0,,,,-0.00245,,,,,,5.0031524,,,,
,32024665.095,5.0027423,10333.8706054688,-3.14705748770495E-5,6.53126338187713E-7,1,0.999253354069792,40.0298881530762,1.99486444062061,21.509999409318,-0.000354456790095247,-5.71628484901999E-5,0.25,5.20821552472736E-7,-3.1314119776008E-5,3.44507975330594E-7,5.0027423,5.0027423,10311.5185546875,10356.22265625,56.2803798986983,20.5168252244528,8.482265,0,0,0,40,4449,5.0008,10333.8706054688,,,,,,,,,,,,,0,,,,0.00245,,,,,,5.0027423,,,,
,32024707.11,5.001852,12435.349609375,-3.73266094459351E-5,5.35638774325424E-7,1,0.999253354069792,40.0298881530762,1.99476588704084,21.509999409318,-0.000420003802843492,-7.04209480043569E-5,0.25,3.90900735160416E-7,-3.71464178897402E-5,1.77236112956053E-7,5.001852,5.001852,12415.4853515625,12455.2138671875,55.8114027871598,20.5165684062594,8.102614,0,0,0,40,4449,4.99955,12435.349609375,,,,,,,,,,,,,0,,,,0.00245,,,,,,5.001852,,,,
,32024749.095,4.9997382,14532.0078125,-4.22560853155435E-5,6.33083270451561E-7,1,0.999253354069792,40.0298881530762,1.99489136847856,21.509999409318,-0.000475800514837869,-7.85534998326558E-5,0.25,5.54581080270842E-7,-4.20605856910906E-5,3.05864755174281E-7,4.9997382,4.9997382,14509.5078125,14554.5078125,56.0959155681598,20.5148377309505,8.482265,0,0,0,40,4449,5.0004,14532.0078125,,,,,,,,,,,,,0,,,,0.00245,,,,,,4.9997382,,,,
,32024790.995,5.0014176,16625.67578125,-4.65105785275732E-5,5.90048591642699E-7,1,0.999253354069792,40.0298881530762,1.99474869408343,21.509999409318,-0.000525241275509401,-7.82539802016538E-5,0.25,1.34884893806644E-6,-4.63087730673882E-5,1.06504088586342E-6,5.0014176,5.0014176,16603.4140625,16647.9375,56.0787197407367,20.5141739320809,8.102614,0,0,0,40,4449,5.0004,16625.67578125,,,,,,,,,,,,,0,,,,-0.0049,,,,,,5.0014176,,,,
,32024833.15,5.0018682,18735.0302734375,-4.94229158558555E-5,5.69878528883477E-7,1,0.999253354069792,40.0298881530762,1.99473617114146,21.509999409318,-0.000558968327314831,-7.91054166941163E-5,0.25,1.80212491136069E-6,-4.92207604471312E-5,1.49217397257352E-6,5.0018682,5.0018682,18712.380859375,18757.6796875,57.0917103016599,20.5173356771069,8.102614,0,0,0,40,4449,4.99925,18735.0302734375,,,,,,,,,,,,,0,,,,0,,,,,,5.0018682,,,,
,32024874.955,5.0016079,20823.478515625,-5.19992936526012E-5,6.40927365286375E-7,1,0.999253354069792,40.0298881530762,1.99475356217709,21.509999409318,-0.000587277963358545,-8.85911942929068E-5,0.25,1.42760235641102E-6,-5.17944574416029E-5,1.09674563694211E-6,5.0013404,5.0018754,20795.953125,20851.00390625,56.8931766577752,20.5159057094379,8.482265,0,0,0,40,4449,4.99915,20823.478515625,,,,,,,,,,,,,0,,,,-0.00245,,,,,,5.0016079,,,,
,32024916.915,5.0008454,22920.3115234375,-5.39137957288942E-5,7.80666642331876E-7,1,0.999253354069792,40.0298881530762,1.9949107659082,21.509999409318,-0.000609199283495166,-9.11913392990345E-5,0.25,1.54833403966616E-6,-5.37132648887224E-5,1.19833889577548E-6,5.0008454,5.0008454,22890.181640625,22950.44140625,56.6125720193714,20.5178700274144,8.861917,0,0,0,40,4449,4.9998,22920.3115234375,,,,,,,,,,,,,0,,,,-0.00245,,,,,,5.0008454,,,,
,32024958.82,5.0004463,25016.5068359375,-5.40141131770753E-5,7.39549525749079E-7,1,0.999253354069792,40.0298881530762,1.99467041028968,21.509999409318,-0.000608725310155679,-0.000100683569410563,0.25,7.29413507185697E-7,-5.38195144975106E-5,3.75495267751342E-7,5.0004463,5.0004463,24994.064453125,25038.94921875,56.7712426087752,20.5212271251204,8.861917,0,0,0,40,4449,4.9988,25016.5068359375,,,,,,,,,,,,,0,,,,-0.0049,,,,,,5.0004463,,,,
,32025000.86,5.0002728,27118.2919921875,-5.61989175380144E-5,8.23520630099408E-7,1,0.999253354069792,40.0298881530762,1.99473612235428,21.509999409318,-0.00063828123051548,-7.81695014635472E-5,0.25,3.13198725711171E-6,-5.60243851780647E-5,2.74916578526298E-6,5.0002728,5.0002728,27098.388671875,27138.1953125,56.4140383754867,20.5188461460854,8.102614,0,0,0,40,4449,5.00015,27118.2919921875,,,,,,,,,,,,,0,,,,-0.00245,,,,,,5.0002728,,,,
,32025042.98,5.0007658,29222.28515625,-5.91781709969543E-5,8.12881077986897E-7,1,0.999253354069792,40.0298881530762,1.99480117866531,21.509999409318,-0.000670319268182233,-9.3319138831197E-5,0.25,2.32778564534008E-6,-5.90011778665075E-5,1.92214561235758E-6,5.0007658,5.0007658,29197.298828125,29247.271484375,56.6821369575829,20.5219142865709,8.102614,0,0,0,40,4449,4.9993,29222.28515625,,,,,,,,,,,,,0,,,,0,,,,,,5.0007658,,,,
,32025084.77,4.9996238,31311.2958984375,-6.30292787992797E-5,1.21167997103268E-6,1,0.999253354069792,40.0298881530762,1.99453812723243,21.509999409318,-0.000713760594217255,-0.000100800549500474,0.25,2.36114289317481E-6,-6.28540411550995E-5,1.92372454200792E-6,4.9989629,5.0002847,31286.443359375,31336.1484375,56.4421770021791,20.523285735766,8.482265,0,0,0,40,4449,4.99835,31311.2958984375,,,,,,,,,,,,,0,,,,0.00245,,,,,,4.9996238,,,,
,32025126.695,4.9990201,33407.638671875,-6.8231456429349E-5,1.0768279641777E-6,1,0.999253354069792,40.0298881530762,1.99451570653155,21.509999409318,-0.000776200337926516,-9.04362412580138E-5,0.25,4.22500546523876E-6,-6.80686586585297E-5,3.74106619975725E-6,4.9987888,4.9992514,33380.109375,33435.16796875,56.0505811140444,20.5199141905291,8.102614,0,0,0,40,4449,5.0005,33407.638671875,,,,,,,,,,,,,0,,,,0,,,,,,4.9990201,,,,
,32025168.62,4.99970055,35498.9609375,-7.29801473711757E-5,8.66870169812582E-7,1,0.999253354069792,40.0298881530762,1.99451164730179,21.509999409318,-0.000822041043980515,-0.00014328991775996,0.25,3.89562957792511E-7,-7.27936744347843E-5,-1.22480245097836E-7,4.9988761,5.000525,35473.94140625,35523.98046875,56.567237565256,20.5218299722908,8.482265,0,0,0,40,4449,4.9989,35498.9609375,,,,,,,,,,,,,0,,,,-0.0049,,,,,,4.99970055,,,,
,32025210.625,4.9982288,37600.26171875,-7.88781979570419E-5,9.20827666633694E-7,1,0.999253354069792,40.0298881530762,1.99455838185747,21.509999409318,-0.000893454114538477,-0.000128456301463653,0.25,2.77707762722032E-6,-7.87109653768845E-5,2.21213124972398E-6,4.9980378,4.9984198,37572.87109375,37627.65234375,56.5766171074867,20.524576234441,8.482265,0,0,0,40,4449,5.00065,37600.26171875,,,,,,,,,,,,,0,,,,0,,,,,,4.9982288,,,,
,32025252.605,4.9987853,39699.064453125,-8.49662494357139E-5,1.17682580880514E-6,1,0.999253354069792,40.0298881530762,1.99441922182379,21.509999409318,-0.000962484357621962,-0.000138851348200079,0.25,2.95641123933343E-6,-8.48049729462993E-5,2.34277852444841E-6,4.9981132,4.9994574,39676.421875,39721.70703125,56.4234179177175,20.5256286095507,8.102614,0,0,0,40,4449,5.0004,39699.064453125,,,,,,,,,,,,,0,,,,-0.00245,,,,,,4.9987853,,,,
,32025308.71,4.99830105,38234.63671875,-7.99562658851991E-5,1.04142201888722E-6,1,0.999253354069792,40.0298881530762,1.99442748437103,21.509999409318,-0.00090361798449568,-0.000141621487480707,0.25,1.80312750161131E-6,-7.9785006272543E-5,1.23125658700735E-6,4.9980903,4.9985118,38207.09375,38262.1796875,56.709493955756,20.5254812325345,8.482265,0,0,0,40,4449,5.0012,38234.63671875,,,,,,,,,,,,,0,,,,0,,,,,,4.99830105,,,,
,32025350.785,4.99985405,36131.81640625,-7.30059945866348E-5,1.14850791586641E-6,1,0.999253354069792,40.0298881530762,1.99446060573214,21.509999409318,-0.000827054216435686,-0.000117287640430591,0.25,2.70706100627019E-6,-7.28406535430617E-5,2.18726802958803E-6,4.998548,5.0011601,36104.38671875,36159.24609375,56.8908317722176,20.5275146828205,8.482265,0,0,0,40,4449,5.0035,36131.81640625,,,,,,,,,,,,,0,,,,-0.00245,,,,,,4.99985405,,,,
,32025392.595,4.9998696,34042.625,-6.41702952786607E-5,1.0788727929474E-6,1,0.999253354069792,40.0298881530762,1.99451622834699,21.509999409318,-0.000728541987664946,-9.34561798085477E-5,0.25,3.22891772034887E-6,-6.40164400463949E-5,2.77440503638383E-6,4.9993086,5.0004306,34015.1640625,34070.0859375,57.0119841926983,20.5262545440466,8.102614,0,0,0,40,4449,5.0001,34042.625,,,,,,,,,,,,,0,,,,0,,,,,,4.9998696,,,,
,32025434.5,5.0011578,31948.92578125,-5.87720154702478E-5,1.02797702283156E-6,1,0.999253354069792,40.0298881530762,1.9945346593276,21.509999409318,-0.000666517753027335,-8.88615725616917E-5,0.25,2.6599716741773E-6,-5.86157741122572E-5,2.24918933780264E-6,5.0008965,5.0014191,31921.298828125,31976.552734375,56.7227816405829,20.5255005101534,8.102614,0,0,0,40,4449,5.0014,31948.92578125,,,,,,,,,,,,,0,,,,0.0049,,,,,,5.0011578,,,,
,32025476.425,5.00038555,29852.3876953125,-5.0780479824424E-5,1.09798819235112E-6,1,0.999253354069792,40.0298881530762,1.99436786822547,21.509999409318,-0.000576750949376546,-7.09665732518548E-5,0.25,2.80808895791645E-6,-5.06374946794109E-5,2.45598911177127E-6,4.9996729,5.0010982,29827.556640625,29877.21875,56.394497662506,20.5311324990802,8.482265,0,0,0,40,4449,5.00005,29852.3876953125,,,,,,,,,,,,,0,,,,0.00245,,,,,,5.00038555,,,,
,32025518.405,5.0007782,27755.8056640625,-4.26432936636744E-5,1.15462162845526E-6,1,0.999253354069792,40.0298881530762,1.99448745947448,21.509999409318,-0.000480912414196301,-7.81783601919792E-5,0.25,7.00057835542514E-7,-4.25026071862761E-5,4.14013580904934E-7,5.0001407,5.0014157,27733.205078125,27778.40625,56.1764233056406,20.530785687788,7.722963,0,0,0,40,4449,5.0006,27755.8056640625,,,,,,,,,,,,,0,,,,-0.00245,,,,,,5.0007782,,,,
,32025560.405,4.99979375,25656.4443359375,-3.68905652693247E-5,7.89723195766084E-7,1,0.999253354069792,40.0298881530762,1.99450913330463,21.509999409318,-0.000416785295917975,-6.2951305414555E-5,0.25,1.01654271888191E-6,-3.67634807122584E-5,7.7164730478995E-7,4.9995513,5.0000362,25628.94921875,25683.939453125,56.4914195988906,20.5317939919179,8.482265,0,0,0,40,4449,5.00045,25656.4443359375,,,,,,,,,,,,,0,,,,0,,,,,,4.99979375,,,,
,32025602.36,5.00140305,23557.6669921875,-2.99741571651821E-5,8.43338943899189E-7,1,0.999253354069792,40.0298881530762,1.994383172092,21.509999409318,-0.000340854302144477,-3.82781085696907E-5,0.25,1.96623787922789E-6,-2.98717176675183E-5,1.76632295601874E-6,5.0009255,5.0018806,23535.18359375,23580.150390625,56.7282530402175,20.5347473961424,8.102614,0,0,0,40,4449,5.00055,23557.6669921875,,,,,,,,,,,,,0,,,,-0.00245,,,,,,5.00140305,,,,
,32025644.345,5.0018101,21458.3115234375,-2.2737134509509E-5,7.94059087878339E-7,1,0.999253354069792,40.0298881530762,1.99442197062386,21.509999409318,-0.000257394916513159,-3.52330568732289E-5,0.25,9.36639563641292E-7,-2.26509798679874E-5,7.89834216171153E-7,5.0018101,5.0018101,21430.8515625,21485.771484375,56.9580518248714,20.5305467685934,8.482265,0,0,0,40,4449,4.9996,21458.3115234375,,,,,,,,,,,,,0,,,,0.0049,,,,,,5.0018101,,,,
,32025686.315,5.0004835,19362.0947265625,-1.6150600807566E-5,7.31432260622976E-7,1,0.999253354069792,40.0298881530762,1.99433087100707,21.509999409318,-0.000182570278618378,-2.6223444410963E-5,0.25,5.56060595346887E-7,-1.60853348455965E-5,4.5428032454253E-7,5.0004835,5.0004835,19342.216796875,19381.97265625,56.7126204698329,20.5364768752564,8.861917,0,0,0,40,4449,4.99815,19362.0947265625,,,,,,,,,,,,,0,,,,0.00245,,,,,,5.0004835,,,,
,32025728.21,5.0012803,17268.0107421875,-8.68531251335697E-6,6.08550060721925E-7,1,0.999253354069792,40.0298881530762,1.99446925048895,21.509999409318,-9.905888442735E-5,-9.11316312959736E-6,0.25,7.41752510641666E-7,-8.65110569813551E-6,6.86205554550312E-7,5.0009723,5.0015883,17242.642578125,17293.37890625,57.0557553897753,20.5353643680091,8.102614,0,0,0,40,4449,4.9992,17268.0107421875,,,,,,,,,,,,,0,,,,0.00245,,,,,,5.0012803,,,,
,32025770.17,5.0006478,15169.16796875,-2.05653136587752E-6,5.93068009464299E-7,1,0.999253354069792,40.0298881530762,1.99430474310036,21.5199999511242,-2.36569132501371E-5,-9.9183574420244E-7,0.25,2.79098035347142E-7,-2.04861564570084E-6,2.65730840317585E-7,5.0001345,5.0011611,15144.474609375,15193.861328125,56.0724667125828,20.536650186104,8.861917,0,0,0,40,4449,4.9986,15169.16796875,,,,,,,,,,,,,0,,,,0.00245,,,,,,5.0006478,,,,
,32025812.14,5.0004725,13074.736328125,4.78820504268393E-6,5.96997696727674E-7,1,0.999253354069792,40.0298881530762,1.99443218332742,21.509999409318,5.38401287420803E-5,9.21069540347173E-6,0.25,-3.45041589643E-8,4.765267686525E-6,-6.95141574711877E-9,5.0004725,5.0004725,13049.9404296875,13099.5322265625,56.8681645451599,20.5361435833454,8.102614,0,0,0,40,4449,4.9977,13074.736328125,,,,,,,,,,,,,0,,,,-0.00245,,,,,,5.0004725,,,,
,32025854.215,5.001164,10971.546875,1.15252439450858E-5,5.09826993983898E-7,1,0.999253354069792,40.0298881530762,1.99443226236392,21.509999409318,0.000128774698765698,2.66258642790538E-5,0.25,3.15904270514815E-7,1.14657401799291E-5,3.78467874122119E-7,5.001164,5.001164,10946.548828125,10996.544921875,56.9815006804483,20.5359543959379,8.102614,0,0,0,40,4449,4.99835,10971.546875,,,,,,,,,,,,,0,,,,0.00245,,,,,,5.001164,,,,
,32025896.085,5.00081255,8876.53466796875,1.83692387967947E-5,4.82385798381194E-7,1,0.999253354069792,40.0298881530762,1.99427886743067,21.509999409318,0.000205728343598088,3.94352303301422E-5,0.25,2.39844971688531E-7,1.82728001483089E-5,3.3799724045863E-7,4.9996529,5.0019722,8851.658203125,8901.4111328125,56.8134505488137,20.5407085738518,8.482265,0,0,0,40,4449,4.99675,8876.53466796875,,,,,,,,,,,,,0,,,,-0.00245,,,,,,5.00081255,,,,
,32025938.08,5.00125765,6777.67797851562,2.52084025413961E-5,4.58439603537748E-7,1,0.999253354069792,40.0298881530762,1.9943187700594,21.509999409318,0.000282632111058033,5.2159942210413E-5,0.25,1.59304682778822E-7,2.50729950624028E-5,2.90955094087273E-7,5.0011444,5.0013709,6752.43310546875,6802.9228515625,56.8634747740445,20.5374427935913,8.482265,0,0,0,40,4449,4.9981,6777.67797851562,,,,,,,,,,,,,0,,,,0,,,,,,5.00125765,,,,
,32025980.1,5.0010221,4678.97998046875,3.19044274353894E-5,3.53081152190951E-7,1,0.999253354069792,40.0298881530762,1.99430589564319,21.509999409318,0.000357811986662684,6.51045245000955E-5,0.25,1.26226666910561E-7,3.17287864094836E-5,2.88402038218911E-7,5.0002413,5.0018029,4654.15625,4703.8037109375,56.6876083572175,20.5383786532146,7.722963,0,0,0,40,4449,4.9963,4678.97998046875,,,,,,,,,,,,,0,,,,0.00245,,,,,,5.0010221,,,,
,32026022.14,5.00120285,2577.08117675781,3.8623376296412E-5,3.93977578994197E-7,1,0.999253354069792,40.0298881530762,1.99436950200761,21.509999409318,0.000433813008383522,7.49169977069054E-5,0.25,-1.88309008492887E-7,3.84073799004813E-5,4.38105065693911E-9,5.0005627,5.001843,2549.67749023438,2604.48486328125,56.7016776705637,20.5373502730583,8.102614,0,0,0,40,4449,4.9966,2577.08117675781,,,,,,,,,,,,,0,,,,0,,,,,,5.00120285,,,,
,32026063.985,4.99994085,484.810684204102,4.42267195398485E-5,3.35962030669641E-7,1,0.999253354069792,40.0298881530762,1.99436910538423,21.509999409318,0.00049619446675932,8.8594505395517E-5,0.25,4.09336222889523E-8,4.39733888557719E-5,2.54725079888952E-7,4.999341,5.0005407,459.753784179687,509.867584228516,56.7853119221214,20.5391941109728,8.482265,0,0,0,40,4449,4.99695,484.810684204102,,,,,,,,,,,,,0,,,,0.00245,,,,,,4.99994085,,,,
,32026105.96,5.0005355,-1611.34899902344,4.88160663990694E-5,2.98373107942734E-7,1,0.999253354069792,40.0298881530762,1.99442362776494,21.509999409318,0.00054801259345716,9.61925427577125E-5,0.25,-1.00697596233635E-7,4.85397710460478E-5,1.39126110221785E-7,4.9997044,5.0013666,-1636.53930664062,-1586.15869140625,56.5828701356406,20.5410026894961,8.102614,0,0,0,40,4449,4.9975,-1611.34899902344,,,,,,,,,,,,,0,,,,-0.00245,,,,,,5.0005355,,,,
,32026147.895,5.0006845,-3703.86413574219,5.46156976528888E-5,4.31613016766761E-7,1,0.999253354069792,40.0298881530762,1.9943881130083,21.509999409318,0.000612824670346521,0.000109658427326042,0.25,6.04551597221295E-8,5.43123711123542E-5,3.35214407169605E-7,4.9999638,5.0014052,-3728.72729492188,-3679.0009765625,56.7790588939676,20.5394411836633,8.482265,0,0,0,40,4449,4.99775,-3703.86413574219,,,,,,,,,,,,,0,,,,0,,,,,,5.0006845,,,,
,32026190.095,5.0005107,-5816.60522460937,6.09784890922403E-5,4.06929787083936E-7,1,0.999253354069792,40.0298881530762,1.99427803022301,21.509999409318,0.000684854753112131,0.00011921996360506,0.25,-2.28936809294149E-7,6.06499563680491E-5,8.85514940407457E-8,5.0002799,5.0007415,-5839.056640625,-5794.15380859375,57.0213637349291,20.541483817961,8.482265,0,0,0,40,4449,4.99635,-5816.60522460937,,,,,,,,,,,,,0,,,,0.00245,,,,,,5.0005107,,,,
,32026231.815,5.000145,-7900.83544921875,6.65436435766883E-5,5.238313352936E-7,1,0.999253354069792,40.0298881530762,1.99445557819243,21.509999409318,0.000747264227354141,0.000131661266920581,0.25,-1.23726444316644E-7,6.6194641700783E-5,2.32187177493743E-7,4.9999619,5.0003281,-7928.29931640625,-7873.37158203125,57.4934673605446,20.538259733751,8.482265,0,0,0,40,4449,4.99635,-7900.83544921875,,,,,,,,,,,,,0,,,,0,,,,,,5.000145,,,,
,32026273.885,5.00146385,-10002.9399414062,7.24599436054616E-5,4.70566735823572E-7,1,0.999253354069792,40.0298881530762,1.99438676435566,21.509999409318,0.000813372898598749,0.000145846499904854,0.25,7.31462156393242E-8,7.20907434748652E-5,4.70887174236336E-7,5.0013537,5.001574,-10032.853515625,-9973.0263671875,56.9510171681983,20.5419243240949,8.482265,0,0,0,40,4449,4.9961,-10002.9399414062,,,,,,,,,,,,,0,,,,-0.00245,,,,,,5.00146385,,,,
,32026315.76,5.00053785,-12096.931640625,7.69204474957009E-5,4.83727846439314E-7,1,0.999253354069792,40.0298881530762,1.99441713135828,21.509999409318,0.000864471164031785,0.000150009536260921,0.25,-3.65607947173001E-7,7.65443896933696E-5,7.06600390341495E-8,4.9996953,5.0013804,-12121.8271484375,-12072.0361328125,56.8572217458906,20.5419686299023,8.102614,0,0,0,40,4449,4.99515,-12096.931640625,,,,,,,,,,,,,0,,,,0.00245,,,,,,5.00053785,,,,
,32026358.025,4.99912355,-14208.90625,8.12963578420971E-5,6.45110690479518E-7,1,0.999253354069792,40.0298881530762,1.99451288874821,21.509999409318,0.000912984768341365,0.000163493055145128,0.25,3.86186412402648E-8,8.09114544898356E-5,5.10047560923552E-7,4.9989972,4.9992499,-14241.3740234375,-14176.4384765625,56.8970848003714,20.539491521571,8.102614,0,0,0,40,4449,4.99675,-14208.90625,,,,,,,,,,,,,0,,,,0,,,,,,4.99912355,,,,
,32026400.03,5.0000036,-16310.0483398438,8.38799077023934E-5,5.83903072653052E-7,1,0.999253354069792,40.0298881530762,1.99435440353369,21.509999409318,0.000942431129633343,0.00016690337432587,0.25,-1.33244025105929E-7,8.34997770502859E-5,3.66388028335023E-7,4.9996648,5.0003424,-16335.17578125,-16284.9208984375,57.3136928011214,20.5425469973498,8.482265,0,0,0,40,4449,4.99655,-16310.0483398438,,,,,,,,,,,,,0,,,,0,,,,,,5.0000036,,,,
,32026441.71,4.9996719,-18393.8515625,8.38024628917208E-5,6.76858643357145E-7,1,0.999253354069792,40.0298881530762,1.99427729564734,21.509999409318,0.000943052767469633,0.00015928172404539,0.25,-8.12102911622526E-7,8.34432189370082E-5,-2.98100805499357E-7,4.9992332,5.0001106,-18418.767578125,-18368.935546875,57.2370932062368,20.541720316212,8.102614,0,0,0,40,4449,4.99635,-18393.8515625,,,,,,,,,,,,,0,,,,-0.00245,,,,,,4.9996719,,,,
,32026483.62,5.0007038,-20487.73828125,8.0929994506043E-5,6.64982379750564E-7,1,0.999253354069792,40.0298881530762,1.9942717977906,21.509999409318,0.000910058011276408,0.000158626538666501,0.25,-3.70476416343969E-7,8.05969533364038E-5,1.35127547723596E-7,4.9998941,5.0015135,-20512.470703125,-20463.005859375,57.3269804859484,20.5388681955906,8.102614,0,0,0,40,4449,4.9973,-20487.73828125,,,,,,,,,,,,,0,,,,-0.0049,,,,,,5.0007038,,,,
,32026525.68,5.00053645,-22589.2724609375,7.76019899718965E-5,6.75501524719455E-7,1,0.999253354069792,40.0298881530762,1.99419669874167,21.509999409318,0.000875553768571086,0.000136684653442137,0.25,-1.73980816585065E-6,7.73076259540732E-5,-1.23944051686194E-6,5.0000644,5.0010085,-22616.591796875,-22561.953125,57.1323549846599,20.543544496513,8.102614,0,0,0,40,4449,4.99635,-22589.2724609375,,,,,,,,,,,,,0,,,,0,,,,,,5.00053645,,,,
,32026567.64,5.00021675,-24685.1767578125,7.52783187640398E-5,7.96851074233271E-7,1,0.999253354069792,40.0298881530762,1.99431219133791,21.509999409318,0.000846240367856752,0.000151182773624841,0.25,-4.6217282047753E-8,7.4998257716052E-5,4.42026227342884E-7,4.9997244,5.0007091,-24705.234375,-24665.119140625,56.5688008222944,20.5416335831579,8.102614,0,0,0,40,4449,4.99565,-24685.1767578125,,,,,,,,,,,,,0,,,,-0.00245,,,,,,5.00021675,,,,
,32026609.585,4.999877,-26784.37890625,7.0818528669481E-5,8.43896984279461E-7,1,0.999253354069792,40.0298881530762,1.99422593294895,21.509999409318,0.000798597212573179,0.000129143000889365,0.25,-1.21767458442281E-6,7.05780646472081E-5,-7.45972576201573E-7,4.999877,4.999877,-26804.48828125,-26764.26953125,57.0135474497368,20.5406127611472,8.482265,0,0,0,40,4449,4.99655,-26784.37890625,,,,,,,,,,,,,0,,,,-0.00245,,,,,,4.999877,,,,
,32026651.535,4.9999542,-28880.9697265625,6.90068011594746E-5,8.64311422940699E-7,1,0.999253354069792,40.0298881530762,1.99431008178945,21.509999409318,0.000780107270061068,0.000116197118098372,0.25,-2.05438115433499E-6,6.87934750095314E-5,-1.58462061131977E-6,4.9999542,4.9999542,-28903.501953125,-28858.4375,56.9986965078714,20.5468882711041,8.482265,0,0,0,40,4449,4.998,-28880.9697265625,,,,,,,,,,,,,0,,,,-0.00245,,,,,,4.9999542,,,,
,32026693.51,4.9991417,-30976.427734375,7.01300729075609E-5,1.0746931004067E-6,1,0.999253354069792,40.0298881530762,1.99426406300678,21.509999409318,0.000794695369221544,0.000108484167682782,0.25,-2.95094049243799E-6,6.99347831182263E-5,-2.46423980056207E-6,4.9991417,4.9991417,-30996.359375,-30956.49609375,56.7282530402175,20.5452148858683,8.482265,0,0,0,40,4449,4.9979,-30976.427734375,,,,,,,,,,,,,0,,,,0.0049,,,,,,4.9991417,,,,
,32026735.605,4.9997635,-33080.962890625,7.2466205780885E-5,8.09050791085911E-7,1,0.999253354069792,40.0298881530762,1.99417459332254,21.509999409318,0.000818820616114838,0.000126023083887482,0.25,-1.81984853221063E-6,7.22723176228744E-5,-1.31432059663293E-6,4.9997635,4.9997635,-33105.96875,-33055.95703125,56.4812584281406,20.5432649486074,8.482265,0,0,0,40,4449,4.99945,-33080.962890625,,,,,,,,,,,,,0,,,,0,,,,,,4.9997635,,,,
,32026777.385,4.9994764,-35169.623046875,7.51989025289555E-5,8.72810302872129E-7,1,0.999253354069792,40.0298881530762,1.99421445914087,21.509999409318,0.000849531474351795,0.000132887777584162,0.25,-1.70987053832991E-6,7.50132715725969E-5,-1.17976368639476E-6,4.9994764,4.9994764,-35194.77734375,-35144.46875,56.8197035769676,20.5446425803949,7.722963,0,0,0,40,4449,4.99905,-35169.623046875,,,,,,,,,,,,,0,,,,0.00245,,,,,,4.9994764,,,,
,32026819.46,4.9992681,-37271.134765625,7.91260665141318E-5,1.32648253296156E-6,1,0.999253354069792,40.0298881530762,1.99422417839074,21.509999409318,0.000893243713147794,0.000144638798637709,0.25,-1.38055566174243E-6,7.89455802752212E-5,-8.18021841958523E-7,4.999054,4.9994822,-37293.71875,-37248.55078125,57.0870205305445,20.5444410012471,7.722963,0,0,0,40,4449,4.9991,-37271.134765625,,,,,,,,,,,,,0,,,,0.00245,,,,,,4.9992681,,,,
,32026861.335,4.99851155,-39364.728515625,8.49122224980315E-5,9.01349320215826E-7,1,0.999253354069792,40.0298881530762,1.9941696471126,21.509999409318,0.000957841562350814,0.000160310368449544,0.25,-1.03739306349357E-6,8.47343286573439E-5,-4.29112282861397E-7,4.9982147,4.9988084,-39391.97265625,-39337.484375,57.1815975813714,20.5432761414142,8.861917,0,0,0,40,4449,4.99945,-39364.728515625,,,,,,,,,,,,,0,,,,-0.00245,,,,,,4.99851155,,,,
,32026917.315,4.9987874,-38579.048828125,8.29314867778631E-5,1.03423760391875E-6,1,0.999253354069792,40.0298881530762,1.99411369921991,21.509999409318,0.000934939304286981,0.000159083659400781,0.25,-7.86333299956042E-7,8.27491971693746E-5,-1.94761715763887E-7,4.9985685,4.9990063,-38606.3046875,-38551.79296875,57.4145228801022,20.5461409187239,7.722963,0,0,0,40,4449,5.0006,-38579.048828125,,,,,,,,,,,,,0,,,,0,,,,,,4.9987874,,,,
,32026959.525,4.99891995,-36474.24609375,7.39882065325302E-5,8.59944508709347E-7,1,0.999253354069792,40.0298881530762,1.9941776370499,21.509999409318,0.000835237121297928,0.000134765065441254,0.25,-1.33037586139107E-6,7.38134196789071E-5,-8.0627318880119E-7,4.9986424,4.9991975,-36499.3671875,-36449.125,57.180034324333,20.5459772789717,8.482265,0,0,0,40,4449,4.9994,-36474.24609375,,,,,,,,,,,,,0,,,,0.00245,,,,,,4.99891995,,,,
,32027001.385,4.99997115,-34380.564453125,6.71316449151789E-5,9.03680849369432E-7,1,0.999253354069792,40.0298881530762,1.99420914801398,21.509999409318,0.00075897452293849,0.000115026923808161,0.25,-1.84387140206913E-6,6.69624676281438E-5,-1.37174264506124E-6,4.9995651,5.0003772,-34410.83203125,-34350.296875,56.9713395096983,20.5422052769685,8.482265,0,0,0,40,4449,4.9993,-34380.564453125,,,,,,,,,,,,,0,,,,-0.00245,,,,,,4.99997115,,,,
,32027043.45,4.99970175,-32276.982421875,6.03780899413627E-5,8.33406707723247E-7,1,0.999253354069792,40.0298881530762,1.9941720829089,21.509999409318,0.000681856578610702,0.000106753308529287,0.25,-1.35760153640258E-6,6.02102655702662E-5,-9.38843335122155E-7,4.9994502,4.9999533,-32296.861328125,-32257.103515625,57.454385934583,20.5473959465848,7.722963,0,0,0,40,4449,4.99915,-32276.982421875,,,,,,,,,,,,,0,,,,0,,,,,,4.99970175,,,,
,32027085.23,4.9999156,-30190.4677734375,5.3263034333808E-5,8.91150742348245E-7,1,0.999253354069792,40.0298881530762,1.9941643080745,21.509999409318,0.000596831132717009,0.000119420250026846,0.25,1.05443327913079E-6,5.30879037892715E-5,1.41189418790167E-6,4.9999156,4.9999156,-30213.228515625,-30167.70703125,56.9377294833714,20.5467316608535,8.482265,0,0,0,40,4449,4.99865,-30190.4677734375,,,,,,,,,,,,,0,,,,0,,,,,,4.9999156,,,,
,32027127.18,5.00061825,-28094.1591796875,4.65975942738746E-5,1.14305710371551E-6,1,0.999253354069792,40.0298881530762,1.99413701760364,21.509999409318,0.000524297202885678,9.17722699489249E-5,0.25,-2.00473827070923E-7,4.6441749840756E-5,1.10982065117433E-7,5.0002728,5.0009637,-28114.09765625,-28074.220703125,56.3960609195444,20.5466597755565,8.102614,0,0,0,40,4449,4.99825,-28094.1591796875,,,,,,,,,,,,,0,,,,-0.00245,,,,,,5.00061825,,,,
,32027169.3,5.0009446,-25989.88671875,3.87089904272782E-5,7.81853658943447E-7,1,0.999253354069792,40.0298881530762,1.99416534372624,21.5199999511242,0.000436438860351269,7.06963187296767E-5,0.25,-6.5364178291776E-7,3.85742781893796E-5,-3.97478016529534E-7,5.0009446,5.0009446,-26015,-25964.7734375,57.2636685758907,20.5461864742207,8.482265,0,0,0,40,4449,5.0002,-25989.88671875,,,,,,,,,,,,,0,,,,-0.00245,,,,,,5.0009446,,,,
,32027211.065,5.0000424,-23898.923828125,3.20209050922993E-5,7.00304205261981E-7,1,0.999253354069792,40.0298881530762,1.99407355823582,21.509999409318,0.000358552755480279,7.17707194939898E-5,0.25,6.46943997811541E-7,3.18949289302706E-5,8.50630449329463E-7,5.0000424,5.0000424,-23921.703125,-23876.14453125,56.6227331901214,20.5450350522249,8.102614,0,0,0,40,4449,4.9979,-23898.923828125,,,,,,,,,,,,,0,,,,0,,,,,,5.0000424,,,,
,32027253.03,5.0012536,-21802.3974609375,2.52441089457948E-5,5.60554776014512E-7,1,0.999253354069792,40.0298881530762,1.99409535837756,21.509999409318,0.000283500698600786,5.16178541909465E-5,0.25,7.24545220242868E-8,2.51423168520391E-5,2.31486854044006E-7,5.000833,5.0016742,-21826.927734375,-21777.8671875,56.8197035769676,20.5451057292586,8.482265,0,0,0,40,4449,4.9975,-21802.3974609375,,,,,,,,,,,,,0,,,,-0.00245,,,,,,5.0012536,,,,
,32027295.095,5.0013158,-19701.5009765625,1.81003088578568E-5,7.22799774270209E-7,1,0.999253354069792,40.0298881530762,1.99408183058369,21.509999409318,0.000203250384284354,3.68872300376885E-5,0.25,4.40796156524873E-8,1.80236494244836E-5,1.55711856744289E-7,5.0009646,5.001667,-19728.634765625,-19674.3671875,56.9619599674676,20.5452495755861,8.102614,0,0,0,40,4449,4.99715,-19701.5009765625,,,,,,,,,,,,,0,,,,0,,,,,,5.0013158,,,,
,32027337.1,5.00091815,-17599.6298828125,1.21131973976184E-5,6.35552188635908E-7,1,0.999253354069792,40.0298881530762,1.99415740160749,21.509999409318,0.000135845127774797,2.55358738109597E-5,0.25,1.07222389310167E-7,1.20589970835545E-5,1.7988610468697E-7,5.0004606,5.0013757,-17629.67578125,-17569.583984375,56.6227331901214,20.5480661503815,8.482265,0,0,0,40,4449,4.99745,-17599.6298828125,,,,,,,,,,,,,0,,,,0.00245,,,,,,5.00091815,,,,
,32027378.945,5.0013671,-15510.5747070313,4.57550159907461E-6,6.0269637537982E-7,1,0.999253354069792,40.0298881530762,1.99409053051367,21.509999409318,5.22632708160405E-5,4.25800139833467E-6,0.25,-4.38393216499489E-7,4.55697108712585E-6,-4.0940468174724E-7,5.0009117,5.0018225,-15535.7294921875,-15485.419921875,56.8970848003714,20.5462678861343,8.102614,0,0,0,40,4449,4.997,-15510.5747070313,,,,,,,,,,,,,0,,,,-0.00245,,,,,,5.0013671,,,,
,32027420.915,5.0006881,-13411.9077148438,-2.00973286037816E-6,5.61714502185911E-7,1,0.999253354069792,40.0298881530762,1.99422773100554,21.509999409318,-2.23011406050141E-5,-5.52042281415196E-6,0.25,-1.32829234024961E-7,-1.99931882111E-6,-1.43734994092801E-7,5.0006881,5.0006881,-13437.171875,-13386.6435546875,56.9994781363906,20.5475922102095,8.482265,0,0,0,40,4449,4.9977,-13411.9077148438,,,,,,,,,,,,,0,,,,0,,,,,,5.0006881,,,,
,32027463.055,5.0000291,-11305.2729492187,-9.0585059705775E-6,5.50497196741052E-7,1,0.999253354069792,40.0298881530762,1.99409364563786,21.509999409318,-0.000100541258157816,-2.46148608221268E-5,0.25,-5.76799599901988E-7,-9.01014689439993E-6,-6.24565259823735E-7,5.0000291,5.0000291,-11328,-11282.5458984375,57.251162519583,20.5468287472095,8.102614,0,0,0,40,4449,4.99725,-11305.2729492187,,,,,,,,,,,,,0,,,,-0.00245,,,,,,5.0000291,,,,
,32027504.895,5.0004163,-9213.94189453125,-1.6023257047975E-5,4.17080846888638E-7,1,0.999253354069792,40.0298881530762,1.99399064738203,21.509999409318,-0.000179081382280615,-3.63751434471122E-5,0.25,-3.8522549045685E-7,-1.59385983777636E-5,-4.70341150957754E-7,5.0004163,5.0004163,-9239.0673828125,-9188.81640625,56.7579549239483,20.5485361528537,8.102614,0,0,0,40,4449,4.99755,-9213.94189453125,,,,,,,,,,,,,0,,,,0.00245,,,,,,5.0004163,,,,
,32027546.815,4.9999523,-7118.76782226563,-2.21109432436018E-5,5.59922233353879E-7,1,0.999253354069792,40.0298881530762,1.99405748850831,21.509999409318,-0.000247174372278988,-4.97047884957902E-5,0.25,-4.91883639972897E-7,-2.19908645918758E-5,-6.06042987749111E-7,4.9999523,4.9999523,-7143.8984375,-7093.63720703125,57.4301554504868,20.5467407834823,7.722963,0,0,0,40,4449,4.99625,-7118.76782226563,,,,,,,,,,,,,0,,,,-0.0049,,,,,,4.9999523,,,,
,32027588.805,4.9999151,-5020.41772460937,-2.85374393362794E-5,4.36079288341215E-7,1,0.999253354069792,40.0298881530762,1.99411633192694,21.509999409318,-0.000319812615900095,-5.94471456089654E-5,0.25,-2.20683686987385E-7,-2.8380433271598E-5,-3.65849436872474E-7,4.9999151,4.9999151,-5040.32958984375,-5000.505859375,56.9408559974483,20.5482359616842,8.482265,0,0,0,40,4449,4.99625,-5020.41772460937,,,,,,,,,,,,,0,,,,0,,,,,,4.9999151,,,,
,32027630.745,5.0012002,-2922.86437988281,-3.57164452749551E-5,3.46986515791087E-7,1,0.999253354069792,40.0298881530762,1.9940603866438,21.509999409318,-0.000400375221176509,-7.34129703907072E-5,0.25,-1.94309310857004E-7,-3.55156001437645E-5,-3.71241223883699E-7,5.0012002,5.0012002,-2945.54638671875,-2900.18237304687,56.3093001539098,20.5474704298728,8.102614,0,0,0,40,4449,4.9956,-2922.86437988281,,,,,,,,,,,,,0,,,,-0.00245,,,,,,5.0012002,,,,
,32027672.855,5.0003338,-818.563629150391,-4.17320814876794E-5,3.63859309293142E-7,1,0.999253354069792,40.0298881530762,1.99410800744016,21.509999409318,-0.000466985966215197,-9.01678491176392E-5,0.25,-6.24360495195731E-7,-4.14907984366244E-5,-8.23452569329831E-7,5.0003338,5.0003338,-840.874206542969,-796.253051757812,56.7321611828137,20.5449237956757,8.102614,0,0,0,40,4449,4.9954,-818.563629150391,,,,,,,,,,,,,0,,,,0,,,,,,5.0003338,,,,
,32027714.665,5.0012398,1271.07635498047,-4.63019898752824E-5,3.61663874654163E-7,1,0.999253354069792,40.0298881530762,1.99401455380525,21.509999409318,-0.000518841821396482,-9.5928844751693E-5,0.25,-3.25196421870069E-7,-4.60370625924894E-5,-5.49353260986754E-7,5.0012398,5.0012398,1246.17126464844,1295.9814453125,56.7446672391214,20.5473239019455,8.102614,0,0,0,40,4449,4.99585,1271.07635498047,,,,,,,,,,,,,0,,,,0,,,,,,5.0012398,,,,
,32027756.625,4.9994993,3364.4794921875,-5.18605287749886E-5,4.09756448391949E-7,1,0.999253354069792,40.0298881530762,1.99394225673351,21.509999409318,-0.000581326259964113,-0.000106616320785919,0.25,-2.82683121475523E-7,-5.15702788003757E-5,-5.41127124751682E-7,4.9994993,4.9994993,3341.98950195313,3386.96948242188,56.7446672391214,20.5434402655673,8.102614,0,0,0,40,4449,4.99735,3364.4794921875,,,,,,,,,,,,,0,,,,0.00245,,,,,,4.9994993,,,,
,32027798.93,5.0007086,5480.42236328125,-5.84616387910453E-5,3.63245775743637E-7,1,0.999253354069792,40.0298881530762,1.99398294774341,21.509999409318,-0.000653928271080678,-0.000128618665917783,0.25,-1.05964984930476E-6,-5.81386874588075E-5,-1.35567542943334E-6,5.0007086,5.0007086,5457.5361328125,5503.30859375,56.709493955756,20.5445494474711,7.722963,0,0,0,40,4449,4.9961,5480.42236328125,,,,,,,,,,,,,0,,,,-0.00245,,,,,,5.0007086,,,,
,32027840.675,5.0001063,7566.85473632813,-6.43182303986795E-5,3.90286475923051E-7,1,0.999253354069792,40.0298881530762,1.99400095861806,21.509999409318,-0.000721227726585809,-0.000132113719032444,0.25,-3.17386466503498E-7,-6.39769526429073E-5,-6.57509376791761E-7,5.0001063,5.0001063,7541.96337890625,7591.74609375,57.3676251689484,20.5438122794136,8.482265,0,0,0,40,4449,4.99705,7566.85473632813,,,,,,,,,,,,,0,,,,0,,,,,,5.0001063,,,,
,32027882.525,5.0001917,9656.67431640625,-6.98851034076348E-5,4.49238066016697E-7,1,0.999253354069792,40.0298881530762,1.99408452457581,21.509999409318,-0.000782759030484612,-0.000149478012740183,0.25,-8.59703386017817E-7,-6.95227611684786E-5,-1.2374807822548E-6,5.0001917,5.0001917,9631.4208984375,9681.927734375,57.4410982497561,20.5440701649353,8.102614,0,0,0,40,4449,4.9961,9656.67431640625,,,,,,,,,,,,,0,,,,0,,,,,,5.0001917,,,,
,32027924.515,4.9991097,11757.6889648438,-7.50516806494131E-5,4.75193867166455E-7,1,0.999253354069792,40.0298881530762,1.9940900242022,21.509999409318,-0.000840680468025429,-0.000161090413034367,0.25,-9.59161347966971E-7,-7.46751906936707E-5,-1.37647074388284E-6,4.9991097,4.9991097,11735.28515625,11780.0927734375,57.0166739638137,20.5420028019041,7.722963,0,0,0,40,4449,4.99445,11757.6889648438,,,,,,,,,,,,,0,,,,-0.00245,,,,,,4.9991097,,,,
,32027966.475,4.9999022,13854.31640625,-7.81648674381838E-5,6.02876920862601E-7,1,0.999253354069792,40.0298881530762,1.99390009031172,21.509999409318,-0.00087527259427604,-0.000169796779346575,0.25,-1.16601304669212E-6,-7.77858137446039E-5,-1.61191764736747E-6,4.9999022,4.9999022,13829.2333984375,13879.3994140625,57.352774227083,20.5428426141734,8.482265,0,0,0,40,4449,4.9946,13854.31640625,,,,,,,,,,,,,0,,,,-0.00245,,,,,,4.9999022,,,,
,32028008.46,5.0004659,15950.9409179687,-8.04831906410498E-5,4.46431612446125E-7,1,0.999253354069792,40.0298881530762,1.99400457932536,21.509999409318,-0.00090173843140066,-0.000173247256465641,0.25,-1.04376469018751E-6,-8.01088489377078E-5,-1.51579696055767E-6,5.0004659,5.0004659,15928.3310546875,15973.55078125,56.5140868259483,20.5404975909163,8.102614,0,0,0,40,4449,4.9957,15950.9409179687,,,,,,,,,,,,,0,,,,-0.00245,,,,,,5.0004659,,,,
,32028050.415,4.9994392,18049.6259765625,-8.10937019955786E-5,4.92678384900207E-7,1,0.999253354069792,40.0298881530762,1.99405045784603,21.509999409318,-0.000910463636999769,-0.000165166354214695,0.25,-2.00228073303031E-7,-8.07374159885935E-5,-6.91450851321972E-7,4.9994392,4.9994392,18027.1328125,18072.119140625,57.190195495083,20.5425220886126,7.722963,0,0,0,40,4449,4.99585,18049.6259765625,,,,,,,,,,,,,0,,,,-0.00245,,,,,,4.9994392,,,,
,32028092.375,4.9991279,20145.779296875,-7.98469531953023E-5,6.14901326470269E-7,1,0.999253354069792,40.0298881530762,1.99400922712611,21.509999409318,-0.000896800401889002,-0.000161705887136462,0.25,-1.01517788857274E-7,-7.95127977705092E-5,-5.96662927481194E-7,4.9991279,4.9991279,20120.783203125,20170.775390625,57.3183825722368,20.5418595098462,8.482265,0,0,0,40,4449,4.997,20145.779296875,,,,,,,,,,,,,0,,,,-0.00245,,,,,,4.9991279,,,,
,32028134.37,4.999588,22244.9375,-7.60494115522489E-5,6.80020908605438E-7,1,0.999253354069792,40.0298881530762,1.99402009881273,21.509999409318,-0.000854291769361805,-0.000154265837904907,0.25,-1.06087476688315E-7,-7.5746807717625E-5,-5.87713125258086E-7,4.999588,4.999588,22219.669921875,22270.205078125,56.963523224506,20.5415412683904,7.722963,0,0,0,40,4449,4.99875,22244.9375,,,,,,,,,,,,,0,,,,0,,,,,,4.999588,,,,
,32028176.375,4.9987555,24346.2861328125,-7.28802198556201E-5,7.36874907087514E-7,1,0.999253354069792,40.0298881530762,1.99402548588468,21.509999409318,-0.000818102772797253,-0.000152134630328416,0.25,-4.72150791098951E-7,-7.26032274342866E-5,-9.41474192940991E-7,4.9987555,4.9987555,24323.767578125,24368.8046875,56.9580518248714,20.5391916080176,8.102614,0,0,0,40,4449,4.99815,24346.2861328125,,,,,,,,,,,,,0,,,,-0.00245,,,,,,4.9987555,,,,
,32028218.255,4.9992681,26437.76953125,-7.00651712991249E-5,9.04227854841446E-7,1,0.999253354069792,40.0298881530762,1.99405995097003,21.509999409318,-0.000787760314346564,-0.000140297470728495,0.25,8.75587784231989E-8,-6.98173839875557E-5,-3.73893097468991E-7,4.9992681,4.9992681,26413.166015625,26462.373046875,57.342613056333,20.5427033585599,8.482265,0,0,0,40,4449,4.99755,26437.76953125,,,,,,,,,,,,,0,,,,0,,,,,,4.9992681,,,,
,32028260.28,5.0001984,28537.3056640625,-6.84414852473442E-5,7.17920445516904E-7,1,0.999253354069792,40.0298881530762,1.99394435359799,21.509999409318,-0.000770685644675743,-0.000131193447340103,0.25,6.1562007614623E-7,-6.82179003727273E-5,1.55553263649799E-7,5.0001984,5.0001984,28512.4296875,28562.181640625,56.994006736756,20.5429275014848,7.722963,0,0,0,40,4449,4.9974,28537.3056640625,,,,,,,,,,,,,0,,,,0.0049,,,,,,5.0001984,,,,
,32028302.25,4.9974256,30635.74609375,-6.85560960612244E-5,8.74895129788251E-7,1,0.999253354069792,40.0298881530762,1.99407512028198,21.509999409318,-0.000768124437759096,-0.000154120810000957,0.25,-1.39235576795978E-6,-6.8333622929831E-5,-1.85385514234867E-6,4.9974256,4.9974256,30615.841796875,30655.650390625,57.1198489283522,20.5474873307866,8.102614,0,0,0,40,4449,4.99835,30635.74609375,,,,,,,,,,,,,0,,,,0.00245,,,,,,4.9974256,,,,
,32028344.18,4.9995191,32732.404296875,-7.0669991945721E-5,8.82085332265226E-7,1,0.999253354069792,40.0298881530762,1.99398578361063,21.509999409318,-0.000794495897700013,-0.000144734374881076,0.25,-1.69079020053541E-7,-7.04648837222812E-5,-6.55473921418334E-7,4.9995112,4.999527,32705.0703125,32759.73828125,56.8564401173714,20.5440543372749,8.102614,0,0,0,40,4449,4.99865,32732.404296875,,,,,,,,,,,,,0,,,,0.00245,,,,,,4.9995191,,,,
,32028386.145,4.9991121,34828.9453125,-7.39957238269259E-5,9.53578010614456E-7,1,0.999253354069792,40.0298881530762,1.99397445433595,21.509999409318,-0.000832170169217083,-0.000150999839002886,0.25,-1.19264761155769E-7,-7.37977948614174E-5,-6.35163636812334E-7,4.9991121,4.9991121,34804.015625,34853.875,56.7251265261406,20.5406865876509,8.102614,0,0,0,40,4449,4.9986,34828.9453125,,,,,,,,,,,,,0,,,,0.00245,,,,,,4.9991121,,,,
,32028428.12,4.998332,36927.685546875,-7.8014186079112E-5,9.36726617678049E-7,1,0.999253354069792,40.0298881530762,1.99393075177601,21.5199999511242,-0.00087834509396701,-0.000154759924538969,0.25,2.77810140263358E-7,-7.78257312164949E-5,-2.73275568375261E-7,4.9980731,4.9985909,36902.609375,36952.76171875,56.709493955756,20.5445591696226,8.102614,0,0,0,40,4449,4.99935,36927.685546875,,,,,,,,,,,,,0,,,,0,,,,,,4.998332,,,,
,32028470.32,4.9981463,39036.439453125,-8.26932146373987E-5,1.04972275494963E-6,1,0.999253354069792,40.0298881530762,1.99380385187357,21.509999409318,-0.000930462245759275,-0.00016804787715306,0.25,-5.33329445640371E-8,-8.25095026329667E-5,-6.42534687477468E-7,4.997642,4.9986506,39006.0625,39066.81640625,57.2238055214099,20.5460740248964,8.102614,0,0,0,40,4449,5.0002,39036.439453125,,,,,,,,,,,,,0,,,,0,,,,,,4.9981463,,,,
,32028525.035,4.99866485,38976.90625,-8.1127511815805E-5,9.8897064957489E-7,1,0.999253354069792,40.0298881530762,1.99395970723387,21.509999409318,-0.000914970241923764,-0.000153412807276703,0.25,9.66227613496048E-7,-8.09540231968531E-5,3.86072151332555E-7,4.9983792,4.9989505,38949.8515625,39003.9609375,56.8361177758714,20.5460471409801,8.102614,0,0,0,40,4449,5.00025,38976.90625,,,,,,,,,,,,,0,,,,0.00245,,,,,,4.99866485,,,,
,32028566.99,4.9991822,36884.05859375,-7.27620466664249E-5,1.17343615594166E-6,1,0.999253354069792,40.0298881530762,1.9940296886712,21.509999409318,-0.000819407384367064,-0.000143457529112068,0.25,3.38063604824825E-7,-7.25864985496173E-5,-1.76002199412124E-7,4.9984145,4.9999499,36858.796875,36909.3203125,56.8759808303522,20.5435358323505,7.722963,0,0,0,40,4449,5.00085,36884.05859375,,,,,,,,,,,,,0,,,,-0.00245,,,,,,4.9991822,,,,
,32028609.03,4.9993856,34782.22265625,-6.62074796214279E-5,9.12034063446299E-7,1,0.999253354069792,40.0298881530762,1.99384034024514,21.509999409318,-0.000746299006743978,-0.000125260995430167,0.25,7.67614276534186E-7,-6.6036153026561E-5,3.03804732707792E-7,4.9989724,4.9997988,34754.96484375,34809.48046875,57.4559491916215,20.5456115209694,8.482265,0,0,0,40,4449,5.0007,34782.22265625,,,,,,,,,,,,,0,,,,-0.0049,,,,,,4.9993856,,,,
,32028651.035,5.0004916,32683.8818359375,-5.9575300657484E-5,8.49106574810562E-7,1,0.999253354069792,40.0298881530762,1.99381966080655,21.509999409318,-0.000670367593971929,-0.000118336280024375,0.25,1.83271860085603E-7,-5.94043313695541E-5,-2.27578385994281E-7,5.0004916,5.0004916,32656.134765625,32711.62890625,56.8603482599676,20.5438697051294,7.722963,0,0,0,40,4449,4.9992,32683.8818359375,,,,,,,,,,,,,0,,,,-0.00245,,,,,,5.0004916,,,,
,32028693.035,4.9997039,30586.9755859375,-5.26487198046463E-5,9.1244266005993E-7,1,0.999253354069792,40.0298881530762,1.99400363553828,21.509999409318,-0.000592350636944352,-0.000104542371570367,0.25,1.58928753379003E-7,-5.24859430413092E-5,-1.99182928486434E-7,4.9997039,4.9997039,30567.0546875,30606.896484375,56.4070037188137,20.544076093691,8.482265,0,0,0,40,4449,4.99855,30586.9755859375,,,,,,,,,,,,,0,,,,-0.00245,,,,,,4.9997039,,,,
,32028734.915,5.0006962,28490.7548828125,-4.4839005482108E-5,7.77245046783186E-7,1,0.999253354069792,40.0298881530762,1.99400709765541,21.509999409318,-0.000505413873610297,-8.32152465682372E-5,0.25,6.46704481265739E-7,-4.46939348131794E-5,3.44587861328449E-7,5.0002971,5.0010953,28463.26953125,28518.240234375,57.0760777312753,20.5458641636906,8.102614,0,0,0,40,4449,5.00055,28490.7548828125,,,,,,,,,,,,,0,,,,0,,,,,,5.0006962,,,,
,32028777.085,5.0010655,26384.0498046875,-3.82138139526033E-5,7.00848331636768E-7,1,0.999253354069792,40.0298881530762,1.99403474496224,21.509999409318,-0.000430821765796584,-6.99290696165472E-5,0.25,6.3376898150328E-7,-3.80823132772424E-5,3.80122455800131E-7,5.0008726,5.0012584,26359.73046875,26408.369140625,56.8337728903137,20.5437282971937,7.722963,0,0,0,40,4449,4.9983,26384.0498046875,,,,,,,,,,,,,0,,,,-0.00245,,,,,,5.0010655,,,,
,32028818.86,5.00051095,24297.837890625,-3.14755725672521E-5,6.67147261164996E-7,1,0.999253354069792,40.0298881530762,1.99392968114621,21.509999409318,-0.00035298605609779,-6.74798137304241E-5,0.25,-3.62316085493288E-7,-3.13547671255697E-5,-5.64322225340452E-7,5.0003152,5.0007067,24270,24325.67578125,57.1065612435253,20.5461363963533,8.102614,0,0,0,40,4449,4.99805,24297.837890625,,,,,,,,,,,,,0,,,,0,,,,,,5.00051095,,,,
,32028860.875,5.0010147,22195.9326171875,-2.4367061647163E-5,6.18405024116332E-7,1,0.999253354069792,40.0298881530762,1.99389679098259,21.509999409318,-0.00027324546584281,-5.20012356893586E-5,0.25,-2.63332734085396E-7,-2.42685322076111E-5,-4.16665735372889E-7,5.0006804,5.001349,22170.75390625,22221.111328125,57.5247325013138,20.5457132516747,8.482265,0,0,0,40,4449,4.9983,22195.9326171875,,,,,,,,,,,,,0,,,,0.00245,,,,,,5.0010147,,,,
,32028902.82,5.0009539,20099.91015625,-1.81792439260594E-5,7.07782905979996E-7,1,0.999253354069792,40.0298881530762,1.99380273675797,21.509999409318,-0.00020399217197547,-3.77443588459179E-5,0.25,-1.06101350786129E-7,-1.81025687702261E-5,-2.18433152804997E-7,5.0005941,5.0013137,20077.302734375,20122.517578125,56.3788650921214,20.5471012506234,8.102614,0,0,0,40,4449,4.9974,20099.91015625,,,,,,,,,,,,,0,,,,0,,,,,,5.0009539,,,,
,32028944.775,5.00198055,18003.2568359375,-1.08075736149848E-5,5.36687136780238E-7,1,0.999253354069792,40.0298881530762,1.99380529154928,21.509999409318,-0.000122069772190721,-1.78461611601515E-5,0.25,3.43983438653134E-7,-1.07622911884839E-5,2.76926133861349E-7,5.0017858,5.0021753,17982.916015625,18023.59765625,57.9679158717177,20.5468286171226,8.102614,0,0,0,40,4449,4.9973,18003.2568359375,,,,,,,,,,,,,0,,,,0,,,,,,5.00198055,,,,
,32028986.66,5.0008156,15909.3916015625,-4.23621025126896E-6,5.67869533277455E-7,1,0.999253354069792,40.0298881530762,1.99399375249113,21.509999409318,-4.69899664743214E-5,-1.17619047288386E-5,0.25,-2.90317200910974E-7,-4.21509711893115E-6,-3.14072384023073E-7,5.0004978,5.0011334,15884.669921875,15934.11328125,57.5919525539676,20.5483838185283,7.722963,0,0,0,40,4449,4.99665,15909.3916015625,,,,,,,,,,,,,0,,,,0.00245,,,,,,5.0008156,,,,
,32029028.655,5.0009618,13810.5834960938,3.21811189957296E-6,5.05502165823825E-7,1,0.999253354069792,40.0298881530762,1.99381042413911,21.509999409318,3.60680974502713E-5,6.79942267271689E-6,0.25,3.10103165008414E-8,3.20259177443865E-6,4.94392969392661E-8,5.0004902,5.0014334,13785.5439453125,13835.623046875,57.4168677656599,20.5485787764223,8.102614,0,0,0,40,4449,4.9986,13810.5834960938,,,,,,,,,,,,,0,,,,0,,,,,,5.0009618,,,,
,32029070.645,5.0007143,11711.6918945313,9.51587435971038E-6,4.72588568443259E-7,1,0.999253354069792,40.0298881530762,1.99400889521963,21.509999409318,0.000107025722860954,1.79598155566109E-5,0.25,-9.78467415158188E-8,9.46933566878122E-6,-4.38822555258511E-8,5.0003138,5.0011148,11686.6923828125,11736.69140625,56.4101302328906,20.5451333184336,8.102614,0,0,0,40,4449,4.99695,11711.6918945313,,,,,,,,,,,,,0,,,,0.00245,,,,,,5.0007143,,,,
,32029112.655,5.0008824,9612.84521484375,1.63371233483777E-5,4.3329296175403E-7,1,0.999253354069792,40.0298881530762,1.99383628405432,21.509999409318,0.000183482330875019,3.20319772798286E-5,0.25,-5.80096167563899E-8,1.62537769485912E-5,3.15764489643806E-8,5.000536,5.0012288,9583.064453125,9642.6259765625,57.0119841926983,20.5473307400714,8.482265,0,0,0,40,4449,4.9965,9612.84521484375,,,,,,,,,,,,,0,,,,0.00245,,,,,,5.0008824,,,,
,32029154.67,5.0011096,7510.6083984375,2.31936288686076E-5,3.62281822505744E-7,1,0.999253354069792,40.0298881530762,1.99390156996009,21.509999409318,0.000260073111744365,4.76019541901347E-5,0.25,1.11272508393501E-7,2.30704810622206E-5,2.33843581887591E-7,5.0007558,5.0014634,7488.2685546875,7532.9482421875,56.8228300910445,20.5481878109185,8.102614,0,0,0,40,4449,4.99625,7510.6083984375,,,,,,,,,,,,,0,,,,-0.00245,,,,,,5.0011096,,,,
,32029196.525,5.0011926,5419.15356445313,2.96579766952503E-5,3.27891611387434E-7,1,0.999253354069792,40.0298881530762,1.99394442860503,21.509999409318,0.000333268032395944,5.66292358796753E-5,0.25,-2.30323794150379E-7,2.94979786139623E-5,-7.61075542077099E-8,5.0008612,5.001524,5394.33837890625,5443.96875,56.2428617297752,20.5488675400441,8.102614,0,0,0,40,4449,4.99565,5419.15356445313,,,,,,,,,,,,,0,,,,-0.00245,,,,,,5.0011926,,,,
,32029238.555,5.0001464,3317.26098632812,3.64086008211054E-5,3.78944252786403E-7,1,0.999253354069792,40.0298881530762,1.99390827620577,21.509999409318,0.000408448900176143,7.29494907125053E-5,0.25,2.93332032658682E-8,3.62055735526197E-5,2.11599090530124E-7,5,5.0002928,3289.9482421875,3344.57373046875,57.4082698519484,20.5477552362901,8.102614,0,0,0,40,4449,4.99715,3317.26098632812,,,,,,,,,,,,,0,,,,0.0049,,,,,,5.0001464,,,,
,32029280.735,5.0009391,1210.55120849609,4.262997066304E-5,3.60669655272781E-7,1,0.999253354069792,40.0298881530762,1.99390916423307,21.509999409318,0.000478120851291009,8.57731361232953E-5,0.25,7.28614083954274E-8,4.23870317842377E-5,2.80382151123715E-7,5.0007448,5.0011334,1185.29321289062,1235.80920410156,57.2050464369484,20.5487992554102,8.102614,0,0,0,40,4449,4.996,1210.55120849609,,,,,,,,,,,,,0,,,,0.0049,,,,,,5.0009391,,,,
,32029304.425,5.0001521,25.0555290132761,4.57683206190258E-5,3.38492578614788E-7,1,0.999253354069792,40.0298881530762,1.9938384423554,21.509999409318,0.000515226832032121,8.10968452997837E-5,0.25,-8.98197211947804E-7,4.55099614589702E-5,-6.72415492425891E-7,4.9997864,5.0005178,-0.441489428281784,50.552547454834,57.1917587521214,20.5481891659096,8.482265,0,0,0,40,4417,4.9962,25.0555290132761,,,,,,,,,,,,,0,,,,0,,,,,,5.0001521,,,,