File: data/monolayers/magneticStructure/ML_Ac_CoFe_C-2/PPMS/data/DD175_23_FCC_100OE.DAT
[Header]
; VSM Data File (default extension .dat)
; Copyright (c) 2003-2013, Quantum Design, Inc. All rights reserved.
TITLE,
FILEOPENTIME,31859550.80,01/05/2019,1:54 am
BYAPP,VSM,2.0,2.0
INFO,PPMS VSM Option Release 1.4.10 Build 1,APPNAME
INFO,Quantum Design Linear Motor Servo Controller,MOTOR_MODULE_NAME
INFO,3101-100 M1,MOTOR_HW_VERSION
INFO,MMC1014,MOTOR_SERIAL_NUMBER
INFO,SRV No X-over 01.03.11,MOTOR_SOFTWARE_VERSION
INFO,Quantum Design VSM Detection Module,VSM_MODULE_NAME
INFO,3101-150 F0,VSM_HW_VERSION
INFO,VSM707,VSM_SERIAL_NUMBER
INFO,VSM No X-over 01.02.05 May 20 2008 13:51:47,VSM_SOFTWARE_VERSION
INFO,704,PREAMP_SERIAL_NUMBER
INFO,822,COIL_SERIAL_NUMBER
INFO,0,MOMENT_UNITS
INFO,CoFe2O4 Monolayer,SAMPLE_MATERIAL
INFO,from YF45,SAMPLE_COMMENT
INFO,29.98,SAMPLE_MASS
INFO,,SAMPLE_VOLUME
INFO,,SAMPLE_MOLECULAR_WEIGHT
INFO,,SAMPLE_SIZE
INFO,,SAMPLE_SHAPE
DATATYPE,COMMENT,1
DATATYPE,TIME,2
STARTUPAXIS,X,2
STARTUPAXIS,Y1,5
[Data]
Comment,Time Stamp (sec),Temperature (K),Magnetic Field (Oe),Moment (emu),M. Std. Err. (emu),Transport Action,Averaging Time (sec),Frequency (Hz),Peak Amplitude (mm),Center Position (mm),Coil Signal' (mV),Coil Signal" (mV),Range (mV),M. Quad. Signal (emu),M. Raw' (emu),M. Raw" (emu),Min. Temperature (K),Max. Temperature (K),Min. Field (Oe),Max. Field (Oe),Mass (grams),Motor Lag (deg),Pressure (Torr),VSM Status (code),Motor Status (code),Measure Status (code),Measure Count,PPMS Status (code),System Temp. (K),System Field (Oe),Sample Position (deg),Bridge 1 Resistance (ohms),Bridge 1 Excitation (에),Bridge 2 Resistance (ohms),Bridge 2 Excitation (에),Bridge 3 Resistance (ohms),Bridge 3 Excitation (에),Bridge 4 Resistance (ohms),Bridge 4 Excitation (에),Signal 1 Vin (V),Signal 2 Vin (V),Digital Inputs (code),Drive 1 Iout (mA),Drive 1 Ipower (W),Drive 2 Iout (mA),Drive 2 Ipower (W),Pressure (),Map 20 (),Map 21 (),Map 22 (),Map 23 (),Map 24 (),Map 25 (),Map 26 (),Map 27 (),Map 28 (),Map 29 ()
,31859729.205,349.5788879,99.6243667602539,8.26931019588405E-6,4.54574275564187E-7,1,0.999253354069792,40.0298881530762,2.0073911809445,19.8800005018711,9.47856377776736E-5,1.06178728335334E-5,0.25,-4.9589967552157E-7,8.25504305317482E-6,-4.90419027499604E-7,349.5788879,349.5788879,99.6243667602539,99.6243667602539,56.8134505488137,20.5391373612501,26.705515,0,0,0,40,4369,350.2973,99.6243667602539,,,,,,,,,,,,,0,,,,-0.0049,,,,,,349.5788879,,,,
,31859876.81,346.98643495,99.6243667602539,7.83238409414516E-6,6.11856182197513E-7,1,0.999253354069792,40.0298881530762,2.00739046085356,19.8800005018711,8.89244091052023E-5,1.50293643215678E-5,0.25,-3.15594609421689E-8,7.81930970630666E-6,-2.70777444698228E-8,346.9624329,347.010437,99.6243667602539,99.6243667602539,56.8830154870253,20.5379768982888,27.085165,0,0,0,40,4374,345.30745,99.6243667602539,,,,,,,,,,,,,0,,,,0,,,,,,346.98643495,,,,
,31860028.125,343.4944763,99.6243667602539,8.69709641698899E-6,5.84359557375552E-7,1,0.999253354069792,40.0298881530762,2.00734336422695,19.8800005018711,9.87945569244586E-5,1.64408129164745E-5,0.25,-5.70868681465227E-8,8.68362128545462E-6,-5.20196529333369E-8,343.4944763,343.4944763,99.6243667602539,99.6243667602539,57.1175040427945,20.5380063426954,26.705515,0,0,0,40,4374,341.3032,99.6243667602539,,,,,,,,,,,,,0,,,,-0.0049,,,,,,343.4944763,,,,
,31860173.735,339.9482727,99.6243667602539,8.7810983536813E-6,4.15585931318772E-7,1,0.999253354069792,40.0298881530762,2.00732903215036,19.8800005018711,9.97338875160555E-5,1.67534063217638E-5,0.25,-4.4311926732649E-8,8.76854848527832E-6,-3.9162039555294E-8,339.9482727,339.9482727,99.6243667602539,99.6243667602539,57.0588819038522,20.5389317404474,27.085165,0,0,0,40,4374,337.5715,99.6243667602539,,,,,,,,,,,,,0,,,,0,,,,,,339.9482727,,,,
,31860296.585,336.9729004,99.6243667602539,9.34812010506962E-6,4.84284530334629E-7,1,0.999253354069792,40.0298881530762,2.00741032198515,19.8500007390976,0.000107004168709927,1.31304580542172E-5,0.25,-4.6198650275086E-7,9.33595714466832E-6,-4.55901327061515E-7,336.9729004,336.9729004,99.6243667602539,99.6243667602539,56.6211699330829,20.5310900683068,26.705515,0,0,0,40,4374,334.4224,99.6243667602539,,,,,,,,,,,,,0,,,,0,,,,,,336.9729004,,,,
,31860440.985,333.4519348,99.6243667602539,9.17103543362652E-6,4.27790425338127E-7,1,0.999253354069792,40.0298881530762,2.00742092809189,19.8500007390976,0.000103715857026545,2.02431409056762E-5,0.25,1.95087950448646E-7,9.15983548630791E-6,2.00285182227645E-7,333.4519348,333.4519348,99.6243667602539,99.6243667602539,56.7509202672752,20.5348861190417,26.705515,0,0,0,40,4374,330.7699,99.6243667602539,,,,,,,,,,,,,0,,,,0,,,,,,333.4519348,,,,
,31860581.4,329.9764404,99.6243667602539,8.91441343997412E-6,4.56394518874223E-7,1,0.999253354069792,40.0298881530762,2.00738898056138,19.8500007390976,0.000101513369210657,1.57002749624597E-5,0.25,-1.60899864927105E-7,8.90480938800142E-6,-1.55378943799087E-7,329.9764404,329.9764404,99.6243667602539,99.6243667602539,56.8580033744099,20.5362831900925,26.705515,0,0,0,40,4374,327.2107,99.6243667602539,,,,,,,,,,,,,0,,,,0,,,,,,329.9764404,,,,
,31860724.315,326.466156,99.6243667602539,9.17703272974266E-6,3.67840809783395E-7,1,0.999253354069792,40.0298881530762,2.00760686728535,19.8400001972914,0.000104128418592491,1.84710473524701E-5,0.25,3.72552328577659E-8,9.16814526523023E-6,4.27927884939241E-8,326.466156,326.466156,99.6243667602539,99.6243667602539,56.567237565256,20.5336413392148,26.705515,0,0,0,40,4374,323.597,99.6243667602539,,,,,,,,,,,,,0,,,,-0.0049,,,,,,326.466156,,,,
,31860866.335,322.9586182,99.6243667602539,9.04860260428904E-6,3.93464546159939E-7,1,0.999253354069792,40.0298881530762,2.00765658657438,19.8400001972914,0.000104181744265635,9.58094577606975E-6,0.25,-7.23645884820486E-7,9.04141668459383E-6,-7.17468743553386E-7,322.9586182,322.9586182,99.6243667602539,99.6243667602539,56.6258597041983,20.5369444176731,27.085165,0,0,0,40,4374,320.0014,99.6243667602539,,,,,,,,,,,,,0,,,,0,,,,,,322.9586182,,,,
,31861008.25,319.4468079,99.6243667602539,9.88167746432934E-6,3.82222756639317E-7,1,0.999253354069792,40.0298881530762,2.00771856884789,19.8400001972914,0.000113011219512952,1.49656016637354E-5,0.25,-3.94067049023695E-7,9.87480750234198E-6,-3.8762423538758E-7,319.4468079,319.4468079,99.6243667602539,99.6243667602539,56.8408075469868,20.5370501242221,27.464817,0,0,0,40,4374,316.44285,99.6243667602539,,,,,,,,,,,,,0,,,,0.00245,,,,,,319.4468079,,,,
,31861147.14,315.9825745,99.6243667602539,1.04334033387321E-5,5.08904776395384E-7,1,0.999253354069792,40.0298881530762,2.00769155549624,19.8500007390976,0.000118977449662714,1.7861648589376E-5,0.25,-2.34913968243901E-7,1.04273120517003E-5,-2.28185560946313E-7,315.9825745,315.9825745,99.6243667602539,99.6243667602539,56.6391473890252,20.5338477427201,27.085165,0,0,0,40,4374,312.96,99.6243667602539,,,,,,,,,,,,,0,,,,0.0049,,,,,,315.9825745,,,,
,31861289.58,312.4776001,99.6243667602539,1.00206204086123E-5,4.65226053203772E-7,1,0.999253354069792,40.0298881530762,2.00791537613233,19.8500007390976,0.000113894227305221,1.9481662470502E-5,0.25,-2.12725133701729E-8,1.0015882338685E-5,-1.48485933236811E-8,312.4776001,312.4776001,99.6243667602539,99.6243667602539,56.7087123272368,20.536895122453,27.085165,0,0,0,40,4374,309.3783,99.6243667602539,,,,,,,,,,,,,0,,,,0.00245,,,,,,312.4776001,,,,
,31861428.87,308.9944763,99.6243667602539,1.02385866142177E-5,4.26662428503201E-7,1,0.999253354069792,40.0298881530762,2.00790033220274,19.8500007390976,0.000116353042615587,2.009319094386E-5,0.25,-5.50309954571581E-9,1.02349990107074E-5,1.14129454383395E-9,308.9944763,308.9944763,99.6243667602539,99.6243667602539,56.8017261210252,20.5333344673301,26.705515,0,0,0,40,4374,305.877,99.6243667602539,,,,,,,,,,,,,0,,,,0.0049,,,,,,308.9944763,,,,
,31861570.705,305.4805603,99.6243667602539,9.99032164085896E-6,4.13344770024843E-7,1,0.999253354069792,40.0298881530762,2.00786597734676,19.8599994182587,0.000113568558551319,1.94666058989398E-5,0.25,-1.79104284192992E-8,9.98807653074466E-6,-1.13341969332078E-8,305.4805603,305.4805603,99.6243667602539,99.6243667602539,56.7743691228522,20.5298730412809,27.464817,0,0,0,40,4374,302.3275,99.6243667602539,,,,,,,,,,,,,0,,,,0,,,,,,305.4805603,,,,
,31861712.005,301.9986572,99.6243667602539,1.03157197101678E-5,4.67347862611998E-7,1,0.999253354069792,40.0298881530762,2.00786637761465,19.8599994182587,0.000117795981187643,1.71378616326894E-5,0.25,-2.7948775414626E-7,1.0314854535067E-5,-2.72576231588996E-7,301.9986572,301.9986572,99.6243667602539,99.6243667602539,56.7790588939676,20.5242186526048,27.085165,0,0,0,40,4374,298.7682,99.6243667602539,,,,,,,,,,,,,0,,,,0,,,,,,301.9986572,,,,
,31861853.415,298.4805298,99.6243667602539,1.00896009761652E-5,4.18442894646393E-7,1,0.999253354069792,40.0298881530762,2.00765256048425,19.8599994182587,0.000115536028551818,1.49197071347198E-5,0.25,-4.35599360103541E-7,1.00901333611863E-5,-4.28780701349228E-7,298.4509888,298.5100708,99.6243667602539,99.6243667602539,57.0002597649099,20.530827889413,26.705515,0,0,0,40,4374,295.23345,99.6243667602539,,,,,,,,,,,,,0,,,,0.00245,,,,,,298.4805298,,,,
,31861994.495,294.9642334,99.6243667602539,1.09766340664206E-5,4.42784635081655E-7,1,0.999253354069792,40.0298881530762,1.98395354857069,19.8800005018711,0.000124236358752463,1.63746108908263E-5,0.25,-4.45163633005488E-7,1.0978576985042E-5,-4.37692077498056E-7,294.9642334,294.9642334,99.6243667602539,99.6243667602539,56.4507749158906,20.531745148704,27.085165,0,0,0,40,4374,291.68635,99.6243667602539,,,,,,,,,,,,,0,,,,0,,,,,,294.9642334,,,,
,31862135.195,291.4957123,99.6243667602539,1.10716744300693E-5,4.27930128338518E-7,1,0.999253354069792,40.0298881530762,1.98391685885039,19.8800005018711,0.000124721543682689,2.00028894186845E-5,0.25,-1.39111781862577E-7,1.10747960274635E-5,-1.31434395065598E-7,291.4700928,291.5213318,99.6243667602539,99.6243667602539,56.6391473890252,20.5309379995118,27.464817,0,0,0,40,4374,288.15685,99.6243667602539,,,,,,,,,,,,,0,,,,0.00245,,,,,,291.4957123,,,,
,31862275.985,287.99848935,99.6243667602539,1.1226831297986E-5,3.82357830278185E-7,1,0.999253354069792,40.0298881530762,1.98393670488853,19.8800005018711,0.000126252262966806,2.16370963370778E-5,0.25,-2.09888913566987E-8,1.12313183760712E-5,-1.30563810530289E-8,287.9719238,288.0250549,99.6243667602539,99.6243667602539,56.6188250475252,20.5339603225493,27.085165,0,0,0,40,4374,284.6157,99.6243667602539,,,,,,,,,,,,,0,,,,-0.0049,,,,,,287.99848935,,,,
,31862396.3,284.98280335,99.6243667602539,1.07050405741677E-5,4.92245814077856E-7,1,0.999253354069792,40.0298881530762,2.00783938595725,19.9100002646446,0.000122191072428562,1.85081729176536E-5,0.25,-2.27871136967464E-7,1.07106242161122E-5,-2.20316904501661E-7,284.9582825,285.0073242,99.6243667602539,99.6243667602539,56.6227331901214,20.5264884534484,27.085165,0,0,0,40,4374,281.5999,99.6243667602539,,,,,,,,,,,,,0,,,,-0.00245,,,,,,284.98280335,,,,
,31862537.54,281.4828186,99.6243667602539,1.11375436212172E-5,4.4585149411111E-7,1,0.999253354069792,40.0298881530762,2.00781643442123,19.9100002646446,0.000127203709327964,1.89043229180126E-5,0.25,-2.68307712181466E-7,1.11447741010617E-5,-2.60375266013811E-7,281.4828186,281.4828186,99.6243667602539,99.6243667602539,56.5766171074867,20.5339932538254,26.705515,0,0,0,40,4374,278.0634,99.6243667602539,,,,,,,,,,,,,0,,,,0.00245,,,,,,281.4828186,,,,
,31862679.095,277.9602356,99.6243667602539,1.08839674108787E-5,4.22604750252911E-7,1,0.999253354069792,40.0298881530762,2.00780445476204,19.9100002646446,0.00012436767373641,1.82159332220073E-5,0.25,-2.85196761671947E-7,1.08924259794097E-5,-2.7737219815894E-7,277.9602356,277.9602356,99.6243667602539,99.6243667602539,56.9252234270637,20.536882119916,27.464817,0,0,0,40,4374,274.52265,99.6243667602539,,,,,,,,,,,,,0,,,,0.00245,,,,,,277.9602356,,,,
touchdown = 15.2700003236532 mm,31862809.585,274.7087555,99.6243667602539,1.07720709516326E-5,3.82113407085885E-7,1,0.999253354069792,40.0298881530762,2.00740005626803,19.9299994856119,0.000124194250848294,1.15981309974369E-5,0.25,-8.47623617853706E-7,1.07821227650765E-5,-8.40290893827993E-7,274.6834412,274.7340698,99.6243667602539,99.6243667602539,56.5609845371021,20.5327621216828,27.085165,0,0,0,40,4374,271.2544,99.6243667602539,,,,,,,,,,,,,0,,,,-0.00245,,,,,,274.7087555,,,,
,31862939.29,271.4897156,99.6243667602539,1.10493588721412E-5,3.7393572567869E-7,1,0.999253354069792,40.0298881530762,2.00725278613135,19.9299994856119,0.000126419359580351,1.75367783280466E-5,0.25,-3.73762626002613E-7,1.10605738246975E-5,-3.65729701112547E-7,271.4897156,271.4897156,99.6243667602539,99.6243667602539,56.5938129349098,20.5344801103075,27.464817,0,0,0,40,4374,268.0028,99.6243667602539,,,,,,,,,,,,,0,,,,-0.0049,,,,,,271.4897156,,,,
,31863080.365,267.9606323,99.6243667602539,1.15803755969659E-5,4.36685247103087E-7,1,0.999253354069792,40.0298881530762,2.00731638923839,19.9299994856119,0.000132407146156139,1.90082513325592E-5,0.25,-3.36856823879779E-7,1.15935516951705E-5,-3.28284332166299E-7,267.9606323,267.9606323,99.6243667602539,99.6243667602539,56.9119357422368,20.5360383483421,27.464817,0,0,0,40,4374,264.4733,99.6243667602539,,,,,,,,,,,,,0,,,,0.0049,,,,,,267.9606323,,,,
touchdown = 15.3000000864267 mm,31863225.595,264.3298035,99.6243667602539,1.17177138387918E-5,3.87459498148164E-7,1,0.999253354069792,40.0298881530762,1.99500429442095,19.9599992483854,0.000133018386161782,2.0231765109806E-5,0.25,-2.43030638693196E-7,1.17324910569982E-5,-2.34127028195526E-7,264.3298035,264.3298035,99.6243667602539,99.6243667602539,56.6571248449675,20.5367118839327,27.085165,0,0,0,40,4374,260.8445,99.6243667602539,,,,,,,,,,,,,0,,,,0.0049,,,,,,264.3298035,,,,
,31863360.345,260.9864197,99.6243667602539,1.16690090423188E-5,4.00088896646575E-7,1,0.999253354069792,40.0298881530762,1.99464405786767,19.9599992483854,0.000132302986074016,2.10431046597424E-5,0.25,-1.62901041525156E-7,1.16850533322447E-5,-1.53811069494345E-7,260.9864197,260.9864197,99.6243667602539,99.6243667602539,56.5656743082175,20.5399246508651,27.464817,0,0,0,40,4374,257.48135,99.6243667602539,,,,,,,,,,,,,0,,,,-0.00245,,,,,,260.9864197,,,,
,31863500.9,257.4752502,99.6243667602539,1.18857667775536E-5,4.55620481580535E-7,1,0.999253354069792,40.0298881530762,1.99441439910673,19.9599992483854,0.000134528594447253,2.27836000057603E-5,0.25,-4.67906865075155E-8,1.19034968718094E-5,-3.7217203673965E-8,257.4752502,257.4752502,99.6243667602539,99.6243667602539,56.6368025034675,20.5409100290778,26.705515,0,0,0,40,4374,253.9692,99.6243667602539,,,,,,,,,,,,,0,,,,0,,,,,,257.4752502,,,,
touchdown = 15.3299998492002 mm,31863642.32,253.9641266,99.6243667602539,1.14759049763252E-5,3.39605740256562E-7,1,0.999253354069792,40.0298881530762,1.99439275488781,19.9900008738041,0.000130218340899491,2.01901015426642E-5,0.25,-2.05372708468482E-7,1.14945836146638E-5,-1.96234174853004E-7,253.9641266,253.9641266,99.6243667602539,99.6243667602539,56.5805252500829,20.5378643555797,27.085165,0,0,0,40,4374,250.41525,99.6243667602539,,,,,,,,,,,,,0,,,,-0.00245,,,,,,253.9641266,,,,
,31863780.215,250.49493405,99.6243667602539,1.22947145159227E-5,4.18474343466652E-7,1,0.999253354069792,40.0298881530762,1.99458489599908,19.9900008738041,0.000139134987615213,2.39670151312542E-5,0.25,-1.41121765358295E-8,1.23160627202642E-5,-3.82096129933682E-9,250.4689178,250.5209503,99.6243667602539,99.6243667602539,56.9697762526599,20.5389121734912,27.464817,0,0,0,40,4374,246.97555,99.6243667602539,,,,,,,,,,,,,0,,,,0,,,,,,250.49493405,,,,
,31863921.87,246.9630585,99.6243667602539,1.25037570035549E-5,3.94747478795245E-7,1,0.999253354069792,40.0298881530762,1.99434919348423,19.9900008738041,0.000142086729182388,2.1005141860525E-5,0.25,-3.12351874056452E-7,1.25272771574388E-5,-3.02257403467137E-7,246.9630585,246.9630585,99.6243667602539,99.6243667602539,56.9017745714868,20.5356561364666,27.085165,0,0,0,40,4374,243.429,99.6243667602539,,,,,,,,,,,,,0,,,,-0.00245,,,,,,246.9630585,,,,
touchdown = 15.3599996119738 mm,31864058.89,243.5321198,99.6243667602539,1.24756030830204E-5,3.97988397531563E-7,1,0.999253354069792,40.0298881530762,1.99441621154498,20.0100000947714,0.00014138387878194,2.32931494897172E-5,0.25,-1.05744507835862E-7,1.2500397044605E-5,-9.5119277196019E-8,243.5321198,243.5321198,99.6243667602539,99.6243667602539,56.7821854080445,20.5376228715281,27.464817,0,0,0,40,4374,240.0058,99.6243667602539,,,,,,,,,,,,,0,,,,0,,,,,,243.5321198,,,,
,31864181.03,240.476593,99.6243667602539,1.25759649802457E-5,3.88470915530327E-7,1,0.999253354069792,40.0298881530762,1.99438080978968,20.0100000947714,0.000141849885942813,2.74263179507212E-5,0.25,2.41704498973852E-7,1.26019949550046E-5,2.53300686091412E-7,240.476593,240.476593,99.6243667602539,99.6243667602539,56.770460980256,20.5407943343306,27.464817,0,0,0,40,4374,236.9509,99.6243667602539,,,,,,,,,,,,,0,,,,-0.0049,,,,,,240.476593,,,,
,31864320.955,236.9739685,99.6243667602539,1.27801791021274E-5,3.27904009708693E-7,1,0.999253354069792,40.0298881530762,1.99439117954495,20.0100000947714,0.000145204277064002,2.19226174087329E-5,0.25,-2.80486231872484E-7,1.28086572867597E-5,-2.69628726038626E-7,236.9739685,236.9739685,99.6243667602539,99.6243667602539,56.7305979257752,20.5383878261148,27.085165,0,0,0,40,4374,233.43965,99.6243667602539,,,,,,,,,,,,,0,,,,-0.00245,,,,,,236.9739685,,,,
,31864459.94,233.5330963,99.6243667602539,,,2,,,,20.0699999165535,,,,,,,233.5330963,233.5330963,99.6243667602539,99.6243667602539,,,27.085165,,,,-99999999,4374,229.9706,99.6243667602539,,,,,,,,,,,,,,,,,,,,,,,233.5330963,,,,
,31864581.55,230.46105195,99.6243667602539,1.23321577478914E-5,3.64196348813725E-7,1,0.999253354069792,40.0298881530762,1.99462215024936,20.0599990785122,0.000140104465583549,2.14872085258917E-5,0.25,-2.42242786166347E-7,1.23623932540771E-5,-2.31371714643983E-7,230.4357605,230.4863434,99.6243667602539,99.6243667602539,57.0909286731407,20.5387818378142,27.085165,0,0,0,40,4374,226.93035,99.6243667602539,,,,,,,,,,,,,0,,,,0,,,,,,230.46105195,,,,
,31864722.245,226.956955,99.6243667602539,1.25474721136605E-5,3.74858778135856E-7,1,0.999253354069792,40.0298881530762,1.99466756718575,20.0599990785122,0.000142578255939969,2.18227912543773E-5,0.25,-2.50462711530702E-7,1.25797496463133E-5,-2.39217918486334E-7,226.956955,226.956955,99.6243667602539,99.6243667602539,56.7923465787945,20.5431418630261,27.085165,0,0,0,40,4374,223.4112,99.6243667602539,,,,,,,,,,,,,0,,,,0,,,,,,226.956955,,,,
,31864876.39,223.1057587,99.6243667602539,,,2,,,,20.1100002211332,,,,,,,223.1057587,223.1057587,99.6243667602539,99.6243667602539,,,27.085165,,,,-99999999,4374,219.5674,99.6243667602539,,,,,,,,,,,,,,,,,,,,,,,223.1057587,,,,
,31865001.055,219.9736328,99.6243667602539,1.29697090419912E-5,4.03809844977096E-7,1,0.999253354069792,40.0298881530762,1.98330261565735,20.0999993830919,0.000146348781198916,2.39386481152538E-5,0.25,-1.26309840000769E-7,1.30060249772782E-5,-1.13893340131464E-7,219.9736328,219.9736328,99.6243667602539,99.6243667602539,56.9502355396791,20.5515848280401,27.085165,0,0,0,40,4374,216.4483,99.6243667602539,,,,,,,,,,,,,0,,,,-0.0049,,,,,,219.9736328,,,,
,31865140.06,216.4906464,99.6243667602539,1.26692791592505E-5,4.06555076190754E-7,1,0.999253354069792,40.0298881530762,1.98344833982435,20.0999993830919,0.0001429893256309,2.3366470695732E-5,0.25,-1.25588165483645E-7,1.27062400712034E-5,-1.13229689361414E-7,216.4906464,216.4906464,99.6243667602539,99.6243667602539,56.6266413327175,20.5499036641141,27.085165,0,0,0,40,4374,212.9778,99.6243667602539,,,,,,,,,,,,,0,,,,0.0049,,,,,,216.4906464,,,,
,31865293.36,212.6685791,99.6243667602539,,,2,,,,20.1399999839067,,,,,,,212.6685791,212.6685791,99.6243667602539,99.6243667602539,,,26.705515,,,,-99999999,4374,209.147,99.6243667602539,,,,,,,,,,,,,,,,,,,,,,,212.6685791,,,,
,31865420.41,209.4757309,99.6243667602539,1.30377402019269E-5,3.00011092143114E-7,1,0.999253354069792,40.0298881530762,2.00714665722857,20.1299991458654,0.00014942663152826,2.1064025006179E-5,0.25,-4.15967017247596E-7,1.30791159950672E-5,-4.03625826280742E-7,209.4496918,209.50177,99.6243667602539,99.6243667602539,56.8650380310829,20.5367141365717,26.705515,0,0,0,40,4374,205.97705,99.6243667602539,,,,,,,,,,,,,0,,,,0.00245,,,,,,209.4757309,,,,
,31865561.08,205.9303284,99.6243667602539,1.29204102780462E-5,3.32918488373127E-7,1,0.999253354069792,40.0298881530762,2.00706006499634,20.1299991458654,0.000147389277917635,2.49283384122924E-5,0.25,-5.70115234796084E-8,1.2962543426552E-5,-4.33782126686064E-8,205.9303284,205.9303284,99.6243667602539,99.6243667602539,56.9056827140829,20.5396025750602,26.705515,0,0,0,40,4374,202.4599,99.6243667602539,,,,,,,,,,,,,0,,,,0,,,,,,205.9303284,,,,
,31865709.41,202.2232666,99.6243667602539,,,2,,,,20.1899998989701,,,,,,,202.2232666,202.2232666,99.6243667602539,99.6243667602539,,,27.085165,,,,-99999999,4374,198.7637,99.6243667602539,,,,,,,,,,,,,,,,,,,,,,,202.2232666,,,,
,31865839.875,198.946579,99.6243667602539,1.32651439907229E-5,3.43229022062086E-7,1,0.999253354069792,40.0298881530762,1.98323577794498,20.1799999922514,0.000150196964716904,2.21056442439898E-5,0.25,-3.43363253428811E-7,1.33117121322195E-5,-3.29729837736956E-7,198.946579,198.946579,99.6243667602539,99.6243667602539,57.1776894387753,20.5551261851138,26.325863,0,0,0,40,4374,195.4972,99.6243667602539,,,,,,,,,,,,,0,,,,-0.0049,,,,,,198.946579,,,,
,31865979.125,195.49578095,99.6243667602539,1.35225051157705E-5,3.46052763251524E-7,1,0.999253354069792,40.0298881530762,1.98307830406735,20.1799999922514,0.000153103695426062,2.26071915543959E-5,0.25,-3.43995377651883E-7,1.35714603332668E-5,-3.29762356118593E-7,195.4675903,195.5239716,99.6243667602539,99.6243667602539,57.0291800201214,20.5564515618241,27.085165,0,0,0,40,4374,192.00785,99.6243667602539,,,,,,,,,,,,,0,,,,0.00245,,,,,,195.49578095,,,,
,31866123.69,191.8817291,99.6243667602539,,,2,,,,20.2300002035499,,,,,,,191.8817291,191.8817291,99.6243667602539,99.6243667602539,,,26.705515,,,,-99999999,4374,188.3893,99.6243667602539,,,,,,,,,,,,,,,,,,,,,,,191.8817291,,,,
,31866239.66,188.9606018,99.6243667602539,1.29529310605296E-5,3.55786434440963E-7,1,0.999253354069792,40.0298881530762,1.98311163631033,20.2200002968311,0.000146773627548169,2.11629325336412E-5,0.25,-3.74242319159121E-7,1.3002538491896E-5,-3.60169169121367E-7,188.9606018,188.9606018,99.6243667602539,99.6243667602539,56.8259566051214,20.5563515835837,26.705515,0,0,0,40,4374,185.4903,99.6243667602539,,,,,,,,,,,,,0,,,,-0.00245,,,,,,188.9606018,,,,
,31866383.4,185.4708328,99.6243667602539,1.30908759151873E-5,3.80848341093134E-7,1,0.999253354069792,40.0298881530762,1.98262259119312,20.2200002968311,0.0001480751217169,2.27808609952777E-5,0.25,-2.54871907675677E-7,1.3142268458697E-5,-2.39789533794813E-7,185.4413452,185.5003204,99.6243667602539,99.6243667602539,56.8978664288906,20.5609212376377,26.325863,0,0,0,40,4374,181.79475,99.6243667602539,,,,,,,,,,,,,0,,,,-0.00245,,,,,,185.4708328,,,,
,31866520.54,181.9615479,99.6243667602539,1.31854032887209E-5,3.87543015638537E-7,1,0.999253354069792,40.0298881530762,1.98275898496052,20.2200002968311,0.000149828084479208,1.91645512854739E-5,0.25,-5.92789001277545E-7,1.32389989924136E-5,-5.78567921137779E-7,181.9615479,181.9615479,99.6243667602539,99.6243667602539,56.750138638756,20.564827334808,26.325863,0,0,0,40,4374,178.4411,99.6243667602539,,,,,,,,,,,,,0,,,,-0.00245,,,,,,181.9615479,,,,
,31866639.825,178.959549,99.6243667602539,1.27350996761222E-5,3.72282310350934E-7,1,0.999253354069792,40.0298881530762,1.99409000618128,20.2799998223782,0.000144942782820774,2.18976241370861E-5,0.25,-2.83167122100855E-7,1.27876488529551E-5,-2.67936356243863E-7,178.959549,178.959549,99.6243667602539,99.6243667602539,56.5828701356406,20.5558483819943,26.325863,0,0,0,40,4374,175.493,99.6243667602539,,,,,,,,,,,,,0,,,,-0.00245,,,,,,178.959549,,,,
,31866778.03,175.4716034,99.6243667602539,1.2980113590861E-5,3.32722397077709E-7,1,0.999253354069792,40.0298881530762,1.99402983053703,20.2799998223782,0.000147882281880961,2.1515847308161E-5,0.25,-3.60036191436964E-7,1.3035108215119E-5,-3.44391450670189E-7,175.4716034,175.4716034,99.6243667602539,99.6243667602539,56.5695824508137,20.5578905775583,25.946213,0,0,0,40,4374,172.0664,99.6243667602539,,,,,,,,,,,,,0,,,,0,,,,,,175.4716034,,,,
,31866916.605,171.967514,99.6243667602539,1.32950455186792E-5,3.51605091292379E-7,1,0.999253354069792,40.0298881530762,1.99384360056277,20.2799998223782,0.000151876043974982,1.97168798014453E-5,0.25,-5.73989253090402E-7,1.3353011716229E-5,-5.58391831400147E-7,171.967514,171.967514,99.6243667602539,99.6243667602539,56.435142345506,20.5644673812973,26.325863,0,0,0,40,4374,168.6116,99.6243667602539,,,,,,,,,,,,,0,,,,0.0049,,,,,,171.967514,,,,
,31867037.305,168.95065305,99.6243667602539,1.30560095362359E-5,3.63827598092751E-7,1,0.999253354069792,40.0298881530762,1.98285601641878,20.3399993479252,0.000147852342885559,2.22559216435852E-5,0.25,-2.98696753753706E-7,1.31136998603917E-5,-2.81819309985321E-7,168.9268646,168.9744415,99.6243667602539,99.6243667602539,56.5985027060252,20.5680836517309,26.705515,0,0,0,40,4374,165.60155,99.6243667602539,,,,,,,,,,,,,0,,,,0.0049,,,,,,168.95065305,,,,
,31867177.125,165.4762115,99.6243667602539,1.28841454665497E-5,3.64516264514753E-7,1,0.999253354069792,40.0298881530762,1.98259119524005,20.3399993479252,0.000146215251417964,2.01603587313241E-5,0.25,-4.55059582687649E-7,1.29425627337994E-5,-4.38610376720806E-7,165.4762115,165.4762115,99.6243667602539,99.6243667602539,56.770460980256,20.5674082594856,25.946213,0,0,0,40,4374,162.11225,99.6243667602539,,,,,,,,,,,,,0,,,,-0.0049,,,,,,165.4762115,,,,
,31867315.1,161.99344635,99.6243667602539,1.33087182288882E-5,3.97210269693335E-7,1,0.999253354069792,40.0298881530762,1.98243338851009,20.3399993479252,0.00015046595375667,2.41024377949413E-5,0.25,-1.80076374566898E-7,1.33699141703625E-5,-1.61215584765083E-7,161.9670563,162.0198364,99.6243667602539,99.6243667602539,56.9338213407753,20.5718759471356,25.566563,0,0,0,40,4374,158.6763,99.6243667602539,,,,,,,,,,,,,0,,,,-0.00245,,,,,,161.99344635,,,,
,31867454.6,158.4957123,99.6243667602539,1.29708561541087E-5,3.2433556308479E-7,1,0.999253354069792,40.0298881530762,1.98240270887918,20.3799996525049,0.000146339417234919,2.5319765910176E-5,0.25,-1.41187426228149E-8,1.30314650065831E-5,5.61910418467047E-9,158.4957123,158.4957123,99.6243667602539,99.6243667602539,56.6837002146214,20.5679049398963,25.946213,0,0,0,40,4374,155.195,99.6243667602539,,,,,,,,,,,,,0,,,,-0.00245,,,,,,158.4957123,,,,
,31867594.2,154.9741821,99.6243667602539,1.3153773655281E-5,2.80568729604087E-7,1,0.999253354069792,40.0298881530762,1.98240686718245,20.3799996525049,0.000148460910838348,2.54265342672357E-5,0.25,-3.73826286782915E-8,1.32164724626694E-5,-1.68064473920956E-8,154.9741821,154.9741821,99.6243667602539,99.6243667602539,56.7274714116983,20.5734811092642,25.946213,0,0,0,40,4374,151.7132,99.6243667602539,,,,,,,,,,,,,0,,,,0,,,,,,154.9741821,,,,
,31867734.635,151.4710541,99.6243667602539,1.32829847833492E-5,3.31900083207515E-7,1,0.999253354069792,40.0298881530762,1.9824114695711,20.3799996525049,0.000149787233593615,2.6513633652541E-5,0.25,3.55406050290899E-8,1.33473487403028E-5,5.74004699015586E-8,151.4710541,151.4710541,99.6243667602539,99.6243667602539,56.7892200647175,20.5686581639219,25.946213,0,0,0,40,4374,148.2187,99.6243667602539,,,,,,,,,,,,,0,,,,-0.0049,,,,,,151.4710541,,,,
,31867873.61,147.9638519,99.6243667602539,1.34663638858299E-5,3.64863030378457E-7,1,0.999253354069792,40.0298881530762,1.99394711908694,20.4499997198582,0.000152993515586381,2.54152801341997E-5,0.25,-1.07188955789668E-7,1.35330039630964E-5,-8.49442308330179E-8,147.9638519,147.9638519,99.6243667602539,99.6243667602539,56.7563916669098,20.5655209626062,25.946213,0,0,0,40,4374,144.758,99.6243667602539,,,,,,,,,,,,,0,,,,0,,,,,,147.9638519,,,,
,31868011.84,144.4982452,99.6243667602539,1.33935438094702E-5,3.19504045207693E-7,1,0.999253354069792,40.0298881530762,1.99375283707231,20.4499997198582,0.00015215983261163,2.53037824418193E-5,0.25,-1.0512672104189E-7,1.34609133733347E-5,-8.21678232857229E-8,144.4982452,144.4982452,99.6243667602539,99.6243667602539,56.5883415352752,20.566360692248,25.566563,0,0,0,40,4374,141.3232,99.6243667602539,,,,,,,,,,,,,0,,,,-0.00245,,,,,,144.4982452,,,,
,31868152.175,140.95067595,99.6243667602539,1.30285256331927E-5,3.55481510296906E-7,1,0.999253354069792,40.0298881530762,1.99375399447598,20.4499997198582,0.00014816414491627,2.38178342142927E-5,0.25,-1.73509170238865E-7,1.30952334709145E-5,-1.50654949359973E-7,140.9269104,140.9744415,99.6243667602539,99.6243667602539,56.7532651528329,20.5683021287267,25.566563,0,0,0,40,4374,137.82805,99.6243667602539,,,,,,,,,,,,,0,,,,0.00245,,,,,,140.95067595,,,,
,31868290.85,137.4803925,99.6243667602539,1.3475909537517E-5,3.52960116792096E-7,1,0.999253354069792,40.0298881530762,1.98256680033205,20.5099992454052,0.00015238472160033,2.48337119943922E-5,0.25,-1.51368487401503E-7,1.35458644483983E-5,-1.26608808578679E-7,137.4803925,137.4803925,99.6243667602539,99.6243667602539,57.0401228193907,20.5717756894015,25.566563,0,0,0,40,4374,134.3653,99.6243667602539,,,,,,,,,,,,,0,,,,0,,,,,,137.4803925,,,,
,31868429.99,133.9852295,99.6243667602539,1.36441070039665E-5,2.95416553541306E-7,1,0.999253354069792,40.0298881530762,1.98247265188595,20.5099992454052,0.000154643038712641,2.31261999772955E-5,0.25,-3.33149813909926E-7,1.37162647877349E-5,-3.07952432828364E-7,133.9578552,134.0126038,99.6243667602539,99.6243667602539,56.831428004756,20.570496954437,25.186911,0,0,0,40,4374,130.90985,99.6243667602539,,,,,,,,,,,,,0,,,,0,,,,,,133.9852295,,,,
,31868568.67,130.4911652,99.6243667602539,1.31838665223264E-5,3.43561247277155E-7,1,0.999253354069792,40.0298881530762,1.98258229775755,20.5099992454052,0.000149034516434092,2.46967877069265E-5,0.25,-1.15016884362791E-7,1.32540607152862E-5,-8.84578698373283E-8,130.4911652,130.4911652,99.6243667602539,99.6243667602539,56.9517987967176,20.5728219175938,25.186911,0,0,0,40,4374,127.45555,99.6243667602539,,,,,,,,,,,,,0,,,,0,,,,,,130.4911652,,,,
,31868688.98,127.4492111,99.6243667602539,1.32574348957869E-5,2.95921112105069E-7,1,0.999253354069792,40.0298881530762,1.99394608173417,20.5799993127584,0.000150762190104657,2.45846157510318E-5,0.25,-1.50841533043379E-7,1.33288129754052E-5,-1.23260339293969E-7,127.4492111,127.4492111,99.6243667602539,99.6243667602539,57.0440309619868,20.564632127537,24.807261,0,0,0,40,4374,124.466,99.6243667602539,,,,,,,,,,,,,0,,,,0,,,,,,127.4492111,,,,
,31868828.625,123.9250412,99.6243667602539,1.34031468504814E-5,3.39175936118041E-7,1,0.999253354069792,40.0298881530762,1.99384038204866,20.5799993127584,0.000152533736965524,2.42060174263048E-5,0.25,-2.11034433936028E-7,1.34762112282781E-5,-1.82114491885127E-7,123.9250412,123.9250412,99.6243667602539,99.6243667602539,56.8892685151791,20.5653033577444,24.807261,0,0,0,40,4374,120.9938,99.6243667602539,,,,,,,,,,,,,0,,,,-0.00245,,,,,,123.9250412,,,,
,31868965.64,120.4934387,99.6243667602539,1.32930728125726E-5,3.34113249860805E-7,1,0.999253354069792,40.0298881530762,1.99385660772659,20.5799993127584,0.000150831453712552,2.66277254299007E-5,0.25,2.00248699088665E-8,1.3365660813815E-5,5.14002094646299E-8,120.4934387,120.4934387,99.6243667602539,99.6243667602539,56.4922012274098,20.5651320818118,25.186911,0,0,0,40,4374,117.5819,99.6243667602539,,,,,,,,,,,,,0,,,,0.00245,,,,,,120.4934387,,,,
,31869104.89,116.9856796,99.6243667602539,1.29335260598951E-5,3.50943072311725E-7,1,0.999253354069792,40.0298881530762,1.99387666980325,20.6400007009506,0.000146987971164258,2.46034810934139E-5,0.25,-9.70816382428575E-8,1.30049814890899E-5,-6.56316144962133E-8,116.9856796,116.9856796,99.6243667602539,99.6243667602539,56.963523224506,20.5616851597742,24.427608,0,0,0,40,4374,114.1282,99.6243667602539,,,,,,,,,,,,,0,,,,0.00245,,,,,,116.9856796,,,,
,31869245.315,113.4544678,99.6243667602539,1.30736451406986E-5,4.03519065690971E-7,1,0.999253354069792,40.0298881530762,1.99388361407287,20.6400007009506,0.000148963747005833,2.27157695769179E-5,0.25,-2.89760465847396E-7,1.3146825414344E-5,-2.57280839072751E-7,113.4544678,113.4544678,99.6243667602539,99.6243667602539,56.8697278021983,20.5624902130329,24.807261,0,0,0,40,4374,110.6438,99.6243667602539,,,,,,,,,,,,,0,,,,0.00245,,,,,,113.4544678,,,,
,31869382.5,109.9727554,99.6243667602539,1.32022273324436E-5,3.45886242696951E-7,1,0.999253354069792,40.0298881530762,1.99387365025521,20.6400007009506,0.000149912945006287,2.59000198163494E-5,0.25,-3.36821958430846E-8,1.32757674260039E-5,2.45346280778762E-9,109.9727554,109.9727554,99.6243667602539,99.6243667602539,56.8728543162753,20.5636970587598,24.047956,0,0,0,40,4374,107.2438,99.6243667602539,,,,,,,,,,,,,0,,,,-0.0049,,,,,,109.9727554,,,,
,31869521.97,106.4574661,99.6243667602539,1.32566506607859E-5,3.49252124000499E-7,1,0.999253354069792,40.0298881530762,1.99378089450331,20.7100007683039,0.000150342885549532,2.70492245797328E-5,0.25,5.59657915091047E-8,1.33303856877746E-5,9.49003180304117E-8,106.4574661,106.4574661,99.6243667602539,99.6243667602539,56.9346029692945,20.5636432860369,24.427608,0,0,0,40,4374,103.77765,99.6243667602539,,,,,,,,,,,,,0,,,,0,,,,,,106.4574661,,,,
,31869660.815,102.9585724,99.6243667602539,1.31725594283032E-5,3.26898513762668E-7,1,0.999253354069792,40.0298881530762,1.99373152713322,20.7100007683039,0.000150002154406125,2.33665728413714E-5,0.25,-2.56034184682015E-7,1.32467429813032E-5,-2.16742855057271E-7,102.9585724,102.9585724,99.6243667602539,99.6243667602539,56.9760292808137,20.5667276839319,24.427608,0,0,0,40,4374,100.34595,99.6243667602539,,,,,,,,,,,,,0,,,,0,,,,,,102.9585724,,,,
,31869798.625,99.4906006,99.6243667602539,1.34647664833413E-5,3.27036859742495E-7,1,0.999253354069792,40.0298881530762,1.99377200631967,20.7100007683039,0.000153602074690532,2.23398258994748E-5,0.25,-4.00503243344492E-7,1.35408297863727E-5,-3.58462159008856E-7,99.4906006,99.4906006,99.6243667602539,99.6243667602539,57.6341604940061,20.5672242505015,23.668306,0,0,0,40,4374,96.9202,99.6243667602539,,,,,,,,,,,,,0,,,,0,,,,,,99.4906006,,,,
,31869937.06,95.9887772,99.6243667602539,1.30937848645578E-5,3.05659736173401E-7,1,0.999253354069792,40.0298881530762,1.98261073184706,20.7800008356571,0.000148440021663263,2.2325463327212E-5,0.25,-3.28692042038322E-7,1.3167097556043E-5,-2.84608761047374E-7,95.9887772,95.9887772,99.6243667602539,99.6243667602539,56.9455457685637,20.5696875071081,23.668306,0,0,0,40,4374,93.4958,99.6243667602539,,,,,,,,,,,,,0,,,,0,,,,,,95.9887772,,,,
,31870076.48,92.4620132,99.6243667602539,1.31668652790725E-5,3.02426142912284E-7,1,0.999253354069792,40.0298881530762,1.98250320303492,20.7800008356571,0.00014910338443624,2.32899352825155E-5,0.25,-2.59077786002445E-7,1.32395279793585E-5,-2.11130289048131E-7,92.4620132,92.4620132,99.6243667602539,99.6243667602539,56.966649738583,20.5722612848356,23.668306,0,0,0,40,4374,90.04555,99.6243667602539,,,,,,,,,,,,,0,,,,-0.00245,,,,,,92.4620132,,,,
,31870214.22,88.9864883,99.6243667602539,1.32420533781992E-5,3.80081337633022E-7,1,0.999253354069792,40.0298881530762,1.98225392358678,20.7800008356571,0.000149441519314702,2.61447015081239E-5,0.25,-2.2398112046905E-8,1.33129612192407E-5,3.06610484898157E-8,88.9864883,88.9864883,99.6243667602539,99.6243667602539,56.9658681100637,20.5743620190753,23.288654,0,0,0,40,4374,86.6362,99.6243667602539,,,,,,,,,,,,,0,,,,0,,,,,,88.9864883,,,,
,31870351.17,85.48862455,99.6243667602539,1.33414029167015E-5,2.94314628279546E-7,1,0.999253354069792,40.0298881530762,1.99372034304268,20.8500009030104,0.000151422906444895,2.62097718426872E-5,0.25,-5.05435389824823E-8,1.34111941245195E-5,6.6820189752743E-9,85.4588394,85.5184097,99.6243667602539,99.6243667602539,56.8017261210252,20.5685332917704,23.668306,0,0,0,40,4374,83.2581,99.6243667602539,,,,,,,,,,,,,0,,,,0,,,,,,85.48862455,,,,
,31870488.36,81.9956284,99.6243667602539,1.32719437159812E-5,3.14333302560622E-7,1,0.999253354069792,40.0298881530762,1.99381528519941,20.8500009030104,0.000150673611783668,2.57374384349815E-5,0.25,-8.38834100806786E-8,1.3339139118946E-5,-2.2816509212934E-8,81.9956284,81.9956284,99.6243667602539,99.6243667602539,56.8197035769676,20.5659068987072,23.668306,0,0,0,40,4374,79.87105,99.6243667602539,,,,,,,,,,,,,0,,,,0.00245,,,,,,81.9956284,,,,
,31870627.485,78.4498138,99.6243667602539,1.32727902576015E-5,3.0443187589753E-7,1,0.999253354069792,40.0298881530762,1.99395588959589,20.8500009030104,0.000150196188004328,2.83317156448745E-5,0.25,1.4044005212179E-7,1.33356862978742E-5,2.07349709801373E-7,78.4498138,78.4498138,99.6243667602539,99.6243667602539,57.2753930036791,20.5630135785724,23.288654,0,0,0,40,4374,76.4555,99.6243667602539,,,,,,,,,,,,,0,,,,-0.0049,,,,,,78.4498138,,,,
,31870746.32,75.4593964,99.6243667602539,1.33481977200356E-5,2.78723020598193E-7,1,0.999253354069792,40.0298881530762,1.99410774979248,20.9199991077185,0.000151774299700455,2.4249429144755E-5,0.25,-2.37046988689997E-7,1.34098318790821E-5,-1.67089484068894E-7,75.4593964,75.4593964,99.6243667602539,99.6243667602539,56.6375841319868,20.5618212089004,23.288654,0,0,0,40,4374,73.5145,99.6243667602539,,,,,,,,,,,,,0,,,,0,,,,,,75.4593964,,,,
,31870881.36,71.9981155,99.6243667602539,1.33636282379015E-5,3.66404251155701E-7,1,0.999253354069792,40.0298881530762,1.99401948914589,20.9199991077185,0.000152636695061866,2.00676886272665E-5,0.25,-6.13290898220979E-7,1.34224988785107E-5,-5.39467477141641E-7,71.9981155,71.9981155,99.6243667602539,99.6243667602539,56.8540952318137,20.560239090951,22.909004,0,0,0,40,4374,70.20435,99.6243667602539,,,,,,,,,,,,,0,,,,0.0049,,,,,,71.9981155,,,,
,31871019.345,68.4724121,99.6243667602539,1.32855707865626E-5,3.2784925043866E-7,1,0.999253354069792,40.0298881530762,1.99402981310396,20.9199991077185,0.000151236787119829,2.23892067645862E-5,0.25,-3.9904726442559E-7,1.33365093270082E-5,-3.19072840819506E-7,68.4724121,68.4724121,99.6243667602539,99.6243667602539,57.1808159528522,20.5622002882963,22.909004,0,0,0,40,4374,66.8102,99.6243667602539,,,,,,,,,,,,,0,,,,-0.00245,,,,,,68.4724121,,,,
,31871136.745,65.4747238,99.6243667602539,1.3538067651109E-5,3.61288609137599E-7,1,0.999253354069792,40.0298881530762,1.99403500768766,20.9800004959106,0.000154279385387324,2.14386569701237E-5,0.25,-5.31973557781362E-7,1.35839914883395E-5,-4.45955624565399E-7,65.4747238,65.4747238,99.6243667602539,99.6243667602539,56.8134505488137,20.5585115703955,21.770052,0,0,0,40,4374,63.9289,99.6243667602539,,,,,,,,,,,,,0,,,,0,,,,,,65.4747238,,,,
,31871274.415,61.9778519,99.6243667602539,1.30686288907083E-5,3.11958268675593E-7,1,0.999253354069792,40.0298881530762,1.99397353119899,20.9800004959106,0.000147278738181095,2.92659228534043E-5,0.25,2.40799957158453E-7,1.30985698622723E-5,3.30972841607724E-7,61.9778519,61.9778519,99.6243667602539,99.6243667602539,56.9322580837368,20.5606978339601,21.770052,0,0,0,40,4374,60.5515,99.6243667602539,,,,,,,,,,,,,0,,,,0.00245,,,,,,61.9778519,,,,
,31871411.64,58.4844208,99.6243667602539,1.35280589707652E-5,3.54894514584416E-7,1,0.999253354069792,40.0298881530762,1.99383765056248,20.9800004959106,0.000153109398855502,2.5862528662753E-5,0.25,-1.44947188759209E-7,1.35503159478489E-5,-4.82077341976499E-8,58.4844208,58.4844208,99.6243667602539,99.6243667602539,56.9861904515637,20.5631338734587,21.3904,0,0,0,40,4374,57.1774,99.6243667602539,,,,,,,,,,,,,0,,,,0,,,,,,58.4844208,,,,
,31871530.86,55.4232101,99.6243667602539,1.3341437725433E-5,3.19463078967859E-7,1,0.999253354069792,40.0298881530762,1.99383064300463,21.0500005632639,0.000150900326844723,2.53291149968563E-5,0.25,-1.59301085206677E-7,1.33524774762623E-5,-6.12944492818442E-8,55.4232101,55.4232101,99.6243667602539,99.6243667602539,57.004167907506,20.5600317995087,21.3904,0,0,0,40,4374,54.2504,99.6243667602539,,,,,,,,,,,,,0,,,,0,,,,,,55.4232101,,,,
,31871665.885,51.99021145,99.6243667602539,1.34403488146741E-5,3.33003587674317E-7,1,0.999253354069792,40.0298881530762,1.99380963332878,21.0500005632639,0.000151576320901153,2.70917455848389E-5,0.25,-1.97657158804526E-8,1.34369028623727E-5,8.02504768282587E-8,51.9619331,52.0184898,99.6243667602539,99.6243667602539,57.0221453634483,20.5629383106417,21.01075,0,0,0,40,4374,50.9504,99.6243667602539,,,,,,,,,,,,,0,,,,-0.00245,,,,,,51.99021145,,,,
,31871803.125,48.4608803,99.6243667602539,1.35900185291917E-5,2.6447426410655E-7,1,0.999253354069792,40.0298881530762,1.99370649938107,21.0500005632639,0.000153928807095461,2.27392866099423E-5,0.25,-4.2974196708645E-7,1.35752819213268E-5,-3.28969193345185E-7,48.4608803,48.4608803,99.6243667602539,99.6243667602539,56.7493570102368,20.5648496823234,20.631098,0,0,0,40,4370,47.5958,99.6243667602539,,,,,,,,,,,,,0,,,,0,,,,,,48.4608803,,,,
,31871938.52,44.9959717,99.6243667602539,1.32445548760282E-5,3.3203706260389E-7,1,0.999253354069792,40.0298881530762,1.99346650392675,21.0999995470047,0.000148893522838125,2.74351951941886E-5,0.25,5.49673199035966E-8,1.3213462925159E-5,1.49624893817853E-7,44.9959717,44.9959717,99.6243667602539,99.6243667602539,57.2042648084291,20.5680981748493,19.112494,0,0,0,40,4370,44.2854,99.6243667602539,,,,,,,,,,,,,0,,,,0.0049,,,,,,44.9959717,,,,
,31872076.375,41.4871101,99.6243667602539,1.32458833377102E-5,3.7868713340929E-7,1,0.999253354069792,40.0298881530762,1.9934365266914,21.0999995470047,0.000148585179535446,2.84294080120511E-5,0.25,1.49995884921895E-7,1.32018893521707E-5,2.39716748052211E-7,41.4871101,41.4871101,99.6243667602539,99.6243667602539,56.7305979257752,20.5721214153348,18.732843,0,0,0,40,4370,40.8943,99.6243667602539,,,,,,,,,,,,,0,,,,0,,,,,,41.4871101,,,,
,31872214.69,37.9653969,99.6243667602539,1.33410836003938E-5,3.34581762592577E-7,1,0.999253354069792,40.0298881530762,1.99333936219871,21.0999995470047,0.000150882935342455,2.10498467128197E-5,0.25,-5.16433345828418E-7,1.32906011333438E-5,-4.29130240782219E-7,37.9653969,37.9653969,99.6243667602539,99.6243667602539,56.6242964471598,20.5706186917517,17.973541,0,0,0,40,4370,37.48345,99.6243667602539,,,,,,,,,,,,,0,,,,-0.0049,,,,,,37.9653969,,,,
,31872352.32,34.4981956,99.6243667602539,1.34761681452803E-5,3.21600817851966E-7,1,0.999253354069792,40.0298881530762,1.99318434661443,21.1500003933907,0.000151325188933172,2.67092258567446E-5,0.25,-2.92560956507216E-8,1.34136457309871E-5,5.10978972217746E-8,34.4981956,34.4981956,99.6243667602539,99.6243667602539,57.0979633298137,20.5723697083775,17.973541,0,0,0,40,4370,34.0864,99.6243667602539,,,,,,,,,,,,,0,,,,0,,,,,,34.4981956,,,,
,31872492.355,30.9497299,99.6243667602539,1.35314664643981E-5,2.96305710966313E-7,1,0.999253354069792,40.0298881530762,1.9935131944643,21.1500003933907,0.000152065010385441,2.58723513761276E-5,0.25,-1.07467738482875E-7,1.34627418899019E-5,-3.18686613213493E-8,30.9497299,30.9497299,99.6243667602539,99.6243667602539,57.2699216040445,20.5645646179172,17.593889,0,0,0,40,4370,30.6162,99.6243667602539,,,,,,,,,,,,,0,,,,0,,,,,,30.9497299,,,,
,31872629.61,27.47953985,99.6243667602539,1.31216199317065E-5,3.74983449159448E-7,1,0.999253354069792,40.0298881530762,1.99327430815473,21.1500003933907,0.000147612396029766,2.38532625037221E-5,0.25,-2.09106684983022E-7,1.30513078774444E-5,-1.3945163353809E-7,27.4516983,27.5073814,99.6243667602539,99.6243667602539,57.1604936113522,20.5720140376792,16.834587,0,0,0,40,4370,27.20985,99.6243667602539,,,,,,,,,,,,,0,,,,0,,,,,,27.47953985,,,,
,31872748.995,24.4640808,99.6243667602539,1.32384350840627E-5,3.18948716401052E-7,1,0.999253354069792,40.0298881530762,1.9820868409095,21.1900006979704,0.000147670367118727,2.63535808095809E-5,0.25,8.81591462732836E-9,1.31639799979352E-5,7.516130351219E-8,24.4640808,24.4640808,99.6243667602539,99.6243667602539,57.2378748347561,20.5727813428145,16.454937,0,0,0,40,4370,24.254,99.6243667602539,,,,,,,,,,,,,0,,,,0.0049,,,,,,24.4640808,,,,
,31872887.585,20.99602125,99.6243667602539,1.36289997193428E-5,3.10271179782072E-7,1,0.999253354069792,40.0298881530762,1.98204506500929,21.1900006979704,0.000151664222484299,2.90538615385775E-5,0.25,1.83780509335147E-7,1.35499455591251E-5,2.49082326749073E-7,20.9690094,21.0230331,99.6243667602539,99.6243667602539,57.0354330482753,20.5757320359892,16.075285,0,0,0,40,4370,20.80775,99.6243667602539,,,,,,,,,,,,,0,,,,0.00245,,,,,,20.99602125,,,,
,31873027.57,17.4751282,99.6243667602539,1.33416097176438E-5,3.53759240085359E-7,1,0.999253354069792,40.0298881530762,1.98226831057338,21.1900006979704,0.00014916730640972,2.45614098087135E-5,0.25,-1.67431601884976E-7,1.3265528896982E-5,-1.02159494407728E-7,17.4751282,17.4751282,99.6243667602539,99.6243667602539,57.0463758475445,20.5745482024396,14.556682,0,0,0,40,4370,17.32005,99.6243667602539,,,,,,,,,,,,,0,,,,0,,,,,,17.4751282,,,,
,31873147.165,14.4646492,99.6243667602539,1.33585936895034E-5,3.13633588177666E-7,1,0.999253354069792,40.0298881530762,1.99380101104939,21.2200004607439,0.000149978509261423,2.59130608905583E-5,0.25,-6.21812704492625E-8,1.3282060921025E-5,2.60199441688601E-9,14.4646492,14.4646492,99.6243667602539,99.6243667602539,56.9564885678329,20.5610975820752,14.177031,0,0,0,40,4370,14.3496,99.6243667602539,,,,,,,,,,,,,0,,,,-0.0049,,,,,,14.4646492,,,,
,31873286.48,10.990541,99.6243667602539,1.33843699783212E-5,3.02582895366391E-7,1,0.999253354069792,40.0298881530762,1.99354515647693,21.2200004607439,0.000150683668283913,2.35216999786702E-5,0.25,-2.79692728589866E-7,1.33088420521023E-5,-2.13535791619425E-7,10.9614687,11.0196133,99.6243667602539,99.6243667602539,56.5172133400252,20.5675298821908,13.038077,0,0,0,40,4370,10.87025,99.6243667602539,,,,,,,,,,,,,0,,,,0.0049,,,,,,10.990541,,,,
,31874154.46,4.9994333,99.6243667602539,1.34669964856023E-5,3.48543270476964E-7,1,0.999253354069792,40.0298881530762,1.99298682895778,21.2200004607439,0.00015157978031986,2.36299024701084E-5,0.25,-2.84168346954841E-7,1.33910995477154E-5,-2.17588574785676E-7,4.9992614,4.9996052,99.6243667602539,99.6243667602539,57.322290714833,20.5736645150115,9.241568,0,0,0,40,4369,4.9979,99.6243667602539,,,,,,,,,,,,,0,,,,0,,,,,,4.9994333,,,,