File: data/monolayers/magneticStructure/ML_Ac_CoFe_C-2/PPMS/data/DD175_23_HYST_INIT_300K.DAT
[Header]
; VSM Data File (default extension .dat)
; Copyright (c) 2003-2013, Quantum Design, Inc. All rights reserved.
TITLE,
FILEOPENTIME,31821722.00,01/04/2019,3:24 pm
BYAPP,VSM,2.0,2.0
INFO,PPMS VSM Option Release 1.4.10 Build 1,APPNAME
INFO,Quantum Design Linear Motor Servo Controller,MOTOR_MODULE_NAME
INFO,3101-100 M1,MOTOR_HW_VERSION
INFO,MMC1014,MOTOR_SERIAL_NUMBER
INFO,SRV No X-over 01.03.11,MOTOR_SOFTWARE_VERSION
INFO,Quantum Design VSM Detection Module,VSM_MODULE_NAME
INFO,3101-150 F0,VSM_HW_VERSION
INFO,VSM707,VSM_SERIAL_NUMBER
INFO,VSM No X-over 01.02.05 May 20 2008 13:51:47,VSM_SOFTWARE_VERSION
INFO,704,PREAMP_SERIAL_NUMBER
INFO,822,COIL_SERIAL_NUMBER
INFO,0,MOMENT_UNITS
INFO,CoFe2O4 Monolayer,SAMPLE_MATERIAL
INFO,from YF45,SAMPLE_COMMENT
INFO,29.98,SAMPLE_MASS
INFO,,SAMPLE_VOLUME
INFO,,SAMPLE_MOLECULAR_WEIGHT
INFO,,SAMPLE_SIZE
INFO,,SAMPLE_SHAPE
DATATYPE,COMMENT,1
DATATYPE,TIME,2
STARTUPAXIS,X,2
STARTUPAXIS,Y1,5
[Data]
Comment,Time Stamp (sec),Temperature (K),Magnetic Field (Oe),Moment (emu),M. Std. Err. (emu),Transport Action,Averaging Time (sec),Frequency (Hz),Peak Amplitude (mm),Center Position (mm),Coil Signal' (mV),Coil Signal" (mV),Range (mV),M. Quad. Signal (emu),M. Raw' (emu),M. Raw" (emu),Min. Temperature (K),Max. Temperature (K),Min. Field (Oe),Max. Field (Oe),Mass (grams),Motor Lag (deg),Pressure (Torr),VSM Status (code),Motor Status (code),Measure Status (code),Measure Count,PPMS Status (code),System Temp. (K),System Field (Oe),Sample Position (deg),Bridge 1 Resistance (ohms),Bridge 1 Excitation (에),Bridge 2 Resistance (ohms),Bridge 2 Excitation (에),Bridge 3 Resistance (ohms),Bridge 3 Excitation (에),Bridge 4 Resistance (ohms),Bridge 4 Excitation (에),Signal 1 Vin (V),Signal 2 Vin (V),Digital Inputs (code),Drive 1 Iout (mA),Drive 1 Ipower (W),Drive 2 Iout (mA),Drive 2 Ipower (W),Pressure (),Map 20 (),Map 21 (),Map 22 (),Map 23 (),Map 24 (),Map 25 (),Map 26 (),Map 27 (),Map 28 (),Map 29 ()
,31821747.48,300.0476379,-0.0456713177263737,,,2,,,,20.2899997290969,,,,,,,300.0476379,300.0476379,-0.0456713177263737,-0.0456713177263737,,,25.186911,,,,-99999999,4369,300.6571,-0.0456713177263737,,,,,,,,,,,,,,,,,,,,,,,300.0476379,,,,
,31821871.985,300.0359497,3692.94116210937,2.65774908908332E-5,4.89766036149398E-7,1,0.999253354069792,40.0298881530762,1.99811600358047,20.2799998223782,0.000300766410747644,5.16820102174126E-5,0.25,-3.67598363041835E-8,2.65766909106453E-5,-1.91614486358069E-8,300.0359497,300.0359497,3668.03295898438,3717.84936523438,55.9802345473136,20.4847127196831,25.566563,0,0,0,40,4449,300.626,3692.94116210937,,,,,,,,,,,,,0,,,,0.00245,,,,,,300.0359497,,,,
,31821950.435,300.0240021,7607.81420898438,1.93455860747012E-5,5.57776633031472E-7,1,0.999253354069792,40.0298881530762,1.99796144715061,20.2799998223782,0.000219183945050209,3.60344831671031E-5,0.25,-1.66567962391475E-7,1.93451052078828E-5,-1.53760837518829E-7,300.0235596,300.0244446,7587.9794921875,7627.64892578125,56.1693886489675,20.4895033765758,25.186911,0,0,0,40,4449,300.6099,7607.81420898438,,,,,,,,,,,,,0,,,,0,,,,,,300.0240021,,,,
,31822028.64,300.0155334,11518.8833007813,8.88150120923207E-6,8.65151174791129E-7,1,0.999253354069792,40.0298881530762,1.99794486476863,20.2799998223782,0.000100256113071892,1.86777244340762E-5,0.25,1.12212672058624E-7,8.88115867850229E-6,1.18082815164428E-7,300.0155334,300.0155334,11486.6318359375,11551.134765625,56.2717819849867,20.492859814254,25.566563,0,0,0,40,4449,300.6062,11518.8833007813,,,,,,,,,,,,,0,,,,-0.00245,,,,,,300.0155334,,,,
,31822107.79,300.0252228,15474.5063476562,-4.25178380936096E-6,6.5536939855331E-7,1,0.999253354069792,40.0298881530762,1.99807998464764,20.2799998223782,-4.90647197206774E-5,-2.78545591532482E-6,0.25,4.90450762094546E-7,-4.25197817628121E-6,4.8762583563212E-7,300.0242615,300.0261841,15444.57421875,15504.4384765625,56.3960609195444,20.4934626231748,25.186911,0,0,0,40,4449,300.58835,15474.5063476562,,,,,,,,,,,,,0,,,,0,,,,,,300.0252228,,,,
,31822185.19,300.0170593,19342.5888671875,-1.70335279055086E-5,1.10425640954939E-6,1,0.999253354069792,40.0298881530762,1.9980540062841,20.2799998223782,-0.000192005520344057,-3.74525336135941E-5,0.25,-3.59236860344135E-7,-1.70327764926195E-5,-3.70475355115775E-7,300.0170593,300.0170593,19312.61328125,19372.564453125,56.4836033136983,20.4958631863364,25.566563,0,0,0,40,4449,300.57815,19342.5888671875,,,,,,,,,,,,,0,,,,0.00245,,,,,,300.0170593,,,,
,31822262.91,300.0181274,23228.138671875,-3.00693735260624E-5,1.1013756076666E-6,1,0.999253354069792,40.0298881530762,1.99805482913107,20.2799998223782,-0.000338809597327243,-6.6916672551481E-5,0.25,-7.05022018918743E-7,-3.00680008437092E-5,-7.24843865195892E-7,300.0181274,300.0181274,23195.662109375,23260.615234375,56.4953277414867,20.4980057248164,25.946213,0,0,0,40,4449,300.5772,23228.138671875,,,,,,,,,,,,,0,,,,0.00245,,,,,,300.0181274,,,,
,31822343.17,300.0172424,27238.955078125,-4.39984143092944E-5,1.47802599935257E-6,1,0.999253354069792,40.0298881530762,1.99797265851115,20.2799998223782,-0.00050072480760743,-6.91220330694439E-5,0.25,1.51308155809368E-6,-4.39980876323745E-5,1.48402274849045E-6,300.0168762,300.0176086,27213.837890625,27264.072265625,56.6532167023714,20.4981457778308,25.946213,0,0,0,40,4449,300.55665,27238.955078125,,,,,,,,,,,,,0,,,,0,,,,,,300.0172424,,,,
,31822422.855,300.01956175,31221.8291015625,-5.74852197457981E-5,1.78621520624429E-6,1,0.999253354069792,40.0298881530762,1.99774148680092,20.2799998223782,-0.00064841052165876,-0.000123365988986056,0.25,-9.46270397002867E-7,-5.74828637904623E-5,-9.84118155955439E-7,300.01828,300.0208435,31191.904296875,31251.75390625,56.6328943608714,20.4999966144406,25.566563,0,0,0,40,4449,300.54455,31221.8291015625,,,,,,,,,,,,,0,,,,0.00245,,,,,,300.01956175,,,,
,31822504.18,300.0183105,35284.779296875,-7.11372520582156E-5,1.17784636457977E-6,1,0.999253354069792,40.0298881530762,1.99770537425068,20.2799998223782,-0.000804322059058231,-0.000141488267763961,0.25,-1.83296224678634E-7,-7.11349942283626E-5,-2.30122453266656E-7,300.0183105,300.0183105,35254.85546875,35314.703125,56.5844333926791,20.5001064472015,25.566563,0,0,0,40,4449,300.53395,35284.779296875,,,,,,,,,,,,,0,,,,0,,,,,,300.0183105,,,,
,31822585.08,300.0137024,39329.8359375,-8.52975603692628E-5,2.29498939882264E-6,1,0.999253354069792,40.0298881530762,1.99768070941169,20.2799998223782,-0.000963133444593746,-0.000177054106780138,0.25,-8.74355064392248E-7,-8.52944410200904E-5,-9.30435508809387E-7,300.0137024,300.0137024,39307.38671875,39352.28515625,56.5648926796983,20.5006355827228,25.946213,0,0,0,40,4449,300.5184,39329.8359375,,,,,,,,,,,,,0,,,,0,,,,,,300.0137024,,,,
,31822666.31,300.0186005,43390.775390625,-9.84479183400995E-5,2.43762693685258E-6,1,0.999253354069792,40.0298881530762,1.99760240954672,20.2799998223782,-0.00111569363442834,-0.000180590212856387,0.25,1.09073134885876E-6,-9.84456866055056E-5,1.0260009505915E-6,300.0176697,300.0195313,43360.78125,43420.76953125,56.7274714116983,20.500194006038,25.566563,0,0,0,40,4449,300.5136,43390.775390625,,,,,,,,,,,,,0,,,,0.00245,,,,,,300.0186005,,,,
,31822748.685,300.01393125,47508.83203125,-0.00011641183862873,2.07849486484612E-6,1,0.999253354069792,40.0298881530762,1.99758759417209,20.2799998223782,-0.00131625539947076,-0.000230921958115733,0.25,-2.46922535382013E-7,-0.000116408215670281,-3.23348921894108E-7,300.0135498,300.0143127,47478.890625,47538.7734375,56.6641595016406,20.4987156920133,25.566563,0,0,0,40,4449,300.5014,47508.83203125,,,,,,,,,,,,,0,,,,0.00245,,,,,,300.01393125,,,,
,31822830.835,300.0176392,51611.927734375,-0.000128040112850343,1.66627613686135E-6,1,0.999253354069792,40.0298881530762,1.99753653575743,20.2799998223782,-0.00144830441805091,-0.000250491036605669,0.25,3.70041215168838E-8,-0.000128036320524032,-4.69872228582019E-8,300.0176392,300.0176392,51582.12890625,51641.7265625,56.8259566051214,20.5028534922605,25.566563,0,0,0,40,4449,300.49215,51611.927734375,,,,,,,,,,,,,0,,,,0.00245,,,,,,300.0176392,,,,
,31822912.4,300.0144653,55689.779296875,-0.00014624230816884,2.96519893516365E-6,1,0.999253354069792,40.0298881530762,1.99746135769694,20.2799998223782,-0.00165636920157306,-0.000273202915150244,0.25,1.18163699146546E-6,-0.00014623874800919,1.08576076815155E-6,300.0144653,300.0144653,55660.08203125,55719.4765625,56.7798405224868,20.5020754738662,25.186911,0,0,0,40,4449,300.47985,55689.779296875,,,,,,,,,,,,,0,,,,0,,,,,,300.0144653,,,,
,31822994.345,300.011261,59788.201171875,-0.000154865862100237,2.35348660514898E-6,1,0.999253354069792,40.0298881530762,1.9972354019604,20.2799998223782,-0.00174885932704946,-0.000318100533829624,0.25,-1.29704906754689E-6,-0.000154860449484996,-1.39840349419886E-6,300.011261,300.011261,59783.40625,59792.99609375,56.6508718168137,20.5039169683749,25.946213,0,0,0,40,4449,300.4775,59788.201171875,,,,,,,,,,,,,0,,,,-0.00245,,,,,,300.011261,,,,
,31823075.275,300.018219,63831.353515625,-0.000172880773889425,2.72466822448277E-6,1,0.999253354069792,40.0298881530762,1.99723983747603,20.2799998223782,-0.00195572334865563,-0.00033534930569908,0.25,2.98794396599698E-7,-0.00017287584168232,1.85708941998048E-7,300.018219,300.018219,63806.4765625,63856.23046875,56.7571732954291,20.5037397693417,25.946213,0,0,0,40,4449,300.4731,63831.353515625,,,,,,,,,,,,,0,,,,0,,,,,,300.018219,,,,
,31823157.59,300.0141602,67947.24609375,-0.000186377542541623,2.99780805049464E-6,1,0.999253354069792,40.0298881530762,1.99714523477343,20.2799998223782,-0.00210752532218164,-0.000366050966784136,0.25,-7.92205451661599E-8,-0.000186372000692531,-2.01002267535516E-7,300.0141602,300.0141602,67945.03125,67949.4609375,56.7728058658137,20.5034731081364,25.566563,0,0,0,40,4449,300.4637,67947.24609375,,,,,,,,,,,,,0,,,,0,,,,,,300.0141602,,,,
,31823238.29,300.0236664,71980.21484375,-0.000196133730484375,3.27130618327054E-6,1,0.999253354069792,40.0298881530762,1.99716780766829,20.2799998223782,-0.002218699388093,-0.000380428689970383,0.25,3.39877560185973E-7,-0.000196128118708883,2.11830154681749E-7,300.0232239,300.0241089,71947.9765625,72012.453125,56.6407106460637,20.5033203975482,25.946213,0,0,0,40,4449,300.4468,71980.21484375,,,,,,,,,,,,,0,,,,0.00245,,,,,,300.0236664,,,,
,31823320.28,300.0204468,76078.484375,-0.00021760324153393,2.90528749678644E-6,1,0.999253354069792,40.0298881530762,1.99724121656109,20.2799998223782,-0.00246318288259767,-0.000413256446363187,0.25,1.15774580811098E-6,-0.000217597561742024,1.01579659716926E-6,300.019928,300.0209656,76050.953125,76106.015625,56.6954246424098,20.5027227476656,25.566563,0,0,0,40,4449,300.42815,76078.484375,,,,,,,,,,,,,0,,,,-0.00245,,,,,,300.0204468,,,,
,31823402.12,300.0217743,80166.65234375,-0.000229698671102927,2.61224783669394E-6,1,0.999253354069792,40.0298881530762,1.9971932495035,20.2799998223782,-0.00259488270241534,-0.000465978572770794,0.25,-1.40971758682804E-6,-0.000229690962135319,-1.55933254543421E-6,300.0212097,300.0223389,80139.0859375,80194.21875,56.8150138058522,20.5037685693627,25.946213,0,0,0,40,4449,300.40985,80166.65234375,,,,,,,,,,,,,0,,,,-0.00245,,,,,,300.0217743,,,,
,31823483.415,300.02445985,84232.8671875,-0.000243449316803027,3.37503090491963E-6,1,0.999253354069792,40.0298881530762,1.99714518547266,20.2799998223782,-0.00275005646481409,-0.000494454857524517,0.25,-1.54664848721259E-6,-0.000243441103538059,-1.70506113282363E-6,300.0241089,300.0248108,84207.96875,84257.765625,56.7993812354675,20.501770323709,25.566563,0,0,0,40,4449,300.39365,84232.8671875,,,,,,,,,,,,,0,,,,-0.0049,,,,,,300.02445985,,,,
,31823562.065,300.0196228,88161.21875,-0.000254903200182402,3.10674161941364E-6,1,0.999253354069792,40.0298881530762,1.99706927144123,20.2799998223782,-0.00288635564191801,-0.000477194144454319,0.25,1.96234537862107E-6,-0.000254896989300525,1.79653747688571E-6,300.0194092,300.0198364,88131.171875,88191.265625,56.6782288149868,20.5052319987713,25.946213,0,0,0,40,4449,300.3828,88161.21875,,,,,,,,,,,,,0,,,,-0.00245,,,,,,300.0196228,,,,
,31823654.18,300.0139771,87995.5625,-0.0002541470571918,3.29948263285962E-6,1,0.999253354069792,40.0298881530762,1.99719878582903,20.2799998223782,-0.00287419730575576,-0.000497597684432718,0.25,2.97893671831916E-8,-0.000254139662061391,-1.354855254427E-7,300.0139771,300.0139771,87968.0234375,88023.1015625,56.6797920720252,20.5040761196167,25.186911,0,0,0,40,4449,300.3699,87995.5625,,,,,,,,,,,,,0,,,,0,,,,,,300.0139771,,,,
,31823730.93,300.00349425,84158.96484375,-0.000240363211732941,3.12755943540965E-6,1,0.999253354069792,40.0298881530762,1.99712097736285,20.2799998223782,-0.00271970111558125,-0.000462003109196281,0.25,7.8789986117299E-7,-0.000240356789234409,6.31413863201774E-7,300.003479,300.0035095,84134.125,84183.8046875,56.7360693254098,20.5066599227809,25.186911,0,0,0,40,4449,300.3764,84158.96484375,,,,,,,,,,,,,0,,,,-0.00245,,,,,,300.00349425,,,,
,31823812.445,300.0027771,80082.31640625,-0.000229987911125042,3.77132247153398E-6,1,0.999253354069792,40.0298881530762,1.99708791115438,20.2799998223782,-0.00260416883554175,-0.000431057418957392,0.25,1.72645407122512E-6,-0.000229982391813411,1.57653350713184E-6,300.0027771,300.0027771,80054.8984375,80109.734375,56.6242964471598,20.5099907151565,25.186911,0,0,0,40,4449,300.37145,80082.31640625,,,,,,,,,,,,,0,,,,0.00245,,,,,,300.0027771,,,,
,31823892.305,300.0014038,76088.87109375,-0.000216138462583625,1.94510722419012E-6,1,0.999253354069792,40.0298881530762,1.99716400884094,20.2799998223782,-0.00244626768669844,-0.000411878875190509,0.25,1.02449446501984E-6,-0.000216132884661371,8.83476513419173E-7,300.0006409,300.0021667,76056.34375,76121.3984375,56.7587365524675,20.5056651043263,25.566563,0,0,0,40,4449,300.3751,76088.87109375,,,,,,,,,,,,,0,,,,0,,,,,,300.0014038,,,,
,31823970.685,299.9943848,72172.44140625,-0.000198496211182521,3.33570078770929E-6,1,0.999253354069792,40.0298881530762,1.99718512123521,20.2799998223782,-0.00224333668837816,-0.00039718446320783,0.25,-7.32132059582332E-7,-0.000198490035711461,-8.61716717960661E-7,299.9943848,299.9943848,72142.484375,72202.3984375,56.831428004756,20.5093637322355,25.566563,0,0,0,40,4449,300.38245,72172.44140625,,,,,,,,,,,,,0,,,,0,,,,,,299.9943848,,,,
,31824050.14,299.999115,68199.12890625,-0.000188146653130716,3.48788029798931E-6,1,0.999253354069792,40.0298881530762,1.99716160663923,20.2799998223782,-0.00212769075977318,-0.000368703954678984,0.25,-7.01502775728621E-9,-0.000188141205081364,-1.29988183397953E-7,299.999115,299.999115,68169.1171875,68229.140625,56.9525804252368,20.50736501083,25.946213,0,0,0,40,4449,300.3777,68199.12890625,,,,,,,,,,,,,0,,,,-0.00245,,,,,,299.999115,,,,
,31824129.14,299.9929199,64253.068359375,-0.000172167887668795,2.73519427475344E-6,1,0.999253354069792,40.0298881530762,1.99694188846155,20.2799998223782,-0.00194404026705741,-0.000353214712489223,0.25,-1.40883403849378E-6,-0.000172162013579197,-1.52143049306024E-6,299.9929199,299.9929199,64225.50390625,64280.6328125,56.7962547213906,20.5111398653987,25.566563,0,0,0,40,4449,300.38545,64253.068359375,,,,,,,,,,,,,0,,,,0,,,,,,299.9929199,,,,
,31824208.5,299.99336245,60284.388671875,-0.000158633562633253,2.06128501652555E-6,1,0.999253354069792,40.0298881530762,1.99702037438099,20.2799998223782,-0.00179499244926202,-0.000304055068216308,0.25,5.9494201163428E-7,-0.00015862937777682,4.91042806270991E-7,299.9928589,299.993866,60256.91796875,60311.859375,56.750138638756,20.5115171145424,26.325863,0,0,0,40,4449,300.39035,60284.388671875,,,,,,,,,,,,,0,,,,0.00245,,,,,,299.99336245,,,,
,31824288.51,299.9903564,56283.5703125,-0.000144244481797151,1.97650529343632E-6,1,0.999253354069792,40.0298881530762,1.99697604673363,20.2799998223782,-0.00163186902807771,-0.000278037221862148,0.25,4.02424653186936E-7,-0.000144240593570123,3.07863222016361E-7,299.9898376,299.9908752,56253.28125,56313.859375,56.9377294833714,20.5136617982689,25.186911,0,0,0,40,4449,300.39445,56283.5703125,,,,,,,,,,,,,0,,,,0,,,,,,299.9903564,,,,
,31824370.015,299.9926453,52210.89453125,-0.000128399771300449,1.82729749230602E-6,1,0.999253354069792,40.0298881530762,1.99692678091889,20.2799998223782,-0.00144914485684898,-0.000267317330979696,0.25,-1.39516503136148E-6,-0.00012839514199649,-1.47937172142685E-6,299.9926453,299.9926453,52186.203125,52235.5859375,56.6618146160829,20.5112892460432,25.186911,0,0,0,40,4449,300.39215,52210.89453125,,,,,,,,,,,,,0,,,,0,,,,,,299.9926453,,,,
,31824453.115,299.9844055,48057.330078125,-0.000114533472020804,2.07201876215091E-6,1,0.999253354069792,40.0298881530762,1.99683212499301,20.2799998223782,-0.00129508199941042,-0.000224048373758104,0.25,2.82184565428213E-8,-0.000114530205513489,-4.6999957395435E-8,299.9844055,299.9844055,48027.3046875,48087.35546875,57.1518956976407,20.5145915375687,25.566563,0,0,0,40,4449,300.41015,48057.330078125,,,,,,,,,,,,,0,,,,-0.00245,,,,,,299.9844055,,,,
,31824533.575,299.9894104,44036.51953125,-0.00010265735503543,1.84271901229409E-6,1,0.999253354069792,40.0298881530762,1.99694702992679,20.2799998223782,-0.00115894640143001,-0.000211854267889106,0.25,-9.498101295094E-7,-0.000102653762255574,-1.01726321941779E-6,299.9894104,299.9894104,44009.04296875,44063.99609375,56.8103240347368,20.5140426852529,25.946213,0,0,0,40,4449,300.4132,44036.51953125,,,,,,,,,,,,,0,,,,-0.00245,,,,,,299.9894104,,,,
,31824614.115,299.9896851,40008.857421875,-8.78490753841568E-5,1.73794778334128E-6,1,0.999253354069792,40.0298881530762,1.99696479583384,20.2799998223782,-0.00099085570780876,-0.000186614817546312,0.25,-1.28312931422976E-6,-8.78456854962145E-5,-1.34088994546594E-6,299.9896851,299.9896851,39981.30078125,40036.4140625,56.8267382336406,20.5117448549948,25.946213,0,0,0,40,4449,300.4219,40008.857421875,,,,,,,,,,,,,0,,,,0,,,,,,299.9896851,,,,
,31824696.175,299.9910278,35911.083984375,-7.34319950527826E-5,1.42653249045027E-6,1,0.999253354069792,40.0298881530762,1.99679780689247,20.2799998223782,-0.000830966439142606,-0.000139883847111992,0.25,3.50777770039718E-7,-7.34300907044256E-5,3.02411605506962E-7,299.9898071,299.9922485,35883.59375,35938.57421875,56.8986480574099,20.5160885258087,25.566563,0,0,0,40,4449,300.4272,35911.083984375,,,,,,,,,,,,,0,,,,0,,,,,,299.9910278,,,,
,31824778.225,299.9948425,31808.25390625,-5.92081312987705E-5,1.33077555883031E-6,1,0.999253354069792,40.0298881530762,1.99671729468633,20.2799998223782,-0.000667935490918712,-0.000124592171747011,0.25,-7.61533946625308E-7,-5.92058963709914E-5,-8.00536285950545E-7,299.9946899,299.9949951,31775.91015625,31840.59765625,56.9103724851983,20.5187573413231,25.946213,0,0,0,40,4449,300.42635,31808.25390625,,,,,,,,,,,,,0,,,,-0.00245,,,,,,299.9948425,,,,
,31824860.635,299.9932861,27690.62890625,-4.5290486922675E-5,1.20213644886962E-6,1,0.999253354069792,40.0298881530762,1.99680535406292,20.2799998223782,-0.000512654005415397,-8.54742043621555E-5,0.25,2.87326001389992E-7,-4.52893510899481E-5,2.5744082687512E-7,299.9932861,299.9932861,27657.97265625,27723.28515625,57.2058280654676,20.5185019634919,25.946213,0,0,0,40,4449,300.4345,27690.62890625,,,,,,,,,,,,,0,,,,-0.00245,,,,,,299.9932861,,,,
,31824940.815,299.9916077,23684.4609375,-3.07827948187748E-5,1.00972794724036E-6,1,0.999253354069792,40.0298881530762,1.99673204693494,20.2799998223782,-0.000346659265641275,-6.82881834361872E-5,0.25,-7.06445973421678E-7,-3.07814279678456E-5,-7.2674833566727E-7,299.9916077,299.9916077,23659.388671875,23709.533203125,57.0307432771599,20.5188637124392,25.946213,0,0,0,40,4449,300.43945,23684.4609375,,,,,,,,,,,,,0,,,,-0.00245,,,,,,299.9916077,,,,
,31825020.67,299.9984131,19691.716796875,-1.77610425673234E-5,7.79045258284334E-7,1,0.999253354069792,40.0298881530762,1.99682094234454,20.2799998223782,-0.000201075728436061,-3.33307118956272E-5,0.25,1.29407642399429E-7,-1.7760603326412E-5,1.17668228002762E-7,299.9984131,299.9984131,19661.62890625,19721.8046875,56.9346029692945,20.5180478672343,26.325863,0,0,0,40,4449,300.4353,19691.716796875,,,,,,,,,,,,,0,,,,-0.00245,,,,,,299.9984131,,,,
,31825099.275,299.99977115,15761.3046875,-5.21508681479343E-6,7.91525716322841E-7,1,0.999253354069792,40.0298881530762,1.99687550610582,20.2799998223782,-5.82773933460374E-5,-1.42024285380949E-5,0.25,-3.52498914963514E-7,-5.2146991674462E-6,-3.55936877385661E-7,299.9994507,300.0000916,15728.6337890625,15793.9755859375,56.7876568076791,20.5188351577238,25.946213,0,0,0,40,4449,300.4409,15761.3046875,,,,,,,,,,,,,0,,,,-0.00245,,,,,,299.99977115,,,,
,31825178.33,299.9942627,11813.455078125,8.19584373186756E-6,6.0133635380549E-7,1,0.999253354069792,40.0298881530762,1.99695546466966,20.2799998223782,9.21969177419095E-5,1.88189360360197E-5,0.25,2.44272623685651E-7,8.19544045315509E-6,2.49688782607176E-7,299.9942627,299.9942627,11786.0712890625,11840.8388671875,56.7423223535637,20.5168462761479,25.946213,0,0,0,40,4449,300.4399,11813.455078125,,,,,,,,,,,,,0,,,,-0.00245,,,,,,299.9942627,,,,
,31825256.81,299.9940491,7889.76293945313,1.85972777446319E-5,4.67522964164138E-7,1,0.999253354069792,40.0298881530762,1.99661254314374,20.2799998223782,0.000209039124228037,4.34548256131962E-5,0.25,6.21458374717265E-7,1.85963173643751E-5,6.33754237698598E-7,299.9940491,299.9940491,7862.18994140625,7917.3359375,56.6539983308906,20.5228465169844,25.946213,0,0,0,40,4449,300.4465,7889.76293945313,,,,,,,,,,,,,0,,,,0.00245,,,,,,299.9940491,,,,
,31825332.665,299.9960022,4096.74487304687,2.6346450274237E-5,4.86807567212177E-7,1,0.999253354069792,40.0298881530762,1.99675025436715,20.2799998223782,0.000298568327770357,4.76752423586249E-5,0.25,-3.48142716595379E-7,2.63459005915513E-5,-3.30677094396449E-7,299.9960022,299.9960022,4069.14892578125,4124.3408203125,57.0151107067753,20.5214403500363,25.566563,0,0,0,40,4449,300.4512,4096.74487304687,,,,,,,,,,,,,0,,,,-0.00245,,,,,,299.9960022,,,,
,31825407.845,299.99432375,340.363876342773,1.90388230991517E-5,3.41992962575044E-7,1,0.999253354069792,40.0298881530762,1.99680245018116,20.2799998223782,0.000215299516072421,3.71150571488168E-5,0.25,-1.6109858643896E-8,1.90382704596618E-5,-3.48928381560666E-9,299.9940491,299.9945984,310.498199462891,370.229553222656,57.2535074051407,20.52211423744,25.946213,0,0,0,40,4449,300.44345,340.363876342773,,,,,,,,,,,,,0,,,,0,,,,,,299.99432375,,,,
,31825483.54,299.9950867,-3437.5380859375,-2.65100303786899E-5,4.24704886848368E-7,1,0.999253354069792,40.0298881530762,1.99679967768457,20.2799998223782,-0.000298945814557754,-5.65339656404513E-5,0.25,-4.06902133300543E-7,-2.65089762958964E-5,-4.24455556819456E-7,299.9950867,299.9950867,-3467.39575195313,-3407.68041992188,56.8806706014676,20.5239994256432,25.946213,0,0,0,40,4449,300.44935,-3437.5380859375,,,,,,,,,,,,,0,,,,-0.00245,,,,,,299.9950867,,,,
,31825561.955,299.997818,-7360.01586914062,-1.99691549588608E-5,5.47367077551352E-7,1,0.999253354069792,40.0298881530762,1.99688595841027,20.2799998223782,-0.000226267106313848,-3.64023198501875E-5,0.25,2.40449837343891E-7,-1.9968722029135E-5,2.2721922212469E-7,299.9976807,299.9979553,-7392.51416015625,-7327.517578125,56.8970848003714,20.5223002085283,26.325863,0,0,0,40,4449,300.4514,-7360.01586914062,,,,,,,,,,,,,0,,,,0.00245,,,,,,299.997818,,,,
,31825641.395,300.0015717,-11331.5571289062,-9.03463776031102E-6,6.57849018913637E-7,1,0.999253354069792,40.0298881530762,1.99683364373813,20.2799998223782,-9.98473131808991E-5,-3.10142001614466E-5,0.25,-1.17760426856969E-6,-9.03358966620312E-6,-1.18354813262381E-6,300.0007935,300.0023499,-11361.615234375,-11301.4990234375,57.0455942190253,20.5233442130639,25.946213,0,0,0,40,4449,300.4408,-11331.5571289062,,,,,,,,,,,,,0,,,,0,,,,,,300.0015717,,,,
,31825723.115,300.00331115,-15417.0986328125,4.80270797245444E-6,7.19078159649172E-7,1,0.999253354069792,40.0298881530762,1.99684713412987,20.2799998223782,5.4618061509776E-5,7.59811420339763E-6,0.25,-1.60125326583528E-7,4.80267089422271E-6,-1.56944685369198E-7,300.0025024,300.0041199,-15444.47265625,-15389.724609375,57.0487207331022,20.5241343003818,25.946213,0,0,0,40,4449,300.44575,-15417.0986328125,,,,,,,,,,,,,0,,,,-0.00245,,,,,,300.00331115,,,,
,31825804.93,300.006897,-19504.9609375,1.72681052433324E-5,7.61439066226215E-7,1,0.999253354069792,40.0298881530762,1.99677133760075,20.2799998223782,0.000196198739957097,2.83165521216923E-5,0.25,-4.87403283297327E-7,1.72679118274974E-5,-4.75978509342043E-7,300.006897,300.006897,-19532.728515625,-19477.193359375,56.8759808303522,20.5259931288575,25.566563,0,0,0,40,4449,300.437,-19504.9609375,,,,,,,,,,,,,0,,,,0.00245,,,,,,300.006897,,,,
,31825887.845,300.0178833,-23647.369140625,3.05994519885156E-5,8.94224753428632E-7,1,0.999253354069792,40.0298881530762,1.99679787516512,20.2799998223782,0.000347529451986406,5.10046620638439E-5,0.25,-7.90573520354839E-7,3.05990499498224E-5,-7.70347503134087E-7,300.0178833,300.0178833,-23649.8515625,-23644.88671875,56.8533136032945,20.5227294940184,25.566563,0,0,0,40,4449,300.4391,-23647.369140625,,,,,,,,,,,,,0,,,,0,,,,,,300.0178833,,,,
,31825971.095,300.0154419,-27810.619140625,4.47226591941078E-5,1.37032555771316E-6,1,0.999253354069792,40.0298881530762,1.99669871361705,20.2799998223782,0.000509775862191084,6.37614588094342E-5,0.25,-2.10898006289888E-6,4.47227059951647E-5,-2.07941265760665E-6,300.0154419,300.0154419,-27838.1171875,-27783.12109375,57.3981086811984,20.5264756797492,25.566563,0,0,0,40,4449,300.41215,-27810.619140625,,,,,,,,,,,,,0,,,,0.00245,,,,,,300.0154419,,,,
,31826053.9,300.0143127,-31948.4423828125,6.01874129312724E-5,1.43603955898878E-6,1,0.999253354069792,40.0298881530762,1.99669520925757,20.2799998223782,0.000680379342909225,0.000118547360407133,0.25,5.73441493195708E-8,6.0185571133951E-5,9.70152341876196E-8,300.0143127,300.0143127,-31950.802734375,-31946.08203125,57.1933220091599,20.5277972432985,25.946213,0,0,0,40,4449,300.4009,-31948.4423828125,,,,,,,,,,,,,0,,,,0,,,,,,300.0143127,,,,
,31826136.12,300.0177917,-36055.802734375,7.47379657915354E-5,1.50424280623635E-6,1,0.999253354069792,40.0298881530762,1.99682728820924,20.2799998223782,0.000846874183331578,0.000135920016046209,0.25,-9.2777723959486E-7,7.47363312236618E-5,-8.7852890392553E-7,300.0177917,300.0177917,-36058.29296875,-36053.3125,57.2628869473714,20.5259106998304,25.566563,0,0,0,40,4449,300.3954,-36055.802734375,,,,,,,,,,,,,0,,,,0,,,,,,300.0177917,,,,
,31826214.245,300.0136108,-39960.787109375,8.56837829418607E-5,1.77941807347948E-6,1,0.999253354069792,40.0298881530762,1.99673989737939,20.2799998223782,0.000972496161290783,0.000146396621447722,0.25,-1.89704369305236E-6,8.56824739123316E-5,-1.84060573682584E-6,300.0136108,300.0136108,-39990.90625,-39930.66796875,56.8408075469868,20.528705089544,25.946213,0,0,0,40,4449,300.38765,-39960.787109375,,,,,,,,,,,,,0,,,,0.00245,,,,,,300.0136108,,,,
,31826292.83,300.0111084,-43888.8125,0.000101146194821776,1.71855186421329E-6,1,0.999253354069792,40.0298881530762,1.99660770713493,20.2799998223782,0.00114681980463785,0.000179151499744525,0.25,-1.67791274672203E-6,0.000101144293372811,-1.611364346265E-6,300.0111084,300.0111084,-43918.515625,-43859.109375,57.0049495360253,20.5294516003821,25.946213,0,0,0,40,4449,300.37805,-43888.8125,,,,,,,,,,,,,0,,,,0,,,,,,300.0111084,,,,
,31826375.135,300.0160522,-48004.03515625,0.000114275453293444,1.58208863813928E-6,1,0.999253354069792,40.0298881530762,1.99664810092391,20.2799998223782,0.00129432161032439,0.000210408338750724,0.25,-1.18820777491269E-6,0.000114272825158668,-1.11311263502066E-6,300.0160522,300.0160522,-48006.46875,-48001.6015625,57.1003082153714,20.5306740909552,25.566563,0,0,0,40,4449,300.37365,-48004.03515625,,,,,,,,,,,,,0,,,,0,,,,,,300.0160522,,,,
,31826456.98,300.01557925,-52091.58984375,0.00012801558752118,2.43707630138927E-6,1,0.999253354069792,40.0298881530762,1.99667229195459,20.2799998223782,0.00144492716552066,0.000264780848164706,0.25,1.24026056955015E-6,0.000128010964083267,1.32423293467566E-6,300.0153809,300.0157776,-52124.07421875,-52059.10546875,57.0510656186599,20.5278261462896,25.566563,0,0,0,40,4449,300.35555,-52091.58984375,,,,,,,,,,,,,0,,,,0,,,,,,300.01557925,,,,
,31826538.095,300.0150299,-56147.0234375,0.000140220782299784,2.48008975941048E-6,1,0.999253354069792,40.0298881530762,1.99674548697067,20.2799998223782,0.00158857254925672,0.00025639446048894,0.25,-1.61678905289378E-6,0.000140217679968447,-1.52480763614143E-6,300.0147095,300.0153503,-56171.828125,-56122.21875,57.014329078256,20.5307818236238,26.325863,0,0,0,40,4449,300.3439,-56147.0234375,,,,,,,,,,,,,0,,,,0.00245,,,,,,300.0150299,,,,
,31826619.46,300.0105591,-60214.58203125,0.000158672117387169,2.3023039555245E-6,1,0.999253354069792,40.0298881530762,1.99677659172064,20.2799998223782,0.00179763923200076,0.000290120371332116,0.25,-1.83092517396281E-6,0.000158668641120796,-1.72694243353613E-6,300.0098572,300.011261,-60245.0234375,-60184.140625,56.750138638756,20.529585565402,25.566563,0,0,0,40,4449,300.3414,-60214.58203125,,,,,,,,,,,,,0,,,,0.00245,,,,,,300.0105591,,,,
,31826701.865,300.0110779,-64332.76171875,0.000172120350010399,2.14916323809802E-6,1,0.999253354069792,40.0298881530762,1.99674406776544,20.2799998223782,0.00194537239973401,0.00034122820884653,0.25,3.59879787978019E-7,0.00017211504935481,4.7249608969928E-7,300.0110779,300.0110779,-64338.14453125,-64327.37890625,56.8267382336406,20.5305267773686,25.946213,0,0,0,40,4449,300.33215,-64332.76171875,,,,,,,,,,,,,0,,,,0.00245,,,,,,300.0110779,,,,
,31826782.8,300.01574705,-68375.17578125,0.000184738919432809,3.13323660827066E-6,1,0.999253354069792,40.0298881530762,1.99666904410057,20.2799998223782,0.00208967031325386,0.000356113308370688,0.25,-5.08533108210249E-7,0.000184733795092249,-3.87754977661601E-7,300.0153503,300.0161438,-68405.0859375,-68345.265625,57.0588819038522,20.5320252170553,26.325863,0,0,0,40,4449,300.32975,-68375.17578125,,,,,,,,,,,,,0,,,,-0.00245,,,,,,300.01574705,,,,
,31826864.11,300.0158234,-72438.015625,0.000201454311989419,2.89604747779538E-6,1,0.999253354069792,40.0298881530762,1.99667664330837,20.2799998223782,0.00227945483141562,0.000384293999830853,0.25,-9.11951843205731E-7,0.000201448967551795,-7.80359417242809E-7,300.015564,300.0160828,-72467.9375,-72408.09375,56.9893169656406,20.5349187962557,25.566563,0,0,0,40,4449,300.30915,-72438.015625,,,,,,,,,,,,,0,,,,0.00245,,,,,,300.0158234,,,,
,31826944.205,300.01016235,-76443.02734375,0.000215228090276821,3.42303395007184E-6,1,0.999253354069792,40.0298881530762,1.99669331422108,20.2799998223782,0.00243455323575976,0.000415027533685169,0.25,-5.80110329802991E-7,0.000215222178336906,-4.39667079856744E-7,300.0098877,300.010437,-76475.453125,-76410.6015625,56.6571248449675,20.5362153660432,25.566563,0,0,0,40,4449,300.2931,-76443.02734375,,,,,,,,,,,,,0,,,,0.0049,,,,,,300.01016235,,,,
,31827026.295,300.01889035,-80545.76171875,0.000228910522575051,2.50518746673163E-6,1,0.999253354069792,40.0298881530762,1.99670199068329,20.2799998223782,0.00259156255773221,0.000428539445914603,0.25,-1.75548008237192E-6,0.000228904918420456,-1.60623031927158E-6,300.0184631,300.0193176,-80573.109375,-80518.4140625,56.8650380310829,20.5369677414625,25.946213,0,0,0,40,4449,300.28935,-80545.76171875,,,,,,,,,,,,,0,,,,-0.00245,,,,,,300.01889035,,,,
,31827108.155,300.0159149,-84635.3984375,0.000246786222483737,2.53196468051551E-6,1,0.999253354069792,40.0298881530762,1.99654937440576,20.2799998223782,0.00279091242004359,0.000478263826619931,0.25,-4.51218906647384E-7,0.00024677928185712,-2.90520714015889E-7,300.0153503,300.0164795,-84660.3671875,-84610.4296875,56.861911517006,20.5350868176749,25.946213,0,0,0,40,4449,300.27855,-84635.3984375,,,,,,,,,,,,,0,,,,-0.00245,,,,,,300.0159149,,,,
,31827187.89,300.0141449,-88620.28125,0.000258779285722907,3.41323713243426E-6,1,0.999253354069792,40.0298881530762,1.99668443233442,20.2799998223782,0.00292639102244351,0.000503504339625891,0.25,-2.99102595056438E-7,0.000258771925398386,-1.30765836372602E-7,300.0141296,300.0141602,-88647.6875,-88592.875,56.6477453027368,20.5351839238361,25.566563,0,0,0,40,4449,300.2632,-88620.28125,,,,,,,,,,,,,0,,,,0,,,,,,300.0141449,,,,
,31827281.37,300.0107117,-87521.03515625,0.000253319255785713,2.36144818851343E-6,1,0.999253354069792,40.0298881530762,1.99673853582194,20.2799998223782,0.00286824390569684,0.000472558821291058,0.25,-2.09135396920002E-6,0.000253313247620264,-1.92646314567938E-6,300.0107117,300.0107117,-87543.5859375,-87498.484375,56.811105663256,20.5372415361573,25.946213,0,0,0,40,4449,300.25385,-87521.03515625,,,,,,,,,,,,,0,,,,-0.00245,,,,,,300.0107117,,,,
,31827362.15,300.0113678,-83483.7265625,0.000239475732746398,3.14119271919764E-6,1,0.999253354069792,40.0298881530762,1.996717739621,20.2799998223782,0.00270926186163283,0.000459483722143156,0.25,-8.49173468563995E-7,0.000239469300806922,-6.93178370995213E-7,300.0107727,300.0119629,-83516.109375,-83451.34375,56.9220969129868,20.532391334882,25.946213,0,0,0,40,4449,300.28105,-83483.7265625,,,,,,,,,,,,,0,,,,0,,,,,,300.0113678,,,,
,31827444.735,299.994339,-79355.62890625,0.00022490325597408,2.90919188396104E-6,1,0.999253354069792,40.0298881530762,1.99667137559158,20.2799998223782,0.00254164128030934,0.000447114401842953,0.25,5.82149937252545E-7,0.000224896439617258,7.28775308729781E-7,299.9942627,299.9944153,-79388.1953125,-79323.0625,56.8634747740445,20.5339106014004,26.325863,0,0,0,40,4449,300.2705,-79355.62890625,,,,,,,,,,,,,0,,,,-0.00245,,,,,,299.994339,,,,
,31827526.98,299.9984436,-75245.578125,0.000213308043720738,3.28959424122407E-6,1,0.999253354069792,40.0298881530762,1.99669278171043,20.2799998223782,0.00241553540725433,0.000395738113665655,0.25,-1.95361417190041E-6,0.000213303169412732,-1.81432855069822E-6,299.9984436,299.9984436,-75275.6484375,-75215.5078125,56.7431039820829,20.5331709573948,25.946213,0,0,0,40,4449,300.26885,-75245.578125,,,,,,,,,,,,,0,,,,0,,,,,,299.9984436,,,,
,31827610.185,299.993988,-71088.046875,0.000195327578954997,2.25404878605759E-6,1,0.999253354069792,40.0298881530762,1.99668209846186,20.2799998223782,0.00221049506995101,0.000370548683918175,0.25,-1.06640800172167E-6,0.000195322664397806,-9.38754706767693E-7,299.993988,299.993988,-71113.1640625,-71062.9296875,56.831428004756,20.5349368706619,25.946213,0,0,0,40,4449,300.2795,-71088.046875,,,,,,,,,,,,,0,,,,0.00245,,,,,,299.993988,,,,
,31827693.395,299.9927673,-66928.4375,0.000183085821023843,2.4485677831674E-6,1,0.999253354069792,40.0298881530762,1.99679924067343,20.2799998223782,0.00207517012485614,0.000329466960761682,0.25,-2.58084788989393E-6,0.00018308224661007,-2.46102822361939E-6,299.9927673,299.9927673,-66931.1953125,-66925.6796875,56.7352876968906,20.5315647824022,25.946213,0,0,0,40,4449,300.2877,-66928.4375,,,,,,,,,,,,,0,,,,0.0049,,,,,,299.9927673,,,,
,31827775.09,299.9940491,-62845.6484375,0.000167484531932463,2.48913799001103E-6,1,0.999253354069792,40.0298881530762,1.99680684053815,20.2799998223782,0.00189573213099196,0.000316476872695693,0.25,-1.02700549218875E-6,0.00016748037254681,-9.17320589611616E-7,299.9940491,299.9940491,-62848.15234375,-62843.14453125,56.9181887703906,20.5338244272997,26.325863,0,0,0,40,4449,300.2819,-62845.6484375,,,,,,,,,,,,,0,,,,0,,,,,,299.9940491,,,,
,31827855.14,299.9843445,-58844.87109375,0.000153385853153827,2.26401028929485E-6,1,0.999253354069792,40.0298881530762,1.99675516137104,20.2799998223782,0.00173842620584077,0.000276453997983458,0.25,-2.12359692336303E-6,0.000153382864914643,-2.02301823315836E-6,299.9843445,299.9843445,-58849.78515625,-58839.95703125,57.1987934087945,20.5295528525711,25.946213,0,0,0,40,4449,300.29545,-58844.87109375,,,,,,,,,,,,,0,,,,0.0049,,,,,,299.9843445,,,,
,31827936.205,299.9838562,-54794.546875,0.000137134536251188,2.39060942351136E-6,1,0.999253354069792,40.0298881530762,1.99662978123718,20.2799998223782,0.00154877252471262,0.000278162783022845,0.25,8.44490843157771E-7,0.000137130061009128,9.34422888623883E-7,299.9837952,299.9839172,-54827.19921875,-54761.89453125,56.8712910592368,20.531143105066,25.946213,0,0,0,40,4449,300.29605,-54794.546875,,,,,,,,,,,,,0,,,,-0.00245,,,,,,299.9838562,,,,
,31828017.785,299.9887695,-50717.35546875,0.000124790431732905,2.06629692014161E-6,1,0.999253354069792,40.0298881530762,1.99680435308697,20.2799998223782,0.00140972811153797,0.000251699983436424,0.25,6.40586197565039E-7,0.000124786414147887,7.22501258836723E-7,299.9887695,299.9887695,-50720.0859375,-50714.625,56.9478906541214,20.532600140626,25.946213,0,0,0,40,4449,300.3121,-50717.35546875,,,,,,,,,,,,,0,,,,-0.00245,,,,,,299.9887695,,,,
,31828098.595,299.9904327,-46679.626953125,0.000110478141094896,1.63260671814348E-6,1,0.999253354069792,40.0298881530762,1.99666440617424,20.2799998223782,0.00124631625539983,0.000232315931312288,0.25,1.4071739772436E-6,0.000110474019206083,1.47973769167054E-6,299.9901733,299.9906921,-46707.13671875,-46652.1171875,56.9994781363906,20.5310066088691,26.705515,0,0,0,40,4449,300.31595,-46679.626953125,,,,,,,,,,,,,0,,,,-0.0049,,,,,,299.9904327,,,,
,31828180.68,299.99082945,-42576.78515625,9.58707260148854E-5,1.18556574929471E-6,1,0.999253354069792,40.0298881530762,1.99666435403463,20.2799998223782,0.00108761236661346,0.0001664824818834,0.25,-1.88494375912839E-6,9.58691847818678E-5,-1.8218237341778E-6,299.9906921,299.9909668,-42604.0859375,-42549.484375,56.8939582862945,20.5341723683995,25.946213,0,0,0,40,4449,300.3129,-42576.78515625,,,,,,,,,,,,,0,,,,-0.00245,,,,,,299.99082945,,,,
,31828262.315,299.9911194,-38498.919921875,8.33894212213723E-5,1.45198097045307E-6,1,0.999253354069792,40.0298881530762,1.99728783259628,20.2799998223782,0.000946297261545861,0.000144862592732832,0.25,-1.63860903995841E-6,8.33880757711373E-5,-1.58365795877323E-6,299.9911194,299.9911194,-38501.57421875,-38496.265625,57.2597604332945,20.5221364921042,26.325863,0,0,0,40,4449,300.32405,-38498.919921875,,,,,,,,,,,,,0,,,,0,,,,,,299.9911194,,,,
,31828344.075,299.9938507,-34411.33984375,6.76187368015646E-5,1.81476185031483E-6,1,0.999253354069792,40.0298881530762,1.99713381110529,20.2799998223782,0.000768346673765682,0.000111278026870219,0.25,-1.87518539173954E-6,6.76179964128102E-5,-1.83056921386881E-6,299.9932251,299.9944763,-34444.01953125,-34378.66015625,56.6907348712945,20.525384553263,25.946213,0,0,0,40,4449,300.31975,-34411.33984375,,,,,,,,,,,,,0,,,,0,,,,,,299.9938507,,,,
,31828429.84,299.9877625,-30123.84375,5.32220639552869E-5,1.45454080737303E-6,1,0.999253354069792,40.0298881530762,1.99724930319009,20.2799998223782,0.000602593320700132,0.00010028015411047,0.25,-3.53927070890304E-7,5.32207509707682E-5,-3.18813352638511E-7,299.9877625,299.9877625,-30146.427734375,-30101.259765625,57.1644017539484,20.5192127599434,26.325863,0,0,0,40,4449,300.3427,-30123.84375,,,,,,,,,,,,,0,,,,-0.00245,,,,,,299.9877625,,,,
,31828515.13,299.9916077,-25860.974609375,3.92626557462085E-5,1.19536799887727E-6,1,0.999253354069792,40.0298881530762,1.99718379455205,20.2799998223782,0.000445068722925966,7.08516993672531E-5,0.25,-5.37366211790163E-7,3.92618622071329E-5,-5.1143148298548E-7,299.9916077,299.9916077,-25863.400390625,-25858.548828125,57.3691884259868,20.5209038945999,25.946213,0,0,0,40,4449,300.3492,-25860.974609375,,,,,,,,,,,,,0,,,,0.0049,,,,,,299.9916077,,,,
,31828599.715,299.99031065,-21633.6142578125,2.50167558811695E-5,8.32117136157164E-7,1,0.999253354069792,40.0298881530762,1.99693791742445,20.2799998223782,0.000284314519109298,4.07176112807517E-5,0.25,-7.33404486488833E-7,2.50165087220492E-5,-7.16854536788927E-7,299.9897461,299.9908752,-21661.046875,-21606.181640625,57.0964000727753,20.5193555351602,26.325863,0,0,0,40,4449,300.35675,-21633.6142578125,,,,,,,,,,,,,0,,,,-0.00245,,,,,,299.99031065,,,,
,31828680.275,299.9952393,-17608.4716796875,1.0395701553694E-5,8.96554159615536E-7,1,0.999253354069792,40.0298881530762,1.9970346309045,20.2799998223782,0.000119378683995332,9.8420416788364E-6,0.25,-9.3077888181894E-7,1.03960106096065E-5,-9.23877451452957E-7,299.9949036,299.995575,-17638.546875,-17578.396484375,56.861911517006,20.5195586629832,26.705515,0,0,0,40,4449,300.35215,-17608.4716796875,,,,,,,,,,,,,0,,,,0.00245,,,,,,299.9952393,,,,
,31828762.3,299.9966431,-13508.3920898438,-1.83791505440131E-6,6.8944095155191E-7,1,0.999253354069792,40.0298881530762,1.99707684437431,20.2799998223782,-2.06673595777057E-5,-4.27212279012374E-6,0.25,-5.93532974794316E-8,-1.83782142980631E-6,-6.05677682401256E-8,299.9966431,299.9966431,-13510.64453125,-13506.1396484375,56.709493955756,20.5201698791036,26.325863,0,0,0,40,4449,300.3537,-13508.3920898438,,,,,,,,,,,,,0,,,,0.00245,,,,,,299.9966431,,,,
,31828838.65,299.9916992,-9692.6162109375,-1.43668782607292E-5,7.13547936267288E-7,1,0.999253354069792,40.0298881530762,1.99702772346051,20.2799998223782,-0.000162080703527607,-3.03415473819704E-5,0.25,-1.94003534508997E-7,-1.43663269544121E-5,-2.03511202204182E-7,299.9916992,299.9916992,-9722.693359375,-9662.5390625,57.0792042453522,20.520239049452,25.946213,0,0,0,40,4449,300.36045,-9692.6162109375,,,,,,,,,,,,,0,,,,0,,,,,,299.9916992,,,,
,31828914.61,299.99234005,-5896.25512695313,-2.33388349376342E-5,4.49415329318917E-7,1,0.999253354069792,40.0298881530762,1.99696691359536,20.2799998223782,-0.00026316621818336,-5.00062129339837E-5,0.25,-3.78656331021426E-7,-2.33378957701317E-5,-3.94108872494756E-7,299.9920959,299.9925842,-5928.7216796875,-5863.78857421875,56.7477937531983,20.5201635007549,26.325863,0,0,0,40,4449,300.3656,-5896.25512695313,,,,,,,,,,,,,0,,,,0.0049,,,,,,299.99234005,,,,
,31828990.225,299.9931335,-2114.89367675781,-2.68815378993647E-5,4.18352479206681E-7,1,0.999253354069792,40.0298881530762,1.99687264794,20.2799998223782,-0.000303240024136185,-5.67842733523483E-5,0.25,-3.64488806525E-7,-2.68805019055607E-5,-3.82298410465368E-7,299.9931335,299.9931335,-2144.73706054687,-2085.05029296875,56.9674313671022,20.5203139333087,25.946213,0,0,0,40,4449,300.3697,-2114.89367675781,,,,,,,,,,,,,0,,,,-0.0049,,,,,,299.9931335,,,,
,31829065.1,299.9981689,1626.01519775391,2.56855759309763E-5,4.87281235566347E-7,1,0.999253354069792,40.0298881530762,1.99684686595069,20.2799998223782,0.000290559177014213,4.9559379514679E-5,0.25,-6.7211503850189E-8,2.56848567161944E-5,-5.01808188486113E-8,299.9981689,299.9981689,1601.07958984375,1650.95080566406,56.922878541506,20.5189619314617,25.946213,0,0,0,40,4449,300.368,1626.01519775391,,,,,,,,,,,,,0,,,,-0.00245,,,,,,299.9981689,,,,
,31829140.325,299.9958801,5383.71069335937,2.4298775116186E-5,4.62967470532466E-7,1,0.999253354069792,40.0298881530762,1.99682590936996,20.2799998223782,0.000275083386377115,4.56443228663159E-5,0.25,-1.73136440020229E-7,2.42981700612867E-5,-1.57030468080808E-7,299.9953613,299.9963989,5353.55615234375,5413.865234375,57.4387533641984,20.5202242210367,26.325863,0,0,0,40,4449,300.36825,5383.71069335937,,,,,,,,,,,,,0,,,,0,,,,,,299.9958801,,,,
,31829218.965,299.9989319,9314.88134765625,1.51895259086684E-5,6.56629158920862E-7,1,0.999253354069792,40.0298881530762,1.99677768098488,20.2799998223782,0.000172724412451645,2.40899654775204E-5,0.25,-5.01117853156315E-7,1.51894067250576E-5,-4.9104468163909E-7,299.9989319,299.9989319,9287.177734375,9342.5849609375,57.149550812083,20.5203130346282,26.325863,0,0,0,40,4449,300.3723,9314.88134765625,,,,,,,,,,,,,0,,,,0,,,,,,299.9989319,,,,
,31829298.59,300.0013123,13295.1572265625,2.85989166435176E-6,5.14164464556133E-7,1,0.999253354069792,40.0298881530762,1.99680316418877,20.2799998223782,3.1839246585931E-5,8.47082023266615E-6,0.25,2.53679724756936E-7,2.85963874095372E-6,2.55564718143507E-7,300.0007935,300.0018311,13265.2890625,13325.025390625,56.6477453027368,20.5200320469914,26.325863,0,0,0,40,4449,300.36,13295.1572265625,,,,,,,,,,,,,0,,,,0,,,,,,300.0013123,,,,
,31829378.005,300.0071106,17263.693359375,-1.09026560363889E-5,1.06649519050326E-6,1,0.999253354069792,40.0298881530762,1.9967333538758,20.2799998223782,-0.000123421756289432,-2.04813277206139E-5,0.25,7.7491830060443E-8,-1.09023812473707E-5,7.02799345627619E-8,300.0071106,300.0071106,17228.4609375,17298.92578125,56.8697278021983,20.5213059363442,26.705515,0,0,0,40,4449,300.35605,17263.693359375,,,,,,,,,,,,,0,,,,0.00245,,,,,,300.0071106,,,,
,31829457.71,300.00996395,21246.24609375,-2.2626985433315E-5,7.91594443987425E-7,1,0.999253354069792,40.0298881530762,1.99670544265242,20.2799998223782,-0.000256270759862225,-4.17607511534891E-5,0.25,2.26695758474158E-7,-2.2626457331932E-5,2.11738323222837E-7,300.0097961,300.0101318,21216.45703125,21276.03515625,57.1432977839291,20.520951927402,26.705515,0,0,0,40,4449,300.35835,21246.24609375,,,,,,,,,,,,,0,,,,0,,,,,,300.00996395,,,,
,31829537.205,300.0093689,25221.8046875,-3.71545319825443E-5,1.22017789685283E-6,1,0.999253354069792,40.0298881530762,1.99670317109254,20.2799998223782,-0.000423108830060531,-5.52915251121975E-5,0.25,1.54692529277149E-6,-3.71544426515512E-5,1.52234766599004E-6,300.0090332,300.0097046,25194.765625,25248.84375,57.1917587521214,20.5208265727217,26.325863,0,0,0,40,4449,300.341,25221.8046875,,,,,,,,,,,,,0,,,,0,,,,,,300.0093689,,,,
,31829616.78,300.0163574,29197.650390625,-4.92580753299934E-5,1.22138502185049E-6,1,0.999253354069792,40.0298881530762,1.99667596596002,20.2799998223782,-0.000557222434222091,-9.47265091927008E-5,0.25,1.5591823746894E-7,-4.92566956402995E-5,1.2341672308148E-7,300.0163574,300.0163574,29172.765625,29222.53515625,57.0033862789868,20.5207316050471,26.325863,0,0,0,40,4449,300.33105,29197.650390625,,,,,,,,,,,,,0,,,,-0.00245,,,,,,300.0163574,,,,
,31829696.705,300.0150146,33193.30078125,-6.36773749274986E-5,1.80234298558547E-6,1,0.999253354069792,40.0298881530762,1.99676259936874,20.2799998223782,-0.000718135764852877,-0.000135344149564015,0.25,-9.37929021772564E-7,-6.36748465818343E-5,-9.79873122509175E-7,300.0150146,300.0150146,33165.75,33220.8515625,56.943200883006,20.519010410828,26.705515,0,0,0,40,4449,300.33765,33193.30078125,,,,,,,,,,,,,0,,,,0.00245,,,,,,300.0150146,,,,
,31829776.33,300.0093079,37174.09765625,-7.75924150590224E-5,1.67890969247826E-6,1,0.999253354069792,40.0298881530762,1.99681225469375,20.2799998223782,-0.000879642374571686,-0.000138629596854696,0.25,1.18260194246675E-6,-7.75908861653783E-5,1.13146604304608E-6,300.0093079,300.0093079,37144.40625,37203.7890625,57.1448610409676,20.5216363924033,25.946213,0,0,0,40,4449,300.32975,37174.09765625,,,,,,,,,,,,,0,,,,0,,,,,,300.0093079,,,,
,31829856.375,300.00819395,41174.509765625,-9.11019342929016E-5,1.07774379575743E-6,1,0.999253354069792,40.0298881530762,1.99668545108424,20.2799998223782,-0.0010301083912026,-0.000177907018330433,0.25,4.84156183648605E-8,-9.10992650735816E-5,-1.15299135293037E-8,300.0076599,300.008728,41146.9765625,41202.04296875,56.8705094307176,20.5211757833387,26.325863,0,0,0,40,4449,300.32765,41174.509765625,,,,,,,,,,,,,0,,,,-0.00245,,,,,,300.00819395,,,,
,31829939.855,300.0161133,45344.916015625,-0.000107209232451868,1.75616314837745E-6,1,0.999253354069792,40.0298881530762,1.99670114076591,20.2799998223782,-0.00121180577006344,-0.000211902921581753,0.25,-1.6769505143931E-7,-0.000107205918540993,-2.38171288551331E-7,300.0161133,300.0161133,45310.3046875,45379.52734375,56.6375841319868,20.5201927558822,26.325863,0,0,0,40,4449,300.3042,45344.916015625,,,,,,,,,,,,,0,,,,0.00245,,,,,,300.0161133,,,,
,31830024.03,300.0083313,49553.427734375,-0.000117427631645966,2.0153997011028E-6,1,0.999253354069792,40.0298881530762,1.99670730069969,20.2799998223782,-0.00133135715421592,-0.000208744288361914,0.25,1.88204046586483E-6,-0.000117425398041887,1.80485814691488E-6,300.0083313,300.0083313,49548.55078125,49558.3046875,56.9869720800829,20.5208406583644,26.705515,0,0,0,40,4449,300.2916,49553.427734375,,,,,,,,,,,,,0,,,,0,,,,,,300.0083313,,,,
,31830105.635,300.0167847,53630.927734375,-0.000134013344539872,1.76085091711324E-6,1,0.999253354069792,40.0298881530762,1.99667603585438,20.2799998223782,-0.00151711103604966,-0.000251306535443633,0.25,9.90668206860696E-7,-0.000134010001782645,9.02704891356599E-7,300.0164185,300.0171509,53595.828125,53666.02734375,56.8634747740445,20.5213810097869,26.705515,0,0,0,40,4449,300.2945,53630.927734375,,,,,,,,,,,,,0,,,,0,,,,,,300.0167847,,,,
,31830186.825,300.0204468,57688.8671875,-0.00014950824638858,2.14740658658425E-6,1,0.999253354069792,40.0298881530762,1.99668210137012,20.2799998223782,-0.00168713620077067,-0.000311481248826699,0.25,-1.6471280933351E-6,-0.000149502700555305,-1.74508933244714E-6,300.0204468,300.0204468,57658.84765625,57718.88671875,57.3011867448138,20.5218947908968,25.946213,0,0,0,40,4449,300.27965,57688.8671875,,,,,,,,,,,,,0,,,,-0.00245,,,,,,300.0204468,,,,
,31830268.045,300.0112,61749.376953125,-0.000160665879014189,2.20493914039333E-6,1,0.999253354069792,40.0298881530762,1.99658210573477,20.2799998223782,-0.00181541277212085,-0.000320549702939739,0.25,-5.17568878065853E-7,-0.000160660802614541,-6.2278226023778E-7,300.0112,300.0112,61746.8984375,61751.85546875,56.4304525743906,20.5195664089437,25.946213,0,0,0,40,4449,300.2592,61749.376953125,,,,,,,,,,,,,0,,,,-0.00245,,,,,,300.0112,,,,
,31830346.705,300.017395,65680.82421875,-0.000175119018642046,2.00206554662755E-6,1,0.999253354069792,40.0298881530762,1.99654990246045,20.2799998223782,-0.00197975179045591,-0.000343265518319892,0.25,-2.33782013492752E-8,-0.000175113810697007,-1.379608884127E-7,300.017395,300.017395,65655.9296875,65705.71875,56.8900501436983,20.5236162403079,26.325863,0,0,0,40,4449,300.2586,65680.82421875,,,,,,,,,,,,,0,,,,0,,,,,,300.017395,,,,
,31830427.565,300.0121155,69723.87890625,-0.000188574472138181,2.97472135151745E-6,1,0.999253354069792,40.0298881530762,1.99654770786179,20.2799998223782,-0.0021356805415305,-0.000347625040390153,0.25,1.92203110171252E-6,-0.000188570183254032,1.79870609905809E-6,300.0121155,300.0121155,69698.84375,69748.9140625,56.8236117195637,20.5201203314329,25.946213,0,0,0,40,4449,300.2464,69723.87890625,,,,,,,,,,,,,0,,,,-0.0049,,,,,,300.0121155,,,,
,31830509.605,300.0135193,73824.41015625,-0.000205442482816329,2.59159589872119E-6,1,0.999253354069792,40.0298881530762,1.99657078062215,20.2799998223782,-0.00232610948187065,-0.000382381629156879,0.25,1.7703220807064E-6,-0.000205437599485613,1.63611379860032E-6,300.0124817,300.0145569,73791.8984375,73856.921875,57.1151591572368,20.5226504306942,26.705515,0,0,0,40,4449,300.245,73824.41015625,,,,,,,,,,,,,0,,,,-0.00245,,,,,,300.0135193,,,,
,31830592.995,300.0131531,77992.921875,-0.000220156058573508,2.33970095864145E-6,1,0.999253354069792,40.0298881530762,1.99659375925631,20.2799998223782,-0.00249381579183114,-0.000403507895331507,0.25,2.45102441720608E-6,-0.000220151201499215,2.30733502529214E-6,300.0131531,300.0131531,77960.609375,78025.234375,56.7876568076791,20.520694116091,26.705515,0,0,0,40,4449,300.2336,77992.921875,,,,,,,,,,,,,0,,,,-0.00735,,,,,,300.0131531,,,,
,31830677.96,300.0106812,82239.07421875,-0.000234372921181132,2.95276189073258E-6,1,0.999253354069792,40.0298881530762,1.99658570922613,20.2799998223782,-0.00264866276892118,-0.000465261151912445,0.25,-5.48381923511949E-7,-0.00023436572627025,-7.01093854692643E-7,300.0106812,300.0106812,82213.96875,82264.1796875,57.0627900464484,20.5200281246733,26.705515,0,0,0,40,4449,300.22735,82239.07421875,,,,,,,,,,,,,0,,,,-0.00245,,,,,,300.0106812,,,,
,31830761.165,300.0162354,86399.88671875,-0.000248976512998901,2.76139681739637E-6,1,0.999253354069792,40.0298881530762,1.9964739204554,20.2799998223782,-0.0028097733836488,-0.000516012777178078,0.25,-2.51000386551856E-6,-0.00024896758046477,-2.67200840786431E-6,300.0162354,300.0162354,86397.3671875,86402.40625,56.9252234270637,20.5210992137537,26.325863,0,0,0,40,4449,300.2118,86399.88671875,,,,,,,,,,,,,0,,,,0.0049,,,,,,300.0162354,,,,
,31830833.445,300.0131836,89997.53125,-0.000261189918047662,2.99366463852014E-6,1,0.999253354069792,40.0298881530762,1.9966551936122,20.2799998223782,-0.00295506651491298,-0.000499782554637797,0.25,1.04527606778285E-6,-0.000261182983933784,8.75375657668673E-7,300.0128784,300.0134888,89995.6484375,89999.4140625,56.4585912010829,20.520280814372,25.946213,0,0,0,40,4417,300.20905,89997.53125,,,,,,,,,,,,,0,,,,-0.0049,,,,,,300.0131836,,,,