File: data/monolayers/magneticStructure/ML_Ac_CoFe_C-2/PPMS/data/DD175_23_HYST_100OE_50K.DAT
[Header]
; VSM Data File (default extension .dat)
; Copyright (c) 2003-2013, Quantum Design, Inc. All rights reserved.
TITLE,
FILEOPENTIME,31931473.77,01/05/2019,9:53 pm
BYAPP,VSM,2.0,2.0
INFO,PPMS VSM Option Release 1.4.10 Build 1,APPNAME
INFO,Quantum Design Linear Motor Servo Controller,MOTOR_MODULE_NAME
INFO,3101-100 M1,MOTOR_HW_VERSION
INFO,MMC1014,MOTOR_SERIAL_NUMBER
INFO,SRV No X-over 01.03.11,MOTOR_SOFTWARE_VERSION
INFO,Quantum Design VSM Detection Module,VSM_MODULE_NAME
INFO,3101-150 F0,VSM_HW_VERSION
INFO,VSM707,VSM_SERIAL_NUMBER
INFO,VSM No X-over 01.02.05 May 20 2008 13:51:47,VSM_SOFTWARE_VERSION
INFO,704,PREAMP_SERIAL_NUMBER
INFO,822,COIL_SERIAL_NUMBER
INFO,0,MOMENT_UNITS
INFO,CoFe2O4 Monolayer,SAMPLE_MATERIAL
INFO,from YF45,SAMPLE_COMMENT
INFO,29.98,SAMPLE_MASS
INFO,,SAMPLE_VOLUME
INFO,,SAMPLE_MOLECULAR_WEIGHT
INFO,,SAMPLE_SIZE
INFO,,SAMPLE_SHAPE
DATATYPE,COMMENT,1
DATATYPE,TIME,2
STARTUPAXIS,X,2
STARTUPAXIS,Y1,5
[Data]
Comment,Time Stamp (sec),Temperature (K),Magnetic Field (Oe),Moment (emu),M. Std. Err. (emu),Transport Action,Averaging Time (sec),Frequency (Hz),Peak Amplitude (mm),Center Position (mm),Coil Signal' (mV),Coil Signal" (mV),Range (mV),M. Quad. Signal (emu),M. Raw' (emu),M. Raw" (emu),Min. Temperature (K),Max. Temperature (K),Min. Field (Oe),Max. Field (Oe),Mass (grams),Motor Lag (deg),Pressure (Torr),VSM Status (code),Motor Status (code),Measure Status (code),Measure Count,PPMS Status (code),System Temp. (K),System Field (Oe),Sample Position (deg),Bridge 1 Resistance (ohms),Bridge 1 Excitation (에),Bridge 2 Resistance (ohms),Bridge 2 Excitation (에),Bridge 3 Resistance (ohms),Bridge 3 Excitation (에),Bridge 4 Resistance (ohms),Bridge 4 Excitation (에),Signal 1 Vin (V),Signal 2 Vin (V),Digital Inputs (code),Drive 1 Iout (mA),Drive 1 Ipower (W),Drive 2 Iout (mA),Drive 2 Ipower (W),Pressure (),Map 20 (),Map 21 (),Map 22 (),Map 23 (),Map 24 (),Map 25 (),Map 26 (),Map 27 (),Map 28 (),Map 29 ()
,31931488.59,50.0008316,-0.243580371141434,,,2,,,,21.390000654459,,,,,,,50.0008316,50.0008316,-0.243580371141434,-0.243580371141434,,,18.732843,,,,-99999999,4369,50.0431,-0.243580371141434,,,,,,,,,,,,,,,,,,,,,,,50.0008316,,,,
,31931633.1,50.0019035,4653.27563476562,3.37052653764917E-5,4.4003345156562E-7,1,0.999253354069792,40.0298881530762,1.99296608690539,21.3799998164177,0.000379117936618767,7.24051114508543E-5,0.25,3.49635248955365E-7,3.36904890961184E-5,6.00331825398122E-7,50.0019035,50.0019035,4645.80517578125,4660.74609375,56.3733936924867,20.558426652995,18.353191,0,0,0,40,4449,50.0379,4653.27563476562,,,,,,,,,,,,,0,,,,0,,,,,,50.0019035,,,,
,31931728.665,50.0019875,9427.1416015625,1.87868400397984E-5,3.40488754588733E-7,1,0.999253354069792,40.0298881530762,1.99285380061604,21.3799998164177,0.000212584182515217,3.35365059383972E-5,0.25,-4.10865540946322E-7,1.87875314636824E-5,-2.71059005272404E-7,50.0019875,50.0019875,9392.087890625,9462.1953125,56.0443280858905,20.5621357267098,18.353191,0,0,0,40,4449,50.03535,9427.1416015625,,,,,,,,,,,,,0,,,,0,,,,,,50.0019875,,,,
,31931824.085,50.0010796,14194.8071289062,3.48283531083738E-6,4.89215639102848E-7,1,0.999253354069792,40.0298881530762,1.99306385284962,21.3799998164177,3.9192474725273E-5,7.50543356807657E-6,0.25,3.79329043778381E-8,3.4829959987314E-6,6.38074821990607E-8,50.0010796,50.0010796,14169.83203125,14219.7822265625,56.4257628032752,20.5618507066044,18.353191,0,0,0,40,4449,50.03465,14194.8071289062,,,,,,,,,,,,,0,,,,0.00245,,,,,,50.0010796,,,,
,31931921.125,50.0012741,19047.296875,-1.11752089574933E-5,5.03471602216892E-7,1,0.999253354069792,40.0298881530762,1.99313681289988,21.3799998164177,-0.00012671896485248,-1.89502160042736E-5,0.25,3.33701838535037E-7,-1.11820645323314E-5,2.51060620284999E-7,50.0012741,50.0012741,19042.32421875,19052.26953125,56.7931282073137,20.5642024444783,17.973541,0,0,0,40,4449,50.0343,19047.296875,,,,,,,,,,,,,0,,,,0.0049,,,,,,50.0012741,,,,
,31932015.265,50.0013847,23749.830078125,-2.67777262804228E-5,6.021661314046E-7,1,0.999253354069792,40.0298881530762,1.99306164091346,21.3799998164177,-0.000300980661069158,-6.05533914957808E-5,0.25,-5.42888132613768E-7,-2.6791155103088E-5,-7.40781173759354E-7,50.0013847,50.0013847,23719.80078125,23779.859375,56.4804767996214,20.5648814100836,18.353191,0,0,0,40,4449,50.03225,23749.830078125,,,,,,,,,,,,,0,,,,0.00245,,,,,,50.0013847,,,,
,31932110.555,50.0011826,28515.2822265625,-4.22756536762972E-5,6.94380628305654E-7,1,0.999253354069792,40.0298881530762,1.99299026419103,21.3799998164177,-0.000475434147445561,-9.4792193243944E-5,0.25,-7.85375482781606E-7,-4.23084562969679E-5,-1.09629425946347E-6,50.0011826,50.0011826,28487.669921875,28542.89453125,57.0213637349291,20.5642511777885,17.973541,0,0,0,40,4449,50.03095,28515.2822265625,,,,,,,,,,,,,0,,,,-0.0049,,,,,,50.0011826,,,,
,31932206.895,50.0018997,33330.416015625,-5.81866666837326E-5,9.36850121621379E-7,1,0.999253354069792,40.0298881530762,1.9929882643218,21.3799998164177,-0.000657240293388166,-0.000115508347389254,0.25,2.44545422083579E-7,-5.82566737355692E-5,-1.79280613213377E-7,50.0018692,50.0019302,33300.39453125,33360.4375,56.5305010248521,20.5680392957113,18.353191,0,0,0,40,4449,50.03015,33330.416015625,,,,,,,,,,,,,0,,,,0,,,,,,50.0018997,,,,
,31932302.485,50.0025902,38107.587890625,-7.34700777437731E-5,9.19788094915763E-7,1,0.999253354069792,40.0298881530762,1.99311265802078,21.3799998164177,-0.000828901619886303,-0.000152719575842035,0.25,-3.00109417003922E-7,-7.35726134755938E-5,-8.31888347942564E-7,50.0025902,50.0025902,38072.74609375,38142.4296875,56.8337728903137,20.5672098997229,18.353191,0,0,0,40,4449,50.02895,38107.587890625,,,,,,,,,,,,,0,,,,0.00245,,,,,,50.0025902,,,,
,31932397.1,50.0010262,42837.62890625,-8.99098363745151E-5,9.6510070415882E-7,1,0.999253354069792,40.0298881530762,1.99304049819682,21.3799998164177,-0.00101374652897316,-0.00019161635028219,0.25,-7.87985526778572E-7,-9.00542636891434E-5,-1.4338336991199E-6,50.0010262,50.0010262,42810.0546875,42865.203125,56.831428004756,20.5664417918834,17.973541,0,0,0,40,4449,50.0301,42837.62890625,,,,,,,,,,,,,0,,,,0.0049,,,,,,50.0010262,,,,
,31932489.975,50.001667,47478.392578125,-0.000104188587394613,1.15110770305114E-6,1,0.999253354069792,40.0298881530762,1.99308841375496,21.3799998164177,-0.00117869302433818,-0.000201796770463263,0.25,8.77289587556946E-7,-0.000104392845889274,1.39208995154422E-7,50.001667,50.001667,47443.38671875,47513.3984375,56.6133536478906,20.5669132269423,18.353191,0,0,0,40,4449,50.02825,47478.392578125,,,,,,,,,,,,,0,,,,-0.0049,,,,,,50.001667,,,,
,31932587.165,50.000679,52338.509765625,-0.000121534136760532,1.38369127702412E-6,1,0.999253354069792,40.0298881530762,1.99302712026733,21.3799998164177,-0.00136948572815327,-0.000267244547646177,0.25,-1.80123861516596E-6,-0.000121780982526545,-2.65851972977139E-6,50.000679,50.000679,52336.14453125,52340.875,56.6766655579483,20.5678361027327,18.353191,0,0,0,40,4449,50.02815,52338.509765625,,,,,,,,,,,,,0,,,,0,,,,,,50.000679,,,,
,31932681.93,50.0008621,57073.701171875,-0.000138214972514334,1.12783022750235E-6,1,0.999253354069792,40.0298881530762,1.99307974159502,21.3799998164177,-0.00156163535063147,-0.000282837222596953,0.25,-1.87342560194775E-7,-0.000138539128726444,-1.14717051822319E-6,50.0008621,50.0008621,57043.5234375,57103.87890625,56.3991874336214,20.5678193465577,18.732843,0,0,0,40,4449,50.02665,57073.701171875,,,,,,,,,,,,,0,,,,-0.00245,,,,,,50.0008621,,,,
,31932777.395,50.0019951,61843.755859375,-0.000151833326312702,1.14608326379268E-6,1,0.999253354069792,40.0298881530762,1.9930303896531,21.3799998164177,-0.0017156322879835,-0.000311840515665487,0.25,-3.14301868466438E-7,-0.000152220940490803,-1.35598614771453E-6,50.0019951,50.0019951,61811.06640625,61876.4453125,56.7556100383906,20.5701837472617,18.732843,0,0,0,40,4449,50.0253,61843.755859375,,,,,,,,,,,,,0,,,,0,,,,,,50.0019951,,,,
,31932873.515,50.00234415,66649.21875,-0.00017177732252332,1.40762919655504E-6,1,0.999253354069792,40.0298881530762,1.99308614899553,21.3799998164177,-0.00194698816955744,-0.000321958891307582,0.25,2.36385833711406E-6,-0.000172269487750872,1.20830735884327E-6,50.0021973,50.002491,66619.2265625,66679.2109375,56.6008475915829,20.5662129306625,18.732843,0,0,0,40,4449,50.02425,66649.21875,,,,,,,,,,,,,0,,,,0,,,,,,50.00234415,,,,
,31932968.51,50.0007706,71394.38671875,-0.000189697763908137,1.21775786994318E-6,1,0.999253354069792,40.0298881530762,1.99299354458642,21.3799998164177,-0.0021493878653508,-0.000361352747694682,0.25,2.08400165743517E-6,-0.000190274205200357,8.24295951340179E-7,50.0007706,50.0007706,71366.8359375,71421.9375,56.7876568076791,20.5669317943042,18.732843,0,0,0,40,4449,50.02235,71394.38671875,,,,,,,,,,,,,0,,,,-0.0049,,,,,,50.0007706,,,,
,31933065.985,50.0019875,76270.3125,-0.000208189182512718,1.32960387782911E-6,1,0.999253354069792,40.0298881530762,1.99294596213106,21.3799998164177,-0.00235670113970551,-0.000411107120953593,0.25,9.87817092350752E-7,-0.000208852569041958,-3.78131134692232E-7,50.0019875,50.0019875,76265.375,76275.25,56.8634747740445,20.5672565614046,19.112494,0,0,0,40,4449,50.02225,76270.3125,,,,,,,,,,,,,0,,,,-0.0049,,,,,,50.0019875,,,,
,31933163.98,50.0018959,81166.234375,-0.000222588544446226,1.48362252072417E-6,1,0.999253354069792,40.0298881530762,1.9930040005563,21.3799998164177,-0.00252276129938778,-0.000425477312664118,0.25,2.28509196923362E-6,-0.000223346001842579,8.51047393799527E-7,50.0018959,50.0018959,81138.625,81193.84375,56.8353361473522,20.5677524075894,18.732843,0,0,0,40,4449,50.01955,81166.234375,,,,,,,,,,,,,0,,,,-0.00245,,,,,,50.0018959,,,,
,31933258.14,50.0003395,85874.10546875,-0.000240483513118879,1.38908347150504E-6,1,0.999253354069792,40.0298881530762,1.99295632455429,21.3799998164177,-0.00272432499284167,-0.000468892277981923,0.25,1.63718991996171E-6,-0.000241336278464352,1.08645460039699E-7,50.0003395,50.0003395,85846.59375,85901.6171875,56.6328943608714,20.5711036380831,18.732843,0,0,0,40,4449,50.0192,85874.10546875,,,,,,,,,,,,,0,,,,-0.00245,,,,,,50.0003395,,,,
,31933368.715,49.9993858,89483.8828125,-0.000253447396528162,1.18762904900967E-6,1,0.999253354069792,40.0298881530762,1.99309181535033,21.3799998164177,-0.00287236149717235,-0.000490671071461814,0.25,2.02356974212817E-6,-0.000254378751283693,4.32854264529158E-7,49.9993858,49.9993858,89481.46875,89486.296875,56.8337728903137,20.56849070325,19.112494,0,0,0,40,4449,50.0171,89483.8828125,,,,,,,,,,,,,0,,,,-0.0049,,,,,,49.9993858,,,,
,31933459.055,50.0006218,84969.19921875,-0.000237537585480976,1.50322026171801E-6,1,0.999253354069792,40.0298881530762,1.99310015865573,21.3799998164177,-0.00269170530704113,-0.000459529626689299,0.25,1.94297925702243E-6,-0.000238374564883081,4.29788924050349E-7,50.0006218,50.0006218,84939.1484375,84999.25,56.6985511564868,20.5693541986281,18.353191,0,0,0,40,4449,50.0186,84969.19921875,,,,,,,,,,,,,0,,,,-0.00245,,,,,,50.0006218,,,,
,31933556.1,49.9994736,80117.7109375,-0.000220122518578702,1.13683384246174E-6,1,0.999253354069792,40.0298881530762,1.99316260629469,21.3799998164177,-0.00250080197304253,-0.000387896604389507,0.25,5.17111508505037E-6,-0.000220882152580343,3.75775137828187E-6,49.9994736,49.9994736,80090.21875,80145.203125,56.8462789466214,20.565915342013,18.353191,0,0,0,40,4449,50.01905,80117.7109375,,,,,,,,,,,,,0,,,,-0.0049,,,,,,49.9994736,,,,
,31933652.195,50.0006218,75313.90234375,-0.000199679204485346,1.29943479136088E-6,1,0.999253354069792,40.0298881530762,1.99316931775201,21.3799998164177,-0.00226598939819902,-0.000363876612014444,0.25,3.64372848229273E-6,-0.00020032590419075,2.33810774020472E-6,50.0006218,50.0006218,75281.2734375,75346.53125,56.729816297256,20.5680682869366,19.112494,0,0,0,40,4449,50.01905,75313.90234375,,,,,,,,,,,,,0,,,,0,,,,,,50.0006218,,,,
,31933748.26,50.000721,70513.0078125,-0.000182944858405154,1.08974199972581E-6,1,0.999253354069792,40.0298881530762,1.99320379841374,21.3799998164177,-0.00207635994635897,-0.000329838040930735,0.25,3.66430849948216E-6,-0.000183505330746074,2.45100818081717E-6,50.000721,50.000721,70483.0078125,70543.0078125,56.7946914643522,20.5655204856775,18.732843,0,0,0,40,4449,50.0186,70513.0078125,,,,,,,,,,,,,0,,,,-0.0049,,,,,,50.000721,,,,
,31933841.215,49.9994736,65867.4765625,-0.000166880835315859,1.03067041672756E-6,1,0.999253354069792,40.0298881530762,1.99318828545946,21.3799998164177,-0.00189149416399957,-0.000312927249825048,0.25,2.28660433801909E-6,-0.000167353344097694,1.16133820571242E-6,49.9994736,49.9994736,65845.109375,65889.84375,57.2191157502945,20.5679899633663,18.353191,0,0,0,40,4449,50.0188,65867.4765625,,,,,,,,,,,,,0,,,,-0.00245,,,,,,49.9994736,,,,
,31933936.22,49.99926565,61116.671875,-0.000149895468612728,8.93237275916734E-7,1,0.999253354069792,40.0298881530762,1.99325662852201,21.3799998164177,-0.00169336369292311,-0.000310667562881562,0.25,-5.54451169764128E-7,-0.000150271534156012,-1.58551494136698E-6,49.9992294,49.9993019,61086.6640625,61146.6796875,57.0002597649099,20.5702795998079,18.353191,0,0,0,40,4449,50.0189,61116.671875,,,,,,,,,,,,,0,,,,0,,,,,,49.99926565,,,,
,31934031.785,50.0004387,56341.091796875,-0.000135012321390479,1.07874624002735E-6,1,0.999253354069792,40.0298881530762,1.9932348961396,21.3799998164177,-0.00152086422210311,-0.000302143931949285,0.25,-2.46837615096439E-6,-0.000135308351526241,-3.41306893822129E-6,50.0004387,50.0004387,56338.5703125,56343.61328125,57.0604451608906,20.5692586480568,19.112494,0,0,0,40,4449,50.01785,56341.091796875,,,,,,,,,,,,,0,,,,-0.0049,,,,,,50.0004387,,,,
,31934129.405,49.9998894,51458.953125,-0.000117292647901871,1.04362432876418E-6,1,0.999253354069792,40.0298881530762,1.99319617436099,21.3799998164177,-0.0013250304674461,-0.000239632563464369,0.25,-1.17382616483371E-7,-0.000117537154653614,-9.43052379788685E-7,49.9998894,49.9998894,51456.19921875,51461.70703125,56.9846271945253,20.569637916856,18.353191,0,0,0,40,4449,50.0186,51458.953125,,,,,,,,,,,,,0,,,,-0.0049,,,,,,49.9998894,,,,
,31934223.635,49.99884985,46751.205078125,-0.000102074032038558,8.01384602163141E-7,1,0.999253354069792,40.0298881530762,1.99322612677654,21.3799998164177,-0.00115179649522626,-0.00021442569766655,0.25,-6.19329911571224E-7,-0.000102259816263413,-1.34640810914302E-6,49.9984512,49.9992485,46718.78515625,46783.625,56.9041194570445,20.5723416927146,18.732843,0,0,0,40,4449,50.0199,46751.205078125,,,,,,,,,,,,,0,,,,0,,,,,,49.99884985,,,,
,31934318.44,50.0001526,42013.251953125,-8.55884527744174E-5,7.76352413834737E-7,1,0.999253354069792,40.0298881530762,1.99329138022994,21.3799998164177,-0.000962791665909305,-0.000195222211665477,0.25,-1.88256575744022E-6,-8.57140074569669E-5,-2.5002227006414E-6,50.0001526,50.0001526,41985.859375,42040.64453125,56.9252234270637,20.5714199431125,19.112494,0,0,0,40,4449,50.019,42013.251953125,,,,,,,,,,,,,0,,,,-0.00245,,,,,,50.0001526,,,,
,31934412.71,49.99975585,37300.8984375,-7.06793899302478E-5,5.90781304392742E-7,1,0.999253354069792,40.0298881530762,1.9933103133053,21.3799998164177,-0.000796240914096831,-0.000153678997272251,0.25,-8.86016179615783E-7,-7.07705543265688E-5,-1.39916115247633E-6,49.9997139,49.9997978,37268.234375,37333.5625,57.014329078256,20.5706172999415,18.353191,0,0,0,40,4449,50.01865,37300.8984375,,,,,,,,,,,,,0,,,,-0.00245,,,,,,49.99975585,,,,
,31934506.575,49.9996967,32607.9873046875,-5.47518175687201E-5,8.25830456077354E-7,1,0.999253354069792,40.0298881530762,1.99331846026083,21.3799998164177,-0.000615912309663389,-0.000123152842230551,0.25,-1.04955705311653E-6,-5.48060924786582E-5,-1.45028064103527E-6,49.9996223,49.9997711,32580.89453125,32635.080078125,56.8955215433329,20.5726942597234,18.732843,0,0,0,40,4449,50.01915,32607.9873046875,,,,,,,,,,,,,0,,,,-0.00245,,,,,,49.9996967,,,,
,31934599.955,49.99958035,27943.31640625,-3.92812949377296E-5,5.78039226092623E-7,1,0.999253354069792,40.0298881530762,1.9932781732928,21.3799998164177,-0.000442453684417943,-8.44874071691356E-5,0.25,-4.10519607581555E-7,-3.93127680250666E-5,-6.99335381083609E-7,49.9994659,49.9996948,27913.5546875,27973.078125,56.9564885678329,20.5688577077196,18.732843,0,0,0,40,4449,50.01875,27943.31640625,,,,,,,,,,,,,0,,,,0.00245,,,,,,49.99958035,,,,
,31934693.47,50.0001831,23270.7099609375,-2.3541531714462E-5,5.06801584049641E-7,1,0.999253354069792,40.0298881530762,1.9933258006301,21.3799998164177,-0.000266471798102437,-4.30264949370437E-5,0.25,4.28127548547514E-7,-2.35593074467652E-5,2.54634252850082E-7,50.0001831,50.0001831,23240.703125,23300.716796875,56.6969878994483,20.5714036358273,18.353191,0,0,0,40,4449,50.01785,23270.7099609375,,,,,,,,,,,,,0,,,,0,,,,,,50.0001831,,,,
,31934793.365,50.00017545,18275.716796875,-7.46164331296351E-6,5.76941100426622E-7,1,0.999253354069792,40.0298881530762,1.9934018413282,21.3799998164177,-8.40954581854278E-5,-1.55454583605377E-5,0.25,-3.34995080166164E-8,-7.46397214398178E-6,-8.88106433774815E-8,49.9999313,50.0004196,18243.263671875,18308.169921875,57.0338697912368,20.5728487617867,18.732843,0,0,0,40,4449,50.0183,18275.716796875,,,,,,,,,,,,,0,,,,-0.0049,,,,,,50.00017545,,,,
,31934889.98,49.9988861,13448.5434570312,8.03072822288641E-6,4.58438889586905E-7,1,0.999253354069792,40.0298881530762,1.9933246650604,21.3799998164177,9.00802536969828E-5,1.89557257396908E-5,0.25,2.33618428688966E-7,8.02965418499989E-6,2.93309116765182E-7,49.9988861,49.9988861,13421.052734375,13476.0341796875,57.1370447557753,20.5742907686881,19.112494,0,0,0,40,4449,50.0198,13448.5434570312,,,,,,,,,,,,,0,,,,0.00245,,,,,,49.9988861,,,,
,31934984.55,50.00031665,8720.482421875,2.29959321721564E-5,4.11308981385727E-7,1,0.999253354069792,40.0298881530762,1.99334313172572,21.3799998164177,0.000258340623284665,5.17216699194995E-5,0.25,4.42963077397567E-7,2.29887854296832E-5,6.13978383406015E-7,50.0002022,50.0004311,8688.0498046875,8752.9150390625,56.9549253107945,20.5723603871775,19.112494,0,0,0,40,4449,50.0183,8720.482421875,,,,,,,,,,,,,0,,,,-0.00245,,,,,,50.00031665,,,,
,31935081.1,50.00055885,3894.89038085937,3.7487371591501E-5,3.33331436452127E-7,1,0.999253354069792,40.0298881530762,1.99333557950652,21.3799998164177,0.000422439080734803,7.65330158124473E-5,0.25,3.32771613279673E-8,3.74720598841961E-5,3.12220861035091E-7,50.0005493,50.0005684,3864.94946289063,3924.83129882812,56.9213152844676,20.5746195240191,18.732843,0,0,0,40,4449,50.0191,3894.89038085937,,,,,,,,,,,,,0,,,,0.00245,,,,,,50.00055885,,,,
,31935176.305,50.0007324,-862.157501220703,4.95736210367249E-5,3.13540747708676E-7,1,0.999253354069792,40.0298881530762,1.99331493966246,21.3799998164177,0.000558482942604795,0.00010163586184022,0.25,8.3245317346039E-8,4.95469589540228E-5,4.5198541651464E-7,50.0007324,50.0007324,-892.095886230469,-832.219116210937,57.0612267894099,20.5742383205356,18.732843,0,0,0,40,4449,50.0183,-862.157501220703,,,,,,,,,,,,,0,,,,0,,,,,,50.0007324,,,,
,31935271.78,50.0007534,-5632.7431640625,6.06049958604246E-5,4.02126115346963E-7,1,0.999253354069792,40.0298881530762,1.99351173051754,21.3799998164177,0.0006823557913248,0.000127660572931109,0.25,4.00754565749149E-7,6.05825652844904E-5,8.51631484775621E-7,50.0006561,50.0008507,-5662.64306640625,-5602.84326171875,56.8736359447945,20.5754034565092,18.353191,0,0,0,40,4449,50.019,-5632.7431640625,,,,,,,,,,,,,0,,,,0.0049,,,,,,50.0007534,,,,
,31935367.555,50.00000955,-10420.7421875,6.75474528329608E-5,3.60595494379634E-7,1,0.999253354069792,40.0298881530762,1.99348129368355,21.3799998164177,0.000762370880686455,0.000133013828980403,0.25,-3.78020482411585E-7,6.75449050585701E-5,1.24397951455182E-7,49.9999962,50.0000229,-10450.7861328125,-10390.6982421875,56.9111541137176,20.5748278964653,18.732843,0,0,0,40,4449,50.018,-10420.7421875,,,,,,,,,,,,,0,,,,0.0049,,,,,,50.00000955,,,,
,31935462.745,50.0004711,-15178.3276367188,6.42720853191996E-5,4.18138747481351E-7,1,0.999253354069792,40.0298881530762,1.99349974550646,21.3799998164177,0.000724485980813189,0.000132747810944649,0.25,1.86609379843085E-7,6.42819556516735E-5,6.6384195826661E-7,50.0003929,50.0005493,-15208.53125,-15148.1240234375,57.2120810936214,20.5721750418603,19.112494,0,0,0,40,4449,50.0163,-15178.3276367188,,,,,,,,,,,,,0,,,,-0.00245,,,,,,50.0004711,,,,
,31935557.945,49.9999886,-19936.19921875,5.35541467158478E-5,4.41222630631645E-7,1,0.999253354069792,40.0298881530762,1.99347348222789,21.3799998164177,0.000603292875768772,0.00011357264533443,0.25,4.16894044607067E-7,5.35744375546399E-5,8.13501489153814E-7,49.9999886,49.9999886,-19940.8515625,-19931.546875,57.0112025641791,20.5743760259064,18.732843,0,0,0,40,4449,50.0169,-19936.19921875,,,,,,,,,,,,,0,,,,0,,,,,,49.9999886,,,,
,31935650.69,50.00214005,-24571.0263671875,4.78325307887791E-5,4.67578699347078E-7,1,0.999253354069792,40.0298881530762,1.99351750081612,21.3799998164177,0.000539717862040405,9.74117239247035E-5,0.25,1.45564821203225E-8,4.78655214415684E-5,3.67162385856622E-7,50.0020447,50.0022354,-24603.49609375,-24538.556640625,56.8978664288906,20.5766348910509,18.732843,0,0,0,40,4449,50.01565,-24571.0263671875,,,,,,,,,,,,,0,,,,0.0049,,,,,,50.00214005,,,,
,31935746.305,50.0020905,-29351.15234375,5.30952792985258E-5,6.46700342234984E-7,1,0.999253354069792,40.0298881530762,1.99352067478866,21.3799998164177,0.000600118961190168,0.000103374768119497,0.25,-4.05325421404113E-7,5.31488821808816E-5,-1.64971452618029E-8,50.0020905,50.0020905,-29381.1015625,-29321.203125,57.0198004778906,20.5748696310239,19.112494,0,0,0,40,4449,50.014,-29351.15234375,,,,,,,,,,,,,0,,,,0.00245,,,,,,50.0020905,,,,
,31935841.335,50.0020981,-34101.08984375,6.44076394163596E-5,6.94558531363669E-7,1,0.999253354069792,40.0298881530762,1.99358485265673,21.3799998164177,0.000728709150107463,0.000122535970713233,0.25,-7.45186303900073E-7,6.44909794552084E-5,-2.77131008946976E-7,50.0020981,50.0020981,-34128.7890625,-34073.390625,57.1253203279868,20.5733099649334,18.732843,0,0,0,40,4449,50.01285,-34101.08984375,,,,,,,,,,,,,0,,,,0,,,,,,50.0020981,,,,
,31935936.295,50.0015488,-38845.35546875,7.75831066910948E-5,6.6462944229361E-7,1,0.999253354069792,40.0298881530762,1.99363595654305,21.3799998164177,0.000875780789096406,0.000160061603863684,0.25,2.065892856755E-7,7.76948681443216E-5,7.67330623455235E-7,50.0015488,50.0015488,-38875.31640625,-38815.39453125,56.7845302936022,20.5742590490376,18.732843,0,0,0,40,4449,50.0112,-38845.35546875,,,,,,,,,,,,,0,,,,0,,,,,,50.0015488,,,,
,31936031.105,50.00102235,-43585.14453125,9.21454417259116E-5,7.56216606169136E-7,1,0.999253354069792,40.0298881530762,1.99369476521704,21.3799998164177,0.00104024482271697,0.000191277537521926,0.25,3.50694970087455E-7,9.22998745195363E-5,1.01096971880826E-6,50.0007973,50.0012474,-43617.5546875,-43552.734375,56.9822823089676,20.5741991681124,18.732843,0,0,0,40,4449,50.01145,-43585.14453125,,,,,,,,,,,,,0,,,,0.00245,,,,,,50.00102235,,,,
,31936128.11,49.9995842,-48433.0546875,0.000107598839493904,7.07572438397414E-7,1,0.999253354069792,40.0298881530762,1.99368839576773,21.3799998164177,0.00121517357218962,0.000222382710606469,0.25,3.26684045981542E-7,0.000107805718751309,1.08979528478348E-6,49.9995842,49.9995842,-48440.62890625,-48425.48046875,57.0229269919676,20.5721711097641,19.112494,0,0,0,40,4449,50.0113,-48433.0546875,,,,,,,,,,,,,0,,,,0,,,,,,49.9995842,,,,
,31936222.845,50.0007973,-53167.1875,0.00012361392213951,8.31528312226326E-7,1,0.999253354069792,40.0298881530762,1.99366835447029,21.3799998164177,0.00139487494174498,0.000263704191318461,0.25,1.1075372010953E-6,0.000123874543337706,1.97640793881744E-6,50.0007973,50.0007973,-53172.14453125,-53162.23046875,57.0612267894099,20.5715822380925,19.492144,0,0,0,40,4449,50.0109,-53167.1875,,,,,,,,,,,,,0,,,,0,,,,,,50.0007973,,,,
,31936318.66,50.0017967,-57954.76953125,0.000140279591890732,1.10268953761612E-6,1,0.999253354069792,40.0298881530762,1.99369022864918,21.3799998164177,0.00158625749125131,0.000282855396357849,0.25,-1.88278082681899E-7,0.000140616407885453,7.82965530973054E-7,50.0017967,50.0017967,-57959.8125,-57949.7265625,57.0940551872176,20.5746414811269,18.732843,0,0,0,40,4449,50.0093,-57954.76953125,,,,,,,,,,,,,0,,,,0,,,,,,50.0017967,,,,
,31936416.62,50.0012245,-62850.017578125,0.000157608708823847,8.82360215951034E-7,1,0.999253354069792,40.0298881530762,1.99362532252596,21.3799998164177,0.00178216391285307,0.00031995195776453,0.25,-1.19378290525175E-8,0.000158019872835652,1.06573857754902E-6,50.0012245,50.0012245,-62852.4921875,-62847.54296875,56.9205336559483,20.5758723075744,19.112494,0,0,0,40,4449,50.00895,-62850.017578125,,,,,,,,,,,,,0,,,,-0.0049,,,,,,50.0012245,,,,
,31936512.515,50.0013161,-67642.33984375,0.000173526351598106,9.66380352940216E-7,1,0.999253354069792,40.0298881530762,1.99361245163533,21.3799998164177,0.00196242775812756,0.00035293603211332,0.25,5.59774040548452E-8,0.000174013696418707,1.2269778512645E-6,50.0013161,50.0013161,-67644.8515625,-67639.828125,56.9643048530253,20.5740679928525,19.112494,0,0,0,40,4449,50.006,-67642.33984375,,,,,,,,,,,,,0,,,,0,,,,,,50.0013161,,,,
,31936610.07,50.0010872,-72518.84375,0.00019099001918641,1.00860367344195E-6,1,0.999253354069792,40.0298881530762,1.99365899145046,21.3799998164177,0.00216171141600966,0.00038121666405777,0.25,-5.67397007671476E-7,0.000191568235178032,7.01387685544006E-7,50.0010872,50.0010872,-72521.1640625,-72516.5234375,56.9189703989099,20.5754377136539,19.112494,0,0,0,40,4449,50.0052,-72518.84375,,,,,,,,,,,,,0,,,,-0.0049,,,,,,50.0010872,,,,
,31936706.015,50.0003662,-77313.59765625,0.000208948062630192,1.02295099070768E-6,1,0.999253354069792,40.0298881530762,1.99373082537832,21.3799998164177,0.00236660233722883,0.000410913457656637,0.25,-1.15183623562656E-6,0.000209622692688689,2.14387270790342E-7,50.0003471,50.0003853,-77343.34375,-77283.8515625,57.1518956976407,20.5760240254593,18.732843,0,0,0,40,4449,50.00505,-77313.59765625,,,,,,,,,,,,,0,,,,0.00245,,,,,,50.0003662,,,,
,31936805.31,50.0005054,-82276.0234375,0.000226185719714247,9.1988339055606E-7,1,0.999253354069792,40.0298881530762,1.99373989687414,21.3799998164177,0.00256260495024615,0.000443269911962054,0.25,-1.36738040635527E-6,0.000226957845386339,8.80517346405077E-8,50.0004272,50.0005836,-82306.03125,-82246.015625,56.8673829166406,20.5750516025747,19.112494,0,0,0,40,4449,50.00475,-82276.0234375,,,,,,,,,,,,,0,,,,0.00245,,,,,,50.0005054,,,,
,31936897.19,50.00053595,-86868.01171875,0.000243487939916843,1.35437754403197E-6,1,0.999253354069792,40.0298881530762,1.99376894076136,21.3799998164177,0.00275381830493896,0.000506799460310113,0.25,1.16080062293624E-6,0.000244341291927148,2.71358492852727E-6,50.0002937,50.0007782,-86897.984375,-86838.0390625,57.0823307594291,20.5746138829256,18.732843,0,0,0,40,4449,50.00405,-86868.01171875,,,,,,,,,,,,,0,,,,0,,,,,,50.00053595,,,,
,31937003.445,50.00040055,-88605.078125,0.000248362530528472,1.16125478048904E-6,1,0.999253354069792,40.0298881530762,1.99373984487167,21.3799998164177,0.00281010721487384,0.00051120092104586,0.25,6.83549929118009E-7,0.000249250758621866,2.2567409301743E-6,50.0003357,50.0004654,-88632.59375,-88577.5625,56.343691808756,20.5728346861153,18.732843,0,0,0,40,4449,50.0041,-88605.078125,,,,,,,,,,,,,0,,,,-0.0049,,,,,,50.00040055,,,,
,31937097.435,49.9987526,-83908.296875,0.000231797755313528,1.16773054703052E-6,1,0.999253354069792,40.0298881530762,1.99372007033189,21.3799998164177,0.00262579776814444,0.000457165008003412,0.25,-1.13943664236545E-6,0.000232600736655614,3.45145035895104E-7,49.9987526,49.9987526,-83910.625,-83905.96875,57.220679007333,20.5750349510272,19.112494,0,0,0,40,4449,50.0047,-83908.296875,,,,,,,,,,,,,0,,,,0,,,,,,49.9987526,,,,
,31937194.54,49.9999046,-79053.421875,0.00021562366129448,1.45684558679204E-6,1,0.999253354069792,40.0298881530762,1.99361954898119,21.3799998164177,0.0024429135743467,0.000420281952634159,0.25,-1.51363919190133E-6,0.000216335910096195,-1.12503241978387E-7,49.9999046,49.9999046,-79058.328125,-79048.515625,57.1933220091599,20.5787835222715,18.732843,0,0,0,40,4449,50.0047,-79053.421875,,,,,,,,,,,,,0,,,,0,,,,,,49.9999046,,,,
,31937291.38,49.9992714,-74213.86328125,0.000196557005326313,1.25639949063631E-6,1,0.999253354069792,40.0298881530762,1.99374507317564,21.3799998164177,0.0022234318435264,0.00040088523670043,0.25,1.75364182016314E-7,0.000197160071592253,1.47680704227431E-6,49.9992714,49.9992714,-74241.5,-74186.2265625,57.0846756449868,20.5744340739067,19.492144,0,0,0,40,4449,50.00495,-74213.86328125,,,,,,,,,,,,,0,,,,-0.00245,,,,,,49.9992714,,,,
,31937387.235,49.9997406,-69426.47265625,0.000177710043369622,1.66892626106119E-6,1,0.999253354069792,40.0298881530762,1.99367176945536,21.3799998164177,0.00201213732672453,0.000349265983446922,0.25,-1.01646844317987E-6,0.000178229351804644,1.73538175831857E-7,49.9997406,49.9997406,-69454.0078125,-69398.9375,56.533627538929,20.578024281321,19.112494,0,0,0,40,4449,50.0056,-69426.47265625,,,,,,,,,,,,,0,,,,0.00245,,,,,,49.9997406,,,,
,31937483.105,49.9980812,-64632.0546875,0.000162471710352626,1.05719402613711E-6,1,0.999253354069792,40.0298881530762,1.9937220495418,21.3799998164177,0.00183943345525464,0.000318407231353879,0.25,-1.01996634070534E-6,0.000162914742224864,8.28844006138899E-8,49.9977493,49.9984131,-64662.30078125,-64601.80859375,56.8533136032945,20.5722325862056,19.492144,0,0,0,40,4449,50.0046,-64632.0546875,,,,,,,,,,,,,0,,,,0,,,,,,49.9980812,,,,
,31937579.195,49.999218,-59829.599609375,0.000145555171338293,1.11906025850146E-6,1,0.999253354069792,40.0298881530762,1.99363833250684,21.3799998164177,0.00164677077157939,0.000289267556078437,0.25,-5.65674628299183E-7,0.000145919351601695,4.36307597119631E-7,49.999218,49.999218,-59834.80859375,-59824.390625,57.1010898438907,20.5752306068782,19.112494,0,0,0,40,4449,50.0056,-59829.599609375,,,,,,,,,,,,,0,,,,0.0049,,,,,,49.999218,,,,
,31937674.42,49.9988403,-55071.955078125,0.000127741391314129,9.76810196734643E-7,1,0.999253354069792,40.0298881530762,1.99368060487447,21.3799998164177,0.00144131799891049,0.000274020585830412,0.25,1.28011999524843E-6,0.000128021057531167,2.17431822153697E-6,49.9988403,49.9988403,-55106.91796875,-55036.9921875,57.0362146767945,20.5716037951956,19.492144,0,0,0,40,4449,50.0059,-55071.955078125,,,,,,,,,,,,,0,,,,-0.00245,,,,,,49.9988403,,,,
,31937770.22,50.0003395,-50283.041015625,0.000115200079739168,7.34535535574794E-7,1,0.999253354069792,40.0298881530762,1.99382012342427,21.3799998164177,0.00130301024039032,0.000228150978711572,0.25,-5.29702050085481E-7,0.000115438020990209,2.82209739565935E-7,50.0003395,50.0003395,-50310.765625,-50255.31640625,56.983845566006,20.5731708043315,18.732843,0,0,0,40,4449,50.00645,-50283.041015625,,,,,,,,,,,,,0,,,,-0.00245,,,,,,50.0003395,,,,
,31937865.94,49.9994736,-45500.86328125,9.73708039804772E-5,8.00015296873194E-7,1,0.999253354069792,40.0298881530762,1.99369807724485,21.3799998164177,0.00110007243961633,0.000198078445789013,0.25,1.34977490858147E-8,9.75458286821304E-5,7.0790926984659E-7,49.9994736,49.9994736,-45503.16015625,-45498.56640625,56.9611783389483,20.5752813561203,19.112494,0,0,0,40,4449,50.0066,-45500.86328125,,,,,,,,,,,,,0,,,,0,,,,,,49.9994736,,,,
,31937961.22,49.99956895,-40738.041015625,8.12799882555868E-5,4.67072730566383E-7,1,0.999253354069792,40.0298881530762,1.99376529897969,21.3799998164177,0.000916994982116232,0.000171399816050695,0.25,5.44693164978018E-7,8.14026271310147E-5,1.13067231575224E-6,49.9992752,49.9998627,-40770.67578125,-40705.40625,56.6844818431406,20.5711861394901,18.732843,0,0,0,40,4449,50.0076,-40738.041015625,,,,,,,,,,,,,0,,,,0,,,,,,49.99956895,,,,
,31938056.995,49.9998322,-35952.951171875,6.53580650542839E-5,5.5744896469747E-7,1,0.999253354069792,40.0298881530762,1.99388697521367,21.3799998164177,0.000739199299395882,0.000126825296979367,0.25,-5.37709925695949E-7,6.54473748527056E-5,-6.39191905184866E-8,49.9998322,49.9998322,-35988.16796875,-35917.734375,57.1862873524868,20.5737267238381,19.112494,0,0,0,40,4449,50.0063,-35952.951171875,,,,,,,,,,,,,0,,,,0.00245,,,,,,49.9998322,,,,
,31938151.71,49.9992275,-31218.2724609375,4.94223574059073E-5,5.38244828945578E-7,1,0.999253354069792,40.0298881530762,1.99387135252993,21.3799998164177,0.000558535758819553,9.74635597009452E-5,0.25,-2.6881701025689E-7,4.94763829489959E-5,9.229372359211E-8,49.9989433,49.9995117,-31251.203125,-31185.341796875,57.2214606358522,20.5734470096079,19.492144,0,0,0,40,4449,50.00725,-31218.2724609375,,,,,,,,,,,,,0,,,,0,,,,,,49.9992275,,,,
,31938247.24,49.9987144,-26443.0126953125,3.4180211927018E-5,5.20680366953491E-7,1,0.999253354069792,40.0298881530762,1.9938955794613,21.3799998164177,0.000385718522264344,6.99746120125151E-5,0.25,4.16205944427839E-8,3.42070223404941E-5,2.93108118331698E-7,49.9987144,49.9987144,-26473.212890625,-26412.8125,56.7462304961599,20.5711879566996,19.112494,0,0,0,40,4449,50.00925,-26443.0126953125,,,,,,,,,,,,,0,,,,0.00245,,,,,,49.9987144,,,,
,31938343.83,49.9993629,-21616.0830078125,1.79457168712695E-5,4.65660723325827E-7,1,0.999253354069792,40.0298881530762,1.99388504997411,21.3799998164177,0.000203332647561242,3.1885371763507E-5,0.25,-4.08061711566826E-7,1.79581926762521E-5,-2.75614692985532E-7,49.9993629,49.9993629,-21621.02734375,-21611.138671875,56.526592882256,20.5683927356917,18.732843,0,0,0,40,4449,50.0089,-21616.0830078125,,,,,,,,,,,,,0,,,,-0.0049,,,,,,49.9993629,,,,
,31938440.025,49.9990807,-16808.9990234375,2.86942575733274E-6,4.26516806873575E-7,1,0.999253354069792,40.0298881530762,1.99400981211032,21.3799998164177,3.30075285604792E-5,2.31000888012685E-6,0.25,-3.12383698987569E-7,2.87249696993264E-6,-2.91179720337512E-7,49.9990807,49.9990807,-16833.98046875,-16784.017578125,57.0010413934291,20.568371917759,19.492144,0,0,0,40,4449,50.0109,-16808.9990234375,,,,,,,,,,,,,0,,,,-0.00245,,,,,,49.9990807,,,,
,31938536.33,49.9992027,-11996.4565429688,-1.25007784363934E-5,4.19003328524699E-7,1,0.999253354069792,40.0298881530762,1.99397062572809,21.3799998164177,-0.000139840592090374,-3.17995442144773E-5,0.25,-5.66278343985982E-7,-1.24965903236426E-5,-6.59215214897409E-7,49.9992027,49.9992027,-12026.5986328125,-11966.314453125,56.8533136032945,20.5691347007796,19.492144,0,0,0,40,4449,50.01035,-11996.4565429688,,,,,,,,,,,,,0,,,,0.00245,,,,,,49.9992027,,,,
,31938631.125,50.00058555,-7258.451171875,-2.71723698249919E-5,3.41481159019878E-7,1,0.999253354069792,40.0298881530762,1.993934225322,21.3799998164177,-0.00030547830838283,-6.02636033464334E-5,0.25,-4.46720819007127E-7,-2.71624152185986E-5,-6.48808185529387E-7,50.000412,50.0007591,-7283.36474609375,-7233.53759765625,56.7892200647175,20.570939492146,19.112494,0,0,0,40,4449,50.0101,-7258.451171875,,,,,,,,,,,,,0,,,,0.00245,,,,,,50.00058555,,,,
,31938725.32,49.9992828,-2547.57604980469,-4.17749997371109E-5,3.29958803121233E-7,1,0.999253354069792,40.0298881530762,1.99415317616154,21.3799998164177,-0.000469327346134125,-9.41003934377648E-5,0.25,-8.16368503340087E-7,-4.17495681184361E-5,-1.12681701263421E-6,49.9992828,49.9992828,-2550.181640625,-2544.97045898438,56.8884868866599,20.5644520430788,19.112494,0,0,0,40,4449,50.00985,-2547.57604980469,,,,,,,,,,,,,0,,,,0,,,,,,49.9992828,,,,
,31938820.125,50.000576,2186.78063964844,-5.18807230158217E-5,3.91909400083507E-7,1,0.999253354069792,40.0298881530762,1.99405059464783,21.3799998164177,-0.000583922791265362,-0.000110762614097589,0.25,-4.73311857379558E-7,-5.18523948037581E-5,-8.59089271203936E-7,50.000576,50.000576,2179.29028320313,2194.27099609375,56.9705578811791,20.5692327970342,19.112494,0,0,0,40,4449,50.0101,2186.78063964844,,,,,,,,,,,,,0,,,,-0.00245,,,,,,50.000576,,,,
,31938913.225,49.9989243,6840.4345703125,-6.20388711853713E-5,3.70684641598566E-7,1,0.999253354069792,40.0298881530762,1.99416158554209,21.3799998164177,-0.000698559322800048,-0.000131823433184597,0.25,-5.07334715723835E-7,-6.20186798724852E-5,-9.68859872339549E-7,49.9989243,49.9989243,6807.92724609375,6872.94189453125,56.8243933480829,20.55948875156,19.112494,0,0,0,40,4449,50.01065,6840.4345703125,,,,,,,,,,,,,0,,,,0.00245,,,,,,49.9989243,,,,
,31939007.405,50.00086785,11548.5161132812,-6.7238394742123E-5,4.46646336000235E-7,1,0.999253354069792,40.0298881530762,1.99425839604071,21.3799998164177,-0.000757728301872556,-0.000140673400458886,0.25,-3.51842439035676E-7,-6.72342749221856E-5,-8.51781456178417E-7,50.0006027,50.001133,11520.822265625,11576.2099609375,56.9369478548522,20.5602726614128,19.112494,0,0,0,40,4449,50.0095,11548.5161132812,,,,,,,,,,,,,0,,,,0.00245,,,,,,50.00086785,,,,
,31939102.775,50.0007057,16316.3959960938,-6.16674527665495E-5,5.19949827779286E-7,1,0.999253354069792,40.0298881530762,1.99435944099693,21.3799998164177,-0.000695446083997017,-0.000127473145265018,0.25,-1.83315938554129E-7,-6.16806086601246E-5,-6.40953291733635E-7,50.0007057,50.0007057,16313.876953125,16318.9150390625,57.0127658212176,20.5568264510145,19.112494,0,0,0,40,4449,50.00975,16316.3959960938,,,,,,,,,,,,,0,,,,0,,,,,,50.0007057,,,,
,31939195.97,50.00048445,20974.0322265625,-5.08699854294005E-5,4.33160588023248E-7,1,0.999253354069792,40.0298881530762,1.99437790681264,21.3799998164177,-0.000573948081610002,-0.000104532772819355,0.25,-9.50536310131447E-8,-5.08942966660918E-5,-4.71355956663339E-7,50.0004005,50.0005684,20941.38671875,21006.677734375,57.0831123879483,20.5558612370762,19.492144,0,0,0,40,4449,50.0093,20974.0322265625,,,,,,,,,,,,,0,,,,0.00245,,,,,,50.00048445,,,,
,31939290.55,50.00045775,25698.8125,-4.79678011604774E-5,5.42625960598326E-7,1,0.999253354069792,40.0298881530762,1.99432046499388,21.3799998164177,-0.000541536548039762,-9.7444264865295E-5,0.25,1.03372772641838E-8,-4.80039670355168E-5,-3.42834833374955E-7,50.0004387,50.0004768,25668.8515625,25728.7734375,56.9103724851983,20.5568348840253,19.112494,0,0,0,40,4449,50.0091,25698.8125,,,,,,,,,,,,,0,,,,0,,,,,,50.00045775,,,,
,31939385.53,50.00084685,30447.0361328125,-5.52151874369062E-5,5.44441195209907E-7,1,0.999253354069792,40.0298881530762,1.99418598469264,21.3799998164177,-0.00062285226189356,-0.00011566098801558,0.25,-2.9807182206664E-7,-5.52688624170033E-5,-7.02554982647693E-7,50.0007248,50.0009689,30417.03125,30477.041015625,56.7360693254098,20.5557982824772,18.732843,0,0,0,40,4449,50.00755,30447.0361328125,,,,,,,,,,,,,0,,,,-0.00245,,,,,,50.00084685,,,,
,31939481.67,50.0007324,35252.3984375,-6.6208177702328E-5,5.98597555309205E-7,1,0.999253354069792,40.0298881530762,1.99421481103585,21.3799998164177,-0.000747248973046804,-0.000137681868978523,0.25,-2.68531605310622E-7,-6.62902921179647E-5,-7.5008290839254E-7,50.0007324,50.0007324,35229.64453125,35275.15234375,57.2191157502945,20.5610788955991,19.112494,0,0,0,40,4449,50.007,35252.3984375,,,,,,,,,,,,,0,,,,0,,,,,,50.0007324,,,,
,31939579.61,50.0009613,40147.322265625,-8.05655581007757E-5,7.94974523632312E-7,1,0.999253354069792,40.0298881530762,1.99425625589737,21.3799998164177,-0.000906953077491038,-0.000181969970323362,0.25,-1.60511243876019E-6,-8.06769611229981E-5,-2.18819289994814E-6,50.0009613,50.0009613,40142.328125,40152.31640625,57.058100275333,20.5561001371021,19.112494,0,0,0,40,4449,50.0065,40147.322265625,,,,,,,,,,,,,0,,,,-0.00245,,,,,,50.0009613,,,,
,31939673.48,50.0014114,44838.009765625,-9.67519388535034E-5,8.02379195850159E-7,1,0.999253354069792,40.0298881530762,1.99448628002414,21.3799998164177,-0.00109258147702509,-0.000201751844466909,0.25,-4.42858968678669E-7,-9.69195493316736E-5,-1.13457036356533E-6,50.0014114,50.0014114,44805.21875,44870.80078125,56.5992843345444,20.5519910105557,19.112494,0,0,0,40,4449,50.00535,44838.009765625,,,,,,,,,,,,,0,,,,0.0049,,,,,,50.0014114,,,,
,31939769.695,50.0012474,49647.94921875,-0.000112713025688877,8.11663278501717E-7,1,0.999253354069792,40.0298881530762,1.9940803819455,21.3799998164177,-0.00127262951350502,-0.000236422165503578,0.25,-6.46290184593192E-7,-0.000112934114399022,-1.44418013431266E-6,50.0012474,50.0012474,49642.7265625,49653.171875,56.7141837268714,20.5591493352856,19.112494,0,0,0,40,4449,50.0049,49647.94921875,,,,,,,,,,,,,0,,,,0.0049,,,,,,50.0012474,,,,
,31939866.085,50.0007706,54465.419921875,-0.000128306934089054,1.01599238344711E-6,1,0.999253354069792,40.0298881530762,1.99434710691475,21.3799998164177,-0.00145128956534391,-0.000257681378596633,0.25,2.75039731195258E-7,-0.000128595077753451,-6.20944460089919E-7,50.0007706,50.0007706,54435.4140625,54495.42578125,56.8939582862945,20.5558035133411,19.112494,0,0,0,40,4449,50.0043,54465.419921875,,,,,,,,,,,,,0,,,,-0.00245,,,,,,50.0007706,,,,
,31939961.435,50.0019989,59233.107421875,-0.000143880070633947,1.04727616109497E-6,1,0.999253354069792,40.0298881530762,1.99425600532261,21.3799998164177,-0.00162803536268368,-0.000287248342054016,0.25,4.51738201777771E-7,-0.000144235435957891,-5.40561539765338E-7,50.0019989,50.0019989,59207.83984375,59258.375,56.9392927404099,20.5546762900232,19.112494,0,0,0,40,4449,50.0032,59233.107421875,,,,,,,,,,,,,0,,,,0.00245,,,,,,50.0019989,,,,
,31940057.23,50.0008583,64018.64453125,-0.000160467479785341,1.01191740487418E-6,1,0.999253354069792,40.0298881530762,1.9943497476042,21.3799998164177,-0.00181727741837797,-0.000314361094800205,0.25,1.02736169074318E-6,-0.000160900941004658,-6.37288097131645E-8,50.0008583,50.0008583,63986.1015625,64051.1875,56.4578095725637,20.5525527092977,18.732843,0,0,0,40,4449,50.00275,64018.64453125,,,,,,,,,,,,,0,,,,0,,,,,,50.0008583,,,,
,31940155.34,49.9997787,68923.875,-0.000179034824741405,1.15285985535118E-6,1,0.999253354069792,40.0298881530762,1.99455268141942,21.3799998164177,-0.00202719875659431,-0.000356196773034095,0.25,6.55920661051936E-7,-0.000179551780607802,-5.45824053893811E-7,49.9997787,49.9997787,68918.8828125,68928.8671875,56.6962062709291,20.5453330853395,19.112494,0,0,0,40,4449,50.0021,68923.875,,,,,,,,,,,,,0,,,,0,,,,,,49.9997787,,,,
,31940250.28,50.0014076,73669.15234375,-0.000195080313199848,1.31014959969755E-6,1,0.999253354069792,40.0298881530762,1.99431289563216,21.3799998164177,-0.00220774201878954,-0.000395396030742666,0.25,5.58697429149078E-8,-0.00019567611456317,-1.23726694128864E-6,50.0014076,50.0014076,73646.5234375,73691.78125,56.5617661656214,20.5560111476381,19.492144,0,0,0,40,4449,50.0005,73669.15234375,,,,,,,,,,,,,0,,,,-0.0049,,,,,,50.0014076,,,,
,31940348.915,50.0021973,78599.83203125,-0.000211942253396935,1.21940782301468E-6,1,0.999253354069792,40.0298881530762,1.99440649589321,21.3799998164177,-0.00240096093309265,-0.000419430333450373,0.25,9.44277290424831E-7,-0.000212635091877795,-4.36756792334222E-7,50.0021973,50.0021973,78594.96875,78604.6953125,56.9588334533906,20.551038081155,18.732843,0,0,0,40,4449,49.9991,78599.83203125,,,,,,,,,,,,,0,,,,-0.0049,,,,,,50.0021973,,,,
,31940442.835,49.9995499,83296,-0.00022921659462007,1.34629741783888E-6,1,0.999253354069792,40.0298881530762,1.99461762437485,21.3799998164177,-0.00259749052776755,-0.000452966892112618,0.25,1.0671775909336E-6,-0.000230005195158039,-4.04057434100263E-7,49.9995499,49.9995499,83263.5078125,83328.4921875,56.6164801619675,20.5462027371781,19.492144,0,0,0,40,4449,50.0003,83296,,,,,,,,,,,,,0,,,,0,,,,,,49.9995499,,,,
,31940534.105,50.0005207,87856.33984375,-0.000247965083662228,1.0679572448735E-6,1,0.999253354069792,40.0298881530762,1.99451935857811,21.3799998164177,-0.00280795245398331,-0.000502927679516739,0.25,-4.46912438017179E-9,-0.000248849790773829,-1.57664881200472E-6,50.0002174,50.000824,87826.9453125,87885.734375,56.7610814380252,20.5472772110747,19.112494,0,0,0,40,4449,49.99865,87856.33984375,,,,,,,,,,,,,0,,,,0.0049,,,,,,50.0005207,,,,
,31940644.17,49.9994659,87428.51171875,-0.000244235479652872,1.32020070364458E-6,1,0.999253354069792,40.0298881530762,1.99441613869685,21.3799998164177,-0.00276687509849675,-0.000487892356868705,0.25,6.54747649817952E-7,-0.000245107582607205,-8.93578944457155E-7,49.9994659,49.9994659,87423.3984375,87433.625,56.5414438241214,20.553269501849,19.112494,0,0,0,40,4449,50.0006,87428.51171875,,,,,,,,,,,,,0,,,,-0.0049,,,,,,49.9994659,,,,
,31940735.53,49.9995117,82862.34765625,-0.000226634584899341,1.43788911193703E-6,1,0.999253354069792,40.0298881530762,1.99441089921293,21.3799998164177,-0.00256833999513534,-0.00044557088524236,0.25,1.25525540096867E-6,-0.000227412136443317,-2.00751204336918E-7,49.9995117,49.9995117,82829.7890625,82894.90625,56.8048526351022,20.5534923542126,19.112494,0,0,0,40,4449,50.0012,82862.34765625,,,,,,,,,,,,,0,,,,0,,,,,,49.9995117,,,,
,31940831.095,50.0011368,78085.91796875,-0.000209489782186148,1.28530941342348E-6,1,0.999253354069792,40.0298881530762,1.99428288429862,21.3799998164177,-0.00237572629305097,-0.000399303156947596,0.25,2.28213650019692E-6,-0.000210179470711037,9.1924958445805E-7,50.0011368,50.0011368,78066.03125,78105.8046875,56.973684395256,20.5551164444616,18.732843,0,0,0,40,4449,50.0008,78085.91796875,,,,,,,,,,,,,0,,,,0,,,,,,50.0011368,,,,
,31940928.6,49.9994087,73210.3203125,-0.000192950677416389,9.6249686547312E-7,1,0.999253354069792,40.0298881530762,1.99442447739902,21.3799998164177,-0.00218057895193023,-0.000408597361205899,0.25,-1.48968080492283E-6,-0.000193526317945064,-2.77512058375264E-6,49.9994087,49.9994087,73207.7890625,73212.8515625,56.7220000120637,20.5522013175201,19.492144,0,0,0,40,4449,50.0028,73210.3203125,,,,,,,,,,,,,0,,,,-0.0049,,,,,,49.9994087,,,,
,31941023.365,49.999054,68474.8515625,-0.000177372015187396,1.21051857596048E-6,1,0.999253354069792,40.0298881530762,1.9943743447948,21.3799998164177,-0.00200727001328585,-0.000357827148531608,0.25,2.1166096109945E-7,-0.000177877982643386,-9.81715351296625E-7,49.999054,49.999054,68470.140625,68479.5625,56.8830154870253,20.5529936698442,18.732843,0,0,0,40,4449,50.00285,68474.8515625,,,,,,,,,,,,,0,,,,-0.0049,,,,,,49.999054,,,,
,31941118.86,49.9992561,63701.560546875,-0.000159202206657044,9.40990837295238E-7,1,0.999253354069792,40.0298881530762,1.99437653075271,21.3799998164177,-0.00180081895426834,-0.000323732523475373,0.25,-2.73838195775494E-8,-0.00015962295456616,-1.11359758141535E-6,49.9992561,49.9992561,63671.46875,63731.65234375,56.7290346687368,20.5518929840502,19.112494,0,0,0,40,4449,50.0028,63701.560546875,,,,,,,,,,,,,0,,,,-0.00245,,,,,,49.9992561,,,,
,31941214.1,49.9979172,58940.927734375,-0.000143657267656062,9.55428120251582E-7,1,0.999253354069792,40.0298881530762,1.99438860882788,21.3799998164177,-0.00162650568234002,-0.000281757958323859,0.25,8.99222734106172E-7,-0.000144013313778638,-9.12066258418894E-8,49.9979172,49.9979172,58913.3671875,58968.48828125,56.5305010248521,20.5547108525241,18.732843,0,0,0,40,4449,50.0034,58940.927734375,,,,,,,,,,,,,0,,,,-0.00245,,,,,,49.9979172,,,,
,31941309.845,49.9994583,54152.955078125,-0.00012776394504327,9.29257082186344E-7,1,0.999253354069792,40.0298881530762,1.99424070120384,21.3799998164177,-0.0014444580901788,-0.000259885357764,0.25,-1.83118678457971E-8,-0.000128046976494713,-9.11832148463378E-7,49.9994583,49.9994583,54120.640625,54185.26953125,56.4601544581214,20.5587514317022,19.492144,0,0,0,40,4449,50.0047,54152.955078125,,,,,,,,,,,,,0,,,,0,,,,,,49.9994583,,,,
,31941402.9,50.0005188,49502.68359375,-0.000110822629473784,8.80240728362547E-7,1,0.999253354069792,40.0298881530762,1.99419678079408,21.3799998164177,-0.00125001697664821,-0.00023985961743691,0.25,-1.28911322825957E-6,-0.000111034616972547,-2.07517476991117E-6,50.0005188,50.0005188,49472.63671875,49532.73046875,57.1073428720445,20.5596490386882,19.112494,0,0,0,40,4449,50.0053,49502.68359375,,,,,,,,,,,,,0,,,,0.00245,,,,,,50.0005188,,,,
,31941500.93,49.9999084,44602.66796875,-9.52467755160701E-5,1.02668622475277E-6,1,0.999253354069792,40.0298881530762,1.99433001655228,21.3799998164177,-0.00107684305244201,-0.000191081694244147,0.25,2.29297925945824E-7,-9.54153922387696E-5,-4.50814046638866E-7,49.9999084,49.9999084,44600.0546875,44605.28125,57.0534105042176,20.5581420291837,18.732843,0,0,0,40,4449,50.0046,44602.66796875,,,,,,,,,,,,,0,,,,0.0049,,,,,,49.9999084,,,,
,31941594.68,49.9980488,39916.982421875,-7.83021963071614E-5,7.68460322037159E-7,1,0.999253354069792,40.0298881530762,1.99441352033604,21.3799998164177,-0.000886519506427015,-0.000149146099732988,0.25,8.93896888515329E-7,-7.84272158160639E-5,3.30689750200696E-7,49.9978142,49.9982834,39886.94921875,39947.015625,56.7931282073137,20.5564632813014,19.112494,0,0,0,40,4449,50.00585,39916.982421875,,,,,,,,,,,,,0,,,,-0.00245,,,,,,49.9980488,,,,
,31941690.4,50.0001068,35131.95703125,-6.26760464376435E-5,7.8797381014504E-7,1,0.999253354069792,40.0298881530762,1.99425245176834,21.3799998164177,-0.000708157575728339,-0.000126086681573783,0.25,1.22303544814388E-7,-6.27560915512331E-5,-3.33173701743444E-7,50.0001068,50.0001068,35129.515625,35134.3984375,56.9783741663714,20.5600514000851,18.732843,0,0,0,40,4449,50.0053,35131.95703125,,,,,,,,,,,,,0,,,,0,,,,,,50.0001068,,,,
,31941784.215,50.0000725,30444.7314453125,-4.7539866724385E-5,4.74328318396144E-7,1,0.999253354069792,40.0298881530762,1.99425237450839,21.3799998164177,-0.000537190058091484,-9.45770789721123E-5,0.25,1.86989584822791E-7,-4.75892911889344E-5,-1.60825573821853E-7,50.0000458,50.0000992,30412.404296875,30477.05859375,56.8462789466214,20.5598309280206,19.112494,0,0,0,40,4449,50.00485,30444.7314453125,,,,,,,,,,,,,0,,,,-0.00245,,,,,,50.0000725,,,,
,31941878.83,49.9992027,25714.326171875,-3.19521808472476E-5,4.751996683704E-7,1,0.999253354069792,40.0298881530762,1.99438045358837,21.3799998164177,-0.000361360106650379,-6.14537778749917E-5,0.25,3.13135337303772E-7,-3.19785270401989E-5,7.81117362153425E-8,49.9992027,49.9992027,25684.2578125,25744.39453125,56.9510171681983,20.5572950163705,18.732843,0,0,0,40,4449,50.0058,25714.326171875,,,,,,,,,,,,,0,,,,-0.00245,,,,,,49.9992027,,,,
,31941972.24,49.99811365,21046.7880859375,-1.61580981915703E-5,4.33232515466161E-7,1,0.999253354069792,40.0298881530762,1.9943154979982,21.3799998164177,-0.000182475872193178,-3.2233824778318E-5,0.25,5.56220471501377E-8,-1.61665137863189E-5,-6.38559366194087E-8,49.9980164,49.9982109,21016.828125,21076.748046875,56.9056827140829,20.5609211090276,19.112494,0,0,0,40,4449,50.0078,21046.7880859375,,,,,,,,,,,,,0,,,,0,,,,,,49.99811365,,,,
,31942066.505,50.0005913,16334.8227539062,-1.05881535671229E-6,4.14697812885178E-7,1,0.999253354069792,40.0298881530762,1.99422174898871,21.3799998164177,-1.22145504887502E-5,-6.64387509045748E-7,0.25,1.31940441662396E-7,-1.06004392289974E-6,1.24114774237521E-7,50.0005913,50.0005913,16309.830078125,16359.8154296875,56.9541436822753,20.5638043574478,19.112494,0,0,0,40,4449,50.00715,16334.8227539062,,,,,,,,,,,,,0,,,,0,,,,,,50.0005913,,,,
,31942160.4,49.9988327,11644.8491210938,1.42256353736295E-5,3.56567688202945E-7,1,0.999253354069792,40.0298881530762,1.99416343699953,21.3799998164177,0.000160212165008154,3.02826297194628E-5,0.25,1.20681457385299E-7,1.42244898876324E-5,2.26450290573486E-7,49.9988327,49.9988327,11612.2841796875,11677.4140625,56.8970848003714,20.5626733109609,19.492144,0,0,0,40,4449,50.00875,11644.8491210938,,,,,,,,,,,,,0,,,,-0.0049,,,,,,49.9988327,,,,
,31942253.48,50.0010624,6991.82543945313,2.86315577477395E-5,3.6153730932713E-7,1,0.999253354069792,40.0298881530762,1.99428656733621,21.3799998164177,0.000323088084278077,5.70990606433593E-5,0.25,-9.77417844190381E-8,2.8624891571263E-5,1.15342222987389E-7,50.000824,50.0013008,6964.162109375,7019.48876953125,57.1956668947176,20.5607921055107,19.492144,0,0,0,40,4449,50.0071,6991.82543945313,,,,,,,,,,,,,0,,,,-0.00245,,,,,,50.0010624,,,,
,31942348.68,49.9986229,2231.24426269531,4.24095565938041E-5,3.59631049286323E-7,1,0.999253354069792,40.0298881530762,1.99425689757355,21.3799998164177,0.00047812860120451,8.63523799213918E-5,0.25,1.44913984525383E-8,4.23892372930022E-5,3.3002202897326E-7,49.9986229,49.9986229,2201.22973632813,2261.2587890625,57.1214121853907,20.5607917752753,19.492144,0,0,0,40,4449,50.0093,2231.24426269531,,,,,,,,,,,,,0,,,,0,,,,,,49.9986229,,,,
,31942393.625,49.999588,-0.426265642046928,4.87657255037684E-5,2.92225189955731E-7,1,0.999253354069792,40.0298881530762,1.99428912276846,21.3799998164177,0.00055053232392042,9.49767982850362E-5,0.25,-3.65713433587541E-7,4.8741492732997E-5,-2.77533536571769E-9,49.999588,49.999588,-0.441489428281784,-0.411041855812073,57.4043617093522,20.5614851711453,18.732843,0,0,0,40,4417,50.009,-0.426265642046928,,,,,,,,,,,,,0,,,,-0.0049,,,,,,49.999588,,,,