File: data/monolayers/magneticStructure/ML_Ac_CoFe_C-2/PPMS/data/DD175_23_HYST_100OE_20K.DAT
[Header]
; VSM Data File (default extension .dat)
; Copyright (c) 2003-2013, Quantum Design, Inc. All rights reserved.
TITLE,
FILEOPENTIME,31919392.94,01/05/2019,6:32 pm
BYAPP,VSM,2.0,2.0
INFO,PPMS VSM Option Release 1.4.10 Build 1,APPNAME
INFO,Quantum Design Linear Motor Servo Controller,MOTOR_MODULE_NAME
INFO,3101-100 M1,MOTOR_HW_VERSION
INFO,MMC1014,MOTOR_SERIAL_NUMBER
INFO,SRV No X-over 01.03.11,MOTOR_SOFTWARE_VERSION
INFO,Quantum Design VSM Detection Module,VSM_MODULE_NAME
INFO,3101-150 F0,VSM_HW_VERSION
INFO,VSM707,VSM_SERIAL_NUMBER
INFO,VSM No X-over 01.02.05 May 20 2008 13:51:47,VSM_SOFTWARE_VERSION
INFO,704,PREAMP_SERIAL_NUMBER
INFO,822,COIL_SERIAL_NUMBER
INFO,0,MOMENT_UNITS
INFO,CoFe2O4 Monolayer,SAMPLE_MATERIAL
INFO,from YF45,SAMPLE_COMMENT
INFO,29.98,SAMPLE_MASS
INFO,,SAMPLE_VOLUME
INFO,,SAMPLE_MOLECULAR_WEIGHT
INFO,,SAMPLE_SIZE
INFO,,SAMPLE_SHAPE
DATATYPE,COMMENT,1
DATATYPE,TIME,2
STARTUPAXIS,X,2
STARTUPAXIS,Y1,5
[Data]
Comment,Time Stamp (sec),Temperature (K),Magnetic Field (Oe),Moment (emu),M. Std. Err. (emu),Transport Action,Averaging Time (sec),Frequency (Hz),Peak Amplitude (mm),Center Position (mm),Coil Signal' (mV),Coil Signal" (mV),Range (mV),M. Quad. Signal (emu),M. Raw' (emu),M. Raw" (emu),Min. Temperature (K),Max. Temperature (K),Min. Field (Oe),Max. Field (Oe),Mass (grams),Motor Lag (deg),Pressure (Torr),VSM Status (code),Motor Status (code),Measure Status (code),Measure Count,PPMS Status (code),System Temp. (K),System Field (Oe),Sample Position (deg),Bridge 1 Resistance (ohms),Bridge 1 Excitation (에),Bridge 2 Resistance (ohms),Bridge 2 Excitation (에),Bridge 3 Resistance (ohms),Bridge 3 Excitation (에),Bridge 4 Resistance (ohms),Bridge 4 Excitation (에),Signal 1 Vin (V),Signal 2 Vin (V),Digital Inputs (code),Drive 1 Iout (mA),Drive 1 Ipower (W),Drive 2 Iout (mA),Drive 2 Ipower (W),Pressure (),Map 20 (),Map 21 (),Map 22 (),Map 23 (),Map 24 (),Map 25 (),Map 26 (),Map 27 (),Map 28 (),Map 29 ()
,31919408.42,20.0011654,-0.365370541810989,,,2,,,,21.5399994683266,,,,,,,20.0011654,20.0011654,-0.365370541810989,-0.365370541810989,,,13.417728,,,,-99999999,4369,20.0175,-0.365370541810989,,,,,,,,,,,,,,,,,,,,,,,20.0011654,,,,
,31919555.14,20.0033703,4738.43041992188,3.46707795174951E-5,3.01147242651493E-7,1,0.999253354069792,40.0298881530762,1.99297845421817,21.5300004929304,0.000388632551782046,7.04522319133261E-5,0.25,1.13712873218482E-7,3.44798329802165E-5,2.91062585886549E-7,20.0033703,20.0033703,4735.9365234375,4740.92431640625,56.496109370006,20.5551583547363,12.658426,0,0,0,40,4449,20.0157,4738.43041992188,,,,,,,,,,,,,0,,,,-0.0049,,,,,,20.0033703,,,,
,31919653.875,20.0012512,9672.2451171875,1.82659653874503E-5,3.99356972400208E-7,1,0.999253354069792,40.0298881530762,1.99302229961329,21.5300004929304,0.000204470664300706,3.91300615185674E-5,0.25,2.31504989441035E-7,1.81710721124819E-5,3.30619688728243E-7,20.0011177,20.0013847,9642.296875,9702.193359375,56.1295255944867,20.555152357657,13.417728,0,0,0,40,4449,20.0135,9672.2451171875,,,,,,,,,,,,,0,,,,0,,,,,,20.0012512,,,,
,31919750.45,20.0018024,14497.3120117188,2.38720238476232E-6,3.69889612018998E-7,1,0.999253354069792,40.0298881530762,1.99310443016304,21.5399991720915,2.73247872234089E-5,1.81187614521372E-6,0.25,-2.64983872717876E-7,2.37749373677962E-6,-2.49792713327242E-7,20.0018024,20.0018024,14469.7412109375,14524.8828125,56.2248842738329,20.55569988156,13.038077,0,0,0,40,4449,20.01235,14497.3120117188,,,,,,,,,,,,,0,,,,0,,,,,,20.0018024,,,,
,31919847.265,20.0028343,19339.71484375,-1.35273226033126E-5,4.55527620748644E-7,1,0.999253354069792,40.0298881530762,1.99332222725343,21.5300004929304,-0.000151112590568589,-3.16087937373362E-5,0.25,-3.93910073670825E-7,-1.3467203619744E-5,-4.75688193655804E-7,20.0028343,20.0028343,19337.482421875,19341.947265625,56.8283014906791,20.5550722828758,13.417728,0,0,0,40,4449,20.01105,19339.71484375,,,,,,,,,,,,,0,,,,0,,,,,,20.0028343,,,,
,31919943.02,20.0028095,24124.681640625,-2.98541316339017E-5,4.1777678303768E-7,1,0.999253354069792,40.0298881530762,1.99312455521876,21.5300004929304,-0.000333614758245665,-6.98296477868411E-5,0.25,-8.64564498264136E-7,-2.97353572663123E-5,-1.05426010501814E-6,20.0028095,20.0028095,24124.681640625,24124.681640625,56.7485753817175,20.5603945897553,13.417728,0,0,0,40,4449,20.009,24124.681640625,,,,,,,,,,,,,0,,,,0,,,,,,20.0028095,,,,
,31920046.065,20.0006809,29274.9921875,-4.69612325354298E-5,4.68161492044208E-7,1,0.999253354069792,40.0298881530762,1.99316543178813,21.5300004929304,-0.000526649990124888,-0.000101104512544361,0.25,-5.64245537217366E-7,-4.68042922388554E-5,-8.78881690450589E-7,20.0006809,20.0006809,29272.384765625,29277.599609375,56.7939098358329,20.5584825656234,13.038077,0,0,0,40,4449,20.006,29274.9921875,,,,,,,,,,,,,0,,,,0,,,,,,20.0006809,,,,
,31920143.285,20.00143525,34132.603515625,-6.44107081272958E-5,6.32370192046401E-7,1,0.999253354069792,40.0298881530762,1.9933535026135,21.5300004929304,-0.000722146550538853,-0.000142241400815421,0.25,-1.07009864779435E-6,-6.42261570353325E-5,-1.51519676451054E-6,20.0013542,20.0015163,34105.1953125,34160.01171875,56.9213152844676,20.5581623062676,13.038077,0,0,0,40,4449,20.0052,34132.603515625,,,,,,,,,,,,,0,,,,0,,,,,,20.00143525,,,,
,31920239.455,20.0023232,38939.76953125,-8.01046324093974E-5,5.95379670937351E-7,1,0.999253354069792,40.0298881530762,1.99341928724483,21.5300004929304,-0.000899309069165852,-0.00017297426217951,0.25,-9.59881599264847E-7,-7.99182976039064E-5,-1.52880158722921E-6,20.0023232,20.0023232,38912.1875,38967.3515625,56.6024108486214,20.5572811820448,13.038077,0,0,0,40,4449,20.00395,38939.76953125,,,,,,,,,,,,,0,,,,0.00245,,,,,,20.0023232,,,,
,31920336.29,20.0006332,43779.798828125,-9.70964579371973E-5,7.13632430952923E-7,1,0.999253354069792,40.0298881530762,1.9935911104888,21.5300004929304,-0.00109203295612871,-0.000202476268800995,0.25,-5.01211928188822E-7,-9.69246694370083E-5,-1.20550156241877E-6,20.0006332,20.0006332,43749.83203125,43809.765625,57.2238055214099,20.5560183531501,13.797379,0,0,0,40,4449,20.00295,43779.798828125,,,,,,,,,,,,,0,,,,0,,,,,,20.0006332,,,,
,31920434.56,20.0020657,48690.35546875,-0.000113708733181251,6.39161483880954E-7,1,0.999253354069792,40.0298881530762,1.99350399197692,21.5300004929304,-0.00127841733943238,-0.000243048785330486,0.25,-1.09327733853996E-6,-0.000113561442284602,-1.92861142802666E-6,20.0020657,20.0020657,48688.015625,48692.6953125,56.8079791491791,20.5551862581618,13.417728,0,0,0,40,4449,20.0036,48690.35546875,,,,,,,,,,,,,0,,,,0,,,,,,20.0020657,,,,
,31920533.63,20.0011635,53642.931640625,-0.000131369525085871,8.33112986938216E-7,1,0.999253354069792,40.0298881530762,1.99342397519059,21.5300004929304,-0.00147683369397333,-0.000285483443371804,0.25,-1.66018210058274E-6,-0.000131261684489423,-2.6333406921596E-6,20.0011635,20.0011635,53640.33203125,53645.53125,56.6962062709291,20.5572013751306,13.038077,0,0,0,40,4449,20.0022,53642.931640625,,,,,,,,,,,,,0,,,,0,,,,,,20.0011635,,,,
,31920628.255,20.0009403,58373.22265625,-0.000146911352108541,8.20836507504572E-7,1,0.999253354069792,40.0298881530762,1.99340509036444,21.5300004929304,-0.00165412884789891,-0.000309227460626588,0.25,-9.5093642662943E-7,-0.000146864810518356,-2.04392468748589E-6,20.0009403,20.0009403,58348.26171875,58398.18359375,56.9557069393137,20.5567297760232,13.417728,0,0,0,40,4449,20.00145,58373.22265625,,,,,,,,,,,,,0,,,,0.00245,,,,,,20.0009403,,,,
,31920723.015,20.000824,63108.919921875,-0.000162275016061559,5.51167218635281E-7,1,0.999253354069792,40.0298881530762,1.99335560854874,21.5300004929304,-0.00182860230831568,-0.000337676319247513,0.25,-6.93893691824838E-7,-0.000162297733223711,-1.90108644364826E-6,20.000824,20.000824,63076.39453125,63141.4453125,57.047939104583,20.5573088932135,13.797379,0,0,0,40,4449,20.0006,63108.919921875,,,,,,,,,,,,,0,,,,0,,,,,,20.000824,,,,
,31920816.665,20.0024357,67789.05859375,-0.000179933798928115,7.75680149399312E-7,1,0.999253354069792,40.0298881530762,1.99332214648956,21.5300004929304,-0.00202620666008582,-0.000386744471000798,0.25,-1.85375676293264E-6,-0.000180025712256078,-3.18844218535652E-6,20.0024281,20.0024433,67764.1328125,67813.984375,56.966649738583,20.5593109343137,13.417728,0,0,0,40,4449,20,67789.05859375,,,,,,,,,,,,,0,,,,0.00245,,,,,,20.0024357,,,,
,31920911.94,20.0017834,72551.84375,-0.000196877508033878,7.36450453156322E-7,1,0.999253354069792,40.0298881530762,1.9933939495128,21.5300004929304,-0.00221909665990689,-0.000417111375882557,0.25,-1.48591108313829E-6,-0.000197061201547813,-2.93705398771713E-6,20.0017815,20.0017853,72521.9453125,72581.7421875,56.8087607776983,20.5569980697247,13.038077,0,0,0,40,4449,19.9969,72551.84375,,,,,,,,,,,,,0,,,,-0.00245,,,,,,20.0017834,,,,
,31921013.365,20.00254535,77622.44140625,-0.000216060834121281,8.65957804887687E-7,1,0.999253354069792,40.0298881530762,1.99339059369124,21.5300004929304,-0.00243643349878108,-0.000457185679831034,0.25,-1.58007644399379E-6,-0.000216350053089998,-3.15785437508857E-6,20.0025253,20.0025654,77599.8515625,77645.03125,56.435142345506,20.5561651281154,13.038077,0,0,0,40,4449,19.9959,77622.44140625,,,,,,,,,,,,,0,,,,0,,,,,,20.00254535,,,,
,31921109.415,20.0019293,82423.375,-0.00023309691848863,7.59362020301809E-7,1,0.999253354069792,40.0298881530762,1.99337533017531,21.5300004929304,-0.00262934055025912,-0.000494103660772243,0.25,-1.78617771305601E-6,-0.000233492176288797,-3.46982200123407E-6,20.0019169,20.0019417,82398.25,82448.5,56.1459397933906,20.5572006012747,13.797379,0,0,0,40,4449,19.9945,82423.375,,,,,,,,,,,,,0,,,,-0.0049,,,,,,20.0019293,,,,
,31921200.635,20.0021572,86981.4765625,-0.000248706438889498,7.03869696557091E-7,1,0.999253354069792,40.0298881530762,1.99328407549448,21.5300004929304,-0.0028065058016316,-0.000525591391263228,0.25,-1.7741742985913E-6,-0.000249209002006883,-3.54851800665961E-6,20.0021572,20.0021572,86951.53125,87011.421875,56.4226362891983,20.5581495463009,13.797379,0,0,0,40,4449,19.99315,86981.4765625,,,,,,,,,,,,,0,,,,0,,,,,,20.0021572,,,,
,31921306.09,20.000412,88542.71484375,-0.000256406040613218,6.39881901121953E-7,1,0.999253354069792,40.0298881530762,1.9934503518421,21.5300004929304,-0.00289398676895752,-0.000541624917779044,0.25,-1.80780949139463E-6,-0.00025695138890999,-3.62877054711276E-6,20.000412,20.000412,88517.4453125,88567.984375,56.7259081546598,20.5564907526451,13.797379,0,0,0,40,4449,19.99245,88542.71484375,,,,,,,,,,,,,0,,,,0,,,,,,20.000412,,,,
,31921394.495,19.9999237,84124.11328125,-0.000240586734786429,7.25212995699006E-7,1,0.999253354069792,40.0298881530762,1.99338706373951,21.5300004929304,-0.0027161296099064,-0.000499163976854925,0.25,-8.88392608198806E-7,-0.00024103093379965,-2.61677587515898E-6,19.9999237,19.9999237,84094.1015625,84154.125,56.8501870892175,20.5558848065477,13.797379,0,0,0,40,4449,19.99185,84124.11328125,,,,,,,,,,,,,0,,,,0,,,,,,19.9999237,,,,
,31921489.085,19.9998598,79392.734375,-0.000222555781696436,7.29249090321784E-7,1,0.999253354069792,40.0298881530762,1.99343386027393,21.5300004929304,-0.00250708769238676,-0.000487536132607146,0.25,-3.09826471571677E-6,-0.000222873092527355,-4.71950091276412E-6,19.9998474,19.9998722,79360.1015625,79425.3671875,56.8697278021983,20.5568953887147,13.038077,0,0,0,40,4449,19.9926,79392.734375,,,,,,,,,,,,,0,,,,0.0049,,,,,,19.9998598,,,,
,31921584.535,19.99996565,74621.5703125,-0.000204357940051099,7.82301634033302E-7,1,0.999253354069792,40.0298881530762,1.99353038309313,21.5300004929304,-0.00230401699838744,-0.000432679002160251,0.25,-1.51429010220673E-6,-0.000204583113759658,-3.01533036372673E-6,19.9998531,20.0000782,74591.6171875,74651.5234375,56.9103724851983,20.5571796592159,13.797379,0,0,0,40,4449,19.9923,74621.5703125,,,,,,,,,,,,,0,,,,0.00245,,,,,,19.99996565,,,,
,31921681.61,19.99922945,69770.75390625,-0.00018875587676594,7.9253920975457E-7,1,0.999253354069792,40.0298881530762,1.99342972749202,21.5300004929304,-0.00212734007145206,-0.000398474431904519,0.25,-1.29938537463046E-6,-0.000188889123754475,-2.69601063944044E-6,19.9989586,19.9995003,69743.4609375,69798.046875,57.1479875550445,20.5598180534395,13.797379,0,0,0,40,4449,19.99445,69770.75390625,,,,,,,,,,,,,0,,,,0,,,,,,19.99922945,,,,
,31921777.02,19.9988632,65002.8515625,-0.000170395755997121,6.3194077897143E-7,1,0.999253354069792,40.0298881530762,1.99351214046873,21.5300004929304,-0.0019179275863875,-0.000369391489855723,0.25,-2.03606100322023E-6,-0.000170438954314051,-3.3028404317022E-6,19.9988632,19.9988632,64970.20703125,65035.49609375,56.5000175126021,20.5573525037987,13.797379,0,0,0,40,4449,19.99535,65002.8515625,,,,,,,,,,,,,0,,,,0,,,,,,19.9988632,,,,
,31921871.855,19.9991188,60259.9296875,-0.000153415880260472,8.11741941093334E-7,1,0.999253354069792,40.0298881530762,1.99351565008176,21.5300004929304,-0.00172890818705722,-0.000316647311733745,0.25,-4.30139313240547E-7,-0.00015339873838802,-1.57203836436164E-6,19.9991188,19.9991188,60227.41796875,60292.44140625,56.6008475915829,20.5579532095669,13.797379,0,0,0,40,4449,19.9967,60259.9296875,,,,,,,,,,,,,0,,,,0,,,,,,19.9991188,,,,
,31921965.18,19.9986534,55596.53125,-0.000137294037783765,5.66308821553765E-7,1,0.999253354069792,40.0298881530762,1.99347063906355,21.5300004929304,-0.00154502301976499,-0.000291448823201872,0.25,-1.1146215631528E-6,-0.000137212205048225,-2.13421246840674E-6,19.9982719,19.9990349,55563.953125,55629.109375,56.8376810329099,20.5573332822573,13.417728,0,0,0,40,4449,19.9973,55596.53125,,,,,,,,,,,,,0,,,,0.00245,,,,,,19.9986534,,,,
,31922062.75,19.9985275,50721.7265625,-0.000120761947080365,6.41650846329759E-7,1,0.999253354069792,40.0298881530762,1.99350910605523,21.5300004929304,-0.00135941934993944,-0.000250297474743725,0.25,-4.58195037899851E-7,-0.000120635544680149,-1.34974334218124E-6,19.9985275,19.9985275,50716.41796875,50727.03515625,56.8814522299868,20.557617572102,14.177031,0,0,0,40,4449,19.99745,50721.7265625,,,,,,,,,,,,,0,,,,0,,,,,,19.9985275,,,,
,31922162.52,19.9989452,45731.49609375,-0.000103277151579985,5.7058127153047E-7,1,0.999253354069792,40.0298881530762,1.99333440597274,21.5300004929304,-0.00116043637176937,-0.000222064017252492,0.25,-1.12236525436874E-6,-0.000103111054990053,-1.87509515642931E-6,19.9989452,19.9989452,45703.97265625,45759.01953125,57.474708276083,20.5603187357512,13.797379,0,0,0,40,4449,19.9974,45731.49609375,,,,,,,,,,,,,0,,,,0,,,,,,19.9989452,,,,
,31922256.595,19.99911975,41028.552734375,-8.65963830688822E-5,5.33160024140413E-7,1,0.999253354069792,40.0298881530762,1.9934076741117,21.5300004929304,-0.000973056274907142,-0.000183380420848435,0.25,-7.07855249842912E-7,-8.64163358524823E-5,-1.32918582984991E-6,19.9988575,19.999382,41001.2109375,41055.89453125,57.1018714724099,20.559025662974,13.417728,0,0,0,40,4449,19.9983,41028.552734375,,,,,,,,,,,,,0,,,,-0.00245,,,,,,19.99911975,,,,
,31922351.35,19.99929145,36293.984375,-7.04499308919992E-5,5.38899029144632E-7,1,0.999253354069792,40.0298881530762,1.99357940443368,21.5300004929304,-0.000791946654637108,-0.000145484836861378,0.25,-2.62755561323973E-7,-7.02704874149808E-5,-7.57981654243195E-7,19.999218,19.9993649,36264.0234375,36323.9453125,56.8751992018329,20.5561262203508,13.797379,0,0,0,40,4449,20.0001,36293.984375,,,,,,,,,,,,,0,,,,-0.00245,,,,,,19.99929145,,,,
,31922444.835,19.9983768,31621.48046875,-5.42671223270756E-5,4.79498680939482E-7,1,0.999253354069792,40.0298881530762,1.99346198413553,21.5399991720915,-0.000609905725115908,-0.000110828926474741,0.25,-1.080079739923E-7,-5.41027750135981E-5,-4.79363797670897E-7,19.9983768,19.9983768,31591.466796875,31651.494140625,56.6594697305252,20.5592068416927,14.177031,0,0,0,40,4449,20.0014,31621.48046875,,,,,,,,,,,,,0,,,,0,,,,,,19.9983768,,,,
,31922540.83,19.9985046,26826.3662109375,-3.80829131953587E-5,4.39715687961204E-7,1,0.999253354069792,40.0298881530762,1.99359043433962,21.5300004929304,-0.000426757976108575,-8.36786863892981E-5,0.25,-6.12917806047623E-7,-3.79449886525807E-5,-8.62638338312333E-7,19.9985046,19.9985046,26823.787109375,26828.9453125,56.5281561392944,20.5573813238589,13.417728,0,0,0,40,4449,20.0022,26826.3662109375,,,,,,,,,,,,,0,,,,0.0049,,,,,,19.9985046,,,,
,31922634.855,19.99839685,22125.6533203125,-2.24768374537731E-5,4.68180090786965E-7,1,0.999253354069792,40.0298881530762,1.99362909523155,21.5300004929304,-0.000251908725443479,-4.85393539625404E-5,0.25,-2.94225747612852E-7,-2.23852450559995E-5,-4.35669278094598E-7,19.9983425,19.9984512,22100.701171875,22150.60546875,57.1026531009291,20.5626654638391,13.797379,0,0,0,40,4449,20.0046,22125.6533203125,,,,,,,,,,,,,0,,,,-0.00245,,,,,,19.99839685,,,,
,31922726.865,19.998332,17526.025390625,-6.89717546793822E-6,3.91865362635966E-7,1,0.999253354069792,40.0298881530762,1.99341933526497,21.5300004929304,-7.7355433641776E-5,-1.43405295465403E-5,0.25,-4.36885171906435E-8,-6.86630590689848E-6,-8.52183006243044E-8,19.9981861,19.9984779,17493.515625,17558.53515625,57.2073913225061,20.5627387461864,13.797379,0,0,0,40,4449,20.0047,17526.025390625,,,,,,,,,,,,,0,,,,0,,,,,,19.998332,,,,
,31922821.01,19.9974976,12820.8149414062,9.23608234353266E-6,3.56379500434747E-7,1,0.999253354069792,40.0298881530762,1.99347009727821,21.5300004929304,0.000103579899580184,1.90045967687142E-5,0.25,4.44961863929746E-8,9.19091424443089E-6,9.71142391780393E-8,19.9973946,19.9976006,12795.896484375,12845.7333984375,56.536754053006,20.5634868713893,13.797379,0,0,0,40,4449,20.00725,12820.8149414062,,,,,,,,,,,,,0,,,,0,,,,,,19.9974976,,,,
,31922913.57,19.9989929,8195.5078125,2.4611361756721E-5,3.48708515324529E-7,1,0.999253354069792,40.0298881530762,1.9935841032037,21.5300004929304,0.000276331315741805,4.83108252168927E-5,0.25,-7.93564458077832E-8,2.44827884633895E-5,5.35348028728009E-8,19.9989929,19.9989929,8168.1201171875,8222.8955078125,56.7102755842752,20.559579170478,13.417728,0,0,0,40,4449,20.00835,8195.5078125,,,,,,,,,,,,,0,,,,0,,,,,,19.9989929,,,,
,31923007.835,19.9994345,3480.15380859375,3.98219109390859E-5,3.04381344882435E-7,1,0.999253354069792,40.0298881530762,1.99346353923239,21.5300004929304,0.000446768238565929,7.90846645463862E-5,0.25,-3.05811510242968E-8,3.96001766174164E-5,1.70544265453899E-7,19.999136,19.999733,3445.20751953125,3515.10009765625,56.7493570102368,20.5648182730033,13.797379,0,0,0,40,4449,20.0086,3480.15380859375,,,,,,,,,,,,,0,,,,-0.00245,,,,,,19.9994345,,,,
,31923102.015,20.0005541,-1223.6611328125,5.14673249229821E-5,3.04944471986291E-7,1,0.999253354069792,40.0298881530762,1.99361802755595,21.5300004929304,0.000577159251267694,0.000103493768165671,0.25,8.257741413206E-8,5.11735641163361E-5,3.34509194647639E-7,20.0002575,20.0008507,-1256.05615234375,-1191.26611328125,57.0878021590637,20.5617492472811,13.797379,0,0,0,40,4449,20.0068,-1223.6611328125,,,,,,,,,,,,,0,,,,0,,,,,,20.0005541,,,,
,31923198.25,19.9998455,-6030.44750976563,6.53990128527332E-5,3.62949280044198E-7,1,0.999253354069792,40.0298881530762,1.99355622020438,21.5300004929304,0.000732929131685909,0.000135254926223928,0.25,4.14654974509503E-7,6.5043588088176E-5,7.54131994859779E-7,19.9998455,19.9998455,-6033.19775390625,-6027.697265625,57.1135959001984,20.5622326273952,13.797379,0,0,0,40,4449,20.0088,-6030.44750976563,,,,,,,,,,,,,0,,,,0.0049,,,,,,19.9998455,,,,
,31923290.735,20.0000725,-10655.849609375,7.61374910608659E-5,3.68525511722596E-7,1,0.999253354069792,40.0298881530762,1.99358678610482,21.5300004929304,0.000854684738825471,0.000151402166730656,0.25,-8.82955468184107E-8,7.57538177570752E-5,3.35714139646196E-7,20.0000725,20.0000725,-10686.0673828125,-10625.6318359375,57.3480844559676,20.564515783348,14.177031,0,0,0,40,4449,20.00815,-10655.849609375,,,,,,,,,,,,,0,,,,0,,,,,,20.0000725,,,,
,31923385.065,20.00070765,-15366.28125,8.05722244564774E-5,3.66217935159582E-7,1,0.999253354069792,40.0298881530762,1.99363256757127,21.5300004929304,0.000904232450929341,0.000163805406123021,0.25,1.92451838550384E-7,8.01974744677112E-5,6.67027727974607E-7,20.0006752,20.0007401,-15393.8916015625,-15338.6708984375,57.2089545795445,20.5621999108049,13.797379,0,0,0,40,4449,20.0064,-15366.28125,,,,,,,,,,,,,0,,,,0,,,,,,20.00070765,,,,
,31923479.455,20.0028286,-20086.240234375,7.54783437705563E-5,3.9177121710041E-7,1,0.999253354069792,40.0298881530762,1.99377270873344,21.5300004929304,0.00084760051335597,0.00015297761796373,0.25,1.07456373172457E-7,7.51612350824887E-5,5.76305206468606E-7,20.0028286,20.0028286,-20116.341796875,-20056.138671875,56.9306948266983,20.5611337397472,13.797379,0,0,0,40,4449,20.00505,-20086.240234375,,,,,,,,,,,,,0,,,,0.0049,,,,,,20.0028286,,,,
,31923573.54,20.0016546,-24790.58203125,6.73745867893555E-5,4.40259245290551E-7,1,0.999253354069792,40.0298881530762,1.99365048841526,21.5300004929304,0.000757087361084401,0.000135623017121132,0.25,-1.09054906502122E-8,6.71237660187322E-5,4.27200212221822E-7,20.0015411,20.0017681,-24823.291015625,-24757.873046875,57.2081729510253,20.5636313526641,14.177031,0,0,0,40,4449,20.0033,-24790.58203125,,,,,,,,,,,,,0,,,,0,,,,,,20.0016546,,,,
,31923667.645,20.00187875,-29493.40234375,6.67322054476143E-5,4.58110310679173E-7,1,0.999253354069792,40.0298881530762,1.99364388081326,21.5300004929304,0.000750772363293156,0.000131393354687042,0.25,-2.94207229293526E-7,6.65180991589235E-5,1.57168820965415E-7,20.0018692,20.0018883,-29525.9140625,-29460.890625,56.7853119221214,20.5633787598195,13.797379,0,0,0,40,4449,20.00175,-29493.40234375,,,,,,,,,,,,,0,,,,-0.00245,,,,,,20.00187875,,,,
,31923763.39,20.00210285,-34275.951171875,7.34136050666065E-5,4.09025046388837E-7,1,0.999253354069792,40.0298881530762,1.99409908097475,21.5300004929304,0.00082678829836314,0.000143278180975612,0.25,-4.61294432110751E-7,7.32160614353059E-5,5.10520857941548E-8,20.0020485,20.0021572,-34303.29296875,-34248.609375,57.180034324333,20.5603964730912,14.177031,0,0,0,40,4449,20.0003,-34275.951171875,,,,,,,,,,,,,0,,,,0,,,,,,20.00210285,,,,
,31923859.035,20.0013847,-39055.220703125,8.54658362935683E-5,4.73635764999423E-7,1,0.999253354069792,40.0298881530762,1.99386625960595,21.5300004929304,0.000961888302279168,0.00017251319810036,0.25,-4.95849288334965E-8,8.52757219724496E-5,5.60126921752949E-7,20.0013847,20.0013847,-39085.265625,-39025.17578125,56.7524835243137,20.5611607646594,13.797379,0,0,0,40,4449,19.99895,-39055.220703125,,,,,,,,,,,,,0,,,,-0.00245,,,,,,20.0013847,,,,
,31923956.5,20.0006218,-43924.9453125,0.000100404339984691,4.71136982106531E-7,1,0.999253354069792,40.0298881530762,1.99383804591011,21.5300004929304,0.00112940231257274,0.000209316668876464,0.25,5.10366979479828E-7,0.00010022826814786,1.23901006078146E-6,20.0006218,20.0006218,-43927.7734375,-43922.1171875,57.0596635323714,20.5625789684862,13.797379,0,0,0,40,4449,19.9977,-43924.9453125,,,,,,,,,,,,,0,,,,-0.00245,,,,,,20.0006218,,,,
,31924051.5,20.00176525,-48675.365234375,0.00011529502923905,5.7074971294793E-7,1,0.999253354069792,40.0298881530762,1.9939174515839,21.5300004929304,0.00130007012959388,0.000226708781285799,0.25,-6.47298075327122E-7,0.000115158417234672,2.01812170742859E-7,20.0017624,20.0017681,-48700.26953125,-48650.4609375,57.2198973788137,20.5613663083171,13.797379,0,0,0,40,4449,19.9975,-48675.365234375,,,,,,,,,,,,,0,,,,0.00245,,,,,,20.00176525,,,,
,31924146.74,20.00036145,-53437.26171875,0.000131179811950408,6.08899173026259E-7,1,0.999253354069792,40.0298881530762,1.99385036519822,21.5300004929304,0.00147962840175144,0.000259287529923808,0.25,-6.3455471016472E-7,0.00013108645404238,3.38648644124938E-7,20.0001736,20.0005493,-53462.67578125,-53411.84765625,56.9963516223137,20.5640102817984,14.177031,0,0,0,40,4449,19.997,-53437.26171875,,,,,,,,,,,,,0,,,,-0.00245,,,,,,20.00036145,,,,
,31924242.625,20.000474,-58227.556640625,0.000148168893399039,5.76052604638722E-7,1,0.999253354069792,40.0298881530762,1.99376428263446,21.5300004929304,0.00167099090674995,0.000298391722615334,0.25,-2.41141700848494E-7,0.000148128825781502,8.61479678067738E-7,20.0001965,20.0007515,-58260.0546875,-58195.05859375,56.7642079521022,20.5647407678817,14.177031,0,0,0,40,4449,19.99735,-58227.556640625,,,,,,,,,,,,,0,,,,-0.00245,,,,,,20.000474,,,,
,31924341.07,20.0011206,-63148.00390625,0.000166016267990904,8.38919514989289E-7,1,0.999253354069792,40.0298881530762,1.99379533535506,21.5300004929304,0.00187159213172497,0.000343144858706852,0.25,4.97982405389655E-7,0.000166041665493803,1.7329509540229E-6,20.0010052,20.001236,-63177.6796875,-63118.328125,57.1167224142753,20.5650517700195,13.797379,0,0,0,40,4449,19.9949,-63148.00390625,,,,,,,,,,,,,0,,,,0,,,,,,20.0011206,,,,
,31924438.595,20.0026903,-68022.04296875,0.000183783527554377,6.00350680120739E-7,1,0.999253354069792,40.0298881530762,1.99377965133404,21.5300004929304,0.00207388251396787,0.000373862704256552,0.25,1.06119282693802E-8,0.000183895052932885,1.37240049048585E-6,20.0025272,20.0028534,-68054.7109375,-67989.375,57.2871174314676,20.5647671637931,13.417728,0,0,0,40,4449,19.99325,-68022.04296875,,,,,,,,,,,,,0,,,,0.00245,,,,,,20.0026903,,,,
,31924537.835,20.002306,-72981.3046875,0.000201457919413984,8.17160250619419E-7,1,0.999253354069792,40.0298881530762,1.99381949584084,21.5300004929304,0.00227447941794099,0.000409085816843293,0.25,-5.78994716510136E-8,0.000201664575718151,1.42437976263011E-6,20.002306,20.002306,-73011.3125,-72951.296875,57.4418798782753,20.5640741554704,14.177031,0,0,0,40,4449,19.99125,-72981.3046875,,,,,,,,,,,,,0,,,,0.00245,,,,,,20.002306,,,,
,31924637.405,20.00185775,-77955.83984375,0.000219813885089671,8.75834129183883E-7,1,0.999253354069792,40.0298881530762,1.99374377520743,21.5300004929304,0.00248009983402201,0.000460431124284182,0.25,1.18489519318275E-6,0.00022011684765568,2.78835911459677E-6,20.0018349,20.0018806,-77988.1484375,-77923.53125,57.5536527565253,20.5652180007269,14.556682,0,0,0,40,4449,19.99135,-77955.83984375,,,,,,,,,,,,,0,,,,0,,,,,,20.00185775,,,,
,31924735.995,20.0010166,-82885.66015625,0.000237221725053123,7.86050942431491E-7,1,0.999253354069792,40.0298881530762,1.99379988745329,21.5300004929304,0.00268010391878833,0.000482952776202485,0.25,4.85293485755253E-8,0.000237644651489925,1.7568179766273E-6,20.0007591,20.0012741,-82910.484375,-82860.8359375,56.8767624588714,20.5644154425066,14.177031,0,0,0,40,4449,19.98945,-82885.66015625,,,,,,,,,,,,,0,,,,-0.00245,,,,,,20.0010166,,,,
,31924829.325,20.0050964,-87547.59765625,0.000253925491706134,7.83439917635464E-7,1,0.999253354069792,40.0298881530762,1.99378995653504,21.5300004929304,0.00286632203079472,0.000536114738076073,0.25,1.75637270071403E-6,0.000254448773623359,3.56489694591915E-6,20.0050964,20.0050964,-87577.609375,-87517.5859375,57.1917587521214,20.5650201191443,13.417728,0,0,0,40,4449,19.99025,-87547.59765625,,,,,,,,,,,,,0,,,,0.00245,,,,,,20.0050964,,,,
,31924938.72,20.0003109,-87788.48828125,0.000254045962206286,7.71135069459851E-7,1,0.999253354069792,40.0298881530762,1.99382156527354,21.5300004929304,0.00286531919920829,0.000550020571649974,0.25,2.96486450570231E-6,0.000254565056781954,4.77555421022714E-6,20.0001907,20.0004311,-87818.4609375,-87758.515625,56.9181887703906,20.566153849889,13.797379,0,0,0,40,4449,19.98465,-87788.48828125,,,,,,,,,,,,,0,,,,-0.00245,,,,,,20.0003109,,,,
,31925029.93,20.00091745,-83228.82421875,0.000237420209165411,8.2938639510493E-7,1,0.999253354069792,40.0298881530762,1.99382471719665,21.5300004929304,0.00268094700371592,0.000491692668166471,0.25,7.86357033674085E-7,0.000237844032940422,2.49586872246288E-6,20.0008793,20.0009556,-83261.40625,-83196.2421875,57.2472543769868,20.565936922898,14.177031,0,0,0,40,4449,19.9855,-83228.82421875,,,,,,,,,,,,,0,,,,0.00245,,,,,,20.00091745,,,,
,31925125.485,19.99949835,-78451.59375,0.000219836485590235,8.07473479452942E-7,1,0.999253354069792,40.0298881530762,1.99383501888462,21.5300004929304,0.0024818820765874,0.00045315783131672,0.25,5.35357437075532E-7,0.000220152554082918,2.13632687240425E-6,19.9994888,19.9995079,-78479.171875,-78424.015625,56.7055858131598,20.5642781726902,13.797379,0,0,0,40,4449,19.9872,-78451.59375,,,,,,,,,,,,,0,,,,0.00245,,,,,,19.99949835,,,,
,31925219.59,19.9991121,-73748.62890625,0.00020297912628788,6.60222144208769E-7,1,0.999253354069792,40.0298881530762,1.99371975282198,21.5300004929304,0.00228857410935569,0.000429460661534833,0.25,1.47433113286801E-6,0.000203188726770041,2.96747743938391E-6,19.9990997,19.9991245,-73781.5234375,-73715.734375,57.098744958333,20.5645970154201,14.177031,0,0,0,40,4449,19.98805,-73748.62890625,,,,,,,,,,,,,0,,,,-0.0049,,,,,,19.9991121,,,,
,31925316.555,19.9992466,-68904.66015625,0.000185706709634659,5.73442181920798E-7,1,0.999253354069792,40.0298881530762,1.9937793636017,21.5399991720915,0.00209561211540728,0.000378528641593824,0.25,7.64984798742393E-8,0.00018583299452357,1.45116599935438E-6,19.9992447,19.9992485,-68934.8125,-68874.5078125,56.8361177758714,20.5657106090766,14.177031,0,0,0,40,4449,19.9885,-68904.66015625,,,,,,,,,,,,,0,,,,0.0049,,,,,,19.9992466,,,,
,31925412.51,19.9983196,-64110.064453125,0.000169012970620043,6.67718610942428E-7,1,0.999253354069792,40.0298881530762,1.99379455487498,21.5300004929304,0.00190785264718586,0.000336541209413919,0.25,-6.29448717407147E-7,0.00016906197736277,6.26927067040788E-7,19.9983196,19.9983196,-64112.41015625,-64107.71875,56.5938129349098,20.565206540489,14.177031,0,0,0,40,4449,19.9903,-64110.064453125,,,,,,,,,,,,,0,,,,0,,,,,,19.9983196,,,,
,31925508.885,19.99886515,-59294.6328125,0.000151600148834524,7.99951259749338E-7,1,0.999253354069792,40.0298881530762,1.99381484588088,21.5300004929304,0.00171055218006387,0.000301729780614944,0.25,-5.67063090929064E-7,0.000151576851190353,5.61396598042722E-7,19.9988251,19.9989052,-59319.578125,-59269.6875,57.1518956976407,20.5632498280894,14.177031,0,0,0,40,4449,19.99125,-59294.6328125,,,,,,,,,,,,,0,,,,0,,,,,,19.99886515,,,,
,31925605.055,19.9993019,-54485.1796875,0.000133839296341437,5.48954354741437E-7,1,0.999253354069792,40.0298881530762,1.99374983632601,21.5300004929304,0.00150940163555211,0.000266264827861624,0.25,-4.97052613263928E-7,0.000133756744546065,4.96825879693739E-7,19.9993019,19.9993019,-54507.8203125,-54462.5390625,56.2037803038136,20.5618980271615,13.797379,0,0,0,40,4449,19.9919,-54485.1796875,,,,,,,,,,,,,0,,,,0,,,,,,19.9993019,,,,
,31925700.26,19.99903775,-49728.1171875,0.000117631206448498,5.73152251606022E-7,1,0.999253354069792,40.0298881530762,1.99385848721246,21.5300004929304,0.00132596076570559,0.00023441253656769,0.25,-3.87711656597621E-7,0.000117502414363216,4.80060398057447E-7,19.9989853,19.9990902,-49755.72265625,-49700.51171875,57.0768593597945,20.5628379073027,14.177031,0,0,0,40,4449,19.9924,-49728.1171875,,,,,,,,,,,,,0,,,,0,,,,,,19.99903775,,,,
,31925795.645,19.999424,-44960.970703125,0.000101466481763773,4.84615928006915E-7,1,0.999253354069792,40.0298881530762,1.99370597416883,21.5300004929304,0.00114274514988555,0.000204077225604229,0.25,-1.49354250816901E-7,0.000101304322410893,5.90471029414662E-7,19.999424,19.999424,-44993.2265625,-44928.71484375,57.0119841926983,20.5610444941106,13.417728,0,0,0,40,4449,19.9921,-44960.970703125,,,,,,,,,,,,,0,,,,0.0049,,,,,,19.999424,,,,
,31925890.455,19.999773,-40223.275390625,8.4109790385142E-5,5.44256907063082E-7,1,0.999253354069792,40.0298881530762,1.99383152382417,21.5300004929304,0.000947398559456313,0.00016606821993381,0.25,-3.82789999009279E-7,8.39354570248301E-5,2.20941465074475E-7,19.999773,19.999773,-40225.7734375,-40220.77734375,56.926005055583,20.5627425746825,14.177031,0,0,0,40,4449,19.99375,-40223.275390625,,,,,,,,,,,,,0,,,,0,,,,,,19.999773,,,,
,31925984.3,19.9977512,-35533.34375,6.84829506560697E-5,5.04617534586927E-7,1,0.999253354069792,40.0298881530762,1.99371105003348,21.5300004929304,0.000771936901428369,0.000129656541189403,0.25,-7.88472844605258E-7,6.83103181319981E-5,-3.06313973069178E-7,19.9976978,19.9978046,-35558.234375,-35508.453125,56.313208296506,20.5652470209454,13.797379,0,0,0,40,4449,19.9939,-35533.34375,,,,,,,,,,,,,0,,,,-0.00245,,,,,,19.9977512,,,,
,31926080.01,19.9982662,-30750.9833984375,5.16763747277655E-5,5.35263103149903E-7,1,0.999253354069792,40.0298881530762,1.99367049447737,21.5300004929304,0.000581371007024917,0.000102320287106029,0.25,-1.8137724510241E-7,5.15170769943812E-5,1.71070404079053E-7,19.9982662,19.9982662,-30781.060546875,-30720.90625,57.3433946848522,20.5614379401208,14.177031,0,0,0,40,4449,19.9957,-30750.9833984375,,,,,,,,,,,,,0,,,,-0.00245,,,,,,19.9982662,,,,
,31926175.365,19.9992905,-25983.365234375,3.58065941392781E-5,3.97554663619327E-7,1,0.999253354069792,40.0298881530762,1.99382061915712,21.5300004929304,0.00040250902959729,7.17095835073403E-5,0.25,-4.22067874355145E-8,3.56778941332477E-5,1.93134259511287E-7,19.9992905,19.9992905,-25988.52734375,-25978.203125,56.8791073444291,20.5604050997056,14.556682,0,0,0,40,4449,19.99785,-25983.365234375,,,,,,,,,,,,,0,,,,0,,,,,,19.9992905,,,,
,31926268.105,19.9985876,-21348.736328125,1.96884552221846E-5,4.55957677791802E-7,1,0.999253354069792,40.0298881530762,1.99375596332116,21.5300004929304,0.000222182742517309,3.39833422695117E-5,0.25,-5.0098985339681E-7,1.96114988043587E-5,-3.74968882594763E-7,19.99823,19.9989452,-21371.408203125,-21326.064453125,57.2292769210445,20.5602312251522,14.177031,0,0,0,40,4449,19.99835,-21348.736328125,,,,,,,,,,,,,0,,,,0,,,,,,19.9985876,,,,
,31926361.09,19.9980717,-16701.583984375,4.03785140122914E-6,3.88587243225214E-7,1,0.999253354069792,40.0298881530762,1.99378209690184,21.5300004929304,4.62175139153323E-5,3.21379851294418E-6,0.25,-4.35705097258514E-7,4.02223395388121E-6,-4.09537877533929E-7,19.9980717,19.9980717,-16733.98046875,-16669.1875,56.8501870892175,20.5605166489146,14.177031,0,0,0,40,4449,20.00005,-16701.583984375,,,,,,,,,,,,,0,,,,-0.00245,,,,,,19.9980717,,,,
,31926453.72,19.99812125,-12071.6943359375,-1.11619475526651E-5,3.33305605928594E-7,1,0.999253354069792,40.0298881530762,1.99369486237225,21.5300004929304,-0.000124867549383724,-2.47375973158515E-5,0.25,-2.11997563224001E-7,-1.1105748848744E-5,-2.74198947221148E-7,19.9980812,19.9981613,-12101.6044921875,-12041.7841796875,57.0416860764291,20.5585444698056,13.797379,0,0,0,40,4449,20.0021,-12071.6943359375,,,,,,,,,,,,,0,,,,0,,,,,,19.99812125,,,,
,31926546.78,19.9993515,-7420.72314453125,-2.64002213556138E-5,3.31748181677478E-7,1,0.999253354069792,40.0298881530762,1.99377137963658,21.5300004929304,-0.000295020390726012,-5.97116429884855E-5,0.25,-6.19275752105911E-7,-2.62569939164533E-5,-7.56598412714184E-7,19.9993515,19.9993515,-7423.25537109375,-7418.19091796875,56.7540467813522,20.5597833257282,14.177031,0,0,0,40,4449,20.0036,-7420.72314453125,,,,,,,,,,,,,0,,,,0.0049,,,,,,19.9993515,,,,
,31926641.38,19.9998026,-2689.95544433594,-4.18119245175885E-5,3.36782912093769E-7,1,0.999253354069792,40.0298881530762,1.99371238782398,21.5300004929304,-0.00046802240321759,-8.92605765856718E-5,0.25,-5.24344293370415E-7,-4.1574325403826E-5,-7.30201564790739E-7,19.9996853,19.9999199,-2719.85278320313,-2660.05810546875,57.1307917276214,20.5592629809718,14.177031,0,0,0,40,4449,20.003,-2689.95544433594,,,,,,,,,,,,,0,,,,0,,,,,,19.9998026,,,,
,31926735.845,19.9993687,2027.23388671875,-5.31283988996242E-5,3.09518704823511E-7,1,0.999253354069792,40.0298881530762,1.99356571437177,21.5300004929304,-0.000594828537440637,-0.000112286085052681,0.25,-5.68581608730082E-7,-5.28249978661963E-5,-8.28446621495751E-7,19.9993687,19.9993687,1994.69116210938,2059.77661132813,56.9541436822753,20.5597700774819,13.797379,0,0,0,40,4449,20.00235,2027.23388671875,,,,,,,,,,,,,0,,,,-0.00245,,,,,,19.9993687,,,,
,31926829.655,19.99881645,6717.97045898438,-6.65852229660769E-5,3.60141348291228E-7,1,0.999253354069792,40.0298881530762,1.99364234031998,21.5300004929304,-0.00074590237236719,-0.000139902460837146,0.25,-6.13313405356118E-7,-6.62256105588351E-5,-9.61250317336695E-7,19.9987659,19.998867,6682.90771484375,6753.033203125,56.9760292808137,20.5619536781527,14.177031,0,0,0,40,4449,20.00425,6717.97045898438,,,,,,,,,,,,,0,,,,0.00245,,,,,,19.99881645,,,,
,31926922.19,20.00013255,11341.2490234375,-7.64490419941711E-5,4.24415205762186E-7,1,0.999253354069792,40.0298881530762,1.9935541748256,21.5300004929304,-0.000857206964610521,-0.000157695224884819,0.25,-4.12462374680713E-7,-7.60653319571715E-5,-8.39522185557789E-7,19.9999523,20.0003128,11311.3447265625,11371.1533203125,57.2808644033138,20.5618613086928,13.797379,0,0,0,40,4449,20.0031,11341.2490234375,,,,,,,,,,,,,0,,,,-0.00245,,,,,,20.00013255,,,,
,31927016.165,20.00080965,16036.7182617188,-7.98494705782017E-5,3.41613163818405E-7,1,0.999253354069792,40.0298881530762,1.99385166132284,21.5300004929304,-0.000895399078228753,-0.000167238434819661,0.25,-6.21191898789144E-7,-7.94803970410359E-5,-1.09326737942663E-6,20.0007305,20.0008888,16009.0859375,16064.3505859375,56.9134989992753,20.5596131770178,14.177031,0,0,0,40,4449,20.0023,16036.7182617188,,,,,,,,,,,,,0,,,,-0.00245,,,,,,20.00080965,,,,
,31927109.095,20.00132655,20684.02734375,-7.3478605657365E-5,3.94572055271596E-7,1,0.999253354069792,40.0298881530762,1.99391472256393,21.5300004929304,-0.000824052990352793,-0.000155620558384738,0.25,-6.96205708285402E-7,-7.31704733598987E-5,-1.15298080611459E-6,20.001009,20.0016441,20656.453125,20711.6015625,57.0057311645445,20.5570310977545,14.177031,0,0,0,40,4449,20.0006,20684.02734375,,,,,,,,,,,,,0,,,,-0.0049,,,,,,20.00132655,,,,
,31927204.525,20.0010529,25451.650390625,-6.54828226890784E-5,5.00911940994341E-7,1,0.999253354069792,40.0298881530762,1.99380338353587,21.5300004929304,-0.00073549152391651,-0.00013429757337275,0.25,-2.06248078812138E-7,-6.52420370124695E-5,-6.33686721365584E-7,20.0010529,20.0010529,25449.224609375,25454.076171875,57.0057311645445,20.5581578190806,14.177031,0,0,0,40,4449,19.9994,25451.650390625,,,,,,,,,,,,,0,,,,-0.0049,,,,,,20.0010529,,,,
,31927297.955,20.0020828,30124.6630859375,-6.65197286521863E-5,5.39027181925562E-7,1,0.999253354069792,40.0298881530762,1.9938592406168,21.5300004929304,-0.000746893675461371,-0.000139991107162296,0.25,-5.0465845951851E-7,-6.63052940286018E-5,-9.54062114733857E-7,20.0020828,20.0020828,30097.099609375,30152.2265625,56.6368025034675,20.5557064272956,14.177031,0,0,0,40,4449,19.9981,30124.6630859375,,,,,,,,,,,,,0,,,,-0.00245,,,,,,20.0020828,,,,
,31927392.46,20.0004444,34847.302734375,-7.4618559280028E-5,4.27974483795003E-7,1,0.999253354069792,40.0298881530762,1.9939403180288,21.5300004929304,-0.000838628680682821,-0.000155178252727659,0.25,-3.78486840969712E-7,-7.44163743756677E-5,-8.98631846466895E-7,20.0002708,20.000618,34820.12109375,34874.484375,56.536754053006,20.5554803214494,14.177031,0,0,0,40,4449,19.99635,34847.302734375,,,,,,,,,,,,,0,,,,-0.00245,,,,,,20.0004444,,,,
,31927488.765,20.0005913,39659.6640625,-8.68511946162428E-5,4.88117164758236E-7,1,0.999253354069792,40.0298881530762,1.99378317934512,21.5300004929304,-0.000977000803549763,-0.000178108743599922,0.25,-1.96377260432711E-7,-8.6661776863214E-5,-8.17061408715711E-7,20.0005913,20.0005913,39656.9296875,39662.3984375,56.7618630665445,20.556912079784,14.556682,0,0,0,40,4449,19.9954,39659.6640625,,,,,,,,,,,,,0,,,,0.0049,,,,,,20.0005913,,,,
,31927581.815,20.0022316,44309.96875,-0.000100619089633974,5.24835030401837E-7,1,0.999253354069792,40.0298881530762,1.99386238759572,21.5300004929304,-0.00113235938495405,-0.000207094445013476,0.25,-2.72507115106885E-7,-0.000100448409060207,-1.00401565637237E-6,20.0022316,20.0022316,44284.83984375,44335.09765625,56.6454004171791,20.5544743484724,14.556682,0,0,0,40,4449,19.9945,44309.96875,,,,,,,,,,,,,0,,,,-0.00245,,,,,,20.0022316,,,,
,31927677.195,20.0011902,49078.00390625,-0.000115534019960461,4.99576494472738E-7,1,0.999253354069792,40.0298881530762,1.99373872048454,21.5300004929304,-0.00130025401327992,-0.00024078315601462,0.25,-5.59347621069326E-7,-0.000115392967611026,-1.40947053392124E-6,20.0011902,20.0011902,49047.96484375,49108.04296875,56.8259566051214,20.5575247688291,14.556682,0,0,0,40,4449,19.9935,49078.00390625,,,,,,,,,,,,,0,,,,0.00245,,,,,,20.0011902,,,,
,31927771.77,20.0005474,53805.744140625,-0.000132165369207844,6.32414315788003E-7,1,0.999253354069792,40.0298881530762,1.99383191805367,21.5300004929304,-0.00148843705998908,-0.000274275653066981,0.25,-5.16742012175687E-7,-0.000132067539336258,-1.49681901614411E-6,20.0005188,20.000576,53780.55078125,53830.9375,57.1128142716791,20.5527831464143,14.177031,0,0,0,40,4449,19.993,53805.744140625,,,,,,,,,,,,,0,,,,0,,,,,,20.0005474,,,,
,31927866.07,20.0014715,58518.646484375,-0.000148649734585694,6.51034396834411E-7,1,0.999253354069792,40.0298881530762,1.99385303412347,21.5300004929304,-0.00167385961377734,-0.000314202317788171,0.25,-1.07252691166163E-6,-0.000148603858048132,-2.1784776030188E-6,20.0012188,20.0017242,58493.421875,58543.87109375,56.9564885678329,20.5532598972749,14.556682,0,0,0,40,4449,19.9918,58518.646484375,,,,,,,,,,,,,0,,,,0.0049,,,,,,20.0014715,,,,
,31927960.19,20.0009575,63221.7734375,-0.000165032049727819,7.53958360301094E-7,1,0.999253354069792,40.0298881530762,1.99398574665673,21.5300004929304,-0.00185969825461498,-0.000346582450143591,0.25,-9.77187149371528E-7,-0.000165054811126381,-2.20488401055595E-6,20.0009575,20.0009575,63191.62109375,63251.92578125,56.7462304961599,20.5493315441729,13.797379,0,0,0,40,4449,19.99155,63221.7734375,,,,,,,,,,,,,0,,,,-0.00245,,,,,,20.0009575,,,,
,31928055.98,20.0014744,68009.3515625,-0.000182104051939035,6.47111245154776E-7,1,0.999253354069792,40.0298881530762,1.99387699063172,21.5300004929304,-0.00205234312940893,-0.000385340126513206,0.25,-1.32879650944097E-6,-0.000182204586583735,-2.67895914127312E-6,20.0013962,20.0015526,67984.4296875,68034.2734375,56.6368025034675,20.5531151935486,14.556682,0,0,0,40,4449,19.9903,68009.3515625,,,,,,,,,,,,,0,,,,-0.00245,,,,,,20.0014744,,,,
,31928152.205,20.0016422,72819.7578125,-0.000197783872981366,6.9125006588157E-7,1,0.999253354069792,40.0298881530762,1.99380125209493,21.5300004929304,-0.00223178218131285,-0.000408099390340956,0.25,-5.1700271935693E-7,-0.000197979924514535,-1.9732265994501E-6,20.0016422,20.0016422,72787.1484375,72852.3671875,56.8267382336406,20.5521403745448,13.797379,0,0,0,40,4449,19.98875,72819.7578125,,,,,,,,,,,,,0,,,,0,,,,,,20.0016422,,,,
,31928247.23,20.0022736,77570.26953125,-0.000215257838831623,8.74608146911818E-7,1,0.999253354069792,40.0298881530762,1.99388139986127,21.5300004929304,-0.00243026145174217,-0.000442695821890584,0.25,-4.32188933833715E-7,-0.000215553431494432,-2.00269131403967E-6,20.0022736,20.0022736,77545.265625,77595.2734375,56.6055373626983,20.5529652510248,13.797379,0,0,0,40,4449,19.9868,77570.26953125,,,,,,,,,,,,,0,,,,-0.00245,,,,,,20.0022736,,,,
,31928342.745,20.0018148,82343.765625,-0.000233180098214669,9.41134551028791E-7,1,0.999253354069792,40.0298881530762,1.99382324046723,21.5300004929304,-0.00263234652689924,-0.00048594529613653,0.25,-1.03961233556848E-6,-0.00023357952432761,-2.72289127426776E-6,20.0015697,20.0020599,82308.953125,82378.578125,56.607882248256,20.5524010317666,14.556682,0,0,0,40,4449,19.98565,82343.765625,,,,,,,,,,,,,0,,,,-0.00245,,,,,,20.0018148,,,,
,31928434.61,20.0019341,86937.05078125,-0.000249204076472267,8.59821223949906E-7,1,0.999253354069792,40.0298881530762,1.99378378218795,21.5300004929304,-0.00281445983794064,-0.00051746177782067,0.25,-9.54088199932952E-7,-0.000249712741678845,-2.73050681856015E-6,20.0019341,20.0019341,86912,86962.1015625,56.6532167023714,20.5528408048605,13.797379,0,0,0,40,4449,19.98415,86937.05078125,,,,,,,,,,,,,0,,,,-0.00245,,,,,,20.0019341,,,,
,31928537.735,20.0010166,88720.32421875,-0.000256375966367838,7.40998521720602E-7,1,0.999253354069792,40.0298881530762,1.99387129803235,21.5300004929304,-0.00289607082681177,-0.000531635368357189,0.25,-9.20231374036045E-7,-0.000256930567900113,-2.73808285336632E-6,20.0010166,20.0010166,88687.859375,88752.7890625,57.0964000727753,20.5504345324673,14.177031,0,0,0,40,4449,19.9839,88720.32421875,,,,,,,,,,,,,0,,,,-0.00245,,,,,,20.0010166,,,,
,31928629.62,19.9998169,84126.90625,-0.000239578019186969,8.46484191338125E-7,1,0.999253354069792,40.0298881530762,1.99373722584705,21.5300004929304,-0.00270561715446613,-0.000494812080362005,0.25,-6.7736213441042E-7,-0.000240021881506706,-2.39810024464556E-6,19.9996967,19.9999371,84099.3515625,84154.4609375,56.5766171074867,20.5516338339418,14.177031,0,0,0,40,4449,19.98455,84126.90625,,,,,,,,,,,,,0,,,,0,,,,,,19.9998169,,,,
,31928726.38,19.9978714,79290.6171875,-0.000220042242314292,8.26104880725909E-7,1,0.999253354069792,40.0298881530762,1.99382224146344,21.5300004929304,-0.00248455424490027,-0.000452460080057161,0.25,-4.37385932041072E-7,-0.000220373338130038,-2.03668021065449E-6,19.9978714,19.9978714,79265.546875,79315.6875,57.0057311645445,20.5531050894653,13.797379,0,0,0,40,4449,19.98535,79290.6171875,,,,,,,,,,,,,0,,,,0,,,,,,19.9978714,,,,
,31928823.4,19.9991894,74441.87109375,-0.000204672763731058,6.09830913436639E-7,1,0.999253354069792,40.0298881530762,1.99370482967615,21.5300004929304,-0.00230743182425417,-0.00043500825372781,0.25,-1.66071331130586E-6,-0.000204894268236251,-3.1647118557925E-6,19.9991894,19.9991894,74417.1171875,74466.625,56.8462789466214,20.5552007795622,14.177031,0,0,0,40,4449,19.98555,74441.87109375,,,,,,,,,,,,,0,,,,0,,,,,,19.9991894,,,,
,31928920.31,19.99891185,69596.5546875,-0.000186616565038989,6.9971965776038E-7,1,0.999253354069792,40.0298881530762,1.99381359687724,21.5300004929304,-0.00210617896547241,-0.000379628591607945,0.25,-8.76411894572178E-9,-0.000186754969657646,-1.38891251976419E-6,19.9989033,19.9989204,69568.9765625,69624.1328125,56.9674313671022,20.5537890919546,13.797379,0,0,0,40,4449,19.98755,69596.5546875,,,,,,,,,,,,,0,,,,0,,,,,,19.99891185,,,,
,31929019.11,19.999054,64658.685546875,-0.000169382419652884,7.57234191584516E-7,1,0.999253354069792,40.0298881530762,1.99383955375851,21.5300004929304,-0.00190908463595304,-0.000354353910597199,0.25,-8.8128770536921E-7,-0.000169428629145853,-2.14041551131064E-6,19.999054,19.999054,64656.30078125,64661.0703125,56.4898563418521,20.5561197947169,14.556682,0,0,0,40,4449,19.98755,64658.685546875,,,,,,,,,,,,,0,,,,0,,,,,,19.999054,,,,
,31929115.845,19.9986725,59822.810546875,-0.000151875486436339,8.03193415558837E-7,1,0.999253354069792,40.0298881530762,1.99384323181494,21.5300004929304,-0.00171219105662901,-0.000311041537840054,0.25,-2.07385159821965E-7,-0.000151853915944735,-1.3378209643304E-6,19.9986725,19.9986725,59792.71875,59852.90234375,57.1855057239676,20.5537478285816,14.177031,0,0,0,40,4449,19.9897,59822.810546875,,,,,,,,,,,,,0,,,,-0.00245,,,,,,19.9986725,,,,
,31929212,19.99926855,55017.673828125,-0.000135183845612593,6.62715201946016E-7,1,0.999253354069792,40.0298881530762,1.99382809189175,21.5300004929304,-0.00152221298103095,-0.000282772178729008,0.25,-7.22616415309518E-7,-0.000135098417568666,-1.72621948414262E-6,19.9991322,19.9994049,54990.55859375,55044.7890625,56.6813553290637,20.5557585447075,14.177031,0,0,0,40,4449,19.9904,55017.673828125,,,,,,,,,,,,,0,,,,0,,,,,,19.99926855,,,,
,31929310.515,19.9994602,50092.724609375,-0.000118007053686447,6.66437081977076E-7,1,0.999253354069792,40.0298881530762,1.99379492713548,21.5300004929304,-0.00133068470350361,-0.00023250719349097,0.25,6.25260938021369E-7,-0.0001178839522108,-2.46116040106687E-7,19.9994602,19.9994602,50062.80859375,50122.640625,57.3754414541407,20.5566318102406,14.556682,0,0,0,40,4449,19.99185,50092.724609375,,,,,,,,,,,,,0,,,,-0.0049,,,,,,19.9994602,,,,
,31929406.44,19.99923135,45297.529296875,-0.000101618998146526,6.27167899930643E-7,1,0.999253354069792,40.0298881530762,1.9938695514133,21.5300004929304,-0.00114306419831688,-0.000212893080452888,0.25,-6.03316402331152E-7,-0.000101454654783161,-1.34378969587417E-6,19.9990578,19.9994049,45269.8828125,45325.17578125,56.6813553290637,20.55583312468,13.797379,0,0,0,40,4449,19.99235,45297.529296875,,,,,,,,,,,,,0,,,,0.00245,,,,,,19.99923135,,,,
,31929505.405,19.9991493,40349.8203125,-8.47829844034645E-5,5.56573317241303E-7,1,0.999253354069792,40.0298881530762,1.99375701146773,21.5300004929304,-0.000952771318882989,-0.00017955410083826,0.25,-6.94348225678581E-7,-8.46006408771949E-5,-1.30096204035462E-6,19.9991493,19.9991493,40347.390625,40352.25,56.8494054606983,20.5564970994486,13.797379,0,0,0,40,4449,19.9931,40349.8203125,,,,,,,,,,,,,0,,,,-0.0049,,,,,,19.9991493,,,,
,31929602.655,19.9989815,35492.51171875,-6.76244131090025E-5,5.67913873492125E-7,1,0.999253354069792,40.0298881530762,1.99378288013524,21.5300004929304,-0.00075886548595825,-0.000147036443381113,0.25,-9.10685966360165E-7,-6.74418095895281E-5,-1.38229680810619E-6,19.9989815,19.9989815,35490.2578125,35494.765625,56.5453519667175,20.5542353178569,14.556682,0,0,0,40,4449,19.99305,35492.51171875,,,,,,,,,,,,,0,,,,-0.00245,,,,,,19.9989815,,,,
,31929696.065,19.9991322,30824.828125,-5.18643698434539E-5,4.55858087101473E-7,1,0.999253354069792,40.0298881530762,1.99369965405665,21.5300004929304,-0.000582908292511205,-0.000105981636919989,0.25,-1.10127475850583E-7,-5.17029040165756E-5,-4.63127496484896E-7,19.9991322,19.9991322,30797.267578125,30852.388671875,57.0268351345637,20.5577994620736,13.797379,0,0,0,40,4449,19.99475,30824.828125,,,,,,,,,,,,,0,,,,0.00245,,,,,,19.9991322,,,,
,31929792.35,19.9987669,26009.265625,-3.51656968031543E-5,4.58191625929903E-7,1,0.999253354069792,40.0298881530762,1.99376978209772,21.5300004929304,-0.000394902548085508,-7.26180403423495E-5,0.25,-1.53675921094034E-7,-3.50381114294724E-5,-3.84151653422602E-7,19.998457,19.9990768,25979.126953125,26039.404296875,56.9181887703906,20.5597877392351,14.556682,0,0,0,40,4449,19.9969,26009.265625,,,,,,,,,,,,,0,,,,0,,,,,,19.9987669,,,,
,31929888.845,19.9982414,21186.7412109375,-1.86066556173793E-5,4.59812812416604E-7,1,0.999253354069792,40.0298881530762,1.99375049045589,21.5300004929304,-0.000209702324676467,-3.36142474057473E-5,0.25,3.39857376784555E-7,-1.85327856125799E-5,2.21486818745466E-7,19.9982414,19.9982414,21156.783203125,21216.69921875,57.1010898438907,20.5584754350415,14.177031,0,0,0,40,4449,19.99745,21186.7412109375,,,,,,,,,,,,,0,,,,0,,,,,,19.9982414,,,,
,31929983.13,19.9979849,16477.3154296875,-2.33633598308857E-6,3.35827955579362E-7,1,0.999253354069792,40.0298881530762,1.99397929394198,21.5300004929304,-2.58937991387561E-5,-6.61431959077243E-6,0.25,-1.71311229998733E-7,-2.32471596854309E-6,-1.84500838396277E-7,19.997942,19.9980278,16444.65234375,16509.978515625,56.6547799594098,20.5561450470398,13.797379,0,0,0,40,4449,19.99935,16477.3154296875,,,,,,,,,,,,,0,,,,0.00245,,,,,,19.9979849,,,,
,31930078.655,19.9980717,11699.8515625,1.31003913829947E-5,3.42934470446705E-7,1,0.999253354069792,40.0298881530762,1.99385860598374,21.5300004929304,0.00014748709447876,2.38367019947438E-5,0.25,-2.13913525182268E-7,1.3036635849357E-5,-1.38977183713206E-7,19.9980717,19.9980717,11672.326171875,11727.376953125,56.9236601700253,20.5569260798122,13.797379,0,0,0,40,4449,20.0009,11699.8515625,,,,,,,,,,,,,0,,,,-0.00245,,,,,,19.9980717,,,,
,31930174.78,19.9987984,6896.6298828125,2.86061522513863E-5,3.79780982682745E-7,1,0.999253354069792,40.0298881530762,1.9938149253454,21.5300004929304,0.000321394204102647,5.49932771955422E-5,0.25,-1.92869827394291E-7,2.84544387947904E-5,-4.0580166534164E-8,19.9986954,19.9989014,6869.31689453125,6923.94287109375,56.7446672391214,20.5599103441368,14.556682,0,0,0,40,4449,20.0017,6896.6298828125,,,,,,,,,,,,,0,,,,-0.00245,,,,,,19.9987984,,,,
,31930268.4,19.9998226,2216.5322265625,4.36313064811179E-5,3.0959560690772E-7,1,0.999253354069792,40.0298881530762,1.99379488756799,21.5300004929304,0.000488893069471876,9.03359708308512E-5,0.25,2.9802695955893E-7,4.3383433371987E-5,5.12913058622196E-7,19.9995956,20.0000496,2186.52075195313,2246.54370117187,57.0033862789868,20.5588530763539,14.177031,0,0,0,40,4449,20.0021,2216.5322265625,,,,,,,,,,,,,0,,,,0,,,,,,19.9998226,,,,
,31930313.235,20.00113485,-0.365370556712151,5.02837056993403E-5,3.13065764175256E-7,1,0.999253354069792,40.0298881530762,1.99380168965777,21.5300004929304,0.000564710548724468,9.65925044168311E-5,0.25,-3.19760553060017E-7,4.99961104831329E-5,-7.42491090564219E-8,20.0009193,20.0013504,-0.441489428281784,-0.289251685142517,56.8892685151791,20.5590230692321,14.177031,0,0,0,40,4417,20.0012,-0.365370556712151,,,,,,,,,,,,,0,,,,-0.0049,,,,,,20.00113485,,,,