File: data/monolayers/magneticStructure/ML_Ac_CoFe_C-2/PPMS/data/DD175_23_HYST_100OE_250K.DAT
[Header]
; VSM Data File (default extension .dat)
; Copyright (c) 2003-2013, Quantum Design, Inc. All rights reserved.
TITLE,
FILEOPENTIME,31980127.80,01/06/2019,11:24 am
BYAPP,VSM,2.0,2.0
INFO,PPMS VSM Option Release 1.4.10 Build 1,APPNAME
INFO,Quantum Design Linear Motor Servo Controller,MOTOR_MODULE_NAME
INFO,3101-100 M1,MOTOR_HW_VERSION
INFO,MMC1014,MOTOR_SERIAL_NUMBER
INFO,SRV No X-over 01.03.11,MOTOR_SOFTWARE_VERSION
INFO,Quantum Design VSM Detection Module,VSM_MODULE_NAME
INFO,3101-150 F0,VSM_HW_VERSION
INFO,VSM707,VSM_SERIAL_NUMBER
INFO,VSM No X-over 01.02.05 May 20 2008 13:51:47,VSM_SOFTWARE_VERSION
INFO,704,PREAMP_SERIAL_NUMBER
INFO,822,COIL_SERIAL_NUMBER
INFO,0,MOMENT_UNITS
INFO,CoFe2O4 Monolayer,SAMPLE_MATERIAL
INFO,from YF45,SAMPLE_COMMENT
INFO,29.98,SAMPLE_MASS
INFO,,SAMPLE_VOLUME
INFO,,SAMPLE_MOLECULAR_WEIGHT
INFO,,SAMPLE_SIZE
INFO,,SAMPLE_SHAPE
DATATYPE,COMMENT,1
DATATYPE,TIME,2
STARTUPAXIS,X,2
STARTUPAXIS,Y1,5
[Data]
Comment,Time Stamp (sec),Temperature (K),Magnetic Field (Oe),Moment (emu),M. Std. Err. (emu),Transport Action,Averaging Time (sec),Frequency (Hz),Peak Amplitude (mm),Center Position (mm),Coil Signal' (mV),Coil Signal" (mV),Range (mV),M. Quad. Signal (emu),M. Raw' (emu),M. Raw" (emu),Min. Temperature (K),Max. Temperature (K),Min. Field (Oe),Max. Field (Oe),Mass (grams),Motor Lag (deg),Pressure (Torr),VSM Status (code),Motor Status (code),Measure Status (code),Measure Count,PPMS Status (code),System Temp. (K),System Field (Oe),Sample Position (deg),Bridge 1 Resistance (ohms),Bridge 1 Excitation (에),Bridge 2 Resistance (ohms),Bridge 2 Excitation (에),Bridge 3 Resistance (ohms),Bridge 3 Excitation (에),Bridge 4 Resistance (ohms),Bridge 4 Excitation (에),Signal 1 Vin (V),Signal 2 Vin (V),Digital Inputs (code),Drive 1 Iout (mA),Drive 1 Ipower (W),Drive 2 Iout (mA),Drive 2 Ipower (W),Pressure (),Map 20 (),Map 21 (),Map 22 (),Map 23 (),Map 24 (),Map 25 (),Map 26 (),Map 27 (),Map 28 (),Map 29 ()
,31980143.61,249.9909515,-0.106566414237022,,,2,,,,20.2800001186132,,,,,,,249.9909515,249.9909515,-0.106566414237022,-0.106566414237022,,,27.464817,,,,-99999999,4369,250.0404,-0.106566414237022,,,,,,,,,,,,,,,,,,,,,,,249.9909515,,,,
,31980286.17,249.98345185,4576.27807617188,2.68341432138762E-5,4.2767826091074E-7,1,0.999253354069792,40.0298881530762,1.9963300224871,20.2699992805719,0.000303841473651383,5.28776958533942E-5,0.25,1.5745517415857E-8,2.68812280607139E-5,3.79402089289452E-8,249.9827728,249.9841309,4546.26513671875,4606.291015625,56.353852979506,20.5073771685346,27.844467,0,0,0,40,4449,250.0672,4576.27807617188,,,,,,,,,,,,,0,,,,0.00245,,,,,,249.98345185,,,,
,31980382.11,249.98470305,9369.7314453125,1.66877668765269E-5,4.83894500548445E-7,1,0.999253354069792,40.0298881530762,1.99596459380303,20.2699992805719,0.000188913298303355,3.2926173038014E-5,0.25,1.40495102474758E-8,1.67170456551051E-5,2.78449171491766E-8,249.9845123,249.9848938,9347.353515625,9392.109375,56.0990420822367,20.5118780552942,27.464817,0,0,0,40,4449,250.0803,9369.7314453125,,,,,,,,,,,,,0,,,,-0.00245,,,,,,249.98470305,,,,
,31980479.6,249.9819183,14242.3095703125,3.5305842018837E-6,5.48796204618482E-7,1,0.999253354069792,40.0298881530762,1.99581808198178,20.2699992805719,4.09206597957983E-5,1.45546167821786E-6,0.25,-4.83729416645144E-7,3.53718052504984E-6,-4.81668482243429E-7,249.9819183,249.9819183,14209.65625,14274.962890625,56.5969394489868,20.5141915607895,27.085165,0,0,0,40,4449,250.08565,14242.3095703125,,,,,,,,,,,,,0,,,,-0.00245,,,,,,249.9819183,,,,
,31980576.47,249.9888306,19084.7998046875,-1.13860649304161E-5,8.16319678447293E-7,1,0.999253354069792,40.0298881530762,1.99567046355833,20.2699992805719,-0.000129607762667286,-1.82511619206032E-5,0.25,3.62388876119628E-7,-1.14063489491071E-5,3.53652001704662E-7,249.9888306,249.9888306,19082.216796875,19087.3828125,56.4382688595829,20.5228448652299,27.844467,0,0,0,40,4449,250.1013,19084.7998046875,,,,,,,,,,,,,0,,,,0,,,,,,249.9888306,,,,
,31980670.29,249.9908142,23774.744140625,-2.70749349992068E-5,9.94979054895237E-7,1,0.999253354069792,40.0298881530762,1.99552923567122,20.2699992805719,-0.000304612329097734,-6.393187164055E-5,0.25,-9.52415918962853E-7,-2.71216770782555E-5,-9.76348469945801E-7,249.9908142,249.9908142,23744.828125,23804.66015625,56.1357786226406,20.5286187978694,27.085165,0,0,0,40,4449,250.10125,23774.744140625,,,,,,,,,,,,,0,,,,-0.00245,,,,,,249.9908142,,,,
,31980763.87,249.9955902,28450.314453125,-4.26983050221918E-5,1.32147685590238E-6,1,0.999253354069792,40.0298881530762,1.99540271998475,20.2699992805719,-0.000484145926376288,-7.89707513657787E-5,0.25,4.28003849620542E-7,-4.27736033261676E-5,3.93693642548805E-7,249.9955902,249.9955902,28422.70703125,28477.921875,56.3773018350829,20.5275265507879,27.464817,0,0,0,40,4449,250.10265,28450.314453125,,,,,,,,,,,,,0,,,,0.00245,,,,,,249.9955902,,,,
,31980860.015,250.0007324,33255.5703125,-5.89002183588268E-5,1.49852925370138E-6,1,0.999253354069792,40.0298881530762,1.99540242074505,20.2699992805719,-0.000664575462984637,-0.000127849671758219,0.25,-1.08058598982982E-6,-5.90027141749393E-5,-1.13078320996783E-6,250.0007324,250.0007324,33230.55859375,33280.58203125,56.4898563418521,20.5274840799859,27.464817,0,0,0,40,4449,250.10275,33255.5703125,,,,,,,,,,,,,0,,,,0,,,,,,250.0007324,,,,
,31980955.31,250.0028687,38017.83203125,-7.4688564954042E-5,1.39562751721934E-6,1,0.999253354069792,40.0298881530762,1.99527508111466,20.2699992805719,-0.000843565824504219,-0.000156917165282867,0.25,-9.11505826122752E-7,-7.48189156074709E-5,-9.74271660989282E-7,250.0028687,250.0028687,37987.9453125,38047.71875,56.4523381729291,20.5302038941125,27.844467,0,0,0,40,4449,250.09555,38017.83203125,,,,,,,,,,,,,0,,,,-0.0049,,,,,,250.0028687,,,,
,31981051.575,250.00543975,42830.5078125,-9.12589155412363E-5,1.2619917436986E-6,1,0.999253354069792,40.0298881530762,1.99528946337384,20.2699992805719,-0.00103093159911984,-0.000190545687185453,0.25,-1.00902407387513E-6,-9.14182760766143E-5,-1.08542495174562E-6,250.0053253,250.0055542,42800.609375,42860.40625,56.2803798986983,20.5299304362465,27.085165,0,0,0,40,4449,250.09705,42830.5078125,,,,,,,,,,,,,0,,,,0,,,,,,250.00543975,,,,
,31981148.785,250.0061035,47691.130859375,-0.000106362668121528,1.93623067066257E-6,1,0.999253354069792,40.0298881530762,1.99530092033229,20.2699992805719,-0.0012011578347985,-0.000224413965399341,0.25,-1.38208124557034E-6,-0.000106548247938164,-1.47136417276559E-6,250.0061035,250.0061035,47658.796875,47723.46484375,56.4234179177175,20.5306918173335,27.844467,0,0,0,40,4449,250.09065,47691.130859375,,,,,,,,,,,,,0,,,,0,,,,,,250.0061035,,,,
,31981244.065,250.0065613,52450.998046875,-0.000123098779331809,1.90510958098385E-6,1,0.999253354069792,40.0298881530762,1.99507928703043,20.2699992805719,-0.00139222630198173,-0.000246930173254926,0.25,-4.7154245067595E-7,-0.000123314495862833,-5.72748455472447E-7,250.0065613,250.0065613,52416,52485.99609375,56.6516534453329,20.5330334524663,27.844467,0,0,0,40,4449,250.0884,52450.998046875,,,,,,,,,,,,,0,,,,-0.00245,,,,,,250.0065613,,,,
,31981342.44,250.00965115,57367.8203125,-0.000140572871857541,2.28864737219646E-6,1,0.999253354069792,40.0298881530762,1.99534198834138,20.2699992805719,-0.00158908543257605,-0.000287609956746158,0.25,-1.03270862569387E-6,-0.000140818811309178,-1.14897850747702E-6,250.0095367,250.0097656,57337.703125,57397.9375,56.472660514429,20.5269495628405,27.085165,0,0,0,40,4449,250.07825,57367.8203125,,,,,,,,,,,,,0,,,,-0.00245,,,,,,250.00965115,,,,
,31981439.48,250.00987245,62218.6875,-0.000157313911476215,2.94361231239123E-6,1,0.999253354069792,40.0298881530762,1.99500744771506,20.2699992805719,-0.00178301406679201,-0.000293171374037035,0.25,1.37474357594164E-6,-0.000157591218572609,1.24925841180178E-6,250.0096588,250.0100861,62186.0625,62251.3125,56.4038772047367,20.5350016974933,27.464817,0,0,0,40,4449,250.0656,62218.6875,,,,,,,,,,,,,0,,,,0,,,,,,250.00987245,,,,
,31981537.315,250.01070405,67109.65625,-0.000175665249721144,2.07686988442198E-6,1,0.999253354069792,40.0298881530762,1.99498918496614,20.2699992805719,-0.00198449572596571,-0.000364835949100274,0.25,-1.7758912154781E-6,-0.00017597223536958,-1.92160711657593E-6,250.0101166,250.0112915,67079.78125,67139.53125,56.5031440266791,20.5343920240942,27.464817,0,0,0,40,4449,250.06055,67109.65625,,,,,,,,,,,,,0,,,,-0.00245,,,,,,250.01070405,,,,
,31981635.11,250.0106659,71997.1328125,-0.000191116599843321,2.73451065932264E-6,1,0.999253354069792,40.0298881530762,1.99530819575365,20.2699992805719,-0.00216531439361819,-0.000362765348372285,0.25,1.0911691051988E-6,-0.000191453067319877,9.38185893194991E-7,250.0106659,250.0106659,71972.078125,72022.1875,56.3827732347175,20.5294146487155,27.464817,0,0,0,40,4449,250.05345,71997.1328125,,,,,,,,,,,,,0,,,,0,,,,,,250.0106659,,,,
,31981731.42,250.0129089,76810.43359375,-0.000207093400764109,3.05496620462448E-6,1,0.999253354069792,40.0298881530762,1.99494185889658,20.2699992805719,-0.00233878534651631,-0.000434151143853454,0.25,-2.45221260093298E-6,-0.000207455064545198,-2.62411260815769E-6,250.0129089,250.0129089,76780.6875,76840.1796875,56.4617177151598,20.5365902614007,27.464817,0,0,0,40,4449,250.03865,76810.43359375,,,,,,,,,,,,,0,,,,0.00245,,,,,,250.0129089,,,,
,31981828.445,250.0074768,81661.09375,-0.000227393281070415,3.46749736050979E-6,1,0.999253354069792,40.0298881530762,1.99501079637727,20.2699992805719,-0.0025790904920516,-0.000413490069725152,0.25,2.89461637626948E-6,-0.000227794990357477,2.71597189842891E-6,250.0067749,250.0081787,81633.7421875,81688.4453125,56.421854660679,20.5339310457986,27.085165,0,0,0,40,4449,250.0349,81661.09375,,,,,,,,,,,,,0,,,,0,,,,,,250.0074768,,,,
,31981922.345,250.01106265,86354.2265625,-0.000239897303810306,2.76448325353885E-6,1,0.999253354069792,40.0298881530762,1.9949855888992,20.2699992805719,-0.00271117004992888,-0.000492206203206968,0.25,-1.89347965199583E-6,-0.000240317109611043,-2.09033794987106E-6,250.0107422,250.0113831,86326.703125,86381.75,56.5273745107752,20.5335989774337,27.844467,0,0,0,40,4449,250.02675,86354.2265625,,,,,,,,,,,,,0,,,,0.00245,,,,,,250.01106265,,,,
,31982029.32,250.0102005,89090.05078125,-0.000251577901682987,2.53952592479955E-6,1,0.999253354069792,40.0298881530762,1.99501337636317,20.2699992805719,-0.00284260283416041,-0.000519709024935399,0.25,-2.29780458820598E-6,-0.000252017924917777,-2.50461818678236E-6,250.0101471,250.0102539,89062.71875,89117.3828125,56.5985027060252,20.5345485618826,27.085165,0,0,0,40,4449,250.0162,89090.05078125,,,,,,,,,,,,,0,,,,0.00245,,,,,,250.0102005,,,,
,31982120.22,250.00385285,84546.98828125,-0.000234403879544636,3.32966376869981E-6,1,0.999253354069792,40.0298881530762,1.99536511767525,20.2699992805719,-0.00265255338933489,-0.000463808474419751,0.25,-3.29170753422604E-7,-0.000234815345547244,-5.18975959410414E-7,250.00383,250.0038757,84514.6015625,84579.375,56.4445218877367,20.5275616698811,27.464817,0,0,0,40,4449,250.0147,84546.98828125,,,,,,,,,,,,,0,,,,0.0049,,,,,,250.00385285,,,,
,31982216.755,250.00081635,79720.31640625,-0.000219490435020749,2.75721194692536E-6,1,0.999253354069792,40.0298881530762,1.99490607686086,20.2699992805719,-0.00248790434829199,-0.000407334135573021,0.25,2.06649156816303E-6,-0.000219877634566582,1.89264799862972E-6,250.0006256,250.0010071,79690.515625,79750.1171875,56.6735390438714,20.536101425927,27.464817,0,0,0,40,4449,250.0164,79720.31640625,,,,,,,,,,,,,0,,,,-0.00245,,,,,,250.00081635,,,,
,31982312.205,249.99306485,74949.15625,-0.000198597353289455,3.0738968082525E-6,1,0.999253354069792,40.0298881530762,1.99526009315043,20.2699992805719,-0.00224764575825797,-0.000390646156261434,0.25,-7.57699282962384E-8,-0.000198946150089736,-2.3673163501139E-7,249.992691,249.9934387,74921.609375,74976.703125,56.8259566051214,20.5304016241434,27.464817,0,0,0,40,4449,250.02375,74949.15625,,,,,,,,,,,,,0,,,,-0.00245,,,,,,249.99306485,,,,
,31982407.93,249.9907837,70166.55859375,-0.000183829556952603,2.90418990208375E-6,1,0.999253354069792,40.0298881530762,1.99520972191606,20.2699992805719,-0.00208104238916592,-0.000358227279788766,0.25,2.27097613655537E-7,-0.000184152647626101,7.83966668940266E-8,249.9907837,249.9907837,70164.140625,70168.9765625,56.5648926796983,20.533469279076,27.464817,0,0,0,40,4449,250.02825,70166.55859375,,,,,,,,,,,,,0,,,,0.0049,,,,,,249.9907837,,,,
,31982503.415,249.9923401,65390.806640625,-0.000169506715448732,2.91479778362044E-6,1,0.999253354069792,40.0298881530762,1.99518618294671,20.2699992805719,-0.00191355344604851,-0.000361021396994959,0.25,-2.50366694334698E-6,-0.000169802397146637,-2.64575392300285E-6,249.9923401,249.9923401,65365.78515625,65415.828125,56.482821685179,20.5316058925772,27.844467,0,0,0,40,4449,250.03785,65390.806640625,,,,,,,,,,,,,0,,,,0,,,,,,249.9923401,,,,
,31982598.375,249.9903107,60644.6328125,-0.000155070526349743,2.57343779892484E-6,1,0.999253354069792,40.0298881530762,1.99494621899041,20.2699992805719,-0.00175211257186887,-0.000320262273763061,0.25,-1.40885354962116E-6,-0.000155341730954225,-1.53747884069271E-6,249.9903107,249.9903107,60617.3671875,60671.8984375,56.3647957787752,20.536592708236,27.085165,0,0,0,40,4449,250.0439,60644.6328125,,,,,,,,,,,,,0,,,,0.00245,,,,,,249.9903107,,,,
,31982694.31,249.991333,55849.046875,-0.000136498330071408,1.8414525931807E-6,1,0.999253354069792,40.0298881530762,1.99514967719781,20.2699992805719,-0.00154369447976159,-0.000274576270701712,0.25,-5.89931801494337E-7,-0.000136737558756937,-7.02173140693123E-7,249.991333,249.991333,55824.01953125,55874.07421875,56.6876083572175,20.5345556399469,27.464817,0,0,0,40,4449,250.0534,55849.046875,,,,,,,,,,,,,0,,,,0.00245,,,,,,249.991333,,,,
,31982790.68,249.9869232,51032.13671875,-0.000117990659694166,2.50370336650223E-6,1,0.999253354069792,40.0298881530762,1.99517037283506,20.2699992805719,-0.00133669820151283,-0.000224095099033164,0.25,6.61267217332873E-7,-0.000118198409689787,5.66161821315327E-7,249.9869232,249.9869232,51027.1875,51037.0859375,56.780622151006,20.5353127363599,27.464817,0,0,0,40,4449,250.06275,51032.13671875,,,,,,,,,,,,,0,,,,-0.0049,,,,,,249.9869232,,,,
,31982884.765,249.98953245,46329.08203125,-0.000102594415914383,2.16853704340852E-6,1,0.999253354069792,40.0298881530762,1.99518179425924,20.2699992805719,-0.00116153730226093,-0.000199152401133624,0.25,1.95364779674471E-7,-0.000102774725267668,1.11886320090986E-7,249.9890289,249.990036,46299.16015625,46359.00390625,56.5891231637945,20.5352026702777,27.464817,0,0,0,40,4449,250.0723,46329.08203125,,,,,,,,,,,,,0,,,,-0.00245,,,,,,249.98953245,,,,
,31982981.485,249.9881744,41493.880859375,-8.80676118203312E-5,1.60636730191006E-6,1,0.999253354069792,40.0298881530762,1.99491708758288,20.2699992805719,-0.000993846612505063,-0.000188790780762993,0.25,-1.41033085681942E-6,-8.82210922493211E-5,-1.48486309837144E-6,249.9881744,249.9881744,41466.51171875,41521.25,56.7626446950637,20.5383411882237,27.844467,0,0,0,40,4449,250.07555,41493.880859375,,,,,,,,,,,,,0,,,,-0.00245,,,,,,249.9881744,,,,
,31983078.485,249.98986055,36648.875,-6.96398376326558E-5,1.4175224439026E-6,1,0.999253354069792,40.0298881530762,1.99497642159846,20.2699992805719,-0.000789042263357695,-0.000131232836400893,0.25,4.80578746494581E-7,-6.97624962103774E-5,4.24365451142768E-7,249.9892426,249.9904785,36618.91796875,36678.83203125,56.5953761919483,20.5382054723131,27.085165,0,0,0,40,4449,250.08415,36648.875,,,,,,,,,,,,,0,,,,0.00245,,,,,,249.98986055,,,,
,31983173.33,249.9898987,31906.6064453125,-5.36613927087244E-5,1.23694680375254E-6,1,0.999253354069792,40.0298881530762,1.99504073835112,20.2699992805719,-0.000606834527266096,-0.000107960431294779,0.25,-2.33588655356543E-7,-5.37554064525754E-5,-2.78022201677133E-7,249.9898987,249.9898987,31876.708984375,31936.50390625,56.7649895806214,20.5372904474865,27.844467,0,0,0,40,4449,250.09245,31906.6064453125,,,,,,,,,,,,,0,,,,-0.00245,,,,,,249.9898987,,,,
,31983269.495,249.9902191,27101.673828125,-3.87474544361327E-5,1.08780223441172E-6,1,0.999253354069792,40.0298881530762,1.99492689423079,20.2699992805719,-0.000438508430677187,-7.59132828310696E-5,0.25,1.14456455550468E-8,-3.88154820055875E-5,-2.03633842318147E-8,249.9899597,249.9904785,27073.94921875,27129.3984375,56.8384626614291,20.5385171926773,27.464817,0,0,0,40,4449,250.102,27101.673828125,,,,,,,,,,,,,0,,,,0.00245,,,,,,249.9902191,,,,
,31983364.88,249.99065395,22333.908203125,-2.29753237473938E-5,1.31481304825392E-6,1,0.999253354069792,40.0298881530762,1.99527813348246,20.2699992805719,-0.000259323906914107,-4.92503176362102E-5,0.25,-3.66911979168157E-7,-2.3015350431728E-5,-3.86452349703252E-7,249.9901733,249.9911346,22306.5390625,22361.27734375,56.7493570102368,20.5342833777709,27.464817,0,0,0,40,4449,250.112,22333.908203125,,,,,,,,,,,,,0,,,,0,,,,,,249.99065395,,,,
,31983461.615,249.9896545,17498.62109375,-6.99067485684276E-6,8.42313954738559E-7,1,0.999253354069792,40.0298881530762,1.9956788707901,20.2699992805719,-7.75965350787955E-5,-2.26155865499531E-5,0.25,-7.85395366402617E-7,-7.00229828138969E-6,-7.92530425146609E-7,249.9896545,249.9896545,17463.75,17533.4921875,56.6813553290637,20.5297364475719,27.085165,0,0,0,40,4449,250.11915,17498.62109375,,,,,,,,,,,,,0,,,,0.00245,,,,,,249.9896545,,,,
,31983556.35,249.98789215,12763.7119140625,7.55728907770512E-6,6.10586860066379E-7,1,0.999253354069792,40.0298881530762,1.99526419963035,20.2699992805719,8.69503350949993E-5,6.67795608228554E-6,0.25,-7.20604978278522E-7,7.57114752168428E-6,-7.15639808584746E-7,249.9878235,249.9879608,12731.51171875,12795.912109375,56.7024592990829,20.5367087931389,27.844467,0,0,0,40,4449,250.12985,12763.7119140625,,,,,,,,,,,,,0,,,,0,,,,,,249.98789215,,,,
,31983650.515,249.9908371,8055.7626953125,2.06260336794188E-5,4.78076955579905E-7,1,0.999253354069792,40.0298881530762,1.99512952203131,20.2699992805719,0.000233522804970402,3.99896661053794E-5,0.25,-4.36676907455022E-8,2.06622678811772E-5,-2.67225091154366E-8,249.9903717,249.9913025,8028.23681640625,8083.28857421875,56.861911517006,20.5374996369083,27.085165,0,0,0,40,4449,250.12555,8055.7626953125,,,,,,,,,,,,,0,,,,-0.00245,,,,,,249.9908371,,,,
,31983747.125,249.9937592,3227.91613769531,2.78459983048961E-5,3.9133851797767E-7,1,0.999253354069792,40.0298881530762,1.99503540106081,20.2699992805719,0.00031627139080583,4.81026138600952E-5,0.25,-5.78776853168389E-7,2.78953401222731E-5,-5.5679115132124E-7,249.9937592,249.9937592,3200.4296875,3255.40258789063,56.861911517006,20.5399746951,27.464817,0,0,0,40,4449,250.13425,3227.91613769531,,,,,,,,,,,,,0,,,,-0.00245,,,,,,249.9937592,,,,
,31983839.83,249.9939728,-1403.09869384766,-1.9977231053985E-5,3.95607438583472E-7,1,0.999253354069792,40.0298881530762,1.99503288244248,20.2699992805719,-0.000225506431701538,-4.25372657286672E-5,0.25,-2.94106794109602E-7,-2.00120431279048E-5,-3.11129011221043E-7,249.9939728,249.9939728,-1435.61840820312,-1370.57897949219,56.7665528376599,20.5423087626102,27.844467,0,0,0,40,4449,250.1403,-1403.09869384766,,,,,,,,,,,,,0,,,,0.00245,,,,,,249.9939728,,,,
,31983932.85,250.003273,-6052.30249023437,-2.44047094855346E-5,4.25084212807762E-7,1,0.999253354069792,40.0298881530762,1.99518750006826,20.2699992805719,-0.000276701842813971,-4.50666126908479E-5,0.25,2.50512513921068E-7,-2.44477342741434E-5,2.30804429814337E-7,250.0026855,250.0038605,-6077.32421875,-6027.28076171875,56.8470605751406,20.5402848373265,27.464817,0,0,0,40,4449,250.13635,-6052.30249023437,,,,,,,,,,,,,0,,,,-0.00245,,,,,,250.003273,,,,
,31984026.975,250.00112915,-10758.5029296875,-1.26695328154683E-5,6.76164008729831E-7,1,0.999253354069792,40.0298881530762,1.99508734324029,20.2699992805719,-0.000141928850572605,-3.32671934882871E-5,0.25,-7.42272969577325E-7,-1.26911514642455E-5,-7.54024232193014E-7,250.0011139,250.0011444,-10790.9228515625,-10726.0830078125,56.8251749766022,20.5434775520314,27.085165,0,0,0,40,4449,250.13675,-10758.5029296875,,,,,,,,,,,,,0,,,,-0.00245,,,,,,250.00112915,,,,
,31984122.92,250.00896455,-15551.1279296875,1.98565743007621E-6,8.67512729174E-7,1,0.999253354069792,40.0298881530762,1.99506544201772,20.2699992805719,2.24503937275481E-5,4.02278833766409E-6,0.25,1.10963484786168E-8,1.98913210080025E-6,1.27516489531369E-8,250.0082245,250.0097046,-15578.689453125,-15523.56640625,56.8494054606983,20.542960116532,27.844467,0,0,0,40,4449,250.12675,-15551.1279296875,,,,,,,,,,,,,0,,,,0,,,,,,250.00896455,,,,
,31984219.76,250.01068875,-20393.5078125,1.68608762699444E-5,9.62399671045891E-7,1,0.999253354069792,40.0298881530762,1.99513178317373,20.2699992805719,0.000191835443353596,2.72655586945253E-5,0.25,-5.14932107535377E-7,1.68908829656581E-5,-5.01961342274719E-7,250.0098419,250.0115356,-20425.880859375,-20361.134765625,57.0502839901407,20.5424052065153,27.085165,0,0,0,40,4449,250.1151,-20393.5078125,,,,,,,,,,,,,0,,,,-0.00245,,,,,,250.01068875,,,,
,31984315.06,250.01006315,-25155.400390625,3.1617320773988E-5,1.06541301482496E-6,1,0.999253354069792,40.0298881530762,1.9950255076986,20.2699992805719,0.000360619218842445,4.58789469064005E-5,0.25,-1.42915748815753E-6,3.16739732849846E-5,-1.40568060627138E-6,250.0098419,250.0102844,-25187.97265625,-25122.828125,56.6493085597752,20.5442216691269,27.464817,0,0,0,40,4449,250.1115,-25155.400390625,,,,,,,,,,,,,0,,,,-0.00245,,,,,,250.01006315,,,,
,31984411.795,250.0074921,-29988.048828125,4.7800361046828E-5,1.15531736565506E-6,1,0.999253354069792,40.0298881530762,1.99494453702555,20.2699992805719,0.000540164103177886,9.82700565582663E-5,0.25,3.94139525944388E-7,4.78839214406052E-5,4.34065124946874E-7,250.0074921,250.0074921,-30020.626953125,-29955.470703125,56.8509687177368,20.5460164126231,27.464817,0,0,0,40,4449,250.10445,-29988.048828125,,,,,,,,,,,,,0,,,,-0.00245,,,,,,250.0074921,,,,
,31984509.345,250.0078735,-34864.9296875,6.36196656214542E-5,1.45987780663637E-6,1,0.999253354069792,40.0298881530762,1.9952224588637,20.2699992805719,0.000721169218302564,0.000118442590606991,0.25,-5.68014567467978E-7,6.37317831435175E-5,-5.16864284278985E-7,250.0078735,250.0078735,-34892.34765625,-34837.51171875,56.577398736006,20.542515207593,27.464817,0,0,0,40,4449,250.1012,-34864.9296875,,,,,,,,,,,,,0,,,,0,,,,,,250.0078735,,,,
,31984607.4,250.0096588,-39764.796875,8.05517344845158E-5,1.96984164626102E-6,1,0.999253354069792,40.0298881530762,1.99512042972922,20.2699992805719,0.000910422270422836,0.000165170847908676,0.25,6.25063210601287E-7,8.06925952259903E-5,6.92096594388393E-7,250.0096588,250.0096588,-39769.91015625,-39759.68359375,56.7454488676406,20.5446569739919,27.464817,0,0,0,40,4449,250.0874,-39764.796875,,,,,,,,,,,,,0,,,,-0.0049,,,,,,250.0096588,,,,
,31984704.405,250.0124512,-44615.2265625,9.73734956678229E-5,1.59246269913071E-6,1,0.999253354069792,40.0298881530762,1.99511067573202,20.2699992805719,0.00110146088021694,0.000194365701839713,0.25,2.87658033964679E-7,9.75441585191249E-5,3.67758585158626E-7,250.0124512,250.0124512,-44642.64453125,-44587.80859375,56.668849272756,20.5459190796478,27.085165,0,0,0,40,4449,250.0756,-44615.2265625,,,,,,,,,,,,,0,,,,0.0049,,,,,,250.0124512,,,,
,31984800.175,250.01499935,-49400.1328125,0.000113012591030266,1.20148432003212E-6,1,0.999253354069792,40.0298881530762,1.99489497948171,20.2699992805719,0.00127996278380238,0.000215590035701466,0.25,-5.46979828088029E-7,0.000113211387550023,-4.55691051882588E-7,250.0145721,250.0154266,-49425.1640625,-49375.1015625,56.9244417985445,20.5500326748438,27.085165,0,0,0,40,4449,250.0684,-49400.1328125,,,,,,,,,,,,,0,,,,0.00245,,,,,,250.01499935,,,,
,31984896.91,250.01235195,-54235.0078125,0.000129957256159727,2.12166909707375E-6,1,0.999253354069792,40.0298881530762,1.99497581081427,20.2699992805719,0.00147251089353355,0.000244589870342938,0.25,-9.23494147084877E-7,0.000130186127865262,-8.19186617224012E-7,250.0118713,250.0128326,-54267.3984375,-54202.6171875,56.9674313671022,20.5487638596883,27.085165,0,0,0,40,4449,250.0554,-54235.0078125,,,,,,,,,,,,,0,,,,0.00245,,,,,,250.01235195,,,,
,31984993.28,250.0126648,-59052.037109375,0.000146842192673978,1.83195676209151E-6,1,0.999253354069792,40.0298881530762,1.99516836380739,20.2699992805719,0.00166309226839935,0.000281531005600076,0.25,-5.89431446394634E-7,0.000147100448138628,-4.70951947944232E-7,250.0126648,250.0126648,-59079.578125,-59024.49609375,56.7587365524675,20.5467788193448,27.464817,0,0,0,40,4449,250.0494,-59052.037109375,,,,,,,,,,,,,0,,,,-0.00245,,,,,,250.0126648,,,,
,31985090.32,250.01678465,-63899.453125,0.000164575012923318,2.19938639433986E-6,1,0.999253354069792,40.0298881530762,1.99504634378683,20.2699992805719,0.00186284967189372,0.000321107321291435,0.25,-1.65880167119361E-7,0.00016486405012196,-3.24198770380863E-8,250.0161438,250.0174255,-63931.80078125,-63867.10546875,56.9494539111599,20.5495639124248,27.464817,0,0,0,40,4449,250.0316,-63899.453125,,,,,,,,,,,,,0,,,,-0.00245,,,,,,250.01678465,,,,
,31985188.85,250.01309205,-68824.015625,0.000180849868299015,2.61364599935333E-6,1,0.999253354069792,40.0298881530762,1.99503283547554,20.2699992805719,0.00204609400652331,0.000358398678650494,0.25,3.07395276436031E-7,0.000181167139881238,4.54685143687151E-7,250.012558,250.0136261,-68854.1640625,-68793.8671875,56.8150138058522,20.548489987805,27.844467,0,0,0,40,4449,250.02375,-68824.015625,,,,,,,,,,,,,0,,,,0.00245,,,,,,250.01309205,,,,
,31985287.45,250.01491545,-73750.94921875,0.000197092870904637,2.36928767994092E-6,1,0.999253354069792,40.0298881530762,1.99501616384768,20.2699992805719,0.00223398132157385,0.000366737993393522,0.25,-1.77193890397552E-6,0.000197440360161291,-1.61536793186233E-6,250.0148468,250.0149841,-73781.046875,-73720.8515625,56.7579549239483,20.5520405726876,27.844467,0,0,0,40,4449,250.01165,-73750.94921875,,,,,,,,,,,,,0,,,,0.00245,,,,,,250.01491545,,,,
,31985385.885,250.011673,-78670.4921875,0.000216294362286012,2.34813183645469E-6,1,0.999253354069792,40.0298881530762,1.9949904233268,20.2699992805719,0.00244658677470264,0.000431338349936813,0.25,6.07321576148308E-7,0.000216673694157179,7.83348416207711E-7,250.011673,250.011673,-78672.9609375,-78668.0234375,56.7571732954291,20.5514146115544,27.844467,0,0,0,40,4449,250.00385,-78670.4921875,,,,,,,,,,,,,0,,,,0,,,,,,250.011673,,,,
,31985481.985,250.0101929,-83475.49609375,0.000230554088585732,1.72026687984458E-6,1,0.999253354069792,40.0298881530762,1.99514300500739,20.2699992805719,0.00261459778617395,0.000422192348648064,0.25,-2.67604796279713E-6,0.000230961157804114,-2.49454271937345E-6,250.0099335,250.0104523,-83505.3203125,-83445.671875,57.1237570709483,20.5498102437319,27.844467,0,0,0,40,4449,249.993,-83475.49609375,,,,,,,,,,,,,0,,,,-0.0049,,,,,,250.0101929,,,,
,31985577,250.01680755,-88222.06640625,0.000247982031098537,2.01236899208628E-6,1,0.999253354069792,40.0298881530762,1.99513091525827,20.2699992805719,0.0028087889560064,0.000473905717313038,0.25,-1.12838050575695E-6,0.000248418431978837,-9.30391501354496E-7,250.0166321,250.016983,-88247.1640625,-88196.96875,56.9088092281599,20.5498106066323,27.085165,0,0,0,40,4449,249.98125,-88222.06640625,,,,,,,,,,,,,0,,,,0,,,,,,250.01680755,,,,
,31985685.215,250.0110474,-87181.3359375,0.000243765538392941,3.08314402235153E-6,1,0.999253354069792,40.0298881530762,1.99505986999742,20.2699992805719,0.00276272703094906,0.000455510036245659,0.25,-2.02132833046707E-6,0.00024419529701774,-1.82823176422764E-6,250.0110474,250.0110474,-87209.1484375,-87153.5234375,56.9080275996406,20.5519264619627,27.464817,0,0,0,40,4449,249.9738,-87181.3359375,,,,,,,,,,,,,0,,,,-0.00245,,,,,,250.0110474,,,,
,31985780.86,250.0025482,-82401.81640625,0.000226464409662462,2.68185833704927E-6,1,0.999253354069792,40.0298881530762,1.9949255423931,20.2699992805719,0.0025637933876926,0.000438643169261485,0.25,-5.0938224817176E-7,0.00022686259939544,-3.2729147623571E-7,250.0025482,250.0025482,-82406.5390625,-82397.09375,56.5297193963329,20.55232530505,27.844467,0,0,0,40,4449,249.97245,-82401.81640625,,,,,,,,,,,,,0,,,,-0.00245,,,,,,250.0025482,,,,
,31985880.02,249.9983826,-77446.84375,0.000213004790993803,3.42592489983213E-6,1,0.999253354069792,40.0298881530762,1.99560128969578,20.2699992805719,0.00241789217432954,0.000379865904801374,0.25,-3.3804375371963E-6,0.000213381664612766,-3.21398642022621E-6,249.9983826,249.9983826,-77449.765625,-77443.921875,56.8556584888522,20.5422205400105,27.464817,0,0,0,40,4449,249.9799,-77446.84375,,,,,,,,,,,,,0,,,,0.0049,,,,,,249.9983826,,,,
,31985975.915,249.9916077,-72652.40625,0.000193035110364295,1.92629475713024E-6,1,0.999253354069792,40.0298881530762,1.99533987641925,20.2699992805719,0.00218801641638722,0.000361043673978099,0.25,-1.57648630896186E-6,0.000193375469944574,-1.42278807597381E-6,249.9916077,249.9916077,-72682.5546875,-72622.2578125,56.9877537086022,20.5441670416887,27.464817,0,0,0,40,4449,249.9893,-72652.40625,,,,,,,,,,,,,0,,,,0.00245,,,,,,249.9916077,,,,
,31986075.39,249.9922562,-67683.0625,0.000177586772015814,2.46168691939121E-6,1,0.999253354069792,40.0298881530762,1.99513255802465,20.2699992805719,0.00201052280989404,0.000344743895960929,0.25,-3.34855463389966E-7,0.000177898960033402,-1.91269396903869E-7,249.9917603,249.9927521,-67710.46875,-67655.65625,56.8329912617945,20.5475078938123,27.464817,0,0,0,40,4449,249.9964,-67683.0625,,,,,,,,,,,,,0,,,,-0.0049,,,,,,249.9922562,,,,
,31986171.375,249.985405,-62885.728515625,0.000161250589146115,1.90837832302614E-6,1,0.999253354069792,40.0298881530762,1.99529774435492,20.2699992805719,0.00182828608424574,0.000298255713645658,0.25,-1.61183621803148E-6,0.000161535140632556,-1.4835608368753E-6,249.9852753,249.9855347,-62908.23828125,-62863.21875,56.8587850029291,20.5456111289736,27.464817,0,0,0,40,4449,250.0084,-62885.728515625,,,,,,,,,,,,,0,,,,0,,,,,,249.985405,,,,
,31986268.81,249.9887848,-58015.291015625,0.000142253472414616,1.67737182782139E-6,1,0.999253354069792,40.0298881530762,1.99508205084929,20.2699992805719,0.00160897837218609,0.00028470607097036,0.25,4.8781459782586E-7,0.000142502910798689,6.0450617172092E-7,249.9887848,249.9887848,-58045.2890625,-57985.29296875,56.6813553290637,20.5461741750916,27.464817,0,0,0,40,4449,250.0174,-58015.291015625,,,,,,,,,,,,,0,,,,0,,,,,,249.9887848,,,,
,31986365.385,249.9890976,-53188.3515625,0.000126980670927056,1.33182487406442E-6,1,0.999253354069792,40.0298881530762,1.99498056465638,20.2699992805719,0.00143791627776072,0.000244017595692591,0.25,-4.57994060036808E-7,0.000127204038464034,-3.55246751234391E-7,249.9889221,249.9892731,-53218.140625,-53158.5625,56.7008960420445,20.5481039039367,27.844467,0,0,0,40,4449,250.0235,-53188.3515625,,,,,,,,,,,,,0,,,,0.00245,,,,,,249.9890976,,,,
,31986461.965,249.98999785,-48363.3828125,0.000108931270000555,1.16447199647965E-6,1,0.999253354069792,40.0298881530762,1.99507185001065,20.2699992805719,0.00123542037095028,0.000198731024115882,0.25,-1.33055182927463E-6,0.000109123635836589,-1.24392666878707E-6,249.9898987,249.990097,-48390.74609375,-48336.01953125,56.7954730928714,20.5477336254079,28.224119,0,0,0,40,4449,250.03015,-48363.3828125,,,,,,,,,,,,,0,,,,0.00245,,,,,,249.98999785,,,,
,31986558.19,249.9916077,-43553.712890625,9.34576599756995E-5,1.14474295503199E-6,1,0.999253354069792,40.0298881530762,1.99506108398342,20.2699992805719,0.00105891817988348,0.000176301310304959,0.25,-6.29092573250651E-7,9.36222653124497E-5,-5.53765300671843E-7,249.9916077,249.9916077,-43578.75390625,-43528.671875,56.912717370756,20.5480889979913,27.844467,0,0,0,40,4449,250.04035,-43553.712890625,,,,,,,,,,,,,0,,,,0,,,,,,249.9916077,,,,
,31986655.645,249.9879608,-38683.95703125,7.82399522836764E-5,1.79257720811063E-6,1,0.999253354069792,40.0298881530762,1.99508211739606,20.2699992805719,0.000887957730459859,0.000139209996749359,0.25,-1.26770258987759E-6,7.83783626738117E-5,-1.2058525402486E-6,249.9879608,249.9879608,-38716.55859375,-38651.35546875,56.9963516223137,20.5467255274359,27.844467,0,0,0,40,4449,250.0494,-38683.95703125,,,,,,,,,,,,,0,,,,0.00245,,,,,,249.9879608,,,,
,31986750.345,249.9903412,-33951.6484375,6.12713044202336E-5,1.33145800305678E-6,1,0.999253354069792,40.0298881530762,1.99508688821001,20.2699992805719,0.000694550662157204,0.000113796561221768,0.25,-5.70637395137392E-7,6.13793384931326E-5,-5.2139136462084E-7,249.9903412,249.9903412,-33983.984375,-33919.3125,56.7220000120637,20.5446523749319,27.464817,0,0,0,40,4449,250.0489,-33951.6484375,,,,,,,,,,,,,0,,,,0,,,,,,249.9903412,,,,
,31986845.75,249.9898529,-29182.181640625,4.56642337962803E-5,1.08566023009535E-6,1,0.999253354069792,40.0298881530762,1.99496812143583,20.2699992805719,0.000516752463862552,8.97200017753318E-5,0.25,8.94647724059235E-9,4.57443887490684E-5,4.64582123030827E-8,249.9898529,249.9898529,-29207.091796875,-29157.271484375,56.7368509539291,20.5476382238461,27.844467,0,0,0,40,4449,250.06505,-29182.181640625,,,,,,,,,,,,,0,,,,-0.00245,,,,,,249.9898529,,,,
,31986942.025,249.9898529,-24369.8076171875,2.95344690478445E-5,1.04638438228441E-6,1,0.999253354069792,40.0298881530762,1.99505815233053,20.2699992805719,0.000333460301402145,6.25083686337577E-5,0.25,4.01370125860292E-7,2.95859825993486E-5,4.26356622827988E-7,249.9898529,249.9898529,-24399.58984375,-24340.025390625,56.739977468006,20.5470547881601,27.085165,0,0,0,40,4449,250.0766,-24369.8076171875,,,,,,,,,,,,,0,,,,0.00245,,,,,,249.9898529,,,,
,31987037.375,249.99132535,-19604.8271484375,1.44184772482198E-5,9.33800191058194E-7,1,0.999253354069792,40.0298881530762,1.99546623752888,20.2699992805719,0.000165560856356575,1.47420394108517E-5,0.25,-1.19812997235464E-6,1.44447707006623E-5,-1.18836419572248E-6,249.9911346,249.9915161,-19637.201171875,-19572.453125,56.8509687177368,20.5399196750962,27.844467,0,0,0,40,4449,250.0824,-19604.8271484375,,,,,,,,,,,,,0,,,,-0.00245,,,,,,249.99132535,,,,
,31987133.99,249.9869003,-14777.6826171875,-1.02440683254674E-6,6.77385159246678E-7,1,0.999253354069792,40.0298881530762,1.99492560522519,20.2699992805719,-1.14142366505966E-5,-3.03948649981423E-6,0.25,-9.09322323595924E-8,-1.02612997623231E-6,-9.19360746759348E-8,249.9859161,249.9878845,-14805.0849609375,-14750.2802734375,56.5797436215637,20.5437265844578,27.844467,0,0,0,40,4449,250.091,-14777.6826171875,,,,,,,,,,,,,0,,,,0,,,,,,249.9869003,,,,
,31987229.955,249.9910736,-9980.00732421875,-1.61073151622649E-5,5.16568161677634E-7,1,0.999253354069792,40.0298881530762,1.99577732916304,20.2699992805719,-0.000180477642883573,-4.24357117148169E-5,0.25,-9.54961975710717E-7,-1.6134795560001E-5,-9.69926573357346E-7,249.9910736,249.9910736,-10007.2158203125,-9952.798828125,56.7384142109675,20.5322684350708,27.464817,0,0,0,40,4449,250.10085,-9980.00732421875,,,,,,,,,,,,,0,,,,0,,,,,,249.9910736,,,,
,31987326.36,249.9962463,-5161.8134765625,-2.6464374299407E-5,4.44656178591509E-7,1,0.999253354069792,40.0298881530762,1.99511434016026,20.2699992805719,-0.000299536468343324,-5.17948210167887E-5,0.25,1.30848629069866E-8,-2.65108225082042E-5,-8.7480779474101E-9,249.9962463,249.9962463,-5189.23486328125,-5134.39208984375,56.9947883652753,20.5418781859535,27.844467,0,0,0,40,4449,250.09785,-5161.8134765625,,,,,,,,,,,,,0,,,,0,,,,,,249.9962463,,,,
,31987421.79,249.9929352,-389.924774169922,-2.25742343968267E-5,4.59187093981952E-7,1,0.999253354069792,40.0298881530762,1.99516005042241,20.2699992805719,-0.000255114082691914,-4.64743319023263E-5,0.25,-1.91350000019507E-7,-2.26136885907226E-5,-2.10343590402783E-7,249.9929352,249.9929352,-414.823059082031,-365.026489257812,56.8431524325445,20.5433129314153,27.464817,0,0,0,40,4449,250.10305,-389.924774169922,,,,,,,,,,,,,0,,,,0.00245,,,,,,249.9929352,,,,
,31987515.945,249.9978638,4313.35473632812,2.65298509068635E-5,3.50155789248685E-7,1,0.999253354069792,40.0298881530762,1.99514459977411,20.2699992805719,0.000299816146971147,5.4609266604142E-5,0.25,2.24168616394848E-7,2.65762162564572E-5,2.46474255633024E-7,249.9978638,249.9978638,4283.28759765625,4343.421875,56.7540467813522,20.5431044795647,27.844467,0,0,0,40,4449,250.11,4313.35473632812,,,,,,,,,,,,,0,,,,-0.00245,,,,,,249.9978638,,,,
,31987616.275,250.00029755,9327.4814453125,1.68667998937655E-5,5.83891188728955E-7,1,0.999253354069792,40.0298881530762,1.99504399477335,20.2699992805719,0.000190324037619424,3.6331388428235E-5,0.25,2.85175220384819E-7,1.68961600023854E-5,2.99592401782651E-7,249.9997253,250.0008698,9292.56640625,9362.396484375,56.8290831191983,20.5432677131048,28.224119,0,0,0,40,4449,250.1076,9327.4814453125,,,,,,,,,,,,,0,,,,0,,,,,,250.00029755,,,,
,31987714.35,250.0029678,14230.0659179688,3.74484903977238E-6,5.60550329168633E-7,1,0.999253354069792,40.0298881530762,1.9949389993389,20.2699992805719,4.25358690205486E-5,6.44390870390682E-6,0.25,-8.00242804964077E-8,3.75148593973674E-6,-7.70782680165507E-8,250.0022125,250.0037231,14210.0087890625,14250.123046875,56.8673829166406,20.545787172591,27.844467,0,0,0,40,4449,250.1035,14230.0659179688,,,,,,,,,,,,,0,,,,-0.00245,,,,,,250.0029678,,,,
,31987812.885,250.005867,19154.744140625,-1.27613046341819E-5,9.02058250618402E-7,1,0.999253354069792,40.0298881530762,1.99511919894842,20.2699992805719,-0.000144037720800228,-2.72891124807952E-5,0.25,-1.98118057473354E-7,-1.27835334078837E-5,-2.08970752154727E-7,250.0057678,250.0059662,19122.306640625,19187.181640625,56.9557069393137,20.5431676229496,27.464817,0,0,0,40,4449,250.09735,19154.744140625,,,,,,,,,,,,,0,,,,0.00245,,,,,,250.005867,,,,
,31987910.205,250.00673675,24017.5166015625,-2.76106530125056E-5,8.91779887160312E-7,1,0.999253354069792,40.0298881530762,1.99491319431041,20.2699992805719,-0.000311227644923857,-6.12575862399735E-5,0.25,-6.2486042733869E-7,-2.76585891654599E-5,-6.48657336735081E-7,250.0065613,250.0069122,23989.904296875,24045.12890625,56.5586396515444,20.5457998631245,27.844467,0,0,0,40,4449,250.0948,24017.5166015625,,,,,,,,,,,,,0,,,,0,,,,,,250.00673675,,,,
,31988009.22,250.0078278,28967.9716796875,-4.52090752563289E-5,8.75372082715302E-7,1,0.999253354069792,40.0298881530762,1.99496395759948,20.2699992805719,-0.000511762858746688,-8.78886083332713E-5,0.25,7.39283026053535E-8,-4.52884703670621E-5,3.69370871068986E-8,250.0078278,250.0078278,28933.203125,29002.740234375,56.7063674416791,20.5440998875091,27.464817,0,0,0,40,4449,250.08505,28967.9716796875,,,,,,,,,,,,,0,,,,0.00245,,,,,,250.0078278,,,,
,31988109.275,250.0094147,33970.470703125,-6.1849215749229E-5,1.11621969452121E-6,1,0.999253354069792,40.0298881530762,1.99501923112927,20.2699992805719,-0.000699523342573955,-0.000123833716787741,0.25,-2.16389819820505E-7,-6.19575776733382E-5,-2.67483943023607E-7,250.0094147,250.0094147,33940.4453125,34000.49609375,56.4836033136983,20.5439455465247,27.844467,0,0,0,40,4449,250.0784,33970.470703125,,,,,,,,,,,,,0,,,,0.00245,,,,,,250.0094147,,,,
,31988206.83,250.01351165,38845.388671875,-7.87335703501234E-5,1.15582952547172E-6,1,0.999253354069792,40.0298881530762,1.99503191873843,20.2699992805719,-0.000891568639893744,-0.000151438657266455,0.25,2.72442798488963E-7,-7.88719612131175E-5,2.08447436329592E-7,250.0130157,250.0140076,38817.609375,38873.16796875,56.4664074862752,20.5400980832538,27.844467,0,0,0,40,4449,250.06105,38845.388671875,,,,,,,,,,,,,0,,,,0,,,,,,250.01351165,,,,
,31988305.08,250.0122223,43752.76953125,-9.43232127293591E-5,1.56317012554372E-6,1,0.999253354069792,40.0298881530762,1.995163943029,20.2699992805719,-0.00106793723893152,-0.00018278581730528,0.25,2.06990798456533E-7,-9.44889243839097E-5,1.30225835310835E-7,250.0122223,250.0122223,43725.17578125,43780.36328125,56.5219031111406,20.5394159868699,28.224119,0,0,0,40,4449,250.05905,43752.76953125,,,,,,,,,,,,,0,,,,-0.0049,,,,,,250.0122223,,,,
,31988401.845,250.011528,48590.908203125,-0.000111518395623988,1.67413773623317E-6,1,0.999253354069792,40.0298881530762,1.99487646006671,20.2699992805719,-0.00126690483381216,-0.000190386069016962,0.25,2.51496422782396E-6,-0.000111716187142496,2.42831829350436E-6,250.0115204,250.0115356,48558.3203125,48623.49609375,56.8509687177368,20.540213453868,28.224119,0,0,0,40,4449,250.04835,48590.908203125,,,,,,,,,,,,,0,,,,-0.00245,,,,,,250.011528,,,,
,31988497.7,250.01654815,53383.373046875,-0.000128652399803329,1.95781583149234E-6,1,0.999253354069792,40.0298881530762,1.99490266722259,20.2699992805719,-0.00145710300238607,-0.000245421824717062,0.25,6.22975457117717E-7,-0.000128878712490555,5.19163125466689E-7,250.0163879,250.0167084,53350.74609375,53416,56.6141352764098,20.542017338234,27.844467,0,0,0,40,4449,250.02895,53383.373046875,,,,,,,,,,,,,0,,,,-0.00245,,,,,,250.01654815,,,,
,31988593.49,250.0084229,58168.7734375,-0.000145232275167837,1.64513990700923E-6,1,0.999253354069792,40.0298881530762,1.99484943912669,20.2699992805719,-0.0016429100154254,-0.000288193632895341,0.25,-2.82272361673852E-7,-0.000145487011978941,-4.01016527455926E-7,250.0084229,250.0084229,58138.8359375,58198.7109375,56.7579549239483,20.5428260551923,27.844467,0,0,0,40,4449,250.02825,58168.7734375,,,,,,,,,,,,,0,,,,0,,,,,,250.0084229,,,,
,31988691.58,250.0123596,63074.43359375,-0.000160721686957276,1.9511185891322E-6,1,0.999253354069792,40.0298881530762,1.99501006280943,20.2699992805719,-0.00182065298527256,-0.000305215975362641,0.25,9.01427286129758E-7,-0.000161004578167225,7.72343495278617E-7,250.0123596,250.0123596,63071.98046875,63076.88671875,56.3952792910252,20.5380226503337,27.844467,0,0,0,40,4449,250.0121,63074.43359375,,,,,,,,,,,,,0,,,,-0.0049,,,,,,250.0123596,,,,
,31988786.7,250.0100708,67827.2578125,-0.000179410521494132,2.14443293242286E-6,1,0.999253354069792,40.0298881530762,1.9947636940578,20.2699992805719,-0.00203118627708048,-0.000346055039650609,0.25,5.29832356221659E-7,-0.000179725958706707,3.85124431475422E-7,250.0100708,250.0100708,67804.7578125,67849.7578125,56.4367056025444,20.5420596425564,27.844467,0,0,0,40,4449,250.0107,67827.2578125,,,,,,,,,,,,,0,,,,-0.00245,,,,,,250.0100708,,,,
,31988884.28,250.0140076,72704.90625,-0.000193292309050396,2.29750685160297E-6,1,0.999253354069792,40.0298881530762,1.99471769769124,20.2699992805719,-0.00218939896913044,-0.000366485145321614,0.25,1.13066284557602E-6,-0.000193632605631223,9.75983705173866E-7,250.0140076,250.0140076,72702.4921875,72707.3203125,56.6461820456983,20.5441252640461,27.464817,0,0,0,40,4449,250.0013,72704.90625,,,,,,,,,,,,,0,,,,0.0049,,,,,,250.0140076,,,,
,31988980.24,250.0108032,77500.4453125,-0.000211054230439187,1.65693990785131E-6,1,0.999253354069792,40.0298881530762,1.99470025613933,20.2699992805719,-0.00238954565450042,-0.000406047228312937,0.25,7.13902707050833E-7,-0.000211425427491699,5.44357858817673E-7,250.0108032,250.0108032,77470.2421875,77530.6484375,56.5859966497175,20.5433348441737,27.464817,0,0,0,40,4449,249.99065,77500.4453125,,,,,,,,,,,,,0,,,,0.00245,,,,,,250.0108032,,,,
,31989080.4,250.0137787,82506.265625,-0.000226488087861177,1.78632138566305E-6,1,0.999253354069792,40.0298881530762,1.99473367741208,20.2699992805719,-0.00256728737947382,-0.000418682070157736,0.25,2.27395414195664E-6,-0.000226887655091943,2.09495234313957E-6,250.0137787,250.0137787,82503.71875,82508.8125,56.6094455052945,20.5435546746367,27.085165,0,0,0,40,4449,249.9761,82506.265625,,,,,,,,,,,,,0,,,,0,,,,,,250.0137787,,,,
,31989174.895,250.01215365,87232.09375,-0.000243846027412129,1.84429146720784E-6,1,0.999253354069792,40.0298881530762,1.99472109186414,20.2699992805719,-0.00275895094609322,-0.000480039212829209,0.25,-1.39002378859251E-7,-0.000244274174864986,-3.35959481249959E-7,250.012085,250.0122223,87202.2109375,87261.9765625,56.5852150211983,20.5445805526822,27.464817,0,0,0,40,4449,249.96855,87232.09375,,,,,,,,,,,,,0,,,,0,,,,,,250.01215365,,,,
,31989282.92,250.01211545,88145.453125,-0.000248634894931231,2.47152257964159E-6,1,0.999253354069792,40.0298881530762,1.99521055572283,20.2699992805719,-0.00281689677009291,-0.000471680549067155,0.25,1.43982645869022E-6,-0.000249072731935968,1.24182725860522E-6,250.0116577,250.0125732,88117.96875,88172.9375,56.7087123272368,20.5370464354368,27.844467,0,0,0,40,4449,249.95365,88145.453125,,,,,,,,,,,,,0,,,,-0.00245,,,,,,250.01211545,,,,
,31989378.245,250.0075226,83379.5625,-0.000232742765750227,3.22738229574286E-6,1,0.999253354069792,40.0298881530762,1.99486757641286,20.2699992805719,-0.00263620730994028,-0.00044265763002242,0.25,1.24221862890484E-6,-0.000233152538596735,1.05638566423635E-6,250.0075226,250.0075226,83349.7109375,83409.4140625,56.6579064734868,20.5438356267666,27.464817,0,0,0,40,4449,249.95185,83379.5625,,,,,,,,,,,,,0,,,,-0.00245,,,,,,250.0075226,,,,
,31989472.585,249.99608615,78666.00390625,-0.000214540862877946,2.26058778571999E-6,1,0.999253354069792,40.0298881530762,1.99482193919229,20.2699992805719,-0.00242946017395969,-0.000411070922876789,0.25,8.76634549437655E-7,-0.000214918431584452,7.04597204634254E-7,249.9954224,249.9967499,78636.4375,78695.5703125,56.4367056025444,20.5436942855017,27.844467,0,0,0,40,4449,249.9606,78666.00390625,,,,,,,,,,,,,0,,,,0,,,,,,249.99608615,,,,
,31989568.78,249.9904404,73857.4609375,-0.000200961029693519,2.36593760707874E-6,1,0.999253354069792,40.0298881530762,1.99492339120698,20.2699992805719,-0.00227571200878075,-0.00038553596644907,0.25,7.80224097536779E-7,-0.000201314679866758,6.18750939923213E-7,249.9901276,249.9907532,73827.3671875,73887.5546875,56.5758354789675,20.5440739982826,27.844467,0,0,0,40,4449,249.96785,73857.4609375,,,,,,,,,,,,,0,,,,-0.00245,,,,,,249.9904404,,,,
,31989665.69,249.9893036,69011.5625,-0.000181400074703814,1.83537171243063E-6,1,0.999253354069792,40.0298881530762,1.99471618754178,20.2699992805719,-0.00205837543758239,-0.000322725889606713,0.25,2.93585660709646E-6,-0.000181721095746634,2.79379160116762E-6,249.9893036,249.9893036,68979.1640625,69043.9609375,56.445303516256,20.5456389458627,28.224119,0,0,0,40,4449,249.974,69011.5625,,,,,,,,,,,,,0,,,,-0.00245,,,,,,249.9893036,,,,
,31989763.59,249.9864655,64118.732421875,-0.000166481940822446,2.21926066880798E-6,1,0.999253354069792,40.0298881530762,1.99477862517841,20.2699992805719,-0.00188749100372746,-0.000305780637374751,0.25,1.84743603462254E-6,-0.000166775870585534,1.71536146627234E-6,249.9864655,249.9864655,64091.296875,64146.16796875,56.5609845371021,20.5466872402464,27.844467,0,0,0,40,4449,249.9878,64118.732421875,,,,,,,,,,,,,0,,,,0,,,,,,249.9864655,,,,
,31989858.17,249.990181,59390.75,-0.000148113412985071,2.33428301394331E-6,1,0.999253354069792,40.0298881530762,1.99472848976799,20.2699992805719,-0.00168043781572846,-0.000264880352124455,0.25,2.27617454199355E-6,-0.00014837539018925,2.15960639296594E-6,249.9901276,249.9902344,59358.52734375,59422.97265625,56.9142806277945,20.5475085690003,28.224119,0,0,0,40,4449,249.99695,59390.75,,,,,,,,,,,,,0,,,,0.00245,,,,,,249.990181,,,,
,31989952.75,249.9865112,54662.365234375,-0.000134109611717112,1.78798365022602E-6,1,0.999253354069792,40.0298881530762,1.99482939020153,20.2699992805719,-0.00152130180745619,-0.000241738136658221,0.25,1.8940980365053E-6,-0.000134346686168605,1.78810154890996E-6,249.9864349,249.9865875,54635.01171875,54689.71875,56.546915223756,20.5456507571922,27.464817,0,0,0,40,4449,250.0081,54662.365234375,,,,,,,,,,,,,0,,,,0,,,,,,249.9865112,,,,
,31990050.775,249.9882355,49765.138671875,-0.000115855124400132,2.13418313669125E-6,1,0.999253354069792,40.0298881530762,1.99484445688176,20.2699992805719,-0.00131038936941426,-0.000231023963968209,0.25,-3.24403939266999E-7,-0.000116058308021655,-4.19554307785589E-7,249.9882355,249.9882355,49757.546875,49772.73046875,56.6071006197368,20.5459566000217,27.085165,0,0,0,40,4449,250.0187,49765.138671875,,,,,,,,,,,,,0,,,,0,,,,,,249.9882355,,,,
,31990146.03,249.9877243,45005.21875,-9.97616048545614E-5,1.50046463213996E-6,1,0.999253354069792,40.0298881530762,1.99472715914125,20.2699992805719,-0.00112880017079395,-0.00019602977769953,0.25,-2.37090311674744E-8,-9.99367618525828E-5,-1.05307668511938E-7,249.9875183,249.9879303,44980.33203125,45030.10546875,56.6313311038329,20.550303886426,28.224119,0,0,0,40,4449,250.02695,45005.21875,,,,,,,,,,,,,0,,,,-0.00245,,,,,,249.9877243,,,,
,31990242.51,249.9898224,40180.03125,-8.25700472433335E-5,1.55259104782694E-6,1,0.999253354069792,40.0298881530762,1.99486366520959,20.2699992805719,-0.000937115459622151,-0.000146248783142213,0.25,1.39529885060968E-6,-8.27161618093043E-5,1.33015277510201E-6,249.9898224,249.9898224,40177.67578125,40182.38671875,56.7946914643522,20.5444627542817,28.224119,0,0,0,40,4449,250.0385,40180.03125,,,,,,,,,,,,,0,,,,0,,,,,,249.9898224,,,,
,31990336.86,249.9911957,35464.357421875,-6.55700980174405E-5,1.06233442512882E-6,1,0.999253354069792,40.0298881530762,1.99472437749524,20.2699992805719,-0.000744530825935937,-0.000113805190213602,0.25,1.31360470315604E-6,-6.56862882536927E-5,1.26215984015733E-6,249.9911957,249.9911957,35439.54296875,35489.171875,56.4367056025444,20.5481690100303,27.844467,0,0,0,40,4449,250.0447,35464.357421875,,,,,,,,,,,,,0,,,,0,,,,,,249.9911957,,,,
,31990433.9,249.9904251,30617.0205078125,-5.01472037919674E-5,1.1966850754427E-6,1,0.999253354069792,40.0298881530762,1.99564617134105,20.2699992805719,-0.000567250698935553,-0.000100963007382456,0.25,-2.2210999974369E-7,-5.0235053932518E-5,-2.63663945786425E-7,249.9897919,249.9910583,30587.00390625,30647.037109375,56.8048526351022,20.5269560005906,27.464817,0,0,0,40,4449,250.0478,30617.0205078125,,,,,,,,,,,,,0,,,,0,,,,,,249.9904251,,,,
,31990528.6,249.9936829,25881.7841796875,-3.54837099981764E-5,8.8829568728923E-7,1,0.999253354069792,40.0298881530762,1.99533243197015,20.2699992805719,-0.000401383314002045,-7.10713924985276E-5,0.25,-1.25463022950925E-7,-3.5545889603346E-5,-1.54847496223808E-7,249.9936829,249.9936829,25849.302734375,25914.265625,56.7165286124291,20.5394310128829,27.464817,0,0,0,40,4449,250.05515,25881.7841796875,,,,,,,,,,,,,0,,,,-0.00245,,,,,,249.9936829,,,,
,31990624.76,249.9871216,21074.16015625,-1.8920384416541E-5,7.67055140119825E-7,1,0.999253354069792,40.0298881530762,1.99513283558732,20.2699992805719,-0.000214513052802005,-3.49485749185608E-5,0.25,1.93247131278991E-7,-1.8953755758545E-5,1.78016917432035E-7,249.9871216,249.9871216,21046.951171875,21101.369140625,56.6242964471598,20.5434029111192,27.464817,0,0,0,40,4449,250.0713,21074.16015625,,,,,,,,,,,,,0,,,,0.00245,,,,,,249.9871216,,,,
,31990720.915,249.9909973,16269.9013671875,-3.14410505383585E-6,6.09764038889789E-7,1,0.999253354069792,40.0298881530762,1.99490560565604,20.2699992805719,-3.53390775131097E-5,-7.5590927961978E-6,0.25,-1.2271493851201E-7,-3.1495222442269E-6,-1.25520680980698E-7,249.9909973,249.9909973,16239.91796875,16299.884765625,56.6930797568522,20.5480571211705,27.844467,0,0,0,40,4449,250.0756,16269.9013671875,,,,,,,,,,,,,0,,,,0,,,,,,249.9909973,,,,
,31990818.265,249.9902344,11404.744140625,1.15901441827645E-5,6.09393471193391E-7,1,0.999253354069792,40.0298881530762,1.99485526261985,20.2699992805719,0.000130829936040409,2.46220750898425E-5,0.25,1.65824293723791E-7,1.16103486335549E-5,1.75675123617568E-7,249.9902344,249.9902344,11377.2509765625,11432.2373046875,56.7352876968906,20.548657624996,27.464817,0,0,0,40,4449,250.07995,11404.744140625,,,,,,,,,,,,,0,,,,0,,,,,,249.9902344,,,,
,31990912.905,249.99209595,6674.47216796875,2.36803571121843E-5,4.40979837565369E-7,1,0.999253354069792,40.0298881530762,1.9950318869157,20.2699992805719,0.0002674874317143,4.93868774665277E-5,0.25,2.57149362854879E-7,2.3721701118454E-5,2.77152309461688E-7,249.9919586,249.9922333,6644.35693359375,6704.58740234375,56.7321611828137,20.5470614817307,27.844467,0,0,0,40,4449,250.08745,6674.47216796875,,,,,,,,,,,,,0,,,,0,,,,,,249.99209595,,,,
,31991008.57,249.9936523,1891.33935546875,2.78314033873545E-5,4.14755634364714E-7,1,0.999253354069792,40.0298881530762,1.99511402805456,20.2699992805719,0.000314625734675306,5.66809671134726E-5,0.25,1.81556662163411E-7,2.78800904747808E-5,2.04874412279717E-7,249.9936523,249.9936523,1886.27685546875,1896.40185546875,56.6360208749483,20.5453272842326,27.464817,0,0,0,40,4449,250.092,1891.33935546875,,,,,,,,,,,,,0,,,,0.0049,,,,,,249.9936523,,,,
,31991046.83,249.9928894,-0.608950927853584,1.35438651804578E-5,4.10389734109022E-7,1,0.999253354069792,40.0298881530762,1.99505159180537,20.2699992805719,0.000154283372923442,2.07865404520315E-5,0.25,-5.12139734405134E-7,1.35680546503935E-5,-5.018434344585E-7,249.9928894,249.9928894,-0.974321484565735,-0.243580371141434,56.780622151006,20.5463375091725,27.844467,0,0,0,40,4417,250.0952,-0.608950927853584,,,,,,,,,,,,,0,,,,0,,,,,,249.9928894,,,,