File: data/monolayers/magneticStructure/ML_Ac_CoFe_C-2/PPMS/data/DD175_23_HYST_100OE_200K.DAT
[Header]
; VSM Data File (default extension .dat)
; Copyright (c) 2003-2013, Quantum Design, Inc. All rights reserved.
TITLE,
FILEOPENTIME,31967918.69,01/06/2019,8:00 am
BYAPP,VSM,2.0,2.0
INFO,PPMS VSM Option Release 1.4.10 Build 1,APPNAME
INFO,Quantum Design Linear Motor Servo Controller,MOTOR_MODULE_NAME
INFO,3101-100 M1,MOTOR_HW_VERSION
INFO,MMC1014,MOTOR_SERIAL_NUMBER
INFO,SRV No X-over 01.03.11,MOTOR_SOFTWARE_VERSION
INFO,Quantum Design VSM Detection Module,VSM_MODULE_NAME
INFO,3101-150 F0,VSM_HW_VERSION
INFO,VSM707,VSM_SERIAL_NUMBER
INFO,VSM No X-over 01.02.05 May 20 2008 13:51:47,VSM_SOFTWARE_VERSION
INFO,704,PREAMP_SERIAL_NUMBER
INFO,822,COIL_SERIAL_NUMBER
INFO,0,MOMENT_UNITS
INFO,CoFe2O4 Monolayer,SAMPLE_MATERIAL
INFO,from YF45,SAMPLE_COMMENT
INFO,29.98,SAMPLE_MASS
INFO,,SAMPLE_VOLUME
INFO,,SAMPLE_MOLECULAR_WEIGHT
INFO,,SAMPLE_SIZE
INFO,,SAMPLE_SHAPE
DATATYPE,COMMENT,1
DATATYPE,TIME,2
STARTUPAXIS,X,2
STARTUPAXIS,Y1,5
[Data]
Comment,Time Stamp (sec),Temperature (K),Magnetic Field (Oe),Moment (emu),M. Std. Err. (emu),Transport Action,Averaging Time (sec),Frequency (Hz),Peak Amplitude (mm),Center Position (mm),Coil Signal' (mV),Coil Signal" (mV),Range (mV),M. Quad. Signal (emu),M. Raw' (emu),M. Raw" (emu),Min. Temperature (K),Max. Temperature (K),Min. Field (Oe),Max. Field (Oe),Mass (grams),Motor Lag (deg),Pressure (Torr),VSM Status (code),Motor Status (code),Measure Status (code),Measure Count,PPMS Status (code),System Temp. (K),System Field (Oe),Sample Position (deg),Bridge 1 Resistance (ohms),Bridge 1 Excitation (에),Bridge 2 Resistance (ohms),Bridge 2 Excitation (에),Bridge 3 Resistance (ohms),Bridge 3 Excitation (에),Bridge 4 Resistance (ohms),Bridge 4 Excitation (에),Signal 1 Vin (V),Signal 2 Vin (V),Digital Inputs (code),Drive 1 Iout (mA),Drive 1 Ipower (W),Drive 2 Iout (mA),Drive 2 Ipower (W),Pressure (),Map 20 (),Map 21 (),Map 22 (),Map 23 (),Map 24 (),Map 25 (),Map 26 (),Map 27 (),Map 28 (),Map 29 ()
,31967934.09,199.991745,-0.0913426354527473,,,2,,,,20.5900001507998,,,,,,,199.991745,199.991745,-0.0913426354527473,-0.0913426354527473,,,26.705515,,,,-99999999,4369,199.9243,-0.0913426354527473,,,,,,,,,,,,,,,,,,,,,,,199.991745,,,,
,31968074.64,199.9813919,4593.65356445313,2.68916348645823E-5,5.30953537906756E-7,1,0.999253354069792,40.0298881530762,2.00779385614911,20.5799993127584,0.000306536017884767,5.41958228773419E-5,0.25,8.11390637355121E-8,2.69843837753057E-5,1.10609377336517E-7,199.9811859,199.9815979,4566.43896484375,4620.8681640625,56.228792416429,20.5230083060811,26.705515,0,0,0,40,4449,199.95075,4593.65356445313,,,,,,,,,,,,,0,,,,0,,,,,,199.9813919,,,,
,31968174.405,199.98325345,9579.88916015625,1.67640623550704E-5,5.50711791416837E-7,1,0.999253354069792,40.0298881530762,2.00779763702058,20.5799993127584,0.000190139210617636,3.92758587880282E-5,0.25,5.32022198517093E-7,1.68213627762855E-5,5.52028074162612E-7,199.983139,199.9833679,9552.4755859375,9607.302734375,55.9935222321405,20.5223358856388,26.325863,0,0,0,40,4449,199.9655,9579.88916015625,,,,,,,,,,,,,0,,,,0.00245,,,,,,199.98325345,,,,
,31968271.345,199.98867035,14425.0478515625,2.7952028836655E-6,7.36125835227657E-7,1,0.999253354069792,40.0298881530762,2.00786825309189,20.5799993127584,3.32148184629634E-5,-2.1468438103886E-6,0.25,-6.73723347118434E-7,2.80558241250138E-6,-6.73024718303998E-7,199.9883575,199.9889832,14395.126953125,14454.96875,56.7032409276022,20.527291529242,25.946213,0,0,0,40,4449,199.97025,14425.0478515625,,,,,,,,,,,,,0,,,,0,,,,,,199.98867035,,,,
,31968370.345,199.9924469,19372.1435546875,-1.27665654627368E-5,7.54248829520035E-7,1,0.999253354069792,40.0298881530762,2.00791263674505,20.5799993127584,-0.00014659271767398,-1.96321467291007E-5,0.25,4.96090649694433E-7,-1.28111801100931E-5,4.84012745865528E-7,199.9924469,199.9924469,19366.990234375,19377.296875,56.401532319179,20.5256876948544,25.946213,0,0,0,40,4449,199.9751,19372.1435546875,,,,,,,,,,,,,0,,,,-0.0049,,,,,,199.9924469,,,,
,31968467.43,199.9964905,24224.552734375,-2.92506106618714E-5,1.18432669582352E-6,1,0.999253354069792,40.0298881530762,2.00802940132175,20.5799993127584,-0.000335428801088621,-4.76401787596299E-5,0.25,9.03661771214676E-7,-2.93525821838266E-5,8.75240938331476E-7,199.9964905,199.9964905,24219.794921875,24229.310546875,56.6227331901214,20.5236630885466,26.705515,0,0,0,40,4449,199.9795,24224.552734375,,,,,,,,,,,,,0,,,,0.0049,,,,,,199.9964905,,,,
,31968561.735,199.9989929,28937.76171875,-4.42204233014793E-5,1.27276287264968E-6,1,0.999253354069792,40.0298881530762,2.00782009954345,20.5799993127584,-0.000506954252844887,-7.25278840560214E-5,0.25,1.32101410762981E-6,-4.43745389916658E-5,1.27797575476605E-6,199.9989929,199.9989929,28907.8984375,28967.625,56.841589175506,20.5332929485235,25.946213,0,0,0,40,4449,199.97595,28937.76171875,,,,,,,,,,,,,0,,,,-0.00245,,,,,,199.9989929,,,,
,31968659.51,200.0040207,33822.919921875,-6.05119701589951E-5,1.20593399306647E-6,1,0.999253354069792,40.0298881530762,2.0076315040411,20.5799993127584,-0.000693372877685838,-0.000100907731108712,0.25,1.6612915561735E-6,-6.07227115103721E-5,1.6020137489843E-6,200.0039978,200.0040436,33790.46484375,33855.375,56.4460851447752,20.5333652722039,26.705515,0,0,0,40,4449,199.97315,33822.919921875,,,,,,,,,,,,,0,,,,0,,,,,,200.0040207,,,,
,31968753.54,200.0045624,38522.779296875,-7.73702448694759E-5,1.42619505066936E-6,1,0.999253354069792,40.0298881530762,2.00741611109191,20.5799993127584,-0.000881748788492304,-0.00015608649463678,0.25,-2.50838865908197E-7,-7.76371675623049E-5,-3.34677685681295E-7,200.0045624,200.0045624,38492.6640625,38552.89453125,56.3421285517175,20.5362746961204,26.325863,0,0,0,40,4449,199.972,38522.779296875,,,,,,,,,,,,,0,,,,0.00245,,,,,,200.0045624,,,,
,31968848.575,200.0079651,43273.0703125,-9.46123050098717E-5,1.40034634432837E-6,1,0.999253354069792,40.0298881530762,2.00765563265545,20.5799993127584,-0.00107736648181372,-0.000196673664925038,0.25,-8.13876064293145E-7,-9.49381867115381E-5,-9.1795944338292E-7,200.0079651,200.0079651,43270.625,43275.515625,56.5242479966983,20.5350872856825,26.325863,0,0,0,40,4449,199.96355,43273.0703125,,,,,,,,,,,,,0,,,,0,,,,,,200.0079651,,,,
,31968942.46,200.0079727,47965.61328125,-0.000110582528586887,1.88707152121234E-6,1,0.999253354069792,40.0298881530762,2.0076027960553,20.5799993127584,-0.00125971751059963,-0.000226833768869301,0.25,-6.85603832085017E-7,-0.000110963736327983,-8.06114876679736E-7,200.0077667,200.0081787,47933.1015625,47998.125,56.6782288149868,20.5314978212301,26.325863,0,0,0,40,4449,199.955,47965.61328125,,,,,,,,,,,,,0,,,,0.00245,,,,,,200.0079727,,,,
,31969035.935,200.0113144,52638.435546875,-0.000125343829346714,1.74162404054598E-6,1,0.999253354069792,40.0298881530762,2.0077779525853,20.5799993127584,-0.00143106596962913,-0.000239435615545813,0.25,7.74491430374667E-7,-0.000125777602803411,6.43509449889907E-7,200.0102844,200.0123444,52605.91015625,52670.9609375,56.5086154263137,20.5340776388634,26.705515,0,0,0,40,4449,199.9458,52638.435546875,,,,,,,,,,,,,0,,,,0,,,,,,200.0113144,,,,
,31969130.655,200.010437,57371.173828125,-0.000143645488841671,2.22521684011094E-6,1,0.999253354069792,40.0298881530762,2.00738162517368,20.5799993127584,-0.001642649939109,-0.000257416304591464,0.25,2.37184046287489E-6,-0.000144144224120872,2.22716399752289E-6,200.010437,200.010437,57368.82421875,57373.5234375,56.6727574153522,20.5389815701791,26.705515,0,0,0,40,4449,199.9374,57371.173828125,,,,,,,,,,,,,0,,,,-0.0049,,,,,,200.010437,,,,
,31969223.805,200.0109406,62028.69921875,-0.000158188550575981,2.28287386962597E-6,1,0.999253354069792,40.0298881530762,2.00754483749485,20.5799993127584,-0.0018045594436213,-0.000309627951760688,0.25,3.20440514725098E-7,-0.000158735384706689,1.53528782553538E-7,200.0109406,200.0109406,62001.3359375,62056.0625,56.5375356815252,20.535025601955,26.325863,0,0,0,40,4449,199.92475,62028.69921875,,,,,,,,,,,,,0,,,,-0.0049,,,,,,200.0109406,,,,
,31969318.73,200.0137024,66772.06640625,-0.000174507790855893,2.14443335208805E-6,1,0.999253354069792,40.0298881530762,2.00742259222327,20.5799993127584,-0.00198692200149226,-0.000362777647491147,0.25,-1.5084321328925E-6,-0.000175109102733643,-1.69861607409457E-6,200.0137024,200.0137024,66769.4921875,66774.640625,56.6829185861022,20.5362544502891,26.325863,0,0,0,40,4449,199.9179,66772.06640625,,,,,,,,,,,,,0,,,,-0.0049,,,,,,200.0137024,,,,
,31969412.255,200.01194,71447.48828125,-0.000191505459801973,2.71322142434964E-6,1,0.999253354069792,40.0298881530762,2.00749391440329,20.5799993127584,-0.00218321127769027,-0.000382686823234743,0.25,-3.01764149888295E-7,-0.000192166848212705,-5.05379983072621E-7,200.0118713,200.0120087,71422.5546875,71472.421875,56.8071975206598,20.5337352519182,26.325863,0,0,0,40,4449,199.9122,71447.48828125,,,,,,,,,,,,,0,,,,-0.00245,,,,,,200.01194,,,,
,31969506.72,200.0137634,76170.38671875,-0.000209945311049691,2.15742654176625E-6,1,0.999253354069792,40.0298881530762,2.00723630796903,20.5799993127584,-0.00239106203178569,-0.000431438196156052,0.25,-1.37969898916752E-6,-0.000210669330291569,-1.60608934939594E-6,200.0137634,200.0137634,76140.3671875,76200.40625,56.7165286124291,20.5386079564734,26.705515,0,0,0,40,4449,199.8995,76170.38671875,,,,,,,,,,,,,0,,,,0.00245,,,,,,200.0137634,,,,
,31969599.14,200.0119781,80788.921875,-0.000226040250783202,2.55388656353578E-6,1,0.999253354069792,40.0298881530762,2.00727565242,20.5799993127584,-0.0025821534841484,-0.000419966443029208,0.25,2.42168258147235E-6,-0.000226823978348664,2.19193018125824E-6,200.0119781,200.0119781,80763.7421875,80814.1015625,56.679010443506,20.5401021633136,26.325863,0,0,0,40,4449,199.89205,80788.921875,,,,,,,,,,,,,0,,,,0,,,,,,200.0119781,,,,
,31969690.75,200.01145935,85367.59375,-0.000244312546870398,1.75656908837575E-6,1,0.999253354069792,40.0298881530762,2.00724418159445,20.5799993127584,-0.00278910350338518,-0.000463935480916422,0.25,1.7375057539315E-6,-0.000245158777372625,1.48666849570355E-6,200.0111542,200.0117645,85337.75,85397.4375,56.3530713509867,20.5369576186093,26.325863,0,0,0,40,4449,199.883,85367.59375,,,,,,,,,,,,,0,,,,0,,,,,,200.01145935,,,,
,31969780.575,200.01407625,89860.42578125,-0.000260007137766399,3.05335054911631E-6,1,0.999253354069792,40.0298881530762,2.00767533525318,20.5799993127584,-0.00295588209607759,-0.000568710346137431,0.25,-4.7164810474575E-6,-0.000260900893121643,-5.00557928811385E-6,200.0139008,200.0142517,89830.4375,89890.4140625,56.0615239133136,20.5264032171712,25.946213,0,0,0,40,4449,199.8686,89860.42578125,,,,,,,,,,,,,0,,,,-0.00245,,,,,,200.01407625,,,,
,31969884.625,200.00809475,85661.53125,-0.000244228638908257,3.4208081204858E-6,1,0.999253354069792,40.0298881530762,2.00745124977265,20.5799993127584,-0.00277981873361016,-0.00051335377013174,0.25,-2.60679952238278E-6,-0.000245070040952056,-2.87255450576467E-6,200.0080566,200.0081329,85629.171875,85693.890625,56.6579064734868,20.5346455137341,26.325863,0,0,0,40,4449,199.8665,85661.53125,,,,,,,,,,,,,0,,,,0,,,,,,200.00809475,,,,
,31969975.57,199.9994202,81115.3359375,-0.000223936786109095,2.87902354820178E-6,1,0.999253354069792,40.0298881530762,2.00737308320298,20.5799993127584,-0.00254964510212502,-0.000465595332265647,0.25,-1.94346347123726E-6,-0.000224708740718112,-2.18607491537013E-6,199.9994202,199.9994202,81085.515625,81145.15625,56.6844818431406,20.5379719630111,26.325863,0,0,0,40,4449,199.8754,81115.3359375,,,,,,,,,,,,,0,,,,-0.00245,,,,,,199.9994202,,,,
,31970069.68,199.9958649,76411.3125,-0.000213146420049461,2.1372161464028E-6,1,0.999253354069792,40.0298881530762,2.00726599830207,20.5799993127584,-0.00243033979539254,-0.000421987398143426,0.25,5.62441226748003E-9,-0.000213883089420594,-2.19359403779352E-7,199.9958649,199.9958649,76386.109375,76436.515625,56.4742237714675,20.5407341248187,25.946213,0,0,0,40,4449,199.88055,76411.3125,,,,,,,,,,,,,0,,,,-0.0049,,,,,,199.9958649,,,,
,31970163,199.9911041,71747.69921875,-0.000193705871042086,2.09321573228794E-6,1,0.999253354069792,40.0298881530762,2.00768701912428,20.5799993127584,-0.00220537916300703,-0.000405094026017342,0.25,-1.881310530543E-6,-0.000194373324760532,-2.09271702190332E-6,199.9911041,199.9911041,71722.8046875,71772.59375,56.7102755842752,20.5361595037033,25.946213,0,0,0,40,4449,199.8869,71747.69921875,,,,,,,,,,,,,0,,,,0,,,,,,199.9911041,,,,
,31970255.51,199.9883118,67122.14453125,-0.000174695059308111,3.00509059652455E-6,1,0.999253354069792,40.0298881530762,2.00759892721953,20.5799993127584,-0.00199326426543768,-0.000339924436808906,0.25,5.30751366669135E-7,-0.000175299327130791,3.47418541953928E-7,199.9883118,199.9883118,67094.546875,67149.7421875,56.6539983308906,20.5353156550901,26.325863,0,0,0,40,4449,199.896,67122.14453125,,,,,,,,,,,,,0,,,,0,,,,,,199.9883118,,,,
,31970351.85,199.99002075,62306.6015625,-0.000161758125176942,2.3841422915211E-6,1,0.999253354069792,40.0298881530762,2.00744649946126,20.5799993127584,-0.00184192482269769,-0.000335430158057387,0.25,-1.32362259426689E-6,-0.000162315656450935,-1.50000978190668E-6,199.9896393,199.9904022,62276.33203125,62336.87109375,56.7884384361983,20.5401027237259,26.325863,0,0,0,40,4449,199.90165,62306.6015625,,,,,,,,,,,,,0,,,,0,,,,,,199.99002075,,,,
,31970449.695,199.99201205,57415.25,-0.00014441902302318,2.18848480379921E-6,1,0.999253354069792,40.0298881530762,2.00745367777435,20.5799993127584,-0.00164576521938498,-0.000292138827023366,0.25,-5.38006103388182E-7,-0.000144917418189364,-6.93582481022999E-7,199.9919434,199.9920807,57382.87109375,57447.62890625,56.6758839294291,20.5387488242548,26.325863,0,0,0,40,4449,199.90825,57415.25,,,,,,,,,,,,,0,,,,0,,,,,,199.99201205,,,,
,31970548,199.9892731,52500.6328125,-0.000127569647310911,1.69930805921523E-6,1,0.999253354069792,40.0298881530762,2.0075178078502,20.5799993127584,-0.00145825834234605,-0.000232378138299643,0.25,1.77739103401507E-6,-0.000128012267353117,1.6474695855034E-6,199.9892731,199.9892731,52475.62109375,52525.64453125,56.7235632691022,20.5396290221761,25.946213,0,0,0,40,4449,199.9179,52500.6328125,,,,,,,,,,,,,0,,,,0.00245,,,,,,199.9892731,,,,
,31970648.445,199.98924255,47482.876953125,-0.000108471612596704,1.87997439164634E-6,1,0.999253354069792,40.0298881530762,2.00749453855771,20.5799993127584,-0.00123950918750086,-0.00020002870028818,0.25,1.29745134734818E-6,-0.000108847709249527,1.18599956892987E-6,199.9890594,199.9894257,47458.03515625,47507.71875,56.9338213407753,20.5399995694872,26.325863,0,0,0,40,4449,199.92345,47482.876953125,,,,,,,,,,,,,0,,,,-0.00245,,,,,,199.98924255,,,,
,31970744.665,199.9901276,42672.75,-9.20375283798558E-5,1.33014034771606E-6,1,0.999253354069792,40.0298881530762,2.00737902289126,20.5799993127584,-0.00105055183941355,-0.000176084394640187,0.25,5.42379169853023E-7,-9.23560180528123E-5,4.45693971212199E-7,199.9900513,199.9902039,42645.33984375,42700.16015625,56.7759323798906,20.5419253181932,26.705515,0,0,0,40,4449,199.9343,42672.75,,,,,,,,,,,,,0,,,,-0.00245,,,,,,199.9901276,,,,
,31970840.415,199.9923706,37885.064453125,-7.66584287248412E-5,1.37787065281995E-6,1,0.999253354069792,40.0298881530762,2.00741104043789,20.5799993127584,-0.00087293357931768,-0.00015868746686931,0.25,-6.02554541180365E-7,-7.69225412609352E-5,-6.86882038569554E-7,199.9921417,199.9925995,37852.74609375,37917.3828125,56.6672860157175,20.5414938610537,26.325863,0,0,0,40,4449,199.94025,37885.064453125,,,,,,,,,,,,,0,,,,-0.0049,,,,,,199.9923706,,,,
,31970935.23,199.9869843,33150.3515625,-6.01883098024251E-5,1.18454623168846E-6,1,0.999253354069792,40.0298881530762,2.00761794374436,20.5799993127584,-0.000684211092027197,-0.000131741514462942,0.25,-1.09871905462924E-6,-6.03949979553784E-5,-1.16720553042805E-6,199.9869843,199.9869843,33120.421875,33180.28125,56.8955215433329,20.5427472697672,26.325863,0,0,0,40,4449,199.953,33150.3515625,,,,,,,,,,,,,0,,,,0.00245,,,,,,199.9869843,,,,
,31971029.385,199.9924469,28442.892578125,-4.35227403817879E-5,1.08726875083164E-6,1,0.999253354069792,40.0298881530762,2.00758544710315,20.5799993127584,-0.000495056651425252,-9.35060988782848E-5,0.25,-6.40433461414813E-7,-4.36723427627091E-5,-6.89508024183515E-7,199.9924469,199.9924469,28417.828125,28467.95703125,56.8447156895829,20.5448097115996,26.325863,0,0,0,40,4449,199.9575,28442.892578125,,,,,,,,,,,,,0,,,,0,,,,,,199.9924469,,,,
,31971124.46,199.9890137,23689.958984375,-2.78211158583878E-5,1.05013109167576E-6,1,0.999253354069792,40.0298881530762,2.00754398587778,20.5799993127584,-0.000317114460042676,-5.59430083767805E-5,0.25,-7.3662380424166E-8,-2.79171035051269E-5,-1.03923844475324E-7,199.9890137,199.9890137,23659.91015625,23720.0078125,56.8767624588714,20.5422920302472,25.946213,0,0,0,40,4449,199.97085,23689.958984375,,,,,,,,,,,,,0,,,,-0.00245,,,,,,199.9890137,,,,
,31971219.47,199.9883118,18942.5703125,-1.21232604833875E-5,9.09897828847571E-7,1,0.999253354069792,40.0298881530762,2.00757264702926,20.5799993127584,-0.000137588727537539,-2.7821664682615E-5,0.25,-3.34061425757599E-7,-1.21647585204153E-5,-3.48312985319505E-7,199.9880524,199.9885712,18912.5234375,18972.6171875,56.7376325824483,20.5404123296288,26.325863,0,0,0,40,4449,199.97135,18942.5703125,,,,,,,,,,,,,0,,,,0,,,,,,199.9883118,,,,
,31971314.835,199.9920502,14178.0166015625,3.12001137902984E-6,5.85427087122068E-7,1,0.999253354069792,40.0298881530762,2.0076954325587,20.5799993127584,3.58440936611128E-5,4.67008137551876E-6,0.25,-1.32408208679702E-7,3.13092620710067E-6,-1.29489135500775E-7,199.9920502,199.9920502,14175.70703125,14180.326171875,56.7892200647175,20.5422401104794,26.325863,0,0,0,40,4449,199.98085,14178.0166015625,,,,,,,,,,,,,0,,,,-0.0049,,,,,,199.9920502,,,,
,31971411.955,199.9899445,9320.3720703125,1.71948469112122E-5,4.35373986695851E-7,1,0.999253354069792,40.0298881530762,2.00778217325036,20.5799993127584,0.000196574021257321,3.1359142250847E-5,0.25,-2.36926295593942E-7,1.72544643763915E-5,-2.19109713694237E-7,199.9899445,199.9899445,9317.986328125,9322.7578125,56.6899532427752,20.542398775353,26.325863,0,0,0,40,4449,199.9909,9320.3720703125,,,,,,,,,,,,,0,,,,0.00245,,,,,,199.9899445,,,,
,31971509.84,199.9932556,4429.6015625,2.7180042195044E-5,4.04557008159852E-7,1,0.999253354069792,40.0298881530762,2.00763477758667,20.5799993127584,0.000310602812932157,5.0151010833497E-5,0.25,-3.23269418977212E-7,2.72742159625063E-5,-2.94888699879919E-7,199.9932556,199.9932556,4399.5673828125,4459.6357421875,56.7845302936022,20.5455900351477,26.325863,0,0,0,40,4449,199.9936,4429.6015625,,,,,,,,,,,,,0,,,,-0.00245,,,,,,199.9932556,,,,
,31971605.445,199.99388885,-350.77571105957,1.67763698210012E-5,3.68671928439727E-7,1,0.999253354069792,40.0298881530762,2.0076204588472,20.5799993127584,0.000191976182379743,2.94359292414111E-5,0.25,-3.32715142567581E-7,1.68346388155858E-5,-3.15640391088711E-7,199.9938049,199.9939728,-378.217407226562,-323.334014892578,56.8486238321791,20.5473981386474,26.705515,0,0,0,40,4449,199.99315,-350.77571105957,,,,,,,,,,,,,0,,,,-0.00245,,,,,,199.99388885,,,,
,31971702.725,199.9949493,-5210.75219726562,-1.89845346963531E-5,3.90884036585653E-7,1,0.999253354069792,40.0298881530762,2.00754996483625,20.5799993127584,-0.000216516537662609,-3.7460214420731E-5,0.25,1.24818771353033E-8,-1.90500806893748E-5,-8.07297263943782E-9,199.9949493,199.9949493,-5243.033203125,-5178.47119140625,56.7493570102368,20.5505121836478,26.325863,0,0,0,40,4449,199.99625,-5210.75219726562,,,,,,,,,,,,,0,,,,0,,,,,,199.9949493,,,,
,31971802.39,200.0013428,-10191.8916015625,-1.43281725229434E-5,5.86227287202486E-7,1,0.999253354069792,40.0298881530762,2.00756411870728,20.5799993127584,-0.000163067736001114,-3.02565164553432E-5,0.25,-1.64583820024119E-7,-1.43774537604645E-5,-1.80675049014311E-7,200.0013428,200.0013428,-10196.9931640625,-10186.7900390625,56.9275683126214,20.5474703684809,26.705515,0,0,0,40,4449,199.9964,-10191.8916015625,,,,,,,,,,,,,0,,,,0,,,,,,200.0013428,,,,
,31971898.995,200.0032806,-15019.1801757813,-7.70800373934156E-7,7.01523015539434E-7,1,0.999253354069792,40.0298881530762,2.00748225883811,20.5799993127584,-7.43149010004761E-6,-9.34601538082838E-6,0.25,-6.85715634669021E-7,-7.7271949650692E-7,-6.88916577756205E-7,200.0032806,200.0032806,-15024.3662109375,-15013.994140625,56.851750346256,20.551143967112,26.705515,0,0,0,40,4449,199.9939,-15019.1801757813,,,,,,,,,,,,,0,,,,-0.00245,,,,,,200.0032806,,,,
,31971998.415,200.0030594,-19988.8662109375,1.50947058595142E-5,1.02828135999512E-6,1,0.999253354069792,40.0298881530762,2.00764088296642,20.5799993127584,0.000171623343959964,3.28815993746628E-5,0.25,2.61588056521577E-7,1.51465358660705E-5,2.78791806063444E-7,200.0020752,200.0040436,-20021.59375,-19956.138671875,56.7892200647175,20.5493505293761,26.705515,0,0,0,40,4449,199.98925,-19988.8662109375,,,,,,,,,,,,,0,,,,0.00245,,,,,,200.0030594,,,,
,31972099.69,200.0103607,-25048.6953125,3.20988911655164E-5,1.01805333292259E-6,1,0.999253354069792,40.0298881530762,2.00764516616713,20.5799993127584,0.000365433579739318,6.71835085983377E-5,0.25,3.1612037085046E-7,3.22093688485224E-5,3.51813852994038E-7,200.0103607,200.0103607,-25078.5390625,-25018.8515625,56.8728543162753,20.5493955385071,26.325863,0,0,0,40,4449,199.9779,-25048.6953125,,,,,,,,,,,,,0,,,,-0.00245,,,,,,200.0103607,,,,
,31972195.29,200.0106354,-29828.1416015625,4.79982192934989E-5,1.48290519708173E-6,1,0.999253354069792,40.0298881530762,2.0075825475711,20.5799993127584,0.000547564774324361,9.38970341192813E-5,0.25,-1.02549304659459E-7,4.81640518399502E-5,-5.12520354808857E-8,200.0106354,200.0106354,-29855.748046875,-29800.53515625,57.1128142716791,20.5454711004592,26.705515,0,0,0,40,4449,199.9678,-29828.1416015625,,,,,,,,,,,,,0,,,,-0.00245,,,,,,200.0106354,,,,
,31972293.075,200.0126343,-34715.578125,6.56670408348721E-5,1.58831200493534E-6,1,0.999253354069792,40.0298881530762,2.00762006540418,20.5799993127584,0.000748369489031013,0.000132927089806076,0.25,2.51176616951285E-7,6.58935125649418E-5,3.2257912152849E-7,200.0124512,200.0128174,-34748.05859375,-34683.09765625,56.7618630665445,20.5479400728315,26.325863,0,0,0,40,4449,199.95735,-34715.578125,,,,,,,,,,,,,0,,,,-0.00245,,,,,,200.0126343,,,,
,31972392.665,200.0124969,-39692.6484375,8.2733682288819E-5,1.72003643703826E-6,1,0.999253354069792,40.0298881530762,2.0076786559865,20.5799993127584,0.000942657772344973,0.000168843417054707,0.25,4.36259151546483E-7,8.30189110017489E-5,5.26460776730679E-7,200.0124969,200.0124969,-39724.99609375,-39660.30078125,56.7352876968906,20.5458873043316,26.325863,0,0,0,40,4449,199.9489,-39692.6484375,,,,,,,,,,,,,0,,,,0.00245,,,,,,200.0124969,,,,
,31972491.525,200.0114975,-44633.0234375,9.90456008052594E-5,1.39835520762842E-6,1,0.999253354069792,40.0298881530762,2.00777834359831,20.5799993127584,0.00113143922490938,0.000185608461821695,0.25,-9.27256096756636E-7,9.93886514378573E-5,-8.24484409772438E-7,200.0114441,200.0115509,-44663.3984375,-44602.6484375,56.8814522299868,20.5474967655135,26.325863,0,0,0,40,4449,199.93985,-44633.0234375,,,,,,,,,,,,,0,,,,0,,,,,,200.0114975,,,,
,31972590.475,200.0128021,-49580.349609375,0.000116765045046499,1.76519215874021E-6,1,0.999253354069792,40.0298881530762,2.00761756422766,20.5799993127584,0.00133367660470938,0.000219244799565644,0.25,-1.05367333147244E-6,0.000117169454833591,-9.32628596336736E-7,200.0128021,200.0128021,-49605.12890625,-49555.5703125,56.943200883006,20.5473037551561,25.946213,0,0,0,40,4449,199.92855,-49580.349609375,,,,,,,,,,,,,0,,,,0,,,,,,200.0128021,,,,
,31972688.805,200.01145935,-54492.326171875,0.000133350778020458,1.45520747046001E-6,1,0.999253354069792,40.0298881530762,2.00767329341528,20.5799993127584,0.00151708494546464,0.000285361090486556,0.25,1.86308558420045E-6,0.000133809408920518,2.01162849976859E-6,200.0111694,200.0117493,-54522.33984375,-54462.3125,56.8486238321791,20.5495887484439,26.325863,0,0,0,40,4449,199.9172,-54492.326171875,,,,,,,,,,,,,0,,,,-0.00245,,,,,,200.01145935,,,,
,31972789.735,200.012619,-59536.494140625,0.000151917868947264,1.83971884400874E-6,1,0.999253354069792,40.0298881530762,2.00769648396237,20.5799993127584,0.00173497625479654,0.000286860588801523,0.25,-1.2299297023634E-6,0.000152443970865107,-1.07262652422764E-6,200.012619,200.012619,-59558.94140625,-59514.046875,57.0502839901407,20.5511118397911,26.325863,0,0,0,40,4449,199.9067,-59536.494140625,,,,,,,,,,,,,0,,,,0.00245,,,,,,200.012619,,,,
,31972889.53,200.0156403,-64524.306640625,0.000169040729036462,1.88408927449608E-6,1,0.999253354069792,40.0298881530762,2.00771339943643,20.5799993127584,0.00193042904769648,0.000319855205059884,0.25,-1.31034214526302E-6,0.000169626102237039,-1.13549136874067E-6,200.0156403,200.0156403,-64551.484375,-64497.12890625,56.9267866841022,20.5517501494105,26.705515,0,0,0,40,4449,199.898,-64524.306640625,,,,,,,,,,,,,0,,,,0,,,,,,200.0156403,,,,
,31972989.055,200.0124359,-69496.71484375,0.00018649423937453,2.15796963682342E-6,1,0.999253354069792,40.0298881530762,2.00798992729854,20.5799993127584,0.00212400415812896,0.000387608544250007,0.25,1.59542205341603E-6,0.000187136909848312,1.79841107223896E-6,200.0123138,200.012558,-69524.4453125,-69468.984375,57.047939104583,20.5483687443698,26.325863,0,0,0,40,4449,199.88565,-69496.71484375,,,,,,,,,,,,,0,,,,0,,,,,,200.0124359,,,,
,31973089.33,200.0125732,-74507.9375,0.000204267792242776,2.17438772237056E-6,1,0.999253354069792,40.0298881530762,2.00799980769174,20.5799993127584,0.0023241232671977,0.000437896846766666,0.25,2.91799205638143E-6,0.000204970546130922,3.14389807899878E-6,200.0125732,200.0125732,-74510.296875,-74505.578125,56.8165770628906,20.5494890754239,26.325863,0,0,0,40,4449,199.8757,-74507.9375,,,,,,,,,,,,,0,,,,-0.00245,,,,,,200.0125732,,,,
,31973186.64,200.01263425,-79372.5703125,0.000219454355675969,2.65851318592469E-6,1,0.999253354069792,40.0298881530762,2.00805522051555,20.5799993127584,0.0024985528980833,0.000461407581373761,0.25,2.3413275707192E-6,0.000220210271200875,2.58079277266989E-6,200.0124969,200.0127716,-79402.671875,-79342.46875,56.7970363499099,20.5492687071773,26.705515,0,0,0,40,4449,199.86305,-79372.5703125,,,,,,,,,,,,,0,,,,0,,,,,,200.01263425,,,,
,31973287.01,200.0133972,-84389.96875,0.000240795196068799,2.17171500061902E-6,1,0.999253354069792,40.0298881530762,2.00814446205353,20.5799993127584,0.00274404929382503,0.000492435291209287,0.25,1.35421837277553E-6,0.000241625980118634,1.61220383536422E-6,200.0133972,200.0133972,-84420.1015625,-84359.8359375,57.1714364106214,20.5487936942433,25.946213,0,0,0,40,4449,199.85285,-84389.96875,,,,,,,,,,,,,0,,,,0.0049,,,,,,200.0133972,,,,
,31973382.625,200.011734,-89166.6171875,0.000257162549457286,2.4947043327637E-6,1,0.999253354069792,40.0298881530762,2.00810927369465,20.5799993127584,0.00293395338329975,0.000506128522729801,0.25,-2.86340619480331E-7,0.000258051723294689,-1.7390898369703E-8,200.011734,200.011734,-89166.6171875,-89166.6171875,56.9002113144483,20.5474428394182,26.325863,0,0,0,40,4449,199.8435,-89166.6171875,,,,,,,,,,,,,0,,,,0.0049,,,,,,200.011734,,,,
,31973491.485,200.0079346,-86162.4296875,0.000244709022742814,2.9439249712821E-6,1,0.999253354069792,40.0298881530762,2.00825374819728,20.5799993127584,0.0027847396528319,0.000523823648900428,0.25,3.4240424009583E-6,0.000245551229942903,3.69311056548727E-6,200.0079346,200.0079346,-86189.921875,-86134.9375,57.0057311645445,20.5479354651741,26.325863,0,0,0,40,4449,199.8387,-86162.4296875,,,,,,,,,,,,,0,,,,0.00245,,,,,,200.0079346,,,,
,31973589.305,200,-81272.9453125,0.000226172756747954,2.47290951145286E-6,1,0.999253354069792,40.0298881530762,2.00818169818615,20.5799993127584,0.00258085181746652,0.00044301599772597,0.25,-4.39948281791523E-7,0.000226954941394942,-2.03187047710351E-7,200,200,-81278.03125,-81267.859375,56.8564401173714,20.5479069106643,26.705515,0,0,0,40,4449,199.841,-81272.9453125,,,,,,,,,,,,,0,,,,0,,,,,,200,,,,
,31973690.4,199.9942474,-76220.515625,0.000208996130393384,1.99956286371768E-6,1,0.999253354069792,40.0298881530762,2.00807662741685,20.5799993127584,0.00238438943927112,0.000411314194727747,0.25,-2.34905087540643E-7,0.000209718699929987,-1.50311469976151E-8,199.9942474,199.9942474,-76250.4453125,-76190.5859375,56.821266834006,20.5483786301816,26.705515,0,0,0,40,4449,199.8472,-76220.515625,,,,,,,,,,,,,0,,,,0,,,,,,199.9942474,,,,
,31973787.65,199.99336245,-71360.82421875,0.000193560648497629,2.60732275919495E-6,1,0.999253354069792,40.0298881530762,2.0080682679261,20.5799993127584,0.00220739479519189,0.000386032732883882,0.25,2.2893526247358E-7,0.0001942293225744,4.34554462964329E-7,199.9930573,199.9936676,-71388.4140625,-71333.234375,56.8478422036599,20.5473837448643,26.705515,0,0,0,40,4449,199.85365,-71360.82421875,,,,,,,,,,,,,0,,,,-0.00245,,,,,,199.99336245,,,,
,31973886.415,199.9902191,-66423.63671875,0.000176816963480975,2.67502337056182E-6,1,0.999253354069792,40.0298881530762,2.00818866326125,20.5799993127584,0.00201474220262009,0.000363139145131366,0.25,1.12741159513586E-6,0.000177426780756328,1.31882051742961E-6,199.9902191,199.9902191,-66431.390625,-66415.8828125,56.9619599674676,20.5461307204999,26.705515,0,0,0,40,4449,199.862,-66423.63671875,,,,,,,,,,,,,0,,,,-0.0049,,,,,,199.9902191,,,,
,31973986.145,199.9868927,-61438.361328125,0.000157373949480743,2.39186923004809E-6,1,0.999253354069792,40.0298881530762,2.00786615165446,20.5799993127584,0.00179277103788892,0.00032403667047052,0.25,1.08009513325303E-6,0.000157916592488898,1.2510778342013E-6,199.9868927,199.9868927,-61443.40234375,-61433.3203125,56.6094455052945,20.5492676709326,26.705515,0,0,0,40,4449,199.8722,-61438.361328125,,,,,,,,,,,,,0,,,,0.0049,,,,,,199.9868927,,,,
,31974085.055,199.987793,-56496.669921875,0.000140486836139356,1.80844197994366E-6,1,0.999253354069792,40.0298881530762,2.00799796359881,20.5799993127584,0.00160267048966556,0.000276764096365564,0.25,-1.3373530747488E-7,0.000140972369134461,1.54117592892948E-8,199.987793,199.987793,-56526.48046875,-56466.859375,56.8486238321791,20.5484280941584,27.085165,0,0,0,40,4449,199.88905,-56496.669921875,,,,,,,,,,,,,0,,,,-0.00245,,,,,,199.987793,,,,
,31974183.5,199.9900055,-51576.62890625,0.000121457021017717,1.66203619787611E-6,1,0.999253354069792,40.0298881530762,2.00767459526857,20.5799993127584,0.00138703709142467,0.000229612684348238,0.25,-9.59877417491792E-7,0.000121877639034984,-8.33582716811689E-7,199.9896851,199.9903259,-51604.171875,-51549.0859375,56.8666012881214,20.548582953333,26.705515,0,0,0,40,4449,199.8959,-51576.62890625,,,,,,,,,,,,,0,,,,0.00245,,,,,,199.9900055,,,,
,31974286.535,199.9882507,-46427.578125,0.000105558832751247,1.47197067653946E-6,1,0.999253354069792,40.0298881530762,2.00779792564228,20.5799993127584,0.00120511493289305,0.000202076261418974,0.25,-6.14638343108881E-7,0.000105924131825748,-5.03875152236894E-7,199.9882507,199.9882507,-46432.40625,-46422.75,56.7649895806214,20.5489875382237,26.705515,0,0,0,40,4449,199.90025,-46427.578125,,,,,,,,,,,,,0,,,,0,,,,,,199.9882507,,,,
,31974385.715,199.9919739,-41469.955078125,8.95100161007474E-5,1.63691370250206E-6,1,0.999253354069792,40.0298881530762,2.00784504963333,20.5799993127584,0.00101957086266737,0.000184858064722484,0.25,6.62376445452957E-7,8.98184700984871E-5,7.60579872526048E-7,199.9919739,199.9919739,-41474.921875,-41464.98828125,56.8509687177368,20.5475643359975,26.705515,0,0,0,40,4449,199.90655,-41469.955078125,,,,,,,,,,,,,0,,,,0,,,,,,199.9919739,,,,
,31974485.79,199.990921,-36467.876953125,7.18247071523212E-5,1.46960432056051E-6,1,0.999253354069792,40.0298881530762,2.00785009492675,20.5799993127584,0.000819690021925575,0.00013933302734895,0.25,-2.57864152082132E-7,7.20730441946604E-5,-1.81640999109355E-7,199.990921,199.990921,-36472.74609375,-36463.0078125,56.648526931256,20.5486946877218,26.325863,0,0,0,40,4449,199.91985,-36467.876953125,,,,,,,,,,,,,0,,,,-0.0049,,,,,,199.990921,,,,
,31974584.97,199.9880981,-31511.453125,5.38408943446007E-5,1.27563240237605E-6,1,0.999253354069792,40.0298881530762,2.00751729584832,20.5799993127584,0.000614165832598211,0.000105518062186592,0.25,-9.7960916218898E-8,5.40269383113855E-5,-4.03834108815899E-8,199.9880981,199.9880981,-31516.4375,-31506.46875,56.7876568076791,20.5486162164638,26.705515,0,0,0,40,4449,199.92695,-31511.453125,,,,,,,,,,,,,0,,,,0.0049,,,,,,199.9880981,,,,
,31974681.505,199.9898529,-26685.9736328125,3.74416147486851E-5,1.23866587773821E-6,1,0.999253354069792,40.0298881530762,2.0077340869692,20.5799993127584,0.000425833709479812,8.09202025199129E-5,0.25,5.9242549191853E-7,3.75702675661484E-5,6.3481860385991E-7,199.9898529,199.9898529,-26713.529296875,-26658.41796875,56.8525319747752,20.5450964272156,26.705515,0,0,0,40,4449,199.93585,-26685.9736328125,,,,,,,,,,,,,0,,,,-0.00245,,,,,,199.9898529,,,,
,31974778.765,199.9914093,-21826.3134765625,2.19729550942008E-5,1.12421436667142E-6,1,0.999253354069792,40.0298881530762,2.00768771949109,20.5799993127584,0.000250654523183176,4.31367281520529E-5,0.25,-3.38895956817068E-8,2.20488601675907E-5,-1.02867757668954E-8,199.9914093,199.9914093,-21856.421875,-21796.205078125,56.973684395256,20.548157351907,26.325863,0,0,0,40,4449,199.94165,-21826.3134765625,,,,,,,,,,,,,0,,,,-0.00245,,,,,,199.9914093,,,,
,31974878.2,199.9910736,-16856.2646484375,5.10576522463094E-6,7.67498953688576E-7,1,0.999253354069792,40.0298881530762,2.00757553643817,20.5799993127584,5.81062459555002E-5,1.07956017049113E-5,0.25,5.98685362092894E-8,5.12332840623301E-6,6.559632433036E-8,199.9909515,199.9911957,-16888.67578125,-16823.853515625,56.7985996069483,20.5494737529395,26.325863,0,0,0,40,4449,199.9494,-16856.2646484375,,,,,,,,,,,,,0,,,,0,,,,,,199.9910736,,,,
,31974976.875,199.98883055,-11924.2192382812,-9.96986667958669E-6,6.99714632073967E-7,1,0.999253354069792,40.0298881530762,2.00766461731222,20.5799993127584,-0.000114214713728157,-1.67762780594227E-5,0.25,2.60591548026092E-7,-1.00045686196423E-5,2.50693271437741E-7,199.9884033,199.9892578,-11946.5986328125,-11901.83984375,56.8540952318137,20.5475615829024,27.085165,0,0,0,40,4449,199.95895,-11924.2192382812,,,,,,,,,,,,,0,,,,0,,,,,,199.98883055,,,,
,31975077.185,199.990509,-6911.07592773437,-2.31264483569854E-5,4.24959153057924E-7,1,0.999253354069792,40.0298881530762,2.00721559302544,20.5799993127584,-0.000264076072579919,-4.35340683732508E-5,0.25,1.98652708191906E-7,-2.32064982063335E-5,1.74254150221082E-7,199.9899902,199.9910278,-6943.615234375,-6878.53662109375,56.7188734979868,20.5513902431852,26.705515,0,0,0,40,4449,199.9679,-6911.07592773437,,,,,,,,,,,,,0,,,,-0.00245,,,,,,199.990509,,,,
,31975174.04,199.9925385,-2070.09997558594,-2.8078340689788E-5,3.57352257447239E-7,1,0.999253354069792,40.0298881530762,2.00742086219452,20.5799993127584,-0.000319204136725335,-6.11960131565382E-5,0.25,-4.89745449836176E-7,-2.81747301784471E-5,-5.21928466340368E-7,199.9925385,199.9925385,-2090.23364257813,-2049.96630859375,57.0831123879483,20.5489993541023,26.325863,0,0,0,40,4449,199.97665,-2070.09997558594,,,,,,,,,,,,,0,,,,0,,,,,,199.9925385,,,,
,31975268.155,199.99462125,2630.49890136719,6.86676821477149E-6,3.85200661390018E-7,1,0.999253354069792,40.0298881530762,2.00747463961599,20.5799993127584,7.83099355650185E-5,1.3560463204467E-5,0.25,-3.51502975317949E-9,6.89047452369996E-6,3.92915111095653E-9,199.9941101,199.9951324,2603.03002929687,2657.9677734375,56.5695824508137,20.5466381081961,26.705515,0,0,0,40,4449,199.97415,2630.49890136719,,,,,,,,,,,,,0,,,,0,,,,,,199.99462125,,,,
,31975362.695,199.9985352,7357.7109375,2.04713135445204E-5,4.62579433279875E-7,1,0.999253354069792,40.0298881530762,2.00775271333464,20.5799993127584,0.00023383211285372,3.84601701127354E-5,0.25,-1.83347818805449E-7,2.0542176095354E-5,-1.61779795985283E-7,199.9985352,199.9985352,7327.54541015625,7387.87646484375,56.6774471864675,20.5441106767723,26.705515,0,0,0,40,4449,199.9723,7357.7109375,,,,,,,,,,,,,0,,,,0.00245,,,,,,199.9985352,,,,
,31975460.075,200.003746,12225.5478515625,8.4119016891291E-6,4.98439127127269E-7,1,0.999253354069792,40.0298881530762,2.00781675014216,20.5799993127584,9.5771430873312E-5,1.76226524684846E-5,0.25,8.41155050585842E-8,8.44084771259474E-6,9.35148237507295E-8,200.0032806,200.0042114,12195.4697265625,12255.6259765625,56.7290346687368,20.54051416599,27.085165,0,0,0,40,4449,199.97165,12225.5478515625,,,,,,,,,,,,,0,,,,-0.00245,,,,,,200.003746,,,,
,31975553.69,200.008728,16903.560546875,-4.67657609911866E-6,6.7994693389772E-7,1,0.999253354069792,40.0298881530762,2.0077937037063,20.5799993127584,-5.33267539937306E-5,-9.3167581502228E-6,0.25,-4.64875886961516E-9,-4.69271454257587E-6,-9.72123605811223E-9,200.008728,200.008728,16868.98046875,16938.140625,56.6196066760444,20.5395054609692,26.325863,0,0,0,40,4449,199.9644,16903.560546875,,,,,,,,,,,,,0,,,,0.00245,,,,,,200.008728,,,,
,31975648.13,200.00688935,21623.10546875,-1.99069253366798E-5,1.2347609588637E-6,1,0.999253354069792,40.0298881530762,2.00786020012958,20.5799993127584,-0.000225980962092306,-4.55554368967598E-5,0.25,-5.36709765699324E-7,-1.99750706745454E-5,-5.60051929274832E-7,200.0065918,200.0071869,21590.744140625,21655.466796875,56.8142321773329,20.5410213366752,27.085165,0,0,0,40,4449,199.9554,21623.10546875,,,,,,,,,,,,,0,,,,0.0049,,,,,,200.00688935,,,,
,31975742.03,200.0113373,26318.4609375,-3.64878865785002E-5,1.07026757361089E-6,1,0.999253354069792,40.0298881530762,2.00759355735383,20.5799993127584,-0.000417154344545636,-6.62119464023334E-5,0.25,5.31215349147688E-7,-3.66144305295699E-5,4.93726775941338E-7,200.0113373,200.0113373,26288.4921875,26348.4296875,56.7251265261406,20.544254275328,26.325863,0,0,0,40,4449,199.946,26318.4609375,,,,,,,,,,,,,0,,,,0.0049,,,,,,200.0113373,,,,
,31975839.625,200.0112762,31196.5791015625,-5.17744672323946E-5,1.24952292574333E-6,1,0.999253354069792,40.0298881530762,2.00755066675879,20.5799993127584,-0.000589460281098951,-0.000108048607737159,0.25,-4.8270166355711E-7,-5.19527098538956E-5,-5.40065229787393E-7,200.0112762,200.0112762,31191.578125,31201.580078125,57.0205821064099,20.5454088128312,26.325863,0,0,0,40,4449,199.93505,31196.5791015625,,,,,,,,,,,,,0,,,,0,,,,,,200.0112762,,,,
,31975937.265,200.0111237,36074.22265625,-6.83435211834149E-5,1.49271809057755E-6,1,0.999253354069792,40.0298881530762,2.00752997960838,20.5799993127584,-0.00077863767094026,-0.000139495693579964,0.25,-3.62869329163568E-7,-6.85791223186804E-5,-4.37503774403167E-7,200.0111237,200.0111237,36044.41015625,36104.03515625,56.7821854080445,20.5438043258147,26.705515,0,0,0,40,4449,199.9335,36074.22265625,,,,,,,,,,,,,0,,,,-0.0049,,,,,,200.0111237,,,,
,31976030.47,200.0124283,40734.50390625,-8.43921793652597E-5,1.64413247983112E-6,1,0.999253354069792,40.0298881530762,2.00776730848829,20.5799993127584,-0.000960696708427222,-0.000177407704557241,0.25,-8.98551868024269E-7,-8.46826434434069E-5,-9.92104663898935E-7,200.0122528,200.0126038,40707.06640625,40761.94140625,56.6602513590445,20.5430699725552,27.085165,0,0,0,40,4449,199.9221,40734.50390625,,,,,,,,,,,,,0,,,,0,,,,,,200.0124283,,,,
,31976124.36,200.0134735,45427.662109375,-0.000101783776375624,1.82381617335356E-6,1,0.999253354069792,40.0298881530762,2.00764893824014,20.5799993127584,-0.0011590846198183,-0.000211239903928527,0.25,-8.45756834879654E-7,-0.000102134382016653,-9.5756649551466E-7,200.0134735,200.0134735,45404.92578125,45450.3984375,56.7360693254098,20.5428390573278,26.325863,0,0,0,40,4449,199.9086,45427.662109375,,,,,,,,,,,,,0,,,,0.0049,,,,,,200.0134735,,,,
,31976218.185,200.0122375,50117.46484375,-0.000118596905776664,1.56962915850469E-6,1,0.999253354069792,40.0298881530762,2.00755833272036,20.5799993127584,-0.00135089474174712,-0.000243793018350519,0.25,-7.81383468751516E-7,-0.000119005685909245,-9.10717455532693E-7,200.0122375,200.0122375,50092.6328125,50142.296875,56.6844818431406,20.5445093157502,26.325863,0,0,0,40,4449,199.89785,50117.46484375,,,,,,,,,,,,,0,,,,-0.00245,,,,,,200.0122375,,,,
,31976312.39,200.01320645,54824.80859375,-0.000133963605099156,1.39223562582402E-6,1,0.999253354069792,40.0298881530762,2.00791133024443,20.5799993127584,-0.00152874943093681,-0.00026067669415176,0.25,4.10410475908469E-7,-0.000134426767064906,2.69062019508372E-7,200.0128784,200.0135345,54794.5625,54855.0546875,56.6594697305252,20.5357142251373,26.705515,0,0,0,40,4449,199.88765,54824.80859375,,,,,,,,,,,,,0,,,,0.00245,,,,,,200.01320645,,,,
,31976405.585,200.0127487,59482.98828125,-0.000150079195993941,1.7149499598681E-6,1,0.999253354069792,40.0298881530762,2.00767819603811,20.5799993127584,-0.00171037020310578,-0.000304072559732331,0.25,-5.98824057897414E-7,-0.000150596996387495,-7.60519740207654E-7,200.0126953,200.0128021,59453.125,59512.8515625,56.8173586914099,20.5397832339601,27.085165,0,0,0,40,4449,199.8793,59482.98828125,,,,,,,,,,,,,0,,,,0,,,,,,200.0127487,,,,
,31976500.93,200.0139313,64248.41015625,-0.000168576039781428,1.75773242356803E-6,1,0.999253354069792,40.0298881530762,2.00774387537117,20.5799993127584,-0.001919893832852,-0.000349247822200551,0.25,-1.34713261287067E-6,-0.000169156989079062,-1.53072418832939E-6,200.0139313,200.0139313,64220.92578125,64275.89453125,56.4679707433137,20.5406649049362,27.085165,0,0,0,40,4449,199.86925,64248.41015625,,,,,,,,,,,,,0,,,,0,,,,,,200.0139313,,,,
,31976595.23,200.0100784,68961.46875,-0.000184053129446136,2.1943405858894E-6,1,0.999253354069792,40.0298881530762,2.00797281663364,20.5799993127584,-0.00209829020044648,-0.000370410023872638,0.25,-5.11700319922928E-7,-0.00018468851622934,-7.08436772238483E-7,200.0097961,200.0103607,68928.8984375,68994.0390625,56.8658196596022,20.5342306580204,27.085165,0,0,0,40,4449,199.8603,68961.46875,,,,,,,,,,,,,0,,,,0,,,,,,200.0100784,,,,
,31976690.585,200.0136108,73726.734375,-0.000203178508412886,1.71826327819828E-6,1,0.999253354069792,40.0298881530762,2.0077183231894,20.5799993127584,-0.00231709065434243,-0.000402851401124599,0.25,-3.92591939835873E-8,-0.000203880516491685,-2.54181024312465E-7,200.0136108,200.0136108,73696.7890625,73756.6796875,56.6500901882945,20.5404930979212,26.325863,0,0,0,40,4449,199.84635,73726.734375,,,,,,,,,,,,,0,,,,-0.00245,,,,,,200.0136108,,,,
,31976785.835,200.0107574,78487.3984375,-0.00022019921157193,1.82236607244586E-6,1,0.999253354069792,40.0298881530762,2.00748708260831,20.5799993127584,-0.00250992052576348,-0.000442327140067771,0.25,-5.49538464341792E-7,-0.000220959585438733,-7.83723582889168E-7,200.0107574,200.0107574,78454.8359375,78519.9609375,56.7876568076791,20.5429514840883,26.705515,0,0,0,40,4449,199.83975,78487.3984375,,,,,,,,,,,,,0,,,,0,,,,,,200.0107574,,,,
,31976880.375,200.0102005,83216.203125,-0.00023403827026501,2.1392736634126E-6,1,0.999253354069792,40.0298881530762,2.00764322016192,20.5799993127584,-0.00266629917640557,-0.00047916419679607,0.25,-1.37401499735036E-6,-0.000234845681116573,-1.6251260718802E-6,200.0099182,200.0104828,83188.6796875,83243.7265625,56.5867782782368,20.5409492342133,27.085165,0,0,0,40,4449,199.83145,83216.203125,,,,,,,,,,,,,0,,,,0.00245,,,,,,200.0102005,,,,
,31976970.61,200.0160599,87726.7890625,-0.000249793519599726,2.16250643417053E-6,1,0.999253354069792,40.0298881530762,2.00779109792387,20.5799993127584,-0.0028407242418377,-0.000541793551099564,0.25,-4.12695978700819E-6,-0.000250652519568028,-4.40364519199208E-6,200.0157013,200.0164185,87701.796875,87751.78125,56.5828701356406,20.5391809427134,26.705515,0,0,0,40,4449,199.817,87726.7890625,,,,,,,,,,,,,0,,,,0,,,,,,200.0160599,,,,
,31977075.355,200.00814055,87810.6015625,-0.000246275803763102,3.25776558250309E-6,1,0.999253354069792,40.0298881530762,2.00802217431973,20.5799993127584,-0.00280676506670991,-0.000501184816405374,0.25,-1.17239226739039E-6,-0.000247125814680504,-1.43516864135638E-6,200.0079193,200.0083618,87788.1796875,87833.0234375,56.2960124690829,20.5363419721823,26.705515,0,0,0,40,4449,199.812,87810.6015625,,,,,,,,,,,,,0,,,,0,,,,,,200.00814055,,,,
,31977166.51,200.0015106,83254.65625,-0.000235770582992568,2.65405947133907E-6,1,0.999253354069792,40.0298881530762,2.00795468987612,20.5799993127584,-0.00268817785201282,-0.000472733888393021,0.25,-5.03170603867442E-7,-0.000236584962829494,-7.53113559649726E-7,200.0015106,200.0015106,83249.8046875,83259.5078125,56.6516534453329,20.5366510497863,26.705515,0,0,0,40,4449,199.8166,83254.65625,,,,,,,,,,,,,0,,,,-0.00245,,,,,,200.0015106,,,,
,31977260.5,199.9980927,78555.95703125,-0.000219108200113935,2.0551130670456E-6,1,0.999253354069792,40.0298881530762,2.00762823482002,20.5799993127584,-0.00249488349885682,-0.000456114333346069,0.25,-1.94532646702099E-6,-0.000219863419226707,-2.18321119733903E-6,199.9978333,199.9983521,78551.234375,78560.6796875,56.5602029085829,20.5410004877686,27.085165,0,0,0,40,4449,199.8159,78555.95703125,,,,,,,,,,,,,0,,,,0,,,,,,199.9980927,,,,
,31977352.605,199.9931793,73949.5625,-0.000200911539838055,2.40774412361075E-6,1,0.999253354069792,40.0298881530762,2.00797765083884,20.5799993127584,-0.00229236245842735,-0.000393563024551014,0.25,3.85784017566613E-7,-0.000201606298060661,1.74713386861956E-7,199.9929657,199.9933929,73917.046875,73982.078125,56.7024592990829,20.533735849129,26.705515,0,0,0,40,4449,199.81885,73949.5625,,,,,,,,,,,,,0,,,,0.00245,,,,,,199.9931793,,,,
,31977447.57,199.9877472,69203.609375,-0.000185581966442794,2.14135077057782E-6,1,0.999253354069792,40.0298881530762,2.00776654707365,20.5799993127584,-0.00211318330922196,-0.000386870630901637,0.25,-1.69263692467087E-6,-0.000186221519427803,-1.89509030537547E-6,199.9877472,199.9877472,69178.53125,69228.6875,56.8978664288906,20.5400355869596,26.705515,0,0,0,40,4449,199.82935,69203.609375,,,,,,,,,,,,,0,,,,0.00245,,,,,,199.9877472,,,,
,31977542.25,199.9887009,64473.4765625,-0.000170287930339238,1.99068217306955E-6,1,0.999253354069792,40.0298881530762,2.00772139316688,20.5799993127584,-0.00193783450003638,-0.000361639723033331,0.25,-2.13668701081752E-6,-0.000170874094740882,-2.32484540085274E-6,199.9886475,199.9887543,64445.92578125,64501.02734375,56.7110572127945,20.5404457395441,26.705515,0,0,0,40,4449,199.8347,64473.4765625,,,,,,,,,,,,,0,,,,0,,,,,,199.9887009,,,,
,31977635.045,199.9875793,59834.98046875,-0.000151103020496319,1.76816915210659E-6,1,0.999253354069792,40.0298881530762,2.00751583019939,20.5799993127584,-0.00172048284793919,-0.000314322676320614,0.25,-1.32190982263195E-6,-0.000151623714310898,-1.48719464612043E-6,199.9875793,199.9875793,59807.67578125,59862.28515625,56.9400743689291,20.5461102745491,27.085165,0,0,0,40,4449,199.8531,59834.98046875,,,,,,,,,,,,,0,,,,0.00245,,,,,,199.9875793,,,,
,31977730.2,199.9897766,55077.115234375,-0.000134689317273102,2.15440708709305E-6,1,0.999253354069792,40.0298881530762,2.00756158560832,20.5799993127584,-0.00153079305302239,-0.000296500428797265,0.25,-2.60873163637464E-6,-0.000135151871274582,-2.76129399645447E-6,199.9897766,199.9897766,55049.51171875,55104.71875,56.7814037795252,20.543302785166,26.705515,0,0,0,40,4449,199.85865,55077.115234375,,,,,,,,,,,,,0,,,,0,,,,,,199.9897766,,,,
,31977825.51,199.99134825,50314.5,-0.000118264877309372,1.40504131382823E-6,1,0.999253354069792,40.0298881530762,2.00775106044886,20.5799993127584,-0.00134689804035951,-0.000245084391589479,0.25,-9.50289565074766E-7,-0.000118672409351347,-1.07987122645151E-6,199.9911041,199.9915924,50286.7265625,50342.2734375,56.6039741056598,20.5407079616361,27.085165,0,0,0,40,4449,199.86095,50314.5,,,,,,,,,,,,,0,,,,-0.0049,,,,,,199.99134825,,,,
,31977918.63,199.98879245,45659.44921875,-0.000100957834997227,1.23314489143178E-6,1,0.999253354069792,40.0298881530762,2.00782755059635,20.5799993127584,-0.00114873177178126,-0.000215564870153978,0.25,-1.36681514824509E-6,-0.000101305111354989,-1.47955431727594E-6,199.9886475,199.9889374,45629.6484375,45689.25,56.7220000120637,20.5411234164929,27.085165,0,0,0,40,4449,199.87425,45659.44921875,,,,,,,,,,,,,0,,,,0,,,,,,199.98879245,,,,
,31978011.01,199.9895401,41041.470703125,-8.66327968533373E-5,1.24675933284044E-6,1,0.999253354069792,40.0298881530762,2.00782706251361,20.5799993127584,-0.000987026044231761,-0.000177551122764658,0.25,-5.21518835654622E-7,-8.69314663400287E-5,-6.16183150787374E-7,199.9892883,199.9897919,41011.40234375,41071.5390625,56.7853119221214,20.5410959406236,26.705515,0,0,0,40,4449,199.8816,41041.470703125,,,,,,,,,,,,,0,,,,0.0049,,,,,,199.9895401,,,,
,31978102.64,199.99072265,36464.0234375,-7.14351609413838E-5,1.49107202798645E-6,1,0.999253354069792,40.0298881530762,2.0077869283796,20.5799993127584,-0.000813100352020233,-0.000150777009801447,0.25,-8.13570152872582E-7,-7.16810005352298E-5,-8.93089492192415E-7,199.9900818,199.9913635,36434.21875,36493.828125,56.6024108486214,20.5418883711778,26.325863,0,0,0,40,4449,199.8905,36464.0234375,,,,,,,,,,,,,0,,,,0.00245,,,,,,199.99072265,,,,
,31978195.39,199.9882431,31826.509765625,-5.40410860721721E-5,1.22811823504288E-6,1,0.999253354069792,40.0298881530762,2.0078707683546,20.5799993127584,-0.000614304493787807,-0.00011887402714361,0.25,-1.03673900469377E-6,-5.42266001935066E-5,-1.09845271294265E-6,199.9877472,199.988739,31796.623046875,31856.396484375,57.1815975813714,20.5410990530068,27.085165,0,0,0,40,4449,199.9011,31826.509765625,,,,,,,,,,,,,0,,,,0,,,,,,199.9882431,,,,
,31978288.375,199.9886017,27181.341796875,-3.88189705415904E-5,9.86843985767305E-7,1,0.999253354069792,40.0298881530762,2.00785628964449,20.5799993127584,-0.000443381056157003,-7.32119485495962E-5,0.25,3.23058802616882E-7,-3.89533678058228E-5,2.82343470267036E-7,199.9886017,199.9886017,27158.705078125,27203.978515625,56.9213152844676,20.5422455960288,26.705515,0,0,0,40,4449,199.9086,27181.341796875,,,,,,,,,,,,,0,,,,0,,,,,,199.9886017,,,,
,31978382.4,199.9899902,22481.162109375,-2.32763526787634E-5,9.31679159469594E-7,1,0.999253354069792,40.0298881530762,2.00768584781146,20.5799993127584,-0.000265249655826045,-4.72675171308555E-5,0.25,-1.0194656529578E-7,-2.33566128288706E-5,-1.27423904389698E-7,199.9899902,199.9899902,22456.142578125,22506.181640625,56.8595666314483,20.5449130029868,26.325863,0,0,0,40,4449,199.91325,22481.162109375,,,,,,,,,,,,,0,,,,0.00245,,,,,,199.9899902,,,,
,31978474.715,199.9899292,17866.158203125,-8.84680551682124E-6,7.78195953934737E-7,1,0.999253354069792,40.0298881530762,2.0076831088196,20.5799993127584,-0.000100463577436267,-1.99893176937223E-5,0.25,-2.16213476756014E-7,-8.87711641018135E-6,-2.26524657733142E-7,199.9892883,199.9905701,17838.7578125,17893.55859375,56.8470605751406,20.5455671925722,26.705515,0,0,0,40,4449,199.92295,17866.158203125,,,,,,,,,,,,,0,,,,-0.00245,,,,,,199.9899292,,,,
,31978567.41,199.9900818,13233.5200195313,6.28882620722252E-6,6.20610704444934E-7,1,0.999253354069792,40.0298881530762,2.00796554765731,20.5799993127584,7.16010475227247E-5,1.31975550263468E-5,0.25,6.47919473281721E-8,6.31046742022264E-6,7.18250855239332E-8,199.9896393,199.9905243,13201.076171875,13265.9638671875,56.679010443506,20.5418020438908,26.325863,0,0,0,40,4449,199.931,13233.5200195313,,,,,,,,,,,,,0,,,,0,,,,,,199.9900818,,,,
,31978662.29,199.9921417,8493.26318359375,1.96674352594205E-5,4.59198501475401E-7,1,0.999253354069792,40.0298881530762,2.00763721517973,20.5799993127584,0.000224254399411266,3.91541079329954E-5,0.25,1.73156993191297E-8,1.97353100510476E-5,3.87008701086323E-8,199.9921417,199.9921417,8488.255859375,8498.2705078125,56.8642564025637,20.5474913863604,27.085165,0,0,0,40,4449,199.9464,8493.26318359375,,,,,,,,,,,,,0,,,,-0.0049,,,,,,199.9921417,,,,
,31978755.885,199.9899902,3812.51391601562,2.79565320455252E-5,4.60368019761765E-7,1,0.999253354069792,40.0298881530762,2.00769013010578,20.5799993127584,0.000319193768322461,5.32597937376017E-5,0.25,-1.85671358081791E-7,2.80532379828386E-5,-1.55959570025198E-7,199.9899902,199.9899902,3780.11596679687,3844.91186523438,57.0893654161022,20.5450742878429,27.085165,0,0,0,40,4449,199.9486,3812.51391601562,,,,,,,,,,,,,0,,,,-0.00245,,,,,,199.9899902,,,,
,31978832.275,199.9924011,-0.441489413380623,2.27544753028226E-5,3.32252678585936E-7,1,0.999253354069792,40.0298881530762,2.00769668459087,20.5799993127584,0.000261306562058164,3.46759394619848E-5,0.25,-9.11689997499017E-7,2.28340083438894E-5,-8.90112470064228E-7,199.9917297,199.9930725,-0.730741083621979,-0.152237743139267,56.7876568076791,20.5480160352594,26.705515,0,0,0,40,4417,199.9517,-0.441489413380623,,,,,,,,,,,,,0,,,,0.00245,,,,,,199.9924011,,,,