File: data/monolayers/magneticStructure/ML_Ac_CoFe_C-2/PPMS/data/DD175_23_HYST_100OE_300K.DAT
[Header]
; VSM Data File (default extension .dat)
; Copyright (c) 2003-2013, Quantum Design, Inc. All rights reserved.
TITLE,
FILEOPENTIME,31992380.66,01/06/2019,2:48 pm
BYAPP,VSM,2.0,2.0
INFO,PPMS VSM Option Release 1.4.10 Build 1,APPNAME
INFO,Quantum Design Linear Motor Servo Controller,MOTOR_MODULE_NAME
INFO,3101-100 M1,MOTOR_HW_VERSION
INFO,MMC1014,MOTOR_SERIAL_NUMBER
INFO,SRV No X-over 01.03.11,MOTOR_SOFTWARE_VERSION
INFO,Quantum Design VSM Detection Module,VSM_MODULE_NAME
INFO,3101-150 F0,VSM_HW_VERSION
INFO,VSM707,VSM_SERIAL_NUMBER
INFO,VSM No X-over 01.02.05 May 20 2008 13:51:47,VSM_SOFTWARE_VERSION
INFO,704,PREAMP_SERIAL_NUMBER
INFO,822,COIL_SERIAL_NUMBER
INFO,0,MOMENT_UNITS
INFO,CoFe2O4 Monolayer,SAMPLE_MATERIAL
INFO,from YF45,SAMPLE_COMMENT
INFO,29.98,SAMPLE_MASS
INFO,,SAMPLE_VOLUME
INFO,,SAMPLE_MOLECULAR_WEIGHT
INFO,,SAMPLE_SIZE
INFO,,SAMPLE_SHAPE
DATATYPE,COMMENT,1
DATATYPE,TIME,2
STARTUPAXIS,X,2
STARTUPAXIS,Y1,5
[Data]
Comment,Time Stamp (sec),Temperature (K),Magnetic Field (Oe),Moment (emu),M. Std. Err. (emu),Transport Action,Averaging Time (sec),Frequency (Hz),Peak Amplitude (mm),Center Position (mm),Coil Signal' (mV),Coil Signal" (mV),Range (mV),M. Quad. Signal (emu),M. Raw' (emu),M. Raw" (emu),Min. Temperature (K),Max. Temperature (K),Min. Field (Oe),Max. Field (Oe),Mass (grams),Motor Lag (deg),Pressure (Torr),VSM Status (code),Motor Status (code),Measure Status (code),Measure Count,PPMS Status (code),System Temp. (K),System Field (Oe),Sample Position (deg),Bridge 1 Resistance (ohms),Bridge 1 Excitation (에),Bridge 2 Resistance (ohms),Bridge 2 Excitation (에),Bridge 3 Resistance (ohms),Bridge 3 Excitation (에),Bridge 4 Resistance (ohms),Bridge 4 Excitation (에),Signal 1 Vin (V),Signal 2 Vin (V),Digital Inputs (code),Drive 1 Iout (mA),Drive 1 Ipower (W),Drive 2 Iout (mA),Drive 2 Ipower (W),Pressure (),Map 20 (),Map 21 (),Map 22 (),Map 23 (),Map 24 (),Map 25 (),Map 26 (),Map 27 (),Map 28 (),Map 29 ()
,31992396.45,299.9997559,-0.182685270905495,,,2,,,,19.9799996969104,,,,,,,299.9997559,299.9997559,-0.182685270905495,-0.182685270905495,,,28.224119,,,,-99999999,4369,300.1945,-0.182685270905495,,,,,,,,,,,,,,,,,,,,,,,299.9997559,,,,
,31992536.085,299.9872284,4449.2236328125,2.71994175018529E-5,5.13801131230526E-7,1,0.999253354069792,40.0298881530762,1.98450355490422,19.9699997901917,0.000305255083564075,5.57072449442445E-5,0.25,2.43470750928487E-7,2.71984575576488E-5,2.61500285752733E-7,299.9866333,299.9878235,4416.5625,4481.884765625,56.0021201458521,20.5141595853511,28.224119,0,0,0,40,4449,300.20965,4449.2236328125,,,,,,,,,,,,,0,,,,-0.00245,,,,,,299.9872284,,,,
,31992631.14,299.9853821,9200.39208984375,1.67326741560097E-5,5.63536225376459E-7,1,0.999253354069792,40.0298881530762,1.98437892423942,19.9699997901917,0.000189488057855081,2.43931398910429E-5,0.25,-7.2880642395132E-7,1.67326677642113E-5,-7.17698398517432E-7,299.9853821,299.9853821,9197.974609375,9202.8095703125,56.2045619323329,20.5224557300925,28.603769,0,0,0,40,4449,300.22695,9200.39208984375,,,,,,,,,,,,,0,,,,-0.0049,,,,,,299.9853821,,,,
,31992726.345,299.9802551,13957.9301757813,2.75721794361805E-6,7.43030689865445E-7,1,0.999253354069792,40.0298881530762,1.98427486189899,19.9699997901917,3.16990231488948E-5,1.26822691609971E-6,0.25,-3.6487040854585E-7,2.75737950873958E-6,-3.63034694650159E-7,299.9802551,299.9802551,13935.4716796875,13980.388671875,56.0802829977752,20.5288217992735,28.983419,0,0,0,40,4449,300.25415,13957.9301757813,,,,,,,,,,,,,0,,,,-0.0049,,,,,,299.9802551,,,,
,31992820.18,299.986969,18648.0078125,-1.19984237454482E-5,7.62282016856575E-7,1,0.999253354069792,40.0298881530762,1.9843188892279,19.9699997901917,-0.00013428658717501,-2.66382600983315E-5,0.25,-2.91279652390859E-7,-1.19978809171567E-5,-2.9920617078411E-7,299.986969,299.986969,18623.03515625,18672.98046875,56.2717819849867,20.5305382066868,27.844467,0,0,0,40,4449,300.2608,18648.0078125,,,,,,,,,,,,,0,,,,-0.00245,,,,,,299.986969,,,,
,31992913.85,299.9897156,23330.5634765625,-2.70888265183803E-5,8.56973595797007E-7,1,0.999253354069792,40.0298881530762,1.98409629861414,19.9699997901917,-0.000304181512943199,-5.41589519222969E-5,0.25,-1.25896512173579E-7,-2.70879515831373E-5,-1.4379046182827E-7,299.9891663,299.9902649,23305.818359375,23355.30859375,56.3999690621406,20.5324951018362,28.224119,0,0,0,40,4449,300.2674,23330.5634765625,,,,,,,,,,,,,0,,,,0.00245,,,,,,299.9897156,,,,
,31993010.1,299.9886169,28138.3759765625,-4.36989854609415E-5,1.47451564840713E-6,1,0.999253354069792,40.0298881530762,1.98394229718156,19.9699997901917,-0.000490911704611239,-8.59161546683388E-5,0.25,-7.45165625328975E-8,-4.36976634238129E-5,-1.03356739242981E-7,299.9886169,299.9886169,28108.30859375,28168.443359375,56.7243448976214,20.5375908901739,28.224119,0,0,0,40,4449,300.27385,28138.3759765625,,,,,,,,,,,,,0,,,,0.00245,,,,,,299.9886169,,,,
,31993107.945,299.99232485,33030.705078125,-5.84730824956655E-5,1.35526345039985E-6,1,0.999253354069792,40.0298881530762,1.98408198767412,19.9699997901917,-0.000655485083027445,-0.000123294339430982,0.25,-8.40384239477624E-7,-5.84708211069234E-5,-8.78912294200421E-7,299.9923096,299.9923401,33000.6171875,33060.79296875,56.6969878994483,20.5353076704747,28.603769,0,0,0,40,4449,300.27605,33030.705078125,,,,,,,,,,,,,0,,,,0,,,,,,299.99232485,,,,
,31993204.13,300.0014648,37835.8125,-7.44381934548625E-5,1.46874398490308E-6,1,0.999253354069792,40.0298881530762,1.98384540814215,19.9699997901917,-0.000836618034151529,-0.000143902362787043,0.25,9.03734855575009E-8,-7.4436059588668E-5,4.1342422531323E-8,300.0014648,300.0014648,37808.57421875,37863.05078125,56.0646504273905,20.5414463298974,28.603769,0,0,0,40,4449,300.266,37835.8125,,,,,,,,,,,,,0,,,,0,,,,,,300.0014648,,,,
,31993299.135,300.0058289,42585.75,-8.97136411338254E-5,1.22142061964424E-6,1,0.999253354069792,40.0298881530762,1.98407437324652,19.9699997901917,-0.0010078350135551,-0.000176778081210384,0.25,-1.87144364930182E-7,-8.97108661340867E-5,-2.46164727530128E-7,300.0058289,300.0058289,42555.65625,42615.84375,56.5820885071214,20.5393032984081,28.603769,0,0,0,40,4449,300.2655,42585.75,,,,,,,,,,,,,0,,,,-0.0049,,,,,,300.0058289,,,,
,31993395.115,300.00712585,47381.287109375,-0.000105465435263733,1.70317020760884E-6,1,0.999253354069792,40.0298881530762,1.98399215257672,19.9699997901917,-0.00118790351589808,-0.000189562593554063,0.25,1.40356177400496E-6,-0.000105463242110689,1.33420685711305E-6,300.0068054,300.0074463,47354.04296875,47408.53125,56.546915223756,20.5366746844196,28.983419,0,0,0,40,4449,300.2616,47381.287109375,,,,,,,,,,,,,0,,,,0,,,,,,300.00712585,,,,
,31993490.22,300.0068054,52136.421875,-0.000122582406027823,1.85443082034897E-6,1,0.999253354069792,40.0298881530762,1.98371862062118,19.9699997901917,-0.00137707711157126,-0.000240158406669202,0.25,-1.36162638476833E-7,-0.000122578704986151,-2.16629871913285E-7,300.0068054,300.0068054,52106.03515625,52166.80859375,56.1092032529867,20.5453813727222,28.224119,0,0,0,40,4449,300.26535,52136.421875,,,,,,,,,,,,,0,,,,-0.00245,,,,,,300.0068054,,,,
,31993586.055,300.00440975,56923.677734375,-0.000140550204308605,2.95846191622352E-6,1,0.999253354069792,40.0298881530762,1.98349459015131,19.9699997901917,-0.00157567076223022,-0.000293134022467268,0.25,-1.74089392767478E-6,-0.000140544943040242,-1.83300582423863E-6,300.0043945,300.004425,56893.77734375,56953.578125,56.3694855498906,20.5486507786538,28.603769,0,0,0,40,4449,300.258,56923.677734375,,,,,,,,,,,,,0,,,,0,,,,,,300.00440975,,,,
,31993684.12,300.0041199,61826.57421875,-0.000154693321436369,2.25374006252708E-6,1,0.999253354069792,40.0298881530762,1.98372196957377,19.9699997901917,-0.0017381716893698,-0.000300986134975311,0.25,1.33380500634545E-8,-0.00015468880830474,-8.79781636100806E-8,300.0041199,300.0041199,61797.125,61856.0234375,56.4484300303329,20.5442953420834,28.224119,0,0,0,40,4449,300.2571,61826.57421875,,,,,,,,,,,,,0,,,,0.0049,,,,,,300.0041199,,,,
,31993784.21,300.0088806,66829.75390625,-0.000172137293227185,2.56089623286486E-6,1,0.999253354069792,40.0298881530762,1.98386660477056,19.9699997901917,-0.00193471750350346,-0.000332603198409378,0.25,2.23565410694666E-7,-0.000172132390111039,1.10951390149554E-7,300.0088806,300.0088806,66804.5390625,66854.96875,56.6328943608714,20.5403621282281,28.603769,0,0,0,40,4449,300.24185,66829.75390625,,,,,,,,,,,,,0,,,,-0.00245,,,,,,300.0088806,,,,
,31993883.725,300.00938415,71807.4375,-0.000189576845350806,2.35461764880263E-6,1,0.999253354069792,40.0298881530762,1.98343664593399,19.9699997901917,-0.00212671801312085,-0.000386820464144698,0.25,-1.58725113483695E-6,-0.000189570257447522,-1.71106844054182E-6,300.0091858,300.0095825,71782.4296875,71832.4453125,56.5281561392944,20.5504054182754,28.603769,0,0,0,40,4449,300.2355,71807.4375,,,,,,,,,,,,,0,,,,-0.0049,,,,,,300.00938415,,,,
,31993982.43,300.00759885,76738.17578125,-0.000207874877961597,2.9084409613598E-6,1,0.999253354069792,40.0298881530762,1.98366087603267,19.9699997901917,-0.0023421529014401,-0.000366995415459831,0.25,3.35089300057191E-6,-0.000207871006255021,3.21514423224464E-6,300.0072021,300.0079956,76705.6171875,76770.734375,56.4109118614098,20.543746901673,28.224119,0,0,0,40,4449,300.23085,76738.17578125,,,,,,,,,,,,,0,,,,0.00245,,,,,,300.00759885,,,,
,31994081.925,300.0174561,81711.171875,-0.000225391354350834,3.62897729899268E-6,1,0.999253354069792,40.0298881530762,1.98347784584608,19.9699997901917,-0.00253765817840952,-0.000407296359672961,0.25,2.79536783571641E-6,-0.000225386543429763,2.64838261121576E-6,300.0174561,300.0174561,81683.5703125,81738.7734375,56.2991389831598,20.5489791906551,28.983419,0,0,0,40,4449,300.2137,81711.171875,,,,,,,,,,,,,0,,,,0.00245,,,,,,300.0174561,,,,
,31994177.58,300.0129089,86491.8671875,-0.000236816364317352,3.86768166211186E-6,1,0.999253354069792,40.0298881530762,1.98342038071828,19.9699997901917,-0.00266397611587106,-0.000440870664601924,0.25,1.78503512084756E-6,-0.000236810612278426,1.63081783767862E-6,300.0129089,300.0129089,86461.96875,86521.765625,56.2225393882752,20.5495150394805,28.603769,0,0,0,40,4449,300.2005,86491.8671875,,,,,,,,,,,,,0,,,,-0.00245,,,,,,300.0129089,,,,
,31994283.375,300.0077209,88969.8515625,-0.000250389386905464,3.36907828730789E-6,1,0.999253354069792,40.0298881530762,1.98330411738685,19.9699997901917,-0.00281716948035297,-0.000462269401347935,0.25,2.22938051380363E-6,-0.000250383582888598,2.06642010011516E-6,300.0077209,300.0077209,88947.4375,88992.265625,56.4640626007175,20.5509451570964,28.603769,0,0,0,40,4449,300.19935,88969.8515625,,,,,,,,,,,,,0,,,,0,,,,,,300.0077209,,,,
,31994375.2,300.0065308,84381.67578125,-0.00022991952853284,2.74843942978027E-6,1,0.999253354069792,40.0298881530762,1.98350379410034,19.9699997901917,-0.00258459325925988,-0.000439038087029988,0.25,7.54960791402172E-7,-0.000229913352775656,6.05179096346619E-7,300.0065308,300.0065308,84349.1796875,84414.171875,56.3014838687175,20.5497720447367,28.224119,0,0,0,40,4449,300.19735,84381.67578125,,,,,,,,,,,,,0,,,,-0.00245,,,,,,300.0065308,,,,
,31994469.71,300.0002747,79654.953125,-0.00021415284041439,2.83524314492644E-6,1,0.999253354069792,40.0298881530762,1.98350957818231,19.9699997901917,-0.00240392325624403,-0.000428782997308668,0.25,-1.0635097983348E-6,-0.000214145969652809,-1.20313901592157E-6,300.0002747,300.0002747,79629.84375,79680.0625,56.4734421429483,20.5495604724609,28.983419,0,0,0,40,4449,300.1998,79654.953125,,,,,,,,,,,,,0,,,,0,,,,,,300.0002747,,,,
,31994564.335,299.995285,74923.9609375,-0.000200256678901981,3.00395202639763E-6,1,0.999253354069792,40.0298881530762,1.98332675868455,19.9699997901917,-0.00224705755727748,-0.000404848602451604,0.25,-1.34365575633943E-6,-0.000200250047211444,-1.47437151688954E-6,299.9951782,299.9953918,74891.5,74956.421875,56.2428617297752,20.5522189064193,28.603769,0,0,0,40,4449,300.2034,74923.9609375,,,,,,,,,,,,,0,,,,-0.00245,,,,,,299.995285,,,,
,31994659.385,299.9903564,70175.77734375,-0.000181769642215677,2.20491051203291E-6,1,0.999253354069792,40.0298881530762,1.98333804693334,19.9699997901917,-0.00204072356946968,-0.00036115221904015,0.25,-6.56531873626003E-7,-0.000181764009952303,-7.75333339045735E-7,299.9898376,299.9908752,70142.96875,70208.5859375,56.282724784256,20.5519017164276,28.983419,0,0,0,40,4449,300.21725,70175.77734375,,,,,,,,,,,,,0,,,,-0.00245,,,,,,299.9903564,,,,
,31994753.375,299.98855595,65477.548828125,-0.000169315556524624,2.87213200366784E-6,1,0.999253354069792,40.0298881530762,1.98343747262852,19.9699997901917,-0.00190675260015208,-0.000303178604929832,0.25,2.34776578902154E-6,-0.000169312245908835,2.23689051120955E-6,299.9879456,299.9891663,65449.81640625,65505.28125,56.618043419006,20.5515383781696,28.603769,0,0,0,40,4449,300.2208,65477.548828125,,,,,,,,,,,,,0,,,,0.00245,,,,,,299.98855595,,,,
,31994846.865,299.98687745,60801.78515625,-0.000153114215331054,1.99884381409863E-6,1,0.999253354069792,40.0298881530762,1.98341602856523,19.9699997901917,-0.00172029630760548,-0.00029717574569622,0.25,7.50287394544643E-8,-0.000153109880666456,-2.5288206030703E-8,299.9866333,299.9871216,60771.87890625,60831.69140625,56.2749084990636,20.5492679563202,28.983419,0,0,0,40,4449,300.23695,60801.78515625,,,,,,,,,,,,,0,,,,-0.0049,,,,,,299.98687745,,,,
,31994941.47,299.99087525,56073.998046875,-0.000136996878819255,1.88721092186291E-6,1,0.999253354069792,40.0298881530762,1.98339121488227,19.9699997901917,-0.00154067537982763,-0.000257335693382542,0.25,8.28750115983431E-7,-0.000136993470982499,7.38865339881872E-7,299.9908142,299.9909363,56044.0390625,56103.95703125,56.5390989385637,20.549111889747,28.603769,0,0,0,40,4449,300.23105,56073.998046875,,,,,,,,,,,,,0,,,,-0.00245,,,,,,299.99087525,,,,
,31995037.19,299.9853821,51289.07421875,-0.000119661645571188,1.78983578368485E-6,1,0.999253354069792,40.0298881530762,1.98334612044339,19.9699997901917,-0.00134716721847183,-0.000216260511735296,0.25,1.48128880649166E-6,-0.000119659182495733,1.40266657547343E-6,299.9853821,299.9853821,51261.5078125,51316.640625,56.5985027060252,20.5511504241056,28.983419,0,0,0,40,4449,300.233,51289.07421875,,,,,,,,,,,,,0,,,,0,,,,,,299.9853821,,,,
,31995134.29,299.98703,46436.201171875,-0.000104093627191201,1.68175919754538E-6,1,0.999253354069792,40.0298881530762,1.9835399660924,19.9699997901917,-0.00116829972746061,-0.000209555518795343,0.25,-6.17259816208311E-7,-0.000104090219869774,-6.85672040670502E-7,299.98703,299.98703,46408.69140625,46463.7109375,56.3804283491598,20.5480564881753,28.603769,0,0,0,40,4449,300.2505,46436.201171875,,,,,,,,,,,,,0,,,,-0.0049,,,,,,299.98703,,,,
,31995231.96,299.9901123,41555.97265625,-8.61046948658135E-5,1.55030878496484E-6,1,0.999253354069792,40.0298881530762,1.98340755442728,19.9699997901917,-0.000968195233720835,-0.000162612154162406,0.25,4.4350589272126E-7,-8.61024889133591E-5,3.86827657584513E-7,299.9901123,299.9901123,41526.1953125,41585.75,56.5891231637945,20.5506358803746,28.603769,0,0,0,40,4449,300.2631,41555.97265625,,,,,,,,,,,,,0,,,,0.00245,,,,,,299.9901123,,,,
,31995325.025,299.9910126,36903.087890625,-7.20514077444749E-5,1.57211542682046E-6,1,0.999253354069792,40.0298881530762,1.98324569229444,19.9699997901917,-0.000812314044547065,-0.00012334736876935,0.25,1.5029625137341E-6,-7.20503009065669E-5,1.45545147962225E-6,299.9902649,299.9917603,36873.07421875,36933.1015625,56.5047072837175,20.5538693760448,28.224119,0,0,0,40,4449,300.2606,36903.087890625,,,,,,,,,,,,,0,,,,0.00245,,,,,,299.9910126,,,,
,31995422.9,299.9871826,32011.1357421875,-5.61133421893365E-5,1.4219870715122E-6,1,0.999253354069792,40.0298881530762,1.98333544838719,19.9699997901917,-0.000630413640229004,-0.000108999078874922,0.25,1.93440411137535E-8,-5.61117262102621E-5,-1.76610612660354E-8,299.9871826,299.9871826,31986.53125,32035.740234375,56.5727089648906,20.5536143343442,28.603769,0,0,0,40,4449,300.2792,32011.1357421875,,,,,,,,,,,,,0,,,,0.00245,,,,,,299.9871826,,,,
,31995521.905,299.99557495,27063.5927734375,-3.97949873623676E-5,1.36458474560134E-6,1,0.999253354069792,40.0298881530762,1.98335591198406,19.9699997901917,-0.000445498366750929,-8.64704837172802E-5,0.25,-8.02410106072573E-7,-3.97932881763212E-5,-8.28656600591584E-7,299.9953613,299.9957886,27033.349609375,27093.8359375,56.3554162365444,20.5523169064558,28.603769,0,0,0,40,4449,300.2884,27063.5927734375,,,,,,,,,,,,,0,,,,0,,,,,,299.99557495,,,,
,31995618.21,299.9865417,22251.0537109375,-2.38781116644158E-5,9.62217426725729E-7,1,0.999253354069792,40.0298881530762,1.98332785506183,19.9699997901917,-0.000269089899962453,-4.15993637348321E-5,0.25,4.34046935497887E-7,-2.38777031401295E-5,4.18256450855791E-7,299.9865417,299.9865417,22225.609375,22276.498046875,56.4765686570252,20.5517638463642,28.603769,0,0,0,40,4449,300.2985,22251.0537109375,,,,,,,,,,,,,0,,,,0,,,,,,299.9865417,,,,
,31995715.01,299.98884585,17410.9814453125,-8.77356300988672E-6,8.09239548832498E-7,1,0.999253354069792,40.0298881530762,1.98333926961084,19.9699997901917,-9.94140141997094E-5,-1.21598144465921E-5,0.25,4.37676803124078E-7,-8.77359577923935E-6,4.31861184519427E-7,299.9882813,299.9894104,17383.5,17438.462890625,56.648526931256,20.555625226624,28.983419,0,0,0,40,4449,300.29925,17410.9814453125,,,,,,,,,,,,,0,,,,0,,,,,,299.98884585,,,,
,31995812.195,299.991272,12553.4282226563,6.53255087381387E-6,6.43386017929572E-7,1,0.999253354069792,40.0298881530762,1.98329732200711,19.9699997901917,7.27433150446647E-5,1.64189121038632E-5,0.25,3.29748469857378E-7,6.53214056647443E-6,3.34062985081258E-7,299.991272,299.991272,12550.88671875,12555.9697265625,56.6883899857368,20.5550222208538,28.603769,0,0,0,40,4449,300.319,12553.4282226563,,,,,,,,,,,,,0,,,,-0.00245,,,,,,299.991272,,,,
,31995907.515,299.992218,7790.6806640625,2.08445249215692E-5,5.44192138019941E-7,1,0.999253354069792,40.0298881530762,1.98330484911397,19.9699997901917,0.000232805539591594,4.84070942663621E-5,0.25,6.97554127910432E-7,2.08434482472498E-5,7.1134350334263E-7,299.992218,299.992218,7788.275390625,7793.0859375,56.6837002146214,20.556641765042,28.224119,0,0,0,40,4449,300.3088,7790.6806640625,,,,,,,,,,,,,0,,,,0,,,,,,299.992218,,,,
,31996002.43,299.993866,3045.15075683594,2.7373689762429E-5,4.1547007089278E-7,1,0.999253354069792,40.0298881530762,1.98322550310382,19.9699997901917,0.00030772813649701,5.19531883478278E-5,0.25,-1.17855553298566E-7,2.73729581252834E-5,-9.97038419433467E-8,299.993866,299.993866,3020.12329101562,3070.17822265625,56.8197035769676,20.5581598159901,28.224119,0,0,0,40,4449,300.31635,3045.15075683594,,,,,,,,,,,,,0,,,,0.00245,,,,,,299.993866,,,,
,31996095.095,299.9965515,-1582.81854248047,-2.57775899543571E-5,4.81725154753506E-7,1,0.999253354069792,40.0298881530762,1.98329903861848,19.9699997901917,-0.000288704705694797,-5.52208817437862E-5,0.25,-4.49398986741933E-7,-2.57765266326497E-5,-4.66478801604974E-7,299.9965515,299.9965515,-1610.099609375,-1555.53747558594,56.5328459104098,20.5576554939679,28.603769,0,0,0,40,4449,300.3179,-1582.81854248047,,,,,,,,,,,,,0,,,,0.00245,,,,,,299.9965515,,,,
,31996191.045,299.9986877,-6377.54541015625,-2.27698096761014E-5,5.15839431114801E-7,1,0.999253354069792,40.0298881530762,1.98334160007925,19.9699997901917,-0.000255537604756122,-4.58101243616693E-5,0.25,-1.3273220823017E-7,-2.27690448709413E-5,-1.47816715298466E-7,299.9986877,299.9986877,-6382.58251953125,-6372.50830078125,56.4953277414867,20.5572955234505,28.603769,0,0,0,40,4449,300.3167,-6377.54541015625,,,,,,,,,,,,,0,,,,0.0049,,,,,,299.9986877,,,,
,31996284.21,300.0066528,-11035.9252929688,-1.08913697546381E-5,6.89732744701431E-7,1,0.999253354069792,40.0298881530762,1.98335977267089,19.9699997901917,-0.000121001185855672,-2.90108652326736E-5,0.25,-6.95370208886249E-7,-1.08905829272275E-5,-7.0256115021364E-7,300.0059814,300.0073242,-11066.005859375,-11005.8447265625,56.7360693254098,20.5565377590181,28.603769,0,0,0,40,4449,300.30815,-11035.9252929688,,,,,,,,,,,,,0,,,,-0.00245,,,,,,300.0066528,,,,
,31996380.095,299.9972839,-15825.7797851562,3.32627461365289E-6,6.58874937734572E-7,1,0.999253354069792,40.0298881530762,1.98350257557644,19.9699997901917,3.86552315250225E-5,-9.41779702982021E-7,0.25,-6.6013050616517E-7,3.32661294491389E-6,-6.57910479919331E-7,299.9969482,299.9976196,-15858.3525390625,-15793.20703125,56.7134020983521,20.5551416239125,28.603769,0,0,0,40,4449,300.31705,-15825.7797851562,,,,,,,,,,,,,0,,,,-0.00245,,,,,,299.9972839,,,,
,31996478.02,300.00769045,-20720.65625,1.86701060273112E-5,1.03728787024011E-6,1,0.999253354069792,40.0298881530762,1.98345359618164,19.9699997901917,0.000210204713086823,3.37236286929243E-5,0.25,-2.32971608918154E-7,1.86697018398279E-5,-2.20624563822891E-7,300.0070496,300.0083313,-20750.658203125,-20690.654296875,56.8181403199291,20.5544971389954,28.603769,0,0,0,40,4449,300.3043,-20720.65625,,,,,,,,,,,,,0,,,,0,,,,,,300.00769045,,,,
,31996576.85,300.0081482,-25662.8740234375,3.56672200297257E-5,1.20171695747638E-6,1,0.999253354069792,40.0298881530762,1.98348039808845,19.9699997901917,0.000401819130049195,6.3037817960175E-5,0.25,-5.68621285996201E-7,3.56665306820993E-5,-5.45053379777229E-7,300.0078125,300.0084839,-25692.970703125,-25632.77734375,56.5789619930445,20.5555124065445,28.224119,0,0,0,40,4449,300.3009,-25662.8740234375,,,,,,,,,,,,,0,,,,0,,,,,,300.0081482,,,,
,31996678.15,300.0140381,-30722.7138671875,5.13649078684327E-5,1.26935907243572E-6,1,0.999253354069792,40.0298881530762,1.98335330750081,19.9699997901917,0.000581231006163463,7.57656643476203E-5,0.25,-2.15500386941977E-6,5.1364788159446E-5,-2.12105798216525E-6,300.0140381,300.0140381,-30729.98046875,-30715.447265625,56.7493570102368,20.5585111492763,28.603769,0,0,0,40,4449,300.2892,-30722.7138671875,,,,,,,,,,,,,0,,,,0,,,,,,300.0140381,,,,
,31996777.935,300.01416015,-35709.77734375,6.89420377195067E-5,1.38810718117113E-6,1,0.999253354069792,40.0298881530762,1.98321848438379,19.9699997901917,0.000776562429599726,0.000121979025095898,0.25,-1.08591505179102E-6,6.89406886057612E-5,-1.04045430667427E-6,300.013855,300.0144653,-35742.4375,-35677.1171875,56.7024592990829,20.5610810080755,28.983419,0,0,0,40,4449,300.27555,-35709.77734375,,,,,,,,,,,,,0,,,,0.0049,,,,,,300.01416015,,,,
,31996877.36,300.00942995,-40679.814453125,8.66189410885753E-5,1.63832504739002E-6,1,0.999253354069792,40.0298881530762,1.98322125293754,19.9699997901917,0.0009756219067515,0.000153569568815037,0.25,-1.33627997668999E-6,8.66172468107069E-5,-1.27922526434165E-6,300.0090332,300.0098267,-40709.80078125,-40649.828125,56.7743691228522,20.5627651037458,28.603769,0,0,0,40,4449,300.26375,-40679.814453125,,,,,,,,,,,,,0,,,,0,,,,,,300.00942995,,,,
,31996976.57,300.0083466,-45639.78515625,0.000103164660032014,1.78480726330919E-6,1,0.999253354069792,40.0298881530762,1.98309754278468,19.9699997901917,0.00115990192530797,0.000194503487337536,0.25,-5.57834720287562E-7,0.000103161972098696,-4.89988253601663E-7,300.0080872,300.008606,-45672.31640625,-45607.25390625,56.6110087623329,20.5624450477992,28.224119,0,0,0,40,4449,300.25775,-45639.78515625,,,,,,,,,,,,,0,,,,0,,,,,,300.0083466,,,,
,31997075.81,300.010437,-50597.19140625,0.000117662686580943,1.53914210171705E-6,1,0.999253354069792,40.0298881530762,1.98323385608902,19.9699997901917,0.00132473415043745,0.000211803208197057,0.25,-1.53070046463657E-6,0.000117660206949774,-1.45338164106287E-6,300.010437,300.010437,-50629.69921875,-50564.68359375,56.5187765970637,20.5650985240907,28.224119,0,0,0,40,4449,300.25345,-50597.19140625,,,,,,,,,,,,,0,,,,-0.0049,,,,,,300.010437,,,,
,31997174.96,300.0110474,-55553.892578125,0.000135798434711941,2.3901752759793E-6,1,0.999253354069792,40.0298881530762,1.98320519574953,19.9699997901917,0.0015254645607489,0.000264268265900207,0.25,-1.91112389592278E-9,0.000135794419819286,8.71733821830274E-8,300.0110474,300.0110474,-55561.5390625,-55546.24609375,56.5476968522752,20.5632444339623,28.224119,0,0,0,40,4449,300.23525,-55553.892578125,,,,,,,,,,,,,0,,,,0.0049,,,,,,300.0110474,,,,
,31997272.76,300.01516725,-60441.21875,0.000154042888736931,1.75938059105478E-6,1,0.999253354069792,40.0298881530762,1.98330486852126,19.9699997901917,0.00173072116240108,0.000298469588888077,0.25,-1.19317246567412E-7,0.000154038398915134,-1.8378781951326E-8,300.0141907,300.0161438,-60473.7734375,-60408.6640625,56.800944492506,20.5624879104856,28.224119,0,0,0,40,4449,300.22965,-60441.21875,,,,,,,,,,,,,0,,,,-0.00245,,,,,,300.01516725,,,,
,31997374.325,300.01428225,-65516.07421875,0.000170150853501827,2.07635161497554E-6,1,0.999253354069792,40.0298881530762,1.98307099696535,19.9699997901917,0.00191227226175493,0.00032509385482634,0.25,-5.36645611438967E-7,0.000170146176304764,-4.25273473587444E-7,300.0137024,300.0148621,-65546.0078125,-65486.140625,56.7259081546598,20.5663231362473,28.983419,0,0,0,40,4449,300.2145,-65516.07421875,,,,,,,,,,,,,0,,,,0.00245,,,,,,300.01428225,,,,
,31997472.9,300.0085907,-70443.12109375,0.000186847136197117,2.20701991545211E-6,1,0.999253354069792,40.0298881530762,1.98318649301986,19.9699997901917,0.00210030436274822,0.000355453399238489,0.25,-7.28089482512441E-7,0.000186842141896139,-6.0593578862129E-7,300.0085449,300.0086365,-70468.0625,-70418.1796875,56.6289862182752,20.5671182478435,28.983419,0,0,0,40,4449,300.2144,-70443.12109375,,,,,,,,,,,,,0,,,,0.00245,,,,,,300.0085907,,,,
,31997571.49,300.0149231,-75372.29296875,0.000204603965746613,2.76353115476529E-6,1,0.999253354069792,40.0298881530762,1.98320728569485,19.9699997901917,0.00230424957569749,0.000364289299421948,0.25,-3.01802699427736E-6,0.000204599913876167,-2.88436143932205E-6,300.0142822,300.015564,-75404.7265625,-75339.859375,56.7524835243137,20.5686015069731,28.983419,0,0,0,40,4449,300.20485,-75372.29296875,,,,,,,,,,,,,0,,,,-0.00245,,,,,,300.0149231,,,,
,31997669.735,300.0148315,-80282.4375,0.00021752927907342,2.17431268077879E-6,1,0.999253354069792,40.0298881530762,1.98319262079831,19.9699997901917,0.00245022787489152,0.00038481416156657,0.25,-3.42977284774027E-6,0.000217525128517222,-3.28782480349647E-6,300.0148315,300.0148315,-80312.6640625,-80252.2109375,57.088583787583,20.5675116334449,28.603769,0,0,0,40,4449,300.1842,-80282.4375,,,,,,,,,,,,,0,,,,0.00245,,,,,,300.0148315,,,,
,31997769.54,300.01690675,-85269.32421875,0.000235867885911847,2.48419292212214E-6,1,0.999253354069792,40.0298881530762,1.98313613091538,19.9699997901917,0.00265631751604363,0.000419565975672519,0.25,-3.51203191058609E-6,0.000235863247044915,-3.35831442489315E-6,300.0167542,300.0170593,-85294.3671875,-85244.28125,56.7220000120637,20.5689167829323,28.983419,0,0,0,40,4449,300.1709,-85269.32421875,,,,,,,,,,,,,0,,,,0,,,,,,300.01690675,,,,
,31997880.36,300.017395,-89957.43359375,0.000253313814521496,2.76678405954317E-6,1,0.999253354069792,40.0298881530762,1.98307026704592,19.9699997901917,0.00284753423135289,0.000480409134721856,0.25,-1.11643422164702E-6,0.00025330711533662,-9.5162270508442E-7,300.017395,300.017395,-89983.8984375,-89930.96875,56.7321611828137,20.5695904190775,28.983419,0,0,0,40,4449,300.1626,-89957.43359375,,,,,,,,,,,,,0,,,,0,,,,,,300.017395,,,,
,31997976.185,300.00642395,-85188.0234375,0.000239425791477102,3.07617285940414E-6,1,0.999253354069792,40.0298881530762,1.98332575727298,19.9699997901917,0.00269618957907855,0.000428496570541186,0.25,-3.33690159612465E-6,0.000239421023389635,-3.18086191775778E-6,300.0053711,300.0074768,-85220.640625,-85155.40625,56.648526931256,20.5644886672675,28.603769,0,0,0,40,4449,300.15755,-85188.0234375,,,,,,,,,,,,,0,,,,0,,,,,,300.00642395,,,,
,31998073.765,300.0013275,-80310.140625,0.00021915165626975,1.95312842701645E-6,1,0.999253354069792,40.0298881530762,1.98359153792452,19.9699997901917,0.00246826035010105,0.00039189939088649,0.25,-3.08684016400648E-6,0.000219147339790152,-2.94383257448724E-6,300.0012512,300.0014038,-80342.9609375,-80277.3203125,56.8900501436983,20.5587087324999,28.983419,0,0,0,40,4449,300.15865,-80310.140625,,,,,,,,,,,,,0,,,,-0.00245,,,,,,300.0013275,,,,
,31998175.015,299.9924622,-75250.53125,0.000205612465134565,2.21476475760862E-6,1,0.999253354069792,40.0298881530762,1.98324620965395,19.9699997901917,0.00231164086628729,0.000389247633712455,0.25,-9.71636753758265E-7,0.000205607211021685,-8.37344396208351E-7,299.9924622,299.9924622,-75280.5546875,-75220.5078125,57.0510656186599,20.5671771676561,28.603769,0,0,0,40,4449,300.15655,-75250.53125,,,,,,,,,,,,,0,,,,0.00245,,,,,,299.9924622,,,,
,31998275.33,299.9902649,-70235.9140625,0.000187020523030802,2.97018328040677E-6,1,0.999253354069792,40.0298881530762,1.98329521237554,19.9699997901917,0.00210377573514998,0.000347658296801815,0.25,-1.45372948274961E-6,0.000187016119105486,-1.3314176558138E-6,299.9902649,299.9902649,-70238.28125,-70233.546875,56.7790588939676,20.5652151352464,28.224119,0,0,0,40,4449,300.1764,-70235.9140625,,,,,,,,,,,,,0,,,,0.00245,,,,,,299.9902649,,,,
,31998372.85,299.9852295,-65364.205078125,0.000168010253841837,2.20591189984099E-6,1,0.999253354069792,40.0298881530762,1.98329939255776,19.9699997901917,0.00188783346875432,0.000324450681529908,0.25,-2.26268792859383E-7,0.000168005610683219,-1.1629047780137E-7,299.9852295,299.9852295,-65391.58203125,-65336.828125,56.7876568076791,20.5641546325155,28.983419,0,0,0,40,4449,300.18585,-65364.205078125,,,,,,,,,,,,,0,,,,-0.00245,,,,,,299.9852295,,,,
,31998474.01,299.98526,-60306.650390625,0.000150888881455279,1.85415694875148E-6,1,0.999253354069792,40.0298881530762,1.98350126455033,19.9699997901917,0.0016990382665875,0.000271658160608003,0.25,-1.96187897137861E-6,0.000150885853587887,-1.86294133233389E-6,299.9852295,299.9852905,-60334.01171875,-60279.2890625,56.7985996069483,20.561100844741,29.363071,0,0,0,40,4449,300.20395,-60306.650390625,,,,,,,,,,,,,0,,,,0.00245,,,,,,299.98526,,,,
,31998573.625,299.98094175,-55329.70703125,0.000134769091057194,1.82337840325387E-6,1,0.999253354069792,40.0298881530762,1.98334767898367,19.9699997901917,0.00151743462169772,0.000242500372011388,0.25,-1.76289995720955E-6,0.000134766406416651,-1.67442521242137E-6,299.9801025,299.981781,-55362.171875,-55297.2421875,56.5547315089483,20.5618235243317,28.983419,0,0,0,40,4449,300.205,-55329.70703125,,,,,,,,,,,,,0,,,,0.00245,,,,,,299.98094175,,,,
,31998673.29,299.9906616,-50347.30859375,0.00011947124225465,1.92852218101993E-6,1,0.999253354069792,40.0298881530762,1.98334975699753,19.9699997901917,0.00134519357353802,0.000214947865638415,0.25,-1.56519812829793E-6,0.000119468815393331,-1.48667593288769E-6,299.9906616,299.9906616,-50374.83203125,-50319.78515625,56.7493570102368,20.5615619309545,28.983419,0,0,0,40,4449,300.21755,-50347.30859375,,,,,,,,,,,,,0,,,,0,,,,,,299.9906616,,,,
,31998772.43,299.9902954,-45393.041015625,9.99627324406144E-5,1.50615723618638E-6,1,0.999253354069792,40.0298881530762,1.98331391612121,19.9699997901917,0.00112649213714342,0.000174216690220441,0.25,-1.81077574158693E-6,9.9961027161223E-5,-1.74498765836169E-6,299.9902954,299.9902954,-45397.9375,-45388.14453125,56.8040710065829,20.562351240563,28.603769,0,0,0,40,4449,300.2301,-45393.041015625,,,,,,,,,,,,,0,,,,0,,,,,,299.9902954,,,,
,31998871.18,299.9881134,-40458.234375,8.63302176436183E-5,1.46866384517824E-6,1,0.999253354069792,40.0298881530762,1.98352474647172,19.9699997901917,0.00097480157667749,0.000139869644466755,0.25,-2.50767469437795E-6,8.63293683501887E-5,-2.45076469424783E-6,299.9878845,299.9883423,-40460.75390625,-40455.71484375,56.9486722826406,20.5544270679028,28.603769,0,0,0,40,4449,300.221,-40458.234375,,,,,,,,,,,,,0,,,,0,,,,,,299.9881134,,,,
,31998968.385,299.99038695,-35600.36328125,6.92744027978107E-5,1.44740257012672E-6,1,0.999253354069792,40.0298881530762,1.98340349987523,19.9699997901917,0.000777979481061293,0.000136412612153299,0.25,1.40288226839699E-7,6.92722940589967E-5,1.859406322318E-7,299.9903564,299.9904175,-35627.8203125,-35572.90625,56.472660514429,20.5573071729149,28.983419,0,0,0,40,4449,300.2302,-35600.36328125,,,,,,,,,,,,,0,,,,-0.00245,,,,,,299.99038695,,,,
,31999065.215,299.9898987,-30764.1064453125,5.35616221262075E-5,1.19588330286763E-6,1,0.999253354069792,40.0298881530762,1.98329702534262,19.9699997901917,0.000604686340672466,8.70045125200819E-5,0.25,-1.53497474886148E-6,5.3561073602324E-5,-1.49959374027117E-6,299.9898987,299.9898987,-30766.42578125,-30761.787109375,56.6719757868329,20.5595108399136,28.983419,0,0,0,40,4449,300.2435,-30764.1064453125,,,,,,,,,,,,,0,,,,0.0049,,,,,,299.9898987,,,,
,31999163.565,299.98321535,-25846.0263671875,3.66307627178591E-5,1.19537933242988E-6,1,0.999253354069792,40.0298881530762,1.98331296108752,19.9699997901917,0.00041326957566777,6.11092267750902E-5,0.25,-9.06794350828929E-7,3.66303004777402E-5,-8.82577367066837E-7,299.9828186,299.9836121,-25873.5234375,-25818.529296875,56.6837002146214,20.5604048204583,28.603769,0,0,0,40,4449,300.2539,-25846.0263671875,,,,,,,,,,,,,0,,,,-0.00245,,,,,,299.98321535,,,,
,31999259.52,299.98764035,-21051.5712890625,1.98919922095226E-5,9.88574115477459E-7,1,0.999253354069792,40.0298881530762,1.98325600991133,19.9699997901917,0.000225106390416551,2.91989190536756E-5,0.25,-8.47176528480761E-7,1.98919716918027E-5,-8.34002224372101E-7,299.9868469,299.9884338,-21081.544921875,-21021.59765625,56.7751507513714,20.5612647178121,29.363071,0,0,0,40,4449,300.2511,-21051.5712890625,,,,,,,,,,,,,0,,,,-0.00245,,,,,,299.98764035,,,,
,31999357.045,299.9908447,-16176.8784179687,4.43763982966932E-6,8.4871049385551E-7,1,0.999253354069792,40.0298881530762,1.98316871278873,19.9699997901917,5.09533692105139E-5,2.25848919623967E-6,0.25,-5.67800125023132E-7,4.43788524688045E-6,-5.64847447251822E-7,299.9908447,299.9908447,-16199.3173828125,-16154.439453125,56.5289377678137,20.5621408815373,28.983419,0,0,0,40,4449,300.2755,-16176.8784179687,,,,,,,,,,,,,0,,,,-0.00245,,,,,,299.9908447,,,,
,31999451.04,299.9887695,-11479.365234375,-9.08467264357366E-6,6.45720949504179E-7,1,0.999253354069792,40.0298881530762,1.98317116494614,19.9699997901917,-0.00010117063167987,-2.27496716834626E-5,0.25,-4.51240178395278E-7,-9.08410742521944E-6,-4.57242561648259E-7,299.9887695,299.9887695,-11512.0693359375,-11446.6611328125,56.7001144135252,20.5611137792046,28.983419,0,0,0,40,4449,300.282,-11479.365234375,,,,,,,,,,,,,0,,,,0.00245,,,,,,299.9887695,,,,
,31999545.815,299.99375915,-6740.94775390625,-2.14367137910201E-5,6.200552855299E-7,1,0.999253354069792,40.0298881530762,1.98333791645773,19.9699997901917,-0.000239642809023878,-4.85161435041702E-5,0.25,-6.0458660230161E-7,-2.14356795667106E-5,-6.18775219070127E-7,299.9935913,299.993927,-6773.40087890625,-6708.49462890625,56.6782288149868,20.5570117683396,28.224119,0,0,0,40,4449,300.2769,-6740.94775390625,,,,,,,,,,,,,0,,,,0.00245,,,,,,299.99375915,,,,
,31999637.475,299.988327,-2157.49475097656,-2.74523279734471E-5,3.71690059917753E-7,1,0.999253354069792,40.0298881530762,1.98312495109988,19.9699997901917,-0.00030747935078569,-5.85522404343403E-5,0.25,-4.56217979046359E-7,-2.74512184449848E-5,-4.74408939519119E-7,299.9877319,299.9889221,-2190.00659179687,-2124.98291015625,57.0057311645445,20.5597900912349,28.983419,0,0,0,40,4449,300.2903,-2157.49475097656,,,,,,,,,,,,,0,,,,0,,,,,,299.988327,,,,
,31999728.745,299.9908142,2398.56823730469,2.80988124118343E-5,4.06496801713025E-7,1,0.999253354069792,40.0298881530762,1.98320796535266,19.9699997901917,0.000316126734898264,5.18884235961264E-5,0.25,-2.4921997934612E-7,2.80981492404864E-5,-2.30580510794855E-7,299.9908142,299.9908142,2373.462890625,2423.67358398438,56.3898078913906,20.5584565096266,28.603769,0,0,0,40,4449,300.29535,2398.56823730469,,,,,,,,,,,,,0,,,,0.00245,,,,,,299.9908142,,,,
,31999821.42,300.0024414,7032.86474609375,2.28290600584209E-5,5.92745186383244E-7,1,0.999253354069792,40.0298881530762,1.98340597141012,19.9699997901917,0.000256070364372001,4.67393372315334E-5,0.25,2.05052528691809E-7,2.28282424967852E-5,2.20174055647506E-7,300.0024414,300.0024414,7007.8349609375,7057.89453125,56.5398805670829,20.5532016968552,28.603769,0,0,0,40,4449,300.2912,7032.86474609375,,,,,,,,,,,,,0,,,,-0.00245,,,,,,300.0024414,,,,
,31999915.4,300.0075073,11731.0205078125,9.58094327702129E-6,6.56527480621546E-7,1,0.999253354069792,40.0298881530762,1.98321992158514,19.9699997901917,0.000107494861499918,1.94037504747364E-5,0.25,6.7354621682272E-8,9.58061128354721E-6,7.36965279887501E-8,300.0075073,300.0075073,11701.0693359375,11760.9716796875,56.6555615879291,20.5576612014462,28.983419,0,0,0,40,4449,300.2827,11731.0205078125,,,,,,,,,,,,,0,,,,0.00245,,,,,,300.0075073,,,,
,32000009.07,300.0091705,16411.5712890625,-4.23680235939583E-6,6.60209675513723E-7,1,0.999253354069792,40.0298881530762,1.98317938437284,19.9699997901917,-4.82628133577982E-5,-4.37690444797069E-6,0.25,3.44417523616706E-7,-4.23690309021153E-6,3.41604237052578E-7,300.0085449,300.0097961,16379.181640625,16443.9609375,56.6305494753137,20.5587753939116,28.603769,0,0,0,40,4449,300.28055,16411.5712890625,,,,,,,,,,,,,0,,,,0,,,,,,300.0091705,,,,
,32000104.455,300.0074005,21178.5419921875,-2.0943420100514E-5,9.72222642454361E-7,1,0.999253354069792,40.0298881530762,1.98313085078417,19.9699997901917,-0.000234191464444245,-4.68948747963779E-5,0.25,-5.46189952433776E-7,-2.0942433106906E-5,-5.60016869403345E-7,300.0066528,300.0081482,21146.12109375,21210.962890625,56.6375841319868,20.5586557380612,28.603769,0,0,0,40,4449,300.26985,21178.5419921875,,,,,,,,,,,,,0,,,,0,,,,,,300.0074005,,,,
,32000198.235,300.0073853,25866.357421875,-3.57637496899979E-5,1.06108544459506E-6,1,0.999253354069792,40.0298881530762,1.98310767044896,19.9699997901917,-0.000400450353725768,-7.69566505502004E-5,0.25,-6.54791669358435E-7,-3.57622504865049E-5,-6.78388095236493E-7,300.0073853,300.0073853,25863.9296875,25868.78515625,56.648526931256,20.5595083490452,28.983419,0,0,0,40,4449,300.2762,25866.357421875,,,,,,,,,,,,,0,,,,0,,,,,,300.0073853,,,,
,32000293.43,300.00619505,30624.55078125,-5.06843086295654E-5,1.20047762153077E-6,1,0.999253354069792,40.0298881530762,1.98306969552936,19.9699997901917,-0.000569076833757175,-0.000100000368981754,0.25,-1.21375846743905E-7,-5.06827217023142E-5,-1.54808642915847E-7,300.0057068,300.0066833,30597.083984375,30652.017578125,56.5555131374675,20.5608983698582,28.983419,0,0,0,40,4449,300.2633,30624.55078125,,,,,,,,,,,,,0,,,,0.00245,,,,,,300.00619505,,,,
,32000389.14,300.01295475,35406.96875,-6.70151408192074E-5,1.30848443632708E-6,1,0.999253354069792,40.0298881530762,1.98319141606024,19.9699997901917,-0.000753842171477543,-0.000124374075418214,0.25,5.38723661315837E-7,-6.70134911726304E-5,4.94541923801993E-7,300.0126038,300.0133057,35379.421875,35434.515625,56.7001144135252,20.5559948327947,28.983419,0,0,0,40,4449,300.2517,35406.96875,,,,,,,,,,,,,0,,,,0,,,,,,300.01295475,,,,
,32000486,300.0110321,40249.98046875,-8.28748847968605E-5,1.38978371286105E-6,1,0.999253354069792,40.0298881530762,1.98314898857413,19.9699997901917,-0.000932278533311505,-0.000153506943317056,0.25,6.92712958982816E-7,-8.2872872586153E-5,6.38131867070321E-7,300.0109253,300.0111389,40227.52734375,40272.43359375,56.4914195988906,20.5584444882478,29.363071,0,0,0,40,4449,300.24235,40249.98046875,,,,,,,,,,,,,0,,,,-0.00245,,,,,,300.0110321,,,,
,32000582.53,300.0118103,45075.349609375,-9.96386068295016E-5,1.70755163897834E-6,1,0.999253354069792,40.0298881530762,1.98316277941202,19.9699997901917,-0.00111581282869143,-0.000213719394452299,0.25,-1.76317213821451E-6,-9.96344833908374E-5,-1.82864502007223E-6,300.0112305,300.0123901,45045.3203125,45105.37890625,56.6336759893906,20.5545928498116,28.603769,0,0,0,40,4449,300.23765,45075.349609375,,,,,,,,,,,,,0,,,,0,,,,,,300.0118103,,,,
,32000677.195,300.0107117,49805.509765625,-0.000116586657098472,2.13914001110953E-6,1,0.999253354069792,40.0298881530762,1.98304075277948,19.9699997901917,-0.00131150242147337,-0.000215588959524421,0.25,1.00550475555657E-6,-0.000116583861391046,9.28884813934205E-7,300.0107117,300.0107117,49772.93359375,49838.0859375,56.6235148186406,20.5583648004643,28.983419,0,0,0,40,4449,300.2235,49805.509765625,,,,,,,,,,,,,0,,,,-0.00245,,,,,,300.0107117,,,,
,32000773.21,300.0128479,54605.53515625,-0.000132761219204909,1.59791685879136E-6,1,0.999253354069792,40.0298881530762,1.98314642673707,19.9699997901917,-0.00149305337734211,-0.000248254671814501,0.25,9.00657419782477E-7,-0.000132757872793076,8.13510304416659E-7,300.0125122,300.0131836,54580.78515625,54630.28515625,56.5140868259483,20.55678572063,28.983419,0,0,0,40,4449,300.2103,54605.53515625,,,,,,,,,,,,,0,,,,0.00245,,,,,,300.0128479,,,,
,32000868.665,300.0125885,59375.84765625,-0.000147779946383985,2.28511658775276E-6,1,0.999253354069792,40.0298881530762,1.98325650596149,19.9699997901917,-0.00165927853722357,-0.000292318749471202,0.25,-4.18787563435109E-7,-0.000147775300153506,-5.15641569802001E-7,300.0122986,300.0128784,59343.39453125,59408.30078125,56.4109118614098,20.5534763838543,28.603769,0,0,0,40,4449,300.20335,59375.84765625,,,,,,,,,,,,,0,,,,0.00245,,,,,,300.0125885,,,,
,32000967.515,300.0112762,64316.2421875,-0.000165760134705694,2.09181520166043E-6,1,0.999253354069792,40.0298881530762,1.98333042945151,19.9699997901917,-0.00186722607220605,-0.000293271341390931,0.25,2.61231671891467E-6,-0.000165756960723843,2.50371766559941E-6,300.0103149,300.0122375,64291.1328125,64341.3515625,56.3968425480637,20.5516973460219,28.603769,0,0,0,40,4449,300.198,64316.2421875,,,,,,,,,,,,,0,,,,-0.00245,,,,,,300.0112762,,,,
,32001062.815,300.0141296,69078.9921875,-0.000181570237909875,2.41231045996479E-6,1,0.999253354069792,40.0298881530762,1.98321870978125,19.9699997901917,-0.00204576101978079,-0.000318050371006881,0.25,3.14404554627653E-6,-0.000181566937350183,3.02521644432685E-6,300.0141296,300.0141296,69049.109375,69108.875,56.5922496778714,20.5529773110086,28.983419,0,0,0,40,4449,300.1874,69078.9921875,,,,,,,,,,,,,0,,,,0,,,,,,300.0141296,,,,
,32001159.025,300.0083008,73889.0625,-0.000200644000052674,2.58644558518886E-6,1,0.999253354069792,40.0298881530762,1.98337247583331,19.9699997901917,-0.00225481469432865,-0.000386231504813715,0.25,3.81450464126324E-7,-0.000200638385913249,2.50387343087532E-7,300.0083008,300.0083008,73886.46875,73891.65625,56.1287439659675,20.5478051117741,28.983419,0,0,0,40,4449,300.1833,73889.0625,,,,,,,,,,,,,0,,,,0,,,,,,300.0083008,,,,
,32001255.08,300.0140381,78690.07421875,-0.000214553892295854,2.12453919564818E-6,1,0.999253354069792,40.0298881530762,1.98326631012411,19.9699997901917,-0.00241440567167614,-0.000393379781096847,0.25,2.15307378328438E-6,-0.000214548997617283,2.01303871351314E-6,300.0140381,300.0140381,78660.0703125,78720.078125,56.4609360866406,20.5482081528463,28.983419,0,0,0,40,4449,300.17085,78690.07421875,,,,,,,,,,,,,0,,,,0.00245,,,,,,300.0140381,,,,
,32001349.97,300.0110474,83433.5703125,-0.000230996729877817,2.40625260446753E-6,1,0.999253354069792,40.0298881530762,1.98326074476744,19.9699997901917,-0.00259673530401313,-0.000439096114738979,0.25,9.31897203170434E-7,-0.000230990595455244,7.81347056486617E-7,300.0110474,300.0110474,83403.7421875,83463.3984375,56.6203883045637,20.5478675280656,28.603769,0,0,0,40,4449,300.15545,83433.5703125,,,,,,,,,,,,,0,,,,-0.00245,,,,,,300.0110474,,,,
,32001444.03,300.0154419,88133.84765625,-0.000250060943841609,1.9690567589099E-6,1,0.999253354069792,40.0298881530762,1.98326446946831,19.9699997901917,-0.00281346223454969,-0.000461407672253618,0.25,2.2484593967982E-6,-0.000250055086931157,2.08564264596696E-6,300.014801,300.0160828,88101.234375,88166.4609375,56.5969394489868,20.5466631419762,28.603769,0,0,0,40,4449,300.1467,88133.84765625,,,,,,,,,,,,,0,,,,-0.00245,,,,,,300.0154419,,,,
,32001551.7,300.011322,87310.9296875,-0.00024525165175148,2.30904480864195E-6,1,0.999253354069792,40.0298881530762,1.98311714698589,19.9699997901917,-0.00276094240666734,-0.000442195710197238,0.25,3.12273937994978E-6,-0.000245246537772152,2.96298560849018E-6,300.011322,300.011322,87283.6015625,87338.2578125,56.3577611221021,20.5493693246883,28.983419,0,0,0,40,4449,300.13465,87310.9296875,,,,,,,,,,,,,0,,,,0.00245,,,,,,300.011322,,,,
,32001645.93,300.00416565,82600.0078125,-0.00022757136497038,1.44311115973999E-6,1,0.999253354069792,40.0298881530762,1.98322487261908,19.9699997901917,-0.0025602294146309,-0.000420780891564308,0.25,1.96826299107515E-6,-0.000227566058668425,1.81987216915454E-6,300.0038452,300.0044861,82570.015625,82630,56.2045619323329,20.5495672001936,28.603769,0,0,0,40,4449,300.1367,82600.0078125,,,,,,,,,,,,,0,,,,-0.00245,,,,,,300.00416565,,,,
,32001741.515,299.99528505,77821.22265625,-0.000211775553144216,1.96910696153089E-6,1,0.999253354069792,40.0298881530762,1.98315714551465,19.9699997901917,-0.00238100214574294,-0.000399894694197616,0.25,1.08998223667233E-6,-0.000211770185081803,9.51742766011784E-7,299.9947205,299.9958496,77791.203125,77851.2421875,56.5938129349098,20.552638207596,28.603769,0,0,0,40,4449,300.1374,77821.22265625,,,,,,,,,,,,,0,,,,-0.00245,,,,,,299.99528505,,,,
,32001837.96,299.99162295,73000.03515625,-0.000194813808760505,2.35813433879939E-6,1,0.999253354069792,40.0298881530762,1.98311750390529,19.9699997901917,-0.00219266133505381,-0.000353991498873952,0.25,2.23737635961981E-6,-0.000194809690583485,2.1100250975209E-6,299.9914856,299.9917603,72972.6015625,73027.46875,56.4968909985252,20.5545867700133,29.363071,0,0,0,40,4449,300.15415,73000.03515625,,,,,,,,,,,,,0,,,,0,,,,,,299.99162295,,,,
,32001931.93,299.9908142,68304.41015625,-0.000180034363425909,2.21281523033656E-6,1,0.999253354069792,40.0298881530762,1.98324938601155,19.9699997901917,-0.00202739111081442,-0.000321695551269745,0.25,2.55393919576655E-6,-0.000180030870543629,2.43610005718976E-6,299.9908142,299.9908142,68274.328125,68334.4921875,56.689171614256,20.5520841275784,28.983419,0,0,0,40,4449,300.16355,68304.41015625,,,,,,,,,,,,,0,,,,0.00245,,,,,,299.9908142,,,,
,32002027.625,299.9907227,63519.046875,-0.000162201449965373,2.65153297352946E-6,1,0.999253354069792,40.0298881530762,1.98322829281333,19.9699997901917,-0.00182670640151579,-0.00028894591327124,0.25,2.37958855788982E-6,-0.000162198345800752,2.27329506663242E-6,299.9907227,299.9907227,63516.67578125,63521.41796875,56.7063674416791,20.5546573916792,28.983419,0,0,0,40,4449,300.16945,63519.046875,,,,,,,,,,,,,0,,,,0,,,,,,299.9907227,,,,
,32002122.195,299.98336795,58793.359375,-0.000145746160312816,2.29463100971179E-6,1,0.999253354069792,40.0298881530762,1.98319658126602,19.9699997901917,-0.0016390947162929,-0.000272720005324263,0.25,9.7286555197993E-7,-0.000145742637416044,8.77279943368227E-7,299.9829407,299.9837952,58768.3828125,58818.3359375,56.3194613246598,20.5503499148974,28.983419,0,0,0,40,4449,300.1742,58793.359375,,,,,,,,,,,,,0,,,,-0.00245,,,,,,299.98336795,,,,
,32002219.915,299.9874573,53907.82421875,-0.000130737527282907,2.54747774334006E-6,1,0.999253354069792,40.0298881530762,1.98340976655503,19.9699997901917,-0.00147235575248148,-0.000233689229216204,0.25,1.84939537511192E-6,-0.000130734981242956,1.76353007662805E-6,299.9874573,299.9874573,53875.36328125,53940.28515625,56.6196066760444,20.5504335553398,29.363071,0,0,0,40,4449,300.1947,53907.82421875,,,,,,,,,,,,,0,,,,-0.00245,,,,,,299.9874573,,,,
,32002319.155,299.9888916,48947.728515625,-0.000114003120817044,1.95510218564698E-6,1,0.999253354069792,40.0298881530762,1.98353722178797,19.9699997901917,-0.00128057676703292,-0.000223391335828563,0.25,-1.31939545708894E-7,-0.00011399974166789,-2.06852597966676E-7,299.9888916,299.9888916,48942.95703125,48952.5,56.5852150211983,20.5472073054702,29.363071,0,0,0,40,4449,300.1937,48947.728515625,,,,,,,,,,,,,0,,,,-0.00245,,,,,,299.9888916,,,,
,32002415.77,299.9918518,44117.228515625,-9.82268584826119E-5,1.3999848856885E-6,1,0.999253354069792,40.0298881530762,1.98351802328604,19.9699997901917,-0.00110835884068541,-0.000163590857239643,0.25,2.45736024870856E-6,-9.82256215164766E-5,2.39266864508926E-6,299.9918518,299.9918518,44089.69921875,44144.7578125,56.780622151006,20.5472092350676,28.603769,0,0,0,40,4449,300.2024,44117.228515625,,,,,,,,,,,,,0,,,,0,,,,,,299.9918518,,,,
,32002513.815,299.9836731,39217.15625,-8.18256231416522E-5,1.53089553972669E-6,1,0.999253354069792,40.0298881530762,1.98345925949391,19.9699997901917,-0.000921838992742087,-0.000144513521108187,0.25,1.31350320285677E-6,-8.18241300466223E-5,1.25957860360228E-6,299.9836426,299.9837036,39192.140625,39242.171875,56.9775925378522,20.5453981150909,28.983419,0,0,0,40,4449,300.2215,39217.15625,,,,,,,,,,,,,0,,,,0.00245,,,,,,299.9836731,,,,
,32002613.375,299.9892578,34242.8359375,-6.4225082653724E-5,1.14319051293688E-6,1,0.999253354069792,40.0298881530762,1.98358854320851,19.9699997901917,-0.000724075257632595,-0.00011068130016018,0.25,1.27619625975429E-6,-6.42240560682092E-5,1.23381651400012E-6,299.9892578,299.9892578,34215.2578125,34270.4140625,56.7001144135252,20.5476794630743,28.983419,0,0,0,40,4449,300.22255,34242.8359375,,,,,,,,,,,,,0,,,,0,,,,,,299.9892578,,,,
,32002709.205,299.9854736,29453.025390625,-4.67790259200606E-5,1.18229558260664E-6,1,0.999253354069792,40.0298881530762,1.98349967543282,19.9699997901917,-0.000526646143090931,-8.47640627354285E-5,0.25,5.60035515816221E-7,-4.67780384437999E-5,5.29146263872421E-7,299.9851379,299.9858093,29428.263671875,29477.787109375,56.7352876968906,20.5505337615609,29.363071,0,0,0,40,4449,300.221,29453.025390625,,,,,,,,,,,,,0,,,,0,,,,,,299.9854736,,,,
,32002805.205,299.9830322,24654.837890625,-3.09966376235574E-5,9.12441391498633E-7,1,0.999253354069792,40.0298881530762,1.98344800357923,19.9699997901917,-0.000349513842941309,-5.29490673770344E-5,0.25,6.57345642757292E-7,-3.09961736561527E-5,6.36850776756536E-7,299.9830322,299.9830322,24630.0078125,24679.66796875,56.3061736398329,20.5502897774684,28.603769,0,0,0,40,4449,300.24425,24654.837890625,,,,,,,,,,,,,0,,,,0,,,,,,299.9830322,,,,
,32002903.125,299.9924927,19762.353515625,-1.51977840828244E-5,7.52047683796318E-7,1,0.999253354069792,40.0298881530762,1.98338341743891,19.9699997901917,-0.000171098077181745,-2.74878849823439E-5,0.25,1.86336294899602E-7,-1.51974608752204E-5,1.76281865209932E-7,299.9919739,299.9930115,19732.607421875,19792.099609375,56.7524835243137,20.5531609559359,28.603769,0,0,0,40,4449,300.25365,19762.353515625,,,,,,,,,,,,,0,,,,0.0049,,,,,,299.9924927,,,,
,32002999.6,299.99224855,14940.501953125,-4.80726838531344E-8,6.67786545835394E-7,1,0.999253354069792,40.0298881530762,1.98342698297006,19.9699997901917,-4.33842621518287E-7,-7.06691784316968E-7,0.25,-5.45749257304187E-8,-4.80351508062744E-8,-5.46051356144483E-8,299.9919739,299.9925232,14910.6435546875,14970.3603515625,56.9760292808137,20.5536728882621,28.983419,0,0,0,40,4449,300.25645,14940.501953125,,,,,,,,,,,,,0,,,,-0.00245,,,,,,299.99224855,,,,
,32003097.25,299.9915161,10060.853515625,1.44408512090334E-5,5.80124230172141E-7,1,0.999253354069792,40.0298881530762,1.98358310056478,19.9699997901917,0.000161893519514443,3.0153250932034E-5,0.25,1.81787237636822E-7,1.44403055836749E-5,1.91347425380397E-7,299.9915161,299.9915161,10038.3837890625,10083.3232421875,56.404658833256,20.5515959371361,29.363071,0,0,0,40,4449,300.25995,10060.853515625,,,,,,,,,,,,,0,,,,0,,,,,,299.9915161,,,,
,32003192.82,299.98797605,5282.8935546875,2.53977107271629E-5,5.12682125244149E-7,1,0.999253354069792,40.0298881530762,1.98341270857541,19.9699997901917,0.00028612168969878,4.48527614371887E-5,0.25,-4.07939744019637E-7,2.53972354521896E-5,-3.91092472215959E-7,299.9877319,299.9882202,5255.2783203125,5310.5087890625,56.8329912617945,20.5546329347085,29.363071,0,0,0,40,4449,300.2777,5282.8935546875,,,,,,,,,,,,,0,,,,0,,,,,,299.98797605,,,,
,32003286.03,299.9941101,623.926391601562,2.29231575540348E-5,4.74318750010219E-7,1,0.999253354069792,40.0298881530762,1.98375309603609,19.9699997901917,0.000256771427108407,4.92338866671697E-5,0.25,4.10048322494024E-7,2.29222066789185E-5,4.25240299365896E-7,299.9941101,299.9941101,596.469482421875,651.38330078125,56.6461820456983,20.5496172827485,28.983419,0,0,0,40,4449,300.2825,623.926391601562,,,,,,,,,,,,,0,,,,0,,,,,,299.9941101,,,,
,32003299.055,299.9943237,-0.228356592357159,4.07243731492616E-6,3.71359164147498E-7,1,0.999253354069792,40.0298881530762,1.98366087238928,19.9699997901917,4.77105858965533E-5,-3.34891928447932E-6,0.25,-1.00365018857819E-6,4.07298240093096E-6,-1.00091907109619E-6,299.9943237,299.9943237,-0.289251685142517,-0.1674614995718,56.4124751184483,20.5511729627152,28.983419,0,0,0,40,4417,300.2698,-0.228356592357159,,,,,,,,,,,,,0,,,,0,,,,,,299.9943237,,,,