File: data/monolayers/magneticStructure/ML_Ac_CoFe_C-2/PPMS/data/DD175_23_HYST_100OE_150K.DAT
[Header]
; VSM Data File (default extension .dat)
; Copyright (c) 2003-2013, Quantum Design, Inc. All rights reserved.
TITLE,
FILEOPENTIME,31955747.55,01/06/2019,4:37 am
BYAPP,VSM,2.0,2.0
INFO,PPMS VSM Option Release 1.4.10 Build 1,APPNAME
INFO,Quantum Design Linear Motor Servo Controller,MOTOR_MODULE_NAME
INFO,3101-100 M1,MOTOR_HW_VERSION
INFO,MMC1014,MOTOR_SERIAL_NUMBER
INFO,SRV No X-over 01.03.11,MOTOR_SOFTWARE_VERSION
INFO,Quantum Design VSM Detection Module,VSM_MODULE_NAME
INFO,3101-150 F0,VSM_HW_VERSION
INFO,VSM707,VSM_SERIAL_NUMBER
INFO,VSM No X-over 01.02.05 May 20 2008 13:51:47,VSM_SOFTWARE_VERSION
INFO,704,PREAMP_SERIAL_NUMBER
INFO,822,COIL_SERIAL_NUMBER
INFO,0,MOMENT_UNITS
INFO,CoFe2O4 Monolayer,SAMPLE_MATERIAL
INFO,from YF45,SAMPLE_COMMENT
INFO,29.98,SAMPLE_MASS
INFO,,SAMPLE_VOLUME
INFO,,SAMPLE_MOLECULAR_WEIGHT
INFO,,SAMPLE_SIZE
INFO,,SAMPLE_SHAPE
DATATYPE,COMMENT,1
DATATYPE,TIME,2
STARTUPAXIS,X,2
STARTUPAXIS,Y1,5
[Data]
Comment,Time Stamp (sec),Temperature (K),Magnetic Field (Oe),Moment (emu),M. Std. Err. (emu),Transport Action,Averaging Time (sec),Frequency (Hz),Peak Amplitude (mm),Center Position (mm),Coil Signal' (mV),Coil Signal" (mV),Range (mV),M. Quad. Signal (emu),M. Raw' (emu),M. Raw" (emu),Min. Temperature (K),Max. Temperature (K),Min. Field (Oe),Max. Field (Oe),Mass (grams),Motor Lag (deg),Pressure (Torr),VSM Status (code),Motor Status (code),Measure Status (code),Measure Count,PPMS Status (code),System Temp. (K),System Field (Oe),Sample Position (deg),Bridge 1 Resistance (ohms),Bridge 1 Excitation (에),Bridge 2 Resistance (ohms),Bridge 2 Excitation (에),Bridge 3 Resistance (ohms),Bridge 3 Excitation (에),Bridge 4 Resistance (ohms),Bridge 4 Excitation (에),Signal 1 Vin (V),Signal 2 Vin (V),Digital Inputs (code),Drive 1 Iout (mA),Drive 1 Ipower (W),Drive 2 Iout (mA),Drive 2 Ipower (W),Pressure (),Map 20 (),Map 21 (),Map 22 (),Map 23 (),Map 24 (),Map 25 (),Map 26 (),Map 27 (),Map 28 (),Map 29 ()
,31955762.45,149.9836884,-0.42626565694809,,,2,,,,20.8799990993738,,,,,,,149.9836884,149.9836884,-0.42626565694809,-0.42626565694809,,,24.807261,,,,-99999999,4369,149.8868,-0.42626565694809,,,,,,,,,,,,,,,,,,,,,,,149.9836884,,,,
,31955905.78,149.98332975,4653.33471679687,2.53848022647813E-5,4.9735598953458E-7,1,0.999253354069792,40.0298881530762,1.99538533808064,20.8700001239777,0.000288471557188345,4.86122314875203E-5,0.25,-1.4065476689953E-7,2.55093769537622E-5,-1.00646166918234E-7,149.9830017,149.9836578,4620.9287109375,4685.74072265625,56.2733452420252,20.5168783304002,24.807261,0,0,0,40,4449,149.9082,4653.33471679687,,,,,,,,,,,,,0,,,,0.0049,,,,,,149.98332975,,,,
,31956003.025,149.9850922,9514.65576171875,1.787396081613E-5,6.71188990899917E-7,1,0.999253354069792,40.0298881530762,1.99537288245371,20.8700001239777,0.000202810014587537,3.5994763752423E-5,0.25,5.65899403028194E-8,1.79614411247123E-5,8.54557798192037E-8,149.9850922,149.9850922,9482.2158203125,9547.095703125,56.2741268705444,20.5227193231781,25.186911,0,0,0,40,4449,149.9215,9514.65576171875,,,,,,,,,,,,,0,,,,-0.00245,,,,,,149.9850922,,,,
,31956102.22,149.9907684,14471.87890625,3.781412580334E-6,1.17735049165615E-6,1,0.999253354069792,40.0298881530762,1.99528474507427,20.8700001239777,4.09832833121661E-5,1.86438044077349E-5,0.25,9.83500315319915E-7,3.79837284891376E-6,9.94352215491321E-7,149.9907684,149.9907684,14444.611328125,14499.146484375,56.0232241158713,20.5279579685407,24.807261,0,0,0,40,4449,149.9268,14471.87890625,,,,,,,,,,,,,0,,,,-0.00245,,,,,,149.9907684,,,,
,31956200.75,149.99552155,19394.40234375,-1.10920051420225E-5,1.03689296191008E-6,1,0.999253354069792,40.0298881530762,1.99508067962987,20.8700001239777,-0.000127473690835466,-1.29561317954808E-5,0.25,7.90941184780385E-7,-1.11476245359262E-5,7.77170169399936E-7,149.9952087,149.9958344,19361.84765625,19426.95703125,55.9833610613905,20.5299385220425,25.186911,0,0,0,40,4449,149.932,19394.40234375,,,,,,,,,,,,,0,,,,0,,,,,,149.99552155,,,,
,31956299.065,149.9980469,24306.970703125,-2.77958430302128E-5,1.06714468989566E-6,1,0.999253354069792,40.0298881530762,1.99513534069559,20.8700001239777,-0.000318861368797849,-3.58431340026342E-5,0.25,1.68460728380876E-6,-2.79347659997153E-5,1.64876549191028E-6,149.9980469,149.9980469,24304.61328125,24309.328125,56.2139414745636,20.5289175001813,24.427608,0,0,0,40,4449,149.93155,24306.970703125,,,,,,,,,,,,,0,,,,0,,,,,,149.9980469,,,,
,31956395.9,150.00096895,29149.84375,-4.39203480305569E-5,1.30546460168756E-6,1,0.999253354069792,40.0298881530762,1.99512606103013,20.8700001239777,-0.000501219914524966,-7.16334109291379E-5,0.25,1.3404664344298E-6,-4.4137798324764E-5,1.27755624073832E-6,150.0004425,150.0014954,29117.322265625,29182.365234375,56.8736359447945,20.5285767933828,24.807261,0,0,0,40,4449,149.93125,29149.84375,,,,,,,,,,,,,0,,,,0.0049,,,,,,150.00096895,,,,
,31956491.97,150.00338745,33949.9140625,-6.12917336049133E-5,1.99612384070067E-6,1,0.999253354069792,40.0298881530762,1.99508525596474,20.8700001239777,-0.000699222381821416,-0.000101267360323647,0.25,1.7555467879807E-6,-6.15950572348194E-5,1.66747527505838E-6,150.0033569,150.003418,33914.98828125,33984.83984375,56.3898078913906,20.5322417553661,25.186911,0,0,0,40,4449,149.93075,33949.9140625,,,,,,,,,,,,,0,,,,0.00245,,,,,,150.00338745,,,,
,31956586.4,150.00424195,38669.44140625,-7.44719191682746E-5,1.70451185169197E-6,1,0.999253354069792,40.0298881530762,1.9950291652929,20.8700001239777,-0.000852038943303043,-0.000108816197826048,0.25,3.38585222617586E-6,-7.48425021596166E-5,3.28532793640306E-6,150.0042114,150.0042725,38641.796875,38697.0859375,56.8712910592368,20.5319036945912,24.427608,0,0,0,40,4449,149.9241,38669.44140625,,,,,,,,,,,,,0,,,,-0.00245,,,,,,150.00424195,,,,
,31956680.365,150.007431,43367.4140625,-9.22290368727649E-5,1.8286160828908E-6,1,0.999253354069792,40.0298881530762,1.99493220582093,20.8700001239777,-0.00104794730049049,-0.000176114537532151,0.25,5.49062993983547E-7,-9.26823317486707E-5,4.07123473366294E-7,150.007431,150.007431,43344.93359375,43389.89453125,56.7642079521022,20.5294661313887,24.427608,0,0,0,40,4449,149.9172,43367.4140625,,,,,,,,,,,,,0,,,,-0.00245,,,,,,150.007431,,,,
,31956774.965,150.0068283,48095.35546875,-0.00010901497450046,1.57252273534025E-6,1,0.999253354069792,40.0298881530762,1.99483590394283,20.8700001239777,-0.00123781431385055,-0.000212788375058632,0.25,2.40564632176054E-7,-0.000109550242180303,7.13062111571267E-8,150.0067596,150.006897,48067.79296875,48122.91796875,56.3366571520829,20.5328583260972,24.807261,0,0,0,40,4449,149.91165,48095.35546875,,,,,,,,,,,,,0,,,,0.00245,,,,,,150.0068283,,,,
,31956869.885,150.0085449,52839.99609375,-0.000124433428598615,1.57932184517115E-6,1,0.999253354069792,40.0298881530762,1.99484226991658,20.8700001239777,-0.00141909650701133,-0.000207247272458295,0.25,3.41381495813182E-6,-0.000125049414922536,3.23661805883491E-6,150.0084686,150.0086212,52809.625,52870.3671875,55.9669468624867,20.5357477360063,24.807261,0,0,0,40,4449,149.9021,52839.99609375,,,,,,,,,,,,,0,,,,0,,,,,,150.0085449,,,,
,31956965.58,150.0092621,57622.94140625,-0.000140709958246756,2.11531412951E-6,1,0.999253354069792,40.0298881530762,1.99494663878538,20.8700001239777,-0.00160757255198644,-0.000218467570857658,0.25,5.26051004933048E-6,-0.000141408819768554,5.0676983928052E-6,150.0091095,150.0094147,57592.6875,57653.1953125,56.5211214826214,20.5308464003246,25.186911,0,0,0,40,4449,149.8929,57622.94140625,,,,,,,,,,,,,0,,,,0.00245,,,,,,150.0092621,,,,
,31957061.825,150.01085665,62433.978515625,-0.000157427047686115,2.76409718655909E-6,1,0.999253354069792,40.0298881530762,1.99486101247199,20.8700001239777,-0.00178897541834353,-0.000299034023340453,0.25,1.07243006238792E-6,-0.000158201613255222,8.33866308819862E-7,150.0107422,150.0109711,62401.3828125,62466.57421875,56.3374387806021,20.531337823636,24.427608,0,0,0,40,4449,149.8827,62433.978515625,,,,,,,,,,,,,0,,,,0,,,,,,150.01085665,,,,
,31957157.53,150.0088043,67216.546875,-0.000174173024374181,1.85714428762756E-6,1,0.999253354069792,40.0298881530762,1.99490016084028,20.8700001239777,-0.00198522085743162,-0.000296928572353342,0.25,4.17412889822679E-6,-0.000175034784287191,3.92572991743817E-6,150.0088043,150.0088043,67189.1640625,67243.9296875,56.1873661049098,20.527984612053,24.807261,0,0,0,40,4449,149.874,67216.546875,,,,,,,,,,,,,0,,,,-0.00245,,,,,,150.0088043,,,,
,31957254.565,150.00881195,72067.08203125,-0.000191012684771966,1.96551882839078E-6,1,0.999253354069792,40.0298881530762,1.99504139986521,20.8700001239777,-0.00217468597198988,-0.000340715935956064,0.25,3.25028238102824E-6,-0.000191955904451293,2.97233189158974E-6,150.0087128,150.0089111,72037.015625,72097.1484375,56.6641595016406,20.5297376579928,24.807261,0,0,0,40,4449,149.8671,72067.08203125,,,,,,,,,,,,,0,,,,0.00245,,,,,,150.00881195,,,,
,31957352.295,150.0113983,76952.22265625,-0.00021385976590532,3.59545691455872E-6,1,0.999253354069792,40.0298881530762,1.99487238015129,20.8700001239777,-0.00243222757417128,-0.000395096618148109,0.25,2.43465276988926E-6,-0.000214914155947846,2.11864506018636E-6,150.0113983,150.0113983,76949.671875,76954.7734375,56.6110087623329,20.5345718880229,25.186911,0,0,0,40,4449,149.8566,76952.22265625,,,,,,,,,,,,,0,,,,0,,,,,,150.0113983,,,,
,31957449.075,150.00955965,81790.78515625,-0.000224940101868788,2.70262610539493E-6,1,0.999253354069792,40.0298881530762,1.99500791634157,20.8700001239777,-0.0025638922190957,-0.000384130085498864,0.25,5.33151989214615E-6,-0.000226053599537015,5.01392168544121E-6,150.0093689,150.0097504,81758.3125,81823.2578125,56.668849272756,20.5338468654463,25.186911,0,0,0,40,4449,149.849,81790.78515625,,,,,,,,,,,,,0,,,,0.00245,,,,,,150.00955965,,,,
,31957543.515,150.0110474,86509.02734375,-0.000245288777282885,2.82054086064067E-6,1,0.999253354069792,40.0298881530762,1.99480714418864,20.8700001239777,-0.00279523037223639,-0.000420747415871501,0.25,5.64450220084751E-6,-0.000246502968164884,5.29858990953969E-6,150.0110474,150.0110474,86506.5078125,86511.546875,56.4476484018137,20.5316777914964,25.186911,0,0,0,40,4449,149.84115,86509.02734375,,,,,,,,,,,,,0,,,,0,,,,,,150.0110474,,,,
,31957652.595,150.0087509,88817.5546875,-0.000259161514751486,4.32308130119353E-6,1,0.999253354069792,40.0298881530762,1.99476768696947,20.8700001239777,-0.00294499791126324,-0.000492011992457483,0.25,1.78013895543742E-6,-0.000260438148119278,1.39473376018075E-6,150.0086212,150.0088806,88792.59375,88842.515625,56.5852150211983,20.533630589659,25.566563,0,0,0,40,4449,149.8338,88817.5546875,,,,,,,,,,,,,0,,,,0,,,,,,150.0087509,,,,
,31957743.82,150.00366975,84259.21484375,-0.000236356226126277,2.99992017672366E-6,1,0.999253354069792,40.0298881530762,1.99493000677642,20.8700001239777,-0.00268734651807268,-0.000441334033535421,0.25,2.27812200440287E-6,-0.000237521311385849,1.92865477110673E-6,150.0033112,150.0040283,84234.0546875,84284.375,56.1263990804098,20.5318259566417,24.807261,0,0,0,40,4449,149.8317,84259.21484375,,,,,,,,,,,,,0,,,,0,,,,,,150.00366975,,,,
,31957840.93,149.99729155,79405.328125,-0.000226165689827579,3.0862016547145E-6,1,0.999253354069792,40.0298881530762,1.99446305471481,20.8700001239777,-0.00256720285437757,-0.000443466311993155,0.25,3.08099522369847E-7,-0.000227277477876595,-3.66903122583479E-8,149.9971008,149.9974823,79400.203125,79410.453125,56.127180708929,20.533317335096,25.186911,0,0,0,40,4449,149.8354,79405.328125,,,,,,,,,,,,,0,,,,-0.00245,,,,,,149.99729155,,,,
,31957937.585,149.995491,74571.73046875,-0.000204691210687135,2.69604952519823E-6,1,0.999253354069792,40.0298881530762,1.99478733247213,20.8700001239777,-0.00232843320177822,-0.000374843074958002,0.25,2.62156694968148E-6,-0.000205700820079446,2.31995603212163E-6,149.9954681,149.9955139,74541.703125,74601.7578125,56.5516049948714,20.5381432678386,25.186911,0,0,0,40,4449,149.8388,74571.73046875,,,,,,,,,,,,,0,,,,0.00245,,,,,,149.995491,,,,
,31958034.415,149.9938202,69733.69921875,-0.00018838032710408,2.82691726185989E-6,1,0.999253354069792,40.0298881530762,1.99483994698968,20.8700001239777,-0.00214833803865126,-0.000314004911126852,0.25,5.14280465945681E-6,-0.000189313511953659,4.8776755589343E-6,149.9938202,149.9938202,69703.90625,69763.4921875,56.3280592383713,20.5341054776525,25.186911,0,0,0,40,4449,149.8489,69733.69921875,,,,,,,,,,,,,0,,,,0.00245,,,,,,149.9938202,,,,
,31958128.88,149.9918289,65010.466796875,-0.000172923546917277,3.30103975615793E-6,1,0.999253354069792,40.0298881530762,1.99469422697831,20.8700001239777,-0.00196930314442366,-0.000303278472417498,0.25,3.39490422635304E-6,-0.000173777963400377,3.14415563397369E-6,149.9915771,149.9920807,64980.4296875,65040.50390625,56.0685585699867,20.5403061883981,24.807261,0,0,0,40,4449,149.85685,65010.466796875,,,,,,,,,,,,,0,,,,0,,,,,,149.9918289,,,,
,31958225.31,149.991745,60192.5078125,-0.00014997553035666,3.20093202292537E-6,1,0.999253354069792,40.0298881530762,1.99473327497121,20.8700001239777,-0.00171345451227682,-0.000231688596844681,0.25,5.70712196942048E-6,-0.000150720700066942,5.50244919833474E-6,149.991745,149.991745,60167.84375,60217.171875,56.1858028478713,20.5424016799868,24.427608,0,0,0,40,4449,149.86105,60192.5078125,,,,,,,,,,,,,0,,,,0.00245,,,,,,149.991745,,,,
,31958321.625,149.99082185,55377.197265625,-0.00013592352577573,2.45055924479366E-6,1,0.999253354069792,40.0298881530762,1.99468764058161,20.8700001239777,-0.00154241498688864,-0.00027004071075461,0.25,-1.19286142749844E-7,-0.000136590524916439,-3.31436459122641E-7,149.9907837,149.99086,55344.59765625,55409.796875,55.8583004983136,20.5436754192359,25.186911,0,0,0,40,4449,149.8691,55377.197265625,,,,,,,,,,,,,0,,,,0,,,,,,149.99082185,,,,
,31958418.4,149.9902344,50536.939453125,-0.000117400737862702,2.36800259184121E-6,1,0.999253354069792,40.0298881530762,1.99480147039741,20.8700001239777,-0.00133821456556826,-0.000199272122854825,0.25,2.89152335266725E-6,-0.000117981395361913,2.72239941969906E-6,149.9902344,149.9902344,50531.8515625,50542.02734375,56.7923465787945,20.5470135564881,25.186911,0,0,0,40,4449,149.87665,50536.939453125,,,,,,,,,,,,,0,,,,0,,,,,,149.9902344,,,,
,31958514.095,149.9923706,45754.37109375,-0.000101882303089148,2.88940627933014E-6,1,0.999253354069792,40.0298881530762,1.99467161927851,20.8700001239777,-0.00116306766793168,-0.000162493685492356,0.25,3.42854204912015E-6,-0.00010238754729966,3.28579022807534E-6,149.9923706,149.9923706,45719.51953125,45789.22265625,56.4515565444098,20.5442135598144,25.566563,0,0,0,40,4449,149.88415,45754.37109375,,,,,,,,,,,,,0,,,,-0.00245,,,,,,149.9923706,,,,
,31958609.57,149.99180605,40984.080078125,-8.83498080708083E-5,2.50916043297447E-6,1,0.999253354069792,40.0298881530762,1.99465718387049,20.8700001239777,-0.00100217545472481,-0.000177652543805774,0.25,-2.63949537890885E-7,-8.87827821308538E-5,-4.04044717144999E-7,149.991684,149.9919281,40961.59375,41006.56640625,56.9338213407753,20.5409992407346,25.186911,0,0,0,40,4449,149.8884,40984.080078125,,,,,,,,,,,,,0,,,,-0.00245,,,,,,149.99180605,,,,
,31958705.08,149.991745,36211.482421875,-6.78887484167591E-5,2.3111206305376E-6,1,0.999253354069792,40.0298881530762,1.99495649283172,20.8700001239777,-0.000775000960352553,-0.000108908768050482,0.25,2.23084285098189E-6,-6.82252143043186E-5,2.1348098412541E-6,149.991745,149.991745,36179.04296875,36243.921875,56.6969878994483,20.5441327016145,24.807261,0,0,0,40,4449,149.89305,36211.482421875,,,,,,,,,,,,,0,,,,0.00245,,,,,,149.991745,,,,
,31958802.45,149.99320985,31343.8388671875,-5.18372374011658E-5,1.39478863222793E-6,1,0.999253354069792,40.0298881530762,1.99474703699377,20.8700001239777,-0.000592904222351501,-7.62434409844228E-5,0.25,2.31216478400855E-6,-5.20950655042466E-5,2.24158117840267E-6,149.9930573,149.9933624,31311.505859375,31376.171875,56.6985511564868,20.5426466379779,25.566563,0,0,0,40,4449,149.90165,31343.8388671875,,,,,,,,,,,,,0,,,,0.0049,,,,,,149.99320985,,,,
,31958898.71,149.99274445,26533.41796875,-3.48059123692528E-5,1.56091445576802E-6,1,0.999253354069792,40.0298881530762,1.9946523004118,20.8700001239777,-0.000395912222512638,-6.36632367900258E-5,0.25,4.53684144101764E-7,-3.49772624057242E-5,4.00748724186214E-7,149.9925995,149.9928894,26503.24609375,26563.58984375,56.5203398541021,20.5495429939109,24.807261,0,0,0,40,4449,149.9118,26533.41796875,,,,,,,,,,,,,0,,,,0.00245,,,,,,149.99274445,,,,
,31958995.455,149.99080655,21698.4287109375,-2.16708837483317E-5,1.35971385143526E-6,1,0.999253354069792,40.0298881530762,1.99447211243901,20.8700001239777,-0.000248035099271664,-3.071761637595E-5,0.25,1.06833680813226E-6,-2.17788004798534E-5,1.03913555840821E-6,149.9905853,149.9910278,21670.666015625,21726.19140625,56.8329912617945,20.5454709335866,25.186911,0,0,0,40,4449,149.9195,21698.4287109375,,,,,,,,,,,,,0,,,,0.0049,,,,,,149.99080655,,,,
,31959090.9,149.9913483,16928.7470703125,-4.70347843284066E-6,8.74323967053533E-7,1,0.999253354069792,40.0298881530762,1.99450940064341,20.8700001239777,-5.43716848694033E-5,-3.58529000373818E-6,0.25,5.03460046911821E-7,-4.72733013479137E-6,4.98433224079127E-7,149.9913483,149.9913483,16898.685546875,16958.80859375,56.5289377678137,20.5465432898133,25.186911,0,0,0,40,4449,149.9232,16928.7470703125,,,,,,,,,,,,,0,,,,-0.00245,,,,,,149.9913483,,,,
,31959186.66,149.9916458,12141.7446289062,9.01941793590597E-6,1.05199747077018E-6,1,0.999253354069792,40.0298881530762,1.99443830342167,20.8700001239777,0.000102973185861993,1.42605899047465E-5,0.25,-3.14632593385363E-7,9.06411262120186E-6,-3.01768568470568E-7,149.9914856,149.991806,12111.9013671875,12171.587890625,57.0932735586983,20.5501194787896,25.186911,0,0,0,40,4449,149.9331,12141.7446289062,,,,,,,,,,,,,0,,,,-0.00245,,,,,,149.9916458,,,,
,31959280.89,149.9923096,7431.19458007812,2.24017907768206E-5,7.95363112932756E-7,1,0.999253354069792,40.0298881530762,1.99468940848156,20.8700001239777,0.000253932640639624,4.60736945330462E-5,0.25,1.56849805614553E-7,2.25112828043108E-5,1.93478703835051E-7,149.9923096,149.9923096,7398.89404296875,7463.4951171875,56.7024592990829,20.5510596314112,25.186911,0,0,0,40,4449,149.9377,7431.19458007812,,,,,,,,,,,,,0,,,,-0.00245,,,,,,149.9923096,,,,
,31959376.08,149.99425505,2675.58740234375,3.18962916450077E-5,4.23890754520254E-7,1,0.999253354069792,40.0298881530762,1.99455199326992,20.8700001239777,0.000362723135850968,5.87613740531597E-5,0.25,-3.79081684913524E-7,3.20531308766503E-5,-3.29778166592702E-7,149.9941711,149.994339,2645.62255859375,2705.55224609375,57.1745629246983,20.5531923368266,25.566563,0,0,0,40,4449,149.9431,2675.58740234375,,,,,,,,,,,,,0,,,,-0.00245,,,,,,149.99425505,,,,
,31959470.345,149.9954987,-2033.97113037109,2.61172266610598E-5,4.17400873583849E-7,1,0.999253354069792,40.0298881530762,1.99448883905191,20.8700001239777,0.000295785473032578,5.50550945309236E-5,0.25,3.0130167737128E-7,2.62446652056468E-5,3.44677107411352E-7,149.9954987,149.9954987,-2058.70483398438,-2009.23742675781,56.760299809506,20.5525285033835,24.807261,0,0,0,40,4449,149.946,-2033.97113037109,,,,,,,,,,,,,0,,,,-0.0049,,,,,,149.9954987,,,,
,31959566.895,149.9997253,-6859.439453125,7.73228854825135E-6,7.66185370542193E-7,1,0.999253354069792,40.0298881530762,1.99459355823016,20.8700001239777,8.89874597059545E-5,8.19273556420462E-6,0.25,-6.25193183456722E-7,7.771166774022E-6,-6.15875723244128E-7,149.9997253,149.9997253,-6887.0927734375,-6831.7861328125,56.7493570102368,20.5502413794106,25.186911,0,0,0,40,4449,149.9459,-6859.439453125,,,,,,,,,,,,,0,,,,0.00245,,,,,,149.9997253,,,,
,31959661.35,150.0054321,-11582.8310546875,-2.77647923268606E-6,8.13223759171564E-7,1,0.999253354069792,40.0298881530762,1.99438488312834,20.8700001239777,-3.06067968556449E-5,-1.06520452709872E-5,0.25,-4.55004567801287E-7,-2.78935487295385E-6,-4.61669267629137E-7,150.0054321,150.0054321,-11605.3466796875,-11560.3154296875,56.9885353371214,20.5553910618457,25.186911,0,0,0,40,4449,149.9389,-11582.8310546875,,,,,,,,,,,,,0,,,,0,,,,,,150.0054321,,,,
,31959759.71,150.00849915,-16500.34375,5.64266022613512E-6,1.07046711807114E-6,1,0.999253354069792,40.0298881530762,1.99469170482731,20.8700001239777,6.57264074609842E-5,1.47608420094981E-6,0.25,-8.5294891095997E-7,5.67166844075476E-6,-8.48136577344585E-7,150.0083008,150.0086975,-16532.876953125,-16467.810546875,56.6133536478906,20.5488554005348,24.807261,0,0,0,40,4449,149.9318,-16500.34375,,,,,,,,,,,,,0,,,,-0.00245,,,,,,150.00849915,,,,
,31959856.79,150.00823975,-21350.28125,1.9652120553359E-5,1.78961166048406E-6,1,0.999253354069792,40.0298881530762,1.99485293041981,20.8700001239777,0.000224914256757479,2.81818907640515E-5,0.25,-9.40561953403486E-7,1.97499289626793E-5,-9.13937677663444E-7,150.0080109,150.0084686,-21380.36328125,-21320.19921875,56.3468183228329,20.5547893070018,25.566563,0,0,0,40,4449,149.92575,-21350.28125,,,,,,,,,,,,,0,,,,0,,,,,,150.00823975,,,,
,31959953.68,150.0100403,-26192.5244140625,3.64419212610939E-5,1.58084164344121E-6,1,0.999253354069792,40.0298881530762,1.99443562373095,20.8700001239777,0.000414963966847791,6.38612060667645E-5,0.25,-7.20658114473072E-7,3.66216950685056E-5,-6.66428944072859E-7,150.0100403,150.0100403,-26222.599609375,-26162.44921875,56.8353361473522,20.5529773299111,24.807261,0,0,0,40,4449,149.9157,-26192.5244140625,,,,,,,,,,,,,0,,,,0,,,,,,150.0100403,,,,
,31960051.185,150.009903,-31067.21484375,5.24307271439422E-5,2.05026143056384E-6,1,0.999253354069792,40.0298881530762,1.99481482586598,20.8700001239777,0.000595585438788669,0.000100805554168477,0.25,-2.51708085328338E-7,5.26881820432138E-5,-1.70072160178616E-7,150.009903,150.009903,-31099.509765625,-31034.919921875,56.3780834636021,20.5512851638667,25.186911,0,0,0,40,4449,149.9051,-31067.21484375,,,,,,,,,,,,,0,,,,0,,,,,,150.009903,,,,
,31960146.775,150.0093536,-35844.5703125,6.73382015578691E-5,2.14352693566528E-6,1,0.999253354069792,40.0298881530762,1.9948499189729,20.8700001239777,0.000767253179034725,0.000116190614085868,0.25,-1.49290532906104E-6,6.76707674315785E-5,-1.39410057066566E-6,150.0093536,150.0093536,-35871.765625,-35817.375,56.926005055583,20.5530372763568,24.807261,0,0,0,40,4449,149.898,-35844.5703125,,,,,,,,,,,,,0,,,,0,,,,,,150.0093536,,,,
,31960245.785,150.0132751,-40791.79296875,8.5578302262163E-5,2.53769254521472E-6,1,0.999253354069792,40.0298881530762,1.99478570747752,20.8700001239777,0.000974151478766359,0.000152829930952758,0.25,-1.44130239498294E-6,8.60003044790226E-5,-1.31390600227644E-6,150.0132751,150.0132751,-40794.421875,-40789.1640625,56.8306463762368,20.5553158520254,25.566563,0,0,0,40,4449,149.8862,-40791.79296875,,,,,,,,,,,,,0,,,,0,,,,,,150.0132751,,,,
,31960342.64,150.0133514,-45629.6640625,0.000102046886457252,2.09448648642549E-6,1,0.999253354069792,40.0298881530762,1.99479796717146,20.8700001239777,0.00116169120766915,0.000181855109406719,0.25,-1.75223561983552E-6,0.000102550246542218,-1.60097089460288E-6,150.0133514,150.0133514,-45656.8828125,-45602.4453125,56.3241510957752,20.5530756699175,25.186911,0,0,0,40,4449,149.8733,-45629.6640625,,,,,,,,,,,,,0,,,,0,,,,,,150.0133514,,,,
,31960439.55,150.0110931,-50477.185546875,0.000116836840632795,2.23453353315225E-6,1,0.999253354069792,40.0298881530762,1.99478704151307,20.8700001239777,0.00133314969486881,0.000190431526997953,0.25,-3.57211774886481E-6,0.00011741571904038,-3.40718022230208E-6,150.0110168,150.0111694,-50509.5390625,-50444.83203125,56.7165286124291,20.5584409098843,24.807261,0,0,0,40,4449,149.86235,-50477.185546875,,,,,,,,,,,,,0,,,,0.0049,,,,,,150.0110931,,,,
,31960536.945,150.0120697,-55343.951171875,0.000133600042159947,1.72220501592716E-6,1,0.999253354069792,40.0298881530762,1.99460643687848,20.8700001239777,0.00152195305914729,0.000231171640769582,0.25,-2.90002878569391E-6,0.00013426024872217,-2.70627544337022E-6,150.0120697,150.0120697,-55376.1953125,-55311.70703125,56.6352392464291,20.5620141467021,25.186911,0,0,0,40,4449,149.852,-55343.951171875,,,,,,,,,,,,,0,,,,-0.0049,,,,,,150.0120697,,,,
,31960635.97,150.0122833,-60293.767578125,0.000152088627283209,1.70924963174807E-6,1,0.999253354069792,40.0298881530762,1.99453356767673,20.8700001239777,0.0017326040583619,0.000262635094472468,0.25,-3.34631178105304E-6,0.000152840415552963,-3.12674173149123E-6,150.0122833,150.0122833,-60323.640625,-60263.89453125,56.8283014906791,20.5542191653673,25.566563,0,0,0,40,4449,149.8418,-60293.767578125,,,,,,,,,,,,,0,,,,-0.00245,,,,,,150.0122833,,,,
,31960731.57,150.0104218,-65068.7109375,0.000174056347526564,2.01023147265086E-6,1,0.999253354069792,40.0298881530762,1.99457992388091,20.8700001239777,0.00197513082542066,0.00034523059481351,0.25,1.05822816439028E-7,0.000174910810134232,3.75569277460765E-7,150.0104218,150.0104218,-65101.046875,-65036.375,56.5031440266791,20.5571850741692,25.186911,0,0,0,40,4449,149.8305,-65068.7109375,,,,,,,,,,,,,0,,,,-0.0049,,,,,,150.0104218,,,,
,31960829.625,150.01184845,-69968.49609375,0.000187513029898833,3.73138532987427E-6,1,0.999253354069792,40.0298881530762,1.9949182432693,20.8700001239777,0.0021329412151354,0.000344639115501439,0.25,-2.29392837224887E-6,0.000188437462767344,-2.01611532141361E-6,150.0116272,150.0120697,-69998.1640625,-69938.828125,56.963523224506,20.5533655729723,25.186911,0,0,0,40,4449,149.82115,-69968.49609375,,,,,,,,,,,,,0,,,,0,,,,,,150.01184845,,,,
,31960925.71,150.0106659,-74770.15234375,0.000208699874034823,2.92191777587576E-6,1,0.999253354069792,40.0298881530762,1.9947049927899,20.8700001239777,0.0023715588090842,0.000395833171584453,0.25,-1.46898854598027E-6,0.000209727308568823,-1.15551601666898E-6,150.0106659,150.0106659,-74800.21875,-74740.0859375,56.8486238321791,20.5564960831579,25.186911,0,0,0,40,4449,149.81025,-74770.15234375,,,,,,,,,,,,,0,,,,0,,,,,,150.0106659,,,,
,31961023.185,150.0093689,-79644.765625,0.000221150921746959,4.54881510009374E-6,1,0.999253354069792,40.0298881530762,1.99505809235921,20.8700001239777,0.00251379688346347,0.000417663137469319,0.25,-1.71905152720405E-6,0.000222240145561397,-1.3888318622749E-6,150.0093689,150.0093689,-79647.296875,-79642.234375,56.7227816405829,20.5514392111151,24.807261,0,0,0,40,4449,149.8038,-79644.765625,,,,,,,,,,,,,0,,,,0,,,,,,150.0093689,,,,
,31961119.595,150.00956725,-84461.953125,0.000243245644193001,3.70932181184855E-6,1,0.999253354069792,40.0298881530762,1.99470536984634,20.8700001239777,0.00276213792154423,0.000472770473371474,0.25,-7.03906481507212E-7,0.000244442132412282,-3.36123865573871E-7,150.0093689,150.0097656,-84489.5,-84434.40625,56.7274714116983,20.5571978270458,25.186911,0,0,0,40,4449,149.79655,-84461.953125,,,,,,,,,,,,,0,,,,0,,,,,,150.00956725,,,,
,31961213.57,150.0104828,-89159,0.000255595905212654,2.73383197257114E-6,1,0.999253354069792,40.0298881530762,1.99487369931007,20.8700001239777,0.002906060981889,0.000477031970259725,0.25,-2.48127279501308E-6,0.0002568560496589,-2.10465745375288E-6,150.0104828,150.0104828,-89191.4375,-89126.5625,56.9189703989099,20.5540299296609,25.186911,0,0,0,40,4449,149.7845,-89159,,,,,,,,,,,,,0,,,,0,,,,,,150.0104828,,,,
,31961319.155,150.00538635,-86354.8125,0.000247816738119829,3.72029615994184E-6,1,0.999253354069792,40.0298881530762,1.99480454498542,20.8700001239777,0.00282095722267071,0.000442755021080342,0.25,-4.14595269177179E-6,0.000249041062260699,-3.7885731893905E-6,150.0052948,150.0054779,-86389.7890625,-86319.8359375,56.8603482599676,20.5585723340831,25.186911,0,0,0,40,4449,149.78095,-86354.8125,,,,,,,,,,,,,0,,,,0.00245,,,,,,150.00538635,,,,
,31961414.88,149.9987335,-81570.05859375,0.00023249269669204,3.41591967877751E-6,1,0.999253354069792,40.0298881530762,1.99450156840804,20.8700001239777,0.00264453008435298,0.000424527321268545,0.25,-3.07912868813687E-6,0.000233639882843119,-2.73864994628153E-6,149.9987335,149.9987335,-81572.515625,-81567.6015625,56.8197035769676,20.5613447095392,24.807261,0,0,0,40,4449,149.784,-81570.05859375,,,,,,,,,,,,,0,,,,0,,,,,,149.9987335,,,,
,31961511.325,149.996315,-76747.76171875,0.000212349395903544,2.59102996015005E-6,1,0.999253354069792,40.0298881530762,1.99467221296576,20.8700001239777,0.00241095745165213,0.000414443955573301,0.25,-4.63852965941757E-7,0.000213393379650496,-1.40221295356597E-7,149.9962616,149.9963684,-76775.125,-76720.3984375,57.3269804859484,20.5581785406922,24.807261,0,0,0,40,4449,149.7867,-76747.76171875,,,,,,,,,,,,,0,,,,0,,,,,,149.996315,,,,
,31961607.615,149.9926605,-71937.671875,0.00019839343859034,2.40018964618273E-6,1,0.999253354069792,40.0298881530762,1.99456862613611,20.8700001239777,0.00225535599899103,0.000370164297787661,0.25,-1.93427217722061E-6,0.000199370931018022,-1.63827670350317E-6,149.9922943,149.9930267,-71962.7421875,-71912.6015625,56.5656743082175,20.5597132956256,25.186911,0,0,0,40,4449,149.7978,-71937.671875,,,,,,,,,,,,,0,,,,0.00245,,,,,,149.9926605,,,,
,31961703.73,149.9934998,-67133.54296875,0.000180730158289347,2.48990057427235E-6,1,0.999253354069792,40.0298881530762,1.99485482781477,20.8700001239777,0.00205719549266658,0.00032371390103702,0.25,-2.95588302843916E-6,0.000181622276907082,-2.69118194539192E-6,149.9934998,149.9934998,-67160.921875,-67106.1640625,56.6579064734868,20.5549736474555,25.186911,0,0,0,40,4449,149.80455,-67133.54296875,,,,,,,,,,,,,0,,,,0,,,,,,149.9934998,,,,
,31961801.945,149.9910278,-62225.51953125,0.000162039252535256,3.72476938385748E-6,1,0.999253354069792,40.0298881530762,1.9947303163804,20.8700001239777,0.00184722625402623,0.000273595207774668,0.25,-4.11564069877691E-6,0.000162841228998935,-3.8846781080533E-6,149.9910278,149.9910278,-62262.921875,-62188.1171875,57.1167224142753,20.5555979685956,24.807261,0,0,0,40,4449,149.81405,-62225.51953125,,,,,,,,,,,,,0,,,,0.00245,,,,,,149.9910278,,,,
,31961899.665,149.9898071,-57343.673828125,0.000140789076069262,2.41133027705169E-6,1,0.999253354069792,40.0298881530762,1.99486314367059,20.8700001239777,0.00160816464981881,0.000220005890940162,0.25,-5.13818342578841E-6,0.000141488179685495,-4.94446212637468E-6,149.9898071,149.9898071,-57371.05078125,-57316.296875,56.9416376259676,20.5546646845826,25.566563,0,0,0,40,4449,149.8219,-57343.673828125,,,,,,,,,,,,,0,,,,-0.00245,,,,,,149.9898071,,,,
,31961997.205,149.9905396,-52466.408203125,0.000125378944397889,2.46533645441027E-6,1,0.999253354069792,40.0298881530762,1.99499717869527,20.8700001239777,0.00143536737598608,0.000177940880127792,0.25,-6.16186696299607E-6,0.000126003885875637,-5.99649112155354E-6,149.9905396,149.9905396,-52493.890625,-52438.92578125,56.6336759893906,20.5506252306479,25.186911,0,0,0,40,4449,149.82425,-52466.408203125,,,,,,,,,,,,,0,,,,0,,,,,,149.9905396,,,,
,31962095.025,149.989624,-47577.021484375,0.000106626325935136,1.91594561054675E-6,1,0.999253354069792,40.0298881530762,1.99462766364102,20.8700001239777,0.00121363339608234,0.00019052837282124,0.25,-1.78421983561554E-6,0.000107152303690864,-1.62609475202349E-6,149.989624,149.989624,-47606.94921875,-47547.09375,57.2300585495638,20.5614946682043,25.186911,0,0,0,40,4449,149.8366,-47577.021484375,,,,,,,,,,,,,0,,,,-0.00245,,,,,,149.989624,,,,
,31962193.85,149.9893799,-42636.7109375,9.14105780320114E-5,1.99981743155972E-6,1,0.999253354069792,40.0298881530762,1.9946063573635,20.8700001239777,0.00103953655260272,0.000168492152501892,0.25,-1.07588564540827E-6,9.18606972643842E-5,-9.37651321528326E-7,149.9893799,149.9893799,-42664.20703125,-42609.21484375,57.1331366131791,20.5579225079533,24.807261,0,0,0,40,4449,149.8475,-42636.7109375,,,,,,,,,,,,,0,,,,0.00245,,,,,,149.9893799,,,,
,31962290.43,149.9908905,-37812.28125,7.58701955551294E-5,2.18698181002756E-6,1,0.999253354069792,40.0298881530762,1.99476935240295,20.8700001239777,0.00086474352480193,0.000129132059382524,0.25,-1.83838881378917E-6,7.62452033786439E-5,-1.72793088611287E-6,149.9908905,149.9908905,-37817.22265625,-37807.33984375,56.8798889729483,20.5522977624625,25.186911,0,0,0,40,4449,149.85405,-37812.28125,,,,,,,,,,,,,0,,,,0.0049,,,,,,149.9908905,,,,
,31962386.67,149.9919968,-33002.787109375,6.00164906864671E-5,1.30219592729447E-6,1,0.999253354069792,40.0298881530762,1.99457403038382,20.8700001239777,0.00068474180435099,9.7786938500122E-5,0.25,-1.83802036993121E-6,6.03136886771607E-5,-1.75224900904167E-6,149.9914551,149.9925385,-33035.16796875,-32970.40625,56.7579549239483,20.5536224202404,24.807261,0,0,0,40,4449,149.8644,-33002.787109375,,,,,,,,,,,,,0,,,,0.00245,,,,,,149.9919968,,,,
,31962482.835,149.9924469,-28195.3447265625,4.21238040946918E-5,1.37156250143993E-6,1,0.999253354069792,40.0298881530762,1.99486363646062,20.8700001239777,0.000480797756791921,6.78884305629792E-5,0.25,-1.35674228890266E-6,4.23324679604745E-5,-1.29667684886683E-6,149.9924469,149.9924469,-28197.8359375,-28192.853515625,57.0534105042176,20.5497576756493,24.807261,0,0,0,40,4449,149.8708,-28195.3447265625,,,,,,,,,,,,,0,,,,0.0049,,,,,,149.9924469,,,,
,31962578.985,149.9910431,-23392.818359375,2.7395490395933E-5,1.47798042353393E-6,1,0.999253354069792,40.0298881530762,1.99502049522635,20.8700001239777,0.000314964467754151,3.12317498671643E-5,0.25,-2.02098756540378E-6,2.75329833720493E-5,-1.98738383110024E-6,149.9910431,149.9910431,-23395.40234375,-23390.234375,56.7720242372945,20.5524016159053,25.186911,0,0,0,40,4449,149.8777,-23392.818359375,,,,,,,,,,,,,0,,,,0,,,,,,149.9910431,,,,
,31962676.79,149.99230195,-18503.296875,1.0719469199015E-5,1.57956049943887E-6,1,0.999253354069792,40.0298881530762,1.99513005162542,20.8700001239777,0.000124217856417825,6.65131648302512E-6,0.25,-1.28149553104269E-6,1.07740426342111E-5,-1.27070472381049E-6,149.9921417,149.9924622,-18528.25,-18478.34375,57.1370447557753,20.5478913359939,25.186911,0,0,0,40,4449,149.88415,-18503.296875,,,,,,,,,,,,,0,,,,0,,,,,,149.99230195,,,,
,31962772.43,149.9923248,-13726.1059570312,-4.19469052113241E-6,1.1455016774293E-6,1,0.999253354069792,40.0298881530762,1.99484467807241,20.8700001239777,-4.60832346378854E-5,-1.70584586239564E-5,0.25,-7.72166732875838E-7,-4.2140108216938E-6,-7.82647198671638E-7,149.9923248,149.9923248,-13756.06640625,-13696.1455078125,56.3569794935829,20.5490366854234,25.566563,0,0,0,40,4449,149.8896,-13726.1059570312,,,,,,,,,,,,,0,,,,-0.0049,,,,,,149.9923248,,,,
,31962869.365,149.9957123,-8877.70263671875,-1.86022457039611E-5,7.50003771409719E-7,1,0.999253354069792,40.0298881530762,1.99464424223209,20.8700001239777,-0.000209861118966062,-4.39851438342411E-5,0.25,-6.34862944127923E-7,-1.8692359292143E-5,-6.67743605613889E-7,149.9957123,149.9957123,-8882.6708984375,-8872.734375,56.8540952318137,20.5497157037494,25.566563,0,0,0,40,4449,149.894,-8877.70263671875,,,,,,,,,,,,,0,,,,0.00245,,,,,,149.9957123,,,,
,31962967.575,149.99451445,-3969.78747558594,-2.9815530087438E-5,5.21476730068717E-7,1,0.999253354069792,40.0298881530762,1.99463740113361,20.8700001239777,-0.000336991714954501,-6.68862035921812E-5,0.25,-6.99135098819941E-7,-2.99604489645007E-5,-7.50378086804403E-7,149.9945068,149.9945221,-3999.76049804687,-3939.814453125,56.658688102006,20.5509961779888,24.807261,0,0,0,40,4449,149.8999,-3969.78747558594,,,,,,,,,,,,,0,,,,-0.00245,,,,,,149.99451445,,,,
,31963061.665,149.9966049,733.433502197266,-2.94619838077086E-5,3.90417384253468E-7,1,0.999253354069792,40.0298881530762,1.99467488132757,20.8700001239777,-0.000332812071746115,-6.71817522000791E-5,0.25,-7.86614679513397E-7,-2.960501540066E-5,-8.37773340677623E-7,149.9963684,149.9968414,703.620483398438,763.246520996094,56.8751992018329,20.5481808377991,25.566563,0,0,0,40,4449,149.9023,733.433502197266,,,,,,,,,,,,,0,,,,0,,,,,,149.9966049,,,,
,31963159.27,150.00057985,5608.21435546875,-1.27621251284732E-5,6.67821335801626E-7,1,0.999253354069792,40.0298881530762,1.99469816412135,20.8700001239777,-0.000144635749179768,-2.64097979575896E-5,0.25,-1.03595809992597E-7,-1.28244706125891E-5,-1.24556724930723E-7,150.0004578,150.0007019,5578.068359375,5638.3603515625,56.7751507513714,20.5490089183429,25.566563,0,0,0,40,4449,149.90155,5608.21435546875,,,,,,,,,,,,,0,,,,-0.00245,,,,,,150.00057985,,,,
,31963258.095,150.00440215,10551.6318359375,3.44145916187077E-6,7.93870675242438E-7,1,0.999253354069792,40.0298881530762,1.99467955572217,20.8700001239777,3.90397530636164E-5,6.90744780271954E-6,0.25,9.07365747133326E-9,3.45830400314434E-6,1.46211936281171E-8,150.0043182,150.0044861,10546.626953125,10556.63671875,56.9846271945253,20.5497194227607,25.186911,0,0,0,40,4449,149.8946,10551.6318359375,,,,,,,,,,,,,0,,,,-0.0049,,,,,,150.00440215,,,,
,31963355.42,150.0066833,15414.26953125,-2.10810786956445E-6,9.84421891370546E-7,1,0.999253354069792,40.0298881530762,1.99484503896916,20.8700001239777,-2.39099655693504E-5,-4.26731478162995E-6,0.25,-8.71488864904583E-9,-2.11842306994521E-6,-1.21202346842085E-8,150.0066833,150.0066833,15409.2666015625,15419.2724609375,56.7305979257752,20.543484040287,25.186911,0,0,0,40,4449,149.89075,15414.26953125,,,,,,,,,,,,,0,,,,-0.00245,,,,,,150.0066833,,,,
,31963452.945,150.0094757,20289.435546875,-1.5706776780095E-5,1.97594542056067E-6,1,0.999253354069792,40.0298881530762,1.99465043555827,20.8700001239777,-0.000178920626659677,-2.72436097736877E-5,0.25,3.35718714256397E-7,-1.57842824523685E-5,3.12374922511126E-7,150.0094757,150.0094757,20286.66015625,20292.2109375,57.187068981006,20.547048942684,25.566563,0,0,0,40,4449,149.88185,20289.435546875,,,,,,,,,,,,,0,,,,0,,,,,,150.0094757,,,,
,31963549.97,150.012207,25139.3056640625,-3.28331149183039E-5,2.30961791735781E-6,1,0.999253354069792,40.0298881530762,1.99461589086042,20.8700001239777,-0.000374684048162024,-5.30563126716638E-5,0.25,1.04460361156876E-6,-3.29957003213954E-5,9.97627565891557E-7,150.012207,150.012207,25109.6640625,25168.947265625,56.6102271338137,20.5467918833532,25.186911,0,0,0,40,4449,149.8715,25139.3056640625,,,,,,,,,,,,,0,,,,0,,,,,,150.012207,,,,
,31963648.56,150.01172635,30066.9501953125,-4.96618434475267E-5,1.62689577867008E-6,1,0.999253354069792,40.0298881530762,1.99415205943375,20.8700001239777,-0.00056367901320467,-9.70258767867774E-5,0.25,9.9754011699207E-8,-4.9905462887963E-5,2.16685297386678E-8,150.0116119,150.0118408,30037.05859375,30096.841796875,56.4851665707367,20.5560961311841,25.186911,0,0,0,40,4449,149.8611,30066.9501953125,,,,,,,,,,,,,0,,,,0.00245,,,,,,150.01172635,,,,
,31963746.61,150.0119934,34967.103515625,-6.49062047365504E-5,2.24055194431413E-6,1,0.999253354069792,40.0298881530762,1.99447430447552,20.8700001239777,-0.000738307944270706,-0.000118299204744335,0.25,8.8171946279092E-7,-6.52258555406254E-5,7.83647023560675E-7,150.0119934,150.0119934,34939.72265625,34994.484375,56.6618146160829,20.5546435731092,25.186911,0,0,0,40,4449,149.85,34967.103515625,,,,,,,,,,,,,0,,,,0.00245,,,,,,150.0119934,,,,
,31963843.045,150.0122833,39786.73828125,-7.99973536846288E-5,1.46137302947463E-6,1,0.999253354069792,40.0298881530762,1.99456755587183,20.8700001239777,-0.000910263033226104,-0.000144365422880626,0.25,1.21375540620649E-6,-8.03916003308619E-5,1.09387620478392E-6,150.0122833,150.0122833,39756.109375,39817.3671875,56.2991389831598,20.5508633379588,25.186911,0,0,0,40,4449,149.84055,39786.73828125,,,,,,,,,,,,,0,,,,0.00245,,,,,,150.0122833,,,,
,31963944,150.0111694,44832.935546875,-9.99388442380879E-5,1.72343546063288E-6,1,0.999253354069792,40.0298881530762,1.99439317557622,20.8700001239777,-0.00113915688959542,-0.000168395639334467,0.25,2.56818242833934E-6,-0.000100433119106128,2.42407460531658E-6,150.0111694,150.0111694,44830.2578125,44835.61328125,56.9088092281599,20.5520465367018,25.566563,0,0,0,40,4449,149.82875,44832.935546875,,,,,,,,,,,,,0,,,,0.00245,,,,,,150.0111694,,,,
,31964039.58,150.0098724,49610.72265625,-0.000118006406621174,1.3742217133914E-6,1,0.999253354069792,40.0298881530762,1.99433451804246,20.8700001239777,-0.00134092564461492,-0.000222594277293897,0.25,9.38008850897652E-7,-0.000118586877518839,7.58142182208058E-7,150.0098724,150.0098724,49578.40625,49643.0390625,56.9236601700253,20.5528100232366,25.566563,0,0,0,40,4449,149.8215,49610.72265625,,,,,,,,,,,,,0,,,,-0.00245,,,,,,150.0098724,,,,
,31964138.97,150.01473995,54578.138671875,-0.000133572713403188,1.53503086225541E-6,1,0.999253354069792,40.0298881530762,1.99440818753726,20.8700001239777,-0.00151960692125588,-0.000241952979068556,0.25,1.94345026218453E-6,-0.000134231246969992,1.74484567088975E-6,150.0145721,150.0149078,54545.76953125,54610.5078125,56.9502355396791,20.5483481336202,25.186911,0,0,0,40,4449,149.8056,54578.138671875,,,,,,,,,,,,,0,,,,0.00245,,,,,,150.01473995,,,,
,31964235.7,150.01166535,59412.837890625,-0.000150599792449512,2.12066749750982E-6,1,0.999253354069792,40.0298881530762,1.99432432229301,20.8700001239777,-0.00170985276872247,-0.000292294470891257,0.25,4.71169560691167E-7,-0.000151339762603888,2.39554774541265E-7,150.0116272,150.0117035,59387.80859375,59437.8671875,56.4281076888329,20.5478138855709,25.566563,0,0,0,40,4449,149.79615,59412.837890625,,,,,,,,,,,,,0,,,,0,,,,,,150.01166535,,,,
,31964333.14,150.010376,64283.572265625,-0.000164083804554692,2.11184309158614E-6,1,0.999253354069792,40.0298881530762,1.99428888319609,20.8700001239777,-0.0018704615611179,-0.000275132973950726,0.25,4.33081634795281E-6,-0.000164896119637327,4.09803959771785E-6,150.010376,150.010376,64255.56640625,64311.578125,57.014329078256,20.551381315376,25.186911,0,0,0,40,4449,149.78815,64283.572265625,,,,,,,,,,,,,0,,,,-0.0049,,,,,,150.010376,,,,
,31964430.595,150.0111084,69153.7578125,-0.000187060624437831,2.23695207489062E-6,1,0.999253354069792,40.0298881530762,1.99435960880195,20.8700001239777,-0.00212535193470321,-0.000354475106355253,0.25,1.34050608154585E-6,-0.00018798131208785,1.05842760760125E-6,150.0111084,150.0111084,69123.5859375,69183.9296875,56.4085669758521,20.549132785039,25.566563,0,0,0,40,4449,149.7781,69153.7578125,,,,,,,,,,,,,0,,,,0,,,,,,150.0111084,,,,
,31964527.905,150.0099792,74016.41015625,-0.000202927140495298,2.37866968591584E-6,1,0.999253354069792,40.0298881530762,1.99456758976325,20.8700001239777,-0.00230898835366396,-0.000366597931405144,0.25,3.03770405711211E-6,-0.000203928574949619,2.74051382907706E-6,150.0099792,150.0099792,73986.4296875,74046.390625,56.4406137451406,20.5442802763174,25.566563,0,0,0,40,4449,149.7664,74016.41015625,,,,,,,,,,,,,0,,,,0.00245,,,,,,150.0099792,,,,
,31964624.875,150.01057435,78864.55859375,-0.000221590238494853,2.46909431641011E-6,1,0.999253354069792,40.0298881530762,1.99452894157766,20.8700001239777,-0.00251808237237259,-0.000418786671368607,0.25,1.68754766283127E-6,-0.000222681499318726,1.35617637171195E-6,150.0104523,150.0106964,78834.6796875,78894.4375,56.9306948266983,20.5477189381087,25.566563,0,0,0,40,4449,149.7609,78864.55859375,,,,,,,,,,,,,0,,,,-0.00245,,,,,,150.01057435,,,,
,31964721.62,150.00860595,83702.99609375,-0.000238986200764473,2.09495334541666E-6,1,0.999253354069792,40.0298881530762,1.99439303970827,20.8700001239777,-0.00272334024773306,-0.000407135303960034,0.25,5.74015573237895E-6,-0.000240169385758714,5.40328250750334E-6,150.0084839,150.008728,83673.0703125,83732.921875,56.5125235689098,20.5489044276311,25.186911,0,0,0,40,4449,149.7546,83702.99609375,,,,,,,,,,,,,0,,,,-0.00245,,,,,,150.00860595,,,,
,31964814.805,150.00959775,88358.94140625,-0.000257760347146663,2.77054630003812E-6,1,0.999253354069792,40.0298881530762,1.99428313910689,20.8700001239777,-0.00293227082425596,-0.000466983189304268,0.25,3.73222039884023E-6,-0.000259032967969006,3.35808998998859E-6,150.0094604,150.0097351,88331.59375,88386.2890625,56.6672860157175,20.5469991835094,25.186911,0,0,0,40,4449,149.74475,88358.94140625,,,,,,,,,,,,,0,,,,-0.00245,,,,,,150.00959775,,,,
,31964921.87,150.0052261,87078.70703125,-0.000250697278783607,1.89691488261128E-6,1,0.999253354069792,40.0298881530762,1.99420375357013,20.8700001239777,-0.00285608088386728,-0.000429660217566977,0.25,5.79033740628967E-6,-0.00025193827871765,5.43670495520188E-6,150.0050201,150.0054321,87048.7265625,87108.6875,56.5594212800637,20.5547307722509,25.186911,0,0,0,40,4449,149.7398,87078.70703125,,,,,,,,,,,,,0,,,,-0.00245,,,,,,150.0052261,,,,
,31965015.68,149.99772645,82387.78125,-0.00023546865428182,2.98967158058487E-6,1,0.999253354069792,40.0298881530762,1.99424487014822,20.8700001239777,-0.00267212881548257,-0.000463920647686969,0.25,1.21051655541431E-7,-0.000236625961317039,-2.38444585011483E-7,149.9970398,149.9984131,82360.109375,82415.453125,56.4304525743906,20.5514621861817,25.186911,0,0,0,40,4449,149.7416,82387.78125,,,,,,,,,,,,,0,,,,0,,,,,,149.99772645,,,,
,31965113.065,149.99314115,77518.953125,-0.000217261700141263,2.83009309098839E-6,1,0.999253354069792,40.0298881530762,1.99417058054271,20.8700001239777,-0.00246855879846741,-0.000410032344454034,0.25,1.69931403627534E-6,-0.000218331744759043,1.37426795378652E-6,149.9930725,149.9932098,77486.421875,77551.484375,55.8887840105636,20.5514960898252,24.807261,0,0,0,40,4449,149.74525,77518.953125,,,,,,,,,,,,,0,,,,0,,,,,,149.99314115,,,,
,31965208.28,149.992836,72757.765625,-0.000200913552948388,2.65419828347867E-6,1,0.999253354069792,40.0298881530762,1.99430850001057,20.8700001239777,-0.0022804577778295,-0.000393555341870002,0.25,3.076923197079E-7,-0.000201900930621898,-1.16215578168492E-10,149.992569,149.993103,72727.7265625,72787.8046875,56.8900501436983,20.5514699485054,25.186911,0,0,0,40,4449,149.7556,72757.765625,,,,,,,,,,,,,0,,,,0.00245,,,,,,149.992836,,,,
,31965304.14,149.9913483,67967.578125,-0.000182455303603826,2.46560234781316E-6,1,0.999253354069792,40.0298881530762,1.99426380181143,20.8700001239777,-0.00207584844793551,-0.000328989388911384,0.25,2.78330052145507E-6,-0.000183355649022683,2.51513928253285E-6,149.9913483,149.9913483,67965.3515625,67969.8046875,56.5711457078521,20.5498592054036,25.946213,0,0,0,40,4449,149.76215,67967.578125,,,,,,,,,,,,,0,,,,0,,,,,,149.9913483,,,,
,31965400.415,149.9918518,63156.986328125,-0.000164102968618236,2.4592380008847E-6,1,0.999253354069792,40.0298881530762,1.99431955855063,20.8700001239777,-0.00186441484704606,-0.000311302180706497,0.25,1.14732026885983E-6,-0.000164910484971032,8.98643393921382E-7,149.9918518,149.9918518,63127.171875,63186.80078125,57.0158923352945,20.5545805316738,25.186911,0,0,0,40,4449,149.7702,63156.986328125,,,,,,,,,,,,,0,,,,0,,,,,,149.9918518,,,,
,31965497.28,149.9909515,58316.060546875,-0.000147985599371059,1.99484750451862E-6,1,0.999253354069792,40.0298881530762,1.99445873623962,20.8700001239777,-0.0016784967037844,-0.000297482672822285,0.25,-4.3945968495768E-7,-0.000148711365305277,-6.71686424880258E-7,149.9909515,149.9909515,58288.48828125,58343.6328125,56.6625962446021,20.54852428741,25.566563,0,0,0,40,4449,149.78205,58316.060546875,,,,,,,,,,,,,0,,,,0.00245,,,,,,149.9909515,,,,
,31965592.515,149.99015045,53553.6015625,-0.000132507432546488,1.73445645766514E-6,1,0.999253354069792,40.0298881530762,1.99416586554031,20.8700001239777,-0.00150452286316921,-0.000256017125994778,0.25,5.16108484677138E-7,-0.00013315856880621,3.11983821438305E-7,149.9899597,149.9903412,53526.0625,53581.140625,56.6837002146214,20.5552029791701,25.186911,0,0,0,40,4449,149.78855,53553.6015625,,,,,,,,,,,,,0,,,,0.00245,,,,,,149.99015045,,,,
,31965689.045,149.99113465,48730.4765625,-0.000113961130930433,2.28792482778195E-6,1,0.999253354069792,40.0298881530762,1.99442214133963,20.8700001239777,-0.00129825116046047,-0.000196383002834554,0.25,2.54416394487059E-6,-0.000114524296366088,2.3783572702153E-6,149.9910736,149.9911957,48703.16796875,48757.78515625,56.5390989385637,20.551807703398,25.946213,0,0,0,40,4449,149.79715,48730.4765625,,,,,,,,,,,,,0,,,,-0.0049,,,,,,149.99113465,,,,
,31965785.055,149.98997495,43929.94921875,-9.79621605977487E-5,1.86951097514989E-6,1,0.999253354069792,40.0298881530762,1.9943961883557,20.8700001239777,-0.00111369786410413,-0.000181884884326287,0.25,1.03530888016803E-6,-9.84443689082986E-5,8.86660440037578E-7,149.9895782,149.9903717,43899.90625,43959.9921875,56.4648442292367,20.5524529840337,24.807261,0,0,0,40,4449,149.80775,43929.94921875,,,,,,,,,,,,,0,,,,-0.00245,,,,,,149.98997495,,,,
,31965880.435,149.9883728,39164.916015625,-8.140564465045E-5,1.92462164866086E-6,1,0.999253354069792,40.0298881530762,1.99420941872429,20.8700001239777,-0.000925197101215003,-0.000152232662544216,0.25,7.63620120926062E-7,-8.18061283485609E-5,6.39238888384156E-7,149.9883728,149.9883728,39162.4375,39167.39453125,56.8736359447945,20.5578667602092,24.807261,0,0,0,40,4449,149.817,39164.916015625,,,,,,,,,,,,,0,,,,-0.0049,,,,,,149.9883728,,,,
,31965975.91,149.9905396,34392.89453125,-6.32085283531392E-5,1.72211261000264E-6,1,0.999253354069792,40.0298881530762,1.99437864750608,20.8700001239777,-0.000719116734023986,-0.000114324403020754,0.25,9.35859486138485E-7,-6.35199657822018E-5,8.40668888659182E-7,149.9905396,149.9905396,34370.484375,34415.3046875,56.3890262628713,20.5540354419164,25.566563,0,0,0,40,4449,149.8222,34392.89453125,,,,,,,,,,,,,0,,,,0,,,,,,149.9905396,,,,
,31966070.63,149.99040985,29657.7958984375,-4.68781339546373E-5,1.57579962284663E-6,1,0.999253354069792,40.0298881530762,1.99462702774145,20.8700001239777,-0.000534326132257144,-7.94268099124686E-5,0.25,1.16754104877411E-6,-4.71098170110595E-5,1.09905818374267E-6,149.9902954,149.9905243,29622.85546875,29692.736328125,56.4531198014483,20.5542493096752,25.186911,0,0,0,40,4449,149.8351,29657.7958984375,,,,,,,,,,,,,0,,,,0,,,,,,149.99040985,,,,
,31966165.56,149.9899979,24912.427734375,-3.06614171860875E-5,1.49914482139725E-6,1,0.999253354069792,40.0298881530762,1.99462529435344,20.8700001239777,-0.000349213036907289,-5.35071728713886E-5,0.25,6.26604374651429E-7,-3.08127099587493E-5,5.8100435055077E-7,149.9899445,149.9900513,24879.87890625,24944.9765625,56.9408559974483,20.5521267579806,25.946213,0,0,0,40,4449,149.8399,24912.427734375,,,,,,,,,,,,,0,,,,-0.00245,,,,,,149.9899979,,,,
,31966260.885,149.9897003,20147.5068359375,-1.54858229989833E-5,1.09863533717174E-6,1,0.999253354069792,40.0298881530762,1.99458484624683,20.8700001239777,-0.00017753538873265,-2.03318567734927E-5,0.25,9.06197688121371E-7,-1.55631605319051E-5,8.85991602348789E-7,149.9897003,149.9897003,20117.6953125,20177.318359375,57.4199942797368,20.5521783806557,25.566563,0,0,0,40,4449,149.8488,20147.5068359375,,,,,,,,,,,,,0,,,,0,,,,,,149.9897003,,,,
,31966357.865,149.9898376,15302.7836914062,-3.83204233245346E-7,8.04354976413131E-7,1,0.999253354069792,40.0298881530762,1.99477373119765,20.8700001239777,-6.43089244135834E-6,1.11911705695489E-5,0.25,1.05279140416618E-6,-3.86761875239493E-7,1.05733866030796E-6,149.9898376,149.9898376,15270.501953125,15335.0654296875,56.6641595016406,20.5473560754074,25.186911,0,0,0,40,4449,149.85925,15302.7836914062,,,,,,,,,,,,,0,,,,-0.00245,,,,,,149.9898376,,,,
,31966454.055,149.9915009,10495.3237304688,1.44113795351012E-5,9.58334925630725E-7,1,0.999253354069792,40.0298881530762,1.99492600149202,20.8700001239777,0.000162378861532206,3.53719312142268E-5,0.25,6.05632738133898E-7,1.44810143930446E-5,6.31651229299874E-7,149.9915009,149.9915009,10462.7880859375,10527.859375,56.8470605751406,20.5503513433052,25.946213,0,0,0,40,4449,149.86715,10495.3237304688,,,,,,,,,,,,,0,,,,-0.0049,,,,,,149.9915009,,,,
,31966548.425,149.9903946,5775.046875,2.67883624787542E-5,5.62109868460241E-7,1,0.999253354069792,40.0298881530762,1.99486227005824,20.8700001239777,0.000303676145092605,5.51282329111656E-5,0.25,1.89985562501659E-7,2.6919278744694E-5,2.33857183134886E-7,149.9901428,149.9906464,5750.01416015625,5800.07958984375,57.1245386994676,20.5516134798813,25.946213,0,0,0,40,4449,149.87475,5775.046875,,,,,,,,,,,,,0,,,,-0.00245,,,,,,149.9903946,,,,
,31966642.915,149.9936523,1054.17175292969,3.30326488783841E-5,4.29543521457064E-7,1,0.999253354069792,40.0298881530762,1.99469069556986,20.8700001239777,0.000375222610072841,6.34298236458405E-5,0.25,-1.66117370345504E-7,3.31946994185526E-5,-1.13884858171323E-7,149.9936523,149.9936523,1021.79992675781,1086.54357910156,56.8634747740445,20.5523970057714,25.186911,0,0,0,40,4449,149.87935,1054.17175292969,,,,,,,,,,,,,0,,,,0,,,,,,149.9936523,,,,
,31966663.785,149.9927826,-0.502384498715401,3.25420271086215E-5,4.36093154431554E-7,1,0.999253354069792,40.0298881530762,1.99487690998713,20.8700001239777,0.000370580313475792,5.73399598595411E-5,0.25,-6.1769268060491E-7,3.27023980066826E-5,-5.68446372659333E-7,149.9927826,149.9927826,-0.761188626289368,-0.243580371141434,56.4617177151598,20.5503552105166,25.186911,0,0,0,40,4417,149.8816,-0.502384498715401,,,,,,,,,,,,,0,,,,0,,,,,,149.9927826,,,,