File: data/monolayers/magneticStructure/ML_Ac_CoFe_C-2/PPMS/data/DD175_23_HYST_20K_100OE.DAT
[Header]
; VSM Data File (default extension .dat)
; Copyright (c) 2003, Quantum Design, Inc. All rights reserved.
TITLE,
FILEOPENTIME,46644185.19,04/06/2017,6:59 am
BYAPP,VSM,1.0,1.0
INFO,PPMS VSM Option Release 1.3.7 Build 2,APPNAME
INFO,291,COIL_SERIAL_NUMBER
INFO,0,MOMENT_UNITS
INFO,CoFe2O4,SAMPLE_MATERIAL
INFO,,SAMPLE_COMMENT
INFO,,SAMPLE_MASS
INFO,,SAMPLE_VOLUME
INFO,,SAMPLE_MOLECULAR_WEIGHT
INFO,,SAMPLE_SIZE
INFO,,SAMPLE_SHAPE
INFO,36.62,SAMPLE_OFFSET
DATATYPE,COMMENT,1
DATATYPE,TIME,2
STARTUPAXIS,X,2
STARTUPAXIS,Y1,5
[Data]
Comment,Time Stamp (sec),Temperature (K),Magnetic Field (Oe),Moment (emu),M. Std. Err. (emu),Transport Action,Averaging Time (sec),Frequency (Hz),Peak Amplitude (mm),Center Position (mm),Coil Signal' (mV),Coil Signal" (mV),Range (mV),M. Quad. Signal (emu),M. Raw' (emu),M. Raw" (emu),Min. Temperature (K),Max. Temperature (K),Min. Field (Oe),Max. Field (Oe),Mass (grams),Motor Lag (deg),Pressure (Torr),VSM Status (code),Motor Status (code),Measure Status (code),PPMS Status (code),System Temp. (K),System Field (Oe),Sample Position (deg),Bridge 1 Resistance (ohms),Bridge 1 Excitation (에),Bridge 2 Resistance (ohms),Bridge 2 Excitation (에),Bridge 3 Resistance (ohms),Bridge 3 Excitation (에),Bridge 4 Resistance (ohms),Bridge 4 Excitation (에),Signal 1 Vin (V),Signal 2 Vin (V),Digital Inputs (code),Drive 1 Iout (mA),Drive 1 Ipower (W),Drive 2 Iout (mA),Drive 2 Ipower (W),Pressure (),Map 20 (),Map 21 (),Map 22 (),Map 23 (),Map 24 (),Map 25 (),Map 26 (),Map 27 (),Map 28 (),Map 29 ()
,46645042.515,20.022439,-0.305619746446609,4.39576442978448E-5,1.90102861909182E-7,1,0.999253354069792,40.0298881530762,1.99441133786709,16.1200007982552,0.000477525136575105,5.57970591616552E-5,0.25,-2.5547646882972E-6,4.37025630388332E-5,-2.43975750113887E-6,20.0223484,20.0225296,-0.305619746446609,-0.305619746446609,52.7216252506402,18.7208838232266,4.57290245,0,0,0,4417,20.0135,-0.305619746446609,,,,,,,,,,,,,,,,,13.753754,,,,,,20.022439,,,,
,46645107.765,20.0100851,2503.24340820313,4.86704578645331E-5,2.75843327655823E-7,1,0.999253354069792,40.0298881530762,1.99461466828715,16.1200007982552,0.000527721481907904,6.78549783160615E-5,0.25,-2.26824271550024E-6,4.83883686365038E-5,-2.14054888838272E-6,20.0099945,20.0101757,2473.47045898438,2533.01635742187,51.8243157105632,18.7296882474401,4.5496073,0,0,0,4449,20.0059,2503.24340820313,,,,,,,,,,,,,,,,,13.003003,,,,,,20.0100851,,,,
,46645158.345,20.00678155,5027.42236328125,4.38217138213104E-5,2.34162219959415E-7,1,0.999253354069792,40.0298881530762,1.9946811429791,16.1200007982552,0.000475406231670197,5.98407178321868E-5,0.25,-2.16375333353984E-6,4.3569986878547E-5,-2.04375815696602E-6,20.0067539,20.0068092,4997.5927734375,5057.251953125,52.3816168447748,18.7321738339911,4.6416528,0,0,0,4449,20.0031,5027.42236328125,,,,,,,,,,,,,,,,,13.753754,,,,,,20.00678155,,,,
,46645209.9,20.0049,7602.35766601562,3.84543933581958E-5,3.24285693488868E-7,1,0.999253354069792,40.0298881530762,1.99462605472955,16.1200007982552,0.000418309764460358,4.61643971614663E-5,0.25,-2.49336393671898E-6,3.82370535683372E-5,-2.38037358783177E-6,20.0048161,20.0049839,7574.99755859375,7629.7177734375,52.4910448374671,18.7336704504661,4.6414213,0,0,0,4449,20.00065,7602.35766601562,,,,,,,,,,,,,,,,,13.753754,,,,,,20.0049,,,,
,46645260.04,20.0023413,10109.2001953125,3.29494356179485E-5,3.2395072427755E-7,1,0.999253354069792,40.0298881530762,1.99460840136497,16.1200007982552,0.000359940296230138,3.10883661202931E-5,0.25,-2.92773525580932E-6,3.27672669144627E-5,-2.82265275185409E-6,20.0022984,20.0023842,10084.1328125,10134.267578125,52.1815199438517,18.7402878788487,4.7588582,0,0,0,4449,19.9987,10109.2001953125,,,,,,,,,,,,,,,,,13.753754,,,,,,20.0023413,,,,
,46645310.305,20.00166035,12620.2827148438,2.73728104191715E-5,4.00268891249005E-7,1,0.999253354069792,40.0298881530762,1.99453055696594,16.1200007982552,0.000299656048225342,2.22868077032904E-5,0.25,-2.76476575535726E-6,2.72242381058538E-5,-2.67241132933352E-6,20.0016041,20.0017166,12592.740234375,12647.8251953125,53.0710131987364,18.7366167702013,4.7353244,0,0,0,4449,20.0001,12620.2827148438,,,,,,,,,,,,,,,,,13.753754,,,,,,20.00166035,,,,
,46645362.235,20.00296215,15214.4223632812,2.15927012706608E-5,4.29046980821317E-7,1,0.999253354069792,40.0298881530762,1.99463928056815,16.1200007982552,0.000237534639213214,1.12244420595648E-5,0.25,-2.77488661789602E-6,2.14788769313346E-5,-2.69606458787162E-6,20.0029488,20.0029755,15181.904296875,15246.9404296875,52.7990064740441,18.7401098933363,4.80663685,0,0,0,4449,19.99865,15214.4223632812,,,,,,,,,,,,,,,,,13.753754,,,,,,20.00296215,,,,
,46645411.975,20.0024357,17703.1572265625,1.67034400690753E-5,2.80078595185514E-7,1,0.999253354069792,40.0298881530762,1.99457073929611,16.1200007982552,0.000185594579613477,-1.69224917013403E-6,0.25,-3.11328346964465E-6,1.66196879807796E-5,-3.04497356909586E-6,20.0023117,20.0025597,17670.80078125,17735.513671875,52.3816168447748,18.7429077719574,4.78286695,0,0,0,4449,19.99705,17703.1572265625,,,,,,,,,,,,,,,,,12.627627,,,,,,20.0024357,,,,
,46645461.03,20.00279045,20153.96875,1.08497041582134E-5,2.92648040831094E-7,1,0.999253354069792,40.0298881530762,1.99482857736971,16.1200007982552,0.000122622252394134,-1.26393759557468E-5,0.25,-3.0962933074595E-6,1.07997007409706E-5,-3.04479325171907E-6,20.002779,20.0028019,20124.05859375,20183.87890625,52.6184502861017,18.7376452606294,4.8308864,0,0,0,4449,19.99725,20153.96875,,,,,,,,,,,,,,,,,13.753754,,,,,,20.00279045,,,,
,46645510.41,20.00769615,22623.22265625,5.49990654452147E-6,3.47119454558248E-7,1,0.999253354069792,40.0298881530762,1.99473354125254,16.1200007982552,6.43227436753033E-5,-1.85916314592789E-5,0.25,-2.70285144941129E-6,5.47889552719529E-6,-2.67000075339359E-6,20.0076618,20.0077305,22593.234375,22653.2109375,52.3394089047363,18.7407045559692,4.8791447,0,0,0,4449,20.00505,22623.22265625,,,,,,,,,,,,,,,,,13.753754,,,,,,20.00769615,,,,
,46645562.955,20.0047226,25246.44140625,-5.63623945240735E-7,1.75390353310258E-7,1,0.999253354069792,40.0298881530762,1.99470352534799,16.1200007982552,-5.48294617014803E-7,-3.2173084633551E-5,0.25,-2.89044951913763E-6,-5.50681707535581E-7,-2.87689179744801E-6,20.0046711,20.0047741,25216.50390625,25276.37890625,52.8865488681979,18.7400497130875,4.87938835,0,0,0,4449,20.00005,25246.44140625,,,,,,,,,,,,,,,,,13.753754,,,,,,20.0047226,,,,
,46645614.27,20.0016985,27813.1669921875,-6.1655868311207E-6,5.27490703241519E-7,1,0.999253354069792,40.0298881530762,1.99468481175303,16.1200007982552,-6.12387691013114E-5,-4.04997226260548E-5,0.25,-2.66977454247519E-6,-6.12354648705359E-6,-2.6776571373878E-6,20.0016594,20.0017376,27775.70703125,27850.626953125,52.6121972579479,18.7421955176352,4.9533644,0,0,0,4449,19.99385,27813.1669921875,,,,,,,,,,,,,,,,,13.003003,,,,,,20.0016985,,,,
,46645664.89,19.99976445,30342.37109375,-1.28711045935522E-5,4.47475200699385E-7,1,0.999253354069792,40.0298881530762,1.99475294894853,16.1200007982552,-0.000131805693466288,-6.22743393578321E-5,0.25,-3.50107826621019E-6,-1.27913967196265E-5,-3.53042046378879E-6,19.9996643,19.9998646,30315.513671875,30369.228515625,53.0483459716787,18.7409728235027,4.92837695,0,0,0,4449,19.99405,30342.37109375,,,,,,,,,,,,,,,,,12.627627,,,,,,19.99976445,,,,
,46645719.09,19.9989805,33052.923828125,-1.84216323163482E-5,4.98208787253553E-7,1,0.999253354069792,40.0298881530762,1.99469001663952,16.1200007982552,-0.000192524933717933,-6.73434650345944E-5,0.25,-2.98334899799947E-6,-1.83164254342631E-5,-3.03866606387005E-6,19.9989223,19.9990387,33022.921875,33082.92578125,52.5574832616017,18.7420073849024,5.0275841,0,0,0,4449,19.9947,33052.923828125,,,,,,,,,,,,,,,,,13.753754,,,,,,19.9989805,,,,
,46645777,20.0004311,35946.423828125,-2.56517962832681E-5,5.03151458588917E-7,1,0.999253354069792,40.0298881530762,1.99483300226179,16.1200007982552,-0.000270011187453145,-8.32097729232678E-5,0.25,-3.16748928234829E-6,-2.55114120199796E-5,-3.25357400263885E-6,20.0004311,20.0004311,35941.484375,35951.36328125,52.677072425044,18.7405777867303,5.0780606,0,0,0,4449,19.9963,35946.423828125,,,,,,,,,,,,,,,,,13.753754,,,,,,20.0004311,,,,
,46645833.07,19.99952315,38747.173828125,-3.20162075113579E-5,5.10401656530442E-7,1,0.999253354069792,40.0298881530762,1.99476918775822,16.1200007982552,-0.000337668299851365,-0.000100246393494152,0.25,-3.61303459962382E-6,-3.18453669879544E-5,-3.72695800298541E-6,19.9994755,19.9995708,38719.640625,38774.70703125,52.0580226378132,18.7395020621966,4.95287015,0,0,0,4449,19.99655,38747.173828125,,,,,,,,,,,,,,,,,13.003003,,,,,,19.99952315,,,,
,46645888.86,20.000124,41538.833984375,-3.75039274586122E-5,4.20857745041148E-7,1,0.999253354069792,40.0298881530762,1.99466085846525,16.1200007982552,-0.000398171304494857,-0.000102810930345624,0.25,-2.86857092274064E-6,-3.73132865528284E-5,-3.01402512364833E-6,20.000124,20.000124,41533.97265625,41543.6953125,52.6325195994479,18.7426188132435,5.0780606,0,0,0,4449,19.9966,41538.833984375,,,,,,,,,,,,,,,,,13.753754,,,,,,20.000124,,,,
,46645942.875,20.0000744,44237.169921875,-4.4942162354311E-5,5.07875768109983E-7,1,0.999253354069792,40.0298881530762,1.99475796056917,16.1200007982552,-0.000477797797974534,-0.000119943872889003,0.25,-3.1273960023767E-6,-4.47197394132762E-5,-3.30924193696073E-6,20.000042,20.0001068,44202.12109375,44272.21875,53.0530357427941,18.7421750468194,5.0533264,0,0,0,4449,19.9957,44237.169921875,,,,,,,,,,,,,,,,,13.378378,,,,,,20.0000744,,,,
,46646000.57,20.00038055,47121.16015625,-5.32929687035694E-5,5.97630776004598E-7,1,0.999253354069792,40.0298881530762,1.99473095289055,16.1200007982552,-0.000567741545657451,-0.000136061230542672,0.25,-3.12693676035657E-6,-5.30380289303092E-5,-3.35274034118272E-6,20.0002499,20.0005112,47090.9765625,47151.34375,52.9053079526594,18.7440021273787,5.0533264,0,0,0,4449,19.9959,47121.16015625,,,,,,,,,,,,,,,,,13.003003,,,,,,20.00038055,,,,
,46646059.33,19.9998093,50057.34375,-5.83951960725079E-5,4.88770810267302E-7,1,0.999253354069792,40.0298881530762,1.99473660945754,16.1200007982552,-0.000622895259715509,-0.000145080615418161,0.25,-3.04467939181607E-6,-5.81248530584603E-5,-3.30190871444373E-6,19.9998093,19.9998093,50054.98828125,50059.69921875,52.6426807701979,18.7405806450146,5.1290436,0,0,0,4449,19.99595,50057.34375,,,,,,,,,,,,,,,,,13.003003,,,,,,19.9998093,,,,
,46646111.39,20.0016136,52658.734375,-6.467989130437E-5,5.90865018217814E-7,1,0.999253354069792,40.0298881530762,1.99462164145681,16.1200007982552,-0.000689022143302616,-0.000166036927370951,0.25,-3.86024889782199E-6,-6.43854968141995E-5,-4.15081142675286E-6,20.0016136,20.0016136,52653.71875,52663.75,52.7779025040248,18.7421548946265,5.1040616,0,0,0,4449,19.996,52658.734375,,,,,,,,,,,,,,,,,13.753754,,,,,,20.0016136,,,,
,46646162.065,20.0024252,55189.80859375,-7.23211183956381E-5,6.70778933307823E-7,1,0.999253354069792,40.0298881530762,1.99468875196805,16.1200007982552,-0.000770654695176441,-0.000185008037930432,0.25,-4.24619143279678E-6,-7.20004296852777E-5,-4.5796312708458E-6,20.0023556,20.0024948,55162.28125,55217.3359375,52.5559200045633,18.74350947718,5.12929985,0,0,0,4449,19.99395,55189.80859375,,,,,,,,,,,,,,,,,13.753754,,,,,,20.0024252,,,,
,46646212,20.00148965,57688.380859375,-7.75140821729483E-5,7.51300658289175E-7,1,0.999253354069792,40.0298881530762,1.99488077590844,16.1200007982552,-0.00082751239925057,-0.000190779801658686,0.25,-3.84185836812945E-6,-7.71827055306395E-5,-4.21059919451872E-6,20.0014286,20.0015507,57660.9453125,57715.81640625,52.5160569500825,18.7448667586832,5.0780606,0,0,0,4449,19.9942,57688.380859375,,,,,,,,,,,,,,,,,13.003003,,,,,,20.00148965,,,,
,46646280.825,19.9981184,59782.259765625,-8.27877161944204E-5,6.80003913021278E-7,1,0.999253354069792,40.0298881530762,1.99479820919642,16.1100011877716,-0.000882659962615824,-0.000210500690074448,0.25,-4.72102391713653E-6,-8.24387890025215E-5,-5.11975805381255E-6,19.9980183,19.9982185,59752.79296875,59811.7265625,53.1702800206787,18.7412982932762,5.1805391,0,0,0,4449,19.9931,59782.259765625,,,,,,,,,,,,,,,,,13.753754,,,,,,19.9981184,,,,
,46646332.22,20.00386525,57223.681640625,-7.62913233830059E-5,7.27290705450284E-7,1,0.999253354069792,40.0298881530762,1.9947015020669,16.1200007982552,-0.000811139293106172,-0.000205818596336873,0.25,-5.46032693889791E-6,-7.59552460560315E-5,-5.8149305339803E-6,20.0035439,20.0041866,57196.23046875,57251.1328125,52.7607066766017,18.7420418917219,5.2588184,0,0,0,4449,19.9991,57223.681640625,,,,,,,,,,,,,,,,,14.129129,,,,,,20.00386525,,,,
,46646385.96,20.0025558,54537.40625,-7.1634711606107E-5,6.09138109324627E-7,1,0.999253354069792,40.0298881530762,1.99481399013905,16.1200007982552,-0.000764043702729643,-0.00017945009349278,0.25,-3.85431211997437E-6,-7.13166615931052E-5,-4.1839683105314E-6,20.0025558,20.0025558,54532.375,54542.4375,52.4308594414863,18.7397994805883,5.1290436,0,0,0,4449,19.9923,54537.40625,,,,,,,,,,,,,,,,,13.003003,,,,,,20.0025558,,,,
,46646437.3,19.9948673,51968.8671875,-6.37860438410607E-5,6.47873861969346E-7,1,0.999253354069792,40.0298881530762,1.99490857508871,16.1200007982552,-0.000677957329147408,-0.000172792952418481,0.25,-4.64765669321932E-6,-6.34898176952272E-5,-4.92856254852278E-6,19.9948673,19.9948673,51963.8359375,51973.8984375,53.350836208621,18.7432453979819,5.2850857,0,0,0,4449,19.98935,51968.8671875,,,,,,,,,,,,,,,,,14.129129,,,,,,19.9948673,,,,
,46646492.22,20.000247,49227.896484375,-5.84003147182452E-5,5.58488992076102E-7,1,0.999253354069792,40.0298881530762,1.99475806080119,16.1200007982552,-0.000622172196269248,-0.000149354302370467,0.25,-3.44319581434894E-6,-5.81260333272711E-5,-3.69642105255153E-6,20.0002251,20.0002689,49200.34765625,49255.4453125,52.4644694678132,18.7428122599342,5.1805391,0,0,0,4449,19.99405,49227.896484375,,,,,,,,,,,,,,,,,13.753754,,,,,,20.000247,,,,
,46646549.775,20.00114725,46349.212890625,-5.01009071491781E-5,6.12505736671152E-7,1,0.999253354069792,40.0298881530762,1.994739326005,16.1200007982552,-0.000532546882117722,-0.000134486712287788,0.25,-3.55249320895344E-6,-4.98569011903479E-5,-3.76011752103119E-6,20.0011215,20.001173,46341.64453125,46356.78125,53.0217706020248,18.7441248120136,5.3381476,0,0,0,4449,19.9955,46349.212890625,,,,,,,,,,,,,,,,,14.129129,,,,,,20.00114725,,,,
,46646603.055,20.00627895,43688.06640625,-4.42319635223808E-5,5.26912530387871E-7,1,0.999253354069792,40.0298881530762,1.99476348090637,16.1200007982552,-0.000469853465358659,-0.000120204612346561,0.25,-3.27962408968309E-6,-4.40112208349913E-5,-3.45644827335625E-6,20.0062656,20.0062923,43658.0625,43718.0703125,52.8498123277941,18.7439743489211,5.1805391,0,0,0,4449,19.99565,43688.06640625,,,,,,,,,,,,,,,,,13.003003,,,,,,20.00627895,,,,
,46646653.935,19.99772165,41144.19140625,-3.77276078825188E-5,4.7372409241531E-7,1,0.999253354069792,40.0298881530762,1.99476651635617,16.1200007982552,-0.000401646064793749,-9.73324956824354E-5,0.25,-2.32013435451657E-6,-3.75376531726957E-5,-2.46839431808183E-6,19.9976425,19.9978008,41114.1875,41174.1953125,53.2312470451787,18.7436771923405,5.31161665,0,0,0,4449,19.9897,41144.19140625,,,,,,,,,,,,,,,,,13.753754,,,,,,19.99772165,,,,
,46646707.69,20.00049685,38457.869140625,-3.19791822824513E-5,4.35914182843869E-7,1,0.999253354069792,40.0298881530762,1.99485655719556,16.1200007982552,-0.00033787363605204,-9.68461261667465E-5,0.25,-3.30388568720644E-6,-3.18094674484882E-5,-3.41867317365675E-6,20.000494,20.0004997,38435.3203125,38480.41796875,52.9584586919671,18.7398330371593,5.28534935,0,0,0,4449,19.9929,38457.869140625,,,,,,,,,,,,,,,,,12.627627,,,,,,20.00049685,,,,
,46646762.955,20.0049763,35694.345703125,-2.5305469687888E-5,5.3718960600238E-7,1,0.999253354069792,40.0298881530762,1.99482402580124,16.1200007982552,-0.00026870331944235,-6.8927428723323E-5,0.25,-1.90245711493972E-6,-2.51716131536572E-5,-1.99313638394479E-6,20.0048714,20.0050812,35667.01953125,35721.671875,53.2304654166595,18.744687715675,5.28534935,0,0,0,4449,19.9968,35694.345703125,,,,,,,,,,,,,,,,,13.003003,,,,,,20.0049763,,,,
,46646815.345,19.9982815,33075.794921875,-1.9647335211687E-5,4.86904850381687E-7,1,0.999253354069792,40.0298881530762,1.99487143853008,16.1200007982552,-0.000206430109401077,-6.57687600203618E-5,0.25,-2.61856937835352E-6,-1.95372955420827E-5,-2.68045549318444E-6,19.9982605,19.9983025,33048.46484375,33103.125,52.8818590970825,18.7444280755351,5.3649449,0,0,0,4449,19.9867,33075.794921875,,,,,,,,,,,,,,,,,13.003003,,,,,,19.9982815,,,,
,46646870.135,20.00081445,30337.0302734375,-1.19109602249644E-5,4.44677750031877E-7,1,0.999253354069792,40.0298881530762,1.99488294238675,16.1200007982552,-0.000124235353419624,-4.49404747286524E-5,0.25,-2.06047668845877E-6,-1.18415495174365E-5,-2.09374524533243E-6,20.0006371,20.0009918,30304.376953125,30369.68359375,53.1038415965441,18.7450607728109,5.33841395,0,0,0,4449,19.991,30337.0302734375,,,,,,,,,,,,,,,,,13.753754,,,,,,20.00081445,,,,
,46646926.74,20.00349905,27508.55859375,-5.70191578269539E-6,5.22281396088996E-7,1,0.999253354069792,40.0298881530762,1.99489875584372,16.1200007982552,-5.69328667074124E-5,-3.58016299322829E-5,0.25,-2.31520187570958E-6,-5.66356253195692E-6,-2.32319091901805E-6,20.0034027,20.0035954,27476.076171875,27541.041015625,53.4336888316595,18.7458557416654,5.33841395,0,0,0,4449,19.9926,27508.55859375,,,,,,,,,,,,,,,,,13.753754,,,,,,20.00349905,,,,
,46646979.335,20.0084133,24882.296875,-5.52997469276677E-7,4.25321600440624E-7,1,0.999253354069792,40.0298881530762,1.9948514295772,16.1200007982552,-2.32920881863579E-6,-2.14714300713183E-5,0.25,-1.89752768776726E-6,-5.43549373352126E-7,-1.88922281781359E-6,20.0084133,20.0084133,24877.2265625,24887.3671875,52.3847433588517,18.7451744881812,5.33841395,0,0,0,4449,19.9943,24882.296875,,,,,,,,,,,,,,,,,13.003003,,,,,,20.0084133,,,,
,46647037.065,19.9933605,21995.541015625,6.63483925853717E-6,3.05846339700083E-7,1,0.999253354069792,40.0298881530762,1.99498482138412,16.1200007982552,7.59730933947041E-5,-1.32341351286512E-5,0.25,-2.40564801915338E-6,6.60646656151503E-6,-2.37084060397911E-6,19.9933605,19.9933605,21993.1015625,21997.98046875,52.3018907358132,18.7450638828702,5.2850857,0,0,0,4449,19.98295,21995.541015625,,,,,,,,,,,,,,,,,13.003003,,,,,,19.9933605,,,,
,46647093.045,19.9995956,19197.6669921875,1.29265470715508E-5,4.05251203013048E-7,1,0.999253354069792,40.0298881530762,1.99496216220491,16.1200007982552,0.000142890074427439,3.05839214213231E-6,0.25,-2.00430672050669E-6,1.2861177519417E-5,-1.95281339918016E-6,19.9994926,19.9996986,19165.203125,19230.130859375,52.8670081552171,18.7451491484063,5.3917422,0,0,0,4449,19.98905,19197.6669921875,,,,,,,,,,,,,,,,,13.003003,,,,,,19.9995956,,,,
,46647148.68,19.9979229,16416.5283203125,1.90950558746747E-5,2.59936230769053E-7,1,0.999253354069792,40.0298881530762,1.99484909809393,16.1200007982552,0.000209540306441513,1.302234874736E-5,0.25,-2.16738251937214E-6,1.89942756378755E-5,-2.09822297715977E-6,19.9978447,19.9980011,16386.3359375,16446.720703125,53.1616821069672,18.7441034675764,5.3917422,0,0,0,4449,19.99085,16416.5283203125,,,,,,,,,,,,,,,,,13.003003,,,,,,19.9979229,,,,
,46647206.09,19.998312,13548.2065429688,2.58534059660769E-5,3.14083189489157E-7,1,0.999253354069792,40.0298881530762,1.99491269871387,16.1200007982552,0.00028198631492503,2.72500314963626E-5,0.25,-2.03650566558119E-6,2.57121289751297E-5,-1.95144145283528E-6,19.99827,19.998354,13518.146484375,13578.2666015625,53.2265572740633,18.7446279322992,5.3654802,0,0,0,4449,19.9897,13548.2065429688,,,,,,,,,,,,,,,,,13.753754,,,,,,19.998312,,,,
,46647263.07,20.0018711,10698.9360351562,3.24280331010926E-5,3.47381517899041E-7,1,0.999253354069792,40.0298881530762,1.99494946371059,16.1200007982552,0.000352155718451378,4.27828965381867E-5,0.25,-1.74993901111171E-6,3.22461790729049E-5,-1.65216698836995E-6,20.0017853,20.0019569,10668.966796875,10728.9052734375,52.6333012279671,18.7478670703828,5.3649449,0,0,0,4449,19.9926,10698.9360351562,,,,,,,,,,,,,,,,,13.753754,,,,,,20.0018711,,,,
,46647320.245,20.0005741,7839.90869140625,3.84527052956986E-5,2.75295584326606E-7,1,0.999253354069792,40.0298881530762,1.99495301996872,16.1200007982552,0.000417855859113559,4.90165949454264E-5,0.25,-2.22900220454852E-6,3.82348961913425E-5,-2.11716244560181E-6,20.0005741,20.0005741,7835.015625,7844.8017578125,53.2218675029479,18.7479336397134,5.4458747,0,0,0,4449,19.9916,7839.90869140625,,,,,,,,,,,,,,,,,13.003003,,,,,,20.0005741,,,,
,46647378.28,20.0038967,4941.50830078125,4.44236627863202E-5,2.18575848511009E-7,1,0.999253354069792,40.0298881530762,1.99502048379596,16.1200007982552,0.000481998821127679,6.07526336476874E-5,0.25,-2.18583413536218E-6,4.41683798729039E-5,-2.06440629658196E-6,20.0038967,20.0038967,4936.65380859375,4946.36279296875,53.3750666927172,18.7467608208747,5.4458747,0,0,0,4449,19.99355,4941.50830078125,,,,,,,,,,,,,,,,,13.003003,,,,,,20.0038967,,,,
,46647428.685,20.00227925,2419.22619628906,4.92730805410288E-5,2.57292193369705E-7,1,0.999253354069792,40.0298881530762,1.99498051530236,16.1200007982552,0.000533942130938468,7.10047831283244E-5,0.25,-2.08251539240866E-6,4.89869203016299E-5,-1.95467961938458E-6,20.0022659,20.0022926,2386.80126953125,2451.65112304687,52.6153237720248,18.7479060483899,5.3381476,0,0,0,4449,19.98975,2419.22619628906,,,,,,,,,,,,,,,,,13.003003,,,,,,20.00227925,,,,
,46647478.17,20.00448325,-55.1997470855713,4.37116873712795E-5,3.30895510776465E-7,1,0.999253354069792,40.0298881530762,1.99514529565059,16.1200007982552,0.000474143234452069,6.04697282161637E-5,0.25,-2.07884582739196E-6,4.34569860536546E-5,-1.96722574396475E-6,20.0042286,20.0047379,-82.5591278076172,-27.8403663635254,52.9154691234094,18.7491089424097,5.39201115,0,0,0,4449,19.98785,-55.1997470855713,,,,,,,,,,,,,,,,,13.753754,,,,,,20.00448325,,,,
,46647527.24,20.00141525,-2501.71252441406,3.64148906945254E-5,2.68854677894586E-7,1,0.999253354069792,40.0298881530762,1.99493819940251,16.1200007982552,0.000395548543904693,4.70837483110327E-5,0.25,-2.04036868006094E-6,3.62046319404245E-5,-1.94282145837162E-6,20.0013046,20.0015259,-2531.6416015625,-2471.78344726562,52.8951467819094,18.7488952407692,5.3381476,0,0,0,4449,19.9914,-2501.71252441406,,,,,,,,,,,,,,,,,13.753754,,,,,,20.00141525,,,,
,46647576.63,19.99883365,-4971.89770507812,4.08060705100977E-5,2.46766962413949E-7,1,0.999253354069792,40.0298881530762,1.99493923901723,16.1200007982552,0.000442898865837193,5.48513016682944E-5,0.25,-2.09637371350914E-6,4.05718136761871E-5,-1.98427186929827E-6,19.998703,19.9989643,-5001.7548828125,-4942.04052734375,52.6919233669094,18.7460324092456,5.41934915,0,0,0,4449,19.98755,-4971.89770507812,,,,,,,,,,,,,,,,,13.753754,,,,,,19.99883365,,,,
,46647626.86,19.9992361,-7483.30883789063,4.42165337193731E-5,3.35539615585055E-7,1,0.999253354069792,40.0298881530762,1.99505206078656,16.1200007982552,0.000480716504689819,5.51877001486371E-5,0.25,-2.67193960757903E-6,4.39660045701887E-5,-2.54339834962817E-6,19.9991913,19.9992809,-7510.75537109375,-7455.8623046875,53.1413597654671,18.7468868852747,5.44614645,0,0,0,4449,19.99055,-7483.30883789063,,,,,,,,,,,,,,,,,13.753754,,,,,,19.9992361,,,,
,46647676.89,19.99726865,-9982.46826171875,4.84076250696309E-5,3.08887014965438E-7,1,0.999253354069792,40.0298881530762,1.99495485523818,16.1200007982552,0.000525832944727093,6.29974803295759E-5,0.25,-2.69116312248654E-6,4.81355279598379E-5,-2.5463623861398E-6,19.9971542,19.9973831,-10009.9482421875,-9954.98828125,53.462609086871,18.7453830639658,5.44614645,0,0,0,4449,19.98905,-9982.46826171875,,,,,,,,,,,,,,,,,13.003003,,,,,,19.99726865,,,,
,46647726.935,19.999341,-12486.3466796875,5.0334944276329E-5,3.17320632860313E-7,1,0.999253354069792,40.0298881530762,1.99488421740032,16.1200007982552,0.000546566188429137,6.6745980250729E-5,0.25,-2.6892717141769E-6,5.00548599224571E-5,-2.53345071238438E-6,19.9993324,19.9993496,-12513.9736328125,-12458.7197265625,53.0616336565056,18.7490997110707,5.5005507,0,0,0,4449,19.99175,-12486.3466796875,,,,,,,,,,,,,,,,,13.003003,,,,,,19.999341,,,,
,46647777.065,20.003458,-14987.9140625,5.08395388106859E-5,3.43018435990524E-7,1,0.999253354069792,40.0298881530762,1.99487781586903,16.1200007982552,0.000550584078984206,7.58855460525487E-5,0.25,-1.93552256358472E-6,5.05577797048345E-5,-1.77647019591855E-6,20.003458,20.003458,-14992.791015625,-14983.037109375,53.0757029698518,18.7476525586104,5.5005507,0,0,0,4449,19.9943,-14987.9140625,,,,,,,,,,,,,,,,,13.753754,,,,,,20.003458,,,,
,46647830.18,19.9892149,-17643.44921875,4.78557554265641E-5,2.97767084434617E-7,1,0.999253354069792,40.0298881530762,1.99507723901296,16.1200007982552,0.000518959025597218,6.80460685865536E-5,0.25,-2.1441046643811E-6,4.75950493122219E-5,-1.98638273679274E-6,19.9889545,19.9894753,-17675.873046875,-17611.025390625,52.8443409281594,18.7474621547844,5.44614645,0,0,0,4449,19.97965,-17643.44921875,,,,,,,,,,,,,,,,,13.753754,,,,,,19.9892149,,,,
,46647885.69,19.99615095,-20417.09765625,4.21228917360777E-5,3.87927058381693E-7,1,0.999253354069792,40.0298881530762,1.99504465087722,16.1200007982552,0.000457863245451609,5.40202673757795E-5,0.25,-2.43956163992118E-6,4.18987028034111E-5,-2.29191654170523E-6,19.9961166,19.9961853,-20449.462890625,-20384.732421875,53.536863796198,18.7509252322631,5.5005507,0,0,0,4449,19.9901,-20417.09765625,,,,,,,,,,,,,,,,,13.003003,,,,,,19.99615095,,,,
,46647942,19.99644945,-23233.06640625,3.59694842780052E-5,3.61854188755131E-7,1,0.999253354069792,40.0298881530762,1.99496296889185,16.1200007982552,0.000391033176383746,4.59376139560907E-5,0.25,-2.10638608850363E-6,3.57814341945505E-5,-1.97520094304857E-6,19.9964237,19.9964752,-23263.0859375,-23203.046875,52.8521572133517,18.7512678491606,5.3917422,0,0,0,4449,19.99105,-23233.06640625,,,,,,,,,,,,,,,,,13.753754,,,,,,19.99644945,,,,
,46647998.095,19.9982586,-26036.68359375,3.0230997928327E-5,4.05024911505846E-7,1,0.999253354069792,40.0298881530762,1.99495975735325,16.1200007982552,0.000329885221980062,3.18210394352804E-5,0.25,-2.40585913817757E-6,3.00780870872386E-5,-2.2880462351842E-6,19.998188,19.9983292,-26066.548828125,-26006.818359375,52.7083375658133,18.749164145322,5.3917422,0,0,0,4449,19.9942,-26036.68359375,,,,,,,,,,,,,,,,,13.753754,,,,,,19.9982586,,,,
,46648056.715,19.99923325,-28965.298828125,2.83684237277381E-5,3.38984241237302E-7,1,0.999253354069792,40.0298881530762,1.99515137031311,16.1200007982552,0.00031009793563074,2.71909302210452E-5,0.25,-2.51050768530872E-6,2.82289614882294E-5,-2.39462667369593E-6,19.9988747,19.9995918,-28995.353515625,-28935.244140625,53.2273389025825,18.7525728109468,5.44614645,0,0,0,4449,19.9947,-28965.298828125,,,,,,,,,,,,,,,,,12.627627,,,,,,19.99923325,,,,
,46648112.44,19.99795815,-31751.48828125,2.8997335382192E-5,4.0391310329487E-7,1,0.999253354069792,40.0298881530762,1.99511949495569,16.1200007982552,0.000315916471055273,3.39118691510237E-5,0.25,-2.00207481036298E-6,2.88558627389686E-5,-1.88269517117142E-6,19.9977722,19.9981441,-31784.00390625,-31718.97265625,53.1483944221402,18.7485343523563,5.3917422,0,0,0,4449,19.9961,-31751.48828125,,,,,,,,,,,,,,,,,13.753754,,,,,,19.99795815,,,,
,46648167.8,20.00044535,-34517.080078125,3.16898715230591E-5,4.67334673873304E-7,1,0.999253354069792,40.0298881530762,1.99503337141885,16.1200007982552,0.00034570856027232,3.46287896826311E-5,0.25,-2.41859102289808E-6,3.15396933412403E-5,-2.28280598655789E-6,20.0004272,20.0004635,-34542.0703125,-34492.08984375,53.4610458298326,18.7509827753542,5.44614645,0,0,0,4449,19.99835,-34517.080078125,,,,,,,,,,,,,,,,,13.003003,,,,,,20.00044535,,,,
,46648218.235,19.9983082,-37038.265625,3.52920432566697E-5,4.60904025903937E-7,1,0.999253354069792,40.0298881530762,1.99485000370219,16.1200007982552,0.000384967744062737,3.88200071021768E-5,0.25,-2.67431876061477E-6,3.51284643552456E-5,-2.51906348485915E-6,19.9982624,19.998354,-37065.87890625,-37010.65234375,52.829489986294,18.7514454679491,5.5281634,0,0,0,4449,19.9971,-37038.265625,,,,,,,,,,,,,,,,,13.753754,,,,,,19.9983082,,,,
,46648270.03,20.0011311,-39626.6484375,4.00223804336619E-5,3.42305175083002E-7,1,0.999253354069792,40.0298881530762,1.99497135530816,16.1200007982552,0.000434201993437369,5.77257692230744E-5,0.25,-1.76559452793169E-6,3.98361198860203E-5,-1.59093011865449E-6,20.0011311,20.0011311,-39629.12890625,-39624.16796875,53.0819559980056,18.75243527946,5.47375915,0,0,0,4449,19.99995,-39626.6484375,,,,,,,,,,,,,,,,,13.003003,,,,,,20.0011311,,,,
,46648321.755,19.99881175,-42212.666015625,4.52693737464058E-5,5.22919161747209E-7,1,0.999253354069792,40.0298881530762,1.99487726612104,16.1200007982552,0.00049150841918304,6.33438428054296E-5,0.25,-2.1842235011231E-6,4.50645540639257E-5,-1.98039452414916E-6,19.9987965,19.998827,-42217.68359375,-42207.6484375,53.2117063321979,18.7526548913981,5.44614645,0,0,0,4449,19.99545,-42212.666015625,,,,,,,,,,,,,,,,,13.003003,,,,,,19.99881175,,,,
,46648374.02,19.9976969,-44824.1796875,5.06834366576245E-5,5.41413614254957E-7,1,0.999253354069792,40.0298881530762,1.99501662525248,16.1200007982552,0.000547662680656779,8.62363906923502E-5,0.25,-1.03024907455133E-6,5.04538202222599E-5,-8.02645523566826E-7,19.9975491,19.9978447,-44826.578125,-44821.78125,52.3941229010825,18.7514298608542,5.5557761,0,0,0,4449,19.99765,-44824.1796875,,,,,,,,,,,,,,,,,13.753754,,,,,,19.9976969,,,,
,46648425.055,19.99860005,-47375.083984375,5.50041714724438E-5,7.44806940658296E-7,1,0.999253354069792,40.0298881530762,1.99503094448089,16.1200007982552,0.000594338875257366,9.40703128707877E-5,0.25,-1.080779773708E-6,5.47610738417313E-5,-8.2763176042409E-7,19.9984837,19.9987164,-47405.07421875,-47345.09375,53.2851794130056,18.7471559784673,5.4458747,0,0,0,4449,19.9974,-47375.083984375,,,,,,,,,,,,,,,,,13.003003,,,,,,19.99860005,,,,
,46648476.34,19.9993496,-49939.037109375,6.26215873083478E-5,5.76996460649823E-7,1,0.999253354069792,40.0298881530762,1.99512986493685,16.1200007982552,0.00067674932585841,0.000107171851499232,0.25,-1.23242308666584E-6,6.23521780885851E-5,-9.37159955873817E-7,19.9992008,19.9994984,-49969.0390625,-49909.03515625,53.3172261822941,18.7552047890559,5.5008254,0,0,0,4449,19.99865,-49939.037109375,,,,,,,,,,,,,,,,,13.753754,,,,,,19.9993496,,,,
,46648527.79,20.00157265,-52509.544921875,6.89734950341343E-5,6.97576836095023E-7,1,0.999253354069792,40.0298881530762,1.99506840414052,16.1200007982552,0.000749774383149956,9.39292039789683E-5,0.25,-3.60514497348897E-6,6.86957132264144E-5,-3.2627519337137E-6,20.0015488,20.0015965,-52542.046875,-52477.04296875,53.0186440879479,18.752998503193,5.52871515,0,0,0,4449,19.9976,-52509.544921875,,,,,,,,,,,,,,,,,14.129129,,,,,,20.00157265,,,,
,46648579.1,20.0009165,-55073.353515625,7.43027007475513E-5,5.69348736956342E-7,1,0.999253354069792,40.0298881530762,1.99501774315146,16.1200007982552,0.000804512995879828,0.000119515034922583,0.25,-2.19106128101718E-6,7.40046213700963E-5,-1.82163764280895E-6,20.0008736,20.0009594,-55100.86328125,-55045.84375,52.5848402597748,18.752536163375,5.58366585,0,0,0,4449,19.998,-55073.353515625,,,,,,,,,,,,,,,,,13.378378,,,,,,20.0009165,,,,
,46648631.755,20.0084324,-57703.935546875,8.17520616104319E-5,7.33147334026913E-7,1,0.999253354069792,40.0298881530762,1.99508430582337,16.1200007982552,0.000883599043403784,0.000141103992320379,0.25,-1.52973098647051E-6,8.14303025561814E-5,-1.11828275840702E-6,20.0084324,20.0084324,-57739.0703125,-57668.80078125,52.964711720121,18.750712170361,5.6115556,0,0,0,4449,19.99985,-57703.935546875,,,,,,,,,,,,,,,,,13.753754,,,,,,20.0084324,,,,
,46648703.86,19.990139,-59576.95703125,8.61665072428133E-5,7.87233181187938E-7,1,0.999253354069792,40.0298881530762,1.99506684710231,16.1200007982552,0.000930612756999737,0.00015308253106192,0.25,-1.21529101878403E-6,8.5833355798138E-5,-7.76897975769746E-7,19.9900093,19.9902687,-59604.09765625,-59549.81640625,53.6455101603711,18.7537187035638,5.55605315,0,0,0,4449,19.9929,-59576.95703125,,,,,,,,,,,,,,,,,13.753754,,,,,,19.990139,,,,
,46648761.845,19.99451635,-56686.84375,7.85513354973107E-5,5.75840308351963E-7,1,0.999253354069792,40.0298881530762,1.99514023753786,16.1200007982552,0.00084928132047052,0.000133917010382347,0.25,-1.62062709341738E-6,7.82389993591938E-5,-1.22785583390278E-6,19.9944725,19.9945602,-56716.8515625,-56656.8359375,52.7497638773325,18.7498632247101,5.5008254,0,0,0,4449,19.99585,-56686.84375,,,,,,,,,,,,,,,,,13.753754,,,,,,19.99451635,,,,
,46648818.835,19.9984665,-53838.818359375,7.21759197278482E-5,6.91249727745815E-7,1,0.999253354069792,40.0298881530762,1.99498332641433,16.1200007982552,0.000780651006087961,0.00012041719609757,0.25,-1.72237918972024E-6,7.18801095881957E-5,-1.36886074788285E-6,19.9984665,19.9984665,-53843.890625,-53833.74609375,52.7607066766017,18.7519569951244,5.5008254,0,0,0,4449,20.0013,-53838.818359375,,,,,,,,,,,,,,,,,13.753754,,,,,,19.9984665,,,,
,46648876.85,19.9986048,-50937.845703125,6.55214685074558E-5,5.27189052325165E-7,1,0.999253354069792,40.0298881530762,1.99515946579958,16.1200007982552,0.000709961220149454,0.000101898348042138,0.25,-2.24349021605037E-6,6.52470836692403E-5,-1.92758758669725E-6,19.9984913,19.9987183,-50970.19921875,-50905.4921875,53.300030354871,18.751447258244,5.5557761,0,0,0,4449,19.99815,-50937.845703125,,,,,,,,,,,,,,,,,13.753754,,,,,,19.9986048,,,,
,46648933.68,20.000556,-48099.328125,5.65642494215555E-5,6.07258542263944E-7,1,0.999253354069792,40.0298881530762,1.99503451137556,16.1200007982552,0.000612786011213941,8.79543115464457E-5,0.25,-1.9293656784249E-6,5.63198313812213E-5,-1.66356279064742E-6,20.000227,20.000885,-48127.04296875,-48071.61328125,53.2109247036787,18.7543485607235,5.5557761,0,0,0,4449,19.99615,-48099.328125,,,,,,,,,,,,,,,,,13.753754,,,,,,20.000556,,,,
,46648986.585,19.9991255,-45453.517578125,5.16889217395108E-5,5.89348736231895E-7,1,0.999253354069792,40.0298881530762,1.99508462264488,16.1200007982552,0.000559483486426885,8.27824134535683E-5,0.25,-1.53237385989253E-6,5.14583252798161E-5,-1.29656072147264E-6,19.999012,19.999239,-45483.45703125,-45423.578125,53.0319317727748,18.7517720100352,5.5008254,0,0,0,4449,20.0044,-45453.517578125,,,,,,,,,,,,,,,,,13.753754,,,,,,19.9991255,,,,
,46649037.455,19.9992981,-42911.92578125,4.4523779162902E-5,4.15392605305824E-7,1,0.999253354069792,40.0298881530762,1.99509478869772,16.1200007982552,0.000483511570654096,6.21208092985916E-5,0.25,-2.16720167308752E-6,4.43237976927481E-5,-1.96522795806961E-6,19.9990635,19.9995327,-42939.515625,-42884.3359375,53.4665172294672,18.7511197413512,5.5557761,0,0,0,4449,20.00185,-42911.92578125,,,,,,,,,,,,,,,,,13.003003,,,,,,19.9992981,,,,
,46649088.61,20.0006628,-40356.365234375,3.76414873672078E-5,4.44512115132022E-7,1,0.999253354069792,40.0298881530762,1.99508076843273,16.1200007982552,0.000408827252132607,5.19301425421007E-5,0.25,-1.88168141769131E-6,3.74684109550971E-5,-1.71506898666645E-6,20.0004692,20.0008564,-40381.328125,-40331.40234375,52.5051141508132,18.7511371200171,5.5557761,0,0,0,4449,20.0042,-40356.365234375,,,,,,,,,,,,,,,,,13.753754,,,,,,20.0006628,,,,
,46649139.45,19.99964045,-37814.703125,3.3050797650583E-5,5.43291597705536E-7,1,0.999253354069792,40.0298881530762,1.99504214281408,16.1200007982552,0.000360576954158875,3.62919756608183E-5,0.25,-2.51199786133562E-6,3.28987403213494E-5,-2.36538643361144E-6,19.9995613,19.9997196,-37842.23046875,-37787.17578125,53.4954374846787,18.7517035120853,5.4732127,0,0,0,4449,19.99715,-37814.703125,,,,,,,,,,,,,,,,,13.753754,,,,,,19.99964045,,,,
,46649190.94,20.0012693,-35241.482421875,2.60579637164218E-5,5.85894229130756E-7,1,0.999253354069792,40.0298881530762,1.99505867554407,16.1200007982552,0.000284340610619505,2.81433781557154E-5,0.25,-2.02058881291708E-6,2.59353876415882E-5,-1.90789278437456E-6,20.0011787,20.0013599,-35273.93359375,-35209.03125,53.5024721413518,18.7504396127234,5.5005507,0,0,0,4449,20.0014,-35241.482421875,,,,,,,,,,,,,,,,,13.753754,,,,,,20.0012693,,,,
,46649241.79,20.0014906,-32700.7607421875,2.00807157976511E-5,4.3179325786315E-7,1,0.999253354069792,40.0298881530762,1.99513157031895,16.1200007982552,0.000221206393173689,9.84843501403008E-6,0.25,-2.65440228713263E-6,1.99883358219034E-5,-2.56434933830886E-6,20.0013275,20.0016537,-32730.7265625,-32670.794921875,53.4547928016787,18.7509618072419,5.5005507,0,0,0,4449,20.00065,-32700.7607421875,,,,,,,,,,,,,,,,,13.753754,,,,,,20.0014906,,,,
,46649291.63,20.00245955,-30209.2119140625,1.44432768442575E-5,5.27875291883601E-7,1,0.999253354069792,40.0298881530762,1.99507456503288,16.1200007982552,0.000159357866901674,5.54000823635867E-6,0.25,-2.05070311739806E-6,1.4375823295793E-5,-1.98683715765879E-6,20.0024109,20.0025082,-30241.736328125,-30176.6875,52.4472736403902,18.7493555523869,5.55605315,0,0,0,4449,19.99845,-30209.2119140625,,,,,,,,,,,,,,,,,13.753754,,,,,,20.00245955,,,,
,46649340.69,20.00373175,-27758.0615234375,8.58316494068288E-6,3.32565403421687E-7,1,0.999253354069792,40.0298881530762,1.99496128246311,16.1200007982552,9.7116945002754E-5,-1.04020792463774E-5,0.25,-2.49015172774888E-6,8.54673256622319E-6,-2.44645161553288E-6,20.0036507,20.0038128,-27783.009765625,-27733.11328125,53.3164445537749,18.7522008556574,5.55605315,0,0,0,4449,19.99815,-27758.0615234375,,,,,,,,,,,,,,,,,13.003003,,,,,,20.00373175,,,,
,46649392.22,20.00268845,-25181.673828125,1.85706080369959E-6,2.27452264288961E-7,1,0.999253354069792,40.0298881530762,1.99496607754842,16.1200007982552,2.42746256696403E-5,-2.06584396092997E-5,0.25,-2.24928923837392E-6,1.85481632337047E-6,-2.23086068798576E-6,20.0024815,20.0028954,-25209.03125,-25154.31640625,53.3484913230633,18.7486017755941,5.6115556,0,0,0,4449,19.9973,-25181.673828125,,,,,,,,,,,,,,,,,13.753754,,,,,,20.00268845,,,,
,46649441.77,20.00125885,-22705.70703125,-3.20645498130953E-6,4.09760445021684E-7,1,0.999253354069792,40.0298881530762,1.99481786715225,16.1200007982552,-3.15790992002469E-5,-2.25795163278625E-5,0.25,-1.53044246784647E-6,-3.183960198379E-6,-1.53270882705484E-6,20.0012283,20.0012894,-22730.798828125,-22680.615234375,53.2523510151979,18.7506650173529,5.58366585,0,0,0,4449,19.99795,-22705.70703125,,,,,,,,,,,,,,,,,13.003003,,,,,,20.00125885,,,,
,46649491.36,20.00201895,-20229.2822265625,-9.84975023519756E-6,3.81096212832526E-7,1,0.999253354069792,40.0298881530762,1.99498896444221,16.1200007982552,-0.000101436581661437,-4.43864963878327E-5,0.25,-2.38113152230864E-6,-9.78789331305483E-6,-2.39929860631747E-6,20.001833,20.0022049,-20251.849609375,-20206.71484375,52.6176686575825,18.7496115625981,5.58366585,0,0,0,4449,20.00045,-20229.2822265625,,,,,,,,,,,,,,,,,13.003003,,,,,,20.00201895,,,,
,46649545.165,19.98676685,-17538.65625,-1.54658071493834E-5,3.36411423180414E-7,1,0.999253354069792,40.0298881530762,1.99499916135638,16.1200007982552,-0.000163142302316504,-4.77918173289724E-5,0.25,-1.70543123489144E-6,-1.53742158844198E-5,-1.7429273256511E-6,19.9864941,19.9870396,-17573.830078125,-17503.482421875,52.9639300916018,18.7504955793039,5.6678953,0,0,0,4449,19.9869,-17538.65625,,,,,,,,,,,,,,,,,13.003003,,,,,,19.98676685,,,,
,46649601.93,19.99551395,-14702.4384765625,-2.17024673020118E-5,2.93679788987803E-7,1,0.999253354069792,40.0298881530762,1.99491694609843,16.1200007982552,-0.000229461349698391,-6.39276708520922E-5,0.25,-2.10532334777978E-6,-2.15735249163806E-5,-2.15632625538953E-6,19.9954758,19.9955521,-14734.9541015625,-14669.9228515625,52.687233595794,18.749727945758,5.5005507,0,0,0,4449,19.99485,-14702.4384765625,,,,,,,,,,,,,,,,,13.003003,,,,,,19.99551395,,,,
,46649659.52,19.9955349,-11823.7084960938,-2.84632596536569E-5,2.64106145928343E-7,1,0.999253354069792,40.0298881530762,1.99489400819258,16.1200007982552,-0.000302269580920058,-7.62180372683217E-5,0.25,-2.05695760405185E-6,-2.82945294877083E-5,-2.12369133624777E-6,19.9955063,19.9955635,-11856.029296875,-11791.3876953125,53.0327134012941,18.7467643489259,5.55605315,0,0,0,4449,19.99745,-11823.7084960938,,,,,,,,,,,,,,,,,13.753754,,,,,,19.9955349,,,,
,46649717.305,20.00118825,-8932.3349609375,-3.50656327785551E-5,3.13085740013579E-7,1,0.999253354069792,40.0298881530762,1.99488550958997,16.1200007982552,-0.000373125572240681,-8.95723973492837E-5,0.25,-2.13732678678379E-6,-3.48569534436088E-5,-2.21688588559321E-6,20.0011482,20.0012283,-8962.37890625,-8902.291015625,52.8537204703902,18.7528836593239,5.6115556,0,0,0,4449,20.00005,-8932.3349609375,,,,,,,,,,,,,,,,,13.753754,,,,,,20.00118825,,,,
,46649775.59,20.00028035,-6021.17358398438,-4.14463092901073E-5,2.8501424707814E-7,1,0.999253354069792,40.0298881530762,1.99498980475952,16.1200007982552,-0.000441654330411359,-0.000102281007034265,0.25,-2.19793357425741E-6,-4.11984686542741E-5,-2.28832342363239E-6,20.000185,20.0003757,-6023.791015625,-6018.55615234375,53.0217706020248,18.7479890398558,5.55605315,0,0,0,4449,19.9996,-6021.17358398438,,,,,,,,,,,,,,,,,13.753754,,,,,,20.00028035,,,,
,46649831.305,19.99820425,-3236.87438964844,-4.64908845728593E-5,3.27004837065329E-7,1,0.999253354069792,40.0298881530762,1.9949707981511,16.1200007982552,-0.000495781701678933,-0.000112472207577223,0.25,-2.26147952099038E-6,-4.62114695923938E-5,-2.35860420195367E-6,19.9981575,19.998251,-3269.46411132812,-3204.28466796875,53.0811743694864,18.7491396699215,5.6115556,0,0,0,4449,19.99485,-3236.87438964844,,,,,,,,,,,,,,,,,13.003003,,,,,,19.99820425,,,,
,46649888.765,20.0053358,-362.484680175781,-4.7018565282437E-5,2.45212721111263E-7,1,0.999253354069792,40.0298881530762,1.99491550457543,16.1200007982552,-0.000501510072690165,-0.000112998745174233,0.25,-2.22264945786596E-6,-4.67345804905769E-5,-2.31659972628971E-6,20.0052452,20.0054264,-389.7314453125,-335.237915039063,53.3961706627364,18.7458136122156,5.55605315,0,0,0,4449,20.00065,-362.484680175781,,,,,,,,,,,,,,,,,13.753754,,,,,,20.0053358,,,,
,46649940.18,20.0028248,2202.14794921875,-3.55243813626732E-5,2.27689927018711E-7,1,0.999253354069792,40.0298881530762,1.99500239840525,16.1200007982552,-0.000377359503333164,-9.431319052291E-5,0.25,-2.50768453958938E-6,-3.53085821727615E-5,-2.57589234987719E-6,20.0028248,20.0028248,2199.67553710938,2204.62036132813,53.1421413939864,18.7476059641793,5.63972545,0,0,0,4449,19.99865,2202.14794921875,,,,,,,,,,,,,,,,,13.753754,,,,,,20.0028248,,,,
,46649988.835,19.9994869,4637.01806640625,-3.92543931910555E-5,3.05983911358371E-7,1,0.999253354069792,40.0298881530762,1.99498172450001,16.1200007982552,-0.000417654114861693,-0.000100456327275896,0.25,-2.41749018644134E-6,-3.90180139913113E-5,-2.49876918778785E-6,19.9994335,19.9995403,4604.39501953125,4669.64111328125,53.218740988871,18.7483172772722,5.63972545,0,0,0,4449,19.9981,4637.01806640625,,,,,,,,,,,,,,,,,13.753754,,,,,,19.9994869,,,,
,46650038.21,19.99943635,7101.07592773437,-4.32751805287633E-5,2.22385232710755E-7,1,0.999253354069792,40.0298881530762,1.99498869591659,16.1200007982552,-0.000460884255700507,-0.000108307113619996,0.25,-2.43331734493633E-6,-4.30168121007749E-5,-2.52899024427142E-6,19.9992313,19.9996414,7073.513671875,7128.63818359375,53.3930441486595,18.748896496931,5.55605315,0,0,0,4449,19.99805,7101.07592773437,,,,,,,,,,,,,,,,,13.003003,,,,,,19.99943635,,,,
,46650090.225,19.9966602,9702.962890625,-4.71566120755239E-5,2.90317539804667E-7,1,0.999253354069792,40.0298881530762,1.99517493232049,16.1200007982552,-0.000502456822299982,-0.000117088511008205,0.25,-2.5577020513497E-6,-4.6877478356927E-5,-2.66826966231859E-6,19.9966602,19.9966602,9697.8095703125,9708.1162109375,52.9725280053133,18.7472601082054,5.5557761,0,0,0,4449,20.0053,9702.962890625,,,,,,,,,,,,,,,,,13.003003,,,,,,19.9966602,,,,
,46650140.64,19.99948695,12224.1552734375,-5.00925287971872E-5,3.062043550508E-7,1,0.999253354069792,40.0298881530762,1.99495360803198,16.1200007982552,-0.000534283440556833,-0.000121125836315803,0.25,-2.40916664718434E-6,-4.97993350616793E-5,-2.53454417587621E-6,19.9994698,19.9995041,12191.6572265625,12256.6533203125,53.1804411914287,18.7466624627799,5.6118357,0,0,0,4449,20.00065,12224.1552734375,,,,,,,,,,,,,,,,,13.003003,,,,,,19.99948695,,,,
,46650190.945,19.99863145,14738.4360351562,-4.98570990921908E-5,4.1088874348101E-7,1,0.999253354069792,40.0298881530762,1.99499754488704,16.1200007982552,-0.000532338734616193,-0.000117590539958407,0.25,-2.11510817106101E-6,-4.95688148176842E-5,-2.24778255420074E-6,19.9985294,19.9987335,14715.8916015625,14760.98046875,52.893583524871,18.7469609111125,5.5557761,0,0,0,4449,20.00195,14738.4360351562,,,,,,,,,,,,,,,,,13.753754,,,,,,19.99863145,,,,
,46650239.945,19.9998226,17187.2421875,-4.77737543619288E-5,4.28881754886058E-7,1,0.999253354069792,40.0298881530762,1.99505506930634,16.1200007982552,-0.000508622732352543,-0.000121250100640162,0.25,-2.81682641454075E-6,-4.74978895672505E-5,-2.945493280539E-6,19.9997768,19.9998684,17164.81640625,17209.66796875,52.7567985340056,18.744552783471,5.6118357,0,0,0,4449,19.9989,17187.2421875,,,,,,,,,,,,,,,,,13.753754,,,,,,19.9998226,,,,
,46650291.28,19.9994888,19753.138671875,-4.33643763383756E-5,4.60447354733211E-7,1,0.999253354069792,40.0298881530762,1.99508707226215,16.1200007982552,-0.000461475241373367,-0.000111420113016295,0.25,-2.67687511335443E-6,-4.31163214153938E-5,-2.79880049116671E-6,19.9994068,19.9995708,19723.11328125,19783.1640625,52.8779509544864,18.7465365955965,5.6678953,0,0,0,4449,19.9993,19753.138671875,,,,,,,,,,,,,,,,,13.003003,,,,,,19.9994888,,,,
,46650340.99,20.0005436,22236.546875,-3.77235318045004E-5,3.43599776124463E-7,1,0.999253354069792,40.0298881530762,1.99502758899621,16.1200007982552,-0.000400521328143633,-0.000102235594890571,0.25,-2.81695275410124E-6,-3.75085827830837E-5,-2.92528571661307E-6,20.0004082,20.000679,22211.583984375,22261.509765625,52.7911901888517,18.7445602960873,5.6681781,0,0,0,4449,19.99855,22236.546875,,,,,,,,,,,,,,,,,13.003003,,,,,,20.0005436,,,,
,46650392.88,20.0063353,24830.67578125,-3.28233678641355E-5,4.05238601173891E-7,1,0.999253354069792,40.0298881530762,1.99503855236157,16.1200007982552,-0.000348362571028316,-8.98585426985935E-5,0.25,-2.52994401259496E-6,-3.26383777167311E-5,-2.62832429872389E-6,20.0062447,20.0064259,24800.798828125,24860.552734375,53.1515209362172,18.7462231680149,5.7248006,0,0,0,4449,20.00575,24830.67578125,,,,,,,,,,,,,,,,,13.753754,,,,,,20.0063353,,,,
,46650447.09,19.99099445,27539.5625,-2.81317980114408E-5,4.01629232291002E-7,1,0.999253354069792,40.0298881530762,1.99491420129237,16.1200007982552,-0.000298168933263611,-7.93077065410733E-5,0.25,-2.37737875958308E-6,-2.79746864895827E-5,-2.46465379163853E-6,19.9906464,19.9913425,27504.583984375,27574.541015625,53.0803927409672,18.7444993971117,5.75353885,0,0,0,4449,19.9916,27539.5625,,,,,,,,,,,,,,,,,13.003003,,,,,,19.99099445,,,,
,46650504.79,19.991848,30422.833984375,-2.85457376516549E-5,5.86174165425269E-7,1,0.999253354069792,40.0298881530762,1.99488547895163,16.1200007982552,-0.000301028117852322,-8.92096553201436E-5,0.25,-3.21931580085972E-6,-2.83858061501334E-5,-3.30810115093737E-6,19.9918003,19.9918957,30388.021484375,30457.646484375,52.4105370999863,18.7453180687984,5.63972545,0,0,0,4449,19.9933,30422.833984375,,,,,,,,,,,,,,,,,13.753754,,,,,,19.991848,,,,
,46650561.235,19.9958839,33243.916015625,-2.9770196014451E-5,3.83814032766581E-7,1,0.999253354069792,40.0298881530762,1.99501592836663,16.1200007982552,-0.000316605194382359,-7.83245663368501E-5,0.25,-1.98489573321961E-6,-2.96112283823443E-5,-2.089037002742E-6,19.9958839,19.9958839,33241.39453125,33246.4375,53.0733580842941,18.7440954786376,5.6678953,0,0,0,4449,20.0055,33243.916015625,,,,,,,,,,,,,,,,,13.003003,,,,,,19.9958839,,,,
,46650618.41,19.9987049,36102.4609375,-3.51193869234501E-5,4.09732883020087E-7,1,0.999253354069792,40.0298881530762,1.99512299713504,16.1200007982552,-0.00037194854059755,-0.000101410976096679,0.25,-3.17256086192807E-6,-3.49320019505497E-5,-3.29651163409005E-6,19.9987049,19.9987049,36099.8828125,36105.0390625,52.7607066766017,18.7462316450846,5.63972545,0,0,0,4449,20.0026,36102.4609375,,,,,,,,,,,,,,,,,13.753754,,,,,,19.9987049,,,,
,46650675.695,19.9991484,38963.154296875,-4.00799706635651E-5,5.70712163033123E-7,1,0.999253354069792,40.0298881530762,1.99507988539815,16.1200007982552,-0.000425032320018284,-0.000112868768051685,0.25,-3.34787176616987E-6,-3.98712482164255E-5,-3.49667367983169E-6,19.9991074,19.9991894,38933.1796875,38993.12890625,53.2539142722364,18.7485914617064,5.6118357,0,0,0,4449,20.0084,38963.154296875,,,,,,,,,,,,,,,,,13.003003,,,,,,19.9991484,,,,
,46650731.285,19.99908255,41742.248046875,-4.48866908377701E-5,5.43167414427485E-7,1,0.999253354069792,40.0298881530762,1.99490648711098,16.1200007982552,-0.000477327832962586,-0.000119046292222408,0.25,-3.05950515262478E-6,-4.46604659146378E-5,-3.23584301585004E-6,19.9988689,19.9992962,41712.19921875,41772.296875,52.6989580235825,18.7447734398117,5.5557761,0,0,0,4449,20.0092,41742.248046875,,,,,,,,,,,,,,,,,13.003003,,,,,,19.99908255,,,,
,46650784.66,19.9990454,44413.33203125,-4.98783713885873E-5,5.00267773375451E-7,1,0.999253354069792,40.0298881530762,1.99492369772284,16.1200007982552,-0.000531579492465465,-0.000126077810211968,0.25,-2.81549249294143E-6,-4.96347433774086E-5,-3.02079511283709E-6,19.9988747,19.9992161,44381.00390625,44445.66015625,53.1147843958133,18.7452818067562,5.584223,0,0,0,4449,20.00475,44413.33203125,,,,,,,,,,,,,,,,,13.003003,,,,,,19.9990454,,,,
,46650835.39,19.9997902,46947.55078125,-5.6296420801422E-5,6.08161734255374E-7,1,0.999253354069792,40.0298881530762,1.99494555492841,16.1200007982552,-0.000601211148919977,-0.00013580515071329,0.25,-2.56636868725178E-6,-5.60300322639287E-5,-2.80777827685731E-6,19.9997425,19.9998379,46914.9609375,46980.140625,52.9350098363902,18.7473339123862,5.5557761,0,0,0,4449,20.00975,46947.55078125,,,,,,,,,,,,,,,,,13.753754,,,,,,19.9997902,,,,
,46650884.65,19.9972563,49409.15234375,-6.09947609373622E-5,5.16618674025514E-7,1,0.999253354069792,40.0298881530762,1.99497509924777,16.1200007982552,-0.000651600197306732,-0.000146397074310854,0.25,-2.70324574787688E-6,-6.07128884243545E-5,-2.97219813324385E-6,19.9971066,19.997406,49379.17578125,49439.12890625,52.9271935511979,18.7447844377458,5.6118357,0,0,0,4449,20.00525,49409.15234375,,,,,,,,,,,,,,,,,13.003003,,,,,,19.9972563,,,,
,46650935.27,19.9998827,51940.158203125,-6.6235006192473E-5,5.9332741348882E-7,1,0.999253354069792,40.0298881530762,1.99493377737791,16.1200007982552,-0.000709709616763856,-0.000147443353016018,0.25,-1.8559842776171E-6,-6.59413493170111E-5,-2.16038119088076E-6,19.9997826,19.9999828,51912.81640625,51967.5,53.3117547826595,18.7461561480863,5.6118357,0,0,0,4449,20.00645,51940.158203125,,,,,,,,,,,,,,,,,12.627627,,,,,,19.9998827,,,,
,46650985.08,20.0008659,54428.78515625,-7.42425352007374E-5,5.94835968018604E-7,1,0.999253354069792,40.0298881530762,1.99498989202957,16.1200007982552,-0.000795598054432274,-0.000165428803813027,0.25,-2.08519392183981E-6,-7.39217665948803E-5,-2.43449660268498E-6,20.0008659,20.0008659,54426.4140625,54431.15625,52.9944136038518,18.7464624530958,5.64028835,0,0,0,4449,20.00425,54428.78515625,,,,,,,,,,,,,,,,,13.003003,,,,,,20.0008659,,,,
,46651033.825,20.00140955,56864.814453125,-7.93827781165566E-5,5.82180028186682E-7,1,0.999253354069792,40.0298881530762,1.99489627851163,16.1200007982552,-0.000848741383944968,-0.000188074989236918,0.25,-3.25954986724342E-6,-7.90437268647688E-5,-3.63712645581996E-6,20.0012913,20.0015278,56834.83203125,56894.796875,52.9225037800825,18.7441118553575,5.64028835,0,0,0,4449,20.00595,56864.814453125,,,,,,,,,,,,,,,,,13.753754,,,,,,20.00140955,,,,
,46651086.01,20.0017796,59474.421875,-8.65523872434764E-5,6.28545306832615E-7,1,0.999253354069792,40.0298881530762,1.99493275580474,16.1200007982552,-0.000926922167523726,-0.000197298116602219,0.25,-2.82152497110834E-6,-8.61969900387002E-5,-3.24561370495884E-6,20.0017796,20.0017796,59469.4375,59479.40625,52.4261696703709,18.7472308940377,5.6115556,0,0,0,4449,20.0038,59474.421875,,,,,,,,,,,,,,,,,13.753754,,,,,,20.0017796,,,,
,46651097.655,20.00161935,59999.615234375,-8.73027400015303E-5,6.2288540710627E-7,1,0.999253354069792,40.0298881530762,1.99493127946276,16.1200007982552,-0.000934570841901291,-0.000201304528520546,0.25,-3.05685895484771E-6,-8.69453910890953E-5,-3.48567851558193E-6,20.001503,20.0017357,59999.609375,59999.62109375,53.4923109706018,18.7453055295971,5.6681781,0,0,0,4417,20.0056,59999.615234375,,,,,,,,,,,,,,,,,13.753754,,,,,,20.00161935,,,,