File: data/monolayers/magneticStructure/ML_Ac_CoFe_C-2/PPMS/data/DD175_23_HYST_100OE_350K.DAT
[Header]
; VSM Data File (default extension .dat)
; Copyright (c) 2003-2013, Quantum Design, Inc. All rights reserved.
TITLE,
FILEOPENTIME,32004685.19,01/06/2019,6:13 pm
BYAPP,VSM,2.0,2.0
INFO,PPMS VSM Option Release 1.4.10 Build 1,APPNAME
INFO,Quantum Design Linear Motor Servo Controller,MOTOR_MODULE_NAME
INFO,3101-100 M1,MOTOR_HW_VERSION
INFO,MMC1014,MOTOR_SERIAL_NUMBER
INFO,SRV No X-over 01.03.11,MOTOR_SOFTWARE_VERSION
INFO,Quantum Design VSM Detection Module,VSM_MODULE_NAME
INFO,3101-150 F0,VSM_HW_VERSION
INFO,VSM707,VSM_SERIAL_NUMBER
INFO,VSM No X-over 01.02.05 May 20 2008 13:51:47,VSM_SOFTWARE_VERSION
INFO,704,PREAMP_SERIAL_NUMBER
INFO,822,COIL_SERIAL_NUMBER
INFO,0,MOMENT_UNITS
INFO,CoFe2O4 Monolayer,SAMPLE_MATERIAL
INFO,from YF45,SAMPLE_COMMENT
INFO,29.98,SAMPLE_MASS
INFO,,SAMPLE_VOLUME
INFO,,SAMPLE_MOLECULAR_WEIGHT
INFO,,SAMPLE_SIZE
INFO,,SAMPLE_SHAPE
DATATYPE,COMMENT,1
DATATYPE,TIME,2
STARTUPAXIS,X,2
STARTUPAXIS,Y1,5
[Data]
Comment,Time Stamp (sec),Temperature (K),Magnetic Field (Oe),Moment (emu),M. Std. Err. (emu),Transport Action,Averaging Time (sec),Frequency (Hz),Peak Amplitude (mm),Center Position (mm),Coil Signal' (mV),Coil Signal" (mV),Range (mV),M. Quad. Signal (emu),M. Raw' (emu),M. Raw" (emu),Min. Temperature (K),Max. Temperature (K),Min. Field (Oe),Max. Field (Oe),Mass (grams),Motor Lag (deg),Pressure (Torr),VSM Status (code),Motor Status (code),Measure Status (code),Measure Count,PPMS Status (code),System Temp. (K),System Field (Oe),Sample Position (deg),Bridge 1 Resistance (ohms),Bridge 1 Excitation (에),Bridge 2 Resistance (ohms),Bridge 2 Excitation (에),Bridge 3 Resistance (ohms),Bridge 3 Excitation (에),Bridge 4 Resistance (ohms),Bridge 4 Excitation (에),Signal 1 Vin (V),Signal 2 Vin (V),Digital Inputs (code),Drive 1 Iout (mA),Drive 1 Ipower (W),Drive 2 Iout (mA),Drive 2 Ipower (W),Pressure (),Map 20 (),Map 21 (),Map 22 (),Map 23 (),Map 24 (),Map 25 (),Map 26 (),Map 27 (),Map 28 (),Map 29 ()
,32004701.45,349.989563,-0.121790185570717,,,2,,,,19.6800002065301,,,,,,,349.989563,349.989563,-0.121790185570717,-0.121790185570717,,,29.363071,,,,-99999999,4369,350.4225,-0.121790185570717,,,,,,,,,,,,,,,,,,,,,,,349.989563,,,,
,32004840.105,349.9712219,4461.41162109375,2.57625468164256E-5,6.1178664016626E-7,1,0.999253354069792,40.0298881530762,1.99646283543158,19.6700002998114,0.000290318538386844,5.27891571481093E-5,0.25,2.16809059613868E-7,2.57167762665223E-5,2.30769829189042E-7,349.9712219,349.9712219,4441.47998046875,4481.34326171875,55.6011447154867,20.5015904064387,29.742722,0,0,0,40,4449,350.4462,4461.41162109375,,,,,,,,,,,,,0,,,,0.00245,,,,,,349.9712219,,,,
,32004932.205,349.9663086,9062.37060546875,1.57612698527649E-5,1.30084170651719E-6,1,0.999253354069792,40.0298881530762,1.99634074169792,19.6700002998114,0.000179076430817884,2.37883004309266E-5,0.25,-6.21083212828086E-7,1.57336903911119E-5,-6.11212414889895E-7,349.9663086,349.9663086,9032.3603515625,9092.380859375,56.0279138869867,20.5056311136614,30.122374,0,0,0,40,4449,350.465,9062.37060546875,,,,,,,,,,,,,0,,,,0.00245,,,,,,349.9663086,,,,
,32005026.55,349.9720459,13777.6362304687,1.48852335762053E-6,1.60769257609267E-6,1,0.999253354069792,40.0298881530762,1.99620390529811,19.6700002998114,1.63907076274179E-5,5.25246803323551E-6,0.25,2.07738145489637E-7,1.4857703149591E-6,2.08197709003433E-7,349.9718628,349.972229,13745.205078125,13810.0673828125,55.9161410087367,20.5051218682281,29.742722,0,0,0,40,4449,350.49545,13777.6362304687,,,,,,,,,,,,,0,,,,0.00245,,,,,,349.9720459,,,,
,32005123.845,349.9780731,18642.6484375,-1.47679945002512E-5,2.10632981034331E-6,1,0.999253354069792,40.0298881530762,1.99618041842165,19.6700002998114,-0.000166367624007583,-3.04334822748586E-5,0.25,-1.39984970485221E-7,-1.47417466230473E-5,-1.47941544344607E-7,349.9779968,349.9781494,18617.7421875,18667.5546875,56.1428132793136,20.5147554127799,30.122374,0,0,0,40,4449,350.5201,18642.6484375,,,,,,,,,,,,,0,,,,0,,,,,,349.9780731,,,,
,32005218.125,349.9715271,23352.72265625,-2.93613598062721E-5,2.06233150497217E-6,1,0.999253354069792,40.0298881530762,1.99604558291221,19.6700002998114,-0.000330544751719958,-6.16697496982764E-5,0.25,-3.81715003444211E-7,-2.93091246202291E-5,-3.97337943651297E-7,349.9715271,349.9715271,23320.1640625,23385.28125,56.1975272756598,20.5179153606734,30.122374,0,0,0,40,4449,350.5306,23352.72265625,,,,,,,,,,,,,0,,,,0.00245,,,,,,349.9715271,,,,
,32005315.23,349.97862245,28207.8388671875,-4.56723716728218E-5,2.94538942823144E-6,1,0.999253354069792,40.0298881530762,1.99586197897038,19.6700002998114,-0.000516588911446085,-8.16954382446091E-5,0.25,6.67047303813409E-7,-4.55918087866353E-5,6.4053358960328E-7,349.9784241,349.9788208,28177.751953125,28237.92578125,56.597721077506,20.517803307929,30.122374,0,0,0,40,4449,350.55025,28207.8388671875,,,,,,,,,,,,,0,,,,0.00245,,,,,,349.97862245,,,,
,32005414.85,349.9921265,33185.529296875,-6.19420162445747E-5,3.19100331947384E-6,1,0.999253354069792,40.0298881530762,1.99564460558185,19.6700002998114,-0.000698757490374545,-0.000121067299145671,0.25,-6.75691075401205E-9,-6.1832223392869E-5,-4.10698917396674E-8,349.9919739,349.9922791,33155.58203125,33215.4765625,56.0513627425636,20.5194262944216,29.742722,0,0,0,40,4449,350.5555,33185.529296875,,,,,,,,,,,,,0,,,,0,,,,,,349.9921265,,,,
,32005513.025,349.9937134,38092.646484375,-7.79997601630094E-5,3.36207778738786E-6,1,0.999253354069792,40.0298881530762,1.99559600058429,19.6700002998114,-0.000881662502923394,-0.000142164369906563,0.25,9.03151401967292E-7,-7.78620082158848E-5,8.58365009536257E-7,349.9937134,349.9937134,38087.6015625,38097.69140625,56.3616692646983,20.518578157282,29.742722,0,0,0,40,4449,350.5507,38092.646484375,,,,,,,,,,,,,0,,,,-0.0049,,,,,,349.9937134,,,,
,32005610.17,349.9873657,42947.734375,-9.5065612477362E-5,2.0221220124058E-6,1,0.999253354069792,40.0298881530762,1.9957440569992,19.6700002998114,-0.00107508422674497,-0.000170721657654713,0.25,1.32759530739027E-6,-9.48978703341426E-5,1.27265867470747E-6,349.9873657,349.9873657,42945.375,42950.09375,56.3984058051021,20.5182480722441,30.122374,0,0,0,40,4449,350.5724,42947.734375,,,,,,,,,,,,,0,,,,0,,,,,,349.9873657,,,,
,32005708.325,349.9983215,47855.5078125,-0.000109646952937272,3.52720981464065E-6,1,0.999253354069792,40.0298881530762,1.99548800092312,19.6700002998114,-0.00123786422690844,-0.000208238437727431,0.25,5.24505710271505E-7,-0.00010945288874434,4.62982876475142E-7,349.9983215,349.9983215,47823.265625,47887.75,56.3874630058329,20.519247151994,30.122374,0,0,0,40,4449,350.5713,47855.5078125,,,,,,,,,,,,,0,,,,0.00245,,,,,,349.9983215,,,,
,32005807.94,350.0019836,52832.865234375,-0.000127221781777602,3.47265161950232E-6,1,0.999253354069792,40.0298881530762,1.99545859266565,19.6700002998114,-0.00143724392388072,-0.000235905322303259,0.25,1.11447503365927E-6,-0.000126996880206651,1.04226164016432E-6,350.0019836,350.0019836,52810.20703125,52855.5234375,56.0654320559098,20.5203599225129,30.502024,0,0,0,40,4449,350.57115,52832.865234375,,,,,,,,,,,,,0,,,,-0.00245,,,,,,350.0019836,,,,
,32005904.24,350.00209045,57645.470703125,-0.00014206687978463,4.67378444070028E-6,1,0.999253354069792,40.0298881530762,1.99551429339983,19.6700002998114,-0.00160545483855783,-0.000260778261805125,0.25,1.48035287613681E-6,-0.000141815869634897,1.39936896315065E-6,350.0012817,350.0028992,57617.92578125,57673.015625,56.5344091674483,20.5162839597464,30.122374,0,0,0,40,4449,350.5698,57645.470703125,,,,,,,,,,,,,0,,,,0,,,,,,350.00209045,,,,
,32006003.12,349.9976501,62589,-0.000160779834920364,4.02853523397979E-6,1,0.999253354069792,40.0298881530762,1.99549211092854,19.6700002998114,-0.00181363055677257,-0.000314038235372657,0.25,-1.438117119652E-9,-0.000160494867582568,-9.00306600887112E-8,349.9976501,349.9976501,62586.46484375,62591.53515625,56.5891231637945,20.5142400079688,30.881676,0,0,0,40,4449,350.565,62589,,,,,,,,,,,,,0,,,,-0.0049,,,,,,349.9976501,,,,
,32006101.635,350.0011292,67514.3984375,-0.000175508468932854,4.40270443367718E-6,1,0.999253354069792,40.0298881530762,1.99568958069661,19.6700002998114,-0.00197928874730752,-0.000346712868606454,0.25,-3.45072172574339E-7,-0.000175197194180986,-4.41072491464287E-7,350.0011292,350.0011292,67484.375,67544.421875,56.5187765970637,20.5167248745306,30.122374,0,0,0,40,4449,350.5749,67514.3984375,,,,,,,,,,,,,0,,,,0.00245,,,,,,350.0011292,,,,
,32006200.97,350.0127563,72476.76953125,-0.000192245388090267,4.37493797164913E-6,1,0.999253354069792,40.0298881530762,1.99557222771936,19.6700002998114,-0.00216455822631407,-0.000399148553347199,0.25,-2.09728567077262E-6,-0.000191903416396485,-2.19928927079559E-6,350.0127563,350.0127563,72446.9375,72506.6015625,56.5813068786021,20.5197326221181,30.881676,0,0,0,40,4449,350.5597,72476.76953125,,,,,,,,,,,,,0,,,,0,,,,,,350.0127563,,,,
,32006297.99,350.0104065,77327.48046875,-0.000210120059667852,3.78830439120485E-6,1,0.999253354069792,40.0298881530762,1.99547477578225,19.6700002998114,-0.00237597546103595,-0.000376925411314204,0.25,2.96596396697868E-6,-0.000209749207132787,2.84526683021933E-6,350.0104065,350.0104065,77299.9375,77355.0234375,56.3694855498906,20.5194824686163,30.881676,0,0,0,40,4449,350.54635,77327.48046875,,,,,,,,,,,,,0,,,,-0.00245,,,,,,350.0104065,,,,
,32006394.84,350.0133667,82170.8359375,-0.00022433134762528,4.00360574354447E-6,1,0.999253354069792,40.0298881530762,1.9954875297917,19.6700002998114,-0.00253180331383462,-0.000430631588817464,0.25,6.65537577502891E-7,-0.00022393402499901,5.4123170190256E-7,350.0133667,350.0133667,82143.3515625,82198.3203125,56.3796467206406,20.5175802028249,30.122374,0,0,0,40,4449,350.5329,82170.8359375,,,,,,,,,,,,,0,,,,0.0049,,,,,,350.0133667,,,,
,32006490.485,350.0009918,86948.8671875,-0.000246476921214703,5.62273259711813E-6,1,0.999253354069792,40.0298881530762,1.99553591802802,19.6700002998114,-0.00277926922860607,-0.000487793072515851,0.25,-5.66643224731523E-7,-0.000246039776775431,-7.0078275023989E-7,350.0009155,350.0010681,86916.4296875,86981.3046875,56.5437887096791,20.5187340647311,30.122374,0,0,0,40,4449,350.53205,86948.8671875,,,,,,,,,,,,,0,,,,-0.00245,,,,,,350.0009918,,,,
,32006599.9,350.00971985,88378.0078125,-0.000246695337832596,4.27323713173496E-6,1,0.999253354069792,40.0298881530762,1.99527976034511,19.6700002998114,-0.0027744114016767,-0.000528473680359544,0.25,-4.14091194437272E-6,-0.000246255778020391,-4.26878947625153E-6,350.0096436,350.0097961,88347.953125,88408.0625,56.3898078913906,20.5229088789379,30.502024,0,0,0,40,4449,350.544,88378.0078125,,,,,,,,,,,,,0,,,,0.00245,,,,,,350.00971985,,,,
,32006697.095,350.0133667,83519.71875,-0.000229745979898268,4.03840989252292E-6,1,0.999253354069792,40.0298881530762,1.99547908937553,19.6700002998114,-0.00259966637271061,-0.000401958034081815,0.25,4.14480567227224E-6,-0.000229340969677726,4.01138973583225E-6,350.0133667,350.0133667,83494.5703125,83544.8671875,56.272563613506,20.5206531365979,30.881676,0,0,0,40,4449,350.51475,83519.71875,,,,,,,,,,,,,0,,,,0,,,,,,350.0133667,,,,
,32006792.71,350.0008545,78738.30078125,-0.000213652212114477,4.62669037697314E-6,1,0.999253354069792,40.0298881530762,1.99542128933977,19.6700002998114,-0.00241139360673599,-0.000409018848612346,0.25,7.31463285136457E-7,-0.000213273941179676,6.12812555797629E-7,350.0008545,350.0008545,78710.7890625,78765.8125,56.3929344054675,20.5231127429791,30.502024,0,0,0,40,4449,350.51845,78738.30078125,,,,,,,,,,,,,0,,,,0,,,,,,350.0008545,,,,
,32006888.4,349.9962616,73954.69140625,-0.000195790482723399,3.59650944575742E-6,1,0.999253354069792,40.0298881530762,1.99514665070066,19.6700002998114,-0.00221010822417429,-0.000371299492405677,0.25,9.78570116278003E-7,-0.000195444027934723,8.69182202801096E-7,349.9955444,349.9969788,73922.1875,73987.1953125,56.5093970548329,20.5245226064722,30.502024,0,0,0,40,4449,350.50865,73954.69140625,,,,,,,,,,,,,0,,,,0,,,,,,349.9962616,,,,
,32006983.965,349.9875488,69179.07421875,-0.000184156707386356,3.52444926466871E-6,1,0.999253354069792,40.0298881530762,1.99510596690861,19.6700002998114,-0.00207427263949808,-0.000375059090821064,0.25,-1.36964008341931E-6,-0.00018382962610552,-1.468563116475E-6,349.9875488,349.9875488,69149.09375,69209.0546875,56.1998721612175,20.5275042779856,30.881676,0,0,0,40,4449,350.53235,69179.07421875,,,,,,,,,,,,,0,,,,-0.00245,,,,,,349.9875488,,,,
,32007078.68,349.98638915,64446.31640625,-0.000167932334979432,3.42996885770279E-6,1,0.999253354069792,40.0298881530762,1.99515943280591,19.6700002998114,-0.00188950943765741,-0.000353958634282919,0.25,-2.30699700641585E-6,-0.000167633486401668,-2.3954174541453E-6,349.9852295,349.9875488,64416.39453125,64476.23828125,56.2209761312367,20.5255421291779,30.122374,0,0,0,40,4449,350.5388,64446.31640625,,,,,,,,,,,,,0,,,,-0.00245,,,,,,349.98638915,,,,
,32007173.085,349.9943695,59725.6015625,-0.000149985935307536,3.11372155193267E-6,1,0.999253354069792,40.0298881530762,1.99497849549151,19.6700002998114,-0.00168940912136797,-0.000304714187072663,0.25,-1.05035330602398E-6,-0.000149719533621306,-1.13118910624968E-6,349.9934692,349.9952698,59703,59748.203125,56.6743206723906,20.5280470229256,30.502024,0,0,0,40,4449,350.55345,59725.6015625,,,,,,,,,,,,,0,,,,-0.00245,,,,,,349.9943695,,,,
,32007269.665,349.981781,54899.83203125,-0.000133784286991551,2.7733903192647E-6,1,0.999253354069792,40.0298881530762,1.99493747964627,19.6700002998114,-0.00151000027902599,-0.00025382004807538,0.25,6.56948700300111E-7,-0.000133547593035167,5.81950118544986E-7,349.9806824,349.9828796,54874.875,54924.7890625,56.546915223756,20.5270001648399,30.502024,0,0,0,40,4449,350.55475,54899.83203125,,,,,,,,,,,,,0,,,,-0.00245,,,,,,349.981781,,,,
,32007369.39,349.98843385,49912.33984375,-0.000118031421410992,3.01666054270394E-6,1,0.999253354069792,40.0298881530762,1.99497503848911,19.6700002998114,-0.00133082707428373,-0.000232004918208428,0.25,-1.35733559414017E-7,-0.000117822171697814,-2.00696157099742E-7,349.9874573,349.9894104,49877.33984375,49947.33984375,56.5039256551983,20.5291096663952,30.881676,0,0,0,40,4449,350.55855,49912.33984375,,,,,,,,,,,,,0,,,,0,,,,,,349.98843385,,,,
,32007467.11,349.9933472,45029.8359375,-0.000100969272393142,2.35922473982878E-6,1,0.999253354069792,40.0298881530762,1.99517806404421,19.6700002998114,-0.00113593033828911,-0.000213664693726727,0.25,-1.46182663564285E-6,-0.00010078950640406,-1.51506273683879E-6,349.9933472,349.9933472,45029.8359375,45029.8359375,56.6360208749483,20.5292750803986,30.881676,0,0,0,40,4449,350.5752,45029.8359375,,,,,,,,,,,,,0,,,,0.0049,,,,,,349.9933472,,,,
,32007562.72,349.985672,40251.95703125,-8.73774412324476E-5,2.32934471691239E-6,1,0.999253354069792,40.0298881530762,1.99522497031012,19.6700002998114,-0.000985762292028957,-0.000169190174838648,0.25,1.28456960808923E-7,-8.7222664286407E-5,7.9876467553561E-8,349.9849243,349.9864197,40222.04296875,40281.87109375,56.8454973181022,20.5253748525599,30.502024,0,0,0,40,4449,350.5923,40251.95703125,,,,,,,,,,,,,0,,,,0.00245,,,,,,349.985672,,,,
,32007662.39,349.9826355,35269.32421875,-6.81255848014069E-5,2.25168089709946E-6,1,0.999253354069792,40.0298881530762,1.99506550809707,19.6700002998114,-0.000766908096103497,-0.000141159171911119,0.25,-7.20591791850122E-7,-6.80044597193761E-5,-7.57048029682569E-7,349.9824219,349.9828491,35244.55078125,35294.09765625,56.6821369575829,20.5289702438019,31.261326,0,0,0,40,4449,350.596,35269.32421875,,,,,,,,,,,,,0,,,,0,,,,,,349.9826355,,,,
,32007759.395,349.98384095,30422.2021484375,-5.28289278421044E-5,1.66134692921728E-6,1,0.999253354069792,40.0298881530762,1.99508820989093,19.6700002998114,-0.000596684971218637,-9.80929377763824E-5,0.25,4.49569539562329E-7,-5.27355544172807E-5,4.19487206732503E-7,349.9837341,349.9839478,30392.318359375,30452.0859375,56.5922496778714,20.5301938605449,31.261326,0,0,0,40,4449,350.6002,30422.2021484375,,,,,,,,,,,,,0,,,,0,,,,,,349.98384095,,,,
,32007856.07,349.9892273,25589.443359375,-3.60259853768619E-5,2.27827906151867E-6,1,0.999253354069792,40.0298881530762,1.99511553569401,19.6700002998114,-0.000404344710741294,-8.16900082487101E-5,0.25,-1.00531558849549E-6,-3.59615750973311E-5,-1.02352132185081E-6,349.9892273,349.9892273,25559.587890625,25619.298828125,56.5602029085829,20.5284724703195,30.502024,0,0,0,40,4449,350.6004,25589.443359375,,,,,,,,,,,,,0,,,,0,,,,,,349.9892273,,,,
,32007951.005,349.9922485,20844.546875,-2.1558431357327E-5,1.40790554548477E-6,1,0.999253354069792,40.0298881530762,1.99502151107723,19.6700002998114,-0.000245024652003744,-3.11501755920226E-5,0.25,9.70724773151596E-7,-2.15207572546997E-5,9.57034470770527E-7,349.9922485,349.9922485,20842.064453125,20847.029296875,56.5781803645252,20.5315217309854,30.881676,0,0,0,40,4449,350.618,20844.546875,,,,,,,,,,,,,0,,,,0,,,,,,349.9922485,,,,
,32008044.83,349.990448,16154.5805664062,-5.85771821290962E-6,1.3649871714076E-6,1,0.999253354069792,40.0298881530762,1.9950397850135,19.6700002998114,-6.78540987954531E-5,-1.08893662139558E-6,0.25,9.17707848211212E-7,-5.84784527663709E-6,9.12826580216791E-7,349.990448,349.990448,16124.623046875,16184.5380859375,57.0424677049483,20.5317711912644,30.881676,0,0,0,40,4449,350.63055,16154.5805664062,,,,,,,,,,,,,0,,,,0.0049,,,,,,349.990448,,,,
,32008139.225,349.992218,11437.0512695312,8.19304524253656E-6,8.27547601392256E-7,1,0.999253354069792,40.0298881530762,1.99499978708579,19.6700002998114,9.25134758641329E-5,1.53292518818539E-5,0.25,-5.93588139551432E-8,8.17855530855956E-6,-5.46981778500174E-8,349.992218,349.992218,11407.1669921875,11466.935546875,57.0377779338329,20.5339946364034,30.881676,0,0,0,40,4449,350.628,11437.0512695312,,,,,,,,,,,,,0,,,,0.00245,,,,,,349.992218,,,,
,32008232.01,349.99313355,6801.6923828125,2.09853951277143E-5,8.08872164262711E-7,1,0.999253354069792,40.0298881530762,1.99480228656235,19.6700002998114,0.000237331958939297,3.69880786446084E-5,0.25,-3.5353234566265E-7,2.09483920424488E-5,-3.41230228303381E-7,349.992981,349.9932861,6769.38232421875,6834.00244140625,56.5852150211983,20.5371523520009,30.881676,0,0,0,40,4449,350.6318,6801.6923828125,,,,,,,,,,,,,0,,,,-0.00245,,,,,,349.99313355,,,,
,32008325.48,349.99174495,2128.65246582031,2.68494890512517E-5,5.12780226674805E-7,1,0.999253354069792,40.0298881530762,1.99485589274673,19.6700002998114,0.00030197171299834,5.70701019877156E-5,0.25,4.11831994983364E-7,2.68016656651539E-5,4.26048196641018E-7,349.9908752,349.9926147,2101.05786132813,2156.2470703125,57.3144744296407,20.5358845260473,30.881676,0,0,0,40,4449,350.6329,2128.65246582031,,,,,,,,,,,,,0,,,,0.00245,,,,,,349.99174495,,,,
,32008416.135,349.9982605,-2397.67578125,-2.66326094518659E-5,5.01921773806507E-7,1,0.999253354069792,40.0298881530762,1.99485796849597,19.6700002998114,-0.000300382973399442,-5.16987785445751E-5,0.25,2.69352039287406E-8,-2.65854089346079E-5,1.20623904253381E-8,349.9976196,349.9989014,-2432.44750976562,-2362.90405273438,56.9267866841022,20.5355751781278,30.502024,0,0,0,40,4449,350.63325,-2397.67578125,,,,,,,,,,,,,0,,,,-0.00245,,,,,,349.9982605,,,,
,32008509.01,349.99302675,-7041.73999023437,-2.02421505483186E-5,5.34033521169434E-7,1,0.999253354069792,40.0298881530762,1.99497364039081,19.6700002998114,-0.000227635146838056,-4.32463272468737E-5,0.25,-3.29829157566656E-7,-2.02060849296618E-5,-3.40505584712551E-7,349.9921875,349.993866,-7071.83203125,-7011.64794921875,56.5531682519098,20.535054635804,31.640976,0,0,0,40,4449,350.64655,-7041.73999023437,,,,,,,,,,,,,0,,,,0.00245,,,,,,349.99302675,,,,
,32008603.97,349.9994812,-11790.1069335938,-6.9486777040443E-6,1.02474429904606E-6,1,0.999253354069792,40.0298881530762,1.99484838513044,19.6700002998114,-7.63212240466741E-5,-2.53333787563727E-5,0.25,-1.04335008447027E-6,-6.93577879446046E-6,-1.0453635447247E-6,349.9994812,349.9994812,-11820.05078125,-11760.1630859375,57.169873153583,20.5384223292199,31.261326,0,0,0,40,4449,350.64555,-11790.1069335938,,,,,,,,,,,,,0,,,,-0.00245,,,,,,349.9994812,,,,
,32008701.24,350.0016937,-16652.7265625,8.32779175544008E-6,1.21388779525089E-6,1,0.999253354069792,40.0298881530762,1.99485768723544,19.6700002998114,9.42021711524056E-5,1.45777134956301E-5,0.25,-1.49238376198958E-7,8.31311049553481E-6,-1.44347180477991E-7,350.0012817,350.0021057,-16677.62890625,-16627.82421875,56.8525319747752,20.5381595279474,31.640976,0,0,0,40,4449,350.6352,-16652.7265625,,,,,,,,,,,,,0,,,,0,,,,,,350.0016937,,,,
,32008797.355,350.00250245,-21454.7705078125,2.22664294879995E-5,1.01077156340149E-6,1,0.999253354069792,40.0298881530762,1.99473201500454,19.6700002998114,0.00025266172883265,3.43322160235061E-5,0.25,-8.10735922245317E-7,2.22274039698152E-5,-7.96937671298837E-7,350.0016174,350.0033875,-21484.837890625,-21424.703125,56.9353845978137,20.538440537709,31.261326,0,0,0,40,4449,350.63535,-21454.7705078125,,,,,,,,,,,,,0,,,,0,,,,,,350.00250245,,,,
,32008893.97,350.0057373,-26282.2353515625,3.90924686505527E-5,1.88584234666945E-6,1,0.999253354069792,40.0298881530762,1.99488063324228,19.6700002998114,0.000443112562610208,6.32209782811524E-5,0.25,-1.16259328161604E-6,3.90238045531168E-5,-1.13884828923142E-6,350.0057373,350.0057373,-26312.318359375,-26252.15234375,56.6868267286983,20.5362197883333,30.881676,0,0,0,40,4449,350.64215,-26282.2353515625,,,,,,,,,,,,,0,,,,0,,,,,,350.0057373,,,,
,32008992.47,350.0119934,-31207.3232421875,5.41321222322609E-5,1.42230578581785E-6,1,0.999253354069792,40.0298881530762,1.99473306089023,19.6700002998114,0.000610810336069803,0.000103321494219726,0.25,-2.1003906924927E-7,5.40362555400895E-5,-1.79665042086781E-7,350.0112915,350.0126953,-31234.97265625,-31179.673828125,57.149550812083,20.5384914437137,31.261326,0,0,0,40,4449,350.62725,-31207.3232421875,,,,,,,,,,,,,0,,,,-0.00245,,,,,,350.0119934,,,,
,32009087.5,350.01361085,-35954.234375,7.03625352157304E-5,1.68101309955672E-6,1,0.999253354069792,40.0298881530762,1.99473691598096,19.6700002998114,0.000791943310287774,0.000145894682773319,0.25,7.55214755412852E-7,7.02373538948106E-5,7.92840539559972E-7,350.0131836,350.0140381,-35981.81640625,-35926.65234375,56.9064643426022,20.540133797139,30.881676,0,0,0,40,4449,350.6185,-35954.234375,,,,,,,,,,,,,0,,,,0,,,,,,350.01361085,,,,
,32009184.995,350.0131226,-40826.794921875,8.68075955374772E-5,1.34944975248841E-6,1,0.999253354069792,40.0298881530762,1.99460157107778,19.6700002998114,0.000981188215525657,0.000155632554312805,0.25,-1.22769842898333E-6,8.66543567972169E-5,-1.17749195828284E-6,350.0131226,350.0131226,-40829.19140625,-40824.3984375,57.0330881627176,20.5394000762316,31.640976,0,0,0,40,4449,350.61245,-40826.794921875,,,,,,,,,,,,,0,,,,-0.00245,,,,,,350.0131226,,,,
,32009280.53,350.0062866,-45602.169921875,0.000102943367983542,2.18892464392466E-6,1,0.999253354069792,40.0298881530762,1.9946518003405,19.6700002998114,0.0011594439107066,0.000208566255833729,0.25,6.72644760408659E-7,0.000102760495327106,7.2836063867004E-7,350.0062866,350.0062866,-45607.0703125,-45597.26953125,56.8173586914099,20.5407719588165,31.640976,0,0,0,40,4449,350.60035,-45602.169921875,,,,,,,,,,,,,0,,,,0,,,,,,350.0062866,,,,
,32009375.14,350.0118408,-50331.58984375,0.000119852868839031,2.11129334101352E-6,1,0.999253354069792,40.0298881530762,1.9947560204267,19.6700002998114,0.00135180139276154,0.000232211586030603,0.25,-1.59130825289228E-7,0.000119640460336617,-9.2652617768924E-8,350.0118408,350.0118408,-50364.26171875,-50298.91796875,56.9799374234099,20.5397636497038,30.881676,0,0,0,40,4449,350.60125,-50331.58984375,,,,,,,,,,,,,0,,,,0,,,,,,350.0118408,,,,
,32009473.045,350.0177307,-55223.587890625,0.000132979227194913,2.54026882017207E-6,1,0.999253354069792,40.0298881530762,1.99460916843753,19.6700002998114,0.00150078651772093,0.000251615055227915,0.25,-7.09537425208498E-7,0.000132743828216155,-6.34900806161347E-7,350.0177307,350.0177307,-55256.171875,-55191.00390625,56.8251749766022,20.5432713401887,31.640976,0,0,0,40,4449,350.58875,-55223.587890625,,,,,,,,,,,,,0,,,,-0.00245,,,,,,350.0177307,,,,
,32009567.41,350.01472475,-59941.189453125,0.000148598168374454,2.77025831026081E-6,1,0.999253354069792,40.0298881530762,1.99473037950657,19.6700002998114,0.00168199212846779,0.000253261665416399,0.25,-3.26909199239888E-6,0.000148336506234104,-3.18137284157123E-6,350.0141602,350.0152893,-59963.8515625,-59918.52734375,56.9189703989099,20.5401109015348,31.640976,0,0,0,40,4449,350.57785,-59941.189453125,,,,,,,,,,,,,0,,,,-0.00245,,,,,,350.01472475,,,,
,32009664.875,350.012085,-64811.158203125,0.000167723805824731,2.6368187175367E-6,1,0.999253354069792,40.0298881530762,1.99493827357608,19.6700002998114,0.00189410710993504,0.000312213872772433,0.25,-1.3552193944964E-6,0.000167427199588169,-1.26043679053886E-6,350.012085,350.012085,-64836.0390625,-64786.27734375,56.6235148186406,20.5404824273356,31.261326,0,0,0,40,4449,350.565,-64811.158203125,,,,,,,,,,,,,0,,,,-0.00245,,,,,,350.012085,,,,
,32009760.595,350.01676945,-69595.9375,0.000183341969593529,2.37004186920863E-6,1,0.999253354069792,40.0298881530762,1.99479926566362,19.6700002998114,0.00207145353188968,0.000334863140319351,0.25,-2.04894692953927E-6,0.000183018033484698,-1.94442635115643E-6,350.0160828,350.0174561,-69623.5234375,-69568.3515625,57.0948368157368,20.541263604294,31.261326,0,0,0,40,4449,350.55065,-69595.9375,,,,,,,,,,,,,0,,,,0,,,,,,350.01676945,,,,
,32009859.345,350.015686,-74530.2734375,0.000196730581719042,2.97482725290559E-6,1,0.999253354069792,40.0298881530762,1.99483904146443,19.6700002998114,0.00221837305706801,0.000384687172108679,0.25,5.07444460319256E-8,0.000196381767510867,1.58803187114522E-7,350.015686,350.015686,-74535.2109375,-74525.3359375,56.9760292808137,20.5415412115971,31.640976,0,0,0,40,4449,350.5381,-74530.2734375,,,,,,,,,,,,,0,,,,0.0049,,,,,,350.015686,,,,
,32009954.89,350.0174866,-79307.14453125,0.000213567693961316,2.73891430621522E-6,1,0.999253354069792,40.0298881530762,1.99497865252976,19.6700002998114,0.00241432107615948,0.000383397536282434,0.25,-2.98101952615265E-6,0.000213190689500745,-2.85844208830465E-6,350.0169373,350.0180359,-79336.921875,-79277.3671875,56.5844333926791,20.541157542452,31.261326,0,0,0,40,4449,350.5231,-79307.14453125,,,,,,,,,,,,,0,,,,0,,,,,,350.0174866,,,,
,32010049.645,350.0174866,-84039.71875,0.000229674309256214,2.76516652762228E-6,1,0.999253354069792,40.0298881530762,1.99469523296996,19.6700002998114,0.00259429315867557,0.000422401294285088,0.25,-2.30601301315208E-6,0.000229268385924843,-2.17590779387726E-6,350.0174866,350.0174866,-84064.3125,-84015.125,56.7962547213906,20.5443158961262,31.261326,0,0,0,40,4449,350.5091,-84039.71875,,,,,,,,,,,,,0,,,,0,,,,,,350.0174866,,,,
,32010140.72,350.016449,-88591.84375,0.000244915230925089,2.06171664358222E-6,1,0.999253354069792,40.0298881530762,1.99469152548038,19.6700002998114,0.00276593861399395,0.00045334218000739,0.25,-2.20069754364131E-6,0.000244482246088274,-2.06254290733083E-6,350.016449,350.016449,-88621.8515625,-88561.8359375,56.9947883652753,20.5447635347901,31.640976,0,0,0,40,4449,350.49705,-88591.84375,,,,,,,,,,,,,0,,,,-0.00245,,,,,,350.016449,,,,
,32010246.4,350.0024414,-86894,0.000242905534354241,2.71063501515337E-6,1,0.999253354069792,40.0298881530762,1.99472967467671,19.6700002998114,0.00274330317452703,0.00044957500062266,0.25,-2.18761988292073E-6,0.00024247621685079,-2.05054246605341E-6,350.0024414,350.0024414,-86919.03125,-86868.96875,56.7173102409483,20.5433454514574,31.640976,0,0,0,40,4449,350.4967,-86894,,,,,,,,,,,,,0,,,,0,,,,,,350.0024414,,,,
,32010338.665,349.99964905,-82284.5390625,0.000223121175277138,3.12579455898686E-6,1,0.999253354069792,40.0298881530762,1.99464940703347,19.6700002998114,0.00252456280602312,0.000385248164624641,0.25,-4.46561119663524E-6,0.000222728186568782,-4.33522661004401E-6,349.9994202,349.9998779,-82312.0546875,-82257.0234375,57.3613721407945,20.5442186381824,32.02063,0,0,0,40,4449,350.4998,-82284.5390625,,,,,,,,,,,,,0,,,,-0.00245,,,,,,349.99964905,,,,
,32010433.75,349.9942017,-77531.67578125,0.000206778871197436,2.49863638195181E-6,1,0.999253354069792,40.0298881530762,1.99487717514549,19.6700002998114,0.00233589693299195,0.000380241460248497,0.25,-2.08387173988986E-6,0.000206413569723037,-1.9665690590997E-6,349.9942017,349.9942017,-77554.140625,-77509.2109375,57.0557553897753,20.5421417869511,31.640976,0,0,0,40,4449,350.512,-77531.67578125,,,,,,,,,,,,,0,,,,-0.0049,,,,,,349.9942017,,,,
,32010528.26,350.0007324,-72806.7734375,0.000192145145110754,2.421197127656E-6,1,0.999253354069792,40.0298881530762,1.99485025821238,19.6700002998114,0.00216714377345928,0.00037304131264281,0.25,-1.88286992830453E-7,0.000191804685792403,-8.22835238113551E-8,350.0007324,350.0007324,-72812.03125,-72801.515625,56.9080275996406,20.5433474213409,31.640976,0,0,0,40,4449,350.5245,-72806.7734375,,,,,,,,,,,,,0,,,,0,,,,,,350.0007324,,,,
,32010624.97,349.9933014,-67975.15234375,0.0001759284580179,2.29728138642091E-6,1,0.999253354069792,40.0298881530762,1.99489538607846,19.6700002998114,0.00198755117300198,0.000322696322800404,0.25,-1.8456729673421E-6,0.000175617690844515,-1.74555230968315E-6,349.9928894,349.9937134,-68005.0390625,-67945.265625,57.1737812961791,20.5410006365834,31.640976,0,0,0,40,4449,350.5166,-67975.15234375,,,,,,,,,,,,,0,,,,0,,,,,,349.9933014,,,,
,32010718.795,349.99319455,-63285.3984375,0.000161525917176753,2.57651892140944E-6,1,0.999253354069792,40.0298881530762,1.99466311902312,19.6700002998114,0.00182531982078849,0.000292294145785765,0.25,-2.04509070489543E-6,0.000161240779768303,-1.9524647012806E-6,349.9915466,349.9948425,-63317.953125,-63252.84375,57.0166739638137,20.5446744018435,32.02063,0,0,0,40,4449,350.53325,-63285.3984375,,,,,,,,,,,,,0,,,,0,,,,,,349.99319455,,,,
,32010813.905,349.98832705,-58533.00390625,0.000146128600131796,1.95692263513178E-6,1,0.999253354069792,40.0298881530762,1.99460665036507,19.6700002998114,0.0016522777610324,0.00025865253965708,0.25,-2.362111984757E-6,0.000145870944841735,-2.27733250596411E-6,349.9881287,349.9885254,-58555.24609375,-58510.76171875,56.7345060683714,20.5462788326299,31.640976,0,0,0,40,4449,350.53635,-58533.00390625,,,,,,,,,,,,,0,,,,-0.0049,,,,,,349.98832705,,,,
,32010911.07,349.979187,-53675.533203125,0.000128502838674142,1.90437542737985E-6,1,0.999253354069792,40.0298881530762,1.99463776316566,19.6700002998114,0.00145040717848956,0.000242462072867255,0.25,-7.46583121434981E-7,0.000128275562429454,-6.74320756167046E-7,349.979187,349.979187,-53678.0859375,-53672.98046875,56.7290346687368,20.5443019316205,31.261326,0,0,0,40,4449,350.5406,-53675.533203125,,,,,,,,,,,,,0,,,,0,,,,,,349.979187,,,,
,32011006.395,349.9861145,-48910.916015625,0.000112418654779632,1.93326228803204E-6,1,0.999253354069792,40.0298881530762,1.99463429644017,19.6700002998114,0.00126895456670898,0.000211585377659001,0.25,-7.00042742417018E-7,0.000112219821647409,-6.36687448761161E-7,349.9861145,349.9861145,-48940.98046875,-48880.8515625,56.9611783389483,20.543304365222,31.640976,0,0,0,40,4449,350.5572,-48910.916015625,,,,,,,,,,,,,0,,,,-0.00245,,,,,,349.9861145,,,,
,32011101.29,349.9790344,-44167.888671875,9.79339756652028E-5,1.81974646898896E-6,1,0.999253354069792,40.0298881530762,1.99466106019377,19.6700002998114,0.001106166201989,0.000180301556556039,0.25,-9.66792159173284E-7,9.77609789524402E-5,-9.10921028713575E-7,349.9790344,349.9790344,-44193.109375,-44142.66796875,56.7360693254098,20.5420673392442,31.640976,0,0,0,40,4449,350.57235,-44167.888671875,,,,,,,,,,,,,0,,,,0,,,,,,349.9790344,,,,
,32011196.18,349.98353575,-39428.2578125,8.19394798772033E-5,1.80262838110843E-6,1,0.999253354069792,40.0298881530762,1.99464512035129,19.6700002998114,0.000926191322440679,0.000146865770250301,0.25,-1.16260891873981E-6,8.17949176583078E-5,-1.11519730023778E-6,349.9832153,349.9838562,-39455.3671875,-39401.1484375,56.851750346256,20.5419774528979,32.02063,0,0,0,40,4449,350.5855,-39428.2578125,,,,,,,,,,,,,0,,,,0,,,,,,349.98353575,,,,
,32011292.47,349.9926147,-34615.943359375,6.55303437549593E-5,1.44827590936832E-6,1,0.999253354069792,40.0298881530762,1.99466431027531,19.6700002998114,0.000739101172452445,0.00012680221688315,0.25,-1.00904291918666E-7,6.54142502142812E-5,-6.44236936596435E-8,349.9926147,349.9926147,-34643.58203125,-34588.3046875,56.9689946241406,20.5405989194558,31.640976,0,0,0,40,4449,350.5789,-34615.943359375,,,,,,,,,,,,,0,,,,-0.00245,,,,,,349.9926147,,,,
,32011388,349.99914555,-29839.2158203125,5.08974148296068E-5,1.55124043812509E-6,1,0.999253354069792,40.0298881530762,1.9947190436053,19.6700002998114,0.000573575736436074,0.00010137173696137,0.25,1.77181761831325E-7,5.08070903353827E-5,2.05086798793081E-7,349.9985352,349.9997559,-29871.38671875,-29807.044921875,56.6876083572175,20.5408033325786,31.261326,0,0,0,40,4449,350.58265,-29839.2158203125,,,,,,,,,,,,,0,,,,0,,,,,,349.99914555,,,,
,32011484.345,349.9933167,-25026.5185546875,3.41278182896936E-5,9.08654930898989E-7,1,0.999253354069792,40.0298881530762,1.99456771632848,19.6700002998114,0.000386659133060001,5.5885106000599E-5,0.25,-9.52757161187165E-7,3.4067853840977E-5,-9.32131182865443E-7,349.9933167,349.9933167,-25029.03125,-25024.005859375,56.6235148186406,20.5423480433346,31.640976,0,0,0,40,4449,350.5827,-25026.5185546875,,,,,,,,,,,,,0,,,,0,,,,,,349.9933167,,,,
,32011579.425,349.98965455,-20274.3017578125,1.89642905117615E-5,9.30583193652586E-7,1,0.999253354069792,40.0298881530762,1.99464672738191,19.6700002998114,0.000217465728715338,1.60559200471163E-5,0.25,-1.85971533778906E-6,1.89317098967314E-5,-1.84588807256811E-6,349.9892883,349.9900208,-20306.833984375,-20241.76953125,56.9283499411406,20.5401683462812,31.640976,0,0,0,40,4449,350.59465,-20274.3017578125,,,,,,,,,,,,,0,,,,-0.00245,,,,,,349.98965455,,,,
,32011673.315,349.98666385,-15582.0048828125,4.98688701286656E-6,7.51944702763088E-7,1,0.999253354069792,40.0298881530762,1.99452790931186,19.6700002998114,5.69527445845368E-5,5.5457048146598E-6,0.25,-3.71622205300215E-7,4.9782548519941E-6,-3.68192208692218E-7,349.9865723,349.9867554,-15614.5341796875,-15549.4755859375,56.9056827140829,20.5401160976515,32.02063,0,0,0,40,4449,350.59035,-15582.0048828125,,,,,,,,,,,,,0,,,,0,,,,,,349.98666385,,,,
,32011768.415,349.9941101,-10827.0649414062,-1.00490988060555E-5,5.978892347637E-7,1,0.999253354069792,40.0298881530762,1.99456734468262,19.6700002998114,-0.000113110306623919,-2.07483652595474E-5,0.25,-1.00166669617894E-7,-1.00312294386128E-5,-1.05577275126392E-7,349.9941101,349.9941101,-10851.83984375,-10802.2900390625,57.0323065341983,20.5381813728997,31.640976,0,0,0,40,4449,350.6104,-10827.0649414062,,,,,,,,,,,,,0,,,,0,,,,,,349.9941101,,,,
,32011860.725,349.9940491,-6213.58837890625,-2.20986973320301E-5,6.38233613899832E-7,1,0.999253354069792,40.0298881530762,1.9946271686691,19.6700002998114,-0.000248543562035072,-4.6791170430151E-5,0.25,-3.23383717593976E-7,-2.20593433356054E-5,-3.35106650904588E-7,349.9940491,349.9940491,-6243.5791015625,-6183.59765625,56.8400259184676,20.537897753338,31.640976,0,0,0,40,4449,350.61925,-6213.58837890625,,,,,,,,,,,,,0,,,,0,,,,,,349.9940491,,,,
,32011952,349.9941101,-1649.84271240234,-2.64217159648206E-5,5.08156416801702E-7,1,0.999253354069792,40.0298881530762,1.99466898834837,19.6700002998114,-0.000297381376176448,-5.47272577854443E-5,0.25,-2.78576753163097E-7,-2.63747228550217E-5,-2.92791888857855E-7,349.9935913,349.9946289,-1679.78479003906,-1619.90063476562,56.983845566006,20.5368973989451,32.02063,0,0,0,40,4449,350.62895,-1649.84271240234,,,,,,,,,,,,,0,,,,-0.00245,,,,,,349.9941101,,,,
,32012041.97,349.9905396,2840.6328125,2.72821165074755E-5,4.12253971844451E-7,1,0.999253354069792,40.0298881530762,1.99455532313686,19.6700002998114,0.000307554596052468,5.35845300435167E-5,0.25,2.85139360830585E-8,2.72337408244083E-5,4.36491502978316E-8,349.9905396,349.9905396,2818.150390625,2863.115234375,56.4241995462367,20.537689085637,32.02063,0,0,0,40,4449,350.63635,2840.6328125,,,,,,,,,,,,,0,,,,0,,,,,,349.9905396,,,,
,32012133.955,349.999176,7440.31640625,2.01437631867683E-5,6.16041255656266E-7,1,0.999253354069792,40.0298881530762,1.9945735478256,19.6700002998114,0.00022691209334816,4.0563065499932E-5,0.25,1.09622419382478E-7,2.01079903176936E-5,1.20634191959965E-7,349.999176,349.999176,7408.080078125,7472.552734375,57.0729512171983,20.5380615910347,31.640976,0,0,0,40,4449,350.63555,7440.31640625,,,,,,,,,,,,,0,,,,0,,,,,,349.999176,,,,
,32012223.91,349.99908445,11936.4829101562,7.87433541048775E-6,6.04365038437811E-7,1,0.999253354069792,40.0298881530762,1.99458769282009,19.6700002998114,9.02676717616729E-5,6.81479452393558E-6,0.25,-7.59045451839172E-7,7.86079761977951E-6,-7.53321947784715E-7,349.9989624,349.9992065,11911.4462890625,11961.51953125,57.1010898438907,20.5403758870031,32.02063,0,0,0,40,4449,350.63135,11936.4829101562,,,,,,,,,,,,,0,,,,0,,,,,,349.99908445,,,,
,32012317.685,350.0010071,16626.576171875,-7.1953357695169E-6,7.94422265747148E-7,1,0.999253354069792,40.0298881530762,1.99466897165917,19.6700002998114,-8.16373102400766E-5,-1.11354695343891E-5,0.25,2.58314951926885E-7,-7.18272297891606E-6,2.53859422557444E-7,350.0010071,350.0010071,16599.197265625,16653.955078125,56.6625962446021,20.5353928898731,32.02063,0,0,0,40,4449,350.6268,16626.576171875,,,,,,,,,,,,,0,,,,0,,,,,,350.0010071,,,,
,32012410.875,350.00328065,21281.13671875,-2.21839554311875E-5,9.57895765353799E-7,1,0.999253354069792,40.0298881530762,1.9945827375306,19.6700002998114,-0.00025143930797849,-3.57537614449005E-5,0.25,6.70162679401783E-7,-2.21449974790858E-5,6.5665875110762E-7,350.002594,350.0039673,21256.244140625,21306.029296875,56.872072687756,20.53725327601,32.02063,0,0,0,40,4449,350.6263,21281.13671875,,,,,,,,,,,,,0,,,,-0.00245,,,,,,350.00328065,,,,
,32012504.765,350.0083618,25974.125,-3.60257064560462E-5,1.15471035831494E-6,1,0.999253354069792,40.0298881530762,1.9947222952052,19.6700002998114,-0.000405623414564853,-7.38300373658259E-5,0.25,-3.09684852263261E-7,-3.59616595699431E-5,-3.29120485179066E-7,350.0081482,350.0085754,25944.064453125,26004.185546875,56.6250780756791,20.5334589532899,32.02063,0,0,0,40,4449,350.62485,25974.125,,,,,,,,,,,,,0,,,,-0.00245,,,,,,350.0083618,,,,
,32012600.755,350.009613,30772.1103515625,-5.17067475592525E-5,1.51748273399701E-6,1,0.999253354069792,40.0298881530762,1.99463161968882,19.6700002998114,-0.000584155949833451,-9.44073996705368E-5,0.25,5.80215726231512E-7,-5.16153904257574E-5,5.50525611974124E-7,350.009613,350.009613,30742.13671875,30802.083984375,56.8603482599676,20.5355059245487,32.02063,0,0,0,40,4449,350.60505,30772.1103515625,,,,,,,,,,,,,0,,,,0.00245,,,,,,350.009613,,,,
,32012696.55,350.0167236,35559.462890625,-6.77228304600403E-5,1.39507218178009E-6,1,0.999253354069792,40.0298881530762,1.99459385533322,19.6700002998114,-0.00076555754158618,-0.000120908958328493,0.25,1.00280164055099E-6,-6.76032957360824E-5,9.63513477549504E-7,350.0167236,350.0167236,35534.5,35584.42578125,56.668849272756,20.5374517717926,32.02063,0,0,0,40,4449,350.5787,35559.462890625,,,,,,,,,,,,,0,,,,-0.00245,,,,,,350.0167236,,,,
,32012794.325,350.020874,40447.349609375,-8.61395232046345E-5,1.4979866742408E-6,1,0.999253354069792,40.0298881530762,1.99466735210653,19.6700002998114,-0.0009755921951972,-0.000143322958094011,0.25,2.20414683239817E-6,-8.59879864228026E-5,2.15257170419611E-6,350.019989,350.021759,40417.26953125,40477.4296875,56.7220000120637,20.5333553319208,32.77993,0,0,0,40,4449,350.58965,40447.349609375,,,,,,,,,,,,,0,,,,-0.00245,,,,,,350.020874,,,,
,32012892.32,350.010437,45345.37890625,-0.00010233489769359,1.67176379563241E-6,1,0.999253354069792,40.0298881530762,1.99475451023592,19.6700002998114,-0.0011543734678474,-0.000197373906731264,0.25,2.15474624602126E-7,-0.000102153579841253,1.58513277759215E-7,350.010437,350.010437,45325.7421875,45365.015625,56.5219031111406,20.5320538607793,32.02063,0,0,0,40,4449,350.5713,45345.37890625,,,,,,,,,,,,,0,,,,0.00245,,,,,,350.010437,,,,
,32012990.44,350.0156097,50250.263671875,-0.000117560744406628,1.99827597565224E-6,1,0.999253354069792,40.0298881530762,1.9947838757369,19.6700002998114,-0.00132636370120824,-0.000225478984060356,0.25,3.59590620520974E-7,-0.00011735249490582,2.9401399648807E-7,350.0150146,350.0162048,50217.66796875,50282.859375,56.5453519667175,20.5333394250041,32.77993,0,0,0,40,4449,350.5575,50250.263671875,,,,,,,,,,,,,0,,,,0,,,,,,350.0156097,,,,
,32013086.105,350.0122986,55030.173828125,-0.000132792321795211,2.24796085963589E-6,1,0.999253354069792,40.0298881530762,1.99450835468722,19.6700002998114,-0.00149988733465116,-0.000243843757913098,0.25,1.36536729251581E-6,-0.000132557639890751,1.28966232297321E-6,350.0122986,350.0122986,55005.3359375,55055.01171875,56.902556200006,20.5346144624723,32.02063,0,0,0,40,4449,350.55905,55030.173828125,,,,,,,,,,,,,0,,,,-0.00245,,,,,,350.0122986,,,,
,32013181.44,350.01437375,59798.1953125,-0.000149153928006065,2.00862755406056E-6,1,0.999253354069792,40.0298881530762,1.99453748617797,19.6700002998114,-0.00168243689205664,-0.000287048417766005,0.25,3.66668328400313E-7,-0.000148889681333362,2.83777541711765E-7,350.0137634,350.0149841,59763.2734375,59833.1171875,56.7517018957945,20.5358039529564,32.02063,0,0,0,40,4449,350.53895,59798.1953125,,,,,,,,,,,,,0,,,,-0.0049,,,,,,350.01437375,,,,
,32013277.395,350.0117035,64591.09765625,-0.000164112314293896,2.28115101058764E-6,1,0.999253354069792,40.0298881530762,1.99464414923709,19.6700002998114,-0.0018534312590313,-0.000303313635565159,0.25,1.51535888182002E-6,-0.000163822200082472,1.42226631634317E-6,350.0112,350.012207,64566.1953125,64616,56.7939098358329,20.533870070121,32.77993,0,0,0,40,4449,350.5204,64591.09765625,,,,,,,,,,,,,0,,,,0.0049,,,,,,350.0117035,,,,
,32013375.12,350.0129089,69476.7109375,-0.00018227247989148,2.34055839292015E-6,1,0.999253354069792,40.0298881530762,1.99467383977091,19.6700002998114,-0.00206122950809213,-0.000321438490491344,0.25,3.05257508821647E-6,-0.000181951015285804,2.94685171748066E-6,350.0129089,350.0129089,69444.3046875,69509.1171875,56.7485753817175,20.5323787196917,32.40028,0,0,0,40,4449,350.51545,69476.7109375,,,,,,,,,,,,,0,,,,0,,,,,,350.0129089,,,,
,32013470.86,350.0137024,74264.1015625,-0.000198568960416498,1.97912418746405E-6,1,0.999253354069792,40.0298881530762,1.99448115914888,19.6700002998114,-0.00224143560693866,-0.000372529441059403,0.25,1.34004501570711E-6,-0.000198217663864198,1.22849658718249E-6,350.0137024,350.0137024,74236.71875,74291.484375,56.7493570102368,20.534793734312,32.40028,0,0,0,40,4449,350.51375,74264.1015625,,,,,,,,,,,,,0,,,,0,,,,,,350.0137024,,,,
,32013565.845,350.01751705,79010.078125,-0.000215175953817876,2.57767997209798E-6,1,0.999253354069792,40.0298881530762,1.99448622549296,19.6700002998114,-0.00242758551611582,-0.000411278784142262,0.25,7.78596254784743E-7,-0.000214794887395245,6.59028755867718E-7,350.0170898,350.0179443,78979.9765625,79040.1796875,56.6250780756791,20.5341376596909,32.40028,0,0,0,40,4449,350.51035,79010.078125,,,,,,,,,,,,,0,,,,0,,,,,,350.01751705,,,,
,32013662.365,350.01647945,83835.8828125,-0.000227059122613603,2.90738229989017E-6,1,0.999253354069792,40.0298881530762,1.9943445050977,19.6700002998114,-0.00256032881294867,-0.000440589348927885,0.25,2.33669456773978E-7,-0.000226656705391326,1.08659363251469E-7,350.0163879,350.016571,83803.3125,83868.453125,56.689171614256,20.5351305871791,32.40028,0,0,0,40,4449,350.48465,83835.8828125,,,,,,,,,,,,,0,,,,-0.0049,,,,,,350.01647945,,,,
,32013753.915,350.0084534,88413.9453125,-0.000245876611339794,3.58677050909358E-6,1,0.999253354069792,40.0298881530762,1.99465691569715,19.6700002998114,-0.00277937387286452,-0.000439963744143241,0.25,3.5529889000191E-6,-0.000245442729191037,3.41190103403261E-6,350.0084534,350.0084534,88381.828125,88446.0625,56.6680676442368,20.530953755524,32.40028,0,0,0,40,4449,350.4846,88413.9453125,,,,,,,,,,,,,0,,,,0.00245,,,,,,350.0084534,,,,
,32013859.49,350.0077515,87053.2265625,-0.000242271334450292,3.23263204458223E-6,1,0.999253354069792,40.0298881530762,1.99444191296606,19.6700002998114,-0.00273642069010023,-0.000444543326442241,0.25,2.51859912316826E-6,-0.000241843279114068,2.38128339609528E-6,350.0077515,350.0077515,87053.2265625,87053.2265625,56.7243448976214,20.5341171319228,32.40028,0,0,0,40,4449,350.487,87053.2265625,,,,,,,,,,,,,0,,,,0.0049,,,,,,350.0077515,,,,
,32013951.01,349.9981537,82476.953125,-0.000222341914607147,2.9221899467542E-6,1,0.999253354069792,40.0298881530762,1.99441090520504,19.6700002998114,-0.00250982631793564,-0.000416388748260999,0.25,1.56472765799655E-6,-0.000221948725961985,1.43991258802411E-6,349.9980469,349.9982605,82444.9609375,82508.9453125,56.861911517006,20.535077973535,32.40028,0,0,0,40,4449,350.4864,82476.953125,,,,,,,,,,,,,0,,,,-0.0049,,,,,,349.9981537,,,,
,32014045.66,349.9976807,77748.58203125,-0.00020771045833229,3.14948743738456E-6,1,0.999253354069792,40.0298881530762,1.99483237654717,19.6700002998114,-0.0023411745842617,-0.000411953389380679,0.25,-5.67725691580107E-7,-0.000207342024564961,-6.80842577823551E-7,349.9976807,349.9976807,77746.046875,77751.1171875,57.0698247031214,20.5281944488879,32.77993,0,0,0,40,4449,350.4908,77748.58203125,,,,,,,,,,,,,0,,,,0,,,,,,349.9976807,,,,
,32014141.16,349.9937134,72972.37109375,-0.000193386181213759,2.67547182601174E-6,1,0.999253354069792,40.0298881530762,1.9946632824767,19.6700002998114,-0.00218503946746289,-0.00035177752034924,0.25,2.28601477354313E-6,-0.000193044721380714,2.17560601564866E-6,349.9937134,349.9937134,72937.484375,73007.2578125,57.0768593597945,20.5330334624722,32.77993,0,0,0,40,4449,350.4944,72972.37109375,,,,,,,,,,,,,0,,,,0,,,,,,349.9937134,,,,
,32014236.455,349.9911041,68209.046875,-0.000174703883234983,2.63141683106028E-6,1,0.999253354069792,40.0298881530762,1.99473111755758,19.6700002998114,-0.00197485592745457,-0.000312949303217376,0.25,2.49578992628324E-6,-0.000174395657209084,2.39519284335628E-6,349.9906311,349.9915771,68183.9140625,68234.1796875,56.6203883045637,20.5326418986408,32.77993,0,0,0,40,4449,350.50465,68209.046875,,,,,,,,,,,,,0,,,,0,,,,,,349.9911041,,,,
,32014333.21,349.9903717,63374.048828125,-0.000160612917330852,2.14613302437067E-6,1,0.999253354069792,40.0298881530762,1.99466280163517,19.6700002998114,-0.00181024750318254,-0.000318103778569423,0.25,-4.01937926164542E-7,-0.000160328064699108,-4.8972759735555E-7,349.9903564,349.990387,63346.52734375,63401.5703125,56.770460980256,20.5329965855209,32.40028,0,0,0,40,4449,350.51285,63374.048828125,,,,,,,,,,,,,0,,,,-0.0049,,,,,,349.9903717,,,,
,32014429.5,349.9938965,58560.615234375,-0.000143449304111382,1.78942366849648E-6,1,0.999253354069792,40.0298881530762,1.99459011112803,19.6700002998114,-0.00161930639414492,-0.000269290397026573,0.25,9.5455928301907E-7,-0.000143195593438534,8.73749344758733E-7,349.9938965,349.9938965,58532.84375,58588.38671875,56.6962062709291,20.5344313779532,32.77993,0,0,0,40,4449,350.5237,58560.615234375,,,,,,,,,,,,,0,,,,0,,,,,,349.9938965,,,,
,32014524.555,349.9863281,53810.146484375,-0.000129807766897267,1.84409140396579E-6,1,0.999253354069792,40.0298881530762,1.99450564999227,19.6700002998114,-0.00146279837919759,-0.000257871679075377,0.25,-3.95554762722328E-7,-0.000129577516683088,-4.6651398311098E-7,349.9863281,349.9863281,53785.19921875,53835.09375,56.8017261210252,20.5361154582582,32.77993,0,0,0,40,4449,350.5297,53810.146484375,,,,,,,,,,,,,0,,,,0.00245,,,,,,349.9863281,,,,
,32014618.23,349.9858398,49127.65234375,-0.000112906000640276,1.97162180254593E-6,1,0.999253354069792,40.0298881530762,1.99484395301328,19.6700002998114,-0.00127684439071397,-0.00019946623971097,0.25,1.86101127104874E-6,-0.000112706946363985,1.79532893596052E-6,349.9858398,349.9858398,49097.64453125,49157.66015625,56.699332785006,20.532470102849,32.40028,0,0,0,40,4449,350.53995,49127.65234375,,,,,,,,,,,,,0,,,,0.00245,,,,,,349.9858398,,,,
,32014712.93,349.9854431,44392.041015625,-9.69621298601038E-5,1.98673005654901E-6,1,0.999253354069792,40.0298881530762,1.99465027503344,19.6700002998114,-0.0010916828936885,-0.000198727685832582,0.25,-8.35711724757265E-7,-9.67898372678598E-5,-8.87853044776092E-7,349.9854431,349.9854431,44389.41015625,44394.671875,56.831428004756,20.5390934862281,32.40028,0,0,0,40,4449,350.54575,44392.041015625,,,,,,,,,,,,,0,,,,0.0049,,,,,,349.9854431,,,,
,32014808.71,349.9893494,39606.662109375,-8.15016861430907E-5,1.70424106782087E-6,1,0.999253354069792,40.0298881530762,1.99477165754317,19.6700002998114,-0.000920461378069537,-0.000150923969068541,0.25,7.27708134476227E-7,-8.13576428861971E-5,6.81307026539423E-7,349.9893494,349.9893494,39601.44140625,39611.8828125,56.8267382336406,20.5356921141686,32.77993,0,0,0,40,4449,350.55505,39606.662109375,,,,,,,,,,,,,0,,,,0.00245,,,,,,349.9893494,,,,
,32014902.275,349.9968567,34929.59765625,-6.63726053343256E-5,1.43538521103309E-6,1,0.999253354069792,40.0298881530762,1.99465715122274,19.6700002998114,-0.000748595770799038,-0.00012844539453645,0.25,1.00973323106688E-7,-6.62550094480997E-5,6.4025854776029E-8,349.9967957,349.9969177,34909.34375,34949.8515625,56.6743206723906,20.5367706397008,32.40028,0,0,0,40,4449,350.55725,34929.59765625,,,,,,,,,,,,,0,,,,0,,,,,,349.9968567,,,,
,32014999.055,349.9856415,30094.9296875,-5.04267929234616E-5,9.73241611750078E-7,1,0.999253354069792,40.0298881530762,1.99465349395695,19.6700002998114,-0.000571750201533907,-8.02429479274509E-5,0.25,1.61488791876321E-6,-5.03383192221094E-5,1.58406659555508E-6,349.9850769,349.9862061,30067.537109375,30122.322265625,56.6876083572175,20.536919693773,32.77993,0,0,0,40,4449,350.5524,30094.9296875,,,,,,,,,,,,,0,,,,0,,,,,,349.9856415,,,,
,32015096.29,349.9869537,25231.9111328125,-3.438778889405E-5,1.31976819823661E-6,1,0.999253354069792,40.0298881530762,1.99467024081329,19.6700002998114,-0.000388722744611839,-6.15171172073153E-5,0.25,4.98536620794235E-7,-3.43271189916535E-5,4.78571821810313E-7,349.9865112,349.9873962,25199.322265625,25264.5,56.8861420011022,20.5384379886255,33.159584,0,0,0,40,4449,350.57415,25231.9111328125,,,,,,,,,,,,,0,,,,0,,,,,,349.9869537,,,,
,32015192.635,349.9889832,20417.009765625,-1.84216566945626E-5,9.42951645983866E-7,1,0.999253354069792,40.0298881530762,1.99478486561161,19.6700002998114,-0.000207152778377721,-3.93023151797182E-5,0.25,-2.95655059746044E-7,-1.83888413884512E-5,-3.05360810997614E-7,349.9889832,349.9889832,20412.37109375,20421.6484375,56.9611783389483,20.5378955812146,32.77993,0,0,0,40,4449,350.58285,20417.009765625,,,,,,,,,,,,,0,,,,-0.00245,,,,,,349.9889832,,,,
,32015287.075,349.99012755,15699.720703125,-4.64862474496898E-6,7.96973186090418E-7,1,0.999253354069792,40.0298881530762,1.99471687364916,19.6700002998114,-5.32034455207143E-5,-4.54031831190222E-6,0.25,4.02257755690341E-7,-4.6406085955213E-6,3.98961464938913E-7,349.9887695,349.9914856,15669.5947265625,15729.8466796875,56.6766655579483,20.538724145876,32.77993,0,0,0,40,4449,350.59345,15699.720703125,,,,,,,,,,,,,0,,,,0,,,,,,349.99012755,,,,
,32015383.315,349.9874573,10890.0600585938,1.01333458306933E-5,7.03061345519141E-7,1,0.999253354069792,40.0298881530762,1.99481706164348,19.6700002998114,0.000114462268835335,1.86722031723777E-5,0.25,-9.87540176098245E-8,1.01154400033187E-5,-9.29437973373441E-8,349.9874573,349.9874573,10862.421875,10917.6982421875,56.8126689202945,20.5365966584414,33.159584,0,0,0,40,4449,350.5966,10890.0600585938,,,,,,,,,,,,,0,,,,0.00245,,,,,,349.9874573,,,,
,32015478.305,349.9925537,6139.68530273437,2.3345894006043E-5,5.21183268200529E-7,1,0.999253354069792,40.0298881530762,1.99467855401734,19.6700002998114,0.000262832369023108,4.79596303015561E-5,0.25,2.10952481456605E-7,2.33043927667044E-5,2.23569784010375E-7,349.9925537,349.9925537,6114.5009765625,6164.86962890625,57.0502839901407,20.540041554584,32.77993,0,0,0,40,4449,350.59285,6139.68530273437,,,,,,,,,,,,,0,,,,0,,,,,,349.9925537,,,,
,32015572.78,349.9912109,1418.49523925781,2.59473834771592E-5,5.01566921401568E-7,1,0.999253354069792,40.0298881530762,1.99479175736165,19.6700002998114,0.000292159149283436,5.31745127062715E-5,0.25,2.22722907998349E-7,2.59012647497146E-5,2.36774256879925E-7,349.9912109,349.9912109,1396.04162597656,1440.94885253906,56.8767624588714,20.5440740098169,33.159584,0,0,0,40,4449,350.6064,1418.49523925781,,,,,,,,,,,,,0,,,,-0.00245,,,,,,349.9912109,,,,
,32015600.835,349.9918518,-0.479548841714859,4.69570873471986E-6,5.2220242683051E-7,1,0.999253354069792,40.0298881530762,1.99493313581041,19.6700002998114,5.34144999453178E-5,6.51215187793528E-6,0.25,-2.35605789284376E-7,4.68751611557528E-6,-2.32573591870071E-7,349.9918518,349.9918518,-0.563279569149017,-0.395818114280701,56.8759808303522,20.5362435519634,32.40028,0,0,0,40,4417,350.61555,-0.479548841714859,,,,,,,,,,,,,0,,,,0.00245,,,,,,349.9918518,,,,