File: data/monolayers/magneticStructure/ML_Ac_CoFe_C-2/PPMS/data/DD175_23_HYST_2K_100OE.DAT
[Header]
; VSM Data File (default extension .dat)
; Copyright (c) 2003, Quantum Design, Inc. All rights reserved.
TITLE,
FILEOPENTIME,46569311.72,04/05/2017,10:11 am
BYAPP,VSM,1.0,1.0
INFO,PPMS VSM Option Release 1.3.7 Build 2,APPNAME
INFO,291,COIL_SERIAL_NUMBER
INFO,0,MOMENT_UNITS
INFO,CoFe2O4,SAMPLE_MATERIAL
INFO,,SAMPLE_COMMENT
INFO,,SAMPLE_MASS
INFO,,SAMPLE_VOLUME
INFO,,SAMPLE_MOLECULAR_WEIGHT
INFO,,SAMPLE_SIZE
INFO,,SAMPLE_SHAPE
INFO,36.48,SAMPLE_OFFSET
DATATYPE,COMMENT,1
DATATYPE,TIME,2
STARTUPAXIS,X,2
STARTUPAXIS,Y1,5
[Data]
Comment,Time Stamp (sec),Temperature (K),Magnetic Field (Oe),Moment (emu),M. Std. Err. (emu),Transport Action,Averaging Time (sec),Frequency (Hz),Peak Amplitude (mm),Center Position (mm),Coil Signal' (mV),Coil Signal" (mV),Range (mV),M. Quad. Signal (emu),M. Raw' (emu),M. Raw" (emu),Min. Temperature (K),Max. Temperature (K),Min. Field (Oe),Max. Field (Oe),Mass (grams),Motor Lag (deg),Pressure (Torr),VSM Status (code),Motor Status (code),Measure Status (code),PPMS Status (code),System Temp. (K),System Field (Oe),Sample Position (deg),Bridge 1 Resistance (ohms),Bridge 1 Excitation (에),Bridge 2 Resistance (ohms),Bridge 2 Excitation (에),Bridge 3 Resistance (ohms),Bridge 3 Excitation (에),Bridge 4 Resistance (ohms),Bridge 4 Excitation (에),Signal 1 Vin (V),Signal 2 Vin (V),Digital Inputs (code),Drive 1 Iout (mA),Drive 1 Ipower (W),Drive 2 Iout (mA),Drive 2 Ipower (W),Pressure (),Map 20 (),Map 21 (),Map 22 (),Map 23 (),Map 24 (),Map 25 (),Map 26 (),Map 27 (),Map 28 (),Map 29 ()
,46575460.97,1.9988602,-0.320900738239288,1.06994268724059E-5,2.21321940841282E-7,1,0.999253354069792,40.0298881530762,1.99532945253506,15.5500008817762,0.000119726817078882,-5.97634200799194E-6,0.25,-2.43965252051834E-6,1.06413765734352E-5,-2.40155604105827E-6,1.9979573,1.9997631,-0.336181730031967,-0.305619746446609,52.2784418802363,18.674789855212,0.98177705,0,0,0,4417,1.85825,-0.320900738239288,,,,,,,,,,,,,,,,,11.876877,,,,,,1.9988602,,,,
,46575554.955,2.00220115,3991.32214355469,2.36836546789487E-5,4.63532135208459E-7,1,0.999253354069792,40.0298881530762,1.99533693991759,15.5500008817762,0.000256670643894483,3.42795734176829E-5,0.25,-9.87645571102536E-7,2.35467648893427E-5,-9.2629770297067E-7,1.999437,2.0049653,3968.83764648438,4013.806640625,52.3769270736594,18.6766232194465,0.96721125,0,0,0,4449,1.85725,3991.32214355469,,,,,,,,,,,,,,,,,12.627627,,,,,,2.00220115,,,,
,46575634.17,2.0086335,7946.98876953125,2.22535086141199E-5,1.08891935320703E-6,1,0.999253354069792,40.0298881530762,1.99487449016205,15.5500008817762,0.000240254004367385,3.72141752853396E-5,0.25,-4.66196119564515E-7,2.21254459529965E-5,-4.07453234489378E-7,2.0056863,2.0115807,7924.60107421875,7969.37646484375,53.0037931460825,18.6747303268128,0.95759705,0,0,0,4453,1.8538,7946.98876953125,,,,,,,,,,,,,,,,,11.876877,,,,,,2.0086335,,,,
,46575712.665,2.0014416,11872.7060546875,2.17520820149173E-5,9.98078396604014E-7,1,0.999253354069792,40.0298881530762,1.9953975580445,15.5500008817762,0.000234098783481346,4.10324532501707E-5,0.25,-2.81018478802128E-8,2.1627628358051E-5,3.08918495127911E-8,2.0007694,2.0021138,11847.7490234375,11897.6630859375,52.4949529800632,18.6803183924682,0.95759705,0,0,0,4453,1.8533,11872.7060546875,,,,,,,,,,,,,,,,,13.003003,,,,,,2.0014416,,,,
,46575792.91,2.0120114,15883.5107421875,1.47357306798687E-5,8.63718430824117E-7,1,0.999253354069792,40.0298881530762,1.99530288394238,15.5500008817762,0.000156730192400036,3.83522061908808E-5,0.25,9.58850214532591E-7,1.46500022131192E-5,9.96249235429998E-7,2.0101132,2.0139096,15856.1787109375,15910.8427734375,53.300030354871,18.6790748763216,0.9386544,0,0,0,4449,1.8519,15883.5107421875,,,,,,,,,,,,,,,,,12.252253,,,,,,2.0120114,,,,
,46575872.725,2.0063071,19871.025390625,9.84960852205031E-6,7.56276782161245E-7,1,0.999253354069792,40.0298881530762,1.99532200718251,15.5500008817762,0.000108108362678491,6.79117332755433E-6,0.25,-1.11254522729324E-6,9.79867852856718E-6,-1.07579293258736E-6,2.0042195,2.0083947,19843.50390625,19898.546875,52.4472736403902,18.6826761445357,0.929324,0,0,0,4453,1.849,19871.025390625,,,,,,,,,,,,,,,,,12.252253,,,,,,2.0063071,,,,
,46575956.93,2.01264905,24079.0224609375,5.22401082231497E-6,7.84863142819116E-7,1,0.999253354069792,40.0298881530762,1.99521915278296,15.5500008817762,5.83814384484753E-5,-2.2500770035445E-6,0.25,-1.13506032810843E-6,5.19959013630984E-6,-1.11156582618372E-6,2.0070159,2.0182822,24051.560546875,24106.484375,52.8693530407748,18.684446427913,0.92008645,0,0,0,4449,1.8483,24079.0224609375,,,,,,,,,,,,,,,,,13.003003,,,,,,2.01264905,,,,
,46576038.94,2.01473185,28177.2158203125,1.00383201390951E-6,9.9774223505321E-7,1,0.999253354069792,40.0298881530762,1.99534277637706,15.5500008817762,1.03287668195864E-5,4.59557025536796E-6,0.25,2.48834432910994E-7,9.97667458562287E-7,2.51074339826961E-7,2.0142257,2.015238,28149.837890625,28204.59375,52.7552352769671,18.6809026312625,0.906368,0,0,0,4453,1.8479,28177.2158203125,,,,,,,,,,,,,,,,,13.003003,,,,,,2.01473185,,,,
,46576119.515,2.02665295,32204.884765625,-7.9410467576185E-6,8.90184102760551E-7,1,0.999253354069792,40.0298881530762,1.99530612679565,15.5500008817762,-8.51336431744877E-5,-1.71121828224641E-5,0.25,-1.78792980577017E-7,-7.89969038552441E-6,-2.07597362768028E-7,2.0260625,2.0272434,32182.37109375,32227.3984375,52.2151299701786,18.683112198036,0.8973586,0,0,0,4454,1.848,32204.884765625,,,,,,,,,,,,,,,,,11.876877,,,,,,2.02665295,,,,
,46576200.625,2.02988825,36260.158203125,-1.94080826404281E-5,7.68228275137559E-7,1,0.999253354069792,40.0298881530762,1.99517896577516,15.5500008817762,-0.00020945080163097,-3.41588584296152E-5,0.25,2.79299265522771E-7,-1.93126876730776E-5,2.01302060079916E-7,2.0289752,2.0308013,36235.23046875,36285.0859375,52.6778540535633,18.6866653041017,0.9018858,0,0,0,4454,1.8466,36260.158203125,,,,,,,,,,,,,,,,,12.252253,,,,,,2.02988825,,,,
,46576282.78,2.04313895,40365.75390625,-3.12329697812993E-5,1.03832869278317E-6,1,0.999253354069792,40.0298881530762,1.99522436818484,15.5500008817762,-0.000334430950041292,-7.01243723780204E-5,0.25,-9.50740607020509E-7,-3.10788274829973E-5,-1.07578288387246E-6,2.0430326,2.0432453,40338.25,40393.2578125,53.0077012886787,18.6809031546247,0.9108952,0,0,0,4454,1.8475,40365.75390625,,,,,,,,,,,,,,,,,12.252253,,,,,,2.04313895,,,,
,46576363.29,2.0418092,44388.404296875,-4.27533471442846E-5,1.0902178448046E-6,1,0.999253354069792,40.0298881530762,1.9952374315993,15.5500008817762,-0.000457687224761176,-9.70027690458589E-5,0.25,-1.38569320633306E-6,-4.25489382282108E-5,-1.56494239680504E-6,2.0412562,2.0423622,44370.984375,44405.82421875,52.6223584286979,18.687013541158,0.89292095,0,0,0,4454,1.84865,44388.404296875,,,,,,,,,,,,,,,,,12.627627,,,,,,2.0418092,,,,
,46576444.165,2.0560646,48431.515625,-5.67573228560212E-5,9.90197301572047E-7,1,0.999253354069792,40.0298881530762,1.99507762820865,15.5500008817762,-0.000607986261701783,-0.000126979124419271,0.25,-1.66085022933871E-6,-5.64964991019662E-5,-1.91059155518821E-6,2.0547469,2.0573823,48409.02734375,48454.00390625,52.7943167029287,18.6869936743376,0.8928764,0,0,0,4454,1.84885,48431.515625,,,,,,,,,,,,,,,,,13.003003,,,,,,2.0560646,,,,
,46576524.205,2.0569949,52432.15234375,-6.89811053595707E-5,1.17344810207713E-6,1,0.999253354069792,40.0298881530762,1.99517506319868,15.5500008817762,-0.000739895653795048,-0.000149877089315816,0.25,-1.58986939218993E-6,-6.8678387047796E-5,-1.90792613402318E-6,2.0536463,2.0603435,52407.09375,52457.2109375,52.8763876974479,18.6891118632001,0.8840452,0,0,0,4454,1.84625,52432.15234375,,,,,,,,,,,,,,,,,13.003003,,,,,,2.0569949,,,,
,46576606.22,2.06091645,56529.951171875,-8.31376751589443E-5,1.52406752299174E-6,1,0.999253354069792,40.0298881530762,1.99515254114786,15.5500008817762,-0.000889436781670051,-0.000194448164330435,0.25,-3.1808383737942E-6,-8.27824653151438E-5,-3.5739244825394E-6,2.0575302,2.0643027,56504.85546875,56555.046875,52.6309563424094,18.6896143440244,0.8885274,0,0,0,4454,1.8482,56529.951171875,,,,,,,,,,,,,,,,,13.003003,,,,,,2.06091645,,,,
,46576686.875,2.02417435,60560.990234375,-9.69669635602199E-5,1.60577396358532E-6,1,0.999253354069792,40.0298881530762,1.99540175425318,15.5500008817762,-0.00103663249545413,-0.000232877652682306,0.25,-4.25223520145741E-6,-9.65684248136747E-5,-4.72520779138137E-6,2.0186055,2.0297432,60533.67578125,60588.3046875,52.6051626012748,18.6796381002014,0.87960755,0,0,0,4454,1.85025,60560.990234375,,,,,,,,,,,,,,,,,11.876877,,,,,,2.02417435,,,,
,46576767.975,2.0264926,64616.48046875,-0.000110689820926793,1.64862081095281E-6,1,0.999253354069792,40.0298881530762,1.99523466107222,15.5500008817762,-0.00118602340242964,-0.000251666237104175,0.25,-3.51905047334651E-6,-0.000110263587756075,-4.08211654318375E-6,2.0264783,2.0265069,64586.27734375,64646.68359375,52.4879183233902,18.6854106532144,0.8665575,0,0,0,4454,1.84885,64616.48046875,,,,,,,,,,,,,,,,,13.003003,,,,,,2.0264926,,,,
,46576848.455,2.02739895,68637.6875,-0.000125181442498591,1.30692624801521E-6,1,0.999253354069792,40.0298881530762,1.99529478870055,15.5500008817762,-0.00133989107291207,-0.00029426067278725,0.25,-4.85044434028192E-6,-0.0001247199691399,-5.503219077362E-6,2.0259209,2.028877,68610.09375,68665.28125,52.7966615884864,18.6837950448553,0.8493733,0,0,0,4454,1.8469,68637.6875,,,,,,,,,,,,,,,,,11.876877,,,,,,2.02739895,,,,
,46576929.67,2.03643605,72697.69921875,-0.000138593880928483,1.07034762823977E-6,1,0.999253354069792,40.0298881530762,1.99529965953727,15.5500008817762,-0.00149057627552083,-0.000287903761316313,0.25,-1.83060748949552E-6,-0.00013813099429641,-2.58505730070475E-6,2.0335824,2.0392897,72672.875,72722.5234375,52.6958315095056,18.6845933238654,0.8493733,0,0,0,4454,1.8517,72697.69921875,,,,,,,,,,,,,,,,,12.252253,,,,,,2.03643605,,,,
,46577011.04,2.04396665,76763.359375,-0.000151518107217251,1.63043156218522E-6,1,0.999253354069792,40.0298881530762,1.99522165534335,15.5500008817762,-0.00163021627926689,-0.000312857738328393,0.25,-1.80123726573804E-6,-0.000151045495656794,-2.64644935958908E-6,2.0436299,2.0443034,76735.8046875,76790.9140625,52.7528903914094,18.687629337036,0.85363715,0,0,0,4454,1.8535,76763.359375,,,,,,,,,,,,,,,,,11.876877,,,,,,2.04396665,,,,
,46577091.825,2.0409539,80802.1953125,-0.000167465017724383,1.0544734229743E-6,1,0.999253354069792,40.0298881530762,1.99534028581323,15.5500008817762,-0.00180369432379289,-0.000338022194914366,0.25,-1.24279902580247E-6,-0.000166982844059134,-2.19916321764225E-6,2.0400012,2.0419066,80774.6796875,80829.7109375,52.1916811146017,18.6833948067752,0.857901,0,0,0,4454,1.85265,80802.1953125,,,,,,,,,,,,,,,,,13.003003,,,,,,2.0409539,,,,
,46577172.19,2.02874695,84817.05859375,-0.000180838909833399,1.13789799986292E-6,1,0.999253354069792,40.0298881530762,1.99529629111811,15.5500008817762,-0.00194385933543084,-0.000388777268626616,0.25,-3.51895661914188E-6,-0.000180344412299083,-4.56564174497072E-6,2.0284586,2.0290353,84787.0625,84847.0546875,52.0799082363517,18.6813792504498,0.8325715,0,0,0,4454,1.8536,84817.05859375,,,,,,,,,,,,,,,,,12.252253,,,,,,2.02874695,,,,
,46577250.525,2.03410565,88735.57421875,-0.000191519958692942,1.30688353278782E-6,1,0.999253354069792,40.0298881530762,1.9952547342934,15.5500008817762,-0.00206041931920147,-0.000404289946311948,0.25,-3.01089261687776E-6,-0.000191040641933153,-4.14017946073253E-6,2.0322404,2.0359709,88710.65625,88760.4921875,53.2789263848518,18.6847856807165,0.8409724,0,0,0,4454,1.85345,88735.57421875,,,,,,,,,,,,,,,,,13.003003,,,,,,2.03410565,,,,
,46577343.79,2.0246699,87439.33984375,-0.00018808051927009,1.522422771259E-6,1,0.999253354069792,40.0298881530762,1.99513890659301,15.5500008817762,-0.00202024990521597,-0.000413182435959591,0.25,-4.46447499214514E-6,-0.000187587836032767,-5.56378808774122E-6,2.023917,2.0254228,87411.8046875,87466.875,52.4808836667171,18.6848987007012,0.83261305,0,0,0,4454,1.8421,87439.33984375,,,,,,,,,,,,,,,,,11.876877,,,,,,2.0246699,,,,
,46577421.36,2.0176737,83563.64453125,-0.000176066885207069,1.50246308043401E-6,1,0.999253354069792,40.0298881530762,1.99534305931224,15.5500008817762,-0.00189340067254574,-0.000373374117204289,0.25,-2.95644045102373E-6,-0.000175576388060672,-3.97083130590701E-6,2.0155935,2.0197539,83538.6484375,83588.640625,52.1103917486017,18.6850300864052,0.8493733,0,0,0,4454,1.83325,83563.64453125,,,,,,,,,,,,,,,,,13.003003,,,,,,2.0176737,,,,
,46577500.43,2.0206052,79610.76171875,-0.000163190585838368,1.16663756491109E-6,1,0.999253354069792,40.0298881530762,1.99529620901242,15.5500008817762,-0.00175421389507823,-0.000347693387000415,0.25,-2.91595324003851E-6,-0.000162700629273879,-3.83740123680561E-6,2.0193522,2.0218582,79580.90625,79640.6171875,52.809167644794,18.6891402728349,0.8242956,0,0,0,4454,1.8314,79610.76171875,,,,,,,,,,,,,,,,,11.876877,,,,,,2.0206052,,,,
,46577580.86,2.02242805,75589.75,-0.000145384906508171,1.4603004215275E-6,1,0.999253354069792,40.0298881530762,1.99516070256541,15.5500008817762,-0.00155903342027199,-0.000328298841519267,0.25,-4.34287560418448E-6,-0.000144907841189388,-5.14040487375421E-6,2.0223303,2.0225258,75562.375,75617.125,52.7990064740441,18.6902217110511,0.8409305,0,0,0,4454,1.83005,75589.75,,,,,,,,,,,,,,,,,11.876877,,,,,,2.02242805,,,,
,46577660.14,2.01357915,71629.38671875,-0.000133559834820822,1.12598963777073E-6,1,0.999253354069792,40.0298881530762,1.99534504528023,15.5500008817762,-0.00143618545459924,-0.000278552020479462,0.25,-1.87223653804161E-6,-0.000133105748968926,-2.59412343337671E-6,2.012821,2.0143373,71604.34375,71654.4296875,52.5832770027363,18.6909569441798,0.8451519,0,0,0,4453,1.8294,71629.38671875,,,,,,,,,,,,,,,,,13.003003,,,,,,2.01357915,,,,
,46577740.13,2.01627635,67629.296875,-0.000120134063492445,1.27032186873875E-6,1,0.999253354069792,40.0298881530762,1.99518539716463,15.5500008817762,-0.00128945669795844,-0.000261604515058684,0.25,-2.73266571911426E-6,-0.00011969532330064,-3.36139003053396E-6,2.0145793,2.0179734,67606.84375,67651.75,52.6958315095056,18.6932578517125,0.83261305,0,0,0,4453,1.8285,67629.296875,,,,,,,,,,,,,,,,,12.252253,,,,,,2.01627635,,,,
,46577820.53,2.01623035,63610.720703125,-0.000109163359751511,1.54268073902791E-6,1,0.999253354069792,40.0298881530762,1.99517353116965,15.5500008817762,-0.0011768990851439,-0.000207295895373516,0.25,3.19190226173584E-7,-0.000108757158186875,-2.45966949676626E-7,2.0146501,2.0178106,63578.23828125,63643.203125,52.0502063526209,18.6869945499471,0.82433675,0,0,0,4453,1.82785,63610.720703125,,,,,,,,,,,,,,,,,13.003003,,,,,,2.01623035,,,,
,46577899.105,2.0098021,59682.537109375,-9.47663322363181E-5,1.26384290893287E-6,1,0.999253354069792,40.0298881530762,1.99527007211741,15.5500008817762,-0.00101813086257685,-0.000198907975874366,0.25,-1.49888095399421E-6,-9.43861893663868E-5,-1.96807441305422E-6,2.0096955,2.0099087,59655.09375,59709.98046875,52.4558715541017,18.6899127320199,0.8325715,0,0,0,4453,1.82725,59682.537109375,,,,,,,,,,,,,,,,,11.876877,,,,,,2.0098021,,,,
,46577978.46,2.01443975,55718.90234375,-8.27180059012934E-5,1.37960664823418E-6,1,0.999253354069792,40.0298881530762,1.9952562110151,15.5500008817762,-0.000883449955822799,-0.000201894541619349,0.25,-3.94976887589226E-6,-8.23576656003822E-5,-4.33469946928421E-6,2.0141819,2.0146976,55696.43359375,55741.37109375,53.0757029698518,18.6896227625028,0.8325715,0,0,0,4449,1.8268,55718.90234375,,,,,,,,,,,,,,,,,11.876877,,,,,,2.01443975,,,,
,46578057.41,2.00732435,51771.193359375,-6.81478576384782E-5,1.15810280330546E-6,1,0.999253354069792,40.0298881530762,1.99530007327056,15.5500008817762,-0.000732011321530827,-0.000142293662242317,0.25,-1.03625780509272E-6,-6.78492491723284E-5,-1.35075141108663E-6,2.0070665,2.0075822,51743.796875,51798.58984375,53.1054048535825,18.6939758600332,0.836751,0,0,0,4449,1.82645,51771.193359375,,,,,,,,,,,,,,,,,11.876877,,,,,,2.00732435,,,,
,46578137.095,2.0050328,47787.72265625,-5.49408632686153E-5,1.02240531484333E-6,1,0.999253354069792,40.0298881530762,1.99522962924387,15.5500008817762,-0.000593711033975705,-9.40243466179506E-5,0.25,1.07402208317372E-6,-5.46989230222373E-5,8.2189128074689E-7,2.0043602,2.0057054,47765.27734375,47810.16796875,52.8107309018325,18.6911693169781,0.81614275,0,0,0,4449,1.8264,47787.72265625,,,,,,,,,,,,,,,,,12.252253,,,,,,2.0050328,,,,
,46578216.71,2.00178015,43812.099609375,-4.14287718597741E-5,9.09275800992953E-7,1,0.999253354069792,40.0298881530762,1.99527298273334,15.5500008817762,-0.000444996143048174,-8.56272380413036E-5,0.25,-5.66598201322481E-7,-4.12330600145803E-5,-7.42750692136038E-7,2.0012374,2.0023229,43787.171875,43837.02734375,53.4954374846787,18.6937060413432,0.8079899,0,0,0,4449,1.82595,43812.099609375,,,,,,,,,,,,,,,,,12.252253,,,,,,2.00178015,,,,
,46578296.85,2.0021651,39803.892578125,-2.80831404427952E-5,1.12764213106269E-6,1,0.999253354069792,40.0298881530762,1.99509044148803,15.5500008817762,-0.000301156377577433,-6.03607965305158E-5,0.25,-6.06105124100672E-7,-2.79449495317441E-5,-7.18949082658407E-7,2.0021639,2.0021663,39778.7265625,39829.05859375,51.9431232454863,18.6922053928513,0.81614275,0,0,0,4449,1.8257,39803.892578125,,,,,,,,,,,,,,,,,12.252253,,,,,,2.0021651,,,,
,46578374.72,1.9975973,35913.67578125,-1.5889228666577E-5,8.48276565348473E-7,1,0.999253354069792,40.0298881530762,1.9953799568123,15.5500008817762,-0.000176440419403266,-1.34530598006535E-7,0.25,2.81385108013678E-6,-1.58210732180264E-5,2.73737957745376E-6,1.9965945,1.9986001,35891.12109375,35936.23046875,52.8662265266979,18.6907370556429,0.8079899,0,0,0,4449,1.82545,35913.67578125,,,,,,,,,,,,,,,,,12.252253,,,,,,1.9975973,,,,
,46578453.62,1.9978931,31970.6103515625,-3.79375659510481E-6,6.93684217336982E-7,1,0.999253354069792,40.0298881530762,1.99531075648859,15.5500008817762,-4.22418466893355E-5,6.63273748277679E-7,0.25,7.35666522595806E-7,-3.77703108980558E-6,7.17737585962845E-7,1.9965098,1.9992764,31943.103515625,31998.1171875,52.6458072842748,18.6955018762464,0.8079899,0,0,0,4449,1.8253,31970.6103515625,,,,,,,,,,,,,,,,,13.003003,,,,,,1.9978931,,,,
,46578532,1.99461015,28052.802734375,1.01908985878749E-5,8.04481478034239E-7,1,0.999253354069792,40.0298881530762,1.99523069563868,15.5500008817762,0.000108810055472558,2.43469623206693E-5,0.25,4.53739324641644E-7,1.01356049721739E-5,4.87321785144046E-7,1.9936866,1.9955337,28030.294921875,28075.310546875,52.707555937294,18.6972194975965,0.8201988,0,0,0,4449,1.82525,28052.802734375,,,,,,,,,,,,,,,,,13.003003,,,,,,1.99461015,,,,
,46578608.79,1.99312275,24214.4873046875,2.09200731193366E-5,1.11065984902024E-6,1,0.999253354069792,40.0298881530762,1.99526701235223,15.5500008817762,0.000224368275919736,4.42029417256486E-5,0.25,3.99252624220322E-7,2.08059232559275E-5,4.66799796856758E-7,1.9919754,1.9942701,24186.994140625,24241.98046875,52.5066774078517,18.6995426851112,0.81212695,0,0,0,4449,1.828,24214.4873046875,,,,,,,,,,,,,,,,,12.252253,,,,,,1.99312275,,,,
,46578686.91,1.9859945,20309.0966796875,2.99435756506952E-5,7.24445761223897E-7,1,0.999253354069792,40.0298881530762,1.99528445197226,15.5500008817762,0.000317734868061148,8.23346505157327E-5,0.25,2.34993093224538E-6,2.97712497824654E-5,2.4307127812131E-6,1.9848721,1.9871169,20284.185546875,20334.0078125,52.9099977237748,18.6965055516325,0.80803015,0,0,0,4449,1.83275,20309.0966796875,,,,,,,,,,,,,,,,,12.252253,,,,,,1.9859945,,,,
,46578764.61,1.9891812,16425.896484375,4.02552255220934E-5,8.32358012711069E-7,1,0.999253354069792,40.0298881530762,1.99532971909174,15.5500008817762,0.000429772762640633,9.56985034873908E-5,0.25,1.77488262426585E-6,4.00239945452947E-5,1.88293254496643E-6,1.9883043,1.9900581,16400.830078125,16450.962890625,51.7172326034286,18.6957440420517,0.7999583,0,0,0,4449,1.83995,16425.896484375,,,,,,,,,,,,,,,,,13.003003,,,,,,1.9891812,,,,
,46578842.375,1.9923805,12540.369140625,4.70915808772755E-5,7.96870238963509E-7,1,0.999253354069792,40.0298881530762,1.99524401509958,15.5500008817762,0.00050411371333486,0.000103903424432133,0.25,1.33889656706126E-6,4.68190342342796E-5,1.46016122910905E-6,1.9905964,1.9941646,12517.892578125,12562.845703125,53.7791686371595,18.69682262212,0.8039741,0,0,0,4453,1.8535,12540.369140625,,,,,,,,,,,,,,,,,13.003003,,,,,,1.9923805,,,,
,46578921.205,1.9930342,8596.26123046875,5.25241018854895E-5,8.69692974438951E-7,1,0.999253354069792,40.0298881530762,1.99527526875347,15.5500008817762,0.000563613984579673,0.000108048328375324,0.25,7.75200636334242E-7,5.22177672705467E-5,9.04545892897105E-7,1.9930342,1.9930342,8593.7626953125,8598.759765625,52.8967100389479,18.6968369229218,0.8039741,0,0,0,4453,1.8548,8596.26123046875,,,,,,,,,,,,,,,,,12.627627,,,,,,1.9930342,,,,
,46578998.39,1.99843825,4742.96826171875,5.56095933882815E-5,4.49284587244297E-7,1,0.999253354069792,40.0298881530762,1.99515005487581,15.5500008817762,0.000599832312887128,9.63077209548344E-5,0.25,-8.49710671042264E-7,5.5285435092724E-5,-7.12578497950771E-7,1.9978616,1.9990149,4720.59814453125,4765.33837890625,52.4871366948709,18.699891631976,0.7920067,0,0,0,4449,1.85945,4742.96826171875,,,,,,,,,,,,,,,,,13.003003,,,,,,1.99843825,,,,
,46579076.525,1.99315475,835.865356445313,4.95263619329924E-5,3.0637906258869E-7,1,0.999253354069792,40.0298881530762,1.99534024242407,15.5500008817762,0.000536016773647416,7.56419247151184E-5,0.25,-1.69136404037727E-6,4.9236864049245E-5,-1.57092055149637E-6,1.9922906,1.9940189,811.015075683594,860.715637207031,52.636427742044,18.7007264099904,0.8079899,0,0,0,4449,1.85995,835.865356445313,,,,,,,,,,,,,,,,,12.252253,,,,,,1.99315475,,,,
,46579155.565,2.002434,-3109.1796875,2.78122075043603E-5,4.2124102371812E-7,1,0.999253354069792,40.0298881530762,1.99533574288163,15.5500008817762,0.000305927343907127,1.46109695544232E-5,0.25,-3.5424379437791E-6,2.76565398954698E-5,-3.45732208829785E-6,2.0013361,2.0035319,-3136.70825195313,-3081.65112304687,52.8756060689287,18.7018073282526,0.7920067,0,0,0,4449,1.86635,-3109.1796875,,,,,,,,,,,,,,,,,13.003003,,,,,,2.002434,,,,
,46579234.25,1.99568905,-7044.41162109375,2.72087783979456E-5,5.7940822106408E-7,1,0.999253354069792,40.0298881530762,1.99540705376212,15.5500008817762,0.000301778088163385,3.95400540279429E-7,0.25,-4.7621793058625E-6,2.70620904955482E-5,-4.66704682451389E-6,1.9925756,1.9988025,-7066.72998046875,-7022.09326171875,52.6895784813517,18.699742769188,0.7959825,0,0,0,4449,1.866,-7044.41162109375,,,,,,,,,,,,,,,,,13.003003,,,,,,1.99568905,,,,
,46579313.5,2.0048442,-11007.6772460938,3.03270542650126E-5,8.00340587673674E-7,1,0.999253354069792,40.0298881530762,1.99527478351249,15.5500008817762,0.00033295251913929,1.98577206541108E-5,0.25,-3.5090516052626E-6,3.01621945198499E-5,-3.4081441810053E-6,2.0047648,2.0049236,-11035.3046875,-10980.0498046875,53.1866942195826,18.7074288745789,0.7959825,0,0,0,4449,1.8636,-11007.6772460938,,,,,,,,,,,,,,,,,12.252253,,,,,,2.0048442,,,,
,46579396.03,2.002708,-15130.8876953125,3.22644616069212E-5,7.27642903470834E-7,1,0.999253354069792,40.0298881530762,1.99530307496122,15.5500008817762,0.000354971764006317,1.71621382000551E-5,0.25,-4.10860196880949E-6,3.20940184779493E-5,-3.99291768917647E-6,2.002708,2.002708,-15133.384765625,-15128.390625,52.7560169054864,18.7002745451398,0.784134,0,0,0,4449,1.85895,-15130.8876953125,,,,,,,,,,,,,,,,,12.252253,,,,,,2.002708,,,,
,46579475.385,2.01100745,-19098.6826171875,3.06467495144728E-5,9.33719927872728E-7,1,0.999253354069792,40.0298881530762,1.99533082381806,15.5500008817762,0.000339643056836442,2.62744842745131E-6,0.25,-5.17988842515039E-6,3.04927553983309E-5,-5.05715040483303E-6,2.0096059,2.012409,-19126.22265625,-19071.142578125,53.3821013493903,18.7021587118054,0.7999583,0,0,0,4449,1.85605,-19098.6826171875,,,,,,,,,,,,,,,,,12.252253,,,,,,2.01100745,,,,
,46579559.17,2.00708655,-23283.90625,2.61656463518677E-5,8.79372600829421E-7,1,0.999253354069792,40.0298881530762,1.99537589431315,15.5600009579211,0.000290375911106678,3.1241518036081E-7,0.25,-4.60777712376093E-6,2.60389179304339E-5,-4.49687716308973E-6,2.0050638,2.0091093,-23313.921875,-23253.890625,52.9600219490056,18.7026403253901,0.7999983,0,0,0,4449,1.8454,-23283.90625,,,,,,,,,,,,,,,,,13.003003,,,,,,2.00708655,,,,
,46579640.68,2.0071855,-27359.498046875,1.96668980040692E-5,7.68855543662371E-7,1,0.999253354069792,40.0298881530762,1.99526053278536,15.5500008817762,0.000223177889068214,-2.73686736625188E-5,0.25,-6.03249133422136E-6,1.95839041206334E-5,-5.93184897463467E-6,2.0070992,2.0072718,-27386.8828125,-27332.11328125,53.506380283948,18.7053664452678,0.7920067,0,0,0,4449,1.8368,-27359.498046875,,,,,,,,,,,,,,,,,13.003003,,,,,,2.0071855,,,,
,46579723.065,2.0306058,-31475.2724609375,2.09911719340944E-5,6.68280800214918E-7,1,0.999253354069792,40.0298881530762,1.9954463248628,15.5500008817762,0.000234464171519487,-7.76183652200025E-6,0.25,-4.45007494524097E-6,2.08995590896108E-5,-4.34937571830166E-6,2.0283234,2.0328882,-31505.37109375,-31445.173828125,52.9811259190248,18.7002663219324,0.80803015,0,0,0,4454,1.84845,-31475.2724609375,,,,,,,,,,,,,,,,,12.252253,,,,,,2.0306058,,,,
,46579803.84,2.03131985,-35514.60546875,2.72059649000721E-5,8.47493632545255E-7,1,0.999253354069792,40.0298881530762,1.9953786679975,15.5500008817762,0.000299955278462074,1.22896818630136E-5,0.25,-3.6971696372258E-6,2.70843737970016E-5,-3.57230819059389E-6,2.0306935,2.0319462,-35542.140625,-35487.0703125,52.6247033142556,18.7031211070828,0.81614275,0,0,0,4454,1.84445,-35514.60546875,,,,,,,,,,,,,,,,,13.003003,,,,,,2.03131985,,,,
,46579883.67,2.0421244,-39502.189453125,3.5689145721966E-5,1.05233617561866E-6,1,0.999253354069792,40.0298881530762,1.99523637702217,15.5500008817762,0.000389024100742236,4.14385422552411E-5,0.25,-2.50577266238828E-6,3.55265606671662E-5,-2.34703359875389E-6,2.0416343,2.0426145,-39534.69921875,-39469.6796875,53.0084829171979,18.7079288396468,0.8079899,0,0,0,4454,1.8417,-39502.189453125,,,,,,,,,,,,,,,,,12.252253,,,,,,2.0421244,,,,
,46579964.96,2.01921905,-43564.99609375,4.4417638090837E-5,1.19782542476855E-6,1,0.999253354069792,40.0298881530762,1.99521559537724,15.5500008817762,0.000483256245736991,5.71679378366186E-5,0.25,-2.60859671726098E-6,4.42211887747339E-5,-2.40522689090317E-6,2.0182023,2.0202358,-43592.5,-43537.4921875,53.350836208621,18.7058142159948,0.8202807,0,0,0,4453,1.81965,-43564.99609375,,,,,,,,,,,,,,,,,12.252253,,,,,,2.01921905,,,,
,46580042.46,2.0191127,-47438.00390625,5.45218069484349E-5,1.31330971442191E-6,1,0.999253354069792,40.0298881530762,1.99525668708612,15.5500008817762,0.000591029620982083,8.29457671014108E-5,0.25,-2.02709666727619E-6,5.42851587942061E-5,-1.7734154828062E-6,2.0172589,2.0209665,-47465.4609375,-47410.546875,53.0928987972748,18.705018934009,0.81614275,0,0,0,4453,1.81805,-47438.00390625,,,,,,,,,,,,,,,,,12.252253,,,,,,2.0191127,,,,
,46580121.655,2.02660165,-51396.150390625,6.89857150614687E-5,1.08828932769541E-6,1,0.999253354069792,40.0298881530762,1.99533011032602,15.5500008817762,0.000749112010404339,9.86818426421834E-5,0.25,-3.16133545236837E-6,6.87018935824331E-5,-2.82591309422988E-6,2.0258193,2.027384,-51418.59765625,-51373.703125,53.5384270532364,18.7082569995266,0.8079899,0,0,0,4454,1.8171,-51396.150390625,,,,,,,,,,,,,,,,,13.003003,,,,,,2.02660165,,,,
,46580199.85,2.0382415,-55303.6171875,8.0664750511009E-5,1.15969535006945E-6,1,0.999253354069792,40.0298881530762,1.99508061426097,15.5500008817762,0.00087623478053886,0.000114081855552717,0.25,-3.83228896914038E-6,8.03489584895256E-5,-3.42655708254331E-6,2.0365419,2.0399411,-55331.09375,-55276.140625,53.1249455665633,18.706929780241,0.81614275,0,0,0,4454,1.8164,-55303.6171875,,,,,,,,,,,,,,,,,13.003003,,,,,,2.0382415,,,,
,46580278.31,2.03883805,-59224.025390625,9.40312024235441E-5,9.63575646735233E-7,1,0.999253354069792,40.0298881530762,1.99524414698225,15.5500008817762,0.00101838065558396,0.000151638560254642,0.25,-2.75462675961002E-6,9.3673103866654E-5,-2.27406214129793E-6,2.0360737,2.0416024,-59254.046875,-59194.00390625,53.0991518254287,18.7068160140423,0.81204595,0,0,0,4454,1.81495,-59224.025390625,,,,,,,,,,,,,,,,,13.003003,,,,,,2.03883805,,,,
,46580357.77,2.03353285,-63197.060546875,0.000110974925169745,1.50658091955439E-6,1,0.999253354069792,40.0298881530762,1.99528051373376,15.5500008817762,0.00120328843251663,0.000172651773721062,0.25,-3.85756459196334E-6,0.00011057786191654,-3.27149161467697E-6,2.0313096,2.0357561,-63221.9453125,-63172.17578125,53.0780478554095,18.7127275424573,0.82843355,0,0,0,4454,1.80705,-63197.060546875,,,,,,,,,,,,,,,,,13.003003,,,,,,2.03353285,,,,
,46580436.085,2.0378817,-67109.9765625,0.000122826577452186,1.29356266244673E-6,1,0.999253354069792,40.0298881530762,1.99512822461881,15.5500008817762,0.00132854479385803,0.000210234536409385,0.25,-2.51322352353828E-6,0.000122402878690185,-1.85387945159264E-6,2.0371289,2.0386345,-67135.0859375,-67084.8671875,53.1429230225056,18.7122263923215,0.8079899,0,0,0,4454,1.80545,-67109.9765625,,,,,,,,,,,,,,,,,13.003003,,,,,,2.0378817,,,,
,46580516.03,2.03193345,-71104.73046875,0.000136895686918894,1.13859841315822E-6,1,0.999253354069792,40.0298881530762,1.99529834090479,15.5500008817762,0.00148437242532966,0.000216448751682359,0.25,-4.48381465246738E-6,0.000136461331083712,-3.72489520226202E-6,2.0308907,2.0329762,-71127.203125,-71082.2578125,53.0686683131787,18.7102374638913,0.81614275,0,0,0,4454,1.80445,-71104.73046875,,,,,,,,,,,,,,,,,13.003003,,,,,,2.03193345,,,,
,46580594.45,2.037655,-75025.01953125,0.000148734785486534,1.31196332785458E-6,1,0.999253354069792,40.0298881530762,1.99519718696326,15.5500008817762,0.00161247183067479,0.00023819950161067,0.25,-4.61277657283898E-6,0.000148292717633521,-3.77113897091095E-6,2.0375412,2.0377688,-75055.1015625,-74994.9375,52.9654933486402,18.7134206152059,0.81614275,0,0,0,4454,1.80445,-75025.01953125,,,,,,,,,,,,,,,,,13.003003,,,,,,2.037655,,,,
,46580674.04,2.0407139,-79002.8046875,0.000163439732316431,1.16272959696002E-6,1,0.999253354069792,40.0298881530762,1.99521667355453,15.5500008817762,0.00176303862235263,0.000313307955932497,0.25,-3.12471103590621E-7,0.000162962132114451,6.16915821123093E-7,2.0391254,2.0423024,-79027.78125,-78977.828125,52.5895300308902,18.7179315867916,0.81614275,0,0,0,4454,1.8041,-79002.8046875,,,,,,,,,,,,,,,,,11.876877,,,,,,2.0407139,,,,
,46580753.45,2.04424275,-82971.109375,0.000175002698530282,1.39246025981587E-6,1,0.999253354069792,40.0298881530762,1.99524144700516,15.5500008817762,0.00189335071447109,0.000306879337983182,0.25,-3.0118741041579E-6,0.000174544093138154,-1.99025862686486E-6,2.0433743,2.0451112,-82991.0234375,-82951.1953125,52.8146390444287,18.7181857168768,0.81614275,0,0,0,4454,1.80385,-82971.109375,,,,,,,,,,,,,,,,,12.252253,,,,,,2.04424275,,,,
,46580830.765,2.03937135,-86836.234375,0.000190587192558201,1.73539794926131E-6,1,0.999253354069792,40.0298881530762,1.99523936047824,15.5500008817762,0.00206543344276385,0.00031737295461708,0.25,-4.86572434868956E-6,0.00019013710400104,-3.73109438628555E-6,2.0384192,2.0403235,-86863.5078125,-86808.9609375,52.6841070817171,18.7128025542708,0.8242956,0,0,0,4454,1.8038,-86836.234375,,,,,,,,,,,,,,,,,12.252253,,,,,,2.03937135,,,,
,46580922.735,2.047791,-89364.08984375,0.000200234141197387,1.84681816720721E-6,1,0.999253354069792,40.0298881530762,1.99530332676689,15.5500008817762,0.00215943940596884,0.000394100649635659,0.25,4.93469616414669E-7,0.000199755558017894,1.68344870637942E-6,2.0463409,2.0492411,-89389.109375,-89339.0703125,53.4329072031403,18.7157602451485,0.81614275,0,0,0,4454,1.80355,-89364.08984375,,,,,,,,,,,,,,,,,13.378378,,,,,,2.047791,,,,
,46580999.8,2.04472015,-85515.79296875,0.000185862790836309,1.51543224445576E-6,1,0.999253354069792,40.0298881530762,1.99528752126314,15.5500008817762,0.00200584158283885,0.000355595057851106,0.25,-4.65087532920417E-7,0.000185385399409171,6.2463893169655E-7,2.0445237,2.0449166,-85543.203125,-85488.3828125,53.4610458298326,18.7157007664434,0.8242956,0,0,0,4454,1.8033,-85515.79296875,,,,,,,,,,,,,,,,,12.252253,,,,,,2.04472015,,,,
,46581077.635,2.05243565,-81625.51171875,0.000171336531805177,1.40483473784684E-6,1,0.999253354069792,40.0298881530762,1.9953645541734,15.5500008817762,0.00185113749514571,0.000314469853950049,0.25,-1.64235624782944E-6,0.000170867520007984,-6.51794921290374E-7,2.0523598,2.0525115,-81650.5703125,-81600.453125,53.0913355402364,18.7080720505964,0.8079899,0,0,0,4454,1.8032,-81625.51171875,,,,,,,,,,,,,,,,,13.003003,,,,,,2.05243565,,,,
,46581155.93,2.05295405,-77710.234375,0.000158051586987234,1.56200473146015E-6,1,0.999253354069792,40.0298881530762,1.99509048473321,15.5500008817762,0.00170515423988029,0.00030038998817548,0.25,-5.32731485474315E-7,0.000157580119310063,3.60744213102996E-7,2.0500073,2.0559008,-77732.6953125,-77687.7734375,53.1429230225056,18.7155357878739,0.8242956,0,0,0,4454,1.80285,-77710.234375,,,,,,,,,,,,,,,,,13.003003,,,,,,2.05295405,,,,
,46581234.77,2.04903425,-73772.25390625,0.000144533914769421,9.82067344639049E-7,1,0.999253354069792,40.0298881530762,1.99518315214759,15.5600009579211,0.00156218011484978,0.000257258737391002,0.25,-2.08319753813072E-6,0.000144081342234612,-1.27846636979619E-6,2.0488799,2.0491886,-73799.703125,-73744.8046875,53.2976854693133,18.7137993076789,0.81614275,0,0,0,4454,1.80275,-73772.25390625,,,,,,,,,,,,,,,,,12.252253,,,,,,2.04903425,,,,
,46581313.5,2.0421507,-69837.64453125,0.000128276556097407,1.12836101860807E-6,1,0.999253354069792,40.0298881530762,1.99519542503686,15.5500008817762,0.0013854895376589,0.000232135325580775,0.25,-1.47412433786549E-6,0.000127846192560443,-7.77545579109704E-7,2.0410492,2.0432522,-69857.6015625,-69817.6875,53.5446800813903,18.7141461770879,0.81614275,0,0,0,4454,1.8023,-69837.64453125,,,,,,,,,,,,,,,,,12.252253,,,,,,2.0421507,,,,
,46581392.825,2.04237475,-65872.0703125,0.000117225162530973,1.1162045925197E-6,1,0.999253354069792,40.0298881530762,1.99504069874606,15.5500008817762,0.00126980634084373,0.000189559906417328,0.25,-3.42027251503702E-6,0.000116818609643709,-2.79240388449019E-6,2.0418363,2.0429132,-65899.6171875,-65844.5234375,53.2539142722364,18.7122753669899,0.8079899,0,0,0,4454,1.80185,-65872.0703125,,,,,,,,,,,,,,,,,12.252253,,,,,,2.04237475,,,,
,46581470.37,2.0381917,-61996.701171875,0.00010245480578588,1.28616964910008E-6,1,0.999253354069792,40.0298881530762,1.99507530613338,15.5500008817762,0.00111135758976204,0.000155860368125119,0.25,-3.88252159938997E-6,0.000102083532367093,-3.34473017032473E-6,2.0358694,2.040514,-62021.75,-61971.65234375,53.2156144747941,18.7123923517795,0.81614275,0,0,0,4454,1.8017,-61996.701171875,,,,,,,,,,,,,,,,,12.252253,,,,,,2.0381917,,,,
,46581547.605,2.0346558,-58136.42578125,8.86130400061175E-5,8.43341391396456E-7,1,0.999253354069792,40.0298881530762,1.99517392834847,15.5500008817762,0.000960615726929734,0.000137301714358263,0.25,-3.11058770675397E-6,8.82732933715708E-5,-2.65942108816429E-6,2.0346553,2.0346563,-58158.90625,-58113.9453125,53.1186925384095,18.713870964063,0.8202807,0,0,0,4454,1.8015,-58136.42578125,,,,,,,,,,,,,,,,,12.252253,,,,,,2.0346558,,,,
,46581624.195,2.0302056,-54310.818359375,7.63097647084636E-5,9.79186782563222E-7,1,0.999253354069792,40.0298881530762,1.99511448920607,15.5500008817762,0.000832878100559827,8.56669532967412E-5,0.25,-5.68810957977194E-6,7.60171497057378E-5,-5.29868931159374E-6,2.029027,2.0313842,-54335.6875,-54285.94921875,53.4438500024095,18.7106882958663,0.8079899,0,0,0,4454,1.80165,-54310.818359375,,,,,,,,,,,,,,,,,12.252253,,,,,,2.0302056,,,,
,46581701.215,2.0289695,-50461.16796875,6.21984334280781E-5,1.08589876810933E-6,1,0.999253354069792,40.0298881530762,1.99527215285473,15.5500008817762,0.000677615928734019,7.63361174292328E-5,0.25,-4.02043126097224E-6,6.19451542227261E-5,-3.71535719851201E-6,2.0275967,2.0303423,-50483.73046875,-50438.60546875,52.9350098363902,18.7123281742777,0.8079899,0,0,0,4454,1.8017,-50461.16796875,,,,,,,,,,,,,,,,,12.252253,,,,,,2.0289695,,,,
,46581778.06,2.0348704,-46620.548828125,5.03313356810148E-5,1.00141452484253E-6,1,0.999253354069792,40.0298881530762,1.99508366851255,15.5500008817762,0.00055328737198009,3.31300336640421E-5,0.25,-5.90292984920728E-6,5.01289177385001E-5,-5.65226150749726E-6,2.0346339,2.0351069,-46645.453125,-46595.64453125,52.7114640798902,18.7116820717044,0.8242956,0,0,0,4454,1.8023,-46620.548828125,,,,,,,,,,,,,,,,,13.003003,,,,,,2.0348704,,,,
,46581855.1,2.0374063,-42767.6953125,3.73416952399752E-5,9.84898508853182E-7,1,0.999253354069792,40.0298881530762,1.99503281602042,15.5500008817762,0.000411330372100519,1.93890180506013E-5,0.25,-4.85426955978824E-6,3.71865509752608E-5,-4.67211193669155E-6,2.0370593,2.0377533,-42792.6171875,-42742.7734375,52.6286114568517,18.7119164818972,0.8242956,0,0,0,4454,1.80255,-42767.6953125,,,,,,,,,,,,,,,,,12.252253,,,,,,2.0374063,,,,
,46581931.95,2.03660215,-38926.982421875,2.43545994164323E-5,9.66376340722777E-7,1,0.999253354069792,40.0298881530762,1.99503358143089,15.5500008817762,0.000269094173892314,7.7573974412401E-6,0.25,-3.61527269848717E-6,2.42508106614143E-5,-3.4983225150142E-6,2.0353439,2.0378604,-38949.41015625,-38904.5546875,52.741165963621,18.7176365519224,0.81614275,0,0,0,4454,1.8029,-38926.982421875,,,,,,,,,,,,,,,,,13.003003,,,,,,2.03660215,,,,
,46582008.895,2.0404594,-35084.390625,1.20169146237976E-5,8.34205016124921E-7,1,0.999253354069792,40.0298881530762,1.99487497564311,15.5500008817762,0.000133998426458293,-3.24310820108665E-6,0.25,-2.43836600346261E-6,1.1966107209483E-5,-2.37940712452798E-6,2.0395529,2.0413659,-35106.90234375,-35061.87890625,53.0499092287172,18.7110191546927,0.8079899,0,0,0,4454,1.803,-35084.390625,,,,,,,,,,,,,,,,,13.003003,,,,,,2.0404594,,,,
,46582085.94,2.0395087,-31231.1240234375,4.72341524257716E-7,1.03394034872868E-7,1,0.999253354069792,40.0298881530762,1.9949922528478,15.5500008817762,1.76624574001311E-5,-6.99124449099933E-5,0.25,-6.58020268039204E-6,4.94205515705623E-7,-6.54451368136469E-6,2.0366881,2.0423293,-31258.703125,-31203.544921875,53.7924563219865,18.7180061858884,0.81614275,0,0,0,4454,1.80355,-31231.1240234375,,,,,,,,,,,,,,,,,13.003003,,,,,,2.0395087,,,,
,46582163.055,2.03055885,-27378.6240234375,-1.29539786754561E-5,8.55887034764289E-7,1,0.999253354069792,40.0298881530762,1.99514859263876,15.5500008817762,-0.000128072574156417,-8.86094678584279E-5,0.25,-5.93543360508725E-6,-1.28646922782256E-5,-5.94930495092474E-6,2.0284367,2.032681,-27406.109375,-27351.138671875,52.6153237720248,18.7100475631485,0.81614275,0,0,0,4454,1.8045,-27378.6240234375,,,,,,,,,,,,,,,,,13.003003,,,,,,2.03055885,,,,
,46582239.845,2.02949605,-23539.7861328125,-2.34375735974977E-5,7.87887961565931E-7,1,0.999253354069792,40.0298881530762,1.99515988349869,15.5500008817762,-0.000240217558847782,-0.000112338447389044,0.25,-6.28598656839978E-6,-2.32899649709022E-5,-6.32922651589309E-6,2.0292618,2.0297303,-23562.28125,-23517.291015625,53.1186925384095,18.715187721553,0.7999583,0,0,0,4454,1.80525,-23539.7861328125,,,,,,,,,,,,,,,,,12.252253,,,,,,2.02949605,,,,
,46582316.795,2.0306413,-19693.9658203125,-3.43158225997427E-5,1.08646532357854E-6,1,0.999253354069792,40.0298881530762,1.99497559081918,15.5500008817762,-0.000356254095199614,-0.000138498591358377,0.25,-6.79836549142113E-6,-3.41051024377069E-5,-6.86712171686958E-6,2.0296161,2.0316665,-19718.875,-19669.056640625,53.3008119833903,18.7137021878106,0.81614275,0,0,0,4454,1.80575,-19693.9658203125,,,,,,,,,,,,,,,,,13.003003,,,,,,2.0306413,,,,
,46582393.625,2.0273502,-15854.0126953125,-4.2547241844833E-5,9.24817421904932E-7,1,0.999253354069792,40.0298881530762,1.99505014729668,15.5500008817762,-0.000442105268848059,-0.000169403647653531,0.25,-8.22291532926775E-6,-4.22838533845581E-5,-8.30012864687412E-6,2.0268641,2.0278363,-15881.611328125,-15826.4140625,53.4579193157556,18.7133112225703,0.80803015,0,0,0,4454,1.806,-15854.0126953125,,,,,,,,,,,,,,,,,12.252253,,,,,,2.0273502,,,,
,46582470.735,2.0330645,-12000.6665039062,-5.1500284250513E-5,7.50172062165648E-7,1,0.999253354069792,40.0298881530762,1.9947746108626,15.5500008817762,-0.000538716074660995,-0.000184174867711999,0.25,-8.02633159378297E-6,-5.11838379472054E-5,-8.12001926732685E-6,2.0330639,2.0330651,-12023.1650390625,-11978.16796875,53.3062833830249,18.7135120912452,0.816102,0,0,0,4454,1.8058,-12000.6665039062,,,,,,,,,,,,,,,,,13.003003,,,,,,2.0330645,,,,
,46582547.765,2.0222707,-8149.64599609375,-5.54166915914912E-5,7.33160926251253E-7,1,0.999253354069792,40.0298881530762,1.99509363680106,15.5500008817762,-0.000582283227555777,-0.000183783287640715,0.25,-7.30703811909899E-6,-5.50766130978748E-5,-7.40469149340943E-6,2.0203984,2.024143,-8169.5078125,-8129.7841796875,53.015517573871,18.7080555492894,0.8201988,0,0,0,4454,1.8054,-8149.64599609375,,,,,,,,,,,,,,,,,12.252253,,,,,,2.0222707,,,,
,46582624.465,2.0163262,-4316.0556640625,-5.60526960660896E-5,5.59141117734084E-7,1,0.999253354069792,40.0298881530762,1.99506077244431,15.5500008817762,-0.00059347745838129,-0.00016007348544873,0.25,-5.00145987292978E-6,-5.57117303586018E-5,-5.10429110283301E-6,2.014936,2.0177164,-4341.07373046875,-4291.03759765625,52.6536235694671,18.7102529229069,0.80803015,0,0,0,4453,1.8052,-4316.0556640625,,,,,,,,,,,,,,,,,12.252253,,,,,,2.0163262,,,,
,46582701.635,2.01064375,-457.59733581543,-4.73130815753147E-5,3.44218018791688E-7,1,0.999253354069792,40.0298881530762,1.99499967102539,15.5500008817762,-0.000503788099854975,-0.000118755582119702,0.25,-2.70829839764547E-6,-4.70267216533241E-5,-2.79723195065815E-6,2.0101655,2.011122,-482.621398925781,-432.573272705078,52.9311016937941,18.7115286166315,0.80803015,0,0,0,4453,1.8048,-457.59733581543,,,,,,,,,,,,,,,,,13.003003,,,,,,2.01064375,,,,
,46582778.415,1.99248935,3372.68420410156,-2.60404086512098E-5,7.35154426556299E-7,1,0.999253354069792,40.0298881530762,1.9950634718683,15.5500008817762,-0.000279720981935745,-5.15969902365829E-5,0.25,-2.07987201607004E-7,-2.58866168966703E-5,-2.67185288421805E-7,1.9907602,1.9942185,3350.21704101562,3395.1513671875,52.6207951716594,18.7127442291811,0.8039741,0,0,0,4453,1.8048,3372.68420410156,,,,,,,,,,,,,,,,,13.378378,,,,,,1.99248935,,,,
,46582855.295,1.98841945,7218.26098632813,-2.47233329935632E-5,8.25386458771574E-7,1,0.999253354069792,40.0298881530762,1.99494071583789,15.5500008817762,-0.000269305882736131,-2.78364135844405E-5,0.25,1.77294712755151E-6,-2.45838126622946E-5,1.70119388383321E-6,1.9883399,1.988499,7195.82861328125,7240.693359375,53.0631969135441,18.7073721887011,0.80803015,0,0,0,4453,1.8044,7218.26098632813,,,,,,,,,,,,,,,,,13.003003,,,,,,1.98841945,,,,
,46582932.65,1.99713055,11084.5859375,-2.55363480647873E-5,7.53122100831781E-7,1,0.999253354069792,40.0298881530762,1.99517251557106,15.5500008817762,-0.000279900600567052,-1.92295621525365E-5,0.25,2.72157097035122E-6,-2.53969631013136E-5,2.63785262359135E-6,1.9964048,1.9978563,11064.482421875,11104.689453125,52.9389179789864,18.7134310954161,0.7999583,0,0,0,4453,1.80435,11084.5859375,,,,,,,,,,,,,,,,,12.627627,,,,,,1.99713055,,,,
,46583009.44,2.0054405,14923.0112304687,-2.84531093493098E-5,7.82928197643021E-7,1,0.999253354069792,40.0298881530762,1.99523458149776,15.5500008817762,-0.000312471090994599,-1.82807975378373E-5,0.25,3.330504377953E-6,-2.83017797475651E-5,3.23041901825286E-6,2.0054405,2.0054405,14903.072265625,14942.9501953125,53.259385671871,18.7134110659083,0.816102,0,0,0,4453,1.8042,14923.0112304687,,,,,,,,,,,,,,,,,13.003003,,,,,,2.0054405,,,,
,46583086.105,2.02415275,18753.2109375,-2.89067157515824E-5,8.9631904059252E-7,1,0.999253354069792,40.0298881530762,1.99508660501778,15.5500008817762,-0.000315472287732747,-2.98603418661846E-5,0.25,2.34026579050687E-6,-2.87533388628512E-5,2.23909671103692E-6,2.022306,2.0259995,18730.82421875,18775.59765625,52.6794173106017,18.7134463351141,0.7999583,0,0,0,4454,1.80385,18753.2109375,,,,,,,,,,,,,,,,,12.252253,,,,,,2.02415275,,,,
,46583163.135,2.0353881,22604.0927734375,-2.20896833088744E-5,7.83223793435706E-7,1,0.999253354069792,40.0298881530762,1.99495909467393,15.5500008817762,-0.000241185773794114,-2.22863713960182E-5,0.25,1.84238092450838E-6,-2.19754532047747E-5,1.76059571401508E-6,2.0350938,2.0356824,22579.185546875,22629,52.6653479972556,18.7131252540123,0.8242956,0,0,0,4454,1.80345,22604.0927734375,,,,,,,,,,,,,,,,,13.378378,,,,,,2.0353881,,,,
,46583240.205,2.0504309,26457.2861328125,-1.68356289368513E-5,9.13640163264715E-7,1,0.999253354069792,40.0298881530762,1.99499519117267,15.5500008817762,-0.000187315597940702,2.56015538871132E-6,0.25,3.22421381648911E-6,-1.67571556079683E-5,3.14901335397896E-6,2.0462682,2.0545936,26432.328125,26482.244140625,52.7286599073133,18.7122373036427,0.7999583,0,0,0,4454,1.8028,26457.2861328125,,,,,,,,,,,,,,,,,12.252253,,,,,,2.0504309,,,,
,46583316.905,2.0630934,30290.7265625,-1.85010735876352E-5,8.82229605425366E-7,1,0.999253354069792,40.0298881530762,1.99500428060409,15.5500008817762,-0.00020474961721241,-3.55837473183974E-6,0.25,2.9548331094659E-6,-1.84157898951673E-5,2.87205789977364E-6,2.062561,2.0636258,30265.658203125,30315.794921875,52.1260243189863,18.7096782451471,0.7999583,0,0,0,4454,1.80225,30290.7265625,,,,,,,,,,,,,,,,,13.003003,,,,,,2.0630934,,,,
,46583393.93,2.071744,34138.716796875,-2.18966756638623E-5,9.57360821658161E-7,1,0.999253354069792,40.0298881530762,1.99489480474,15.5500008817762,-0.00023809595963713,-2.81825122080052E-5,0.25,1.27427987643089E-6,-2.17909359732675E-5,1.18374336625306E-6,2.071744,2.071744,34118.78515625,34158.6484375,53.0741397128133,18.7124764639934,0.816102,0,0,0,4454,1.8018,34138.716796875,,,,,,,,,,,,,,,,,13.003003,,,,,,2.071744,,,,
,46583472.02,2.08300075,38043.923828125,-2.89224873999677E-5,1.02394749677654E-6,1,0.999253354069792,40.0298881530762,1.99487670093932,15.5500008817762,-0.000318050877543889,-1.75086370113965E-5,0.25,3.52117117099397E-6,-2.87949122369567E-5,3.38718032886668E-6,2.0796101,2.0863914,38021.4921875,38066.35546875,53.0397480579671,18.7134279989939,0.80803015,0,0,0,4454,1.80155,38043.923828125,,,,,,,,,,,,,,,,,13.003003,,,,,,2.08300075,,,,
,46583549.82,2.0828441,41931.552734375,-3.86621514266191E-5,9.4022301587802E-7,1,0.999253354069792,40.0298881530762,1.99491236077391,15.5500008817762,-0.000421589015148642,-4.38967976672913E-5,0.25,2.81122733431935E-6,-3.84906067972737E-5,2.63451208927894E-6,2.0810246,2.0846636,41903.95703125,41959.1484375,52.9553321778902,18.7140823943128,0.81614275,0,0,0,4454,1.80095,41931.552734375,,,,,,,,,,,,,,,,,12.252253,,,,,,2.0828441,,,,
,46583626.955,2.09762035,45785.072265625,-5.09250495215709E-5,1.20278105274949E-6,1,0.999253354069792,40.0298881530762,1.99489661483306,15.5500008817762,-0.00054927434237946,-9.21968090242131E-5,0.25,5.20193573946789E-7,-5.06941114344814E-5,2.93300539358341E-7,2.0968578,2.0983829,45757.6171875,45812.52734375,52.7099008228517,18.7122564193705,0.8242956,0,0,0,4454,1.8008,45785.072265625,,,,,,,,,,,,,,,,,13.003003,,,,,,2.09762035,,,,
,46583703.815,2.0676588,49628.0546875,-5.80656609699701E-5,1.27107407418406E-6,1,0.999253354069792,40.0298881530762,1.9950172738756,15.5500008817762,-0.000626481684525409,-0.000104901328093605,0.25,6.26355135937775E-7,-5.78125302596907E-5,3.57364838475841E-7,2.0651877,2.0701299,49600.4921875,49655.6171875,53.0436562005633,18.7086988162314,0.8242956,0,0,0,4454,1.8,49628.0546875,,,,,,,,,,,,,,,,,13.003003,,,,,,2.0676588,,,,
,46583780.765,2.08408245,53473.640625,-7.31502138175948E-5,1.17524800435376E-6,1,0.999253354069792,40.0298881530762,1.99480592970078,15.5500008817762,-0.000784396726403257,-0.000159575317291557,0.25,-1.74393194566629E-6,-7.28324136725934E-5,-2.0843602954838E-6,2.082164,2.0860009,53453.5078125,53493.7734375,53.1147843958133,18.7080667871844,0.8242956,0,0,0,4454,1.79945,53473.640625,,,,,,,,,,,,,,,,,13.003003,,,,,,2.08408245,,,,
,46583857.635,2.1014482,57313.986328125,-8.82942824737319E-5,1.28112016181402E-6,1,0.999253354069792,40.0298881530762,1.99484587086925,15.5500008817762,-0.00095020235904542,-0.000174622950431395,0.25,-4.16949225246662E-7,-8.79348370335006E-5,-8.49401895548729E-7,2.1006265,2.1022699,57286.41796875,57341.5546875,53.178096305871,18.7143569721105,0.81614275,0,0,0,4454,1.79935,57313.986328125,,,,,,,,,,,,,,,,,13.003003,,,,,,2.1014482,,,,
,46583935.51,2.10155215,61207.32421875,-9.8894149445792E-5,1.36838170723416E-6,1,0.999253354069792,40.0298881530762,1.99478957828116,15.5500008817762,-0.00106343971157583,-0.000201270959645772,0.25,-9.76210933782012E-7,-9.85078064742314E-5,-1.47419947084303E-6,2.1015048,2.1015995,61179.8828125,61234.765625,52.9779994049479,18.7146317626484,0.81614275,0,0,0,4454,1.7992,61207.32421875,,,,,,,,,,,,,,,,,12.252253,,,,,,2.10155215,,,,
,46584012.485,2.1052564,65056.650390625,-0.000115311814839982,1.4195137828799E-6,1,0.999253354069792,40.0298881530762,1.99475540801301,15.5400010384619,-0.00123799783386962,-0.000247038005415547,0.25,-2.26413976169147E-6,-0.000114877624328993,-2.85782119947551E-6,2.1047835,2.1057293,65034.1328125,65079.16796875,52.9201588945248,18.7155336535217,0.8202807,0,0,0,4454,1.79895,65056.650390625,,,,,,,,,,,,,,,,,13.378378,,,,,,2.1052564,,,,
,46584089.455,2.11747965,68904.8046875,-0.000127187470685662,1.12992172362564E-6,1,0.999253354069792,40.0298881530762,1.99489308784794,15.5500008817762,-0.00137027554973612,-0.000247891752073653,0.25,-1.91557005818835E-7,-0.000126745702213204,-8.72461140665614E-7,2.1170933,2.117866,68887.25,68922.359375,52.9983217464479,18.7178903295515,0.8079899,0,0,0,4454,1.799,68904.8046875,,,,,,,,,,,,,,,,,13.003003,,,,,,2.11747965,,,,
,46584166.77,2.12793135,72767.90234375,-0.000140929558232257,1.13896677754449E-6,1,0.999253354069792,40.0298881530762,1.99479040404722,15.5500008817762,-0.00151947477546079,-0.000269635180125983,0.25,2.77589407258421E-7,-0.000140471133309887,-4.96885721990189E-7,2.1254406,2.1304221,72745.2734375,72790.53125,52.8818590970825,18.7131650200644,0.81212695,0,0,0,4454,1.79895,72767.90234375,,,,,,,,,,,,,,,,,13.003003,,,,,,2.12793135,,,,
,46584244.845,2.1282605,76668.5234375,-0.000155871335170038,1.18518711167049E-6,1,0.999253354069792,40.0298881530762,1.99474716453531,15.5500008817762,-0.00168132761403483,-0.000295836709020323,0.25,5.52545508808285E-7,-0.00015539786933429,-3.23848270110914E-7,2.127528,2.128993,76643.6328125,76693.4140625,52.8810774685633,18.7164887639463,0.8242956,0,0,0,4454,1.79905,76668.5234375,,,,,,,,,,,,,,,,,12.252253,,,,,,2.1282605,,,,
,46584323.345,2.13835405,80594.24609375,-0.000168905935215064,1.51669108411077E-6,1,0.999253354069792,40.0298881530762,1.99460541154723,15.5500008817762,-0.00181679785745172,-0.000350623883678927,0.25,-2.16489191198588E-6,-0.000168412525435719,-3.12589521549282E-6,2.1382518,2.1384563,80566.6875,80621.8046875,52.852938841871,18.7157713302792,0.81614275,0,0,0,4454,1.799,80594.24609375,,,,,,,,,,,,,,,,,13.003003,,,,,,2.13835405,,,,
,46584404.46,2.1628672,84646.97265625,-0.000184091989210633,1.49173768052271E-6,1,0.999253354069792,40.0298881530762,1.99462716769352,15.5500008817762,-0.0019885640687122,-0.000337921089665731,0.25,1.76973944048657E-6,-0.000183618161897976,6.90982288414922E-7,2.1621547,2.1635797,84624.5546875,84669.390625,53.2914324411595,18.7165701322894,0.80803015,0,0,0,4454,1.82235,84646.97265625,,,,,,,,,,,,,,,,,13.003003,,,,,,2.1628672,,,,
,46584482.195,2.1276995,88532.79296875,-0.000195981828991793,1.37102446791696E-6,1,0.999253354069792,40.0298881530762,1.9948441041267,15.5500008817762,-0.002111110141701,-0.000396279353721704,0.25,-1.47396761329862E-6,-0.000195498751258833,-2.6324952392678E-6,2.1275661,2.1278329,88507.5546875,88558.03125,53.4540111731595,18.7156050911457,0.7999583,0,0,0,4454,1.80265,88532.79296875,,,,,,,,,,,,,,,,,12.252253,,,,,,2.1276995,,,,
,46584513.035,2.1282674,89999.609375,-0.000203171520512784,1.49006688312386E-6,1,0.999253354069792,40.0298881530762,1.99482580395398,15.5500008817762,-0.00219355764779185,-0.000383921547413255,0.25,9.74660388317488E-7,-0.000202701687517641,-2.39172027203254E-7,2.1254251,2.1311097,89999.609375,89999.609375,53.1296353376787,18.7122819631543,0.816102,0,0,0,4422,1.80065,89999.609375,,,,,,,,,,,,,,,,,13.003003,,,,,,2.1282674,,,,