File: data/monolayers/magneticStructure/ML_Ac_CoFe_C-2/PPMS/data/DD175_23_HYST_100OE_100K.DAT
[Header]
; VSM Data File (default extension .dat)
; Copyright (c) 2003-2013, Quantum Design, Inc. All rights reserved.
TITLE,
FILEOPENTIME,31943580.47,01/06/2019,1:15 am
BYAPP,VSM,2.0,2.0
INFO,PPMS VSM Option Release 1.4.10 Build 1,APPNAME
INFO,Quantum Design Linear Motor Servo Controller,MOTOR_MODULE_NAME
INFO,3101-100 M1,MOTOR_HW_VERSION
INFO,MMC1014,MOTOR_SERIAL_NUMBER
INFO,SRV No X-over 01.03.11,MOTOR_SOFTWARE_VERSION
INFO,Quantum Design VSM Detection Module,VSM_MODULE_NAME
INFO,3101-150 F0,VSM_HW_VERSION
INFO,VSM707,VSM_SERIAL_NUMBER
INFO,VSM No X-over 01.02.05 May 20 2008 13:51:47,VSM_SOFTWARE_VERSION
INFO,704,PREAMP_SERIAL_NUMBER
INFO,822,COIL_SERIAL_NUMBER
INFO,0,MOMENT_UNITS
INFO,CoFe2O4 Monolayer,SAMPLE_MATERIAL
INFO,from YF45,SAMPLE_COMMENT
INFO,29.98,SAMPLE_MASS
INFO,,SAMPLE_VOLUME
INFO,,SAMPLE_MOLECULAR_WEIGHT
INFO,,SAMPLE_SIZE
INFO,,SAMPLE_SHAPE
DATATYPE,COMMENT,1
DATATYPE,TIME,2
STARTUPAXIS,X,2
STARTUPAXIS,Y1,5
[Data]
Comment,Time Stamp (sec),Temperature (K),Magnetic Field (Oe),Moment (emu),M. Std. Err. (emu),Transport Action,Averaging Time (sec),Frequency (Hz),Peak Amplitude (mm),Center Position (mm),Coil Signal' (mV),Coil Signal" (mV),Range (mV),M. Quad. Signal (emu),M. Raw' (emu),M. Raw" (emu),Min. Temperature (K),Max. Temperature (K),Min. Field (Oe),Max. Field (Oe),Mass (grams),Motor Lag (deg),Pressure (Torr),VSM Status (code),Motor Status (code),Measure Status (code),Measure Count,PPMS Status (code),System Temp. (K),System Field (Oe),Sample Position (deg),Bridge 1 Resistance (ohms),Bridge 1 Excitation (에),Bridge 2 Resistance (ohms),Bridge 2 Excitation (에),Bridge 3 Resistance (ohms),Bridge 3 Excitation (에),Bridge 4 Resistance (ohms),Bridge 4 Excitation (에),Signal 1 Vin (V),Signal 2 Vin (V),Digital Inputs (code),Drive 1 Iout (mA),Drive 1 Ipower (W),Drive 2 Iout (mA),Drive 2 Ipower (W),Pressure (),Map 20 (),Map 21 (),Map 22 (),Map 23 (),Map 24 (),Map 25 (),Map 26 (),Map 27 (),Map 28 (),Map 29 ()
,31943595.33,100.0025482,-0.3349229991436,,,2,,,,21.1899991315603,,,,,,,100.0025482,100.0025482,-0.3349229991436,-0.3349229991436,,,22.529354,,,,-99999999,4369,99.906,-0.3349229991436,,,,,,,,,,,,,,,,,,,,,,,100.0025482,,,,
,31943763.82,99.9942818,5429.31640625,2.84066691114673E-5,4.68435208382774E-7,1,0.999253354069792,40.0298881530762,1.99389742163575,21.1800001561642,0.000321487979940197,6.19839110731067E-5,0.25,4.68416284050947E-7,2.85651209538956E-5,5.59165677213947E-7,99.9942017,99.9943619,5424.1201171875,5434.5126953125,56.3968425480637,20.5433213068648,22.149702,0,0,0,40,4449,99.9153,5429.31640625,,,,,,,,,,,,,0,,,,-0.0049,,,,,,99.9942818,,,,
,31943868.61,99.9972534,10663.9360351562,1.3705256556485E-5,6.0033107403886E-7,1,0.999253354069792,40.0298881530762,1.99386013231999,21.1800001561642,0.000154083087200122,3.57226060455168E-5,0.25,7.38792229992268E-7,1.37802282935973E-5,7.85241946552042E-7,99.9972534,99.9972534,10661.34375,10666.5283203125,56.231918930506,20.5495688771106,22.529354,0,0,0,40,4449,99.9192,10663.9360351562,,,,,,,,,,,,,0,,,,-0.00245,,,,,,99.9972534,,,,
,31943970.09,99.99887085,15738.88671875,-1.32646633069666E-6,8.90562310143509E-7,1,0.999253354069792,40.0298881530762,1.99375947865907,21.1800001561642,-1.72992033234888E-5,1.01258286399915E-5,0.25,1.1252521573011E-6,-1.33740588970758E-6,1.12753363878259E-6,99.998703,99.9990387,15733.9677734375,15743.8056640625,56.5985027060252,20.5521294668727,22.909004,0,0,0,40,4449,99.9169,15738.88671875,,,,,,,,,,,,,0,,,,-0.0049,,,,,,99.99887085,,,,
,31944052.66,99.9998169,19864.3095703125,-1.58276023975456E-5,1.05449310659531E-6,1,0.999253354069792,40.0298881530762,1.99392856609901,21.1800001561642,-0.000180795121773828,-2.50781001463233E-5,0.25,5.7161161759475E-7,-1.59187897762221E-5,5.26513146853415E-7,99.9998169,99.9998169,19861.79296875,19866.826171875,56.6008475915829,20.5528723095877,22.909004,0,0,0,40,4449,99.9166,19864.3095703125,,,,,,,,,,,,,0,,,,0.0049,,,,,,99.9998169,,,,
,31944131.055,100.00354005,23782.4462890625,-2.8846213448082E-5,9.85827475784413E-7,1,0.999253354069792,40.0298881530762,1.99392094671533,21.1800001561642,-0.000330151591615625,-4.20223201903226E-5,0.25,1.36585605828926E-6,-2.90135590570095E-5,1.2859185782435E-6,100.0034332,100.0036469,23750.107421875,23814.78515625,56.6680676442368,20.5536933922958,22.529354,0,0,0,40,4449,99.91515,23782.4462890625,,,,,,,,,,,,,0,,,,-0.00245,,,,,,100.00354005,,,,
,31944198.05,100.00328825,27130.97265625,-3.9063511434142E-5,1.76730534063301E-6,1,0.999253354069792,40.0298881530762,1.99415838357552,21.1800001561642,-0.000447486650143551,-5.49626422605481E-5,0.25,2.0209876946993E-6,-3.92908443048279E-5,1.91420496730039E-6,100.0031128,100.0034637,27098.544921875,27163.400390625,56.7587365524675,20.5470387053328,22.909004,0,0,0,40,4449,99.9119,27130.97265625,,,,,,,,,,,,,0,,,,-0.00245,,,,,,100.00328825,,,,
,31944259.015,100.0058746,30179.1787109375,-4.84165223891321E-5,1.6503184730473E-6,1,0.999253354069792,40.0298881530762,1.99394278912203,21.1800001561642,-0.000554583099676141,-6.80637359364292E-5,0.25,2.50889297211647E-6,-4.86985142551727E-5,2.3771360204157E-6,100.0058746,100.0058746,30151.607421875,30206.75,56.5555131374675,20.5537379202696,22.909004,0,0,0,40,4449,99.90805,30179.1787109375,,,,,,,,,,,,,0,,,,0.00245,,,,,,100.0058746,,,,
,31944320.92,100.0071182,33270.41015625,-5.89335215744136E-5,1.5258768025027E-6,1,0.999253354069792,40.0298881530762,1.99402523640603,21.1800001561642,-0.000673378359242998,-9.25332950910532E-5,0.25,2.20033770906895E-6,-5.92744729084281E-5,2.03582604174874E-6,100.0071182,100.0071182,33265.4140625,33275.40625,56.0982604537175,20.5523192155552,22.529354,0,0,0,40,4449,99.90235,33270.41015625,,,,,,,,,,,,,0,,,,0.0049,,,,,,100.0071182,,,,
,31944382.3,100.007782,36338.880859375,-6.85934916669046E-5,1.17244594507675E-6,1,0.999253354069792,40.0298881530762,1.99395990829361,21.1800001561642,-0.000784400967683096,-0.000103894768888899,0.25,2.89522524291492E-6,-6.89916553935921E-5,2.70647070036849E-6,100.007782,100.007782,36308.8671875,36368.89453125,56.7548284098714,20.5540546648069,22.909004,0,0,0,40,4449,99.8975,36338.880859375,,,,,,,,,,,,,0,,,,-0.0049,,,,,,100.007782,,,,
,31944443.72,100.0080185,39409.328125,-7.84604197901506E-5,1.45770020993786E-6,1,0.999253354069792,40.0298881530762,1.99406695897922,21.1800001561642,-0.000897879227944049,-0.000115460009947869,0.25,3.6090386749635E-6,-7.89171225003506E-5,3.39579705927476E-6,100.0080185,100.0080185,39406.859375,39411.796875,56.7954730928714,20.5505601625036,22.529354,0,0,0,40,4449,99.89745,39409.328125,,,,,,,,,,,,,0,,,,-0.0049,,,,,,100.0080185,,,,
,31944503.525,100.0085983,42397.796875,-8.97419463387181E-5,1.66898259295972E-6,1,0.999253354069792,40.0298881530762,1.99389732412895,21.1800001561642,-0.00102336833600303,-0.000152178572119746,0.25,2.35380671017902E-6,-9.02594522801485E-5,2.1008619553647E-6,100.0085983,100.0085983,42365.3125,42430.28125,56.7579549239483,20.5547710641679,23.288654,0,0,0,40,4449,99.8877,42397.796875,,,,,,,,,,,,,0,,,,-0.00245,,,,,,100.0085983,,,,
,31944563.955,100.0070496,45419.91015625,-0.00010073305577058,1.83123712897004E-6,1,0.999253354069792,40.0298881530762,1.99402487437635,21.1800001561642,-0.00114887444282897,-0.000170294161696395,0.25,2.68789234364643E-6,-0.000101314576669732,2.40545614386715E-6,100.0070496,100.0070496,45384.6328125,45455.1875,56.6422739031022,20.5520085140341,22.529354,0,0,0,40,4449,99.8849,45419.91015625,,,,,,,,,,,,,0,,,,0.00245,,,,,,100.0070496,,,,
,31944625.59,100.0089607,48500.439453125,-0.000111530078000275,1.74838518780623E-6,1,0.999253354069792,40.0298881530762,1.99405767523489,21.1800001561642,-0.00127009460355558,-0.000199642411923513,0.25,1.99759003876175E-6,-0.000112171602439103,1.68069632878377E-6,100.0084915,100.0094299,48472.8046875,48528.07421875,56.6571248449675,20.5484141314562,22.909004,0,0,0,40,4449,99.8818,48500.439453125,,,,,,,,,,,,,0,,,,0,,,,,,100.0089607,,,,
,31944686.06,100.0082626,51521.390625,-0.000122762602772435,1.94495230932216E-6,1,0.999253354069792,40.0298881530762,1.9937070346847,21.1800001561642,-0.00140037354451807,-0.000204951887356001,0.25,3.4978180967117E-6,-0.000123473153235318,3.15790220451071E-6,100.0082626,100.0082626,51491.47265625,51551.30859375,56.4265444317944,20.55761380729,22.909004,0,0,0,40,4449,99.87525,51521.390625,,,,,,,,,,,,,0,,,,0,,,,,,100.0082626,,,,
,31944746.36,100.0075226,54537.271484375,-0.000134938635318974,1.60922733455446E-6,1,0.999253354069792,40.0298881530762,1.99390358137914,21.1800001561642,-0.00153878662978394,-0.000228909056754784,0.25,3.52534074336191E-6,-0.000135719390839755,3.15156079002534E-6,100.0075226,100.0075226,54509.8515625,54564.69140625,57.2722664896022,20.5554847212572,22.909004,0,0,0,40,4449,99.87365,54537.271484375,,,,,,,,,,,,,0,,,,-0.00245,,,,,,100.0075226,,,,
,31944807.61,100.0084534,57595.369140625,-0.000145410514981307,1.62451102899665E-6,1,0.999253354069792,40.0298881530762,1.99393102994297,21.1800001561642,-0.0016561961495303,-0.000258283773532052,0.25,2.77475595407358E-6,-0.00014624959723366,2.36792793932792E-6,100.0084534,100.0084534,57567.9609375,57622.77734375,56.9049010855637,20.5522805508885,22.909004,0,0,0,40,4449,99.8691,57595.369140625,,,,,,,,,,,,,0,,,,-0.00245,,,,,,100.0084534,,,,
,31944868.24,100.00826265,60626.6796875,-0.000156139989314827,2.19319721032735E-6,1,0.999253354069792,40.0298881530762,1.99395116326386,21.1800001561642,-0.00177637480620998,-0.000289044591892082,0.25,1.94707222953442E-6,-0.000157038761805516,1.50622454639982E-6,100.0081024,100.0084229,60621.81640625,60631.54296875,57.0190188493714,20.5522721695993,22.909004,0,0,0,40,4449,99.8614,60626.6796875,,,,,,,,,,,,,0,,,,0.00245,,,,,,100.00826265,,,,
,31944927.76,100.006485,63603.341796875,-0.000163958000989709,2.04547208077983E-6,1,0.999253354069792,40.0298881530762,1.99406266586495,21.1800001561642,-0.00186606618641077,-0.00029989718888374,0.25,2.36300311526743E-6,-0.000164903517103378,1.90391416835886E-6,100.006485,100.006485,63570.68359375,63636,56.5148684544675,20.5514605647242,22.909004,0,0,0,40,4449,99.8598,63603.341796875,,,,,,,,,,,,,0,,,,-0.0049,,,,,,100.006485,,,,
,31944989.275,100.0077629,66676.6015625,-0.000176976126517613,2.23638258918856E-6,1,0.999253354069792,40.0298881530762,1.99380666810912,21.1800001561642,-0.00201555568926683,-0.000314769106072702,0.25,3.33263215488773E-6,-0.000177999842297156,2.84377531529721E-6,100.007576,100.0079498,66644.109375,66709.09375,56.7423223535637,20.5553656124003,23.288654,0,0,0,40,4449,99.8531,66676.6015625,,,,,,,,,,,,,0,,,,0,,,,,,100.0077629,,,,
,31945050.46,100.0061264,69735.30078125,-0.000188469758779314,2.22724546086722E-6,1,0.999253354069792,40.0298881530762,1.99378699510195,21.1800001561642,-0.00214325237068605,-0.000353404253651713,0.25,1.94388528739982E-6,-0.000189556325053877,1.4164662622493E-6,100.0061264,100.0061264,69732.4765625,69738.125,57.0635716749676,20.5559068910928,22.909004,0,0,0,40,4449,99.8524,69735.30078125,,,,,,,,,,,,,0,,,,-0.00245,,,,,,100.0061264,,,,
,31945110.405,100.0061493,72731.3515625,-0.000199279702128494,2.39358536096358E-6,1,0.999253354069792,40.0298881530762,1.99378800756282,21.1800001561642,-0.00226385827858497,-0.000386984419676699,0.25,8.8057182349156E-7,-0.000200426234042941,3.18605543645288E-7,100.0061493,100.0061493,72701.2890625,72761.4140625,56.811105663256,20.5543062910054,23.288654,0,0,0,40,4449,99.8492,72731.3515625,,,,,,,,,,,,,0,,,,0.00245,,,,,,100.0061493,,,,
,31945172.86,100.0081482,75853.11328125,-0.000208568221263686,1.66563312873657E-6,1,0.999253354069792,40.0298881530762,1.99404181395502,21.1800001561642,-0.00237694779389116,-0.000363643035577438,0.25,4.56830399159008E-6,-0.000209779593100001,4.00374109347324E-6,100.007515,100.0087814,75820.6015625,75885.625,56.8283014906791,20.5514821654311,22.529354,0,0,0,40,4449,99.8437,75853.11328125,,,,,,,,,,,,,0,,,,-0.0049,,,,,,100.0081482,,,,
,31945235.885,100.0059357,79004.10546875,-0.000221745515865397,2.4349289483109E-6,1,0.999253354069792,40.0298881530762,1.99417877403433,21.1800001561642,-0.00252360722554212,-0.000407696826557767,0.25,2.9999369195608E-6,-0.000223029299191969,2.39188753216098E-6,100.0056,100.0062714,78974.1171875,79034.09375,56.7305979257752,20.5503872927558,22.909004,0,0,0,40,4449,99.83875,79004.10546875,,,,,,,,,,,,,0,,,,0,,,,,,100.0059357,,,,
,31945298.585,100.0057297,82138.0546875,-0.000233181089035983,2.16858676191806E-6,1,0.999253354069792,40.0298881530762,1.99393775078218,21.1800001561642,-0.00265219332618046,-0.000435886664582069,0.25,2.51636614349713E-6,-0.000234530480788873,1.87632125683751E-6,100.0055237,100.0059357,82108.1171875,82167.9921875,56.8423708040252,20.5565908741969,23.288654,0,0,0,40,4449,99.8391,82138.0546875,,,,,,,,,,,,,0,,,,0,,,,,,100.0057297,,,,
,31945358.075,100.00701525,85114.859375,-0.000243024847244069,1.50129130377145E-6,1,0.999253354069792,40.0298881530762,1.99399670455117,21.1800001561642,-0.00276711217121309,-0.000437970231438311,0.25,4.0582946327592E-6,-0.000244436367721877,3.40243974337951E-6,100.0069733,100.0070572,85082.3828125,85147.3359375,56.6602513590445,20.5519864069574,22.529354,0,0,0,40,4449,99.8337,85114.859375,,,,,,,,,,,,,0,,,,0.00245,,,,,,100.00701525,,,,
,31945425.23,100.0057602,88468.046875,-0.000256504921880972,1.74873553294359E-6,1,0.999253354069792,40.0298881530762,1.99397979944282,21.1800001561642,-0.00292609421375814,-0.000430884590308193,0.25,7.04375471845046E-6,-0.000258003781390006,6.37097378286392E-6,100.0057602,100.0057602,88465.5703125,88470.5234375,56.7892200647175,20.5502516203556,22.909004,0,0,0,40,4449,99.8309,88468.046875,,,,,,,,,,,,,0,,,,0,,,,,,100.0057602,,,,
,31945507.79,100.0041046,88200.26953125,-0.000255719567387888,1.85961370721277E-6,1,0.999253354069792,40.0298881530762,1.99384543488047,21.1800001561642,-0.00291293806126343,-0.000452386415193282,0.25,5.00975634004017E-6,-0.000257208130347401,4.32711681140978E-6,100.0041046,100.0041046,88167.734375,88232.8046875,56.7149653553906,20.5552533623035,23.288654,0,0,0,40,4449,99.8283,88200.26953125,,,,,,,,,,,,,0,,,,-0.00245,,,,,,100.0041046,,,,
,31945566.695,100.0001831,85256.87109375,-0.000245617318652276,2.34620133464736E-6,1,0.999253354069792,40.0298881530762,1.99379379938997,21.1800001561642,-0.00279929956983845,-0.000425841687404335,0.25,5.57769810850697E-6,-0.0002470480997775,4.92346473125691E-6,99.9998474,100.0005188,85224.359375,85289.3828125,56.9947883652753,20.5589160271587,23.288654,0,0,0,40,4449,99.8307,85256.87109375,,,,,,,,,,,,,0,,,,-0.00245,,,,,,100.0001831,,,,
,31945625.725,99.9999084,82305.16796875,-0.000233137406911163,2.53899742716172E-6,1,0.999253354069792,40.0298881530762,1.99411261602195,21.1800001561642,-0.00265826195462994,-0.000399690331924415,0.25,5.69999017603074E-6,-0.000234495541842684,5.07847470124591E-6,99.9999084,99.9999084,82280.15625,82330.1796875,56.8775440873906,20.5561077579047,22.909004,0,0,0,40,4449,99.8311,82305.16796875,,,,,,,,,,,,,0,,,,0.00245,,,,,,99.9999084,,,,
,31945695.425,99.9973602,78820.68359375,-0.000221657300206788,2.63229905454419E-6,1,0.999253354069792,40.0298881530762,1.99403845388905,21.1800001561642,-0.00252259380694285,-0.000406592297333507,0.25,3.0795519760298E-6,-0.000222940751241718,2.47198377259124E-6,99.9972534,99.997467,78785.8984375,78855.46875,56.5867782782368,20.5536053325385,22.909004,0,0,0,40,4449,99.833,78820.68359375,,,,,,,,,,,,,0,,,,-0.00245,,,,,,99.9973602,,,,
,31945767.735,99.9968338,75206.5546875,-0.000209668452168403,2.2959089080409E-6,1,0.999253354069792,40.0298881530762,1.99406932343602,21.1800001561642,-0.00238697949631464,-0.000380019331896361,0.25,3.31992783649168E-6,-0.000210882408476909,2.74443985493524E-6,99.9968338,99.9968338,75201.28125,75211.828125,56.9916618511983,20.5536879547577,22.909004,0,0,0,40,4449,99.8361,75206.5546875,,,,,,,,,,,,,0,,,,-0.0049,,,,,,99.9968338,,,,
,31945834.445,99.999794,71872.91015625,-0.000198834444412035,2.35185767504521E-6,1,0.999253354069792,40.0298881530762,1.99399380458548,21.1800001561642,-0.0022657932098019,-0.00034755748116691,0.25,4.27953791342322E-6,-0.000199987792569769,3.73751713317165E-6,99.999794,99.999794,71867.734375,71878.0859375,56.7892200647175,20.5511982108879,23.288654,0,0,0,40,4449,99.8357,71872.91015625,,,,,,,,,,,,,0,,,,0,,,,,,99.999794,,,,
,31945924.545,99.9954681,67367.40625,-0.000178642008687645,2.22971663020269E-6,1,0.999253354069792,40.0298881530762,1.9938522434574,21.1800001561642,-0.00203258725973112,-0.000329063703666092,0.25,2.36601043164456E-6,-0.000179672700756421,1.86722773985197E-6,99.9954681,99.9954681,67359.8515625,67374.9609375,56.8392442899483,20.5560580496323,22.909004,0,0,0,40,4449,99.83885,67367.40625,,,,,,,,,,,,,0,,,,0.00245,,,,,,99.9954681,,,,
,31946017.88,99.9966736,62704.42578125,-0.000163855431534128,2.10425903528449E-6,1,0.999253354069792,40.0298881530762,1.99388500409258,21.1800001561642,-0.00186983077224864,-0.000270665517859705,0.25,4.91856781098195E-6,-0.000164807463220517,4.47363698516085E-6,99.9966736,99.9966736,62702.01953125,62706.83203125,56.7728058658137,20.5548708884721,23.288654,0,0,0,40,4449,99.83985,62704.42578125,,,,,,,,,,,,,0,,,,0,,,,,,99.9966736,,,,
,31946098.93,99.9950867,58650.494140625,-0.000147735208700607,1.98877940198522E-6,1,0.999253354069792,40.0298881530762,1.99385101565308,21.1800001561642,-0.00168144847680494,-0.000269031591156992,0.25,2.23473295184765E-6,-0.000148586239340993,1.81853266628816E-6,99.9950867,99.9950867,58642.23828125,58658.75,56.8064158921406,20.5561883549038,22.909004,0,0,0,40,4449,99.84445,58650.494140625,,,,,,,,,,,,,0,,,,0,,,,,,99.9950867,,,,
,31946204.625,99.9922714,53368.109375,-0.000129588366358381,1.49223877434541E-6,1,0.999253354069792,40.0298881530762,1.99375605735708,21.1800001561642,-0.00147476511096705,-0.000236344882407079,0.25,1.93019474774043E-6,-0.000130333647258611,1.56216801940825E-6,99.9922714,99.9922714,53355.71875,53380.5,56.6516534453329,20.5584044586246,22.529354,0,0,0,40,4449,99.85235,53368.109375,,,,,,,,,,,,,0,,,,-0.00245,,,,,,99.9922714,,,,
,31946293.18,99.9954681,48942.794921875,-0.000112047573339669,1.83742752926646E-6,1,0.999253354069792,40.0298881530762,1.993990504695,21.1800001561642,-0.00127691862882514,-0.000195031233609253,0.25,2.49404560740641E-6,-0.000112693564817403,2.17852043736975E-6,99.9954681,99.9954681,48937.94140625,48947.6484375,56.6594697305252,20.5558724268455,22.529354,0,0,0,40,4449,99.8561,48942.794921875,,,,,,,,,,,,,0,,,,0,,,,,,99.9954681,,,,
,31946394.415,99.993721,43882.17578125,-9.62960297450573E-5,2.1070289579213E-6,1,0.999253354069792,40.0298881530762,1.99391855527478,21.1800001561642,-0.00109558897398894,-0.000177713534824953,0.25,1.25501558958344E-6,-9.68477801233655E-5,9.76824652087996E-7,99.993721,99.993721,43874.5859375,43889.765625,56.821266834006,20.5592269658747,22.909004,0,0,0,40,4449,99.862,43882.17578125,,,,,,,,,,,,,0,,,,-0.00245,,,,,,99.993721,,,,
,31946487.285,99.9938889,39239.7265625,-7.99447707618738E-5,1.61967450733641E-6,1,0.999253354069792,40.0298881530762,1.99392998736437,21.1800001561642,-0.000906270890241368,-0.000166229158458823,0.25,-6.03327825309958E-7,-8.03973090813244E-5,-8.45101592596059E-7,99.9938889,99.9938889,39236.625,39242.828125,56.8150138058522,20.5580153571373,23.288654,0,0,0,40,4449,99.869,39239.7265625,,,,,,,,,,,,,0,,,,0.0049,,,,,,99.9938889,,,,
,31946593.57,99.9921417,33927.71484375,-6.28735243030822E-5,1.49233643389643E-6,1,0.999253354069792,40.0298881530762,1.99379355124604,21.1800001561642,-0.000716351970120671,-0.000109901320029099,0.25,1.36126907706351E-6,-6.32343590368432E-5,1.1802397881386E-6,99.9921417,99.9921417,33920.2265625,33935.203125,56.4070037188137,20.5603017135816,22.909004,0,0,0,40,4449,99.875,33927.71484375,,,,,,,,,,,,,0,,,,-0.00245,,,,,,99.9921417,,,,
,31946698.86,99.9902725,28665.5380859375,-4.34725133955221E-5,1.29901917673208E-6,1,0.999253354069792,40.0298881530762,1.99387754616638,21.1800001561642,-0.000495918103808787,-7.25958566946912E-5,0.25,1.24122034631827E-6,-4.3722547754354E-5,1.11687637778932E-6,99.9902725,99.9902725,28658.033203125,28673.04296875,56.9791557948906,20.5556555117959,22.529354,0,0,0,40,4449,99.88535,28665.5380859375,,,,,,,,,,,,,0,,,,0,,,,,,99.9902725,,,,
,31946804.68,99.9916687,23375.8740234375,-2.63601383896408E-5,1.25243463256959E-6,1,0.999253354069792,40.0298881530762,1.99391577064119,21.1800001561642,-0.000299132073361785,-5.29988542726709E-5,0.25,-3.78957688812295E-8,-2.6509127969963E-5,-1.18290181542342E-7,99.9916687,99.9916687,23370.740234375,23381.0078125,57.1847240954484,20.5585746633059,23.288654,0,0,0,40,4449,99.893,23375.8740234375,,,,,,,,,,,,,0,,,,0.00245,,,,,,99.9916687,,,,
,31946910.44,99.9913788,18090.982421875,-9.47089149524059E-6,8.64922108863608E-7,1,0.999253354069792,40.0298881530762,1.99390233146555,21.1800001561642,-0.000109566867121565,-7.12558135633889E-6,0.25,1.03638153644766E-6,-9.52755404782099E-6,1.01324646916923E-6,99.9913483,99.9914093,18083.46484375,18098.5,57.017455592333,20.5604518297206,22.909004,0,0,0,40,4449,99.899,18090.982421875,,,,,,,,,,,,,0,,,,-0.00245,,,,,,99.9913788,,,,
,31947014.555,99.9905014,12888.7255859375,8.08293020664497E-6,7.2678597115493E-7,1,0.999253354069792,40.0298881530762,1.99378295920635,21.1800001561642,9.14676593320269E-5,1.76683120083135E-5,0.25,1.36290012323608E-7,8.12809752342277E-6,1.61941462418211E-7,99.9905014,99.9905014,12881.0302734375,12896.4208984375,57.0190188493714,20.561870264174,23.288654,0,0,0,40,4449,99.9095,12888.7255859375,,,,,,,,,,,,,0,,,,-0.00245,,,,,,99.9905014,,,,
,31947121.315,99.99181745,7551.27514648438,2.46384159845776E-5,5.21451783256848E-7,1,0.999253354069792,40.0298881530762,1.99385983849151,21.1800001561642,0.000279694646887189,4.88819834987946E-5,0.25,-2.34017556865844E-8,2.47772560172572E-5,5.27301940260395E-8,99.9914093,99.9922256,7543.87939453125,7558.6708984375,56.7743691228522,20.5623074623852,23.668306,0,0,0,40,4449,99.9182,7551.27514648438,,,,,,,,,,,,,0,,,,-0.0049,,,,,,99.99181745,,,,
,31947228.275,99.9925919,2205.99719238281,3.89725308049349E-5,3.88816614937116E-7,1,0.999253354069792,40.0298881530762,1.99401517418639,21.1800001561642,0.000442701097889151,7.58692446543571E-5,0.25,-1.65901038816369E-7,3.91922835679328E-5,-4.56307446582229E-8,99.9925919,99.9925919,2200.998046875,2210.99633789062,56.8869236296214,20.5613812819796,23.288654,0,0,0,40,4449,99.92505,2205.99719238281,,,,,,,,,,,,,0,,,,0,,,,,,99.9925919,,,,
,31947333.305,99.9947968,-3041.423828125,4.59959678047116E-5,3.43647552474697E-7,1,0.999253354069792,40.0298881530762,1.99403330576247,21.1800001561642,0.000522263921560764,9.08152838571521E-5,0.25,-8.35972294215592E-8,4.62550209944419E-5,5.88723936456512E-8,99.9947968,99.9947968,-3046.6044921875,-3036.2431640625,57.017455592333,20.5586835597246,23.288654,0,0,0,40,4449,99.9289,-3041.423828125,,,,,,,,,,,,,0,,,,0,,,,,,99.9947968,,,,
,31947436.905,100.0003586,-8221.46923828125,4.42193132597929E-5,5.69204693498881E-7,1,0.999253354069792,40.0298881530762,1.99403218712977,21.1800001561642,0.000503793604474862,7.76361918105293E-5,0.25,-9.31773511224248E-7,4.44712887358277E-5,-8.00261201817649E-7,100.0003586,100.0003586,-8226.451171875,-8216.4873046875,56.8275198621599,20.5607241566879,23.288654,0,0,0,40,4449,99.9264,-8221.46923828125,,,,,,,,,,,,,0,,,,-0.0049,,,,,,100.0003586,,,,
,31947531.79,100.0059509,-12962.1337890625,3.09526107240463E-5,7.40158856387679E-7,1,0.999253354069792,40.0298881530762,1.99415428049296,21.1800001561642,0.000353886266973615,4.74150270332713E-5,0.25,-1.26242236332094E-6,3.11310691578175E-5,-1.17428730837312E-6,100.0059509,100.0059509,-12969.591796875,-12954.67578125,57.1167224142753,20.5589876662998,23.288654,0,0,0,40,4449,99.9232,-12962.1337890625,,,,,,,,,,,,,0,,,,0.0049,,,,,,100.0059509,,,,
,31947619.51,100.0086937,-17347.4345703125,2.13539293115267E-5,9.73292338756346E-7,1,0.999253354069792,40.0298881530762,1.99394928631581,21.1800001561642,0.000244666271233456,2.96019641891273E-5,0.25,-1.14427720831039E-6,2.14780118728991E-5,-1.08533731943952E-6,100.0084305,100.0089569,-17377.20703125,-17317.662109375,57.0330881627176,20.5620493902152,23.288654,0,0,0,40,4449,99.9127,-17347.4345703125,,,,,,,,,,,,,0,,,,0.00245,,,,,,100.0086937,,,,
,31947713.4,100.0100708,-22036.7861328125,2.72857780163065E-5,1.16567126449894E-6,1,0.999253354069792,40.0298881530762,1.99451513336556,21.1800001561642,0.000312629281265414,3.83413579199578E-5,0.25,-1.41713541117512E-6,2.74443718842804E-5,-1.34203429623704E-6,100.0097275,100.0104141,-22044.095703125,-22029.4765625,56.6758839294291,20.5520752384174,22.909004,0,0,0,40,4449,99.9054,-22036.7861328125,,,,,,,,,,,,,0,,,,0,,,,,,100.0100708,,,,
,31947820.21,100.0099945,-27377.119140625,4.1194222707316E-5,1.07749361174655E-6,1,0.999253354069792,40.0298881530762,1.99402094533727,21.1800001561642,0.00047200524513826,5.71505826726113E-5,0.25,-2.20223784526521E-6,4.14341658000311E-5,-2.09003570142374E-6,100.0099945,100.0099945,-27386.986328125,-27367.251953125,57.0870205305445,20.5636275378523,23.288654,0,0,0,40,4449,99.8952,-27377.119140625,,,,,,,,,,,,,0,,,,-0.0049,,,,,,100.0099945,,,,
,31947927.175,100.0086746,-32721.666015625,5.83573910886493E-5,1.2016066648085E-6,1,0.999253354069792,40.0298881530762,1.99391564191946,21.1800001561642,0.000667445175446241,8.77209939391731E-5,0.25,-2.5228337265928E-6,5.86959687404892E-5,-2.36169820440321E-6,100.0086746,100.0086746,-32729.005859375,-32714.326171875,56.8884868866599,20.5654212815516,23.288654,0,0,0,40,4449,99.8839,-32721.666015625,,,,,,,,,,,,,0,,,,-0.0049,,,,,,100.0086746,,,,
,31948031.995,100.01156235,-37963.1015625,7.61205814287619E-5,1.10226928887604E-6,1,0.999253354069792,40.0298881530762,1.99360232703475,21.1800001561642,0.000871971123689898,0.000105930216099241,0.25,-4.03601685389887E-6,7.65650421284258E-5,-3.8316161502422E-6,100.011467,100.0116577,-37970.46484375,-37955.73828125,57.0096393071407,20.5725322953424,22.909004,0,0,0,40,4449,99.86985,-37963.1015625,,,,,,,,,,,,,0,,,,-0.0049,,,,,,100.01156235,,,,
,31948141.14,100.0105743,-43417.6953125,9.25501546589492E-5,1.05410105920446E-6,1,0.999253354069792,40.0298881530762,1.99387304744476,21.1800001561642,0.00105422250457693,0.000163532732882944,0.25,-1.84630758654098E-6,9.30822315290791E-5,-1.58239830336263E-6,100.0105743,100.0105743,-43427.71875,-43407.671875,56.8689461736791,20.5657963559323,23.668306,0,0,0,40,4449,99.8604,-43417.6953125,,,,,,,,,,,,,0,,,,0,,,,,,100.0105743,,,,
,31948247.965,100.0108261,-48755.109375,0.000113427367186417,1.79006351290566E-6,1,0.999253354069792,40.0298881530762,1.99405282216985,21.1800001561642,0.00129456980825838,0.000186679966843138,0.25,-3.47259905017434E-6,0.000114084018461034,-3.15846764588025E-6,100.0108261,100.0108261,-48764.98828125,-48745.23046875,57.0049495360253,20.5626071294528,23.288654,0,0,0,40,4449,99.84995,-48755.109375,,,,,,,,,,,,,0,,,,0,,,,,,100.0108261,,,,
,31948358.605,100.0093384,-54284.45703125,0.000133735255236022,1.86269061364897E-6,1,0.999253354069792,40.0298881530762,1.99434091857054,21.1800001561642,0.00152184146300583,0.000247077246611508,0.25,-1.71845660911414E-6,0.000134503708767723,-1.33750525883863E-6,100.0093384,100.0093384,-54286.84375,-54282.0703125,56.7462304961599,20.5606837491332,23.668306,0,0,0,40,4449,99.8383,-54284.45703125,,,,,,,,,,,,,0,,,,0.0049,,,,,,100.0093384,,,,
,31948467.925,100.0076218,-59751.306640625,0.000153640874693288,1.74846607668115E-6,1,0.999253354069792,40.0298881530762,1.99407161417992,21.1800001561642,0.00175045850486004,0.000270658091536863,0.25,-3.13013495251817E-6,0.000154528472098849,-2.70252087535573E-6,100.0076218,100.0076218,-59758.71875,-59743.89453125,56.8658196596022,20.5651483405222,22.909004,0,0,0,40,4449,99.83275,-59751.306640625,,,,,,,,,,,,,0,,,,0,,,,,,100.0076218,,,,
,31948574.635,100.0091629,-65081.03125,0.000173975381026664,1.82679491359657E-6,1,0.999253354069792,40.0298881530762,1.99394780751433,21.1800001561642,0.00198610459300826,0.000283265344756979,0.25,-5.58428367538472E-6,0.000174987819040938,-5.11552884868964E-6,100.0091629,100.0091629,-65086.046875,-65076.015625,57.0362146767945,20.5663147805701,23.668306,0,0,0,40,4449,99.8223,-65081.03125,,,,,,,,,,,,,0,,,,-0.0049,,,,,,100.0091629,,,,
,31948682.995,100.0061798,-70497.40234375,0.000191598886552907,1.78478359478606E-6,1,0.999253354069792,40.0298881530762,1.99386511299181,21.1800001561642,0.00218418463871325,0.000329283438036019,0.25,-4.61880490159743E-6,0.000192711159543075,-4.09808375473231E-6,100.0061798,100.0061798,-70502.6640625,-70492.140625,56.9197520274291,20.5685235644384,23.288654,0,0,0,40,4449,99.8171,-70497.40234375,,,,,,,,,,,,,0,,,,0,,,,,,100.0061798,,,,
,31948793.675,100.006279,-76029.4609375,0.000212347814413849,1.86151910682521E-6,1,0.999253354069792,40.0298881530762,1.9939974140763,21.1800001561642,0.00242196443166688,0.000358858630127945,0.25,-5.65244622300156E-6,0.000213583922270299,-5.08324706765338E-6,100.006279,100.006279,-76034.4765625,-76024.4453125,57.1354814987368,20.5661256965489,23.668306,0,0,0,40,4449,99.81095,-76029.4609375,,,,,,,,,,,,,0,,,,0.00245,,,,,,100.006279,,,,
,31948903.265,100.0073547,-81503.77734375,0.00023286356534569,1.67356336573032E-6,1,0.999253354069792,40.0298881530762,1.99393579799002,21.1800001561642,0.00265819197253627,0.000380480744586257,0.25,-7.34204272840376E-6,0.000234224306624711,-6.7296991450131E-6,100.0073547,100.0073547,-81511.1875,-81496.3671875,57.1362631272561,20.5688077768677,23.288654,0,0,0,40,4449,99.8053,-81503.77734375,,,,,,,,,,,,,0,,,,0.00245,,,,,,100.0073547,,,,
,31949012.24,100.005722,-86950.59765625,0.000249417474702087,1.39219211460627E-6,1,0.999253354069792,40.0298881530762,1.99383948132828,21.1800001561642,0.0028402391703862,0.00044634051693361,0.25,-4.43818244818419E-6,0.000250867470591911,-3.76814751146281E-6,100.005722,100.005722,-86957.84375,-86943.3515625,56.8392442899483,20.5709093273939,23.288654,0,0,0,40,4449,99.7969,-86950.59765625,,,,,,,,,,,,,0,,,,0,,,,,,100.005722,,,,
,31949136.215,100.0022736,-87835.94921875,0.000252025010881445,1.79194157895409E-6,1,0.999253354069792,40.0298881530762,1.99383476754679,21.1800001561642,0.00287289215027197,0.000434121800456378,0.25,-5.97105197250268E-6,0.000253494670372799,-5.3034844425065E-6,100.0022736,100.0022736,-87843.5859375,-87828.3125,57.1862873524868,20.5711431120441,22.909004,0,0,0,40,4449,99.7947,-87835.94921875,,,,,,,,,,,,,0,,,,0,,,,,,100.0022736,,,,
,31949242.235,100.0006447,-82536.44921875,0.000236708920545693,1.35183328712499E-6,1,0.999253354069792,40.0298881530762,1.99388452951315,21.1800001561642,0.0026963546045526,0.000419076083574464,0.25,-4.6152546752989E-6,0.000238084506685879,-3.97731116013662E-6,100.0004654,100.000824,-82546.59375,-82526.3046875,57.0471574760637,20.5704491219355,23.288654,0,0,0,40,4449,99.79425,-82536.44921875,,,,,,,,,,,,,0,,,,0.0049,,,,,,100.0006447,,,,
,31949349.61,99.9973831,-77172.09765625,0.000214471409857875,1.76114073726565E-6,1,0.999253354069792,40.0298881530762,1.9942716901614,21.1800001561642,0.00244136203880929,0.000391837964274826,0.25,-3.1238105387175E-6,0.000215712944691717,-2.53495348860075E-6,99.9973831,99.9973831,-77174.625,-77169.5703125,57.2292769210445,20.5591454298191,23.668306,0,0,0,40,4449,99.7973,-77172.09765625,,,,,,,,,,,,,0,,,,-0.0049,,,,,,99.9973831,,,,
,31949455.77,99.9955292,-71865.04296875,0.000198059792438503,1.91215421541186E-6,1,0.999253354069792,40.0298881530762,1.99425819287612,21.1800001561642,0.00225588241275103,0.000354041125508394,0.25,-3.57670847245002E-6,0.000199206586358051,-3.03254902408473E-6,99.9955292,99.9955292,-71872.390625,-71857.6953125,56.8869236296214,20.5599255193247,23.668306,0,0,0,40,4449,99.802,-71865.04296875,,,,,,,,,,,,,0,,,,-0.0049,,,,,,99.9955292,,,,
,31949565.14,99.9950333,-66398.28515625,0.000174918521118934,2.10048257058673E-6,1,0.999253354069792,40.0298881530762,1.99426739242501,21.1800001561642,0.00199341733479524,0.000306289757382186,0.25,-3.72495374029505E-6,0.000175931398408727,-3.2436935153721E-6,99.9950333,99.9950333,-66405.8203125,-66390.75,57.1808159528522,20.5634093371301,23.288654,0,0,0,40,4449,99.8096,-66398.28515625,,,,,,,,,,,,,0,,,,0,,,,,,99.9950333,,,,
,31949674.085,99.9961929,-60953.677734375,0.000158589582187796,1.91970936746797E-6,1,0.999253354069792,40.0298881530762,1.99449605761328,21.1800001561642,0.00180788319806772,0.000275600758813405,0.25,-3.56783452457712E-6,0.000159507036701146,-3.12901279258934E-6,99.9961929,99.9961929,-60963.9375,-60943.41796875,56.946327397083,20.5585823443808,23.668306,0,0,0,40,4449,99.81225,-60953.677734375,,,,,,,,,,,,,0,,,,0.00245,,,,,,99.9961929,,,,
,31949781.655,99.9939041,-55579.26171875,0.000136769795835679,1.85458420216861E-6,1,0.999253354069792,40.0298881530762,1.99439057193968,21.1800001561642,0.00156037599641926,0.000230118979401027,0.25,-3.74477316279234E-6,0.000137561772859476,-3.36712141845841E-6,99.9939041,99.9939041,-55581.703125,-55576.8203125,57.6185279236215,20.5618732994806,22.909004,0,0,0,40,4449,99.8176,-55579.26171875,,,,,,,,,,,,,0,,,,-0.0049,,,,,,99.9939041,,,,
,31949890.395,99.9949417,-50142.7109375,0.000118054604508562,1.51661611905121E-6,1,0.999253354069792,40.0298881530762,1.99423931138961,21.1800001561642,0.00134877457404642,0.000187080400984772,0.25,-4.25080525678998E-6,0.000118740168380083,-3.92803273360547E-6,99.9949417,99.9949417,-50150.2109375,-50135.2109375,56.9541436822753,20.5610636010316,23.668306,0,0,0,40,4449,99.82715,-50142.7109375,,,,,,,,,,,,,0,,,,0.0049,,,,,,99.9949417,,,,
,31950000.22,99.9934311,-44656.23828125,9.90542081196698E-5,1.50123544992798E-6,1,0.999253354069792,40.0298881530762,1.99426498014332,21.1800001561642,0.00113109656267393,0.000160402314795661,0.25,-3.26661615514881E-6,9.96276820704335E-5,-2.99186585420602E-6,99.9934311,99.9934311,-44668.8984375,-44643.578125,56.4585912010829,20.5596749710888,22.909004,0,0,0,40,4449,99.832,-44656.23828125,,,,,,,,,,,,,0,,,,-0.0049,,,,,,99.9934311,,,,
,31950108.08,99.991272,-39265.623046875,7.96455229198781E-5,1.74427749040782E-6,1,0.999253354069792,40.0298881530762,1.99421230331842,21.1800001561642,0.000908273464510319,0.000135604411752295,0.25,-2.04374071367747E-6,8.0104215320816E-5,-1.81780109378655E-6,99.991272,99.991272,-39270.578125,-39260.66796875,57.332451885583,20.5621740695816,23.668306,0,0,0,40,4449,99.84175,-39265.623046875,,,,,,,,,,,,,0,,,,0,,,,,,99.991272,,,,
,31950217.905,99.9924927,-33776.779296875,6.1970443547791E-5,1.50468868351544E-6,1,0.999253354069792,40.0298881530762,1.99441109318943,21.1800001561642,0.00070862544114929,9.49500862087674E-5,0.25,-2.52247460092286E-6,6.23295908194558E-5,-2.35062087443237E-6,99.9924927,99.9924927,-33779.4609375,-33774.09765625,56.8048526351022,20.5574769724828,23.668306,0,0,0,40,4449,99.84795,-33776.779296875,,,,,,,,,,,,,0,,,,0.0049,,,,,,99.9924927,,,,
,31950325.58,99.9921417,-28397.755859375,4.28682799711498E-5,1.58396104954042E-6,1,0.999253354069792,40.0298881530762,1.99414281540466,21.1800001561642,0.000490963995964998,6.09103726736719E-5,0.25,-2.16535142242694E-6,4.31176399242142E-5,-2.04795905536025E-6,99.9921417,99.9921417,-28407.7890625,-28387.72265625,56.2944492120444,20.5626834015177,22.909004,0,0,0,40,4449,99.8568,-28397.755859375,,,,,,,,,,,,,0,,,,-0.0049,,,,,,99.9921417,,,,
,31950433.505,99.9904938,-23000.7255859375,2.51024928778721E-5,1.17363317987813E-6,1,0.999253354069792,40.0298881530762,1.99420212199429,21.1800001561642,0.000285598633183514,4.64958350350594E-5,0.25,-3.14688515602055E-7,2.52454099280763E-5,-2.40040556267361E-7,99.9898987,99.9910889,-23010.591796875,-22990.859375,57.0596635323714,20.5581758366281,23.288654,0,0,0,40,4449,99.8643,-23000.7255859375,,,,,,,,,,,,,0,,,,-0.00245,,,,,,99.9904938,,,,
,31950543.43,99.9888458,-17508.3466796875,7.36628990759525E-6,1.10262475834319E-6,1,0.999253354069792,40.0298881530762,1.9942535506396,21.1800001561642,8.57595164531305E-5,2.54888113699187E-6,0.25,-1.06985218332595E-6,7.41116140440624E-6,-1.053322366771E-6,99.9888458,99.9888458,-17513.302734375,-17503.390625,56.9916618511983,20.5582727894022,23.288654,0,0,0,40,4449,99.87695,-17508.3466796875,,,,,,,,,,,,,0,,,,0.0049,,,,,,99.9888458,,,,
,31950651.98,99.9913139,-12083.748046875,-1.05909711578502E-5,1.48080359532972E-6,1,0.999253354069792,40.0298881530762,1.99431723493893,21.1800001561642,-0.000118320511926911,-3.2027442011664E-5,0.25,-9.59936606116236E-7,-1.06477238412412E-5,-9.97996318115293E-7,99.9911346,99.9914932,-12091.0595703125,-12076.4365234375,56.9932251082368,20.5566557073463,23.288654,0,0,0,40,4449,99.88285,-12083.748046875,,,,,,,,,,,,,0,,,,-0.00245,,,,,,99.9913139,,,,
,31950757.82,99.9911041,-6790.791015625,-2.64952926603143E-5,4.58569182136737E-7,1,0.999253354069792,40.0298881530762,1.99423113646911,21.1800001561642,-0.000299732410060128,-5.88024193297166E-5,0.25,-5.23290344221231E-7,-2.66428538608432E-5,-6.0834286292707E-7,99.9911041,99.9911041,-6803.005859375,-6778.576171875,56.5836517641598,20.5585161381889,23.288654,0,0,0,40,4449,99.89515,-6790.791015625,,,,,,,,,,,,,0,,,,-0.00245,,,,,,99.9911041,,,,
,31950866.585,99.9914627,-1354.78784179688,-4.06223586501137E-5,3.00588837355676E-7,1,0.999253354069792,40.0298881530762,1.99447073908716,21.1800001561642,-0.000460386750180021,-8.56706503768833E-5,0.25,-4.05851524934552E-7,-4.08495528962959E-5,-5.3460085340957E-7,99.9914627,99.9914627,-1359.80224609375,-1349.7734375,56.800944492506,20.5564283984295,23.668306,0,0,0,40,4449,99.9018,-1354.78784179688,,,,,,,,,,,,,0,,,,-0.0049,,,,,,99.9914627,,,,
,31950971.475,99.9968338,3885.72717285156,-4.60465846086984E-5,5.35493138495393E-7,1,0.999253354069792,40.0298881530762,1.99513936496792,21.1800001561642,-0.000521978985893019,-9.74307252008211E-5,0.25,-4.85813747161376E-7,-4.63041713102687E-5,-6.31601660111928E-7,99.9968338,99.9968338,3878.3876953125,3893.06665039063,57.2472543769868,20.5425667325422,23.288654,0,0,0,40,4449,99.905,3885.72717285156,,,,,,,,,,,,,0,,,,0.00245,,,,,,99.9968338,,,,
,31951079.09,100.0026703,9264.88525390625,-4.1403822012755E-5,7.26188640223338E-7,1,0.999253354069792,40.0298881530762,1.99447448144298,21.1800001561642,-0.000469660063604339,-8.49802857824026E-5,0.25,-2.08520267327493E-7,-4.16364443855616E-5,-3.37671343988782E-7,100.0026703,100.0026703,9252.4013671875,9277.369140625,56.6008475915829,20.55927016855,23.288654,0,0,0,40,4449,99.8998,9264.88525390625,,,,,,,,,,,,,0,,,,0,,,,,,100.0026703,,,,
,31951187.825,100.0062256,14700.0288085938,-2.50828223295267E-5,7.26895773754281E-7,1,0.999253354069792,40.0298881530762,1.99436318743444,21.1800001561642,-0.000285917289720259,-4.34800787645194E-5,0.25,5.77843979469239E-7,-2.52261150604841E-5,5.04021842374102E-7,100.0062256,100.0062256,14690.01171875,14710.0458984375,56.9650864815445,20.5548896085086,23.668306,0,0,0,40,4449,99.89275,14700.0288085938,,,,,,,,,,,,,0,,,,0.00245,,,,,,100.0062256,,,,
,31951294.525,100.0085449,20032.05078125,-2.3858158901417E-5,8.87977208779023E-7,1,0.999253354069792,40.0298881530762,1.99407311764122,21.1800001561642,-0.000272116527430757,-4.02434336593325E-5,0.25,6.46829326207234E-7,-2.39949396856262E-5,5.77604556824908E-7,100.0085449,100.0085449,20027.103515625,20036.998046875,56.831428004756,20.5611189418454,23.668306,0,0,0,40,4449,99.88115,20032.05078125,,,,,,,,,,,,,0,,,,-0.00245,,,,,,100.0085449,,,,
,31951403.39,100.0108566,25474.25,-3.56044590869892E-5,1.11006632152678E-6,1,0.999253354069792,40.0298881530762,1.99405091310609,21.1800001561642,-0.000407519258644925,-5.19162444455052E-5,0.25,1.68170953319622E-6,-3.58110521201509E-5,1.58317023652808E-6,100.0108566,100.0108566,25469.072265625,25479.427734375,56.5906864208329,20.5582962679168,23.668306,0,0,0,40,4449,99.87215,25474.25,,,,,,,,,,,,,0,,,,0,,,,,,100.0108566,,,,
,31951511.335,100.0111771,30866.7490234375,-5.20740780073318E-5,1.03138569124164E-6,1,0.999253354069792,40.0298881530762,1.99393849611929,21.1800001561642,-0.000594110882077324,-8.66749049704979E-5,0.25,1.51178276161264E-6,-5.23737924712531E-5,1.36335472754863E-6,100.0111771,100.0111771,30861.6015625,30871.896484375,57.1628384969099,20.5604717958808,23.668306,0,0,0,40,4449,99.85925,30866.7490234375,,,,,,,,,,,,,0,,,,0,,,,,,100.0111771,,,,
,31951619.97,100.0109253,36299.615234375,-7.03181364957145E-5,1.38003453704227E-6,1,0.999253354069792,40.0298881530762,1.99381836846409,21.1800001561642,-0.000802326531538223,-0.000116413085322076,0.25,2.09481924177199E-6,-7.07236180346236E-5,1.89617131590648E-6,100.0109253,100.0109253,36294.44140625,36304.7890625,56.7563916669098,20.5631588006547,23.288654,0,0,0,40,4449,99.8481,36299.615234375,,,,,,,,,,,,,0,,,,-0.00245,,,,,,100.0109253,,,,
,31951728.435,100.0114059,41721.646484375,-8.98656261840962E-5,1.02537916063951E-6,1,0.999253354069792,40.0298881530762,1.9940716598033,21.1800001561642,-0.00102328247975746,-0.000161394643384752,0.25,1.56524526131793E-6,-9.03812935637096E-5,1.30697387015562E-6,100.0114059,100.0114059,41711.890625,41731.40234375,56.7853119221214,20.5578861290046,23.668306,0,0,0,40,4449,99.8372,41721.646484375,,,,,,,,,,,,,0,,,,0,,,,,,100.0114059,,,,
,31951837.155,100.0105515,47154.1640625,-0.000107835067852679,1.69452951010864E-6,1,0.999253354069792,40.0298881530762,1.99414430236394,21.1800001561642,-0.00123049403918944,-0.000179191290637171,0.25,3.15175999674444E-6,-0.000108458574958124,2.8514347296684E-6,100.0105515,100.0105515,47149.2734375,47159.0546875,56.9142806277945,20.5572771247606,23.668306,0,0,0,40,4449,99.8279,47154.1640625,,,,,,,,,,,,,0,,,,-0.0049,,,,,,100.0105515,,,,
,31951945.945,100.0104675,52591.578125,-0.000127105828941551,1.42566863484216E-6,1,0.999253354069792,40.0298881530762,1.99400424801707,21.1800001561642,-0.00144838666689242,-0.000222131299261636,0.25,2.74945848618305E-6,-0.000127839031145935,2.39272871735334E-6,100.0104675,100.0104675,52586.89453125,52596.26171875,56.7149653553906,20.5569059700511,23.288654,0,0,0,40,4449,99.8149,52591.578125,,,,,,,,,,,,,0,,,,-0.00245,,,,,,100.0104675,,,,
,31952054.575,100.0098495,58024.0703125,-0.000145650248616736,1.58300870672152E-6,1,0.999253354069792,40.0298881530762,1.99406528265537,21.1800001561642,-0.00165464068618395,-0.000283742642295604,0.25,5.75879118004157E-7,-0.000146484234874221,1.55621008563781E-7,100.0098495,100.0098495,58014.19140625,58033.94921875,56.9955699937945,20.5566854508002,23.288654,0,0,0,40,4449,99.80795,58024.0703125,,,,,,,,,,,,,0,,,,0,,,,,,100.0098495,,,,
,31952165.665,100.0079117,63574.18359375,-0.000164709169119344,1.99107900863921E-6,1,0.999253354069792,40.0298881530762,1.99418137340857,21.1800001561642,-0.00187147039817634,-0.000319799734022099,0.25,7.43772791186497E-7,-0.000165654116968164,2.72775064827163E-7,100.0079117,100.0079117,63566.66015625,63581.70703125,56.6539983308906,20.5560400082364,23.288654,0,0,0,40,4449,99.801,63574.18359375,,,,,,,,,,,,,0,,,,0,,,,,,100.0079117,,,,
,31952274.875,100.0095062,69031.609375,-0.000184512338232436,1.83101063950646E-6,1,0.999253354069792,40.0298881530762,1.99400650243856,21.1800001561642,-0.00209958274403342,-0.000339648960305297,0.25,2.46524034679851E-6,-0.00018557725952288,1.95106540769103E-6,100.0095062,100.0095062,69018.890625,69044.328125,56.4468667732944,20.5581419684689,23.668306,0,0,0,40,4449,99.7919,69031.609375,,,,,,,,,,,,,0,,,,0.0049,,,,,,100.0095062,,,,
,31952384.455,100.0093384,74509.18359375,-0.000204112588038773,1.59461435223017E-6,1,0.999253354069792,40.0298881530762,1.99388845691226,21.1800001561642,-0.00232390833976642,-0.000367714649868864,0.25,3.42699121322348E-6,-0.000205294451363948,2.86679186805206E-6,100.0093384,100.0093384,74501.5625,74516.8046875,56.8251749766022,20.5557794018373,23.288654,0,0,0,40,4449,99.7835,74509.18359375,,,,,,,,,,,,,0,,,,0,,,,,,100.0093384,,,,
,31952495.55,100.0061493,80061.92578125,-0.000226330806430382,2.01603388936899E-6,1,0.999253354069792,40.0298881530762,1.99427995768107,21.1800001561642,-0.00257088282429672,-0.000444839669719213,0.25,5.34611345061308E-7,-0.000227634162399024,-1.00167832930664E-7,100.0061493,100.0061493,80054.6484375,80069.203125,56.4687523718329,20.5525802459366,23.288654,0,0,0,40,4449,99.77805,80061.92578125,,,,,,,,,,,,,0,,,,0.00245,,,,,,100.0061493,,,,
,31952602.075,100.0048828,85387.875,-0.000245230923631806,1.66720577489547E-6,1,0.999253354069792,40.0298881530762,1.99418402586948,21.1800001561642,-0.00278646257731333,-0.000476282275104882,0.25,1.07479090979132E-6,-0.000246646672231316,3.95195772202582E-7,100.0048828,100.0048828,85383.15625,85392.59375,56.8767624588714,20.5507605197876,23.668306,0,0,0,40,4449,99.772,85387.875,,,,,,,,,,,,,0,,,,-0.00245,,,,,,100.0048828,,,,
,31952725.375,100.0052338,89456.71484375,-0.000260021432834113,1.34518969791234E-6,1,0.999253354069792,40.0298881530762,1.99426934376976,21.1800001561642,-0.00295568510177226,-0.00049919632148266,0.25,1.64926671020472E-6,-0.000261525714222592,9.35955698572839E-7,100.0052338,100.0052338,89446.765625,89466.6640625,56.6235148186406,20.551074214619,23.288654,0,0,0,40,4449,99.7686,89456.71484375,,,,,,,,,,,,,0,,,,-0.00245,,,,,,100.0052338,,,,
,31952831.54,100.00047685,84149.28125,-0.000240282296063185,1.73093765718782E-6,1,0.999253354069792,40.0298881530762,1.9942695544832,21.1800001561642,-0.00272977145405358,-0.000469927269268634,0.25,7.69198759303098E-7,-0.000241668189322167,1.00404365418708E-7,100.0002213,100.0007324,84144.421875,84154.140625,57.0252718775253,20.5506220505589,23.668306,0,0,0,40,4449,99.76755,84149.28125,,,,,,,,,,,,,0,,,,-0.00245,,,,,,100.00047685,,,,
,31952940.365,99.9971924,78708.32421875,-0.000225071488073303,1.66228584733972E-6,1,0.999253354069792,40.0298881530762,1.99404708862605,21.1800001561642,-0.00255767415473737,-0.000434412877309498,0.25,1.22893728483324E-6,-0.000226369061344304,6.00368829392398E-7,99.9971924,99.9971924,78695.7578125,78720.890625,57.0166739638137,20.5558279318655,23.288654,0,0,0,40,4449,99.7712,78708.32421875,,,,,,,,,,,,,0,,,,-0.00245,,,,,,99.9971924,,,,
,31953049.49,99.9967346,73252.37890625,-0.000198969858068097,1.44916879733202E-6,1,0.999253354069792,40.0298881530762,1.99401279401677,21.1800001561642,-0.00226377360136854,-0.000368231964487822,0.25,2.48191172015114E-6,-0.000200119110254523,1.9297795221267E-6,99.9967346,99.9967346,73242.3046875,73262.453125,56.9674313671022,20.5571705648129,24.047956,0,0,0,40,4449,99.77515,73252.37890625,,,,,,,,,,,,,0,,,,-0.00245,,,,,,99.9967346,,,,
,31953157.63,99.9949646,67849.90234375,-0.000181941602880989,1.88660219086453E-6,1,0.999253354069792,40.0298881530762,1.99408500457744,21.1800001561642,-0.00206904614112242,-0.000342665559001381,0.25,1.75038568166272E-6,-0.000182989392275736,1.23848601971355E-6,99.9949646,99.9949646,67844.5703125,67855.234375,56.8978664288906,20.557103975952,23.288654,0,0,0,40,4449,99.78075,67849.90234375,,,,,,,,,,,,,0,,,,0.0049,,,,,,99.9949646,,,,
,31953266.4,99.9953613,62411.58984375,-0.000159661807192982,1.34268095671776E-6,1,0.999253354069792,40.0298881530762,1.99410975695906,21.1800001561642,-0.00181996393343231,-0.000276327211699288,0.25,3.68686048559065E-6,-0.000160586049010602,3.24639065034694E-6,99.9953613,99.9953613,62406.72265625,62416.45703125,56.5867782782368,20.5580151795288,23.668306,0,0,0,40,4449,99.7866,62411.58984375,,,,,,,,,,,,,0,,,,0,,,,,,99.9953613,,,,
,31953374.945,99.9928322,56986.302734375,-0.000141391034774747,1.54207333022853E-6,1,0.999253354069792,40.0298881530762,1.99427456397689,21.1800001561642,-0.00161689193631509,-0.000215781788776521,0.25,5.81715286283104E-6,-0.000142215703299254,5.43851777647366E-6,99.9928055,99.9928589,56978.81640625,56993.7890625,56.811105663256,20.5531522553959,23.288654,0,0,0,40,4449,99.7932,56986.302734375,,,,,,,,,,,,,0,,,,-0.00245,,,,,,99.9928322,,,,
,31953481.975,99.9950714,51636.525390625,-0.000122045403590931,1.5664021816577E-6,1,0.999253354069792,40.0298881530762,1.99449760079428,21.1800001561642,-0.00139066275990584,-0.000215536197046549,0.25,2.44694287213057E-6,-0.00012274865484277,2.10273875721826E-6,99.9950714,99.9950714,51631.26171875,51641.7890625,56.9869720800829,20.5484879603159,23.288654,0,0,0,40,4449,99.799,51636.525390625,,,,,,,,,,,,,0,,,,-0.0049,,,,,,99.9950714,,,,
,31953588.48,99.9945221,46311.94921875,-0.000104534543800992,1.87143944163469E-6,1,0.999253354069792,40.0298881530762,1.99454293621669,21.1800001561642,-0.00118898798548046,-0.000196916869266085,0.25,1.01456849466483E-6,-0.000105132781767724,7.11344618257076E-7,99.9945221,99.9945221,46304.71484375,46319.18359375,56.8118872917752,20.5491426387963,23.668306,0,0,0,40,4449,99.8069,46311.94921875,,,,,,,,,,,,,0,,,,-0.00245,,,,,,99.9945221,,,,
,31953695.225,99.9921112,40979.982421875,-8.53368008098799E-5,1.52000759648517E-6,1,0.999253354069792,40.0298881530762,1.99452320379506,21.1800001561642,-0.000972476503205777,-0.000150138929149833,0.25,1.76458560789033E-6,-8.58271952140576E-5,1.52055590264431E-6,99.9921112,99.9921112,40972.90234375,40987.0625,56.4906379703714,20.5525277623667,23.288654,0,0,0,40,4449,99.8139,40979.982421875,,,,,,,,,,,,,0,,,,-0.00245,,,,,,99.9921112,,,,
,31953801.165,99.9911575,35684.578125,-6.77743264574106E-5,1.23023423196156E-6,1,0.999253354069792,40.0298881530762,1.99464349190072,21.1800001561642,-0.000772576508827284,-0.000118109359408348,0.25,1.50292148369285E-6,-6.81635150379081E-5,1.30827201864601E-6,99.9911575,99.9911575,35679.640625,35689.515625,56.4109118614098,20.5489558225237,24.047956,0,0,0,40,4449,99.8217,35684.578125,,,,,,,,,,,,,0,,,,0,,,,,,99.9911575,,,,
,31953908.395,99.9920578,30324.900390625,-4.81215506253978E-5,1.01060167518445E-6,1,0.999253354069792,40.0298881530762,1.99433262440976,21.1800001561642,-0.000548957444040217,-8.1034690065717E-5,0.25,1.31585725955667E-6,-4.83982196646525E-5,1.17806332593501E-6,99.9920578,99.9920578,30322.501953125,30327.298828125,56.8626931455252,20.5554840401529,23.668306,0,0,0,40,4449,99.8314,30324.900390625,,,,,,,,,,,,,0,,,,0,,,,,,99.9920578,,,,
,31954016.485,99.9909821,24922.3193359375,-3.26545957459219E-5,8.33630670952898E-7,1,0.999253354069792,40.0298881530762,1.99426783641843,21.1800001561642,-0.000373166724540577,-5.11919215657212E-5,0.25,1.22785482232038E-6,-3.28430804578812E-5,1.13557402089201E-6,99.9909821,99.9909821,24914.923828125,24929.71484375,56.8814522299868,20.5563923604227,23.668306,0,0,0,40,4449,99.83935,24922.3193359375,,,,,,,,,,,,,0,,,,0,,,,,,99.9909821,,,,
,31954122.49,99.9908981,19622.9248046875,-1.37249948892982E-5,6.69567261850877E-7,1,0.999253354069792,40.0298881530762,1.99452064528486,21.1800001561642,-0.000159736588271668,-5.16345650777983E-6,0.25,1.95684319464202E-6,-1.3808513447942E-5,1.92592684070584E-6,99.9908981,99.9908981,19612.994140625,19632.85546875,56.6102271338137,20.5517854676161,23.288654,0,0,0,40,4449,99.84725,19622.9248046875,,,,,,,,,,,,,0,,,,-0.0049,,,,,,99.9908981,,,,
,31954229.145,99.990715,14293.6142578125,3.27537276396179E-6,7.42149576668077E-7,1,0.999253354069792,40.0298881530762,1.99452903981391,21.1800001561642,3.46853820640589E-5,2.07769154523306E-5,0.25,1.25436772431051E-6,3.2899897307801E-6,1.27151961356454E-6,99.990715,99.990715,14286.1181640625,14301.1103515625,56.7900016932368,20.5545257754991,23.288654,0,0,0,40,4449,99.85855,14293.6142578125,,,,,,,,,,,,,0,,,,0.00245,,,,,,99.990715,,,,
,31954336.195,99.9905472,8943.76416015625,2.0421186707051E-5,6.20094302701596E-7,1,0.999253354069792,40.0298881530762,1.99430433967404,21.1800001561642,0.00023030547830751,4.9427545216002E-5,0.25,7.64938620171047E-7,2.05338517878494E-5,8.32423635981848E-7,99.9905472,99.9905472,8938.806640625,8948.7216796875,56.9244417985445,20.5595983374581,23.668306,0,0,0,40,4449,99.8684,8943.76416015625,,,,,,,,,,,,,0,,,,0,,,,,,99.9905472,,,,
,31954442.88,99.990387,3610.66076660156,3.53456110814535E-5,3.75706530474273E-7,1,0.999253354069792,40.0298881530762,1.99429064273076,21.1800001561642,0.000400433795830112,7.51961852684952E-5,0.25,4.11432690310878E-7,3.5543179959887E-5,5.23643876999501E-7,99.990387,99.990387,3605.61767578125,3615.70385742188,56.7321611828137,20.5580029753232,23.288654,0,0,0,40,4449,99.8735,3610.66076660156,,,,,,,,,,,,,0,,,,-0.0049,,,,,,99.990387,,,,
,31954515.02,99.9935684,-0.56327959895134,4.393291157011E-5,3.34769979079276E-7,1,0.999253354069792,40.0298881530762,1.99422077795903,21.1800001561642,0.000499738272907633,8.18749985334202E-5,0.25,-5.09643787072306E-7,4.41814983600806E-5,-3.75571120770535E-7,99.9935684,99.9935684,-0.593727171421051,-0.532832026481628,56.8298647477175,20.5591855954603,23.288654,0,0,0,40,4417,99.8791,-0.56327959895134,,,,,,,,,,,,,0,,,,0,,,,,,99.9935684,,,,