File: data/looselyPackedNP/ios-11/vsm/rawdata/PMK18_ZFCW_100OESLOW.DAT
[Header]
; VSM Data File (default extension .dat)
; Copyright (c) 2003-2013, Quantum Design, Inc. All rights reserved.
TITLE,
FILEOPENTIME,30338846.23,12/18/2018,11:28 am
BYAPP,VSM,2.0,2.0
INFO,PPMS VSM Option Release 1.4.10 Build 1,APPNAME
INFO,Quantum Design Linear Motor Servo Controller,MOTOR_MODULE_NAME
INFO,3101-100 M1,MOTOR_HW_VERSION
INFO,MMC1014,MOTOR_SERIAL_NUMBER
INFO,SRV No X-over 01.03.11,MOTOR_SOFTWARE_VERSION
INFO,Quantum Design VSM Detection Module,VSM_MODULE_NAME
INFO,3101-150 F0,VSM_HW_VERSION
INFO,VSM707,VSM_SERIAL_NUMBER
INFO,VSM No X-over 01.02.05 May 20 2008 13:51:47,VSM_SOFTWARE_VERSION
INFO,704,PREAMP_SERIAL_NUMBER
INFO,822,COIL_SERIAL_NUMBER
INFO,0,MOMENT_UNITS
INFO,Maghemite,SAMPLE_MATERIAL
INFO,Oleate Iron Spheres,SAMPLE_COMMENT
INFO,,SAMPLE_MASS
INFO,,SAMPLE_VOLUME
INFO,,SAMPLE_MOLECULAR_WEIGHT
INFO,,SAMPLE_SIZE
INFO,,SAMPLE_SHAPE
DATATYPE,COMMENT,1
DATATYPE,TIME,2
STARTUPAXIS,X,2
STARTUPAXIS,Y1,5
[Data]
Comment,Time Stamp (sec),Temperature (K),Magnetic Field (Oe),Moment (emu),M. Std. Err. (emu),Transport Action,Averaging Time (sec),Frequency (Hz),Peak Amplitude (mm),Center Position (mm),Coil Signal' (mV),Coil Signal" (mV),Range (mV),M. Quad. Signal (emu),M. Raw' (emu),M. Raw" (emu),Min. Temperature (K),Max. Temperature (K),Min. Field (Oe),Max. Field (Oe),Mass (grams),Motor Lag (deg),Pressure (Torr),VSM Status (code),Motor Status (code),Measure Status (code),Measure Count,PPMS Status (code),System Temp. (K),System Field (Oe),Sample Position (deg),Bridge 1 Resistance (ohms),Bridge 1 Excitation (에),Bridge 2 Resistance (ohms),Bridge 2 Excitation (에),Bridge 3 Resistance (ohms),Bridge 3 Excitation (에),Bridge 4 Resistance (ohms),Bridge 4 Excitation (에),Signal 1 Vin (V),Signal 2 Vin (V),Digital Inputs (code),Drive 1 Iout (mA),Drive 1 Ipower (W),Drive 2 Iout (mA),Drive 2 Ipower (W),Pressure (),Map 20 (),Map 21 (),Map 22 (),Map 23 (),Map 24 (),Map 25 (),Map 26 (),Map 27 (),Map 28 (),Map 29 ()
,30356515.75,10.0031767,99.7004928588867,,,2,,,,29.2999994564056,,,,,,,10.0031767,10.0031767,99.7004928588867,99.7004928588867,,,11.899124,,,,-99999999,4369,9.9929,99.7004928588867,,,,,,,,,,,,,,,,,,,,,,,10.0031767,,,,
,30356893.35,12.0025043,99.7004928588867,0.000364454489445583,3.40838154531576E-7,1,0.999253354069792,40.0298881530762,1.98829773763639,29.279999434948,0.0040701694437988,0.000766177276288462,0.25,3.76154086875328E-6,0.000362342292168538,5.49762501011875E-6,12.0025043,12.0025043,99.7004928588867,99.7004928588867,56.6266413327175,20.5730856901818,12.278775,0,0,0,40,4370,12.0171,99.7004928588867,,,,,,,,,,,,,0,,,,0.0049,,,,,,12.0025043,,,,
,30357256.625,15.0206165,99.7004928588867,0.00040510524315125,3.46144567931132E-7,1,0.999253354069792,40.0298881530762,1.98755783210389,29.279999434948,0.00452405699307165,0.000842611112174914,0.25,3.40182834287111E-6,0.000402758236152027,5.33599096475328E-6,15.0206165,15.0206165,99.7004928588867,99.7004928588867,56.9041194570445,20.596250815199,12.658426,0,0,0,40,4370,15.0541,99.7004928588867,,,,,,,,,,,,,0,,,,0.00245,,,,,,15.0206165,,,,
,30357614.055,18.0095406,99.7004928588867,0.000454511382263725,3.74853783909417E-7,1,0.999253354069792,40.0298881530762,1.98829464026844,29.279999434948,0.00507678888678576,0.000949996860515807,0.25,4.20095661375095E-6,0.000451871788047321,6.36852586037607E-6,18.0095406,18.0095406,99.7004928588867,99.7004928588867,56.7337244398522,20.5927910676778,13.038077,0,0,0,40,4370,18.03445,99.7004928588867,,,,,,,,,,,,,0,,,,-0.00245,,,,,,18.0095406,,,,
,30357916.165,20.5134602,99.7004928588867,0.000503255976030843,3.48171922971799E-7,1,0.999253354069792,40.0298881530762,1.99933463129724,29.3099991977215,0.00565118724747608,0.00105746239072539,0.25,4.62985112020518E-6,0.000500345460743137,7.05006527672337E-6,20.5134602,20.5134602,99.7004928588867,99.7004928588867,56.5398805670829,20.5861923277681,13.797379,0,0,0,40,4370,20.55455,99.7004928588867,,,,,,,,,,,,,0,,,,-0.00245,,,,,,20.5134602,,,,
,30358276.52,23.5112324,99.7004928588867,0.0005700551694938,3.40586147976505E-7,1,0.999253354069792,40.0298881530762,1.99919317716866,29.3099991977215,0.00640088450641816,0.00120090773356796,0.25,5.45002650527357E-6,0.000566807288579516,8.25695761035398E-6,23.5112324,23.5112324,99.7004928588867,99.7004928588867,57.3652802833907,20.5921784849619,14.177031,0,0,0,40,4370,23.5664,99.7004928588867,,,,,,,,,,,,,0,,,,0,,,,,,23.5112324,,,,
,30358638.32,26.5015602,99.7004928588867,0.000644798751909856,3.37226960759554E-7,1,0.999253354069792,40.0298881530762,1.99934023683975,29.3099991977215,0.00724176920767437,0.00135918305467204,0.25,6.08281115892822E-6,0.000641231374105105,9.38493047611169E-6,26.5015602,26.5015602,99.7004928588867,99.7004928588867,57.6826214621984,20.5902921877424,14.556682,0,0,0,40,4370,26.59695,99.7004928588867,,,,,,,,,,,,,0,,,,0,,,,,,26.5015602,,,,
,30358999.34,29.5158768,99.7004928588867,0.000725103973025502,3.16107277107478E-7,1,0.999253354069792,40.0298881530762,1.99907990184925,29.3099991977215,0.00814430937498302,0.00153114432330519,0.25,6.86634289475536E-6,0.000721275516833968,1.07760415093458E-5,29.5158768,29.5158768,99.7004928588867,99.7004928588867,57.1855057239676,20.598477210606,14.556682,0,0,0,40,4370,29.60905,99.7004928588867,,,,,,,,,,,,,0,,,,0,,,,,,29.5158768,,,,
,30359299.455,32.0047607,99.7004928588867,0.00079659203387331,3.22410068791589E-7,1,0.999253354069792,40.0298881530762,1.99991033611746,29.3099991977215,0.00895366040890852,0.00168199596665876,0.25,7.21335529657932E-6,0.000792619630181994,1.17300964841861E-5,32.0047607,32.0047607,99.7004928588867,99.7004928588867,57.058100275333,20.5905042723598,14.556682,0,0,0,40,4370,32.1202,99.7004928588867,,,,,,,,,,,,,0,,,,0.0049,,,,,,32.0047607,,,,
,30359663.38,35.0053253,99.7004928588867,0.000886114451758382,2.90039638100728E-7,1,0.999253354069792,40.0298881530762,1.99945793254974,29.3099991977215,0.00996231538272064,0.00187194209289756,0.25,7.73326450091566E-6,0.000882107742524311,1.30941849145927E-5,35.0053253,35.0053253,99.7004928588867,99.7004928588867,57.6294707228907,20.6017628646765,15.315984,0,0,0,40,4370,35.1643,99.7004928588867,,,,,,,,,,,,,0,,,,0,,,,,,35.0053253,,,,
,30360023.255,38.0138855,99.7004928588867,0.000981221649610143,3.39624101222423E-7,1,0.999253354069792,40.0298881530762,2.00042508255065,29.3099991977215,0.0110424855812816,0.00207891427887035,0.25,8.529335636125E-6,0.000977359001015798,1.48506185915458E-5,38.0138855,38.0138855,99.7004928588867,99.7004928588867,57.3004051162945,20.5891854454031,16.075285,0,0,0,40,4370,38.16995,99.7004928588867,,,,,,,,,,,,,0,,,,-0.0049,,,,,,38.0138855,,,,
touchdown = 19.0999992191792 mm,30360335.32,40.5934868,99.7004928588867,0.00106891821413511,3.0445791678988E-7,1,0.999253354069792,40.0298881530762,2.00099876900776,29.3099991977215,0.0120393986411133,0.00227065525233823,0.25,9.29976473582766E-6,0.00106536324463307,1.65345919835378E-5,40.5934868,40.5934868,99.7004928588867,99.7004928588867,57.0127658212176,20.5724941248294,15.315984,0,0,0,40,4370,40.7782,99.7004928588867,,,,,,,,,,,,,0,,,,0.0049,,,,,,40.5934868,,,,
,30360687.88,43.5164337,99.7004928588867,0.00117498691715381,4.12759090272955E-7,1,0.999253354069792,40.0298881530762,2.00105363724554,29.3099991977215,0.0132443249486777,0.00250164458930573,0.25,1.01840399252107E-5,0.00117201147690113,1.85092495223203E-5,43.5164337,43.5164337,99.7004928588867,99.7004928588867,57.166746639506,20.5745039384052,16.075285,0,0,0,40,4370,43.7245,99.7004928588867,,,,,,,,,,,,,0,,,,0.00245,,,,,,43.5164337,,,,
,30361049.43,46.5083122,99.7004928588867,0.00129194762362954,3.50193994993113E-7,1,0.999253354069792,40.0298881530762,2.00104008773764,29.3099991977215,0.0145758283578626,0.00275317654569039,0.25,1.09169590888826E-5,0.00128984714639008,2.03729227467503E-5,46.5083122,46.5083122,99.7004928588867,99.7004928588867,57.0526288756983,20.5730526840706,16.075285,0,0,0,40,4370,46.76315,99.7004928588867,,,,,,,,,,,,,0,,,,-0.00245,,,,,,46.5083122,,,,
,30361412.345,49.5122681,99.7004928588867,0.00141669683917068,3.96221194583762E-7,1,0.999253354069792,40.0298881530762,2.00141087940215,29.3099991977215,0.0160018051386344,0.0030199511442194,0.25,1.1613807047269E-5,0.00141574661281902,2.21416127611947E-5,49.5122681,49.5122681,99.7004928588867,99.7004928588867,57.4661103623715,20.5683522971669,17.214239,0,0,0,40,4370,49.8117,99.7004928588867,,,,,,,,,,,,,0,,,,0,,,,,,49.5122681,,,,
,30361719.28,52.0144882,99.7004928588867,0.00152635758358488,3.52090673923047E-7,1,0.999253354069792,40.0298881530762,2.00133731532369,29.3099991977215,0.0172536927233395,0.00325683449925493,0.25,1.25979462963028E-5,0.00152656904761558,2.39278102941659E-5,52.0144882,52.0144882,99.7004928588867,99.7004928588867,57.1847240954484,20.5743279652359,18.732843,0,0,0,40,4370,52.4028,99.7004928588867,,,,,,,,,,,,,0,,,,-0.0049,,,,,,52.0144882,,,,
,30362083.435,55.0153503,99.7004928588867,0.00165800604306098,3.51938343095045E-7,1,0.999253354069792,40.0298881530762,2.00211185515784,29.3099991977215,0.0187676982783957,0.00353251749081556,0.25,1.3054440336308E-5,0.00165976269422656,2.5152480041823E-5,55.0153503,55.0153503,99.7004928588867,99.7004928588867,57.1175040427945,20.5600616271201,19.492144,0,0,0,40,4370,55.477,99.7004928588867,,,,,,,,,,,,,0,,,,0,,,,,,55.0153503,,,,
,30362445.235,58.0150986,99.7004928588867,0.00179447580980549,3.98835093264729E-7,1,0.999253354069792,40.0298881530762,2.00201368194035,29.3099991977215,0.0203289266969138,0.0038226601131724,0.25,1.42405799100085E-5,0.00179786253125816,2.6927729134607E-5,58.0150986,58.0150986,99.7004928588867,99.7004928588867,57.5223876157561,20.5629847334067,20.631098,0,0,0,40,4370,58.513,99.7004928588867,,,,,,,,,,,,,0,,,,0,,,,,,58.0150986,,,,
,30362772.92,60.7469864,99.7004928588867,,,2,,,,29.3099999982119,,,,,,,60.7469864,60.7469864,99.7004928588867,99.7004928588867,,,21.01075,,,,-99999999,4370,61.2435,99.7004928588867,,,,,,,,,,,,,,,,,,,,,,,60.7469864,,,,
,30363107.09,63.5141487,99.7004928588867,0.00204091330639659,3.84631174657654E-7,1,0.999253354069792,40.0298881530762,1.99065329529011,29.3000005185604,0.0230279726828706,0.00430755870679255,0.25,1.54762197827548E-5,0.002047317684338,2.87198965663254E-5,63.5141487,63.5141487,99.7004928588867,99.7004928588867,57.2777378892368,20.5510920908047,21.3904,0,0,0,40,4370,64.0333,99.7004928588867,,,,,,,,,,,,,0,,,,0.00245,,,,,,63.5141487,,,,
,30363468.245,66.5124359,99.7004928588867,0.00216729065946187,3.91314323421705E-7,1,0.999253354069792,40.0298881530762,1.99095680783222,29.3000005185604,0.0244724081506593,0.00456692310382539,0.25,1.63048272072993E-5,0.00217525859400091,2.95844588842113E-5,66.5124359,66.5124359,99.7004928588867,99.7004928588867,57.3129111726022,20.547808395015,21.3904,0,0,0,40,4370,67.0567,99.7004928588867,,,,,,,,,,,,,0,,,,-0.00245,,,,,,66.5124359,,,,
,30363827.595,69.50027085,99.7004928588867,0.00228222463516511,4.00544272284858E-7,1,0.999253354069792,40.0298881530762,1.99115087967278,29.3000005185604,0.0257861998837249,0.00479880654596343,0.25,1.6875857815289E-5,0.00229162572095491,3.00254501333136E-5,69.4910889,69.5094528,99.7004928588867,99.7004928588867,57.627125837333,20.5510178497818,21.770052,0,0,0,40,4370,70.0689,99.7004928588867,,,,,,,,,,,,,0,,,,0.00245,,,,,,69.50027085,,,,
,30364131.015,72.0113144,99.7004928588867,0.00237118205969689,3.65346900169573E-7,1,0.999253354069792,40.0298881530762,1.99093722763541,29.279999434948,0.0267986196382435,0.00497630977611575,0.25,1.73221011208792E-5,0.00238168162256991,3.0268191266682E-5,72.0113144,72.0113144,99.7004928588867,99.7004928588867,57.1878506095253,20.5613726673239,21.3904,0,0,0,40,4370,72.6093,99.7004928588867,,,,,,,,,,,,,0,,,,0,,,,,,72.0113144,,,,
,30364491.875,75.0150681,99.7004928588867,0.00246330406809621,4.32399493305212E-7,1,0.999253354069792,40.0298881530762,1.99147543260525,29.279999434948,0.0278566194585741,0.00516434338186426,0.25,1.81219054008978E-5,0.0024749454911715,3.07293586500572E-5,75.0150681,75.0150681,99.7004928588867,99.7004928588867,57.1776894387753,20.5477278480537,22.149702,0,0,0,40,4370,75.6156,99.7004928588867,,,,,,,,,,,,,0,,,,0.0049,,,,,,75.0150681,,,,
,30364855.035,78.0137863,99.7004928588867,0.00254085773826994,4.66877126802981E-7,1,0.999253354069792,40.0298881530762,1.99131640510942,29.279999434948,0.0287407647831698,0.00531414440592202,0.25,1.83193470082763E-5,0.00255348318316699,3.04921854762699E-5,78.0137863,78.0137863,99.7004928588867,99.7004928588867,56.8392442899483,20.561461979056,22.529354,0,0,0,40,4370,78.67655,99.7004928588867,,,,,,,,,,,,,0,,,,0,,,,,,78.0137863,,,,
,30365217.03,81.022171,99.7004928588867,,,2,,,,29.2900007772446,,,,,,,81.022171,81.022171,99.7004928588867,99.7004928588867,,,22.529354,,,,-99999999,4370,81.7075,99.7004928588867,,,,,,,,,,,,,,,,,,,,,,,81.022171,,,,
,30365520.96,83.5579071,99.7004928588867,0.00264656217727927,4.25166015408347E-7,1,0.999253354069792,40.0298881530762,2.00182589676406,29.279999434948,0.030100638654362,0.0055415954049494,0.25,1.84563283258853E-5,0.0026605451282311,2.97198710152093E-5,83.5579071,83.5579071,99.7004928588867,99.7004928588867,56.9713395096983,20.5544258877352,22.149702,0,0,0,40,4370,84.26485,99.7004928588867,,,,,,,,,,,,,0,,,,0,,,,,,83.5579071,,,,
,30365877.025,86.524086,99.7004928588867,0.00268428688618763,3.03508166473055E-7,1,0.999253354069792,40.0298881530762,2.00163830546618,29.279999434948,0.0305312548890983,0.00561577319105024,0.25,1.89570652679055E-5,0.00269877247883345,2.97108284775502E-5,86.524086,86.524086,99.7004928588867,99.7004928588867,57.2417829773522,20.5454392992402,22.909004,0,0,0,40,4370,87.22635,99.7004928588867,,,,,,,,,,,,,0,,,,0,,,,,,86.524086,,,,
,30366236.985,89.5351334,99.7004928588867,0.00270924131398102,3.63615358684349E-7,1,0.999253354069792,40.0298881530762,2.00183810074464,29.279999434948,0.0308220121191357,0.00566121553855154,0.25,1.90777271440242E-5,0.0027240953302381,2.93023199542762E-5,89.5351334,89.5351334,99.7004928588867,99.7004928588867,57.1628384969099,20.5421082682845,22.529354,0,0,0,40,4370,90.23035,99.7004928588867,,,,,,,,,,,,,0,,,,0,,,,,,89.5351334,,,,
,30366534.085,92.01446155,99.7004928588867,0.00272222901639952,4.18142822314164E-7,1,0.999253354069792,40.0298881530762,2.00137203384666,29.2700007557869,0.030966231184446,0.0056775364133276,0.25,1.87819613212901E-5,0.00273729934933935,2.85746821792162E-5,92.0021973,92.0267258,99.7004928588867,99.7004928588867,56.7798405224868,20.5533478514338,22.909004,0,0,0,40,4370,92.7039,99.7004928588867,,,,,,,,,,,,,0,,,,-0.00245,,,,,,92.01446155,,,,
,30366894.175,95.0045471,99.7004928588867,0.00272682625020883,5.32352626241322E-7,1,0.999253354069792,40.0298881530762,2.00133539532449,29.2700007557869,0.0310206073572455,0.00568033922337969,0.25,1.87388109478048E-5,0.00274204791732227,2.80112562130859E-5,95.0045471,95.0045471,99.7004928588867,99.7004928588867,56.9799374234099,20.5460288650279,23.288654,0,0,0,40,4370,95.7108,99.7004928588867,,,,,,,,,,,,,0,,,,-0.00245,,,,,,95.0045471,,,,
,30367252.37,98.006546,99.7004928588867,0.002723582293079,3.82342201969655E-7,1,0.999253354069792,40.0298881530762,2.00133584061825,29.2700007557869,0.0309853157369666,0.0056694534975182,0.25,1.88249700074509E-5,0.00273886234474933,2.76003649598819E-5,98.006546,98.006546,99.7004928588867,99.7004928588867,56.628204589756,20.5538311248044,23.288654,0,0,0,40,4370,98.7011,99.7004928588867,,,,,,,,,,,,,0,,,,0.00245,,,,,,98.006546,,,,
,30367612.56,101.0021057,99.7004928588867,0.00271314293598953,4.06244866811395E-7,1,0.999253354069792,40.0298881530762,2.0012864183509,29.2700007557869,0.0308680383924569,0.00563749853659095,0.25,1.83035903646966E-5,0.00272840500408525,2.6597120577615E-5,101.0021057,101.0021057,99.7004928588867,99.7004928588867,57.139389641333,20.5517683120878,23.288654,0,0,0,40,4370,101.70655,99.7004928588867,,,,,,,,,,,,,0,,,,-0.0049,,,,,,101.0021057,,,,
,30367915.39,103.5174484,99.7004928588867,0.00269917889140697,4.54382900640435E-7,1,0.999253354069792,40.0298881530762,2.00096066640615,29.2600002139807,0.0307041467801444,0.00560947066270832,0.25,1.87137089480747E-5,0.00271436845300262,2.6623192299199E-5,103.5174484,103.5174484,99.7004928588867,99.7004928588867,57.2949337166599,20.556690835319,23.288654,0,0,0,40,4370,104.23785,99.7004928588867,,,,,,,,,,,,,0,,,,0,,,,,,103.5174484,,,,
,30368275.43,106.513237,99.7004928588867,0.00267829382748692,4.84279487077425E-7,1,0.999253354069792,40.0298881530762,2.00107298159528,29.2600002139807,0.030468833057531,0.00556153282247231,0.25,1.85202455908589E-5,0.00269334836611762,2.5993762716303E-5,106.513237,106.513237,99.7004928588867,99.7004928588867,57.0659165605253,20.551783036614,23.668306,0,0,0,40,4370,107.2458,99.7004928588867,,,,,,,,,,,,,0,,,,-0.00245,,,,,,106.513237,,,,
,30368634.87,109.514801,99.7004928588867,0.00265335212147099,4.62259477724636E-7,1,0.999253354069792,40.0298881530762,2.00138000957667,29.2600002139807,0.0301906800287816,0.00550100214633029,0.25,1.78558120594516E-5,0.00266822557956311,2.49165052143689E-5,109.514801,109.514801,99.7004928588867,99.7004928588867,56.9791557948906,20.5523528796136,23.668306,0,0,0,40,4370,110.2534,99.7004928588867,,,,,,,,,,,,,0,,,,0,,,,,,109.514801,,,,
,30368937.68,112.0159683,99.7004928588867,0.00262974311774529,4.17652557633249E-7,1,0.999253354069792,40.0298881530762,2.00147029571575,29.2399991303682,0.0299227341784366,0.00545236181925872,0.25,1.79735218762919E-5,0.0026444336272824,2.47098750611951E-5,112.0159683,112.0159683,99.7004928588867,99.7004928588867,57.3512109700445,20.4731010981849,24.047956,0,0,0,40,4370,112.7874,99.7004928588867,,,,,,,,,,,,,0,,,,-0.00245,,,,,,112.0159683,,,,
,30369294.07,115.0061188,99.7004928588867,0.00259978931888386,3.9024771942128E-7,1,0.999253354069792,40.0298881530762,2.00167192714065,29.2399991303682,0.0295850382954858,0.00538388737500269,0.25,1.74593587930643E-5,0.00261423570388678,2.38339811151356E-5,115.0061188,115.0061188,99.7004928588867,99.7004928588867,57.393418910083,20.4653592172357,24.047956,0,0,0,40,4370,115.76295,99.7004928588867,,,,,,,,,,,,,0,,,,0,,,,,,115.0061188,,,,
,30369657.58,118.0146179,99.7004928588867,0.00256656613478523,4.17184447137309E-7,1,0.999253354069792,40.0298881530762,2.00155482632188,29.2399991303682,0.0292062739509327,0.00530327662547751,0.25,1.65036280620034E-5,0.00258073809529123,2.2529170762962E-5,118.0146179,118.0146179,99.7004928588867,99.7004928588867,57.3074397729676,20.4706551022459,24.427608,0,0,0,40,4370,118.8025,99.7004928588867,,,,,,,,,,,,,0,,,,0,,,,,,118.0146179,,,,
,30370017.135,121.0174255,99.7004928588867,0.00253197831493543,4.28600629540123E-7,1,0.999253354069792,40.0298881530762,2.00203820758271,29.2399991303682,0.0288165268055419,0.00524195068726334,0.25,1.73198335411613E-5,0.00254585211976903,2.30323910098694E-5,121.0174255,121.0174255,99.7004928588867,99.7004928588867,57.6662072632946,20.4663413163703,24.807261,0,0,0,40,4370,121.8069,99.7004928588867,,,,,,,,,,,,,0,,,,0.0049,,,,,,121.0174255,,,,
,30370314.84,123.5011673,99.7004928588867,0.00250276469663116,4.28408383651006E-7,1,0.999253354069792,40.0298881530762,2.00154330814297,29.2300004512072,0.0284775501858946,0.00517261682848792,0.25,1.66467996222818E-5,0.00251638466283714,2.21095559119899E-5,123.5011673,123.5011673,99.7004928588867,99.7004928588867,57.4317187075253,20.4763476414256,24.427608,0,0,0,40,4370,124.2954,99.7004928588867,,,,,,,,,,,,,0,,,,0,,,,,,123.5011673,,,,
,30370675.79,126.5064163,99.7004928588867,0.00246529763663768,4.43272251145222E-7,1,0.999253354069792,40.0298881530762,2.00163196777413,29.2300004512072,0.0280520379498758,0.00508934112338786,0.25,1.60880550071986E-5,0.00247859151628367,2.12653974214352E-5,126.5064163,126.5064163,99.7004928588867,99.7004928588867,57.146424298006,20.4741014578061,24.047956,0,0,0,40,4370,127.30915,99.7004928588867,,,,,,,,,,,,,0,,,,0.00245,,,,,,126.5064163,,,,
,30371036.24,129.503418,99.7004928588867,0.00242763773472541,4.41447693220299E-7,1,0.999253354069792,40.0298881530762,2.00171864549876,29.2300004512072,0.0276265871288044,0.00499200376394429,0.25,1.43096632494094E-5,0.00244060123309536,1.92157465673633E-5,129.503418,129.503418,99.7004928588867,99.7004928588867,57.5638139272753,20.4722008393964,24.047956,0,0,0,40,4370,130.30865,99.7004928588867,,,,,,,,,,,,,0,,,,0.00245,,,,,,129.503418,,,,
,30371336.88,132.0122223,99.7004928588867,0.00239110213843923,3.9636073422195E-7,1,0.999253354069792,40.0298881530762,2.00116267440604,29.2099993675947,0.0272006673470857,0.0049247031310102,0.25,1.50561267244053E-5,0.00240375427050812,1.975241655799E-5,132.0122223,132.0122223,99.7004928588867,99.7004928588867,57.3973270526791,20.4760232889808,24.807261,0,0,0,40,4370,132.8023,99.7004928588867,,,,,,,,,,,,,0,,,,0,,,,,,132.0122223,,,,
,30371699.71,135.0168457,99.7004928588867,0.002357206120375,3.80051058345696E-7,1,0.999253354069792,40.0298881530762,2.00164919584682,29.2099993675947,0.0268212684424136,0.00484667921406273,0.25,1.42052178713803E-5,0.00236953867468492,1.86727596031074E-5,135.0168457,135.0168457,99.7004928588867,99.7004928588867,57.4872143323907,20.4748661725686,25.186911,0,0,0,40,4370,135.8383,99.7004928588867,,,,,,,,,,,,,0,,,,0,,,,,,135.0168457,,,,
,30372059.035,138.0030823,99.7004928588867,0.00232199822367289,4.78092693796105E-7,1,0.999253354069792,40.0298881530762,2.00075360970658,29.2099993675947,0.0264096555231335,0.00476089598213431,0.25,1.31643645720851E-5,0.0023340023185937,1.74166428763478E-5,138.0030823,138.0030823,99.7004928588867,99.7004928588867,57.3347967711407,20.4840272233867,24.427608,0,0,0,40,4370,138.8356,99.7004928588867,,,,,,,,,,,,,0,,,,0,,,,,,138.0030823,,,,
,30372420.76,141.0039825,99.7004928588867,0.0022866274134416,4.40743891841655E-7,1,0.999253354069792,40.0298881530762,2.00096649835403,29.2099993675947,0.0260097770618946,0.0046800318703323,0.25,1.23482329907248E-5,0.00229829914492785,1.6398934235477E-5,141.0039825,141.0039825,99.7004928588867,99.7004928588867,57.5434915857753,20.4759874775998,25.186911,0,0,0,40,4370,141.85045,99.7004928588867,,,,,,,,,,,,,0,,,,-0.0049,,,,,,141.0039825,,,,
,30372721.13,143.5059357,99.7004928588867,0.00225741574970385,3.93145070802307E-7,1,0.999253354069792,40.0298881530762,2.00045402650312,29.2099993675947,0.025670558219297,0.0046143403674039,0.25,1.18957898742043E-5,0.00226881038534076,1.57900074259636E-5,143.5059357,143.5059357,99.7004928588867,99.7004928588867,57.6224360662176,20.4819276442874,25.186911,0,0,0,40,4370,144.3549,99.7004928588867,,,,,,,,,,,,,0,,,,0.00245,,,,,,143.5059357,,,,
,30373081.84,146.5091248,99.7004928588867,0.0022230304039569,3.59020622305772E-7,1,0.999253354069792,40.0298881530762,2.00043515850959,29.2099993675947,0.0252793569447173,0.0045332457625651,0.25,1.0909932562258E-5,0.0022340960082619,1.46258237432131E-5,146.5091248,146.5091248,99.7004928588867,99.7004928588867,57.6716786629292,20.4821787057967,25.566563,0,0,0,40,4370,147.3568,99.7004928588867,,,,,,,,,,,,,0,,,,-0.0049,,,,,,146.5091248,,,,
,30373443.305,149.5054474,99.7004928588867,0.00218843283467866,3.58262533431646E-7,1,0.999253354069792,40.0298881530762,2.00026573789111,29.2099993675947,0.024882918037605,0.00445742529305788,0.25,1.0442467168624E-5,0.00219916796965263,1.39922301905121E-5,149.5054474,149.5054474,99.7004928588867,99.7004928588867,57.7224845166792,20.4877368291469,25.186911,0,0,0,40,4370,150.37215,99.7004928588867,,,,,,,,,,,,,0,,,,0.0049,,,,,,149.5054474,,,,
touchdown = 18.9699996262789 mm,30373764.835,152.19107815,99.7004928588867,0.00216268887897133,3.17127538416262E-7,1,0.999253354069792,40.0298881530762,2.00114771781156,29.1900001466274,0.0246056695418104,0.00436774901323646,0.25,6.99851646903491E-6,0.00217315831878932,1.04017866179657E-5,152.1826782,152.1994781,99.7004928588867,99.7004928588867,58.0038707836023,20.4661807567342,24.807261,0,0,0,40,4370,153.053,99.7004928588867,,,,,,,,,,,,,0,,,,-0.00245,,,,,,152.19107815,,,,
,30374105.275,155.0118866,99.7004928588867,0.0021312815445689,4.34819578229733E-7,1,0.999253354069792,40.0298881530762,2.00141217029976,29.1900001466274,0.0242500046058266,0.00430256193313282,0.25,6.80805530643002E-6,0.00214144582646375,1.00742285231402E-5,155.0118866,155.0118866,99.7004928588867,99.7004928588867,57.5466180998522,20.4749080844164,25.946213,0,0,0,40,4370,155.887,99.7004928588867,,,,,,,,,,,,,0,,,,0,,,,,,155.0118866,,,,
,30374464.185,158.0068817,99.7004928588867,0.0020979669540008,4.89711028744814E-7,1,0.999253354069792,40.0298881530762,2.00145513334577,29.1900001466274,0.0238697549283822,0.00423403872217769,0.25,6.69583483576342E-6,0.00210780830185251,9.82546322830253E-6,158.0068817,158.0068817,99.7004928588867,99.7004928588867,57.7201396311215,20.4779969152363,25.566563,0,0,0,40,4370,158.8688,99.7004928588867,,,,,,,,,,,,,0,,,,-0.00245,,,,,,158.0068817,,,,
,30374825.285,161.0113831,99.7004928588867,0.00206425867922363,4.37182495218802E-7,1,0.999253354069792,40.0298881530762,2.0018904491359,29.1900001466274,0.0234903576701003,0.00416009624197953,0.25,6.10118499212387E-6,0.00207377719728383,9.09807966904103E-6,161.0113831,161.0113831,99.7004928588867,99.7004928588867,57.4762715331215,20.4666413805168,25.946213,0,0,0,40,4370,161.87685,99.7004928588867,,,,,,,,,,,,,0,,,,0,,,,,,161.0113831,,,,
,30375124.045,163.5059357,99.7004928588867,0.00203808042874618,3.65866261418257E-7,1,0.999253354069792,40.0298881530762,2.00160120717946,29.1700009256601,0.0231876080064682,0.00410700884523133,0.25,6.13021463211148E-6,0.00204733988507164,9.02737979946433E-6,163.5059357,163.5059357,99.7004928588867,99.7004928588867,57.7342089444676,20.4781619665829,25.946213,0,0,0,40,4370,164.3629,99.7004928588867,,,,,,,,,,,,,0,,,,0,,,,,,163.5059357,,,,
,30375487.595,166.5166473,99.7004928588867,0.00200480642120087,3.74037718133468E-7,1,0.999253354069792,40.0298881530762,2.00145129216585,29.1700009256601,0.0228045341776127,0.00404501982640875,0.25,6.59960538476738E-6,0.00201374711394417,9.38108705651222E-6,166.5166473,166.5166473,99.7004928588867,99.7004928588867,57.3043132588907,20.4871234457639,25.566563,0,0,0,40,4370,167.3895,99.7004928588867,,,,,,,,,,,,,0,,,,0,,,,,,166.5166473,,,,
,30375847.125,169.5110168,99.7004928588867,0.00197731754284982,4.53956163035793E-7,1,0.999253354069792,40.0298881530762,2.00228765087691,29.1700009256601,0.0225000298006713,0.00398448224867275,0.25,6.01763854080088E-6,0.0019859696822631,8.69326290288181E-6,169.5110168,169.5110168,99.7004928588867,99.7004928588867,57.5473997283715,20.4887328660448,25.566563,0,0,0,40,4370,170.3764,99.7004928588867,,,,,,,,,,,,,0,,,,0,,,,,,169.5110168,,,,
,30376185.53,172.3330231,99.7004928588867,,,2,,,,29.1800004053116,,,,,,,172.3330231,172.3330231,99.7004928588867,99.7004928588867,,,25.566563,,,,-99999999,4370,173.1892,99.7004928588867,,,,,,,,,,,,,,,,,,,,,,,172.3330231,,,,
,30376505.91,175.0085907,99.7004928588867,0.00194416631947291,4.04071642690719E-7,1,0.999253354069792,40.0298881530762,2.00184881877468,29.1799996048212,0.0221147569546118,0.00391583564305515,0.25,5.98924674168597E-6,0.00195236554037443,8.51026004664681E-6,175.0085907,175.0085907,99.7004928588867,99.7004928588867,57.688092861833,20.4992742022753,25.566563,0,0,0,40,4370,175.85475,99.7004928588867,,,,,,,,,,,,,0,,,,-0.0049,,,,,,175.0085907,,,,
,30376865.16,178.0059814,99.7004928588867,0.00192483711510394,4.07317295346504E-7,1,0.999253354069792,40.0298881530762,2.0023191634925,29.1799996048212,0.0218983248745924,0.00387484041405271,0.25,5.75660698880265E-6,0.00193278542260759,8.19625002777068E-6,178.0059814,178.0059814,99.7004928588867,99.7004928588867,57.4520410490253,20.5091265019056,25.946213,0,0,0,40,4370,178.8501,99.7004928588867,,,,,,,,,,,,,0,,,,-0.0049,,,,,,178.0059814,,,,
,30377225.965,181.000824,99.7004928588867,0.00162569844859654,3.75065880181855E-6,1,0.999253354069792,40.0298881530762,2.00260803406746,29.1799996048212,0.0176837090401673,0.00794560400815154,0.25,0.000415403465163446,0.00163176233613649,0.000419079345640637,181.000824,181.000824,99.7004928588867,99.7004928588867,57.1409528983714,20.4958794889974,25.946213,0,0,0,40,4370,181.84395,99.7004928588867,,,,,,,,,,,,,0,,,,0.00245,,,,,,181.000824,,,,
,30377527.79,183.5215454,99.7004928588867,0.00142262249712675,2.1998292391942E-6,1,0.999253354069792,40.0298881530762,1.99168654257946,29.1600003838539,0.0153103413537994,0.00739247740250787,0.25,0.000405591368605421,0.0014277779055681,0.000408916130196343,183.5215454,183.5215454,99.7004928588867,99.7004928588867,57.5075366738907,20.4917991175493,26.705515,0,0,0,40,4370,184.3615,99.7004928588867,,,,,,,,,,,,,0,,,,0.0049,,,,,,183.5215454,,,,
,30377888.86,186.5113983,99.7004928588867,0.00125394897414201,1.41668107749589E-5,1,0.999253354069792,40.0298881530762,1.99183108265063,29.1600003838539,0.0135112466002374,0.00642167082294426,0.25,0.000349214919098354,0.00125839752046492,0.000352049181148767,186.5113983,186.5113983,99.7004928588867,99.7004928588867,57.2269320354868,20.4962434702625,26.705515,0,0,0,40,4370,187.3711,99.7004928588867,,,,,,,,,,,,,0,,,,0,,,,,,186.5113983,,,,
,30378248.235,189.5017548,99.7004928588867,0.00124828292192902,3.85836006230483E-5,1,0.999253354069792,40.0298881530762,1.99192374744541,29.1600003838539,0.0135142054479984,0.00602084778834744,0.25,0.000314854209330481,0.00125264240387045,0.00031748957102611,189.5017548,189.5017548,99.7004928588867,99.7004928588867,57.3097846585253,20.4983989724764,26.705515,0,0,0,40,4370,190.3711,99.7004928588867,,,,,,,,,,,,,0,,,,0,,,,,,189.5017548,,,,
,30378620.02,192.5683441,99.7004928588867,,,2,,,,29.1599993216991,,,,,,,192.5683441,192.5683441,99.7004928588867,99.7004928588867,,,25.946213,,,,-99999999,4370,193.4737,99.7004928588867,,,,,,,,,,,,,,,,,,,,,,,192.5683441,,,,
,30378913.53,195.0193176,99.7004928588867,0.0010695748221322,2.87681240596715E-5,1,0.999253354069792,40.0298881530762,1.98039183798049,29.1399993002415,0.0114104672940422,0.00572301503838205,0.25,0.000322543004458751,0.00107307769756827,0.000324900311934527,195.0193176,195.0193176,99.7004928588867,99.7004928588867,57.2636685758907,20.4976160356074,25.946213,0,0,0,40,4370,195.923,99.7004928588867,,,,,,,,,,,,,0,,,,0,,,,,,195.0193176,,,,
,30379274.835,198.011734,99.7004928588867,0.00105598621364698,2.10475232393236E-5,1,0.999253354069792,40.0298881530762,1.98052338133081,29.1499998420477,0.0111927865364882,0.00606717230221122,0.25,0.000355511606588871,0.00105931045603946,0.000357916411023131,198.011734,198.011734,99.7004928588867,99.7004928588867,57.4840878183138,20.489820427576,26.325863,0,0,0,40,4370,198.944,99.7004928588867,,,,,,,,,,,,,0,,,,0,,,,,,198.011734,,,,
,30379634.42,201.0092163,99.7004928588867,0.00098759699015356,2.43099379479858E-5,1,0.999253354069792,40.0298881530762,1.9803142297722,29.1399993002415,0.0103901729661338,0.00610927277929753,0.25,0.000371255889093547,0.00099057613417129,0.000373585451929589,201.0092163,201.0092163,99.7004928588867,99.7004928588867,57.7209212596407,20.5161273231619,27.085165,0,0,0,40,4370,201.93625,99.7004928588867,,,,,,,,,,,,,0,,,,0,,,,,,201.0092163,,,,
,30379935.25,203.5096893,99.7004928588867,0.000960544623314837,5.89413428878557E-6,1,0.999253354069792,40.0298881530762,1.992853727267,29.1399993002415,0.0101093964431409,0.00630285537602263,0.25,0.000389846895300552,0.000963340044466104,0.000392163681702704,203.5096893,203.5096893,99.7004928588867,99.7004928588867,57.1573670972753,20.5167744210481,27.085165,0,0,0,40,4370,204.4426,99.7004928588867,,,,,,,,,,,,,0,,,,0.00245,,,,,,203.5096893,,,,
,30380297.86,206.5067139,99.7004928588867,0.000879935025581773,1.36299949925681E-5,1,0.999253354069792,40.0298881530762,1.99316333676203,29.1399993002415,0.00918079008018018,0.00623936008651537,0.25,0.000398225204123886,0.000882374139970529,0.000400429049579878,206.5067139,206.5067139,99.7004928588867,99.7004928588867,57.1855057239676,20.4991331003342,27.085165,0,0,0,40,4374,207.4653,99.7004928588867,,,,,,,,,,,,,0,,,,0,,,,,,206.5067139,,,,
,30380658.27,209.5167084,99.7004928588867,0.000854738685407149,2.58720542965674E-5,1,0.999253354069792,40.0298881530762,1.99396328674041,29.1399993002415,0.00887739397075263,0.00631083478594702,0.25,0.000408768206193181,0.000857008164141744,0.000410924023416939,209.5167084,209.5167084,99.7004928588867,99.7004928588867,57.2832092888714,20.4960961348553,27.085165,0,0,0,40,4374,210.4647,99.7004928588867,,,,,,,,,,,,,0,,,,0.00245,,,,,,209.5167084,,,,
,30381019.665,212.5128937,99.7004928588867,0.000846063583411559,2.47700468665463E-5,1,0.999253354069792,40.0298881530762,1.99423087165799,29.1399993002415,0.00874587940431951,0.00648747813737513,0.25,0.000425866682811626,0.000848212043015457,0.000428010196092914,212.5128937,212.5128937,99.7004928588867,99.7004928588867,57.1487691835637,20.5102510375572,27.085165,0,0,0,40,4374,213.47385,99.7004928588867,,,,,,,,,,,,,0,,,,0.0049,,,,,,212.5128937,,,,
,30381318.97,215.0126495,99.7004928588867,0.000820967289084919,2.3517211000994E-5,1,0.999253354069792,40.0298881530762,1.99369734101784,29.1300006210804,0.00835002284486433,0.00706270747064025,0.25,0.000481229188658675,0.000822922430612726,0.000483464307688681,215.0126495,215.0126495,99.7004928588867,99.7004928588867,57.3402681707753,20.5190505055579,27.085165,0,0,0,40,4374,215.97495,99.7004928588867,,,,,,,,,,,,,0,,,,0.00245,,,,,,215.0126495,,,,
,30381679.155,218.0024872,99.7004928588867,0.000827971404034428,3.46289499498344E-5,1,0.999253354069792,40.0298881530762,1.99397653393102,29.1300006210804,0.00845700071329,0.00691947447264641,0.25,0.000467355352898109,0.000829885767588644,0.000469495807979632,218.0024872,218.0024872,99.7004928588867,99.7004928588867,57.3215090863138,20.5133470691766,27.085165,0,0,0,40,4374,218.97285,99.7004928588867,,,,,,,,,,,,,0,,,,0,,,,,,218.0024872,,,,
,30382040.125,221.0000916,99.7004928588867,0.000774197813874063,1.69176842001407E-5,1,0.999253354069792,40.0298881530762,1.99442585258114,29.1300006210804,0.00769078625435432,0.00772659646944744,0.25,0.000547900037104478,0.000775810725113344,0.000550150871554946,221.0000916,221.0000916,99.7004928588867,99.7004928588867,57.1823792098907,20.5044828493279,27.085165,0,0,0,40,4374,221.97815,99.7004928588867,,,,,,,,,,,,,0,,,,0.00245,,,,,,221.0000916,,,,
,30382343.205,223.5145416,99.7004928588867,0.000786341993613262,9.1234879966561E-6,1,0.999253354069792,40.0298881530762,1.9811446434656,29.109999537468,0.00765430208280479,0.00841298197382951,0.25,0.000611228695055129,0.000787868919646227,0.000613603461846142,223.5145416,223.5145416,99.7004928588867,99.7004928588867,57.2628869473714,20.5360988754103,27.085165,0,0,0,40,4374,224.50755,99.7004928588867,,,,,,,,,,,,,0,,,,0,,,,,,223.5145416,,,,
,30382701.18,226.5019836,99.7004928588867,0.000805516465885709,1.07792578382987E-5,1,0.999253354069792,40.0298881530762,1.98229594314669,29.109999537468,0.00782293438251679,0.00874695786810969,0.25,0.000637240636259186,0.000806997687429659,0.000639626082282432,226.5019836,226.5019836,99.7004928588867,99.7004928588867,57.383257739333,20.5276900480354,27.085165,0,0,0,40,4374,227.4861,99.7004928588867,,,,,,,,,,,,,0,,,,0,,,,,,226.5019836,,,,
,30383064.88,229.528717,99.7004928588867,0.000788410266906154,1.20138794619408E-5,1,0.999253354069792,40.0298881530762,1.98256599415223,29.109999537468,0.00764882948321556,0.00860918107065573,0.25,0.000627959412164264,0.000789783615384579,0.000630228383025262,229.528717,229.528717,99.7004928588867,99.7004928588867,57.3785679682176,20.5127464874899,27.085165,0,0,0,40,4374,230.5203,99.7004928588867,,,,,,,,,,,,,0,,,,0,,,,,,229.528717,,,,
,30383423.665,232.5050659,99.7004928588867,0.000787242109040727,1.30175390921062E-5,1,0.999253354069792,40.0298881530762,1.98302031932807,29.109999537468,0.00765156768427085,0.00852204789644561,0.25,0.00062034319172948,0.000788547605590605,0.000622517629121211,232.5050659,232.5050659,99.7004928588867,99.7004928588867,57.2925888311022,20.5101465490468,27.085165,0,0,0,40,4374,233.5104,99.7004928588867,,,,,,,,,,,,,0,,,,0,,,,,,232.5050659,,,,
,30383725.115,235.0127563,99.7004928588867,0.000784698952001271,1.1605651805795E-5,1,0.999253354069792,40.0298881530762,1.98257698601567,29.109999537468,0.00763308332736866,0.00844331794218119,0.25,0.000614024482181354,0.000785943157932752,0.000616119392585166,235.0127563,235.0127563,99.7004928588867,99.7004928588867,57.3754414541407,20.5302625743762,27.085165,0,0,0,40,4374,236.02545,99.7004928588867,,,,,,,,,,,,,0,,,,0.00245,,,,,,235.0127563,,,,
,30384087,238.0109634,99.7004928588867,0.00076831083048131,1.18010267713188E-5,1,0.999253354069792,40.0298881530762,1.98245412689293,29.109999537468,0.00746258070682302,0.00832306860340076,0.25,0.000606313312788608,0.000769452728848606,0.000608302673435628,238.0002441,238.0216827,99.7004928588867,99.7004928588867,57.5481813568907,20.5312630385361,27.464817,0,0,0,40,4374,239.0413,99.7004928588867,,,,,,,,,,,,,0,,,,-0.0049,,,,,,238.0109634,,,,
,30384446.135,241.0006256,99.7004928588867,0.000746973892341693,1.26323714988977E-5,1,0.999253354069792,40.0298881530762,1.98284809576728,29.109999537468,0.00725416144824125,0.00810348836023294,0.25,0.000590449110816138,0.000748013061502078,0.000592314111062156,241.0006256,241.0006256,99.7004928588867,99.7004928588867,57.484869446833,20.5227845822942,27.464817,0,0,0,40,4374,242.03455,99.7004928588867,,,,,,,,,,,,,0,,,,-0.00245,,,,,,241.0006256,,,,
,30384747.735,243.5052795,99.7004928588867,0.000748220989831827,1.54032081101032E-5,1,0.999253354069792,40.0298881530762,1.99419624185034,29.1000008583069,0.00732273341429634,0.00806080811399505,0.25,0.000582616923433472,0.00074921010662409,0.00058440780563044,243.5052795,243.5052795,99.7004928588867,99.7004928588867,57.4325003360445,20.5200819791235,27.085165,0,0,0,40,4374,244.5411,99.7004928588867,,,,,,,,,,,,,0,,,,0,,,,,,243.5052795,,,,
,30385110.91,246.5193024,99.7004928588867,0.00074245777431874,1.49653001050638E-5,1,0.999253354069792,40.0298881530762,1.99495406674479,29.1000008583069,0.00726946821830173,0.00799393512900947,0.25,0.000577532797480948,0.00074336848355841,0.000579238345911736,246.5193024,246.5193024,99.7004928588867,99.7004928588867,57.5833546402561,20.5138861193676,27.464817,0,0,0,40,4374,247.57315,99.7004928588867,,,,,,,,,,,,,0,,,,0.0049,,,,,,246.5193024,,,,
,30385469.5,249.502243,99.7004928588867,0.000738972860808442,1.23900539656516E-5,1,0.999253354069792,40.0298881530762,1.99525102729678,29.1000008583069,0.00725223358360756,0.00786135249171702,0.25,0.000566404632177994,0.000739815528559398,0.000568018042502905,249.502243,249.502243,99.7004928588867,99.7004928588867,57.4684552479292,20.5137016808292,27.464817,0,0,0,40,4374,250.5588,99.7004928588867,,,,,,,,,,,,,0,,,,0,,,,,,249.502243,,,,
,30385832.52,252.5152893,99.7004928588867,0.000728668880164734,1.47781642021546E-5,1,0.999253354069792,40.0298881530762,1.99592363805108,29.1000008583069,0.00715855731376581,0.0077197970748922,0.25,0.000555545443795114,0.000729431322044806,0.000557063372825345,252.5152893,252.5152893,99.7004928588867,99.7004928588867,57.4457880208715,20.5136770995408,27.464817,0,0,0,40,4374,253.5944,99.7004928588867,,,,,,,,,,,,,0,,,,0,,,,,,252.5152893,,,,
,30386133.33,255.0113831,99.7004928588867,0.000727925710936847,1.3718202934395E-5,1,0.999253354069792,40.0298881530762,1.98253690764831,29.1000008583069,0.00710797597459841,0.00764400783138541,0.25,0.000553398655744218,0.000728629650677847,0.000554856552136944,255.0113831,255.0113831,99.7004928588867,99.7004928588867,57.5833546402561,20.5375814372334,27.464817,0,0,0,40,4374,256.103,99.7004928588867,,,,,,,,,,,,,0,,,,0,,,,,,255.0113831,,,,
,30386494.725,258.0165253,99.7004928588867,0.000716686262737374,1.49703203301097E-5,1,0.999253354069792,40.0298881530762,1.98267527256228,29.1000008583069,0.00698920701491182,0.00757649745611911,0.25,0.000549379003551194,0.000717305461540421,0.000550754933568462,258.0067444,258.0263062,99.7004928588867,99.7004928588867,57.4942489890638,20.5364513486168,28.224119,0,0,0,40,4374,259.1121,99.7004928588867,,,,,,,,,,,,,0,,,,0.00245,,,,,,258.0165253,,,,
,30386854.455,261.0058899,99.7004928588867,0.00070477008308629,1.15998822282342E-5,1,0.999253354069792,40.0298881530762,1.98338968763914,29.1000008583069,0.00686415773327927,0.00751311987056384,0.25,0.000545657691857833,0.00070530575608763,0.00054695304368263,261.0058899,261.0058899,99.7004928588867,99.7004928588867,57.4668919908907,20.5267512525295,27.464817,0,0,0,40,4374,262.113,99.7004928588867,,,,,,,,,,,,,0,,,,-0.00245,,,,,,261.0058899,,,,
touchdown = 18.8800003379583 mm,30387170.89,263.6300049,99.7004928588867,0.000701339374521614,1.48214092058181E-5,1,0.999253354069792,40.0298881530762,1.98157611360971,29.1000008583069,0.0068464317589417,0.00734107757431554,0.25,0.000531596619797036,0.000701820800891537,0.000532813848391094,263.6300049,263.6300049,99.7004928588867,99.7004928588867,57.0627900464484,20.5393059930875,28.224119,0,0,0,40,4374,264.7565,99.7004928588867,,,,,,,,,,,,,0,,,,-0.0049,,,,,,263.6300049,,,,
,30387516.6,266.50030515,99.7004928588867,0.00071181940170778,1.07652084804116E-5,1,0.999253354069792,40.0298881530762,1.98247799068744,29.1000008583069,0.00701624068733519,0.00707755442126537,0.25,0.00050612898241775,0.000712265993563886,0.000507263002292283,266.4897766,266.5108337,99.7004928588867,99.7004928588867,57.4254656793715,20.5328295186986,27.844467,0,0,0,40,4374,267.6341,99.7004928588867,,,,,,,,,,,,,0,,,,-0.00245,,,,,,266.50030515,,,,
,30387880.045,269.5213928,99.7004928588867,0.00070754160029324,1.09387525061269E-5,1,0.999253354069792,40.0298881530762,1.98299057330742,29.1000008583069,0.00696459057493172,0.00709665602591161,0.25,0.000508488053926844,0.000707910260013039,0.000509559461692196,269.5213928,269.5213928,99.7004928588867,99.7004928588867,57.3613721407945,20.5287408757352,27.464817,0,0,0,40,4374,270.65865,99.7004928588867,,,,,,,,,,,,,0,,,,0,,,,,,269.5213928,,,,
,30388241.52,272.513092,99.7004928588867,0.000686046614174842,1.4799184119308E-5,1,0.999253354069792,40.0298881530762,1.98284665916558,29.1000008583069,0.00672739410551079,0.00702107428193451,0.25,0.000505608292660902,0.000686326280229652,0.000506599573799012,272.513092,272.513092,99.7004928588867,99.7004928588867,57.5599057846792,20.5297371291519,27.464817,0,0,0,40,4374,273.6721,99.7004928588867,,,,,,,,,,,,,0,,,,0,,,,,,272.513092,,,,
,30388539.75,275.0027466,99.7004928588867,0.000690776064484913,1.12717946492799E-5,1,0.999253354069792,40.0298881530762,1.98263349446679,29.109999537468,0.00682084115302841,0.0067893392133838,0.25,0.000484296183287764,0.000691018389603668,0.000485221942614859,275.0027466,275.0027466,99.7004928588867,99.7004928588867,57.4254656793715,20.5315584126202,28.224119,0,0,0,40,4374,276.15385,99.7004928588867,,,,,,,,,,,,,0,,,,0,,,,,,275.0027466,,,,
,30388901,278.0085144,99.7004928588867,0.000679969445452268,1.06948475338505E-5,1,0.999253354069792,40.0298881530762,1.98233343172349,29.109999537468,0.00669382462061766,0.00678915445899849,0.25,0.000486310790862676,0.000680132363783035,0.000487171578650325,278.0085144,278.0085144,99.7004928588867,99.7004928588867,57.6685521488523,20.5342380567426,28.224119,0,0,0,40,4374,279.1488,99.7004928588867,,,,,,,,,,,,,0,,,,0.00245,,,,,,278.0085144,,,,
,30389261.94,281.0039368,99.7004928588867,0.000674020053153711,1.04198495202226E-5,1,0.999253354069792,40.0298881530762,1.98256203754792,29.109999537468,0.00665859381912236,0.00659553143624014,0.25,0.000470115269402071,0.000674122264766493,0.00047090274113457,281.0039368,281.0039368,99.7004928588867,99.7004928588867,57.6865296047946,20.5310736632735,28.224119,0,0,0,40,4374,282.17345,99.7004928588867,,,,,,,,,,,,,0,,,,0.00245,,,,,,281.0039368,,,,
,30389592.7,283.7275391,99.7004928588867,,,2,,,,29.1400001007319,,,,,,,283.7275391,283.7275391,99.7004928588867,99.7004928588867,,,28.603769,,,,-99999999,4374,284.9273,99.7004928588867,,,,,,,,,,,,,,,,,,,,,,,283.7275391,,,,
,30389924.795,286.5079651,99.7004928588867,0.000669663785379007,1.06910594969384E-5,1,0.999253354069792,40.0298881530762,1.98251640888226,29.1300006210804,0.00665436643545028,0.00631967518965606,0.25,0.000446454934000534,0.000669655386023699,0.00044712482098703,286.5079651,286.5079651,99.7004928588867,99.7004928588867,57.5724118409869,20.5278665908625,28.603769,0,0,0,40,4374,287.69635,99.7004928588867,,,,,,,,,,,,,0,,,,0,,,,,,286.5079651,,,,
,30390285.02,289.5012512,99.7004928588867,0.000657545369833234,9.93729736444091E-6,1,0.999253354069792,40.0298881530762,1.98261844184545,29.1300006210804,0.00653100705682673,0.00621998379879549,0.25,0.000439718726892011,0.000657469494968547,0.000440324263349412,289.5012512,289.5012512,99.7004928588867,99.7004928588867,57.7662557137561,20.5267128419413,27.844467,0,0,0,40,4374,290.6945,99.7004928588867,,,,,,,,,,,,,0,,,,-0.00245,,,,,,289.5012512,,,,
,30390648.36,292.5159302,99.7004928588867,0.00065573319248558,1.17495837896684E-5,1,0.999253354069792,40.0298881530762,1.98227871155045,29.1300006210804,0.00651429372809355,0.006183776981351,0.25,0.000436964307435643,0.000655591571407562,0.000437514866605763,292.5159302,292.5159302,99.7004928588867,99.7004928588867,57.6537012069869,20.5289637629267,28.224119,0,0,0,40,4374,293.7342,99.7004928588867,,,,,,,,,,,,,0,,,,-0.0049,,,,,,292.5159302,,,,
,30390950.83,295.017395,99.7004928588867,0.000645379514798284,8.83245873620655E-6,1,0.999253354069792,40.0298881530762,1.98192723194517,29.1600003838539,0.00642034794496585,0.00602375314263699,0.25,0.000424653061903367,0.00064518903344834,0.000425151136251203,295.017395,295.017395,99.7004928588867,99.7004928588867,57.4973755031407,20.5367928522877,28.603769,0,0,0,40,4374,296.2669,99.7004928588867,,,,,,,,,,,,,0,,,,0,,,,,,295.017395,,,,
,30391310.21,298.0100708,99.7004928588867,0.000634520215352382,1.21064942147226E-5,1,0.999253354069792,40.0298881530762,1.98202176228169,29.1600003838539,0.00629409061508527,0.00602521791529485,0.25,0.000426702535375174,0.000634262308855466,0.000427142840593169,298.0100708,298.0100708,99.7004928588867,99.7004928588867,57.5044101598138,20.5348436592527,28.603769,0,0,0,40,4374,299.2539,99.7004928588867,,,,,,,,,,,,,0,,,,0,,,,,,298.0100708,,,,
,30391617.785,299.7753906,99.7004928588867,0.000640909404394423,1.04189486539694E-5,1,0.999253354069792,40.0298881530762,1.98169497610244,29.1600003838539,0.00636677661280222,0.00602278911776703,0.25,0.00042549904624747,0.000640613114982867,0.00042591503707909,299.7753906,299.7753906,99.7004928588867,99.7004928588867,57.6411951506792,20.5354125858578,28.983419,0,0,0,40,4369,300.19695,99.7004928588867,,,,,,,,,,,,,0,,,,-0.00245,,,,,,299.7753906,,,,