File: data/looselyPackedNP/ios-11/vsm/rawdata/PMK18_FCC_100OE.DAT
[Header]
; VSM Data File (default extension .dat)
; Copyright (c) 2003-2013, Quantum Design, Inc. All rights reserved.
TITLE,
FILEOPENTIME,30298760.30,12/18/2018,12:20 am
BYAPP,VSM,2.0,2.0
INFO,PPMS VSM Option Release 1.4.10 Build 1,APPNAME
INFO,Quantum Design Linear Motor Servo Controller,MOTOR_MODULE_NAME
INFO,3101-100 M1,MOTOR_HW_VERSION
INFO,MMC1014,MOTOR_SERIAL_NUMBER
INFO,SRV No X-over 01.03.11,MOTOR_SOFTWARE_VERSION
INFO,Quantum Design VSM Detection Module,VSM_MODULE_NAME
INFO,3101-150 F0,VSM_HW_VERSION
INFO,VSM707,VSM_SERIAL_NUMBER
INFO,VSM No X-over 01.02.05 May 20 2008 13:51:47,VSM_SOFTWARE_VERSION
INFO,704,PREAMP_SERIAL_NUMBER
INFO,822,COIL_SERIAL_NUMBER
INFO,0,MOMENT_UNITS
INFO,Maghemite,SAMPLE_MATERIAL
INFO,Oleate Iron Spheres,SAMPLE_COMMENT
INFO,,SAMPLE_MASS
INFO,,SAMPLE_VOLUME
INFO,,SAMPLE_MOLECULAR_WEIGHT
INFO,,SAMPLE_SIZE
INFO,,SAMPLE_SHAPE
DATATYPE,COMMENT,1
DATATYPE,TIME,2
STARTUPAXIS,X,2
STARTUPAXIS,Y1,5
[Data]
Comment,Time Stamp (sec),Temperature (K),Magnetic Field (Oe),Moment (emu),M. Std. Err. (emu),Transport Action,Averaging Time (sec),Frequency (Hz),Peak Amplitude (mm),Center Position (mm),Coil Signal' (mV),Coil Signal" (mV),Range (mV),M. Quad. Signal (emu),M. Raw' (emu),M. Raw" (emu),Min. Temperature (K),Max. Temperature (K),Min. Field (Oe),Max. Field (Oe),Mass (grams),Motor Lag (deg),Pressure (Torr),VSM Status (code),Motor Status (code),Measure Status (code),Measure Count,PPMS Status (code),System Temp. (K),System Field (Oe),Sample Position (deg),Bridge 1 Resistance (ohms),Bridge 1 Excitation (에),Bridge 2 Resistance (ohms),Bridge 2 Excitation (에),Bridge 3 Resistance (ohms),Bridge 3 Excitation (에),Bridge 4 Resistance (ohms),Bridge 4 Excitation (에),Signal 1 Vin (V),Signal 2 Vin (V),Digital Inputs (code),Drive 1 Iout (mA),Drive 1 Ipower (W),Drive 2 Iout (mA),Drive 2 Ipower (W),Pressure (),Map 20 (),Map 21 (),Map 22 (),Map 23 (),Map 24 (),Map 25 (),Map 26 (),Map 27 (),Map 28 (),Map 29 ()
,30298895.145,299.8014832,99.5634765625,0.000655611719311995,9.94676633960633E-6,1,0.999253354069792,40.0298881530762,1.9930886512081,29.2399991303682,0.00657736213185746,0.0060286443756648,0.25,0.000420541298296389,0.000655317746770231,0.000420966806971671,299.8014832,299.8014832,99.5634765625,99.5634765625,57.7607843141215,20.545137505348,26.705515,0,0,0,40,4369,300.1666,99.5634765625,,,,,,,,,,,,,0,,,,0.0049,,,,,,299.8014832,,,,
,30299038.055,297.99858095,99.5634765625,0.000658715306622344,1.31577411522598E-5,1,0.999253354069792,40.0298881530762,1.99286114126825,29.2399991303682,0.00658193338223144,0.00620809473771552,0.25,0.000435919618898768,0.000658446845270651,0.000436383701686343,297.9548035,298.0423584,99.5634765625,99.5634765625,57.6841847192369,20.5444430928876,26.705515,0,0,0,40,4374,294.9841,99.5634765625,,,,,,,,,,,,,0,,,,0.00245,,,,,,297.99858095,,,,
,30299130.785,295.4490967,99.5634765625,0.000655646458152046,1.18109977990069E-5,1,0.999253354069792,40.0298881530762,1.99301864810772,29.2399991303682,0.00655235564688587,0.00618007658322788,0.25,0.000433874458125899,0.000655436690724456,0.000434379560134206,295.4490967,295.4490967,99.5634765625,99.5634765625,57.5896076684099,20.544689487114,26.705515,0,0,0,40,4374,293.0141,99.5634765625,,,,,,,,,,,,,0,,,,-0.0049,,,,,,295.4490967,,,,
,30299234.105,292.9629517,99.5634765625,0.000661043106048761,1.41617297805517E-5,1,0.999253354069792,40.0298881530762,1.99340399925886,29.2399991303682,0.00660953714298994,0.00622411835486012,0.25,0.000436686024537709,0.000660887763069838,0.00043723873134948,292.9629517,292.9629517,99.5634765625,99.5634765625,57.7498415148523,20.5419747095482,26.705515,0,0,0,40,4374,290.48395,99.5634765625,,,,,,,,,,,,,0,,,,-0.0049,,,,,,292.9629517,,,,
,30299335.915,290.4835205,99.5634765625,0.000655254313684145,1.08951852660335E-5,1,0.999253354069792,40.0298881530762,1.99348058383358,29.2399991303682,0.00650979435387804,0.00641646988828894,0.25,0.000454649040593956,0.000655139865567015,0.000455247109845853,290.4835205,290.4835205,99.5634765625,99.5634765625,57.6154014095446,20.5383673290218,26.705515,0,0,0,40,4374,287.7987,99.5634765625,,,,,,,,,,,,,0,,,,0,,,,,,290.4835205,,,,
,30299442.03,287.9382324,99.5634765625,0.00066134964884184,1.14298732586497E-5,1,0.999253354069792,40.0298881530762,1.99322506113761,29.2399991303682,0.00658771065826516,0.00637434520159746,0.25,0.000449875470893982,0.000661297010566073,0.000450522625028786,287.9382324,287.9382324,99.5634765625,99.5634765625,57.5317671579869,20.5388924635352,26.325863,0,0,0,40,4374,285.0604,99.5634765625,,,,,,,,,,,,,0,,,,0.00245,,,,,,287.9382324,,,,
,30299543.43,285.4625549,99.5634765625,0.000656402285204248,1.13334215461078E-5,1,0.999253354069792,40.0298881530762,1.99325825698962,29.2399991303682,0.00651917251799539,0.00644214667416947,0.25,0.000456673063927798,0.000656397479500309,0.000457365032873845,285.4625549,285.4625549,99.5634765625,99.5634765625,57.6826214621984,20.5431383546761,26.705515,0,0,0,40,4374,282.4749,99.5634765625,,,,,,,,,,,,,0,,,,-0.00245,,,,,,285.4625549,,,,
,30299644.57,282.9381714,99.5634765625,0.000671692394317848,1.18524254763976E-5,1,0.999253354069792,40.0298881530762,1.99351496426064,29.2399991303682,0.00669756059777543,0.00644850079859453,0.25,0.00045445934466863,0.000671753789583862,0.000455207518714347,282.9381714,282.9381714,99.5634765625,99.5634765625,57.6318156084484,20.5417858165043,26.705515,0,0,0,40,4374,279.9132,99.5634765625,,,,,,,,,,,,,0,,,,-0.00245,,,,,,282.9381714,,,,
touchdown = 18.9500004053116 mm,30299748.56,280.3822632,99.5634765625,0.000688009609649986,1.10928153074039E-5,1,0.999253354069792,40.0298881530762,1.98134356000106,29.1700009256601,0.00679988610698657,0.00668809413555566,0.25,0.000476255830541072,0.000688123747516968,0.000477077697778272,280.3822632,280.3822632,99.5634765625,99.5634765625,57.4027984523138,20.5260887627717,26.705515,0,0,0,40,4374,277.2735,99.5634765625,,,,,,,,,,,,,0,,,,0,,,,,,280.3822632,,,,
,30299848.22,277.9547424,99.5634765625,0.000687635541404927,1.09582284034808E-5,1,0.999253354069792,40.0298881530762,1.98107560495723,29.1700009256601,0.0067962593067642,0.00668185497444518,0.25,0.000475785537282947,0.000687805708615179,0.000476653673471472,277.9547424,277.9547424,99.5634765625,99.5634765625,57.5552160135638,20.5320459837632,26.705515,0,0,0,40,4374,274.7704,99.5634765625,,,,,,,,,,,,,0,,,,0,,,,,,277.9547424,,,,
,30299947.565,275.4672546,99.5634765625,0.000685717864226417,1.08741762596254E-5,1,0.999253354069792,40.0298881530762,1.98071564033349,29.1700009256601,0.0067369477567836,0.0068919085134988,0.25,0.000494868968506452,0.000685929466267314,0.000495799854699339,275.4672546,275.4672546,99.5634765625,99.5634765625,57.3152560581599,20.5306322573859,27.085165,0,0,0,40,4374,272.2525,99.5634765625,,,,,,,,,,,,,0,,,,0,,,,,,275.4672546,,,,
,30300047.37,272.9673767,99.5634765625,0.000685441443516041,1.29381695350762E-5,1,0.999253354069792,40.0298881530762,1.98035016835095,29.1700009256601,0.00672326655840815,0.00694813568791225,0.25,0.000499972860983606,0.000685706134199034,0.00050095828677726,272.9673767,272.9673767,99.5634765625,99.5634765625,57.2652318329291,20.5337487645501,26.705515,0,0,0,40,4374,269.7545,99.5634765625,,,,,,,,,,,,,0,,,,0,,,,,,272.9673767,,,,
,30300153.27,270.3968811,99.5634765625,,,2,,,,29.1200008797646,,,,,,,270.3968811,270.3968811,99.5634765625,99.5634765625,,,27.085165,,,,-99999999,4374,267.108,99.5634765625,,,,,,,,,,,,,,,,,,,,,,,270.3968811,,,,
,30300247.715,267.9923706,99.5634765625,0.000702766067346606,1.08580562139484E-5,1,0.999253354069792,40.0298881530762,1.99290544836871,29.109999537468,0.00691855818292973,0.00726911023966638,0.25,0.000521534801157327,0.000703146648897177,0.000522658291316821,267.9923706,267.9923706,99.5634765625,99.5634765625,56.8462789466214,20.5330336226512,26.325863,0,0,0,40,4374,264.74755,99.5634765625,,,,,,,,,,,,,0,,,,0,,,,,,267.9923706,,,,
,30300350.565,265.4361572,99.5634765625,0.000703576781117847,1.3583059783763E-5,1,0.999253354069792,40.0298881530762,1.9926824061441,29.109999537468,0.00693358798351359,0.00723578062905337,0.25,0.000518448857767888,0.000704020070433228,0.000519623231892176,265.4361572,265.4361572,99.5634765625,99.5634765625,57.4637654768138,20.5432321101973,26.705515,0,0,0,40,4374,262.17375,99.5634765625,,,,,,,,,,,,,0,,,,0,,,,,,265.4361572,,,,
,30300451.92,262.9407349,99.5634765625,0.000695677365410792,1.53168338378221E-5,1,0.999253354069792,40.0298881530762,1.99257338498464,29.109999537468,0.00683097877193533,0.00729874850907152,0.25,0.000525362605402129,0.000696162761684223,0.000526592221087012,262.9407349,262.9407349,99.5634765625,99.5634765625,57.2519441481022,20.5404735853256,27.085165,0,0,0,40,4374,259.64435,99.5634765625,,,,,,,,,,,,,0,,,,0,,,,,,262.9407349,,,,
,30300550.455,260.4682007,99.5634765625,0.000716227858716893,1.56742025953867E-5,1,0.999253354069792,40.0298881530762,1.99222162681553,29.109999537468,0.00705164592956291,0.00740127414531548,0.25,0.00053092073235862,0.000716793593274218,0.00053222704832854,260.4682007,260.4682007,99.5634765625,99.5634765625,57.5012836457369,20.5478577637906,26.325863,0,0,0,40,4374,257.1649,99.5634765625,,,,,,,,,,,,,0,,,,-0.0049,,,,,,260.4682007,,,,
,30300651.125,257.9481812,99.5634765625,0.000714382098934617,1.39779079996338E-5,1,0.999253354069792,40.0298881530762,1.97931291725316,29.0600005537271,0.00696935783708874,0.00745911047852441,0.25,0.000540406975676879,0.000714996475905364,0.000541780122877108,257.9481812,257.9481812,99.5634765625,99.5634765625,56.8150138058522,20.5508771175996,27.085165,0,0,0,40,4374,254.6368,99.5634765625,,,,,,,,,,,,,0,,,,0,,,,,,257.9481812,,,,
,30300754,255.4415436,99.5634765625,0.000722631618269068,9.94334245120729E-6,1,0.999253354069792,40.0298881530762,1.97878805133648,29.0600005537271,0.00703605067969462,0.00761645429445415,0.25,0.000553094586348184,0.000723306573333742,0.000554549399054133,255.4415436,255.4415436,99.5634765625,99.5634765625,57.1268835850253,20.5527777378707,26.705515,0,0,0,40,4374,252.0631,99.5634765625,,,,,,,,,,,,,0,,,,0.0049,,,,,,255.4415436,,,,
,30300852.17,252.9968567,99.5634765625,0.000733159085427612,1.47175839931132E-5,1,0.999253354069792,40.0298881530762,1.97827288403602,29.0600005537271,0.0071703568514583,0.00753572983214141,0.25,0.000544181539233621,0.000733915880470926,0.000545685259325071,252.9968567,252.9968567,99.5634765625,99.5634765625,57.261323690333,20.5555069630269,27.085165,0,0,0,40,4374,249.5994,99.5634765625,,,,,,,,,,,,,0,,,,0,,,,,,252.9968567,,,,
,30300952.78,250.4565582,99.5634765625,0.000713291803534095,1.5775107585747E-5,1,0.999253354069792,40.0298881530762,1.9784591842093,29.0600005537271,0.00690415000121882,0.00775427973238695,0.25,0.000566966726509814,0.000714055186038413,0.000568549643904211,250.4565582,250.4565582,99.5634765625,99.5634765625,56.9502355396791,20.5509177176879,26.705515,0,0,0,40,4374,247.0734,99.5634765625,,,,,,,,,,,,,0,,,,0,,,,,,250.4565582,,,,
,30301032.03,248.4823151,99.5634765625,0.00074927465483352,1.44074923551611E-5,1,0.999253354069792,40.0298881530762,2.00204505537515,29.0300007909536,0.00737746266760809,0.00799635399955427,0.25,0.00057421944999214,0.000750141958711295,0.000575891097250763,248.4823151,248.4823151,99.5634765625,99.5634765625,57.2316218066022,20.5533511539898,26.325863,0,0,0,40,4374,245.12555,99.5634765625,,,,,,,,,,,,,0,,,,0.0049,,,,,,248.4823151,,,,
,30301133.165,245.9679947,99.5634765625,0.000756171507533158,1.32539042150074E-5,1,0.999253354069792,40.0298881530762,2.00189087923041,29.0200002491474,0.00745287295235852,0.00802703130025134,0.25,0.000575707261346903,0.000757110538136175,0.000577446515042451,245.9435425,245.9924469,99.5634765625,99.5634765625,56.8345545188329,20.5560623907325,26.705515,0,0,0,40,4374,242.5392,99.5634765625,,,,,,,,,,,,,0,,,,-0.00245,,,,,,245.9679947,,,,
,30301233.225,243.4754181,99.5634765625,0.000769121241143015,1.23008247173377E-5,1,0.999253354069792,40.0298881530762,2.00175705495062,29.0300007909536,0.00760292850879287,0.00803603236232748,0.25,0.000574229951227992,0.000770147070215876,0.000576035960002047,243.4754181,243.4754181,99.5634765625,99.5634765625,56.976810909333,20.5555072873976,27.085165,0,0,0,40,4374,240.038,99.5634765625,,,,,,,,,,,,,0,,,,0,,,,,,243.4754181,,,,
,30301333.675,240.9629517,99.5634765625,0.000760682459287061,1.27097800646763E-5,1,0.999253354069792,40.0298881530762,2.00159350557081,29.0200002491474,0.00749422656794423,0.00809367206364154,0.25,0.000580755370764159,0.000761746201446844,0.000582626442217533,240.9629517,240.9629517,99.5634765625,99.5634765625,57.1651833824676,20.5545878514058,26.705515,0,0,0,40,4374,237.5133,99.5634765625,,,,,,,,,,,,,0,,,,0,,,,,,240.9629517,,,,
touchdown = 18.7800005078316 mm,30301426.53,238.624054,99.5634765625,0.000766748118244134,1.26989733469344E-5,1,0.999253354069792,40.0298881530762,1.99099678365943,28.999999165535,0.00751643371177219,0.0081171565071361,0.25,0.000585336308590705,0.000767876623463944,0.000587278037131705,238.624054,238.624054,99.5634765625,99.5634765625,57.0737328457176,20.5585277809364,27.085165,0,0,0,40,4374,235.15915,99.5634765625,,,,,,,,,,,,,0,,,,-0.00245,,,,,,238.624054,,,,
,30301513.705,236.4987488,99.5634765625,0.000765015735887942,1.20150592023498E-5,1,0.999253354069792,40.0298881530762,1.9906108796255,28.999999165535,0.00748213534838009,0.00819251320170097,0.25,0.000592380132024453,0.000766184805390666,0.000594386795800623,236.4987488,236.4987488,99.5634765625,99.5634765625,57.0018230219483,20.5628457765849,26.705515,0,0,0,40,4374,233.00605,99.5634765625,,,,,,,,,,,,,0,,,,0.00245,,,,,,236.4987488,,,,
,30301615.115,233.9498596,99.5634765625,0.000787205080193868,1.48946204503591E-5,1,0.999253354069792,40.0298881530762,1.9906917895829,28.999999165535,0.00771435751595855,0.00834873417745632,0.25,0.000602255344407701,0.000788476836791422,0.000604366564224785,233.9498596,233.9498596,99.5634765625,99.5634765625,56.9134989992753,20.5643742983636,26.325863,0,0,0,40,4374,230.4614,99.5634765625,,,,,,,,,,,,,0,,,,0.00245,,,,,,233.9498596,,,,
,30301713.24,231.475647,99.5634765625,0.00079402681880951,1.48238765761227E-5,1,0.999253354069792,40.0298881530762,1.99030618934943,28.999999165535,0.00776918334852295,0.00848458296209538,0.25,0.000613160884744268,0.000795364867860444,0.000615365318615994,231.475647,231.475647,99.5634765625,99.5634765625,57.2691399755253,20.5670947036912,26.325863,0,0,0,40,4374,228.01075,99.5634765625,,,,,,,,,,,,,0,,,,-0.0049,,,,,,231.475647,,,,
,30301827.13,228.7239227,99.5634765625,,,2,,,,28.9800007450581,,,,,,,228.7239227,228.7239227,99.5634765625,99.5634765625,,,25.946213,,,,-99999999,4374,225.1494,99.5634765625,,,,,,,,,,,,,,,,,,,,,,,228.7239227,,,,
,30301912.875,226.4960938,99.5634765625,0.000827129524686832,1.14665403452429E-5,1,0.999253354069792,40.0298881530762,2.00185689824014,28.9799999445677,0.00815301793732177,0.00880857067026255,0.25,0.000631647784022991,0.000828655069444739,0.000634055830753432,226.4960938,226.4960938,99.5634765625,99.5634765625,57.0354330482753,20.5564908783642,26.325863,0,0,0,40,4374,223.0049,99.5634765625,,,,,,,,,,,,,0,,,,0.00245,,,,,,226.4960938,,,,
,30302014.275,223.9826355,99.5634765625,0.000829274247291831,9.39738800583923E-6,1,0.999253354069792,40.0298881530762,2.0008820523512,28.9799999445677,0.00816809523190966,0.00884456645186743,0.25,0.000634729246411159,0.000830864875700695,0.000637212591319909,223.9826355,223.9826355,99.5634765625,99.5634765625,56.9009929429675,20.5657546070378,26.325863,0,0,0,40,4374,220.4728,99.5634765625,,,,,,,,,,,,,0,,,,0,,,,,,223.9826355,,,,
,30302115.84,221.4490051,99.5634765625,0.00081371493206181,8.61127149292599E-6,1,0.999253354069792,40.0298881530762,2.00133239053378,28.9799999445677,0.00803495934917265,0.00857862021556093,0.25,0.000613779851220169,0.000815345824003924,0.000616256475423242,221.4490051,221.4490051,99.5634765625,99.5634765625,57.3777863396984,20.5663759488423,26.325863,0,0,0,40,4374,217.9305,99.5634765625,,,,,,,,,,,,,0,,,,-0.00245,,,,,,221.4490051,,,,
,30302214.185,218.9705505,99.5634765625,0.000803778178123633,6.38353446418594E-6,1,0.999253354069792,40.0298881530762,2.00150388801567,28.9799999445677,0.00793231819175913,0.00850830047562568,0.25,0.000609182549614616,0.000805445132652742,0.000611698805550696,218.9705505,218.9705505,99.5634765625,99.5634765625,57.1722180391407,20.5605848711038,26.705515,0,0,0,40,4374,215.4653,99.5634765625,,,,,,,,,,,,,0,,,,0.0049,,,,,,218.9705505,,,,
,30302314.555,216.4906464,99.5634765625,0.000834690675400963,2.976033866805E-5,1,0.999253354069792,40.0298881530762,1.9910075536567,28.9600007236004,0.00861982376808771,0.00635493178921702,0.25,0.000417080281695295,0.000836698502402802,0.000419131309650834,216.4906464,216.4906464,99.5634765625,99.5634765625,57.0424677049483,20.5546158373083,26.325863,0,0,0,40,4374,212.9479,99.5634765625,,,,,,,,,,,,,0,,,,0,,,,,,216.4906464,,,,
,30302414.97,213.9592896,99.5634765625,0.000836592743100839,3.22710144246447E-5,1,0.999253354069792,40.0298881530762,1.99061371808531,28.9600007236004,0.00857448784035596,0.00673737940968353,0.25,0.000450622590548602,0.000838636429301785,0.000452823417578465,213.9592896,213.9592896,99.5634765625,99.5634765625,57.3129111726022,20.5641967200751,26.705515,0,0,0,40,4374,210.4548,99.5634765625,,,,,,,,,,,,,0,,,,0,,,,,,213.9592896,,,,
,30302515.97,211.4529724,99.5634765625,0.000836583839251714,3.32589974198325E-5,1,0.999253354069792,40.0298881530762,1.99004772142586,28.9500001817942,0.00857508575064349,0.00672228922395821,0.25,0.000449390121636697,0.000838691332523369,0.000451637474761727,211.4529724,211.4529724,99.5634765625,99.5634765625,57.1565854687561,20.5681108469923,26.705515,0,0,0,40,4374,207.923,99.5634765625,,,,,,,,,,,,,0,,,,0,,,,,,211.4529724,,,,
,30302614.58,208.9718475,99.5634765625,0.000881508581577982,3.12887885327419E-5,1,0.999253354069792,40.0298881530762,1.98986913702557,28.9600007236004,0.0091303738709471,0.00653661053836451,0.25,0.000425154289935505,0.000883844787120683,0.000427422022424401,208.9718475,208.9718475,99.5634765625,99.5634765625,57.2480360055061,20.5791622343494,25.946213,0,0,0,40,4374,205.455,99.5634765625,,,,,,,,,,,,,0,,,,0,,,,,,208.9718475,,,,
,30302714.24,206.4812469,99.5634765625,0.000869166088952849,1.73802676808144E-5,1,0.999253354069792,40.0298881530762,2.00127282134203,28.9399996399879,0.00907775991871757,0.00633502004290415,0.25,0.000406358338678046,0.000871547408851063,0.000408600924728943,206.4812469,206.4812469,99.5634765625,99.5634765625,56.8306463762368,20.5652989332795,25.946213,0,0,0,40,4374,202.9675,99.5634765625,,,,,,,,,,,,,0,,,,-0.0049,,,,,,206.4812469,,,,
,30302814.53,203.9558716,99.5634765625,0.000930107007922166,1.92462996281469E-5,1,0.999253354069792,40.0298881530762,2.00212428189213,28.9399996399879,0.00978419599477004,0.00640653434675853,0.25,0.000401776796956843,0.000932760224256105,0.000404118137346368,203.9558716,203.9558716,99.5634765625,99.5634765625,57.1081245005637,20.5477465322048,26.325863,0,0,0,40,4374,200.4597,99.5634765625,,,,,,,,,,,,,0,,,,-0.0049,,,,,,203.9558716,,,,
,30302913.375,201.4786072,99.5634765625,0.000955274605808228,1.980961149971E-5,1,0.999253354069792,40.0298881530762,2.00133836882074,28.9399996399879,0.0100533959849769,0.0065347948225861,0.25,0.000408837788635236,0.000958073143022817,0.000411278940586095,201.4786072,201.4786072,99.5634765625,99.5634765625,57.4223391652945,20.5598071388144,26.705515,0,0,0,40,4374,197.97695,99.5634765625,,,,,,,,,,,,,0,,,,0,,,,,,201.4786072,,,,
,30303014.735,198.9784851,99.5634765625,0.00101319316636222,1.00188198563172E-5,1,0.999253354069792,40.0298881530762,2.00109428393489,28.9399996399879,0.0107197664900967,0.00660085362449623,0.25,0.000404591538078894,0.00101626717766941,0.000407132714725282,198.9784851,198.9784851,99.5634765625,99.5634765625,57.6927826329484,20.5616428456075,25.946213,0,0,0,40,4374,195.4485,99.5634765625,,,,,,,,,,,,,0,,,,0,,,,,,198.9784851,,,,
,30303094.115,196.9833527,99.5634765625,0.00108863599577913,5.53125982756683E-6,1,0.999253354069792,40.0298881530762,2.00123111247636,28.9399996399879,0.0115468610199125,0.00693504488181308,0.25,0.000420787312436094,0.00109201741008492,0.000423512006990668,196.9833527,196.9833527,99.5634765625,99.5634765625,57.2886806885061,20.5558958212826,25.946213,0,0,0,40,4374,193.4502,99.5634765625,,,,,,,,,,,,,0,,,,-0.00245,,,,,,196.9833527,,,,
,30303194.875,194.4596252,99.5634765625,0.00127265244847311,7.74886174440922E-6,1,0.999253354069792,40.0298881530762,2.00152769545118,28.9399996399879,0.013584250021827,0.00763312250119066,0.25,0.000450040291560255,0.00127674580207755,0.000453137380504924,194.4596252,194.4596252,99.5634765625,99.5634765625,57.2589788047753,20.5524406209887,26.705515,0,0,0,40,4374,190.94185,99.5634765625,,,,,,,,,,,,,0,,,,-0.00245,,,,,,194.4596252,,,,
,30303295.47,191.9710083,99.5634765625,0.00106940403588911,3.88211661050563E-6,1,0.999253354069792,40.0298881530762,2.00191801020339,28.9399996399879,0.0114669049010903,0.00613265952812265,0.25,0.000353259739730071,0.00107294865620183,0.000355820814890417,191.9710083,191.9710083,99.5634765625,99.5634765625,57.271484861083,20.5510780328863,26.325863,0,0,0,40,4374,188.41755,99.5634765625,,,,,,,,,,,,,0,,,,-0.00245,,,,,,191.9710083,,,,
,30303395.195,189.4768677,99.5634765625,0.00113721409247826,4.22927173444072E-6,1,0.999253354069792,40.0298881530762,2.00149944481547,28.9399996399879,0.012239887749416,0.00624767842911026,0.25,0.000351631979720995,0.00114109252727232,0.000354317017274704,189.4768677,189.4768677,99.5634765625,99.5634765625,57.0971817012945,20.5608093479969,26.325863,0,0,0,40,4374,185.9218,99.5634765625,,,,,,,,,,,,,0,,,,-0.00245,,,,,,189.4768677,,,,
,30303495.27,187.0015106,99.5634765625,,,2,,,,28.9299998986721,,,,,,,187.0015106,187.0015106,99.5634765625,99.5634765625,,,26.325863,,,,-99999999,4374,183.4071,99.5634765625,,,,,,,,,,,,,,,,,,,,,,,187.0015106,,,,
,30303579.16,184.9372101,99.5634765625,0.00131854419277311,9.46542744392837E-6,1,0.999253354069792,40.0298881530762,1.99067293199251,28.9200004190207,0.0141047517789985,0.00729542463163982,0.25,0.000415422485534455,0.00132319861054135,0.00041867509654002,184.9372101,184.9372101,99.5634765625,99.5634765625,56.997133250833,20.5626246959476,26.325863,0,0,0,40,4374,181.3203,99.5634765625,,,,,,,,,,,,,0,,,,0,,,,,,184.9372101,,,,
,30303675.19,182.4992828,99.5634765625,0.00154734651116073,1.01170950834214E-6,1,0.999253354069792,40.0298881530762,1.99033614412775,28.9200004190207,0.016459511691583,0.00908518365324019,0.25,0.000533832852004317,0.00155285356513303,0.000537905217108113,182.4992828,182.4992828,99.5634765625,99.5634765625,57.1096877576022,20.5541209272782,26.325863,0,0,0,40,4374,178.8796,99.5634765625,,,,,,,,,,,,,0,,,,0,,,,,,182.4992828,,,,
,30303775.93,179.9679871,99.5634765625,0.0017055679597532,7.04073505893489E-6,1,0.999253354069792,40.0298881530762,1.99114485274214,28.9200004190207,0.0182581562268967,0.00940142204244017,0.25,0.000533847090868889,0.00171182304968949,0.000538198966115388,179.9679871,179.9679871,99.5634765625,99.5634765625,57.2050464369484,20.5540630921429,25.946213,0,0,0,40,4374,176.3807,99.5634765625,,,,,,,,,,,,,0,,,,-0.00245,,,,,,179.9679871,,,,
,30303873.96,177.4850769,99.5634765625,0.00183270723878937,9.90800234036859E-7,1,0.999253354069792,40.0298881530762,1.9911536018922,28.9200004190207,0.0197346227647165,0.00944706089294114,0.25,0.000515663881897541,0.00183962481286986,0.000520186615115192,177.4850769,177.4850769,99.5634765625,99.5634765625,57.3105662870445,20.5533568932667,25.566563,0,0,0,40,4374,173.9324,99.5634765625,,,,,,,,,,,,,0,,,,-0.0049,,,,,,177.4850769,,,,
,30303973.65,174.9875336,99.5634765625,0.00198496493500797,2.02249164350457E-6,1,0.999253354069792,40.0298881530762,1.97737580911572,28.9200004190207,0.0213984659884492,0.00922070487666273,0.25,0.000474503546787604,0.0019926993054312,0.000479139601199179,174.9875336,174.9875336,99.5634765625,99.5634765625,57.1909771236022,20.5540598012881,25.946213,0,0,0,40,4374,171.4504,99.5634765625,,,,,,,,,,,,,0,,,,0,,,,,,174.9875336,,,,
,30304073.82,172.4639893,99.5634765625,0.00217688171415005,4.15560518354333E-7,1,0.999253354069792,40.0298881530762,1.9772068907089,28.9200004190207,0.0237418267953467,0.00853239675937872,0.25,0.000379878548264468,0.00218569888091888,0.000384456680530166,172.4639893,172.4639893,99.5634765625,99.5634765625,57.1956668947176,20.563849700064,26.325863,0,0,0,40,4374,168.9633,99.5634765625,,,,,,,,,,,,,0,,,,0,,,,,,172.4639893,,,,
,30304174.825,169.9701233,99.5634765625,0.00227094978536928,3.72349782257428E-7,1,0.999253354069792,40.0298881530762,1.97722523544219,28.9200004190207,0.0250188544754511,0.00746930449554756,0.25,0.000268883054096158,0.00228047394670399,0.000273196233511514,169.9701233,169.9701233,99.5634765625,99.5634765625,57.0315249056791,20.5584407600532,25.566563,0,0,0,40,4374,166.44155,99.5634765625,,,,,,,,,,,,,0,,,,0,,,,,,169.9701233,,,,
,30304272.655,167.4910126,99.5634765625,0.00234593812709427,4.62741059533276E-7,1,0.999253354069792,40.0298881530762,1.97728312222797,28.9200004190207,0.0260508078794901,0.00654796206697926,0.25,0.000173806192790798,0.00235607896680914,0.000177887894651397,167.4910126,167.4910126,99.5634765625,99.5634765625,57.0870205305445,20.5556829678666,25.566563,0,0,0,40,4374,164.009,99.5634765625,,,,,,,,,,,,,0,,,,0,,,,,,167.4910126,,,,
,30304371.39,164.9939423,99.5634765625,0.00240925225792228,3.45212549446808E-7,1,0.999253354069792,40.0298881530762,1.97727527681502,28.9299990981817,0.0269009161239105,0.00589004462358636,0.25,0.000104199189769278,0.00241993497003681,0.000108141980807326,164.9939423,164.9939423,99.5634765625,99.5634765625,57.2073913225061,20.5591199240912,25.566563,0,0,0,40,4374,161.55115,99.5634765625,,,,,,,,,,,,,0,,,,0.00245,,,,,,164.9939423,,,,
,30304472.87,162.4469757,99.5634765625,0.00246304537414782,4.14062659643665E-7,1,0.999253354069792,40.0298881530762,1.97683015844585,28.9299990981817,0.0275816145798886,0.00553746566231492,0.25,6.34897577055969E-5,0.00247419723781058,6.74114837246648E-5,162.4469757,162.4469757,99.5634765625,99.5634765625,57.2878990599868,20.5688668543922,25.566563,0,0,0,40,4374,159.02325,99.5634765625,,,,,,,,,,,,,0,,,,0.00245,,,,,,162.4469757,,,,
,30304570.38,159.9977417,99.5634765625,0.00250956668370936,4.60680834403469E-7,1,0.999253354069792,40.0298881530762,1.97696837081038,28.9299990981817,0.0281483321758026,0.00540114723929647,0.25,4.31274458326485E-5,0.00252112386954681,4.7109927590892E-5,159.9977417,159.9977417,99.5634765625,99.5634765625,57.108906129083,20.5610722623849,25.946213,0,0,0,40,4374,156.58775,99.5634765625,,,,,,,,,,,,,0,,,,-0.00245,,,,,,159.9977417,,,,
,30304671.195,157.4774323,99.5634765625,0.00255650610760861,3.39280021849559E-7,1,0.999253354069792,40.0298881530762,1.97637749285988,28.9299990981817,0.0286940749025577,0.00535413496257558,0.25,3.07902732772823E-5,0.0025684672690481,3.48790350760691E-5,157.4774323,157.4774323,99.5634765625,99.5634765625,57.2417829773522,20.5687177050269,25.566563,0,0,0,40,4374,154.07755,99.5634765625,,,,,,,,,,,,,0,,,,0.00245,,,,,,157.4774323,,,,
,30304771.18,154.957077,99.5634765625,0.0026069807561673,3.84552823107827E-7,1,0.999253354069792,40.0298881530762,2.00006794839208,28.9299990981817,0.0296129599913693,0.00543314904976181,0.25,2.34338803211717E-5,0.00261935893453368,2.76626932571052E-5,154.957077,154.957077,99.5634765625,99.5634765625,57.1409528983714,20.5674852329563,25.566563,0,0,0,40,4374,151.6148,99.5634765625,,,,,,,,,,,,,0,,,,0,,,,,,154.957077,,,,
,30304869.975,152.4642334,99.5634765625,0.00265152493514637,3.84387423972041E-7,1,0.999253354069792,40.0298881530762,2.00015104105013,28.9399996399879,0.0301328816525684,0.00546414151522011,0.25,1.82476269723036E-5,0.00266428914192035,2.26260439922958E-5,152.4642334,152.4642334,99.5634765625,99.5634765625,57.017455592333,20.5736917324625,25.566563,0,0,0,40,4374,149.1267,99.5634765625,,,,,,,,,,,,,0,,,,-0.00245,,,,,,152.4642334,,,,
,30304968.97,149.991333,99.5634765625,0.00269738471881066,4.33315757245468E-7,1,0.999253354069792,40.0298881530762,2.00042197606356,28.9399996399879,0.0306666715561743,0.00552061552202877,0.25,1.50199641227535E-5,0.00271053885464917,1.95674292991731E-5,149.991333,149.991333,99.5634765625,99.5634765625,56.7954730928714,20.57013350332,25.566563,0,0,0,40,4374,146.65065,99.5634765625,,,,,,,,,,,,,0,,,,0,,,,,,149.991333,,,,
,30305070.235,147.4564056,99.5634765625,0.00274194857899992,4.23419868505928E-7,1,0.999253354069792,40.0298881530762,2.00039807707657,28.9399996399879,0.0311812722838149,0.00557524180644727,0.25,1.19112850219727E-5,0.00275549199367069,1.66374181568612E-5,147.4564056,147.4564056,99.5634765625,99.5634765625,57.1511140691214,20.5725366291527,25.186911,0,0,0,40,4374,144.1337,99.5634765625,,,,,,,,,,,,,0,,,,0.0049,,,,,,147.4564056,,,,
touchdown = 18.7199991196394 mm,30305165.315,145.0730591,99.5634765625,0.00278230086167072,4.59113802098676E-7,1,0.999253354069792,40.0298881530762,1.97577416367771,28.9299990981817,0.0312720907199993,0.0055781382103009,0.25,1.08160553721945E-5,0.002796200017451,1.57270632999369E-5,145.0730591,145.0730591,99.5634765625,99.5634765625,57.2503808910638,20.5832611485575,25.566563,0,0,0,40,4374,141.74425,99.5634765625,,,,,,,,,,,,,0,,,,-0.00245,,,,,,145.0730591,,,,
,30305248.515,142.9759064,99.5634765625,0.00281504095508657,4.22885382801774E-7,1,0.999253354069792,40.0298881530762,1.97635692908452,28.9299990981817,0.0316516082370885,0.00563928920051178,0.25,1.02688859403651E-5,0.00282923904295665,1.53458382558892E-5,142.9759064,142.9759064,99.5634765625,99.5634765625,57.0768593597945,20.5659385979919,24.807261,0,0,0,40,4374,139.6796,99.5634765625,,,,,,,,,,,,,0,,,,0.00245,,,,,,142.9759064,,,,
,30305350.515,140.4348755,99.5634765625,0.00285769536020541,3.442857435018E-7,1,0.999253354069792,40.0298881530762,1.97596149512149,28.9299990981817,0.0321274751343179,0.00572035935011452,0.25,9.95937977174479E-6,0.00287226902237529,1.52574036801455E-5,140.4348755,140.4348755,99.5634765625,99.5634765625,56.9752476522945,20.5711951228712,25.186911,0,0,0,40,4374,137.1396,99.5634765625,,,,,,,,,,,,,0,,,,0,,,,,,140.4348755,,,,
,30305449.35,137.9626617,99.5634765625,0.0028994565404667,4.56594816528971E-7,1,0.999253354069792,40.0298881530762,1.97607328488758,28.9299990981817,0.0326000696613396,0.00580668813100597,0.25,1.01421596526413E-5,0.00291439511399896,1.56702879718756E-5,137.9626617,137.9626617,99.5634765625,99.5634765625,57.1706547821022,20.5660986002406,25.186911,0,0,0,40,4374,134.6762,99.5634765625,,,,,,,,,,,,,0,,,,0,,,,,,137.9626617,,,,
,30305565.11,135.072525,99.5634765625,,,2,,,,28.9700002032518,,,,,,,135.072525,135.072525,99.5634765625,99.5634765625,,,25.186911,,,,-99999999,4374,131.7785,99.5634765625,,,,,,,,,,,,,,,,,,,,,,,135.072525,,,,
,30305648.235,132.9663391,99.5634765625,0.00298739448595762,4.22851109060855E-7,1,0.999253354069792,40.0298881530762,1.99947113937905,28.9699994027615,0.0339710962900822,0.0060556005050113,0.25,1.05101349352862E-5,0.00300308370442953,1.65504337386254E-5,132.9663391,132.9663391,99.5634765625,99.5634765625,57.3246356003907,20.5864545455359,24.807261,0,0,0,40,4374,129.72505,99.5634765625,,,,,,,,,,,,,0,,,,0.00245,,,,,,132.9663391,,,,
,30305744.195,130.490448,99.5634765625,0.00302890778391264,3.67637769933157E-7,1,0.999253354069792,40.0298881530762,1.99955811521704,28.9600007236004,0.0344448132399322,0.00614819063966798,0.25,1.11710270579403E-5,0.00304495500501656,1.74791715449775E-5,130.490448,130.490448,99.5634765625,99.5634765625,57.1221938139099,20.5822089994199,25.186911,0,0,0,40,4374,127.3678,99.5634765625,,,,,,,,,,,,,0,,,,0,,,,,,130.490448,,,,
,30305845.92,127.9720688,99.5634765625,0.00307450207205075,4.42077265245949E-7,1,0.999253354069792,40.0298881530762,2.00030487925883,28.9600007236004,0.0349759911211999,0.00625071181364872,0.25,1.17882583367995E-5,0.00309092424879738,1.84032917277591E-5,127.9720688,127.9720688,99.5634765625,99.5634765625,57.1690915250637,20.5771620974166,24.807261,0,0,0,40,4374,124.8372,99.5634765625,,,,,,,,,,,,,0,,,,0,,,,,,127.9720688,,,,
,30305944.725,125.4488449,99.5634765625,0.00311897566349907,3.66399222233637E-7,1,0.999253354069792,40.0298881530762,2.00022908588233,28.9699994027615,0.0354827008896943,0.00633781693054941,0.25,1.14471365178366E-5,0.00313576589582592,1.83747047738015E-5,125.4488449,125.4488449,99.5634765625,99.5634765625,57.159711982833,20.5686181490963,24.807261,0,0,0,40,4374,122.3808,99.5634765625,,,,,,,,,,,,,0,,,,0.0049,,,,,,125.4488449,,,,
,30306042.22,122.9867859,99.5634765625,0.00316294847076734,4.01965136135553E-7,1,0.999253354069792,40.0298881530762,2.00049022600928,28.9699994027615,0.0359873324494383,0.00643643720603605,0.25,1.2099329010821E-5,0.00318009182993556,1.93610035901946E-5,122.9867859,122.9867859,99.5634765625,99.5634765625,57.1909771236022,20.5739037299378,25.186911,0,0,0,40,4374,119.957,99.5634765625,,,,,,,,,,,,,0,,,,0.00245,,,,,,122.9867859,,,,
,30306141.89,120.486763,99.5634765625,0.00320817033956909,3.74766432232013E-7,1,0.999253354069792,40.0298881530762,2.00070452358139,28.9799999445677,0.0365055985435146,0.00653640254288228,0.25,1.26353943823238E-5,0.00322566730988234,2.02611182334242E-5,120.4582062,120.5153198,99.5634765625,99.5634765625,57.3535558556022,20.5747780650174,24.807261,0,0,0,40,4374,117.47995,99.5634765625,,,,,,,,,,,,,0,,,,0,,,,,,120.486763,,,,
,30306241.205,117.9934082,99.5634765625,0.0032546095408096,3.93149839670113E-7,1,0.999253354069792,40.0298881530762,2.00081995918765,28.9799999445677,0.0370364738017064,0.00663565107271828,0.25,1.28990955538553E-5,0.00327245780489738,2.09141067631592E-5,117.9934082,117.9934082,99.5634765625,99.5634765625,57.3926372815638,20.568148169675,24.807261,0,0,0,40,4374,115.0139,99.5634765625,,,,,,,,,,,,,0,,,,0.00245,,,,,,117.9934082,,,,
,30306339.82,115.4917526,99.5634765625,0.00329812848039655,3.96382358747962E-7,1,0.999253354069792,40.0298881530762,2.00096978404177,28.9799999445677,0.0375345806764315,0.00672957431217412,0.25,1.31718294876275E-5,0.0033163016586158,2.15949316042881E-5,115.4917526,115.4917526,99.5634765625,99.5634765625,57.2441278629099,20.5677469515513,24.427608,0,0,0,40,4374,112.5577,99.5634765625,,,,,,,,,,,,,0,,,,0,,,,,,115.4917526,,,,
,30306440.875,112.9660034,99.5634765625,0.00333813042981791,4.18711785558561E-7,1,0.999253354069792,40.0298881530762,1.97704857800405,28.999999165535,0.0375560806386433,0.0067377573858844,0.25,1.33735524536129E-5,0.00335659447150318,2.22321173149709E-5,112.9660034,112.9660034,99.5634765625,99.5634765625,57.4059249663907,20.5589274032508,24.807261,0,0,0,40,4374,110.0444,99.5634765625,,,,,,,,,,,,,0,,,,-0.00245,,,,,,112.9660034,,,,
,30306539.56,110.4804802,99.5634765625,0.00338086845125099,5.1820330998357E-7,1,0.999253354069792,40.0298881530762,1.97732140564228,28.999999165535,0.0380416110848802,0.00683029398242038,0.25,1.36619634782642E-5,0.00339962188824895,2.2987231087778E-5,110.4471054,110.513855,99.5634765625,99.5634765625,57.1636201254291,20.5623687345547,24.427608,0,0,0,40,4374,107.5937,99.5634765625,,,,,,,,,,,,,0,,,,0,,,,,,110.4804802,,,,
,30306638.63,107.984993,99.5634765625,0.00342370821400669,4.814021200633E-7,1,0.999253354069792,40.0298881530762,1.97767969918093,28.999999165535,0.0385291418343758,0.00692705707608215,0.25,1.42487841619817E-5,0.00344273236496583,2.40775374880599E-5,107.984993,107.984993,99.5634765625,99.5634765625,57.4551675631022,20.5580230568807,24.427608,0,0,0,40,4374,105.1427,99.5634765625,,,,,,,,,,,,,0,,,,0,,,,,,107.984993,,,,
,30306738.825,105.4655228,99.5634765625,0.00346685745750499,4.4668805419458E-7,1,0.999253354069792,40.0298881530762,1.9777158015151,28.999999165535,0.0390141896595041,0.0070221468917135,0.25,1.46858588012149E-5,0.00348613042443344,2.50635074991484E-5,105.4655228,105.4655228,99.5634765625,99.5634765625,57.3582456267176,20.5614115160616,24.427608,0,0,0,40,4374,102.651,99.5634765625,,,,,,,,,,,,,0,,,,-0.00245,,,,,,105.4655228,,,,
,30306837.555,102.9867096,99.5634765625,0.00351035549053434,4.33406082182628E-7,1,0.999253354069792,40.0298881530762,1.99039257239594,29.0399994701147,0.0397428006744161,0.00716846159099902,0.25,1.57222399179591E-5,0.00352985268663914,2.66831126347412E-5,102.9867096,102.9867096,99.5634765625,99.5634765625,56.9439825115252,20.567646071925,24.427608,0,0,0,40,4374,100.22865,99.5634765625,,,,,,,,,,,,,0,,,,0,,,,,,102.9867096,,,,
,30306938.36,100.45224,99.5634765625,0.0035522016183347,5.00979612207595E-7,1,0.999253354069792,40.0298881530762,1.99111632778243,29.0300007909536,0.0402287390682932,0.00726326222728174,0.25,1.60145448620672E-5,0.00357187865633608,2.76157655222943E-5,100.45224,100.45224,99.5634765625,99.5634765625,57.5028469027753,20.5450327519369,24.427608,0,0,0,40,4374,97.70085,99.5634765625,,,,,,,,,,,,,0,,,,-0.0049,,,,,,100.45224,,,,
,30307035.855,97.9612274,99.5634765625,0.00359996158439342,4.04673082479728E-7,1,0.999253354069792,40.0298881530762,1.99086626413951,29.0399994701147,0.0407637915396937,0.00736010034731101,0.25,1.57207940537836E-5,0.00361982310728004,2.80066455283768E-5,97.9612274,97.9612274,99.5634765625,99.5634765625,57.5380201861407,20.556054455012,24.047956,0,0,0,40,4374,95.28345,99.5634765625,,,,,,,,,,,,,0,,,,0,,,,,,97.9612274,,,,
,30307135.955,95.4545898,99.5634765625,0.0036426772041917,4.86820325087568E-7,1,0.999253354069792,40.0298881530762,1.9905814346693,29.0399994701147,0.0412380181620783,0.00745953811581641,0.25,1.64957133369664E-5,0.00366264004309659,2.9526096895504E-5,95.4545898,95.4545898,99.5634765625,99.5634765625,57.8827183631215,20.5583684630057,23.668306,0,0,0,40,4374,92.7983,99.5634765625,,,,,,,,,,,,,0,,,,0,,,,,,95.4545898,,,,
touchdown = 18.8299994915724 mm,30307240.055,92.7745209,99.5634765625,0.00368472249909157,3.76700940482919E-7,1,0.999253354069792,40.0298881530762,1.99039879622739,29.0399994701147,0.0417050680251153,0.00756297457819248,0.25,1.76406843606359E-5,0.0037047283020645,3.14955557246729E-5,92.7745209,92.7745209,99.5634765625,99.5634765625,57.4895592179484,20.5561841851814,24.047956,0,0,0,40,4374,90.24305,99.5634765625,,,,,,,,,,,,,0,,,,-0.0049,,,,,,92.7745209,,,,
,30307331.845,90.4583206,99.5634765625,0.00371935727950667,4.69668007950558E-7,1,0.999253354069792,40.0298881530762,1.99050028803079,29.0500000119209,0.0420956322306498,0.00763937895178086,0.25,1.76323055186281E-5,0.00373932360436852,3.22693863801407E-5,90.4583206,90.4583206,99.5634765625,99.5634765625,57.332451885583,20.5659952113793,23.668306,0,0,0,40,4374,87.94735,99.5634765625,,,,,,,,,,,,,0,,,,0.00245,,,,,,90.4583206,,,,
,30307432.625,87.9409409,99.5634765625,0.00375712191567598,5.50125502451978E-7,1,0.999253354069792,40.0298881530762,1.99058753977964,29.0500000119209,0.0425188575484771,0.00773036927610504,0.25,1.82577712937615E-5,0.00377697115929104,3.38141625736767E-5,87.9409409,87.9409409,99.5634765625,99.5634765625,57.3238539718714,20.5671602085852,23.288654,0,0,0,40,4374,85.4592,99.5634765625,,,,,,,,,,,,,0,,,,0.00245,,,,,,87.9409409,,,,
,30307529.45,85.4314117,99.5634765625,0.00379106431349501,5.14045897337734E-7,1,0.999253354069792,40.0298881530762,1.99046617318159,29.0500000119209,0.0428935086690009,0.00781444289460938,0.25,1.89902568221359E-5,0.00381071064665297,3.54886252876406E-5,85.4314117,85.4314117,99.5634765625,99.5634765625,57.3652802833907,20.5697172045502,23.288654,0,0,0,40,4374,83.07455,99.5634765625,,,,,,,,,,,,,0,,,,0,,,,,,85.4314117,,,,
,30307632.67,82.8141022,99.5634765625,,,2,,,,29.0999997961521,,,,,,,82.8141022,82.8141022,99.5634765625,99.5634765625,,,23.288654,,,,-99999999,4374,80.5304,99.5634765625,,,,,,,,,,,,,,,,,,,,,,,82.8141022,,,,
,30307724.03,80.4903412,99.5634765625,0.00385511920975524,4.75113689039778E-7,1,0.999253354069792,40.0298881530762,2.00166496917418,29.1000008583069,0.043836455290673,0.00800904985658647,0.25,1.9449142921282E-5,0.00387402127797271,3.80300333660303E-5,80.4903412,80.4903412,99.5634765625,99.5634765625,57.3840393678522,20.555475312721,23.668306,0,0,0,40,4374,78.2874,99.5634765625,,,,,,,,,,,,,0,,,,0,,,,,,80.4903412,,,,
,30307824.47,77.9676208,99.5634765625,0.00388396235549906,4.22851550188833E-7,1,0.999253354069792,40.0298881530762,2.00156859409497,29.1000008583069,0.0441515918047961,0.00808026555345494,0.25,1.97227450402388E-5,0.00390225220584726,3.94737649001213E-5,77.9676208,77.9676208,99.5634765625,99.5634765625,57.2066096939868,20.5580022469743,22.529354,0,0,0,40,4374,75.8105,99.5634765625,,,,,,,,,,,,,0,,,,-0.0049,,,,,,77.9676208,,,,
,30307922.225,75.4787064,99.5634765625,0.00391064335197576,5.3185350792213E-7,1,0.999253354069792,40.0298881530762,2.00141613547363,29.1000008583069,0.0444372165393016,0.00815832032578883,0.25,2.09838197246959E-5,0.00392816327859269,4.19411065336499E-5,75.4787064,75.4787064,99.5634765625,99.5634765625,57.3418314278138,20.5609421549965,23.288654,0,0,0,40,4374,73.39745,99.5634765625,,,,,,,,,,,,,0,,,,0.00245,,,,,,75.4787064,,,,
,30308020.025,72.9972382,99.5634765625,0.00393456967178009,4.33475239894133E-7,1,0.999253354069792,40.0298881530762,2.00064989786223,29.1000008583069,0.0446777511342563,0.00822019476815184,0.25,2.15045391754194E-5,0.00395113133933603,4.37019048406662E-5,72.9972382,72.9972382,99.5634765625,99.5634765625,57.1112510146407,20.5794987769202,22.909004,0,0,0,40,4374,70.99865,99.5634765625,,,,,,,,,,,,,0,,,,0,,,,,,72.9972382,,,,
,30308098.065,70.9925308,99.5634765625,0.00395115895217863,4.32495867928834E-7,1,0.999253354069792,40.0298881530762,2.0008690081249,29.1200000792742,0.0448578192700525,0.00826380365566791,0.25,2.15664710692661E-5,0.0039667963566999,4.47715141850991E-5,70.9925308,70.9925308,99.5634765625,99.5634765625,57.3363600281791,20.5680531836649,22.149702,0,0,0,40,4374,69.07995,99.5634765625,,,,,,,,,,,,,0,,,,0.00245,,,,,,70.9925308,,,,
,30308199.205,68.4423294,99.5634765625,0.00397083244315232,4.6481325727612E-7,1,0.999253354069792,40.0298881530762,2.00076096602674,29.1200000792742,0.0450576697893087,0.00832535522308446,0.25,2.25718676725598E-5,0.00398504038925255,4.70933078018434E-5,68.4423294,68.4423294,99.5634765625,99.5634765625,57.3387049137368,20.5687474588408,22.149702,0,0,0,40,4374,66.601,99.5634765625,,,,,,,,,,,,,0,,,,-0.0049,,,,,,68.4423294,,,,
,30308295.07,65.9485397,99.5634765625,0.00398864175950543,4.94968538921481E-7,1,0.999253354069792,40.0298881530762,2.0005288915215,29.1200000792742,0.0452289827385824,0.00839715601545654,0.25,2.49530530200288E-5,0.00400122852425737,5.07189849173618E-5,65.9485397,65.9485397,99.5634765625,99.5634765625,57.3332335141022,20.5754354547649,21.770052,0,0,0,40,4374,64.24325,99.5634765625,,,,,,,,,,,,,0,,,,0.00245,,,,,,65.9485397,,,,
,30308392.83,63.4695282,99.5634765625,0.00400379456708451,4.01510216628825E-7,1,0.999253354069792,40.0298881530762,2.00061598071608,29.1200000792742,0.045372783264238,0.00846822893865837,0.25,2.77139376291403E-5,0.00401443968285653,5.46817820673356E-5,63.4695282,63.4695282,99.5634765625,99.5634765625,57.1479875550445,20.5705481036018,22.529354,0,0,0,40,4374,61.8388,99.5634765625,,,,,,,,,,,,,0,,,,0.00245,,,,,,63.4695282,,,,
,30308491.725,60.9508514,99.5634765625,0.00401557860793978,4.09268312084906E-7,1,0.999253354069792,40.0298881530762,1.99985369153862,29.1499998420477,0.0454569464700433,0.00852587751589502,0.25,3.03444444456414E-5,0.00402396961669321,5.83994278633384E-5,60.9508514,60.9508514,99.5634765625,99.5634765625,57.4145228801022,20.5790728021841,22.149702,0,0,0,40,4374,59.4104,99.5634765625,,,,,,,,,,,,,0,,,,-0.0049,,,,,,60.9508514,,,,
,30308589.575,58.4624672,99.5634765625,0.00402744045762017,3.91279830446989E-7,1,0.999253354069792,40.0298881530762,1.99953331068693,29.1399993002415,0.0455474877393625,0.00859174431219551,0.25,3.37450425365854E-5,0.00403332454585181,6.27170794665163E-5,58.4624672,58.4624672,99.5634765625,99.5634765625,57.1878506095253,20.5875350588523,21.3904,0,0,0,40,4374,57.0098,99.5634765625,,,,,,,,,,,,,0,,,,-0.0049,,,,,,58.4624672,,,,
,30308686.005,55.9766731,99.5634765625,0.00403294129509493,5.2694884039061E-7,1,0.999253354069792,40.0298881530762,1.99944613356854,29.1399993002415,0.0455752892464358,0.00860863779765156,0.25,3.41442364534219E-5,0.00403612675710265,6.37570532091093E-5,55.9766731,55.9766731,99.5634765625,99.5634765625,57.0416860764291,20.5870338613952,22.149702,0,0,0,40,4374,54.6386,99.5634765625,,,,,,,,,,,,,0,,,,0,,,,,,55.9766731,,,,
,30308784.765,53.4763527,99.5634765625,0.00404015200244412,3.48170440091911E-7,1,0.999253354069792,40.0298881530762,1.99945515213529,29.1499998420477,0.0456210041774478,0.00863414657674302,0.25,3.52656529658667E-5,0.00404040760580744,6.52678834751188E-5,53.4763527,53.4763527,99.5634765625,99.5634765625,57.1659650109868,20.5897812542254,21.01075,0,0,0,40,4374,52.2313,99.5634765625,,,,,,,,,,,,,0,,,,-0.0049,,,,,,53.4763527,,,,
,30308882.39,50.9503136,99.5634765625,0.00404296330494566,5.18332289599002E-7,1,0.999253354069792,40.0298881530762,1.99946393218416,29.1700009256601,0.0456098860992466,0.00868646642418289,0.25,3.98767839824384E-5,0.00404021152566653,6.99192782481554E-5,50.9503136,50.9503136,99.5634765625,99.5634765625,57.0690430746022,20.589975015787,20.251448,0,0,0,40,4374,49.8681,99.5634765625,,,,,,,,,,,,,0,,,,0.00245,,,,,,50.9503136,,,,
,30308977.305,48.4730911,99.5634765625,0.00403200244856379,4.06174803815779E-7,1,0.999253354069792,40.0298881530762,1.99981830035285,29.1700009256601,0.0454900167035744,0.00849651173380083,0.25,2.57055266614719E-5,0.00402643873512808,5.53929587314119E-5,48.4730911,48.4730911,99.5634765625,99.5634765625,57.0721695886791,20.5855534426186,19.871798,0,0,0,40,4374,47.5485,99.5634765625,,,,,,,,,,,,,0,,,,0.00245,,,,,,48.4730911,,,,
,30309076.045,45.9623451,99.5634765625,0.00403489488434437,5.30653946373893E-7,1,0.999253354069792,40.0298881530762,1.99974182566143,29.1700009256601,0.0454877077394131,0.00849611440200599,0.25,2.62901937993532E-5,0.00402638178960239,5.53950780283115E-5,45.9623451,45.9623451,99.5634765625,99.5634765625,57.0541921327368,20.5894722019504,19.492144,0,0,0,40,4370,45.15455,99.5634765625,,,,,,,,,,,,,0,,,,0.00245,,,,,,45.9623451,,,,
,30309173.115,43.4768906,99.5634765625,0.00403582316400246,5.29887839601588E-7,1,0.999253354069792,40.0298881530762,1.99971632653004,29.1700009256601,0.0454664026652876,0.00849222247200314,0.25,2.71414132374343E-5,0.00402454621593822,5.53773006742537E-5,43.4768906,43.4768906,99.5634765625,99.5634765625,56.8173586914099,20.589071665544,18.353191,0,0,0,40,4370,42.7725,99.5634765625,,,,,,,,,,,,,0,,,,-0.00245,,,,,,43.4768906,,,,
touchdown = 18.9699996262789 mm,30309284.5,40.671257,99.5634765625,0.00403435101320383,4.63270469702638E-7,1,0.999253354069792,40.0298881530762,2.00003561349884,29.2000006884336,0.0454240461359334,0.00848689865216002,0.25,2.85666894634453E-5,0.00402022273225673,5.55391381432381E-5,40.671257,40.671257,99.5634765625,99.5634765625,57.0010413934291,20.575591323477,18.353191,0,0,0,40,4370,40.049,99.5634765625,,,,,,,,,,,,,0,,,,0.0049,,,,,,40.671257,,,,
,30309371.065,38.4455528,99.5634765625,0.00403427555352638,3.6769042801843E-7,1,0.999253354069792,40.0298881530762,1.99963342873691,29.2000006884336,0.045394840590526,0.00846544194168021,0.25,2.82724524653682E-5,0.00401817219529273,5.41419800644404E-5,38.4455528,38.4455528,99.5634765625,99.5634765625,57.3301070000253,20.5927042358627,17.593889,0,0,0,40,4370,37.8897,99.5634765625,,,,,,,,,,,,,0,,,,0,,,,,,38.4455528,,,,
,30309468.375,35.9813957,99.5634765625,0.00403312102383852,4.76768671521559E-7,1,0.999253354069792,40.0298881530762,1.99983760963007,29.1900001466274,0.0453664787413292,0.00845123213245343,0.25,2.87365112723058E-5,0.00401513847613965,5.33379460127799E-5,35.9504242,36.0123672,99.5634765625,99.5634765625,56.7900016932368,20.5921444558994,17.214239,0,0,0,40,4370,35.4955,99.5634765625,,,,,,,,,,,,,0,,,,-0.00245,,,,,,35.9813957,,,,
,30309566.75,33.481144,99.5634765625,0.00403208114999985,5.14142998447676E-7,1,0.999253354069792,40.0298881530762,1.99980197183898,29.1900001466274,0.0453371765402008,0.00843953760069741,0.25,2.9419599072278E-5,0.00401252105125334,5.27696790819907E-5,33.481144,33.481144,99.5634765625,99.5634765625,57.0283983916022,20.5932432021613,16.454937,0,0,0,40,4370,33.05875,99.5634765625,,,,,,,,,,,,,0,,,,0.0049,,,,,,33.481144,,,,
,30309678.97,30.6211433,99.5634765625,,,2,,,,29.2200007098913,,,,,,,30.6211433,30.6211433,99.5634765625,99.5634765625,,,16.075285,,,,-99999999,4370,30.2883,99.5634765625,,,,,,,,,,,,,,,,,,,,,,,30.6211433,,,,
,30309766.035,28.4498024,99.5634765625,0.00403014421905427,4.11898542609129E-7,1,0.999253354069792,40.0298881530762,2.00022439141766,29.2199999094009,0.045300808908605,0.00842270913866558,0.25,3.06566727007399E-5,0.00400834560528874,5.18543792533973E-5,28.4498024,28.4498024,99.5634765625,99.5634765625,56.8603482599676,20.5818046190744,16.075285,0,0,0,40,4370,28.1292,99.5634765625,,,,,,,,,,,,,0,,,,0,,,,,,28.4498024,,,,
,30309864.765,25.9718418,99.5634765625,0.00402952618558364,4.79191406236706E-7,1,0.999253354069792,40.0298881530762,1.99971385633904,29.2099993675947,0.0452772596379603,0.0084041569447332,0.25,3.02188230761459E-5,0.00400702812293989,5.06246121985358E-5,25.9718418,25.9718418,99.5634765625,99.5634765625,57.1065612435253,20.5883393389713,16.075285,0,0,0,40,4370,25.6797,99.5634765625,,,,,,,,,,,,,0,,,,0,,,,,,25.9718418,,,,
,30309964.765,23.462944,99.5634765625,0.00402930661875397,4.77245255562428E-7,1,0.999253354069792,40.0298881530762,1.99905711851871,29.2199999094009,0.0452558801874,0.00839562238455379,0.25,3.04147605379881E-5,0.00400632403134194,5.02248827832185E-5,23.462944,23.462944,99.5634765625,99.5634765625,57.007294421583,20.5942532011647,15.315984,0,0,0,40,4370,23.1908,99.5634765625,,,,,,,,,,,,,0,,,,0,,,,,,23.462944,,,,
,30310061.995,20.9750824,99.5634765625,0.00403039836327574,5.60012231840584E-7,1,0.999253354069792,40.0298881530762,1.99933941527608,29.2099993675947,0.0452729698321167,0.00838794050410284,0.25,2.98588951104353E-5,0.00400713627088025,4.93063004315314E-5,20.9750824,20.9750824,99.5634765625,99.5634765625,57.0666981890445,20.5989703018871,14.936333,0,0,0,40,4370,20.7703,99.5634765625,,,,,,,,,,,,,0,,,,0.00245,,,,,,20.9750824,,,,
,30310162.9,18.4577103,99.5634765625,0.00403050056748194,4.85866257291665E-7,1,0.999253354069792,40.0298881530762,1.9989347458343,29.2300004512072,0.0452628116914363,0.00839364957948832,0.25,3.06906493400257E-5,0.00400712349165767,4.99559631241017E-5,18.4577103,18.4577103,99.5634765625,99.5634765625,56.9369478548522,20.6010137832551,14.177031,0,0,0,40,4370,18.259,99.5634765625,,,,,,,,,,,,,0,,,,0,,,,,,18.4577103,,,,
,30310262.635,15.936285,99.5634765625,0.00403181598026178,5.01528341729376E-7,1,0.999253354069792,40.0298881530762,1.99887704644264,29.2300004512072,0.0452771150200836,0.00839377660141334,0.25,3.04874645390706E-5,0.00400846279522379,4.97564772204225E-5,15.936285,15.936285,99.5634765625,99.5634765625,57.2628869473714,20.6054119257584,13.417728,0,0,0,40,4370,15.7851,99.5634765625,,,,,,,,,,,,,0,,,,-0.0049,,,,,,15.936285,,,,
,30310361.855,13.47664405,99.5634765625,0.00403385794081238,4.72830699128307E-7,1,0.999253354069792,40.0298881530762,1.99845301897766,29.2300004512072,0.0452917704487957,0.00839306936509038,0.25,3.02080489466655E-5,0.00401052146038717,4.94888522988228E-5,13.4472857,13.5060024,99.5634765625,99.5634765625,57.0760777312753,20.6131559128897,13.797379,0,0,0,40,4370,13.3163,99.5634765625,,,,,,,,,,,,,0,,,,-0.0049,,,,,,13.47664405,,,,
,30310461.83,10.9508514,99.5634765625,0.0040373348634661,4.7919429495486E-7,1,0.999253354069792,40.0298881530762,1.9982263413727,29.2300004512072,0.0453256335557013,0.00840231973795912,0.25,3.04903089939837E-5,0.00401399854421659,4.97865249196157E-5,10.9508514,10.9508514,99.5634765625,99.5634765625,57.0690430746022,20.614740634422,12.658426,0,0,0,40,4370,10.8054,99.5634765625,,,,,,,,,,,,,0,,,,-0.00245,,,,,,10.9508514,,,,
,30310633.595,10.0175676,99.5634765625,0.00403818728425136,4.9565846274427E-7,1,0.999253354069792,40.0298881530762,1.99799325769827,29.2399991303682,0.0453310141208334,0.00839874400549889,0.25,3.01028642217687E-5,0.00401485424684505,4.94054942301163E-5,10.0175676,10.0175676,99.5634765625,99.5634765625,57.0588819038522,20.6089331088987,12.278775,0,0,0,40,4369,9.9684,99.5634765625,,,,,,,,,,,,,0,,,,-0.00245,,,,,,10.0175676,,,,