File: data/doubleLayers/dl_2-5/ppms/DD205_5/DD205_5_HYST_100OE_300K.DAT
[Header]
; VSM Data File (default extension .dat)
; Copyright (c) 2003-2013, Quantum Design, Inc. All rights reserved.
TITLE,
FILEOPENTIME,3737938331.96781,06/12/2018,4:13 am
BYAPP,VSM,1.0,1.0
INFO,DYNACOOL VSM Option Release 1.4.10 Build 1,APPNAME
INFO,Quantum Design Linear Motor Servo Controller,MOTOR_MODULE_NAME
INFO,3101-100 J0,MOTOR_HW_VERSION
INFO,MMC654,MOTOR_SERIAL_NUMBER
INFO,SRV No X-over 01.03.11,MOTOR_SOFTWARE_VERSION
INFO,Quantum Design VSM Detection Module,VSM_MODULE_NAME
INFO,3101-150 F0,VSM_HW_VERSION
INFO,VSM507,VSM_SERIAL_NUMBER
INFO,VSM No X-over 01.02.05 May 20 2008 13:51:47,VSM_SOFTWARE_VERSION
INFO,494,PREAMP_SERIAL_NUMBER
INFO,Quantum Design VSM Oven,OVEN_MODULE_NAME
INFO,3101-201 A1,OVEN_HW_VERSION
INFO,OVB210,OVEN_SERIAL_NUMBER
INFO,01.06.24,OVEN_SOFTWARE_VERSION
INFO,593,COIL_SERIAL_NUMBER
INFO,0,MOMENT_UNITS
INFO,CoFe2O4,SAMPLE_MATERIAL
INFO,,SAMPLE_COMMENT
INFO,,SAMPLE_MASS
INFO,,SAMPLE_VOLUME
INFO,,SAMPLE_MOLECULAR_WEIGHT
INFO,,SAMPLE_SIZE
INFO,,SAMPLE_SHAPE
DATATYPE,COMMENT,1
DATATYPE,TIME,2
STARTUPAXIS,X,2
STARTUPAXIS,Y1,5
[Data]
Comment,Time Stamp (sec),Temperature (K),Magnetic Field (Oe),Moment (emu),M. Std. Err. (emu),Transport Action,Averaging Time (sec),Frequency (Hz),Peak Amplitude (mm),Center Position (mm),Coil Signal' (mV),Coil Signal" (mV),Range (mV),M. Quad. Signal (emu),M. Raw' (emu),M. Raw" (emu),Min. Temperature (K),Max. Temperature (K),Min. Field (Oe),Max. Field (Oe),Mass (grams),Motor Lag (deg),Pressure (Torr),VSM Status (code),Motor Status (code),Measure Status (code),Measure Count,System Temp. (K),Temp. Status (code),Field Status (code),Chamber Status (code),Motor Current (amps),Motor Heatsink Temp. (C),Map 01,Map 02,Map 03,Map 04,Map 05,Map 06,Map 07,Map 08,Map 09,Map 10,Map 11,Map 12,Map 13,Map 14,Map 15,Map 16
,3737940229.687,300.278259277344,0.31454636156559,6.3870349034292E-7,2.86434591597578E-7,1,0.999253354069792,40.0298881530762,1.99758650909537,16.1700006574392,8.82669167456285E-6,-9.87802612218113E-6,0.25,-1.02818107126515E-6,6.3936021672672E-7,-1.02771673793833E-6,300.277069091797,300.277069091797,0.266154617071152,0.362938106060028,55.0203947256981,19.7088919875909,33.9202995300293,0,0,0,40,301.540710449219,1,4,1,2.14523315429687,44.9657897949219,,,,,,,,,,,,,,,,
,3737940320.696,300.429153442383,4142.0703125,4.1325635161201E-5,5.22859344627486E-7,1,0.999253354069792,40.0298881530762,1.99746133281594,16.1700006574392,0.000446835604481267,7.02225449134337E-5,0.25,-7.23648485557696E-7,4.13242642595273E-5,-6.96234830080611E-7,300.427795410156,300.427795410156,4119.62939453125,4164.51123046875,55.0508782379481,19.7078826772735,34.4635353088379,0,0,0,40,301.246063232422,1,6,1,2.16354370117187,43.9882698059082,,,,,,,,,,,,,,,,
,3737940404.573,300.467575073242,8336.5126953125,3.30966069932769E-5,4.64126674566792E-7,1,0.999253354069792,40.0298881530762,1.99747362043562,16.1700006574392,0.000357817137796329,5.64868093642042E-5,0.25,-5.5660296287987E-7,3.30954507015751E-5,-5.34666176894944E-7,300.467895507812,300.467895507812,8314.0322265625,8358.9931640625,54.8882995059481,19.704830738767,35.0415840148926,0,0,0,40,301.106567382812,1,6,1,2.16110229492187,43.9882698059082,,,,,,,,,,,,,,,,
,3737940488.4835,300.468872070313,12529.2548828125,1.99265563076471E-5,4.84885986093287E-7,1,0.999253354069792,40.0298881530762,1.99748143030573,16.1700006574392,0.000214996893825038,3.64972285468676E-5,0.25,-1.04303657620854E-7,1.99257072480713E-5,-9.11164528488604E-8,300.468597412109,300.468597412109,12504.2607421875,12554.2490234375,54.9344155885827,19.7065919855454,35.7329750061035,0,0,0,40,301.004638671875,1,6,1,2.16415405273438,43.9882698059082,,,,,,,,,,,,,,,,
,3737940572.431,300.459335327148,16728.9208984375,4.85454404260551E-6,5.26517458098393E-7,1,0.999253354069792,40.0298881530762,1.9974927405726,16.1700006574392,5.29799578070659E-5,5.45604779337575E-6,0.25,-3.44113051989268E-7,4.85454969485208E-6,-3.40888197908321E-7,300.458862304687,300.458862304687,16703.876953125,16753.96484375,55.0454068383135,19.7041512534443,36.435432434082,0,0,0,40,300.938385009766,1,6,1,2.16171264648438,43.9882698059082,,,,,,,,,,,,,,,,
,3737940656.3785,300.441009521484,20924.2998046875,-9.5158858969922E-6,6.23812465858334E-7,1,0.999253354069792,40.0298881530762,1.99754370955821,16.1700006574392,-0.000102693987116303,-1.7318308501449E-5,0.25,6.01348881415029E-8,-9.51549731715216E-6,5.38463486135339E-8,300.441986083984,300.441986083984,20899.240234375,20949.359375,55.016486583102,19.7050895466469,36.634593963623,0,0,0,40,300.884307861328,1,6,1,2.1612548828125,43.9882698059082,,,,,,,,,,,,,,,,
,3737940740.3115,300.419830322266,25124.72265625,-2.4152790086426E-5,6.78000284028067E-7,1,0.999253354069792,40.0298881530762,1.99767453988248,16.1700006574392,-0.000259619086659894,-4.99575764189877E-5,0.25,-4.03774731034545E-7,-2.41514554689195E-5,-4.1969897999196E-7,300.420135498047,300.420135498047,25099.673828125,25149.771484375,54.9289441889481,19.7008729726346,36.7762718200684,0,0,0,40,300.850250244141,1,6,1,2.16079711914062,43.9882698059082,,,,,,,,,,,,,,,,
,3737940824.2715,300.395477294922,29334.478515625,-3.99622432541831E-5,5.58023670402581E-7,1,0.999253354069792,40.0298881530762,1.99778784816167,16.1700006574392,-0.000431698834547368,-7.05586808836933E-5,0.25,4.54574738243576E-7,-3.99608117176436E-5,4.28198702550129E-7,300.395477294922,300.395477294922,29311.837890625,29357.119140625,55.0078886693904,19.7017538818492,36.8388786315918,0,0,0,40,300.812805175781,1,6,1,2.15896606445313,44.4770278930664,,,,,,,,,,,,,,,,
,3737940908.1745,300.373001098633,33548.24609375,-5.60410689182343E-5,1.08126696866369E-6,1,0.999253354069792,40.0298881530762,1.99774849253358,16.1700006574392,-0.000606047120472836,-9.51498643425994E-5,0.25,9.89577119281057E-7,-5.60393398640547E-5,9.5260467284166E-7,300.373046875,300.373046875,33523.1640625,33573.328125,55.0305558964481,19.7003967758369,36.9773216247559,0,0,0,40,300.786865234375,1,6,1,2.159423828125,44.4770278930664,,,,,,,,,,,,,,,,
,3737940992.1255,300.35090637207,37760.029296875,-7.05114914737522E-5,1.20217967980328E-6,1,0.999253354069792,40.0298881530762,1.99777562078743,16.1700006574392,-0.000760643090774585,-0.000130583032489776,0.25,2.37485476673343E-7,-7.05087098281751E-5,1.91048695711687E-7,300.350921630859,300.350921630859,37734.91796875,37785.140625,55.0907412924289,19.6985330756307,37.1343803405762,0,0,0,40,300.764373779297,1,6,1,2.156982421875,43.9882698059082,,,,,,,,,,,,,,,,
,3737941076.061,300.328979492188,41973.30078125,-8.56952610300483E-5,9.50711647672951E-7,1,0.999253354069792,40.0298881530762,1.99778296050205,16.1700006574392,-0.000926081638406123,-0.000149341834636037,0.25,1.15687575169496E-6,-8.56925215080504E-5,1.10045314941397E-6,300.3291015625,300.3291015625,41945.6640625,42000.9375,54.9899112134481,19.6994962939463,37.3046646118164,0,0,0,40,300.738739013672,1,6,1,2.16079711914062,44.4770278930664,,,,,,,,,,,,,,,,
,3737941160.0015,300.308212280273,46189.72265625,-0.00010158695802259,7.96165629459586E-7,1,0.999253354069792,40.0298881530762,1.99785632267355,16.1700006574392,-0.00109758294858708,-0.000178609542026849,0.25,1.22603012522987E-6,-0.000101583693220406,1.15921079242754E-6,300.308380126953,300.308380126953,46167.12890625,46212.31640625,55.0383721816404,19.7002608791712,37.4374389648438,0,0,0,40,300.725982666016,1,6,1,2.16171264648438,43.9882698059082,,,,,,,,,,,,,,,,
,3737941243.9655,300.28694152832,50403.427734375,-0.000117450548679073,1.1066239459694E-6,1,0.999253354069792,40.0298881530762,1.99778039728075,16.1700006574392,-0.00127044943302154,-0.000197841981300629,0.25,2.21987843610098E-6,-0.000117447393741138,2.14266436225246E-6,300.286468505859,300.286468505859,50378.28125,50428.57421875,55.2509751388712,19.7010151366915,37.4568672180176,0,0,0,40,300.713745117188,1,6,1,2.16354370117187,44.4770278930664,,,,,,,,,,,,,,,,
,3737941327.865,300.265197753906,54633.5234375,-0.000131578265873523,1.81999748909801E-6,1,0.999253354069792,40.0298881530762,1.99773860261795,16.1700006574392,-0.0014212670109805,-0.000232901761565696,0.25,1.44180611279076E-6,-0.000131574151461744,1.35542634702342E-6,300.264739990234,300.264739990234,54608.3203125,54658.7265625,55.0086702979097,19.698864161452,37.4042434692383,0,0,0,40,300.704284667969,1,6,1,2.16156005859375,44.4770278930664,,,,,,,,,,,,,,,,
,3737941411.7855,300.247863769531,58875.931640625,-0.000148112561436993,1.70698312948379E-6,1,0.999253354069792,40.0298881530762,1.99774868615735,16.1799993366003,-0.0016009038334041,-0.000256289849196578,0.25,2.16830053512943E-6,-0.000148108384504056,2.07113992229412E-6,300.247955322266,300.247955322266,58850.71875,58901.14453125,54.9813132997366,19.6972172553181,37.3575592041016,0,0,0,40,300.686920166016,1,6,1,2.16156005859375,44.4770278930664,,,,,,,,,,,,,,,,
,3737941495.7725,300.232696533203,63123.455078125,-0.000164121577012652,1.81534049631507E-6,1,0.999253354069792,40.0298881530762,1.99781986622175,16.1700006574392,-0.00177420819358366,-0.000282821297719058,0.25,2.51199654284258E-6,-0.000164117115128401,2.40443731542266E-6,300.233215332031,300.233215332031,63098.18359375,63148.7265625,55.1266962043135,19.6985780804421,37.3321914672852,0,0,0,40,300.678283691406,1,6,1,2.15682983398438,44.4770278930664,,,,,,,,,,,,,,,,
,3737941579.667,300.217559814453,67366.20703125,-0.000180049021923321,1.88004093902054E-6,1,0.999253354069792,40.0298881530762,1.99804253864995,16.1700006574392,-0.00194627286158947,-0.00031214888173149,0.25,2.58430206944416E-6,-0.000180044118820131,2.46642988557177E-6,300.217559814453,300.217559814453,67340.9453125,67391.46875,55.1704674013905,19.69489229526,37.2865829467773,0,0,0,40,300.663360595703,1,6,1,2.15927124023438,45.4545478820801,,,,,,,,,,,,,,,,
,3737941663.5875,300.20344543457,71610.703125,-0.000195020630348433,1.77746666007258E-6,1,0.999253354069792,40.0298881530762,1.99791016694289,16.1700006574392,-0.00210777942255518,-0.000339226709688043,0.25,2.6930693783108E-6,-0.000195015356080599,2.56553033636072E-6,300.203552246094,300.203552246094,71587.875,71633.53125,54.965680729352,19.6976872449371,37.2614860534668,0,0,0,40,300.647491455078,1,6,1,2.16629028320313,44.4770278930664,,,,,,,,,,,,,,,,
,3737941747.561,300.19075012207,75855.87890625,-0.000213059767634961,2.20962621495832E-6,1,0.999253354069792,40.0298881530762,1.99790112867379,16.1700006574392,-0.00230316299260219,-0.000368172825698439,0.25,3.16745328048689E-6,-0.000213054257917558,3.02825394645521E-6,300.19140625,300.19140625,75830.5859375,75881.171875,55.0149233260635,19.6968922225948,37.2226257324219,0,0,0,40,300.638366699219,1,6,1,2.1600341796875,44.4770278930664,,,,,,,,,,,,,,,,
,3737941831.5205,300.180465698242,80103.9609375,-0.000228340871679592,2.05854294590023E-6,1,0.999253354069792,40.0298881530762,1.99795475633148,16.1700006574392,-0.00246811591217696,-0.000396295707017813,0.25,3.23620161524829E-6,-0.000228334957176473,3.08718231898573E-6,300.181365966797,300.181365966797,80078.6796875,80129.2421875,54.7851245414096,19.7015831572758,37.1848449707031,0,0,0,40,300.626281738281,1,6,1,2.16079711914062,44.4770278930664,,,,,,,,,,,,,,,,
,3737941915.422,300.168045043945,84345.828125,-0.000243717853797049,2.09732437264929E-6,1,0.999253354069792,40.0298881530762,1.99792261861039,16.1799993366003,-0.00263323295719744,-0.000428985700997713,0.25,2.89666543736735E-6,-0.000243711296155408,2.73779906703712E-6,300.168029785156,300.168029785156,84320.6484375,84371.0078125,54.9273809319096,19.6945056628085,37.1600189208984,0,0,0,40,300.618316650391,1,6,1,2.15713500976562,44.4770278930664,,,,,,,,,,,,,,,,
,3737941999.3465,300.15885925293,88591.01953125,-0.000260032710760995,2.34501238729558E-6,1,0.999253354069792,40.0298881530762,1.99793678529966,16.1700006574392,-0.0028103948509486,-0.000452743261768398,0.25,3.55066166951297E-6,-0.000260026111028258,3.38132812510606E-6,300.158233642578,300.158233642578,88568.2578125,88613.78125,54.9172197611597,19.6987138982162,37.158130645752,0,0,0,40,300.607116699219,1,6,1,2.16018676757813,44.9657897949219,,,,,,,,,,,,,,,,
,3737942093.295,300.147262573242,87291.4140625,-0.000255389144924133,1.69970130950685E-6,1,0.999253354069792,40.0298881530762,1.99808959544453,16.1700006574392,-0.00275920740313878,-0.000451555430966799,0.25,2.85069912108262E-6,-0.000255382347441323,2.68434812136893E-6,300.147277832031,300.147277832031,87266.5,87316.328125,54.945358387852,19.6990875730151,37.1473350524902,0,0,0,40,300.598205566406,1,6,1,2.16201782226562,44.4770278930664,,,,,,,,,,,,,,,,
,3737942177.2555,300.138931274414,83108.5625,-0.000239111010086104,1.73667222689468E-6,1,0.999253354069792,40.0298881530762,1.99803918289942,16.1799993366003,-0.00258397388677575,-0.000418791422955157,0.25,3.03759052820979E-6,-0.00023910494220665,2.88165546014243E-6,300.138580322266,300.138580322266,83081.1640625,83135.9609375,54.9500481589674,19.6963173620753,37.1446342468262,0,0,0,40,300.585571289063,1,6,1,2.16064453125,44.4770278930664,,,,,,,,,,,,,,,,
,3737942261.1915,300.131362915039,78928.73046875,-0.000223657591287715,1.90508230722386E-6,1,0.999253354069792,40.0298881530762,1.99816470697299,16.1700006574392,-0.00241732382240892,-0.000390585363866474,0.25,2.94934708161008E-6,-0.000223652032978265,2.80332470203424E-6,300.131408691406,300.131408691406,78906.234375,78951.2265625,54.9086218474481,19.6987448776578,37.131950378418,0,0,0,40,300.579071044922,1,6,1,2.15805053710938,44.4770278930664,,,,,,,,,,,,,,,,
,3737942345.082,300.120986938477,74745.73828125,-0.000206906891564131,1.98420957186222E-6,1,0.999253354069792,40.0298881530762,1.99805782786297,16.1700006574392,-0.00223748661487481,-0.00035377860815585,0.25,3.42749068745111E-6,-0.000206902269863064,3.29223182473586E-6,300.120941162109,300.120941162109,74720.84375,74770.6328125,54.8789199637173,19.6949404999224,37.1265563964844,0,0,0,40,300.569427490234,1,6,1,2.15896606445313,44.4770278930664,,,,,,,,,,,,,,,,
,3737942429.0215,300.114624023438,70565.23828125,-0.000191612582669756,2.08381893275844E-6,1,0.999253354069792,40.0298881530762,1.9982001981602,16.1700006574392,-0.00207135285571746,-0.000332686807004858,0.25,2.70717983956019E-6,-0.000191608030086551,2.5817990374526E-6,300.114807128906,300.114807128906,70540.3515625,70590.125,54.9461400163712,19.6924191351503,37.1060447692871,0,0,0,40,300.559967041016,1,6,1,2.15682983398438,44.4770278930664,,,,,,,,,,,,,,,,
,3737942513.012,300.107269287109,66378.046875,-0.000175719030129243,1.38385798897221E-6,1,0.999253354069792,40.0298881530762,1.99808313979877,16.1700006574392,-0.00189989314082858,-0.00030246704491959,0.25,2.7245916556109E-6,-0.000175715049467617,2.60947905683276E-6,300.107574462891,300.107574462891,66350.6171875,66405.4765625,55.0508782379481,19.693651369714,37.0758209228516,0,0,0,40,300.561431884766,1,6,1,2.1563720703125,44.9657897949219,,,,,,,,,,,,,,,,
,3737942596.886,300.099639892578,62197.759765625,-0.000160500836729498,2.05931836392767E-6,1,0.999253354069792,40.0298881530762,1.99810032881426,16.1700006574392,-0.00173394229101692,-0.000284408532785997,0.25,1.73436064146463E-6,-0.000160496741136156,1.62913024971336E-6,300.099670410156,300.099670410156,62175.38671875,62220.1328125,54.986003070852,19.694653116883,37.0396575927734,0,0,0,40,300.546508789063,1,6,1,2.16033935546875,44.4770278930664,,,,,,,,,,,,,,,,
,3737942680.831,300.092956542969,58014.607421875,-0.000145151629375539,1.58951644086597E-6,1,0.999253354069792,40.0298881530762,1.99821946385751,16.1700006574392,-0.00156827847847289,-0.000256827668579296,0.25,1.60537602175268E-6,-0.000145147975742152,1.51010810206912E-6,300.09326171875,300.09326171875,57989.7265625,58039.48828125,54.9344155885827,19.6975528449849,37.0269737243652,0,0,0,40,300.545806884766,1,6,1,2.16598510742187,44.9657897949219,,,,,,,,,,,,,,,,
,3737942764.7795,300.087585449219,53834.98046875,-0.00012907575436243,1.63702458188085E-6,1,0.999253354069792,40.0298881530762,1.99820197568996,16.1799993366003,-0.00139704184354364,-0.000214306064383665,0.25,2.7329516703183E-6,-0.000129073379972071,2.64810544762932E-6,300.087860107422,300.087860107422,53810.05078125,53859.91015625,54.972715386025,19.6957464307127,36.9991798400879,0,0,0,40,300.538482666016,1,6,1,2.16354370117187,44.9657897949219,,,,,,,,,,,,,,,,
,3737942848.743,300.081832885742,49648.001953125,-0.000113819307783679,1.35596707878905E-6,1,0.999253354069792,40.0298881530762,1.99813389780544,16.1700006574392,-0.00123001573299794,-0.000199585922929896,0.25,1.42545653998118E-6,-0.000113816584629315,1.35059457835472E-6,300.081909179687,300.081909179687,49625.5625,49670.44140625,55.1845367147366,19.6969262950273,36.9905433654785,0,0,0,40,300.534881591797,1,6,1,2.1588134765625,44.9657897949219,,,,,,,,,,,,,,,,
,3737942932.6555,300.07600402832,45469.865234375,-9.72142637194488E-5,9.64846347069653E-7,1,0.999253354069792,40.0298881530762,1.9982314318971,16.1700006574392,-0.00105150801455985,-0.00016539609811789,0.25,1.68867249159882E-6,-9.72122627598748E-5,1.62465302926069E-6,300.076721191406,300.076721191406,45444.91796875,45494.8125,55.1352941180251,19.6967873843307,36.9684143066406,0,0,0,40,300.528747558594,1,6,1,2.16552734375,44.9657897949219,,,,,,,,,,,,,,,,
,3737943016.59,300.072235107422,41285.326171875,-8.23356018949563E-5,1.11019788374384E-6,1,0.999253354069792,40.0298881530762,1.99819351967395,16.1700006574392,-0.000888761481237071,-0.000150340050209488,0.25,4.78776586259326E-7,-8.23332875589818E-5,4.24532684006421E-7,300.071472167969,300.071472167969,41260.36328125,41310.2890625,55.2611363096212,19.6986288041259,36.9533004760742,0,0,0,40,300.524475097656,1,6,1,2.1630859375,44.9657897949219,,,,,,,,,,,,,,,,
,3737943100.58,300.066619873047,37102.861328125,-6.74019001781631E-5,1.19362050186349E-6,1,0.999253354069792,40.0298881530762,1.99812525937474,16.1799993366003,-0.000727842703314308,-0.000121328046176678,0.25,5.53340721337899E-7,-6.74001216517202E-5,5.08887267948066E-7,300.066467285156,300.066467285156,37075.44140625,37130.28125,55.1032473487366,19.6977556440238,36.9225387573242,0,0,0,40,300.517395019531,1,6,1,2.15850830078125,44.9657897949219,,,,,,,,,,,,,,,,
,3737943184.441,300.063812255859,32925.296875,-5.16613046484921E-5,9.30051313155862E-7,1,0.999253354069792,40.0298881530762,1.99823646526112,16.1799993366003,-0.00055929964544312,-8.49883962774035E-5,0.25,1.16698187482358E-6,-5.16604341489383E-5,1.13285431882028E-6,300.064361572266,300.064361572266,32900.40625,32950.1875,55.2267446547751,19.6973020825044,36.8955497741699,0,0,0,40,300.517486572266,1,6,1,2.1588134765625,44.4770278930664,,,,,,,,,,,,,,,,
,3737943268.3945,300.059707641602,28740.23046875,-3.67448970702042E-5,9.78523737836014E-7,1,0.999253354069792,40.0298881530762,1.9981927221679,16.1700006574392,-0.000398514322741273,-5.63823581626667E-5,0.25,1.2070891145553E-6,-3.67445307330078E-5,1.18278117091559E-6,300.060180664063,300.060180664063,28715.369140625,28765.091796875,55.0993392061404,19.6960701391193,36.8669471740723,0,0,0,40,300.512817382812,1,6,1,2.15682983398438,44.9657897949219,,,,,,,,,,,,,,,,
,3737943352.335,300.055450439453,24558.50390625,-2.12105945650348E-5,7.31888139210513E-7,1,0.999253354069792,40.0298881530762,1.99837413277167,16.1700006574392,-0.000228738727367919,-4.00811065911382E-5,0.25,-1.64708331764048E-9,-2.12099238267615E-5,-1.56690097688695E-8,300.055694580078,300.055694580078,24536.15625,24580.8515625,55.2572281670251,19.6997789083737,36.842658996582,0,0,0,40,300.507904052734,1,6,1,2.16201782226562,43.0107536315918,,,,,,,,,,,,,,,,
,3737943436.263,300.051788330078,20376.3935546875,-6.83396969306664E-6,6.43329865033364E-7,1,0.999253354069792,40.0298881530762,1.99830744345911,16.1700006574392,-7.33836304853142E-5,-1.46992104523026E-5,0.25,-1.66109938652539E-7,-6.83364455158949E-6,-1.7062643850741E-7,300.051361083984,300.051361083984,20351.4609375,20401.326171875,55.2087671988328,19.700481694275,36.8367195129395,0,0,0,40,300.507965087891,1,6,1,2.16384887695313,43.9882698059082,,,,,,,,,,,,,,,,
,3737943520.2235,300.048873901367,16194.2670898438,8.58898418370713E-6,6.91447762156237E-7,1,0.999253354069792,40.0298881530762,1.99817018937553,16.1700006574392,9.30508013936333E-5,1.37470066666629E-5,0.25,-2.29495395508544E-7,8.58886610100915E-6,-2.23800529642871E-7,300.048797607422,300.048797607422,16171.8447265625,16216.689453125,55.0094519264289,19.6976120967712,36.8186416625977,0,0,0,40,300.507232666016,1,6,1,2.16400146484375,44.4770278930664,,,,,,,,,,,,,,,,
,3737943604.1765,300.045379638672,12010.435546875,2.36510530919743E-5,5.68952277167153E-7,1,0.999253354069792,40.0298881530762,1.99819409002719,16.1700006574392,0.000256386078767762,3.69765443934653E-5,0.25,-7.13414290282101E-7,2.36507840301539E-5,-6.97717752050798E-7,300.044616699219,300.044616699219,11990.4306640625,12030.4404296875,55.2126753414289,19.6993944642682,36.8013687133789,0,0,0,40,300.499481201172,1,6,1,2.15667724609375,44.4770278930664,,,,,,,,,,,,,,,,
,3737943688.102,300.042053222656,7821.05932617187,3.60384221272529E-5,5.53885464993115E-7,1,0.999253354069792,40.0298881530762,1.99830725364445,16.1700006574392,0.000390709794114198,5.62375933526773E-5,0.25,-1.09716240546887E-6,3.60380219751304E-5,-1.07322687616039E-6,300.04248046875,300.04248046875,7793.568359375,7848.55029296875,55.2079855703135,19.6975157463139,36.7873344421387,0,0,0,40,300.501770019531,1,6,1,2.15896606445313,44.9657897949219,,,,,,,,,,,,,,,,
,3737943772.0865,300.041030883789,3626.10595703125,4.34043170221743E-5,4.46741899746263E-7,1,0.999253354069792,40.0298881530762,1.99814953583134,16.1700006574392,0.0004702960539598,6.90722459568627E-5,0.25,-1.19666828950831E-6,4.34037527285684E-5,-1.16782569913053E-6,300.040588378906,300.040588378906,3598.62915039063,3653.58276367188,55.1657776302751,19.6997810846332,36.7622375488281,0,0,0,40,300.494476318359,1,6,1,2.159423828125,44.9657897949219,,,,,,,,,,,,,,,,
,3737943861.964,300.037750244141,-867.8955078125,-3.25914263175901E-5,4.83355023771854E-7,1,0.999253354069792,40.0298881530762,1.9982906210273,16.1700006574392,-0.000349651344323796,-7.18982886680075E-5,0.25,-9.58823944815245E-7,-3.2589772755873E-5,-9.80431095939261E-7,300.038604736328,300.038604736328,-890.219299316406,-845.571716308594,55.1048106057751,19.7005237027065,36.7603492736816,0,0,0,40,300.498229980469,1,6,1,2.15774536132813,43.9882698059082,,,,,,,,,,,,,,,,
,3737943948.9375,300.034149169922,-5213.6123046875,-4.21488595142121E-5,4.51931299512207E-7,1,0.999253354069792,40.0298881530762,1.99816187562716,16.1700006574392,-0.000452445048090024,-9.13433562803149E-5,0.25,-1.08853710081971E-6,-4.21468287588505E-5,-1.11646949808241E-6,300.034332275391,300.034332275391,-5238.5439453125,-5188.6806640625,55.0930861779866,19.7017021420582,36.752254486084,0,0,0,40,300.49267578125,1,6,1,2.16018676757813,45.4545478820801,,,,,,,,,,,,,,,,
,3737944032.857,300.032791137695,-9411.63818359375,-3.27812710323384E-5,5.01131791802366E-7,1,0.999253354069792,40.0298881530762,1.99818396372988,16.1700006574392,-0.000351939011189267,-7.07793194959719E-5,0.25,-8.22168128278032E-7,-3.27797110815432E-5,-8.43878669150264E-7,300.031799316406,300.031799316406,-9439.1884765625,-9384.087890625,55.0688556938904,19.7005912664331,36.7317428588867,0,0,0,40,300.494232177734,1,6,1,2.15652465820313,44.4770278930664,,,,,,,,,,,,,,,,
,3737944116.743,300.030258178711,-13604.1455078125,-1.87966759551531E-5,6.23907927388261E-7,1,0.999253354069792,40.0298881530762,1.99822481767982,16.1799993366003,-0.000199629773245364,-5.30028161348457E-5,0.25,-1.62294866015694E-6,-1.87950212390156E-5,-1.63535281221787E-6,300.030426025391,300.030426025391,-13629.1142578125,-13579.1767578125,55.1548348310058,19.7009324435538,36.7352523803711,0,0,0,40,300.489868164063,1,6,1,2.16323852539062,44.4770278930664,,,,,,,,,,,,,,,,
,3737944200.7145,300.030380249023,-17800.99609375,-2.99667130376277E-6,4.49097182671407E-7,1,0.999253354069792,40.0298881530762,1.99823593682985,16.1700006574392,-2.8241799506225E-5,-2.89154688339635E-5,0.25,-2.15656600435616E-6,-2.99515131500274E-6,-2.15848355972799E-6,300.029388427734,300.029388427734,-17828.51953125,-17773.47265625,55.0993392061404,19.7031509770266,36.7387619018555,0,0,0,40,300.485900878906,1,6,1,2.15988159179687,44.4770278930664,,,,,,,,,,,,,,,,
,3737944284.621,300.027328491211,-21998.2548828125,1.09995219210618E-5,6.3006973951428E-7,1,0.999253354069792,40.0298881530762,1.99825829796697,16.1700006574392,0.00012223019368202,1.39624995179889E-7,0.25,-1.91358533669023E-6,1.10004508986737E-5,-1.90625050553697E-6,300.027130126953,300.027130126953,-22023.33203125,-21973.177734375,55.0055437838327,19.7005614759351,36.7217597961426,0,0,0,40,300.487518310547,1,6,1,2.16506958007813,44.4770278930664,,,,,,,,,,,,,,,,
,3737944368.5905,300.025726318359,-26198.763671875,2.66780693712084E-5,6.92302064590636E-7,1,0.999253354069792,40.0298881530762,1.99819891783229,16.1799993366003,0.000292333132770441,2.38258755087824E-5,0.25,-2.46307878660582E-6,2.66788831340647E-5,-2.4453711200625E-6,300.025360107422,300.025360107422,-26223.875,-26173.65234375,55.1126268909674,19.7019408428817,36.6945037841797,0,0,0,40,300.485931396484,1,6,1,2.15988159179687,44.4770278930664,,,,,,,,,,,,,,,,
,3737944452.495,300.023345947266,-30408.8857421875,4.21547863792025E-5,8.97116489535121E-7,1,0.999253354069792,40.0298881530762,1.9983206017081,16.1700006574392,0.00045834919550301,5.82135286255383E-5,0.25,-1.98512457619164E-6,4.2154816480815E-5,-1.9572273019168E-6,300.023132324219,300.023132324219,-30433.96484375,-30383.806640625,55.1063738628135,19.7014339342616,36.696662902832,0,0,0,40,300.481750488281,1,6,1,2.15927124023438,44.9657897949219,,,,,,,,,,,,,,,,
,3737944536.428,300.022445678711,-34623.685546875,5.76071234179512E-5,9.2738143393479E-7,1,0.999253354069792,40.0298881530762,1.99826935145415,16.1700006574392,0.000626169055769119,8.05681213050658E-5,0.25,-2.61839050732001E-6,5.76071055688875E-5,-2.58030510200935E-6,300.022155761719,300.022155761719,-34648.80859375,-34598.5625,55.1478001743328,19.7032816682428,36.6893768310547,0,0,0,40,300.480682373047,1,6,1,2.15774536132813,44.4770278930664,,,,,,,,,,,,,,,,
,3737944620.3485,300.022064208984,-38831.244140625,7.15376218701943E-5,8.82494145768975E-7,1,0.999253354069792,40.0298881530762,1.99830146968388,16.1700006574392,0.000777381943530081,0.000101300758935181,0.25,-3.1357768113388E-6,7.15375262943311E-5,-3.0885296462397E-6,300.021728515625,300.021728515625,-38858.796875,-38803.69140625,55.0555680090635,19.7048089181361,36.6761512756348,0,0,0,40,300.476867675781,1,6,1,2.16445922851562,44.4770278930664,,,,,,,,,,,,,,,,
,3737944704.3055,300.018814086914,-43043.865234375,8.80181740898608E-5,1.12529044719554E-6,1,0.999253354069792,40.0298881530762,1.9981976705016,16.1700006574392,0.000956071624895378,0.000126649536229369,0.25,-3.67102314279025E-6,8.80179457682133E-5,-3.6129526437889E-6,300.019073486328,300.019073486328,-43068.96484375,-43018.765625,55.229871168852,19.701790267845,36.6707534790039,0,0,0,40,300.479034423828,1,6,1,2.15774536132813,43.9882698059082,,,,,,,,,,,,,,,,
,3737944788.2395,300.018402099609,-47256.125,0.000105347609181551,1.08175109063162E-6,1,0.999253354069792,40.0298881530762,1.99837602263821,16.1799993366003,0.00114222343396359,0.000164051833289686,0.25,-3.23889609455784E-6,0.00010534658090214,-3.16949513881127E-6,300.018646240234,300.018646240234,-47283.76171875,-47228.48828125,54.7038351754096,19.7030123316131,36.644847869873,0,0,0,40,300.477355957031,1,6,1,2.1649169921875,44.4770278930664,,,,,,,,,,,,,,,,
,3737944872.1745,300.018310546875,-51469.041015625,0.000120244566314438,1.40263038164614E-6,1,0.999253354069792,40.0298881530762,1.99822220876183,16.1700006574392,0.0013041496096871,0.000184367853710211,0.25,-3.96282576143066E-6,0.000120243572393685,-3.88368198024613E-6,300.018035888672,300.018035888672,-51494.09765625,-51443.984375,55.0329007820058,19.7024877420042,36.615161895752,0,0,0,40,300.473480224609,1,6,1,2.159423828125,44.4770278930664,,,,,,,,,,,,,,,,
,3737944956.1025,300.017013549805,-55708.794921875,0.000134592020317346,1.26655147380423E-6,1,0.999253354069792,40.0298881530762,1.99837284098096,16.1799993366003,0.00145878364615227,0.000212550162786311,0.25,-3.86354989689117E-6,0.000134590543334298,-3.77506984461509E-6,300.017028808594,300.017028808594,-55736.5546875,-55681.03515625,54.9383237311789,19.7046532865912,36.5987014770508,0,0,0,40,300.471862792969,1,6,1,2.1636962890625,44.9657897949219,,,,,,,,,,,,,,,,
,3737945040.036,300.016143798828,-59952.3515625,0.000150500854491713,1.43604845399471E-6,1,0.999253354069792,40.0298881530762,1.99827840818968,16.1700006574392,0.00163109327717478,0.000237925996153943,0.25,-4.29573548668834E-6,0.000150499197597012,-4.19689991158245E-6,300.015686035156,300.015686035156,-59977.6171875,-59927.0859375,55.0219579827366,19.7047062715006,36.589527130127,0,0,0,40,300.470245361328,1,6,1,2.15927124023438,44.4770278930664,,,,,,,,,,,,,,,,
,3737945123.991,300.014007568359,-64194.185546875,0.000166871164307168,1.293139214644E-6,1,0.999253354069792,40.0298881530762,1.99824634567871,16.1700006574392,0.00180660838441499,0.000274508169535811,0.25,-3.77004342779323E-6,0.000166868695970341,-3.66060091097498E-6,300.014068603516,300.014068603516,-64219.4375,-64168.93359375,54.9641174723135,19.7043493233516,36.5798110961914,0,0,0,40,300.473083496094,1,6,1,2.15805053710938,44.4770278930664,,,,,,,,,,,,,,,,
,3737945207.979,300.015487670898,-68443.19921875,0.000184154866960297,8.62896781916486E-7,1,0.999253354069792,40.0298881530762,1.99846999365394,16.1799993366003,0.00199370222621653,0.000304331344905591,0.25,-4.03441260521873E-6,0.000184152059434851,-3.91376704032574E-6,300.015960693359,300.015960693359,-68470.9765625,-68415.421875,54.9781867856597,19.7047774905502,36.5617294311523,0,0,0,40,300.469268798828,1,6,1,2.16415405273438,44.9657897949219,,,,,,,,,,,,,,,,
,3737945291.843,300.012557983398,-72682.0078125,0.000199481741300023,1.87348045975586E-6,1,0.999253354069792,40.0298881530762,1.99829487226806,16.1799993366003,0.00215985789011523,0.000327331654954474,0.25,-4.58344431108065E-6,0.000199478869233958,-4.45289033238307E-6,300.012634277344,300.012634277344,-72707.2578125,-72656.7578125,54.7210310028327,19.7038346845184,36.5563316345215,0,0,0,40,300.469268798828,1,6,1,2.16598510742187,44.9657897949219,,,,,,,,,,,,,,,,
,3737945375.796,300.012817382812,-76927.8203125,0.000214966645830244,1.77681007544527E-6,1,0.999253354069792,40.0298881530762,1.99841319058549,16.1799993366003,0.00232797401546079,0.000350907410359099,0.25,-5.1109463715567E-6,0.000214963671038285,-4.97040571290287E-6,300.012908935547,300.012908935547,-76953.046875,-76902.59375,55.0422803242366,19.7005541749139,36.5560607910156,0,0,0,40,300.46875,1,6,1,2.16354370117187,46.4320640563965,,,,,,,,,,,,,,,,
,3737945459.732,300.011520385742,-81168.8671875,0.000231646025633842,1.35813248844699E-6,1,0.999253354069792,40.0298881530762,1.99841746855537,16.1799993366003,0.00250683354113501,0.000388267842317316,0.25,-4.5678044200109E-6,0.000231642228186112,-4.41655184551999E-6,300.011962890625,300.011962890625,-81194.1171875,-81143.6171875,54.955519558602,19.7032892679825,36.5617294311523,0,0,0,40,300.466735839844,1,6,1,2.159423828125,44.9657897949219,,,,,,,,,,,,,,,,
,3737945543.645,300.010589599609,-85414.9375,0.000248612625159506,1.55700079054689E-6,1,0.999253354069792,40.0298881530762,1.99845630732031,16.1700006574392,0.00268896207125735,0.000425455597664435,0.25,-4.09161402652445E-6,0.0002486080416378,-3.9294858746266E-6,300.010406494141,300.010406494141,-85440.2265625,-85389.6484375,54.9062769618904,19.7056077845049,36.5393295288086,0,0,0,40,300.465270996094,1,6,1,2.15896606445313,44.9657897949219,,,,,,,,,,,,,,,,
,3737945627.607,300.012054443359,-89658.08203125,0.000264794386536117,8.43743546425115E-7,1,0.999253354069792,40.0298881530762,1.99857797324042,16.1799993366003,0.00286257074149045,0.000462177957593099,0.25,-3.52290783690297E-6,0.000264788961493362,-3.3504446260906E-6,300.011779785156,300.011779785156,-89685.84375,-89630.3203125,54.5811194978904,19.704298640273,36.5177421569824,0,0,0,40,300.465759277344,1,6,1,2.15576171875,44.9657897949219,,,,,,,,,,,,,,,,
,3737945720.518,300.009490966797,-86236.046875,0.00024999673726479,2.48248581864312E-6,1,0.999253354069792,40.0298881530762,1.99833126735591,16.1700006574392,0.00270587705124301,0.000415777954752764,0.25,-5.22903957775507E-6,0.000249992866512861,-5.06601087349913E-6,300.009368896484,300.009368896484,-86260.8984375,-86211.1953125,55.1204431761597,19.7037477850874,36.512882232666,0,0,0,40,300.464691162109,1,6,1,2.15713500976562,44.4770278930664,,,,,,,,,,,,,,,,
,3737945804.4995,300.009094238281,-82050.39453125,0.000234073316145717,2.33330193463378E-6,1,0.999253354069792,40.0298881530762,1.99827625775614,16.1799993366003,0.00253387730162705,0.000386908771674336,0.25,-5.11649380375414E-6,0.000234069827729241,-4.96367565150759E-6,300.009063720703,300.009063720703,-82077.875,-82022.9140625,54.9516114160058,19.7032161993576,36.5015487670898,0,0,0,40,300.463256835937,1,6,1,2.16293334960938,45.4545478820801,,,,,,,,,,,,,,,,
,3737945888.397,300.00959777832,-77871.11328125,0.000218433741030803,1.74985770216761E-6,1,0.999253354069792,40.0298881530762,1.99827970350068,16.1799993366003,0.00236564688743704,0.000354968546276455,0.25,-5.33947912255309E-6,0.00021843084038162,-5.19670090867224E-6,300.009704589844,300.009704589844,-77898.4765625,-77843.75,54.843746680352,19.7044551637173,36.4883270263672,0,0,0,40,300.464721679687,1,6,1,2.16552734375,43.9882698059082,,,,,,,,,,,,,,,,
,3737945972.34,300.006149291992,-73692.7421875,0.000202723465228528,1.82863912221488E-6,1,0.999253354069792,40.0298881530762,1.998375469975,16.1799993366003,0.0021939689284189,0.00033878986336942,0.25,-4.08985353700149E-6,0.000202720222642169,-3.95722639129223E-6,300.005828857422,300.005828857422,-73715.140625,-73670.34375,54.9508297874866,19.7035662007091,36.4707832336426,0,0,0,40,300.466430664063,1,6,1,2.15744018554687,44.4770278930664,,,,,,,,,,,,,,,,
,3737946056.258,300.0078125,-69511.75,0.000187160325059277,1.98764313912001E-6,1,0.999253354069792,40.0298881530762,1.99832891459799,16.1799993366003,0.00202665052300111,0.000306160289105622,0.25,-4.38927657877533E-6,0.000187157713034716,-4.26668398161328E-6,300.007659912109,300.007659912109,-69536.5859375,-69486.9140625,54.8773567066789,19.704167671056,36.4753723144531,0,0,0,40,300.467193603516,1,6,1,2.16537475585938,44.4770278930664,,,,,,,,,,,,,,,,
,3737946140.242,300.006378173828,-65327.1640625,0.000171393015734127,1.23793324323727E-6,1,0.999253354069792,40.0298881530762,1.99829208633085,16.1799993366003,0.00185774578684746,0.000269726830150608,0.25,-5.00591135802043E-6,0.000171391270725572,-4.893499321834E-6,300.005493164063,300.005493164063,-65352.01171875,-65302.31640625,55.0203947256981,19.7039867317258,36.4656562805176,0,0,0,40,300.459350585937,1,6,1,2.16690063476562,44.4770278930664,,,,,,,,,,,,,,,,
,3737946224.1935,300.006561279297,-61145.376953125,0.000156241863611596,1.3543270979774E-6,1,0.999253354069792,40.0298881530762,1.99839508715294,16.1700006574392,0.00169266641205455,0.000251247518322943,0.25,-4.06717693046278E-6,0.000156239940157353,-3.96461043378512E-6,300.006591796875,300.006591796875,-61172.80859375,-61117.9453125,55.057131266102,19.7071132037541,36.4767227172852,0,0,0,40,300.460723876953,1,6,1,2.16567993164062,44.9657897949219,,,,,,,,,,,,,,,,
,3737946308.0995,300.005462646484,-56966.5078125,0.000140222202621659,1.04977022748804E-6,1,0.999253354069792,40.0298881530762,1.99835310685387,16.1799993366003,0.00151833040476023,0.00022979081974959,0.25,-3.25074032039843E-6,0.000140220213643853,-3.15860735389138E-6,300.004669189453,300.004669189453,-56988.9609375,-56944.0546875,55.0868331498328,19.7029517386733,36.4661979675293,0,0,0,40,300.463806152344,1,6,1,2.16552734375,43.49951171875,,,,,,,,,,,,,,,,
,3737946392.0275,300.005294799805,-52785.208984375,0.00012391894458791,1.00346579130468E-6,1,0.999253354069792,40.0298881530762,1.99845100634023,16.1700006574392,0.00134294914259681,0.000196868227695731,0.25,-3.44913366065271E-6,0.000123917560845296,-3.3676134895514E-6,300.005615234375,300.005615234375,-52810.1171875,-52760.30078125,55.0203947256981,19.7031155513589,36.4608001708984,0,0,0,40,300.465270996094,1,6,1,2.15896606445313,44.4770278930664,,,,,,,,,,,,,,,,
,3737946475.952,300.00471496582,-48606.396484375,0.000109021545501482,1.01399149296997E-6,1,0.999253354069792,40.0298881530762,1.99835712666694,16.1700006574392,0.00118271654836707,0.000165953084459079,0.25,-3.70591418787392E-6,0.000109020767526806,-3.63410302891082E-6,300.00537109375,300.00537109375,-48631.27734375,-48581.515625,55.0899596639097,19.7030302701183,36.4521636962891,0,0,0,40,300.463134765625,1,6,1,2.16156005859375,44.9657897949219,,,,,,,,,,,,,,,,
,3737946559.8905,300.004287719727,-44423.142578125,9.44852701744472E-5,8.19759865787205E-7,1,0.999253354069792,40.0298881530762,1.9985207053536,16.1700006574392,0.00102487250193151,0.000145135991572871,0.25,-3.09141607819928E-6,9.44845147209063E-5,-3.02912228652676E-6,300.004333496094,300.004333496094,-44447.9921875,-44398.29296875,54.9922560990058,19.7017211329671,36.4427185058594,0,0,0,40,300.458221435547,1,6,1,2.1563720703125,44.9657897949219,,,,,,,,,,,,,,,,
,3737946643.8315,300.004165649414,-40241.841796875,7.80355703262356E-5,9.69959437850713E-7,1,0.999253354069792,40.0298881530762,1.99836891091663,16.1799993366003,0.000847343849752974,0.000114373810260067,0.25,-3.0619235195699E-6,7.80352791506152E-5,-3.01041038464046E-6,300.003601074219,300.003601074219,-40264.1328125,-40219.55078125,55.3502419608135,19.7034465799715,36.4424476623535,0,0,0,40,300.454742431641,1,6,1,2.16567993164062,44.9657897949219,,,,,,,,,,,,,,,,
,3737946727.7475,300.004257202148,-36063.046875,6.27328978237806E-5,7.60319531921295E-7,1,0.999253354069792,40.0298881530762,1.99848242200857,16.1700006574392,0.000680853747523368,9.40276280954275E-5,0.25,-2.2689012306475E-6,6.27325345636648E-5,-2.22745641949131E-6,300.004058837891,300.004058837891,-36085.44140625,-36040.65234375,55.0954310635443,19.7029037295467,36.4257164001465,0,0,0,40,300.459381103516,1,6,1,2.15835571289062,44.4770278930664,,,,,,,,,,,,,,,,
,3737946811.722,300.00439453125,-31878.958984375,4.77461210779458E-5,7.49903952168709E-7,1,0.999253354069792,40.0298881530762,1.99837647050892,16.1700006574392,0.000519452905972359,6.42525988165359E-5,0.25,-2.40457824771606E-6,4.77462902387268E-5,-2.37298528298954E-6,300.004333496094,300.004333496094,-31901.314453125,-31856.603515625,55.0540047520251,19.7022979876137,36.4111442565918,0,0,0,40,300.457275390625,1,6,1,2.1600341796875,44.4770278930664,,,,,,,,,,,,,,,,
,3737946895.66,300.005035400391,-27698,3.22162822826199E-5,6.03145232588303E-7,1,0.999253354069792,40.0298881530762,1.99864809477391,16.1700006574392,0.000352059719075581,3.46919156487946E-5,0.25,-2.42610087219383E-6,3.2216925975785E-5,-2.40474069328138E-6,300.005432128906,300.005432128906,-27722.865234375,-27673.134765625,55.0844882642751,19.6968453226192,36.3766021728516,0,0,0,40,300.458435058594,1,6,1,2.15545654296875,44.4770278930664,,,,,,,,,,,,,,,,
,3737946979.567,300.003677368164,-23519.0439453125,1.70929840816733E-5,5.8923652169866E-7,1,0.999253354069792,40.0298881530762,1.9984413790164,16.1799993366003,0.000189216712678247,4.45727925325125E-6,0.25,-2.580484891241E-6,1.70941815918298E-5,-2.56910339649258E-6,300.003875732422,300.003875732422,-23543.900390625,-23494.1875,55.0493149809097,19.7014627835869,36.3892860412598,0,0,0,40,300.45654296875,1,6,1,2.16506958007813,44.9657897949219,,,,,,,,,,,,,,,,
,3737947063.512,300.003463745117,-19334.3310546875,1.96804601247625E-6,5.25767757154243E-7,1,0.999253354069792,40.0298881530762,1.99844071450099,16.1700006574392,2.50443815516918E-5,-1.8090671237731E-5,0.25,-2.02213998830284E-6,1.96932580218144E-6,-2.02077698465504E-6,300.002868652344,300.002868652344,-19359.23046875,-19309.431640625,55.0360272960828,19.700943217647,36.3936042785645,0,0,0,40,300.457122802734,1,6,1,2.16400146484375,44.4770278930664,,,,,,,,,,,,,,,,
,3737947147.428,300.002059936523,-15155.6220703125,-1.30197737801445E-5,6.93093012624084E-7,1,0.999253354069792,40.0298881530762,1.99841986846502,16.1799993366003,-0.000138388244742598,-3.61513788149323E-5,0.25,-1.07175198056627E-6,-1.30186754454734E-5,-1.08034504539845E-6,300.002166748047,300.002166748047,-15180.5517578125,-15130.6923828125,55.0915229209481,19.7018796558404,36.3671569824219,0,0,0,40,300.459442138672,1,6,1,2.159423828125,44.9657897949219,,,,,,,,,,,,,,,,
,3737947231.395,300.003204345703,-10970.6459960938,-2.72939964326314E-5,4.44406609424118E-7,1,0.999253354069792,40.0298881530762,1.99842805162768,16.1799993366003,-0.000290565481790888,-7.31926420424806E-5,0.25,-2.00626498054622E-6,-2.7291849921993E-5,-2.02429978637063E-6,300.002899169922,300.002899169922,-10998.0810546875,-10943.2109375,54.9484849019289,19.7054441346592,36.3801116943359,0,0,0,40,300.456573486328,1,6,1,2.16201782226562,44.9657897949219,,,,,,,,,,,,,,,,
,3737947315.3325,300.002380371094,-6780.32690429688,-3.98373391851265E-5,5.57465510760782E-7,1,0.999253354069792,40.0298881530762,1.99836357958053,16.1799993366003,-0.000427017084177623,-9.00909208076029E-5,0.25,-1.37644328122568E-6,-3.98352338207735E-5,-1.40283142957666E-6,300.002746582031,300.002746582031,-6805.31103515625,-6755.3427734375,54.9211279037558,19.7033542876027,36.3793029785156,0,0,0,40,300.45751953125,1,6,1,2.16506958007813,44.9657897949219,,,,,,,,,,,,,,,,
,3737947399.254,300.0087890625,-2591.59875488281,,,1,0.999253354069792,40.0298881530762,1.99834836488879,16.1700006574392,-0.00304608959046376,0.00382994690595276,0.25,,,,300.002319335937,300.002319335937,-2614.47631835938,-2568.72119140625,55.0258661253327,19.7035250310373,36.3639183044434,1,0,,40,300.455718994141,1,6,1,2.15469360351562,44.4770278930664,,,,,,,,,,,,,,,,
,3737947489.2105,300.003158569336,1908.66119384766,4.0639721555367E-5,4.6777893992991E-7,1,0.999253354069792,40.0298881530762,1.99838280695796,16.1700006574392,0.000440059728217008,6.65682569755454E-5,0.25,-9.45367757746615E-7,4.06391301613953E-5,-9.18358708066967E-7,300.00390625,300.00390625,1883.66955566406,1933.65283203125,55.1806285721405,19.7034237037231,36.3393630981445,0,0,0,40,300.455780029297,1,6,1,2.15896606445313,44.4770278930664,,,,,,,,,,,,,,,,
,3737947576.116,300.002639770508,6253.85498046875,3.99564860434639E-5,4.91144988579615E-7,1,0.999253354069792,40.0298881530762,1.99839140442581,16.1799993366003,0.000432439920073762,6.6724338958879E-5,0.25,-8.11235530561973E-7,3.99558279724553E-5,-7.84700662181831E-7,300.002410888672,300.002410888672,6228.904296875,6278.8056640625,54.8836097348327,19.7042539220937,36.329647064209,0,0,0,40,300.458190917969,1,6,1,2.1636962890625,44.9657897949219,,,,,,,,,,,,,,,,
,3737947660.073,300.003555297852,10451.3935546875,2.86534658997786E-5,4.43912674109862E-7,1,0.999253354069792,40.0298881530762,1.99862318407776,16.1700006574392,0.000310365975210638,4.65876689929312E-5,0.25,-6.99185202840035E-7,2.86530718642355E-5,-6.80166477891386E-7,300.003448486328,300.003448486328,10428.876953125,10473.91015625,54.9461400163712,19.7010756958372,36.3139953613281,0,0,0,40,300.45849609375,1,6,1,2.15591430664062,44.4770278930664,,,,,,,,,,,,,,,,
,3737947744.0105,300.003189086914,14648.6381835938,1.36970923972971E-5,6.11804803115038E-7,1,0.999253354069792,40.0298881530762,1.99843564559314,16.1799993366003,0.000148369593067345,2.21544122518294E-5,0.25,-3.4476474205104E-7,1.36969116462693E-5,-3.35679894928028E-7,300.002746582031,300.002746582031,14623.640625,14673.6357421875,54.9977274986404,19.7028285501927,36.2888984680176,0,0,0,40,300.456573486328,1,6,1,2.15713500976562,43.9882698059082,,,,,,,,,,,,,,,,
,3737947827.9365,300.003387451172,18843.9248046875,-1.81965109828954E-6,6.25530078110374E-7,1,0.999253354069792,40.0298881530762,1.9983982665698,16.1799993366003,-1.87515306563292E-5,-8.41817654634194E-6,0.25,-4.61876606141575E-7,-1.81929106137377E-6,-4.63067406032941E-7,300.002838134766,300.002838134766,18818.984375,18868.865234375,54.9946009845635,19.703130646712,36.2543525695801,0,0,0,40,300.454956054687,1,6,1,2.16262817382813,44.9657897949219,,,,,,,,,,,,,,,,
,3737947911.882,300.002258300781,23044.845703125,-1.66601282708168E-5,6.06067351002859E-7,1,0.999253354069792,40.0298881530762,1.99844163888925,16.1700006574392,-0.000179129413025298,-3.45800808754226E-5,0.25,-2.88436194349786E-7,-1.66594419868163E-5,-2.99447107001773E-7,300.002105712891,300.002105712891,23019.8359375,23069.85546875,54.9883479564097,19.7047782135,36.2513847351074,0,0,0,40,300.454681396484,1,6,1,2.15789794921875,44.4770278930664,,,,,,,,,,,,,,,,
,3737947995.8055,300.002395629883,27246.7880859375,-3.11450651942643E-5,5.17667675648458E-7,1,0.999253354069792,40.0298881530762,1.9984304255308,16.1700006574392,-0.000337411938552387,-5.01285186955529E-5,0.25,8.06798481686083E-7,-3.11446735206274E-5,7.86192258914851E-7,300.002655029297,300.002655029297,27224.171875,27269.404296875,55.0313375249674,19.7051983052797,36.2327651977539,0,0,0,40,300.459716796875,1,6,1,2.15911865234375,43.9882698059082,,,,,,,,,,,,,,,,
,3737948079.7745,300.000991821289,31459.9580078125,-4.64754843676381E-5,5.53319392266659E-7,1,0.999253354069792,40.0298881530762,1.99852759212583,16.1799993366003,-0.000502962066402728,-7.79822321555748E-5,0.25,9.09448863823558E-7,-4.64747095097347E-5,8.78736070739979E-7,300.000823974609,300.000823974609,31434.810546875,31485.10546875,55.0602577801789,19.7042187603019,36.2238578796387,0,0,0,40,300.454986572266,1,6,1,2.164306640625,44.4770278930664,,,,,,,,,,,,,,,,
,3737948163.7035,300.000564575195,35674.375,-6.24282559307887E-5,7.69211653359153E-7,1,0.999253354069792,40.0298881530762,1.99837189552678,16.1700006574392,-0.00067312863835193,-0.0001185923807701,0.25,-6.27267901283906E-8,-6.24263714863204E-5,-1.03905711795361E-7,300.000732421875,300.000732421875,35651.76171875,35696.98828125,55.1321676039481,19.7029657611913,36.2316856384277,0,0,0,40,300.456817626953,1,6,1,2.15484619140625,43.9882698059082,,,,,,,,,,,,,,,,
,3737948247.654,300.000396728516,39887.896484375,-7.77765841804936E-5,1.01813501243642E-6,1,0.999253354069792,40.0298881530762,1.99834966038035,16.1799993366003,-0.000841127289244926,-0.000133387202357175,0.25,1.25339754407285E-6,-7.77751188108779E-5,1.20210385237881E-6,300.000335693359,300.000335693359,39862.8046875,39912.98828125,55.0657291798135,19.7032739328103,36.2279090881348,0,0,0,40,300.455535888672,1,6,1,2.159423828125,45.4545478820801,,,,,,,,,,,,,,,,
,3737948331.553,300.001235961914,44098.486328125,-9.18173141170813E-5,9.72286334034843E-7,1,0.999253354069792,40.0298881530762,1.99836993635041,16.1799993366003,-0.000992478939087486,-0.000160344338426796,0.25,1.21295503888325E-6,-9.18154102135831E-5,1.15246797212706E-6,300.001708984375,300.001708984375,44073.2890625,44123.68359375,54.901587190775,19.7047248629783,36.2192726135254,0,0,0,40,300.455780029297,1,6,1,2.15728759765625,44.4770278930664,,,,,,,,,,,,,,,,
,3737948415.4825,300.000579833984,48312.80078125,-0.000108740303105878,1.2378874403896E-6,1,0.999253354069792,40.0298881530762,1.99835146565382,16.1799993366003,-0.00117627014476879,-0.000184893544888791,0.25,1.90031314780181E-6,-0.000108738361197414,1.82873436032276E-6,300.000762939453,300.000762939453,48290.1171875,48335.484375,54.9328523315443,19.705902031896,36.2254791259766,0,0,0,40,300.457977294922,1,6,1,2.16293334960938,44.9657897949219,,,,,,,,,,,,,,,,
,3737948499.418,300.002960205078,52530.486328125,-0.000124129150254872,1.04199717851606E-6,1,0.999253354069792,40.0298881530762,1.9984101787235,16.1799993366003,-0.00134145792508495,-0.000218571053069255,0.25,1.4731999122957E-6,-0.00012412647176483,1.39159422074772E-6,300.003387451172,300.003387451172,52505.1953125,52555.77734375,55.0125784405058,19.7057365781797,36.2319564819336,0,0,0,40,300.451995849609,1,6,1,2.16445922851562,44.4770278930664,,,,,,,,,,,,,,,,
,3737948583.4375,300.000854492188,56777.671875,-0.000140208266454516,1.48923562116452E-6,1,0.999253354069792,40.0298881530762,1.99838100787423,16.1799993366003,-0.00151582865592355,-0.00024331003428589,0.25,1.99500044764084E-6,-0.000140205475817299,1.90290797429124E-6,300.001251220703,300.001251220703,56752.37890625,56802.96484375,54.8484364514673,19.7041210663781,36.2346534729004,0,0,0,40,300.457550048828,1,6,1,2.15652465820313,44.9657897949219,,,,,,,,,,,,,,,,
,3737948667.2815,300.001617431641,61020.123046875,-0.000155588113169967,1.92619516592429E-6,1,0.999253354069792,40.0298881530762,1.99829945527734,16.1700006574392,-0.00168253737003285,-0.00026714358836355,0.25,2.47758178853958E-6,-0.000155585193163749,2.37548594945134E-6,300.001647949219,300.001647949219,60994.80078125,61045.4453125,54.7601124287943,19.7053977939042,36.2333030700684,0,0,0,40,300.454223632812,1,6,1,2.158203125,44.4770278930664,,,,,,,,,,,,,,,,
,3737948751.2475,300.002105712891,65265.251953125,-0.000172208589990675,1.98985524287466E-6,1,0.999253354069792,40.0298881530762,1.99833251478762,16.1700006574392,-0.00185968289621809,-0.000310636129255224,0.25,1.35577211805354E-6,-0.000172204455614447,1.24292943139498E-6,300.00146484375,300.00146484375,65242.578125,65287.92578125,54.9774051571404,19.7046789133229,36.2214317321777,0,0,0,40,300.456970214844,1,6,1,2.161865234375,44.4770278930664,,,,,,,,,,,,,,,,
,3737948835.175,300.001770019531,69507.7578125,-0.000188240204996089,1.49999194850985E-6,1,0.999253354069792,40.0298881530762,1.99841461383714,16.1799993366003,-0.00203459058360053,-0.000329846826708403,0.25,2.38323618534865E-6,-0.000188236288278403,2.25999323370839E-6,300.001525878906,300.001525878906,69485,69530.515625,54.932070703025,19.7028883817912,36.2100982666016,0,0,0,40,300.451507568359,1,6,1,2.16583251953125,44.9657897949219,,,,,,,,,,,,,,,,
,3737948919.122,300.001251220703,73754.94140625,-0.000202924483423261,1.89939993846011E-6,1,0.999253354069792,40.0298881530762,1.9982929866348,16.1700006574392,-0.00219218764373567,-0.00036121504199344,0.25,2.04433607135943E-6,-0.000202919932674584,1.91163713343782E-6,300.000823974609,300.000823974609,73732.234375,73777.6484375,54.6897658620635,19.7036634409761,36.2009201049805,0,0,0,40,300.454772949219,1,6,1,2.16583251953125,44.4770278930664,,,,,,,,,,,,,,,,
,3737949003.07,300.001831054687,77998.2421875,-0.000220006713443072,1.51761916487417E-6,1,0.999253354069792,40.0298881530762,1.9983574539297,16.1799993366003,-0.00237890284392153,-0.000379624491347686,0.25,3.32990645285428E-6,-0.00022000251448309,3.18616119937588E-6,300.001342773438,300.001342773438,77970.421875,78026.0625,54.6428681509096,19.7058441676667,36.1782531738281,0,0,0,40,300.454925537109,1,6,1,2.15606689453125,44.9657897949219,,,,,,,,,,,,,,,,
,3737949086.9885,300.000854492188,82242.75,-0.000236593046890531,1.62871335228201E-6,1,0.999253354069792,40.0298881530762,1.99830786762778,16.1799993366003,-0.00255755915708435,-0.000411828263925359,0.25,3.24756179175666E-6,-0.000236588334426784,3.0931583857798E-6,300.001220703125,300.001220703125,82217.4765625,82268.0234375,54.7116514606019,19.7051589211394,36.1733932495117,0,0,0,40,300.451995849609,1,6,1,2.16293334960938,44.9657897949219,,,,,,,,,,,,,,,,
,3737949170.916,299.999435424805,86487.453125,-0.000252578372844716,2.54362769490117E-6,1,0.999253354069792,40.0298881530762,1.99843129719639,16.1700006574392,-0.00272834079590836,-0.000452123969854824,0.25,2.31286419634738E-6,-0.000252572616197589,2.14824361798409E-6,299.999755859375,299.999755859375,86464.75,86510.15625,54.8093550255058,19.7058863871632,36.1642189025879,0,0,0,40,300.456573486328,1,6,1,2.15728759765625,44.9657897949219,,,,,,,,,,,,,,,,
,3737949243.8485,300.000228881836,90003.62109375,-0.000268734470399388,1.9074340208133E-6,1,0.999253354069792,40.0298881530762,1.99829743962503,16.1799993366003,-0.00290915614295692,-0.000443998390398634,0.25,5.8930442515232E-6,-0.000268730584971309,5.71795761535125E-6,300.000061035156,300.000061035156,90000.5390625,90006.703125,54.8484364514673,19.7058142309403,36.1658401489258,0,0,0,40,300.458404541016,1,4,1,2.16537475585938,44.4770278930664,,,,,,,,,,,,,,,,