File: data/doubleLayers/dl_2-5/ppms/DD205_5/DD205_5_HYST_100OE_20K.DAT
[Header]
; VSM Data File (default extension .dat)
; Copyright (c) 2003-2013, Quantum Design, Inc. All rights reserved.
TITLE,
FILEOPENTIME,3737919446.9674,06/11/2018,10:59 pm
BYAPP,VSM,1.0,1.0
INFO,DYNACOOL VSM Option Release 1.4.10 Build 1,APPNAME
INFO,Quantum Design Linear Motor Servo Controller,MOTOR_MODULE_NAME
INFO,3101-100 J0,MOTOR_HW_VERSION
INFO,MMC654,MOTOR_SERIAL_NUMBER
INFO,SRV No X-over 01.03.11,MOTOR_SOFTWARE_VERSION
INFO,Quantum Design VSM Detection Module,VSM_MODULE_NAME
INFO,3101-150 F0,VSM_HW_VERSION
INFO,VSM507,VSM_SERIAL_NUMBER
INFO,VSM No X-over 01.02.05 May 20 2008 13:51:47,VSM_SOFTWARE_VERSION
INFO,494,PREAMP_SERIAL_NUMBER
INFO,Quantum Design VSM Oven,OVEN_MODULE_NAME
INFO,3101-201 A1,OVEN_HW_VERSION
INFO,OVB210,OVEN_SERIAL_NUMBER
INFO,01.06.24,OVEN_SOFTWARE_VERSION
INFO,593,COIL_SERIAL_NUMBER
INFO,0,MOMENT_UNITS
INFO,CoFe2O4,SAMPLE_MATERIAL
INFO,,SAMPLE_COMMENT
INFO,,SAMPLE_MASS
INFO,,SAMPLE_VOLUME
INFO,,SAMPLE_MOLECULAR_WEIGHT
INFO,,SAMPLE_SIZE
INFO,,SAMPLE_SHAPE
DATATYPE,COMMENT,1
DATATYPE,TIME,2
STARTUPAXIS,X,2
STARTUPAXIS,Y1,5
[Data]
Comment,Time Stamp (sec),Temperature (K),Magnetic Field (Oe),Moment (emu),M. Std. Err. (emu),Transport Action,Averaging Time (sec),Frequency (Hz),Peak Amplitude (mm),Center Position (mm),Coil Signal' (mV),Coil Signal" (mV),Range (mV),M. Quad. Signal (emu),M. Raw' (emu),M. Raw" (emu),Min. Temperature (K),Max. Temperature (K),Min. Field (Oe),Max. Field (Oe),Mass (grams),Motor Lag (deg),Pressure (Torr),VSM Status (code),Motor Status (code),Measure Status (code),Measure Count,System Temp. (K),Temp. Status (code),Field Status (code),Chamber Status (code),Motor Current (amps),Motor Heatsink Temp. (C),Map 01,Map 02,Map 03,Map 04,Map 05,Map 06,Map 07,Map 08,Map 09,Map 10,Map 11,Map 12,Map 13,Map 14,Map 15,Map 16
,3737919959.05,19.9935970306396,-0.447623699903488,6.47818796731569E-5,3.82954718546121E-7,1,0.999253354069792,40.0298881530762,1.99681854760541,16.1700006574392,0.00069256938524437,0.000129522742267249,0.25,4.71715190613976E-7,6.43947184805407E-5,7.82772293446852E-7,19.9935836791992,19.9935836791992,-0.471819579601288,-0.423427820205688,54.7960673406789,19.7362920712885,8.52685356140137,0,0,0,40,20.0113258361816,1,4,1,2.16552734375,44.9657897949219,,,,,,,,,,,,,,,,
,3737920050.0125,19.9981031417847,4126.62426757812,4.505893128792E-5,2.32689805607633E-7,1,0.999253354069792,40.0298881530762,1.99662699332243,16.1700006574392,0.000483672563789038,7.9557941657283E-5,0.25,-6.67729522036811E-7,4.48045053035765E-5,-4.34590156958376E-7,19.9980926513672,19.9980926513672,4099.1240234375,4154.12451171875,54.5975336967942,19.7375027809564,8.62380790710449,0,0,0,40,20.0177459716797,1,6,1,2.16537475585938,43.9882698059082,,,,,,,,,,,,,,,,
,3737920133.9135,19.9993829727173,8318.53515625,2.91150819037439E-5,2.29250490067323E-7,1,0.999253354069792,40.0298881530762,1.99651118506104,16.1700006574392,0.000313808075887349,4.47456325339315E-5,0.25,-1.06352765466074E-6,2.89629227049362E-5,-9.00814888404163E-7,19.9993515014648,19.9993515014648,8293.4990234375,8343.5712890625,54.8312406240443,19.7315515192612,8.68799877166748,0,0,0,40,20.0196952819824,1,6,1,2.1624755859375,44.9657897949219,,,,,,,,,,,,,,,,
,3737920217.8815,19.9998054504395,12521.0708007813,1.43454979940664E-5,2.42180474797983E-7,1,0.999253354069792,40.0298881530762,1.99661691613792,16.1700006574392,0.000155345851015395,1.83741659163439E-5,0.25,-8.72149206772737E-7,1.42775958874864E-5,-7.85983961595955E-7,19.9996910095215,19.9996910095215,12498.490234375,12543.6513671875,54.718686117275,19.7364435301184,8.73460006713867,0,0,0,40,20.0216522216797,1,6,1,2.16201782226562,44.9657897949219,,,,,,,,,,,,,,,,
,3737920301.806,20.0006427764893,16713.205078125,5.55736050560387E-7,2.53378123788405E-7,1,0.999253354069792,40.0298881530762,1.99688259747064,16.1799993366003,7.86351788518182E-6,-9.48484786978525E-6,0.25,-9.85496340055828E-7,5.59027747335954E-7,-9.77529686486001E-7,20.000509262085,20.000509262085,16688.17578125,16738.234375,55.1235696902366,19.7385580444799,8.77151203155518,0,0,0,40,20.0213794708252,1,6,1,2.13958740234375,44.9657897949219,,,,,,,,,,,,,,,,
,3737920385.704,20.0005750656128,20910.9296875,-1.20390738162547E-5,2.86341033731882E-7,1,0.999253354069792,40.0298881530762,1.99668734181967,16.1700006574392,-0.00012700505315032,-3.46413731251328E-5,0.25,-1.05315809023805E-6,-1.19806674877845E-5,-1.1240955602548E-6,20.0004634857178,20.0004634857178,20888.458984375,20933.400390625,54.9359788456212,19.7398779319966,8.8001594543457,0,0,0,40,20.020824432373,1,6,1,2.1661376953125,44.4770278930664,,,,,,,,,,,,,,,,
,3737920469.666,20.0003366470337,25108.8427734375,-2.42989494217639E-5,2.50696662736566E-7,1,0.999253354069792,40.0298881530762,1.99676713306406,16.1700006574392,-0.000258434204497138,-5.90119750692938E-5,0.25,-1.09966047934311E-6,-2.41974383660085E-5,-1.25378637752231E-6,20.0003776550293,20.0003776550293,25083.875,25133.810546875,54.7538594006404,19.7397868265664,8.82347011566162,0,0,0,40,20.0200080871582,1,6,1,2.15087890625,45.4545478820801,,,,,,,,,,,,,,,,
,3737920553.604,19.9999876022339,29318.501953125,-3.65862929485462E-5,2.72992730398186E-7,1,0.999253354069792,40.0298881530762,1.99653317972912,16.1700006574392,-0.000389575178137501,-8.70383634555009E-5,0.25,-1.47592043922943E-6,-3.64502067063733E-5,-1.71741912150463E-6,20.0000057220459,20.0000057220459,29295.8515625,29341.15234375,54.6921107476212,19.7317812464596,8.84328746795654,0,0,0,40,20.0203418731689,1,6,1,2.16262817382813,44.9657897949219,,,,,,,,,,,,,,,,
,3737920637.5365,19.9999809265137,33532.376953125,-4.88469975459135E-5,2.5590801073862E-7,1,0.999253354069792,40.0298881530762,1.99645335647085,16.1700006574392,-0.000521387386778224,-0.000110469412425591,0.25,-1.42236328471834E-6,-4.86903788041226E-5,-1.75660524239471E-6,19.9997482299805,19.9997482299805,33507.28125,33557.47265625,54.9406686167366,19.7363175123038,8.86067771911621,0,0,0,40,20.0205078125,1,6,1,2.16064453125,44.4770278930664,,,,,,,,,,,,,,,,
,3737920721.482,19.9993190765381,37746.771484375,-6.07745060004685E-5,3.2552197583525E-7,1,0.999253354069792,40.0298881530762,1.99641213288572,16.1700006574392,-0.000649478748313038,-0.000134734627318986,0.25,-1.50238810264516E-6,-6.06083722894514E-5,-1.92934803109422E-6,19.9993419647217,19.9993419647217,37719.12890625,37774.4140625,54.8390569092366,19.7319150801388,8.87533569335938,0,0,0,40,20.0206966400146,1,6,1,2.16598510742187,44.4770278930664,,,,,,,,,,,,,,,,
,3737920805.401,20.0001363754272,41959.912109375,-7.34208420896574E-5,3.42028077894761E-7,1,0.999253354069792,40.0298881530762,1.99648825482025,16.1799993366003,-0.000785091651947682,-0.000162360398262468,0.25,-1.76038834038251E-6,-7.32529384903451E-5,-2.28644203064937E-6,20.0001068115234,20.0001068115234,41934.8359375,41984.98828125,54.6631904924096,19.7360799585537,8.88842964172363,0,0,0,40,20.0197772979736,1,6,1,2.15362548828125,44.4770278930664,,,,,,,,,,,,,,,,
,3737920889.3855,19.999382019043,46173.927734375,-8.63556971165191E-5,3.04294648150866E-7,1,0.999253354069792,40.0298881530762,1.99645271054418,16.1700006574392,-0.000923855122739902,-0.000190708221492329,0.25,-2.03110378277385E-6,-8.61962319223592E-5,-2.6591754886825E-6,19.9991683959961,19.9991683959961,46146.3515625,46201.50390625,55.1259145757943,19.7370256568042,8.90057468414307,0,0,0,40,20.0201396942139,1,6,1,2.16567993164062,44.9657897949219,,,,,,,,,,,,,,,,
,3737920973.263,20.0004644393921,50385.087890625,-9.91168598627457E-5,3.18856326307129E-7,1,0.999253354069792,40.0298881530762,1.99688040549925,16.1700006574392,-0.00106294638745606,-0.000208610633599533,0.25,-1.35573085516085E-6,-9.8983528796894E-5,-2.08561022279652E-6,20.0003108978271,20.0003108978271,50362.49609375,50407.6796875,54.7515145150827,19.7397398451136,8.91090202331543,0,0,0,40,20.019905090332,1,6,1,2.16217041015625,44.9657897949219,,,,,,,,,,,,,,,,
,3737921057.2575,19.9994115829468,54622.689453125,-0.000112039430181922,3.07221310221362E-7,1,0.999253354069792,40.0298881530762,1.99676209220351,16.1799993366003,-0.00120183632595326,-0.000236626806160376,0.25,-1.59615346559333E-6,-0.000111935429367152,-2.42651766766639E-6,19.9994239807129,19.9994239807129,54597.46484375,54647.9140625,54.8875178774289,19.7424117589699,8.92138671875,0,0,0,40,20.0192642211914,1,6,1,2.16354370117187,44.4770278930664,,,,,,,,,,,,,,,,
,3737921141.171,20.0001564025879,58862.63671875,-0.000125379303266687,3.60897201221386E-7,1,0.999253354069792,40.0298881530762,1.99653051822088,16.1700006574392,-0.00134503471424152,-0.000266518425480006,0.25,-1.93666772083525E-6,-0.000125312983456058,-2.86881285061774E-6,20.0002326965332,20.0002326965332,58834.87890625,58890.39453125,54.5701766986212,19.7367151993526,8.93018341064453,0,0,0,40,20.0190734863281,1,6,1,2.14691162109375,44.4770278930664,,,,,,,,,,,,,,,,
,3737921225.125,19.9997978210449,63110.19921875,-0.000138701296653501,3.99273175324352E-7,1,0.999253354069792,40.0298881530762,1.99652961709647,16.1700006574392,-0.0014890735667579,-0.000291998552657263,0.25,-1.86887879027842E-6,-0.000138684630541022,-2.90036480510766E-6,19.9998073577881,19.9998073577881,63082.3515625,63138.046875,54.7265024024673,19.740239120693,8.93827438354492,0,0,0,40,20.0185737609863,1,6,1,2.1600341796875,44.9657897949219,,,,,,,,,,,,,,,,
,3737921309.0285,19.9995832443237,67352.8984375,-0.000152204106467065,2.57076775746605E-7,1,0.999253354069792,40.0298881530762,1.99661619915792,16.1700006574392,-0.00163394103108968,-0.000324846144186727,0.25,-2.45296312098554E-6,-0.000152240319135461,-3.58221855349505E-6,19.9995803833008,19.9995803833008,67330.1171875,67375.6796875,54.9609909582366,19.737014241742,8.94697570800781,0,0,0,40,20.0182018280029,1,6,1,2.16598510742187,44.9657897949219,,,,,,,,,,,,,,,,
,3737921392.9525,20.0002307891846,71597.4765625,-0.000165615719306249,3.3027552360849E-7,1,0.999253354069792,40.0298881530762,1.99653475277771,16.1700006574392,-0.00177905566931081,-0.000350476106977202,0.25,-2.38768053939798E-6,-0.00016571701685139,-3.61049945442263E-6,20.0000915527344,20.0000915527344,71572.203125,71622.75,54.8828281063135,19.7394647643083,8.95494270324707,0,0,0,40,20.0184879302979,1,6,1,2.16567993164062,44.9657897949219,,,,,,,,,,,,,,,,
,3737921476.878,20.0005569458008,75840.11328125,-0.000179040236201137,3.62621840920666E-7,1,0.999253354069792,40.0298881530762,1.99670274374534,16.1700006574392,-0.00192432633898099,-0.000377673965321026,0.25,-2.46426258238006E-6,-0.000179212158753287,-3.77708266938713E-6,20.0005683898926,20.0005683898926,75814.8515625,75865.375,54.9891295849289,19.7394485849459,8.96232604980469,0,0,0,40,20.0178565979004,1,6,1,2.16522216796875,45.4545478820801,,,,,,,,,,,,,,,,
,3737921560.8495,20.0000295639038,80088.1328125,-0.000192890601937411,3.73331433305512E-7,1,0.999253354069792,40.0298881530762,1.99642696696947,16.1700006574392,-0.00207305595680271,-0.000409927013747622,0.25,-2.94283330875261E-6,-0.000193136800586056,-4.34538755948327E-6,20.0000247955322,20.0000247955322,80062.8828125,80113.3828125,54.8765750781596,19.737205314827,8.96960830688477,0,0,0,40,20.0181674957275,1,6,1,2.14752197265625,44.9657897949219,,,,,,,,,,,,,,,,
,3737921644.796,20.0003356933594,84332.84765625,-0.000206678692181609,5.35582724077649E-7,1,0.999253354069792,40.0298881530762,1.99663867627711,16.1700006574392,-0.00222280066268927,-0.000435834352768409,0.25,-2.83828735479167E-6,-0.000207008749169598,-4.32532707470909E-6,20.0003337860107,20.0003337860107,84305.015625,84360.6796875,54.6405232653519,19.7423162159556,8.97632312774658,0,0,0,40,20.0185146331787,1,6,1,2.14630126953125,44.9657897949219,,,,,,,,,,,,,,,,
,3737921728.7125,19.9998760223389,88577.76953125,-0.000220424628939068,4.16390812297895E-7,1,0.999253354069792,40.0298881530762,1.99656473251229,16.1700006574392,-0.00237021379437947,-0.000470609358526709,0.25,-3.57236964773549E-6,-0.000220837301946001,-5.14104273932979E-6,19.9998626708984,19.9998626708984,88552.5,88603.0390625,54.9133116185635,19.7410114932021,8.98197269439697,0,0,0,40,20.0178966522217,1,6,1,2.15057373046875,44.9657897949219,,,,,,,,,,,,,,,,
,3737921822.622,19.9995746612549,87345.76953125,-0.00021581301311697,4.23352775644013E-7,1,0.999253354069792,40.0298881530762,1.99680225796182,16.1700006574392,-0.00232189238201914,-0.000454191999822943,0.25,-2.88126703926385E-6,-0.000216203453532653,-4.42129814072089E-6,19.9997081756592,19.9997081756592,87320.7890625,87370.75,55.3377359045058,19.7402864553938,8.98888874053955,0,0,0,40,20.0167713165283,1,6,1,2.13592529296875,44.9657897949219,,,,,,,,,,,,,,,,
,3737921906.5655,19.9999208450317,83162.98828125,-0.000202599339348157,3.91308839608452E-7,1,0.999253354069792,40.0298881530762,1.99670291996354,16.1700006574392,-0.00217824095124002,-0.000430354163001947,0.25,-3.06926270689969E-6,-0.000202903876212242,-4.53175528519322E-6,19.9999389648438,19.9999389648438,83140.53125,83185.4453125,54.9719337575058,19.7437262056625,8.99497509002686,0,0,0,40,20.0175285339355,1,6,1,2.16552734375,44.9657897949219,,,,,,,,,,,,,,,,
,3737921990.5985,20.0003814697266,78975.640625,-0.00018894686292005,4.8606310065606E-7,1,0.999253354069792,40.0298881530762,1.99651305792884,16.1700006574392,-0.00203085883788825,-0.00040002134437245,0.25,-2.73911731882699E-6,-0.00018917320338407,-4.11613388583483E-6,20.0002727508545,20.0002727508545,78950.7109375,79000.5703125,54.9633358437943,19.7350449824723,9.00110530853271,0,0,0,40,20.0179347991943,1,6,1,2.16552734375,44.4770278930664,,,,,,,,,,,,,,,,
,3737922074.427,19.9993648529053,74800.203125,-0.000175522427527014,3.79712539840455E-7,1,0.999253354069792,40.0298881530762,1.99641396135917,16.1700006574392,-0.001885951952575,-0.000370995753313092,0.25,-2.48962256051429E-6,-0.000175675920114751,-3.77911371832287E-6,19.9994468688965,19.9994468688965,74775.3671875,74825.0390625,54.5686134415827,19.7344932332281,9.00517559051514,0,0,0,40,20.0178127288818,1,6,1,2.1368408203125,44.4770278930664,,,,,,,,,,,,,,,,
,3737922158.4025,19.9999408721924,70612.12890625,-0.000162467626034056,4.01590087650548E-7,1,0.999253354069792,40.0298881530762,1.99673981443747,16.1700006574392,-0.00174526865374448,-0.000343802720937225,0.25,-2.33889304952064E-6,-0.000162553649828744,-3.54002658691299E-6,19.9999847412109,19.9999847412109,70584.8359375,70639.421875,55.118098290602,19.7347658521067,9.01021194458008,0,0,0,40,20.0183162689209,1,6,1,2.14859008789062,44.9657897949219,,,,,,,,,,,,,,,,
,3737922242.3445,19.9988889694214,66432.50390625,-0.000148756310072201,3.77075504014822E-7,1,0.999253354069792,40.0298881530762,1.99685423324025,16.1700006574392,-0.00159696676037761,-0.000317574720277728,0.25,-2.40344981023808E-6,-0.000148779675351385,-3.50791683775309E-6,19.9988307952881,19.9988307952881,66410.109375,66454.8984375,55.0282110108904,19.7399965970473,9.01504611968994,0,0,0,40,20.0187854766846,1,6,1,2.16400146484375,43.9882698059082,,,,,,,,,,,,,,,,
,3737922326.2695,19.999828338623,62252.31640625,-0.000135635701779528,3.65627996409924E-7,1,0.999253354069792,40.0298881530762,1.99670810803342,16.1700006574392,-0.00145520981982021,-0.000290826841486082,0.25,-2.31777828845092E-6,-0.000135605131415753,-3.32660780324062E-6,19.9997673034668,19.9997673034668,62224.8984375,62279.734375,55.077453607602,19.7420954612422,9.01948356628418,0,0,0,40,20.0195941925049,1,6,1,2.16629028320313,44.4770278930664,,,,,,,,,,,,,,,,
,3737922410.2025,20.0000677108765,58069.046875,-0.000122734708383061,2.46396738118643E-7,1,0.999253354069792,40.0298881530762,1.99669180688834,16.1700006574392,-0.00131668065173031,-0.000260817335388048,0.25,-1.88852474446853E-6,-0.000122660596959114,-2.8006708340071E-6,20.0000343322754,20.0000343322754,58044.0859375,58094.0078125,54.9531746730443,19.7398501269603,9.02372550964355,0,0,0,40,20.0194072723389,1,6,1,2.1649169921875,44.4770278930664,,,,,,,,,,,,,,,,
,3737922494.1675,19.9995965957642,53882.0703125,-0.000109614702258914,3.23933474838589E-7,1,0.999253354069792,40.0298881530762,1.99686053679457,16.1700006574392,-0.00117474957442929,-0.000237245380097283,0.25,-2.09640893582342E-6,-0.000109501015330638,-2.90760079887483E-6,19.9995937347412,19.9995937347412,53859.63671875,53904.50390625,55.0055437838327,19.7399335116672,9.02727508544922,0,0,0,40,20.0196590423584,1,6,1,2.16140747070313,44.4770278930664,,,,,,,,,,,,,,,,
,3737922578.0645,20.000189781189,49705.1171875,-9.65120765751265E-5,3.58645059371331E-7,1,0.999253354069792,40.0298881530762,1.996786466989,16.1700006574392,-0.001033715692774,-0.000209580559549365,0.25,-1.92330669903712E-6,-9.63711752361195E-5,-2.63223408554862E-6,20.0000877380371,20.0000877380371,49680.16015625,49730.07421875,54.9906928419674,19.7428821403999,9.03245830535889,0,0,0,40,20.020715713501,1,6,1,2.16278076171875,43.9882698059082,,,,,,,,,,,,,,,,
,3737922661.9965,20.0004215240479,45522.173828125,-8.39973051852678E-5,3.31323505974777E-7,1,0.999253354069792,40.0298881530762,1.99657395249635,16.1700006574392,-0.000900051945620106,-0.000177607709886826,0.25,-1.24229936649045E-6,-8.38419090969931E-5,-1.85326463465178E-6,20.0004920959473,20.0004920959473,45494.78515625,45549.5625,54.7249391454289,19.7403713609145,9.03669261932373,0,0,0,40,20.0191879272461,1,6,1,2.15255737304687,44.4770278930664,,,,,,,,,,,,,,,,
,3737922745.941,20.0002632141113,41340.146484375,-7.05485862214734E-5,3.25145052364717E-7,1,0.999253354069792,40.0298881530762,1.9968615263323,16.1700006574392,-0.00075433255107481,-0.000156746598045712,0.25,-1.7597261135825E-6,-7.03821931433714E-5,-2.26375930466285E-6,20.0004558563232,20.0004558563232,41315.24609375,41365.046875,54.8875178774289,19.7381390326944,9.03975486755371,0,0,0,40,20.0197486877441,1,6,1,2.1478271484375,44.4770278930664,,,,,,,,,,,,,,,,
,3737922829.8765,19.9998550415039,37160.427734375,-5.79280306666089E-5,4.26127006481996E-7,1,0.999253354069792,40.0298881530762,1.99669735790357,16.1700006574392,-0.000619158688668674,-0.000128138806906668,0.25,-1.40570703175078E-6,-5.7766297374621E-5,-1.81148279474032E-6,19.9998798370361,19.9998798370361,37135.25390625,37185.6015625,54.6499028075827,19.7358879511876,9.04195785522461,0,0,0,40,20.0200366973877,1,6,1,2.16323852539062,43.9882698059082,,,,,,,,,,,,,,,,
,3737922913.8075,20.0000371932983,32975.10546875,-4.5413091750111E-5,2.64722922270258E-7,1,0.999253354069792,40.0298881530762,1.9968363142667,16.1700006574392,-0.000485745788058263,-9.74769770053356E-5,0.25,-8.35229369520062E-7,-4.52682047785376E-5,-1.14632919217103E-6,20.0000190734863,20.0000190734863,32950.22265625,32999.98828125,55.209548827352,19.7347755156924,9.04604148864746,0,0,0,40,20.0212421417236,1,6,1,2.16506958007813,44.9657897949219,,,,,,,,,,,,,,,,
,3737922997.7245,19.9998731613159,28795.18359375,-3.30281872181532E-5,2.21911710702124E-7,1,0.999253354069792,40.0298881530762,1.99652397022186,16.1700006574392,-0.000351896705711821,-7.73058788494799E-5,0.25,-1.21545850309142E-6,-3.29043518750895E-5,-1.43295439857018E-6,19.9997711181641,19.9997711181641,28770.318359375,28820.048828125,54.8546894796212,19.7350162332569,9.04908084869385,0,0,0,40,20.0210418701172,1,6,1,2.14797973632813,43.9882698059082,,,,,,,,,,,,,,,,
,3737923081.7305,19.999755859375,24610.9638671875,-2.0666219826601E-5,2.85582767614876E-7,1,0.999253354069792,40.0298881530762,1.99675043495535,16.1799993366003,-0.000219395492270622,-5.23376094761484E-5,0.25,-1.1364273403246E-6,-2.05775582626769E-5,-1.26609037798075E-6,19.9998207092285,19.9998207092285,24585.984375,24635.943359375,54.8882995059481,19.7370841213182,9.05293655395508,0,0,0,40,20.0205097198486,1,6,1,2.14706420898438,43.49951171875,,,,,,,,,,,,,,,,
,3737923165.722,19.9997444152832,20426.322265625,-7.7873911633341E-6,2.89932410115531E-7,1,0.999253354069792,40.0298881530762,1.99667908809553,16.1700006574392,-8.11810710827041E-5,-2.77523630045409E-5,0.25,-1.18022002582724E-6,-7.74615013481072E-6,-1.22366393399513E-6,19.9996719360352,19.9996719360352,20401.390625,20451.25390625,54.864069021852,19.7380530833038,9.05680465698242,0,0,0,40,20.0199413299561,1,6,1,2.16476440429687,43.9882698059082,,,,,,,,,,,,,,,,
,3737923249.5415,19.9995994567871,16251.74609375,5.38873346770226E-6,2.12632172952654E-7,1,0.999253354069792,40.0298881530762,1.99658765163676,16.1700006574392,5.91750480180535E-5,2.46853247203095E-6,0.25,-7.43046628246699E-7,5.36758236103006E-6,-7.07395368094245E-7,19.9995079040527,19.9995079040527,16226.8212890625,16276.6708984375,55.0547863805443,19.7320255748494,9.0587911605835,0,0,0,40,20.0208492279053,1,6,1,2.14431762695313,43.9882698059082,,,,,,,,,,,,,,,,
,3737923333.5195,19.9999704360962,12063.0498046875,1.89832073497881E-5,2.94124679864481E-7,1,0.999253354069792,40.0298881530762,1.99665836950994,16.1700006574392,0.000204832449604201,2.83626495369798E-5,0.25,-7.75470760570514E-7,1.8890426875987E-5,-6.63971545327834E-7,19.999885559082,19.999885559082,12035.615234375,12090.484375,55.0454068383135,19.7355552055121,9.06183815002441,0,0,0,40,20.0209770202637,1,6,1,2.14614868164062,43.49951171875,,,,,,,,,,,,,,,,
,3737923417.436,20.0000810623169,7878.69848632813,3.34259980495914E-5,2.72532523424606E-7,1,0.999253354069792,40.0298881530762,1.99669514662151,16.1700006574392,0.000359639596289314,5.4991299177916E-5,0.25,-8.82080991385352E-7,3.32483298243707E-5,-6.98161247358977E-7,20.0000114440918,20.0000114440918,7853.79443359375,7903.6025390625,54.4326100792365,19.7341408579705,9.06519985198975,0,0,0,40,20.0197334289551,1,6,1,2.15103149414062,43.49951171875,,,,,,,,,,,,,,,,
,3737923501.403,20.0002899169922,3681.30786132812,4.86258935996961E-5,2.26836480863685E-7,1,0.999253354069792,40.0298881530762,1.99654159885506,16.1700006574392,0.000521901859376896,8.59768630063334E-5,0.25,-7.07246851257391E-7,4.83498556250283E-5,-4.57189813463045E-7,20.0003108978271,20.0003108978271,3653.78955078125,3708.826171875,55.0141416975443,19.7373988928866,9.06817150115967,0,0,0,40,20.0202941894531,1,6,1,2.16598510742187,43.9882698059082,,,,,,,,,,,,,,,,
,3737923588.319,19.9998321533203,-662.204742431641,7.10369422309322E-5,3.10910013900916E-7,1,0.999253354069792,40.0298881530762,1.99656657713336,16.1799993366003,0.000761593236916575,0.000129620971400939,0.25,-6.42678914586032E-7,7.06197491791191E-5,-2.92722312333453E-7,19.9998340606689,19.9998340606689,-689.549194335938,-634.860290527344,54.7280656595058,19.7335109004698,9.07052707672119,0,0,0,40,20.0205020904541,1,6,1,2.16522216796875,43.9882698059082,,,,,,,,,,,,,,,,
,3737923675.236,19.9999656677246,-5008.57934570313,8.9433784459766E-5,2.57676419411676E-7,1,0.999253354069792,40.0298881530762,1.99662527640231,16.1700006574392,0.000959026920202837,0.000163657010388017,0.25,-7.9474368693981E-7,8.89313742368601E-5,-3.29569446170364E-7,19.9999122619629,19.9999122619629,-5033.5166015625,-4983.64208984375,55.1071554913327,19.7390469088243,9.07398223876953,0,0,0,40,20.0202331542969,1,6,1,2.16354370117187,43.0107536315918,,,,,,,,,,,,,,,,
,3737923759.165,20.0001287460327,-9204.048828125,9.96183014222482E-5,2.43180989457437E-7,1,0.999253354069792,40.0298881530762,1.99658383162402,16.1700006574392,0.00106805033670826,0.000185149109794726,0.25,-6.54000901990183E-7,9.90885250379099E-5,-1.07031149857981E-7,20.0002555847168,20.0002555847168,-9229.0888671875,-9179.0087890625,54.9328523315443,19.734779769551,9.0754280090332,0,0,0,40,20.019214630127,1,6,1,2.14981079101562,44.4770278930664,,,,,,,,,,,,,,,,
,3737923843.178,19.9997110366821,-13404.0087890625,0.000104181196496552,2.09856839611056E-7,1,0.999253354069792,40.0298881530762,1.99659287922059,16.1700006574392,0.00111632718504776,0.000199500971042287,0.25,-1.74165693407136E-7,0.000103660967498713,4.26903734371449E-7,19.9996547698975,19.9996547698975,-13434.0859375,-13373.931640625,54.8585976222173,19.7374687727823,9.07830619812012,0,0,0,40,20.0205326080322,1,6,1,2.16522216796875,43.9882698059082,,,,,,,,,,,,,,,,
,3737923927.0435,20.0006923675537,-17598.263671875,9.9804161456751E-5,2.38019814053778E-7,1,0.999253354069792,40.0298881530762,1.99656528618961,16.1700006574392,0.00107059897667988,0.000186905709623298,0.25,-5.95758773779782E-7,9.93465092635641E-5,1.11122453983173E-8,20.0006847381592,20.0006847381592,-17623.26953125,-17573.2578125,54.8679771644481,19.7349070872741,9.0799503326416,0,0,0,40,20.0201072692871,1,6,1,2.16567993164062,44.4770278930664,,,,,,,,,,,,,,,,
,3737924010.9555,19.9998121261597,-21793.2900390625,8.65083601054827E-5,2.67767253942227E-7,1,0.999253354069792,40.0298881530762,1.99679203050463,16.1799993366003,0.000928663294612967,0.000160947370913904,0.25,-6.46294792740189E-7,8.61477240322032E-5,-9.65345739488009E-8,19.9996814727783,19.9996814727783,-21818.2265625,-21768.353515625,54.9500481589674,19.7373518263191,9.08137798309326,0,0,0,40,20.0210113525391,1,6,1,2.16232299804687,43.9882698059082,,,,,,,,,,,,,,,,
,3737924094.936,19.9995765686035,-25995.5068359375,7.29112215450032E-5,2.65243051159606E-7,1,0.999253354069792,40.0298881530762,1.9968580376839,16.1700006574392,0.000782610792224652,0.000138186820849839,0.25,-3.31694316103222E-7,7.26369268519804E-5,1.48425118320242E-7,19.9994850158691,19.9994850158691,-26023.05859375,-25967.955078125,55.0790168646404,19.741202082701,9.08451652526855,0,0,0,40,20.0201568603516,1,6,1,2.16842651367187,44.4770278930664,,,,,,,,,,,,,,,,
,3737924178.8395,20.000057220459,-30203.1767578125,6.50869898495914E-5,3.22874885966077E-7,1,0.999253354069792,40.0298881530762,1.99682380129549,16.1700006574392,0.000698908215759791,0.000123497362285514,0.25,-3.01801881182177E-7,6.48706609845514E-5,1.40659842076976E-7,20.0001029968262,20.0001029968262,-30228.26171875,-30178.091796875,55.0813617501981,19.7415836891774,9.08593654632568,0,0,0,40,20.0196895599365,1,6,1,2.16629028320313,43.9882698059082,,,,,,,,,,,,,,,,
,3737924262.7985,19.9991903305054,-34417.80859375,6.50829227515693E-5,3.05974287997098E-7,1,0.999253354069792,40.0298881530762,1.99679264125593,16.1700006574392,0.000699228914374781,0.000123203229091279,0.25,-3.45235774716495E-7,6.48958793318519E-5,1.09139433554882E-7,19.9991569519043,19.9991569519043,-34442.84375,-34392.7734375,54.9375421026597,19.7400947438325,9.0881986618042,0,0,0,40,20.0202350616455,1,6,1,2.16873168945313,44.4770278930664,,,,,,,,,,,,,,,,
,3737924346.7805,19.9998388290405,-38633.0078125,7.07257674317893E-5,3.05142466421749E-7,1,0.999253354069792,40.0298881530762,1.99663122569229,16.1700006574392,0.00076054501595142,0.00013169008241376,0.25,-5.94804378989646E-7,7.0555690200546E-5,-8.99225934737315E-8,19.9998111724854,19.9998111724854,-38663.171875,-38602.84375,55.0907412924289,19.7384895538051,9.09070491790771,0,0,0,40,20.0205783843994,1,6,1,2.14767456054687,43.9882698059082,,,,,,,,,,,,,,,,
,3737924430.6695,20.0001649856567,-42840.625,7.9426135287806E-5,2.67382435927177E-7,1,0.999253354069792,40.0298881530762,1.99648861433514,16.1700006574392,0.000854024977884157,0.000150154388566369,0.25,-4.71693905389204E-7,7.92689896863711E-5,1.04168527860262E-7,20.0002326965332,20.0002326965332,-42868.25,-42813,54.8625057648135,19.7352475693522,9.09264945983887,0,0,0,40,20.0198936462402,1,6,1,2.15133666992187,44.9657897949219,,,,,,,,,,,,,,,,
,3737924514.628,19.9993553161621,-47055.291015625,9.04637173182016E-5,2.66404170038648E-7,1,0.999253354069792,40.0298881530762,1.99666100378888,16.1700006574392,0.000972796708663735,0.000173400456934933,0.25,-3.32050536846798E-7,9.03228801091757E-5,3.31489595313065E-7,19.9995498657227,19.9995498657227,-47082.83203125,-47027.75,54.6756965487173,19.7375487579573,9.09512329101562,0,0,0,40,20.0190143585205,1,6,1,2.15347290039062,44.4770278930664,,,,,,,,,,,,,,,,
,3737924598.523,20.0001420974731,-51265.37109375,0.000102401516386429,2.85423779608687E-7,1,0.999253354069792,40.0298881530762,1.99653160443049,16.1700006574392,0.00110147498011918,0.000196899953220313,0.25,-3.31276339686077E-7,0.000102285628411063,4.26031478255213E-7,20.0001468658447,20.0001468658447,-51292.94921875,-51237.79296875,54.7499512580443,19.7390610326896,9.09674549102783,0,0,0,40,20.0202503204346,1,6,1,2.16522216796875,44.4770278930664,,,,,,,,,,,,,,,,
,3737924682.4635,19.9997243881226,-55504.087890625,0.000114782791310014,3.92794299751977E-7,1,0.999253354069792,40.0298881530762,1.99687987444506,16.1700006574392,0.0012346929642118,0.000224590730129144,0.25,-2.61766655621125E-8,0.000114698458444689,8.26532235798636E-7,19.9996452331543,19.9996452331543,-55529.359375,-55478.81640625,55.0039805267943,19.7417530971035,9.09804344177246,0,0,0,40,20.0196533203125,1,6,1,2.1624755859375,44.9657897949219,,,,,,,,,,,,,,,,
,3737924766.4245,20.0000553131104,-59750.1953125,0.000127976388926735,3.7810441498882E-7,1,0.999253354069792,40.0298881530762,1.99675118868808,16.1700006574392,0.00137673897959134,0.000252412273874947,0.25,1.47930509840311E-7,0.000127933007637349,1.10026856991759E-6,20.0000553131104,20.0000553131104,-59775.328125,-59725.0625,54.9070585904097,19.7357262808067,9.10087871551514,0,0,0,40,20.0193824768066,1,6,1,2.14431762695313,43.49951171875,,,,,,,,,,,,,,,,
,3737924850.353,20.000807762146,-63991.9453125,0.000141102933802422,3.34057563946176E-7,1,0.999253354069792,40.0298881530762,1.9967226244728,16.1700006574392,0.00151850532178963,0.00027850380068441,0.25,1.73664034265516E-7,0.000141110087332964,1.2225860260033E-6,20.0010166168213,20.0010166168213,-64017.18359375,-63966.70703125,55.0219579827366,19.7380100586229,9.10237979888916,0,0,0,40,20.0186805725098,1,6,1,2.164306640625,44.4770278930664,,,,,,,,,,,,,,,,
,3737924934.285,20.0002689361572,-68235.92578125,0.000154244342145164,4.5223226991835E-7,1,0.999253354069792,40.0298881530762,1.99675930373437,16.1700006574392,0.00165970180665162,0.000309374943215225,0.25,6.41505147575945E-7,0.000154306505998071,1.7841934505878E-6,20.0000114440918,20.0000114440918,-68258.6171875,-68213.234375,55.138420632102,19.7394240702203,9.10494518280029,0,0,0,40,20.0201110839844,1,6,1,2.16156005859375,44.4770278930664,,,,,,,,,,,,,,,,
,3737925018.2065,20.000452041626,-72479.28515625,0.000167728788587042,2.59880163097277E-7,1,0.999253354069792,40.0298881530762,1.9967743302609,16.1700006574392,0.00180559033451265,0.000335793231098648,0.25,6.35691033954846E-7,0.000167856726472519,1.87114557762068E-6,20.0002326965332,20.0002326965332,-72504.59375,-72453.9765625,54.9953826130827,19.7407066685814,9.10630893707275,0,0,0,40,20.0195426940918,1,6,1,2.16354370117187,44.9657897949219,,,,,,,,,,,,,,,,
,3737925102.1435,20.0001316070557,-76720.6640625,0.00018136453364999,4.17174075331482E-7,1,0.999253354069792,40.0298881530762,1.99673996888597,16.1700006574392,0.00195337522964611,0.000361190571716273,0.25,5.11003260124556E-7,0.000181565738370801,1.83641999726867E-6,20.0001602172852,20.0001602172852,-76746.0390625,-76695.2890625,54.667880263525,19.7348896393321,9.10771083831787,0,0,0,40,20.0181636810303,1,6,1,2.1478271484375,43.9882698059082,,,,,,,,,,,,,,,,
,3737925186.1365,20.0000810623169,-80966.859375,0.000195226562825605,4.77160798500724E-7,1,0.999253354069792,40.0298881530762,1.99661410561984,16.1700006574392,0.00210346984222637,0.000387555478534688,0.25,4.39579061325283E-7,0.00019550689897601,1.85261426675254E-6,20.0000343322754,20.0000343322754,-80992.140625,-80941.578125,55.4667046101789,19.735965469671,9.10988426208496,0,0,0,40,20.0170955657959,1,6,1,2.15438842773438,44.4770278930664,,,,,,,,,,,,,,,,
,3737925270.023,20.0002346038818,-85207.7734375,0.000209397251516943,4.18459293287507E-7,1,0.999253354069792,40.0298881530762,1.99667282516844,16.1700006574392,0.00225572496720538,0.000422289778704333,0.25,1.08833987529849E-6,0.000209757356553508,2.58834966257061E-6,20.0002727508545,20.0002727508545,-85232.984375,-85182.5625,54.9586460726789,19.7356680566179,9.11139392852783,0,0,0,40,20.0174655914307,1,6,1,2.16583251953125,44.4770278930664,,,,,,,,,,,,,,,,
,3737925353.949,20.0005187988281,-89448.38671875,0.000222820447578245,5.26444541843609E-7,1,0.999253354069792,40.0298881530762,1.9966954810205,16.1700006574392,0.0024010745040164,0.000449310109807859,0.25,1.16124493040414E-6,0.000223267850703236,2.73796955958087E-6,20.000373840332,20.000373840332,-89473.7109375,-89423.0625,55.1649960017558,19.7374699971378,9.11404228210449,0,0,0,40,20.0167598724365,1,6,1,2.15530395507813,44.4770278930664,,,,,,,,,,,,,,,,
,3737925446.893,19.9999361038208,-86425.32421875,0.000212701577181698,4.2759929081694E-7,1,0.999253354069792,40.0298881530762,1.99672616698433,16.1700006574392,0.0022916163673836,0.000428754933339215,0.25,1.08810628890961E-6,0.000213085455375888,2.60659492617331E-6,19.9999885559082,19.9999885559082,-86450.265625,-86400.3828125,55.1618694876789,19.7378173147053,9.11555862426758,0,0,0,40,20.0173816680908,1,6,1,2.16445922851562,44.9657897949219,,,,,,,,,,,,,,,,
,3737925530.8335,20.0001974105835,-82247.07421875,0.000199416925568277,3.92457141884356E-7,1,0.999253354069792,40.0298881530762,1.99683585669947,16.1700006574392,0.0021480156072669,0.000401621755192535,0.25,9.79598816157072E-7,0.000199718161837492,2.41918861771323E-6,20.0001888275146,20.0001888275146,-82271.9453125,-82222.203125,54.9742786430635,19.7379599573708,9.11685943603516,0,0,0,40,20.017858505249,1,6,1,2.17147827148438,43.9882698059082,,,,,,,,,,,,,,,,
,3737925614.7725,19.9999418258667,-78063.421875,0.000185594527054347,3.37911978518305E-7,1,0.999253354069792,40.0298881530762,1.99679319114169,16.1799993366003,0.00199935396636675,0.000368771183291862,0.25,4.44263162062577E-7,0.00018582027092131,1.79665745313425E-6,19.9999847412109,19.9999847412109,-78088.3046875,-78038.5390625,54.972715386025,19.7393386334504,9.11925506591797,0,0,0,40,20.0175132751465,1,6,1,2.15118408203125,45.4545478820801,,,,,,,,,,,,,,,,
,3737925698.719,19.9993696212769,-73881.92578125,0.000172271131707461,3.39503511543821E-7,1,0.999253354069792,40.0298881530762,1.99665520454109,16.1700006574392,0.00185480022686097,0.000343776943328013,0.25,5.51221841202556E-7,0.000172422954832998,1.81706916152667E-6,19.9992790222168,19.9992790222168,-73904.3671875,-73859.484375,54.8718853070443,19.7364872772952,9.12018203735352,0,0,0,40,20.018856048584,1,6,1,2.15255737304687,44.4770278930664,,,,,,,,,,,,,,,,
,3737925782.635,19.9998626708984,-69703.4375,0.000158969060945023,3.58784889213925E-7,1,0.999253354069792,40.0298881530762,1.99677615981584,16.1700006574392,0.00171177609533205,0.000313362021734052,0.25,1.49767909523654E-7,0.000159056847324463,1.32513122865328E-6,20.000020980835,20.000020980835,-69725.765625,-69681.109375,55.0172682116212,19.7393540889374,9.12095546722412,0,0,0,40,20.0191860198975,1,6,1,2.14889526367187,44.4770278930664,,,,,,,,,,,,,,,,
,3737925866.602,19.999324798584,-65519.154296875,0.000145829941392944,4.05172752244748E-7,1,0.999253354069792,40.0298881530762,1.99670383512472,16.1700006574392,0.00156967825078005,0.000287308941429331,0.25,1.2859333702194E-7,0.000145857620532778,1.21154314444168E-6,19.9992046356201,19.9992046356201,-65546.7421875,-65491.56640625,55.0618210372174,19.738067226211,9.12181377410889,0,0,0,40,20.0186100006104,1,6,1,2.15225219726562,44.9657897949219,,,,,,,,,,,,,,,,
,3737925950.581,19.9995632171631,-61334.623046875,0.000132528203762416,3.48160246565377E-7,1,0.999253354069792,40.0298881530762,1.99681661558117,16.1700006574392,0.00142533365528954,0.000264882245730594,0.25,4.7358976071771E-7,0.000132500459486627,1.45967062973905E-6,19.9996166229248,19.9996166229248,-61361.93359375,-61307.3125,54.9375421026597,19.73701877718,9.12274551391602,0,0,0,40,20.0188007354736,1,6,1,2.1661376953125,44.9657897949219,,,,,,,,,,,,,,,,
,3737926034.445,19.9992303848267,-57158.21484375,0.000119031235514064,3.56391073282292E-7,1,0.999253354069792,40.0298881530762,1.99674863751085,16.1700006574392,0.00128046109754125,0.000233235855872376,0.25,8.46692055118994E-10,0.000118962608778077,8.86029245816293E-7,19.9994087219238,19.9994087219238,-57183.18359375,-57133.24609375,55.0868331498328,19.7352183281356,9.12364673614502,0,0,0,40,20.019510269165,1,6,1,2.16567993164062,44.4770278930664,,,,,,,,,,,,,,,,
,3737926118.372,20.0009059906006,-52979.37890625,0.000106237023489764,3.61994949547538E-7,1,0.999253354069792,40.0298881530762,1.99684760087269,16.1799993366003,0.00114242539908209,0.000208040822222028,0.25,-1.37926311915643E-9,0.000106132439077936,7.85808480767192E-7,20.0010166168213,20.0010166168213,-53004.30078125,-52954.45703125,55.0024172697558,19.7351008613504,9.12495136260986,0,0,0,40,20.0199012756348,1,6,1,2.16995239257813,44.4770278930664,,,,,,,,,,,,,,,,
,3737926202.3445,19.9996728897095,-48795.66015625,9.29127739316319E-5,3.72902305175998E-7,1,0.999253354069792,40.0298881530762,1.99667047185922,16.1700006574392,0.000999230133285352,0.00017859739901322,0.25,-2.9991013308991E-7,9.27843927435263E-5,3.84186677149375E-7,19.9996299743652,19.9996299743652,-48820.5859375,-48770.734375,54.8836097348327,19.7317109957891,9.12559986114502,0,0,0,40,20.0194892883301,1,6,1,2.1661376953125,44.4770278930664,,,,,,,,,,,,,,,,
,3737926286.3025,19.9999570846558,-44612.251953125,8.00759675931119E-5,3.69395305066726E-7,1,0.999253354069792,40.0298881530762,1.99683597118392,16.1700006574392,0.00086136837389942,0.000151141330971063,0.25,-5.06222633842738E-7,7.99325891934967E-5,7.76590433275981E-8,19.9999446868896,19.9999446868896,-44637.10546875,-44587.3984375,54.9492665304481,19.7386274389212,9.1266622543335,0,0,0,40,20.0207214355469,1,6,1,2.15103149414062,44.4770278930664,,,,,,,,,,,,,,,,
,3737926370.1865,19.9996128082275,-40435.90625,6.74621629302532E-5,2.75658743267683E-7,1,0.999253354069792,40.0298881530762,1.99662820568556,16.1700006574392,0.000725462061066038,0.000126330029096161,0.25,-5.06493035494462E-7,6.73123719032608E-5,-2.14216297179289E-8,19.99973487854,19.99973487854,-40458.28515625,-40413.52734375,55.077453607602,19.737295859178,9.12765026092529,0,0,0,40,20.0198535919189,1,6,1,2.14736938476562,44.4770278930664,,,,,,,,,,,,,,,,
,3737926454.1345,19.9996242523193,-36252.150390625,5.46068584168101E-5,3.33878895507606E-7,1,0.999253354069792,40.0298881530762,1.99655004687567,16.1700006574392,0.000587247859347907,0.000100501183489707,0.25,-5.6162744635846E-7,5.44624628716566E-5,-1.75887866419277E-7,19.9996681213379,19.9996681213379,-36279.54296875,-36224.7578125,55.0813617501981,19.7331104588105,9.1284351348877,0,0,0,40,20.0198860168457,1,6,1,2.15957641601562,43.9882698059082,,,,,,,,,,,,,,,,
,3737926538.055,20.0000371932983,-32070.7978515625,4.23446963275225E-5,2.76402644287222E-7,1,0.999253354069792,40.0298881530762,1.99670835999453,16.1700006574392,0.000455519488213677,7.62021317418196E-5,0.25,-5.87134955164381E-7,4.22149699519378E-5,-2.94468204638502E-7,20.0000190734863,20.0000190734863,-32095.701171875,-32045.89453125,54.9946009845635,19.7334451851426,9.12988376617432,0,0,0,40,20.020471572876,1,6,1,2.1624755859375,44.4770278930664,,,,,,,,,,,,,,,,
,3737926622.016,20.0000839233398,-27892.2099609375,2.93924862757181E-5,2.57946970423982E-7,1,0.999253354069792,40.0298881530762,1.99675283335292,16.1700006574392,0.000317345775744932,4.57483510053546E-5,0.25,-1.06583015683898E-6,2.92938926003719E-5,-8.65997981272102E-7,20.0000648498535,20.0000648498535,-27917.029296875,-27867.390625,54.7241575169096,19.7363035290806,9.13081359863281,0,0,0,40,20.0204772949219,1,6,1,2.16766357421875,43.9882698059082,,,,,,,,,,,,,,,,
,3737926705.927,19.9998760223389,-23710.6748046875,1.7167734008493E-5,2.21586853627999E-7,1,0.999253354069792,40.0298881530762,1.99684630370351,16.1700006574392,0.000185792265540375,2.39041182784599E-5,0.25,-8.80336242329067E-7,1.71043126411598E-5,-7.66259306114584E-7,19.9997673034668,19.9997673034668,-23733.064453125,-23688.28515625,54.962554215275,19.7383193735464,9.1312084197998,0,0,0,40,20.0208053588867,1,6,1,2.15972900390625,44.9657897949219,,,,,,,,,,,,,,,,
,3737926789.882,20.0000305175781,-19528.86328125,4.40313011648688E-6,2.65198463575807E-7,1,0.999253354069792,40.0298881530762,1.99676614159072,16.1700006574392,4.85768821826909E-5,8.8820808653926E-7,0.25,-7.1352164145124E-7,4.38800084196876E-6,-6.83141630432231E-7,19.9999694824219,19.9999694824219,-19553.7890625,-19503.9375,55.0969943205828,19.7409836008006,9.13193988800049,0,0,0,40,20.0202808380127,1,6,1,2.14370727539062,44.4770278930664,,,,,,,,,,,,,,,,
,3737926873.7995,20.000280380249,-15349.775390625,-9.413732048799E-6,2.38466178697527E-7,1,0.999253354069792,40.0298881530762,1.9967469812349,16.1700006574392,-9.88223099773126E-5,-2.95123521459832E-5,0.25,-1.05452758480941E-6,-9.36204740368757E-6,-1.10496411081633E-6,20.000373840332,20.000373840332,-15374.65625,-15324.89453125,54.7179044887558,19.7378410597053,9.13288688659668,0,0,0,40,20.0204925537109,1,6,1,2.16171264648438,44.4770278930664,,,,,,,,,,,,,,,,
,3737926957.737,19.9999485015869,-11162.6479492187,-2.28185973281558E-5,2.2521494916952E-7,1,0.999253354069792,40.0298881530762,1.99658673902282,16.1700006574392,-0.000241805812948545,-5.84044498111336E-5,0.25,-1.33963024585369E-6,-2.26925605289917E-5,-1.4604318003612E-6,19.9999580383301,19.9999580383301,-11187.5712890625,-11137.724609375,55.3955764149289,19.7345463129503,9.13435459136963,0,0,0,40,20.0212306976318,1,6,1,2.14950561523438,44.9657897949219,,,,,,,,,,,,,,,,
,3737927041.675,19.9996881484985,-6972.41870117187,-3.73652315433108E-5,2.65259833860624E-7,1,0.999253354069792,40.0298881530762,1.99670152438252,16.1700006574392,-0.000398062977030702,-8.33229303076545E-5,0.25,-1.05747639372931E-6,-3.71532127639959E-5,-1.24937610161231E-6,19.9996185302734,19.9996185302734,-6994.8447265625,-6949.99267578125,55.1266962043135,19.738743368868,9.13504791259766,0,0,0,40,20.020149230957,1,6,1,2.16522216796875,44.4770278930664,,,,,,,,,,,,,,,,
,3737927128.6635,20.0001878738403,-2626.74145507813,-5.36546445193456E-5,3.13987029389428E-7,1,0.999253354069792,40.0298881530762,1.99683960211104,16.1700006574392,-0.000572141188577878,-0.000115906825232255,0.25,-1.18781601524275E-6,-5.3336746668561E-5,-1.44858070844303E-6,20.0001926422119,20.0001926422119,-2654.24658203125,-2599.236328125,54.9039320763327,19.7405179175174,9.13543224334717,0,0,0,40,20.0200138092041,1,6,1,2.166748046875,44.9657897949219,,,,,,,,,,,,,,,,
,3737927215.5905,20.0001125335693,1718.56884765625,-7.7544765813362E-5,2.40232551341619E-7,1,0.999253354069792,40.0298881530762,1.9967677099869,16.1700006574392,-0.00082755923340523,-0.000163392889468879,0.25,-1.3373576726039E-6,-7.70833514529517E-5,-1.71196255315765E-6,20.0001373291016,20.0001373291016,1693.51806640625,1743.61962890625,55.0938678065058,19.7367336547208,9.13700103759766,0,0,0,40,20.0199222564697,1,6,1,2.16552734375,44.9657897949219,,,,,,,,,,,,,,,,
,3737927302.5475,20.0003776550293,6063.859375,-9.2802470171811E-5,2.2229477706561E-7,1,0.999253354069792,40.0298881530762,1.99672927467792,16.1700006574392,-0.000991081287570686,-0.000193150738322456,0.25,-1.34515526497759E-6,-9.22766588563018E-5,-1.82265369837252E-6,20.0004329681396,20.0004329681396,6043.8369140625,6083.8818359375,54.7960673406789,19.7367186834123,9.13767051696777,0,0,0,40,20.0206184387207,1,6,1,2.15103149414062,44.4770278930664,,,,,,,,,,,,,,,,
,3737927389.4435,19.999418258667,10411.5615234375,-0.000102077979441811,2.3446269307145E-7,1,0.999253354069792,40.0298881530762,1.99687165250343,16.1700006574392,-0.00109090178219134,-0.000210728732296751,0.25,-1.27797945036361E-6,-0.000101534297710821,-1.83718737086678E-6,19.999418258667,19.999418258667,10384.0400390625,10439.0830078125,54.8922076485443,19.7388069999186,9.13881397247314,0,0,0,40,20.0191268920898,1,6,1,2.16567993164062,44.9657897949219,,,,,,,,,,,,,,,,
,3737927473.3935,20.0004816055298,14608.8110351562,-0.000104161556060559,2.35974189147262E-7,1,0.999253354069792,40.0298881530762,1.9967770940601,16.1700006574392,-0.00111300688571698,-0.000217938600882479,0.25,-1.53773418289452E-6,-0.000103642549241739,-2.13921208215054E-6,20.0003814697266,20.0003814697266,14583.888671875,14633.7333984375,54.7648021999096,19.7358938779807,9.13777637481689,0,0,0,40,20.0198383331299,1,6,1,2.1661376953125,44.9657897949219,,,,,,,,,,,,,,,,
,3737927557.314,20.0003213882446,18804.1162109375,-9.70375570759838E-5,2.84226379846125E-7,1,0.999253354069792,40.0298881530762,1.9968179821581,16.1700006574392,-0.00103756253015155,-0.000201704478710282,0.25,-1.27317242731736E-6,-9.65923781837862E-5,-1.86258931246859E-6,20.0002746582031,20.0002746582031,18779.171875,18829.060546875,54.9156565041212,19.7352440327213,9.13887977600098,0,0,0,40,20.0206031799316,1,6,1,2.16567993164062,44.9657897949219,,,,,,,,,,,,,,,,
,3737927641.216,20.0004281997681,22999.73828125,-8.29516637912843E-5,3.05949872835537E-7,1,0.999253354069792,40.0298881530762,1.99681520599275,16.1700006574392,-0.000885873322555717,-0.000180454822892195,0.25,-1.80895122522635E-6,-8.26003368296911E-5,-2.33214476148665E-6,20.0003471374512,20.0003471374512,22974.552734375,23024.923828125,55.4104273567943,19.7391646623919,9.13933849334717,0,0,0,40,20.0202465057373,1,6,1,2.15042114257813,44.9657897949219,,,,,,,,,,,,,,,,
,3737927725.1695,19.9999542236328,27204.2861328125,-7.01220406682627E-5,2.71964393923713E-7,1,0.999253354069792,40.0298881530762,1.99671497440177,16.1700006574392,-0.000749077604935119,-0.000152971533025516,0.25,-1.54712695210399E-6,-6.98546115731599E-5,-2.00654241873005E-6,19.9999389648438,19.9999389648438,27179.265625,27229.306640625,54.9367604741404,19.7337514176366,9.13829040527344,0,0,0,40,20.0208568572998,1,6,1,2.1661376953125,44.4770278930664,,,,,,,,,,,,,,,,
,3737927809.1,20.0000448226929,31414.9052734375,-6.49503680923932E-5,2.58831871854279E-7,1,0.999253354069792,40.0298881530762,1.99695786683524,16.1700006574392,-0.000694229279199185,-0.000141692168853307,0.25,-1.41272562447764E-6,-6.47310552394143E-5,-1.85232813455152E-6,20.0000381469727,20.0000381469727,31389.884765625,31439.92578125,54.955519558602,19.7395637266384,9.13899421691895,0,0,0,40,20.0203227996826,1,6,1,2.16217041015625,45.9433059692383,,,,,,,,,,,,,,,,
,3737927893.0715,20.0005226135254,35629.361328125,-6.69745830168178E-5,2.56482367135453E-7,1,0.999253354069792,40.0298881530762,1.99677676442241,16.1700006574392,-0.000716045988528199,-0.000146576282275167,0.25,-1.48398293882414E-6,-6.67778131434467E-5,-1.94954161514245E-6,20.0005054473877,20.0005054473877,35606.84765625,35651.875,55.1110636339289,19.7370728992632,9.13751602172852,0,0,0,40,20.0195808410645,1,6,1,2.1478271484375,43.9882698059082,,,,,,,,,,,,,,,,
,3737927976.9555,20.0001077651978,39842.693359375,-7.35613284986158E-5,3.53513574949904E-7,1,0.999253354069792,40.0298881530762,1.99680992182138,16.1799993366003,-0.000787088450943868,-0.000159640698628258,0.25,-1.48693471997739E-6,-7.33787909109193E-5,-2.00983675258423E-6,20.0000877380371,20.0000877380371,39817.59375,39867.79296875,54.9242544178327,19.7373747773251,9.13830852508545,0,0,0,40,20.0203590393066,1,6,1,2.1417236328125,43.49951171875,,,,,,,,,,,,,,,,
,3737928060.951,20.0003662109375,44055.7890625,-8.33221484605308E-5,3.47870340757161E-7,1,0.999253354069792,40.0298881530762,1.99679318595724,16.1700006574392,-0.000892016685985927,-0.000180336099418442,0.25,-1.62250525461534E-6,-8.31525024878259E-5,-2.22497101734617E-6,20.0003318786621,20.0003318786621,44033.1875,44078.390625,54.853907851102,19.7337367823294,9.13900566101074,0,0,0,40,20.0198268890381,1,6,1,2.15042114257813,44.9657897949219,,,,,,,,,,,,,,,,
,3737928144.8605,20.0000877380371,48270.103515625,-9.4410549963661E-5,3.08137535040286E-7,1,0.999253354069792,40.0298881530762,1.99677617427751,16.1799993366003,-0.00101105069123609,-0.000205005113060536,0.25,-1.88515236256747E-6,-9.42589364814279E-5,-2.57631280718908E-6,20.0000419616699,20.0000419616699,48245.0546875,48295.15234375,55.1368573750635,19.7371371204442,9.13821506500244,0,0,0,40,20.0190143585205,1,6,1,2.14706420898438,44.9657897949219,,,,,,,,,,,,,,,,
,3737928228.7695,20.0005207061768,52484.8984375,-0.000106618784482146,3.21013413130297E-7,1,0.999253354069792,40.0298881530762,1.99692276300724,16.1700006574392,-0.00114212326208233,-0.000232902500172617,0.25,-2.24180907061245E-6,-0.000106491973502904,-3.02899969948983E-6,20.0007171630859,20.0007171630859,52459.62890625,52510.16796875,55.2032957991982,19.7368072843906,9.13891220092773,0,0,0,40,20.0200214385986,1,6,1,2.16156005859375,45.4545478820801,,,,,,,,,,,,,,,,
,3737928312.733,19.9999561309814,56729.529296875,-0.000119327108339709,3.86589635496882E-7,1,0.999253354069792,40.0298881530762,1.99681873523239,16.1700006574392,-0.00127970521341046,-0.000255382546308833,0.25,-2.0060540052804E-6,-0.000119238482515847,-2.89199638923981E-6,20.0000152587891,20.0000152587891,56706.75390625,56752.3046875,54.8109182825443,19.7376238265005,9.13906764984131,0,0,0,40,20.0194034576416,1,6,1,2.15240478515625,44.4770278930664,,,,,,,,,,,,,,,,
,3737928396.678,19.999885559082,60977.15625,-0.000132337326349785,2.8168358436432E-7,1,0.999253354069792,40.0298881530762,1.99665673986644,16.1700006574392,-0.00141858220636021,-0.000289414082853881,0.25,-2.79070506964752E-6,-0.000132287991667213,-3.77490439941031E-6,19.9997882843018,19.9997882843018,60949.3515625,61004.9609375,54.9609909582366,19.7381396266233,9.13987350463867,0,0,0,40,20.0200271606445,1,6,1,2.15301513671875,44.4770278930664,,,,,,,,,,,,,,,,
,3737928480.6545,19.9999198913574,65222.3359375,-0.000145529662365703,2.52994820622023E-7,1,0.999253354069792,40.0298881530762,1.99664634468692,16.1700006574392,-0.0015614411697974,-0.000313720403267624,0.25,-2.63791989232968E-6,-0.00014553480780789,-3.71930853535222E-6,19.9997978210449,19.9997978210449,65191.9921875,65252.6796875,54.9742786430635,19.7354645740958,9.14053630828857,0,0,0,40,20.0189418792725,1,6,1,2.16567993164062,44.9657897949219,,,,,,,,,,,,,,,,
,3737928564.5235,20.0002107620239,69464.73046875,-0.000159147803529875,4.22860861340453E-7,1,0.999253354069792,40.0298881530762,1.99673842576864,16.1700006574392,-0.00170913140742304,-0.000338436869401013,0.25,-2.44628088756427E-6,-0.000159215483006985,-3.62456695103579E-6,20.0000305175781,20.0000305175781,69439.453125,69490.0078125,55.0289926394097,19.7325070207442,9.14136409759522,0,0,0,40,20.0183086395264,1,6,1,2.16033935546875,44.9657897949219,,,,,,,,,,,,,,,,
,3737928648.4835,20.000020980835,73711.88671875,-0.000173016883245686,3.67058298188903E-7,1,0.999253354069792,40.0298881530762,1.9966454842691,16.1799993366003,-0.00185915640617486,-0.000365248885175139,0.25,-2.40880922383226E-6,-0.000173153355571399,-3.68216669402989E-6,20.0000305175781,20.0000305175781,73686.6015625,73737.171875,54.8734485640827,19.735497054831,9.14186191558838,0,0,0,40,20.0180931091309,1,6,1,2.14736938476562,44.9657897949219,,,,,,,,,,,,,,,,
,3737928732.4475,19.9996700286865,77957.69140625,-0.000186520683712498,4.09195015142345E-7,1,0.999253354069792,40.0298881530762,1.99669830928221,16.1700006574392,-0.00200544154584394,-0.000391378284745621,0.25,-2.37497874573556E-6,-0.000186731990454287,-3.73679789323982E-6,19.9996185302734,19.9996185302734,77934.8828125,77980.5,54.9695888719481,19.7301689021084,9.14253520965576,0,0,0,40,20.0176734924316,1,6,1,2.14569091796875,44.9657897949219,,,,,,,,,,,,,,,,
,3737928816.3615,20.0004453659058,82199.80859375,-0.000200000610785615,4.28159334687081E-7,1,0.999253354069792,40.0298881530762,1.99669547242358,16.1700006574392,-0.00214994981680371,-0.000425867882772116,0.25,-3.12497111350396E-6,-0.000200286588840039,-4.57225096234534E-6,20.0004367828369,20.0004367828369,82171.96875,82227.6484375,54.881264849275,19.7356257094937,9.14317512512207,0,0,0,40,20.018367767334,1,6,1,2.16018676757813,44.9657897949219,,,,,,,,,,,,,,,,
,3737928900.2675,20.0003395080566,86444.33984375,-0.000214037072879062,4.3186361636567E-7,1,0.999253354069792,40.0298881530762,1.99678745664085,16.1700006574392,-0.00230218439084931,-0.000452860370930037,0.25,-3.07942847408003E-6,-0.000214409493547974,-4.61102542253285E-6,20.0003547668457,20.0003547668457,86419.09375,86469.5859375,55.2775505085251,19.7363377634899,9.14346408843994,0,0,0,40,20.0180187225342,1,6,1,2.16354370117187,44.9657897949219,,,,,,,,,,,,,,,,
,3737928974.264,20.000036239624,90001.2421875,-0.000228666229510716,8.02679459030934E-7,1,0.999253354069792,40.0298881530762,1.99678683654222,16.1700006574392,-0.00246278441633595,-0.000469276783527513,0.25,-1.94934401838951E-6,-0.000229128343798122,-3.56628486099521E-6,20.0001010894775,20.0001010894775,90000.5859375,90001.8984375,55.0508782379481,19.7375542962417,9.14413452148438,0,0,0,40,20.0175323486328,1,4,1,2.16506958007813,44.9657897949219,,,,,,,,,,,,,,,,