File: data/doubleLayers/dl_2-5/ppms/DD205_5/DD205_5_ZFCW_100OE.DAT
[Header]
; VSM Data File (default extension .dat)
; Copyright (c) 2003-2013, Quantum Design, Inc. All rights reserved.
TITLE,
FILEOPENTIME,3737870434.98326,06/11/2018,9:22 am
BYAPP,VSM,1.0,1.0
INFO,DYNACOOL VSM Option Release 1.4.10 Build 1,APPNAME
INFO,Quantum Design Linear Motor Servo Controller,MOTOR_MODULE_NAME
INFO,3101-100 J0,MOTOR_HW_VERSION
INFO,MMC654,MOTOR_SERIAL_NUMBER
INFO,SRV No X-over 01.03.11,MOTOR_SOFTWARE_VERSION
INFO,Quantum Design VSM Detection Module,VSM_MODULE_NAME
INFO,3101-150 F0,VSM_HW_VERSION
INFO,VSM507,VSM_SERIAL_NUMBER
INFO,VSM No X-over 01.02.05 May 20 2008 13:51:47,VSM_SOFTWARE_VERSION
INFO,494,PREAMP_SERIAL_NUMBER
INFO,Quantum Design VSM Oven,OVEN_MODULE_NAME
INFO,3101-201 A1,OVEN_HW_VERSION
INFO,OVB210,OVEN_SERIAL_NUMBER
INFO,01.06.24,OVEN_SOFTWARE_VERSION
INFO,593,COIL_SERIAL_NUMBER
INFO,0,MOMENT_UNITS
INFO,CoFe2O4,SAMPLE_MATERIAL
INFO,,SAMPLE_COMMENT
INFO,,SAMPLE_MASS
INFO,,SAMPLE_VOLUME
INFO,,SAMPLE_MOLECULAR_WEIGHT
INFO,,SAMPLE_SIZE
INFO,,SAMPLE_SHAPE
DATATYPE,COMMENT,1
DATATYPE,TIME,2
STARTUPAXIS,X,2
STARTUPAXIS,Y1,5
[Data]
Comment,Time Stamp (sec),Temperature (K),Magnetic Field (Oe),Moment (emu),M. Std. Err. (emu),Transport Action,Averaging Time (sec),Frequency (Hz),Peak Amplitude (mm),Center Position (mm),Coil Signal' (mV),Coil Signal" (mV),Range (mV),M. Quad. Signal (emu),M. Raw' (emu),M. Raw" (emu),Min. Temperature (K),Max. Temperature (K),Min. Field (Oe),Max. Field (Oe),Mass (grams),Motor Lag (deg),Pressure (Torr),VSM Status (code),Motor Status (code),Measure Status (code),Measure Count,System Temp. (K),Temp. Status (code),Field Status (code),Chamber Status (code),Motor Current (amps),Motor Heatsink Temp. (C),Map 01,Map 02,Map 03,Map 04,Map 05,Map 06,Map 07,Map 08,Map 09,Map 10,Map 11,Map 12,Map 13,Map 14,Map 15,Map 16
sample offset = 32.87 mm touchdown = 8.20000004023314 mm,3737873214.958,5.00243997573853,99.6990966796875,-3.3385513589877E-6,2.83782067714803E-7,1,0.999253354069792,40.0298881530762,2.00082743980619,16.1700006574392,-3.41083515077176E-5,-1.58924677260728E-5,0.25,-8.82600101374167E-7,-3.31450085642226E-6,-8.93465308636679E-7,5.00243997573853,5.00243997573853,99.6990966796875,99.6990966796875,55.1696857728712,19.6748753080561,8.48134899139404,0,0,0,40,5.00663089752197,1,4,1,2.1563720703125,33.2355842590332,,,,,,,,,,,,,,,,
,3737873338.404,8.00992631912231,99.6990966796875,-3.34467228726142E-6,3.30111092547484E-7,1,0.999253354069792,40.0298881530762,2.00091229172465,16.1799993366003,-3.34450267533049E-5,-1.99740290464429E-5,0.25,-1.26198181573981E-6,-3.31874967767108E-6,-1.27062466309055E-6,8.00175094604492,8.00175094604492,99.6990966796875,99.6990966796875,54.3653900265827,19.6838890435559,9.80155658721924,0,0,0,40,8.09076023101807,2,4,1,2.1533203125,40.0782012939453,,,,,,,,,,,,,,,,
,3737873478.2415,11.5143795013428,99.6990966796875,-3.51832458085269E-6,2.93355155323183E-7,1,0.999253354069792,40.0298881530762,2.00077016684107,16.1799993366003,-3.62278653910915E-5,-1.51647057690785E-5,0.25,-7.82530868529054E-7,-3.49366602151882E-6,-7.94850635028743E-7,11.5060987472534,11.5060987472534,99.6990966796875,99.6990966796875,55.3932315293713,19.6812480720687,11.1168022155762,0,0,0,40,11.5973958969116,2,4,1,2.15469360351562,41.5444793701172,,,,,,,,,,,,,,,,
,3737873618.1535,15.0038089752197,99.8624229431152,-3.14526691386556E-6,3.56576989105959E-7,1,0.999253354069792,40.0298881530762,2.00063938228437,16.1799993366003,-3.15605613583693E-5,-1.81454175999008E-5,0.25,-1.12752303377914E-6,-3.12113407607915E-6,-1.13598684987414E-6,14.987307548523,14.987307548523,99.8442764282227,99.8805694580078,54.813263168102,19.6809742839381,12.2386131286621,0,0,0,40,15.1146717071533,2,4,1,2.16110229492187,43.0107536315918,,,,,,,,,,,,,,,,
,3737873758.0825,18.5188627243042,99.8624229431152,-3.50561011512881E-6,1.99868690988512E-7,1,0.999253354069792,40.0298881530762,2.00056528347326,16.1799993366003,-3.5635633192916E-5,-1.76555426389306E-5,0.25,-1.01723469837644E-6,-3.47983471561315E-6,-1.02809443192653E-6,18.5065326690674,18.5065326690674,99.8442764282227,99.8805694580078,55.1571797165635,19.682603573549,13.0040893554687,0,0,0,40,18.6931076049805,2,4,1,2.15621948242187,43.49951171875,,,,,,,,,,,,,,,,
,3737873901.9545,22.0061941146851,99.8684692382813,-3.32054567716975E-6,2.78495339201756E-7,1,0.999253354069792,40.0298881530762,2.00040608170716,16.1799993366003,-3.34999545652892E-5,-1.81320258493899E-5,0.25,-1.09465306630683E-6,-3.29559831699339E-6,-1.10449478867464E-6,21.9989147186279,21.9989147186279,99.8563690185547,99.8805694580078,54.9180013896789,19.6807842915884,14.0073289871216,0,0,0,40,22.2028865814209,2,4,1,2.15682983398438,43.49951171875,,,,,,,,,,,,,,,,
,3737874042.828,25.5063228607178,99.8745193481445,-3.0980906244292E-6,2.7375555395151E-7,1,0.999253354069792,40.0298881530762,2.00026554699688,16.1799993366003,-3.11835367196317E-5,-1.73234572217908E-5,0.25,-1.05851427542307E-6,-3.0749051010783E-6,-1.06821231265382E-6,25.4895191192627,25.4895191192627,99.8684692382813,99.8805694580078,54.9000239337366,19.6829131489778,14.8349027633667,0,0,0,40,25.7349338531494,2,4,1,2.15774536132813,43.9882698059082,,,,,,,,,,,,,,,,
,3737874183.7245,29.005181312561,99.8503227233887,-3.62644052634276E-6,2.75042038221502E-7,1,0.999253354069792,40.0298881530762,2.00020772522619,16.1799993366003,-3.69488506412281E-5,-1.78255923428635E-5,0.25,-1.00897279739141E-6,-3.60114667711271E-6,-1.02295972417931E-6,28.9886913299561,28.9886913299561,99.8321762084961,99.8684692382813,54.6530293216596,19.6802090392517,15.5603818893433,0,0,0,40,29.2929363250732,2,4,1,2.16018676757813,43.9882698059082,,,,,,,,,,,,,,,,
,3737874324.602,32.5028781890869,99.9229125976563,-3.12033209531193E-6,2.76515414723292E-7,1,0.999253354069792,40.0298881530762,2.00001800227733,16.1799993366003,-3.14652267471104E-5,-1.71911629824415E-5,0.25,-1.03932976187844E-6,-3.09851701417912E-6,-1.05202574170144E-6,32.4877166748047,32.4877166748047,99.916862487793,99.9289627075195,54.4998301318904,19.6814203397291,16.2015514373779,0,0,0,40,32.8485412597656,2,4,1,2.16171264648438,43.9882698059082,,,,,,,,,,,,,,,,
,3737874466.506,36.020658493042,99.8926696777344,-2.99307006601524E-6,3.4484277438506E-7,1,0.999253354069792,40.0298881530762,2.0000484881398,16.1799993366003,-3.00169710844316E-5,-1.74832659988501E-5,0.25,-1.08733422880827E-6,-2.97285075546286E-6,-1.10098743251969E-6,36.0054244995117,36.0054244995117,99.8805694580078,99.9047698974609,54.9672439863904,19.6805766221907,16.8033466339111,0,0,0,40,36.4260787963867,2,4,1,2.15744018554687,43.9882698059082,,,,,,,,,,,,,,,,
,3737874607.4295,39.5098819732666,99.9289627075195,-3.43969819805828E-6,2.9069777805412E-7,1,0.999253354069792,40.0298881530762,1.99998887624622,16.1700006574392,-3.47186047724666E-5,-1.89820256180567E-5,0.25,-1.14347451309877E-6,-3.41914819247327E-6,-1.16201867744459E-6,39.5006637573242,39.5006637573242,99.916862487793,99.9410629272461,55.013360069025,19.6808519414631,17.3474235534668,0,0,0,40,39.9953346252441,2,4,1,2.14874267578125,44.4770278930664,,,,,,,,,,,,,,,,
,3737874748.2905,43.0040607452393,99.910816192627,-3.39639919826421E-6,3.08882022756603E-7,1,0.999253354069792,40.0298881530762,2.00002248916726,16.1799993366003,-3.40146504161707E-5,-2.03766473307653E-5,0.25,-1.27818497744411E-6,-3.37767987239825E-6,-1.29842446333529E-6,42.988883972168,42.988883972168,99.9047698974609,99.916862487793,54.8015387403135,19.6828342140611,17.8447647094727,0,0,0,40,43.5413436889648,2,4,1,2.1533203125,44.4770278930664,,,,,,,,,,,,,,,,
,3737874890.1585,46.5112457275391,99.8987197875977,-3.02530954013827E-6,2.37705605853416E-7,1,0.999253354069792,40.0298881530762,1.99991499814212,16.1799993366003,-3.11861818711329E-5,-1.34352920851406E-5,0.25,-6.97909965177657E-7,-3.01466545083782E-6,-7.18767622965488E-7,46.5029640197754,46.5029640197754,99.8926696777344,99.9047698974609,54.8038836258712,19.6824994428422,18.3009090423584,0,0,0,40,47.1413726806641,2,4,1,2.15621948242187,44.9657897949219,,,,,,,,,,,,,,,,
,3737875031.06,50.00146484375,99.8987159729004,-3.41172094313907E-6,2.76717343446214E-7,1,0.999253354069792,40.0298881530762,1.99986324653813,16.1799993366003,-3.41312633306806E-5,-2.10685982434181E-5,0.25,-1.33452127946052E-6,-3.39927453552399E-6,-1.35890766713074E-6,49.9930992126465,49.9930992126465,99.8684692382813,99.9289627075195,55.0477517238712,19.6824004777927,18.7387828826904,0,0,0,40,50.715015411377,2,4,1,2.15682983398438,44.4770278930664,,,,,,,,,,,,,,,,
,3737875172.9545,53.5058193206787,99.8805694580078,-3.13233518780095E-6,3.33628764956832E-7,1,0.999253354069792,40.0298881530762,1.99989350778781,16.1799993366003,-3.14313147497975E-5,-1.90363091176936E-5,0.25,-1.19496914331675E-6,-3.12459458544356E-6,-1.2185169367254E-6,53.4905738830566,53.4905738830566,99.8684692382813,99.8926696777344,54.7812163988135,19.6869835160594,19.1472339630127,0,0,0,40,54.3059616088867,2,4,1,2.1563720703125,44.9657897949219,,,,,,,,,,,,,,,,
,3737875314.8465,57.0101909637451,99.9047660827637,-3.08535181837717E-6,2.81274495200041E-7,1,0.999253354069792,40.0298881530762,1.9997831497521,16.1799993366003,-3.18660374150352E-5,-1.39638714276025E-5,0.25,-7.32529869202543E-7,-3.0842751755309E-6,-7.55674819198724E-7,56.9947814941406,56.9947814941406,99.8926696777344,99.916862487793,54.7421349728519,19.687859081684,19.5418949127197,0,0,0,40,57.9002952575684,2,4,1,2.15744018554687,46.4320640563965,,,,,,,,,,,,,,,,
,3737875455.747,60.5107250213623,99.8805694580078,-3.11977700613379E-6,2.88750842177155E-7,1,0.999253354069792,40.0298881530762,1.9997279656002,16.1799993366003,-3.17086553947452E-5,-1.71247649379511E-5,0.25,-1.01869867536064E-6,-3.11979094143914E-6,-1.04238169714763E-6,60.5016212463379,60.5016212463379,99.8684692382813,99.8926696777344,55.0235212397751,19.6869683401557,19.9124164581299,0,0,0,40,61.4994697570801,2,4,1,2.15484619140625,44.9657897949219,,,,,,,,,,,,,,,,
,3737875596.666,64.0021381378174,99.8745193481445,-3.3668742626614E-6,2.57365982501092E-7,1,0.999253354069792,40.0298881530762,1.99965691436571,16.1799993366003,-3.45494762033255E-5,-1.68364996731191E-5,0.25,-9.4732033694074E-7,-3.37082080809334E-6,-9.71929485932975E-7,63.9869956970215,63.9869956970215,99.8563690185547,99.8926696777344,54.799975483275,19.6889029783263,20.2441730499268,0,0,0,40,65.0998992919922,2,4,1,2.15591430664062,44.9657897949219,,,,,,,,,,,,,,,,
,3737875737.536,67.5048561096191,99.8684692382813,-3.04849521510825E-6,2.98564414117097E-7,1,0.999253354069792,40.0298881530762,1.99974715073552,16.1700006574392,-3.02777459066895E-5,-2.09502518159437E-5,0.25,-1.38537591232226E-6,-3.05111191988441E-6,-1.40879249482292E-6,67.4969940185547,67.4969940185547,99.8684692382813,99.8684692382813,55.2251813977366,19.6929749199544,20.546215057373,0,0,0,40,68.6848602294922,2,4,1,2.15087890625,44.9657897949219,,,,,,,,,,,,,,,,
,3737875878.445,71.0014152526855,99.8563690185547,-3.16942943973348E-6,2.57560602030766E-7,1,0.999253354069792,40.0298881530762,1.99976998433707,16.1799993366003,-3.24081904091006E-5,-1.67604205371716E-5,0.25,-9.76826223898688E-7,-3.17691198355904E-6,-9.98627104664811E-7,70.9934921264648,70.9934921264648,99.8563690185547,99.8563690185547,54.9430135022943,19.6917721880526,20.8164710998535,0,0,0,40,72.2795562744141,6,4,1,2.16171264648438,44.9657897949219,,,,,,,,,,,,,,,,
,3737876019.3425,74.5090217590332,99.8503265380859,-3.00974949284238E-6,2.90569449627366E-7,1,0.999253354069792,40.0298881530762,1.99977643091878,16.1799993366003,-3.02925997326713E-5,-1.8696314218156E-5,0.25,-1.18490526112864E-6,-3.01704744128057E-6,-1.20587718012991E-6,74.4937133789063,74.4937133789063,99.8200836181641,99.8805694580078,54.8070101399481,19.6934437256787,21.0676345825195,0,0,0,40,75.8690032958984,6,4,1,2.15225219726562,45.4545478820801,,,,,,,,,,,,,,,,
,3737876160.276,78.0128974914551,99.8987159729004,-3.36867832431617E-6,2.7553682994495E-7,1,0.999253354069792,40.0298881530762,1.99957786958581,16.1799993366003,-3.52970938978668E-5,-1.32406920444906E-5,0.25,-6.17696906288554E-7,-3.38176293983896E-6,-6.36889599290936E-7,77.9964370727539,77.9964370727539,99.8805694580078,99.916862487793,54.9742786430635,19.6951645214118,21.2816581726074,0,0,0,40,79.4593887329102,6,4,1,2.16171264648438,44.9657897949219,,,,,,,,,,,,,,,,
,3737876300.1325,81.5007171630859,99.8805694580078,-2.98235687025559E-6,3.38176705697686E-7,1,0.999253354069792,40.0298881530762,1.99951727292709,16.1700006574392,-3.04261508419821E-5,-1.63664066485322E-5,0.25,-9.76199787810763E-7,-2.99287501142548E-6,-9.94411120615125E-7,81.4924163818359,81.4924163818359,99.8684692382813,99.8926696777344,54.9648991008327,19.6932935297613,21.5066070556641,0,0,0,40,83.0110702514648,6,4,1,2.15179443359375,44.9657897949219,,,,,,,,,,,,,,,,
,3737876441.0235,85.010326385498,99.8684692382813,-2.94099358886801E-6,3.03561326160022E-7,1,0.999253354069792,40.0298881530762,1.99957800278284,16.1799993366003,-3.06442867482374E-5,-1.26126520600956E-5,0.25,-6.37906111177566E-7,-2.95351330858412E-6,-6.53409676717167E-7,84.9938049316406,84.9938049316406,99.8684692382813,99.8684692382813,54.7327554306212,19.6930770340404,21.7462615966797,0,0,0,40,86.5988845825195,6,4,1,2.15957641601562,44.9657897949219,,,,,,,,,,,,,,,,
,3737876581.9285,88.5129623413086,99.8442726135254,-2.95232098345957E-6,3.0328719948742E-7,1,0.999253354069792,40.0298881530762,1.99957090501307,16.1799993366003,-3.04845801805149E-5,-1.42508109722429E-5,0.25,-7.87658320912615E-7,-2.96486222813051E-6,-8.03226822618267E-7,88.5051574707031,88.5051574707031,99.8321762084961,99.8563690185547,54.7765266276981,19.6945157851007,21.9821071624756,0,0,0,40,90.1803970336914,6,4,1,2.15606689453125,44.9657897949219,,,,,,,,,,,,,,,,
,3737876721.7995,92.0084838867187,99.856372833252,-3.30187982725199E-6,2.796089440067E-7,1,0.999253354069792,40.0298881530762,1.99959859167557,16.1700006574392,-3.41316516722789E-5,-1.57611000117027E-5,0.25,-8.65259103319659E-7,-3.31647115404143E-6,-8.81808728249903E-7,92,92,99.8442764282227,99.8684692382813,54.911748361525,19.6913802358272,22.2095947265625,0,0,0,40,93.7164916992188,6,4,1,2.15011596679687,44.9657897949219,,,,,,,,,,,,,,,,
,3737876862.6765,95.5113067626953,99.8321800231934,-3.12100839742537E-6,2.93935468886309E-7,1,0.999253354069792,40.0298881530762,1.99947895693918,16.1799993366003,-3.19400851705286E-5,-1.6718481845135E-5,0.25,-9.86461062163039E-7,-3.13459790943642E-6,-1.00233803732788E-6,95.4948425292969,95.4948425292969,99.8200836181641,99.8442764282227,55.1337308609866,19.6940475182003,22.4778938293457,0,0,0,40,97.2955856323242,6,4,1,2.16079711914062,45.4545478820801,,,,,,,,,,,,,,,,
,3737877002.6525,99.0144462585449,99.856372833252,-2.94547888408408E-6,2.95096143249513E-7,1,0.999253354069792,40.0298881530762,1.99954255662036,16.1700006574392,-3.00721393945506E-5,-1.62048559727559E-5,0.25,-9.70809828713367E-7,-2.95847004469272E-6,-9.85425739202058E-7,99.0043411254883,99.0043411254883,99.8442764282227,99.8684692382813,54.9734970145443,19.691942173289,22.7438678741455,0,0,0,40,100.832679748535,6,4,1,2.15072631835938,44.9657897949219,,,,,,,,,,,,,,,,
,3737877143.4895,102.520343780518,99.8442764282227,-3.25125928752726E-6,3.76343461726456E-7,1,0.999253354069792,40.0298881530762,1.99956861011134,16.1799993366003,-3.3369644141293E-5,-1.69158182856337E-5,0.25,-9.82564349546349E-7,-3.26611167507762E-6,-9.97612812971387E-7,102.513000488281,102.513000488281,99.8442764282227,99.8442764282227,54.8984606766981,19.6928014899419,22.9611873626709,0,0,0,40,104.406768798828,6,4,1,2.15835571289062,45.4545478820801,,,,,,,,,,,,,,,,
,3737877283.391,106.019161224365,99.8503227233887,-2.9501200396155E-6,3.54830520346458E-7,1,0.999253354069792,40.0298881530762,1.99956717344481,16.1799993366003,-3.02152153170654E-5,-1.57169290517514E-5,0.25,-9.25952764728769E-7,-2.9636464814269E-6,-9.39293256700824E-7,106.003845214844,106.003845214844,99.8321762084961,99.8684692382813,54.8328038810827,19.6927472913062,23.1591510772705,0,0,0,40,107.942375183105,6,4,1,2.16232299804687,45.4545478820801,,,,,,,,,,,,,,,,
,3737877423.2475,109.509143829346,99.8503227233887,-3.01727241248854E-6,3.14393281494989E-7,1,0.999253354069792,40.0298881530762,1.99954748404206,16.1799993366003,-3.03804299871984E-5,-1.90283636265582E-5,0.25,-1.2198342056624E-6,-3.0304833486111E-6,-1.23448993100036E-6,109.494033813477,109.494033813477,99.8442764282227,99.8563690185547,54.9344155885827,19.6936240408721,23.3477630615234,0,0,0,40,111.477493286133,6,4,1,2.15927124023438,44.9657897949219,,,,,,,,,,,,,,,,
,3737877564.1945,113.025718688965,99.862419128418,-3.05675149664566E-6,3.06645449680825E-7,1,0.999253354069792,40.0298881530762,1.99958514145666,16.1799993366003,-3.14568445638878E-5,-1.5451894588076E-5,0.25,-8.83495881989327E-7,-3.07111437356574E-6,-8.95973253426154E-7,113.016998291016,113.016998291016,99.8563690185547,99.8684692382813,54.864069021852,19.6966790270719,23.5467510223389,0,0,0,40,115.037673950195,6,4,1,2.15072631835938,45.4545478820801,,,,,,,,,,,,,,,,
,3737877704.0375,116.508556365967,99.8745193481445,-3.0682784856293E-6,3.92061251666129E-7,1,0.999253354069792,40.0298881530762,1.99950704495454,16.1799993366003,-3.15795555283301E-5,-1.54800665140231E-5,0.25,-8.84519014484236E-7,-3.08270534502092E-6,-8.96614701214029E-7,116.49951171875,116.49951171875,99.8563690185547,99.8926696777344,54.5381299293327,19.6980189444137,23.7622489929199,0,0,0,40,118.575942993164,6,4,1,2.159423828125,44.9657897949219,,,,,,,,,,,,,,,,
,3737877843.9465,120.007747650146,99.8382263183594,-2.75004527993056E-6,2.97771816094697E-7,1,0.999253354069792,40.0298881530762,1.9996108321031,16.1799993366003,-2.75215280070752E-5,-1.83083846172836E-5,0.25,-1.20188334659232E-6,-2.7620185917556E-6,-1.21456200548013E-6,119.999168395996,119.999168395996,99.8321762084961,99.8442764282227,55.1712490299097,19.6992925572452,23.9382801055908,0,0,0,40,122.104133605957,6,4,1,2.16033935546875,44.9657897949219,,,,,,,,,,,,,,,,
,3737877984.852,123.517669677734,99.8745193481445,-2.90751644116366E-6,2.82266044253667E-7,1,0.999253354069792,40.0298881530762,1.99953361511859,16.1799993366003,-2.89794822203945E-5,-2.00168279998713E-5,0.25,-1.3320054988963E-6,-2.92003049877315E-6,-1.34536531028811E-6,123.508499145508,123.508499145508,99.8684692382813,99.8805694580078,54.6803863198327,19.6993246437917,24.1660671234131,0,0,0,40,125.668296813965,6,4,1,2.16018676757813,44.9657897949219,,,,,,,,,,,,,,,,
,3737878124.762,127.016536712646,99.856372833252,-2.92954712313386E-6,3.63628602561439E-7,1,0.999253354069792,40.0298881530762,1.9995068912402,16.1700006574392,-2.9475449226509E-5,-1.85987564121982E-5,0.25,-1.1977309176498E-6,-2.9424199715661E-6,-1.21007897398991E-6,126.999984741211,126.999984741211,99.8442764282227,99.8684692382813,54.9008055622558,19.6969120934966,24.3600807189941,0,0,0,40,129.18620300293,6,4,1,2.14874267578125,45.4545478820801,,,,,,,,,,,,,,,,
,3737878264.687,130.510162353516,99.8442726135254,-2.94695761818643E-6,3.65722912517988E-7,1,0.999253354069792,40.0298881530762,1.99950376999596,16.1799993366003,-3.01736525639676E-5,-1.57409471562209E-5,0.25,-9.31461145550226E-7,-2.96037503274619E-6,-9.42133515411495E-7,130.493560791016,130.493560791016,99.8321762084961,99.8563690185547,54.7296289165443,19.6986385069234,24.5140132904053,0,0,0,40,132.730514526367,6,4,1,2.1630859375,45.4545478820801,,,,,,,,,,,,,,,,
,3737878404.528,134.008255004883,99.8745193481445,-2.91779572722737E-6,2.58529310046537E-7,1,0.999253354069792,40.0298881530762,1.99950891539529,16.1799993366003,-2.98188351404397E-5,-1.58969077669082E-5,0.25,-9.51304735470719E-7,-2.93090721261376E-6,-9.61722926399932E-7,134.00048828125,134.00048828125,99.8684692382813,99.8805694580078,54.8445283088712,19.6986854966266,24.6910572052002,0,0,0,40,136.247100830078,6,4,1,2.15988159179687,44.4770278930664,,,,,,,,,,,,,,,,
,3737878545.4565,137.519683837891,99.8261299133301,-2.96457984396571E-6,3.79104956321883E-7,1,0.999253354069792,40.0298881530762,1.99945902331888,16.1700006574392,-3.01199295493937E-5,-1.71425659463515E-5,0.25,-1.05828441195082E-6,-2.97759733565333E-6,-1.06904194445732E-6,137.503646850586,137.503646850586,99.8200836181641,99.8321762084961,54.9664623578712,19.7014415246068,24.8359622955322,0,0,0,40,139.813049316406,6,4,1,2.16445922851562,44.9657897949219,,,,,,,,,,,,,,,,
,3737878685.3355,141.026634216309,99.8442764282227,-3.04493695708418E-6,3.46664772461116E-7,1,0.999253354069792,40.0298881530762,1.99944943525879,16.1799993366003,-3.13909560415802E-5,-1.5017768970828E-5,0.25,-8.48451818371737E-7,-3.05857601758382E-6,-8.58024359736691E-7,141.012405395508,141.012405395508,99.8200836181641,99.8684692382813,54.7718368565827,19.7019408513085,24.9845943450928,0,0,0,40,143.338180541992,6,4,1,2.16293334960938,44.4770278930664,,,,,,,,,,,,,,,,
,3737878825.1985,144.513153076172,99.8382263183594,-2.69353603966974E-6,3.64738553185344E-7,1,0.999253354069792,40.0298881530762,1.99939442599563,16.1799993366003,-2.68076366509726E-5,-1.87219267440957E-5,0.25,-1.25238478936255E-6,-2.7045900142875E-6,-1.26307820773116E-6,144.507095336914,144.507095336914,99.8321762084961,99.8442764282227,54.881264849275,19.6989874867683,25.1551151275635,0,0,0,40,146.851058959961,6,4,1,2.16156005859375,45.4545478820801,,,,,,,,,,,,,,,,
,3737878965.1275,148.015762329102,99.8382263183594,-2.89764907945131E-6,3.6280133774855E-7,1,0.999253354069792,40.0298881530762,1.99941310316217,16.1799993366003,-3.01047488174277E-5,-1.29471356468388E-5,0.25,-6.83975037852288E-7,-2.91047190103669E-6,-6.9200638339021E-7,147.998748779297,147.998748779297,99.8321762084961,99.8442764282227,54.9703705004673,19.7013031347077,25.3433094024658,0,0,0,40,150.385147094727,6,4,1,2.15194702148438,46.4320640563965,,,,,,,,,,,,,,,,
,3737879104.978,151.512870788574,99.8079833984375,-3.08470074173394E-6,2.83225056195428E-7,1,0.999253354069792,40.0298881530762,1.99945742841533,16.1799993366003,-3.16467045190074E-5,-1.60527927402357E-5,0.25,-9.3777680332169E-7,-3.0978024109354E-6,-9.47086783718939E-7,151.504745483398,151.504745483398,99.7837905883789,99.8321762084961,54.853907851102,19.7024284957809,25.5153732299805,0,0,0,40,153.893417358398,6,4,1,2.14935302734375,44.9657897949219,,,,,,,,,,,,,,,,
,3737879244.915,155.010025024414,99.8140335083008,-2.59505711934802E-6,3.58664739900608E-7,1,0.999253354069792,40.0298881530762,1.99938245794128,16.1799993366003,-2.61294577033669E-5,-1.62927700896632E-5,0.25,-1.04644155492391E-6,-2.60550215143789E-6,-1.05526758512136E-6,154.993301391602,154.993301391602,99.8079833984375,99.8200836181641,54.8445283088712,19.702903926116,25.669397354126,0,0,0,40,157.405624389648,6,4,1,2.16156005859375,44.9657897949219,,,,,,,,,,,,,,,,
,3737879384.7675,158.510620117187,99.8321762084961,-2.34034331093236E-6,2.8794555249609E-7,1,0.999253354069792,40.0298881530762,1.99929328980085,16.1700006574392,-2.31511296966555E-5,-1.70273780956689E-5,0.25,-1.15936642443845E-6,-2.34928133842947E-6,-1.16811160551569E-6,158.495147705078,158.495147705078,99.8321762084961,99.8321762084961,55.0923045494674,19.7041583247549,25.802921295166,0,0,0,40,160.934722900391,6,4,1,2.16156005859375,44.9657897949219,,,,,,,,,,,,,,,,
,3737879524.6795,162.002449035645,99.8382263183594,-3.06922416388576E-6,3.74350658555976E-7,1,0.999253354069792,40.0298881530762,1.99943345464459,16.1799993366003,-3.14756461497321E-5,-1.59967074909151E-5,0.25,-9.36151949358292E-7,-3.08157454929714E-6,-9.44737689059026E-7,161.986312866211,161.986312866211,99.8200836181641,99.8563690185547,54.7976305977173,19.7055356001453,25.9662780761719,0,0,0,40,164.452056884766,6,4,1,2.161865234375,44.9657897949219,,,,,,,,,,,,,,,,
,3737879665.5605,165.522636413574,99.8140335083008,-2.17935457854881E-6,2.26343696549142E-7,1,0.999253354069792,40.0298881530762,1.99940766826547,16.1799993366003,-2.15500634969243E-5,-1.58926241146862E-5,0.25,-1.08334893111931E-6,-2.18736451431808E-6,-1.09111923142126E-6,165.506820678711,165.506820678711,99.8079833984375,99.8200836181641,55.0110151834674,19.7043234234706,26.1281661987305,0,0,0,40,168.011764526367,6,4,1,2.1600341796875,44.9657897949219,,,,,,,,,,,,,,,,
,3737879805.479,169.015869140625,99.8442764282227,-2.64403462605109E-6,3.58157798215319E-7,1,0.999253354069792,40.0298881530762,1.9993555162348,16.1799993366003,-2.74743014507141E-5,-1.17050863050668E-5,0.25,-6.15385579245811E-7,-2.65449973118862E-6,-6.21596347437342E-7,169.006530761719,169.006530761719,99.8442764282227,99.8442764282227,54.6960188902173,19.7053176990131,26.3247528076172,0,0,0,40,171.520706176758,6,4,1,2.164306640625,45.4545478820801,,,,,,,,,,,,,,,,
,3737879945.38,172.514152526855,99.8261299133301,-2.74150710329899E-6,3.68197370023722E-7,1,0.999253354069792,40.0298881530762,1.99943489595331,16.1799993366003,-2.83490961678481E-5,-1.29129931017779E-5,0.25,-7.09898699400698E-7,-2.75202100699119E-6,-7.16474245388778E-7,172.498931884766,172.498931884766,99.8200836181641,99.8321762084961,54.9985091271597,19.7062283771373,26.4856204986572,0,0,0,40,175.05859375,6,4,1,2.16079711914062,44.9657897949219,,,,,,,,,,,,,,,,
,3737880085.2325,176.009834289551,99.8442726135254,-2.42666759352475E-6,2.64553740075891E-7,1,0.999253354069792,40.0298881530762,1.99946628467165,16.1799993366003,-2.4338700232886E-5,-1.57121659434034E-5,0.25,-1.02382316646119E-6,-2.43524940356816E-6,-1.03110865537446E-6,176.002532958984,176.002532958984,99.8321762084961,99.8563690185547,54.7718368565827,19.7047886374444,26.7632484436035,0,0,0,40,178.57470703125,6,4,1,2.16323852539062,45.4545478820801,,,,,,,,,,,,,,,,
,3737880225.148,179.502014160156,99.8200836181641,-2.29876313387955E-6,2.63189255141421E-7,1,0.999253354069792,40.0298881530762,1.99948797310665,16.1799993366003,-2.31237885364424E-5,-1.44864185470566E-5,0.25,-9.33348095136236E-7,-2.30673960752299E-6,-9.39930865034082E-7,179.492492675781,179.492492675781,99.8200836181641,99.8200836181641,55.2001692851212,19.7017721823002,27.1101245880127,0,0,0,40,182.086074829102,6,4,1,2.15652465820313,44.9657897949219,,,,,,,,,,,,,,,,
,3737880366.111,183.022972106934,99.8321762084961,-2.6977582316951E-6,4.10402730783203E-7,1,0.999253354069792,40.0298881530762,1.99944390200477,16.1700006574392,-2.67812981005162E-5,-1.90082775685984E-5,0.25,-1.28096641676981E-6,-2.70665050105214E-6,-1.28921302936415E-6,183.00569152832,183.00569152832,99.8321762084961,99.8321762084961,54.8187345677366,19.7026126550718,27.3801193237305,0,0,0,40,185.634033203125,6,4,1,2.15744018554687,45.4545478820801,,,,,,,,,,,,,,,,
,3737880505.98,186.524948120117,99.8079833984375,-2.64478833903673E-6,3.50633744074716E-7,1,0.999253354069792,40.0298881530762,1.99941118656965,16.1799993366003,-2.75418009010409E-5,-1.129550254819E-5,0.25,-5.78365345358304E-7,-2.65407347008458E-6,-5.83686746623802E-7,186.50666809082,186.50666809082,99.7958831787109,99.8200836181641,54.8226427103327,19.7039970301635,27.6745719909668,0,0,0,40,189.140625,6,4,1,2.15850830078125,45.4545478820801,,,,,,,,,,,,,,,,
,3737880645.825,190.018615722656,99.7898368835449,-2.3779229451453E-6,3.0211852219173E-7,1,0.999253354069792,40.0298881530762,1.99952550757436,16.1799993366003,-2.42716200599633E-5,-1.29451774347489E-5,0.25,-7.77701260441811E-7,-2.3857375913106E-6,-7.83308719127491E-7,190.001510620117,190.001510620117,99.7837905883789,99.7958831787109,54.698363775775,19.7043804196058,27.9596214294434,0,0,0,40,192.656448364258,6,4,1,2.15164184570313,44.9657897949219,,,,,,,,,,,,,,,,
,3737880785.7485,193.521873474121,99.8261299133301,-2.16167045964698E-6,2.93420770840806E-7,1,0.999253354069792,40.0298881530762,1.99950479029122,16.1799993366003,-2.21875445321297E-5,-1.10515314504995E-5,0.25,-6.40995249446612E-7,-2.16863780836511E-6,-6.45724541194262E-7,193.514785766602,193.514785766602,99.8079833984375,99.8442764282227,55.240032339602,19.705650713835,28.1739768981934,0,0,0,40,196.170196533203,6,4,1,2.16094970703125,44.9657897949219,,,,,,,,,,,,,,,,
,3737880925.604,197.020668029785,99.8140335083008,-1.77793394802213E-6,2.77652296297984E-7,1,0.999253354069792,40.0298881530762,1.9993803836939,16.1700006574392,-1.67258871745177E-5,-1.7744488125387E-5,0.25,-1.32681902625623E-6,-1.78260134793001E-6,-1.33336627283024E-6,197.003326416016,197.003326416016,99.8079833984375,99.8200836181641,55.0938678065058,19.706608278961,28.4501056671143,0,0,0,40,199.670135498047,6,4,1,2.15667724609375,45.4545478820801,,,,,,,,,,,,,,,,
,3737881065.528,200.512855529785,99.7837905883789,-1.67197662442232E-6,2.51564993358518E-7,1,0.999253354069792,40.0298881530762,1.99923165885068,16.1799993366003,-1.6499738112613E-5,-1.22806829699253E-5,0.25,-8.40982859610362E-7,-1.67665485029512E-6,-8.45604049017741E-7,200.494369506836,200.494369506836,99.7837905883789,99.7837905883789,54.3012964880057,19.7096827306075,28.7021083831787,0,0,0,40,203.186584472656,6,4,1,2.16262817382813,44.9657897949219,,,,,,,,,,,,,,,,
,3737881205.3925,204.018669128418,99.8200798034668,-1.47787851843219E-6,2.24637906520075E-7,1,0.999253354069792,40.0298881530762,1.99937750736885,16.1799993366003,-1.49106683077042E-5,-8.99322943282115E-6,0.25,-5.71418041989196E-7,-1.48205017794893E-6,-5.74830641930936E-7,204.010314941406,204.010314941406,99.7958831787109,99.8442764282227,54.9187830181981,19.7070569161874,28.9848041534424,0,0,0,40,206.687744140625,6,4,1,2.1588134765625,45.4545478820801,,,,,,,,,,,,,,,,
,3737881345.2985,207.514060974121,99.7837867736816,-1.31950492597879E-6,2.66711606026882E-7,1,0.999253354069792,40.0298881530762,1.9994601962238,16.1700006574392,-1.2768497982825E-5,-1.11251073547011E-5,0.25,-7.96279932589609E-7,-1.32279768538846E-6,-8.00133919717634E-7,207.497131347656,207.497131347656,99.7716903686523,99.7958831787109,55.1188799191212,19.7078573580538,29.2111415863037,0,0,0,40,210.19775390625,6,4,1,2.15240478515625,44.9657897949219,,,,,,,,,,,,,,,,
,3737881485.2165,211.01318359375,99.7898368835449,-7.79698514375452E-7,2.64363452686397E-7,1,0.999253354069792,40.0298881530762,1.99949654923097,16.1799993366003,-5.95843078855533E-6,-1.56092399405229E-5,0.25,-1.30548771023878E-6,-7.80718576811162E-7,-1.31020828485526E-6,210.996185302734,210.996185302734,99.7595901489258,99.8200836181641,54.8163896821789,19.7077164383919,29.4814281463623,0,0,0,40,213.709503173828,6,4,1,2.15835571289062,45.4545478820801,,,,,,,,,,,,,,,,
,3737881625.1825,214.520698547363,99.7958869934082,-8.85109776762111E-7,2.57980390669629E-7,1,0.999253354069792,40.0298881530762,1.99945827721294,16.1799993366003,-8.19581089356149E-6,-9.55492744354654E-6,0.25,-7.27685040032102E-7,-8.8694856473609E-7,-7.30673390630905E-7,214.513580322266,214.513580322266,99.7837905883789,99.8079833984375,54.4232305370057,19.7093448177134,29.7131385803223,0,0,0,40,217.207626342773,6,4,1,2.1630859375,45.4545478820801,,,,,,,,,,,,,,,,
,3737881764.9705,218.012893676758,99.7898368835449,-7.09468259654227E-7,2.93428977883808E-7,1,0.999253354069792,40.0298881530762,1.99967721703585,16.1799993366003,-5.9191659115985E-6,-1.13650243514675E-5,0.25,-9.25807228634194E-7,-7.105385673941E-7,-9.29075296909251E-7,217.996002197266,217.996002197266,99.7837905883789,99.7958831787109,54.6921107476212,19.7077850929132,30.0207633972168,0,0,0,40,220.702224731445,6,4,1,2.15652465820313,45.4545478820801,,,,,,,,,,,,,,,,
,3737881904.877,221.519668579102,99.7595939636231,-4.21481215194037E-7,3.04927391184046E-7,1,0.999253354069792,40.0298881530762,1.99954705150651,16.1799993366003,-2.58052063286289E-6,-1.2082201146749E-5,0.25,-1.0428192884025E-6,-4.21607266865783E-7,-1.04600388945398E-6,221.511184692383,221.511184692383,99.7474975585938,99.7716903686523,55.1032473487366,19.7068334257297,30.1994132995605,0,0,0,40,224.201919555664,6,4,1,2.15805053710938,44.9657897949219,,,,,,,,,,,,,,,,
,3737882044.7545,225.021095275879,99.8019332885742,1.21460690106267E-7,3.06477021354543E-7,1,0.999253354069792,40.0298881530762,1.99968702173196,16.1799993366003,3.81310321751572E-6,-1.40149655150116E-5,0.25,-1.31678189195423E-6,1.23006981595791E-7,-1.32002736086068E-6,225.013320922852,225.013320922852,99.7958831787109,99.8079833984375,54.9031504478135,19.706351124839,30.4293365478516,0,0,0,40,227.696517944336,6,4,1,2.16262817382813,44.9657897949219,,,,,,,,,,,,,,,,
,3737882183.6965,228.502807617187,99.8200798034668,3.88404253747467E-7,2.82424643372383E-7,1,0.999253354069792,40.0298881530762,1.99962049421489,16.1799993366003,6.32770623340578E-6,-1.13852806168323E-5,0.25,-1.12068170038891E-6,3.90383061373189E-7,-1.12305316982194E-6,228.486022949219,228.486022949219,99.8079833984375,99.8321762084961,54.9054953333712,19.704604798889,30.6152725219727,0,0,0,40,231.172988891602,6,4,1,2.16079711914062,45.4545478820801,,,,,,,,,,,,,,,,
,3737882324.542,232.022102355957,99.8442764282227,9.33459220208734E-7,2.88177072002125E-7,1,0.999253354069792,40.0298881530762,1.99953849103678,16.1799993366003,1.14306949658824E-5,-5.84156017758857E-6,0.25,-7.03850178361825E-7,9.36259545837428E-7,-7.04637013334176E-7,232.013244628906,232.013244628906,99.8200836181641,99.8684692382813,54.7538594006404,19.7061992377126,30.7734127044678,0,0,0,40,234.697570800781,6,4,1,2.1612548828125,45.4545478820801,,,,,,,,,,,,,,,,
,3737882464.4775,235.523277282715,99.8140335083008,1.14761616328636E-6,2.64707824727468E-7,1,0.999253354069792,40.0298881530762,1.99966719872348,16.1799993366003,1.42340092478274E-5,-8.21794423362995E-6,0.25,-9.61160562162482E-7,1.15099487367141E-6,-9.62255432223224E-7,235.504669189453,235.504669189453,99.8079833984375,99.8200836181641,54.7804347702943,19.7080675115543,30.984447479248,0,0,0,40,238.201721191406,6,4,1,2.16232299804687,44.9657897949219,,,,,,,,,,,,,,,,
,3737882604.368,239.019302368164,99.8442764282227,1.89151239624179E-6,2.13893336488399E-7,1,0.999253354069792,40.0298881530762,1.99966043686775,16.1799993366003,2.22871408977406E-5,-6.86922316486022E-6,0.25,-9.66956397524739E-7,1.89629406088923E-6,-9.67318364625408E-7,239.003433227539,239.003433227539,99.8442764282227,99.8442764282227,54.7139963461596,19.7071518587343,31.1879253387451,0,0,0,40,241.717834472656,6,4,1,2.158203125,44.9657897949219,,,,,,,,,,,,,,,,
,3737882744.2295,242.51732635498,99.8442726135254,2.5846393074894E-6,2.72438912208743E-7,1,0.999253354069792,40.0298881530762,1.99971548995335,16.1799993366003,3.01134197841372E-5,-7.46020911750162E-6,0.25,-1.14318060467529E-6,2.59069324372757E-6,-1.14320772842915E-6,242.501831054687,242.501831054687,99.8321762084961,99.8563690185547,54.8054468829097,19.7068861701546,31.3117923736572,0,0,0,40,245.218322753906,6,4,1,2.159423828125,45.4545478820801,,,,,,,,,,,,,,,,
,3737882884.1215,246.017585754395,99.8442726135254,2.74924574571702E-6,3.12299145408194E-7,1,0.999253354069792,40.0298881530762,1.99978158944788,16.1799993366003,3.09059953917786E-5,-1.5340340183332E-6,0.25,-6.23921988982604E-7,2.75483995952976E-6,-6.22754485901936E-7,246.008590698242,246.008590698242,99.8321762084961,99.8563690185547,54.6076948675442,19.7072508664237,31.4737110137939,0,0,0,40,248.730453491211,6,4,1,2.16018676757813,45.4545478820801,,,,,,,,,,,,,,,,
,3737883024.0365,249.510368347168,99.8503227233887,3.92086533330275E-6,2.70589597375291E-7,1,0.999253354069792,40.0298881530762,1.99985622200383,16.1799993366003,4.41296937779976E-5,-2.51059251383012E-6,0.25,-9.19633517188226E-7,3.92838665580261E-6,-9.17969022971364E-7,249.493453979492,249.493453979492,99.8442764282227,99.8563690185547,54.8156080536596,19.7092094800741,31.6256446838379,0,0,0,40,252.246627807617,6,4,1,2.1575927734375,45.4545478820801,,,,,,,,,,,,,,,,
,3737883163.983,253.001304626465,99.8079833984375,4.44227705690716E-6,2.63443695803491E-7,1,0.999253354069792,40.0298881530762,1.99971755827057,16.1799993366003,5.01257993493733E-5,-3.62549503809208E-6,0.25,-1.11417644165195E-6,4.45031021716656E-6,-1.11234248787458E-6,252.985717773438,252.985717773438,99.8079833984375,99.8079833984375,54.6788230627943,19.7056132633524,31.8177871704102,0,0,0,40,255.767333984375,6,4,1,2.16217041015625,44.9657897949219,,,,,,,,,,,,,,,,
,3737883303.833,256.500762939453,99.9289627075195,4.78215976513272E-6,3.23956164316066E-7,1,0.999253354069792,40.0298881530762,1.99971394225381,16.1799993366003,5.40909161947599E-5,-4.68234409078614E-6,0.25,-1.27152467641023E-6,4.79027243538201E-6,-1.26957652847613E-6,256.491973876953,256.491973876953,99.9289627075195,99.9289627075195,54.8414017947943,19.7031561051055,32.0439338684082,0,0,0,40,259.288360595703,6,4,1,2.16140747070313,44.9657897949219,,,,,,,,,,,,,,,,
,3737883444.718,260.021743774414,99.9047660827637,5.60075010374479E-6,2.84052887715263E-7,1,0.999253354069792,40.0298881530762,1.99982472832829,16.1799993366003,6.24513488928887E-5,-3.82695597222721E-7,0.25,-1.01709583532228E-6,5.60917804779186E-6,-1.01406323953034E-6,260.003784179687,260.003784179687,99.8926696777344,99.916862487793,54.9547379300827,19.7052826427967,32.2447128295898,0,0,0,40,262.822662353516,6,4,1,2.16171264648438,45.4545478820801,,,,,,,,,,,,,,,,
,3737883584.685,263.519271850586,99.8684692382813,6.14501687126112E-6,3.25555979914472E-7,1,0.999253354069792,40.0298881530762,1.99994549503296,16.1799993366003,6.8906152714661E-5,-2.64766366441761E-6,0.25,-1.32202137124046E-6,6.15366507886234E-6,-1.31889176581177E-6,263.499908447266,263.499908447266,99.8563690185547,99.8805694580078,54.9516114160058,19.7102322949781,32.4260597229004,0,0,0,40,266.335052490234,6,4,1,2.16033935546875,46.9208221435547,,,,,,,,,,,,,,,,
,3737883724.491,267.016006469727,99.9047660827637,7.38141337543877E-6,2.9429770443123E-7,1,0.999253354069792,40.0298881530762,1.99992909202036,16.1799993366003,8.15995291001835E-5,3.43828582160872E-6,0.25,-9.75378280465851E-7,7.39041817036213E-6,-9.70830867689527E-7,267.006683349609,267.006683349609,99.8926696777344,99.916862487793,54.9414502452558,19.7090420547247,32.6694793701172,0,0,0,40,269.838195800781,6,4,1,2.161865234375,44.9657897949219,,,,,,,,,,,,,,,,
,3737883864.4715,270.516632080078,99.9289627075195,7.62496035778016E-6,3.65990779014825E-7,1,0.999253354069792,40.0298881530762,2.0000255925928,16.1799993366003,8.47078708968855E-5,1.14040654427048E-6,0.25,-1.23063746765916E-6,7.63348990735757E-6,-1.22613047886695E-6,270.497406005859,270.497406005859,99.916862487793,99.9410629272461,54.952393044525,19.7040905049508,32.8551445007324,0,0,0,40,273.354858398438,6,4,1,2.16232299804687,45.4545478820801,,,,,,,,,,,,,,,,
,3737884004.2875,274.018417358398,99.8321800231934,8.31198844639093E-6,2.64570841198953E-7,1,0.999253354069792,40.0298881530762,2.00003993949015,16.1799993366003,9.19768489808828E-5,3.25539761988515E-6,0.25,-1.15513473033584E-6,8.32011962489362E-6,-1.14999103805323E-6,273.999481201172,273.999481201172,99.8200836181641,99.8442764282227,54.955519558602,19.6972454188418,33.1082763671875,0,0,0,40,276.855346679687,6,4,1,2.15774536132813,45.4545478820801,,,,,,,,,,,,,,,,
,3737884144.151,277.521240234375,99.8140296936035,9.03116299465839E-6,3.76166760867545E-7,1,0.999253354069792,40.0298881530762,2.00007730719616,16.1799993366003,9.95133942909315E-5,5.88212493903336E-6,0.25,-1.03783548516388E-6,9.03872277523637E-6,-1.03203146187034E-6,277.506164550781,277.506164550781,99.7958831787109,99.8321762084961,54.996164241602,19.6963144903172,33.3697776794434,0,0,0,40,280.383758544922,6,4,1,2.15682983398438,45.4545478820801,,,,,,,,,,,,,,,,
,3737884284.0745,281.009231567383,99.8745193481445,9.33523622783006E-6,2.99224557017362E-7,1,0.999253354069792,40.0298881530762,2.00017928976355,16.1799993366003,0.000102905956081532,5.79630082284215E-6,0.25,-1.0989176060453E-6,9.34192230794362E-6,-1.09290588644341E-6,280.994262695313,280.994262695313,99.8684692382813,99.8805694580078,55.189226485852,19.6967140754546,33.7130432128906,0,0,0,40,283.898040771484,6,4,1,2.15805053710938,45.4545478820801,,,,,,,,,,,,,,,,
,3737884423.952,284.515716552734,99.8745193481445,1.01236528769436E-5,3.2919840170174E-7,1,0.999253354069792,40.0298881530762,2.00016118813967,16.1799993366003,0.000111739237585046,5.38888561708096E-6,0.25,-1.27459910251871E-6,1.01297115792231E-5,-1.26808396429477E-6,284.500549316406,284.500549316406,99.8684692382813,99.8805694580078,55.0203947256981,19.6927322861648,34.0096244812012,0,0,0,40,287.412109375,6,4,1,2.15667724609375,45.4545478820801,,,,,,,,,,,,,,,,
,3737884563.9055,288.007049560547,99.8987197875977,9.70673925870889E-6,3.11985021020131E-7,1,0.999253354069792,40.0298881530762,2.00027448183748,16.1799993366003,0.000106149806480769,1.07628022690842E-5,0.25,-7.03770136649586E-7,9.7109926151065E-6,-6.97273737635726E-7,287.991119384766,287.991119384766,99.8926696777344,99.9047698974609,55.0282110108904,19.692172848068,34.2627563476562,0,0,0,40,290.938293457031,6,4,1,2.15988159179687,44.9657897949219,,,,,,,,,,,,,,,,
,3737884704.7745,291.524139404297,99.9289627075195,1.02284498339974E-5,3.78844621980065E-7,1,0.999253354069792,40.0298881530762,2.0003859834211,16.1799993366003,0.000111961795855806,1.06863132874693E-5,0.25,-8.02075826848874E-7,1.02317119913202E-5,-7.95258778326566E-7,291.516326904297,291.516326904297,99.9289627075195,99.9289627075195,54.9609909582366,19.6921286790929,34.4848556518555,0,0,0,40,294.4921875,6,4,1,2.15728759765625,43.9882698059082,,,,,,,,,,,,,,,,
,3737884844.6405,295.013092041016,99.9289627075195,1.09520839267016E-5,3.42477612265161E-7,1,0.999253354069792,40.0298881530762,2.00031450111843,16.1700006574392,0.000119485636825031,1.36009116245172E-5,0.25,-6.58609010509191E-7,1.09541020813231E-5,-6.51283394247398E-7,295.003021240234,295.003021240234,99.916862487793,99.9410629272461,55.3963580434482,19.691525049596,34.7593078613281,0,0,0,40,298.002197265625,6,4,1,2.14828491210938,44.9657897949219,,,,,,,,,,,,,,,,
,3737884984.52,298.515075683594,99.9471092224121,1.05956158739596E-5,3.21204186003732E-7,1,0.999253354069792,40.0298881530762,2.00030257114711,16.1799993366003,0.000115160750769409,1.55605475391562E-5,0.25,-4.14371674631702E-7,1.05961226587084E-5,-4.0730289027736E-7,298.499298095703,298.499298095703,99.9410629272461,99.9531555175781,54.9906928419674,19.6909147599646,35.0183753967285,0,0,0,40,301.518585205078,6,4,1,2.1575927734375,45.4545478820801,,,,,,,,,,,,,,,,
,3737885124.4135,302.000350952148,99.8442764282227,1.08561864478314E-5,4.18786045870958E-7,1,0.999253354069792,40.0298881530762,2.00038049270627,16.1799993366003,0.000118623087743818,1.2286438999612E-5,0.25,-7.63120523090666E-7,1.08556105476156E-5,-7.55892841254345E-7,301.98974609375,301.98974609375,99.8442764282227,99.8442764282227,55.0297742679289,19.689561186217,35.2331886291504,0,0,0,40,305.027648925781,6,4,1,2.156982421875,45.9433059692383,,,,,,,,,,,,,,,,
,3737885264.3345,305.503463745117,99.9350128173828,1.16379458189896E-5,3.60909730927705E-7,1,0.999253354069792,40.0298881530762,2.00046347689624,16.1799993366003,0.000127246984405242,1.26430616375627E-5,0.25,-8.6680059315919E-7,1.1635939201994E-5,-8.59046999158664E-7,305.486328125,305.486328125,99.9289627075195,99.9410629272461,54.8922076485443,19.6901430679484,35.3338470458984,0,0,0,40,308.570831298828,6,4,1,2.15652465820313,44.9657897949219,,,,,,,,,,,,,,,,
,3737885405.243,309.017395019531,99.910816192627,1.10791049189083E-5,3.58129103426803E-7,1,0.999253354069792,40.0298881530762,2.00050798225723,16.1799993366003,0.000121336693832723,1.08229694356555E-5,0.25,-9.37365680184513E-7,1.10759124410647E-5,-9.29942752702274E-7,309,309,99.9047698974609,99.916862487793,54.9680256149097,19.6899860871907,35.5046730041504,0,0,0,40,312.098022460937,6,4,1,2.158203125,44.9657897949219,,,,,,,,,,,,,,,,
,3737885545.159,312.506851196289,99.8866195678711,1.0592993612286E-5,3.20094269001866E-7,1,0.999253354069792,40.0298881530762,2.00045250247212,16.1799993366003,0.000116514002385981,7.38717142965628E-6,0.25,-1.17041081157917E-6,1.05888314480732E-5,-1.16316822389805E-6,312.490509033203,312.490509033203,99.8684692382813,99.9047698974609,55.046970095352,19.6886363878744,35.674144744873,0,0,0,40,315.651336669922,6,4,1,2.1563720703125,45.4545478820801,,,,,,,,,,,,,,,,
,3737885686.069,316.029083251953,99.8503227233887,1.12095264806434E-5,3.66555397456345E-7,1,0.999253354069792,40.0298881530762,2.00055134771808,16.1799993366003,0.000122083871521463,1.46819647414089E-5,0.25,-6.02136529780418E-7,1.12033558610794E-5,-5.94786644391459E-7,316.0126953125,316.0126953125,99.8321762084961,99.8684692382813,55.2697342233328,19.6878935522634,35.8625106811523,0,0,0,40,319.18896484375,6,4,1,2.15103149414062,45.4545478820801,,,,,,,,,,,,,,,,
,3737885822.9175,319.505264282227,99.8805694580078,1.14794902477456E-5,3.95062085339548E-7,1,0.999253354069792,40.0298881530762,2.0005794245272,16.1799993366003,0.000125319861795698,1.3268718254006E-5,0.25,-7.80170582421918E-7,1.14718981411643E-5,-7.72545948443654E-7,319.489868164063,319.489868164063,99.8805694580078,99.8805694580078,55.0524414949866,19.6880228306803,36.0309066772461,0,0,0,40,322.769439697266,6,4,1,2.15667724609375,44.9657897949219,,,,,,,,,,,,,,,,
,3737885960.786,323.024185180664,99.8926696777344,1.12892306007651E-5,3.17245262080137E-7,1,0.999253354069792,40.0298881530762,2.00056089837003,16.1799993366003,0.00012376652372221,9.96485814189657E-6,0.25,-1.05288853536603E-6,1.12805743976482E-5,-1.04515027236504E-6,323.007080078125,323.007080078125,99.8805694580078,99.9047698974609,55.0180498401404,19.6875128434039,36.1580123901367,0,0,0,40,326.320831298828,6,4,1,2.15606689453125,45.4545478820801,,,,,,,,,,,,,,,,
,3737886097.69,326.514266967773,99.9168663024902,1.06425482838096E-5,4.22394673908387E-7,1,0.999253354069792,40.0298881530762,2.00054323956468,16.1799993366003,0.000116321454291253,1.1337042983454E-5,0.25,-8.12239386052187E-7,1.06330075190265E-5,-8.05075543705617E-7,326.498107910156,326.498107910156,99.9047698974609,99.9289627075195,55.2267446547751,19.687842475769,36.3455696105957,0,0,0,40,329.834106445313,6,4,1,2.15850830078125,45.4545478820801,,,,,,,,,,,,,,,,
,3737886234.6495,330.000747680664,99.8926696777344,1.12303545898364E-5,4.6949547723636E-7,1,0.999253354069792,40.0298881530762,2.00062943059006,16.1799993366003,0.000123100967897206,9.88067422945219E-6,0.25,-1.05003102371485E-6,1.12190678908054E-5,-1.04224620306977E-6,329.985046386719,329.985046386719,99.8805694580078,99.9047698974609,55.0344640390443,19.6854381625229,36.5398712158203,0,0,0,40,333.352844238281,6,4,1,2.15713500976562,45.4545478820801,,,,,,,,,,,,,,,,
,3737886372.4935,333.501831054687,99.8745193481445,1.14218659733998E-5,4.33735821835885E-7,1,0.999253354069792,40.0298881530762,2.00064055249225,16.1700006574392,0.00012307336537353,2.21152317796352E-5,0.25,5.11649680424239E-8,1.14083728845076E-5,5.78101858679475E-8,333.486419677734,333.486419677734,99.8563690185547,99.8926696777344,55.2541016529482,19.6876357430879,36.7249984741211,0,0,0,40,336.884368896484,6,4,1,2.14813232421875,45.4545478820801,,,,,,,,,,,,,,,,
,3737886510.371,337.005645751953,99.8987197875977,1.11604722970642E-5,3.46646144025396E-7,1,0.999253354069792,40.0298881530762,2.00070190041826,16.1799993366003,0.000121789878974752,1.27889957866787E-5,0.25,-7.67738152793709E-7,1.11464498577002E-5,-7.60265642339035E-7,336.989959716797,336.989959716797,99.8926696777344,99.9047698974609,55.1102820054097,19.686820390224,36.873420715332,0,0,0,40,340.417297363281,6,4,1,2.15560913085938,45.4545478820801,,,,,,,,,,,,,,,,
,3737886649.2975,340.522506713867,99.9229164123535,1.08079806647592E-5,3.56867688456021E-7,1,0.999253354069792,40.0298881530762,2.00067125457283,16.1799993366003,0.000118481907921924,9.21719042306171E-6,0.25,-1.03709771359223E-6,1.07932953036241E-5,-1.02942869996642E-6,340.505187988281,340.505187988281,99.9047698974609,99.9410629272461,55.1134085194866,19.6877218011689,37.0822982788086,0,0,0,40,343.9541015625,2,4,1,2.15866088867187,45.9433059692383,,,,,,,,,,,,,,,,
,3737886787.164,344.005401611328,99.9047698974609,1.11612902022468E-5,4.34864660057282E-7,1,0.999253354069792,40.0298881530762,2.0006903452986,16.1799993366003,0.000122688020440987,7.54028477608541E-6,0.25,-1.25434095458387E-6,1.11449313695278E-5,-1.24608557591449E-6,343.998382568359,343.998382568359,99.9047698974609,99.9047698974609,54.962554215275,19.6866251529931,37.2612190246582,0,0,0,40,347.494323730469,2,4,1,2.15667724609375,45.4545478820801,,,,,,,,,,,,,,,,
,3737886926.071,347.517868041992,99.910816192627,1.10571493975463E-5,3.8558597590105E-7,1,0.999253354069792,40.0298881530762,2.00068726696089,16.1799993366003,0.000120785699568455,1.17148375909109E-5,0.25,-8.48674784520468E-7,1.10394326063642E-5,-8.41066238358507E-7,347.510467529297,347.510467529297,99.8926696777344,99.9289627075195,55.1509266884097,19.6864699632764,37.4579467773438,0,0,0,40,351.032470703125,2,4,1,2.15591430664062,45.4545478820801,,,,,,,,,,,,,,,,
,3737887147.8945,350.223617553711,99.8987197875977,1.00273162628772E-5,4.37361162759624E-7,1,0.999253354069792,40.0298881530762,2.00071473913432,16.1700006574392,0.000108115350787426,1.86916013809653E-5,0.25,-2.09738102119782E-8,1.00099384936988E-5,-1.53479065020402E-8,350.222961425781,350.222961425781,99.8926696777344,99.9047698974609,55.2963095929866,19.6839259992319,37.7359085083008,0,0,0,40,351.435760498047,1,4,1,2.14889526367187,48.8758583068848,,,,,,,,,,,,,,,,