File: data/doubleLayers/dl_2-5/ppms/DD205_5/DD205_5_HYST_100OE_50K.DAT
[Header]
; VSM Data File (default extension .dat)
; Copyright (c) 2003-2013, Quantum Design, Inc. All rights reserved.
TITLE,
FILEOPENTIME,3737928889.57343,06/12/2018,1:36 am
BYAPP,VSM,1.0,1.0
INFO,DYNACOOL VSM Option Release 1.4.10 Build 1,APPNAME
INFO,Quantum Design Linear Motor Servo Controller,MOTOR_MODULE_NAME
INFO,3101-100 J0,MOTOR_HW_VERSION
INFO,MMC654,MOTOR_SERIAL_NUMBER
INFO,SRV No X-over 01.03.11,MOTOR_SOFTWARE_VERSION
INFO,Quantum Design VSM Detection Module,VSM_MODULE_NAME
INFO,3101-150 F0,VSM_HW_VERSION
INFO,VSM507,VSM_SERIAL_NUMBER
INFO,VSM No X-over 01.02.05 May 20 2008 13:51:47,VSM_SOFTWARE_VERSION
INFO,494,PREAMP_SERIAL_NUMBER
INFO,Quantum Design VSM Oven,OVEN_MODULE_NAME
INFO,3101-201 A1,OVEN_HW_VERSION
INFO,OVB210,OVEN_SERIAL_NUMBER
INFO,01.06.24,OVEN_SOFTWARE_VERSION
INFO,593,COIL_SERIAL_NUMBER
INFO,0,MOMENT_UNITS
INFO,CoFe2O4,SAMPLE_MATERIAL
INFO,,SAMPLE_COMMENT
INFO,,SAMPLE_MASS
INFO,,SAMPLE_VOLUME
INFO,,SAMPLE_MOLECULAR_WEIGHT
INFO,,SAMPLE_SIZE
INFO,,SAMPLE_SHAPE
DATATYPE,COMMENT,1
DATATYPE,TIME,2
STARTUPAXIS,X,2
STARTUPAXIS,Y1,5
[Data]
Comment,Time Stamp (sec),Temperature (K),Magnetic Field (Oe),Moment (emu),M. Std. Err. (emu),Transport Action,Averaging Time (sec),Frequency (Hz),Peak Amplitude (mm),Center Position (mm),Coil Signal' (mV),Coil Signal" (mV),Range (mV),M. Quad. Signal (emu),M. Raw' (emu),M. Raw" (emu),Min. Temperature (K),Max. Temperature (K),Min. Field (Oe),Max. Field (Oe),Mass (grams),Motor Lag (deg),Pressure (Torr),VSM Status (code),Motor Status (code),Measure Status (code),Measure Count,System Temp. (K),Temp. Status (code),Field Status (code),Chamber Status (code),Motor Current (amps),Motor Heatsink Temp. (C),Map 01,Map 02,Map 03,Map 04,Map 05,Map 06,Map 07,Map 08,Map 09,Map 10,Map 11,Map 12,Map 13,Map 14,Map 15,Map 16
,3737929401.9405,49.9761085510254,-0.526260271668434,6.33528359175111E-5,2.49538992190081E-7,1,0.999253354069792,40.0298881530762,1.99661180693511,16.1799993366003,0.000682319509146554,0.000118767412292511,0.25,-4.9614325862109E-7,6.33090785347873E-5,-2.46402838568872E-8,49.9759330749512,49.9759330749512,-0.568603038787842,-0.483917504549026,55.0516598664674,19.7351332412111,13.8007774353027,0,0,0,40,50.012622833252,1,4,1,2.15362548828125,45.4545478820801,,,,,,,,,,,,,,,,
,3737929492.8415,49.9841461181641,4114.07885742188,4.35784505542189E-5,3.04445262313793E-7,1,0.999253354069792,40.0298881530762,1.99660393712265,16.1700006574392,0.000470470823807376,7.59398977798632E-5,0.25,-8.77732526633124E-7,4.35593283214051E-5,-5.52993590550257E-7,49.9841423034668,49.9841423034668,4089.05224609375,4139.10546875,54.894552534102,19.7341693794604,13.8931274414062,0,0,0,40,50.0175361633301,1,6,1,2.16552734375,44.4770278930664,,,,,,,,,,,,,,,,
,3737929576.81,49.9880523681641,8313.40234375,2.90574955925116E-5,3.36670159045136E-7,1,0.999253354069792,40.0298881530762,1.99666693027358,16.1700006574392,0.000314615811767521,4.60432523897642E-5,0.25,-1.01314238833886E-6,2.90538958197977E-5,-7.96589668197125E-7,49.9879112243652,49.9879112243652,8283.4443359375,8343.3603515625,55.4010478145636,19.732694154545,13.9654607772827,0,0,0,40,50.0223121643066,1,6,1,2.14523315429687,44.9657897949219,,,,,,,,,,,,,,,,
,3737929660.693,49.9912242889404,12508.5703125,1.66525144602061E-5,2.30065324203232E-7,1,0.999253354069792,40.0298881530762,1.99653315219703,16.1700006574392,0.000180923029106045,2.31403589008836E-5,0.25,-8.82556449436074E-7,1.66563703428625E-5,-7.58651172613786E-7,49.9911575317383,49.9911575317383,12483.5439453125,12533.5966796875,55.0125784405058,19.7319614340283,14.025387763977,0,0,0,40,50.0257415771484,1,6,1,2.14767456054687,44.9657897949219,,,,,,,,,,,,,,,,
,3737929744.6785,49.9926319122314,16705.654296875,4.74581640155996E-6,2.42325651255675E-7,1,0.999253354069792,40.0298881530762,1.99682821222903,16.1700006574392,5.36216246172023E-5,-4.61100264041742E-6,0.25,-1.29264252332736E-6,4.75571818553418E-6,-1.25752480706866E-6,49.9926643371582,49.9926643371582,16683.177734375,16728.130859375,54.8359303951596,19.7356874577605,14.0793647766113,0,0,0,40,50.0275802612305,1,6,1,2.16415405273438,44.4770278930664,,,,,,,,,,,,,,,,
,3737929828.556,49.994686126709,20903.455078125,-6.98835904240919E-6,2.91045613177734E-7,1,0.999253354069792,40.0298881530762,1.9965847574673,16.1700006574392,-7.208335330796E-5,-3.10182661763364E-5,0.25,-1.60858717326016E-6,-6.97854434345328E-6,-1.66075174082463E-6,49.9948463439941,49.9948463439941,20878.453125,20928.45703125,54.9953826130827,19.7285918781625,14.1322135925293,0,0,0,40,50.0299949645996,1,6,1,2.1649169921875,44.9657897949219,,,,,,,,,,,,,,,,
,3737929912.511,49.9954128265381,25098.955078125,-1.74798199709305E-5,3.18159404321993E-7,1,0.999253354069792,40.0298881530762,1.99656041901964,16.1700006574392,-0.000185152468130786,-5.11772448709843E-5,0.25,-1.57010353039855E-6,-1.74775152175024E-5,-1.69970505786936E-6,49.9954452514648,49.9954452514648,25073.966796875,25123.943359375,55.0016356412366,19.7310829190057,14.1787691116333,0,0,0,40,50.0311431884766,1,6,1,2.15042114257813,44.4770278930664,,,,,,,,,,,,,,,,
,3737929996.445,49.9967250823975,29308.62890625,-2.81561765195491E-5,3.46191042403157E-7,1,0.999253354069792,40.0298881530762,1.99667188799845,16.1700006574392,-0.000299329369932982,-7.69462571694983E-5,0.25,-2.01838599235216E-6,-2.81628090156912E-5,-2.22631473621031E-6,49.9966926574707,49.9966926574707,29281.01953125,29336.23828125,54.853907851102,19.7293215069804,14.2250871658325,0,0,0,40,50.0334548950195,1,6,1,2.16506958007813,43.9882698059082,,,,,,,,,,,,,,,,
,3737930080.4135,49.9971046447754,33525.01953125,-3.83573648691017E-5,2.75870828228824E-7,1,0.999253354069792,40.0298881530762,1.99652066733982,16.1700006574392,-0.000409817834904537,-9.3990877296939E-5,0.25,-1.74426140146631E-6,-3.83825962702875E-5,-2.02549386767867E-6,49.9973220825195,49.9973220825195,33502.375,33547.6640625,54.901587190775,19.7315502296034,14.2683296203613,0,0,0,40,50.033992767334,1,6,1,2.1624755859375,44.9657897949219,,,,,,,,,,,,,,,,
,3737930164.3305,49.9984264373779,37739.291015625,-4.95371151657703E-5,3.52761920719989E-7,1,0.999253354069792,40.0298881530762,1.99646858395392,16.1700006574392,-0.000529486563340229,-0.000120773897458564,0.25,-2.19615634568171E-6,-4.95813111775304E-5,-2.55732690015871E-6,49.9983253479004,49.9983253479004,37714.19921875,37764.3828125,55.0250844968135,19.7309396494493,14.3088779449463,0,0,0,40,50.0348014831543,1,6,1,2.14752197265625,43.9882698059082,,,,,,,,,,,,,,,,
,3737930248.254,49.9979209899902,41950.1484375,-6.04518230463458E-5,3.80980205442431E-7,1,0.999253354069792,40.0298881530762,1.9966856222597,16.1700006574392,-0.000647537501940672,-0.000140953863261911,0.25,-2.08249863017969E-6,-6.05233806348978E-5,-2.51961915874046E-6,49.9978561401367,49.9978561401367,41925.02734375,41975.26953125,55.077453607602,19.7277755981533,14.3408203125,0,0,0,40,50.0352401733398,1,6,1,2.16445922851562,43.9882698059082,,,,,,,,,,,,,,,,
,3737930332.2165,49.9986572265625,46164.134765625,-7.16099049128364E-5,3.13841218830147E-7,1,0.999253354069792,40.0298881530762,1.99648670609858,16.1700006574392,-0.000767251962966912,-0.000166431274098659,0.25,-2.41945803976436E-6,-7.17103852029419E-5,-2.93333981965769E-6,49.9986457824707,49.9986457824707,46141.5625,46186.70703125,54.9336339600635,19.7284070748586,14.3704252243042,0,0,0,40,50.0350646972656,1,6,1,2.14874267578125,43.49951171875,,,,,,,,,,,,,,,,
,3737930416.151,49.9987297058105,50377.87109375,-8.22083546239529E-5,3.5509255909859E-7,1,0.999253354069792,40.0298881530762,1.99645826162643,16.1700006574392,-0.000880721326487793,-0.000192513852127425,0.25,-2.91413163593322E-6,-8.23398730326882E-5,-3.49948853372879E-6,49.9986686706543,49.9986686706543,50352.7734375,50402.96875,55.2009509136404,19.7325051749919,14.3913087844849,0,0,0,40,50.0364074707031,1,6,1,2.14691162109375,43.49951171875,,,,,,,,,,,,,,,,
,3737930500.0905,49.9986763000488,54610.453125,-9.34186211014472E-5,3.77141583700458E-7,1,0.999253354069792,40.0298881530762,1.99649442202131,16.1700006574392,-0.0010018402285041,-0.000214405877365907,0.25,-2.90951144965759E-6,-9.35898312520525E-5,-3.56795925400345E-6,49.9986686706543,49.9986686706543,54582.640625,54638.265625,54.914874875602,19.7276462146339,14.4158143997192,0,0,0,40,50.0353851318359,1,6,1,2.16262817382813,43.49951171875,,,,,,,,,,,,,,,,
,3737930584.068,49.9984283447266,58858.0234375,-0.000104790497066238,3.44336549070684E-7,1,0.999253354069792,40.0298881530762,1.99648341652126,16.1700006574392,-0.00112556706260862,-0.000231967042166206,0.25,-2.47583873327629E-6,-0.000105008571679646,-3.20551475344963E-6,49.9984321594238,49.9984321594238,58835.30078125,58880.74609375,55.0899596639097,19.7280120663425,14.4401817321777,0,0,0,40,50.0370025634766,1,6,1,2.16598510742187,43.49951171875,,,,,,,,,,,,,,,,
,3737930667.954,49.9994106292725,63098.08984375,-0.000116064221685642,3.18436446907003E-7,1,0.999253354069792,40.0298881530762,1.9965180886224,16.1700006574392,-0.00124716683702395,-0.000255582765760833,0.25,-2.62226544227778E-6,-0.000116328473555438,-3.42166357116526E-6,49.9994888305664,49.9994888305664,63072.79296875,63123.38671875,55.1040289772558,19.7322963951557,14.4695873260498,0,0,0,40,50.0355224609375,1,6,1,2.14385986328125,43.49951171875,,,,,,,,,,,,,,,,
,3737930751.8715,49.9999523162842,67340.8203125,-0.00012722806077881,3.31200324390312E-7,1,0.999253354069792,40.0298881530762,1.99629912611754,16.1700006574392,-0.00136655461473713,-0.000283922206607423,0.25,-3.23091986192361E-6,-0.000127538423610759,-4.09843789802467E-6,50.0000877380371,50.0000877380371,67315.4765625,67366.1640625,54.8367120236789,19.7297634535835,14.494270324707,0,0,0,40,50.035961151123,1,6,1,2.16476440429687,43.49951171875,,,,,,,,,,,,,,,,
,3737930835.816,49.9997215270996,71588.02734375,-0.000138974419597763,4.27872527134985E-7,1,0.999253354069792,40.0298881530762,1.99628808669146,16.1700006574392,-0.00149281083864763,-0.000311085997254902,0.25,-3.62407298082406E-6,-0.000139337100986927,-4.56107186420586E-6,49.9996109008789,49.9996109008789,71562.734375,71613.3203125,54.9054953333712,19.7265385308809,14.5236597061157,0,0,0,40,50.0364608764648,1,6,1,2.15057373046875,43.49951171875,,,,,,,,,,,,,,,,
,3737930919.7735,49.9999141693115,75833.14453125,-0.000150234208398516,3.82968542862559E-7,1,0.999253354069792,40.0298881530762,1.99641480769792,16.1700006574392,-0.00161513473686,-0.000330800826984619,0.25,-3.4149363904295E-6,-0.00015065480713333,-4.41432134021487E-6,49.9998741149902,49.9998741149902,75810.3515625,75855.9375,54.8648506503712,19.7288253880436,14.5446720123291,0,0,0,40,50.0360870361328,1,6,1,2.1649169921875,43.9882698059082,,,,,,,,,,,,,,,,
,3737931003.6705,50.0003185272217,80078.85546875,-0.000161866046655021,4.55433616598855E-7,1,0.999253354069792,40.0298881530762,1.9962741599334,16.1700006574392,-0.00173970077378556,-0.000360016225749536,0.25,-4.02407299335891E-6,-0.000162342994595787,-5.08856865414363E-6,50.0002555847168,50.0002555847168,80053.5078125,80104.203125,54.6436497794289,19.7287282541571,14.5675802230835,0,0,0,40,50.0360717773438,1,6,1,2.16583251953125,43.9882698059082,,,,,,,,,,,,,,,,
,3737931087.621,50.000020980835,84320.91015625,-0.000173256785396235,3.89974166835321E-7,1,0.999253354069792,40.0298881530762,1.99618358107846,16.1700006574392,-0.00186294571330036,-0.000381995787227049,0.25,-4.00779502368374E-6,-0.000173795905294241,-5.13180530661423E-6,49.9998817443848,49.9998817443848,84295.6796875,84346.140625,55.1556164595251,19.7292225917999,14.5828371047974,0,0,0,40,50.0350875854492,1,6,1,2.15057373046875,43.0107536315918,,,,,,,,,,,,,,,,
,3737931171.541,50.0016250610352,88565.9140625,-0.00018502157527324,4.26484179347428E-7,1,0.999253354069792,40.0298881530762,1.99635811629301,16.1700006574392,-0.00199016084434867,-0.000406608442338056,0.25,-4.16486007112706E-6,-0.000185625348028577,-5.34915024110199E-6,50.0017051696777,50.0017051696777,88538.0625,88593.765625,54.8195161962558,19.7270045520849,14.6075086593628,0,0,0,40,50.0354270935059,1,6,1,2.16506958007813,44.4770278930664,,,,,,,,,,,,,,,,
,3737931265.4855,49.9997577667236,87331.1875,-0.000180034319042202,5.30129871815742E-7,1,0.999253354069792,40.0298881530762,1.99620724838948,16.1700006574392,-0.00193684866393804,-0.000392546462367185,0.25,-3.76487016491139E-6,-0.000180616010846702,-4.92073476014398E-6,49.9998245239258,49.9998245239258,87306.3203125,87356.0546875,54.5115545596788,19.7304275102694,14.630274772644,0,0,0,40,50.0377616882324,1,6,1,2.14859008789062,43.49951171875,,,,,,,,,,,,,,,,
,3737931349.4065,50.0000591278076,83148.4140625,-0.000168404569747865,5.36336329750348E-7,1,0.999253354069792,40.0298881530762,1.99629040884536,16.1700006574392,-0.0018114801077164,-0.000367484688139077,0.25,-3.5380113787807E-6,-0.000168923839812033,-4.63329642333186E-6,50.0001182556152,50.0001182556152,83125.9609375,83170.8671875,54.864069021852,19.7303529722844,14.6614446640015,0,0,0,40,50.0378494262695,1,6,1,2.1502685546875,44.4770278930664,,,,,,,,,,,,,,,,
,3737931433.415,49.9990787506103,78963.64453125,-0.00015624970439423,4.11598333881229E-7,1,0.999253354069792,40.0298881530762,1.99658784278375,16.1700006574392,-0.00168086344220036,-0.000340140047749795,0.25,-3.19347210226437E-6,-0.000156708086352232,-4.22231426583359E-6,49.9989471435547,49.9989471435547,78941.21875,78986.0703125,55.0985575776212,19.7303790807378,14.685549736023,0,0,0,40,50.0373573303223,1,6,1,2.1636962890625,43.9882698059082,,,,,,,,,,,,,,,,
,3737931517.278,49.9990043640137,74783.03515625,-0.0001435191173946,3.10379125305232E-7,1,0.999253354069792,40.0298881530762,1.99634164801993,16.1700006574392,-0.00154263774503262,-0.000317028379134401,0.25,-3.35533943456997E-6,-0.000143914429006641,-4.31322360501046E-6,49.9990119934082,49.9990119934082,74760.6953125,74805.375,54.8265508529289,19.7293657560211,14.7017478942871,0,0,0,40,50.037540435791,1,6,1,2.16461181640625,44.4770278930664,,,,,,,,,,,,,,,,
,3737931601.2715,50.000431060791,70597.484375,-0.000131792471104975,3.98726721463767E-7,1,0.999253354069792,40.0298881530762,1.99634461617127,16.1700006574392,-0.00141585102311432,-0.000293879488900901,0.25,-3.32983689038729E-6,-0.000132131843522124,-4.22054258433155E-6,50.0004539489746,50.0004539489746,70570.203125,70624.765625,54.9805316712174,19.7269072353618,14.7252378463745,0,0,0,40,50.037281036377,1,6,1,2.15042114257813,44.9657897949219,,,,,,,,,,,,,,,,
,3737931685.158,49.9990520477295,66420.26953125,-0.000120365989786246,4.19007361009318E-7,1,0.999253354069792,40.0298881530762,1.99638821676322,16.1700006574392,-0.00129268864822757,-0.000269521114655085,0.25,-3.13895720204323E-6,-0.000120654367450431,-3.9619088187171E-6,49.9990921020508,49.9990921020508,66395.3671875,66445.171875,54.8671955359289,19.729606101103,14.7457504272461,0,0,0,40,50.0373382568359,1,6,1,2.16506958007813,43.9882698059082,,,,,,,,,,,,,,,,
,3737931769.132,49.9997444152832,62232.5859375,-0.000108593972290537,3.71522156773234E-7,1,0.999253354069792,40.0298881530762,1.99627795512975,16.1700006574392,-0.00116537832966194,-0.000246476836666052,0.25,-3.13585945036581E-6,-0.000108832433463887,-3.88708824213713E-6,49.9997444152832,49.9997444152832,62205.1796875,62259.9921875,55.0891780353904,19.7306029351767,14.7587022781372,0,0,0,40,50.0361289978027,1,6,1,2.16323852539062,44.4770278930664,,,,,,,,,,,,,,,,
,3737931853.0395,49.9993991851807,58054.375,-9.63159749238039E-5,4.35649130137152E-7,1,0.999253354069792,40.0298881530762,1.99641428509763,16.1700006574392,-0.00103368445382304,-0.00021751720801979,0.25,-2.67511631780694E-6,-9.65101444266491E-5,-3.34795726021059E-6,49.999210357666,49.999210357666,58029.37890625,58079.37109375,54.6530293216596,19.7309624591791,14.7699708938599,0,0,0,40,50.038890838623,1,6,1,2.16720581054687,44.9657897949219,,,,,,,,,,,,,,,,
,3737931936.9925,50.0003242492676,53869.75,-8.51975938055261E-5,3.32329644164157E-7,1,0.999253354069792,40.0298881530762,1.9962831541012,16.1700006574392,-0.000913216876114248,-0.000197360382522408,0.25,-2.8238545382355E-6,-8.53495901455999E-5,-3.42567406319996E-6,50.0003356933594,50.0003356933594,53844.84765625,53894.65234375,54.894552534102,19.7317689156612,14.7785530090332,0,0,0,40,50.0383110046387,1,6,1,2.1502685546875,44.4770278930664,,,,,,,,,,,,,,,,
,3737932020.8985,49.9997158050537,49690.203125,-7.41422279255934E-5,3.48846367281141E-7,1,0.999253354069792,40.0298881530762,1.99636265072406,16.1700006574392,-0.000794605413199461,-0.000171622673676642,0.25,-2.44295121411357E-6,-7.42596740083915E-5,-2.97126432464029E-6,49.9997673034668,49.9997673034668,49665.25390625,49715.15234375,54.8554711081404,19.7315430335218,14.785475730896,0,0,0,40,50.0381278991699,1,6,1,2.16552734375,44.4770278930664,,,,,,,,,,,,,,,,
,3737932104.886,50.0004539489746,45507.1953125,-6.27032242798539E-5,3.15192330975868E-7,1,0.999253354069792,40.0298881530762,1.99624064772891,16.1700006574392,-0.000670981831672216,-0.000149781620687633,0.25,-2.49573038977852E-6,-6.27864666067806E-5,-2.94684574300419E-6,50.0004692077637,50.0004692077637,45484.80859375,45529.58203125,55.1040289772558,19.730870661675,14.8034038543701,0,0,0,40,50.036434173584,1,6,1,2.15316772460938,44.4770278930664,,,,,,,,,,,,,,,,
,3737932188.8425,50.0004501342773,41322.63671875,-5.16183097423643E-5,3.31603224527424E-7,1,0.999253354069792,40.0298881530762,1.99631259395863,16.1700006574392,-0.000552169822104909,-0.000123798768912482,0.25,-2.09944878516443E-6,-5.16754523103499E-5,-2.47352669633455E-6,50.0005035400391,50.0005035400391,41300.23046875,41345.04296875,54.8148264251404,19.7308006815403,14.8205146789551,0,0,0,40,50.037525177002,1,6,1,2.16552734375,41.5444793701172,,,,,,,,,,,,,,,,
,3737932272.7,50.0002117156982,37145.21484375,-4.07865523316456E-5,3.15270225533053E-7,1,0.999253354069792,40.0298881530762,1.99640160024529,16.1700006574392,-0.000435676627757566,-0.000100810129036836,0.25,-1.9356840241907E-6,-4.08207468432245E-5,-2.23344709810996E-6,50.0000877380371,50.0000877380371,37120.15234375,37170.27734375,54.9367604741404,19.730727747867,14.8324060440063,0,0,0,40,50.0371894836426,1,6,1,2.16644287109375,44.9657897949219,,,,,,,,,,,,,,,,
,3737932356.719,50.0003700256348,32960.052734375,-3.01540558694384E-5,3.28510370007122E-7,1,0.999253354069792,40.0298881530762,1.99636581032261,16.1700006574392,-0.000320730021846859,-8.16223867427244E-5,0.25,-2.08960076515907E-6,-3.01677514694091E-5,-2.31151808444392E-6,50.0003890991211,50.0003890991211,32935.2109375,32984.89453125,54.8648506503712,19.7314614400645,14.8516550064087,0,0,0,40,50.0365142822266,1,6,1,2.14813232421875,43.9882698059082,,,,,,,,,,,,,,,,
,3737932440.583,49.9996738433838,28780.03515625,-2.00762201130792E-5,3.40968151644308E-7,1,0.999253354069792,40.0298881530762,1.99645929894085,16.1700006574392,-0.000213143392538896,-5.6286190696901E-5,0.25,-1.57168171512298E-6,-2.00794053738331E-5,-1.72009496458532E-6,49.9997291564941,49.9997291564941,28755.14453125,28804.92578125,55.1048106057751,19.7326489664563,14.8638515472412,0,0,0,40,50.0376739501953,1,6,1,2.16552734375,44.4770278930664,,,,,,,,,,,,,,,,
,3737932524.514,49.999979019165,24595.7509765625,-8.90541573596708E-6,3.50634830291463E-7,1,0.999253354069792,40.0298881530762,1.99629633113582,16.1700006574392,-9.19602378968023E-5,-3.90023826859039E-5,0.25,-2.00109073247406E-6,-8.89514846819457E-6,-2.06773490089849E-6,49.9998397827148,49.9998397827148,24570.884765625,24620.6171875,55.0618210372174,19.7323166197447,14.8745422363281,0,0,0,40,50.0376777648926,1,6,1,2.16537475585938,44.9657897949219,,,,,,,,,,,,,,,,
,3737932608.4745,49.9995536804199,20416.1279296875,2.10067602932797E-6,2.08619104021295E-7,1,0.999253354069792,40.0298881530762,1.99636185040126,16.1700006574392,2.56619611969194E-5,-1.26261720217395E-5,0.25,-1.55546076837405E-6,2.11275640535985E-6,-1.5403421114341E-6,49.999584197998,49.999584197998,20391.197265625,20441.05859375,54.9938193560443,19.7301210112273,14.8861980438232,0,0,0,40,50.0369911193848,1,6,1,2.16323852539062,44.4770278930664,,,,,,,,,,,,,,,,
,3737932692.382,50.0001544952393,16233.9755859375,1.24458088962957E-5,3.35373896852438E-7,1,0.999253354069792,40.0298881530762,1.99630228260878,16.1700006574392,0.000136520322613633,1.02196120608779E-5,0.25,-1.31701207752131E-6,1.24561061447767E-5,-1.22472578015903E-6,50,50,16206.5556640625,16261.3955078125,54.7296289165443,19.7294383619404,14.8864831924438,0,0,0,40,50.0383911132812,1,6,1,2.15103149414062,44.4770278930664,,,,,,,,,,,,,,,,
,3737932776.331,50.0009117126465,12050.2299804687,2.38156364367121E-5,2.97858195548848E-7,1,0.999253354069792,40.0298881530762,1.9963401432866,16.1700006574392,0.000258282377660192,3.54830243190061E-5,0.25,-1.03985282178336E-6,2.38189816193702E-5,-8.62639235649539E-7,50.0007247924805,50.0007247924805,12025.2705078125,12075.189453125,55.0000723841981,19.7275729797779,14.8935956954956,0,0,0,40,50.0373840332031,1,6,1,2.16537475585938,44.4770278930664,,,,,,,,,,,,,,,,
,3737932860.2575,49.9996395111084,7863.38818359375,3.60206712969773E-5,3.23972596410774E-7,1,0.999253354069792,40.0298881530762,1.99626430644892,16.1700006574392,0.000389122543789905,6.14772319301419E-5,0.25,-8.45737004311939E-7,3.6012458664419E-5,-5.77420338312069E-7,49.9995079040527,49.9995079040527,7838.37890625,7888.3974609375,55.006325412352,19.7298147216156,14.8948726654053,0,0,0,40,50.0374031066895,1,6,1,2.15072631835938,44.4770278930664,,,,,,,,,,,,,,,,
,3737932944.2405,50.000431060791,3670.97644042969,4.88594482169742E-5,3.63280859309804E-7,1,0.999253354069792,40.0298881530762,1.99631157907552,16.1700006574392,0.00052623837665558,9.15226972787785E-5,0.25,-3.89642935291882E-7,4.88328544719107E-5,-2.59030801702224E-8,50.0002784729004,50.0002784729004,3643.486328125,3698.46655273438,55.0047621553135,19.7290573437632,14.9089670181274,0,0,0,40,50.037841796875,1,6,1,2.16567993164062,44.4770278930664,,,,,,,,,,,,,,,,
,3737933034.1385,50.000244140625,-825.375579833984,6.93181850074831E-5,2.88188429325436E-7,1,0.999253354069792,40.0298881530762,1.99626769420725,16.1700006574392,0.000746730149375565,0.000128493227463191,0.25,-6.76830003469547E-7,6.92734343344674E-5,-1.60787118075482E-7,50.0003433227539,50.0003433227539,-850.228088378906,-800.523071289063,55.0532231235058,19.7288493275207,14.9164934158325,0,0,0,40,50.037525177002,1,6,1,2.16232299804687,43.9882698059082,,,,,,,,,,,,,,,,
,3737933121.091,50.0010719299316,-5171.1591796875,8.3147220063896E-5,3.14633152738156E-7,1,0.999253354069792,40.0298881530762,1.99637385446709,16.1700006574392,0.000895335741910554,0.000157336061252293,0.25,-5.17050869175625E-7,8.31066370913435E-5,1.01866880555602E-7,50.0010375976562,50.0010375976562,-5198.732421875,-5143.5859375,55.1321676039481,19.7296830533005,14.9255332946777,0,0,0,40,50.0369110107422,1,6,1,2.16552734375,44.4770278930664,,,,,,,,,,,,,,,,
,3737933204.9935,50.0001163482666,-9369.28564453125,8.75158127540571E-5,3.33095619775575E-7,1,0.999253354069792,40.0298881530762,1.99644695230444,16.1700006574392,0.000942599782614716,0.000165681679571615,0.25,-5.40273419094773E-7,8.74913508207795E-5,1.10840797734E-7,50,50,-9394.259765625,-9344.3115234375,55.0102335549481,19.7306680073344,14.9397802352905,0,0,0,40,50.036693572998,1,6,1,2.1502685546875,44.4770278930664,,,,,,,,,,,,,,,,
,3737933288.955,50.0001888275146,-13566.7021484375,8.3092184952601E-5,2.88755490019535E-7,1,0.999253354069792,40.0298881530762,1.99632170289806,16.1700006574392,0.000894148189987524,0.000162560205817332,0.25,-2.62616272877057E-8,8.30838330387409E-5,5.91030667180579E-7,50.0001373291016,50.0001373291016,-13594.130859375,-13539.2734375,55.0680740653712,19.7290567320895,14.9407224655151,0,0,0,40,50.037239074707,1,6,1,2.16461181640625,44.4770278930664,,,,,,,,,,,,,,,,
,3737933375.882,50.0002937316895,-17913.6650390625,6.77397797832081E-5,2.9843627324395E-7,1,0.999253354069792,40.0298881530762,1.99642264161254,16.1700006574392,0.000729952294047596,0.000128158352047414,0.25,-4.29349835222359E-7,6.77520719207777E-5,7.26814445124736E-8,50.0002937316895,50.0002937316895,-17938.6328125,-17888.697265625,55.1032473487366,19.7304657330145,14.9605331420898,0,0,0,40,50.0372924804687,1,6,1,2.16552734375,44.9657897949219,,,,,,,,,,,,,,,,
,3737933459.811,50.0003471374512,-22108.4208984375,4.97956197452442E-5,2.52723790216811E-7,1,0.999253354069792,40.0298881530762,1.9963860731964,16.1700006574392,0.000536397281616201,9.59128202280068E-5,0.25,-1.57985394899512E-7,4.98150133012404E-5,2.09852424320753E-7,50.000431060791,50.000431060791,-22133.423828125,-22083.41796875,55.0016356412366,19.7270730296121,14.9709434509277,0,0,0,40,50.0369415283203,1,6,1,2.15118408203125,44.9657897949219,,,,,,,,,,,,,,,,
,3737933543.786,50.0007057189941,-26309.20703125,3.82466825192717E-5,3.26904695312698E-7,1,0.999253354069792,40.0298881530762,1.9964001401279,16.1700006574392,0.000412609649863055,7.08336726273433E-5,0.25,-3.84925283042319E-7,3.82723769654907E-5,-1.03781939940562E-7,50.0007095336914,50.0007095336914,-26334.251953125,-26284.162109375,55.0813617501981,19.7308845284734,14.9867677688599,0,0,0,40,50.0366325378418,1,6,1,2.16644287109375,43.49951171875,,,,,,,,,,,,,,,,
,3737933627.7815,50.0003871917725,-30524.3974609375,3.58590796797364E-5,3.09532239843087E-7,1,0.999253354069792,40.0298881530762,1.99646703893709,16.1700006574392,0.00038694923285771,6.64497893047871E-5,0.25,-3.57537941736993E-7,3.58913883906085E-5,-9.54062843407782E-8,50.000358581543,50.000358581543,-30554.533203125,-30494.26171875,55.0274293823712,19.7325184067971,14.9911623001099,0,0,0,40,50.0361175537109,1,6,1,2.16583251953125,44.9657897949219,,,,,,,,,,,,,,,,
,3737933711.61,49.9997997283936,-34731.6484375,3.96893382015458E-5,3.24189704337958E-7,1,0.999253354069792,40.0298881530762,1.99629166963609,16.1700006574392,0.000427656059703404,7.73254587638282E-5,0.25,-4.41565649069802E-8,3.97315021708201E-5,2.44464723587823E-7,50.0000152587891,50.0000152587891,-34759.1796875,-34704.1171875,54.9906928419674,19.7311632858576,14.9991331100464,0,0,0,40,50.0363311767578,1,6,1,2.16583251953125,44.9657897949219,,,,,,,,,,,,,,,,
,3737933795.564,49.9991321563721,-38944.453125,4.69472449286781E-5,3.5966588204638E-7,1,0.999253354069792,40.0298881530762,1.9963810117578,16.1700006574392,0.000505682331211969,9.32037410637227E-5,0.25,1.09296382747356E-7,4.7006368857628E-5,4.484778608457E-7,49.9989814758301,49.9989814758301,-38969.66015625,-38919.24609375,55.0180498401404,19.7327588428624,15.0001735687256,0,0,0,40,50.0367813110352,1,6,1,2.16552734375,44.4770278930664,,,,,,,,,,,,,,,,
,3737933879.528,49.99928855896,-43159.298828125,5.55193590411208E-5,3.1923719625346E-7,1,0.999253354069792,40.0298881530762,1.99635934103407,16.1700006574392,0.000598051076994411,0.000110723557578294,0.25,1.76954699492642E-7,5.56009801795405E-5,5.74989795004589E-7,49.9995155334473,49.9995155334473,-43184.3515625,-43134.24609375,54.9484849019289,19.7304775990446,15.0033016204834,0,0,0,40,50.0365142822266,1,6,1,2.16690063476562,44.4770278930664,,,,,,,,,,,,,,,,
,3737933963.4275,50.000617980957,-47368.947265625,6.52746699276486E-5,3.19694289906358E-7,1,0.999253354069792,40.0298881530762,1.99628214863362,16.1700006574392,0.000702971888459871,0.000131767630302165,0.25,3.57502494356337E-7,6.5383339866902E-5,8.21701172798272E-7,50.0004234313965,50.0004234313965,-47394.01171875,-47343.8828125,55.0250844968135,19.728769611946,15.0072050094604,0,0,0,40,50.0363998413086,1,6,1,2.1661376953125,44.4770278930664,,,,,,,,,,,,,,,,
,3737934047.4175,50.000207901001,-51584.498046875,7.59261048565997E-5,3.94091139091356E-7,1,0.999253354069792,40.0298881530762,1.99642795127383,16.1700006574392,0.000817378224799803,0.000156212155988214,0.25,6.90054877385532E-7,7.60661149106492E-5,1.22551928300261E-6,50.0004959106445,50.0004959106445,-51609.51953125,-51559.4765625,55.0313375249674,19.7305764544207,15.0110387802124,0,0,0,40,50.0365028381348,1,6,1,2.15042114257813,44.4770278930664,,,,,,,,,,,,,,,,
,3737934131.307,50.0000476837158,-55822.509765625,8.64728977956497E-5,3.8907760968427E-7,1,0.999253354069792,40.0298881530762,1.99638780281847,16.1700006574392,0.000930707137855682,0.000180029198294395,0.25,9.85607989767988E-7,8.66481965419241E-5,1.58984327496653E-6,50.0001525878906,50.0001525878906,-55847.765625,-55797.25390625,55.1251329472751,19.7280020411986,15.0210046768188,0,0,0,40,50.0356101989746,1,6,1,2.16506958007813,44.9657897949219,,,,,,,,,,,,,,,,
,3737934215.254,50.0005264282227,-60066.1796875,9.7879258292208E-5,4.0416041283806E-7,1,0.999253354069792,40.0298881530762,1.99641354786518,16.1700006574392,0.00105340916793809,0.000205358101618687,0.25,1.26587740578938E-6,9.8095519194364E-5,1.9430046111437E-6,50.0004081726074,50.0004081726074,-60093.9765625,-60038.3828125,55.0321191534866,19.7285421367195,15.0346279144287,0,0,0,40,50.0353851318359,1,6,1,2.14797973632813,44.4770278930664,,,,,,,,,,,,,,,,
,3737934299.162,50.000114440918,-64310.474609375,0.000108837926496948,3.62505625834964E-7,1,0.999253354069792,40.0298881530762,1.99647462372379,16.1700006574392,0.00117269159876598,0.000222387034475748,0.25,8.59073474726113E-7,0.000109102355014579,1.60238165024495E-6,50.0001907348633,50.0001907348633,-64335.8359375,-64285.11328125,55.0594761516597,19.7296799148118,15.0301599502563,0,0,0,40,50.03662109375,1,6,1,2.14706420898438,44.4770278930664,,,,,,,,,,,,,,,,
,3737934383.11,49.9994239807129,-68552.05859375,0.000119586175879958,3.68421312952759E-7,1,0.999253354069792,40.0298881530762,1.99643023981708,16.1700006574392,0.00128723447203582,0.000252473863722914,0.25,1.70305642625869E-6,0.000119892912633954,2.51228074714409E-6,49.9991340637207,49.9991340637207,-68577.3671875,-68526.75,55.0532231235058,19.7298677804978,15.0333375930786,0,0,0,40,50.0370979309082,1,6,1,2.15057373046875,44.4770278930664,,,,,,,,,,,,,,,,
,3737934467.0705,50.0003471374512,-72798.33984375,0.000130902321914935,5.13117020709297E-7,1,0.999253354069792,40.0298881530762,1.99648134926391,16.1700006574392,0.00141023968373615,0.00027133281427576,0.25,1.4040553137887E-6,0.000131263659676381,2.27796734140315E-6,50.0001983642578,50.0001983642578,-72823.53125,-72773.1484375,54.678041434275,19.7324474231951,15.0290174484253,0,0,0,40,50.0362205505371,1,6,1,2.16705322265625,44.9657897949219,,,,,,,,,,,,,,,,
,3737934551,49.9994468688965,-77039.00390625,0.000142539662068233,3.89658661658777E-7,1,0.999253354069792,40.0298881530762,1.99652947574381,16.1700006574392,0.00153535087742422,0.00029852484930811,0.25,1.82036953924883E-6,0.000142954631339735,2.76100779262329E-6,49.9993629455566,49.9993629455566,-77064.1796875,-77013.828125,55.1141901480058,19.7290426895074,15.0392217636108,0,0,0,40,50.0362815856934,1,6,1,2.16461181640625,44.9657897949219,,,,,,,,,,,,,,,,
,3737934634.941,50.0009517669678,-81285.15625,0.000153733732052841,4.77149855099877E-7,1,0.999253354069792,40.0298881530762,1.9963189278103,16.1700006574392,0.00165621131346357,0.00032093497466945,0.25,1.87928092930554E-6,0.000154206144857534,2.88054423904004E-6,50.0009231567383,50.0009231567383,-81310.4453125,-81259.8671875,54.8062285114289,19.7292197813949,15.0489902496338,0,0,0,40,50.0353736877441,1,6,1,2.16598510742187,44.4770278930664,,,,,,,,,,,,,,,,
,3737934718.8615,50.0005187988281,-85526.0546875,0.00016525629705945,4.53136086956031E-7,1,0.999253354069792,40.0298881530762,1.9963591907084,16.1700006574392,0.00178056152545357,0.000345524995658978,0.25,2.07884477807151E-6,0.000165788696949357,3.14123714531631E-6,50.00048828125,50.00048828125,-85551.2734375,-85500.8359375,54.8476548229481,19.7302628811359,15.0475702285767,0,0,0,40,50.0366020202637,1,6,1,2.14736938476562,44.9657897949219,,,,,,,,,,,,,,,,
,3737934802.865,50.0004100799561,-89771.78125,0.000176847523111521,3.7486978428097E-7,1,0.999253354069792,40.0298881530762,1.9964033840535,16.1700006574392,0.00190605773318762,0.000368207314461982,0.25,2.09090199771946E-6,0.000177443706269923,3.21210109219901E-6,50.0002861022949,50.0002861022949,-89792.0234375,-89751.5390625,54.7890326840058,19.7298570663967,15.0580310821533,0,0,0,40,50.0358085632324,1,6,1,2.164306640625,45.4545478820801,,,,,,,,,,,,,,,,
,3737934895.7495,49.9986057281494,-86131.96875,0.000167045822754104,5.04808532523723E-7,1,0.999253354069792,40.0298881530762,1.99647770482136,16.1700006574392,0.00180067467343174,0.000345465511271016,0.25,1.748994121624E-6,0.000167589718846912,2.81969172092846E-6,49.9987106323242,49.9987106323242,-86156.8359375,-86107.1015625,54.9852214423327,19.7276056395736,15.0731439590454,0,0,0,40,50.0371246337891,1,6,1,2.166748046875,44.9657897949219,,,,,,,,,,,,,,,,
,3737934979.7055,49.9988613128662,-81951.2421875,0.00015525380210304,5.25189706325433E-7,1,0.999253354069792,40.0298881530762,1.99643798136242,16.1700006574392,0.00167342800226471,0.000320236180157248,0.25,1.53896884433761E-6,0.000155736921084466,2.54694086978063E-6,49.9986228942871,49.9986228942871,-81973.671875,-81928.8125,54.9094034759674,19.7288049560587,15.0817289352417,0,0,0,40,50.0382385253906,1,6,1,2.16339111328125,44.4770278930664,,,,,,,,,,,,,,,,
,3737935063.5925,49.9997634887695,-77771.9375,0.000143655945425637,4.43836760013745E-7,1,0.999253354069792,40.0298881530762,1.99656352474606,16.1700006574392,0.0015481663417413,0.000296881792187814,0.25,1.46684530100422E-6,0.000144080563968405,2.41165747416329E-6,49.999584197998,49.999584197998,-77794.328125,-77749.546875,54.9742786430635,19.7271967671065,15.0940084457397,0,0,0,40,50.0379104614258,1,6,1,2.16537475585938,44.9657897949219,,,,,,,,,,,,,,,,
,3737935147.593,49.9984455108643,-73588.61328125,0.000132607292843526,2.95961421209426E-7,1,0.999253354069792,40.0298881530762,1.99653700106516,16.1700006574392,0.00142905116301769,0.00027288755249411,0.25,1.23961427596202E-6,0.00013297864998762,2.12236533492297E-6,49.9984931945801,49.9984931945801,-73616,-73561.2265625,54.965680729352,19.7296448674287,15.0908880233765,0,0,0,40,50.038158416748,1,6,1,2.16415405273438,44.4770278930664,,,,,,,,,,,,,,,,
,3737935231.465,50.000244140625,-69410.19140625,0.000121457340123947,4.78273883707503E-7,1,0.999253354069792,40.0298881530762,1.99647410519535,16.1700006574392,0.00130832883345662,0.000251588620400107,0.25,1.28236711818439E-6,0.000121776180308711,2.10107822487946E-6,50.0001754760742,50.0001754760742,-69437.7265625,-69382.65625,54.9109667330058,19.7281587750408,15.1062631607056,0,0,0,40,50.037052154541,1,6,1,2.15042114257813,43.9882698059082,,,,,,,,,,,,,,,,
,3737935315.4405,49.9994773864746,-65225.60546875,0.000109934292639253,3.29572654228562E-7,1,0.999253354069792,40.0298881530762,1.99656752331464,16.1700006574392,0.00118511330686162,0.000221832878642527,0.25,6.08966389173381E-7,0.000110207425966879,1.35725027524091E-6,49.9994735717773,49.9994735717773,-65248.0703125,-65203.140625,54.864069021852,19.7284694097484,15.1087331771851,0,0,0,40,50.0364418029785,1,6,1,2.16232299804687,44.4770278930664,,,,,,,,,,,,,,,,
,3737935399.3425,49.9991073608398,-61048.755859375,9.85479365883681E-5,3.9380803633814E-7,1,0.999253354069792,40.0298881530762,1.99648487892304,16.1700006574392,0.00106146681924872,0.000202484508694648,0.25,8.78428961924774E-7,9.87726770473765E-5,1.55755595067013E-6,49.9990119934082,49.9990119934082,-61073.6796875,-61023.83203125,54.9719337575058,19.7286966451248,15.1110334396362,0,0,0,40,50.0378074645996,1,6,1,2.16567993164062,45.4545478820801,,,,,,,,,,,,,,,,
,3737935483.2815,50.0000038146973,-56864.99609375,8.76633461442176E-5,3.24607189417604E-7,1,0.999253354069792,40.0298881530762,1.99642634472829,16.1700006574392,0.000943873637576399,0.000180915620690252,0.25,8.52079599836227E-7,8.78462873098231E-5,1.46277106139678E-6,50.000072479248,50.000072479248,-56889.9296875,-56840.0625,55.0125784405058,19.7265459225182,15.1111478805542,0,0,0,40,50.0385589599609,1,6,1,2.16506958007813,44.4770278930664,,,,,,,,,,,,,,,,
,3737935567.219,50.000171661377,-52683.671875,7.67017068943514E-5,3.46654690552699E-7,1,0.999253354069792,40.0298881530762,1.99649511606066,16.1700006574392,0.000825968329125535,0.000156880233434738,0.25,6.11272264197145E-7,7.68477640707779E-5,1.15068029688708E-6,50.0002136230469,50.0002136230469,-52706.046875,-52661.296875,54.9187830181981,19.7299414816891,15.1114473342896,0,0,0,40,50.0379905700684,1,6,1,2.16567993164062,44.9657897949219,,,,,,,,,,,,,,,,
,3737935651.172,49.9993762969971,-48504.861328125,6.58809797876068E-5,3.68773279813303E-7,1,0.999253354069792,40.0298881530762,1.99655961519626,16.1799993366003,0.00070990921022649,0.000131505393126792,0.25,2.21855609009269E-7,6.59953052319398E-5,6.88984767628477E-7,49.999324798584,49.999324798584,-48527.26953125,-48482.453125,54.9742786430635,19.7281710094328,15.1221628189087,0,0,0,40,50.0385780334473,1,6,1,2.1527099609375,44.4770278930664,,,,,,,,,,,,,,,,
,3737935735.1105,50.0007286071777,-44321.470703125,5.52960139708393E-5,3.93080506246568E-7,1,0.999253354069792,40.0298881530762,1.99652355745175,16.1700006574392,0.000595363534135507,0.000112291421913628,0.25,3.62557869843537E-7,5.53792408829303E-5,7.58362489151714E-7,50.0008201599121,50.0008201599121,-44343.87109375,-44299.0703125,55.0125784405058,19.7307681545888,15.1176376342773,0,0,0,40,50.0373191833496,1,6,1,2.16552734375,44.4770278930664,,,,,,,,,,,,,,,,
,3737935819.03,49.9993114471436,-40142.78515625,4.43784008522613E-5,3.5461421326547E-7,1,0.999253354069792,40.0298881530762,1.99642168726366,16.1700006574392,0.000478244230205503,8.70514751191277E-5,0.25,5.71419382830736E-9,4.44377569372438E-5,3.25514811089198E-7,49.9992752075195,49.9992752075195,-40165.23046875,-40120.33984375,55.0829250072366,19.7274806747049,15.1308507919312,0,0,0,40,50.0372848510742,1,6,1,2.16583251953125,44.9657897949219,,,,,,,,,,,,,,,,
,3737935902.9635,50.0001316070557,-35961.306640625,3.43738270594307E-5,3.4261946156956E-7,1,0.999253354069792,40.0298881530762,1.99650616385413,16.1700006574392,0.000370290742825679,6.78172228550482E-5,0.25,3.99124237106323E-8,3.44120244630143E-5,2.89468863369911E-7,50.0001754760742,50.0001754760742,-35986.2265625,-35936.38671875,54.7984122262366,19.7313524253315,15.1302061080933,0,0,0,40,50.0379219055176,1,6,1,2.1661376953125,44.9657897949219,,,,,,,,,,,,,,,,
,3737935986.909,50.0008640289307,-31779.8837890625,2.37916610602978E-5,3.12008074879332E-7,1,0.999253354069792,40.0298881530762,1.99650585637646,16.1700006574392,0.000256917935742732,4.31904884104941E-5,0.25,-3.20560862279616E-7,2.38153227432926E-5,-1.47038336228759E-7,50.0009307861328,50.0009307861328,-31802.306640625,-31757.4609375,55.0344640390443,19.7293112163363,15.1229629516602,0,0,0,40,50.0371589660645,1,6,1,2.16522216796875,44.4770278930664,,,,,,,,,,,,,,,,
,3737936070.837,50.0008754730225,-27598.9873046875,1.41051096010152E-5,2.91720548976937E-7,1,0.999253354069792,40.0298881530762,1.99638006653316,16.1700006574392,0.000152227295914391,2.58474072154312E-5,0.25,-1.67530449949419E-7,1.41157706965414E-5,-6.40297824189419E-8,50.0009956359863,50.0009956359863,-27623.927734375,-27574.046875,54.8718853070443,19.7277781714516,15.1457948684692,0,0,0,40,50.0371856689453,1,6,1,2.16461181640625,44.9657897949219,,,,,,,,,,,,,,,,
,3737936154.765,49.9987812042236,-23419.939453125,3.29732266587995E-6,3.67896724638341E-7,1,0.999253354069792,40.0298881530762,1.99664381146654,16.1700006574392,3.62542971345177E-5,2.35013310447863E-6,0.25,-3.82107475195915E-7,3.30158677697207E-6,-3.57943343776279E-7,49.9987564086914,49.9987564086914,-23444.779296875,-23395.099609375,55.0039805267943,19.726872122309,15.1371059417725,0,0,0,40,50.0382270812988,1,6,1,2.16476440429687,44.9657897949219,,,,,,,,,,,,,,,,
,3737936238.7155,50.0002956390381,-19235.2578125,-6.76866187723753E-6,2.89364052765453E-7,1,0.999253354069792,40.0298881530762,1.99650784544558,16.1799993366003,-7.24696753714291E-5,-1.5424038181264E-5,0.25,-2.00241043116526E-7,-6.76858222974346E-6,-2.5040648261768E-7,50.0001029968262,50.0001029968262,-19260.1328125,-19210.3828125,55.0071070408712,19.7255582442144,15.1536483764648,0,0,0,40,50.0375137329102,1,6,1,2.15377807617187,45.4545478820801,,,,,,,,,,,,,,,,
,3737936322.637,50.0004825592041,-15056.6103515625,-1.74600295991331E-5,3.7376213071566E-7,1,0.999253354069792,40.0298881530762,1.99652697222094,16.1700006574392,-0.00018675905470637,-4.05363508227479E-5,0.25,-5.86623491886168E-7,-1.74552909103938E-5,-7.16234799337417E-7,50.0004005432129,50.0004005432129,-15081.517578125,-15031.703125,54.9391053596981,19.7273221472137,15.1602792739868,0,0,0,40,50.0370979309082,1,6,1,2.16537475585938,44.9657897949219,,,,,,,,,,,,,,,,
,3737936406.6205,49.9999675750732,-10868.9306640625,-2.90562933773069E-5,3.12633882298624E-7,1,0.999253354069792,40.0298881530762,1.99652941197435,16.1700006574392,-0.000310414100712057,-6.9163750921995E-5,0.25,-1.13569592049912E-6,-2.9040670460113E-5,-1.35146489965312E-6,50.0000801086426,50.0000801086426,-10893.8857421875,-10843.9755859375,54.8961157911404,19.72545989692,15.1495351791382,0,0,0,40,50.0370178222656,1,6,1,2.16705322265625,44.4770278930664,,,,,,,,,,,,,,,,
,3737936490.507,49.9998893737793,-6681.03979492188,-4.05086993476739E-5,2.99040512769385E-7,1,0.999253354069792,40.0298881530762,1.99655500693138,16.1700006574392,-0.000433373727982157,-9.25670094586908E-5,0.25,-1.22632353451148E-6,-4.0480873709002E-5,-1.52714850689637E-6,50.0000419616699,50.0000419616699,-6705.91796875,-6656.16162109375,55.046970095352,19.7278731747319,15.1710252761841,0,0,0,40,50.0376815795898,1,6,1,2.16476440429687,44.4770278930664,,,,,,,,,,,,,,,,
,3737936574.4745,50.000093460083,-2485.07678222656,-5.37510841337812E-5,2.64663930954931E-7,1,0.999253354069792,40.0298881530762,1.99645756938788,16.1700006574392,-0.000575131170318982,-0.000121565680521135,0.25,-1.51262180058692E-6,-5.3704629836736E-5,-1.91148593862327E-6,50.0000495910645,50.0000495910645,-2510.02490234375,-2460.12866210938,55.2142385984674,19.7276056933083,15.1699361801147,0,0,0,40,50.0363159179687,1,6,1,2.16567993164062,44.4770278930664,,,,,,,,,,,,,,,,
,3737936661.407,49.9994106292725,1858.15911865234,-7.46490661749523E-5,3.33095231396407E-7,1,0.999253354069792,40.0298881530762,1.99651204296533,16.1700006574392,-0.000800600123900387,-0.000158604795511211,0.25,-1.1500534105588E-6,-7.45897137147137E-5,-1.70454637767023E-6,49.9992828369141,49.9992828369141,1833.21472167969,1883.103515625,55.0712005794481,19.7279010025576,15.1678705215454,0,0,0,40,50.0370330810547,1,6,1,2.16415405273438,44.9657897949219,,,,,,,,,,,,,,,,
,3737936748.3795,50.0003986358643,6210.75073242188,-8.50981916706746E-5,2.79795045757907E-7,1,0.999253354069792,40.0298881530762,1.99658707599048,16.1700006574392,-0.000911542610243884,-0.000188173453834759,0.25,-1.9919964224573E-6,-8.50421334647717E-5,-2.62418584643593E-6,50.0004768371582,50.0004768371582,6183.28759765625,6238.2138671875,54.9031504478135,19.7286152632732,15.171462059021,0,0,0,40,50.0366477966309,1,6,1,2.16705322265625,44.9657897949219,,,,,,,,,,,,,,,,
,3737936835.266,50.000020980835,10553.494140625,-8.73442102076621E-5,2.65760087380033E-7,1,0.999253354069792,40.0298881530762,1.99645147030867,16.1700006574392,-0.000936392322409515,-0.000189630789718178,0.25,-1.7161133014064E-6,-8.73084207464661E-5,-2.36516361781525E-6,50.0000419616699,50.0000419616699,10528.5048828125,10578.4833984375,55.0430619527558,19.7278574536718,15.1735467910767,0,0,0,40,50.0363502502441,1,6,1,2.16552734375,46.9208221435547,,,,,,,,,,,,,,,,
,3737936919.1985,50.0004348754883,14748.2133789062,-7.96202854123455E-5,2.93144617736301E-7,1,0.999253354069792,40.0298881530762,1.99649323692729,16.1700006574392,-0.000853361081977438,-0.000175288926275557,0.25,-1.78697967085092E-6,-7.96039304229257E-5,-2.37810277984401E-6,50.0005989074707,50.0005989074707,14723.1943359375,14773.232421875,54.9508297874866,19.7281290666106,15.1714525222778,0,0,0,40,50.0375747680664,1,6,1,2.16567993164062,44.4770278930664,,,,,,,,,,,,,,,,
,3737937003.226,50.0002346038818,18951.041015625,-6.24243572285682E-5,2.79986143009688E-7,1,0.999253354069792,40.0298881530762,1.99647559480741,16.1700006574392,-0.000668483760839302,-0.000141426635323531,0.25,-1.77064179922995E-6,-6.24232038778508E-5,-2.23334614707687E-6,50.0001106262207,50.0001106262207,18923.509765625,18978.572265625,54.9211279037558,19.7272239321357,15.173282623291,0,0,0,40,50.0366096496582,1,6,1,2.16461181640625,44.9657897949219,,,,,,,,,,,,,,,,
,3737937087.0645,50.0002670288086,23144.4287109375,-4.5636445134301E-5,2.67088591963317E-7,1,0.999253354069792,40.0298881530762,1.99665170710218,16.1700006574392,-0.000488074339949029,-0.000107748277729246,0.25,-1.69720074473854E-6,-4.56432329911248E-5,-2.0347649822587E-6,50.0002708435059,50.0002708435059,23119.4375,23169.419921875,54.8414017947943,19.7279701463185,15.1895198822021,0,0,0,40,50.036205291748,1,6,1,2.14736938476562,44.9657897949219,,,,,,,,,,,,,,,,
,3737937171.013,50.0001049041748,27344.1748046875,-3.64526991411895E-5,3.44588118736919E-7,1,0.999253354069792,40.0298881530762,1.99665865570966,16.1700006574392,-0.000388732764676899,-9.27582333136404E-5,0.25,-1.97646768721891E-6,-3.64620319052813E-5,-2.2456163269676E-6,50.0002326965332,50.0002326965332,27319.056640625,27369.29296875,54.9750602715827,19.7317890033769,15.1861867904663,0,0,0,40,50.035816192627,1,6,1,2.16537475585938,44.9657897949219,,,,,,,,,,,,,,,,
,3737937254.9345,49.9999160766602,31559.830078125,-3.56473966834644E-5,2.91729181493592E-7,1,0.999253354069792,40.0298881530762,1.99671971961816,16.1700006574392,-0.000380604577404687,-8.87514939837905E-5,0.25,-1.75040157661706E-6,-3.56661173186859E-5,-2.01245369208878E-6,49.9996566772461,49.9996566772461,31534.8515625,31584.80859375,54.8531262225827,19.7260856188726,15.1877212524414,0,0,0,40,50.0359230041504,1,6,1,2.16629028320313,44.9657897949219,,,,,,,,,,,,,,,,
,3737937338.912,49.9993305206299,35774.390625,-4.0343656912933E-5,3.4208403928034E-7,1,0.999253354069792,40.0298881530762,1.99668769270259,16.1700006574392,-0.000431442443964572,-9.71407476975429E-5,0.25,-1.67445027232568E-6,-4.03762634046788E-5,-1.96924489043709E-6,49.9992980957031,49.9992980957031,35746.765625,35802.015625,54.9109667330058,19.7273636328008,15.1917238235474,0,0,0,40,50.0363807678223,1,6,1,2.16552734375,44.4770278930664,,,,,,,,,,,,,,,,
,3737937422.871,50.0004787445068,39990.173828125,-4.72776800718763E-5,3.31102484645976E-7,1,0.999253354069792,40.0298881530762,1.99661745990274,16.1700006574392,-0.000505520363608402,-0.000114801309477581,0.25,-2.05232778144217E-6,-4.73258025157705E-5,-2.39583699542957E-6,50.0006294250488,50.0006294250488,39962.51953125,40017.828125,55.0907412924289,19.7265672655751,15.1784057617188,0,0,0,40,50.0360336303711,1,6,1,2.1502685546875,44.9657897949219,,,,,,,,,,,,,,,,
,3737937506.804,49.999605178833,44203.45703125,-5.68270407232125E-5,3.0845973247448E-7,1,0.999253354069792,40.0298881530762,1.99658289975064,16.1700006574392,-0.000608495834587917,-0.000133912399754575,0.25,-2.08950952867104E-6,-5.68999462509968E-5,-2.49902606532771E-6,49.9996643066406,49.9996643066406,44183.359375,44223.5546875,54.9101851044866,19.7277642151462,15.1710453033447,0,0,0,40,50.0349769592285,1,6,1,2.16400146484375,44.4770278930664,,,,,,,,,,,,,,,,
,3737937590.6705,50.0005054473877,48412.671875,-6.67000476741093E-5,4.09454585034881E-7,1,0.999253354069792,40.0298881530762,1.99661710505322,16.1700006574392,-0.000714819668849074,-0.000154776576570794,0.25,-2.23084605480303E-6,-6.6801291343273E-5,-2.70739422014918E-6,50.0003967285156,50.0003967285156,48390.109375,48435.234375,54.9992907556789,19.7268834544972,15.1695680618286,0,0,0,40,50.034969329834,1,6,1,2.16445922851562,44.9657897949219,,,,,,,,,,,,,,,,
,3737937674.6155,50.0004577636719,52631.0078125,-7.66871230877376E-5,3.12100488882604E-7,1,0.999253354069792,40.0298881530762,1.9966004351011,16.1700006574392,-0.00082219848278969,-0.000176959033483158,0.25,-2.47494541538183E-6,-7.6819885113835E-5,-3.01796402400559E-6,50.0005722045898,50.0005722045898,52605.76171875,52656.25390625,55.0258661253327,19.7262790909566,15.1740026473999,0,0,0,40,50.0349807739258,1,6,1,2.16476440429687,44.4770278930664,,,,,,,,,,,,,,,,
,3737937758.5585,50.0002040863037,56878.154296875,-8.77686272043453E-5,3.47140704570884E-7,1,0.999253354069792,40.0298881530762,1.99668967540965,16.1700006574392,-0.000941904140768462,-0.000198897448393801,0.25,-2.49779151122859E-6,-8.79404212030192E-5,-3.1127398358913E-6,50.0002784729004,50.0002784729004,56852.90625,56903.40234375,54.9648991008327,19.7273196096883,15.1716613769531,0,0,0,40,50.0353584289551,1,6,1,2.16476440429687,44.4770278930664,,,,,,,,,,,,,,,,
,3737937842.4895,50.0012989044189,61120.638671875,-9.91039738571641E-5,4.24325191599182E-7,1,0.999253354069792,40.0298881530762,1.99666947280638,16.1700006574392,-0.00106400039436327,-0.000223218077119102,0.25,-2.69755960601977E-6,-9.93178678652108E-5,-3.38463139650132E-6,50.0015525817871,50.0015525817871,61095.3515625,61145.92578125,54.8421834233135,19.7271622694754,15.1727476119995,0,0,0,40,50.0337944030762,1,6,1,2.16461181640625,44.9657897949219,,,,,,,,,,,,,,,,
,3737937926.419,50.0000839233398,65363.123046875,-0.000109704814151771,3.26466997967332E-7,1,0.999253354069792,40.0298881530762,1.99667767839573,16.1700006574392,-0.00117786372671391,-0.000248082564409967,0.25,-3.08210181057686E-6,-0.000109961225378384,-3.83479253679689E-6,49.9999618530273,49.9999618530273,65337.8203125,65388.42578125,54.9492665304481,19.7264000852898,15.174220085144,0,0,0,40,50.0340919494629,1,6,1,2.1453857421875,44.9657897949219,,,,,,,,,,,,,,,,
,3737938010.357,50.0007629394531,69610.796875,-0.000121186859245413,3.65043241426869E-7,1,0.999253354069792,40.0298881530762,1.99665769416775,16.1700006574392,-0.00130236783166079,-0.00026854315564695,0.25,-2.90046948162687E-6,-0.000121495117105235,-3.72127361071553E-6,50.0009422302246,50.0009422302246,69585.53125,69636.0625,54.9531746730443,19.7267365405098,15.1814308166504,0,0,0,40,50.0337524414063,1,6,1,2.16323852539062,44.9657897949219,,,,,,,,,,,,,,,,
,3737938094.327,49.9997501373291,73855.484375,-0.000131957469419965,4.2961313061759E-7,1,0.999253354069792,40.0298881530762,1.99661393113993,16.1700006574392,-0.0014182850510042,-0.000292692622946114,0.25,-3.19153270201498E-6,-0.000132315437322806,-4.0748834884518E-6,49.9997787475586,49.9997787475586,73827.6171875,73883.3515625,54.8828281063135,19.7260112088527,15.1899604797363,0,0,0,40,50.0348587036133,1,6,1,2.16522216796875,44.9657897949219,,,,,,,,,,,,,,,,
,3737938178.2275,49.9995059967041,78101.28125,-0.000143570261054916,5.55083004652258E-7,1,0.999253354069792,40.0298881530762,1.99662348674012,16.1700006574392,-0.00154393989730607,-0.000315295060527262,0.25,-3.18756559516754E-6,-0.000143985142331085,-4.13610196891015E-6,49.9997367858887,49.9997367858887,78076.046875,78126.515625,54.9805316712174,19.7261273004471,15.1915464401245,0,0,0,40,50.0353889465332,1,6,1,2.16522216796875,44.9657897949219,,,,,,,,,,,,,,,,
,3737938262.163,49.9995937347412,82343.40625,-0.00015479743107559,3.41442067485116E-7,1,0.999253354069792,40.0298881530762,1.99660540471422,16.1700006574392,-0.00166490151061556,-0.000340108813329623,0.25,-3.4603183397901E-6,-0.000155268902030005,-4.47023967463317E-6,49.9995613098145,49.9995613098145,82318.078125,82368.734375,54.7233758883904,19.726413297703,15.2003536224365,0,0,0,40,50.0341873168945,1,6,1,2.16659545898438,44.9657897949219,,,,,,,,,,,,,,,,
,3737938346.1115,50.000545501709,86587.80078125,-0.000166201781798675,4.64003980108024E-7,1,0.999253354069792,40.0298881530762,1.99664699140398,16.1700006574392,-0.00178831695963403,-0.000362714016664598,0.25,-3.4972265145143E-6,-0.000166734391979055,-4.56681838571506E-6,50.0005111694336,50.0005111694336,86565.171875,86610.4296875,54.9297258174673,19.7254239232037,15.204873085022,0,0,0,40,50.0340881347656,1,6,1,2.16445922851562,44.9657897949219,,,,,,,,,,,,,,,,
,3737938417.0655,50.0001029968262,90002.3125,-0.000178429486555936,1.00448667309816E-6,1,0.999253354069792,40.0298881530762,1.99657359009608,16.1700006574392,-0.00192479061739157,-0.000363177172625524,0.25,-1.33683047155221E-6,-0.000179037231101273,-2.46455457854657E-6,50.0002784729004,50.0002784729004,90000.59375,90004.03125,54.8968974196597,19.7258739059229,15.2058868408203,0,0,0,40,50.0352783203125,1,4,1,2.16552734375,44.9657897949219,,,,,,,,,,,,,,,,