File: data/doubleLayers/dl_2-5/ppms/DD205_5/DD205_5_FCC_100OE.DAT
[Header]
; VSM Data File (default extension .dat)
; Copyright (c) 2003-2013, Quantum Design, Inc. All rights reserved.
TITLE,
FILEOPENTIME,3737887058.08907,06/11/2018,1:59 pm
BYAPP,VSM,1.0,1.0
INFO,DYNACOOL VSM Option Release 1.4.10 Build 1,APPNAME
INFO,Quantum Design Linear Motor Servo Controller,MOTOR_MODULE_NAME
INFO,3101-100 J0,MOTOR_HW_VERSION
INFO,MMC654,MOTOR_SERIAL_NUMBER
INFO,SRV No X-over 01.03.11,MOTOR_SOFTWARE_VERSION
INFO,Quantum Design VSM Detection Module,VSM_MODULE_NAME
INFO,3101-150 F0,VSM_HW_VERSION
INFO,VSM507,VSM_SERIAL_NUMBER
INFO,VSM No X-over 01.02.05 May 20 2008 13:51:47,VSM_SOFTWARE_VERSION
INFO,494,PREAMP_SERIAL_NUMBER
INFO,Quantum Design VSM Oven,OVEN_MODULE_NAME
INFO,3101-201 A1,OVEN_HW_VERSION
INFO,OVB210,OVEN_SERIAL_NUMBER
INFO,01.06.24,OVEN_SOFTWARE_VERSION
INFO,593,COIL_SERIAL_NUMBER
INFO,0,MOMENT_UNITS
INFO,CoFe2O4,SAMPLE_MATERIAL
INFO,,SAMPLE_COMMENT
INFO,,SAMPLE_MASS
INFO,,SAMPLE_VOLUME
INFO,,SAMPLE_MOLECULAR_WEIGHT
INFO,,SAMPLE_SIZE
INFO,,SAMPLE_SHAPE
DATATYPE,COMMENT,1
DATATYPE,TIME,2
STARTUPAXIS,X,2
STARTUPAXIS,Y1,5
[Data]
Comment,Time Stamp (sec),Temperature (K),Magnetic Field (Oe),Moment (emu),M. Std. Err. (emu),Transport Action,Averaging Time (sec),Frequency (Hz),Peak Amplitude (mm),Center Position (mm),Coil Signal' (mV),Coil Signal" (mV),Range (mV),M. Quad. Signal (emu),M. Raw' (emu),M. Raw" (emu),Min. Temperature (K),Max. Temperature (K),Min. Field (Oe),Max. Field (Oe),Mass (grams),Motor Lag (deg),Pressure (Torr),VSM Status (code),Motor Status (code),Measure Status (code),Measure Count,System Temp. (K),Temp. Status (code),Field Status (code),Chamber Status (code),Motor Current (amps),Motor Heatsink Temp. (C),Map 01,Map 02,Map 03,Map 04,Map 05,Map 06,Map 07,Map 08,Map 09,Map 10,Map 11,Map 12,Map 13,Map 14,Map 15,Map 16
,3737887162.92,350.235824584961,99.8805694580078,1.05327912091166E-5,3.87579982224655E-7,1,0.999253354069792,40.0298881530762,2.00068397689357,16.1799993366003,0.000115454270619858,8.83290044296674E-6,0.25,-1.02413438845276E-6,1.05150918046476E-5,-1.01648682322173E-6,350.235443115234,350.235443115234,99.8684692382813,99.8926696777344,55.0196130971789,19.6857404328207,37.7728805541992,0,0,0,40,351.385345458984,1,4,1,2.15682983398438,43.9882698059082,,,,,,,,,,,,,,,,
,3737887312.8005,346.996688842773,99.8987197875977,1.06484505476369E-5,4.13728533183384E-7,1,0.999253354069792,40.0298881530762,2.00068048768993,16.1799993366003,0.000116755963005473,8.80742906352392E-6,0.25,-1.04688501360992E-6,1.06317011769249E-5,-1.03918870533167E-6,347.004272460937,347.004272460937,99.8926696777344,99.9047698974609,55.1728122869481,19.686504980092,37.8481712341309,0,0,0,40,345.434906005859,6,4,1,2.16232299804687,44.9657897949219,,,,,,,,,,,,,,,,
,3737887456.64,343.497802734375,99.8866157531738,1.05434803257384E-5,4.21327860002454E-7,1,0.999253354069792,40.0298881530762,2.0007176491818,16.1799993366003,0.00011478278323436,1.35073038136761E-5,0.25,-5.92722791395107E-7,1.05278685812109E-5,-5.85830799826711E-7,343.507141113281,343.507141113281,99.8563690185547,99.916862487793,55.2040774277174,19.6868040555683,37.8487129211426,0,0,0,40,341.670745849609,6,4,1,2.15408325195313,45.4545478820801,,,,,,,,,,,,,,,,
,3737887598.612,339.997024536133,99.8805694580078,1.0562888330527E-5,3.44402620275273E-7,1,0.999253354069792,40.0298881530762,2.00065788280804,16.1799993366003,0.000116292999686159,6.17151846124917E-6,0.25,-1.2767037102819E-6,1.05488731521434E-5,-1.26884891401718E-6,340.005798339844,340.005798339844,99.8684692382813,99.8926696777344,55.1055922342943,19.6842293019164,37.7917709350586,0,0,0,40,338.022674560547,6,4,1,2.14813232421875,45.4545478820801,,,,,,,,,,,,,,,,
,3737887740.497,336.483917236328,99.9108123779297,1.08728160663254E-5,3.71844019957253E-7,1,0.999253354069792,40.0298881530762,2.00075676457663,16.1799993366003,0.000118234497960536,1.48674589948651E-5,0.25,-5.24692523458991E-7,1.0859216049661E-5,-5.17700530844533E-7,336.491546630859,336.491546630859,99.8684692382813,99.9531555175781,55.0540047520251,19.6849185481129,37.7129707336426,0,0,0,40,334.410888671875,6,4,1,2.1575927734375,44.9657897949219,,,,,,,,,,,,,,,,
,3737887881.3635,332.993667602539,99.8987197875977,1.12135774843144E-5,3.66315232156129E-7,1,0.999253354069792,40.0298881530762,2.00081079023036,16.1799993366003,0.000122866601165457,1.01430980338933E-5,0.25,-1.02267979634577E-6,1.1201153254993E-5,-1.01489746911294E-6,333.009155273438,333.009155273438,99.8926696777344,99.9047698974609,55.0407170671981,19.6848345820579,37.5685920715332,0,0,0,40,330.833129882812,6,4,1,2.15484619140625,44.9657897949219,,,,,,,,,,,,,,,,
,3737888022.24,329.493682861328,99.8987159729004,1.1018905646302E-5,3.78158671951219E-7,1,0.999253354069792,40.0298881530762,2.00071706074196,16.1799993366003,0.000121633484218512,4.8791649612743E-6,0.25,-1.4767999683314E-6,1.10082872976189E-5,-1.46870214899722E-6,329.503540039063,329.503540039063,99.8805694580078,99.916862487793,54.881264849275,19.6876385836678,37.5621147155762,0,0,0,40,327.262054443359,6,4,1,2.15591430664062,46.4320640563965,,,,,,,,,,,,,,,,
,3737888163.124,325.996109008789,99.9047660827637,1.13311813835383E-5,3.69415353643016E-7,1,0.999253354069792,40.0298881530762,2.00076757844117,16.1799993366003,0.000123403488756894,1.46994757450357E-5,0.25,-6.21242182081288E-7,1.13210770768638E-5,-6.13842922233543E-7,326.013763427734,326.013763427734,99.8926696777344,99.916862487793,55.0891780353904,19.6857740038791,37.4962692260742,0,0,0,40,323.719879150391,6,4,1,2.15728759765625,50.3421325683594,,,,,,,,,,,,,,,,
,3737888304.0565,322.486267089844,99.8926658630371,1.19563054222565E-5,3.81634149788603E-7,1,0.999253354069792,40.0298881530762,2.00070611493131,16.1799993366003,0.000130218439744339,1.55396312746882E-5,0.25,-6.5302778207131E-7,1.19470767277239E-5,-6.45210818030715E-7,322.502807617188,322.502807617188,99.8684692382813,99.916862487793,55.0930861779866,19.6860429788855,37.3853530883789,0,0,0,40,320.161651611328,6,4,1,2.15835571289062,45.4545478820801,,,,,,,,,,,,,,,,
,3737888444.921,318.98454284668,99.916862487793,1.21262671655819E-5,3.46059559737676E-7,1,0.999253354069792,40.0298881530762,2.00070077435948,16.1799993366003,0.000133215469866119,9.30675962036498E-6,0.25,-1.26074154775361E-6,1.21187341910679E-5,-1.25238858762038E-6,318.993225097656,318.993225097656,99.916862487793,99.916862487793,54.9680256149097,19.6858384523582,37.3435249328613,0,0,0,40,316.607788085937,6,4,1,2.15667724609375,44.9657897949219,,,,,,,,,,,,,,,,
,3737888585.814,315.483688354492,99.9471092224121,1.1833044755776E-5,2.97509362767517E-7,1,0.999253354069792,40.0298881530762,2.0007457633736,16.1799993366003,0.000129867103519001,9.9146560644419E-6,0.25,-1.15328062774363E-6,1.18270773264401E-5,-1.14522626118067E-6,315.499664306641,315.499664306641,99.9410629272461,99.9531555175781,55.067292436852,19.6853756997582,37.2838859558105,0,0,0,40,313.067718505859,6,4,1,2.15499877929687,44.4770278930664,,,,,,,,,,,,,,,,
,3737888726.7725,311.977661132812,99.9652557373047,1.22256236424663E-5,3.3977348660933E-7,1,0.999253354069792,40.0298881530762,2.00070510887925,16.1799993366003,0.000132174748437068,2.17488918810617E-5,0.25,-1.25632197817307E-7,1.22202681474156E-5,-1.17827207952262E-7,311.986694335937,311.986694335937,99.9531555175781,99.9773559570312,55.026647753852,19.6832868174819,37.2936019897461,0,0,0,40,309.511383056641,6,4,1,2.15316772460938,44.4770278930664,,,,,,,,,,,,,,,,
,3737888867.66,308.478256225586,100.031791687012,1.23244176367628E-5,3.4308208960393E-7,1,0.999253354069792,40.0298881530762,2.00074361671454,16.1799993366003,0.000134225467621979,1.64227102881859E-5,0.25,-6.36786085281976E-7,1.23208365947785E-5,-6.2866330031282E-7,308.497894287109,308.497894287109,100.013641357422,100.049942016602,55.168904144352,19.6850822552571,37.2177696228027,0,0,0,40,305.959838867188,6,4,1,2.15469360351562,43.9882698059082,,,,,,,,,,,,,,,,
,3737889007.5035,304.996627807617,100.062042236328,1.22688656848896E-5,3.84042392784077E-7,1,0.999253354069792,40.0298881530762,2.00073340709818,16.1799993366003,0.000133668260714685,1.61662002619822E-5,0.25,-6.51103265897238E-7,1.22667958438189E-5,-6.429830008914E-7,305.011932373047,305.011932373047,100.062042236328,100.062042236328,55.0618210372174,19.6830386192655,37.2053565979004,0,0,0,40,302.442230224609,6,4,1,2.15408325195313,43.9882698059082,,,,,,,,,,,,,,,,
,3737889148.3795,301.491668701172,100.086235046387,1.26581853855105E-5,3.78352354219995E-7,1,0.999253354069792,40.0298881530762,2.00071630768573,16.1799993366003,0.00013851474175668,1.3317250272929E-5,0.25,-9.83466161561707E-7,1.26578004106498E-5,-9.75030019180522E-7,301.508819580078,301.508819580078,100.086235046387,100.086235046387,55.1063738628135,19.6850447910049,37.1656837463379,0,0,0,40,298.917053222656,6,4,1,2.15377807617187,43.9882698059082,,,,,,,,,,,,,,,,
,3737889289.271,297.977523803711,100.110431671143,1.29723933190223E-5,4.18662655860835E-7,1,0.999253354069792,40.0298881530762,2.00068602107627,16.1799993366003,0.000141215486137363,1.79479592597223E-5,0.25,-6.09861889046464E-7,1.29733256014613E-5,-6.01202350735701E-7,297.987121582031,297.987121582031,100.086235046387,100.134628295898,55.0360272960828,19.6835730070752,37.1413993835449,0,0,0,40,295.379455566406,6,4,1,2.154541015625,43.49951171875,,,,,,,,,,,,,,,,
,3737889429.218,294.496276855469,100.152770996094,1.30732662551211E-5,3.41590959548304E-7,1,0.999253354069792,40.0298881530762,2.00067528863001,16.1700006574392,0.000143133528242675,1.3503208387822E-5,0.25,-1.03946790138348E-6,1.30760835836669E-5,-1.03075986600305E-6,294.505615234375,294.505615234375,100.14672088623,100.158821105957,55.4057375856789,19.6838388677932,37.1036148071289,0,0,0,40,291.887786865234,6,4,1,2.16293334960938,44.4770278930664,,,,,,,,,,,,,,,,
,3737889570.0975,290.98193359375,100.031791687012,1.32020466974819E-5,3.69645147235974E-7,1,0.999253354069792,40.0298881530762,2.00066679757772,16.1799993366003,0.000144536993858179,1.37732370249347E-5,0.25,-1.03730066266084E-6,1.32065096536857E-5,-1.02850158227694E-6,290.989074707031,290.989074707031,100.013641357422,100.049942016602,55.1939162569674,19.6823178095608,37.0550422668457,0,0,0,40,288.341705322266,6,4,1,2.15728759765625,44.4770278930664,,,,,,,,,,,,,,,,
,3737889709.976,287.492767333984,100.025741577148,1.33449068981072E-5,4.23339248566717E-7,1,0.999253354069792,40.0298881530762,2.00066975486268,16.1799993366003,0.000145648974876661,1.66077245650194E-5,0.25,-8.00183639897532E-7,1.33508782206199E-5,-7.91181767231027E-7,287.507934570313,287.507934570313,100.013641357422,100.037841796875,55.0211763542174,19.6835783011851,37.0129432678223,0,0,0,40,284.856567382813,6,4,1,2.15713500976562,43.9882698059082,,,,,,,,,,,,,,,,
,3737889850.894,283.986557006836,100.09228515625,1.34296035408416E-5,3.34977636101742E-7,1,0.999253354069792,40.0298881530762,2.00071433204775,16.1700006574392,0.000147072777506976,1.39854695504877E-5,0.25,-1.05813196864293E-6,1.34374425222896E-5,-1.04916518307271E-6,283.994445800781,283.994445800781,100.086235046387,100.098335266113,55.2337793114482,19.6863358699274,36.9403495788574,0,0,0,40,281.309600830078,6,4,1,2.15469360351562,43.9882698059082,,,,,,,,,,,,,,,,
,3737889990.7515,280.492706298828,100.110431671143,1.41134520895456E-5,3.5418513385564E-7,1,0.999253354069792,40.0298881530762,2.00070985078882,16.1799993366003,0.000153679301615627,1.98429721031998E-5,0.25,-6.36062214427435E-7,1.41230791190797E-5,-6.26314710696098E-7,280.501708984375,280.501708984375,100.098335266113,100.122528076172,55.0891780353904,19.6843150874254,36.8696441650391,0,0,0,40,277.820220947266,6,4,1,2.15316772460938,43.9882698059082,,,,,,,,,,,,,,,,
,3737890131.6335,276.982681274414,100.074138641357,1.37167426580524E-5,3.43104594897245E-7,1,0.999253354069792,40.0298881530762,2.00073115877426,16.1799993366003,0.000149497395350751,1.86146088846228E-5,0.25,-6.80635166777097E-7,1.37278301612674E-5,-6.71134544883423E-7,276.991119384766,276.991119384766,100.062042236328,100.086235046387,55.1298227183905,19.6852606506909,36.747127532959,0,0,0,40,274.292114257813,6,4,1,2.15774536132813,44.9657897949219,,,,,,,,,,,,,,,,
,3737890271.5215,273.49446105957,100.055992126465,1.38981019413045E-5,3.74355835457619E-7,1,0.999253354069792,40.0298881530762,2.00062720649815,16.1799993366003,0.000151610539884567,1.8145733921336E-5,0.25,-7.56084429896221E-7,1.39110823245495E-5,-7.46445091400697E-7,273.509643554687,273.509643554687,100.025749206543,100.086235046387,55.0219579827366,19.6824423855837,36.6300048828125,0,0,0,40,270.81494140625,6,4,1,2.156982421875,43.9882698059082,,,,,,,,,,,,,,,,
,3737890411.4565,269.996047973633,100.086235046387,1.40627461679636E-5,3.42094289952333E-7,1,0.999253354069792,40.0298881530762,2.00064794113741,16.1799993366003,0.00015502333037153,9.25306549966678E-6,0.25,-1.60817231679376E-6,1.40782373019052E-5,-1.59920494002561E-6,270.011688232422,270.011688232422,100.062042236328,100.110427856445,55.2267446547751,19.6849638729234,36.5217895507812,0,0,0,40,267.313262939453,6,4,1,2.15652465820313,43.9882698059082,,,,,,,,,,,,,,,,
,3737890552.298,266.483764648438,100.031795501709,1.42684850401171E-5,3.29772121965169E-7,1,0.999253354069792,40.0298881530762,2.00060276695733,16.1799993366003,0.000157060910468818,1.07956217838327E-5,0.25,-1.50176392256439E-6,1.42858650705437E-5,-1.49254587702313E-6,266.500366210938,266.500366210938,100.025749206543,100.037841796875,55.0399354386789,19.684763168686,36.4527053833008,0,0,0,40,263.813415527344,6,4,1,2.15789794921875,44.4770278930664,,,,,,,,,,,,,,,,
,3737890692.243,262.991271972656,100.037841796875,1.43558717184204E-5,3.81341128316826E-7,1,0.999253354069792,40.0298881530762,2.00061937277237,16.1799993366003,0.0001574674005807,1.41496149271706E-5,0.25,-1.20710457000991E-6,1.43748804047698E-5,-1.19745480828189E-6,262.999633789062,262.999633789062,100.037841796875,100.037841796875,55.3252298481982,19.6849066746807,36.3895568847656,0,0,0,40,260.306396484375,6,4,1,2.158203125,44.9657897949219,,,,,,,,,,,,,,,,
,3737890833.176,259.478958129883,100.025745391846,1.3920182070926E-5,3.62471940242162E-7,1,0.999253354069792,40.0298881530762,2.00061005333938,16.1799993366003,0.000151945050678893,1.80655894990797E-5,0.25,-7.68845414380042E-7,1.39400045685561E-5,-7.58899906372094E-7,259.494567871094,259.494567871094,100.00154876709,100.049942016602,55.0149233260635,19.6864815576813,36.2338447570801,0,0,0,40,256.784210205078,6,4,1,2.1563720703125,44.9657897949219,,,,,,,,,,,,,,,,
,3737890973.023,255.982849121094,99.977352142334,1.46337093608453E-5,3.17368163377585E-7,1,0.999253354069792,40.0298881530762,2.0005643161639,16.1799993366003,0.00015943104981721,2.08098104330876E-5,0.25,-6.40451337350028E-7,1.46561913546232E-5,-6.2965143046509E-7,255.998657226562,255.998657226562,99.9410629272461,100.013641357422,55.0915229209481,19.6864081243288,36.1612510681152,0,0,0,40,253.301651000977,6,4,1,2.1551513671875,44.4770278930664,,,,,,,,,,,,,,,,
,3737891112.907,252.492095947266,99.9592094421387,1.47919678371444E-5,2.83522121183939E-7,1,0.999253354069792,40.0298881530762,2.00059612863934,16.1799993366003,0.000161431886050443,1.958449827515E-5,0.25,-7.81966416314854E-7,1.48165908514618E-5,-7.71147857380019E-7,252.510467529297,252.510467529297,99.9410629272461,99.9773559570312,55.0485333523904,19.6872823647836,36.0103950500488,0,0,0,40,249.792007446289,6,4,1,2.1551513671875,44.9657897949219,,,,,,,,,,,,,,,,
,3737891253.796,248.973915100098,100.001552581787,1.47463400665288E-5,3.02781603744567E-7,1,0.999253354069792,40.0298881530762,2.00057632195689,16.1799993366003,0.000161167702787314,1.8295652731408E-5,0.25,-8.93552325313084E-7,1.47727747964853E-5,-8.82854883662039E-7,248.993286132813,248.993286132813,99.9773559570312,100.025749206543,55.1087187483712,19.6880582510466,35.8846397399902,0,0,0,40,246.284408569336,6,4,1,2.15545654296875,44.9657897949219,,,,,,,,,,,,,,,,
,3737891393.684,245.480316162109,99.971305847168,1.43750848180906E-5,3.95412263105184E-7,1,0.999253354069792,40.0298881530762,2.00051217078363,16.1799993366003,0.000156127131138711,2.35234819255136E-5,0.25,-3.45449509704572E-7,1.44021411866329E-5,-3.33942108815953E-7,245.4951171875,245.4951171875,99.9652557373047,99.9773559570312,54.8093550255058,19.6884364593507,35.7810134887695,0,0,0,40,242.781692504883,6,4,1,2.15499877929687,44.9657897949219,,,,,,,,,,,,,,,,
,3737891533.566,241.98804473877,99.9713020324707,1.49638979982066E-5,3.21259559667572E-7,1,0.999253354069792,40.0298881530762,2.0004719007496,16.1799993366003,0.000163371721213077,1.97375256852895E-5,0.25,-7.99143966406534E-7,1.4994227678179E-5,-7.87858672552452E-7,242.005462646484,242.005462646484,99.9531555175781,99.9894485473633,55.2150202269866,19.6892263021376,35.6663208007812,0,0,0,40,239.305465698242,6,4,1,2.15423583984375,44.9657897949219,,,,,,,,,,,,,,,,
,3737891673.474,238.486610412598,99.9652557373047,1.52180378690172E-5,2.99630369881029E-7,1,0.999253354069792,40.0298881530762,2.00047584734152,16.1799993366003,0.000166558378560165,1.78405856891151E-5,0.25,-1.01951436483056E-6,1.5250885018903E-5,-1.00833637794411E-6,238.494873046875,238.494873046875,99.9531555175781,99.9773559570312,54.9789684141789,19.6883463683618,35.5456924438477,0,0,0,40,235.814392089844,6,4,1,2.156982421875,44.4770278930664,,,,,,,,,,,,,,,,
,3737891813.3525,234.993553161621,99.9531555175781,1.48202649797088E-5,2.85352967287329E-7,1,0.999253354069792,40.0298881530762,2.00047344311561,16.1799993366003,0.000162564030975638,1.54370722510391E-5,0.25,-1.17234260327605E-6,1.48541782911949E-5,-1.16173904237948E-6,235.001419067383,235.001419067383,99.9531555175781,99.9531555175781,55.2525383959097,19.6906265716097,35.4358558654785,0,0,0,40,232.330001831055,6,4,1,2.15621948242187,45.4545478820801,,,,,,,,,,,,,,,,
,3737891953.287,231.49299621582,99.9531593322754,1.49172348765414E-5,2.69870641138415E-7,1,0.999253354069792,40.0298881530762,2.00058946942265,16.1799993366003,0.000163467621851505,1.66155963692561E-5,0.25,-1.08092695645243E-6,1.49530548360635E-5,-1.06991818036552E-6,231.501205444336,231.501205444336,99.9410629272461,99.9652557373047,54.8859546203904,19.6897691964764,35.3047027587891,0,0,0,40,228.827667236328,6,4,1,2.156982421875,44.9657897949219,,,,,,,,,,,,,,,,
,3737892094.159,227.974449157715,99.971305847168,1.4753277324729E-5,3.17465417263427E-7,1,0.999253354069792,40.0298881530762,2.00050435225849,16.1700006574392,0.000161864241406501,1.54042225590692E-5,0.25,-1.16447936331436E-6,1.47905452310739E-5,-1.15370081243159E-6,227.99186706543,227.99186706543,99.9652557373047,99.9773559570312,54.6702251490827,19.6895536912586,35.1584358215332,0,0,0,40,225.298492431641,6,4,1,2.15621948242187,44.9657897949219,,,,,,,,,,,,,,,,
,3737892233.0385,224.497718811035,99.9410591125488,1.49558700756811E-5,3.3365410940179E-7,1,0.999253354069792,40.0298881530762,2.00047750559295,16.1799993366003,0.000163895486249504,1.68060091725914E-5,0.25,-1.07090156440336E-6,1.49952948887093E-5,-1.05956952811914E-6,224.513442993164,224.513442993164,99.9289627075195,99.9531555175781,54.8617241362943,19.6915495379343,35.0869216918945,0,0,0,40,221.854415893555,6,4,1,2.1575927734375,45.4545478820801,,,,,,,,,,,,,,,,
,3737892373.934,220.980842590332,99.9592056274414,1.47981466481246E-5,3.7179278813694E-7,1,0.999253354069792,40.0298881530762,2.00047735755918,16.1799993366003,0.000161687582965797,1.94717039487469E-5,0.25,-7.97403781024934E-7,1.48386414555715E-5,-7.85339682979804E-7,220.990646362305,220.990646362305,99.9531555175781,99.9652557373047,55.0235212397751,19.6894097113785,34.9282417297363,0,0,0,40,218.346771240234,6,4,1,2.156982421875,45.4545478820801,,,,,,,,,,,,,,,,
,3737892513.872,217.483810424805,99.9289627075195,1.4393595415042E-5,2.51668422901186E-7,1,0.999253354069792,40.0298881530762,2.00036573872213,16.1799993366003,0.000157729242372701,1.63642602889022E-5,0.25,-1.01388199305752E-6,1.44348811535541E-5,-1.00263151181726E-6,217.493026733398,217.493026733398,99.916862487793,99.9410629272461,55.2798953940828,19.6895963614904,34.831901550293,0,0,0,40,214.864593505859,6,4,1,2.15682983398438,45.4545478820801,,,,,,,,,,,,,,,,
,3737892653.7245,213.981620788574,99.9350128173828,1.4917690780509E-5,2.80975067371603E-7,1,0.999253354069792,40.0298881530762,2.00043992837764,16.1799993366003,0.000163156261855438,1.89042861443778E-5,0.25,-8.71744898291734E-7,1.496202160849E-5,-8.59388863887999E-7,213.997100830078,213.997100830078,99.9289627075195,99.9410629272461,55.2744239944482,19.6922103286645,34.7074928283691,0,0,0,40,211.374099731445,6,4,1,2.156982421875,45.4545478820801,,,,,,,,,,,,,,,,
,3737892793.612,210.483306884766,99.9471092224121,1.54515345196282E-5,2.6590843130847E-7,1,0.999253354069792,40.0298881530762,2.00045725196032,16.1799993366003,0.000169134819698985,1.89038350719573E-5,0.25,-9.6600025161583E-7,1.54992792446264E-5,-9.53177839812668E-7,210.49836730957,210.49836730957,99.9410629272461,99.9531555175781,55.1649960017558,19.694812405915,34.5763397216797,0,0,0,40,207.901885986328,6,4,1,2.15896606445313,44.9657897949219,,,,,,,,,,,,,,,,
,3737892933.52,206.987701416016,99.9289627075195,1.53939976604783E-5,2.55869257724731E-7,1,0.999253354069792,40.0298881530762,2.00038657533756,16.1799993366003,0.000168351481118092,1.9785701679505E-5,0.25,-8.74925934213239E-7,1.54432161626125E-5,-8.61655144924999E-7,207.004318237305,207.004318237305,99.916862487793,99.9410629272461,55.0008540127174,19.6922368469344,34.4627265930176,0,0,0,40,204.406097412109,6,4,1,2.15728759765625,44.9657897949219,,,,,,,,,,,,,,,,
,3737893073.4155,203.485771179199,99.9229125976563,1.48874538781328E-5,2.6502992607349E-7,1,0.999253354069792,40.0298881530762,2.00035813903389,16.1799993366003,0.00016310508946497,1.7557389182455E-5,0.25,-9.9229102243549E-7,1.49368801964877E-5,-9.79692444397977E-7,203.494338989258,203.494338989258,99.916862487793,99.9289627075195,54.853907851102,19.6920079396349,34.3499221801758,0,0,0,40,200.932495117187,6,4,1,2.15667724609375,45.4545478820801,,,,,,,,,,,,,,,,
,3737893213.2895,199.989547729492,99.9410629272461,1.50934027294929E-5,2.90790124344486E-7,1,0.999253354069792,40.0298881530762,2.00039710223392,16.1799993366003,0.000165221736023323,1.87202100347422E-5,0.25,-9.216430708171E-7,1.51451015501761E-5,-9.08344273687018E-7,200.000213623047,200.000213623047,99.9410629272461,99.9410629272461,54.932070703025,19.6928361058614,34.2249755859375,0,0,0,40,197.442138671875,6,4,1,2.15652465820313,45.4545478820801,,,,,,,,,,,,,,,,
,3737893353.1765,196.486030578613,99.9592094421387,1.49132439613388E-5,2.87841630115736E-7,1,0.999253354069792,40.0298881530762,2.00041158872111,16.1799993366003,0.000163111164225134,1.9395955862169E-5,0.25,-8.28191084714943E-7,1.49658798601306E-5,-8.14498083032696E-7,196.493515014648,196.493515014648,99.9410629272461,99.9773559570312,54.8116999110635,19.6946640515588,34.0266265869141,0,0,0,40,193.971633911133,6,4,1,2.1588134765625,44.9657897949219,,,,,,,,,,,,,,,,
,3737893493.1115,192.993148803711,99.9229125976563,1.4539290399171E-5,2.37741486663905E-7,1,0.999253354069792,40.0298881530762,2.00031687371562,16.1799993366003,0.000159344217168866,1.71284936982666E-5,0.25,-9.723309151231E-7,1.45923748856587E-5,-9.5928408575113E-7,193.010635375977,193.010635375977,99.916862487793,99.9289627075195,54.9180013896789,19.6960921168275,33.8506736755371,0,0,0,40,190.466613769531,6,4,1,2.15896606445313,45.4545478820801,,,,,,,,,,,,,,,,
,3737893632.989,189.49503326416,99.9471092224121,1.46941662567959E-5,3.08558124058872E-7,1,0.999253354069792,40.0298881530762,2.00034167192693,16.1799993366003,0.00016043080890845,2.08995632276905E-5,0.25,-6.52024954780804E-7,1.47490185571276E-5,-6.37329133327229E-7,189.511383056641,189.511383056641,99.9410629272461,99.9531555175781,54.9008055622558,19.6959285165195,33.7241096496582,0,0,0,40,186.992538452148,6,4,1,2.15911865234375,44.9657897949219,,,,,,,,,,,,,,,,
,3737893773.8845,185.979347229004,99.9350090026855,1.46753179373549E-5,2.95904404222091E-7,1,0.999253354069792,40.0298881530762,2.0002315213075,16.1799993366003,0.000160854102182459,1.7342428889225E-5,0.25,-9.77563659425417E-7,1.47320538913423E-5,-9.63771675649249E-7,185.985229492187,185.985229492187,99.916862487793,99.9531555175781,55.0078886693904,19.6943686618482,33.5689353942871,0,0,0,40,183.479736328125,6,4,1,2.15499877929687,45.4545478820801,,,,,,,,,,,,,,,,
,3737893913.7715,182.480072021484,99.9350128173828,1.47784860367666E-5,2.92706953831013E-7,1,0.999253354069792,40.0298881530762,2.00021618213778,16.1799993366003,0.000161954274974538,1.77305539989136E-5,0.25,-9.60466182398294E-7,1.48371498478211E-5,-9.46142583856972E-7,182.487030029297,182.487030029297,99.9289627075195,99.9410629272461,54.8124815395827,19.6985717819074,33.4078254699707,0,0,0,40,180.004486083984,6,4,1,2.15957641601562,45.4545478820801,,,,,,,,,,,,,,,,
,3737894053.6585,178.985618591309,99.9289627075195,1.46387409044837E-5,2.43440300740052E-7,1,0.999253354069792,40.0298881530762,2.00022225996087,16.1799993366003,0.000160153017759167,1.91970813946981E-5,0.25,-8.01208297335029E-7,1.46981819408121E-5,-7.86054646237658E-7,179.00129699707,179.00129699707,99.9289627075195,99.9289627075195,55.1110636339289,19.7019551073577,33.2731666564941,0,0,0,40,176.508636474609,6,4,1,2.15576171875,44.9657897949219,,,,,,,,,,,,,,,,
,3737894193.556,175.482536315918,99.9410591125488,1.46335933792489E-5,2.24681162679783E-7,1,0.999253354069792,40.0298881530762,2.000207682398,16.1799993366003,0.000160050784248687,1.95398690624827E-5,0.25,-7.69328906225972E-7,1.46944695398186E-5,-7.53641258353779E-7,175.490142822266,175.490142822266,99.9289627075195,99.9531555175781,55.0227396112558,19.7003128709524,33.1449813842773,0,0,0,40,173.025482177734,6,4,1,2.15866088867187,44.9657897949219,,,,,,,,,,,,,,,,
,3737894333.446,171.983131408691,99.9289627075195,1.46879006175639E-5,3.06460858815968E-7,1,0.999253354069792,40.0298881530762,2.00011914454263,16.1799993366003,0.000160628036085043,1.97616557402666E-5,0.25,-7.59033877294263E-7,1.47504615309423E-5,-7.42788171017086E-7,171.99853515625,171.99853515625,99.9289627075195,99.9289627075195,55.189226485852,19.7017995479006,33.0032997131348,0,0,0,40,169.54997253418,6,4,1,2.15484619140625,45.4545478820801,,,,,,,,,,,,,,,,
,3737894473.3795,168.491333007813,99.9652557373047,1.46250190616135E-5,2.76550018853487E-7,1,0.999253354069792,40.0298881530762,2.00012065403809,16.1799993366003,0.000160410081406077,1.70979801744606E-5,0.25,-9.94463061744494E-7,1.46890784357126E-5,-9.78834222369342E-7,168.498901367187,168.498901367187,99.9410629272461,99.9894485473633,55.0211763542174,19.7032168245333,32.8675575256348,0,0,0,40,166.049026489258,6,4,1,2.15774536132813,44.9657897949219,,,,,,,,,,,,,,,,
,3737894613.249,164.99031829834,99.9652557373047,1.45433717977002E-5,3.10342766786115E-7,1,0.999253354069792,40.0298881530762,2.00016570033172,16.1799993366003,0.000159818987418043,1.53815456420885E-5,0.25,-1.13921784752045E-6,1.46087048534666E-5,-1.12384705549402E-6,164.998962402344,164.998962402344,99.9531555175781,99.9773559570312,55.026647753852,19.7017354920077,32.6767654418945,0,0,0,40,162.583023071289,6,4,1,2.15805053710938,45.4545478820801,,,,,,,,,,,,,,,,
,3737894753.1815,161.495735168457,99.9289627075195,1.46880927131532E-5,2.97943213031284E-7,1,0.999253354069792,40.0298881530762,2.00021953191808,16.1799993366003,0.000160284408570026,2.20414378528722E-5,0.25,-5.5114420619806E-7,1.47546226283827E-5,-5.32420034104955E-7,161.502777099609,161.502777099609,99.916862487793,99.9410629272461,54.8374936521981,19.6992247411671,32.4983863830566,0,0,0,40,159.100982666016,6,4,1,2.15957641601562,45.4545478820801,,,,,,,,,,,,,,,,
,3737894893.107,157.992958068848,99.9410591125488,1.4472605120814E-5,2.86318978796768E-7,1,0.999253354069792,40.0298881530762,2.00014499100012,16.1799993366003,0.000158504351913626,1.85231390248783E-5,0.25,-8.38521311965818E-7,1.45399375860502E-5,-8.20812244969124E-7,157.999237060547,157.999237060547,99.9289627075195,99.9531555175781,54.6811679483519,19.7000382196035,32.3046226501465,0,0,0,40,155.620010375977,6,4,1,2.15774536132813,44.9657897949219,,,,,,,,,,,,,,,,
,3737895032.9585,154.498443603516,99.9592056274414,1.43470308022974E-5,3.19993406863424E-7,1,0.999253354069792,40.0298881530762,2.00014627130853,16.1799993366003,0.000157236729565451,1.78339959937665E-5,0.25,-8.80830213843945E-7,1.44151618562036E-5,-8.62883378572474E-7,154.515518188477,154.515518188477,99.9531555175781,99.9652557373047,54.667880263525,19.7040403821076,32.0968284606934,0,0,0,40,152.125122070313,6,4,1,2.15896606445313,45.4545478820801,,,,,,,,,,,,,,,,
,3737895172.82,150.995079040527,99.9350128173828,1.45597003283969E-5,1.91482216009621E-7,1,0.999253354069792,40.0298881530762,2.00010091896636,16.1799993366003,0.000159783294990663,1.69350197584169E-5,0.25,-1.00204398759664E-6,1.46303114452801E-5,-9.83662817353486E-7,151.002212524414,151.002212524414,99.9289627075195,99.9410629272461,55.0235212397751,19.7026611776532,31.8957786560059,0,0,0,40,148.665222167969,6,4,1,2.16156005859375,44.9657897949219,,,,,,,,,,,,,,,,
,3737895312.783,147.491340637207,99.8987159729004,1.43095947670645E-5,2.02241258570077E-7,1,0.999253354069792,40.0298881530762,2.00012064744087,16.1799993366003,0.000157253585293937,1.55106935607753E-5,0.25,-1.09029783380624E-6,1.4380412958638E-5,-1.07202371881946E-6,147.497329711914,147.497329711914,99.8805694580078,99.916862487793,55.1720306584289,19.7037936273876,31.6850147247314,0,0,0,40,145.210037231445,6,4,1,2.15591430664062,45.4545478820801,,,,,,,,,,,,,,,,
,3737895452.608,143.990615844727,99.9350128173828,1.47014679692696E-5,2.24671458107328E-7,1,0.999253354069792,40.0298881530762,2.00008963576269,16.1799993366003,0.000161324054068309,1.73396866456906E-5,0.25,-9.916515746733E-7,1.4775253633694E-5,-9.71454246174024E-7,144.008117675781,144.008117675781,99.9289627075195,99.9410629272461,54.9813132997366,19.7056479637693,31.4863948822022,0,0,0,40,141.735198974609,6,4,1,2.1600341796875,44.9657897949219,,,,,,,,,,,,,,,,
,3737895592.5105,140.490684509277,99.8866195678711,1.40192497330146E-5,2.3946851143923E-7,1,0.999253354069792,40.0298881530762,2.00002327170419,16.1799993366003,0.000153418630303673,1.89572565707694E-5,0.25,-7.23261656419548E-7,1.40903590998383E-5,-7.02060114451207E-7,140.499404907227,140.499404907227,99.8684692382813,99.9047698974609,54.6022234679096,19.7070344448462,31.2864246368408,0,0,0,40,138.273941040039,6,4,1,2.16201782226562,44.9657897949219,,,,,,,,,,,,,,,,
,3737895732.44,136.983207702637,99.9410629272461,1.41406742837543E-5,2.42109607421614E-7,1,0.999253354069792,40.0298881530762,1.99993878339175,16.1799993366003,0.00015466534683758,1.96199697728413E-5,0.25,-6.84609238129046E-7,1.42134099014221E-5,-6.62060852034342E-7,136.990875244141,136.990875244141,99.9410629272461,99.9410629272461,54.6663170064866,19.7076094127584,31.0394992828369,0,0,0,40,134.800521850586,6,4,1,2.16110229492187,44.9657897949219,,,,,,,,,,,,,,,,
,3737895872.284,133.48087310791,99.9047698974609,1.45702770309297E-5,2.88830813040663E-7,1,0.999253354069792,40.0298881530762,1.99999327734419,16.1799993366003,0.000160629933210255,1.31331941480748E-5,0.25,-1.35973265139042E-6,1.46475442507218E-5,-1.33879875847782E-6,133.496337890625,133.496337890625,99.9047698974609,99.9047698974609,55.1141901480058,19.7066711287422,30.770715713501,0,0,0,40,131.338806152344,6,4,1,2.15896606445313,45.4545478820801,,,,,,,,,,,,,,,,
,3737896012.1745,129.979690551758,99.8926696777344,1.45599727718129E-5,2.84422723757146E-7,1,0.999253354069792,40.0298881530762,2.00001065476937,16.1799993366003,0.000159636556708616,1.81828913025936E-5,0.25,-8.93652843561896E-7,1.46373197782774E-5,-8.69213559054761E-7,129.995468139648,129.995468139648,99.8805694580078,99.9047698974609,54.8343671381212,19.7059341776522,30.5089473724365,0,0,0,40,127.861991882324,6,4,1,2.15850830078125,44.9657897949219,,,,,,,,,,,,,,,,
,3737896152.187,126.477096557617,99.9229125976563,1.42270368147748E-5,2.36513802639896E-7,1,0.999253354069792,40.0298881530762,2.00003426145562,16.1799993366003,0.000156486880280523,1.5001697194735E-5,0.25,-1.1295550990463E-6,1.43040898674804E-5,-1.10580265244556E-6,126.493759155273,126.493759155273,99.916862487793,99.9289627075195,54.5436013289673,19.7071538367355,30.2269382476807,0,0,0,40,124.406631469727,6,4,1,2.16079711914062,45.4545478820801,,,,,,,,,,,,,,,,
,3737896290.967,122.996562957764,99.9047698974609,1.42402015608769E-5,2.45016880884133E-7,1,0.999253354069792,40.0298881530762,2.00005072261346,16.1799993366003,0.000156021675793947,1.85310064031068E-5,0.25,-8.08002595769606E-7,1.43175117580164E-5,-7.81200965211446E-7,123.005386352539,123.005386352539,99.9047698974609,99.9047698974609,54.952393044525,19.7062322270537,29.9328022003174,0,0,0,40,120.97989654541,6,4,1,2.15728759765625,45.9433059692383,,,,,,,,,,,,,,,,
,3737896430.9105,119.491012573242,99.9047698974609,1.44943833006191E-5,3.12215020699836E-7,1,0.999253354069792,40.0298881530762,2.00019951030608,16.1799993366003,0.000158963166506314,1.80916069873294E-5,0.25,-8.95174123018731E-7,1.45740387958652E-5,-8.66780355534658E-7,119.507972717285,119.507972717285,99.9047698974609,99.9047698974609,55.0712005794481,19.7057666289772,29.6228065490723,0,0,0,40,117.499954223633,6,4,1,2.16064453125,44.9657897949219,,,,,,,,,,,,,,,,
,3737896570.7585,115.987796783447,99.8987197875977,1.44444251228294E-5,3.1212835891276E-7,1,0.999253354069792,40.0298881530762,2.00011027303892,16.1799993366003,0.000158454771777269,1.78121378302447E-5,0.25,-9.13793796166601E-7,1.4524568456133E-5,-8.83967642658006E-7,116.006530761719,116.006530761719,99.8926696777344,99.9047698974609,55.0125784405058,19.7061743873447,29.2798233032227,0,0,0,40,114.055328369141,6,4,1,2.15927124023438,45.4545478820801,,,,,,,,,,,,,,,,
,3737896710.6405,112.483245849609,99.9168663024902,1.43952774625774E-5,2.66260368492755E-7,1,0.999253354069792,40.0298881530762,2.00012555031337,16.1799993366003,0.000157841167419284,1.82168374067469E-5,0.25,-8.69716728019121E-7,1.4475647436457E-5,-8.3795468268276E-7,112.491470336914,112.491470336914,99.9047698974609,99.9289627075195,54.9609909582366,19.7068392270614,28.9159183502197,0,0,0,40,110.588188171387,6,4,1,2.1575927734375,44.4770278930664,,,,,,,,,,,,,,,,
,3737896849.5505,108.995594024658,99.977352142334,1.43452679169933E-5,2.4255977592825E-7,1,0.999253354069792,40.0298881530762,2.00009242170882,16.1799993366003,0.000157415006613764,1.74795175893495E-5,0.25,-9.3086664012679E-7,1.44259982344225E-5,-8.9756980166641E-7,109.003913879395,109.003913879395,99.9652557373047,99.9894485473633,54.871103678525,19.7068835210517,28.5148811340332,0,0,0,40,107.165077209473,6,4,1,2.15896606445313,44.4770278930664,,,,,,,,,,,,,,,,
,3737896989.486,105.493465423584,99.9954986572266,1.41449568952558E-5,2.33196230082628E-7,1,0.999253354069792,40.0298881530762,2.00015122633043,16.1799993366003,0.000155312988657667,1.67396883269125E-5,0.25,-9.65847796802598E-7,1.42250222612704E-5,-9.31086030511463E-7,105.500762939453,105.500762939453,99.9894485473633,100.00154876709,54.6287988375635,19.707809057957,28.0772266387939,0,0,0,40,103.708213806152,6,4,1,2.1624755859375,44.4770278930664,,,,,,,,,,,,,,,,
,3737897129.353,101.983367919922,100.019695281982,1.42410884930602E-5,2.63716565284608E-7,1,0.999253354069792,40.0298881530762,2.00014558054945,16.1799993366003,0.000156934579605377,1.36733699152052E-5,0.25,-1.26802656736575E-6,1.43227471193341E-5,-1.23218153194467E-6,102.00106048584,102.00106048584,99.9894485473633,100.049942016602,54.8992423052174,19.7064360189014,27.6593799591064,0,0,0,40,100.261871337891,6,4,1,2.16217041015625,44.4770278930664,,,,,,,,,,,,,,,,
,3737897268.2465,98.4930648803711,100.049942016602,1.41170433232368E-5,2.4131317889047E-7,1,0.999253354069792,40.0298881530762,2.00014366360152,16.1799993366003,0.000155135654806951,1.59846700698751E-5,0.25,-1.03563527799027E-6,1.41972892715936E-5,-9.96183604500034E-7,98.5018692016602,98.5018692016602,100.037841796875,100.062042236328,54.9828765567751,19.7079029828306,27.2119846343994,0,0,0,40,96.8491668701172,6,4,1,2.15805053710938,45.4545478820801,,,,,,,,,,,,,,,,
,3737897408.1815,94.9849853515625,100.074138641357,1.43825018652985E-5,2.26411478976402E-7,1,0.999253354069792,40.0298881530762,2.00007778904271,16.1799993366003,0.000157634686544845,1.85887473017936E-5,0.25,-8.4572558342183E-7,1.44632462655191E-5,-8.0129962146334E-7,94.9951400756836,94.9951400756836,100.062042236328,100.086235046387,54.9742786430635,19.7094803811644,26.7567005157471,0,0,0,40,93.3961715698242,6,4,1,2.1600341796875,43.9882698059082,,,,,,,,,,,,,,,,
,3737897547.0245,91.4984245300293,100.086235046387,1.41966695008309E-5,2.46841712095953E-7,1,0.999253354069792,40.0298881530762,2.00000897515092,16.1799993366003,0.000155542564107642,1.85899385293145E-5,0.25,-8.15747285626208E-7,1.42756456461072E-5,-7.68403159796344E-7,91.5138473510742,91.5138473510742,100.086235046387,100.086235046387,54.6420865223904,19.7076835634985,26.3180618286133,0,0,0,40,89.981689453125,6,4,1,2.16110229492187,43.49951171875,,,,,,,,,,,,,,,,
,3737897686.929,87.9825897216797,100.134624481201,1.43382636270082E-5,2.45664617710908E-7,1,0.999253354069792,40.0298881530762,1.99989636782182,16.1799993366003,0.000157019206690095,1.907937380666E-5,0.25,-7.99407963190693E-7,1.44168517035828E-5,-7.47602065043622E-7,87.9981536865234,87.9981536865234,100.122528076172,100.14672088623,54.9258176748712,19.7061310528467,25.902961730957,0,0,0,40,86.5333862304687,6,4,1,2.1563720703125,43.49951171875,,,,,,,,,,,,,,,,
,3737897825.839,84.4982528686523,100.176971435547,1.40770446438464E-5,2.59366109062032E-7,1,0.999253354069792,40.0298881530762,1.99982856534806,16.1700006574392,0.000154080150988906,1.90463254611954E-5,0.25,-7.5967995993315E-7,1.41525393755535E-5,-7.04493698651849E-7,84.515998840332,84.515998840332,100.170921325684,100.18302154541,55.1399838891405,19.7085065403989,25.4258594512939,0,0,0,40,83.1205062866211,6,4,1,2.14996337890625,44.4770278930664,,,,,,,,,,,,,,,,
,3737897965.738,80.9897270202637,100.128574371338,1.39699161976326E-5,2.48697547894802E-7,1,0.999253354069792,40.0298881530762,1.99990148238199,16.1799993366003,0.00015278307954118,1.9491863638302E-5,0.25,-7.03745425042192E-7,1.4042418475925E-5,-6.4406512484484E-7,81.0089492797852,81.0089492797852,100.110427856445,100.14672088623,54.7741817421404,19.7074516686746,24.8901329040527,0,0,0,40,79.6709823608398,6,4,1,2.15789794921875,43.9882698059082,,,,,,,,,,,,,,,,
,3737898105.6045,77.4808654785156,100.116477966309,1.4467069451353E-5,2.45536830123055E-7,1,0.999253354069792,40.0298881530762,1.9997987850927,16.1799993366003,0.000158553204978164,1.80947547997168E-5,0.25,-9.26438908298868E-7,1.45400027079724E-5,-8.60231400318149E-7,77.4892425537109,77.4892425537109,100.110427856445,100.122528076172,54.874230192602,19.7083224081013,24.3823680877686,0,0,0,40,76.2273025512695,6,4,1,2.15774536132813,38.1231689453125,,,,,,,,,,,,,,,,
,3737898244.4865,73.9879875183105,100.068088531494,1.41478635609724E-5,2.44174147462375E-7,1,0.999253354069792,40.0298881530762,1.99979348200481,16.1799993366003,0.000155366621008778,1.57162738048386E-5,0.25,-1.09376844063256E-6,1.42162091170346E-5,-1.02410519759857E-6,73.9947280883789,73.9947280883789,100.062042236328,100.07413482666,54.9039320763327,19.7075133803498,23.8490352630615,0,0,0,40,72.8313751220703,6,4,1,2.15652465820313,44.4770278930664,,,,,,,,,,,,,,,,
,3737898384.3945,70.4782981872559,100.080184936523,1.41338106504722E-5,2.4264004653556E-7,1,0.999253354069792,40.0298881530762,1.99977438349384,16.1799993366003,0.000154511761386195,1.92615207925088E-5,0.25,-7.6912108762798E-7,1.41950878950909E-5,-6.91933238183185E-7,70.493782043457,70.493782043457,100.07413482666,100.086235046387,55.0235212397751,19.7086798750735,23.2702903747559,0,0,0,40,69.3837432861328,6,4,1,2.16094970703125,43.9882698059082,,,,,,,,,,,,,,,,
,3737898523.289,66.9809417724609,100.049942016602,1.39461010596463E-5,2.42745979026453E-7,1,0.999253354069792,40.0298881530762,1.99980117740194,16.1700006574392,0.000153663032249676,1.194751660243E-5,0.25,-1.41642812897909E-6,1.40038608869127E-5,-1.33624115581648E-6,66.9884414672852,66.9884414672852,100.037841796875,100.062042236328,55.0985575776212,19.7068122154669,22.6518115997314,0,0,0,40,65.9792785644531,6,4,1,2.15286254882813,44.4770278930664,,,,,,,,,,,,,,,,
,3737898663.1955,63.4895076751709,100.043891906738,1.38058245537341E-5,2.26712929677056E-7,1,0.999253354069792,40.0298881530762,1.99977903495391,16.1799993366003,0.000151840519383888,1.28506117027192E-5,0.25,-1.31278813991191E-6,1.38543041792249E-5,-1.22646377835095E-6,63.4967803955078,63.4967803955078,100.037841796875,100.049942016602,54.8351487666404,19.7074820627733,21.9982032775879,0,0,0,40,62.4979667663574,6,4,1,2.15896606445313,44.4770278930664,,,,,,,,,,,,,,,,
,3737898802.101,59.9932250976563,99.9713020324707,1.4410372853971E-5,2.79646870984434E-7,1,0.999253354069792,40.0298881530762,1.9998076559724,16.1799993366003,0.000156566876677454,2.33686821522956E-5,0.25,-4.5350659295063E-7,1.44440744870255E-5,-3.54870736996255E-7,60.0088500976563,60.0088500976563,99.9531555175781,99.9894485473633,54.9977274986404,19.7078975951547,21.3480262756348,0,0,0,40,59.0930824279785,6,4,1,2.15972900390625,44.4770278930664,,,,,,,,,,,,,,,,
,3737898941.9605,56.4767894744873,99.9652557373047,1.41755855733687E-5,2.38987826982213E-7,1,0.999253354069792,40.0298881530762,1.99978072450341,16.1799993366003,0.00015489390948518,1.73692153041319E-5,0.25,-9.69242185050831E-7,1.41997212697773E-5,-8.68072124889432E-7,56.4927864074707,56.4927864074707,99.9531555175781,99.9773559570312,54.789814312525,19.7041125126601,20.6493549346924,0,0,0,40,55.6581497192383,6,4,1,2.16171264648438,44.4770278930664,,,,,,,,,,,,,,,,
,3737899079.87,52.9919261932373,99.9531555175781,1.37747393481388E-5,2.39134277414059E-7,1,0.999253354069792,40.0298881530762,1.99976886608588,16.1799993366003,0.000150340901269265,1.6977820266414E-5,0.25,-9.33648656595457E-7,1.37842764593413E-5,-8.31845957601686E-7,53.01123046875,53.01123046875,99.9531555175781,99.9531555175781,54.9367604741404,19.7089070201916,19.9078025817871,0,0,0,40,52.2510108947754,6,4,1,2.15988159179687,45.9433059692383,,,,,,,,,,,,,,,,
,3737899218.787,49.4876918792725,99.9834022521973,1.41651495906945E-5,2.23037738259896E-7,1,0.999253354069792,40.0298881530762,1.99972407110881,16.1799993366003,0.000154163237365868,1.89061344925461E-5,0.25,-8.24427917492761E-7,1.41585139688205E-5,-7.18437679302048E-7,49.4980087280273,49.4980087280273,99.9773559570312,99.9894485473633,54.8023203688327,19.7091019383281,19.1585845947266,0,0,0,40,48.8320693969727,6,4,1,2.159423828125,44.9657897949219,,,,,,,,,,,,,,,,
,3737899356.634,45.9950351715088,99.9592094421387,1.4183631345008E-5,2.29073538052285E-7,1,0.999253354069792,40.0298881530762,1.99974289469246,16.1799993366003,0.000154525056932526,1.71041944912203E-5,0.25,-9.91425930405241E-7,1.41626532522206E-5,-8.86131153044883E-7,46.0106468200684,46.0106468200684,99.9410629272461,99.9773559570312,55.0766719790828,19.7084806233301,18.3691463470459,0,0,0,40,45.4344139099121,6,4,1,2.158203125,44.9657897949219,,,,,,,,,,,,,,,,
,3737899495.576,42.4911804199219,99.9531593322754,1.39434375636593E-5,2.34787638394504E-7,1,0.999253354069792,40.0298881530762,1.99963597108822,16.1799993366003,0.000152208463161809,1.42307571216334E-5,0.25,-1.20924023716756E-6,1.39099840290535E-5,-1.10821551827548E-6,42.5078392028809,42.5078392028809,99.9289627075195,99.9773559570312,55.016486583102,19.7111908792941,17.545690536499,0,0,0,40,41.9864921569824,6,4,1,2.15194702148438,44.9657897949219,,,,,,,,,,,,,,,,
,3737899634.4445,38.9838943481445,99.9471092224121,1.38813118433633E-5,2.38655117975901E-7,1,0.999253354069792,40.0298881530762,1.99963094245513,16.1799993366003,0.000150374620519569,1.97555431571761E-5,0.25,-6.76592061475348E-7,1.38317895010449E-5,-5.82653387307268E-7,39.0008926391602,39.0008926391602,99.9289627075195,99.9652557373047,54.9344155885827,19.7130875173989,16.6884613037109,0,0,0,40,38.5597305297852,6,4,1,2.1563720703125,44.9657897949219,,,,,,,,,,,,,,,,
,3737899773.357,35.4871158599854,99.9289627075195,1.35523067047838E-5,2.56068226342004E-7,1,0.999253354069792,40.0298881530762,1.99971756761748,16.1700006574392,0.000147076573864215,1.72348024961477E-5,0.25,-8.44499295124688E-7,1.34951239085017E-5,-7.57549999777123E-7,35.503662109375,35.503662109375,99.916862487793,99.9410629272461,54.8797015922366,19.7130072924209,15.7902269363403,0,0,0,40,35.1334381103516,6,4,1,2.15347290039062,44.4770278930664,,,,,,,,,,,,,,,,
,3737899912.233,31.9883632659912,99.9350128173828,1.3552511094955E-5,2.66843360390381E-7,1,0.999253354069792,40.0298881530762,1.99975771991424,16.1700006574392,0.000147529212111265,1.42769438103982E-5,0.25,-1.1135480008352E-6,1.34891652187472E-5,-1.03059425024155E-6,32.0053787231445,32.0053787231445,99.9289627075195,99.9410629272461,55.5237634920828,19.7111347734745,14.8476428985596,0,0,0,40,31.688533782959,6,4,1,2.16323852539062,45.4545478820801,,,,,,,,,,,,,,,,
,3737900051.1235,28.4857444763184,99.8987197875977,1.39320000861915E-5,2.66847200897666E-7,1,0.999253354069792,40.0298881530762,1.99971395224492,16.1799993366003,0.000151527200240817,1.50404464025457E-5,0.25,-1.10507365016828E-6,1.38609128887404E-5,-1.02468179139331E-6,28.5013980865479,28.5013980865479,99.8926696777344,99.9047698974609,54.7968489691981,19.7090116937498,13.8632335662842,0,0,0,40,28.2436351776123,6,4,1,2.15850830078125,44.9657897949219,,,,,,,,,,,,,,,,
,3737900190.092,24.9921073913574,99.9229125976563,1.39533950849301E-5,2.63930972988051E-7,1,0.999253354069792,40.0298881530762,1.99970951508865,16.1700006574392,0.000151651068212442,1.54337321607037E-5,0.25,-1.06801883122047E-6,1.38782497436106E-5,-9.91263739822754E-7,24.9997940063477,24.9997940063477,99.916862487793,99.9289627075195,54.860942507775,19.7069855839764,12.8117570877075,0,0,0,40,24.7920799255371,6,4,1,2.16018676757813,44.9657897949219,,,,,,,,,,,,,,,,
,3737900329.9675,21.4801120758057,99.9652557373047,1.38653360664299E-5,2.19292161727579E-7,1,0.999253354069792,40.0298881530762,1.999657142981,16.1700006574392,0.000150676893164474,1.52809018216763E-5,0.25,-1.0638153383862E-6,1.37885997756087E-5,-9.89748145047753E-7,21.488842010498,21.488842010498,99.9531555175781,99.9773559570312,55.0180498401404,19.7060881410759,11.6984586715698,0,0,0,40,21.322416305542,6,4,1,2.16033935546875,45.4545478820801,,,,,,,,,,,,,,,,
,3737900468.8225,17.9904899597168,99.9350128173828,1.42140109816686E-5,2.65963058164507E-7,1,0.999253354069792,40.0298881530762,1.99957063544345,16.1799993366003,0.000154635360283489,1.46413439033142E-5,0.25,-1.18498571971651E-6,1.41350932590875E-5,-1.10940297743709E-6,18.0089817047119,18.0089817047119,99.9289627075195,99.9410629272461,55.0141416975443,19.7083148399146,10.4784364700317,0,0,0,40,17.8766117095947,6,4,1,2.15225219726562,45.4545478820801,,,,,,,,,,,,,,,,
,3737900608.702,14.4821019172668,99.9471092224121,1.38202170929622E-5,2.55238527959876E-7,1,0.999253354069792,40.0298881530762,1.99956476486633,16.1799993366003,0.000149960688699799,1.64192049528328E-5,0.25,-9.48470422445909E-7,1.37426597061054E-5,-8.76194581526498E-7,14.4991149902344,14.4991149902344,99.9410629272461,99.9531555175781,55.1649960017558,19.7068221567519,9.1345272064209,0,0,0,40,14.3991041183472,6,4,1,2.1600341796875,44.9657897949219,,,,,,,,,,,,,,,,
,3737900747.636,10.9980621337891,99.9531555175781,1.33030773447385E-5,2.12675175299054E-7,1,0.999253354069792,40.0298881530762,1.99961979897145,16.1700006574392,0.000144421044252304,1.54327721321841E-5,0.25,-9.47737454161219E-7,1.32286908683755E-5,-8.77966261818808E-7,11.0145149230957,11.0145149230957,99.9531555175781,99.9531555175781,54.9344155885827,19.7078211075627,7.71475744247437,0,0,0,40,10.9282464981079,6,4,1,2.15560913085938,44.9657897949219,,,,,,,,,,,,,,,,
,3737900888.52,7.4990975856781,99.9652557373047,1.3820962036844E-5,2.24091489045476E-7,1,0.999253354069792,40.0298881530762,1.99948897023706,16.1799993366003,0.000149238061710704,2.04714203908903E-5,0.25,-5.70511316877586E-7,1.3741746956815E-5,-5.00484173076603E-7,7.50852727890015,7.50852727890015,99.9531555175781,99.9773559570312,54.9039320763327,19.7053069090641,6.54330015182495,0,0,0,40,7.45258140563965,6,4,1,2.16262817382813,44.9657897949219,,,,,,,,,,,,,,,,
,3737901062.4105,4.99989485740662,99.977352142334,1.36958299325387E-5,2.33175482009677E-7,1,0.999253354069792,40.0298881530762,1.9992067036137,16.1799993366003,0.000148474382744497,1.69004913556983E-5,0.25,-8.80999089006605E-7,1.36188739643297E-5,-8.09735131847921E-7,4.99984693527222,4.99984693527222,99.9531555175781,100.00154876709,54.9156565041212,19.7085980098062,4.70618391036987,0,0,0,40,5.00572109222412,1,4,1,2.16094970703125,44.9657897949219,,,,,,,,,,,,,,,,