File: data/doubleLayers/dl_2-5/ppms/DD205_5/DD205_5_HYST_100OE_5K.DAT
[Header]
; VSM Data File (default extension .dat)
; Copyright (c) 2003-2013, Quantum Design, Inc. All rights reserved.
TITLE,
FILEOPENTIME,3737900971.94738,06/11/2018,5:51 pm
BYAPP,VSM,1.0,1.0
INFO,DYNACOOL VSM Option Release 1.4.10 Build 1,APPNAME
INFO,Quantum Design Linear Motor Servo Controller,MOTOR_MODULE_NAME
INFO,3101-100 J0,MOTOR_HW_VERSION
INFO,MMC654,MOTOR_SERIAL_NUMBER
INFO,SRV No X-over 01.03.11,MOTOR_SOFTWARE_VERSION
INFO,Quantum Design VSM Detection Module,VSM_MODULE_NAME
INFO,3101-150 F0,VSM_HW_VERSION
INFO,VSM507,VSM_SERIAL_NUMBER
INFO,VSM No X-over 01.02.05 May 20 2008 13:51:47,VSM_SOFTWARE_VERSION
INFO,494,PREAMP_SERIAL_NUMBER
INFO,Quantum Design VSM Oven,OVEN_MODULE_NAME
INFO,3101-201 A1,OVEN_HW_VERSION
INFO,OVB210,OVEN_SERIAL_NUMBER
INFO,01.06.24,OVEN_SOFTWARE_VERSION
INFO,593,COIL_SERIAL_NUMBER
INFO,0,MOMENT_UNITS
INFO,CoFe2O4,SAMPLE_MATERIAL
INFO,,SAMPLE_COMMENT
INFO,,SAMPLE_MASS
INFO,,SAMPLE_VOLUME
INFO,,SAMPLE_MOLECULAR_WEIGHT
INFO,,SAMPLE_SIZE
INFO,,SAMPLE_SHAPE
DATATYPE,COMMENT,1
DATATYPE,TIME,2
STARTUPAXIS,X,2
STARTUPAXIS,Y1,5
[Data]
Comment,Time Stamp (sec),Temperature (K),Magnetic Field (Oe),Moment (emu),M. Std. Err. (emu),Transport Action,Averaging Time (sec),Frequency (Hz),Peak Amplitude (mm),Center Position (mm),Coil Signal' (mV),Coil Signal" (mV),Range (mV),M. Quad. Signal (emu),M. Raw' (emu),M. Raw" (emu),Min. Temperature (K),Max. Temperature (K),Min. Field (Oe),Max. Field (Oe),Mass (grams),Motor Lag (deg),Pressure (Torr),VSM Status (code),Motor Status (code),Measure Status (code),Measure Count,System Temp. (K),Temp. Status (code),Field Status (code),Chamber Status (code),Motor Current (amps),Motor Heatsink Temp. (C),Map 01,Map 02,Map 03,Map 04,Map 05,Map 06,Map 07,Map 08,Map 09,Map 10,Map 11,Map 12,Map 13,Map 14,Map 15,Map 16
,3737901074.353,5.0016918182373,-0.0604896862059832,1.42240793051573E-5,2.338673715429E-7,1,0.999253354069792,40.0298881530762,1.99931281866118,16.1700006574392,0.000154256359910559,1.72860431176361E-5,0.25,-9.39862901535065E-7,1.41442371738708E-5,-8.65741836613364E-7,5.00259113311768,5.00259113311768,-0.0725876241922378,-0.0483917482197285,55.1860999717751,19.7042518225964,4.6942663192749,0,0,0,40,5.00476980209351,1,4,1,2.15682983398438,44.9657897949219,,,,,,,,,,,,,,,,
,3737901165.275,4.99995946884155,4134.44213867188,-2.06713882808931E-6,2.5636512455549E-7,1,0.999253354069792,40.0298881530762,1.99950085116732,16.1799993366003,-2.05624519618725E-5,-1.28760860225364E-5,0.25,-8.29565526763099E-7,-2.05112820299515E-6,-8.35298205866578E-7,4.99986600875854,4.99986600875854,4109.41796875,4159.46630859375,54.6835128339096,19.7025797854171,4.6443977355957,0,0,0,40,5.00579357147217,1,6,1,2.16201782226562,44.9657897949219,,,,,,,,,,,,,,,,
,3737901249.3115,4.99961161613464,8333.7880859375,-1.32771615615316E-5,2.57940569742447E-7,1,0.999253354069792,40.0298881530762,1.99964043220003,16.1799993366003,-0.000140250346890498,-3.74769788502302E-5,0.25,-1.10438770603164E-6,-1.31993594023191E-5,-1.16970442386813E-6,4.99951219558716,4.99951219558716,8313.791015625,8353.78515625,54.4865424470635,19.7037888547397,4.60884094238281,0,0,0,40,5.00376987457275,1,6,1,2.16400146484375,44.9657897949219,,,,,,,,,,,,,,,,
,3737901333.1495,5.00060772895813,12528.9809570312,-2.3074978450119E-5,3.06085926981655E-7,1,0.999253354069792,40.0298881530762,1.9995219903874,16.1799993366003,-0.000244996692603395,-5.85804182445341E-5,0.25,-1.29970972434607E-6,-2.29505950612033E-5,-1.42415630077852E-6,5.00067853927612,5.00067853927612,12503.953125,12554.0087890625,54.8617241362943,19.7042205822613,4.55475187301636,0,0,0,40,5.00379371643066,1,6,1,2.1600341796875,45.4545478820801,,,,,,,,,,,,,,,,
,3737901417.088,4.99979948997498,16726.1474609375,-3.0389407171697E-5,2.48557591207834E-7,1,0.999253354069792,40.0298881530762,1.99958592704178,16.1799993366003,-0.000323804002031384,-7.15336146632423E-5,0.25,-1.17642686822114E-6,-3.0239710459982E-5,-1.35253961943059E-6,4.99976778030396,4.99976778030396,16703.62109375,16748.673828125,54.9781867856597,19.6997820778782,4.51225996017456,0,0,0,40,5.00383615493774,1,6,1,2.16140747070313,44.9657897949219,,,,,,,,,,,,,,,,
,3737901501.076,5.00016212463379,20926.4013671875,-3.39441987190732E-5,2.45954346063253E-7,1,0.999253354069792,40.0298881530762,1.99955855974966,16.1700006574392,-0.000362074260477101,-7.85210236266332E-5,0.25,-1.17319480302623E-6,-3.37911518620283E-5,-1.3804858015401E-6,5.00016784667969,5.00016784667969,20903.875,20948.927734375,55.0344640390443,19.7028711115439,4.49448680877686,0,0,0,40,5.00433301925659,1,6,1,2.164306640625,44.9657897949219,,,,,,,,,,,,,,,,
,3737901584.965,4.99978828430176,25119.4296875,-3.44192500308991E-5,2.76491069049455E-7,1,0.999253354069792,40.0298881530762,1.99939766580094,16.1799993366003,-0.000367163863626087,-8.0210115423953E-5,0.25,-1.23344526271098E-6,-3.42779520168416E-5,-1.45263819816185E-6,4.99959564208984,4.99959564208984,25094.470703125,25144.388671875,55.3322645048712,19.7057722938233,4.47085952758789,0,0,0,40,5.00462055206299,1,6,1,2.1612548828125,45.4545478820801,,,,,,,,,,,,,,,,
,3737901668.922,4.99968409538269,29331.517578125,-3.52493766277151E-5,3.05076359740143E-7,1,0.999253354069792,40.0298881530762,1.99927558101574,16.1700006574392,-0.000376041593673881,-8.28249241490195E-5,0.25,-1.31586206032138E-6,-3.51194007928821E-5,-1.54859048811288E-6,4.99965810775757,4.99965810775757,29306.396484375,29356.638671875,55.250193510352,19.7052236983219,4.44689702987671,0,0,0,40,5.00588941574097,1,6,1,2.14797973632813,44.9657897949219,,,,,,,,,,,,,,,,
,3737901752.8245,5.00004458427429,33542.857421875,-3.9640015481892E-5,3.33381330185445E-7,1,0.999253354069792,40.0298881530762,1.99933798148421,16.1700006574392,-0.000423540826985629,-9.06456305251987E-5,0.25,-1.23589504253413E-6,-3.95128498067E-5,-1.50661215294442E-6,4.9998664855957,4.9998664855957,33517.78515625,33567.9296875,54.9406686167366,19.7039754276023,4.42335081100464,0,0,0,40,5.00755453109741,1,6,1,2.16278076171875,44.9657897949219,,,,,,,,,,,,,,,,
,3737901836.7975,5.00040674209595,37759.6640625,-4.65920339515047E-5,3.46090107312663E-7,1,0.999253354069792,40.0298881530762,1.99923017737372,16.1700006574392,-0.000498826388880427,-0.000102132276683371,0.25,-1.03107926951051E-6,-4.64661692262674E-5,-1.35846494974504E-6,5.00049161911011,5.00049161911011,37734.5703125,37784.7578125,54.7655838284289,19.707335465248,4.40089845657349,0,0,0,40,5.00910043716431,1,6,1,2.16094970703125,44.9657897949219,,,,,,,,,,,,,,,,
,3737901920.725,4.99970960617065,41970.220703125,-5.59606404783065E-5,4.37796667912178E-7,1,0.999253354069792,40.0298881530762,1.99927261294809,16.1799993366003,-0.00059943711091274,-0.000122563764964321,0.25,-1.21630828550963E-6,-5.58343933350649E-5,-1.61731200511056E-6,4.99963808059692,4.99963808059692,41950.125,41990.31640625,55.0852698927943,19.7064553146067,4.38018751144409,0,0,0,40,5.01097822189331,1,6,1,2.16018676757813,44.9657897949219,,,,,,,,,,,,,,,,
,3737902004.6625,4.99973773956299,46186.728515625,-6.68126433341464E-5,3.44676870027899E-7,1,0.999253354069792,40.0298881530762,1.99914826449967,16.1799993366003,-0.000716085776004032,-0.000145663285092866,0.25,-1.37850783503195E-6,-6.66917577261219E-5,-1.8646021022657E-6,4.99980449676514,4.99980449676514,46161.63671875,46211.8203125,55.1454552887751,19.7096262262907,4.360764503479,0,0,0,40,5.01329517364502,1,6,1,2.16293334960938,44.4770278930664,,,,,,,,,,,,,,,,
,3737902088.5995,4.99985241889954,50397.96484375,-7.87899568461661E-5,2.93750576873023E-7,1,0.999253354069792,40.0298881530762,1.99906206388683,16.1799993366003,-0.000845602253437249,-0.000167361301957516,0.25,-1.20396853226529E-6,-7.86844082688489E-5,-1.7838978482714E-6,4.99993228912354,4.99993228912354,50372.80078125,50423.12890625,55.1509266884097,19.7001643807052,4.34196949005127,0,0,0,40,5.01552391052246,1,6,1,2.16140747070313,45.4545478820801,,,,,,,,,,,,,,,,
,3737902172.5355,4.99926662445068,54630.51171875,-9.06676262565657E-5,3.68003573165333E-7,1,0.999253354069792,40.0298881530762,1.99925442104774,16.1700006574392,-0.000974097019767986,-0.000189840887212704,0.25,-1.11721988253214E-6,-9.05864059848987E-5,-1.78928512608715E-6,4.99915266036987,4.99915266036987,54602.73046875,54658.29296875,55.311160534852,19.7048983719165,4.32486200332642,0,0,0,40,5.01790618896484,1,6,1,2.14187622070313,44.9657897949219,,,,,,,,,,,,,,,,
,3737902256.4405,4.99930357933044,58875.501953125,-0.000104008339117439,4.15416538196259E-7,1,0.999253354069792,40.0298881530762,1.99928632767552,16.1700006574392,-0.00111782077812712,-0.00021830134545754,0.25,-1.32034163720596E-6,-0.000103957522348793,-2.09375016601762E-6,4.99932432174683,4.99932432174683,58850.29296875,58900.7109375,55.097775949102,19.7053946276681,4.30856132507324,0,0,0,40,5.02173328399658,1,6,1,2.15850830078125,48.8758583068848,,,,,,,,,,,,,,,,
,3737902340.4515,4.99961709976196,63120.4765625,-0.000117116062071186,4.84163501675032E-7,1,0.999253354069792,40.0298881530762,1.99905199806098,16.1799993366003,-0.00125923210493099,-0.000244894383687225,0.25,-1.39576127669754E-6,-0.000117105788127119,-2.26683043707511E-6,4.999671459198,4.999671459198,63097.7421875,63143.2109375,55.2369058255251,19.705976404849,4.2933292388916,0,0,0,40,5.02377462387085,1,6,1,2.16110229492187,44.9657897949219,,,,,,,,,,,,,,,,
,3737902424.353,5.00015354156494,67365.6640625,-0.000130553375651185,4.52884998007545E-7,1,0.999253354069792,40.0298881530762,1.9991672752469,16.1799993366003,-0.00140464683772402,-0.000271309932577135,0.25,-1.39222179523114E-6,-0.00013059261692394,-2.3607603654535E-6,5.00022840499878,5.00022840499878,67340.4140625,67390.9140625,55.4252782986597,19.7046225162201,4.27956819534302,0,0,0,40,5.02860116958618,1,6,1,2.15728759765625,44.9657897949219,,,,,,,,,,,,,,,,
,3737902508.2625,4.99994230270386,71607.671875,-0.000144281173552668,3.76688399937672E-7,1,0.999253354069792,40.0298881530762,1.99904496040149,16.1700006574392,-0.00155269192508718,-0.000300618299590319,0.25,-1.60867615835214E-6,-0.000144376230748586,-2.67387858117026E-6,4.9998927116394,4.9998927116394,71582.34375,71633,54.9602093297174,19.7069432701249,4.26610660552978,0,0,0,40,5.03253793716431,1,6,1,2.16354370117187,45.4545478820801,,,,,,,,,,,,,,,,
,3737902592.21,4.99983525276184,75852.70703125,-0.000157907085854818,5.40281281969214E-7,1,0.999253354069792,40.0298881530762,1.99901490992685,16.1799993366003,-0.00170013977929241,-0.000327738104003295,0.25,-1.64182327469453E-6,-0.000158066444901212,-2.79941861966911E-6,4.9999532699585,4.9999532699585,75830.0078125,75875.40625,55.1095003768904,19.7058254499066,4.25361013412476,0,0,0,40,5.03639650344849,1,6,1,2.16079711914062,44.9657897949219,,,,,,,,,,,,,,,,
,3737902676.131,5.00001311302185,80098.32421875,-0.000171590526228066,5.41337575485322E-7,1,0.999253354069792,40.0298881530762,1.99931010456113,16.1700006574392,-0.00184602312141677,-0.000368974698152595,0.25,-2.97009836649368E-6,-0.00017181128592742,-4.21864985066067E-6,4.99993228912354,4.99993228912354,80073.046875,80123.6015625,55.3932315293713,19.7054227397982,4.24191236495972,0,0,0,40,5.04135990142822,1,6,1,2.15118408203125,46.9208221435547,,,,,,,,,,,,,,,,
,3737902760.086,4.99943876266479,84342.796875,-0.000186096625691024,5.16789107066114E-7,1,0.999253354069792,40.0298881530762,1.99897367827931,16.1700006574392,-0.00200563323396536,-0.000382359472595021,0.25,-1.58081654123502E-6,-0.000186405633584649,-2.91851043335228E-6,4.99950075149536,4.99950075149536,84320.09375,84365.5,55.4198068990251,19.7031438048471,4.23054170608521,0,0,0,40,5.0435962677002,1,6,1,2.15789794921875,44.9657897949219,,,,,,,,,,,,,,,,
,3737902844.057,4.99972772598267,88590.390625,-0.000201263884486705,4.266782517483E-7,1,0.999253354069792,40.0298881530762,1.99918586899127,16.1799993366003,-0.00216902158095795,-0.00041878817558889,0.25,-2.2001875829202E-6,-0.00020165362639289,-3.63082254635638E-6,4.99970388412476,4.99970388412476,88567.6015625,88613.1796875,55.4323129553328,19.7060901196464,4.22097301483154,0,0,0,40,5.04790592193604,1,6,1,2.16293334960938,45.4545478820801,,,,,,,,,,,,,,,,
,3737902936.9575,5.00042366981506,87321.18359375,-0.000196135177098547,5.80586060130714E-7,1,0.999253354069792,40.0298881530762,1.99888806817341,16.1700006574392,-0.00211382394854795,-0.000404972656272105,0.25,-1.85612338865905E-6,-0.000196500178823945,-3.25484312993152E-6,5.00054407119751,5.00054407119751,87296.2578125,87346.109375,55.4776474094482,19.7020481440296,4.20879125595093,0,0,0,40,5.0479531288147,1,6,1,2.14324951171875,44.9657897949219,,,,,,,,,,,,,,,,
,3737903020.9325,4.9999668598175,83135.87109375,-0.000181432066497402,5.15574254814626E-7,1,0.999253354069792,40.0298881530762,1.99916785237866,16.1799993366003,-0.00195542082582755,-0.000372518832290341,0.25,-1.51287077905041E-6,-0.000181717855597872,-2.82107592632511E-6,4.99968576431274,4.99968576431274,83110.9375,83160.8046875,55.3244482196789,19.7117604761899,4.19675827026367,0,0,0,40,5.04380989074707,1,6,1,2.15072631835938,44.9657897949219,,,,,,,,,,,,,,,,
,3737903104.831,5.00077867507935,78955.98828125,-0.000167426209805219,3.81093536612764E-7,1,0.999253354069792,40.0298881530762,1.99894158702456,16.1799993366003,-0.00180413849644817,-0.000341309819732198,0.25,-1.16927490781819E-6,-0.000167639692893061,-2.38822175523671E-6,5.00080585479736,5.00080585479736,78931.0390625,78980.9375,54.9328523315443,19.7062606167959,4.1849479675293,0,0,0,40,5.03962516784668,1,6,1,2.15560913085938,44.9657897949219,,,,,,,,,,,,,,,,
,3737903188.7335,4.99952721595764,74773.02734375,-0.000154049824362028,4.89341189262568E-7,1,0.999253354069792,40.0298881530762,1.99910413676105,16.1799993366003,-0.00165922379234452,-0.000315949445408135,0.25,-1.2498586013606E-6,-0.000154194615307167,-2.38103998996522E-6,4.99953174591064,4.99953174591064,74745.65625,74800.3984375,54.8968974196597,19.7102190332123,4.17312955856323,0,0,0,40,5.03443717956543,1,6,1,2.16583251953125,45.4545478820801,,,,,,,,,,,,,,,,
,3737903272.6805,5.00009775161743,70590.140625,-0.000139725420205914,4.00085112073718E-7,1,0.999253354069792,40.0298881530762,1.99908822097598,16.1700006574392,-0.001503515877184,-0.000291392733326094,0.25,-1.58271777090393E-6,-0.00013980538274787,-2.61571455959804E-6,5.0001540184021,5.0001540184021,70565.2578125,70615.0234375,55.0414986957174,19.7086113686445,4.16157531738281,0,0,0,40,5.03085374832153,1,6,1,2.156982421875,44.4770278930664,,,,,,,,,,,,,,,,
,3737903356.616,5.00045967102051,66408.015625,-0.000126724117637717,4.3969318087777E-7,1,0.999253354069792,40.0298881530762,1.99903616068176,16.1799993366003,-0.00136269185064712,-0.00026636576772523,0.25,-1.63361965520272E-6,-0.000126749463685037,-2.57457770564203E-6,5.00051403045654,5.00051403045654,66385.59375,66430.4375,55.2994361070635,19.7118316345586,4.15078067779541,0,0,0,40,5.02652740478516,1,6,1,2.16384887695313,44.4770278930664,,,,,,,,,,,,,,,,
,3737903440.567,5.0006058216095,62225.3828125,-0.000112900548279486,4.09369220099645E-7,1,0.999253354069792,40.0298881530762,1.99888240473881,16.1700006574392,-0.00121353913473699,-0.000236976444672775,0.25,-1.43198913258403E-6,-0.000112880742930143,-2.27186139139852E-6,5.0005202293396,5.0005202293396,62200.484375,62250.28125,54.5443829574865,19.7106339670519,4.14011240005493,0,0,0,40,5.02414178848267,1,6,1,2.16354370117187,44.4770278930664,,,,,,,,,,,,,,,,
,3737903524.539,5.00011706352234,58042.244140625,-9.96086828322295E-5,4.22216554746848E-7,1,0.999253354069792,40.0298881530762,1.99896882738052,16.1799993366003,-0.00106938232907912,-0.000213998015754338,0.25,-1.72694256788411E-6,-9.95486718227917E-5,-2.46713141477779E-6,5.00021266937256,5.00021266937256,58014.765625,58069.72265625,55.5331430343136,19.7053802941426,4.13015794754028,0,0,0,40,5.02007150650024,1,6,1,2.16598510742187,44.4770278930664,,,,,,,,,,,,,,,,
,3737903608.452,5.00030589103699,53860.224609375,-8.67140960717597E-5,3.66629852074771E-7,1,0.999253354069792,40.0298881530762,1.99888784647016,16.1700006574392,-0.000930278986263436,-0.000187610743682322,0.25,-1.63499089721522E-6,-8.66256368102253E-5,-2.27665450533815E-6,5.00049686431885,5.00049686431885,53835.3046875,53885.14453125,55.1102820054097,19.7084148207457,4.12007284164429,0,0,0,40,5.01826763153076,1,6,1,2.16018676757813,43.9882698059082,,,,,,,,,,,,,,,,
,3737903692.375,4.99989891052246,49680.751953125,-7.39901775816611E-5,3.20020268800754E-7,1,0.999253354069792,40.0298881530762,1.99914802616667,16.1700006574392,-0.00079395391715766,-0.000157765089505998,0.25,-1.18746329492145E-6,-7.38852657214035E-5,-1.7311754355642E-6,4.99996995925903,4.99996995925903,49655.80078125,49705.703125,54.9875663278904,19.7069122634504,4.1111044883728,0,0,0,40,5.01460933685303,1,6,1,2.15423583984375,43.9882698059082,,,,,,,,,,,,,,,,
,3737903776.3085,5.00028944015503,45495.197265625,-6.19354810947284E-5,3.73310451843272E-7,1,0.999253354069792,40.0298881530762,1.99893286103879,16.1700006574392,-0.000664717825634186,-0.000129401497000132,0.25,-7.57616691174981E-7,-6.1822787885299E-5,-1.20816268152014E-6,5.00019073486328,5.00019073486328,45470.26171875,45520.1328125,55.1055922342943,19.7085514995188,4.10285234451294,0,0,0,40,5.01159858703613,1,6,1,2.15347290039062,43.9882698059082,,,,,,,,,,,,,,,,
,3737903860.2385,4.99993753433228,41315.4375,-4.97905895929499E-5,3.5235289288033E-7,1,0.999253354069792,40.0298881530762,1.99891891485321,16.1700006574392,-0.000532881835243397,-0.000110875498349057,0.25,-1.25523956533959E-6,-4.9673600668737E-5,-1.61068616436805E-6,4.99983644485474,4.99983644485474,41290.44921875,41340.42578125,54.6921107476212,19.707293690837,4.09399461746216,0,0,0,40,5.00938272476196,1,6,1,2.15530395507813,43.9882698059082,,,,,,,,,,,,,,,,
,3737903944.187,5.00028705596924,37133.341796875,-3.76029041503841E-5,2.89121278151668E-7,1,0.999253354069792,40.0298881530762,1.99898244574537,16.1799993366003,-0.000401596164917304,-8.74526272571978E-5,0.25,-1.30191529295925E-6,-3.749552409229E-5,-1.56403636980957E-6,5.00030040740967,5.00030040740967,37105.8046875,37160.87890625,54.4169775088519,19.7096212018411,4.0856204032898,0,0,0,40,5.00772142410278,1,6,1,2.16323852539062,43.49951171875,,,,,,,,,,,,,,,,
,3737904028.1845,5.00075793266296,32948.1953125,-2.60063772329095E-5,3.05947186706378E-7,1,0.999253354069792,40.0298881530762,1.99888800770875,16.1799993366003,-0.000278012215878558,-5.82455206184161E-5,0.25,-6.99083088610233E-7,-2.59221019068597E-5,-8.76326176129405E-7,5.00078678131103,5.00078678131103,32925.859375,32970.53125,55.077453607602,19.7031176468519,4.07856750488281,0,0,0,40,5.00686931610107,1,6,1,2.1539306640625,43.9882698059082,,,,,,,,,,,,,,,,
,3737904112.1185,4.99950575828552,28765.62890625,-1.52252273541541E-5,2.9608239751872E-7,1,0.999253354069792,40.0298881530762,1.99890933815384,16.1700006574392,-0.000161160363789011,-4.25196834081597E-5,0.25,-1.19770213456267E-6,-1.51639843800361E-5,-1.29556117821385E-6,4.99963474273682,4.99963474273682,28740.814453125,28790.443359375,55.1095003768904,19.7059801269042,4.07219886779785,0,0,0,40,5.00526189804077,1,6,1,2.15469360351562,43.9882698059082,,,,,,,,,,,,,,,,
,3737904196.0345,5.00027132034302,24583.8603515625,-4.80151765376958E-6,3.18730678477206E-7,1,0.999253354069792,40.0298881530762,1.99892911330639,16.1799993366003,-5.01027205959172E-5,-1.72733672168798E-5,0.25,-7.39285948888526E-7,-4.77787604744715E-6,-7.67480024087814E-7,5.00032234191895,5.00032234191895,24556.4140625,24611.306640625,54.8265508529289,19.7049786260037,4.0653510093689,0,0,0,40,5.00395441055298,1,6,1,2.16339111328125,43.49951171875,,,,,,,,,,,,,,,,
,3737904279.9545,5.00054144859314,20404.357421875,6.44955534287228E-6,2.16150744643055E-7,1,0.999253354069792,40.0298881530762,1.99899496189953,16.1700006574392,7.12736547568158E-5,1.09700375404517E-6,0.25,-1.06456681981649E-6,6.4281639055244E-6,-1.01981404976964E-6,5.00044012069702,5.00044012069702,20377.0078125,20431.70703125,55.107937119852,19.7048978760674,4.05978584289551,0,0,0,40,5.00446939468384,1,6,1,2.15087890625,43.49951171875,,,,,,,,,,,,,,,,
,3737904363.8735,5.00035691261292,16222.2016601562,1.73033607179921E-5,2.734634299095E-7,1,0.999253354069792,40.0298881530762,1.99900693096707,16.1700006574392,0.000187371212640335,2.37743220667729E-5,0.25,-9.09052433470076E-7,1.72267235359384E-5,-8.01924905059921E-7,5.00050354003906,5.00050354003906,16197.2138671875,16247.189453125,54.8953341626212,19.7030892022635,4.05378293991089,0,0,0,40,5.00288581848145,1,6,1,2.15835571289062,43.9882698059082,,,,,,,,,,,,,,,,
,3737904447.8115,5.0002326965332,12038.4038085938,2.84757970931609E-5,2.31878206005003E-7,1,0.999253354069792,40.0298881530762,1.99896969656153,16.1799993366003,0.000306729867767427,4.74131506540079E-5,0.25,-7.13074134991622E-7,2.83342388929181E-5,-5.48741157860707E-7,5.00018310546875,5.00018310546875,12015.96875,12060.8388671875,54.7476063724866,19.7054802532643,4.04734230041504,0,0,0,40,5.00256443023682,1,6,1,2.14920043945313,43.9882698059082,,,,,,,,,,,,,,,,
,3737904531.7355,5.00021839141846,7851.51440429688,3.96716908243022E-5,2.49532285731029E-7,1,0.999253354069792,40.0298881530762,1.99892412581258,16.1700006574392,0.000426164949853161,7.16099753443278E-5,0.25,-4.60681461574435E-7,3.94579355226273E-5,-2.46556486301174E-7,5.00020933151245,5.00020933151245,7829.05322265625,7873.9755859375,55.2009509136404,19.7073762966795,4.04183387756348,0,0,0,40,5.00286102294922,1,6,1,2.15057373046875,48.8758583068848,,,,,,,,,,,,,,,,
,3737904615.7235,4.99999451637268,3656.51904296875,5.19177042350324E-5,2.23221195937632E-7,1,0.999253354069792,40.0298881530762,1.99876856635176,16.1799993366003,0.000557256716690811,9.50725907724367E-5,0.25,-4.57262655860769E-7,5.16218497170445E-5,-1.93350300479011E-7,4.99991703033447,4.99991703033447,3634.01025390625,3679.02783203125,54.6592823498135,19.6992222995587,4.03737115859985,0,0,0,40,5.00474309921265,1,6,1,2.16339111328125,43.9882698059082,,,,,,,,,,,,,,,,
,3737904705.6145,5.00092601776123,-836.9140625,7.20372301734314E-5,2.48415166242035E-7,1,0.999253354069792,40.0298881530762,1.99879836565487,16.1799993366003,0.000772884755939063,0.000133072863637131,0.25,-5.11948755141849E-7,7.16147101452167E-5,-1.59103327644473E-7,5.00111675262451,5.00111675262451,-859.415161132813,-814.412963867187,55.1376390035828,19.7020742139214,4.03328609466553,0,0,0,40,5.00567054748535,1,6,1,2.15988159179687,43.49951171875,,,,,,,,,,,,,,,,
,3737904792.5445,5.00044846534729,-5183.20458984375,8.6481387696864E-5,2.35682853384777E-7,1,0.999253354069792,40.0298881530762,1.99887412039996,16.1799993366003,0.000927936599390062,0.00016089119002795,0.25,-5.3761162577769E-7,8.59961658724298E-5,-9.00880656229455E-8,5.00023126602173,5.00023126602173,-5208.13720703125,-5158.27197265625,54.9563011871212,19.7024925576787,4.02758550643921,0,0,0,40,5.00475263595581,1,6,1,2.16384887695313,43.9882698059082,,,,,,,,,,,,,,,,
,3737904879.451,5.0003547668457,-9528.814453125,9.54999218126935E-5,2.52585901670718E-7,1,0.999253354069792,40.0298881530762,1.99883904466771,16.1700006574392,0.00102481883641602,0.000178865693499841,0.25,-5.17670265744194E-7,9.49947377622092E-5,6.33506129617097E-9,5.00016927719116,5.00016927719116,-9553.7509765625,-9503.8779296875,55.1728122869481,19.7078433483147,4.02259588241577,0,0,0,40,5.00399446487427,1,6,1,2.1484375,44.4770278930664,,,,,,,,,,,,,,,,
,3737904963.444,4.99979496002197,-13731.20703125,0.000100279105145258,2.86608321913206E-7,1,0.999253354069792,40.0298881530762,1.99872526611803,16.1799993366003,0.00107552763509027,0.000192889934092978,0.25,-1.06628548706553E-7,9.97817454882091E-5,4.72086397146565E-7,4.99981498718262,4.99981498718262,-13758.6650390625,-13703.7490234375,54.4834159329865,19.7065306433165,4.01768016815186,0,0,0,40,5.00326585769653,1,6,1,2.16156005859375,43.9882698059082,,,,,,,,,,,,,,,,
,3737905050.354,5.00039744377136,-18075.591796875,9.68063705561181E-5,3.13243260420788E-7,1,0.999253354069792,40.0298881530762,1.99865954164459,16.1799993366003,0.00103966673651153,0.00018074497367706,0.25,-6.48107353659419E-7,9.63681011882419E-5,-5.7642493022008E-8,5.00028228759766,5.00028228759766,-18098.109375,-18053.07421875,54.5412564434096,19.7116069399993,4.01326847076416,0,0,0,40,5.00245952606201,1,6,1,2.15682983398438,44.4770278930664,,,,,,,,,,,,,,,,
,3737905134.322,4.99982619285583,-22273.0234375,8.48061650739502E-5,3.3143866413152E-7,1,0.999253354069792,40.0298881530762,1.99866918826908,16.1700006574392,0.000911413643680491,0.000157059679189954,0.25,-7.16028768815171E-7,8.4457967839131E-5,-1.7545571755927E-7,4.99985885620117,4.99985885620117,-22298.080078125,-22247.966796875,55.3205400770828,19.7096329355028,4.00939893722534,0,0,0,40,5.00374555587769,1,6,1,2.15133666992187,44.4770278930664,,,,,,,,,,,,,,,,
,3737905218.231,4.9999475479126,-26469.3916015625,6.90272155343737E-5,3.65650130835983E-7,1,0.999253354069792,40.0298881530762,1.99875639461411,16.1700006574392,0.000742747882409882,0.000124807225314307,0.25,-8.87338215085655E-7,6.87753433002385E-5,-4.29684012677591E-7,4.99985933303833,4.99985933303833,-26494.515625,-26444.267578125,54.860942507775,19.7093054683768,4.00599336624146,0,0,0,40,5.00459241867065,1,6,1,2.1630859375,43.9882698059082,,,,,,,,,,,,,,,,
,3737905302.139,5.00036334991455,-30679.634765625,5.75539176497699E-5,3.35105707517572E-7,1,0.999253354069792,40.0298881530762,1.99860161286024,16.1700006574392,0.000620533965998799,9.85282164390904E-5,0.25,-1.27096525318659E-6,5.73729376841849E-5,-8.75666641084924E-7,5.00039720535278,5.00039720535278,-30704.75390625,-30654.515625,55.1860999717751,19.7063428698724,4.00247430801392,0,0,0,40,5.00591611862183,1,6,1,2.15377807617187,43.9882698059082,,,,,,,,,,,,,,,,
,3737905386.074,4.99958968162537,-34894.2890625,5.31215142224436E-5,2.5611607669878E-7,1,0.999253354069792,40.0298881530762,1.99859766352287,16.1799993366003,0.000572899975023471,9.15471437483622E-5,0.25,-1.1299443119627E-6,5.2978062449282E-5,-7.56068045966673E-7,4.99958229064941,4.99958229064941,-34919.390625,-34869.1875,54.6741332916789,19.7140521812574,4.00012540817261,0,0,0,40,5.00732707977295,1,6,1,2.14889526367187,44.4770278930664,,,,,,,,,,,,,,,,
,3737905470.017,5.00006461143494,-39105.0078125,5.57676315268621E-5,3.46443482970645E-7,1,0.999253354069792,40.0298881530762,1.99845260138388,16.1799993366003,0.000600595046202019,0.000102045375289413,0.25,-6.45333033619084E-7,5.56382768717687E-5,-2.46304932030925E-7,5.00007724761963,5.00007724761963,-39130.09765625,-39079.91796875,55.1345124895058,19.7050577248325,3.99716663360596,0,0,0,40,5.00810623168945,1,6,1,2.16156005859375,44.4770278930664,,,,,,,,,,,,,,,,
,3737905553.9665,4.99969458580017,-43319.55078125,6.19811279375707E-5,3.55617425192401E-7,1,0.999253354069792,40.0298881530762,1.99844329002198,16.1799993366003,0.000667909185347121,0.000112908449766711,0.25,-7.76205045763337E-7,6.18654264283883E-5,-3.25562623753835E-7,4.99988651275635,4.99988651275635,-43344.69140625,-43294.41015625,55.229871168852,19.7050117530109,3.9945764541626,0,0,0,40,5.01060962677002,1,6,1,2.15896606445313,44.4770278930664,,,,,,,,,,,,,,,,
,3737905637.9125,4.99939322471619,-47529.1328125,7.08374098164679E-5,4.4023852391592E-7,1,0.999253354069792,40.0298881530762,1.99858920952019,16.1799993366003,0.0007637185797486,0.000129189717085151,0.25,-8.85526826820164E-7,7.07362432876722E-5,-3.64597935918941E-7,4.99943351745605,4.99943351745605,-47554.12109375,-47504.14453125,54.9531746730443,19.7097990778382,3.99226808547974,0,0,0,40,5.01216793060303,1,6,1,2.1527099609375,44.4770278930664,,,,,,,,,,,,,,,,
,3737905721.819,4.99881625175476,-51744.765625,8.14271281045444E-5,2.71456242000859E-7,1,0.999253354069792,40.0298881530762,1.99875467383714,16.1799993366003,0.00087797062747545,0.000150587528350033,0.25,-8.35921584238369E-7,8.13444675017128E-5,-2.32797836076745E-7,4.9988842010498,4.9988842010498,-51769.765625,-51719.765625,55.2986544785443,19.7078403416122,3.99013161659241,0,0,0,40,5.01484060287476,1,6,1,2.16140747070313,44.9657897949219,,,,,,,,,,,,,,,,
,3737905805.758,5.00044512748718,-55983.990234375,9.34366602166211E-5,3.82370677176361E-7,1,0.999253354069792,40.0298881530762,1.99864162992399,16.1700006574392,0.00100747052377552,0.000174833801433593,0.25,-7.78932686451035E-7,9.33796599626246E-5,-8.40969365836794E-8,5.00047016143799,5.00047016143799,-56009.21484375,-55958.765625,55.2752056229674,19.7120177943082,3.98836088180542,0,0,0,40,5.0193133354187,1,6,1,2.15652465820313,44.4770278930664,,,,,,,,,,,,,,,,
,3737905889.711,5.00007462501526,-60227.6484375,0.000105980448974145,4.55002791862482E-7,1,0.999253354069792,40.0298881530762,1.99880245648744,16.1700006574392,0.00114276627203112,0.000201186694204475,0.25,-6.25743492972712E-7,0.000105956853559759,1.63154041918691E-7,4.99991130828857,4.99991130828857,-60250.4140625,-60204.8828125,55.1509266884097,19.706171862281,3.98663640022278,0,0,0,40,5.02303695678711,1,6,1,2.15805053710938,45.4545478820801,,,,,,,,,,,,,,,,
,3737905973.6485,4.99945306777954,-64471.833984375,0.000118794514133402,4.53596507922242E-7,1,0.999253354069792,40.0298881530762,1.99858045820086,16.1799993366003,0.00128121972376521,0.000226027019220641,0.25,-6.58041236542483E-7,0.000118814051097254,2.24798921875362E-7,4.99957132339478,4.99957132339478,-64497.05859375,-64446.609375,54.9109667330058,19.7080448223395,3.985684633255,0,0,0,40,5.0258092880249,1,6,1,2.16293334960938,44.4770278930664,,,,,,,,,,,,,,,,
,3737906057.574,5.00031304359436,-68715.83984375,0.000132139776420588,3.61461627249423E-7,1,0.999253354069792,40.0298881530762,1.99898006947776,16.1799993366003,0.00142614698598728,0.000250494967031081,0.25,-8.26622290097517E-7,0.000132211510524933,1.51283842032469E-7,5.00020790100098,5.00020790100098,-68743.6328125,-68688.046875,54.9242544178327,19.7101301371236,3.98435091972351,0,0,0,40,5.02988624572754,1,6,1,2.16583251953125,44.9657897949219,,,,,,,,,,,,,,,,
,3737906141.535,4.9994068145752,-72959.8203125,0.000146207872707943,4.32138336258589E-7,1,0.999253354069792,40.0298881530762,1.99856692442663,16.1799993366003,0.00157669757833674,0.000285627115656054,0.25,-1.2678495283559E-7,0.000146333463587819,9.48985375351256E-7,4.99909591674805,4.99909591674805,-72985.140625,-72934.5,55.1415471461789,19.7122006622898,3.98353052139282,0,0,0,40,5.0335545539856,1,6,1,2.16171264648438,44.4770278930664,,,,,,,,,,,,,,,,
,3737906225.4815,5.00023889541626,-77202.890625,0.000159789202074516,5.07867494558197E-7,1,0.999253354069792,40.0298881530762,1.99863778012383,16.1799993366003,0.00172311935566836,0.000316003716835558,0.25,2.16962652758026E-7,0.000159977945903019,1.38357586730297E-6,4.99999046325684,4.99999046325684,-77230.6875,-77175.09375,54.9992907556789,19.709804843846,3.98322796821594,0,0,0,40,5.03732299804687,1,6,1,2.14691162109375,44.4770278930664,,,,,,,,,,,,,,,,
,3737906309.4245,4.99977922439575,-81449.4375,0.000175016290282547,4.92625115395153E-7,1,0.999253354069792,40.0298881530762,1.99848274587199,16.1799993366003,0.00188787736027662,0.000345719100630244,0.25,2.05690594936231E-7,0.00017527950018653,1.47102448712241E-6,4.99988317489624,4.99988317489624,-81477.5078125,-81421.3671875,55.2353425684866,19.7103588742591,3.98292517662048,0,0,0,40,5.04112005233765,1,6,1,2.16323852539062,45.4545478820801,,,,,,,,,,,,,,,,
,3737906393.377,5.00005674362183,-85692.6015625,0.000188392228482684,5.12490850462296E-7,1,0.999253354069792,40.0298881530762,1.99855342679795,16.1700006574392,0.00203274676593261,0.000372809832702108,0.25,2.87458671468704E-7,0.0001887323307878,1.63436059039052E-6,5.00021028518677,5.00021028518677,-85722.9765625,-85662.2265625,55.1665592587943,19.7085366018144,3.98276615142822,0,0,0,40,5.04527235031128,1,6,1,2.166748046875,43.9882698059082,,,,,,,,,,,,,,,,
,3737906477.2545,4.99961876869202,-89933.125,0.000203040058013581,4.16692532274077E-7,1,0.999253354069792,40.0298881530762,1.99846844657146,16.1799993366003,0.00219237693131833,0.000396155123106108,0.25,-2.0329582517843E-7,0.000203468474386456,1.22914148612296E-6,4.9994421005249,4.9994421005249,-89958.3984375,-89907.8515625,54.7460431154481,19.706822722783,3.982745885849,0,0,0,40,5.04895687103271,1,6,1,2.16445922851562,44.4770278930664,,,,,,,,,,,,,,,,
,3737906570.2035,5.00080132484436,-85987.48828125,0.000189627577236703,5.83115089178329E-7,1,0.999253354069792,40.0298881530762,1.99857273857485,16.1799993366003,0.00204582342871324,0.000376988532500943,0.25,4.50135951994618E-7,0.000189972646796768,1.80503678222185E-6,5.00081396102905,5.00081396102905,-86012.4453125,-85962.53125,55.2947463359481,19.709322061179,3.98197293281555,0,0,0,40,5.04610395431519,1,6,1,2.15133666992187,44.9657897949219,,,,,,,,,,,,,,,,
,3737906654.149,5.00020313262939,-81806.87109375,0.000175161666610214,4.76821455544346E-7,1,0.999253354069792,40.0298881530762,1.99844116879576,16.1799993366003,0.00189145343724207,0.000335036563578027,0.25,-8.09900822889654E-7,0.000175437029956154,4.53790045650826E-7,5.00041103363037,5.00041103363037,-81829.328125,-81784.4140625,55.2361241970058,19.7133345410267,3.97864365577698,0,0,0,40,5.04084157943726,1,6,1,2.16552734375,44.9657897949219,,,,,,,,,,,,,,,,
,3737906738.061,5.00068855285645,-77624.98046875,0.000161264252266336,4.13259685868539E-7,1,0.999253354069792,40.0298881530762,1.99863033758238,16.1799993366003,0.0017401588991751,0.000312981988913895,0.25,-3.31366221808208E-7,0.00016146402930225,8.44288535609745E-7,5.00074005126953,5.00074005126953,-77649.90625,-77600.0546875,54.9086218474481,19.7107089470082,3.97476029396057,0,0,0,40,5.03814220428467,1,6,1,2.166748046875,45.4545478820801,,,,,,,,,,,,,,,,
,3737906821.9755,5.00016856193542,-73446.55859375,0.000147991590311284,4.70792303397166E-7,1,0.999253354069792,40.0298881530762,1.99815471143059,16.1799993366003,0.00159623282741797,0.00028604850953367,0.25,-4.07331495729958E-7,0.000148126642256033,6.8040377611628E-7,5.00029611587524,5.00029611587524,-73471.5078125,-73421.609375,55.1579613450827,19.7073127609307,3.97204875946045,0,0,0,40,5.03360462188721,1,6,1,2.14736938476562,44.9657897949219,,,,,,,,,,,,,,,,
,3737906905.9295,4.99987387657166,-69265.64453125,0.000133552849636707,4.2486828701261E-7,1,0.999253354069792,40.0298881530762,1.99847145827179,16.1700006574392,0.0014396455693274,0.000261204964176928,0.25,-8.50460379808127E-8,0.000133626085724143,9.03022887190689E-7,4.99973630905151,4.99973630905151,-69288.09375,-69243.1953125,54.5928439256789,19.7091515292058,3.96858429908752,0,0,0,40,5.02911376953125,1,6,1,2.15957641601562,44.4770278930664,,,,,,,,,,,,,,,,
,3737906989.8595,5.00028610229492,-65083.59375,0.000119700817830561,3.69389840401517E-7,1,0.999253354069792,40.0298881530762,1.99836915259726,16.1799993366003,0.00128966596454023,0.000234710695838704,0.25,-1.57399434447015E-8,0.000119722257793796,8.73551393694257E-7,5.00044727325439,5.00044727325439,-65108.44921875,-65058.73828125,54.7546410291596,19.7082908133188,3.96486759185791,0,0,0,40,5.02658319473267,1,6,1,2.16232299804687,45.4545478820801,,,,,,,,,,,,,,,,
,3737907073.8225,4.99985218048096,-60901.7578125,0.00010692081797066,3.87534700298218E-7,1,0.999253354069792,40.0298881530762,1.99854965791372,16.1799993366003,0.00115265921242694,0.000203953336383305,0.25,-5.39016238817871E-7,0.000106903061910339,2.56799864021689E-7,5.0000262260437,5.0000262260437,-60924.171875,-60879.34375,54.9226911607943,19.7078093300728,3.96195912361145,0,0,0,40,5.02364540100098,1,6,1,2.16278076171875,44.9657897949219,,,,,,,,,,,,,,,,
,3737907157.7785,5.00043487548828,-56720.443359375,9.39372299431488E-5,3.55195454163358E-7,1,0.999253354069792,40.0298881530762,1.99849960841225,16.1700006574392,0.00101219799943167,0.000179470873259592,0.25,-4.39747867604711E-7,9.38840830329969E-5,2.58887578710588E-7,5.00044918060303,5.00044918060303,-56745.32421875,-56695.5625,55.2103304558712,19.7032355081724,3.95849061012268,0,0,0,40,5.0203013420105,1,6,1,2.1588134765625,44.4770278930664,,,,,,,,,,,,,,,,
,3737907241.6945,4.99944448471069,-52539.18359375,8.15419420142371E-5,3.18289634728235E-7,1,0.999253354069792,40.0298881530762,1.99864848589637,16.1700006574392,0.000878536320285057,0.000154636936680378,0.25,-4.81631921036725E-7,8.1463024579969E-5,1.22609287346566E-7,4.99952507019043,4.99952507019043,-52561.58203125,-52516.78515625,55.1024657202174,19.7126879235535,3.95524549484253,0,0,0,40,5.01679849624634,1,6,1,2.16323852539062,44.9657897949219,,,,,,,,,,,,,,,,
,3737907325.6025,4.99996304512024,-48357.892578125,6.85008394798632E-5,4.08690977919763E-7,1,0.999253354069792,40.0298881530762,1.99859568798916,16.1700006574392,0.000738203256624141,0.00012707901453869,0.25,-6.58358358763169E-7,6.84073986058944E-5,-1.54002585979989E-7,5.00003051757812,5.00003051757812,-48382.81640625,-48332.96875,55.2189283695828,19.7147350012173,3.95351767539978,0,0,0,40,5.01346588134766,1,6,1,2.15896606445313,44.9657897949219,,,,,,,,,,,,,,,,
,3737907409.554,5.00089049339294,-44176.623046875,5.64680001147928E-5,4.00947744390374E-7,1,0.999253354069792,40.0298881530762,1.99862283090954,16.1700006574392,0.000608627044682042,0.000102771069285708,0.25,-7.18736167652172E-7,5.63677553080528E-5,-3.07065813264072E-7,5.00091075897217,5.00091075897217,-44199.02734375,-44154.21875,54.7421349728519,19.7100981329062,3.95016264915466,0,0,0,40,5.01189470291138,1,6,1,2.16049194335938,44.9657897949219,,,,,,,,,,,,,,,,
,3737907493.471,5.00052499771118,-40000.822265625,4.47186653061997E-5,2.27711535606539E-7,1,0.999253354069792,40.0298881530762,1.99826617235535,16.1799993366003,0.000483186288471237,7.31356890056017E-5,0.25,-1.32752330744354E-6,4.46249910598442E-5,-1.00448894573976E-6,5.0006217956543,5.0006217956543,-40025.78515625,-39975.859375,54.576429726775,19.7073861120104,3.94799256324768,0,0,0,40,5.01062250137329,1,6,1,2.16476440429687,44.9657897949219,,,,,,,,,,,,,,,,
,3737907577.4365,5.00005125999451,-35814.451171875,3.30741581774504E-5,3.26749048514659E-7,1,0.999253354069792,40.0298881530762,1.99872429644313,16.1700006574392,0.000356719019307752,5.71884166694828E-5,0.25,-6.87838104262622E-7,3.29879887479613E-5,-4.53996732979532E-7,5.00016498565674,5.00016498565674,-35841.8125,-35787.08984375,54.7202493743135,19.7116715006243,3.94481587409973,0,0,0,40,5.00774192810059,1,6,1,2.16217041015625,45.4545478820801,,,,,,,,,,,,,,,,
,3737907661.361,4.99952626228333,-31632.94921875,2.18449180570178E-5,3.27932448231983E-7,1,0.999253354069792,40.0298881530762,1.99844621864098,16.1700006574392,0.00023623196801586,3.3552448696315E-5,0.25,-8.41444650632874E-7,2.1780897148985E-5,-6.89348012007114E-7,4.99962425231934,4.99962425231934,-31657.94140625,-31607.95703125,54.7046168039289,19.7120464748721,3.94293284416199,0,0,0,40,5.00536441802978,1,6,1,2.1533203125,44.9657897949219,,,,,,,,,,,,,,,,
,3737907745.3105,4.9998996257782,-27454.5078125,1.09272088634015E-5,2.54049168947257E-7,1,0.999253354069792,40.0298881530762,1.99857459260084,16.1799993366003,0.000119554093577057,8.8774125410672E-6,0.25,-1.15454560769414E-6,1.08951853147659E-5,-1.07785279813803E-6,4.99981021881103,4.99981021881103,-27479.345703125,-27429.669921875,54.7866877984481,19.7090144194561,3.94154357910156,0,0,0,40,5.00554609298706,1,6,1,2.16354370117187,44.9657897949219,,,,,,,,,,,,,,,,
,3737907829.301,4.99991297721863,-23270.498046875,-1.82978895379281E-7,2.82741681871702E-7,1,0.999253354069792,40.0298881530762,1.99842637424062,16.1799993366003,6.34493174018289E-7,-1.47012776287348E-5,0.25,-1.3369294848203E-6,-1.7368048130974E-7,-1.33267324712538E-6,5.00000810623169,5.00000810623169,-23295.318359375,-23245.677734375,54.6733516631596,19.7110867392911,3.94021201133728,0,0,0,40,5.00466203689575,1,6,1,2.16232299804687,46.9208221435547,,,,,,,,,,,,,,,,
,3737907913.1845,5.00087547302246,-19090.8583984375,-1.08266107318285E-5,2.78291201823408E-7,1,0.999253354069792,40.0298881530762,1.99849248612204,16.1700006574392,-0.0001137223219632,-3.43381480787384E-5,0.25,-1.24346514389364E-6,-1.07705744688276E-5,-1.30434308170183E-6,5.00109958648682,5.00109958648682,-19115.80078125,-19065.916015625,54.7429166013712,19.7083819398733,3.93845772743225,0,0,0,40,5.00463581085205,1,6,1,2.16033935546875,44.9657897949219,,,,,,,,,,,,,,,,
,3737907997.146,5.00046443939209,-14907.10546875,-2.1483449715671E-5,2.52082186966687E-7,1,0.999253354069792,40.0298881530762,1.99856178374428,16.1799993366003,-0.000228340100574657,-5.28675458853746E-5,0.25,-1.05172081507023E-6,-2.13728647037998E-5,-1.17228077822963E-6,5.00080156326294,5.00080156326294,-14932.0546875,-14882.15625,54.8656322788904,19.7121844902871,3.93700289726257,0,0,0,40,5.00313329696655,1,6,1,2.16461181640625,44.4770278930664,,,,,,,,,,,,,,,,
,3737908081.036,4.99955415725708,-10724.1513671875,-3.26852766438111E-5,3.23848337238967E-7,1,0.999253354069792,40.0298881530762,1.99828814278763,16.1700006574392,-0.000347268540393293,-8.02010451934002E-5,0.25,-1.59193557081419E-6,-3.25057476278691E-5,-1.76490832882374E-6,4.99973964691162,4.99973964691162,-10749.1474609375,-10699.1552734375,55.4174620134674,19.7097527899629,3.93610835075378,0,0,0,40,5.00324869155884,1,6,1,2.154541015625,44.4770278930664,,,,,,,,,,,,,,,,
,3737908164.9725,5.0001175403595,-6536.38671875,-4.46407646453013E-5,2.52311711945677E-7,1,0.999253354069792,40.0298881530762,1.9983319973656,16.1799993366003,-0.000475742964121616,-0.000100662723933407,0.25,-1.36293092502743E-6,-4.4385981938617E-5,-1.58917907365397E-6,4.99992084503174,4.99992084503174,-6561.3662109375,-6511.4072265625,54.9578644441597,19.711357295809,3.93534541130066,0,0,0,40,5.00449275970459,1,6,1,2.158203125,44.4770278930664,,,,,,,,,,,,,,,,
,3737908251.9405,5.00003433227539,-2192.72644042969,-5.78238550320345E-5,2.10322668360145E-7,1,0.999253354069792,40.0298881530762,1.99840812442271,16.1799993366003,-0.000617167970901745,-0.000124350377229538,0.25,-1.2221063083449E-6,-5.7480704675585E-5,-1.50039912602287E-6,5.00044345855713,5.00044345855713,-2220.27026367187,-2165.1826171875,54.4607487059288,19.7096059699719,3.93492341041565,0,0,0,40,5.00476551055908,1,6,1,2.14508056640625,44.4770278930664,,,,,,,,,,,,,,,,
,3737908338.836,4.99953722953796,2152.58093261719,-7.83819208260133E-5,3.36029748513069E-7,1,0.999253354069792,40.0298881530762,1.99832216823645,16.1799993366003,-0.000836671488830579,-0.000167894123742675,0.25,-1.59527212910688E-6,-7.79169014481417E-5,-1.97266162130274E-6,4.99945878982544,4.99945878982544,2127.02905273438,2178.1328125,54.9828765567751,19.7082396728361,3.93376278877258,0,0,0,40,5.00513601303101,1,6,1,2.15911865234375,43.9882698059082,,,,,,,,,,,,,,,,
,3737908425.7915,4.99992346763611,6503.37451171875,-9.09165077616452E-5,2.406882462158E-7,1,0.999253354069792,40.0298881530762,1.9983354801715,16.1799993366003,-0.000972102073411381,-0.000187265026882489,0.25,-1.11986928391825E-6,-9.04060696168179E-5,-1.58961639422842E-6,4.99988460540771,4.99988460540771,6478.30859375,6528.4404296875,54.5037382744865,19.7093355478161,3.93273115158081,0,0,0,40,5.00320243835449,1,6,1,2.16293334960938,44.4770278930664,,,,,,,,,,,,,,,,
,3737908512.7265,5.00062465667725,10851.2368164062,-9.91385668133087E-5,2.97339235592659E-7,1,0.999253354069792,40.0298881530762,1.9985103066555,16.1799993366003,-0.00105999730601669,-0.000206855864673802,0.25,-1.42906295453421E-6,-9.86139139352164E-5,-1.97240840395368E-6,5.00063133239746,5.00063133239746,10828.7060546875,10873.767578125,54.4498059066596,19.7056123626007,3.93007302284241,0,0,0,40,5.00260877609253,1,6,1,2.16644287109375,43.49951171875,,,,,,,,,,,,,,,,
,3737908596.6445,5.00094175338745,15043.353515625,-0.000101489463758378,3.31965596840428E-7,1,0.999253354069792,40.0298881530762,1.99830416419098,16.1700006574392,-0.00108541567420711,-0.000211842548711392,0.25,-1.43456574990606E-6,-0.000100988957393839,-2.02227523690919E-6,5.00073194503784,5.00073194503784,15018.3779296875,15068.3291015625,54.9086218474481,19.704294750137,3.92965507507324,0,0,0,40,5.0037260055542,1,6,1,2.15240478515625,43.49951171875,,,,,,,,,,,,,,,,
,3737908680.635,4.99972105026245,19246.2119140625,-9.50619270780135E-5,2.88262821519208E-7,1,0.999253354069792,40.0298881530762,1.99820395107618,16.1700006574392,-0.00101709065059328,-0.000198128645743268,0.25,-1.28237784859414E-6,-9.46304437889359E-5,-1.86098305780585E-6,5.00005435943604,5.00005435943604,19218.701171875,19273.72265625,54.7655838284289,19.7063077953445,3.9293360710144,0,0,0,40,5.00218200683594,1,6,1,2.15866088867187,43.49951171875,,,,,,,,,,,,,,,,
,3737908764.522,5.00064873695374,23439.595703125,-8.05275172901149E-5,2.93906467013535E-7,1,0.999253354069792,40.0298881530762,1.99828080529942,16.1799993366003,-0.000860895365403996,-0.000173852795842532,0.25,-1.61898534206738E-6,-8.01916133548298E-5,-2.12858420340056E-6,5.00077962875366,5.00077962875366,23414.701171875,23464.490234375,54.6538109501788,19.7084357729417,3.92769193649292,0,0,0,40,5.00407123565674,1,6,1,2.15957641601562,43.49951171875,,,,,,,,,,,,,,,,
,3737908848.467,4.99988436698914,27645.6005859375,-6.51182888568332E-5,2.73108202237586E-7,1,0.999253354069792,40.0298881530762,1.99829436202921,16.1700006574392,-0.000696673624519436,-0.000139486657456316,0.25,-1.18591308041145E-6,-6.48752131547669E-5,-1.61433054667926E-6,5.00013399124146,5.00013399124146,27620.521484375,27670.6796875,54.952393044525,19.7051015580955,3.92716860771179,0,0,0,40,5.0033016204834,1,6,1,2.15118408203125,43.9882698059082,,,,,,,,,,,,,,,,
,3737908932.417,5.00024676322937,31859.15234375,-5.55968057165721E-5,2.92200758938311E-7,1,0.999253354069792,40.0298881530762,1.99822740825745,16.1799993366003,-0.00059492119278817,-0.000119851980654905,0.25,-1.0675619862821E-6,-5.5413235889147E-5,-1.44500008420491E-6,5.00038909912109,5.00038909912109,31831.345703125,31886.958984375,55.2009509136404,19.701504903162,3.926349401474,0,0,0,40,5.00489711761475,1,6,1,2.16033935546875,43.49951171875,,,,,,,,,,,,,,,,
,3737909016.35,5.0002818107605,36073.26171875,-5.40965890001056E-5,3.53368864138748E-7,1,0.999253354069792,40.0298881530762,1.99837500013946,16.1799993366003,-0.000579168891643211,-0.000116666093870389,0.25,-1.02841755124822E-6,-5.39420233765357E-5,-1.40552042702867E-6,5.00018453598022,5.00018453598022,36048.20703125,36098.31640625,54.8961157911404,19.7084649265005,3.9263768196106,0,0,0,40,5.00671052932739,1,6,1,2.16415405273438,43.9882698059082,,,,,,,,,,,,,,,,
,3737909100.2985,5.00002646446228,40286.65625,-5.78430965616164E-5,2.91512543167627E-7,1,0.999253354069792,40.0298881530762,1.99838276703832,16.1799993366003,-0.000619273167228858,-0.000126370721197392,0.25,-1.23759259456385E-6,-5.7702526347633E-5,-1.64915060314308E-6,4.99975728988647,4.99975728988647,40259.12109375,40314.19140625,54.8077917684673,19.7039577859175,3.92642450332642,0,0,0,40,5.00838327407837,1,6,1,2.14874267578125,44.4770278930664,,,,,,,,,,,,,,,,
,3737909184.2105,5.00023984909058,44497.8203125,-6.4718231352626E-5,3.27520946033898E-7,1,0.999253354069792,40.0298881530762,1.9981427576932,16.1700006574392,-0.000693914823297476,-0.000136994072582862,0.25,-9.64478415320911E-7,-6.45925104197508E-5,-1.4334631916338E-6,5.00027656555176,5.00027656555176,44470.24609375,44525.39453125,54.9500481589674,19.7061429277405,3.92700338363647,0,0,0,40,5.0120325088501,1,6,1,2.15164184570313,43.9882698059082,,,,,,,,,,,,,,,,
,3737909268.182,4.99947118759155,48711.64453125,-7.39834783379526E-5,4.07634322124158E-7,1,0.999253354069792,40.0298881530762,1.99828852994738,16.1700006574392,-0.000793582744898756,-0.000157101635219761,0.25,-1.13547674709315E-6,-7.38716617756072E-5,-1.67801327100935E-6,4.99956083297729,4.99956083297729,48686.578125,48736.7109375,54.8703220500058,19.704117646028,3.92762494087219,0,0,0,40,5.01447200775146,1,6,1,2.15118408203125,44.4770278930664,,,,,,,,,,,,,,,,
,3737909352.074,5.00020146369934,52932.267578125,-8.56387695656734E-5,3.39103826075362E-7,1,0.999253354069792,40.0298881530762,1.99793536357935,16.1799993366003,-0.000918983329105944,-0.000181112837189249,0.25,-1.23704959453335E-6,-8.55463336218005E-5,-1.87026608451288E-6,5.00018453598022,5.00018453598022,52909.48046875,52955.0546875,54.6725700346404,19.7048161910629,3.92822027206421,0,0,0,40,5.01715660095215,1,6,1,2.16232299804687,44.4770278930664,,,,,,,,,,,,,,,,
,3737909436.038,4.9993302822113,57176.86328125,-9.68956972449724E-5,4.05122689159676E-7,1,0.999253354069792,40.0298881530762,1.99823699505423,16.1700006574392,-0.00104022623495334,-0.000205782253054455,0.25,-1.46670469987265E-6,-9.68308648848529E-5,-2.18643702174901E-6,4.99929857254028,4.99929857254028,57151.55859375,57202.16796875,54.7069616894866,19.7081015069173,3.92937636375427,0,0,0,40,5.0193042755127,1,6,1,2.16537475585938,44.4770278930664,,,,,,,,,,,,,,,,
,3737909519.974,4.99946045875549,61419.447265625,-0.000109770990659111,4.24047984905049E-7,1,0.999253354069792,40.0298881530762,1.99820633995958,16.1799993366003,-0.00117861171297264,-0.000234826214820076,0.25,-1.81084818448253E-6,-0.000109740448430047,-2.62742674089904E-6,4.99935579299927,4.99935579299927,61394.14453125,61444.75,54.8312406240443,19.70603273581,3.93015694618225,0,0,0,40,5.02282667160034,1,6,1,2.16461181640625,43.9882698059082,,,,,,,,,,,,,,,,
,3737909603.915,4.99996829032898,65667.5625,-0.000123279849727505,5.3454080693011E-7,1,0.999253354069792,40.0298881530762,1.99817657801762,16.1700006574392,-0.00132385958000521,-0.000265408807632979,0.25,-2.18316148805009E-6,-0.000123292012332236,-3.09914678750976E-6,4.99999046325684,4.99999046325684,65642.3046875,65692.8203125,54.9258176748712,19.7050185854282,3.93143606185913,0,0,0,40,5.02666807174683,1,6,1,2.15774536132813,44.4770278930664,,,,,,,,,,,,,,,,
,3737909687.853,4.99971842765808,69912.0546875,-0.000136527694240266,4.25395936660442E-7,1,0.999253354069792,40.0298881530762,1.99807356085956,16.1700006574392,-0.00146773737806816,-0.000287736007537195,0.25,-1.8392479407974E-6,-0.000136595832359594,-2.84962976903351E-6,4.9997706413269,4.9997706413269,69889.3359375,69934.7734375,54.4818526759481,19.702427437467,3.93350434303284,0,0,0,40,5.03048181533814,1,6,1,2.16567993164062,43.9882698059082,,,,,,,,,,,,,,,,
,3737909771.775,5.00029587745666,74154.11328125,-0.000150441940160901,4.14128163761613E-7,1,0.999253354069792,40.0298881530762,1.99823637726568,16.1799993366003,-0.00161848870638185,-0.000314595803424275,0.25,-1.79327067973702E-6,-0.000150571640204997,-2.89970189731279E-6,5.00030994415283,5.00030994415283,74131.359375,74176.8671875,54.9602093297174,19.706987757432,3.93403506278992,0,0,0,40,5.03372669219971,1,6,1,2.16323852539062,44.4770278930664,,,,,,,,,,,,,,,,
,3737909855.695,4.99991893768311,78399.890625,-0.000164390021805279,4.82631819236337E-7,1,0.999253354069792,40.0298881530762,1.99827751421007,16.1799993366003,-0.00176896700257436,-0.000345001773207003,0.25,-2.07382325762466E-6,-0.000164585909471961,-3.27330454703953E-6,4.99988555908203,4.99988555908203,78374.6328125,78425.1484375,55.0297742679289,19.7105844863025,3.93528699874878,0,0,0,40,5.03803443908691,1,6,1,2.16262817382813,44.4770278930664,,,,,,,,,,,,,,,,
,3737909939.649,4.99991250038147,82644.5546875,-0.000178610392288193,4.76130451707816E-7,1,0.999253354069792,40.0298881530762,1.99798933492666,16.1700006574392,-0.00192351005850924,-0.000368445703268626,0.25,-1.66737759034857E-6,-0.000178884100947978,-2.95712203514367E-6,5.00003814697266,5.00003814697266,82621.84375,82667.265625,55.4518536683136,19.7072212968671,3.93742251396179,0,0,0,40,5.04233884811401,1,6,1,2.15286254882813,44.4770278930664,,,,,,,,,,,,,,,,
,3737910023.618,4.99994397163391,86892.17578125,-0.000192726101721165,4.44913206797499E-7,1,0.999253354069792,40.0298881530762,1.99802292808367,16.1799993366003,-0.00207624428822693,-0.000397337158435125,0.25,-1.78306851243502E-6,-0.000193079388881808,-3.1590698829425E-6,5.0001072883606,5.0001072883606,86864.4140625,86919.9375,55.0797984931597,19.7095760226767,3.93899774551392,0,0,0,40,5.04412698745728,1,6,1,2.16339111328125,44.4770278930664,,,,,,,,,,,,,,,,
,3737910088.598,4.99968361854553,90003.67578125,-0.000205862529292506,1.29374978934538E-6,1,0.999253354069792,40.0298881530762,1.99817417005002,16.1700006574392,-0.00222185431737552,-0.00040544892805088,0.25,-1.50057512712238E-7,-0.000206295341138378,-1.60283732650152E-6,4.99953413009644,4.99953413009644,90000.5390625,90006.8125,55.1157534050443,19.7039032366979,3.9394326210022,0,0,0,40,5.04896593093872,1,4,1,2.1551513671875,44.4770278930664,,,,,,,,,,,,,,,,