File: data/doubleLayers/dl_2-5/ppms/DD205_5/DD205_8_extracted.dat
#Loading data from DD205_5_HYST_100OE_300K.DAT
#
#Found columns:
#Comment
#Time Stamp (sec)
#Temperature (K)
#Magnetic Field (Oe)
#Moment (emu)
#M. Std. Err. (emu)
#Transport Action
#Averaging Time (sec)
#Frequency (Hz)
#Peak Amplitude (mm)
#Center Position (mm)
#Coil Signal' (mV)
#Coil Signal" (mV)
#Range (mV)
#M. Quad. Signal (emu)
#M. Raw' (emu)
#M. Raw" (emu)
#Min. Temperature (K)
#Max. Temperature (K)
#Min. Field (Oe)
#Max. Field (Oe)
#Mass (grams)
#Motor Lag (deg)
#Pressure (Torr)
#VSM Status (code)
#Motor Status (code)
#Measure Status (code)
#Measure Count
#System Temp. (K)
#Temp. Status (code)
#Field Status (code)
#Chamber Status (code)
#Motor Current (amps)
#Motor Heatsink Temp. (C)
#Map 01
#Map 02
#Map 03
#Map 04
#Map 05
#Map 06
#Map 07
#Map 08
#Map 09
#Map 10
#Map 11
#Map 12
#Map 13
#Map 14
#Map 15
#Map 16
#
#Transformed data from column 'Moment (emu)' from emu to memu by multiplication with 1000.
#Transformed data from column 'Magnetic Field (Oe)' from Oe to Tesla by division with 10000.
#Loaded 8975 datapoints.
#Loading Magnetic Field (Oe) and Moment (emu)
#Running linear fit between B=(6.000750390625 .. 8.99995234375) with LM algorithm.
#[[Fit Statistics]]
#    # function evals   = 8
#    # data points      = 1791
#    # variables        = 2
#    chi-square         = 0.000
#    reduced chi-square = 0.000
#    Akaike info crit   = -27129.449
#    Bayesian info crit = -27118.468
#[[Variables]]
#    m:  -0.03777519 +/- 1.40e-05 (0.04%) (init=-0.03782475)
#    b:   0.07458125 +/- 0.000106 (0.14%) (init= 0.07474587)
#[[Correlations]] (unreported correlations are <  0.100)
#    C(m, b)                      = -0.993
#Running linear fit between B=(-8.99939296875 .. -6.0002373046875) with LM algorithm.
#[[Fit Statistics]]
#    # function evals   = 8
#    # data points      = 1198
#    # variables        = 2
#    chi-square         = 0.000
#    reduced chi-square = 0.000
#    Akaike info crit   = -17882.890
#    Bayesian info crit = -17872.713
#[[Variables]]
#    m:  -0.03781492 +/- 1.91e-05 (0.05%) (init=-0.0377752)
#    b:  -0.07556762 +/- 0.000144 (0.19%) (init=-0.07458125)
#[[Correlations]] (unreported correlations are <  0.100)
#    C(m, b)                      =  0.993
#Mean diamagnetic slope: -0.037791122089376745 +/- 1.1355958703816894e-05
#Exporting data to DD205_8_extracted.dat
#
#B / T	M / memu	T / K
3.1454636156559004e-05	0.00063870349034292	300.278259277344
0.0444305877685547	0.0286717855572348	300.321838378906
0.0941273101806641	0.0347148756854384	300.343322753906
0.144344384765625	0.037517746834145896	300.36100769043
0.19411103515625	0.0389758736075944	300.378387451172
0.244306616210938	0.0400602653441579	300.393341064453
0.29400440673828104	0.041413979289754196	300.405883789063
0.343707775878906	0.040893980699902695	300.417343139648
0.393976513671875	0.040538266897887004	300.425857543945
0.44393083496093705	0.0398569892547113	300.434219360352
0.49389802246093706	0.0400096618819878	300.4404296875
0.543680493164063	0.0401345326564789	300.448501586914
0.593398974609375	0.038740405455091304	300.45182800293
0.643632836914062	0.0372613179392119	300.457290649414
0.693369580078125	0.036385516275156606	300.461151123047
0.743425341796875	0.035000226584215303	300.462493896484
0.7936673583984379	0.034098310820537	300.465545654297
0.84339521484375	0.0322969420672585	300.467544555664
0.89343896484375	0.0311097749760645	300.469375610352
0.9436775390625	0.0299195244126456	300.470108032227
0.99291708984375	0.0280128002113849	300.470642089844
1.04339619140625	0.0267319412885932	300.471115112305
1.09339272460938	0.0245464621780526	300.471084594727
1.14339741210938	0.0233740154274437	300.471405029297
1.19362841796875	0.022172220755880098	300.471084594727
1.24317192382812	0.0202263354299702	300.469451904297
1.293146484375	0.0186689716381226	300.469100952148
1.3431481933593798	0.0171492989775462	300.468154907227
1.3928856933593798	0.0146792368451587	300.467544555664
1.44287954101562	0.0136384545368791	300.466873168945
1.4931230957031298	0.0111746357643048	300.464920043945
1.54287265625	0.009619069748415119	300.462646484375
1.5928916015625	0.007984801421592429	300.461181640625
1.64338828125	0.00646127154695087	300.459655761719
1.69289111328125	0.00471330911123598	300.459228515625
1.743126953125	0.00223922447947988	300.456588745117
1.7929251953125	0.00136026597512502	300.453796386719
1.8429123046875	-0.000776721499306881	300.45231628418
1.89290595703125	-0.0029809106095613196	300.449798583984
1.94241728515625	-0.00435335829345387	300.447296142578
1.99244384765625	-0.0060519016769086205	300.444610595703
2.04268955078125	-0.00788049026643778	300.443496704102
2.09242998046875	-0.0095158858969922	300.441009521484
2.14272587890625	-0.011860704693866901	300.43864440918
2.19271455078125	-0.013595939857	300.436141967773
2.24246025390625	-0.0150503600565125	300.43440246582
2.29244443359375	-0.016888971506428	300.43083190918
2.34273583984375	-0.0187444341945288	300.427658081055
2.39247734375	-0.0213846145101595	300.425750732422
2.44272197265625	-0.0223013417036947	300.421722412109
2.49247919921875	-0.0242589962180633	300.420928955078
2.54247119140625	-0.0258969686238732	300.418685913086
2.59220205078125	-0.027881097279594702	300.415084838867
2.642606640625	-0.0299179202503318	300.410766601562
2.6925783203125	-0.0311328218003331	300.40966796875
2.74275322265625	-0.0332004327987925	300.406646728516
2.79318408203125	-0.034414222492729504	300.403137207031
2.84287685546875	-0.0367840121000153	300.402221679687
2.89306513671875	-0.0391358207813432	300.397872924805
2.943228515625	-0.0404164742055019	300.395065307617
2.99366494140625	-0.0424875663874079	300.392379760742
3.0438966796875	-0.0442585364409876	300.389984130859
3.09382431640625	-0.0459897052450887	300.387115478516
3.14400146484375	-0.0476723515858551	300.383865356445
3.19424169921875	-0.049551720105085496	300.381576538086
3.2444294921875	-0.0507685643909113	300.379440307617
3.2946087890625	-0.053212666044298904	300.375305175781
3.3447814453125	-0.0547264593850188	300.374420166016
3.395017578125	-0.056062345402120795	300.370422363281
3.4449509765625	-0.0584754617160872	300.367431640625
3.4951357421875	-0.0605262260386884	300.364974975586
3.545363671875	-0.0620242530411197	300.361526489258
3.5955548828125	-0.0636406642457763	300.359832763672
3.645487890625	-0.0656726283363795	300.357147216797
3.6956740234375	-0.0677444356044005	300.354339599609
3.745898828125	-0.0691437569747941	300.351165771484
3.7963244140625	-0.0713516761065504	300.350433349609
3.8462560546875	-0.0730331834723924	300.346603393555
3.8967048828125	-0.07536919131350961	300.344772338867
3.94663515625	-0.0765429627211535	300.341979980469
3.9968173828125	-0.0786180626169339	300.337341308594
4.046741796875	-0.0810393272234857	300.336181640625
4.097219140625	-0.0824696153776176	300.333618164063
4.147398828125	-0.08387041686037311	300.331924438477
4.197330078125	-0.08569526103004829	300.328979492188
4.2477650390625	-0.0877614316987779	300.324996948242
4.2974419921875	-0.0889876600973643	300.322723388672
4.3476326171875	-0.0915568127750823	300.32014465332
4.3983236328125	-0.09404667084839831	300.318420410156
4.448051171875	-0.0942159349493384	300.316528320313
4.498227734375	-0.0963278744331571	300.313278198242
4.548410546875	-0.099399097640818	300.312118530273
4.5985953125	-0.101107742131205	300.308517456055
4.648824609375	-0.102155132913886	300.306930541992
4.6990068359375	-0.104442741793661	300.304977416992
4.7494390625	-0.106111431735086	300.301376342773
4.79916875	-0.10791796380876001	300.298080444336
4.8495904296875	-0.109747999265468	300.295425415039
4.8995181640625	-0.111349957297187	300.292236328125
4.9497095703125	-0.113939125920382	300.289245605469
5.0001916015625	-0.115279804114263	300.287521362305
5.050129296875	-0.117167582834202	300.285446166992
5.100556640625	-0.11863093481989401	300.28254699707
5.1502955078125	-0.12174414016283899	300.279342651367
5.200477734375	-0.12245970124759699	300.277008056641
5.2510181640625	-0.12477223416439401	300.275756835937
5.3020736328125	-0.125733448595898	300.275131225586
5.352382421875	-0.12845378917914	300.271530151367
5.4026880859375	-0.130037892876465	300.269195556641
5.453240234375	-0.13295319228525002	300.264587402344
5.5038447265625	-0.133252190298559	300.263214111328
5.5543859375	-0.136250000592696	300.263305664063
5.60468671875	-0.13757470184412302	300.260498046875
5.655486328125	-0.139351494247348	300.257537841797
5.70606640625	-0.14135366913896	300.25569152832
5.7563513671875	-0.14332780194828598	300.254013061523
5.8069037109375	-0.145432226666527	300.252334594727
5.8572658203125	-0.147671092887366	300.249572753906
5.9080642578125	-0.148960202801577	300.247894287109
5.9586255859375	-0.150385328642739	300.244537353516
6.0089302734375	-0.152568933673425	300.244125366211
6.0595375	-0.15495970499536302	300.242538452148
6.110089453125	-0.157214885632762	300.240447998047
6.16089375	-0.15795249894734	300.237350463867
6.211504296875	-0.159730309640471	300.237777709961
6.261796875	-0.162955053336308	300.234924316406
6.3123455078125	-0.164121577012652	300.232696533203
6.362652734375	-0.165999062154556	300.23063659668
6.413525	-0.16722697579836102	300.229370117188
6.4638251953125	-0.170129062799405	300.227310180664
6.5143779296875	-0.171544545376304	300.226211547852
6.564980078125	-0.17335969136301999	300.223937988281
6.615273828125	-0.174345778861981	300.223205566406
6.666076171875	-0.177450248089991	300.220672607422
6.71638046875	-0.17945431381649202	300.218612670898
6.76720625	-0.18145791452068702	300.217590332031
6.817504296875	-0.183004009595966	300.21533203125
6.86805	-0.184796016092006	300.212478637695
6.918662109375	-0.186714561411242	300.21257019043
6.96920390625	-0.18893159873118098	300.210632324219
7.0197546875	-0.191361092313025	300.208999633789
7.070308203125	-0.191873311785286	300.207977294922
7.1208875	-0.19485612346979198	300.206512451172
7.17142109375	-0.19610661990502098	300.203735351562
7.221474609375	-0.198356223276385	300.200881958008
7.272595703125	-0.19947430868425398	300.202163696289
7.322634765625	-0.203000445459902	300.199890136719
7.373438671875	-0.203664770621598	300.198379516602
7.42374921875	-0.206490890249285	300.197448730469
7.4743765625	-0.20797117215134	300.193542480469
7.52491640625	-0.209799958504197	300.193206787109
7.57571796875	-0.21157628844713	300.192230224609
7.626071875	-0.213477677770627	300.190689086914
7.676621484375	-0.21582566330463102	300.18994140625
7.7274328125	-0.217284604216429	300.187957763672
7.777733984375	-0.219414931436977	300.186431884766
7.82835703125	-0.220973856836641	300.184967041016
7.87865	-0.222616731366148	300.183395385742
7.929459375	-0.224116369312284	300.181411743164
7.97980859375	-0.227734377630889	300.181823730469
8.03036484375	-0.229102417794295	300.179656982422
8.080654296875	-0.230247222727786	300.178176879883
8.13171953125	-0.23331503668441098	300.176956176758
8.1817828125	-0.23429585212861398	300.175552368164
8.232341796875	-0.236464018545684	300.173248291016
8.282891015625	-0.238395944051507	300.172653198242
8.33374609375	-0.240755397535082	300.171035766602
8.384044921875	-0.24221837510041203	300.168655395508
8.4345828125	-0.243717853797049	300.168045043945
8.485137890625	-0.24569814297581102	300.167419433594
8.535718359375	-0.24723049919363	300.166046142578
8.58601484375	-0.24964353329353597	300.164611816406
8.6368046875	-0.251591475495983	300.162963867188
8.68792578125	-0.253857377980182	300.161407470703
8.73771328125	-0.256139826902543	300.160537719727
8.788259765625	-0.25801530847724297	300.158798217773
8.838819921875	-0.259990816234897	300.159317016602
8.889441796875	-0.261334822314099	300.158340454102
8.9397328125	-0.263353899352156	300.157653808594
8.99028828125	-0.26488794645001995	300.153884887695
8.967729296875	-0.26401288030104997	300.152420043945
8.918221875	-0.262148064396958	300.149978637695
8.868672265625	-0.26038726991175903	300.151245117188
8.81879765625	-0.25835439287927	300.150756835937
8.76898359375	-0.25691297543822705	300.147750854492
8.719188671875	-0.255062495669642	300.146438598633
8.66932734375	-0.253200772183937	300.145614624023
8.619753125	-0.25076439368584996	300.146545410156
8.569692578125	-0.24961665856273496	300.143936157227
8.52013046875	-0.24619179247184503	300.143493652344
8.470051171875	-0.245446374599202	300.141693115234
8.420491015625	-0.242917099083083	300.139343261719
8.370934765625	-0.241013017828793	300.138809204102
8.32084921875	-0.23945031105286302	300.138748168945
8.271262890625	-0.23732904941962898	300.138442993164
8.2214359375	-0.23580757054718401	300.135009765625
8.171631640625	-0.23415724106336	300.135101318359
8.121562890625	-0.23234437619827802	300.134963989258
8.071994921875	-0.230196212786005	300.134323120117
8.0221859375	-0.228469059780048	300.132125854492
7.97236640625	-0.226210874520201	300.131561279297
7.922503125	-0.224214463460613	300.130554199219
7.872690234375	-0.222555846893525	300.130950927734
7.8228859375	-0.220422518757915	300.129272460937
7.77324921875	-0.219477934219971	300.125915527344
7.7231921875	-0.216305551760789	300.126129150391
7.67363203125	-0.21472391397867102	300.124877929687
7.62381796875	-0.21291923603315	300.124877929687
7.574196484375	-0.211676837041133	300.122329711914
7.524384765625	-0.209286449866776	300.122787475586
7.474573828125	-0.206906891564131	300.120986938477
7.424705078125	-0.206031714237792	300.120620727539
7.374892578125	-0.204060432479095	300.118881225586
7.324826953125	-0.202095244669265	300.118148803711
7.275278515625	-0.19968952397335898	300.117553710937
7.22564921875	-0.197500023085556	300.116561889648
7.175583203125	-0.195551338469459	300.116775512695
7.12602265625	-0.19472052325050002	300.115081787109
7.07595	-0.193312864186355	300.114288330078
7.026387890625	-0.190584121569145	300.11344909668
6.976575390625	-0.18818645096894301	300.113372802734
6.927025390625	-0.187459632256534	300.112396240234
6.877161328125	-0.185282903042549	300.11083984375
6.8271078125	-0.182915387803951	300.110412597656
6.7772890625	-0.18097403265831902	300.108551025391
6.7277234375	-0.1797077607869	300.108276367188
6.67790703125	-0.17774775354941902	300.10774230957
6.628094921875	-0.17589752068717399	300.107086181641
6.578269140625	-0.17338552984422398	300.106155395508
6.5284228515625	-0.17236176402408102	300.104629516602
6.4783673828125	-0.170660401273226	300.104278564453
6.4287958984375	-0.168423528927262	300.102691650391
6.379239453125	-0.165684764378458	300.102462768555
6.329607421875	-0.164610422413731	300.102783203125
6.2793099609375	-0.162693237819714	300.101486206055
6.2297458984375	-0.16102533596134	300.099884033203
6.1798763671875	-0.158783003163916	300.099334716797
6.1303171875	-0.157172752225967	300.098770141602
6.0805025390625	-0.15508716563729202	300.097595214844
6.0306984375	-0.153095763591937	300.097747802734
5.9805748046875	-0.15096733220432	300.097045898438
5.93101484375	-0.14895300477397602	300.095779418945
5.881219921875	-0.14736964558646598	300.094665527344
5.831096484375	-0.145554369723192	300.093597412109
5.7815326171875	-0.143775645493017	300.093048095703
5.7317287109375	-0.141843145733354	300.093887329102
5.6819193359375	-0.14018916906554	300.091293334961
5.63234453125	-0.138399868232097	300.090927124023
5.582533203125	-0.136825457369747	300.089996337891
5.532727734375	-0.13389870615854202	300.087890625
5.4826283203125	-0.131990689385356	300.09001159668
5.433308984375	-0.13100589081659	300.088653564453
5.383498046875	-0.12907575436243002	300.087585449219
5.333701171875	-0.126612759052633	300.086624145508
5.283883203125	-0.12492193301808098	300.086517333984
5.2340658203125	-0.12320751456680701	300.086318969727
5.1837541015625	-0.12177853921373599	300.08576965332
5.1344294921875	-0.12003521762173901	300.084548950195
5.0843408203125	-0.117421944875144	300.083557128906
5.0345318359375	-0.115227363132755	300.08203125
4.98496953125	-0.11422065355668	300.080932617188
4.93510078125	-0.11233118288795299	300.081619262695
4.8855546875	-0.110188974711867	300.081420898438
4.8357341796875	-0.108412433214758	300.080780029297
4.7859208984375	-0.1069103738125	300.081176757812
4.7360595703125	-0.105195866180112	300.079376220703
4.6862638671875	-0.10307979717429801	300.0791015625
4.6367041015625	-0.10145194222479201	300.079315185547
4.5865775390625	-0.09935823569052711	300.078353881836
4.537023828125	-0.09727768047027041	300.076065063477
4.4872240234375	-0.09572097889777059	300.076324462891
4.43741015625	-0.0936010320726517	300.075790405273
4.3875421875	-0.0921713529797393	300.076400756836
4.3379921875	-0.0907761408751456	300.074920654297
4.2876904296875	-0.0889289056276672	300.072052001953
4.238113671875	-0.08664199767325631	300.074295043945
4.1883091796875	-0.08480305658249611	300.07421875
4.1384978515625	-0.0829522991565637	300.071319580078
4.088693359375	-0.08092031170677999	300.071914672852
4.0388306640625	-0.0786074299837542	300.072219848633
3.988773046875	-0.07727598668895	300.070907592773
3.939716796875	-0.07656913049636371	300.069305419922
3.8898900390625	-0.0735993571901317	300.069686889648
3.840085546875	-0.0712180932184638	300.070098876953
3.7900263671875	-0.0692073982718521	300.070053100586
3.740465234375	-0.0687729493671151	300.067733764648
3.6903646484375	-0.067099269134469	300.066421508789
3.6405529296875	-0.0649834413068172	300.067398071289
3.5907451171875	-0.06284823772110609	300.067153930664
3.54115625	-0.060301173322329	300.066192626953
3.491321875	-0.059099712689563	300.064300537109
3.4415052734375	-0.057652319516775505	300.064819335937
3.3919396484375	-0.0548604089694562	300.065521240234
3.3420841796875	-0.054011081491705505	300.064956665039
3.2925296875	-0.0516613046484921	300.063812255859
3.2427140625	-0.0505789245185783	300.064025878906
3.19241044921875	-0.0477903537831702	300.062271118164
3.14278818359375	-0.046452564797786894	300.063125610352
3.093237890625	-0.045502696585200494	300.062545776367
3.0431765625	-0.0427198968867614	300.060577392578
2.9933162109375	-0.0408597610246734	300.061538696289
2.9437609375	-0.0392490048325224	300.060745239258
2.893957421875	-0.0376197749096348	300.059753417969
2.8441419921875	-0.035773236440103	300.05924987793
2.79432763671875	-0.0336388232665268	300.059494018555
2.7445263671875	-0.0314582341071825	300.05876159668
2.6947158203125	-0.029589846111702	300.058120727539
2.64461259765625	-0.0284682339989085	300.058166503906
2.5953154296875	-0.027088773281051002	300.057891845703
2.54551025390625	-0.0244349544575561	300.055572509766
2.49571357421875	-0.0226043557224278	300.05615234375
2.44564609375	-0.0210727049973716	300.056732177734
2.39608857421875	-0.019134512309268503	300.054885864258
2.34653564453125	-0.017927495356726	300.053741455078
2.29668740234375	-0.015459485329126898	300.054046630859
2.24687216796875	-0.013935333323241001	300.053253173828
2.19706064453125	-0.012595022265163	300.052810668945
2.14751455078125	-0.0102841564252886	300.052215576172
2.0974041015625	-0.00807617824155114	300.052612304687
2.04759912109375	-0.00638934029370254	300.051513671875
1.99779072265625	-0.0056106548765325	300.052047729492
1.948466796875	-0.0034612794070015	300.050476074219
1.898383203125	-0.00138651197225522	300.051605224609
1.848831640625	0.0007108004365900299	300.052215576172
1.7990224609375	0.00186114335862361	300.051742553711
1.7491607421875	0.0032747894047064	300.049530029297
1.6991171875	0.00614470917835589	300.049575805664
1.64955322265625	0.0078065518358040095	300.049453735352
1.59975043945313	0.0102989996121993	300.048233032227
1.54914951171875	0.0112157178597177	300.048675537109
1.50009643554687	0.012547710303181801	300.046737670898
1.45029458007813	0.0140335160670897	300.046249389648
1.40048422851562	0.0166585679853374	300.046234130859
1.35067138671875	0.0180001708852763	300.046524047852
1.3008702636718799	0.0196608778216733	300.04670715332
1.2512345703125	0.021367331763334	300.046813964844
1.2010435546875	0.023651053091974298	300.045379638672
1.1511466308593798	0.024533155557687203	300.046569824219
1.1010013183593799	0.026517737408393003	300.04443359375
1.05132114257813	0.0283652989616895	300.043350219727
1.0014352050781299	0.0301676683027259	300.044570922852
0.95205361328125	0.031116208437412803	300.044494628906
0.902154833984375	0.032330099431103404	300.04460144043
0.85221787109375	0.034525856568309705	300.042297363281
0.8018253173828129	0.036161355663523	300.041473388672
0.752171435546875	0.0365219407996203	300.041687011719
0.702470556640625	0.037971604697187404	300.04231262207
0.652568774414062	0.039494536998588896	300.042678833008
0.60263076171875	0.040887630436112	300.042129516602
0.552433154296875	0.0415012254424083	300.041137695313
0.502700244140625	0.0423179507231218	300.040283203125
0.453014208984375	0.042536568582556895	300.040161132812
0.403307482910156	0.0429567678934017	300.041015625
0.353095031738281	0.0432808023577957	300.040985107422
0.303359912109375	0.0431701795914569	300.038619995117
0.237868334960938	0.0418361963444166	300.038452148438
0.188431176757813	0.0415269144086235	300.039123535156
0.13789096069335902	0.0402643636103256	300.039627075195
0.0884157012939453	0.036475235974537105	300.0380859375
0.0384395141601562	0.0296700713246563	300.037399291992
-0.0115469551086426	-0.00872875125206368	300.037948608398
-0.0730871673583984	-0.031125460122084298	300.038757324219
-0.126440679931641	-0.0368918555127975	300.038040161133
-0.176657739257813	-0.040415166764205805	300.037994384766
-0.22638677978515603	-0.0418073480553786	300.035415649414
-0.276344958496094	-0.0426288084455452	300.035736083984
-0.325843029785156	-0.0432910959427856	300.034942626953
-0.376377978515625	-0.043367275825635	300.03581237793
-0.426118115234375	-0.0433318289649641	300.036239624023
-0.49088466796875	-0.0423827230932182	300.034332275391
-0.54140537109375	-0.042523396072789904	300.033538818359
-0.5911439208984379	-0.041346351892234505	300.033340454102
-0.640884423828125	-0.0404935702739839	300.035171508789
-0.6911186279296879	-0.0385632105773708	300.033996582031
-0.7409140380859379	-0.0383043997925703	300.034866333008
-0.790907153320312	-0.0369318470628935	300.033645629883
-0.8408876953125	-0.034725460488709704	300.032806396484
-0.89118173828125	-0.0335011537566956	300.031707763672
-0.941163818359375	-0.032781271032338404	300.032791137695
-0.990905859375	-0.0305479887740784	300.032470703125
-1.0408895996093799	-0.0286114034177274	300.033462524414
-1.0909346191406202	-0.026964958556218	300.032989501953
-1.14091904296875	-0.0255997511707036	300.031463623047
-1.19090913085938	-0.0249435917545692	300.031188964844
-1.24041640625	-0.0222509065941813	300.03125
-1.29067836914062	-0.0200477985210172	300.033172607422
-1.34041440429688	-0.0190075470053831	300.030807495117
-1.39040302734375	-0.017320657214861097	300.030166625977
-1.4403940917968798	-0.015670778103264203	300.031173706055
-1.4903783203125	-0.0132743639311064	300.030334472656
-1.54061821289062	-0.0122029942924272	300.030853271484
-1.5903507324218702	-0.010774265606400199	300.030975341797
-1.64038935546875	-0.00828436024123479	300.030075073242
-1.69036259765625	-0.0063384097759233505	300.029373168945
-1.74010615234375	-0.00521827790090863	300.028869628906
-1.7906041015625	-0.00319623867625344	300.030212402344
-1.84007783203125	-0.00132125593156669	300.029296875
-1.8900669921875	0.000377775759868728	300.028518676758
-1.940059375	0.0020954114575100604	300.028366088867
-1.9900888671875	0.00432985747409429	300.027481079102
-2.04007265625	0.00541881585215493	300.027160644531
-2.0900548828125	0.00725948879777005	300.028091430664
-2.1398515625	0.00973776487719487	300.027801513672
-2.1898357421875	0.0109380289796826	300.026123046875
-2.23982001953125	0.012405160208408499	300.02783203125
-2.28978994140625	0.0148195617325771	300.02815246582
-2.33983671875	0.0172258996587985	300.026748657227
-2.3898123046875	0.018842767780456703	300.026763916016
-2.43979677734375	0.0203473646579773	300.027374267578
-2.48984296875	0.0214658289123311	300.024841308594
-2.53932734375	0.024617880194895598	300.026580810547
-2.58981083984375	0.0263408158568291	300.02587890625
-2.63993076171875	0.0277822715300612	300.025833129883
-2.69016044921875	0.0292940473128307	300.026885986328
-2.740087890625	0.031223740230713302	300.02424621582
-2.7902443359375	0.0332017273752479	300.025421142578
-2.84067900390625	0.0343065652783101	300.025466918945
-2.8905873046875	0.0370489833123309	300.024536132812
-2.94077314453125	0.0387489499097058	300.023910522461
-2.9906712890625	0.040424378669749794	300.024566650391
-3.04088857421875	0.0421547863792025	300.023345947266
-3.0910541015625	0.0432306290922079	300.023910522461
-3.14147880859375	0.045719585063138606	300.024627685547
-3.19140966796875	0.0472276547462873	300.023956298828
-3.241579296875	0.0496315945451758	300.022827148438
-3.2917458984375	0.0508827812941764	300.024276733398
-3.3419013671875	0.0528472981944668	300.024002075195
-3.39187109375	0.0548124005045026	300.022369384766
-3.4420404296875	0.0567332909699513	300.022964477539
-3.4919640625	0.0592979057988455	300.022720336914
-3.542411328125	0.0600661241842641	300.02197265625
-3.5926072265625	0.0622551956865327	300.023818969727
-3.6425220703125	0.0642231859188091	300.022506713867
-3.6926939453125	0.0652195347222633	300.020782470703
-3.7429150390625	0.06773208185513399	300.021438598633
-3.7930701171875	0.0692781499829456	300.021530151367
-3.843248828125	0.0714260980787817	300.022216796875
-3.8934228515625	0.0726238121788816	300.022537231445
-3.9436328125	0.07569736404352839	300.021301269531
-3.993794921875	0.0766448906717004	300.01953125
-4.0439607421875	0.0790284193923986	300.020614624023
-4.09393671875	0.0808190280855815	300.022003173828
-4.1443380859375	0.0820125554788686	300.020751953125
-4.19426015625	0.0840917114893931	300.020645141602
-4.2444251953125	0.08607873685378101	300.020446777344
-4.2946009765625	0.0880927803853266	300.01969909668
-4.3447685546875	0.0896657683785908	300.018600463867
-4.3949384765625	0.0911121576345054	300.01969909668
-4.4449087890625	0.09358891537587351	300.018829345703
-4.4950669921875	0.09594684701318561	300.019271850586
-4.5452328125	0.0979330277133978	300.019973754883
-4.59540078125	0.0992680155035236	300.019332885742
-4.6455814453125	0.10109068455838001	300.020217895508
-4.6957453125	0.102676577629261	300.017883300781
-4.7459197265625	0.105172095520742	300.018402099609
-4.7961365234375	0.105971208806695	300.02099609375
-4.8462953125	0.10727295506987	300.017761230469
-4.8962099609375	0.110255449582995	300.017883300781
-4.94663203125	0.11248344862913	300.017486572266
-4.996609375	0.114532225377255	300.017150878906
-5.0465234375	0.11595591745875	300.018081665039
-5.0969369140625	0.11839346025162499	300.018127441406
-5.1469041015625	0.120244566314438	300.018310546875
-5.197079296875	0.121267378046413	300.018295288086
-5.24759375	0.123434386475381	300.017532348633
-5.298380078125	0.125421752995963	300.017013549805
-5.3487318359375	0.12665652752581802	300.015914916992
-5.3995216796875	0.128983551395408	300.015808105469
-5.4500412109375	0.132046189643004	300.017181396484
-5.5001326171875	0.132882369581232	300.017852783203
-5.5509166015625	0.134410933472531	300.016494750977
-5.601449609375	0.136949338589746	300.015670776367
-5.651731640625	0.138337839268732	300.015884399414
-5.702537109375	0.139669760821507	300.015380859375
-5.7525806640625	0.142467425013944	300.016754150391
-5.8031212890625	0.144511489160573	300.017288208008
-5.8537126953125	0.146678125277163	300.015182495117
-5.9042611328125	0.147367579339199	300.015548706055
-5.9547958984375	0.149954771630152	300.016372680664
-6.0053419921875	0.151782380394718	300.015502929687
-6.055893359375	0.15266841781190602	300.014541625977
-6.1066947265625	0.15571281471760098	300.016021728516
-6.157232421875	0.157332574541067	300.014999389648
-6.207574609375	0.15887626353264	300.015777587891
-6.2583779296875	0.160997418274602	300.015869140625
-6.30866484375	0.162960668556893	300.015472412109
-6.3589443359375	0.164468771268383	300.014312744141
-6.409560546875	0.166645249142951	300.013885498047
-6.459853515625	0.16861508013783702	300.014266967773
-6.510646484375	0.17107203262297302	300.014221191406
-6.561490234375	0.173076324682798	300.013534545898
-6.6115296875	0.173822055103463	300.01530456543
-6.662574609375	0.176617354383099	300.014633178711
-6.7131125	0.178175034117637	300.014099121094
-6.76346328125	0.180846332373052	300.01448059082
-6.81401015625	0.181921067410653	300.01628112793
-6.864034765625	0.18516355026617698	300.014053344727
-6.915124609375	0.18604048945974	300.012969970703
-6.965416015625	0.18894818738271899	300.012893676758
-7.015960546875	0.18922798315071201	300.014190673828
-7.066233203125	0.192032531050735	300.014450073242
-7.116791015625	0.193148675928228	300.014663696289
-7.167579296875	0.194972321994853	300.012741088867
-7.217863671875	0.19745303222288998	300.012252807617
-7.26820078125	0.199481741300023	300.012557983398
-7.319246875	0.200740042002768	300.013320922852
-7.36953359375	0.202080091728707	300.013366699219
-7.419811328125	0.20569627867866003	300.013198852539
-7.4703625	0.20604184764097	300.012130737305
-7.52090546875	0.208714239718559	300.013122558594
-7.571438671875	0.210816910203456	300.013168334961
-7.622280859375	0.213018416722525	300.011688232422
-7.672555859375	0.215052888369707	300.011276245117
-7.723095703125	0.21777824177527802	300.012832641602
-7.77363828125	0.218465207817962	300.012283325195
-7.824232421875	0.22154344060317802	300.012832641602
-7.87451796875	0.22230102054107198	300.011962890625
-7.92555390625	0.22324126991050902	300.012908935547
-7.975886328125	0.227426600332497	300.011154174805
-8.0259296875	0.229499814733164	300.011627197266
-8.076706640625	0.229013882116767	300.011779785156
-8.1272390625	0.231540482555161	300.011291503906
-8.177583203125	0.233682562768147	300.011032104492
-8.228373828125	0.235371313554197	300.0107421875
-8.278647265625	0.237506814297647	300.012924194336
-8.329240234375	0.23906112142952402	300.012756347656
-8.37976328125	0.24122526439703001	300.011306762695
-8.430044921875	0.24347286376914098	300.009307861328
-8.48082421875	0.24634260829557303	300.011566162109
-8.531129296875	0.247447336864662	300.011108398438
-8.581918359375	0.24884002472110597	300.011871337891
-8.6322	0.251894639153881	300.011962890625
-8.682777734375	0.25261188169909404	300.01025390625
-8.73331796875	0.25459873048480003	300.009887695313
-8.783604296875	0.256665274754922	300.010177612305
-8.834390234375	0.25944215847895497	300.010620117188
-8.885196484375	0.260484624603396	300.011474609375
-8.935478125	0.262269501884847	300.010757446289
-8.986021484375	0.264554370005155	300.011367797852
-8.971640625	0.263343882101403	300.009475708008
-8.921923828125	0.262322731269723	300.009307861328
-8.871902734375	0.260006597620891	300.010879516602
-8.8223421875	0.257779225768753	300.009689331055
-8.77228984375	0.255738563137298	300.009796142578
-8.722980859375	0.254549948480848	300.009552001953
-8.672897265625	0.253358040278102	300.009979248047
-8.6236046875	0.24999673726479002	300.009490966797
-8.5738015625	0.24795480795017502	300.009887695313
-8.523756640625	0.24632173915062902	300.008346557617
-8.474208984375	0.243533196226319	300.010513305664
-8.42442265625	0.24296541061257598	300.00959777832
-8.374382421875	0.24078622056187002	300.008117675781
-8.324567578125	0.23833727933199	300.009185791016
-8.27476015625	0.237606119462542	300.009002685547
-8.225206640625	0.235528968921158	300.0078125
-8.17541953125	0.233233474652592	300.00910949707
-8.1255671875	0.231072019548972	300.008209228516
-8.075775	0.229511287034053	300.008316040039
-8.025981640625	0.228301433245795	300.007278442383
-7.9761859375	0.22561539648604098	300.00862121582
-7.926593359375	0.224031979962264	300.00862121582
-7.876798828125	0.22220487063851802	300.008331298828
-7.826508203125	0.22019704017418001	300.007507324219
-7.7773953125	0.21778189067087	300.010284423828
-7.727608203125	0.215588474994536	300.009246826172
-7.6775546875	0.21443761951957502	300.006271362305
-7.62776953125	0.212686359222419	300.0068359375
-7.578173828125	0.210824520614532	300.008911132812
-7.528378515625	0.210318361520893	300.008743286133
-7.478587890625	0.206832254409539	300.009582519531
-7.4285265625	0.204897785714342	300.006881713867
-7.378975	0.20360688284123402	300.006393432617
-7.329180078125	0.20281399621306498	300.006774902344
-7.27939140625	0.199731525497236	300.00715637207
-7.229548046875	0.19733627460106298	300.009094238281
-7.180013671875	0.19631816699354898	300.0087890625
-7.13020078125	0.19348650150093802	300.006851196289
-7.080398046875	0.191994040538089	300.006652832031
-7.030601171875	0.189797088020957	300.004943847656
-6.981047265625	0.188370634436127	300.006988525391
-6.9307625	0.186786648653964	300.006454467773
-6.881401171875	0.183880434820157	300.007751464844
-6.83161875	0.182139358236507	300.009780883789
-6.781808984375	0.181573490471928	300.007446289063
-6.731758984375	0.178442688805031	300.007095336914
-6.681921875	0.177302806955317	300.005813598633
-6.6321078125	0.175844008315273	300.006072998047
-6.58256171875	0.173459646625954	300.007263183594
-6.53271640625	0.171393015734127	300.006378173828
-6.4829283203125	0.16923828528582	300.006225585937
-6.4331134765625	0.167202823697127	300.006072998047
-6.383562890625	0.16580576962994198	300.005569458008
-6.333707421875	0.164178103941224	300.005401611328
-6.2841572265625	0.161846946590911	300.00715637207
-6.2341111328125	0.159515675729579	300.007247924805
-6.1845001953125	0.158045606637823	300.006866455078
-6.134705078125	0.156629666042455	300.005920410156
-6.0846609375	0.155235612811563	300.004913330078
-6.03511015625	0.15324773821267798	300.005645751953
-5.9852923828125	0.15105273752798598	300.005767822266
-5.9354966796875	0.148850621876813	300.005340576172
-5.8856935546875	0.147479584641276	300.006057739258
-5.83585078125	0.145699426509651	300.005310058594
-5.7862845703125	0.143795694665118	300.005554199219
-5.7364943359375	0.14171246619755098	300.005706787109
-5.686698046875	0.140294136498631	300.005874633789
-5.6371390625	0.137664605131249	300.004821777344
-5.587096875	0.135827067864568	300.005264282227
-5.5373123046875	0.13412689250618598	300.004989624023
-5.4877240234375	0.132220034357066	300.006378173828
-5.4379326171875	0.130365299630741	300.005386352539
-5.3878771484375	0.12915200703114899	300.004943847656
-5.3383376953125	0.126665794390533	300.006011962891
-5.28823984375	0.12555027679128	300.005844116211
-5.2381951171875	0.122969092037789	300.00537109375
-5.188644921875	0.121769167923947	300.004638671875
-5.1390943359375	0.11913688846546801	300.006072998047
-5.0895140625	0.117405616687779	300.005889892578
-5.039469921875	0.11559578915233899	300.004821777344
-4.989676171875	0.11425018384829301	300.006408691406
-4.9400603515625	0.11122609239030701	300.005264282227
-4.890026953125	0.109984606401872	300.005172729492
-4.8404796875	0.108168224925243	300.005157470703
-4.7906775390625	0.106130673670449	300.004974365234
-4.7410880859375	0.10397308718010699	300.003921508789
-4.6912990234375	0.103384149134315	300.005249023438
-4.6414951171875	0.101723144561691	300.004013061523
-4.5911935546875	0.09846330321015741	300.004760742188
-4.5418923828125	0.096204443136068	300.005340576172
-4.4921080078125	0.0957276364307826	300.005310058594
-4.4423142578125	0.0944852701744472	300.004287719727
-4.39221484375	0.0922318741042519	300.005310058594
-4.3429205078125	0.0893857358153442	300.006423950195
-4.29287109375	0.0880289031071116	300.005386352539
-4.2430685546875	0.08566712118359769	300.004760742188
-4.1932728515625	0.08439437589035881	300.004684448242
-4.14373203125	0.0828096843986815	300.004028320313
-4.0941865234375	0.0804784945444387	300.005905151367
-4.0438521484375	0.0791354424706799	300.006057739258
-3.9940560546875	0.07660006494595879	300.00456237793
-3.9447603515625	0.07537439003511229	300.003860473633
-3.8949265625	0.0733549691803271	300.00422668457
-3.845116796875	0.0705211214168504	300.005218505859
-3.7950685546875	0.0698429720451673	300.005798339844
-3.745271875	0.0675902440724301	300.005157470703
-3.695433203125	0.0659715756562341	300.00390625
-3.6458806640625	0.0640986243527555	300.003540039063
-3.596085546875	0.0623713846536648	300.004501342773
-3.5462873046875	0.0600266034242903	300.004470825195
-3.4964369140625	0.058554552319164205	300.00373840332
-3.4466435546875	0.056302285825382	300.004470825195
-3.39660625	0.0550329235220644	300.004104614258
-3.3474935546875	0.053176793421519895	300.003067016602
-3.2974626953125	0.050846649841260194	300.003982543945
-3.247663671875	0.048601318196342	300.004119873047
-3.198111328125	0.0473231801314522	300.004608154297
-3.14829833984375	0.0459560999645972	300.003631591797
-3.09850654296875	0.044233232076707506	300.004745483398
-3.04871376953125	0.0426821772307747	300.006225585937
-2.99886689453125	0.0399879391227681	300.003829956055
-2.9490646484375	0.038697050702567	300.003280639648
-2.89928642578125	0.037361476496285795	300.003295898438
-2.84948984375	0.034762417132937	300.00358581543
-2.79967890625	0.033667075383617295	300.004180908203
-2.7501228515625	0.031119496878312	300.004669189453
-2.700335546875	0.030048715284317	300.004745483398
-2.65049755859375	0.0275978754649868	300.004348754883
-2.600941796875	0.025687360162354803	300.004196166992
-2.55115322265625	0.0248314499769046	300.002777099609
-2.501355078125	0.022576843752341202	300.002029418945
-2.45150439453125	0.0209952458372195	300.003067016602
-2.40120224609375	0.018894361853070203	300.00505065918
-2.35190439453125	0.0170929840816733	300.003677368164
-2.30206884765625	0.016100755193557102	300.002670288086
-2.25225625	0.0136697908370089	300.002563476562
-2.20246025390625	0.0112849693444208	300.00439453125
-2.15266025390625	0.00970133818703069	300.003189086914
-2.10279970703125	0.00783024447948387	300.003494262695
-2.05300537109375	0.00629175645853774	300.002365112305
-2.00344931640625	0.00439031504464986	300.003509521484
-1.9536498046875	0.00233323392088246	300.003311157227
-1.90380673828125	0.0009123276301906919	300.003952026367
-1.85400810546875	-0.0007794861680592459	300.001968383789
-1.8042033203125	-0.00223644005755031	300.00309753418
-1.75464091796875	-0.00529048596069675	300.003540039063
-1.704851953125	-0.0062757717617053605	300.004196166992
-1.654803125	-0.007707479125910649	300.003219604492
-1.60500068359375	-0.00943374157428533	300.003341674805
-1.55540390625	-0.0112961253359069	300.002243041992
-1.5053490234375	-0.0136649911045361	300.002304077148
-1.45580244140625	-0.0148861332859238	300.001892089844
-1.4059918457031202	-0.017063430708817502	300.002731323242
-1.3564447265625	-0.017958697055457603	300.004028320313
-1.30639799804687	-0.0207814566974913	300.003005981445
-1.25652626953125	-0.0224858187930298	300.001983642578
-1.2070720703125	-0.0231398050338706	300.00032043457
-1.157175390625	-0.025490484178991798	300.002243041992
-1.10679326171875	-0.0274240958177235	300.003356933594
-1.0573449707031202	-0.0289277255948038	300.002777099609
-1.007197265625	-0.0296500300653548	300.001571655273
-0.957051904296875	-0.031644982339407296	300.002578735352
-0.9076568359375	-0.033835145608576096	300.003479003906
-0.857714453125	-0.0347144339477244	300.003524780273
-0.807568530273437	-0.0357679001574471	300.002990722656
-0.757923901367187	-0.036522212630362996	300.001602172852
-0.707481640625	-0.0387489827015906	300.001815795898
-0.658329663085938	-0.0402201294056945	300.002182006836
-0.608133569335938	-0.041147324236433004	300.002731323242
-0.558202856445313	-0.0420801974411471	300.001892089844
-0.5087141357421879	-0.042549250388478205	300.003204345703
-0.45852214355468707	-0.0433751240320188	300.002655029297
-0.408320043945313	-0.0442043491296138	300.003234863281
-0.35887425537109396	-0.0439633516465611	300.002456665039
-0.30866396484375	-0.043611417055947906	300.002334594727
-0.259159875488281	0.0	300.0087890625
-0.19397947387695302	-0.041652834474412904	300.00244140625
-0.143713708496094	-0.0406601356779725	300.002029418945
-0.09397581481933591	-0.0377944969948545	300.002716064453
-0.0440030914306641	-0.0321978397560994	300.002304077148
0.00598215370178223	0.00227991627678795	300.001861572266
0.0561940887451172	0.0277906404948538	300.00178527832
0.121151220703125	0.0353249643239051	300.002456665039
0.170834704589844	0.0389824221222732	300.003128051758
0.22058575439453101	0.0412657599621767	300.00260925293
0.270794348144531	0.042706393406519	300.003143310547
0.320527734375	0.0427986983340779	300.001541137695
0.370618994140625	0.0428208728871215	300.000961303711
0.420867578125	0.0421820495127098	300.002685546875
0.48565295410156206	0.0427070445515703	300.002975463867
0.53539833984375	0.0414766557776825	300.001907348633
0.585643359375	0.0408907044457592	300.00048828125
0.63564150390625	0.0396833761515687	300.003234863281
0.685380200195313	0.0387139539935553	300.001998901367
0.73542060546875	0.036865110240993794	300.001510620117
0.785409887695313	0.0357819756088171	300.003295898438
0.8354064453125	0.034784357260274595	300.001358032227
0.885659375	0.0336663551717752	300.000137329102
0.935415673828125	0.0314723707592153	300.002944946289
0.985407421875	0.0300533469700251	300.00114440918
1.03514956054688	0.0289152896523992	300.002334594727
1.08539248046875	0.027134367407711097	300.001983642578
1.13538129882813	0.024752125252543798	300.001678466797
1.1851318359375	0.0231661124883694	300.001586914063
1.23538071289062	0.022311307959328803	300.002624511719
1.28515219726563	0.0204976102037796	300.001235961914
1.3348955078125	0.0187232261471269	300.002029418945
1.3848794433593798	0.017033865364052	300.001495361328
1.4351330566406202	0.014615887368277401	300.002792358398
1.48486811523438	0.0133909454388167	300.002899169922
1.53486025390625	0.0120576136862338	300.00146484375
1.58485166015625	0.009126146014179529	300.002288818359
1.6346494140625	0.00826362355605109	300.001571655273
1.68512529296875	0.00554381892427317	300.002395629883
1.734871484375	0.00517409668373122	300.001663208008
1.7849322265625	0.0029948273894286003	300.002136230469
1.83465693359375	0.0005687198128421449	300.002075195313
1.88439248046875	-0.00181965109828954	300.003387451172
1.93464697265625	-0.00218504969173583	300.001617431641
1.9846919921875	-0.00422030173082916	300.001235961914
2.03517578125	-0.0068345758057193695	300.001541137695
2.08441416015625	-0.00828540405432592	300.002578735352
2.134723046875	-0.00958866899469275	300.0029296875
2.18471630859375	-0.0119870530185447	300.001861572266
2.23445205078125	-0.0132505051132793	300.003005981445
2.28443974609375	-0.0156329067480156	300.001708984375
2.33447841796875	-0.017192288622547	300.002029418945
2.38447685546875	-0.018553697814786798	300.000595092773
2.43445751953125	-0.020590516816721	300.001007080078
2.48421650390625	-0.022413292129753598	300.00163269043
2.53446083984375	-0.024855837353271598	300.001968383789
2.58445654296875	-0.026338761412628	300.001449584961
2.63406962890625	-0.0275821768310437	300.00129699707
2.6845384765625	-0.0303873703128738	300.001892089844
2.7344626953125	-0.031668360284398595	300.001510620117
2.78464521484375	-0.0337938308133231	300.001312255859
2.835578515625	-0.03487595278464781	300.001556396484
2.88500439453125	-0.037184064898835294	300.001831054687
2.93519443359375	-0.0393442061519277	300.000427246094
2.9853802734375	-0.0406177838332233	300.002578735352
3.0355958984375	-0.0424751836081	300.000610351562
3.08578935546875	-0.044338321941403996	300.001892089844
3.1357205078125	-0.0468706435618189	300.000518798828
3.1859251953125	-0.0482872482839551	300.003479003906
3.23613662109375	-0.049338621870710794	300.002899169922
3.286320703125	-0.0515369756551839	300.001983642578
3.3365013671875	-0.053412032621709696	300.001480102539
3.386978515625	-0.0559232615372618	300.002380371094
3.4366583984375	-0.0568891831360937	300.001449584961
3.4868458984375	-0.0584990914364766	300.002487182617
3.5370427734375	-0.0608617264249799	300.002197265625
3.58751484375	-0.0628669587028822	300.000259399414
3.637445703125	-0.0646205156750023	300.001327514648
3.687882421875	-0.0656499236451134	300.001327514648
3.73786171875	-0.06818232094218801	300.001602172852
3.7880357421875	-0.0697677865864274	300.002990722656
3.838224609375	-0.07199983055614119	300.000640869141
3.8883998046875	-0.0738598769747143	300.002166748047
3.9386041015625	-0.0757728700244316	300.001724243164
3.9887896484375	-0.0777765841804936	300.000396728516
4.0389646484375	-0.0794127242004747	300.000869750977
4.0889435546875	-0.0808488168860844	300.001678466797
4.139369140625	-0.0817101677831515	300.002105712891
4.1890439453125	-0.085211366562125	300.002105712891
4.2394822265625	-0.0862579864635165	300.001281738281
4.289686328125	-0.08785493712073951	300.00065612793
4.340095703125	-0.0899157681498367	300.001174926758
4.3900259765625	-0.0923490383612927	300.002182006836
4.44001328125	-0.09525864637296891	300.001937866211
4.49019375	-0.0950294970772078	300.002319335937
4.5406298828125	-0.0976585987181048	300.001098632812
4.590813671875	-0.0996044149845678	299.999847412109
4.64079765625	-0.101049573984117	300.002258300781
4.690728515625	-0.103792448438593	300.001525878906
4.741147265625	-0.104241950277639	300.00146484375
4.791129296875	-0.10702311531728399	300.001495361328
4.841575	-0.108961816869817	300.000793457031
4.89149453125	-0.11110801810208899	300.000885009766
4.9416728515625	-0.112185384481194	300.002532958984
4.99192421875	-0.11481266349428801	299.999633789063
5.0420966796875	-0.116877881935967	300.00048828125
5.09227890625	-0.117863882871564	300.000137329102
5.1422677734375	-0.120843404830924	300.001708984375
5.1926927734375	-0.121176793238457	300.001525878906
5.24293671875	-0.12353366812003	300.002227783203
5.2937390625	-0.125378026923244	300.001815795898
5.3440494140625	-0.12819762289549602	300.001037597656
5.394609375	-0.129070327247025	299.999847412109
5.444912109375	-0.130766938222376	300.001419067383
5.4957544921875	-0.133586783521977	300.001556396484
5.5463083984375	-0.13526262954777998	300.001419067383
5.5968638671875	-0.13700744314829	300.000930786133
5.6474123046875	-0.13843908466245	300.001205444336
5.697730859375	-0.140768362533629	300.000122070313
5.748290625	-0.142952877269761	299.999069213867
5.798830859375	-0.144468151398566	300.002471923828
5.849180078125	-0.14612830999698598	300.000595092773
5.8999912109375	-0.148295212431335	300.00048828125
5.9505490234375	-0.15001214432104099	300.001190185547
6.000844921875	-0.152178384425139	300.000503540039
6.05145703125	-0.153337343892975	300.002944946289
6.1020123046875	-0.155588113169967	300.001617431641
6.1523119140625	-0.159301037324338	300.0009765625
6.2029064453125	-0.159906857647757	300.000595092773
6.253731640625	-0.16170771543298101	300.001358032227
6.3040328125	-0.16318823014497902	299.999816894531
6.3545810546875	-0.164748790723646	300.000793457031
6.4049419921875	-0.16754975987204399	300.000625610352
6.4554951171875	-0.16940244842117	300.001876831055
6.506056640625	-0.170311622683732	300.001342773438
6.556655859375	-0.172259574630372	300.002136230469
6.60721484375	-0.174246690809465	300.0009765625
6.65776015625	-0.176255525762494	300.001922607422
6.708559375	-0.178420143128874	300.00016784668
6.75913046875	-0.17998465084117599	300.000259399414
6.809694140625	-0.183211345675269	300.001831054687
6.859984765625	-0.185397658663396	300.001800537109
6.910590625	-0.18644326817774598	300.001770019531
6.961394921875	-0.187661491738428	300.000946044922
7.01169296875	-0.190145553609078	300.001480102539
7.062240234375	-0.19211704219866899	300.001358032227
7.11281640625	-0.19447926796392798	300.002410888672
7.163117578125	-0.195945438921548	300.001892089844
7.21392265625	-0.197019992060401	300.001342773438
7.2645203125	-0.19979994882219698	300.001831054687
7.314584375	-0.201754168214089	300.000122070313
7.365388671875	-0.203576213096825	300.001052856445
7.415684765625	-0.204911261601902	300.000457763672
7.46654921875	-0.207576239344541	300.00080871582
7.516859765625	-0.209439976427294	300.002182006836
7.567667578125	-0.210431983024048	300.001266479492
7.618016015625	-0.212828855222021	300.000762939453
7.66856484375	-0.21477050966756	300.001266479492
7.719128515625	-0.21704770290321201	300.002395629883
7.7696796875	-0.218371331794002	300.000564575195
7.820298828125	-0.220427719111168	300.000076293945
7.870600390625	-0.222215489052698	299.999984741211
7.921151953125	-0.223809560624842	300.001098632812
7.971756640625	-0.22683183343487198	300.000930786133
8.022562890625	-0.22783830047335601	300.000534057617
8.072613671875	-0.230195972882395	300.001770019531
8.12316328125	-0.233416234770633	300.001022338867
8.173733203125	-0.234197097629166	300.001342773438
8.224275	-0.236593046890531	300.000854492188
8.274837890625	-0.23700680567860102	300.000854492188
8.32569609375	-0.23977921026758198	300.00227355957
8.375995703125	-0.242224558809899	300.000274658203
8.426298828125	-0.24373155462413498	300.000625610352
8.477101953125	-0.24523307741787298	300.000793457031
8.52766484375	-0.24689260189365403	300.001281738281
8.577974609375	-0.249399695573844	300.000061035156
8.6282671875	-0.250435626938664	300.000915527344
8.679363671875	-0.25325712119793603	300.000274658203
8.72941484375	-0.256832430011866	300.000289916992
8.78023203125	-0.257771146247814	300.00048828125
8.83052421875	-0.25924554207227996	300.000946044922
8.881389453125	-0.260079469501363	300.001419067383
8.931690234375	-0.26230160716635204	300.00146484375
8.982238671875	-0.265454100101701	299.999938964844
9.000362109375	-0.268734470399388	300.000228881836