File: data/doubleLayers/dl_2-5/ppms/DD205_5/DD205_5_HYST_100OE_10K.DAT
[Header]
; VSM Data File (default extension .dat)
; Copyright (c) 2003-2013, Quantum Design, Inc. All rights reserved.
TITLE,
FILEOPENTIME,3737910004.55964,06/11/2018,8:21 pm
BYAPP,VSM,1.0,1.0
INFO,DYNACOOL VSM Option Release 1.4.10 Build 1,APPNAME
INFO,Quantum Design Linear Motor Servo Controller,MOTOR_MODULE_NAME
INFO,3101-100 J0,MOTOR_HW_VERSION
INFO,MMC654,MOTOR_SERIAL_NUMBER
INFO,SRV No X-over 01.03.11,MOTOR_SOFTWARE_VERSION
INFO,Quantum Design VSM Detection Module,VSM_MODULE_NAME
INFO,3101-150 F0,VSM_HW_VERSION
INFO,VSM507,VSM_SERIAL_NUMBER
INFO,VSM No X-over 01.02.05 May 20 2008 13:51:47,VSM_SOFTWARE_VERSION
INFO,494,PREAMP_SERIAL_NUMBER
INFO,Quantum Design VSM Oven,OVEN_MODULE_NAME
INFO,3101-201 A1,OVEN_HW_VERSION
INFO,OVB210,OVEN_SERIAL_NUMBER
INFO,01.06.24,OVEN_SOFTWARE_VERSION
INFO,593,COIL_SERIAL_NUMBER
INFO,0,MOMENT_UNITS
INFO,CoFe2O4,SAMPLE_MATERIAL
INFO,,SAMPLE_COMMENT
INFO,,SAMPLE_MASS
INFO,,SAMPLE_VOLUME
INFO,,SAMPLE_MOLECULAR_WEIGHT
INFO,,SAMPLE_SIZE
INFO,,SAMPLE_SHAPE
DATATYPE,COMMENT,1
DATATYPE,TIME,2
STARTUPAXIS,X,2
STARTUPAXIS,Y1,5
[Data]
Comment,Time Stamp (sec),Temperature (K),Magnetic Field (Oe),Moment (emu),M. Std. Err. (emu),Transport Action,Averaging Time (sec),Frequency (Hz),Peak Amplitude (mm),Center Position (mm),Coil Signal' (mV),Coil Signal" (mV),Range (mV),M. Quad. Signal (emu),M. Raw' (emu),M. Raw" (emu),Min. Temperature (K),Max. Temperature (K),Min. Field (Oe),Max. Field (Oe),Mass (grams),Motor Lag (deg),Pressure (Torr),VSM Status (code),Motor Status (code),Measure Status (code),Measure Count,System Temp. (K),Temp. Status (code),Field Status (code),Chamber Status (code),Motor Current (amps),Motor Heatsink Temp. (C),Map 01,Map 02,Map 03,Map 04,Map 05,Map 06,Map 07,Map 08,Map 09,Map 10,Map 11,Map 12,Map 13,Map 14,Map 15,Map 16
,3737910516.193,9.99728298187256,-0.65933758020401,6.53426145371718E-5,4.58645758631781E-7,1,0.999253354069792,40.0298881530762,1.99780507353963,16.1799993366003,0.000699057669490218,0.000129803898347815,0.25,3.93279087010963E-7,6.49528435601905E-5,7.05831256363881E-7,9.99950122833252,9.99950122833252,-0.725876212120056,-0.592798948287964,54.7991938547558,19.7110516528887,6.31059646606445,0,0,0,40,9.99976348876953,1,4,1,2.16567993164062,44.4770278930664,,,,,,,,,,,,,,,,
,3737910607.158,10.0002799034119,4131.5,4.64416583970826E-5,2.6190218088826E-7,1,0.999253354069792,40.0298881530762,1.99794276960257,16.1700006574392,0.00049856762347749,8.35087574785413E-5,0.25,-5.51032577372072E-7,4.61789409616316E-5,-3.12633887912171E-7,10.0003252029419,10.0003252029419,4109.03125,4153.96875,54.4724731337173,19.7147245518126,6.31946992874146,0,0,0,40,10.0091514587402,1,6,1,2.16323852539062,44.4770278930664,,,,,,,,,,,,,,,,
,3737910691.0835,10.0008220672607,8325.90087890625,3.16640818985571E-5,2.47969312860506E-7,1,0.999253354069792,40.0298881530762,1.99783442861838,16.1700006574392,0.000340818698000914,5.24675046559898E-5,0.25,-8.03766282877648E-7,3.14968331553357E-5,-6.29402407870745E-7,10.0007963180542,10.0007963180542,8298.4599609375,8353.341796875,54.891426020025,19.7112221420876,6.32279205322266,0,0,0,40,10.0085325241089,1,6,1,2.14645385742187,44.4770278930664,,,,,,,,,,,,,,,,
,3737910775.0345,10.0004353523254,12523.4038085938,1.73834152712092E-5,2.49952826786583E-7,1,0.999253354069792,40.0298881530762,1.99772321587032,16.1700006574392,0.000188485010926648,2.14887773105072E-5,0.25,-1.1300534042199E-6,1.73016028617582E-5,-1.02560943921966E-6,10.0006237030029,10.0006237030029,12498.4580078125,12548.349609375,54.5897174116019,19.7113716085543,6.32529067993164,0,0,0,40,10.0069789886475,1,6,1,2.16659545898438,42.0332374572754,,,,,,,,,,,,,,,,
,3737910858.948,10.0004601478577,16720.5400390625,4.36971155241788E-6,2.46782861448222E-7,1,0.999253354069792,40.0298881530762,1.99764091702381,16.1700006574392,4.78841864094696E-5,2.70683076048953E-6,0.25,-5.36931326823579E-7,4.35238483748942E-6,-5.0829230413107E-7,10.0004987716675,10.0004987716675,16693.119140625,16747.9609375,54.7225942598712,19.7086453125347,6.32488870620728,0,0,0,40,10.0053653717041,1,6,1,2.15621948242187,44.4770278930664,,,,,,,,,,,,,,,,
,3737910942.885,10.0002608299255,20918.4111328125,-7.75532982947486E-6,2.50919762739779E-7,1,0.999253354069792,40.0298881530762,1.99774623114895,16.1799993366003,-8.1556541136302E-5,-2.39809545085789E-5,0.25,-8.32785547410187E-7,-7.71678995540327E-6,-8.77713209005737E-7,10.0001497268677,10.0001497268677,20893.3828125,20943.439453125,54.2458008631404,19.7162341748068,6.32503080368042,0,0,0,40,10.005913734436,1,6,1,2.15240478515625,44.9657897949219,,,,,,,,,,,,,,,,
,3737911026.821,10.0000448226929,25116.3779296875,-1.94848515106522E-5,3.09310209287164E-7,1,0.999253354069792,40.0298881530762,1.99772698879421,16.1700006574392,-0.000206332773637573,-5.28421154208926E-5,0.25,-1.39464517033097E-6,-1.94002380163345E-5,-1.5160239941269E-6,10.000057220459,10.000057220459,25093.84375,25138.912109375,54.6585007212942,19.7135082962817,6.32509708404541,0,0,0,40,10.0065355300903,1,6,1,2.1636962890625,44.4770278930664,,,,,,,,,,,,,,,,
,3737911110.775,9.99982786178589,29326.1103515625,-3.0782940386876E-5,2.56053832892233E-7,1,0.999253354069792,40.0298881530762,1.99766316899345,16.1700006574392,-0.000327524726685773,-7.56659646610259E-5,0.25,-1.46514784789579E-6,-3.06671523017748E-5,-1.66728495656587E-6,9.99987983703613,9.99987983703613,29301.033203125,29351.1875,54.5647052989865,19.7148869409858,6.32593297958374,0,0,0,40,10.0084419250488,1,6,1,2.16278076171875,45.4545478820801,,,,,,,,,,,,,,,,
,3737911194.7075,9.99953699111938,33537.337890625,-4.26239898431005E-5,3.16519594949056E-7,1,0.999253354069792,40.0298881530762,1.99754808454263,16.1799993366003,-0.000454419224045694,-0.000100769101525331,0.25,-1.64407457181154E-6,-4.24848549930752E-5,-1.93420796963629E-6,9.99936771392822,9.99936771392822,33512.2578125,33562.41796875,54.4513691636981,19.7123141592727,6.33076095581055,0,0,0,40,10.0101928710938,1,6,1,2.16659545898438,44.4770278930664,,,,,,,,,,,,,,,,
,3737911278.6395,9.9996018409729,37751.666015625,-5.40579234680769E-5,3.31302030621063E-7,1,0.999253354069792,40.0298881530762,1.99764278410583,16.1700006574392,-0.000578030927682152,-0.000119988129682828,0.25,-1.34343577676056E-6,-5.39105610079385E-5,-1.72288353612574E-6,9.99951457977295,9.99951457977295,37724.08203125,37779.25,55.0883964068712,19.7110758516882,6.33661890029907,0,0,0,40,10.0136680603027,1,6,1,2.16171264648438,44.4770278930664,,,,,,,,,,,,,,,,
,3737911362.548,9.99895524978638,41962.50390625,-6.61873389889466E-5,2.56911696577825E-7,1,0.999253354069792,40.0298881530762,1.99766419715573,16.1700006574392,-0.000708842978265355,-0.00014261945879511,0.25,-1.23099070123183E-6,-6.6039168129966E-5,-1.70569050988373E-6,9.99909114837646,9.99909114837646,41939.89453125,41985.11328125,54.3716430547365,19.7139556684714,6.33581447601318,0,0,0,40,10.0161790847778,1,6,1,2.16339111328125,44.9657897949219,,,,,,,,,,,,,,,,
,3737911446.4975,9.99907064437866,46176.32421875,-7.87263551032941E-5,3.26988994726849E-7,1,0.999253354069792,40.0298881530762,1.99732465763102,16.1700006574392,-0.000843468885832754,-0.000169122402148857,0.25,-1.40430166437044E-6,-7.85850853539555E-5,-1.97741222184554E-6,9.99911594390869,9.99911594390869,46151.203125,46201.4453125,55.2486302533135,19.710231552041,6.33684730529785,0,0,0,40,10.0194892883301,1,6,1,2.1661376953125,44.4770278930664,,,,,,,,,,,,,,,,
,3737911530.425,9.99907636642456,50392.6484375,-9.09026343432508E-5,3.25211380426688E-7,1,0.999253354069792,40.0298881530762,1.99753352039078,16.1700006574392,-0.000974720104694486,-0.000193859262114923,0.25,-1.47369990564141E-6,-9.07797792973024E-5,-2.1426632981967E-6,9.99915313720703,9.99915313720703,50367.60546875,50417.69140625,54.6350518657173,19.7116956344828,6.33654880523682,0,0,0,40,10.0236825942993,1,6,1,2.16598510742187,44.9657897949219,,,,,,,,,,,,,,,,
,3737911614.388,9.99943208694458,54625.203125,-0.000103358883230628,3.37764133360381E-7,1,0.999253354069792,40.0298881530762,1.99744930163061,16.1799993366003,-0.00110829846626627,-0.000222759384848288,0.25,-1.88077838202487E-6,-0.000103261270927142,-2.64641120120966E-6,9.99948501586914,9.99948501586914,54602.48828125,54647.91796875,54.7014902898519,19.7106505744294,6.33643865585327,0,0,0,40,10.0286865234375,1,6,1,2.16629028320313,44.9657897949219,,,,,,,,,,,,,,,,
,3737911698.315,9.99899959564209,58870.248046875,-0.00011637438024459,3.99965855069203E-7,1,0.999253354069792,40.0298881530762,1.99754757245269,16.1700006574392,-0.00124917219515898,-0.000246860167790431,0.25,-1.73812536963188E-6,-0.000116315001915378,-2.60337171667042E-6,9.99907493591309,9.99907493591309,58845.15625,58895.33984375,54.6131662671789,19.709931309275,6.33263683319092,0,0,0,40,10.0327768325806,1,6,1,2.16400146484375,44.4770278930664,,,,,,,,,,,,,,,,
,3737911782.269,9.99917936325073,63115.224609375,-0.000129978405686212,3.41847768275138E-7,1,0.999253354069792,40.0298881530762,1.99744035107655,16.1700006574392,-0.00139638083144824,-0.000271960401349984,0.25,-1.58434084257928E-6,-0.000129966096415969,-2.55106573829118E-6,9.99922466278076,9.99922466278076,63092.48828125,63137.9609375,54.7663654569481,19.7118703877957,6.33650922775269,0,0,0,40,10.0385837554932,1,6,1,2.16064453125,44.4770278930664,,,,,,,,,,,,,,,,
,3737911866.18,9.99921941757202,67360.4375,-0.000142941023244416,4.01215646112166E-7,1,0.999253354069792,40.0298881530762,1.99746751859519,16.1700006574392,-0.00153640036849298,-0.000298331351879084,0.25,-1.6653909314029E-6,-0.000142982236204088,-2.72587616254697E-6,9.99910068511963,9.99910068511963,67335.140625,67385.734375,55.0829250072366,19.7126463606386,6.3390645980835,0,0,0,40,10.0437831878662,1,6,1,2.14385986328125,44.9657897949219,,,,,,,,,,,,,,,,
,3737911950.1195,9.99934339523315,71602.52734375,-0.000155982310246533,3.98379070442091E-7,1,0.999253354069792,40.0298881530762,1.99742417541291,16.1799993366003,-0.00167640640927699,-0.000329722790814835,0.25,-2.20098847909736E-6,-0.00015608090447498,-3.35291367954908E-6,9.99932670593262,9.99932670593262,71577.2109375,71627.84375,54.6217641808904,19.7149243799022,6.34162855148315,0,0,0,40,10.0502223968506,1,6,1,2.16415405273438,44.4770278930664,,,,,,,,,,,,,,,,
,3737912034.046,9.99904537200928,75847.64453125,-0.0001699951544193,4.04846508250552E-7,1,0.999253354069792,40.0298881530762,1.99741160003274,16.1700006574392,-0.00182782287900619,-0.000358386670753358,0.25,-2.30840318255045E-6,-0.000170161923092692,-3.55519719710221E-6,9.99906635284424,9.99906635284424,75824.90625,75870.3828125,55.2384690825635,19.711433951629,6.34211492538452,0,0,0,40,10.0549125671387,1,6,1,2.16171264648438,44.9657897949219,,,,,,,,,,,,,,,,
,3737912117.9755,9.99920272827148,80093.421875,-0.000183726757371535,4.39214939753412E-7,1,0.999253354069792,40.0298881530762,1.99741710676354,16.1700006574392,-0.00197731846500232,-0.000380869937976163,0.25,-1.89621790332493E-6,-0.000183971550189145,-3.23126411997665E-6,9.99931049346924,9.99931049346924,80068.203125,80118.640625,54.4568405633327,19.7099789081114,6.34606790542602,0,0,0,40,10.0621004104614,1,6,1,2.15103149414062,45.4545478820801,,,,,,,,,,,,,,,,
,3737912201.9595,9.99865245819092,84337.8984375,-0.000197762420675819,4.62277338786321E-7,1,0.999253354069792,40.0298881530762,1.99748517086201,16.1700006574392,-0.00212754272202172,-0.000418676077794193,0.25,-2.85149549177812E-6,-0.000198081438697978,-4.27506067575622E-6,9.99857521057129,9.99857521057129,84310.1171875,84365.6796875,54.9226911607943,19.7096190937065,6.3476095199585,0,0,0,40,10.0679960250854,1,6,1,2.16552734375,43.9882698059082,,,,,,,,,,,,,,,,
,3737912285.864,9.99862146377564,88582.93359375,-0.000211177667139209,3.86270119167244E-7,1,0.999253354069792,40.0298881530762,1.99725849449937,16.1700006574392,-0.00227352452980645,-0.000440336513696669,0.25,-2.43132017374278E-6,-0.000211584683466596,-3.93268703456966E-6,9.99868011474609,9.99868011474609,88557.6484375,88608.21875,54.7382268302558,19.7146368380858,6.35041809082031,0,0,0,40,10.0729808807373,1,6,1,2.15286254882813,44.9657897949219,,,,,,,,,,,,,,,,
,3737912379.829,10.0009775161743,87328.62109375,-0.000207048936811067,5.2839218968638E-7,1,0.999253354069792,40.0298881530762,1.99736833364042,16.1700006574392,-0.00222993169842135,-0.000426604077163896,0.25,-1.90454295213105E-6,-0.000207433814255542,-3.38094091758232E-6,10.0008430480957,10.0008430480957,87301.140625,87356.1015625,55.1720306584289,19.7145394128589,6.35260438919067,0,0,0,40,10.0727958679199,1,6,1,2.159423828125,44.4770278930664,,,,,,,,,,,,,,,,
,3737912463.7815,10.0011377334595,83145.82421875,-0.000192871782533289,4.54703633420487E-7,1,0.999253354069792,40.0298881530762,1.99723678021185,16.1700006574392,-0.00207434772693604,-0.000409114223848469,0.25,-2.85757363371284E-6,-0.00019316587305581,-4.25025363047111E-6,10.0011615753174,10.0011615753174,83120.9453125,83170.703125,54.6287988375635,19.7116614449517,6.35736989974976,0,0,0,40,10.066427230835,1,6,1,2.15682983398438,44.9657897949219,,,,,,,,,,,,,,,,
,3737912547.637,10.0010161399841,78966.08203125,-0.0001801671982466,4.2031462994695E-7,1,0.999253354069792,40.0298881530762,1.99745738474413,16.1700006574392,-0.00193874883579902,-0.000374197178018236,0.25,-1.9237231903613E-6,-0.00018039141838807,-3.23626995973209E-6,10.0009241104126,10.0009241104126,78941.1875,78990.9765625,54.7562042861981,19.7150080101961,6.35906744003296,0,0,0,40,10.0620603561401,1,6,1,2.16552734375,44.9657897949219,,,,,,,,,,,,,,,,
,3737912631.5845,10.0007877349854,74783.0234375,-0.000166317890294993,4.87409660453858E-7,1,0.999253354069792,40.0298881530762,1.99744554377514,16.1799993366003,-0.00178857700962744,-0.00034832799836164,0.25,-2.04412195424029E-6,-0.000166468503445969,-3.2660456778326E-6,10.0007877349854,10.0007877349854,74760.6953125,74805.3515625,54.7100882035635,19.7141108425209,6.36047267913818,0,0,0,40,10.0555286407471,1,6,1,2.16064453125,44.9657897949219,,,,,,,,,,,,,,,,
,3737912715.5225,10.0013365745544,70600.07421875,-0.00015250307954681,4.02547058262282E-7,1,0.999253354069792,40.0298881530762,1.99758571049847,16.1700006574392,-0.00163869897929178,-0.000324031378181661,0.25,-2.30470172795371E-6,-0.000152585534835241,-3.43251373025628E-6,10.0013589859009,10.0013589859009,70575.2578125,70624.890625,54.7327554306212,19.7139069706684,6.36083221435547,0,0,0,40,10.0503129959106,1,6,1,2.15621948242187,44.9657897949219,,,,,,,,,,,,,,,,
,3737912799.47,10.0010280609131,66417.8515625,-0.000139861444573293,3.74186895506835E-7,1,0.999253354069792,40.0298881530762,1.99763020203884,16.1700006574392,-0.00150250668640011,-0.000296212809065364,0.25,-2.02866464418506E-6,-0.00013988723757907,-3.06721626290265E-6,10.0010442733765,10.0010442733765,66390.515625,66445.1875,54.6452130364673,19.7158159857042,6.36103057861328,0,0,0,40,10.0439872741699,1,6,1,2.15682983398438,44.4770278930664,,,,,,,,,,,,,,,,
,3737912883.402,10.0005216598511,62235.130859375,-0.000126141967744693,3.12181134189395E-7,1,0.999253354069792,40.0298881530762,1.99741918008166,16.1799993366003,-0.00135453947799839,-0.000266670488845103,0.25,-1.7936719913835E-6,-0.000126117946059435,-2.73201869497856E-6,10.0005826950073,10.0005826950073,62210.20703125,62260.0546875,54.6061316105058,19.7129633730683,6.36132621765137,0,0,0,40,10.0394983291626,1,6,1,2.16445922851562,44.9657897949219,,,,,,,,,,,,,,,,
,3737912967.3715,10.0004467964172,58051.740234375,-0.000113569838414747,4.08378296524103E-7,1,0.999253354069792,40.0298881530762,1.99738069497687,16.1700006574392,-0.00121860405249636,-0.000242366831274764,0.25,-1.83518024089765E-6,-0.000113502006058713,-2.679169941363E-6,10.0003843307495,10.0003843307495,58029.3046875,58074.17578125,54.7734001136212,19.7148700438066,6.36144065856934,0,0,0,40,10.0341901779175,1,6,1,2.15896606445313,44.4770278930664,,,,,,,,,,,,,,,,
,3737913051.2685,10.0019207000732,53872.359375,-0.000100294818417869,3.19195010841777E-7,1,0.999253354069792,40.0298881530762,1.99723278079888,16.1700006574392,-0.00107571909798958,-0.000213554893061492,0.25,-1.58732635165671E-6,-0.000100194428583857,-2.32975294068402E-6,10.0019226074219,10.0019226074219,53849.8671875,53894.8515625,54.7663654569481,19.7136224433103,6.36449098587036,0,0,0,40,10.0294170379639,1,6,1,2.16232299804687,44.4770278930664,,,,,,,,,,,,,,,,
,3737913135.246,10.0005884170532,49687.970703125,-8.76963285912961E-5,3.09535223564914E-7,1,0.999253354069792,40.0298881530762,1.99713977416751,16.1700006574392,-0.000939776288355973,-0.000188731416384864,0.25,-1.58607003166404E-6,-8.75703378512365E-5,-2.23026903633869E-6,10.0006113052368,10.0006113052368,49665.5703125,49710.37109375,54.8531262225827,19.7133033836228,6.36526679992676,0,0,0,40,10.0244874954224,1,6,1,2.147216796875,43.9882698059082,,,,,,,,,,,,,,,,
,3737913219.1545,10.0006475448608,45507.48046875,-7.53503149726727E-5,3.39188292293092E-7,1,0.999253354069792,40.0298881530762,1.99734725680795,16.1799993366003,-0.000806518884414736,-0.000165882183708198,0.25,-1.71925324449636E-6,-7.52071532665193E-5,-2.26601609328547E-6,10.0007400512695,10.0007400512695,45480.015625,45534.9453125,54.8023203688327,19.7166940484764,6.36771965026855,0,0,0,40,10.020055770874,1,6,1,2.16522216796875,43.9882698059082,,,,,,,,,,,,,,,,
,3737913303.113,10.0009641647339,41325.41796875,-6.33166361393593E-5,3.51306498154655E-7,1,0.999253354069792,40.0298881530762,1.99723789031771,16.1700006574392,-0.000678307285505422,-0.000134244211208207,0.25,-9.78301090036687E-7,-6.31720944790223E-5,-1.43165998518207E-6,10.0007963180542,10.0007963180542,41300.53515625,41350.30078125,54.5740848412173,19.7133319773918,6.36981391906738,0,0,0,40,10.0173511505127,1,6,1,2.15835571289062,44.4770278930664,,,,,,,,,,,,,,,,
,3737913387.0265,10.0010180473328,37143.044921875,-5.10549184750996E-5,2.83212066510163E-7,1,0.999253354069792,40.0298881530762,1.99730428174441,16.1700006574392,-0.000545306488975636,-0.000115997120139915,0.25,-1.52129497260613E-6,-5.09106879015637E-5,-1.8778408583015E-6,10.0007514953613,10.0007514953613,37120.53125,37165.55859375,54.7077433180058,19.7134160321451,6.37403631210327,0,0,0,40,10.0146760940552,1,6,1,2.16278076171875,43.9882698059082,,,,,,,,,,,,,,,,
,3737913470.9465,10.0007200241089,32960.38671875,-3.87827269440154E-5,3.02239152340072E-7,1,0.999253354069792,40.0298881530762,1.99726012862992,16.1700006574392,-0.000414245669791624,-8.69326179424813E-5,0.25,-1.05554040973831E-6,-3.86568355105423E-5,-1.31983501034936E-6,10.000828742981,10.000828742981,32935.5546875,32985.21875,54.8734485640827,19.7159841290549,6.37802743911743,0,0,0,40,10.0113945007324,1,6,1,2.15789794921875,43.9882698059082,,,,,,,,,,,,,,,,
,3737913554.946,9.99946880340576,28775.4921875,-2.6856776589296E-5,2.42988832467065E-7,1,0.999253354069792,40.0298881530762,1.99743242167614,16.1700006574392,-0.000285654831767075,-6.62726482482415E-5,0.25,-1.30401887915032E-6,-2.67540733524448E-5,-1.47947345687122E-6,9.99948215484619,9.99948215484619,28755.60546875,28795.37890625,54.4435528785058,19.7131414761793,6.38313102722168,0,0,0,40,10.0079984664917,1,6,1,2.15835571289062,43.49951171875,,,,,,,,,,,,,,,,
,3737913638.816,10.0006880760193,24596.1240234375,-1.53252623251855E-5,2.99264069480933E-7,1,0.999253354069792,40.0298881530762,1.99727730102061,16.1700006574392,-0.000162551715888057,-3.98420053873277E-5,0.25,-9.38088037400131E-7,-1.52589607203159E-5,-1.03366572115647E-6,10.0007028579712,10.0007028579712,24571.177734375,24621.0703125,54.6186376668135,19.7140439191342,6.38916492462158,0,0,0,40,10.0072336196899,1,6,1,2.16476440429687,43.9882698059082,,,,,,,,,,,,,,,,
,3737913722.7635,10.0012392997742,20416.431640625,-3.55223478614424E-6,3.07705326183232E-7,1,0.999253354069792,40.0298881530762,1.99739974152038,16.1700006574392,-3.61370818423748E-5,-1.7675821776868E-5,0.25,-1.00586164137432E-6,-3.53053406026355E-6,-1.0235935072308E-6,10.0013179779053,10.0013179779053,20391.556640625,20441.306640625,54.0589916470442,19.7109001795626,6.39242649078369,0,0,0,40,10.0057849884033,1,6,1,2.16690063476562,43.49951171875,,,,,,,,,,,,,,,,
,3737913806.736,9.99924993515015,16234.55078125,8.87565051419226E-6,2.53003385360432E-7,1,0.999253354069792,40.0298881530762,1.99747247869022,16.1700006574392,9.70533598337455E-5,6.57808316491224E-6,0.25,-9.89473698026897E-7,8.83942007378551E-6,-9.32032127670025E-7,9.99920749664307,9.99920749664307,16212.2021484375,16256.8994140625,55.1579613450827,19.7158208806794,6.39534997940063,0,0,0,40,10.0055103302002,1,6,1,2.14340209960938,43.49951171875,,,,,,,,,,,,,,,,
,3737913890.6675,9.99983310699463,12048.2319335938,2.18424350221931E-5,2.79495216320644E-7,1,0.999253354069792,40.0298881530762,1.99741972475231,16.1700006574392,0.000235546747092965,3.38842461375281E-5,0.25,-7.76299092898493E-7,2.17350679711202E-5,-6.49056632628486E-7,9.99980735778809,9.99980735778809,12020.791015625,12075.6728515625,54.5201524733904,19.713057665553,6.40003061294556,0,0,0,40,10.0060234069824,1,6,1,2.16094970703125,44.4770278930664,,,,,,,,,,,,,,,,
,3737913974.61,9.99985933303833,7858.96606445313,3.57393654595596E-5,2.599489186114E-7,1,0.999253354069792,40.0298881530762,1.99742289342152,16.1799993366003,0.00038466061952661,5.88351399823834E-5,0.25,-9.40646510460114E-7,3.55494631383649E-5,-7.44858814885328E-7,9.99981498718262,9.99981498718262,7833.9306640625,7884.00146484375,54.1824889530827,19.7123077043104,6.402268409729,0,0,0,40,10.0068483352661,1,6,1,2.15591430664062,43.49951171875,,,,,,,,,,,,,,,,
,3737914058.514,9.99966812133789,3668.88635253906,4.99415808546396E-5,2.52995381105198E-7,1,0.999253354069792,40.0298881530762,1.99744109587785,16.1700006574392,0.000536412619277444,8.74613735551142E-5,0.25,-8.07271084048057E-7,4.96586534046904E-5,-5.51249805826322E-7,9.99967384338379,9.99967384338379,3643.89990234375,3693.87280273438,54.4060347095827,19.7116157356314,6.40702486038208,0,0,0,40,10.0091142654419,1,6,1,2.16522216796875,43.0107536315918,,,,,,,,,,,,,,,,
,3737914148.454,9.99959087371826,-824.415344238281,7.25558894693921E-5,2.62524546970678E-7,1,0.999253354069792,40.0298881530762,1.99728582821064,16.1799993366003,0.000778187504577549,0.000132251391317618,0.25,-6.72717463198247E-7,7.21307251985873E-5,-3.16451068646706E-7,9.99954986572266,9.99954986572266,-849.40283203125,-799.427856445313,54.078532360025,19.7134694911115,6.41348838806152,0,0,0,40,10.0107192993164,1,6,1,2.16415405273438,43.49951171875,,,,,,,,,,,,,,,,
,3737914235.3775,9.99998903274536,-5170.8505859375,8.97406738559726E-5,2.26546027991304E-7,1,0.999253354069792,40.0298881530762,1.99708949789819,16.1700006574392,0.00096198535490819,0.00016737197986626,0.25,-5.05522208650305E-7,8.92364200986221E-5,-4.15065227578846E-8,10.0000076293945,10.0000076293945,-5198.43115234375,-5143.27001953125,54.5037382744865,19.7125831858009,6.4132490158081,0,0,0,40,10.0089931488037,1,6,1,2.16217041015625,43.9882698059082,,,,,,,,,,,,,,,,
,3737914322.298,10.0001945495605,-9518.83154296875,0.00010076153607189,2.59597483463364E-7,1,0.999253354069792,40.0298881530762,1.99718697737765,16.1700006574392,0.00108075649447708,0.000186738597276664,0.25,-7.17185322242849E-7,0.000100228922016854,-1.63473175256451E-7,10.0002155303955,10.0002155303955,-9543.7294921875,-9493.93359375,55.3432073041405,19.7156935549254,6.41420269012451,0,0,0,40,10.007926940918,1,6,1,2.14920043945313,43.9882698059082,,,,,,,,,,,,,,,,
,3737914406.2495,10.0002207756042,-13718.66796875,0.000105460048873488,2.99170132461891E-7,1,0.999253354069792,40.0298881530762,1.997105740216,16.1700006574392,0.0011315112062666,0.000195528094431625,0.25,-7.8121410879912E-7,0.000104940263227803,-1.69370654916459E-7,10.0002517700195,10.0002517700195,-13743.599609375,-13693.736328125,54.7687103425058,19.7144615848156,6.41364622116089,0,0,0,40,10.0064964294434,1,6,1,2.14279174804687,43.9882698059082,,,,,,,,,,,,,,,,
,3737914490.264,10.0006952285767,-17918.1611328125,0.000102073039871555,2.84186392678406E-7,1,0.999253354069792,40.0298881530762,1.99720820602174,16.1700006574392,0.0010957336763527,0.00018887742990612,0.25,-8.28339461070131E-7,0.000101609820876958,-2.06158167786608E-7,10.0006847381592,10.0006847381592,-17943.11328125,-17893.208984375,54.5709583271404,19.7180619046318,6.41707420349121,0,0,0,40,10.0071983337402,1,6,1,2.16171264648438,43.9882698059082,,,,,,,,,,,,,,,,
,3737914574.2015,9.99948406219482,-22115.4775390625,8.95709100642687E-5,2.76006037482633E-7,1,0.999253354069792,40.0298881530762,1.99723163100014,16.1700006574392,0.000961245986019492,0.000169615625010631,0.25,-3.96496613863854E-7,8.91990606329254E-5,1.72090429634826E-7,9.99946594238281,9.99946594238281,-22137.9921875,-22092.962890625,54.9164381326404,19.7165513810674,6.41335678100586,0,0,0,40,10.0056047439575,1,6,1,2.1649169921875,44.4770278930664,,,,,,,,,,,,,,,,
,3737914658.0565,9.9996657371521,-26308.837890625,7.46702865315372E-5,2.13541117443731E-7,1,0.999253354069792,40.0298881530762,1.99702166490651,16.1700006574392,0.000802036157859388,0.00013904683661423,0.25,-5.72259704402959E-7,7.43936985937649E-5,-7.92827234007571E-8,9.99983501434326,9.99983501434326,-26333.927734375,-26283.748046875,54.5584522708327,19.7164595075776,6.41186475753784,0,0,0,40,10.0066270828247,1,6,1,2.15164184570313,43.9882698059082,,,,,,,,,,,,,,,,
,3737914742.009,10.0003228187561,-30521.4423828125,6.54896829618292E-5,2.3733290775638E-7,1,0.999253354069792,40.0298881530762,1.9971583071559,16.1700006574392,0.000703616462533152,0.000122940469135489,0.25,-4.29421449449073E-7,6.52754537592116E-5,1.65515581417838E-8,10.0002603530884,10.0002603530884,-30544.115234375,-30498.76953125,54.7968489691981,19.7183352,6.41071271896362,0,0,0,40,10.0091695785522,1,6,1,2.16171264648438,44.9657897949219,,,,,,,,,,,,,,,,
,3737914825.9685,9.99945306777954,-34736.33203125,6.31438055442537E-5,3.11335677817289E-7,1,0.999253354069792,40.0298881530762,1.99725011210256,16.1700006574392,0.000678834169179348,0.000118116201289214,0.25,-4.70057553655778E-7,6.29658538073191E-5,-2.85164204670453E-8,9.99947643280029,9.99947643280029,-34763.8828125,-34708.78125,54.9781867856597,19.7135805171075,6.4113621711731,0,0,0,40,10.0107259750366,1,6,1,2.15835571289062,44.4770278930664,,,,,,,,,,,,,,,,
,3737914909.903,9.9989128112793,-38946.599609375,6.70826635458394E-5,3.69958955196924E-7,1,0.999253354069792,40.0298881530762,1.99741101804185,16.1700006574392,0.000721924337065714,0.00012354260367086,0.25,-6.96238064454872E-7,6.69250635291942E-5,-2.16768142278112E-7,9.99878406524658,9.99878406524658,-38974.34375,-38918.85546875,54.3763328258519,19.7166688093194,6.41140031814575,0,0,0,40,10.0137577056885,1,6,1,2.1478271484375,44.4770278930664,,,,,,,,,,,,,,,,
,3737914993.801,9.99954748153687,-43159.03125,7.39539762908788E-5,3.55010706300228E-7,1,0.999253354069792,40.0298881530762,1.99702101785859,16.1799993366003,0.000795986118906914,0.000136748143419014,0.25,-7.28234335920401E-7,7.38129120817943E-5,-1.91209078335566E-7,9.99941444396973,9.99941444396973,-43184.0546875,-43134.0078125,54.9039320763327,19.7149275121303,6.41074323654175,0,0,0,40,10.0181922912598,1,6,1,2.16690063476562,44.4770278930664,,,,,,,,,,,,,,,,
,3737915077.7825,10.0000743865967,-47371.12890625,8.42690658785495E-5,3.58654618789559E-7,1,0.999253354069792,40.0298881530762,1.9971632884122,16.1799993366003,0.000906918837377889,0.000158935119659669,0.25,-5.54861174386772E-7,8.41433100488859E-5,6.38562749926791E-8,10.0000104904175,10.0000104904175,-47398.67578125,-47343.58203125,54.5537624997173,19.7158753385612,6.40880155563354,0,0,0,40,10.0214738845825,1,6,1,2.15087890625,44.4770278930664,,,,,,,,,,,,,,,,
,3737915161.6925,9.99917697906494,-51584.1796875,9.49230866655435E-5,3.86737137845229E-7,1,0.999253354069792,40.0298881530762,1.99716453260526,16.1700006574392,0.00102231548004015,0.000177481517833369,0.25,-7.81669738306003E-7,9.48233426239946E-5,-7.89536456079008E-8,9.99917030334473,9.99917030334473,-51609.23046875,-51559.12890625,54.7444798584096,19.7113923078172,6.41175651550293,0,0,0,40,10.0253229141235,1,6,1,2.16323852539062,43.9882698059082,,,,,,,,,,,,,,,,
,3737915245.6425,9.9989709854126,-55824.740234375,0.000107207672861532,4.10195039954204E-7,1,0.999253354069792,40.0298881530762,1.99716433197974,16.1700006574392,0.00115364171008207,0.00020857052853185,0.25,-1.39433210298764E-7,0.000107134524970445,6.57208326186635E-7,9.99903011322022,9.99903011322022,-55847.46875,-55802.01171875,54.5475094715635,19.7162224522374,6.41263055801392,0,0,0,40,10.0303220748901,1,6,1,2.16293334960938,44.4770278930664,,,,,,,,,,,,,,,,
,3737915329.545,9.99893522262573,-60063.38671875,0.000119565416909065,3.88193660451589E-7,1,0.999253354069792,40.0298881530762,1.99719083373477,16.1700006574392,0.0012872076040558,0.00023244555275078,0.25,-1.81145294604832E-7,0.000119532513211379,7.0873230232714E-7,9.99887657165527,9.99887657165527,-60088.62109375,-60038.15234375,54.4474610211019,19.7214756765883,6.41257286071777,0,0,0,40,10.0348300933838,1,6,1,2.14187622070313,44.4770278930664,,,,,,,,,,,,,,,,
,3737915413.509,9.99829387664795,-64310.27734375,0.000133128774439922,4.453479176225E-7,1,0.999253354069792,40.0298881530762,1.99697986575054,16.1700006574392,0.00143282298319587,0.000263390901627774,0.25,2.18068096880683E-7,0.000133141034737277,1.20764280483109E-6,9.99829959869385,9.99829959869385,-64335.515625,-64285.0390625,54.4412079929481,19.7152724983852,6.41345596313477,0,0,0,40,10.0401401519775,1,6,1,2.15728759765625,44.4770278930664,,,,,,,,,,,,,,,,
,3737915497.536,9.99984836578369,-68559.296875,0.000145795400331397,4.4741675468336E-7,1,0.999253354069792,40.0298881530762,1.99703333354604,16.1700006574392,0.00157051357320433,0.000284521173295078,0.25,-1.32305835618106E-7,0.000145866158100733,9.47242925051995E-7,9.99986934661865,9.99986934661865,-68582.0078125,-68536.5859375,54.7304105450635,19.7190662441686,6.41178607940674,0,0,0,40,10.0466299057007,1,6,1,2.16110229492187,45.4545478820801,,,,,,,,,,,,,,,,
,3737915581.3895,9.99878454208374,-72800.5625,0.000158946997632243,3.81935625056144E-7,1,0.999253354069792,40.0298881530762,1.99701634706251,16.1700006574392,0.00171182732763751,0.000315519888450522,0.25,3.48237105540349E-7,0.000159077167557897,1.51845436278717E-6,9.99869632720947,9.99869632720947,-72828.3359375,-72772.7890625,54.9508297874866,19.7188013012301,6.41387796401978,0,0,0,40,10.0524158477783,1,6,1,2.16354370117187,44.4770278930664,,,,,,,,,,,,,,,,
,3737915665.3855,9.99966764450073,-77043.7421875,0.000172843163788149,3.59423477942405E-7,1,0.999253354069792,40.0298881530762,1.99705660038321,16.1700006574392,0.00186184176778217,0.000344933134965216,0.25,5.47510660156009E-7,0.000173042127038037,1.81021154660954E-6,9.99974822998047,9.99974822998047,-77074.1015625,-77013.3828125,54.9226911607943,19.7153228216875,6.41805219650269,0,0,0,40,10.0581960678101,1,6,1,2.1502685546875,44.9657897949219,,,,,,,,,,,,,,,,
,3737915749.2715,9.99952220916748,-81284.80078125,0.000186932676676151,4.09172915086843E-7,1,0.999253354069792,40.0298881530762,1.99695655934302,16.1700006574392,0.00201378559742694,0.000375222669295981,0.25,7.9779178852319E-7,0.000187206520234793,2.15068805406501E-6,9.99956321716309,9.99956321716309,-81310.125,-81259.4765625,55.0078886693904,19.7156065933004,6.41891574859619,0,0,0,40,10.063961982727,1,6,1,2.16156005859375,44.9657897949219,,,,,,,,,,,,,,,,
,3737915833.211,9.99799633026123,-85528.3671875,0.000200235054373807,3.31783407931053E-7,1,0.999253354069792,40.0298881530762,1.99698967362327,16.1700006574392,0.0021578636790312,0.000401584296544598,0.25,8.2778268323193E-7,0.000200589612032573,2.26094693560523E-6,9.99806022644043,9.99806022644043,-85556.125,-85500.609375,54.9109667330058,19.7192409136858,6.42701196670532,0,0,0,40,10.068793296814,1,6,1,2.16400146484375,44.4770278930664,,,,,,,,,,,,,,,,
,3737915917.1095,9.99941492080689,-89766.43359375,0.000214756795179631,4.37160500955192E-7,1,0.999253354069792,40.0298881530762,1.99689707646249,16.1700006574392,0.00231484575140238,0.00043122331464899,0.25,9.4542837328852E-7,0.000215198423202959,2.46373181625555E-6,9.99938678741455,9.99938678741455,-89791.6796875,-89741.1875,54.9688072434289,19.7203639825587,6.42896938323975,0,0,0,40,10.0760641098022,1,6,1,2.14920043945313,44.9657897949219,,,,,,,,,,,,,,,,
,3737916010.0735,10.0005226135254,-86129.2890625,0.000202438128866498,3.77690955550044E-7,1,0.999253354069792,40.0298881530762,1.99691716738581,16.1799993366003,0.00218144748374887,0.000406959654575041,0.25,9.27876521749205E-7,0.000202804397357753,2.37454439393778E-6,10.0005931854248,10.0005931854248,-86151.7109375,-86106.8671875,54.7132147176404,19.7221139836658,6.43122339248657,0,0,0,40,10.0711784362793,1,6,1,2.144775390625,44.4770278930664,,,,,,,,,,,,,,,,
,3737916094.0545,10.0004844665527,-81948.578125,0.000189470590897383,3.90546507555384E-7,1,0.999253354069792,40.0298881530762,1.9969948484676,16.1700006574392,0.00204192211509933,0.000376716161169707,0.25,4.74645600915103E-7,0.00018975981065662,1.84315098017633E-6,10.0003786087036,10.0003786087036,-81973.4453125,-81923.7109375,54.8445283088712,19.7239728235192,6.42948150634766,0,0,0,40,10.0661640167236,1,6,1,2.16156005859375,44.9657897949219,,,,,,,,,,,,,,,,
,3737916177.9005,10.0010213851929,-77769.2421875,0.000175285348968728,4.23363873278102E-7,1,0.999253354069792,40.0298881530762,1.99724770312985,16.1700006574392,0.001890176789668,0.000340239551657205,0.25,-3.35007506852401E-7,0.000175503477642491,9.424882153283E-7,10.0010852813721,10.0010852813721,-77794.1640625,-77744.3203125,55.016486583102,19.7256209269459,6.42887020111084,0,0,0,40,10.0603113174438,1,6,1,2.1502685546875,44.4770278930664,,,,,,,,,,,,,,,,
,3737916261.8395,10.0013475418091,-73590.85546875,0.000161764918690367,3.74549097790351E-7,1,0.999253354069792,40.0298881530762,1.99714289295455,16.1700006574392,0.00174107966052487,0.000328367623481827,0.25,1.02557239962519E-6,0.000161902899398974,2.2155568661098E-6,10.0013418197632,10.0013418197632,-73615.7265625,-73565.984375,54.6467762935058,19.7230204955882,6.42844867706299,0,0,0,40,10.0549201965332,1,6,1,2.16293334960938,45.4545478820801,,,,,,,,,,,,,,,,
,3737916345.7845,10.0009684562683,-69407.48046875,0.000148555733416723,3.43775768463468E-7,1,0.999253354069792,40.0298881530762,1.99676973463098,16.1700006574392,0.00159928363726057,0.000294723416687571,0.25,3.14957557216892E-7,0.000148635298832135,1.41404611151959E-6,10.0008878707886,10.0008878707886,-69432.3359375,-69382.625,55.0680740653712,19.7178946950797,6.42859697341919,0,0,0,40,10.0494213104248,1,6,1,2.147216796875,44.9657897949219,,,,,,,,,,,,,,,,
,3737916429.711,10.0005679130554,-65227.810546875,0.000135726961986377,4.10970387748098E-7,1,0.999253354069792,40.0298881530762,1.99705967063796,16.1700006574392,0.00146268740689365,0.000259090433771393,0.25,-6.56795117651596E-7,0.00013575715843611,3.51330466242286E-7,10.0006198883057,10.0006198883057,-65252.703125,-65202.91796875,54.9797500426981,19.7227756018406,6.43257141113281,0,0,0,40,10.0437679290771,1,6,1,2.14447021484375,44.9657897949219,,,,,,,,,,,,,,,,
,3737916513.6645,10.0011539459229,-61043.501953125,0.000122685797462144,2.92463678561169E-7,1,0.999253354069792,40.0298881530762,1.99686754467984,16.1700006574392,0.00132090437922946,0.000237476312213405,0.25,-2.80592587763581E-7,0.000122663977676106,6.32473818615459E-7,10.0011558532715,10.0011558532715,-61068.4453125,-61018.55859375,54.8961157911404,19.7202098895736,6.43745613098145,0,0,0,40,10.0382175445557,1,6,1,2.16201782226562,44.4770278930664,,,,,,,,,,,,,,,,
,3737916597.5895,10.0004372596741,-56864.837890625,0.00010962269629492,2.97297716749748E-7,1,0.999253354069792,40.0298881530762,1.99674064557191,16.1700006574392,0.00117932879992071,0.000214244970558734,0.25,-5.03199157736119E-8,0.000109558272352488,7.64758855506913E-7,10.0004739761353,10.0004739761353,-56889.7734375,-56839.90234375,54.9430135022943,19.7191041097684,6.43593311309814,0,0,0,40,10.0322399139404,1,6,1,2.1453857421875,44.9657897949219,,,,,,,,,,,,,,,,
,3737916681.601,10.0006146430969,-52678.279296875,9.59519215263854E-5,3.4266792324963E-7,1,0.999253354069792,40.0298881530762,1.99688880607121,16.1700006574392,0.0010331771732996,0.000180481027858689,0.25,-6.90785983110277E-7,9.58608793489354E-5,2.04855554675453E-8,10.0005626678467,10.0005626678467,-52705.5390625,-52651.01953125,54.4435528785058,19.7239590624396,6.43445587158203,0,0,0,40,10.0290107727051,1,6,1,2.16262817382813,44.4770278930664,,,,,,,,,,,,,,,,
,3737916765.5315,10.00048828125,-48499.6171875,8.37896327070173E-5,3.14775680767744E-7,1,0.999253354069792,40.0298881530762,1.99675350013383,16.1700006574392,0.00090165760988306,0.000158185848334199,0.25,-5.37671752254563E-7,8.3674212649214E-5,7.90529143222562E-8,10.0005302429199,10.0005302429199,-48521.96484375,-48477.26953125,54.7265024024673,19.7194134011215,6.43371200561523,0,0,0,40,10.0233135223389,1,6,1,2.16445922851562,44.9657897949219,,,,,,,,,,,,,,,,
,3737916849.47,10.0005774497986,-44318.685546875,7.14779002593245E-5,3.17123547989246E-7,1,0.999253354069792,40.0298881530762,1.99678698954602,16.1799993366003,0.000769423448237444,0.000131732692048059,0.25,-7.46569863913125E-7,7.13505668519556E-5,-2.25553711490385E-7,10.000452041626,10.000452041626,-44343.5703125,-44293.80078125,54.792940826602,19.72086764514,6.43259048461914,0,0,0,40,10.0204019546509,1,6,1,2.16079711914062,44.9657897949219,,,,,,,,,,,,,,,,
,3737916933.3245,10.000599861145,-40142.517578125,5.89012544817292E-5,2.81882958176621E-7,1,0.999253354069792,40.0298881530762,1.99680788047858,16.1700006574392,0.000633929997556524,0.000107618064440189,0.25,-6.9167632427955E-7,5.87709315754763E-5,-2.6838712420005E-7,10.0005073547363,10.0005073547363,-40169.8828125,-40115.15234375,54.4865424470635,19.7202185458232,6.4317421913147,0,0,0,40,10.0158205032349,1,6,1,2.16018676757813,44.9657897949219,,,,,,,,,,,,,,,,
,3737917017.2715,10.0005087852478,-35961.0859375,4.65299903669876E-5,3.23280850157767E-7,1,0.999253354069792,40.0298881530762,1.99678258053364,16.1799993366003,0.000501430072228699,8.01506407826166E-5,0.25,-9.89429942187176E-7,4.6409438344593E-5,-6.60149159087608E-7,10.0005159378052,10.0005159378052,-35986.00390625,-35936.16796875,54.3974367958711,19.7206059457109,6.42751741409302,0,0,0,40,10.0129222869873,1,6,1,2.1527099609375,43.0107536315918,,,,,,,,,,,,,,,,
,3737917101.212,9.9998779296875,-31777.0576171875,3.49763909557847E-5,2.53113264013682E-7,1,0.999253354069792,40.0298881530762,1.99688927222694,16.1700006574392,0.000376730056715721,6.04591002000767E-5,0.25,-7.1597873299166E-7,3.48699483240055E-5,-4.74251058997535E-7,9.99986934661865,9.99986934661865,-31801.943359375,-31752.171875,54.6358334942366,19.7250098312819,6.4261679649353,0,0,0,40,10.0109977722168,1,6,1,2.164306640625,43.9882698059082,,,,,,,,,,,,,,,,
,3737917185.1865,10.0001039505005,-27598.626953125,2.32212261650561E-5,2.7564012094613E-7,1,0.999253354069792,40.0298881530762,1.9967385925141,16.1700006574392,0.000251240112179464,3.3204475940227E-5,0.25,-1.11529763163462E-6,2.31445465960533E-5,-9.570154151982E-7,10.0001516342163,10.0001516342163,-27623.521484375,-27573.732421875,55.0196130971789,19.7236838473489,6.42395734786987,0,0,0,40,10.0084562301636,1,6,1,2.14141845703125,44.4770278930664,,,,,,,,,,,,,,,,
,3737917269.074,9.9998049736023,-23417.12890625,1.10288469331848E-5,2.82959606211797E-7,1,0.999253354069792,40.0298881530762,1.99669083661058,16.1700006574392,0.000120633584161982,8.23483829055452E-6,0.25,-1.22929254940343E-6,1.09920669052964E-5,-1.15364028062378E-6,9.99970626831055,9.99970626831055,-23439.50390625,-23394.75390625,54.864069021852,19.7214933077486,6.42154169082642,0,0,0,40,10.0067310333252,1,6,1,2.16079711914062,44.4770278930664,,,,,,,,,,,,,,,,
,3737917353.0625,10.0002198219299,-19232.5927734375,-9.13234842925944E-7,2.99347672620473E-7,1,0.999253354069792,40.0298881530762,1.99680434098234,16.1700006574392,-8.0787496047523E-6,-1.12234295055155E-5,0.25,-8.81993776615419E-7,-9.03739589729046E-7,-8.83671035963608E-7,10.0000648498535,10.0000648498535,-19254.982421875,-19210.203125,54.759330800275,19.7253984931737,6.42189407348633,0,0,0,40,10.0064516067505,1,6,1,2.1502685546875,44.4770278930664,,,,,,,,,,,,,,,,
,3737917436.9785,10.0005784034729,-15053.759765625,-1.36223068214114E-5,2.50410608599971E-7,1,0.999253354069792,40.0298881530762,1.99689539910565,16.1700006574392,-0.000143650068878062,-3.91632173260731E-5,0.25,-1.19562780026151E-6,-1.35492007330721E-5,-1.26965419680086E-6,10.0005645751953,10.0005645751953,-15081.142578125,-15026.376953125,54.5350034152558,19.7246488451502,6.42418003082275,0,0,0,40,10.0068817138672,1,6,1,2.15103149414062,44.9657897949219,,,,,,,,,,,,,,,,
,3737917520.8815,9.99984741210937,-10868.6875,-2.62063896584145E-5,2.86369313082234E-7,1,0.999253354069792,40.0298881530762,1.99681001961062,16.1700006574392,-0.0002783178769951,-6.38212177447381E-5,0.25,-1.23524939114148E-6,-2.60628577839581E-5,-1.37443793057047E-6,9.99977779388428,9.99977779388428,-10893.5283203125,-10843.8466796875,54.749169629525,19.7254272811297,6.42568254470825,0,0,0,40,10.0069160461426,1,6,1,2.16598510742187,44.4770278930664,,,,,,,,,,,,,,,,
,3737917604.8325,9.99987316131592,-6680.740234375,-3.99789619673758E-5,2.95276829334821E-7,1,0.999253354069792,40.0298881530762,1.99675577707038,16.1700006574392,-0.000425737118891933,-9.01242082908286E-5,0.25,-1.22397981991533E-6,-3.97509958017842E-5,-1.42701033106447E-6,9.99986839294434,9.99986839294434,-6705.65966796875,-6655.82080078125,54.7499512580443,19.7230219458041,6.43123197555542,0,0,0,40,10.0088415145874,1,6,1,2.16552734375,44.4770278930664,,,,,,,,,,,,,,,,
,3737917691.7645,9.99970769882202,-2334.54052734375,-5.57197804536992E-5,2.54194511095426E-7,1,0.999253354069792,40.0298881530762,1.99673759458743,16.1700006574392,-0.000593787382394477,-0.000122251427236358,0.25,-1.41259286652286E-6,-5.53881414183939E-5,-1.67989513078072E-6,9.99969100952148,9.99969100952148,-2359.51293945313,-2309.56811523438,54.6616272353712,19.7240702195463,6.43390226364136,0,0,0,40,10.0095348358154,1,6,1,2.15972900390625,44.9657897949219,,,,,,,,,,,,,,,,
,3737917778.738,9.9994215965271,2010.8896484375,-7.89506533262537E-5,2.4422410788402E-7,1,0.999253354069792,40.0298881530762,1.99674713982144,16.1700006574392,-0.000842463143708632,-0.000166964270357965,0.25,-1.41892358318416E-6,-7.84822285902757E-5,-1.79942764604836E-6,9.99948883056641,9.99948883056641,1983.40014648438,2038.37915039062,54.688202605025,19.7251584799165,6.4377293586731,0,0,0,40,10.0093326568604,1,6,1,2.14828491210938,44.9657897949219,,,,,,,,,,,,,,,,
,3737917865.631,10.0000309944153,6358.67333984375,-9.33584777024732E-5,2.16828494803768E-7,1,0.999253354069792,40.0298881530762,1.99661244423022,16.1700006574392,-0.000996917818307214,-0.000194698858400232,0.25,-1.39044642587768E-6,-9.28316962148365E-5,-1.870468146852E-6,9.99997520446777,9.99997520446777,6333.72216796875,6383.62451171875,55.5909835447367,19.7257503132615,6.43719816207886,0,0,0,40,10.0085334777832,1,6,1,2.14401245117187,44.4770278930664,,,,,,,,,,,,,,,,
,3737917949.5815,9.99977016448975,10556.130859375,-0.000102314906646785,2.68744952121822E-7,1,0.999253354069792,40.0298881530762,1.99660800356235,16.1700006574392,-0.00109308209138579,-0.000212482522786959,0.25,-1.40223000470556E-6,-0.00010177093580055,-1.96109370105163E-6,9.999831199646,9.999831199646,10533.6630859375,10578.5986328125,54.9336339600635,19.7247766283556,6.43434190750122,0,0,0,40,10.0063972473145,1,6,1,2.164306640625,44.9657897949219,,,,,,,,,,,,,,,,
,3737918033.5415,9.9999418258667,14753.5107421875,-0.000105927440967513,2.82716239264641E-7,1,0.999253354069792,40.0298881530762,1.99658115401275,16.1700006574392,-0.00113186530228572,-0.000221198910333764,0.25,-1.52567956830095E-6,-0.00010540167491298,-2.1367255386573E-6,9.99989223480225,9.99989223480225,14728.4912109375,14778.5302734375,54.8875178774289,19.7262866941892,6.42772769927978,0,0,0,40,10.0065002441406,1,6,1,2.16567993164062,44.9657897949219,,,,,,,,,,,,,,,,
,3737918120.431,9.99958562850952,19098.728515625,-9.95738455836027E-5,2.32452907422719E-7,1,0.999253354069792,40.0298881530762,1.99696653742249,16.1700006574392,-0.00106427768313418,-0.000209839714716414,0.25,-1.57122045514795E-6,-9.91186398630779E-5,-2.17527327450461E-6,9.99950885772705,9.99950885772705,19073.681640625,19123.775390625,54.3927470247558,19.7249907418103,6.42204284667969,0,0,0,40,10.0052947998047,1,6,1,2.1649169921875,44.9657897949219,,,,,,,,,,,,,,,,
,3737918204.382,9.99939441680908,23294.595703125,-8.57630223053673E-5,3.26800077858196E-7,1,0.999253354069792,40.0298881530762,1.99669346132809,16.1799993366003,-0.000916448123524013,-0.000183403502105844,0.25,-1.57490649907329E-6,-8.54046157778821E-5,-2.11746752621734E-6,9.99939346313477,9.99939346313477,23269.533203125,23319.658203125,54.6022234679096,19.7283218065739,6.42474985122681,0,0,0,40,10.0064449310303,1,6,1,2.13714599609375,44.4770278930664,,,,,,,,,,,,,,,,
,3737918288.288,9.99999284744263,27497.5712890625,-7.19541213246623E-5,3.63202126182682E-7,1,0.999253354069792,40.0298881530762,1.9968061740853,16.1799993366003,-0.000769428248247469,-0.000153018254929641,0.25,-1.21782966736211E-6,-7.16847268311011E-5,-1.69096958126645E-6,10.0000972747803,10.0000972747803,27475.001953125,27520.140625,54.3231820865442,19.725139804355,6.4243688583374,0,0,0,40,10.0074300765991,1,6,1,2.14492797851562,45.4545478820801,,,,,,,,,,,,,,,,
,3737918372.2655,9.99940729141235,31713.2158203125,-6.42232736573149E-5,2.84226210867839E-7,1,0.999253354069792,40.0298881530762,1.99654803845449,16.1700006574392,-0.000686892652277279,-0.000137092954009435,0.25,-1.11786087337823E-6,-6.40107422317263E-5,-1.55378260645622E-6,9.99932098388672,9.99932098388672,31690.63671875,31735.794921875,55.2861484222366,19.7236564569148,6.42159748077393,0,0,0,40,10.0101299285889,1,6,1,2.14920043945313,44.9657897949219,,,,,,,,,,,,,,,,
,3737918456.2105,9.99918508529663,35927.666015625,-6.43686012179818E-5,2.78217081533302E-7,1,0.999253354069792,40.0298881530762,1.99677164417476,16.1700006574392,-0.000688540294379159,-0.000139059462371588,0.25,-1.25656367011563E-6,-6.41831796588955E-5,-1.70480503091819E-6,9.99912357330322,9.99912357330322,35902.55859375,35952.7734375,54.4419896214673,19.7273119907323,6.41839027404785,0,0,0,40,10.0123119354248,1,6,1,2.16583251953125,44.9657897949219,,,,,,,,,,,,,,,,
,3737918540.1415,10.0000143051147,40138.474609375,-6.92985763302693E-5,2.95819234234381E-7,1,0.999253354069792,40.0298881530762,1.99667280963518,16.1799993366003,-0.000741814438194577,-0.000148432242551865,0.25,-1.21860326519723E-6,-6.91306685495679E-5,-1.71193543225497E-6,10.0000600814819,10.0000600814819,40113.4140625,40163.53515625,54.3802409684481,19.7286960409673,6.41971254348755,0,0,0,40,10.0149412155151,1,6,1,2.15530395507813,45.4545478820801,,,,,,,,,,,,,,,,
,3737918624.1015,9.99911832809448,44354.736328125,-7.74935906877418E-5,3.65486651316976E-7,1,0.999253354069792,40.0298881530762,1.99676194176254,16.1700006574392,-0.000830015610157932,-0.000165660984575523,0.25,-1.31662134141771E-6,-7.73403758650641E-5,-1.87760702179251E-6,9.99905300140381,9.99905300140381,44329.65234375,44379.8203125,55.0008540127174,19.7251370123043,6.41767501831055,0,0,0,40,10.0178756713867,1,6,1,2.14874267578125,44.9657897949219,,,,,,,,,,,,,,,,
,3737918708.0135,9.99939155578613,48565.935546875,-8.8182195486649E-5,3.25692595498866E-7,1,0.999253354069792,40.0298881530762,1.99664729462306,16.1700006574392,-0.000945156118718332,-0.000186948923966041,0.25,-1.33931651937692E-6,-8.8047316750736E-5,-1.98576122143108E-6,9.99934864044189,9.99934864044189,48540.79296875,48591.078125,54.4576221918519,19.7232385572693,6.41606092453003,0,0,0,40,10.0223245620728,1,6,1,2.1502685546875,44.9657897949219,,,,,,,,,,,,,,,,
,3737918791.9815,9.99917221069336,52788.099609375,-9.9868910271867E-5,2.95872707226217E-7,1,0.999253354069792,40.0298881530762,1.99643322670748,16.1799993366003,-0.00107063181362226,-0.00021252351459189,0.25,-1.57955822824688E-6,-9.97582213920967E-5,-2.31768746325449E-6,9.9992036819458,9.9992036819458,52762.796875,52813.40234375,54.8257692244096,19.7204365158049,6.41673135757446,0,0,0,40,10.0271034240723,1,6,1,2.16522216796875,44.9657897949219,,,,,,,,,,,,,,,,
,3737918875.8635,9.99878072738647,57027.56640625,-0.000111827080811896,3.92642733447987E-7,1,0.999253354069792,40.0298881530762,1.99648205886741,16.1700006574392,-0.00119841222663097,-0.000243248297630665,0.25,-2.24672326157767E-6,-0.000111746030006277,-3.07694443934089E-6,9.99886703491211,9.99886703491211,57004.875,57050.2578125,54.6467762935058,19.7223182628449,6.41667032241821,0,0,0,40,10.0316162109375,1,6,1,2.16506958007813,44.9657897949219,,,,,,,,,,,,,,,,
,3737918959.784,9.99915409088135,61272.609375,-0.000124097846037755,3.91287028757301E-7,1,0.999253354069792,40.0298881530762,1.99662245104877,16.1700006574392,-0.00133126295306409,-0.000266082919479031,0.25,-2.12270949168137E-6,-0.000124060509053,-3.04583245837684E-6,9.99922466278076,9.99922466278076,61247.3515625,61297.8671875,54.8351487666404,19.7268248101982,6.41753339767456,0,0,0,40,10.036190032959,1,6,1,2.16064453125,45.4545478820801,,,,,,,,,,,,,,,,
,3737919043.777,9.99837255477905,65520.6484375,-0.000136793197673744,3.26206979210633E-7,1,0.999253354069792,40.0298881530762,1.99671560087931,16.1700006574392,-0.00146937878628624,-0.000286325401823809,0.25,-1.68236322264098E-6,-0.000136809788904171,-2.69866645489375E-6,9.99841690063477,9.99841690063477,65500.3984375,65540.8984375,54.8195161962558,19.7274180595611,6.41692972183228,0,0,0,40,10.0410890579224,1,6,1,2.14920043945313,44.9657897949219,,,,,,,,,,,,,,,,
,3737919127.6865,9.99907684326172,69765.14453125,-0.00015014280947182,4.04859681116347E-7,1,0.999253354069792,40.0298881530762,1.99655124166908,16.1799993366003,-0.0016130695803041,-0.000315318372157845,0.25,-1.94096814204809E-6,-0.000150215798960722,-3.05223860334349E-6,9.99911499023437,9.99911499023437,69742.4375,69787.8515625,55.1360757465443,19.7261529288485,6.41803169250488,0,0,0,40,10.047625541687,1,6,1,2.16766357421875,44.9657897949219,,,,,,,,,,,,,,,,
,3737919211.6365,9.99854040145874,74007.31640625,-0.000164131248480238,4.13979749647486E-7,1,0.999253354069792,40.0298881530762,1.99673840119835,16.1700006574392,-0.0017651188559349,-0.000339430367325049,0.25,-1.6273949466256E-6,-0.000164272482179395,-2.83447922101252E-6,9.99860763549805,9.99860763549805,73979.5078125,74035.125,54.4513691636981,19.7259388295752,6.42244625091553,0,0,0,40,10.0532636642456,1,6,1,2.15011596679687,44.4770278930664,,,,,,,,,,,,,,,,
,3737919295.582,9.99905014038086,78255.75,-0.00017731416710617,3.69171383941393E-7,1,0.999253354069792,40.0298881530762,1.99664657001842,16.1700006574392,-0.00190611169498873,-0.000374134883960111,0.25,-2.45022594206764E-6,-0.000177521142536047,-3.74465270497668E-6,9.99904060363769,9.99904060363769,78227.9609375,78283.5390625,54.884391363352,19.7271435513493,6.42369842529297,0,0,0,40,10.0593862533569,1,6,1,2.16476440429687,44.9657897949219,,,,,,,,,,,,,,,,
,3737919379.584,9.99961233139038,82502.90625,-0.000191555360801783,4.4179892128973E-7,1,0.999253354069792,40.0298881530762,1.99656104449827,16.1700006574392,-0.00205934909495946,-0.000406623032922649,0.25,-2.87750686449635E-6,-0.000191838221952013,-4.26292723283441E-6,9.99963474273682,9.99963474273682,82480.1328125,82525.6796875,54.5443829574865,19.7260556932078,6.42652320861816,0,0,0,40,10.0645523071289,1,6,1,2.16278076171875,44.9657897949219,,,,,,,,,,,,,,,,
,3737919463.416,9.99886798858643,86742.65234375,-0.0002054850099979,4.77912775577116E-7,1,0.999253354069792,40.0298881530762,1.9965137855327,16.1700006574392,-0.00221098329236964,-0.000429332054006647,0.25,-2.45694431506887E-6,-0.00020585469131739,-3.92568967067971E-6,9.99886512756348,9.99886512756348,86717.265625,86768.0390625,54.9508297874866,19.7260640766229,6.42641401290894,0,0,0,40,10.0712022781372,1,6,1,2.16110229492187,44.4770278930664,,,,,,,,,,,,,,,,
,3737919531.3635,9.99957132339478,90002.22265625,-0.000218971276084712,9.54543410837395E-7,1,0.999253354069792,40.0298881530762,1.99647572904698,16.1700006574392,-0.00235887068517347,-0.000444917724419473,0.25,-1.45776938652235E-6,-0.000219421484965527,-3.00578749347506E-6,9.99952983856201,9.99952983856201,90000.421875,90004.0234375,54.9594277011981,19.7248020409336,6.42650127410889,0,0,0,40,10.0761842727661,1,4,1,2.14981079101562,45.4545478820801,,,,,,,,,,,,,,,,