File: data/looselyPackedNP/ios-11/ppms/rawdata/FC100Oe.dc.dat
[Header]
TITLE,MPMS DC Measurement
BYAPP,MPMS Measurement,2.1,Summary
FILEOPENTIME, 1418239200.498000 12/10/2014, 8:20:00 PM

INFO, APPNAME, MPMS MultiVu Application, Revision 1.60,  Build 081

INFO, NAME, PMK18
INFO, WEIGHT, 13.800
INFO, AREA, 1.000
INFO, LENGTH, 1.000
INFO, SHAPE, NP
INFO, COMMENT, Fe2O3
INFO, SEQUENCE FILE: 04062014.seq


INFO, BACKGROUND DATA FILE:, None


STARTUPAXIS,X,4,LINEAR,AUTO,0.000000,0.000000
STARTUPAXIS,Y1,5,LINEAR,AUTO,0.000000,0.000000


STARTUPGROUP,Longitudinal
FIELDGROUP,Longitudinal,1,2,3,4,5,6,7,8,9,15,16,17,18,27,28
FIELDGROUP,Transverse,1,2,3,4,10,11,12,13,14,19,20,21,22,27,28

PLOT_APPEARANCE,ALL,HORZ_GRID_ON,VERT_GRID_ON,MARKERS_AND_LINES

[Data]
Time,Comment,Field (Oe),Temperature (K),Moment (emu),Long Scan Std Dev,Long Algorithm,Long Reg Fit,Long Percent Error (%),Trans Moment (emu),Trans Scan Std Dev,Trans Algorithm,Trans Reg Fit,Trans Percent Error (%),Long Moment [w/o ABS] (emu),Long Scan Std Dev [w/o ABS],Long Reg Fit [w/o ABS],Long Percent Error [w/o ABS] (%),Trans Moment [w/o ABS] (emu),Trans Scan Std Dev [w/o ABS],Trans Reg Fit [w/o ABS],Trans Percent Error [w/o ABS] (%),Points per Scan,Scans per Measurement,Scan Length (cm),Delta Temp (K),Rot Position (deg),Error,EC Comp. Running,Using ABS,
1418239200.498,,1.000000e+002,2.999957e+002,2.289520e-002,0.000000e+000,3,9.965565e-001,0.000000e+000,,,,,,,,,,,,,,24,1,4.000000e+000,2.639771e-002,0.000000e+000,0,,0,
1418239311.949,,1.000000e+002,2.988862e+002,2.297542e-002,0.000000e+000,3,9.964464e-001,0.000000e+000,,,,,,,,,,,,,,24,1,4.000000e+000,2.271729e-001,0.000000e+000,0,,0,
1418239384.152,,1.000000e+002,2.977856e+002,2.308344e-002,0.000000e+000,3,9.964775e-001,0.000000e+000,,,,,,,,,,,,,,24,1,4.000000e+000,3.899841e-001,0.000000e+000,0,,0,
1418239431.268,,1.000000e+002,2.966591e+002,4.739591e-002,0.000000e+000,3,5.541942e-001,0.000000e+000,,,,,,,,,,,,,,24,1,4.000000e+000,6.018066e-001,0.000000e+000,0,,0,
1418239461.166,,1.000000e+002,2.955931e+002,2.330311e-002,0.000000e+000,3,9.965168e-001,0.000000e+000,,,,,,,,,,,,,,24,1,4.000000e+000,7.934875e-001,0.000000e+000,0,,0,
1418239489.119,,1.000000e+002,2.944296e+002,2.341034e-002,0.000000e+000,3,9.964797e-001,0.000000e+000,,,,,,,,,,,,,,24,1,4.000000e+000,1.074493e+000,0.000000e+000,0,,0,
1418239509.486,,1.000000e+002,2.932753e+002,2.347804e-002,0.000000e+000,3,9.964833e-001,0.000000e+000,,,,,,,,,,,,,,24,1,4.000000e+000,9.816284e-001,0.000000e+000,0,,0,
1418239530.283,,1.000000e+002,2.920975e+002,2.358335e-002,0.000000e+000,3,9.964661e-001,0.000000e+000,,,,,,,,,,,,,,24,1,4.000000e+000,1.106293e+000,0.000000e+000,0,,0,
1418239552.267,,1.000000e+002,2.908763e+002,2.371207e-002,0.000000e+000,3,9.963918e-001,0.000000e+000,,,,,,,,,,,,,,24,1,4.000000e+000,1.187073e+000,0.000000e+000,0,,0,
1418239573.196,,1.000000e+002,2.896206e+002,2.381916e-002,0.000000e+000,3,9.965132e-001,0.000000e+000,,,,,,,,,,,,,,24,1,4.000000e+000,1.176208e+000,0.000000e+000,0,,0,
1418239592.508,,1.000000e+002,2.884816e+002,2.394348e-002,0.000000e+000,3,9.965302e-001,0.000000e+000,,,,,,,,,,,,,,24,1,4.000000e+000,1.101715e+000,0.000000e+000,0,,0,
1418239652.304,,1.000000e+002,2.852318e+002,2.426310e-002,0.000000e+000,3,9.965019e-001,0.000000e+000,,,,,,,,,,,,,,24,1,4.000000e+000,8.381958e-001,0.000000e+000,0,,0,
1418239672.445,,1.000000e+002,2.842708e+002,2.435861e-002,0.000000e+000,3,9.964743e-001,0.000000e+000,,,,,,,,,,,,,,24,1,4.000000e+000,9.419861e-001,0.000000e+000,0,,0,
1418239692.804,,1.000000e+002,2.832853e+002,2.446040e-002,0.000000e+000,3,9.965267e-001,0.000000e+000,,,,,,,,,,,,,,24,1,4.000000e+000,9.039001e-001,0.000000e+000,0,,0,
1418239712.952,,1.000000e+002,2.823765e+002,2.454627e-002,0.000000e+000,3,9.965118e-001,0.000000e+000,,,,,,,,,,,,,,24,1,4.000000e+000,8.049011e-001,0.000000e+000,0,,0,
1418239732.186,,1.000000e+002,2.815203e+002,2.463170e-002,0.000000e+000,3,9.965214e-001,0.000000e+000,,,,,,,,,,,,,,24,1,4.000000e+000,7.843018e-001,0.000000e+000,0,,0,
1418239752.569,,1.000000e+002,2.806429e+002,2.472250e-002,0.000000e+000,3,9.964333e-001,0.000000e+000,,,,,,,,,,,,,,24,1,4.000000e+000,8.477173e-001,0.000000e+000,0,,0,
1418239772.443,,1.000000e+002,2.797750e+002,2.481867e-002,0.000000e+000,3,9.964216e-001,0.000000e+000,,,,,,,,,,,,,,24,1,4.000000e+000,7.662964e-001,0.000000e+000,0,,0,
1418239832.122,,1.000000e+002,2.771536e+002,2.507263e-002,0.000000e+000,3,9.965074e-001,0.000000e+000,,,,,,,,,,,,,,24,1,4.000000e+000,7.510986e-001,0.000000e+000,0,,0,
1418239852.442,,1.000000e+002,2.762829e+002,2.516906e-002,0.000000e+000,3,9.964846e-001,0.000000e+000,,,,,,,,,,,,,,24,1,4.000000e+000,8.715820e-001,0.000000e+000,0,,0,
1418239872.106,,1.000000e+002,2.753739e+002,2.525436e-002,0.000000e+000,3,9.965683e-001,0.000000e+000,,,,,,,,,,,,,,24,1,4.000000e+000,8.287964e-001,0.000000e+000,0,,0,
1418239893.114,,1.000000e+002,2.744822e+002,2.536227e-002,0.000000e+000,3,9.965379e-001,0.000000e+000,,,,,,,,,,,,,,24,1,4.000000e+000,8.229980e-001,0.000000e+000,0,,0,
1418239912.418,,1.000000e+002,2.735497e+002,2.544486e-002,0.000000e+000,3,9.966084e-001,0.000000e+000,,,,,,,,,,,,,,24,1,4.000000e+000,7.952881e-001,0.000000e+000,0,,0,
1418239930.848,,1.000000e+002,2.726670e+002,2.552648e-002,0.000000e+000,3,9.965740e-001,0.000000e+000,,,,,,,,,,,,,,24,1,4.000000e+000,7.251892e-001,0.000000e+000,0,,0,
1418239949.254,,1.000000e+002,2.717976e+002,2.562170e-002,0.000000e+000,3,9.965749e-001,0.000000e+000,,,,,,,,,,,,,,24,1,4.000000e+000,7.416992e-001,0.000000e+000,0,,0,
1418239968.519,,1.000000e+002,2.709272e+002,3.087561e-002,0.000000e+000,3,4.065467e-001,0.000000e+000,,,,,,,,,,,,,,24,1,4.000000e+000,8.710938e-001,0.000000e+000,0,,0,
1418239988.253,,1.000000e+002,2.699958e+002,2.580065e-002,0.000000e+000,3,9.965566e-001,0.000000e+000,,,,,,,,,,,,,,24,1,4.000000e+000,8.646851e-001,0.000000e+000,0,,0,
1418240007.612,,1.000000e+002,2.690643e+002,2.590380e-002,0.000000e+000,3,9.965639e-001,0.000000e+000,,,,,,,,,,,,,,24,1,4.000000e+000,8.721924e-001,0.000000e+000,0,,0,
1418240027.159,,1.000000e+002,2.681917e+002,2.601364e-002,0.000000e+000,3,9.965151e-001,0.000000e+000,,,,,,,,,,,,,,24,1,4.000000e+000,8.731079e-001,0.000000e+000,0,,0,
1418240047.174,,1.000000e+002,2.671874e+002,2.611208e-002,0.000000e+000,3,9.964946e-001,0.000000e+000,,,,,,,,,,,,,,24,1,4.000000e+000,8.866882e-001,0.000000e+000,0,,0,
1418240067.526,,1.000000e+002,2.662699e+002,2.621172e-002,0.000000e+000,3,9.964752e-001,0.000000e+000,,,,,,,,,,,,,,24,1,4.000000e+000,9.484253e-001,0.000000e+000,0,,0,
1418240087.096,,1.000000e+002,2.652979e+002,2.631005e-002,0.000000e+000,3,9.965165e-001,0.000000e+000,,,,,,,,,,,,,,24,1,4.000000e+000,8.731995e-001,0.000000e+000,0,,0,
1418240106.353,,1.000000e+002,2.643738e+002,2.640095e-002,0.000000e+000,3,9.964890e-001,0.000000e+000,,,,,,,,,,,,,,24,1,4.000000e+000,8.130188e-001,0.000000e+000,0,,0,
1418240127.814,,1.000000e+002,2.634697e+002,2.651161e-002,0.000000e+000,3,9.965348e-001,0.000000e+000,,,,,,,,,,,,,,24,1,4.000000e+000,8.748169e-001,0.000000e+000,0,,0,
1418240147.837,,1.000000e+002,2.624893e+002,2.518625e-002,0.000000e+000,3,7.241845e-001,0.000000e+000,,,,,,,,,,,,,,24,1,4.000000e+000,8.203125e-001,0.000000e+000,0,,0,
1418240166.274,,1.000000e+002,2.615631e+002,2.655170e-002,0.000000e+000,3,9.950259e-001,0.000000e+000,,,,,,,,,,,,,,24,1,4.000000e+000,7.553101e-001,0.000000e+000,0,,0,
1418240184.977,,1.000000e+002,2.606960e+002,2.680215e-002,0.000000e+000,3,9.965392e-001,0.000000e+000,,,,,,,,,,,,,,24,1,4.000000e+000,8.349915e-001,0.000000e+000,0,,0,
1418240204.516,,1.000000e+002,2.597570e+002,2.689728e-002,0.000000e+000,3,9.965718e-001,0.000000e+000,,,,,,,,,,,,,,24,1,4.000000e+000,9.130859e-001,0.000000e+000,0,,0,
1418240224.149,,1.000000e+002,2.588567e+002,2.691924e-002,0.000000e+000,3,9.951936e-001,0.000000e+000,,,,,,,,,,,,,,24,1,4.000000e+000,8.874207e-001,0.000000e+000,0,,0,
1418240242.398,,1.000000e+002,2.579118e+002,2.710240e-002,0.000000e+000,3,9.965317e-001,0.000000e+000,,,,,,,,,,,,,,24,1,4.000000e+000,8.616028e-001,0.000000e+000,0,,0,
1418240262.015,,1.000000e+002,2.569897e+002,2.712089e-002,0.000000e+000,3,9.970024e-001,0.000000e+000,,,,,,,,,,,,,,24,1,4.000000e+000,8.427124e-001,0.000000e+000,0,,0,
1418240281.015,,1.000000e+002,2.560742e+002,2.547181e-002,0.000000e+000,3,6.417214e-001,0.000000e+000,,,,,,,,,,,,,,24,1,4.000000e+000,8.491058e-001,0.000000e+000,0,,0,
1418240300.023,,1.000000e+002,2.551468e+002,5.923280e-002,0.000000e+000,3,2.192775e-001,0.000000e+000,,,,,,,,,,,,,,24,1,4.000000e+000,8.429108e-001,0.000000e+000,0,,0,
1418240319.522,,1.000000e+002,2.541642e+002,3.290516e-002,0.000000e+000,3,8.867570e-001,0.000000e+000,,,,,,,,,,,,,,24,1,4.000000e+000,8.735046e-001,0.000000e+000,0,,0,
1418240339.272,,1.000000e+002,2.532168e+002,2.746622e-002,0.000000e+000,3,9.962967e-001,0.000000e+000,,,,,,,,,,,,,,24,1,4.000000e+000,8.484039e-001,0.000000e+000,0,,0,
1418240358.311,,1.000000e+002,2.522858e+002,2.773488e-002,0.000000e+000,3,9.964616e-001,0.000000e+000,,,,,,,,,,,,,,24,1,4.000000e+000,8.908997e-001,0.000000e+000,0,,0,
1418240378.514,,1.000000e+002,2.513013e+002,2.784999e-002,0.000000e+000,3,9.964776e-001,0.000000e+000,,,,,,,,,,,,,,24,1,4.000000e+000,9.443054e-001,0.000000e+000,0,,0,
1418240396.521,,1.000000e+002,2.503454e+002,2.793881e-002,0.000000e+000,3,9.965242e-001,0.000000e+000,,,,,,,,,,,,,,24,1,4.000000e+000,8.229980e-001,0.000000e+000,0,,0,
1418240416.959,,1.000000e+002,2.493882e+002,2.807183e-002,0.000000e+000,3,9.963911e-001,0.000000e+000,,,,,,,,,,,,,,24,1,4.000000e+000,9.356995e-001,0.000000e+000,0,,0,
1418240436.107,,1.000000e+002,2.484470e+002,2.816490e-002,0.000000e+000,3,9.964425e-001,0.000000e+000,,,,,,,,,,,,,,24,1,4.000000e+000,8.162079e-001,0.000000e+000,0,,0,
1418240455.185,,1.000000e+002,2.474663e+002,2.826985e-002,0.000000e+000,3,9.964786e-001,0.000000e+000,,,,,,,,,,,,,,24,1,4.000000e+000,8.624115e-001,0.000000e+000,0,,0,
1418240472.817,,1.000000e+002,2.465632e+002,2.836284e-002,0.000000e+000,3,9.965093e-001,0.000000e+000,,,,,,,,,,,,,,24,1,4.000000e+000,8.035889e-001,0.000000e+000,0,,0,
1418240493.442,,1.000000e+002,2.456237e+002,2.849063e-002,0.000000e+000,3,9.964755e-001,0.000000e+000,,,,,,,,,,,,,,24,1,4.000000e+000,9.360962e-001,0.000000e+000,0,,0,
1418240512.996,,1.000000e+002,2.446653e+002,2.859791e-002,0.000000e+000,3,9.964437e-001,0.000000e+000,,,,,,,,,,,,,,24,1,4.000000e+000,8.654938e-001,0.000000e+000,0,,0,
1418240534.270,,1.000000e+002,2.437035e+002,2.870840e-002,0.000000e+000,3,9.963655e-001,0.000000e+000,,,,,,,,,,,,,,24,1,4.000000e+000,9.098053e-001,0.000000e+000,0,,0,
1418240554.324,,1.000000e+002,2.427067e+002,2.881581e-002,0.000000e+000,3,9.964789e-001,0.000000e+000,,,,,,,,,,,,,,24,1,4.000000e+000,8.231964e-001,0.000000e+000,0,,0,
1418240572.902,,1.000000e+002,2.418414e+002,2.892341e-002,0.000000e+000,3,9.964288e-001,0.000000e+000,,,,,,,,,,,,,,24,1,4.000000e+000,7.726135e-001,0.000000e+000,0,,0,
1418240592.238,,1.000000e+002,2.409297e+002,2.903421e-002,0.000000e+000,3,9.964867e-001,0.000000e+000,,,,,,,,,,,,,,24,1,4.000000e+000,7.610931e-001,0.000000e+000,0,,0,
1418240612.441,,1.000000e+002,2.399947e+002,2.913740e-002,0.000000e+000,3,9.964268e-001,0.000000e+000,,,,,,,,,,,,,,24,1,4.000000e+000,8.432007e-001,0.000000e+000,0,,0,
1418240632.815,,1.000000e+002,2.390644e+002,2.925156e-002,0.000000e+000,3,9.964464e-001,0.000000e+000,,,,,,,,,,,,,,24,1,4.000000e+000,9.076996e-001,0.000000e+000,0,,0,
1418240650.971,,1.000000e+002,2.381979e+002,2.934746e-002,0.000000e+000,3,9.964228e-001,0.000000e+000,,,,,,,,,,,,,,24,1,4.000000e+000,7.164001e-001,0.000000e+000,0,,0,
1418240710.830,,1.000000e+002,2.353807e+002,2.967560e-002,0.000000e+000,3,9.963572e-001,0.000000e+000,,,,,,,,,,,,,,24,1,4.000000e+000,9.268951e-001,0.000000e+000,0,,0,
1418240731.173,,1.000000e+002,2.344496e+002,2.979658e-002,0.000000e+000,3,9.963121e-001,0.000000e+000,,,,,,,,,,,,,,24,1,4.000000e+000,9.353027e-001,0.000000e+000,0,,0,
1418240749.681,,1.000000e+002,2.334945e+002,2.990476e-002,0.000000e+000,3,9.963517e-001,0.000000e+000,,,,,,,,,,,,,,24,1,4.000000e+000,8.180084e-001,0.000000e+000,0,,0,
1418240770.540,,1.000000e+002,2.325422e+002,3.003031e-002,0.000000e+000,3,9.963401e-001,0.000000e+000,,,,,,,,,,,,,,24,1,4.000000e+000,9.560089e-001,0.000000e+000,0,,0,
1418240790.977,,1.000000e+002,2.315491e+002,3.015609e-002,0.000000e+000,3,9.964163e-001,0.000000e+000,,,,,,,,,,,,,,24,1,4.000000e+000,8.862000e-001,0.000000e+000,0,,0,
1418240810.360,,1.000000e+002,2.305392e+002,3.027048e-002,0.000000e+000,3,9.964794e-001,0.000000e+000,,,,,,,,,,,,,,24,1,4.000000e+000,8.276062e-001,0.000000e+000,0,,0,
1418240829.485,,1.000000e+002,2.295837e+002,3.038175e-002,0.000000e+000,3,9.964805e-001,0.000000e+000,,,,,,,,,,,,,,24,1,4.000000e+000,8.610077e-001,0.000000e+000,0,,0,
1418240887.312,,1.000000e+002,2.268628e+002,3.072000e-002,0.000000e+000,3,9.964726e-001,0.000000e+000,,,,,,,,,,,,,,24,1,4.000000e+000,8.993988e-001,0.000000e+000,0,,0,
1418240906.843,,1.000000e+002,2.258597e+002,3.083724e-002,0.000000e+000,3,9.964707e-001,0.000000e+000,,,,,,,,,,,,,,24,1,4.000000e+000,8.231964e-001,0.000000e+000,0,,0,
1418240926.733,,1.000000e+002,2.248898e+002,3.098889e-002,0.000000e+000,3,9.963911e-001,0.000000e+000,,,,,,,,,,,,,,24,1,4.000000e+000,8.160095e-001,0.000000e+000,0,,0,
1418240944.843,,1.000000e+002,2.239449e+002,3.109024e-002,0.000000e+000,3,9.964729e-001,0.000000e+000,,,,,,,,,,,,,,24,1,4.000000e+000,7.658997e-001,0.000000e+000,0,,0,
1418240961.967,,1.000000e+002,2.230985e+002,3.119469e-002,0.000000e+000,3,9.964827e-001,0.000000e+000,,,,,,,,,,,,,,24,1,4.000000e+000,7.837982e-001,0.000000e+000,0,,0,
1418240981.358,,1.000000e+002,2.222540e+002,3.130668e-002,0.000000e+000,3,9.964048e-001,0.000000e+000,,,,,,,,,,,,,,24,1,4.000000e+000,9.051971e-001,0.000000e+000,0,,0,
1418241000.147,,1.000000e+002,2.213010e+002,3.140647e-002,0.000000e+000,3,9.964233e-001,0.000000e+000,,,,,,,,,,,,,,24,1,4.000000e+000,8.412018e-001,0.000000e+000,0,,0,
1418241059.224,,1.000000e+002,2.184598e+002,3.177499e-002,0.000000e+000,3,9.964070e-001,0.000000e+000,,,,,,,,,,,,,,24,1,4.000000e+000,9.105072e-001,0.000000e+000,0,,0,
1418241078.638,,1.000000e+002,2.175012e+002,3.190225e-002,0.000000e+000,3,9.965875e-001,0.000000e+000,,,,,,,,,,,,,,24,1,4.000000e+000,8.528900e-001,0.000000e+000,0,,0,
1418241097.137,,1.000000e+002,2.166046e+002,3.202471e-002,0.000000e+000,3,9.966144e-001,0.000000e+000,,,,,,,,,,,,,,24,1,4.000000e+000,7.964935e-001,0.000000e+000,0,,0,
1418241115.661,,1.000000e+002,2.156670e+002,3.215582e-002,0.000000e+000,3,9.966099e-001,0.000000e+000,,,,,,,,,,,,,,24,1,4.000000e+000,7.938995e-001,0.000000e+000,0,,0,
1418241135.535,,1.000000e+002,2.147202e+002,3.225242e-002,0.000000e+000,3,9.965467e-001,0.000000e+000,,,,,,,,,,,,,,24,1,4.000000e+000,9.407043e-001,0.000000e+000,0,,0,
1418241153.910,,1.000000e+002,2.137876e+002,3.236157e-002,0.000000e+000,3,9.965340e-001,0.000000e+000,,,,,,,,,,,,,,24,1,4.000000e+000,7.843018e-001,0.000000e+000,0,,0,
1418241173.168,,1.000000e+002,2.128767e+002,3.252492e-002,0.000000e+000,3,9.963470e-001,0.000000e+000,,,,,,,,,,,,,,24,1,4.000000e+000,8.466034e-001,0.000000e+000,0,,0,
1418241193.167,,1.000000e+002,2.119160e+002,3.263434e-002,0.000000e+000,3,9.963482e-001,0.000000e+000,,,,,,,,,,,,,,24,1,4.000000e+000,9.373016e-001,0.000000e+000,0,,0,
1418241247.901,,1.000000e+002,2.092245e+002,3.300744e-002,0.000000e+000,3,9.964690e-001,0.000000e+000,,,,,,,,,,,,,,24,1,4.000000e+000,8.049011e-001,0.000000e+000,0,,0,
1418241267.745,,1.000000e+002,2.083132e+002,3.311463e-002,0.000000e+000,3,9.964988e-001,0.000000e+000,,,,,,,,,,,,,,24,1,4.000000e+000,8.679962e-001,0.000000e+000,0,,0,
1418241349.509,,1.000000e+002,2.044356e+002,-1.187826e-001,0.000000e+000,2,0.000000e+000,0.000000e+000,,,,,,,,,,,,,,24,1,4.000000e+000,9.593964e-001,0.000000e+000,0,,0,
1418241387.063,,1.000000e+002,2.024655e+002,-1.815855e-002,0.000000e+000,3,0.000000e+000,0.000000e+000,,,,,,,,,,,,,,24,1,4.000000e+000,8.048096e-001,0.000000e+000,0,,0,
1418241408.696,,1.000000e+002,2.014803e+002,3.409035e-002,0.000000e+000,3,9.962700e-001,0.000000e+000,,,,,,,,,,,,,,24,1,4.000000e+000,1.010010e+000,0.000000e+000,0,,0,
1418241427.688,,1.000000e+002,2.005034e+002,3.422865e-002,0.000000e+000,3,9.962603e-001,0.000000e+000,,,,,,,,,,,,,,24,1,4.000000e+000,8.050995e-001,0.000000e+000,0,,0,
1418241487.414,,1.000000e+002,1.977314e+002,3.464392e-002,0.000000e+000,3,9.962325e-001,0.000000e+000,,,,,,,,,,,,,,24,1,4.000000e+000,8.804932e-001,0.000000e+000,0,,0,
1418241506.913,,1.000000e+002,1.967564e+002,3.478801e-002,0.000000e+000,3,9.963176e-001,0.000000e+000,,,,,,,,,,,,,,24,1,4.000000e+000,8.166962e-001,0.000000e+000,0,,0,
1418241566.272,,1.000000e+002,1.939088e+002,3.520726e-002,0.000000e+000,3,9.965593e-001,0.000000e+000,,,,,,,,,,,,,,24,1,4.000000e+000,8.335114e-001,0.000000e+000,0,,0,
1418241584.327,,1.000000e+002,1.930395e+002,3.533261e-002,0.000000e+000,3,9.965807e-001,0.000000e+000,,,,,,,,,,,,,,24,1,4.000000e+000,7.693024e-001,0.000000e+000,0,,0,
1418241602.990,,1.000000e+002,1.921602e+002,3.547085e-002,0.000000e+000,3,9.966224e-001,0.000000e+000,,,,,,,,,,,,,,24,1,4.000000e+000,8.472900e-001,0.000000e+000,0,,0,
1418241623.326,,1.000000e+002,1.912119e+002,3.561890e-002,0.000000e+000,3,9.965255e-001,0.000000e+000,,,,,,,,,,,,,,24,1,4.000000e+000,9.161072e-001,0.000000e+000,0,,0,
1418241642.115,,1.000000e+002,1.902531e+002,3.573441e-002,0.000000e+000,3,9.966296e-001,0.000000e+000,,,,,,,,,,,,,,24,1,4.000000e+000,8.690948e-001,0.000000e+000,0,,0,
1418241660.310,,1.000000e+002,1.893449e+002,3.588096e-002,0.000000e+000,3,9.966329e-001,0.000000e+000,,,,,,,,,,,,,,24,1,4.000000e+000,8.163910e-001,0.000000e+000,0,,0,
1418241717.926,,1.000000e+002,1.865386e+002,3.633797e-002,0.000000e+000,3,9.965568e-001,0.000000e+000,,,,,,,,,,,,,,24,1,4.000000e+000,8.798065e-001,0.000000e+000,0,,0,
1418241737.989,,1.000000e+002,1.855258e+002,3.647873e-002,0.000000e+000,3,9.965219e-001,0.000000e+000,,,,,,,,,,,,,,24,1,4.000000e+000,8.805084e-001,0.000000e+000,0,,0,
1418241757.020,,1.000000e+002,1.845692e+002,3.663703e-002,0.000000e+000,3,9.964576e-001,0.000000e+000,,,,,,,,,,,,,,24,1,4.000000e+000,8.815002e-001,0.000000e+000,0,,0,
1418241816.738,,1.000000e+002,1.816353e+002,3.708864e-002,0.000000e+000,3,9.964108e-001,0.000000e+000,,,,,,,,,,,,,,24,1,4.000000e+000,9.432068e-001,0.000000e+000,0,,0,
1418241837.237,,1.000000e+002,1.806326e+002,3.482395e-002,0.000000e+000,3,8.467885e-001,0.000000e+000,,,,,,,,,,,,,,24,1,4.000000e+000,9.361877e-001,0.000000e+000,0,,0,
1418241856.745,,1.000000e+002,1.796900e+002,3.741976e-002,0.000000e+000,3,9.964577e-001,0.000000e+000,,,,,,,,,,,,,,24,1,4.000000e+000,8.119965e-001,0.000000e+000,0,,0,
1418241876.362,,1.000000e+002,1.787189e+002,3.757237e-002,0.000000e+000,3,9.965158e-001,0.000000e+000,,,,,,,,,,,,,,24,1,4.000000e+000,8.709106e-001,0.000000e+000,0,,0,
1418241896.666,,1.000000e+002,1.777747e+002,3.773166e-002,0.000000e+000,3,9.964880e-001,0.000000e+000,,,,,,,,,,,,,,24,1,4.000000e+000,8.710938e-001,0.000000e+000,0,,0,
1418241954.166,,1.000000e+002,1.749509e+002,3.820551e-002,0.000000e+000,3,9.964887e-001,0.000000e+000,,,,,,,,,,,,,,24,1,4.000000e+000,8.266907e-001,0.000000e+000,0,,0,
1418241973.025,,1.000000e+002,1.740276e+002,3.835855e-002,0.000000e+000,3,9.964550e-001,0.000000e+000,,,,,,,,,,,,,,24,1,4.000000e+000,8.968048e-001,0.000000e+000,0,,0,
1418241993.017,,1.000000e+002,1.730618e+002,3.851667e-002,0.000000e+000,3,9.964777e-001,0.000000e+000,,,,,,,,,,,,,,24,1,4.000000e+000,8.899994e-001,0.000000e+000,0,,0,
1418242012.024,,1.000000e+002,1.721462e+002,3.866091e-002,0.000000e+000,3,9.965985e-001,0.000000e+000,,,,,,,,,,,,,,24,1,4.000000e+000,8.209991e-001,0.000000e+000,0,,0,
1418242031.774,,1.000000e+002,1.711668e+002,3.883670e-002,0.000000e+000,3,9.965963e-001,0.000000e+000,,,,,,,,,,,,,,24,1,4.000000e+000,8.599091e-001,0.000000e+000,0,,0,
1418242051.516,,1.000000e+002,1.702317e+002,3.885292e-002,0.000000e+000,3,9.889113e-001,0.000000e+000,,,,,,,,,,,,,,24,1,4.000000e+000,8.758087e-001,0.000000e+000,0,,0,
1418242071.383,,1.000000e+002,1.692444e+002,3.914605e-002,0.000000e+000,3,9.965384e-001,0.000000e+000,,,,,,,,,,,,,,24,1,4.000000e+000,8.880005e-001,0.000000e+000,0,,0,
1418242092.164,,1.000000e+002,1.682820e+002,3.932279e-002,0.000000e+000,3,9.964829e-001,0.000000e+000,,,,,,,,,,,,,,24,1,4.000000e+000,9.273071e-001,0.000000e+000,0,,0,
1418242113.945,,1.000000e+002,1.672681e+002,3.950559e-002,0.000000e+000,3,9.964459e-001,0.000000e+000,,,,,,,,,,,,,,24,1,4.000000e+000,9.811096e-001,0.000000e+000,0,,0,
1418242134.718,,1.000000e+002,1.662551e+002,3.968884e-002,0.000000e+000,3,9.965182e-001,0.000000e+000,,,,,,,,,,,,,,24,1,4.000000e+000,9.270020e-001,0.000000e+000,0,,0,
1418242154.975,,1.000000e+002,1.652961e+002,3.988489e-002,0.000000e+000,3,9.965378e-001,0.000000e+000,,,,,,,,,,,,,,24,1,4.000000e+000,8.744965e-001,0.000000e+000,0,,0,
1418242175.546,,1.000000e+002,1.643636e+002,4.004850e-002,0.000000e+000,3,9.965596e-001,0.000000e+000,,,,,,,,,,,,,,24,1,4.000000e+000,8.753052e-001,0.000000e+000,0,,0,
1418242195.287,,1.000000e+002,1.633923e+002,4.019001e-002,0.000000e+000,3,9.966156e-001,0.000000e+000,,,,,,,,,,,,,,24,1,4.000000e+000,8.291931e-001,0.000000e+000,0,,0,
1418242216.193,,1.000000e+002,1.624478e+002,4.038860e-002,0.000000e+000,3,9.964619e-001,0.000000e+000,,,,,,,,,,,,,,24,1,4.000000e+000,9.470978e-001,0.000000e+000,0,,0,
1418242236.529,,1.000000e+002,1.614040e+002,4.055000e-002,0.000000e+000,3,9.965518e-001,0.000000e+000,,,,,,,,,,,,,,24,1,4.000000e+000,8.973999e-001,0.000000e+000,0,,0,
1418242256.959,,1.000000e+002,1.604059e+002,4.074731e-002,0.000000e+000,3,9.965231e-001,0.000000e+000,,,,,,,,,,,,,,24,1,4.000000e+000,9.788971e-001,0.000000e+000,0,,0,
1418242277.880,,1.000000e+002,1.593983e+002,4.095975e-002,0.000000e+000,3,9.965538e-001,0.000000e+000,,,,,,,,,,,,,,24,1,4.000000e+000,9.178925e-001,0.000000e+000,0,,0,
1418242297.833,,1.000000e+002,1.584078e+002,4.111527e-002,0.000000e+000,3,9.965777e-001,0.000000e+000,,,,,,,,,,,,,,24,1,4.000000e+000,9.359894e-001,0.000000e+000,0,,0,
1418242316.427,,1.000000e+002,1.574362e+002,4.129229e-002,0.000000e+000,3,9.966009e-001,0.000000e+000,,,,,,,,,,,,,,24,1,4.000000e+000,8.818054e-001,0.000000e+000,0,,0,
1418242337.208,,1.000000e+002,1.564221e+002,4.151591e-002,0.000000e+000,3,9.965290e-001,0.000000e+000,,,,,,,,,,,,,,24,1,4.000000e+000,9.654999e-001,0.000000e+000,0,,0,
1418242357.215,,1.000000e+002,1.554344e+002,4.169476e-002,0.000000e+000,3,9.965566e-001,0.000000e+000,,,,,,,,,,,,,,24,1,4.000000e+000,1.009796e+000,0.000000e+000,0,,0,
1418242376.840,,1.000000e+002,1.544259e+002,4.189515e-002,0.000000e+000,3,9.965136e-001,0.000000e+000,,,,,,,,,,,,,,24,1,4.000000e+000,8.863983e-001,0.000000e+000,0,,0,
1418242395.949,,1.000000e+002,1.534805e+002,4.206010e-002,0.000000e+000,3,9.966142e-001,0.000000e+000,,,,,,,,,,,,,,24,1,4.000000e+000,8.760071e-001,0.000000e+000,0,,0,
1418242416.019,,1.000000e+002,1.525012e+002,4.225320e-002,0.000000e+000,3,9.965808e-001,0.000000e+000,,,,,,,,,,,,,,24,1,4.000000e+000,8.921967e-001,0.000000e+000,0,,0,
1418242436.488,,1.000000e+002,1.515139e+002,4.248344e-002,0.000000e+000,3,9.965652e-001,0.000000e+000,,,,,,,,,,,,,,24,1,4.000000e+000,9.122009e-001,0.000000e+000,0,,0,
1418242456.151,,1.000000e+002,1.505717e+002,4.263689e-002,0.000000e+000,3,9.965918e-001,0.000000e+000,,,,,,,,,,,,,,24,1,4.000000e+000,8.661041e-001,0.000000e+000,0,,0,
1418242474.589,,1.000000e+002,1.496102e+002,4.282541e-002,0.000000e+000,3,9.965536e-001,0.000000e+000,,,,,,,,,,,,,,24,1,4.000000e+000,8.034058e-001,0.000000e+000,0,,0,
1418242493.823,,1.000000e+002,1.487123e+002,4.302293e-002,0.000000e+000,3,9.965860e-001,0.000000e+000,,,,,,,,,,,,,,24,1,4.000000e+000,8.542023e-001,0.000000e+000,0,,0,
1418242513.705,,1.000000e+002,1.477993e+002,4.321149e-002,0.000000e+000,3,9.964450e-001,0.000000e+000,,,,,,,,,,,,,,24,1,4.000000e+000,8.524933e-001,0.000000e+000,0,,0,
1418242533.330,,1.000000e+002,1.468823e+002,4.338891e-002,0.000000e+000,3,9.965271e-001,0.000000e+000,,,,,,,,,,,,,,24,1,4.000000e+000,8.632965e-001,0.000000e+000,0,,0,
1418242554.009,,1.000000e+002,1.459329e+002,4.357808e-002,0.000000e+000,3,9.960147e-001,0.000000e+000,,,,,,,,,,,,,,24,1,4.000000e+000,9.188080e-001,0.000000e+000,0,,0,
1418242574.869,,1.000000e+002,1.448910e+002,4.381590e-002,0.000000e+000,3,9.964856e-001,0.000000e+000,,,,,,,,,,,,,,24,1,4.000000e+000,9.265900e-001,0.000000e+000,0,,0,
1418242594.790,,1.000000e+002,1.439256e+002,4.400859e-002,0.000000e+000,3,9.965833e-001,0.000000e+000,,,,,,,,,,,,,,24,1,4.000000e+000,8.743896e-001,0.000000e+000,0,,0,
1418242615.665,,1.000000e+002,1.429756e+002,4.423106e-002,0.000000e+000,3,9.966214e-001,0.000000e+000,,,,,,,,,,,,,,24,1,4.000000e+000,9.053955e-001,0.000000e+000,0,,0,
1418242636.001,,1.000000e+002,1.419824e+002,4.445680e-002,0.000000e+000,3,9.965402e-001,0.000000e+000,,,,,,,,,,,,,,24,1,4.000000e+000,9.546051e-001,0.000000e+000,0,,0,
1418242656.047,,1.000000e+002,1.409907e+002,4.466479e-002,0.000000e+000,3,9.965032e-001,0.000000e+000,,,,,,,,,,,,,,24,1,4.000000e+000,8.961029e-001,0.000000e+000,0,,0,
1418242676.875,,1.000000e+002,1.399715e+002,4.486024e-002,0.000000e+000,3,9.965217e-001,0.000000e+000,,,,,,,,,,,,,,24,1,4.000000e+000,9.418945e-001,0.000000e+000,0,,0,
1418242696.289,,1.000000e+002,1.390103e+002,4.503838e-002,0.000000e+000,3,9.965484e-001,0.000000e+000,,,,,,,,,,,,,,24,1,4.000000e+000,8.509064e-001,0.000000e+000,0,,0,
1418242716.101,,1.000000e+002,1.380258e+002,4.528710e-002,0.000000e+000,3,9.964953e-001,0.000000e+000,,,,,,,,,,,,,,24,1,4.000000e+000,8.625031e-001,0.000000e+000,0,,0,
1418242734.991,,1.000000e+002,1.370298e+002,4.547991e-002,0.000000e+000,3,9.964220e-001,0.000000e+000,,,,,,,,,,,,,,24,1,4.000000e+000,8.625031e-001,0.000000e+000,0,,0,
1418242754.116,,1.000000e+002,1.360958e+002,4.568766e-002,0.000000e+000,3,9.963983e-001,0.000000e+000,,,,,,,,,,,,,,24,1,4.000000e+000,8.592987e-001,0.000000e+000,0,,0,
1418242773.499,,1.000000e+002,1.351191e+002,4.590290e-002,0.000000e+000,3,9.963699e-001,0.000000e+000,,,,,,,,,,,,,,24,1,4.000000e+000,8.769073e-001,0.000000e+000,0,,0,
1418242792.874,,1.000000e+002,1.341851e+002,4.612509e-002,0.000000e+000,3,9.963185e-001,0.000000e+000,,,,,,,,,,,,,,24,1,4.000000e+000,8.553925e-001,0.000000e+000,0,,0,
1418242813.592,,1.000000e+002,1.332052e+002,4.631930e-002,0.000000e+000,3,9.964954e-001,0.000000e+000,,,,,,,,,,,,,,24,1,4.000000e+000,9.844055e-001,0.000000e+000,0,,0,
1418242833.623,,1.000000e+002,1.322234e+002,4.653232e-002,0.000000e+000,3,9.965423e-001,0.000000e+000,,,,,,,,,,,,,,24,1,4.000000e+000,8.538971e-001,0.000000e+000,0,,0,
1418242852.881,,1.000000e+002,1.312411e+002,4.676981e-002,0.000000e+000,3,9.965581e-001,0.000000e+000,,,,,,,,,,,,,,24,1,4.000000e+000,8.562927e-001,0.000000e+000,0,,0,
1418242872.537,,1.000000e+002,1.303190e+002,4.698857e-002,0.000000e+000,3,9.965583e-001,0.000000e+000,,,,,,,,,,,,,,24,1,4.000000e+000,8.591003e-001,0.000000e+000,0,,0,
1418242892.154,,1.000000e+002,1.293420e+002,4.719553e-002,0.000000e+000,3,9.965435e-001,0.000000e+000,,,,,,,,,,,,,,24,1,4.000000e+000,8.741913e-001,0.000000e+000,0,,0,
1418242911.411,,1.000000e+002,1.284025e+002,4.741955e-002,0.000000e+000,3,9.966167e-001,0.000000e+000,,,,,,,,,,,,,,24,1,4.000000e+000,8.727036e-001,0.000000e+000,0,,0,
1418242931.153,,1.000000e+002,1.274589e+002,4.763844e-002,0.000000e+000,3,9.965371e-001,0.000000e+000,,,,,,,,,,,,,,24,1,4.000000e+000,8.840027e-001,0.000000e+000,0,,0,
1418242950.403,,1.000000e+002,1.264850e+002,4.784686e-002,0.000000e+000,3,9.966457e-001,0.000000e+000,,,,,,,,,,,,,,24,1,4.000000e+000,8.846970e-001,0.000000e+000,0,,0,
1418242970.153,,1.000000e+002,1.255163e+002,4.809044e-002,0.000000e+000,3,9.966329e-001,0.000000e+000,,,,,,,,,,,,,,24,1,4.000000e+000,9.068069e-001,0.000000e+000,0,,0,
1418242988.996,,1.000000e+002,1.245208e+002,4.830027e-002,0.000000e+000,3,9.966428e-001,0.000000e+000,,,,,,,,,,,,,,24,1,4.000000e+000,8.344040e-001,0.000000e+000,0,,0,
1418243008.379,,1.000000e+002,1.236197e+002,4.852176e-002,0.000000e+000,3,9.966118e-001,0.000000e+000,,,,,,,,,,,,,,24,1,4.000000e+000,8.262024e-001,0.000000e+000,0,,0,
1418243028.535,,1.000000e+002,1.225999e+002,4.874611e-002,0.000000e+000,3,9.966174e-001,0.000000e+000,,,,,,,,,,,,,,24,1,4.000000e+000,9.459991e-001,0.000000e+000,0,,0,
1418243049.911,,1.000000e+002,1.215955e+002,4.899564e-002,0.000000e+000,3,9.966013e-001,0.000000e+000,,,,,,,,,,,,,,24,1,4.000000e+000,9.375000e-001,0.000000e+000,0,,0,
1418243070.781,,1.000000e+002,1.206003e+002,4.925013e-002,0.000000e+000,3,9.966093e-001,0.000000e+000,,,,,,,,,,,,,,24,1,4.000000e+000,9.289932e-001,0.000000e+000,0,,0,
1418243091.402,,1.000000e+002,1.196243e+002,4.949053e-002,0.000000e+000,3,9.965471e-001,0.000000e+000,,,,,,,,,,,,,,24,1,4.000000e+000,8.086014e-001,0.000000e+000,0,,0,
1418243111.671,,1.000000e+002,1.186733e+002,4.970450e-002,0.000000e+000,3,9.965509e-001,0.000000e+000,,,,,,,,,,,,,,24,1,4.000000e+000,8.420029e-001,0.000000e+000,0,,0,
1418243131.049,,1.000000e+002,1.177347e+002,4.992769e-002,0.000000e+000,3,9.965376e-001,0.000000e+000,,,,,,,,,,,,,,24,1,4.000000e+000,7.876053e-001,0.000000e+000,0,,0,
1418243151.302,,1.000000e+002,1.168187e+002,5.017325e-002,0.000000e+000,3,9.964724e-001,0.000000e+000,,,,,,,,,,,,,,24,1,4.000000e+000,9.166031e-001,0.000000e+000,0,,0,
1418243170.399,,1.000000e+002,1.159312e+002,5.040014e-002,0.000000e+000,3,9.964720e-001,0.000000e+000,,,,,,,,,,,,,,24,1,4.000000e+000,7.381973e-001,0.000000e+000,0,,0,
1418243189.348,,1.000000e+002,1.150235e+002,5.060566e-002,0.000000e+000,3,9.964345e-001,0.000000e+000,,,,,,,,,,,,,,24,1,4.000000e+000,8.077011e-001,0.000000e+000,0,,0,
1418243208.359,,1.000000e+002,1.141195e+002,5.082428e-002,0.000000e+000,3,9.964002e-001,0.000000e+000,,,,,,,,,,,,,,24,1,4.000000e+000,7.985992e-001,0.000000e+000,0,,0,
1418243227.479,,1.000000e+002,1.131834e+002,5.103603e-002,0.000000e+000,3,9.964913e-001,0.000000e+000,,,,,,,,,,,,,,24,1,4.000000e+000,8.537979e-001,0.000000e+000,0,,0,
1418243247.725,,1.000000e+002,1.122692e+002,5.124088e-002,0.000000e+000,3,9.965312e-001,0.000000e+000,,,,,,,,,,,,,,24,1,4.000000e+000,9.745026e-001,0.000000e+000,0,,0,
1418243267.392,,1.000000e+002,1.112872e+002,5.147868e-002,0.000000e+000,3,9.964772e-001,0.000000e+000,,,,,,,,,,,,,,24,1,4.000000e+000,8.578033e-001,0.000000e+000,0,,0,
1418243286.489,,1.000000e+002,1.103561e+002,5.171109e-002,0.000000e+000,3,9.964732e-001,0.000000e+000,,,,,,,,,,,,,,24,1,4.000000e+000,8.695984e-001,0.000000e+000,0,,0,
1418243305.477,,1.000000e+002,1.094086e+002,5.194565e-002,0.000000e+000,3,9.965143e-001,0.000000e+000,,,,,,,,,,,,,,24,1,4.000000e+000,8.877029e-001,0.000000e+000,0,,0,
1418243325.488,,1.000000e+002,1.084565e+002,5.218703e-002,0.000000e+000,3,9.964185e-001,0.000000e+000,,,,,,,,,,,,,,24,1,4.000000e+000,8.760986e-001,0.000000e+000,0,,0,
1418243344.749,,1.000000e+002,1.074672e+002,5.242359e-002,0.000000e+000,3,9.964955e-001,0.000000e+000,,,,,,,,,,,,,,24,1,4.000000e+000,8.168030e-001,0.000000e+000,0,,0,
1418243364.117,,1.000000e+002,1.064669e+002,5.263515e-002,0.000000e+000,3,9.964956e-001,0.000000e+000,,,,,,,,,,,,,,24,1,4.000000e+000,8.934937e-001,0.000000e+000,0,,0,
1418243383.508,,1.000000e+002,1.055336e+002,5.286342e-002,0.000000e+000,3,9.964895e-001,0.000000e+000,,,,,,,,,,,,,,24,1,4.000000e+000,9.731064e-001,0.000000e+000,0,,0,
1418243401.790,,1.000000e+002,1.046310e+002,5.308198e-002,0.000000e+000,3,9.965556e-001,0.000000e+000,,,,,,,,,,,,,,24,1,4.000000e+000,8.320999e-001,0.000000e+000,0,,0,
1418243420.245,,1.000000e+002,1.036622e+002,5.331022e-002,0.000000e+000,3,9.965045e-001,0.000000e+000,,,,,,,,,,,,,,24,1,4.000000e+000,8.512955e-001,0.000000e+000,0,,0,
1418243439.191,,1.000000e+002,1.027150e+002,5.355480e-002,0.000000e+000,3,9.965735e-001,0.000000e+000,,,,,,,,,,,,,,24,1,4.000000e+000,9.113007e-001,0.000000e+000,0,,0,
1418243458.856,,1.000000e+002,1.017739e+002,5.379662e-002,0.000000e+000,3,9.964947e-001,0.000000e+000,,,,,,,,,,,,,,24,1,4.000000e+000,9.710007e-001,0.000000e+000,0,,0,
1418243477.544,,1.000000e+002,1.008309e+002,5.402259e-002,0.000000e+000,3,9.965633e-001,0.000000e+000,,,,,,,,,,,,,,24,1,4.000000e+000,9.149017e-001,0.000000e+000,0,,0,
1418243495.662,,1.000000e+002,9.990868e+001,5.423636e-002,0.000000e+000,3,9.965736e-001,0.000000e+000,,,,,,,,,,,,,,24,1,4.000000e+000,8.004379e-001,0.000000e+000,0,,0,
1418243514.163,,1.000000e+002,9.901643e+001,5.444273e-002,0.000000e+000,3,9.965551e-001,0.000000e+000,,,,,,,,,,,,,,24,1,4.000000e+000,8.567734e-001,0.000000e+000,0,,0,
1418243532.985,,1.000000e+002,9.809044e+001,5.464074e-002,0.000000e+000,3,9.966236e-001,0.000000e+000,,,,,,,,,,,,,,24,1,4.000000e+000,8.660507e-001,0.000000e+000,0,,0,
1418243552.040,,1.000000e+002,9.713305e+001,5.485415e-002,0.000000e+000,3,9.965932e-001,0.000000e+000,,,,,,,,,,,,,,24,1,4.000000e+000,8.426361e-001,0.000000e+000,0,,0,
1418243572.424,,1.000000e+002,9.611145e+001,5.508073e-002,0.000000e+000,3,9.966866e-001,0.000000e+000,,,,,,,,,,,,,,24,1,4.000000e+000,9.631348e-001,0.000000e+000,0,,0,
1418243591.816,,1.000000e+002,9.511061e+001,5.527189e-002,0.000000e+000,3,9.967292e-001,0.000000e+000,,,,,,,,,,,,,,24,1,4.000000e+000,9.050522e-001,0.000000e+000,0,,0,
1418243610.278,,1.000000e+002,9.419958e+001,5.546144e-002,0.000000e+000,3,9.966952e-001,0.000000e+000,,,,,,,,,,,,,,24,1,4.000000e+000,9.169846e-001,0.000000e+000,0,,0,
1418243631.240,,1.000000e+002,9.314850e+001,5.567830e-002,0.000000e+000,3,9.966901e-001,0.000000e+000,,,,,,,,,,,,,,24,1,4.000000e+000,1.049171e+000,0.000000e+000,0,,0,
1418243650.678,,1.000000e+002,9.207825e+001,5.588976e-002,0.000000e+000,3,9.966543e-001,0.000000e+000,,,,,,,,,,,,,,24,1,4.000000e+000,8.936005e-001,0.000000e+000,0,,0,
1418243669.303,,1.000000e+002,9.106769e+001,5.607752e-002,0.000000e+000,3,9.966446e-001,0.000000e+000,,,,,,,,,,,,,,24,1,4.000000e+000,8.878860e-001,0.000000e+000,0,,0,
1418243688.428,,1.000000e+002,9.011916e+001,5.626565e-002,0.000000e+000,3,9.967384e-001,0.000000e+000,,,,,,,,,,,,,,24,1,4.000000e+000,8.709793e-001,0.000000e+000,0,,0,
1418243707.991,,1.000000e+002,8.907750e+001,5.644579e-002,0.000000e+000,3,9.967335e-001,0.000000e+000,,,,,,,,,,,,,,24,1,4.000000e+000,9.447403e-001,0.000000e+000,0,,0,
1418243725.695,,1.000000e+002,8.813332e+001,5.659783e-002,0.000000e+000,3,9.967346e-001,0.000000e+000,,,,,,,,,,,,,,24,1,4.000000e+000,8.077011e-001,0.000000e+000,0,,0,
1418243744.476,,1.000000e+002,8.718909e+001,5.677431e-002,0.000000e+000,3,9.967395e-001,0.000000e+000,,,,,,,,,,,,,,24,1,4.000000e+000,9.440231e-001,0.000000e+000,0,,0,
1418243764.304,,1.000000e+002,8.618552e+001,5.693178e-002,0.000000e+000,3,9.967563e-001,0.000000e+000,,,,,,,,,,,,,,24,1,4.000000e+000,9.323883e-001,0.000000e+000,0,,0,
1418243783.102,,1.000000e+002,8.521549e+001,5.708239e-002,0.000000e+000,3,9.967630e-001,0.000000e+000,,,,,,,,,,,,,,24,1,4.000000e+000,8.702698e-001,0.000000e+000,0,,0,
1418243801.844,,1.000000e+002,8.427511e+001,5.722242e-002,0.000000e+000,3,9.967585e-001,0.000000e+000,,,,,,,,,,,,,,24,1,4.000000e+000,8.757782e-001,0.000000e+000,0,,0,
1418243820.235,,1.000000e+002,8.332730e+001,5.734724e-002,0.000000e+000,3,9.967630e-001,0.000000e+000,,,,,,,,,,,,,,24,1,4.000000e+000,8.878403e-001,0.000000e+000,0,,0,
1418243839.852,,1.000000e+002,8.233916e+001,5.749757e-002,0.000000e+000,3,9.967236e-001,0.000000e+000,,,,,,,,,,,,,,24,1,4.000000e+000,9.561996e-001,0.000000e+000,0,,0,
1418243859.345,,1.000000e+002,8.138477e+001,5.761760e-002,0.000000e+000,3,9.966968e-001,0.000000e+000,,,,,,,,,,,,,,24,1,4.000000e+000,9.525757e-001,0.000000e+000,0,,0,
1418243878.095,,1.000000e+002,8.037190e+001,5.773556e-002,0.000000e+000,3,9.967071e-001,0.000000e+000,,,,,,,,,,,,,,24,1,4.000000e+000,9.323959e-001,0.000000e+000,0,,0,
1418243897.267,,1.000000e+002,7.938644e+001,5.785052e-002,0.000000e+000,3,9.966977e-001,0.000000e+000,,,,,,,,,,,,,,24,1,4.000000e+000,9.283829e-001,0.000000e+000,0,,0,
1418243916.244,,1.000000e+002,7.831988e+001,5.795345e-002,0.000000e+000,3,9.967020e-001,0.000000e+000,,,,,,,,,,,,,,24,1,4.000000e+000,9.357300e-001,0.000000e+000,0,,0,
1418243934.846,,1.000000e+002,7.733813e+001,5.805072e-002,0.000000e+000,3,9.967552e-001,0.000000e+000,,,,,,,,,,,,,,24,1,4.000000e+000,8.858643e-001,0.000000e+000,0,,0,
1418243953.744,,1.000000e+002,7.635876e+001,5.814701e-002,0.000000e+000,3,9.967441e-001,0.000000e+000,,,,,,,,,,,,,,24,1,4.000000e+000,9.495239e-001,0.000000e+000,0,,0,
1418243974.072,,1.000000e+002,7.531490e+001,5.823905e-002,0.000000e+000,3,9.967071e-001,0.000000e+000,,,,,,,,,,,,,,24,1,4.000000e+000,1.027809e+000,0.000000e+000,0,,0,
1418243993.854,,1.000000e+002,7.424731e+001,5.832105e-002,0.000000e+000,3,9.967532e-001,0.000000e+000,,,,,,,,,,,,,,24,1,4.000000e+000,9.655457e-001,0.000000e+000,0,,0,
1418244013.174,,1.000000e+002,7.317088e+001,5.840572e-002,0.000000e+000,3,9.967677e-001,0.000000e+000,,,,,,,,,,,,,,24,1,4.000000e+000,1.020508e+000,0.000000e+000,0,,0,
1418244032.604,,1.000000e+002,7.210439e+001,5.847881e-002,0.000000e+000,3,9.967920e-001,0.000000e+000,,,,,,,,,,,,,,24,1,4.000000e+000,9.825287e-001,0.000000e+000,0,,0,
1418244053.213,,1.000000e+002,7.101372e+001,5.854426e-002,0.000000e+000,3,9.967948e-001,0.000000e+000,,,,,,,,,,,,,,24,1,4.000000e+000,1.054138e+000,0.000000e+000,0,,0,
1418244071.268,,1.000000e+002,6.998433e+001,5.859957e-002,0.000000e+000,3,9.967983e-001,0.000000e+000,,,,,,,,,,,,,,24,1,4.000000e+000,8.771820e-001,0.000000e+000,0,,0,
1418244090.268,,1.000000e+002,6.897214e+001,5.865476e-002,0.000000e+000,3,9.968021e-001,0.000000e+000,,,,,,,,,,,,,,24,1,4.000000e+000,1.022781e+000,0.000000e+000,0,,0,
1418244109.268,,1.000000e+002,6.791290e+001,5.869956e-002,0.000000e+000,3,9.967737e-001,0.000000e+000,,,,,,,,,,,,,,24,1,4.000000e+000,9.456253e-001,0.000000e+000,0,,0,
1418244128.525,,1.000000e+002,6.685483e+001,5.873964e-002,0.000000e+000,3,9.968002e-001,0.000000e+000,,,,,,,,,,,,,,24,1,4.000000e+000,1.024521e+000,0.000000e+000,0,,0,
1418244148.127,,1.000000e+002,6.577350e+001,5.877971e-002,0.000000e+000,3,9.967250e-001,0.000000e+000,,,,,,,,,,,,,,24,1,4.000000e+000,9.768295e-001,0.000000e+000,0,,0,
1418244167.635,,1.000000e+002,6.469185e+001,5.881492e-002,0.000000e+000,3,9.967846e-001,0.000000e+000,,,,,,,,,,,,,,24,1,4.000000e+000,1.056564e+000,0.000000e+000,0,,0,
1418244186.377,,1.000000e+002,6.362373e+001,5.884193e-002,0.000000e+000,3,9.967757e-001,0.000000e+000,,,,,,,,,,,,,,24,1,4.000000e+000,9.427567e-001,0.000000e+000,0,,0,
1418244207.275,,1.000000e+002,6.247347e+001,5.886568e-002,0.000000e+000,3,9.967845e-001,0.000000e+000,,,,,,,,,,,,,,24,1,4.000000e+000,1.066959e+000,0.000000e+000,0,,0,
1418244227.127,,1.000000e+002,6.132984e+001,5.888581e-002,0.000000e+000,3,9.968029e-001,0.000000e+000,,,,,,,,,,,,,,24,1,4.000000e+000,1.088482e+000,0.000000e+000,0,,0,
1418244246.268,,1.000000e+002,6.019980e+001,5.889726e-002,0.000000e+000,3,9.967632e-001,0.000000e+000,,,,,,,,,,,,,,24,1,4.000000e+000,1.010719e+000,0.000000e+000,0,,0,
1418244266.018,,1.000000e+002,5.916069e+001,5.890687e-002,0.000000e+000,3,9.968385e-001,0.000000e+000,,,,,,,,,,,,,,24,1,4.000000e+000,1.067490e+000,0.000000e+000,0,,0,
1418244284.416,,1.000000e+002,5.810377e+001,5.891071e-002,0.000000e+000,3,9.968517e-001,0.000000e+000,,,,,,,,,,,,,,24,1,4.000000e+000,9.113121e-001,0.000000e+000,0,,0,
1418244302.268,,1.000000e+002,5.713659e+001,5.891368e-002,0.000000e+000,3,9.967796e-001,0.000000e+000,,,,,,,,,,,,,,24,1,4.000000e+000,8.828201e-001,0.000000e+000,0,,0,
1418244321.635,,1.000000e+002,5.619212e+001,5.891556e-002,0.000000e+000,3,9.968188e-001,0.000000e+000,,,,,,,,,,,,,,24,1,4.000000e+000,8.700409e-001,0.000000e+000,0,,0,
1418244341.018,,1.000000e+002,5.520586e+001,5.891066e-002,0.000000e+000,3,9.968253e-001,0.000000e+000,,,,,,,,,,,,,,24,1,4.000000e+000,8.500366e-001,0.000000e+000,0,,0,
1418244360.525,,1.000000e+002,5.425373e+001,5.890455e-002,0.000000e+000,3,9.968296e-001,0.000000e+000,,,,,,,,,,,,,,24,1,4.000000e+000,9.151001e-001,0.000000e+000,0,,0,
1418244379.674,,1.000000e+002,5.331294e+001,5.889686e-002,0.000000e+000,3,9.968277e-001,0.000000e+000,,,,,,,,,,,,,,24,1,4.000000e+000,8.425598e-001,0.000000e+000,0,,0,
1418244399.111,,1.000000e+002,5.235776e+001,5.888508e-002,0.000000e+000,3,9.967991e-001,0.000000e+000,,,,,,,,,,,,,,24,1,4.000000e+000,8.197289e-001,0.000000e+000,0,,0,
1418244417.979,,1.000000e+002,5.147949e+001,5.887401e-002,0.000000e+000,3,9.968058e-001,0.000000e+000,,,,,,,,,,,,,,24,1,4.000000e+000,8.228798e-001,0.000000e+000,0,,0,
1418244435.807,,1.000000e+002,5.062242e+001,5.886039e-002,0.000000e+000,3,9.968109e-001,0.000000e+000,,,,,,,,,,,,,,24,1,4.000000e+000,7.709007e-001,0.000000e+000,0,,0,
1418244453.682,,1.000000e+002,4.977908e+001,5.884674e-002,0.000000e+000,3,9.967732e-001,0.000000e+000,,,,,,,,,,,,,,24,1,4.000000e+000,7.941284e-001,0.000000e+000,0,,0,
1418244472.807,,1.000000e+002,4.888096e+001,5.883195e-002,0.000000e+000,3,9.967362e-001,0.000000e+000,,,,,,,,,,,,,,24,1,4.000000e+000,8.702202e-001,0.000000e+000,0,,0,
1418244490.182,,1.000000e+002,4.796248e+001,5.881580e-002,0.000000e+000,3,9.967446e-001,0.000000e+000,,,,,,,,,,,,,,24,1,4.000000e+000,8.280602e-001,0.000000e+000,0,,0,
1418244508.830,,1.000000e+002,4.709305e+001,5.879657e-002,0.000000e+000,3,9.967347e-001,0.000000e+000,,,,,,,,,,,,,,24,1,4.000000e+000,9.108009e-001,0.000000e+000,0,,0,
1418244527.572,,1.000000e+002,4.614425e+001,5.877784e-002,0.000000e+000,3,9.967217e-001,0.000000e+000,,,,,,,,,,,,,,24,1,4.000000e+000,8.614883e-001,0.000000e+000,0,,0,
1418244546.924,,1.000000e+002,4.516867e+001,5.875847e-002,0.000000e+000,3,9.967154e-001,0.000000e+000,,,,,,,,,,,,,,24,1,4.000000e+000,9.808578e-001,0.000000e+000,0,,0,
1418244566.494,,1.000000e+002,4.415232e+001,5.873850e-002,0.000000e+000,3,9.967468e-001,0.000000e+000,,,,,,,,,,,,,,24,1,4.000000e+000,9.339218e-001,0.000000e+000,0,,0,
1418244585.939,,1.000000e+002,4.316391e+001,5.871583e-002,0.000000e+000,3,9.967870e-001,0.000000e+000,,,,,,,,,,,,,,24,1,4.000000e+000,9.278030e-001,0.000000e+000,0,,0,
1418244604.939,,1.000000e+002,4.219572e+001,5.869616e-002,0.000000e+000,3,9.967768e-001,0.000000e+000,,,,,,,,,,,,,,24,1,4.000000e+000,8.891678e-001,0.000000e+000,0,,0,
1418244623.540,,1.000000e+002,4.121535e+001,5.867460e-002,0.000000e+000,3,9.968031e-001,0.000000e+000,,,,,,,,,,,,,,24,1,4.000000e+000,8.287201e-001,0.000000e+000,0,,0,
1418244642.180,,1.000000e+002,4.023571e+001,5.865438e-002,0.000000e+000,3,9.967379e-001,0.000000e+000,,,,,,,,,,,,,,24,1,4.000000e+000,8.859024e-001,0.000000e+000,0,,0,
1418244661.680,,1.000000e+002,3.927559e+001,5.863516e-002,0.000000e+000,3,9.967630e-001,0.000000e+000,,,,,,,,,,,,,,24,1,4.000000e+000,9.037590e-001,0.000000e+000,0,,0,
1418244681.219,,1.000000e+002,3.829272e+001,5.861443e-002,0.000000e+000,3,9.968003e-001,0.000000e+000,,,,,,,,,,,,,,24,1,4.000000e+000,9.323997e-001,0.000000e+000,0,,0,
1418244700.523,,1.000000e+002,3.718325e+001,5.859281e-002,0.000000e+000,3,9.967702e-001,0.000000e+000,,,,,,,,,,,,,,24,1,4.000000e+000,9.176712e-001,0.000000e+000,0,,0,
1418244719.461,,1.000000e+002,3.620827e+001,5.857199e-002,0.000000e+000,3,9.967640e-001,0.000000e+000,,,,,,,,,,,,,,24,1,4.000000e+000,9.264679e-001,0.000000e+000,0,,0,
1418244737.585,,1.000000e+002,3.520124e+001,5.855381e-002,0.000000e+000,3,9.967716e-001,0.000000e+000,,,,,,,,,,,,,,24,1,4.000000e+000,8.731689e-001,0.000000e+000,0,,0,
1418244757.085,,1.000000e+002,3.422236e+001,5.853448e-002,0.000000e+000,3,9.967360e-001,0.000000e+000,,,,,,,,,,,,,,24,1,4.000000e+000,9.700813e-001,0.000000e+000,0,,0,
1418244776.468,,1.000000e+002,3.318407e+001,5.851791e-002,0.000000e+000,3,9.967518e-001,0.000000e+000,,,,,,,,,,,,,,24,1,4.000000e+000,9.949608e-001,0.000000e+000,0,,0,
1418244795.975,,1.000000e+002,3.214559e+001,5.850247e-002,0.000000e+000,3,9.967677e-001,0.000000e+000,,,,,,,,,,,,,,24,1,4.000000e+000,9.626198e-001,0.000000e+000,0,,0,
1418244816.217,,1.000000e+002,3.102797e+001,5.848668e-002,0.000000e+000,3,9.967673e-001,0.000000e+000,,,,,,,,,,,,,,24,1,4.000000e+000,1.044500e+000,0.000000e+000,0,,0,
1418244835.217,,1.000000e+002,2.997089e+001,5.847827e-002,0.000000e+000,3,9.967396e-001,0.000000e+000,,,,,,,,,,,,,,24,1,4.000000e+000,9.466496e-001,0.000000e+000,0,,0,
1418244854.717,,1.000000e+002,2.888979e+001,5.846742e-002,0.000000e+000,3,9.967189e-001,0.000000e+000,,,,,,,,,,,,,,24,1,4.000000e+000,1.083450e+000,0.000000e+000,0,,0,
1418244875.115,,1.000000e+002,2.776254e+001,5.845746e-002,0.000000e+000,3,9.967514e-001,0.000000e+000,,,,,,,,,,,,,,24,1,4.000000e+000,1.043760e+000,0.000000e+000,0,,0,
1418244896.333,,1.000000e+002,2.657435e+001,5.845292e-002,0.000000e+000,3,9.967452e-001,0.000000e+000,,,,,,,,,,,,,,24,1,4.000000e+000,1.206141e+000,0.000000e+000,0,,0,
1418244915.966,,1.000000e+002,2.535146e+001,5.845007e-002,0.000000e+000,3,9.967844e-001,0.000000e+000,,,,,,,,,,,,,,24,1,4.000000e+000,1.108889e+000,0.000000e+000,0,,0,
1418244934.630,,1.000000e+002,2.443958e+001,5.845076e-002,0.000000e+000,3,9.967637e-001,0.000000e+000,,,,,,,,,,,,,,24,1,4.000000e+000,5.743618e-001,0.000000e+000,0,,0,
1418244954.458,,1.000000e+002,2.361039e+001,5.845229e-002,0.000000e+000,3,9.967635e-001,0.000000e+000,,,,,,,,,,,,,,24,1,4.000000e+000,9.854908e-001,0.000000e+000,0,,0,
1418244973.895,,1.000000e+002,2.260876e+001,5.845539e-002,0.000000e+000,3,9.967277e-001,0.000000e+000,,,,,,,,,,,,,,24,1,4.000000e+000,8.243294e-001,0.000000e+000,0,,0,
1418244992.754,,1.000000e+002,2.163953e+001,5.845854e-002,0.000000e+000,3,9.967490e-001,0.000000e+000,,,,,,,,,,,,,,24,1,4.000000e+000,8.836803e-001,0.000000e+000,0,,0,
1418245011.808,,1.000000e+002,2.072198e+001,5.846427e-002,0.000000e+000,3,9.967560e-001,0.000000e+000,,,,,,,,,,,,,,24,1,4.000000e+000,8.217888e-001,0.000000e+000,0,,0,
1418245032.339,,1.000000e+002,1.974416e+001,5.847257e-002,0.000000e+000,3,9.967910e-001,0.000000e+000,,,,,,,,,,,,,,24,1,4.000000e+000,1.013170e+000,0.000000e+000,0,,0,
1418245053.597,,1.000000e+002,1.870665e+001,5.848183e-002,0.000000e+000,3,9.967893e-001,0.000000e+000,,,,,,,,,,,,,,24,1,4.000000e+000,9.329891e-001,0.000000e+000,0,,0,
1418245072.909,,1.000000e+002,1.771929e+001,5.849027e-002,0.000000e+000,3,9.967745e-001,0.000000e+000,,,,,,,,,,,,,,24,1,4.000000e+000,8.391609e-001,0.000000e+000,0,,0,
1418245091.511,,1.000000e+002,1.683752e+001,5.850170e-002,0.000000e+000,3,9.968453e-001,0.000000e+000,,,,,,,,,,,,,,24,1,4.000000e+000,7.766304e-001,0.000000e+000,0,,0,
1418245110.753,,1.000000e+002,1.598755e+001,5.851530e-002,0.000000e+000,3,9.967885e-001,0.000000e+000,,,,,,,,,,,,,,24,1,4.000000e+000,7.933893e-001,0.000000e+000,0,,0,
1418245130.323,,1.000000e+002,1.498711e+001,5.826809e-002,0.000000e+000,3,9.951119e-001,0.000000e+000,,,,,,,,,,,,,,24,1,4.000000e+000,1.087999e+000,0.000000e+000,0,,0,
1418245149.010,,1.000000e+002,1.410196e+001,5.853871e-002,0.000000e+000,3,9.967834e-001,0.000000e+000,,,,,,,,,,,,,,24,1,4.000000e+000,5.632896e-001,0.000000e+000,0,,0,
1418245169.135,,1.000000e+002,1.308837e+001,5.862607e-002,0.000000e+000,3,9.966422e-001,0.000000e+000,,,,,,,,,,,,,,24,1,4.000000e+000,1.289130e+000,0.000000e+000,0,,0,
1418245189.009,,1.000000e+002,1.188690e+001,5.856900e-002,0.000000e+000,3,9.967924e-001,0.000000e+000,,,,,,,,,,,,,,24,1,4.000000e+000,1.030581e+000,0.000000e+000,0,,0,
1418245211.150,,1.000000e+002,1.105280e+001,5.858033e-002,0.000000e+000,3,9.967863e-001,0.000000e+000,,,,,,,,,,,,,,24,1,4.000000e+000,5.644197e-001,0.000000e+000,0,,0,
1418245230.126,,1.000000e+002,1.032809e+001,5.863904e-002,0.000000e+000,3,9.969326e-001,0.000000e+000,,,,,,,,,,,,,,24,1,4.000000e+000,7.217302e-001,0.000000e+000,0,,0,
1418245249.759,,1.000000e+002,8.937799e+000,5.860343e-002,0.000000e+000,3,9.967730e-001,0.000000e+000,,,,,,,,,,,,,,24,1,4.000000e+000,1.972213e+000,0.000000e+000,0,,0,
1418245269.290,,1.000000e+002,7.826160e+000,5.863487e-002,0.000000e+000,3,9.968066e-001,0.000000e+000,,,,,,,,,,,,,,24,1,4.000000e+000,2.510662e-001,0.000000e+000,0,,0,
1418245289.047,,1.000000e+002,7.606404e+000,5.863898e-002,0.000000e+000,3,9.967669e-001,0.000000e+000,,,,,,,,,,,,,,24,1,4.000000e+000,1.917090e-001,0.000000e+000,0,,0,
1418245307.172,,1.000000e+002,6.183852e+000,5.865681e-002,0.000000e+000,3,9.967518e-001,0.000000e+000,,,,,,,,,,,,,,24,1,4.000000e+000,2.342399e+000,0.000000e+000,0,,0,
1418245325.789,,1.000000e+002,4.781574e+000,5.868823e-002,0.000000e+000,3,9.967333e-001,0.000000e+000,,,,,,,,,,,,,,24,1,4.000000e+000,4.873223e-001,0.000000e+000,0,,0,
1418245344.421,,1.000000e+002,4.423706e+000,5.869834e-002,0.000000e+000,3,9.967030e-001,0.000000e+000,,,,,,,,,,,,,,24,1,4.000000e+000,8.343029e-002,0.000000e+000,0,,0,
1418245364.296,,1.000000e+002,4.825339e+000,5.869490e-002,0.000000e+000,3,9.966784e-001,0.000000e+000,,,,,,,,,,,,,,24,1,4.000000e+000,8.551621e-001,0.000000e+000,0,,0,
1418245384.046,,1.000000e+002,5.540987e+000,5.868001e-002,0.000000e+000,3,9.966630e-001,0.000000e+000,,,,,,,,,,,,,,24,1,4.000000e+000,2.889271e-001,0.000000e+000,0,,0,
1418245403.678,,1.000000e+002,5.704905e+000,5.867183e-002,0.000000e+000,3,9.967143e-001,0.000000e+000,,,,,,,,,,,,,,24,1,4.000000e+000,3.561497e-002,0.000000e+000,0,,0,
1418245422.663,,1.000000e+002,5.711797e+000,5.867118e-002,0.000000e+000,3,9.966717e-001,0.000000e+000,,,,,,,,,,,,,,24,1,4.000000e+000,2.673960e-002,0.000000e+000,0,,0,
1418245442.912,,1.000000e+002,5.687473e+000,5.857820e-002,0.000000e+000,3,9.917847e-001,0.000000e+000,,,,,,,,,,,,,,24,1,4.000000e+000,2.897215e-002,0.000000e+000,0,,0,
1418245462.154,,1.000000e+002,5.877361e+000,5.866670e-002,0.000000e+000,3,9.966994e-001,0.000000e+000,,,,,,,,,,,,,,24,1,4.000000e+000,3.534541e-001,0.000000e+000,0,,0,
1418245481.826,,1.000000e+002,6.468596e+000,5.865519e-002,0.000000e+000,3,9.966978e-001,0.000000e+000,,,,,,,,,,,,,,24,1,4.000000e+000,7.637033e-001,0.000000e+000,0,,0,
1418245501.521,,1.000000e+002,7.554709e+000,5.863158e-002,0.000000e+000,3,9.967092e-001,0.000000e+000,,,,,,,,,,,,,,24,1,4.000000e+000,1.088248e+000,0.000000e+000,0,,0,
1418245521.622,,1.000000e+002,8.234327e+000,5.862110e-002,0.000000e+000,3,9.967451e-001,0.000000e+000,,,,,,,,,,,,,,24,1,4.000000e+000,1.805601e-001,0.000000e+000,0,,0,
1418245540.810,,1.000000e+002,8.341498e+000,5.861858e-002,0.000000e+000,3,9.967560e-001,0.000000e+000,,,,,,,,,,,,,,24,1,4.000000e+000,2.929497e-002,0.000000e+000,0,,0,
1418245559.903,,1.000000e+002,8.353884e+000,5.861893e-002,0.000000e+000,3,9.967342e-001,0.000000e+000,,,,,,,,,,,,,,24,1,4.000000e+000,3.391266e-003,0.000000e+000,0,,0,
1418245663.245,,1.000000e+002,7.830734e+000,5.862117e-002,0.000000e+000,3,9.968187e-001,0.000000e+000,,,,,,,,,,,,,,24,1,4.000000e+000,8.759451e-001,0.000000e+000,0,,0,
1418245682.136,,1.000000e+002,7.019343e+000,5.863770e-002,0.000000e+000,3,9.968031e-001,0.000000e+000,,,,,,,,,,,,,,24,1,4.000000e+000,5.862598e-001,0.000000e+000,0,,0,
1418245702.128,,1.000000e+002,6.175161e+000,5.865598e-002,0.000000e+000,3,9.968149e-001,0.000000e+000,,,,,,,,,,,,,,24,1,4.000000e+000,8.483448e-001,0.000000e+000,0,,0,
1418245721.495,,1.000000e+002,5.488702e+000,5.867177e-002,0.000000e+000,3,9.967783e-001,0.000000e+000,,,,,,,,,,,,,,24,1,4.000000e+000,4.982281e-001,0.000000e+000,0,,0,
1418245814.329,,1.000000e+002,5.001623e+000,5.867746e-002,0.000000e+000,3,9.967826e-001,0.000000e+000,,,,,,,,,,,,,,24,1,4.000000e+000,0.000000e+000,0.000000e+000,0,,0,