File: data/looselyPackedNP/ios-11/ppms/rawdata/PMK18_FCW_100OESLOW.DAT
[Header]
; VSM Data File (default extension .dat)
; Copyright (c) 2003-2013, Quantum Design, Inc. All rights reserved.
TITLE,
FILEOPENTIME,30409193.34,12/19/2018,7:01 am
BYAPP,VSM,2.0,2.0
INFO,PPMS VSM Option Release 1.4.10 Build 1,APPNAME
INFO,Quantum Design Linear Motor Servo Controller,MOTOR_MODULE_NAME
INFO,3101-100 M1,MOTOR_HW_VERSION
INFO,MMC1014,MOTOR_SERIAL_NUMBER
INFO,SRV No X-over 01.03.11,MOTOR_SOFTWARE_VERSION
INFO,Quantum Design VSM Detection Module,VSM_MODULE_NAME
INFO,3101-150 F0,VSM_HW_VERSION
INFO,VSM707,VSM_SERIAL_NUMBER
INFO,VSM No X-over 01.02.05 May 20 2008 13:51:47,VSM_SOFTWARE_VERSION
INFO,704,PREAMP_SERIAL_NUMBER
INFO,822,COIL_SERIAL_NUMBER
INFO,0,MOMENT_UNITS
INFO,Maghemite,SAMPLE_MATERIAL
INFO,Oleate Iron Spheres,SAMPLE_COMMENT
INFO,,SAMPLE_MASS
INFO,,SAMPLE_VOLUME
INFO,,SAMPLE_MOLECULAR_WEIGHT
INFO,,SAMPLE_SIZE
INFO,,SAMPLE_SHAPE
DATATYPE,COMMENT,1
DATATYPE,TIME,2
STARTUPAXIS,X,2
STARTUPAXIS,Y1,5
[Data]
Comment,Time Stamp (sec),Temperature (K),Magnetic Field (Oe),Moment (emu),M. Std. Err. (emu),Transport Action,Averaging Time (sec),Frequency (Hz),Peak Amplitude (mm),Center Position (mm),Coil Signal' (mV),Coil Signal" (mV),Range (mV),M. Quad. Signal (emu),M. Raw' (emu),M. Raw" (emu),Min. Temperature (K),Max. Temperature (K),Min. Field (Oe),Max. Field (Oe),Mass (grams),Motor Lag (deg),Pressure (Torr),VSM Status (code),Motor Status (code),Measure Status (code),Measure Count,PPMS Status (code),System Temp. (K),System Field (Oe),Sample Position (deg),Bridge 1 Resistance (ohms),Bridge 1 Excitation (에),Bridge 2 Resistance (ohms),Bridge 2 Excitation (에),Bridge 3 Resistance (ohms),Bridge 3 Excitation (에),Bridge 4 Resistance (ohms),Bridge 4 Excitation (에),Signal 1 Vin (V),Signal 2 Vin (V),Digital Inputs (code),Drive 1 Iout (mA),Drive 1 Ipower (W),Drive 2 Iout (mA),Drive 2 Ipower (W),Pressure (),Map 20 (),Map 21 (),Map 22 (),Map 23 (),Map 24 (),Map 25 (),Map 26 (),Map 27 (),Map 28 (),Map 29 ()
,30409209.77,10.0048647,99.7004928588867,,,2,,,,29.2999994564056,,,,,,,10.0048647,10.0048647,99.7004928588867,99.7004928588867,,,11.519473,,,,-99999999,4369,9.9958,99.7004928588867,,,,,,,,,,,,,,,,,,,,,,,10.0048647,,,,
,30409589.09,12.0082083,99.7004928588867,0.00396996938191531,4.94282944357057E-7,1,0.999253354069792,40.0298881530762,1.98045683263663,29.2899999767542,0.0441703836038538,0.00830641675177858,0.25,4.02527443963761E-5,0.00394696484285618,5.91678941125664E-5,12.0082083,12.0082083,99.7004928588867,99.7004928588867,56.8634747740445,20.5137789303748,12.278775,0,0,0,40,4370,12.02095,99.7004928588867,,,,,,,,,,,,,0,,,,0.00245,,,,,,12.0082083,,,,
,30409951.1,15.013133,99.7004928588867,0.00396362050537163,3.76755680501914E-7,1,0.999253354069792,40.0298881530762,1.98021000208959,29.279999434948,0.0440985524614867,0.00826740016148839,0.25,3.79735097498847E-5,0.00394063444593612,5.68707174861733E-5,15.013133,15.013133,99.7004928588867,99.7004928588867,56.9854088230445,20.5258499824022,13.038077,0,0,0,40,4370,15.0483,99.7004928588867,,,,,,,,,,,,,0,,,,-0.0049,,,,,,15.013133,,,,
,30410310.23,18.0082684,99.7004928588867,0.00395952015057471,5.20399884944183E-7,1,0.999253354069792,40.0298881530762,1.98025227360278,29.279999434948,0.0440559910752457,0.0082443077046439,0.25,3.66234805121235E-5,0.00393652511624857,5.55065073010119E-5,17.9965363,18.0200005,99.7004928588867,99.7004928588867,57.0104209356599,20.5284968322521,13.038077,0,0,0,40,4370,18.0425,99.7004928588867,,,,,,,,,,,,,0,,,,-0.0049,,,,,,18.0082684,,,,
,30410612.235,20.51538755,99.7004928588867,0.00395058577790377,4.56437690914633E-7,1,0.999253354069792,40.0298881530762,1.9804259819318,29.3199997395277,0.0439669062324127,0.00819525633487815,0.25,3.3571518679632E-5,0.00392775223574224,5.25870707954333E-5,20.5042858,20.5264893,99.7004928588867,99.7004928588867,56.9322580837368,20.5210469285372,13.797379,0,0,0,40,4370,20.5626,99.7004928588867,,,,,,,,,,,,,0,,,,0.0049,,,,,,20.51538755,,,,
,30410971.775,23.503149,99.7004928588867,0.00394721567678151,4.69420914703689E-7,1,0.999253354069792,40.0298881530762,1.98055256525056,29.3099991977215,0.0439382071348491,0.0081769872991373,0.25,3.1962399723431E-5,0.00392475575749753,5.14314070241219E-5,23.503149,23.503149,99.7004928588867,99.7004928588867,57.281646031833,20.529707059856,13.797379,0,0,0,40,4370,23.5685,99.7004928588867,,,,,,,,,,,,,0,,,,-0.00245,,,,,,23.503149,,,,
,30411334.78,26.5216198,99.7004928588867,0.00394327427598548,4.07383755949402E-7,1,0.999253354069792,40.0298881530762,1.98031287575181,29.3099991977215,0.0438965128068294,0.00816970030094271,0.25,3.11987940550987E-5,0.00392149194834277,5.14294328552898E-5,26.5216198,26.5216198,99.7004928588867,99.7004928588867,57.6083667528715,20.5257042076822,14.556682,0,0,0,40,4370,26.60865,99.7004928588867,,,,,,,,,,,,,0,,,,0,,,,,,26.5216198,,,,
,30411693.24,29.5014362,99.7004928588867,0.00394840108595852,4.62821632836843E-7,1,0.999253354069792,40.0298881530762,1.98046607471564,29.3099991977215,0.0439623258875533,0.00821496388024403,0.25,3.30516073728214E-5,0.00392757419686189,5.43601253219196E-5,29.5014362,29.5014362,99.7004928588867,99.7004928588867,57.8092452823138,20.5216862099021,14.936333,0,0,0,40,4370,29.60005,99.7004928588867,,,,,,,,,,,,,0,,,,0,,,,,,29.5014362,,,,
,30411998.57,32.02442935,99.7004928588867,0.00396090571510298,4.32423694633014E-7,1,0.999253354069792,40.0298881530762,1.98042112880325,29.3099991977215,0.0440981945450051,0.00833083887202827,0.25,3.99055498442571E-5,0.00394114962513107,6.23609148868536E-5,32.0106316,32.0382271,99.7004928588867,99.7004928588867,57.6708970344099,20.5163030509042,14.936333,0,0,0,40,4370,32.15585,99.7004928588867,,,,,,,,,,,,,0,,,,-0.0049,,,,,,32.02442935,,,,
,30412357.975,35.010746,99.7004928588867,0.00396698969902664,3.43872778928717E-7,1,0.999253354069792,40.0298881530762,1.98060449355937,29.3099991977215,0.0441781820119734,0.00841540318388993,0.25,4.45274641080733E-5,0.00394898632102556,6.84791904546468E-5,35.010746,35.010746,99.7004928588867,99.7004928588867,57.6216544376984,20.5225071542884,15.315984,0,0,0,40,4370,35.1566,99.7004928588867,,,,,,,,,,,,,0,,,,-0.0049,,,,,,35.010746,,,,
,30412719.6,38.01616095,99.7004928588867,0.00396984362379097,4.89449337732847E-7,1,0.999253354069792,40.0298881530762,1.98025058853101,29.3099991977215,0.0442191703695104,0.00847786695856639,0.25,4.7755337227247E-5,0.00395414157266355,7.32853157159224E-5,38.004631,38.0276909,99.7004928588867,99.7004928588867,57.4817429327561,20.516019061627,15.695635,0,0,0,40,4370,38.18275,99.7004928588867,,,,,,,,,,,,,0,,,,0,,,,,,38.01616095,,,,
touchdown = 19.0999992191792 mm,30413031.505,40.6076736,99.7004928588867,0.00397039169021106,5.08283697217292E-7,1,0.999253354069792,40.0298881530762,1.99240887119606,29.3099991977215,0.0445107582783856,0.0085404498527406,0.25,4.70754636101654E-5,0.00395711382052152,7.39132739151845E-5,40.6076736,40.6076736,99.7004928588867,99.7004928588867,57.6279074658522,20.4998462009486,15.695635,0,0,0,40,4370,40.7902,99.7004928588867,,,,,,,,,,,,,0,,,,-0.00245,,,,,,40.6076736,,,,
,30413380.64,43.5058403,99.7004928588867,0.00397050028125701,4.09248152148051E-7,1,0.999253354069792,40.0298881530762,1.99192918652714,29.3099991977215,0.0445375682894817,0.00854183759396866,0.25,4.55514473026118E-5,0.00396035182381165,7.36514739906759E-5,43.5058403,43.5058403,99.7004928588867,99.7004928588867,57.5794464976599,20.5092626306671,16.454937,0,0,0,40,4370,43.71155,99.7004928588867,,,,,,,,,,,,,0,,,,-0.00245,,,,,,43.5058403,,,,
,30413744.57,46.5188675,99.7004928588867,0.00394980014637284,4.8261925705268E-7,1,0.999253354069792,40.0298881530762,1.99247352174666,29.3099991977215,0.0443929375785901,0.00830921951771744,0.25,2.68450876511058E-5,0.00394341889932574,5.57632193933937E-5,46.5188675,46.5188675,99.7004928588867,99.7004928588867,57.7951759689677,20.5038100387921,16.075285,0,0,0,40,4370,46.75755,99.7004928588867,,,,,,,,,,,,,0,,,,0,,,,,,46.5188675,,,,
,30414108.835,49.5120277,99.7004928588867,0.00396500396529683,5.25625210951566E-7,1,0.999253354069792,40.0298881530762,1.99244594298132,29.3099991977215,0.0445717860294833,0.00853908734659347,0.25,4.34296438428713E-5,0.00396227481912021,7.28884243617014E-5,49.5120277,49.5120277,99.7004928588867,99.7004928588867,57.667770520333,20.5065825634303,16.834587,0,0,0,40,4370,49.82065,99.7004928588867,,,,,,,,,,,,,0,,,,-0.00245,,,,,,49.5120277,,,,
,30414414.015,52.0113297,99.7004928588867,0.00395701979849038,5.75313813731271E-7,1,0.999253354069792,40.0298881530762,1.98035089272083,29.3199997395277,0.0442732550839605,0.00840451536774869,0.25,3.67519164400493E-5,0.00395753576270533,6.61250778911613E-5,52.0113297,52.0113297,99.7004928588867,99.7004928588867,57.5841362687753,20.5066881781213,17.973541,0,0,0,40,4370,52.4012,99.7004928588867,,,,,,,,,,,,,0,,,,0,,,,,,52.0113297,,,,
,30414780.915,55.0232048,99.7004928588867,0.00394931413048094,5.3238895642514E-7,1,0.999253354069792,40.0298881530762,1.9802829304994,29.3099991977215,0.0442349275123933,0.00834901255863351,0.25,3.30833419531089E-5,0.00395351897283509,6.18956579960959E-5,55.0232048,55.0232048,99.7004928588867,99.7004928588867,57.4356268501215,20.5030747010552,19.871798,0,0,0,40,4370,55.507,99.7004928588867,,,,,,,,,,,,,0,,,,0,,,,,,55.0232048,,,,
,30415141.25,58.0030479,99.7004928588867,0.00394230494385195,4.40952186780976E-7,1,0.999253354069792,40.0298881530762,1.98058954434119,29.3099991977215,0.0442009628961767,0.00833193524836557,0.25,3.30419104863865E-5,0.00394973970963244,6.091584905457E-5,58.0030479,58.0030479,99.7004928588867,99.7004928588867,57.4371901071599,20.497197255614,21.01075,0,0,0,40,4370,58.51885,99.7004928588867,,,,,,,,,,,,,0,,,,-0.00245,,,,,,58.0030479,,,,
,30415472.22,60.7704926,99.7004928588867,,,2,,,,29.3099999982119,,,,,,,60.7704926,60.7704926,99.7004928588867,99.7004928588867,,,21.770052,,,,-99999999,4370,61.2882,99.7004928588867,,,,,,,,,,,,,,,,,,,,,,,60.7704926,,,,
,30415802.75,63.5023117,99.7004928588867,0.00392196886863789,4.74876073259449E-7,1,0.999253354069792,40.0298881530762,1.98048158741621,29.3000005185604,0.0440364542104492,0.00823678389870705,0.25,2.96963962841407E-5,0.00393428635682107,5.51410026959583E-5,63.5023117,63.5023117,99.7004928588867,99.7004928588867,57.8154983104676,20.4962293336829,22.149702,0,0,0,40,4370,64.04485,99.7004928588867,,,,,,,,,,,,,0,,,,-0.0049,,,,,,63.5023117,,,,
,30416164.44,66.5065231,99.7004928588867,0.00390505034522058,3.53275087663146E-7,1,0.999253354069792,40.0298881530762,1.98035671667155,29.3000005185604,0.0438760539231651,0.00815614527765963,0.25,2.66515278855917E-5,0.00391943574797206,5.05607114657804E-5,66.5065231,66.5065231,99.7004928588867,99.7004928588867,57.4074882234292,20.4969170513248,22.529354,0,0,0,40,4370,67.07375,99.7004928588867,,,,,,,,,,,,,0,,,,-0.0049,,,,,,66.5065231,,,,
,30416523.4,69.5050049,99.7004928588867,0.00388622291176112,4.545705260638E-7,1,0.999253354069792,40.0298881530762,1.97999424771625,29.3000005185604,0.0436808835670029,0.00809109612124502,0.25,2.54797895641032E-5,0.00390225396764393,4.7854145336515E-5,69.5050049,69.5050049,99.7004928588867,99.7004928588867,57.0979633298137,20.4961278058156,22.529354,0,0,0,40,4370,70.0764,99.7004928588867,,,,,,,,,,,,,0,,,,0,,,,,,69.5050049,,,,
,30416826.905,72.0046005,99.7004928588867,0.0038699791671329,5.138695907997E-7,1,0.999253354069792,40.0298881530762,1.98008034727446,29.279999434948,0.0435189271184976,0.00802908701968767,0.25,2.37999483343149E-5,0.00388714578304551,4.49038371029654E-5,72.0046005,72.0046005,99.7004928588867,99.7004928588867,57.5614690417176,20.5065041977886,22.529354,0,0,0,40,4370,72.62105,99.7004928588867,,,,,,,,,,,,,0,,,,0,,,,,,72.0046005,,,,
,30417186.48,75.0041275,99.7004928588867,0.00384246374969949,3.85510344148399E-7,1,0.999253354069792,40.0298881530762,1.97975949919023,29.279999434948,0.0432237039518465,0.0079273865648176,0.25,2.08933752872596E-5,0.0038606683447513,4.05168005184658E-5,74.9908066,75.0174484,99.7004928588867,99.7004928588867,57.004167907506,20.5111135443457,22.909004,0,0,0,40,4370,75.6335,99.7004928588867,,,,,,,,,,,,,0,,,,0.0049,,,,,,75.0041275,,,,
,30417549.095,78.0132599,99.7004928588867,0.00381431457444044,6.03314592731387E-7,1,0.999253354069792,40.0298881530762,1.97989699906926,29.2899999767542,0.042923505658963,0.00785220740995213,0.25,2.02506553313778E-5,0.00383330010356312,3.8490752634566E-5,78.0132599,78.0132599,99.7004928588867,99.7004928588867,57.444224763833,20.5005497260248,22.529354,0,0,0,40,4370,78.6699,99.7004928588867,,,,,,,,,,,,,0,,,,0,,,,,,78.0132599,,,,
,30417917.3,81.0658798,99.7004928588867,,,2,,,,29.2900007772446,,,,,,,81.0658798,81.0658798,99.7004928588867,99.7004928588867,,,22.909004,,,,-99999999,4370,81.7514,99.7004928588867,,,,,,,,,,,,,,,,,,,,,,,81.0658798,,,,
,30418214.585,83.5180511,99.7004928588867,0.00375598398920426,5.195370299808E-7,1,0.999253354069792,40.0298881530762,1.99114269267336,29.279999434948,0.0425142537237404,0.00774980920934299,0.25,1.95960869794899E-5,0.00377585814037976,3.55474516504837E-5,83.5180511,83.5180511,99.7004928588867,99.7004928588867,57.4582940771792,20.5006214630002,22.909004,0,0,0,40,4370,84.2611,99.7004928588867,,,,,,,,,,,,,0,,,,0,,,,,,83.5180511,,,,
,30418573.095,86.5217743,99.7004928588867,0.00371861924275029,4.9655850974541E-7,1,0.999253354069792,40.0298881530762,1.99137684402998,29.279999434948,0.0421029701254898,0.00766192788731662,0.25,1.92354078194178E-5,0.00373871881460046,3.4088159353702E-5,86.5217743,86.5217743,99.7004928588867,99.7004928588867,57.8162799389869,20.5046443629744,22.909004,0,0,0,40,4370,87.24845,99.7004928588867,,,,,,,,,,,,,0,,,,-0.00245,,,,,,86.5217743,,,,
,30418930.805,89.5063095,99.7004928588867,0.00367794867829878,4.38770344759151E-7,1,0.999253354069792,40.0298881530762,1.99097939072751,29.279999434948,0.0416420450155512,0.007554564128935,0.25,1.7860988162147E-5,0.00369814474053876,3.16991258298759E-5,89.5063095,89.5063095,99.7004928588867,99.7004928588867,57.77250874191,20.5015508473532,24.047956,0,0,0,40,4370,90.2232,99.7004928588867,,,,,,,,,,,,,0,,,,-0.00245,,,,,,89.5063095,,,,
,30419230.555,92.0061722,99.7004928588867,0.00364583741846016,5.66015191580351E-7,1,0.999253354069792,40.0298881530762,2.00192139195865,29.2700007557869,0.0414966752335402,0.0075309038147448,0.25,1.85820293966267E-5,0.00366604745821966,3.16559902146138E-5,92.0061722,92.0061722,99.7004928588867,99.7004928588867,57.2894623170253,20.4963340472356,23.668306,0,0,0,40,4370,92.7229,99.7004928588867,,,,,,,,,,,,,0,,,,0.00245,,,,,,92.0061722,,,,
,30419591.645,95.0195694,99.7004928588867,0.00360112856818352,2.88494762961331E-7,1,0.999253354069792,40.0298881530762,2.00190549818038,29.2700007557869,0.0409916777229038,0.00742539485470021,0.25,1.78823300285625E-5,0.00362125568334002,3.00836118886138E-5,95.0195694,95.0195694,99.7004928588867,99.7004928588867,57.6161830380638,20.4967736308019,24.047956,0,0,0,40,4370,95.7362,99.7004928588867,,,,,,,,,,,,,0,,,,-0.00245,,,,,,95.0195694,,,,
,30419952.56,98.0185394,99.7004928588867,0.00355433276355732,4.81970751616715E-7,1,0.999253354069792,40.0298881530762,2.0018489293951,29.2700007557869,0.0404603935265489,0.00732116194347444,0.25,1.7606679700163E-5,0.00357429956294082,2.90096954939196E-5,98.0185394,98.0185394,99.7004928588867,99.7004928588867,57.3762230826599,20.4979088701052,23.288654,0,0,0,40,4370,98.7498,99.7004928588867,,,,,,,,,,,,,0,,,,0,,,,,,98.0185394,,,,
,30420310.055,101.0129929,99.7004928588867,0.00350598984666248,3.54913736140971E-7,1,0.999253354069792,40.0298881530762,2.00185212691123,29.2700007557869,0.0399116331121713,0.00721615928750826,0.25,1.74500643529943E-5,0.0035257319462702,2.81273510272316E-5,101.0129929,101.0129929,99.7004928588867,99.7004928588867,57.6107116384292,20.5019143127597,24.047956,0,0,0,40,4370,101.7328,99.7004928588867,,,,,,,,,,,,,0,,,,0,,,,,,101.0129929,,,,
,30420609.71,103.5113678,99.7004928588867,0.00346358578316219,4.99385380721593E-7,1,0.999253354069792,40.0298881530762,1.99059450500045,29.2600002139807,0.0392202833884542,0.00707378051711089,0.25,1.618732910169E-5,0.00348310019186108,2.62923723923346E-5,103.5113678,103.5113678,99.7004928588867,99.7004928588867,57.5497446139292,20.4997367459098,24.427608,0,0,0,40,4370,104.2391,99.7004928588867,,,,,,,,,,,,,0,,,,0,,,,,,103.5113678,,,,
,30420970.875,106.5102158,99.7004928588867,0.00341275024439572,4.69292503811546E-7,1,0.999253354069792,40.0298881530762,1.99057893660323,29.2600002139807,0.0386462847008799,0.00695726803470249,0.25,1.53146160545041E-5,0.00343195675694299,2.47893120880076E-5,106.5102158,106.5102158,99.7004928588867,99.7004928588867,57.2425646058714,20.5080405592278,24.427608,0,0,0,40,4370,107.2559,99.7004928588867,,,,,,,,,,,,,0,,,,-0.00245,,,,,,106.5102158,,,,
,30421329.485,109.5024872,99.7004928588867,0.00336131012640319,4.4442836047434E-7,1,0.999253354069792,40.0298881530762,1.99058725444488,29.2700007557869,0.0380645006784536,0.00684547396545341,0.25,1.49073370598972E-5,0.00338017341922271,2.38080696141747E-5,109.5024872,109.5024872,99.7004928588867,99.7004928588867,57.3816944822945,20.5051741618533,24.427608,0,0,0,40,4370,110.2571,99.7004928588867,,,,,,,,,,,,,0,,,,-0.0049,,,,,,109.5024872,,,,
,30421631.475,112.0113297,99.7004928588867,0.00332200763277719,4.37951675012466E-7,1,0.999253354069792,40.0298881530762,2.00152677007168,29.2399991303682,0.0378167695830881,0.00679632225928365,0.25,1.46701437386974E-5,0.00334058566315154,2.31355883418326E-5,112.0113297,112.0113297,99.7004928588867,99.7004928588867,57.4653287338522,20.5045407670195,24.807261,0,0,0,40,4370,112.781,99.7004928588867,,,,,,,,,,,,,0,,,,0,,,,,,112.0113297,,,,
,30421992.64,115.0175743,99.7004928588867,0.00327077236308802,3.99437246773411E-7,1,0.999253354069792,40.0298881530762,2.00205105867428,29.2399991303682,0.0372426499780879,0.00668759614502817,0.25,1.4330206769677E-5,0.00328896618738478,2.230352098746E-5,115.008728,115.0264206,99.7004928588867,99.7004928588867,57.383257739333,20.4994795857246,25.186911,0,0,0,40,4370,115.7978,99.7004928588867,,,,,,,,,,,,,0,,,,0,,,,,,115.0175743,,,,
,30422350.75,118.0059738,99.7004928588867,0.00322258376790399,4.88070405073532E-7,1,0.999253354069792,40.0298881530762,2.00182046865186,29.2399991303682,0.0366898213667248,0.00658111156933819,0.25,1.38282185844093E-5,0.00324039432827946,2.13568519250642E-5,118.0059738,118.0059738,99.7004928588867,99.7004928588867,57.1120326431599,20.5063293944218,25.186911,0,0,0,40,4370,118.79175,99.7004928588867,,,,,,,,,,,,,0,,,,0,,,,,,118.0059738,,,,
,30422713.38,121.0099869,99.7004928588867,0.00316832318146186,4.4974220815463E-7,1,0.999253354069792,40.0298881530762,2.00224446312468,29.2399991303682,0.0360786079953035,0.00646700814142837,0.25,1.35122261820414E-5,0.00318570297658191,2.06140492877442E-5,121.0099869,121.0099869,99.7004928588867,99.7004928588867,57.3723149400638,20.5040150389053,24.807261,0,0,0,40,4370,121.8238,99.7004928588867,,,,,,,,,,,,,0,,,,-0.0049,,,,,,121.0099869,,,,
,30423014.44,123.515358,99.7004928588867,0.00312134730429773,4.21812933816151E-7,1,0.999253354069792,40.0298881530762,1.99092039526415,29.2399991303682,0.0353527028085626,0.00632352188625803,0.25,1.23944544938448E-5,0.00313835169988336,1.91576362095833E-5,123.515358,123.515358,99.7004928588867,99.7004928588867,57.3082214014868,20.5004386015836,24.807261,0,0,0,40,4370,124.3422,99.7004928588867,,,,,,,,,,,,,0,,,,0.00245,,,,,,123.515358,,,,
,30423372.45,126.5048866,99.7004928588867,0.00306910193100098,3.74937765466923E-7,1,0.999253354069792,40.0298881530762,1.99140351088099,29.2399991303682,0.0347686827415109,0.00621082949579096,0.25,1.1729469996388E-5,0.00308566951017741,1.81283215466148E-5,126.4958038,126.5139694,99.7004928588867,99.7004928588867,57.6943458899869,20.5014865826326,25.566563,0,0,0,40,4370,127.3301,99.7004928588867,,,,,,,,,,,,,0,,,,0.00245,,,,,,126.5048866,,,,
,30423732.57,129.5111389,99.7004928588867,0.00300464368804051,4.3549964042223E-7,1,0.999253354069792,40.0298881530762,1.99117956579045,29.2399991303682,0.0340342918750339,0.00607181621536636,0.25,1.10382849850887E-5,0.00302070144366384,1.70733894355104E-5,129.5111389,129.5111389,99.7004928588867,99.7004928588867,57.5200427301984,20.5037038281433,25.186911,0,0,0,40,4370,130.3273,99.7004928588867,,,,,,,,,,,,,0,,,,-0.00245,,,,,,129.5111389,,,,
,30424030.81,132.0081177,99.7004928588867,0.00290906011396356,3.98256153803444E-7,1,0.999253354069792,40.0298881530762,1.99077877139552,29.2099993675947,0.032944544712284,0.00587235435503237,0.25,1.04229879213422E-5,0.00292446836204607,1.6095173230223E-5,132.0081177,132.0081177,99.7004928588867,99.7004928588867,57.0799858738714,20.5109498480437,25.186911,0,0,0,40,4370,132.7954,99.7004928588867,,,,,,,,,,,,,0,,,,-0.00245,,,,,,132.0081177,,,,
,30424394.455,135.004837,99.7004928588867,0.00285784324068544,3.79728496907146E-7,1,0.999253354069792,40.0298881530762,1.99136253888743,29.2099993675947,0.0323717512360094,0.00576967026234234,0.25,1.03805347228832E-5,0.00287280881246061,1.57606397038087E-5,135.004837,135.004837,99.7004928588867,99.7004928588867,57.1214121853907,20.5036612674727,25.566563,0,0,0,40,4370,135.8451,99.7004928588867,,,,,,,,,,,,,0,,,,0,,,,,,135.004837,,,,
,30424756.815,138.0178833,99.7004928588867,0.00280739013600927,4.51963836134819E-7,1,0.999253354069792,40.0298881530762,1.99176536145296,29.2099993675947,0.0318054648695677,0.00566232945895004,0.25,9.82213871284413E-6,0.00282191386207884,1.4930119159402E-5,138.0178833,138.0178833,99.7004928588867,99.7004928588867,57.7428068581792,20.5093687551758,25.946213,0,0,0,40,4370,138.86475,99.7004928588867,,,,,,,,,,,,,0,,,,0.0049,,,,,,138.0178833,,,,
,30425117.1,141.009964,99.7004928588867,0.0027569283352036,4.02654283041227E-7,1,0.999253354069792,40.0298881530762,1.99158457879046,29.2099993675947,0.0312285538842113,0.00556237193954492,0.25,1.0039246982367E-5,0.00277100889041515,1.48973143180086E-5,141.009964,141.009964,99.7004928588867,99.7004928588867,57.3613721407945,20.5023160097308,25.946213,0,0,0,40,4370,141.86925,99.7004928588867,,,,,,,,,,,,,0,,,,-0.00245,,,,,,141.009964,,,,
,30425417.7,143.5203247,99.7004928588867,0.00271777440797853,4.41032436509733E-7,1,0.999253354069792,40.0298881530762,2.00202228392681,29.2099993675947,0.0309374463214894,0.00550936532795579,0.25,9.92085847118939E-6,0.00273149939568725,1.45860558525648E-5,143.5203247,143.5203247,99.7004928588867,99.7004928588867,57.7818882841407,20.507465631413,25.946213,0,0,0,40,4370,144.37405,99.7004928588867,,,,,,,,,,,,,0,,,,0.00245,,,,,,143.5203247,,,,
,30425778.71,146.5177002,99.7004928588867,0.00266917615928573,5.05947525926607E-7,1,0.999253354069792,40.0298881530762,2.00206101800433,29.2099993675947,0.0303834986899346,0.00540577360332258,0.25,9.45876998199349E-6,0.00268246817613278,1.3901109773723E-5,146.5177002,146.5177002,99.7004928588867,99.7004928588867,57.3308886285445,20.5093093188613,25.946213,0,0,0,40,4370,147.38285,99.7004928588867,,,,,,,,,,,,,0,,,,0,,,,,,146.5177002,,,,
,30426139.665,149.519043,99.7004928588867,0.00262103653906101,4.13656631801824E-7,1,0.999253354069792,40.0298881530762,2.00246366094573,29.2099993675947,0.0298387818440252,0.00531063370063332,0.25,9.56492725231299E-6,0.00263389761550208,1.38012889604296E-5,149.519043,149.519043,99.7004928588867,99.7004928588867,57.8014289971215,20.4878760787498,25.946213,0,0,0,40,4370,150.38815,99.7004928588867,,,,,,,,,,,,,0,,,,0,,,,,,149.519043,,,,
touchdown = 18.9800001680851 mm,30426472.015,152.2745056,99.7004928588867,0.00257820568439131,4.38141921233738E-7,1,0.999253354069792,40.0298881530762,2.00239783556593,29.2000006884336,0.0293498019309432,0.00521444681924283,0.25,8.73613023269054E-6,0.00259068077049804,1.279110479197E-5,152.2745056,152.2745056,99.7004928588867,99.7004928588867,57.2730481181214,20.4977727007784,26.325863,0,0,0,40,4370,153.1596,99.7004928588867,,,,,,,,,,,,,0,,,,0.0049,,,,,,152.2745056,,,,
,30426801.32,155.012085,99.7004928588867,0.00253653298591606,4.08474491212518E-7,1,0.999253354069792,40.0298881530762,2.00270610923411,29.2000006884336,0.0288779123839444,0.00512899552403394,0.25,8.55649702023254E-6,0.0025486293292201,1.24454937721598E-5,155.012085,155.012085,99.7004928588867,99.7004928588867,57.5333304150253,20.5122626384342,26.325863,0,0,0,40,4370,155.898,99.7004928588867,,,,,,,,,,,,,0,,,,0,,,,,,155.012085,,,,
,30427161.485,158.0149536,99.7004928588867,0.00249171511819652,4.0528344292788E-7,1,0.999253354069792,40.0298881530762,2.00281932499414,29.2000006884336,0.0283677779014618,0.00503369573204105,0.25,8.10604987714262E-6,0.00250340285108478,1.18229687151941E-5,158.0149536,158.0149536,99.7004928588867,99.7004928588867,57.4700185049676,20.5282907453405,26.325863,0,0,0,40,4370,158.8932,99.7004928588867,,,,,,,,,,,,,0,,,,0,,,,,,158.0149536,,,,
,30427519.885,161.0069427,99.7004928588867,0.00244826597987852,4.59938996384986E-7,1,0.999253354069792,40.0298881530762,2.00219326571527,29.2000006884336,0.0278632160956927,0.0049404462614427,0.25,7.74097171766805E-6,0.00245955479149091,1.12976971996421E-5,161.0069427,161.0069427,99.7004928588867,99.7004928588867,57.2191157502945,20.5126103666221,26.705515,0,0,0,40,4370,161.87695,99.7004928588867,,,,,,,,,,,,,0,,,,0,,,,,,161.0069427,,,,
,30427822.495,163.5154877,99.7004928588867,0.00241576215652673,5.05786381461407E-7,1,0.999253354069792,40.0298881530762,1.99185982211257,29.1700009256601,0.027358010518889,0.00483895123620554,0.25,6.69167529888891E-6,0.00242673783852819,1.01220345898199E-5,163.5154877,163.5154877,99.7004928588867,99.7004928588867,57.6841847192369,20.51392096256,26.325863,0,0,0,40,4370,164.40025,99.7004928588867,,,,,,,,,,,,,0,,,,0.0049,,,,,,163.5154877,,,,
,30428181.72,166.5104218,99.7004928588867,0.00238466956797041,4.19083851166393E-7,1,0.999253354069792,40.0298881530762,1.99210481147121,29.1700009256601,0.027006264779483,0.00478012022544945,0.25,6.97722031805922E-6,0.00239530592702712,1.02819715128672E-5,166.5104218,166.5104218,99.7004928588867,99.7004928588867,57.3082214014868,20.5301932678806,25.946213,0,0,0,40,4370,167.3843,99.7004928588867,,,,,,,,,,,,,0,,,,0,,,,,,166.5104218,,,,
,30428542.915,169.5213623,99.7004928588867,0.00234963723043335,4.33296881639E-7,1,0.999253354069792,40.0298881530762,1.99214616599597,29.1700009256601,0.0266081460042408,0.00470764115148303,0.25,6.77955698004247E-6,0.00235991834499473,9.95704652169991E-6,169.5213623,169.5213623,99.7004928588867,99.7004928588867,57.2699216040445,20.5293414806482,26.325863,0,0,0,40,4370,170.3889,99.7004928588867,,,,,,,,,,,,,0,,,,-0.0049,,,,,,169.5213623,,,,
,30428894.39,172.4406891,99.7004928588867,,,2,,,,29.1800004053116,,,,,,,172.4406891,172.4406891,99.7004928588867,99.7004928588867,,,26.705515,,,,-99999999,4370,173.3111,99.7004928588867,,,,,,,,,,,,,,,,,,,,,,,172.4406891,,,,
,30429202,175.0172272,99.7004928588867,0.0020770119738673,4.37449269578867E-7,1,0.999253354069792,40.0298881530762,1.97926781732151,29.1700009256601,0.0233728339235857,0.00412970647424317,0.25,5.6322980960995E-6,0.00208577193671668,8.32201603729608E-6,175.0172272,175.0172272,99.7004928588867,99.7004928588867,57.5247325013138,20.5533124769482,27.085165,0,0,0,40,4370,175.8706,99.7004928588867,,,,,,,,,,,,,0,,,,-0.0049,,,,,,175.0172272,,,,
,30429562.07,178.0041962,99.7004928588867,0.00193469407683493,4.11513250050206E-7,1,0.999253354069792,40.0298881530762,1.97902712084134,29.1700009256601,0.0217687868003393,0.00383499617879184,0.25,4.32790715591965E-6,0.00194268509126009,6.77363647129239E-6,178.0041962,178.0041962,99.7004928588867,99.7004928588867,57.1753445532176,20.532583834196,27.085165,0,0,0,40,4370,178.8713,99.7004928588867,,,,,,,,,,,,,0,,,,0,,,,,,178.0041962,,,,
,30429923.065,181.0172119,99.7004928588867,0.00162712388539583,1.21740742525444E-6,1,0.999253354069792,40.0298881530762,1.9792944506215,29.1700009256601,0.0174322537045542,0.0082677823516102,0.25,0.000451625343491085,0.00163314833780868,0.000455448965987713,181.0172119,181.0172119,99.7004928588867,99.7004928588867,57.2449094914291,20.5149265956354,27.085165,0,0,0,40,4370,181.8619,99.7004928588867,,,,,,,,,,,,,0,,,,-0.0049,,,,,,181.0172119,,,,
,30430221.36,183.50302125,99.7004928588867,0.00157001912353004,2.64152787079208E-6,1,0.999253354069792,40.0298881530762,1.98020796209182,29.1600003838539,0.0167526997779465,0.00840644933762804,0.25,0.000473629489808183,0.00157567815916832,0.000477402372353421,183.4944458,183.5115967,99.7004928588867,99.7004928588867,57.0369963053137,20.5122306703354,26.705515,0,0,0,40,4370,184.35,99.7004928588867,,,,,,,,,,,,,0,,,,0.00245,,,,,,183.50302125,,,,
,30430583.735,186.5038452,99.7004928588867,0.00137058529578666,1.34794806626902E-5,1,0.999253354069792,40.0298881530762,1.9806827286099,29.1600003838539,0.0146309128596629,0.00731596167849699,0.25,0.000411397968647215,0.00137541289791784,0.000414611072734712,186.5038452,186.5038452,99.7004928588867,99.7004928588867,57.4074882234292,20.5263197202872,27.464817,0,0,0,40,4370,187.37305,99.7004928588867,,,,,,,,,,,,,0,,,,-0.00245,,,,,,186.5038452,,,,
,30430945.32,189.5150604,99.7004928588867,0.0013231695474471,3.86474290407693E-5,1,0.999253354069792,40.0298881530762,1.98173322506591,29.1600003838539,0.0141910132592812,0.00671875574201199,0.25,0.000366395188519939,0.00132775232881767,0.00036931182409942,189.5150604,189.5150604,99.7004928588867,99.7004928588867,57.0510656186599,20.5160526377781,26.705515,0,0,0,40,4370,190.39435,99.7004928588867,,,,,,,,,,,,,0,,,,-0.00245,,,,,,189.5150604,,,,
,30431307.81,192.5076141,99.7004928588867,0.00119113011818054,3.3226473590126E-5,1,0.999253354069792,40.0298881530762,1.98244878952761,29.1600003838539,0.0127196522236848,0.00638676539094178,0.25,0.000359756634485414,0.00119511809949648,0.00036243428752862,192.5076141,192.5076141,99.7004928588867,99.7004928588867,57.5403650716984,20.5208874685635,27.464817,0,0,0,40,4370,193.4185,99.7004928588867,,,,,,,,,,,,,0,,,,0,,,,,,192.5076141,,,,
,30431608.395,195.0166473,99.7004928588867,0.00113106497779392,2.77383954878808E-5,1,0.999253354069792,40.0298881530762,1.98236392483075,29.1399993002415,0.0120348142956013,0.00630603476741622,0.25,0.000363115565312753,0.00113474478806228,0.000365687947412144,195.0166473,195.0166473,99.7004928588867,99.7004928588867,57.3308886285445,20.5277692533748,27.085165,0,0,0,40,4370,195.9273,99.7004928588867,,,,,,,,,,,,,0,,,,0.0049,,,,,,195.0166473,,,,
,30431969.655,198.0096283,99.7004928588867,0.00103918070912178,3.55234738163193E-5,1,0.999253354069792,40.0298881530762,1.98302245582372,29.1399993002415,0.010990713279654,0.00619212042809398,0.25,0.000368867343236483,0.00104243135016713,0.000371300714444394,198.0096283,198.0096283,99.7004928588867,99.7004928588867,57.647448178833,20.5148527237801,27.085165,0,0,0,40,4374,198.9502,99.7004928588867,,,,,,,,,,,,,0,,,,-0.00245,,,,,,198.0096283,,,,
,30432330.9,201.0126038,99.7004928588867,0.00101614034865071,2.4348962648927E-5,1,0.999253354069792,40.0298881530762,1.98334854942775,29.1399993002415,0.0106861851896018,0.00640980368433276,0.25,0.000392167045394459,0.0010191946245087,0.000394598588729026,201.0126038,201.0126038,99.7004928588867,99.7004928588867,57.4332819645638,20.5119437424477,27.085165,0,0,0,40,4374,201.95565,99.7004928588867,,,,,,,,,,,,,0,,,,-0.0049,,,,,,201.0126038,,,,
,30432632.77,203.5186005,99.7004928588867,0.000963725471501892,1.99872364909677E-5,1,0.999253354069792,40.0298881530762,1.98291976376192,29.1399993002415,0.0100799909513485,0.00637763527955924,0.25,0.000398593764305504,0.000966522081293891,0.000400942836515881,203.5186005,203.5186005,99.7004928588867,99.7004928588867,57.4176493941791,20.5122301178065,27.464817,0,0,0,40,4374,204.4707,99.7004928588867,,,,,,,,,,,,,0,,,,0,,,,,,203.5186005,,,,
,30432992.935,206.515152,99.7004928588867,0.000905516027408954,2.09600119944047E-5,1,0.999253354069792,40.0298881530762,1.98393382980238,29.1399993002415,0.00942558644587793,0.00627900288155304,0.25,0.000399747696424971,0.000908036253614544,0.000401982861649424,206.515152,206.515152,99.7004928588867,99.7004928588867,57.6114932669484,20.4964184404351,27.464817,0,0,0,40,4374,207.4737,99.7004928588867,,,,,,,,,,,,,0,,,,0,,,,,,206.515152,,,,
,30433352.855,209.5006561,99.7004928588867,0.000849291105140644,2.60413486324066E-5,1,0.999253354069792,40.0298881530762,1.98371517961679,29.1399993002415,0.00878512974897439,0.00619602275119127,0.25,0.000402275628708172,0.000851550562816996,0.000404405677116165,209.5006561,209.5006561,99.7004928588867,99.7004928588867,57.7068519462946,20.508312911552,27.464817,0,0,0,40,4374,210.4713,99.7004928588867,,,,,,,,,,,,,0,,,,0,,,,,,209.5006561,,,,
,30433713.78,212.5023727,99.7004928588867,0.000833673551766077,1.83133246260017E-5,1,0.999253354069792,40.0298881530762,1.9837463374527,29.1399993002415,0.00859488167855219,0.00624317459591281,0.25,0.000409230586835006,0.0008358012735749,0.000411311188852935,212.4918365,212.5129089,99.7004928588867,99.7004928588867,57.3684067974676,20.5025413512699,27.464817,0,0,0,40,4374,213.47755,99.7004928588867,,,,,,,,,,,,,0,,,,-0.0049,,,,,,212.5023727,,,,
,30434016.085,215.0155945,99.7004928588867,0.000840391772488342,2.36435654155444E-5,1,0.999253354069792,40.0298881530762,1.98335721571426,29.1300006210804,0.00860234979484624,0.00663463385914417,0.25,0.000442969004599917,0.000842442166364218,0.000445109912732533,215.0155945,215.0155945,99.7004928588867,99.7004928588867,57.1878506095253,20.5142933761245,27.844467,0,0,0,40,4374,215.9944,99.7004928588867,,,,,,,,,,,,,0,,,,0,,,,,,215.0155945,,,,
,30434376.48,218.0085297,99.7004928588867,0.000818691587837012,3.12763359096122E-5,1,0.999253354069792,40.0298881530762,1.9833875152191,29.1300006210804,0.00834919364264891,0.0066378900800258,0.25,0.000447087438379367,0.000820598988087914,0.000449160725961741,218.0085297,218.0085297,99.7004928588867,99.7004928588867,57.2027015513907,20.5097632774744,27.844467,0,0,0,40,4374,218.9968,99.7004928588867,,,,,,,,,,,,,0,,,,-0.00245,,,,,,218.0085297,,,,
,30434736.325,221.0059204,99.7004928588867,0.000827731567464681,2.6289377002828E-5,1,0.999253354069792,40.0298881530762,1.98389106601181,29.1300006210804,0.00842713981606289,0.00680158677567238,0.25,0.000459974636145633,0.000829575998992443,0.000462033849631513,221.0059204,221.0059204,99.7004928588867,99.7004928588867,57.342613056333,20.510198930551,28.224119,0,0,0,40,4374,221.9913,99.7004928588867,,,,,,,,,,,,,0,,,,0,,,,,,221.0059204,,,,
,30435038.65,223.5187225,99.7004928588867,0.000803190977444244,6.83396603773937E-6,1,0.999253354069792,40.0298881530762,1.98304182074184,29.109999537468,0.00781198056885207,0.00867879325271922,0.25,0.00063122340130473,0.000804743986887983,0.0006336674261923,223.5187225,223.5187225,99.7004928588867,99.7004928588867,57.4520410490253,20.517802387186,27.844467,0,0,0,40,4374,224.50155,99.7004928588867,,,,,,,,,,,,,0,,,,0,,,,,,223.5187225,,,,
,30435400.015,226.519516,99.7004928588867,0.000800216887171587,9.12875857379212E-6,1,0.999253354069792,40.0298881530762,1.98408515414047,29.109999537468,0.00777960440393926,0.00868859780383627,0.25,0.000632311597769951,0.000801688694181754,0.00063467893577983,226.519516,226.519516,99.7004928588867,99.7004928588867,57.1354814987368,20.5085965988297,27.844467,0,0,0,40,4374,227.5238,99.7004928588867,,,,,,,,,,,,,0,,,,-0.0049,,,,,,226.519516,,,,
,30435759.105,229.5147552,99.7004928588867,0.000792190602247742,1.19739123095132E-5,1,0.999253354069792,40.0298881530762,1.98348774923202,29.109999537468,0.00770746313845832,0.0085474485962748,0.25,0.000621482260862673,0.000793579547573683,0.000623739022162571,229.5147552,229.5147552,99.7004928588867,99.7004928588867,57.6513563214292,20.5150554402375,27.844467,0,0,0,40,4374,230.5124,99.7004928588867,,,,,,,,,,,,,0,,,,0,,,,,,229.5147552,,,,
,30436119.195,232.50666045,99.7004928588867,0.00079176964474413,9.4876988438505E-6,1,0.999253354069792,40.0298881530762,1.98358138076668,29.109999537468,0.00769130912040342,0.00860993595226543,0.25,0.000627157290049672,0.00079307968183014,0.000629351886654772,232.4977417,232.5155792,99.7004928588867,99.7004928588867,57.5614690417176,20.5190307015214,28.224119,0,0,0,40,4374,233.50785,99.7004928588867,,,,,,,,,,,,,0,,,,0.00245,,,,,,232.50666045,,,,
,30436421.735,235.0085297,99.7004928588867,0.000777512407278056,1.54775720610915E-5,1,0.999253354069792,40.0298881530762,1.98276066133499,29.109999537468,0.00756616637181049,0.0083533693570236,0.25,0.000607213882518893,0.000778746434486071,0.000609286943088847,235.0085297,235.0085297,99.7004928588867,99.7004928588867,57.484869446833,20.5358599182175,28.603769,0,0,0,40,4374,236.0408,99.7004928588867,,,,,,,,,,,,,0,,,,0,,,,,,235.0085297,,,,
,30436783.595,238.016037,99.7004928588867,0.000765684291297382,1.2109552365041E-5,1,0.999253354069792,40.0298881530762,1.98329058976661,29.109999537468,0.00745974238493611,0.00818453278312172,0.25,0.000594165673822041,0.00076683099410426,0.000596126161527355,238.016037,238.016037,99.7004928588867,99.7004928588867,57.2949337166599,20.5204005637236,28.224119,0,0,0,40,4374,239.0585,99.7004928588867,,,,,,,,,,,,,0,,,,-0.00245,,,,,,238.016037,,,,
,30437141.945,241.0005188,99.7004928588867,0.000747163513830111,1.33840554796123E-5,1,0.999253354069792,40.0298881530762,1.98326341591279,29.109999537468,0.00727319761707532,0.00801641347207578,0.25,0.000582536891484536,0.000748209928824328,0.000584385624327519,241.0005188,241.0005188,99.7004928588867,99.7004928588867,57.4176493941791,20.5201501658871,28.603769,0,0,0,40,4374,242.0511,99.7004928588867,,,,,,,,,,,,,0,,,,-0.0049,,,,,,241.0005188,,,,
touchdown = 18.8800003379583 mm,30437452.41,243.5831757,99.7004928588867,0.000753537398185187,1.16760210257437E-5,1,0.999253354069792,40.0298881530762,1.98196113256113,29.1000008583069,0.00733873844920655,0.00802893728383489,0.25,0.00058306298869998,0.000754534887512485,0.000584857358247011,243.5831757,243.5831757,99.7004928588867,99.7004928588867,57.4364084786407,20.5337503502775,27.844467,0,0,0,40,4374,244.64565,99.7004928588867,,,,,,,,,,,,,0,,,,0.00245,,,,,,243.5831757,,,,
,30437805.555,246.5075684,99.7004928588867,0.000737931035830104,1.40317596168224E-5,1,0.999253354069792,40.0298881530762,1.98261712811831,29.1000008583069,0.00717549274633535,0.00793853811438291,0.25,0.00057759033913727,0.000738833523788975,0.000579292431587667,246.5075684,246.5075684,99.7004928588867,99.7004928588867,57.4653287338522,20.5268374147422,28.224119,0,0,0,40,4374,247.57975,99.7004928588867,,,,,,,,,,,,,0,,,,-0.0049,,,,,,246.5075684,,,,
,30438165.99,249.5084534,99.7004928588867,0.000726036417587785,1.48227422377891E-5,1,0.999253354069792,40.0298881530762,1.98314423777896,29.1000008583069,0.00705223950294801,0.00786201577083569,0.25,0.000572755743408547,0.000726850815577548,0.000574369555005715,249.5084534,249.5084534,99.7004928588867,99.7004928588867,57.454385934583,20.5154796614504,28.224119,0,0,0,40,4374,250.58165,99.7004928588867,,,,,,,,,,,,,0,,,,0,,,,,,249.5084534,,,,
,30438528.375,252.5140686,99.7004928588867,0.000732394923494371,1.32840462522758E-5,1,0.999253354069792,40.0298881530762,1.98282059492132,29.1000008583069,0.00715955800220894,0.00765580022965378,0.25,0.000553513024708234,0.000733165276167041,0.000555030600806462,252.5140686,252.5140686,99.7004928588867,99.7004928588867,57.4410982497561,20.5211234647129,28.603769,0,0,0,40,4374,253.6021,99.7004928588867,,,,,,,,,,,,,0,,,,0.00245,,,,,,252.5140686,,,,
,30438827.085,255.0020905,99.7004928588867,0.000709675472063328,1.15650180723728E-5,1,0.999253354069792,40.0298881530762,1.98298445420669,29.1000008583069,0.00692282616175369,0.0075026323616086,0.25,0.000543849638854245,0.000710358495452888,0.000545278019733524,255.0020905,255.0020905,99.7004928588867,99.7004928588867,57.3644986548715,20.5213428346673,28.224119,0,0,0,40,4374,256.0906,99.7004928588867,,,,,,,,,,,,,0,,,,0.0049,,,,,,255.0020905,,,,
,30439190.145,258.0166931,99.7004928588867,0.000717933951282396,1.07029501668968E-5,1,0.999253354069792,40.0298881530762,1.98390596951355,29.1000008583069,0.00701356903263598,0.00754780349117259,0.25,0.000546213727005561,0.000718557506569554,0.000547585966364797,258.0166931,258.0166931,99.7004928588867,99.7004928588867,57.5434915857753,20.5113887811479,28.603769,0,0,0,40,4374,259.12,99.7004928588867,,,,,,,,,,,,,0,,,,0.0049,,,,,,258.0166931,,,,
,30439548.265,261.001709,99.7004928588867,0.00071482321864023,1.33970540268767E-5,1,0.999253354069792,40.0298881530762,1.98410480199434,29.1000008583069,0.00697858406766322,0.00754150807792355,0.25,0.000546207205212059,0.00071537226406316,0.000547511271813849,261.001709,261.001709,99.7004928588867,99.7004928588867,57.4637654768138,20.509975822881,28.224119,0,0,0,40,4374,262.10065,99.7004928588867,,,,,,,,,,,,,0,,,,0,,,,,,261.001709,,,,
,30439874.16,263.6853333,99.7004928588867,,,2,,,,29.1100003379583,,,,,,,263.6853333,263.6853333,99.7004928588867,99.7004928588867,,,28.983419,,,,-99999999,4374,264.8142,99.7004928588867,,,,,,,,,,,,,,,,,,,,,,,263.6853333,,,,
,30440211.81,266.5043335,99.7004928588867,0.000698709007142363,1.31024542262728E-5,1,0.999253354069792,40.0298881530762,1.98329445399485,29.1000008583069,0.0068231909769443,0.00733371046527805,0.25,0.000530929781180696,0.000699121274773822,0.000532082731186965,266.5043335,266.5043335,99.7004928588867,99.7004928588867,57.3942005386022,20.5197851400186,28.603769,0,0,0,40,4374,267.6337,99.7004928588867,,,,,,,,,,,,,0,,,,0,,,,,,266.5043335,,,,
,30440573.765,269.5107422,99.7004928588867,0.000700743145430579,1.21272000429224E-5,1,0.999253354069792,40.0298881530762,1.98314729543366,29.1000008583069,0.00688476607309458,0.00710646193757675,0.25,0.000510490668431841,0.000701103323701335,0.000511559322246484,269.5107422,269.5107422,99.7004928588867,99.7004928588867,57.525514129833,20.519272926708,28.983419,0,0,0,40,4374,270.6427,99.7004928588867,,,,,,,,,,,,,0,,,,0,,,,,,269.5107422,,,,
,30440935.62,272.5046082,99.7004928588867,0.000686462400333581,8.88500474907377E-6,1,0.999253354069792,40.0298881530762,1.98306378650005,29.1000008583069,0.00675062192199892,0.00691965958832813,0.25,0.000496450754411766,0.000686749447603922,0.000497433777217992,272.5046082,272.5046082,99.7004928588867,99.7004928588867,57.5552160135638,20.5252750491661,28.983419,0,0,0,40,4374,273.6626,99.7004928588867,,,,,,,,,,,,,0,,,,-0.00245,,,,,,272.5046082,,,,
,30441236.12,275.0011597,99.7004928588867,0.000682319809545347,1.27183395157702E-5,1,0.999253354069792,40.0298881530762,1.98256601632764,29.1000008583069,0.00671531346314597,0.00683184052961909,0.25,0.000489562890247531,0.000682551006371059,0.000490487016365716,275.0011597,275.0011597,99.7004928588867,99.7004928588867,57.616964666583,20.5300152569348,28.983419,0,0,0,40,4374,276.1608,99.7004928588867,,,,,,,,,,,,,0,,,,-0.0049,,,,,,275.0011597,,,,
,30441597,278.0057983,99.7004928588867,0.000681730362997533,1.26207830674739E-5,1,0.999253354069792,40.0298881530762,1.98267299355934,29.1000008583069,0.00672802544953917,0.00671688497660928,0.25,0.000479476536011172,0.000681899676724079,0.000480333416146684,278.0057983,278.0057983,99.7004928588867,99.7004928588867,57.4895592179484,20.5293118682415,28.603769,0,0,0,40,4374,279.1757,99.7004928588867,,,,,,,,,,,,,0,,,,-0.0049,,,,,,278.0057983,,,,
,30441958.915,281.021759,99.7004928588867,0.000682875862170161,1.21337349946035E-5,1,0.999253354069792,40.0298881530762,1.9828477691898,29.1000008583069,0.00676414339527154,0.00658421413325828,0.25,0.000467493068927937,0.000682985290980975,0.000468284835891415,281.021759,281.021759,99.7004928588867,99.7004928588867,57.7568761715253,20.5256184182083,28.603769,0,0,0,40,4374,282.18835,99.7004928588867,,,,,,,,,,,,,0,,,,-0.0049,,,,,,281.021759,,,,
,30442314.03,283.9441528,99.7004928588867,,,2,,,,29.1299995589256,,,,,,,283.9441528,283.9441528,99.7004928588867,99.7004928588867,,,28.983419,,,,-99999999,4374,285.1473,99.7004928588867,,,,,,,,,,,,,,,,,,,,,,,283.9441528,,,,
,30442620.915,286.5185547,99.7004928588867,0.000675293215562598,8.57455774790694E-6,1,0.999253354069792,40.0298881530762,1.98253036855742,29.109999537468,0.00672581647114763,0.00628358110331422,0.25,0.000442263163620645,0.000675290048472995,0.00044293489740149,286.5185547,286.5185547,99.7004928588867,99.7004928588867,57.6154014095446,20.530879311346,28.603769,0,0,0,40,4374,287.70515,99.7004928588867,,,,,,,,,,,,,0,,,,0.0049,,,,,,286.5185547,,,,
,30442981.75,289.5139771,99.7004928588867,0.00066052097212773,1.19784190262612E-5,1,0.999253354069792,40.0298881530762,1.98236583433155,29.109999537468,0.00655341066923329,0.00628401333043637,0.25,0.000444970984337677,0.000660442243028901,0.000445580133229799,289.5139771,289.5139771,99.7004928588867,99.7004928588867,57.6411951506792,20.5295771051891,29.363071,0,0,0,40,4374,290.7239,99.7004928588867,,,,,,,,,,,,,0,,,,-0.00245,,,,,,289.5139771,,,,
,30443344.305,292.5100403,99.7004928588867,0.000654951076189577,1.03080168893495E-5,1,0.999253354069792,40.0298881530762,1.98186961437364,29.109999537468,0.00652275252757429,0.00607413353553347,0.25,0.00042744399943686,0.000654815905193914,0.000427991835607783,292.5100403,292.5100403,99.7004928588867,99.7004928588867,57.6904377473907,20.5306656091815,29.742722,0,0,0,40,4374,293.74385,99.7004928588867,,,,,,,,,,,,,0,,,,-0.0049,,,,,,292.5100403,,,,
,30443643.305,295.001709,99.7004928588867,0.000601286825847454,1.27768240601694E-5,1,0.999253354069792,40.0298881530762,1.99357400396971,29.279999434948,0.00601691577338228,0.00563423137284486,0.25,0.000394801718103025,0.000601110232407116,0.000395265901154066,295.001709,295.001709,99.7004928588867,99.7004928588867,57.6865296047946,20.5331211377208,29.363071,0,0,0,40,4374,296.2416,99.7004928588867,,,,,,,,,,,,,0,,,,0,,,,,,295.001709,,,,
,30444006.47,298.0138855,99.7004928588867,0.000599352610894405,1.00640881520625E-5,1,0.999253354069792,40.0298881530762,1.99341112402234,29.279999434948,0.00598652665973019,0.00567253536172259,0.25,0.000398626752204347,0.000599111872456381,0.000399042405903696,298.0036926,298.0240784,99.7004928588867,99.7004928588867,57.5302039009484,20.538165798129,29.363071,0,0,0,40,4374,299.26055,99.7004928588867,,,,,,,,,,,,,0,,,,0.00245,,,,,,298.0138855,,,,
,30444317.835,299.7874451,99.7004928588867,0.000592859326731069,1.28386630788141E-5,1,0.999253354069792,40.0298881530762,1.99311623540973,29.279999434948,0.00588814954925651,0.00579646554079008,0.25,0.000410835934607241,0.000592573552514796,0.000411220189286879,299.7874451,299.7874451,99.7004928588867,99.7004928588867,57.6935642614676,20.5379658179508,29.742722,0,0,0,40,4369,300.19355,99.7004928588867,,,,,,,,,,,,,0,,,,-0.00245,,,,,,299.7874451,,,,