File: data/looselyPackedNP/ios-11/ppms/rawdata/PMK18_ZFCW_100OE.DAT
[Header]
; VSM Data File (default extension .dat)
; Copyright (c) 2003-2013, Quantum Design, Inc. All rights reserved.
TITLE,
FILEOPENTIME,30281907.06,12/17/2018,7:39 pm
BYAPP,VSM,2.0,2.0
INFO,PPMS VSM Option Release 1.4.10 Build 1,APPNAME
INFO,Quantum Design Linear Motor Servo Controller,MOTOR_MODULE_NAME
INFO,3101-100 M1,MOTOR_HW_VERSION
INFO,MMC1014,MOTOR_SERIAL_NUMBER
INFO,SRV No X-over 01.03.11,MOTOR_SOFTWARE_VERSION
INFO,Quantum Design VSM Detection Module,VSM_MODULE_NAME
INFO,3101-150 F0,VSM_HW_VERSION
INFO,VSM707,VSM_SERIAL_NUMBER
INFO,VSM No X-over 01.02.05 May 20 2008 13:51:47,VSM_SOFTWARE_VERSION
INFO,704,PREAMP_SERIAL_NUMBER
INFO,822,COIL_SERIAL_NUMBER
INFO,0,MOMENT_UNITS
INFO,Maghemite,SAMPLE_MATERIAL
INFO,Oleate Iron Spheres,SAMPLE_COMMENT
INFO,,SAMPLE_MASS
INFO,,SAMPLE_VOLUME
INFO,,SAMPLE_MOLECULAR_WEIGHT
INFO,,SAMPLE_SIZE
INFO,,SAMPLE_SHAPE
DATATYPE,COMMENT,1
DATATYPE,TIME,2
STARTUPAXIS,X,2
STARTUPAXIS,Y1,5
[Data]
Comment,Time Stamp (sec),Temperature (K),Magnetic Field (Oe),Moment (emu),M. Std. Err. (emu),Transport Action,Averaging Time (sec),Frequency (Hz),Peak Amplitude (mm),Center Position (mm),Coil Signal' (mV),Coil Signal" (mV),Range (mV),M. Quad. Signal (emu),M. Raw' (emu),M. Raw" (emu),Min. Temperature (K),Max. Temperature (K),Min. Field (Oe),Max. Field (Oe),Mass (grams),Motor Lag (deg),Pressure (Torr),VSM Status (code),Motor Status (code),Measure Status (code),Measure Count,PPMS Status (code),System Temp. (K),System Field (Oe),Sample Position (deg),Bridge 1 Resistance (ohms),Bridge 1 Excitation (에),Bridge 2 Resistance (ohms),Bridge 2 Excitation (에),Bridge 3 Resistance (ohms),Bridge 3 Excitation (에),Bridge 4 Resistance (ohms),Bridge 4 Excitation (에),Signal 1 Vin (V),Signal 2 Vin (V),Digital Inputs (code),Drive 1 Iout (mA),Drive 1 Ipower (W),Drive 2 Iout (mA),Drive 2 Ipower (W),Pressure (),Map 20 (),Map 21 (),Map 22 (),Map 23 (),Map 24 (),Map 25 (),Map 26 (),Map 27 (),Map 28 (),Map 29 ()
,30286811.78,9.9829559,99.5634765625,,,2,,,,29.0899992543459,,,,,,,9.9829559,9.9829559,99.5634765625,99.5634765625,,,12.658426,,,,-99999999,4373,9.951,99.5634765625,,,,,,,,,,,,,,,,,,,,,,,9.9829559,,,,
,30286972.61,11.5137653,99.5634765625,0.00034761700139667,3.20220961953347E-7,1,0.999253354069792,40.0298881530762,1.9924916966921,29.0699992328882,0.00389028252440012,0.000730399298970609,0.25,3.42241263130052E-6,0.000345603520863529,5.07924450947374E-6,11.5137653,11.5137653,99.5634765625,99.5634765625,55.7824825319482,20.6562702346291,13.038077,0,0,0,40,4370,11.56565,99.5634765625,,,,,,,,,,,,,0,,,,0.00245,,,,,,11.5137653,,,,
,30287072.515,14.0126591,99.5634765625,0.00037705746762741,3.19791223684648E-7,1,0.999253354069792,40.0298881530762,1.9936403619686,29.0699992328882,0.00422286685031491,0.00078813405590613,0.25,3.30609964751179E-6,0.000374873302311668,5.10555682590102E-6,14.0126591,14.0126591,99.5634765625,99.5634765625,56.1052951103906,20.639882490174,13.038077,0,0,0,40,4370,14.08785,99.5634765625,,,,,,,,,,,,,0,,,,0,,,,,,14.0126591,,,,
,30287174.705,16.5397768,99.5634765625,0.000416010015610815,3.25617743081557E-7,1,0.999253354069792,40.0298881530762,1.99312198857258,29.0699992328882,0.00465831061514786,0.00086716883732955,0.25,3.45480259589995E-6,0.00041359812015671,5.44122483577468E-6,16.5065269,16.5730267,99.5634765625,99.5634765625,56.4929828559291,20.6441662385184,14.177031,0,0,0,40,4370,16.6483,99.5634765625,,,,,,,,,,,,,0,,,,0,,,,,,16.5397768,,,,
,30287276.08,19.0525723,99.5634765625,0.000462225446262136,3.1865178657875E-7,1,0.999253354069792,40.0298881530762,1.99403645652736,29.0699992328882,0.00517794753097027,0.000964697263564502,0.25,3.90189715834778E-6,0.000459545730039523,6.11393306719115E-6,19.0525723,19.0525723,99.5634765625,99.5634765625,56.4937644844483,20.6409651112002,14.556682,0,0,0,40,4370,19.1932,99.5634765625,,,,,,,,,,,,,0,,,,0.0049,,,,,,19.0525723,,,,
,30287374.905,21.5099888,99.5634765625,0.000511712948138877,4.36981307462132E-7,1,0.999253354069792,40.0298881530762,1.98326585075561,29.1399993002415,0.00570318683476417,0.0010614268449899,0.25,4.19019431592788E-6,0.000508768876965727,6.67161626393965E-6,21.5099888,21.5099888,99.5634765625,99.5634765625,56.3585427506213,20.6374321737481,14.936333,0,0,0,40,4370,21.6722,99.5634765625,,,,,,,,,,,,,0,,,,0,,,,,,21.5099888,,,,
,30287476.015,24.0277023,99.5634765625,0.000569179135736734,3.30149230130949E-7,1,0.999253354069792,40.0298881530762,1.98301439486869,29.1399993002415,0.00634368518899107,0.00117946873615423,0.25,4.49311871011096E-6,0.000565957557697488,7.32132619966782E-6,24.0277023,24.0277023,99.5634765625,99.5634765625,56.9674313671022,20.6424155146555,14.936333,0,0,0,40,4370,24.2184,99.5634765625,,,,,,,,,,,,,0,,,,0.00245,,,,,,24.0277023,,,,
,30287576.355,26.52279475,99.5634765625,0.000631294678342109,3.35260396500924E-7,1,0.999253354069792,40.0298881530762,1.98358833313255,29.1399993002415,0.00703845035408421,0.00131173890949513,0.25,5.1423860626987E-6,0.000627814226116657,8.38828528569608E-6,26.4959679,26.5496216,99.5634765625,99.5634765625,56.7180918694675,20.6368712461343,15.695635,0,0,0,40,4370,26.76815,99.5634765625,,,,,,,,,,,,,0,,,,-0.00245,,,,,,26.52279475,,,,
,30287678.575,29.0037899,99.5634765625,0.000700399661177909,3.66676630271659E-7,1,0.999253354069792,40.0298881530762,1.9840725860678,29.1399993002415,0.00781235026757221,0.00145643644214699,0.25,5.58656953649E-6,0.000696688891612294,9.34884010015208E-6,29.0037899,29.0037899,99.5634765625,99.5634765625,56.353852979506,20.6309371199349,15.315984,0,0,0,40,4370,29.3288,99.5634765625,,,,,,,,,,,,,0,,,,-0.0049,,,,,,29.0037899,,,,
,30287778.725,31.5352135,99.5634765625,0.000770590889823076,3.92145883712321E-7,1,0.999253354069792,40.0298881530762,1.97193211452724,29.1300006210804,0.00854814942422884,0.0015896414830388,0.25,5.59193835349905E-6,0.000766731033281987,9.94467689128809E-6,31.5352135,31.5352135,99.5634765625,99.5634765625,56.4812584281406,20.6217684211974,16.454937,0,0,0,40,4370,31.8595,99.5634765625,,,,,,,,,,,,,0,,,,-0.0049,,,,,,31.5352135,,,,
,30287879.06,34.0048008,99.5634765625,0.000843802714853434,3.8241376628816E-7,1,0.999253354069792,40.0298881530762,1.97282405827426,29.1300006210804,0.00936731029893051,0.00174486866826391,0.25,6.11775047941588E-6,0.000839886275545731,1.11442994889087E-5,33.9709358,34.0386658,99.5634765625,99.5634765625,56.9424192544868,20.617804089896,16.834587,0,0,0,40,4370,34.38745,99.5634765625,,,,,,,,,,,,,0,,,,-0.0049,,,,,,34.0048008,,,,
,30287981.31,36.5567856,99.5634765625,0.000922264717278625,3.23579979188601E-7,1,0.999253354069792,40.0298881530762,1.97253246274055,29.1300006210804,0.0102417118699384,0.00190771610653679,0.25,6.38050986033893E-6,0.000918415713047785,1.21837622932294E-5,36.5567856,36.5567856,99.5634765625,99.5634765625,57.0596635323714,20.6157742924619,16.834587,0,0,0,40,4370,36.96465,99.5634765625,,,,,,,,,,,,,0,,,,-0.0049,,,,,,36.5567856,,,,
,30288083.15,39.0461273,99.5634765625,0.0010033948671268,3.59121436441757E-7,1,0.999253354069792,40.0298881530762,1.97178598894659,29.1300006210804,0.0111437639672482,0.00208230700122729,0.25,7.18813570597967E-6,0.000999766601020919,1.38323577532154E-5,39.0461273,39.0461273,99.5634765625,99.5634765625,56.9244417985445,20.640307354356,17.214239,0,0,0,40,4370,39.53325,99.5634765625,,,,,,,,,,,,,0,,,,-0.00245,,,,,,39.0461273,,,,
touchdown = 18.9200006425381 mm,30288190.025,41.7120094,99.5634765625,0.00109561086456705,3.98593765043889E-7,1,0.999253354069792,40.0298881530762,1.9966947318182,29.1399993002415,0.012321924389094,0.00230934658843098,0.25,8.10526490372205E-6,0.0010923904132617,1.57041653734197E-5,41.7120094,41.7120094,99.5634765625,99.5634765625,56.9041194570445,20.61155948911,16.834587,0,0,0,40,4370,42.2153,99.5634765625,,,,,,,,,,,,,0,,,,0.0049,,,,,,41.7120094,,,,
,30288283.12,44.0004616,99.5634765625,0.00117940859423995,3.85045508564001E-7,1,0.999253354069792,40.0298881530762,1.99569863844558,29.1399993002415,0.0132672975191262,0.00248475220090929,0.25,8.31218236928787E-6,0.00117673573827363,1.67646682340988E-5,44.0004616,44.0004616,99.5634765625,99.5634765625,56.5508233663521,20.6179073639279,16.834587,0,0,0,40,4370,44.5914,99.5634765625,,,,,,,,,,,,,0,,,,0,,,,,,44.0004616,,,,
,30288386.89,46.53028485,99.5634765625,0.00127669163186323,3.64013190059744E-7,1,0.999253354069792,40.0298881530762,1.99657965695964,29.1399993002415,0.0143798821667263,0.00268926615279097,0.25,8.45174972784206E-6,0.00127482151440069,1.78317862899662E-5,46.4984283,46.5621414,99.5634765625,99.5634765625,56.8368994043906,20.6055868456787,17.593889,0,0,0,40,4370,47.2263,99.5634765625,,,,,,,,,,,,,0,,,,0,,,,,,46.53028485,,,,
,30288490.335,49.0556107,99.5634765625,0.0013791001055517,3.70961331372261E-7,1,0.999253354069792,40.0298881530762,1.99630435718016,29.1399993002415,0.0155444196411872,0.0029059231878345,0.25,8.93023754688134E-6,0.00137822603667861,1.91813546218873E-5,49.0556107,49.0556107,99.5634765625,99.5634765625,57.0416860764291,20.6119571763965,17.973541,0,0,0,40,4370,49.87065,99.5634765625,,,,,,,,,,,,,0,,,,-0.00245,,,,,,49.0556107,,,,
,30288599.7,51.6934776,99.5634765625,,,2,,,,29.1599993216991,,,,,,,51.6934776,51.6934776,99.5634765625,99.5634765625,,,18.353191,,,,-99999999,4374,52.6789,99.5634765625,,,,,,,,,,,,,,,,,,,,,,,51.6934776,,,,
,30288696.865,54.0189896,99.5634765625,0.00158891583330382,4.16211646302794E-7,1,0.999253354069792,40.0298881530762,1.99549212272183,29.1399993002415,0.0179316198158974,0.00335181343226593,0.25,1.04846292458937E-5,0.00159049611181465,2.21029873072568E-5,54.0189896,54.0189896,99.5634765625,99.5634765625,56.9830639374868,20.6254448297522,19.492144,0,0,0,40,4374,55.19,99.5634765625,,,,,,,,,,,,,0,,,,0.0049,,,,,,54.0189896,,,,
,30288801.875,56.5665245,99.5634765625,0.00169920894802787,3.42638606556347E-7,1,0.999253354069792,40.0298881530762,1.99622877703148,29.1399993002415,0.0191988420134718,0.00358103107593169,0.25,1.09011753348582E-5,0.00170218272514356,2.29992166256836E-5,56.5665245,56.5665245,99.5634765625,99.5634765625,56.5500417378329,20.6174340081208,19.871798,0,0,0,40,4374,57.9044,99.5634765625,,,,,,,,,,,,,0,,,,-0.00245,,,,,,56.5665245,,,,
,30288902.52,59.047039,99.5634765625,0.00180942555484461,3.46816593080036E-7,1,0.999253354069792,40.0298881530762,1.99649072304444,29.1399993002415,0.0204611281130534,0.00380852696799668,0.25,1.13766529161554E-5,0.00181375288551965,2.38255269270067E-5,59.047039,59.047039,99.5634765625,99.5634765625,56.7853119221214,20.6108228028353,20.631098,0,0,0,40,4374,60.46455,99.5634765625,,,,,,,,,,,,,0,,,,0.0049,,,,,,59.047039,,,,
,30289004.965,61.5514488,99.5634765625,0.0019226142335206,3.84484396844522E-7,1,0.999253354069792,40.0298881530762,1.99682928021861,29.1399993002415,0.0217586617562981,0.00404065814285155,0.25,1.18438672476392E-5,0.00192832004877856,2.45264186521184E-5,61.5514488,61.5514488,99.5634765625,99.5634765625,56.8236117195637,20.6027586458585,21.01075,0,0,0,40,4374,63.06755,99.5634765625,,,,,,,,,,,,,0,,,,0,,,,,,61.5514488,,,,
,30289106.05,64.0241547,99.5634765625,0.00203428211561001,4.06045666224782E-7,1,0.999253354069792,40.0298881530762,1.99579666656752,29.1600003838539,0.0230233871877102,0.00426892042622377,0.25,1.25892037550579E-5,0.00204131365663583,2.53976722183536E-5,64.0241547,64.0241547,99.5634765625,99.5634765625,56.8392442899483,20.6225198476185,21.01075,0,0,0,40,4374,65.62,99.5634765625,,,,,,,,,,,,,0,,,,-0.00245,,,,,,64.0241547,,,,
,30289205.235,66.5068054,99.5634765625,0.00213947072994862,3.87796742200341E-7,1,0.999253354069792,40.0298881530762,1.9957151800837,29.1600003838539,0.0242245625644191,0.00448124657048077,0.25,1.30088922800346E-5,0.00214774262702752,2.58309270859774E-5,66.5068054,66.5068054,99.5634765625,99.5634765625,56.831428004756,20.6139112154964,21.3904,0,0,0,40,4374,68.1173,99.5634765625,,,,,,,,,,,,,0,,,,0,,,,,,66.5068054,,,,
,30289306.665,69.0221634,99.5634765625,0.00224304842948875,4.19060079898913E-7,1,0.999253354069792,40.0298881530762,1.99529072030677,29.1600003838539,0.0254035852382082,0.00468528084001856,0.25,1.31402025891642E-5,0.00225252309285523,2.58844989085864E-5,69.0221634,69.0221634,99.5634765625,99.5634765625,56.6844818431406,20.6206612598528,21.3904,0,0,0,40,4374,70.6832,99.5634765625,,,,,,,,,,,,,0,,,,-0.00245,,,,,,69.0221634,,,,
,30289407.6,71.5052338,99.5634765625,0.00233810683082332,3.84742811830369E-7,1,0.999253354069792,40.0298881530762,1.99478614661991,29.1600003838539,0.0264817174354996,0.00488308488751423,0.25,1.43146491765214E-5,0.00234867204626717,2.69001614302452E-5,71.5052338,71.5052338,99.5634765625,99.5634765625,56.8580033744099,20.6347784511676,21.770052,0,0,0,40,4374,73.2275,99.5634765625,,,,,,,,,,,,,0,,,,-0.0049,,,,,,71.5052338,,,,
,30289488.39,73.5105591,99.5634765625,0.0024110502781481,3.9769797750986E-7,1,0.999253354069792,40.0298881530762,1.9953425801459,29.1700009256601,0.0273238318039734,0.00501944969925139,0.25,1.37071945513954E-5,0.00242243383844695,2.61226578620645E-5,73.5105591,73.5105591,99.5634765625,99.5634765625,56.8837971155445,20.6223831329709,21.770052,0,0,0,40,4374,75.2637,99.5634765625,,,,,,,,,,,,,0,,,,0,,,,,,73.5105591,,,,
,30289591.6,76.0363235,99.5634765625,0.00249122043927159,3.60977195574058E-7,1,0.999253354069792,40.0298881530762,1.99520271099745,29.1700009256601,0.0282386837563739,0.00517510582024902,0.25,1.38119138169747E-5,0.0025035249189947,2.59331033277245E-5,76.0363235,76.0363235,99.5634765625,99.5634765625,56.7274714116983,20.6273091877027,22.149702,0,0,0,40,4374,77.8796,99.5634765625,,,,,,,,,,,,,0,,,,0.00245,,,,,,76.0363235,,,,
,30289690.985,78.5305939,99.5634765625,0.00256029165906398,4.04093306002314E-7,1,0.999253354069792,40.0298881530762,1.99567246093697,29.1600003838539,0.0290338087062774,0.00531616600706738,0.25,1.44524704372068E-5,0.0025733700343125,2.62572134164988E-5,78.5305939,78.5305939,99.5634765625,99.5634765625,56.9893169656406,20.621089931345,21.770052,0,0,0,40,4374,80.38995,99.5634765625,,,,,,,,,,,,,0,,,,0,,,,,,78.5305939,,,,
,30289794.24,81.0134201,99.5634765625,0.00262079712494169,4.45532317582128E-7,1,0.999253354069792,40.0298881530762,1.99505820900384,29.1700009256601,0.0297177803171501,0.00542808045976361,0.25,1.43110400380635E-5,0.00263456935932562,2.57386832742031E-5,81.0134201,81.0134201,99.5634765625,99.5634765625,56.9658681100637,20.6260802026775,22.149702,0,0,0,40,4374,83.016,99.5634765625,,,,,,,,,,,,,0,,,,0,,,,,,81.0134201,,,,
,30289896.265,83.6216278,99.5634765625,0.00267224335323415,4.37586060001714E-7,1,0.999253354069792,40.0298881530762,1.99592634263009,29.1700009256601,0.0303188174052565,0.00552744302809718,0.25,1.43042144005345E-5,0.00268658268786708,2.53532265102075E-5,83.6216278,83.6216278,99.5634765625,99.5634765625,56.7165286124291,20.6135121808021,21.770052,0,0,0,40,4374,85.56675,99.5634765625,,,,,,,,,,,,,0,,,,0.00245,,,,,,83.6216278,,,,
,30289994.665,86.0182953,99.5634765625,0.002711106436898,4.18700736797684E-7,1,0.999253354069792,40.0298881530762,1.99593183814556,29.1600003838539,0.0307641820163245,0.00559893039609426,0.25,1.42383119490676E-5,0.00272589583783266,2.48916444547275E-5,85.9821091,86.0544815,99.5634765625,99.5634765625,57.1972301517561,20.6071168964138,22.909004,0,0,0,40,4374,88.0663,99.5634765625,,,,,,,,,,,,,0,,,,0,,,,,,86.0182953,,,,
,30290094,88.5144119,99.5634765625,0.00274153416163747,4.15768823516526E-7,1,0.999253354069792,40.0298881530762,1.99515112669044,29.1700009256601,0.0310998091840419,0.00566046006216734,0.25,1.49496824938856E-5,0.00275667032778361,2.52110320368096E-5,88.5144119,88.5144119,99.5634765625,99.5634765625,56.7681160946983,20.6291653695079,22.529354,0,0,0,40,4374,90.5368,99.5634765625,,,,,,,,,,,,,0,,,,0.00245,,,,,,88.5144119,,,,
,30290195.63,91.070755,99.5634765625,0.0027642067383399,3.41175922309953E-7,1,0.999253354069792,40.0298881530762,1.99622913037999,29.1700009256601,0.0313772705840285,0.00569658018161952,0.25,1.43442975442443E-5,0.00277961757577191,2.41876224787562E-5,91.070755,91.070755,99.5634765625,99.5634765625,56.9322580837368,20.617927366271,22.909004,0,0,0,40,4374,93.1011,99.5634765625,,,,,,,,,,,,,0,,,,-0.00245,,,,,,91.070755,,,,
touchdown = 18.9699996262789 mm,30290313.57,93.9886551,99.5634765625,0.00278037915966669,4.13324820678002E-7,1,0.999253354069792,40.0298881530762,1.99705844025355,29.1900001466274,0.0315764439623661,0.00572248911670342,0.25,1.40801792906742E-5,0.00279600115718625,2.34513231254282E-5,93.9886551,93.9886551,99.5634765625,99.5634765625,57.1370447557753,20.5943534859334,22.909004,0,0,0,40,4374,96.03375,99.5634765625,,,,,,,,,,,,,0,,,,-0.00245,,,,,,93.9886551,,,,
,30290395.695,96.0387955,99.5634765625,0.00278564770607208,4.20456679350729E-7,1,0.999253354069792,40.0298881530762,1.99637956352064,29.1900001466274,0.0316272539925891,0.00572823466311627,0.25,1.41575426423706E-5,0.00280135782654164,2.31992830610284E-5,96.0387955,96.0387955,99.5634765625,99.5634765625,56.8251749766022,20.6116315213463,22.909004,0,0,0,40,4374,98.11285,99.5634765625,,,,,,,,,,,,,0,,,,-0.00245,,,,,,96.0387955,,,,
,30290496.51,98.5521622,99.5634765625,0.00278662675040165,4.38099406960304E-7,1,0.999253354069792,40.0298881530762,1.99571500858193,29.1900001466274,0.03163080666889,0.00571707920239273,0.25,1.35484233259935E-5,0.00280238800646457,2.21955379145036E-5,98.5521622,98.5521622,99.5634765625,99.5634765625,57.0299616486406,20.6266676150196,23.288654,0,0,0,40,4374,100.63935,99.5634765625,,,,,,,,,,,,,0,,,,-0.00245,,,,,,98.5521622,,,,
,30290598.125,101.0297089,99.5634765625,0.00278187673774557,3.56150420439127E-7,1,0.999253354069792,40.0298881530762,1.99652048596506,29.1900001466274,0.0315902143438539,0.00570437509548312,0.25,1.34370556651171E-5,0.00279763436238188,2.16975552262074E-5,101.0297089,101.0297089,99.5634765625,99.5634765625,57.0409044479099,20.620331967608,22.529354,0,0,0,40,4374,103.20875,99.5634765625,,,,,,,,,,,,,0,,,,0,,,,,,101.0297089,,,,
,30290713.81,103.9078903,99.5634765625,,,2,,,,29.2100001680851,,,,,,,103.9078903,103.9078903,99.5634765625,99.5634765625,,,22.909004,,,,-99999999,4374,106.1178,99.5634765625,,,,,,,,,,,,,,,,,,,,,,,103.9078903,,,,
,30290798.45,106.01547625,99.5634765625,0.00275790744265298,4.06270111100444E-7,1,0.999253354069792,40.0298881530762,1.9971008559115,29.2000006884336,0.0313286551419535,0.0056438929919187,0.25,1.2833757840044E-5,0.00277350475322406,2.03741821886708E-5,105.9874039,106.0435486,99.5634765625,99.5634765625,57.007294421583,20.6091668924635,23.668306,0,0,0,40,4374,108.2437,99.5634765625,,,,,,,,,,,,,0,,,,0,,,,,,106.01547625,,,,
,30290900.09,108.5506897,99.5634765625,0.00274016519416002,3.75328022576399E-7,1,0.999253354069792,40.0298881530762,1.99752668618199,29.2000006884336,0.0311347115076686,0.00559878353745951,0.25,1.21744077245561E-5,0.00275562359259193,1.93708911813386E-5,108.5506897,108.5506897,99.5634765625,99.5634765625,57.0119841926983,20.614203311948,23.288654,0,0,0,40,4374,110.79905,99.5634765625,,,,,,,,,,,,,0,,,,0.0049,,,,,,108.5506897,,,,
,30290999.305,111.0078659,99.5634765625,0.0027198255447644,4.00107257246733E-7,1,0.999253354069792,40.0298881530762,1.99740783271226,29.2000006884336,0.0309020508050318,0.0055522473193215,0.25,1.19459362119916E-5,0.00273511732996045,1.88239082033157E-5,111.0078659,111.0078659,99.5634765625,99.5634765625,56.7751507513714,20.5910733414279,23.288654,0,0,0,40,4374,113.2982,99.5634765625,,,,,,,,,,,,,0,,,,0.00245,,,,,,111.0078659,,,,
,30291101.69,113.5455627,99.5634765625,0.0026968125514868,4.53884438026804E-7,1,0.999253354069792,40.0298881530762,1.99845611482651,29.2000006884336,0.0306550509185538,0.00550852682590057,0.25,1.21506199573746E-5,0.00271190703564997,1.87206100505864E-5,113.5455627,113.5455627,99.5634765625,99.5634765625,57.1135959001984,20.5946671071651,23.288654,0,0,0,40,4374,115.8685,99.5634765625,,,,,,,,,,,,,0,,,,0,,,,,,113.5455627,,,,
,30291199.94,116.0005341,99.5634765625,0.00267239678983035,4.23462270163406E-7,1,0.999253354069792,40.0298881530762,1.99755349004533,29.2000006884336,0.0303652684435846,0.00544634023669612,0.25,1.14004524006133E-5,0.00268727991832442,1.76834034578329E-5,116.0005341,116.0005341,99.5634765625,99.5634765625,56.8759808303522,20.6018992968484,22.909004,0,0,0,40,4374,118.33985,99.5634765625,,,,,,,,,,,,,0,,,,0,,,,,,116.0005341,,,,
,30291301.28,118.5385208,99.5634765625,0.00264634486535075,4.35366387924046E-7,1,0.999253354069792,40.0298881530762,1.99842570958899,29.2000006884336,0.0300822906733876,0.00538665351581296,0.25,1.07407172514237E-5,0.0026609956530011,1.67449319847225E-5,118.5385208,118.5385208,99.5634765625,99.5634765625,57.159711982833,20.58731289879,23.288654,0,0,0,40,4374,120.89235,99.5634765625,,,,,,,,,,,,,0,,,,0.00245,,,,,,118.5385208,,,,
,30291403.25,121.0284119,99.5634765625,0.00261747023678629,4.64393801453044E-7,1,0.999253354069792,40.0298881530762,1.99815930077751,29.2000006884336,0.0297500618706497,0.00532213225771689,0.25,1.03921937310199E-5,0.00263186794676587,1.61303598784771E-5,121.0284119,121.0284119,99.5634765625,99.5634765625,56.6610329875637,20.5962147328365,24.047956,0,0,0,40,4374,123.4539,99.5634765625,,,,,,,,,,,,,0,,,,0.00245,,,,,,121.0284119,,,,
,30291504.64,123.5656357,99.5634765625,0.00258835018765595,3.72699953254998E-7,1,0.999253354069792,40.0298881530762,1.9974599649994,29.2000006884336,0.0294085412644385,0.00525827790041126,0.25,1.02234188937498E-5,0.00260248342603651,1.57137480462034E-5,123.5656357,123.5656357,99.5634765625,99.5634765625,56.7376325824483,20.6077061623763,23.668306,0,0,0,40,4374,126.00065,99.5634765625,,,,,,,,,,,,,0,,,,0,,,,,,123.5656357,,,,
,30291604.275,126.0587921,99.5634765625,0.00255796668782428,4.28876641728625E-7,1,0.999253354069792,40.0298881530762,1.99804080118046,29.2000006884336,0.0290708618290689,0.00519375747990412,0.25,9.9164179471064E-6,0.00257182568024076,1.51734508739808E-5,126.0587921,126.0587921,99.5634765625,99.5634765625,56.6922981283329,20.5931679636586,23.288654,0,0,0,40,4374,128.50645,99.5634765625,,,,,,,,,,,,,0,,,,0,,,,,,126.0587921,,,,
,30291704.23,128.5477448,99.5634765625,0.00252689510941161,4.15648169099504E-7,1,0.999253354069792,40.0298881530762,1.99794209886808,29.2000006884336,0.0287161871347599,0.00512393902173445,0.25,9.40007739783952E-6,0.00254047270411945,1.44352218187354E-5,128.5477448,128.5477448,99.5634765625,99.5634765625,57.1722180391407,20.5962967227454,23.668306,0,0,0,40,4374,131.00985,99.5634765625,,,,,,,,,,,,,0,,,,-0.0049,,,,,,128.5477448,,,,
,30291804.635,131.0436554,99.5634765625,0.00249567554090557,3.72020570090554E-7,1,0.999253354069792,40.0298881530762,1.99787740131465,29.2000006884336,0.0283589806645119,0.00506137868176968,0.25,9.52888943314198E-6,0.00250896622489799,1.4357151660867E-5,131.0436554,131.0436554,99.5634765625,99.5634765625,57.1659650109868,20.5965685150061,24.047956,0,0,0,40,4374,133.5289,99.5634765625,,,,,,,,,,,,,0,,,,-0.00245,,,,,,131.0436554,,,,
,30291902.79,133.5243225,99.5634765625,0.00245618852451374,4.00356059989278E-7,1,0.999253354069792,40.0298881530762,1.99854450231968,29.2000006884336,0.027919439784756,0.00497316838646999,0.25,8.67616654762545E-6,0.00246914789927518,1.32924446570805E-5,133.5243225,133.5243225,99.5634765625,99.5634765625,56.9846271945253,20.5902174239105,23.668306,0,0,0,40,4374,135.9777,99.5634765625,,,,,,,,,,,,,0,,,,0,,,,,,133.5243225,,,,
,30292002.79,136.0320129,99.5634765625,0.00242478774430855,4.0404012855831E-7,1,0.999253354069792,40.0298881530762,1.99859045484059,29.2000006884336,0.0275615944582974,0.00490989314241427,0.25,8.72820790545972E-6,0.00243745408496291,1.31617849599436E-5,136.0320129,136.0320129,99.5634765625,99.5634765625,57.1745629246983,20.5908962187731,23.668306,0,0,0,40,4374,138.4554,99.5634765625,,,,,,,,,,,,,0,,,,0,,,,,,136.0320129,,,,
,30292104.775,138.5206146,99.5634765625,0.00239569309550872,3.98863536747187E-7,1,0.999253354069792,40.0298881530762,1.99888488919708,29.2000006884336,0.0272339501952056,0.00484750052344226,0.25,8.40051638827906E-6,0.00240808018881398,1.26581817251706E-5,138.5206146,138.5206146,99.5634765625,99.5634765625,57.0502839901407,20.5910818516853,23.668306,0,0,0,40,4374,141.04575,99.5634765625,,,,,,,,,,,,,0,,,,0,,,,,,138.5206146,,,,
,30292203.695,141.0016327,99.5634765625,0.00236637822798166,4.22793965363617E-7,1,0.999253354069792,40.0298881530762,1.99901688738965,29.2000006884336,0.0269014083768043,0.00478538345653481,0.25,8.15643065577776E-6,0.00237848296931476,1.22518026512304E-5,141.0016327,141.0016327,99.5634765625,99.5634765625,56.9205336559483,20.6033829620749,24.047956,0,0,0,40,4374,143.5414,99.5634765625,,,,,,,,,,,,,0,,,,-0.00245,,,,,,141.0016327,,,,
,30292305.535,143.5470123,99.5634765625,0.00233533174665262,3.84794243109761E-7,1,0.999253354069792,40.0298881530762,1.99829954137836,29.2000006884336,0.0265379667180583,0.0047199029328293,0.25,8.08234189174579E-6,0.00234714085213235,1.2019252605106E-5,143.5470123,143.5470123,99.5634765625,99.5634765625,57.1370447557753,20.5996951214594,24.427608,0,0,0,40,4374,146.09865,99.5634765625,,,,,,,,,,,,,0,,,,0.00245,,,,,,143.5470123,,,,
touchdown = 18.9800001680851 mm,30292402.35,145.9503021,99.5634765625,0.00230588888388855,4.05555965461081E-7,1,0.999253354069792,40.0298881530762,1.99934243738367,29.2000006884336,0.02621605404517,0.00465614778722237,0.25,7.51843471010072E-6,0.00231741897694144,1.13099282243133E-5,145.9503021,145.9503021,99.5634765625,99.5634765625,57.1511140691214,20.5948211165315,24.047956,0,0,0,40,4374,148.5297,99.5634765625,,,,,,,,,,,,,0,,,,0.0049,,,,,,145.9503021,,,,
,30292487.835,148.0393066,99.5634765625,0.00228144503589555,4.05415928778962E-7,1,0.999253354069792,40.0298881530762,1.99799358224274,29.2000006884336,0.0259201400579563,0.00460363121739537,0.25,7.51886456059495E-6,0.00229273780412547,1.11928826584426E-5,148.0393066,148.0393066,99.5634765625,99.5634765625,57.2441278629099,20.6063840113335,24.047956,0,0,0,40,4374,150.6703,99.5634765625,,,,,,,,,,,,,0,,,,0.0049,,,,,,148.0393066,,,,
,30292585.955,150.5219879,99.5634765625,0.00225211378012711,3.88026622016082E-7,1,0.999253354069792,40.0298881530762,1.99779825065438,29.2000006884336,0.0255831555264648,0.00454253549776797,0.25,7.39908169143353E-6,0.00226312292398448,1.09415807986513E-5,150.5219879,150.5219879,99.5634765625,99.5634765625,57.0112025641791,20.6118453413271,24.047956,0,0,0,40,4374,153.1299,99.5634765625,,,,,,,,,,,,,0,,,,0,,,,,,150.5219879,,,,
,30292686.85,153.0137939,99.5634765625,0.00222276535499218,3.66543532417196E-7,1,0.999253354069792,40.0298881530762,1.9975149941788,29.2000006884336,0.0252461658537617,0.00447444303578896,0.25,6.678212345895E-6,0.00223349225236251,1.00901362240698E-5,153.0137939,153.0137939,99.5634765625,99.5634765625,56.709493955756,20.6083966919066,24.427608,0,0,0,40,4374,155.66145,99.5634765625,,,,,,,,,,,,,0,,,,-0.00245,,,,,,153.0137939,,,,
,30292804.17,155.9243927,99.5634765625,,,2,,,,29.2100001680851,,,,,,,155.9243927,155.9243927,99.5634765625,99.5634765625,,,24.047956,,,,-99999999,4374,158.5954,99.5634765625,,,,,,,,,,,,,,,,,,,,,,,155.9243927,,,,
,30292886.74,158.0145111,99.5634765625,0.00216331565151669,4.24712368097134E-7,1,0.999253354069792,40.0298881530762,1.97365381070041,29.2000006884336,0.0242869094301618,0.00430710186512956,0.25,6.87385629582573E-6,0.00217347336602735,1.00506854290954E-5,158.0145111,158.0145111,99.5634765625,99.5634765625,56.9424192544868,20.6105072084349,24.427608,0,0,0,40,4374,160.66185,99.5634765625,,,,,,,,,,,,,0,,,,0,,,,,,158.0145111,,,,
,30292987.715,160.5299072,99.5634765625,0.00213476563502338,4.34152523040488E-7,1,0.999253354069792,40.0298881530762,1.97424941581841,29.2000006884336,0.0239723180384978,0.00424762112848973,0.25,6.53128234495416E-6,0.00214464605070358,9.59728491370276E-6,160.5299072,160.5299072,99.5634765625,99.5634765625,57.3379232852176,20.6108758571077,24.427608,0,0,0,40,4374,163.1898,99.5634765625,,,,,,,,,,,,,0,,,,0.0049,,,,,,160.5299072,,,,
,30293086.43,163.0095062,99.5634765625,0.002108121167323,3.79314801891315E-7,1,0.999253354069792,40.0298881530762,1.98539577371252,29.2000006884336,0.0237987484384922,0.00421961054847784,0.25,6.74691832634825E-6,0.00211773559973842,9.71360104741752E-6,163.0095062,163.0095062,99.5634765625,99.5634765625,57.4145228801022,20.6241001883501,24.047956,0,0,0,40,4374,165.6576,99.5634765625,,,,,,,,,,,,,0,,,,0,,,,,,163.0095062,,,,
,30293189.865,165.5613098,99.5634765625,0.00207892263874179,4.48742465370666E-7,1,0.999253354069792,40.0298881530762,1.98676401523537,29.2000006884336,0.0234843107097324,0.00415564545559574,0.25,6.00932509271087E-6,0.00208825839347418,8.87019460611601E-6,165.5613098,165.5613098,99.5634765625,99.5634765625,57.4113963660253,20.6061249344465,24.427608,0,0,0,40,4374,168.2498,99.5634765625,,,,,,,,,,,,,0,,,,0.0049,,,,,,165.5613098,,,,
,30293288.41,168.063324,99.5634765625,0.0020536978784888,4.02616773061968E-7,1,0.999253354069792,40.0298881530762,1.99913881955968,29.2000006884336,0.0233360732561467,0.00412696843916198,0.25,5.78256846254676E-6,0.00206277633283782,8.5523184713358E-6,168.0359192,168.0907288,99.5634765625,99.5634765625,57.3402681707753,20.595550446226,24.427608,0,0,0,40,4374,170.72185,99.5634765625,,,,,,,,,,,,,0,,,,0.0049,,,,,,168.063324,,,,
,30293387.725,170.5198669,99.5634765625,0.00203324285059389,3.94050467049662E-7,1,0.999253354069792,40.0298881530762,1.9990598586507,29.2000006884336,0.0231012410748938,0.00408499734343915,0.25,5.73953309740842E-6,0.00204208894008587,8.42873030362671E-6,170.5198669,170.5198669,99.5634765625,99.5634765625,57.6365053795638,20.5997844918561,25.186911,0,0,0,40,4374,173.20075,99.5634765625,,,,,,,,,,,,,0,,,,0.0049,,,,,,170.5198669,,,,
,30293487.16,173.0233765,99.5634765625,0.00201398087329298,4.33121802171738E-7,1,0.999253354069792,40.0298881530762,1.99965542076081,29.2000006884336,0.0228876157395499,0.00404506325617074,0.25,5.55080566039221E-6,0.00202259805973123,8.1632957997317E-6,172.9919434,173.0548096,99.5634765625,99.5634765625,57.586481154333,20.5972456827996,24.427608,0,0,0,40,4374,175.6914,99.5634765625,,,,,,,,,,,,,0,,,,0.0049,,,,,,173.0233765,,,,
,30293586.82,175.5115051,99.5634765625,0.00199300936521867,3.75120578782311E-7,1,0.999253354069792,40.0298881530762,1.99949550392705,29.2000006884336,0.0226463011707395,0.00400016946795368,0.25,5.34873467968142E-6,0.0020013923960768,7.88532117851587E-6,175.5115051,175.5115051,99.5634765625,99.5634765625,57.5466180998522,20.601675647188,24.427608,0,0,0,40,4374,178.1801,99.5634765625,,,,,,,,,,,,,0,,,,-0.00245,,,,,,175.5115051,,,,
,30293686.1,178.0167084,99.5634765625,0.00197208652270628,4.49340649071724E-7,1,0.999253354069792,40.0298881530762,1.97437296108026,29.2000006884336,0.0221375119736651,0.00391289161438108,0.25,5.56140588618658E-6,0.0019802353601282,8.02689555936382E-6,178.0167084,178.0167084,99.5634765625,99.5634765625,57.5513078709676,20.6035142715306,24.807261,0,0,0,40,4374,180.65995,99.5634765625,,,,,,,,,,,,,0,,,,0,,,,,,178.0167084,,,,
,30293789.16,180.5127716,99.5634765625,0.00199868867986259,4.01727882047596E-7,1,0.999253354069792,40.0298881530762,1.97541110037404,29.2000006884336,0.0224451153532983,0.00397101418684063,0.25,6.00653854115138E-6,0.00200679850422711,8.45990692734874E-6,180.5127716,180.5127716,99.5634765625,99.5634765625,57.271484861083,20.607184072464,25.186911,0,0,0,40,4374,183.2794,99.5634765625,,,,,,,,,,,,,0,,,,-0.00245,,,,,,180.5127716,,,,
,30293889.05,183.0370789,99.5634765625,0.00159548255806828,4.7631390277653E-6,1,0.999253354069792,40.0298881530762,1.9756372582512,29.2000006884336,0.0170169174611866,0.00835309266111376,0.25,0.000466110928100961,0.0016012839660115,0.000469873462173252,183.0370789,183.0370789,99.5634765625,99.5634765625,57.3723149400638,20.5972682846072,25.186911,0,0,0,40,4374,185.76695,99.5634765625,,,,,,,,,,,,,0,,,,0,,,,,,183.0370789,,,,
,30293987.645,185.5041656,99.5634765625,0.00142388468759162,8.64546768693666E-7,1,0.999253354069792,40.0298881530762,1.97517711321044,29.2000006884336,0.0151259052496067,0.00777690985282353,0.25,0.000444888727509881,0.00142892944611407,0.000448299655293782,185.5041656,185.5041656,99.5634765625,99.5634765625,57.5810097546984,20.6012171250407,24.807261,0,0,0,40,4374,188.21515,99.5634765625,,,,,,,,,,,,,0,,,,0,,,,,,185.5041656,,,,
,30294087.02,188.0181122,99.5634765625,0.00128497013851744,2.23688340783401E-5,1,0.999253354069792,40.0298881530762,1.97519546221926,29.1900001466274,0.0137258727885508,0.00657747429003573,0.25,0.000362314387053125,0.00128947630493973,0.000365186186114806,188.0181122,188.0181122,99.5634765625,99.5634765625,57.1472059265253,20.6035272875241,24.807261,0,0,0,40,4374,190.6834,99.5634765625,,,,,,,,,,,,,0,,,,0,,,,,,188.0181122,,,,
,30294188.11,190.5323029,99.5634765625,0.00125016150068649,3.19057298803188E-5,1,0.999253354069792,40.0298881530762,1.97516708845021,29.1900001466274,0.0133703112917861,0.00629854847815219,0.25,0.000343604424527967,0.00125446501441814,0.00034631307413514,190.5323029,190.5323029,99.5634765625,99.5634765625,57.3269804859484,20.5983008552123,25.566563,0,0,0,40,4374,193.24065,99.5634765625,,,,,,,,,,,,,0,,,,-0.00245,,,,,,190.5323029,,,,
,30294289.1,193.0218964,99.5634765625,0.00117336893107295,3.57961523146823E-5,1,0.999253354069792,40.0298881530762,1.9752202711719,29.1900001466274,0.0125166379329898,0.00609442339401088,0.25,0.000338820539131776,0.00117730446383592,0.000341375650712339,193.0218964,193.0218964,99.5634765625,99.5634765625,57.4465696493907,20.5931755433311,25.186911,0,0,0,40,4374,195.78495,99.5634765625,,,,,,,,,,,,,0,,,,0,,,,,,193.0218964,,,,
,30294390.285,195.5598831,99.5634765625,0.00108865807868662,3.41994378064857E-5,1,0.999253354069792,40.0298881530762,1.97626585019919,29.1900001466274,0.0115598619871728,0.00599164372353524,0.25,0.000344176225516212,0.00109219512341694,0.000346609196070828,195.5290985,195.5906677,99.5634765625,99.5634765625,57.4403166212368,20.5874511370051,25.186911,0,0,0,40,4374,198.32385,99.5634765625,,,,,,,,,,,,,0,,,,0,,,,,,195.5598831,,,,
touchdown = 18.9800001680851 mm,30294484.76,197.945816,99.5634765625,0.00105408462991212,2.41606442076138E-5,1,0.999253354069792,40.0298881530762,1.99965485663565,29.2000006884336,0.0112491167150321,0.00626549825634081,0.25,0.000368383092863361,0.00105739673737946,0.000370819806088953,197.945816,197.945816,99.5634765625,99.5634765625,56.9994781363906,20.5931923688896,25.186911,0,0,0,40,4374,200.71385,99.5634765625,,,,,,,,,,,,,0,,,,0.00245,,,,,,197.945816,,,,
,30294569.93,200.0041199,99.5634765625,0.0009980589190067,2.82901044795758E-5,1,0.999253354069792,40.0298881530762,1.99995898559818,29.2000006884336,0.0106107640902203,0.00617106086634095,0.25,0.000369771996462285,0.00100111171661464,0.000372114512113197,200.0041199,200.0041199,99.5634765625,99.5634765625,56.7556100383906,20.5691398760555,25.186911,0,0,0,40,4374,202.8285,99.5634765625,,,,,,,,,,,,,0,,,,-0.00245,,,,,,200.0041199,,,,
,30294669.965,202.5241241,99.5634765625,0.00100797661271496,5.87342482711129E-6,1,0.999253354069792,40.0298881530762,2.00032061251288,29.2099993675947,0.0106608978686595,0.00655747595086292,0.25,0.00040201983068072,0.00101095377375582,0.0004044352225737,202.5241241,202.5241241,99.5634765625,99.5634765625,57.5075366738907,20.5709878536809,24.807261,0,0,0,40,4374,205.3339,99.5634765625,,,,,,,,,,,,,0,,,,0,,,,,,202.5241241,,,,
,30294770.7,205.0591278,99.5634765625,0.000934773581065709,1.07488706255276E-5,1,0.999253354069792,40.0298881530762,2.00046354988964,29.2099993675947,0.00983334934951345,0.00638779889755666,0.25,0.000399821712955633,0.000937435411739598,0.000402105028218154,205.0591278,205.0591278,99.5634765625,99.5634765625,56.6328943608714,20.5644043445854,25.186911,0,0,0,40,4374,207.8462,99.5634765625,,,,,,,,,,,,,0,,,,0,,,,,,205.0591278,,,,
,30294887.05,207.9224548,99.5634765625,,,2,,,,29.1999996262789,,,,,,,207.9224548,207.9224548,99.5634765625,99.5634765625,,,25.566563,,,,-99999999,4374,210.7643,99.5634765625,,,,,,,,,,,,,,,,,,,,,,,207.9224548,,,,
,30294968.495,210.0112762,99.5634765625,0.00084925071226332,1.97764559087666E-5,1,0.999253354069792,40.0298881530762,1.99991045415227,29.1900001466274,0.00883596112857476,0.00634264587628148,0.25,0.000410959054248674,0.000851493750135862,0.000413098419434469,210.0112762,210.0112762,99.5634765625,99.5634765625,57.0807675023906,20.5750477222169,25.186911,0,0,0,40,4374,212.7967,99.5634765625,,,,,,,,,,,,,0,,,,0.00245,,,,,,210.0112762,,,,
,30295071.385,212.5499573,99.5634765625,0.000827122081581492,1.60804295530198E-5,1,0.999253354069792,40.0298881530762,1.99948073366961,29.2000006884336,0.00863764835827481,0.00597777696396207,0.25,0.000382841539106807,0.000829260311935466,0.000384826244271859,212.5499573,212.5499573,99.5634765625,99.5634765625,57.3676251689484,20.577265556437,25.566563,0,0,0,40,4374,215.38275,99.5634765625,,,,,,,,,,,,,0,,,,0,,,,,,212.5499573,,,,
,30295170.805,215.0395813,99.5634765625,0.000833761717492726,3.02254530850048E-5,1,0.999253354069792,40.0298881530762,1.99986230677004,29.2000006884336,0.00856155819422024,0.00686951793995728,0.25,0.000460169187359673,0.000835780739345262,0.000462346094569419,215.0395813,215.0395813,99.5634765625,99.5634765625,57.3238539718714,20.5687967377452,25.186911,0,0,0,40,4374,217.8704,99.5634765625,,,,,,,,,,,,,0,,,,0,,,,,,215.0395813,,,,
,30295271.675,217.5497131,99.5634765625,0.000852182947179271,2.57126602310997E-5,1,0.999253354069792,40.0298881530762,2.0002023524515,29.2000006884336,0.00881664719190549,0.00664637346163102,0.25,0.000437287347660952,0.000854213140548388,0.000439366099193392,217.5497131,217.5497131,99.5634765625,99.5634765625,57.373096568583,20.5803565126304,25.566563,0,0,0,40,4374,220.38895,99.5634765625,,,,,,,,,,,,,0,,,,0.00245,,,,,,217.5497131,,,,
,30295371.085,220.0276642,99.5634765625,0.000819382663872817,2.7345132312745E-5,1,0.999253354069792,40.0298881530762,1.99926755986539,29.1900001466274,0.00838050209547894,0.00691942383980476,0.25,0.000467353999729438,0.000821227314364787,0.000469437837765604,220.0276642,220.0276642,99.5634765625,99.5634765625,57.2019199228714,20.592917668572,25.566563,0,0,0,40,4374,222.8932,99.5634765625,,,,,,,,,,,,,0,,,,0,,,,,,220.0276642,,,,
,30295470.04,222.5048523,99.5634765625,0.000807271473378625,7.34384986460682E-6,1,0.999253354069792,40.0298881530762,2.00034267366795,29.1900001466274,0.00795744048876908,0.00856494575567168,0.25,0.000614101510174915,0.000808882960157377,0.000616521983766693,222.4702454,222.5394592,99.5634765625,99.5634765625,57.241001348833,20.578024916825,25.566563,0,0,0,40,4374,225.36885,99.5634765625,,,,,,,,,,,,,0,,,,-0.0049,,,,,,222.5048523,,,,
,30295570.915,225.0221558,99.5634765625,0.000817614737059963,8.04422363861181E-6,1,0.999253354069792,40.0298881530762,1.9999568866088,29.1900001466274,0.0080418645332669,0.00876138835293684,0.25,0.00062982124508613,0.000819177418746357,0.000632229785116233,225.0221558,225.0221558,99.5634765625,99.5634765625,57.3129111726022,20.5837886535851,25.566563,0,0,0,40,4374,227.8904,99.5634765625,,,,,,,,,,,,,0,,,,0,,,,,,225.0221558,,,,
,30295670.405,227.5326843,99.5634765625,0.000823625798569325,1.30677931851913E-5,1,0.999253354069792,40.0298881530762,2.0004386460752,29.1900001466274,0.00811205297888111,0.00877055106797907,0.25,0.000629482366511924,0.000825141505074131,0.000631831600735613,227.5326843,227.5326843,99.5634765625,99.5634765625,57.2886806885061,20.5759042833223,25.566563,0,0,0,40,4374,230.37925,99.5634765625,,,,,,,,,,,,,0,,,,-0.0049,,,,,,227.5326843,,,,
,30295770.25,230.0113525,99.5634765625,0.000818906476500547,1.28434487557624E-5,1,0.999253354069792,40.0298881530762,2.00038711805382,29.1900001466274,0.00806542274221563,0.00871560742627325,0.25,0.000625554869860057,0.000820351546040905,0.000627826925199164,230.0113525,230.0113525,99.5634765625,99.5634765625,57.0838940164676,20.5607364671921,25.186911,0,0,0,40,4374,232.8795,99.5634765625,,,,,,,,,,,,,0,,,,-0.0049,,,,,,230.0113525,,,,
,30295870.69,232.5115051,99.5634765625,0.00080810919853268,1.41864251566574E-5,1,0.999253354069792,40.0298881530762,2.00117272501869,29.1900001466274,0.00796600897512219,0.00857696720320892,0.25,0.000615007381500624,0.000809474867230578,0.000617181420298659,232.5115051,232.5115051,99.5634765625,99.5634765625,57.1761261817368,20.5593404670202,25.186911,0,0,0,40,4374,235.41045,99.5634765625,,,,,,,,,,,,,0,,,,0.0049,,,,,,232.5115051,,,,
,30295971.075,235.0299225,99.5634765625,0.000812979660622724,1.38508039558762E-5,1,0.999253354069792,40.0298881530762,2.00146965791192,29.2000006884336,0.00801830566523182,0.00860741996534506,0.25,0.000616810303567045,0.000814291413696404,0.000618929994442956,235.0299225,235.0299225,99.5634765625,99.5634765625,56.7860935506406,20.5612859187146,25.566563,0,0,0,40,4374,237.92495,99.5634765625,,,,,,,,,,,,,0,,,,-0.0049,,,,,,235.0299225,,,,
,30296072.665,237.5175323,99.5634765625,0.000788087952629723,1.33569828538503E-5,1,0.999253354069792,40.0298881530762,2.0019741368495,29.1900001466274,0.00775681446519739,0.00844469575546797,0.25,0.000606694216729199,0.000789290616578485,0.000608707777695942,237.5175323,237.5175323,99.5634765625,99.5634765625,57.1581487257945,20.552563614423,26.325863,0,0,0,40,4374,240.478,99.5634765625,,,,,,,,,,,,,0,,,,-0.00245,,,,,,237.5175323,,,,
,30296172.055,240.0278473,99.5634765625,0.000775016602579668,1.29606904770678E-5,1,0.999253354069792,40.0298881530762,1.9908113362175,29.1900001466274,0.00757838715150166,0.00830917486346622,0.25,0.000601016900461915,0.000776134078993419,0.000602945915941246,240.0016937,240.0540009,99.5634765625,99.5634765625,56.7743691228522,20.5660828011964,25.946213,0,0,0,40,4374,242.9404,99.5634765625,,,,,,,,,,,,,0,,,,-0.0049,,,,,,240.0278473,,,,
,30296273.725,242.5354767,99.5634765625,0.000774026818328272,9.59429517570499E-6,1,0.999253354069792,40.0298881530762,1.99127756072277,29.1900001466274,0.00758973309131329,0.00818484931060911,0.25,0.000590093044678397,0.00077509012702452,0.000591938156824537,242.5354767,242.5354767,99.5634765625,99.5634765625,56.8751992018329,20.5578569969746,25.946213,0,0,0,40,4374,245.5164,99.5634765625,,,,,,,,,,,,,0,,,,0,,,,,,242.5354767,,,,
,30296372.25,245.00970455,99.5634765625,0.000759980002762852,1.40718377438672E-5,1,0.999253354069792,40.0298881530762,1.99128829756075,29.1900001466274,0.00742761376338361,0.00817313795597214,0.25,0.000591558437794633,0.000760953780170005,0.000593335656564552,244.9812469,245.0381622,99.5634765625,99.5634765625,56.8767624588714,20.5538452447174,25.946213,0,0,0,40,4374,247.9794,99.5634765625,,,,,,,,,,,,,0,,,,0,,,,,,245.00970455,,,,
,30296474.135,247.5393677,99.5634765625,0.0007569560545553,1.13588571524667E-5,1,0.999253354069792,40.0298881530762,1.99188999035535,29.1900001466274,0.00743691731846516,0.00792710207605107,0.25,0.000570174007268481,0.00075788038950936,0.000571848957230143,247.5393677,247.5393677,99.5634765625,99.5634765625,57.2050464369484,20.5469200884025,25.566563,0,0,0,40,4374,250.53505,99.5634765625,,,,,,,,,,,,,0,,,,0,,,,,,247.5393677,,,,
touchdown = 18.9699996262789 mm,30296574.145,250.0645905,99.5634765625,0.000747411805756201,1.66236757797071E-5,1,0.999253354069792,40.0298881530762,1.99146969876984,29.1900001466274,0.00732444388450052,0.00792081255744038,0.25,0.000571482550053036,0.00074825662548978,0.000573093772874519,250.0645905,250.0645905,99.5634765625,99.5634765625,56.9002113144483,20.5476102084262,26.325863,0,0,0,40,4374,253.0651,99.5634765625,,,,,,,,,,,,,0,,,,0,,,,,,250.0645905,,,,
,30296672.54,252.5045319,99.5634765625,0.000746067478523182,1.73670980769689E-5,1,0.999253354069792,40.0298881530762,1.99175078357629,29.1900001466274,0.00730568833899138,0.0079415474363192,0.25,0.000573522759506164,0.000746849351406405,0.000575080035770673,252.5045319,252.5045319,99.5634765625,99.5634765625,57.1815975813714,20.5510578947536,25.946213,0,0,0,40,4374,255.5114,99.5634765625,,,,,,,,,,,,,0,,,,0.0049,,,,,,252.5045319,,,,
,30296773.545,255.0092621,99.5634765625,0.000740964272116289,1.48275510563309E-5,1,0.999253354069792,40.0298881530762,1.99154705109386,29.1900001466274,0.00727654677430003,0.0077581951752891,0.25,0.000558313376909838,0.000741689501470608,0.000559784635726296,255.0092621,255.0092621,99.5634765625,99.5634765625,57.2245871499291,20.5543083483349,25.946213,0,0,0,40,4374,258.0459,99.5634765625,,,,,,,,,,,,,0,,,,-0.0049,,,,,,255.0092621,,,,
,30296873.965,257.5004578,99.5634765625,0.00074234268661218,1.20629897709851E-5,1,0.999253354069792,40.0298881530762,1.99136899676101,29.1900001466274,0.00729138880527732,0.00775679045304011,0.25,0.000558075090324493,0.000743009784187791,0.000559490958053077,257.5004578,257.5004578,99.5634765625,99.5634765625,57.2472543769868,20.5563739981234,25.946213,0,0,0,40,4374,260.5372,99.5634765625,,,,,,,,,,,,,0,,,,-0.0049,,,,,,257.5004578,,,,
,30296975.94,260.0104065,99.5634765625,,,2,,,,29.2100001680851,,,,,,,260.0104065,260.0104065,99.5634765625,99.5634765625,,,26.325863,,,,-99999999,4374,263.1143,99.5634765625,,,,,,,,,,,,,,,,,,,,,,,260.0104065,,,,
,30297053.915,262.0084534,99.5634765625,0.000715530071757907,1.38587310143957E-5,1,0.999253354069792,40.0298881530762,1.99145848175433,29.2000006884336,0.00702302966066087,0.0075004267494092,0.25,0.000540113344346864,0.000716065366099179,0.000541383198456062,262.0084534,262.0084534,99.5634765625,99.5634765625,56.9377294833714,20.5631503705979,25.946213,0,0,0,40,4374,265.0665,99.5634765625,,,,,,,,,,,,,0,,,,-0.0049,,,,,,262.0084534,,,,
,30297155.455,264.5037231,99.5634765625,0.000714868290105251,1.11300204392634E-5,1,0.999253354069792,40.0298881530762,1.99143274937429,29.2000006884336,0.00702663453085828,0.00743069125203619,0.25,0.000534124955818101,0.000715348446927298,0.000535332564325136,264.5037231,264.5037231,99.5634765625,99.5634765625,56.9877537086022,20.5637742786454,25.946213,0,0,0,40,4374,267.6016,99.5634765625,,,,,,,,,,,,,0,,,,-0.0049,,,,,,264.5037231,,,,
,30297256.04,267.0350647,99.5634765625,0.000709503357710344,1.57253834940435E-5,1,0.999253354069792,40.0298881530762,1.99196911514667,29.2000006884336,0.0069929022498537,0.0072735624078705,0.25,0.000521037615614861,0.000709927198356069,0.000522171744825874,267.0350647,267.0350647,99.5634765625,99.5634765625,57.2894623170253,20.5601490980437,26.325863,0,0,0,40,4374,270.126,99.5634765625,,,,,,,,,,,,,0,,,,-0.0049,,,,,,267.0350647,,,,
,30297357.165,269.5491638,99.5634765625,0.000699526440473108,1.1222737492929E-5,1,0.999253354069792,40.0298881530762,1.99128993653638,29.2000006884336,0.00686157571456107,0.00734241736814591,0.25,0.00052913901951825,0.000699874377721076,0.000530221478647729,269.5491638,269.5491638,99.5634765625,99.5634765625,57.2589788047753,20.5541957166884,26.705515,0,0,0,40,4374,272.686,99.5634765625,,,,,,,,,,,,,0,,,,0.0049,,,,,,269.5491638,,,,
,30297459.875,272.08810425,99.5634765625,0.000694396850073238,1.54704687721153E-5,1,0.999253354069792,40.0298881530762,1.9791333864903,29.2099993675947,0.00680222212020226,0.00706512655569432,0.25,0.000509198916258008,0.000694695367109227,0.000510204415964405,272.0516052,272.1246033,99.5634765625,99.5634765625,57.0119841926983,20.5471884477761,25.946213,0,0,0,40,4374,275.2276,99.5634765625,,,,,,,,,,,,,0,,,,-0.0049,,,,,,272.08810425,,,,
,30297559.01,274.5812378,99.5634765625,0.000669411557111698,1.7235264112202E-5,1,0.999253354069792,40.0298881530762,1.97926166576367,29.2099993675947,0.00653168618094115,0.00695871047536869,0.25,0.000504068611830057,0.000669633867442582,0.000505000455239292,274.5812378,274.5812378,99.5634765625,99.5634765625,57.146424298006,20.5525426452717,26.325863,0,0,0,40,4374,277.7035,99.5634765625,,,,,,,,,,,,,0,,,,0.00245,,,,,,274.5812378,,,,
,30297657.21,277.0149536,99.5634765625,0.00068545519119101,1.5414965225648E-5,1,0.999253354069792,40.0298881530762,1.97917469879654,29.2099993675947,0.00670572808891959,0.00701889171159947,0.25,0.000506735929338779,0.00068563388424511,0.000507632346653326,277.0149536,277.0149536,99.5634765625,99.5634765625,57.1112510146407,20.5534755289793,25.946213,0,0,0,40,4374,280.17745,99.5634765625,,,,,,,,,,,,,0,,,,0,,,,,,277.0149536,,,,
,30297759.04,279.5635681,99.5634765625,0.000683618626834834,1.31953618548474E-5,1,0.999253354069792,40.0298881530762,1.9793069671421,29.2099993675947,0.00672636413381344,0.00677635821693332,0.25,0.000485460309323755,0.000683752550645824,0.000486288877872633,279.5635681,279.5635681,99.5634765625,99.5634765625,57.0995265868522,20.5506929303226,26.325863,0,0,0,40,4374,282.707,99.5634765625,,,,,,,,,,,,,0,,,,0,,,,,,279.5635681,,,,
,30297857.75,282.0114136,99.5634765625,0.000676634714541745,1.20334328360487E-5,1,0.999253354069792,40.0298881530762,1.9923619638498,29.2099993675947,0.00670048421123525,0.0067404288759712,0.25,0.0004797648760088,0.000676711950840511,0.000480537424950064,282.0114136,282.0114136,99.5634765625,99.5634765625,57.2753930036791,20.5527538566657,26.705515,0,0,0,40,4374,285.1376,99.5634765625,,,,,,,,,,,,,0,,,,-0.0049,,,,,,282.0114136,,,,
,30297959.05,284.5480957,99.5634765625,0.000676664729389569,1.2251651015817E-5,1,0.999253354069792,40.0298881530762,1.99258926831836,29.2099993675947,0.00670893860392613,0.00669471826916332,0.25,0.000475704635623015,0.000676686936427869,0.000476426355094224,284.5480957,284.5480957,99.5634765625,99.5634765625,57.3254172289099,20.5532557235727,25.946213,0,0,0,40,4374,287.6975,99.5634765625,,,,,,,,,,,,,0,,,,-0.0049,,,,,,284.5480957,,,,
,30298059.36,287.0393066,99.5634765625,0.000677302708204261,1.21613839822924E-5,1,0.999253354069792,40.0298881530762,1.9932147384985,29.2099993675947,0.00674776648605772,0.00652326217941646,0.25,0.000460290551260538,0.000677278912461486,0.0004609586210239,287.0393066,287.0393066,99.5634765625,99.5634765625,57.3652802833907,20.545209986392,26.705515,0,0,0,40,4374,290.2164,99.5634765625,,,,,,,,,,,,,0,,,,0,,,,,,287.0393066,,,,
,30298159.69,289.5413513,99.5634765625,0.000675073477877119,8.82064427285643E-6,1,0.999253354069792,40.0298881530762,1.99320361612754,29.2099993675947,0.00673881789479328,0.0064211816416635,0.25,0.000451695433195376,0.000674997366702428,0.000452312932138255,289.5413513,289.5413513,99.5634765625,99.5634765625,57.5020652742561,20.5455676799293,26.325863,0,0,0,40,4374,292.72895,99.5634765625,,,,,,,,,,,,,0,,,,-0.00245,,,,,,289.5413513,,,,
,30298260.2,292.0583496,99.5634765625,0.000669867694557897,1.17890425261426E-5,1,0.999253354069792,40.0298881530762,1.99334147122286,29.2399991303682,0.00669376361025505,0.00633090087798048,0.25,0.000444619636627821,0.000669737342972238,0.000445186404602621,292.0583496,292.0583496,99.5634765625,99.5634765625,57.4145228801022,20.5377541055466,26.325863,0,0,0,40,4374,295.22895,99.5634765625,,,,,,,,,,,,,0,,,,0,,,,,,292.0583496,,,,
,30298359.95,294.516861,99.5634765625,0.000665885133706878,8.57825941380996E-6,1,0.999253354069792,40.0298881530762,1.99312613867214,29.2399991303682,0.00666047254634038,0.00624737761043977,0.25,0.000438022283297855,0.000665702652738016,0.000438541593570152,294.4844666,294.5492554,99.5634765625,99.5634765625,57.677931691083,20.544497578689,26.325863,0,0,0,40,4374,297.7369,99.5634765625,,,,,,,,,,,,,0,,,,0,,,,,,294.516861,,,,
,30298461.15,297.0369263,99.5634765625,0.000658900758283771,1.15274590500964E-5,1,0.999253354069792,40.0298881530762,1.99301958438884,29.2399991303682,0.00658280545180498,0.00622086090818275,0.25,0.000436965281026879,0.000658661425732867,0.000437435880114643,297.0369263,297.0369263,99.5634765625,99.5634765625,57.7576578000446,20.5444781093015,26.325863,0,0,0,40,4374,300.2852,99.5634765625,,,,,,,,,,,,,0,,,,-0.0049,,,,,,297.0369263,,,,
,30298625.785,299.5055542,99.5634765625,0.000655741400044205,1.12822622072164E-5,1,0.999253354069792,40.0298881530762,1.99309981072766,29.2399991303682,0.00656492672366179,0.00610984676507108,0.25,0.000427705049224506,0.000655450010867271,0.000428134562783805,299.5055542,299.5055542,99.5634765625,99.5634765625,57.3840393678522,20.5435131503165,26.705515,0,0,0,40,4374,300.4578,99.5634765625,,,,,,,,,,,,,0,,,,0,,,,,,299.5055542,,,,
,30298753.485,299.8088379,99.5634765625,0.000653331988095401,1.54983873238832E-5,1,0.999253354069792,40.0298881530762,1.99313414728315,29.2399991303682,0.006511071671589,0.00625924618772198,0.25,0.000441355779293663,0.00065302437607853,0.000441778824976235,299.8088379,299.8088379,99.5634765625,99.5634765625,57.657609349583,20.5445064489253,26.325863,0,0,0,40,4369,300.3909,99.5634765625,,,,,,,,,,,,,0,,,,0,,,,,,299.8088379,,,,