File: data/looselyPackedNP/ios-11/ppms/rawdata/PMK18_HYST_ZFC_30K.DAT
[Header]
; VSM Data File (default extension .dat)
; Copyright (c) 2003-2013, Quantum Design, Inc. All rights reserved.
TITLE,
FILEOPENTIME,32666649.53,01/14/2019,10:06 am
BYAPP,VSM,2.0,2.0
INFO,PPMS VSM Option Release 1.4.10 Build 1,APPNAME
INFO,Quantum Design Linear Motor Servo Controller,MOTOR_MODULE_NAME
INFO,3101-100 M1,MOTOR_HW_VERSION
INFO,MMC1014,MOTOR_SERIAL_NUMBER
INFO,SRV No X-over 01.03.11,MOTOR_SOFTWARE_VERSION
INFO,Quantum Design VSM Detection Module,VSM_MODULE_NAME
INFO,3101-150 F0,VSM_HW_VERSION
INFO,VSM707,VSM_SERIAL_NUMBER
INFO,VSM No X-over 01.02.05 May 20 2008 13:51:47,VSM_SOFTWARE_VERSION
INFO,704,PREAMP_SERIAL_NUMBER
INFO,822,COIL_SERIAL_NUMBER
INFO,0,MOMENT_UNITS
INFO,Maghemite,SAMPLE_MATERIAL
INFO,Oleate Iron Spheres,SAMPLE_COMMENT
INFO,,SAMPLE_MASS
INFO,,SAMPLE_VOLUME
INFO,,SAMPLE_MOLECULAR_WEIGHT
INFO,,SAMPLE_SIZE
INFO,,SAMPLE_SHAPE
DATATYPE,COMMENT,1
DATATYPE,TIME,2
STARTUPAXIS,X,2
STARTUPAXIS,Y1,5
[Data]
Comment,Time Stamp (sec),Temperature (K),Magnetic Field (Oe),Moment (emu),M. Std. Err. (emu),Transport Action,Averaging Time (sec),Frequency (Hz),Peak Amplitude (mm),Center Position (mm),Coil Signal' (mV),Coil Signal" (mV),Range (mV),M. Quad. Signal (emu),M. Raw' (emu),M. Raw" (emu),Min. Temperature (K),Max. Temperature (K),Min. Field (Oe),Max. Field (Oe),Mass (grams),Motor Lag (deg),Pressure (Torr),VSM Status (code),Motor Status (code),Measure Status (code),Measure Count,PPMS Status (code),System Temp. (K),System Field (Oe),Sample Position (deg),Bridge 1 Resistance (ohms),Bridge 1 Excitation (에),Bridge 2 Resistance (ohms),Bridge 2 Excitation (에),Bridge 3 Resistance (ohms),Bridge 3 Excitation (에),Bridge 4 Resistance (ohms),Bridge 4 Excitation (에),Signal 1 Vin (V),Signal 2 Vin (V),Digital Inputs (code),Drive 1 Iout (mA),Drive 1 Ipower (W),Drive 2 Iout (mA),Drive 2 Ipower (W),Pressure (),Map 20 (),Map 21 (),Map 22 (),Map 23 (),Map 24 (),Map 25 (),Map 26 (),Map 27 (),Map 28 (),Map 29 ()
,32666665.81,29.9963932,0.243580371141434,,,2,,,,34.1100009202957,,,,,,,29.9963932,29.9963932,0.243580371141434,0.243580371141434,,,16.075285,,,,-99999999,4369,29.996,0.243580371141434,,,,,,,,,,,,,,,,,,,,,,,29.9963932,,,,
,32666743.965,30.0192661,926.003540039063,0.00737152292934879,1.23699350298911E-5,1,0.999253354069792,40.0298881530762,2.00142351821447,34.0999998152256,0.0828644744439596,0.0157557348063222,0.25,8.44983089996621E-5,0.00733305367071274,0.000124690433051432,30.0192661,30.0192661,920.967590332031,931.039489746094,55.7824825319482,20.7346132372237,16.075285,0,0,0,40,4449,29.9839,926.003540039063,,,,,,,,,,,,,0,,,,0,,,,,,30.0192661,,,,
,32666769.485,30.0200281,2197.48266601562,0.0102684495654364,2.35474612820961E-6,1,0.999253354069792,40.0298881530762,2.00367101248393,34.0900011360645,0.115586120759178,0.0219171464791605,2.5,0.000111920958974703,0.0102155779672464,0.000168564659335695,30.0196457,30.0204105,2187.5537109375,2207.41162109375,55.6691463966597,20.7165160718622,16.075285,0,0,0,40,4449,29.9734,2197.48266601562,,,,,,,,,,,,,0,,,,-0.0049,,,,,,30.0200281,,,,
,32666791.415,30.0193996,3294.32702636719,0.0109023672548212,1.25084046942418E-6,1,0.999253354069792,40.0298881530762,2.00493119644444,34.0999998152256,0.122810678506876,0.0232453625270545,2.5,0.000114630469908516,0.010846965803569,0.000175427806724196,30.0193996,30.0193996,3289.30004882812,3299.35400390625,56.1811130767559,20.7005495460539,16.075285,0,0,0,40,4449,29.9656,3294.32702636719,,,,,,,,,,,,,0,,,,0.0049,,,,,,30.0193996,,,,
,32666814.915,30.0156384,4464.0703125,0.0113046131366762,1.80118717932198E-6,1,0.999253354069792,40.0298881530762,2.00688240956981,34.0900011360645,0.127457022982939,0.0241988674605258,2.5,0.000124462107025333,0.011247995407455,0.000188223873793196,30.0156384,30.0156384,4451.62109375,4476.51953125,56.106858367429,20.6864326002873,16.075285,0,0,0,40,4449,29.9664,4464.0703125,,,,,,,,,,,,,0,,,,0.00245,,,,,,30.0156384,,,,
,32666837.405,30.0122051,5586.94555664063,0.0115400838913087,1.02456807811952E-6,1,0.999253354069792,40.0298881530762,1.9952945318994,34.0999998152256,0.12939141923965,0.0246452270372701,2.5,0.000133118698421371,0.0114831433050347,0.000198935457397231,30.0122051,30.0122051,5579.49169921875,5594.3994140625,56.3022654972367,20.6778446741163,16.075285,0,0,0,40,4449,29.9669,5586.94555664063,,,,,,,,,,,,,0,,,,0.00245,,,,,,30.0122051,,,,
,32666860.71,30.011116,6750.87475585938,0.0117461047629409,1.186221205896E-6,1,0.999253354069792,40.0298881530762,1.99435954296338,34.0999998152256,0.131655422488162,0.025065900504949,2.5,0.000133789024723042,0.0116891396907472,0.00020159981305479,30.011116,30.011116,6743.6162109375,6758.13330078125,56.2100333319675,20.691816067184,15.695635,0,0,0,40,4449,29.96575,6750.87475585938,,,,,,,,,,,,,0,,,,0,,,,,,30.011116,,,,
,32666883.14,30.0082626,7870.21337890625,0.0119158764522063,1.23205253987372E-6,1,0.999253354069792,40.0298881530762,1.99390664021124,34.0999998152256,0.133539817727968,0.025429028745135,2.5,0.000135316381823614,0.0118590828254365,0.000204904357331951,30.0082626,30.0082626,7857.86279296875,7882.56396484375,56.1506295645059,20.6814387864901,15.695635,0,0,0,40,4449,29.96165,7870.21337890625,,,,,,,,,,,,,0,,,,0.00245,,,,,,30.0082626,,,,
,32666905.885,30.0087433,9010.29345703125,0.0120701617990783,9.46873984649945E-7,1,0.999253354069792,40.0298881530762,1.9957486075403,34.0900011360645,0.135385604582145,0.0258649185242954,2.5,0.000143518396146284,0.0120136579381314,0.000214804695014697,30.0087433,30.0087433,9002.646484375,9017.9404296875,56.1701702774867,20.6882483205293,16.075285,0,0,0,40,4449,29.96135,9010.29345703125,,,,,,,,,,,,,0,,,,-0.00245,,,,,,30.0087433,,,,
,32666927.93,30.0059261,10112.1044921875,0.0122010558654415,1.25074359634044E-6,1,0.999253354069792,40.0298881530762,1.99565259291216,34.0999998152256,0.136853926031213,0.0261785114376957,2.5,0.000147126017925429,0.0121449998386124,0.000219985787674281,30.0059261,30.0059261,10097.0439453125,10127.1650390625,56.6399290175445,20.6786892714863,16.075285,0,0,0,40,4449,29.9637,10112.1044921875,,,,,,,,,,,,,0,,,,0,,,,,,30.0059261,,,,
,32666950.84,30.0062656,11256.5043945312,0.0123147265638199,1.6008506596656E-6,1,0.999253354069792,40.0298881530762,1.99457783479922,34.0900011360645,0.138101084908434,0.026242482436953,2.5,0.000132650095804853,0.0122593916910016,0.000207097798398005,30.0062656,30.0062656,11246.412109375,11266.5966796875,56.6735390438714,20.6851283847023,15.315984,0,0,0,40,4449,29.9612,11256.5043945312,,,,,,,,,,,,,0,,,,-0.00245,,,,,,30.0062656,,,,
,32666974.07,30.0057507,12415.6284179688,0.0124114725587453,1.56847428026224E-6,1,0.999253354069792,40.0298881530762,1.99612704752034,34.0999998152256,0.139328825013088,0.0263256152817064,2.5,0.000119945188256786,0.0123569909789804,0.000195886492153729,30.0057507,30.0057507,12410.56640625,12420.6904296875,56.4671891147944,20.6821347114624,15.695635,0,0,0,40,4449,29.9611,12415.6284179688,,,,,,,,,,,,,0,,,,0,,,,,,30.0057507,,,,
,32666997.56,30.0047455,13593.0356445313,0.0125428091837014,1.35010140699894E-6,1,0.999253354069792,40.0298881530762,1.99529699873166,34.0999998152256,0.140725859008328,0.026796082298443,2.5,0.000138138637454371,0.0124889109492505,0.000215672525974032,30.0047455,30.0047455,13585.5146484375,13600.556640625,56.2772533846213,20.7032417156777,15.695635,0,0,0,40,4449,29.9626,13593.0356445313,,,,,,,,,,,,,0,,,,-0.00245,,,,,,30.0047455,,,,
,32667021.435,30.0057449,14784.7866210938,0.0126480862850331,1.52282379496671E-6,1,0.999253354069792,40.0298881530762,1.99419316689697,34.0999998152256,0.141829395230256,0.0271072030818162,2.5,0.000147147302302816,0.0125949945534515,0.000226160794652707,30.0057449,30.0057449,14774.7841796875,14794.7890625,57.3668435404292,20.7097447589115,16.075285,0,0,0,40,4449,29.95895,14784.7866210938,,,,,,,,,,,,,0,,,,0.00245,,,,,,30.0057449,,,,
,32667045.055,30.0045986,15964.2470703125,0.0127275937457105,1.79354200626749E-6,1,0.999253354069792,40.0298881530762,1.99366582112805,34.0999998152256,0.142728408104639,0.0271147803751049,2.5,0.000133112799166678,0.0126755933734923,0.000213528236340118,30.0045986,30.0045986,15959.20703125,15969.287109375,55.812184415679,20.7140277614107,15.315984,0,0,0,40,4449,29.9582,15964.2470703125,,,,,,,,,,,,,0,,,,0,,,,,,30.0045986,,,,
,32667067.38,30.0051174,17081.0458984375,0.0128240132980745,1.22453842638042E-6,1,0.999253354069792,40.0298881530762,1.99482809394494,34.0999998152256,0.14388764578592,0.027431126369134,2.5,0.000141618601653845,0.0127728626204265,0.000223403560180581,30.0051174,30.0051174,17073.521484375,17088.5703125,56.3522897224675,20.7019298152823,16.075285,0,0,0,40,4449,29.9592,17081.0458984375,,,,,,,,,,,,,0,,,,0.00245,,,,,,30.0051174,,,,
,32667089.81,30.0043812,18200.66796875,0.0129009590185703,1.41573722131447E-6,1,0.999253354069792,40.0298881530762,1.9945153459262,34.0999998152256,0.14473567472606,0.0276422534870437,2.5,0.000145963306155551,0.0128507986138045,0.000229004910709407,30.0043812,30.0043812,18193.20703125,18208.12890625,56.3350938950444,20.6996616777663,16.075285,0,0,0,40,4449,29.95995,18200.66796875,,,,,,,,,,,,,0,,,,0.00245,,,,,,30.0043812,,,,
,32667113.665,30.0028496,19392.3095703125,0.0129749057917909,1.9603117604738E-6,1,0.999253354069792,40.0298881530762,1.9968719139374,34.0999998152256,0.145765922516572,0.0277216770328476,2.5,0.000135932009781328,0.0129259547748318,0.00022030079492013,30.0028496,30.0028496,19382.3359375,19402.283203125,57.2886806885061,20.6654097813098,15.315984,0,0,0,40,4449,29.9574,19392.3095703125,,,,,,,,,,,,,0,,,,0,,,,,,30.0028496,,,,
,32667155.425,30.0010185,19559.830078125,0.0129854109095756,1.50991414085676E-6,1,0.999253354069792,40.0298881530762,1.99638686287428,34.0999998152256,0.145864126175163,0.0276728048984743,2.5,0.000130128229600425,0.0129366614349321,0.000214699401002109,30.0010185,30.0010185,19549.9453125,19569.71484375,57.0369963053137,20.6695964281077,15.315984,0,0,0,40,4449,29.9572,19559.830078125,,,,,,,,,,,,,0,,,,0.0049,,,,,,30.0010185,,,,
,32667178.685,29.9996243,18402.9111328125,0.0129333156116055,1.0387755928461E-6,1,0.999253354069792,40.0298881530762,1.99678892542184,34.0999998152256,0.145270133133153,0.0276816765489208,2.5,0.000140811952917777,0.0128833055175931,0.000224221494219537,29.9996243,29.9996243,18395.416015625,18410.40625,56.9572701963522,20.6709399591181,15.695635,0,0,0,40,4449,29.9595,18402.9111328125,,,,,,,,,,,,,0,,,,0,,,,,,29.9996243,,,,
,32667202.275,29.9999866,17225.7158203125,0.0128570397401205,1.08869300830424E-6,1,0.999253354069792,40.0298881530762,1.99720693457169,34.0999998152256,0.144426085924232,0.027524028784399,2.5,0.000141043093607832,0.0128059397188291,0.000223147872556333,29.9999866,29.9999866,17218.1015625,17233.330078125,56.7915649502752,20.6707634104881,15.695635,0,0,0,40,4449,29.9642,17225.7158203125,,,,,,,,,,,,,0,,,,-0.0049,,,,,,29.9999866,,,,
,32667224.795,30.0001106,16099.337890625,0.0127750676593826,1.78571786504442E-6,1,0.999253354069792,40.0298881530762,1.99710114367656,34.0999998152256,0.143488668073948,0.0273144362997975,2.5,0.000138257082835302,0.0127230057369159,0.000219054211898796,30.0001106,30.0001106,16094.3271484375,16104.3486328125,57.027616763083,20.6729886817898,16.075285,0,0,0,40,4449,29.96325,16099.337890625,,,,,,,,,,,,,0,,,,0.0049,,,,,,30.0001106,,,,
,32667248.36,29.9978685,14922.4091796875,0.0126956272074841,1.74659599167689E-6,1,0.999253354069792,40.0298881530762,1.99654535439481,34.0999998152256,0.142527761669289,0.0272217454162406,2.5,0.000145978242651506,0.0126424978622526,0.000225392993274339,29.9978008,29.9979362,14919.7890625,14925.029296875,56.7759323798906,20.669683109433,15.315984,0,0,0,40,4449,29.9566,14922.4091796875,,,,,,,,,,,,,0,,,,0.0049,,,,,,29.9978685,,,,
,32667272.075,30.0000076,13735.5712890625,0.012595502725755,1.70427372265382E-6,1,0.999253354069792,40.0298881530762,1.9964566216584,34.0900011360645,0.141405262049825,0.0268787411022731,2.5,0.000134604015626062,0.0125415558860352,0.000212582499128123,30.0000076,30.0000076,13725.572265625,13745.5703125,56.6368025034675,20.6800761747527,15.695635,0,0,0,40,4449,29.9602,13735.5712890625,,,,,,,,,,,,,0,,,,0.00245,,,,,,30.0000076,,,,
,32667294.89,29.9978199,12595.8754882812,0.0125093607249888,1.54909461717412E-6,1,0.999253354069792,40.0298881530762,1.99813301544659,34.0900011360645,0.14050513077077,0.0268912009117177,2.5,0.000150264616554237,0.0124544608979389,0.000226810737194029,29.9978199,29.9978199,12585.83984375,12605.9111328125,57.0065127930637,20.6564213570957,15.315984,0,0,0,40,4449,29.96175,12595.8754882812,,,,,,,,,,,,,0,,,,0,,,,,,29.9978199,,,,
,32667318.4,29.9964561,11421.6005859375,0.012412153687052,1.13516469274736E-6,1,0.999253354069792,40.0298881530762,2.00121144948655,34.0999998152256,0.139613794118539,0.0266659632179378,2.5,0.000145254063866166,0.0123564778621149,0.000220359029076714,29.9964561,29.9964561,11416.556640625,11426.64453125,56.8908317722176,20.6215398554781,16.075285,0,0,0,40,4449,29.9589,11421.6005859375,,,,,,,,,,,,,0,,,,0,,,,,,29.9964561,,,,
,32667340.175,29.9961987,10332.0205078125,0.0123049748769461,1.39458028534273E-6,1,0.999253354069792,40.0298881530762,2.00224308386148,34.0999998152256,0.138458050662807,0.0264790477707346,2.5,0.000147679014907724,0.0122486649827276,0.000221324521407286,29.9961987,29.9961987,10322.0859375,10341.955078125,56.9846271945253,20.607253361895,15.695635,0,0,0,40,4449,29.96365,10332.0205078125,,,,,,,,,,,,,0,,,,0.0049,,,,,,29.9961987,,,,
,32667362.875,29.9936256,9198.04052734375,0.0121682359790852,1.49407469447645E-6,1,0.999253354069792,40.0298881530762,2.00230236571292,34.0999998152256,0.136921044689026,0.0261258243766109,2.5,0.000141764979834067,0.0121114757711336,0.000213784709758383,29.9936256,29.9936256,9188.10546875,9207.9755859375,57.0541921327368,20.5970111573754,15.695635,0,0,0,40,4449,29.9646,9198.04052734375,,,,,,,,,,,,,0,,,,0,,,,,,29.9936256,,,,
,32667385.5,29.9933624,8067.833984375,0.0120591730907163,1.23683490954045E-6,1,0.999253354069792,40.0298881530762,2.00267760574298,34.0999998152256,0.135693532183026,0.0259643731944219,2.5,0.000147536315944597,0.0120018246454499,0.000218060828056191,29.9933624,29.9933624,8062.70703125,8072.9609375,57.2042648084291,20.5779577766729,15.695635,0,0,0,40,4449,29.96735,8067.833984375,,,,,,,,,,,,,0,,,,0,,,,,,29.9933624,,,,
,32667408.16,29.9935589,6935.8447265625,0.011910553399873,1.2205479993041E-6,1,0.999253354069792,40.0298881530762,2.00218438828361,34.0999998152256,0.133979888388877,0.0256268182367676,2.5,0.000145684391155187,0.0118528985702369,0.000214530588808441,29.9935589,29.9935589,6928.43212890625,6943.25732421875,56.943200883006,20.5884623930552,16.075285,0,0,0,40,4449,29.9677,6935.8447265625,,,,,,,,,,,,,0,,,,-0.0049,,,,,,29.9935589,,,,
,32667431.765,29.9940319,5756.18115234375,0.0117281782138904,1.46106440538253E-6,1,0.999253354069792,40.0298881530762,2.00249369820508,34.0999998152256,0.131937336594271,0.025231369416803,2.5,0.000143850498975457,0.0116704081433616,0.000210821083746837,29.9939384,29.9941254,5748.64306640625,5763.71923828125,57.1714364106214,20.5987797308971,15.695635,0,0,0,40,4449,29.97185,5756.18115234375,,,,,,,,,,,,,0,,,,-0.00245,,,,,,29.9940319,,,,
,32667455.135,29.9929867,4587.03686523438,0.0115005832011399,1.46928496227198E-6,1,0.999253354069792,40.0298881530762,2.0020789682647,34.0999998152256,0.129338356693591,0.0247486629747285,2.5,0.000143064777755067,0.011442990145053,0.00020793514781361,29.9929867,29.9929867,4574.607421875,4599.46630859375,57.2292769210445,20.6037673509881,15.695635,0,0,0,40,4449,29.96895,4587.03686523438,,,,,,,,,,,,,0,,,,0.00245,,,,,,29.9929867,,,,
,32667477.97,29.9955902,3444.30090332031,0.0111587766059542,1.5482485670346E-6,1,0.999253354069792,40.0298881530762,2.00114125909706,34.0999998152256,0.125469755841465,0.0237710181195768,2.5,0.000119148846538093,0.011102174836573,0.00018146503603253,29.9955902,29.9955902,3434.2001953125,3454.40161132812,57.1995750373137,20.6080157990398,15.315984,0,0,0,40,4449,29.97025,3444.30090332031,,,,,,,,,,,,,0,,,,0,,,,,,29.9955902,,,,
,32667501.46,29.996233,2269.77136230469,0.0106146747595503,1.87792511697258E-6,1,0.999253354069792,40.0298881530762,2.00078285902558,34.0999998152256,0.119322854597311,0.0226065020022464,2.5,0.000114009611075265,0.0105600724409968,0.000172608832687933,29.996233,29.996233,2259.77197265625,2279.77075195313,57.2535074051407,20.6168100228662,15.315984,0,0,0,40,4449,29.9706,2269.77136230469,,,,,,,,,,,,,0,,,,-0.00245,,,,,,29.996233,,,,
,32667523.97,29.9965076,1145.01159667969,0.00919732603373976,5.3914009921364E-6,1,0.999253354069792,40.0298881530762,2.00097616440394,34.0999998152256,0.103394246432572,0.0195822542326168,2.5,9.87389630666136E-5,0.00914945154047418,0.000148998970720448,29.9965076,29.9965076,1135.02966308594,1154.99353027344,57.0534105042176,20.6083620690472,15.315984,0,0,0,40,4449,29.9699,1145.01159667969,,,,,,,,,,,,,0,,,,0,,,,,,29.9965076,,,,
,32667549.065,29.9966125,-109.722766876221,0.000126041398639349,2.64653335170225E-5,1,0.999253354069792,40.0298881530762,2.00117075749337,34.0999998152256,0.00142713015930998,0.00021045219543151,0.25,-3.78118713645398E-6,0.000125407813937887,-3.07101580419866E-6,29.9966125,29.9966125,-119.652626037598,-99.7929077148438,57.2456911199484,20.6035121744838,15.315984,0,0,0,40,4449,29.97215,-109.722766876221,,,,,,,,,,,,,0,,,,-0.00245,,,,,,29.9966125,,,,
,32667572.095,29.9960384,-1256.712890625,-0.00894752903201965,6.15345394534973E-6,1,0.999253354069792,40.0298881530762,2.00145325387182,34.0999998152256,-0.100583649852506,-0.0191246596455159,0.25,-0.00010242276498996,-0.00890097521997343,-0.000151336307861669,29.9960384,29.9960384,-1261.66906738281,-1251.75671386719,57.3011867448138,20.6090505742066,15.695635,0,0,0,40,4449,29.9748,-1256.712890625,,,,,,,,,,,,,0,,,,0,,,,,,29.9960384,,,,
,32667598.065,29.9974556,-2553.69665527344,-0.0106163173722747,1.3881137736934E-6,1,0.999253354069792,40.0298881530762,2.0019994528334,34.0999998152256,-0.119403872432508,-0.0226723783737012,2.5,-0.000118204937249388,-0.0105618622703141,-0.000176953435385971,29.9974556,29.9974556,-2563.37939453125,-2544.01391601562,57.3363600281791,20.6035021096806,15.315984,0,0,0,40,4449,29.9726,-2553.69665527344,,,,,,,,,,,,,0,,,,0.0049,,,,,,29.9974556,,,,
,32667621.305,29.9974365,-3715.70043945313,-0.0111404151034444,1.43966072886398E-6,1,0.999253354069792,40.0298881530762,2.00221393754583,34.0999998152256,-0.125327426046446,-0.023756550929988,2.5,-0.000119855939984356,-0.0110840969214897,-0.000182236862689821,29.9974365,29.9974365,-3723.14892578125,-3708.251953125,57.0369963053137,20.5962511695686,15.315984,0,0,0,40,4449,29.97245,-3715.70043945313,,,,,,,,,,,,,0,,,,0.00245,,,,,,29.9974365,,,,
,32667643.365,29.9963341,-4816.36279296875,-0.0114387951324357,1.3532679522963E-6,1,0.999253354069792,40.0298881530762,2.00226992813119,34.0999998152256,-0.128695825914084,-0.0244023199742112,2.5,-0.000122977513300051,-0.0113818057184626,-0.000187752313718806,29.9963341,29.9963341,-4819.0068359375,-4813.71875,57.5841362687753,20.586897930653,15.695635,0,0,0,40,4449,29.9741,-4816.36279296875,,,,,,,,,,,,,0,,,,-0.0049,,,,,,29.9963341,,,,
,32667665.375,29.9967327,-5918.64306640625,-0.0116620183754123,1.1207540447818E-6,1,0.999253354069792,40.0298881530762,2.0025893646287,34.0999998152256,-0.131223317564211,-0.0249634652032132,2.5,-0.000131658316766831,-0.0116047801347179,-0.000198423258847653,29.9967327,29.9967327,-5923.390625,-5913.8955078125,57.129228470583,20.6034150783351,15.315984,0,0,0,40,4449,29.9763,-5918.64306640625,,,,,,,,,,,,,0,,,,0.0049,,,,,,29.9967327,,,,
,32667688.625,29.9968815,-7080.89501953125,-0.0118520280930992,1.1595545195905E-6,1,0.999253354069792,40.0298881530762,2.00268654226292,34.0999998152256,-0.133383070065369,-0.0253500813135842,2.5,-0.000130918998650899,-0.0117948742505186,-0.000199603599868209,29.9968815,29.9968815,-7088.3623046875,-7073.427734375,57.4262473078907,20.5940027342906,14.936333,0,0,0,40,4449,29.9741,-7080.89501953125,,,,,,,,,,,,,0,,,,0,,,,,,29.9968815,,,,
,32667711.08,29.9973736,-8205.31689453125,-0.0119966015050065,1.03197743657949E-6,1,0.999253354069792,40.0298881530762,2.00217213238154,34.0999998152256,-0.134985308198331,-0.0256738519712489,2.5,-0.000133369898402271,-0.0119397683923064,-0.000203700072147857,29.9973736,29.9973736,-8217.908203125,-8192.7255859375,57.5872627828522,20.5952302693379,15.315984,0,0,0,40,4449,29.9766,-8205.31689453125,,,,,,,,,,,,,0,,,,0,,,,,,29.9973736,,,,
,32667734.64,29.9974918,-9380.41357421875,-0.0121459443375979,5.97670844845403E-7,1,0.999253354069792,40.0298881530762,2.00296846744321,34.0999998152256,-0.136716653461076,-0.0260816133926818,2.5,-0.000140916175665224,-0.0120894822238103,-0.000212951725701137,29.9974918,29.9974918,-9382.91796875,-9377.9091796875,57.2550706621791,20.5760196888181,15.315984,0,0,0,40,4449,29.9762,-9380.41357421875,,,,,,,,,,,,,0,,,,0.0049,,,,,,29.9974918,,,,
,32667757.61,29.9976501,-10529.9047851562,-0.0122674445743373,1.00962539041331E-6,1,0.999253354069792,40.0298881530762,2.00301611541733,34.0999998152256,-0.138127016676166,-0.0261962082576288,2.5,-0.00012825518198763,-0.0122116376352635,-0.000201920639803041,29.9976501,29.9976501,-10537.4775390625,-10522.33203125,57.2878990599868,20.5797276949454,15.315984,0,0,0,40,4449,29.9778,-10529.9047851562,,,,,,,,,,,,,0,,,,-0.00245,,,,,,29.9976501,,,,
,32667780.47,29.996685,-11674.1079101562,-0.0123771548246782,6.58504851433998E-7,1,0.999253354069792,40.0298881530762,2.00342315534236,34.0999998152256,-0.13940260838303,-0.0264378549817651,2.5,-0.00012855626948405,-0.0123220182612269,-0.000203722484904989,29.996685,29.996685,-11676.3408203125,-11671.875,57.5395834431792,20.5906904482028,15.315984,0,0,0,40,4449,29.9754,-11674.1079101562,,,,,,,,,,,,,0,,,,-0.0049,,,,,,29.996685,,,,
,32667803.79,29.9981136,-12838.5375976563,-0.0124782779386395,1.42645123165847E-6,1,0.999253354069792,40.0298881530762,2.00327979114859,34.0999998152256,-0.140548304687317,-0.0266412480855006,2.5,-0.000127578184088091,-0.0124239311726155,-0.000204221942613375,29.9981136,29.9981136,-12850.9775390625,-12826.09765625,57.1245386994676,20.5839341797273,15.695635,0,0,0,40,4449,29.9771,-12838.5375976563,,,,,,,,,,,,,0,,,,-0.0049,,,,,,29.9981136,,,,
,32667826.835,29.9970627,-13990.9990234375,-0.0125918089155058,7.07456901793675E-7,1,0.999253354069792,40.0298881530762,2.00389248420028,34.0999998152256,-0.14185852054665,-0.027029118526286,2.5,-0.000139866941312017,-0.0125381519186651,-0.000218004162712359,29.9970627,29.9970627,-14001.12890625,-13980.869140625,57.8326941378907,20.5740968102246,15.315984,0,0,0,40,4449,29.9802,-13990.9990234375,,,,,,,,,,,,,0,,,,-0.00245,,,,,,29.9970627,,,,
,32667849.6,29.9984207,-15127.6147460938,-0.0126886189667294,1.19259976157637E-6,1,0.999253354069792,40.0298881530762,2.0032851610426,34.0999998152256,-0.142916996345149,-0.0272606092331214,2.5,-0.00014269546381582,-0.0126357988121505,-0.000222246208416295,29.9984207,29.9984207,-15135.15234375,-15120.0771484375,57.2284952925253,20.5717327171897,15.695635,0,0,0,40,4449,29.9779,-15127.6147460938,,,,,,,,,,,,,0,,,,0.0049,,,,,,29.9984207,,,,
,32667871.755,29.9979181,-16234.7275390625,-0.0127694219175609,7.34379894576235E-7,1,0.999253354069792,40.0298881530762,2.00326840599999,34.0999998152256,-0.143844142212336,-0.0274149579971908,2.5,-0.000140905527904973,-0.0127175401891314,-0.000221763928295372,29.9978752,29.997961,-16239.73046875,-16229.724609375,57.3621537693137,20.5768982094891,15.695635,0,0,0,40,4449,29.9769,-16234.7275390625,,,,,,,,,,,,,0,,,,0.0049,,,,,,29.9979181,,,,
,32667894.64,29.998003,-17378.9560546875,-0.0128558747301774,1.31485091819266E-6,1,0.999253354069792,40.0298881530762,2.00297753303687,34.0999998152256,-0.144798555001913,-0.0276805402076628,2.5,-0.000148242468427621,-0.0128049316011682,-0.000230430210921515,29.998003,29.998003,-17383.904296875,-17374.0078125,57.1018714724099,20.5725768546505,14.936333,0,0,0,40,4449,29.9779,-17378.9560546875,,,,,,,,,,,,,0,,,,0,,,,,,29.998003,,,,
,32667918.405,29.99803355,-18568.501953125,-0.0129351266126093,1.41628622345261E-6,1,0.999253354069792,40.0298881530762,2.00281182368103,34.0999998152256,-0.145701451223959,-0.0278197515264808,2.5,-0.000145495797898732,-0.0128853008628223,-0.000229026538842947,29.997942,29.9981251,-18573.564453125,-18563.439453125,57.2730481181214,20.5810824154376,14.936333,0,0,0,40,4449,29.97655,-18568.501953125,,,,,,,,,,,,,0,,,,0,,,,,,29.99803355,,,,
,32667941.36,30.0006599,-19712.791015625,-0.0130087458196986,1.37362290576627E-6,1,0.999253354069792,40.0298881530762,2.00247067847008,34.0999998152256,-0.146522267695168,-0.0279784267653279,2.5,-0.000145734544297974,-0.0129600257607338,-0.000230521290405479,30.0006599,30.0006599,-19717.8515625,-19707.73046875,57.004167907506,20.5813920791272,15.695635,0,0,0,40,4449,29.97995,-19712.791015625,,,,,,,,,,,,,0,,,,0,,,,,,30.0006599,,,,
,32667986.45,29.99967,-19129.2314453125,-0.0129718816846694,1.34662848196247E-6,1,0.999253354069792,40.0298881530762,2.0031892111818,34.0999998152256,-0.146163421238107,-0.0278272489869384,2.5,-0.00013862255176275,-0.0129226402719667,-0.000222802687612378,29.99967,29.99967,-19136.919921875,-19121.54296875,57.5364569291022,20.571067420363,15.695635,0,0,0,40,4449,29.9806,-19129.2314453125,,,,,,,,,,,,,0,,,,0,,,,,,29.99967,,,,
,32668009.41,29.99881265,-17989.130859375,-0.0129082423982776,1.23383839744236E-6,1,0.999253354069792,40.0298881530762,2.00431856475394,34.0999998152256,-0.14548699782936,-0.0278261961090538,2.5,-0.000149635039988803,-0.0128578078250902,-0.000232579965358648,29.9986286,29.9989967,-17996.490234375,-17981.771484375,57.2464727484676,20.5597524872838,15.315984,0,0,0,40,4449,29.97935,-17989.130859375,,,,,,,,,,,,,0,,,,-0.0049,,,,,,29.99881265,,,,
,32668031.555,29.9973946,-16880.919921875,-0.0128286787607625,1.30301230430926E-6,1,0.999253354069792,40.0298881530762,2.00483184524761,34.0999998152256,-0.144632201031351,-0.0275396857173449,2.5,-0.000138931325011575,-0.0127773252059398,-0.000220634745281591,29.9973946,29.9973946,-16883.3828125,-16878.45703125,56.9932251082368,20.5500245951627,15.695635,0,0,0,40,4449,29.9805,-16880.919921875,,,,,,,,,,,,,0,,,,0,,,,,,29.9973946,,,,
,32668055.08,29.9965096,-15706.59765625,-0.0127524068801536,8.30119166786739E-7,1,0.999253354069792,40.0298881530762,2.00571574881793,34.0999998152256,-0.143814393377352,-0.0274015598712849,2.5,-0.00014042104981932,-0.012699995963802,-0.000220799235839809,29.9965096,29.9965096,-15714.052734375,-15699.142578125,56.7454488676406,20.5460359930999,15.695635,0,0,0,40,4449,29.97825,-15706.59765625,,,,,,,,,,,,,0,,,,-0.00735,,,,,,29.9965096,,,,
,32668077.94,29.9969711,-14562.34765625,-0.0126718304956469,9.92187740808821E-7,1,0.999253354069792,40.0298881530762,2.00580925550072,34.0999998152256,-0.142872972056123,-0.0273639606455188,2.5,-0.000152464513414433,-0.0126183914310936,-0.00023146479365455,29.9969711,29.9969711,-14574.7744140625,-14549.9208984375,57.3551191126407,20.5335985435024,15.315984,0,0,0,40,4449,29.98075,-14562.34765625,,,,,,,,,,,,,0,,,,-0.00245,,,,,,29.9969711,,,,
,32668102.675,29.9971848,-13327.9897460938,-0.0125714708734088,1.33270419138389E-6,1,0.999253354069792,40.0298881530762,2.00578396002752,34.0999998152256,-0.141738981838143,-0.0270627556259253,2.5,-0.000144939046794389,-0.0125171495884543,-0.000222447542837285,29.9971848,29.9971848,-13335.4404296875,-13320.5390625,56.7978179784291,20.5408619070647,14.936333,0,0,0,40,4449,29.9817,-13327.9897460938,,,,,,,,,,,,,0,,,,-0.00245,,,,,,29.9971848,,,,
,32668126,29.9960709,-12161.2158203125,-0.0124758982908288,4.64786692602268E-7,1,0.999253354069792,40.0298881530762,2.00601602104392,34.0999998152256,-0.140651630435145,-0.0269203542613587,2.5,-0.000150249060127433,-0.0124207156715796,-0.000226291199810357,29.9960709,29.9960709,-12171.2236328125,-12151.2080078125,56.6274229612368,20.5418798586161,15.315984,0,0,0,40,4449,29.98365,-12161.2158203125,,,,,,,,,,,,,0,,,,0.00245,,,,,,29.9960709,,,,
,32668148.535,29.9961681,-11034.3061523438,-0.0123663262905043,5.30125255441364E-7,1,0.999253354069792,40.0298881530762,1.99528808800914,34.0900011360645,-0.138700989537716,-0.0264935433888955,2.5,-0.000145136149501874,-0.0123104946780443,-0.000219703802404183,29.9961681,29.9961681,-11041.7666015625,-11026.845703125,56.7462304961599,20.5650822923659,14.936333,0,0,0,40,4449,29.98545,-11034.3061523438,,,,,,,,,,,,,0,,,,0,,,,,,29.9961681,,,,
,32668170.82,29.9966488,-9922.63525390625,-0.0122587205470846,1.18956133773172E-6,1,0.999253354069792,40.0298881530762,1.99461015258994,34.0999998152256,-0.137435490291927,-0.0262602544231113,2.5,-0.000145397463792056,-0.0122022570936873,-0.000218494992229679,29.9966488,29.9966488,-9927.7939453125,-9917.4765625,56.6633778731214,20.5540196437148,15.695635,0,0,0,40,4449,29.9848,-9922.63525390625,,,,,,,,,,,,,0,,,,0,,,,,,29.9966488,,,,
,32668193.685,29.9960823,-8779.6630859375,-0.0121356547592435,6.02999825605875E-7,1,0.999253354069792,40.0298881530762,1.99448959642529,34.0999998152256,-0.136033093503692,-0.0260063282208668,2.5,-0.000145961444237551,-0.0120786498685167,-0.000217484281326058,29.9960823,29.9960823,-8787.087890625,-8772.23828125,56.9830639374868,20.5442056662376,15.315984,0,0,0,40,4449,29.98595,-8779.6630859375,,,,,,,,,,,,,0,,,,-0.00245,,,,,,29.9960823,,,,
,32668216.79,29.99615005,-7623.15014648438,-0.0120006377641024,9.21742595183985E-7,1,0.999253354069792,40.0298881530762,1.99464046283731,34.0999998152256,-0.134520967528278,-0.0256959700658201,2.5,-0.000143325234128432,-0.0119432072293409,-0.000213222623469509,29.9960957,29.9962044,-7633.2490234375,-7613.05126953125,57.4082698519484,20.5433769458982,15.315984,0,0,0,40,4449,29.9857,-7623.15014648438,,,,,,,,,,,,,0,,,,-0.00245,,,,,,29.99615005,,,,
,32668239.985,29.9972057,-6463.19677734375,-0.011846256606847,8.14441124438492E-7,1,0.999253354069792,40.0298881530762,1.99487181671753,34.0999998152256,-0.132789649921198,-0.0253883598474958,2.5,-0.000144275844137523,-0.0117885327474731,-0.00021244059053631,29.9972057,29.9972057,-6468.33154296875,-6458.06201171875,56.8681645451599,20.5414188252537,14.936333,0,0,0,40,4449,29.9878,-6463.19677734375,,,,,,,,,,,,,0,,,,0,,,,,,29.9972057,,,,
,32668262.955,29.9960194,-5316.17407226562,-0.0116476979821112,1.04067143409945E-6,1,0.999253354069792,40.0298881530762,1.9949940563624,34.0999998152256,-0.130574421880066,-0.0248856408059013,2.5,-0.000135822569934797,-0.0115900213564219,-0.000202079644601026,29.9960194,29.9960194,-5323.41796875,-5308.93017578125,56.9541436822753,20.5468160771251,15.315984,0,0,0,40,4449,29.9844,-5316.17407226562,,,,,,,,,,,,,0,,,,0,,,,,,29.9960194,,,,
,32668285.965,29.9970398,-4165.71630859375,-0.0114000141241539,9.74395569406177E-7,1,0.999253354069792,40.0298881530762,1.99521834066387,34.0999998152256,-0.127805371965059,-0.0243352283501299,2.5,-0.000131730839076923,-0.0113426820699572,-0.000195824982431893,29.9970398,29.9970398,-4178.19580078125,-4153.23681640625,56.6962062709291,20.5498858040808,15.695635,0,0,0,40,4449,29.9848,-4165.71630859375,,,,,,,,,,,,,0,,,,0,,,,,,29.9970398,,,,
,32668309.43,29.9961262,-2991.45544433594,-0.0109984172439004,1.46559055982897E-6,1,0.999253354069792,40.0298881530762,1.9954058657352,34.0999998152256,-0.123319156648855,-0.0233983929418669,2.5,-0.000120683696986802,-0.0109423251785779,-0.000181835455277101,29.9961262,29.9961262,-2998.52587890625,-2984.38500976562,56.7876568076791,20.5460431694759,15.315984,0,0,0,40,4449,29.9907,-2991.45544433594,,,,,,,,,,,,,0,,,,0.0049,,,,,,29.9961262,,,,
,32668332.04,29.9968109,-1862.0068359375,-0.0102961103428274,2.00378968816825E-6,1,0.999253354069792,40.0298881530762,1.99507103292617,34.0900011360645,-0.115417651146558,-0.0219030685646839,2.5,-0.000113921827245115,-0.0102429091126621,-0.000170546609994367,29.996788,29.9968338,-1874.33557128906,-1849.67810058594,57.7983024830446,20.5336303915049,15.315984,0,0,0,40,4449,29.9873,-1862.0068359375,,,,,,,,,,,,,0,,,,-0.00245,,,,,,29.9968109,,,,
,32668354.815,29.9970741,-721.779113769531,-0.00804747353763142,9.27429738164174E-6,1,0.999253354069792,40.0298881530762,1.99517141434112,34.0999998152256,-0.0902047853382977,-0.0171476042054207,2.5,-9.19866248317066E-5,-0.0080054053980619,-0.000135796858751087,29.9970741,29.9970741,-729.481811523437,-714.076416015625,57.6021137247176,20.531605711673,15.315984,0,0,0,40,4449,29.98745,-721.779113769531,,,,,,,,,,,,,0,,,,0,,,,,,29.9970741,,,,
,32668380.065,29.997715,539.709655761719,0.0045086197830079,2.59400042988997E-5,1,0.999253354069792,40.0298881530762,1.99512843679161,34.0999998152256,0.0505239595289037,0.00963638879179224,0.25,5.43225680954291E-5,0.00448499913081232,7.88188742917579E-5,29.997715,29.997715,529.664916992188,549.75439453125,57.5012836457369,20.5300573483239,15.695635,0,0,0,40,4449,29.98735,539.709655761719,,,,,,,,,,,,,0,,,,-0.00245,,,,,,29.997715,,,,
,32668401.75,29.9976311,1618.99853515625,0.00972454004436504,3.60026474107409E-6,1,0.999253354069792,40.0298881530762,1.99512943768577,34.0999998152256,0.108971077114865,0.0208351793446249,0.25,0.000121104293857559,0.00967409010904056,0.000174400355868986,29.9976311,29.9976311,1611.66857910156,1626.32849121094,57.8827183631215,20.5331209789822,15.695635,0,0,0,40,4449,29.98935,1618.99853515625,,,,,,,,,,,,,0,,,,0,,,,,,29.9976311,,,,
,32668426.245,29.9977646,2843.22351074219,0.010828960921572,1.89032901815094E-6,1,0.999253354069792,40.0298881530762,1.99526057219631,34.0900011360645,0.121408963715291,0.023039257005365,2.5,0.000119198798072892,0.0107736281497328,0.000179314953388494,29.9977646,29.9977646,2838.19140625,2848.25561523438,57.5184794731599,20.5324197349007,14.936333,0,0,0,40,4449,29.9868,2843.22351074219,,,,,,,,,,,,,0,,,,-0.0049,,,,,,29.9977646,,,,
,32668448.825,29.9977989,3971.55249023438,0.0112486703010613,1.15709411767205E-6,1,0.999253354069792,40.0298881530762,1.99525327840236,34.0999998152256,0.126131632537533,0.0238865753744805,2.5,0.000118912147479031,0.0111920240738545,0.000182090562516708,29.9977989,29.9977989,3964.0830078125,3979.02197265625,56.9596150819099,20.5317140906294,14.936333,0,0,0,40,4449,29.98895,3971.55249023438,,,,,,,,,,,,,0,,,,-0.00245,,,,,,29.9977989,,,,
,32668471.035,29.9981365,5084.52001953125,0.011512979365479,1.12192831372644E-6,1,0.999253354069792,40.0298881530762,1.99518424639692,34.0999998152256,0.129132566415409,0.0242711107508098,2.5,0.00010515455955875,0.0114559587956517,0.000170637623604367,29.9981365,29.9981365,5074.716796875,5094.3232421875,57.2707032325638,20.5305008171531,14.936333,0,0,0,40,4449,29.9898,5084.52001953125,,,,,,,,,,,,,0,,,,-0.00245,,,,,,29.9981365,,,,
,32668493.375,29.99827095,6198.80078125,0.0117420220736545,1.51082102475799E-6,1,0.999253354069792,40.0298881530762,1.99516516737063,34.0999998152256,0.131648084730586,0.0251071795710779,2.5,0.000137769218655711,0.0116846158229513,0.000205177961191859,29.997961,29.9985809,6188.6484375,6208.953125,56.7884384361983,20.5259136428009,14.936333,0,0,0,40,4449,29.99085,6198.80078125,,,,,,,,,,,,,0,,,,0,,,,,,29.99827095,,,,
,32668516.43,29.9982281,7350.94897460937,0.0119139375251587,1.45893373280498E-6,1,0.999253354069792,40.0298881530762,1.9950800604016,34.0999998152256,0.133577540542689,0.025497989153825,2.5,0.000140949145494412,0.0118566888498298,0.000210155783436868,29.9982281,29.9982281,7343.56640625,7358.33154296875,57.75218640041,20.5336100576213,14.936333,0,0,0,40,4449,29.988,7350.94897460937,,,,,,,,,,,,,0,,,,0,,,,,,29.9982281,,,,
,32668538.685,29.9987926,8462.8193359375,0.0120359056281473,1.35206150381897E-6,1,0.999253354069792,40.0298881530762,1.99532715652118,34.0900011360645,0.135018244678814,0.0255084846250393,2.5,0.000118840567583222,0.0119792306007995,0.000189669857774778,29.9987926,29.9987926,8457.736328125,8467.90234375,57.688092861833,20.527774269901,15.315984,0,0,0,40,4449,29.9889,8462.8193359375,,,,,,,,,,,,,0,,,,0,,,,,,29.9987926,,,,
,32668561.835,29.9991436,9620.40478515625,0.0121841619063638,1.38189369214807E-6,1,0.999253354069792,40.0298881530762,1.99518804117357,34.0999998152256,0.136655324433705,0.02598831016743,2.5,0.000134153987056184,0.0121278131719904,0.00020663626147089,29.9991436,29.9991436,9612.9658203125,9627.84375,57.4278105649292,20.5305184952455,15.315984,0,0,0,40,4449,29.9876,9620.40478515625,,,,,,,,,,,,,0,,,,0,,,,,,29.9991436,,,,
,32668584.095,29.9995499,10734.669921875,0.0122986712222105,1.15245041057389E-6,1,0.999253354069792,40.0298881530762,1.99526546641074,34.0999998152256,0.137951960607652,0.0262659711033822,2.5,0.00013728143361077,0.0122428936511318,0.000211259205801875,29.9995499,29.9995499,10727.5830078125,10741.7568359375,57.4199942797368,20.5273483007571,14.936333,0,0,0,40,4449,29.9914,10734.669921875,,,,,,,,,,,,,0,,,,-0.00245,,,,,,29.9995499,,,,
,32668607.145,30.0006218,11886.7827148438,0.0124073855491762,1.23208247703103E-6,1,0.999253354069792,40.0298881530762,1.99527468909154,34.0999998152256,0.139205365295247,0.0263888157339257,2.5,0.000127705075695663,0.0123523585179391,0.0002032275027765,30.0006218,30.0006218,11881.6630859375,11891.90234375,57.83347576641,20.5307399630615,14.936333,0,0,0,40,4449,29.9875,11886.7827148438,,,,,,,,,,,,,0,,,,0,,,,,,30.0006218,,,,
,32668629.455,30,13000.9638671875,0.012510004792832,1.07962322737295E-6,1,0.999253354069792,40.0298881530762,1.99515316066969,34.0999998152256,0.140348148170323,0.0266851483271882,2.5,0.000134815958094491,0.0124556690659129,0.000211756137131333,30,30,12990.7119140625,13011.2158203125,57.8178431960254,20.5279216578517,15.315984,0,0,0,40,4449,29.9905,13000.9638671875,,,,,,,,,,,,,0,,,,0.00245,,,,,,30,,,,
,32668652.36,29.999403,14145.7373046875,0.012603089635926,1.87603614379358E-6,1,0.999253354069792,40.0298881530762,1.99530029317387,34.0999998152256,0.141417087969074,0.0268847263232136,2.5,0.000134690516889672,0.0125495979921287,0.000213038995783087,29.999403,29.999403,14135.6767578125,14155.7978515625,57.7467150007753,20.5311024736575,15.315984,0,0,0,40,4449,29.9879,14145.7373046875,,,,,,,,,,,,,0,,,,0,,,,,,29.999403,,,,
,32668674.525,29.9999218,15252.6040039062,0.0126868844775895,1.59598943891132E-6,1,0.999253354069792,40.0298881530762,1.9955601233704,34.0999998152256,0.142367033407245,0.0271918757676602,2.5,0.000145691738796876,0.0126342040073974,0.000225316067135551,29.9999218,29.9999218,15245.119140625,15260.0888671875,57.3387049137368,20.5259897106535,15.695635,0,0,0,40,4449,29.986,15252.6040039062,,,,,,,,,,,,,0,,,,-0.0049,,,,,,29.9999218,,,,
,32668697.305,30.0011387,16391.9775390625,0.012780951355072,1.38837445707155E-6,1,0.999253354069792,40.0298881530762,1.99530436503512,34.0999998152256,0.143437148746358,0.0272959785947816,2.5,0.000137354708980995,0.0127292405179851,0.000218420491618655,30.0011387,30.0011387,16384.369140625,16399.5859375,57.8319125093715,20.52861330303,14.936333,0,0,0,40,4449,29.9868,16391.9775390625,,,,,,,,,,,,,0,,,,0,,,,,,30.0011387,,,,
,32668719.3,30.0003338,17491.427734375,0.0128558983236797,1.51004010823895E-6,1,0.999253354069792,40.0298881530762,1.99521789236467,34.0999998152256,0.144295679192262,0.0274080392897246,2.5,0.000132993717493951,0.012805199043389,0.00021532744820325,30.0003338,30.0003338,17484,17498.85546875,57.616964666583,20.5314311905387,15.315984,0,0,0,40,4449,29.98795,17491.427734375,,,,,,,,,,,,,0,,,,-0.0049,,,,,,30.0003338,,,,
,32668742.11,30.0002995,18630.9912109375,0.0129357937777317,1.48885953189111E-6,1,0.999253354069792,40.0298881530762,1.99524561810759,34.0999998152256,0.145189311564043,0.0276951777085153,2.5,0.000143149139575468,0.0128860724248527,0.000226745591350042,30.0002995,30.0002995,18623.494140625,18638.48828125,57.3301070000253,20.5303653787886,14.936333,0,0,0,40,4449,29.98875,18630.9912109375,,,,,,,,,,,,,0,,,,0,,,,,,30.0002995,,,,
,32668765.095,30.0005836,19780.306640625,0.0129962449118247,1.54552844321745E-6,1,0.999253354069792,40.0298881530762,1.99526870295115,34.0999998152256,0.145923845809751,0.0276117182193597,2.5,0.000123844125913627,0.0129478066882601,0.000208679875673735,30.0005836,30.0005836,19767.826171875,19792.787109375,57.5286406439099,20.5331602405589,14.936333,0,0,0,40,4449,29.9873,19780.306640625,,,,,,,,,,,,,0,,,,0.00245,,,,,,30.0005836,,,,
,32668806.25,30.0004711,19186.662109375,0.0129933796662796,1.68449078096445E-6,1,0.999253354069792,40.0298881530762,1.9953710854635,34.0999998152256,0.145815723508017,0.0280237220199706,2.5,0.000161390138242254,0.0129439917963863,0.000245672165169709,30.0004711,30.0004711,19186.662109375,19186.662109375,57.7076335748138,20.5341974539712,15.315984,0,0,0,40,4449,29.9899,19186.662109375,,,,,,,,,,,,,0,,,,0,,,,,,30.0004711,,,,
,32668829.175,29.9989357,18044.5615234375,0.0129192912891895,1.68655079695771E-6,1,0.999253354069792,40.0298881530762,1.99522705177891,34.0999998152256,0.144974772441502,0.0277705983210747,2.5,0.000153360353782049,0.0128688708420372,0.000236409533303002,29.9989357,29.9989357,18027.23828125,18061.884765625,57.5161345876022,20.533909803569,14.936333,0,0,0,40,4449,29.9899,18044.5615234375,,,,,,,,,,,,,0,,,,-0.00245,,,,,,29.9989357,,,,
,32668849.43,29.9986763,17033.6181640625,0.0128547319863085,1.67530967333445E-6,1,0.999253354069792,40.0298881530762,1.99511463610704,34.0999998152256,0.144239126720899,0.0275721680469742,2.5,0.000148331922678745,0.0128034060213645,0.000230280380920646,29.9985085,29.9988441,17028.76953125,17038.466796875,57.6591726066215,20.5276322206397,15.315984,0,0,0,40,4449,29.9895,17033.6181640625,,,,,,,,,,,,,0,,,,0,,,,,,29.9986763,,,,
,32668871.87,29.9993668,15911.8715820313,0.0127787142477242,1.32907228279441E-6,1,0.999253354069792,40.0298881530762,1.99591438642892,34.0999998152256,0.143417043054695,0.0274691279851096,2.5,0.000152877018533422,0.0127263667296086,0.000233527918005475,29.9993668,29.9993668,15904.38671875,15919.3564453125,57.5692853269099,20.5228381085108,14.556682,0,0,0,40,4449,29.9889,15911.8715820313,,,,,,,,,,,,,0,,,,0.0049,,,,,,29.9993668,,,,
,32668894.89,29.9999886,14762.90625,0.0126872381984692,2.00224431476054E-6,1,0.999253354069792,40.0298881530762,1.99600757254361,34.0999998152256,0.142391510667321,0.0272188114747081,2.5,0.000147947763137355,0.0126340023727055,0.000227218630502654,29.9999886,29.9999886,14755.375,14770.4375,57.5184794731599,20.5163178164343,15.315984,0,0,0,40,4449,29.99185,14762.90625,,,,,,,,,,,,,0,,,,0.0049,,,,,,29.9999886,,,,
,32668918.115,29.9994564,13600.9809570312,0.0125751938608158,1.27760150453938E-6,1,0.999253354069792,40.0298881530762,1.99588427123769,34.0999998152256,0.141169942777901,0.0266463350214936,2.5,0.000118314809059931,0.0125213297292074,0.000196165695763987,29.9994564,29.9994564,13595.962890625,13605.9990234375,57.3902923960061,20.5182635445471,14.936333,0,0,0,40,4449,29.99005,13600.9809570312,,,,,,,,,,,,,0,,,,-0.0049,,,,,,29.9994564,,,,
,32668941.335,29.9981785,12441.4760742187,0.0124991725768892,1.35631298211984E-6,1,0.999253354069792,40.0298881530762,1.99617497417441,34.0999998152256,0.140284419615188,0.0266961699881877,2.5,0.000137090115219391,0.01244427316094,0.000213543877410249,29.9981785,29.9981785,12431.365234375,12451.5869140625,57.2660134614484,20.5159975661667,14.556682,0,0,0,40,4449,29.98945,12441.4760742187,,,,,,,,,,,,,0,,,,0.00245,,,,,,29.9981785,,,,
,32668963.625,29.9991856,11326.9624023438,0.0124038597262363,1.31134810426042E-6,1,0.999253354069792,40.0298881530762,1.99605676363908,34.0999998152256,0.139172607235149,0.0266065429001428,2.5,0.000147332242475583,0.0123481526328487,0.000222338016390804,29.9991856,29.9991856,11322.0634765625,11331.861328125,57.3254172289099,20.5165274540592,15.315984,0,0,0,40,4449,29.98935,11326.9624023438,,,,,,,,,,,,,0,,,,0.00245,,,,,,29.9991856,,,,
,32668987.375,29.9982777,10140.2866210938,0.0122754334677007,1.36635095749986E-6,1,0.999253354069792,40.0298881530762,1.99613874468071,34.0999998152256,0.137774585810334,0.0260443595664583,2.5,0.000121293660910505,0.0122192620487181,0.00019476625781157,29.9982777,29.9982777,10132.958984375,10147.6142578125,57.5145713305638,20.5146732533517,14.556682,0,0,0,40,4449,29.99035,10140.2866210938,,,,,,,,,,,,,0,,,,0,,,,,,29.9982777,,,,
,32669010.03,29.9976101,9007.8916015625,0.0121647176042685,1.16394843201222E-6,1,0.999253354069792,40.0298881530762,1.99614581650716,34.0999998152256,0.13648521766614,0.0260014428282548,2.5,0.00013829123853248,0.0121078433506815,0.000210190932214277,29.9976101,29.9976101,8997.828125,9017.955078125,56.9908802226791,20.5155965027459,14.936333,0,0,0,40,4449,29.9876,9007.8916015625,,,,,,,,,,,,,0,,,,0,,,,,,29.9976101,,,,
,32669032.85,29.9981537,7865.5556640625,0.0120316216917311,1.59280025406622E-6,1,0.999253354069792,40.0298881530762,1.99597042640121,34.0900011360645,0.134985839983812,0.0256163382121543,2.5,0.000129025643958571,0.0119743608890576,0.000199355968901407,29.9981537,29.9981537,7858.3359375,7872.775390625,58.2516470241985,20.5095812385033,14.936333,0,0,0,40,4449,29.9936,7865.5556640625,,,,,,,,,,,,,0,,,,-0.00245,,,,,,29.9981537,,,,
,32669055.97,29.9982357,6711.6767578125,0.0118843594617024,1.46026119741216E-6,1,0.999253354069792,40.0298881530762,1.99589619656394,34.0999998152256,0.13329758781408,0.0254101817506137,2.5,0.000138082949879758,0.0118267119679382,0.000206681285918338,29.9982357,29.9982357,6703.81494140625,6719.53857421875,57.5552160135638,20.5091982072557,14.936333,0,0,0,40,4449,29.9936,6711.6767578125,,,,,,,,,,,,,0,,,,0.00245,,,,,,29.9982357,,,,
,32669078.545,29.9978943,5581.87524414063,0.011701391979954,1.31178016769224E-6,1,0.999253354069792,40.0298881530762,1.99576117243708,34.0999998152256,0.131236703612379,0.0249559071905786,2.5,0.000131447275937172,0.0116437032795581,0.000198223326615877,29.9978943,29.9978943,5574.5888671875,5589.16162109375,57.5935158110061,20.5099320602185,14.936333,0,0,0,40,4449,29.9902,5581.87524414063,,,,,,,,,,,,,0,,,,0.00245,,,,,,29.9978943,,,,
,32669101.065,29.9981289,4457.15087890625,0.0114818378452715,1.30904430131121E-6,1,0.999253354069792,40.0298881530762,1.99600923964715,34.0999998152256,0.128783481884414,0.0244667845436478,2.5,0.000127771922791764,0.0114243555858567,0.000192551996752424,29.9981289,29.9981289,4444.47802734375,4469.82373046875,57.6787133196022,20.5077249962207,15.315984,0,0,0,40,4449,29.9935,4457.15087890625,,,,,,,,,,,,,0,,,,0.00245,,,,,,29.9981289,,,,
,32669123.605,29.9978733,3329.71179199219,0.0111573017323068,1.38136304097112E-6,1,0.999253354069792,40.0298881530762,1.9960684480077,34.0999998152256,0.125104395918237,0.0239607489255144,2.5,0.000141466224871682,0.0111005302243954,0.000203616980376323,29.9978733,29.9978733,3324.80249023438,3334.62109375,58.0304461532561,20.5142993369351,14.556682,0,0,0,40,4449,29.9938,3329.71179199219,,,,,,,,,,,,,0,,,,-0.0049,,,,,,29.9978733,,,,
,32669145.94,29.9982586,2215.36804199219,0.0106064570379666,2.00618056666392E-6,1,0.999253354069792,40.0298881530762,1.99592379238038,34.0999998152256,0.118911516356567,0.0227751356045165,2.5,0.000135152355713623,0.0105517722287115,0.000193592587058387,29.9982586,29.9982586,2205.16186523438,2225.57421875,57.6724602914484,20.5102610420319,14.936333,0,0,0,40,4449,29.99345,2215.36804199219,,,,,,,,,,,,,0,,,,-0.0049,,,,,,29.9982586,,,,
,32669168.615,29.9984474,1080.27404785156,0.00907572006883777,5.70196610261788E-6,1,0.999253354069792,40.0298881530762,1.996121299533,34.0999998152256,0.101753384314328,0.0194888726528164,2.5,0.000116151284248128,0.00902837026822142,0.000165645920382547,29.9984474,29.9984474,1075.41833496094,1085.12976074219,57.6013320961984,20.5098682926426,14.936333,0,0,0,40,4449,29.9941,1080.27404785156,,,,,,,,,,,,,0,,,,-0.00245,,,,,,29.9984474,,,,
,32669193.655,29.9985371,-0.144625850021839,0.00103726053332269,2.51930154457993E-6,1,0.999253354069792,40.0298881530762,1.99524438517333,34.0999998152256,0.0116287275167822,0.00219081483850331,0.25,1.01798455286429E-5,0.00103181971324676,1.58094113745339E-5,29.9985371,29.9985371,-0.152237743139267,-0.137013956904411,57.8545797364292,20.5111012603957,15.315984,0,0,0,40,4417,29.99395,-0.144625850021839,,,,,,,,,,,,,0,,,,-0.00245,,,,,,29.9985371,,,,