File: data/looselyPackedNP/ios-11/ppms/rawdata/PMK18_HYST_10K.DAT
[Header]
; VSM Data File (default extension .dat)
; Copyright (c) 2003-2013, Quantum Design, Inc. All rights reserved.
TITLE,
FILEOPENTIME,28645341.55,11/28/2018,9:03 pm
BYAPP,VSM,2.0,2.0
INFO,PPMS VSM Option Release 1.4.10 Build 1,APPNAME
INFO,Quantum Design Linear Motor Servo Controller,MOTOR_MODULE_NAME
INFO,3101-100 M1,MOTOR_HW_VERSION
INFO,MMC1014,MOTOR_SERIAL_NUMBER
INFO,SRV No X-over 01.03.11,MOTOR_SOFTWARE_VERSION
INFO,Quantum Design VSM Detection Module,VSM_MODULE_NAME
INFO,3101-150 F0,VSM_HW_VERSION
INFO,VSM707,VSM_SERIAL_NUMBER
INFO,VSM No X-over 01.02.05 May 20 2008 13:51:47,VSM_SOFTWARE_VERSION
INFO,704,PREAMP_SERIAL_NUMBER
INFO,822,COIL_SERIAL_NUMBER
INFO,0,MOMENT_UNITS
INFO,Maghemite,SAMPLE_MATERIAL
INFO,Oleate Iron Spheres,SAMPLE_COMMENT
INFO,,SAMPLE_MASS
INFO,,SAMPLE_VOLUME
INFO,,SAMPLE_MOLECULAR_WEIGHT
INFO,,SAMPLE_SIZE
INFO,,SAMPLE_SHAPE
DATATYPE,COMMENT,1
DATATYPE,TIME,2
STARTUPAXIS,X,2
STARTUPAXIS,Y1,5
[Data]
Comment,Time Stamp (sec),Temperature (K),Magnetic Field (Oe),Moment (emu),M. Std. Err. (emu),Transport Action,Averaging Time (sec),Frequency (Hz),Peak Amplitude (mm),Center Position (mm),Coil Signal' (mV),Coil Signal" (mV),Range (mV),M. Quad. Signal (emu),M. Raw' (emu),M. Raw" (emu),Min. Temperature (K),Max. Temperature (K),Min. Field (Oe),Max. Field (Oe),Mass (grams),Motor Lag (deg),Pressure (Torr),VSM Status (code),Motor Status (code),Measure Status (code),Measure Count,PPMS Status (code),System Temp. (K),System Field (Oe),Sample Position (deg),Bridge 1 Resistance (ohms),Bridge 1 Excitation (에),Bridge 2 Resistance (ohms),Bridge 2 Excitation (에),Bridge 3 Resistance (ohms),Bridge 3 Excitation (에),Bridge 4 Resistance (ohms),Bridge 4 Excitation (에),Signal 1 Vin (V),Signal 2 Vin (V),Digital Inputs (code),Drive 1 Iout (mA),Drive 1 Ipower (W),Drive 2 Iout (mA),Drive 2 Ipower (W),Pressure (),Map 20 (),Map 21 (),Map 22 (),Map 23 (),Map 24 (),Map 25 (),Map 26 (),Map 27 (),Map 28 (),Map 29 ()
,28645358.98,9.9948111,-0.182685270905495,,,2,,,,28.4299997961521,,,,,,,9.9948111,9.9948111,-0.182685270905495,-0.182685270905495,,,12.278775,,,,-99999999,4369,9.9933,-0.182685270905495,,,,,,,,,,,,,,,,,,,,,,,9.9948111,,,,
,28645639.64,10.0076046,4446.02783203125,0.0122553647998844,9.48864871404088E-6,1,0.999253354069792,40.0298881530762,1.99775504922116,28.4299999475479,0.136367276203114,0.0324749798140107,2.5,0.000708889795335341,0.0121842914693001,0.000767347860104429,10.0076046,10.0076046,4435.9677734375,4456.087890625,57.5333304150253,20.8993032787981,12.278775,0,0,0,40,4449,9.9058,4446.02783203125,,,,,,,,,,,,,0,,,,0,,,,,,10.0076046,,,,
,28645736.25,10.0108733,9274.7939453125,0.0132937581860694,1.27968607444263E-5,1,0.999253354069792,40.0298881530762,1.99221784778313,28.4299999475479,0.147624653207669,0.034893590309835,2.5,0.00074182959997777,0.0132212252638047,0.000810330192250837,10.0094919,10.0122547,9267.333984375,9282.25390625,57.8889713912754,20.9552968211751,11.899124,0,0,0,40,4449,9.9006,9274.7939453125,,,,,,,,,,,,,0,,,,0,,,,,,10.0108733,,,,
,28645831.655,10.0056639,14042.5581054687,0.0139496793148569,9.57425974502385E-6,1,0.999253354069792,40.0298881530762,1.99265708432889,28.4299999475479,0.155001267399555,0.0366353576066308,2.5,0.000773402715001319,0.0138789245027638,0.000850485673700521,10.0056639,10.0056639,14035.056640625,14050.0595703125,57.6443216647561,20.9548260791698,11.519473,0,0,0,40,4449,9.8996,14042.5581054687,,,,,,,,,,,,,0,,,,0,,,,,,10.0056639,,,,
,28645930.615,10.0042486,18987.0419921875,0.0145039490450746,8.96923705440122E-6,1,0.999253354069792,40.0298881530762,1.99466666164718,28.4299999475479,0.161394220074035,0.0381020127468851,2.5,0.000795394189395015,0.0144367970997735,0.000880899775901197,10.0042486,10.0042486,18981.8359375,18992.248046875,57.505191788333,20.9251017279677,11.899124,0,0,0,40,4449,9.8952,18987.0419921875,,,,,,,,,,,,,0,,,,0,,,,,,10.0042486,,,,
,28646027.97,10.0000515,23854.5751953125,0.0149945139103065,1.11672529887066E-5,1,0.999253354069792,40.0298881530762,1.99634752339339,28.4299999475479,0.16709575537601,0.039271366447888,2.5,0.000802681069139482,0.0149321716008694,0.000896114023805794,10.0000515,10.0000515,23844.765625,23864.384765625,57.86395927866,20.9071149123218,12.278775,0,0,0,40,4449,9.8962,23854.5751953125,,,,,,,,,,,,,0,,,,-0.00245,,,,,,10.0000515,,,,
,28646122.55,9.9996243,28582.3291015625,0.0153741645480096,1.04640092827961E-5,1,0.999253354069792,40.0298881530762,1.99725441540489,28.4299999475479,0.171482797361577,0.0403000806101646,2.5,0.000818845369329412,0.0153175347837555,0.000919041582560527,9.9996243,9.9996243,28577.607421875,28587.05078125,57.8928795338715,20.8987729158664,11.519473,0,0,0,40,4449,9.89505,28582.3291015625,,,,,,,,,,,,,0,,,,0,,,,,,9.9996243,,,,
,28646221.165,9.99675225,33512.17578125,0.0157224755391642,1.05718546081594E-5,1,0.999253354069792,40.0298881530762,1.99763945813461,28.4299999475479,0.175512145867522,0.0411163776647734,2.5,0.000822719265018358,0.0156726334956974,0.000929251129974662,9.9960909,9.9974136,33504.84765625,33519.50390625,57.6154014095446,20.8941187225723,11.139823,0,0,0,40,4449,9.89305,33512.17578125,,,,,,,,,,,,,0,,,,0,,,,,,9.99675225,,,,
,28646318.765,9.9990864,38387.220703125,0.0160003630896815,1.04740543651253E-5,1,0.999253354069792,40.0298881530762,1.99827040227405,28.4299999475479,0.178780005058421,0.0417622115978337,2.5,0.000824194688707795,0.0159578589227586,0.000935996268030216,9.9990864,9.9990864,38377.06640625,38397.375,57.6083667528715,20.891288371491,11.519473,0,0,0,40,4449,9.9055,38387.220703125,,,,,,,,,,,,,0,,,,0,,,,,,9.9990864,,,,
,28646415.9,9.9950962,43242.271484375,0.0162655885336373,1.28646065440238E-5,1,0.999253354069792,40.0298881530762,1.99879594079708,28.4299999475479,0.181874184361553,0.0425268636597298,2.5,0.000839186217234749,0.0162305909786533,0.000955548012191639,9.9950962,9.9950962,43234.359375,43250.18359375,57.6247809517753,20.8843754095323,11.899124,0,0,0,40,4449,9.9012,43242.271484375,,,,,,,,,,,,,0,,,,-0.0049,,,,,,9.9950962,,,,
,28646512.08,9.9929972,48049.9921875,0.0165046565602657,1.172372926828E-5,1,0.999253354069792,40.0298881530762,1.99935174351128,28.4299999475479,0.184691935313154,0.0431621620550169,2.5,0.00084792727778957,0.0164773280929543,0.000968073974055289,9.9929972,9.9929972,48042.63671875,48057.34765625,57.7678189707946,20.8757498955499,11.519473,0,0,0,40,4449,9.9045,48049.9921875,,,,,,,,,,,,,0,,,,-0.00245,,,,,,9.9929972,,,,
,28646609.615,9.9927163,52924.923828125,0.016704736113618,1.1767238025848E-5,1,0.999253354069792,40.0298881530762,1.99981969728788,28.4299999475479,0.187123022306038,0.0433918267381916,2.5,0.000828455844827223,0.0166854821420172,0.000951577612825462,9.9920816,9.993351,52895.04296875,52954.8046875,57.7052886892561,20.8606949070395,11.519473,0,0,0,40,4449,9.9095,52924.923828125,,,,,,,,,,,,,0,,,,-0.00245,,,,,,9.9927163,,,,
,28646706.37,9.993576,57759.74609375,0.0168875913441953,1.33234095377506E-5,1,0.999253354069792,40.0298881530762,2.00121628493414,28.4299999475479,0.189418207505691,0.0437420070494586,2.5,0.00082162719096829,0.0168762013400298,0.000947009916756518,9.993576,9.993576,57757.40234375,57762.08984375,57.3605905122753,20.8509785294562,10.760172,0,0,0,40,4449,9.9145,57759.74609375,,,,,,,,,,,,,0,,,,0,,,,,,9.993576,,,,
,28646802.73,9.9954739,62578.224609375,0.0170284321119201,1.03996345115815E-5,1,0.999253354069792,40.0298881530762,2.00262541015693,28.4299999475479,0.191243284840691,0.043986579414988,2.5,0.000813531277615483,0.017024753750469,0.00094034685382308,9.9954739,9.9954739,62570.796875,62585.65234375,57.77250874191,20.8364613228793,10.760172,0,0,0,40,4449,9.92295,62578.224609375,,,,,,,,,,,,,0,,,,0.0049,,,,,,9.9954739,,,,
,28646899.735,9.9954433,67425.79296875,0.0171601170942346,1.04353181916495E-5,1,0.999253354069792,40.0298881530762,2.00202597832654,28.4299999475479,0.192771209983884,0.0442208278661604,2.5,0.00081037722636241,0.0171639419427291,0.00093809436533215,9.9954433,9.9954433,67418.265625,67433.3203125,57.3285437429868,20.8296356793623,10.760172,0,0,0,40,4449,9.92435,67425.79296875,,,,,,,,,,,,,0,,,,0,,,,,,9.9954433,,,,
,28646995.11,9.99714135,72193.69921875,0.0172635185462005,1.14460309387201E-5,1,0.999253354069792,40.0298881530762,2.00212685367659,28.4299999475479,0.194017196746404,0.0445283842584146,2.5,0.000817955643997875,0.0172743727755746,0.000945973663527543,9.9970751,9.9972076,72186.1796875,72201.21875,57.8256594812177,20.8355820462109,10.760172,0,0,0,40,4449,9.92755,72193.69921875,,,,,,,,,,,,,0,,,,0.00245,,,,,,9.99714135,,,,
,28647092.1,9.990509,77041.5234375,0.0173431344607995,1.1237456892021E-5,1,0.999253354069792,40.0298881530762,2.00495426865742,28.4299999475479,0.195300927627349,0.044533966466737,2.5,0.000798478672661092,0.0173610096951407,0.000926230384161161,9.990509,9.990509,77034.0859375,77048.9609375,57.728737544833,20.8084319146291,10.760172,0,0,0,40,4449,9.9355,77041.5234375,,,,,,,,,,,,,0,,,,-0.0049,,,,,,9.990509,,,,
,28647187.655,9.9955587,81817.21875,0.0174226488731932,1.44279039641104E-5,1,0.999253354069792,40.0298881530762,2.00365392377458,28.4299999475479,0.196142870933901,0.0447455232213377,2.5,0.000805244049932922,0.0174469363345086,0.000932474119709054,9.9955587,9.9955587,81807.359375,81827.078125,57.5333304150253,20.8120915881013,11.519473,0,0,0,40,4449,9.93875,81817.21875,,,,,,,,,,,,,0,,,,0,,,,,,9.9955587,,,,
,28647280.415,9.9969492,86455.390625,0.0174716880468751,1.35534154644754E-5,1,0.999253354069792,40.0298881530762,2.00332782457734,28.4299999475479,0.196723297405675,0.0449157833864569,2.5,0.000812330739829786,0.0175018417601215,0.000938618392080582,9.9969492,9.9969492,86450.34375,86460.4375,57.3895107674868,20.8249362849649,11.139823,0,0,0,40,4449,9.9406,86455.390625,,,,,,,,,,,,,0,,,,0,,,,,,9.9969492,,,,
,28647387.35,9.9958467,89229.8671875,0.017489139703271,1.0329115818342E-5,1,0.999253354069792,40.0298881530762,2.00363772432337,28.4299999475479,0.197015084753255,0.0448151264725403,2.5,0.000800045925320372,0.0175227442920901,0.000925556005164744,9.9958467,9.9958467,89227.3046875,89232.4296875,57.5028469027753,20.8168208319997,11.519473,0,0,0,40,4449,9.9453,89229.8671875,,,,,,,,,,,,,0,,,,0.0049,,,,,,9.9958467,,,,
,28647476.345,9.9968262,84782.2734375,0.0174752628888248,1.52450556926828E-5,1,0.999253354069792,40.0298881530762,1.99236694454206,28.4299999475479,0.195725954594475,0.04461291960335,2.5,0.000805500611629118,0.0175034084086245,0.000932296012998274,9.9968262,9.9968262,84779.4765625,84785.0703125,57.7600026856023,20.8032603073165,11.139823,0,0,0,40,4449,9.9512,84782.2734375,,,,,,,,,,,,,0,,,,0,,,,,,9.9968262,,,,
,28647572.405,9.9971905,79980.34375,0.017402681350479,1.34722784093461E-5,1,0.999253354069792,40.0298881530762,1.99445667448548,28.4299999475479,0.195044318287053,0.0444295697274895,2.5,0.00079818267943702,0.017424588722135,0.000925714747659305,9.9971905,9.9971905,79974.78125,79985.90625,57.698254032583,20.7704618493918,11.139823,0,0,0,40,4449,9.9544,79980.34375,,,,,,,,,,,,,0,,,,0,,,,,,9.9971905,,,,
,28647668.06,9.99835065,75197.12890625,0.0173629860975212,1.27014902409382E-5,1,0.999253354069792,40.0298881530762,1.99555507529498,28.4299999475479,0.194622635553269,0.0443715205488476,2.5,0.00079824174494452,0.0173783453231059,0.000926493295591609,9.9982653,9.998436,75192.21875,75202.0390625,57.6732419199676,20.7524562611247,11.519473,0,0,0,40,4449,9.95605,75197.12890625,,,,,,,,,,,,,0,,,,-0.00245,,,,,,9.99835065,,,,
,28647765.15,9.999567,70343.71484375,0.0172625504344849,1.05579163141582E-5,1,0.999253354069792,40.0298881530762,1.99564837614126,28.4299999475479,0.193423439996071,0.0441248290105693,2.5,0.000794821073026877,0.0172708913982994,0.000923038098360131,9.999567,9.999567,70338.515625,70348.9140625,57.5036285312945,20.7586168208356,11.519473,0,0,0,40,4449,9.95685,70343.71484375,,,,,,,,,,,,,0,,,,0,,,,,,9.999567,,,,
,28647864.465,9.992959,65381.14453125,0.0171772157975076,1.34226991606798E-5,1,0.999253354069792,40.0298881530762,2.00163266056694,28.4299999475479,0.192967186510123,0.0438328564220685,2.5,0.000774222854174701,0.0171782122166694,0.000902138097450178,9.992959,9.992959,65376.00390625,65386.28515625,58.0749989788523,20.696062592504,11.139823,0,0,0,40,4449,9.9522,65381.14453125,,,,,,,,,,,,,0,,,,0,,,,,,9.992959,,,,
,28647962.31,9.9948292,60490.1484375,0.0170594692308456,1.12685732960258E-5,1,0.999253354069792,40.0298881530762,2.00262506627478,28.4299999475479,0.191642743775582,0.043570027127494,2.5,0.000771835620262016,0.0170528041504225,0.000898778020305797,9.9948292,9.9948292,60482.57421875,60497.72265625,57.8326941378907,20.6783241385554,10.760172,0,0,0,40,4449,9.9654,60490.1484375,,,,,,,,,,,,,0,,,,0,,,,,,9.9948292,,,,
,28648059.465,9.9988451,55634.958984375,0.0169293930601848,1.25851248940661E-5,1,0.999253354069792,40.0298881530762,2.00310523701102,28.4299999475479,0.190164181841817,0.0430756436485624,2.5,0.000752694565761267,0.0169150310013958,0.000878094634892773,9.9988451,9.9988451,55629.94140625,55639.9765625,58.0093421832369,20.6844112479941,11.519473,0,0,0,40,4449,9.9657,55634.958984375,,,,,,,,,,,,,0,,,,-0.0049,,,,,,9.9988451,,,,
,28648156.595,10.0007973,50779.9609375,0.0167479417604753,1.4277942317228E-5,1,0.999253354069792,40.0298881530762,2.00306392287929,28.4299999475479,0.188008087428597,0.0427240911948685,2.5,0.000756934745493422,0.0167255979190419,0.000879870179180391,10.0007973,10.0007973,50777.27734375,50782.64453125,58.1367476318715,20.6750622753234,11.139823,0,0,0,40,4449,9.96315,50779.9609375,,,,,,,,,,,,,0,,,,0,,,,,,10.0007973,,,,
,28648255.265,10.0021596,45847.337890625,0.0165834352210779,1.24829462672951E-5,1,0.999253354069792,40.0298881530762,2.00304738827316,28.4299999475479,0.18605783898042,0.0423295043951606,2.5,0.000754917528786173,0.0165529480187673,0.000874910334925742,10.00208,10.0022392,45839.63671875,45855.0390625,57.9679158717177,20.6795742780486,11.139823,0,0,0,40,4449,9.96095,45847.337890625,,,,,,,,,,,,,0,,,,0.00245,,,,,,10.0021596,,,,
,28648353.985,10.0031757,40914.763671875,0.016345067278032,1.07130935403178E-5,1,0.999253354069792,40.0298881530762,2.0035936635453,28.4199994057417,0.183353223142867,0.0416205818029682,2.5,0.000738035376672765,0.0163067018972586,0.000853957154890735,10.0029907,10.0033607,40907.23046875,40922.296875,57.9038223331407,20.6699887648462,10.760172,0,0,0,40,4449,9.9586,40914.763671875,,,,,,,,,,,,,0,,,,0,,,,,,10.0031757,,,,
,28648450.195,10.0042887,36107.166015625,0.0161388082065783,1.25261576586556E-5,1,0.999253354069792,40.0298881530762,2.00317268343751,28.4299999475479,0.180894782833759,0.0411611576163849,2.5,0.000739612532193018,0.0160927405829511,0.000851119115701536,10.0042887,10.0042887,36104.84765625,36109.484375,57.91476513241,20.6780229315748,11.139823,0,0,0,40,4449,9.9561,36107.166015625,,,,,,,,,,,,,0,,,,0,,,,,,10.0042887,,,,
,28648548.525,10.0037918,31192.4931640625,0.0158063911587974,1.34902781381254E-5,1,0.999253354069792,40.0298881530762,2.00327274730242,28.4299999475479,0.177059555571224,0.0404428157514744,2.5,0.000740695596793352,0.0157530807426577,0.000846244859110323,10.0037918,10.0037918,31182.458984375,31202.52734375,57.9499384157754,20.6738834326464,11.139823,0,0,0,40,4449,9.9548,31192.4931640625,,,,,,,,,,,,,0,,,,0.00245,,,,,,10.0037918,,,,
,28648647.525,10.0020132,26242.224609375,0.0154394253485716,1.19473150032743E-5,1,0.999253354069792,40.0298881530762,2.00283215749521,28.4299999475479,0.172849676783927,0.0393366006442736,2.5,0.000715017093802352,0.0153796162830874,0.000813915716326097,10.0020132,10.0020132,26234.787109375,26249.662109375,57.9327425883523,20.6711309262979,11.139823,0,0,0,40,4449,9.9547,26242.224609375,,,,,,,,,,,,,0,,,,-0.0049,,,,,,10.0020132,,,,
,28648744.07,10.0012426,21417.2470703125,0.0150564935597379,1.40894666521258E-5,1,0.999253354069792,40.0298881530762,2.0031069612703,28.4299999475479,0.168505234484638,0.0383414228878076,2.5,0.000700979351731623,0.0149910034971783,0.000792799774384025,10.0012426,10.0012426,21402.1640625,21432.330078125,57.9429037591023,20.6768081204275,11.519473,0,0,0,40,4449,9.95115,21417.2470703125,,,,,,,,,,,,,0,,,,-0.00245,,,,,,10.0012426,,,,
,28648840.995,10.0007086,16572.7978515625,0.0146123827631906,8.40569343487781E-6,1,0.999253354069792,40.0298881530762,2.00298857038518,28.4199994057417,0.163409285392985,0.037427951027445,2.5,0.000705924128603111,0.0145420992740274,0.000789931279717927,10.0007086,10.0007086,16565.291015625,16580.3046875,58.0554582658715,20.6662483951562,11.519473,0,0,0,40,4449,9.95175,16572.7978515625,,,,,,,,,,,,,0,,,,-0.0049,,,,,,10.0007086,,,,
,28648938.14,10.0003529,11720.5083007813,0.0140833994495173,1.13564932924367E-5,1,0.999253354069792,40.0298881530762,2.00342685083744,28.4199994057417,0.157459542497384,0.0360722253860354,2.5,0.00068585000401519,0.0140097998020339,0.000761612543185847,10.0003529,10.0003529,11718.0517578125,11722.96484375,58.2039676845254,20.6646832572673,11.139823,0,0,0,40,4449,9.9521,11720.5083007813,,,,,,,,,,,,,0,,,,0,,,,,,10.0003529,,,,
,28649033.945,9.9994059,6929.95190429688,0.01336849956515,1.20038267707159E-5,1,0.999253354069792,40.0298881530762,2.00304837364537,28.4299999475479,0.149389019231478,0.0341996334731335,2.5,0.000653744730912377,0.0132937787946887,0.00072067566616325,9.9994059,9.9994059,6924.9677734375,6934.93603515625,58.0718724647754,20.6674308281419,11.139823,0,0,0,40,4449,9.95145,6929.95190429688,,,,,,,,,,,,,0,,,,0.0049,,,,,,9.9994059,,,,
,28649128.33,9.999712,2211.94665527344,0.0118272260242433,9.97556611500613E-6,1,0.999253354069792,40.0298881530762,2.00306222541186,28.4199994057417,0.132142726532716,0.0301611161287936,2.5,0.000574577956797474,0.011757659658663,0.000629740590395634,9.999712,9.999712,2207.05737304687,2216.8359375,58.0523317517946,20.6683072715174,10.760172,0,0,0,40,4449,9.9531,2211.94665527344,,,,,,,,,,,,,0,,,,0,,,,,,9.999712,,,,
,28649223.88,9.9992676,-2558.48474121094,-0.0116450677913643,8.74686506852511E-6,1,0.999253354069792,40.0298881530762,2.00316069016308,28.4299999475479,-0.130059427488606,-0.0300173115368437,2.5,-0.000593752026155991,-0.0115766514793122,-0.000648177276594854,9.9992676,9.9992676,-2571.0244140625,-2545.94506835938,58.0937580633138,20.6676293091116,10.760172,0,0,0,40,4449,9.9521,-2558.48474121094,,,,,,,,,,,,,0,,,,-0.0049,,,,,,9.9992676,,,,
,28649317.365,9.9978933,-7233.24145507812,-0.0132775148773384,9.09312048114336E-6,1,0.999253354069792,40.0298881530762,2.00398356812852,28.4299999475479,-0.148448080280539,-0.0339461973658858,2.5,-0.000645759438260585,-0.0132036042085048,-0.000712563742528583,9.9978933,9.9978933,-7240.85986328125,-7225.623046875,58.0890682921985,20.6600915099577,11.139823,0,0,0,40,4449,9.9548,-7233.24145507812,,,,,,,,,,,,,0,,,,-0.00245,,,,,,9.9978933,,,,
,28649411.34,10.0024576,-11928.978515625,-0.0139828320486729,1.00064746620009E-5,1,0.999253354069792,40.0298881530762,2.00346327241291,28.4299999475479,-0.156369182338839,-0.0356552672263596,2.5,-0.000666499375552634,-0.0139100756629352,-0.000742017736696462,10.0024576,10.0024576,-11934.125,-11923.83203125,57.9397772450254,20.6705065226435,11.519473,0,0,0,40,4449,9.9536,-11928.978515625,,,,,,,,,,,,,0,,,,-0.00245,,,,,,10.0024576,,,,
,28649499.62,10.0015249,-16341.73828125,-0.0144933572296842,1.00389826950878E-5,1,0.999253354069792,40.0298881530762,2.00330594346796,28.4299999475479,-0.162150605174218,-0.0368412094850333,2.5,-0.00067499219500112,-0.0144234974170468,-0.000758182583838906,10.0015249,10.0015249,-16346.6748046875,-16336.8017578125,58.2883835646023,20.6657943780386,11.139823,0,0,0,40,4449,9.95345,-16341.73828125,,,,,,,,,,,,,0,,,,0,,,,,,10.0015249,,,,
,28649584.91,10.0015278,-20604.1435546875,-0.0149113306038307,1.00230108929025E-5,1,0.999253354069792,40.0298881530762,2.00324606903651,28.4299999475479,-0.166916591739611,-0.0377593092806979,2.5,-0.000676199748223937,-0.0148454274834336,-0.000766387436439658,10.0015278,10.0015278,-20614.234375,-20594.052734375,58.1813004574677,20.6676884029078,11.139823,0,0,0,40,4449,9.9524,-20604.1435546875,,,,,,,,,,,,,0,,,,0,,,,,,10.0015278,,,,
,28649671.315,9.9996185,-24921.7939453125,-0.0153195566388916,9.05982636981963E-6,1,0.999253354069792,40.0298881530762,2.00322481951711,28.4199994057417,-0.171539302286428,-0.0389088630278896,2.5,-0.000699566650758535,-0.0152582556904141,-0.000796507101705661,9.9996185,9.9996185,-24926.626953125,-24916.9609375,58.0554582658715,20.6720082569457,11.139823,0,0,0,40,4449,9.95215,-24921.7939453125,,,,,,,,,,,,,0,,,,0,,,,,,9.9996185,,,,
,28649757.345,10.000186,-29224.2607421875,-0.015645150097487,1.21956840590883E-5,1,0.999253354069792,40.0298881530762,2.00407961144211,28.4199994057417,-0.175363123887527,-0.0396023785183279,2.5,-0.000696089983613979,-0.0155894674313585,-0.000799059032459482,10.000186,10.000186,-29229.306640625,-29219.21484375,58.1117355192562,20.6634707369778,11.139823,0,0,0,40,4449,9.9518,-29224.2607421875,,,,,,,,,,,,,0,,,,0.0049,,,,,,10.000186,,,,
,28649843,9.9992275,-33504.5,-0.0159140543369572,8.81043726854009E-6,1,0.999253354069792,40.0298881530762,2.00399252510839,28.4299999475479,-0.178462589741002,-0.0402251380842812,2.5,-0.000698408941478908,-0.0158645221480664,-0.000806610408201298,9.9992275,9.9992275,-33506.85546875,-33502.14453125,58.1883351141408,20.6584231984188,11.139823,0,0,0,40,4449,9.9525,-33504.5,,,,,,,,,,,,,0,,,,-0.0049,,,,,,9.9992275,,,,
,28649930.085,9.99928,-37854.236328125,-0.0161836252002273,1.0191287052233E-5,1,0.999253354069792,40.0298881530762,2.00365884875803,28.4299999475479,-0.181543518748985,-0.040897480142061,2.5,-0.000705729644638832,-0.0161406404328421,-0.000818775074310537,9.99928,9.99928,-37859.25390625,-37849.21875,57.76234757116,20.6566636018113,10.760172,0,0,0,40,4449,9.9527,-37854.236328125,,,,,,,,,,,,,0,,,,-0.0049,,,,,,9.99928,,,,
,28650018.325,9.9983139,-42264.2734375,-0.0164174830951009,1.23243351666769E-5,1,0.999253354069792,40.0298881530762,2.0037922873625,28.4299999475479,-0.184293450120527,-0.0413456588770949,2.5,-0.000699234735925551,-0.0163815599069486,-0.000816464259754011,9.9983139,9.9983139,-42266.71875,-42261.828125,58.33137313316,20.664077385882,11.519473,0,0,0,40,4449,9.9502,-42264.2734375,,,,,,,,,,,,,0,,,,0,,,,,,9.9983139,,,,
,28650106.2,9.9973392,-46659.703125,-0.0166488497404011,1.26863797084386E-5,1,0.999253354069792,40.0298881530762,2.00357705543502,28.4299999475479,-0.186977574876336,-0.0418276321355651,2.5,-0.000697270293721979,-0.0166200754702028,-0.000818153121106784,9.9973392,9.9973392,-46664.7578125,-46654.6484375,58.2782223938523,20.6589535438016,11.139823,0,0,0,40,4449,9.9543,-46659.703125,,,,,,,,,,,,,0,,,,0,,,,,,9.9973392,,,,
,28650194.39,9.9966164,-51067.099609375,-0.0167886403976114,1.24068234468012E-5,1,0.999253354069792,40.0298881530762,2.00414172512355,28.4299999475479,-0.188682571979306,-0.0422106151554702,2.5,-0.00070215456244343,-0.016767144619253,-0.000825525913471287,9.9966164,9.9966164,-51072.00390625,-51062.1953125,58.1836453430254,20.6553617424891,11.139823,0,0,0,40,4449,9.9567,-51067.099609375,,,,,,,,,,,,,0,,,,-0.0049,,,,,,9.9966164,,,,
,28650282.28,9.996397,-55459.599609375,-0.016924639148515,1.26789374425061E-5,1,0.999253354069792,40.0298881530762,2.00351097248395,28.4299999475479,-0.190247640871205,-0.0424976103277453,2.5,-0.000701858966348055,-0.0169103683383226,-0.000827220314734686,9.996397,9.996397,-55464.66015625,-55454.5390625,58.3016712494292,20.6599903656713,11.139823,0,0,0,40,4449,9.9608,-55459.599609375,,,,,,,,,,,,,0,,,,-0.00245,,,,,,9.996397,,,,
,28650371.495,9.9979143,-59916.59765625,-0.0170716672723712,1.15446971575125E-5,1,0.999253354069792,40.0298881530762,2.00375749820775,28.4199994057417,-0.192056398248062,-0.0426043829863108,2.5,-0.000682547534102039,-0.0170647478481785,-0.000809547764637002,9.9979143,9.9979143,-59921.5078125,-59911.6875,58.0968845773908,20.6544635831507,10.760172,0,0,0,40,4449,9.96375,-59916.59765625,,,,,,,,,,,,,0,,,,0,,,,,,9.9979143,,,,
,28650460.435,9.9961357,-64362.16796875,-0.0171957543624258,1.09552805528907E-5,1,0.999253354069792,40.0298881530762,2.00390586086474,28.4299999475479,-0.193536472248566,-0.0429837165792874,2.5,-0.000692047311694711,-0.0171957952288945,-0.00082009340462845,9.9961357,9.9961357,-64369.59765625,-64354.73828125,58.2352328252946,20.652700614052,11.139823,0,0,0,40,4449,9.9667,-64362.16796875,,,,,,,,,,,,,0,,,,0,,,,,,9.9961357,,,,
,28650551.32,9.9956999,-68904.54296875,-0.0172837635089568,1.21013609000502E-5,1,0.999253354069792,40.0298881530762,2.00467034534625,28.4299999475479,-0.194672766010231,-0.0432531009382639,2.5,-0.000697616876743909,-0.0172907142749425,-0.000826063951759147,9.9956999,9.9956999,-68912.0546875,-68897.03125,58.1930248852562,20.6482935690048,10.760172,0,0,0,40,4449,9.9693,-68904.54296875,,,,,,,,,,,,,0,,,,-0.00245,,,,,,9.9956999,,,,
,28650648.25,9.9967766,-73748.51953125,-0.0173810715888268,8.38562105868045E-6,1,0.999253354069792,40.0298881530762,2.00361759136376,28.4299999475479,-0.195779687872076,-0.0433282216796794,2.5,-0.000688048200143756,-0.0173952232166985,-0.000816558293043442,9.9967766,9.9967766,-73758.3984375,-73738.640625,58.2594633093908,20.6604528444808,10.760172,0,0,0,40,4449,9.97375,-73748.51953125,,,,,,,,,,,,,0,,,,0,,,,,,9.9967766,,,,
,28650743.59,9.994031,-78510.609375,-0.0174599401810078,1.16521345943043E-5,1,0.999253354069792,40.0298881530762,2.00434589213146,28.4199994057417,-0.196812396338616,-0.0435454704119585,2.5,-0.000691483310569586,-0.0174807520017085,-0.00081961413467261,9.994031,9.994031,-78515.640625,-78505.578125,58.1930248852562,20.6543433570401,11.139823,0,0,0,40,4449,9.9785,-78510.609375,,,,,,,,,,,,,0,,,,0,,,,,,9.994031,,,,
,28650839.27,9.9941883,-83293.12109375,-0.0175117868136648,8.59630389873336E-6,1,0.999253354069792,40.0298881530762,2.00433204384578,28.4299999475479,-0.197476965597209,-0.0436290666531487,2.5,-0.000689693590960755,-0.0175389575315279,-0.000816959432785131,9.9941883,9.9941883,-83297.9140625,-83288.328125,58.2758775082946,20.6576500482553,10.760172,0,0,0,40,4449,9.98215,-83293.12109375,,,,,,,,,,,,,0,,,,0.0049,,,,,,9.9941883,,,,
,28650929.56,9.9947462,-87807.38671875,-0.0175389959132922,1.45950701045867E-5,1,0.999253354069792,40.0298881530762,2.00431633925518,28.4299999475479,-0.19780075258621,-0.0439567316340028,2.5,-0.000714081237074623,-0.0175716277074284,-0.000840217963185019,9.9947462,9.9947462,-87814.875,-87799.8984375,58.2344511967754,20.6551261465129,11.139823,0,0,0,40,4449,9.98895,-87807.38671875,,,,,,,,,,,,,0,,,,0,,,,,,9.9947462,,,,
,28651035.7,9.997057,-87886.1171875,-0.0175611978173617,8.59066663356319E-6,1,0.999253354069792,40.0298881530762,2.00442546559013,28.4299999475479,-0.198109468250671,-0.0437537337240228,2.5,-0.000692028681176379,-0.0175941285581855,-0.000818250137914349,9.997057,9.997057,-87893.5234375,-87878.7109375,58.1344027463138,20.6538082202351,10.760172,0,0,0,40,4449,9.9908,-87886.1171875,,,,,,,,,,,,,0,,,,-0.0049,,,,,,9.997057,,,,
,28651128.27,9.9984603,-83258.8125,-0.0174936403830147,1.17991923529724E-5,1,0.999253354069792,40.0298881530762,2.00456349790196,28.4299999475479,-0.197301754452393,-0.0435430826557147,2.5,-0.000684964340022278,-0.0175207681237965,-0.000812100670052557,9.9982748,9.9986458,-83266.578125,-83251.046875,58.3227752194485,20.655793081712,10.38052,0,0,0,40,4449,9.99025,-83258.8125,,,,,,,,,,,,,0,,,,-0.00245,,,,,,9.9984603,,,,
,28651226.725,10.0030117,-78339.08984375,-0.0174581382998085,1.03298475897067E-5,1,0.999253354069792,40.0298881530762,2.00440992430061,28.4299999475479,-0.196791812275485,-0.0435621030335281,2.5,-0.000693156247703793,-0.017478703890807,-0.000821315982119055,10.0030117,10.0030117,-78348.5546875,-78329.625,58.2618081949485,20.6561461090587,11.139823,0,0,0,40,4449,9.9855,-78339.08984375,,,,,,,,,,,,,0,,,,0,,,,,,10.0030117,,,,
,28651325.93,10.0008793,-73382.0625,-0.0173779848014177,1.0211958439836E-5,1,0.999253354069792,40.0298881530762,2.00436976164863,28.4299999475479,-0.19581291573277,-0.0433138984894293,2.5,-0.000686003478807523,-0.0173916271573793,-0.000814550017145739,10.000206,10.0015526,-73386.8984375,-73377.2265625,58.1742658007946,20.6571579670713,10.38052,0,0,0,40,4449,9.9814,-73382.0625,,,,,,,,,,,,,0,,,,-0.0049,,,,,,10.0008793,,,,
,28651426.08,10.0043812,-68375.24609375,-0.0172872074274251,8.98319547158727E-6,1,0.999253354069792,40.0298881530762,2.0043172085683,28.4299999475479,-0.194690875657156,-0.0431363210164989,2.5,-0.000687430552665652,-0.0172934454425676,-0.000815944433091961,10.0043812,10.0043812,-68380.390625,-68370.1015625,58.2954182212754,20.6575877825908,11.139823,0,0,0,40,4449,9.98055,-68375.24609375,,,,,,,,,,,,,0,,,,0,,,,,,10.0043812,,,,
,28651525.225,10.0031891,-63420.8203125,-0.017169270085655,8.87253101169167E-6,1,0.999253354069792,40.0298881530762,2.00453961842215,28.4199994057417,-0.193307713994967,-0.0427741663244174,2.5,-0.000677445080316205,-0.0171679462939606,-0.000805297297896701,10.0031681,10.0032101,-63428.328125,-63413.3125,58.2571184238331,20.6598357295909,10.760172,0,0,0,40,4449,9.97575,-63420.8203125,,,,,,,,,,,,,0,,,,0.00245,,,,,,10.0031891,,,,
,28651622.04,10.005538,-58580.787109375,-0.0170601045351308,9.68085098846713E-6,1,0.999253354069792,40.0298881530762,2.00422477477528,28.4299999475479,-0.191978788385644,-0.0423908001952708,2.5,-0.000665436692859409,-0.0170511587355691,-0.000792240006757523,10.0054722,10.0056038,-58585.81640625,-58575.7578125,58.3665464165254,20.6564716560126,11.139823,0,0,0,40,4449,9.9739,-58580.787109375,,,,,,,,,,,,,0,,,,0,,,,,,10.005538,,,,
,28651710.665,10.005455,-54153.3046875,-0.0169267846475772,8.92999121357692E-6,1,0.999253354069792,40.0298881530762,2.00409436337051,28.4299999475479,-0.190371429860559,-0.0421143504742817,2.5,-0.000667213755294159,-0.0169106047844245,-0.000792369870110964,10.005455,10.005455,-54163.4140625,-54143.1953125,58.2211635119485,20.6622517340893,11.139823,0,0,0,40,4449,9.96885,-54153.3046875,,,,,,,,,,,,,0,,,,0,,,,,,10.005455,,,,
,28651800.63,10.0043173,-49656.2734375,-0.0167576679119989,9.73604473925127E-6,1,0.999253354069792,40.0298881530762,2.00424694314353,28.4299999475479,-0.188380927741296,-0.0417745209095225,2.5,-0.000669864465230462,-0.0167340582632832,-0.000792627587762503,10.0043173,10.0043173,-49666.10546875,-49646.44140625,58.2266349115831,20.6629432497509,10.760172,0,0,0,40,4449,9.9643,-49656.2734375,,,,,,,,,,,,,0,,,,0,,,,,,10.0043173,,,,
,28651888.325,10.0061331,-45273.89453125,-0.0165904372541876,1.18934869912572E-5,1,0.999253354069792,40.0298881530762,2.00374202301089,28.4299999475479,-0.186406749217759,-0.041138462556958,2.5,-0.000647573234726591,-0.0165597423071595,-0.00076754192780369,10.0061331,10.0061331,-45279.06640625,-45268.72265625,58.0945396918331,20.6626813392313,10.38052,0,0,0,40,4449,9.9608,-45273.89453125,,,,,,,,,,,,,0,,,,-0.0049,,,,,,10.0061331,,,,
,28651976.315,10.0029659,-40878.755859375,-0.0164011792794034,1.03482756282876E-5,1,0.999253354069792,40.0298881530762,2.00442284157002,28.4299999475479,-0.184268504863279,-0.0405914557224957,2.5,-0.000635552994327635,-0.0163633748633659,-0.000752065788306152,10.0029659,10.0029659,-40881.265625,-40876.24609375,58.01637683991,20.6603514750935,11.139823,0,0,0,40,4449,9.95575,-40878.755859375,,,,,,,,,,,,,0,,,,0,,,,,,10.0029659,,,,
,28652060.525,10.0056801,-36668.84765625,-0.0161781610098834,1.15968901773664E-5,1,0.999253354069792,40.0298881530762,2.00475813331282,28.4299999475479,-0.181681651330249,-0.0401933926458585,2.5,-0.000643685225179378,-0.0161336193714692,-0.000756082977837103,10.0056801,10.0056801,-36678.6328125,-36659.0625,57.8874081342369,20.6534630217588,11.139823,0,0,0,40,4449,9.9566,-36668.84765625,,,,,,,,,,,,,0,,,,-0.00245,,,,,,10.0056801,,,,
,28652151.205,10.0011311,-32136.8271484375,-0.0159104743191892,9.91571065111937E-6,1,0.999253354069792,40.0298881530762,2.00517373365649,28.4299999475479,-0.178633178437874,-0.0394763279648098,2.5,-0.000632269479130961,-0.0158591444338444,-0.000739602005885337,10.0011311,10.0011311,-32141.81640625,-32131.837890625,58.1469088026215,20.6540448310654,11.139823,0,0,0,40,4449,9.95415,-32136.8271484375,,,,,,,,,,,,,0,,,,0,,,,,,10.0011311,,,,
,28652243.335,10.0004673,-27532.216796875,-0.0156115325778367,9.00249679933886E-6,1,0.999253354069792,40.0298881530762,2.00469974085578,28.4299999475479,-0.17513359796766,-0.0388197396509388,2.5,-0.000633780839971196,-0.0155536806667818,-0.000735265899808443,10.0004673,10.0004673,-27534.626953125,-27529.806640625,58.2641530805062,20.6574583458842,11.139823,0,0,0,40,4449,9.9542,-27532.216796875,,,,,,,,,,,,,0,,,,-0.0049,,,,,,10.0004673,,,,
,28652334.155,9.9999743,-22993.7421875,-0.0152452882791597,9.13431834363191E-6,1,0.999253354069792,40.0298881530762,2.00485018391948,28.4199994057417,-0.170945745044251,-0.0379690949327494,2.5,-0.000629399753314339,-0.0151818149812224,-0.000724272108905293,9.9999743,9.9999743,-22996.330078125,-22991.154296875,58.0835968925638,20.6578143869744,11.139823,0,0,0,40,4449,9.9541,-22993.7421875,,,,,,,,,,,,,0,,,,0,,,,,,9.9999743,,,,
,28652430.095,9.9987049,-18199.4208984375,-0.0148326938765078,9.55354920355476E-6,1,0.999253354069792,40.0298881530762,2.00498724712505,28.4299999475479,-0.166277542957295,-0.0367932144543898,2.5,-0.000605043464940259,-0.0147642137488599,-0.000692558035807376,9.9987049,9.9987049,-18204.658203125,-18194.18359375,57.9983993839677,20.6537182298608,11.139823,0,0,0,40,4449,9.955,-18199.4208984375,,,,,,,,,,,,,0,,,,0,,,,,,9.9987049,,,,
,28652526.435,9.9997425,-13382.0297851562,-0.0143138679266988,1.02599795352091E-5,1,0.999253354069792,40.0298881530762,2.00497682803995,28.4299999475479,-0.160374864467212,-0.0355839484891316,2.5,-0.000596945243378703,-0.0142415997949044,-0.000676259944884395,9.9997425,9.9997425,-13386.9404296875,-13377.119140625,58.3696729306023,20.6569941813229,11.139823,0,0,0,40,4449,9.95605,-13382.0297851562,,,,,,,,,,,,,0,,,,0.0049,,,,,,9.9997425,,,,
,28652623.32,9.9988117,-8541.4697265625,-0.0136979802676638,1.00730353931654E-5,1,0.999253354069792,40.0298881530762,2.00544102238067,28.4299999475479,-0.15345835153937,-0.0339914067025388,2.5,-0.000571197501774835,-0.0136235366631238,-0.000642000376760923,9.9988117,9.9988117,-8549.1103515625,-8533.8291015625,58.3954666717369,20.6577433457985,11.139823,0,0,0,40,4449,9.95675,-8541.4697265625,,,,,,,,,,,,,0,,,,0,,,,,,9.9988117,,,,
,28652715.635,9.9980946,-3925.94006347656,-0.0127470662682477,7.57498902370417E-6,1,0.999253354069792,40.0298881530762,2.00501702370572,28.4299999475479,-0.14272716157469,-0.0316370924847063,2.5,-0.000537743259375139,-0.0126737467848761,-0.000599165323636033,9.9980946,9.9980946,-3955.99560546875,-3895.88452148438,58.2180369978715,20.6618364485302,10.760172,0,0,0,40,4449,9.95795,-3925.94006347656,,,,,,,,,,,,,0,,,,-0.00245,,,,,,9.9980946,,,,
,28652815.45,9.9997578,1061.04943847656,0.00712402506225257,2.05029742714927E-5,1,0.999253354069792,40.0298881530762,2.00523110380512,28.4199994057417,0.0795972427750313,0.0185487817730283,0.25,0.000379045004097218,0.00708155610039637,0.000411572287737282,9.9997578,9.9997578,1055.99731445312,1066.1015625,58.1039192340638,20.6550522429892,11.139823,0,0,0,40,4449,9.9522,1061.04943847656,,,,,,,,,,,,,0,,,,-0.00245,,,,,,9.9997578,,,,
,28652914,9.999898,5984.43237304687,0.013112914935401,1.04982602996806E-5,1,0.999253354069792,40.0298881530762,2.00470277331498,28.4299999475479,0.14681992960597,0.0325521295151193,2.5,0.000551922767604689,0.0130392373945278,0.000617108476979645,9.999898,9.999898,5981.953125,5986.91162109375,58.0351359243715,20.6523371942814,10.760172,0,0,0,40,4449,9.95815,5984.43237304687,,,,,,,,,,,,,0,,,,-0.0049,,,,,,9.999898,,,,
,28653010.115,10.0008469,10789.884765625,0.0139055622988956,7.65922287460881E-6,1,0.999253354069792,40.0298881530762,2.00467616575719,28.4299999475479,0.155761862811019,0.034458562255308,2.5,0.000573867914447286,0.0138324315757049,0.000648189529061515,10.0008469,10.0008469,10784.9140625,10794.85546875,58.2758775082946,20.6544444020414,11.139823,0,0,0,40,4449,9.95605,10789.884765625,,,,,,,,,,,,,0,,,,0,,,,,,10.0008469,,,,
,28653105,10.0020819,15532.6030273438,0.014479525213446,7.55914539189089E-6,1,0.999253354069792,40.0298881530762,2.00463651709099,28.4299999475479,0.162264932944446,0.0358296441891429,2.5,0.000586837665424845,0.0144092111316705,0.000669484599136158,10.0020819,10.0020819,15527.60546875,15537.6005859375,57.8991325620254,20.6553212774765,11.139823,0,0,0,40,4449,9.9548,15532.6030273438,,,,,,,,,,,,,0,,,,0.00245,,,,,,10.0020819,,,,
,28653201.5,9.9984713,20354.8388671875,0.0149582826492575,9.24508761043842E-6,1,0.999253354069792,40.0298881530762,2.00449739545526,28.4299999475479,0.167701904978895,0.0369840021142019,2.5,0.000597459375961462,0.0148923213106183,0.000688012357350124,9.9984713,9.9984713,20345.1015625,20364.576171875,58.0929764347946,20.6528383945781,10.760172,0,0,0,40,4449,9.953,20354.8388671875,,,,,,,,,,,,,0,,,,0,,,,,,9.9984713,,,,
,28653298.415,10.0001745,25197.1640625,0.0153916989064274,1.11557748157454E-5,1,0.999253354069792,40.0298881530762,2.004445687867,28.4199994057417,0.172676012967434,0.0378670248818117,2.5,0.000592069637583042,0.0153312525497681,0.000690134415305202,10.0001745,10.0001745,25192.271484375,25202.056640625,58.1641046300446,20.6510521809669,10.760172,0,0,0,40,4449,9.95205,25197.1640625,,,,,,,,,,,,,0,,,,0,,,,,,10.0001745,,,,
,28653393.445,10.0003309,29948.2412109375,0.0157530740752436,1.06349212375029E-5,1,0.999253354069792,40.0298881530762,2.00425706747569,28.4299999475479,0.17681604519861,0.038684045556938,2.5,0.000594340023241824,0.0156988980808267,0.000698969945299129,10.0003309,10.0003309,29940.767578125,29955.71484375,58.2946365927562,20.6612479608925,10.760172,0,0,0,40,4449,9.95395,29948.2412109375,,,,,,,,,,,,,0,,,,0.00245,,,,,,10.0003309,,,,
,28653489.36,9.9992914,34742.927734375,0.0160430032368349,9.85814920660822E-6,1,0.999253354069792,40.0298881530762,2.00445986508549,28.4299999475479,0.180163721305122,0.0394991722552586,2.5,0.000608975937874969,0.0159958042990116,0.000719211218927315,9.9992914,9.9992914,34737.82421875,34748.03125,58.0343542958523,20.6547357880396,10.760172,0,0,0,40,4449,9.9541,34742.927734375,,,,,,,,,,,,,0,,,,0.00245,,,,,,9.9992914,,,,
,28653582.815,9.9997959,39415.130859375,0.0163151877464276,9.57671106967175E-6,1,0.999253354069792,40.0298881530762,2.004095138541,28.4299999475479,0.183333878121534,0.0398756328028977,2.5,0.000589555742648249,0.0162753879526336,0.000704736069886356,9.9997959,9.9997959,39405.0703125,39425.19140625,58.36185664541,20.6610741682203,10.38052,0,0,0,40,4449,9.95305,39415.130859375,,,,,,,,,,,,,0,,,,0.00245,,,,,,9.9997959,,,,
,28653670.07,9.9970646,43775.658203125,0.0165345780599512,1.22675075068334E-5,1,0.999253354069792,40.0298881530762,2.00450396305984,28.4199994057417,0.185916041091007,0.0404617616338327,2.5,0.000597631406476495,0.016501768991108,0.00071661885071049,9.9970646,9.9970646,43773.22265625,43778.09375,58.2938549642369,20.656137823666,10.38052,0,0,0,40,4449,9.9565,43775.658203125,,,,,,,,,,,,,0,,,,0,,,,,,9.9970646,,,,
,28653757.295,9.9971895,48133.75,0.0167299130519672,1.05313961240945E-5,1,0.999253354069792,40.0298881530762,2.00398572205605,28.4299999475479,0.188163965250774,0.040874545873766,2.5,0.000596770525402933,0.016704284314825,0.000718921537835617,9.9971895,9.9971895,48131.41015625,48136.08984375,58.3079242775831,20.6579556219028,10.760172,0,0,0,40,4449,9.9579,48133.75,,,,,,,,,,,,,0,,,,0,,,,,,9.9971895,,,,
,28653845.15,9.9958353,52526.609375,0.0168800753983685,1.03517165848325E-5,1,0.999253354069792,40.0298881530762,2.0043521873677,28.4299999475479,0.189963103608298,0.0413067991767714,2.5,0.000604707086998764,0.0168616734475497,0.00072921334105392,9.9958353,9.9958353,52524.296875,52528.921875,58.2571184238331,20.6553134242516,10.38052,0,0,0,40,4449,9.9601,52526.609375,,,,,,,,,,,,,0,,,,0.0049,,,,,,9.9958353,,,,
,28653933.56,9.9981976,56944.3046875,0.0170355954061027,9.63711516479178E-6,1,0.999253354069792,40.0298881530762,2.00420592763278,28.4299999475479,0.191779031081394,0.0417247336512627,2.5,0.000611757806209748,0.0170243860520942,0.000738209029954977,9.9981976,9.9981976,56936.83984375,56951.76953125,58.3298098761216,20.6504141888833,11.139823,0,0,0,40,4449,9.9632,56944.3046875,,,,,,,,,,,,,0,,,,-0.00245,,,,,,9.9981976,,,,
,28654023.3,9.9955883,61429.6171875,0.0171574536730846,8.09495780515421E-6,1,0.999253354069792,40.0298881530762,2.00456231992075,28.4199994057417,0.193305511341738,0.0418269878316805,2.5,0.000596574905407156,0.017153589318754,0.000724295797859287,9.9955883,9.9955883,61424.58203125,61434.65234375,58.2969814783139,20.646941033978,10.760172,0,0,0,40,4449,9.9669,61429.6171875,,,,,,,,,,,,,0,,,,0.0049,,,,,,9.9955883,,,,
,28654118.085,9.9975505,66167.84375,0.0172676527141009,8.82451279585787E-6,1,0.999253354069792,40.0298881530762,2.00467793023238,28.4299999475479,0.194638921937499,0.0421296541091519,2.5,0.000601981561791531,0.0172711724729105,0.000730461871555229,9.9973078,9.9977932,66162.8515625,66172.8359375,58.1570699733715,20.6538537304655,10.760172,0,0,0,40,4449,9.9684,66167.84375,,,,,,,,,,,,,0,,,,0,,,,,,9.9975505,,,,
,28654215.125,9.9967756,71017.9765625,0.0173885827275638,1.00659818061827E-5,1,0.999253354069792,40.0298881530762,2.00480426127506,28.4199994057417,0.196125871015302,0.0422783484554799,2.5,0.000592295399921061,0.0173995139574329,0.000721187260684743,9.9967756,9.9967756,71015.390625,71020.5625,57.9983993839677,20.6466820425621,10.760172,0,0,0,40,4449,9.9714,71017.9765625,,,,,,,,,,,,,0,,,,0.0049,,,,,,9.9967756,,,,
,28654312.76,9.9958305,75898.6328125,0.0174649126391867,8.22977636909896E-6,1,0.999253354069792,40.0298881530762,2.00448152401402,28.4199994057417,0.197030487512257,0.0424996230497832,2.5,0.000598259845393836,0.0174828404395165,0.000726872177514038,9.9958305,9.9958305,75888.4609375,75908.8046875,58.2086574556408,20.6517603704517,10.760172,0,0,0,40,4449,9.9758,75898.6328125,,,,,,,,,,,,,0,,,,0.0049,,,,,,9.9958305,,,,
,28654408.305,9.9964657,80674.625,0.0175341388059586,9.74134890923002E-6,1,0.999253354069792,40.0298881530762,2.00417074911794,28.4299999475479,0.197861865453587,0.0426391822846384,2.5,0.000598657205683176,0.0175586197255703,0.000726644535678808,9.9964657,9.9964657,80667.21875,80682.03125,58.4791009232947,20.6618707488773,10.38052,0,0,0,40,4449,9.9787,80674.625,,,,,,,,,,,,,0,,,,0,,,,,,9.9964657,,,,
,28654504.24,9.99517155,85470.10546875,0.0175737690253227,8.43410353644126E-6,1,0.999253354069792,40.0298881530762,2.00405855883718,28.4299999475479,0.198372658693778,0.0427189522397047,2.5,0.000599077877742958,0.0176044410399955,0.000725966218717756,9.9949589,9.9953842,85465.234375,85474.9765625,58.3384077898331,20.6648688056643,10.38052,0,0,0,40,4449,9.9818,85470.10546875,,,,,,,,,,,,,0,,,,0,,,,,,9.99517155,,,,
,28654592.62,9.9949589,89888.453125,0.0176305054073698,1.07306818839325E-5,1,0.999253354069792,40.0298881530762,2.00447555632253,28.4199994057417,0.199119831823326,0.0428380066011406,2.5,0.000599144725661961,0.0176666238009504,0.000724976056269337,9.9949589,9.9949589,89878.5546875,89898.3515625,58.3274649905639,20.6564858121554,10.38052,0,0,0,40,4449,9.9862,89888.453125,,,,,,,,,,,,,0,,,,-0.00245,,,,,,9.9949589,,,,
,28654702.625,9.9986715,85659.33984375,0.0175788539575475,8.30400399606437E-6,1,0.999253354069792,40.0298881530762,2.00421125717717,28.4299999475479,0.198488815812225,0.0425032175237532,2.5,0.000578915322852865,0.0176099143426476,0.000705740487944525,9.9986715,9.9986715,85649.2734375,85669.40625,58.4056278424869,20.6597550116873,10.38052,0,0,0,40,4449,9.98745,85659.33984375,,,,,,,,,,,,,0,,,,-0.00245,,,,,,9.9986715,,,,
,28654796.7,10.0000706,80956.30078125,0.0175306177552498,1.0065281349019E-5,1,0.999253354069792,40.0298881530762,2.00433984120409,28.4299999475479,0.197875730527043,0.0424487515717033,2.5,0.000582229831562332,0.0175555812537538,0.000710089441520903,10.0000706,10.0000706,80946.4375,80966.1640625,58.5666433174485,20.6551114241164,10.760172,0,0,0,40,4449,9.98675,80956.30078125,,,,,,,,,,,,,0,,,,0,,,,,,10.0000706,,,,
,28654894.36,10.0022678,76072.25390625,0.0174590852028137,7.40821031859755E-6,1,0.999253354069792,40.0298881530762,2.00421156036372,28.4299999475479,0.19697796790094,0.0422816866612318,2.5,0.000580584093775126,0.0174773754603777,0.000709094809834232,10.0022678,10.0022678,76062.2578125,76082.25,58.3251201050062,20.6547256784053,10.760172,0,0,0,40,4449,9.9831,76072.25390625,,,,,,,,,,,,,0,,,,0,,,,,,10.0022678,,,,
,28654993.29,10.0040941,71128.66796875,0.017374295229245,9.57700343707245E-6,1,0.999253354069792,40.0298881530762,2.00449835775671,28.4299999475479,0.195972295170362,0.0420476092876088,2.5,0.000575064940945746,0.0173855025265602,0.000703820615147149,10.0040941,10.0040941,71123.5234375,71133.8125,57.9085121042561,20.6537711650946,10.760172,0,0,0,40,4449,9.97995,71128.66796875,,,,,,,,,,,,,0,,,,0,,,,,,10.0040941,,,,
,28655090.295,10.0041513,66280.58203125,0.017280064591459,9.65174256904616E-6,1,0.999253354069792,40.0298881530762,2.00435411113419,28.4299999475479,0.19480721274599,0.0418405991494527,2.5,0.000574807316868503,0.0172839641422567,0.00070336040963442,10.0041513,10.0041513,66275.65625,66285.5078125,58.1492536881792,20.6577873267242,10.00087,0,0,0,40,4449,9.9776,66280.58203125,,,,,,,,,,,,,0,,,,0,,,,,,10.0041513,,,,
,28655185.315,10.0040503,61529.6796875,0.017194430912801,7.29520942924711E-6,1,0.999253354069792,40.0298881530762,2.00460732882499,28.4299999475479,0.193765403421759,0.0417112525386689,2.5,0.000579592324063288,0.0171908534810167,0.000707590863696922,10.0040503,10.0040503,61521.98828125,61537.37109375,58.385305500987,20.657261632804,10.38052,0,0,0,40,4449,9.9741,61529.6796875,,,,,,,,,,,,,0,,,,-0.00245,,,,,,10.0040503,,,,
,28655281.805,10.0058117,56706.927734375,0.0170523538449349,1.09676312795984E-5,1,0.999253354069792,40.0298881530762,2.00491924498223,28.4199994057417,0.192140042116201,0.0411599542622741,2.5,0.000557757818853167,0.0170411488226004,0.000684324617604994,10.0058117,10.0058117,56699.29296875,56714.5625,58.2813489079292,20.6562893411543,10.00087,0,0,0,40,4449,9.9719,56706.927734375,,,,,,,,,,,,,0,,,,0.0049,,,,,,10.0058117,,,,
,28655379.86,10.0042286,51807.4375,0.0168988099314432,9.66906902395677E-6,1,0.999253354069792,40.0298881530762,2.00484689452847,28.4199994057417,0.190290294002439,0.0408863363346059,2.5,0.000563740368346849,0.0168794834076943,0.000688248925240093,10.0042286,10.0042286,51802.51171875,51812.36328125,58.2250716545446,20.6547932943581,10.38052,0,0,0,40,4449,9.9662,51807.4375,,,,,,,,,,,,,0,,,,-0.0049,,,,,,10.0042286,,,,
,28655478.67,10.0048409,46867.298828125,0.0167066146195764,7.33142843092334E-6,1,0.999253354069792,40.0298881530762,2.00516969455126,28.4299999475479,0.188056039599096,0.0404319808368076,2.5,0.000560684206124915,0.016679114166276,0.000682261645463865,10.0048409,10.0048409,46854.9375,46879.66015625,58.2031860560062,20.6549747424418,10.38052,0,0,0,40,4449,9.9641,46867.298828125,,,,,,,,,,,,,0,,,,-0.00245,,,,,,10.0048409,,,,
,28655574.645,10.0042696,42072.083984375,0.0164988712893652,9.10298232493551E-6,1,0.999253354069792,40.0298881530762,2.00472967143992,28.4299999475479,0.18558556175304,0.0399043420896988,2.5,0.0005557485986468,0.0164635000168875,0.000673740295617928,10.0042696,10.0042696,42062.0625,42082.10546875,58.3071426490639,20.6559124180674,10.38052,0,0,0,40,4449,9.9601,42072.083984375,,,,,,,,,,,,,0,,,,0.00245,,,,,,10.0042696,,,,
,28655670.36,10.0029984,37287.419921875,0.016264029216051,8.44075863149592E-6,1,0.999253354069792,40.0298881530762,2.00445213534947,28.4199994057417,0.182830959961168,0.0392932944025528,2.5,0.000548590749435116,0.0162210015234897,0.000662223153018424,10.0029984,10.0029984,37284.98046875,37289.859375,58.2563367953139,20.6567964696106,10.00087,0,0,0,40,4449,9.9577,37287.419921875,,,,,,,,,,,,,0,,,,-0.0049,,,,,,10.0029984,,,,
,28655769.14,10.0029202,32349.6806640625,0.0159631862781604,8.47120553358378E-6,1,0.999253354069792,40.0298881530762,2.0048720242782,28.4199994057417,0.179373740691509,0.0386535348040841,2.5,0.00055030356435864,0.0159126172000481,0.00065840240769273,10.0029202,10.0029202,32346.94921875,32352.412109375,58.40250132841,20.6571039271904,10.760172,0,0,0,40,4449,9.9557,32349.6806640625,,,,,,,,,,,,,0,,,,-0.0049,,,,,,10.0029202,,,,
,28655858.065,10.0013371,27904.83203125,0.0156539536322134,7.23720770689513E-6,1,0.999253354069792,40.0298881530762,2.00469611985491,28.4199994057417,0.175827197224893,0.0377492131920347,2.5,0.000531012029730863,0.0155972338044433,0.000633457143034771,10.0013371,10.0013371,27900.05078125,27909.61328125,58.1914616282177,20.658014415669,10.38052,0,0,0,40,4449,9.954,27904.83203125,,,,,,,,,,,,,0,,,,0.00245,,,,,,10.0013371,,,,
,28655945.79,10.0002594,23521.810546875,0.0153285203791768,7.37108486032965E-6,1,0.999253354069792,40.0298881530762,2.00458154584181,28.4299999475479,0.172061778250357,0.0370812913647235,2.5,0.00053566216366632,0.0152661182498517,0.000631943516105576,10.0002594,10.0002594,23516.408203125,23527.212890625,58.1813004574677,20.6587356796957,10.38052,0,0,0,40,4449,9.9536,23521.810546875,,,,,,,,,,,,,0,,,,0,,,,,,10.0002594,,,,
,28656031.895,10.0013332,19216.55859375,0.014956876596484,8.36334792042126E-6,1,0.999253354069792,40.0298881530762,2.00502515025877,28.4299999475479,0.167873065143624,0.0360749766927836,2.5,0.000517857067055145,0.0148898036852386,0.000607568913580367,10.0013332,10.0013332,19214.18359375,19218.93359375,57.93508747391,20.6517336215877,10.38052,0,0,0,40,4449,9.95275,19216.55859375,,,,,,,,,,,,,0,,,,0,,,,,,10.0013332,,,,
,28656118.22,10.0016317,14901.775390625,0.0145321410903848,8.61980157161185E-6,1,0.999253354069792,40.0298881530762,2.00495601516146,28.4299999475479,0.163014271168519,0.0351569503636075,2.5,0.000518191005149846,0.0144611810561829,0.000600788453474454,10.0016317,10.0016317,14896.9130859375,14906.6376953125,58.3595117598523,20.6562663705949,10.00087,0,0,0,40,4449,9.9526,14901.775390625,,,,,,,,,,,,,0,,,,0.00245,,,,,,10.0016317,,,,
,28656207.565,9.999692,10439.37109375,0.0139952643931857,7.24299590608001E-6,1,0.999253354069792,40.0298881530762,2.0045620366947,28.4199994057417,0.156904370932692,0.0338332172990249,2.5,0.000503064096207585,0.0139216855112262,0.000577863578228227,9.999692,9.999692,10429.564453125,10449.177734375,57.9632261006023,20.659342851424,10.760172,0,0,0,40,4449,9.9506,10439.37109375,,,,,,,,,,,,,0,,,,0,,,,,,9.999692,,,,
,28656292.32,9.999054,6201.125,0.013358968440257,7.13148237568738E-6,1,0.999253354069792,40.0298881530762,2.00460806864524,28.4299999475479,0.149721377704257,0.0323135376520854,2.5,0.000486860049814575,0.013284498501008,0.000553893851087514,9.999054,9.999054,6196.0283203125,6206.2216796875,57.9905830987754,20.6607075261084,10.00087,0,0,0,40,4449,9.9521,6201.125,,,,,,,,,,,,,0,,,,0,,,,,,9.999054,,,,
,28656378.03,10.0000849,1920.08660888672,0.0116960679709062,7.19998509843369E-6,1,0.999253354069792,40.0298881530762,2.00441976526601,28.4199994057417,0.131055480745738,0.0281813051349459,2.5,0.000420851520312662,0.0116278197111207,0.000476013489362536,10.0000849,10.0000849,1917.67565917969,1922.49755859375,58.1781739433908,20.6586985018999,10.00087,0,0,0,40,4449,9.9525,1920.08660888672,,,,,,,,,,,,,0,,,,0,,,,,,10.0000849,,,,
,28656418.875,10.0040417,-0.380594328045845,0.00430443596976023,3.95902925060969E-6,1,0.999253354069792,40.0298881530762,2.00482592150098,28.4199994057417,0.0484973477046226,0.00890563560929879,2.5,2.52540905139205E-5,0.00427958705036701,4.58561148073146E-5,10.0040417,10.0040417,-0.395818114280701,-0.365370541810989,58.3939034146985,20.6525270632508,10.760172,0,0,0,40,4417,9.949,-0.380594328045845,,,,,,,,,,,,,0,,,,0.00245,,,,,,10.0040417,,,,