File: data/looselyPackedNP/ios-11/ppms/rawdata/PMK18_HYST_EB_FC1T_30K.DAT
[Header]
; VSM Data File (default extension .dat)
; Copyright (c) 2003-2013, Quantum Design, Inc. All rights reserved.
TITLE,
FILEOPENTIME,32677279.02,01/14/2019,1:03 pm
BYAPP,VSM,2.0,2.0
INFO,PPMS VSM Option Release 1.4.10 Build 1,APPNAME
INFO,Quantum Design Linear Motor Servo Controller,MOTOR_MODULE_NAME
INFO,3101-100 M1,MOTOR_HW_VERSION
INFO,MMC1014,MOTOR_SERIAL_NUMBER
INFO,SRV No X-over 01.03.11,MOTOR_SOFTWARE_VERSION
INFO,Quantum Design VSM Detection Module,VSM_MODULE_NAME
INFO,3101-150 F0,VSM_HW_VERSION
INFO,VSM707,VSM_SERIAL_NUMBER
INFO,VSM No X-over 01.02.05 May 20 2008 13:51:47,VSM_SOFTWARE_VERSION
INFO,704,PREAMP_SERIAL_NUMBER
INFO,822,COIL_SERIAL_NUMBER
INFO,0,MOMENT_UNITS
INFO,Maghemite,SAMPLE_MATERIAL
INFO,Oleate Iron Spheres,SAMPLE_COMMENT
INFO,,SAMPLE_MASS
INFO,,SAMPLE_VOLUME
INFO,,SAMPLE_MOLECULAR_WEIGHT
INFO,,SAMPLE_SIZE
INFO,,SAMPLE_SHAPE
DATATYPE,COMMENT,1
DATATYPE,TIME,2
STARTUPAXIS,X,2
STARTUPAXIS,Y1,5
[Data]
Comment,Time Stamp (sec),Temperature (K),Magnetic Field (Oe),Moment (emu),M. Std. Err. (emu),Transport Action,Averaging Time (sec),Frequency (Hz),Peak Amplitude (mm),Center Position (mm),Coil Signal' (mV),Coil Signal" (mV),Range (mV),M. Quad. Signal (emu),M. Raw' (emu),M. Raw" (emu),Min. Temperature (K),Max. Temperature (K),Min. Field (Oe),Max. Field (Oe),Mass (grams),Motor Lag (deg),Pressure (Torr),VSM Status (code),Motor Status (code),Measure Status (code),Measure Count,PPMS Status (code),System Temp. (K),System Field (Oe),Sample Position (deg),Bridge 1 Resistance (ohms),Bridge 1 Excitation (에),Bridge 2 Resistance (ohms),Bridge 2 Excitation (에),Bridge 3 Resistance (ohms),Bridge 3 Excitation (에),Bridge 4 Resistance (ohms),Bridge 4 Excitation (에),Signal 1 Vin (V),Signal 2 Vin (V),Digital Inputs (code),Drive 1 Iout (mA),Drive 1 Ipower (W),Drive 2 Iout (mA),Drive 2 Ipower (W),Pressure (),Map 20 (),Map 21 (),Map 22 (),Map 23 (),Map 24 (),Map 25 (),Map 26 (),Map 27 (),Map 28 (),Map 29 ()
,32677294.97,29.9977398,9999.7958984375,,,2,,,,34.0400008529425,,,,,,,29.9977398,29.9977398,9999.7958984375,9999.7958984375,,,16.075285,,,,-99999999,4369,30.0027,9999.7958984375,,,,,,,,,,,,,,,,,,,,,,,29.9977398,,,,
,32677413.39,30.023838,899.051849365234,0.0099992816532758,3.55608915980209E-6,1,0.999253354069792,40.0298881530762,1.9961680617586,34.0199992060661,0.112219107974812,0.0208553349808388,2.5,7.31779930530956E-5,0.00994729281309621,0.000127879532017957,30.023838,30.023838,896.539916992188,901.563781738281,55.0555680090635,20.7710709652349,15.315984,0,0,0,40,4449,29.9647,899.051849365234,,,,,,,,,,,,,0,,,,-0.0049,,,,,,30.023838,,,,
,32677436.935,30.0279255,2075.67248535156,0.0109724161855791,1.63792172033489E-6,1,0.999253354069792,40.0298881530762,1.99675131480376,34.0199992060661,0.123187145149466,0.0228660625561106,2.5,7.73062160680766E-5,0.0109160646399723,0.000137967090747847,30.0279255,30.0279255,2063.26245117187,2088.08251953125,55.4495087827559,20.773488784749,15.695635,0,0,0,40,4449,29.96225,2075.67248535156,,,,,,,,,,,,,0,,,,0,,,,,,30.0279255,,,,
,32677458.26,30.0197239,3137.81652832031,0.0113599997107006,1.14982139749398E-6,1,0.999253354069792,40.0298881530762,1.99680309632557,34.0199992060661,0.127545243427036,0.0237010406614347,2.5,8.16524227437606E-5,0.0113023576117294,0.000145079122269761,30.0197239,30.0197239,3130.33227539063,3145.30078125,55.6066161151213,20.7704905344178,15.695635,0,0,0,40,4449,29.9525,3137.81652832031,,,,,,,,,,,,,0,,,,0.0049,,,,,,30.0197239,,,,
,32677479.52,30.0210247,4197.31420898438,0.011598998192937,1.21946134450053E-6,1,0.999253354069792,40.0298881530762,1.9975548071615,34.0199992060661,0.130286601357132,0.0241980153534375,2.5,8.16126097984465E-5,0.0115409508671082,0.000147076645165184,30.0210247,30.0210247,4187.228515625,4207.39990234375,55.6214670569867,20.7698443542393,16.075285,0,0,0,40,4449,29.9581,4197.31420898438,,,,,,,,,,,,,0,,,,-0.0049,,,,,,30.0210247,,,,
,32677501.93,30.0153761,5315.37939453125,0.0117895308086718,1.22523497359799E-6,1,0.999253354069792,40.0298881530762,1.99808110663246,34.0300016105175,0.132471033121115,0.0245985153634204,2.5,8.17609213910569E-5,0.0117314235649437,0.000149057709100967,30.0145683,30.0161839,5310.29638671875,5320.46240234375,55.8215639579098,20.7641755318422,15.315984,0,0,0,40,4449,29.94945,5315.37939453125,,,,,,,,,,,,,0,,,,0.0049,,,,,,30.0153761,,,,
,32677525.165,30.01556205,6476.64306640625,0.0119587670888974,1.51653009610172E-6,1,0.999253354069792,40.0298881530762,1.99842276539595,34.0300016105175,0.134404285771327,0.0249665114830575,2.5,8.28984713865047E-5,0.0119008207624907,0.000151981434584381,30.0152988,30.0158253,6469.06396484375,6484.22216796875,55.659766854429,20.756296666667,15.315984,0,0,0,40,4449,29.95115,6476.64306640625,,,,,,,,,,,,,0,,,,0.00245,,,,,,30.01556205,,,,
,32677548.295,30.0097618,7633.12963867187,0.0120979610025317,1.05266491837168E-6,1,0.999253354069792,40.0298881530762,1.99938888221595,34.0300016105175,0.136041225814572,0.0252818474820255,2.5,8.40123604017344E-5,0.0120403756626679,0.000154727394596924,30.0097618,30.0097618,7628.24462890625,7638.0146484375,55.9622570913713,20.7439486802771,15.695635,0,0,0,40,4449,29.9469,7633.12963867187,,,,,,,,,,,,,0,,,,0,,,,,,30.0097618,,,,
,32677571.66,30.0104866,8802.65234375,0.0122240821776127,1.2994540779439E-6,1,0.999253354069792,40.0298881530762,1.99979862417793,34.0300016105175,0.137500464469343,0.0255439649923268,2.5,8.32612001624386E-5,0.0121670125799195,0.000155579119321117,30.010313,30.0106602,8797.6083984375,8807.6962890625,55.7973334738136,20.7421101107024,15.695635,0,0,0,40,4449,29.9499,8802.65234375,,,,,,,,,,,,,0,,,,0,,,,,,30.0104866,,,,
,32677595.91,30.007843,10015.029296875,0.0123438227888637,9.18377751916777E-7,1,0.999253354069792,40.0298881530762,2.00076639806805,34.0300016105175,0.138917108813856,0.0258526472366182,2.5,8.71033645628367E-5,0.0122873667560698,0.000161009371450463,30.007843,30.007843,10007.6279296875,10022.4306640625,55.9989936317752,20.7176428408457,15.695635,0,0,0,40,4449,29.94985,10015.029296875,,,,,,,,,,,,,0,,,,0,,,,,,30.007843,,,,
,32677618.85,30.005806,11161.9560546875,0.0124487345327285,6.12876437694787E-7,1,0.999253354069792,40.0298881530762,2.00106224409851,34.0300016105175,0.14013638477531,0.0260472362094304,2.5,8.4233504562812E-5,0.0123929865334773,0.000159630264149019,30.005806,30.005806,11152.03515625,11171.876953125,55.8160925582751,20.7178382727672,15.695635,0,0,0,40,4449,29.9488,11161.9560546875,,,,,,,,,,,,,0,,,,0.00245,,,,,,30.005806,,,,
,32677642.715,30.0040283,12353.6083984375,0.0125501283756252,5.32298326593568E-7,1,0.999253354069792,40.0298881530762,2.0006303632888,34.0300016105175,0.141262276231703,0.0262599749420244,2.5,8.43530857638271E-5,0.0124951794109062,0.000161243191766474,30.0040283,30.0040283,12346.33984375,12360.876953125,56.0779381122175,20.723023815261,15.695635,0,0,0,40,4449,29.94655,12353.6083984375,,,,,,,,,,,,,0,,,,0.00245,,,,,,30.0040283,,,,
,32677665.295,30.0040531,13480.73046875,0.012642962133264,1.36748242932177E-6,1,0.999253354069792,40.0298881530762,2.00099760949831,34.0300016105175,0.142344727439678,0.0264683644484018,2.5,8.47779029580862E-5,0.0125888273606676,0.000163064437227881,30.0040531,30.0040531,13475.7431640625,13485.7177734375,56.2076884464098,20.7227862236674,16.075285,0,0,0,40,4449,29.94655,13480.73046875,,,,,,,,,,,,,0,,,,0,,,,,,30.0040531,,,,
,32677689.26,30.0030479,14677.6254882812,0.0127330114133879,9.16608074100972E-7,1,0.999253354069792,40.0298881530762,2.0028865147417,34.0300016105175,0.143502649477197,0.0266844773065255,2.5,8.45943762955228E-5,0.0126798249886683,0.000164311684529222,30.0030479,30.0030479,14670.05859375,14685.1923828125,56.3991874336214,20.6987868213625,14.936333,0,0,0,40,4449,29.9461,14677.6254882812,,,,,,,,,,,,,0,,,,0.0049,,,,,,30.0030479,,,,
,32677713.37,30.0016232,15884.4169921875,0.0128184716036859,1.37254040957194E-6,1,0.999253354069792,40.0298881530762,2.00257590156726,34.0300016105175,0.144455520733814,0.0268875352805933,2.5,8.65304301218957E-5,0.0127662912986425,0.000167642362812846,30.0016232,30.0016232,15874.4462890625,15894.3876953125,56.3780834636021,20.6980975984646,15.695635,0,0,0,40,4449,29.94445,15884.4169921875,,,,,,,,,,,,,0,,,,0.00245,,,,,,30.0016232,,,,
,32677737.11,30.003191,17071.421875,0.0129005300180517,1.38526305551708E-6,1,0.999253354069792,40.0298881530762,2.00317951527454,34.0300016105175,0.145437991044409,0.0270696025597494,2.5,8.61870337423863E-5,0.0128494105583044,0.0001686655200612,30.003191,30.003191,17069.013671875,17073.830078125,56.0943523111213,20.6923053444804,15.695635,0,0,0,40,4449,29.9495,17071.421875,,,,,,,,,,,,,0,,,,0,,,,,,30.003191,,,,
,32677759.86,30.0004053,18205.775390625,0.0129741178089921,1.17823993097023E-6,1,0.999253354069792,40.0298881530762,2.00352827511125,34.0300016105175,0.146307154239786,0.0272315357973066,2.5,8.59206599789995E-5,0.0129240566897225,0.000169659054588527,30.0002022,30.0006084,18193.224609375,18218.326171875,56.5641110511791,20.6898245598491,15.315984,0,0,0,40,4449,29.9479,18205.775390625,,,,,,,,,,,,,0,,,,0,,,,,,30.0004053,,,,
,32677782.445,30.0022049,19337.4765625,0.013043394679497,1.16398399403474E-6,1,0.999253354069792,40.0298881530762,2.00235644248848,34.0300016105175,0.147020917211154,0.027369809153416,2.5,8.60880358852804E-5,0.0129944380161513,0.000171046373021932,30.0022049,30.0022049,19332.419921875,19342.533203125,56.6242964471598,20.7111694328629,14.936333,0,0,0,40,4449,29.9494,19337.4765625,,,,,,,,,,,,,0,,,,0.0049,,,,,,30.0022049,,,,
,32677826.845,30.0016232,19544.9248046875,0.0130640507521827,1.20679894828221E-6,1,0.999253354069792,40.0298881530762,2.00344953635207,34.0300016105175,0.147333420802758,0.0274273362164909,2.5,8.60323056868669E-5,0.013015270697354,0.000171265135286097,30.0016232,30.0016232,19530.06640625,19559.783203125,56.7180918694675,20.692970899004,15.315984,0,0,0,40,4449,29.9494,19544.9248046875,,,,,,,,,,,,,0,,,,0.00245,,,,,,30.0016232,,,,
,32677850.215,30.0015583,18382.9658203125,0.0129924583820635,1.42254694270086E-6,1,0.999253354069792,40.0298881530762,2.00253764537009,34.0300016105175,0.146447805558901,0.0272548961148437,2.5,8.56792506670877E-5,0.0129425446538742,0.000169660960150937,30.001524,30.0015926,18375.41015625,18390.521484375,56.0709034555444,20.7089685702556,14.936333,0,0,0,40,4449,29.95045,18382.9658203125,,,,,,,,,,,,,0,,,,-0.0049,,,,,,30.0015583,,,,
,32677872.14,30.0007858,17288.25,0.0129237569296735,1.36744431911538E-6,1,0.999253354069792,40.0298881530762,2.00282086222963,34.0300016105175,0.145675012413141,0.027129660494781,2.5,8.75647725187985E-5,0.0128727856474559,0.000170334163306231,30.0007858,30.0007858,17283.208984375,17293.291015625,56.1506295645059,20.7093764255413,15.315984,0,0,0,40,4449,29.9444,17288.25,,,,,,,,,,,,,0,,,,0.00245,,,,,,30.0007858,,,,
,32677894.2,30.000433,16186.7958984375,0.0128508004674848,1.3293095542022E-6,1,0.999253354069792,40.0298881530762,2.00419426681354,34.0300016105175,0.144936333672818,0.0269724548356203,2.5,8.6141243162E-5,0.0127988484297634,0.000167679410315458,30.000433,30.000433,16184.2490234375,16189.3427734375,56.3632325217367,20.6891439054896,15.315984,0,0,0,40,4449,29.9495,16186.7958984375,,,,,,,,,,,,,0,,,,0,,,,,,30.000433,,,,
,32677917.62,29.9981346,15017.4116210938,0.012768132624464,1.40576071921742E-6,1,0.999253354069792,40.0298881530762,2.00464426844973,34.0300016105175,0.144019261164014,0.0268039304962076,2.5,8.65903599619564E-5,0.0127151730287224,0.000166765947972813,29.9981346,29.9981346,15004.9970703125,15029.826171875,56.5953761919483,20.681557116532,15.315984,0,0,0,40,4449,29.947,15017.4116210938,,,,,,,,,,,,,0,,,,-0.00245,,,,,,29.9981346,,,,
,32677941.245,29.9981918,13838.1958007813,0.0126840460616208,1.0762509902345E-6,1,0.999253354069792,40.0298881530762,2.0030159597052,34.0300016105175,0.142946255520971,0.0265974013736028,2.5,8.62679951104535E-5,0.0126301256440329,0.000165067284249777,29.9981918,29.9981918,13830.47265625,13845.9189453125,56.7649895806214,20.6997589983002,14.936333,0,0,0,40,4449,29.9497,13838.1958007813,,,,,,,,,,,,,0,,,,0,,,,,,29.9981918,,,,
,32677964.32,29.9989452,12680.9482421875,0.0125961331715309,1.2646589901746E-6,1,0.999253354069792,40.0298881530762,2.00370045036739,34.0300016105175,0.141987469465465,0.0264191100485147,2.5,8.65098013464044E-5,0.0125413243873182,0.000163915754994848,29.9989452,29.9989452,12675.91015625,12685.986328125,56.4038772047367,20.6896814044187,14.936333,0,0,0,40,4449,29.94815,12680.9482421875,,,,,,,,,,,,,0,,,,-0.0049,,,,,,29.9989452,,,,
,32677987.22,29.9984112,11539.2119140625,0.0125016542434836,1.16428425120806E-6,1,0.999253354069792,40.0298881530762,2.00573656564819,34.0199992060661,0.141042522364666,0.02625986900595,2.5,8.81044142648432E-5,0.0124460408343886,0.000164084888217637,29.9984112,29.9984112,11531.7412109375,11546.6826171875,56.5820885071214,20.6698714131332,14.936333,0,0,0,40,4449,29.9492,11539.2119140625,,,,,,,,,,,,,0,,,,0.00245,,,,,,29.9984112,,,,
,32678009.695,29.9978371,10412.3173828125,0.0123932717658122,1.5112204187895E-6,1,0.999253354069792,40.0298881530762,1.99262965281451,34.0300016105175,0.138942009407494,0.0258267810250966,2.5,8.45325619619705E-5,0.0123370085379465,0.000159041776602988,29.9978371,29.9978371,10402.3525390625,10422.2822265625,57.0049495360253,20.6669645232467,15.315984,0,0,0,40,4449,29.9508,10412.3173828125,,,,,,,,,,,,,0,,,,0,,,,,,29.9978371,,,,
,32678031.985,29.9943256,9302.7548828125,0.0122916974596996,1.2031017955153E-6,1,0.999253354069792,40.0298881530762,1.99226930369301,34.0300016105175,0.137770257388485,0.0255903908851675,2.5,8.30403596474848E-5,0.0122348021871463,0.000156128739104978,29.9943256,29.9943256,9297.828125,9307.681640625,56.8118872917752,20.6700309391358,15.315984,0,0,0,40,4449,29.9498,9302.7548828125,,,,,,,,,,,,,0,,,,-0.0049,,,,,,29.9943256,,,,
,32678055.875,29.9970322,8105.298828125,0.0121700440079869,1.00109686499879E-6,1,0.999253354069792,40.0298881530762,1.99291789910386,34.0300016105175,0.136435799221233,0.0253452869728006,2.5,8.33142525499666E-5,0.0121125709716966,0.000154806479203114,29.9970322,29.9970322,8092.68798828125,8117.90966796875,56.7282530402175,20.6641811001576,15.315984,0,0,0,40,4449,29.9532,8105.298828125,,,,,,,,,,,,,0,,,,0,,,,,,29.9970322,,,,
,32678078.125,29.9952965,6993.5712890625,0.0120462581269143,1.08513607371373E-6,1,0.999253354069792,40.0298881530762,1.99334930119721,34.0300016105175,0.135068780103479,0.0250665182947366,2.5,8.111837462685E-5,0.0119883631109501,0.000151089010588248,29.9952965,29.9952965,6983.32275390625,7003.81982421875,56.7415407250445,20.660841089215,15.315984,0,0,0,40,4449,29.95185,6993.5712890625,,,,,,,,,,,,,0,,,,0,,,,,,29.9952965,,,,
,32678101.245,29.9959927,5839.36206054687,0.0119004396291814,1.06061809172128E-6,1,0.999253354069792,40.0298881530762,1.99217447784706,34.0300016105175,0.133346464757199,0.0247525352852595,2.5,8.14248461758734E-5,0.0118422419137222,0.000149732587705822,29.9959927,29.9959927,5834.3984375,5844.32568359375,56.7055858131598,20.6693485751723,15.315984,0,0,0,40,4449,29.9555,5839.36206054687,,,,,,,,,,,,,0,,,,-0.0049,,,,,,29.9959927,,,,
,32678124.555,29.9953938,4672.1240234375,0.0117178901840805,1.07280853019089E-6,1,0.999253354069792,40.0298881530762,1.99189039332283,34.0300016105175,0.131267955964228,0.0243921213185619,2.5,8.31557019681856E-5,0.0116596183298178,0.000149605663673207,29.9953938,29.9953938,4664.61376953125,4679.63427734375,56.4843849422175,20.6696625249327,15.315984,0,0,0,40,4449,29.9576,4672.1240234375,,,,,,,,,,,,,0,,,,0.00245,,,,,,29.9953938,,,,
,32678148.17,29.9969177,3492.1572265625,0.0114959625376863,9.00279723486722E-7,1,0.999253354069792,40.0298881530762,1.99248472678208,34.0300016105175,0.128812501284275,0.0239120199630862,2.5,8.02894987392707E-5,0.011437905191844,0.000144715041558531,29.9969177,29.9969177,3484.61206054687,3499.70239257812,56.4710972573906,20.6672414051427,15.695635,0,0,0,40,4449,29.9551,3492.1572265625,,,,,,,,,,,,,0,,,,0,,,,,,29.9969177,,,,
,32678171.215,29.996521,2342.44152832031,0.011168870456269,9.61384058482292E-7,1,0.999253354069792,40.0298881530762,1.9917008974067,34.0300016105175,0.125091937322386,0.0232194455433807,2.5,7.85232908150304E-5,0.0111116827794429,0.000140423555169881,29.996521,29.996521,2339.96435546875,2344.91870117187,56.8978664288906,20.6754687585813,14.936333,0,0,0,40,4449,29.9603,2342.44152832031,,,,,,,,,,,,,0,,,,-0.00245,,,,,,29.996521,,,,
,32678194.26,29.9973125,1187.52917480469,0.0105225039110467,2.2868713026772E-6,1,0.999253354069792,40.0298881530762,1.99142405760544,34.0300016105175,0.117828074277984,0.0218785999428088,2.5,7.52267261122691E-5,0.0104679475021149,0.000132929633587991,29.9973125,29.9973125,1180.06860351562,1194.98974609375,56.340565294679,20.6775306400552,15.315984,0,0,0,40,4449,29.9572,1187.52917480469,,,,,,,,,,,,,0,,,,0,,,,,,29.9973125,,,,
,32678217.135,29.9968853,45.4814853668213,0.00719865670612522,2.3218975362026E-5,1,0.999253354069792,40.0298881530762,1.99177179234577,34.0300016105175,0.0806226305999657,0.0149434041788654,2.5,4.94742925616624E-5,0.00716099189163504,8.8633965690505E-5,29.9968853,29.9968853,40.3526153564453,50.6103553771973,56.5344091674483,20.6729764854328,15.695635,0,0,0,40,4449,29.95855,45.4814853668213,,,,,,,,,,,,,0,,,,0,,,,,,29.9968853,,,,
,32678241.89,29.9973392,-1192.26336669922,-0.00954615937593071,5.69144348621848E-6,1,0.999253354069792,40.0298881530762,1.9921814944675,34.0300016105175,-0.106911428161813,-0.0199022723972768,0.25,-7.26224104757339E-5,-0.0094966413844246,-0.000124949209187549,29.9973392,29.9973392,-1202.37463378906,-1182.15209960938,56.3147715535444,20.6744869177838,15.695635,0,0,0,40,4449,29.9555,-1192.26336669922,,,,,,,,,,,,,0,,,,0,,,,,,29.9973392,,,,
,32678266.9,29.997364,-2435.94897460938,-0.0109011003305446,9.87680136334694E-7,1,0.999253354069792,40.0298881530762,1.99235108492962,34.0300016105175,-0.12212853308045,-0.0226872060605087,2.5,-7.81270014029709E-5,-0.0108453337397994,-0.00013858794982673,29.997364,29.997364,-2448.4794921875,-2423.41845703125,56.9314764552176,20.6736908029032,15.315984,0,0,0,40,4449,29.9591,-2435.94897460938,,,,,,,,,,,,,0,,,,0.00245,,,,,,29.997364,,,,
,32678290.22,29.9971905,-3602.94714355469,-0.0113435158353591,8.8975303619077E-7,1,0.999253354069792,40.0298881530762,1.99253098858759,34.0300016105175,-0.127105838407215,-0.0236082774034666,2.5,-8.02803802005898E-5,-0.0112863060022846,-0.000143919243755383,29.9971905,29.9971905,-3608.07250976562,-3597.82177734375,56.811105663256,20.6718358380788,14.936333,0,0,0,40,4449,29.9577,-3602.94714355469,,,,,,,,,,,,,0,,,,0,,,,,,29.9971905,,,,
,32678313.4,29.9978504,-4763.84057617188,-0.0116283868090636,6.06142883725132E-7,1,0.999253354069792,40.0298881530762,1.99294468008281,34.0300016105175,-0.130334014867745,-0.0242065993602965,2.5,-8.14269485045037E-5,-0.0115706381816193,-0.000147435917387615,29.9978504,29.9978504,-4768.71435546875,-4758.966796875,56.8361177758714,20.6611527781373,15.315984,0,0,0,40,4449,29.95725,-4763.84057617188,,,,,,,,,,,,,0,,,,0,,,,,,29.9978504,,,,
,32678335.985,29.9972878,-5890.904296875,-0.0118207682586148,6.17906555824738E-7,1,0.999253354069792,40.0298881530762,1.99341083019197,34.0300016105175,-0.132529963336521,-0.0246173795441539,2.5,-8.22518448302245E-5,-0.011763004411394,-0.000150138724717334,29.9972878,29.9972878,-5898.29248046875,-5883.51611328125,57.0354330482753,20.6588303060608,15.315984,0,0,0,40,4449,29.9621,-5890.904296875,,,,,,,,,,,,,0,,,,0,,,,,,29.9972878,,,,
,32678358.41,29.997818,-7012.90625,-0.0119884575543496,7.24190681323521E-7,1,0.999253354069792,40.0298881530762,1.99344695664486,34.0300016105175,-0.134420586181525,-0.0249847899025981,2.5,-8.40346302731792E-5,-0.0119308454658799,-0.000153673507935083,29.997818,29.997818,-7022.68310546875,-7003.12939453125,56.8666012881214,20.6546690518536,15.315984,0,0,0,40,4449,29.95735,-7012.90625,,,,,,,,,,,,,0,,,,0,,,,,,29.997818,,,,
,32678381.295,29.99706935,-8157.6318359375,-0.0121294804145968,9.10764791342465E-7,1,0.999253354069792,40.0298881530762,1.9937640491445,34.0300016105175,-0.13603287733079,-0.0252929632091268,2.5,-8.49368664396793E-5,-0.0120722414478274,-0.000156223678661868,29.9970627,29.997076,-8162.80126953125,-8152.46240234375,56.8056342636214,20.6511626319397,15.695635,0,0,0,40,4449,29.9568,-8157.6318359375,,,,,,,,,,,,,0,,,,0,,,,,,29.99706935,,,,
,32678405.285,29.9980068,-9357.8349609375,-0.0122649796501545,7.26522248432843E-7,1,0.999253354069792,40.0298881530762,1.99348207353584,34.0300016105175,-0.137549463974657,-0.025560898890046,2.5,-8.38018379868857E-5,-0.012208270788479,-0.000156778654012569,29.9980068,29.9980068,-9362.822265625,-9352.84765625,56.8181403199291,20.6560351735306,15.315984,0,0,0,40,4449,29.9607,-9357.8349609375,,,,,,,,,,,,,0,,,,0,,,,,,29.9980068,,,,
,32678428.14,29.9979362,-10499.7905273438,-0.012383469086678,9.589188508511E-7,1,0.999253354069792,40.0298881530762,1.99371754621937,34.0300016105175,-0.138904899046606,-0.02582383947695,2.5,-8.47358941347563E-5,-0.0123273471768254,-0.000159256689539664,29.9979362,29.9979362,-10507.3720703125,-10492.208984375,57.1003082153714,20.6481022672685,15.315984,0,0,0,40,4449,29.9581,-10499.7905273438,,,,,,,,,,,,,0,,,,0,,,,,,29.9979362,,,,
,32678452.025,29.9978142,-11694.0073242187,-0.0124965991301498,1.24218075565638E-6,1,0.999253354069792,40.0298881530762,1.99427357729414,34.0300016105175,-0.140220745837977,-0.026094163823555,2.5,-8.68511393831659E-5,-0.0124411932834221,-0.000162931408676175,29.9978142,29.9978142,-11701.6083984375,-11686.40625,57.0283983916022,20.6477206413751,15.315984,0,0,0,40,4449,29.96065,-11694.0073242187,,,,,,,,,,,,,0,,,,0,,,,,,29.9978142,,,,
,32678475.015,29.99817755,-12843.3920898438,-0.0125969520707787,9.04700273318971E-7,1,0.999253354069792,40.0298881530762,1.9938124026512,34.0300016105175,-0.141334238071152,-0.0262737124582661,2.5,-8.43304004891509E-5,-0.0125423470633875,-0.000161882762351823,29.9981289,29.9982262,-12850.931640625,-12835.8525390625,56.8548768603329,20.654276089034,15.315984,0,0,0,40,4449,29.96175,-12843.3920898438,,,,,,,,,,,,,0,,,,0.00245,,,,,,29.99817755,,,,
,32678498.765,29.9985828,-14031.0107421875,-0.0126953421898896,8.97584129227279E-7,1,0.999253354069792,40.0298881530762,1.99416961431119,34.0300016105175,-0.142473238194149,-0.0265082470847374,2.5,-8.61004141897636E-5,-0.0126416009622504,-0.000165119306269051,29.9985828,29.9985828,-14040.8818359375,-14021.1396484375,56.8337728903137,20.6426294888161,14.936333,0,0,0,40,4449,29.95865,-14031.0107421875,,,,,,,,,,,,,0,,,,-0.0049,,,,,,29.9985828,,,,
,32678521.355,29.9986095,-15160.05078125,-0.0127850979286692,1.11208792389252E-6,1,0.999253354069792,40.0298881530762,1.99439158895759,34.0300016105175,-0.143511023822365,-0.0266960620083187,2.5,-8.54519471012016E-5,-0.0127322522027104,-0.000165851099214793,29.9986095,29.9986095,-15170.068359375,-15150.033203125,56.7884384361983,20.6392244122954,15.315984,0,0,0,40,4449,29.95745,-15160.05078125,,,,,,,,,,,,,0,,,,-0.0049,,,,,,29.9986095,,,,
,32678544.83,29.9990139,-16331.8203125,-0.0128710054303329,6.93956227597348E-7,1,0.999253354069792,40.0298881530762,1.9946344195785,34.0300016105175,-0.144506657342426,-0.0268857506410052,2.5,-8.55852554530839E-5,-0.0128191610392734,-0.000167367361819606,29.9990139,29.9990139,-16339.2294921875,-16324.4111328125,56.9697762526599,20.6388676092717,14.936333,0,0,0,40,4449,29.9613,-16331.8203125,,,,,,,,,,,,,0,,,,-0.0049,,,,,,29.9990139,,,,
,32678567.44,29.9987469,-17461.375,-0.012950225582716,8.74381333628954E-7,1,0.999253354069792,40.0298881530762,1.99458388566166,34.0300016105175,-0.14540563896566,-0.0270642410627793,2.5,-8.62986752373398E-5,-0.0128993881239431,-0.000169378143761167,29.9987469,29.9987469,-17468.82421875,-17453.92578125,56.8462789466214,20.6473404553923,14.936333,0,0,0,40,4449,29.96135,-17461.375,,,,,,,,,,,,,0,,,,0,,,,,,29.9987469,,,,
,32678590.08,29.9980202,-18593.5302734375,-0.0130232954573143,6.38986525610088E-7,1,0.999253354069792,40.0298881530762,1.99452245349462,34.0300016105175,-0.146239096743529,-0.0272078572726358,2.5,-8.50275059278024E-5,-0.01297353738953,-0.000169364280320819,29.9980202,29.9980202,-18603.767578125,-18583.29296875,56.8783257159099,20.6420350088226,15.315984,0,0,0,40,4449,29.9609,-18593.5302734375,,,,,,,,,,,,,0,,,,0,,,,,,29.9980202,,,,
,32678613.605,29.9990177,-19770.0322265625,-0.0130976604723526,1.19743413055054E-6,1,0.999253354069792,40.0298881530762,1.99486945685001,34.0300016105175,-0.147112363117379,-0.0273844926789711,2.5,-8.59502914157455E-5,-0.0130490518549381,-0.000171564588722827,29.9990177,29.9990177,-19777.60546875,-19762.458984375,57.2581971762561,20.6413648492959,14.936333,0,0,0,40,4449,29.9628,-19770.0322265625,,,,,,,,,,,,,0,,,,0.00245,,,,,,29.9990177,,,,
,32678657.115,29.9975319,-19114.130859375,-0.0130678502603839,1.14197701650984E-6,1,0.999253354069792,40.0298881530762,1.9953116808846,34.0300016105175,-0.146797337830279,-0.0273387173832649,2.5,-8.72916597590237E-5,-0.0130185447968938,-0.000172266429508388,29.9975319,29.9975319,-19116.404296875,-19111.857421875,57.1862873524868,20.6382621660062,15.695635,0,0,0,40,4449,29.9642,-19114.130859375,,,,,,,,,,,,,0,,,,0.00245,,,,,,29.9975319,,,,
,32678680.005,29.9980831,-17974.03515625,-0.0129969066995653,9.67740691293264E-7,1,0.999253354069792,40.0298881530762,1.99455770987348,34.0300016105175,-0.145933301256338,-0.0271715545924433,2.5,-8.70426546748738E-5,-0.0129464958620465,-0.000170777116996025,29.9980831,29.9980831,-17981.45703125,-17966.61328125,56.9002113144483,20.6403910200378,15.315984,0,0,0,40,4449,29.9629,-17974.03515625,,,,,,,,,,,,,0,,,,0,,,,,,29.9980831,,,,
,32678703.655,29.9982052,-16793.345703125,-0.0129167687495169,1.03397161977302E-6,1,0.999253354069792,40.0298881530762,1.99404392854037,34.0300016105175,-0.144984306048343,-0.0269822237566601,2.5,-8.62212900846669E-5,-0.0128652816705321,-0.000168621930080249,29.9982052,29.9982052,-16803.45703125,-16783.234375,56.5445703381983,20.6506958623983,15.315984,0,0,0,40,4449,29.96485,-16793.345703125,,,,,,,,,,,,,0,,,,0.00245,,,,,,29.9982052,,,,
,32678726.485,29.9987583,-15651.6318359375,-0.0128387655193738,8.45592540474653E-7,1,0.999253354069792,40.0298881530762,1.99440381733811,34.0300016105175,-0.144121230356113,-0.0268064255562746,2.5,-8.51900991332222E-5,-0.0127862680000691,-0.00016628474785799,29.9987583,29.9987583,-15664.0498046875,-15639.2138671875,56.8814522299868,20.6477435143764,14.936333,0,0,0,40,4449,29.96065,-15651.6318359375,,,,,,,,,,,,,0,,,,-0.00245,,,,,,29.9987583,,,,
,32678749.39,29.9982166,-14507.5888671875,-0.0127588430344857,1.33454451252835E-6,1,0.999253354069792,40.0298881530762,1.9951136503284,34.0300016105175,-0.143256647911135,-0.0266543382309276,2.5,-8.62132265319151E-5,-0.0127053762062268,-0.00016598075188361,29.9982166,29.9982166,-14509.84765625,-14505.330078125,57.0221453634483,20.6469379660291,15.315984,0,0,0,40,4449,29.9651,-14507.5888671875,,,,,,,,,,,,,0,,,,-0.00245,,,,,,29.9982166,,,,
,32678772.385,29.9973316,-13357.7778320312,-0.0126698995934388,5.82832206077235E-7,1,0.999253354069792,40.0298881530762,1.99437771916756,34.0300016105175,-0.142193114850179,-0.0264588680116966,2.5,-8.66409826118299E-5,-0.0126155296426138,-0.000165013778380123,29.9973316,29.9973316,-13365.1962890625,-13350.359375,56.8040710065829,20.6543869335226,14.556682,0,0,0,40,4449,29.9639,-13357.7778320312,,,,,,,,,,,,,0,,,,0,,,,,,29.9973316,,,,
,32678795.74,29.9977207,-12190.8774414062,-0.0125750304870395,5.62469974802373E-7,1,0.999253354069792,40.0298881530762,1.99473885414546,34.0300016105175,-0.141139432335488,-0.026258416322104,2.5,-8.64512882302059E-5,-0.0125198166697017,-0.000163385758558624,29.9977207,29.9977207,-12205.744140625,-12176.0107421875,57.3676251689484,20.6499278917137,14.936333,0,0,0,40,4449,29.9669,-12190.8774414062,,,,,,,,,,,,,0,,,,0,,,,,,29.9977207,,,,
,32678818.415,29.9986,-11059.1630859375,-0.0124765516010785,7.17640428664348E-7,1,0.999253354069792,40.0298881530762,1.99488797958242,34.0300016105175,-0.140031572429734,-0.0260472347598459,2.5,-8.61607476367428E-5,-0.0124205820833383,-0.000161656105184202,29.9986,29.9986,-11066.6455078125,-11051.6806640625,56.902556200006,20.647486831194,15.315984,0,0,0,40,4449,29.96245,-11059.1630859375,,,,,,,,,,,,,0,,,,0,,,,,,29.9986,,,,
,32678840.415,29.9970798,-9957.30517578125,-0.012375422070056,1.23772506847244E-6,1,0.999253354069792,40.0298881530762,1.99516340163662,34.0300016105175,-0.138902484245304,-0.025836101494677,2.5,-8.61617865766012E-5,-0.012318793776508,-0.000160235984783033,29.9970798,29.9970798,-9962.416015625,-9952.1943359375,56.973684395256,20.6416804328919,15.315984,0,0,0,40,4449,29.9657,-9957.30517578125,,,,,,,,,,,,,0,,,,0.0049,,,,,,29.9970798,,,,
,32678863.455,29.9977932,-8807.146484375,-0.0122579703132832,4.96336634114196E-7,1,0.999253354069792,40.0298881530762,1.99574957944144,34.0300016105175,-0.137611053046281,-0.0255903475072426,2.5,-8.56965225071314E-5,-0.0122007573634004,-0.000158225315275896,29.9977932,29.9977932,-8817.2548828125,-8797.0380859375,57.2261504069676,20.6347432471869,15.315984,0,0,0,40,4449,29.96635,-8807.146484375,,,,,,,,,,,,,0,,,,-0.0049,,,,,,29.9977932,,,,
,32678887.235,29.99706745,-7620.37963867187,-0.0121232866315831,9.46588988483748E-7,1,0.999253354069792,40.0298881530762,1.99554540117316,34.0300016105175,-0.136074924374002,-0.0252949673889943,2.5,-8.47646454459235E-5,-0.0120655965270259,-0.000155639329925941,29.9969788,29.9971561,-7627.92822265625,-7612.8310546875,57.3535558556022,20.6363565004438,15.315984,0,0,0,40,4449,29.96885,-7620.37963867187,,,,,,,,,,,,,0,,,,0.0049,,,,,,29.99706745,,,,
,32678911.395,29.9971924,-6410.74340820312,-0.0119681104030838,5.76145426685159E-7,1,0.999253354069792,40.0298881530762,1.9964878392428,34.0300016105175,-0.134381457475385,-0.0249805592528561,2.5,-8.45657450311268E-5,-0.011910076034551,-0.000153666656500114,29.9971924,29.9971924,-6418.37451171875,-6403.1123046875,57.2253687784484,20.6296914020566,14.936333,0,0,0,40,4449,29.968,-6410.74340820312,,,,,,,,,,,,,0,,,,0.00245,,,,,,29.9971924,,,,
,32678934.895,29.9958553,-5236.388671875,-0.0117914422541464,8.35558266031758E-7,1,0.999253354069792,40.0298881530762,1.99561764574268,34.0300016105175,-0.132329647743806,-0.0246099355738772,2.5,-8.50528566223079E-5,-0.0117332677192261,-0.00015231060821117,29.9958553,29.9958553,-5243.88330078125,-5228.89404296875,57.068261446083,20.6334249181668,14.936333,0,0,0,40,4449,29.9679,-5236.388671875,,,,,,,,,,,,,0,,,,-0.0049,,,,,,29.9958553,,,,
,32678957.65,29.9961243,-4098.931640625,-0.0115681206084071,7.5106678230804E-7,1,0.999253354069792,40.0298881530762,1.99569436726528,34.0300016105175,-0.129818602305728,-0.0241400728322161,2.5,-8.39419765941809E-5,-0.011510155992625,-0.000149168168939668,29.9961243,29.9961243,-4109.10498046875,-4088.75830078125,57.0924919301791,20.6345447391927,14.556682,0,0,0,40,4449,29.97045,-4098.931640625,,,,,,,,,,,,,0,,,,0,,,,,,29.9961243,,,,
,32678979.72,29.9958134,-2994.21765136719,-0.0112687932829182,9.74605948316493E-7,1,0.999253354069792,40.0298881530762,1.99608942148949,34.0300016105175,-0.126475641535549,-0.0235109996277956,2.5,-8.18192779905117E-5,-0.0112115291365877,-0.000144660303054636,29.9958134,29.9958134,-3004.20727539063,-2984.22802734375,57.187068981006,20.6325964381482,15.315984,0,0,0,40,4449,29.96695,-2994.21765136719,,,,,,,,,,,,,0,,,,0,,,,,,29.9958134,,,,
,32679003.03,29.9965076,-1829.35113525391,-0.0106629053790748,2.05586400854531E-6,1,0.999253354069792,40.0298881530762,1.99562992447533,34.0300016105175,-0.119643277616538,-0.0222276082126006,2.5,-7.69124940779802E-5,-0.0106080027364407,-0.000135733118148451,29.9965076,29.9965076,-1839.39001464844,-1819.31225585938,57.0573186468137,20.6379057558224,14.936333,0,0,0,40,4449,29.97475,-1829.35113525391,,,,,,,,,,,,,0,,,,0,,,,,,29.9965076,,,,
,32679026.365,29.9976349,-661.640594482422,-0.00870400429140672,9.34300830623985E-6,1,0.999253354069792,40.0298881530762,1.99620831050907,34.0300016105175,-0.0976877357630537,-0.0181298254175099,2.5,-6.16353549213726E-5,-0.00865867108759404,-0.000109177012794184,29.9976349,29.9976349,-669.069641113281,-654.211547851562,57.0424677049483,20.635260185103,14.556682,0,0,0,40,4449,29.9694,-661.640594482422,,,,,,,,,,,,,0,,,,-0.00245,,,,,,29.9976349,,,,
,32679051.48,29.9975147,592.302673339844,0.0084137853640977,1.33600385079774E-5,1,0.999253354069792,40.0298881530762,1.99691311044946,34.0300016105175,0.0944370835528735,0.0176002901510423,0.25,6.59532289234231E-5,0.00836990531458633,0.000111855092788189,29.9975147,29.9975147,584.959228515625,599.646118164062,57.0127658212176,20.6338234834613,14.936333,0,0,0,40,4449,29.9722,592.302673339844,,,,,,,,,,,,,0,,,,-0.00245,,,,,,29.9975147,,,,
,32679074.97,29.9977016,1763.55090332031,0.0107513013169817,1.91421578932406E-6,1,0.999253354069792,40.0298881530762,1.99609381497385,34.0300016105175,0.120659769987065,0.0224257610355171,2.5,7.83923970866453E-5,0.01069589346332,0.000137655281544107,29.9977016,29.9977016,1751.1015625,1776.00024414062,57.1237570709483,20.6382035184398,15.315984,0,0,0,40,4449,29.9696,1763.55090332031,,,,,,,,,,,,,0,,,,0.00245,,,,,,29.9977016,,,,
,32679097.21,29.997961,2872.94262695313,0.0112481146716935,1.55637383565237E-6,1,0.999253354069792,40.0298881530762,1.99992622355188,34.0300016105175,0.12648022923353,0.0234769725697488,2.5,7.87412739351182E-5,0.0111908911161085,0.000141410314294979,29.997961,29.997961,2867.82275390625,2878.0625,57.3473028274484,20.5967160691913,14.936333,0,0,0,40,4449,29.96925,2872.94262695313,,,,,,,,,,,,,0,,,,0,,,,,,29.997961,,,,
,32679119.205,29.9957523,3971.2646484375,0.0115323128062602,1.01328055518409E-6,1,0.999253354069792,40.0298881530762,2.00025084814996,34.0300016105175,0.129705778485725,0.0240719614117091,2.5,7.97139081459587E-5,0.0114744532739396,0.000144674400664076,29.9957523,29.9957523,3968.89038085937,3973.63891601562,57.3144744296407,20.5893386029799,14.936333,0,0,0,40,4449,29.97035,3971.2646484375,,,,,,,,,,,,,0,,,,0.00245,,,,,,29.9957523,,,,
,32679142.57,29.9965229,5141.75512695313,0.0117472558358311,1.23167924588103E-6,1,0.999253354069792,40.0298881530762,2.00011458704221,34.0300016105175,0.132124114680349,0.0245277150381617,2.5,8.10076479798976E-5,0.0116892544246726,0.000147976089986051,29.9965229,29.9965229,5134.28564453125,5149.224609375,57.6849663477561,20.5977945826676,14.936333,0,0,0,40,4449,29.97625,5141.75512695313,,,,,,,,,,,,,0,,,,-0.00245,,,,,,29.9965229,,,,
,32679164.41,29.99484445,6233.83740234375,0.0119116284170283,1.39424491958679E-6,1,0.999253354069792,40.0298881530762,2.00115694171434,34.0300016105175,0.134048468487584,0.0248936016488733,2.5,8.2127835059461E-5,0.0118537389607267,0.000150797583063596,29.9947834,29.9949055,6228.8095703125,6238.865234375,57.4395349927176,20.5818189804356,14.556682,0,0,0,40,4449,29.977,6233.83740234375,,,,,,,,,,,,,0,,,,0.0049,,,,,,29.99484445,,,,
,32679187.165,29.9945145,7371.0322265625,0.0120592674728332,8.54933128433683E-7,1,0.999253354069792,40.0298881530762,2.00184564059545,34.0300016105175,0.13576868565142,0.0251975685925931,2.5,8.10104709698668E-5,0.0120016857713383,0.000151356013949486,29.9945145,29.9945145,7368.59521484375,7373.46923828125,57.3824761108138,20.5698143963949,15.315984,0,0,0,40,4449,29.9771,7371.0322265625,,,,,,,,,,,,,0,,,,0,,,,,,29.9945145,,,,
,32679209.315,29.9953499,8477.83984375,0.0121862695836571,1.07747946342338E-6,1,0.999253354069792,40.0298881530762,2.002041605295,34.0300016105175,0.137221236796302,0.0254777903408758,2.5,8.19808513068252E-5,0.0121291129005989,0.000153872325067776,29.9953499,29.9953499,8472.8955078125,8482.7841796875,57.4825245612753,20.5653285216695,14.556682,0,0,0,40,4449,29.9776,8477.83984375,,,,,,,,,,,,,0,,,,-0.0049,,,,,,29.9953499,,,,
,32679232.905,29.9939079,9657.7451171875,0.012308566460477,1.22798219210111E-6,1,0.999253354069792,40.0298881530762,2.00236496601446,34.0300016105175,0.138628372546199,0.0257641873138867,2.5,8.41046173614347E-5,0.0122519744619286,0.000157578643428809,29.9939079,29.9939079,9647.6513671875,9667.8388671875,57.7975208545254,20.5665003727275,14.556682,0,0,0,40,4449,29.9778,9657.7451171875,,,,,,,,,,,,,0,,,,0,,,,,,29.9939079,,,,
,32679255.6,29.9951248,10792.5083007813,0.0124194863777453,1.13770792625625E-6,1,0.999253354069792,40.0298881530762,2.00300412059508,34.0300016105175,0.139933835407866,0.0260033017647732,2.5,8.37351715138204E-5,0.0123635344076371,0.000158713928647266,29.9948063,29.9954433,10782.7822265625,10802.234375,57.5348936720638,20.5542943367132,15.315984,0,0,0,40,4449,29.978,10792.5083007813,,,,,,,,,,,,,0,,,,0.0049,,,,,,29.9951248,,,,
,32679280.27,29.9951859,12026.7216796875,0.0125265836307325,1.25551131950429E-6,1,0.999253354069792,40.0298881530762,2.00313705807698,34.0300016105175,0.141164525785063,0.0262295979748463,2.5,8.33522240419938E-5,0.0124714441692465,0.000159894403114474,29.9951859,29.9951859,12021.662109375,12031.78125,57.3996719382368,20.5557526934901,14.556682,0,0,0,40,4449,29.9796,12026.7216796875,,,,,,,,,,,,,0,,,,-0.0049,,,,,,29.9951859,,,,
,32679302.185,29.99511815,13120.8837890625,0.0126144892467412,1.05108730948915E-6,1,0.999253354069792,40.0298881530762,2.00335987150267,34.0300016105175,0.142180524268875,0.026436061423131,2.5,8.46619568627441E-5,0.0125601328476312,0.000162541577945151,29.9949169,29.9953194,13116.0771484375,13125.6904296875,57.4934673605446,20.5545009493624,14.936333,0,0,0,40,4449,29.98005,13120.8837890625,,,,,,,,,,,,,0,,,,0,,,,,,29.99511815,,,,
,32679325.39,29.9952106,14280.5678710938,0.0127049023788022,1.36945875286169E-6,1,0.999253354069792,40.0298881530762,2.00367865099003,34.0300016105175,0.143234095686431,0.026642494477234,2.5,8.53365656470417E-5,0.0126514398398896,0.000164623124533314,29.9952106,29.9952106,14275.5615234375,14285.57421875,57.5622506702369,20.5486055747443,14.556682,0,0,0,40,4449,29.9846,14280.5678710938,,,,,,,,,,,,,0,,,,0.00245,,,,,,29.9952106,,,,
,32679348.78,29.9963551,15449.919921875,0.0127964377117963,1.2311191138304E-6,1,0.999253354069792,40.0298881530762,2.0033406031233,34.0300016105175,0.144261329175609,0.0268133876361872,2.5,8.33932660099243E-5,0.0127439254237759,0.000164103241677023,29.9963551,29.9963551,15440.1982421875,15459.6416015625,57.6005504676792,20.5574494415926,15.315984,0,0,0,40,4449,29.9835,15449.919921875,,,,,,,,,,,,,0,,,,0,,,,,,29.9963551,,,,
,32679373.43,29.9970455,16681.75390625,0.012883205441243,1.0515078412994E-6,1,0.999253354069792,40.0298881530762,2.00345945660433,34.0300016105175,0.145260930520512,0.0270164359174284,2.5,8.45778837041285E-5,0.0128317580111042,0.000166707864392692,29.9970455,29.9970455,16674.259765625,16689.248046875,57.5481813568907,20.5574836736986,14.556682,0,0,0,40,4449,29.9837,16681.75390625,,,,,,,,,,,,,0,,,,0,,,,,,29.9970455,,,,
,32679395.735,29.996273,17796.12109375,0.0129577950286462,1.30046081546056E-6,1,0.999253354069792,40.0298881530762,2.00342408928885,34.0300016105175,0.146114906107246,0.0271724579717503,2.5,8.40637536110741E-5,0.0129073706695323,0.000167450661481047,29.996273,29.996273,17788.724609375,17803.517578125,57.5341120435445,20.558980835048,14.556682,0,0,0,40,4449,29.983,17796.12109375,,,,,,,,,,,,,0,,,,0,,,,,,29.996273,,,,
,32679419.005,29.9959545,18957.9248046875,0.0130321392221911,1.23808120497737E-6,1,0.999253354069792,40.0298881530762,2.00377104380137,34.0300016105175,0.146993075288043,0.0273376950784869,2.5,8.39290636837163E-5,0.0129828291811932,0.000168594155278818,29.9959545,29.9959545,18952.861328125,18962.98828125,57.5309855294676,20.552904650932,15.315984,0,0,0,40,4449,29.98475,18957.9248046875,,,,,,,,,,,,,0,,,,0.00245,,,,,,29.9959545,,,,
,32679462.43,29.9967937,19950.4140625,0.0130941968864149,1.60120271539511E-6,1,0.999253354069792,40.0298881530762,2.00395170302376,34.0300016105175,0.147717111211908,0.0274858432133828,2.5,8.48350713066982E-5,0.0130458552124708,0.000170564540006457,29.9967937,29.9967937,19948.080078125,19952.748046875,57.5856995258138,20.5493609431173,14.556682,0,0,0,40,4449,29.9807,19950.4140625,,,,,,,,,,,,,0,,,,0.0049,,,,,,29.9967937,,,,
,32679485.05,29.9978256,18831.1884765625,0.0130274123903535,1.06434168094989E-6,1,0.999253354069792,40.0298881530762,2.0041451150661,34.0300016105175,0.146961612957103,0.027346794937907,2.5,8.52627253307013E-5,0.0129779599416946,0.000169807294968314,29.9978256,29.9978256,18818.67578125,18843.701171875,57.4207759082561,20.5501398028534,14.936333,0,0,0,40,4449,29.9861,18831.1884765625,,,,,,,,,,,,,0,,,,0.00245,,,,,,29.9978256,,,,
,32679507.335,29.996027,17719.8125,0.0129604288126766,1.10619863896632E-6,1,0.999253354069792,40.0298881530762,2.00418400071325,34.0300016105175,0.146192334555326,0.027210575579548,2.5,8.61654054959745E-5,0.0129098894804826,0.000169508134723431,29.996027,29.996027,17712.20703125,17727.41796875,57.80299225416,20.552425454844,14.936333,0,0,0,40,4449,29.98255,17719.8125,,,,,,,,,,,,,0,,,,0.0049,,,,,,29.996027,,,,
,32679529.57,29.9999104,16609.0185546875,0.0128874891185338,1.31267909918521E-6,1,0.999253354069792,40.0298881530762,2.00401613736144,34.0300016105175,0.145349064374451,0.0270196479724458,2.5,8.35267341581991E-5,0.0128359463260019,0.000165637082126102,29.9999104,29.9999104,16603.974609375,16614.0625,57.8295676238138,20.5535660215381,14.556682,0,0,0,40,4449,29.9836,16609.0185546875,,,,,,,,,,,,,0,,,,0,,,,,,29.9999104,,,,
,32679551.855,29.9975681,15494.4907226562,0.0128119533882339,1.1428933405527E-6,1,0.999253354069792,40.0298881530762,2.00398165223011,34.0300016105175,0.144478386283075,0.0268683001660686,2.5,8.47119855448186E-5,0.0127594203276391,0.000165546617177355,29.9975681,29.9975681,15489.556640625,15499.4248046875,57.5169162161215,20.5555282290836,14.556682,0,0,0,40,4449,29.9834,15494.4907226562,,,,,,,,,,,,,0,,,,0,,,,,,29.9975681,,,,
,32679574.57,29.997364,14360.3374023437,0.0127286839381764,1.25596898719051E-6,1,0.999253354069792,40.0298881530762,2.0038566387369,34.0300016105175,0.14351730861288,0.0266840055990205,2.5,8.44822568697634E-5,0.0126752161315694,0.000163978946377045,29.997364,29.997364,14350.40234375,14370.2724609375,57.1690915250637,20.5512571739896,14.556682,0,0,0,40,4449,29.9844,14360.3374023437,,,,,,,,,,,,,0,,,,-0.00245,,,,,,29.997364,,,,
,32679597.455,29.9971905,13215.6391601562,0.0126435517469246,1.17070716890827E-6,1,0.999253354069792,40.0298881530762,2.00358173967647,34.0300016105175,0.142525795286983,0.0264923008820223,2.5,8.41007573366912E-5,0.012589186239665,0.00016223801858468,29.9971905,29.9971905,13210.509765625,13220.7685546875,57.4567308201407,20.5520217837964,14.556682,0,0,0,40,4449,29.98615,13215.6391601562,,,,,,,,,,,,,0,,,,-0.00245,,,,,,29.9971905,,,,
,32679620.905,29.9968758,12046.3891601562,0.0125515502972098,1.33637054418195E-6,1,0.999253354069792,40.0298881530762,2.00409280962202,34.0300016105175,0.141508774507048,0.0263042475759803,2.5,8.44124973552435E-5,0.0124963274411279,0.000161125661657261,29.9968758,29.9968758,12036.3896484375,12056.388671875,57.7811066556215,20.543557559847,14.556682,0,0,0,40,4449,29.98765,12046.3891601562,,,,,,,,,,,,,0,,,,0,,,,,,29.9968758,,,,
,32679644.86,29.997015,10847.0786132813,0.012449223650354,1.34285772513876E-6,1,0.999253354069792,40.0298881530762,2.00420294703885,34.0300016105175,0.140349135930895,0.026084245522021,2.5,8.42084497128086E-5,0.0123932069901492,0.000159416705699304,29.997015,29.997015,10837.10546875,10857.0517578125,57.5169162161215,20.5449088144364,15.315984,0,0,0,40,4449,29.9889,10847.0786132813,,,,,,,,,,,,,0,,,,0,,,,,,29.997015,,,,
,32679667.655,29.9976063,9707.439453125,0.0123438967599133,1.46309432729897E-6,1,0.999253354069792,40.0298881530762,2.00389199706315,34.0300016105175,0.139127125537066,0.0258626759416179,2.5,8.47980356819857E-5,0.0122872006048634,0.00015852648916493,29.9976063,29.9976063,9692.728515625,9722.150390625,57.8108085393523,20.5503321391731,14.936333,0,0,0,40,4449,29.98655,9707.439453125,,,,,,,,,,,,,0,,,,0,,,,,,29.9976063,,,,
,32679689.79,29.9978485,8599.9306640625,0.0122357514746692,8.39585561494988E-7,1,0.999253354069792,40.0298881530762,2.00440077379495,34.0300016105175,0.137930388085095,0.0256348281261612,2.5,8.43908860199336E-5,0.0121784799967678,0.000156664274253868,29.9978485,29.9978485,8587.298828125,8612.5625,57.7881413122946,20.5410628088274,14.556682,0,0,0,40,4449,29.98745,8599.9306640625,,,,,,,,,,,,,0,,,,0,,,,,,29.9978485,,,,
,32679713.07,29.9969788,7438.1796875,0.0121115463849928,1.29173924580756E-6,1,0.999253354069792,40.0298881530762,2.00427417861054,34.0300016105175,0.136512465789729,0.0253556643851369,2.5,8.30226844077073E-5,0.012053780754495,0.000153725183423397,29.9969788,29.9969788,7428.23388671875,7448.12548828125,57.2222422643714,20.5463801845398,14.936333,0,0,0,40,4449,29.98765,7438.1796875,,,,,,,,,,,,,0,,,,0,,,,,,29.9969788,,,,
,32679736.445,29.9976368,6271.5,0.0119658857412726,1.02442832520169E-6,1,0.999253354069792,40.0298881530762,2.0043493956239,34.0300016105175,0.134864516994729,0.0250454536875147,2.5,8.24875062133896E-5,0.011907782972954,0.000151511308139448,29.9976368,29.9976368,6264.150390625,6278.849609375,57.4575124486599,20.5464367835713,14.556682,0,0,0,40,4449,29.99025,6271.5,,,,,,,,,,,,,0,,,,-0.00245,,,,,,29.9976368,,,,
,32679760.6,29.9966316,5061.8564453125,0.0117931468159752,9.87960199285624E-7,1,0.999253354069792,40.0298881530762,2.0045943764236,34.0300016105175,0.132920687961569,0.0246896234095785,2.5,8.25691519756779E-5,0.0117348616477002,0.00014975109319346,29.9966316,29.9966316,5054.14404296875,5069.56884765625,57.5739750980253,20.5419348154908,15.315984,0,0,0,40,4449,29.9877,5061.8564453125,,,,,,,,,,,,,0,,,,-0.0049,,,,,,29.9966316,,,,
,32679783.25,29.998661,3929.55590820313,0.0115987554728517,1.12271379527393E-6,1,0.999253354069792,40.0298881530762,2.00471557902944,34.0300016105175,0.130730312068395,0.0242646748387495,2.5,8.04012371762383E-5,0.0115405522871878,0.000145727267087123,29.998661,29.998661,3924.552734375,3934.55908203125,57.4958122461022,20.5391778001975,14.936333,0,0,0,40,4449,29.9879,3929.55590820313,,,,,,,,,,,,,0,,,,-0.0049,,,,,,29.998661,,,,
,32679806.195,29.9975262,2782.40576171875,0.0113061768746836,1.18503091512592E-6,1,0.999253354069792,40.0298881530762,2.00464346050325,34.0300016105175,0.127420739513558,0.0236402930455364,2.5,7.82129229498777E-5,0.0112486282830213,0.000141179241130821,29.9975262,29.9975262,2769.92626953125,2794.88525390625,57.505191788333,20.5404449173608,14.556682,0,0,0,40,4449,29.99085,2782.40576171875,,,,,,,,,,,,,0,,,,0,,,,,,29.9975262,,,,
,32679828.43,29.997921,1672.78485107422,0.0108457406260771,1.48182544234476E-6,1,0.999253354069792,40.0298881530762,2.00450052566507,34.0300016105175,0.122212000274842,0.022693191995372,2.5,7.73040672270758E-5,0.0107898222306096,0.000137066041660942,29.997921,29.997921,1665.728515625,1679.84118652344,57.3981086811984,20.5411461079109,14.556682,0,0,0,40,4449,29.9863,1672.78485107422,,,,,,,,,,,,,0,,,,0,,,,,,29.997921,,,,
,32679851.525,29.9979706,517.355285644531,0.00944288299874916,6.13324750323325E-6,1,0.999253354069792,40.0298881530762,2.00467982137501,34.0300016105175,0.106409382260657,0.0197466684570516,2.5,6.67484166327177E-5,0.00939366333893105,0.000118290570245997,29.9979706,29.9979706,509.727111816406,524.983459472656,57.6646440062561,20.5396352913218,14.936333,0,0,0,40,4449,29.9895,517.355285644531,,,,,,,,,,,,,0,,,,-0.00245,,,,,,29.9979706,,,,
,32679861.955,29.9984226,-0.31208735704422,0.00650959045315211,2.46946932499852E-5,1,0.999253354069792,40.0298881530762,2.00479021973749,34.0300016105175,0.0733626599525787,0.0135834606274178,2.5,4.34950986470226E-5,0.00647555493563449,7.89288684340522E-5,29.9984226,29.9984226,-0.319699227809906,-0.304475486278534,57.1307917276214,20.5389479497945,15.315984,0,0,0,40,4417,29.9912,-0.31208735704422,,,,,,,,,,,,,0,,,,-0.00245,,,,,,29.9984226,,,,