File: data/looselyPackedNP/ios-11/ppms/rawdata/PMK18_FCW_100OE.DAT
[Header]
; VSM Data File (default extension .dat)
; Copyright (c) 2003-2013, Quantum Design, Inc. All rights reserved.
TITLE,
FILEOPENTIME,30310672.78,12/18/2018,3:39 am
BYAPP,VSM,2.0,2.0
INFO,PPMS VSM Option Release 1.4.10 Build 1,APPNAME
INFO,Quantum Design Linear Motor Servo Controller,MOTOR_MODULE_NAME
INFO,3101-100 M1,MOTOR_HW_VERSION
INFO,MMC1014,MOTOR_SERIAL_NUMBER
INFO,SRV No X-over 01.03.11,MOTOR_SOFTWARE_VERSION
INFO,Quantum Design VSM Detection Module,VSM_MODULE_NAME
INFO,3101-150 F0,VSM_HW_VERSION
INFO,VSM707,VSM_SERIAL_NUMBER
INFO,VSM No X-over 01.02.05 May 20 2008 13:51:47,VSM_SOFTWARE_VERSION
INFO,704,PREAMP_SERIAL_NUMBER
INFO,822,COIL_SERIAL_NUMBER
INFO,0,MOMENT_UNITS
INFO,Maghemite,SAMPLE_MATERIAL
INFO,Oleate Iron Spheres,SAMPLE_COMMENT
INFO,,SAMPLE_MASS
INFO,,SAMPLE_VOLUME
INFO,,SAMPLE_MOLECULAR_WEIGHT
INFO,,SAMPLE_SIZE
INFO,,SAMPLE_SHAPE
DATATYPE,COMMENT,1
DATATYPE,TIME,2
STARTUPAXIS,X,2
STARTUPAXIS,Y1,5
[Data]
Comment,Time Stamp (sec),Temperature (K),Magnetic Field (Oe),Moment (emu),M. Std. Err. (emu),Transport Action,Averaging Time (sec),Frequency (Hz),Peak Amplitude (mm),Center Position (mm),Coil Signal' (mV),Coil Signal" (mV),Range (mV),M. Quad. Signal (emu),M. Raw' (emu),M. Raw" (emu),Min. Temperature (K),Max. Temperature (K),Min. Field (Oe),Max. Field (Oe),Mass (grams),Motor Lag (deg),Pressure (Torr),VSM Status (code),Motor Status (code),Measure Status (code),Measure Count,PPMS Status (code),System Temp. (K),System Field (Oe),Sample Position (deg),Bridge 1 Resistance (ohms),Bridge 1 Excitation (에),Bridge 2 Resistance (ohms),Bridge 2 Excitation (에),Bridge 3 Resistance (ohms),Bridge 3 Excitation (에),Bridge 4 Resistance (ohms),Bridge 4 Excitation (에),Signal 1 Vin (V),Signal 2 Vin (V),Digital Inputs (code),Drive 1 Iout (mA),Drive 1 Ipower (W),Drive 2 Iout (mA),Drive 2 Ipower (W),Pressure (),Map 20 (),Map 21 (),Map 22 (),Map 23 (),Map 24 (),Map 25 (),Map 26 (),Map 27 (),Map 28 (),Map 29 ()
,30310809.78,10.0151882,99.5634765625,0.00403821436984421,5.4065359127069E-7,1,0.999253354069792,40.0298881530762,1.99768560516251,29.2399991303682,0.0453234646868967,0.00840427925477858,0.25,3.07003812031461E-5,0.00401487831013574,4.99997109977591E-5,10.0151882,10.0151882,99.5634765625,99.5634765625,57.2183341217753,20.6090825138245,12.278775,0,0,0,40,4369,9.9662,99.5634765625,,,,,,,,,,,,,0,,,,0,,,,,,10.0151882,,,,
,30310897.61,12.00634,99.5634765625,0.00403615879705553,4.95509896319823E-7,1,0.999253354069792,40.0298881530762,1.99751140498559,29.2399991303682,0.0452982695931862,0.00838907989516846,0.25,2.97778295382859E-5,0.00401282446871846,4.90723654999734E-5,12.00634,12.00634,99.5634765625,99.5634765625,57.352774227083,20.6146988101642,13.038077,0,0,0,40,4370,12.09295,99.5634765625,,,,,,,,,,,,,0,,,,-0.0049,,,,,,12.00634,,,,
,30310997.905,14.5170031,99.5634765625,0.00403376194129508,5.62921994659515E-7,1,0.999253354069792,40.0298881530762,1.99779956156205,29.2399991303682,0.0452763396072839,0.00839078449552882,0.25,3.02568286150971E-5,0.00401041505181682,4.95367560610142E-5,14.5170031,14.5170031,99.5634765625,99.5634765625,57.495030617583,20.6122366485061,13.038077,0,0,0,40,4370,14.6034,99.5634765625,,,,,,,,,,,,,0,,,,0,,,,,,14.5170031,,,,
,30311099.055,17.0007248,99.5634765625,0.00403162149384074,4.87870941623408E-7,1,0.999253354069792,40.0298881530762,1.99755994985046,29.2399991303682,0.0452469675792871,0.00838434491196025,0.25,3.01549475192675E-5,0.0040082574309761,4.94247684167621E-5,17.0007248,17.0007248,99.5634765625,99.5634765625,57.0831123879483,20.6136416702394,13.417728,0,0,0,40,4370,17.1483,99.5634765625,,,,,,,,,,,,,0,,,,-0.0049,,,,,,17.0007248,,,,
,30311201.265,19.5503445,99.5634765625,0.00403050504052733,4.73055178372185E-7,1,0.999253354069792,40.0298881530762,1.99765474396162,29.2399991303682,0.0452360357849189,0.00838705873403054,0.25,3.04731751777101E-5,0.0040071777533407,4.98174153053257E-5,19.5503445,19.5503445,99.5634765625,99.5634765625,57.068261446083,20.6120710473983,13.797379,0,0,0,40,4370,19.7089,99.5634765625,,,,,,,,,,,,,0,,,,0.00245,,,,,,19.5503445,,,,
,30311301.68,22.01688,99.5634765625,0.00402865853522904,4.88196002127568E-7,1,0.999253354069792,40.0298881530762,1.99730746708265,29.279999434948,0.0452095001220428,0.00838654510929103,0.25,3.05393016168946E-5,0.00400555696690975,5.01747380786988E-5,22.01688,22.01688,99.5634765625,99.5634765625,57.5270773868715,20.6159787809442,13.797379,0,0,0,40,4370,22.23345,99.5634765625,,,,,,,,,,,,,0,,,,0,,,,,,22.01688,,,,
,30311403.01,24.5302982,99.5634765625,0.00402860219649603,4.63050792643693E-7,1,0.999253354069792,40.0298881530762,1.99781082032422,29.279999434948,0.0452243409570952,0.00839032021590698,0.25,3.01010974741484E-5,0.00400592351811569,5.02668652242045E-5,24.5302982,24.5302982,99.5634765625,99.5634765625,57.3535558556022,20.612619270387,13.797379,0,0,0,40,4370,24.79285,99.5634765625,,,,,,,,,,,,,0,,,,0,,,,,,24.5302982,,,,
,30311503.895,27.0426445,99.5634765625,0.00402855312782452,4.37492233253641E-7,1,0.999253354069792,40.0298881530762,1.99774145074421,29.279999434948,0.0452278726543592,0.00840155295684215,0.25,3.02650784307477E-5,0.00400652579897696,5.11803637801796E-5,27.0426445,27.0426445,99.5634765625,99.5634765625,56.9220969129868,20.6124671737767,14.936333,0,0,0,40,4370,27.3408,99.5634765625,,,,,,,,,,,,,0,,,,0,,,,,,27.0426445,,,,
,30311602.765,29.5065994,99.5634765625,0.00402958465507613,6.07475129667586E-7,1,0.999253354069792,40.0298881530762,1.99835149938449,29.279999434948,0.0452616892093529,0.00841423728168051,0.25,2.98940934734046E-5,0.00400844812986963,5.17531027343591E-5,29.5065994,29.5065994,99.5634765625,99.5634765625,57.2605420618137,20.6001904317592,14.936333,0,0,0,40,4370,29.8243,99.5634765625,,,,,,,,,,,,,0,,,,-0.0049,,,,,,29.5065994,,,,
,30311704.905,32.0056114,99.5634765625,0.00403122450949444,4.60929027151009E-7,1,0.999253354069792,40.0298881530762,1.99878634591681,29.2899999767542,0.0453022693286301,0.00842970787306984,0.25,2.94384919557877E-5,0.00401132636613029,5.24687839793407E-5,32.0056114,32.0056114,99.5634765625,99.5634765625,57.3402681707753,20.6004187976305,15.315984,0,0,0,40,4370,32.41,99.5634765625,,,,,,,,,,,,,0,,,,-0.0049,,,,,,32.0056114,,,,
,30311807.155,34.533699,99.5634765625,0.00403258734959585,4.41977890570786E-7,1,0.999253354069792,40.0298881530762,1.998964064206,29.279999434948,0.0453390377361196,0.00843878332196249,0.25,2.83677168730385E-5,0.00401427452060489,5.26985281901405E-5,34.533699,34.533699,99.5634765625,99.5634765625,57.2159892362176,20.5977430282009,14.936333,0,0,0,40,4370,34.9783,99.5634765625,,,,,,,,,,,,,0,,,,-0.00245,,,,,,34.533699,,,,
,30311907.37,37.0413704,99.5634765625,0.00403342949718761,4.78712717407719E-7,1,0.999253354069792,40.0298881530762,1.99916797218924,29.279999434948,0.0453717097569438,0.00846242346449029,0.25,2.85759496214345E-5,0.00401703619013819,5.423749970997E-5,37.0413704,37.0413704,99.5634765625,99.5634765625,57.3152560581599,20.5958021900316,16.075285,0,0,0,40,4370,37.5049,99.5634765625,,,,,,,,,,,,,0,,,,0,,,,,,37.0413704,,,,
,30312009.88,39.559269,99.5634765625,0.00403432041874689,5.44631527222523E-7,1,0.999253354069792,40.0298881530762,1.99933052916082,29.279999434948,0.0454109334480848,0.00847540170951834,0.25,2.77689460107924E-5,0.00402028077905363,5.47658413040852E-5,39.559269,39.559269,99.5634765625,99.5634765625,57.2894623170253,20.5959912808555,15.695635,0,0,0,40,4370,40.09225,99.5634765625,,,,,,,,,,,,,0,,,,-0.00245,,,,,,39.559269,,,,
,30312109.11,42.0344925,99.5634765625,0.00403450519510094,4.80680840936106E-7,1,0.999253354069792,40.0298881530762,1.99987616534179,29.3000005185604,0.0454535186326764,0.00849001151290738,0.25,2.72142691047045E-5,0.00402310180460316,5.53741512639371E-5,42.0344925,42.0344925,99.5634765625,99.5634765625,56.9963516223137,20.5865579132729,15.695635,0,0,0,40,4370,42.61185,99.5634765625,,,,,,,,,,,,,0,,,,0,,,,,,42.0344925,,,,
,30312210.125,44.5268745,99.5634765625,0.00403533715504054,4.76381226381637E-7,1,0.999253354069792,40.0298881530762,1.99940535457694,29.3099991977215,0.0454859652213731,0.00849661604638539,0.25,2.6362496505944E-5,0.00402688634125302,5.54727886453094E-5,44.5268745,44.5268745,99.5634765625,99.5634765625,57.332451885583,20.594773116743,16.454937,0,0,0,40,4370,45.15955,99.5634765625,,,,,,,,,,,,,0,,,,0,,,,,,44.5268745,,,,
,30312312.39,47.01114655,99.5634765625,0.0040346134233488,5.72575321400409E-7,1,0.999253354069792,40.0298881530762,1.9999775035149,29.3099991977215,0.0455261934251349,0.00850650420717633,0.25,2.59642256085567E-5,0.00402938262032882,5.57102164812163E-5,46.980999,47.0412941,99.5634765625,99.5634765625,57.1909771236022,20.5874009568488,16.454937,0,0,0,40,4370,47.76135,99.5634765625,,,,,,,,,,,,,0,,,,0,,,,,,47.01114655,,,,
,30312416.07,49.555809,99.5634765625,0.00403344803147754,5.24770968611331E-7,1,0.999253354069792,40.0298881530762,1.99995616968812,29.3099991977215,0.0455533305339686,0.00849629416498668,0.25,2.44301179373727E-5,0.00403159937017887,5.44337898739061E-5,49.555809,49.555809,99.5634765625,99.5634765625,57.1909771236022,20.5846956177643,17.593889,0,0,0,40,4370,50.41715,99.5634765625,,,,,,,,,,,,,0,,,,-0.00245,,,,,,49.555809,,,,
touchdown = 19.0799999982119 mm,30312524.245,52.15522,99.5634765625,0.00402980859700565,4.86634093242482E-7,1,0.999253354069792,40.0298881530762,2.00007083028128,29.3000005185604,0.0455539814474993,0.00849602530842041,0.25,2.45729273697385E-5,0.00403143065781383,5.43981296605163E-5,52.15522,52.15522,99.5634765625,99.5634765625,57.2222422643714,20.5830388487269,17.214239,0,0,0,40,4374,53.18955,99.5634765625,,,,,,,,,,,,,0,,,,0,,,,,,52.15522,,,,
,30312624.195,54.5325127,99.5634765625,0.00403426724805213,5.53243532632095E-7,1,0.999253354069792,40.0298881530762,1.99968178612422,29.3099991977215,0.0456033492178213,0.0086645676702831,0.25,3.87654492775085E-5,0.00403890685874672,6.81308400117202E-5,54.5325127,54.5325127,99.5634765625,99.5634765625,57.1300100991022,20.5857181635762,18.732843,0,0,0,40,4374,55.80405,99.5634765625,,,,,,,,,,,,,0,,,,-0.00245,,,,,,54.5325127,,,,
,30312728.68,57.0439339,99.5634765625,0.00402720610701337,4.41199910544384E-7,1,0.999253354069792,40.0298881530762,1.99977995943356,29.3099991977215,0.0455599168216431,0.00864994608055527,0.25,3.90197320785476E-5,0.00403477694218575,6.75165782551715E-5,57.0439339,57.0439339,99.5634765625,99.5634765625,57.2793011462753,20.5905740767941,19.871798,0,0,0,40,4374,58.4861,99.5634765625,,,,,,,,,,,,,0,,,,0,,,,,,57.0439339,,,,
,30312830.17,59.5260792,99.5634765625,0.00401911075689915,3.96111195582753E-7,1,0.999253354069792,40.0298881530762,1.99991037434909,29.3000005185604,0.0455060266922284,0.00860353905768671,0.25,3.69035906117129E-5,0.00402921836506574,6.43306570281153E-5,59.4874382,59.5647202,99.5634765625,99.5634765625,57.2652318329291,20.5909927351306,20.631098,0,0,0,40,4374,61.0737,99.5634765625,,,,,,,,,,,,,0,,,,0,,,,,,59.5260792,,,,
,30312939.7,62.1930618,99.5634765625,,,2,,,,29.3099999982119,,,,,,,62.1930618,62.1930618,99.5634765625,99.5634765625,,,21.01075,,,,-99999999,4374,63.8522,99.5634765625,,,,,,,,,,,,,,,,,,,,,,,62.1930618,,,,
,30313032.745,64.5185928,99.5634765625,0.00399300319537588,4.79480035445604E-7,1,0.999253354069792,40.0298881530762,1.97589570403187,29.3000005185604,0.0447557628936234,0.00835525128861726,0.25,2.98894338557168E-5,0.00400717802539926,5.47716063009018E-5,64.5185928,64.5185928,99.5634765625,99.5634765625,57.0502839901407,20.5869132611021,20.631098,0,0,0,40,4374,66.1968,99.5634765625,,,,,,,,,,,,,0,,,,0.0049,,,,,,64.5185928,,,,
,30313132.235,67.0201187,99.5634765625,0.00397964760223719,4.67763012183666E-7,1,0.999253354069792,40.0298881530762,1.97587079182342,29.3000005185604,0.0446257160205834,0.0083157442264985,0.25,2.97058880921673E-5,0.00399535454237815,5.32921209528302E-5,67.0201187,67.0201187,99.5634765625,99.5634765625,57.4254656793715,20.5876443359312,20.251448,0,0,0,40,4374,68.7086,99.5634765625,,,,,,,,,,,,,0,,,,0.00245,,,,,,67.0201187,,,,
,30313234.735,69.5156021,99.5634765625,0.00396369948735643,4.94237474039273E-7,1,0.999253354069792,40.0298881530762,1.97590248989052,29.3000005185604,0.0444700620831754,0.00824478231416304,0.25,2.72194732998519E-5,0.00398072968629249,4.9466120427812E-5,69.5156021,69.5156021,99.5634765625,99.5634765625,57.3754414541407,20.5916932838263,21.01075,0,0,0,40,4374,71.2983,99.5634765625,,,,,,,,,,,,,0,,,,0,,,,,,69.5156021,,,,
,30313336.54,72.0305557,99.5634765625,0.00394657166362274,3.94924753018168E-7,1,0.999253354069792,40.0298881530762,1.9760315534829,29.3000005185604,0.0442957368142722,0.008197841768915,0.25,2.70354831107859E-5,0.00396465860614554,4.80010373202187E-5,72.0305557,72.0305557,99.5634765625,99.5634765625,57.4661103623715,20.5895358913371,21.01075,0,0,0,40,4374,73.86895,99.5634765625,,,,,,,,,,,,,0,,,,-0.0049,,,,,,72.0305557,,,,
,30313435.375,74.5039902,99.5634765625,0.00392768372722042,5.55165158633755E-7,1,0.999253354069792,40.0298881530762,1.99999846999851,29.3099991977215,0.044612756891229,0.0082076584142553,0.25,2.38423096465823E-5,0.00394660113242236,4.3602320720937E-5,74.5039902,74.5039902,99.5634765625,99.5634765625,57.2214606358522,20.5824146837114,20.631098,0,0,0,40,4374,76.3565,99.5634765625,,,,,,,,,,,,,0,,,,0,,,,,,74.5039902,,,,
,30313538.38,77.0145493,99.5634765625,0.00390290417907332,4.98197255054343E-7,1,0.999253354069792,40.0298881530762,2.00022855297054,29.3199997395277,0.0443493059047281,0.00813368876912259,0.25,2.26003019582773E-5,0.00392248741098395,4.11538238013278E-5,77.0145493,77.0145493,99.5634765625,99.5634765625,57.2097362080637,20.593270039595,21.3904,0,0,0,40,4374,78.971,99.5634765625,,,,,,,,,,,,,0,,,,-0.00245,,,,,,77.0145493,,,,
,30313640.415,79.5234375,99.5634765625,0.00387837021624885,5.6670319478567E-7,1,0.999253354069792,40.0298881530762,2.00040778113914,29.3199997395277,0.0440840328710556,0.00806907409809915,0.25,2.20924332008959E-5,0.00389845576033429,3.95357092120456E-5,79.5234375,79.5234375,99.5634765625,99.5634765625,57.4793980471984,20.5808643373309,21.3904,0,0,0,40,4374,81.56065,99.5634765625,,,,,,,,,,,,,0,,,,0.00245,,,,,,79.5234375,,,,
,30313741.11,82.0305862,99.5634765625,0.00385147291912054,4.57208158950143E-7,1,0.999253354069792,40.0298881530762,1.99986263576151,29.3199997395277,0.043776896864417,0.00798678863631543,0.25,2.06240654796697E-5,0.00387191619465305,3.70352470482478E-5,82.0305862,82.0305862,99.5634765625,99.5634765625,57.3652802833907,20.5759267920589,21.3904,0,0,0,40,4374,84.11265,99.5634765625,,,,,,,,,,,,,0,,,,0.00245,,,,,,82.0305862,,,,
,30313845,84.6158981,99.5634765625,0.00382102407836179,4.26593127834434E-7,1,0.999253354069792,40.0298881530762,2.00008954178088,29.3099991977215,0.0434423294800706,0.00791184337162787,0.25,2.01272763818181E-5,0.00384170315691591,3.55559771022152E-5,84.5763931,84.6554031,99.5634765625,99.5634765625,57.3269804859484,20.5687157509624,21.770052,0,0,0,40,4374,86.72135,99.5634765625,,,,,,,,,,,,,0,,,,0,,,,,,84.6158981,,,,
,30313943.735,87.0490112,99.5634765625,0.00379009602345658,4.86093242505093E-7,1,0.999253354069792,40.0298881530762,2.00009152992123,29.3199997395277,0.0430971522050033,0.00783090490255458,0.25,1.91692557209896E-5,0.0038109073123609,3.37238291000899E-5,87.0490112,87.0490112,99.5634765625,99.5634765625,57.3332335141022,20.5739504561722,21.770052,0,0,0,40,4374,89.2055,99.5634765625,,,,,,,,,,,,,0,,,,0,,,,,,87.0490112,,,,
,30314044.61,89.5823822,99.5634765625,0.00375516193558998,3.69262895224387E-7,1,0.999253354069792,40.0298881530762,2.00003895767888,29.3099991977215,0.0427025131295609,0.00775262556327667,0.25,1.91268774874171E-5,0.00377600843673449,3.28523767327116E-5,89.5823822,89.5823822,99.5634765625,99.5634765625,57.2925888311022,20.5644065188594,21.770052,0,0,0,40,4374,91.73165,99.5634765625,,,,,,,,,,,,,0,,,,-0.00245,,,,,,89.5823822,,,,
,30314143.98,92.0442963,99.5634765625,0.00371963859473193,4.87879353240388E-7,1,0.999253354069792,40.0298881530762,2.00037754703636,29.3199997395277,0.0423090205124087,0.00767090875104986,0.25,1.86979191949073E-5,0.00374045718641248,3.16632724718053E-5,92.0442963,92.0442963,99.5634765625,99.5634765625,57.7224845166792,20.5556300028204,21.770052,0,0,0,40,4374,94.2204,99.5634765625,,,,,,,,,,,,,0,,,,-0.00245,,,,,,92.0442963,,,,
,30314242.67,94.5568619,99.5634765625,0.0036823160727701,5.09088172637226E-7,1,0.999253354069792,40.0298881530762,2.00071922697502,29.3199997395277,0.0418930301089443,0.00759283501886466,0.25,1.88537628686782E-5,0.00370303753880745,3.11195463408302E-5,94.5568619,94.5568619,99.5634765625,99.5634765625,57.3129111726022,20.5453673005873,22.149702,0,0,0,40,4374,96.6829,99.5634765625,,,,,,,,,,,,,0,,,,0.00245,,,,,,94.5568619,,,,
,30314345.14,97.0322876,99.5634765625,0.00364354355687298,5.05185851181657E-7,1,0.999253354069792,40.0298881530762,2.0005452050592,29.3199997395277,0.0414518915570516,0.00749845877452069,0.25,1.79735722809047E-5,0.00366413487703239,2.95581037862707E-5,97.0322876,97.0322876,99.5634765625,99.5634765625,57.3770047111791,20.5479261943679,22.149702,0,0,0,40,4374,99.2597,99.5634765625,,,,,,,,,,,,,0,,,,0.0049,,,,,,97.0322876,,,,
,30314444.345,99.5107269,99.5634765625,0.00360273367367102,4.00307601302809E-7,1,0.999253354069792,40.0298881530762,2.00082575634881,29.3099991977215,0.040994843095953,0.00740814860157834,0.25,1.76079933969422E-5,0.00362313641953326,2.85741504926394E-5,99.5107269,99.5107269,99.5634765625,99.5634765625,57.4457880208715,20.5504032922737,22.149702,0,0,0,40,4374,101.7585,99.5634765625,,,,,,,,,,,,,0,,,,0,,,,,,99.5107269,,,,
,30314543.6,102.0205917,99.5634765625,0.00356184100307133,4.87677229169821E-7,1,0.999253354069792,40.0298881530762,2.00100391665704,29.3099991977215,0.0405346409203822,0.00731573632780784,0.25,1.70676236471806E-5,0.00358202247247152,2.74583002630509E-5,102.0205917,102.0205917,99.5634765625,99.5634765625,57.4793980471984,20.5403893761985,22.149702,0,0,0,40,4374,104.2639,99.5634765625,,,,,,,,,,,,,0,,,,0,,,,,,102.0205917,,,,
touchdown = 19.0900005400181 mm,30314643.055,104.4542389,99.5634765625,0.00351833021785287,5.08314628022494E-7,1,0.999253354069792,40.0298881530762,2.00089182645606,29.3099991977215,0.0400400288617755,0.00720979602890603,0.25,1.58491501177398E-5,0.00353825643121817,2.56958144460905E-5,104.4542389,104.4542389,99.5634765625,99.5634765625,57.1753445532176,20.5508405626796,22.909004,0,0,0,40,4374,106.7633,99.5634765625,,,,,,,,,,,,,0,,,,0.0049,,,,,,104.4542389,,,,
,30314725.655,106.5076904,99.5634765625,0.00348388782307456,4.9437322600612E-7,1,0.999253354069792,40.0298881530762,2.00084609277389,29.3099991977215,0.0396465532307273,0.00714074329881172,0.25,1.61624903357376E-5,0.00350358879280413,2.55979850102288E-5,106.5076904,106.5076904,99.5634765625,99.5634765625,57.3394865422561,20.5594524759406,22.529354,0,0,0,40,4374,108.84355,99.5634765625,,,,,,,,,,,,,0,,,,0,,,,,,106.5076904,,,,
,30314829.36,109.1201324,99.5634765625,0.00343853426078856,4.76263349383284E-7,1,0.999253354069792,40.0298881530762,2.00130947898883,29.3099991977215,0.0391404726387483,0.00703746951175056,0.25,1.52865011098572E-5,0.00345792272882451,2.42268077838556E-5,109.1201324,109.1201324,99.5634765625,99.5634765625,57.1714364106214,20.5681639832144,22.909004,0,0,0,40,4374,111.45825,99.5634765625,,,,,,,,,,,,,0,,,,0,,,,,,109.1201324,,,,
,30314928.82,111.5416336,99.5634765625,0.00339586862231196,5.20277095049107E-7,1,0.999253354069792,40.0298881530762,2.0010459084229,29.3099991977215,0.038648401713328,0.0069536479704595,0.25,1.58144335003816E-5,0.0034149479246543,2.43239887175155E-5,111.5416336,111.5416336,99.5634765625,99.5634765625,57.5231692442753,20.5561710613492,22.909004,0,0,0,40,4374,113.9558,99.5634765625,,,,,,,,,,,,,0,,,,0,,,,,,111.5416336,,,,
,30315028.605,114.0399704,99.5634765625,0.00335261811657771,3.86079398814894E-7,1,0.999253354069792,40.0298881530762,2.00145113605622,29.3099991977215,0.0381645609612656,0.00685476914718579,0.25,1.49053213987145E-5,0.00337136975686223,2.30015749024993E-5,114.0052719,114.0746689,99.5634765625,99.5634765625,57.5528711280061,20.5581425571165,23.288654,0,0,0,40,4374,116.47215,99.5634765625,,,,,,,,,,,,,0,,,,0,,,,,,114.0399704,,,,
,30315108.875,116.0547485,99.5634765625,0.00331929405363338,5.35035670065101E-7,1,0.999253354069792,40.0298881530762,2.00121139197208,29.3099991977215,0.0377807150253629,0.00678154054925553,0.25,1.46147266769894E-5,0.00333777979283582,2.24055867090457E-5,116.0547485,116.0547485,99.5634765625,99.5634765625,57.3559007411599,20.5407860698532,22.529354,0,0,0,40,4374,118.483,99.5634765625,,,,,,,,,,,,,0,,,,-0.0049,,,,,,116.0547485,,,,
,30315208.25,118.5018616,99.5634765625,0.00327799845219086,4.72103824428132E-7,1,0.999253354069792,40.0298881530762,2.00101493239281,29.3000005185604,0.0373062144911461,0.00669508074808802,0.25,1.45807045211166E-5,0.00329614920455126,2.20158631349926E-5,118.5018616,118.5018616,99.5634765625,99.5634765625,57.4184310226984,20.5518903795054,22.529354,0,0,0,40,4374,120.98525,99.5634765625,,,,,,,,,,,,,0,,,,-0.00245,,,,,,118.5018616,,,,
,30315309.61,121.0023041,99.5634765625,0.00323146105422914,4.57689965201579E-7,1,0.999253354069792,40.0298881530762,2.00077457160954,29.3000005185604,0.0367730739224933,0.00658737721734226,0.25,1.35919467490869E-5,0.0032492387248742,2.06731020393852E-5,121.0023041,121.0023041,99.5634765625,99.5634765625,57.4301554504868,20.5588133147823,23.668306,0,0,0,40,4374,123.53235,99.5634765625,,,,,,,,,,,,,0,,,,0,,,,,,121.0023041,,,,
,30315409.985,123.5152664,99.5634765625,0.00318567337719388,4.19988173899222E-7,1,0.999253354069792,40.0298881530762,2.00092338137918,29.3000005185604,0.0362527075572327,0.00649675610983345,0.25,1.38411566954506E-5,0.00320307065456321,2.06015320709925E-5,123.5152664,123.5152664,99.5634765625,99.5634765625,57.4692368764484,20.5591127505172,23.668306,0,0,0,40,4374,126.0461,99.5634765625,,,,,,,,,,,,,0,,,,0,,,,,,123.5152664,,,,
,30315511.145,126.0441513,99.5634765625,0.00313919516212348,3.79415435949411E-7,1,0.999253354069792,40.0298881530762,2.00105011343983,29.3000005185604,0.0357265868228932,0.00638961509814723,0.25,1.27507894034165E-5,0.00315620491154833,1.91995660927284E-5,126.0441513,126.0441513,99.5634765625,99.5634765625,57.159711982833,20.5467593152375,23.288654,0,0,0,40,4374,128.5814,99.5634765625,,,,,,,,,,,,,0,,,,0,,,,,,126.0441513,,,,
,30315610.36,128.5395966,99.5634765625,0.00309416977149226,3.67487482230794E-7,1,0.999253354069792,40.0298881530762,2.00136539030921,29.3000005185604,0.0352190375198585,0.0062919162470868,0.25,1.21667883372091E-5,0.00311079626839482,1.83306033391491E-5,128.5395966,128.5395966,99.5634765625,99.5634765625,57.3824761108138,20.5557955733982,22.909004,0,0,0,40,4374,131.081,99.5634765625,,,,,,,,,,,,,0,,,,-0.00245,,,,,,128.5395966,,,,
,30315711.995,131.0530853,99.5634765625,0.00304810509364436,5.18951201966002E-7,1,0.999253354069792,40.0298881530762,2.00119864530268,29.3000005185604,0.0346901247192212,0.0061984527642027,0.25,1.22514721932759E-5,0.00306433771033661,1.81447862977909E-5,131.0530853,131.0530853,99.5634765625,99.5634765625,57.4825245612753,20.5556429561349,23.288654,0,0,0,40,4374,133.63115,99.5634765625,,,,,,,,,,,,,0,,,,0,,,,,,131.0530853,,,,
,30315811.155,133.5032196,99.5634765625,0.00297253203179704,4.13104123113616E-7,1,0.999253354069792,40.0298881530762,2.00160810717242,29.3000005185604,0.0338359210591563,0.00604034275758074,0.25,1.16411069422351E-5,0.00298821757842547,1.72250045078486E-5,133.5032196,133.5032196,99.5634765625,99.5634765625,57.5364569291022,20.540069401563,24.047956,0,0,0,40,4374,136.1187,99.5634765625,,,,,,,,,,,,,0,,,,0,,,,,,133.5032196,,,,
,30315907.735,136.0437775,99.5634765625,0.00274235474247898,5.2168097284507E-7,1,0.999253354069792,40.0298881530762,2.00166477698545,29.279999434948,0.0312144547963623,0.00557565231484298,0.25,1.11522540386851E-5,0.00275667710549704,1.61719320151591E-5,136.0437775,136.0437775,99.5634765625,99.5634765625,57.4231207938138,20.5354898308328,23.288654,0,0,0,40,4374,138.4781,99.5634765625,,,,,,,,,,,,,0,,,,-0.0049,,,,,,136.0437775,,,,
,30316011.61,138.5286865,99.5634765625,0.00275301560032219,3.82437808322425E-7,1,0.999253354069792,40.0298881530762,2.00150877591558,29.2899999767542,0.0313325029256282,0.00559270854393795,0.25,1.09946382436959E-5,0.00276724860858802,1.58890099935388E-5,138.5286865,138.5286865,99.5634765625,99.5634765625,57.3684067974676,20.5428967976018,23.288654,0,0,0,40,4374,141.1472,99.5634765625,,,,,,,,,,,,,0,,,,0.0049,,,,,,138.5286865,,,,
,30316112.825,141.0247955,99.5634765625,0.00271509375797646,4.61962970415784E-7,1,0.999253354069792,40.0298881530762,2.00146765740156,29.279999434948,0.0309009695569677,0.00550161275055232,0.25,9.77106172487804E-6,0.00272898156752001,1.44650288432792E-5,141.0247955,141.0247955,99.5634765625,99.5634765625,57.3996719382368,20.5471754442437,23.288654,0,0,0,40,4374,143.6859,99.5634765625,,,,,,,,,,,,,0,,,,0,,,,,,141.0247955,,,,
,30316213.87,143.5598602,99.5634765625,0.00267704655820151,4.04527106935008E-7,1,0.999253354069792,40.0298881530762,2.0011613387897,29.279999434948,0.0304617386491682,0.00542333980171253,0.25,9.74579524395815E-6,0.00269058325362407,1.42553146298859E-5,143.5598602,143.5598602,99.5634765625,99.5634765625,57.2636685758907,20.5533387789959,24.047956,0,0,0,40,4374,146.22845,99.5634765625,,,,,,,,,,,,,0,,,,-0.0049,,,,,,143.5598602,,,,
touchdown = 19.0699994564056 mm,30316319.18,146.1940918,99.5634765625,0.00263636671117089,4.08691739302234E-7,1,0.999253354069792,40.0298881530762,2.00083950428167,29.279999434948,0.0299929863816213,0.00533630105704599,0.25,9.40674238855524E-6,0.00264953351933041,1.37310051175974E-5,146.1940918,146.1940918,99.5634765625,99.5634765625,57.3519925985638,20.5668315708098,24.047956,0,0,0,40,4374,148.8742,99.5634765625,,,,,,,,,,,,,0,,,,-0.0049,,,,,,146.1940918,,,,
,30316411.75,148.5010376,99.5634765625,0.00260326613795771,4.78518302035074E-7,1,0.999253354069792,40.0298881530762,2.00137121404427,29.2899999767542,0.0296233725549561,0.00526400828223675,0.25,8.82586650386808E-6,0.00261612246945354,1.29986849099985E-5,148.5010376,148.5010376,99.5634765625,99.5634765625,57.241001348833,20.5675700523389,24.047956,0,0,0,40,4374,151.1835,99.5634765625,,,,,,,,,,,,,0,,,,-0.0049,,,,,,148.5010376,,,,
,30316514.895,151.0527954,99.5634765625,0.00256661130748516,3.6638915532315E-7,1,0.999253354069792,40.0298881530762,2.00146226922396,29.279999434948,0.0292050209363895,0.00519364057908204,0.25,9.13840775398961E-6,0.00257912345830248,1.31549227105852E-5,151.0527954,151.0527954,99.5634765625,99.5634765625,57.2472543769868,20.5547646964969,24.047956,0,0,0,40,4374,153.7688,99.5634765625,,,,,,,,,,,,,0,,,,0,,,,,,151.0527954,,,,
,30316614.685,153.5596008,99.5634765625,0.00253030768732801,3.58863982673495E-7,1,0.999253354069792,40.0298881530762,2.0017188603096,29.2899999767542,0.0287945254358817,0.00511530595699529,0.25,8.64416087639989E-6,0.00254248233291596,1.25114121919188E-5,153.5596008,153.5596008,99.5634765625,99.5634765625,57.2972786022176,20.5566734181536,24.047956,0,0,0,40,4374,156.2754,99.5634765625,,,,,,,,,,,,,0,,,,-0.00245,,,,,,153.5596008,,,,
,30316720.47,156.15979,99.5634765625,,,2,,,,29.2900007772446,,,,,,,156.15979,156.15979,99.5634765625,99.5634765625,,,24.427608,,,,-99999999,4374,158.9228,99.5634765625,,,,,,,,,,,,,,,,,,,,,,,156.15979,,,,
,30316814.915,158.5539322,99.5634765625,0.00246017048895549,4.09679032827006E-7,1,0.999253354069792,40.0298881530762,2.00247276309211,29.279999434948,0.0280043890033853,0.00496548588887522,0.25,7.7611874141425E-6,0.0024716874075771,1.1354125388873E-5,158.5285187,158.5793457,99.5634765625,99.5634765625,57.3152560581599,20.5494402403446,24.427608,0,0,0,40,4374,161.2853,99.5634765625,,,,,,,,,,,,,0,,,,0,,,,,,158.5539322,,,,
,30316912.55,161.0059357,99.5634765625,0.00242753344383309,3.35350188099782E-7,1,0.999253354069792,40.0298881530762,2.00234632019198,29.279999434948,0.0276294270497817,0.00489884575359804,0.25,7.71765353935718E-6,0.00243873761815538,1.11894779965871E-5,161.0059357,161.0059357,99.5634765625,99.5634765625,57.5427099572561,20.5559094785895,24.427608,0,0,0,40,4374,163.73065,99.5634765625,,,,,,,,,,,,,0,,,,0.00245,,,,,,161.0059357,,,,
,30317013.195,163.5012665,99.5634765625,0.0023937180412505,4.00590929763065E-7,1,0.999253354069792,40.0298881530762,2.00180433402643,29.2899999767542,0.0272355454762585,0.00482973824390086,0.25,7.74272896282177E-6,0.00240460305612559,1.10953321991031E-5,163.5012665,163.5012665,99.5634765625,99.5634765625,57.5005020172176,20.5538392305613,24.427608,0,0,0,40,4374,166.24405,99.5634765625,,,,,,,,,,,,,0,,,,-0.00245,,,,,,163.5012665,,,,
,30317112.87,166.0054932,99.5634765625,0.00236154360072064,4.33480108344562E-7,1,0.999253354069792,40.0298881530762,2.00250078756914,29.279999434948,0.0268767917119959,0.00476455521486934,0.25,7.57134992696333E-6,0.00237211848191153,1.08115706803389E-5,166.0054932,166.0054932,99.5634765625,99.5634765625,57.820188081583,20.5452821882282,24.807261,0,0,0,40,4374,168.74015,99.5634765625,,,,,,,,,,,,,0,,,,0,,,,,,166.0054932,,,,
,30317215.875,168.5587616,99.5634765625,0.00232944300109693,3.32952707596356E-7,1,0.999253354069792,40.0298881530762,1.99176283907871,29.279999434948,0.0263751687969251,0.004667952758187,0.25,6.87527291213256E-6,0.00233970779887866,1.00034701037544E-5,168.5587616,168.5587616,99.5634765625,99.5634765625,57.4160861371407,20.5580383714563,24.807261,0,0,0,40,4374,171.31885,99.5634765625,,,,,,,,,,,,,0,,,,0,,,,,,168.5587616,,,,
,30317312.97,171.0205383,99.5634765625,0.00230286324822621,3.86620843350735E-7,1,0.999253354069792,40.0298881530762,1.99190925410774,29.279999434948,0.0260736578158005,0.00461794894108669,0.25,7.14185925958666E-6,0.00231284870913994,1.01774946212898E-5,171.0205383,171.0205383,99.5634765625,99.5634765625,57.4285921934484,20.5464835294774,24.807261,0,0,0,40,4374,173.7494,99.5634765625,,,,,,,,,,,,,0,,,,0,,,,,,171.0205383,,,,
,30317414.595,173.5480652,99.5634765625,0.00225511405379645,4.16518668667876E-7,1,0.999253354069792,40.0298881530762,1.9917390402733,29.279999434948,0.0255293649086109,0.00451991444514943,0.25,6.91018045410167E-6,0.00226472802154018,9.82520569160703E-6,173.5480652,173.5480652,99.5634765625,99.5634765625,57.5630322987561,20.5601776676106,24.427608,0,0,0,40,4374,176.2879,99.5634765625,,,,,,,,,,,,,0,,,,0.0049,,,,,,173.5480652,,,,
,30317514.9,176.0401611,99.5634765625,0.00218059434188049,4.18445037689464E-7,1,0.999253354069792,40.0298881530762,1.99185517043673,29.279999434948,0.0246858086581269,0.00436776191151671,0.25,6.49328340195469E-6,0.00218973201514519,9.25876747729962E-6,176.0401611,176.0401611,99.5634765625,99.5634765625,57.2089545795445,20.558977818382,25.186911,0,0,0,40,4374,178.7892,99.5634765625,,,,,,,,,,,,,0,,,,0.0049,,,,,,176.0401611,,,,
,30317592.6,178.0004425,99.5634765625,0.00210956842739468,4.39274665536419E-7,1,0.999253354069792,40.0298881530762,1.99144429837877,29.279999434948,0.0238755171129415,0.00422527122229007,0.25,6.39408420026465E-6,0.00211828606711214,9.03216932195479E-6,178.0004425,178.0004425,99.5634765625,99.5634765625,57.4528226775445,20.5546494689639,24.807261,0,0,0,40,4374,180.7193,99.5634765625,,,,,,,,,,,,,0,,,,0,,,,,,178.0004425,,,,
,30317695.165,180.51002505,99.5634765625,0.00208938340618951,3.54585302577754E-7,1,0.999253354069792,40.0298881530762,1.99191686754653,29.2700007557869,0.0236498015006652,0.00419044975888921,0.25,6.8199234139198E-6,0.00209786093289468,9.38576112105139E-6,180.4798279,180.5402222,99.5634765625,99.5634765625,57.1722180391407,20.5681015316663,24.807261,0,0,0,40,4374,183.33775,99.5634765625,,,,,,,,,,,,,0,,,,0,,,,,,180.51002505,,,,
,30317796.09,183.0726776,99.5634765625,0.00168029257509507,6.22066186181258E-7,1,0.999253354069792,40.0298881530762,1.99191132705593,29.2700007557869,0.0181622290134416,0.00829226764492256,0.25,0.000440198871187153,0.00168646166545443,0.000443957402784554,183.0726776,183.0726776,99.5634765625,99.5634765625,57.5622506702369,20.5630303630355,24.427608,0,0,0,40,4374,185.8798,99.5634765625,,,,,,,,,,,,,0,,,,-0.00245,,,,,,183.0726776,,,,
,30317894.905,185.5424805,99.5634765625,0.00145925922808025,1.870423110181E-5,1,0.999253354069792,40.0298881530762,1.99179969484339,29.279999434948,0.0157785748712552,0.00715779223091962,0.25,0.00037854548046461,0.00146451883783157,0.000381737060552093,185.5149689,185.5699921,99.5634765625,99.5634765625,57.403580080833,20.5698168175228,24.427608,0,0,0,40,4374,188.30635,99.5634765625,,,,,,,,,,,,,0,,,,-0.0049,,,,,,185.5424805,,,,
,30317993.87,188.01771545,99.5634765625,0.00136006787493165,2.74474999675712E-5,1,0.999253354069792,40.0298881530762,1.99000587220927,29.2700007557869,0.0147280200971491,0.0064598037171008,0.25,0.00033470018578125,0.00136489413600483,0.000337551891059608,187.9920349,188.043396,99.5634765625,99.5634765625,57.6107116384292,20.5749125203494,24.807261,0,0,0,40,4374,190.77825,99.5634765625,,,,,,,,,,,,,0,,,,0,,,,,,188.01771545,,,,
,30318095.795,190.5559082,99.5634765625,0.00129604394860512,3.45375357462195E-5,1,0.999253354069792,40.0298881530762,1.9906046214639,29.2700007557869,0.0140314472289284,0.00619306865323898,0.25,0.000322156328868778,0.0013005434693613,0.000324835315550412,190.5559082,190.5559082,99.5634765625,99.5634765625,57.6193095521407,20.5667026986021,24.427608,0,0,0,40,4374,193.3439,99.5634765625,,,,,,,,,,,,,0,,,,0,,,,,,190.5559082,,,,
,30318195.85,193.0363922,99.5634765625,0.00121792156720303,3.30539236761014E-5,1,0.999253354069792,40.0298881530762,1.99026791672752,29.2700007557869,0.0131483894433219,0.00601518828056382,0.25,0.000320157027631379,0.00122204141621105,0.000322692464673766,193.0363922,193.0363922,99.5634765625,99.5634765625,57.3254172289099,20.5611487253691,25.186911,0,0,0,40,4374,195.8599,99.5634765625,,,,,,,,,,,,,0,,,,0,,,,,,193.0363922,,,,
,30318296.535,195.551178,99.5634765625,0.00112941906674024,2.74871711786215E-5,1,0.999253354069792,40.0298881530762,1.99060124048395,29.2600002139807,0.0121237790943883,0.00598269788492393,0.25,0.000332636155480363,0.00113311592208707,0.000335071963861729,195.551178,195.551178,99.5634765625,99.5634765625,57.5200427301984,20.5505947881155,25.186911,0,0,0,40,4374,198.39185,99.5634765625,,,,,,,,,,,,,0,,,,0,,,,,,195.551178,,,,
touchdown = 19.0399996936321 mm,30318406.905,198.3114014,99.5634765625,0.00105910533245786,2.42065638273286E-5,1,0.999253354069792,40.0298881530762,1.99091751299219,29.2600002139807,0.011296600596548,0.00603199702809503,0.25,0.000349192224476582,0.00106244464998166,0.000351559506725678,198.3114014,198.3114014,99.5634765625,99.5634765625,57.6161830380638,20.5536657526033,25.186911,0,0,0,40,4374,201.16885,99.5634765625,,,,,,,,,,,,,0,,,,-0.0049,,,,,,198.3114014,,,,
,30318495.625,200.5240326,99.5634765625,0.00100911435796853,2.51381066600102E-5,1,0.999253354069792,40.0298881530762,1.99137729520093,29.2600002139807,0.0106882139701449,0.00619059902313779,0.25,0.000371824773613474,0.00101218760284669,0.000374176383011562,200.5240326,200.5240326,99.5634765625,99.5634765625,57.3449579418907,20.5525169869249,25.186911,0,0,0,40,4374,203.3686,99.5634765625,,,,,,,,,,,,,0,,,,0.0049,,,,,,200.5240326,,,,
,30318596.625,203.0123444,99.5634765625,0.0009663279480897,2.4502500054666E-5,1,0.999253354069792,40.0298881530762,1.99129583260601,29.2700007557869,0.0101556838260938,0.00637772101042442,0.25,0.000395873477982431,0.000969157278463673,0.00039821467496539,203.0123444,203.0123444,99.5634765625,99.5634765625,57.6333788654869,20.5460787287773,24.807261,0,0,0,40,4374,205.8952,99.5634765625,,,,,,,,,,,,,0,,,,0.00245,,,,,,203.0123444,,,,
,30318694.85,205.5074615,99.5634765625,0.000908992759113597,1.02377960303327E-5,1,0.999253354069792,40.0298881530762,1.9921010480237,29.2600002139807,0.00952841384142309,0.00616057018746539,0.25,0.0003864843434667,0.000911571543854166,0.000388688567925375,205.5074615,205.5074615,99.5634765625,99.5634765625,57.4629838482945,20.5212696991633,24.807261,0,0,0,40,4374,208.36055,99.5634765625,,,,,,,,,,,,,0,,,,-0.0049,,,,,,205.5074615,,,,
,30318809.58,208.3158722,99.5634765625,,,2,,,,29.2599991518259,,,,,,,208.3158722,208.3158722,99.5634765625,99.5634765625,,,25.186911,,,,-99999999,4374,211.2378,99.5634765625,,,,,,,,,,,,,,,,,,,,,,,208.3158722,,,,
,30318894.665,210.5059204,99.5634765625,0.000841883692868303,2.28534649680925E-5,1,0.999253354069792,40.0298881530762,1.97983803635084,29.2399991303682,0.00866329108697413,0.00629596494906301,0.25,0.000413504700523753,0.00084408877647498,0.000415635105766055,210.5059204,210.5059204,99.5634765625,99.5634765625,57.2417829773522,20.5407295518449,25.946213,0,0,0,40,4374,213.3653,99.5634765625,,,,,,,,,,,,,0,,,,-0.0049,,,,,,210.5059204,,,,
,30318996.775,213.0248718,99.5634765625,0.000852412329324934,2.77169697253932E-5,1,0.999253354069792,40.0298881530762,1.98003782886983,29.2399991303682,0.00873031143946799,0.00661390317659961,0.25,0.000439942528578677,0.000854558892690172,0.000442116555538674,213.0248718,213.0248718,99.5634765625,99.5634765625,57.3050948874099,20.5291297334367,25.566563,0,0,0,40,4374,215.92615,99.5634765625,,,,,,,,,,,,,0,,,,0,,,,,,213.0248718,,,,
,30319098.78,215.551651,99.5634765625,0.000834390819856481,3.64137363352957E-5,1,0.999253354069792,40.0298881530762,1.98065356840652,29.2399991303682,0.00856282065784724,0.0063879252578589,0.25,0.000422873320338199,0.000836435329813511,0.000424930407408205,215.551651,215.551651,99.5634765625,99.5634765625,57.2793011462753,20.5300361349726,25.566563,0,0,0,40,4374,218.4845,99.5634765625,,,,,,,,,,,,,0,,,,0,,,,,,215.551651,,,,
,30319197.48,218.0234528,99.5634765625,0.000799865238600131,2.50124410752474E-5,1,0.999253354069792,40.0298881530762,1.98009997538843,29.2399991303682,0.00815758906114836,0.00639864630123735,0.25,0.000430027459880718,0.00080174054536661,0.000432025686862508,218.0234528,218.0234528,99.5634765625,99.5634765625,57.3785679682176,20.5363996229953,25.946213,0,0,0,40,4374,220.95965,99.5634765625,,,,,,,,,,,,,0,,,,-0.00245,,,,,,218.0234528,,,,
,30319297.375,220.52257535,99.5634765625,0.000797797389519046,2.83606483770086E-5,1,0.999253354069792,40.0298881530762,1.99236500580602,29.2399991303682,0.00799995049358158,0.00747985269939134,0.25,0.000522662465270302,0.000799517435580177,0.000524869221348024,220.4916992,220.5534515,99.5634765625,99.5634765625,57.2832092888714,20.5332921979071,25.566563,0,0,0,40,4374,223.46125,99.5634765625,,,,,,,,,,,,,0,,,,0,,,,,,220.52257535,,,,
,30319398.03,223.0311737,99.5634765625,0.000816456486828078,7.75847249123739E-6,1,0.999253354069792,40.0298881530762,1.99328246519572,29.2399991303682,0.00802542476028888,0.00860609648706887,0.25,0.000618708430315515,0.000818075881975914,0.000621136473346204,223.0311737,223.0311737,99.5634765625,99.5634765625,57.3981086811984,20.5355024499085,25.186911,0,0,0,40,4374,225.97605,99.5634765625,,,,,,,,,,,,,0,,,,-0.00245,,,,,,223.0311737,,,,
,30319496.135,225.5143127,99.5634765625,0.000804665260906278,1.04131846730525E-5,1,0.999253354069792,40.0298881530762,1.99361753640888,29.2399991303682,0.00787646104659606,0.00867694488606203,0.25,0.000626964540665616,0.000806184817706236,0.000629340937929493,225.5143127,225.5143127,99.5634765625,99.5634765625,57.6130565239869,20.5257254465096,25.566563,0,0,0,40,4374,228.43975,99.5634765625,,,,,,,,,,,,,0,,,,0.0049,,,,,,225.5143127,,,,
,30319598.295,228.0404053,99.5634765625,0.000812383297971639,8.88379962182289E-6,1,0.999253354069792,40.0298881530762,1.99329762498203,29.2399991303682,0.00794799635065443,0.00877075070882028,0.25,0.000634106958427859,0.000813854031635876,0.000636444292552524,228.0404053,228.0404053,99.5634765625,99.5634765625,57.2980602307368,20.5323479420171,25.566563,0,0,0,40,4374,230.9937,99.5634765625,,,,,,,,,,,,,0,,,,0.00245,,,,,,228.0404053,,,,
,30319698.295,230.5049286,99.5634765625,0.000789842575952446,1.35966349946703E-5,1,0.999253354069792,40.0298881530762,1.99202420088715,29.2399991303682,0.00772382109439412,0.00851205156254188,0.25,0.000615687551685931,0.000791213638607027,0.00061789656131339,230.5049286,230.5049286,99.5634765625,99.5634765625,57.3316702570638,20.5443234445112,25.566563,0,0,0,40,4374,233.49045,99.5634765625,,,,,,,,,,,,,0,,,,0.00245,,,,,,230.5049286,,,,
,30319800.61,233.081192,99.5634765625,0.000792200422095489,1.02004431865799E-5,1,0.999253354069792,40.0298881530762,1.9931364687327,29.2399991303682,0.00775246859497435,0.00852936133524247,0.25,0.00061648219224972,0.000793513416159255,0.000618631111376327,233.051651,233.110733,99.5634765625,99.5634765625,57.4692368764484,20.537134957442,25.186911,0,0,0,40,4374,236.0671,99.5634765625,,,,,,,,,,,,,0,,,,-0.00245,,,,,,233.081192,,,,
,30319899.025,235.5535736,99.5634765625,0.000751679488309687,1.29204278447631E-5,1,0.999253354069792,40.0298881530762,1.99308783900059,29.2399991303682,0.00735197160800748,0.00811085061199482,0.25,0.000586604521407729,0.000752865991241069,0.000588588894867963,235.5535736,235.5535736,99.5634765625,99.5634765625,57.5020652742561,20.53763305442,25.566563,0,0,0,40,4374,238.5336,99.5634765625,,,,,,,,,,,,,0,,,,0,,,,,,235.5535736,,,,
,30319998.75,238.0046387,99.5634765625,0.000784621174843618,1.27521545584266E-5,1,0.999253354069792,40.0298881530762,1.9939641798005,29.2399991303682,0.00771233344326743,0.00826435803097801,0.25,0.000594222970956546,0.000785815222380981,0.000596194219375283,238.0046387,238.0046387,99.5634765625,99.5634765625,57.3598088837561,20.5233733280097,25.566563,0,0,0,40,4374,241.0403,99.5634765625,,,,,,,,,,,,,0,,,,-0.0049,,,,,,238.0046387,,,,
,30320101.25,240.558609,99.5634765625,0.000761102219447548,1.30407285751671E-5,1,0.999253354069792,40.0298881530762,1.97983003723545,29.2399991303682,0.00742545228067995,0.00798736467174214,0.25,0.00057870673092024,0.000762196996232181,0.000580564110925373,240.558609,240.558609,99.5634765625,99.5634765625,57.1745629246983,20.5428646717362,25.946213,0,0,0,40,4374,243.5792,99.5634765625,,,,,,,,,,,,,0,,,,0.00245,,,,,,240.558609,,,,
,30320200.84,243.0615234,99.5634765625,0.000741897875530132,1.22802995780092E-5,1,0.999253354069792,40.0298881530762,1.98090321846423,29.2399991303682,0.00721500386079648,0.00794064774826999,0.25,0.00057758349671687,0.000742894659116869,0.000579363802361709,243.0615234,243.0615234,99.5634765625,99.5634765625,57.1370447557753,20.5349535626131,25.566563,0,0,0,40,4374,246.0977,99.5634765625,,,,,,,,,,,,,0,,,,-0.00245,,,,,,243.0615234,,,,
,30320300.165,245.5552673,99.5634765625,0.000743182074907472,1.38270799838517E-5,1,0.999253354069792,40.0298881530762,1.98151970649064,29.2399991303682,0.00722026819216001,0.00800686149068968,0.25,0.00058310691315635,0.00074411770207154,0.000584840783110431,245.5552673,245.5552673,99.5634765625,99.5634765625,57.4199942797368,20.5295077084936,25.946213,0,0,0,40,4374,248.59435,99.5634765625,,,,,,,,,,,,,0,,,,-0.00245,,,,,,245.5552673,,,,
,30320398.435,248.0157623,99.5634765625,0.000739377967042196,9.55598374365576E-6,1,0.999253354069792,40.0298881530762,1.98158917754835,29.2399991303682,0.00721938442346188,0.00775562785483889,0.25,0.000561468791817812,0.000740265871880134,0.000563102267342826,248.0157623,248.0157623,99.5634765625,99.5634765625,57.2996234877753,20.5293775272612,26.325863,0,0,0,40,4374,251.05895,99.5634765625,,,,,,,,,,,,,0,,,,-0.0049,,,,,,248.0157623,,,,
touchdown = 19.0200004726648 mm,30320494.355,250.4144135,99.5634765625,0.000733162788495593,1.55842995699524E-5,1,0.999253354069792,40.0298881530762,1.99311568854114,29.2399991303682,0.00716479739109479,0.0079234714853748,0.25,0.000573645534286839,0.000733972732924159,0.000575240710976758,250.4144135,250.4144135,99.5634765625,99.5634765625,57.4043617093522,20.5269515566443,25.946213,0,0,0,40,4374,253.47405,99.5634765625,,,,,,,,,,,,,0,,,,0,,,,,,250.4144135,,,,
,30320579.945,252.5485992,99.5634765625,0.000727880967459282,1.37137316143851E-5,1,0.999253354069792,40.0298881530762,1.9931579868398,29.2399991303682,0.00714478128620243,0.00768177346799994,0.25,0.000553227147767553,0.000728647930312473,0.000554734840793377,252.5485992,252.5485992,99.5634765625,99.5634765625,56.953362053756,20.5330225005276,25.946213,0,0,0,40,4374,255.599,99.5634765625,,,,,,,,,,,,,0,,,,0.00245,,,,,,252.5485992,,,,
,30320681.055,255.0376282,99.5634765625,0.0007236936098265,1.43784991873522E-5,1,0.999253354069792,40.0298881530762,1.99382476961667,29.2399991303682,0.00708511903545971,0.00775621532155361,0.25,0.000560384813450555,0.000724389440199734,0.00056184476379171,255.0376282,255.0376282,99.5634765625,99.5634765625,57.2886806885061,20.5307861130285,25.946213,0,0,0,40,4374,258.15195,99.5634765625,,,,,,,,,,,,,0,,,,-0.0049,,,,,,255.0376282,,,,
,30320781.97,257.56396485,99.5634765625,0.000718489973573079,1.60898485417506E-5,1,0.999253354069792,40.0298881530762,1.99429238708546,29.2399991303682,0.00706195355496916,0.00754705253207718,0.25,0.000542707166273773,0.000719132215752576,0.00054407987271168,257.5354004,257.5925293,99.5634765625,99.5634765625,57.4145228801022,20.5272068281202,26.325863,0,0,0,40,4374,260.64205,99.5634765625,,,,,,,,,,,,,0,,,,-0.0049,,,,,,257.56396485,,,,
,30320898.34,260.3850098,99.5634765625,,,2,,,,29.2500004726648,,,,,,,260.3850098,260.3850098,99.5634765625,99.5634765625,,,26.325863,,,,-99999999,4374,263.5538,99.5634765625,,,,,,,,,,,,,,,,,,,,,,,260.3850098,,,,
,30320981.94,262.5435181,99.5634765625,0.000715025917801092,1.31829950992471E-5,1,0.999253354069792,40.0298881530762,1.99384739071694,29.2399991303682,0.00703916541739124,0.00742763015608303,0.25,0.000533016009926635,0.000715553503239039,0.000534264408288709,262.5435181,262.5435181,99.5634765625,99.5634765625,57.342613056333,20.5255862071672,26.325863,0,0,0,40,4374,265.65985,99.5634765625,,,,,,,,,,,,,0,,,,-0.0049,,,,,,262.5435181,,,,
,30321082.07,265.034668,99.5634765625,0.000694168486282189,1.5584172082315E-5,1,0.999253354069792,40.0298881530762,1.99415131418719,29.2399991303682,0.0067895080018218,0.00746958798653617,0.25,0.000540310823361522,0.000694606147948482,0.000541498765523231,265.034668,265.034668,99.5634765625,99.5634765625,57.5802281261792,20.5136715147227,26.705515,0,0,0,40,4374,268.16755,99.5634765625,,,,,,,,,,,,,0,,,,0,,,,,,265.034668,,,,
,30321180.805,267.5166626,99.5634765625,0.00070466928096252,1.4317297051386E-5,1,0.999253354069792,40.0298881530762,1.99407914097462,29.2399991303682,0.00696193091724574,0.00717488579858813,0.25,0.000512508530768749,0.000705082736659044,0.000513619202488232,267.5166626,267.5166626,99.5634765625,99.5634765625,57.5974239536023,20.5184502351818,26.325863,0,0,0,40,4374,270.6299,99.5634765625,,,,,,,,,,,,,0,,,,0,,,,,,267.5166626,,,,
,30321283.68,270.0525513,99.5634765625,0.000696979720499508,1.2269321870204E-5,1,0.999253354069792,40.0298881530762,1.99493116283027,29.2399991303682,0.00687705534940182,0.00716310992710922,0.25,0.000512604036155972,0.000697325631641145,0.000513656620424307,270.0525513,270.0525513,99.5634765625,99.5634765625,57.5090999309292,20.5153130081358,26.325863,0,0,0,40,4374,273.21745,99.5634765625,,,,,,,,,,,,,0,,,,0,,,,,,270.0525513,,,,
,30321381.86,272.50131225,99.5634765625,0.000702264237621933,1.08398691261262E-5,1,0.999253354069792,40.0298881530762,1.98194930779669,29.2399991303682,0.00691316118507056,0.00701278595744872,0.25,0.000502333000346508,0.000702565804286645,0.000503329189901868,272.4689331,272.5336914,99.5634765625,99.5634765625,57.4457880208715,20.5353724787426,26.325863,0,0,0,40,4374,275.6813,99.5634765625,,,,,,,,,,,,,0,,,,-0.0049,,,,,,272.50131225,,,,
,30321483.25,275.0282288,99.5634765625,0.000698312360278464,1.0387330615096E-5,1,0.999253354069792,40.0298881530762,1.98222443492899,29.2399991303682,0.00688435055063355,0.0069173309121282,0.25,0.000494502432644204,0.000698556704765622,0.000495437915914721,275.0282288,275.0282288,99.5634765625,99.5634765625,57.7381170870638,20.530846390325,26.705515,0,0,0,40,4374,278.1978,99.5634765625,,,,,,,,,,,,,0,,,,-0.0049,,,,,,275.0282288,,,,
,30321583.83,277.5267334,99.5634765625,0.000698379804676487,1.2113794483275E-5,1,0.999253354069792,40.0298881530762,1.98270943498128,29.2399991303682,0.00690938458114567,0.00678438096719305,0.25,0.000482577846140929,0.000698574143761023,0.000483454445229816,277.5267334,277.5267334,99.5634765625,99.5634765625,57.7138866029676,20.5239406278758,26.705515,0,0,0,40,4374,280.694,99.5634765625,,,,,,,,,,,,,0,,,,-0.00245,,,,,,277.5267334,,,,
,30321684.025,280.0162659,99.5634765625,0.000691128854215963,1.02673107657105E-5,1,0.999253354069792,40.0298881530762,1.98266813123895,29.2399991303682,0.00686858068643527,0.00653066727719073,0.25,0.000461329193445572,0.000691274766253323,0.000462137639723158,280.0162659,280.0162659,99.5634765625,99.5634765625,57.454385934583,20.5207421737639,26.705515,0,0,0,40,4374,283.20945,99.5634765625,,,,,,,,,,,,,0,,,,0,,,,,,280.0162659,,,,
,30321784.545,282.5490112,99.5634765625,0.000676900848046014,1.03774323247971E-5,1,0.999253354069792,40.0298881530762,1.98220808226746,29.2600002139807,0.00669433706489862,0.00657183536058894,0.25,0.000467645376752642,0.000676974558827037,0.000468400514150086,282.5490112,282.5490112,99.5634765625,99.5634765625,57.4489145349484,20.5291027411003,26.325863,0,0,0,40,4374,285.70605,99.5634765625,,,,,,,,,,,,,0,,,,0,,,,,,282.5490112,,,,
,30321883.785,285.0334167,99.5634765625,0.000683936847056916,1.06632567078011E-5,1,0.999253354069792,40.0298881530762,1.98266740624144,29.2600002139807,0.00680461745693944,0.00641158159017268,0.25,0.000452090870107402,0.000683968150889462,0.000452796404820162,285.0334167,285.0334167,99.5634765625,99.5634765625,57.5434915857753,20.5245185406236,26.325863,0,0,0,40,4374,288.2175,99.5634765625,,,,,,,,,,,,,0,,,,0,,,,,,285.0334167,,,,
,30321985.82,287.5297546,99.5634765625,0.000672565871986866,1.0722695527647E-5,1,0.999253354069792,40.0298881530762,1.98300362920579,29.2600002139807,0.00668610617317613,0.00633950399603914,0.25,0.000447610059175861,0.000672537675860336,0.000448260431854198,287.5297546,287.5297546,99.5634765625,99.5634765625,57.5450548428138,20.5218011288112,27.085165,0,0,0,40,4374,290.76585,99.5634765625,,,,,,,,,,,,,0,,,,-0.0049,,,,,,287.5297546,,,,
,30322086.885,290.094696,99.5634765625,0.000672864845969037,1.01100748216269E-5,1,0.999253354069792,40.0298881530762,1.98303476766019,29.2600002139807,0.00670550658197437,0.00624427369569859,0.25,0.000439130609261373,0.000672783961479013,0.000439732457319866,290.094696,290.094696,99.5634765625,99.5634765625,57.5630322987561,20.5166190756381,26.705515,0,0,0,40,4374,293.31715,99.5634765625,,,,,,,,,,,,,0,,,,0.00245,,,,,,290.094696,,,,
,30322186.95,292.5574951,99.5634765625,0.000642725717388978,1.33292636966192E-5,1,0.999253354069792,40.0298881530762,1.98288791805189,29.3000005185604,0.00635613791725861,0.00624081855435867,0.25,0.00044413767114093,0.00064257796471337,0.000444677051164512,292.5574951,292.5574951,99.5634765625,99.5634765625,57.5286406439099,20.5175357548639,26.705515,0,0,0,40,4374,295.7731,99.5634765625,,,,,,,,,,,,,0,,,,-0.00245,,,,,,292.5574951,,,,
,30322288.1,295.0656891,99.5634765625,0.000650958690569205,1.20427414309658E-5,1,0.999253354069792,40.0298881530762,1.98290577137179,29.3000005185604,0.00647943645553076,0.00607573288413674,0.25,0.000428064477968068,0.000650768333141906,0.00042856265092941,295.0332642,295.098114,99.5634765625,99.5634765625,57.5552160135638,20.5171845526351,26.325863,0,0,0,40,4374,298.35225,99.5634765625,,,,,,,,,,,,,0,,,,0.00245,,,,,,295.0656891,,,,
,30322386.45,297.5290527,99.5634765625,0.000644639307255165,1.31398465406576E-5,1,0.999253354069792,40.0298881530762,1.98293767120071,29.3000005185604,0.00641580652864465,0.00601801033141855,0.25,0.000424063658713858,0.000644396683096664,0.000424515474865402,297.5290527,297.5290527,99.5634765625,99.5634765625,57.7631291996792,20.5161095842989,26.705515,0,0,0,40,4374,300.8016,99.5634765625,,,,,,,,,,,,,0,,,,0,,,,,,297.5290527,,,,
,30322658.63,299.7946472,99.5634765625,0.000644334212158486,1.3267438081375E-5,1,0.999253354069792,40.0298881530762,1.98317734318296,29.3000005185604,0.00640847255475642,0.00604139661601715,0.25,0.000426179647701183,0.000644037218115106,0.000426597266763937,299.7946472,299.7946472,99.5634765625,99.5634765625,57.5896076684099,20.5167875830577,26.705515,0,0,0,40,4369,300.40765,99.5634765625,,,,,,,,,,,,,0,,,,0,,,,,,299.7946472,,,,