File: data/looselyPackedNP/ios-11/ppms/rawdata/ZFC100Oe.dc.dat
[Header]
TITLE,MPMS DC Measurement
BYAPP,MPMS Measurement,2.1,Summary
FILEOPENTIME, 1418232120.354000 12/10/2014, 6:22:00 PM

INFO, APPNAME, MPMS MultiVu Application, Revision 1.60,  Build 081

INFO, NAME, PMK18
INFO, WEIGHT, 13.800
INFO, AREA, 1.000
INFO, LENGTH, 1.000
INFO, SHAPE, NP
INFO, COMMENT, Fe2O3
INFO, SEQUENCE FILE: 04062014.seq


INFO, BACKGROUND DATA FILE:, None


STARTUPAXIS,X,4,LINEAR,AUTO,0.000000,0.000000
STARTUPAXIS,Y1,5,LINEAR,AUTO,0.000000,0.000000


STARTUPGROUP,Longitudinal
FIELDGROUP,Longitudinal,1,2,3,4,5,6,7,8,9,15,16,17,18,27,28
FIELDGROUP,Transverse,1,2,3,4,10,11,12,13,14,19,20,21,22,27,28

PLOT_APPEARANCE,ALL,HORZ_GRID_ON,VERT_GRID_ON,MARKERS_AND_LINES

[Data]
Time,Comment,Field (Oe),Temperature (K),Moment (emu),Long Scan Std Dev,Long Algorithm,Long Reg Fit,Long Percent Error (%),Trans Moment (emu),Trans Scan Std Dev,Trans Algorithm,Trans Reg Fit,Trans Percent Error (%),Long Moment [w/o ABS] (emu),Long Scan Std Dev [w/o ABS],Long Reg Fit [w/o ABS],Long Percent Error [w/o ABS] (%),Trans Moment [w/o ABS] (emu),Trans Scan Std Dev [w/o ABS],Trans Reg Fit [w/o ABS],Trans Percent Error [w/o ABS] (%),Points per Scan,Scans per Measurement,Scan Length (cm),Delta Temp (K),Rot Position (deg),Error,EC Comp. Running,Using ABS,
1418232120.354,,1.000000e+002,4.999262e+000,1.458358e-003,0.000000e+000,3,9.953877e-001,0.000000e+000,,,,,,,,,,,,,,24,1,4.000000e+000,2.322197e-004,0.000000e+000,0,,0,
1418232166.580,,1.000000e+002,6.578890e+000,1.493971e-003,0.000000e+000,3,9.966219e-001,0.000000e+000,,,,,,,,,,,,,,24,1,4.000000e+000,9.415631e-001,0.000000e+000,0,,0,
1418232185.298,,1.000000e+002,7.498438e+000,1.543194e-003,0.000000e+000,3,9.965260e-001,0.000000e+000,,,,,,,,,,,,,,24,1,4.000000e+000,7.831898e-001,0.000000e+000,0,,0,
1418232205.501,,1.000000e+002,8.429043e+000,1.609366e-003,0.000000e+000,3,9.965067e-001,0.000000e+000,,,,,,,,,,,,,,24,1,4.000000e+000,7.786417e-001,0.000000e+000,0,,0,
1418232226.595,,1.000000e+002,9.498571e+000,1.737938e-003,0.000000e+000,3,9.966039e-001,0.000000e+000,,,,,,,,,,,,,,24,1,4.000000e+000,8.550835e-001,0.000000e+000,0,,0,
1418232245.720,,1.000000e+002,1.038342e+001,1.830989e-003,0.000000e+000,3,9.962449e-001,0.000000e+000,,,,,,,,,,,,,,24,1,4.000000e+000,7.096405e-001,0.000000e+000,0,,0,
1418232271.602,,1.000000e+002,1.144063e+001,1.968775e-003,0.000000e+000,3,9.961780e-001,0.000000e+000,,,,,,,,,,,,,,24,1,4.000000e+000,8.626404e-001,0.000000e+000,0,,0,
1418232298.399,,1.000000e+002,1.266549e+001,2.174870e-003,0.000000e+000,3,9.959478e-001,0.000000e+000,,,,,,,,,,,,,,24,1,4.000000e+000,8.745594e-001,0.000000e+000,0,,0,
1418232317.586,,1.000000e+002,1.359304e+001,2.364872e-003,0.000000e+000,3,9.959481e-001,0.000000e+000,,,,,,,,,,,,,,24,1,4.000000e+000,8.714800e-001,0.000000e+000,0,,0,
1418232336.843,,1.000000e+002,1.449796e+001,2.558742e-003,0.000000e+000,3,9.955870e-001,0.000000e+000,,,,,,,,,,,,,,24,1,4.000000e+000,9.383698e-001,0.000000e+000,0,,0,
1418232354.890,,1.000000e+002,1.545743e+001,2.783904e-003,0.000000e+000,3,9.960509e-001,0.000000e+000,,,,,,,,,,,,,,24,1,4.000000e+000,8.755302e-001,0.000000e+000,0,,0,
1418232379.132,,1.000000e+002,1.660359e+001,3.097510e-003,0.000000e+000,3,9.953856e-001,0.000000e+000,,,,,,,,,,,,,,24,1,4.000000e+000,1.015041e+000,0.000000e+000,0,,0,
1418232398.632,,1.000000e+002,1.760853e+001,3.417371e-003,0.000000e+000,3,9.959481e-001,0.000000e+000,,,,,,,,,,,,,,24,1,4.000000e+000,8.949394e-001,0.000000e+000,0,,0,
1418232417.670,,1.000000e+002,1.857226e+001,3.757556e-003,0.000000e+000,3,9.957131e-001,0.000000e+000,,,,,,,,,,,,,,24,1,4.000000e+000,8.345795e-001,0.000000e+000,0,,0,
1418232436.420,,1.000000e+002,1.949898e+001,4.112737e-003,0.000000e+000,3,9.955211e-001,0.000000e+000,,,,,,,,,,,,,,24,1,4.000000e+000,9.214592e-001,0.000000e+000,0,,0,
1418232458.420,,1.000000e+002,2.056832e+001,4.576044e-003,0.000000e+000,3,9.950706e-001,0.000000e+000,,,,,,,,,,,,,,24,1,4.000000e+000,9.529495e-001,0.000000e+000,0,,0,
1418232518.529,,1.000000e+002,2.354947e+001,6.134268e-003,0.000000e+000,3,9.957457e-001,0.000000e+000,,,,,,,,,,,,,,24,1,4.000000e+000,8.666306e-001,0.000000e+000,0,,0,
1418232538.083,,1.000000e+002,2.448633e+001,6.695306e-003,0.000000e+000,3,9.958186e-001,0.000000e+000,,,,,,,,,,,,,,24,1,4.000000e+000,9.062386e-001,0.000000e+000,0,,0,
1418232558.895,,1.000000e+002,2.548888e+001,7.326328e-003,0.000000e+000,3,9.959685e-001,0.000000e+000,,,,,,,,,,,,,,24,1,4.000000e+000,9.906292e-001,0.000000e+000,0,,0,
1418232579.254,,1.000000e+002,2.648654e+001,7.930256e-003,0.000000e+000,3,9.962595e-001,0.000000e+000,,,,,,,,,,,,,,24,1,4.000000e+000,8.416405e-001,0.000000e+000,0,,0,
1418232599.246,,1.000000e+002,2.737775e+001,8.540911e-003,0.000000e+000,3,9.962965e-001,0.000000e+000,,,,,,,,,,,,,,24,1,4.000000e+000,9.407902e-001,0.000000e+000,0,,0,
1418232619.402,,1.000000e+002,2.838413e+001,9.172919e-003,0.000000e+000,3,9.965061e-001,0.000000e+000,,,,,,,,,,,,,,24,1,4.000000e+000,8.913994e-001,0.000000e+000,0,,0,
1418232639.050,,1.000000e+002,2.927493e+001,9.771946e-003,0.000000e+000,3,9.965104e-001,0.000000e+000,,,,,,,,,,,,,,24,1,4.000000e+000,8.143406e-001,0.000000e+000,0,,0,
1418232658.550,,1.000000e+002,3.018904e+001,1.033703e-002,0.000000e+000,3,9.967849e-001,0.000000e+000,,,,,,,,,,,,,,24,1,4.000000e+000,9.080200e-001,0.000000e+000,0,,0,
1418232678.050,,1.000000e+002,3.110590e+001,1.089859e-002,0.000000e+000,3,9.966016e-001,0.000000e+000,,,,,,,,,,,,,,24,1,4.000000e+000,8.311710e-001,0.000000e+000,0,,0,
1418232696.987,,1.000000e+002,3.199493e+001,1.143439e-002,0.000000e+000,3,9.967039e-001,0.000000e+000,,,,,,,,,,,,,,24,1,4.000000e+000,8.449688e-001,0.000000e+000,0,,0,
1418232714.792,,1.000000e+002,3.284679e+001,1.192403e-002,0.000000e+000,3,9.969850e-001,0.000000e+000,,,,,,,,,,,,,,24,1,4.000000e+000,7.572021e-001,0.000000e+000,0,,0,
1418232733.799,,1.000000e+002,3.365385e+001,1.239998e-002,0.000000e+000,3,9.968368e-001,0.000000e+000,,,,,,,,,,,,,,24,1,4.000000e+000,8.569069e-001,0.000000e+000,0,,0,
1418232754.791,,1.000000e+002,3.459438e+001,1.291259e-002,0.000000e+000,3,9.967377e-001,0.000000e+000,,,,,,,,,,,,,,24,1,4.000000e+000,9.372482e-001,0.000000e+000,0,,0,
1418232775.486,,1.000000e+002,3.561540e+001,1.341166e-002,0.000000e+000,3,9.970018e-001,0.000000e+000,,,,,,,,,,,,,,24,1,4.000000e+000,9.028511e-001,0.000000e+000,0,,0,
1418232795.064,,1.000000e+002,3.656400e+001,1.391212e-002,0.000000e+000,3,9.969690e-001,0.000000e+000,,,,,,,,,,,,,,24,1,4.000000e+000,7.952690e-001,0.000000e+000,0,,0,
1418232813.595,,1.000000e+002,3.739318e+001,1.436863e-002,0.000000e+000,3,9.970249e-001,0.000000e+000,,,,,,,,,,,,,,24,1,4.000000e+000,8.630791e-001,0.000000e+000,0,,0,
1418232833.126,,1.000000e+002,3.836901e+001,1.480713e-002,0.000000e+000,3,9.968992e-001,0.000000e+000,,,,,,,,,,,,,,24,1,4.000000e+000,8.935471e-001,0.000000e+000,0,,0,
1418232852.454,,1.000000e+002,3.926992e+001,1.527607e-002,0.000000e+000,3,9.968792e-001,0.000000e+000,,,,,,,,,,,,,,24,1,4.000000e+000,8.138809e-001,0.000000e+000,0,,0,
1418232872.899,,1.000000e+002,4.016339e+001,1.574064e-002,0.000000e+000,3,9.969617e-001,0.000000e+000,,,,,,,,,,,,,,24,1,4.000000e+000,8.907089e-001,0.000000e+000,0,,0,
1418232892.985,,1.000000e+002,4.111670e+001,1.620257e-002,0.000000e+000,3,9.969631e-001,0.000000e+000,,,,,,,,,,,,,,24,1,4.000000e+000,9.178314e-001,0.000000e+000,0,,0,
1418232914.047,,1.000000e+002,4.216100e+001,1.669481e-002,0.000000e+000,3,9.969813e-001,0.000000e+000,,,,,,,,,,,,,,24,1,4.000000e+000,9.746399e-001,0.000000e+000,0,,0,
1418232934.195,,1.000000e+002,4.310682e+001,1.720488e-002,0.000000e+000,3,9.970834e-001,0.000000e+000,,,,,,,,,,,,,,24,1,4.000000e+000,9.169922e-001,0.000000e+000,0,,0,
1418232955.328,,1.000000e+002,4.407798e+001,1.770430e-002,0.000000e+000,3,9.969958e-001,0.000000e+000,,,,,,,,,,,,,,24,1,4.000000e+000,9.466782e-001,0.000000e+000,0,,0,
1418232976.577,,1.000000e+002,4.514624e+001,1.823792e-002,0.000000e+000,3,9.968603e-001,0.000000e+000,,,,,,,,,,,,,,24,1,4.000000e+000,9.292221e-001,0.000000e+000,0,,0,
1418233018.124,,1.000000e+002,4.719461e+001,1.932940e-002,0.000000e+000,3,9.970769e-001,0.000000e+000,,,,,,,,,,,,,,24,1,4.000000e+000,9.442596e-001,0.000000e+000,0,,0,
1418233039.334,,1.000000e+002,4.822186e+001,1.990798e-002,0.000000e+000,3,9.971395e-001,0.000000e+000,,,,,,,,,,,,,,24,1,4.000000e+000,9.926491e-001,0.000000e+000,0,,0,
1418233060.193,,1.000000e+002,4.931635e+001,2.050318e-002,0.000000e+000,3,9.969866e-001,0.000000e+000,,,,,,,,,,,,,,24,1,4.000000e+000,9.833107e-001,0.000000e+000,0,,0,
1418233079.639,,1.000000e+002,5.029648e+001,2.109283e-002,0.000000e+000,3,9.969788e-001,0.000000e+000,,,,,,,,,,,,,,24,1,4.000000e+000,8.709984e-001,0.000000e+000,0,,0,
1418233100.357,,1.000000e+002,5.132960e+001,2.170642e-002,0.000000e+000,3,9.969259e-001,0.000000e+000,,,,,,,,,,,,,,24,1,4.000000e+000,9.761391e-001,0.000000e+000,0,,0,
1418233119.997,,1.000000e+002,5.227571e+001,2.235150e-002,0.000000e+000,3,9.970007e-001,0.000000e+000,,,,,,,,,,,,,,24,1,4.000000e+000,9.160919e-001,0.000000e+000,0,,0,
1418233140.396,,1.000000e+002,5.331947e+001,2.300838e-002,0.000000e+000,3,9.970046e-001,0.000000e+000,,,,,,,,,,,,,,24,1,4.000000e+000,9.183884e-001,0.000000e+000,0,,0,
1418233166.083,,1.000000e+002,5.461050e+001,2.386614e-002,0.000000e+000,3,9.969487e-001,0.000000e+000,,,,,,,,,,,,,,24,1,4.000000e+000,9.396973e-001,0.000000e+000,0,,0,
1418233185.989,,1.000000e+002,5.557180e+001,2.455466e-002,0.000000e+000,3,9.970161e-001,0.000000e+000,,,,,,,,,,,,,,24,1,4.000000e+000,8.843918e-001,0.000000e+000,0,,0,
1418233205.645,,1.000000e+002,5.653084e+001,2.525174e-002,0.000000e+000,3,9.970055e-001,0.000000e+000,,,,,,,,,,,,,,24,1,4.000000e+000,9.118309e-001,0.000000e+000,0,,0,
1418233226.996,,1.000000e+002,5.749152e+001,2.599887e-002,0.000000e+000,3,9.969229e-001,0.000000e+000,,,,,,,,,,,,,,24,1,4.000000e+000,1.009537e+000,0.000000e+000,0,,0,
1418233245.722,,1.000000e+002,5.843235e+001,2.672883e-002,0.000000e+000,3,9.969811e-001,0.000000e+000,,,,,,,,,,,,,,24,1,4.000000e+000,8.721313e-001,0.000000e+000,0,,0,
1418233265.402,,1.000000e+002,5.937344e+001,2.745141e-002,0.000000e+000,3,9.968607e-001,0.000000e+000,,,,,,,,,,,,,,24,1,4.000000e+000,8.990784e-001,0.000000e+000,0,,0,
1418233284.183,,1.000000e+002,6.029428e+001,2.818560e-002,0.000000e+000,3,9.969463e-001,0.000000e+000,,,,,,,,,,,,,,24,1,4.000000e+000,8.250885e-001,0.000000e+000,0,,0,
1418233302.784,,1.000000e+002,6.119114e+001,2.892641e-002,0.000000e+000,3,9.970258e-001,0.000000e+000,,,,,,,,,,,,,,24,1,4.000000e+000,8.445892e-001,0.000000e+000,0,,0,
1418233320.776,,1.000000e+002,6.207104e+001,2.963739e-002,0.000000e+000,3,9.970144e-001,0.000000e+000,,,,,,,,,,,,,,24,1,4.000000e+000,7.947502e-001,0.000000e+000,0,,0,
1418233340.338,,1.000000e+002,6.300966e+001,3.041607e-002,0.000000e+000,3,9.969393e-001,0.000000e+000,,,,,,,,,,,,,,24,1,4.000000e+000,8.634605e-001,0.000000e+000,0,,0,
1418233359.901,,1.000000e+002,6.393832e+001,3.120565e-002,0.000000e+000,3,9.971201e-001,0.000000e+000,,,,,,,,,,,,,,24,1,4.000000e+000,8.740425e-001,0.000000e+000,0,,0,
1418233379.408,,1.000000e+002,6.484265e+001,3.200243e-002,0.000000e+000,3,9.971435e-001,0.000000e+000,,,,,,,,,,,,,,24,1,4.000000e+000,9.346085e-001,0.000000e+000,0,,0,
1418233398.627,,1.000000e+002,6.582239e+001,3.277684e-002,0.000000e+000,3,9.970354e-001,0.000000e+000,,,,,,,,,,,,,,24,1,4.000000e+000,8.908386e-001,0.000000e+000,0,,0,
1418233417.900,,1.000000e+002,6.674266e+001,3.359550e-002,0.000000e+000,3,9.969411e-001,0.000000e+000,,,,,,,,,,,,,,24,1,4.000000e+000,9.496994e-001,0.000000e+000,0,,0,
1418233436.267,,1.000000e+002,6.764197e+001,3.439730e-002,0.000000e+000,3,9.969694e-001,0.000000e+000,,,,,,,,,,,,,,24,1,4.000000e+000,8.489227e-001,0.000000e+000,0,,0,
1418233455.524,,1.000000e+002,6.855623e+001,3.518147e-002,0.000000e+000,3,9.969184e-001,0.000000e+000,,,,,,,,,,,,,,24,1,4.000000e+000,8.638840e-001,0.000000e+000,0,,0,
1418233474.774,,1.000000e+002,6.949298e+001,3.599349e-002,0.000000e+000,3,9.969398e-001,0.000000e+000,,,,,,,,,,,,,,24,1,4.000000e+000,8.909988e-001,0.000000e+000,0,,0,
1418233494.516,,1.000000e+002,7.046524e+001,3.679369e-002,0.000000e+000,3,9.969844e-001,0.000000e+000,,,,,,,,,,,,,,24,1,4.000000e+000,9.363251e-001,0.000000e+000,0,,0,
1418233514.524,,1.000000e+002,7.144411e+001,3.796135e-002,0.000000e+000,3,9.874530e-001,0.000000e+000,,,,,,,,,,,,,,24,1,4.000000e+000,9.056473e-001,0.000000e+000,0,,0,
1418233533.391,,1.000000e+002,7.239101e+001,3.844852e-002,0.000000e+000,3,9.970517e-001,0.000000e+000,,,,,,,,,,,,,,24,1,4.000000e+000,8.649979e-001,0.000000e+000,0,,0,
1418233553.531,,1.000000e+002,7.335962e+001,3.923908e-002,0.000000e+000,3,9.969890e-001,0.000000e+000,,,,,,,,,,,,,,24,1,4.000000e+000,8.527985e-001,0.000000e+000,0,,0,
1418233573.749,,1.000000e+002,7.430383e+001,4.004502e-002,0.000000e+000,3,9.970060e-001,0.000000e+000,,,,,,,,,,,,,,24,1,4.000000e+000,9.209518e-001,0.000000e+000,0,,0,
1418233594.148,,1.000000e+002,7.530086e+001,4.087371e-002,0.000000e+000,3,9.969844e-001,0.000000e+000,,,,,,,,,,,,,,24,1,4.000000e+000,9.556885e-001,0.000000e+000,0,,0,
1418233612.608,,1.000000e+002,7.624413e+001,4.159201e-002,0.000000e+000,3,9.968563e-001,0.000000e+000,,,,,,,,,,,,,,24,1,4.000000e+000,8.456879e-001,0.000000e+000,0,,0,
1418233631.085,,1.000000e+002,7.713710e+001,4.229577e-002,0.000000e+000,3,9.969531e-001,0.000000e+000,,,,,,,,,,,,,,24,1,4.000000e+000,8.481064e-001,0.000000e+000,0,,0,
1418233650.202,,1.000000e+002,7.804794e+001,4.292601e-002,0.000000e+000,3,9.962115e-001,0.000000e+000,,,,,,,,,,,,,,24,1,4.000000e+000,8.586197e-001,0.000000e+000,0,,0,
1418233670.201,,1.000000e+002,7.903926e+001,4.365443e-002,0.000000e+000,3,9.968616e-001,0.000000e+000,,,,,,,,,,,,,,24,1,4.000000e+000,9.157333e-001,0.000000e+000,0,,0,
1418233689.006,,1.000000e+002,8.001508e+001,4.432534e-002,0.000000e+000,3,9.968394e-001,0.000000e+000,,,,,,,,,,,,,,24,1,4.000000e+000,8.062973e-001,0.000000e+000,0,,0,
1418233708.771,,1.000000e+002,8.097847e+001,4.495379e-002,0.000000e+000,3,9.968250e-001,0.000000e+000,,,,,,,,,,,,,,24,1,4.000000e+000,9.196625e-001,0.000000e+000,0,,0,
1418233728.122,,1.000000e+002,8.192596e+001,4.558352e-002,0.000000e+000,3,9.968449e-001,0.000000e+000,,,,,,,,,,,,,,24,1,4.000000e+000,8.555298e-001,0.000000e+000,0,,0,
1418233747.755,,1.000000e+002,8.291327e+001,4.615124e-002,0.000000e+000,3,9.968759e-001,0.000000e+000,,,,,,,,,,,,,,24,1,4.000000e+000,9.153442e-001,0.000000e+000,0,,0,
1418233786.958,,1.000000e+002,8.492480e+001,4.724816e-002,0.000000e+000,3,9.969095e-001,0.000000e+000,,,,,,,,,,,,,,24,1,4.000000e+000,8.511963e-001,0.000000e+000,0,,0,
1418233807.075,,1.000000e+002,8.590765e+001,4.775504e-002,0.000000e+000,3,9.969178e-001,0.000000e+000,,,,,,,,,,,,,,24,1,4.000000e+000,8.909912e-001,0.000000e+000,0,,0,
1418233826.574,,1.000000e+002,8.688359e+001,4.821275e-002,0.000000e+000,3,9.969108e-001,0.000000e+000,,,,,,,,,,,,,,24,1,4.000000e+000,8.452835e-001,0.000000e+000,0,,0,
1418233845.410,,1.000000e+002,8.775575e+001,4.863002e-002,0.000000e+000,3,9.968590e-001,0.000000e+000,,,,,,,,,,,,,,24,1,4.000000e+000,8.085251e-001,0.000000e+000,0,,0,
1418233864.816,,1.000000e+002,8.862737e+001,4.900093e-002,0.000000e+000,3,9.968917e-001,0.000000e+000,,,,,,,,,,,,,,24,1,4.000000e+000,8.426437e-001,0.000000e+000,0,,0,
1418233884.488,,1.000000e+002,8.955396e+001,4.935474e-002,0.000000e+000,3,9.968737e-001,0.000000e+000,,,,,,,,,,,,,,24,1,4.000000e+000,8.965912e-001,0.000000e+000,0,,0,
1418233904.737,,1.000000e+002,9.052449e+001,4.968246e-002,0.000000e+000,3,9.968383e-001,0.000000e+000,,,,,,,,,,,,,,24,1,4.000000e+000,9.283066e-001,0.000000e+000,0,,0,
1418233924.503,,1.000000e+002,9.152641e+001,4.997028e-002,0.000000e+000,3,9.968200e-001,0.000000e+000,,,,,,,,,,,,,,24,1,4.000000e+000,8.733292e-001,0.000000e+000,0,,0,
1418233943.049,,1.000000e+002,9.246623e+001,5.022034e-002,0.000000e+000,3,9.968150e-001,0.000000e+000,,,,,,,,,,,,,,24,1,4.000000e+000,7.857895e-001,0.000000e+000,0,,0,
1418233962.057,,1.000000e+002,9.339368e+001,5.044455e-002,0.000000e+000,3,9.968262e-001,0.000000e+000,,,,,,,,,,,,,,24,1,4.000000e+000,8.953781e-001,0.000000e+000,0,,0,
1418233982.455,,1.000000e+002,9.439948e+001,5.064210e-002,0.000000e+000,3,9.968020e-001,0.000000e+000,,,,,,,,,,,,,,24,1,4.000000e+000,9.169312e-001,0.000000e+000,0,,0,
1418234039.611,,1.000000e+002,9.716324e+001,5.107583e-002,0.000000e+000,3,9.968004e-001,0.000000e+000,,,,,,,,,,,,,,24,1,4.000000e+000,9.513168e-001,0.000000e+000,0,,0,
1418234060.915,,1.000000e+002,9.819090e+001,5.117955e-002,0.000000e+000,3,9.967518e-001,0.000000e+000,,,,,,,,,,,,,,24,1,4.000000e+000,8.657684e-001,0.000000e+000,0,,0,
1418234079.040,,1.000000e+002,9.910825e+001,5.124684e-002,0.000000e+000,3,9.967985e-001,0.000000e+000,,,,,,,,,,,,,,24,1,4.000000e+000,7.829056e-001,0.000000e+000,0,,0,
1418234097.610,,1.000000e+002,1.000088e+002,5.128846e-002,0.000000e+000,3,9.968237e-001,0.000000e+000,,,,,,,,,,,,,,24,1,4.000000e+000,8.537827e-001,0.000000e+000,0,,0,
1418234116.813,,1.000000e+002,1.009389e+002,5.131294e-002,0.000000e+000,3,9.968093e-001,0.000000e+000,,,,,,,,,,,,,,24,1,4.000000e+000,9.147034e-001,0.000000e+000,0,,0,
1418234136.250,,1.000000e+002,1.018846e+002,5.131868e-002,0.000000e+000,3,9.967904e-001,0.000000e+000,,,,,,,,,,,,,,24,1,4.000000e+000,8.831024e-001,0.000000e+000,0,,0,
1418234155.914,,1.000000e+002,1.028225e+002,5.130620e-002,0.000000e+000,3,9.967430e-001,0.000000e+000,,,,,,,,,,,,,,24,1,4.000000e+000,8.978043e-001,0.000000e+000,0,,0,
1418234175.601,,1.000000e+002,1.037897e+002,5.127377e-002,0.000000e+000,3,9.967865e-001,0.000000e+000,,,,,,,,,,,,,,24,1,4.000000e+000,9.663010e-001,0.000000e+000,0,,0,
1418234194.780,,1.000000e+002,1.047731e+002,5.122437e-002,0.000000e+000,3,9.966954e-001,0.000000e+000,,,,,,,,,,,,,,24,1,4.000000e+000,9.198990e-001,0.000000e+000,0,,0,
1418234215.702,,1.000000e+002,1.057508e+002,5.116434e-002,0.000000e+000,3,9.967316e-001,0.000000e+000,,,,,,,,,,,,,,24,1,4.000000e+000,9.263992e-001,0.000000e+000,0,,0,
1418234235.217,,1.000000e+002,1.067312e+002,5.108253e-002,0.000000e+000,3,9.967428e-001,0.000000e+000,,,,,,,,,,,,,,24,1,4.000000e+000,9.420013e-001,0.000000e+000,0,,0,
1418234254.702,,1.000000e+002,1.076830e+002,5.099629e-002,0.000000e+000,3,9.966893e-001,0.000000e+000,,,,,,,,,,,,,,24,1,4.000000e+000,9.051971e-001,0.000000e+000,0,,0,
1418234275.397,,1.000000e+002,1.086820e+002,5.089344e-002,0.000000e+000,3,9.967442e-001,0.000000e+000,,,,,,,,,,,,,,24,1,4.000000e+000,9.494019e-001,0.000000e+000,0,,0,
1418234295.623,,1.000000e+002,1.096975e+002,5.076913e-002,0.000000e+000,3,9.967331e-001,0.000000e+000,,,,,,,,,,,,,,24,1,4.000000e+000,8.774033e-001,0.000000e+000,0,,0,
1418234317.099,,1.000000e+002,1.107236e+002,5.063830e-002,0.000000e+000,3,9.967234e-001,0.000000e+000,,,,,,,,,,,,,,24,1,4.000000e+000,9.870987e-001,0.000000e+000,0,,0,
1418234337.419,,1.000000e+002,1.117718e+002,5.048933e-002,0.000000e+000,3,9.967070e-001,0.000000e+000,,,,,,,,,,,,,,24,1,4.000000e+000,9.281998e-001,0.000000e+000,0,,0,
1418234399.145,,1.000000e+002,1.148566e+002,4.999213e-002,0.000000e+000,3,9.966925e-001,0.000000e+000,,,,,,,,,,,,,,24,1,4.000000e+000,8.963013e-001,0.000000e+000,0,,0,
1418234419.200,,1.000000e+002,1.158383e+002,4.982176e-002,0.000000e+000,3,9.966087e-001,0.000000e+000,,,,,,,,,,,,,,24,1,4.000000e+000,9.918976e-001,0.000000e+000,0,,0,
1418234440.645,,1.000000e+002,1.168740e+002,4.963409e-002,0.000000e+000,3,9.966561e-001,0.000000e+000,,,,,,,,,,,,,,24,1,4.000000e+000,9.920044e-001,0.000000e+000,0,,0,
1418234460.230,,1.000000e+002,1.179127e+002,4.943655e-002,0.000000e+000,3,9.966143e-001,0.000000e+000,,,,,,,,,,,,,,24,1,4.000000e+000,8.852997e-001,0.000000e+000,0,,0,
1418234479.949,,1.000000e+002,1.189177e+002,4.925503e-002,0.000000e+000,3,9.966571e-001,0.000000e+000,,,,,,,,,,,,,,24,1,4.000000e+000,8.423996e-001,0.000000e+000,0,,0,
1418234501.948,,1.000000e+002,1.199163e+002,4.905540e-002,0.000000e+000,3,9.967196e-001,0.000000e+000,,,,,,,,,,,,,,24,1,4.000000e+000,9.482040e-001,0.000000e+000,0,,0,
1418234521.768,,1.000000e+002,1.209127e+002,4.885570e-002,0.000000e+000,3,9.967182e-001,0.000000e+000,,,,,,,,,,,,,,24,1,4.000000e+000,9.748001e-001,0.000000e+000,0,,0,
1418234584.190,,1.000000e+002,1.239225e+002,4.824652e-002,0.000000e+000,3,9.966981e-001,0.000000e+000,,,,,,,,,,,,,,24,1,4.000000e+000,8.731003e-001,0.000000e+000,0,,0,
1418234605.338,,1.000000e+002,1.248609e+002,4.805135e-002,0.000000e+000,3,9.966618e-001,0.000000e+000,,,,,,,,,,,,,,24,1,4.000000e+000,9.416046e-001,0.000000e+000,0,,0,
1418234625.595,,1.000000e+002,1.258595e+002,4.784993e-002,0.000000e+000,3,9.967310e-001,0.000000e+000,,,,,,,,,,,,,,24,1,4.000000e+000,8.671951e-001,0.000000e+000,0,,0,
1418234645.814,,1.000000e+002,1.267866e+002,4.765335e-002,0.000000e+000,3,9.967063e-001,0.000000e+000,,,,,,,,,,,,,,24,1,4.000000e+000,7.957993e-001,0.000000e+000,0,,0,
1418234666.868,,1.000000e+002,1.277531e+002,4.743209e-002,0.000000e+000,3,9.967233e-001,0.000000e+000,,,,,,,,,,,,,,24,1,4.000000e+000,1.027496e+000,0.000000e+000,0,,0,
1418234686.673,,1.000000e+002,1.287660e+002,4.721109e-002,0.000000e+000,3,9.966468e-001,0.000000e+000,,,,,,,,,,,,,,24,1,4.000000e+000,8.936005e-001,0.000000e+000,0,,0,
1418234707.133,,1.000000e+002,1.297941e+002,4.699943e-002,0.000000e+000,3,9.966758e-001,0.000000e+000,,,,,,,,,,,,,,24,1,4.000000e+000,9.498901e-001,0.000000e+000,0,,0,
1418234765.476,,1.000000e+002,1.326167e+002,4.638942e-002,0.000000e+000,3,9.966050e-001,0.000000e+000,,,,,,,,,,,,,,24,1,4.000000e+000,8.410950e-001,0.000000e+000,0,,0,
1418234787.257,,1.000000e+002,1.336090e+002,4.617717e-002,0.000000e+000,3,9.966367e-001,0.000000e+000,,,,,,,,,,,,,,24,1,4.000000e+000,9.474945e-001,0.000000e+000,0,,0,
1418234806.218,,1.000000e+002,1.345587e+002,4.596981e-002,0.000000e+000,3,9.967468e-001,0.000000e+000,,,,,,,,,,,,,,24,1,4.000000e+000,8.526001e-001,0.000000e+000,0,,0,
1418234825.296,,1.000000e+002,1.354955e+002,4.578390e-002,0.000000e+000,3,9.967262e-001,0.000000e+000,,,,,,,,,,,,,,24,1,4.000000e+000,8.272095e-001,0.000000e+000,0,,0,
1418234844.788,,1.000000e+002,1.363894e+002,4.560020e-002,0.000000e+000,3,9.967479e-001,0.000000e+000,,,,,,,,,,,,,,24,1,4.000000e+000,8.587952e-001,0.000000e+000,0,,0,
1418234864.342,,1.000000e+002,1.372975e+002,4.540176e-002,0.000000e+000,3,9.966628e-001,0.000000e+000,,,,,,,,,,,,,,24,1,4.000000e+000,8.544006e-001,0.000000e+000,0,,0,
1418234883.725,,1.000000e+002,1.381714e+002,4.520788e-002,0.000000e+000,3,9.966528e-001,0.000000e+000,,,,,,,,,,,,,,24,1,4.000000e+000,7.743988e-001,0.000000e+000,0,,0,
1418234922.240,,1.000000e+002,1.399290e+002,4.484020e-002,0.000000e+000,3,9.967957e-001,0.000000e+000,,,,,,,,,,,,,,24,1,4.000000e+000,8.265991e-001,0.000000e+000,0,,0,
1418234941.505,,1.000000e+002,1.407892e+002,4.465432e-002,0.000000e+000,3,9.968202e-001,0.000000e+000,,,,,,,,,,,,,,24,1,4.000000e+000,8.937988e-001,0.000000e+000,0,,0,
1418234962.068,,1.000000e+002,1.417216e+002,4.446192e-002,0.000000e+000,3,9.967811e-001,0.000000e+000,,,,,,,,,,,,,,24,1,4.000000e+000,9.710999e-001,0.000000e+000,0,,0,
1418234981.997,,1.000000e+002,1.427004e+002,4.426792e-002,0.000000e+000,3,9.967936e-001,0.000000e+000,,,,,,,,,,,,,,24,1,4.000000e+000,8.839874e-001,0.000000e+000,0,,0,
1418235000.997,,1.000000e+002,1.436308e+002,4.406416e-002,0.000000e+000,3,9.967038e-001,0.000000e+000,,,,,,,,,,,,,,24,1,4.000000e+000,8.652039e-001,0.000000e+000,0,,0,
1418235019.965,,1.000000e+002,1.445753e+002,4.387446e-002,0.000000e+000,3,9.966676e-001,0.000000e+000,,,,,,,,,,,,,,24,1,4.000000e+000,9.105072e-001,0.000000e+000,0,,0,
1418235039.246,,1.000000e+002,1.455428e+002,4.367637e-002,0.000000e+000,3,9.966425e-001,0.000000e+000,,,,,,,,,,,,,,24,1,4.000000e+000,9.098969e-001,0.000000e+000,0,,0,
1418235059.730,,1.000000e+002,1.465667e+002,4.350461e-002,0.000000e+000,3,9.966901e-001,0.000000e+000,,,,,,,,,,,,,,24,1,4.000000e+000,9.140015e-001,0.000000e+000,0,,0,
1418235119.542,,1.000000e+002,1.495910e+002,4.288960e-002,0.000000e+000,3,9.965257e-001,0.000000e+000,,,,,,,,,,,,,,24,1,4.000000e+000,9.465027e-001,0.000000e+000,0,,0,
1418235139.964,,1.000000e+002,1.506112e+002,4.269168e-002,0.000000e+000,3,9.965910e-001,0.000000e+000,,,,,,,,,,,,,,24,1,4.000000e+000,8.665924e-001,0.000000e+000,0,,0,
1418235160.471,,1.000000e+002,1.515693e+002,4.249442e-002,0.000000e+000,3,9.965923e-001,0.000000e+000,,,,,,,,,,,,,,24,1,4.000000e+000,8.372040e-001,0.000000e+000,0,,0,
1418235180.494,,1.000000e+002,1.525282e+002,4.230310e-002,0.000000e+000,3,9.965641e-001,0.000000e+000,,,,,,,,,,,,,,24,1,4.000000e+000,8.655090e-001,0.000000e+000,0,,0,
1418235199.893,,1.000000e+002,1.534532e+002,4.212641e-002,0.000000e+000,3,9.967011e-001,0.000000e+000,,,,,,,,,,,,,,24,1,4.000000e+000,8.846893e-001,0.000000e+000,0,,0,
1418235218.533,,1.000000e+002,1.543195e+002,4.195468e-002,0.000000e+000,3,9.967975e-001,0.000000e+000,,,,,,,,,,,,,,24,1,4.000000e+000,7.653961e-001,0.000000e+000,0,,0,
1418235279.501,,1.000000e+002,1.571160e+002,4.142101e-002,0.000000e+000,3,9.966611e-001,0.000000e+000,,,,,,,,,,,,,,24,1,4.000000e+000,9.547119e-001,0.000000e+000,0,,0,
1418235300.196,,1.000000e+002,1.581295e+002,4.123038e-002,0.000000e+000,3,9.966113e-001,0.000000e+000,,,,,,,,,,,,,,24,1,4.000000e+000,9.667053e-001,0.000000e+000,0,,0,
1418235320.946,,1.000000e+002,1.591558e+002,4.104864e-002,0.000000e+000,3,9.966454e-001,0.000000e+000,,,,,,,,,,,,,,24,1,4.000000e+000,9.788971e-001,0.000000e+000,0,,0,
1418235340.571,,1.000000e+002,1.601600e+002,4.086467e-002,0.000000e+000,3,9.966905e-001,0.000000e+000,,,,,,,,,,,,,,24,1,4.000000e+000,9.215088e-001,0.000000e+000,0,,0,
1418235359.820,,1.000000e+002,1.611317e+002,4.069159e-002,0.000000e+000,3,9.967625e-001,0.000000e+000,,,,,,,,,,,,,,24,1,4.000000e+000,9.123077e-001,0.000000e+000,0,,0,
1418235381.078,,1.000000e+002,1.621162e+002,4.050396e-002,0.000000e+000,3,9.967486e-001,0.000000e+000,,,,,,,,,,,,,,24,1,4.000000e+000,9.456940e-001,0.000000e+000,0,,0,
1418235401.023,,1.000000e+002,1.630943e+002,4.032807e-002,0.000000e+000,3,9.967090e-001,0.000000e+000,,,,,,,,,,,,,,24,1,4.000000e+000,8.981018e-001,0.000000e+000,0,,0,
# 1418235421.874,,1.000000e+002,1.641194e+002,6.497855e-002,0.000000e+000,3,4.926790e-001,0.000000e+000,,,,,,,,,,,,,,24,1,4.000000e+000,9.454956e-001,0.000000e+000,0,,0,
1418235442.577,,1.000000e+002,1.651227e+002,3.996154e-002,0.000000e+000,3,9.965811e-001,0.000000e+000,,,,,,,,,,,,,,24,1,4.000000e+000,9.568024e-001,0.000000e+000,0,,0,
1418235463.100,,1.000000e+002,1.661248e+002,3.978356e-002,0.000000e+000,3,9.966269e-001,0.000000e+000,,,,,,,,,,,,,,24,1,4.000000e+000,9.414978e-001,0.000000e+000,0,,0,
1418235483.061,,1.000000e+002,1.670955e+002,3.960774e-002,0.000000e+000,3,9.966314e-001,0.000000e+000,,,,,,,,,,,,,,24,1,4.000000e+000,8.930054e-001,0.000000e+000,0,,0,
1418235502.826,,1.000000e+002,1.681048e+002,3.943664e-002,0.000000e+000,3,9.966002e-001,0.000000e+000,,,,,,,,,,,,,,24,1,4.000000e+000,8.981018e-001,0.000000e+000,0,,0,
1418235523.631,,1.000000e+002,1.690602e+002,3.926381e-002,0.000000e+000,3,9.966377e-001,0.000000e+000,,,,,,,,,,,,,,24,1,4.000000e+000,1.012695e+000,0.000000e+000,0,,0,
1418235543.021,,1.000000e+002,1.701007e+002,3.909077e-002,0.000000e+000,3,9.966546e-001,0.000000e+000,,,,,,,,,,,,,,24,1,4.000000e+000,8.578033e-001,0.000000e+000,0,,0,
1418235562.763,,1.000000e+002,1.710696e+002,3.891739e-002,0.000000e+000,3,9.965740e-001,0.000000e+000,,,,,,,,,,,,,,24,1,4.000000e+000,8.560028e-001,0.000000e+000,0,,0,
1418235581.935,,1.000000e+002,1.720266e+002,3.875173e-002,0.000000e+000,3,9.965110e-001,0.000000e+000,,,,,,,,,,,,,,24,1,4.000000e+000,8.540039e-001,0.000000e+000,0,,0,
1418235604.012,,1.000000e+002,1.730317e+002,7.135232e-003,0.000000e+000,2,0.000000e+000,0.000000e+000,,,,,,,,,,,,,,24,1,4.000000e+000,9.386139e-001,0.000000e+000,0,,0,
1418235623.903,,1.000000e+002,1.741385e+002,3.840141e-002,0.000000e+000,3,9.965567e-001,0.000000e+000,,,,,,,,,,,,,,24,1,4.000000e+000,9.387054e-001,0.000000e+000,0,,0,
1418235643.473,,1.000000e+002,1.751115e+002,3.823737e-002,0.000000e+000,3,9.966027e-001,0.000000e+000,,,,,,,,,,,,,,24,1,4.000000e+000,9.017944e-001,0.000000e+000,0,,0,
1418235663.355,,1.000000e+002,1.760835e+002,3.807259e-002,0.000000e+000,3,9.966671e-001,0.000000e+000,,,,,,,,,,,,,,24,1,4.000000e+000,9.474030e-001,0.000000e+000,0,,0,
1418235684.199,,1.000000e+002,1.771203e+002,3.790192e-002,0.000000e+000,3,9.967053e-001,0.000000e+000,,,,,,,,,,,,,,24,1,4.000000e+000,1.006500e+000,0.000000e+000,0,,0,
1418235704.285,,1.000000e+002,1.781263e+002,3.773355e-002,0.000000e+000,3,9.966092e-001,0.000000e+000,,,,,,,,,,,,,,24,1,4.000000e+000,1.005402e+000,0.000000e+000,0,,0,
1418235723.347,,1.000000e+002,1.791276e+002,3.757043e-002,0.000000e+000,3,9.965585e-001,0.000000e+000,,,,,,,,,,,,,,24,1,4.000000e+000,7.885895e-001,0.000000e+000,0,,0,
1418235742.847,,1.000000e+002,1.800753e+002,3.741620e-002,0.000000e+000,3,9.965009e-001,0.000000e+000,,,,,,,,,,,,,,24,1,4.000000e+000,8.963928e-001,0.000000e+000,0,,0,
1418235762.854,,1.000000e+002,1.810734e+002,3.725145e-002,0.000000e+000,3,9.965078e-001,0.000000e+000,,,,,,,,,,,,,,24,1,4.000000e+000,8.871918e-001,0.000000e+000,0,,0,
1418235783.213,,1.000000e+002,1.820636e+002,3.306932e-002,0.000000e+000,3,5.476536e-001,0.000000e+000,,,,,,,,,,,,,,24,1,4.000000e+000,9.794006e-001,0.000000e+000,0,,0,
1418235802.276,,1.000000e+002,1.830377e+002,3.693993e-002,0.000000e+000,3,9.965889e-001,0.000000e+000,,,,,,,,,,,,,,24,1,4.000000e+000,8.665924e-001,0.000000e+000,0,,0,
1418235822.174,,1.000000e+002,1.839737e+002,3.679485e-002,0.000000e+000,3,9.966275e-001,0.000000e+000,,,,,,,,,,,,,,24,1,4.000000e+000,9.149933e-001,0.000000e+000,0,,0,
1418235841.228,,1.000000e+002,1.849223e+002,3.664206e-002,0.000000e+000,3,9.966716e-001,0.000000e+000,,,,,,,,,,,,,,24,1,4.000000e+000,7.864990e-001,0.000000e+000,0,,0,
1418235860.486,,1.000000e+002,1.858047e+002,3.650424e-002,0.000000e+000,3,9.965796e-001,0.000000e+000,,,,,,,,,,,,,,24,1,4.000000e+000,7.805023e-001,0.000000e+000,0,,0,
1418235879.603,,1.000000e+002,1.866617e+002,3.636871e-002,0.000000e+000,3,9.964886e-001,0.000000e+000,,,,,,,,,,,,,,24,1,4.000000e+000,7.474976e-001,0.000000e+000,0,,0,
1418235900.774,,1.000000e+002,1.875437e+002,3.623213e-002,0.000000e+000,3,9.964938e-001,0.000000e+000,,,,,,,,,,,,,,24,1,4.000000e+000,9.093018e-001,0.000000e+000,0,,0,
1418235919.899,,1.000000e+002,1.884366e+002,3.609060e-002,0.000000e+000,3,9.964804e-001,0.000000e+000,,,,,,,,,,,,,,24,1,4.000000e+000,7.680969e-001,0.000000e+000,0,,0,
1418235939.149,,1.000000e+002,1.893105e+002,3.596159e-002,0.000000e+000,3,9.965596e-001,0.000000e+000,,,,,,,,,,,,,,24,1,4.000000e+000,8.025055e-001,0.000000e+000,0,,0,
1418235997.765,,1.000000e+002,1.919593e+002,3.556113e-002,0.000000e+000,3,9.966186e-001,0.000000e+000,,,,,,,,,,,,,,24,1,4.000000e+000,8.665924e-001,0.000000e+000,0,,0,
1418236018.515,,1.000000e+002,1.929151e+002,3.541658e-002,0.000000e+000,3,9.965838e-001,0.000000e+000,,,,,,,,,,,,,,24,1,4.000000e+000,8.464966e-001,0.000000e+000,0,,0,
1418236038.632,,1.000000e+002,1.938551e+002,3.527879e-002,0.000000e+000,3,9.965183e-001,0.000000e+000,,,,,,,,,,,,,,24,1,4.000000e+000,9.192047e-001,0.000000e+000,0,,0,
1418236059.264,,1.000000e+002,1.948510e+002,3.513674e-002,0.000000e+000,3,9.964052e-001,0.000000e+000,,,,,,,,,,,,,,24,1,4.000000e+000,8.849030e-001,0.000000e+000,0,,0,
1418236078.452,,1.000000e+002,1.957580e+002,3.499696e-002,0.000000e+000,3,9.963972e-001,0.000000e+000,,,,,,,,,,,,,,24,1,4.000000e+000,8.269958e-001,0.000000e+000,0,,0,
1418236097.967,,1.000000e+002,1.967104e+002,3.486088e-002,0.000000e+000,3,9.963955e-001,0.000000e+000,,,,,,,,,,,,,,24,1,4.000000e+000,8.865967e-001,0.000000e+000,0,,0,
1418236116.514,,1.000000e+002,1.976268e+002,3.472180e-002,0.000000e+000,3,9.964333e-001,0.000000e+000,,,,,,,,,,,,,,24,1,4.000000e+000,8.424072e-001,0.000000e+000,0,,0,
1418236177.161,,1.000000e+002,2.005804e+002,3.430446e-002,0.000000e+000,3,9.964992e-001,0.000000e+000,,,,,,,,,,,,,,24,1,4.000000e+000,9.360046e-001,0.000000e+000,0,,0,
1418236195.888,,1.000000e+002,2.015206e+002,3.416613e-002,0.000000e+000,3,9.965307e-001,0.000000e+000,,,,,,,,,,,,,,24,1,4.000000e+000,8.671875e-001,0.000000e+000,0,,0,
1418236215.887,,1.000000e+002,2.025009e+002,3.403067e-002,0.000000e+000,3,9.965568e-001,0.000000e+000,,,,,,,,,,,,,,24,1,4.000000e+000,9.066925e-001,0.000000e+000,0,,0,
1418236235.137,,1.000000e+002,2.034705e+002,3.389264e-002,0.000000e+000,3,9.964883e-001,0.000000e+000,,,,,,,,,,,,,,24,1,4.000000e+000,8.441925e-001,0.000000e+000,0,,0,
1418236255.520,,1.000000e+002,2.044494e+002,3.375290e-002,0.000000e+000,3,9.964868e-001,0.000000e+000,,,,,,,,,,,,,,24,1,4.000000e+000,8.917999e-001,0.000000e+000,0,,0,
1418236275.301,,1.000000e+002,2.054134e+002,3.361209e-002,0.000000e+000,3,9.964635e-001,0.000000e+000,,,,,,,,,,,,,,24,1,4.000000e+000,9.402008e-001,0.000000e+000,0,,0,
1418236294.144,,1.000000e+002,2.063246e+002,3.339887e-002,0.000000e+000,3,9.957415e-001,0.000000e+000,,,,,,,,,,,,,,24,1,4.000000e+000,8.822021e-001,0.000000e+000,0,,0,
1418236314.714,,1.000000e+002,2.072934e+002,3.334573e-002,0.000000e+000,3,9.964338e-001,0.000000e+000,,,,,,,,,,,,,,24,1,4.000000e+000,9.575958e-001,0.000000e+000,0,,0,
1418236332.847,,1.000000e+002,2.082595e+002,3.321380e-002,0.000000e+000,3,9.964577e-001,0.000000e+000,,,,,,,,,,,,,,24,1,4.000000e+000,8.592987e-001,0.000000e+000,0,,0,
1418236352.675,,1.000000e+002,2.092518e+002,3.308188e-002,0.000000e+000,3,9.964724e-001,0.000000e+000,,,,,,,,,,,,,,24,1,4.000000e+000,9.093933e-001,0.000000e+000,0,,0,
1418236371.245,,1.000000e+002,2.102240e+002,3.294914e-002,0.000000e+000,3,9.964779e-001,0.000000e+000,,,,,,,,,,,,,,24,1,4.000000e+000,8.168945e-001,0.000000e+000,0,,0,
1418236391.416,,1.000000e+002,2.112101e+002,3.282119e-002,0.000000e+000,3,9.965050e-001,0.000000e+000,,,,,,,,,,,,,,24,1,4.000000e+000,9.692993e-001,0.000000e+000,0,,0,
1418236410.932,,1.000000e+002,2.121923e+002,3.268566e-002,0.000000e+000,3,9.965794e-001,0.000000e+000,,,,,,,,,,,,,,24,1,4.000000e+000,9.098053e-001,0.000000e+000,0,,0,
1418236430.353,,1.000000e+002,2.131838e+002,3.255334e-002,0.000000e+000,3,9.965964e-001,0.000000e+000,,,,,,,,,,,,,,24,1,4.000000e+000,8.491058e-001,0.000000e+000,0,,0,
1418236449.486,,1.000000e+002,2.141413e+002,3.242842e-002,0.000000e+000,3,9.966691e-001,0.000000e+000,,,,,,,,,,,,,,24,1,4.000000e+000,8.744049e-001,0.000000e+000,0,,0,
1418236472.267,,1.000000e+002,2.151385e+002,-1.036651e-002,0.000000e+000,2,0.000000e+000,0.000000e+000,,,,,,,,,,,,,,24,1,4.000000e+000,9.444885e-001,0.000000e+000,0,,0,
1418236491.595,,1.000000e+002,2.162119e+002,3.215430e-002,0.000000e+000,3,9.965745e-001,0.000000e+000,,,,,,,,,,,,,,24,1,4.000000e+000,9.004974e-001,0.000000e+000,0,,0,
1418236511.079,,1.000000e+002,2.171295e+002,3.202924e-002,0.000000e+000,3,9.966085e-001,0.000000e+000,,,,,,,,,,,,,,24,1,4.000000e+000,8.453064e-001,0.000000e+000,0,,0,
1418236531.516,,1.000000e+002,2.180554e+002,3.190659e-002,0.000000e+000,3,9.965798e-001,0.000000e+000,,,,,,,,,,,,,,24,1,4.000000e+000,8.798981e-001,0.000000e+000,0,,0,
1418236551.289,,1.000000e+002,2.190074e+002,3.178242e-002,0.000000e+000,3,9.965208e-001,0.000000e+000,,,,,,,,,,,,,,24,1,4.000000e+000,8.601990e-001,0.000000e+000,0,,0,
1418236571.336,,1.000000e+002,2.199264e+002,3.166310e-002,0.000000e+000,3,9.965422e-001,0.000000e+000,,,,,,,,,,,,,,24,1,4.000000e+000,8.122101e-001,0.000000e+000,0,,0,
1418236591.961,,1.000000e+002,2.209373e+002,3.153623e-002,0.000000e+000,3,9.965085e-001,0.000000e+000,,,,,,,,,,,,,,24,1,4.000000e+000,9.316101e-001,0.000000e+000,0,,0,
1418236612.585,,1.000000e+002,2.219481e+002,3.140645e-002,0.000000e+000,3,9.964751e-001,0.000000e+000,,,,,,,,,,,,,,24,1,4.000000e+000,9.777985e-001,0.000000e+000,0,,0,
1418236632.077,,1.000000e+002,2.229540e+002,3.128191e-002,0.000000e+000,3,9.964271e-001,0.000000e+000,,,,,,,,,,,,,,24,1,4.000000e+000,9.394073e-001,0.000000e+000,0,,0,
1418236650.804,,1.000000e+002,2.238828e+002,1.615541e-002,0.000000e+000,3,0.000000e+000,0.000000e+000,,,,,,,,,,,,,,24,1,4.000000e+000,8.228912e-001,0.000000e+000,0,,0,
1418236671.225,,1.000000e+002,2.248441e+002,3.104107e-002,0.000000e+000,3,9.965219e-001,0.000000e+000,,,,,,,,,,,,,,24,1,4.000000e+000,9.074097e-001,0.000000e+000,0,,0,
1418236691.374,,1.000000e+002,2.257941e+002,3.091690e-002,0.000000e+000,3,9.965141e-001,0.000000e+000,,,,,,,,,,,,,,24,1,4.000000e+000,8.956909e-001,0.000000e+000,0,,0,
1418236711.631,,1.000000e+002,2.267474e+002,3.079815e-002,0.000000e+000,3,9.965431e-001,0.000000e+000,,,,,,,,,,,,,,24,1,4.000000e+000,9.131927e-001,0.000000e+000,0,,0,
1418236732.584,,1.000000e+002,2.277188e+002,3.067868e-002,0.000000e+000,3,9.965590e-001,0.000000e+000,,,,,,,,,,,,,,24,1,4.000000e+000,9.309998e-001,0.000000e+000,0,,0,
1418236752.232,,1.000000e+002,2.286935e+002,3.063952e-002,0.000000e+000,3,9.970726e-001,0.000000e+000,,,,,,,,,,,,,,24,1,4.000000e+000,8.193054e-001,0.000000e+000,0,,0,
1418236772.419,,1.000000e+002,2.296366e+002,3.036465e-002,0.000000e+000,3,9.960773e-001,0.000000e+000,,,,,,,,,,,,,,24,1,4.000000e+000,8.865967e-001,0.000000e+000,0,,0,
1418236793.482,,1.000000e+002,2.305826e+002,3.034306e-002,0.000000e+000,3,9.964922e-001,0.000000e+000,,,,,,,,,,,,,,24,1,4.000000e+000,9.244995e-001,0.000000e+000,0,,0,
1418236815.106,,1.000000e+002,2.315876e+002,3.020602e-002,0.000000e+000,3,9.965252e-001,0.000000e+000,,,,,,,,,,,,,,24,1,4.000000e+000,9.019012e-001,0.000000e+000,0,,0,
1418236835.833,,1.000000e+002,2.326083e+002,3.008391e-002,0.000000e+000,3,9.965384e-001,0.000000e+000,,,,,,,,,,,,,,24,1,4.000000e+000,9.543915e-001,0.000000e+000,0,,0,
1418236855.910,,1.000000e+002,2.336380e+002,2.996751e-002,0.000000e+000,3,9.965049e-001,0.000000e+000,,,,,,,,,,,,,,24,1,4.000000e+000,9.183044e-001,0.000000e+000,0,,0,
1418236876.481,,1.000000e+002,2.346338e+002,2.984380e-002,0.000000e+000,3,9.965065e-001,0.000000e+000,,,,,,,,,,,,,,24,1,4.000000e+000,9.683075e-001,0.000000e+000,0,,0,
1418236897.293,,1.000000e+002,2.355902e+002,2.972496e-002,0.000000e+000,3,9.965194e-001,0.000000e+000,,,,,,,,,,,,,,24,1,4.000000e+000,9.445953e-001,0.000000e+000,0,,0,
1418236918.496,,1.000000e+002,2.366618e+002,2.960123e-002,0.000000e+000,3,9.965292e-001,0.000000e+000,,,,,,,,,,,,,,24,1,4.000000e+000,1.006897e+000,0.000000e+000,0,,0,
1418236939.878,,1.000000e+002,2.377433e+002,2.947463e-002,0.000000e+000,3,9.964680e-001,0.000000e+000,,,,,,,,,,,,,,24,1,4.000000e+000,9.622955e-001,0.000000e+000,0,,0,
1418236962.362,,1.000000e+002,2.387809e+002,2.934796e-002,0.000000e+000,3,9.964537e-001,0.000000e+000,,,,,,,,,,,,,,24,1,4.000000e+000,1.112701e+000,0.000000e+000,0,,0,
1418236983.682,,1.000000e+002,2.399041e+002,2.922164e-002,0.000000e+000,3,9.965013e-001,0.000000e+000,,,,,,,,,,,,,,24,1,4.000000e+000,1.024307e+000,0.000000e+000,0,,0,
1418237046.338,,1.000000e+002,2.430571e+002,2.885106e-002,0.000000e+000,3,9.965382e-001,0.000000e+000,,,,,,,,,,,,,,24,1,4.000000e+000,9.728088e-001,0.000000e+000,0,,0,
1418237067.119,,1.000000e+002,2.440795e+002,2.873208e-002,0.000000e+000,3,9.965075e-001,0.000000e+000,,,,,,,,,,,,,,24,1,4.000000e+000,9.812012e-001,0.000000e+000,0,,0,
1418237088.611,,1.000000e+002,2.451798e+002,2.860889e-002,0.000000e+000,3,9.964831e-001,0.000000e+000,,,,,,,,,,,,,,24,1,4.000000e+000,1.036301e+000,0.000000e+000,0,,0,
1418237108.814,,1.000000e+002,2.462318e+002,2.848759e-002,0.000000e+000,3,9.964760e-001,0.000000e+000,,,,,,,,,,,,,,24,1,4.000000e+000,8.827057e-001,0.000000e+000,0,,0,
1418237129.688,,1.000000e+002,2.471998e+002,2.837165e-002,0.000000e+000,3,9.964374e-001,0.000000e+000,,,,,,,,,,,,,,24,1,4.000000e+000,9.365997e-001,0.000000e+000,0,,0,
1418237150.993,,1.000000e+002,2.482227e+002,2.825739e-002,0.000000e+000,3,9.965475e-001,0.000000e+000,,,,,,,,,,,,,,24,1,4.000000e+000,9.208984e-001,0.000000e+000,0,,0,
1418237170.899,,1.000000e+002,2.491945e+002,2.814853e-002,0.000000e+000,3,9.965887e-001,0.000000e+000,,,,,,,,,,,,,,24,1,4.000000e+000,8.569031e-001,0.000000e+000,0,,0,
1418237233.406,,1.000000e+002,2.521091e+002,2.782006e-002,0.000000e+000,3,9.965958e-001,0.000000e+000,,,,,,,,,,,,,,24,1,4.000000e+000,9.017944e-001,0.000000e+000,0,,0,
1418237254.023,,1.000000e+002,2.530509e+002,2.881121e-002,0.000000e+000,3,9.764327e-001,0.000000e+000,,,,,,,,,,,,,,24,1,4.000000e+000,8.840942e-001,0.000000e+000,0,,0,
1418237274.530,,1.000000e+002,2.540063e+002,2.760997e-002,0.000000e+000,3,9.966018e-001,0.000000e+000,,,,,,,,,,,,,,24,1,4.000000e+000,9.281006e-001,0.000000e+000,0,,0,
1418237294.397,,1.000000e+002,2.549377e+002,2.750786e-002,0.000000e+000,3,9.965894e-001,0.000000e+000,,,,,,,,,,,,,,24,1,4.000000e+000,7.854004e-001,0.000000e+000,0,,0,
1418237314.287,,1.000000e+002,2.558386e+002,2.741407e-002,0.000000e+000,3,9.965286e-001,0.000000e+000,,,,,,,,,,,,,,24,1,4.000000e+000,8.414154e-001,0.000000e+000,0,,0,
1418237376.177,,1.000000e+002,2.587411e+002,2.709805e-002,0.000000e+000,3,9.965234e-001,0.000000e+000,,,,,,,,,,,,,,24,1,4.000000e+000,8.992920e-001,0.000000e+000,0,,0,
1418237396.200,,1.000000e+002,2.596565e+002,2.699762e-002,0.000000e+000,3,9.965814e-001,0.000000e+000,,,,,,,,,,,,,,24,1,4.000000e+000,8.541870e-001,0.000000e+000,0,,0,
1418237418.599,,1.000000e+002,2.606832e+002,2.688722e-002,0.000000e+000,3,9.965547e-001,0.000000e+000,,,,,,,,,,,,,,24,1,4.000000e+000,9.914856e-001,0.000000e+000,0,,0,
1418237438.395,,1.000000e+002,2.616225e+002,2.678426e-002,0.000000e+000,3,9.966184e-001,0.000000e+000,,,,,,,,,,,,,,24,1,4.000000e+000,8.870239e-001,0.000000e+000,0,,0,
1418237457.223,,1.000000e+002,2.625356e+002,2.668869e-002,0.000000e+000,3,9.966612e-001,0.000000e+000,,,,,,,,,,,,,,24,1,4.000000e+000,7.411804e-001,0.000000e+000,0,,0,
1418237476.285,,1.000000e+002,2.633728e+002,2.659819e-002,0.000000e+000,3,9.966738e-001,0.000000e+000,,,,,,,,,,,,,,24,1,4.000000e+000,7.608032e-001,0.000000e+000,0,,0,
1418237495.309,,1.000000e+002,2.642934e+002,2.649889e-002,0.000000e+000,3,9.966108e-001,0.000000e+000,,,,,,,,,,,,,,24,1,4.000000e+000,8.930054e-001,0.000000e+000,0,,0,
1418237552.659,,1.000000e+002,2.671943e+002,2.619836e-002,0.000000e+000,3,9.966068e-001,0.000000e+000,,,,,,,,,,,,,,24,1,4.000000e+000,8.594055e-001,0.000000e+000,0,,0,
1418237572.261,,1.000000e+002,2.681293e+002,2.609951e-002,0.000000e+000,3,9.966458e-001,0.000000e+000,,,,,,,,,,,,,,24,1,4.000000e+000,9.142761e-001,0.000000e+000,0,,0,
1418237591.182,,1.000000e+002,2.691063e+002,2.600184e-002,0.000000e+000,3,9.966186e-001,0.000000e+000,,,,,,,,,,,,,,24,1,4.000000e+000,9.145203e-001,0.000000e+000,0,,0,
1418237610.721,,1.000000e+002,2.700594e+002,2.589996e-002,0.000000e+000,3,9.966227e-001,0.000000e+000,,,,,,,,,,,,,,24,1,4.000000e+000,9.916992e-001,0.000000e+000,0,,0,
1418237630.229,,1.000000e+002,2.710408e+002,2.580026e-002,0.000000e+000,3,9.965146e-001,0.000000e+000,,,,,,,,,,,,,,24,1,4.000000e+000,9.711914e-001,0.000000e+000,0,,0,
1418237649.768,,1.000000e+002,2.720228e+002,2.569886e-002,0.000000e+000,3,9.964396e-001,0.000000e+000,,,,,,,,,,,,,,24,1,4.000000e+000,9.928894e-001,0.000000e+000,0,,0,
1418237669.252,,1.000000e+002,2.730089e+002,2.559745e-002,0.000000e+000,3,9.964623e-001,0.000000e+000,,,,,,,,,,,,,,24,1,4.000000e+000,9.792175e-001,0.000000e+000,0,,0,
1418237729.860,,1.000000e+002,2.760250e+002,2.529084e-002,0.000000e+000,3,9.965472e-001,0.000000e+000,,,,,,,,,,,,,,24,1,4.000000e+000,1.046814e+000,0.000000e+000,0,,0,
1418237749.954,,1.000000e+002,2.770350e+002,2.518433e-002,0.000000e+000,3,9.965512e-001,0.000000e+000,,,,,,,,,,,,,,24,1,4.000000e+000,9.732056e-001,0.000000e+000,0,,0,
1418237768.352,,1.000000e+002,2.780266e+002,2.509158e-002,0.000000e+000,3,9.965333e-001,0.000000e+000,,,,,,,,,,,,,,24,1,4.000000e+000,8.010864e-001,0.000000e+000,0,,0,
1418237787.492,,1.000000e+002,2.789544e+002,2.499710e-002,0.000000e+000,3,9.965402e-001,0.000000e+000,,,,,,,,,,,,,,24,1,4.000000e+000,8.443909e-001,0.000000e+000,0,,0,
1418237806.187,,1.000000e+002,2.798853e+002,2.490461e-002,0.000000e+000,3,9.965180e-001,0.000000e+000,,,,,,,,,,,,,,24,1,4.000000e+000,9.113159e-001,0.000000e+000,0,,0,
1418237826.039,,1.000000e+002,2.808036e+002,2.481211e-002,0.000000e+000,3,9.965812e-001,0.000000e+000,,,,,,,,,,,,,,24,1,4.000000e+000,9.252930e-001,0.000000e+000,0,,0,
1418237844.765,,1.000000e+002,2.817396e+002,2.471936e-002,0.000000e+000,3,9.965809e-001,0.000000e+000,,,,,,,,,,,,,,24,1,4.000000e+000,8.395081e-001,0.000000e+000,0,,0,
1418237864.609,,1.000000e+002,2.826478e+002,2.462985e-002,0.000000e+000,3,9.966301e-001,0.000000e+000,,,,,,,,,,,,,,24,1,4.000000e+000,8.684998e-001,0.000000e+000,0,,0,
1418237921.975,,1.000000e+002,2.854058e+002,2.435914e-002,0.000000e+000,3,9.965878e-001,0.000000e+000,,,,,,,,,,,,,,24,1,4.000000e+000,7.919006e-001,0.000000e+000,0,,0,
1418237940.975,,1.000000e+002,2.862837e+002,2.427425e-002,0.000000e+000,3,9.966285e-001,0.000000e+000,,,,,,,,,,,,,,24,1,4.000000e+000,8.528137e-001,0.000000e+000,0,,0,
1418237961.865,,1.000000e+002,2.872034e+002,2.418514e-002,0.000000e+000,3,9.966471e-001,0.000000e+000,,,,,,,,,,,,,,24,1,4.000000e+000,8.907166e-001,0.000000e+000,0,,0,
1418237982.224,,1.000000e+002,2.881374e+002,2.408954e-002,0.000000e+000,3,9.966894e-001,0.000000e+000,,,,,,,,,,,,,,24,1,4.000000e+000,8.967896e-001,0.000000e+000,0,,0,
1418238002.794,,1.000000e+002,2.891023e+002,2.399961e-002,0.000000e+000,3,9.965161e-001,0.000000e+000,,,,,,,,,,,,,,24,1,4.000000e+000,8.381958e-001,0.000000e+000,0,,0,
1418238020.833,,1.000000e+002,2.900045e+002,2.391399e-002,0.000000e+000,3,9.965417e-001,0.000000e+000,,,,,,,,,,,,,,24,1,4.000000e+000,8.520203e-001,0.000000e+000,0,,0,
1418238040.489,,1.000000e+002,2.908881e+002,2.382582e-002,0.000000e+000,3,9.965228e-001,0.000000e+000,,,,,,,,,,,,,,24,1,4.000000e+000,9.151917e-001,0.000000e+000,0,,0,
1418238099.902,,1.000000e+002,2.938047e+002,2.355458e-002,0.000000e+000,3,9.965353e-001,0.000000e+000,,,,,,,,,,,,,,24,1,4.000000e+000,8.674927e-001,0.000000e+000,0,,0,
1418238119.644,,1.000000e+002,2.947725e+002,2.346198e-002,0.000000e+000,3,9.965308e-001,0.000000e+000,,,,,,,,,,,,,,24,1,4.000000e+000,9.500122e-001,0.000000e+000,0,,0,
1418238139.261,,1.000000e+002,2.957682e+002,2.337009e-002,0.000000e+000,3,9.965653e-001,0.000000e+000,,,,,,,,,,,,,,24,1,4.000000e+000,8.371887e-001,0.000000e+000,0,,0,
1418238158.089,,1.000000e+002,2.967238e+002,2.328043e-002,0.000000e+000,3,9.966218e-001,0.000000e+000,,,,,,,,,,,,,,24,1,4.000000e+000,8.170776e-001,0.000000e+000,0,,0,
1418238179.042,,1.000000e+002,2.976606e+002,2.318757e-002,0.000000e+000,3,9.965935e-001,0.000000e+000,,,,,,,,,,,,,,24,1,4.000000e+000,9.525146e-001,0.000000e+000,0,,0,
1418238198.018,,1.000000e+002,2.986032e+002,2.295859e-002,0.000000e+000,3,0.000000e+000,0.000000e+000,,,,,,,,,,,,,,24,1,4.000000e+000,8.457031e-001,0.000000e+000,0,,0,
1418238218.549,,1.000000e+002,2.995481e+002,2.301131e-002,0.000000e+000,3,9.964654e-001,0.000000e+000,,,,,,,,,,,,,,24,1,4.000000e+000,9.216003e-001,0.000000e+000,0,,0,
1418238470.804,,1.000000e+002,3.000045e+002,2.290664e-002,0.000000e+000,3,9.965085e-001,0.000000e+000,,,,,,,,,,,,,,24,1,4.000000e+000,8.819580e-003,0.000000e+000,0,,0,
1418238487.679,,1.000000e+002,3.000001e+002,2.288952e-002,0.000000e+000,3,9.964765e-001,0.000000e+000,,,,,,,,,,,,,,24,1,4.000000e+000,0.000000e+000,0.000000e+000,0,,0,
1418238504.569,,1.000000e+002,3.000045e+002,2.288185e-002,0.000000e+000,3,9.964697e-001,0.000000e+000,,,,,,,,,,,,,,24,1,4.000000e+000,8.819580e-003,0.000000e+000,0,,0,
1418238521.475,,1.000000e+002,3.000089e+002,2.287845e-002,0.000000e+000,3,9.964818e-001,0.000000e+000,,,,,,,,,,,,,,24,1,4.000000e+000,0.000000e+000,0.000000e+000,0,,0,
1418238538.928,,1.000000e+002,3.000089e+002,2.287743e-002,0.000000e+000,3,9.964640e-001,0.000000e+000,,,,,,,,,,,,,,24,1,4.000000e+000,1.760864e-002,0.000000e+000,0,,0,
1418238555.811,,1.000000e+002,3.000133e+002,2.287597e-002,0.000000e+000,3,9.965023e-001,0.000000e+000,,,,,,,,,,,,,,24,1,4.000000e+000,8.789063e-003,0.000000e+000,0,,0,
1418238573.310,,1.000000e+002,3.000089e+002,2.287422e-002,0.000000e+000,3,9.964867e-001,0.000000e+000,,,,,,,,,,,,,,24,1,4.000000e+000,0.000000e+000,0.000000e+000,0,,0,
1418238590.193,,1.000000e+002,3.000133e+002,2.287339e-002,0.000000e+000,3,9.964859e-001,0.000000e+000,,,,,,,,,,,,,,24,1,4.000000e+000,8.789063e-003,0.000000e+000,0,,0,
1418238607.060,,1.000000e+002,3.000133e+002,2.287313e-002,0.000000e+000,3,9.965036e-001,0.000000e+000,,,,,,,,,,,,,,24,1,4.000000e+000,8.789063e-003,0.000000e+000,0,,0,
1418238623.943,,1.000000e+002,3.000089e+002,2.287366e-002,0.000000e+000,3,9.965385e-001,0.000000e+000,,,,,,,,,,,,,,24,1,4.000000e+000,0.000000e+000,0.000000e+000,0,,0,
1418238640.802,,1.000000e+002,3.000089e+002,2.287389e-002,0.000000e+000,3,9.965901e-001,0.000000e+000,,,,,,,,,,,,,,24,1,4.000000e+000,0.000000e+000,0.000000e+000,0,,0,
1418238657.676,,1.000000e+002,3.000045e+002,2.287336e-002,0.000000e+000,3,9.965700e-001,0.000000e+000,,,,,,,,,,,,,,24,1,4.000000e+000,8.819580e-003,0.000000e+000,0,,0,
1418238674.598,,1.000000e+002,3.000045e+002,2.287277e-002,0.000000e+000,3,9.965428e-001,0.000000e+000,,,,,,,,,,,,,,24,1,4.000000e+000,8.819580e-003,0.000000e+000,0,,0,
1418238691.473,,1.000000e+002,3.000089e+002,2.287195e-002,0.000000e+000,3,9.965540e-001,0.000000e+000,,,,,,,,,,,,,,24,1,4.000000e+000,0.000000e+000,0.000000e+000,0,,0,
1418238709.981,,1.000000e+002,3.000089e+002,2.287214e-002,0.000000e+000,3,9.965800e-001,0.000000e+000,,,,,,,,,,,,,,24,1,4.000000e+000,0.000000e+000,0.000000e+000,0,,0,
1418238727.722,,1.000000e+002,3.000133e+002,2.287155e-002,0.000000e+000,3,9.965650e-001,0.000000e+000,,,,,,,,,,,,,,24,1,4.000000e+000,8.789063e-003,0.000000e+000,0,,0,
1418238782.456,,1.000000e+002,3.000089e+002,2.286869e-002,0.000000e+000,3,9.964874e-001,0.000000e+000,,,,,,,,,,,,,,24,1,4.000000e+000,0.000000e+000,0.000000e+000,0,,0,
1418238800.979,,1.000000e+002,3.000045e+002,2.286760e-002,0.000000e+000,3,9.965097e-001,0.000000e+000,,,,,,,,,,,,,,24,1,4.000000e+000,8.819580e-003,0.000000e+000,0,,0,
1418238819.721,,1.000000e+002,3.000045e+002,2.286766e-002,0.000000e+000,3,9.965385e-001,0.000000e+000,,,,,,,,,,,,,,24,1,4.000000e+000,8.819580e-003,0.000000e+000,0,,0,
1418238838.096,,1.000000e+002,3.000045e+002,2.286769e-002,0.000000e+000,3,9.965397e-001,0.000000e+000,,,,,,,,,,,,,,24,1,4.000000e+000,8.819580e-003,0.000000e+000,0,,0,
1418238855.721,,1.000000e+002,3.000089e+002,2.286618e-002,0.000000e+000,3,9.965810e-001,0.000000e+000,,,,,,,,,,,,,,24,1,4.000000e+000,0.000000e+000,0.000000e+000,0,,0,
1418238873.049,,1.000000e+002,3.000045e+002,2.286613e-002,0.000000e+000,3,9.965711e-001,0.000000e+000,,,,,,,,,,,,,,24,1,4.000000e+000,8.819580e-003,0.000000e+000,0,,0,
1418238891.220,,1.000000e+002,3.000001e+002,2.286632e-002,0.000000e+000,3,9.965580e-001,0.000000e+000,,,,,,,,,,,,,,24,1,4.000000e+000,0.000000e+000,0.000000e+000,0,,0,
1418238910.275,,1.000000e+002,3.000001e+002,2.286600e-002,0.000000e+000,3,9.965616e-001,0.000000e+000,,,,,,,,,,,,,,24,1,4.000000e+000,0.000000e+000,0.000000e+000,0,,0,
1418238928.845,,1.000000e+002,2.999957e+002,3.231616e-004,0.000000e+000,3,0.000000e+000,0.000000e+000,,,,,,,,,,,,,,24,1,4.000000e+000,8.789063e-003,0.000000e+000,0,,0,
1418238947.712,,1.000000e+002,3.000001e+002,2.286606e-002,0.000000e+000,3,9.965488e-001,0.000000e+000,,,,,,,,,,,,,,24,1,4.000000e+000,1.760864e-002,0.000000e+000,0,,0,