File: data/looselyPackedNP/ios-7/ppms/rawdata/KWI338_HYST_EB_FC1T_30K.DAT
[Header]
; VSM Data File (default extension .dat)
; Copyright (c) 2003-2013, Quantum Design, Inc. All rights reserved.
TITLE,
FILEOPENTIME,32704991.70,01/14/2019,8:45 pm
BYAPP,VSM,2.0,2.0
INFO,PPMS VSM Option Release 1.4.10 Build 1,APPNAME
INFO,Quantum Design Linear Motor Servo Controller,MOTOR_MODULE_NAME
INFO,3101-100 M1,MOTOR_HW_VERSION
INFO,MMC1014,MOTOR_SERIAL_NUMBER
INFO,SRV No X-over 01.03.11,MOTOR_SOFTWARE_VERSION
INFO,Quantum Design VSM Detection Module,VSM_MODULE_NAME
INFO,3101-150 F0,VSM_HW_VERSION
INFO,VSM707,VSM_SERIAL_NUMBER
INFO,VSM No X-over 01.02.05 May 20 2008 13:51:47,VSM_SOFTWARE_VERSION
INFO,704,PREAMP_SERIAL_NUMBER
INFO,822,COIL_SERIAL_NUMBER
INFO,0,MOMENT_UNITS
INFO,Maghemite,SAMPLE_MATERIAL
INFO,Oleate Iron Spheres,SAMPLE_COMMENT
INFO,,SAMPLE_MASS
INFO,,SAMPLE_VOLUME
INFO,,SAMPLE_MOLECULAR_WEIGHT
INFO,,SAMPLE_SIZE
INFO,,SAMPLE_SHAPE
DATATYPE,COMMENT,1
DATATYPE,TIME,2
STARTUPAXIS,X,2
STARTUPAXIS,Y1,5
[Data]
Comment,Time Stamp (sec),Temperature (K),Magnetic Field (Oe),Moment (emu),M. Std. Err. (emu),Transport Action,Averaging Time (sec),Frequency (Hz),Peak Amplitude (mm),Center Position (mm),Coil Signal' (mV),Coil Signal" (mV),Range (mV),M. Quad. Signal (emu),M. Raw' (emu),M. Raw" (emu),Min. Temperature (K),Max. Temperature (K),Min. Field (Oe),Max. Field (Oe),Mass (grams),Motor Lag (deg),Pressure (Torr),VSM Status (code),Motor Status (code),Measure Status (code),Measure Count,PPMS Status (code),System Temp. (K),System Field (Oe),Sample Position (deg),Bridge 1 Resistance (ohms),Bridge 1 Excitation (에),Bridge 2 Resistance (ohms),Bridge 2 Excitation (에),Bridge 3 Resistance (ohms),Bridge 3 Excitation (에),Bridge 4 Resistance (ohms),Bridge 4 Excitation (에),Signal 1 Vin (V),Signal 2 Vin (V),Digital Inputs (code),Drive 1 Iout (mA),Drive 1 Ipower (W),Drive 2 Iout (mA),Drive 2 Ipower (W),Pressure (),Map 20 (),Map 21 (),Map 22 (),Map 23 (),Map 24 (),Map 25 (),Map 26 (),Map 27 (),Map 28 (),Map 29 ()
,32705007.7,29.9986057,9999.537109375,,,2,,,,28.1000007975101,,,,,,,29.9986057,29.9986057,9999.537109375,9999.537109375,,,16.075285,,,,-99999999,4369,30.0022,9999.537109375,,,,,,,,,,,,,,,,,,,,,,,29.9986057,,,,
,32705129.755,30.0256348,943.772369384766,0.00228056273101339,1.39851574999969E-6,1,0.999253354069792,40.0298881530762,1.99740318837656,28.0900001525879,0.0256043085009192,0.00476791558039709,0.25,1.75030496719519E-5,0.00226870511830631,2.9978585810692E-5,30.0256348,30.0256348,941.408813476563,946.135925292969,55.331482876352,20.6805288868983,16.075285,0,0,0,40,4449,29.9616,943.772369384766,,,,,,,,,,,,,0,,,,-0.00245,,,,,,30.0256348,,,,
,32705153.25,30.0250587,2115.69519042969,0.00268244760612689,6.86698103584376E-7,1,0.999253354069792,40.0298881530762,1.99772157658998,28.0900001525879,0.0301215229202258,0.00561650161339335,0.25,2.10761016091076E-5,0.00266866296452583,3.5898309708665E-5,30.0250587,30.0250587,2108.29663085938,2123.09375,55.3017809926212,20.6768955719249,15.695635,0,0,0,40,4449,29.95445,2115.69519042969,,,,,,,,,,,,,0,,,,0,,,,,,30.0250587,,,,
,32705176.65,30.0223675,3282.40637207031,0.0028493136650253,5.41533930108842E-7,1,0.999253354069792,40.0298881530762,1.99724597935059,28.0900001525879,0.0319907409645197,0.00596224751790585,0.25,2.19722595017632E-5,0.00283487199747275,3.78950466564892E-5,30.0223675,30.0223675,3275.09594726562,3289.716796875,55.4932799798328,20.6827192948285,16.075285,0,0,0,40,4449,29.94875,3282.40637207031,,,,,,,,,,,,,0,,,,0.00245,,,,,,30.0223675,,,,
,32705200.49,30.0199375,4471.96997070313,0.00293384416991319,4.6504634220509E-7,1,0.999253354069792,40.0298881530762,1.99691601098217,28.0900001525879,0.0329379736079594,0.00613425023887862,0.25,2.20387269230351E-5,0.00291920446465328,3.86336782126663E-5,30.019722,30.020153,4462.0498046875,4481.89013671875,55.4033927001213,20.6947283575947,16.075285,0,0,0,40,4449,29.94865,4471.96997070313,,,,,,,,,,,,,0,,,,-0.00245,,,,,,30.0199375,,,,
,32705225.4,30.0182571,5714.42065429687,0.0029918423833376,3.68220788117017E-7,1,0.999253354069792,40.0298881530762,1.99718181767162,28.0900001525879,0.0335948583099294,0.00626477261764737,0.25,2.29666493805616E-5,0.00297716549493353,4.01020149619793E-5,30.0182571,30.0182571,5704.4365234375,5724.40478515625,55.6918136237174,20.6905170535904,16.834587,0,0,0,40,4449,29.94295,5714.42065429687,,,,,,,,,,,,,0,,,,0.00245,,,,,,30.0182571,,,,
,32705249.22,30.0164051,6906.08935546875,0.00303048693038543,4.90005816690814E-7,1,0.999253354069792,40.0298881530762,1.99744499787272,28.0900001525879,0.0340384166080084,0.00633369562393926,0.25,2.18656336839331E-5,0.00301588984360617,3.94424111862503E-5,30.0164051,30.0164051,6893.5771484375,6918.6015625,55.7621601904482,20.6904621153971,16.454937,0,0,0,40,4449,29.9407,6906.08935546875,,,,,,,,,,,,,0,,,,0,,,,,,30.0164051,,,,
,32705274.305,30.0137711,8158.00537109375,0.00306220208490624,5.40552350662344E-7,1,0.999253354069792,40.0298881530762,1.99812938297522,28.0900001525879,0.0344057513829987,0.00642180654337141,0.25,2.35682142075891E-5,0.0030477327888564,4.15507169947443E-5,30.0137711,30.0137711,8148.00341796875,8168.00732421875,55.7176073648521,20.6801439754414,16.075285,0,0,0,40,4449,29.9394,8158.00537109375,,,,,,,,,,,,,0,,,,-0.00245,,,,,,30.0137711,,,,
,32705298.705,30.0117798,9380.41748046875,0.00308795833604645,4.82683718784838E-7,1,0.999253354069792,40.0298881530762,1.99861914795805,28.0900001525879,0.0347097594818477,0.00646021142468827,0.25,2.19678103986656E-5,0.00307367189385491,4.03346973395681E-5,30.0117798,30.0117798,9373.060546875,9387.7744140625,55.8473576990444,20.6782832395089,16.454937,0,0,0,40,4449,29.935,9380.41748046875,,,,,,,,,,,,,0,,,,-0.0049,,,,,,30.0117798,,,,
,32705322.87,30.0124378,10587.1157226562,0.00310739431158996,4.98162401970732E-7,1,0.999253354069792,40.0298881530762,1.99721186404702,28.0900001525879,0.0349088668512456,0.0064933500890391,0.25,2.15479215303696E-5,0.00309332422232515,4.02568502160112E-5,30.0124378,30.0124378,10581.9140625,10592.3173828125,55.7519990196982,20.6934669901879,16.075285,0,0,0,40,4449,29.9365,10587.1157226562,,,,,,,,,,,,,0,,,,0,,,,,,30.0124378,,,,
,32705346.235,30.0105324,11753.8837890625,0.00312329602389311,4.86237119561115E-7,1,0.999253354069792,40.0298881530762,1.99714822283106,28.0900001525879,0.0350884406805018,0.00653483541336102,0.25,2.21423986620716E-5,0.00310945084217073,4.11591591793914E-5,30.0105324,30.0105324,11746.2138671875,11761.5537109375,55.5534653758136,20.6932500152806,16.075285,0,0,0,40,4449,29.93135,11753.8837890625,,,,,,,,,,,,,0,,,,0.00245,,,,,,30.0105324,,,,
,32705369.975,30.0115795,12943.1928710938,0.00313779916131553,5.13798867646916E-7,1,0.999253354069792,40.0298881530762,1.99684926924323,28.0900001525879,0.0352537111129061,0.0065437594792402,0.25,2.01495186176319E-5,0.00312421920644112,3.94821745559623E-5,30.0115795,30.0115795,12940.529296875,12945.8564453125,55.7230787644867,20.6995214414332,16.075285,0,0,0,40,4449,29.9329,12943.1928710938,,,,,,,,,,,,,0,,,,0,,,,,,30.0115795,,,,
,32705393.115,30.0081768,14097.7983398438,0.00315005858722338,5.68788927951458E-7,1,0.999253354069792,40.0298881530762,1.99701672317223,28.0900001525879,0.0354008628587232,0.00655361362998101,0.25,1.85203426841194E-5,0.00313675014462491,3.81446272004633E-5,30.0081768,30.0081768,14090.1806640625,14105.416015625,56.313208296506,20.7004409202746,16.834587,0,0,0,40,4449,29.9309,14097.7983398438,,,,,,,,,,,,,0,,,,-0.0049,,,,,,30.0081768,,,,
,32705418.275,30.0069599,15357.2231445313,0.00316135879355518,4.39769824821331E-7,1,0.999253354069792,40.0298881530762,1.99699105416362,28.0900001525879,0.0355276110384312,0.00659885429300734,0.25,2.02392040383891E-5,0.0031483421747418,4.01514790806778E-5,30.0069599,30.0069599,15344.8525390625,15369.59375,56.1178011666983,20.6973499805931,16.075285,0,0,0,40,4449,29.928,15357.2231445313,,,,,,,,,,,,,0,,,,0,,,,,,30.0069599,,,,
,32705442.095,30.0089951,16546.5595703125,0.00317487962108721,5.11032743647183E-7,1,0.999253354069792,40.0298881530762,1.99682848866168,28.0900001525879,0.0356802393010213,0.00662935768462839,0.25,2.03059636367916E-5,0.00316214520450183,4.05121063288279E-5,30.0089951,30.0089951,16539.02734375,16554.091796875,55.575350974352,20.6989788688586,16.454937,0,0,0,40,4449,29.92575,16546.5595703125,,,,,,,,,,,,,0,,,,-0.00245,,,,,,30.0089951,,,,
,32705465.665,30.0070534,17723.3095703125,0.00318479844848055,5.61472891636089E-7,1,0.999253354069792,40.0298881530762,1.99757079878697,28.0900001525879,0.0358022105541861,0.00668692084727177,0.25,2.3171252384819E-5,0.00317234654970984,4.36321038987586E-5,30.0070534,30.0070534,17718.73828125,17727.880859375,56.0834095118521,20.6955541202697,15.695635,0,0,0,40,4449,29.92355,17723.3095703125,,,,,,,,,,,,,0,,,,0,,,,,,30.0070534,,,,
,32705489.35,30.0070324,18905.54296875,0.00319386424436822,6.21740113300805E-7,1,0.999253354069792,40.0298881530762,1.99763104667837,28.0900001525879,0.0359128295872809,0.00668609855099364,0.25,2.11951873755847E-5,0.00318173839597556,4.19215888758512E-5,30.0070324,30.0070324,18893.1953125,18917.890625,56.0537076281213,20.6932492677846,15.695635,0,0,0,40,4449,29.9237,18905.54296875,,,,,,,,,,,,,0,,,,-0.00245,,,,,,30.0070324,,,,
,32705532.89,30.0066185,19936.8291015625,0.00320088933780604,6.12521434392699E-7,1,0.999253354069792,40.0298881530762,1.99729472428834,28.0900001525879,0.0359921625713056,0.00668570444597191,0.25,1.97716403339017E-5,0.0031890547775574,4.071908911909E-5,30.0066185,30.0066185,19930.015625,19943.642578125,55.8473576990444,20.7048083546616,16.454937,0,0,0,40,4449,29.92475,19936.8291015625,,,,,,,,,,,,,0,,,,0,,,,,,30.0066185,,,,
,32705557.37,30.0060787,18721.2734375,0.00319188127218141,5.68236364566306E-7,1,0.999253354069792,40.0298881530762,1.99737389704048,28.0900001525879,0.0358923953373438,0.00664253984668235,0.25,1.7794839781867E-5,0.00317972973696378,3.84900231312119E-5,30.0060787,30.0060787,18708.611328125,18733.935546875,55.9989936317752,20.6958236222082,16.075285,0,0,0,40,4449,29.9216,18721.2734375,,,,,,,,,,,,,0,,,,-0.00245,,,,,,30.0060787,,,,
,32705581.765,30.0068226,17507.572265625,0.00318217141948548,6.91218160124008E-7,1,0.999253354069792,40.0298881530762,1.99708763118127,28.0900001525879,0.0357735753240908,0.00662470649750497,0.25,1.82985849050202E-5,0.00316969854602231,3.87247270595164E-5,30.0068226,30.0068226,17497.453125,17517.69140625,56.0482362284867,20.6992645426749,16.075285,0,0,0,40,4449,29.9244,17507.572265625,,,,,,,,,,,,,0,,,,0,,,,,,30.0068226,,,,
,32705605.85,30.00622465,16303.787109375,0.00317305657165852,5.21784591428242E-7,1,0.999253354069792,40.0298881530762,1.99703296400944,28.0900001525879,0.0356582366933433,0.00664938645973601,0.25,2.24117853492214E-5,0.00316024377294962,4.25539055151668E-5,30.0058289,30.0066204,16298.7939453125,16308.7802734375,55.9216124083713,20.700522608431,15.695635,0,0,0,40,4449,29.9179,16303.787109375,,,,,,,,,,,,,0,,,,-0.00245,,,,,,30.00622465,,,,
,32705629.275,30.005537,15134.751953125,0.00316373347832178,4.52229731889567E-7,1,0.999253354069792,40.0298881530762,1.99701847852668,28.0900001525879,0.0355535933554778,0.00660615673202877,0.25,2.05081107841345E-5,0.00315064004665868,4.03929582164202E-5,30.005537,30.005537,15119.7841796875,15149.7197265625,55.9786712902751,20.6988131548427,16.075285,0,0,0,40,4449,29.91955,15134.751953125,,,,,,,,,,,,,0,,,,0,,,,,,30.005537,,,,
,32705652.975,30.0031738,13947.5078125,0.00315091640492147,5.67432191928107E-7,1,0.999253354069792,40.0298881530762,1.9971208184553,28.0900001525879,0.0354056913340325,0.0065895088851982,0.25,2.15656884053268E-5,0.0031375405422577,4.11531201419482E-5,30.0031738,30.0031738,13939.99609375,13955.01953125,56.0779381122175,20.700952162171,16.454937,0,0,0,40,4449,29.9206,13947.5078125,,,,,,,,,,,,,0,,,,0,,,,,,30.0031738,,,,
,32705676.37,30.005579,12778.0981445313,0.0031390675820442,4.94611375999853E-7,1,0.999253354069792,40.0298881530762,1.99610709675248,28.0900001525879,0.0352556463720452,0.00653975649655316,0.25,1.98153744368904E-5,0.0031254347920771,3.9123637145902E-5,30.005579,30.005579,12770.7314453125,12785.46484375,56.0849727688906,20.7153539955103,16.075285,0,0,0,40,4449,29.91785,12778.0981445313,,,,,,,,,,,,,0,,,,-0.00245,,,,,,30.005579,,,,
,32705699.15,30.0003662,11641.1772460938,0.0031245769546252,4.97239444067436E-7,1,0.999253354069792,40.0298881530762,1.99659415788463,28.0900001525879,0.035094300903453,0.00652928045751174,0.25,2.16033233627308E-5,0.0031106953434129,4.06061421197957E-5,30.0003662,30.0003662,11635.994140625,11646.3603515625,56.3116450394675,20.7057253948122,16.454937,0,0,0,40,4449,29.91745,11641.1772460938,,,,,,,,,,,,,0,,,,0.00245,,,,,,30.0003662,,,,
,32705723.44,30.0032482,10426.7817382813,0.00310611483267393,4.19092839119035E-7,1,0.999253354069792,40.0298881530762,1.99675410705426,28.0900001525879,0.0348859002641238,0.00649155224224642,0.25,2.17858049978319E-5,0.00309200215500214,4.04516319409182E-5,30.002882,30.0036144,10421.90625,10431.6572265625,56.1029502248329,20.7019044017825,16.454937,0,0,0,40,4449,29.918,10426.7817382813,,,,,,,,,,,,,0,,,,0.00245,,,,,,30.0032482,,,,
,32705746.39,30.0027161,9277.68408203125,0.00308835304311279,3.96573867480727E-7,1,0.999253354069792,40.0298881530762,1.9968794724147,28.0900001525879,0.0346821993546084,0.00647127760315505,0.25,2.33880084956222E-5,0.00307402483412909,4.17268879679736E-5,30.0027161,30.0027161,9262.8115234375,9292.556640625,56.0920074255636,20.7050462620183,16.075285,0,0,0,40,4449,29.9163,9277.68408203125,,,,,,,,,,,,,0,,,,0.00245,,,,,,30.0027161,,,,
,32705769.805,30.0031376,8109.86987304687,0.0030651170140559,4.88564571255717E-7,1,0.999253354069792,40.0298881530762,1.99717584840264,28.0900001525879,0.0344271121518829,0.00639968486647864,0.25,2.13590812849294E-5,0.00305062768104938,3.93538511831148E-5,30.0031376,30.0031376,8107.56591796875,8112.173828125,56.1138930241021,20.7095012062807,16.075285,0,0,0,40,4449,29.9152,8109.86987304687,,,,,,,,,,,,,0,,,,0.0049,,,,,,30.0031376,,,,
,32705793.54,29.9963207,6920.7216796875,0.0030358707568267,5.46137295909779E-7,1,0.999253354069792,40.0298881530762,1.99677020016975,28.0900001525879,0.034087223251806,0.0063463951948147,0.25,2.22193575198553E-5,0.00302124196995412,3.98223861298359E-5,29.9963207,29.9963207,6913.31298828125,6928.13037109375,56.5844333926791,20.7172095816173,16.454937,0,0,0,40,4449,29.9183,6920.7216796875,,,,,,,,,,,,,0,,,,0,,,,,,29.9963207,,,,
,32705817.595,29.9994335,5721.73779296875,0.00299861558662656,4.087817137005E-7,1,0.999253354069792,40.0298881530762,1.99680593447797,28.0900001525879,0.0336650933477862,0.00627622749952887,0.25,2.28815687295636E-5,0.00298390135379745,4.00520243636276E-5,29.9994335,29.9994335,5718.9189453125,5724.556640625,56.5117419403906,20.7131227526325,16.075285,0,0,0,40,4449,29.9226,5721.73779296875,,,,,,,,,,,,,0,,,,0,,,,,,29.9994335,,,,
,32705841.215,29.994503,4539.1591796875,0.00294669614284347,3.61367345852813E-7,1,0.999253354069792,40.0298881530762,1.99725971076828,28.0900001525879,0.0330870737250184,0.00616594240781768,0.25,2.24693005479127E-5,0.00293199533245439,3.91391015032239E-5,29.994503,29.994503,4529.1669921875,4549.1513671875,56.4624993436791,20.7101107575016,16.075285,0,0,0,40,4449,29.9217,4539.1591796875,,,,,,,,,,,,,0,,,,-0.00245,,,,,,29.994503,,,,
,32705864.71,29.9975891,3364.18664550781,0.00286586176608696,4.64712142488864E-7,1,0.999253354069792,40.0298881530762,1.99779345715979,28.0900001525879,0.0321861078839148,0.00599241086852069,0.25,2.15567202136364E-5,0.0028513460043493,3.75802244216194E-5,29.9975891,29.9975891,3359.34155273438,3369.03173828125,56.2670922138713,20.7044550990426,16.075285,0,0,0,40,4449,29.9222,3364.18664550781,,,,,,,,,,,,,0,,,,0,,,,,,29.9975891,,,,
,32705887.025,29.9956722,2247.11145019531,0.00272081375815213,5.76659333466051E-7,1,0.999253354069792,40.0298881530762,1.9972368261707,28.0900001525879,0.0305463909206478,0.00569000376547079,0.25,2.0874774699542E-5,0.00270684694140429,3.59220628576165E-5,29.9956722,29.9956722,2239.7099609375,2254.51293945313,56.381209977679,20.7123003497032,16.075285,0,0,0,40,4449,29.92505,2247.11145019531,,,,,,,,,,,,,0,,,,0,,,,,,29.9956722,,,,
,32705909.995,30.00037385,1099.99438476562,0.00238288049316022,1.0316133833551E-6,1,0.999253354069792,40.0298881530762,1.99732354190518,28.0900001525879,0.0267518907130996,0.00498300661657024,0.25,1.84006086115223E-5,0.00237049908394346,3.1443056288441E-5,30.0000992,30.0006485,1095.01232910156,1104.97644042969,56.2037803038136,20.712313978147,16.075285,0,0,0,40,4449,29.9243,1099.99438476562,,,,,,,,,,,,,0,,,,0,,,,,,30.00037385,,,,
,32705932.76,30.0015602,-37.1840171813965,0.00078297854807815,1.06666907276854E-5,1,0.999253354069792,40.0298881530762,1.99710454728573,28.0900001525879,0.00879103249791493,0.00162537554771499,0.25,5.03639372866972E-6,0.000778880125105545,9.29412883264215E-6,30.0015602,30.0015602,-45.1212501525879,-29.2467842102051,56.3718304354483,20.7135872164757,16.454937,0,0,0,40,4449,29.91925,-37.1840171813965,,,,,,,,,,,,,0,,,,-0.0049,,,,,,30.0015602,,,,
,32705955.48,29.9991608,-1169.59411621094,-0.00203406421231586,2.14717418015301E-6,1,0.999253354069792,40.0298881530762,1.99733470607239,28.0900001525879,-0.0228347179477565,-0.00426097250261325,0.25,-1.63559962391898E-5,-0.00202349826808505,-2.74919545852062E-5,29.9991608,29.9991608,-1182.033203125,-1157.15502929688,56.5297193963329,20.7109370745974,16.075285,0,0,0,40,4449,29.92195,-1169.59411621094,,,,,,,,,,,,,0,,,,-0.00245,,,,,,29.9991608,,,,
,32705978.51,30.0035782,-2319.05688476562,-0.00261049114260012,6.990116640174E-7,1,0.999253354069792,40.0298881530762,1.99686436300013,28.0900001525879,-0.0293017953693852,-0.00546342229521503,0.25,-2.04718442235339E-5,-0.00259709808639156,-3.49157782906927E-5,30.0035782,30.0035782,-2329.2509765625,-2308.86279296875,57.2847725459099,20.7197989604865,16.454937,0,0,0,40,4449,29.92205,-2319.05688476562,,,,,,,,,,,,,0,,,,-0.0049,,,,,,30.0035782,,,,
,32706001.9,30.0029202,-3488.37866210937,-0.00282042715607726,4.51842713736157E-7,1,0.999253354069792,40.0298881530762,1.9968810088536,28.0900001525879,-0.0316624619976784,-0.00589376920694025,0.25,-2.10980772775022E-5,-0.00280616274537701,-3.68862568510121E-5,30.0029202,30.0029202,-3498.146484375,-3478.61083984375,56.6969878994483,20.7198048014293,16.075285,0,0,0,40,4449,29.9173,-3488.37866210937,,,,,,,,,,,,,0,,,,-0.00245,,,,,,30.0029202,,,,
,32706025.11,30.0007915,-4648.91821289063,-0.00291962466425938,4.4108818253186E-7,1,0.999253354069792,40.0298881530762,1.9976443084293,28.0900001525879,-0.0327908009417956,-0.0061024089037767,0.25,-2.15289174475852E-5,-0.00290508407702591,-3.80672045239356E-5,30.0007915,30.0007915,-4659.0673828125,-4638.76904296875,56.4671891147944,20.7055638714796,16.454937,0,0,0,40,4449,29.92,-4648.91821289063,,,,,,,,,,,,,0,,,,-0.00245,,,,,,30.0007915,,,,
,32706048.25,30.0014744,-5806.23364257812,-0.00297995565102892,3.65409025687611E-7,1,0.999253354069792,40.0298881530762,1.99741308826167,28.0900001525879,-0.0334694042028604,-0.00621713136515634,0.25,-2.07794861528592E-5,-0.00296536081293338,-3.78663484694571E-5,30.0014744,30.0014744,-5813.80078125,-5798.66650390625,56.4413953736598,20.7088970493133,16.075285,0,0,0,40,4449,29.9186,-5806.23364257812,,,,,,,,,,,,,0,,,,0,,,,,,30.0014744,,,,
,32706071.625,30.0009251,-6973.4345703125,-0.00302246897660414,3.90788960782487E-7,1,0.999253354069792,40.0298881530762,1.9973209916638,28.0900001525879,-0.0339492054726108,-0.00630109639109529,0.25,-2.04246540348616E-5,-0.0030079267035064,-3.79678150354644E-5,30.0009251,30.0009251,-6978.3193359375,-6968.5498046875,56.5250296252175,20.7189554308089,15.695635,0,0,0,40,4449,29.9192,-6973.4345703125,,,,,,,,,,,,,0,,,,-0.00245,,,,,,30.0009251,,,,
,32706094.395,29.9982033,-8112.54663085938,-0.00305432390864074,4.55693868736445E-7,1,0.999253354069792,40.0298881530762,1.99748875371208,28.0900001525879,-0.0343139906590089,-0.00636157711218239,0.25,-1.98127561937563E-5,-0.00303989623756746,-3.77525033931172E-5,29.9982033,29.9982033,-8117.22265625,-8107.87060546875,56.5273745107752,20.7126168193205,15.695635,0,0,0,40,4449,29.9188,-8112.54663085938,,,,,,,,,,,,,0,,,,0,,,,,,29.9982033,,,,
,32706117.805,30.0007915,-9285.640625,-0.00308117503207303,3.57229413602929E-7,1,0.999253354069792,40.0298881530762,1.99790030031077,28.0900001525879,-0.0346252425984879,-0.00642172305054495,0.25,-1.99829929891057E-5,-0.00306690336240409,-3.82970438599955E-5,30.0007915,30.0007915,-9293.248046875,-9278.033203125,56.4914195988906,20.7011224990734,16.075285,0,0,0,40,4449,29.9199,-9285.640625,,,,,,,,,,,,,0,,,,0.00245,,,,,,30.0007915,,,,
,32706141.2,30.0020046,-10452.0854492187,-0.00310266933189036,4.89020067330279E-7,1,0.999253354069792,40.0298881530762,1.99731623751265,28.0900001525879,-0.0348623592129536,-0.00645414448170904,0.25,-1.89151465093132E-5,-0.00308859634795008,-3.75780502251561E-5,30.0020046,30.0020046,-10461.779296875,-10442.3916015625,57.1847240954484,20.712310947433,16.454937,0,0,0,40,4449,29.9192,-10452.0854492187,,,,,,,,,,,,,0,,,,0.00245,,,,,,30.0020046,,,,
,32706165.09,30.0005779,-11649.1586914062,-0.0031212611016322,4.73465853297699E-7,1,0.999253354069792,40.0298881530762,1.99763052984468,28.0900001525879,-0.0350762621679464,-0.00651544723315611,0.25,-2.06777937339233E-5,-0.0031074017472793,-3.96658366637722E-5,30.0005779,30.0005779,-11656.490234375,-11641.8271484375,56.963523224506,20.7167195803912,16.454937,0,0,0,40,4449,29.91725,-11649.1586914062,,,,,,,,,,,,,0,,,,0,,,,,,30.0005779,,,,
,32706188.08,30.0043926,-12795.9282226563,-0.00313692566831556,5.18880001727262E-7,1,0.999253354069792,40.0298881530762,1.99729638826102,28.0900001525879,-0.0352496574212485,-0.0065503258401572,0.25,-2.08033824567526E-5,-0.00312330096781586,-4.00975333695738E-5,30.0043926,30.0043926,-12805.826171875,-12786.0302734375,57.0721695886791,20.7157746557096,16.075285,0,0,0,40,4449,29.91835,-12795.9282226563,,,,,,,,,,,,,0,,,,0,,,,,,30.0043926,,,,
,32706212.175,30.0020523,-14001.10546875,-0.00314981623229123,4.06577609008212E-7,1,0.999253354069792,40.0298881530762,1.99690397206135,28.0900001525879,-0.0353937643043473,-0.00656446718403392,0.25,-1.95863645203809E-5,-0.00313647047861678,-3.9183848305162E-5,30.0020523,30.0020523,-14011.068359375,-13991.142578125,57.0510656186599,20.713057393721,16.075285,0,0,0,40,4449,29.916,-14001.10546875,,,,,,,,,,,,,0,,,,-0.00245,,,,,,30.0020523,,,,
,32706236.33,30.0033646,-15208.0068359375,-0.00316336568891565,5.65666601120697E-7,1,0.999253354069792,40.0298881530762,1.99661286424552,28.0900001525879,-0.0355505423176789,-0.00656079970992352,0.25,-1.66407186625542E-5,-0.00315031667309197,-3.65507490669531E-5,30.0033646,30.0033646,-15215.4794921875,-15200.5341796875,56.6962062709291,20.7181912163811,16.075285,0,0,0,40,4449,29.9135,-15208.0068359375,,,,,,,,,,,,,0,,,,-0.00245,,,,,,30.0033646,,,,
,32706260.19,30.0035992,-16399.7158203125,-0.00317812827813312,5.07986720295238E-7,1,0.999253354069792,40.0298881530762,1.99670839698711,28.0900001525879,-0.0357208895251205,-0.00659824208499492,0.25,-1.70276012727391E-5,-0.00316535646433016,-3.72399019944235E-5,30.0035992,30.0035992,-16404.830078125,-16394.6015625,56.953362053756,20.7144736571326,16.075285,0,0,0,40,4449,29.91605,-16399.7158203125,,,,,,,,,,,,,0,,,,-0.00245,,,,,,30.0035992,,,,
,32706283.385,30.0007801,-17559.0361328125,-0.00318475098271045,5.56884354239519E-7,1,0.999253354069792,40.0298881530762,1.99638825675952,28.0900001525879,-0.035786670327807,-0.00665057276030415,0.25,-2.03236815792284E-5,-0.00317226646255867,-4.07652069528452E-5,30.0007801,30.0007801,-17569.01953125,-17549.052734375,57.210517836583,20.7204995258052,16.075285,0,0,0,40,4449,29.9138,-17559.0361328125,,,,,,,,,,,,,0,,,,0,,,,,,30.0007801,,,,
,32706308.12,30.00383185,-18796.0888671875,-0.00319525463759574,6.18433305919369E-7,1,0.999253354069792,40.0298881530762,1.996452998796,28.0900001525879,-0.0359168414939972,-0.00663503709986087,0.25,-1.67675168480022E-5,-0.00318311795804283,-3.75002414154151E-5,30.0035076,30.0041561,-18803.58203125,-18788.595703125,56.9244417985445,20.7233611885628,16.075285,0,0,0,40,4449,29.9178,-18796.0888671875,,,,,,,,,,,,,0,,,,-0.0049,,,,,,30.00383185,,,,
,32706330.75,29.99993325,-19928.197265625,-0.00320486187590756,3.6867473981572E-7,1,0.999253354069792,40.0298881530762,1.99696354736953,28.0900001525879,-0.0360341192368641,-0.00667591781109999,0.25,-1.82874948434839E-5,-0.00319301714464321,-3.92634681199625E-5,29.9995804,30.0002861,-19938.236328125,-19918.158203125,57.2058280654676,20.7192015620809,16.454937,0,0,0,40,4449,29.9163,-19928.197265625,,,,,,,,,,,,,0,,,,0,,,,,,29.99993325,,,,
,32706373.49,29.9963131,-19007.2421875,-0.00319601348534981,6.49713564435353E-7,1,0.999253354069792,40.0298881530762,1.99766753016403,28.0900001525879,-0.0359457170404609,-0.00664746318452717,0.25,-1.73464567422198E-5,-0.00318393356807959,-3.81173500049464E-5,29.9963131,29.9963131,-19022.1328125,-18992.3515625,56.7579549239483,20.7090276461228,15.315984,0,0,0,40,4449,29.9194,-19007.2421875,,,,,,,,,,,,,0,,,,0.00245,,,,,,29.9963131,,,,
,32706395.82,29.995266,-17891.740234375,-0.00318642982427093,3.69925998402514E-7,1,0.999253354069792,40.0298881530762,1.99762733805598,28.0900001525879,-0.0358275758324608,-0.00665992040632835,0.25,-2.04272231467321E-5,-0.00317403819617618,-4.09374982102459E-5,29.995266,29.995266,-17896.703125,-17886.77734375,56.8298647477175,20.7105710276314,15.315984,0,0,0,40,4449,29.9218,-17891.740234375,,,,,,,,,,,,,0,,,,0,,,,,,29.995266,,,,
,32706419.275,29.9958038,-16720.7783203125,-0.00317480227590627,4.8848794299293E-7,1,0.999253354069792,40.0298881530762,1.99769302829849,28.0900001525879,-0.0356946396481326,-0.00663216019103913,0.25,-2.02877842383135E-5,-0.0031621167031394,-4.05226125840159E-5,29.9958038,29.9958038,-16728.12890625,-16713.427734375,56.9346029692945,20.7136784659632,15.695635,0,0,0,40,4449,29.92035,-16720.7783203125,,,,,,,,,,,,,0,,,,0,,,,,,29.9958038,,,,
,32706443.88,29.99504565,-15494.4833984375,-0.00316715308912173,5.23626641665456E-7,1,0.999253354069792,40.0298881530762,1.99709314122541,28.0900001525879,-0.0355891252403001,-0.006643506703278,0.25,-2.31114583503965E-5,-0.00315413183792862,-4.30719022350313E-5,29.9948826,29.9952087,-15499.4599609375,-15489.5068359375,57.0643533034868,20.7428901588144,16.075285,0,0,0,40,4449,29.92295,-15494.4833984375,,,,,,,,,,,,,0,,,,-0.00245,,,,,,29.99504565,,,,
,32706466.78,29.9957771,-14347.7314453125,-0.00315602405049123,6.28219350409928E-7,1,0.999253354069792,40.0298881530762,1.99820948641241,28.0900001525879,-0.0354763716979637,-0.00663971106361526,0.25,-2.4714323828837E-5,-0.00314271800031979,-4.43930492275706E-5,29.9957771,29.9957771,-14350.177734375,-14345.28515625,56.9283499411406,20.7344299785035,16.075285,0,0,0,40,4449,29.92215,-14347.7314453125,,,,,,,,,,,,,0,,,,-0.0049,,,,,,29.9957771,,,,
,32706490.585,29.9955387,-13157.8012695313,-0.00314396479853475,3.72835561708968E-7,1,0.999253354069792,40.0298881530762,1.99750290662277,28.0900001525879,-0.0353262525201846,-0.00660566313054424,0.25,-2.43191091868135E-5,-0.00313038777149182,-4.37091965483895E-5,29.9955387,29.9955387,-13166.220703125,-13149.3818359375,56.9244417985445,20.7367350455269,15.695635,0,0,0,40,4449,29.92435,-13157.8012695313,,,,,,,,,,,,,0,,,,0.0049,,,,,,29.9955387,,,,
,32706514.195,29.9986591,-11978.6420898438,-0.00312971147168124,4.0335786417241E-7,1,0.999253354069792,40.0298881530762,1.99758080865191,28.0900001525879,-0.0351662770991822,-0.00656168640007798,0.25,-2.32121423868003E-5,-0.00311588745718615,-4.23024769109155E-5,29.9986591,29.9986591,-11991.1005859375,-11966.18359375,56.7509202672752,20.74271328115,15.695635,0,0,0,40,4449,29.92165,-11978.6420898438,,,,,,,,,,,,,0,,,,0,,,,,,29.9986591,,,,
,32706538.21,29.9972363,-10779.2436523438,-0.00311255668601472,4.50743079255895E-7,1,0.999253354069792,40.0298881530762,1.99733742164025,28.0900001525879,-0.0349683125848603,-0.00651103872476096,0.25,-2.21228720818957E-5,-0.00309850413795904,-4.08922751930854E-5,29.9972363,29.9972363,-10786.4462890625,-10772.041015625,56.6094455052945,20.7479811940679,15.695635,0,0,0,40,4449,29.9218,-10779.2436523438,,,,,,,,,,,,,0,,,,-0.0049,,,,,,29.9972363,,,,
,32706561.57,29.992712,-9612.27880859375,-0.00309039668852384,4.60221739450301E-7,1,0.999253354069792,40.0298881530762,1.99770482031122,28.0900001525879,-0.0347233078918569,-0.00645882002829351,0.25,-2.16077405432591E-5,-0.00307615674281291,-4.00321894179572E-5,29.992712,29.992712,-9622.4189453125,-9602.138671875,56.9900985941599,20.7420554220953,16.075285,0,0,0,40,4449,29.92925,-9612.27880859375,,,,,,,,,,,,,0,,,,0,,,,,,29.992712,,,,
,32706584.7,29.9946327,-8454.224609375,-0.00306697455845929,5.14734372998076E-7,1,0.999253354069792,40.0298881530762,1.99755323972364,28.0900001525879,-0.0344539067961723,-0.00641197021881026,0.25,-2.19343517055661E-5,-0.00305255971036563,-4.00044050609369E-5,29.9946136,29.9946518,-8461.8310546875,-8446.6181640625,56.7774956369291,20.7449213504225,15.315984,0,0,0,40,4449,29.9293,-8454.224609375,,,,,,,,,,,,,0,,,,0.00245,,,,,,29.9946327,,,,
,32706608.68,29.9949074,-7258.20532226563,-0.00303856785895009,5.06750311190234E-7,1,0.999253354069792,40.0298881530762,1.99794921098099,28.0900001525879,-0.0341372768438162,-0.00635783744046643,0.25,-2.23581988397384E-5,-0.00302400573681188,-4.00406255442443E-5,29.9949074,29.9949074,-7268.1826171875,-7248.22802734375,56.8204852054868,20.7458313990535,16.075285,0,0,0,40,4449,29.9298,-7258.20532226563,,,,,,,,,,,,,0,,,,0.00245,,,,,,29.9949074,,,,
,32706631.875,29.9961758,-6095.7998046875,-0.0030010323627275,4.36461152079375E-7,1,0.999253354069792,40.0298881530762,1.99746162105655,28.0900001525879,-0.0337043166146903,-0.00628007893517095,0.25,-2.253500988438E-5,-0.00298639070131595,-3.97890155061034E-5,29.9961758,29.9961758,-6098.15869140625,-6093.44091796875,56.7517018957945,20.7470959867136,15.695635,0,0,0,40,4449,29.9286,-6095.7998046875,,,,,,,,,,,,,0,,,,-0.0049,,,,,,29.9961758,,,,
,32706655.135,29.9952908,-4934.02197265625,-0.00295060598745809,5.64737431946177E-7,1,0.999253354069792,40.0298881530762,1.99755768554335,28.0900001525879,-0.0331358147488843,-0.00617968469935928,0.25,-2.28313329359076E-5,-0.00293596548726952,-3.95911252539603E-5,29.9952908,29.9952908,-4944.0517578125,-4923.9921875,56.8580033744099,20.7403922961375,16.075285,0,0,0,40,4449,29.9292,-4934.02197265625,,,,,,,,,,,,,0,,,,0.00245,,,,,,29.9952908,,,,
,32706678.18,29.9951973,-3781.41711425781,-0.00287169824115056,5.01002555730153E-7,1,0.999253354069792,40.0298881530762,1.99743483960235,28.0900001525879,-0.0322462178840166,-0.00600833250073617,0.25,-2.19389087035868E-5,-0.00285723066893829,-3.80629423855161E-5,29.9951973,29.9951973,-3794.12133789063,-3768.712890625,57.0190188493714,20.7442569714482,16.075285,0,0,0,40,4449,29.93155,-3781.41711425781,,,,,,,,,,,,,0,,,,-0.00245,,,,,,29.9951973,,,,
,32706699.9,29.9957542,-2694.08569335938,-0.00273471921824548,6.33736725243494E-7,1,0.999253354069792,40.0298881530762,1.99716281056351,28.0900001525879,-0.0307018466753424,-0.00572137011624584,0.25,-2.11229939123114E-5,-0.00272075446642134,-3.63129802741197E-5,29.9957542,29.9957542,-2699.1435546875,-2689.02783203125,56.9908802226791,20.7478967050145,16.075285,0,0,0,40,4449,29.9317,-2694.08569335938,,,,,,,,,,,,,0,,,,0.00245,,,,,,29.9957542,,,,
,32706722.485,29.9975014,-1566.98236083984,-0.00240935009919834,1.13717788801922E-6,1,0.999253354069792,40.0298881530762,1.99658400703526,28.0900001525879,-0.0270395982587836,-0.00504002742395355,0.25,-1.88450347694339E-5,-0.00239689085204068,-3.20870450408395E-5,29.9975014,29.9975014,-1579.44287109375,-1554.52185058594,56.7634263235829,20.7540811345342,15.695635,0,0,0,40,4449,29.9339,-1566.98236083984,,,,,,,,,,,,,0,,,,0,,,,,,29.9975014,,,,
,32706746.615,29.9975147,-359.431350708008,-0.00113973186766767,4.93763663524727E-6,1,0.999253354069792,40.0298881530762,1.99678550539507,28.0900001525879,-0.0127911528652768,-0.00238584486144536,0.25,-9.11692229383732E-6,-0.00113377070118627,-1.53188033234179E-5,29.9975147,29.9975147,-369.456207275391,-349.406494140625,56.8751992018329,20.7447409481436,15.315984,0,0,0,40,4449,29.9327,-359.431350708008,,,,,,,,,,,,,0,,,,-0.00245,,,,,,29.9975147,,,,
,32706769.53,29.9991131,783.907836914062,0.00192629446405577,2.67395274197843E-6,1,0.999253354069792,40.0298881530762,1.99711894233696,28.0900001525879,0.0216227944713255,0.00403172047154396,0.25,1.52534385223861E-5,0.00191625522511299,2.57688288484145E-5,29.9991131,29.9991131,778.817199707031,788.998474121094,57.4825245612753,20.7329554676435,15.695635,0,0,0,40,4449,29.9302,783.907836914062,,,,,,,,,,,,,0,,,,0,,,,,,29.9991131,,,,
,32706792.455,29.9984856,1928.17492675781,0.00260684466011911,6.85820872968637E-7,1,0.999253354069792,40.0298881530762,1.99725341316316,28.0900001525879,0.0292652512934034,0.00545899296001112,0.25,2.06992909677633E-5,0.00259341218424536,3.50704621041007E-5,29.9984856,29.9984856,1915.77856445313,1940.5712890625,57.3723149400638,20.7382289664438,16.075285,0,0,0,40,4449,29.92725,1928.17492675781,,,,,,,,,,,,,0,,,,-0.0049,,,,,,29.9984856,,,,
,32706815.99,29.9996052,3102.5146484375,0.00281220036856722,5.25442810807264E-7,1,0.999253354069792,40.0298881530762,1.99753693466941,28.0900001525879,0.0315784090846102,0.00588315494364556,0.25,2.15254416579751E-5,0.00279791078984613,3.7208735404936E-5,29.9996052,29.9996052,3092.4130859375,3112.6162109375,57.2988418592561,20.7377292694728,16.075285,0,0,0,40,4449,29.9304,3102.5146484375,,,,,,,,,,,,,0,,,,0,,,,,,29.9996052,,,,
,32706841.19,29.99963,4361.37377929687,0.00292315813034869,4.80628726880932E-7,1,0.999253354069792,40.0298881530762,1.9973522674491,28.0900001525879,0.0328249793412361,0.00611062383303894,0.25,2.17597740433076E-5,0.00290854537357309,3.82713899762908E-5,29.99963,29.99963,4353.97412109375,4368.7734375,57.0260535060445,20.7527053863608,15.315984,0,0,0,40,4449,29.9296,4361.37377929687,,,,,,,,,,,,,0,,,,-0.00245,,,,,,29.99963,,,,
,32706865.37,29.9998951,5571.63525390625,0.00298263672765962,3.51682836056916E-7,1,0.999253354069792,40.0298881530762,1.99732915453473,28.0900001525879,0.0334949033047009,0.00623783756767873,0.25,2.22097131696484E-5,0.00296797563398767,3.92677167414334E-5,29.9998951,29.9998951,5559.02197265625,5584.24853515625,57.2832092888714,20.7472007135571,15.695635,0,0,0,40,4449,29.93235,5571.63525390625,,,,,,,,,,,,,0,,,,-0.00245,,,,,,29.9998951,,,,
,32706888.72,29.997467,6738.52880859375,0.00302118627308941,5.2130157997909E-7,1,0.999253354069792,40.0298881530762,1.99713257364984,28.0900001525879,0.033928246321191,0.00631427230109797,0.25,2.19233524817979E-5,0.00300659324751964,3.94130556120854E-5,29.997467,29.997467,6733.45556640625,6743.60205078125,57.3684067974676,20.7487153858899,15.695635,0,0,0,40,4449,29.9319,6738.52880859375,,,,,,,,,,,,,0,,,,0.0049,,,,,,29.997467,,,,
,32706910.46,29.9949007,7825.509765625,0.00305076998496741,4.7441503269866E-7,1,0.999253354069792,40.0298881530762,1.99750042654979,28.0900001525879,0.0342673261699497,0.00638894091374635,0.25,2.29368153739153E-5,0.00303627882176596,4.0792614773348E-5,29.9940357,29.9957657,7812.96630859375,7838.05322265625,57.0643533034868,20.7437985555114,15.315984,0,0,0,40,4449,29.9342,7825.509765625,,,,,,,,,,,,,0,,,,-0.00245,,,,,,29.9949007,,,,
,32706934.745,29.9992447,9040.72900390625,0.00307635120930619,5.49370105182956E-7,1,0.999253354069792,40.0298881530762,1.9967071950718,28.0900001525879,0.0345457596865497,0.00643552408244943,0.25,2.2450355451288E-5,0.00306203119204585,4.06820167587291E-5,29.9992447,29.9992447,9038.3291015625,9043.12890625,57.0190188493714,20.7512363121756,16.075285,0,0,0,40,4449,29.93085,9040.72900390625,,,,,,,,,,,,,0,,,,-0.00245,,,,,,29.9992447,,,,
,32706958.25,29.9989452,10214.8676757813,0.0030957887242489,4.86385820226873E-7,1,0.999253354069792,40.0298881530762,1.99659708124891,28.0900001525879,0.0347643662940161,0.00648279865583636,0.25,2.29414904367341E-5,0.00308166709874936,4.15041597524794E-5,29.9989452,29.9989452,10202.3330078125,10227.40234375,57.0369963053137,20.7535072797312,16.075285,0,0,0,40,4449,29.9318,10214.8676757813,,,,,,,,,,,,,0,,,,0.00245,,,,,,29.9989452,,,,
,32706981.125,30.0012913,11356.9770507813,0.00311136072465853,5.35934047917493E-7,1,0.999253354069792,40.0298881530762,1.99639996820784,28.0900001525879,0.0349421789560508,0.00649902289160453,0.25,2.13914301729973E-5,0.00309747008637911,4.02659400833461E-5,30.0012913,30.0012913,11352.1201171875,11361.833984375,57.1917587521214,20.7591816458651,15.315984,0,0,0,40,4449,29.9325,11356.9770507813,,,,,,,,,,,,,0,,,,-0.0049,,,,,,30.0012913,,,,
,32707005.365,30.0014572,12568.744140625,0.0031277829490541,5.68738060019864E-7,1,0.999253354069792,40.0298881530762,1.99666413353442,28.0900001525879,0.0351357063568951,0.00652893402809172,0.25,2.07617628322908E-5,0.00311414197059566,3.99613827209946E-5,30.0014572,30.0014572,12556.0810546875,12581.4072265625,57.393418910083,20.7530726457489,15.695635,0,0,0,40,4449,29.93165,12568.744140625,,,,,,,,,,,,,0,,,,0,,,,,,30.0014572,,,,
,32707028.695,30.0029192,13735.6953125,0.00314162700543432,5.50113194787879E-7,1,0.999253354069792,40.0298881530762,1.99712437768579,28.0900001525879,0.0352988667385156,0.00658056194451477,0.25,2.2477612993045E-5,0.00312823078507646,4.19677231847252E-5,30.0028534,30.002985,13730.8369140625,13740.5537109375,56.6508718168137,20.7476506195989,16.075285,0,0,0,40,4449,29.9324,13735.6953125,,,,,,,,,,,,,0,,,,0.00245,,,,,,30.0029192,,,,
,32707053.165,30.00243,14957.6870117188,0.00315264474023223,6.33768196015426E-7,1,0.999253354069792,40.0298881530762,1.99673091602799,28.0900001525879,0.0354192859418683,0.00660605946538754,0.25,2.26033470692275E-5,0.00313953799885597,4.23806002469357E-5,30.00243,30.00243,14950.3349609375,14965.0390625,57.1112510146407,20.7394360911142,15.315984,0,0,0,40,4449,29.9305,14957.6870117188,,,,,,,,,,,,,0,,,,0.00245,,,,,,30.00243,,,,
,32707077.17,30.0025024,16159.3173828125,0.00316249770803703,5.48559860157443E-7,1,0.999253354069792,40.0298881530762,1.99694874245711,28.0900001525879,0.0355360139124548,0.00663650477801233,0.25,2.32116258431875E-5,0.00314968528807662,4.32606767429421E-5,30.0025024,30.0025024,16149.0849609375,16169.5498046875,56.1263990804098,20.7258696845459,15.695635,0,0,0,40,4449,29.93035,16159.3173828125,,,,,,,,,,,,,0,,,,0,,,,,,30.0025024,,,,
,32707101.45,30.001791,17373.83984375,0.00317029055577689,6.38080837143455E-7,1,0.999253354069792,40.0298881530762,1.9952120780794,28.0799996107817,0.0356012655203846,0.00662960666069316,0.25,2.14201455278665E-5,0.00315780720636659,4.17360744468011E-5,30.001791,30.001791,17363.5703125,17384.109375,56.9158438848329,20.7505471867022,15.695635,0,0,0,40,4449,29.9305,17373.83984375,,,,,,,,,,,,,0,,,,-0.00245,,,,,,30.001791,,,,
,32707124.68,30.0005493,18533.607421875,0.00318583811561587,8.16444348987755E-7,1,0.999253354069792,40.0298881530762,1.99640306048452,28.0900001525879,0.0358014166419722,0.00665919281950914,0.25,2.06713837797774E-5,0.00317363832096804,4.12867078054445E-5,30.0005493,30.0005493,18528.544921875,18538.669921875,56.9580518248714,20.7312414026455,16.075285,0,0,0,40,4449,29.9299,18533.607421875,,,,,,,,,,,,,0,,,,-0.0049,,,,,,30.0005493,,,,
,32707148.2,30.0024929,19707.560546875,0.00318883273686434,6.32985771692294E-7,1,0.999253354069792,40.0298881530762,1.9959092819546,28.0900001525879,0.0358282473491089,0.00667745175107891,0.25,2.16421208388635E-5,0.0031769634085699,4.24672723317158E-5,30.0024929,30.0024929,19692.43359375,19722.6875,56.8736359447945,20.7543928043632,15.695635,0,0,0,40,4449,29.92995,19707.560546875,,,,,,,,,,,,,0,,,,0,,,,,,30.0024929,,,,
,32707191.52,29.99964715,19149.580078125,0.00318606173570654,7.55670758241998E-7,1,0.999253354069792,40.0298881530762,1.99653096307264,28.0900001525879,0.035803289765941,0.00668778765262978,0.25,2.30012403537838E-5,0.00317402895924058,4.37122407131387E-5,29.9994755,29.9998188,19147.013671875,19152.146484375,56.6313311038329,20.7351305047892,15.695635,0,0,0,40,4449,29.93285,19149.580078125,,,,,,,,,,,,,0,,,,-0.0049,,,,,,29.99964715,,,,
,32707214.765,29.9983673,17992.0341796875,0.00318285229809588,8.05483228894286E-7,1,0.999253354069792,40.0298881530762,1.99802787129205,28.0900001525879,0.0357947220359893,0.00665285451775944,0.25,2.03039386893375E-5,0.00317050672639708,4.08098513499477E-5,29.9983673,29.9983673,17987.05859375,17997.009765625,57.1987934087945,20.7240107083033,16.075285,0,0,0,40,4449,29.9282,17992.0341796875,,,,,,,,,,,,,0,,,,-0.0049,,,,,,29.9983673,,,,
,32707237.875,29.99924945,16838.9130859375,0.00317153777355223,5.68267767158381E-7,1,0.999253354069792,40.0298881530762,1.99837994653747,28.0900001525879,0.0356668689871932,0.00664541688566092,0.25,2.18276045291969E-5,0.00315889276303976,4.20580816403137E-5,29.9990482,29.9994507,16834.080078125,16843.74609375,57.3168193151984,20.705210007071,16.075285,0,0,0,40,4449,29.93075,16838.9130859375,,,,,,,,,,,,,0,,,,0,,,,,,29.99924945,,,,
,32707261.625,29.9967957,15652.2392578125,0.00315858722432376,5.76524509028367E-7,1,0.999253354069792,40.0298881530762,1.99804035153738,28.0900001525879,0.0355091223964029,0.00663055736337967,0.25,2.31908133668825E-5,0.00314564702210214,4.31259885228135E-5,29.9967957,29.9967957,15644.5498046875,15659.9287109375,56.8837971155445,20.7226381152517,15.695635,0,0,0,40,4449,29.92965,15652.2392578125,,,,,,,,,,,,,0,,,,0,,,,,,29.9967957,,,,
,32707284.98,30.0021591,14482.9331054687,0.00315168029592952,7.65687178777901E-7,1,0.999253354069792,40.0298881530762,1.99576077953731,28.0900001525879,0.0353927272930254,0.00658852140475908,0.25,2.15961643743794E-5,0.00313845278504841,4.1287264096703E-5,30.0021591,30.0021591,14475.4765625,14490.3896484375,56.4953277414867,20.7555527586443,15.695635,0,0,0,40,4449,29.9326,14482.9331054687,,,,,,,,,,,,,0,,,,0.00245,,,,,,30.0021591,,,,
,32707309.435,30.0031433,13260.8725585938,0.00313713177322334,7.62473829324081E-7,1,0.999253354069792,40.0298881530762,1.99520682528121,28.0900001525879,0.0352149482615488,0.00656285112388344,0.25,2.23525286601226E-5,0.00312362586691544,4.17287749249598E-5,30.0031433,30.0031433,13251.0068359375,13270.73828125,56.4945461129675,20.7591524712267,15.315984,0,0,0,40,4449,29.93035,13260.8725585938,,,,,,,,,,,,,0,,,,0,,,,,,30.0031433,,,,
,32707332.695,30.002121,12098.9770507813,0.00311994481545861,2.18079843831397E-6,1,0.999253354069792,40.0298881530762,1.99337056493158,28.0900001525879,0.0349860531891372,0.00652994098830016,0.25,2.32792701904391E-5,0.00310619602940443,4.23324536042443E-5,30.002121,30.002121,12091.384765625,12106.5693359375,57.5989872106407,20.8166191995553,15.315984,0,0,0,40,4449,29.9257,12098.9770507813,,,,,,,,,,,,,0,,,,0,,,,,,30.002121,,,,
,32707357.18,30.0041313,10877.3115234375,0.00310907584434745,4.8007369432249E-7,1,0.999253354069792,40.0298881530762,1.99851569860988,28.0900001525879,0.0349470690256918,0.00651926381967095,0.25,2.31261490357528E-5,0.00309505975924281,4.18895577609587E-5,30.0041313,30.0041313,10867.2822265625,10887.3408203125,57.2214606358522,20.7296541829712,15.315984,0,0,0,40,4449,29.92775,10877.3115234375,,,,,,,,,,,,,0,,,,0,,,,,,30.0041313,,,,
,32707379.765,30.0025024,9745.5576171875,0.00309061709713645,7.63933365659022E-7,1,0.999253354069792,40.0298881530762,1.99489001821502,28.0900001525879,0.0346761115362832,0.00646934609971052,0.25,2.32480895317005E-5,0.00307639897224888,4.16908931565798E-5,30.0025024,30.0025024,9743.1240234375,9747.9912109375,56.8142321773329,20.7715325164766,16.075285,0,0,0,40,4449,29.9289,9745.5576171875,,,,,,,,,,,,,0,,,,0,,,,,,30.0025024,,,,
,32707404.385,29.9979839,8515.18115234375,0.00307259417100697,5.01818104412572E-7,1,0.999253354069792,40.0298881530762,1.99761818719158,28.0900001525879,0.0345194827397839,0.00641722206522019,0.25,2.13647633637263E-5,0.00305817174778769,3.94825487207718E-5,29.9979839,29.9979839,8502.7421875,8527.6201171875,56.7157469839098,20.7344211524345,15.315984,0,0,0,40,4449,29.93145,8515.18115234375,,,,,,,,,,,,,0,,,,-0.00245,,,,,,29.9979839,,,,
,32707428.58,30.0007,7305.9443359375,0.00304784740499729,9.09012261962557E-7,1,0.999253354069792,40.0298881530762,1.99456369010509,28.0900001525879,0.0341869810332916,0.00636295687149066,0.25,2.20616343177406E-5,0.0030332533859432,3.98081969404488E-5,30.0007,30.0007,7298.373046875,7313.515625,56.0583973992367,20.7690651844445,15.315984,0,0,0,40,4449,29.92875,7305.9443359375,,,,,,,,,,,,,0,,,,0,,,,,,30.0007,,,,
,32707452.05,29.998579,6131.86938476563,0.00301245413554906,9.08252165805078E-7,1,0.999253354069792,40.0298881530762,1.9939936151023,28.0900001525879,0.0337781637493469,0.00628491684950271,0.25,2.18446548360424E-5,0.00299776988211494,3.91752143630344E-5,29.998579,29.998579,6124.4169921875,6139.32177734375,56.5891231637945,20.766646437295,15.695635,0,0,0,40,4449,29.93115,6131.86938476563,,,,,,,,,,,,,0,,,,-0.0049,,,,,,29.998579,,,,
,32707475.17,30.0015478,4977.06274414063,0.00296584131166031,4.45959356880373E-7,1,0.999253354069792,40.0298881530762,1.99860041816429,28.0900001525879,0.0333245190108641,0.0062095744642878,0.25,2.24855878735492E-5,0.00295113673555532,3.93417981136539E-5,30.0011883,30.0019073,4969.5029296875,4984.62255859375,56.7985996069483,20.6968570069938,15.695635,0,0,0,40,4449,29.92985,4977.06274414063,,,,,,,,,,,,,0,,,,0.00245,,,,,,30.0015478,,,,
,32707497.815,29.9986925,3844.70227050781,0.00289961698587057,5.1460737761627E-7,1,0.999253354069792,40.0298881530762,1.99892752222611,28.0900001525879,0.0325818266321788,0.00607798354307068,0.25,2.27553679306576E-5,0.00288501582621711,3.90423137102246E-5,29.9982147,29.9991703,3834.78759765625,3854.61694335937,56.9744660237753,20.6916729684836,16.075285,0,0,0,40,4449,29.92735,3844.70227050781,,,,,,,,,,,,,0,,,,0,,,,,,29.9986925,,,,
,32707521.1,29.9999599,2682.49377441406,0.00278808826812988,4.96928440940039E-7,1,0.999253354069792,40.0298881530762,1.99949378442228,28.0900001525879,0.0313357136020828,0.0058401796450349,0.25,2.15969630536738E-5,0.00277384752159464,3.70803568785139E-5,29.9999599,29.9999599,2675.00854492187,2689.97900390625,57.4371901071599,20.6916221641806,15.695635,0,0,0,40,4449,29.92815,2682.49377441406,,,,,,,,,,,,,0,,,,-0.00245,,,,,,29.9999599,,,,
,32707544.705,29.9994936,1500.38293457031,0.00253625229957925,8.68780374926132E-7,1,0.999253354069792,40.0298881530762,1.99934842684813,28.0900001525879,0.0285008519728115,0.00531485453000332,0.25,2.00590897308019E-5,0.0025231243963406,3.39872327912803E-5,29.9994907,29.9994965,1495.33544921875,1505.43041992187,57.5442732142945,20.6922825573624,16.075285,0,0,0,40,4449,29.92635,1500.38293457031,,,,,,,,,,,,,0,,,,-0.00245,,,,,,29.9994936,,,,
,32707568.325,29.9962902,320.304580688477,0.00173185121799307,3.53095755939144E-6,1,0.999253354069792,40.0298881530762,2.00000773947733,28.1000006943941,0.0194673919378461,0.00362515671718334,0.25,1.3344619279331E-5,0.00172279184786779,2.27674124991931E-5,29.9962902,29.9962902,310.122680664063,330.486480712891,56.5500417378329,20.7100097882468,15.695635,0,0,0,40,4449,29.9256,320.304580688477,,,,,,,,,,,,,0,,,,0,,,,,,29.9962902,,,,
,32707575.795,29.9963913,-0.167461507022381,0.000734870136584584,2.2331789679118E-6,1,0.999253354069792,40.0298881530762,2.0007544499859,28.1000006943941,0.00826422224722962,0.00153410898748496,0.25,5.25405720247715E-6,0.000731021087877256,9.24783318011686E-6,29.9963913,29.9963913,-0.182685270905495,-0.152237743139267,56.9377294833714,20.7009347193095,15.695635,0,0,0,40,4417,29.9314,-0.167461507022381,,,,,,,,,,,,,0,,,,0.0049,,,,,,29.9963913,,,,