File: data/looselyPackedNP/ios-7/ppms/rawdata/KWI338_FCC_100OE.DAT
[Header]
; VSM Data File (default extension .dat)
; Copyright (c) 2003-2013, Quantum Design, Inc. All rights reserved.
TITLE,
FILEOPENTIME,28913692.14,12/01/2018,11:35 pm
BYAPP,VSM,2.0,2.0
INFO,PPMS VSM Option Release 1.4.10 Build 1,APPNAME
INFO,Quantum Design Linear Motor Servo Controller,MOTOR_MODULE_NAME
INFO,3101-100 M1,MOTOR_HW_VERSION
INFO,MMC1014,MOTOR_SERIAL_NUMBER
INFO,SRV No X-over 01.03.11,MOTOR_SOFTWARE_VERSION
INFO,Quantum Design VSM Detection Module,VSM_MODULE_NAME
INFO,3101-150 F0,VSM_HW_VERSION
INFO,VSM707,VSM_SERIAL_NUMBER
INFO,VSM No X-over 01.02.05 May 20 2008 13:51:47,VSM_SOFTWARE_VERSION
INFO,704,PREAMP_SERIAL_NUMBER
INFO,822,COIL_SERIAL_NUMBER
INFO,0,MOMENT_UNITS
INFO,Maghemite,SAMPLE_MATERIAL
INFO,Oleate Iron Spheres,SAMPLE_COMMENT
INFO,,SAMPLE_MASS
INFO,,SAMPLE_VOLUME
INFO,,SAMPLE_MOLECULAR_WEIGHT
INFO,,SAMPLE_SIZE
INFO,,SAMPLE_SHAPE
DATATYPE,COMMENT,1
DATATYPE,TIME,2
STARTUPAXIS,X,2
STARTUPAXIS,Y1,5
[Data]
Comment,Time Stamp (sec),Temperature (K),Magnetic Field (Oe),Moment (emu),M. Std. Err. (emu),Transport Action,Averaging Time (sec),Frequency (Hz),Peak Amplitude (mm),Center Position (mm),Coil Signal' (mV),Coil Signal" (mV),Range (mV),M. Quad. Signal (emu),M. Raw' (emu),M. Raw" (emu),Min. Temperature (K),Max. Temperature (K),Min. Field (Oe),Max. Field (Oe),Mass (grams),Motor Lag (deg),Pressure (Torr),VSM Status (code),Motor Status (code),Measure Status (code),Measure Count,PPMS Status (code),System Temp. (K),System Field (Oe),Sample Position (deg),Bridge 1 Resistance (ohms),Bridge 1 Excitation (에),Bridge 2 Resistance (ohms),Bridge 2 Excitation (에),Bridge 3 Resistance (ohms),Bridge 3 Excitation (에),Bridge 4 Resistance (ohms),Bridge 4 Excitation (에),Signal 1 Vin (V),Signal 2 Vin (V),Digital Inputs (code),Drive 1 Iout (mA),Drive 1 Ipower (W),Drive 2 Iout (mA),Drive 2 Ipower (W),Pressure (),Map 20 (),Map 21 (),Map 22 (),Map 23 (),Map 24 (),Map 25 (),Map 26 (),Map 27 (),Map 28 (),Map 29 ()
,28913821.765,349.6277466,99.5330276489258,5.92480790233942E-5,9.51967619095931E-7,1,0.999253354069792,40.0298881530762,1.9914853603344,29.3799992650747,0.00059921228067528,0.000507330734059039,0.25,3.48021911264346E-5,5.91243819978751E-5,3.47739483809439E-5,349.6277466,349.6277466,99.5330276489258,99.5330276489258,57.2675767184868,20.436237846671,30.122374,0,0,0,40,4369,350.2579,99.5330276489258,,,,,,,,,,,,,0,,,,0.00245,,,,,,349.6277466,,,,
,28913955.475,347.4205933,99.5330276489258,5.8959363729084E-5,1.38066102071922E-6,1,0.999253354069792,40.0298881530762,1.99165068166034,29.3799992650747,0.000592733953816636,0.000525997089928383,0.25,3.65025612471115E-5,5.88393244365824E-5,3.64743140670124E-5,347.4205933,347.4205933,99.5330276489258,99.5330276489258,57.2144259791791,20.4361546706796,29.742722,0,0,0,40,4374,345.6532,99.5330276489258,,,,,,,,,,,,,0,,,,0.0049,,,,,,347.4205933,,,,
,28914084.865,344.471283,99.5330276489258,5.80044481849375E-5,1.27299155021736E-6,1,0.999253354069792,40.0298881530762,1.99149958369196,29.3799992650747,0.000583072557154452,0.000517926109090315,0.25,3.59495948337585E-5,5.78919203832617E-5,3.59256632153591E-5,344.471283,344.471283,99.5330276489258,99.5330276489258,57.4012351952753,20.4379940837519,29.363071,0,0,0,40,4374,342.34355,99.5330276489258,,,,,,,,,,,,,0,,,,-0.0049,,,,,,344.471283,,,,
,28914211.585,341.4577332,99.5330276489258,5.83220399820531E-5,1.34491726175716E-6,1,0.999253354069792,40.0298881530762,1.99160061431906,29.3799992650747,0.000584968317496277,0.000528826254964374,0.25,3.68551652908496E-5,5.82142533608911E-5,3.68341119443997E-5,341.4577332,341.4577332,99.5330276489258,99.5330276489258,57.3152560581599,20.4336738564347,29.742722,0,0,0,40,4374,338.98545,99.5330276489258,,,,,,,,,,,,,0,,,,0.00245,,,,,,341.4577332,,,,
,28914333.74,338.4853516,99.5330276489258,5.90617294738004E-5,1.23570514094929E-6,1,0.999253354069792,40.0298881530762,1.99129814251859,29.389999806881,0.000593798240050748,0.000527201194368384,0.25,3.65844943637707E-5,5.89587952309968E-5,3.65683374332579E-5,338.4853516,338.4853516,99.5330276489258,99.5330276489258,57.322290714833,20.4378424355566,29.742722,0,0,0,40,4374,335.8436,99.5330276489258,,,,,,,,,,,,,0,,,,-0.0049,,,,,,338.4853516,,,,
,28914458.765,335.4647522,99.5330276489258,5.79049948219617E-5,9.84111715532875E-7,1,0.999253354069792,40.0298881530762,1.99134135119843,29.3799992650747,0.000582961973863769,0.00051276376260533,0.25,3.54968518241349E-5,5.78100876501107E-5,3.54855693621499E-5,335.4647522,335.4647522,99.5330276489258,99.5330276489258,57.2566339192176,20.437190644305,29.363071,0,0,0,40,4374,332.6449,99.5330276489258,,,,,,,,,,,,,0,,,,0,,,,,,335.4647522,,,,
,28914579.855,332.4532166,99.5330276489258,6.05515023093883E-5,1.2616110132433E-6,1,0.999253354069792,40.0298881530762,1.991344632787,29.1600003838539,0.000608586201777501,0.000542500692008995,0.25,3.76732559566592E-5,6.04580027314722E-5,3.76650367112179E-5,332.4532166,332.4532166,99.5330276489258,99.5330276489258,56.9572701963522,20.4384164510367,30.122374,0,0,0,40,4374,329.61065,99.5330276489258,,,,,,,,,,,,,0,,,,-0.0049,,,,,,332.4532166,,,,
,28914702.345,329.4854736,99.5330276489258,6.11631615657011E-5,1.23648927125455E-6,1,0.999253354069792,40.0298881530762,1.99108879997959,29.1600003838539,0.000616793384084583,0.00053599265349923,0.25,3.69901602214933E-5,6.10754085601938E-5,3.69873071861528E-5,329.4854736,329.4854736,99.5330276489258,99.5330276489258,57.241001348833,20.4461168911021,30.122374,0,0,0,40,4374,326.4972,99.5330276489258,,,,,,,,,,,,,0,,,,0,,,,,,329.4854736,,,,
,28914824.4,326.45980835,99.5330276489258,6.27293675123082E-5,1.12713533712032E-6,1,0.999253354069792,40.0298881530762,1.99104993178229,29.1600003838539,0.000631998170664409,0.00055346934640218,0.25,3.82657799605904E-5,6.26455271192418E-5,3.82669480548951E-5,326.4294434,326.4901733,99.5330276489258,99.5330276489258,57.3301070000253,20.4488220869479,30.122374,0,0,0,40,4374,323.3945,99.5330276489258,,,,,,,,,,,,,0,,,,-0.00245,,,,,,326.45980835,,,,
,28914946.2,323.4700012,99.5330276489258,6.19780529085021E-5,1.25372770443817E-6,1,0.999253354069792,40.0298881530762,1.99087268123587,29.1600003838539,0.000624717524685706,0.000545237205361816,0.25,3.76638350905358E-5,6.19015264367649E-5,3.76694817873235E-5,323.4700012,323.4700012,99.5330276489258,99.5330276489258,57.1346998702176,20.4526299791336,30.122374,0,0,0,40,4374,320.315,99.5330276489258,,,,,,,,,,,,,0,,,,-0.0049,,,,,,323.4700012,,,,
,28915046.75,320.9502258,99.5330276489258,6.31184397248357E-5,1.33905121342948E-6,1,0.999253354069792,40.0298881530762,1.99080993928091,29.0399994701147,0.000633707476862466,0.000569961903900603,0.25,3.96577753073585E-5,6.30450557887542E-5,3.96662701389649E-5,320.9502258,320.9502258,99.5330276489258,99.5330276489258,56.8001628639868,20.450723763109,29.363071,0,0,0,40,4374,317.7732,99.5330276489258,,,,,,,,,,,,,0,,,,0,,,,,,320.9502258,,,,
,28915165.19,317.9986267,99.5330276489258,6.44202125024519E-5,1.57613010351962E-6,1,0.999253354069792,40.0298881530762,1.99060356808533,29.0500000119209,0.000648436400457013,0.000572141569199742,0.25,3.96251209452025E-5,6.43522588979883E-5,3.96390008888837E-5,317.9986267,317.9986267,99.5330276489258,99.5330276489258,57.1128142716791,20.4564672846026,29.742722,0,0,0,40,4374,314.8144,99.5330276489258,,,,,,,,,,,,,0,,,,0.00245,,,,,,317.9986267,,,,
,28915289.28,314.9674072,99.5330276489258,6.45218667805381E-5,1.20121449313087E-6,1,0.999253354069792,40.0298881530762,1.99055223067114,29.0399994701147,0.000649365997786481,0.000573921220410175,0.25,3.97608592814712E-5,6.44603620966155E-5,3.977944012437E-5,314.9674072,314.9674072,99.5330276489258,99.5330276489258,57.1745629246983,20.4558831933649,29.742722,0,0,0,40,4374,311.686,99.5330276489258,,,,,,,,,,,,,0,,,,0,,,,,,314.9674072,,,,
,28915407.815,311.9800415,99.5330276489258,6.65802603035363E-5,1.27434889105857E-6,1,0.999253354069792,40.0298881530762,1.99043094257371,28.9200004190207,0.00067071406485964,0.000588775640874603,0.25,4.07197659282762E-5,6.65237279667069E-5,4.07438986802962E-5,311.9800415,311.9800415,99.5330276489258,99.5330276489258,56.8611298884868,20.4486722700108,29.363071,0,0,0,40,4374,308.70145,99.5330276489258,,,,,,,,,,,,,0,,,,0,,,,,,311.9800415,,,,
,28915532.53,308.9629517,99.5330276489258,6.7296434324387E-5,1.03766258128915E-6,1,0.999253354069792,40.0298881530762,1.99018052593449,28.9200004190207,0.000680196544054115,0.000581937413739399,0.25,3.99890146402335E-5,6.72469266855803E-5,4.00187428205576E-5,308.9629517,308.9629517,99.5330276489258,99.5330276489258,56.8283014906791,20.4551715892816,29.742722,0,0,0,40,4374,305.56705,99.5330276489258,,,,,,,,,,,,,0,,,,0,,,,,,308.9629517,,,,
,28915653.2,305.9476318,99.5330276489258,6.53972085432849E-5,1.58599357841144E-6,1,0.999253354069792,40.0298881530762,1.99022660506279,28.9200004190207,0.000656629237080229,0.000591288962045565,0.25,4.11407823647875E-5,6.53543035224393E-5,4.11737871287103E-5,305.9476318,305.9476318,99.5330276489258,99.5330276489258,56.9486722826406,20.4528948488517,29.742722,0,0,0,40,4374,302.5452,99.5330276489258,,,,,,,,,,,,,0,,,,0.00245,,,,,,305.9476318,,,,
,28915772.18,302.9962158,99.5330276489258,6.54816091442062E-5,1.15978859388849E-6,1,0.999253354069792,40.0298881530762,1.99015307475716,28.9200004190207,0.000657612153259048,0.00059155470931561,0.25,4.11456238368628E-5,6.54452343339805E-5,4.11835199523948E-5,302.9962158,302.9962158,99.5330276489258,99.5330276489258,57.0096393071407,20.4556257085395,30.122374,0,0,0,40,4374,299.547,99.5330276489258,,,,,,,,,,,,,0,,,,-0.0049,,,,,,302.9962158,,,,
,28915894.125,299.9624939,99.5330276489258,6.91170466986442E-5,1.47400928711954E-6,1,0.999253354069792,40.0298881530762,1.99024636089568,28.7999995052814,0.000694867526953921,0.000620777161214477,0.25,4.30998432524026E-5,6.90859909080959E-5,4.31451197878486E-5,299.9624939,299.9624939,99.5330276489258,99.5330276489258,56.8705094307176,20.4504814578049,30.122374,0,0,0,40,4374,296.48125,99.5330276489258,,,,,,,,,,,,,0,,,,-0.0049,,,,,,299.9624939,,,,
,28916015.15,296.9486694,99.5330276489258,6.68320298382791E-5,1.46972837301179E-6,1,0.999253354069792,40.0298881530762,1.99007487071231,28.7999995052814,0.000668473684237739,0.000620089950177789,0.25,4.34329185860618E-5,6.68076472608446E-5,4.34818740513437E-5,296.923645,296.9736938,99.5330276489258,99.5330276489258,56.6571248449675,20.4547255681448,29.742722,0,0,0,40,4374,293.47305,99.5330276489258,,,,,,,,,,,,,0,,,,0,,,,,,296.9486694,,,,
,28916134.865,293.9751282,99.5330276489258,6.85139340461825E-5,1.14828185537327E-6,1,0.999253354069792,40.0298881530762,1.98998996426596,28.7999995052814,0.00068832559499714,0.000618490999556808,0.25,4.29955115779757E-5,6.84968938740637E-5,4.30507337809848E-5,293.9751282,293.9751282,99.5330276489258,99.5330276489258,57.068261446083,20.4575899119696,30.122374,0,0,0,40,4374,290.4463,99.5330276489258,,,,,,,,,,,,,0,,,,0,,,,,,293.9751282,,,,
,28916255.815,290.9658813,99.5330276489258,6.99849776326271E-5,1.57579410142876E-6,1,0.999253354069792,40.0298881530762,1.99034086774712,28.7299994379282,0.00069954304373911,0.000653590320860454,0.25,4.58378264639224E-5,6.99733827798924E-5,4.59001300176701E-5,290.9658813,290.9658813,99.5330276489258,99.5330276489258,56.882233858506,20.4485348672033,30.122374,0,0,0,40,4374,287.4466,99.5330276489258,,,,,,,,,,,,,0,,,,0,,,,,,290.9658813,,,,
,28916377.375,287.9592896,99.5330276489258,7.01398908617825E-5,1.09045014823403E-6,1,0.999253354069792,40.0298881530762,1.99034379096304,28.7299994379282,0.000704620899161873,0.000635156414145882,0.25,4.41694037759421E-5,7.01366536283712E-5,4.42367176996764E-5,287.9592896,287.9592896,99.5330276489258,99.5330276489258,56.9713395096983,20.452345445052,30.502024,0,0,0,40,4374,284.3827,99.5330276489258,,,,,,,,,,,,,0,,,,-0.0049,,,,,,287.9592896,,,,
,28916496.45,284.9838257,99.5330276489258,7.05149928283732E-5,1.06155408888332E-6,1,0.999253354069792,40.0298881530762,1.99060003040085,28.7299994379282,0.000706428047055343,0.000650925954565807,0.25,4.54890187988248E-5,7.05180708557313E-5,4.55626124594832E-5,284.9838257,284.9838257,99.5330276489258,99.5330276489258,57.0049495360253,20.449340407643,29.742722,0,0,0,40,4374,281.3906,99.5330276489258,,,,,,,,,,,,,0,,,,-0.0049,,,,,,284.9838257,,,,
,28916616.195,281.9825745,99.5330276489258,6.96522505735217E-5,1.46989704956741E-6,1,0.999253354069792,40.0298881530762,1.99075365741563,28.7299994379282,0.000695189835664256,0.000658752702457799,0.25,4.632131022099E-5,6.96613511787582E-5,4.64003328012936E-5,281.9825745,281.9825745,99.5330276489258,99.5330276489258,56.7767140084099,20.4483142137799,30.122374,0,0,0,40,4374,278.3999,99.5330276489258,,,,,,,,,,,,,0,,,,-0.0049,,,,,,281.9825745,,,,
,28916736.555,278.995697,99.5330276489258,6.97857253810977E-5,1.23268432869478E-6,1,0.999253354069792,40.0298881530762,1.99067974547455,28.659999370575,0.000698478689837376,0.00064903102659034,0.25,4.54317154696412E-5,6.98025772774295E-5,4.55158227260559E-5,278.995697,278.995697,99.5330276489258,99.5330276489258,57.1440794124484,20.4473424091427,30.122374,0,0,0,40,4374,275.35905,99.5330276489258,,,,,,,,,,,,,0,,,,-0.00245,,,,,,278.995697,,,,
,28916858.155,275.9530334,99.5330276489258,6.99123432826421E-5,1.4560603682698E-6,1,0.999253354069792,40.0298881530762,1.9908376970843,28.659999370575,0.00069906705631745,0.000654960760218757,0.25,4.59240387647402E-5,6.99360855092228E-5,4.60142859638692E-5,275.9530334,275.9530334,99.5330276489258,99.5330276489258,56.9033378285253,20.4466599714106,30.122374,0,0,0,40,4374,272.3321,99.5330276489258,,,,,,,,,,,,,0,,,,-0.00245,,,,,,275.9530334,,,,
,28916977.83,272.9871521,99.5330276489258,7.00015914483967E-5,1.02411849455282E-6,1,0.999253354069792,40.0298881530762,1.9910141392362,28.659999370575,0.000700939960415786,0.000651005202378623,0.25,4.55464149974582E-5,7.00326623899995E-5,4.56419448379264E-5,272.9871521,272.9871521,99.5330276489258,99.5330276489258,56.9158438848329,20.4471888191382,30.122374,0,0,0,40,4374,269.3498,99.5330276489258,,,,,,,,,,,,,0,,,,0.0049,,,,,,272.9871521,,,,
,28917077.095,270.4933777,99.5330276489258,7.2591271469952E-5,1.16504896600504E-6,1,0.999253354069792,40.0298881530762,1.9911125158626,28.5899993032217,0.000726886920332952,0.000675633091450381,0.25,4.72709056991895E-5,7.26295285368893E-5,4.73748404379729E-5,270.4933777,270.4933777,99.5330276489258,99.5330276489258,56.5945945634291,20.4420551067111,30.502024,0,0,0,40,4374,266.8472,99.5330276489258,,,,,,,,,,,,,0,,,,0.00245,,,,,,270.4933777,,,,
,28917198.04,267.4910889,99.5330276489258,7.38048031647005E-5,1.1726583735215E-6,1,0.999253354069792,40.0298881530762,1.99089907669302,28.5899993032217,0.000741212394095089,0.000674379225294276,0.25,4.69484759097451E-5,7.38519704204853E-5,4.7058814907815E-5,267.4910889,267.4910889,99.5330276489258,99.5330276489258,56.6727574153522,20.4499246066732,30.122374,0,0,0,40,4374,263.8447,99.5330276489258,,,,,,,,,,,,,0,,,,0,,,,,,267.4910889,,,,
,28917318.745,264.4819946,99.5330276489258,7.31465824944914E-5,1.08618832955288E-6,1,0.999253354069792,40.0298881530762,1.99084677043818,28.5899993032217,0.00073321382912608,0.000676740178222141,0.25,4.7266136574813E-5,7.32000955302714E-5,4.7382188150577E-5,264.4819946,264.4819946,99.5330276489258,99.5330276489258,56.8259566051214,20.4491476397727,30.122374,0,0,0,40,4374,260.82215,99.5330276489258,,,,,,,,,,,,,0,,,,0.00245,,,,,,264.4819946,,,,
,28917439.99,261.4690247,99.5330276489258,7.47007329756299E-5,1.42840535538099E-6,1,0.999253354069792,40.0298881530762,1.99087199310976,28.5899993032217,0.000746492671554657,0.000704943834989425,0.25,4.94869022212764E-5,7.47618895443805E-5,4.96130655333696E-5,261.4690247,261.4690247,99.5330276489258,99.5330276489258,56.9924434797176,20.4500633004454,29.742722,0,0,0,40,4374,257.79465,99.5330276489258,,,,,,,,,,,,,0,,,,0,,,,,,261.4690247,,,,
,28917561.405,258.4545593,99.5330276489258,7.56006820122613E-5,8.93309144276295E-7,1,0.999253354069792,40.0298881530762,1.99097916703374,28.5500008612871,0.000759888544900146,0.000688812738739903,0.25,4.7891630961001E-5,7.56718687671618E-5,4.80223605573045E-5,258.4545593,258.4545593,99.5330276489258,99.5330276489258,56.6766655579483,20.4498706553987,30.502024,0,0,0,40,4374,254.74695,99.5330276489258,,,,,,,,,,,,,0,,,,0,,,,,,258.4545593,,,,
,28917679.485,255.4800415,99.5330276489258,7.60047844728525E-5,1.19244320935024E-6,1,0.999253354069792,40.0298881530762,1.9909190193343,28.5500008612871,0.000760755137441983,0.000711272547728606,0.25,4.98050224510653E-5,7.60824607139238E-5,4.99449806165835E-5,255.4800415,255.4800415,99.5330276489258,99.5330276489258,56.8150138058522,20.4500694175531,30.502024,0,0,0,40,4374,251.79645,99.5330276489258,,,,,,,,,,,,,0,,,,0,,,,,,255.4800415,,,,
,28917801.21,252.4447632,99.5330276489258,7.75062771304969E-5,9.55488581427404E-7,1,0.999253354069792,40.0298881530762,1.99069138947302,28.5500008612871,0.000778639537952553,0.000708808062979042,0.25,4.93256921069035E-5,7.75944108472544E-5,4.94723674221753E-5,252.4447632,252.4447632,99.5330276489258,99.5330276489258,56.8220484625252,20.4541035823571,30.122374,0,0,0,40,4374,248.7465,99.5330276489258,,,,,,,,,,,,,0,,,,-0.0049,,,,,,252.4447632,,,,
,28917919.44,249.4921722,99.5330276489258,7.87973021580271E-5,1.17414194675258E-6,1,0.999253354069792,40.0298881530762,1.99060844364767,28.5199992358685,0.000789183207686142,0.000734902288277231,0.25,5.14075273310418E-5,7.88934484743149E-5,5.15650432320223E-5,249.4921722,249.4921722,99.5330276489258,99.5330276489258,56.7157469839098,20.449881804493,29.742722,0,0,0,40,4374,245.81305,99.5330276489258,,,,,,,,,,,,,0,,,,0.00245,,,,,,249.4921722,,,,
,28918040.405,246.4902344,99.5330276489258,8.00826205374846E-5,1.33283935868716E-6,1,0.999253354069792,40.0298881530762,1.99156098534869,28.5199992358685,0.000799275623736689,0.000765895251838211,0.25,5.38899637463567E-5,8.01867106014108E-5,5.40596740098659E-5,246.4902344,246.4902344,99.5330276489258,99.5330276489258,56.9619599674676,20.4426062096253,29.363071,0,0,0,40,4374,242.7553,99.5330276489258,,,,,,,,,,,,,0,,,,-0.00245,,,,,,246.4902344,,,,
,28918159.945,243.4739075,99.5330276489258,7.77781906733543E-5,1.43578770954346E-6,1,0.999253354069792,40.0298881530762,1.99123468631977,28.5199992358685,0.000766586846926454,0.000799400360278686,0.25,5.72575857245754E-5,7.78825628160522E-5,5.74386941776963E-5,243.4739075,243.4739075,99.5330276489258,99.5330276489258,56.9650864815445,20.4480186638359,29.742722,0,0,0,40,4374,239.77705,99.5330276489258,,,,,,,,,,,,,0,,,,-0.00245,,,,,,243.4739075,,,,
,28918280.36,240.4921875,99.5330276489258,7.98888911097414E-5,1.54590158354594E-6,1,0.999253354069792,40.0298881530762,1.99074673768867,28.5199992358685,0.000786499079375723,0.000825480669446643,0.25,5.92082268400656E-5,8.00032822550352E-5,5.94022658206646E-5,240.4921875,240.4921875,99.5330276489258,99.5330276489258,57.0205821064099,20.4504610083006,30.122374,0,0,0,40,4374,236.7756,99.5330276489258,,,,,,,,,,,,,0,,,,0.0049,,,,,,240.4921875,,,,
,28918401.03,237.4535828,99.5330276489258,8.06862548411976E-5,1.04201889888505E-6,1,0.999253354069792,40.0298881530762,1.99074439425737,28.4899994730949,0.000792430448488537,0.000845288188253296,0.25,6.0814394770161E-5,8.08085824824169E-5,6.10200330408937E-5,237.4535828,237.4535828,99.5330276489258,99.5330276489258,56.8994296859291,20.4481884240082,29.742722,0,0,0,40,4374,233.7505,99.5330276489258,,,,,,,,,,,,,0,,,,-0.0049,,,,,,237.4535828,,,,
,28918520.535,234.4556274,99.5330276489258,8.40993053685116E-5,1.25966661079455E-6,1,0.999253354069792,40.0298881530762,1.99107846903451,28.4899994730949,0.00083074307595146,0.000854852322929832,0.25,6.1047733722919E-5,8.42367793930117E-5,6.12644706759292E-5,234.4556274,234.4556274,99.5330276489258,99.5330276489258,56.922878541506,20.4412927195915,30.122374,0,0,0,40,4374,230.7539,99.5330276489258,,,,,,,,,,,,,0,,,,0.00245,,,,,,234.4556274,,,,
,28918640.4,231.4759521,99.5330276489258,8.04175926475617E-5,1.57821662253021E-6,1,0.999253354069792,40.0298881530762,1.9911715962954,28.4899994730949,0.000787701409435423,0.000856622857883709,0.25,6.18310604273539E-5,8.05532675910343E-5,6.20537647031332E-5,231.4759521,231.4759521,99.5330276489258,99.5330276489258,56.9627415959868,20.4444159770003,30.122374,0,0,0,40,4374,227.76145,99.5330276489258,,,,,,,,,,,,,0,,,,0,,,,,,231.4759521,,,,
,28918761.75,228.451828,99.5330276489258,8.76991396806232E-5,1.35920770313934E-6,1,0.999253354069792,40.0298881530762,1.99139352332341,28.4899994730949,0.00086686214428137,0.000890196875890698,0.25,6.3520140515503E-5,8.78588684109538E-5,6.3761543899069E-5,228.451828,228.451828,99.5330276489258,99.5330276489258,56.9603967104291,20.4396766330146,29.742722,0,0,0,40,4374,224.76435,99.5330276489258,,,,,,,,,,,,,0,,,,0.0049,,,,,,228.451828,,,,
,28918881.14,225.45438385,99.5330276489258,8.78286434243203E-5,1.15358195037895E-6,1,0.999253354069792,40.0298881530762,1.99160292301018,28.4899994730949,0.000865537728387445,0.000907645208966473,0.25,6.50235662402871E-5,8.79952554451412E-5,6.52768798542013E-5,225.4234161,225.4853516,99.5330276489258,99.5330276489258,56.8884868866599,20.4356693216385,29.742722,0,0,0,40,4374,221.74395,99.5330276489258,,,,,,,,,,,,,0,,,,-0.0049,,,,,,225.45438385,,,,
,28918999.33,222.4999084,99.5330276489258,8.95189040071902E-5,1.20031695608304E-6,1,0.999253354069792,40.0298881530762,1.99149282937107,28.4899994730949,0.000883166025477483,0.000919733093729588,0.25,6.57941212497562E-5,8.9697125838577E-5,6.60590719538202E-5,222.4999084,222.4999084,99.5330276489258,99.5330276489258,56.9705578811791,20.4361760766939,29.742722,0,0,0,40,4374,218.79115,99.5330276489258,,,,,,,,,,,,,0,,,,0.0049,,,,,,222.4999084,,,,
,28919120.385,219.4395905,99.5330276489258,9.1072634777147E-5,1.27795018385337E-6,1,0.999253354069792,40.0298881530762,1.99149682417399,28.4899994730949,0.000898145964882014,0.000938272456251746,0.25,6.71538496251939E-5,9.12620291721368E-5,6.74324493203142E-5,219.4395905,219.4395905,99.5330276489258,99.5330276489258,56.6446187886598,20.4373685170246,30.122374,0,0,0,40,4374,215.77055,99.5330276489258,,,,,,,,,,,,,0,,,,0,,,,,,219.4395905,,,,
,28919239.405,216.4917297,99.5330276489258,9.27511273454244E-5,1.29793319085166E-6,1,0.999253354069792,40.0298881530762,1.99131912970022,28.4800007939339,0.000916034751243687,0.000947877756694839,0.25,6.77093043616387E-5,9.29527119282703E-5,6.79993902458545E-5,216.4917297,216.4917297,99.5330276489258,99.5330276489258,56.9525804252368,20.4417610292455,29.742722,0,0,0,40,4374,212.81045,99.5330276489258,,,,,,,,,,,,,0,,,,-0.0049,,,,,,216.4917297,,,,
,28919358.39,213.4897156,99.5330276489258,8.68189577847304E-5,1.13681175636508E-6,1,0.999253354069792,40.0298881530762,1.99088051207894,28.4800007939339,0.000850218757714515,0.00092816634115947,0.25,6.70040464557341E-5,8.70115099830932E-5,6.72943579394404E-5,213.4897156,213.4897156,99.5330276489258,99.5330276489258,56.8728543162753,20.4461053902769,29.742722,0,0,0,40,4374,209.8313,99.5330276489258,,,,,,,,,,,,,0,,,,-0.0049,,,,,,213.4897156,,,,
,28919478.345,210.4837952,99.5330276489258,8.44652927445664E-5,2.23869541846603E-6,1,0.999253354069792,40.0298881530762,1.99106433455033,28.4800007939339,0.000860416017413637,0.000712522994104501,0.25,4.83300728068931E-5,8.46773823662912E-5,4.85681823909785E-5,210.4837952,210.4837952,99.5330276489258,99.5330276489258,57.1073428720445,20.4440417867605,29.742722,0,0,0,40,4374,206.8365,99.5330276489258,,,,,,,,,,,,,0,,,,0,,,,,,210.4837952,,,,
,28919577.78,207.9829865,99.5330276489258,8.54853845650368E-5,2.5942413132577E-6,1,0.999253354069792,40.0298881530762,1.99133350948658,28.4800007939339,0.000875401395723842,0.000695833065673746,0.25,4.66631150397013E-5,8.57086689931235E-5,4.69022974551077E-5,207.9829865,207.9829865,99.5330276489258,99.5330276489258,56.8087607776983,20.4432540327929,29.363071,0,0,0,40,4374,204.3498,99.5330276489258,,,,,,,,,,,,,0,,,,-0.00245,,,,,,207.9829865,,,,
,28919698.94,204.9463959,99.5330276489258,8.84280064405091E-5,2.8020724623742E-6,1,0.999253354069792,40.0298881530762,1.99106610577309,28.4800007939339,0.000907946667273378,0.000705660776843971,0.25,4.70210680691815E-5,8.8668121772707E-5,4.7270927226967E-5,204.9463959,204.9463959,99.5330276489258,99.5330276489258,57.0010413934291,20.4465452439955,29.363071,0,0,0,40,4374,201.3239,99.5330276489258,,,,,,,,,,,,,0,,,,0,,,,,,204.9463959,,,,
,28919817.955,201.978363,99.5330276489258,9.02456730162824E-5,1.78606509796952E-6,1,0.999253354069792,40.0298881530762,1.99093550576192,28.4800007939339,0.000934371996755565,0.000675614832048989,0.25,4.4045701827908E-5,9.05027396376411E-5,4.42938061674518E-5,201.978363,201.978363,99.5330276489258,99.5330276489258,57.0010413934291,20.4478952227798,29.363071,0,0,0,40,4374,198.3512,99.5330276489258,,,,,,,,,,,,,0,,,,0.0049,,,,,,201.978363,,,,
,28919938.37,198.9860229,99.5330276489258,9.47310536625697E-5,2.31193412093465E-6,1,0.999253354069792,40.0298881530762,1.99070207770534,28.4800007939339,0.000985241243610645,0.000683529070144878,0.25,4.396528811734E-5,9.50115326208686E-5,4.42243020627558E-5,198.9860229,198.9860229,99.5330276489258,99.5330276489258,57.017455592333,20.4498912152847,29.363071,0,0,0,40,4374,195.33675,99.5330276489258,,,,,,,,,,,,,0,,,,0.0049,,,,,,198.9860229,,,,
,28920057.565,195.9737091,99.5330276489258,9.84598123058198E-5,2.15819221523335E-6,1,0.999253354069792,40.0298881530762,1.99104706190953,28.4800007939339,0.00102729264239815,0.000693264828383492,0.25,4.41601450777409E-5,9.87615014304184E-5,4.44304213515085E-5,195.9737091,195.9737091,99.5330276489258,99.5330276489258,56.9361662263329,20.446842916106,29.742722,0,0,0,40,4374,192.3605,99.5330276489258,,,,,,,,,,,,,0,,,,0.00245,,,,,,195.9737091,,,,
,28920178.4,192.949646,99.5330276489258,0.000107969075364076,6.62439257821832E-7,1,0.999253354069792,40.0298881530762,1.99078494916863,28.4800007939339,0.00114079689030178,0.000677697910899775,0.25,4.11317098544029E-5,0.0001083175383731,4.14084498670603E-5,192.949646,192.949646,99.5330276489258,99.5330276489258,57.0604451608906,20.4490110031215,29.363071,0,0,0,40,4374,189.34885,99.5330276489258,,,,,,,,,,,,,0,,,,0.00245,,,,,,192.949646,,,,
,28920298.005,189.9506683,99.5330276489258,0.000134663709930269,1.1565218559026E-6,1,0.999253354069792,40.0298881530762,1.99078212460955,28.4800007939339,0.00143508986829723,0.000775581108303502,0.25,4.5134331453247E-5,0.00013511699168521,4.54643373293889E-5,189.9506683,189.9506683,99.5330276489258,99.5330276489258,57.0917103016599,20.4488911869626,29.363071,0,0,0,40,4374,186.35955,99.5330276489258,,,,,,,,,,,,,0,,,,0,,,,,,189.9506683,,,,
,28920416.75,186.9574127,99.5330276489258,0.000116985004982998,1.86068904111774E-6,1,0.999253354069792,40.0298881530762,1.99102786277874,28.4800007939339,0.00125453280682462,0.000630228137882084,0.25,3.53475090244688E-5,0.000117393284379214,3.56258265059431E-5,186.9574127,186.9574127,99.5330276489258,99.5330276489258,56.7524835243137,20.4461171402192,28.983419,0,0,0,40,4374,183.4279,99.5330276489258,,,,,,,,,,,,,0,,,,0,,,,,,186.9574127,,,,
,28920536.515,183.9724274,99.5330276489258,0.000126266624284762,1.17321091286034E-6,1,0.999253354069792,40.0298881530762,1.99060682673706,28.4800007939339,0.00135475341581048,0.00067527444893575,0.25,3.77175626917019E-5,0.000126718273981808,3.80231029864753E-5,183.9724274,183.9724274,99.5330276489258,99.5330276489258,57.0190188493714,20.4538321922105,29.363071,0,0,0,40,4374,180.4034,99.5330276489258,,,,,,,,,,,,,0,,,,0,,,,,,183.9724274,,,,
,28920657.04,180.9836655,99.5330276489258,0.000130469852693315,1.11256028969103E-6,1,0.999253354069792,40.0298881530762,1.99059537671386,28.4800007939339,0.00139424242940253,0.000730672071744927,0.25,4.18730631098277E-5,0.00013094348272982,4.22076358191972E-5,180.95047,181.016861,99.5330276489258,99.5330276489258,57.0573186468137,20.4518585647754,28.983419,0,0,0,40,4374,177.3972,99.5330276489258,,,,,,,,,,,,,0,,,,0,,,,,,180.9836655,,,,
,28920777.77,177.989502,99.5330276489258,0.000161629770024556,9.17485166677855E-7,1,0.999253354069792,40.0298881530762,1.99016258217198,28.4800007939339,0.00172661448673721,0.000907304581697634,0.25,5.20665118163396E-5,0.000162229038653796,5.24912380826389E-5,177.989502,177.989502,99.5330276489258,99.5330276489258,56.9494539111599,20.4561041909877,28.603769,0,0,0,40,4374,174.3285,99.5330276489258,,,,,,,,,,,,,0,,,,-0.00245,,,,,,177.989502,,,,
,28920897.265,174.9895172,99.5330276489258,0.000174746569957304,4.49759107027916E-7,1,0.999253354069792,40.0298881530762,1.98997716670219,28.4899994730949,0.00188233116364823,0.00089113966572281,0.25,4.83520322319586E-5,0.000175418643155476,4.8788041117104E-5,174.9895172,174.9895172,99.5330276489258,99.5330276489258,57.0432493334676,20.4590571649881,28.603769,0,0,0,40,4374,171.363,99.5330276489258,,,,,,,,,,,,,0,,,,0,,,,,,174.9895172,,,,
,28921018.85,171.9626007,99.5330276489258,0.000193618065428879,4.06267306882001E-7,1,0.999253354069792,40.0298881530762,1.99014036392353,28.4899994730949,0.00212062396625828,0.000788146766557946,0.25,3.59507476540584E-5,0.000194401836501341,3.63690580161884E-5,171.9626007,171.9626007,99.5330276489258,99.5330276489258,57.0229269919676,20.4565497516614,28.224119,0,0,0,40,4374,168.3373,99.5330276489258,,,,,,,,,,,,,0,,,,0,,,,,,171.9626007,,,,
,28921138.335,168.9391785,99.5330276489258,0.000202397706306817,3.6374475569627E-7,1,0.999253354069792,40.0298881530762,1.98974934434425,28.4899994730949,0.00224938970101308,0.000635033460577981,0.25,2.08943253346586E-5,0.000203256379447542,2.12685107598461E-5,168.9391785,168.9391785,99.5330276489258,99.5330276489258,57.1339182416984,20.4645603026824,28.983419,0,0,0,40,4374,165.3561,99.5330276489258,,,,,,,,,,,,,0,,,,-0.00245,,,,,,168.9391785,,,,
,28921255.43,165.9625549,99.5330276489258,0.000207622951642595,3.21407796899674E-7,1,0.999253354069792,40.0298881530762,1.99006012708669,28.4899994730949,0.00232817458548668,0.000535593811761303,0.25,1.1180309656581E-5,0.000208534964579435,1.15272900121688E-5,165.9625549,165.9625549,99.5330276489258,99.5330276489258,56.7126204698329,20.4542062180816,28.603769,0,0,0,40,4374,162.4781,99.5330276489258,,,,,,,,,,,,,0,,,,0,,,,,,165.9625549,,,,
,28921376.245,162.9605408,99.5330276489258,0.000211319607850977,3.63433303271595E-7,1,0.999253354069792,40.0298881530762,1.9899714259736,28.4899994730949,0.00238019020502503,0.000484973159516529,0.25,6.05521750638707E-6,0.000212272538938937,6.39325654494289E-6,162.9605408,162.9605408,99.5330276489258,99.5330276489258,56.8986480574099,20.4604797827441,28.983419,0,0,0,40,4374,159.4273,99.5330276489258,,,,,,,,,,,,,0,,,,-0.00245,,,,,,162.9605408,,,,
,28921495.91,159.95760345,99.5330276489258,0.000215342973041107,3.92646396263006E-7,1,0.999253354069792,40.0298881530762,1.98959305560742,28.4899994730949,0.00243083705435217,0.0004621174189598,0.25,3.33137201590787E-6,0.000216335402626504,3.67179666213597E-6,159.9293518,159.9858551,99.5330276489258,99.5330276489258,56.9877537086022,20.4685630584884,28.603769,0,0,0,40,4374,156.4527,99.5330276489258,,,,,,,,,,,,,0,,,,0,,,,,,159.95760345,,,,
,28921614.765,156.960434,99.5330276489258,0.000219002364510353,2.87361126055294E-7,1,0.999253354069792,40.0298881530762,1.98970605327488,28.5000000149012,0.00247433346356131,0.000459338231981123,0.25,2.43412333344319E-6,0.000220030193043127,2.78533861258498E-6,156.960434,156.960434,99.5330276489258,99.5330276489258,56.7454488676406,20.4670517279021,28.603769,0,0,0,40,4374,153.4886,99.5330276489258,,,,,,,,,,,,,0,,,,-0.0049,,,,,,156.960434,,,,
,28921734.675,153.9513397,99.5330276489258,0.000223434678858317,3.85819206692359E-7,1,0.999253354069792,40.0298881530762,1.98963889069914,28.5299997776747,0.00252614823972338,0.000459317237367829,0.25,1.64850403894197E-6,0.000224501714010901,2.0131088755818E-6,153.9513397,153.9513397,99.5330276489258,99.5330276489258,57.0323065341983,20.4656886695275,28.224119,0,0,0,40,4374,150.49565,99.5330276489258,,,,,,,,,,,,,0,,,,0,,,,,,153.9513397,,,,
,28921853.82,150.9795685,99.5330276489258,0.00022814674743374,3.2260783404755E-7,1,0.999253354069792,40.0298881530762,1.99003152610455,28.5199992358685,0.00258112848319503,0.000463213235685254,0.25,1.15027599476213E-6,0.000229253950834428,1.53094568479704E-6,150.9795685,150.9795685,99.5330276489258,99.5330276489258,56.8251749766022,20.4607188739816,28.603769,0,0,0,40,4374,147.5295,99.5330276489258,,,,,,,,,,,,,0,,,,-0.0049,,,,,,150.9795685,,,,
,28921973.89,147.9485321,99.5330276489258,0.000233713754183701,4.07325347070054E-7,1,0.999253354069792,40.0298881530762,1.9900046460055,28.5199992358685,0.00264485439341425,0.000471186762652066,0.25,8.69989635944739E-7,0.000234865584853231,1.27043396719693E-6,147.9485321,147.9485321,99.5330276489258,99.5330276489258,57.0643533034868,20.4665870405438,28.603769,0,0,0,40,4374,144.5368,99.5330276489258,,,,,,,,,,,,,0,,,,0.00245,,,,,,147.9485321,,,,
,28922073.765,145.4488373,99.5330276489258,0.000238028161932551,3.71515550923961E-7,1,0.999253354069792,40.0298881530762,1.99040456725425,28.5400003194809,0.00269470006008677,0.000478014597454964,0.25,6.99724135003182E-7,0.000239215511141801,1.11735381145081E-6,145.4488373,145.4488373,99.5330276489258,99.5330276489258,56.8814522299868,20.4637409627333,27.464817,0,0,0,40,4374,142.05475,99.5330276489258,,,,,,,,,,,,,0,,,,0.00245,,,,,,145.4488373,,,,
,28922191.15,142.4723816,99.5330276489258,0.000243369422225634,3.19969265389079E-7,1,0.999253354069792,40.0298881530762,1.9903674847203,28.5400003194809,0.00275472487365868,0.000492089549144516,0.25,9.95323941503687E-7,0.000244599364778402,1.4374651173119E-6,142.4723816,142.4723816,99.5330276489258,99.5330276489258,57.0627900464484,20.468025561013,27.844467,0,0,0,40,4374,139.1219,99.5330276489258,,,,,,,,,,,,,0,,,,-0.0049,,,,,,142.4723816,,,,
,28922313.685,139.4369965,99.5330276489258,0.000248849635468164,3.33401477997034E-7,1,0.999253354069792,40.0298881530762,1.98996554279203,28.5400003194809,0.00281670352320451,0.000501353475283783,0.25,8.47505657006258E-7,0.000250123974354542,1.31435735167565E-6,139.4369965,139.4369965,99.5330276489258,99.5330276489258,57.1440794124484,20.4783208034655,28.224119,0,0,0,40,4374,136.06845,99.5330276489258,,,,,,,,,,,,,0,,,,0,,,,,,139.4369965,,,,
,28922430.915,136.4667358,99.5330276489258,0.000255026435830149,3.34563198115662E-7,1,0.999253354069792,40.0298881530762,1.99020156605479,28.5400003194809,0.00288805140220743,0.00050857087610664,0.25,3.82973813913426E-7,0.000256349144141223,8.75254166688179E-7,136.4667358,136.4667358,99.5330276489258,99.5330276489258,57.1284468420637,20.4671819357441,27.844467,0,0,0,40,4374,133.1516,99.5330276489258,,,,,,,,,,,,,0,,,,0,,,,,,136.4667358,,,,
,28922532.135,133.9324646,99.5330276489258,0.000259687416511187,3.41525406450034E-7,1,0.999253354069792,40.0298881530762,2.00288943538696,28.5599995404482,0.00295843928875039,0.000523537086731959,0.25,5.93674019567515E-7,0.000261046972274441,1.11132439516918E-6,133.9324646,133.9324646,99.5330276489258,99.5330276489258,57.3676251689484,20.4700167161332,27.844467,0,0,0,40,4374,130.63135,99.5330276489258,,,,,,,,,,,,,0,,,,0,,,,,,133.9324646,,,,
,28922649.71,130.9893799,99.5330276489258,0.000265734484934474,3.55247137928382E-7,1,0.999253354069792,40.0298881530762,2.00281331246175,28.5599995404482,0.00302652519633223,0.000540670768193295,0.25,1.02107935023499E-6,0.000267139565447807,1.57234535654591E-6,130.9893799,130.9893799,99.5330276489258,99.5330276489258,57.0635716749676,20.4760497244692,27.464817,0,0,0,40,4374,127.7118,99.5330276489258,,,,,,,,,,,,,0,,,,-0.0049,,,,,,130.9893799,,,,
,28922767.725,127.9869919,99.5330276489258,0.000271952625428322,3.51110326304343E-7,1,0.999253354069792,40.0298881530762,2.00295978640285,28.5599995404482,0.00309759930103236,0.00055411096657888,0.25,1.0869911322651E-6,0.000273404906129162,1.67279329237116E-6,127.9869919,127.9869919,99.5330276489258,99.5330276489258,56.9893169656406,20.4678605180345,27.464817,0,0,0,40,4374,124.7789,99.5330276489258,,,,,,,,,,,,,0,,,,-0.0049,,,,,,127.9869919,,,,
touchdown = 18.2199999690056 mm,28922898.825,124.7000275,99.5330276489258,0.000279321766997339,3.60546180893573E-7,1,0.999253354069792,40.0298881530762,1.9906862701612,28.5899993032217,0.00316411938072529,0.000559952117136147,0.25,5.7174082525983E-7,0.000280829314687751,1.19701047690179E-6,124.7000275,124.7000275,99.5330276489258,99.5330276489258,56.8916134007368,20.4567127694689,27.085165,0,0,0,40,4374,121.5038,99.5330276489258,,,,,,,,,,,,,0,,,,0,,,,,,124.7000275,,,,
,28923006.905,121.9714966,99.5330276489258,0.000285555016414315,3.36746399426567E-7,1,0.999253354069792,40.0298881530762,1.99046560018809,28.5800006240606,0.0032344270221013,0.000572918934672282,0.25,6.05796841445607E-7,0.000287107607276889,1.2689165399737E-6,121.9714966,121.9714966,99.5330276489258,99.5330276489258,57.105779615006,20.4690371668808,27.085165,0,0,0,40,4374,118.8402,99.5330276489258,,,,,,,,,,,,,0,,,,0,,,,,,121.9714966,,,,
,28923126.485,118.9730606,99.5330276489258,0.000293051928895955,3.24711840813543E-7,1,0.999253354069792,40.0298881530762,1.99018819752962,28.5800006240606,0.00331870269370196,0.000589771380323128,0.25,7.57325608321888E-7,0.000294656252117776,1.46794374585862E-6,118.9730606,118.9730606,99.5330276489258,99.5330276489258,57.2902439455445,20.4757969219802,27.085165,0,0,0,40,4374,115.8659,99.5330276489258,,,,,,,,,,,,,0,,,,0,,,,,,118.9730606,,,,
,28923246.055,115.939209,99.5330276489258,0.000301007170052298,3.27692418968286E-7,1,0.999253354069792,40.0298881530762,1.99023648359134,28.5800006240606,0.00340875534236879,0.000607134616805588,0.25,8.61994297026846E-7,0.000302664923135744,1.62488254278584E-6,115.939209,115.939209,99.5330276489258,99.5330276489258,57.1956668947176,20.4764391274315,27.085165,0,0,0,40,4374,112.9038,99.5330276489258,,,,,,,,,,,,,0,,,,-0.00245,,,,,,115.939209,,,,
,28923364.015,112.9321442,99.5330276489258,0.000308741107234198,3.90271762432281E-7,1,0.999253354069792,40.0298881530762,1.99083659813963,28.6200009286404,0.00349734948041342,0.000623438121691725,0.25,8.93472950013781E-7,0.000310449645419888,1.71175698991622E-6,112.9321442,112.9321442,99.5330276489258,99.5330276489258,57.0823307594291,20.4629699463203,27.085165,0,0,0,40,4374,109.97615,99.5330276489258,,,,,,,,,,,,,0,,,,-0.00245,,,,,,112.9321442,,,,
,28923483.285,109.9286499,99.5330276489258,0.000317693495620487,2.89221659481377E-7,1,0.999253354069792,40.0298881530762,1.99075664531089,28.6200009286404,0.00359801597829109,0.00064533840421662,0.25,1.21764470678665E-6,0.000319456556149937,2.1017434270445E-6,109.9286499,109.9286499,99.5330276489258,99.5330276489258,56.9689946241406,20.46544907223,26.325863,0,0,0,40,4374,107.0133,99.5330276489258,,,,,,,,,,,,,0,,,,0,,,,,,109.9286499,,,,
,28923601.11,106.97991565,99.5330276489258,0.000326895495917643,3.28144693362788E-7,1,0.999253354069792,40.0298881530762,1.99090251383566,28.6200009286404,0.00370250281287036,0.000664214918783296,0.25,1.22024732396536E-6,0.000328712635702824,2.17432200936863E-6,106.9461365,107.0136948,99.5330276489258,99.5330276489258,57.2832092888714,20.4652665876846,27.085165,0,0,0,40,4374,104.09695,99.5330276489258,,,,,,,,,,,,,0,,,,0,,,,,,106.97991565,,,,
touchdown = 18.2900000363588 mm,28923727.955,103.7421951,99.5330276489258,0.000337469790262705,3.46789620147034E-7,1,0.999253354069792,40.0298881530762,1.99088099468832,28.6500006914139,0.00382174595289225,0.00068845362180634,0.25,1.44942611705669E-6,0.000339344996327518,2.48953843001226E-6,103.7421951,103.7421951,99.5330276489258,99.5330276489258,57.1620568683907,20.4617425127371,25.946213,0,0,0,40,4374,100.9562,99.5330276489258,,,,,,,,,,,,,0,,,,0,,,,,,103.7421951,,,,
,28923839.25,100.9776535,99.5330276489258,0.000346401072882719,4.02110306560261E-7,1,0.999253354069792,40.0298881530762,1.99062809629048,28.6500006914139,0.00392309427421935,0.000702406986979939,0.25,1.06614155882362E-6,0.000348322325266659,2.18521130750341E-6,100.9776535,100.9776535,99.5330276489258,99.5330276489258,57.1268835850253,20.4699795698813,26.325863,0,0,0,40,4374,98.1697,99.5330276489258,,,,,,,,,,,,,0,,,,0.00245,,,,,,100.9776535,,,,
,28923959.615,97.9359665,99.5330276489258,0.000357486164981399,3.52883507620264E-7,1,0.999253354069792,40.0298881530762,1.99022810009484,28.6500006914139,0.00404687058063808,0.000729741968657919,0.25,1.4788823802759E-6,0.000359457997132572,2.70025471119541E-6,97.9359665,97.9359665,99.5330276489258,99.5330276489258,57.1503324406022,20.4797951424029,25.946213,0,0,0,40,4374,95.20355,99.5330276489258,,,,,,,,,,,,,0,,,,0,,,,,,97.9359665,,,,
,28924076.59,94.9745445,99.5330276489258,0.000368863735263892,3.31523113431063E-7,1,0.999253354069792,40.0298881530762,1.98999355650109,28.6500006914139,0.00417546888001177,0.000750312000997554,0.25,1.23107543443477E-6,0.000370883371102649,2.56072902221042E-6,94.929039,95.02005,99.5330276489258,99.5330276489258,57.2152076076984,20.4861790764685,25.566563,0,0,0,40,4374,92.3025,99.5330276489258,,,,,,,,,,,,,0,,,,-0.00245,,,,,,94.9745445,,,,
,28924194.195,91.9777527,99.5330276489258,0.000380381904312593,3.44379688241832E-7,1,0.999253354069792,40.0298881530762,1.99025413663673,28.6899991333485,0.00430541039806126,0.000777839512391761,0.25,1.54680070174551E-6,0.000382439639016827,2.99995880894752E-6,91.9777527,91.9777527,99.5330276489258,99.5330276489258,57.1714364106214,20.4779766009337,26.325863,0,0,0,40,4374,89.38615,99.5330276489258,,,,,,,,,,,,,0,,,,0.0049,,,,,,91.9777527,,,,
,28924315.215,88.964859,99.5330276489258,0.000392591640721913,4.15530129760152E-7,1,0.999253354069792,40.0298881530762,1.99031838399192,28.6899991333485,0.00444301875860905,0.000804631061768185,0.25,1.66871264054278E-6,0.000394679604088204,3.26203506696629E-6,88.964859,88.964859,99.5330276489258,99.5330276489258,56.9861904515637,20.4770239942409,25.946213,0,0,0,40,4374,86.3959,99.5330276489258,,,,,,,,,,,,,0,,,,-0.00245,,,,,,88.964859,,,,
,28924434.61,85.8868942,99.5330276489258,0.00040641775440099,3.35199925123333E-7,1,0.999253354069792,40.0298881530762,1.9902522916338,28.6899991333485,0.00459866643655205,0.000833691366443369,0.25,1.69850549378713E-6,0.00040853192994639,3.451576271169E-6,85.8868942,85.8868942,99.5330276489258,99.5330276489258,57.393418910083,20.4801394924528,25.946213,0,0,0,40,4374,83.4496,99.5330276489258,,,,,,,,,,,,,0,,,,-0.0049,,,,,,85.8868942,,,,
touchdown = 18.3700006455183 mm,28924562.97,82.6610336,99.5330276489258,0.000421938997837449,3.08613906207717E-7,1,0.999253354069792,40.0298881530762,1.99034776104944,28.7299994379282,0.00477377241932907,0.000865193278846054,0.25,1.61693912171081E-6,0.000424064791820971,3.56190666805504E-6,82.6610336,82.6610336,99.5330276489258,99.5330276489258,56.9955699937945,20.4761495736893,24.807261,0,0,0,40,4374,80.30065,99.5330276489258,,,,,,,,,,,,,0,,,,0.00245,,,,,,82.6610336,,,,
,28924668.965,79.9471359,99.5330276489258,0.000435591685450672,3.35593624895239E-7,1,0.999253354069792,40.0298881530762,1.98980192919388,28.7299994379282,0.00492571839553303,0.000894922879201035,0.25,1.73984428606133E-6,0.000437709680581881,3.86502702500002E-6,79.9471359,79.9471359,99.5330276489258,99.5330276489258,57.1573670972753,20.4824436555395,25.186911,0,0,0,40,4374,77.67475,99.5330276489258,,,,,,,,,,,,,0,,,,0,,,,,,79.9471359,,,,
,28924785.735,76.989212,99.5330276489258,0.000451345566505434,3.58192736386273E-7,1,0.999253354069792,40.0298881530762,1.98984808395961,28.7299994379282,0.00510142913935778,0.000934635850666635,0.25,2.32763419547722E-6,0.000453429483172329,4.67391821454012E-6,76.989212,76.989212,99.5330276489258,99.5330276489258,57.2699216040445,20.482126778028,25.186911,0,0,0,40,4374,74.79765,99.5330276489258,,,,,,,,,,,,,0,,,,-0.00245,,,,,,76.989212,,,,
,28924904.185,73.9970551,99.5330276489258,0.00046896848127854,3.61096960332464E-7,1,0.999253354069792,40.0298881530762,1.98951761329701,28.7299994379282,0.0052983011540791,0.000970063655104986,0.25,2.20496589838376E-6,0.000470993184464448,4.79980524510829E-6,73.9970551,73.9970551,99.5330276489258,99.5330276489258,57.1456426694868,20.4795469152249,25.186911,0,0,0,40,4374,71.8837,99.5330276489258,,,,,,,,,,,,,0,,,,-0.0049,,,,,,73.9970551,,,,
,28925021.57,70.979744,99.5330276489258,0.000487519109934353,3.43053744905267E-7,1,0.999253354069792,40.0298881530762,1.99014994566695,28.7599992007017,0.00550698576159177,0.00101149832271982,0.25,2.39812192192509E-6,0.000489443675532823,5.26530934769223E-6,70.979744,70.979744,99.5330276489258,99.5330276489258,57.2886806885061,20.4690792009263,24.807261,0,0,0,40,4374,68.9946,99.5330276489258,,,,,,,,,,,,,0,,,,0.00245,,,,,,70.979744,,,,
,28925139.79,67.9489441,99.5330276489258,0.000507307920074295,3.74316672295233E-7,1,0.999253354069792,40.0298881530762,1.98983261624939,28.7599992007017,0.00572638929285537,0.00105591712720551,0.25,2.6685043253401E-6,0.000509082332719443,5.83087308470903E-6,67.9489441,67.9489441,99.5330276489258,99.5330276489258,57.3027500018522,20.4747432560909,24.047956,0,0,0,40,4374,66.1078,99.5330276489258,,,,,,,,,,,,,0,,,,0,,,,,,67.9489441,,,,
,28925256.29,64.9984665,99.5330276489258,0.000528689314524029,3.67130183597062E-7,1,0.999253354069792,40.0298881530762,1.98999750336906,28.7599992007017,0.0059645591053379,0.00110259143004044,0.25,2.83449074025392E-6,0.000530254929771969,6.31043030443823E-6,64.9984665,64.9984665,99.5330276489258,99.5330276489258,57.1956668947176,20.4656728151845,24.047956,0,0,0,40,4374,63.23265,99.5330276489258,,,,,,,,,,,,,0,,,,0.00245,,,,,,64.9984665,,,,
touchdown = 18.4400007128716 mm,28925379.25,61.8315659,99.5330276489258,0.00055222143465184,3.02055390033191E-7,1,0.999253354069792,40.0298881530762,1.97855792764765,28.7999995052814,0.00619138718549361,0.0011468126807464,0.25,2.97446412262306E-6,0.000553493949261761,6.78500280647487E-6,61.8315659,61.8315659,99.5330276489258,99.5330276489258,56.9682129956214,20.461948698247,23.668306,0,0,0,40,4374,60.2381,99.5330276489258,,,,,,,,,,,,,0,,,,0,,,,,,61.8315659,,,,
,28925492.255,58.9675903,99.5330276489258,0.00057481118920189,3.50600039971849E-7,1,0.999253354069792,40.0298881530762,1.97789111891518,28.7999995052814,0.0064383266355646,0.00119119210032539,0.25,2.82827629166622E-6,0.000575734779746122,6.93999923615938E-6,58.9675903,58.9675903,99.5330276489258,99.5330276489258,57.3535558556022,20.4654979661682,23.668306,0,0,0,40,4374,57.4605,99.5330276489258,,,,,,,,,,,,,0,,,,-0.0049,,,,,,58.9675903,,,,
,28925608.775,55.9738312,99.5330276489258,0.000600137912522833,3.73124057140391E-7,1,0.999253354069792,40.0298881530762,1.97795941369343,28.7999995052814,0.00671506917840146,0.00125250167359825,0.25,3.7070338754863E-6,0.00060061328326474,8.11394374666071E-6,55.9738312,55.9738312,99.5330276489258,99.5330276489258,57.3918556530445,20.4604381666123,23.288654,0,0,0,40,4374,54.5909,99.5330276489258,,,,,,,,,,,,,0,,,,-0.00245,,,,,,55.9738312,,,,
,28925726,52.9635353,99.5330276489258,0.000628038236646013,3.52711871469354E-7,1,0.999253354069792,40.0298881530762,1.97824589868034,28.7999995052814,0.00702086472348687,0.00131724887119762,0.25,4.48176934411262E-6,0.000627992808472302,9.15026361797171E-6,52.9635353,52.9635353,99.5330276489258,99.5330276489258,57.1511140691214,20.4569868323424,22.909004,0,0,0,40,4374,51.7532,99.5330276489258,,,,,,,,,,,,,0,,,,-0.00245,,,,,,52.9635353,,,,
,28925841.775,49.9482307,99.5330276489258,0.000655670887897919,3.28024799391898E-7,1,0.999253354069792,40.0298881530762,1.98969613039579,28.829999268055,0.00736425818315873,0.00137930674108495,0.25,4.47972129043908E-6,0.00065505141527011,9.34088533575302E-6,49.9482307,49.9482307,99.5330276489258,99.5330276489258,57.2066096939868,20.4543053082535,21.3904,0,0,0,40,4374,48.95285,99.5330276489258,,,,,,,,,,,,,0,,,,0.00245,,,,,,49.9482307,,,,
,28925956.34,46.9910202,99.5330276489258,0.000684316539683722,3.6816802866346E-7,1,0.999253354069792,40.0298881530762,1.99001496078984,28.829999268055,0.0076789786466047,0.00144707123688158,0.25,5.51472057871821E-6,0.000683072438590527,1.04982891910814E-5,46.9910202,46.9910202,99.5330276489258,99.5330276489258,57.2214606358522,20.4530080077308,20.631098,0,0,0,40,4370,46.1621,99.5330276489258,,,,,,,,,,,,,0,,,,-0.0049,,,,,,46.9910202,,,,
,28926074.085,43.9843731,99.5330276489258,0.000713828746580082,3.38304521269352E-7,1,0.999253354069792,40.0298881530762,1.98968557660577,28.829999268055,0.00800242300399168,0.00150618601180833,0.25,5.75545040377948E-6,0.00071192917238406,1.07839325548484E-5,43.957016,44.0117302,99.5330276489258,99.5330276489258,57.3113479155637,20.4607095314629,20.251448,0,0,0,40,4370,43.28495,99.5330276489258,,,,,,,,,,,,,0,,,,0,,,,,,43.9843731,,,,
touchdown = 18.5100007802248 mm,28926197.705,40.85061645,99.5330276489258,0.000742980188440525,2.91291486764299E-7,1,0.999253354069792,40.0298881530762,1.99096691760641,28.8800001144409,0.008327375441877,0.00156904668177945,0.25,6.37901480951648E-6,0.00074040829745417,1.13612715003722E-5,40.8214874,40.8797455,99.5330276489258,99.5330276489258,57.0299616486406,20.4580847143114,19.112494,0,0,0,40,4370,40.25565,99.5330276489258,,,,,,,,,,,,,0,,,,0.0049,,,,,,40.85061645,,,,
,28926310.06,37.9897194,99.5330276489258,0.000769737371175858,3.53223299793437E-7,1,0.999253354069792,40.0298881530762,1.99082950440747,28.8699995726347,0.00862145242696648,0.00162328539972498,0.25,6.77416641026389E-6,0.000766588546051895,1.16623888793654E-5,37.9897194,37.9897194,99.5330276489258,99.5330276489258,57.0190188493714,20.4603912728549,17.973541,0,0,0,40,4370,37.469,99.5330276489258,,,,,,,,,,,,,0,,,,0,,,,,,37.9897194,,,,
,28926429.475,34.9810829,99.5330276489258,0.000796013950992968,3.24919333959526E-7,1,0.999253354069792,40.0298881530762,1.99091478553396,28.8699995726347,0.0089120215653879,0.00167335304918765,0.25,6.90607200860662E-6,0.00079232351272875,1.16552097780648E-5,34.9810829,34.9810829,99.5330276489258,99.5330276489258,57.2675767184868,20.4577143466603,17.593889,0,0,0,40,4370,34.51125,99.5330276489258,,,,,,,,,,,,,0,,,,0,,,,,,34.9810829,,,,
,28926549.25,31.9534416,99.5330276489258,0.000820180814402625,3.50768998329505E-7,1,0.999253354069792,40.0298881530762,1.99129189666542,28.8699995726347,0.00918062368408517,0.00172198813236758,0.25,7.25217963484894E-6,0.000816029280620408,1.1849459967266E-5,31.9534416,31.9534416,99.5330276489258,99.5330276489258,57.2019199228714,20.4591561270083,17.593889,0,0,0,40,4370,31.55205,99.5330276489258,,,,,,,,,,,,,0,,,,0,,,,,,31.9534416,,,,
,28926668.125,28.958889,99.5330276489258,0.000840693950632229,3.05658348319405E-7,1,0.999253354069792,40.0298881530762,1.99091866637372,28.8900006562471,0.00940606723484896,0.0017614726747392,0.25,7.44782657185646E-6,0.000836176081186721,1.19013746259856E-5,28.958889,28.958889,99.5330276489258,99.5330276489258,57.034651419756,20.4608894389971,16.454937,0,0,0,40,4370,28.6111,99.5330276489258,,,,,,,,,,,,,0,,,,0,,,,,,28.958889,,,,
,28926785.415,25.9729214,99.5330276489258,0.000858547972113827,4.15866245718905E-7,1,0.999253354069792,40.0298881530762,1.99054788304358,28.8900006562471,0.00960276309588354,0.00179405816036808,0.25,7.44290480145299E-6,0.000853750516225096,1.17863853072158E-5,25.9729214,25.9729214,99.5330276489258,99.5330276489258,57.115940785756,20.4601323590365,16.454937,0,0,0,40,4370,25.7014,99.5330276489258,,,,,,,,,,,,,0,,,,0,,,,,,25.9729214,,,,
,28926905.03,22.9591255,99.5330276489258,0.000873079652046934,3.33580209700566E-7,1,0.999253354069792,40.0298881530762,1.99052609094208,28.8900006562471,0.00976440649835008,0.00182090445139377,0.25,7.42747047289344E-6,0.000868080940506657,1.16961056126916E-5,22.9591255,22.9591255,99.5330276489258,99.5330276489258,57.1659650109868,20.4620437736344,16.075285,0,0,0,40,4370,22.71895,99.5330276489258,,,,,,,,,,,,,0,,,,0,,,,,,22.9591255,,,,
touchdown = 18.5499992221594 mm,28927027.75,19.923727,99.5330276489258,0.00088464992848685,3.94814597415246E-7,1,0.999253354069792,40.0298881530762,1.99055035368327,28.8999993354082,0.00989361439969098,0.00184278372995198,0.25,7.41864237813847E-6,0.000879524682414504,1.16598810746714E-5,19.923727,19.923727,99.5330276489258,99.5330276489258,56.8501870892175,20.4530578096592,14.936333,0,0,0,40,4370,19.6861,99.5330276489258,,,,,,,,,,,,,0,,,,0,,,,,,19.923727,,,,
,28927142.29,16.9919109,99.5330276489258,0.000892354644679994,3.04091529944349E-7,1,0.999253354069792,40.0298881530762,1.99022172876659,28.8999993354082,0.00997881799303651,0.00185474854022658,0.25,7.16339863597865E-6,0.000887180935972308,1.14257430251442E-5,16.9919109,16.9919109,99.5330276489258,99.5330276489258,57.1839424669291,20.4489529977604,14.556682,0,0,0,40,4370,16.8255,99.5330276489258,,,,,,,,,,,,,0,,,,0.0049,,,,,,16.9919109,,,,
,28927263.44,13.9521551,99.5330276489258,0.000899567898244273,3.31372309049897E-7,1,0.999253354069792,40.0298881530762,1.99066495994369,28.8999993354082,0.0100614473164507,0.00187163310331503,0.25,7.35321984966599E-6,0.000894359723292709,1.16493628102553E-5,13.9521551,13.9521551,99.5330276489258,99.5330276489258,57.1206305568714,20.4518184342009,13.797379,0,0,0,40,4370,13.8024,99.5330276489258,,,,,,,,,,,,,0,,,,0,,,,,,13.9521551,,,,
,28927384.46,10.9527416,99.5330276489258,0.00090601659816587,3.04333779395377E-7,1,0.999253354069792,40.0298881530762,1.99046175755125,28.8999993354082,0.0101327336040986,0.00188442533187438,0.25,7.36544279997679E-6,0.000900777177874968,1.16926927124087E-5,10.9527416,10.9527416,99.5330276489258,99.5330276489258,57.1073428720445,20.4502752018597,13.038077,0,0,0,40,4370,10.7806,99.5330276489258,,,,,,,,,,,,,0,,,,-0.00245,,,,,,10.9527416,,,,
,28927555.005,10.0157633,99.5330276489258,0.000907823453081153,2.74525678974869E-7,1,0.999253354069792,40.0298881530762,1.99044051431263,28.9299990981817,0.0101524646949755,0.00189035786282513,0.25,7.57573272675119E-6,0.000902574064560333,1.19105077218608E-5,10.0157633,10.0157633,99.5330276489258,99.5330276489258,57.0659165605253,20.4469654700826,12.278775,0,0,0,40,4369,9.95955,99.5330276489258,,,,,,,,,,,,,0,,,,-0.00245,,,,,,10.0157633,,,,