File: data/looselyPackedNP/ios-7/ppms/rawdata/KWI338_HYST_ZFC_30K.DAT
[Header]
; VSM Data File (default extension .dat)
; Copyright (c) 2003-2013, Quantum Design, Inc. All rights reserved.
TITLE,
FILEOPENTIME,32694414.08,01/14/2019,5:49 pm
BYAPP,VSM,2.0,2.0
INFO,PPMS VSM Option Release 1.4.10 Build 1,APPNAME
INFO,Quantum Design Linear Motor Servo Controller,MOTOR_MODULE_NAME
INFO,3101-100 M1,MOTOR_HW_VERSION
INFO,MMC1014,MOTOR_SERIAL_NUMBER
INFO,SRV No X-over 01.03.11,MOTOR_SOFTWARE_VERSION
INFO,Quantum Design VSM Detection Module,VSM_MODULE_NAME
INFO,3101-150 F0,VSM_HW_VERSION
INFO,VSM707,VSM_SERIAL_NUMBER
INFO,VSM No X-over 01.02.05 May 20 2008 13:51:47,VSM_SOFTWARE_VERSION
INFO,704,PREAMP_SERIAL_NUMBER
INFO,822,COIL_SERIAL_NUMBER
INFO,0,MOMENT_UNITS
INFO,Maghemite,SAMPLE_MATERIAL
INFO,Oleate Iron Spheres,SAMPLE_COMMENT
INFO,,SAMPLE_MASS
INFO,,SAMPLE_VOLUME
INFO,,SAMPLE_MOLECULAR_WEIGHT
INFO,,SAMPLE_SIZE
INFO,,SAMPLE_SHAPE
DATATYPE,COMMENT,1
DATATYPE,TIME,2
STARTUPAXIS,X,2
STARTUPAXIS,Y1,5
[Data]
Comment,Time Stamp (sec),Temperature (K),Magnetic Field (Oe),Moment (emu),M. Std. Err. (emu),Transport Action,Averaging Time (sec),Frequency (Hz),Peak Amplitude (mm),Center Position (mm),Coil Signal' (mV),Coil Signal" (mV),Range (mV),M. Quad. Signal (emu),M. Raw' (emu),M. Raw" (emu),Min. Temperature (K),Max. Temperature (K),Min. Field (Oe),Max. Field (Oe),Mass (grams),Motor Lag (deg),Pressure (Torr),VSM Status (code),Motor Status (code),Measure Status (code),Measure Count,PPMS Status (code),System Temp. (K),System Field (Oe),Sample Position (deg),Bridge 1 Resistance (ohms),Bridge 1 Excitation (에),Bridge 2 Resistance (ohms),Bridge 2 Excitation (에),Bridge 3 Resistance (ohms),Bridge 3 Excitation (에),Bridge 4 Resistance (ohms),Bridge 4 Excitation (에),Signal 1 Vin (V),Signal 2 Vin (V),Digital Inputs (code),Drive 1 Iout (mA),Drive 1 Ipower (W),Drive 2 Iout (mA),Drive 2 Ipower (W),Pressure (),Map 20 (),Map 21 (),Map 22 (),Map 23 (),Map 24 (),Map 25 (),Map 26 (),Map 27 (),Map 28 (),Map 29 ()
,32694431.19,29.9975128,0.1674614995718,,,2,,,,28.0300007301569,,,,,,,29.9975128,29.9975128,0.1674614995718,0.1674614995718,,,16.075285,,,,-99999999,4369,30.0053,0.1674614995718,,,,,,,,,,,,,,,,,,,,,,,29.9975128,,,,
,32694510,30.0282021,883.911071777344,0.00182403830787424,2.5296241013375E-6,1,0.999253354069792,40.0298881530762,1.99058889713741,28.0200000852346,0.0203982946990203,0.00387845299467806,0.25,2.09092694657063E-5,0.00181451375787226,3.08494875158443E-5,30.0282021,30.0282021,881.236328125,886.585815429688,55.8465760705251,20.6534034591364,16.454937,0,0,0,40,4449,29.9751,883.911071777344,,,,,,,,,,,,,0,,,,0.00245,,,,,,30.0282021,,,,
,32694532.785,30.0291939,2020.7001953125,0.00250879140872893,8.40496224672717E-7,1,0.999253354069792,40.0298881530762,1.99145424100424,28.0200000852346,0.0280729945776205,0.00531571813107876,0.25,2.67311714019469E-5,0.00249584792980076,4.05470747454847E-5,30.0291939,30.0291939,2008.20361328125,2033.19677734375,56.8197035769676,20.6269042164401,16.834587,0,0,0,40,4449,29.9596,2020.7001953125,,,,,,,,,,,,,0,,,,-0.00245,,,,,,30.0291939,,,,
,32694555.64,30.0239258,3159.78039550781,0.00276457139889704,4.64883045282415E-7,1,0.999253354069792,40.0298881530762,1.99126112044202,28.0300006270409,0.0309291506594389,0.0058868346345111,0.25,3.19051929263633E-5,0.00275048110495715,4.72847657844993E-5,30.0239258,30.0239258,3149.82568359375,3169.73510742188,55.2744239944482,20.6505792317728,16.075285,0,0,0,40,4449,29.95715,3159.78039550781,,,,,,,,,,,,,0,,,,0.0049,,,,,,30.0239258,,,,
,32694578.265,30.0233307,4286.66259765625,0.00288592192896346,4.43718185680691E-7,1,0.999253354069792,40.0298881530762,1.99260812577157,28.0300006270409,0.0323096852070895,0.00615128551330037,0.25,3.32723304446863E-5,0.00287142054285186,4.95088529925653E-5,30.0233307,30.0233307,4276.74609375,4296.5791015625,56.2225393882752,20.6122550672622,16.834587,0,0,0,40,4449,29.95145,4286.66259765625,,,,,,,,,,,,,0,,,,-0.00245,,,,,,30.0233307,,,,
,32694600.67,30.0213814,5407.33154296875,0.00295514350319375,4.76881270017243E-7,1,0.999253354069792,40.0298881530762,1.99173716936288,28.0300006270409,0.0330734870427405,0.00629626165118555,0.25,3.38424873971491E-5,0.00294052156477182,5.06624897609996E-5,30.0213814,30.0213814,5399.85791015625,5414.80517578125,55.9497510350636,20.6331550454628,16.075285,0,0,0,40,4449,29.9523,5407.33154296875,,,,,,,,,,,,,0,,,,0.0049,,,,,,30.0213814,,,,
,32694623.845,30.0184231,6563.58203125,0.00300525923027831,5.29247057018938E-7,1,0.999253354069792,40.0298881530762,1.99186070304081,28.0300006270409,0.0336391313071635,0.0064039630752538,0.25,3.42180034286679E-5,0.00299063545804978,5.15275081257627E-5,30.0184231,30.0184231,6558.5595703125,6568.6044921875,55.8231272149482,20.6289975956574,16.075285,0,0,0,40,4449,29.9423,6563.58203125,,,,,,,,,,,,,0,,,,-0.0049,,,,,,30.0184231,,,,
,32694645.81,30.0184746,7662.98681640625,0.00303943127223119,5.76591556662109E-7,1,0.999253354069792,40.0298881530762,1.99155224953735,28.0200000852346,0.0340207610219502,0.00646877799760788,0.25,3.37346056641436E-5,0.0030248944827925,5.144512291502E-5,30.0184746,30.0184746,7658.0205078125,7667.953125,56.6274229612368,20.6313085289239,16.075285,0,0,0,40,4449,29.9416,7662.98681640625,,,,,,,,,,,,,0,,,,-0.00245,,,,,,30.0184746,,,,
,32694669.61,30.0157909,8852.46142578125,0.00307013431483803,6.31597727971084E-7,1,0.999253354069792,40.0298881530762,1.99281361879027,28.0200000852346,0.0343858802091818,0.00655264038022821,0.25,3.51040349024064E-5,0.00305572517773402,5.32080020353164E-5,30.0157909,30.0157909,8842.40234375,8862.5205078125,56.1795498197175,20.6194238067659,16.834587,0,0,0,40,4449,29.94035,8852.46142578125,,,,,,,,,,,,,0,,,,0,,,,,,30.0157909,,,,
,32694692.67,30.0135269,10004.8017578125,0.00309285321399084,5.64037979377602E-7,1,0.999253354069792,40.0298881530762,1.99285276204806,28.0200000852346,0.0346396752935981,0.00662703936878282,0.25,3.73969821623398E-5,0.00307860769289882,5.58396522367158E-5,30.0135269,30.0135269,10002.251953125,10007.3515625,56.279598270179,20.6188721973299,16.075285,0,0,0,40,4449,29.9395,10004.8017578125,,,,,,,,,,,,,0,,,,0,,,,,,30.0135269,,,,
,32694715.97,30.0113068,11169.0283203125,0.00311347855693978,6.00911082738305E-7,1,0.999253354069792,40.0298881530762,1.99320035330009,28.0200000852346,0.0348844923465602,0.0066468793759044,0.25,3.51088436788837E-5,0.00309944892350993,5.39026641490369E-5,30.0113068,30.0113068,11161.5966796875,11176.4599609375,55.9989936317752,20.6111350214472,16.834587,0,0,0,40,4449,29.93995,11169.0283203125,,,,,,,,,,,,,0,,,,-0.00245,,,,,,30.0113068,,,,
,32694738.29,30.0096951,12283.3950195313,0.00312834968812733,5.81993213903457E-7,1,0.999253354069792,40.0298881530762,1.99293267349778,28.0200000852346,0.0350523161110988,0.00666482697272382,0.25,3.38670915015213E-5,0.0031145509240883,5.29619505454696E-5,30.0096951,30.0096951,12280.669921875,12286.1201171875,56.4562463155252,20.6347630264326,16.075285,0,0,0,40,4449,29.935,12283.3950195313,,,,,,,,,,,,,0,,,,0.0049,,,,,,30.0096951,,,,
,32694761.395,30.0085735,13438.2163085938,0.00314385252165193,6.8677926859921E-7,1,0.999253354069792,40.0298881530762,1.99336450036003,28.0200000852346,0.0352398705710299,0.00668287339819842,0.25,3.23093482428738E-5,0.00313030690731256,5.1719187464675E-5,30.0085735,30.0085735,13430.8544921875,13445.578125,56.299920611679,20.6144911777703,16.454937,0,0,0,40,4449,29.9386,13438.2163085938,,,,,,,,,,,,,0,,,,0,,,,,,30.0085735,,,,
,32694784.94,30.00608445,14614.8857421875,0.00315660565985585,7.75470600807827E-7,1,0.999253354069792,40.0298881530762,1.99276192091675,28.0200000852346,0.0353743342416867,0.00671948062049345,0.25,3.31884197300153E-5,0.0031433231346151,5.28871969790509E-5,30.0060158,30.0061531,14609.7373046875,14620.0341796875,56.882233858506,20.6238722947231,16.834587,0,0,0,40,4449,29.93765,14614.8857421875,,,,,,,,,,,,,0,,,,0.00245,,,,,,30.00608445,,,,
,32694808.075,30.0070839,15771.720703125,0.00317078211046999,8.16395808285768E-7,1,0.999253354069792,40.0298881530762,1.99160803125131,28.0200000852346,0.0355232261639911,0.00671299776222908,0.25,3.01402199781197E-5,0.00315778301477139,5.0146363850452E-5,30.0070839,30.0070839,15764.400390625,15779.041015625,56.4929828559291,20.6373317041079,15.695635,0,0,0,40,4449,29.93245,15771.720703125,,,,,,,,,,,,,0,,,,0.0049,,,,,,30.0070839,,,,
,32694832.68,30.0054035,17001.0478515625,0.00318396021052102,6.15442456045452E-7,1,0.999253354069792,40.0298881530762,1.99157420263794,28.0200000852346,0.0356720589236217,0.00675388937576134,0.25,3.11540240583431E-5,0.00317125436143572,5.14562682135299E-5,30.0054035,30.0054035,16988.5546875,17013.541015625,56.0701218270252,20.6374527014461,16.075285,0,0,0,40,4449,29.9343,17001.0478515625,,,,,,,,,,,,,0,,,,0.0049,,,,,,30.0054035,,,,
,32694855.205,30.0045147,18128.16015625,0.00319633732663662,8.26320519300941E-7,1,0.999253354069792,40.0298881530762,1.99166228486381,28.0200000852346,0.0358196402725144,0.00676059975945923,0.25,2.92558268129328E-5,0.0031839245006592,4.98392741764869E-5,30.0045147,30.0045147,18123.001953125,18133.318359375,56.2991389831598,20.6420007538939,16.075285,0,0,0,40,4449,29.9355,18128.16015625,,,,,,,,,,,,,0,,,,0,,,,,,30.0045147,,,,
,32694877.51,30.0047283,19242.5009765625,0.00319924981056568,7.06777361050209E-7,1,0.999253354069792,40.0298881530762,1.99148043390156,28.0300006270409,0.0358550787925124,0.00675453002010973,0.25,2.80006148834426E-5,0.00318716285227224,4.87945454950173E-5,30.0047283,30.0047283,19232.568359375,19252.43359375,55.9552224346982,20.6477833881068,16.454937,0,0,0,40,4449,29.93315,19242.5009765625,,,,,,,,,,,,,0,,,,-0.00245,,,,,,30.0047283,,,,
,32694923.125,30.0049114,19666.62890625,0.00320683052568013,9.60936691549957E-7,1,0.999253354069792,40.0298881530762,1.99180030790659,28.0300006270409,0.0359420786052673,0.00679922187072103,0.25,3.04366279754976E-5,0.00319482683814546,5.13416627567574E-5,30.0049114,30.0049114,19659.326171875,19673.931640625,56.3671406643329,20.6514875886038,16.834587,0,0,0,40,4449,29.9351,19666.62890625,,,,,,,,,,,,,0,,,,0,,,,,,30.0049114,,,,
,32694946.765,30.002737,18492.77734375,0.00319779739546669,8.39993649393329E-7,1,0.999253354069792,40.0298881530762,1.99152736954574,28.0200000852346,0.0358306465489673,0.0067871127974146,0.25,3.13152233620414E-5,0.00318547186367463,5.19614665212222E-5,30.002737,30.002737,18485.236328125,18500.318359375,56.5961578204675,20.6508608252108,16.454937,0,0,0,40,4449,29.93215,18492.77734375,,,,,,,,,,,,,0,,,,0.00245,,,,,,30.002737,,,,
,32694968.905,30.0035629,17388.0185546875,0.00318523674788042,1.02543649433896E-6,1,0.999253354069792,40.0298881530762,1.99146003132372,28.0200000852346,0.0356841466555675,0.00676499192410753,0.25,3.18605707207793E-5,0.00317263356080985,5.22353329722386E-5,30.0035629,30.0035629,17382.98046875,17393.056640625,56.8853603725829,20.6356204658798,16.454937,0,0,0,40,4449,29.9347,17388.0185546875,,,,,,,,,,,,,0,,,,-0.0049,,,,,,30.0035629,,,,
,32694991.985,30.0034046,16234.2338867188,0.00317161852726333,6.7474929222059E-7,1,0.999253354069792,40.0298881530762,1.99175418800464,28.0300006270409,0.0355349864403297,0.00672434611918043,0.25,3.08550204021745E-5,0.00315874268590205,5.09450129614349E-5,30.0034046,30.0034046,16229.146484375,16239.3212890625,56.6024108486214,20.6584578436311,16.075285,0,0,0,40,4449,29.9317,16234.2338867188,,,,,,,,,,,,,0,,,,0.00245,,,,,,30.0034046,,,,
,32695014.265,30.001236,15119.8579101562,0.00316445892434601,7.52723741105623E-7,1,0.999253354069792,40.0298881530762,1.99119905358506,28.0200000852346,0.0354445956319101,0.00669103818726323,0.25,2.95813706516462E-5,0.00315130564493955,4.94338141748456E-5,30.001236,30.001236,15109.7333984375,15129.982421875,57.1503324406022,20.6484957191448,16.075285,0,0,0,40,4449,29.93235,15119.8579101562,,,,,,,,,,,,,0,,,,-0.00245,,,,,,30.001236,,,,
,32695038.725,30.0018444,13900.7651367188,0.0031517190812599,7.82289120395717E-7,1,0.999253354069792,40.0298881530762,1.99094438533589,28.0200000852346,0.0352857713112366,0.00670732098520127,0.25,3.36665177334423E-5,0.0031382555982595,5.32023330401563E-5,30.0018444,30.0018444,13890.880859375,13910.6494140625,56.9314764552176,20.6746295761514,16.454937,0,0,0,40,4449,29.9323,13900.7651367188,,,,,,,,,,,,,0,,,,-0.0049,,,,,,30.0018444,,,,
,32695062.54,30.0018845,12708.4130859375,0.00313831316620648,7.09271771112421E-7,1,0.999253354069792,40.0298881530762,1.99103264319314,28.0200000852346,0.0351362941666578,0.00666290403962992,0.25,3.2357305032711E-5,0.00312459127752681,5.15966607162196E-5,30.0018845,30.0018845,12696.0595703125,12720.7666015625,57.1354814987368,20.6661035249686,16.454937,0,0,0,40,4449,29.9284,12708.4130859375,,,,,,,,,,,,,0,,,,0.00245,,,,,,30.0018845,,,,
,32695085.825,30.0011845,11544.2602539062,0.00312136167930038,6.6560372286645E-7,1,0.999253354069792,40.0298881530762,1.99106528448724,28.0200000852346,0.0349432734379214,0.0066282704287425,0.25,3.25613949211792E-5,0.0031074069994026,5.14819557139135E-5,30.0011845,30.0011845,11531.880859375,11556.6396484375,56.3976241765829,20.6620517806312,15.695635,0,0,0,40,4449,29.93175,11544.2602539062,,,,,,,,,,,,,0,,,,0.0049,,,,,,30.0011845,,,,
,32695108.265,30.000061,10422.2368164062,0.00310279792795213,6.30971310633367E-7,1,0.999253354069792,40.0298881530762,1.99115486732838,28.0200000852346,0.0347350583496218,0.00658101859906288,0.25,3.19019920344413E-5,0.00308864307453122,5.0505147094679E-5,30.000061,30.000061,10412.234375,10432.2392578125,55.7762295037944,20.6630446962637,16.075285,0,0,0,40,4449,29.9327,10422.2368164062,,,,,,,,,,,,,0,,,,-0.00245,,,,,,30.000061,,,,
,32695131.5,29.9999294,9262.841796875,0.00307854110576197,7.46196339863114E-7,1,0.999253354069792,40.0298881530762,1.99099827329131,28.0200000852346,0.0344623594901722,0.00650234950334964,0.25,2.95334648602958E-5,0.00306422351986737,4.77871717943353E-5,29.9999294,29.9999294,9252.9853515625,9272.6982421875,55.8997268098328,20.6712375834937,16.075285,0,0,0,40,4449,29.9332,9262.841796875,,,,,,,,,,,,,0,,,,0,,,,,,29.9999294,,,,
,32695153.415,30.0000629,8165.349609375,0.00305866765106006,6.65645711457717E-7,1,0.999253354069792,40.0298881530762,1.99030891887538,28.0300006270409,0.0342169432425899,0.00650619716798295,0.25,3.38695067203159E-5,0.00304415400776203,5.1782695348313E-5,30.0000629,30.0000629,8152.9287109375,8177.7705078125,56.1303072230059,20.684460157858,16.075285,0,0,0,40,4449,29.9335,8165.349609375,,,,,,,,,,,,,0,,,,0.00245,,,,,,30.0000629,,,,
,32695175.63,29.9996796,7055.8984375,0.00303009368808443,6.32981903803288E-7,1,0.999253354069792,40.0298881530762,1.99129580714833,28.0200000852346,0.0339112224731565,0.00644365994333233,0.25,3.33722920608046E-5,0.00301546204821637,5.09164087541528E-5,29.9996796,29.9996796,7043.24609375,7068.55078125,57.0205821064099,20.6746596332135,16.075285,0,0,0,40,4449,29.93115,7055.8984375,,,,,,,,,,,,,0,,,,0,,,,,,29.9996796,,,,
,32695198.065,29.9986286,5936.46728515625,0.00299280948918378,5.25077385147373E-7,1,0.999253354069792,40.0298881530762,1.99183194135208,28.0200000852346,0.033495482538104,0.00638975565304089,0.25,3.53217653961353E-5,0.00297810082091978,5.24391699821048E-5,29.9986286,29.9986286,5933.78125,5939.1533203125,57.1206305568714,20.6744438894333,16.075285,0,0,0,40,4449,29.9327,5936.46728515625,,,,,,,,,,,,,0,,,,0,,,,,,29.9986286,,,,
,32695220.765,29.9990692,4799.41430664063,0.00293774770779016,5.55346326660244E-7,1,0.999253354069792,40.0298881530762,1.99118609592624,28.0200000852346,0.0328660543243682,0.00627184174395387,0.25,3.50511715731086E-5,0.00292307503089463,5.16555746359717E-5,29.9990692,29.9990692,4789.47705078125,4809.3515625,56.4429586306983,20.6712680698261,16.075285,0,0,0,40,4449,29.9338,4799.41430664063,,,,,,,,,,,,,0,,,,-0.00245,,,,,,29.9990692,,,,
,32695244.035,29.9977531,3637.35754394531,0.00284957670947471,5.87669706916942E-7,1,0.999253354069792,40.0298881530762,1.99114937835862,28.0200000852346,0.0318792959821638,0.00606796248449089,0.25,3.28425324156928E-5,0.00283513216871163,4.87644170355273E-5,29.9977531,29.9977531,3634.93676757812,3639.7783203125,57.0878021590637,20.6820207361033,16.075285,0,0,0,40,4449,29.93345,3637.35754394531,,,,,,,,,,,,,0,,,,0.0049,,,,,,29.9977531,,,,
,32695268.115,29.9993973,2432.44506835938,0.00267882154058727,7.10020985255584E-7,1,0.999253354069792,40.0298881530762,1.99204417636661,28.0200000852346,0.0299760427560752,0.00572636235655039,0.25,3.28313403224824E-5,0.00266503319502522,4.76123228503113E-5,29.9993973,29.9993973,2429.90478515625,2434.9853515625,56.279598270179,20.6676127231514,16.075285,0,0,0,40,4449,29.9334,2432.44506835938,,,,,,,,,,,,,0,,,,-0.0049,,,,,,29.9993973,,,,
,32695290.88,29.9961567,1295.03552246094,0.00228578890842923,1.32157133581025E-6,1,0.999253354069792,40.0298881530762,1.99265758846166,28.0200000852346,0.0255846560909741,0.00488310884848098,0.25,2.77675377204038E-5,0.00227388178063932,4.0250088394381E-5,29.9961567,29.9961567,1285.19177246094,1304.87927246094,57.2230238928907,20.6511697132095,15.695635,0,0,0,40,4449,29.93595,1295.03552246094,,,,,,,,,,,,,0,,,,-0.0049,,,,,,29.9961567,,,,
,32695314.625,29.9978485,107.821292877197,0.000719749877822275,7.21185557322551E-6,1,0.999253354069792,40.0298881530762,1.99235017019649,28.0200000852346,0.00805609681626371,0.00152826826549162,0.25,7.97421234311407E-6,0.000715966907171326,1.18733397971126E-5,29.9978485,29.9978485,95.2360305786133,120.406555175781,57.0229269919676,20.6592060189911,15.695635,0,0,0,40,4449,29.9358,107.821292877197,,,,,,,,,,,,,0,,,,0,,,,,,29.9978485,,,,
,32695336.985,29.9970226,-1007.673828125,-0.00189872444489645,2.37290948227805E-6,1,0.999253354069792,40.0298881530762,1.99208661179836,28.0200000852346,-0.0212448658566743,-0.00406226726003609,0.25,-2.37333700460006E-5,-0.00188880261069321,-3.40733964604492E-5,29.9970226,29.9970226,-1012.94396972656,-1002.40368652344,55.964601976929,20.6680116416879,16.454937,0,0,0,40,4449,29.9363,-1007.673828125,,,,,,,,,,,,,0,,,,-0.0049,,,,,,29.9970226,,,,
,32695360.245,30.000742,-2169.42199707031,-0.00255187622175186,7.97412856106906E-7,1,0.999253354069792,40.0298881530762,1.99259183343114,28.0200000852346,-0.0285643152349534,-0.00544667427342151,0.25,-3.04469078025891E-5,-0.00253870801462147,-4.44973129170254E-5,30.000742,30.000742,-2174.33837890625,-2164.50561523438,56.8963031718522,20.6404646064104,15.695635,0,0,0,40,4449,29.9371,-2169.42199707031,,,,,,,,,,,,,0,,,,0,,,,,,30.000742,,,,
,32695383.335,29.9986534,-3322.73400878906,-0.00278991452782778,6.12014007637525E-7,1,0.999253354069792,40.0298881530762,1.99310159288489,28.0200000852346,-0.0312392246605461,-0.00595308544752961,0.25,-3.28023129263486E-5,-0.00277571367312643,-4.83389643467561E-5,29.9986534,29.9986534,-3332.70825195313,-3312.759765625,56.8079791491791,20.6626253301397,16.075285,0,0,0,40,4449,29.9352,-3322.73400878906,,,,,,,,,,,,,0,,,,0.00245,,,,,,29.9986534,,,,
,32695406.04,29.9995308,-4458.8056640625,-0.00289785701422857,4.61378040979447E-7,1,0.999253354069792,40.0298881530762,1.99389215147244,28.0200000852346,-0.0324630076442662,-0.00618375987296813,0.25,-3.3669873143028E-5,-0.00288332163566947,-4.99956110765905E-5,29.9995308,29.9995308,-4468.78125,-4448.830078125,56.8845787440637,20.64718529408,15.695635,0,0,0,40,4449,29.9322,-4458.8056640625,,,,,,,,,,,,,0,,,,-0.0049,,,,,,29.9995308,,,,
,32695428.18,29.9989109,-5566.23657226562,-0.00296650393948244,4.56583388572004E-7,1,0.999253354069792,40.0298881530762,1.99338951168107,28.0200000852346,-0.0332259044434881,-0.00633297872000976,0.25,-3.46139909252209E-5,-0.00295184933672257,-5.15180769957125E-5,29.9989109,29.9989109,-5573.84228515625,-5558.630859375,56.6930797568522,20.6594000697414,16.075285,0,0,0,40,4449,29.9335,-5566.23657226562,,,,,,,,,,,,,0,,,,0.0049,,,,,,29.9989109,,,,
,32695451.555,29.9982452,-6733.12133789063,-0.00301264521531277,6.57361687714432E-7,1,0.999253354069792,40.0298881530762,1.99369946948867,28.0200000852346,-0.0337486867752303,-0.00644358062912913,0.25,-3.58900386088198E-5,-0.00299801189644424,-5.32632637731908E-5,29.9982452,29.9982452,-6743.0185546875,-6723.22412109375,56.3976241765829,20.6371999200545,15.695635,0,0,0,40,4449,29.93595,-6733.12133789063,,,,,,,,,,,,,0,,,,0,,,,,,29.9982452,,,,
,32695473.785,29.9981985,-7842.69311523437,-0.0030440474864398,4.86732200482816E-7,1,0.999253354069792,40.0298881530762,1.99355603639745,28.0200000852346,-0.0341089006091181,-0.00646650312773048,0.25,-3.21152076645582E-5,-0.00302953847307026,-4.98918846393135E-5,29.9980221,29.9983749,-7847.74853515625,-7837.6376953125,56.8611298884868,20.6700123043324,16.454937,0,0,0,40,4449,29.9361,-7842.69311523437,,,,,,,,,,,,,0,,,,0,,,,,,29.9981985,,,,
,32695496.79,29.9977608,-8995.1435546875,-0.00307231066518154,6.3724279539513E-7,1,0.999253354069792,40.0298881530762,1.99372753920667,28.0200000852346,-0.0344290440251272,-0.00654150434532407,0.25,-3.34364957764866E-5,-0.00305793470060139,-5.1586424162756E-5,29.9975071,29.9980145,-9007.451171875,-8982.8359375,57.3691884259868,20.6576447651679,16.075285,0,0,0,40,4449,29.9363,-8995.1435546875,,,,,,,,,,,,,0,,,,0.00245,,,,,,29.9977608,,,,
,32695519.94,29.996954,-10152.3076171875,-0.00309109562917054,6.26343043197703E-7,1,0.999253354069792,40.0298881530762,1.99426947601672,28.0200000852346,-0.0346580773914193,-0.00654854606073218,0.25,-3.02890351118989E-5,-0.003076937356431,-4.87801777018173E-5,29.996954,29.996954,-10157.4365234375,-10147.1787109375,56.6962062709291,20.6691537870451,15.695635,0,0,0,40,4449,29.93775,-10152.3076171875,,,,,,,,,,,,,0,,,,0,,,,,,29.996954,,,,
,32695543.58,29.9980488,-11331.7543945312,-0.00311410897831448,6.60692020088528E-7,1,0.999253354069792,40.0298881530762,1.99372041038419,28.0200000852346,-0.0349072120384984,-0.00661362137811162,0.25,-3.1850540856083E-5,-0.00310013738116858,-5.0691897893653E-5,29.9980488,29.9980488,-11341.796875,-11321.7119140625,56.679010443506,20.67485580412,16.075285,0,0,0,40,4449,29.93655,-11331.7543945312,,,,,,,,,,,,,0,,,,-0.00245,,,,,,29.9980488,,,,
,32695566.77,29.9985485,-12493.5102539062,-0.00313089485289771,4.92748800476196E-7,1,0.999253354069792,40.0298881530762,1.99371252638533,28.0200000852346,-0.0350950280449811,-0.00667040203657076,0.25,-3.36364774308641E-5,-0.00311714382374403,-5.27877169145613E-5,29.9985485,29.9985485,-12496.130859375,-12490.8896484375,57.7607843141215,20.6702086544183,15.695635,0,0,0,40,4449,29.9394,-12493.5102539062,,,,,,,,,,,,,0,,,,0.00245,,,,,,29.9985485,,,,
,32695590.21,29.9983387,-13663.408203125,-0.00314598354154322,7.07348303452462E-7,1,0.999253354069792,40.0298881530762,1.99399529799799,28.0200000852346,-0.035274270471611,-0.00669414982298267,0.25,-3.27009037474504E-5,-0.00313248686549675,-5.21627250987454E-5,29.9983387,29.9983387,-13675.84375,-13650.97265625,57.4121779945445,20.6772076072481,15.695635,0,0,0,40,4449,29.93595,-13663.408203125,,,,,,,,,,,,,0,,,,-0.00245,,,,,,29.9983387,,,,
,32695613.03,30.0020542,-14805.2084960938,-0.00315491492725613,7.02580677671422E-7,1,0.999253354069792,40.0298881530762,1.99377522772853,28.0200000852346,-0.0353772583567242,-0.00669630818962258,0.25,-3.10943290106095E-5,-0.00314170557612059,-5.08253882915466E-5,30.0020542,30.0020542,-14815.353515625,-14795.0634765625,56.5383173100444,20.6609686590804,16.075285,0,0,0,40,4449,29.93805,-14805.2084960938,,,,,,,,,,,,,0,,,,-0.00245,,,,,,30.0020542,,,,
,32695636.97,30.0015011,-16002.1850585938,-0.0031704040455826,8.88228664855966E-7,1,0.999253354069792,40.0298881530762,1.99335217042309,28.0200000852346,-0.0355544363215059,-0.00669005816606219,0.25,-2.76127554000191E-5,-0.00315748912255753,-4.76680610836868E-5,30.0015011,30.0015011,-16009.2373046875,-15995.1328125,57.169873153583,20.6873416922493,16.075285,0,0,0,40,4449,29.93565,-16002.1850585938,,,,,,,,,,,,,0,,,,-0.00245,,,,,,30.0015011,,,,
,32695659.07,30.0005131,-17106.1259765625,-0.00318177680849881,8.19122933995406E-7,1,0.999253354069792,40.0298881530762,1.99381329985232,28.0200000852346,-0.0356880679071434,-0.00674613316424985,0.25,-3.01864713216677E-5,-0.0031691158386707,-5.04965172493518E-5,30.0005131,30.0005131,-17108.580078125,-17103.671875,56.2670922138713,20.6895313746015,16.075285,0,0,0,40,4449,29.9333,-17106.1259765625,,,,,,,,,,,,,0,,,,0,,,,,,30.0005131,,,,
,32695682.245,30.00106335,-18263.9296875,-0.00319366233650174,7.46364542997938E-7,1,0.999253354069792,40.0298881530762,1.99415432762472,28.0200000852346,-0.0358339817787595,-0.00675684425251049,0.25,-2.86528427756443E-5,-0.00318130323708865,-4.92441062130896E-5,30.0009003,30.0012264,-18273.583984375,-18254.275390625,57.352774227083,20.6671182403628,16.075285,0,0,0,40,4449,29.93445,-18263.9296875,,,,,,,,,,,,,0,,,,-0.00245,,,,,,30.00106335,,,,
,32695704.31,30.0013771,-19367.9765625,-0.00319730857712393,7.74783142535419E-7,1,0.999253354069792,40.0298881530762,1.99378155441646,28.0200000852346,-0.035881240176476,-0.0067136111056246,0.25,-2.40161896537313E-5,-0.00318529346568988,-4.48336402225799E-5,30.0013771,30.0013771,-19378.033203125,-19357.919921875,57.3770047111791,20.6907712460472,16.075285,0,0,0,40,4449,29.9365,-19367.9765625,,,,,,,,,,,,,0,,,,0.00245,,,,,,30.0013771,,,,
,32695745.645,30.0008869,-19557.14453125,-0.00319694934563708,8.36147998830498E-7,1,0.999253354069792,40.0298881530762,1.99386651254215,28.0200000852346,-0.0358773121396059,-0.00672430374292423,0.25,-2.49674105514551E-5,-0.00318498480023341,-4.58096008458066E-5,30.0008831,30.0008907,-19569.609375,-19544.6796875,57.085457273506,20.6954023453096,16.075285,0,0,0,40,4449,29.93375,-19557.14453125,,,,,,,,,,,,,0,,,,0,,,,,,30.0008869,,,,
,32695768.18,30.0007553,-18437.5576171875,-0.00318926750033411,7.89147959653413E-7,1,0.999253354069792,40.0298881530762,1.9936389299896,28.0200000852346,-0.0357792253116613,-0.00673030537612731,0.25,-2.71891315094828E-5,-0.00317698526782617,-4.77865506168319E-5,30.0007553,30.0007553,-18444.90625,-18430.208984375,56.7954730928714,20.7027406073182,16.454937,0,0,0,40,4449,29.93325,-18437.5576171875,,,,,,,,,,,,,0,,,,0,,,,,,30.0007553,,,,
,32695790.845,30.000124,-17305.8359375,-0.00314555156637339,1.12577290917447E-6,1,0.999253354069792,40.0298881530762,1.99376979025759,28.0200000852346,-0.0352079318464746,-0.00708071815644945,0.25,-6.64259031602825E-5,-0.00313285725717711,-8.63965589828063E-5,30.000124,30.000124,-17313.3046875,-17298.3671875,57.190195495083,20.6960129467903,15.695635,0,0,0,40,4449,29.9352,-17305.8359375,,,,,,,,,,,,,0,,,,-0.00245,,,,,,30.000124,,,,
,32695813.785,29.9990005,-16158.9838867188,-0.00313541194713526,1.52462321903002E-6,1,0.999253354069792,40.0298881530762,1.99377339918927,28.0200000852346,-0.0350894813032901,-0.00706479597875214,0.25,-6.70838882294889E-5,-0.00312242918392998,-8.67850832208953E-5,29.9990005,29.9990005,-16164.060546875,-16153.9072265625,58.10782737666,20.7054844808062,16.075285,0,0,0,40,4449,29.9322,-16158.9838867188,,,,,,,,,,,,,0,,,,0,,,,,,29.9990005,,,,
,32695835.915,30.0022678,-15055.01171875,-0.00312769741518614,1.38599274264541E-6,1,0.999253354069792,40.0298881530762,1.99388410462716,28.0200000852346,-0.0350010546916039,-0.00704997379859944,0.25,-6.73634224777182E-5,-0.00311443972629434,-8.68181648851067E-5,30.0022678,30.0022678,-15059.98046875,-15050.04296875,57.6482298073523,20.6798396769355,16.454937,0,0,0,40,4449,29.936,-15055.01171875,,,,,,,,,,,,,0,,,,0,,,,,,30.0022678,,,,
,32695858.835,30.0001965,-13910.7026367188,-0.00311094375891676,1.35337356792263E-6,1,0.999253354069792,40.0298881530762,1.99392817708149,28.0200000852346,-0.0348085961158574,-0.00702400262527507,0.25,-6.8301165521557E-5,-0.00309743902098007,-8.74391354806415E-5,30.0001965,30.0001965,-13915.5380859375,-13905.8671875,57.474708276083,20.6579055666483,16.454937,0,0,0,40,4449,29.9347,-13910.7026367188,,,,,,,,,,,,,0,,,,0,,,,,,30.0001965,,,,
,32695882.57,30.0000973,-12723.2978515625,-0.00309611050641507,1.18564664420425E-6,1,0.999253354069792,40.0298881530762,1.9939982389702,28.0200000852346,-0.0346320056517129,-0.00703614881064926,0.25,-7.22895499212626E-5,-0.00308233080479228,-9.11011253652694E-5,30.0000973,30.0000973,-12730.83984375,-12715.755859375,57.312129544083,20.636766804709,16.454937,0,0,0,40,4449,29.9372,-12723.2978515625,,,,,,,,,,,,,0,,,,0.0049,,,,,,30.0000973,,,,
,32695905.055,29.9981785,-11598.8198242187,-0.003082114375695,1.47401682400062E-6,1,0.999253354069792,40.0298881530762,1.99370931286163,28.0200000852346,-0.0344642487376766,-0.00702038492607767,0.25,-7.37374040772056E-5,-0.00306809627145743,-9.224780696486E-5,29.9981785,29.9981785,-11601.2646484375,-11596.375,56.6532167023714,20.661130109569,16.075285,0,0,0,40,4449,29.9352,-11598.8198242187,,,,,,,,,,,,,0,,,,0.0049,,,,,,29.9981785,,,,
,32695928.58,29.9996223,-10422.017578125,-0.0030675701188477,1.5010709346087E-6,1,0.999253354069792,40.0298881530762,1.99387637662619,28.0200000852346,-0.0343009707976959,-0.00698751207524346,0.25,-7.36336536335942E-5,-0.00305332234826791,-9.18367044989419E-5,29.9996223,29.9996223,-10432.0830078125,-10411.9521484375,57.3465211989291,20.6440779696403,15.695635,0,0,0,40,4449,29.9349,-10422.017578125,,,,,,,,,,,,,0,,,,-0.00245,,,,,,29.9996223,,,,
,32695950.915,29.9989147,-9305.1142578125,-0.00304456142180464,1.37099976396802E-6,1,0.999253354069792,40.0298881530762,1.99394509990354,28.0200000852346,-0.0340429669606477,-0.00692802149661559,0.25,-7.26855605480236E-5,-0.00303015339997793,-9.05468378958361E-5,29.9989147,29.9989147,-9307.650390625,-9302.578125,56.2881961838906,20.6684946309229,16.075285,0,0,0,40,4449,29.9366,-9305.1142578125,,,,,,,,,,,,,0,,,,0,,,,,,29.9989147,,,,
,32695973.19,30.0012722,-8189.92504882813,-0.00302028903172546,1.27025120790878E-6,1,0.999253354069792,40.0298881530762,1.99409229340499,28.0200000852346,-0.0337747595163695,-0.00685166276511249,0.25,-7.04342240283117E-5,-0.00300574537434011,-8.7954727851633E-5,30.0012722,30.0012722,-8197.3876953125,-8182.46240234375,57.413741251583,20.6585967388938,15.695635,0,0,0,40,4449,29.9359,-8189.92504882813,,,,,,,,,,,,,0,,,,-0.00245,,,,,,30.0012722,,,,
,32695995.68,30.0009747,-7067.9072265625,-0.00298315813870991,1.10659896771139E-6,1,0.999253354069792,40.0298881530762,1.99385265073182,28.0300006270409,-0.0333613345855394,-0.00671875059116486,0.25,-6.55509199103807E-5,-0.00296856591894461,-8.267066278791E-5,30.0009747,30.0009747,-7072.8291015625,-7062.9853515625,56.2678738423906,20.6477869051055,16.075285,0,0,0,40,4449,29.93475,-7067.9072265625,,,,,,,,,,,,,0,,,,0.0049,,,,,,30.0009747,,,,
,32696019.615,29.99879835,-5871.13037109375,-0.00294483102873858,1.27902634972099E-6,1,0.999253354069792,40.0298881530762,1.99376679304696,28.0200000852346,-0.0329231562863272,-0.00666147757176717,0.25,-6.75786159853105E-5,-0.00293015594350005,-8.42517936562481E-5,29.9985275,29.9990692,-5878.685546875,-5863.5751953125,56.0599606562752,20.6310902099969,16.075285,0,0,0,40,4449,29.9357,-5871.13037109375,,,,,,,,,,,,,0,,,,0.0049,,,,,,29.99879835,,,,
,32696041.735,29.998333,-4766.61157226562,-0.00289351986823196,1.32397317807938E-6,1,0.999253354069792,40.0298881530762,1.99359681157362,28.0200000852346,-0.0323409221359592,-0.00656382791113199,0.25,-6.83180591884E-5,-0.00287887063719138,-8.45020784150141E-5,29.998333,29.998333,-4773.97509765625,-4759.248046875,57.759221057083,20.6378424763796,16.454937,0,0,0,40,4449,29.9398,-4766.61157226562,,,,,,,,,,,,,0,,,,-0.0049,,,,,,29.998333,,,,
,32696064.925,30.001236,-3606.73364257812,-0.00280475179942767,1.19355539944939E-6,1,0.999253354069792,40.0298881530762,1.99319457783803,28.0200000852346,-0.0313366072600216,-0.00638149658780649,0.25,-6.82560166853638E-5,-0.00279032678652695,-8.37433187595071E-5,30.001236,30.001236,-3614.40625,-3599.06103515625,56.5039256551983,20.6301832733727,16.075285,0,0,0,40,4449,29.9355,-3606.73364257812,,,,,,,,,,,,,0,,,,-0.00245,,,,,,30.001236,,,,
,32696086.95,30.0000687,-2506.92822265625,-0.00264661566177401,1.21103863343835E-6,1,0.999253354069792,40.0298881530762,1.99378825621388,28.0200000852346,-0.0295834275587905,-0.00598254146612946,0.25,-6.09600545848814E-5,-0.00263284611562398,-7.54297412849176E-5,30.0000687,30.0000687,-2514.21875,-2499.6376953125,56.926005055583,20.6620100491887,15.315984,0,0,0,40,4449,29.93585,-2506.92822265625,,,,,,,,,,,,,0,,,,-0.00245,,,,,,30.0000687,,,,
,32696109.905,29.9993973,-1359.46362304688,-0.00228177423941676,1.61891855821252E-6,1,0.999253354069792,40.0298881530762,1.99391938145179,28.0200000852346,-0.0255035053887569,-0.00516768088544576,0.25,-5.35656102565201E-5,-0.00226975289906739,-6.59005996763528E-5,29.9991417,29.9996529,-1364.72961425781,-1354.19763183594,55.6777443103713,20.6447929266425,15.695635,0,0,0,40,4449,29.9366,-1359.46362304688,,,,,,,,,,,,,0,,,,-0.0049,,,,,,29.9993973,,,,
,32696132.25,29.9997158,-239.819007873535,-0.00111808755744853,4.91747410734106E-6,1,0.999253354069792,40.0298881530762,1.99399573753489,28.0200000852346,-0.0125068559903705,-0.00247539296957503,0.25,-2.12421274043645E-5,-0.00111216759137365,-2.72580945913924E-5,29.9997158,29.9997158,-244.599838256836,-235.038177490234,57.2370932062368,20.6382378468842,16.075285,0,0,0,40,4449,29.9369,-239.819007873535,,,,,,,,,,,,,0,,,,0.00245,,,,,,29.9997158,,,,
,32696153.99,29.9994164,846.249420166016,0.00169877382820062,3.10619885909741E-6,1,0.999253354069792,40.0298881530762,1.99343116961163,28.0200000852346,0.0189820261982675,0.00384818246527506,0.25,4.00847409390621E-5,0.00168977989422873,4.92262328756246E-5,29.9994164,29.9994164,843.786071777344,848.712768554687,56.7282530402175,20.6477914646288,16.454937,0,0,0,40,4449,29.9362,846.249420166016,,,,,,,,,,,,,0,,,,0,,,,,,29.9994164,,,,
,32696176.41,29.9965343,1962.85150146484,0.00244567801010171,1.00051770427558E-6,1,0.999253354069792,40.0298881530762,1.99371931204548,28.0200000852346,0.0273418130748828,0.0054933119191997,0.25,5.33108630655081E-5,0.00243289568323002,6.66277445724121E-5,29.9965343,29.9965343,1955.23950195313,1970.46350097656,56.8884868866599,20.6398899963536,16.075285,0,0,0,40,4449,29.93905,1962.85150146484,,,,,,,,,,,,,0,,,,-0.0049,,,,,,29.9965343,,,,
,32696198.915,29.9977283,3085.42553710937,0.00271109691101331,8.78025714765153E-7,1,0.999253354069792,40.0298881530762,1.99415277834207,28.0200000852346,0.0303101559645089,0.00613175069793492,0.25,6.25541508963565E-5,0.00269708561436675,7.74623105864114E-5,29.9977283,29.9977283,3077.8681640625,3092.98291015625,57.5247325013138,20.6390619954823,16.454937,0,0,0,40,4449,29.9374,3085.42553710937,,,,,,,,,,,,,0,,,,0.0049,,,,,,29.9977283,,,,
,32696222.285,29.9987698,4256.22387695313,0.00283783283864689,1.18809452910455E-6,1,0.999253354069792,40.0298881530762,1.9930873385669,28.0200000852346,0.0317202623954197,0.00637639106946224,0.25,6.17998139489824E-5,0.00282339824343901,7.76127081266947E-5,29.9987698,29.9987698,4243.6220703125,4268.82568359375,55.8794044683328,20.6644133654852,16.075285,0,0,0,40,4449,29.9376,4256.22387695313,,,,,,,,,,,,,0,,,,-0.00245,,,,,,29.9987698,,,,
,32696244.305,30.0006542,5356.826171875,0.00290778443606238,9.75309446874307E-7,1,0.999253354069792,40.0298881530762,1.99339515269763,28.0200000852346,0.0325052364890562,0.00655827053313693,0.25,6.52111004452327E-5,0.00289319922490401,8.15931995951773E-5,30.0006542,30.0006542,5349.24169921875,5364.41064453125,56.4023139476983,20.6368987028206,16.075285,0,0,0,40,4449,29.93855,5356.826171875,,,,,,,,,,,,,0,,,,0,,,,,,30.0006542,,,,
,32696266.93,30.0017071,6488.84545898438,0.00295467053091012,1.17945671428084E-6,1,0.999253354069792,40.0298881530762,1.99326644170612,28.0200000852346,0.0330340284558774,0.00664150922516869,0.25,6.40512010913553E-5,0.0029400986382009,8.09084966570566E-5,30.0017071,30.0017071,6483.48779296875,6494.203125,56.6915164998137,20.6430577468014,16.454937,0,0,0,40,4449,29.9367,6488.84545898438,,,,,,,,,,,,,0,,,,0.0049,,,,,,30.0017071,,,,
,32696289.205,30.0029602,7600.7373046875,0.00298730066582975,1.1304603607281E-6,1,0.999253354069792,40.0298881530762,1.99406240482655,28.0200000852346,0.0334133223474454,0.00672361065768792,0.25,6.50654055807615E-5,0.00297281010795749,8.23088079718976E-5,30.0029602,30.0029602,7593.09765625,7608.376953125,56.9689946241406,20.6276947115705,16.075285,0,0,0,40,4449,29.936,7600.7373046875,,,,,,,,,,,,,0,,,,-0.00245,,,,,,30.0029602,,,,
,32696312.285,29.9999638,8754.96044921875,0.00301637539172743,1.37262142441636E-6,1,0.999253354069792,40.0298881530762,1.99420492289324,28.0200000852346,0.0337492123426757,0.006759983518544,0.25,6.28093730999174E-5,0.00300202646925349,8.04465681065434E-5,29.9999638,29.9999638,8747.3857421875,8762.53515625,56.3249327242944,20.6166075845193,16.075285,0,0,0,40,4449,29.93705,8754.96044921875,,,,,,,,,,,,,0,,,,0.00245,,,,,,29.9999638,,,,
,32696335.485,29.999548,9912.73095703125,0.00304515609382334,1.0832015953865E-6,1,0.999253354069792,40.0298881530762,1.99427855139565,28.0200000852346,0.0340683132681397,0.00686587834268995,0.25,6.6808878506266E-5,0.00303092687405775,8.48134957655156E-5,29.999548,29.999548,9902.5927734375,9922.869140625,56.9791557948906,20.6212183713352,16.075285,0,0,0,40,4449,29.937,9912.73095703125,,,,,,,,,,,,,0,,,,0.00245,,,,,,29.999548,,,,
,32696358.165,29.9985027,11047.1391601562,0.00306648149027677,1.35658933348061E-6,1,0.999253354069792,40.0298881530762,1.99424490901309,28.0200000852346,0.034308922604937,0.00691774767747949,0.25,6.73634112529057E-5,0.00305243224747732,8.57043619840447E-5,29.9985027,29.9985027,11037.1220703125,11057.15625,56.8236117195637,20.6204293750646,15.695635,0,0,0,40,4449,29.93545,11047.1391601562,,,,,,,,,,,,,0,,,,0.00245,,,,,,29.9985027,,,,
,32696380.265,30.0011711,12154.015625,0.00307012303837322,9.84849675730922E-7,1,0.999253354069792,40.0298881530762,1.99302745556783,28.0200000852346,0.0343412177307724,0.00687565144920032,0.25,6.3066597605353E-5,0.00305636551311982,8.16534436507521E-5,30.0011711,30.0011711,12146.77734375,12161.25390625,57.4067065949099,20.642483769998,15.695635,0,0,0,40,4449,29.93785,12154.015625,,,,,,,,,,,,,0,,,,0.00245,,,,,,30.0011711,,,,
,32696403.395,30.0007,13308.0825195313,0.00309310009008267,1.22000461345594E-6,1,0.999253354069792,40.0298881530762,1.99262727324635,28.0200000852346,0.0345866714415166,0.00697294711390753,0.25,6.74754224061523E-5,0.00307951607309725,8.63960141796267E-5,30.0007,30.0007,13290.134765625,13326.0302734375,56.4382688595829,20.6565149590994,16.075285,0,0,0,40,4449,29.93575,13308.0825195313,,,,,,,,,,,,,0,,,,0,,,,,,30.0007,,,,
,32696425.595,30.0001698,14418.01953125,0.00310007378581731,1.20646519475513E-6,1,0.999253354069792,40.0298881530762,1.99281112561559,28.0200000852346,0.03467841478312,0.00694880303840788,0.25,6.37678587267021E-5,0.00308677961185349,8.29489424764865E-5,30.0001698,30.0001698,14405.6025390625,14430.4365234375,56.729816297256,20.6486836844338,16.075285,0,0,0,40,4449,29.93585,14418.01953125,,,,,,,,,,,,,0,,,,0,,,,,,30.0001698,,,,
,32696449.295,30.0033379,15602.2250976562,0.00311237076624347,9.9401787180853E-7,1,0.999253354069792,40.0298881530762,1.99305875495505,28.0200000852346,0.0348125340298044,0.00704053000566067,0.25,6.93914067178677E-5,0.00309931302701248,8.88388722960952E-5,30.0027657,30.0039101,15594.7080078125,15609.7421875,56.7134020983521,20.6438806440599,16.075285,0,0,0,40,4449,29.9359,15602.2250976562,,,,,,,,,,,,,0,,,,-0.00245,,,,,,30.0033379,,,,
,32696472.395,29.999403,16759.353515625,0.00312380023842067,1.14061179258522E-6,1,0.999253354069792,40.0298881530762,1.99283546538791,28.0200000852346,0.0349427481214944,0.0070524479951435,0.25,6.82121410091536E-5,0.00311102452269052,8.79403635416692E-5,29.999403,29.999403,16749.43359375,16769.2734375,56.648526931256,20.6558461853447,15.695635,0,0,0,40,4449,29.9323,16759.353515625,,,,,,,,,,,,,0,,,,0.0049,,,,,,29.999403,,,,
,32696496.04,30.0022831,17938.63671875,0.00313574788492708,1.0887420571719E-6,1,0.999253354069792,40.0298881530762,1.99298432940326,28.0200000852346,0.0350945675234985,0.00701434715930045,0.25,6.23702275130085E-5,0.00312329791540844,8.24022987189542E-5,30.0022831,30.0022831,17933.79296875,17943.48046875,57.4325003360445,20.6485340402234,16.075285,0,0,0,40,4449,29.93475,17938.63671875,,,,,,,,,,,,,0,,,,0,,,,,,30.0022831,,,,
,32696518.95,29.9996891,19083.0419921875,0.00313937165751144,1.36627473568795E-6,1,0.999253354069792,40.0298881530762,1.99350550301212,28.0200000852346,0.0351456085141753,0.00703618547702942,0.25,6.32565280322392E-5,0.00312723246177437,8.35023989258032E-5,29.9996891,29.9996891,19072.890625,19093.193359375,56.6852634716598,20.6498075263892,15.695635,0,0,0,40,4449,29.93725,19083.0419921875,,,,,,,,,,,,,0,,,,0,,,,,,29.9996891,,,,
,32696562.925,29.9998283,19812.951171875,0.00314347294223758,1.38298375775334E-6,1,0.999253354069792,40.0298881530762,1.99385302756502,28.0200000852346,0.0351974902434603,0.00705972407801421,0.25,6.43537305136856E-5,0.0031315229339535,8.47427210971081E-5,29.9998283,29.9998283,19807.833984375,19818.068359375,57.1675282680253,20.6480390786387,16.075285,0,0,0,40,4449,29.9349,19812.951171875,,,,,,,,,,,,,0,,,,0.0049,,,,,,29.9998283,,,,
,32696585.705,29.9995441,18679.6142578125,0.00313703367321573,1.30424394636666E-6,1,0.999253354069792,40.0298881530762,1.99380013398954,28.0200000852346,0.0351184218838611,0.00705764740862836,0.25,6.55852112178884E-5,0.00312477188775156,8.5739723962957E-5,29.9995441,29.9995441,18669.7734375,18689.455078125,56.2420801012559,20.6403512985424,15.695635,0,0,0,40,4449,29.9383,18679.6142578125,,,,,,,,,,,,,0,,,,0.0049,,,,,,29.9995441,,,,
,32696608.42,30.000885,17547.6669921875,0.00312344687701214,1.17007856447949E-6,1,0.999253354069792,40.0298881530762,1.99414513150539,28.0200000852346,0.0349735295591003,0.00699911378785993,0.25,6.2959291576688E-5,0.0031109292313499,8.28427294943591E-5,30.000885,30.000885,17542.5703125,17552.763671875,56.6743206723906,20.6372250782625,16.454937,0,0,0,40,4449,29.93445,17547.6669921875,,,,,,,,,,,,,0,,,,-0.0049,,,,,,30.000885,,,,
,32696631.785,30.0048428,16381.5634765625,0.00311343761882918,1.27030950995015E-6,1,0.999253354069792,40.0298881530762,1.99386895019693,28.0200000852346,0.0348533738302561,0.00697370371091171,0.25,6.28349459835146E-5,0.00310063095934048,8.24517539476663E-5,30.0048428,30.0048428,16378.96875,16384.158203125,56.4304525743906,20.6465817428703,15.695635,0,0,0,40,4449,29.9301,16381.5634765625,,,,,,,,,,,,,0,,,,0,,,,,,30.0048428,,,,
,32696653.915,30.00374415,15277.2143554687,0.00310353396733575,1.35971259778393E-6,1,0.999253354069792,40.0298881530762,1.99375064407901,28.0200000852346,0.0347417774390926,0.00692434707693256,0.25,6.04996039762363E-5,0.00309047705630758,7.98680935056207E-5,30.0036793,30.003809,15269.568359375,15284.8603515625,55.8575188697944,20.6451079739194,15.695635,0,0,0,40,4449,29.92925,15277.2143554687,,,,,,,,,,,,,0,,,,-0.0049,,,,,,30.00374415,,,,
,32696676.935,30.0049782,14125.3178710938,0.00309975031193295,1.05602346563553E-6,1,0.999253354069792,40.0298881530762,1.99362732142886,28.0200000852346,0.0346825721546648,0.00697778077060469,0.25,6.62327155676909E-5,0.00308636080401774,8.53469827800736E-5,30.0049782,30.0049782,14120.2724609375,14130.36328125,56.3343122665252,20.649683506626,15.695635,0,0,0,40,4449,29.9286,14125.3178710938,,,,,,,,,,,,,0,,,,0.00245,,,,,,30.0049782,,,,
,32696699.945,30.0039215,12973.0874023437,0.0030844412437455,1.19370055722029E-6,1,0.999253354069792,40.0298881530762,1.99411428208404,28.0200000852346,0.0345205928407584,0.00691796163328078,0.25,6.37676570178475E-5,0.00307082627168396,8.25872250985659E-5,30.0039215,30.0039215,12965.4814453125,12980.693359375,56.3999690621406,20.6363584143471,16.075285,0,0,0,40,4449,29.92745,12973.0874023437,,,,,,,,,,,,,0,,,,0,,,,,,30.0039215,,,,
,32696722.57,30.003479,11843.7036132812,0.00307260848339834,1.42593065357945E-6,1,0.999253354069792,40.0298881530762,1.99375803066269,28.0200000852346,0.0343767675576542,0.00690224819161924,0.25,6.48482949389274E-5,0.0030587482697834,8.33845294658618E-5,30.003479,30.003479,11831.0048828125,11856.40234375,56.9181887703906,20.6487511536277,15.695635,0,0,0,40,4449,29.93365,11843.7036132812,,,,,,,,,,,,,0,,,,-0.00245,,,,,,30.003479,,,,
,32696745.22,30.0027065,10711.6123046875,0.00305845407895718,1.13423898156181E-6,1,0.999253354069792,40.0298881530762,1.99354698754095,28.0200000852346,0.0342053046704966,0.00690500389698771,0.25,6.79489603259366E-5,0.00304435144302563,8.61749260900383E-5,30.0027065,30.0027065,10706.9052734375,10716.3193359375,56.6008475915829,20.6497554501301,15.695635,0,0,0,40,4449,29.9297,10711.6123046875,,,,,,,,,,,,,0,,,,0.00245,,,,,,30.0027065,,,,
,32696768.38,30.0028076,9552.77294921875,0.0030357186886975,9.07585933891231E-7,1,0.999253354069792,40.0298881530762,1.99412976272412,28.0200000852346,0.033964812732718,0.00681314078420536,0.25,6.392777134692E-5,0.00302146101768692,8.18208462173736E-5,30.0028076,30.0028076,9542.544921875,9563.0009765625,56.5101786833521,20.6394538151958,16.454937,0,0,0,40,4449,29.9315,9552.77294921875,,,,,,,,,,,,,0,,,,0.0049,,,,,,30.0028076,,,,
,32696790.49,30.0035114,8448.01904296875,0.00301307633720772,7.7663150146192E-7,1,0.999253354069792,40.0298881530762,1.99410391276648,28.0200000852346,0.0337075333510812,0.00676493340827005,0.25,6.39411284518041E-5,0.00299866139073578,8.14945264579286E-5,30.0032825,30.0037403,8437.896484375,8458.1416015625,56.3085185253906,20.6512286028995,15.315984,0,0,0,40,4449,29.9274,8448.01904296875,,,,,,,,,,,,,0,,,,-0.00245,,,,,,30.0035114,,,,
,32696813.25,30.0037117,7310.90161132813,0.00298371323642269,1.45124704374246E-6,1,0.999253354069792,40.0298881530762,1.99421868529727,28.0200000852346,0.0333856571711718,0.00665589466724663,0.25,5.96977022640096E-5,0.0029692043474269,7.68910310607815E-5,30.0037117,30.0037117,7303.42333984375,7318.3798828125,56.4546830584867,20.6464007083289,16.075285,0,0,0,40,4449,29.9292,7310.90161132813,,,,,,,,,,,,,0,,,,0,,,,,,30.0037117,,,,
,32696836.36,30.00387,6156.27172851562,0.00294654109638642,8.42864047434733E-7,1,0.999253354069792,40.0298881530762,1.994253546381,28.0200000852346,0.0329654913491843,0.00658361558604485,0.25,6.01421853135584E-5,0.00293195777269292,7.69096749054248E-5,30.00387,30.00387,6148.84423828125,6163.69921875,56.1607907352559,20.6461642255628,16.075285,0,0,0,40,4449,29.9282,6156.27172851562,,,,,,,,,,,,,0,,,,-0.0049,,,,,,30.00387,,,,
,32696858.385,30.0007458,5054.6455078125,0.00289851909465456,9.42150479141633E-7,1,0.999253354069792,40.0298881530762,1.99428898574082,28.0200000852346,0.0324207023019776,0.00650702693117335,0.25,6.21179795433858E-5,0.00288393315350014,7.84068602171643E-5,30.0007458,30.0007458,5044.876953125,5064.4140625,56.6391473890252,20.6530420419479,16.075285,0,0,0,40,4449,29.92725,5054.6455078125,,,,,,,,,,,,,0,,,,0,,,,,,30.0007458,,,,
,32696881.515,30.0027828,3899.37048339844,0.00282652265301585,1.18306827294963E-6,1,0.999253354069792,40.0298881530762,1.99453889720418,28.0200000852346,0.0316202687313063,0.00632588908153456,0.25,5.89990933401119E-5,0.0028120914844385,7.47008382660241E-5,30.0027828,30.0027828,3889.13427734375,3909.60668945313,56.4421770021791,20.6508154598397,16.075285,0,0,0,40,4449,29.9283,3899.37048339844,,,,,,,,,,,,,0,,,,-0.00245,,,,,,30.0027828,,,,
,32696904.55,30.0018291,2747.06872558594,0.00268705951062434,1.24173448407807E-6,1,0.999253354069792,40.0298881530762,1.99410107008337,28.0200000852346,0.0300552110611516,0.00599195615931091,0.25,5.4465816039639E-5,0.00267315701950854,6.92272945630828E-5,30.0018291,30.0018291,2739.65942382813,2754.47802734375,56.4906379703714,20.6621293281099,15.695635,0,0,0,40,4449,29.92855,2747.06872558594,,,,,,,,,,,,,0,,,,-0.0049,,,,,,30.0018291,,,,
,32696926.89,30.0007915,1630.20379638672,0.00240538875548542,1.10215644364475E-6,1,0.999253354069792,40.0298881530762,1.9940180634899,28.0200000852346,0.0269009662932685,0.00536840149644356,0.25,4.93498841271156E-5,0.00239278720048752,6.2419442631915E-5,30.0007915,30.0007915,1625.21350097656,1635.19409179687,56.7681160946983,20.6664242444518,15.695635,0,0,0,40,4449,29.9271,1630.20379638672,,,,,,,,,,,,,0,,,,0,,,,,,30.0007915,,,,
,32696949.51,29.9999638,497.901062011719,0.00152544014175537,3.51833835595439E-6,1,0.999253354069792,40.0298881530762,1.99382146037325,28.0200000852346,0.017062812350011,0.00337366846985345,0.25,2.86704470131123E-5,0.00151737971098439,3.68937890613609E-5,29.9999638,29.9999638,485.246276855469,510.555847167969,57.1440794124484,20.6646469095905,16.075285,0,0,0,40,4449,29.9316,497.901062011719,,,,,,,,,,,,,0,,,,0,,,,,,29.9999638,,,,
,32696961.04,29.99967,-0.266416028141975,0.000229415066864578,1.23550811734321E-6,1,0.999253354069792,40.0298881530762,1.99424999948149,28.0200000852346,0.00257327230613282,0.000470052385760852,0.25,9.82294040714957E-7,0.000228216964833942,2.23243120873402E-6,29.99967,29.99967,-0.289251685142517,-0.243580371141434,57.1948852661984,20.6686602306668,16.075285,0,0,0,40,4417,29.9281,-0.266416028141975,,,,,,,,,,,,,0,,,,0,,,,,,29.99967,,,,