File: data/monolayers/magneticStructure/ML_Ac_CoFe_C-2/VSM/data/DD175_23_HYST_10K_100OE.DAT
[Header]
; VSM Data File (default extension .dat)
; Copyright (c) 2003, Quantum Design, Inc. All rights reserved.
TITLE,
FILEOPENTIME,46636692.25,04/06/2017,4:54 am
BYAPP,VSM,1.0,1.0
INFO,PPMS VSM Option Release 1.3.7 Build 2,APPNAME
INFO,291,COIL_SERIAL_NUMBER
INFO,0,MOMENT_UNITS
INFO,CoFe2O4,SAMPLE_MATERIAL
INFO,,SAMPLE_COMMENT
INFO,,SAMPLE_MASS
INFO,,SAMPLE_VOLUME
INFO,,SAMPLE_MOLECULAR_WEIGHT
INFO,,SAMPLE_SIZE
INFO,,SAMPLE_SHAPE
INFO,36.62,SAMPLE_OFFSET
DATATYPE,COMMENT,1
DATATYPE,TIME,2
STARTUPAXIS,X,2
STARTUPAXIS,Y1,5
[Data]
Comment,Time Stamp (sec),Temperature (K),Magnetic Field (Oe),Moment (emu),M. Std. Err. (emu),Transport Action,Averaging Time (sec),Frequency (Hz),Peak Amplitude (mm),Center Position (mm),Coil Signal' (mV),Coil Signal" (mV),Range (mV),M. Quad. Signal (emu),M. Raw' (emu),M. Raw" (emu),Min. Temperature (K),Max. Temperature (K),Min. Field (Oe),Max. Field (Oe),Mass (grams),Motor Lag (deg),Pressure (Torr),VSM Status (code),Motor Status (code),Measure Status (code),PPMS Status (code),System Temp. (K),System Field (Oe),Sample Position (deg),Bridge 1 Resistance (ohms),Bridge 1 Excitation (에),Bridge 2 Resistance (ohms),Bridge 2 Excitation (에),Bridge 3 Resistance (ohms),Bridge 3 Excitation (에),Bridge 4 Resistance (ohms),Bridge 4 Excitation (에),Signal 1 Vin (V),Signal 2 Vin (V),Digital Inputs (code),Drive 1 Iout (mA),Drive 1 Ipower (W),Drive 2 Iout (mA),Drive 2 Ipower (W),Pressure (),Map 20 (),Map 21 (),Map 22 (),Map 23 (),Map 24 (),Map 25 (),Map 26 (),Map 27 (),Map 28 (),Map 29 ()
,46637433.255,10.0250006,0.504272609949112,1.33773634772242E-5,1.98863442645568E-7,1,0.999253354069792,40.0298881530762,1.99517526463773,16.1200007982552,0.000148753533555434,-2.20189340808672E-6,0.25,-2.56039441884211E-6,1.33036507582191E-5,-2.51565770052601E-6,10.0250006,10.0250006,0.473710656166077,0.534834563732147,52.0791266078324,18.6988912366038,2.9022818,0,0,0,4417,9.9954,0.504272609949112,,,,,,,,,,,,,,,,,13.003003,,,,,,10.0250006,,,,
,46637498.245,10.0077982,2553.93884277344,2.00692999088753E-5,2.63713553562087E-7,1,0.999253354069792,40.0298881530762,1.99533144245917,16.1200007982552,0.000220199974437265,1.36854584265284E-5,0.25,-2.26370008972772E-6,1.99560076559925E-5,-2.20440316949689E-6,10.0077868,10.0078096,2529.21362304687,2578.6640625,52.4269512988902,18.7135025494574,2.9024266,0,0,0,4449,9.9909,2553.93884277344,,,,,,,,,,,,,,,,,13.753754,,,,,,10.0077982,,,,
,46637550.47,10.0070157,5158.10791015625,1.79485358697235E-5,2.48659930780409E-7,1,0.999253354069792,40.0298881530762,1.99537872556078,16.1200007982552,0.000197518580638937,8.99164741122258E-6,0.25,-2.3283604397446E-6,1.78488903050069E-5,-2.27174290200567E-6,10.0070057,10.0070257,5138.15185546875,5178.06396484375,52.1869913434863,18.7172114989817,2.8881456,0,0,0,4449,9.9894,5158.10791015625,,,,,,,,,,,,,,,,,13.753754,,,,,,10.0070157,,,,
,46637602.195,10.00583695,7743.2294921875,1.55179932202397E-5,3.77968935557387E-7,1,0.999253354069792,40.0298881530762,1.99536990242941,16.1200007982552,0.000171982024327294,9.66913168471128E-7,0.25,-2.64761548781652E-6,1.54343946634953E-5,-2.59328922745329E-6,10.0057373,10.0059366,7715.7421875,7770.716796875,52.2260727694478,18.7224259083858,2.9314206,0,0,0,4449,9.98825,7743.2294921875,,,,,,,,,,,,,,,,,13.753754,,,,,,10.00583695,,,,
,46637655.47,10.00491855,10407.48046875,1.31019114432295E-5,4.11985203706242E-7,1,0.999253354069792,40.0298881530762,1.99545380553026,16.1200007982552,0.000144879406655273,2.75733856047464E-6,0.25,-2.05670444225505E-6,1.30318489853992E-5,-2.01034855588009E-6,10.0048618,10.0049753,10379.9423828125,10435.0185546875,52.4660327248517,18.7197553931305,2.9314206,0,0,0,4449,9.987,10407.48046875,,,,,,,,,,,,,,,,,14.129129,,,,,,10.00491855,,,,
,46637707.525,10.0040627,13008.328125,9.98505927675194E-6,3.70633807105669E-7,1,0.999253354069792,40.0298881530762,1.99531278739636,16.1200007982552,0.000112015342683242,-6.95719313010042E-6,0.25,-2.41065750610258E-6,9.93477203428108E-6,-2.36934671192136E-6,10.0040627,10.0040627,12993.5146484375,13023.1416015625,52.7966615884864,18.7214366152543,2.91714215,0,0,0,4449,9.9843,13008.328125,,,,,,,,,,,,,,,,,13.753754,,,,,,10.0040627,,,,
,46637760.955,10.0031161,15677.3891601562,8.44457260457025E-6,4.84148056075995E-7,1,0.999253354069792,40.0298881530762,1.99525174613136,16.1200007982552,9.50150243325333E-5,-7.43828044440744E-6,0.25,-2.18437313505748E-6,8.40328519038169E-6,-2.14762099481987E-6,10.002984,10.0032482,15647.25390625,15707.5244140625,52.115081519717,18.7241885145659,2.94613615,0,0,0,4449,9.98435,15677.3891601562,,,,,,,,,,,,,,,,,13.003003,,,,,,10.0031161,,,,
,46637813.99,10.0017767,18328.541015625,7.49377836638334E-6,4.1045108874028E-7,1,0.999253354069792,40.0298881530762,1.99542125885926,16.1200007982552,8.83922825876956E-5,-2.95445897339161E-5,0.25,-4.07154562057332E-6,7.46438185746399E-6,-4.02617889514737E-6,10.001647,10.0019064,18300.99609375,18356.0859375,52.5910932879286,18.7268830317902,2.9608517,0,0,0,4449,9.98345,18328.541015625,,,,,,,,,,,,,,,,,13.753754,,,,,,10.0017767,,,,
,46637866.93,10.00163745,20974.087890625,7.59677766806561E-6,4.55922336022819E-7,1,0.999253354069792,40.0298881530762,1.99521947171498,16.1200007982552,8.52108915862416E-5,-5.0992316259113E-6,0.25,-1.81917377521777E-6,7.56079719598315E-6,-1.78513990359536E-6,10.0015831,10.0016918,20949.1796875,20998.99609375,52.8083860162748,18.7250159306339,2.9608517,0,0,0,4449,9.983,20974.087890625,,,,,,,,,,,,,,,,,13.378378,,,,,,10.00163745,,,,
,46637919.185,10.00078015,23585.296875,6.94505432532315E-6,3.44411879029692E-7,1,0.999253354069792,40.0298881530762,1.99525917269975,16.1200007982552,8.13809130550032E-5,-2.42424380795982E-5,0.25,-3.48360697010094E-6,6.91893211818499E-6,-3.44182612314573E-6,10.0007153,10.000845,23562.755859375,23607.837890625,51.914984618794,18.7240818915419,2.91714215,0,0,0,4449,9.98315,23585.296875,,,,,,,,,,,,,,,,,13.003003,,,,,,10.00078015,,,,
,46637970.135,10.0085082,26131.318359375,7.08385089793192E-6,6.48488582016548E-7,1,0.999253354069792,40.0298881530762,1.99512588469909,16.1200007982552,7.87053099245167E-5,-4.34030880411848E-7,0.25,-1.29673930650361E-6,7.05050156363423E-6,-1.26551693365342E-6,10.0083132,10.0087032,26106.361328125,26156.275390625,52.2714072235632,18.727345759957,2.93156675,0,0,0,4449,9.97745,26131.318359375,,,,,,,,,,,,,,,,,13.003003,,,,,,10.0085082,,,,
,46638022.97,10.0075593,28772.6064453125,4.59527338320911E-6,5.19561963579325E-7,1,0.999253354069792,40.0298881530762,1.99495644947445,16.1200007982552,5.35064339090338E-5,-1.40774564533249E-5,0.25,-2.12386961180425E-6,4.57873284209665E-6,-2.0963323038428E-6,10.0075083,10.0076103,28744.779296875,28800.43359375,52.5832770027363,18.7348720287309,2.9608517,0,0,0,4449,9.9717,28772.6064453125,,,,,,,,,,,,,,,,,13.753754,,,,,,10.0075593,,,,
,46638075.24,10.01163815,31386.5615234375,3.34066673247302E-6,7.29045661955851E-7,1,0.999253354069792,40.0298881530762,1.99490673181157,16.1200007982552,3.96375959761419E-5,-1.43698725563014E-5,0.25,-1.92875012122904E-6,3.33057741761414E-6,-1.90644026117836E-6,10.0114641,10.0118122,31364.080078125,31409.04296875,52.7466373632556,18.7367591053436,2.9464301,0,0,0,4449,9.96215,31386.5615234375,,,,,,,,,,,,,,,,,13.003003,,,,,,10.01163815,,,,
,46638127.91,10.0132313,34017.771484375,-1.75818191409082E-6,5.74246139237956E-7,1,0.999253354069792,40.0298881530762,1.99482501346847,16.1200007982552,-1.97444738884996E-5,1.26675438084484E-6,0.25,4.30277071082213E-7,-1.75093386458202E-6,4.21357632711305E-7,10.0128193,10.0136433,33987.73828125,34047.8046875,53.5798533647557,18.7380469656594,2.9022818,0,0,0,4449,9.9603,34017.771484375,,,,,,,,,,,,,,,,,13.753754,,,,,,10.0132313,,,,
,46638179.995,10.0085039,36620.9609375,-3.70449243189067E-6,8.84016664072209E-7,1,0.999253354069792,40.0298881530762,1.99481470550895,16.1200007982552,-3.78266248226325E-5,-1.85784750998332E-5,0.25,-1.06712275557378E-6,-3.68187976064712E-6,-1.07651702318455E-6,10.0084734,10.0085344,36596.01171875,36645.91015625,52.6747275394863,18.7337309870445,2.9022818,0,0,0,4449,9.9581,36620.9609375,,,,,,,,,,,,,,,,,12.627627,,,,,,10.0085039,,,,
,46638231.895,10.00439265,39217.263671875,-9.26055682407032E-6,7.30278581485433E-7,1,0.999253354069792,40.0298881530762,1.99479651911114,16.1200007982552,-9.85035964241901E-5,-2.43253428966157E-5,0.25,-6.11190735278691E-7,-9.21305495354451E-6,-6.46131007249724E-7,10.0039282,10.0048571,39189.80859375,39244.71875,52.8177655585056,18.7344721667041,2.9168512,0,0,0,4449,9.9581,39217.263671875,,,,,,,,,,,,,,,,,13.753754,,,,,,10.00439265,,,,
,46638283.98,10.00072005,41818.884765625,-1.37174021408035E-5,6.63869088067021E-7,1,0.999253354069792,40.0298881530762,1.99470923502901,16.1200007982552,-0.000143674756090088,-4.86303434908735E-5,0.25,-2.07378889670734E-6,-1.36434538431531E-5,-2.12182466589273E-6,10.0007086,10.0007315,41798.81640625,41838.953125,53.0077012886787,18.737591362942,2.9022818,0,0,0,4449,9.959,41818.884765625,,,,,,,,,,,,,,,,,13.003003,,,,,,10.00072005,,,,
,46638335.77,10.0053453,44407.234375,-1.83786761168498E-5,6.70308746282797E-7,1,0.999253354069792,40.0298881530762,1.99489032695694,16.1200007982552,-0.000194725630162281,-5.28566110616426E-5,0.25,-1.63268654647191E-6,-1.82862448865415E-5,-1.70494066688302E-6,10.0053453,10.0053453,44387.34375,44427.125,53.1226006810056,18.7341440904584,2.93156675,0,0,0,4449,9.95795,44407.234375,,,,,,,,,,,,,,,,,13.003003,,,,,,10.0053453,,,,
,46638387.29,10.00111105,46981.771484375,-2.25478595303775E-5,9.44167775063207E-7,1,0.999253354069792,40.0298881530762,1.99471231876505,16.1200007982552,-0.00023989765904293,-5.92756330217792E-5,0.25,-1.48270056739638E-6,-2.24390715120746E-5,-1.57664062776807E-6,10.0010357,10.0011864,46956.765625,47006.77734375,52.4324226985248,18.736626638898,2.9608517,0,0,0,4449,9.9552,46981.771484375,,,,,,,,,,,,,,,,,13.003003,,,,,,10.00111105,,,,
,46638439.735,9.99918745,49603.26171875,-3.00922652375885E-5,6.13066616812486E-7,1,0.999253354069792,40.0298881530762,1.99477787444971,16.1200007982552,-0.000323334713848426,-6.16290180538911E-5,0.25,-3.50702168924754E-7,-2.99578365809725E-5,-4.87091972086564E-7,9.9982071,10.0001678,49580.7109375,49625.8125,52.9279751797171,18.737135922357,2.9022818,0,0,0,4449,9.95845,49603.26171875,,,,,,,,,,,,,,,,,13.378378,,,,,,9.99918745,,,,
,46638490.965,9.9896717,52164.166015625,-3.5693531280865E-5,7.81698238370791E-7,1,0.999253354069792,40.0298881530762,1.99481311754918,16.1200007982552,-0.000380382426758521,-9.0953355786439E-5,0.25,-2.06890565365981E-6,-3.5530467212411E-5,-2.22769375207498E-6,9.9892778,9.9900656,52139.08984375,52189.2421875,52.392559644044,18.7358778176507,2.9608517,0,0,0,4449,9.96995,52164.166015625,,,,,,,,,,,,,,,,,13.003003,,,,,,9.9896717,,,,
,46638542.515,9.9927759,54739.87109375,-4.08886968297965E-5,9.34310038191631E-7,1,0.999253354069792,40.0298881530762,1.99495695871559,16.1200007982552,-0.000440633029470587,-7.7328104373327E-5,0.25,1.30531608765232E-7,-4.07186092836201E-5,-6.66473756908393E-8,9.9924917,9.9930601,54717.35546875,54762.38671875,53.3414566663903,18.7345633847955,2.9022818,0,0,0,4449,9.9718,54739.87109375,,,,,,,,,,,,,,,,,13.753754,,,,,,9.9927759,,,,
,46638594.525,9.9957037,57341.33984375,-4.51731892337269E-5,8.77932746385031E-7,1,0.999253354069792,40.0298881530762,1.99486911036106,16.1200007982552,-0.000484135068651178,-0.000100589856651459,0.25,-1.25759353684167E-6,-4.4984040021792E-5,-1.47466529997326E-6,9.9954329,9.9959745,57316.69921875,57365.98046875,53.3985155482941,18.7368671162395,2.9608517,0,0,0,4449,9.9695,57341.33984375,,,,,,,,,,,,,,,,,13.003003,,,,,,9.9957037,,,,
,46638646.435,9.99978015,59952.568359375,-5.08395615899814E-5,8.04048632843738E-7,1,0.999253354069792,40.0298881530762,1.99466177822041,16.1200007982552,-0.000542626224615452,-0.000125792715820254,0.25,-2.57809610376215E-6,-5.06271876929171E-5,-2.82340212332387E-6,9.999711,9.9998493,59910.55859375,59994.578125,53.0092645457172,18.7411833490781,2.9608517,0,0,0,4433,9.971,59952.568359375,,,,,,,,,,,,,,,,,13.003003,,,,,,9.99978015,,,,
,46638715.48,9.9928384,57463.791015625,-4.51728757252069E-5,6.62176727892882E-7,1,0.999253354069792,40.0298881530762,1.99477885910746,16.1200007982552,-0.00048447849420088,-9.85474732868094E-5,0.25,-1.06813884203341E-6,-4.49849225179828E-5,-1.28621079610347E-6,9.9927626,9.9929142,57436.26953125,57491.3125,52.3104886495248,18.7364411637808,2.9608517,0,0,0,4449,9.97915,57463.791015625,,,,,,,,,,,,,,,,,12.627627,,,,,,9.9928384,,,,
,46638767.86,9.99659345,54845.369140625,-4.10695210628576E-5,6.92508678937064E-7,1,0.999253354069792,40.0298881530762,1.99503352940712,16.1200007982552,-0.000438993798989022,-9.7842828490809E-5,0.25,-1.74133978700914E-6,-4.08898745736252E-5,-1.93176619924564E-6,9.9964876,9.9966993,54822.8984375,54867.83984375,53.1210374239672,18.7389149695826,2.93156675,0,0,0,4449,9.9793,54845.369140625,,,,,,,,,,,,,,,,,13.753754,,,,,,9.99659345,,,,
,46638819.455,10.0012207,52269.0234375,-3.50593642379116E-5,7.23344614216765E-7,1,0.999253354069792,40.0298881530762,1.99471705336631,16.1200007982552,-0.000375041229939113,-8.13176087875576E-5,0.25,-1.28754364168002E-6,-3.4902859676377E-5,-1.44687685835236E-6,10.0011024,10.001339,52249.25,52288.796875,52.6129788864671,18.7410351787844,2.93156675,0,0,0,4449,9.97765,52269.0234375,,,,,,,,,,,,,,,,,13.003003,,,,,,10.0012207,,,,
,46638871.445,10.00307515,49670.560546875,-3.10131001619784E-5,7.41987988234142E-7,1,0.999253354069792,40.0298881530762,1.99482201967652,16.1200007982552,-0.000331167584927374,-7.51052311194639E-5,0.25,-1.43762422740514E-6,-3.08697150810851E-5,-1.57353589563126E-6,10.0030642,10.0030861,49640.5625,49700.55859375,53.0327134012941,18.7417261190453,2.9608517,0,0,0,4449,9.97345,49670.560546875,,,,,,,,,,,,,,,,,12.627627,,,,,,10.00307515,,,,
,46638924.3,10.00160315,47026.837890625,-2.45226985404593E-5,5.28597533377307E-7,1,0.999253354069792,40.0298881530762,1.99470962593014,16.1200007982552,-0.000260429617029345,-6.71544281436323E-5,0.25,-1.86211010983626E-6,-2.44033133070099E-5,-1.96320184398596E-6,10.0013905,10.0018158,47006.890625,47046.78515625,53.2117063321979,18.743955080246,2.9608517,0,0,0,4449,9.9707,47026.837890625,,,,,,,,,,,,,,,,,13.003003,,,,,,10.00160315,,,,
,46638975.405,9.99920275,44474.630859375,-1.92518438909305E-5,6.43167831911365E-7,1,0.999253354069792,40.0298881530762,1.99469991396754,16.1200007982552,-0.000202594828580857,-6.30146837030586E-5,0.25,-2.42100220046907E-6,-1.91519820398108E-5,-2.49345715823373E-6,9.9991703,9.9992352,44447.17578125,44502.0859375,53.6705222729865,18.7399890854328,2.93156675,0,0,0,4449,9.97415,44474.630859375,,,,,,,,,,,,,,,,,13.753754,,,,,,9.99920275,,,,
,46639027.61,10.0011225,41864.037109375,-1.45061577217154E-5,9.18449072431514E-7,1,0.999253354069792,40.0298881530762,1.99493728150786,16.1200007982552,-0.000150601832506628,-5.9013793788487E-5,0.25,-2.89727764200636E-6,-1.44250061699428E-5,-2.94476536331273E-6,10.0011063,10.0011387,41838.87890625,41889.1953125,52.5707709464286,18.7400063837209,2.9608517,0,0,0,4449,9.9738,41864.037109375,,,,,,,,,,,,,,,,,13.753754,,,,,,10.0011225,,,,
,46639080.105,10.0024939,39242.3828125,-9.11083093108381E-6,6.21342560909232E-7,1,0.999253354069792,40.0298881530762,1.99492353291319,16.1200007982552,-9.44271121183827E-5,-3.79171653433652E-5,0.25,-1.90040720696007E-6,-9.05878580678477E-6,-1.92848301306718E-6,10.0024939,10.0024939,39219.890625,39264.875,52.9467342641787,18.7420927054202,2.9022818,0,0,0,4449,9.9721,39242.3828125,,,,,,,,,,,,,,,,,13.378378,,,,,,10.0024939,,,,
,46639132.04,10.0040989,36646.14453125,-5.19082303380729E-6,8.32414897573114E-7,1,0.999253354069792,40.0298881530762,1.99467923993064,16.1200007982552,-5.10352476109505E-5,-3.70752630776448E-5,0.25,-2.52151047529E-6,-5.15507029536487E-6,-2.52959089353826E-6,10.0038662,10.0043316,36621.2421875,36671.046875,53.0671050561402,18.7404129319103,2.93156675,0,0,0,4449,9.9699,36646.14453125,,,,,,,,,,,,,,,,,13.003003,,,,,,10.0040989,,,,
,46639185.485,10.00542305,33972.66796875,-1.25856309217817E-6,9.32307181049541E-7,1,0.999253354069792,40.0298881530762,1.99474899482074,16.1200007982552,-1.1741867899198E-5,-1.25444693453826E-5,0.25,-9.4194416329867E-7,-1.24858174283703E-6,-9.41998677311011E-7,10.0053072,10.0055389,33947.6953125,33997.640625,53.729926040448,18.7417037828329,2.9022818,0,0,0,4449,9.9657,33972.66796875,,,,,,,,,,,,,,,,,13.753754,,,,,,10.00542305,,,,
,46639237.08,10.00551125,31396.5966796875,4.39622276510102E-6,4.04321119313247E-7,1,0.999253354069792,40.0298881530762,1.99488221750264,16.1200007982552,5.02649963936994E-5,-8.23480594614642E-6,0.25,-1.54617533085251E-6,4.37927659400051E-6,-1.52193016256754E-6,10.0053558,10.0056667,31369.103515625,31424.08984375,53.4391602312941,18.7439126459952,2.93156675,0,0,0,4449,9.9644,31396.5966796875,,,,,,,,,,,,,,,,,13.003003,,,,,,10.00551125,,,,
,46639289.25,10.00446415,28787.755859375,8.7396494317713E-6,5.16311845253594E-7,1,0.999253354069792,40.0298881530762,1.99474703895898,16.1200007982552,9.69595042983608E-5,2.32548456929095E-7,0.25,-1.52970766480336E-6,8.69924534470445E-6,-1.49049976122974E-6,10.0042439,10.0046844,28760.2421875,28815.26953125,53.425090917948,18.7475371674969,2.9608517,0,0,0,4449,9.96155,28787.755859375,,,,,,,,,,,,,,,,,13.753754,,,,,,10.00446415,,,,
,46639341.76,10.00288535,26161.3359375,1.3640334976351E-5,5.37259240748306E-7,1,0.999253354069792,40.0298881530762,1.99468344398039,16.1200007982552,0.00014927450769675,1.18237241428274E-5,0.25,-1.32032792007765E-6,1.35720977467557E-5,-1.26646591269126E-6,10.0027819,10.0029888,26131.306640625,26191.365234375,52.842777671121,18.7440511778251,2.93156675,0,0,0,4449,9.96205,26161.3359375,,,,,,,,,,,,,,,,,13.753754,,,,,,10.00288535,,,,
,46639393.855,10.00293065,23560.44140625,1.84022276128588E-5,4.85033013252136E-7,1,0.999253354069792,40.0298881530762,1.99461806199574,16.1200007982552,0.000200238584663384,2.22841071797899E-5,0.25,-1.18991446025883E-6,1.83064688299905E-5,-1.12277971384895E-6,10.0027952,10.0030661,23537.84375,23583.0390625,52.9561138064094,18.7453791719751,2.9464301,0,0,0,4449,9.9603,23560.44140625,,,,,,,,,,,,,,,,,13.003003,,,,,,10.00293065,,,,
,46639445.5,10.00026655,20978.7451171875,2.2274957055362E-5,5.17037505762006E-7,1,0.999253354069792,40.0298881530762,1.99490204385449,16.1200007982552,0.000243406064200133,2.12382180320692E-5,0.25,-1.97056238142944E-6,2.21588165267601E-5,-1.88924406773785E-6,10.0000172,10.0005159,20953.90234375,21003.587890625,53.2875242985633,18.7433958231461,2.9608517,0,0,0,4449,9.9594,20978.7451171875,,,,,,,,,,,,,,,,,13.003003,,,,,,10.00026655,,,,
,46639497.955,10.00055835,18357.529296875,2.73304306323631E-5,5.26062594912828E-7,1,0.999253354069792,40.0298881530762,1.99484890129216,16.1200007982552,0.000297502856143644,3.23444285291427E-5,0.25,-1.82949138059426E-6,2.7183812401956E-5,-1.73649370938372E-6,10.0003185,10.0007982,18335.033203125,18380.025390625,52.6512786839094,18.7417425573098,2.94613615,0,0,0,4449,9.96155,18357.529296875,,,,,,,,,,,,,,,,,13.003003,,,,,,10.00055835,,,,
,46639550.79,10.00082255,15716.3637695313,3.23677335563947E-5,4.86378554233609E-7,1,0.999253354069792,40.0298881530762,1.99492818793588,16.1200007982552,0.000351481839592685,4.30519922173285E-5,0.25,-1.7209802455923E-6,3.21902671295815E-5,-1.61754917229424E-6,10.0007925,10.0008526,15686.375,15746.3525390625,52.6708193968902,18.7477924525852,2.9464301,0,0,0,4449,9.9647,15716.3637695313,,,,,,,,,,,,,,,,,13.003003,,,,,,10.00082255,,,,
,46639602.655,9.9972315,13122.4086914062,3.58722749999965E-5,3.79727829280297E-7,1,0.999253354069792,40.0298881530762,1.99475441335845,16.1200007982552,0.000391157329839828,3.82015082079567E-5,0.25,-2.78623423278384E-6,3.56755092824856E-5,-2.67112571458089E-6,9.997097,9.997366,13097.337890625,13147.4794921875,52.9826891760633,18.7464672846082,2.9905784,0,0,0,4449,9.9641,13122.4086914062,,,,,,,,,,,,,,,,,13.753754,,,,,,9.9972315,,,,
,46639654.445,9.9978943,10536.3564453125,3.94819444673154E-5,3.27764136356758E-7,1,0.999253354069792,40.0298881530762,1.99489890536061,16.1200007982552,0.000429404631283054,4.83498461991904E-5,0.25,-2.47549640582167E-6,3.92611361147646E-5,-2.35701179574648E-6,9.9976816,9.998107,10503.9228515625,10568.7900390625,53.0952436828325,18.7466461077688,2.9609995,0,0,0,4449,9.96535,10536.3564453125,,,,,,,,,,,,,,,,,13.003003,,,,,,9.9978943,,,,
,46639705.93,9.9970422,7962.17041015625,4.38199817088421E-5,3.33466428435877E-7,1,0.999253354069792,40.0298881530762,1.99489965453891,16.1200007982552,0.000475781812193694,5.80478623695913E-5,0.25,-2.33411270773172E-6,4.35712244074814E-5,-2.21017813358455E-6,9.9969616,9.9971228,7939.7265625,7984.6142578125,52.524654863794,18.7473167387751,2.9314206,0,0,0,4449,9.96755,7962.17041015625,,,,,,,,,,,,,,,,,13.003003,,,,,,9.9970422,,,,
,46639758.765,9.996799,5320.7421875,4.73113667587654E-5,3.22360513806811E-7,1,0.999253354069792,40.0298881530762,1.99486680628986,16.1200007982552,0.000513143556748774,6.55615236360188E-5,0.25,-2.24549420982159E-6,4.70395374498035E-5,-2.11874569741146E-6,9.9967499,9.9968481,5295.85107421875,5345.63330078125,52.5832770027363,18.7454530685839,2.9609995,0,0,0,4449,9.9665,5320.7421875,,,,,,,,,,,,,,,,,13.753754,,,,,,9.996799,,,,
,46639811.13,9.9962816,2701.28051757813,5.04691403002988E-5,2.91348192164376E-7,1,0.999253354069792,40.0298881530762,1.99502920160459,16.1200007982552,0.000546871147865557,7.29936588641864E-5,0.25,-2.10601407465533E-6,5.01761493694462E-5,-1.9777941295553E-6,9.9961109,9.9964523,2676.2626953125,2726.29833984375,53.6392571322172,18.7445156569945,2.9609995,0,0,0,4449,9.96855,2701.28051757813,,,,,,,,,,,,,,,,,14.129129,,,,,,9.9962816,,,,
,46639863.76,9.9972825,72.0114116668701,4.50647921560306E-5,3.13852456186603E-7,1,0.999253354069792,40.0298881530762,1.99497804348799,16.1200007982552,0.000488980218937916,6.12078399611099E-5,0.25,-2.24534138682245E-6,4.4802404852874E-5,-2.13243847723036E-6,9.9968309,9.9977341,42.0331230163574,101.989700317383,52.8904570107941,18.7427961763044,2.9314206,0,0,0,4449,9.9707,72.0114116668701,,,,,,,,,,,,,,,,,13.378378,,,,,,9.9972825,,,,
,46639916.53,9.99654245,-2561.97912597656,3.50896690023887E-5,3.39384695014644E-7,1,0.999253354069792,40.0298881530762,1.99502694601887,16.1200007982552,0.00038198931818486,4.07172817916694E-5,0.25,-2.39677278899306E-6,3.48880181899367E-5,-2.30230201170127E-6,9.9965334,9.9965515,-2581.88891601562,-2542.0693359375,52.8849856111594,18.7440477584818,2.9314206,0,0,0,4449,9.9757,-2561.97912597656,,,,,,,,,,,,,,,,,13.003003,,,,,,9.99654245,,,,
,46639969.585,9.99609805,-5217.19140625,3.69244720264813E-5,2.4816902607501E-7,1,0.999253354069792,40.0298881530762,1.99502867817512,16.1200007982552,0.000401621720915653,4.49004291959257E-5,0.25,-2.33534896341598E-6,3.67136444403346E-5,-2.23317196707812E-6,9.9959164,9.9962797,-5242.2255859375,-5192.1572265625,53.1226006810056,18.7437362269272,2.97571505,0,0,0,4449,9.9763,-5217.19140625,,,,,,,,,,,,,,,,,13.753754,,,,,,9.99609805,,,,
,46640021.82,9.99550535,-7826.05932617187,3.96628465546393E-5,3.55783941545538E-7,1,0.999253354069792,40.0298881530762,1.99507028659998,16.1200007982552,0.000431433576428602,4.82650607593791E-5,0.25,-2.5102910493421E-6,3.9438569433758E-5,-2.39604490821709E-6,9.9953518,9.9956589,-7850.9248046875,-7801.19384765625,52.9053079526594,18.7442851771159,3.00559105,0,0,0,4449,9.97835,-7826.05932617187,,,,,,,,,,,,,,,,,12.627627,,,,,,9.99550535,,,,
,46640074.525,9.9962268,-10460.3325195312,4.2840477653629E-5,3.23473120161074E-7,1,0.999253354069792,40.0298881530762,1.99494535803377,16.1200007982552,0.000463814756058374,6.45095283087842E-5,0.25,-1.56612498703112E-6,4.2597854036489E-5,-1.4441641386068E-6,9.996069,9.9963846,-10485.2783203125,-10435.38671875,52.8490306992748,18.7451972347606,2.9609995,0,0,0,4449,9.9791,-10460.3325195312,,,,,,,,,,,,,,,,,13.378378,,,,,,9.9962268,,,,
,46640127.94,9.99600175,-13131.330078125,4.34210099738543E-5,3.91377985804778E-7,1,0.999253354069792,40.0298881530762,1.99496300483084,16.1200007982552,0.000470259172803602,6.46835565251622E-5,0.25,-1.65856864731228E-6,4.31781069307748E-5,-1.52898835062005E-6,9.9957886,9.9962149,-13158.7744140625,-13103.8857421875,53.0913355402364,18.7469143440847,2.9609995,0,0,0,4449,9.98095,-13131.330078125,,,,,,,,,,,,,,,,,13.753754,,,,,,9.99600175,,,,
,46640181.26,9.99716905,-15795.4482421875,4.22959283300675E-5,3.43011831264551E-7,1,0.999253354069792,40.0298881530762,1.9950008341126,16.1200007982552,0.000459711055735247,5.39860679491379E-5,0.25,-2.46034259984051E-6,4.20647346117452E-5,-2.3238300073913E-6,9.9970713,9.9972668,-15818.046875,-15772.849609375,53.1061864821018,18.7449168573163,2.97601215,0,0,0,4449,9.98095,-15795.4482421875,,,,,,,,,,,,,,,,,13.753754,,,,,,9.99716905,,,,
,46640233.75,9.9976125,-18418.7275390625,3.85178315522434E-5,4.87105642370615E-7,1,0.999253354069792,40.0298881530762,1.99506475064075,16.1200007982552,0.000418150779157074,5.22295561536739E-5,0.25,-1.96128915328427E-6,3.83093974131942E-5,-1.83354226005101E-6,9.9975214,9.9977036,-18446.109375,-18391.345703125,52.9318833223133,18.7446156978441,2.9907277,0,0,0,4449,9.9811,-18418.7275390625,,,,,,,,,,,,,,,,,13.003003,,,,,,9.9976125,,,,
,46640286.37,9.9973817,-21047.0361328125,3.12936186511647E-5,4.44585431741803E-7,1,0.999253354069792,40.0298881530762,1.995098023614,16.1200007982552,0.000340165450464243,4.01345496422127E-5,0.25,-1.81174931375859E-6,3.11274962504941E-5,-1.70265615254312E-6,9.9973707,9.9973927,-21069.56640625,-21024.505859375,52.9451710071402,18.7446403053342,3.0206037,0,0,0,4449,9.98145,-21047.0361328125,,,,,,,,,,,,,,,,,14.129129,,,,,,9.9973817,,,,
,46640338.55,9.99722715,-23656.25390625,2.33875165153768E-5,4.59535760048937E-7,1,0.999253354069792,40.0298881530762,1.99496931648667,16.1200007982552,0.000253728526178852,3.28349155279311E-5,0.25,-1.09331602955445E-6,2.32645087975147E-5,-1.01015086094263E-6,9.9971561,9.9972982,-23683.744140625,-23628.763671875,52.8044778736787,18.7479917134575,3.0206037,0,0,0,4449,9.98345,-23656.25390625,,,,,,,,,,,,,,,,,13.003003,,,,,,9.99722715,,,,
,46640391.315,9.99542995,-26291.875,1.77015179891091E-5,4.72809458021087E-7,1,0.999253354069792,40.0298881530762,1.99495925194026,16.1200007982552,0.000198169432483219,-9.60002040593464E-6,0.25,-4.03189628431195E-6,1.76210243356887E-5,-3.94952690951155E-6,9.9952478,9.9956121,-26316.8515625,-26266.8984375,53.2476612440826,18.7458084192485,3.00559105,0,0,0,4449,9.9864,-26291.875,,,,,,,,,,,,,,,,,13.753754,,,,,,9.99542995,,,,
,46640444.515,9.9966607,-28953.291015625,1.31065202817479E-5,5.16611622892867E-7,1,0.999253354069792,40.0298881530762,1.99513067458538,16.1200007982552,0.000143643078242283,1.04372227998014E-5,0.25,-1.35674135040942E-6,1.30426694959257E-5,-1.30275741437885E-6,9.996623,9.9966984,-28980.697265625,-28925.884765625,53.1890391051402,18.7484470698019,2.9608517,0,0,0,4449,9.98695,-28953.291015625,,,,,,,,,,,,,,,,,12.627627,,,,,,9.9966607,,,,
,46640495.995,9.99588395,-31525.05859375,1.23365458651505E-5,4.6784340456445E-7,1,0.999253354069792,40.0298881530762,1.99509715887699,16.1200007982552,0.000136992819401798,-1.74580504745827E-7,0.25,-2.20779341703476E-6,1.22811754395502E-5,-2.15067539247818E-6,9.995822,9.9959459,-31549.998046875,-31500.119140625,53.2632938144672,18.7477415977286,3.0206037,0,0,0,4449,9.9916,-31525.05859375,,,,,,,,,,,,,,,,,13.003003,,,,,,9.99588395,,,,
,46640549.17,9.99557355,-34183.1875,1.22136853652352E-5,4.83635217412169E-7,1,0.999253354069792,40.0298881530762,1.9950760174466,16.1200007982552,0.000134440683746784,6.59399819468431E-6,0.25,-1.55880490334432E-6,1.21579392472174E-5,-1.50398949908916E-6,9.9955063,9.9956408,-34188.09375,-34178.28125,52.4644694678132,18.7497553550734,2.9907277,0,0,0,4449,9.99295,-34183.1875,,,,,,,,,,,,,,,,,13.003003,,,,,,9.99557355,,,,
,46640599.925,9.9966855,-36718.990234375,1.29423791533697E-5,7.00544822489895E-7,1,0.999253354069792,40.0298881530762,1.99505044824251,16.1200007982552,0.00014188583902688,1.03062441688009E-5,0.25,-1.34521724190143E-6,1.28835506738703E-5,-1.28716465047456E-6,9.9966164,9.9967546,-36746.546875,-36691.43359375,53.7760421230826,18.7469315257726,3.0206037,0,0,0,4449,9.99325,-36718.990234375,,,,,,,,,,,,,,,,,13.003003,,,,,,9.9966855,,,,
,46640652.925,9.99750325,-39367.408203125,1.4759356853393E-5,7.07502277149634E-7,1,0.999253354069792,40.0298881530762,1.99504805319211,16.1200007982552,0.000163339150759545,3.24685607766248E-6,0.25,-2.3263589618429E-6,1.46972667285317E-5,-2.25453898991282E-6,9.9974546,9.9975519,-39394.9375,-39339.87890625,53.3023752404287,18.7521502473312,3.0509303,0,0,0,4449,9.9943,-39367.408203125,,,,,,,,,,,,,,,,,13.003003,,,,,,9.99750325,,,,
,46640706.175,9.99701785,-42028.5390625,2.02809005519822E-5,6.72565144935911E-7,1,0.999253354069792,40.0298881530762,1.99492413752207,16.1200007982552,0.000223887945560623,7.67934425395661E-6,0.25,-2.90046735247333E-6,2.01969568453468E-5,-2.80091019266647E-6,9.9967804,9.9972553,-42058.515625,-41998.5625,53.0538173713133,18.746810526975,2.9907277,0,0,0,4449,9.99655,-42028.5390625,,,,,,,,,,,,,,,,,13.753754,,,,,,9.99701785,,,,
,46640757.97,9.9964819,-44616.755859375,2.36792474864202E-5,5.79932509985722E-7,1,0.999253354069792,40.0298881530762,1.99495434761213,16.1200007982552,0.000258672090414419,2.44943273052135E-5,0.25,-1.94726301759598E-6,2.35779875542938E-5,-1.83514402536162E-6,9.9962969,9.9966669,-44636.81640625,-44596.6953125,52.8662265266979,18.7465865585573,3.0509303,0,0,0,4449,9.9966,-44616.755859375,,,,,,,,,,,,,,,,,13.003003,,,,,,9.9964819,,,,
,46640810.21,9.9950023,-47228.35546875,2.87131593196575E-5,6.19435147767198E-7,1,0.999253354069792,40.0298881530762,1.99496241161872,16.1200007982552,0.000312439130345711,3.67881335297253E-5,0.25,-1.70693586252071E-6,2.85910071900673E-5,-1.57071161669007E-6,9.9946404,9.9953642,-47255.80078125,-47200.91015625,53.3680320360441,18.7502301779954,2.97571505,0,0,0,4449,10.0007,-47228.35546875,,,,,,,,,,,,,,,,,13.003003,,,,,,9.9950023,,,,
,46640862.775,9.99594115,-49857.130859375,3.37296192672666E-5,4.80482234676707E-7,1,0.999253354069792,40.0298881530762,1.99501469659695,16.1200007982552,0.000367975233521728,3.8211741041126E-5,0.25,-2.47446375851782E-6,3.35925035980219E-5,-2.30857457066896E-6,9.9958715,9.9960108,-49879.5390625,-49834.72265625,52.7833739036594,18.7499247241468,2.9905784,0,0,0,4449,10.003,-49857.130859375,,,,,,,,,,,,,,,,,13.753754,,,,,,9.99594115,,,,
,46640915.79,9.9950323,-52505.32421875,3.88050876116297E-5,4.98582425324889E-7,1,0.999253354069792,40.0298881530762,1.9950590726277,16.1200007982552,0.000422139135726088,5.108605753904E-5,0.25,-2.19049266809893E-6,3.86493136449696E-5,-1.99824376585089E-6,9.9948149,9.9952497,-52528.015625,-52482.6328125,52.8459041851979,18.7483749580888,3.0509303,0,0,0,4449,10.0053,-52505.32421875,,,,,,,,,,,,,,,,,13.753754,,,,,,9.9950323,,,,
,46640969.57,9.9942975,-55191.30859375,4.46881647236847E-5,5.83115168586011E-7,1,0.999253354069792,40.0298881530762,1.99493339668541,16.1200007982552,0.000485246822727977,6.40223969102635E-5,0.25,-2.04616017152799E-6,4.45124253753425E-5,-1.82189859356062E-6,9.9941988,9.9943962,-55216.34765625,-55166.26953125,52.8490306992748,18.7489149439578,2.9905784,0,0,0,4449,10.0079,-55191.30859375,,,,,,,,,,,,,,,,,13.753754,,,,,,9.9942975,,,,
,46641022.855,9.9935036,-57857.12890625,4.97934089646556E-5,5.19213201197254E-7,1,0.999253354069792,40.0298881530762,1.9950105453506,16.1200007982552,0.000541557390843593,6.69737182565409E-5,0.25,-2.69159137027132E-6,4.96062732178906E-5,-2.43481292587343E-6,9.9935036,9.9935036,-57879.61328125,-57834.64453125,53.1530841932556,18.7543020537623,3.02075435,0,0,0,4449,10.01145,-57857.12890625,,,,,,,,,,,,,,,,,13.753754,,,,,,9.9935036,,,,
,46641090.54,9.9952297,-59589.1640625,5.41035207912074E-5,6.59194333796034E-7,1,0.999253354069792,40.0298881530762,1.99510340627065,16.1200007982552,0.00058641208391884,8.45174195453088E-5,0.25,-1.83893075882422E-6,5.38995395012369E-5,-1.56065343298613E-6,9.9951601,9.9952993,-59613.8828125,-59564.4453125,52.6794173106017,18.7505494616525,3.03606985,0,0,0,4449,10.0156,-59589.1640625,,,,,,,,,,,,,,,,,13.378378,,,,,,9.9952297,,,,
,46641143.73,9.998282,-56936.376953125,4.73818554911092E-5,6.70422241338565E-7,1,0.999253354069792,40.0298881530762,1.9949394792457,16.1200007982552,0.000513239425030637,7.51747398669927E-5,0.25,-1.49642773493871E-6,4.71963512900513E-5,-1.2581033507246E-6,9.9981461,9.9984179,-56961.4140625,-56911.33984375,53.0483459716787,18.7536897927574,2.9905784,0,0,0,4449,10.0157,-56936.376953125,,,,,,,,,,,,,,,,,13.003003,,,,,,9.998282,,,,
,46641197.79,9.99959705,-54233.357421875,4.17651319158378E-5,6.57146513420217E-7,1,0.999253354069792,40.0298881530762,1.99511326782008,16.1200007982552,0.000454607612646751,5.37748718048175E-5,0.25,-2.47343933907047E-6,4.16015954972394E-5,-2.2631078737863E-6,9.999588,9.9996061,-54263.1640625,-54203.55078125,52.7302231643517,18.7495838381096,3.035767,0,0,0,4449,10.01525,-54233.357421875,,,,,,,,,,,,,,,,,13.753754,,,,,,9.99959705,,,,
,46641250.515,10.00020505,-51600.294921875,3.61302032564273E-5,7.54957356564679E-7,1,0.999253354069792,40.0298881530762,1.9948277467767,16.1200007982552,0.000391781664332017,5.42654458440565E-5,0.25,-1.41510537903388E-6,3.59806498943916E-5,-1.24015719903449E-6,10.0000105,10.0003996,-51630.1484375,-51570.44140625,53.2820528989287,18.7494983994013,3.0509303,0,0,0,4449,10.0135,-51600.294921875,,,,,,,,,,,,,,,,,13.753754,,,,,,10.00020505,,,,
,46641304.69,10.00172375,-48893.58203125,3.13429189642762E-5,6.07465418476076E-7,1,0.999253354069792,40.0298881530762,1.99505951555324,16.1200007982552,0.000340363706066362,4.42722265713206E-5,0.25,-1.48401518580504E-6,3.12103266509068E-5,-1.3347524416434E-6,10.0016813,10.0017662,-48921.17578125,-48865.98828125,53.3735034356787,18.7533328316351,3.035767,0,0,0,4449,10.0124,-48893.58203125,,,,,,,,,,,,,,,,,13.003003,,,,,,10.00172375,,,,
,46641358.405,10.00235225,-46208.083984375,2.43698006798126E-5,6.83100092750606E-7,1,0.999253354069792,40.0298881530762,1.99491096947883,16.1200007982552,0.00026562617691018,2.85972993502864E-5,0.25,-1.69127060776571E-6,2.42660360755836E-5,-1.5756316172152E-6,10.0022364,10.0024681,-46238.12890625,-46178.0390625,53.3930441486595,18.7548030527761,3.06655185,0,0,0,4449,10.01005,-46208.083984375,,,,,,,,,,,,,,,,,13.753754,,,,,,10.00235225,,,,
,46641410.8,10.0030823,-43590.986328125,2.02071266186778E-5,4.95501014409443E-7,1,0.999253354069792,40.0298881530762,1.99515836523564,16.1200007982552,0.000219812038301439,2.61835638354264E-5,0.25,-1.17035896925891E-6,2.01176313079486E-5,-1.07788775378397E-6,10.0030823,10.0030823,-43608.421875,-43573.55078125,52.6223584286979,18.7504276378601,3.09703065,0,0,0,4449,10.00825,-43590.986328125,,,,,,,,,,,,,,,,,13.753754,,,,,,10.0030823,,,,
,46641463.745,10.00268125,-40942.759765625,1.58225228886142E-5,5.04747111568616E-7,1,0.999253354069792,40.0298881530762,1.99496862255008,16.1200007982552,0.00017424155334464,8.36686806051098E-6,0.25,-2.04129869057924E-6,1.5755276097705E-5,-1.96541689933952E-6,10.0025873,10.0027752,-40970.4921875,-40915.02734375,53.3484913230633,18.7514585884758,3.09703065,0,0,0,4449,10.00725,-40942.759765625,,,,,,,,,,,,,,,,,14.129129,,,,,,10.00268125,,,,
,46641517.455,10.00292495,-38259.20703125,8.46326526621456E-6,6.77802856578293E-7,1,0.999253354069792,40.0298881530762,1.99494274713788,16.1200007982552,9.50047206239616E-5,-5.73925972697369E-6,0.25,-2.03965119194726E-6,8.43006923433736E-6,-1.99541478013034E-6,10.00278,10.0030699,-38291.60546875,-38226.80859375,52.822455329621,18.7495143718166,3.0206037,0,0,0,4449,10.0063,-38259.20703125,,,,,,,,,,,,,,,,,13.003003,,,,,,10.00292495,,,,
,46641569.385,10.00195695,-35662.9609375,3.43788888737147E-6,4.87220337354558E-7,1,0.999253354069792,40.0298881530762,1.99493824069679,16.1200007982552,4.06003184633029E-5,-1.36507935205443E-5,0.25,-1.87979768062885E-6,3.42806750410958E-6,-1.85693359949173E-6,10.0017014,10.0022125,-35687.8359375,-35638.0859375,53.3047201259864,18.7511781161943,3.0510825,0,0,0,4449,10.0052,-35662.9609375,,,,,,,,,,,,,,,,,13.003003,,,,,,10.00195695,,,,
,46641621.185,10.0029416,-33072.1953125,-2.7327419724421E-6,5.9899962157162E-7,1,0.999253354069792,40.0298881530762,1.99509006557683,16.1200007982552,-2.70460717404719E-5,-1.85404564614185E-5,0.25,-1.23693762365345E-6,-2.71413240985683E-6,-1.24098241889135E-6,10.0029383,10.0029449,-33094.671875,-33049.71875,52.9365730934287,18.7486006875096,3.0510825,0,0,0,4449,10.0042,-33072.1953125,,,,,,,,,,,,,,,,,13.003003,,,,,,10.0029416,,,,
,46641674.225,10.0023403,-30423.529296875,-5.61043945706215E-6,7.87350024932898E-7,1,0.999253354069792,40.0298881530762,1.99487634393748,16.1200007982552,-5.74594435527773E-5,-2.7134016977976E-5,0.25,-1.52514734778648E-6,-5.57574654453476E-6,-1.53771786781088E-6,10.002284,10.0023966,-30446.041015625,-30401.017578125,53.394607405698,18.7498182647731,3.0510825,0,0,0,4449,10.004,-30423.529296875,,,,,,,,,,,,,,,,,13.753754,,,,,,10.0023403,,,,
,46641727.605,10.0023122,-27757.439453125,-1.10814689742914E-5,6.89045414216782E-7,1,0.999253354069792,40.0298881530762,1.99494020895533,16.1200007982552,-0.00011566772287086,-4.13105108565547E-5,0.25,-1.87265189626238E-6,-1.10163514193322E-5,-1.90170787878135E-6,10.0021105,10.0025139,-27782.361328125,-27732.517578125,53.198418647371,18.749054623224,3.0815613,0,0,0,4449,10.00145,-27757.439453125,,,,,,,,,,,,,,,,,13.753754,,,,,,10.0023122,,,,
,46641780.44,10.00260545,-25116.140625,-1.46021076069967E-5,5.2903345092623E-7,1,0.999253354069792,40.0298881530762,1.99495585021469,16.1200007982552,-0.000155217728277844,-3.8581639819634E-5,0.25,-9.96579210328051E-7,-1.4520351598035E-5,-1.04056007004891E-6,10.0025425,10.0026684,-25143.73828125,-25088.54296875,52.9600219490056,18.7486418192389,3.0510825,0,0,0,4449,10.00165,-25116.140625,,,,,,,,,,,,,,,,,13.003003,,,,,,10.00260545,,,,
,46641832.575,10.00273035,-22510.318359375,-2.066582970561E-5,6.76782940125675E-7,1,0.999253354069792,40.0298881530762,1.99493943203678,16.1200007982552,-0.000219205270804485,-5.71454262019777E-5,0.25,-1.64991555967191E-6,-2.05478746809469E-5,-1.70795851070087E-6,10.0024719,10.0029888,-22535.25,-22485.38671875,52.9459526356594,18.7519818348956,3.0510825,0,0,0,4449,10.0011,-22510.318359375,,,,,,,,,,,,,,,,,13.003003,,,,,,10.00273035,,,,
,46641885.93,10.0020299,-19841.1796875,-2.4445675164013E-5,5.32587958967674E-7,1,0.999253354069792,40.0298881530762,1.99500951337698,16.1200007982552,-0.000261384683617186,-5.57608137542221E-5,0.25,-8.55146725236751E-7,-2.43079219192724E-5,-9.26351460837153E-7,10.0018272,10.0022326,-19866.169921875,-19816.189453125,53.7056955563518,18.7483464748857,3.0206037,0,0,0,4449,9.99925,-19841.1796875,,,,,,,,,,,,,,,,,13.003003,,,,,,10.0020299,,,,
,46641937.985,10.00150395,-17243.001953125,-2.90752196813992E-5,6.72834174210999E-7,1,0.999253354069792,40.0298881530762,1.99498304268867,16.1200007982552,-0.000308477366363321,-7.97922272927854E-5,0.25,-2.27363809666471E-6,-2.8905716319784E-5,-2.34735736110919E-6,10.0013876,10.0016203,-17272.896484375,-17213.107421875,53.3523994656595,18.7515602379454,3.035767,0,0,0,4449,10.0002,-17243.001953125,,,,,,,,,,,,,,,,,13.003003,,,,,,10.00150395,,,,
,46641990.735,10.0003934,-14604.525390625,-3.33469715839575E-5,4.30384706634554E-7,1,0.999253354069792,40.0298881530762,1.99499743681477,16.1200007982552,-0.000355168264544109,-8.36628912575497E-5,0.25,-1.88268779681246E-6,-3.31527314789553E-5,-1.96672528499422E-6,10.0002384,10.0005484,-14634.4443359375,-14574.6064453125,53.0686683131787,18.7471861237541,3.0510825,0,0,0,4449,9.9998,-14604.525390625,,,,,,,,,,,,,,,,,13.003003,,,,,,10.0003934,,,,
,46642043.975,10.0003629,-11945.1997070312,-3.75380331410023E-5,3.32159320093296E-7,1,0.999253354069792,40.0298881530762,1.99486114449338,16.1200007982552,-0.000398209182365394,-0.000102935157827791,0.25,-2.93946297758828E-6,-3.73150879060046E-5,-3.02428994690412E-6,10.0001574,10.0005684,-11970.20703125,-11920.1923828125,53.0514724857556,18.7519406809169,3.0206037,0,0,0,4449,9.99865,-11945.1997070312,,,,,,,,,,,,,,,,,12.627627,,,,,,10.0003629,,,,
,46642095.975,10.0005474,-9344.23486328125,-4.13383996150059E-5,4.00633541175456E-7,1,0.999253354069792,40.0298881530762,1.99491118033995,16.1200007982552,-0.00044016927992028,-0.00010397351709683,0.25,-2.37025594556836E-6,-4.10932058343142E-5,-2.46333248934361E-6,10.0004358,10.000659,-9371.82421875,-9316.6455078125,53.7987093501403,18.748355968064,3.0662458,0,0,0,4449,10.00005,-9344.23486328125,,,,,,,,,,,,,,,,,13.003003,,,,,,10.0005474,,,,
,46642148.775,10.00085305,-6707.66870117187,-4.49537104264742E-5,3.98999488315626E-7,1,0.999253354069792,40.0298881530762,1.99496529945083,16.1200007982552,-0.00047943023706576,-0.000108671978209188,0.25,-2.17470375045009E-6,-4.46860623686725E-5,-2.27268148240466E-6,10.0007334,10.0009727,-6732.62744140625,-6682.7099609375,52.9889422042171,18.7483761571875,3.08217645,0,0,0,4449,9.99905,-6707.66870117187,,,,,,,,,,,,,,,,,12.627627,,,,,,10.00085305,,,,
,46642203.205,9.99944825,-3985.91198730469,-4.8636327588993E-5,2.18602853887751E-7,1,0.999253354069792,40.0298881530762,1.99503121463342,16.1200007982552,-0.000518644859846633,-0.000117884804289682,0.25,-2.38755042254177E-6,-4.83446693740032E-5,-2.48755824793066E-6,9.999299,9.9995975,-4013.28173828125,-3958.54223632812,53.4594825727941,18.7508429133364,3.0815613,0,0,0,4449,9.9998,-3985.91198730469,,,,,,,,,,,,,,,,,13.753754,,,,,,9.99944825,,,,
,46642256.095,10.00061845,-1341.80798339844,-5.04631055662839E-5,2.64361554176583E-7,1,0.999253354069792,40.0298881530762,1.99481804615156,16.1200007982552,-0.000538201050893256,-0.000121455717154231,0.25,-2.40413108975727E-6,-5.01589985693672E-5,-2.50322659735967E-6,10.000494,10.0007429,-1369.37902832031,-1314.23693847656,52.7927534458902,18.7483473210418,3.035767,0,0,0,4449,9.99965,-1341.80798339844,,,,,,,,,,,,,,,,,13.003003,,,,,,10.00061845,,,,
,46642309.23,10.00013495,1312.83892822266,-3.36784926087338E-5,2.74435330413911E-7,1,0.999253354069792,40.0298881530762,1.99494710857887,16.1200007982552,-0.00035818277855975,-8.69004936718892E-5,0.25,-2.1472287300582E-6,-3.34743064026224E-5,-2.21011827912044E-6,10.0001154,10.0001545,1287.82092285156,1337.85693359375,53.6408203892557,18.7468794768113,3.0662458,0,0,0,4449,10.0002,1312.83892822266,,,,,,,,,,,,,,,,,13.003003,,,,,,10.00013495,,,,
,46642361.625,9.9988809,3928.98413085937,-3.53147756002899E-5,2.83309773671646E-7,1,0.999253354069792,40.0298881530762,1.99490516148415,16.1200007982552,-0.000375779047572099,-9.0048483792869E-5,0.25,-2.14810727945548E-6,-3.51020040551503E-5,-2.21820104183173E-6,9.9987183,9.9990435,3904.02856445313,3953.93969726562,52.5668628038325,18.7441391708163,3.08171515,0,0,0,4449,10,3928.98413085937,,,,,,,,,,,,,,,,,12.627627,,,,,,9.9988809,,,,
,46642412.605,9.99912885,6479.42895507812,-3.7871204807494E-5,3.78257379303779E-7,1,0.999253354069792,40.0298881530762,1.99494450582541,16.1200007982552,-0.000403301044787922,-9.48891175337142E-5,0.25,-2.14295017997807E-6,-3.76448230380089E-5,-2.22328305584539E-6,9.999095,9.9991627,6454.26171875,6504.59619140625,52.7013029091402,18.7449759550745,3.08171515,0,0,0,4449,10.00055,6479.42895507812,,,,,,,,,,,,,,,,,13.003003,,,,,,9.99912885,,,,
,46642464.7,10.00025225,9084.10791015625,-4.0135231864924E-5,3.60687794413446E-7,1,0.999253354069792,40.0298881530762,1.99496865543316,16.1200007982552,-0.000426299558571853,-0.000107001867311227,0.25,-2.86439630756883E-6,-3.98955410602475E-5,-2.95100023249234E-6,10.000082,10.0004225,9064.130859375,9104.0849609375,52.9185956374864,18.749171405327,3.08171515,0,0,0,4449,9.99975,9084.10791015625,,,,,,,,,,,,,,,,,13.753754,,,,,,10.00025225,,,,
,46642517.96,10.0008736,11744.5893554687,-4.15744160419549E-5,4.66326050711945E-7,1,0.999253354069792,40.0298881530762,1.99495897405784,16.1200007982552,-0.000442187805647013,-0.000107545658930589,0.25,-2.65517719071645E-6,-4.13289622423446E-5,-2.75214461341755E-6,10.0008736,10.0008736,11717.2685546875,11771.91015625,53.3977339197749,18.750684911003,3.0509303,0,0,0,4449,9.9996,11744.5893554687,,,,,,,,,,,,,,,,,13.003003,,,,,,10.0008736,,,,
,46642571.8,10.0022788,14436.0361328125,-4.18058795007303E-5,4.56914866752184E-7,1,0.999253354069792,40.0298881530762,1.99478182457296,16.1200007982552,-0.000445322015768453,-0.000104265502140386,0.25,-2.30404069412593E-6,-4.15623744922608E-5,-2.40935184389741E-6,10.0022011,10.0023565,14411.0078125,14461.064453125,53.2015451614479,18.7484780739682,3.0509303,0,0,0,4449,9.99925,14436.0361328125,,,,,,,,,,,,,,,,,13.753754,,,,,,10.0022788,,,,
,46642623.97,10.0007248,17042.2314453125,-3.9546603293333E-5,4.08632921178276E-7,1,0.999253354069792,40.0298881530762,1.99481609607818,16.1200007982552,-0.000420032879588607,-0.000105732967472821,0.25,-2.83379831400893E-6,-3.93166427761912E-5,-2.93509655844513E-6,10.0006151,10.0008345,17014.9765625,17069.486328125,53.770570723448,18.7450181090353,3.09733975,0,0,0,4449,9.9976,17042.2314453125,,,,,,,,,,,,,,,,,13.753754,,,,,,10.0007248,,,,
,46642676.4,9.99961475,19663.2666015625,-3.32217833175787E-5,3.90635362619215E-7,1,0.999253354069792,40.0298881530762,1.99495368535643,16.1200007982552,-0.000352791994618683,-8.94474391881454E-5,0.25,-2.43309953198571E-6,-3.30304844471601E-5,-2.52252744419346E-6,9.9995928,9.9996367,19638.29296875,19688.240234375,53.1562107073326,18.7465731283173,3.08171515,0,0,0,4449,10.0002,19663.2666015625,,,,,,,,,,,,,,,,,13.003003,,,,,,9.99961475,,,,
,46642728.435,9.99798585,22263.9267578125,-2.72308566363324E-5,4.41543844878374E-7,1,0.999253354069792,40.0298881530762,1.99491942513642,16.1200007982552,-0.000287923327928436,-8.04543748795148E-5,0.25,-2.65366380988824E-6,-2.70737077538784E-5,-2.72716627339996E-6,9.99786,9.9981117,22241.564453125,22286.2890625,53.1945105047749,18.747306605388,3.08171515,0,0,0,4449,9.99965,22263.9267578125,,,,,,,,,,,,,,,,,13.003003,,,,,,9.99798585,,,,
,46642780.36,9.9986515,24860.7919921875,-1.95199459525458E-5,6.54748727700504E-7,1,0.999253354069792,40.0298881530762,1.99479608360377,16.1200007982552,-0.000206833057265696,-5.5199253622157E-5,0.25,-1.66967649060984E-6,-1.94093797787705E-5,-1.72638693873596E-6,9.9985075,9.9987955,24835.91015625,24885.673828125,53.7463402393518,18.7484276490372,3.1125,0,0,0,4449,10.00085,24860.7919921875,,,,,,,,,,,,,,,,,13.753754,,,,,,9.9986515,,,,
,46642833.14,9.99701265,27497.0419921875,-1.41054183236006E-5,7.06093680343631E-7,1,0.999253354069792,40.0298881530762,1.99484306938361,16.1200007982552,-0.00014549066861688,-6.23484909768082E-5,0.25,-3.29164440354848E-6,-1.4019261835201E-5,-3.32361519692677E-6,9.9969807,9.9970446,27464.54296875,27529.541015625,52.3276844769478,18.7458200278075,3.09733975,0,0,0,4449,10.00275,27497.0419921875,,,,,,,,,,,,,,,,,13.003003,,,,,,9.99701265,,,,
,46642885.375,9.99655725,30108.048828125,-9.9452536581833E-6,6.95418637265715E-7,1,0.999253354069792,40.0298881530762,1.9949165259667,16.1200007982552,-0.000101456328760218,-5.03488047677677E-5,0.25,-2.9127438793992E-6,-9.88292918771297E-6,-2.93374790766469E-6,9.9963436,9.9967709,30077.943359375,30138.154296875,52.6583133405825,18.7487124244844,3.08171515,0,0,0,4449,10.00415,30108.048828125,,,,,,,,,,,,,,,,,12.627627,,,,,,9.99655725,,,,
,46642937.75,9.99710515,32724.5048828125,-1.01214271738955E-5,7.22647317670844E-7,1,0.999253354069792,40.0298881530762,1.99499746909734,16.1200007982552,-0.000105175010712961,-4.04876217506897E-5,0.25,-1.96328316521319E-6,-1.00623214019338E-5,-1.99140168412514E-6,9.9970942,9.9971161,32697.076171875,32751.93359375,53.2992487263518,18.744664035005,3.1125,0,0,0,4449,10.00695,32724.5048828125,,,,,,,,,,,,,,,,,13.003003,,,,,,9.99710515,,,,
,46642989.36,9.99687575,35305.6015625,-1.18198078553324E-5,5.356775802336E-7,1,0.999253354069792,40.0298881530762,1.99486836818451,16.1200007982552,-0.000123576259422362,-4.30564475369915E-5,0.25,-1.89850276018927E-6,-1.17531593548997E-5,-1.93507715109811E-6,9.9964914,9.9972601,35275.609375,35335.59375,52.7466373632556,18.7483231741235,3.1125,0,0,0,4449,10.00865,35305.6015625,,,,,,,,,,,,,,,,,13.753754,,,,,,9.99687575,,,,
,46643042.02,9.99624015,37936.376953125,-1.4023921171364E-5,6.54821855682821E-7,1,0.999253354069792,40.0298881530762,1.99490295544376,16.1200007982552,-0.000148235738057609,-4.20950312636634E-5,0.25,-1.41490108086453E-6,-1.3949355687623E-5,-1.46447808601822E-6,9.9961739,9.9963064,37908.703125,37964.05078125,53.1952921332941,18.7483204476508,3.09733975,0,0,0,4449,10.00965,37936.376953125,,,,,,,,,,,,,,,,,13.003003,,,,,,9.99624015,,,,
,46643094.445,9.9967408,40555.470703125,-1.64943598440271E-5,7.1050401858977E-7,1,0.999253354069792,40.0298881530762,1.99482323753909,16.1200007982552,-0.000171141029710721,-6.75772670106856E-5,0.25,-3.34019865606249E-6,-1.64012126239897E-5,-3.39275147323086E-6,9.9966297,9.9968519,40532.97265625,40577.96875,53.2945589552364,18.7469010122588,3.08171515,0,0,0,4449,10.01095,40555.470703125,,,,,,,,,,,,,,,,,13.753754,,,,,,9.9967408,,,,
,46643147.07,9.9958234,43186.53515625,-1.98806046464031E-5,7.64867311743592E-7,1,0.999253354069792,40.0298881530762,1.99499099913549,16.1200007982552,-0.000210440004643458,-5.82919593557774E-5,0.25,-1.87091988008479E-6,-1.97792386385798E-5,-1.94734234327794E-6,9.9956007,9.9960461,43161.5859375,43211.484375,52.8302716148133,18.7477279276698,3.1281246,0,0,0,4449,10.0123,43186.53515625,,,,,,,,,,,,,,,,,13.753754,,,,,,9.9958234,,,,
,46643199.295,9.99656725,45798.23046875,-2.51894361197453E-5,6.3497905081419E-7,1,0.999253354069792,40.0298881530762,1.99482689121732,16.1200007982552,-0.000267051287165278,-7.15620913338439E-5,0.25,-2.15396487446644E-6,-2.50644916563015E-5,-2.25515931633723E-6,9.9965563,9.9965782,45770.671875,45825.7890625,53.0209889735056,18.7458891390184,3.11265525,0,0,0,4449,10.01505,45798.23046875,,,,,,,,,,,,,,,,,13.378378,,,,,,9.99656725,,,,
,46643252.125,9.9959135,48439.314453125,-2.99757204094569E-5,5.79691883848962E-7,1,0.999253354069792,40.0298881530762,1.99486376264495,16.1200007982552,-0.000317828484463523,-8.52002984702766E-5,0.25,-2.56234409291628E-6,-2.98302294820973E-5,-2.6867226125504E-6,9.9958448,9.9959822,48409.3828125,48469.24609375,53.6783385581788,18.7447053661178,3.11265525,0,0,0,4449,10.0172,48439.314453125,,,,,,,,,,,,,,,,,13.003003,,,,,,9.9959135,,,,
,46643304.93,9.9966836,51078.03125,-3.60454278403404E-5,6.19096833875765E-7,1,0.999253354069792,40.0298881530762,1.99492277704722,16.1200007982552,-0.000384344091338231,-9.06745533141492E-5,0.25,-1.98184050753929E-6,-3.58795450363758E-5,-2.14082925908735E-6,9.9965839,9.9967833,51053.01953125,51103.04296875,53.0069196601595,18.7450973475578,3.1125,0,0,0,4449,10.01805,51078.03125,,,,,,,,,,,,,,,,,13.003003,,,,,,9.9966836,,,,
,46643357.06,9.997776,53681.638671875,-4.06405756126169E-5,5.39660816745395E-7,1,0.999253354069792,40.0298881530762,1.99487076723463,16.1200007982552,-0.000432581540878373,-0.000106714516414695,0.25,-2.64503106341786E-6,-4.04562619277527E-5,-2.82745313760745E-6,9.9975767,9.9979753,53656.6015625,53706.67578125,53.3992971768133,18.7504222316793,3.0509303,0,0,0,4449,10.0188,53681.638671875,,,,,,,,,,,,,,,,,13.003003,,,,,,9.997776,,,,
,46643410.095,9.99652625,56332.986328125,-4.53242419265701E-5,6.96111487722094E-7,1,0.999253354069792,40.0298881530762,1.99472291841189,16.1200007982552,-0.000485793256149569,-0.000100376836467796,0.25,-1.21377995311052E-6,-4.51325405068272E-5,-1.42981540001169E-6,9.9965162,9.9965363,56305.5390625,56360.43359375,52.9146874948902,18.7470726273924,3.0662458,0,0,0,4449,10.0215,56332.986328125,,,,,,,,,,,,,,,,,13.753754,,,,,,9.99652625,,,,
,46643462.015,9.9957538,58929.486328125,-5.1162859282945E-5,7.89165070446185E-7,1,0.999253354069792,40.0298881530762,1.99473544464489,16.1200007982552,-0.000547152619225498,-0.000120537834623688,0.25,-2.03461386477946E-6,-5.09494571395788E-5,-2.28147214056621E-6,9.9953938,9.9961138,58904.5078125,58954.46484375,52.954550549371,18.7475254492453,3.1125,0,0,0,4449,10.02365,58929.486328125,,,,,,,,,,,,,,,,,13.003003,,,,,,9.9957538,,,,
,46643484.9,9.99261285,59999.462890625,-5.37274287720849E-5,7.26703939908534E-7,1,0.999253354069792,40.0298881530762,1.99484741692489,16.1200007982552,-0.000573757162027479,-0.000131518698071352,0.25,-2.59155484381953E-6,-5.35037794615886E-5,-2.85142321765926E-6,9.9925127,9.992713,59999.37890625,59999.546875,53.6455101603711,18.7462838513893,3.0815613,0,0,0,4417,10.02575,59999.462890625,,,,,,,,,,,,,,,,,12.627627,,,,,,9.99261285,,,,