File: data/monolayers/magneticStructure/ML_Ac_CoFe_C-2/VSM/data/DD175_23_HYST_300K.DAT
[Header]
; VSM Data File (default extension .dat)
; Copyright (c) 2003, Quantum Design, Inc. All rights reserved.
TITLE,
FILEOPENTIME,46492639.42,04/04/2017,12:53 pm
BYAPP,VSM,1.0,1.0
INFO,PPMS VSM Option Release 1.3.7 Build 2,APPNAME
INFO,291,COIL_SERIAL_NUMBER
INFO,0,MOMENT_UNITS
INFO,CoFe2O4,SAMPLE_MATERIAL
INFO,,SAMPLE_COMMENT
INFO,,SAMPLE_MASS
INFO,,SAMPLE_VOLUME
INFO,,SAMPLE_MOLECULAR_WEIGHT
INFO,,SAMPLE_SIZE
INFO,,SAMPLE_SHAPE
INFO,36.48,SAMPLE_OFFSET
DATATYPE,COMMENT,1
DATATYPE,TIME,2
STARTUPAXIS,X,2
STARTUPAXIS,Y1,5
[Data]
Comment,Time Stamp (sec),Temperature (K),Magnetic Field (Oe),Moment (emu),M. Std. Err. (emu),Transport Action,Averaging Time (sec),Frequency (Hz),Peak Amplitude (mm),Center Position (mm),Coil Signal' (mV),Coil Signal" (mV),Range (mV),M. Quad. Signal (emu),M. Raw' (emu),M. Raw" (emu),Min. Temperature (K),Max. Temperature (K),Min. Field (Oe),Max. Field (Oe),Mass (grams),Motor Lag (deg),Pressure (Torr),VSM Status (code),Motor Status (code),Measure Status (code),PPMS Status (code),System Temp. (K),System Field (Oe),Sample Position (deg),Bridge 1 Resistance (ohms),Bridge 1 Excitation (�A),Bridge 2 Resistance (ohms),Bridge 2 Excitation (�A),Bridge 3 Resistance (ohms),Bridge 3 Excitation (�A),Bridge 4 Resistance (ohms),Bridge 4 Excitation (�A),Signal 1 Vin (V),Signal 2 Vin (V),Digital Inputs (code),Drive 1 Iout (mA),Drive 1 Ipower (W),Drive 2 Iout (mA),Drive 2 Ipower (W),Pressure (),Map 20 (),Map 21 (),Map 22 (),Map 23 (),Map 24 (),Map 25 (),Map 26 (),Map 27 (),Map 28 (),Map 29 ()
,46493123.39,300.0344238,89999.625,-0.000332125985681386,1.48604801697604E-6,1,0.999253354069792,40.0298881530762,1.99707028299837,15.5500008817762,-0.00360262619930085,-0.000602188893976484,0.25,2.36132413423431E-6,-0.000332116385343671,2.14743174953821E-6,300.0342712,300.0345764,89999.609375,89999.640625,52.057241009294,18.6824928054717,12.5412607,0,0,0,4417,299.5146,89999.625,,,,,,,,,,,,,,,,,12.627627,,,,,,300.0344238,,,,
,46493154.695,300.0342102,86886.93359375,-0.000318417704321254,1.38526428444411E-6,1,0.999253354069792,40.0298881530762,1.9969946826873,15.5500008817762,-0.0034553926305282,-0.000568224383580073,0.25,3.10292580967246E-6,-0.000318409034902014,2.89774923806297E-6,300.033844,300.0345764,86759.953125,87013.9140625,52.1807383153324,18.6816304208938,12.6039028,0,0,0,4449,299.5106,86886.93359375,,,,,,,,,,,,,,,,,12.627627,,,,,,300.0342102,,,,
,46493170.86,300.0327301,83733.01953125,-0.000305948336183577,1.47167146645393E-6,1,0.999253354069792,40.0298881530762,1.99713492533736,15.5500008817762,-0.00331996711255521,-0.000547904368172267,0.25,2.80651954129513E-6,-0.000305939900398933,2.60929886591535E-6,300.0326843,300.0327759,83615.8359375,83850.203125,52.1783934297748,18.678901760461,12.6039028,0,0,0,4449,299.50235,83733.01953125,,,,,,,,,,,,,,,,,12.627627,,,,,,300.0327301,,,,
,46493187.32,300.0284424,80510.71484375,-0.000290737304385173,1.96611723092385E-6,1,0.999253354069792,40.0298881530762,1.99707010777065,15.5500008817762,-0.00315355314932334,-0.00052785178854172,0.25,2.00212642611796E-6,-0.000290728891900532,1.81465067716303E-6,300.0280457,300.0288391,80393.375,80628.0546875,52.5645179182748,18.6808229261218,12.6039028,0,0,0,4449,299.4925,80510.71484375,,,,,,,,,,,,,,,,,12.627627,,,,,,300.0284424,,,,
,46493207.065,300.0234375,76653.72265625,-0.000273578250460794,2.00340016433163E-6,1,0.999253354069792,40.0298881530762,1.99706370892394,15.5500008817762,-0.00296917534412707,-0.000486663081011154,0.25,2.8102246203896E-6,-0.000273570967983064,2.63369955159375E-6,300.0234375,300.0234375,76644.0078125,76663.4375,52.3269028484286,18.6843906516135,12.3545799,0,0,0,4449,299.49415,76653.72265625,,,,,,,,,,,,,,,,,11.876877,,,,,,300.0234375,,,,
,46493223.9,300.0153656,73362.74609375,-0.000258618048675399,1.38101942403682E-6,1,0.999253354069792,40.0298881530762,1.99707485936806,15.5500008817762,-0.00280571804551007,-0.000466403725732261,0.25,2.07044276337981E-6,-0.000258610846941969,1.90351969884894E-6,300.0151367,300.0155945,73245.4609375,73480.03125,52.5848402597748,18.6815891526447,12.4786186,0,0,0,4449,299.4891,73362.74609375,,,,,,,,,,,,,,,,,12.627627,,,,,,300.0153656,,,,
,46493241.77,300.00566105,69876.578125,-0.000244083287098474,1.30909407266139E-6,1,0.999253354069792,40.0298881530762,1.99708224966708,15.5500008817762,-0.00264616826696575,-0.000450932548805054,0.25,9.62812931167251E-7,-0.000244075921049692,8.05245975256928E-7,300.0053101,300.006012,69749.4453125,70003.7109375,52.4175717566594,18.6831023898086,12.7304459,0,0,0,4449,299.5034,69876.578125,,,,,,,,,,,,,,,,,12.627627,,,,,,300.00566105,,,,
,46493259.795,300.0019226,66361.015625,-0.00022947278440377,1.65407590900829E-6,1,0.999253354069792,40.0298881530762,1.99705442307032,15.5500008817762,-0.00248919799701856,-0.000415576452991596,0.25,1.67675515311761E-6,-0.000229466379361371,1.52853646843748E-6,300.0019226,300.0019226,66351.2421875,66370.7890625,52.5426323197363,18.6801753861067,12.4786186,0,0,0,4449,299.5113,66361.015625,,,,,,,,,,,,,,,,,11.876877,,,,,,300.0019226,,,,
,46493276.17,299.999115,63157.9609375,-0.000214620702416246,1.78864672344911E-6,1,0.999253354069792,40.0298881530762,1.99704481131709,15.5500008817762,-0.0023291378453766,-0.000382615286315941,0.25,2.12785781153655E-6,-0.000214615088040426,1.98916383018464E-6,299.999115,299.999115,63148.234375,63167.6875,52.2768786231978,18.6856806046041,12.4786186,0,0,0,4449,299.5166,63157.9609375,,,,,,,,,,,,,,,,,11.876877,,,,,,299.999115,,,,
,46493293.14,299.9968872,59829.8671875,-0.000199865530729014,1.121290266926E-6,1,0.999253354069792,40.0298881530762,1.99708052946587,15.5500008817762,-0.00216804245460889,-0.000362070154028728,0.25,1.4505341824436E-6,-0.000199859968984498,1.32134304050131E-6,299.9963684,299.997406,59722.34375,59937.390625,52.0588042663324,18.6836931225654,12.4786186,0,0,0,4449,299.519,59829.8671875,,,,,,,,,,,,,,,,,12.627627,,,,,,299.9968872,,,,
,46493309.935,299.99317935,56550.689453125,-0.000186033876776395,1.06441680009756E-6,1,0.999253354069792,40.0298881530762,1.9970895119528,15.5500008817762,-0.00201675391871808,-0.000344226888531562,0.25,6.84478663625375E-7,-0.000186028287561131,5.6420461880653E-7,299.993042,299.9933167,56433.3984375,56667.98046875,52.1908994860824,18.683013883337,12.6684384,0,0,0,4449,299.5211,56550.689453125,,,,,,,,,,,,,,,,,12.627627,,,,,,299.99317935,,,,
,46493326.6,299.98994445,53281.04296875,-0.000172796962062894,8.85583109897322E-7,1,0.999253354069792,40.0298881530762,1.99709059756071,15.5500008817762,-0.00187532012153076,-0.000307906108615,0.25,1.72758929639072E-6,-0.000172792490676592,1.61579871509907E-6,299.9893188,299.9905701,53202.7890625,53359.296875,52.4292961844479,18.6843337573335,12.6684384,0,0,0,4449,299.5284,53281.04296875,,,,,,,,,,,,,,,,,11.876877,,,,,,299.98994445,,,,
,46493343.955,299.986496,49884.998046875,-0.000157135053262216,9.69071927356774E-7,1,0.999253354069792,40.0298881530762,1.99708203112091,15.5500008817762,-0.00170508163440619,-0.000281471016080506,0.25,1.43499583789702E-6,-0.000157130913174054,1.33330480093205E-6,299.9862061,299.9867859,49777.39453125,49992.6015625,52.7466373632556,18.6853898653896,12.7310805,0,0,0,4449,299.53375,49884.998046875,,,,,,,,,,,,,,,,,11.876877,,,,,,299.986496,,,,
,46493360.955,299.9846191,46557.10546875,-0.000143198599101011,8.48359594665736E-7,1,0.999253354069792,40.0298881530762,1.99710906358653,15.5500008817762,-0.00155359960839792,-0.000258095910010075,0.25,1.1614076129823E-6,-0.000143194737200611,1.06870831446416E-6,299.9846191,299.9846191,46547.55859375,46566.65234375,52.544977205294,18.6851636820518,12.8582582,0,0,0,4449,299.54135,46557.10546875,,,,,,,,,,,,,,,,,13.003003,,,,,,299.9846191,,,,
,46493377.18,299.98272705,43385.59375,-0.000130113734497328,1.09348971085127E-6,1,0.999253354069792,40.0298881530762,1.99709265744904,15.5500008817762,-0.00141172283209343,-0.000233964405789429,0.25,1.10571125874432E-6,-0.000130110263346781,1.0214520024918E-6,299.9823303,299.9831238,43277.9453125,43493.2421875,52.6504970553902,18.6867182743041,12.8582582,0,0,0,4449,299.54425,43385.59375,,,,,,,,,,,,,,,,,13.003003,,,,,,299.98272705,,,,
,46493393.135,299.98081975,40253.455078125,-0.00011671940072823,7.32620038371384E-7,1,0.999253354069792,40.0298881530762,1.9969997081009,15.5500008817762,-0.00126478184062881,-0.000218800569660296,0.25,1.67565511166454E-7,-0.000116715758142399,9.1983371678658E-8,299.9804688,299.9811707,40145.53125,40361.37890625,52.5676444323517,18.6864341805474,12.7310805,0,0,0,4449,299.5533,40253.455078125,,,,,,,,,,,,,,,,,11.876877,,,,,,299.98081975,,,,
,46493410.545,299.98114015,36847.61328125,-0.000103449281728365,8.55140443660872E-7,1,0.999253354069792,40.0298881530762,1.99710779007492,15.5500008817762,-0.0011212708018051,-0.000192627632581755,0.25,2.69163071163831E-7,-0.000103446128003925,2.02146607396722E-7,299.9801941,299.9820862,36720.31640625,36974.91015625,52.4175717566594,18.687190614039,12.6039028,0,0,0,4449,299.5576,36847.61328125,,,,,,,,,,,,,,,,,11.876877,,,,,,299.98114015,,,,
,46493427.08,299.97918705,33617.875,-8.93799625711383E-5,7.49118192171163E-7,1,0.999253354069792,40.0298881530762,1.99707191450575,15.5500008817762,-0.000968166759352817,-0.000169822985197128,0.25,-8.08824731780305E-8,-8.93770383651416E-5,-1.38793818665444E-7,299.9789429,299.9794312,33510.2578125,33725.4921875,52.524654863794,18.6853002845796,12.7310805,0,0,0,4449,299.56,33617.875,,,,,,,,,,,,,,,,,11.876877,,,,,,299.97918705,,,,
,46493444.53,299.97846985,30192.1142578125,-7.49418761207316E-5,8.00993798014045E-7,1,0.999253354069792,40.0298881530762,1.99707606009394,15.5500008817762,-0.000811215669009471,-0.000145593723576088,0.25,-3.63449085937926E-7,-7.4939232619346E-5,-4.12013388440289E-7,299.9780273,299.9789124,30084.3515625,30299.876953125,52.5738974605056,18.6865273119601,12.8582582,0,0,0,4449,299.56065,30192.1142578125,,,,,,,,,,,,,,,,,11.876877,,,,,,299.97846985,,,,
,46493461.895,299.97743225,26795.9375,-5.97542072305328E-5,7.49476037608825E-7,1,0.999253354069792,40.0298881530762,1.99705903318681,15.5500008817762,-0.000645648066902153,-0.000122746901586651,0.25,-9.0453473713862E-7,-5.97517017365715E-5,-9.43248013576201E-7,299.9769287,299.9779358,26658.69921875,26933.17578125,52.6278298283325,18.6871005145721,12.7310805,0,0,0,4449,299.5783,26795.9375,,,,,,,,,,,,,,,,,12.627627,,,,,,299.97743225,,,,
,46493478.735,299.9797516,23507.2451171875,-4.62431468754744E-5,5.83664064322234E-7,1,0.999253354069792,40.0298881530762,1.9970961763214,15.5500008817762,-0.000499133874029871,-9.80606586915712E-5,0.25,-9.83045936131543E-7,-4.62410197752182E-5,-1.01300605361892E-6,299.9792786,299.9802246,23389.791015625,23624.69921875,52.2542113961401,18.6844547326164,12.8582582,0,0,0,4449,299.58085,23507.2451171875,,,,,,,,,,,,,,,,,12.627627,,,,,,299.9797516,,,,
,46493495.17,299.9801178,20286.9462890625,-3.443199885934E-5,6.0380318671055E-7,1,0.999253354069792,40.0298881530762,1.9970552526819,15.5500008817762,-0.000370043289268169,-8.21698365625909E-5,0.25,-1.57716187733206E-6,-3.44298657341038E-5,-1.59944752937631E-6,299.9798889,299.9803467,20277.173828125,20296.71875,52.5098039219286,18.687398959112,12.6039028,0,0,0,4449,299.6027,20286.9462890625,,,,,,,,,,,,,,,,,12.627627,,,,,,299.9801178,,,,
,46493511.395,299.98002625,17096.4697265625,-2.06262178915799E-5,5.12624723423093E-7,1,0.999253354069792,40.0298881530762,1.99703306050539,15.5500008817762,-0.000220753617434983,-5.44702556814528E-5,0.25,-1.42916338509726E-6,-2.0624624940335E-5,-1.44250338540107E-6,299.9798584,299.9801941,16988.77734375,17204.162109375,52.7294415358325,18.6875980681288,12.79562855,0,0,0,4449,299.5724,17096.4697265625,,,,,,,,,,,,,,,,,11.876877,,,,,,299.98002625,,,,
,46493528.58,299.9727783,13748.0610351562,-6.98685289280665E-6,6.69156975948377E-7,1,0.999253354069792,40.0298881530762,1.99717745758747,15.5500008817762,-7.27608272528392E-5,-3.00390116239076E-5,0.25,-1.55355505939737E-6,-6.98562043265352E-6,-1.55804100043653E-6,299.9722595,299.9732971,13640.392578125,13855.7294921875,52.8076043877556,18.6894064287687,12.66717435,0,0,0,4449,299.57265,13748.0610351562,,,,,,,,,,,,,,,,,12.627627,,,,,,299.9727783,,,,
,46493545.31,299.96665955,10466.783203125,5.90173812576435E-6,4.79982264690761E-7,1,0.999253354069792,40.0298881530762,1.99706808563474,15.5500008817762,6.81792234575189E-5,-1.31539381978174E-5,0.25,-2.24387466575898E-6,5.90300703389085E-6,-2.23997110693546E-6,299.9665527,299.9667664,10349.33984375,10584.2265625,52.8576286129864,18.6892132489008,12.8589001,0,0,0,4449,299.59385,10466.783203125,,,,,,,,,,,,,,,,,12.627627,,,,,,299.96665955,,,,
,46493561.895,299.9663086,7204.60571289063,1.75836989859627E-5,3.84888294371344E-7,1,0.999253354069792,40.0298881530762,1.997121895678,15.5500008817762,0.000195346340759035,5.47158369621526E-6,0.25,-2.56288954001753E-6,1.75848030917126E-5,-2.55138806966944E-6,299.9661865,299.9664307,7096.81103515625,7312.400390625,52.6958315095056,18.6906496794832,12.8582582,0,0,0,4449,299.60455,7204.60571289063,,,,,,,,,,,,,,,,,12.627627,,,,,,299.9663086,,,,
,46493577.24,299.9682312,4196.40478515625,2.5914738405043E-5,3.40457210280598E-7,1,0.999253354069792,40.0298881530762,1.99714444838399,15.5500008817762,0.0002854035736157,2.2390467471771E-5,0.25,-2.45483014347552E-6,2.59155052149091E-5,-2.43791926474866E-6,299.9671631,299.9692993,4098.38671875,4294.4228515625,52.5738974605056,18.6866814631881,12.8589001,0,0,0,4449,299.62985,4196.40478515625,,,,,,,,,,,,,,,,,11.876877,,,,,,299.9682312,,,,
,46493595.13,299.9769592,695.145782470703,2.63009298745189E-5,3.04596093634577E-7,1,0.999253354069792,40.0298881530762,1.99717248768634,15.5500008817762,0.000289675762925259,2.26370662449675E-5,0.25,-2.49948108959762E-6,2.63017059458155E-5,-2.48231308084367E-6,299.9769592,299.9769592,685.380737304687,704.910827636719,52.8591918700248,18.691749023033,12.9873543,0,0,0,4449,299.6233,695.145782470703,,,,,,,,,,,,,,,,,12.627627,,,,,,299.9769592,,,,
,46493610.74,299.978302,-2344.43701171875,-2.77800666769512E-5,4.65945055568023E-7,1,0.999253354069792,40.0298881530762,1.99708253412587,15.5500008817762,-0.000296787965294733,-7.64428034658425E-5,0.25,-2.20900732843142E-6,-2.77777349879222E-5,-2.22698348844205E-6,299.9782104,299.9783936,-2451.36743164062,-2237.50659179687,52.6708193968902,18.690737456776,12.8589001,0,0,0,4449,299.61325,-2344.43701171875,,,,,,,,,,,,,,,,,11.876877,,,,,,299.978302,,,,
,46493626.84,299.9806976,-5503.03466796875,-2.15208743272075E-5,3.99171772039039E-7,1,0.999253354069792,40.0298881530762,1.99709753138678,15.5600009579211,-0.000227861128901232,-7.10176562063589E-5,0.25,-2.80028080083057E-6,-2.15183595583902E-5,-2.81416842478951E-6,299.9804382,299.980957,-5610.837890625,-5395.2314453125,52.5168385786017,18.6910594535644,12.8589001,0,0,0,4449,299.61215,-5503.03466796875,,,,,,,,,,,,,,,,,11.876877,,,,,,299.9806976,,,,
,46493643.7,299.9828644,-8806.39208984375,-1.11311720542208E-5,5.33198916384906E-7,1,0.999253354069792,40.0298881530762,1.99715457691438,15.5500008817762,-0.00011665775397426,-4.36183592394206E-5,0.25,-2.08388493438085E-6,-1.11294583776706E-5,-2.09104533449411E-6,299.9824524,299.9832764,-8943.9287109375,-8668.85546875,52.8740428118902,18.6903902618689,12.9873543,0,0,0,4449,299.6172,-8806.39208984375,,,,,,,,,,,,,,,,,11.876877,,,,,,299.9828644,,,,
,46493660.485,299.98368835,-12089.544921875,4.26450080942877E-7,7.90989358879954E-8,1,0.999253354069792,40.0298881530762,1.99708832122126,15.5500008817762,1.17294342541468E-5,-3.99409225115339E-5,0.25,-3.7610928147624E-6,4.2887775099023E-7,-3.76069414413801E-6,299.983551,299.9838257,-12177.6083984375,-12001.4814453125,52.7857187892171,18.6913456186667,13.05255035,0,0,0,4449,299.6241,-12089.544921875,,,,,,,,,,,,,,,,,13.003003,,,,,,299.98368835,,,,
,46493676.36,299.9873505,-15215.9775390625,1.27662045167936E-5,3.38368204632118E-7,1,0.999253354069792,40.0298881530762,1.99707660213547,15.5500008817762,0.000143721530765742,-6.90787104944255E-6,0.25,-2.86501003224121E-6,1.27676489541082E-5,-2.85663219337021E-6,299.9872742,299.9874268,-15333.60546875,-15098.349609375,52.6723826539286,18.6917391812933,12.8589001,0,0,0,4449,299.626,-15215.9775390625,,,,,,,,,,,,,,,,,13.003003,,,,,,299.9873505,,,,
,46493693.215,299.9921875,-18517.8681640625,2.59915374596503E-5,4.87852940820745E-7,1,0.999253354069792,40.0298881530762,1.99709341071185,15.5500008817762,0.000289064168757833,6.28255673443459E-6,0.25,-3.95497210360598E-6,2.59932552019524E-5,-3.93798033857356E-6,299.9917603,299.9926147,-18625.529296875,-18410.20703125,52.6895784813517,18.6931538248478,12.79435205,0,0,0,4449,299.62015,-18517.8681640625,,,,,,,,,,,,,,,,,13.003003,,,,,,299.9921875,,,,
,46493710.11,299.9943848,-21819.869140625,4.0301482315038E-5,5.84243690308781E-7,1,0.999253354069792,40.0298881530762,1.99709889100709,15.5500008817762,0.0004450135892343,2.80786116973561E-5,0.25,-4.43984998094942E-6,4.03030447624867E-5,-4.41356592626959E-6,299.9935303,299.9952393,-21937.501953125,-21702.236328125,52.9928503468133,18.6915589448422,12.79435205,0,0,0,4449,299.6153,-21819.869140625,,,,,,,,,,,,,,,,,11.876877,,,,,,299.9943848,,,,
,46493727.665,299.9967346,-25259.3486328125,5.33647993416308E-5,5.99745740516089E-7,1,0.999253354069792,40.0298881530762,1.9970659571615,15.5500008817762,0.000585637558343031,5.7890019323325E-5,0.25,-3.96728953004588E-6,5.33656246312661E-5,-3.93255967364938E-6,299.9967346,299.9967346,-25269.052734375,-25249.64453125,52.738039449544,18.6939312201213,12.7304459,0,0,0,4449,299.61495,-25259.3486328125,,,,,,,,,,,,,,,,,12.627627,,,,,,299.9967346,,,,
,46493743.765,299.99913025,-28424.490234375,6.70622332028405E-5,5.197260640976E-7,1,0.999253354069792,40.0298881530762,1.99714168849063,15.5500008817762,0.000734523358131275,8.11151660748399E-5,0.25,-4.21361111189572E-6,6.70627651432318E-5,-4.17000521955142E-6,299.9988098,299.9994507,-28541.978515625,-28307.001953125,53.0639785420633,18.6907807110851,12.79435205,0,0,0,4449,299.61125,-28424.490234375,,,,,,,,,,,,,,,,,11.876877,,,,,,299.99913025,,,,
,46493760.095,300.0028687,-31619.2783203125,8.18608973025077E-5,6.68617043929647E-7,1,0.999253354069792,40.0298881530762,1.99721276117578,15.5500008817762,0.000894825900529205,0.000109421757455708,0.25,-4.18318498525608E-6,8.18609153050332E-5,-4.13000584280821E-6,300.0028687,300.0028687,-31736.9140625,-31501.642578125,52.7161538510056,18.6920693658505,12.92280625,0,0,0,4449,299.6148,-31619.2783203125,,,,,,,,,,,,,,,,,11.876877,,,,,,300.0028687,,,,
,46493778.115,300.00592045,-35159.990234375,9.49451730545716E-5,7.24467981811232E-7,1,0.999253354069792,40.0298881530762,1.99709794814546,15.5500008817762,0.00103796203814852,0.000125944131814084,0.25,-4.94041611359491E-6,9.49452430877756E-5,-4.87875504877903E-6,300.0056763,300.0061646,-35287.4765625,-35032.50390625,52.7083375658133,18.6949150474701,12.8582582,0,0,0,4449,299.60805,-35159.990234375,,,,,,,,,,,,,,,,,11.876877,,,,,,300.00592045,,,,
,46493794.855,300.01071165,-38445.904296875,0.000108332787812603,8.77786496645534E-7,1,0.999253354069792,40.0298881530762,1.99718608489429,15.5500008817762,0.00118361565453438,0.000148018186835661,0.25,-5.23924452879082E-6,0.000108332594585445,-5.16892414550793E-6,300.010437,300.0109863,-38524.23828125,-38367.5703125,52.9060895811787,18.6925178293267,12.8589001,0,0,0,4449,299.6007,-38445.904296875,,,,,,,,,,,,,,,,,11.876877,,,,,,300.01071165,,,,
,46493812.28,300.0121765,-41869.6640625,0.000123129159866346,6.84256792734991E-7,1,0.999253354069792,40.0298881530762,1.99714244807515,15.5500008817762,0.00134346100233584,0.000178480463788304,0.25,-5.00880831469312E-6,0.00012312832352032,-4.92894149587251E-6,300.0121765,300.0121765,-41879.53125,-41859.796875,52.7802473895825,18.6941851879578,12.9880023,0,0,0,4449,299.5916,-41869.6640625,,,,,,,,,,,,,,,,,12.252253,,,,,,300.0121765,,,,
,46493827.845,300.01452635,-44910.720703125,0.000135124224236898,8.0766838540343E-7,1,0.999253354069792,40.0298881530762,1.99711728367474,15.5500008817762,0.00147480784560974,0.000193077497212539,0.25,-5.7540637032626E-6,0.000135123464428468,-5.66643589589835E-6,300.0144348,300.0146179,-45018.8984375,-44802.54296875,52.6004728301594,18.695370012529,12.8582582,0,0,0,4449,299.5884,-44910.720703125,,,,,,,,,,,,,,,,,13.003003,,,,,,300.01452635,,,,
,46493845.01,300.0153809,-48274.869140625,0.000148806912224681,1.08596621851329E-6,1,0.999253354069792,40.0298881530762,1.99714965794177,15.5500008817762,0.00162439186260776,0.000211370357325161,0.25,-6.45311733963886E-6,0.000148806148674244,-6.3566463356255E-6,300.0153809,300.0153809,-48294.484375,-48255.25390625,52.9092160952556,18.6975704293806,12.8582582,0,0,0,4449,299.58185,-48274.869140625,,,,,,,,,,,,,,,,,11.876877,,,,,,300.0153809,,,,
,46493860.195,300.01774595,-51266.919921875,0.000162138451402355,1.11571944333047E-6,1,0.999253354069792,40.0298881530762,1.9971479168716,15.5500008817762,0.00176709123580204,0.000246512913839171,0.25,-5.53536746620857E-6,0.000162136641801574,-5.43033730177415E-6,300.0177002,300.0177917,-51374.703125,-51159.13671875,52.5199650926786,18.6964626602543,12.8582582,0,0,0,4449,299.57845,-51266.919921875,,,,,,,,,,,,,,,,,12.627627,,,,,,300.01774595,,,,
,46493876.67,300.0188141,-54493.875,0.000176419047039019,1.02594171125442E-6,1,0.999253354069792,40.0298881530762,1.99713280605588,15.5500008817762,0.00192370313282656,0.000262569715843918,0.25,-6.54467125920496E-6,0.000176417411951877,-6.43041279459098E-6,300.0186157,300.0190125,-54591.875,-54395.875,52.8302716148133,18.6959071208499,12.8582582,0,0,0,4449,299.57275,-54493.875,,,,,,,,,,,,,,,,,11.876877,,,,,,300.0188141,,,,
,46493892.84,300.02041625,-57662.076171875,0.00019005572040517,1.28891392158468E-6,1,0.999253354069792,40.0298881530762,1.99719829239242,15.5500008817762,0.00207026360466515,0.000295484277386808,0.25,-5.88662965061078E-6,0.000190053199660605,-5.76361917406893E-6,300.0201721,300.0206604,-57769.88671875,-57554.265625,53.0116094312748,18.6939156819283,12.9880023,0,0,0,4449,299.56445,-57662.076171875,,,,,,,,,,,,,,,,,11.876877,,,,,,300.02041625,,,,
,46493909.505,300.02204895,-60938.580078125,0.00020309583751055,1.2842619466252E-6,1,0.999253354069792,40.0298881530762,1.99716808256489,15.5500008817762,0.00221294260915367,0.000311938935410799,0.25,-6.6425651832439E-6,0.000203093363921949,-6.51115064381015E-6,300.021698,300.0223999,-61085.67578125,-60791.484375,52.9733096338325,18.6975106875888,12.8582582,0,0,0,4449,299.5591,-60938.580078125,,,,,,,,,,,,,,,,,11.876877,,,,,,300.02204895,,,,
,46493926.54,300.0227661,-64274.087890625,0.000215903557306471,1.42171839393037E-6,1,0.999253354069792,40.0298881530762,1.99713255314982,15.5500008817762,0.002352516662126,0.000331261471923827,0.25,-7.09310818245193E-6,0.000215900947431539,-6.95346735535688E-6,300.0227661,300.0227661,-64303.44140625,-64244.734375,52.6950498809863,18.698339469039,12.8582582,0,0,0,4449,299.5714,-64274.087890625,,,,,,,,,,,,,,,,,11.876877,,,,,,300.0227661,,,,
,46493942.06,300.0209503,-67325.265625,0.000229202613214676,1.60607206106485E-6,1,0.999253354069792,40.0298881530762,1.99715358219093,15.5500008817762,0.00249574656538306,0.000361433596665802,0.25,-6.62877478085861E-6,0.000229199276982495,-6.48060377432043E-6,300.0204773,300.0214233,-67443,-67207.53125,52.7474189917748,18.6946276976369,12.9880023,0,0,0,4449,299.5483,-67325.265625,,,,,,,,,,,,,,,,,12.627627,,,,,,300.0209503,,,,
,46493960,300.01687625,-70846.015625,0.000244288215266053,1.08571757909623E-6,1,0.999253354069792,40.0298881530762,1.99717787726466,15.5500008817762,0.00266152968448529,0.000376699465639337,0.25,-7.85207119054252E-6,0.000244285204016285,-7.69418916910583E-6,300.0168152,300.0169373,-70953.7734375,-70738.2578125,52.443365497794,18.6950976883362,13.1177464,0,0,0,4449,299.54655,-70846.015625,,,,,,,,,,,,,,,,,12.627627,,,,,,300.01687625,,,,
,46493976.07,300.0166016,-73994.64453125,0.000259044716985108,1.24478485286745E-6,1,0.999253354069792,40.0298881530762,1.99712962072296,15.5500008817762,0.00282216227291074,0.000399880241595163,0.25,-8.28617379574882E-6,0.000259041504831432,-8.11882371924868E-6,300.0166016,300.0166016,-74112.40625,-73876.8828125,52.7857187892171,18.6994457011539,13.05255035,0,0,0,4449,299.55115,-73994.64453125,,,,,,,,,,,,,,,,,13.003003,,,,,,300.0166016,,,,
,46493992.625,300.015152,-77251.67578125,0.000272281520887282,1.65804795431264E-6,1,0.999253354069792,40.0298881530762,1.99720807129778,15.5500008817762,0.00296557523705132,0.000425518462901341,0.25,-8.23054831658775E-6,0.000272277853229518,-8.05473269261181E-6,300.01474,300.015564,-77369.375,-77133.9765625,52.8115125303517,18.6932936510662,13.25010875,0,0,0,4449,299.5495,-77251.67578125,,,,,,,,,,,,,,,,,11.876877,,,,,,300.015152,,,,
,46494010.33,300.0185852,-80714.32421875,0.000285909248768927,2.0070959626968E-6,1,0.999253354069792,40.0298881530762,1.99722141243945,15.5500008817762,0.00311553861449371,0.000438125875749568,0.25,-9.44471991339273E-6,0.000285905888442721,-9.26015456177049E-6,300.0183411,300.0188293,-80724.171875,-80704.4765625,53.0717948272556,18.6974333816041,12.9873543,0,0,0,4449,299.54635,-80714.32421875,,,,,,,,,,,,,,,,,11.876877,,,,,,300.0185852,,,,
,46494026.01,300.02001955,-83794.328125,0.000300229599711242,1.21490236804818E-6,1,0.999253354069792,40.0298881530762,1.99718476092225,15.5500008817762,0.00327072854295065,0.000464656388126564,0.25,-9.49368190819078E-6,0.000300225788666545,-9.2999544002779E-6,300.0198059,300.0202332,-83902.3046875,-83686.3515625,53.0319317727748,18.6979643393489,13.18359665,0,0,0,4449,299.53805,-83794.328125,,,,,,,,,,,,,,,,,11.876877,,,,,,300.02001955,,,,
,46494042.25,300.02209475,-86982.29296875,0.000312703311329146,1.48823885949298E-6,1,0.999253354069792,40.0298881530762,1.99719181712484,15.5500008817762,0.00340619402329623,0.000486458934155546,0.25,-9.6576906302588E-6,0.000312699177585198,-9.4559920805424E-6,300.0218201,300.0223694,-87080.359375,-86884.2265625,52.710682451371,18.6984771119644,12.9873543,0,0,0,4449,299.5248,-86982.29296875,,,,,,,,,,,,,,,,,12.627627,,,,,,300.02209475,,,,
,46494060.145,300.02297975,-89999.65625,0.000325079241916249,1.22364543156112E-6,1,0.999253354069792,40.0298881530762,1.99717253439896,15.5500008817762,0.00354255825611072,0.000496600729067791,0.25,-1.08803437121453E-5,0.000325075482005122,-1.0670715540729E-5,300.0223999,300.0235596,-89999.6875,-89999.625,52.8740428118902,18.6995308628191,13.05255035,0,0,0,4417,299.5256,-89999.65625,,,,,,,,,,,,,,,,,11.876877,,,,,,300.02297975,,,,
,46494090.54,300.02583315,-86916.03125,0.000313931515729249,1.23346181759601E-6,1,0.999253354069792,40.0298881530762,1.99717212886489,15.5500008817762,0.00341966194187043,0.000487668031447706,0.25,-9.75995801320051E-6,0.000313927369137014,-9.55745933599925E-6,300.0255127,300.0261536,-87032.9453125,-86799.1171875,52.8498123277941,18.6971175754112,12.92280625,0,0,0,4449,299.5211,-86916.03125,,,,,,,,,,,,,,,,,11.876877,,,,,,300.02583315,,,,
,46494105.945,300.02407835,-83908.7421875,0.000301477782290031,1.28710418430487E-6,1,0.999253354069792,40.0298881530762,1.99720382281384,15.5500008817762,0.00328230560878375,0.000478341285757736,0.25,-8.44875631783947E-6,0.000301473216103287,-8.25423917755313E-6,300.0239868,300.0241699,-84025.96875,-83791.515625,52.3542598466017,18.6995267178183,13.05255035,0,0,0,4449,299.50945,-83908.7421875,,,,,,,,,,,,,,,,,12.627627,,,,,,300.02407835,,,,
,46494122.185,300.0210571,-80735.57421875,0.000286674475128821,1.3682565212836E-6,1,0.999253354069792,40.0298881530762,1.99718447603252,15.5500008817762,0.00312263877195469,0.000446075655543228,0.25,-8.84379020992267E-6,0.000286670677477674,-8.65872230093962E-6,300.0207214,300.0213928,-80862.515625,-80608.6328125,52.6966131380248,18.6979508583474,13.18359665,0,0,0,4449,299.5063,-80735.57421875,,,,,,,,,,,,,,,,,12.627627,,,,,,300.0210571,,,,
,46494138.1,300.0165863,-77620.6328125,0.00027284346962589,1.40165946097154E-6,1,0.999253354069792,40.0298881530762,1.99713908840411,15.5500008817762,0.00297065511794446,0.000431791889466349,0.25,-7.74828843256935E-6,0.000272839458317673,-7.57210353280665E-6,300.0160828,300.0170898,-77718.171875,-77523.09375,52.717717108044,18.6984240461269,13.1184006,0,0,0,4449,299.50525,-77620.6328125,,,,,,,,,,,,,,,,,12.627627,,,,,,300.0165863,,,,
,46494154.605,300.0126343,-74408.05859375,0.000259689302021099,1.23393015265466E-6,1,0.999253354069792,40.0298881530762,1.99717913841709,15.5500008817762,0.00282734399396288,0.00041181583190125,0.25,-7.29787300283512E-6,0.000259685462782856,-7.13012036776916E-6,300.0122986,300.01297,-74515.28125,-74300.8359375,52.7536720199287,18.6971036774515,13.1184006,0,0,0,4449,299.50725,-74408.05859375,,,,,,,,,,,,,,,,,11.876877,,,,,,300.0126343,,,,
,46494170.945,300.00849915,-71215.3984375,0.000246471904312994,1.45731436563047E-6,1,0.999253354069792,40.0298881530762,1.99713848755699,15.5500008817762,0.00268607427937022,0.000375460654047003,0.25,-8.346784518282E-6,0.000246469205392277,-8.18746394860652E-6,300.0082092,300.0087891,-71313.0234375,-71117.7734375,52.8482490707556,18.6979677296511,12.9873543,0,0,0,4449,299.51045,-71215.3984375,,,,,,,,,,,,,,,,,12.627627,,,,,,300.00849915,,,,
,46494189.775,300.0048218,-67544.484375,0.000230970507563302,1.53772769565335E-6,1,0.999253354069792,40.0298881530762,1.99716159723128,15.5500008817762,0.00251630495595128,0.000356787395530531,0.25,-7.3662285210866E-6,0.000230967707157464,-7.21687822526922E-6,300.0048218,300.0048218,-67563.9609375,-67525.0078125,52.9326649508325,18.6964381575273,13.2494469,0,0,0,4449,299.512,-67544.484375,,,,,,,,,,,,,,,,,12.627627,,,,,,300.0048218,,,,
,46494206.1,300.00097655,-64351.171875,0.000217145963294147,1.31114416737457E-6,1,0.999253354069792,40.0298881530762,1.99716515623801,15.5500008817762,0.00236624962898905,0.000332270394663398,0.25,-7.21726893379219E-6,0.000217143542386518,-7.07679859189375E-6,300.0009155,300.0010376,-64458.55859375,-64243.78515625,52.6481521698325,18.6967718725467,13.1184006,0,0,0,4449,299.5181,-64351.171875,,,,,,,,,,,,,,,,,11.876877,,,,,,300.00097655,,,,
,46494223.245,299.995697,-60986.88671875,0.000203269019366257,1.51671922433894E-6,1,0.999253354069792,40.0298881530762,1.9972441386379,15.5500008817762,0.00221361126393398,0.000319665705007711,0.25,-5.96070527177475E-6,0.00020326627010569,-5.82918403809513E-6,299.995697,299.995697,-60996.66796875,-60977.10546875,52.842777671121,18.6944309957595,13.2494469,0,0,0,4449,299.5142,-60986.88671875,,,,,,,,,,,,,,,,,11.876877,,,,,,299.995697,,,,
,46494240.115,299.99333195,-57688.443359375,0.000189042947353887,1.17031541758038E-6,1,0.999253354069792,40.0298881530762,1.99718066603863,15.5500008817762,0.00205974724981538,0.000290863707269992,0.25,-6.13621699438299E-6,0.000189040785106669,-6.01384248682285E-6,299.9933167,299.9933472,-57805.6484375,-57571.23828125,52.8310532433325,18.694853991312,13.1184006,0,0,0,4449,299.53165,-57688.443359375,,,,,,,,,,,,,,,,,12.627627,,,,,,299.99333195,,,,
,46494256.875,299.9927063,-54410.095703125,0.000174972977036677,1.09523464231907E-6,1,0.999253354069792,40.0298881530762,1.99714952042699,15.5500008817762,0.00190779515422689,0.000261316313769076,0.25,-6.40829168484674E-6,0.000174971447499199,-6.29495918872635E-6,299.9921265,299.9932861,-54517.7578125,-54302.43359375,52.812294158871,18.6940912609224,13.1184006,0,0,0,4449,299.5335,-54410.095703125,,,,,,,,,,,,,,,,,12.627627,,,,,,299.9927063,,,,
,46494273.5,299.99284365,-51151.31640625,0.000161878824113922,1.00932044105993E-6,1,0.999253354069792,40.0298881530762,1.99708731801824,15.5500008817762,0.0017652678767201,0.000240062909523718,0.25,-6.08481586958195E-6,0.000161877506683406,-5.97991924180545E-6,299.9923401,299.9933472,-51249.01953125,-51053.61328125,53.0084829171979,18.6950381037995,13.1184006,0,0,0,4449,299.5313,-51151.31640625,,,,,,,,,,,,,,,,,11.876877,,,,,,299.99284365,,,,
,46494290.105,299.98963925,-47911.76953125,0.000147612565100231,1.09633847555558E-6,1,0.999253354069792,40.0298881530762,1.99708963462791,15.5500008817762,0.00161195948113689,0.000205945112748093,0.25,-6.74498969592969E-6,0.000147612150908183,-6.64926532978687E-6,299.9894714,299.9898071,-48019.390625,-47804.1484375,52.9905054612556,18.69538389256,13.2494469,0,0,0,4449,299.53465,-47911.76953125,,,,,,,,,,,,,,,,,11.876877,,,,,,299.98963925,,,,
,46494306.725,299.98556515,-44652.533203125,0.000133722296771859,1.10991138424076E-6,1,0.999253354069792,40.0298881530762,1.99708237014222,15.5500008817762,0.00146032454600215,0.000186252931101726,0.25,-6.1391392196353E-6,0.000133721956102003,-6.05239280148479E-6,299.9852905,299.9858398,-44770.0859375,-44534.98046875,52.6379909990825,18.6960483626641,12.9873543,0,0,0,4449,299.54125,-44652.533203125,,,,,,,,,,,,,,,,,11.876877,,,,,,299.98556515,,,,
,46494322.96,299.9853668,-41472.044921875,0.000119918275478956,1.01216645751264E-6,1,0.999253354069792,40.0298881530762,1.99714149014798,15.5500008817762,0.00131032188927536,0.00016296906555933,0.25,-5.88033847879922E-6,0.000119918212047693,-5.8025086272228E-6,299.984436,299.9862976,-41579.8359375,-41364.25390625,52.8412144140825,18.6944454141435,13.1184006,0,0,0,4449,299.54555,-41472.044921875,,,,,,,,,,,,,,,,,12.627627,,,,,,299.9853668,,,,
,46494338.755,299.9828491,-38379.05859375,0.000108268030416596,7.89574910856164E-7,1,0.999253354069792,40.0298881530762,1.99707269245056,15.5500008817762,0.00118270482818407,0.000148730390528483,0.25,-5.16150136849178E-6,0.000108267885221876,-5.09121638675369E-6,299.9826355,299.9830627,-38506.1953125,-38251.921875,52.6333012279671,18.6944489459639,13.1184006,0,0,0,4449,299.5533,-38379.05859375,,,,,,,,,,,,,,,,,11.876877,,,,,,299.9828491,,,,
,46494354.115,299.98141475,-35374.88671875,9.49132013584264E-5,7.24070077944564E-7,1,0.999253354069792,40.0298881530762,1.99704576759844,15.5500008817762,0.00103624200577924,0.000133612017041024,0.25,-4.22678484039952E-6,9.49128843525958E-5,-4.16516041284882E-6,299.9808044,299.9820251,-35472.70703125,-35277.06640625,52.8459041851979,18.6916322866762,13.315959,0,0,0,4449,299.55755,-35374.88671875,,,,,,,,,,,,,,,,,12.627627,,,,,,299.98141475,,,,
,46494370.445,299.97872925,-32184.654296875,8.29170521220115E-5,7.29310524109997E-7,1,0.999253354069792,40.0298881530762,1.9970835565737,15.5600009579211,0.000907232722040635,0.000105573897676736,0.25,-4.7220276928788E-6,8.29174485338517E-5,-4.66814268329336E-6,299.9782715,299.979187,-32302.140625,-32067.16796875,52.8568469844671,18.6973438878203,13.2520919,0,0,0,4449,299.56495,-32184.654296875,,,,,,,,,,,,,,,,,11.876877,,,,,,299.97872925,,,,
,46494385.795,299.9792633,-29179.6318359375,6.92317733661556E-5,6.90627897959573E-7,1,0.999253354069792,40.0298881530762,1.99702169352062,15.5500008817762,0.000759589709728617,7.60192636552712E-5,0.25,-5.06210952162213E-6,6.92328282220897E-5,-5.01706857352595E-6,299.9788208,299.9797058,-29267.70703125,-29091.556640625,53.2351551877748,18.6946064519286,13.2494469,0,0,0,4449,299.5681,-29179.6318359375,,,,,,,,,,,,,,,,,11.876877,,,,,,299.9792633,,,,
,46494402.335,299.9777069,-25940.041015625,5.61119756048576E-5,5.50545507262756E-7,1,0.999253354069792,40.0298881530762,1.99705981943184,15.5500008817762,0.000615760394189615,6.1006989768643E-5,0.25,-4.15888091891729E-6,5.61128694373601E-5,-4.12236377990647E-6,299.9774475,299.9779663,-26057.5078125,-25822.57421875,52.8490306992748,18.6962384189734,13.2494469,0,0,0,4449,299.58145,-25940.041015625,,,,,,,,,,,,,,,,,11.876877,,,,,,299.9777069,,,,
,46494417.995,299.97685245,-22866.9697265625,4.49709440342727E-5,4.96215143198483E-7,1,0.999253354069792,40.0298881530762,1.99706728511136,15.5500008817762,0.000494519865695453,4.30656770054403E-5,0.25,-3.87114501132235E-6,4.49720103428938E-5,-3.84185212395992E-6,299.9763489,299.977356,-22984.427734375,-22749.51171875,52.9053079526594,18.6967219743033,13.3824711,0,0,0,4449,299.58055,-22866.9697265625,,,,,,,,,,,,,,,,,12.627627,,,,,,299.97685245,,,,
,46494434.1,299.97602845,-19715.3271484375,3.02887757553786E-5,5.50044229102356E-7,1,0.999253354069792,40.0298881530762,1.99706204465681,15.5500008817762,0.000335259650810724,1.64418049570139E-5,0.25,-3.76697929442158E-6,3.02902470513252E-5,-3.74720705926891E-6,299.9753113,299.9767456,-19832.701171875,-19597.953125,52.9365730934287,18.6935034346891,13.1184006,0,0,0,4449,299.5839,-19715.3271484375,,,,,,,,,,,,,,,,,12.252253,,,,,,299.97602845,,,,
,46494450.025,299.9738922,-16603.013671875,1.77694438916176E-5,4.06437905436338E-7,1,0.999253354069792,40.0298881530762,1.99709971225143,15.5500008817762,0.000199191079307841,-4.69174277454836E-6,0.25,-3.53338854686781E-6,1.77711671866004E-5,-3.52174361916785E-6,299.9738464,299.973938,-16720.494140625,-16485.533203125,52.9662749771594,18.6934320441028,13.25010875,0,0,0,4449,299.59415,-16603.013671875,,,,,,,,,,,,,,,,,11.876877,,,,,,299.9738922,,,,
,46494466.77,299.9738159,-13322.611328125,5.22472508169117E-6,3.86012499764536E-7,1,0.999253354069792,40.0298881530762,1.99718802273194,15.5500008817762,6.1239176863011E-5,-1.66760279931527E-5,0.25,-2.45076907970209E-6,5.22614842137172E-6,-2.44729874993424E-6,299.9737854,299.9738464,-13430.365234375,-13214.857421875,52.5809321171786,18.6932156742472,13.1849127,0,0,0,4449,299.5884,-13322.611328125,,,,,,,,,,,,,,,,,12.627627,,,,,,299.9738159,,,,
,46494482.62,299.97496035,-10218.259765625,-5.88181378881958E-6,6.44547941467707E-7,1,0.999253354069792,40.0298881530762,1.99710480672204,15.5600009579211,-5.89755373605003E-5,-3.83282470698675E-5,0.25,-2.511571346363E-6,-5.87999406259894E-6,-2.51530965839784E-6,299.974762,299.9751587,-10335.8076171875,-10100.7119140625,52.6309563424094,18.6910574390381,13.315959,0,0,0,4449,299.6063,-10218.259765625,,,,,,,,,,,,,,,,,13.003003,,,,,,299.97496035,,,,
,46494498.515,299.97703555,-7093.3525390625,-1.82419907769173E-5,4.53175282273819E-7,1,0.999253354069792,40.0298881530762,1.997082759797,15.5500008817762,-0.000193409498723335,-5.86712796656137E-5,0.25,-2.23279582585143E-6,-1.82399530987604E-5,-2.24457096181563E-6,299.9767151,299.977356,-7181.33544921875,-7005.36962890625,52.7442924776979,18.6923040329266,13.2520919,0,0,0,4449,299.6123,-7093.3525390625,,,,,,,,,,,,,,,,,13.003003,,,,,,299.97703555,,,,
,46494513.865,299.9799652,-4095.27087402344,-2.70241079207958E-5,4.29544414411287E-7,1,0.999253354069792,40.0298881530762,1.99706612420929,15.5500008817762,-0.000288072026517537,-7.80153594757348E-5,0.25,-2.48611451344742E-6,-2.70216194877699E-5,-2.5035888162733E-6,299.9798584,299.980072,-4222.4462890625,-3968.09545898438,52.9576770634479,18.6951084605976,13.05255035,0,0,0,4449,299.6083,-4095.27087402344,,,,,,,,,,,,,,,,,12.252253,,,,,,299.9799652,,,,
,46494529.215,299.9809875,-1084.5885925293,-2.74778770533464E-5,3.58093862145364E-7,1,0.999253354069792,40.0298881530762,1.99703260841841,15.5500008817762,-0.000293597016908555,-7.53547987226744E-5,0.25,-2.16146848699565E-6,-2.74755834055852E-5,-2.17925090605442E-6,299.9809875,299.9809875,-1182.80798339844,-986.369201660156,52.9006181815441,18.6924586700964,13.25010875,0,0,0,4449,299.61415,-1084.5885925293,,,,,,,,,,,,,,,,,12.627627,,,,,,299.9809875,,,,
,46494544.745,299.9812622,1949.4375,2.91629422068629E-5,4.14911556312982E-7,1,0.999253354069792,40.0298881530762,1.99702847316415,15.5500008817762,0.000321056095891744,2.57847604929493E-5,0.25,-2.70813977460093E-6,2.9163757548262E-5,-2.68910500123612E-6,299.9807434,299.981781,1842.73071289062,2056.14428710938,52.852938841871,18.6926522627857,13.3824711,0,0,0,4449,299.6026,1949.4375,,,,,,,,,,,,,,,,,11.876877,,,,,,299.9812622,,,,
# ,46494560.275,299.978714,4996.48120117188,2.45830082477112E-5,4.25435109327072E-7,1,0.999253354069792,40.0298881530762,1.99704644708291,15.5500008817762,0.000270482579198749,2.26247406189042E-5,0.25,-2.20075514712588E-6,2.45836442710162E-5,-2.1847160734294E-6,299.9780579,299.9793701,4898.45361328125,5094.5087890625,52.5715525749479,18.6928424603211,13.31728795,0,0,0,4449,299.60645,4996.48120117188,,,,,,,,,,,,,,,,,11.876877,,,,,,299.978714,,,,
# ,46494576.705,299.97705075,8211.8818359375,1.52804298029564E-5,3.88133733340746E-7,1,0.999253354069792,40.0298881530762,1.99703198041423,15.5500008817762,0.000169241536152291,7.67393646203605E-6,0.25,-1.95771183450521E-6,1.5281208964878E-5,-1.94772619861283E-6,299.9769897,299.9771118,8113.8564453125,8309.9072265625,52.5785872316209,18.6956493643616,13.25010875,0,0,0,4449,299.6186,8211.8818359375,,,,,,,,,,,,,,,,,13.003003,,,,,,299.97705075,,,,
# ,46494592.22,299.97993465,11250.861328125,3.40415480184103E-6,3.52481016738542E-7,1,0.999253354069792,40.0298881530762,1.99701966291115,15.5500008817762,3.91885154085049E-5,-6.80350184631787E-6,0.25,-1.22194866762246E-6,3.40483817536685E-6,-1.21969934908495E-6,299.9797668,299.9801025,11152.9033203125,11348.8193359375,52.9013998100633,18.6916383459451,13.1177464,0,0,0,4449,299.6314,11250.861328125,,,,,,,,,,,,,,,,,12.252253,,,,,,299.97993465,,,,
# ,46494609.04,299.98291015,14553.3393554687,-9.46729876707616E-6,4.36956669550938E-7,1,0.999253354069792,40.0298881530762,1.99703794134334,15.5500008817762,-9.98806961308475E-5,-3.32777392342221E-5,0.25,-1.41991645409232E-6,-9.46607092154696E-6,-1.42601475911219E-6,299.9825134,299.9833069,14426.0078125,14680.6708984375,52.9076528382171,18.692089170321,13.1177464,0,0,0,4449,299.6262,14553.3393554687,,,,,,,,,,,,,,,,,11.876877,,,,,,299.98291015,,,,
# ,46494624.785,299.9851532,17640.1552734375,-2.10960109981736E-5,5.39913428684896E-7,1,0.999253354069792,40.0298881530762,1.99703331442454,15.5500008817762,-0.000225499350228387,-5.73286585908996E-5,0.25,-1.61104736100526E-6,-2.10942820202026E-5,-1.62468251399318E-6,299.9848328,299.9854736,17522.494140625,17757.81640625,52.7849371606979,18.6937137329444,13.25010875,0,0,0,4449,299.6268,17640.1552734375,,,,,,,,,,,,,,,,,11.876877,,,,,,299.9851532,,,,
# ,46494640.835,299.98835755,20785.177734375,-3.28647626998545E-5,4.37298877842371E-7,1,0.999253354069792,40.0298881530762,1.99702180537542,15.5500008817762,-0.000356202932471248,-6.11852188322393E-5,0.25,8.62848973122612E-8,-3.28637508037259E-5,6.49654133724756E-8,299.9883423,299.9883728,20677.435546875,20892.919921875,52.5598281471594,18.6943598395679,13.25010875,0,0,0,4449,299.62775,20785.177734375,,,,,,,,,,,,,,,,,11.876877,,,,,,299.98835755,,,,
# ,46494656.41,299.98886105,23833.013671875,-4.5553312477794E-5,6.52563543972898E-7,1,0.999253354069792,40.0298881530762,1.99699761782006,15.5500008817762,-0.000492718787473926,-9.05536211258099E-5,0.25,-4.10878789984711E-7,-4.5551566043505E-5,-4.40403531870654E-7,299.9888,299.9889221,23735.080078125,23930.947265625,52.7325680499094,18.6916898507903,13.3824711,0,0,0,4449,299.6266,23833.013671875,,,,,,,,,,,,,,,,,12.627627,,,,,,299.98886105,,,,
# ,46494672.355,299.9943237,26958.833984375,-5.95251374548713E-5,6.42270784972507E-7,1,0.999253354069792,40.0298881530762,1.99698122973969,15.5500008817762,-0.000645689440440449,-0.000107711243999598,0.25,4.42982778209007E-7,-5.95234814341961E-5,4.04382555301228E-7,299.9941406,299.9945068,26831.25390625,27086.4140625,53.1718432777172,18.6928400667472,13.25010875,0,0,0,4449,299.62685,26958.833984375,,,,,,,,,,,,,,,,,12.252253,,,,,,299.9943237,,,,
# ,46494688.645,299.99658205,30153.1376953125,-7.11679943846045E-5,7.41465906285948E-7,1,0.999253354069792,40.0298881530762,1.99709451000195,15.5500008817762,-0.000769355759310146,-0.00014408306022281,0.25,-8.82356951371568E-7,-7.1165095596749E-5,-9.28447065876453E-7,299.9959412,299.9972229,30045.169921875,30261.10546875,52.7646148191979,18.6892023138961,13.1177464,0,0,0,4449,299.6212,30153.1376953125,,,,,,,,,,,,,,,,,13.003003,,,,,,299.99658205,,,,
# ,46494704.82,299.999115,33330.21875,-8.42799875861144E-5,7.07066536157569E-7,1,0.999253354069792,40.0298881530762,1.99704597210338,15.5500008817762,-0.000914475450746192,-0.000151169439065555,0.25,7.50915791044396E-7,-8.42777130521961E-5,6.96290735137284E-7,299.9989929,299.9992371,33222.5234375,33437.9140625,52.741165963621,18.6925780811845,13.3824711,0,0,0,4449,299.6091,33330.21875,,,,,,,,,,,,,,,,,11.876877,,,,,,299.999115,,,,
# ,46494719.915,300.002655,36292.4921875,-9.7172331166985E-5,8.46657595741555E-7,1,0.999253354069792,40.0298881530762,1.99698497923966,15.5500008817762,-0.00105506657650526,-0.00017008251232441,0.25,1.2540405831411E-6,-9.71699511551307E-5,1.1910690873664E-6,300.0023193,300.0029907,36184.57421875,36400.41015625,52.9459526356594,18.6922295662507,13.25010875,0,0,0,4449,299.6197,36292.4921875,,,,,,,,,,,,,,,,,11.876877,,,,,,300.002655,,,,
# ,46494736.305,300.0066223,39499.916015625,-0.000110617710180017,8.25108149819008E-7,1,0.999253354069792,40.0298881530762,1.99702076626461,15.5500008817762,-0.00120026653418027,-0.000198238439940643,0.25,1.00117066225922E-6,-0.000110614712890168,9.2952457417699E-7,300.0064392,300.0068054,39382.19140625,39617.640625,52.5910932879286,18.693866237887,13.25010875,0,0,0,4449,299.6192,39499.916015625,,,,,,,,,,,,,,,,,11.876877,,,,,,300.0066223,,,,
# ,46494752.605,300.0117645,42698.400390625,-0.000123207005258214,9.50674040466133E-7,1,0.999253354069792,40.0298881530762,1.99702134205467,15.5500008817762,-0.00133790961135324,-0.000214829071781452,0.25,1.66622448741766E-6,-0.000123204005442454,1.58643073434407E-6,300.0108337,300.0126953,42580.59375,42816.20703125,52.8232369581402,18.691044348536,13.3824711,0,0,0,4449,299.60885,42698.400390625,,,,,,,,,,,,,,,,,11.876877,,,,,,300.0117645,,,,
# ,46494768.58,300.01576235,45837.974609375,-0.000136531621291878,6.48338885616314E-7,1,0.999253354069792,40.0298881530762,1.99698962160239,15.5500008817762,-0.00148243951115348,-0.000238862769298703,0.25,1.77218658991608E-6,-0.000136528234102996,1.68379544475439E-6,300.0157166,300.0158081,45720.28125,45955.66796875,52.7794657610633,18.6912998852855,13.25010875,0,0,0,4449,299.6061,45837.974609375,,,,,,,,,,,,,,,,,12.252253,,,,,,300.01576235,,,,
# ,46494784.13,300.0166168,48888.615234375,-0.000149104440392379,1.23333536241773E-6,1,0.999253354069792,40.0298881530762,1.99699907818411,15.5500008817762,-0.00161930326597662,-0.000258895381508622,0.25,2.1167183223555E-6,-0.000149100856777948,2.02020745428359E-6,300.0163269,300.0169067,48780.6484375,48996.58203125,53.0217706020248,18.6900526896283,13.31728795,0,0,0,4449,299.5873,48888.615234375,,,,,,,,,,,,,,,,,11.876877,,,,,,300.0166168,,,,
# ,46494800.14,300.0172577,52027.998046875,-0.00016392652560321,1.26364329778747E-6,1,0.999253354069792,40.0298881530762,1.99706607924994,15.5500008817762,-0.00177911920091757,-0.000291581929336415,0.25,1.68637452025377E-6,-0.000163922171193578,1.58032689689196E-6,300.0170593,300.0174561,51920.10546875,52135.890625,53.0553806283518,18.6889149979508,13.25010875,0,0,0,4449,299.58225,52027.998046875,,,,,,,,,,,,,,,,,11.876877,,,,,,300.0172577,,,,
# ,46494816.685,300.0172119,55284.83984375,-0.000175821726739264,1.06757468914373E-6,1,0.999253354069792,40.0298881530762,1.99698844496904,15.5500008817762,-0.00191127873426037,-0.000294794838932432,0.25,3.46415609475055E-6,-0.000175818130551012,3.35040222522415E-6,300.0172119,300.0172119,55275.01953125,55294.66015625,52.9709647482748,18.6900367425767,13.31728795,0,0,0,4449,299.5849,55284.83984375,,,,,,,,,,,,,,,,,12.627627,,,,,,300.0172119,,,,
# ,46494832.645,300.01594545,58404.876953125,-0.0001885948013034,1.29240138671841E-6,1,0.999253354069792,40.0298881530762,1.99699591105103,15.5500008817762,-0.00204794392523837,-0.000328778595817234,0.25,2.55580372609814E-6,-0.000188590205428538,2.43386611510504E-6,300.015564,300.0163269,58316.60546875,58493.1484375,52.3698924169863,18.6883431115687,13.25010875,0,0,0,4449,299.57905,58404.876953125,,,,,,,,,,,,,,,,,12.627627,,,,,,300.01594545,,,,
# ,46494848.065,300.01820375,61436.04296875,-0.000202113365508026,1.17602711857987E-6,1,0.999253354069792,40.0298881530762,1.99703662762745,15.5500008817762,-0.00219436903897668,-0.000354728286151309,0.25,2.51964411488545E-6,-0.000202108288094593,2.38902154629501E-6,300.018158,300.0182495,61337.8671875,61534.21875,52.7122457084094,18.6877511984713,13.25010875,0,0,0,4449,299.5825,61436.04296875,,,,,,,,,,,,,,,,,13.003003,,,,,,300.01820375,,,,
# ,46494864.025,300.02226255,64556.03515625,-0.000215265383834284,1.7191077755111E-6,1,0.999253354069792,40.0298881530762,1.99710080820759,15.5500008817762,-0.00233627795621214,-0.000383294428849444,0.25,2.17850275864281E-6,-0.000215259626020108,2.03944414589286E-6,300.0221252,300.0223999,64457.88671875,64654.18359375,52.9983217464479,18.6893415696941,13.25010875,0,0,0,4449,299.57465,64556.03515625,,,,,,,,,,,,,,,,,12.627627,,,,,,300.02226255,,,,
# ,46494880.365,300.02449035,67773.90625,-0.00022938097576477,9.55978175292651E-7,1,0.999253354069792,40.0298881530762,1.99698153839289,15.5500008817762,-0.00249171192869171,-0.000394778146114616,0.25,3.57918883221146E-6,-0.00022937564047856,3.4310210182725E-6,300.024292,300.0246887,67656.234375,67891.578125,52.7044294232171,18.6909558954321,13.3824711,0,0,0,4449,299.5644,67773.90625,,,,,,,,,,,,,,,,,11.876877,,,,,,300.02449035,,,,
# ,46494896.885,300.0269165,71011.046875,-0.000241377258114756,1.67011049840682E-6,1,0.999253354069792,40.0298881530762,1.9970047520953,15.5500008817762,-0.00262287191828803,-0.000410737057620145,0.25,4.19941934613819E-6,-0.00024137190898709,4.04354181591543E-6,300.0262756,300.0275574,70893.171875,71128.921875,52.7427292206594,18.6896907176948,13.1177464,0,0,0,4449,299.5525,71011.046875,,,,,,,,,,,,,,,,,13.003003,,,,,,300.0269165,,,,
# ,46494913.91,300.0262451,74356.05078125,-0.00025533602641411,1.90759236559282E-6,1,0.999253354069792,40.0298881530762,1.99700523870431,15.5500008817762,-0.0027747136857633,-0.000433566116240104,0.25,4.52748650301982E-6,-0.000255330433589655,4.36265379857438E-6,300.0262451,300.0262451,74346.25,74365.8515625,52.8974916674671,18.6877146128776,13.2494469,0,0,0,4449,299.5438,74356.05078125,,,,,,,,,,,,,,,,,13.003003,,,,,,300.0262451,,,,
# ,46494930.08,300.02552795,77534.84375,-0.000269277424109711,1.6681532336282E-6,1,0.999253354069792,40.0298881530762,1.99700735600995,15.5500008817762,-0.00292578653894777,-0.000459704648885939,0.25,4.54706068470824E-6,-0.000269271390910854,4.37330244427241E-6,300.0253296,300.0257263,77427.0234375,77642.6640625,52.8138574159094,18.6875099269026,13.3831382,0,0,0,4449,299.5415,77534.84375,,,,,,,,,,,,,,,,,13.378378,,,,,,300.02552795,,,,
# ,46494946.335,300.02526855,80723.359375,-0.000283170272209301,1.62063289474746E-6,1,0.999253354069792,40.0298881530762,1.99695857668466,15.5500008817762,-0.00307815258015974,-0.000474891096547642,0.25,5.56806907766973E-6,-0.000283164442264412,5.38538349569764E-6,300.0250854,300.0254517,80605.4609375,80841.2578125,52.6387726276017,18.6873965790701,13.25010875,0,0,0,4449,299.5289,80723.359375,,,,,,,,,,,,,,,,,13.003003,,,,,,300.02526855,,,,
# ,46494962.815,300.02583315,83950.4609375,-0.000297616617549621,1.85339494231949E-6,1,0.999253354069792,40.0298881530762,1.99697889234701,15.5500008817762,-0.00323484926441411,-0.000501248452650031,0.25,5.65586696920282E-6,-0.000297610365007539,5.46394999850028E-6,300.0256348,300.0260315,83842.5390625,84058.3828125,52.6778540535633,18.6896961796646,13.31728795,0,0,0,4449,299.5348,83950.4609375,,,,,,,,,,,,,,,,,11.876877,,,,,,300.02583315,,,,
# ,46494978.355,300.0283966,87001.36328125,-0.000310566226863759,1.86008009129527E-6,1,0.999253354069792,40.0298881530762,1.99699669820882,15.5500008817762,-0.00337291790782498,-0.000538602149516484,0.25,4.46747395356935E-6,-0.000310558758949278,4.26732775641089E-6,300.0274353,300.0293579,86863.7890625,87138.9375,52.4996427511786,18.6863496553812,13.315959,0,0,0,4449,299.5307,87001.36328125,,,,,,,,,,,,,,,,,12.252253,,,,,,300.0283966,,,,
# ,46494994.655,300.0306396,89999.5546875,-0.000323310732933742,2.2781643739198E-6,1,0.999253354069792,40.0298881530762,1.99698750884583,15.5500008817762,-0.00351482711072135,-0.000540570324525558,0.25,6.50904242741353E-6,-0.000323304137517992,6.30069012179715E-6,300.0306396,300.0306396,89999.5546875,89999.5546875,52.8365246429671,18.6903202381012,13.5168295,0,0,0,4417,299.5185,89999.5546875,,,,,,,,,,,,,,,,,12.627627,,,,,,300.0306396,,,,