File: data/looselyPackedNP/nanoparticles/vsm/ios-11/rawdata/PMK18_HYST_300K.DAT
[Header]
; VSM Data File (default extension .dat)
; Copyright (c) 2003-2013, Quantum Design, Inc. All rights reserved.
TITLE,
FILEOPENTIME,28741373.25,11/29/2018,11:43 pm
BYAPP,VSM,2.0,2.0
INFO,PPMS VSM Option Release 1.4.10 Build 1,APPNAME
INFO,Quantum Design Linear Motor Servo Controller,MOTOR_MODULE_NAME
INFO,3101-100 M1,MOTOR_HW_VERSION
INFO,MMC1014,MOTOR_SERIAL_NUMBER
INFO,SRV No X-over 01.03.11,MOTOR_SOFTWARE_VERSION
INFO,Quantum Design VSM Detection Module,VSM_MODULE_NAME
INFO,3101-150 F0,VSM_HW_VERSION
INFO,VSM707,VSM_SERIAL_NUMBER
INFO,VSM No X-over 01.02.05 May 20 2008 13:51:47,VSM_SOFTWARE_VERSION
INFO,704,PREAMP_SERIAL_NUMBER
INFO,822,COIL_SERIAL_NUMBER
INFO,0,MOMENT_UNITS
INFO,Maghemite,SAMPLE_MATERIAL
INFO,Oleate Iron Spheres,SAMPLE_COMMENT
INFO,,SAMPLE_MASS
INFO,,SAMPLE_VOLUME
INFO,,SAMPLE_MOLECULAR_WEIGHT
INFO,,SAMPLE_SIZE
INFO,,SAMPLE_SHAPE
DATATYPE,COMMENT,1
DATATYPE,TIME,2
STARTUPAXIS,X,2
STARTUPAXIS,Y1,5
[Data]
Comment,Time Stamp (sec),Temperature (K),Magnetic Field (Oe),Moment (emu),M. Std. Err. (emu),Transport Action,Averaging Time (sec),Frequency (Hz),Peak Amplitude (mm),Center Position (mm),Coil Signal' (mV),Coil Signal" (mV),Range (mV),M. Quad. Signal (emu),M. Raw' (emu),M. Raw" (emu),Min. Temperature (K),Max. Temperature (K),Min. Field (Oe),Max. Field (Oe),Mass (grams),Motor Lag (deg),Pressure (Torr),VSM Status (code),Motor Status (code),Measure Status (code),Measure Count,PPMS Status (code),System Temp. (K),System Field (Oe),Sample Position (deg),Bridge 1 Resistance (ohms),Bridge 1 Excitation (에),Bridge 2 Resistance (ohms),Bridge 2 Excitation (에),Bridge 3 Resistance (ohms),Bridge 3 Excitation (에),Bridge 4 Resistance (ohms),Bridge 4 Excitation (에),Signal 1 Vin (V),Signal 2 Vin (V),Digital Inputs (code),Drive 1 Iout (mA),Drive 1 Ipower (W),Drive 2 Iout (mA),Drive 2 Ipower (W),Pressure (),Map 20 (),Map 21 (),Map 22 (),Map 23 (),Map 24 (),Map 25 (),Map 26 (),Map 27 (),Map 28 (),Map 29 ()
,28741389.81,300.196991,-0.487160742282867,,,2,,,,28.3200001680851,,,,,,,300.196991,300.196991,-0.487160742282867,-0.487160742282867,,,22.529354,,,,-99999999,4369,300.5351,-0.487160742282867,,,,,,,,,,,,,,,,,,,,,,,300.196991,,,,
,28741532.845,300.1652222,4443.61303710937,0.00901748590286613,8.43608257388974E-5,1,0.999253354069792,40.0298881530762,2.00264225764531,28.3100008964539,0.092992140166211,0.0711848292856379,2.5,0.00471509881452777,0.00901403819745151,0.00472090782660887,300.1652222,300.1652222,4441.10693359375,4446.119140625,57.5583425276407,20.5831135635554,22.909004,0,0,0,40,4449,300.3044,4443.61303710937,,,,,,,,,,,,,0,,,,0.00245,,,,,,300.1652222,,,,
,28741626.055,300.1136475,9101.81640625,0.00944586465506915,8.09859161720423E-5,1,0.999253354069792,40.0298881530762,2.00258931587909,28.3100008964539,0.0972806119559137,0.0752971584241688,2.5,0.00500368333130725,0.00944222972639826,0.00500977237931227,300.1136475,300.1136475,9091.5224609375,9112.1103515625,57.5927341824868,20.5925048208445,23.288654,0,0,0,40,4449,300.23905,9101.81640625,,,,,,,,,,,,,0,,,,0.00245,,,,,,300.1136475,,,,
,28741719.745,300.0704651,13784.5327148438,0.00965732413388264,0.000120065342013186,1,0.999253354069792,40.0298881530762,2.00260769138925,28.3100008964539,0.0988732607732309,0.0803668344049989,2.5,0.00541405858718013,0.00965342799667596,0.00542027806692183,300.0698242,300.071106,13779.5087890625,13789.556640625,57.8920979053523,20.5958141390772,22.909004,0,0,0,40,4449,300.2031,13784.5327148438,,,,,,,,,,,,,0,,,,-0.0049,,,,,,300.0704651,,,,
,28741815.025,300.0377808,18546.9169921875,0.0100286251024265,0.000107094225679592,1,0.999253354069792,40.0298881530762,2.00257623739136,28.3100008964539,0.103099073971926,0.0809982759512439,2.5,0.00540551532978215,0.0100247378121076,0.00541198213865814,300.0377808,300.0377808,18541.76171875,18552.072265625,57.555997642083,20.5967353015756,23.288654,0,0,0,40,4449,300.17965,18546.9169921875,,,,,,,,,,,,,0,,,,-0.0049,,,,,,300.0377808,,,,
,28741910.79,300.0079956,23334.037109375,0.0100470581635819,0.000138208945920439,1,0.999253354069792,40.0298881530762,2.00249291557129,28.3100008964539,0.103225257350252,0.0814867260577754,2.5,0.00544568012912399,0.0100431586615195,0.00545215741777474,300.0079956,300.0079956,23329.01171875,23339.0625,57.860832764583,20.5987298464613,23.288654,0,0,0,40,4449,300.1895,23334.037109375,,,,,,,,,,,,,0,,,,0,,,,,,300.0079956,,,,
,28742006.69,299.9967651,28126.8671875,0.0101118686887511,0.000118934931147414,1,0.999253354069792,40.0298881530762,2.00253884674981,28.3100008964539,0.103926305186948,0.0818248434936711,2.5,0.00546411512427023,0.010107963446953,0.00547063040285906,299.9967651,299.9967651,28121.8828125,28131.8515625,57.8326941378907,20.600045029657,22.909004,0,0,0,40,4449,300.1955,28126.8671875,,,,,,,,,,,,,0,,,,0,,,,,,299.9967651,,,,
,28742100.655,299.9844666,32821.95703125,0.010297837908275,0.000140730555692944,1,0.999253354069792,40.0298881530762,2.00248599207476,28.3100008964539,0.105832043785776,0.0833450892421228,2.5,0.00556615181562799,0.0102938689098128,0.00557278248289774,299.9844666,299.9844666,32814.4140625,32829.5,57.5575608991215,20.6014697756284,22.909004,0,0,0,40,4449,300.2078,32821.95703125,,,,,,,,,,,,,0,,,,0.00245,,,,,,299.9844666,,,,
,28742196.085,299.9829102,37591.8515625,0.0102165948307354,9.74247531025839E-5,1,0.999253354069792,40.0298881530762,2.00243751932811,28.3100008964539,0.104869243784188,0.0834099681351037,2.5,0.00558612526694952,0.0102126203986592,0.0055926948865183,299.9829102,299.9829102,37581.62109375,37602.08203125,57.616964666583,20.6006301175624,23.288654,0,0,0,40,4449,300.2251,37591.8515625,,,,,,,,,,,,,0,,,,-0.0049,,,,,,299.9829102,,,,
,28742287.61,299.9764709,42166.865234375,0.0102713193599667,0.00011742375771382,1,0.999253354069792,40.0298881530762,2.00246528035531,28.3100008964539,0.10535339903649,0.08431410663801,2.5,0.00565628909954186,0.0102673042398135,0.00566288702459606,299.9764709,299.9764709,42154.41796875,42179.3125,58.1672311441215,20.6067267046341,22.909004,0,0,0,40,4449,300.2395,42166.865234375,,,,,,,,,,,,,0,,,,0.0049,,,,,,299.9764709,,,,
,28742383.315,299.9838562,46947.40234375,0.0101584497678463,0.000136479591441569,1,0.999253354069792,40.0298881530762,2.00245185203758,28.3100008964539,0.10401314920698,0.0844369676813211,2.5,0.00568673567095009,0.0101544201006095,0.00569324967697113,299.9838562,299.9838562,46937.3671875,46957.4375,57.83347576641,20.6065286334866,22.909004,0,0,0,40,4449,300.249,46947.40234375,,,,,,,,,,,,,0,,,,0,,,,,,299.9838562,,,,
,28742477.615,299.9895935,51662.3046875,0.0101819764759488,0.000142493028371083,1,0.999253354069792,40.0298881530762,2.00293435116138,28.3100008964539,0.104435983820945,0.0837403435509412,2.5,0.00561953309326409,0.0101779931591497,0.00562605599318485,299.9895935,299.9895935,51654.7578125,51669.8515625,57.8428553086407,20.6163564061519,22.909004,0,0,0,40,4449,300.2595,51662.3046875,,,,,,,,,,,,,0,,,,0,,,,,,299.9895935,,,,
,28742572.475,300.0000916,56404.84375,0.0103703934522946,0.000127937283213417,1,0.999253354069792,40.0298881530762,2.00299523895567,28.3100008964539,0.106547219177504,0.0842791314440523,2.5,0.00563418931783672,0.0103663960333073,0.00564082605234073,300.0000916,300.0000916,56397.26171875,56412.42578125,58.0335726673331,20.615194761769,23.288654,0,0,0,40,4449,300.2573,56404.84375,,,,,,,,,,,,,0,,,,-0.00245,,,,,,300.0000916,,,,
,28742668.555,299.9973755,61204.896484375,0.00999694024957243,0.000174127065076742,1,0.999253354069792,40.0298881530762,2.00289108346165,28.3100008964539,0.102057676740985,0.0849779565690441,2.5,0.0057608835559903,0.00999287665641299,0.00576726504544083,299.9973755,299.9973755,61199.74609375,61210.046875,57.9804219280254,20.6157490360134,22.909004,0,0,0,40,4449,300.2538,61204.896484375,,,,,,,,,,,,,0,,,,-0.0049,,,,,,299.9973755,,,,
,28742763.935,299.9928589,65972.66015625,0.010142055795958,0.00011762025245959,1,0.999253354069792,40.0298881530762,2.00291051970795,28.3100008964539,0.103993333179048,0.0835967354818642,2.5,0.00561389129629644,0.0101380911150456,0.00562036534225048,299.9928589,299.9928589,65962.71875,65982.6015625,58.0335726673331,20.6144085907721,23.288654,0,0,0,40,4449,300.26295,65972.66015625,,,,,,,,,,,,,0,,,,-0.00245,,,,,,299.9928589,,,,
,28742860.775,299.9954529,70815.3359375,0.0100388261680043,0.000122418151927487,1,0.999253354069792,40.0298881530762,2.00308334238997,28.3100008964539,0.102642574808452,0.0844888773595423,2.5,0.00570983326072009,0.0100348060085282,0.00571622888370477,299.9954529,299.9954529,70810.4375,70820.234375,57.83347576641,20.6146402165525,23.288654,0,0,0,40,4449,300.2637,70815.3359375,,,,,,,,,,,,,0,,,,0,,,,,,299.9954529,,,,
,28742955.185,300.0081482,75532.984375,0.010091011051167,0.000141347037460745,1,0.999253354069792,40.0298881530762,2.00279924143349,28.3100008964539,0.103277796543604,0.0842492767958348,2.5,0.00568068258117,0.0100870088080575,0.00568710330499976,300.0081482,300.0081482,75527.7578125,75538.2109375,58.2633714519869,20.6170653704165,23.288654,0,0,0,40,4449,300.25305,75532.984375,,,,,,,,,,,,,0,,,,0,,,,,,300.0081482,,,,
,28743052.325,300.0051575,80389.38671875,0.0101321414822122,0.000119843118080587,1,0.999253354069792,40.0298881530762,2.00276263949716,28.3100008964539,0.103945660110501,0.0831560183133287,2.5,0.005577289232983,0.0101282118097396,0.00558373268412333,300.0051575,300.0051575,80376.921875,80401.8515625,58.0687459506985,20.6154151795188,23.288654,0,0,0,40,4449,300.2485,80389.38671875,,,,,,,,,,,,,0,,,,0,,,,,,300.0051575,,,,
,28743146.155,300.0081787,85079.92578125,0.00995945146097643,0.000127655708120517,1,0.999253354069792,40.0298881530762,2.00270882432825,28.3100008964539,0.102177915294533,0.0816993614590444,2.5,0.00547895203003139,0.00995559476607592,0.0054852777958193,300.0081787,300.0081787,85069.7265625,85090.125,57.7857964267369,20.6116127214164,22.909004,0,0,0,40,4449,300.24195,85079.92578125,,,,,,,,,,,,,0,,,,0.00245,,,,,,300.0081787,,,,
,28743233.945,300.0095825,89465.296875,0.00995842168528611,0.000133344822724526,1,0.999253354069792,40.0298881530762,2.00276176704083,28.3100008964539,0.102023200747991,0.0825401792198578,2.5,0.00555309828364193,0.00995452099615125,0.00555941394600602,300.0095825,300.0095825,89452.84375,89477.75,57.9108569898138,20.6159784139578,23.288654,0,0,0,40,4449,300.23835,89465.296875,,,,,,,,,,,,,0,,,,0,,,,,,300.0095825,,,,
,28743343.725,300.0036926,86076.3984375,0.00991649076158872,0.000110399012746582,1,0.999253354069792,40.0298881530762,2.00277468718735,28.3100008964539,0.10167734372242,0.0817133887434513,2.5,0.00548740585612316,0.00991263238378974,0.00549370284169178,300.0036926,300.0036926,86063.9765625,86088.8203125,57.6951275185061,20.6108002142687,23.288654,0,0,0,40,4449,300.23555,86076.3984375,,,,,,,,,,,,,0,,,,0,,,,,,300.0036926,,,,
,28743437.09,299.9978943,81410.546875,0.0101019940018425,0.000130929537666342,1,0.999253354069792,40.0298881530762,2.00273038674255,28.3100008964539,0.103373203105452,0.0844174292387056,2.5,0.00569385660038219,0.0100979928120021,0.00570027710042544,299.9978943,299.9978943,81405.3359375,81415.7578125,58.0742173503331,20.6066257936111,22.529354,0,0,0,40,4449,300.23825,81410.546875,,,,,,,,,,,,,0,,,,-0.0049,,,,,,299.9978943,,,,
,28743532.72,299.9996033,76629.46484375,0.0099851262212104,0.000103231921186101,1,0.999253354069792,40.0298881530762,2.00275609934805,28.3100008964539,0.10211063644679,0.0838334699060099,2.5,0.00566251293086265,0.00998114302170744,0.00566886532013336,299.9996033,299.9996033,76626.9765625,76631.953125,57.9303977027946,20.6058883009884,22.909004,0,0,0,40,4449,300.2429,76629.46484375,,,,,,,,,,,,,0,,,,0,,,,,,299.9996033,,,,
,28743630.29,299.9926758,71751.0390625,0.0100495035463464,0.00014522201210039,1,0.999253354069792,40.0298881530762,2.00241500361068,28.3100008964539,0.102910664121977,0.0834458696361664,2.5,0.00561836837368897,0.0100455446186712,0.00562477304134753,299.9921875,299.9931641,71738.578125,71763.5,57.5286406439099,20.6080857402985,23.288654,0,0,0,40,4449,300.24925,71751.0390625,,,,,,,,,,,,,0,,,,-0.00245,,,,,,299.9926758,,,,
,28743725.475,299.9931641,66993.20703125,0.0100196007707149,0.000101809484849321,1,0.999253354069792,40.0298881530762,2.00216768004172,28.3100008964539,0.102624010517888,0.0830047228357891,2.5,0.00558549888357935,0.0100156590509076,0.0055918921376439,299.9931641,299.9931641,66980.8125,67005.6015625,58.0921948062754,20.6052657081459,22.909004,0,0,0,40,4449,300.25645,66993.20703125,,,,,,,,,,,,,0,,,,-0.0049,,,,,,299.9931641,,,,
,28743822.46,299.98812865,62144.421875,0.0101217103278786,0.000147079132032081,1,0.999253354069792,40.0298881530762,2.00212691052021,28.3100008964539,0.103479956178931,0.0849332109366782,2.5,0.00573804754667947,0.01011766259177,0.00574451166498685,299.9878845,299.9883728,62131.9765625,62156.8671875,57.8225329671407,20.6052451491938,23.288654,0,0,0,40,4449,300.26265,62144.421875,,,,,,,,,,,,,0,,,,0.00245,,,,,,299.98812865,,,,
,28743917.205,299.9877472,57409.142578125,0.0102954718192187,9.00483906000941E-5,1,0.999253354069792,40.0298881530762,2.00230030120568,28.3100008964539,0.105873024292692,0.082889280616952,2.5,0.00552704517588848,0.0102915527979282,0.00553363625164665,299.9872131,299.9882813,57398.98828125,57419.296875,57.8147166819484,20.6074303622371,22.529354,0,0,0,40,4449,300.27875,57409.142578125,,,,,,,,,,,,,0,,,,-0.00245,,,,,,299.9877472,,,,
,28744013.955,299.9874573,52571.59765625,0.0102417584403735,0.000106593434037047,1,0.999253354069792,40.0298881530762,2.00240036255082,28.3100008964539,0.105226689682553,0.083031849668723,2.5,0.00554856991626981,0.0102378221309884,0.00555513249590655,299.9874573,299.9874573,52561.58984375,52581.60546875,57.8350390234484,20.6083671770423,23.288654,0,0,0,40,4449,300.2858,52571.59765625,,,,,,,,,,,,,0,,,,-0.0049,,,,,,299.9874573,,,,
,28744107.72,299.9873657,47886.48046875,0.0101072447753854,0.000138945873869499,1,0.999253354069792,40.0298881530762,2.00234169473878,28.3100008964539,0.103572955392978,0.0834902197786614,2.5,0.00561250051982594,0.010103265833645,0.00561897973590278,299.9873657,299.9873657,47884.046875,47888.9140625,58.2579000523523,20.6061996429406,23.288654,0,0,0,40,4449,300.2963,47886.48046875,,,,,,,,,,,,,0,,,,0.0049,,,,,,299.9873657,,,,
,28744204.73,299.992218,43036.5625,0.0101181881975987,0.000159210676245764,1,0.999253354069792,40.0298881530762,2.00256342038371,28.3100008964539,0.103724961550789,0.0834221405091098,2.5,0.00560381802638791,0.0101142081596318,0.00561031068474317,299.992218,299.992218,43026.65234375,43046.47265625,58.0687459506985,20.61405743515,22.909004,0,0,0,40,4449,300.30235,43036.5625,,,,,,,,,,,,,0,,,,0,,,,,,299.992218,,,,
,28744299.125,299.9926453,38321.373046875,0.0101528174527281,9.06966138695844E-5,1,0.999253354069792,40.0298881530762,2.00252724465152,28.3100008964539,0.104223790460362,0.0828653600568687,2.5,0.00554883712205548,0.0101488679495446,0.00555536075359272,299.9926453,299.9926453,38313.78515625,38328.9609375,58.2555551667946,20.619229750653,22.909004,0,0,0,40,4449,300.3079,38321.373046875,,,,,,,,,,,,,0,,,,0,,,,,,299.9926453,,,,
,28744394.89,299.993042,33534.23046875,0.0101620033739008,0.000111230966045946,1,0.999253354069792,40.0298881530762,2.00243892337302,28.3100008964539,0.104270528675319,0.0831857032883328,2.5,0.00557579943385656,0.0101580312020767,0.00558233495737358,299.993042,299.993042,33526.87890625,33541.58203125,58.0241931251023,20.6161936749908,23.668306,0,0,0,40,4449,300.3105,33534.23046875,,,,,,,,,,,,,0,,,,0,,,,,,299.993042,,,,
,28744491.775,299.9909973,28692.1962890625,0.010115001701844,0.00012007632714058,1,0.999253354069792,40.0298881530762,2.00245330221082,28.3100008964539,0.103915867205695,0.0820688157142034,2.5,0.00548538489003181,0.0101110869659186,0.00549189891624461,299.9909973,299.9909973,28684.603515625,28699.7890625,58.2508653956792,20.6191857746141,23.288654,0,0,0,40,4449,300.31865,28692.1962890625,,,,,,,,,,,,,0,,,,-0.0049,,,,,,299.9909973,,,,
,28744588.24,299.9898071,23869.6728515625,0.0100575556083161,9.76276507833056E-5,1,0.999253354069792,40.0298881530762,2.00254029213334,28.3100008964539,0.103736254496352,0.0792609311699882,2.5,0.00524740716926221,0.0100537959550311,0.00525389677586896,299.9898071,299.9898071,23857.138671875,23882.20703125,58.1578516018908,20.6239889982842,22.909004,0,0,0,40,4449,300.32155,23869.6728515625,,,,,,,,,,,,,0,,,,0.00245,,,,,,299.9898071,,,,
,28744681.32,299.9921417,19219.5341796875,0.0098754593541998,0.000133566417256922,1,0.999253354069792,40.0298881530762,2.00290778243368,28.3100008964539,0.101593249707859,0.0794705853764075,2.5,0.00529621459738863,0.00987166822624812,0.0053025877310816,299.9916992,299.9925842,19209.66796875,19229.400390625,58.3610750168908,20.6396398583929,23.288654,0,0,0,40,4449,300.32735,19219.5341796875,,,,,,,,,,,,,0,,,,-0.00245,,,,,,299.9921417,,,,
,28744774.975,299.9921265,14539.7734375,0.00978498111036367,0.000114594316260999,1,0.999253354069792,40.0298881530762,2.00301164379388,28.3100008964539,0.100704183297358,0.0785340663390295,2.5,0.00522896703824244,0.00978123360442032,0.00523528766497682,299.9921265,299.9921265,14532.142578125,14547.404296875,58.35169547466,20.6369922446366,22.909004,0,0,0,40,4449,300.3355,14539.7734375,,,,,,,,,,,,,0,,,,-0.00245,,,,,,299.9921265,,,,
,28744870.48,299.9905396,9765.2392578125,0.00946871306578881,0.000119974565078815,1,0.999253354069792,40.0298881530762,2.00296042455379,28.3100008964539,0.0974714001466597,0.0758520642347605,2.5,0.00504745100280538,0.00946509215261078,0.00505357310760362,299.9905396,299.9905396,9755.1416015625,9775.3369140625,58.2860386790446,20.6420606960922,22.909004,0,0,0,40,4449,300.33555,9765.2392578125,,,,,,,,,,,,,0,,,,-0.0049,,,,,,299.9905396,,,,
,28744964.85,299.994873,5049.69482421875,0.00891442818228533,0.000128472029180501,1,0.999253354069792,40.0298881530762,2.00299277551101,28.3100008964539,0.0915583371767962,0.0726168192155263,2.5,0.00485812786150053,0.00891094463163015,0.00486389208146699,299.994873,299.994873,5047.73876953125,5051.65087890625,57.7138866029676,20.6423698142661,23.288654,0,0,0,40,4449,300.3325,5049.69482421875,,,,,,,,,,,,,0,,,,0,,,,,,299.994873,,,,
,28745052.785,299.989563,650.511047363281,0.00517446294897014,5.98797212622392E-5,1,0.999253354069792,40.0298881530762,2.00297862122272,28.3100008964539,0.0533019477688196,0.0412480341080184,2.5,0.00274034360997913,0.00517249352311892,0.00274369408889734,299.989563,299.989563,647.927795410156,653.094299316406,58.42282366991,20.6470208850487,23.668306,0,0,0,40,4449,300.3476,650.511047363281,,,,,,,,,,,,,0,,,,-0.0049,,,,,,299.989563,,,,
,28745147.935,299.9957886,-4097.67651367188,-0.00867270887274535,9.68987249934852E-5,1,0.999253354069792,40.0298881530762,2.00277084730406,28.3100008964539,-0.0891538859574922,-0.0701345743037055,2.5,-0.00468180155648154,-0.00866934871055738,-0.00468741115635306,299.9957886,299.9957886,-4105.1650390625,-4090.18798828125,58.2070941986023,20.643006850115,23.668306,0,0,0,40,4449,300.3444,-4097.67651367188,,,,,,,,,,,,,0,,,,0,,,,,,299.9957886,,,,
,28745241.32,300.0034485,-8766.2783203125,-0.00939145203565609,0.000119914888638173,1,0.999253354069792,40.0298881530762,2.00279843797924,28.3100008964539,-0.0964902051295265,-0.0762567179280677,2.5,-0.00509703723237863,-0.00938779562664568,-0.00510310521433734,300.0034485,300.0034485,-8778.6884765625,-8753.8681640625,57.93508747391,20.6430028580854,23.288654,0,0,0,40,4449,300.3416,-8766.2783203125,,,,,,,,,,,,,0,,,,0,,,,,,300.0034485,,,,
,28745338.935,300.0048828,-13644.7622070312,-0.00954833732215521,0.000134738502352235,1,0.999253354069792,40.0298881530762,2.00273195364412,28.3100008964539,-0.0980301687913652,-0.0779254815247908,2.5,-0.00521722667106872,-0.00954459949883284,-0.00522338967107008,300.0048828,300.0048828,-13647.462890625,-13642.0615234375,58.3040161349869,20.6451899582524,22.909004,0,0,0,40,4449,300.3353,-13644.7622070312,,,,,,,,,,,,,0,,,,0,,,,,,300.0048828,,,,
,28745434.17,300.0105896,-18406.74609375,-0.00984328358736154,0.00014803783312914,1,0.999253354069792,40.0298881530762,2.00282831568646,28.3100008964539,-0.101061810376865,-0.0803429103960364,2.5,-0.00537897754851607,-0.00983943164236273,-0.00538532420048456,300.0105896,300.0105896,-18414.396484375,-18399.095703125,58.2954182212754,20.6499330718765,23.288654,0,0,0,40,4449,300.3355,-18406.74609375,,,,,,,,,,,,,0,,,,0.00245,,,,,,300.0105896,,,,
,28745531.3,300.0163574,-23261.466796875,-0.00991247556104224,0.000126067206970662,1,0.999253354069792,40.0298881530762,2.00277006560157,28.3100008964539,-0.101594346640544,-0.0819158428930163,2.5,-0.00550589325640612,-0.00990853961225379,-0.00551227475546953,300.0163574,300.0163574,-23271.525390625,-23251.408203125,58.1007927199869,20.6512845449326,23.668306,0,0,0,40,4449,300.3318,-23261.466796875,,,,,,,,,,,,,0,,,,-0.0049,,,,,,300.0163574,,,,
,28745629.305,300.0154419,-28158.8388671875,-0.0101341808843981,0.000121118021779898,1,0.999253354069792,40.0298881530762,2.00280899420345,28.3100008964539,-0.104148195763816,-0.0821358544378819,2.5,-0.00548675250163092,-0.0101302551847772,-0.00549327523228958,300.0154419,300.0154419,-28168.96484375,-28148.712890625,58.3087059061023,20.6581448217797,23.288654,0,0,0,40,4449,300.31095,-28158.8388671875,,,,,,,,,,,,,0,,,,-0.00245,,,,,,300.0154419,,,,
,28745725.125,300.0115356,-32948.60546875,-0.0100686740328952,0.000110494580813877,1,0.999253354069792,40.0298881530762,2.00280855429378,28.3100008964539,-0.103626535099806,-0.0807304555627054,2.5,-0.00537418293297104,-0.0100648300852173,-0.00538066034109822,300.0115356,300.0115356,-32956.21484375,-32940.99609375,58.1007927199869,20.6606826190889,22.909004,0,0,0,40,4449,300.29925,-32948.60546875,,,,,,,,,,,,,0,,,,0,,,,,,300.0115356,,,,
,28745822.345,300.0101318,-37805.37109375,-0.0100593917583571,0.000125403459308807,1,0.999253354069792,40.0298881530762,2.00266961538174,28.3100008964539,-0.103215246187375,-0.0824339678011088,2.5,-0.00552648990521586,-0.010055452713859,-0.00553295017892217,300.0101318,300.0101318,-37812.83984375,-37797.90234375,58.0546766373523,20.6605613443429,22.909004,0,0,0,40,4449,300.2976,-37805.37109375,,,,,,,,,,,,,0,,,,0,,,,,,300.0101318,,,,
,28745917.46,300.0098877,-42557.43359375,-0.0101490052066905,0.000104328973511771,1,0.999253354069792,40.0298881530762,2.00253714059591,28.3100008964539,-0.104328827457311,-0.0820051546185429,2.5,-0.00547361167122278,-0.0101451026772994,-0.00548012612019145,300.0098877,300.0098877,-42559.90625,-42554.9609375,58.1070457481408,20.6605051847227,22.909004,0,0,0,40,4449,300.2816,-42557.43359375,,,,,,,,,,,,,0,,,,0,,,,,,300.0098877,,,,
,28746014.87,300.0116882,-47427.48828125,-0.0100796601043555,0.000178444405782069,1,0.999253354069792,40.0298881530762,2.00272958091722,28.3100008964539,-0.103252840033877,-0.0836034040196886,2.5,-0.00562590509592954,-0.0100756635256788,-0.00563236208467966,300.0116882,300.0116882,-47432.453125,-47422.5234375,57.9733872713523,20.6648204721806,23.668306,0,0,0,40,4449,300.27485,-47427.48828125,,,,,,,,,,,,,0,,,,0,,,,,,300.0116882,,,,
,28746110.72,300.0138245,-52219.92578125,-0.0101330433516948,0.000151083702191821,1,0.999253354069792,40.0298881530762,2.00256998148299,28.3100008964539,-0.103706133499856,-0.0845344501208603,2.5,-0.005699330371407,-0.0101290008741137,-0.00570581294852078,300.0138245,300.0138245,-52224.85546875,-52214.99609375,57.9233630461215,20.6597972969497,23.288654,0,0,0,40,4449,300.263,-52219.92578125,,,,,,,,,,,,,0,,,,0,,,,,,300.0138245,,,,
,28746208.815,300.0206909,-57121.669921875,-0.0100949314313724,0.000130573000209621,1,0.999253354069792,40.0298881530762,2.0026284299832,28.3100008964539,-0.103316738093773,-0.0842318090360417,2.5,-0.0056790453710347,-0.0100909057869506,-0.0056854950266431,300.0206909,300.0206909,-57126.65234375,-57116.6875,58.1023559770254,20.655550957757,23.668306,0,0,0,40,4449,300.2499,-57121.669921875,,,,,,,,,,,,,0,,,,-0.00245,,,,,,300.0206909,,,,
,28746304.62,300.0154419,-61908.853515625,-0.010148786787653,0.000116783345444825,1,0.999253354069792,40.0298881530762,2.00253729682372,28.3100008964539,-0.103779886527821,-0.085160061197114,2.5,-0.0057519039301487,-0.0101447185378945,-0.00575838076116505,300.0154419,300.0154419,-61913.62109375,-61904.0859375,57.9718240143138,20.6648377032327,23.288654,0,0,0,40,4449,300.2357,-61908.853515625,,,,,,,,,,,,,0,,,,-0.0049,,,,,,300.0154419,,,,
,28746402.015,300.013031,-66778.41015625,-0.00999413491467822,0.000117666826612037,1,0.999253354069792,40.0298881530762,2.00259550678654,28.3100008964539,-0.102408850065431,-0.082666957893534,2.5,-0.005558636539386,-0.00999020367614388,-0.00556501095711962,300.013031,300.013031,-66785.9609375,-66770.859375,57.7263926592753,20.6598973685683,23.288654,0,0,0,40,4449,300.228,-66778.41015625,,,,,,,,,,,,,0,,,,-0.00245,,,,,,300.013031,,,,
,28746496.795,300.0133667,-71510.6171875,-0.01006995637799,0.000123310980163373,1,0.999253354069792,40.0298881530762,2.00240879192184,28.3100008964539,-0.103051322169397,-0.084010172220979,2.5,-0.00566461960424905,-0.0100659584088397,-0.00567103319453706,300.0133667,300.0133667,-71512.9453125,-71508.2890625,57.9616628435638,20.6653149738154,22.909004,0,0,0,40,4449,300.2195,-71510.6171875,,,,,,,,,,,,,0,,,,-0.0049,,,,,,300.0133667,,,,
,28746594.045,300.0190125,-76370.1328125,-0.00980767053089512,0.000128164059053712,1,0.999253354069792,40.0298881530762,2.0024057357497,28.3100008964539,-0.100134402359788,-0.0831650121555892,2.5,-0.00563554049202506,-0.00980370226063678,-0.00564177529633725,300.0190125,300.0190125,-76380.1484375,-76360.1171875,57.7990841115638,20.6558989717013,23.668306,0,0,0,40,4449,300.20185,-76370.1328125,,,,,,,,,,,,,0,,,,-0.0049,,,,,,300.0190125,,,,
,28746691.73,300.015625,-81254.92578125,-0.00980654264411283,0.000119766227825324,1,0.999253354069792,40.0298881530762,2.00239596349888,28.3100008964539,-0.100220295282061,-0.0825905557177624,2.5,-0.00558511154882186,-0.00980261371768401,-0.00559134028213291,300.015625,300.015625,-81257.5,-81252.3515625,57.6755868055253,20.6547704396324,22.909004,0,0,0,40,4449,300.1961,-81254.92578125,,,,,,,,,,,,,0,,,,-0.0049,,,,,,300.015625,,,,
,28746785.76,300.0144043,-85954.671875,-0.00984127864008898,0.000138113284802346,1,0.999253354069792,40.0298881530762,2.00249303282833,28.3100008964539,-0.100707680886967,-0.0821499606897309,2.5,-0.00553990618265126,-0.00983738346289354,-0.00554615202891233,300.0144043,300.0144043,-85959.5234375,-85949.8203125,57.7005989181407,20.6501859222351,23.288654,0,0,0,40,4449,300.1812,-85954.671875,,,,,,,,,,,,,0,,,,0,,,,,,300.0144043,,,,
,28746896.585,300.0128784,-89503.0546875,-0.00986650561757185,0.000107567999959508,1,0.999253354069792,40.0298881530762,2.00232214071326,28.3100008964539,-0.100909940384323,-0.082629297428078,2.5,-0.00557840662909801,-0.00986258895095306,-0.00558466259290301,300.0128784,300.0128784,-89510.3828125,-89495.7265625,57.8022106256407,20.6491563228223,23.288654,0,0,0,40,4449,300.1729,-89503.0546875,,,,,,,,,,,,,0,,,,-0.0049,,,,,,300.0128784,,,,
,28746990.45,300.0031738,-84815.87890625,-0.00990958030535386,0.000137520662586277,1,0.999253354069792,40.0298881530762,2.00192651866013,28.3100008964539,-0.101554106916242,-0.081688686036754,2.5,-0.00548933309933875,-0.00990571862007719,-0.00549562924074588,300.0031738,300.0031738,-84826.1484375,-84805.609375,57.6185279236215,20.6233038275959,23.288654,0,0,0,40,4449,300.1686,-84815.87890625,,,,,,,,,,,,,0,,,,0,,,,,,300.0031738,,,,
,28747088.945,300.0027466,-79893.3515625,-0.00998121862505657,0.000120969611335062,1,0.999253354069792,40.0298881530762,2.00181664327192,28.3100008964539,-0.102240618171791,-0.0825186565533857,2.5,-0.00555051167318961,-0.0099773098276067,-0.00555686068184072,300.0027466,300.0027466,-79898.140625,-79888.5625,57.7107600888907,20.6285377296422,23.288654,0,0,0,40,4449,300.16935,-79893.3515625,,,,,,,,,,,,,0,,,,0,,,,,,300.0027466,,,,
,28747187.25,299.9967499,-74980.921875,-0.0100026593476443,0.000119136018891473,1,0.999253354069792,40.0298881530762,2.00175034622061,28.3100008964539,-0.102448696696155,-0.0827410436439287,2.5,-0.00556663814275549,-0.00999873627434973,-0.0055730096661111,299.9960938,299.997406,-74990.9296875,-74970.9140625,57.799865740083,20.6283296692122,23.288654,0,0,0,40,4449,300.1706,-74980.921875,,,,,,,,,,,,,0,,,,0,,,,,,299.9967499,,,,
,28747284.725,299.9948425,-70106.58203125,-0.0099313768673601,0.000119670057412985,1,0.999253354069792,40.0298881530762,2.00166295561686,28.3100008964539,-0.10162672974548,-0.0826535710772404,2.5,-0.00557156747556964,-0.00992744824230574,-0.00557790009882852,299.9948425,299.9948425,-70114.125,-70099.0390625,57.7764168845061,20.6264110334158,23.288654,0,0,0,40,4449,300.17975,-70106.58203125,,,,,,,,,,,,,0,,,,-0.0049,,,,,,299.9948425,,,,
,28747381.68,299.9885559,-65264.912109375,-0.00996649427171248,0.000127502220854216,1,0.999253354069792,40.0298881530762,2.00150657575955,28.3199995756149,-0.101925924722686,-0.08324281760291,2.5,-0.00561800953021076,-0.00996253151184847,-0.00562437233856547,299.9885559,299.9885559,-65272.45703125,-65257.3671875,57.7756352559869,20.6252318929295,22.909004,0,0,0,40,4449,300.1889,-65264.912109375,,,,,,,,,,,,,0,,,,-0.0049,,,,,,299.9885559,,,,
,28747478.21,299.9885559,-60439.9453125,-0.00993229712893462,0.000134572466340548,1,0.999253354069792,40.0298881530762,2.00139498200945,28.3199995756149,-0.101534296104149,-0.0831631042706551,2.5,-0.00561728502760326,-0.00992833093239686,-0.00562363256776214,299.9885559,299.9885559,-60449.796875,-60430.09375,57.6255625802946,20.6276139466911,22.909004,0,0,0,40,4449,300.2002,-60439.9453125,,,,,,,,,,,,,0,,,,0,,,,,,299.9885559,,,,
,28747576.01,299.9906616,-55550.32421875,-0.00998851842494651,0.00013067018277409,1,0.999253354069792,40.0298881530762,2.00146901932402,28.3100008964539,-0.102444415446562,-0.0817213721839032,2.5,-0.00548006997555815,-0.00998463493767994,-0.0054864651016768,299.9906616,299.9906616,-55558.14453125,-55542.50390625,57.9217997890831,20.6261342680579,23.288654,0,0,0,40,4449,300.2083,-55550.32421875,,,,,,,,,,,,,0,,,,-0.00245,,,,,,299.9906616,,,,
,28747675.915,299.9909363,-50558.849609375,-0.0101984234078272,0.000102725722682229,1,0.999253354069792,40.0298881530762,2.00129224207411,28.3100008964539,-0.104680598645223,-0.082899364753188,2.5,-0.0055482523770673,-0.010194484068998,-0.00555479065190271,299.9909363,299.9909363,-50561.24609375,-50556.453125,57.8115901678715,20.6248082974234,23.288654,0,0,0,40,4449,300.2146,-50558.849609375,,,,,,,,,,,,,0,,,,-0.00245,,,,,,299.9909363,,,,
,28747772.9,299.9923706,-45714.25,-0.00998546648947998,9.94871318864225E-5,1,0.999253354069792,40.0298881530762,2.00121468636917,28.3199995756149,-0.102316778166381,-0.082170185242849,2.5,-0.00552106637821443,-0.0099815460005038,-0.00552747216279553,299.9923706,299.9923706,-45724.203125,-45704.296875,57.8584878790253,20.6242764791085,23.668306,0,0,0,40,4449,300.22355,-45714.25,,,,,,,,,,,,,0,,,,-0.0049,,,,,,299.9923706,,,,
,28747867.49,299.9927673,-40984.123046875,-0.0100362650676166,0.000112647460485207,1,0.999253354069792,40.0298881530762,2.00101750361454,28.3100008964539,-0.102970247334137,-0.0817569119570238,2.5,-0.00547646864256103,-0.010032367825655,-0.00548291572933356,299.9927673,299.9927673,-40991.65234375,-40976.59375,57.6794949481215,20.624266024049,22.909004,0,0,0,40,4449,300.2303,-40984.123046875,,,,,,,,,,,,,0,,,,0,,,,,,299.9927673,,,,
,28747963.175,299.9867096,-36204.36328125,-0.0102631385668536,9.95757676598291E-5,1,0.999253354069792,40.0298881530762,2.00107188200914,28.3199995756149,-0.105645924121611,-0.0816142591610291,2.5,-0.00542437787556909,-0.0102592668649732,-0.00543098375014336,299.9866333,299.9867859,-36219.33203125,-36189.39453125,57.7920494548907,20.6225403589148,23.288654,0,0,0,40,4449,300.23795,-36204.36328125,,,,,,,,,,,,,0,,,,0.00245,,,,,,299.9867096,,,,
,28748060.04,299.9886475,-31362.6787109375,-0.00986896210755056,0.000137910554691565,1,0.999253354069792,40.0298881530762,2.00092072508778,28.3199995756149,-0.1009950556467,-0.0818560089213786,2.5,-0.0055145212829965,-0.00986503739715376,-0.00552087077188668,299.9886475,299.9886475,-31372.6328125,-31352.724609375,57.6404135221599,20.6236476659861,23.288654,0,0,0,40,4449,300.247,-31362.6787109375,,,,,,,,,,,,,0,,,,-0.00245,,,,,,299.9886475,,,,
,28748153.97,299.9935913,-26667.2255859375,-0.00975664900755498,0.000123290054112258,1,0.999253354069792,40.0298881530762,2.00071288323999,28.3199995756149,-0.0997556814250884,-0.0813784162971391,2.5,-0.00549253709825419,-0.00975273617374762,-0.00549881821763606,299.9935913,299.9935913,-26679.56640625,-26654.884765625,57.6537012069869,20.622108773982,23.288654,0,0,0,40,4449,300.24995,-26667.2255859375,,,,,,,,,,,,,0,,,,0,,,,,,299.9935913,,,,
,28748248.815,299.9953918,-21928.044921875,-0.00974477674963228,0.000104316267672635,1,0.999253354069792,40.0298881530762,2.0006399026029,28.3199995756149,-0.0999214945711093,-0.079598587491681,2.5,-0.00533773558594734,-0.00974096191330007,-0.00534401892924568,299.9953918,299.9953918,-21933.0859375,-21923.00390625,57.82331459566,20.6223900900404,22.909004,0,0,0,40,4449,300.2545,-21928.044921875,,,,,,,,,,,,,0,,,,0,,,,,,299.9953918,,,,
,28748344.435,299.9880371,-17147.8408203125,-0.00952829250150281,0.000113805398384051,1,0.999253354069792,40.0298881530762,2.0007655921756,28.3100008964539,-0.0976754819368104,-0.0780199732681256,2.5,-0.0052354809119498,-0.00952455048755881,-0.00524163100324965,299.9880371,299.9880371,-17160.3984375,-17135.283203125,57.6646440062561,20.6148751083856,22.909004,0,0,0,40,4449,300.2639,-17147.8408203125,,,,,,,,,,,,,0,,,,-0.0049,,,,,,299.9880371,,,,
,28748440.715,299.9886169,-12338.1108398438,-0.00964473698592324,0.000114023567210592,1,0.999253354069792,40.0298881530762,2.00068402079948,28.3199995756149,-0.0990318065265494,-0.0780092059272017,2.5,-0.00521461883558215,-0.00964100159787791,-0.00522085184344898,299.9886169,299.9886169,-12343.2421875,-12332.9794921875,57.82331459566,20.6177600060606,23.288654,0,0,0,40,4449,300.2668,-12338.1108398438,,,,,,,,,,,,,0,,,,-0.00245,,,,,,299.9886169,,,,
,28748536.4,299.9898376,-7555.35913085938,-0.009131955193402,0.000102508652222126,1,0.999253354069792,40.0298881530762,2.00064123083576,28.3199995756149,-0.0936154264294494,-0.0747213304833337,2.5,-0.0050133820546638,-0.00912836460197058,-0.00501928580015866,299.9898376,299.9898376,-7565.513671875,-7545.20458984375,57.81315342491,20.6190983164012,23.288654,0,0,0,40,4449,300.2743,-7555.35913085938,,,,,,,,,,,,,0,,,,0.00245,,,,,,299.9898376,,,,
,28748627.485,299.9903564,-2999.33276367188,-0.00844074613837317,9.38546400988181E-5,1,0.999253354069792,40.0298881530762,2.00070052288288,28.3199995756149,-0.0868266736930201,-0.0673666287111114,2.5,-0.00448377699982915,-0.00843752433449704,-0.00448924176600194,299.9903564,299.9903564,-3002.08349609375,-2996.58203125,57.7193580026023,20.6216237083416,23.668306,0,0,0,40,4449,300.2804,-2999.33276367188,,,,,,,,,,,,,0,,,,0,,,,,,299.9903564,,,,
,28748720.465,299.997406,1643.70593261719,0.00739957565184038,7.50581244457952E-5,1,0.999253354069792,40.0298881530762,2.00024484167072,28.3100008964539,0.0760728896137219,0.0591357939657774,0.25,0.00393947593650918,0.00739674307028651,0.0039442661236327,299.9972229,299.9975891,1633.70166015625,1653.71020507813,57.81315342491,20.6251272620997,23.668306,0,0,0,40,4449,300.2835,1643.70593261719,,,,,,,,,,,,,0,,,,0.00245,,,,,,299.997406,,,,
,28748816.79,300.0012817,6455.9326171875,0.00896718258070581,0.000136645355402472,1,0.999253354069792,40.0298881530762,2.00046107114944,28.3199995756149,0.0918893473397928,0.0735340550730871,2.5,0.00493769064444953,0.00896364284698882,0.00494348607925627,300.0012817,300.0012817,6450.962890625,6460.90234375,57.7764168845061,20.6264900740386,23.668306,0,0,0,40,4449,300.2887,6455.9326171875,,,,,,,,,,,,,0,,,,0.0049,,,,,,300.0012817,,,,
,28748910.77,299.9966736,11156.54296875,0.00946762677565377,0.00014867451208822,1,0.999253354069792,40.0298881530762,2.0004870304948,28.3100008964539,0.0971508472698414,0.0768766987344522,2.5,0.00514598016515132,0.00946393863634355,0.00515209740427851,299.9966736,299.9966736,11154.15234375,11158.93359375,57.8053371397177,20.6258581763885,23.668306,0,0,0,40,4449,300.2788,11156.54296875,,,,,,,,,,,,,0,,,,0.0049,,,,,,299.9966736,,,,
,28749006.405,300.0048828,15936.5849609375,0.00976109287107448,0.000123315632964523,1,0.999253354069792,40.0298881530762,2.00068575578413,28.3199995756149,0.100202959323987,0.0790868040540234,2.5,0.00528957786929784,0.00975730162116918,0.00529587828707564,300.0048828,300.0048828,15926.669921875,15946.5,57.80299225416,20.62060648799,23.668306,0,0,0,40,4449,300.2768,15936.5849609375,,,,,,,,,,,,,0,,,,0.00245,,,,,,300.0048828,,,,
,28749099.91,300.0073242,20608.79296875,0.00985381697630076,0.000110869558693608,1,0.999253354069792,40.0298881530762,2.00043534871546,28.3199995756149,0.101174279420032,0.0796467033863196,2.5,0.00532377847563183,0.00985000304935387,0.00533013334363784,300.0073242,300.0073242,20603.8203125,20613.765625,57.84363693716,20.623980168064,23.288654,0,0,0,40,4449,300.26725,20608.79296875,,,,,,,,,,,,,0,,,,0,,,,,,300.0073242,,,,
,28749194.36,300.0044556,25328.896484375,0.00995214073199064,9.51701896382917E-5,1,0.999253354069792,40.0298881530762,2.00071278077323,28.3199995756149,0.102192426553765,0.0804807967318859,2.5,0.00537943957831008,0.00994829211505916,0.00538585226800741,300.0044556,300.0044556,25316.494140625,25341.298828125,57.7748536274677,20.6195128071826,23.288654,0,0,0,40,4449,300.26925,25328.896484375,,,,,,,,,,,,,0,,,,0,,,,,,300.0044556,,,,
,28749289.455,300.0089111,30081.5341796875,0.00989329160154272,0.000154413240854796,1,0.999253354069792,40.0298881530762,2.00050931383219,28.3199995756149,0.101248484469763,0.0819008249690004,2.5,0.00551568379962595,0.00988935725901219,0.00552204669090906,300.0089111,300.0089111,30078.9140625,30084.154296875,57.8428553086407,20.6198960899028,22.909004,0,0,0,40,4449,300.2596,30081.5341796875,,,,,,,,,,,,,0,,,,0.00245,,,,,,300.0089111,,,,
,28749384.755,300.0122528,34844.146484375,0.0101148362655087,0.00012572069460287,1,0.999253354069792,40.0298881530762,2.00042846434992,28.3199995756149,0.10402347937168,0.080778467658861,2.5,0.00537850540296881,0.0101109885423291,0.00538501188197889,300.0113525,300.0131531,34836.640625,34851.65234375,57.6857479762753,20.6210811497229,23.668306,0,0,0,40,4449,300.2369,34844.146484375,,,,,,,,,,,,,0,,,,0.00245,,,,,,300.0122528,,,,
,28749479.585,300.0140991,39584.078125,0.0101114824635492,0.000108370114344063,1,0.999253354069792,40.0298881530762,2.00034082331373,28.3199995756149,0.103776219293551,0.0819515473601402,2.5,0.00548295267602838,0.0101075699772475,0.00548944644758666,300.0140991,300.0140991,39579.1015625,39589.0546875,57.6888744903523,20.6231841007824,23.288654,0,0,0,40,4449,300.2484,39584.078125,,,,,,,,,,,,,0,,,,0,,,,,,300.0140991,,,,
,28749575.035,300.0107727,44356.72265625,0.0100975108143404,0.000155885344597949,1,0.999253354069792,40.0298881530762,2.00035785519696,28.3199995756149,0.103600841667196,0.0820288153866522,2.5,0.00549214080417051,0.0100935982812683,0.00549861918054108,300.0107727,300.0107727,44351.76953125,44361.67578125,57.7803250271023,20.6197590538805,23.668306,0,0,0,40,4449,300.23495,44356.72265625,,,,,,,,,,,,,0,,,,0.00245,,,,,,300.0107727,,,,
,28749673.68,300.0128479,49287.078125,0.0100189053814013,0.000135261030360212,1,0.999253354069792,40.0298881530762,2.00044326375295,28.3199995756149,0.102521645715725,0.0829920006440959,2.5,0.00559049854421801,0.0100149344527569,0.00559691496514952,300.0128479,300.0128479,49279.484375,49294.671875,57.6669888918138,20.6202686442498,22.909004,0,0,0,40,4449,300.22255,49287.078125,,,,,,,,,,,,,0,,,,0,,,,,,300.0128479,,,,
,28749771.5,300.0137329,54174.505859375,0.010030790357881,0.00011103669323731,1,0.999253354069792,40.0298881530762,2.00040782187261,28.3100008964539,0.102642676734385,0.0830827125134858,2.5,0.00559657766829107,0.0100268195591724,0.00560299449687466,300.0137329,300.0137329,54166.75,54182.26171875,57.5958606965638,20.6187536035578,23.668306,0,0,0,40,4449,300.2124,54174.505859375,,,,,,,,,,,,,0,,,,-0.0049,,,,,,300.0137329,,,,
,28749867.93,300.0134277,58991.986328125,0.0100928817257129,7.90601082775091E-5,1,0.999253354069792,40.0298881530762,2.00032595143374,28.3199995756149,0.103431402649751,0.0826856041584552,2.5,0.00555105518128927,0.0100889438238707,0.00555750709744044,300.0134277,300.0134277,58984.484375,58999.48828125,57.5481813568907,20.6204330667035,23.668306,0,0,0,40,4449,300.20115,58991.986328125,,,,,,,,,,,,,0,,,,-0.00245,,,,,,300.0134277,,,,
,28749961.835,300.0113983,63690.087890625,0.0099373667296329,9.3514549436013E-5,1,0.999253354069792,40.0298881530762,2.00048411720421,28.3199995756149,0.101778217395757,0.0818056833832382,2.5,0.00549977774124069,0.00993347235323891,0.00550612285229997,300.011322,300.0114746,63682.62109375,63697.5546875,57.6185279236215,20.6184822743618,23.288654,0,0,0,40,4449,300.1855,63690.087890625,,,,,,,,,,,,,0,,,,-0.00245,,,,,,300.0113983,,,,
,28750058.47,300.0132141,68517.68359375,0.00994603584207472,0.000132347437168563,1,0.999253354069792,40.0298881530762,2.00051925410054,28.3199995756149,0.101799135825895,0.0822803095065418,2.5,0.00554005884075488,0.00994211913029525,0.00554640080148825,300.0132141,300.0132141,68514.96875,68520.3984375,57.5927341824868,20.6186070526935,22.909004,0,0,0,40,4449,300.1783,68517.68359375,,,,,,,,,,,,,0,,,,0,,,,,,300.0132141,,,,
,28750153.935,300.0127258,73287.734375,0.0099193883839318,0.000116297492388043,1,0.999253354069792,40.0298881530762,2.00062749547099,28.3199995756149,0.101259811938406,0.0836334246252536,2.5,0.00566374560710056,0.0099153968144745,0.00567005928166842,300.0127258,300.0127258,73282.890625,73292.578125,57.5622506702369,20.6205540250003,23.668306,0,0,0,40,4449,300.17375,73287.734375,,,,,,,,,,,,,0,,,,0,,,,,,300.0127258,,,,
,28750253.685,300.01246645,78273.08203125,0.00997861445397111,0.000146846436252688,1,0.999253354069792,40.0298881530762,2.00065387856129,28.3100008964539,0.102197002728716,0.0822218458089096,2.5,0.00552880083969152,0.00997471458532911,0.00553514954304282,300.0123291,300.0126038,78260.6171875,78285.546875,57.5411467002176,20.6170652737383,23.668306,0,0,0,40,4449,300.16465,78273.08203125,,,,,,,,,,,,,0,,,,0.0049,,,,,,300.01246645,,,,
,28750349.935,300.015686,83086.89453125,0.00988630755172085,0.000128738206816746,1,0.999253354069792,40.0298881530762,2.00070952804188,28.3199995756149,0.101002198854543,0.0829189282590005,2.5,0.00560613616065539,0.00988236378615638,0.00561241447841997,300.015686,300.015686,83079.5078125,83094.28125,57.6075851243522,20.6180049517702,23.668306,0,0,0,40,4449,300.1485,83086.89453125,,,,,,,,,,,,,0,,,,-0.0049,,,,,,300.015686,,,,
,28750442.585,300.0175934,87717.36328125,0.00984492567837129,9.42805986305721E-5,1,0.999253354069792,40.0298881530762,2.00056722791763,28.3100008964539,0.100754696328773,0.0815154540478899,2.5,0.00548992161182858,0.00984106304251712,0.0054961688573995,300.0175171,300.0176697,87712.046875,87722.6796875,57.6193095521407,20.6194762666884,23.668306,0,0,0,40,4449,300.1384,87717.36328125,,,,,,,,,,,,,0,,,,0,,,,,,300.0175934,,,,
,28750551.175,300.0075378,87848.21875,0.00970402522280778,0.000146669370447902,1,0.999253354069792,40.0298881530762,2.00045073682026,28.3199995756149,0.0989023671299264,0.0826811919840321,2.5,0.00561763711329961,0.00970008713691026,0.00562379086077914,300.0075378,300.0075378,87838.140625,87858.296875,57.6052402387946,20.6177640060429,23.668306,0,0,0,40,4449,300.1322,87848.21875,,,,,,,,,,,,,0,,,,0,,,,,,300.0075378,,,,
,28750646.64,300.0081482,83075.01953125,0.00978398064700231,0.000141245906445502,1,0.999253354069792,40.0298881530762,2.00046157394842,28.3199995756149,0.10001788863419,0.0816302371721547,2.5,0.00551096623975034,0.00978010417859289,0.00551718270934523,300.0081482,300.0081482,83070.0390625,83080,57.5794464976599,20.6189477297482,23.668306,0,0,0,40,4449,300.1258,83075.01953125,,,,,,,,,,,,,0,,,,0,,,,,,300.0081482,,,,
,28750743.075,299.9986267,78253.52734375,0.0100391650918429,0.000123275278164843,1,0.999253354069792,40.0298881530762,2.00022166102786,28.3199995756149,0.103000217779192,0.0815249401439579,2.5,0.00545827529970172,0.0100353139516546,0.00546466905002032,299.9986267,299.9986267,78245.9765625,78261.078125,57.5810097546984,20.6226261749853,23.668306,0,0,0,40,4449,300.13465,78253.52734375,,,,,,,,,,,,,0,,,,0.0049,,,,,,299.9986267,,,,
,28750838.38,299.9933167,73490.24609375,0.00993537686065396,0.000102487401816796,1,0.999253354069792,40.0298881530762,2.00045071886386,28.3199995756149,0.101665486416199,0.0823127659013618,2.5,0.00554500886916851,0.00993146892340301,0.00555134092354277,299.9933167,299.9933167,73488.03125,73492.4609375,57.6583909781023,20.6207391534783,23.288654,0,0,0,40,4449,300.13645,73490.24609375,,,,,,,,,,,,,0,,,,0.0049,,,,,,299.9933167,,,,
,28750930.29,299.9918518,68894.6640625,0.00975862966302914,0.000116724990144898,1,0.999253354069792,40.0298881530762,2.00051678126372,28.3100008964539,0.0997439417560181,0.0815208029855125,2.5,0.00550548492775926,0.00975474827880383,0.00551170999370943,299.9918518,299.9918518,68889.65625,68899.671875,57.6036769817561,20.6196113338134,23.288654,0,0,0,40,4449,300.1356,68894.6640625,,,,,,,,,,,,,0,,,,0,,,,,,299.9918518,,,,
,28751025.68,299.9850464,64129.36328125,0.00997222122982874,0.000115282776628233,1,0.999253354069792,40.0298881530762,2.00021038518725,28.3199995756149,0.102117058802713,0.0821102270442392,2.5,0.00552156220097455,0.00996832073491518,0.00552793511457351,299.9850464,299.9850464,64126.98046875,64131.74609375,57.5473997283715,20.6251028735877,23.668306,0,0,0,40,4449,300.1414,64129.36328125,,,,,,,,,,,,,0,,,,0.0049,,,,,,299.9850464,,,,
,28751124.88,299.9836426,59171.052734375,0.0100732554250547,9.57710121848723E-5,1,0.999253354069792,40.0298881530762,2.00009752339427,28.3100008964539,0.102981655698108,0.0838866101015034,2.5,0.00566128166809465,0.0100692563311915,0.00566772393934472,299.9836426,299.9836426,59163.609375,59178.49609375,57.5989872106407,20.6260716157516,23.288654,0,0,0,40,4449,300.17265,59171.052734375,,,,,,,,,,,,,0,,,,-0.0049,,,,,,299.9836426,,,,
,28751223.19,299.9897461,54256.337890625,0.0101055951198247,0.000105583094474208,1,0.999253354069792,40.0298881530762,2.00019437661353,28.3199995756149,0.103576711624631,0.0826605633273704,2.5,0.00554708687702777,0.0101016628303894,0.00555355972984272,299.9897461,299.9897461,54246.28515625,54266.390625,57.7646924567176,20.6249799288688,23.288654,0,0,0,40,4449,300.17985,54256.337890625,,,,,,,,,,,,,0,,,,0,,,,,,299.9897461,,,,
,28751319.665,299.98721315,49433.958984375,0.0100772596456196,0.000120131383773946,1,0.999253354069792,40.0298881530762,2.00012761933411,28.3199995756149,0.103257213618014,0.082574747647034,2.5,0.00554464505263312,0.0100733260718181,0.0055511067545401,299.9871216,299.9873047,49428.9765625,49438.94140625,57.7263926592753,20.6247656023658,23.668306,0,0,0,40,4449,300.1947,49433.958984375,,,,,,,,,,,,,0,,,,-0.00245,,,,,,299.98721315,,,,
,28751412.765,299.99200435,44781.28125,0.010055565743562,0.000130081001336622,1,0.999253354069792,40.0298881530762,2.00000870491095,28.3100008964539,0.103085149572289,0.0820682564602214,2.5,0.00550409143712375,0.0100516530670069,0.00551054604240246,299.9919128,299.9920959,44771.16015625,44791.40234375,57.6654256347753,20.6264564439756,23.668306,0,0,0,40,4449,300.19115,44781.28125,,,,,,,,,,,,,0,,,,0.00245,,,,,,299.99200435,,,,
,28751511.53,299.9951172,39845.65625,0.010026366110081,0.000130364298629197,1,0.999253354069792,40.0298881530762,1.99991882637474,28.3199995756149,0.102538286661194,0.0832292618172366,2.5,0.00561197185391631,0.0100223774749268,0.00561841040104603,299.9951172,299.9951172,39843.2421875,39848.0703125,57.7138866029676,20.6260335034976,23.288654,0,0,0,40,4449,300.1988,39845.65625,,,,,,,,,,,,,0,,,,0.00245,,,,,,299.9951172,,,,
,28751608.27,299.9896851,35011.19140625,0.00999825066398501,0.000122729736726838,1,0.999253354069792,40.0298881530762,2.00014774225597,28.3100008964539,0.102467136473479,0.0818203047795088,2.5,0.00549163673371019,0.00999433959252686,0.00549806798209996,299.9896851,299.9896851,35006.05859375,35016.32421875,57.6927826329484,20.6231658019347,23.668306,0,0,0,40,4449,300.20535,35011.19140625,,,,,,,,,,,,,0,,,,0,,,,,,299.9896851,,,,
,28751705.755,299.9893494,30136.1259765625,0.00997851987144997,0.000118672401078862,1,0.999253354069792,40.0298881530762,2.00005180834065,28.3199995756149,0.102410173705639,0.0807894627344431,2.5,0.00540436317995703,0.00997466278272802,0.00541079042280545,299.9893494,299.9893494,30133.7890625,30138.462890625,57.7514047718907,20.6259077419769,23.668306,0,0,0,40,4449,300.2161,30136.1259765625,,,,,,,,,,,,,0,,,,0,,,,,,299.9893494,,,,
,28751801.995,299.9858704,25326.2587890625,0.00992911204903703,0.000114488819677533,1,0.999253354069792,40.0298881530762,1.99985693670675,28.3100008964539,0.101915556033426,0.0802551898870716,2.5,0.00536640300864361,0.00992527864055568,0.00537280554002695,299.9858704,299.9858704,25321.1953125,25331.322265625,57.8217513386215,20.6265968980467,23.668306,0,0,0,40,4449,300.2255,25326.2587890625,,,,,,,,,,,,,0,,,,0.00245,,,,,,299.9858704,,,,
,28751897.805,299.9908142,20538.9765625,0.00985588160367717,0.000127243064283863,1,0.999253354069792,40.0298881530762,1.99981909812258,28.3100008964539,0.101199513156735,0.0794453590407891,2.5,0.00530770400000498,0.00985208366603262,0.00531406449884581,299.9908142,299.9908142,20533.953125,20544,57.7396803441023,20.6280504994728,24.047956,0,0,0,40,4449,300.2448,20538.9765625,,,,,,,,,,,,,0,,,,-0.00735,,,,,,299.9908142,,,,
,28751996.37,299.9889221,15614.45703125,0.00955670964392734,0.000151277145359603,1,0.999253354069792,40.0298881530762,1.99977386897428,28.3100008964539,0.0978269348123374,0.0787552933048225,2.5,0.00529874713943754,0.00955292318594362,0.0053049161595708,299.9889221,299.9889221,15607.0478515625,15621.8662109375,57.6794949481215,20.6287864726436,23.668306,0,0,0,40,4449,300.24735,15614.45703125,,,,,,,,,,,,,0,,,,0.00245,,,,,,299.9889221,,,,
,28752089.625,299.9931946,10954.9223632813,0.00940296866619562,0.000111441299082024,1,0.999253354069792,40.0298881530762,1.99968970915117,28.3100008964539,0.0964155235449632,0.0765255343635041,2.5,0.00512875197539188,0.00939929437839724,0.00513482851664185,299.9931946,299.9931946,10949.734375,10960.1103515625,57.79283108341,20.6297489795139,23.288654,0,0,0,40,4449,300.24635,10954.9223632813,,,,,,,,,,,,,0,,,,0,,,,,,299.9931946,,,,
,28752186.89,299.987915,6092.0419921875,0.00892709755643671,0.000120168495322484,1,0.999253354069792,40.0298881530762,1.99984102820971,28.3100008964539,0.0914879565829848,0.0729736774894654,2.5,0.00489706914931567,0.00892358942035194,0.00490284278063603,299.987915,299.987915,6082.0947265625,6101.9892578125,57.78266991266,20.6295547260134,24.047956,0,0,0,40,4449,300.24935,6092.0419921875,,,,,,,,,,,,,0,,,,0,,,,,,299.987915,,,,
,28752280.825,299.9923096,1395.63330078125,0.00708354543953421,9.81308006158182E-5,1,0.999253354069792,40.0298881530762,2.00003293276321,28.3100008964539,0.0725410653804014,0.058256201411317,2.5,0.00391641625784775,0.00708073836429274,0.00392099896739732,299.9923096,299.9923096,1393.45227050781,1397.81433105469,57.8983509335061,20.6249655083075,23.668306,0,0,0,40,4449,300.2509,1395.63330078125,,,,,,,,,,,,,0,,,,0.0049,,,,,,299.9923096,,,,
,28752310.7,299.9914856,-0.357758671045303,-0.000148890321187549,2.87675457800987E-6,1,0.999253354069792,40.0298881530762,2.00001677192646,28.3199995756149,-0.00152802064554384,-0.00120426318026526,0.25,-8.05478835785005E-5,-0.000148832492066783,-8.06442728451506E-5,299.9914856,299.9914856,-0.365370541810989,-0.350146800279617,57.8522348508715,20.6233572585455,23.668306,0,0,0,40,4417,300.25915,-0.357758671045303,,,,,,,,,,,,,0,,,,-0.00245,,,,,,299.9914856,,,,