File: data/looselyPackedNP/nanoparticles/vsm/ios-7/rawdata/KWI338_FCW_100OE.DAT
[Header]
; VSM Data File (default extension .dat)
; Copyright (c) 2003-2013, Quantum Design, Inc. All rights reserved.
TITLE,
FILEOPENTIME,28927594.08,12/02/2018,3:27 am
BYAPP,VSM,2.0,2.0
INFO,PPMS VSM Option Release 1.4.10 Build 1,APPNAME
INFO,Quantum Design Linear Motor Servo Controller,MOTOR_MODULE_NAME
INFO,3101-100 M1,MOTOR_HW_VERSION
INFO,MMC1014,MOTOR_SERIAL_NUMBER
INFO,SRV No X-over 01.03.11,MOTOR_SOFTWARE_VERSION
INFO,Quantum Design VSM Detection Module,VSM_MODULE_NAME
INFO,3101-150 F0,VSM_HW_VERSION
INFO,VSM707,VSM_SERIAL_NUMBER
INFO,VSM No X-over 01.02.05 May 20 2008 13:51:47,VSM_SOFTWARE_VERSION
INFO,704,PREAMP_SERIAL_NUMBER
INFO,822,COIL_SERIAL_NUMBER
INFO,0,MOMENT_UNITS
INFO,Maghemite,SAMPLE_MATERIAL
INFO,Oleate Iron Spheres,SAMPLE_COMMENT
INFO,,SAMPLE_MASS
INFO,,SAMPLE_VOLUME
INFO,,SAMPLE_MOLECULAR_WEIGHT
INFO,,SAMPLE_SIZE
INFO,,SAMPLE_SHAPE
DATATYPE,COMMENT,1
DATATYPE,TIME,2
STARTUPAXIS,X,2
STARTUPAXIS,Y1,5
[Data]
Comment,Time Stamp (sec),Temperature (K),Magnetic Field (Oe),Moment (emu),M. Std. Err. (emu),Transport Action,Averaging Time (sec),Frequency (Hz),Peak Amplitude (mm),Center Position (mm),Coil Signal' (mV),Coil Signal" (mV),Range (mV),M. Quad. Signal (emu),M. Raw' (emu),M. Raw" (emu),Min. Temperature (K),Max. Temperature (K),Min. Field (Oe),Max. Field (Oe),Mass (grams),Motor Lag (deg),Pressure (Torr),VSM Status (code),Motor Status (code),Measure Status (code),Measure Count,PPMS Status (code),System Temp. (K),System Field (Oe),Sample Position (deg),Bridge 1 Resistance (ohms),Bridge 1 Excitation (에),Bridge 2 Resistance (ohms),Bridge 2 Excitation (에),Bridge 3 Resistance (ohms),Bridge 3 Excitation (에),Bridge 4 Resistance (ohms),Bridge 4 Excitation (에),Signal 1 Vin (V),Signal 2 Vin (V),Digital Inputs (code),Drive 1 Iout (mA),Drive 1 Ipower (W),Drive 2 Iout (mA),Drive 2 Ipower (W),Pressure (),Map 20 (),Map 21 (),Map 22 (),Map 23 (),Map 24 (),Map 25 (),Map 26 (),Map 27 (),Map 28 (),Map 29 ()
,28927727.825,10.0176134,99.5330276489258,0.000907711410486101,2.94345302626851E-7,1,0.999253354069792,40.0298881530762,1.99051846209666,28.9299990981817,0.0101516869518622,0.00188965621400344,0.25,7.5266729072281E-6,0.000902462899324016,1.1861189214383E-5,10.0176134,10.0176134,99.5330276489258,99.5330276489258,57.1839424669291,20.440773280843,12.278775,0,0,0,40,4369,9.9657,99.5330276489258,,,,,,,,,,,,,0,,,,0,,,,,,10.0176134,,,,
,28927838.86,12.5982647,99.5330276489258,0.000902085500147921,3.30492031154711E-7,1,0.999253354069792,40.0298881530762,1.99023696230452,28.9299990981817,0.0100880136704774,0.00187397878572995,0.25,7.14938301080348E-6,0.000896866732881827,1.14588770086099E-5,12.5982647,12.5982647,99.5330276489258,99.5330276489258,57.1831608384099,20.4441562940529,13.038077,0,0,0,40,4370,12.6668,99.5330276489258,,,,,,,,,,,,,0,,,,0,,,,,,12.5982647,,,,
,28927956.58,15.5005207,99.5330276489258,0.000896115219541281,3.72058781166239E-7,1,0.999253354069792,40.0298881530762,1.98996694679319,28.9299990981817,0.0100206486833983,0.00185696269108668,0.25,6.71282592038875E-6,0.000890926188481526,1.09959528687389E-5,15.5005207,15.5005207,99.5330276489258,99.5330276489258,57.1268835850253,20.4546445493431,14.177031,0,0,0,40,4370,15.63845,99.5330276489258,,,,,,,,,,,,,0,,,,-0.00245,,,,,,15.5005207,,,,
,28928076.61,18.5211391,99.5330276489258,0.000888859012524333,3.50825270208027E-7,1,0.999253354069792,40.0298881530762,1.98985521845789,28.9399996399879,0.00993850123387953,0.00184413959595932,0.25,6.86189352703551E-6,0.000883705598120092,1.11131702533219E-5,18.5211391,18.5211391,99.5330276489258,99.5330276489258,57.0424677049483,20.4525803142357,14.556682,0,0,0,40,4370,18.6506,99.5330276489258,,,,,,,,,,,,,0,,,,-0.0049,,,,,,18.5211391,,,,
,28928198.84,21.53302765,99.5330276489258,0.000878609854025786,3.29419471675985E-7,1,0.999253354069792,40.0298881530762,1.98999052302343,28.9600007236004,0.00982433309523331,0.00182695011481997,0.25,7.06611486698553E-6,0.000873556747933449,1.13289752652797E-5,21.4989071,21.5671482,99.5330276489258,99.5330276489258,57.1003082153714,20.4477811977747,14.556682,0,0,0,40,4370,21.7211,99.5330276489258,,,,,,,,,,,,,0,,,,-0.00245,,,,,,21.53302765,,,,
,28928319.715,24.500309,99.5330276489258,0.000866156805794081,3.54272631156548E-7,1,0.999253354069792,40.0298881530762,1.98927350256203,28.9600007236004,0.00968305619887695,0.00179981105352275,0.25,6.76260481552709E-6,0.000861278179281614,1.10951872811983E-5,24.500309,24.500309,99.5330276489258,99.5330276489258,57.3668435404292,20.4588564863932,14.936333,0,0,0,40,4370,24.7656,99.5330276489258,,,,,,,,,,,,,0,,,,-0.00245,,,,,,24.500309,,,,
,28928439.445,27.5138874,99.5330276489258,0.000851730054241416,3.68972752529479E-7,1,0.999253354069792,40.0298881530762,1.98938346551278,28.9600007236004,0.00952382042203494,0.00177232866520158,0.25,6.64113483308911E-6,0.000847101388699094,1.10944296742625E-5,27.5138874,27.5138874,99.5330276489258,99.5330276489258,57.3543374841214,20.4451816065198,15.315984,0,0,0,40,4370,27.7882,99.5330276489258,,,,,,,,,,,,,0,,,,0.00245,,,,,,27.5138874,,,,
,28928574.58,30.8059196,99.5330276489258,,,2,,,,28.9800006103516,,,,,,,30.8059196,30.8059196,99.5330276489258,99.5330276489258,,,15.695635,,,,-99999999,4370,31.1933,99.5330276489258,,,,,,,,,,,,,,,,,,,,,,,30.8059196,,,,
,28928683.48,33.5434723,99.5330276489258,0.000812443870205866,3.3879092300097E-7,1,0.999253354069792,40.0298881530762,1.98978318346627,28.9699994027615,0.00908954307527702,0.00171071945443381,0.25,7.45566773597989E-6,0.000808604871128841,1.22414323137318E-5,33.5434723,33.5434723,99.5330276489258,99.5330276489258,57.3207274577945,20.4353117486538,16.454937,0,0,0,40,4370,33.93265,99.5330276489258,,,,,,,,,,,,,0,,,,0,,,,,,33.5434723,,,,
,28928804.975,36.5265274,99.5330276489258,0.000787990006499409,3.64971199684082E-7,1,0.999253354069792,40.0298881530762,1.99004840406863,28.9699994027615,0.00882149656883332,0.00166276705234244,0.25,7.13889508513588E-6,0.00078469672060042,1.20939523019232E-5,36.5265274,36.5265274,99.5330276489258,99.5330276489258,57.1456426694868,20.4411875281938,15.695635,0,0,0,40,4370,37.00025,99.5330276489258,,,,,,,,,,,,,0,,,,-0.0049,,,,,,36.5265274,,,,
,28928925.35,39.5290031,99.5330276489258,0.000761681939838811,3.54695897907718E-7,1,0.999253354069792,40.0298881530762,1.9900144097184,28.9699994027615,0.00853276303964971,0.00160744653319252,0.25,6.53364249049432E-6,0.000759012111636503,1.16210189210182E-5,39.5290031,39.5290031,99.5330276489258,99.5330276489258,57.251162519583,20.4389938195868,16.454937,0,0,0,40,4370,40.03645,99.5330276489258,,,,,,,,,,,,,0,,,,0,,,,,,39.5290031,,,,
,28929047.555,42.5021782,99.5330276489258,0.000734065017629235,3.18023787796682E-7,1,0.999253354069792,40.0298881530762,1.99001559340034,28.9699994027615,0.00822907063786004,0.0015561347696696,0.25,6.55721358220863E-6,0.000732085154903224,1.17156486402259E-5,42.5021782,42.5021782,99.5330276489258,99.5330276489258,57.1221938139099,20.4386331510648,16.834587,0,0,0,40,4370,43.1332,99.5330276489258,,,,,,,,,,,,,0,,,,0.00245,,,,,,42.5021782,,,,
,28929168.79,45.5187912,99.5330276489258,0.000706196276017436,3.76886188714011E-7,1,0.999253354069792,40.0298881530762,1.98995366085266,28.9699994027615,0.00792371452153991,0.00149753364686489,0.25,6.06334831520158E-6,0.000704927869006839,1.12073626777764E-5,45.5187912,45.5187912,99.5330276489258,99.5330276489258,57.281646031833,20.4407775223181,16.834587,0,0,0,40,4370,46.19645,99.5330276489258,,,,,,,,,,,,,0,,,,-0.0049,,,,,,45.5187912,,,,
,28929292.555,48.5497437,99.5330276489258,0.000677660253125075,3.83548507761836E-7,1,0.999253354069792,40.0298881530762,1.98991016660323,28.9699994027615,0.00761119987343079,0.00143672874807877,0.25,5.58519391001836E-6,0.000677113454138635,1.06155200014833E-5,48.5497437,48.5497437,99.5330276489258,99.5330276489258,57.251162519583,20.4386654969623,17.214239,0,0,0,40,4370,49.3625,99.5330276489258,,,,,,,,,,,,,0,,,,-0.00245,,,,,,48.5497437,,,,
,28929424.48,51.696209,99.5330276489258,,,2,,,,28.9899992895126,,,,,,,51.696209,51.696209,99.5330276489258,99.5330276489258,,,18.732843,,,,-99999999,4374,52.7465,99.5330276489258,,,,,,,,,,,,,,,,,,,,,,,51.696209,,,,
,28929541.205,54.5412979,99.5330276489258,0.000623115060236919,3.18193622877159E-7,1,0.999253354069792,40.0298881530762,1.98935813654895,28.9699994027615,0.00701149350288716,0.00131710747365313,0.25,4.69259330264509E-6,0.000623831744594936,9.22861995173274E-6,54.5412979,54.5412979,99.5330276489258,99.5330276489258,57.1143775287176,20.4440208706034,19.492144,0,0,0,40,4374,55.75385,99.5330276489258,,,,,,,,,,,,,0,,,,-0.00245,,,,,,54.5412979,,,,
,28929664.67,57.5108299,99.5330276489258,0.000597893689997507,3.76208570423902E-7,1,0.999253354069792,40.0298881530762,1.98928745487576,28.9699994027615,0.00673350429214037,0.0012635280641913,0.25,4.54294893800061E-6,0.00059909839599121,8.74588930321118E-6,57.5108299,57.5108299,99.5330276489258,99.5330276489258,57.3793495967368,20.4462857907166,20.631098,0,0,0,40,4374,58.9572,99.5330276489258,,,,,,,,,,,,,0,,,,-0.00245,,,,,,57.5108299,,,,
,28929789.07,60.5060425,99.5330276489258,0.000573430173586962,3.23924627960826E-7,1,0.999253354069792,40.0298881530762,1.9892204006291,28.9699994027615,0.00646179792994268,0.00121726212247146,0.25,4.95414448269783E-6,0.000575012630590845,8.79997236281605E-6,60.5060425,60.5060425,99.5330276489258,99.5330276489258,57.2488176340253,20.4476416283253,21.770052,0,0,0,40,4374,62.1509,99.5330276489258,,,,,,,,,,,,,0,,,,0,,,,,,60.5060425,,,,
,28929913.305,63.5428772,99.5330276489258,0.000548490444174192,3.24357603340323E-7,1,0.999253354069792,40.0298881530762,1.97736654386447,28.9900004863739,0.00615004553509998,0.00115498251625372,0.25,4.63855504674749E-6,0.000550351430112533,8.11547002592278E-6,63.5428772,63.5428772,99.5330276489258,99.5330276489258,57.2230238928907,20.4527034751519,22.529354,0,0,0,40,4374,65.32915,99.5330276489258,,,,,,,,,,,,,0,,,,-0.00245,,,,,,63.5428772,,,,
,28930034.075,66.5314865,99.5330276489258,0.000526552660767435,3.52714754315738E-7,1,0.999253354069792,40.0298881530762,1.97718544139569,28.9900004863739,0.00590735174864309,0.00110438273345334,0.25,4.21739703540469E-6,0.000528604551025981,7.36058624443026E-6,66.5314865,66.5314865,99.5330276489258,99.5330276489258,57.2800827747945,20.4563567388843,22.529354,0,0,0,40,4374,68.3751,99.5330276489258,,,,,,,,,,,,,0,,,,0,,,,,,66.5314865,,,,
,28930155.74,69.5507889,99.5330276489258,0.00050532843250039,3.51003567325265E-7,1,0.999253354069792,40.0298881530762,1.97726986093423,28.9900004863739,0.00567301225697276,0.00105348200020525,0.25,3.62551729113963E-6,0.000507508481946397,6.45366084853303E-6,69.5507889,69.5507889,99.5330276489258,99.5330276489258,57.3605905122753,20.4592970369151,22.909004,0,0,0,40,4374,71.444,99.5330276489258,,,,,,,,,,,,,0,,,,-0.00245,,,,,,69.5507889,,,,
,28930276.7,72.5488892,99.5330276489258,,,2,,,,28.9999998313189,,,,,,,72.5488892,72.5488892,99.5330276489258,99.5330276489258,,,22.909004,,,,-99999999,4374,74.4991,99.5330276489258,,,,,,,,,,,,,,,,,,,,,,,72.5488892,,,,
,28930374.995,75.0033875,99.5330276489258,0.000470239838959653,3.54859779931323E-7,1,0.999253354069792,40.0298881530762,1.97730928796819,28.9900004863739,0.00528332173687993,0.000973798771045367,0.25,3.04041433631482E-6,0.000472528243687949,5.37595096375866E-6,75.0033875,75.0033875,99.5330276489258,99.5330276489258,57.2066096939868,20.4531876571218,23.288654,0,0,0,40,4374,76.9696,99.5330276489258,,,,,,,,,,,,,0,,,,-0.00245,,,,,,75.0033875,,,,
,28930501.42,78.0640869,99.5330276489258,0.00045196217224442,3.90048360713495E-7,1,0.999253354069792,40.0298881530762,1.97755138403426,28.9900004863739,0.00508121617496224,0.000927753188762786,0.25,2.31493382607092E-6,0.00045426767366043,4.40748574134701E-6,78.0640869,78.0640869,99.5330276489258,99.5330276489258,57.241001348833,20.4539666969261,23.668306,0,0,0,40,4374,80.1685,99.5330276489258,,,,,,,,,,,,,0,,,,0.0049,,,,,,78.0640869,,,,
,28930621.085,81.0800858,99.5330276489258,0.00043648193979209,3.52943684504042E-7,1,0.999253354069792,40.0298881530762,1.97753323720312,28.9900004863739,0.00490783357866487,0.000896724519210313,0.25,2.41551163689205E-6,0.000438780279135464,4.31159115502649E-6,81.0800858,81.0800858,99.5330276489258,99.5330276489258,57.2902439455445,20.4573404248157,23.288654,0,0,0,40,4374,83.19975,99.5330276489258,,,,,,,,,,,,,0,,,,-0.00245,,,,,,81.0800858,,,,
,28930724.68,83.628994,99.5330276489258,0.000423463483056829,3.70140768084344E-7,1,0.999253354069792,40.0298881530762,1.98932395928347,28.9900004863739,0.00478953150258602,0.000872588162859018,0.25,2.22394015297459E-6,0.000425741290673628,3.96657026663044E-6,83.5896912,83.6682968,99.5330276489258,99.5330276489258,57.1081245005637,20.4471598245558,23.668306,0,0,0,40,4374,85.79155,99.5330276489258,,,,,,,,,,,,,0,,,,-0.0049,,,,,,83.628994,,,,
,28930842.875,86.5606689,99.5330276489258,0.000409477062357678,3.40277235087933E-7,1,0.999253354069792,40.0298881530762,1.98910498121692,28.9900004863739,0.00463150510963386,0.00084265710421135,0.25,2.15130373676013E-6,0.000411720641198934,3.73777706580585E-6,86.5606689,86.5606689,99.5330276489258,99.5330276489258,57.1941036376791,20.4557765572661,24.047956,0,0,0,40,4374,88.77335,99.5330276489258,,,,,,,,,,,,,0,,,,0,,,,,,86.5606689,,,,
,28930965.14,89.5718689,99.5330276489258,0.000395634092699225,4.0022054621784E-7,1,0.999253354069792,40.0298881530762,1.9891882824787,28.9900004863739,0.00447537771709988,0.000814640203588236,0.25,2.20093970323006E-6,0.000397831471496843,3.64515498531673E-6,89.5718689,89.5718689,99.5330276489258,99.5330276489258,57.0291800201214,20.4558032614859,23.668306,0,0,0,40,4374,91.8361,99.5330276489258,,,,,,,,,,,,,0,,,,0,,,,,,89.5718689,,,,
,28931082.84,92.5493469,99.5330276489258,0.000382838409092889,3.34432230625524E-7,1,0.999253354069792,40.0298881530762,1.98975911399587,28.9900004863739,0.00433262479457822,0.000785207431298574,0.25,1.91068471009556E-6,0.000384984904043769,3.23084100404175E-6,92.5493469,92.5493469,99.5330276489258,99.5330276489258,57.1214121853907,20.4542663434549,24.047956,0,0,0,40,4374,94.79295,99.5330276489258,,,,,,,,,,,,,0,,,,0.00245,,,,,,92.5493469,,,,
,28931205.14,95.6064758,99.5330276489258,0.000372652028213096,3.64419510197119E-7,1,0.999253354069792,40.0298881530762,1.98931170304355,28.9900004863739,0.00421539305301129,0.000770937282068171,0.25,2.52671108967015E-6,0.000374752214211703,3.74528687643546E-6,95.6064758,95.6064758,99.5330276489258,99.5330276489258,57.014329078256,20.4520111491673,24.047956,0,0,0,40,4374,97.86365,99.5330276489258,,,,,,,,,,,,,0,,,,0,,,,,,95.6064758,,,,
,28931321.785,98.5013123,99.5330276489258,0.000362094255980994,3.10872682558659E-7,1,0.999253354069792,40.0298881530762,1.98926712512341,28.9900004863739,0.00409550505711602,0.000751639764552315,0.25,2.73902549599418E-6,0.000364140946982286,3.86536464054865E-6,98.5013123,98.5013123,99.5330276489258,99.5330276489258,56.9502355396791,20.4540217536732,24.427608,0,0,0,40,4374,100.7846,99.5330276489258,,,,,,,,,,,,,0,,,,0,,,,,,98.5013123,,,,
,28931443.54,101.5009232,99.5330276489258,0.000351508882737914,3.46191395499628E-7,1,0.999253354069792,40.0298881530762,1.98937047128492,28.9900004863739,0.00397569173973698,0.000731494253020758,0.25,2.87180556478495E-6,0.000353497947430142,3.91097511701995E-6,101.5009232,101.5009232,99.5330276489258,99.5330276489258,57.1995750373137,20.4508999119411,24.807261,0,0,0,40,4374,103.8565,99.5330276489258,,,,,,,,,,,,,0,,,,0,,,,,,101.5009232,,,,
,28931564.96,104.5449448,99.5330276489258,0.00033868146039342,3.13132968342632E-7,1,0.999253354069792,40.0298881530762,2.00239583073915,28.9900004863739,0.00385662003596947,0.000697255735714455,0.25,1.76705865828736E-6,0.000340599084574265,2.71427443501153E-6,104.5449448,104.5449448,99.5330276489258,99.5330276489258,57.0455942190253,20.4475013549681,24.427608,0,0,0,40,4374,106.8955,99.5330276489258,,,,,,,,,,,,,0,,,,0,,,,,,104.5449448,,,,
,28931686.215,107.5146103,99.5330276489258,0.000329566437623244,3.70770463988622E-7,1,0.999253354069792,40.0298881530762,2.00238445582549,28.9900004863739,0.00375313258220177,0.000676333179361447,0.25,1.57450907698624E-6,0.000331428638876128,2.45195993818319E-6,107.5146103,107.5146103,99.5330276489258,99.5330276489258,57.1448610409676,20.4532963790441,24.427608,0,0,0,40,4374,109.9588,99.5330276489258,,,,,,,,,,,,,0,,,,0,,,,,,107.5146103,,,,
,28931806.17,110.5340195,99.5330276489258,0.000321048740985772,3.30991187921447E-7,1,0.999253354069792,40.0298881530762,2.00213864025697,28.9900004863739,0.00365619323528,0.00065548988289041,0.25,1.28484276631906E-6,0.000322856136974373,2.09988298258732E-6,110.5340195,110.5340195,99.5330276489258,99.5330276489258,57.1894138665637,20.4568393545185,24.807261,0,0,0,40,4374,112.9794,99.5330276489258,,,,,,,,,,,,,0,,,,0.00245,,,,,,110.5340195,,,,
,28931927.86,113.5428772,99.5330276489258,0.000312270001923229,3.49267721179185E-7,1,0.999253354069792,40.0298881530762,2.00228660304888,28.9900004863739,0.00355666980364834,0.000635852343369087,0.25,1.13152447028855E-6,0.000314019158516091,1.88886083399567E-6,113.5428772,113.5428772,99.5330276489258,99.5330276489258,57.3480844559676,20.4560773293802,24.807261,0,0,0,40,4374,116.0408,99.5330276489258,,,,,,,,,,,,,0,,,,-0.0049,,,,,,113.5428772,,,,
,28932046.735,116.504715,99.5330276489258,0.000303362345929416,2.63640276807787E-7,1,0.999253354069792,40.0298881530762,1.98949753277642,28.9900004863739,0.00343442648217491,0.00061163282172477,0.25,9.2687049280057E-7,0.000305051325338318,1.63131541877534E-6,116.504715,116.504715,99.5330276489258,99.5330276489258,57.0901470446214,20.4557698215501,25.186911,0,0,0,40,4374,119.0227,99.5330276489258,,,,,,,,,,,,,0,,,,0,,,,,,116.504715,,,,
,28932170.14,119.5519867,99.5330276489258,0.000296125730650813,3.29160719650781E-7,1,0.999253354069792,40.0298881530762,1.98987152918677,28.9900004863739,0.00335257530710118,0.000599336794279223,0.25,1.12818704538542E-6,0.000297761640186705,1.78865526308874E-6,119.5519867,119.5519867,99.5330276489258,99.5330276489258,57.0737328457176,20.45015584726,25.186911,0,0,0,40,4374,122.12175,99.5330276489258,,,,,,,,,,,,,0,,,,0,,,,,,119.5519867,,,,
,28932290.145,122.5426254,99.5330276489258,0.000288337086675166,3.48002804542896E-7,1,0.999253354069792,40.0298881530762,1.99057537823212,28.9900004863739,0.00326549492194861,0.000582914252551103,0.25,1.05006592958479E-6,0.00028991689252802,1.66794569505152E-6,122.5426254,122.5426254,99.5330276489258,99.5330276489258,57.3316702570638,20.4449817286261,25.186911,0,0,0,40,4374,125.1429,99.5330276489258,,,,,,,,,,,,,0,,,,-0.00245,,,,,,122.5426254,,,,
,28932409.275,125.555069,99.5330276489258,0.000281840972644445,3.35350660946605E-7,1,0.999253354069792,40.0298881530762,1.99018724216432,28.9699994027615,0.00319159472520165,0.00056720392797234,0.25,8.32837804172047E-7,0.000283371214049459,1.41353783459436E-6,125.555069,125.555069,99.5330276489258,99.5330276489258,57.2761746321984,20.4516142675263,25.186911,0,0,0,40,4374,128.1061,99.5330276489258,,,,,,,,,,,,,0,,,,0,,,,,,125.555069,,,,
,28932529.96,128.5059967,99.5330276489258,0.000275037465082226,3.84160698989036E-7,1,0.999253354069792,40.0298881530762,1.98996187092388,28.9699994027615,0.003113622660766,0.000555876320887855,0.25,1.04992697876383E-6,0.000276515834099228,1.59707445759438E-6,128.5059967,128.5059967,99.5330276489258,99.5330276489258,57.0283983916022,20.4445465674221,25.566563,0,0,0,40,4374,131.1698,99.5330276489258,,,,,,,,,,,,,0,,,,0.00245,,,,,,128.5059967,,,,
,28932649.03,131.5020447,99.5330276489258,0.000268475069566309,3.68066041510854E-7,1,0.999253354069792,40.0298881530762,1.99011351793437,28.9699994027615,0.00304007125917244,0.000538648306986614,0.25,6.92379158057329E-7,0.000269903299599496,1.20629976003539E-6,131.5020447,131.5020447,99.5330276489258,99.5330276489258,57.1534589546791,20.4432395190127,25.566563,0,0,0,40,4374,134.1478,99.5330276489258,,,,,,,,,,,,,0,,,,0,,,,,,131.5020447,,,,
,28932768.555,134.526474,99.5330276489258,0.000256535988010333,3.50557556061301E-7,1,0.999253354069792,40.0298881530762,1.98979250344227,28.9699994027615,0.00290406908986917,0.000515640201101679,0.25,7.71111597332288E-7,0.00025788468174384,1.24635282344436E-6,134.526474,134.526474,99.5330276489258,99.5330276489258,57.0205821064099,20.4456740514464,25.566563,0,0,0,40,4374,137.1264,99.5330276489258,,,,,,,,,,,,,0,,,,0,,,,,,134.526474,,,,
,28932892.12,137.5230408,99.5330276489258,0.000255199000244666,3.62342029999886E-7,1,0.999253354069792,40.0298881530762,2.00249550319222,28.9699994027615,0.00290609990319743,0.000517490070907266,0.25,9.09615615869096E-7,0.000256524290032341,1.36721272832383E-6,137.5230408,137.5230408,99.5330276489258,99.5330276489258,56.9306948266983,20.4482963934201,25.186911,0,0,0,40,4374,140.236,99.5330276489258,,,,,,,,,,,,,0,,,,0,,,,,,137.5230408,,,,
,28933013.15,140.5435944,99.5330276489258,0.000249712366605818,3.24019233714763E-7,1,0.999253354069792,40.0298881530762,2.00255097086804,28.9699994027615,0.00284360552457868,0.000505774514212167,0.25,8.54194616777491E-7,0.00025099253916882,1.28749312413145E-6,140.5435944,140.5435944,99.5330276489258,99.5330276489258,56.6883899857368,20.4505512544368,25.946213,0,0,0,40,4374,143.2846,99.5330276489258,,,,,,,,,,,,,0,,,,-0.0049,,,,,,140.5435944,,,,
,28933131.32,143.5324402,99.5330276489258,0.000244523864291121,3.43060988219821E-7,1,0.999253354069792,40.0298881530762,2.00221836537582,28.9699994027615,0.00278533637873667,0.000486849486591211,0.25,1.20106546742041E-7,0.000245761798497799,5.28051679280217E-7,143.5324402,143.5324402,99.5330276489258,99.5330276489258,57.1245386994676,20.4572844918224,25.566563,0,0,0,40,4374,146.243,99.5330276489258,,,,,,,,,,,,,0,,,,0,,,,,,143.5324402,,,,
,28933253.095,146.5482941,99.5330276489258,0.0002390795150447,3.82774179128153E-7,1,0.999253354069792,40.0298881530762,1.99005465975321,28.9699994027615,0.00270515382796875,0.000485727727534736,0.25,1.23412034724768E-6,0.000240270941314264,1.62660712416227E-6,146.5482941,146.5482941,99.5330276489258,99.5330276489258,57.0307432771599,20.4513875775428,25.946213,0,0,0,40,4374,149.2809,99.5330276489258,,,,,,,,,,,,,0,,,,0,,,,,,146.5482941,,,,
,28933372.86,149.5372696,99.5330276489258,0.000234366524370707,3.35245882219733E-7,1,0.999253354069792,40.0298881530762,1.98989095174308,28.9699994027615,0.00265178892655831,0.000473996667580276,0.25,1.03659490353349E-6,0.000235517635954553,1.40948864901502E-6,149.5058289,149.5687103,99.5330276489258,99.5330276489258,57.0557553897753,20.4541308715089,25.946213,0,0,0,40,4374,152.2945,99.5330276489258,,,,,,,,,,,,,0,,,,-0.00245,,,,,,149.5372696,,,,
,28933493.88,152.5352173,99.5330276489258,0.000229386368370673,3.73651543531207E-7,1,0.999253354069792,40.0298881530762,1.98958916381126,28.9699994027615,0.00259439465877459,0.000466550852920802,0.25,1.26562906908407E-6,0.000230495393878476,1.62159206423253E-6,152.5352173,152.5352173,99.5330276489258,99.5330276489258,57.1706547821022,20.4628135509841,25.566563,0,0,0,40,4374,155.3347,99.5330276489258,,,,,,,,,,,,,0,,,,0,,,,,,152.5352173,,,,
,28933612.06,155.5216064,99.5330276489258,0.000224746452742719,3.8744300225219E-7,1,0.999253354069792,40.0298881530762,1.98935484270075,28.9699994027615,0.00254087465425196,0.000460251057978642,0.25,1.53388408562001E-6,0.00022581532043335,1.87484047393264E-6,155.5216064,155.5216064,99.5330276489258,99.5330276489258,57.0393411908714,20.4604505648846,25.946213,0,0,0,40,4374,158.2881,99.5330276489258,,,,,,,,,,,,,0,,,,-0.0049,,,,,,155.5216064,,,,
,28933733.79,158.5672913,99.5330276489258,0.000219269881226696,3.41391508144878E-7,1,0.999253354069792,40.0298881530762,1.98954935184176,28.9600007236004,0.00247930431336492,0.000447252731680644,0.25,1.34706213542495E-6,0.000220295359674865,1.67020597089421E-6,158.5672913,158.5672913,99.5330276489258,99.5330276489258,56.9392927404099,20.4573933217618,25.946213,0,0,0,40,4374,161.3425,99.5330276489258,,,,,,,,,,,,,0,,,,0,,,,,,158.5672913,,,,
,28933854.45,161.5467529,99.5330276489258,0.000215060823268862,3.50573969679693E-7,1,0.999253354069792,40.0298881530762,1.98954479860308,28.9600007236004,0.00243301972514038,0.000429974144011499,0.25,5.64221567514874E-7,0.000216050489179642,8.69597644770336E-7,161.5467529,161.5467529,99.5330276489258,99.5330276489258,57.0307432771599,20.4573561296828,26.325863,0,0,0,40,4374,164.36715,99.5330276489258,,,,,,,,,,,,,0,,,,-0.00245,,,,,,161.5467529,,,,
,28933972.83,164.5194855,99.5330276489258,0.000210592454468582,3.44434471383578E-7,1,0.999253354069792,40.0298881530762,1.98959689947564,28.9600007236004,0.00238273581908788,0.00041870894946847,0.25,3.55766458122973E-7,0.000211544647331174,6.46625376847942E-7,164.5194855,164.5194855,99.5330276489258,99.5330276489258,57.2152076076984,20.4533138218737,26.325863,0,0,0,40,4374,167.3264,99.5330276489258,,,,,,,,,,,,,0,,,,-0.00245,,,,,,164.5194855,,,,
,28934071.87,167.00630185,99.5330276489258,0.000207757183573344,3.88607977820875E-7,1,0.999253354069792,40.0298881530762,1.98955739212734,28.9500001817942,0.00234996121608645,0.000415841217752554,0.25,6.04582761259886E-7,0.000208681801873775,8.86916252330439E-7,166.9796295,167.0329742,99.5330276489258,99.5330276489258,56.7563916669098,20.4544581320485,26.325863,0,0,0,40,4374,169.81155,99.5330276489258,,,,,,,,,,,,,0,,,,0,,,,,,167.00630185,,,,
,28934193.9,170.0205841,99.5330276489258,0.000203710633523279,3.65714053393797E-7,1,0.999253354069792,40.0298881530762,1.98937719548475,28.9500001817942,0.00230389893541738,0.000407075667341619,0.25,5.46602498351052E-7,0.000204599925026534,8.16648173500114E-7,170.0205841,170.0205841,99.5330276489258,99.5330276489258,57.0799858738714,20.4557324122515,26.705515,0,0,0,40,4374,172.8515,99.5330276489258,,,,,,,,,,,,,0,,,,0,,,,,,170.0205841,,,,
,28934313.625,173.0535431,99.5330276489258,0.000199194738086131,3.70686522691511E-7,1,0.999253354069792,40.0298881530762,1.98906176007406,28.9500001817942,0.00225218655425984,0.000398543477504001,0.25,5.92301221713722E-7,0.000200046843281717,8.50572998265914E-7,173.0535431,173.0535431,99.5330276489258,99.5330276489258,57.0166739638137,20.4674195816409,26.705515,0,0,0,40,4374,175.8477,99.5330276489258,,,,,,,,,,,,,0,,,,0.0049,,,,,,173.0535431,,,,
,28934432.815,176.0446777,99.5330276489258,0.000195291318871173,3.53447261697078E-7,1,0.999253354069792,40.0298881530762,1.98905892157877,28.9500001817942,0.00220720976418778,0.000394424849960105,0.25,9.1559771350185E-7,0.000196109243936153,1.16459677898314E-6,176.0446777,176.0446777,99.5330276489258,99.5330276489258,57.115940785756,20.4627219809592,26.325863,0,0,0,40,4374,178.8307,99.5330276489258,,,,,,,,,,,,,0,,,,0,,,,,,176.0446777,,,,
,28934534.555,178.548584,99.5330276489258,0.0001928422772619,4.03165281220463E-7,1,0.999253354069792,40.0298881530762,1.98912205855593,28.9399996399879,0.00217971882454628,0.000387833668151393,0.25,7.64625584954748E-7,0.000193635852877075,1.00538086327053E-6,178.548584,178.548584,99.5330276489258,99.5330276489258,56.9439825115252,20.4603666349285,26.705515,0,0,0,40,4374,181.37225,99.5330276489258,,,,,,,,,,,,,0,,,,0.0049,,,,,,178.548584,,,,
,28934653.71,181.5025787,99.5330276489258,0.000191264076515253,3.54110773895307E-7,1,0.999253354069792,40.0298881530762,1.98907994590428,28.9399996399879,0.0021608648739632,0.000389114026956689,0.25,1.16092262868603E-6,0.000192033781870163,1.39619837376252E-6,181.5025787,181.5025787,99.5330276489258,99.5330276489258,57.0409044479099,20.4601998295956,27.085165,0,0,0,40,4374,184.3985,99.5330276489258,,,,,,,,,,,,,0,,,,0.0049,,,,,,181.5025787,,,,
,28934773.565,184.506546,99.5330276489258,0.000126705493819193,1.58276883979033E-6,1,0.999253354069792,40.0298881530762,1.989178654367,28.9399996399879,0.00135282188170726,0.000710098521509845,0.25,4.07690177281525E-5,0.000127156639865004,4.10792595160524E-5,184.506546,184.506546,99.5330276489258,99.5330276489258,57.047939104583,20.4635864191835,27.085165,0,0,0,40,4374,187.3897,99.5330276489258,,,,,,,,,,,,,0,,,,-0.00245,,,,,,184.506546,,,,
touchdown = 18.580000847578 mm,28934907.59,187.903717,99.5330276489258,0.000123086949652133,4.03776009030549E-6,1,0.999253354069792,40.0298881530762,1.97737960824963,28.9399996399879,0.00131385486210282,0.000644174973257101,0.25,3.59024194921436E-5,0.0001235176838612,3.61821867999977E-5,187.903717,187.903717,99.5330276489258,99.5330276489258,56.8142321773329,20.464252810412,27.085165,0,0,0,40,4374,190.7264,99.5330276489258,,,,,,,,,,,,,0,,,,0,,,,,,187.903717,,,,
,28935014.095,190.5358124,99.5330276489258,0.000112247643288931,3.95778535349708E-6,1,0.999253354069792,40.0298881530762,1.9775031470545,28.9399996399879,0.00119049296771723,0.000631423350933012,0.25,3.66551493835642E-5,0.000112627502244575,3.69200159194882E-5,190.5080414,190.5635834,99.5330276489258,99.5330276489258,56.7845302936022,20.455971734466,27.085165,0,0,0,40,4374,193.391,99.5330276489258,,,,,,,,,,,,,0,,,,0,,,,,,190.5358124,,,,
,28935133.92,193.5377502,99.5330276489258,0.000106765366516978,2.83568038218907E-6,1,0.999253354069792,40.0298881530762,1.97673932502256,28.9399996399879,0.00112714705986588,0.000627279371678316,0.25,3.72671164099406E-5,0.000107114717206802,3.75222041720105E-5,193.5377502,193.5377502,99.5330276489258,99.5330276489258,56.983845566006,20.4793868522985,26.705515,0,0,0,40,4374,196.3929,99.5330276489258,,,,,,,,,,,,,0,,,,-0.0049,,,,,,193.5377502,,,,
,28935255.4,196.5191345,99.5330276489258,9.97404459451713E-5,2.4993747962706E-6,1,0.999253354069792,40.0298881530762,1.97721480150345,28.9399996399879,0.00104702068507959,0.000621286293668343,0.25,3.79486941240282E-5,0.000100054729838837,3.81927421746869E-5,196.5191345,196.5191345,99.5330276489258,99.5330276489258,56.9705578811791,20.4630152382149,27.085165,0,0,0,40,4374,199.44675,99.5330276489258,,,,,,,,,,,,,0,,,,0,,,,,,196.5191345,,,,
,28935376.3,199.5319519,99.5330276489258,9.32311784682542E-5,2.7604210696982E-6,1,0.999253354069792,40.0298881530762,1.98907440670579,28.9299990981817,0.000978436452491608,0.000617260583682639,0.25,3.84153446840742E-5,9.35135503788394E-5,3.86483492613267E-5,199.5319519,199.5319519,99.5330276489258,99.5330276489258,56.8048526351022,20.4586522374087,27.464817,0,0,0,40,4374,202.4799,99.5330276489258,,,,,,,,,,,,,0,,,,0,,,,,,199.5319519,,,,
,28935494.595,202.50309755,99.5330276489258,9.00325762204299E-5,2.40795554590794E-6,1,0.999253354069792,40.0298881530762,1.98925849889238,28.9299990981817,0.000933624361430474,0.000660834345530679,0.25,4.28276986217508E-5,9.02913241520658E-5,4.3066753008594E-5,202.4741516,202.5320435,99.5330276489258,99.5330276489258,57.065134932006,20.456479924546,27.464817,0,0,0,40,4374,205.4391,99.5330276489258,,,,,,,,,,,,,0,,,,0,,,,,,202.50309755,,,,
,28935617.065,205.5909119,99.5330276489258,8.79521429489518E-5,3.08883134266081E-6,1,0.999253354069792,40.0298881530762,1.98925898738602,28.9299990981817,0.000907989784121313,0.000668414816430342,0.25,4.38670355476077E-5,8.81947828777618E-5,4.41013188840279E-5,205.5909119,205.5909119,99.5330276489258,99.5330276489258,57.1151591572368,20.4597692172328,27.085165,0,0,0,40,4374,208.4996,99.5330276489258,,,,,,,,,,,,,0,,,,0.0049,,,,,,205.5909119,,,,
touchdown = 18.5599997639656 mm,28935743.705,208.7496643,99.5330276489258,8.66596774487985E-5,2.54579797293039E-6,1,0.999253354069792,40.0298881530762,1.98947917102335,28.9200004190207,0.000878080734943942,0.000754079362101922,0.25,5.16720232993763E-5,8.68820520552837E-5,5.19235050364906E-5,208.7496643,208.7496643,99.5330276489258,99.5330276489258,56.9619599674676,20.4483585133396,27.464817,0,0,0,40,4374,211.6869,99.5330276489258,,,,,,,,,,,,,0,,,,-0.0049,,,,,,208.7496643,,,,
,28935854.135,211.5110931,99.5330276489258,8.3704457322455E-5,3.07886371082789E-6,1,0.999253354069792,40.0298881530762,1.98910428520432,28.9200004190207,0.000847748428055737,0.000729134036665168,0.25,4.99967156898469E-5,8.39123195216528E-5,5.0233997677171E-5,211.5110931,211.5110931,99.5330276489258,99.5330276489258,56.9072459711214,20.4631396703715,27.844467,0,0,0,40,4374,214.4348,99.5330276489258,,,,,,,,,,,,,0,,,,0,,,,,,211.5110931,,,,
,28935977.015,214.5576782,99.5330276489258,8.44905457281883E-5,2.67597816817848E-6,1,0.999253354069792,40.0298881530762,1.98930200459965,28.9200004190207,0.000840599657455162,0.000823053911303041,0.25,5.81738050314896E-5,8.46851245151926E-5,5.84296862270933E-5,214.5576782,214.5576782,99.5330276489258,99.5330276489258,57.0127658212176,20.4574911642388,27.844467,0,0,0,40,4374,217.5122,99.5330276489258,,,,,,,,,,,,,0,,,,-0.0049,,,,,,214.5576782,,,,
,28936095.87,217.513382,99.5330276489258,8.70800076024822E-5,1.29969523194482E-6,1,0.999253354069792,40.0298881530762,1.98942562764739,28.9200004190207,0.00085287769884556,0.000925805001846243,0.25,6.68221722746676E-5,8.72662880004187E-5,6.70983134569727E-5,217.513382,217.513382,99.5330276489258,99.5330276489258,56.9134989992753,20.4631840106874,27.464817,0,0,0,40,4374,220.4888,99.5330276489258,,,,,,,,,,,,,0,,,,0.0049,,,,,,217.513382,,,,
,28936217.61,220.56375885,99.5330276489258,8.92481684172549E-5,1.14204804130827E-6,1,0.999253354069792,40.0298881530762,1.9893540431325,28.9200004190207,0.000876400497211566,0.000934929372092056,0.25,6.72659467465017E-5,8.9432162700686E-5,6.75371060655894E-5,220.5332642,220.5942535,99.5330276489258,99.5330276489258,56.8032893780637,20.4594459110411,27.464817,0,0,0,40,4374,223.54485,99.5330276489258,,,,,,,,,,,,,0,,,,0,,,,,,220.56375885,,,,
,28936336.925,223.5435791,99.5330276489258,8.7446572940847E-5,1.26305147067651E-6,1,0.999253354069792,40.0298881530762,1.98934086992819,28.9200004190207,0.000855205998696151,0.000935681930536161,0.25,6.76552304894734E-5,8.76173861254327E-5,6.79176057507804E-5,223.5435791,223.5435791,99.5330276489258,99.5330276489258,56.9095908566791,20.4623872065696,28.224119,0,0,0,40,4374,226.5255,99.5330276489258,,,,,,,,,,,,,0,,,,-0.0049,,,,,,223.5435791,,,,
,28936455.455,226.5103455,99.5330276489258,8.72320860922976E-5,1.34657560992387E-6,1,0.999253354069792,40.0298881530762,1.98918591613222,28.9200004190207,0.000857564697701974,0.000906744968038356,0.25,6.51460112317316E-5,8.73967905708915E-5,6.5393612273462E-5,226.5103455,226.5103455,99.5330276489258,99.5330276489258,56.8204852054868,20.4628505123816,27.844467,0,0,0,40,4374,229.49705,99.5330276489258,,,,,,,,,,,,,0,,,,-0.00245,,,,,,226.5103455,,,,
touchdown = 18.5499992221594 mm,28936577.4,229.5645447,99.5330276489258,8.49013160741058E-5,1.23326312919599E-6,1,0.999253354069792,40.0298881530762,1.98955452990131,28.8999993354082,0.000827589794991738,0.0009236914519166,0.25,6.70460071823514E-5,8.50503789279067E-5,6.72880943654241E-5,229.5645447,229.5645447,99.5330276489258,99.5330276489258,56.6422739031022,20.4578323503429,27.464817,0,0,0,40,4374,232.5793,99.5330276489258,,,,,,,,,,,,,0,,,,0.00245,,,,,,229.5645447,,,,
,28936697.755,232.5227051,99.5330276489258,8.46899284980918E-5,1.22025330291659E-6,1,0.999253354069792,40.0298881530762,1.98921842779922,28.8999993354082,0.000827611731462299,0.000907956359667408,0.25,6.57117654988071E-5,8.48319561271588E-5,6.59424999337411E-5,232.5227051,232.5227051,99.5330276489258,99.5330276489258,56.9525804252368,20.4637984477045,27.844467,0,0,0,40,4374,235.5793,99.5330276489258,,,,,,,,,,,,,0,,,,0.00245,,,,,,232.5227051,,,,
,28936816.92,235.5351563,99.5330276489258,7.86923043320028E-5,1.51898379675347E-6,1,0.999253354069792,40.0298881530762,1.98930632024263,28.8999993354082,0.000759679916694524,0.000897117837097786,0.25,6.57982861142211E-5,7.88127397976356E-5,6.60159819519488E-5,235.5351563,235.5351563,99.5330276489258,99.5330276489258,56.689171614256,20.4617140789276,28.224119,0,0,0,40,4374,238.566,99.5330276489258,,,,,,,,,,,,,0,,,,-0.00245,,,,,,235.5351563,,,,
,28936938.04,238.537262,99.5330276489258,7.89954409265501E-5,1.56668748327898E-6,1,0.999253354069792,40.0298881530762,1.98908125359787,28.8999993354082,0.000763496275880923,0.00089437766650829,0.25,6.55207190770914E-5,7.91094304336959E-5,6.57301722792251E-5,238.537262,238.537262,99.5330276489258,99.5330276489258,56.8931766577752,20.4634440395584,28.224119,0,0,0,40,4374,241.5999,99.5330276489258,,,,,,,,,,,,,0,,,,0,,,,,,238.537262,,,,
,28937039.335,241.0467377,99.5330276489258,8.20337367271883E-5,1.3966967775406E-6,1,0.999253354069792,40.0298881530762,2.00238673673053,28.8900006562471,0.000809587153751188,0.000867025062622979,0.25,6.2091062343808E-5,8.21507261425745E-5,6.22894156492641E-5,241.0467377,241.0467377,99.5330276489258,99.5330276489258,56.922878541506,20.4582050384159,28.224119,0,0,0,40,4374,244.1356,99.5330276489258,,,,,,,,,,,,,0,,,,0,,,,,,241.0467377,,,,
,28937156.85,244.0104675,99.5330276489258,7.68513237844434E-5,2.08370681361809E-6,1,0.999253354069792,40.0298881530762,2.00245904340618,28.8900006562471,0.000749970242913235,0.000860787458862119,0.25,6.24469287819184E-5,7.69500723583231E-5,6.26341907741016E-5,244.0104675,244.0104675,99.5330276489258,99.5330276489258,56.9486722826406,20.4600034478769,27.844467,0,0,0,40,4374,247.0882,99.5330276489258,,,,,,,,,,,,,0,,,,-0.0049,,,,,,244.0104675,,,,
,28937277.57,247.0121002,99.5330276489258,7.69720482352874E-5,1.59700600438177E-6,1,0.999253354069792,40.0298881530762,2.00254209055685,28.8900006562471,0.000753604324044698,0.000847688214417337,0.25,6.12785519018143E-5,7.7064646901563E-5,6.14562203293E-5,247.0121002,247.0121002,99.5330276489258,99.5330276489258,56.9220969129868,20.4590150202265,28.224119,0,0,0,40,4374,250.1113,99.5330276489258,,,,,,,,,,,,,0,,,,-0.00245,,,,,,247.0121002,,,,
touchdown = 18.5300000011921 mm,28937410.34,250.2952271,99.5330276489258,7.55589394849604E-5,1.69131287738118E-6,1,0.999253354069792,40.0298881530762,1.9899806416623,28.8900006562471,0.000737404465734184,0.000814702188515164,0.25,5.90608913450989E-5,7.56427776145433E-5,5.92254414048918E-5,250.2952271,250.2952271,99.5330276489258,99.5330276489258,56.6500901882945,20.4497591300789,27.844467,0,0,0,40,4374,253.4632,99.5330276489258,,,,,,,,,,,,,0,,,,0,,,,,,250.2952271,,,,
,28937518.97,253.0216827,99.5330276489258,7.47514210578202E-5,1.64996188365683E-6,1,0.999253354069792,40.0298881530762,1.98960198957761,28.8900006562471,0.000725835443943,0.000825911539729753,0.25,6.02148041641545E-5,7.48263259583227E-5,6.03741411693165E-5,253.0216827,253.0216827,99.5330276489258,99.5330276489258,56.8337728903137,20.4598360394915,28.603769,0,0,0,40,4374,256.15395,99.5330276489258,,,,,,,,,,,,,0,,,,-0.00245,,,,,,253.0216827,,,,
,28937639.04,256.0435791,99.5330276489258,7.68011223329858E-5,1.42873516606224E-6,1,0.999253354069792,40.0298881530762,1.98959666613028,28.8900006562471,0.000753610651247562,0.000802636839385214,0.25,5.78057363294558E-5,7.68737681479503E-5,5.79556970416376E-5,256.0435791,256.0435791,99.5330276489258,99.5330276489258,56.7634263235829,20.4604465137577,28.603769,0,0,0,40,4374,259.1651,99.5330276489258,,,,,,,,,,,,,0,,,,-0.00245,,,,,,256.0435791,,,,
,28937759.2,259.011322,99.5330276489258,7.51424248767454E-5,1.38249537587461E-6,1,0.999253354069792,40.0298881530762,1.98955522067333,28.8900006562471,0.000739605331175431,0.000771616559736906,0.25,5.53538699085413E-5,7.52071429212251E-5,5.54920820572529E-5,259.011322,259.011322,99.5330276489258,99.5330276489258,56.8775440873906,20.4638763431473,28.603769,0,0,0,40,4374,262.17785,99.5330276489258,,,,,,,,,,,,,0,,,,0.00245,,,,,,259.011322,,,,
,28937882.915,262.0890808,99.5330276489258,7.54006837844358E-5,1.51035173827702E-6,1,0.999253354069792,40.0298881530762,1.98954487771913,28.8900006562471,0.000742725143177292,0.000770398148173426,0.25,5.52096375401344E-5,7.54582350801446E-5,5.5340970333235E-5,262.0643616,262.1138,99.5330276489258,99.5330276489258,56.8322096332752,20.460878379327,28.603769,0,0,0,40,4374,265.2808,99.5330276489258,,,,,,,,,,,,,0,,,,0.0049,,,,,,262.0890808,,,,
,28938000.03,265.0164185,99.5330276489258,7.48810792720999E-5,1.12260311161705E-6,1,0.999253354069792,40.0298881530762,1.98946040675499,28.8900006562471,0.000741224864715518,0.000743528981087732,0.25,5.29284554855884E-5,7.49324168289148E-5,5.30500831416052E-5,265.0164185,265.0164185,99.5330276489258,99.5330276489258,56.9361662263329,20.4633837336091,28.603769,0,0,0,40,4374,268.198,99.5330276489258,,,,,,,,,,,,,0,,,,-0.00245,,,,,,265.0164185,,,,
,28938120.795,268.0115356,99.5330276489258,7.48142287465032E-5,1.28978040703972E-6,1,0.999253354069792,40.0298881530762,1.98961699421312,28.8900006562471,0.000744305069167862,0.000721155858986521,0.25,5.09594776812274E-5,7.4859498744636E-5,5.10724392632541E-5,268.0115356,268.0115356,99.5330276489258,99.5330276489258,56.983845566006,20.4603361938224,28.983419,0,0,0,40,4374,271.2074,99.5330276489258,,,,,,,,,,,,,0,,,,0,,,,,,268.0115356,,,,
touchdown = 18.5300000011921 mm,28938247.43,271.1574097,99.5330276489258,7.34217183398997E-5,1.57359048958178E-6,1,0.999253354069792,40.0298881530762,2.00227542380576,28.8900006562471,0.000729025007205928,0.000745324964528495,0.25,5.29526933491612E-5,7.34562449429365E-5,5.30601050857069E-5,271.1574097,271.1574097,99.5330276489258,99.5330276489258,56.6242964471598,20.4633783086012,28.224119,0,0,0,40,4374,274.42355,99.5330276489258,,,,,,,,,,,,,0,,,,0,,,,,,271.1574097,,,,
,28938362.975,274.0516968,99.5330276489258,7.21755948849538E-5,1.42190860031723E-6,1,0.999253354069792,40.0298881530762,2.00203686280576,28.8900006562471,0.000715590552461954,0.000737773548801372,0.25,5.25179422278331E-5,7.22021989003153E-5,5.26178943383327E-5,274.0516968,274.0516968,99.5330276489258,99.5330276489258,56.9861904515637,20.4683748930876,28.603769,0,0,0,40,4374,277.2835,99.5330276489258,,,,,,,,,,,,,0,,,,-0.0049,,,,,,274.0516968,,,,
,28938481.79,277.0148621,99.5330276489258,7.15718946617854E-5,1.55874806606463E-6,1,0.999253354069792,40.0298881530762,2.00188966049035,28.8900006562471,0.000710029156485911,0.000728338009866365,0.25,5.18028085831684E-5,7.1591361860119E-5,5.18955177453965E-5,277.0148621,277.0148621,99.5330276489258,99.5330276489258,56.729816297256,20.4692445760129,28.983419,0,0,0,40,4374,280.23145,99.5330276489258,,,,,,,,,,,,,0,,,,0,,,,,,277.0148621,,,,
,28938602.765,280.0065918,99.5330276489258,7.17251261404769E-5,1.27830539900354E-6,1,0.999253354069792,40.0298881530762,2.00221878996205,28.8900006562471,0.000717557555375725,0.000695502208751737,0.25,4.88791019862125E-5,7.17395896858184E-5,4.89636961373931E-5,280.0065918,280.0065918,99.5330276489258,99.5330276489258,56.8095424062176,20.4648896971624,28.603769,0,0,0,40,4374,283.2649,99.5330276489258,,,,,,,,,,,,,0,,,,0.0049,,,,,,280.0065918,,,,
,28938723.865,283.0419617,99.5330276489258,6.8192643533041E-5,1.82850277471466E-6,1,0.999253354069792,40.0298881530762,2.00217893993507,28.9200004190207,0.000678844957893989,0.000680151384581322,0.25,4.81463103961811E-5,6.81982259585594E-5,4.82220278780796E-5,283.0419617,283.0419617,99.5330276489258,99.5330276489258,56.8626931455252,20.4633071645879,28.983419,0,0,0,40,4374,286.3211,99.5330276489258,,,,,,,,,,,,,0,,,,0.0049,,,,,,283.0419617,,,,
,28938842.955,286.0043945,99.5330276489258,6.94680542816473E-5,1.08388281284211E-6,1,0.999253354069792,40.0298881530762,2.00268540591707,28.9200004190207,0.000697610783531824,0.000658510034069623,0.25,4.60100016328478E-5,6.94689007661067E-5,4.60798909684348E-5,286.0043945,286.0043945,99.5330276489258,99.5330276489258,56.8376810329099,20.4581405938638,28.983419,0,0,0,40,4374,289.3062,99.5330276489258,,,,,,,,,,,,,0,,,,0,,,,,,286.0043945,,,,
,28938963.445,289.0063477,99.5330276489258,6.88999100028408E-5,1.2920494079529E-6,1,0.999253354069792,40.0298881530762,2.00243671373226,28.9200004190207,0.000690046535517059,0.000662827799863889,0.25,4.6502790835578E-5,6.88931330103254E-5,4.65669290130292E-5,289.0063477,289.0063477,99.5330276489258,99.5330276489258,56.912717370756,20.4631306705942,28.983419,0,0,0,40,4374,292.2983,99.5330276489258,,,,,,,,,,,,,0,,,,0,,,,,,289.0063477,,,,
touchdown = 18.5899995267391 mm,28939084.705,292.0349121,99.5330276489258,6.79696786694629E-5,1.20594312527169E-6,1,0.999253354069792,40.0298881530762,1.99018809182253,28.9500001817942,0.000677395442729792,0.000645898273979513,0.25,4.55125015556386E-5,6.79562606757508E-5,4.55701245529039E-5,292.0349121,292.0349121,99.5330276489258,99.5330276489258,56.8275198621599,20.4559126666551,28.983419,0,0,0,40,4374,295.3747,99.5330276489258,,,,,,,,,,,,,0,,,,0.0049,,,,,,292.0349121,,,,
,28939206.46,295.0617981,99.5330276489258,6.64209829566296E-5,1.63724505471326E-6,1,0.999253354069792,40.0298881530762,1.99031735220288,28.9500001817942,0.000660531298672762,0.000639250763198471,0.25,4.51943301644991E-5,6.64005618062878E-5,4.52453830871278E-5,295.0617981,295.0617981,99.5330276489258,99.5330276489258,56.9002113144483,20.4588576536166,29.363071,0,0,0,40,4374,298.40055,99.5330276489258,,,,,,,,,,,,,0,,,,-0.00245,,,,,,295.0617981,,,,
,28939326.975,298.0392456,99.5330276489258,6.67269143600678E-5,1.31587054740564E-6,1,0.999253354069792,40.0298881530762,1.99039768526585,28.9500001817942,0.00066602421778854,0.000627771658161717,0.25,4.41273528874796E-5,6.67005031198091E-5,4.41732230772285E-5,298.0142517,298.0642395,99.5330276489258,99.5330276489258,56.9400743689291,20.4585864558368,29.363071,0,0,0,40,4374,301.4189,99.5330276489258,,,,,,,,,,,,,0,,,,-0.00245,,,,,,298.0392456,,,,
,28939446.865,301.0402832,99.5330276489258,6.73825337619188E-5,1.44374413883779E-6,1,0.999253354069792,40.0298881530762,1.99035961002432,28.9500001817942,0.00067556123948067,0.000616120326249362,0.25,4.29875141118191E-5,6.73500160497678E-5,4.30286418908454E-5,301.0402832,301.0402832,99.5330276489258,99.5330276489258,56.997133250833,20.460478740577,29.363071,0,0,0,40,4374,304.4194,99.5330276489258,,,,,,,,,,,,,0,,,,0,,,,,,301.0402832,,,,
,28939548.795,303.5299988,99.5330276489258,6.53879165792483E-5,9.28077560553626E-7,1,0.999253354069792,40.0298881530762,1.99035600099851,28.999999165535,0.000655402547904576,0.000598433712189329,0.25,4.17691203134093E-5,6.53507917199855E-5,4.18048986409923E-5,303.5299988,303.5299988,99.5330276489258,99.5330276489258,56.9916618511983,20.4550162102081,28.983419,0,0,0,40,4374,306.9687,99.5330276489258,,,,,,,,,,,,,0,,,,-0.00245,,,,,,303.5299988,,,,
,28939669.285,306.5487671,99.5330276489258,6.39534056495133E-5,1.50029208818099E-6,1,0.999253354069792,40.0298881530762,1.99042991290818,28.999999165535,0.000637958118021866,0.000602714471233297,0.25,4.24017263708952E-5,6.39095378471357E-5,4.24314465427966E-5,306.5487671,306.5487671,99.5330276489258,99.5330276489258,57.065134932006,20.4546914292455,28.983419,0,0,0,40,4374,309.9872,99.5330276489258,,,,,,,,,,,,,0,,,,-0.0049,,,,,,306.5487671,,,,
,28939788.785,309.5037231,99.5330276489258,6.37358426919721E-5,1.07113021881462E-6,1,0.999253354069792,40.0298881530762,1.99061602225647,28.999999165535,0.000636616234221081,0.000595835047990082,0.25,4.18302196805098E-5,6.36860079061852E-5,4.18551000850209E-5,309.5037231,309.5037231,99.5330276489258,99.5330276489258,57.1073428720445,20.4557494604871,29.742722,0,0,0,40,4374,312.9845,99.5330276489258,,,,,,,,,,,,,0,,,,-0.00245,,,,,,309.5037231,,,,
touchdown = 18.6999998986721 mm,28939922.935,312.8695374,99.5330276489258,6.17264591339282E-5,1.25280476167966E-6,1,0.999253354069792,40.0298881530762,1.99097221548233,29.0600005537271,0.000616735534432666,0.000576189287699983,0.25,4.04328458246174E-5,6.16712026165827E-5,4.04516566111047E-5,312.8695374,312.8695374,99.5330276489258,99.5330276489258,56.994006736756,20.4451508218732,29.363071,0,0,0,40,4374,316.3812,99.5330276489258,,,,,,,,,,,,,0,,,,0.0049,,,,,,312.8695374,,,,
,28940029.885,315.538208,99.5330276489258,6.27431899589392E-5,1.06120532012977E-6,1,0.999253354069792,40.0298881530762,1.99066795715234,29.0699992328882,0.000628667832568838,0.000574446072175759,0.25,4.01146403135471E-5,6.26819596968466E-5,4.01300744577426E-5,315.538208,315.538208,99.5330276489258,99.5330276489258,56.9611783389483,20.4530807602961,28.983419,0,0,0,40,4374,319.04275,99.5330276489258,,,,,,,,,,,,,0,,,,0,,,,,,315.538208,,,,
,28940151.01,318.5186462,99.5330276489258,6.19172783062265E-5,1.17638874510693E-6,1,0.999253354069792,40.0298881530762,1.99080760726304,29.0600005537271,0.000620770576229251,0.000564560596974218,0.25,3.93826365243581E-5,6.18507380106106E-5,3.93934292560931E-5,318.5186462,318.5186462,99.5330276489258,99.5330276489258,57.1847240954484,20.4525173763962,29.363071,0,0,0,40,4374,322.0834,99.5330276489258,,,,,,,,,,,,,0,,,,0.00245,,,,,,318.5186462,,,,
,28940272.935,321.5368958,99.5330276489258,6.17504950929736E-5,1.0742140626181E-6,1,0.999253354069792,40.0298881530762,1.99102863162226,29.0600005537271,0.000619677156670116,0.000559714927147992,0.25,3.89818215937949E-5,6.16780186020396E-5,3.8988242510446E-5,321.5368958,321.5368958,99.5330276489258,99.5330276489258,56.9744660237753,20.4494954738489,29.363071,0,0,0,40,4374,325.15015,99.5330276489258,,,,,,,,,,,,,0,,,,-0.00245,,,,,,321.5368958,,,,
,28940393.71,324.5554199,99.5330276489258,5.97947934837479E-5,1.25435140039855E-6,1,0.999253354069792,40.0298881530762,1.99058208582525,29.1200000792742,0.000599045832270143,0.000546527526219302,0.25,3.816597178707E-5,5.97182734699828E-5,3.81674432893229E-5,324.5554199,324.5554199,99.5330276489258,99.5330276489258,57.0080760501022,20.4479748143637,29.742722,0,0,0,40,4374,328.1576,99.5330276489258,,,,,,,,,,,,,0,,,,0.00245,,,,,,324.5554199,,,,
,28940512.955,327.5420532,99.5330276489258,6.00468471214352E-5,1.06890132874705E-6,1,0.999253354069792,40.0298881530762,1.99076878532463,29.109999537468,0.000601387337897994,0.000549847358775534,0.25,3.84181063157186E-5,5.99639186363548E-5,3.84151311954932E-5,327.5420532,327.5420532,99.5330276489258,99.5330276489258,57.105779615006,20.4490105356278,29.742722,0,0,0,40,4374,331.1363,99.5330276489258,,,,,,,,,,,,,0,,,,0.0049,,,,,,327.5420532,,,,
,28940634.165,330.5307922,99.5330276489258,5.96760194145727E-5,1.32382664179663E-6,1,0.999253354069792,40.0298881530762,1.99080904343167,29.109999537468,0.000597452743696223,0.000547402047731752,0.25,3.82696625505706E-5,5.95875751121976E-5,3.82622782603184E-5,330.5307922,330.5307922,99.5330276489258,99.5330276489258,57.115940785756,20.4498985251327,30.122374,0,0,0,40,4374,334.19275,99.5330276489258,,,,,,,,,,,,,0,,,,-0.00245,,,,,,330.5307922,,,,
touchdown = 18.8299994915724 mm,28940764.575,333.769104,99.5330276489258,5.76004556297634E-5,1.06361994085989E-6,1,0.999253354069792,40.0298881530762,1.99085460003958,29.2000006884336,0.000580478813292856,0.000506052678760053,0.25,3.49620428912761E-5,5.75100014201215E-5,3.49528183584918E-5,333.769104,333.769104,99.5330276489258,99.5330276489258,57.0198004778906,20.4462461057344,30.122374,0,0,0,40,4374,337.4891,99.5330276489258,,,,,,,,,,,,,0,,,,0,,,,,,333.769104,,,,
,28940876.445,336.5348511,99.5330276489258,5.59548341392699E-5,1.28838436738304E-6,1,0.999253354069792,40.0298881530762,1.99080826109661,29.1900001466274,0.000560542750845163,0.00051052184302517,0.25,3.564946813451E-5,5.58608271153826E-5,3.56347676244671E-5,336.5348511,336.5348511,99.5330276489258,99.5330276489258,56.9494539111599,20.447343804667,29.742722,0,0,0,40,4374,340.2355,99.5330276489258,,,,,,,,,,,,,0,,,,0,,,,,,336.5348511,,,,
,28940997.375,339.5518799,99.5330276489258,5.77828446777129E-5,9.32012607634773E-7,1,0.999253354069792,40.0298881530762,1.99084413575261,29.2000006884336,0.000580099943673389,0.000519691057529736,0.25,3.61514977854125E-5,5.76803547008801E-5,3.61331278308937E-5,339.5518799,339.5518799,99.5330276489258,99.5330276489258,57.095618444256,20.4457231178154,30.122374,0,0,0,40,4374,343.2871,99.5330276489258,,,,,,,,,,,,,0,,,,0,,,,,,339.5518799,,,,
,28941115.33,342.5130615,99.5330276489258,5.59541532450243E-5,1.52666296387511E-6,1,0.999253354069792,40.0298881530762,1.99100121418939,29.1900001466274,0.000558929413992398,0.000519396029265415,0.25,3.64434075793638E-5,5.58486092201812E-5,3.64196109841951E-5,342.5130615,342.5130615,99.5330276489258,99.5330276489258,57.024490249006,20.4447573473539,30.122374,0,0,0,40,4374,346.2382,99.5330276489258,,,,,,,,,,,,,0,,,,0.00245,,,,,,342.5130615,,,,
,28941238.005,345.5574341,99.5330276489258,5.51687895120208E-5,1.39612081811034E-6,1,0.999253354069792,40.0298881530762,1.99064216288039,29.2700007557869,0.000551704581346573,0.000507516786572296,0.25,3.55369803358461E-5,5.50594174277954E-5,3.55101580986264E-5,345.5574341,345.5574341,99.5330276489258,99.5330276489258,57.3519925985638,20.4439300858425,29.742722,0,0,0,40,4374,349.3184,99.5330276489258,,,,,,,,,,,,,0,,,,0.0049,,,,,,345.5574341,,,,
,28941359.79,348.5480652,99.5330276489258,5.51204201812238E-5,1.18481827346642E-6,1,0.999253354069792,40.0298881530762,1.99098546963285,29.2700007557869,0.00055380966460005,0.000492363201802758,0.25,3.41964790001863E-5,5.50064292267002E-5,3.4168127682391E-5,348.5480652,348.5480652,99.5330276489258,99.5330276489258,57.352774227083,20.4415872927655,30.502024,0,0,0,40,4374,351.7727,99.5330276489258,,,,,,,,,,,,,0,,,,0.0049,,,,,,348.5480652,,,,
,28941675.955,349.7748413,99.5330276489258,5.51028107852554E-5,1.21040318811086E-6,1,0.999253354069792,40.0298881530762,1.9903194335282,29.2700007557869,0.000552442823038033,0.000497742033930903,0.25,3.46932634898092E-5,5.49862257736733E-5,3.46626922078399E-5,349.7748413,349.7748413,99.5330276489258,99.5330276489258,57.251162519583,20.4443846501685,30.502024,0,0,0,40,4369,350.71195,99.5330276489258,,,,,,,,,,,,,0,,,,0,,,,,,349.7748413,,,,