File: data/looselyPackedNP/nanoparticles/vsm/ios-7/rawdata/KWI338_HYST_10K.DAT
[Header]
; VSM Data File (default extension .dat)
; Copyright (c) 2003-2013, Quantum Design, Inc. All rights reserved.
TITLE,
FILEOPENTIME,28795336.94,11/30/2018,2:43 pm
BYAPP,VSM,2.0,2.0
INFO,PPMS VSM Option Release 1.4.10 Build 1,APPNAME
INFO,Quantum Design Linear Motor Servo Controller,MOTOR_MODULE_NAME
INFO,3101-100 M1,MOTOR_HW_VERSION
INFO,MMC1014,MOTOR_SERIAL_NUMBER
INFO,SRV No X-over 01.03.11,MOTOR_SOFTWARE_VERSION
INFO,Quantum Design VSM Detection Module,VSM_MODULE_NAME
INFO,3101-150 F0,VSM_HW_VERSION
INFO,VSM707,VSM_SERIAL_NUMBER
INFO,VSM No X-over 01.02.05 May 20 2008 13:51:47,VSM_SOFTWARE_VERSION
INFO,704,PREAMP_SERIAL_NUMBER
INFO,822,COIL_SERIAL_NUMBER
INFO,0,MOMENT_UNITS
INFO,Maghemite,SAMPLE_MATERIAL
INFO,Oleate Iron Spheres,SAMPLE_COMMENT
INFO,,SAMPLE_MASS
INFO,,SAMPLE_VOLUME
INFO,,SAMPLE_MOLECULAR_WEIGHT
INFO,,SAMPLE_SIZE
INFO,,SAMPLE_SHAPE
DATATYPE,COMMENT,1
DATATYPE,TIME,2
STARTUPAXIS,X,2
STARTUPAXIS,Y1,5
[Data]
Comment,Time Stamp (sec),Temperature (K),Magnetic Field (Oe),Moment (emu),M. Std. Err. (emu),Transport Action,Averaging Time (sec),Frequency (Hz),Peak Amplitude (mm),Center Position (mm),Coil Signal' (mV),Coil Signal" (mV),Range (mV),M. Quad. Signal (emu),M. Raw' (emu),M. Raw" (emu),Min. Temperature (K),Max. Temperature (K),Min. Field (Oe),Max. Field (Oe),Mass (grams),Motor Lag (deg),Pressure (Torr),VSM Status (code),Motor Status (code),Measure Status (code),Measure Count,PPMS Status (code),System Temp. (K),System Field (Oe),Sample Position (deg),Bridge 1 Resistance (ohms),Bridge 1 Excitation (에),Bridge 2 Resistance (ohms),Bridge 2 Excitation (에),Bridge 3 Resistance (ohms),Bridge 3 Excitation (에),Bridge 4 Resistance (ohms),Bridge 4 Excitation (에),Signal 1 Vin (V),Signal 2 Vin (V),Digital Inputs (code),Drive 1 Iout (mA),Drive 1 Ipower (W),Drive 2 Iout (mA),Drive 2 Ipower (W),Pressure (),Map 20 (),Map 21 (),Map 22 (),Map 23 (),Map 24 (),Map 25 (),Map 26 (),Map 27 (),Map 28 (),Map 29 ()
,28795353.69,10.0003958,-0.243580371141434,,,2,,,,29.7099991840124,,,,,,,10.0003958,10.0003958,-0.243580371141434,-0.243580371141434,,,13.038077,,,,-99999999,4369,9.9946,-0.243580371141434,,,,,,,,,,,,,,,,,,,,,,,10.0003958,,,,
,28795742.25,10.0144663,4678.05981445313,0.00421232311600474,6.15555735794906E-7,1,0.999253354069792,40.0298881530762,1.98002417532242,29.6899992972612,0.0468873595528389,0.00871103006951346,0.25,3.22905876150738E-5,0.00418903394480424,5.36162810693964E-5,10.0144663,10.0144663,4665.60595703125,4690.513671875,57.1370447557753,20.5801678239675,13.417728,0,0,0,40,4449,9.69455,4678.05981445313,,,,,,,,,,,,,0,,,,-0.00245,,,,,,10.0144663,,,,
,28795836.58,10.0091963,9391.9814453125,0.00463772024315545,5.33920195682168E-7,1,0.999253354069792,40.0298881530762,1.98002556750657,29.6899992972612,0.0516436743397615,0.00957588971457976,0.25,3.23229399857496E-5,0.00461369106106834,5.74278115963482E-5,10.0091963,10.0091963,9387.16015625,9396.802734375,57.3074397729676,20.5896152964825,13.038077,0,0,0,40,4449,9.69315,9391.9814453125,,,,,,,,,,,,,0,,,,-0.0049,,,,,,10.0091963,,,,
,28795934.96,10.0099344,14309.4501953125,0.00493760023236827,7.52714454460251E-7,1,0.999253354069792,40.0298881530762,1.97965971412153,29.6899992972612,0.0549906855947085,0.0102287297430094,0.25,3.54394511906583E-5,0.00491405209788371,6.39509852963099E-5,10.0099344,10.0099344,14299.6259765625,14319.2744140625,56.8970848003714,20.587810396921,12.658426,0,0,0,40,4449,9.70105,14309.4501953125,,,,,,,,,,,,,0,,,,-0.0049,,,,,,10.0099344,,,,
,28796031.69,10.012805,19144.0537109375,0.00518475007188264,7.44994486225128E-7,1,0.999253354069792,40.0298881530762,1.97993139754848,29.6899992972612,0.0577755233596312,0.0107542283775605,0.25,3.6143940458062E-5,0.00516234452020328,6.78296640871287E-5,10.012805,10.012805,19136.6953125,19151.412109375,57.3621537693137,20.6019177878939,12.658426,0,0,0,40,4449,9.683,19144.0537109375,,,,,,,,,,,,,0,,,,0.00245,,,,,,10.012805,,,,
,28796127.76,10.0011091,23946.6455078125,0.00540126761114552,8.95478909557136E-7,1,0.999253354069792,40.0298881530762,1.97985353287882,29.6899992972612,0.0602162369197126,0.0111995679879862,0.25,3.52675261351308E-5,0.0053804947338208,6.99211763317151E-5,10.0011091,10.0011091,23939.0859375,23954.205078125,57.1284468420637,20.5881246535848,12.658426,0,0,0,40,4449,9.67945,23946.6455078125,,,,,,,,,,,,,0,,,,0,,,,,,10.0011091,,,,
,28796224.615,9.9986086,28784.4599609375,0.00559678943937038,9.63750127586146E-7,1,0.999253354069792,40.0298881530762,1.9798429375348,29.6899992972612,0.0624167867542947,0.0116670679358258,0.25,4.01257198922492E-5,0.00557801861089518,7.75172549239816E-5,9.9986086,9.9986086,28781.958984375,28786.9609375,57.2183341217753,20.5922623192596,13.038077,0,0,0,40,4449,9.68405,28784.4599609375,,,,,,,,,,,,,0,,,,0,,,,,,9.9986086,,,,
,28796319.725,9.9758577,33539.38671875,0.00577431405550165,1.75746150645554E-6,1,0.999253354069792,40.0298881530762,1.98077428903295,29.6899992972612,0.0644787551175862,0.0119325677259543,0.25,2.97671926440072E-5,0.00575791128897584,6.96641067060291E-5,9.9758577,9.9758577,33529.390625,33549.3828125,57.3488660844868,20.5852567902848,13.038077,0,0,0,40,4449,9.7,33539.38671875,,,,,,,,,,,,,0,,,,0.00245,,,,,,9.9758577,,,,
,28796417.77,9.9960823,38439.173828125,0.0058998234777337,9.59203804559681E-7,1,0.999253354069792,40.0298881530762,1.98008191204841,29.6899992972612,0.06587764322155,0.0122774472696047,0.25,3.67968934183293E-5,0.00588608128996087,7.86436940246959E-5,9.9940996,9.998065,38431.52734375,38446.8203125,57.1315733561406,20.5991713766412,12.278775,0,0,0,40,4449,9.6916,38439.173828125,,,,,,,,,,,,,0,,,,0,,,,,,9.9960823,,,,
,28796515.05,10.0023928,43301.7265625,0.00602101665732315,1.00780099920038E-6,1,0.999253354069792,40.0298881530762,1.98012344803639,29.6899992972612,0.0672601074546255,0.0125737362645157,0.25,4.00738508936734E-5,0.00601005948346849,8.36374680548787E-5,10.0023928,10.0023928,43294.22265625,43309.23046875,57.2925888311022,20.6067991461026,12.658426,0,0,0,40,4449,9.68065,43301.7265625,,,,,,,,,,,,,0,,,,0.00245,,,,,,10.0023928,,,,
,28796610.205,9.9990664,48056.88671875,0.00612767435206716,1.3693294892284E-6,1,0.999253354069792,40.0298881530762,1.9801150933365,29.6899992972612,0.0684898184363909,0.0127769017504382,0.25,3.78925039868698E-5,0.00611956642584015,8.28540591320682E-5,9.9990664,9.9990664,48046.76171875,48067.01171875,56.9369478548522,20.591636015355,12.658426,0,0,0,40,4449,9.6756,48056.88671875,,,,,,,,,,,,,0,,,,0,,,,,,9.9990664,,,,
,28796706.615,9.9961805,52877.041015625,0.00622464784864852,1.68777427228986E-6,1,0.999253354069792,40.0298881530762,1.97978058243861,29.6899992972612,0.0695947188436283,0.0129929874276944,0.25,3.89796701956359E-5,0.0062194420951946,8.50669758698437E-5,9.9961805,9.9961805,52869.53515625,52884.546875,57.3082214014868,20.6061311856055,13.038077,0,0,0,40,4449,9.67605,52877.041015625,,,,,,,,,,,,,0,,,,0.0049,,,,,,9.9961805,,,,
,28796804.335,10.0087337,57761.833984375,0.00628315854377054,1.5101254326352E-6,1,0.999253354069792,40.0298881530762,1.97935476422519,29.6899992972612,0.0702693345853683,0.0131114711087289,0.25,3.85297644653487E-5,0.00628090953951293,8.52629077617687E-5,10.0087337,10.0087337,57751.89453125,57771.7734375,57.0096393071407,20.6129004185324,12.658426,0,0,0,40,4449,9.6623,57761.833984375,,,,,,,,,,,,,0,,,,0,,,,,,10.0087337,,,,
,28796901.845,10.0039234,62635.1171875,0.00633158112922666,1.56185832372789E-6,1,0.999253354069792,40.0298881530762,1.97958428180179,29.6899992972612,0.0708342972234295,0.0133132413910085,0.25,4.71650188635455E-5,0.00633214614610682,9.42817897828522E-5,10.0039234,10.0039234,62624.953125,62645.28125,56.882233858506,20.6080297063272,12.278775,0,0,0,40,4449,9.6562,62635.1171875,,,,,,,,,,,,,0,,,,0,,,,,,10.0039234,,,,
,28797000.12,10.0122004,67547.6484375,0.00636135347368878,1.90064884144805E-6,1,0.999253354069792,40.0298881530762,1.97916278484992,29.6899992972612,0.0712161519010458,0.0132012926569547,0.25,3.17129219214154E-5,0.00636483133187103,7.88988157213993E-5,10.0122004,10.0122004,67537.71875,67557.578125,57.0807675023906,20.616415955111,12.278775,0,0,0,40,4449,9.6543,67547.6484375,,,,,,,,,,,,,0,,,,0.00245,,,,,,10.0122004,,,,
,28797098.94,10.0066252,72487.80859375,0.00640521670075532,1.96318873692752E-6,1,0.999253354069792,40.0298881530762,1.97909131050731,29.6899992972612,0.0717111685116585,0.0134280861498878,0.25,4.39217238069201E-5,0.00641131205796429,9.11445997536871E-5,10.0066252,10.0066252,72485.15625,72490.4609375,57.4528226775445,20.6098365063851,12.278775,0,0,0,40,4449,9.6648,72487.80859375,,,,,,,,,,,,,0,,,,0,,,,,,10.0066252,,,,
,28797194.495,9.9941101,77260.8828125,0.00642669305668871,1.86604537505761E-6,1,0.999253354069792,40.0298881530762,1.97997070894758,29.6899992972612,0.0720469987866539,0.0132764086071581,0.25,2.60084354727537E-5,0.00643539759128627,7.29580686565972E-5,9.9941101,9.9941101,77248.328125,77273.4375,57.4536043060638,20.6046300780449,12.658426,0,0,0,40,4449,9.68705,77260.8828125,,,,,,,,,,,,,0,,,,0.00245,,,,,,9.9941101,,,,
,28797290.295,9.9908371,82049.01953125,0.00640020581773395,1.96999648846543E-6,1,0.999253354069792,40.0298881530762,1.97941766536604,29.6899992972612,0.0717118638543358,0.0134722188375449,0.25,4.86568595808742E-5,0.0064110216968118,9.49414000974362E-5,9.9908371,9.9908371,82041.4609375,82056.578125,57.3512109700445,20.6113602976384,12.658426,0,0,0,40,4449,9.679,82049.01953125,,,,,,,,,,,,,0,,,,0,,,,,,9.9908371,,,,
,28797385.775,9.9769983,86822.13671875,0.00642910176512732,1.67190455637864E-6,1,0.999253354069792,40.0298881530762,1.97976096536056,29.6899992972612,0.0720456969692144,0.0136853682728456,0.25,6.24550315834909E-5,0.00644204674989584,0.00010839179599455,9.9769983,9.9769983,86814.6875,86829.5859375,57.5849178972945,20.609483163307,12.278775,0,0,0,40,4449,9.69585,86822.13671875,,,,,,,,,,,,,0,,,,-0.0049,,,,,,9.9769983,,,,
,28797496.265,9.9845037,88707.3984375,0.00639366244528107,1.94465184881134E-6,1,0.999253354069792,40.0298881530762,1.97994322263298,29.6899992972612,0.071673077608895,0.0135623363135725,0.25,5.78709166890991E-5,0.00640738424027866,0.000103298287339573,9.9845037,9.9845037,88697.578125,88717.21875,57.0799858738714,20.6082976623539,12.278775,0,0,0,40,4449,9.6942,88707.3984375,,,,,,,,,,,,,0,,,,-0.0049,,,,,,9.9845037,,,,
,28797586.82,9.9987364,84181.51953125,0.00639062875662224,1.68700042663442E-6,1,0.999253354069792,40.0298881530762,1.97963880534921,29.6899992972612,0.0715983993823343,0.0135932715589093,0.25,6.11195325808766E-5,0.00640232207493438,0.000107107792212895,9.9987364,9.9987364,84174,84189.0390625,57.3996719382368,20.6079523568037,12.278775,0,0,0,40,4449,9.70415,84181.51953125,,,,,,,,,,,,,0,,,,0.00245,,,,,,9.9987364,,,,
,28797685.07,9.9952869,79270.40234375,0.00641180772469673,2.0270970964016E-6,1,0.999253354069792,40.0298881530762,1.97995666122439,29.6899992972612,0.071803486072663,0.0137319354945186,0.25,6.93279064054351E-5,0.00642116591768602,0.000116031487228072,9.9952869,9.9952869,79260.7890625,79280.015625,57.0924919301791,20.609684603139,12.278775,0,0,0,40,4449,9.6978,79270.40234375,,,,,,,,,,,,,0,,,,0.00245,,,,,,9.9952869,,,,
,28797776.17,10.0011663,74713.5625,0.00639529700068379,1.56905423039277E-6,1,0.999253354069792,40.0298881530762,1.97993365451395,29.6899992972612,0.0716311478331878,0.0134763394602934,0.25,4.94992451728678E-5,0.006402499133814,9.64803881793524E-5,10.0011663,10.0011663,74705.796875,74721.328125,57.4629838482945,20.6111972991593,12.278775,0,0,0,40,4449,9.68925,74713.5625,,,,,,,,,,,,,0,,,,0.00245,,,,,,10.0011663,,,,
,28797874.745,10.010478,69788.77734375,0.00638701176399833,2.05346746026313E-6,1,0.999253354069792,40.0298881530762,1.97973541450789,29.6899992972612,0.0715111352666134,0.0134039705678302,0.25,4.47498471512324E-5,0.00639163985438255,9.2017162472799E-5,10.010478,10.010478,69784.0859375,69793.46875,57.5817913832176,20.6097907395925,11.899124,0,0,0,40,4449,9.6949,69788.77734375,,,,,,,,,,,,,0,,,,0,,,,,,10.010478,,,,
,28797971.035,10.0025406,64975.68359375,0.00633007956159171,1.48692786805465E-6,1,0.999253354069792,40.0298881530762,1.97927797626343,29.6899992972612,0.0708258294646195,0.013289882830959,0.25,4.53427849019241E-5,0.00633200013629232,9.23994730957568E-5,10.0025406,10.0025406,64965.6796875,64985.6875,57.2159892362176,20.6156555488801,12.278775,0,0,0,40,4449,9.68895,64975.68359375,,,,,,,,,,,,,0,,,,0,,,,,,10.0025406,,,,
,28798069.725,10.0066385,60042.697265625,0.00630813741513785,1.51722911283274E-6,1,0.999253354069792,40.0298881530762,1.97930188220482,29.6899992972612,0.070539436429412,0.0132922060143088,0.25,4.99292082793795E-5,0.00630716095875778,9.6879632314643E-5,10.0066385,10.0066385,60037.6484375,60047.74609375,57.5778832406215,20.6138393584413,12.278775,0,0,0,40,4449,9.6846,60042.697265625,,,,,,,,,,,,,0,,,,0.0049,,,,,,10.0066385,,,,
,28798165.79,9.995718,55242.232421875,0.00625741058923722,1.75800228894082E-6,1,0.999253354069792,40.0298881530762,1.97951984258784,29.6899992972612,0.0699643310652332,0.0130863056131804,0.25,4.11784634476227E-5,0.00625362333513225,8.76347750557193E-5,9.995718,9.995718,55239.4296875,55245.03515625,57.4098331089868,20.6069026598392,12.278775,0,0,0,40,4449,9.6829,55242.232421875,,,,,,,,,,,,,0,,,,-0.0049,,,,,,9.995718,,,,
,28798261.835,10.018508,50442.20703125,0.0061848867757829,1.5966956015983E-6,1,0.999253354069792,40.0298881530762,1.9791139584445,29.6899992972612,0.0690981987372607,0.0129737013483824,0.25,4.52401919136426E-5,0.00617815446714879,9.08450780899508E-5,10.018508,10.018508,50432.13671875,50452.27734375,57.637287008083,20.623820986489,12.278775,0,0,0,40,4449,9.6851,50442.20703125,,,,,,,,,,,,,0,,,,0,,,,,,10.018508,,,,
,28798355.775,10.0173216,45744.5234375,0.00610654096762919,1.18222967968198E-6,1,0.999253354069792,40.0298881530762,1.97954059519748,29.6899992972612,0.0682153570526382,0.012742950716791,0.25,3.9507600476675E-5,0.00609699126369583,8.40385690045198E-5,10.0173216,10.0173216,45739.41796875,45749.62890625,57.1808159528522,20.6238261673003,12.278775,0,0,0,40,4449,9.6666,45744.5234375,,,,,,,,,,,,,0,,,,0,,,,,,10.0173216,,,,
,28798450.425,9.9950924,41014.388671875,0.00599814485919409,9.95419427001058E-7,1,0.999253354069792,40.0298881530762,1.97946057673975,29.6899992972612,0.0669567655976623,0.0125759146402304,0.25,4.53724198799181E-5,0.00598574859487928,8.83858483811961E-5,9.9950924,9.9950924,41011.80078125,41016.9765625,57.3801312252561,20.614633144923,11.899124,0,0,0,40,4449,9.6645,41014.388671875,,,,,,,,,,,,,0,,,,0,,,,,,9.9950924,,,,
,28798545.915,10.0008097,36244.701171875,0.00586642202036996,9.29393950831629E-7,1,0.999253354069792,40.0298881530762,1.97869042138101,29.6899992972612,0.0654305007704109,0.012279764033313,0.25,4.44503384753501E-5,0.00585133848304857,8.55815864394953E-5,10.0008097,10.0008097,36239.7421875,36249.66015625,56.8970848003714,20.6151149058175,11.899124,0,0,0,40,4449,9.6598,36244.701171875,,,,,,,,,,,,,0,,,,-0.0049,,,,,,10.0008097,,,,
,28798639.29,10.0081825,31574.7998046875,0.00572243366862624,6.35724117019704E-7,1,0.999253354069792,40.0298881530762,1.97867238115361,29.6899992972612,0.0637985767335801,0.0119375435511796,0.25,4.13274420741548E-5,0.00570491062259617,8.03339602398788E-5,10.0081825,10.0081825,31567.123046875,31582.4765625,57.4622022197753,20.6323862865645,12.278775,0,0,0,40,4449,9.63135,31574.7998046875,,,,,,,,,,,,,0,,,,-0.00245,,,,,,10.0081825,,,,
,28798736.72,10.01916505,26706.5595703125,0.00554746370425176,7.30165134307922E-7,1,0.999253354069792,40.0298881530762,1.97848425633296,29.6899992972612,0.0618115207658927,0.0115609420675104,0.25,4.09757407443662E-5,0.00552765727030268,7.74233581382686E-5,10.0175772,10.0207529,26699.322265625,26713.796875,57.2316218066022,20.637285423924,11.899124,0,0,0,40,4449,9.6305,26706.5595703125,,,,,,,,,,,,,0,,,,0.0049,,,,,,10.01916505,,,,
,28798829.91,10.0057173,22046.37109375,0.00535715922930679,4.39053288163813E-7,1,0.999253354069792,40.0298881530762,1.97904805385491,29.6899992972612,0.0596795183185403,0.0111593349836434,0.25,4.07574272659583E-5,0.00533550190400715,7.44859352929543E-5,10.0057173,10.0057173,22041.16015625,22051.58203125,57.5856995258138,20.62277825457,11.899124,0,0,0,40,4449,9.62525,22046.37109375,,,,,,,,,,,,,0,,,,-0.00245,,,,,,10.0057173,,,,
,28798927.49,9.9951677,17172.1474609375,0.0051391929204805,5.16114140611855E-7,1,0.999253354069792,40.0298881530762,1.97944117182304,29.6899992972612,0.0572345338049365,0.0107057075130205,0.25,4.10319924325178E-5,0.00511599607787964,7.1728587522818E-5,9.9951677,9.9951677,17164.61328125,17179.681640625,57.5434915857753,20.6205385306726,12.278775,0,0,0,40,4449,9.63725,17172.1474609375,,,,,,,,,,,,,0,,,,0,,,,,,9.9951677,,,,
,28799025.65,9.9912901,12267.1796875,0.00488096721792201,5.94729492619701E-7,1,0.999253354069792,40.0298881530762,1.97977396425292,29.6899992972612,0.0543470806188735,0.0101445872927258,0.25,3.88396280278527E-5,0.00485680228099213,6.62788850265249E-5,9.9912901,9.9912901,12257.21484375,12277.14453125,57.1784710672945,20.6145112132645,11.899124,0,0,0,40,4449,9.6361,12267.1796875,,,,,,,,,,,,,0,,,,-0.00245,,,,,,9.9912901,,,,
,28799124.385,9.9864521,7329.70385742188,0.0045630221369292,4.36906766224041E-7,1,0.999253354069792,40.0298881530762,1.9792986948223,29.6899992972612,0.05077960801789,0.00945243638635898,0.25,3.56907075230053E-5,0.00453863926260605,5.96704327994129E-5,9.9864521,9.9864521,7319.86572265625,7339.5419921875,57.1776894387753,20.6199446121013,11.899124,0,0,0,40,4449,9.64425,7329.70385742188,,,,,,,,,,,,,0,,,,0,,,,,,9.9864521,,,,
,28799218.78,9.988276,2614.03552246094,0.00390584768657089,8.81575114701899E-7,1,0.999253354069792,40.0298881530762,1.9790686785703,29.6899992972612,0.043449825323122,0.00807515260174573,0.25,3.07324619766467E-5,0.00388374827554389,4.99481858768184E-5,9.9869232,9.9896288,2606.46923828125,2621.60180664062,57.217552493256,20.6267260170451,11.899124,0,0,0,40,4449,9.6541,2614.03552246094,,,,,,,,,,,,,0,,,,0.00245,,,,,,9.988276,,,,
,28799314.22,10.0162325,-2154.83984375,-0.00356453896208593,1.37593193333836E-6,1,0.999253354069792,40.0298881530762,1.97842615426208,29.6899992972612,-0.0396405598167918,-0.00736196892891184,0.25,-2.76971778201946E-5,-0.00354427973585145,-4.51301276036857E-5,10.0162325,10.0162325,-2162.365234375,-2147.314453125,57.3238539718714,20.6234881631318,12.278775,0,0,0,40,4449,9.6459,-2154.83984375,,,,,,,,,,,,,0,,,,0,,,,,,10.0162325,,,,
,28799409.115,10.0043402,-6898.34985351562,-0.00449760327475227,3.42751711795475E-7,1,0.999253354069792,40.0298881530762,1.9792124988334,29.6899992972612,-0.050049346426686,-0.00930816315931319,0.25,-3.45972288091326E-5,-0.00447343063658447,-5.80927049498346E-5,10.0043402,10.0043402,-6905.71337890625,-6890.986328125,57.5544343850446,20.6217795077291,11.519473,0,0,0,40,4449,9.65145,-6898.34985351562,,,,,,,,,,,,,0,,,,0,,,,,,10.0043402,,,,
,28799505.485,10.0090284,-11716.5913085938,-0.00482990436697012,5.36763781573058E-7,1,0.999253354069792,40.0298881530762,1.9793826739759,29.6899992972612,-0.0537706963185944,-0.010008879136045,0.25,-3.61864467965058E-5,-0.00480578037477524,-6.31534520033907E-5,10.0090284,10.0090284,-11729.107421875,-11704.0751953125,57.3801312252561,20.6287450605464,12.278775,0,0,0,40,4449,9.6468,-11716.5913085938,,,,,,,,,,,,,0,,,,-0.00245,,,,,,10.0090284,,,,
,28799601.315,10.0149183,-16504.1015625,-0.00508871313591195,3.45719766490231E-7,1,0.999253354069792,40.0298881530762,1.97904288961419,29.6899992972612,-0.056661848369433,-0.0105758444350738,0.25,-3.88883497283783E-5,-0.00506543978393263,-6.90548591181048E-5,10.0149183,10.0149183,-16516.5546875,-16491.6484375,57.3058765159291,20.6319817885914,12.278775,0,0,0,40,4449,9.63265,-16504.1015625,,,,,,,,,,,,,0,,,,0.00245,,,,,,10.0149183,,,,
,28799696.695,10.0075598,-21271.3330078125,-0.00531342297363672,5.48978223104754E-7,1,0.999253354069792,40.0298881530762,1.97865027591915,29.6899992972612,-0.0591774949101384,-0.0110589343903844,0.25,-4.01130513353381E-5,-0.00529153848110695,-7.33080306672301E-5,10.0075598,10.0075598,-21278.833984375,-21263.83203125,57.4598573342176,20.6280701881043,11.519473,0,0,0,40,4449,9.62305,-21271.3330078125,,,,,,,,,,,,,0,,,,-0.00245,,,,,,10.0075598,,,,
,28799796.53,10.008462,-26260.6669921875,-0.00552585582088721,6.54891061044242E-7,1,0.999253354069792,40.0298881530762,1.9791910372928,29.6899992972612,-0.061586107093264,-0.0115350917597066,0.25,-4.23628904349403E-5,-0.00550586340533299,-7.85271645311285E-5,10.008462,10.008462,-26270.904296875,-26250.4296875,57.3801312252561,20.6258112356853,11.519473,0,0,0,40,4449,9.619,-26260.6669921875,,,,,,,,,,,,,0,,,,0,,,,,,10.008462,,,,
,28799895.69,10.0157261,-31218.318359375,-0.00570579235437611,8.41640030168218E-7,1,0.999253354069792,40.0298881530762,1.97889082912737,29.6899992972612,-0.0636164230810892,-0.0119088330870671,0.25,-4.17646214396602E-5,-0.00568810256164452,-8.05615119646113E-5,10.0157261,10.0157261,-31223.51171875,-31213.125,57.3488660844868,20.6232448910034,11.899124,0,0,0,40,4449,9.6305,-31218.318359375,,,,,,,,,,,,,0,,,,0.0049,,,,,,10.0157261,,,,
,28799991.04,9.9756966,-35980.40625,-0.00586671638098163,1.11518422190289E-6,1,0.999253354069792,40.0298881530762,1.97962915426077,29.6899992972612,-0.0654605751611058,-0.0122913460237532,0.25,-4.50232731280539E-5,-0.00585146407996406,-8.60962354527612E-5,9.9756966,9.9756966,-35985.58984375,-35975.22265625,57.5317671579869,20.6115223772418,11.899124,0,0,0,40,4449,9.6236,-35980.40625,,,,,,,,,,,,,0,,,,0.00245,,,,,,9.9756966,,,,
,28800087.295,10.0129213,-40792.90234375,-0.00599583452535751,8.11896557850608E-7,1,0.999253354069792,40.0298881530762,1.97909520054323,29.6899992972612,-0.0669198730050293,-0.0125559303321311,0.25,-4.4262173986611E-5,-0.00598331075017252,-8.72220860401278E-5,10.0129213,10.0129213,-40802.91796875,-40782.88671875,57.4223391652945,20.6251998342751,11.899124,0,0,0,40,4449,9.6119,-40792.90234375,,,,,,,,,,,,,0,,,,0,,,,,,10.0129213,,,,
,28800180.11,9.978754,-45432.763671875,-0.00611628373613897,1.15522771780794E-6,1,0.999253354069792,40.0298881530762,1.97900064349352,29.6899992972612,-0.0682955360656124,-0.0128074839241222,0.25,-4.38968813126315E-5,-0.00610648967572851,-8.84512612133314E-5,9.978754,9.978754,-45440.3671875,-45425.16015625,57.708415203333,20.6193951715466,12.278775,0,0,0,40,4449,9.6162,-45432.763671875,,,,,,,,,,,,,0,,,,0.0049,,,,,,9.978754,,,,
,28800277.195,9.989398,-50282.453125,-0.0062091006671878,6.7754261697165E-7,1,0.999253354069792,40.0298881530762,1.97923775823395,29.6899992972612,-0.069372635246066,-0.0130201185535937,0.25,-4.498794690287E-5,-0.00620224506427576,-9.07578846231414E-5,9.989398,9.989398,-50292.53515625,-50272.37109375,57.6146197810253,20.6188625124622,11.519473,0,0,0,40,4449,9.6252,-50282.453125,,,,,,,,,,,,,0,,,,0,,,,,,9.989398,,,,
,28800374.97,9.9941072,-55169.4453125,-0.00627850773102998,1.17250280022374E-6,1,0.999253354069792,40.0298881530762,1.97906148495137,29.6899992972612,-0.0701683539095186,-0.0132152688029542,0.25,-4.91686191975488E-5,-0.00627460469434003,-9.57739046690268E-5,9.9941072,9.9941072,-55174.50390625,-55164.38671875,57.6646440062561,20.6181571806563,11.519473,0,0,0,40,4449,9.6366,-55169.4453125,,,,,,,,,,,,,0,,,,0.00245,,,,,,9.9941072,,,,
,28800471.57,9.9987965,-59996.775390625,-0.00633871841841037,1.48132733991507E-6,1,0.999253354069792,40.0298881530762,1.97896237888986,29.6899992972612,-0.0708704132416621,-0.0133492174737432,0.25,-4.9708438600783E-5,-0.00633771340647655,-9.68862082385057E-5,9.9987965,9.9987965,-60001.71484375,-59991.8359375,57.4309370790061,20.6154311648225,11.899124,0,0,0,40,4449,9.6232,-59996.775390625,,,,,,,,,,,,,0,,,,0.00245,,,,,,9.9987965,,,,
,28800570.79,9.9715366,-64956.416015625,-0.0063934131275644,1.57144808737388E-6,1,0.999253354069792,40.0298881530762,1.97953323096259,29.6899992972612,-0.0715580330940626,-0.0133419054140941,0.25,-3.84258418318293E-5,-0.00639539697132431,-8.59512847045687E-5,9.9715366,9.9715366,-64963.9296875,-64948.90234375,57.5724118409869,20.6193018017644,11.899124,0,0,0,40,4449,9.6357,-64956.416015625,,,,,,,,,,,,,0,,,,0,,,,,,9.9715366,,,,
,28800666.65,9.9881487,-69748.47265625,-0.00641363838926121,1.50843824157275E-6,1,0.999253354069792,40.0298881530762,1.97920314428901,29.6899992972612,-0.0717836042187587,-0.0134949724711515,0.25,-4.83801478468298E-5,-0.0064182385528034,-9.5849540739195E-5,9.9881487,9.9881487,-69750.90625,-69746.0390625,57.5856995258138,20.614131035013,11.519473,0,0,0,40,4449,9.6393,-69748.47265625,,,,,,,,,,,,,0,,,,0,,,,,,9.9881487,,,,
,28800764.835,9.9967117,-74652.74609375,-0.00642863589706983,1.35404667087903E-6,1,0.999253354069792,40.0298881530762,1.97917124302211,29.6899992972612,-0.0719848219665619,-0.0135021109269094,0.25,-4.62348890610194E-5,-0.00643587007699598,-9.34619067647546E-5,9.9967117,9.9967117,-74657.7109375,-74647.78125,57.5364569291022,20.6194874579677,12.278775,0,0,0,40,4449,9.6479,-74652.74609375,,,,,,,,,,,,,0,,,,0,,,,,,9.9967117,,,,
,28800864.63,9.98326255,-79639.6875,-0.00644613728734774,1.73959098382266E-6,1,0.999253354069792,40.0298881530762,1.97960845788278,29.6899992972612,-0.0722215367494463,-0.0135606839639609,0.25,-4.8095051892662E-5,-0.00645588284933659,-9.49765924779896E-5,9.9793825,9.9871426,-79644.53125,-79634.84375,57.3715333115445,20.612409351091,11.519473,0,0,0,40,4449,9.64985,-79639.6875,,,,,,,,,,,,,0,,,,-0.0049,,,,,,9.98326255,,,,
,28800963.69,10.0041342,-84589.14453125,-0.00643599508168503,1.51230639498131E-6,1,0.999253354069792,40.0298881530762,1.97913084641595,29.6899992972612,-0.0721025736788368,-0.013622863044107,0.25,-5.59072753588808E-5,-0.00644799815507177,-0.000102161477527526,10.0041342,10.0041342,-84596.703125,-84581.5859375,57.6036769817561,20.6138306196597,11.519473,0,0,0,40,4449,9.6628,-84589.14453125,,,,,,,,,,,,,0,,,,0.00245,,,,,,10.0041342,,,,
,28801050.345,9.9949436,-88921.421875,-0.00641526594864993,1.19807255638753E-6,1,0.999253354069792,40.0298881530762,1.97901869053577,29.6899992972612,-0.0718896565063773,-0.0135718835335789,0.25,-5.53880089868368E-5,-0.00642914482691386,-0.000100934134864999,9.9949436,9.9949436,-88929.0078125,-88913.8359375,57.3887291389676,20.6138443970575,11.519473,0,0,0,40,4449,9.6604,-88921.421875,,,,,,,,,,,,,0,,,,0.0049,,,,,,9.9949436,,,,
,28801161.18,10.0091763,-86544.51171875,-0.0064293146985545,1.7927398403593E-6,1,0.999253354069792,40.0298881530762,1.97904383622359,29.6899992972612,-0.0720525461788482,-0.0135097626229015,0.25,-4.7175662564223E-5,-0.00644224581409985,-9.31181128750519E-5,10.0091763,10.0091763,-86554.328125,-86534.6953125,57.7240477737176,20.6036316740713,11.519473,0,0,0,40,4449,9.6649,-86544.51171875,,,,,,,,,,,,,0,,,,0,,,,,,10.0091763,,,,
,28801255.25,10.0037355,-81841.8671875,-0.00643433947262531,1.71842643291027E-6,1,0.999253354069792,40.0298881530762,1.97909057582827,29.6899992972612,-0.072067882584363,-0.0136192765745069,0.25,-5.58043628795139E-5,-0.00644506546888051,-0.000102371353507428,10.0006971,10.0067739,-81852.0234375,-81831.7109375,57.7412436011407,20.6139170246585,11.519473,0,0,0,40,4449,9.65285,-81841.8671875,,,,,,,,,,,,,0,,,,-0.00245,,,,,,10.0037355,,,,
,28801348.92,9.9975829,-77162.23828125,-0.00643725199917828,1.40412747518705E-6,1,0.999253354069792,40.0298881530762,1.97935839274936,29.6899992972612,-0.0720796969912585,-0.0136484268971654,0.25,-5.76259809400437E-5,-0.00644569086871175,-0.000104705826055868,9.9916477,10.0035181,-77169.3515625,-77155.125,57.6247809517753,20.6043466441568,11.519473,0,0,0,40,4449,9.6486,-77162.23828125,,,,,,,,,,,,,0,,,,0,,,,,,9.9975829,,,,
,28801446.455,10.0018463,-72287.62109375,-0.00642165076771101,1.41034447425177E-6,1,0.999253354069792,40.0298881530762,1.9789516841102,29.6899992972612,-0.0718806429718968,-0.0135085105287286,0.25,-4.82205092754359E-5,-0.00642762491749818,-9.55832784852531E-5,10.0018463,10.0018463,-72292.484375,-72282.7578125,57.7514047718907,20.6128336311389,11.519473,0,0,0,40,4449,9.6578,-72287.62109375,,,,,,,,,,,,,0,,,,-0.0049,,,,,,10.0018463,,,,
,28801542.925,9.9934511,-67468.45703125,-0.00641963778541535,1.42293625949016E-6,1,0.999253354069792,40.0298881530762,1.97928823195862,29.6899992972612,-0.0718404729560271,-0.0135007389781055,0.25,-4.78640310903975E-5,-0.00642298578290322,-9.54950805404073E-5,9.9934511,9.9934511,-67481.21875,-67455.6953125,57.5935158110061,20.6122791283105,11.899124,0,0,0,40,4449,9.6515,-67468.45703125,,,,,,,,,,,,,0,,,,0.00245,,,,,,9.9934511,,,,
,28801641.755,10.0092926,-62526.55078125,-0.00636308834410232,1.47345682753424E-6,1,0.999253354069792,40.0298881530762,1.97879942061612,29.6899992972612,-0.0711530163805247,-0.0134080630312643,0.25,-5.04135250640267E-5,-0.00636357034733938,-9.77664954511954E-5,10.0092926,10.0092926,-62529.1953125,-62523.90625,57.5724118409869,20.6148090641379,11.899124,0,0,0,40,4449,9.647,-62526.55078125,,,,,,,,,,,,,0,,,,0,,,,,,10.0092926,,,,
,28801735.7,10.0118189,-57833.517578125,-0.00631149756099597,1.43993298818303E-6,1,0.999253354069792,40.0298881530762,1.97880071197428,29.6899992972612,-0.0705412740680396,-0.0133147556954909,0.25,-5.18872777580857E-5,-0.00630918363937776,-9.88288196667004E-5,10.0118189,10.0118189,-57836.10546875,-57830.9296875,57.4528226775445,20.6154182411094,11.139823,0,0,0,40,4449,9.6349,-57833.517578125,,,,,,,,,,,,,0,,,,0,,,,,,10.0118189,,,,
,28801831.195,10.0034657,-53058.962890625,-0.00624788118811728,1.40312324758141E-6,1,0.999253354069792,40.0298881530762,1.97870055963618,29.6899992972612,-0.0697897548622455,-0.0131990221595092,0.25,-5.37834107380153E-5,-0.00624266038370923,-0.000100042951322099,10.0034657,10.0034657,-53069,-53048.92578125,57.7146682314869,20.6185911040515,11.899124,0,0,0,40,4449,9.62755,-53058.962890625,,,,,,,,,,,,,0,,,,-0.0049,,,,,,10.0034657,,,,
,28801926.855,10.0024595,-48279.513671875,-0.00617345867201674,1.30197951249999E-6,1,0.999253354069792,40.0298881530762,1.97915952223417,29.6899992972612,-0.0689555633873118,-0.0129541534941705,0.25,-4.5970450456829E-5,-0.00616537373672251,-9.12819573093611E-5,10.0024595,10.0024595,-48287.1796875,-48271.84765625,57.677931691083,20.6133321582863,11.139823,0,0,0,40,4449,9.6245,-48279.513671875,,,,,,,,,,,,,0,,,,0.0049,,,,,,10.0024595,,,,
,28802025.61,9.99742795,-43344.53515625,-0.00606592751261603,1.29424877080689E-6,1,0.999253354069792,40.0298881530762,1.9792017331108,29.6899992972612,-0.067721749831365,-0.0127186896597566,0.25,-4.54422640833944E-5,-0.00605487910114954,-8.93284233622241E-5,9.9948578,9.9999981,-43349.71875,-43339.3515625,57.2433462343907,20.6162277581046,11.139823,0,0,0,40,4449,9.6352,-43344.53515625,,,,,,,,,,,,,0,,,,0.0049,,,,,,9.99742795,,,,
,28802125.435,10.0019674,-38352.80078125,-0.00594422432866346,1.12920430112875E-6,1,0.999253354069792,40.0298881530762,1.97926420711237,29.6899992972612,-0.0663387884318131,-0.0124083977135565,0.25,-4.09876818726991E-5,-0.00593029650505887,-8.31230991764674E-5,10.0019674,10.0019674,-38357.8046875,-38347.796875,57.474708276083,20.6168599726094,11.139823,0,0,0,40,4449,9.6346,-38352.80078125,,,,,,,,,,,,,0,,,,0.0049,,,,,,10.0019674,,,,
,28802222.43,10.0073671,-33508.0859375,-0.00579917047607819,7.46858483443132E-7,1,0.999253354069792,40.0298881530762,1.97881928957935,29.6899992972612,-0.06466465108721,-0.0121415737118056,0.25,-4.50361737796626E-5,-0.00578257280856374,-8.50546100990297E-5,10.0073671,10.0073671,-33515.6640625,-33500.5078125,57.3488660844868,20.629372140612,11.139823,0,0,0,40,4449,9.6314,-33508.0859375,,,,,,,,,,,,,0,,,,0,,,,,,10.0073671,,,,
,28802318.585,9.9970293,-28703.8251953125,-0.00563885699125612,4.9761032388433E-7,1,0.999253354069792,40.0298881530762,1.97936377233746,29.6899992972612,-0.0628699208580773,-0.0117571800084103,0.25,-4.09189883054693E-5,-0.0056198944875896,-7.85666708600254E-5,9.9970293,9.9970293,-28708.78125,-28698.869140625,57.2793011462753,20.6209336181571,11.519473,0,0,0,40,4449,9.6302,-28703.8251953125,,,,,,,,,,,,,0,,,,0,,,,,,9.9970293,,,,
,28802413.645,9.9904423,-23951.3447265625,-0.00545348376735522,5.82839426803926E-7,1,0.999253354069792,40.0298881530762,1.97924790654477,29.6899992972612,-0.060772448374183,-0.0113501826293922,0.25,-3.96975244459622E-5,-0.00543248640717078,-7.46721533465748E-5,9.9904423,9.9904423,-23956.515625,-23946.173828125,57.6091483813907,20.621867593171,11.519473,0,0,0,40,4449,9.62695,-23951.3447265625,,,,,,,,,,,,,0,,,,0.0049,,,,,,9.9904423,,,,
,28802507.025,10.0042706,-19283.6455078125,-0.00524586154138431,5.08005876372726E-7,1,0.999253354069792,40.0298881530762,1.97869804081386,29.6899992972612,-0.0584134204479687,-0.0109254121148836,0.25,-4.10738243143333E-5,-0.00522323443284575,-7.31624781398965E-5,10.0042706,10.0042706,-19288.48828125,-19278.802734375,57.2707032325638,20.633615103173,11.899124,0,0,0,40,4449,9.63235,-19283.6455078125,,,,,,,,,,,,,0,,,,0.00245,,,,,,10.0042706,,,,
,28802604.235,10.0022268,-14426.8686523438,-0.00500649637499373,5.58250548636395E-7,1,0.999253354069792,40.0298881530762,1.97868538666273,29.6899992972612,-0.0557296571593129,-0.0103817882661825,0.25,-3.72469757131145E-5,-0.0049826642426964,-6.61924908187956E-5,10.0022268,10.0022268,-14436.9072265625,-14416.830078125,57.4395349927176,20.6307414534194,11.519473,0,0,0,40,4449,9.65835,-14426.8686523438,,,,,,,,,,,,,0,,,,-0.00245,,,,,,10.0022268,,,,
,28802698.085,10.0062628,-9736.63916015625,-0.00473392087958708,4.62258204241191E-7,1,0.999253354069792,40.0298881530762,1.9785602988252,29.6899992972612,-0.0526731097682915,-0.00980150339777415,0.25,-3.5890464152069E-5,-0.00470950693835214,-6.16228821300132E-5,10.0062628,10.0062628,-9744.296875,-9728.9814453125,57.4418798782753,20.6347186791774,11.139823,0,0,0,40,4449,9.6356,-9736.63916015625,,,,,,,,,,,,,0,,,,-0.00245,,,,,,10.0062628,,,,
,28802791.47,10.0025759,-5065.759765625,-0.0043597936302387,4.95515633857278E-7,1,0.999253354069792,40.0298881530762,1.97926748850519,29.6899992972612,-0.0485100282128666,-0.00902628145119868,0.25,-3.44982822618324E-5,-0.00433579641079392,-5.66855660302537E-5,10.0025759,10.0025759,-5075.60498046875,-5055.91455078125,57.1815975813714,20.6269398473089,11.139823,0,0,0,40,4449,9.63555,-5065.759765625,,,,,,,,,,,,,0,,,,-0.0049,,,,,,10.0025759,,,,
,28802887.45,10.0012302,-269.088989257813,-0.00156632176319558,5.94950571212025E-6,1,0.999253354069792,40.0298881530762,1.97859050032134,29.6899992972612,-0.017419529496661,-0.0032294580733199,0.25,-1.1843071601765E-5,-0.00155727943196407,-1.93396530501414E-5,10.0012302,10.0012302,-276.531158447266,-261.646820068359,57.1511140691214,20.6343081938524,11.519473,0,0,0,40,4449,9.6324,-269.088989257813,,,,,,,,,,,,,0,,,,0.0049,,,,,,10.0012302,,,,
,28802983.175,9.9940033,4512.11743164063,0.00425003584666823,5.57633392755911E-7,1,0.999253354069792,40.0298881530762,1.97869392223332,29.6899992972612,0.047277088642554,0.00877856184503421,0.25,3.22058344320136E-5,0.00422649382862631,5.36744235006335E-5,9.9940033,9.9940033,4507.03271484375,4517.2021484375,57.2800827747945,20.6377745570364,11.139823,0,0,0,40,4449,9.6411,4512.11743164063,,,,,,,,,,,,,0,,,,0,,,,,,9.9940033,,,,
,28803078.475,9.9647131,9275.74951171875,0.00468697937362799,6.12479731418233E-7,1,0.999253354069792,40.0298881530762,1.97916670648354,29.6899992972612,0.0521636023640703,0.00970990786024515,0.25,3.59734473928831E-5,0.00466263433592568,6.12873187152282E-5,9.9647131,9.9647131,9270.90625,9280.5927734375,57.2245871499291,20.6219409786928,11.519473,0,0,0,40,4449,9.6315,9275.74951171875,,,,,,,,,,,,,0,,,,0,,,,,,9.9647131,,,,
,28803178.115,10.0063887,14258.4262695313,0.00498264849936242,5.77606441910363E-7,1,0.999253354069792,40.0298881530762,1.97876114245261,29.6899992972612,0.0554655886877792,0.0103314338593828,0.25,3.70284854335812E-5,0.00495885568378313,6.57758251036795E-5,10.0063887,10.0063887,14248.5341796875,14268.318359375,56.9893169656406,20.6313853931497,11.899124,0,0,0,40,4449,9.6377,14258.4262695313,,,,,,,,,,,,,0,,,,-0.00245,,,,,,10.0063887,,,,
,28803275.43,10.0059118,19117.8388671875,0.00523040380612984,6.43188009197154E-7,1,0.999253354069792,40.0298881530762,1.97891875488315,29.6899992972612,0.0582517785565957,0.0108651053800828,0.25,3.8400147524329E-5,0.0052077759997889,7.0347452465169E-5,10.0059118,10.0059118,19110.001953125,19125.67578125,57.5262957583522,20.6246093441029,11.519473,0,0,0,40,4449,9.6335,19117.8388671875,,,,,,,,,,,,,0,,,,0,,,,,,10.0059118,,,,
,28803374.52,10.0010462,24073.123046875,0.00545485158776765,6.67457118989001E-7,1,0.999253354069792,40.0298881530762,1.97867202173672,29.6899992972612,0.0607771009834163,0.0113189931587402,0.25,3.68881720438578E-5,0.00543393402800487,7.19216274067334E-5,10.0010462,10.0010462,24073.123046875,24073.123046875,57.4371901071599,20.6282536275275,11.139823,0,0,0,40,4449,9.6335,24073.123046875,,,,,,,,,,,,,0,,,,-0.00245,,,,,,10.0010462,,,,
,28803471.055,10.0140953,28895.9765625,0.00564270245284308,5.32712561455152E-7,1,0.999253354069792,40.0298881530762,1.97865424655703,29.6899992972612,0.0628932673147555,0.0117571836336345,0.25,4.05147167023969E-5,0.00562384259961566,7.82448923891888E-5,10.0140953,10.0140953,28885.783203125,28906.169921875,57.2964969736984,20.6263081169695,11.519473,0,0,0,40,4449,9.63395,28895.9765625,,,,,,,,,,,,,0,,,,0,,,,,,10.0140953,,,,
,28803565.325,10.0003605,33608.33984375,0.00580316742640374,5.42208678475643E-7,1,0.999253354069792,40.0298881530762,1.97887515898234,29.6899992972612,0.0647174310567031,0.0121182663981495,0.25,4.21656825568553E-5,0.00578663994605311,8.22446119207543E-5,10.0003605,10.0003605,33598.5,33618.1796875,57.4059249663907,20.623205429732,11.139823,0,0,0,40,4449,9.63365,33608.33984375,,,,,,,,,,,,,0,,,,-0.0049,,,,,,10.0003605,,,,
,28803653.695,10.0084362,38025.6796875,0.00593684988152174,8.26386311228841E-7,1,0.999253354069792,40.0298881530762,1.97862249149946,29.6899992972612,0.0662344282914068,0.0123844382448915,0.25,4.06160230842466E-5,0.00592273595039106,8.26334957812664E-5,10.0084362,10.0084362,38020.84375,38030.515625,57.1917587521214,20.6276279836042,11.139823,0,0,0,40,4449,9.62985,38025.6796875,,,,,,,,,,,,,0,,,,0,,,,,,10.0084362,,,,
,28803742.275,9.9988842,42451.126953125,0.00605100010389173,7.19435862049769E-7,1,0.999253354069792,40.0298881530762,1.97832582132188,29.6899992972612,0.0675317653786226,0.0126164834126834,0.25,3.97041333033483E-5,0.00603945281148036,8.33518657077678E-5,9.9988842,9.9988842,42443.6796875,42458.57421875,57.3410497992945,20.6301650640213,11.519473,0,0,0,40,4449,9.6262,42451.126953125,,,,,,,,,,,,,0,,,,0,,,,,,9.9988842,,,,
,28803833.785,9.9902487,47029.146484375,0.00615765044351956,8.32491597494276E-7,1,0.999253354069792,40.0298881530762,1.97911129988554,29.6899992972612,0.0687768587860529,0.0128727876795637,0.25,4.18478170240543E-5,0.0061488244572323,8.69083113420574E-5,9.9902487,9.9902487,47026.53125,47031.76171875,57.2839909173907,20.6263205692611,11.899124,0,0,0,40,4449,9.63,47029.146484375,,,,,,,,,,,,,0,,,,-0.0049,,,,,,9.9902487,,,,
,28803924.9,9.9986091,51581.94140625,0.00623683305162397,1.0442913161606E-6,1,0.999253354069792,40.0298881530762,1.97852149156203,29.6899992972612,0.069670992563077,0.0130562492865311,0.25,4.3375702415046E-5,0.00623077744609055,8.94587514375261E-5,9.9983006,9.9989176,51574.5625,51589.3203125,57.0776409883137,20.6224638890393,11.519473,0,0,0,40,4449,9.62605,51581.94140625,,,,,,,,,,,,,0,,,,0.00245,,,,,,9.9986091,,,,
,28804013.305,10.0042114,55999.513671875,0.00630589004981155,1.04113315607935E-6,1,0.999253354069792,40.0298881530762,1.97908391809664,29.6899992972612,0.0704883015124383,0.0132327940942912,0.25,4.56633263605662E-5,0.00630250813173253,9.25086579880274E-5,10.0042114,10.0042114,55986.953125,56012.07421875,57.085457273506,20.6304743586018,11.139823,0,0,0,40,4449,9.64495,55999.513671875,,,,,,,,,,,,,0,,,,0,,,,,,10.0042114,,,,
,28804106.65,9.9856033,60664.8203125,0.00636922076999526,1.2647711733911E-6,1,0.999253354069792,40.0298881530762,1.97889382534413,29.6899992972612,0.071216160707309,0.0133993519134716,0.25,4.86558847007123E-5,0.00636861923753026,9.60636760410133E-5,9.9856033,9.9856033,60655.00390625,60674.63671875,57.484869446833,20.627012617535,11.139823,0,0,0,40,4449,9.6408,60664.8203125,,,,,,,,,,,,,0,,,,-0.00245,,,,,,9.9856033,,,,
,28804202.89,10.002923,65475.197265625,0.00640722375374991,1.1746557206553E-6,1,0.999253354069792,40.0298881530762,1.97877787962265,29.6899992972612,0.0716741760702051,0.0134530131436248,0.25,4.62555166280265E-5,0.00640945083772571,9.38705270428171E-5,10.002923,10.002923,65467.60546875,65482.7890625,57.4012351952753,20.6195816764383,10.760172,0,0,0,40,4449,9.64725,65475.197265625,,,,,,,,,,,,,0,,,,-0.0049,,,,,,10.002923,,,,
,28804297.875,9.9862471,70220.4609375,0.00643650796685428,1.16850583400124E-6,1,0.999253354069792,40.0298881530762,1.97947300971296,29.6899992972612,0.0720510792300851,0.0135495866666471,0.25,4.89583027041558E-5,0.00644137921385806,9.6569105642785E-5,9.9862471,9.9862471,70215.375,70225.546875,57.3285437429868,20.6220959573722,11.899124,0,0,0,40,4449,9.65605,70220.4609375,,,,,,,,,,,,,0,,,,0,,,,,,9.9862471,,,,
,28804393.79,10.0130873,75015.921875,0.00645805228780001,1.20746780983678E-6,1,0.999253354069792,40.0298881530762,1.97881678011931,29.6899992972612,0.0723025960808217,0.0135693945431436,0.25,4.71427596582383E-5,0.00646550224554821,9.45557019472009E-5,10.0130873,10.0130873,75013.390625,75018.453125,57.3394865422561,20.6217615462098,11.139823,0,0,0,40,4449,9.6831,75015.921875,,,,,,,,,,,,,0,,,,0,,,,,,10.0130873,,,,
,28804484.455,10.0000219,79548.921875,0.00645380235500005,1.07406400528124E-6,1,0.999253354069792,40.0298881530762,1.97918263812109,29.6899992972612,0.0722910316726752,0.0135796186894305,0.25,4.86495931085429E-5,0.00646351147442855,9.55972683500223E-5,10.0000219,10.0000219,79546.4765625,79551.3671875,57.3582456267176,20.6197468074829,11.139823,0,0,0,40,4449,9.6637,79548.921875,,,,,,,,,,,,,0,,,,0,,,,,,10.0000219,,,,
,28804579.83,10.0060797,84314.8984375,0.00644384187850508,1.17511142979532E-6,1,0.999253354069792,40.0298881530762,1.97901929459005,29.6899992972612,0.0722023868145468,0.0135429378966316,0.25,4.74249813092726E-5,0.00645579555608984,9.37528703066648E-5,10.0060797,10.0060797,84309.8671875,84319.9296875,57.1472059265253,20.6219963801415,11.519473,0,0,0,40,4449,9.66015,84314.8984375,,,,,,,,,,,,,0,,,,-0.0049,,,,,,10.0060797,,,,
,28804666.44,10.0034494,88645.5390625,0.00644290440783991,1.29313458336524E-6,1,0.999253354069792,40.0298881530762,1.97923788797055,29.6899992972612,0.0722261304031815,0.0135178891986948,0.25,4.54617059386023E-5,0.0064567960733217,9.12189127087249E-5,10.0034494,10.0034494,88642.9140625,88648.1640625,57.4168677656599,20.6264364367275,11.139823,0,0,0,40,4449,9.6638,88645.5390625,,,,,,,,,,,,,0,,,,0.0049,,,,,,10.0034494,,,,
,28804770.54,10.003829,87161.1484375,0.00645046515669418,1.27186663674191E-6,1,0.999253354069792,40.0298881530762,1.97874258676429,29.6899992972612,0.072291478501454,0.0135007297823497,0.25,4.27740277127457E-5,0.00646374444482797,8.87775050947183E-5,10.003829,10.003829,87153.6171875,87168.6796875,57.2808644033138,20.6261567117793,11.139823,0,0,0,40,4449,9.66235,87161.1484375,,,,,,,,,,,,,0,,,,0.0049,,,,,,10.003829,,,,
,28804859.495,9.9956923,82712.13671875,0.00646854579107415,9.7155053060175E-7,1,0.999253354069792,40.0298881530762,1.97924502827045,29.6899992972612,0.0724900025499358,0.0135324433155925,0.25,4.18470498349731E-5,0.00647984252811348,8.85353918141865E-5,9.9956923,9.9956923,82709.3515625,82714.921875,57.200356665833,20.6279847290424,11.139823,0,0,0,40,4449,9.6623,82712.13671875,,,,,,,,,,,,,0,,,,0,,,,,,9.9956923,,,,
,28804952.06,10.0051861,78086,0.00644966194411939,9.77962603003408E-7,1,0.999253354069792,40.0298881530762,1.97873132994678,29.6899992972612,0.0722239939338265,0.0135491211540913,0.25,4.69131879015475E-5,0.00645865739408808,9.39785081337714E-5,10.0051861,10.0051861,78076.0859375,78095.9140625,57.2800827747945,20.6237031953091,10.760172,0,0,0,40,4449,9.65805,78086,,,,,,,,,,,,,0,,,,0.00245,,,,,,10.0051861,,,,
,28805046.845,10.01352785,73347.69921875,0.00644559175303186,9.45834609492553E-7,1,0.999253354069792,40.0298881530762,1.978451205319,29.6899992972612,0.0721459592043977,0.0135095516540377,0.25,4.4274582117202E-5,0.00645217929835089,9.17298911359514E-5,10.0119333,10.0151224,73337.4609375,73357.9375,56.9572701963522,20.6231321401064,10.760172,0,0,0,40,4449,9.6582,73347.69921875,,,,,,,,,,,,,0,,,,0,,,,,,10.01352785,,,,
,28805135.995,10.0067978,68892.015625,0.00643044484583794,9.82268358177511E-7,1,0.999253354069792,40.0298881530762,1.97875857415024,29.6899992972612,0.0719566691851376,0.0134949816329867,0.25,4.56442215449558E-5,0.00643460747697966,9.3283837668741E-5,10.0067978,10.0067978,68884.1875,68899.84375,57.3621537693137,20.6227221655809,11.139823,0,0,0,40,4449,9.6555,68892.015625,,,,,,,,,,,,,0,,,,0,,,,,,10.0067978,,,,
,28805225.695,9.993474,64408.951171875,0.00639832650563179,9.69132262281321E-7,1,0.999253354069792,40.0298881530762,1.97899276980985,29.6899992972612,0.071568640078584,0.0134710974254105,0.25,4.94240459166783E-5,0.00639991560180359,9.70045018501807E-5,9.993474,9.993474,64406.5,64411.40234375,57.2198973788137,20.621964544164,11.139823,0,0,0,40,4449,9.65035,64408.951171875,,,,,,,,,,,,,0,,,,0,,,,,,9.993474,,,,
,28805311.375,10.0021906,60126.005859375,0.00635355494709385,1.31246429358921E-6,1,0.999253354069792,40.0298881530762,1.97892923526899,29.6899992972612,0.0710494904847283,0.0133056733882256,0.25,4.31499444577591E-5,0.00635267433605503,9.04395581358723E-5,10.0021906,10.0021906,60118.390625,60133.62109375,57.3363600281791,20.6217311502534,11.139823,0,0,0,40,4449,9.64335,60126.005859375,,,,,,,,,,,,,0,,,,0,,,,,,10.0021906,,,,
,28805399.305,10.01704265,55732.328125,0.00630188419160641,9.35121969071025E-7,1,0.999253354069792,40.0298881530762,1.9785021896618,29.6899992972612,0.0704119165197613,0.0132757308141656,0.25,5.05937480630485E-5,0.00629830355390897,9.73962709898736E-5,10.0124855,10.0215998,55724.64453125,55740.01171875,57.2347483206791,20.6203707502046,11.139823,0,0,0,40,4449,9.6387,55732.328125,,,,,,,,,,,,,0,,,,0,,,,,,10.01704265,,,,
,28805485.44,10.0065908,51424.87890625,0.00623746089163165,9.96688289372599E-7,1,0.999253354069792,40.0298881530762,1.97879985221138,29.6899992972612,0.0696822484187418,0.0130814359790125,0.25,4.53863631336094E-5,0.00623129133150175,9.14600946225905E-5,10.0065908,10.0065908,51422.24609375,51427.51171875,57.3863842534099,20.6149795347268,11.519473,0,0,0,40,4449,9.63365,51424.87890625,,,,,,,,,,,,,0,,,,0,,,,,,10.0065908,,,,
,28805571.07,10.0052662,47144.595703125,0.00616110814003519,9.35254809211501E-7,1,0.999253354069792,40.0298881530762,1.97876740994306,29.6899992972612,0.0688027296126057,0.012889923940748,0.25,4.29224202335278E-5,0.00615234266510335,8.80203480315205E-5,10.0052662,10.0052662,47134.40625,47154.78515625,57.4926857320253,20.6177761515406,11.139823,0,0,0,40,4449,9.62475,47144.595703125,,,,,,,,,,,,,0,,,,0.00245,,,,,,10.0052662,,,,
,28805658.295,9.9948502,42786.52734375,0.00606550316097666,6.52181535234979E-7,1,0.999253354069792,40.0298881530762,1.97907874775248,29.6899992972612,0.0677168201070404,0.0126729708002616,0.25,4.16450936484699E-5,0.00605412837512017,8.54478596708344E-5,9.9948502,9.9948502,42781.58984375,42791.46484375,57.3504293415253,20.6223959075583,11.519473,0,0,0,40,4449,9.62585,42786.52734375,,,,,,,,,,,,,0,,,,0.00245,,,,,,9.9948502,,,,
,28805744.875,10.002389,38458.859375,0.00595547545439736,8.73819380204281E-7,1,0.999253354069792,40.0298881530762,1.97891198374609,29.6899992972612,0.0664537119734468,0.0124304017493058,0.25,4.10887912640529E-5,0.00594158795281323,8.3325266195126E-5,10.002389,10.002389,38448.94921875,38468.76953125,57.4504777919868,20.6213936031121,11.139823,0,0,0,40,4449,9.62485,38458.859375,,,,,,,,,,,,,0,,,,0,,,,,,10.002389,,,,
,28805833.14,10.0007067,34048.701171875,0.00582351497680538,6.92660911023636E-7,1,0.999253354069792,40.0298881530762,1.97888264039269,29.6899992972612,0.0649519626423255,0.0121372302265521,0.25,4.00475721808094E-5,0.00580721638239595,8.03811578174918E-5,10.0007067,10.0007067,34035.92578125,34061.4765625,57.5059734168522,20.6191945392243,11.139823,0,0,0,40,4449,9.6211,34048.701171875,,,,,,,,,,,,,0,,,,0,,,,,,10.0007067,,,,
,28805915.905,10.00294015,29910.7236328125,0.00568723532448741,6.77291645808098E-7,1,0.999253354069792,40.0298881530762,1.97872109443918,29.6899992972612,0.0634051075817467,0.0118144455773452,0.25,3.7222951214229E-5,0.00566885337984024,7.5551057139752E-5,10.0018835,10.0039968,29903.0703125,29918.376953125,57.3473028274484,20.6241798674955,11.519473,0,0,0,40,4449,9.6204,29910.7236328125,,,,,,,,,,,,,0,,,,0,,,,,,10.00294015,,,,
,28806004.47,10.0038166,25485.58203125,0.00551747391791794,7.9974071987526E-7,1,0.999253354069792,40.0298881530762,1.9787380532158,29.6899992972612,0.0614832828324535,0.0114642544043856,0.25,3.80609492231442E-5,0.005497102198019,7.39454512825445E-5,10.0038166,10.0038166,25480.673828125,25490.490234375,57.4395349927176,20.619418122528,11.139823,0,0,0,40,4449,9.61785,25485.58203125,,,,,,,,,,,,,0,,,,0,,,,,,10.0038166,,,,
,28806092.32,9.9993362,21095.5283203125,0.00533233408881976,4.0932295211329E-7,1,0.999253354069792,40.0298881530762,1.97846547747289,29.6899992972612,0.0593851178681164,0.0110784872934345,0.25,3.86443860263399E-5,0.0053102899384737,7.19043769332493E-5,9.9993362,9.9993362,21088.080078125,21102.9765625,57.095618444256,20.6225837542531,11.519473,0,0,0,40,4449,9.6189,21095.5283203125,,,,,,,,,,,,,0,,,,0.00245,,,,,,9.9993362,,,,
,28806178.375,9.9998722,16795.4638671875,0.00512870403070677,4.74524001818127E-7,1,0.999253354069792,40.0298881530762,1.97842677761065,29.6899992972612,0.0570944524614919,0.0106406829400042,0.25,3.77102875586903E-5,0.00510539468231958,6.8224760334246E-5,9.9998722,9.9998722,16785.34765625,16805.580078125,57.423902422333,20.6250749065805,11.139823,0,0,0,40,4449,9.6142,16795.4638671875,,,,,,,,,,,,,0,,,,0,,,,,,9.9998722,,,,
,28806266.055,9.9961443,12410.5092773437,0.00489542322775552,5.63408284569919E-7,1,0.999253354069792,40.0298881530762,1.97812360046464,29.6899992972612,0.0544721639827722,0.0101281327648753,0.25,3.54462548438577E-5,0.00487126624533977,6.30356068518373E-5,9.9961443,9.9961443,12398.08203125,12422.9365234375,57.5090999309292,20.616915649531,11.139823,0,0,0,40,4449,9.6182,12410.5092773437,,,,,,,,,,,,,0,,,,0,,,,,,9.9961443,,,,
,28806348.35,9.9910517,8297.19287109375,0.00464091746743108,4.99639550363665E-7,1,0.999253354069792,40.0298881530762,1.97879869962822,29.6899992972612,0.0516404364161701,0.00959734623061961,0.25,3.46371900382833E-5,0.00461646465415472,5.93687597607356E-5,9.9910517,9.9910517,8294.7197265625,8299.666015625,57.4043617093522,20.6194783946334,11.519473,0,0,0,40,4449,9.617,8297.19287109375,,,,,,,,,,,,,0,,,,-0.0049,,,,,,9.9910517,,,,
,28806434.745,9.9905958,3979.13488769531,0.0042095772770295,6.4551564601882E-7,1,0.999253354069792,40.0298881530762,1.9784671376094,29.6899992972612,0.0468216754139688,0.00868585685472627,0.25,3.13483019918468E-5,0.00418611739823874,5.24578157355558E-5,9.9905958,9.9905958,3976.54663085937,3981.72314453125,57.180034324333,20.6220547876655,11.519473,0,0,0,40,4449,9.61305,3979.13488769531,,,,,,,,,,,,,0,,,,0,,,,,,9.9905958,,,,
,28806516.18,9.9937134,-0.342534884810448,0.000515838987134391,1.46421008597576E-6,1,0.999253354069792,40.0298881530762,1.97942602771721,29.6899992972612,0.00574047684232079,0.00105604190079069,0.25,3.19246467558344E-6,0.000512860327069865,5.66043518422337E-6,9.9937134,9.9937134,-0.365370541810989,-0.319699227809906,57.0495023616214,20.6218132066942,11.139823,0,0,0,40,4417,9.6107,-0.342534884810448,,,,,,,,,,,,,0,,,,-0.00245,,,,,,9.9937134,,,,