File: data/looselyPackedNP/nanoparticles/vsm/ios-7/rawdata/KWI338_ZFCW_100OE.DAT
[Header]
; VSM Data File (default extension .dat)
; Copyright (c) 2003-2013, Quantum Design, Inc. All rights reserved.
TITLE,
FILEOPENTIME,28895017.36,12/01/2018,6:24 pm
BYAPP,VSM,2.0,2.0
INFO,PPMS VSM Option Release 1.4.10 Build 1,APPNAME
INFO,Quantum Design Linear Motor Servo Controller,MOTOR_MODULE_NAME
INFO,3101-100 M1,MOTOR_HW_VERSION
INFO,MMC1014,MOTOR_SERIAL_NUMBER
INFO,SRV No X-over 01.03.11,MOTOR_SOFTWARE_VERSION
INFO,Quantum Design VSM Detection Module,VSM_MODULE_NAME
INFO,3101-150 F0,VSM_HW_VERSION
INFO,VSM707,VSM_SERIAL_NUMBER
INFO,VSM No X-over 01.02.05 May 20 2008 13:51:47,VSM_SOFTWARE_VERSION
INFO,704,PREAMP_SERIAL_NUMBER
INFO,822,COIL_SERIAL_NUMBER
INFO,0,MOMENT_UNITS
INFO,Maghemite,SAMPLE_MATERIAL
INFO,Oleate Iron Spheres,SAMPLE_COMMENT
INFO,,SAMPLE_MASS
INFO,,SAMPLE_VOLUME
INFO,,SAMPLE_MOLECULAR_WEIGHT
INFO,,SAMPLE_SIZE
INFO,,SAMPLE_SHAPE
DATATYPE,COMMENT,1
DATATYPE,TIME,2
STARTUPAXIS,X,2
STARTUPAXIS,Y1,5
[Data]
Comment,Time Stamp (sec),Temperature (K),Magnetic Field (Oe),Moment (emu),M. Std. Err. (emu),Transport Action,Averaging Time (sec),Frequency (Hz),Peak Amplitude (mm),Center Position (mm),Coil Signal' (mV),Coil Signal" (mV),Range (mV),M. Quad. Signal (emu),M. Raw' (emu),M. Raw" (emu),Min. Temperature (K),Max. Temperature (K),Min. Field (Oe),Max. Field (Oe),Mass (grams),Motor Lag (deg),Pressure (Torr),VSM Status (code),Motor Status (code),Measure Status (code),Measure Count,PPMS Status (code),System Temp. (K),System Field (Oe),Sample Position (deg),Bridge 1 Resistance (ohms),Bridge 1 Excitation (에),Bridge 2 Resistance (ohms),Bridge 2 Excitation (에),Bridge 3 Resistance (ohms),Bridge 3 Excitation (에),Bridge 4 Resistance (ohms),Bridge 4 Excitation (에),Signal 1 Vin (V),Signal 2 Vin (V),Digital Inputs (code),Drive 1 Iout (mA),Drive 1 Ipower (W),Drive 2 Iout (mA),Drive 2 Ipower (W),Pressure (),Map 20 (),Map 21 (),Map 22 (),Map 23 (),Map 24 (),Map 25 (),Map 26 (),Map 27 (),Map 28 (),Map 29 ()
,28899737.44,10.0396547,99.5330276489258,0.000223780668366104,3.859008886397E-7,1,0.999253354069792,40.0298881530762,1.99993646659354,29.4000003486872,0.00251467424377174,0.000464314700494548,0.25,1.53103577270944E-6,0.000222488295517149,2.60149981547996E-6,10.0396547,10.0396547,99.5330276489258,99.5330276489258,56.7149653553906,20.4391632221622,12.658426,0,0,0,40,4369,9.9288,99.5330276489258,,,,,,,,,,,,,0,,,,0.00245,,,,,,10.0396547,,,,
,28899865.16,13.0231142,99.5330276489258,0.000252772287049358,3.12941971395947E-7,1,0.999253354069792,40.0298881530762,2.00028990084315,29.4000003486872,0.00284101891882016,0.0005240086666564,0.25,1.68094359368291E-6,0.00025131125470263,2.89035160211609E-6,13.0231142,13.0231142,99.5330276489258,99.5330276489258,57.342613056333,20.4386955025667,13.797379,0,0,0,40,4370,13.061,99.5330276489258,,,,,,,,,,,,,0,,,,0,,,,,,13.0231142,,,,
,28900005.5,16.5129223,99.5330276489258,0.000303796944306227,3.1270393286851E-7,1,0.999253354069792,40.0298881530762,2.00025163456859,29.4000003486872,0.00341409802012714,0.00063153700565166,0.25,2.17750800537439E-6,0.000302037316527737,3.6301084532694E-6,16.5129223,16.5129223,99.5330276489258,99.5330276489258,57.1378263842945,20.4503208801487,13.797379,0,0,0,40,4370,16.57615,99.5330276489258,,,,,,,,,,,,,0,,,,-0.00245,,,,,,16.5129223,,,,
,28900146.485,20.0265579,99.5330276489258,0.000357435375665917,3.15177945896261E-7,1,0.999253354069792,40.0298881530762,2.00029816816681,29.4000003486872,0.0040168119811265,0.00074429111082427,0.25,2.66039298959011E-6,0.000355368840849216,4.37927247387856E-6,20.0265579,20.0265579,99.5330276489258,99.5330276489258,57.1386080128137,20.4453141551281,14.936333,0,0,0,40,4370,20.1316,99.5330276489258,,,,,,,,,,,,,0,,,,0,,,,,,20.0265579,,,,
,28900269.44,23.0739231,99.5330276489258,0.000407018255412784,3.02934218951056E-7,1,0.999253354069792,40.0298881530762,1.97578060921471,29.1600003838539,0.00452046525574043,0.000839780753335422,0.25,3.17322295508416E-6,0.00040469769860375,5.1746255696058E-6,23.0739231,23.0739231,99.5330276489258,99.5330276489258,56.9572701963522,20.4549478227585,14.936333,0,0,0,40,4370,23.234,99.5330276489258,,,,,,,,,,,,,0,,,,-0.00245,,,,,,23.0739231,,,,
,28900409.385,26.5570488,99.5330276489258,0.000460900839869703,3.35528941642896E-7,1,0.999253354069792,40.0298881530762,1.97573782675387,29.1600003838539,0.00511942709746424,0.000953071416197996,0.25,3.66561223456081E-6,0.000458359882788014,6.03558471743407E-6,26.5570488,26.5570488,99.5330276489258,99.5330276489258,57.0917103016599,20.4567554792986,15.695635,0,0,0,40,4370,26.7598,99.5330276489258,,,,,,,,,,,,,0,,,,0.00245,,,,,,26.5570488,,,,
,28900552.32,30.0434361,99.5330276489258,0.000511892790240124,3.62632383011135E-7,1,0.999253354069792,40.0298881530762,1.97606369206266,29.1600003838539,0.00568857316246803,0.00105895808593246,0.25,3.89463853834175E-6,0.000509236157430345,6.69946524597503E-6,30.0434361,30.0434361,99.5330276489258,99.5330276489258,57.088583787583,20.4587646605959,16.075285,0,0,0,40,4370,30.35585,99.5330276489258,,,,,,,,,,,,,0,,,,0,,,,,,30.0434361,,,,
,28900693.56,33.5657959,99.5330276489258,0.000555086221796101,2.6124616805989E-7,1,0.999253354069792,40.0298881530762,1.99980125395928,29.0699992328882,0.00624068736520509,0.0011709615895321,0.25,4.78780275701709E-6,0.000552462878198894,8.05735191955246E-6,33.5657959,33.5657959,99.5330276489258,99.5330276489258,57.1018714724099,20.4597914590785,17.214239,0,0,0,40,4370,33.9089,99.5330276489258,,,,,,,,,,,,,0,,,,0,,,,,,33.5657959,,,,
,28900835.305,37.0394516,99.5330276489258,0.000586750314219339,3.06106236540697E-7,1,0.999253354069792,40.0298881530762,1.99970420184051,29.0699992328882,0.00660067252523323,0.00123863277040177,0.25,4.80385574785232E-6,0.000584359837349074,8.53332235084846E-6,37.0394516,37.0394516,99.5330276489258,99.5330276489258,57.2347483206791,20.467072127444,16.834587,0,0,0,40,4370,37.4923,99.5330276489258,,,,,,,,,,,,,0,,,,0.00245,,,,,,37.0394516,,,,
,28900974.53,40.5069351,99.5330276489258,0.00060673209454195,3.13234758591223E-7,1,0.999253354069792,40.0298881530762,1.99958612438784,29.0699992328882,0.0068315917829636,0.0012765951647656,0.25,4.24564701224968E-6,0.000604757801483847,8.37181466221916E-6,40.5069351,40.5069351,99.5330276489258,99.5330276489258,57.1847240954484,20.4696511146825,17.593889,0,0,0,40,4370,41.005,99.5330276489258,,,,,,,,,,,,,0,,,,0,,,,,,40.5069351,,,,
,28901118.13,44.0456009,99.5330276489258,0.000616449887536798,3.47228325177657E-7,1,0.999253354069792,40.0298881530762,2.00016221105899,29.0699992328882,0.00694989394581678,0.00129890207053729,0.25,4.1104132604643E-6,0.000615064221154988,8.53161233191684E-6,44.0456009,44.0456009,99.5330276489258,99.5330276489258,57.1284468420637,20.4623012009886,17.593889,0,0,0,40,4370,44.6447,99.5330276489258,,,,,,,,,,,,,0,,,,-0.00245,,,,,,44.0456009,,,,
,28901261.065,47.5196075,99.5330276489258,0.000617633867187667,3.05796122522904E-7,1,0.999253354069792,40.0298881530762,1.9997558186416,29.0699992328882,0.00697030634040148,0.00129900255097133,0.25,3.67307804500946E-6,0.000616935365499641,8.23980703846568E-6,47.5196075,47.5196075,99.5330276489258,99.5330276489258,57.1425161554099,20.4688953119517,17.973541,0,0,0,40,4370,48.2789,99.5330276489258,,,,,,,,,,,,,0,,,,-0.00245,,,,,,47.5196075,,,,
,28901404.44,51.0354042,99.5330276489258,0.000612111010331856,3.29278997519626E-7,1,0.999253354069792,40.0298881530762,1.99972568809527,29.0699992328882,0.00691637010978617,0.00128609683008116,0.25,3.38295480754855E-6,0.000612128084561039,7.93142427270171E-6,51.0354042,51.0354042,99.5330276489258,99.5330276489258,56.9181887703906,20.4702256056327,18.353191,0,0,0,40,4374,51.9593,99.5330276489258,,,,,,,,,,,,,0,,,,0,,,,,,51.0354042,,,,
,28901549.64,54.5136032,99.5330276489258,0.000599996731262702,3.03417743430679E-7,1,0.999253354069792,40.0298881530762,1.99985929911543,29.0900003165007,0.00678799659472364,0.0012592847777855,0.25,3.16284688938447E-6,0.000600684662615674,7.53152929424546E-6,54.5136032,54.5136032,99.5330276489258,99.5330276489258,57.2628869473714,20.4693763057512,20.251448,0,0,0,40,4374,55.68525,99.5330276489258,,,,,,,,,,,,,0,,,,0,,,,,,54.5136032,,,,
,28901695.49,58.0203362,99.5330276489258,0.000585172161107342,3.23467410377069E-7,1,0.999253354069792,40.0298881530762,1.99907695612811,29.0900003165007,0.00662433331103568,0.00122982949058297,0.25,3.34759498409039E-6,0.000586434080061667,7.43047991077756E-6,58.0203362,58.0203362,99.5330276489258,99.5330276489258,57.2324034351214,20.4806149304943,21.01075,0,0,0,40,4374,59.47155,99.5330276489258,,,,,,,,,,,,,0,,,,0,,,,,,58.0203362,,,,
,28901839.14,61.535408,99.5330276489258,0.000567072346368779,3.41711402488658E-7,1,0.999253354069792,40.0298881530762,1.99924738765603,29.0900003165007,0.00642541788509533,0.00119196593908911,0.25,3.39067348193236E-6,0.0005687645398618,7.12663945233335E-6,61.535408,61.535408,99.5330276489258,99.5330276489258,57.2441278629099,20.4762725114294,22.149702,0,0,0,40,4374,63.1359,99.5330276489258,,,,,,,,,,,,,0,,,,-0.00245,,,,,,61.535408,,,,
,28901982.585,65.039093,99.5330276489258,0.000547282493154931,3.40373751441639E-7,1,0.999253354069792,40.0298881530762,1.99979059492862,29.0699992328882,0.0062076244917727,0.00114756778326727,0.25,3.17185322328173E-6,0.000549284364124805,6.54065810376834E-6,65.039093,65.039093,99.5330276489258,99.5330276489258,57.1323549846599,20.468634592204,22.149702,0,0,0,40,4374,66.7732,99.5330276489258,,,,,,,,,,,,,0,,,,0,,,,,,65.039093,,,,
,28902123.02,68.527771,99.5330276489258,0.000526993070559152,3.57664799289586E-7,1,0.999253354069792,40.0298881530762,1.99958075424491,29.0699992328882,0.00598016589672518,0.00110440387631208,0.25,3.18763611417716E-6,0.000529194079427737,6.20601157150963E-6,68.527771,68.527771,99.5330276489258,99.5330276489258,57.098744958333,20.4745323286024,22.909004,0,0,0,40,4374,70.3082,99.5330276489258,,,,,,,,,,,,,0,,,,0,,,,,,68.527771,,,,
,28902263.345,72.008873,99.5330276489258,0.000507007178395327,3.18040811110558E-7,1,0.999253354069792,40.0298881530762,1.99985476311324,29.0699992328882,0.00575795625752611,0.00105464762766331,0.25,2.53682112264958E-6,0.0005093347642815,5.22699439632006E-6,72.008873,72.008873,99.5330276489258,99.5330276489258,57.268358347006,20.4738815341929,23.288654,0,0,0,40,4374,73.85,99.5330276489258,,,,,,,,,,,,,0,,,,0.00245,,,,,,72.008873,,,,
,28902406.945,75.5460739,99.5330276489258,0.000487050499865735,3.54293271397532E-7,1,0.999253354069792,40.0298881530762,1.99996732958736,29.0699992328882,0.00553438550943248,0.00100782668099923,0.25,2.13306744674979E-6,0.000489445075101162,4.52038113537113E-6,75.5460739,75.5460739,99.5330276489258,99.5330276489258,57.0659165605253,20.4686439154342,23.288654,0,0,0,40,4374,77.4839,99.5330276489258,,,,,,,,,,,,,0,,,,0,,,,,,75.5460739,,,,
,28902549.18,79.0966949,99.5330276489258,0.000468209443848241,3.21976684713779E-7,1,0.999253354069792,40.0298881530762,2.00010436553842,29.0699992328882,0.00532183952859424,0.000969532372610222,0.25,2.25704345873703E-6,0.000470623432174903,4.38172219447668E-6,79.0966949,79.0966949,99.5330276489258,99.5330276489258,57.268358347006,20.4680771533632,23.288654,0,0,0,40,4374,81.0933,99.5330276489258,,,,,,,,,,,,,0,,,,0,,,,,,79.0966949,,,,
,28902692.685,82.61779025,99.5330276489258,0.000449925721425455,3.81208075238246E-7,1,0.999253354069792,40.0298881530762,1.99983654084408,29.0699992328882,0.00511460215201983,0.000929901905155431,0.25,2.15906641673878E-6,0.000452326957184777,4.05077108140904E-6,82.5720978,82.6634827,99.5330276489258,99.5330276489258,57.1659650109868,20.4731960314669,23.288654,0,0,0,40,4374,84.72195,99.5330276489258,,,,,,,,,,,,,0,,,,0.00245,,,,,,82.61779025,,,,
,28902831.165,86.0476074,99.5330276489258,0.000433092140582477,3.41125639838555E-7,1,0.999253354069792,40.0298881530762,1.97619805568859,29.0699992328882,0.00486831011234037,0.000884819374006505,0.25,2.17663915838298E-6,0.000435457665789826,3.87342734349055E-6,86.0476074,86.0476074,99.5330276489258,99.5330276489258,57.1964485232368,20.4677217132965,23.668306,0,0,0,40,4374,88.19905,99.5330276489258,,,,,,,,,,,,,0,,,,-0.0049,,,,,,86.0476074,,,,
,28902969.285,89.5255585,99.5330276489258,0.00041718147992499,3.46965122326423E-7,1,0.999253354069792,40.0298881530762,1.97617624132076,29.0699992328882,0.00469088024087069,0.000846347221343177,0.25,1.66798755299164E-6,0.000419498294662793,3.19248991946976E-6,89.5255585,89.5255585,99.5330276489258,99.5330276489258,57.3004051162945,20.4706527406585,23.288654,0,0,0,40,4374,91.65675,99.5330276489258,,,,,,,,,,,,,0,,,,0.0049,,,,,,89.5255585,,,,
,28903108.61,93.0042343,99.5330276489258,0.00040241464601551,3.63335287243401E-7,1,0.999253354069792,40.0298881530762,1.97610697211032,29.0699992328882,0.00452504338486561,0.000815887934164733,0.25,1.65645405870101E-6,0.000404673256861947,3.03303783162449E-6,93.0042343,93.0042343,99.5330276489258,99.5330276489258,57.1909771236022,20.4745919882274,24.047956,0,0,0,40,4374,95.14635,99.5330276489258,,,,,,,,,,,,,0,,,,0,,,,,,93.0042343,,,,
,28903252.14,96.5737228,99.5330276489258,0.000387811320826495,3.10724413477407E-7,1,0.999253354069792,40.0298881530762,2.0010885009599,29.0699992328882,0.00441362825010453,0.000795770162999796,0.25,1.67778473861118E-6,0.000390002088189622,2.92058939059515E-6,96.5737228,96.5737228,99.5330276489258,99.5330276489258,57.0932735586983,20.4595965047237,24.427608,0,0,0,40,4374,98.75375,99.5330276489258,,,,,,,,,,,,,0,,,,0,,,,,,96.5737228,,,,
,28903391.88,100.049675,99.5330276489258,0.000374583120165339,3.424656701248E-7,1,0.999253354069792,40.0298881530762,2.00072989784692,29.0699992328882,0.00426361585040615,0.000761684738694749,0.25,1.09239671653469E-6,0.000376706839927849,2.21853267165413E-6,100.049675,100.049675,99.5330276489258,99.5330276489258,57.1034347294484,20.4605201845427,23.668306,0,0,0,40,4374,102.2656,99.5330276489258,,,,,,,,,,,,,0,,,,0,,,,,,100.049675,,,,
,28903533.325,103.5461807,99.5330276489258,0.000361871270479967,3.22941125837619E-7,1,0.999253354069792,40.0298881530762,2.00080451585563,29.0699992328882,0.00411858290774342,0.000738646558121878,0.25,1.3622355907414E-6,0.000363922147953471,2.38911031925671E-6,103.5461807,103.5461807,99.5330276489258,99.5330276489258,57.1198489283522,20.4619601164169,24.047956,0,0,0,40,4374,105.8184,99.5330276489258,,,,,,,,,,,,,0,,,,0,,,,,,103.5461807,,,,
,28903672.71,107.0009155,99.5330276489258,0.000349800212747243,3.38789890314139E-7,1,0.999253354069792,40.0298881530762,1.98857443096357,29.0699992328882,0.00395791678434612,0.000709804394691212,0.25,1.36823953979484E-6,0.000351777969499505,2.30701483156252E-6,107.0009155,107.0009155,99.5330276489258,99.5330276489258,57.1104693861214,20.4469105456992,24.427608,0,0,0,40,4374,109.32785,99.5330276489258,,,,,,,,,,,,,0,,,,-0.0049,,,,,,107.0009155,,,,
,28903814.46,110.5333405,99.5330276489258,0.000338771640962626,3.61322161382924E-7,1,0.999253354069792,40.0298881530762,1.98858144447539,29.0699992328882,0.00383297877267007,0.000687797018739111,0.25,1.40722165105024E-6,0.000340678316968632,2.26855863917268E-6,110.5333405,110.5333405,99.5330276489258,99.5330276489258,57.1409528983714,20.4517289296702,24.807261,0,0,0,40,4374,112.9002,99.5330276489258,,,,,,,,,,,,,0,,,,0,,,,,,110.5333405,,,,
,28903954.895,114.0333099,99.5330276489258,0.000328561412490969,3.13660935463299E-7,1,0.999253354069792,40.0298881530762,1.98819038186408,29.0699992328882,0.0037173272280938,0.000662930262467572,0.25,1.05412047166713E-6,0.000330399952545958,1.84578225504824E-6,114.0333099,114.0333099,99.5330276489258,99.5330276489258,57.3308886285445,20.4586523575426,24.807261,0,0,0,40,4374,116.42825,99.5330276489258,,,,,,,,,,,,,0,,,,0.0049,,,,,,114.0333099,,,,
,28904095.32,117.5044098,99.5330276489258,0.000318875861853137,3.484998866483E-7,1,0.999253354069792,40.0298881530762,2.00153839852476,29.0699992328882,0.00363057828662772,0.000648223938205717,0.25,1.12481596810795E-6,0.000320646433182161,1.85669478625787E-6,117.5044098,117.5044098,99.5330276489258,99.5330276489258,57.2238055214099,20.448141424919,24.427608,0,0,0,40,4374,119.9512,99.5330276489258,,,,,,,,,,,,,0,,,,0.00245,,,,,,117.5044098,,,,
,28904238.06,121.0376129,99.5330276489258,0.000309559040467995,3.30064280493657E-7,1,0.999253354069792,40.0298881530762,2.0018770975786,29.0699992328882,0.00352520514290366,0.000627566944170287,0.25,9.6823724501529E-7,0.00031126255240398,1.64462914469235E-6,121.0376129,121.0376129,99.5330276489258,99.5330276489258,57.2808644033138,20.4455648185431,24.807261,0,0,0,40,4374,123.5447,99.5330276489258,,,,,,,,,,,,,0,,,,0,,,,,,121.0376129,,,,
,28904376.585,124.5013504,99.5330276489258,0.000300743515511472,2.76406510981117E-7,1,0.999253354069792,40.0298881530762,2.00150835082257,29.0699992328882,0.00342416197232139,0.00060875410571577,0.25,8.98942038939128E-7,0.000302381763232337,1.52709719851924E-6,124.5013504,124.5013504,99.5330276489258,99.5330276489258,56.9877537086022,20.4535992861606,25.186911,0,0,0,40,4374,127.0235,99.5330276489258,,,,,,,,,,,,,0,,,,-0.00245,,,,,,124.5013504,,,,
,28904518.735,128.0251999,99.5330276489258,0.000292218935159959,3.72465532194E-7,1,0.999253354069792,40.0298881530762,1.98878041307554,29.0699992328882,0.00330682824278048,0.000587137747336818,0.25,8.34677943239093E-7,0.0002937926269249,1.41856084674598E-6,127.9933014,128.0570984,99.5330276489258,99.5330276489258,57.1511140691214,20.4468716037376,25.186911,0,0,0,40,4374,130.58875,99.5330276489258,,,,,,,,,,,,,0,,,,0,,,,,,128.0251999,,,,
,28904658.525,131.5089569,99.5330276489258,0.000283970337116687,2.93227359821516E-7,1,0.999253354069792,40.0298881530762,1.98876018648825,29.0699992328882,0.00321322536247448,0.000570607267423556,0.25,8.41581446549909E-7,0.000285480647311878,1.3860931527106E-6,131.5089569,131.5089569,99.5330276489258,99.5330276489258,57.2980602307368,20.4486118114694,24.807261,0,0,0,40,4374,134.0923,99.5330276489258,,,,,,,,,,,,,0,,,,0,,,,,,131.5089569,,,,
,28904795.25,135.072876,99.5330276489258,0.000267916649803754,3.42068828177243E-7,1,0.999253354069792,40.0298881530762,1.98848597361013,29.0699992328882,0.00303099114628196,0.000538006199351619,0.25,7.92611468655347E-7,0.000269321850248498,1.28698360001116E-6,135.072876,135.072876,99.5330276489258,99.5330276489258,57.0182372208522,20.4526393246336,25.186911,0,0,0,40,4374,137.4655,99.5330276489258,,,,,,,,,,,,,0,,,,0.0049,,,,,,135.072876,,,,
,28904921.105,138.0582428,99.5330276489258,0.000269596663101578,3.64230421352294E-7,1,0.999253354069792,40.0298881530762,1.97735736231965,29.0699992328882,0.00303243224884491,0.000544567842754489,0.25,1.35795066960542E-6,0.000270992761694278,1.84109880058454E-6,138.0582428,138.0582428,99.5330276489258,99.5330276489258,57.027616763083,20.4517133073937,25.566563,0,0,0,40,4374,140.68245,99.5330276489258,,,,,,,,,,,,,0,,,,0,,,,,,138.0582428,,,,
,28905059.03,141.5103455,99.5330276489258,0.000262822652833978,2.71402392239021E-7,1,0.999253354069792,40.0298881530762,1.97742602360386,29.0699992328882,0.00295680827860257,0.000526851040841845,0.25,9.84214187828417E-7,0.000264164001383829,1.43662103481828E-6,141.5103455,141.5103455,99.5330276489258,99.5330276489258,57.2097362080637,20.4516902482322,25.566563,0,0,0,40,4374,144.1464,99.5330276489258,,,,,,,,,,,,,0,,,,0,,,,,,141.5103455,,,,
,28905201.95,145.0127869,99.5330276489258,0.000255637942680591,3.56138892140641E-7,1,0.999253354069792,40.0298881530762,1.97726552001615,29.0699992328882,0.00287564655360202,0.000511658286128837,0.25,9.09852054039041E-7,0.000256921930310743,1.33391609814039E-6,145.0127869,145.0127869,99.5330276489258,99.5330276489258,56.8947399148137,20.4575465969242,25.566563,0,0,0,40,4374,147.7329,99.5330276489258,,,,,,,,,,,,,0,,,,-0.0049,,,,,,145.0127869,,,,
,28905341.225,148.5092468,99.5330276489258,0.000249533637840023,3.43914433987893E-7,1,0.999253354069792,40.0298881530762,1.98912435580949,29.1600003838539,0.00282389868908271,0.000496083093859779,0.25,3.56231064530417E-7,0.000250766726846567,7.53619259409529E-7,148.5092468,148.5092468,99.5330276489258,99.5330276489258,57.2230238928907,20.4506007546474,26.325863,0,0,0,40,4374,151.2286,99.5330276489258,,,,,,,,,,,,,0,,,,0,,,,,,148.5092468,,,,
,28905480.225,152.010788,99.5330276489258,0.000243919944520535,3.96883592834777E-7,1,0.999253354069792,40.0298881530762,1.98897997015576,29.1600003838539,0.0027596653503287,0.000486413503344845,0.25,4.99113040992627E-7,0.000245103707064102,8.75687721786183E-7,152.010788,152.010788,99.5330276489258,99.5330276489258,57.0799858738714,20.4541400603469,25.946213,0,0,0,40,4374,154.7132,99.5330276489258,,,,,,,,,,,,,0,,,,-0.0049,,,,,,152.010788,,,,
,28905620.945,155.5180206,99.5330276489258,0.000237920053159434,3.6798835115564E-7,1,0.999253354069792,40.0298881530762,1.98896965629089,29.1600003838539,0.00269117707210665,0.000476423617228148,0.25,6.76807206173856E-7,0.000239052970512315,1.03339431066759E-6,155.5180206,155.5180206,99.5330276489258,99.5330276489258,57.1894138665637,20.4511813718757,25.566563,0,0,0,40,4374,158.23795,99.5330276489258,,,,,,,,,,,,,0,,,,0,,,,,,155.5180206,,,,
,28905762.965,159.0538483,99.5330276489258,0.000232143136269853,4.06763775594734E-7,1,0.999253354069792,40.0298881530762,1.98900342955397,29.1399993002415,0.00262578515611493,0.00046393701381008,0.25,5.9293311825006E-7,0.000233226990163604,9.29817722495718E-7,159.0538483,159.0538483,99.5330276489258,99.5330276489258,57.0369963053137,20.4494167267061,25.946213,0,0,0,40,4374,161.7952,99.5330276489258,,,,,,,,,,,,,0,,,,0,,,,,,159.0538483,,,,
,28905903.115,162.5812225,99.5330276489258,0.000226812728843156,3.50670108132686E-7,1,0.999253354069792,40.0298881530762,1.98891749132826,29.1399993002415,0.00256579112824433,0.00044949695999925,0.25,2.59605020837895E-7,0.000227850492872804,5.77613104474035E-7,162.5812225,162.5812225,99.5330276489258,99.5330276489258,57.1683098965445,20.4521247752715,26.325863,0,0,0,40,4374,165.3001,99.5330276489258,,,,,,,,,,,,,0,,,,0,,,,,,162.5812225,,,,
,28906040.91,166.0134583,99.5330276489258,0.000221286775484057,3.25155307396409E-7,1,0.999253354069792,40.0298881530762,1.98930148560103,29.1399993002415,0.00250285361662073,0.000442325474853892,0.25,5.92443719281816E-7,0.000222277797104526,8.95521264551476E-7,166.0134583,166.0134583,99.5330276489258,99.5330276489258,57.2566339192176,20.4471043437585,26.325863,0,0,0,40,4374,168.7485,99.5330276489258,,,,,,,,,,,,,0,,,,0.00245,,,,,,166.0134583,,,,
,28906181.61,169.5252228,99.5330276489258,0.000216569231491157,3.75731288258158E-7,1,0.999253354069792,40.0298881530762,1.98948210296479,29.1300006210804,0.0024493086874661,0.000433799534924331,0.25,6.6822983534179E-7,0.000217517562273541,9.57029459288135E-7,169.5252228,169.5252228,99.5330276489258,99.5330276489258,57.0901470446214,20.4452730926696,25.946213,0,0,0,40,4374,172.2623,99.5330276489258,,,,,,,,,,,,,0,,,,0.00245,,,,,,169.5252228,,,,
,28906321.025,173.0171356,99.5330276489258,0.000211579040564184,3.72049336969867E-7,1,0.999253354069792,40.0298881530762,1.98988564269764,29.1300006210804,0.00239378094906174,0.000419904833375914,0.25,3.12186903958989E-7,0.000212484733866989,5.853427925503E-7,173.0171356,173.0171356,99.5330276489258,99.5330276489258,57.0643533034868,20.4434049729821,26.325863,0,0,0,40,4374,175.7589,99.5330276489258,,,,,,,,,,,,,0,,,,-0.0049,,,,,,173.0171356,,,,
,28906461.26,176.5015259,99.5330276489258,0.000207490091126766,3.68090791633299E-7,1,0.999253354069792,40.0298881530762,1.98990744284368,29.1300006210804,0.00234723943708694,0.000412131594814937,0.25,3.46539968841222E-7,0.000208357093217418,6.07629099863835E-7,176.5015259,176.5015259,99.5330276489258,99.5330276489258,57.098744958333,20.445059344934,26.325863,0,0,0,40,4374,179.2622,99.5330276489258,,,,,,,,,,,,,0,,,,0,,,,,,176.5015259,,,,
,28906600.75,180.004364,99.5330276489258,0.000203016078361146,3.4758276849847E-7,1,0.999253354069792,40.0298881530762,1.98958873467813,29.1000008583069,0.0022959334279029,0.000403740764050318,0.25,3.98372135899712E-7,0.000203843176599235,6.47652385739943E-7,180.004364,180.004364,99.5330276489258,99.5330276489258,57.3660619119099,20.4477902728414,26.705515,0,0,0,40,4374,182.75245,99.5330276489258,,,,,,,,,,,,,0,,,,-0.00245,,,,,,180.004364,,,,
,28906746.57,183.5505371,99.5330276489258,0.000158410468016924,7.41655410874145E-7,1,0.999253354069792,40.0298881530762,1.98924303333083,29.1000008583069,0.00169389287927512,0.000873664113386824,0.25,4.97162553888129E-5,0.000158980232423205,5.01018259948398E-5,183.5505371,183.5505371,99.5330276489258,99.5330276489258,57.2730481181214,20.4477192167554,26.705515,0,0,0,40,4374,186.47725,99.5330276489258,,,,,,,,,,,,,0,,,,-0.00245,,,,,,183.5505371,,,,
,28906881.055,187.004776,99.5330276489258,0.000135399847780345,4.00020671756396E-6,1,0.999253354069792,40.0298881530762,1.98955433304094,29.1000008583069,0.00146135237543011,0.000669462714154143,0.25,3.56612205056369E-5,0.000135881576033212,3.59562655940168E-5,187.004776,187.004776,99.5330276489258,99.5330276489258,57.2449094914291,20.4496435386189,26.325863,0,0,0,40,4374,189.77765,99.5330276489258,,,,,,,,,,,,,0,,,,0,,,,,,187.004776,,,,
,28907023.915,190.5284119,99.5330276489258,0.000120469037639253,3.61839591799822E-6,1,0.999253354069792,40.0298881530762,1.98941143215283,29.0699992328882,0.00128656320669334,0.000672789638626261,0.25,3.85635301528917E-5,0.000120877614429376,3.88449175505464E-5,190.5284119,190.5284119,99.5330276489258,99.5330276489258,57.3168193151984,20.4478236211288,27.085165,0,0,0,40,4374,193.35985,99.5330276489258,,,,,,,,,,,,,0,,,,0,,,,,,190.5284119,,,,
,28907164,194.0135193,99.5330276489258,0.000111274214174385,2.45214334311953E-6,1,0.999253354069792,40.0298881530762,1.98910257574353,29.0699992328882,0.00117923722547018,0.000672130902193652,0.25,4.01207421482823E-5,0.000111635364821707,4.03903005313208E-5,194.0135193,194.0135193,99.5330276489258,99.5330276489258,57.0713879601599,20.451483371742,26.325863,0,0,0,40,4374,196.8751,99.5330276489258,,,,,,,,,,,,,0,,,,-0.00245,,,,,,194.0135193,,,,
,28907304.145,197.5390015,99.5330276489258,0.000103598518358221,2.33959115245143E-6,1,0.999253354069792,40.0298881530762,1.98919192291993,29.0699992328882,0.00109229102217784,0.000657606452122303,0.25,4.01757598049049E-5,0.000103921015134173,4.04299755082563E-5,197.5390015,197.5390015,99.5330276489258,99.5330276489258,57.2253687784484,20.4506702444573,27.464817,0,0,0,40,4374,200.3903,99.5330276489258,,,,,,,,,,,,,0,,,,0,,,,,,197.5390015,,,,
,28907424.04,200.5146942,99.5330276489258,0.000100628003361206,2.51502503741371E-6,1,0.999253354069792,40.0298881530762,1.98908268320225,29.0399994701147,0.00104785875573818,0.000713310899004755,0.25,4.56302861845392E-5,0.00010092540601531,4.58941863428067E-5,200.5146942,200.5146942,99.5330276489258,99.5330276489258,57.1073428720445,20.4490327387655,27.085165,0,0,0,40,4374,203.38885,99.5330276489258,,,,,,,,,,,,,0,,,,-0.0049,,,,,,200.5146942,,,,
,28907566.275,204.0577087,99.5330276489258,9.63280808180614E-5,2.23148477106103E-6,1,0.999253354069792,40.0298881530762,1.98928474875222,29.0399994701147,0.000997909484447047,0.000712577393800234,0.25,4.63152412641171E-5,9.65999800791701E-5,4.65694155652773E-5,204.0577087,204.0577087,99.5330276489258,99.5330276489258,57.0127658212176,20.450882521471,27.085165,0,0,0,40,4374,206.9491,99.5330276489258,,,,,,,,,,,,,0,,,,0,,,,,,204.0577087,,,,
,28907703.49,207.5024719,99.5330276489258,9.47560727386841E-5,2.29307229162134E-6,1,0.999253354069792,40.0298881530762,1.98915971320511,29.0399994701147,0.000967206705542328,0.000782957106860667,0.25,5.28284720559138E-5,9.50064141006558E-5,5.30947077868929E-5,207.5024719,207.5024719,99.5330276489258,99.5330276489258,57.1206305568714,20.4542356740207,27.085165,0,0,0,40,4374,210.39195,99.5330276489258,,,,,,,,,,,,,0,,,,0,,,,,,207.5024719,,,,
,28907824.32,210.5457001,99.5330276489258,9.23029380215318E-5,2.46858206208564E-6,1,0.999253354069792,40.0298881530762,2.00206956991063,29.0399994701147,0.000940308395833096,0.000811168555193055,0.25,5.53174516619234E-5,9.25345903118836E-5,5.5581985982534E-5,210.5457001,210.5457001,99.5330276489258,99.5330276489258,57.3652802833907,20.4559035804529,27.085165,0,0,0,40,4374,213.41195,99.5330276489258,,,,,,,,,,,,,0,,,,0,,,,,,210.5457001,,,,
,28907964.185,214.0200958,99.5330276489258,0.000100690308611299,1.36610692713247E-6,1,0.999253354069792,40.0298881530762,2.00204610799872,29.0399994701147,0.00100651078906312,0.000994947409113398,0.25,7.00373790727596E-5,0.000100923071927019,7.03460185931828E-5,214.0200958,214.0200958,99.5330276489258,99.5330276489258,57.1487691835637,20.4590524741457,27.085165,0,0,0,40,4374,216.91755,99.5330276489258,,,,,,,,,,,,,0,,,,0.0049,,,,,,214.0200958,,,,
,28908105.105,217.5197449,99.5330276489258,0.000102006601358772,1.30432061132373E-6,1,0.999253354069792,40.0298881530762,2.00190846603895,29.0399994701147,0.00102059989414459,0.00100142416010728,0.25,7.03963650038435E-5,0.000102232358722542,7.06971663532506E-5,217.5197449,217.5197449,99.5330276489258,99.5330276489258,57.0807675023906,20.4614653221858,27.085165,0,0,0,40,4374,220.4492,99.5330276489258,,,,,,,,,,,,,0,,,,0.0049,,,,,,217.5197449,,,,
,28908245.185,221.0436096,99.5330276489258,0.000100927468709494,1.05682060645148E-6,1,0.999253354069792,40.0298881530762,1.98906523263755,29.0300007909536,0.00100471372114022,0.000977732787112207,0.25,6.90413335039577E-5,0.000101140697944403,6.93271375422061E-5,221.0436096,221.0436096,99.5330276489258,99.5330276489258,57.1042163579676,20.4576000040313,27.464817,0,0,0,40,4374,223.95845,99.5330276489258,,,,,,,,,,,,,0,,,,-0.0049,,,,,,221.0436096,,,,
,28908385.83,224.5069885,99.5330276489258,9.85142478970216E-5,1.36721079829799E-6,1,0.999253354069792,40.0298881530762,1.98911847262983,29.0300007909536,0.000982228125477949,0.000944968144396777,0.25,6.65687484468019E-5,9.87127574840983E-5,6.68358735879348E-5,224.5069885,224.5069885,99.5330276489258,99.5330276489258,57.1425161554099,20.4624374208954,27.464817,0,0,0,40,4374,227.49,99.5330276489258,,,,,,,,,,,,,0,,,,0,,,,,,224.5069885,,,,
,28908525.315,228.0123444,99.5330276489258,9.7625098970203E-5,9.87879509918152E-7,1,0.999253354069792,40.0298881530762,1.98948710413287,29.0300007909536,0.000975799033187609,0.000922849527372439,0.25,6.47615005320719E-5,9.78123352518236E-5,6.50136175734321E-5,228.0123444,228.0123444,99.5330276489258,99.5330276489258,57.1526773261599,20.4564479687811,27.464817,0,0,0,40,4374,230.9758,99.5330276489258,,,,,,,,,,,,,0,,,,0,,,,,,228.0123444,,,,
,28908666.285,231.5310974,99.5330276489258,9.53908263008837E-5,1.2735888411372E-6,1,0.999253354069792,40.0298881530762,1.98932751295352,29.0300007909536,0.000952524317740021,0.00090596828654228,0.25,6.36718738635182E-5,9.55629387713243E-5,6.39099269984155E-5,231.5310974,231.5310974,99.5330276489258,99.5330276489258,57.2238055214099,20.4601579092318,27.844467,0,0,0,40,4374,234.5177,99.5330276489258,,,,,,,,,,,,,0,,,,0,,,,,,231.5310974,,,,
,28908805.915,235.0172119,99.5330276489258,9.44896936212123E-5,1.01054356420859E-6,1,0.999253354069792,40.0298881530762,1.98925801370852,29.0300007909536,0.000949392201209796,0.000862688280237725,0.25,6.0008911188092E-5,9.46524794411938E-5,6.02286393480002E-5,235.0172119,235.0172119,99.5330276489258,99.5330276489258,57.0862389020253,20.4639959919109,27.844467,0,0,0,40,4374,238.0189,99.5330276489258,,,,,,,,,,,,,0,,,,0.0049,,,,,,235.0172119,,,,
,28908946.025,238.5157928,99.5330276489258,9.30401559242076E-5,7.98687825014396E-7,1,0.999253354069792,40.0298881530762,1.98894311514981,29.0300007909536,0.000939400589753902,0.000821453394749101,0.25,5.66296493381391E-5,9.31921643328337E-5,5.68320879531E-5,238.5157928,238.5157928,99.5330276489258,99.5330276489258,57.166746639506,20.4670421085622,27.464817,0,0,0,40,4374,241.535,99.5330276489258,,,,,,,,,,,,,0,,,,0,,,,,,238.5157928,,,,
,28909087.11,242.0255585,99.5330276489258,9.04772341563634E-5,1.49127029612426E-6,1,0.999253354069792,40.0298881530762,1.98924419924753,29.0699992328882,0.00090985481115329,0.000820166783772007,0.25,5.6959821042202E-5,9.06131955842584E-5,5.71524320405324E-5,242.0255585,242.0255585,99.5330276489258,99.5330276489258,57.129228470583,20.4590302693258,28.224119,0,0,0,40,4374,245.0732,99.5330276489258,,,,,,,,,,,,,0,,,,0,,,,,,242.0255585,,,,
,28909227.455,245.526474,99.5330276489258,8.93995408463948E-5,8.39437619564466E-7,1,0.999253354069792,40.0298881530762,1.98910640471591,29.0699992328882,0.000907317590887549,0.000761462213360708,0.25,5.1960385874153E-5,8.95273202412872E-5,5.21342429538642E-5,245.526474,245.526474,99.5330276489258,99.5330276489258,57.1909771236022,20.4630380896392,27.844467,0,0,0,40,4374,248.5866,99.5330276489258,,,,,,,,,,,,,0,,,,0.0049,,,,,,245.526474,,,,
,28909368.82,249.0386505,99.5330276489258,8.79679677465911E-5,1.0071634402968E-6,1,0.999253354069792,40.0298881530762,1.98877584213645,29.0699992328882,0.000889903681309615,0.000764288359771268,0.25,5.2479262702576E-5,8.80824419381614E-5,5.26452007007211E-5,249.0386505,249.0386505,99.5330276489258,99.5330276489258,57.1253203279868,20.468037922065,27.844467,0,0,0,40,4374,252.1243,99.5330276489258,,,,,,,,,,,,,0,,,,0.00245,,,,,,249.0386505,,,,
,28909508.205,252.5020752,99.5330276489258,8.80715534101498E-5,9.4056813078665E-7,1,0.999253354069792,40.0298881530762,1.98923297647586,28.999999165535,0.000893563051704855,0.000750750267628226,0.25,5.12560711493843E-5,8.81771349294854E-5,5.14124520903293E-5,252.5020752,252.5020752,99.5330276489258,99.5330276489258,57.0964000727753,20.4623777060976,28.224119,0,0,0,40,4374,255.6227,99.5330276489258,,,,,,,,,,,,,0,,,,-0.0049,,,,,,252.5020752,,,,
,28909649.985,256.0260925,99.5330276489258,8.67742322748378E-5,8.3179714328945E-7,1,0.999253354069792,40.0298881530762,1.98892925622293,28.999999165535,0.000879472336062292,0.000743516513734828,0.25,5.08588532565811E-5,8.68678140237252E-5,5.10060305724248E-5,256.0260925,256.0260925,99.5330276489258,99.5330276489258,57.1620568683907,20.4662179298863,27.464817,0,0,0,40,4374,259.1711,99.5330276489258,,,,,,,,,,,,,0,,,,0,,,,,,256.0260925,,,,
,28909788.28,259.5043945,99.5330276489258,8.48217195632936E-5,1.35905294867847E-6,1,0.999253354069792,40.0298881530762,1.98881686705142,28.999999165535,0.000855970452965475,0.00074723445298674,0.25,5.15396456096348E-5,8.49019173347881E-5,5.16788965605602E-5,259.5043945,259.5043945,99.5330276489258,99.5330276489258,56.9627415959868,20.4736196710267,28.224119,0,0,0,40,4374,262.62955,99.5330276489258,,,,,,,,,,,,,0,,,,-0.0049,,,,,,259.5043945,,,,
,28909909.55,262.5152893,99.5330276489258,8.56364930079792E-5,1.21318674686814E-6,1,0.999253354069792,40.0298881530762,1.98884142390189,28.9900004863739,0.000865251995575687,0.000747792451423774,0.25,5.14549801529619E-5,8.57092891013332E-5,5.158831304435E-5,262.5152893,262.5152893,99.5330276489258,99.5330276489258,57.1096877576022,20.4665097978379,27.844467,0,0,0,40,4374,265.6733,99.5330276489258,,,,,,,,,,,,,0,,,,-0.00245,,,,,,262.5152893,,,,
,28910052.53,266.08332825,99.5330276489258,8.41165958877649E-5,1.1589807517013E-6,1,0.999253354069792,40.0298881530762,1.9888189923539,28.9900004863739,0.00085130534406209,0.000725650647158147,0.25,4.97651084836E-5,8.4178604622935E-5,4.9887692482724E-5,266.0520935,266.114563,99.5330276489258,99.5330276489258,56.9658681100637,20.4705138594414,27.844467,0,0,0,40,4374,269.2456,99.5330276489258,,,,,,,,,,,,,0,,,,0,,,,,,266.08332825,,,,
,28910189.52,269.5164795,99.5330276489258,8.24768290967327E-5,1.18114840515203E-6,1,0.999253354069792,40.0298881530762,1.98882513877553,28.9900004863739,0.000834205075916159,0.000713793896793741,0.25,4.90063739030065E-5,8.25279116205919E-5,4.91198700718231E-5,269.5164795,269.5164795,99.5330276489258,99.5330276489258,56.9830639374868,20.4651544831916,28.603769,0,0,0,40,4374,272.6542,99.5330276489258,,,,,,,,,,,,,0,,,,0.00245,,,,,,269.5164795,,,,
,28910312.925,272.5559387,99.5330276489258,8.09838504422297E-5,1.12231248523226E-6,1,0.999253354069792,40.0298881530762,1.98883254378122,28.999999165535,0.000818357123665376,0.000704646890684531,0.25,4.84612543384963E-5,8.1025440771675E-5,4.85669750509376E-5,272.5559387,272.5559387,99.5330276489258,99.5330276489258,56.9088092281599,20.4642134512293,28.603769,0,0,0,40,4374,275.7578,99.5330276489258,,,,,,,,,,,,,0,,,,0,,,,,,272.5559387,,,,
,28910450.33,276.0016327,99.5330276489258,7.99451427713687E-5,1.18392367348751E-6,1,0.999253354069792,40.0298881530762,1.98874891698443,28.999999165535,0.000808842008651445,0.000689106920494598,0.25,4.72737435247276E-5,7.99772664306737E-5,4.73708701047044E-5,275.9690857,276.0341797,99.5330276489258,99.5330276489258,57.0299616486406,20.4669417687569,28.603769,0,0,0,40,4374,279.18035,99.5330276489258,,,,,,,,,,,,,0,,,,0,,,,,,276.0016327,,,,
,28910593.51,279.5603333,99.5330276489258,7.84677598630898E-5,1.43716317121569E-6,1,0.999253354069792,40.0298881530762,1.98864512765823,28.999999165535,0.000790038400801346,0.000697725149900154,0.25,4.83060586949241E-5,7.84884409758597E-5,4.83959472844948E-5,279.5603333,279.5603333,99.5330276489258,99.5330276489258,56.9947883652753,20.4723563362624,28.224119,0,0,0,40,4374,282.76665,99.5330276489258,,,,,,,,,,,,,0,,,,0.00245,,,,,,279.5603333,,,,
,28910733.22,283.0283203,99.5330276489258,7.85004466327378E-5,1.15241061003231E-6,1,0.999253354069792,40.0298881530762,1.98912857258967,29.0099997073412,0.000795357185084245,0.000669824821415222,0.25,4.5819269018715E-5,7.85136492726689E-5,4.59009169615583E-5,283.0283203,283.0283203,99.5330276489258,99.5330276489258,56.9627415959868,20.4662321554362,28.224119,0,0,0,40,4374,286.2654,99.5330276489258,,,,,,,,,,,,,0,,,,-0.0049,,,,,,283.0283203,,,,
,28910872.465,286.5274048,99.5330276489258,7.76455212615911E-5,1.04184288413565E-6,1,0.999253354069792,40.0298881530762,1.98878229236874,29.0099997073412,0.000786177186072768,0.000664033010378682,0.25,4.54714908939953E-5,7.76491998937853E-5,4.55458458211453E-5,286.5274048,286.5274048,99.5330276489258,99.5330276489258,57.1128142716791,20.4696749951133,28.603769,0,0,0,40,4374,289.7526,99.5330276489258,,,,,,,,,,,,,0,,,,-0.00245,,,,,,286.5274048,,,,
,28911014.485,290.0430603,99.5330276489258,7.52063733070733E-5,1.28388763412891E-6,1,0.999253354069792,40.0298881530762,1.98893069930771,29.0099997073412,0.00075643120676173,0.000672065810191662,0.25,4.66109322195173E-5,7.51991561634974E-5,4.66774880546309E-5,290.0430603,290.0430603,99.5330276489258,99.5330276489258,57.1628384969099,20.4705717182253,28.224119,0,0,0,40,4374,293.30005,99.5330276489258,,,,,,,,,,,,,0,,,,0,,,,,,290.0430603,,,,
,28911154.345,293.508667,99.5330276489258,7.54763706761805E-5,1.36438296135484E-6,1,0.999253354069792,40.0298881530762,2.00157881599731,29.0399994701147,0.000764232277307347,0.00067521276526411,0.25,4.64899765179428E-5,7.54604118599311E-5,4.65501784151066E-5,293.508667,293.508667,99.5330276489258,99.5330276489258,57.1346998702176,20.4717628401996,28.983419,0,0,0,40,4374,296.8161,99.5330276489258,,,,,,,,,,,,,0,,,,0,,,,,,293.508667,,,,
,28911293.5,297.0092163,99.5330276489258,7.43963502575838E-5,1.13989613372775E-6,1,0.999253354069792,40.0298881530762,2.00133129235001,29.0399994701147,0.000757827714149107,0.000638208203810676,0.25,4.34268554842274E-5,7.43733238723732E-5,4.34795786780873E-5,297.0092163,297.0092163,99.5330276489258,99.5330276489258,56.8705094307176,20.4761023299015,28.983419,0,0,0,40,4374,300.2965,99.5330276489258,,,,,,,,,,,,,0,,,,-0.00245,,,,,,297.0092163,,,,
,28911437.085,300.5479126,99.5330276489258,7.39858923861702E-5,1.27086882211689E-6,1,0.999253354069792,40.0298881530762,2.00158312412866,29.0399994701147,0.00075047163585438,0.000653008825267053,0.25,4.48049880510487E-5,7.39529915399197E-5,4.48511893740385E-5,300.5479126,300.5479126,99.5330276489258,99.5330276489258,57.068261446083,20.4755760061324,28.603769,0,0,0,40,4374,303.90425,99.5330276489258,,,,,,,,,,,,,0,,,,-0.00245,,,,,,300.5479126,,,,
,28911577.695,304.0403137,99.5330276489258,7.16651364678269E-5,1.54219591168266E-6,1,0.999253354069792,40.0298881530762,1.98899842240534,29.0900003165007,0.000723107649461505,0.000625041584543336,0.25,4.30796978917227E-5,7.16249385605649E-5,4.31184621031222E-5,304.0403137,304.0403137,99.5330276489258,99.5330276489258,56.9494539111599,20.4686100537642,28.603769,0,0,0,40,4374,307.43575,99.5330276489258,,,,,,,,,,,,,0,,,,0,,,,,,304.0403137,,,,
,28911716.975,307.5260925,99.5330276489258,7.19950411355524E-5,1.21380002033236E-6,1,0.999253354069792,40.0298881530762,1.98900650184925,29.0900003165007,0.000726669097263469,0.00062602100929865,0.25,4.31167335505357E-5,7.19462032809864E-5,4.31497383771737E-5,307.5260925,307.5260925,99.5330276489258,99.5330276489258,57.0510656186599,20.4687229454906,28.224119,0,0,0,40,4374,310.9348,99.5330276489258,,,,,,,,,,,,,0,,,,0,,,,,,307.5260925,,,,
,28911857.6,311.0280762,99.5330276489258,7.22581410760488E-5,1.19195577228111E-6,1,0.999253354069792,40.0298881530762,1.98903555519541,29.0900003165007,0.000732766846053647,0.000607927104139451,0.25,4.14709747802393E-5,7.22016357196114E-5,4.14988787264786E-5,311.0280762,311.0280762,99.5330276489258,99.5330276489258,57.169873153583,20.4694331909507,28.983419,0,0,0,40,4374,314.43475,99.5330276489258,,,,,,,,,,,,,0,,,,-0.00245,,,,,,311.0280762,,,,
,28911998.92,314.503418,99.5330276489258,6.85609939377767E-5,1.48004077574044E-6,1,0.999253354069792,40.0298881530762,1.98957746032099,29.1300006210804,0.000691175916183982,0.000601132804219393,0.25,4.15012146536658E-5,6.84979341741294E-5,4.15211164849889E-5,314.503418,314.503418,99.5330276489258,99.5330276489258,57.0088576786214,20.4610559266938,28.603769,0,0,0,40,4374,317.9865,99.5330276489258,,,,,,,,,,,,,0,,,,-0.0049,,,,,,314.503418,,,,
,28912140.88,318.050415,99.5330276489258,6.9858402100958E-5,1.1027584261598E-6,1,0.999253354069792,40.0298881530762,1.98989693366822,29.1399993002415,0.000706285664184818,0.000600939908881583,0.25,4.12583534283221E-5,6.9786370457069E-5,4.12734705462847E-5,318.050415,318.050415,99.5330276489258,99.5330276489258,57.0792042453522,20.4598860542571,28.983419,0,0,0,40,4374,321.5518,99.5330276489258,,,,,,,,,,,,,0,,,,-0.0049,,,,,,318.050415,,,,
,28912279.94,321.5204468,99.5330276489258,6.86258119865449E-5,1.54924389245313E-6,1,0.999253354069792,40.0298881530762,1.99029269114894,29.1300006210804,0.000693147319467014,0.000594574759988136,0.25,4.09035594645464E-5,6.85467561393688E-5,4.09126503498839E-5,321.5204468,321.5204468,99.5330276489258,99.5330276489258,57.0971817012945,20.4542345858232,28.983419,0,0,0,40,4374,325.04025,99.5330276489258,,,,,,,,,,,,,0,,,,-0.00245,,,,,,321.5204468,,,,
,28912401.83,324.5021057,99.5330276489258,6.71598605468499E-5,1.213557354923E-6,1,0.999253354069792,40.0298881530762,1.99024093157276,29.2000006884336,0.000679027474302555,0.00057734264863547,0.25,3.96345153196955E-5,6.70759646919457E-5,3.96391583788181E-5,324.5021057,324.5021057,99.5330276489258,99.5330276489258,57.0878021590637,20.4523802523661,29.363071,0,0,0,40,4374,328.05915,99.5330276489258,,,,,,,,,,,,,0,,,,0,,,,,,324.5021057,,,,
,28912544.3,328.0481873,99.5330276489258,6.70652274743212E-5,1.48334710758622E-6,1,0.999253354069792,40.0298881530762,1.99054067546571,29.2000006884336,0.00067716032024564,0.000581894050493529,0.25,4.00544635501705E-5,6.69731543965412E-5,4.00532248495574E-5,328.0481873,328.0481873,99.5330276489258,99.5330276489258,57.2214606358522,20.4517609224762,29.363071,0,0,0,40,4374,331.6624,99.5330276489258,,,,,,,,,,,,,0,,,,0.0049,,,,,,328.0481873,,,,
,28912683.125,331.5183411,99.5330276489258,6.56532082398477E-5,1.16130029752377E-6,1,0.999253354069792,40.0298881530762,1.99073752106128,29.2000006884336,0.000663184737701654,0.000567918175309197,0.25,3.90597441590707E-5,6.55555087499784E-5,3.90535281060283E-5,331.5183411,331.5183411,99.5330276489258,99.5330276489258,57.2011382943522,20.447363232892,29.363071,0,0,0,40,4374,335.14145,99.5330276489258,,,,,,,,,,,,,0,,,,-0.0049,,,,,,331.5183411,,,,
,28912804.86,334.5385742,99.5330276489258,6.28607504296966E-5,1.28957750665464E-6,1,0.999253354069792,40.0298881530762,1.99105414820584,29.3000005185604,0.000633276475614252,0.000553796492201046,0.25,3.82873714653204E-5,6.2760335329007E-5,3.82760447246448E-5,334.5385742,334.5385742,99.5330276489258,99.5330276489258,57.0698247031214,20.4369884068583,29.363071,0,0,0,40,4374,338.17135,99.5330276489258,,,,,,,,,,,,,0,,,,0,,,,,,334.5385742,,,,
,28912947.455,338.0635376,99.5330276489258,6.36625393653157E-5,1.00098877475154E-6,1,0.999253354069792,40.0298881530762,1.99069601461638,29.3000005185604,0.000645169358092483,0.000537592931391382,0.25,3.67241387739055E-5,6.35545416259357E-5,3.67103467483948E-5,338.0635376,338.0635376,99.5330276489258,99.5330276489258,57.0792042453522,20.4479697551967,29.742722,0,0,0,40,4374,341.7825,99.5330276489258,,,,,,,,,,,,,0,,,,-0.00245,,,,,,338.0635376,,,,
,28913085.93,341.5384216,99.5330276489258,6.29926387910121E-5,1.19434678701295E-6,1,0.999253354069792,40.0298881530762,1.99049362881601,29.3000005185604,0.000633414287999989,0.000559717761683927,0.25,3.88163329024625E-5,6.28770958940575E-5,3.87942983642029E-5,341.5384216,341.5384216,99.5330276489258,99.5330276489258,56.9932251082368,20.4545420594494,29.742722,0,0,0,40,4374,345.24795,99.5330276489258,,,,,,,,,,,,,0,,,,-0.0049,,,,,,341.5384216,,,,
,28913226.155,345.016571,99.5330276489258,6.0704714490122E-5,1.16968731674982E-6,1,0.999253354069792,40.0298881530762,1.99076466953117,29.3799992650747,0.00061187598216611,0.000530973204079213,0.25,3.66586783805832E-5,6.05868113123841E-5,3.66338627772051E-5,344.9848022,345.0483398,99.5330276489258,99.5330276489258,57.0018230219483,20.4452063214207,28.983419,0,0,0,40,4374,348.7098,99.5330276489258,,,,,,,,,,,,,0,,,,0,,,,,,345.016571,,,,
,28913368.315,348.5328674,99.5330276489258,5.86768356800709E-5,1.55679999897728E-6,1,0.999253354069792,40.0298881530762,1.99109819172413,29.3799992650747,0.000588979670552129,0.00052759272630944,0.25,3.6707853007154E-5,5.85553537983182E-5,3.66771616033956E-5,348.5328674,348.5328674,99.5330276489258,99.5330276489258,56.8775440873906,20.4402812873645,29.742722,0,0,0,40,4374,351.8195,99.5330276489258,,,,,,,,,,,,,0,,,,-0.00245,,,,,,348.5328674,,,,
,28913685.275,349.78196715,99.5330276489258,5.96123427420944E-5,1.1732608879003E-6,1,0.999253354069792,40.0298881530762,1.99113402961541,29.3799992650747,0.000601386872034564,0.000518475959568592,0.25,3.57370724740209E-5,5.94872029259824E-5,3.57071583888483E-5,349.7805786,349.7833557,99.5330276489258,99.5330276489258,57.2636685758907,20.4392764410796,29.363071,0,0,0,40,4369,350.7319,99.5330276489258,,,,,,,,,,,,,0,,,,0.0049,,,,,,349.78196715,,,,