File: data/looselyPackedNP/nanoparticles/vsm/ios-7/rawdata/KWI338_HYST_300K.DAT
[Header]
; VSM Data File (default extension .dat)
; Copyright (c) 2003-2013, Quantum Design, Inc. All rights reserved.
TITLE,
FILEOPENTIME,28865346.83,12/01/2018,10:10 am
BYAPP,VSM,2.0,2.0
INFO,PPMS VSM Option Release 1.4.10 Build 1,APPNAME
INFO,Quantum Design Linear Motor Servo Controller,MOTOR_MODULE_NAME
INFO,3101-100 M1,MOTOR_HW_VERSION
INFO,MMC1014,MOTOR_SERIAL_NUMBER
INFO,SRV No X-over 01.03.11,MOTOR_SOFTWARE_VERSION
INFO,Quantum Design VSM Detection Module,VSM_MODULE_NAME
INFO,3101-150 F0,VSM_HW_VERSION
INFO,VSM707,VSM_SERIAL_NUMBER
INFO,VSM No X-over 01.02.05 May 20 2008 13:51:47,VSM_SOFTWARE_VERSION
INFO,704,PREAMP_SERIAL_NUMBER
INFO,822,COIL_SERIAL_NUMBER
INFO,0,MOMENT_UNITS
INFO,Maghemite,SAMPLE_MATERIAL
INFO,Oleate Iron Spheres,SAMPLE_COMMENT
INFO,,SAMPLE_MASS
INFO,,SAMPLE_VOLUME
INFO,,SAMPLE_MOLECULAR_WEIGHT
INFO,,SAMPLE_SIZE
INFO,,SAMPLE_SHAPE
DATATYPE,COMMENT,1
DATATYPE,TIME,2
STARTUPAXIS,X,2
STARTUPAXIS,Y1,5
[Data]
Comment,Time Stamp (sec),Temperature (K),Magnetic Field (Oe),Moment (emu),M. Std. Err. (emu),Transport Action,Averaging Time (sec),Frequency (Hz),Peak Amplitude (mm),Center Position (mm),Coil Signal' (mV),Coil Signal" (mV),Range (mV),M. Quad. Signal (emu),M. Raw' (emu),M. Raw" (emu),Min. Temperature (K),Max. Temperature (K),Min. Field (Oe),Max. Field (Oe),Mass (grams),Motor Lag (deg),Pressure (Torr),VSM Status (code),Motor Status (code),Measure Status (code),Measure Count,PPMS Status (code),System Temp. (K),System Field (Oe),Sample Position (deg),Bridge 1 Resistance (ohms),Bridge 1 Excitation (에),Bridge 2 Resistance (ohms),Bridge 2 Excitation (에),Bridge 3 Resistance (ohms),Bridge 3 Excitation (에),Bridge 4 Resistance (ohms),Bridge 4 Excitation (에),Signal 1 Vin (V),Signal 2 Vin (V),Digital Inputs (code),Drive 1 Iout (mA),Drive 1 Ipower (W),Drive 2 Iout (mA),Drive 2 Ipower (W),Pressure (),Map 20 (),Map 21 (),Map 22 (),Map 23 (),Map 24 (),Map 25 (),Map 26 (),Map 27 (),Map 28 (),Map 29 ()
,28865363.84,300.2122192,-0.152237743139267,,,2,,,,29.6600002002716,,,,,,,300.2122192,300.2122192,-0.152237743139267,-0.152237743139267,,,27.844467,,,,-99999999,4369,300.6052,-0.152237743139267,,,,,,,,,,,,,,,,,,,,,,,300.2122192,,,,
,28865513.775,300.1948547,4491.26245117188,0.00229113445453331,2.56803916159958E-5,1,0.999253354069792,40.0298881530762,1.99660994406695,29.6500008553266,0.0235804682577991,0.0178917132427845,0.25,0.00118558317744045,0.00229026436524289,0.00118705813376268,300.1948547,300.1948547,4486.36181640625,4496.1630859375,56.3358755235637,20.509489618489,27.464817,0,0,0,40,4449,300.3305,4491.26245117188,,,,,,,,,,,,,0,,,,0.00245,,,,,,300.1948547,,,,
,28865608.11,300.145813,9202.42529296875,0.00271217018766683,2.53739616587515E-5,1,0.999253354069792,40.0298881530762,1.99435700250322,29.6500008553266,0.0279456774657909,0.0207995797639592,0.25,0.00137182008697818,0.00271116632349556,0.00137356907366671,300.145813,300.145813,9197.6142578125,9207.236328125,56.5695824508137,20.5448249747937,27.844467,0,0,0,40,4449,300.22835,9202.42529296875,,,,,,,,,,,,,0,,,,0,,,,,,300.145813,,,,
,28865703.86,300.0952454,13987.2797851562,0.00280946937606223,2.41535473468932E-5,1,0.999253354069792,40.0298881530762,1.99377929443771,29.6500008553266,0.0289169083555724,0.0216747702212654,0.25,0.00143298542527693,0.00280842735882888,0.00143479826708247,300.0952454,300.0952454,13979.7666015625,13994.79296875,56.5578580230252,20.5541751715475,28.224119,0,0,0,40,4449,300.1662,13987.2797851562,,,,,,,,,,,,,0,,,,-0.00245,,,,,,300.0952454,,,,
,28865800.35,300.0482788,18812.419921875,0.00282649826832249,2.53467650650914E-5,1,0.999253354069792,40.0298881530762,1.99317948162621,29.6500008553266,0.0290268221032318,0.0221292756963857,0.25,0.00147085198563229,0.0028254363244882,0.00147267585659029,300.0482788,300.0482788,18802.26171875,18822.578125,56.5047072837175,20.5631987818071,27.844467,0,0,0,40,4449,300.1426,18812.419921875,,,,,,,,,,,,,0,,,,0,,,,,,300.0482788,,,,
,28865897.38,300.0233459,23662.2548828125,0.00282540004287329,3.26624754884016E-5,1,0.999253354069792,40.0298881530762,1.99331451663181,29.6500008553266,0.0289859193685117,0.0223041650898499,0.25,0.00148640866280085,0.00282433143340403,0.00148823100731583,300.0233459,300.0233459,23649.794921875,23674.71484375,56.8837971155445,20.5602385689552,27.844467,0,0,0,40,4449,300.1298,23662.2548828125,,,,,,,,,,,,,0,,,,0,,,,,,300.0233459,,,,
,28865992.695,300.0031738,28424.890625,0.00277182651104667,2.52974482581772E-5,1,0.999253354069792,40.0298881530762,1.99277818780486,29.6500008553266,0.0283851144724125,0.0221291455118296,0.25,0.00148068954345523,0.00277076650659374,0.0014824759160123,300.0031738,300.0031738,28417.640625,28432.140625,56.9674313671022,20.5695424849258,27.844467,0,0,0,40,4449,300.14035,28424.890625,,,,,,,,,,,,,0,,,,0,,,,,,300.0031738,,,,
,28866090.15,299.9941711,33295.146484375,0.00266460140938509,3.93323377020375E-5,1,0.999253354069792,40.0298881530762,1.99255770826986,29.6500008553266,0.0271763747321795,0.0218932545653823,0.25,0.00147856999379011,0.00266354810257787,0.00148028425489873,299.9941711,299.9941711,33285.03125,33305.26171875,56.8845787440637,20.5729120484232,27.844467,0,0,0,40,4449,300.1543,33295.146484375,,,,,,,,,,,,,0,,,,0,,,,,,299.9941711,,,,
,28866183.995,299.9987183,37987.400390625,0.00263359976332074,3.62764008959663E-5,1,0.999253354069792,40.0298881530762,1.99249636123702,29.6500008553266,0.0268485952716113,0.021700302899766,0.25,0.00146689982068335,0.00263255583572813,0.00146859196642472,299.9987183,299.9987183,37982.29296875,37992.5078125,56.7931282073137,20.5737334472444,27.464817,0,0,0,40,4449,300.162,37987.400390625,,,,,,,,,,,,,0,,,,0,,,,,,299.9987183,,,,
,28866280.15,299.9935913,42792.6015625,0.00255872356050125,3.12806291975918E-5,1,0.999253354069792,40.0298881530762,1.99212911171056,29.6500008553266,0.0260817806190851,0.021073325433048,0.25,0.00142463666548559,0.00255771133602041,0.001426279238933,299.9935913,299.9935913,42785.05078125,42800.15234375,56.6696309012752,20.5841585031071,28.224119,0,0,0,40,4449,300.1607,42792.6015625,,,,,,,,,,,,,0,,,,-0.0049,,,,,,299.9935913,,,,
,28866374.335,299.991394,47500.595703125,0.00251458917576556,2.66065660362389E-5,1,0.999253354069792,40.0298881530762,1.99174895006839,29.6500008553266,0.0256621527928981,0.0205046274311412,0.25,0.00138220615633351,0.00251360753465954,0.00138381928326035,299.991394,299.991394,47493.1171875,47508.07421875,56.8236117195637,20.5916926264617,27.844467,0,0,0,40,4449,300.16455,47500.595703125,,,,,,,,,,,,,0,,,,0,,,,,,299.991394,,,,
,28866472.66,299.9924622,52413.01953125,0.00238513000409292,4.5268392651318E-5,1,0.999253354069792,40.0298881530762,1.99131559511528,29.6500008553266,0.0242030612537932,0.0202118963143914,0.25,0.00137905685352224,0.00238415531503567,0.00138058317415328,299.9924622,299.9924622,52405.44140625,52420.59765625,56.9166255133522,20.5973483821462,27.844467,0,0,0,40,4449,300.1651,52413.01953125,,,,,,,,,,,,,0,,,,0,,,,,,299.9924622,,,,
,28866567.67,300.0007324,57162.7890625,0.00235172016554124,3.14384481556186E-5,1,0.999253354069792,40.0298881530762,1.99080061477293,29.6500008553266,0.0239136542837474,0.0196034785601724,0.25,0.0013313251191773,0.00235077821418267,0.0013328288584282,300.0007324,300.0007324,57157.7265625,57167.8515625,57.0666981890445,20.6069248796838,27.844467,0,0,0,40,4449,300.15655,57162.7890625,,,,,,,,,,,,,0,,,,0,,,,,,300.0007324,,,,
,28866663.695,299.9987793,61960.4765625,0.00222978029961637,2.80720733222723E-5,1,0.999253354069792,40.0298881530762,1.99110739826995,29.6500008553266,0.0226344728317751,0.0188355025246442,0.25,0.00128409004508853,0.00222887422945458,0.0012855135830605,299.9987793,299.9987793,61955.58984375,61965.36328125,56.9080275996406,20.6021176063136,27.844467,0,0,0,40,4449,300.1669,61960.4765625,,,,,,,,,,,,,0,,,,0.0049,,,,,,299.9987793,,,,
,28866758.78,300.0016174,66713.6328125,0.00222502320244608,2.74444755917839E-5,1,0.999253354069792,40.0298881530762,1.99167801736689,29.6599995344877,0.022536646480099,0.0191221201025529,0.25,0.00130987024185647,0.00222410130831281,0.00131128816586324,300.0016174,300.0016174,66708.875,66718.390625,56.8197035769676,20.59542670026,27.844467,0,0,0,40,4449,300.1642,66713.6328125,,,,,,,,,,,,,0,,,,0,,,,,,300.0016174,,,,
,28866853.375,300.0049744,71443.98828125,0.00207957248757411,3.39887427914667E-5,1,0.999253354069792,40.0298881530762,1.99080457862644,29.6500008553266,0.0210404863411477,0.0179461146799186,0.25,0.00123147365358545,0.00207870694368472,0.00123279704307112,300.0049744,300.0049744,71436.6953125,71451.28125,57.1386080128137,20.6044206941052,27.844467,0,0,0,40,4449,300.15465,71443.98828125,,,,,,,,,,,,,0,,,,0.0049,,,,,,300.0049744,,,,
,28866948.975,300.0075073,76222.07421875,0.00203689752553807,2.28075929823254E-5,1,0.999253354069792,40.0298881530762,1.99033829265502,29.6500008553266,0.0205780096684863,0.0177245933470108,0.25,0.00121957200952216,0.00203604190001114,0.00122086625279821,300.0075073,300.0075073,76214.515625,76229.6328125,56.7008960420445,20.6142354286887,27.844467,0,0,0,40,4449,300.14555,76222.07421875,,,,,,,,,,,,,0,,,,0,,,,,,300.0075073,,,,
,28867043.87,300.0117798,80965.390625,0.00191923590790938,3.11134926786532E-5,1,0.999253354069792,40.0298881530762,1.98995257306714,29.6500008553266,0.0193484408085564,0.016912928095879,0.25,0.00116822790904979,0.00191841798427037,0.00116944523753198,300.0117798,300.0117798,80962.9765625,80967.8046875,56.8509687177368,20.6156443090098,27.464817,0,0,0,40,4449,300.1388,80965.390625,,,,,,,,,,,,,0,,,,0,,,,,,300.0117798,,,,
,28867137.68,300.01264955,85653.65625,0.00185329360443419,2.08979052236123E-5,1,0.999253354069792,40.0298881530762,1.98941366788406,29.6500008553266,0.0187338246620311,0.0160101898892139,0.25,0.00109991844250557,0.0018525230528042,0.0011010934048333,300.0118408,300.0134583,85646.0703125,85661.2421875,56.8494054606983,20.6223891606279,27.464817,0,0,0,40,4449,300.1239,85653.65625,,,,,,,,,,,,,0,,,,0,,,,,,300.01264955,,,,
,28867245.645,300.011261,89872.21484375,0.00172325128135404,2.41644894734032E-5,1,0.999253354069792,40.0298881530762,1.9899986576981,29.6500008553266,0.0172197044593612,0.0160713747237919,0.25,0.00112747897547819,0.00172246756135005,0.0011285673508247,300.011261,300.011261,89869.703125,89874.7265625,56.6719757868329,20.6148627970155,27.844467,0,0,0,40,4449,300.11585,89872.21484375,,,,,,,,,,,,,0,,,,-0.00245,,,,,,300.011261,,,,
,28867335.74,300.0049744,85376.6328125,0.00181025132396809,2.10544097603503E-5,1,0.999253354069792,40.0298881530762,1.98965095065795,29.6500008553266,0.0181787999050201,0.0163444781208698,0.25,0.0011368797201103,0.0018094583609519,0.00113802600566918,300.0049744,300.0049744,85374.2734375,85378.9921875,56.8189219484483,20.616617630036,27.464817,0,0,0,40,4449,300.11385,85376.6328125,,,,,,,,,,,,,0,,,,0,,,,,,300.0049744,,,,
,28867427.545,299.9997559,80788.19140625,0.00190709792311257,2.76075760890232E-5,1,0.999253354069792,40.0298881530762,1.9893871068231,29.6500008553266,0.0191992573190486,0.0169261253521755,0.25,0.00117190866843844,0.00190627865090318,0.00117311865159407,299.9997559,299.9997559,80760.9765625,80815.40625,57.0487207331022,20.6219745446864,27.464817,0,0,0,40,4449,300.11315,80788.19140625,,,,,,,,,,,,,0,,,,-0.00245,,,,,,299.9997559,,,,
,28867521.625,299.9966736,76084.0703125,0.00201392538855148,2.3832079180612E-5,1,0.999253354069792,40.0298881530762,1.99206123812989,29.6500008553266,0.0203445311570791,0.0176443650339522,0.25,0.00121514090792982,0.00201307399390532,0.0012164209141794,299.9966736,299.9966736,76071.8828125,76096.2578125,56.9291315696599,20.5916272445122,28.224119,0,0,0,40,4449,300.1219,76084.0703125,,,,,,,,,,,,,0,,,,-0.00245,,,,,,299.9966736,,,,
,28867618.655,299.9817505,71233.2109375,0.00208015589010961,2.27355846434212E-5,1,0.999253354069792,40.0298881530762,1.98948336954027,29.6500008553266,0.020993122452015,0.0181703529357094,0.25,0.00125228219065566,0.00207927831916998,0.00125360659756266,299.9817505,299.9817505,71227.953125,71238.46875,56.9416376259676,20.6208707703664,27.844467,0,0,0,40,4449,300.129,71233.2109375,,,,,,,,,,,,,0,,,,0,,,,,,299.9817505,,,,
,28867712.82,299.99284365,66524.98046875,0.00217776851560808,2.87825143782707E-5,1,0.999253354069792,40.0298881530762,1.98912559844999,29.6500008553266,0.0220396787790634,0.0186431860651653,0.25,0.00127761950079973,0.00217686961240133,0.00127900808793465,299.9926758,299.9930115,66519.7734375,66530.1875,56.6610329875637,20.625414566543,28.224119,0,0,0,40,4449,300.1297,66524.98046875,,,,,,,,,,,,,0,,,,-0.0049,,,,,,299.99284365,,,,
,28867807.72,299.9929199,61781.705078125,0.00227360558018468,3.4257500022179E-5,1,0.999253354069792,40.0298881530762,1.98899010147317,29.6500008553266,0.02304635013438,0.0192413941493659,0.25,0.00131422714880586,0.00227267883507103,0.00131567899285783,299.992218,299.9936218,61776.66015625,61786.75,56.6500901882945,20.6251242833698,27.464817,0,0,0,40,4449,300.1432,61781.705078125,,,,,,,,,,,,,0,,,,-0.0049,,,,,,299.9929199,,,,
,28867901.39,299.9954834,57100.912109375,0.00233813194674998,2.67548363308105E-5,1,0.999253354069792,40.0298881530762,1.989225865148,29.6500008553266,0.0237280822344955,0.0196454436945709,0.25,0.0013387181859183,0.00233718590011931,0.00134021316820297,299.9954529,299.9955139,57088.33203125,57113.4921875,56.9689946241406,20.6228234175926,27.844467,0,0,0,40,4449,300.13935,57100.912109375,,,,,,,,,,,,,0,,,,0,,,,,,299.9954834,,,,
,28867996.72,299.9898682,52333.81640625,0.0024237211735877,3.09915927846191E-5,1,0.999253354069792,40.0298881530762,1.98956082124181,29.6500008553266,0.0246979971802195,0.0198057788992982,0.25,0.00133783720926184,0.00242277262472106,0.00133939024389798,299.9898682,299.9898682,52326.5,52341.1328125,56.7024592990829,20.6223239830303,28.224119,0,0,0,40,4449,300.16095,52333.81640625,,,,,,,,,,,,,0,,,,0.00245,,,,,,299.9898682,,,,
,28868091.495,299.9881592,47598.744140625,0.00248586594083484,3.65941126699812E-5,1,0.999253354069792,40.0298881530762,1.98893241668841,29.6500008553266,0.025252563408391,0.0207175358403797,0.25,0.00140854159536272,0.00248486814176505,0.00141013518856111,299.9881592,299.9881592,47588.89453125,47608.59375,56.7165286124291,20.6263147970858,27.464817,0,0,0,40,4449,300.1669,47598.744140625,,,,,,,,,,,,,0,,,,-0.00245,,,,,,299.9881592,,,,
,28868189.51,299.9828796,42698.49609375,0.00256804028861535,3.49945854932265E-5,1,0.999253354069792,40.0298881530762,1.98957198677424,29.6500008553266,0.0261808998363617,0.0209150658670644,0.25,0.00141126873801317,0.00256703766257714,0.00141291825219279,299.9828796,299.9828796,42690.8828125,42706.109375,56.9744660237753,20.6215409010684,28.224119,0,0,0,40,4449,300.18605,42698.49609375,,,,,,,,,,,,,0,,,,0,,,,,,299.9828796,,,,
,28868285.065,299.9902649,37925.580078125,0.00260513674827141,3.63138014983759E-5,1,0.999253354069792,40.0298881530762,1.98939100374167,29.6500008553266,0.0265744593118865,0.021113225886666,0.25,0.00142258986670287,0.00260412375175441,0.00142426483108218,299.9902649,299.9902649,37918.21484375,37932.9453125,57.004167907506,20.6266297136702,27.844467,0,0,0,40,4449,300.1909,37925.580078125,,,,,,,,,,,,,0,,,,0,,,,,,299.9902649,,,,
,28868380.64,299.9941711,33146.40625,0.00267404033010988,3.63321379524759E-5,1,0.999253354069792,40.0298881530762,1.98824922132885,29.6500008553266,0.0271839452844399,0.0221123811012598,0.25,0.00150040881160625,0.00267297246861498,0.00150212847416531,299.9941711,299.9941711,33141.4296875,33151.3828125,56.9111541137176,20.6362234132437,28.224119,0,0,0,40,4449,300.19075,33146.40625,,,,,,,,,,,,,0,,,,0.00245,,,,,,299.9941711,,,,
,28868477.635,299.9926147,28301.3076171875,0.00275338366444648,2.56772280692165E-5,1,0.999253354069792,40.0298881530762,1.98809940192202,29.6500008553266,0.0281959063355963,0.0215698250927184,0.25,0.0014386162907694,0.00275235325686126,0.0014403919323165,299.9926147,299.9926147,28298.9140625,28303.701171875,57.0526288756983,20.6400429680379,28.603769,0,0,0,40,4449,300.19815,28301.3076171875,,,,,,,,,,,,,0,,,,0,,,,,,299.9926147,,,,
,28868572.95,299.9830017,23536.271484375,0.00278033505684465,3.00413608161871E-5,1,0.999253354069792,40.0298881530762,1.98977974046411,29.6500008553266,0.0285001765260565,0.0217679645729957,0.25,0.00144998273823659,0.0027792962524795,0.00145177799931728,299.9830017,299.9830017,23530.87109375,23541.671875,57.159711982833,20.6236762464382,28.603769,0,0,0,40,4449,300.21025,23536.271484375,,,,,,,,,,,,,0,,,,0,,,,,,299.9830017,,,,
,28868669.02,299.9852905,18736.158203125,0.00280448174799631,2.35527818354735E-5,1,0.999253354069792,40.0298881530762,1.98890110909479,29.6500008553266,0.0287712890188513,0.0217415254094474,0.25,0.00144426541946918,0.00280344468940651,0.00144607842129749,299.9852905,299.9852905,18728.65625,18743.66015625,57.0713879601599,20.6304888176784,27.844467,0,0,0,40,4449,300.20525,18736.158203125,,,,,,,,,,,,,0,,,,-0.00245,,,,,,299.9852905,,,,
,28868765.81,300.0012207,13899.2075195313,0.00280661508837454,2.12904875697677E-5,1,0.999253354069792,40.0298881530762,1.98842663759869,29.6500008553266,0.0288232172014718,0.0215416792044916,0.25,0.00142658937914148,0.00280558707756892,0.00142840504781901,300.0012207,300.0012207,13891.7919921875,13906.623046875,56.9815006804483,20.6351589115068,28.224119,0,0,0,40,4449,300.2161,13899.2075195313,,,,,,,,,,,,,0,,,,0,,,,,,300.0012207,,,,
,28868858.59,299.99874875,9259.18896484375,0.00267489623754268,2.74696934726441E-5,1,0.999253354069792,40.0298881530762,1.98814623414054,29.6500008553266,0.0274033870399682,0.0208938813219904,0.25,0.00139213608129709,0.00267389429864644,0.00139386709300434,299.9981689,299.9993286,9254.0478515625,9264.330078125,57.0768593597945,20.6352633544282,27.844467,0,0,0,40,4449,300.2155,9259.18896484375,,,,,,,,,,,,,0,,,,0,,,,,,299.99874875,,,,
,28868953.055,299.9992676,4538.634765625,0.00229440008751615,1.92702917573035E-5,1,0.999253354069792,40.0298881530762,1.98737952604049,29.6500008553266,0.0235711888905984,0.0174850882732024,0.25,0.00115589664558836,0.00229356526060559,0.00115738364545334,299.9989319,299.9996033,4530.9560546875,4546.3134765625,57.098744958333,20.6459783552118,27.844467,0,0,0,40,4449,300.2143,4538.634765625,,,,,,,,,,,,,0,,,,0,,,,,,299.9992676,,,,
,28869042.93,300.0075378,47.4540996551514,3.13456050222281E-5,2.30907383404495E-6,1,0.999253354069792,40.0298881530762,1.98630894378735,29.6500008553266,0.00032309821557132,0.000231600513918967,0.25,1.51556890464957E-5,3.13346052632454E-5,1.5176030073443E-5,300.0075378,300.0075378,42.5535926818848,52.354606628418,56.9549253107945,20.6591213383536,28.603769,0,0,0,40,4449,300.20875,47.4540996551514,,,,,,,,,,,,,0,,,,0,,,,,,300.0075378,,,,
,28869134.39,300.0038757,-4521.80078125,-0.00226041414429796,2.41276227997477E-5,1,0.999253354069792,40.0298881530762,1.98630372691106,29.6500008553266,-0.023177826256657,-0.0174030468292046,0.25,-0.00115529624767029,-0.00225958033735867,-0.00115676056376911,300.0038757,300.0038757,-4531.677734375,-4511.923828125,57.0666981890445,20.6558467648909,27.844467,0,0,0,40,4449,300.2103,-4521.80078125,,,,,,,,,,,,,0,,,,-0.00245,,,,,,300.0038757,,,,
,28869227.73,300.0073242,-9187.89697265625,-0.00270779607116124,2.49790418836606E-5,1,0.999253354069792,40.0298881530762,1.98553744167397,29.6500008553266,-0.0277572832471119,-0.0208263953406085,0.25,-0.00138276386923821,-0.00270679848390235,-0.00138451660659966,300.0073242,300.0073242,-9190.376953125,-9185.4169921875,56.9994781363906,20.6668357054138,28.224119,0,0,0,40,4449,300.2076,-9187.89697265625,,,,,,,,,,,,,0,,,,-0.0049,,,,,,300.0073242,,,,
,28869323.995,300.0156555,-13998.4594726563,-0.00273472546567231,3.36127578437587E-5,1,0.999253354069792,40.0298881530762,1.98524525461557,29.6500008553266,-0.0279359050700059,-0.0215701448560717,0.25,-0.00144450480184803,-0.00273368618554864,-0.00144627179363594,300.0156555,300.0156555,-14003.3916015625,-13993.52734375,56.9392927404099,20.6694742510262,27.844467,0,0,0,40,4449,300.18185,-13998.4594726563,,,,,,,,,,,,,0,,,,0,,,,,,300.0156555,,,,
,28869418.11,300.0152588,-18703.001953125,-0.00276601798847625,2.78893194388025E-5,1,0.999253354069792,40.0298881530762,1.98443337538316,29.6500008553266,-0.0282718461790442,-0.0216508411085564,0.25,-0.00144701357329534,-0.00276497714648665,-0.00144879966314704,300.0152588,300.0152588,-18710.369140625,-18695.634765625,56.8173586914099,20.6803228900121,28.224119,0,0,0,40,4449,300.18205,-18703.001953125,,,,,,,,,,,,,0,,,,0,,,,,,300.0152588,,,,
,28869512.555,300.015564,-23422.79296875,-0.00275070968620461,3.21175607708581E-5,1,0.999253354069792,40.0298881530762,1.98451396272708,29.6500008553266,-0.028050903092953,-0.0219103388235612,0.25,-0.0014726787262446,-0.00274965323740657,-0.0014744524675398,300.015564,300.015564,-23427.626953125,-23417.958984375,56.7173102409483,20.6802981048195,27.844467,0,0,0,40,4449,300.15145,-23422.79296875,,,,,,,,,,,,,0,,,,0.00245,,,,,,300.015564,,,,
,28869605.695,300.018158,-28077.9052734375,-0.00274568396642233,2.76514554825969E-5,1,0.999253354069792,40.0298881530762,1.98488233210108,29.6500008553266,-0.0281177809956112,-0.0212210808910695,0.25,-0.00141189637067018,-0.00274466861961132,-0.00141366686697092,300.018158,300.018158,-28085.283203125,-28070.52734375,57.1456426694868,20.6761077718082,28.224119,0,0,0,40,4449,300.14355,-28077.9052734375,,,,,,,,,,,,,0,,,,0,,,,,,300.018158,,,,
,28869702.825,300.015686,-32932.669921875,-0.00267543597296425,2.44540078066908E-5,1,0.999253354069792,40.0298881530762,1.98337534547068,29.6500008553266,-0.0272830794572362,-0.02121409552732,0.25,-0.00142481686115028,-0.00267441555949158,-0.00142653901269954,300.015686,300.015686,-32937.6875,-32927.65234375,57.0409044479099,20.692922676793,28.603769,0,0,0,40,4449,300.13325,-32932.669921875,,,,,,,,,,,,,0,,,,0,,,,,,300.015686,,,,
,28869796.98,300.0223694,-37637.18359375,-0.00262441522496757,3.04793263531777E-5,1,0.999253354069792,40.0298881530762,1.98330145262346,29.6500008553266,-0.0267589517272728,-0.0208254818099007,0.25,-0.00139913231497001,-0.00262341373114106,-0.00140081960621015,300.0223694,300.0223694,-37644.5546875,-37629.8125,56.8736359447945,20.6945904530942,28.224119,0,0,0,40,4449,300.12075,-37637.18359375,,,,,,,,,,,,,0,,,,0.00245,,,,,,300.0223694,,,,
,28869894.19,300.019928,-42496.654296875,-0.00254681067882648,3.04177241587224E-5,1,0.999253354069792,40.0298881530762,1.98289170040721,29.6500008553266,-0.0258516620366723,-0.0208458430682814,0.25,-0.00141475786522428,-0.00254580259274713,-0.00141639199096731,300.019928,300.019928,-42506.42578125,-42486.8828125,57.0604451608906,20.6981628278359,27.844467,0,0,0,40,4449,300.10665,-42496.654296875,,,,,,,,,,,,,0,,,,0.00245,,,,,,300.019928,,,,
,28869986.885,300.01765445,-47129.353515625,-0.00250273513282968,2.23985706171471E-5,1,0.999253354069792,40.0298881530762,1.98276993466797,29.6500008553266,-0.025464376082045,-0.0201284306104265,0.25,-0.0013586258963007,-0.00250176658110276,-0.00136023122796046,300.0174561,300.0178528,-47134.23828125,-47124.46875,56.9369478548522,20.7026113877874,28.224119,0,0,0,40,4449,300.08915,-47129.353515625,,,,,,,,,,,,,0,,,,-0.0049,,,,,,300.01765445,,,,
,28870081.65,300.0121765,-51864.328125,-0.00239402550681658,3.09921343719735E-5,1,0.999253354069792,40.0298881530762,1.9830774582152,29.6500008553266,-0.0243367737110395,-0.0194021433661285,0.25,-0.00131253684242608,-0.00239309207900041,-0.00131407070000021,300.0121765,300.0121765,-51871.84765625,-51856.80859375,56.9353845978137,20.6951482968091,28.224119,0,0,0,40,4449,300.07885,-51864.328125,,,,,,,,,,,,,0,,,,0,,,,,,300.0121765,,,,
,28870175.375,300.014801,-56548.828125,-0.00233452441424717,2.53851347862489E-5,1,0.999253354069792,40.0298881530762,1.98266020491851,29.6500008553266,-0.0236715463439122,-0.0192370413516506,0.25,-0.00130849295924854,-0.00233359625140658,-0.00130998617081009,300.014801,300.014801,-56553.83984375,-56543.81640625,56.9596150819099,20.7040141808669,28.603769,0,0,0,40,4449,300.063,-56548.828125,,,,,,,,,,,,,0,,,,0,,,,,,300.014801,,,,
,28870270.895,300.0152893,-61320.958984375,-0.00225092075723826,2.92763617137641E-5,1,0.999253354069792,40.0298881530762,1.98220000039488,29.6599995344877,-0.0227669354703588,-0.0188432283480111,0.25,-0.0012882841360534,-0.00225000939021501,-0.00128972149893274,300.0152893,300.0152893,-61331.0234375,-61310.89453125,56.7391958394868,20.7051334043596,28.224119,0,0,0,40,4449,300.04925,-61320.958984375,,,,,,,,,,,,,0,,,,0,,,,,,300.0152893,,,,
,28870364.555,300.01474,-66003.28515625,-0.0021969242718896,3.02689721225628E-5,1,0.999253354069792,40.0298881530762,1.98260624469178,29.6500008553266,-0.0222188512049566,-0.0184311724070948,0.25,-0.00126061959701357,-0.00219603376130915,-0.00126202087009704,300.01474,300.01474,-66008.3203125,-65998.25,57.0964000727753,20.7022170484433,28.224119,0,0,0,40,4449,300.04035,-66003.28515625,,,,,,,,,,,,,0,,,,0.00245,,,,,,300.01474,,,,
,28870461.265,300.0135803,-70835.62890625,-0.00209194611099603,2.46759686094476E-5,1,0.999253354069792,40.0298881530762,1.98231443218159,29.6500008553266,-0.0211734931031727,-0.017436514280569,0.25,-0.00119045556229711,-0.00209110578912005,-0.00119178870619578,300.0135803,300.0135803,-70845.7265625,-70825.53125,56.973684395256,20.7022478414511,28.224119,0,0,0,40,4449,300.0277,-70835.62890625,,,,,,,,,,,,,0,,,,-0.0049,,,,,,300.0135803,,,,
,28870555.86,300.0127563,-75564.8984375,-0.0020416124424928,2.82186968797967E-5,1,0.999253354069792,40.0298881530762,1.98257514049402,29.6500008553266,-0.0206704534624349,-0.0169971838836925,0.25,-0.00115986049597217,-0.00204079472732301,-0.00116116013637944,300.0127563,300.0127563,-75572.5390625,-75557.2578125,56.9471090256022,20.7001794471508,28.603769,0,0,0,40,4449,300.02665,-75564.8984375,,,,,,,,,,,,,0,,,,0,,,,,,300.0127563,,,,
,28870650.69,300.0112,-80302.6640625,-0.00190518479546291,3.26610088103882E-5,1,0.999253354069792,40.0298881530762,1.98385102292044,29.6500008553266,-0.0191665719957807,-0.0166473537172161,0.25,-0.00115143512704289,-0.00190437772945097,-0.00115264455033794,300.0112,300.0112,-80310.2578125,-80295.0703125,57.3050948874099,20.6804266658669,28.224119,0,0,0,40,4449,300.02005,-80302.6640625,,,,,,,,,,,,,0,,,,-0.00245,,,,,,300.0112,,,,
,28870746.355,300.0134277,-85084.515625,-0.00179048623488102,2.7825694176626E-5,1,0.999253354069792,40.0298881530762,1.9829897192697,29.6500008553266,-0.0179287737319842,-0.0160798852695041,0.25,-0.00112140058586144,-0.00178970302482711,-0.0011225345777585,300.0134277,300.0134277,-85097.015625,-85072.015625,57.1370447557753,20.6947436554582,28.224119,0,0,0,40,4449,300.02225,-85084.515625,,,,,,,,,,,,,0,,,,0,,,,,,300.0134277,,,,
,28870836.905,300.0099792,-89608.8515625,-0.00173463702484337,2.55623924345657E-5,1,0.999253354069792,40.0298881530762,1.98322824204409,29.6500008553266,-0.0174063330789091,-0.0153793055438959,0.25,-0.0010685470015942,-0.0017338909939699,-0.00106964508873258,300.0099792,300.0099792,-89613.8828125,-89603.8203125,57.0964000727753,20.6917005896129,28.603769,0,0,0,40,4449,300.00285,-89608.8515625,,,,,,,,,,,,,0,,,,0.00245,,,,,,300.0099792,,,,
,28870946.89,300.0151367,-85884.94140625,-0.00177912250532832,4.01359869312814E-5,1,0.999253354069792,40.0298881530762,1.9826208772957,29.6500008553266,-0.0178401227188366,-0.0158116159148858,0.25,-0.00109973552099314,-0.00177835367725703,-0.00110086262079278,300.0151367,300.0151367,-85894.78125,-85875.1015625,56.9142806277945,20.7005878011631,28.603769,0,0,0,40,4449,299.98065,-85884.94140625,,,,,,,,,,,,,0,,,,0.00245,,,,,,300.0151367,,,,
,28871041.235,300.0036926,-81170.45703125,-0.00190259924209417,2.68371736292671E-5,1,0.999253354069792,40.0298881530762,1.98264016151519,29.6500008553266,-0.0191900517050755,-0.0162650250675545,0.25,-0.00111870253177928,-0.00190181421678999,-0.00111991139596913,300.0036926,300.0036926,-81178.0234375,-81162.890625,56.9549253107945,20.699889249211,28.224119,0,0,0,40,4449,299.991,-81170.45703125,,,,,,,,,,,,,0,,,,0,,,,,,300.0036926,,,,
,28871138.45,300.0035095,-76310.59375,-0.00199191340452623,2.50442491505898E-5,1,0.999253354069792,40.0298881530762,1.9822034895336,29.6500008553266,-0.0201001187500611,-0.0169472587945653,0.25,-0.00116429493275057,-0.00199109493371088,-0.00116556233604676,300.0035095,300.0035095,-76315.625,-76305.5625,56.9205336559483,20.7066866403989,27.844467,0,0,0,40,4449,299.983,-76310.59375,,,,,,,,,,,,,0,,,,0.00245,,,,,,300.0035095,,,,
,28871235.725,299.99668885,-71450.6796875,-0.0021272727202881,3.06347916374306E-5,1,0.999253354069792,40.0298881530762,1.98212773656114,29.6500008553266,-0.0214964830699188,-0.0179177871993437,0.25,-0.00122733973230542,-0.00212640852356375,-0.00122869563807964,299.9963989,299.9969788,-71458.109375,-71443.25,56.8533136032945,20.7089142436534,27.844467,0,0,0,40,4449,299.9879,-71450.6796875,,,,,,,,,,,,,0,,,,0,,,,,,299.99668885,,,,
,28871328.705,299.9927368,-66801.15625,-0.00216559725382561,2.69679162143823E-5,1,0.999253354069792,40.0298881530762,1.98191412828653,29.6500008553266,-0.0218889609777051,-0.0181956325892141,0.25,-0.00124561222886919,-0.00216471921346916,-0.00124699441153817,299.9927368,299.9927368,-66806.1171875,-66796.1953125,56.9338213407753,20.7100827031508,28.224119,0,0,0,40,4449,299.99035,-66801.15625,,,,,,,,,,,,,0,,,,0,,,,,,299.9927368,,,,
,28871426.305,299.9903564,-61925.8828125,-0.00225742269477299,2.88800653335464E-5,1,0.999253354069792,40.0298881530762,1.98261612232311,29.6500008553266,-0.0228698421193743,-0.0187136260965174,0.25,-0.00127527898180279,-0.00225652164925242,-0.0012767221834337,299.9903564,299.9903564,-61933.02734375,-61918.73828125,56.9580518248714,20.7007796737913,28.224119,0,0,0,40,4449,300.0024,-61925.8828125,,,,,,,,,,,,,0,,,,0,,,,,,299.9903564,,,,
,28871523.63,299.9857788,-57061.154296875,-0.00233705148945645,2.82187609360587E-5,1,0.999253354069792,40.0298881530762,1.9815227648526,29.6599995344877,-0.023677082481646,-0.0192884469491622,0.25,-0.00131357257895603,-0.00233612231134314,-0.00131506873030066,299.9857788,299.9857788,-57066.10546875,-57056.203125,56.7970363499099,20.7144016434033,28.603769,0,0,0,40,4449,300.0203,-57061.154296875,,,,,,,,,,,,,0,,,,0,,,,,,299.9857788,,,,
,28871618.305,299.9908447,-52329.1953125,-0.00240257545718551,3.34215140381665E-5,1,0.999253354069792,40.0298881530762,1.98415114634255,29.6500008553266,-0.0243990994330891,-0.0196964615564626,0.25,-0.00133634976003498,-0.00240162783999144,-0.00133788974566587,299.9908447,299.9908447,-52339.1171875,-52319.2734375,57.1479875550445,20.6850698114506,27.844467,0,0,0,40,4449,300.01745,-52329.1953125,,,,,,,,,,,,,0,,,,0.0049,,,,,,299.9908447,,,,
,28871714.175,299.9837036,-47537.41015625,-0.0024994797685009,2.38453395233081E-5,1,0.999253354069792,40.0298881530762,1.9830710577276,29.6500008553266,-0.025486019348393,-0.0198105582642396,0.25,-0.00133062834292137,-0.00249853264402732,-0.00133223419859982,299.9837036,299.9837036,-47547.671875,-47527.1484375,56.9650864815445,20.6940252504629,27.844467,0,0,0,40,4449,300.03175,-47537.41015625,,,,,,,,,,,,,0,,,,0.00245,,,,,,299.9837036,,,,
,28871810.155,299.9857788,-42742.22265625,-0.00252039934791817,3.21065065356807E-5,1,0.999253354069792,40.0298881530762,1.98283536294578,29.6500008553266,-0.0256070920589114,-0.0204895293766602,0.25,-0.00138765644269473,-0.00251941277677848,-0.00138927601725907,299.9857788,299.9857788,-42749.8359375,-42734.609375,57.0291800201214,20.7010075872055,28.224119,0,0,0,40,4449,300.0409,-42742.22265625,,,,,,,,,,,,,0,,,,-0.0049,,,,,,299.9857788,,,,
,28871906.575,299.9865417,-37925.04296875,-0.00261631074598355,2.81932156722188E-5,1,0.999253354069792,40.0298881530762,1.98320626122791,29.6500008553266,-0.0266946085871972,-0.0206477942776068,0.25,-0.00138480082028391,-0.0026153220884521,-0.00138648532708808,299.9865417,299.9865417,-37927.625,-37922.4609375,56.8751992018329,20.6972216383317,28.224119,0,0,0,40,4449,300.0516,-37925.04296875,,,,,,,,,,,,,0,,,,0.0049,,,,,,299.9865417,,,,
,28872004.53,299.9929504,-33028.3828125,-0.00264649787269149,3.89083126306255E-5,1,0.999253354069792,40.0298881530762,1.98250232314113,29.6500008553266,-0.0269473952243631,-0.0211446811178521,0.25,-0.00142444153439584,-0.00264548041295669,-0.00142614626364467,299.9929504,299.9929504,-33035.86328125,-33020.90234375,57.0627900464484,20.7069191815988,27.844467,0,0,0,40,4449,300.0524,-33028.3828125,,,,,,,,,,,,,0,,,,0.00245,,,,,,299.9929504,,,,
,28872098.275,299.98573305,-28343.66796875,-0.0027175613251895,3.91869240469849E-5,1,0.999253354069792,40.0298881530762,1.98293454015772,29.6500008553266,-0.0277411662833044,-0.021345139560168,0.25,-0.00142958271527562,-0.00271653805893887,-0.00143133616608174,299.9846802,299.9867859,-28353.77734375,-28333.55859375,57.0510656186599,20.701760270494,27.844467,0,0,0,40,4449,300.07065,-28343.66796875,,,,,,,,,,,,,0,,,,0.0049,,,,,,299.98573305,,,,
,28872192.895,299.9937744,-23613.4892578125,-0.00274987403764295,2.98591828861203E-5,1,0.999253354069792,40.0298881530762,1.98191065448848,29.6500008553266,-0.0280394066220635,-0.0216906883417685,0.25,-0.00145570168820412,-0.00274883068040597,-0.00145747700255708,299.9937744,299.9937744,-23616.064453125,-23610.9140625,56.8017261210252,20.7154685865846,28.603769,0,0,0,40,4449,300.07215,-23613.4892578125,,,,,,,,,,,,,0,,,,0,,,,,,299.9937744,,,,
,28872288.15,299.997406,-18854.146484375,-0.00276645581961995,2.9627051392561E-5,1,0.999253354069792,40.0298881530762,1.98183635773107,29.6500008553266,-0.0282401555426586,-0.0216319787098853,0.25,-0.00144766687660252,-0.00276541585062979,-0.0014494548732213,299.997406,299.997406,-18864.341796875,-18843.951171875,56.7970363499099,20.7188398917583,28.224119,0,0,0,40,4449,300.0715,-18854.146484375,,,,,,,,,,,,,0,,,,0,,,,,,299.997406,,,,
,28872382.905,299.9928589,-14116.78515625,-0.00275653081047028,2.50612643202991E-5,1,0.999253354069792,40.0298881530762,1.98214895481701,29.6500008553266,-0.0282039327885337,-0.0212063623390136,0.25,-0.00141118620175958,-0.00275551474440171,-0.00141297050033558,299.9928589,299.9928589,-14121.93359375,-14111.63671875,56.8275198621599,20.7132743809247,28.603769,0,0,0,40,4449,300.0739,-14116.78515625,,,,,,,,,,,,,0,,,,-0.0049,,,,,,299.9928589,,,,
,28872477.045,299.9949646,-9413.92626953125,-0.00263855824303262,3.24696933448129E-5,1,0.999253354069792,40.0298881530762,1.98194156617393,29.6500008553266,-0.0269306777267601,-0.0206631819540574,0.25,-0.00138342966160145,-0.00263756296804679,-0.00138513788582613,299.9949646,299.9949646,-9423.9130859375,-9403.939453125,56.9822823089676,20.7169839064764,28.224119,0,0,0,40,4449,300.0805,-9413.92626953125,,,,,,,,,,,,,0,,,,0,,,,,,299.9949646,,,,
,28872569.64,299.9981995,-4782.97119140625,-0.00229891659391215,2.43356996719654E-5,1,0.999253354069792,40.0298881530762,1.98108764215583,29.6599995344877,-0.0234672184257412,-0.0179221186187188,0.25,-0.00119877066740402,-0.00229805284892178,-0.001200260119402,299.9981995,299.9981995,-4785.4306640625,-4780.51171875,56.9486722826406,20.7271559057882,28.603769,0,0,0,40,4449,300.0851,-4782.97119140625,,,,,,,,,,,,,0,,,,0.0049,,,,,,299.9981995,,,,
,28872658.53,299.9966431,-338.793426513672,-0.000324211734922063,4.95441135303391E-6,1,0.999253354069792,40.0298881530762,1.98115608796419,29.6599995344877,-0.00331139268037263,-0.00251751639589346,0.25,-0.000168161191089576,-0.000324090460840218,-0.000168371401423944,299.9966431,299.9966431,-341.260101318359,-336.326751708984,56.7860935506406,20.7303215848069,28.224119,0,0,0,40,4449,300.0821,-338.793426513672,,,,,,,,,,,,,0,,,,0,,,,,,299.9966431,,,,
,28872746.645,300.0006409,4059.3212890625,0.00217056881868711,2.27089272462828E-5,1,0.999253354069792,40.0298881530762,1.98077541371277,29.6599995344877,0.0221634024482854,0.0168630509435777,0.25,0.00112685858317498,0.00216975632217502,0.00112826507148002,300.0006409,300.0006409,4056.64672851562,4061.99584960937,56.7110572127945,20.7344946790774,28.224119,0,0,0,40,4449,300.0858,4059.3212890625,,,,,,,,,,,,,0,,,,0,,,,,,300.0006409,,,,
,28872837.045,300.008728,8578.4384765625,0.00265258122148938,2.61817690570963E-5,1,0.999253354069792,40.0298881530762,1.98050265184072,29.6599995344877,0.0271014330286758,0.0204906410774363,0.25,0.00136689863818564,0.00265159510814333,0.00136861608360072,300.008728,300.008728,8565.7900390625,8591.0869140625,56.851750346256,20.7410017718789,28.224119,0,0,0,40,4449,300.0995,8578.4384765625,,,,,,,,,,,,,0,,,,0,,,,,,300.008728,,,,
,28872929.985,300.0119324,13223.9072265625,0.00273239350711948,2.61408226780121E-5,1,0.999253354069792,40.0298881530762,1.98006682769672,29.6500008553266,0.0278876972144746,0.0212372972683511,0.25,0.00142002488490755,0.00273137025430607,0.00142179222970008,300.0119324,300.0119324,13219.0927734375,13228.7216796875,56.8978664288906,20.7498147841261,27.844467,0,0,0,40,4449,300.076,13223.9072265625,,,,,,,,,,,,,0,,,,0.00245,,,,,,300.0119324,,,,
,28873024.61,300.00798035,17954.1376953125,0.00277150376289715,3.23890293230424E-5,1,0.999253354069792,40.0298881530762,1.97978945219479,29.6599995344877,0.028325248333295,0.0212951161019525,0.25,0.00141865877296698,0.00277048154216438,0.0014204508219661,300.0079346,300.0080261,17951.78125,17956.494140625,56.7548284098714,20.7491538751189,27.844467,0,0,0,40,4449,300.0592,17954.1376953125,,,,,,,,,,,,,0,,,,0.0049,,,,,,300.00798035,,,,
,28873116.86,300.010498,22566.7314453125,0.00274478592564116,3.09996553075708E-5,1,0.999253354069792,40.0298881530762,1.98133505771025,29.6599995344877,0.0279838715177976,0.0216206813109514,0.25,0.00145088251792158,0.00274374395355601,0.00145265420306721,300.010498,300.010498,22564.34375,22569.119140625,56.8728543162753,20.7301375941556,28.603769,0,0,0,40,4449,300.058,22566.7314453125,,,,,,,,,,,,,0,,,,-0.00245,,,,,,300.010498,,,,
,28873209.11,300.00013735,27177.0966796875,0.00270463675325318,2.38905107907014E-5,1,0.999253354069792,40.0298881530762,1.98186687623804,29.6599995344877,0.0275100907649851,0.0217228229685255,0.25,0.00146644416123139,0.00270358778229619,0.00146818774613312,299.9998169,300.0004578,27167.25,27186.943359375,56.9854088230445,20.7208606655361,28.603769,0,0,0,40,4449,300.0583,27177.0966796875,,,,,,,,,,,,,0,,,,0.00245,,,,,,300.00013735,,,,
,28873305.57,300.0048218,31997.3046875,0.00266016194105421,2.96747500578551E-5,1,0.999253354069792,40.0298881530762,1.98057377105776,29.6599995344877,0.0271161601641928,0.020917662688626,0.25,0.0014035911804992,0.00265915645232151,0.0014053053299558,300.0048218,300.0048218,31989.828125,32004.78125,56.9619599674676,20.7404070426774,28.603769,0,0,0,40,4449,300.05,31997.3046875,,,,,,,,,,,,,0,,,,0.00245,,,,,,300.0048218,,,,
,28873399.625,300.0102844,36697.298828125,0.00262865041077996,2.4088264889479E-5,1,0.999253354069792,40.0298881530762,1.98065156583918,29.6500008553266,0.0267292491486331,0.0210557069306972,0.25,0.00142128665204638,0.00262763476697986,0.00142297753017143,300.0102844,300.0102844,36692.35546875,36702.2421875,57.1120326431599,20.7372060096489,28.603769,0,0,0,40,4449,300.0432,36697.298828125,,,,,,,,,,,,,0,,,,-0.00245,,,,,,300.0102844,,,,
,28873494.935,300.0105286,41462.240234375,0.00257729368176782,2.91529952729763E-5,1,0.999253354069792,40.0298881530762,1.98061393863837,29.6599995344877,0.0262248970271664,0.0205381729953541,0.25,0.00138409094386728,0.0025763051876721,0.00138574736530116,300.0105286,300.0105286,41454.66796875,41469.8125,56.8931766577752,20.7403302483438,28.603769,0,0,0,40,4449,300.03505,41462.240234375,,,,,,,,,,,,,0,,,,0.00245,,,,,,300.0105286,,,,
,28873588.69,300.0087585,46147.60546875,0.00252514992517624,2.26141162898159E-5,1,0.999253354069792,40.0298881530762,1.98110468905621,29.6500008553266,0.0256979815204459,0.0201414414205916,0.25,0.00135733986443957,0.00252418186159188,0.00135896115922624,300.0087585,300.0087585,46142.4140625,46152.796875,56.7493570102368,20.7366589622668,27.844467,0,0,0,40,4449,300.02685,46147.60546875,,,,,,,,,,,,,0,,,,0,,,,,,300.0087585,,,,
,28873685.875,300.0212708,51002.677734375,0.00240422785228744,3.26651658560836E-5,1,0.999253354069792,40.0298881530762,1.98136599510504,29.6599995344877,0.0244326792405922,0.0193974308145028,0.25,0.00131177473988291,0.00240329340064237,0.00131331554763401,300.0212708,300.0212708,51000.35546875,51005,56.7251265261406,20.7283818094534,28.224119,0,0,0,40,4449,300.02,51002.677734375,,,,,,,,,,,,,0,,,,-0.0049,,,,,,300.0212708,,,,
,28873779.85,300.0138855,55700.263671875,0.00239136633616285,1.99670393320655E-5,1,0.999253354069792,40.0298881530762,1.98121771041987,29.6500008553266,0.0243270080618691,0.0191378831080178,0.25,0.00129100018801324,0.00239044762413286,0.00129253189924892,300.0138855,300.0138855,55687.6484375,55712.87890625,56.8134505488137,20.732575751711,28.983419,0,0,0,40,4449,300.00715,55700.263671875,,,,,,,,,,,,,0,,,,-0.00245,,,,,,300.0138855,,,,
,28873875.565,300.0171509,60482.830078125,0.00228611515253109,2.763293044066E-5,1,0.999253354069792,40.0298881530762,1.98071053608836,29.6599995344877,0.0232315544155078,0.0184011630059399,0.25,0.00124399136734315,0.00228523120602684,0.00124545366234842,300.0171509,300.0171509,60480.10546875,60485.5546875,57.0393411908714,20.7407470602568,28.224119,0,0,0,40,4449,299.989,60482.830078125,,,,,,,,,,,,,0,,,,-0.0049,,,,,,300.0171509,,,,
,28873970.96,300.0127258,65253.466796875,0.00218468193672006,2.60739159387537E-5,1,0.999253354069792,40.0298881530762,1.98113611543162,29.6599995344877,0.0221207215338586,0.018076863997306,0.25,0.00123233107416901,0.00218381006955713,0.00123372584038844,300.0127258,300.0127258,65243.54296875,65263.390625,56.7681160946983,20.7366447988108,28.224119,0,0,0,40,4449,299.9781,65253.466796875,,,,,,,,,,,,,0,,,,0,,,,,,300.0127258,,,,
,28874066.39,300.0088043,70023.74609375,0.00215080578086573,2.90834965002763E-5,1,0.999253354069792,40.0298881530762,1.98121654470668,29.6500008553266,0.0217822280830783,0.0177761560663856,0.25,0.00121134378644747,0.00214995004329105,0.00121271558312863,300.0081787,300.0094299,70021.0859375,70026.40625,56.8572217458906,20.7333533962966,28.603769,0,0,0,40,4449,299.972,70023.74609375,,,,,,,,,,,,,0,,,,0,,,,,,300.0088043,,,,
,28874162.79,300.0074768,74841.484375,0.00203629051696687,2.35567052248006E-5,1,0.999253354069792,40.0298881530762,1.98091819095853,29.6599995344877,0.0206060655643912,0.0169049601718867,0.25,0.00115377238015322,0.00203547695230649,0.00115506947684501,300.0074768,300.0074768,74838.953125,74844.015625,56.719655126506,20.7374661349454,28.603769,0,0,0,40,4449,299.96515,74841.484375,,,,,,,,,,,,,0,,,,0.0049,,,,,,300.0074768,,,,
,28874258.985,300.018158,79649.76171875,0.00192576488218281,3.87698780152926E-5,1,0.999253354069792,40.0298881530762,1.98088174617004,29.6599995344877,0.0193701062879039,0.0166633910530986,0.25,0.00115142032028742,0.00192495634333104,0.00115264343467493,300.018158,300.018158,79642.265625,79657.2578125,56.4171648895637,20.7409918000917,28.224119,0,0,0,40,4449,299.9442,79649.76171875,,,,,,,,,,,,,0,,,,0,,,,,,300.018158,,,,
,28874355.705,300.0176849,84485.5,0.00185505586434108,2.86355434586616E-5,1,0.999253354069792,40.0298881530762,1.98086651580794,29.6500008553266,0.0186838526953598,0.0159066114798239,0.25,0.00109623728154221,0.00185428646515767,0.00109741449778186,300.0170898,300.01828,84480.4921875,84490.5078125,56.9088092281599,20.7412305209793,28.603769,0,0,0,40,4449,299.9325,84485.5,,,,,,,,,,,,,0,,,,-0.0049,,,,,,300.0176849,,,,
,28874444.715,300.0137024,88933.71484375,0.00177356908203118,3.84669707462837E-5,1,0.999253354069792,40.0298881530762,1.98152706074204,29.6599995344877,0.0178418450941354,0.0153685114234856,0.25,0.00106196304034565,0.00177282557759969,0.00106308705702347,300.0137024,300.0137024,88928.5390625,88938.890625,56.6360208749483,20.7288361889762,28.224119,0,0,0,40,4449,299.9217,88933.71484375,,,,,,,,,,,,,0,,,,0,,,,,,300.0137024,,,,
,28874551.495,300.006073,86658.8046875,0.0017946752465443,2.7031906938413E-5,1,0.999253354069792,40.0298881530762,1.98183432008356,29.6599995344877,0.018068616224953,0.0154857609936604,0.25,0.00106854726499768,0.00179392684960953,0.001069685791195,300.006073,300.006073,86653.734375,86663.875,56.4890747133329,20.7219278717638,28.603769,0,0,0,40,4449,299.92155,86658.8046875,,,,,,,,,,,,,0,,,,0,,,,,,300.006073,,,,
,28874644.61,299.9987183,82005.30859375,0.00187496432720795,3.1503189445261E-5,1,0.999253354069792,40.0298881530762,1.9818158053928,29.6599995344877,0.0189056086594801,0.0160120349265324,0.25,0.00110152894617103,0.00187419161175792,0.00110272051865262,299.9987183,299.9987183,81995.0703125,82015.546875,56.7884384361983,20.7243504831632,28.603769,0,0,0,40,4449,299.92545,82005.30859375,,,,,,,,,,,,,0,,,,0,,,,,,299.9987183,,,,
,28874742.105,299.9987488,77131.22265625,0.00200268276048443,3.03882974140805E-5,1,0.999253354069792,40.0298881530762,1.98019831018517,29.6500008553266,0.0202163421076446,0.01686611140024,0.25,0.00115665484877213,0.00200186930491249,0.00115792971459753,299.9987488,299.9987488,77121.2421875,77141.203125,57.0291800201214,20.7504224140245,28.983419,0,0,0,40,4449,299.92715,77131.22265625,,,,,,,,,,,,,0,,,,0,,,,,,299.9987488,,,,
,28874839.195,299.9959412,72275.52734375,0.00207113518389942,1.96559425031353E-5,1,0.999253354069792,40.0298881530762,1.98006662166993,29.6500008553266,0.0209702689288396,0.017070562505778,0.25,0.0011631175329252,0.00207031465506903,0.00116443862867843,299.9959412,299.9959412,72268.140625,72282.9140625,56.7759323798906,20.754618013533,28.983419,0,0,0,40,4449,299.92985,72275.52734375,,,,,,,,,,,,,0,,,,0,,,,,,299.9959412,,,,
,28874934.33,299.988739,67519.9765625,0.00217241990843003,2.41878051690026E-5,1,0.999253354069792,40.0298881530762,1.9802121223378,29.6599995344877,0.0219798524918816,0.0180074214929238,0.25,0.00122898194340294,0.00217155283631252,0.00123036930294993,299.988739,299.988739,67510.2890625,67529.6640625,56.5656743082175,20.7528400473821,28.603769,0,0,0,40,4449,299.93385,67519.9765625,,,,,,,,,,,,,0,,,,0,,,,,,299.988739,,,,
,28875033.25,299.9937744,62577.318359375,0.00226684018509845,2.68088347078239E-5,1,0.999253354069792,40.0298881530762,1.9795247489806,29.6500008553266,0.0229455997018503,0.0186796176611431,0.25,0.00127310094856798,0.00226593994969087,0.00127455033015687,299.9937744,299.9937744,62567.2578125,62587.37890625,56.7540467813522,20.75519655955,28.224119,0,0,0,40,4449,299.9429,62577.318359375,,,,,,,,,,,,,0,,,,-0.00245,,,,,,299.9937744,,,,
,28875131.335,299.9896851,57673.78515625,0.00233931078366523,2.75700699407066E-5,1,0.999253354069792,40.0298881530762,1.98019521242648,29.6500008553266,0.0237236918448449,0.0190702278967005,0.25,0.00129482764517536,0.00233839338740845,0.0012963258242766,299.9896851,299.9896851,57658.75390625,57688.81640625,57.2152076076984,20.7403409574023,28.603769,0,0,0,40,4449,299.94885,57673.78515625,,,,,,,,,,,,,0,,,,0.0049,,,,,,299.9896851,,,,
,28875227.85,299.9883423,52848.857421875,0.00240261851818296,2.63188658628275E-5,1,0.999253354069792,40.0298881530762,1.97998786303682,29.6599995344877,0.0244165262182863,0.0192769464982236,0.25,0.00130245887292704,0.00240169330157244,0.00130400010982089,299.9883423,299.9883423,52841.2109375,52856.50390625,56.7970363499099,20.7498689430678,28.603769,0,0,0,40,4449,299.9643,52848.857421875,,,,,,,,,,,,,0,,,,0,,,,,,299.9883423,,,,
,28875322.945,299.9874573,48096.0078125,0.0024756148246357,2.9964864029613E-5,1,0.999253354069792,40.0298881530762,1.97958590587376,29.6500008553266,0.0251487478763053,0.0198859416955351,0.25,0.00134445209480809,0.0024746588589438,0.00134604182501632,299.9874573,299.9874573,48083.4921875,48108.5234375,56.9236601700253,20.7552231172922,28.983419,0,0,0,40,4449,299.97315,48096.0078125,,,,,,,,,,,,,0,,,,-0.00245,,,,,,299.9874573,,,,
,28875419.675,299.9934998,43263.404296875,0.00253070954615331,3.11817066613904E-5,1,0.999253354069792,40.0298881530762,1.98034446880356,29.6599995344877,0.0257075627674535,0.0203951796683775,0.25,0.00137965200786167,0.00252972710017967,0.00138127843882816,299.9934998,299.9934998,43260.87890625,43265.9296875,56.6438371601406,20.7455986713897,28.983419,0,0,0,40,4449,299.9749,43263.404296875,,,,,,,,,,,,,0,,,,0.0049,,,,,,299.9934998,,,,
,28875515.64,299.9876709,38465.890625,0.00258712564279823,3.22378632005E-5,1,0.999253354069792,40.0298881530762,1.98030267530648,29.6599995344877,0.0263056785592673,0.0207018700066685,0.25,0.00139725260684464,0.00258612938586765,0.00139891765742524,299.9876709,299.9876709,38458.5234375,38473.2578125,56.8556584888522,20.7433993618393,28.603769,0,0,0,40,4449,299.9891,38465.890625,,,,,,,,,,,,,0,,,,0,,,,,,299.9876709,,,,
,28875613.04,299.9841309,33598.51953125,0.00264364209256773,3.88613483590348E-5,1,0.999253354069792,40.0298881530762,1.98015910643782,29.6599995344877,0.0268801363804921,0.0211429751844814,0.25,0.00142691229616089,0.00264262380853365,0.00142861569457444,299.9841309,299.9841309,33591.19921875,33605.83984375,56.780622151006,20.7474476614023,28.983419,0,0,0,40,4449,299.9939,33598.51953125,,,,,,,,,,,,,0,,,,0,,,,,,299.9841309,,,,
,28875708.405,299.9844666,28831.357421875,0.00270527425626556,3.97779144436485E-5,1,0.999253354069792,40.0298881530762,1.98000603029168,29.6599995344877,0.0275473613247809,0.0213883926983349,0.25,0.00143825302429673,0.00270424559255737,0.00143999840370652,299.9844666,299.9844666,28823.7265625,28838.98828125,56.8001628639868,20.7506528526598,28.603769,0,0,0,40,4449,300.00965,28831.357421875,,,,,,,,,,,,,0,,,,0,,,,,,299.9844666,,,,
,28875804.585,299.9865112,24023.61328125,0.00273390039949933,3.37112916439122E-5,1,0.999253354069792,40.0298881530762,1.98048552543757,29.6500008553266,0.0278491299686175,0.0215975160048108,0.25,0.0014514917045497,0.00273286087383523,0.00145325716754441,299.9865112,299.9865112,24016.048828125,24031.177734375,57.1651833824676,20.7479989814927,28.603769,0,0,0,40,4449,300.02015,24023.61328125,,,,,,,,,,,,,0,,,,-0.00245,,,,,,299.9865112,,,,
,28875902.595,299.9963379,19126.0458984375,0.00275026446204687,3.67756696651476E-5,1,0.999253354069792,40.0298881530762,1.97967054972533,29.6500008553266,0.0280122544242445,0.0216751313192644,0.25,0.00145633412883492,0.00274921917171488,0.00145811147086323,299.9963379,299.9963379,19113.404296875,19138.6875,56.8814522299868,20.7601096309943,28.603769,0,0,0,40,4449,300.0196,19126.0458984375,,,,,,,,,,,,,0,,,,0,,,,,,299.9963379,,,,
,28875998.38,299.9972534,14339.337890625,0.00274071418384385,2.668216333174E-5,1,0.999253354069792,40.0298881530762,1.97921626444282,29.6500008553266,0.0279386248618338,0.0214232650819326,0.25,0.0014359467173775,0.00273968155578174,0.00143771988395159,299.9972534,299.9972534,14326.81640625,14351.859375,57.0198004778906,20.7664234836352,28.603769,0,0,0,40,4449,300.0191,14339.337890625,,,,,,,,,,,,,0,,,,0,,,,,,299.9972534,,,,
,28876095.295,299.9861145,9494.25048828125,0.00267167284457939,2.37072135676245E-5,1,0.999253354069792,40.0298881530762,1.97900066093584,29.6500008553266,0.0273221510699024,0.0203610354366585,0.25,0.00135335262996626,0.00267069717355579,0.00135508445426583,299.9861145,299.9861145,9484.1484375,9504.3525390625,56.9478906541214,20.768700044269,28.224119,0,0,0,40,4449,300.0282,9494.25048828125,,,,,,,,,,,,,0,,,,0,,,,,,299.9861145,,,,
,28876190.55,299.9943848,4736.515625,0.00225504263020652,3.01749840273596E-5,1,0.999253354069792,40.0298881530762,1.97870360944468,29.6500008553266,0.0229873991767383,0.0175915398933731,0.25,0.00117871784100594,0.00225419361445701,0.00118017923972527,299.9943848,299.9943848,4726.62060546875,4746.41064453125,56.8587850029291,20.7719713322856,28.983419,0,0,0,40,4449,300.0345,4736.515625,,,,,,,,,,,,,0,,,,0,,,,,,299.9943848,,,,
,28876281.665,300.0061951,177.393363952637,0.00017393767941877,2.87266650885554E-6,1,0.999253354069792,40.0298881530762,1.9785486506516,29.6500008553266,0.00177953183718627,0.00131878116891583,0.25,8.75272117970264E-5,0.000173874326992179,8.76400637305993E-5,300.0061951,300.0061951,172.547973632813,182.238754272461,56.6821369575829,20.7722205683368,28.603769,0,0,0,40,4449,300.0273,177.393363952637,,,,,,,,,,,,,0,,,,0.0049,,,,,,300.0061951,,,,
,28876286.44,300.0035095,-0.144625842571259,2.70763304026765E-6,7.64955021108995E-7,1,0.999253354069792,40.0298881530762,1.97844474537358,29.6500008553266,3.06502960631892E-5,3.50007409609672E-6,0.25,-1.568282842158E-7,2.70765589219809E-6,-1.55025784907386E-7,300.0035095,300.0035095,-0.1674614995718,-0.121790185570717,56.7767140084099,20.7781288370002,28.983419,0,0,0,40,4417,300.0258,-0.144625842571259,,,,,,,,,,,,,0,,,,0,,,,,,300.0035095,,,,