File: data/doubleLayers/dl_2-5/ppms/data/DD205_5_HYST_100OE_150K.DAT
[Header]
; VSM Data File (default extension .dat)
; Copyright (c) 2003-2013, Quantum Design, Inc. All rights reserved.
TITLE,
FILEOPENTIME,23166029.53,09/26/2018,11:59 am
BYAPP,VSM,2.0,2.0
INFO,PPMS VSM Option Release 1.4.10 Build 1,APPNAME
INFO,Quantum Design Linear Motor Servo Controller,MOTOR_MODULE_NAME
INFO,3101-100 M1,MOTOR_HW_VERSION
INFO,MMC1014,MOTOR_SERIAL_NUMBER
INFO,SRV No X-over 01.03.11,MOTOR_SOFTWARE_VERSION
INFO,Quantum Design VSM Detection Module,VSM_MODULE_NAME
INFO,3101-150 F0,VSM_HW_VERSION
INFO,VSM707,VSM_SERIAL_NUMBER
INFO,VSM No X-over 01.02.05 May 20 2008 13:51:47,VSM_SOFTWARE_VERSION
INFO,704,PREAMP_SERIAL_NUMBER
INFO,822,COIL_SERIAL_NUMBER
INFO,0,MOMENT_UNITS
INFO,,SAMPLE_MATERIAL
INFO,,SAMPLE_COMMENT
INFO,,SAMPLE_MASS
INFO,,SAMPLE_VOLUME
INFO,,SAMPLE_MOLECULAR_WEIGHT
INFO,,SAMPLE_SIZE
INFO,,SAMPLE_SHAPE
DATATYPE,COMMENT,1
DATATYPE,TIME,2
STARTUPAXIS,X,2
STARTUPAXIS,Y1,5
[Data]
Comment,Time Stamp (sec),Temperature (K),Magnetic Field (Oe),Moment (emu),M. Std. Err. (emu),Transport Action,Averaging Time (sec),Frequency (Hz),Peak Amplitude (mm),Center Position (mm),Coil Signal' (mV),Coil Signal" (mV),Range (mV),M. Quad. Signal (emu),M. Raw' (emu),M. Raw" (emu),Min. Temperature (K),Max. Temperature (K),Min. Field (Oe),Max. Field (Oe),Mass (grams),Motor Lag (deg),Pressure (Torr),VSM Status (code),Motor Status (code),Measure Status (code),Measure Count,PPMS Status (code),System Temp. (K),System Field (Oe),Sample Position (deg),Bridge 1 Resistance (ohms),Bridge 1 Excitation (에),Bridge 2 Resistance (ohms),Bridge 2 Excitation (에),Bridge 3 Resistance (ohms),Bridge 3 Excitation (에),Bridge 4 Resistance (ohms),Bridge 4 Excitation (에),Signal 1 Vin (V),Signal 2 Vin (V),Digital Inputs (code),Drive 1 Iout (mA),Drive 1 Ipower (W),Drive 2 Iout (mA),Drive 2 Ipower (W),Pressure (),Map 20 (),Map 21 (),Map 22 (),Map 23 (),Map 24 (),Map 25 (),Map 26 (),Map 27 (),Map 28 (),Map 29 ()
,23166044.7,150.4437408,-0.182685270905495,,,2,,,,16.539999820292,,,,,,,150.4437408,150.4437408,-0.182685270905495,-0.182685270905495,,,25.566563,,,,-99999999,4369,150.5929,-0.182685270905495,,,,,,,,,,,,,,,,,,,,,,,150.4437408,,,,
,23166195.96,150.2536163,4598.79614257812,4.48387824536855E-5,4.64081520923596E-7,1,0.999253354069792,40.0298881530762,1.9963595084897,16.5299996733665,0.000507592248900106,9.84620242100123E-5,0.25,8.5719085555987E-7,4.50567627739604E-5,9.33061899063442E-7,150.2536163,150.2536163,4591.185546875,4606.40673828125,55.8497025846021,20.5626371884532,24.807261,0,0,0,40,4449,150.20905,4598.79614257812,,,,,,,,,,,,,0,,,,0.00245,,,,,,150.2536163,,,,
,23166290.615,150.1383514,9327.5419921875,4.17835568009097E-5,7.49750725363618E-7,1,0.999253354069792,40.0298881530762,1.99619166509702,16.5299996733665,0.000469216269426673,0.000113291205388336,0.25,2.6958998837421E-6,4.19838125663395E-5,2.77580362678159E-6,150.1383514,150.1383514,9322.310546875,9332.7734375,55.5315797772751,20.564943243626,25.186911,0,0,0,40,4449,150.1239,9327.5419921875,,,,,,,,,,,,,0,,,,-0.00245,,,,,,150.1383514,,,,
,23166384.17,150.0651398,14002.4926757813,3.25966310705865E-5,1.35741394940568E-6,1,0.999253354069792,40.0298881530762,1.99632621534871,16.5299996733665,0.000361351056958513,0.000115502056367987,0.25,4.49046894108203E-6,3.27491514114871E-5,4.56439618088621E-6,150.0651398,150.0651398,13995.2568359375,14009.728515625,56.6555615879291,20.5650091173076,25.186911,0,0,0,40,4449,150.09535,14002.4926757813,,,,,,,,,,,,,0,,,,-0.00245,,,,,,150.0651398,,,,
,23166479.805,150.0253067,18782.537109375,1.9772926313337E-5,1.77984433587784E-6,1,0.999253354069792,40.0298881530762,1.99628385470106,16.5299996733665,0.000211249022394291,0.000115643013893651,0.25,6.73715387819196E-6,1.98591169294853E-5,6.80159126300657E-6,150.0248108,150.0258026,18777.646484375,18787.427734375,55.8762779542559,20.5671060671779,25.186911,0,0,0,40,4449,150.0878,18782.537109375,,,,,,,,,,,,,0,,,,0.0049,,,,,,150.0253067,,,,
,23166577.655,150.0078278,23672.0712890625,6.79847191707689E-6,1.63681156193491E-6,1,0.999253354069792,40.0298881530762,1.99629642614896,16.5299996733665,6.3785242312576E-5,9.05568307655129E-5,0.25,6.78864711567821E-6,6.82103962253561E-6,6.83269832271488E-6,150.0078278,150.0078278,23664.5703125,23679.572265625,56.4765686570252,20.5707164379789,24.807261,0,0,0,40,4449,150.0902,23672.0712890625,,,,,,,,,,,,,0,,,,0,,,,,,150.0078278,,,,
,23166674.245,150.005661,28499.88671875,-9.91162996197877E-6,8.97826614853952E-7,1,0.999253354069792,40.0298881530762,1.99628987575691,16.5299996733665,-0.000134399389938969,0.000105668462744356,0.25,1.10300155644033E-5,-9.97765682741293E-6,1.10684324698424E-5,150.005661,150.005661,28492.12890625,28507.64453125,56.506270540756,20.5699428177644,25.186911,0,0,0,40,4449,150.0865,28499.88671875,,,,,,,,,,,,,0,,,,0.00245,,,,,,150.005661,,,,
,23166769.26,150.0056152,33247.9765625,-2.32615185655632E-5,1.65856426381876E-6,1,0.999253354069792,40.0298881530762,1.99648069512001,16.5299996733665,-0.000290736825988591,0.000106150702620028,0.25,1.33970032883094E-5,-2.33967028799571E-5,1.34260460735941E-5,150.0056152,150.0056152,33240.24609375,33255.70703125,56.6321127323521,20.5690241474402,25.186911,0,0,0,40,4449,150.08085,33247.9765625,,,,,,,,,,,,,0,,,,-0.0049,,,,,,150.0056152,,,,
,23166866.79,150.0085754,38124.984375,-4.13433145004298E-5,1.502395438502E-6,1,0.999253354069792,40.0298881530762,1.99626539798089,16.5299996733665,-0.000497273090496787,7.72295603477518E-5,0.25,1.40011097153158E-5,-4.15680960423669E-5,1.40048276854819E-5,150.0085754,150.0085754,38117.53515625,38132.43359375,56.1295255944867,20.5709337122839,25.566563,0,0,0,40,4449,150.0728,38124.984375,,,,,,,,,,,,,0,,,,0.00245,,,,,,150.0085754,,,,
,23166962.635,150.0103912,42915.376953125,-5.97167260722928E-5,2.44523062622508E-6,1,0.999253354069792,40.0298881530762,1.9963140703091,16.5299996733665,-0.000709846725144797,6.31210911015119E-5,0.25,1.59589257339265E-5,-6.00346856526132E-5,1.59436736476612E-5,150.0103912,150.0103912,42910.359375,42920.39453125,56.6219515616021,20.5708680768152,25.186911,0,0,0,40,4449,150.06435,42915.376953125,,,,,,,,,,,,,0,,,,0.00245,,,,,,150.0103912,,,,
,23167060.105,150.0114594,47785.66015625,-7.39476554751821E-5,2.47524774606314E-6,1,0.999253354069792,40.0298881530762,1.99629723472484,16.5299996733665,-0.000865047896761901,-1.94603552172704E-6,0.25,1.27086826044052E-5,-7.43303515652714E-5,1.26555615313998E-5,150.0114594,150.0114594,47772.9375,47798.3828125,55.6925952522367,20.5706419487116,25.186911,0,0,0,40,4449,150.05435,47785.66015625,,,,,,,,,,,,,0,,,,-0.00245,,,,,,150.0114594,,,,
,23167153.595,150.0132141,52458.048828125,-8.9987839263975E-5,2.22671971659148E-6,1,0.999253354069792,40.0298881530762,1.99622412279287,16.5299996733665,-0.00105702576758991,2.27487505829433E-5,0.25,1.76763565266033E-5,-9.0457003021298E-5,1.76229970714791E-5,150.0132141,150.0132141,52445.25,52470.84765625,56.4492116588521,20.5696661553801,25.566563,0,0,0,40,4449,150.0426,52458.048828125,,,,,,,,,,,,,0,,,,-0.00245,,,,,,150.0132141,,,,
,23167250.405,150.0119476,57295.193359375,-0.000110516446903105,2.77985500731493E-6,1,0.999253354069792,40.0298881530762,1.99624106930008,16.5299996733665,-0.00128990051835648,-1.95528231017104E-5,0.25,1.75268698463532E-5,-0.000111086162036062,1.7441374273175E-5,150.0119476,150.0119476,57292.5078125,57297.87890625,56.2803798986983,20.5714004287613,25.186911,0,0,0,40,4449,150.03215,57295.193359375,,,,,,,,,,,,,0,,,,0,,,,,,150.0119476,,,,
,23167345.115,150.0126038,62030.703125,-0.000125113977631118,3.18837052733206E-6,1,0.999253354069792,40.0298881530762,1.9962441580873,16.5299996733665,-0.00146183925948055,-1.31776299449883E-5,0.25,2.06299721140481E-5,-0.000125760193690533,2.05376804395082E-5,150.0126038,150.0126038,62020.46484375,62040.94140625,56.4179465180829,20.5733406270835,25.566563,0,0,0,40,4449,150.02195,62030.703125,,,,,,,,,,,,,0,,,,0,,,,,,150.0126038,,,,
,23167442.31,150.0131073,66889.234375,-0.000138938211656526,3.09869341080711E-6,1,0.999253354069792,40.0298881530762,1.99631411864491,16.5299996733665,-0.00161980405419032,-3.53799496933763E-5,0.25,2.10822491119266E-5,-0.000139653043010408,2.09714992397601E-5,150.0131073,150.0131073,66879.3046875,66899.1640625,56.364014150256,20.5682619830333,25.566563,0,0,0,40,4449,150.0067,66889.234375,,,,,,,,,,,,,0,,,,0.0049,,,,,,150.0131073,,,,
,23167538.71,150.0120239,71706.796875,-0.000158133623678312,2.79772661828957E-6,1,0.999253354069792,40.0298881530762,1.99629369979436,16.5299996733665,-0.00183484001767061,-9.04269012921206E-5,0.25,1.95779861705901E-5,-0.000158940477409791,1.94310617289951E-5,150.0120239,150.0120239,71691.7734375,71721.8203125,56.4093486043714,20.5730298501256,25.566563,0,0,0,40,4449,149.9969,71706.796875,,,,,,,,,,,,,0,,,,0.00245,,,,,,150.0120239,,,,
,23167635.315,150.0103912,76535.01171875,-0.000175332503559746,3.50199956524172E-6,1,0.999253354069792,40.0298881530762,1.99589594853843,16.5299996733665,-0.00204296765794359,-4.88308727805851E-5,0.25,2.62336943494352E-5,-0.000176234133086413,2.60939422782831E-5,150.0103912,150.0103912,76529.953125,76540.0703125,56.0232241158713,20.570480266255,24.807261,0,0,0,40,4449,149.9862,76535.01171875,,,,,,,,,,,,,0,,,,0,,,,,,150.0103912,,,,
,23167732.225,150.0130005,81380.8359375,-0.00019399999023872,3.97952550338964E-6,1,0.999253354069792,40.0298881530762,1.99608800077394,16.5299996733665,-0.00224986654409811,-0.000116179946733938,0.25,2.35538635103663E-5,-0.000194989303433783,2.33733520542875E-5,150.0130005,150.0130005,81368.5,81393.171875,56.4890747133329,20.569363512864,25.186911,0,0,0,40,4449,149.97245,81380.8359375,,,,,,,,,,,,,0,,,,0,,,,,,150.0130005,,,,
,23167827.545,150.0130005,86143.54296875,-0.000219544565990317,2.82462666311162E-6,1,0.999253354069792,40.0298881530762,1.99598835426409,16.5299996733665,-0.00254801362307916,-0.000119868945428136,0.25,2.76758109018957E-5,-0.000220665796351688,2.74776839619421E-5,150.0130005,150.0130005,86135.9609375,86151.125,56.5219031111406,20.5686660889151,25.566563,0,0,0,40,4449,149.9609,86143.54296875,,,,,,,,,,,,,0,,,,0.0049,,,,,,150.0130005,,,,
,23167940.91,150.0145874,89214.6484375,-0.000230620578434977,4.2382199587752E-6,1,0.999253354069792,40.0298881530762,1.99602669330295,16.5299996733665,-0.00268025699488398,-0.000104977466722445,0.25,3.09152396494952E-5,-0.000231801225214156,3.07169320252762E-5,150.0145874,150.0145874,89207.15625,89222.140625,55.812184415679,20.5683846939133,25.566563,0,0,0,40,4449,149.9478,89214.6484375,,,,,,,,,,,,,0,,,,0,,,,,,150.0145874,,,,
,23168032.36,150.0044098,84644.3046875,-0.000208766186711388,3.01810775504133E-6,1,0.999253354069792,40.0298881530762,1.99595236312165,16.5299996733665,-0.00241606520076163,-0.000153112337981096,0.25,2.28718199866702E-5,-0.000209827139748012,2.26661029486871E-5,150.0044098,150.0044098,84634.4609375,84654.1484375,56.4468667732944,20.5710457890243,25.566563,0,0,0,40,4449,149.9484,84644.3046875,,,,,,,,,,,,,0,,,,0,,,,,,150.0044098,,,,
,23168126.715,150.00143435,79925.24609375,-0.000194658117082927,3.59448531234015E-6,1,0.999253354069792,40.0298881530762,1.9960430323862,16.5299996733665,-0.00225324734220696,-0.000140709454067808,0.25,2.15087595074962E-5,-0.000195647566401058,2.13168071816404E-5,150.0013123,150.0015564,79920.3203125,79930.171875,56.7884384361983,20.5702188782316,25.566563,0,0,0,40,4449,149.94515,79925.24609375,,,,,,,,,,,,,0,,,,-0.00245,,,,,,150.00143435,,,,
,23168223.745,149.9967422,75076.43359375,-0.000173338536138991,3.36978335714453E-6,1,0.999253354069792,40.0298881530762,1.996109074461,16.5299996733665,-0.00201879129262639,-5.48788687842353E-5,0.25,2.53547340525449E-5,-0.000174229065423544,2.52133546538957E-5,149.9966125,149.9968719,75066.1640625,75086.703125,56.5523866233906,20.5715888714637,25.566563,0,0,0,40,4449,149.9503,75076.43359375,,,,,,,,,,,,,0,,,,0,,,,,,149.9967422,,,,
,23168321.445,149.9945068,70193.54296875,-0.000157718036132892,3.40880505561929E-6,1,0.999253354069792,40.0298881530762,1.99621440225885,16.5299996733665,-0.00183014322872635,-8.90710581424856E-5,0.25,1.96250410961261E-5,-0.000158522968004996,1.94786365757622E-5,149.9945068,149.9945068,70188.609375,70198.4765625,56.8587850029291,20.5674812868684,25.566563,0,0,0,40,4449,149.9555,70193.54296875,,,,,,,,,,,,,0,,,,0.0049,,,,,,149.9945068,,,,
,23168416.06,149.9925995,65463.1796875,-0.000138267751496195,3.69909779309502E-6,1,0.999253354069792,40.0298881530762,1.99614002154131,16.5299996733665,-0.00162211953374716,2.37364603374804E-5,0.25,2.61706584945442E-5,-0.000138987210952414,2.60856340618425E-5,149.9925995,149.9925995,65455.7421875,65470.6171875,56.7243448976214,20.5683755832859,25.566563,0,0,0,40,4449,149.9617,65463.1796875,,,,,,,,,,,,,0,,,,0.00245,,,,,,149.9925995,,,,
,23168513.395,149.9945526,60597.359375,-0.000116879619081028,2.77857490599668E-6,1,0.999253354069792,40.0298881530762,1.99629498220343,16.5299996733665,-0.00136591306533758,-1.08705232391817E-5,0.25,1.93992841496412E-5,-0.000117483547677322,1.93134183632735E-5,149.9945526,149.9945526,60587.3984375,60607.3203125,56.4257628032752,20.5714921172115,25.566563,0,0,0,40,4449,149.966,60597.359375,,,,,,,,,,,,,0,,,,0,,,,,,149.9945526,,,,
,23168607.445,149.9942398,55896.75,-0.000101084893789736,2.88638093055494E-6,1,0.999253354069792,40.0298881530762,1.99627186148968,16.5299996733665,-0.00118621105531104,1.87106307784692E-5,0.25,1.92533130237905E-5,-0.000101611035130814,1.91906974174417E-5,149.993927,149.9945526,55889.1328125,55904.3671875,56.7892200647175,20.5713209022007,25.186911,0,0,0,40,4449,149.9743,55896.75,,,,,,,,,,,,,0,,,,0,,,,,,149.9942398,,,,
,23168703.85,149.9920044,51076.955078125,-8.47877549415422E-5,1.96302322751061E-6,1,0.999253354069792,40.0298881530762,1.99622840900789,16.5299996733665,-0.000993102369778785,5.1049922641429E-6,0.25,1.52173911739402E-5,-8.52276127473691E-5,1.5159861214104E-5,149.9920044,149.9920044,51071.67578125,51082.234375,56.5242479966983,20.5700037154216,25.566563,0,0,0,40,4449,149.97935,51076.955078125,,,,,,,,,,,,,0,,,,0.00245,,,,,,149.9920044,,,,
,23168800.635,149.991745,46241.716796875,-6.66539374347197E-5,2.16406446153337E-6,1,0.999253354069792,40.0298881530762,1.99634744838356,16.5299996733665,-0.000790222523545364,5.84036137112175E-5,0.25,1.67516884441557E-5,-6.700720140781E-5,1.67296227765919E-5,149.991745,149.991745,46239.30078125,46244.1328125,56.3663590358137,20.5705286580726,25.946213,0,0,0,40,4449,149.9856,46241.716796875,,,,,,,,,,,,,0,,,,-0.0049,,,,,,149.991745,,,,
,23168897.415,149.9917755,41401.423828125,-4.73664902522917E-5,2.18919319081091E-6,1,0.999253354069792,40.0298881530762,1.99639813657846,16.5299996733665,-0.000565743251457922,6.54521193003829E-5,0.25,1.40128569938403E-5,-4.76208477224812E-5,1.40072814411994E-5,149.9917755,149.9917755,41391.32421875,41411.5234375,56.2475515008906,20.5704321876821,25.946213,0,0,0,40,4449,149.99375,41401.423828125,,,,,,,,,,,,,0,,,,0,,,,,,149.9917755,,,,
,23168992.8,149.992218,36636.43359375,-3.71041503089581E-5,1.98905405056078E-6,1,0.999253354069792,40.0298881530762,1.99639231559113,16.5299996733665,-0.000445974829614609,6.73777129320003E-5,0.25,1.23950425746847E-5,-3.73056442474807E-5,1.23974463320579E-5,149.992218,149.992218,36629.21875,36643.6484375,56.6031924771406,20.5701038779241,25.566563,0,0,0,40,4449,149.999,36636.43359375,,,,,,,,,,,,,0,,,,0,,,,,,149.992218,,,,
,23169088.125,149.9918213,31871.6865234375,-2.32783821009059E-5,1.75751394894183E-6,1,0.999253354069792,40.0298881530762,1.99639089743059,16.5299996733665,-0.000287652450546934,8.73763527675338E-5,0.25,1.17475235851582E-5,-2.34110751722691E-5,1.17683925794489E-5,149.9918213,149.9918213,31861.599609375,31881.7734375,57.0119841926983,20.5698688359734,25.566563,0,0,0,40,4449,150.008,31871.6865234375,,,,,,,,,,,,,0,,,,0,,,,,,149.9918213,,,,
,23169184.715,149.9908905,27044.208984375,-3.47455086074426E-6,1.4203663325236E-6,1,0.999253354069792,40.0298881530762,1.99634966326117,16.5299996733665,-5.70976855980064E-5,9.43464643300447E-5,0.25,8.91164344900503E-6,-3.50569074500102E-6,8.94983672852064E-6,149.9908905,149.9908905,27039.201171875,27049.216796875,56.7673344661791,20.570912261097,25.566563,0,0,0,40,4449,150.0152,27044.208984375,,,,,,,,,,,,,0,,,,0,,,,,,149.9908905,,,,
,23169277.8,149.9940643,22394.095703125,1.02732969826569E-5,1.87158427859945E-6,1,0.999253354069792,40.0298881530762,1.9964431676604,16.5299996733665,9.89360290864864E-5,0.000122256800150338,0.25,8.97353435150616E-6,1.03094145984918E-5,9.03382440300989E-6,149.9940643,149.9940643,22386.8046875,22401.38671875,56.4875114562944,20.5745862073503,25.566563,0,0,0,40,4449,150.02035,22394.095703125,,,,,,,,,,,,,0,,,,0,,,,,,149.9940643,,,,
,23169376.505,149.9920044,17459.2294921875,2.43085418803794E-5,1.51296206145821E-6,1,0.999253354069792,40.0298881530762,1.99647100118222,16.5299996733665,0.000263784414174858,0.000118906673153568,0.25,6.23337986218246E-6,2.44177580437606E-5,6.30261079065335E-6,149.9920044,149.9920044,17454.05859375,17464.400390625,56.7157469839098,20.5731608785122,25.946213,0,0,0,40,4449,150.02515,17459.2294921875,,,,,,,,,,,,,0,,,,-0.0049,,,,,,149.9920044,,,,
,23169472.835,149.9936371,12644.07421875,3.72918479600343E-5,1.19100158399796E-6,1,0.999253354069792,40.0298881530762,1.99647905521774,16.5299996733665,0.000415495610523887,0.000120296321695334,0.25,4.09374940434441E-6,3.74680488497803E-5,4.17329874264306E-6,149.9936371,149.9936371,12636.65625,12651.4921875,56.6274229612368,20.5734943522615,25.566563,0,0,0,40,4449,150.03115,12644.07421875,,,,,,,,,,,,,0,,,,0.00245,,,,,,149.9936371,,,,
,23169568.87,149.9937134,7843.68310546875,4.78108765168679E-5,7.40195467864811E-7,1,0.999253354069792,40.0298881530762,1.99646445425635,16.5299996733665,0.000539029639122846,0.000117845892136867,0.25,2.0453905265184E-6,4.80418426605803E-5,2.13185626939728E-6,149.9937134,149.9937134,7833.82421875,7853.5419921875,56.4429586306983,20.574159568274,25.186911,0,0,0,40,4449,150.03915,7843.68310546875,,,,,,,,,,,,,0,,,,0,,,,,,149.9937134,,,,
,23169665.015,149.995163,3038.57922363281,5.25071062564284E-5,3.76832612199248E-7,1,0.999253354069792,40.0298881530762,1.9965318186179,16.5299996733665,0.000594796009685733,0.000113344588006122,0.25,8.30467214740143E-7,5.27629798743838E-5,9.18661613997988E-7,149.995163,149.995163,3026.0673828125,3051.09106445313,56.9236601700253,20.5755715716037,25.566563,0,0,0,40,4449,150.0419,3038.57922363281,,,,,,,,,,,,,0,,,,0.0049,,,,,,149.995163,,,,
,23169761.47,149.9957123,-1778.71636962891,3.41240793535186E-5,3.14484091094186E-7,1,0.999253354069792,40.0298881530762,1.99653281100762,16.5299996733665,0.000389209087041153,5.84265587191309E-5,0.25,-8.01553549671174E-7,3.42925136559364E-5,-7.5078122072796E-7,149.9957123,149.9957123,-1783.74011230469,-1773.69262695313,56.6985511564868,20.5738854743742,25.946213,0,0,0,40,4449,150.04225,-1778.71636962891,,,,,,,,,,,,,0,,,,-0.00245,,,,,,149.9957123,,,,
,23169859.86,150.0003357,-6696.49340820312,5.22077777319823E-6,4.88940968063673E-7,1,0.999253354069792,40.0298881530762,1.99666946699069,16.5299996733665,6.34924772171754E-5,-1.36870651190749E-5,0.25,-2.11439589693133E-6,5.24973606176116E-6,-2.11640244879113E-6,150.0003357,150.0003357,-6701.37939453125,-6691.607421875,56.9689946241406,20.5744523831163,25.946213,0,0,0,40,4449,150.04315,-6696.49340820312,,,,,,,,,,,,,0,,,,0,,,,,,150.0003357,,,,
,23169959.485,150.006073,-11677.4125976563,-2.12600962882445E-5,1.33766196127539E-6,1,0.999253354069792,40.0298881530762,1.99668120166879,16.5299996733665,-0.000232635039077183,-9.30514238563702E-5,0.25,-4.48733181265064E-6,-2.13570990905638E-5,-4.54324810288508E-6,150.0056458,150.0065002,-11684.859375,-11669.9658203125,56.7141837268714,20.5762935811006,25.186911,0,0,0,40,4449,150.0354,-11677.4125976563,,,,,,,,,,,,,0,,,,-0.00245,,,,,,150.006073,,,,
,23170060.2,150.0109711,-16709.6728515625,-2.3161816066445E-5,1.80545948981062E-6,1,0.999253354069792,40.0298881530762,1.99656798653165,16.5299996733665,-0.000248243238839725,-0.000131148540851948,0.25,-7.51033887257101E-6,-2.32633607668886E-5,-7.58401142019575E-6,150.0109711,150.0109711,-16722.201171875,-16697.14453125,56.7134020983521,20.5752605123802,25.946213,0,0,0,40,4449,150.0309,-16709.6728515625,,,,,,,,,,,,,0,,,,0,,,,,,150.0109711,,,,
,23170160.125,150.0103149,-21704.3974609375,-1.16855674482012E-5,1.24716033906477E-6,1,0.999253354069792,40.0298881530762,1.99667713897861,16.5299996733665,-0.000113459990222687,-0.00013385066919336,0.25,-9.74688918593208E-6,-1.17273668678318E-5,-9.8132132938535E-6,150.0103149,150.0103149,-21714.35546875,-21694.439453125,56.371048806929,20.577199663693,25.946213,0,0,0,40,4449,150.01705,-21704.3974609375,,,,,,,,,,,,,0,,,,-0.00245,,,,,,150.0103149,,,,
,23170260.665,150.0106049,-26731.505859375,3.29080905106153E-6,1.61996885494537E-6,1,0.999253354069792,40.0298881530762,1.99675649952037,16.5299996733665,5.61886081424059E-5,-0.000101428803193801,0.25,-9.50144497232597E-6,3.32198347318609E-6,-9.54281322417416E-6,150.0106049,150.0106049,-26736.578125,-26726.43359375,57.0799858738714,20.5729194188352,25.566563,0,0,0,40,4449,150.0065,-26731.505859375,,,,,,,,,,,,,0,,,,0,,,,,,150.0106049,,,,
,23170361.65,150.0126038,-31776.619140625,2.01639251587996E-5,1.84167063486104E-6,1,0.999253354069792,40.0298881530762,1.99664433592502,16.5299996733665,0.00025685583498672,-0.000119662494320031,0.25,-1.40461894560148E-5,2.0284963972128E-5,-1.40832319547764E-5,150.0126038,150.0126038,-31783.955078125,-31769.283203125,57.0979633298137,20.5776608467608,25.566563,0,0,0,40,4449,149.9974,-31776.619140625,,,,,,,,,,,,,0,,,,0,,,,,,150.0126038,,,,
,23170457.52,150.0116272,-36566.009765625,3.44871255564852E-5,1.71408056106056E-6,1,0.999253354069792,40.0298881530762,1.99663782965774,16.5299996733665,0.000423227384522824,-0.000112345915564071,0.25,-1.58970025318777E-5,3.46812784903521E-5,-1.59206802163074E-5,150.0116272,150.0116272,-36571.12109375,-36560.8984375,56.7696793517368,20.5756353963651,25.946213,0,0,0,40,4449,149.9822,-36566.009765625,,,,,,,,,,,,,0,,,,0.0049,,,,,,150.0116272,,,,
,23170554.565,150.0116959,-41418.3046875,5.07436685263959E-5,2.36800068380408E-6,1,0.999253354069792,40.0298881530762,1.99659864179179,16.5299996733665,0.000611476730014996,-0.000100775776907898,0.25,-1.77101336977583E-5,5.1020368662817E-5,-1.7717369780285E-5,150.0116425,150.0117493,-41423.29296875,-41413.31640625,57.0635716749676,20.5786939409436,25.566563,0,0,0,40,4449,149.9709,-41418.3046875,,,,,,,,,,,,,0,,,,0,,,,,,150.0116959,,,,
,23170651.63,150.01376345,-46268.68359375,7.10966553400298E-5,2.31382451424335E-6,1,0.999253354069792,40.0298881530762,1.99667915994141,16.5299996733665,0.000845596780116164,-7.70610486219396E-5,0.25,-1.91670940901419E-5,7.14754547739028E-5,-1.91498890122681E-5,150.0135498,150.0139771,-46276.1640625,-46261.203125,56.8486238321791,20.5814804133525,25.566563,0,0,0,40,4449,149.95675,-46268.68359375,,,,,,,,,,,,,0,,,,0,,,,,,150.01376345,,,,
,23170750.695,150.012207,-51220.443359375,8.55361307567853E-5,2.45375242469078E-6,1,0.999253354069792,40.0298881530762,1.99661970849531,16.5299996733665,0.00101393263611133,-7.3345602983824E-5,0.25,-2.13548486192828E-5,8.59891844148921E-5,-2.13262305057051E-5,150.012207,150.012207,-51227.96875,-51212.91796875,56.7266897831791,20.5775498068164,25.566563,0,0,0,40,4449,149.94585,-51220.443359375,,,,,,,,,,,,,0,,,,0.00245,,,,,,150.012207,,,,
,23170847.51,150.0123596,-56057.583984375,0.000102868147346968,2.90391577136702E-6,1,0.999253354069792,40.0298881530762,1.99671518014706,16.5299996733665,0.00121449226488024,-5.98085259718973E-5,0.25,-2.31812391697743E-5,0.000103409096096974,-2.31350765625516E-5,150.0123596,150.0123596,-56065.1953125,-56049.97265625,56.7134020983521,20.5771972588402,25.566563,0,0,0,40,4449,149.93415,-56057.583984375,,,,,,,,,,,,,0,,,,0,,,,,,150.0123596,,,,
,23170943.96,150.0118561,-60879.861328125,0.000122175032472019,3.39855480596027E-6,1,0.999253354069792,40.0298881530762,1.99673867411513,16.5299996733665,0.0014367906860009,-3.8533288355578E-5,0.25,-2.46705171562508E-5,0.000122813069248923,-2.46022714436969E-5,150.0118561,150.0118561,-60892.3203125,-60867.40234375,56.5664559367368,20.5781170360187,25.566563,0,0,0,40,4449,149.9218,-60879.861328125,,,,,,,,,,,,,0,,,,0,,,,,,150.0118561,,,,
,23171041.675,150.0114746,-65762.09765625,0.000138270843372669,3.27188785296978E-6,1,0.999253354069792,40.0298881530762,1.99676269759081,16.5299996733665,0.00162467389800141,-3.54344401483216E-5,0.25,-2.72003192184686E-5,0.000138991833940465,-2.71202754934234E-5,150.0112762,150.011673,-65769.5,-65754.6953125,56.8236117195637,20.5784446609285,25.946213,0,0,0,40,4449,149.9121,-65762.09765625,,,,,,,,,,,,,0,,,,0.00245,,,,,,150.0114746,,,,
,23171140.06,150.0111389,-70678.74609375,0.000153327183297007,2.9283239764579E-6,1,0.999253354069792,40.0298881530762,1.99668933044187,16.5299996733665,0.00179617501817916,-8.5894845236619E-6,0.25,-2.74587872699163E-5,0.000154122533997546,-2.73575725563537E-5,150.0111389,150.0111389,-70686.140625,-70671.3515625,56.8376810329099,20.5758442842476,25.566563,0,0,0,40,4449,149.90275,-70678.74609375,,,,,,,,,,,,,0,,,,0.00245,,,,,,150.0111389,,,,
,23171238.39,150.0117798,-75593.66796875,0.000172161118947994,3.23546263707412E-6,1,0.999253354069792,40.0298881530762,1.99661205905612,16.5299996733665,0.00201250709459681,1.46266761894074E-5,0.25,-2.8694237559017E-5,0.000173050912322876,-2.85710135323209E-5,150.0117798,150.0117798,-75598.625,-75588.7109375,56.9142806277945,20.5798264775154,25.566563,0,0,0,40,4449,149.89245,-75593.66796875,,,,,,,,,,,,,0,,,,-0.0049,,,,,,150.0117798,,,,
,23171335.6,150.0104218,-80451.09375,0.000189941030448421,3.22635616946218E-6,1,0.999253354069792,40.0298881530762,1.99664285575157,16.5299996733665,0.00222502630770882,-1.05335623410604E-5,0.25,-3.40044015398056E-5,0.000190926356778671,-3.38810008699808E-5,150.0104218,150.0104218,-80456,-80446.1875,56.8939582862945,20.5786085591259,25.186911,0,0,0,40,4449,149.88395,-80451.09375,,,,,,,,,,,,,0,,,,-0.00245,,,,,,150.0104218,,,,
,23171432.97,150.0106049,-85318.125,0.000208082549708398,4.12736627096869E-6,1,0.999253354069792,40.0298881530762,1.99671607511541,16.5299996733665,0.00242548286134526,5.81992074005303E-5,0.25,-3.11123780848188E-5,0.000209152660099228,-3.09481349698744E-5,150.0106049,150.0106049,-85328.171875,-85308.078125,56.6883899857368,20.5798933005457,25.566563,0,0,0,40,4449,149.8738,-85318.125,,,,,,,,,,,,,0,,,,-0.0049,,,,,,150.0106049,,,,
,23171528.905,150.0094452,-89999.54296875,0.000230422758666798,4.56639636453941E-6,1,0.999253354069792,40.0298881530762,1.99677944388512,16.5299996733665,0.00269064940581489,3.75791907544499E-5,0.25,-3.68166598882707E-5,0.000231611426268941,-3.66475937532604E-5,150.0094452,150.0094452,-89999.5546875,-89999.53125,57.0463758475445,20.5796855620935,25.566563,0,0,0,40,4417,149.863,-89999.54296875,,,,,,,,,,,,,0,,,,0,,,,,,150.0094452,,,,
,23171637.555,150.0037842,-85510.42578125,0.000207196245756051,4.17949644380349E-6,1,0.999253354069792,40.0298881530762,1.99680697822784,16.5299996733665,0.00241596748815073,5.38749741896441E-5,0.25,-3.13388783843847E-5,0.000208262385264978,-3.11771076952365E-5,150.0037842,150.0037842,-85515.3671875,-85505.484375,56.2889778124098,20.58324911428,25.186911,0,0,0,40,4449,149.8595,-85510.42578125,,,,,,,,,,,,,0,,,,0.00245,,,,,,150.0037842,,,,
,23171732.8,149.9977264,-80750.4296875,0.000193534190906195,4.24454271714933E-6,1,0.999253354069792,40.0298881530762,1.99685407056266,16.5299996733665,0.00225213221312957,7.66370722544916E-5,0.25,-2.69574226104859E-5,0.000194526465503361,-2.67939185994817E-5,149.9977264,149.9977264,-80752.890625,-80747.96875,57.1972301517561,20.5817003720753,26.325863,0,0,0,40,4449,149.8641,-80750.4296875,,,,,,,,,,,,,0,,,,0,,,,,,149.9977264,,,,
,23171830.885,149.9965515,-75848.01171875,0.000175854462909519,3.53917732710936E-6,1,0.999253354069792,40.0298881530762,1.99680464861498,16.5299996733665,0.00205985312417276,-7.92312129943597E-6,0.25,-3.13224096234809E-5,0.000176766508212506,-3.12064279064089E-5,149.9965515,149.9965515,-75855.4453125,-75840.578125,56.7571732954291,20.5845110374253,25.566563,0,0,0,40,4449,149.86735,-75848.01171875,,,,,,,,,,,,,0,,,,0,,,,,,149.9965515,,,,
,23171929.55,149.9936523,-70916.22265625,0.000160031734372405,2.80285126325089E-6,1,0.999253354069792,40.0298881530762,1.99688652355752,16.5299996733665,0.00187940161883508,-3.48479146101856E-5,0.25,-3.09375623406586E-5,0.000160865449415366,-3.08431032989297E-5,149.9936523,149.9936523,-70923.6953125,-70908.75,57.2034831799099,20.5838297098832,26.325863,0,0,0,40,4449,149.8754,-70916.22265625,,,,,,,,,,,,,0,,,,-0.0049,,,,,,149.9936523,,,,
,23172026.51,149.9916992,-66071.5,0.00013902430648086,2.48419914329499E-6,1,0.999253354069792,40.0298881530762,1.99681429986618,16.5299996733665,0.00162671040356482,3.74813389713047E-6,0.25,-2.38826049287329E-5,0.000139743948596374,-2.37851118814188E-5,149.9916992,149.9916992,-66076.3046875,-66066.6953125,56.6297678467945,20.5812885284055,25.946213,0,0,0,40,4449,149.8857,-66071.5,,,,,,,,,,,,,0,,,,-0.0049,,,,,,149.9916992,,,,
,23172124.075,149.9906006,-61193.95703125,0.000121479972047799,3.23854486666242E-6,1,0.999253354069792,40.0298881530762,1.99665187727246,16.5299996733665,0.00143232232633214,-5.99243704785495E-5,0.25,-2.64326147402349E-5,0.00012211740039905,-2.63740997819061E-5,149.9906006,149.9906006,-61203.7890625,-61184.125,56.8603482599676,20.5801739307652,25.946213,0,0,0,40,4449,149.8918,-61193.95703125,,,,,,,,,,,,,0,,,,0,,,,,,149.9906006,,,,
,23172221.54,149.9920654,-56324.568359375,0.000104704665795329,2.41245981638962E-6,1,0.999253354069792,40.0298881530762,1.99663236439322,16.5299996733665,0.0012355205989392,-5.73950032524514E-5,0.25,-2.32888765774679E-5,0.000105254856064816,-2.32403767453836E-5,149.9920654,149.9920654,-56331.9453125,-56317.19140625,56.6391473890252,20.5810766248802,25.946213,0,0,0,40,4449,149.90045,-56324.568359375,,,,,,,,,,,,,0,,,,0,,,,,,149.9920654,,,,
,23172318.86,149.9916992,-51459.51171875,8.66698500432879E-5,2.75778075350484E-6,1,0.999253354069792,40.0298881530762,1.99669652943997,16.5299996733665,0.00102994809666809,-8.88930981348242E-5,0.25,-2.29206839149979E-5,8.71309607540309E-5,-2.28979663796E-5,149.9915771,149.9918213,-51469.2890625,-51449.734375,56.6493085597752,20.5800052366457,25.186911,0,0,0,40,4449,149.90805,-51459.51171875,,,,,,,,,,,,,0,,,,0,,,,,,149.9916992,,,,
,23172417.215,149.9906158,-46545.51953125,7.28449787471147E-5,2.11639830725069E-6,1,0.999253354069792,40.0298881530762,1.9967133563489,16.5299996733665,0.000868320390220073,-8.99515446720327E-5,0.25,-2.06062171405483E-5,7.32346564280435E-5,-2.05933262234046E-5,149.9906158,149.9906158,-46553.06640625,-46537.97265625,56.8869236296214,20.5785469070411,25.946213,0,0,0,40,4449,149.9165,-46545.51953125,,,,,,,,,,,,,0,,,,0.00245,,,,,,149.9906158,,,,
,23172515.635,149.9893036,-41625.201171875,5.35395697743409E-5,2.15677164509875E-6,1,0.999253354069792,40.0298881530762,1.99670687861691,16.5299996733665,0.000640920917361344,-8.17561631551917E-5,0.25,-1.65224843672634E-5,5.38281564086314E-5,-1.65194918914943E-5,149.9893036,149.9893036,-41630.15625,-41620.24609375,57.0495023616214,20.578265923218,25.946213,0,0,0,40,4449,149.927,-41625.201171875,,,,,,,,,,,,,0,,,,0,,,,,,149.9893036,,,,
,23172613.76,149.9888153,-36723.21484375,3.56418955830618E-5,1.72690331030142E-6,1,0.999253354069792,40.0298881530762,1.99667012868119,16.5299996733665,0.000432211009185913,-8.62868340053633E-5,0.25,-1.38040996980426E-5,3.58384435493262E-5,-1.38156839611072E-5,149.9888153,149.9888153,-36728.15625,-36718.2734375,57.0393411908714,20.5767124837692,25.946213,0,0,0,40,4449,149.93625,-36723.21484375,,,,,,,,,,,,,0,,,,-0.00245,,,,,,149.9888153,,,,
,23172711.805,149.9917755,-31823.6787109375,2.14430834176917E-5,1.55983651209311E-6,1,0.999253354069792,40.0298881530762,1.99663050886378,16.5299996733665,0.000271827526016011,-0.00011966848849639,0.25,-1.42696234343268E-5,2.15707668643799E-5,-1.43057316915526E-5,149.9917755,149.9917755,-31826.056640625,-31821.30078125,57.0002597649099,20.5806234166629,25.186911,0,0,0,40,4449,149.9432,-31823.6787109375,,,,,,,,,,,,,0,,,,-0.0049,,,,,,149.9917755,,,,
,23172811.375,149.9911804,-26846.9443359375,6.21517564621753E-6,2.00933016531163E-6,1,0.999253354069792,40.0298881530762,1.99675121091403,16.5299996733665,9.42789368307398E-5,-0.000123586859598662,0.25,-1.19613427615922E-5,6.26459180442948E-6,-1.20101400529358E-5,149.9911804,149.9911804,-26849.455078125,-26844.43359375,57.0315249056791,20.5776348676652,26.325863,0,0,0,40,4449,149.94925,-26846.9443359375,,,,,,,,,,,,,0,,,,0.0049,,,,,,149.9911804,,,,
,23172910.03,149.9903412,-21916.455078125,-9.95742587370172E-6,1.56154356470944E-6,1,0.999253354069792,40.0298881530762,1.99675660824092,16.5299996733665,-9.25747681752889E-5,-0.000137651078179954,0.25,-1.03820088735354E-5,-9.9897437848452E-6,-1.04487134078743E-5,149.9903412,149.9903412,-21925.94921875,-21906.9609375,56.7282530402175,20.5763636794195,25.946213,0,0,0,40,4449,149.9591,-21916.455078125,,,,,,,,,,,,,0,,,,0,,,,,,149.9903412,,,,
,23173004.085,149.9911346,-17214.3095703125,-2.41709849167502E-5,1.24657245836351E-6,1,0.999253354069792,40.0298881530762,1.99673525442471,16.5299996733665,-0.000262250934423133,-0.000118672245083413,0.25,-6.23536313089647E-6,-2.42795120334428E-5,-6.3044093909455E-6,149.9911346,149.9911346,-17224.240234375,-17204.37890625,56.9299131981791,20.5704481752315,25.566563,0,0,0,40,4449,149.9696,-17214.3095703125,,,,,,,,,,,,,0,,,,0.00245,,,,,,149.9911346,,,,
,23173099.235,149.9930115,-12459.3359375,-3.65002378943621E-5,1.22907685643319E-6,1,0.999253354069792,40.0298881530762,1.99669751823128,16.5299996733665,-0.000404492542016258,-0.000130529613994589,0.25,-5.13132291430059E-6,-3.66708914550055E-5,-5.21473093516095E-6,149.9930115,149.9930115,-12466.7080078125,-12451.9638671875,56.8681645451599,20.571758850937,25.946213,0,0,0,40,4449,149.97285,-12459.3359375,,,,,,,,,,,,,0,,,,0,,,,,,149.9930115,,,,
,23173196.24,149.9933472,-7611.38940429688,-4.74389493251746E-5,6.66602225718891E-7,1,0.999253354069792,40.0298881530762,1.99673785401241,16.5299996733665,-0.000532265403862461,-0.000132102591524116,0.25,-3.36373511980201E-6,-4.76659709645404E-5,-3.45611553149768E-6,149.9933472,149.9933472,-7618.91845703125,-7603.8603515625,56.5086154263137,20.5731001385955,25.566563,0,0,0,40,4449,149.98085,-7611.38940429688,,,,,,,,,,,,,0,,,,-0.00245,,,,,,149.9933472,,,,
,23173293.79,149.9927063,-2735.53857421875,-5.19712257809339E-5,3.9465597738449E-7,1,0.999253354069792,40.0298881530762,1.99683621869389,16.5299996733665,-0.000587863351603516,-0.000117644468098279,0.25,-1.30080679152215E-6,-5.22237113961328E-5,-1.39049931550631E-6,149.9927063,149.9927063,-2745.419921875,-2725.6572265625,56.8494054606983,20.5693573214572,25.566563,0,0,0,40,4449,149.9886,-2735.53857421875,,,,,,,,,,,,,0,,,,0.00245,,,,,,149.9927063,,,,
,23173387.5,149.9937286,1944.33331298828,-3.27071894267862E-5,3.88016810326277E-7,1,0.999253354069792,40.0298881530762,1.99688282361576,16.5299996733665,-0.000373809199974829,-5.20015476135033E-5,0.25,1.12111148049426E-6,-3.28691933788648E-5,1.07415369493775E-6,149.9937286,149.9937286,1939.31213378906,1949.3544921875,56.5000175126021,20.5735044352971,25.186911,0,0,0,40,4449,149.9936,1944.33331298828,,,,,,,,,,,,,0,,,,-0.0049,,,,,,149.9937286,,,,
,23173485.16,149.9982605,6827.05297851562,-3.59571423294393E-6,5.20548096718069E-7,1,0.999253354069792,40.0298881530762,1.99689366993385,16.5299996733665,-4.55118579558367E-5,1.96327594780735E-5,0.25,2.35449066791412E-6,-3.61709692333351E-6,2.36027025936369E-6,149.9982605,149.9982605,6817.05859375,6837.04736328125,57.0393411908714,20.5712284736237,25.946213,0,0,0,40,4449,149.99205,6827.05297851562,,,,,,,,,,,,,0,,,,0,,,,,,149.9982605,,,,
,23173581.525,150.0029449,11645.5068359375,2.19793680565965E-5,1.37616959224827E-6,1,0.999253354069792,40.0298881530762,1.99684942027034,16.5299996733665,0.000240613853167841,9.56963013006076E-5,0.25,4.59415677220727E-6,2.20797198229265E-5,4.65175941270924E-6,150.0029449,150.0029449,11640.3828125,11650.630859375,56.8494054606983,20.5678743842932,25.946213,0,0,0,40,4449,149.99205,11645.5068359375,,,,,,,,,,,,,0,,,,0,,,,,,150.0029449,,,,
,23173677.305,150.0075378,16433.0322265625,2.36367074214928E-5,1.24897046139033E-6,1,0.999253354069792,40.0298881530762,1.99695354919089,16.5299996733665,0.000256261982481421,0.00011731658806393,0.25,6.20802361239445E-6,2.37426428293241E-5,6.27609393339223E-6,150.0075378,150.0075378,16428.107421875,16437.95703125,56.851750346256,20.5690895282888,25.566563,0,0,0,40,4449,149.97945,16433.0322265625,,,,,,,,,,,,,0,,,,-0.00245,,,,,,150.0075378,,,,
,23173773.915,150.0106659,21260.0869140625,1.23044922596614E-5,1.91016685401807E-6,1,0.999253354069792,40.0298881530762,1.99710427732548,16.5299996733665,0.000124766541244476,0.000110700335599559,0.25,7.59920100852821E-6,1.23527233592271E-5,7.6559931205873E-6,150.0106659,150.0106659,21249.931640625,21270.2421875,57.0252718775253,20.569992790222,26.325863,0,0,0,40,4449,149.97085,21260.0869140625,,,,,,,,,,,,,0,,,,0.00245,,,,,,150.0106659,,,,
,23173870.2,150.0122833,26072.9052734375,-9.0563086898743E-7,1.80135165283909E-6,1,0.999253354069792,40.0298881530762,1.99693755091917,16.5299996733665,-2.79809283292156E-5,9.97662884638102E-5,0.25,8.93885260860287E-6,-9.24233133567064E-7,8.9812349193386E-6,150.0122833,150.0122833,26062.896484375,26082.9140625,56.7251265261406,20.567924702824,25.946213,0,0,0,40,4449,149.96285,26072.9052734375,,,,,,,,,,,,,0,,,,-0.00245,,,,,,150.0122833,,,,
,23173968.77,150.0120392,30998.3330078125,-1.63747739055197E-5,1.54871844903007E-6,1,0.999253354069792,40.0298881530762,1.99697099815119,16.5299996733665,-0.000206068115196858,8.25364934396493E-5,0.25,1.01168781716058E-5,-1.64710413997592E-5,1.01406085810783E-5,150.0120392,150.0120392,30985.81640625,31010.849609375,56.5594212800637,20.5683792592763,25.946213,0,0,0,40,4449,149.94995,30998.3330078125,,,,,,,,,,,,,0,,,,-0.00245,,,,,,150.0120392,,,,
,23174066.08,150.0122375,35863.53125,-3.21370719229317E-5,1.76273328128348E-6,1,0.999253354069792,40.0298881530762,1.99697460656792,16.5299996733665,-0.000393426277069728,9.88242234311557E-5,0.25,1.42959960434186E-5,-3.23171891195715E-5,1.43154733020968E-5,150.0122375,150.0122375,35853.67578125,35873.38671875,56.5140868259483,20.5710985574267,25.946213,0,0,0,40,4449,149.93835,35863.53125,,,,,,,,,,,,,0,,,,0,,,,,,150.0122375,,,,
,23174164.63,150.012558,40788.53515625,-4.77910745343444E-5,1.85904032492452E-6,1,0.999253354069792,40.0298881530762,1.99700976425185,16.5299996733665,-0.000569770253846717,5.91065770935117E-5,0.25,1.35267240392034E-5,-4.80467293564812E-5,1.35180076528043E-5,150.012558,150.012558,40786.16015625,40790.91015625,57.0135474497368,20.5682961566913,25.946213,0,0,0,40,4449,149.92685,40788.53515625,,,,,,,,,,,,,0,,,,0,,,,,,150.012558,,,,
,23174263,150.0107727,45703.63671875,-6.11457959913869E-5,2.97156882712624E-6,1,0.999253354069792,40.0298881530762,1.99706372309697,16.5299996733665,-0.000729552068270294,7.87645655868819E-5,0.25,1.75826048404444E-5,-6.14733063268666E-5,1.75731209477826E-5,150.0107727,150.0107727,45698.45703125,45708.81640625,56.7290346687368,20.5698029336679,25.946213,0,0,0,40,4449,149.9166,45703.63671875,,,,,,,,,,,,,0,,,,0,,,,,,150.0107727,,,,
,23174361.455,150.0133209,50626.248046875,-8.20025969352497E-5,2.63421431708829E-6,1,0.999253354069792,40.0298881530762,1.99689821236345,16.5299996733665,-0.00097353502077422,7.81271687439938E-5,0.25,2.11594986006729E-5,-8.24380076387501E-5,2.11353296234105E-5,150.0133209,150.0133209,50616.1640625,50636.33203125,56.7556100383906,20.5697456261512,26.325863,0,0,0,40,4449,149.907,50626.248046875,,,,,,,,,,,,,0,,,,0,,,,,,150.0133209,,,,
,23174460.03,150.0117188,55553.873046875,-0.000100543735143727,3.08051479554041E-6,1,0.999253354069792,40.0298881530762,1.99686246953722,16.5299996733665,-0.00118388379617699,3.98050668633063E-5,0.25,2.10154582320573E-5,-0.000101069908849346,2.09621656494848E-5,150.0117188,150.0117188,55543.7421875,55564.00390625,56.7235632691022,20.5674215285276,25.946213,0,0,0,40,4449,149.896,55553.873046875,,,,,,,,,,,,,0,,,,0,,,,,,150.0117188,,,,
,23174555.615,150.01254275,60331.373046875,-0.000113269942727316,2.63380698195902E-6,1,0.999253354069792,40.0298881530762,1.99697824406564,16.5299996733665,-0.00133034216126044,2.49559295420831E-5,0.25,2.19243105555273E-5,-0.000113860000151727,2.18562487637077E-5,150.0118561,150.0132294,60321.3359375,60341.41015625,57.0307432771599,20.5706465784104,25.566563,0,0,0,40,4449,149.8826,60331.373046875,,,,,,,,,,,,,0,,,,0,,,,,,150.01254275,,,,
,23174653.875,150.0112762,65242.041015625,-0.000135761803972126,3.10789455777406E-6,1,0.999253354069792,40.0298881530762,1.99690533337996,16.5299996733665,-0.00159012870753043,5.0922229230062E-6,0.25,2.40926644279364E-5,-0.000136465668700981,2.400108311693E-5,150.0112762,150.0112762,65234.328125,65249.75390625,56.9275683126214,20.568664296671,25.946213,0,0,0,40,4449,149.87495,65242.041015625,,,,,,,,,,,,,0,,,,0.00245,,,,,,150.0112762,,,,
,23174752.36,150.0108643,70164.46484375,-0.000149111605836677,2.77008703726103E-6,1,0.999253354069792,40.0298881530762,1.99705248698872,16.5299996733665,-0.00174799915084284,1.35512140522369E-5,0.25,2.71613448361285E-5,-0.000149885789831001,2.70649890312723E-5,150.0108643,150.0108643,70157.1328125,70171.796875,57.1737812961791,20.5716499793128,26.325863,0,0,0,40,4449,149.8643,70164.46484375,,,,,,,,,,,,,0,,,,-0.00245,,,,,,150.0108643,,,,
,23174852.51,150.0115662,75169.90234375,-0.000167367096092038,3.15415976581164E-6,1,0.999253354069792,40.0298881530762,1.99708547675915,16.5299996733665,-0.00195780859004368,-9.05827166536479E-6,0.25,2.83498865044991E-5,-0.000168232804039055,2.82321584976826E-5,150.0115662,150.0115662,75164.8203125,75174.984375,57.078422616833,20.5708235231245,25.946213,0,0,0,40,4449,149.8562,75169.90234375,,,,,,,,,,,,,0,,,,-0.0049,,,,,,150.0115662,,,,
,23174950.495,150.0115204,80067.87890625,-0.000186734410216235,4.05483565856013E-6,1,0.999253354069792,40.0298881530762,1.99698958691809,16.5299996733665,-0.00217721154704619,-5.05908562395598E-5,0.25,2.80663087347035E-5,-0.000187694881368843,2.7918438123847E-5,150.0115204,150.0115204,80062.8671875,80072.890625,56.5836517641598,20.5689243655226,25.946213,0,0,0,40,4449,149.8419,80067.87890625,,,,,,,,,,,,,0,,,,0.00245,,,,,,150.0115204,,,,
,23175047.22,150.009964,84904.3046875,-0.000201841952507645,2.97695874382006E-6,1,0.999253354069792,40.0298881530762,1.99691477868546,16.5299996733665,-0.00235290429425962,-5.67999701211233E-5,0.25,3.0149488213101E-5,-0.000202879915551296,2.99898213914542E-5,150.0098114,150.0101166,84896.8125,84911.796875,56.5789619930445,20.5718396080987,25.566563,0,0,0,40,4449,149.8364,84904.3046875,,,,,,,,,,,,,0,,,,0,,,,,,150.009964,,,,
,23175139.83,150.0096283,89534.45703125,-0.000219980137909675,4.10813032762946E-6,1,0.999253354069792,40.0298881530762,1.99682215578082,16.5299996733665,-0.00255432068040281,-0.000118814873318217,0.25,2.78482430828583E-5,-0.000221103825625173,2.76507142741077E-5,150.0096283,150.0096283,89529.46875,89539.4453125,56.546915223756,20.5718451448365,25.946213,0,0,0,40,4449,149.8238,89534.45703125,,,,,,,,,,,,,0,,,,0.00245,,,,,,150.0096283,,,,
,23175253.265,150.0034943,85736.6640625,-0.000208219048130514,3.07868330018701E-6,1,0.999253354069792,40.0298881530762,1.99686515162467,16.5299996733665,-0.00242945292445395,-4.55758719875749E-5,0.25,3.22476394505222E-5,-0.000209291598720877,3.20887236357397E-5,150.0034943,150.0034943,85729.328125,85744,57.2183341217753,20.5727083252858,25.946213,0,0,0,40,4449,149.8241,85736.6640625,,,,,,,,,,,,,0,,,,0,,,,,,150.0034943,,,,
,23175348.955,149.9997253,80955.828125,-0.00018875745377829,3.0664482976387E-6,1,0.999253354069792,40.0298881530762,1.9967472985693,16.5299996733665,-0.00220386884231441,-3.20463877637446E-5,0.25,3.00502885269047E-5,-0.000189730971367595,2.99092269606269E-5,149.9997253,149.9997253,80945.828125,80965.828125,57.2378748347561,20.5736469465831,25.566563,0,0,0,40,4449,149.82645,80955.828125,,,,,,,,,,,,,0,,,,-0.00245,,,,,,149.9997253,,,,
,23175447.43,149.9954681,76031.62109375,-0.000175608596136501,2.76696299075689E-6,1,0.999253354069792,40.0298881530762,1.9966882886458,16.5299996733665,-0.00204785444747534,-4.37930848719176E-5,0.25,2.67273552644291E-5,-0.000176512383555106,2.65891124682276E-5,149.9954681,149.9954681,76026.7734375,76036.46875,56.8025077495445,20.572464775103,26.325863,0,0,0,40,4449,149.8286,76031.62109375,,,,,,,,,,,,,0,,,,-0.0049,,,,,,149.9954681,,,,
,23175546.155,149.991745,71096.125,-0.000152541931179666,2.58755139307099E-6,1,0.999253354069792,40.0298881530762,1.99665606314719,16.5299996733665,-0.00178410308258258,-7.79354172196856E-6,0.25,2.58799625699155E-5,-0.000153331074709838,2.57721496160367E-5,149.991745,149.991745,71088.625,71103.625,56.6211699330829,20.5707310115728,25.566563,0,0,0,40,4449,149.8417,71096.125,,,,,,,,,,,,,0,,,,-0.0049,,,,,,149.991745,,,,
,23175643.34,149.9911499,66239.859375,-0.000139904134590291,2.6230233832347E-6,1,0.999253354069792,40.0298881530762,1.99666614765083,16.5299996733665,-0.00163764519288394,5.68786342036776E-7,0.25,2.44158687757196E-5,-0.000140628921593458,2.43195830262477E-5,149.9907532,149.9915466,66224.703125,66255.015625,56.9588334533906,20.5711613394448,25.946213,0,0,0,40,4449,149.848,66239.859375,,,,,,,,,,,,,0,,,,-0.00245,,,,,,149.9911499,,,,
,23175741.94,149.9912109,61309.599609375,-0.000121722641647749,2.56773069277085E-6,1,0.999253354069792,40.0298881530762,1.99665741457466,16.5299996733665,-0.00143208591807404,4.22370385519079E-5,0.25,2.49179455563014E-5,-0.000122358911234619,2.48515709342511E-5,149.9912109,149.9912109,61302.00390625,61317.1953125,56.8478422036599,20.5733947014892,25.946213,0,0,0,40,4449,149.8583,61309.599609375,,,,,,,,,,,,,0,,,,-0.0049,,,,,,149.9912109,,,,
,23175841.51,149.9894104,56334.443359375,-0.00010285404478052,2.52992473741345E-6,1,0.999253354069792,40.0298881530762,1.99651145673487,16.5299996733665,-0.00121022728793287,3.6937623051535E-5,0.25,2.11659633864819E-5,-0.000103391856738109,2.11098680179904E-5,149.9894104,149.9894104,56329.5234375,56339.36328125,56.7915649502752,20.5757087092667,25.946213,0,0,0,40,4449,149.8654,56334.443359375,,,,,,,,,,,,,0,,,,-0.0049,,,,,,149.9894104,,,,
,23175939.08,149.9909363,51456.837890625,-8.07723444605754E-5,2.51694528852231E-6,1,0.999253354069792,40.0298881530762,1.99649091130764,16.5299996733665,-0.000949931597777808,2.63490327867005E-5,0.25,1.63882530580752E-5,-8.11943222462372E-5,1.63426363980044E-5,149.9909363,149.9909363,51441.85546875,51471.8203125,56.5906864208329,20.5762406549675,25.946213,0,0,0,40,4449,149.8759,51456.837890625,,,,,,,,,,,,,0,,,,-0.0049,,,,,,149.9909363,,,,
,23176038.74,149.9935303,46476.990234375,-6.39059272358058E-5,1.96218795424345E-6,1,0.999253354069792,40.0298881530762,1.99649651975278,16.5299996733665,-0.000759290437591427,6.51467050652415E-5,0.25,1.68663848153004E-5,-6.42458873430209E-5,1.6849092818461E-5,149.9935303,149.9935303,46464.796875,46489.18359375,56.5492601093137,20.574420743778,26.325863,0,0,0,40,4449,149.8826,46476.990234375,,,,,,,,,,,,,0,,,,0,,,,,,149.9935303,,,,
,23176135.115,149.9930267,41659.14453125,-5.36444674781513E-5,2.15144068713222E-6,1,0.999253354069792,40.0298881530762,1.9966057503934,16.5299996733665,-0.000641343596434446,7.73082726399316E-5,0.25,1.61495892510862E-5,-5.3932980271337E-5,1.61445689376148E-5,149.9930267,149.9930267,41646.59375,41671.6953125,56.2975757261213,20.5796752067008,25.566563,0,0,0,40,4449,149.887,41659.14453125,,,,,,,,,,,,,0,,,,-0.00245,,,,,,149.9930267,,,,
,23176233.03,149.9907684,36764.37890625,-3.3465851708837E-5,1.74565749694274E-6,1,0.999253354069792,40.0298881530762,1.99643883354954,16.5299996733665,-0.000404521186168929,7.37924532553574E-5,0.25,1.23259433396208E-5,-3.36494003629659E-5,1.23336833171032E-5,149.9907684,149.9907684,36754.44140625,36774.31640625,56.973684395256,20.5773115033484,25.946213,0,0,0,40,4449,149.89665,36764.37890625,,,,,,,,,,,,,0,,,,0.00245,,,,,,149.9907684,,,,
,23176330.96,149.9892426,31870.0048828125,-1.77846394424492E-5,1.66471976397308E-6,1,0.999253354069792,40.0298881530762,1.99654330085883,16.5299996733665,-0.000224710101124985,9.50505310551929E-5,0.25,1.14655963305974E-5,-1.78899602598373E-5,1.14937228586906E-5,149.9892426,149.9892426,31862.58203125,31877.427734375,57.1534589546791,20.5811794427613,25.946213,0,0,0,40,4449,149.90645,31870.0048828125,,,,,,,,,,,,,0,,,,0,,,,,,149.9892426,,,,
,23176428.13,149.9886932,27014.439453125,-3.68228034814454E-6,1.50182022070491E-6,1,0.999253354069792,40.0298881530762,1.99646853309453,16.5299996733665,-6.06113687351205E-5,0.000100546386536765,0.25,9.49318606744135E-6,-3.71537268626744E-6,9.53389354560064E-6,149.9886932,149.9886932,27005.005859375,27023.873046875,56.0935706826021,20.5813821925182,25.946213,0,0,0,40,4449,149.91615,27014.439453125,,,,,,,,,,,,,0,,,,0.00245,,,,,,149.9886932,,,,
,23176525.88,149.9901428,22128.9853515625,1.23467095545146E-5,1.39984801210932E-6,1,0.999253354069792,40.0298881530762,1.99646272998585,16.5299996733665,0.000123548091425834,0.000120277934795336,0.25,8.43800950298211E-6,1.23938226219689E-5,8.49898401908269E-6,149.9901428,149.9901428,22121.224609375,22136.74609375,56.760299809506,20.5809970671138,25.566563,0,0,0,40,4449,149.92285,22128.9853515625,,,,,,,,,,,,,0,,,,0,,,,,,149.9901428,,,,
,23176623.13,149.9895172,17267.0869140625,2.58874386270232E-5,9.14988751243159E-7,1,0.999253354069792,40.0298881530762,1.99636169114587,16.5299996733665,0.000282565002118772,0.000117082756988277,0.25,5.79825495649156E-6,2.60050689849726E-5,5.86790507229583E-6,149.9895172,149.9895172,17259.419921875,17274.75390625,56.3108634109483,20.5793961892219,26.325863,0,0,0,40,4449,149.93345,17267.0869140625,,,,,,,,,,,,,0,,,,0,,,,,,149.9895172,,,,
,23176719.975,149.9906158,12427.1826171875,3.73472530953764E-5,1.30131880330577E-6,1,0.999253354069792,40.0298881530762,1.99661256794244,16.5299996733665,0.000415369635159247,0.00012490065620861,0.25,4.48869045631625E-6,3.75230790932429E-5,4.5703196603686E-6,149.9906158,149.9906158,12417.12890625,12437.236328125,56.9549253107945,20.5788142987832,25.566563,0,0,0,40,4449,149.94335,12427.1826171875,,,,,,,,,,,,,0,,,,-0.00245,,,,,,149.9906158,,,,
,23176817.005,149.9898224,7577.06762695313,4.75477819803412E-5,5.96393641638867E-7,1,0.999253354069792,40.0298881530762,1.99660543129392,16.5299996733665,0.000534890938669061,0.000124141927869246,0.25,2.64470185737233E-6,4.77764854470731E-5,2.73375736450042E-6,149.9898224,149.9898224,7569.74072265625,7584.39453125,56.5133051974291,20.5821031523628,26.325863,0,0,0,40,4449,149.9507,7577.06762695313,,,,,,,,,,,,,0,,,,-0.0049,,,,,,149.9898224,,,,
,23176913.975,149.9924164,2731.39538574219,5.20868373126049E-5,3.08905881695874E-7,1,0.999253354069792,40.0298881530762,1.99651806349822,16.5299996733665,0.000590257198573292,0.000111139410030483,0.25,7.09545278252295E-7,5.23408319859449E-5,7.96550693033768E-7,149.9924164,149.9924164,2721.26025390625,2741.53051757813,56.6555615879291,20.5843401470504,26.325863,0,0,0,40,4449,149.95955,2731.39538574219,,,,,,,,,,,,,0,,,,0.00245,,,,,,149.9924164,,,,
,23176970.25,149.9933929,-0.296863585710526,4.54418310218062E-5,2.9727877609427E-7,1,0.999253354069792,40.0298881530762,1.9965889767878,16.5299996733665,0.000517620041626025,8.17652892103491E-5,0.25,-7.19010796201305E-7,4.56655534846041E-5,-6.49594548968851E-7,149.9933929,149.9933929,-0.304475486278534,-0.289251685142517,56.5125235689098,20.5818090808334,25.946213,0,0,0,40,4417,149.95785,-0.296863585710526,,,,,,,,,,,,,0,,,,0,,,,,,149.9933929,,,,