File: data/doubleLayers/dl_2-5/ppms/data/DD205_5_HYST_100OE_10KREPEAT.DAT
[Header]
; VSM Data File (default extension .dat)
; Copyright (c) 2003-2013, Quantum Design, Inc. All rights reserved.
TITLE,
FILEOPENTIME,32872420.11,01/16/2019,7:16 pm
BYAPP,VSM,2.0,2.0
INFO,PPMS VSM Option Release 1.4.10 Build 1,APPNAME
INFO,Quantum Design Linear Motor Servo Controller,MOTOR_MODULE_NAME
INFO,3101-100 M1,MOTOR_HW_VERSION
INFO,MMC1014,MOTOR_SERIAL_NUMBER
INFO,SRV No X-over 01.03.11,MOTOR_SOFTWARE_VERSION
INFO,Quantum Design VSM Detection Module,VSM_MODULE_NAME
INFO,3101-150 F0,VSM_HW_VERSION
INFO,VSM707,VSM_SERIAL_NUMBER
INFO,VSM No X-over 01.02.05 May 20 2008 13:51:47,VSM_SOFTWARE_VERSION
INFO,704,PREAMP_SERIAL_NUMBER
INFO,822,COIL_SERIAL_NUMBER
INFO,0,MOMENT_UNITS
INFO,DL 2.5,SAMPLE_MATERIAL
INFO,CoFe2O4,SAMPLE_COMMENT
INFO,29.51,SAMPLE_MASS
INFO,,SAMPLE_VOLUME
INFO,,SAMPLE_MOLECULAR_WEIGHT
INFO,,SAMPLE_SIZE
INFO,,SAMPLE_SHAPE
DATATYPE,COMMENT,1
DATATYPE,TIME,2
STARTUPAXIS,X,2
STARTUPAXIS,Y1,5
[Data]
Comment,Time Stamp (sec),Temperature (K),Magnetic Field (Oe),Moment (emu),M. Std. Err. (emu),Transport Action,Averaging Time (sec),Frequency (Hz),Peak Amplitude (mm),Center Position (mm),Coil Signal' (mV),Coil Signal" (mV),Range (mV),M. Quad. Signal (emu),M. Raw' (emu),M. Raw" (emu),Min. Temperature (K),Max. Temperature (K),Min. Field (Oe),Max. Field (Oe),Mass (grams),Motor Lag (deg),Pressure (Torr),VSM Status (code),Motor Status (code),Measure Status (code),Measure Count,PPMS Status (code),System Temp. (K),System Field (Oe),Sample Position (deg),Bridge 1 Resistance (ohms),Bridge 1 Excitation (에),Bridge 2 Resistance (ohms),Bridge 2 Excitation (에),Bridge 3 Resistance (ohms),Bridge 3 Excitation (에),Bridge 4 Resistance (ohms),Bridge 4 Excitation (에),Signal 1 Vin (V),Signal 2 Vin (V),Digital Inputs (code),Drive 1 Iout (mA),Drive 1 Ipower (W),Drive 2 Iout (mA),Drive 2 Ipower (W),Pressure (),Map 20 (),Map 21 (),Map 22 (),Map 23 (),Map 24 (),Map 25 (),Map 26 (),Map 27 (),Map 28 (),Map 29 ()
,32872435.53,10.0016394,0.228356599807739,,,2,,,,21.8100001478195,,,,,,,10.0016394,10.0016394,0.228356599807739,0.228356599807739,,,11.899124,,,,-99999999,4369,9.9908,0.228356599807739,,,,,,,,,,,,,,,,,,,,,,,10.0016394,,,,
,32872586.405,9.997262,4516.39965820313,-1.28305150187336E-5,3.5450811425578E-7,1,0.999253354069792,40.0298881530762,1.99587021022769,21.8000002205372,-0.000142958999403621,-3.20615500746415E-5,0.25,-5.72690781693738E-7,-1.27570253847339E-5,-6.34891378791737E-7,9.997262,9.997262,4511.171875,4521.62744140625,56.0333852866213,20.50775086927,12.278775,0,0,0,40,4449,9.994,4516.39965820313,,,,,,,,,,,,,0,,,,0.0049,,,,,,9.997262,,,,
,32872679.07,9.9987774,9145.1474609375,-2.50532486072728E-5,5.90858799333247E-7,1,0.999253354069792,40.0298881530762,1.99583982496628,21.8000002205372,-0.000280934258170669,-5.30773434919992E-5,0.25,-2.60015846085332E-7,-2.49224913236492E-5,-3.94731948580961E-7,9.9987774,9.9987774,9137.7431640625,9152.5517578125,55.7988967308521,20.5093358714207,11.899124,0,0,0,40,4449,9.9948,9145.1474609375,,,,,,,,,,,,,0,,,,-0.0049,,,,,,9.9987774,,,,
,32872774.05,9.9998932,13892.6469726563,-3.59270542596821E-5,6.93426709572439E-7,1,0.999253354069792,40.0298881530762,1.9954769961679,21.8000002205372,-0.000401109674619018,-8.6484257082725E-5,0.25,-1.28177447200415E-6,-3.57484751053536E-5,-1.48327018554764E-6,9.9998932,9.9998932,13880.1552734375,13905.138671875,56.8337728903137,20.5149652008762,11.519473,0,0,0,40,4449,9.99445,13892.6469726563,,,,,,,,,,,,,0,,,,-0.0049,,,,,,9.9998932,,,,
,32872868.04,9.9999208,18593.125,-4.22287470389646E-5,6.86160629012081E-7,1,0.999253354069792,40.0298881530762,1.99569971982304,21.8000002205372,-0.000474087467083982,-8.84526979522554E-5,0.25,-3.13734578948363E-7,-4.20439220757779E-5,-5.70167666771461E-7,9.9999208,9.9999208,18583.30078125,18602.94921875,56.3671406643329,20.5143485045598,11.519473,0,0,0,40,4449,9.9935,18593.125,,,,,,,,,,,,,0,,,,-0.00245,,,,,,9.9999208,,,,
,32872964.125,9.9999857,23392.8271484375,-4.41259468581476E-5,1.20329209997848E-6,1,0.999253354069792,40.0298881530762,1.9955853307009,21.8000002205372,-0.000500074682440441,-6.74629726893434E-5,0.25,1.90875141244547E-6,-4.3967861480224E-5,1.61862705695936E-6,9.9999857,9.9999857,23380.51171875,23405.142578125,56.2584943001598,20.5160506288562,11.899124,0,0,0,40,4449,9.99445,23392.8271484375,,,,,,,,,,,,,0,,,,0.00245,,,,,,9.9999857,,,,
,32873059.375,10.0006695,28153.240234375,-4.21904670341403E-5,1.19917860234878E-6,1,0.999253354069792,40.0298881530762,1.99565644832979,21.8000002205372,-0.000473479586491834,-9.19365176359694E-5,0.25,-5.99026058573845E-7,-4.2044220489849E-5,-8.78520132592604E-7,10.0006695,10.0006695,28148.333984375,28158.146484375,56.8658196596022,20.5174152164342,11.899124,0,0,0,40,4449,9.9948,28153.240234375,,,,,,,,,,,,,0,,,,-0.0049,,,,,,10.0006695,,,,
,32873154.24,10.0009861,32896.109375,-4.71921605616715E-5,1.53101821502193E-6,1,0.999253354069792,40.0298881530762,1.99591168126642,21.8000002205372,-0.000530132853094707,-0.000101823353868901,0.25,-5.64002665323754E-7,-4.70526821607437E-5,-8.87845655009634E-7,10.0009861,10.0009861,32886.44921875,32905.76953125,56.2960124690829,20.5224159097385,11.519473,0,0,0,40,4449,9.99565,32896.109375,,,,,,,,,,,,,0,,,,0.00245,,,,,,10.0009861,,,,
,32873248.79,9.9990921,37623.21875,-5.58454758570969E-5,1.13129485869258E-6,1,0.999253354069792,40.0298881530762,1.99581877411591,21.8000002205372,-0.000627169880895766,-0.000123090050973056,0.25,-8.82971293961706E-7,-5.57067863554939E-5,-1.27624114245177E-6,9.9990921,9.9990921,37618.3125,37628.125,56.7985996069483,20.5266921545151,11.899124,0,0,0,40,4449,9.99385,37623.21875,,,,,,,,,,,,,0,,,,0,,,,,,9.9990921,,,,
,32873342.815,9.9987535,42320.86328125,-6.86283352659605E-5,1.73069051132671E-6,1,0.999253354069792,40.0298881530762,1.99550943636052,21.8000002205372,-0.000775026857135982,-0.000128928962773703,0.25,9.11738693152242E-7,-6.85062679405476E-5,4.14387906666678E-7,9.9987535,9.9987535,42316.06640625,42325.66015625,56.8157954343714,20.5222877472504,11.899124,0,0,0,40,4449,9.9961,42320.86328125,,,,,,,,,,,,,0,,,,0,,,,,,9.9987535,,,,
,32873434.245,9.9978466,46891.72265625,-8.34821454752307E-5,1.28880187812427E-6,1,0.999253354069792,40.0298881530762,1.99542419982469,21.8000002205372,-0.000935986147656748,-0.000196873213847699,0.25,-2.42896488306169E-6,-8.33476675466794E-5,-3.037047735949E-6,9.9978466,9.9978466,46884.359375,46899.0859375,56.9174071418714,20.5279242760154,11.139823,0,0,0,40,4449,9.9977,46891.72265625,,,,,,,,,,,,,0,,,,0.0049,,,,,,9.9978466,,,,
,32873529.85,9.9974813,51671.439453125,-9.80338122249509E-5,1.33406412478229E-6,1,0.999253354069792,40.0298881530762,1.99542075082508,21.8000002205372,-0.00110179106032004,-0.000219529543419529,0.25,-1.80166566334578E-6,-9.79312252453964E-5,-2.52511013200144E-6,9.9974813,9.9974813,51661.5625,51681.31640625,56.7337244398522,20.5249752347363,11.519473,0,0,0,40,4449,10.00105,51671.439453125,,,,,,,,,,,,,0,,,,-0.00245,,,,,,9.9974813,,,,
,32873625.19,9.9963751,56433.982421875,-0.000116158176397664,1.21448336018983E-6,1,0.999253354069792,40.0298881530762,1.9952087621634,21.8000002205372,-0.00131277686398924,-0.000222448891377808,0.25,1.21696566998858E-6,-0.000116116080384305,3.52849071993787E-7,9.9963751,9.9963751,56424.296875,56443.66796875,56.9174071418714,20.5219541135305,11.519473,0,0,0,40,4449,10.0046,56433.982421875,,,,,,,,,,,,,0,,,,0,,,,,,9.9963751,,,,
,32873722.655,9.9958291,61306.802734375,-0.000128686463191071,1.31455981568867E-6,1,0.999253354069792,40.0298881530762,1.99495692147817,21.8000002205372,-0.0014483375997728,-0.000282736418771954,0.25,-1.86012088970972E-6,-0.000128675471428411,-2.81797974312552E-6,9.9957895,9.9958687,61302.0078125,61311.59765625,57.115940785756,20.5222908201512,11.139823,0,0,0,40,4449,10.00685,61306.802734375,,,,,,,,,,,,,0,,,,0,,,,,,9.9958291,,,,
,32873819.67,9.996088,66154.8203125,-0.00014768617558717,1.51352768567219E-6,1,0.999253354069792,40.0298881530762,1.99499854186119,21.8000002205372,-0.00166416273910343,-0.000317838452141556,0.25,-1.53642201008451E-6,-0.000147742927749708,-2.63362315119967E-6,9.996088,9.996088,66150.0546875,66159.5859375,57.1378263842945,20.5190285531736,11.519473,0,0,0,40,4449,10.0112,66154.8203125,,,,,,,,,,,,,0,,,,0,,,,,,9.996088,,,,
,32873916.435,9.995182,70992.62890625,-0.000161983435468169,1.1777024948657E-6,1,0.999253354069792,40.0298881530762,1.99483552319752,21.8000002205372,-0.00182469592728553,-0.000355326701051165,0.25,-2.27690861789679E-6,-0.000162108845071669,-3.47478882325969E-6,9.995182,9.995182,70987.46875,70997.7890625,57.1995750373137,20.5199199831404,11.519473,0,0,0,40,4449,10.0144,70992.62890625,,,,,,,,,,,,,0,,,,-0.00245,,,,,,9.995182,,,,
,32874012.325,9.9951782,75783.328125,-0.000182306819594963,1.62346467633002E-6,1,0.999253354069792,40.0298881530762,1.99503461951626,21.8000002205372,-0.00205897831159568,-0.000375960805731298,0.25,-4.37558970746327E-7,-0.000182534807406027,-1.77295764479509E-6,9.9951782,9.9951782,75776.046875,75790.609375,56.2092517034482,20.5249119209497,11.519473,0,0,0,40,4449,10.01935,75783.328125,,,,,,,,,,,,,0,,,,0.00245,,,,,,9.9951782,,,,
,32874109.39,9.9956427,80636.88671875,-0.000201059949175342,1.60815286248389E-6,1,0.999253354069792,40.0298881530762,1.99471320875571,21.8000002205372,-0.00226874280550213,-0.00042876936591831,0.25,-1.74151862982505E-6,-0.000201377208946515,-3.20082887265777E-6,9.9956427,9.9956427,80634.15625,80639.6171875,56.8837971155445,20.5225968889758,11.519473,0,0,0,40,4449,10.0221,80636.88671875,,,,,,,,,,,,,0,,,,0.0049,,,,,,9.9956427,,,,
,32874204.78,9.9953413,85407.12109375,-0.000212159309856839,1.66490062210133E-6,1,0.999253354069792,40.0298881530762,1.99459905256545,21.8000002205372,-0.00239854863245188,-0.000431064023844672,0.25,4.50849356980865E-8,-0.000212580716576648,-1.47256731703241E-6,9.9953413,9.9953413,85401.890625,85412.3515625,57.1448610409676,20.5235264082153,11.899124,0,0,0,40,4449,10.0274,85407.12109375,,,,,,,,,,,,,0,,,,0.00245,,,,,,9.9953413,,,,
,32874295.665,9.9951324,89969.9609375,-0.000231543491037782,1.74309712199943E-6,1,0.999253354069792,40.0298881530762,1.99439185128815,21.8000002205372,-0.00261151081389645,-0.000507970115322209,0.25,-3.28311778551795E-6,-0.000232051454565412,-4.92478373666456E-6,9.9951324,9.9951324,89945.7265625,89994.1953125,57.1182856713137,20.5277477843299,11.519473,0,0,0,40,4449,10.0322,89969.9609375,,,,,,,,,,,,,0,,,,0,,,,,,9.9951324,,,,
,32874406.36,9.9986029,85576.609375,-0.000216711804324678,1.356248662348E-6,1,0.999253354069792,40.0298881530762,1.99444911603787,21.8000002205372,-0.00244437875243309,-0.00047080262794867,0.25,-2.6541418142749E-6,-0.000217125508282345,-4.20901094936049E-6,9.9986029,9.9986029,85574.2265625,85578.9921875,57.3723149400638,20.5287426281389,11.139823,0,0,0,40,4449,10.0333,85576.609375,,,,,,,,,,,,,0,,,,0,,,,,,9.9986029,,,,
,32874500.97,10.0012093,80848.25,-0.00019647103451823,1.53877693878729E-6,1,0.999253354069792,40.0298881530762,1.99410362538112,21.8000002205372,-0.00221530757505046,-0.000424657421663599,0.25,-2.21496672026007E-6,-0.000196780428009309,-3.64111380183211E-6,10.0012093,10.0012093,80830.7421875,80865.7578125,57.2027015513907,20.5329408130541,11.899124,0,0,0,40,4449,10.03055,80848.25,,,,,,,,,,,,,0,,,,-0.00245,,,,,,10.0012093,,,,
,32874599.515,10.0031033,75919.2109375,-0.000182686168670815,1.43449356764087E-6,1,0.999253354069792,40.0298881530762,1.99412497169621,21.8000002205372,-0.0020569546477454,-0.000406742271671864,0.25,-3.10918054469881E-6,-0.000182897042117003,-4.45041746098808E-6,10.0031033,10.0031033,75911.6796875,75926.7421875,56.4507749158906,20.5325081054155,11.899124,0,0,0,40,4449,10.0272,75919.2109375,,,,,,,,,,,,,0,,,,-0.00245,,,,,,10.0031033,,,,
,32874696.575,10.0027905,71067.9609375,-0.000165831418382065,1.36928764319188E-6,1,0.999253354069792,40.0298881530762,1.99412965389171,21.8000002205372,-0.00187037408870113,-0.000347269193812457,0.25,-8.8043313194867E-7,-0.000165971561004564,-2.10536634871254E-6,10.0027905,10.0027905,71057.9140625,71078.0078125,57.1776894387753,20.536118916371,11.139823,0,0,0,40,4449,10.02445,71067.9609375,,,,,,,,,,,,,0,,,,0,,,,,,10.0027905,,,,
,32874793.485,10.0024137,66222.74609375,-0.000146879374921572,1.38892344425227E-6,1,0.999253354069792,40.0298881530762,1.99412199537718,21.8000002205372,-0.00165722826881284,-0.00030020806969694,0.25,-1.31224077081023E-7,-0.000146947067690506,-1.22172368033016E-6,10.0024137,10.0024137,66215.4609375,66230.03125,57.2402197203138,20.540530176277,11.519473,0,0,0,40,4449,10.0214,66222.74609375,,,,,,,,,,,,,0,,,,0,,,,,,10.0024137,,,,
,32874894.11,10.0027771,61194.138671875,-0.000130855325631817,9.22958159766044E-7,1,0.999253354069792,40.0298881530762,1.99413694891289,21.8000002205372,-0.00147368432293515,-0.000278898125434952,0.25,-1.13896626936314E-6,-0.00013084837887115,-2.11295650452423E-6,10.0027771,10.0027771,61181.62109375,61206.65625,56.6766655579483,20.5394511188177,11.519473,0,0,0,40,4449,10.0192,61194.138671875,,,,,,,,,,,,,0,,,,0.00245,,,,,,10.0027771,,,,
,32874996.065,10.0037518,56096.52734375,-0.000111701887777157,1.45961662418603E-6,1,0.999253354069792,40.0298881530762,1.99424277392661,21.8000002205372,-0.00125588845608593,-0.000246543702381274,0.25,-1.73324883667806E-6,-0.000111636163441303,-2.56269006695305E-6,10.0037518,10.0037518,56088.9296875,56104.125,57.1909771236022,20.5421285451104,11.139823,0,0,0,40,4449,10.01535,56096.52734375,,,,,,,,,,,,,0,,,,0.0049,,,,,,10.0037518,,,,
,32875094.605,10.0040073,51173.904296875,-9.58897058718623E-5,1.02175287566664E-6,1,0.999253354069792,40.0298881530762,1.99427595808626,21.8000002205372,-0.00107838034146937,-0.000207215154278526,0.25,-1.10750498321852E-6,-9.57894108307267E-5,-1.81510712671183E-6,10.0040073,10.0040073,51171.1484375,51176.66015625,57.217552493256,20.539304360421,11.139823,0,0,0,40,4449,10.0128,51173.904296875,,,,,,,,,,,,,0,,,,0.0049,,,,,,10.0040073,,,,
,32875193.055,10.0037651,46251.298828125,-7.72311126531778E-5,1.45067732893706E-6,1,0.999253354069792,40.0298881530762,1.99414614703336,21.8000002205372,-0.000866879354103258,-0.000173318695678143,0.25,-1.47650950791946E-6,-7.71072487031624E-5,-2.0390891309068E-6,10.0037651,10.0037651,46239,46263.59765625,56.7853119221214,20.5438364210978,11.519473,0,0,0,40,4449,10.00785,46251.298828125,,,,,,,,,,,,,0,,,,-0.00245,,,,,,10.0037651,,,,
,32875293.655,10.0033503,41223.818359375,-6.05846528923039E-5,1.22558061184167E-6,1,0.999253354069792,40.0298881530762,1.99428891171454,21.8000002205372,-0.000681000274870884,-0.000128789483539327,0.25,-5.33806481385273E-7,-6.046023630767E-5,-9.68485617675992E-7,10.0033503,10.0033503,41221.47265625,41226.1640625,57.3261988574291,20.5408637805292,11.139823,0,0,0,40,4449,10.0062,41223.818359375,,,,,,,,,,,,,0,,,,-0.0049,,,,,,10.0033503,,,,
,32875390.075,10.0026712,36403.80859375,-4.48085327950429E-5,1.20723183296712E-6,1,0.999253354069792,40.0298881530762,1.99415966604062,21.8000002205372,-0.000504940107528397,-8.65261161043335E-5,0.25,3.69067912559079E-7,-4.46990634727961E-5,5.28615425999968E-8,10.0026712,10.0026712,36393.765625,36413.8515625,57.0510656186599,20.5430379564305,11.899124,0,0,0,40,4449,10.00385,36403.80859375,,,,,,,,,,,,,0,,,,0,,,,,,10.0026712,,,,
,32875481.46,10.002656,31838.64453125,-2.93574779318715E-5,1.08312918168471E-6,1,0.999253354069792,40.0298881530762,1.99412181146848,21.8000002205372,-0.000323791043821366,-9.48789511369944E-5,0.25,-3.16166118928063E-6,-2.92481904555384E-5,-3.35332519298167E-6,10.002656,10.002656,31826.72265625,31850.56640625,57.5505262424484,20.5432589979423,11.519473,0,0,0,40,4449,10.00135,31838.64453125,,,,,,,,,,,,,0,,,,0.00245,,,,,,10.002656,,,,
,32875572.48,10.0016584,27286.1005859375,-1.26031378754133E-5,1.11328264491552E-6,1,0.999253354069792,40.0298881530762,1.99409550842506,21.8000002205372,-0.000134970401942623,-6.28246382524844E-5,0.25,-3.3270825392399E-6,-1.25374609273168E-5,-3.39908823426308E-6,10.0016584,10.0016584,27278.498046875,27293.703125,56.5719273363714,20.5456345041515,11.139823,0,0,0,40,4449,10.0002,27286.1005859375,,,,,,,,,,,,,0,,,,0,,,,,,10.0016584,,,,
,32875661.89,10.0010128,22820.5771484375,3.55164617364229E-6,8.79966775556239E-7,1,0.999253354069792,40.0298881530762,1.99401789439437,21.8000002205372,4.50465997182576E-5,-2.1524473183649E-5,0.25,-2.5519107016296E-6,3.55399834023504E-6,-2.51927731870759E-6,10.0010128,10.0010128,22815.55078125,22825.603515625,57.2425646058714,20.5540883987726,11.899124,0,0,0,40,4449,10,22820.5771484375,,,,,,,,,,,,,0,,,,-0.0049,,,,,,10.0010128,,,,
,32875749.92,10.0003471,18420.201171875,1.62844658576683E-5,8.03631114850472E-7,1,0.999253354069792,40.0298881530762,1.99389052401531,21.8000002205372,0.000177608089194233,6.23138928943775E-5,0.25,2.63498344694493E-6,1.61976074232479E-5,2.7227499557994E-6,10.0003471,10.0003471,18412.708984375,18427.693359375,56.9361662263329,20.5533718094862,11.519473,0,0,0,40,4449,10.00075,18420.201171875,,,,,,,,,,,,,0,,,,-0.00245,,,,,,10.0003471,,,,
,32875841.405,9.9996252,13845.7592773437,2.98770283646403E-5,7.41499820616261E-7,1,0.999253354069792,40.0298881530762,1.99392933545426,21.8000002205372,0.000336441057290154,5.43625855518255E-5,0.25,-4.929986874427E-7,2.97374042034778E-5,-3.18105501743537E-7,9.9996252,9.9996252,13840.89453125,13850.6240234375,56.4007506906598,20.5519750439631,11.139823,0,0,0,40,4449,10.001,13845.7592773437,,,,,,,,,,,,,0,,,,0,,,,,,9.9996252,,,,
,32875935.955,9.9985952,9123.271484375,4.43501695174996E-5,4.47543697931506E-7,1,0.999253354069792,40.0298881530762,1.99359174536921,21.8000002205372,0.000497890713850175,8.76501898583448E-5,0.25,-9.28348314956966E-8,4.41216254168577E-5,1.48428541119473E-7,9.9985952,9.9985952,9118.240234375,9128.302734375,56.6657227586791,20.5564377901793,11.139823,0,0,0,40,4449,10.0019,9123.271484375,,,,,,,,,,,,,0,,,,0,,,,,,9.9985952,,,,
,32876031.14,9.9987793,4364.67163085937,5.91995408816842E-5,3.89397547242038E-7,1,0.999253354069792,40.0298881530762,1.99361953884005,21.8000002205372,0.000664310784178278,0.000117297490406202,0.25,-7.31406320865681E-8,5.88737018500035E-5,2.28157057424258E-7,9.9987793,9.9987793,4354.736328125,4374.60693359375,56.9760292808137,20.5549673696851,11.139823,0,0,0,40,4449,10.00365,4364.67163085937,,,,,,,,,,,,,0,,,,0,,,,,,9.9987793,,,,
,32876128.08,10.0029631,-480.65185546875,7.1307357691759E-5,3.33731576385618E-7,1,0.999253354069792,40.0298881530762,1.99364235069284,21.8000002205372,0.000799208108702516,0.00014578200723742,0.25,3.32586025468933E-7,7.08972804008603E-5,6.75741837084126E-7,10.0029631,10.0029631,-488.149169921875,-473.154541015625,56.9322580837368,20.5556618815208,11.899124,0,0,0,40,4449,10.002,-480.65185546875,,,,,,,,,,,,,0,,,,0,,,,,,10.0029631,,,,
,32876224.76,9.998435,-5310.31225585937,8.26605479110695E-5,3.90255285509744E-7,1,0.999253354069792,40.0298881530762,1.99383100649943,21.8000002205372,0.000927907875664273,0.000162828493289463,0.25,-1.95149649602245E-7,8.22113095970193E-5,2.31597269137837E-7,9.998435,9.998435,-5312.8798828125,-5307.74462890625,57.2394380917945,20.5517667536646,11.139823,0,0,0,40,4449,10.0042,-5310.31225585937,,,,,,,,,,,,,0,,,,0,,,,,,9.998435,,,,
,32876320.005,9.9994764,-10071.4331054688,9.13989573407195E-5,5.27417404418882E-7,1,0.999253354069792,40.0298881530762,1.99365934240552,21.8000002205372,0.0010259257025284,0.000182130562481048,0.25,-6.61095709084774E-8,9.09342174588427E-5,4.3685621538249E-7,9.9994764,9.9994764,-10076.41015625,-10066.4560546875,56.8751992018329,20.5622515542865,10.760172,0,0,0,40,4449,10.0044,-10071.4331054688,,,,,,,,,,,,,0,,,,-0.0049,,,,,,9.9994764,,,,
,32876415.16,10.0001674,-14829.134765625,9.56367099477876E-5,4.68515214189597E-7,1,0.999253354069792,40.0298881530762,1.99371340011629,21.8000002205372,0.00107249138721655,0.000198899576647287,0.25,6.31795455198051E-7,9.51853515990585E-5,1.18786377249168E-6,10.0001221,10.0002127,-14864.103515625,-14794.166015625,57.1784710672945,20.5596234486243,11.519473,0,0,0,40,4449,10.0028,-14829.134765625,,,,,,,,,,,,,0,,,,0.00245,,,,,,10.0001674,,,,
,32876511.9,10.0007048,-19663.888671875,8.66715627037934E-5,6.18860195706844E-7,1,0.999253354069792,40.0298881530762,1.9937503645426,21.8000002205372,0.000974600675993737,0.000168116592266805,0.25,-5.44123540822934E-7,8.63084376149466E-5,-6.60670426665066E-9,10.0007048,10.0007048,-19671.310546875,-19656.466796875,57.3207274577945,20.5582316518106,11.139823,0,0,0,40,4449,10.0041,-19663.888671875,,,,,,,,,,,,,0,,,,0.00245,,,,,,10.0007048,,,,
,32876608.93,10.0004072,-24513.6953125,7.23508289060873E-5,1.10400762170875E-6,1,0.999253354069792,40.0298881530762,1.99364665135563,21.8000002205372,0.000819980591475714,0.00010661676490543,0.25,-3.4822705452158E-6,7.21023202195982E-5,-3.00085019260264E-6,10.0004072,10.0004072,-24518.634765625,-24508.755859375,56.8939582862945,20.5593769654968,11.139823,0,0,0,40,4449,10.0032,-24513.6953125,,,,,,,,,,,,,0,,,,0,,,,,,10.0004072,,,,
,32876703.895,9.999814,-29258.83203125,5.84588903836597E-5,1.3120137607067E-6,1,0.999253354069792,40.0298881530762,1.99395768781253,21.8000002205372,0.000662399347900245,8.93893887267782E-5,0.25,-2.54492281856912E-6,5.82856594041795E-5,-2.14330815050948E-6,9.999814,9.999814,-29291.35546875,-29226.30859375,57.0612267894099,20.5605375037986,11.139823,0,0,0,40,4449,10.00285,-29258.83203125,,,,,,,,,,,,,0,,,,-0.00245,,,,,,9.999814,,,,
,32876801.735,9.9997311,-34147.94140625,5.3586453935044E-5,1.008585766888E-6,1,0.999253354069792,40.0298881530762,1.99395399182257,21.8000002205372,0.000606360588527705,8.83729282456844E-5,0.25,-1.77635331253945E-6,5.34519456724316E-5,-1.39911540292526E-6,9.9997311,9.9997311,-34152.80859375,-34143.07421875,56.9580518248714,20.5547037460599,11.139823,0,0,0,40,4449,10.0043,-34147.94140625,,,,,,,,,,,,,0,,,,0,,,,,,9.9997311,,,,
,32876899.595,9.9981308,-39037.927734375,6.40712718465673E-5,9.98266415253443E-7,1,0.999253354069792,40.0298881530762,1.99415422301941,21.8000002205372,0.000724093363827286,0.000113292164916563,0.25,-1.46321756261555E-6,6.39393688724795E-5,-1.00335698002263E-6,9.9981308,9.9981308,-39040.54296875,-39035.3125,57.6224360662176,20.5542621128576,11.519473,0,0,0,40,4449,10.005,-39037.927734375,,,,,,,,,,,,,0,,,,0,,,,,,9.9981308,,,,
,32876994.87,9.9980392,-43802.595703125,7.51092967208064E-5,1.23986918648857E-6,1,0.999253354069792,40.0298881530762,1.99405695332712,21.8000002205372,0.000847010790400833,0.00014519111884679,0.25,-6.30859504922675E-7,7.49847560562388E-5,-8.45447927128082E-8,9.9980392,9.9980392,-43807.86328125,-43797.328125,56.7743691228522,20.5549351333942,11.139823,0,0,0,40,4449,10.00575,-43802.595703125,,,,,,,,,,,,,0,,,,0.00245,,,,,,9.9980392,,,,
,32877091.28,9.9968195,-48620.44140625,8.66222768466434E-5,1.43842874121201E-6,1,0.999253354069792,40.0298881530762,1.99385961181213,21.8000002205372,0.000975335563097115,0.000178088537275815,0.25,2.0318169296854E-7,8.65151063659483E-5,8.40006773860114E-7,9.9968195,9.9968195,-48630.390625,-48610.4921875,57.1401712698522,20.5582616023278,11.519473,0,0,0,40,4449,10.00895,-48620.44140625,,,,,,,,,,,,,0,,,,-0.0049,,,,,,9.9968195,,,,
,32877189.495,9.9973688,-53530.248046875,0.000105887765996489,1.07873189999145E-6,1,0.999253354069792,40.0298881530762,1.99387108283253,21.8000002205372,0.00119558874121496,0.000202641912529755,0.25,-1.10317128398424E-6,0.000105819176741278,-3.17218970380357E-7,9.9973688,9.9973688,-53532.7890625,-53527.70703125,56.7149653553906,20.5619594152815,10.760172,0,0,0,40,4449,10.0124,-53530.248046875,,,,,,,,,,,,,0,,,,0,,,,,,9.9973688,,,,
,32877287.43,9.9966431,-58422.673828125,0.000117826451192405,1.36794861172561E-6,1,0.999253354069792,40.0298881530762,1.99400475078899,21.8000002205372,0.00134338845168186,0.000157486549362183,0.25,-7.27185987988187E-6,0.000117851209637024,-6.39323934556966E-6,9.9966431,9.9966431,-58425.2578125,-58420.08984375,57.3652802833907,20.5545153532785,11.139823,0,0,0,40,4449,10.0142,-58422.673828125,,,,,,,,,,,,,0,,,,-0.0049,,,,,,9.9966431,,,,
,32877387.61,9.9960489,-63430.044921875,0.000139426358929872,1.15662232313868E-6,1,0.999253354069792,40.0298881530762,1.9941426204346,21.8000002205372,0.00157612125160631,0.000266250489776391,0.25,-1.53123443641235E-6,0.00013946803566648,-4.94513451196918E-7,9.9960489,9.9960489,-63432.4375,-63427.65234375,56.9549253107945,20.5607667918027,10.760172,0,0,0,40,4449,10.02015,-63430.044921875,,,,,,,,,,,,,0,,,,-0.0049,,,,,,9.9960489,,,,
,32877484.505,9.9951973,-68272.09765625,0.00015672915385195,1.04570607559376E-6,1,0.999253354069792,40.0298881530762,1.99411820504488,21.8000002205372,0.00176607376696626,0.000334834419262946,0.25,1.42177150597899E-6,0.000156819951132481,2.58387372911844E-6,9.9951296,9.995265,-68279.5234375,-68264.671875,56.9619599674676,20.5579406064704,11.139823,0,0,0,40,4449,10.02165,-68272.09765625,,,,,,,,,,,,,0,,,,0,,,,,,9.9951973,,,,
,32877583.25,9.9956608,-73208.92578125,0.000171897700340536,1.16451561164315E-6,1,0.999253354069792,40.0298881530762,1.99411787307333,21.8000002205372,0.00194215689442677,0.000343210629628807,0.25,-5.72757072346871E-7,0.000172084341537595,6.91257157250593E-7,9.9956608,9.9956608,-73221.4140625,-73196.4375,57.2402197203138,20.5620504861529,11.139823,0,0,0,40,4449,10.02825,-73208.92578125,,,,,,,,,,,,,0,,,,0.00245,,,,,,9.9956608,,,,
,32877677.735,9.995512,-77928.7421875,0.000189139750462981,1.55735937713025E-6,1,0.999253354069792,40.0298881530762,1.99394480880572,21.8000002205372,0.00213534323806246,0.000390187316460195,0.25,4.84579163456987E-7,0.000189407753487282,1.86397400780763E-6,9.995512,9.995512,-77933.8828125,-77923.6015625,56.7681160946983,20.5601751007602,10.760172,0,0,0,40,4449,10.03015,-77928.7421875,,,,,,,,,,,,,0,,,,-0.0049,,,,,,9.995512,,,,
,32877767.225,9.996397,-82401.1171875,0.000203120820316088,1.6729511363466E-6,1,0.999253354069792,40.0298881530762,1.99419863824116,21.8000002205372,0.00230201641424018,0.000375967348028769,0.25,-3.29104436007533E-6,0.000203504172102925,-1.83197301274695E-6,9.996397,9.996397,-82411.2109375,-82391.0234375,57.1675282680253,20.5603862341271,11.139823,0,0,0,40,4449,10.03315,-82401.1171875,,,,,,,,,,,,,0,,,,-0.0049,,,,,,9.996397,,,,
,32877852.175,9.9953938,-86646.0546875,0.000220498285945353,1.56385883524625E-6,1,0.999253354069792,40.0298881530762,1.99405118086038,21.8000002205372,0.00249236574462506,0.0004480272640588,0.25,-3.23791974420085E-8,0.000220955080391844,1.53938472802785E-6,9.9953938,9.9953938,-86658.53125,-86633.578125,57.0424677049483,20.5621108218568,11.139823,0,0,0,40,4449,10.03655,-86646.0546875,,,,,,,,,,,,,0,,,,0.00245,,,,,,9.9953938,,,,
,32877954.855,9.9967213,-89219.4140625,0.000233242715382595,1.22983516332835E-6,1,0.999253354069792,40.0298881530762,1.99411063621937,21.8000002205372,0.00263866572389596,0.000464486297297119,0.25,-8.64372728382706E-7,0.000233772308480819,7.8364278312481E-7,9.9967213,9.9967213,-89226.8203125,-89212.0078125,57.115940785756,20.5631637713555,11.139823,0,0,0,40,4449,10.04105,-89219.4140625,,,,,,,,,,,,,0,,,,0,,,,,,9.9967213,,,,
,32878038.15,9.9991293,-85057.6484375,0.000216581400735895,1.21114802100328E-6,1,0.999253354069792,40.0298881530762,1.99419480716836,21.8000002205372,0.00244607328428969,0.000450709095338602,0.25,9.04087461220351E-7,0.000216999485661045,2.45675046763536E-6,9.9991293,9.9991293,-85064.875,-85050.421875,57.1472059265253,20.5638569762651,11.139823,0,0,0,40,4449,10.03965,-85057.6484375,,,,,,,,,,,,,0,,,,0,,,,,,9.9991293,,,,
,32878126.565,10.0014591,-80640.8046875,0.000199927805018616,1.23613550627404E-6,1,0.999253354069792,40.0298881530762,1.99437640708997,21.8000002205372,0.00225683900218548,0.000419431103420973,0.25,1.12504623890715E-6,0.00020024772949488,2.57513045963494E-6,10.0014591,10.0014591,-80648.53125,-80633.078125,57.1221938139099,20.555297664825,11.139823,0,0,0,40,4449,10.03775,-80640.8046875,,,,,,,,,,,,,0,,,,0,,,,,,10.0014591,,,,
,32878216.235,10.0028324,-76158.03125,0.000186307358918001,1.24253685628057E-6,1,0.999253354069792,40.0298881530762,1.99416018496992,21.8100007623434,0.0021018617673962,0.000392280938558609,0.25,1.17595931630494E-6,0.000186540527674343,2.54060078305328E-6,10.0028324,10.0028324,-76170.640625,-76145.421875,57.3684067974676,20.5602007117312,11.519473,0,0,0,40,4449,10.0348,-76158.03125,,,,,,,,,,,,,0,,,,0.0049,,,,,,10.0028324,,,,
,32878307.135,10.0030136,-71615.4453125,0.000166801987540422,1.40567525049835E-6,1,0.999253354069792,40.0298881530762,1.99399712312178,21.8000002205372,0.00188453415471629,0.000331275312905298,0.25,-7.09549892710327E-7,0.00016696233995073,5.20098426244109E-7,10.0030136,10.0030136,-71627.96875,-71602.921875,57.200356665833,20.5664544441384,11.519473,0,0,0,40,4449,10.03255,-71615.4453125,,,,,,,,,,,,,0,,,,0,,,,,,10.0030136,,,,
,32878399.22,10.0036736,-67013.34375,0.000151060753693876,1.392433893888E-6,1,0.999253354069792,40.0298881530762,1.99414210929897,21.8000002205372,0.00170883758719465,0.00028493961221673,0.25,-1.97650051708026E-6,0.000151156541839792,-8.56894070100387E-7,10.0036736,10.0036736,-67020.8671875,-67005.8203125,57.2198973788137,20.5622977565883,11.519473,0,0,0,40,4449,10.02985,-67013.34375,,,,,,,,,,,,,0,,,,-0.00245,,,,,,10.0036736,,,,
,32878489.19,10.0036812,-62516.123046875,0.00013337042449708,1.29395869667233E-6,1,0.999253354069792,40.0298881530762,1.9939075331982,21.8000002205372,0.00150054242904904,0.000292501547105941,0.25,1.89175342900903E-6,0.000133374187169544,2.8843866214605E-6,10.0036812,10.0036812,-62523.46875,-62508.77734375,57.1659650109868,20.5708065834634,11.139823,0,0,0,40,4449,10.0259,-62516.123046875,,,,,,,,,,,,,0,,,,0,,,,,,10.0036812,,,,
,32878585.335,10.0040855,-57713.146484375,0.000117386456175576,1.32565733308741E-6,1,0.999253354069792,40.0298881530762,1.99358538332685,21.8000002205372,0.00132572791353376,0.000225007867109828,0.25,-1.19895326704237E-6,0.00011735816678398,-3.25264285825223E-7,10.0040855,10.0040855,-57715.9921875,-57710.30078125,56.9713395096983,20.5712348230566,10.760172,0,0,0,40,4449,10.0225,-57713.146484375,,,,,,,,,,,,,0,,,,-0.0049,,,,,,10.0040855,,,,
,32878683.275,10.003396,-52816.26953125,9.69507643510749E-5,1.22322273921576E-6,1,0.999253354069792,40.0298881530762,1.99349594421146,21.8000002205372,0.00109799284735267,0.000165588403924887,0.25,-2.77601885809904E-6,9.68941589375615E-5,-2.05556307365139E-6,10.003396,10.003396,-52828.95703125,-52803.58203125,56.8228300910445,20.5766222813539,11.139823,0,0,0,40,4449,10.0195,-52816.26953125,,,,,,,,,,,,,0,,,,0.00245,,,,,,10.003396,,,,
,32878783.425,10.0037909,-47811.3671875,8.404335670548E-5,1.52400536166119E-6,1,0.999253354069792,40.0298881530762,1.99335181455654,21.8000002205372,0.00095294794067525,0.000134103320633945,0.25,-3.23200266860583E-6,8.39575769364563E-5,-2.61081445910146E-6,10.0037909,10.0037909,-47816.44140625,-47806.29296875,57.0049495360253,20.5669984154203,10.760172,0,0,0,40,4449,10.0165,-47811.3671875,,,,,,,,,,,,,0,,,,0.00245,,,,,,10.0037909,,,,
,32878884.13,10.0030298,-42776.54296875,6.73201549788488E-5,9.57740199955504E-7,1,0.999253354069792,40.0298881530762,1.99325251979923,21.8000002205372,0.000758258279873295,0.000133066702822923,0.25,-2.97520686679244E-7,6.71993323342889E-5,1.90010169256166E-7,10.0030298,10.0030298,-42788.75390625,-42764.33203125,56.7970363499099,20.5732318294112,10.760172,0,0,0,40,4449,10.013,-42776.54296875,,,,,,,,,,,,,0,,,,0,,,,,,10.0030298,,,,
,32878983.125,10.0030212,-37831.9375,4.97435603307537E-5,1.15912375731647E-6,1,0.999253354069792,40.0298881530762,1.99342074895966,21.8000002205372,0.000556988547304784,0.000115218747727464,0.25,1.29294244047581E-6,4.96175316353637E-5,1.64242553381991E-6,10.0030212,10.0030212,-37842.0078125,-37821.8671875,57.0018230219483,20.5708936014929,10.760172,0,0,0,40,4449,10.011,-37831.9375,,,,,,,,,,,,,0,,,,0,,,,,,10.0030212,,,,
,32879082.845,10.0023203,-32847.349609375,3.44826935208963E-5,1.10145367910085E-6,1,0.999253354069792,40.0298881530762,1.99340582979344,21.8000002205372,0.000383414951832828,9.36760932143098E-5,0.25,2.13438252063203E-6,3.43687271703852E-5,2.36597868021562E-6,10.0023203,10.0023203,-32860.0390625,-32834.66015625,57.0862389020253,20.5712137336267,11.139823,0,0,0,40,4449,10.0094,-32847.349609375,,,,,,,,,,,,,0,,,,0.00245,,,,,,10.0023203,,,,
,32879182.395,10.001812,-27873.375,1.48197056116369E-5,9.21594455392497E-7,1,0.999253354069792,40.0298881530762,1.99370136194007,21.8000002205372,0.000174754076442702,-1.56655512568656E-5,0.25,-4.05330659329801E-6,1.47962947685238E-5,-3.94085321539823E-6,10.001812,10.001812,-27878.171875,-27868.578125,57.5505262424484,20.5667089999996,11.139823,0,0,0,40,4449,10.00775,-27873.375,,,,,,,,,,,,,0,,,,0,,,,,,10.001812,,,,
,32879282.21,10.0010748,-22882.845703125,-1.59470182016637E-6,6.08503466734768E-7,1,0.999253354069792,40.0298881530762,1.99324859556899,21.8000002205372,-1.39095253028224E-5,-2.55514946415259E-5,0.25,-1.98902249341049E-6,-1.57578013149657E-6,-1.99141339704828E-6,10.0010748,10.0010748,-22890.37109375,-22875.3203125,57.3176009437176,20.5728825395813,11.139823,0,0,0,40,4449,10.0077,-22882.845703125,,,,,,,,,,,,,0,,,,0,,,,,,10.0010748,,,,
,32879382.24,9.9999304,-17883.7216796875,-1.72436386904824E-5,5.20599385108592E-7,1,0.999253354069792,40.0298881530762,1.99293614575636,21.8000002205372,-0.000194320574726529,-3.04703361972232E-5,0.25,3.69747388991245E-7,-1.71700267267014E-5,2.63675066750482E-7,9.9999304,9.9999304,-17894.109375,-17873.333984375,57.1948852661984,20.5748246106903,11.139823,0,0,0,40,4449,10.00755,-17883.7216796875,,,,,,,,,,,,,0,,,,-0.00245,,,,,,9.9999304,,,,
,32879483.04,9.9995995,-12845.8203125,-3.19896419460699E-5,4.77279704892867E-7,1,0.999253354069792,40.0298881530762,1.99305083283143,21.8000002205372,-0.000357731206337031,-7.11526509642955E-5,0.25,-6.30704381009496E-7,-3.18307020524694E-5,-8.1007373624019E-7,9.9995995,9.9995995,-12855.884765625,-12835.755859375,56.9893169656406,20.5734076461258,11.139823,0,0,0,40,4449,10.00765,-12845.8203125,,,,,,,,,,,,,0,,,,-0.00245,,,,,,9.9995995,,,,
,32879578.44,9.9989719,-8078.01879882813,-4.70519486818839E-5,3.56344499382543E-7,1,0.999253354069792,40.0298881530762,1.99345925319152,21.8000002205372,-0.000525582194340514,-0.000107363736744052,0.25,-1.18737454010486E-6,-4.67987730470791E-5,-1.43296133052002E-6,9.9989719,9.9989719,-8083.11083984375,-8072.9267578125,57.1776894387753,20.5643045877166,11.139823,0,0,0,40,4449,10.00895,-8078.01879882813,,,,,,,,,,,,,0,,,,0,,,,,,9.9989719,,,,
,32879676.135,10.0004377,-3194.78820800781,-6.22020615081816E-5,3.39637693559728E-7,1,0.999253354069792,40.0298881530762,1.99341713971857,21.8000002205372,-0.000696061757962546,-0.00013347527010685,0.25,-8.41900136056638E-7,-6.18504897333506E-5,-1.14835483465855E-6,10.0004377,10.0004377,-3204.91723632812,-3184.6591796875,57.0698247031214,20.5741275065204,11.139823,0,0,0,40,4449,10.0082,-3194.78820800781,,,,,,,,,,,,,0,,,,0,,,,,,10.0004377,,,,
,32879774.18,10.0007048,1705.70104980469,-7.41993335064274E-5,2.94801050865239E-7,1,0.999253354069792,40.0298881530762,1.99331723059825,21.8000002205372,-0.000830447736152682,-0.000157831991643473,0.25,-8.89567762259331E-7,-7.37742852299104E-5,-1.24860290511186E-6,10.0007048,10.0007048,1700.60498046875,1710.79711914062,57.1628384969099,20.5675873419353,10.760172,0,0,0,40,4449,10.0074,1705.70104980469,,,,,,,,,,,,,0,,,,0,,,,,,10.0007048,,,,
,32879862.605,9.9988232,6125.93969726563,-8.56007059266066E-5,3.45111651743089E-7,1,0.999253354069792,40.0298881530762,1.99334413060086,21.8000002205372,-0.000959587998510487,-0.000175087074954109,0.25,-3.7194324732796E-7,-8.51373928356348E-5,-8.15803359235184E-7,9.9988232,9.9988232,6118.408203125,6133.47119140625,57.1034347294484,20.5640199244087,10.760172,0,0,0,40,4449,10.0088,6125.93969726563,,,,,,,,,,,,,0,,,,0,,,,,,9.9988232,,,,
,32879953.6,10.0003929,10671.8461914062,-9.52782378733397E-5,4.24154498398596E-7,1,0.999253354069792,40.0298881530762,1.9932986098763,21.8000002205372,-0.00106731346889205,-0.000201189177576214,0.25,-9.38449078441083E-7,-9.47928628612859E-5,-1.46190582352297E-6,10.0003929,10.0003929,10666.9140625,10676.7783203125,56.9697762526599,20.566346198792,11.139823,0,0,0,40,4449,10.0086,10671.8461914062,,,,,,,,,,,,,0,,,,0,,,,,,10.0003929,,,,
,32880043.38,10.0010481,15159.6748046875,-9.68442957125155E-5,5.52010445778434E-7,1,0.999253354069792,40.0298881530762,1.99352150763916,21.8000002205372,-0.0010871857583412,-0.000194572613941666,0.25,-2.9504006646908E-8,-9.63936940351389E-5,-5.97717468578471E-7,10.0010481,10.0010481,15149.27734375,15170.072265625,56.8736359447945,20.5624897796897,10.760172,0,0,0,40,4449,10.00635,15159.6748046875,,,,,,,,,,,,,0,,,,0,,,,,,10.0010481,,,,
,32880135.915,10.0002728,19784.6435546875,-8.67614262221452E-5,6.79867978041528E-7,1,0.999253354069792,40.0298881530762,1.99365621417505,21.8000002205372,-0.000973882881906105,-0.000177760593327108,0.25,-2.98250226213173E-7,-8.6393732158149E-5,-8.33445399021924E-7,10.0002728,10.0002728,19777.05859375,19792.228515625,57.291807202583,20.5680392870289,10.760172,0,0,0,40,4449,10.00735,19784.6435546875,,,,,,,,,,,,,0,,,,-0.00245,,,,,,10.0002728,,,,
,32880226.45,9.9999895,24309.814453125,-7.46879290887709E-5,6.43172553541026E-7,1,0.999253354069792,40.0298881530762,1.99324923276596,21.8000002205372,-0.000838669719570876,-0.000152538701801037,0.25,-1.89360772865717E-7,-7.44053513284569E-5,-6.71270356879519E-7,9.9999895,9.9999895,24304.86328125,24314.765625,57.0440309619868,20.5622508259339,11.139823,0,0,0,40,4449,10.0066,24309.814453125,,,,,,,,,,,,,0,,,,0.0049,,,,,,9.9999895,,,,
,32880318.42,10.0004196,28908.0185546875,-5.9895516345788E-5,8.08311604204103E-7,1,0.999253354069792,40.0298881530762,1.99339101986229,21.8000002205372,-0.000672447452573826,-0.000125095691358154,0.25,-3.77441899319486E-7,-5.96957543421588E-5,-7.78145846653202E-7,10.0004196,10.0004196,28902.888671875,28913.1484375,57.078422616833,20.5657393611762,10.760172,0,0,0,40,4449,10.00655,28908.0185546875,,,,,,,,,,,,,0,,,,0,,,,,,10.0004196,,,,
,32880419.275,9.99938775,33947.93359375,-5.88317569156502E-5,7.84785098771146E-7,1,0.999253354069792,40.0298881530762,1.99360815622414,21.8000002205372,-0.000659897450431696,-0.000128671265806221,0.25,-8.65900126653262E-7,-5.8663272432404E-5,-1.27184669464859E-6,9.9992933,9.9994822,33940.50390625,33955.36328125,57.1245386994676,20.5591296201633,10.760172,0,0,0,40,4449,10.00675,33947.93359375,,,,,,,,,,,,,0,,,,0.00245,,,,,,9.99938775,,,,
,32880516.845,9.9990978,38825.1328125,-6.42508452160084E-5,9.09724986984352E-7,1,0.999253354069792,40.0298881530762,1.99360091319375,21.8000002205372,-0.000725063572527056,-0.000118302779921809,0.25,1.04689036410748E-6,-6.41141197560046E-5,5.87090857990158E-7,9.9990978,9.9990978,38817.71484375,38832.55078125,57.2495992625445,20.5612183860531,10.760172,0,0,0,40,4449,10.0082,38825.1328125,,,,,,,,,,,,,0,,,,-0.00245,,,,,,9.9990978,,,,
,32880614.6,9.9986401,43707.7265625,-6.98921241323431E-5,1.38036047017002E-6,1,0.999253354069792,40.0298881530762,1.99370107302874,21.8000002205372,-0.000786320296505193,-0.000144600367984443,0.25,-2.58624561917273E-7,-6.97694016287605E-5,-7.65377305769733E-7,9.9986401,9.9986401,43700.171875,43715.28125,57.017455592333,20.5650582103913,10.760172,0,0,0,40,4449,10.0097,43707.7265625,,,,,,,,,,,,,0,,,,0,,,,,,9.9986401,,,,
,32880711.965,9.9970417,48575.697265625,-8.75727282476392E-5,1.43469912909829E-6,1,0.999253354069792,40.0298881530762,1.99357734515269,21.8000002205372,-0.00098896608708807,-0.000162996890520253,0.25,1.30574308694109E-6,-8.74750937123386E-5,6.60143718836893E-7,9.9970417,9.9970417,48568.42578125,48582.96875,57.0260535060445,20.5640851555663,11.139823,0,0,0,40,4449,10.0119,48575.697265625,,,,,,,,,,,,,0,,,,0,,,,,,9.9970417,,,,
,32880809.71,9.9964666,53460.830078125,-9.70425883717619E-5,1.17561634618418E-6,1,0.999253354069792,40.0298881530762,1.99367525847211,21.8000002205372,-0.0011120294195793,-9.45736737275661E-5,0.25,9.09719944683471E-6,-9.70390138015838E-5,8.37103448335397E-6,9.9964666,9.9964666,53455.8671875,53465.79296875,57.0182372208522,20.5705508775345,11.139823,0,0,0,40,4449,10.01585,53460.830078125,,,,,,,,,,,,,0,,,,-0.0049,,,,,,9.9964666,,,,
,32880912.51,9.9963865,58600.826171875,-0.000119674824787005,1.16975563039592E-6,1,0.999253354069792,40.0298881530762,1.99377154761433,21.8000002205372,-0.00135820471865031,-0.000193942415680867,0.25,4.37037860250377E-6,-0.000119679563255626,3.47875440365754E-6,9.9963865,9.9963865,58588.23828125,58613.4140625,56.7188734979868,20.5744137819653,10.760172,0,0,0,40,4449,10.01845,58600.826171875,,,,,,,,,,,,,0,,,,-0.0049,,,,,,9.9963865,,,,
,32881010.535,9.9957647,63498.94921875,-0.000135449363448757,1.76120173948793E-6,1,0.999253354069792,40.0298881530762,1.99394200635334,21.8000002205372,-0.00152807344727951,-0.00027501650022347,0.25,3.51835823308467E-8,-0.000135479896854056,-9.7224790493441E-7,9.9957647,9.9957647,63486.52734375,63511.37109375,57.3441763133715,20.5568193979889,10.760172,0,0,0,40,4449,10.0231,63498.94921875,,,,,,,,,,,,,0,,,,0,,,,,,9.9957647,,,,
,32881112.255,9.9959087,68584.171875,-0.000156868723431993,1.32672447881288E-6,1,0.999253354069792,40.0298881530762,1.99380419271709,21.8000002205372,-0.00176724584868192,-0.00033610369024002,0.25,-1.51320024011533E-6,-0.00015696315885621,-2.6760190832791E-6,9.9959087,9.9959087,68574.109375,68594.234375,56.7626446950637,20.5581125110214,10.760172,0,0,0,40,4449,10.02715,68584.171875,,,,,,,,,,,,,0,,,,0,,,,,,9.9959087,,,,
,32881210.385,9.9959145,73489.2890625,-0.00017477257058885,1.24322716264307E-6,1,0.999253354069792,40.0298881530762,1.99340229620391,21.8000002205372,-0.00196637405058232,-0.000391206954015147,0.25,-3.17169356010262E-6,-0.000174938719177576,-4.46028253128499E-6,9.9959145,9.9959145,73481.8984375,73496.6796875,56.7673344661791,20.5619014537476,10.760172,0,0,0,40,4449,10.03085,73489.2890625,,,,,,,,,,,,,0,,,,-0.00245,,,,,,9.9959145,,,,
,32881309.83,9.99506,78459.85546875,-0.000192684354257387,8.30588843485034E-7,1,0.999253354069792,40.0298881530762,1.99345290511043,21.8000002205372,-0.00217298638996564,-0.000408255291922045,0.25,-1.45465261372049E-6,-0.00019295824368856,-2.85968913492142E-6,9.99506,9.99506,78454.9296875,78464.78125,56.8462789466214,20.5608526394833,11.139823,0,0,0,40,4449,10.03545,78459.85546875,,,,,,,,,,,,,0,,,,0.00245,,,,,,9.99506,,,,
,32881407.22,9.9971323,83328.26171875,-0.000209751509942374,1.12947546762855E-6,1,0.999253354069792,40.0298881530762,1.99332228572747,21.8000002205372,-0.00236165134526479,-0.000469628270978767,0.25,-3.82221459016676E-6,-0.000210109422310374,-5.33829517209999E-6,9.9971323,9.9971323,83323.1328125,83333.390625,56.7688977232175,20.5635070744484,11.139823,0,0,0,40,4449,10.0364,83328.26171875,,,,,,,,,,,,,0,,,,0,,,,,,9.9971323,,,,
,32881492.475,9.9952898,87588.9921875,-0.00022591848185338,1.28538902003814E-6,1,0.999253354069792,40.0298881530762,1.99352116169742,21.8000002205372,-0.00254537985378884,-0.000502134424467267,0.25,-3.79237446948422E-6,-0.000226373853027597,-5.40649653761269E-6,9.9952898,9.9952898,87586.6015625,87591.3828125,57.4129596230638,20.5631851245463,10.760172,0,0,0,40,4449,10.0424,87588.9921875,,,,,,,,,,,,,0,,,,0,,,,,,9.9952898,,,,
,32881592.455,9.9973812,88335.79296875,-0.000226931774164309,1.10415051053015E-6,1,0.999253354069792,40.0298881530762,1.99349420999872,21.8000002205372,-0.0025616752585644,-0.000477815540624466,0.25,-1.46024529382828E-6,-0.000227417347800048,-3.07306946933427E-6,9.9973812,9.9973812,88328.390625,88343.1953125,56.8251749766022,20.5625444054385,11.139823,0,0,0,40,4449,10.0452,88335.79296875,,,,,,,,,,,,,0,,,,0,,,,,,9.9973812,,,,
,32881675.665,9.9998302,84176.859375,-0.000211706367899189,9.66338451628641E-7,1,0.999253354069792,40.0298881530762,1.99340522574104,21.8000002205372,-0.00239250196422358,-0.000426259916932352,0.25,3.69003437616123E-7,-0.000212110851826378,-1.14995352780117E-6,9.9998302,9.9998302,84169.6953125,84184.0234375,57.0620084179291,20.5635111752998,10.760172,0,0,0,40,4449,10.0429,84176.859375,,,,,,,,,,,,,0,,,,0,,,,,,9.9998302,,,,
,32881767.595,10.0022306,79580.57421875,-0.000195561982822077,1.12458031431978E-6,1,0.999253354069792,40.0298881530762,1.99355605650636,21.8000002205372,-0.00220416214826046,-0.000423144144726376,0.25,-2.25362911461747E-6,-0.000195850993426092,-3.67734498996866E-6,10.0022306,10.0022306,79575.65625,79585.4921875,57.027616763083,20.5631565286704,10.760172,0,0,0,40,4449,10.04,79580.57421875,,,,,,,,,,,,,0,,,,0.00245,,,,,,10.0022306,,,,
,32881858.47,10.0036116,75036.86328125,-0.000176308823594416,1.17852731053021E-6,1,0.999253354069792,40.0298881530762,1.99394884982009,21.8000002205372,-0.00199269493057456,-0.000348888747631665,0.25,8.62157563219199E-7,-0.000176528268903306,-4.29597870363894E-7,10.0036116,10.0036116,75027.109375,75046.6171875,57.1112510146407,20.5560853115435,10.760172,0,0,0,40,4449,10.03815,75036.86328125,,,,,,,,,,,,,0,,,,0,,,,,,10.0036116,,,,
,32881950.81,10.0034809,70421.234375,-0.000164683516854194,1.25136005468707E-6,1,0.999253354069792,40.0298881530762,1.99357496114542,21.8000002205372,-0.00185461936377183,-0.000357041176673002,0.25,-1.96176756528037E-6,-0.000164805701488902,-3.18020251650691E-6,10.0034809,10.0034809,70413.703125,70428.765625,57.0463758475445,20.5629563648329,10.760172,0,0,0,40,4449,10.0342,70421.234375,,,,,,,,,,,,,0,,,,-0.00245,,,,,,10.0034809,,,,
,32882042.655,10.0042305,65830.390625,-0.000147474721136538,1.26336216567978E-6,1,0.999253354069792,40.0298881530762,1.99347431914099,21.8000002205372,-0.00165903988053537,-0.000325356849940392,0.25,-2.26203757713526E-6,-0.00014752174587252,-3.35823492186102E-6,10.0042305,10.0042305,65825.515625,65835.265625,56.8220484625252,20.5637615509311,10.760172,0,0,0,40,4449,10.0305,65830.390625,,,,,,,,,,,,,0,,,,-0.00245,,,,,,10.0042305,,,,
,32882134.355,10.0041828,61247.11328125,-0.000130164116301046,1.2353767002426E-6,1,0.999253354069792,40.0298881530762,1.99372931498781,21.8000002205372,-0.00145910247412862,-0.000313536382689149,0.25,-4.33972577453637E-6,-0.000130133978189235,-5.30862258355432E-6,10.0041828,10.0041828,61242.09765625,61252.12890625,57.4348452216022,20.5605111537986,10.760172,0,0,0,40,4449,10.0278,61247.11328125,,,,,,,,,,,,,0,,,,0,,,,,,10.0041828,,,,
,32882225.655,10.0041265,56684.3984375,-0.000115127866970634,9.90728980057457E-7,1,0.999253354069792,40.0298881530762,1.9936826322267,21.8000002205372,-0.00130029449726827,-0.000219874623443568,0.25,1.24580871760131E-6,-0.000115089230554829,3.89235833628407E-7,10.0041265,10.0041265,56679.125,56689.671875,57.2284952925253,20.5578804736245,10.760172,0,0,0,40,4449,10.0247,56684.3984375,,,,,,,,,,,,,0,,,,0,,,,,,10.0041265,,,,
,32882318.275,10.0040836,52054.0234375,-9.39816516347622E-5,1.21420103202477E-6,1,0.999253354069792,40.0298881530762,1.99380071169116,21.8000002205372,-0.00105494235981086,-0.000213234734797709,0.25,-1.98723669014467E-6,-9.38849791687905E-5,-2.68101689099685E-6,10.0040836,10.0040836,52046.6328125,52061.4140625,57.0198004778906,20.5734588527409,11.139823,0,0,0,40,4449,10.0213,52054.0234375,,,,,,,,,,,,,0,,,,0,,,,,,10.0040836,,,,
,32882409.305,10.0039587,47503.77734375,-7.7931607479313E-5,1.60147230793109E-6,1,0.999253354069792,40.0298881530762,1.99400606593518,21.8000002205372,-0.000880819933143632,-0.000141466049559276,0.25,1.4802278037485E-6,-7.78384566136608E-5,9.06561671970983E-7,10.0039587,10.0039587,47498.5546875,47509,56.9525804252368,20.5683775536308,11.139823,0,0,0,40,4449,10.0162,47503.77734375,,,,,,,,,,,,,0,,,,0,,,,,,10.0039587,,,,
,32882501.515,10.0039625,42895.8984375,-6.32231791209367E-5,1.04723184330925E-6,1,0.999253354069792,40.0298881530762,1.99393597076357,21.8000002205372,-0.000716639493625731,-0.000101210662820111,0.25,2.39362020608547E-6,-6.31258032740389E-5,1.93173597422039E-6,10.0039625,10.0039625,42886.00390625,42905.79296875,56.8861420011022,20.5710926313898,10.760172,0,0,0,40,4449,10.0136,42895.8984375,,,,,,,,,,,,,0,,,,0.00245,,,,,,10.0039625,,,,
,32882594.485,10.0027866,38247.806640625,-4.70562182692247E-5,1.07215423658107E-6,1,0.999253354069792,40.0298881530762,1.99363203034313,21.8000002205372,-0.000530162183806238,-9.12913142820518E-5,0.25,3.52351315284579E-7,-4.69502444527205E-5,1.74027846527826E-8,10.0027866,10.0027866,38242.80859375,38252.8046875,57.5169162161215,20.5788519480677,10.760172,0,0,0,40,4449,10.01165,38247.806640625,,,,,,,,,,,,,0,,,,0,,,,,,10.0027866,,,,
,32882685.655,10.0028286,33693.4453125,-3.26392028713852E-5,9.12441266532351E-7,1,0.999253354069792,40.0298881530762,1.99364500860271,21.8000002205372,-0.000366854487621871,-6.71889492173019E-5,0.25,-1.07651771847451E-7,-3.25474370290964E-5,-3.33549693046887E-7,10.0028286,10.0028286,33690.73046875,33696.16015625,56.7423223535637,20.5758099597809,11.139823,0,0,0,40,4449,10.0081,33693.4453125,,,,,,,,,,,,,0,,,,0.0049,,,,,,10.0028286,,,,
,32882776.29,10.0021152,29163.01171875,-1.63704261720326E-5,9.68502053586693E-7,1,0.999253354069792,40.0298881530762,1.99392007777552,21.8000002205372,-0.000182574555950388,-4.12622004796694E-5,0.25,-7.31080586107534E-7,-1.63120411477595E-5,-8.38759734491837E-7,10.0021152,10.0021152,29157.94921875,29168.07421875,57.5896076684099,20.5701682173594,10.760172,0,0,0,40,4449,10.0073,29163.01171875,,,,,,,,,,,,,0,,,,-0.0049,,,,,,10.0021152,,,,
,32882869.415,10.0012846,24507.5791015625,-8.82854112681484E-7,6.97782361373509E-7,1,0.999253354069792,40.0298881530762,1.99382420006846,21.8000002205372,-1.81571403887027E-5,4.41628133318881E-5,0.25,4.08826252009081E-6,-9.06010651073689E-7,4.06722891531942E-6,10.0012846,10.0012846,24500.009765625,24515.1484375,57.4074882234292,20.5705289448173,10.760172,0,0,0,40,4449,10.00675,24507.5791015625,,,,,,,,,,,,,0,,,,0,,,,,,10.0012846,,,,
,32882961.155,10.0007143,19923.111328125,1.29490496827993E-5,6.87836618645105E-7,1,0.999253354069792,40.0298881530762,1.99372579890483,21.8000002205372,0.000145076811302011,2.81016041234839E-5,0.25,1.84154529233862E-7,1.28934806714146E-5,2.63561843689914E-7,10.0007143,10.0007143,19918.1875,19928.03515625,57.0416860764291,20.5732313582608,10.38052,0,0,0,40,4449,10.0062,19923.111328125,,,,,,,,,,,,,0,,,,-0.00245,,,,,,10.0007143,,,,
,32883051.76,10.0003042,15393.0258789062,2.71744168660129E-5,5.52334355760372E-7,1,0.999253354069792,40.0298881530762,1.99367948533638,21.8000002205372,0.000304486451459921,5.7996284346228E-5,0.25,3.10127433085382E-7,2.70467771964569E-5,4.68617402860085E-7,10.0003042,10.0003042,15385.5654296875,15400.486328125,56.9353845978137,20.5780398342364,11.139823,0,0,0,40,4449,10.0063,15393.0258789062,,,,,,,,,,,,,0,,,,0.0049,,,,,,10.0003042,,,,
,32883141.435,9.9992247,10912.8344726562,4.0719452633252E-5,6.91348975094385E-7,1,0.999253354069792,40.0298881530762,1.99364935388885,21.8000002205372,0.0004553666668502,9.08281910735513E-5,0.25,8.30589718960269E-7,4.05104301692534E-5,1.05287669100853E-6,9.9992247,9.9992247,10902.9736328125,10922.6953125,57.1307917276214,20.5794664520188,11.139823,0,0,0,40,4449,10.00675,10912.8344726562,,,,,,,,,,,,,0,,,,-0.00245,,,,,,9.9992247,,,,
,32883228.195,9.9988966,6577.22314453125,5.36086564940722E-5,4.28677285424186E-7,1,0.999253354069792,40.0298881530762,1.99363121124799,21.8000002205372,0.00060028345050097,0.000114019599390889,0.25,6.18869210734614E-7,5.33182066070713E-5,8.9654527219547E-7,9.9988966,9.9988966,6574.82958984375,6579.61669921875,57.159711982833,20.5786430450298,11.139823,0,0,0,40,4449,10.0085,6577.22314453125,,,,,,,,,,,,,0,,,,0,,,,,,9.9988966,,,,
,32883315.695,10.0005836,2201.49462890625,6.59230942188003E-5,3.50082910196089E-7,1,0.999253354069792,40.0298881530762,1.99403455288953,21.8000002205372,0.000738444602478551,0.000138297664136592,0.25,6.11705304254373E-7,6.55480981450927E-5,9.3374700949972E-7,10.0005836,10.0005836,2196.62768554687,2206.36157226562,57.1573670972753,20.5696618686731,11.139823,0,0,0,40,4449,10.00785,2201.49462890625,,,,,,,,,,,,,0,,,,0,,,,,,10.0005836,,,,
,32883360.705,10.0029755,-0.411041870713234,7.15420903533196E-5,2.85384301739972E-7,1,0.999253354069792,40.0298881530762,1.99407219652117,21.8000002205372,0.000802811832766594,0.00014166626576029,0.25,-7.7032921466323E-8,7.11314822004213E-5,2.68237801112826E-7,10.0029755,10.0029755,-0.456713199615479,-0.365370541810989,57.1917587521214,20.5688004895662,11.519473,0,0,0,40,4417,10.0046,-0.411041870713234,,,,,,,,,,,,,0,,,,0.00245,,,,,,10.0029755,,,,