File: data/doubleLayers/dl_2-5/ppms/data/DD205_5_HYST_100OE_300K.DAT
[Header]
; VSM Data File (default extension .dat)
; Copyright (c) 2003-2013, Quantum Design, Inc. All rights reserved.
TITLE,
FILEOPENTIME,23201299.14,09/26/2018,9:46 pm
BYAPP,VSM,2.0,2.0
INFO,PPMS VSM Option Release 1.4.10 Build 1,APPNAME
INFO,Quantum Design Linear Motor Servo Controller,MOTOR_MODULE_NAME
INFO,3101-100 M1,MOTOR_HW_VERSION
INFO,MMC1014,MOTOR_SERIAL_NUMBER
INFO,SRV No X-over 01.03.11,MOTOR_SOFTWARE_VERSION
INFO,Quantum Design VSM Detection Module,VSM_MODULE_NAME
INFO,3101-150 F0,VSM_HW_VERSION
INFO,VSM707,VSM_SERIAL_NUMBER
INFO,VSM No X-over 01.02.05 May 20 2008 13:51:47,VSM_SOFTWARE_VERSION
INFO,704,PREAMP_SERIAL_NUMBER
INFO,822,COIL_SERIAL_NUMBER
INFO,0,MOMENT_UNITS
INFO,,SAMPLE_MATERIAL
INFO,,SAMPLE_COMMENT
INFO,,SAMPLE_MASS
INFO,,SAMPLE_VOLUME
INFO,,SAMPLE_MOLECULAR_WEIGHT
INFO,,SAMPLE_SIZE
INFO,,SAMPLE_SHAPE
DATATYPE,COMMENT,1
DATATYPE,TIME,2
STARTUPAXIS,X,2
STARTUPAXIS,Y1,5
[Data]
Comment,Time Stamp (sec),Temperature (K),Magnetic Field (Oe),Moment (emu),M. Std. Err. (emu),Transport Action,Averaging Time (sec),Frequency (Hz),Peak Amplitude (mm),Center Position (mm),Coil Signal' (mV),Coil Signal" (mV),Range (mV),M. Quad. Signal (emu),M. Raw' (emu),M. Raw" (emu),Min. Temperature (K),Max. Temperature (K),Min. Field (Oe),Max. Field (Oe),Mass (grams),Motor Lag (deg),Pressure (Torr),VSM Status (code),Motor Status (code),Measure Status (code),Measure Count,PPMS Status (code),System Temp. (K),System Field (Oe),Sample Position (deg),Bridge 1 Resistance (ohms),Bridge 1 Excitation (에),Bridge 2 Resistance (ohms),Bridge 2 Excitation (에),Bridge 3 Resistance (ohms),Bridge 3 Excitation (에),Bridge 4 Resistance (ohms),Bridge 4 Excitation (에),Signal 1 Vin (V),Signal 2 Vin (V),Digital Inputs (code),Drive 1 Iout (mA),Drive 1 Ipower (W),Drive 2 Iout (mA),Drive 2 Ipower (W),Pressure (),Map 20 (),Map 21 (),Map 22 (),Map 23 (),Map 24 (),Map 25 (),Map 26 (),Map 27 (),Map 28 (),Map 29 ()
,23201314.66,300.2577515,0.0152237731963396,,,2,,,,15.6400004178286,,,,,,,300.2577515,300.2577515,0.0152237731963396,0.0152237731963396,,,28.983419,,,,-99999999,4369,301.2964,0.0152237731963396,,,,,,,,,,,,,,,,,,,,,,,300.2577515,,,,
,23201440,300.2675476,3124.40026855469,4.71971465626796E-5,3.95413408810495E-7,1,0.999253354069792,40.0298881530762,1.99754822781544,15.6299993395805,0.00053398282950748,9.16282503168313E-5,0.25,-7.62582999154161E-8,4.71953442260365E-5,-4.50471433536493E-8,300.2675476,300.2675476,3119.42822265625,3129.37231445313,56.1639172493329,20.5366616685982,29.363071,0,0,0,40,4449,300.9822,3124.40026855469,,,,,,,,,,,,,0,,,,0.0049,,,,,,300.2675476,,,,
,23201506.9,300.2232666,6465.63745117187,4.57814468353915E-5,4.58531956398463E-7,1,0.999253354069792,40.0298881530762,1.99749502488408,15.6299993395805,0.000517867441562584,8.93740217980521E-5,0.25,-3.00875485496143E-8,4.57797425175869E-5,1.83893194375268E-10,300.2232666,300.2232666,6463.39599609375,6467.87890625,56.2811615272175,20.5387578413195,29.742722,0,0,0,40,4449,300.87115,6465.63745117187,,,,,,,,,,,,,0,,,,0.0049,,,,,,300.2232666,,,,
,23201575.77,300.1739807,9909.8115234375,3.81595809159482E-5,6.19756446218926E-7,1,0.999253354069792,40.0298881530762,1.99764516485883,15.6299993395805,0.000432465183283874,6.9983728148845E-5,0.25,-4.2435980688738E-7,3.8158492372404E-5,-3.99119822489555E-7,300.1739807,300.1739807,9907.154296875,9912.46875,56.371048806929,20.541850914137,28.983419,0,0,0,40,4449,300.78735,9909.8115234375,,,,,,,,,,,,,0,,,,0.00245,,,,,,300.1739807,,,,
,23201645.17,300.127655,13374.9409179688,2.87326361403826E-5,7.86320814034714E-7,1,0.999253354069792,40.0298881530762,1.99766531903736,15.6299993395805,0.000322352337599666,7.16287049452848E-5,0.25,1.35429356564105E-6,2.87307588922193E-5,1.37323305656274E-6,300.127655,300.127655,13369.98828125,13379.8935546875,56.4851665707367,20.5445334219013,28.983419,0,0,0,40,4449,300.7307,13374.9409179688,,,,,,,,,,,,,0,,,,-0.00245,,,,,,300.127655,,,,
,23201713.22,300.0899658,16775.794921875,1.83235652775872E-5,6.95038137569258E-7,1,0.999253354069792,40.0298881530762,1.99768773464967,15.6299993395805,0.000206208201752812,4.20261774458345E-5,0.25,5.40650943074428E-7,1.83226071070062E-5,5.52734659745148E-7,300.0899658,300.0899658,16773.322265625,16778.267578125,56.5492601093137,20.5443782854056,28.983419,0,0,0,40,4449,300.7013,16775.794921875,,,,,,,,,,,,,0,,,,-0.0049,,,,,,300.0899658,,,,
,23201782.265,300.0642395,20228.841796875,6.68731384707908E-6,1.12524133688792E-6,1,0.999253354069792,40.0298881530762,1.99768726537678,15.6299993395805,7.61678056417976E-5,1.00818666388514E-5,0.25,-2.6733145776787E-7,6.68727732870122E-6,-2.62908967097257E-7,300.0642395,300.0642395,20221.298828125,20236.384765625,56.6985511564868,20.5446443952753,29.363071,0,0,0,40,4449,300.6762,20228.841796875,,,,,,,,,,,,,0,,,,-0.0049,,,,,,300.0642395,,,,
,23201852.62,300.0449829,23744.4169921875,-3.24204343410811E-6,1.04862994850053E-6,1,0.999253354069792,40.0298881530762,1.99775643666236,15.6299993395805,-3.71526441168736E-5,-3.59004725331836E-6,0.25,2.44335735895721E-7,-3.24210372136566E-6,2.42189589469518E-7,300.0449829,300.0449829,23734.08203125,23754.751953125,56.8048526351022,20.5453394599406,28.983419,0,0,0,40,4449,300.65945,23744.4169921875,,,,,,,,,,,,,0,,,,0.00245,,,,,,300.0449829,,,,
,23201920.91,300.0307007,27158.4208984375,-1.7362464636086E-5,1.88079725443315E-6,1,0.999253354069792,40.0298881530762,1.99762428087362,15.6299993395805,-0.000192474871734582,-5.66276603940943E-5,0.25,-1.99817814827583E-6,-1.73606167660485E-5,-2.00956227873139E-6,300.0307007,300.0307007,27153.494140625,27163.34765625,56.7618630665445,20.5462543679969,29.742722,0,0,0,40,4449,300.6474,27158.4208984375,,,,,,,,,,,,,0,,,,0,,,,,,300.0307007,,,,
,23201989.64,300.0234985,30591.4375,-2.80554843199056E-5,1.59972922420624E-6,1,0.999253354069792,40.0298881530762,1.99765042659986,15.6299993395805,-0.000320764095227811,-3.52532979887128E-5,0.25,1.74413405440118E-6,-2.80557841336138E-5,1.72560026733704E-6,300.0234985,300.0234985,30581.4609375,30601.4140625,56.7759323798906,20.5464333751339,29.363071,0,0,0,40,4449,300.64,30591.4375,,,,,,,,,,,,,0,,,,0,,,,,,300.0234985,,,,
,23202060.295,300.0158386,34122.5390625,-4.07538239974892E-5,1.75095958276128E-6,1,0.999253354069792,40.0298881530762,1.99758987463897,15.6299993395805,-0.000464951587559219,-5.68752738457581E-5,0.25,2.03249765238631E-6,-4.07539414642739E-5,2.00561122366161E-6,300.0158386,300.0158386,34115.36328125,34129.71484375,56.7743691228522,20.5461933706558,28.983419,0,0,0,40,4449,300.63635,34122.5390625,,,,,,,,,,,,,0,,,,0,,,,,,300.0158386,,,,
,23202130.625,300.0146179,37637.564453125,-5.04183024132185E-5,1.62982614925756E-6,1,0.999253354069792,40.0298881530762,1.99769977513364,15.6299993395805,-0.000570209817365715,-9.94103280336512E-5,0.25,-5.31356564193211E-8,-5.04167620815835E-5,-8.62964349861584E-8,300.0146179,300.0146179,37627.03515625,37648.09375,56.7337244398522,20.5494884861439,28.983419,0,0,0,40,4449,300.62725,37637.564453125,,,,,,,,,,,,,0,,,,-0.00245,,,,,,300.0146179,,,,
,23202200.11,300.0120697,41110.78125,-6.51613474092684E-5,2.12281025988002E-6,1,0.999253354069792,40.0298881530762,1.9977341140371,15.6299993395805,-0.000744583783734252,-8.44758770057422E-5,0.25,3.82152184478037E-6,-6.51619223666075E-5,3.77858082094657E-6,300.0119019,300.0122375,41105.87109375,41115.69140625,56.6633778731214,20.5475182112538,28.603769,0,0,0,40,4449,300.61815,41110.78125,,,,,,,,,,,,,0,,,,0.0049,,,,,,300.0120697,,,,
,23202268.885,300.0149841,44549.478515625,-7.39816859367799E-5,1.88518351162633E-6,1,0.999253354069792,40.0298881530762,1.99772226905125,15.6299993395805,-0.000839976006967872,-0.000127025872658939,0.25,1.58802903842823E-6,-7.39805255445058E-5,1.53939435833257E-6,300.0149841,300.0149841,44539.5859375,44559.37109375,56.6219515616021,20.5488523018794,28.983419,0,0,0,40,4449,300.6122,44549.478515625,,,,,,,,,,,,,0,,,,-0.0049,,,,,,300.0149841,,,,
,23202339.375,300.0169067,48072.55859375,-8.74184795902448E-5,2.19200121221763E-6,1,0.999253354069792,40.0298881530762,1.99756232393358,15.6299993395805,-0.000992444066993633,-0.000150173177101435,0.25,1.86863025797929E-6,-8.7417100528261E-5,1.81121064186754E-6,300.0169067,300.0169067,48062.7578125,48082.359375,56.6242964471598,20.54776759941,29.742722,0,0,0,40,4449,300.61645,48072.55859375,,,,,,,,,,,,,0,,,,0.00245,,,,,,300.0169067,,,,
,23202408,300.0094299,51500.98046875,-9.86946363416789E-5,2.43758856441614E-6,1,0.999253354069792,40.0298881530762,1.99759734119451,15.6299993395805,-0.00111329913394176,-0.000210988968127687,0.25,-1.5542152595031E-6,-9.86907066776363E-5,-1.61888498077031E-6,300.0094299,300.0094299,51495.97265625,51505.98828125,56.7126204698329,20.5470570117816,29.742722,0,0,0,40,4449,300.5981,51500.98046875,,,,,,,,,,,,,0,,,,0,,,,,,300.0094299,,,,
,23202477.425,300.0146637,54974.015625,-0.000112732728182121,2.21527934116709E-6,1,0.999253354069792,40.0298881530762,1.99772029647181,15.6299993395805,-0.00127841310563288,-0.000202420050898828,0.25,1.63647033403968E-6,-0.000112730459894277,1.5625600627729E-6,300.0145264,300.014801,54958.6640625,54989.3671875,56.7509202672752,20.5484773423107,29.363071,0,0,0,40,4449,300.58895,54974.015625,,,,,,,,,,,,,0,,,,0.00245,,,,,,300.0146637,,,,
,23202546.02,300.0196533,58402.8671875,-0.000124092184403242,2.69157695552396E-6,1,0.999253354069792,40.0298881530762,1.99759351610537,15.6299993395805,-0.00141053930995943,-0.00020321905597263,0.25,3.53272528216154E-6,-0.000124090803479269,3.45137842158355E-6,300.0196533,300.0196533,58397.99609375,58407.73828125,56.6336759893906,20.547455982122,29.742722,0,0,0,40,4449,300.57395,58402.8671875,,,,,,,,,,,,,0,,,,0.0049,,,,,,300.0196533,,,,
,23202616.085,300.018158,61903.728515625,-0.000140070400007075,2.8777633948914E-6,1,0.999253354069792,40.0298881530762,1.997677310364,15.6299993395805,-0.00157923776835511,-0.000304359578511159,0.25,-2.63974981347957E-6,-0.000140064518024983,-2.73129901217503E-6,300.018158,300.018158,61901.375,61906.08203125,56.6633778731214,20.5498541690038,29.363071,0,0,0,40,4449,300.5639,61903.728515625,,,,,,,,,,,,,0,,,,-0.0049,,,,,,300.018158,,,,
,23202685.13,300.0206604,65354.5,-0.000147927641396069,1.82202425287426E-6,1,0.999253354069792,40.0298881530762,1.99768051433837,15.6299993395805,-0.00167615422159377,-0.000273371322727931,0.25,1.46100466265776E-6,-0.000147924201846242,1.36427361033987E-6,300.0206604,300.0206604,65349.64453125,65359.35546875,56.7954730928714,20.5493687718916,29.363071,0,0,0,40,4449,300.5563,65354.5,,,,,,,,,,,,,0,,,,0.0049,,,,,,300.0206604,,,,
,23202755.625,300.0148926,68877.88671875,-0.000162093859022462,3.8245521664879E-6,1,0.999253354069792,40.0298881530762,1.9976643761842,15.6299993395805,-0.00183909798504083,-0.000285456633904787,0.25,2.84661932186988E-6,-0.00016209094419318,2.74067723676328E-6,300.0148926,300.0148926,68867.9296875,68887.84375,56.8181403199291,20.54692605635,29.363071,0,0,0,40,4449,300.5453,68877.88671875,,,,,,,,,,,,,0,,,,-0.00245,,,,,,300.0148926,,,,
,23202825.64,300.0175171,72378.89453125,-0.000174854181455247,3.48059928489796E-6,1,0.999253354069792,40.0298881530762,1.99755143323106,15.6299993395805,-0.00197188365081917,-0.000376508403818573,0.25,-2.99406334879353E-6,-0.000174847069835914,-3.10807341697814E-6,300.0175171,300.0175171,72371.4921875,72386.296875,56.6665043871983,20.5495060080732,29.363071,0,0,0,40,4449,300.52825,72378.89453125,,,,,,,,,,,,,0,,,,-0.0049,,,,,,300.0175171,,,,
,23202896.1,300.0214844,75900.05078125,-0.000182662149332474,3.20218027872267E-6,1,0.999253354069792,40.0298881530762,1.9974547579077,15.6299993395805,-0.00206237073259901,-0.000378701982983677,0.25,-1.83692919270168E-6,-0.000182655546476818,-1.95596636033685E-6,300.0214844,300.0214844,75895.0234375,75905.078125,56.5734905934098,20.5493075847028,29.363071,0,0,0,40,4449,300.51765,75900.05078125,,,,,,,,,,,,,0,,,,-0.00245,,,,,,300.0214844,,,,
,23202966.75,300.0205383,79430.5078125,-0.000203226464175911,2.69354760072514E-6,1,0.999253354069792,40.0298881530762,1.99753393928772,15.6299993395805,-0.0023018894575013,-0.000379518679501505,0.25,1.65474928998124E-6,-0.000203221545598855,1.52231843623289E-6,300.0205383,300.0205383,79427.734375,79433.28125,56.6532167023714,20.547475735949,28.983419,0,0,0,40,4449,300.51185,79430.5078125,,,,,,,,,,,,,0,,,,-0.0049,,,,,,300.0205383,,,,
,23203036.085,300.02223205,82897.03125,-0.000212473780121919,2.93975043519453E-6,1,0.999253354069792,40.0298881530762,1.99756096742326,15.6299993395805,-0.00239711087006891,-0.000451924449028703,0.25,-3.14426459783321E-6,-0.000212465461422634,-3.28246377444498E-6,300.0222168,300.0222473,82892.109375,82901.953125,56.679010443506,20.5484139081255,28.983419,0,0,0,40,4449,300.49265,82897.03125,,,,,,,,,,,,,0,,,,-0.0049,,,,,,300.02223205,,,,
,23203104.495,300.01750185,86315.98046875,-0.000225996113891937,3.29065165112941E-6,1,0.999253354069792,40.0298881530762,1.99748903155006,15.6299993395805,-0.00255726161834578,-0.00043633971978451,0.25,5.74844990493053E-7,-0.000225989865955963,4.27861844895123E-7,300.0174866,300.0175171,86306.046875,86325.9140625,56.6258597041983,20.5454224708636,29.363071,0,0,0,40,4449,300.4856,86315.98046875,,,,,,,,,,,,,0,,,,-0.00245,,,,,,300.01750185,,,,
,23203172.84,300.0197144,89732.0546875,-0.000239433455727845,3.78301217117175E-6,1,0.999253354069792,40.0298881530762,1.99760665581206,15.6299993395805,-0.002716235449927,-0.000423225022853832,0.25,4.06429765977974E-6,-0.000239429073785245,3.90860745750821E-6,300.0197144,300.0197144,89724.40625,89739.703125,56.7008960420445,20.5468053370232,28.983419,0,0,0,40,4449,300.4759,89732.0546875,,,,,,,,,,,,,0,,,,0.00245,,,,,,300.0197144,,,,
,23203261.335,300.0181885,86866.140625,-0.000226058522806639,2.94455704170483E-6,1,0.999253354069792,40.0298881530762,1.99767349542162,15.6299993395805,-0.00255798186646928,-0.000437718476760808,0.25,4.67160953434158E-7,-0.000226052197909527,3.20145827743905E-7,300.0176392,300.0187378,86858.5234375,86873.7578125,56.6946430138906,20.5480037614264,29.363071,0,0,0,40,4449,300.4579,86866.140625,,,,,,,,,,,,,0,,,,0,,,,,,300.0181885,,,,
,23203327.74,300.0081482,83544.15234375,-0.000210803531966471,3.69842764446094E-6,1,0.999253354069792,40.0298881530762,1.99755290782508,15.6299993395805,-0.00238896189779842,-0.000386594045152068,0.25,2.34212278663698E-6,-0.000210798940640753,2.20485652835722E-6,300.0081482,300.0081482,83534.28125,83554.0234375,56.8157954343714,20.5488785051813,29.363071,0,0,0,40,4449,300.46165,83544.15234375,,,,,,,,,,,,,0,,,,0,,,,,,300.0081482,,,,
,23203398.145,300.006012,80024.4609375,-0.000205292316801811,3.30429422040206E-6,1,0.999253354069792,40.0298881530762,1.99754342980214,15.6299993395805,-0.00232148692028669,-0.000405391101812672,0.25,-2.74577114708208E-7,-0.000205286187265841,-4.08300971162156E-7,300.006012,300.006012,80013.4609375,80035.4609375,56.8353361473522,20.5482993844551,29.363071,0,0,0,40,4449,300.46445,80024.4609375,,,,,,,,,,,,,0,,,,0,,,,,,300.006012,,,,
,23203468.82,300.0004578,76491.90234375,-0.000189735833568794,3.19715786018065E-6,1,0.999253354069792,40.0298881530762,1.99758221165964,15.6299993395805,-0.00214480370291538,-0.000379339253308862,0.25,-6.65693750603719E-7,-0.000189729927523424,-7.89386724776921E-7,300.0004578,300.0004578,76476.9375,76506.8671875,56.8736359447945,20.5480522171812,29.363071,0,0,0,40,4449,300.4604,76491.90234375,,,,,,,,,,,,,0,,,,0.00245,,,,,,300.0004578,,,,
,23203539.855,299.99684145,72939.9140625,-0.000175155194713455,3.79384794599148E-6,1,0.999253354069792,40.0298881530762,1.99768515186378,15.6299993395805,-0.00198246427114592,-0.00033643980834449,0.25,6.02510286275577E-7,-0.000175150550185387,4.88186235245322E-7,299.9960938,299.9975891,72937.46875,72942.359375,56.780622151006,20.5481650767605,28.983419,0,0,0,40,4449,300.4648,72939.9140625,,,,,,,,,,,,,0,,,,0.00245,,,,,,299.99684145,,,,
,23203609.53,299.9962158,69459.04296875,-0.000164274818879259,3.28276941508656E-6,1,0.999253354069792,40.0298881530762,1.99764792856448,15.6299993395805,-0.0018629573080649,-0.000294329645386407,0.25,2.43986684271636E-6,-0.00016427168358823,2.33250304246964E-6,299.9962158,299.9962158,69448.90625,69469.1796875,56.7360693254098,20.549359458909,28.983419,0,0,0,40,4449,300.48135,69459.04296875,,,,,,,,,,,,,0,,,,0.00245,,,,,,299.9962158,,,,
,23203680.015,299.9916077,65935.1171875,-0.000150872760093307,2.71152002069551E-6,1,0.999253354069792,40.0298881530762,1.99748077130788,15.6299993395805,-0.0016976683482744,-0.000346293355374791,0.25,-4.47831451066504E-6,-0.000150865506505182,-4.57681549992666E-6,299.9916077,299.9916077,65930.0546875,65940.1796875,56.892395029256,20.5479469560592,29.742722,0,0,0,40,4449,300.4755,65935.1171875,,,,,,,,,,,,,0,,,,-0.00245,,,,,,299.9916077,,,,
,23203751.94,299.993866,62341.5234375,-0.000137976908847238,2.92242207260398E-6,1,0.999253354069792,40.0298881530762,1.99756334668736,15.6299993395805,-0.00155343806107887,-0.000311991150306501,0.25,-3.67857772991053E-6,-0.000137970527465859,-3.76875021881681E-6,299.993866,299.993866,62336.3359375,62346.7109375,56.7337244398522,20.549998686081,29.363071,0,0,0,40,4449,300.47815,62341.5234375,,,,,,,,,,,,,0,,,,-0.0049,,,,,,299.993866,,,,
,23203821.395,299.99531555,58868.166015625,-0.000126942539621994,2.37138841092019E-6,1,0.999253354069792,40.0298881530762,1.99764299618635,15.6299993395805,-0.00143597812570885,-0.000248273550733625,0.25,4.38938006968613E-8,-0.000126938898764732,-3.92376011273865E-8,299.9946289,299.9960022,58863.3359375,58872.99609375,56.7243448976214,20.549410665211,29.363071,0,0,0,40,4449,300.4759,58868.166015625,,,,,,,,,,,,,0,,,,0,,,,,,299.99531555,,,,
,23203890.165,299.9954224,55432.302734375,-0.000111101029381311,2.32535949701722E-6,1,0.999253354069792,40.0298881530762,1.99753692869143,15.6299993395805,-0.00125401455912828,-0.000232864851511832,0.25,-1.33941977703072E-6,-0.000111096934207068,-1.41219593159024E-6,299.9954224,299.9954224,55424.72265625,55439.8828125,56.7688977232175,20.5497696920284,29.742722,0,0,0,40,4449,300.48225,55432.302734375,,,,,,,,,,,,,0,,,,0.00245,,,,,,299.9954224,,,,
,23203958.125,299.9904175,52033.828125,-0.00010367817518269,2.69769995270046E-6,1,0.999253354069792,40.0298881530762,1.99756687100602,15.6299993395805,-0.00117277899658888,-0.000202704271334477,0.25,4.14051244426951E-8,-0.000103675213744636,-2.66007435787114E-8,299.9904175,299.9904175,52021.125,52046.53125,56.7853119221214,20.5496449257378,29.742722,0,0,0,40,4449,300.48515,52033.828125,,,,,,,,,,,,,0,,,,-0.0049,,,,,,299.9904175,,,,
,23204028.385,299.9924011,48522.77734375,-8.71104529376485E-5,2.12629848448165E-6,1,0.999253354069792,40.0298881530762,1.99759115387378,15.6299993395805,-0.000986144592965207,-0.000165905613555691,0.25,4.24591745644548E-7,-8.71082103197476E-5,3.67395756025482E-7,299.9924011,299.9924011,48517.7578125,48527.796875,56.8197035769676,20.5483175779958,29.363071,0,0,0,40,4449,300.4913,48522.77734375,,,,,,,,,,,,,0,,,,0,,,,,,299.9924011,,,,
,23204096.4,299.989624,45125.220703125,-7.87597580421374E-5,2.54021481358823E-6,1,0.999253354069792,40.0298881530762,1.99765016544908,15.6299993395805,-0.000891158180172019,-0.000152756077301889,0.25,1.40770577020946E-7,-7.8757574976455E-5,8.90223724055084E-8,299.989624,299.989624,45115.09375,45135.34765625,56.790783321756,20.5499981485125,29.363071,0,0,0,40,4449,300.48535,45125.220703125,,,,,,,,,,,,,0,,,,0.00245,,,,,,299.989624,,,,
,23204165.94,300.0001526,41648.9609375,-6.29446172621355E-5,2.05687925383577E-6,1,0.999253354069792,40.0298881530762,1.99767944017686,15.6299993395805,-0.000712742657966995,-0.000119074314475355,0.25,3.78604806245961E-7,-6.29430208603091E-5,3.37207276008022E-7,300.0001526,300.0001526,41646.26953125,41651.65234375,56.8306463762368,20.5513320067384,29.363071,0,0,0,40,4449,300.4882,41648.9609375,,,,,,,,,,,,,0,,,,0,,,,,,300.0001526,,,,
,23204234.67,299.9951172,38212.970703125,-5.28285328744962E-5,1.38224749586311E-6,1,0.999253354069792,40.0298881530762,1.99765251519259,15.6299993395805,-0.000596221097297913,-0.000111284689842887,0.25,-6.85500550591158E-7,-5.28265401385825E-5,-7.20243020260027E-7,299.9951172,299.9951172,38202.90234375,38223.0390625,56.7642079521022,20.5503435077671,29.363071,0,0,0,40,4449,300.48555,38212.970703125,,,,,,,,,,,,,0,,,,0.00245,,,,,,299.9951172,,,,
,23204304.68,299.9866943,34712.451171875,-4.03462669373493E-5,1.13496531992525E-6,1,0.999253354069792,40.0298881530762,1.99751063930968,15.6299993395805,-0.000459624931273593,-6.01137124943164E-5,0.25,1.67539264350165E-6,-4.03462033417001E-5,1.6487775018752E-6,299.9866943,299.9866943,34699.80078125,34725.1015625,56.8173586914099,20.5488199236405,28.983419,0,0,0,40,4449,300.51305,34712.451171875,,,,,,,,,,,,,0,,,,0,,,,,,299.9866943,,,,
,23204374.89,299.997345,31204.3720703125,-2.86805984907974E-5,1.31628516670493E-6,1,0.999253354069792,40.0298881530762,1.99759471483169,15.6299993395805,-0.000325185005484904,-5.1724100507324E-5,0.25,3.96200385738226E-7,-2.86800178543532E-5,3.77288674454253E-7,299.997345,299.997345,31197.275390625,31211.46875,56.526592882256,20.5511421177821,29.363071,0,0,0,40,4449,300.50785,31204.3720703125,,,,,,,,,,,,,0,,,,0.00245,,,,,,299.997345,,,,
,23204445.17,299.9967957,27694.4052734375,-1.60231200983445E-5,1.38355246149906E-6,1,0.999253354069792,40.0298881530762,1.99762414617531,15.6299993395805,-0.000179325582691265,-4.24585005058878E-5,0.25,-9.77555031911901E-7,-1.6022004785545E-5,-9.88093175043028E-7,299.9967957,299.9967957,27689.462890625,27699.34765625,56.8533136032945,20.5515723856449,29.363071,0,0,0,40,4449,300.50935,27694.4052734375,,,,,,,,,,,,,0,,,,0.0049,,,,,,299.9967957,,,,
,23204514.35,299.993866,24235.5791015625,-7.02201833544623E-6,9.39058182669907E-7,1,0.999253354069792,40.0298881530762,1.9976316184548,15.6299993395805,-7.86047135892864E-5,-1.85132956376223E-5,0.25,-4.20101187499179E-7,-7.02153528653485E-6,-4.2472298430524E-7,299.993866,299.993866,24230.576171875,24240.58203125,56.9877537086022,20.5512966780256,29.363071,0,0,0,40,4449,300.51385,24235.5791015625,,,,,,,,,,,,,0,,,,-0.00245,,,,,,299.993866,,,,
,23204585.49,299.9909668,20679.826171875,4.72559634257184E-6,9.48174279395447E-7,1,0.999253354069792,40.0298881530762,1.99774326177123,15.6299993395805,5.50811889288189E-5,-1.22240698517012E-7,0.25,-8.29548649658212E-7,4.72600597231114E-6,-8.26403597999679E-7,299.9909668,299.9909668,20667.318359375,20692.333984375,56.7462304961599,20.5528347510326,29.363071,0,0,0,40,4449,300.51935,20679.826171875,,,,,,,,,,,,,0,,,,-0.0049,,,,,,299.9909668,,,,
,23204655.405,299.9916992,17184.3291015625,1.77228963933257E-5,5.93725030087814E-7,1,0.999253354069792,40.0298881530762,1.99762246343044,15.6299993395805,0.000202031983580158,2.5703925595144E-5,0.25,-7.98196813293729E-7,1.77229043731573E-5,-7.86461181934939E-7,299.9916992,299.9916992,17174.296875,17194.361328125,56.8142321773329,20.5521546471427,29.742722,0,0,0,40,4449,300.51965,17184.3291015625,,,,,,,,,,,,,0,,,,-0.00245,,,,,,299.9916992,,,,
,23204723.205,299.9911194,13798.8754882812,2.65044815345255E-5,6.40997625002391E-7,1,0.999253354069792,40.0298881530762,1.99765007188913,15.6299993395805,0.000300500797157709,4.79106554835143E-5,0.25,-3.56490841251397E-7,2.65039399536849E-5,-3.38954398989477E-7,299.9911194,299.9911194,13796.4677734375,13801.283203125,56.6477453027368,20.5539939134018,29.363071,0,0,0,40,4449,300.5307,13798.8754882812,,,,,,,,,,,,,0,,,,0.0049,,,,,,299.9911194,,,,
,23204790.49,299.9941406,10433.3520507813,3.62381915171848E-5,5.67284999584993E-7,1,0.999253354069792,40.0298881530762,1.99775405779142,15.6299993395805,0.000411649528119901,6.1063880555854E-5,0.25,-8.80382666475747E-7,3.62377059824157E-5,-8.56379451007796E-7,299.9941406,299.9941406,10423.322265625,10443.3818359375,56.8947399148137,20.556172869332,29.363071,0,0,0,40,4449,300.52615,10433.3520507813,,,,,,,,,,,,,0,,,,-0.00245,,,,,,299.9941406,,,,
,23204857.115,299.993927,7104.54370117187,4.44222218105462E-5,4.7203791098161E-7,1,0.999253354069792,40.0298881530762,1.99774672695242,15.6299993395805,0.000502200249091056,8.87895242690347E-5,0.25,1.52686719819208E-7,4.44208103928252E-5,1.82090341199778E-7,299.993927,299.993927,7099.66357421875,7109.423828125,56.8572217458906,20.5541028554665,29.363071,0,0,0,40,4449,300.5316,7104.54370117187,,,,,,,,,,,,,0,,,,0,,,,,,299.993927,,,,
,23204921.32,299.993988,3895.89331054687,4.77376528039076E-5,4.34648870370746E-7,1,0.999253354069792,40.0298881530762,1.99774275004553,15.6299993395805,0.000540497362007969,9.07024465390165E-5,0.25,-2.52632522333509E-7,4.77364105424158E-5,-2.21007082378953E-7,299.993988,299.993988,3891.0771484375,3900.70947265625,56.9572701963522,20.5545582316505,29.363071,0,0,0,40,4449,300.5359,3895.89331054687,,,,,,,,,,,,,0,,,,0,,,,,,299.993988,,,,
,23204987.455,299.9989929,586.648284912109,3.64350096565419E-5,4.5801187751421E-7,1,0.999253354069792,40.0298881530762,1.99772067822911,15.6299993395805,0.000412344701644077,7.02477170689063E-5,0.25,-1.02545590504702E-7,3.64339942964824E-5,-7.84004930941988E-8,299.9989929,299.9989929,576.573791503906,596.722778320312,57.0260535060445,20.553795105071,29.363071,0,0,0,40,4449,300.5353,586.648284912109,,,,,,,,,,,,,0,,,,0.00245,,,,,,299.9989929,,,,
,23205051.1,299.9998779,-2589.22839355469,-4.50635915681594E-5,4.24954351089449E-7,1,0.999253354069792,40.0298881530762,1.99774897259639,15.6299993395805,-0.000509910631684891,-8.74212980194216E-5,0.25,7.94169242438793E-8,-4.50623035038867E-5,4.95620057584571E-8,299.9998779,299.9998779,-2596.83471679687,-2581.6220703125,56.8228300910445,20.5548199389407,29.363071,0,0,0,40,4449,300.5333,-2589.22839355469,,,,,,,,,,,,,0,,,,-0.00245,,,,,,299.9998779,,,,
,23205113.91,300.0012817,-5729.26025390625,-4.61521060918972E-5,4.74447480574444E-7,1,0.999253354069792,40.0298881530762,1.99781532972277,15.6299993395805,-0.000520406745753618,-0.000100140510729905,0.25,-8.56130956666487E-7,-4.61501650441539E-5,-8.86665426585055E-7,300.0012817,300.0012817,-5736.86962890625,-5721.65087890625,56.9689946241406,20.5561948733194,29.742722,0,0,0,40,4449,300.5317,-5729.26025390625,,,,,,,,,,,,,0,,,,0,,,,,,300.0012817,,,,
,23205180.555,300.0012207,-9061.109375,-3.9124680692088E-5,5.0517512935444E-7,1,0.999253354069792,40.0298881530762,1.99781015338477,15.6299993395805,-0.000442323201765934,-7.82079594343754E-5,0.25,-1.3489356543784E-7,-3.91234277374667E-5,-1.60783437736078E-7,300.0012207,300.0012207,-9071.1806640625,-9051.0380859375,56.8243933480829,20.5561884713917,28.983419,0,0,0,40,4449,300.5198,-9061.109375,,,,,,,,,,,,,0,,,,0.00245,,,,,,300.0012207,,,,
,23205248.13,300.0067444,-12436.6669921875,-3.05703477667271E-5,6.98405703738795E-7,1,0.999253354069792,40.0298881530762,1.99778824129068,15.6299993395805,-0.000345211194465933,-6.3402049338844E-5,0.25,-3.0823533673813E-7,-3.05692297199425E-5,-3.28445818999301E-7,300.0067444,300.0067444,-12444.38671875,-12428.947265625,56.8243933480829,20.5567326757453,29.363071,0,0,0,40,4449,300.52865,-12436.6669921875,,,,,,,,,,,,,0,,,,0.00245,,,,,,300.0067444,,,,
,23205314.86,300.0030212,-15775.189453125,-2.08064548556347E-5,7.56178089604176E-7,1,0.999253354069792,40.0298881530762,1.99781367710884,15.6299993395805,-0.000237108755933148,-3.07317088260187E-5,0.25,8.88201390107352E-7,-2.08064233147741E-5,8.74421795348956E-7,300.0030212,300.0030212,-15777.705078125,-15772.673828125,57.027616763083,20.557616585111,29.742722,0,0,0,40,4449,300.52925,-15775.189453125,,,,,,,,,,,,,0,,,,0.0049,,,,,,300.0030212,,,,
,23205384.345,300.0091858,-19245.3134765625,-1.00685572872742E-5,9.55437365948997E-7,1,0.999253354069792,40.0298881530762,1.99781636223349,15.6299993395805,-0.000112048052786674,-3.04124672341907E-5,0.25,-9.44000534632195E-7,-1.00676324461322E-5,-9.50623573866887E-7,300.0091858,300.0091858,-19255.169921875,-19235.45703125,56.9103724851983,20.5564101504301,29.742722,0,0,0,40,4449,300.51525,-19245.3134765625,,,,,,,,,,,,,0,,,,-0.0049,,,,,,300.0091858,,,,
,23205453.075,300.0075073,-22681.283203125,-1.22240416324916E-7,7.87093088528398E-7,1,0.999253354069792,40.0298881530762,1.99778769871167,15.6299993395805,-8.84317283942215E-7,-3.1167006478488E-6,0.25,-2.54339831885867E-7,-1.22068868082207E-7,-2.54412945373894E-7,300.0075073,300.0075073,-22683.708984375,-22678.857421875,57.0049495360253,20.5584145030762,29.742722,0,0,0,40,4449,300.5123,-22681.283203125,,,,,,,,,,,,,0,,,,0,,,,,,300.0075073,,,,
,23205523.14,300.00692745,-26184.173828125,1.27361377064983E-5,1.15186514452226E-6,1,0.999253354069792,40.0298881530762,1.99775592101037,15.6299993395805,0.000144233453957238,2.40205821546968E-5,0.25,-8.31442349213309E-8,1.27358135852047E-5,-7.47398812639452E-8,300.0059814,300.0078735,-26191.5859375,-26176.76171875,56.9877537086022,20.5574253561734,28.983419,0,0,0,40,4449,300.50795,-26184.173828125,,,,,,,,,,,,,0,,,,-0.00245,,,,,,300.00692745,,,,
,23205593.14,300.0081482,-29679.7177734375,2.43463457373129E-5,1.36010816065071E-6,1,0.999253354069792,40.0298881530762,1.99772349202373,15.6299993395805,0.00027519852850079,4.88792879795954E-5,0.25,1.02956302890664E-7,2.43455534050008E-5,1.19002588317597E-7,300.0081482,300.0081482,-29684.591796875,-29674.84375,56.9056827140829,20.5596382748491,28.983419,0,0,0,40,4449,300.5044,-29679.7177734375,,,,,,,,,,,,,0,,,,-0.0049,,,,,,300.0081482,,,,
,23205663.51,300.0052185,-33200.14453125,3.85538906604537E-5,1.51974082610191E-6,1,0.999253354069792,40.0298881530762,1.99779912172229,15.6299993395805,0.000436533756830403,7.32234528442984E-5,0.25,-2.06688684801203E-7,3.85528853299345E-5,-1.81286355157522E-7,300.0052185,300.0052185,-33212.7890625,-33187.5,57.0706063316407,20.5599694604834,28.983419,0,0,0,40,4449,300.49975,-33200.14453125,,,,,,,,,,,,,0,,,,0.00245,,,,,,300.0052185,,,,
,23205732.57,300.0062561,-36648.294921875,4.91017861103284E-5,1.5193943086179E-6,1,0.999253354069792,40.0298881530762,1.99778266475444,15.6299993395805,0.000557273704154588,8.56729534968267E-5,0.25,-9.33543252364529E-7,4.91009471563711E-5,-9.01195559090237E-7,300.0062561,300.0062561,-36661.15234375,-36635.4375,56.8845787440637,20.5599182735814,28.983419,0,0,0,40,4449,300.49685,-36648.294921875,,,,,,,,,,,,,0,,,,0,,,,,,300.0062561,,,,
,23205804.49,300.0115051,-40243.78515625,6.02024465896896E-5,1.95177959404008E-6,1,0.999253354069792,40.0298881530762,1.99781855784819,15.6299993395805,0.000678241121693636,0.000134073118856861,0.25,1.421665069596E-6,6.01997208906119E-5,1.46121905261445E-6,300.0115051,300.0115051,-40253.75390625,-40233.81640625,56.9353845978137,20.560151087243,29.363071,0,0,0,40,4449,300.48705,-40243.78515625,,,,,,,,,,,,,0,,,,0.00245,,,,,,300.0115051,,,,
,23205875.265,300.0127869,-43779.09375,7.29723507466467E-5,1.44244669550288E-6,1,0.999253354069792,40.0298881530762,1.99773349862343,15.6299993395805,0.000826734925677726,0.000135600608854089,0.25,-6.55220232812672E-7,7.29706108593921E-5,-6.0724268468361E-7,300.0127869,300.0127869,-43786.5859375,-43771.6015625,56.9416376259676,20.5607246914436,28.983419,0,0,0,40,4449,300.4785,-43779.09375,,,,,,,,,,,,,0,,,,0.00245,,,,,,300.0127869,,,,
,23205944.425,300.0113525,-47237.55078125,8.51746076613633E-5,1.74209238281053E-6,1,0.999253354069792,40.0298881530762,1.99767298297343,15.6299993395805,0.000962859588329466,0.000170346299758337,0.25,3.02796813336191E-7,8.51718837018417E-5,3.58721128224678E-7,300.0113525,300.0113525,-47249.9453125,-47225.15625,56.7587365524675,20.5616368256279,29.742722,0,0,0,40,4449,300.475,-47237.55078125,,,,,,,,,,,,,0,,,,-0.00245,,,,,,300.0113525,,,,
,23206015.315,300.0149536,-50780.70703125,9.76600960717562E-5,2.25382163162952E-6,1,0.999253354069792,40.0298881530762,1.9977629882379,15.6299993395805,0.001107942959075,0.00017285334382273,0.25,-1.63932117466962E-6,9.7658268353161E-5,-1.5751905348088E-6,300.0149536,300.0149536,-50788.15234375,-50773.26171875,56.8666012881214,20.5611395822367,29.363071,0,0,0,40,4449,300.4628,-50780.70703125,,,,,,,,,,,,,0,,,,0.0049,,,,,,300.0149536,,,,
,23206085.58,300.0165405,-54293.525390625,0.000110364715325846,1.90454924161816E-6,1,0.999253354069792,40.0298881530762,1.99763159235773,15.6299993395805,0.00124508861435486,0.000235201450108969,0.25,1.67261759103337E-6,0.000110360336530011,1.74492746644029E-6,300.0165405,300.0165405,-54305.94921875,-54281.1015625,56.983845566006,20.561382826877,29.363071,0,0,0,40,4449,300.4557,-54293.525390625,,,,,,,,,,,,,0,,,,-0.0049,,,,,,300.0165405,,,,
,23206154.985,300.0135803,-57761.314453125,0.000122155742815151,2.68802891629804E-6,1,0.999253354069792,40.0298881530762,1.99768295630763,15.6299993395805,0.00138461345052486,0.000222995269128943,0.25,-1.44973983230023E-6,0.000122153078441383,-1.36967068285334E-6,300.0135803,300.0135803,-57768.79296875,-57753.8359375,56.9244417985445,20.5608028430245,28.983419,0,0,0,40,4449,300.44595,-57761.314453125,,,,,,,,,,,,,0,,,,0,,,,,,300.0135803,,,,
,23206224.68,300.0158386,-61244.26171875,0.000135240848490926,2.76766829207609E-6,1,0.999253354069792,40.0298881530762,1.99774319712237,15.6299993395805,0.00152645511897571,0.000284520850260876,0.25,1.72177222893493E-6,0.000135235715717009,1.81024679995285E-6,300.0158386,300.0158386,-61246.99609375,-61241.52734375,57.0643533034868,20.5612520771394,29.742722,0,0,0,40,4449,300.4389,-61244.26171875,,,,,,,,,,,,,0,,,,0,,,,,,300.0158386,,,,
,23206294.025,300.01145935,-64710.1796875,0.000146176519659222,2.88737580226792E-6,1,0.999253354069792,40.0298881530762,1.99764136495938,15.6299993395805,0.00165035150477254,0.000304360704297429,0.25,1.58243405691353E-6,0.000146171185115211,1.67799177274781E-6,300.0113525,300.0115662,-64715.34375,-64705.015625,56.9752476522945,20.5610494520519,29.363071,0,0,0,40,4449,300.4327,-64710.1796875,,,,,,,,,,,,,0,,,,0.00245,,,,,,300.01145935,,,,
,23206363.605,300.0128784,-68185.44140625,0.000158763520650632,2.73185256117401E-6,1,0.999253354069792,40.0298881530762,1.99768283194087,15.6299993395805,0.00179622593429856,0.000309045195742215,0.25,-1.84581633637017E-7,0.000158758971078719,-8.0826421321143E-8,300.0128784,300.0128784,-68193.125,-68177.7578125,56.9674313671022,20.5612022132006,29.363071,0,0,0,40,4449,300.4248,-68185.44140625,,,,,,,,,,,,,0,,,,0,,,,,,300.0128784,,,,
,23206434.565,300.019104,-71730.8359375,0.000175250652745694,2.70040979254145E-6,1,0.999253354069792,40.0298881530762,1.99771072644843,15.6299993395805,0.00198093369036111,0.000351828222827994,0.25,7.40951939268914E-7,0.000175244983279476,8.55355931998063E-7,300.019104,300.019104,-71740.7109375,-71720.9609375,56.9119357422368,20.5622641781286,29.363071,0,0,0,40,4449,300.41525,-71730.8359375,,,,,,,,,,,,,0,,,,0.00245,,,,,,300.019104,,,,
,23206505.72,300.0193176,-75288.2734375,0.000184875706545987,3.08968587026659E-6,1,0.999253354069792,40.0298881530762,1.99762855341666,15.6299993395805,0.00208813778069419,0.000379853010743532,0.25,1.55233826789227E-6,0.000184869230955929,1.67290102276265E-6,300.0193176,300.0193176,-75298.09375,-75278.453125,56.8462789466214,20.5598361350713,29.742722,0,0,0,40,4449,300.3996,-75288.2734375,,,,,,,,,,,,,0,,,,0.00245,,,,,,300.0193176,,,,
,23206577.195,300.0205078,-78863.76171875,0.000198928387242893,3.62217299646452E-6,1,0.999253354069792,40.0298881530762,1.99767363192925,15.6299993395805,0.00224638344951441,0.000411766760271387,0.25,1.93847052115317E-6,0.000198921247218167,2.06807546794822E-6,300.0205078,300.0205078,-78871.1640625,-78856.359375,57.0002597649099,20.5616864451473,29.742722,0,0,0,40,4449,300.39,-78863.76171875,,,,,,,,,,,,,0,,,,0,,,,,,300.0205078,,,,
,23206646.08,300.0195618,-82304.5546875,0.000212951116965227,3.21632354869559E-6,1,0.999253354069792,40.0298881530762,1.99766199870726,15.6299993395805,0.00240950675151909,0.000413165895904006,0.25,-3.66934439459168E-7,0.000212945082539267,-2.28235817819638E-7,300.0195618,300.0195618,-82309.484375,-82299.625,56.8353361473522,20.562520041262,29.742722,0,0,0,40,4449,300.37345,-82304.5546875,,,,,,,,,,,,,0,,,,0,,,,,,300.0195618,,,,
,23206714.515,300.0159912,-85722.63671875,0.000220822747733647,4.06843950648105E-6,1,0.999253354069792,40.0298881530762,1.99763070208283,15.6299993395805,0.00249599852667608,0.000443078833174349,0.25,9.14510141742204E-7,0.000220815686777166,1.05817242418151E-6,300.0159912,300.0159912,-85732.578125,-85712.6953125,56.8048526351022,20.5621519764913,29.742722,0,0,0,40,4449,300.36875,-85722.63671875,,,,,,,,,,,,,0,,,,0.0049,,,,,,300.0159912,,,,
,23206779.09,300.01672365,-88950.12109375,0.0002365827106946,4.22905235568724E-6,1,0.999253354069792,40.0298881530762,1.99765476750443,15.6299993395805,0.00267658139351636,0.000460770192482264,0.25,-2.52157074221755E-7,0.000236575951927157,-9.83285662675435E-8,300.0166626,300.0167847,-88955.0703125,-88945.171875,56.8861420011022,20.5614511950236,29.742722,0,0,0,40,4449,300.3565,-88950.12109375,,,,,,,,,,,,,0,,,,-0.0049,,,,,,300.01672365,,,,
,23206861.48,300.0152588,-87878.296875,0.000230938823361293,3.3342188344961E-6,1,0.999253354069792,40.0298881530762,1.99766214148929,15.6299993395805,0.00261291883564658,0.000448738808662425,0.25,-3.3821012079975E-7,0.000230932293844944,-1.88002617137432E-7,300.0152588,300.0152588,-87888.6875,-87867.90625,57.0166739638137,20.5632999806393,29.742722,0,0,0,40,4449,300.35005,-87878.296875,,,,,,,,,,,,,0,,,,-0.00245,,,,,,300.0152588,,,,
,23206925.82,300.0107727,-84663.32421875,0.0002148590965111,3.30509223117378E-6,1,0.999253354069792,40.0298881530762,1.99759135331323,15.6299993395805,0.00243283133590669,0.000406364035385536,0.25,-1.29754107427505E-6,0.000214853685608946,-1.15764349231103E-6,300.0107727,300.0107727,-84671.0859375,-84655.5625,56.8494054606983,20.5612752836777,29.363071,0,0,0,40,4449,300.3454,-84663.32421875,,,,,,,,,,,,,0,,,,0.00245,,,,,,300.0107727,,,,
,23206993.775,300.0056763,-81268.03125,0.000205526072824857,2.76272095653413E-6,1,0.999253354069792,40.0298881530762,1.9975904697747,15.6299993395805,0.00231905786244128,0.000435441791236345,0.25,2.89000593742586E-6,0.00020551823353963,3.02382289979171E-6,300.0056763,300.0056763,-81272.6875,-81263.375,56.9291315696599,20.5595720827876,29.742722,0,0,0,40,4449,300.34915,-81268.03125,,,,,,,,,,,,,0,,,,0,,,,,,300.0056763,,,,
,23207063.055,300.0000305,-77804.359375,0.000193902047120652,2.7528199256468E-6,1,0.999253354069792,40.0298881530762,1.9976155505811,15.6299993395805,0.00219369682386538,0.000377500798803036,0.25,-2.19177341474529E-7,0.000193896599678906,-9.27289420390597E-8,300.0000305,300.0000305,-77809.1484375,-77799.5703125,56.9041194570445,20.560165911114,29.363071,0,0,0,40,4449,300.34595,-77804.359375,,,,,,,,,,,,,0,,,,0,,,,,,300.0000305,,,,
,23207131.055,299.9968567,-74406.46875,0.00017741809781469,3.0253044117865E-6,1,0.999253354069792,40.0298881530762,1.99757391350548,15.6299993395805,0.00200535264625753,0.000355874804224591,0.25,7.25257614619718E-7,0.000177412520865232,8.4102817405505E-7,299.9968262,299.9968872,-74411.53125,-74401.40625,56.9908802226791,20.5586272586152,29.742722,0,0,0,40,4449,300.35085,-74406.46875,,,,,,,,,,,,,0,,,,-0.00245,,,,,,299.9968567,,,,
,23207199.395,299.99157715,-70988.28515625,0.000171635565263759,3.14017680733257E-6,1,0.999253354069792,40.0298881530762,1.99749252240997,15.6299993395805,0.0019336227063403,0.00038059708182427,0.25,3.91397187444745E-6,0.000171628095575693,4.02597170524852E-6,299.9914856,299.9916687,-70998.3828125,-70978.1875,57.0541921327368,20.558741423203,29.363071,0,0,0,40,4449,300.35725,-70988.28515625,,,,,,,,,,,,,0,,,,0,,,,,,299.99157715,,,,
,23207268.07,299.9850159,-67561.1484375,0.000158765968815314,2.05840260318852E-6,1,0.999253354069792,40.0298881530762,1.99750255975591,15.6299993395805,0.00179490822122777,0.000315906600160768,0.25,4.239167643632E-7,0.000158761176904305,5.27694760362667E-7,299.9850159,299.9850159,-67571.0234375,-67551.2734375,56.8994296859291,20.5576784616316,30.122374,0,0,0,40,4449,300.3693,-67561.1484375,,,,,,,,,,,,,0,,,,0,,,,,,299.9850159,,,,
,23207338.735,299.9883423,-64025.255859375,0.000145801006776639,2.54741615133334E-6,1,0.999253354069792,40.0298881530762,1.99757027199901,15.6299993395805,0.00164840083903023,0.000290042081654987,0.25,3.8244089983106E-7,0.000145796585807984,4.7782564251294E-7,299.9883423,299.9883423,-64032.75,-64017.76171875,56.8595666314483,20.5586700839484,29.742722,0,0,0,40,4449,300.3767,-64025.255859375,,,,,,,,,,,,,0,,,,0.00245,,,,,,299.9883423,,,,
,23207408.16,299.9887695,-60557.3515625,0.000131112296934467,1.89952017114503E-6,1,0.999253354069792,40.0298881530762,1.99759654996212,15.6299993395805,0.00148492216866118,0.00024598640810936,0.25,-9.6802722579121E-7,0.00013110917183871,-8.82142199513723E-7,299.9887695,299.9887695,-60560.01953125,-60554.68359375,56.811105663256,20.5575931448466,29.742722,0,0,0,40,4449,300.38015,-60557.3515625,,,,,,,,,,,,,0,,,,-0.00245,,,,,,299.9887695,,,,
,23207478.595,299.9802856,-57038.76171875,0.000117692552570207,2.50057743073103E-6,1,0.999253354069792,40.0298881530762,1.99751467696453,15.6299993395805,0.00133215343853803,0.000225017422723542,0.25,-4.9617571719053E-7,0.000117689533346827,-4.19024209751037E-7,299.9802856,299.9802856,-57046.19140625,-57031.33203125,56.9056827140829,20.5571445797133,29.742722,0,0,0,40,4449,300.3745,-57038.76171875,,,,,,,,,,,,,0,,,,0.00245,,,,,,299.9802856,,,,
,23207548.28,299.9865112,-53553.62890625,0.000107324751382283,2.10310853910669E-6,1,0.999253354069792,40.0298881530762,1.99747161263813,15.6299993395805,0.00120765409120599,0.000246296482680794,0.25,3.18179297372142E-6,0.000107319585966872,3.25209623176557E-6,299.9865112,299.9865112,-53563.578125,-53543.6796875,56.7618630665445,20.5566163228697,30.122374,0,0,0,40,4449,300.3993,-53553.62890625,,,,,,,,,,,,,0,,,,-0.00245,,,,,,299.9865112,,,,
,23207620.045,299.9867554,-49966.080078125,9.56390161815285E-5,1.71923367445974E-6,1,0.999253354069792,40.0298881530762,1.99746259971716,15.6299993395805,0.00107919364233897,0.000201954314733655,0.25,1.28593275428156E-6,9.56354233635267E-5,1.34867681440816E-6,299.9867554,299.9867554,-49971.08203125,-49961.078125,57.054973761256,20.5548653877091,29.742722,0,0,0,40,4449,300.4092,-49966.080078125,,,,,,,,,,,,,0,,,,0.0049,,,,,,299.9867554,,,,
,23207690.555,299.9858093,-46443.103515625,8.10025160075419E-5,2.10242501306558E-6,1,0.999253354069792,40.0298881530762,1.99743338997096,15.6299993395805,0.000915674234874276,0.000161509337112454,0.25,2.45987255343738E-7,8.10000252943513E-5,2.99196210682284E-7,299.9858093,299.9858093,-46453.08984375,-46433.1171875,57.068261446083,20.5558643200564,29.742722,0,0,0,40,4449,300.4144,-46443.103515625,,,,,,,,,,,,,0,,,,0.00245,,,,,,299.9858093,,,,
,23207761.47,299.9852295,-42899.60546875,7.21632208107162E-5,1.47695326319197E-6,1,0.999253354069792,40.0298881530762,1.99748206988134,15.6299993395805,0.000816285376524413,0.000140921668366625,0.25,-4.31726144387797E-8,7.21611724658928E-5,4.27432692343922E-9,299.9852295,299.9852295,-42909.48046875,-42889.73046875,56.8595666314483,20.5557606699614,29.363071,0,0,0,40,4449,300.42585,-42899.60546875,,,,,,,,,,,,,0,,,,0,,,,,,299.9852295,,,,
,23207831.205,299.9844666,-39413.94921875,5.7448851061526E-5,1.4106767556875E-6,1,0.999253354069792,40.0298881530762,1.997522631145,15.6299993395805,0.000648580923684962,0.000119537950950194,0.25,6.15305193233656E-7,5.74467919158396E-5,6.53087728411652E-7,299.9844666,299.9844666,-39416.39453125,-39411.50390625,56.8501870892175,20.553692029986,30.122374,0,0,0,40,4449,300.43335,-39413.94921875,,,,,,,,,,,,,0,,,,0.00245,,,,,,299.9844666,,,,
,23207900.73,299.9894104,-35941.140625,4.55090462109421E-5,1.75194129795934E-6,1,0.999253354069792,40.0298881530762,1.99743814947569,15.6299993395805,0.000515719365686253,8.33989851289661E-5,0.25,-5.10905611797248E-7,4.55080622004789E-5,-4.80925934946749E-7,299.9886475,299.9901733,-35948.67578125,-35933.60546875,56.8118872917752,20.5536475061222,29.742722,0,0,0,40,4449,300.4551,-35941.140625,,,,,,,,,,,,,0,,,,0,,,,,,299.9894104,,,,
,23207972.17,299.986145,-32368.7294921875,3.47891034543167E-5,1.13190187618013E-6,1,0.999253354069792,40.0298881530762,1.99736793989391,15.6299993395805,0.000395381718345424,5.70766007173397E-5,0.25,-9.80778760344893E-7,3.47887427782584E-5,-9.5782501589306E-7,299.986145,299.986145,-32376.26171875,-32361.197265625,56.8259566051214,20.5546363983424,29.742722,0,0,0,40,4449,300.44505,-32368.7294921875,,,,,,,,,,,,,0,,,,0.00245,,,,,,299.986145,,,,
,23208042.875,299.9898682,-28837.9091796875,2.12795100824983E-5,1.50985931964877E-6,1,0.999253354069792,40.0298881530762,1.99742107748,15.6299993395805,0.00023729901008805,6.11799315427105E-5,0.25,1.72249512442425E-6,2.12777543805438E-5,1.73647840312062E-6,299.9898682,299.9898682,-28847.865234375,-28827.953125,56.9643048530253,20.554756902842,29.742722,0,0,0,40,4449,300.44525,-28837.9091796875,,,,,,,,,,,,,0,,,,0,,,,,,299.9898682,,,,
,23208114.02,299.9868164,-25279.8232421875,1.01050151334418E-5,1.20234970070823E-6,1,0.999253354069792,40.0298881530762,1.99744194033611,15.6299993395805,0.000113840022071964,2.24005329844024E-5,0.25,2.29791517332005E-7,1.01045698911888E-5,2.36453420387923E-7,299.9868164,299.9868164,-25284.916015625,-25274.73046875,56.8048526351022,20.5521843119099,29.742722,0,0,0,40,4449,300.4636,-25279.8232421875,,,,,,,,,,,,,0,,,,0,,,,,,299.9868164,,,,
,23208185.285,299.9865417,-21716.65625,-3.06195810593411E-6,8.53637617954464E-7,1,0.999253354069792,40.0298881530762,1.99745546803497,15.6299993395805,-3.67139705431386E-5,6.01790461411521E-6,0.25,1.062577083047E-6,-3.06257078487396E-6,1.06052399342946E-6,299.9865417,299.9865417,-21726.53515625,-21706.77734375,56.6571248449675,20.5518361503379,30.122374,0,0,0,40,4449,300.45905,-21716.65625,,,,,,,,,,,,,0,,,,-0.00245,,,,,,299.9865417,,,,
,23208254.32,299.9918518,-18269.1494140625,-1.29313634418197E-5,7.68788085716232E-7,1,0.999253354069792,40.0298881530762,1.99752825642909,15.6299993395805,-0.000145468386083718,-2.99275296872589E-5,0.25,-4.05490121191163E-7,-1.29307163580019E-5,-4.14023855358358E-7,299.9918518,299.9918518,-18274.5234375,-18263.775390625,56.6594697305252,20.5523497618352,29.363071,0,0,0,40,4449,300.46955,-18269.1494140625,,,,,,,,,,,,,0,,,,-0.00245,,,,,,299.9918518,,,,
,23208324.775,299.9884949,-14748.4184570313,-2.44012089416125E-5,7.67043709790642E-7,1,0.999253354069792,40.0298881530762,1.99753314092446,15.6299993395805,-0.000276044579014544,-4.75371824815318E-5,0.25,2.48673039872861E-8,-2.44005119034441E-5,8.72960541173314E-9,299.9884949,299.9884949,-14756.1357421875,-14740.701171875,56.7446672391214,20.5518663290207,29.742722,0,0,0,40,4449,300.45815,-14748.4184570313,,,,,,,,,,,,,0,,,,0.00245,,,,,,299.9884949,,,,
,23208395.06,299.9952698,-11235.2905273438,-3.45105543459169E-5,7.23318670913334E-7,1,0.999253354069792,40.0298881530762,1.9975455353922,15.6299993395805,-0.000388823881306306,-7.63936375215486E-5,0.25,-7.74800855080995E-7,-3.4509023031339E-5,-7.97613342076114E-7,299.9952698,299.9952698,-11237.748046875,-11232.8330078125,57.2191157502945,20.5528632474816,29.363071,0,0,0,40,4449,300.4771,-11235.2905273438,,,,,,,,,,,,,0,,,,0,,,,,,299.9952698,,,,
,23208464.7,299.9909668,-7754.06909179688,-4.23448630771194E-5,5.1984220576051E-7,1,0.999253354069792,40.0298881530762,1.9974202478105,15.6299993395805,-0.000478361285193154,-8.62372552696608E-5,0.25,-2.88165797436518E-7,-4.23434274998431E-5,-3.16192796834769E-7,299.9909668,299.9909668,-7759.15771484375,-7748.98046875,56.7345060683714,20.5509239682968,30.122374,0,0,0,40,4449,300.48135,-7754.06909179688,,,,,,,,,,,,,0,,,,0,,,,,,299.9909668,,,,
,23208532.88,299.9963379,-4345.34228515625,-4.69861962684817E-5,4.51003063457707E-7,1,0.999253354069792,40.0298881530762,1.99742474482591,15.6299993395805,-0.000530947117639157,-9.48088662260938E-5,0.25,-2.4185257874811E-7,-4.69846443123138E-5,-2.72969948545258E-7,299.9963379,299.9963379,-4350.3857421875,-4340.298828125,56.7665528376599,20.5518524946955,30.122374,0,0,0,40,4449,300.4846,-4345.34228515625,,,,,,,,,,,,,0,,,,0.0049,,,,,,299.9963379,,,,
,23208596.825,300.000824,-1148.49493408203,-4.05648773920482E-5,4.48322876912485E-7,1,0.999253354069792,40.0298881530762,1.99741360998239,15.6299993395805,-0.00045763545144229,-8.61676125284086E-5,0.25,-5.90407100297818E-7,-4.05632769084246E-5,-6.17272889885238E-7,300.000824,300.000824,-1150.94860839844,-1146.04125976562,56.7462304961599,20.5498997776579,29.742722,0,0,0,40,4449,300.4743,-1148.49493408203,,,,,,,,,,,,,0,,,,0,,,,,,300.000824,,,,
,23208665.125,299.9954224,2260.5732421875,4.43958056020395E-5,3.91930057812879E-7,1,0.999253354069792,40.0298881530762,1.99744284548302,15.6299993395805,0.000501995986532818,8.77582619258558E-5,0.25,6.7197736171939E-8,4.43944467133899E-5,9.66132668195235E-8,299.9954224,299.9954224,2253.2392578125,2267.9072265625,56.7587365524675,20.5503833313121,30.122374,0,0,0,40,4449,300.4809,2260.5732421875,,,,,,,,,,,,,0,,,,0,,,,,,299.9954224,,,,
,23208733.275,299.9989319,5667.53979492188,4.62952390959473E-5,5.11773125683562E-7,1,0.999253354069792,40.0298881530762,1.99733060853009,15.6299993395805,0.00052333696036398,9.21332943068178E-5,0.25,1.25376391464692E-7,4.62937809969418E-5,1.56033577426099E-7,299.9989319,299.9989319,5662.6142578125,5672.46533203125,56.8040710065829,20.5516633834356,30.122374,0,0,0,40,4449,300.48305,5667.53979492188,,,,,,,,,,,,,0,,,,0,,,,,,299.9989319,,,,
,23208801.415,299.9997559,9074.02001953125,4.05813208418116E-5,5.98056519169192E-7,1,0.999253354069792,40.0298881530762,1.99743229763809,15.6299993395805,0.00045943723465124,7.68985411875354E-5,0.25,-2.3201135013191E-7,4.05802691587361E-5,-2.05142157435811E-7,299.9997559,299.9997559,9066.5185546875,9081.521484375,56.6852634716598,20.5503360754045,29.742722,0,0,0,40,4449,300.47795,9074.02001953125,,,,,,,,,,,,,0,,,,0,,,,,,299.9997559,,,,
,23208869.945,300.0037537,12499.6440429688,3.09338364112158E-5,6.84721662503354E-7,1,0.999253354069792,40.0298881530762,1.99725701706225,15.6299993395805,0.000351385417454782,5.16831015198689E-5,0.25,-7.89551816725554E-7,3.09334365980285E-5,-7.69063291919743E-7,300.0037537,300.0037537,12494.7080078125,12504.580078125,56.7477937531983,20.5515071223222,30.122374,0,0,0,40,4449,300.4653,12499.6440429688,,,,,,,,,,,,,0,,,,0,,,,,,300.0037537,,,,
,23208940.125,300.009552,16008.1245117188,1.96359304104541E-5,9.31430589426815E-7,1,0.999253354069792,40.0298881530762,1.99730117777418,15.6299993395805,0.000223135821783465,3.23369079607005E-5,0.25,-5.42801850264378E-7,1.96357006011987E-5,-5.29803636027968E-7,300.009552,300.009552,16003.27734375,16012.9716796875,56.7954730928714,20.551028527623,29.363071,0,0,0,40,4449,300.4694,16008.1245117188,,,,,,,,,,,,,0,,,,0,,,,,,300.009552,,,,
,23209009.44,300.0102539,19471.0068359375,9.22721384749879E-6,9.01608580376406E-7,1,0.999253354069792,40.0298881530762,1.99726672441163,15.6299993395805,0.000106393194475463,6.30624088827654E-6,0.25,-1.04106595497932E-6,9.22762518078044E-6,-1.03493825856965E-6,300.0102539,300.0102539,19461.201171875,19480.8125,56.7993812354675,20.5530389148699,30.122374,0,0,0,40,4449,300.46185,19471.0068359375,,,,,,,,,,,,,0,,,,-0.00245,,,,,,300.0102539,,,,