File: data/doubleLayers/dl_2-5/ppms/data/DD205_5_HYST_100OE_20K.DAT
[Header]
; VSM Data File (default extension .dat)
; Copyright (c) 2003-2013, Quantum Design, Inc. All rights reserved.
TITLE,
FILEOPENTIME,23131292.23,09/26/2018,2:20 am
BYAPP,VSM,2.0,2.0
INFO,PPMS VSM Option Release 1.4.10 Build 1,APPNAME
INFO,Quantum Design Linear Motor Servo Controller,MOTOR_MODULE_NAME
INFO,3101-100 M1,MOTOR_HW_VERSION
INFO,MMC1014,MOTOR_SERIAL_NUMBER
INFO,SRV No X-over 01.03.11,MOTOR_SOFTWARE_VERSION
INFO,Quantum Design VSM Detection Module,VSM_MODULE_NAME
INFO,3101-150 F0,VSM_HW_VERSION
INFO,VSM707,VSM_SERIAL_NUMBER
INFO,VSM No X-over 01.02.05 May 20 2008 13:51:47,VSM_SOFTWARE_VERSION
INFO,704,PREAMP_SERIAL_NUMBER
INFO,822,COIL_SERIAL_NUMBER
INFO,0,MOMENT_UNITS
INFO,,SAMPLE_MATERIAL
INFO,,SAMPLE_COMMENT
INFO,,SAMPLE_MASS
INFO,,SAMPLE_VOLUME
INFO,,SAMPLE_MOLECULAR_WEIGHT
INFO,,SAMPLE_SIZE
INFO,,SAMPLE_SHAPE
DATATYPE,COMMENT,1
DATATYPE,TIME,2
STARTUPAXIS,X,2
STARTUPAXIS,Y1,5
[Data]
Comment,Time Stamp (sec),Temperature (K),Magnetic Field (Oe),Moment (emu),M. Std. Err. (emu),Transport Action,Averaging Time (sec),Frequency (Hz),Peak Amplitude (mm),Center Position (mm),Coil Signal' (mV),Coil Signal" (mV),Range (mV),M. Quad. Signal (emu),M. Raw' (emu),M. Raw" (emu),Min. Temperature (K),Max. Temperature (K),Min. Field (Oe),Max. Field (Oe),Mass (grams),Motor Lag (deg),Pressure (Torr),VSM Status (code),Motor Status (code),Measure Status (code),Measure Count,PPMS Status (code),System Temp. (K),System Field (Oe),Sample Position (deg),Bridge 1 Resistance (ohms),Bridge 1 Excitation (에),Bridge 2 Resistance (ohms),Bridge 2 Excitation (에),Bridge 3 Resistance (ohms),Bridge 3 Excitation (에),Bridge 4 Resistance (ohms),Bridge 4 Excitation (에),Signal 1 Vin (V),Signal 2 Vin (V),Digital Inputs (code),Drive 1 Iout (mA),Drive 1 Ipower (W),Drive 2 Iout (mA),Drive 2 Ipower (W),Pressure (),Map 20 (),Map 21 (),Map 22 (),Map 23 (),Map 24 (),Map 25 (),Map 26 (),Map 27 (),Map 28 (),Map 29 ()
,23131307.55,19.9851112,-0.3349229991436,,,2,,,,17.0399999022484,,,,,,,19.9851112,19.9851112,-0.3349229991436,-0.3349229991436,,,13.417728,,,,-99999999,4369,20.0661,-0.3349229991436,,,,,,,,,,,,,,,,,,,,,,,19.9851112,,,,
,23131468.19,20.00422575,4990.16015625,6.19192065330263E-5,3.03666097405934E-7,1,0.999253354069792,40.0298881530762,1.99529536435879,17.0200001448393,0.000695259377641779,0.000123655862960635,0.25,-3.60005479285289E-9,6.1580335474163E-5,3.15400471974331E-7,20.0038147,20.0046368,4985.0869140625,4995.2333984375,56.0693401985059,20.5974226536307,13.417728,0,0,0,40,4449,20.0446,4990.16015625,,,,,,,,,,,,,0,,,,-0.0049,,,,,,20.00422575,,,,
,23131565.115,19.9992027,9836.85400390625,4.82901960919607E-5,3.65899245207402E-7,1,0.999253354069792,40.0298881530762,1.99545057523965,17.0200001448393,0.000542612533272967,9.5650689892936E-5,0.25,-9.36876809029103E-8,4.80438754915722E-5,1.72575759466199E-7,19.9992027,19.9992027,9831.9091796875,9841.798828125,55.6199037999482,20.5909979297934,13.797379,0,0,0,40,4449,20.0516,9836.85400390625,,,,,,,,,,,,,0,,,,0.0049,,,,,,19.9992027,,,,
,23131670.305,19.9989681,15091.5244140625,3.38466809190626E-5,3.90576403707611E-7,1,0.999253354069792,40.0298881530762,1.99541072157394,17.0200001448393,0.000380935580026048,6.45444364408002E-5,0.25,-3.03309237057545E-7,3.36907067835578E-5,-1.02787639147937E-7,19.9989681,19.9989681,15084.01953125,15099.029296875,56.2162863601213,20.5913876356948,13.038077,0,0,0,40,4449,20.05455,15091.5244140625,,,,,,,,,,,,,0,,,,-0.00245,,,,,,19.9989681,,,,
,23131767.455,19.998909,19949.15234375,2.02285558223346E-5,3.94508167268683E-7,1,0.999253354069792,40.0298881530762,1.99539202502664,17.0200001448393,0.000229602224717733,2.83601472621393E-5,0.25,-1.09813147390018E-6,2.01503168630611E-5,-9.67904800393221E-7,19.998909,19.998909,19946.703125,19951.6015625,56.4288893173521,20.5923334529686,13.797379,0,0,0,40,4449,20.0539,19949.15234375,,,,,,,,,,,,,0,,,,-0.0049,,,,,,19.998909,,,,
,23131862.06,19.99893855,24676.7822265625,7.14621615058106E-6,4.14179741461549E-7,1,0.999253354069792,40.0298881530762,1.99534543852774,17.0200001448393,8.26553013516428E-5,1.62995213271752E-6,0.25,-1.13636808613969E-6,7.12691100080254E-6,-1.08570249168362E-6,19.998909,19.9989681,24669.427734375,24684.13671875,56.3773018350829,20.5956828416036,14.177031,0,0,0,40,4449,20.0554,24676.7822265625,,,,,,,,,,,,,0,,,,0.0049,,,,,,19.99893855,,,,
,23131955.565,20.00039865,29349.8330078125,-6.07663486318625E-6,6.5051730923253E-7,1,0.999253354069792,40.0298881530762,1.99538281895138,17.0200001448393,-6.60504677163235E-5,-2.51785728305528E-5,0.25,-1.14685922738912E-6,-6.0491385832309E-6,-1.18410502338028E-6,20.0003357,20.0004616,29342.53125,29357.134765625,56.3319673809675,20.5880869259254,13.797379,0,0,0,40,4449,20.05385,29349.8330078125,,,,,,,,,,,,,0,,,,0,,,,,,20.00039865,,,,
,23132052.975,20.0040703,34217.123046875,-2.00663838097683E-5,5.71161166102775E-7,1,0.999253354069792,40.0298881530762,1.99526625857476,17.0200001448393,-0.000223073273169671,-5.60977633402982E-5,0.25,-1.37662029168412E-6,-2.00018227130873E-5,-1.51250449446516E-6,20.0040703,20.0040703,34209.73046875,34224.515625,56.6477453027368,20.5920356497343,13.797379,0,0,0,40,4449,20.0529,34217.123046875,,,,,,,,,,,,,0,,,,-0.00245,,,,,,20.0040703,,,,
,23132148.18,20.0031929,38977.025390625,-3.36580782747008E-5,6.72643268649116E-7,1,0.999253354069792,40.0298881530762,1.99528785485669,17.0200001448393,-0.000375835639348232,-8.59307222408245E-5,0.25,-1.5741805088177E-6,-3.35715912777513E-5,-1.81065775889026E-6,20.0031929,20.0031929,38971.875,38982.17578125,56.3952792910252,20.5892867969133,13.797379,0,0,0,40,4449,20.0476,38977.025390625,,,,,,,,,,,,,0,,,,0,,,,,,20.0031929,,,,
,23132241.045,20.0031853,43617.08203125,-4.77381294683193E-5,7.16113001899133E-7,1,0.999253354069792,40.0298881530762,1.99523718090357,17.0200001448393,-0.000535669855024514,-0.000108787813054762,0.25,-1.05984988010463E-6,-4.76469826785849E-5,-1.40451606100569E-6,20.0031853,20.0031853,43609.5234375,43624.640625,56.2241026453136,20.5913510442695,13.797379,0,0,0,40,4449,20.0446,43617.08203125,,,,,,,,,,,,,0,,,,-0.00245,,,,,,20.0031853,,,,
,23132333.11,20.0022507,48220.029296875,-6.22117521962612E-5,5.79430550758225E-7,1,0.999253354069792,40.0298881530762,1.99531160397112,17.0200001448393,-0.00069734937961238,-0.000147870969506014,0.25,-1.91042546511719E-6,-6.21185708858365E-5,-2.36529034533624E-6,20.0022507,20.0022507,48217.63671875,48222.421875,56.6837002146214,20.5907419476352,13.797379,0,0,0,40,4449,20.04375,48220.029296875,,,,,,,,,,,,,0,,,,0,,,,,,20.0022507,,,,
,23132429.415,20.0013962,53035.146484375,-7.68328501038764E-5,6.41869432431041E-7,1,0.999253354069792,40.0298881530762,1.99451299241519,17.0200001448393,-0.000862232953684712,-0.000177630018632357,0.25,-1.91033326371324E-6,-7.67582387108445E-5,-2.47829248936006E-6,20.0013962,20.0013962,53030.3359375,53039.95703125,56.8064158921406,20.6118879532332,13.797379,0,0,0,40,4449,20.04325,53035.146484375,,,,,,,,,,,,,0,,,,0,,,,,,20.0013962,,,,
,23132529.365,20.0013542,58028.025390625,-9.31338115534963E-5,1.07465073814723E-6,1,0.999253354069792,40.0298881530762,1.99417657070851,17.0200001448393,-0.00104424273899091,-0.000222387424963515,0.25,-2.93414780522359E-6,-9.30839415422357E-5,-3.62624673366444E-6,20.0013542,20.0013542,58023.0390625,58033.01171875,55.9638203484098,20.6126618407602,13.797379,0,0,0,40,4449,20.04105,58028.025390625,,,,,,,,,,,,,0,,,,0,,,,,,20.0013542,,,,
,23132624.075,20.00100995,62763.490234375,-0.000107369997369739,7.32180772144486E-7,1,0.999253354069792,40.0298881530762,1.9943137589318,17.0200001448393,-0.00120730214885441,-0.000240821515004338,0.25,-1.9924643642533E-6,-0.000107370286778263,-2.79152547826516E-6,20.0007668,20.0012531,62761.0078125,62765.97265625,56.2702187279483,20.6102115803597,13.797379,0,0,0,40,4449,20.0415,62763.490234375,,,,,,,,,,,,,0,,,,-0.0049,,,,,,20.00100995,,,,
,23132719.43,20.0029659,67528.734375,-0.000120938379196502,7.31599015499534E-7,1,0.999253354069792,40.0298881530762,1.99442714462568,17.0200001448393,-0.00135790663700959,-0.00028588754903215,0.25,-3.5326779427902E-6,-0.00012098051657797,-4.43126541673543E-6,20.0029659,20.0029659,67523.96875,67533.5,55.9794529187944,20.6083170142396,13.417728,0,0,0,40,4449,20.0416,67528.734375,,,,,,,,,,,,,0,,,,-0.0049,,,,,,20.0029659,,,,
,23132815.18,20.0017242,72314.05078125,-0.000138545974124289,9.40956320909776E-7,1,0.999253354069792,40.0298881530762,1.99499267787515,17.0200001448393,-0.00155875954861407,-0.000316066991110151,0.25,-3.02128100607286E-6,-0.000138658026920333,-4.04475931996027E-6,20.0017242,20.0017242,72311.65625,72316.4453125,56.3061736398329,20.6035060986498,13.797379,0,0,0,40,4449,20.03865,72314.05078125,,,,,,,,,,,,,0,,,,-0.0049,,,,,,20.0017242,,,,
,23132908.05,20.0022755,76957.09765625,-0.000154149219546962,8.17338155481933E-7,1,0.999253354069792,40.0298881530762,1.99520895089494,17.0200001448393,-0.00173429144047132,-0.000356507344841734,0.25,-3.7856409739125E-6,-0.000154328243942818,-4.91640438457589E-6,20.0022755,20.0022755,76954.5390625,76959.65625,56.2960124690829,20.5898161899066,14.177031,0,0,0,40,4449,20.0369,76957.09765625,,,,,,,,,,,,,0,,,,0,,,,,,20.0022755,,,,
,23133004.185,20.0024338,81762.890625,-0.000169510498777893,8.09901524847327E-7,1,0.999253354069792,40.0298881530762,1.99528234859096,17.0200001448393,-0.0019071183334224,-0.000396404677252587,0.25,-4.5498245261321E-6,-0.000169766331731993,-5.78171636325121E-6,20.0022812,20.0025864,81757.8984375,81767.8828125,55.832506757179,20.592798200412,14.177031,0,0,0,40,4449,20.034,81762.890625,,,,,,,,,,,,,0,,,,0,,,,,,20.0024338,,,,
,23133098.05,20.0019875,86453.38671875,-0.000182465965316138,9.09210516379778E-7,1,0.999253354069792,40.0298881530762,1.99523726586832,17.0200001448393,-0.00205228522744011,-0.000433685472151494,0.25,-5.52041614288472E-6,-0.000182798024762825,-6.83270377670143E-6,20.0019875,20.0019875,86450.90625,86455.8671875,56.6602513590445,20.5907540581994,13.797379,0,0,0,40,4449,20.0351,86453.38671875,,,,,,,,,,,,,0,,,,0,,,,,,20.0019875,,,,
,23133205.55,19.99970435,89136.69140625,-0.000192613193253721,9.17199331864906E-7,1,0.999253354069792,40.0298881530762,1.99514415405147,17.0200001448393,-0.00216851392313592,-0.000447857670252208,0.25,-4.95369272712571E-6,-0.000193005091242919,-6.32714861890059E-6,19.9996395,19.9997692,89126.5234375,89146.859375,56.1717335345252,20.5893797447085,13.417728,0,0,0,40,4449,20.0347,89136.69140625,,,,,,,,,,,,,0,,,,0,,,,,,19.99970435,,,,
,23133297.595,20.0010033,84536.546875,-0.000176691556043072,9.03859739993693E-7,1,0.999253354069792,40.0298881530762,1.99526583857795,17.0200001448393,-0.00198558539886846,-0.000428318114932727,0.25,-6.08228552673914E-6,-0.000176984054951182,-7.36055248301039E-6,20.0010033,20.0010033,84529.171875,84543.921875,56.6289862182752,20.5856664441942,13.797379,0,0,0,40,4449,20.0347,84536.546875,,,,,,,,,,,,,0,,,,-0.0049,,,,,,20.0010033,,,,
,23133391.945,20.0008259,79820.14453125,-0.000162374146944366,9.40591857355172E-7,1,0.999253354069792,40.0298881530762,1.99519080853874,17.0200001448393,-0.00182527505950209,-0.000386367991664477,0.25,-4.9473405194721E-6,-0.000162591432559317,-6.13324798783022E-6,20.0008259,20.0008259,79815.25,79825.0390625,56.6031924771406,20.5863751414967,13.797379,0,0,0,40,4449,20.0335,79820.14453125,,,,,,,,,,,,,0,,,,-0.00245,,,,,,20.0008259,,,,
,23133487.645,20.0010815,75036.4765625,-0.000147907856607436,7.66703235057501E-7,1,0.999253354069792,40.0298881530762,1.99515559353398,17.0200001448393,-0.00166615458279694,-0.000328813577814642,0.25,-2.45987762835221E-6,-0.000148065779921583,-3.54708443954009E-6,20.0010815,20.0010815,75026.390625,75046.5625,56.1811130767559,20.5886090513719,13.417728,0,0,0,40,4449,20.0345,75036.4765625,,,,,,,,,,,,,0,,,,-0.00245,,,,,,20.0010815,,,,
,23133582.56,19.999733,70290.79296875,-0.000131836742911833,9.36179638299559E-7,1,0.999253354069792,40.0298881530762,1.99520617294844,17.0200001448393,-0.00148285926441064,-0.000302501852695957,0.25,-3.02773589641146E-6,-0.000131919980690311,-4.00425501057309E-6,19.999733,19.999733,70283.2578125,70298.328125,56.3874630058329,20.5876374096864,14.177031,0,0,0,40,4449,20.0343,70290.79296875,,,,,,,,,,,,,0,,,,-0.00245,,,,,,19.999733,,,,
,23133678.03,19.9986534,65520.580078125,-0.000116806317936226,9.32907092242694E-7,1,0.999253354069792,40.0298881530762,1.99514457090445,17.0200001448393,-0.00131283735747586,-0.000270023283505391,0.25,-2.86612669487375E-6,-0.000116830435208909,-3.73480053781962E-6,19.9986534,19.9986534,65515.9140625,65525.24609375,55.7637234474867,20.589294793713,14.556682,0,0,0,40,4449,20.03505,65520.580078125,,,,,,,,,,,,,0,,,,0,,,,,,19.9986534,,,,
,23133773.675,19.9984493,60737.171875,-0.000100804159366803,8.82456801375946E-7,1,0.999253354069792,40.0298881530762,1.99519693304621,17.0200001448393,-0.00113163291120955,-0.000237844536758601,0.25,-2.90658060811232E-6,-0.000100777893103153,-3.65675484973202E-6,19.9984493,19.9984493,60727.078125,60747.265625,56.2960124690829,20.5905912869338,13.417728,0,0,0,40,4449,20.03665,60737.171875,,,,,,,,,,,,,0,,,,0.0049,,,,,,19.9984493,,,,
,23133868.285,19.9985466,56009.3828125,-8.6545116979337E-5,8.7019528324382E-7,1,0.999253354069792,40.0298881530762,1.99514793427639,17.0200001448393,-0.000969482499075833,-0.000213084271587025,0.25,-3.29218130334271E-6,-8.64777962610012E-5,-3.93383653615752E-6,19.9985466,19.9985466,56004.40234375,56014.36328125,56.4499932873714,20.5900191647812,14.177031,0,0,0,40,4449,20.0401,56009.3828125,,,,,,,,,,,,,0,,,,0.00245,,,,,,19.9985466,,,,
,23133961.3,19.9996262,51362.203125,-7.24928819257416E-5,6.86056052501186E-7,1,0.999253354069792,40.0298881530762,1.99514846867304,17.0200001448393,-0.000811102621055041,-0.000181703383740305,0.25,-3.05280719196947E-6,-7.24011665005307E-5,-3.58593235940173E-6,19.9996262,19.9996262,51357.07421875,51367.33203125,56.9674313671022,20.5905564656997,13.417728,0,0,0,40,4449,20.037,51362.203125,,,,,,,,,,,,,0,,,,0.00245,,,,,,19.9996262,,,,
,23134057.58,20.0003853,46549.421875,-5.64005092273332E-5,8.56413775226946E-7,1,0.999253354069792,40.0298881530762,1.99516119092817,17.0200001448393,-0.000629119791044938,-0.000150324179430252,0.25,-3.17988577943925E-6,-5.62958001185268E-5,-3.58821379361727E-6,20.0003853,20.0003853,46539.3671875,46559.4765625,56.9760292808137,20.5927066740649,14.177031,0,0,0,40,4449,20.0384,46549.421875,,,,,,,,,,,,,0,,,,0,,,,,,20.0003853,,,,
,23134152.895,20.0004787,41786.341796875,-4.20614669011036E-5,7.00443773132846E-7,1,0.999253354069792,40.0298881530762,1.99513897903429,17.0200001448393,-0.000469972480062921,-0.00010630998666522,0.25,-1.86626888496754E-6,-4.1966404393377E-5,-2.1660162828687E-6,20.0004787,20.0004787,41781.25,41791.43359375,56.0802829977752,20.5914469419652,13.797379,0,0,0,40,4449,20.0375,41786.341796875,,,,,,,,,,,,,0,,,,0,,,,,,20.0004787,,,,
,23134247.415,20.0005817,37061.517578125,-2.75847711270707E-5,7.51119147229482E-7,1,0.999253354069792,40.0298881530762,1.99521285929184,17.0200001448393,-0.00030485359352928,-8.76026264473177E-5,0.25,-2.81907086592022E-6,-2.74975722857727E-5,-3.00712346260977E-6,20.0005817,20.0005817,37059.1171875,37063.91796875,56.5156500829868,20.5918767473621,13.797379,0,0,0,40,4449,20.03735,37061.517578125,,,,,,,,,,,,,0,,,,0.00245,,,,,,20.0005817,,,,
,23134343.66,19.998642,32251.5615234375,-1.25549213811366E-5,6.81925920988961E-7,1,0.999253354069792,40.0298881530762,1.99529043476827,17.0200001448393,-0.000137365786642983,-4.72103299325808E-5,0.25,-1.93918943333438E-6,-1.25045750791784E-5,-2.01981615778017E-6,19.998642,19.998642,32241.53125,32261.591796875,56.841589175506,20.5937568071941,13.797379,0,0,0,40,4449,20.0364,32251.5615234375,,,,,,,,,,,,,0,,,,0.0049,,,,,,19.998642,,,,
,23134437.475,19.9975739,27562.0400390625,1.87434214088738E-6,4.8401277112793E-7,1,0.999253354069792,40.0298881530762,1.99522042722506,17.0200001448393,2.47734960000236E-5,-1.67828829975401E-5,0.25,-1.82844045152298E-6,1.88006156666185E-6,-1.80968346454572E-6,19.9975739,19.9975739,27554.58203125,27569.498046875,56.005246659929,20.5933895193628,14.177031,0,0,0,40,4449,20.03825,27562.0400390625,,,,,,,,,,,,,0,,,,-0.00245,,,,,,19.9975739,,,,
,23134533.22,19.9983768,22776.7705078125,1.52772758555159E-5,4.25321939567547E-7,1,0.999253354069792,40.0298881530762,1.99531325906738,17.0200001448393,0.000174217201126532,1.71256229891094E-5,0.25,-1.21430745297551E-6,1.52250454287028E-5,-1.11199626775313E-6,19.9983768,19.9983768,22771.81640625,22781.724609375,56.5844333926791,20.5948781833196,14.177031,0,0,0,40,4449,20.0397,22776.7705078125,,,,,,,,,,,,,0,,,,0,,,,,,19.9983768,,,,
,23134626.905,19.9996796,18094.0224609375,2.85531884448603E-5,3.92230237196549E-7,1,0.999253354069792,40.0298881530762,1.99524530892798,17.0200001448393,0.000321946887265015,5.15376714108279E-5,0.25,-5.21826855444511E-7,2.84312131339647E-5,-3.4571050327014E-7,19.9996796,19.9996796,18089.083984375,18098.9609375,55.8293802431021,20.5917094904014,13.797379,0,0,0,40,4449,20.0379,18094.0224609375,,,,,,,,,,,,,0,,,,0,,,,,,19.9996796,,,,
,23134721.18,20.0018883,13384.03125,4.18719988753304E-5,4.15427107923538E-7,1,0.999253354069792,40.0298881530762,1.99526513247311,17.0200001448393,0.000471302110731145,7.89935229763419E-5,0.25,-4.44662361697021E-7,4.16730186873811E-5,-2.0128319885857E-7,20.0018883,20.0018883,13381.7880859375,13386.2744140625,56.2436433582944,20.59157972444,13.797379,0,0,0,40,4449,20.03585,13384.03125,,,,,,,,,,,,,0,,,,0.00245,,,,,,20.0018883,,,,
,23134817.765,20.0033054,8556.26220703125,5.51823565486131E-5,3.28362133080925E-7,1,0.999253354069792,40.0298881530762,1.99528406217127,17.0200001448393,0.000620205645824924,0.000107808831034376,0.25,-2.3306611528203E-7,5.48959420833817E-5,6.66643253394978E-8,20.0033054,20.0033054,8543.5166015625,8569.0078125,56.5007991411214,20.5951091261178,13.797379,0,0,0,40,4449,20.0343,8556.26220703125,,,,,,,,,,,,,0,,,,0,,,,,,20.0033054,,,,
,23134912.315,20.0073681,3828.75024414063,6.70781148196747E-5,3.06511344108225E-7,1,0.999253354069792,40.0298881530762,1.99522423744754,17.0200001448393,0.000754020711641565,0.000128778081937403,0.25,-4.58531651702938E-7,6.67081714914691E-5,-1.15874165970165E-7,20.0073681,20.0073681,3826.26220703125,3831.23828125,56.1115481385444,20.5937488431266,14.177031,0,0,0,40,4449,20.02725,3828.75024414063,,,,,,,,,,,,,0,,,,-0.0049,,,,,,20.0073681,,,,
,23135008.125,19.9956493,-960.959930419922,6.96084256831652E-5,3.21545824557267E-7,1,0.999253354069792,40.0298881530762,1.99528636542736,17.0200001448393,0.000781110159720943,0.000140640063055409,0.25,1.62272824832979E-7,6.9210022913528E-5,5.01737946991868E-7,19.9956493,19.9956493,-965.932983398438,-955.986877441406,56.9244417985445,20.5936599265797,14.177031,0,0,0,40,4449,20.0309,-960.959930419922,,,,,,,,,,,,,0,,,,-0.0049,,,,,,19.9956493,,,,
,23135107.01,20.0007935,-5898.92211914062,7.79597033791842E-5,2.42057008575036E-7,1,0.999253354069792,40.0298881530762,1.99526376225472,17.0200001448393,0.000874489546157946,0.00016088033055329,0.25,4.5205060292175E-7,7.75355387263873E-5,8.56240357656884E-7,20.0007935,20.0007935,-5906.3349609375,-5891.50927734375,56.4836033136983,20.5954360577735,13.797379,0,0,0,40,4449,20.02565,-5898.92211914062,,,,,,,,,,,,,0,,,,0.00245,,,,,,20.0007935,,,,
,23135200.375,19.9964199,-10567.3173828125,8.38644649014236E-5,3.52679596811177E-7,1,0.999253354069792,40.0298881530762,1.99539297188701,17.0200001448393,0.000940713943753248,0.000175422471984645,0.25,6.61016782890673E-7,8.34370680107451E-5,1.12371789602947E-6,19.9964199,19.9964199,-10574.77734375,-10559.857421875,56.3390020376406,20.5958701932575,14.177031,0,0,0,40,4449,20.0316,-10567.3173828125,,,,,,,,,,,,,0,,,,-0.0049,,,,,,19.9964199,,,,
,23135295.185,19.9964552,-15305.3110351562,8.13846923142239E-5,4.21476058702398E-7,1,0.999253354069792,40.0298881530762,1.99532446612884,17.0200001448393,0.00091250796560711,0.00017442064816235,0.25,9.80561470544275E-7,8.10011236208343E-5,1.45596035569633E-6,19.9964066,19.9965038,-15307.5966796875,-15303.025390625,56.7423223535637,20.5935157780313,14.177031,0,0,0,40,4449,20.035,-15305.3110351562,,,,,,,,,,,,,0,,,,0,,,,,,19.9964552,,,,
,23135390.95,19.9966774,-20089.7314453125,6.7432930387785E-5,4.97753305319583E-7,1,0.999253354069792,40.0298881530762,1.99528840440118,17.0200001448393,0.000755490881612401,0.000149686900775844,0.25,1.24501246881904E-6,6.71425455100129E-5,1.65911293199506E-6,19.9966774,19.9966774,-20094.607421875,-20084.85546875,57.1034347294484,20.595528522214,14.177031,0,0,0,40,4449,20.0385,-20089.7314453125,,,,,,,,,,,,,0,,,,0.0049,,,,,,19.9966774,,,,
,23135489.68,19.9972839,-25024.4931640625,4.71291103534634E-5,5.185649424395E-7,1,0.999253354069792,40.0298881530762,1.99532584486943,17.0200001448393,0.000526880144565589,0.000112497385496291,0.25,1.5522542028019E-6,4.69446498666549E-5,1.85358213015489E-6,19.9972839,19.9972839,-25037.08984375,-25011.896484375,56.6883899857368,20.5960734571363,14.177031,0,0,0,40,4449,20.03875,-25024.4931640625,,,,,,,,,,,,,0,,,,-0.00245,,,,,,19.9972839,,,,
,23135584.8,19.9988194,-29779.4296875,3.64226263919028E-5,5.51971276762294E-7,1,0.999253354069792,40.0298881530762,1.99528765789475,17.0200001448393,0.000407393557403054,8.68943022769831E-5,0.25,1.18288700340307E-6,3.62977959770856E-5,1.42544977182943E-6,19.9988194,19.9988194,-29789.478515625,-29769.380859375,56.2233210167944,20.5946443009301,13.797379,0,0,0,40,4449,20.0388,-29779.4296875,,,,,,,,,,,,,0,,,,-0.00245,,,,,,19.9988194,,,,
,23135680.35,20.0007515,-34554.044921875,3.54052449992272E-5,7.04567868077002E-7,1,0.999253354069792,40.0298881530762,1.9952683163746,17.0200001448393,0.000394981786902592,9.13294444335616E-5,0.25,1.74851697707341E-6,3.52972986925883E-5,1.99066962441681E-6,20.0007515,20.0007515,-34561.4609375,-34546.62890625,56.4460851447752,20.5981972791936,13.417728,0,0,0,40,4449,20.03745,-34554.044921875,,,,,,,,,,,,,0,,,,0,,,,,,20.0007515,,,,
,23135774.69,20.0012026,-39268.708984375,4.19766761853043E-5,6.69795027574672E-7,1,0.999253354069792,40.0298881530762,1.99531232166647,17.0200001448393,0.000467817389372876,0.000112317659909522,0.25,2.41969806962505E-6,4.18668245104242E-5,2.71405671645802E-6,20.0011044,20.0013008,-39278.72265625,-39258.6953125,56.1498479359867,20.5995160766542,14.177031,0,0,0,40,4449,20.03725,-39268.708984375,,,,,,,,,,,,,0,,,,-0.00245,,,,,,20.0012026,,,,
,23135871.17,20.0009193,-44091.17578125,5.33077332606699E-5,6.49095321608627E-7,1,0.999253354069792,40.0298881530762,1.99531639190645,17.0200001448393,0.000594654111285995,0.000141283870101282,0.25,2.93967164594367E-6,5.31958044307723E-5,3.32221307947522E-6,20.0009193,20.0009193,-44096.015625,-44086.3359375,56.8095424062176,20.599369752577,14.177031,0,0,0,40,4449,20.0371,-44091.17578125,,,,,,,,,,,,,0,,,,-0.0049,,,,,,20.0009193,,,,
,23135965.3,20.0004845,-48796.244140625,6.58548448076714E-5,8.21536484802404E-7,1,0.999253354069792,40.0298881530762,1.99526106482873,17.0200001448393,0.000737546440080962,0.000160225474617229,0.25,2.3490724799061E-6,6.57576509066677E-5,2.83089690735287E-6,20.0004845,20.0004845,-48803.828125,-48788.66015625,56.5688008222944,20.599939484862,13.417728,0,0,0,40,4449,20.03545,-48796.244140625,,,,,,,,,,,,,0,,,,0.00245,,,,,,20.0004845,,,,
,23136059.985,20.000227,-53528.62109375,7.87309968352237E-5,5.36613514936053E-7,1,0.999253354069792,40.0298881530762,1.99525722893055,17.0200001448393,0.000880700459933356,0.000199800813171033,0.25,3.52751965278158E-6,7.86467302705784E-5,4.108789857199E-6,20.000227,20.000227,-53531.15625,-53526.0859375,56.2327005590252,20.5972820126276,13.417728,0,0,0,40,4449,20.0361,-53528.62109375,,,,,,,,,,,,,0,,,,-0.00245,,,,,,20.000227,,,,
,23136156.52,19.9998531,-58350.7890625,9.37330805142856E-5,9.06152417590633E-7,1,0.999253354069792,40.0298881530762,1.99530445885649,17.0200001448393,0.00104994684226527,0.000232904213249336,0.25,3.74694431512233E-6,9.36798548998088E-5,4.44344409479639E-6,19.9998531,19.9998531,-58358.54296875,-58343.03515625,56.3085185253906,20.6002774778909,13.797379,0,0,0,40,4449,20.0365,-58350.7890625,,,,,,,,,,,,,0,,,,0.00245,,,,,,19.9998531,,,,
,23136256.825,20.0017891,-63365.814453125,0.000108595884417435,8.90578617982193E-7,1,0.999253354069792,40.0298881530762,1.99529920861059,17.0200001448393,0.00121739232660185,0.00026776051706844,0.25,4.14704797912769E-6,0.000108586267174832,4.95554477984245E-6,20.0016308,20.0019474,-63375.74609375,-63355.8828125,56.4476484018137,20.5990688380986,13.797379,0,0,0,40,4449,20.0355,-63365.814453125,,,,,,,,,,,,,0,,,,0.00245,,,,,,20.0017891,,,,
,23136352.37,20.0013313,-68140.30078125,0.000124728569928875,8.64366717190479E-7,1,0.999253354069792,40.0298881530762,1.99530715864731,17.0200001448393,0.00139846410624639,0.000309764806653292,0.25,4.95265052392186E-6,0.000124768937014781,5.87978586051272E-6,20.0013313,20.0013313,-68147.6953125,-68132.90625,56.8744175733137,20.6056589059686,14.177031,0,0,0,40,4449,20.0334,-68140.30078125,,,,,,,,,,,,,0,,,,-0.00245,,,,,,20.0013313,,,,
,23136451.14,20.0023804,-73076.80078125,0.000138899633920585,9.06403556301736E-7,1,0.999253354069792,40.0298881530762,1.99526164050467,17.0200001448393,0.00155843654862005,0.000342471923394077,0.25,5.29083225211162E-6,0.000139004025851985,6.31814988662058E-6,20.0023804,20.0023804,-73079.1171875,-73074.484375,56.8056342636214,20.6061704735118,13.797379,0,0,0,40,4449,20.0325,-73076.80078125,,,,,,,,,,,,,0,,,,0,,,,,,20.0023804,,,,
,23136551.13,20.0016842,-78074.1640625,0.000156079872831196,1.00797617022035E-6,1,0.999253354069792,40.0298881530762,1.9953456311975,17.0200001448393,0.00175192671152385,0.000385197395690883,0.25,5.97437407985669E-6,0.000156259057799594,7.11994861824041E-6,20.0016842,20.0016842,-78076.359375,-78071.96875,56.3960609195444,20.604210440311,13.417728,0,0,0,40,4449,20.0306,-78074.1640625,,,,,,,,,,,,,0,,,,0,,,,,,20.0016842,,,,
,23136649.805,20.0011711,-83003.6328125,0.000173338774281666,8.43916955940131E-7,1,0.999253354069792,40.0298881530762,1.99530154127044,17.0200001448393,0.00194617667335084,0.000428768930146763,0.25,6.72375722952536E-6,0.000173601174340736,7.98360571594328E-6,20.0011711,20.0011711,-83008.734375,-82998.53125,56.3257143528137,20.6053757875449,13.797379,0,0,0,40,4449,20.0297,-83003.6328125,,,,,,,,,,,,,0,,,,0,,,,,,20.0011711,,,,
,23136740.145,20.0011177,-87518.17578125,0.000187302273210077,8.80205686644822E-7,1,0.999253354069792,40.0298881530762,1.99529560494628,17.0200001448393,0.00210537883214723,0.000453648535804336,0.25,6.41571816655064E-6,0.000187651530629701,7.76063067322899E-6,20.0011177,20.0011177,-87525.984375,-87510.3671875,56.2162863601213,20.604922399484,13.797379,0,0,0,40,4449,20.02915,-87518.17578125,,,,,,,,,,,,,0,,,,0,,,,,,20.0011177,,,,
,23136850.795,20.0000896,-87926.05859375,0.000189416927054083,1.1098340490053E-6,1,0.999253354069792,40.0298881530762,1.99529938349588,17.0200001448393,0.00213252414342622,0.000440368162771278,0.25,4.86164058389047E-6,0.000189786944332456,6.21681151379515E-6,20.0000896,20.0000896,-87933.40625,-87918.7109375,56.3866813773137,20.6059988491315,13.797379,0,0,0,40,4449,20.0253,-87926.05859375,,,,,,,,,,,,,0,,,,0,,,,,,20.0000896,,,,
,23136942.62,19.9989872,-83336.47265625,0.000173635416364663,1.0077541199976E-6,1,0.999253354069792,40.0298881530762,1.99530053191904,17.0200001448393,0.00195185636335078,0.000416716045181063,0.25,5.6046145743445E-6,0.000173910589431539,6.86362738581405E-6,19.9989872,19.9989872,-83341.5703125,-83331.375,56.496109370006,20.6045108131432,14.177031,0,0,0,40,4449,20.03005,-83336.47265625,,,,,,,,,,,,,0,,,,0.0049,,,,,,19.9989872,,,,
,23137041.04,19.9993134,-78418.99609375,0.000158970237705185,8.3419397619067E-7,1,0.999253354069792,40.0298881530762,1.99527464557792,17.0200001448393,0.00178338600375334,0.00039771716566147,0.25,6.56276610856684E-6,0.000159153489900815,7.72952316210935E-6,19.9993134,19.9993134,-78423.96875,-78414.0234375,56.6031924771406,20.6026600228427,14.177031,0,0,0,40,4449,20.0296,-78418.99609375,,,,,,,,,,,,,0,,,,0,,,,,,19.9993134,,,,
,23137138.15,19.9997501,-73566.9140625,0.000141908978225702,9.42451082343598E-7,1,0.999253354069792,40.0298881530762,1.99541037507869,17.0200001448393,0.00159304104223073,0.000346249926710323,0.25,5.0806203247908E-6,0.000142023704027995,6.12917752476409E-6,19.9995422,19.999958,-73571.90625,-73561.921875,56.2881961838906,20.6004105416571,13.797379,0,0,0,40,4449,20.031,-73566.9140625,,,,,,,,,,,,,0,,,,0,,,,,,19.9997501,,,,
,23137232.575,19.9971523,-68847.6875,0.000126064200450673,5.65601185646948E-7,1,0.999253354069792,40.0298881530762,1.99532325053693,17.0200001448393,0.00141479517743689,0.000306117326235001,0.25,4.38793711994199E-6,0.00012611726152566,5.32411154193493E-6,19.9971523,19.9971523,-68860.2578125,-68835.1171875,56.299920611679,20.6022285961335,14.177031,0,0,0,40,4449,20.03035,-68847.6875,,,,,,,,,,,,,0,,,,0.00245,,,,,,19.9971523,,,,
,23137331.165,19.9979,-63920.388671875,0.000109983267636264,7.67091405071438E-7,1,0.999253354069792,40.0298881530762,1.99536792404748,17.0200001448393,0.00123361491511912,0.000268057126374861,0.25,3.92156333117345E-6,0.000109981121642832,4.74029351743186E-6,19.9978752,19.9979248,-63922.77734375,-63918,56.7978179784291,20.6019054519318,13.797379,0,0,0,40,4449,20.0335,-63920.388671875,,,,,,,,,,,,,0,,,,0,,,,,,19.9979,,,,
,23137427.775,19.9983654,-59092.9921875,9.52437599966524E-5,9.30417923933319E-7,1,0.999253354069792,40.0298881530762,1.99524000416467,17.0200001448393,0.001067229532171,0.000234898669430516,0.25,3.65051894605055E-6,9.51975343336793E-5,4.35866442868536E-6,19.9983654,19.9983654,-59100.30078125,-59085.68359375,55.9192675228136,20.600218006418,14.177031,0,0,0,40,4449,20.03435,-59092.9921875,,,,,,,,,,,,,0,,,,0.00245,,,,,,19.9983654,,,,
,23137525.535,19.9979057,-54205.755859375,8.02568481756831E-5,8.90663224598235E-7,1,0.999253354069792,40.0298881530762,1.99530335095495,17.0200001448393,0.00089782901481252,0.000203799518708255,0.25,3.60509793964074E-6,8.01762178648385E-5,4.19830365485978E-6,19.9979057,19.9979057,-54213.3359375,-54198.17578125,56.4257628032752,20.6000663611885,14.177031,0,0,0,40,4449,20.0355,-54205.755859375,,,,,,,,,,,,,0,,,,0,,,,,,19.9979057,,,,
,23137620.965,19.9990406,-49438.92578125,6.49785704571125E-5,7.71489909628939E-7,1,0.999253354069792,40.0298881530762,1.99528247655804,17.0200001448393,0.000725479659290826,0.000170913417999952,0.25,3.45340214311744E-6,6.48785285830033E-5,3.92828661287134E-6,19.9990406,19.9990406,-49446.2734375,-49431.578125,56.679010443506,20.6035208405338,14.177031,0,0,0,40,4449,20.0355,-49438.92578125,,,,,,,,,,,,,0,,,,0,,,,,,19.9990406,,,,
,23137717.19,20.0001793,-44629.20703125,4.99906140710249E-5,7.03764251352808E-7,1,0.999253354069792,40.0298881530762,1.99524544625335,17.0200001448393,0.000558160272754156,0.000129735743218176,0.25,2.51124965003746E-6,4.98902043003616E-5,2.87114908948007E-6,20.0001793,20.0001793,-44634.17578125,-44624.23828125,56.4241995462367,20.5999818976761,14.177031,0,0,0,40,4449,20.0346,-44629.20703125,,,,,,,,,,,,,0,,,,0.00245,,,,,,20.0001793,,,,
,23137812.63,19.9997826,-39856.234375,3.50977414526998E-5,7.6328550838093E-7,1,0.999253354069792,40.0298881530762,1.99529414423184,17.0200001448393,0.00039008920794699,9.9945752194211E-5,0.25,2.55790680165992E-6,3.50042048256589E-5,2.80363824150958E-6,19.9997826,19.9997826,-39866.4609375,-39846.0078125,56.3765202065637,20.6009099313143,13.797379,0,0,0,40,4449,20.03535,-39856.234375,,,,,,,,,,,,,0,,,,0,,,,,,19.9997826,,,,
,23137907.97,19.9988003,-35093.908203125,2.04888486504453E-5,5.91570931165315E-7,1,0.999253354069792,40.0298881530762,1.99520132377093,17.0200001448393,0.000227714505613144,5.76648101316486E-5,0.25,1.43889525743155E-6,2.04245428752393E-5,1.57838666707164E-6,19.9988003,19.9988003,-35098.97265625,-35088.84375,56.4281076888329,20.5976421666302,13.417728,0,0,0,40,4449,20.0347,-35093.908203125,,,,,,,,,,,,,0,,,,-0.0049,,,,,,19.9988003,,,,
,23138005.095,19.9984398,-30239.486328125,6.69089640745771E-6,6.38739503037067E-7,1,0.999253354069792,40.0298881530762,1.99544718560526,17.0200001448393,7.29549177668988E-5,2.65062965732642E-5,0.25,1.15401312668835E-6,6.66192598006254E-6,1.19576989486858E-6,19.9984398,19.9984398,-30242.388671875,-30236.583984375,56.3546346080252,20.6003039599072,14.177031,0,0,0,40,4449,20.03685,-30239.486328125,,,,,,,,,,,,,0,,,,0.0049,,,,,,19.9984398,,,,
,23138100.815,19.9984512,-25457.3642578125,-7.34152499493671E-6,4.74498056558854E-7,1,0.999253354069792,40.0298881530762,1.99527242415267,17.0200001448393,-8.381887666761E-5,-7.80709501819826E-6,0.25,6.22450376275379E-7,-7.31876128084937E-6,5.72163634182377E-7,19.9984512,19.9984512,-25464.796875,-25449.931640625,56.5992843345444,20.6013034610519,13.797379,0,0,0,40,4449,20.0397,-25457.3642578125,,,,,,,,,,,,,0,,,,0,,,,,,19.9984512,,,,
,23138194.445,19.9987068,-20774.8369140625,-2.14684415900684E-5,5.15186533779927E-7,1,0.999253354069792,40.0298881530762,1.99528077645429,17.0200001448393,-0.000242777706633927,-3.51544246598249E-5,0.25,7.16876723540262E-7,-2.138438176625E-5,5.79488871238996E-7,19.9987068,19.9987068,-20782.576171875,-20767.09765625,56.0068099169675,20.5992952033213,14.177031,0,0,0,40,4449,20.0386,-20774.8369140625,,,,,,,,,,,,,0,,,,0.00245,,,,,,19.9987068,,,,
,23138288.3,20.0008984,-16085.390625,-3.40641065553089E-5,3.73692099780402E-7,1,0.999253354069792,40.0298881530762,1.99512534753035,17.0200001448393,-0.000383796434843991,-6.2545006860986E-5,0.25,5.22185609590493E-7,-3.39115171660927E-5,3.17065416310094E-7,20.0008984,20.0008984,-16090.1162109375,-16080.6650390625,56.5000175126021,20.5968676271537,13.797379,0,0,0,40,4449,20.0368,-16085.390625,,,,,,,,,,,,,0,,,,0.00245,,,,,,20.0008984,,,,
,23138383.02,20.0031528,-11350.2124023438,-4.70998918292859E-5,3.70741925630401E-7,1,0.999253354069792,40.0298881530762,1.99521932397234,17.0200001448393,-0.000528553903563088,-9.717150978434E-5,0.25,-2.48595412774318E-7,-4.68635858763926E-5,-5.11790168868008E-7,20.0031528,20.0031528,-11362.6923828125,-11337.732421875,56.4101302328906,20.598793701563,14.177031,0,0,0,40,4449,20.0368,-11350.2124023438,,,,,,,,,,,,,0,,,,0.00245,,,,,,20.0031528,,,,
,23138477.8,20.0038013,-6614.85034179688,-5.97425513513341E-5,3.52703821384407E-7,1,0.999253354069792,40.0298881530762,1.99528670315052,17.0200001448393,-0.000669926068033724,-0.000124754889351594,0.25,-4.7337305106415E-7,-5.94198852548508E-5,-7.8554633389634E-7,20.0038013,20.0038013,-6624.7802734375,-6604.92041015625,56.4140383754867,20.5989112512971,13.797379,0,0,0,40,4449,20.0316,-6614.85034179688,,,,,,,,,,,,,0,,,,0,,,,,,20.0038013,,,,
,23138575.99,20.00500105,-1706.02307128906,-7.11450016818527E-5,3.0760490617268E-7,1,0.999253354069792,40.0298881530762,1.99524232687326,17.0200001448393,-0.000797206943451274,-0.000150270467514506,0.25,-7.43910612199424E-7,-7.07376035146405E-5,-1.09062465091997E-6,20.0048637,20.0051384,-1710.8876953125,-1701.15844726562,56.4054404617752,20.60046355946,14.177031,0,0,0,40,4449,20.0246,-1706.02307128906,,,,,,,,,,,,,0,,,,0,,,,,,20.00500105,,,,
,23138670.825,20.0034809,3031.6025390625,-7.18725074910017E-5,3.31599948698367E-7,1,0.999253354069792,40.0298881530762,1.9952965235114,17.0200001448393,-0.000804876948020109,-0.000154993239459061,0.25,-1.02788380986591E-6,-7.14649238468713E-5,-1.38269546473601E-6,20.0034809,20.0034809,3021.46875,3041.736328125,56.3835548632367,20.5982896338466,13.797379,0,0,0,40,4449,20.027,3031.6025390625,,,,,,,,,,,,,0,,,,-0.0049,,,,,,20.0034809,,,,
,23138765.16,19.9981289,7746.49462890625,-8.04139693520883E-5,3.54050204189683E-7,1,0.999253354069792,40.0298881530762,1.99530121316101,17.0200001448393,-0.000900571637948942,-0.00017487822251004,0.25,-1.24867716943838E-6,-7.99830758392761E-5,-1.67231564923128E-6,19.9981289,19.9981289,7741.44580078125,7751.54345703125,56.6680676442368,20.5996889979518,14.177031,0,0,0,40,4449,20.0264,7746.49462890625,,,,,,,,,,,,,0,,,,0.00245,,,,,,19.9981289,,,,
,23138862.945,19.99547385,12634.5903320312,-8.35826430041241E-5,4.04468067883692E-7,1,0.999253354069792,40.0298881530762,1.99526522721476,17.0200001448393,-0.000935658864115841,-0.000186059191016872,0.25,-1.64380845565348E-6,-8.31655042572121E-5,-2.1128257184772E-6,19.9951954,19.9957523,12629.55078125,12639.6298828125,56.496109370006,20.5987883108803,14.177031,0,0,0,40,4449,20.0291,12634.5903320312,,,,,,,,,,,,,0,,,,-0.00245,,,,,,19.99547385,,,,
,23138962.595,19.997261,17614.7060546875,-7.55040212706932E-5,5.08880163560963E-7,1,0.999253354069792,40.0298881530762,1.99526502445164,17.0200001448393,-0.000843862016591929,-0.000177877388248672,0.25,-2.32416806849308E-6,-7.51555783348532E-5,-2.7711077862998E-6,19.997261,19.997261,17607.056640625,17622.35546875,56.3429101802367,20.6006116972688,14.177031,0,0,0,40,4449,20.03255,17614.7060546875,,,,,,,,,,,,,0,,,,-0.0049,,,,,,19.997261,,,,
,23139060.335,19.997654,22499.4931640625,-5.62827472035376E-5,4.13985789707713E-7,1,0.999253354069792,40.0298881530762,1.99523880888778,17.0200001448393,-0.0006285786103727,-0.000136819559224818,0.25,-2.08539625648186E-6,-5.60469205559294E-5,-2.43556778409399E-6,19.997654,19.997654,22494.62109375,22504.365234375,56.4781319140637,20.601916833494,13.797379,0,0,0,40,4449,20.0366,22499.4931640625,,,,,,,,,,,,,0,,,,-0.00245,,,,,,19.997654,,,,
,23139155.355,19.9986305,27247.533203125,-3.96828132345749E-5,5.55952856185099E-7,1,0.999253354069792,40.0298881530762,1.99526082847521,17.0200001448393,-0.000441876789668428,-0.000105016971449562,0.25,-2.2157845372952E-6,-3.95303642037094E-5,-2.47144646362183E-6,19.9986305,19.9986305,27242.55078125,27252.515625,56.1138930241021,20.5961460782544,14.177031,0,0,0,40,4449,20.03655,27247.533203125,,,,,,,,,,,,,0,,,,-0.0049,,,,,,19.9986305,,,,
,23139251.66,20.0000153,32062.76171875,-3.45698852519662E-5,6.00994083087046E-7,1,0.999253354069792,40.0298881530762,1.99525709846353,17.0200001448393,-0.000382787680744044,-0.000104581899968479,0.25,-3.08207112788034E-6,-3.44461199006946E-5,-3.31038371787873E-6,20.0000153,20.0000153,32055.130859375,32070.392578125,56.9689946241406,20.5976418051577,14.556682,0,0,0,40,4449,20.03725,32062.76171875,,,,,,,,,,,,,0,,,,0,,,,,,20.0000153,,,,
,23139348.535,20.0006351,36904.9609375,-3.6945011879712E-5,6.51652060890926E-7,1,0.999253354069792,40.0298881530762,1.99538927484831,17.0200001448393,-0.00041084035959588,-0.000103360033796752,0.25,-2.53452503921577E-6,-3.68363956838051E-5,-2.78917021459623E-6,20.0006351,20.0006351,36897.578125,36912.34375,56.6868267286983,20.5961715410179,14.177031,0,0,0,40,4449,20.0368,36904.9609375,,,,,,,,,,,,,0,,,,0.0049,,,,,,20.0006351,,,,
,23139444.385,20.0010567,41695.185546875,-4.64056140124206E-5,6.46280702574417E-7,1,0.999253354069792,40.0298881530762,1.99518998488042,17.0200001448393,-0.000517131113819235,-0.000125002980586907,0.25,-2.74376497317049E-6,-4.62953548578914E-5,-3.07300151869599E-6,20.0010567,20.0010567,41690.12890625,41700.2421875,55.8450128134867,20.596133478663,14.177031,0,0,0,40,4449,20.03485,41695.185546875,,,,,,,,,,,,,0,,,,-0.00245,,,,,,20.0010567,,,,
,23139539.1,20.0014324,46430.62890625,-5.77236668473689E-5,7.33343606095269E-7,1,0.999253354069792,40.0298881530762,1.99524245571098,17.0200001448393,-0.000642961643995499,-0.000159042463009664,0.25,-3.71494263068417E-6,-5.76124262229197E-5,-4.13200810173587E-6,20.0014324,20.0014324,46428.046875,46433.2109375,56.5836517641598,20.5953843926466,14.177031,0,0,0,40,4449,20.0328,46430.62890625,,,,,,,,,,,,,0,,,,0.00245,,,,,,20.0014324,,,,
,23139636.775,20.0003242,51312.91796875,-7.26486131463225E-5,7.81538222204498E-7,1,0.999253354069792,40.0298881530762,1.99524400591109,17.0200001448393,-0.000810820784386426,-0.000193517936651315,0.25,-4.07200360644814E-6,-7.25488542356012E-5,-4.60524621775835E-6,20.0003242,20.0003242,51305.359375,51320.4765625,55.9661652339675,20.5977117928557,14.177031,0,0,0,40,4449,20.0354,51312.91796875,,,,,,,,,,,,,0,,,,0,,,,,,20.0003242,,,,
,23139732.895,19.9992123,56115.384765625,-8.64963223184975E-5,6.94714778596325E-7,1,0.999253354069792,40.0298881530762,1.9950883985765,17.0200001448393,-0.000967136225265784,-0.000222846588836701,0.25,-4.16679843448973E-6,-8.64234063486683E-5,-4.80774685360699E-6,19.9992123,19.9992123,56112.875,56117.89453125,56.1818947052752,20.5950171921424,14.177031,0,0,0,40,4449,20.0357,56115.384765625,,,,,,,,,,,,,0,,,,0,,,,,,19.9992123,,,,
,23139827.165,19.999836,60828.392578125,-0.000100969321377158,7.79961765052592E-7,1,0.999253354069792,40.0298881530762,1.99520436636727,17.0200001448393,-0.0011282114695955,-0.000267580361832448,0.25,-5.51159377261252E-6,-0.000100924511670647,-6.26291750635554E-6,19.999836,19.999836,60825.6796875,60831.10546875,56.4687523718329,20.5995677108432,14.177031,0,0,0,40,4449,20.0345,60828.392578125,,,,,,,,,,,,,0,,,,-0.0049,,,,,,19.999836,,,,
,23139922.74,20.0013504,65606.4453125,-0.000116532578622953,9.53223045680444E-7,1,0.999253354069792,40.0298881530762,1.99517343573755,17.0200001448393,-0.00130462011277987,-0.000298074064942982,0.25,-5.39967138549044E-6,-0.000116538662851489,-6.26727903109955E-6,20.0013504,20.0013504,65598.96875,65613.921875,56.5398805670829,20.5974768691786,14.177031,0,0,0,40,4449,20.0372,65606.4453125,,,,,,,,,,,,,0,,,,0.0049,,,,,,20.0013504,,,,
,23140019.095,20.0011635,70421.49609375,-0.000131220582416917,7.81079074003441E-7,1,0.999253354069792,40.0298881530762,1.99519017308048,17.0200001448393,-0.00146941816227199,-0.000337249323376005,0.25,-6.21536190844689E-6,-0.000131281222148844,-7.18977328989055E-6,20.0011635,20.0011635,70416.5390625,70426.453125,56.5219031111406,20.5946686244124,14.556682,0,0,0,40,4449,20.0321,70421.49609375,,,,,,,,,,,,,0,,,,-0.0049,,,,,,20.0011635,,,,
,23140117.005,20.0021973,75314.38671875,-0.00014650217233197,8.38968551665122E-7,1,0.999253354069792,40.0298881530762,1.99518800877126,17.0200001448393,-0.00164337430156108,-0.000364605088928427,0.25,-5.88022594177005E-6,-0.000146636603688002,-6.96075291418363E-6,20.0021973,20.0021973,75309.2421875,75319.53125,56.1740784200829,20.5985611821625,14.177031,0,0,0,40,4449,20.0317,75314.38671875,,,,,,,,,,,,,0,,,,-0.00245,,,,,,20.0021973,,,,
,23140213.94,20.002058,80160.1015625,-0.000162410389340831,7.37907804795838E-7,1,0.999253354069792,40.0298881530762,1.99522339509378,17.0200001448393,-0.00182397775138141,-0.000396355338416038,0.25,-5.8239418709012E-6,-0.000162625530705967,-7.01067564297794E-6,20.002058,20.002058,80152.671875,80167.53125,56.0677769414675,20.5964677621443,14.177031,0,0,0,40,4449,20.03035,80160.1015625,,,,,,,,,,,,,0,,,,0,,,,,,20.002058,,,,
,23140310.17,20.0004902,84971.203125,-0.000177663779580588,8.90234571790334E-7,1,0.999253354069792,40.0298881530762,1.99518171297629,17.0200001448393,-0.00199632532758095,-0.000431595690107354,0.25,-6.19911362474123E-6,-0.000177962764166143,-7.48323526600181E-6,20.0004902,20.0004902,84966.34375,84976.0625,56.4413953736598,20.5970583957603,14.177031,0,0,0,40,4449,20.0282,84971.203125,,,,,,,,,,,,,0,,,,0,,,,,,20.0004902,,,,
,23140401.505,20.0005569,89534.16015625,-0.000191479411349875,8.80403162359821E-7,1,0.999253354069792,40.0298881530762,1.99511915468989,17.0200001448393,-0.00214900738639914,-0.000482887782694419,0.25,-8.25575335662215E-6,-0.000191850529989408,-9.62707013406765E-6,20.0005569,20.0005569,89524.3828125,89543.9375,56.1076399959482,20.5969490928257,13.797379,0,0,0,40,4449,20.02885,89534.16015625,,,,,,,,,,,,,0,,,,-0.00245,,,,,,20.0005569,,,,
,23140515.445,20.000761,85811.6328125,-0.000180351482779716,9.48302580475139E-7,1,0.999253354069792,40.0298881530762,1.99516625188837,17.0200001448393,-0.00203116063983994,-0.000412968204879002,0.25,-4.06936429180102E-6,-0.000180681539834584,-5.36580797323383E-6,20.000761,20.000761,85804.0546875,85819.2109375,56.4687523718329,20.5937747807614,14.177031,0,0,0,40,4449,20.0268,85811.6328125,,,,,,,,,,,,,0,,,,-0.00245,,,,,,20.000761,,,,
,23140609.235,19.9999676,81122.828125,-0.000165921869690238,9.53454027300154E-7,1,0.999253354069792,40.0298881530762,1.99520346164855,17.0200001448393,-0.00186512228955457,-0.000396105353894768,0.25,-5.17033816261626E-6,-0.000166159248499315,-6.37904964478372E-6,19.9999676,19.9999676,81120.421875,81125.234375,56.4710972573906,20.5927936435487,14.177031,0,0,0,40,4449,20.027,81122.828125,,,,,,,,,,,,,0,,,,-0.0049,,,,,,19.9999676,,,,
,23140705.86,19.9992924,76291.77734375,-0.000149829683652967,8.31968202301698E-7,1,0.999253354069792,40.0298881530762,1.99523733689038,17.0200001448393,-0.00168272247515822,-0.000362639413267058,0.25,-5.10587381251531E-6,-0.000149985434889263,-6.20810679645777E-6,19.9992924,19.9992924,76286.953125,76296.6015625,56.0333852866213,20.5942730605524,14.556682,0,0,0,40,4449,20.0263,76291.77734375,,,,,,,,,,,,,0,,,,-0.0049,,,,,,19.9992924,,,,
,23140802.13,19.9988098,71478.203125,-0.000134913658658,8.3882710246047E-7,1,0.999253354069792,40.0298881530762,1.99514753558782,17.0200001448393,-0.00151278417876313,-0.00033617750715367,0.25,-5.45462043246414E-6,-0.000134994887012757,-6.45463447165096E-6,19.9988098,19.9988098,71473.34375,71483.0625,56.739977468006,20.5961691906495,14.177031,0,0,0,40,4449,20.0292,71478.203125,,,,,,,,,,,,,0,,,,0.0049,,,,,,19.9988098,,,,
,23140900.245,19.9979362,66574.7578125,-0.000117756511975926,8.04165019724904E-7,1,0.999253354069792,40.0298881530762,1.99522627047173,17.0200001448393,-0.00131913860807932,-0.000297520176856273,0.25,-5.12790387945328E-6,-0.000117775177719043,-6.00420145333913E-6,19.9979362,19.9979362,66569.609375,66579.90625,56.1506295645059,20.595655960624,13.797379,0,0,0,40,4449,20.0303,66574.7578125,,,,,,,,,,,,,0,,,,-0.0049,,,,,,19.9979362,,,,
,23140995.01,19.9977436,61839.48828125,-0.000103746115380433,7.46423281043035E-7,1,0.999253354069792,40.0298881530762,1.99526939254561,17.0200001448393,-0.00116310523494178,-0.000254325300063106,0.25,-3.83388737688069E-6,-0.000103723395738597,-4.60615775637942E-6,19.9977436,19.9977436,61832.234375,61846.7421875,56.5219031111406,20.5927423474557,14.177031,0,0,0,40,4449,20.0333,61839.48828125,,,,,,,,,,,,,0,,,,0.0049,,,,,,19.9977436,,,,
,23141091.22,19.9981766,57029.029296875,-8.8239833634535E-5,7.76173007610085E-7,1,0.999253354069792,40.0298881530762,1.99526599226891,17.0200001448393,-0.000988124433101585,-0.00022003861656486,0.25,-3.59991312106411E-6,-8.81780484813041E-5,-4.25477013372792E-6,19.9981766,19.9981766,57024.1015625,57033.95703125,56.3124266679867,20.5935433193865,14.177031,0,0,0,40,4449,20.0323,57029.029296875,,,,,,,,,,,,,0,,,,-0.0049,,,,,,19.9981766,,,,
,23141189.655,19.9997883,52106.623046875,-7.23971655181804E-5,8.96611189300806E-7,1,0.999253354069792,40.0298881530762,1.99524379045345,17.0200001448393,-0.000808823079944393,-0.000188730354691091,0.25,-3.69076878235916E-6,-7.23061838547362E-5,-4.22344712489592E-6,19.9997883,19.9997883,52096.60546875,52116.640625,56.2201945027175,20.5971893373636,14.177031,0,0,0,40,4449,20.03295,52106.623046875,,,,,,,,,,,,,0,,,,-0.00245,,,,,,19.9997883,,,,
,23141286.21,20.0000324,47283.939453125,-5.68573914047498E-5,8.18278461932583E-7,1,0.999253354069792,40.0298881530762,1.9952842961217,17.0200001448393,-0.00063505043787753,-0.000147402382976218,0.25,-2.83581616724269E-6,-5.67588010961301E-5,-3.24896587756897E-6,20.0000324,20.0000324,47279.171875,47288.70703125,56.4382688595829,20.5931611546596,14.177031,0,0,0,40,4449,20.0349,47283.939453125,,,,,,,,,,,,,0,,,,0,,,,,,20.0000324,,,,
,23141381.385,20.0005093,42526.447265625,-4.28949471153488E-5,9.52731802991149E-7,1,0.999253354069792,40.0298881530762,1.99531719005407,17.0200001448393,-0.000477281112078881,-0.000119998017864951,0.25,-2.92894587441705E-6,-4.27938753049044E-5,-3.2337004733382E-6,20.0005093,20.0005093,42521.40625,42531.48828125,56.4812584281406,20.5953148095947,13.797379,0,0,0,40,4449,20.0326,42526.447265625,,,,,,,,,,,,,0,,,,0.0049,,,,,,20.0005093,,,,
,23141476.32,19.9991589,37781.0546875,-2.79421122180311E-5,7.06088416903261E-7,1,0.999253354069792,40.0298881530762,1.99534266224598,17.0200001448393,-0.000308719968525848,-8.94432941283815E-5,0.25,-2.91651825056048E-6,-2.78554076886988E-5,-3.10777135758412E-6,19.9991589,19.9991589,37773.42578125,37788.68359375,56.231918930506,20.5936119904772,14.177031,0,0,0,40,4449,20.03205,37781.0546875,,,,,,,,,,,,,0,,,,0,,,,,,19.9991589,,,,
,23141571.12,19.9988213,33044.16796875,-1.46737768347636E-5,7.22327717215367E-7,1,0.999253354069792,40.0298881530762,1.99522703129312,17.0200001448393,-0.000160239299616707,-5.69448599589284E-5,0.25,-2.42272733578072E-6,-1.46150034655312E-5,-2.51720236981991E-6,19.9988213,19.9988213,33041.5,33046.8359375,56.2952308405636,20.5970959278481,14.556682,0,0,0,40,4449,20.0335,33044.16796875,,,,,,,,,,,,,0,,,,0.00245,,,,,,19.9988213,,,,
,23141667.085,19.9981689,28246.3291015625,1.48594452073734E-7,5.52028411799958E-7,1,0.999253354069792,40.0298881530762,1.99524268943933,17.0200001448393,4.61722587327344E-6,-1.61110065971066E-5,0.25,-1.45890281587626E-6,1.57851237556086E-7,-1.45299602381894E-6,19.9981689,19.9981689,28238.931640625,28253.7265625,56.3343122665252,20.5958207064676,14.177031,0,0,0,40,4449,20.03555,28246.3291015625,,,,,,,,,,,,,0,,,,0,,,,,,19.9981689,,,,
,23141761.265,19.9981804,23541.0166015625,1.35415597671869E-5,3.9111400985505E-7,1,0.999253354069792,40.0298881530762,1.99526446049663,17.0200001448393,0.00015484441574176,1.28826729003019E-5,0.25,-1.28134210779387E-6,1.34976684648891E-5,-1.18933465284549E-6,19.9981804,19.9981804,23536.12890625,23545.904296875,56.3194613246598,20.5957521610542,13.797379,0,0,0,40,4449,20.0374,23541.0166015625,,,,,,,,,,,,,0,,,,0,,,,,,19.9981804,,,,
,23141857.54,20.0011692,18728.91015625,2.77860382225985E-5,3.82065568100916E-7,1,0.999253354069792,40.0298881530762,1.99515189945797,17.0200001448393,0.000315091535402619,4.01540058097425E-5,0.25,-1.39873815185356E-6,2.76745008113994E-5,-1.22236477620087E-6,20.0011692,20.0011692,18718.8984375,18738.921875,56.5359724244868,20.599344075024,14.177031,0,0,0,40,4449,20.0364,18728.91015625,,,,,,,,,,,,,0,,,,0.00245,,,,,,20.0011692,,,,
,23141950.275,20.0016222,14091.5229492187,4.04753548624575E-5,4.39530799100381E-7,1,0.999253354069792,40.0298881530762,1.99520573840326,17.0200001448393,0.000456429275364903,7.17055234751333E-5,0.25,-8.46280889861413E-7,4.02879769175089E-5,-6.0702647174142E-7,20.0014038,20.0018406,14086.59375,14096.4521484375,55.8942554101982,20.5967533948695,14.556682,0,0,0,40,4449,20.0347,14091.5229492187,,,,,,,,,,,,,0,,,,0.00245,,,,,,20.0016222,,,,
,23142045.38,20.0019093,9339.6083984375,5.33558705270087E-5,3.68192074216895E-7,1,0.999253354069792,40.0298881530762,1.99539724218536,17.0200001448393,0.000600613863838706,9.93907459617325E-5,0.25,-6.61275887831569E-7,5.30846137758153E-5,-3.66168181237598E-7,20.0019093,20.0019093,9334.86328125,9344.353515625,56.6110087623329,20.5975976189284,14.177031,0,0,0,40,4449,20.0328,9339.6083984375,,,,,,,,,,,,,0,,,,0.00245,,,,,,20.0019093,,,,
,23142142.74,20.0063038,4473.7177734375,6.58453486755084E-5,3.28870157318395E-7,1,0.999253354069792,40.0298881530762,1.99542404727145,17.0200001448393,0.000739267083368397,0.000132041814153015,0.25,4.68362839308038E-8,6.54824326716101E-5,3.83371748941372E-7,20.0063038,20.0063038,4461.24560546875,4486.18994140625,56.3624508932175,20.5965806794129,14.177031,0,0,0,40,4449,20.0252,4473.7177734375,,,,,,,,,,,,,0,,,,-0.00245,,,,,,20.0063038,,,,
,23142233.555,19.9968491,-0.1674614995718,7.17042985816313E-5,3.0027140646658E-7,1,0.999253354069792,40.0298881530762,1.99535948344657,17.0200001448393,0.000805238830457956,0.000141427067757453,0.25,-1.36784656034357E-7,7.12926852968407E-5,2.11526150724652E-7,19.9968491,19.9968491,-0.1674614995718,-0.1674614995718,56.567237565256,20.5974565799956,13.797379,0,0,0,40,4417,20.0326,-0.1674614995718,,,,,,,,,,,,,0,,,,0.00245,,,,,,19.9968491,,,,