File: data/doubleLayers/dl_2-5/ppms/data/DD205_5_HYST_100OE_250K.DAT
[Header]
; VSM Data File (default extension .dat)
; Copyright (c) 2003-2013, Quantum Design, Inc. All rights reserved.
TITLE,
FILEOPENTIME,23189509.88,09/26/2018,6:30 pm
BYAPP,VSM,2.0,2.0
INFO,PPMS VSM Option Release 1.4.10 Build 1,APPNAME
INFO,Quantum Design Linear Motor Servo Controller,MOTOR_MODULE_NAME
INFO,3101-100 M1,MOTOR_HW_VERSION
INFO,MMC1014,MOTOR_SERIAL_NUMBER
INFO,SRV No X-over 01.03.11,MOTOR_SOFTWARE_VERSION
INFO,Quantum Design VSM Detection Module,VSM_MODULE_NAME
INFO,3101-150 F0,VSM_HW_VERSION
INFO,VSM707,VSM_SERIAL_NUMBER
INFO,VSM No X-over 01.02.05 May 20 2008 13:51:47,VSM_SOFTWARE_VERSION
INFO,704,PREAMP_SERIAL_NUMBER
INFO,822,COIL_SERIAL_NUMBER
INFO,0,MOMENT_UNITS
INFO,,SAMPLE_MATERIAL
INFO,,SAMPLE_COMMENT
INFO,,SAMPLE_MASS
INFO,,SAMPLE_VOLUME
INFO,,SAMPLE_MOLECULAR_WEIGHT
INFO,,SAMPLE_SIZE
INFO,,SAMPLE_SHAPE
DATATYPE,COMMENT,1
DATATYPE,TIME,2
STARTUPAXIS,X,2
STARTUPAXIS,Y1,5
[Data]
Comment,Time Stamp (sec),Temperature (K),Magnetic Field (Oe),Moment (emu),M. Std. Err. (emu),Transport Action,Averaging Time (sec),Frequency (Hz),Peak Amplitude (mm),Center Position (mm),Coil Signal' (mV),Coil Signal" (mV),Range (mV),M. Quad. Signal (emu),M. Raw' (emu),M. Raw" (emu),Min. Temperature (K),Max. Temperature (K),Min. Field (Oe),Max. Field (Oe),Mass (grams),Motor Lag (deg),Pressure (Torr),VSM Status (code),Motor Status (code),Measure Status (code),Measure Count,PPMS Status (code),System Temp. (K),System Field (Oe),Sample Position (deg),Bridge 1 Resistance (ohms),Bridge 1 Excitation (에),Bridge 2 Resistance (ohms),Bridge 2 Excitation (에),Bridge 3 Resistance (ohms),Bridge 3 Excitation (에),Bridge 4 Resistance (ohms),Bridge 4 Excitation (에),Signal 1 Vin (V),Signal 2 Vin (V),Digital Inputs (code),Drive 1 Iout (mA),Drive 1 Ipower (W),Drive 2 Iout (mA),Drive 2 Ipower (W),Pressure (),Map 20 (),Map 21 (),Map 22 (),Map 23 (),Map 24 (),Map 25 (),Map 26 (),Map 27 (),Map 28 (),Map 29 ()
,23189526.31,250.3523712,-0.0761188715696335,,,2,,,,15.9500004500151,,,,,,,250.3523712,250.3523712,-0.0761188715696335,-0.0761188715696335,,,28.224119,,,,-99999999,4369,250.8246,-0.0761188715696335,,,,,,,,,,,,,,,,,,,,,,,250.3523712,,,,
,23189679.01,250.269928,4551.203125,4.78814476934403E-5,4.00282546143468E-7,1,0.999253354069792,40.0298881530762,1.99711301583941,15.939999371767,0.000542403177147647,9.41168628060743E-5,0.25,4.35559725875581E-9,4.79650009574228E-5,4.38471941327895E-8,250.269928,250.269928,4541.42138671875,4560.98486328125,56.2139414745636,20.5424147352239,28.224119,0,0,0,40,4449,250.43625,4551.203125,,,,,,,,,,,,,0,,,,0.00245,,,,,,250.269928,,,,
,23189774.575,250.17500305,9322.36474609375,4.2024416098984E-5,6.40194810949773E-7,1,0.999253354069792,40.0298881530762,1.9970930133443,15.939999371767,0.000477660073055801,7.33285188797468E-5,0.25,-8.14928512112019E-7,4.20985679514864E-5,-7.81715167456691E-7,250.1738129,250.1761932,9312.626953125,9332.1025390625,56.3155531820637,20.5479585932081,28.224119,0,0,0,40,4449,250.3252,9322.36474609375,,,,,,,,,,,,,0,,,,-0.00245,,,,,,250.17500305,,,,
,23189871.39,250.103653,14162.4750976563,2.82692708396903E-5,1.01609413084265E-6,1,0.999253354069792,40.0298881530762,1.99717352238419,15.939999371767,0.000322343572186038,4.3477951696888E-5,0.25,-1.06466919183654E-6,2.83196510294624E-5,-1.04325266949433E-6,250.103653,250.103653,14160.0205078125,14164.9296875,56.6782288149868,20.5472316244727,28.224119,0,0,0,40,4449,250.2691,14162.4750976563,,,,,,,,,,,,,0,,,,-0.00245,,,,,,250.103653,,,,
,23189966.32,250.0552673,18907.1337890625,1.45406149257771E-5,1.02501863887909E-6,1,0.999253354069792,40.0298881530762,1.99710938439014,15.939999371767,0.000166973389045587,1.5574906775932E-5,0.25,-1.14680297366474E-6,1.4567047538804E-5,-1.13685132847284E-6,250.0552673,250.0552673,18902.03125,18912.236328125,56.4843849422175,20.5470191903025,28.224119,0,0,0,40,4449,250.2481,18907.1337890625,,,,,,,,,,,,,0,,,,0,,,,,,250.0552673,,,,
,23190062.565,250.0306091,23717.0966796875,-1.58071562392964E-6,1.32233573962401E-6,1,0.999253354069792,40.0298881530762,1.99700826635549,15.939999371767,-1.64106384313708E-5,-1.17278111561321E-5,0.25,-7.61185623780071E-7,-1.58286266383283E-6,-7.63819571772822E-7,250.0306091,250.0306091,23709.8125,23724.380859375,56.5899047923137,20.5495694792503,28.224119,0,0,0,40,4449,250.23165,23717.0966796875,,,,,,,,,,,,,0,,,,0,,,,,,250.0306091,,,,
,23190160.225,250.0151367,28597.734375,-1.76968506637374E-5,2.17447765636926E-6,1,0.999253354069792,40.0298881530762,1.99707613549456,15.939999371767,-0.000198630268601473,-4.5388309914583E-5,0.25,-9.37690951557618E-7,-1.77271324685224E-5,-9.53858974395264E-7,250.0149536,250.0153198,28592.85546875,28602.61328125,56.6125720193714,20.5501745402179,27.464817,0,0,0,40,4449,250.22385,28597.734375,,,,,,,,,,,,,0,,,,-0.00245,,,,,,250.0151367,,,,
,23190256.295,250.0104218,33399.9765625,-3.3709597584564E-5,2.00883577747237E-6,1,0.999253354069792,40.0298881530762,1.99703661588738,15.939999371767,-0.000381058894917805,-7.08413285070606E-5,0.25,-4.07789909561781E-7,-3.37684207828473E-5,-4.36132405531564E-7,250.0104218,250.0104218,33394.59765625,33405.35546875,56.6399290175445,20.5500243116506,28.224119,0,0,0,40,4449,250.21935,33399.9765625,,,,,,,,,,,,,0,,,,-0.0049,,,,,,250.0104218,,,,
,23190354.175,250.00672915,38292.16015625,-5.37532179346846E-5,1.43791229562683E-6,1,0.999253354069792,40.0298881530762,1.99703171863561,15.939999371767,-0.000608585274005673,-0.00010747800246422,0.25,-1.66108560059147E-7,-5.38474281109265E-5,-2.10392525225341E-7,250.0059052,250.0075531,38286.96484375,38297.35546875,56.5758354789675,20.5483438345747,28.603769,0,0,0,40,4449,250.21615,38292.16015625,,,,,,,,,,,,,0,,,,0,,,,,,250.00672915,,,,
,23190448.21,250.0074158,42990.169921875,-6.71242402110684E-5,2.32963495039688E-6,1,0.999253354069792,40.0298881530762,1.99713098931192,15.939999371767,-0.000758190662178797,-0.000144687209392421,0.25,-1.13153476755399E-6,-6.72411366363765E-5,-1.18838157874199E-6,250.0074158,250.0074158,42980.0625,43000.27734375,56.8071975206598,20.547084533716,28.603769,0,0,0,40,4449,250.21155,42990.169921875,,,,,,,,,,,,,0,,,,0.00245,,,,,,250.0074158,,,,
,23190545.07,250.0113754,47835.455078125,-8.46063919550171E-5,2.77521418822115E-6,1,0.999253354069792,40.0298881530762,1.9970618285004,15.939999371767,-0.000962316430282184,-0.00014378283734215,0.25,1.97948302832466E-6,-8.47565134748954E-5,1.9139058333203E-6,250.01091,250.0118408,47827.8828125,47843.02734375,56.546915223756,20.5468676639848,28.224119,0,0,0,40,4449,250.2005,47835.455078125,,,,,,,,,,,,,0,,,,0,,,,,,250.0113754,,,,
,23190643.215,250.012558,52737.96484375,-0.000103798582430332,2.44317086624257E-6,1,0.999253354069792,40.0298881530762,1.99701513876775,15.939999371767,-0.00117616522059591,-0.000201869328304887,0.25,1.79538426374277E-7,-0.000103980931121061,9.52605419355285E-8,250.012558,250.012558,52730.6015625,52745.328125,56.790783321756,20.5493549385826,28.224119,0,0,0,40,4449,250.18835,52737.96484375,,,,,,,,,,,,,0,,,,-0.0049,,,,,,250.012558,,,,
,23190740.85,250.013504,57617.634765625,-0.0001176068475296,2.97831790695161E-6,1,0.999253354069792,40.0298881530762,1.99697511626646,15.939999371767,-0.00132744100725442,-0.000258494768086331,0.25,-2.42526979742753E-6,-0.000117811326009461,-2.52523398540268E-6,250.013504,250.013504,57607.66796875,57627.6015625,56.6821369575829,20.5493708169805,28.603769,0,0,0,40,4449,250.1747,57617.634765625,,,,,,,,,,,,,0,,,,-0.00245,,,,,,250.013504,,,,
,23190836.445,250.0157471,62396.173828125,-0.000135086392091121,3.20805481824951E-6,1,0.999253354069792,40.0298881530762,1.99706659938911,15.939999371767,-0.00152065109223047,-0.000320859490890472,0.25,-4.89855047378179E-6,-0.000135319555152332,-5.01691923606878E-6,250.0157471,250.0157471,62391.00390625,62401.34375,56.7001144135252,20.5483924046251,28.224119,0,0,0,40,4449,250.1664,62396.173828125,,,,,,,,,,,,,0,,,,-0.00245,,,,,,250.0157471,,,,
,23190933.12,250.0172882,67229.01953125,-0.000159343445925335,3.86479374535009E-6,1,0.999253354069792,40.0298881530762,1.99686747866553,15.939999371767,-0.00180669554471703,-0.000302571989458263,0.25,9.19530970658535E-7,-0.000159623931367915,7.91859114066113E-7,250.0172882,250.0172882,67224.03125,67234.0078125,56.7517018957945,20.552113943483,28.224119,0,0,0,40,4449,250.1554,67229.01953125,,,,,,,,,,,,,0,,,,0,,,,,,250.0172882,,,,
,23191031.145,250.014389,72128.9296875,-0.000174266298578075,2.92078240586517E-6,1,0.999253354069792,40.0298881530762,1.99715704226916,15.939999371767,-0.00196681426767002,-0.00038490795854625,0.25,-3.75716246729457E-6,-0.000174569234063328,-3.90493839029477E-6,250.014389,250.014389,72126.3203125,72131.5390625,56.6188250475252,20.5491856971021,27.844467,0,0,0,40,4449,250.13995,72128.9296875,,,,,,,,,,,,,0,,,,-0.0049,,,,,,250.014389,,,,
,23191128.37,250.01462555,76986.84375,-0.00018861932710872,3.21249620639625E-6,1,0.999253354069792,40.0298881530762,1.99725466630114,15.939999371767,-0.00213874505598831,-0.00035988959136778,0.25,9.41464642287325E-7,-0.000188951293570972,7.9054699715063E-7,250.0141602,250.0150909,76979.4453125,76994.2421875,56.506270540756,20.5454132192307,28.224119,0,0,0,40,4449,250.1285,76986.84375,,,,,,,,,,,,,0,,,,0,,,,,,250.01462555,,,,
,23191224.225,250.0163879,81777.75,-0.000203098554408389,3.05611608501065E-6,1,0.999253354069792,40.0298881530762,1.99717805276916,15.939999371767,-0.00229891135635987,-0.000410158411598819,0.25,-9.86410960557839E-7,-0.000203454401846464,-1.15217766101834E-6,250.0163879,250.0163879,81772.71875,81782.78125,56.6446187886598,20.544518605142,27.844467,0,0,0,40,4449,250.11065,81777.75,,,,,,,,,,,,,0,,,,-0.0049,,,,,,250.0163879,,,,
,23191317.59,250.0159454,86448.24609375,-0.000218940197360234,3.96703644147996E-6,1,0.999253354069792,40.0298881530762,1.99695789386302,15.939999371767,-0.0024842569668559,-0.000405823010290064,0.25,2.13930270945644E-6,-0.000219326417596291,1.96649732550759E-6,250.0159454,250.0159454,86435.75,86460.7421875,56.6391473890252,20.550790678466,28.603769,0,0,0,40,4449,250.0976,86448.24609375,,,,,,,,,,,,,0,,,,0.00245,,,,,,250.0159454,,,,
,23191431.19,250.0181122,88929.703125,-0.000237113659912162,3.54741924344764E-6,1,0.999253354069792,40.0298881530762,1.99704450311108,15.939999371767,-0.00268112413615214,-0.000494044927881947,0.25,-2.49592055918919E-6,-0.00023752805721622,-2.69137322206052E-6,250.0181122,250.0181122,88922.109375,88937.296875,56.7016776705637,20.5508617591176,28.224119,0,0,0,40,4449,250.0841,88929.703125,,,,,,,,,,,,,0,,,,0,,,,,,250.0181122,,,,
,23191524.695,250.0090179,84256.265625,-0.000214226100907369,3.7853222709312E-6,1,0.999253354069792,40.0298881530762,1.9970966569191,15.939999371767,-0.00242140043641014,-0.000452060721859018,0.25,-2.75723656152149E-6,-0.000214600129138225,-2.93498281676272E-6,250.0090179,250.0090179,84248.796875,84263.734375,56.5641110511791,20.5509363479904,28.224119,0,0,0,40,4449,250.07875,84256.265625,,,,,,,,,,,,,0,,,,0.00245,,,,,,250.0090179,,,,
,23191619.485,250.0050354,79520.046875,-0.000198445370786102,3.16209201128972E-6,1,0.999253354069792,40.0298881530762,1.99719649903716,15.939999371767,-0.00223903105190295,-0.000442461746896287,0.25,-4.64425712980301E-6,-0.000198790154032208,-4.81283521480321E-6,250.0050354,250.0050354,79515.0546875,79525.0390625,56.4085669758521,20.5513380718566,28.224119,0,0,0,40,4449,250.0786,79520.046875,,,,,,,,,,,,,0,,,,0,,,,,,250.0050354,,,,
,23191715.87,249.9998627,74698.8515625,-0.0001826040014105,2.52878918857251E-6,1,0.999253354069792,40.0298881530762,1.99718915663435,15.939999371767,-0.00207602952937675,-0.000316362519155686,0.25,3.73968715997661E-6,-0.000182927751772363,3.59840250511546E-6,249.9998627,249.9998627,74691.484375,74706.21875,56.5985027060252,20.5527538064851,28.603769,0,0,0,40,4449,250.07605,74698.8515625,,,,,,,,,,,,,0,,,,0,,,,,,249.9998627,,,,
,23191812.335,249.997757,69878.72265625,-0.000160755829937338,2.64219140441472E-6,1,0.999253354069792,40.0298881530762,1.99703861008492,15.939999371767,-0.00181926594195367,-0.000326005520879698,0.25,-9.02054180903465E-7,-0.000161037437169289,-1.03400079871139E-6,249.997757,249.997757,69873.578125,69883.8671875,56.8736359447945,20.5528756496518,28.603769,0,0,0,40,4449,250.08605,69878.72265625,,,,,,,,,,,,,0,,,,-0.0049,,,,,,249.997757,,,,
,23191907.105,249.9934845,65140.57421875,-0.000146446096154014,2.32346841404078E-6,1,0.999253354069792,40.0298881530762,1.99709602464612,15.939999371767,-0.00165111083229871,-0.000333081922735918,0.25,-4.00720911506031E-6,-0.000146700050314145,-4.13318583096362E-6,249.9934845,249.9934845,65135.49609375,65145.65234375,56.7798405224868,20.5526415724098,28.224119,0,0,0,40,4449,250.089,65140.57421875,,,,,,,,,,,,,0,,,,0,,,,,,249.9934845,,,,
,23192002.92,249.9951324,60349.994140625,-0.000127318253273962,3.24982339861618E-6,1,0.999253354069792,40.0298881530762,1.99715616338126,15.939999371767,-0.00143679368442923,-0.000282092362848431,0.25,-2.82225179427769E-6,-0.000127539546756326,-2.93076732918481E-6,249.9951324,249.9951324,60337.5546875,60362.43359375,56.7892200647175,20.5547979603544,28.224119,0,0,0,40,4449,250.09475,60349.994140625,,,,,,,,,,,,,0,,,,-0.00245,,,,,,249.9951324,,,,
,23192098.625,249.9953003,55569.408203125,-0.000112566922820622,2.26963835776154E-6,1,0.999253354069792,40.0298881530762,1.99701385117427,15.939999371767,-0.00128093070525351,-0.00018772872923128,0.25,2.94836294929929E-6,-0.000112766992325179,2.86184210286103E-6,249.9953003,249.9953003,55559.39453125,55579.421875,56.5844333926791,20.5530853697944,28.603769,0,0,0,40,4449,250.09575,55569.408203125,,,,,,,,,,,,,0,,,,-0.0049,,,,,,249.9953003,,,,
,23192196.98,249.9910278,50651.81640625,-9.38574551777536E-5,2.95557930387633E-6,1,0.999253354069792,40.0298881530762,1.99702649684458,15.939999371767,-0.00106137325738398,-0.000194953733339102,0.25,-9.33719889003384E-7,-9.40215092442466E-5,-1.01192868111914E-6,249.9910278,249.9910278,50641.8359375,50661.796875,56.800944492506,20.5547738612658,27.844467,0,0,0,40,4449,250.1088,50651.81640625,,,,,,,,,,,,,0,,,,-0.0049,,,,,,249.9910278,,,,
,23192293.67,249.9935913,45819.646484375,-7.57941771379717E-5,3.04716270524832E-6,1,0.999253354069792,40.0298881530762,1.99700722973243,15.939999371767,-0.000863827146065289,-0.000118636345079243,0.25,2.67093887004961E-6,-7.59294386231168E-5,2.61370547116289E-6,249.9935913,249.9935913,45814.46484375,45824.828125,56.6954246424098,20.5537282507737,28.224119,0,0,0,40,4449,250.11245,45819.646484375,,,,,,,,,,,,,0,,,,-0.00245,,,,,,249.9935913,,,,
,23192390.985,249.9885712,40954.46484375,-5.96554440079084E-5,2.36116984767257E-6,1,0.999253354069792,40.0298881530762,1.99688481711052,15.939999371767,-0.000677147364572248,-0.000108977991577074,0.25,7.24344797172139E-7,-5.97607825957388E-5,6.76809361527573E-7,249.9885712,249.9885712,40947.00390625,40961.92578125,56.7180918694675,20.5570744683704,28.224119,0,0,0,40,4449,250.11855,40954.46484375,,,,,,,,,,,,,0,,,,0,,,,,,249.9885712,,,,
,23192487.405,249.99201965,36136.9296875,-4.50644439491412E-5,1.94311732323494E-6,1,0.999253354069792,40.0298881530762,1.99712182609275,15.939999371767,-0.000510633123736989,-8.78107222070194E-5,0.25,6.3655071023913E-8,-4.51436112872692E-5,2.68466221156227E-8,249.9914856,249.9925537,36129.53515625,36144.32421875,56.7696793517368,20.5563106069668,28.603769,0,0,0,40,4449,250.12585,36136.9296875,,,,,,,,,,,,,0,,,,0,,,,,,249.99201965,,,,
,23192585.185,249.991333,31249.513671875,-2.85397607981192E-5,1.87696575441709E-6,1,0.999253354069792,40.0298881530762,1.99710864144709,15.939999371767,-0.000319792457820653,-7.63382276985596E-5,0.25,-1.78933201595042E-6,-2.85883944339383E-5,-1.81588695477355E-6,249.991333,249.991333,31242.134765625,31256.892578125,56.8486238321791,20.5571720226246,27.844467,0,0,0,40,4449,250.13215,31249.513671875,,,,,,,,,,,,,0,,,,0,,,,,,249.991333,,,,
,23192681.02,249.9934387,26461.859375,-1.17735140319029E-5,1.47125590697527E-6,1,0.999253354069792,40.0298881530762,1.99711873562139,15.939999371767,-0.000136545940701475,-4.84424741007989E-6,0.25,1.6141576807183E-6,-1.17955061292189E-5,1.60731948535499E-6,249.9934387,249.9934387,26454.365234375,26469.353515625,56.7626446950637,20.5559183297935,27.844467,0,0,0,40,4449,250.1349,26461.859375,,,,,,,,,,,,,0,,,,-0.0049,,,,,,249.9934387,,,,
,23192776.26,249.9945526,21699.2685546875,3.44125372478464E-6,8.6730723553725E-7,1,0.999253354069792,40.0298881530762,1.99725195351588,15.939999371767,3.88513210060991E-5,7.53933603593686E-6,0.25,6.86940805871174E-8,3.44723714456114E-6,7.16450708500368E-8,249.9945526,249.9945526,21691.85546875,21706.681640625,56.7149653553906,20.5572756082177,27.844467,0,0,0,40,4449,250.138,21699.2685546875,,,,,,,,,,,,,0,,,,-0.0049,,,,,,249.9945526,,,,
,23192872.025,249.9943848,16914.3564453125,1.99823541926872E-5,8.23529306228825E-7,1,0.999253354069792,40.0298881530762,1.99712441684723,15.939999371767,0.000227315937036126,3.37920863610281E-5,0.25,-4.82454448017811E-7,2.00178214605739E-5,-4.66846123614815E-7,249.9943848,249.9943848,16909.302734375,16919.41015625,56.6837002146214,20.5589728829392,28.224119,0,0,0,40,4449,250.14405,16914.3564453125,,,,,,,,,,,,,0,,,,-0.00245,,,,,,249.9943848,,,,
,23192967.375,249.9957199,12149.75390625,3.33812682974065E-5,7.55424993664861E-7,1,0.999253354069792,40.0298881530762,1.99712779146782,15.939999371767,0.00037862681861919,6.28716874372904E-5,0.25,-2.39214717523528E-7,3.34400460839298E-5,-2.1211411277742E-7,249.9954834,249.9959564,12142.2490234375,12157.2587890625,57.085457273506,20.5576143228045,27.844467,0,0,0,40,4449,250.14425,12149.75390625,,,,,,,,,,,,,0,,,,0,,,,,,249.9957199,,,,
,23193064.525,249.9933167,7291.86499023437,4.49833807196997E-5,4.86138780623376E-7,1,0.999253354069792,40.0298881530762,1.99709050354321,15.939999371767,0.000508985555969872,9.18090157587081E-5,0.25,3.03203944331971E-7,4.50620709854919E-5,3.40860800621416E-7,249.9933167,249.9933167,7284.3271484375,7299.40283203125,56.638365760506,20.5574402264266,28.224119,0,0,0,40,4449,250.1493,7291.86499023437,,,,,,,,,,,,,0,,,,-0.00245,,,,,,249.9933167,,,,
,23193161.83,249.99286655,2428.86840820313,4.60856234110418E-5,3.80054840684405E-7,1,0.999253354069792,40.0298881530762,1.99733961633016,15.939999371767,0.000522045063469204,9.10390077663681E-5,0.25,4.30843693948721E-8,4.61664595264297E-5,8.12286467652839E-8,249.9927979,249.9929352,2416.11352539062,2441.62329101562,56.841589175506,20.5549045384829,28.603769,0,0,0,40,4449,250.15765,2428.86840820313,,,,,,,,,,,,,0,,,,-0.0049,,,,,,249.99286655,,,,
,23193254.165,249.9967957,-2182.39453125,-3.4775604346387E-5,4.57401752801028E-7,1,0.999253354069792,40.0298881530762,1.99719531658662,15.939999371767,-0.00039285574583239,-7.47198112863308E-5,0.25,-5.64581742566639E-7,-3.4836157694907E-5,-5.94299500334253E-7,249.9967957,249.9967957,-2187.22290039062,-2177.56616210938,56.8447156895829,20.5593222128857,28.603769,0,0,0,40,4449,250.1591,-2182.39453125,,,,,,,,,,,,,0,,,,0,,,,,,249.9967957,,,,
,23193348.005,249.996582,-6873.80102539063,-4.44944683077629E-5,7.52814498064106E-7,1,0.999253354069792,40.0298881530762,1.997207563913,15.939999371767,-0.00050269708401517,-9.53400730553655E-5,0.25,-6.99227527129369E-7,-4.45719684164626E-5,-7.37176923738385E-7,249.996582,249.996582,-6881.21044921875,-6866.3916015625,56.9338213407753,20.5571815731843,27.844467,0,0,0,40,4449,250.1611,-6873.80102539063,,,,,,,,,,,,,0,,,,0,,,,,,249.996582,,,,
,23193445.56,250.0037994,-11749.6162109375,-3.40254325903139E-5,5.02402640693994E-7,1,0.999253354069792,40.0298881530762,1.99727696561346,15.939999371767,-0.000384553259025434,-7.22047733186537E-5,0.25,-4.72483344801332E-7,-3.40847441561157E-5,-5.01364624758936E-7,250.0037994,250.0037994,-11754.6572265625,-11744.5751953125,56.7493570102368,20.5591303584349,28.224119,0,0,0,40,4449,250.1578,-11749.6162109375,,,,,,,,,,,,,0,,,,0,,,,,,250.0037994,,,,
,23193543.165,250.0113525,-16629.8408203125,-2.0294638636867E-5,1.13567942636243E-6,1,0.999253354069792,40.0298881530762,1.9971145758278,15.939999371767,-0.000229786346605798,-4.05524968602918E-5,0.25,-6.01726259512365E-8,-2.03301947134171E-5,-7.69914978067711E-8,250.0113525,250.0113525,-16637.337890625,-16622.34375,56.9525804252368,20.5600996970605,27.844467,0,0,0,40,4449,250.1451,-16629.8408203125,,,,,,,,,,,,,0,,,,0,,,,,,250.0113525,,,,
,23193639.35,250.0098114,-21434.29296875,-4.39357993193664E-6,9.89235056198414E-7,1,0.999253354069792,40.0298881530762,1.9971803082759,15.939999371767,-4.87026693864192E-5,-1.480681081265E-5,0.25,-5.45072349849026E-7,-4.40084054849271E-6,-5.49642718834018E-7,250.0098114,250.0098114,-21439.171875,-21429.4140625,56.9416376259676,20.5576190847951,28.224119,0,0,0,40,4449,250.13625,-21434.29296875,,,,,,,,,,,,,0,,,,0,,,,,,250.0098114,,,,
,23193735.51,250.0088654,-26241.4169921875,1.16794270956279E-5,1.24284137024612E-6,1,0.999253354069792,40.0298881530762,1.99720873193637,15.939999371767,0.000130566492917891,3.30260522534048E-5,0.25,8.89752773192615E-7,1.16991906507308E-5,9.00908740615781E-7,250.0088654,250.0088654,-26246.2890625,-26236.544921875,56.9033378285253,20.5593842319819,27.844467,0,0,0,40,4449,250.13805,-26241.4169921875,,,,,,,,,,,,,0,,,,0.00245,,,,,,250.0088654,,,,
,23193831.165,250.0119476,-31021.6953125,2.92908204433251E-5,1.46576669678016E-6,1,0.999253354069792,40.0298881530762,1.99719249745348,15.939999371767,0.000331059868238571,6.19809712529526E-5,0.25,3.91488280886276E-7,2.93418974152152E-5,4.16208088758825E-7,250.0119476,250.0119476,-31029.212890625,-31014.177734375,57.0385595623522,20.5589215487769,27.844467,0,0,0,40,4449,250.11985,-31021.6953125,,,,,,,,,,,,,0,,,,0,,,,,,250.0119476,,,,
,23193928.085,250.0151215,-35863.484375,4.41001968956357E-5,1.76772309405981E-6,1,0.999253354069792,40.0298881530762,1.9973305565171,15.939999371767,0.000501737778964844,7.45155178817118E-5,0.25,-1.07071011213898E-6,4.41784595316503E-5,-1.03645253666469E-6,250.0151215,250.0151215,-35870.796875,-35856.171875,56.9486722826406,20.5590029990828,28.603769,0,0,0,40,4449,250.10605,-35863.484375,,,,,,,,,,,,,0,,,,-0.0049,,,,,,250.0151215,,,,
,23194026.84,250.0149841,-40801.046875,6.32556816616199E-5,1.92995619744925E-6,1,0.999253354069792,40.0298881530762,1.99721119998325,15.939999371767,0.00071929002097331,0.000108854140248944,0.25,-1.36112284199043E-6,6.33678022691286E-5,-1.31175008606384E-6,250.0149841,250.0149841,-40813.640625,-40788.453125,56.8525319747752,20.5585212571244,28.603769,0,0,0,40,4449,250.0929,-40801.046875,,,,,,,,,,,,,0,,,,-0.0049,,,,,,250.0149841,,,,
,23194125.39,250.012558,-45725.806640625,7.91156110215633E-5,2.41010485800584E-6,1,0.999253354069792,40.0298881530762,1.997177770608,15.939999371767,0.000897332228120201,0.000149345679090494,0.25,-5.37033206793865E-7,7.92549061979075E-5,-4.73328492041001E-7,250.012558,250.012558,-45730.98828125,-45720.625,56.9447641400445,20.5588663325309,27.844467,0,0,0,40,4449,250.0833,-45725.806640625,,,,,,,,,,,,,0,,,,-0.00245,,,,,,250.012558,,,,
,23194221.69,250.0140076,-50538.201171875,9.73738610822138E-5,2.2422372668463E-6,1,0.999253354069792,40.0298881530762,1.99715847249979,15.939999371767,0.00110122786157532,0.000202147412217159,0.25,9.57834414769181E-7,9.75439884299935E-5,1.03897017231289E-6,250.0140076,250.0140076,-50548.19140625,-50528.2109375,56.946327397083,20.5629311553215,28.224119,0,0,0,40,4449,250.07125,-50538.201171875,,,,,,,,,,,,,0,,,,0,,,,,,250.0140076,,,,
,23194320.45,250.0124969,-55475.26953125,0.000116200719302638,2.82506452494135E-6,1,0.999253354069792,40.0298881530762,1.99719217963872,15.939999371767,0.00131165353003472,0.000255732209884811,0.25,2.42277857150507E-6,0.000116402720484311,2.52170893414926E-6,250.0124969,250.0124969,-55480.15234375,-55470.38671875,56.7274714116983,20.5603384998303,27.844467,0,0,0,40,4449,250.0587,-55475.26953125,,,,,,,,,,,,,0,,,,-0.0049,,,,,,250.0124969,,,,
,23194418.725,250.0141907,-60387.3984375,0.000129640921197455,2.56735912407444E-6,1,0.999253354069792,40.0298881530762,1.9973385669886,15.939999371767,0.00147073708972411,0.000243405914934286,0.25,-9.97343590690597E-7,0.000129869309967981,-8.93624235297303E-7,250.0141907,250.0141907,-60392.28515625,-60382.51171875,56.8845787440637,20.5621764837914,28.224119,0,0,0,40,4449,250.04825,-60387.3984375,,,,,,,,,,,,,0,,,,-0.00245,,,,,,250.0141907,,,,
,23194515.5,250.0115967,-65222.259765625,0.000150260383815732,3.68339180448134E-6,1,0.999253354069792,40.0298881530762,1.99728472445208,15.939999371767,0.00169094138869181,0.000360964049796011,0.25,5.80417364175307E-6,0.00015051947667965,5.9364261680085E-6,250.0115967,250.0115967,-65229.8828125,-65214.63671875,56.9494539111599,20.5597627414236,28.603769,0,0,0,40,4449,250.0381,-65222.259765625,,,,,,,,,,,,,0,,,,-0.00245,,,,,,250.0115967,,,,
,23194614.705,250.0119781,-70181.765625,0.00016511956483443,2.81837585924269E-6,1,0.999253354069792,40.0298881530762,1.99729119418058,15.939999371767,0.00186663528937379,0.00034780918595316,0.25,2.0663865787441E-6,0.000165407805256897,2.20393911876014E-6,250.0119781,250.0119781,-70186.8203125,-70176.7109375,56.8712910592368,20.5608417998421,28.224119,0,0,0,40,4449,250.0274,-70181.765625,,,,,,,,,,,,,0,,,,-0.0049,,,,,,250.0119781,,,,
,23194713.295,250.01402285,-75108.8046875,0.000183340558054407,3.71542743219876E-6,1,0.999253354069792,40.0298881530762,1.99725571946688,15.939999371767,0.00207158696800065,0.000391933584578699,0.25,2.80219003340374E-6,0.000183660209650163,2.95558214322857E-6,250.0134888,250.0145569,-75113.953125,-75103.65625,56.9252234270637,20.5626370322876,28.224119,0,0,0,40,4449,250.0144,-75108.8046875,,,,,,,,,,,,,0,,,,-0.0049,,,,,,250.01402285,,,,
,23194811.235,250.01297,-80000.51171875,0.000202583548111938,3.82200316491438E-6,1,0.999253354069792,40.0298881530762,1.99738123857409,15.939999371767,0.00229372670245847,0.000406723960298002,0.25,7.68892542821447E-7,0.000202938671706318,9.34036449211053E-7,250.01297,250.01297,-80005.6640625,-79995.359375,56.9322580837368,20.5616716619619,27.844467,0,0,0,40,4449,250.0083,-80000.51171875,,,,,,,,,,,,,0,,,,-0.00245,,,,,,250.01297,,,,
,23194909.365,250.0112915,-84908.25390625,0.00022220491913085,3.97888977328329E-6,1,0.999253354069792,40.0298881530762,1.99745076131246,15.939999371767,0.00251278387497339,0.000464513601805286,0.25,2.46596884159831E-6,0.000222593174693399,2.64966971127685E-6,250.0112915,250.0112915,-84913.234375,-84903.2734375,57.0010413934291,20.5629669676339,28.983419,0,0,0,40,4449,249.9994,-84908.25390625,,,,,,,,,,,,,0,,,,0.00245,,,,,,250.0112915,,,,
,23195003.445,250.0146637,-89609.78515625,0.000236998784337388,3.97088234685913E-6,1,0.999253354069792,40.0298881530762,1.99744026095405,15.939999371767,0.00267674158058042,0.000514606161426888,0.25,4.32227872656866E-6,0.000237411531569586,4.52089216021416E-6,250.0146637,250.0146637,-89614.6328125,-89604.9375,56.8353361473522,20.5626800471279,28.224119,0,0,0,40,4449,249.98275,-89609.78515625,,,,,,,,,,,,,0,,,,-0.0049,,,,,,250.0146637,,,,
,23195115.125,250.0104599,-85765.26953125,0.000223715079608413,3.71283161737842E-6,1,0.999253354069792,40.0298881530762,1.99748364151946,15.939999371767,0.00252660686530169,0.000486675951019391,0.25,4.15949155551311E-6,0.000224104630993836,4.34735450917089E-6,250.0100861,250.0108337,-85770.21875,-85760.3203125,56.9822823089676,20.5632906236892,28.603769,0,0,0,40,4449,249.97455,-85765.26953125,,,,,,,,,,,,,0,,,,0.0049,,,,,,250.0104599,,,,
,23195211.69,250.0052948,-80940.6015625,0.000206425069580812,4.16894206433299E-6,1,0.999253354069792,40.0298881530762,1.99731673452283,15.939999371767,0.00234278412373341,0.000381936062877453,0.25,-2.08404627009914E-6,0.000206789304890014,-1.92083281749073E-6,250.0051422,250.0054474,-80947.84375,-80933.359375,57.0401228193907,20.5644403284499,28.224119,0,0,0,40,4449,249.97425,-80940.6015625,,,,,,,,,,,,,0,,,,0,,,,,,250.0052948,,,,
,23195310.605,249.9958649,-75998.15625,0.000190840619435998,2.67565902214032E-6,1,0.999253354069792,40.0298881530762,1.99738686345168,15.939999371767,0.00216400698521602,0.000364515239916705,0.25,-9.20568498966895E-7,0.000191176580624675,-7.67659124414247E-7,249.9958649,249.9958649,-76010.4375,-75985.875,56.9854088230445,20.565226884931,28.224119,0,0,0,40,4449,249.97805,-75998.15625,,,,,,,,,,,,,0,,,,0.0049,,,,,,249.9958649,,,,
,23195408.015,249.9918518,-71128.30078125,0.000169378966557072,3.25196807458742E-6,1,0.999253354069792,40.0298881530762,1.99738007929733,15.939999371767,0.00190777253582932,0.000397722329508066,0.25,5.73191614564655E-6,0.000169671836760992,5.87934675333932E-6,249.9918518,249.9918518,-71138.2734375,-71118.328125,57.0893654161022,20.5613006512051,28.224119,0,0,0,40,4449,249.98745,-71128.30078125,,,,,,,,,,,,,0,,,,0,,,,,,249.9918518,,,,
,23195503.29,249.9932709,-66366.51171875,0.000154201458883185,3.2861394404346E-6,1,0.999253354069792,40.0298881530762,1.99737714832765,15.939999371767,0.00173887558072558,0.000350231155670485,0.25,4.17202060381749E-6,0.000154468900481172,4.30459209539029E-6,249.9932709,249.9932709,-66371.5859375,-66361.4375,57.0268351345637,20.5609888786069,28.603769,0,0,0,40,4449,249.99315,-66366.51171875,,,,,,,,,,,,,0,,,,-0.00245,,,,,,249.9932709,,,,
,23195600.805,249.99024965,-61493.857421875,0.000135649588231525,2.80857889229124E-6,1,0.999253354069792,40.0298881530762,1.99730186485142,15.939999371767,0.0015369026861695,0.000266073660302719,0.25,-3.81616080040835E-8,0.000135887862197306,7.21146397872512E-8,249.9899597,249.9905396,-61498.95703125,-61488.7578125,56.9916618511983,20.5620765348212,28.224119,0,0,0,40,4449,250.00285,-61493.857421875,,,,,,,,,,,,,0,,,,0,,,,,,249.99024965,,,,
,23195696.235,249.9915466,-56724.3671875,0.000116855234381083,2.62513500197051E-6,1,0.999253354069792,40.0298881530762,1.99721079641781,15.939999371767,0.00131694002165686,0.000269367339989693,0.25,3.51264365942334E-6,0.0001170575859747,3.61400847145429E-6,249.9915466,249.9915466,-56732.0078125,-56716.7265625,56.9822823089676,20.5591428688568,28.603769,0,0,0,40,4449,250.00825,-56724.3671875,,,,,,,,,,,,,0,,,,-0.00245,,,,,,249.9915466,,,,
,23195793.465,249.98913575,-51864.96875,0.00010017375080285,3.11724286623503E-6,1,0.999253354069792,40.0298881530762,1.99723201867737,15.939999371767,0.0011384745538097,0.000176014569119944,0.25,-1.83505931235785E-6,0.000100351161619019,-1.75655600637673E-6,249.9887543,249.9895172,-51875.2109375,-51854.7265625,56.872072687756,20.5594806558421,28.983419,0,0,0,40,4449,250.0194,-51864.96875,,,,,,,,,,,,,0,,,,-0.00245,,,,,,249.98913575,,,,
,23195890.755,249.990448,-47005.138671875,8.35843381027556E-5,2.85386551393315E-6,1,0.999253354069792,40.0298881530762,1.99730651261761,15.939999371767,0.000946720655423479,0.00016560536773369,0.25,1.2237997818494E-7,8.37310048842407E-5,1.90881785311877E-7,249.990448,249.990448,-47012.5078125,-46997.76953125,56.9955699937945,20.5603774781381,28.603769,0,0,0,40,4449,250.0382,-47005.138671875,,,,,,,,,,,,,0,,,,0,,,,,,249.990448,,,,
,23195985.57,249.9853973,-42265.244140625,6.77413957500647E-5,2.55966485894793E-6,1,0.999253354069792,40.0298881530762,1.99729901700133,15.939999371767,0.000762682305098748,0.000160683484804641,0.25,2.43534896551658E-6,6.78583547573414E-5,2.49504720795716E-6,249.9853973,249.9853973,-42275.0859375,-42255.40234375,57.1370447557753,20.558927799331,28.603769,0,0,0,40,4449,250.03995,-42265.244140625,,,,,,,,,,,,,0,,,,-0.0049,,,,,,249.9853973,,,,
,23196082.47,249.9881744,-37422.6640625,4.86053254753929E-5,2.33025567076511E-6,1,0.999253354069792,40.0298881530762,1.99719563626641,15.939999371767,0.00055226036746845,8.61483650037136E-5,0.25,-8.24722765253612E-7,4.86913394247391E-5,-7.86349992591033E-7,249.9881744,249.9881744,-37432.78125,-37412.546875,56.9181887703906,20.558635753021,28.224119,0,0,0,40,4449,250.0492,-37422.6640625,,,,,,,,,,,,,0,,,,0,,,,,,249.9881744,,,,
,23196177.07,249.9908142,-32695.9609375,3.28319696280706E-5,1.48122987260045E-6,1,0.999253354069792,40.0298881530762,1.99735289164948,15.939999371767,0.000371677596649812,6.62209582571388E-5,0.25,1.51200227927315E-7,3.28894828991667E-5,1.78399511209367E-7,249.9908142,249.9908142,-32701.158203125,-32690.763671875,56.9424192544868,20.5562609469613,28.224119,0,0,0,40,4449,250.0555,-32695.9609375,,,,,,,,,,,,,0,,,,0,,,,,,249.9908142,,,,
,23196273.445,249.988678,-27876.4541015625,1.58220578193276E-5,2.27189927126637E-6,1,0.999253354069792,40.0298881530762,1.99727037038396,15.939999371767,0.000173854393345009,6.22058675791215E-5,0.25,2.74687467472352E-6,1.58475768368118E-5,2.7646932194536E-6,249.988678,249.988678,-27884.025390625,-27868.8828125,57.0229269919676,20.5552951457256,28.224119,0,0,0,40,4449,250.06675,-27876.4541015625,,,,,,,,,,,,,0,,,,-0.00245,,,,,,249.988678,,,,
,23196372.07,249.9911957,-22951.482421875,2.53353040380001E-7,1.1452540907997E-6,1,0.999253354069792,40.0298881530762,1.99705627150872,15.939999371767,1.05344142953725E-6,1.09724414387763E-5,0.25,9.24672285215596E-7,2.53037213897889E-7,9.26503716206299E-7,249.9911957,249.9911957,-22956.498046875,-22946.466796875,56.8283014906791,20.5576167807729,27.844467,0,0,0,40,4449,250.07155,-22951.482421875,,,,,,,,,,,,,0,,,,0,,,,,,249.9911957,,,,
,23196467.575,249.9920349,-18176.55859375,-1.46170836690654E-5,1.58626010151389E-6,1,0.999253354069792,40.0298881530762,1.99722577316205,15.939999371767,-0.000166697349894807,-2.23688006264916E-5,0.25,5.60462717481317E-7,-1.46432001020297E-5,5.49409587800026E-7,249.9920349,249.9920349,-18184.0390625,-18169.078125,56.946327397083,20.5584575974318,28.603769,0,0,0,40,4449,250.07835,-18176.55859375,,,,,,,,,,,,,0,,,,0,,,,,,249.9920349,,,,
,23196562.895,249.9905853,-13411.427734375,-2.9444459281041E-5,1.10623067499884E-6,1,0.999253354069792,40.0298881530762,1.99706659578495,15.939999371767,-0.000333996375264891,-5.52679624613373E-5,0.25,2.27542436673582E-7,-2.94963241744406E-5,2.03667106332329E-7,249.9905853,249.9905853,-13416.4951171875,-13406.3603515625,56.7782772654483,20.5569650945052,28.603769,0,0,0,40,4449,250.08275,-13411.427734375,,,,,,,,,,,,,0,,,,0.0049,,,,,,249.9905853,,,,
,23196658.765,249.9918213,-8621.0185546875,-4.17469757260675E-5,7.40267850580339E-7,1,0.999253354069792,40.0298881530762,1.9971297930213,15.939999371767,-0.000472181055896462,-8.63214411749816E-5,0.25,-3.79918446988372E-7,-4.18199254391024E-5,-4.15038637849865E-7,249.9918213,249.9918213,-8628.681640625,-8613.35546875,56.9181887703906,20.5553811533502,28.983419,0,0,0,40,4449,250.09135,-8621.0185546875,,,,,,,,,,,,,0,,,,-0.00245,,,,,,249.9918213,,,,
,23196756.335,249.9933777,-3742.97106933594,-4.7016075973011E-5,4.59303033667029E-7,1,0.999253354069792,40.0298881530762,1.99729759195489,15.939999371767,-0.000531685533108412,-9.79997290811334E-5,0.25,-4.96277005827463E-7,-4.70981693284752E-5,-5.3598771118295E-7,249.9933777,249.9933777,-3750.36694335937,-3735.5751953125,56.8587850029291,20.5546115333825,28.603769,0,0,0,40,4449,250.09485,-3742.97106933594,,,,,,,,,,,,,0,,,,0,,,,,,249.9933777,,,,
,23196850.085,249.99417115,942.242980957031,1.7267920929551E-5,4.0152432118869E-7,1,0.999253354069792,40.0298881530762,1.9972246134195,15.939999371767,0.000197873191223924,2.09757657275428E-5,0.25,-1.14319254721554E-6,1.72991661099957E-5,-1.13092728498328E-6,249.9937592,249.9945831,937.415100097656,947.070861816406,56.9361662263329,20.5555444917852,28.224119,0,0,0,40,4449,250.1005,942.242980957031,,,,,,,,,,,,,0,,,,0,,,,,,249.99417115,,,,
,23196943.075,249.996933,5587.69653320313,4.60734980204221E-5,4.37864696701336E-7,1,0.999253354069792,40.0298881530762,1.99725722018482,15.939999371767,0.000522815078061125,8.56606072762204E-5,0.25,-4.29224744871129E-7,4.61546975891206E-5,-3.9193163209099E-7,249.996933,249.996933,5582.78125,5592.61181640625,56.8986480574099,20.5554676509051,28.603769,0,0,0,40,4449,250.1024,5587.69653320313,,,,,,,,,,,,,0,,,,0,,,,,,249.996933,,,,
,23197038.51,250.0012817,10358.2666015625,3.82449568603183E-5,6.24699569591473E-7,1,0.999253354069792,40.0298881530762,1.99721604043971,15.939999371767,0.00043296149079331,7.69356873250316E-5,0.25,1.58479287594546E-7,3.83119322006197E-5,1.90306748246663E-7,250.0012817,250.0012817,10350.7568359375,10365.7763671875,56.8689461736791,20.5543821237142,28.603769,0,0,0,40,4449,250.1026,10358.2666015625,,,,,,,,,,,,,0,,,,-0.00245,,,,,,250.0012817,,,,
,23197135.855,250.0052185,15223.6147460938,2.32396161964893E-5,1.01920908724598E-6,1,0.999253354069792,40.0298881530762,1.99732932776237,15.939999371767,0.000261817075796523,5.41736360771699E-5,0.25,7.5133681820902E-7,2.32797733182609E-5,7.71804942539643E-7,250.0052185,250.0052185,15218.5908203125,15228.638671875,56.9541436822753,20.5536693887436,28.224119,0,0,0,40,4449,250.09445,15223.6147460938,,,,,,,,,,,,,0,,,,0,,,,,,250.0052185,,,,
,23197231.775,250.0112457,20018.3984375,8.04512137393669E-6,1.1474980547987E-6,1,0.999253354069792,40.0298881530762,1.99718908530178,15.939999371767,9.15543583735431E-5,1.34231629407203E-5,0.25,-2.10332326824582E-7,8.05940958762851E-6,-2.04079689469163E-7,250.0112457,250.0112457,20010.822265625,20025.974609375,56.9080275996406,20.553664018414,28.603769,0,0,0,40,4449,250.0842,20018.3984375,,,,,,,,,,,,,0,,,,-0.00245,,,,,,250.0112457,,,,
,23197328.715,250.0124664,24863.4912109375,-6.6893673392595E-6,1.29013024989115E-6,1,0.999253354069792,40.0298881530762,1.99726418583392,15.939999371767,-7.58869239314362E-5,-1.25543029673349E-5,0.25,5.1941624419217E-8,-6.70114694785183E-6,4.65338066182684E-8,250.0124664,250.0124664,24853.419921875,24873.5625,56.8759808303522,20.5526498640645,28.603769,0,0,0,40,4449,250.0774,24863.4912109375,,,,,,,,,,,,,0,,,,-0.00245,,,,,,250.0124664,,,,
,23197423.315,250.0068665,29591.7646484375,-2.19099688986371E-5,1.36748082132903E-6,1,0.999253354069792,40.0298881530762,1.9972200396701,15.939999371767,-0.000247972420807197,-4.44521636250247E-5,0.25,-1.24132626856622E-7,-2.19483163643842E-5,-1.42338187975813E-7,250.0068665,250.0068665,29586.73828125,29596.791015625,57.0799858738714,20.5504019123048,28.603769,0,0,0,40,4449,250.07725,29591.7646484375,,,,,,,,,,,,,0,,,,0.0049,,,,,,250.0068665,,,,
,23197520.755,250.009079,34461.37890625,-3.69582047321762E-5,1.83857229342948E-6,1,0.999253354069792,40.0298881530762,1.99719734561686,15.939999371767,-0.000414944582573868,-9.42191379533991E-5,0.25,-1.90749828191201E-6,-3.70214994881E-5,-1.94114821260968E-6,250.009079,250.009079,34458.875,34463.8828125,56.8556584888522,20.5533414126623,28.224119,0,0,0,40,4449,250.0636,34461.37890625,,,,,,,,,,,,,0,,,,0,,,,,,250.009079,,,,
,23197616.655,250.01091,39253.48046875,-5.69658518291815E-5,1.85478294609437E-6,1,0.999253354069792,40.0298881530762,1.99715646385466,15.939999371767,-0.000643009571151328,-0.000125365888288275,0.25,-1.18739814764471E-6,-5.70648534303326E-5,-1.23612605448271E-6,250.01091,250.01091,39246.046875,39260.9140625,56.8595666314483,20.5509340993268,28.603769,0,0,0,40,4449,250.055,39253.48046875,,,,,,,,,,,,,0,,,,-0.00245,,,,,,250.01091,,,,
,23197715.175,250.0155945,44178.6015625,-7.22445295738669E-5,2.03952773627445E-6,1,0.999253354069792,40.0298881530762,1.9971442188416,15.939999371767,-0.000815689348027474,-0.000157694648947837,0.25,-1.39168984949248E-6,-7.23701763491802E-5,-1.45320387306728E-6,250.0155945,250.0155945,44173.76171875,44183.44140625,56.8095424062176,20.5515460932695,28.603769,0,0,0,40,4449,250.04195,44178.6015625,,,,,,,,,,,,,0,,,,0.0049,,,,,,250.0155945,,,,
,23197812.31,250.0148773,49034.544921875,-9.02098697853647E-5,2.1743727682351E-6,1,0.999253354069792,40.0298881530762,1.99732193953736,15.939999371767,-0.00101933906330515,-0.000192761112897314,0.25,-1.370259089231E-6,-9.03670777069427E-5,-1.446320403019E-6,250.0148773,250.0148773,49027.11328125,49041.9765625,56.9111541137176,20.5508344621452,28.603769,0,0,0,40,4449,250.0322,49034.544921875,,,,,,,,,,,,,0,,,,-0.00245,,,,,,250.0148773,,,,
,23197909.555,250.012558,53894.390625,-0.000108881903629649,2.08749594803033E-6,1,0.999253354069792,40.0298881530762,1.9974408925324,15.939999371767,-0.0012302587445318,-0.000233467554659566,0.25,-1.72414603697914E-6,-0.000109071619410997,-1.81594334000736E-6,250.012558,250.012558,53884.55078125,53904.23046875,56.7939098358329,20.5502728654175,28.603769,0,0,0,40,4449,250.0278,53894.390625,,,,,,,,,,,,,0,,,,0,,,,,,250.012558,,,,
,23198006.83,250.0112915,58757.1875,-0.000125516145930823,2.81589748653467E-6,1,0.999253354069792,40.0298881530762,1.99725324435412,15.939999371767,-0.00141779702985488,-0.000270757194259027,0.25,-2.13299740585328E-6,-0.000125734751232765,-2.23892635529666E-6,250.0112915,250.0112915,58747.35546875,58767.01953125,56.8345545188329,20.5491043752221,28.603769,0,0,0,40,4449,250.01195,58757.1875,,,,,,,,,,,,,0,,,,0,,,,,,250.0112915,,,,
,23198104.515,250.0122833,63639.923828125,-0.000142073341634254,2.38352823494672E-6,1,0.999253354069792,40.0298881530762,1.99745814695306,15.939999371767,-0.00161155708768765,-0.000268576400464006,0.25,9.32891326459437E-7,-0.000142323521982393,8.19039887181549E-7,250.0122833,250.0122833,63629.94921875,63649.8984375,56.8970848003714,20.549654582743,28.983419,0,0,0,40,4449,250.0031,63639.923828125,,,,,,,,,,,,,0,,,,-0.0049,,,,,,250.0122833,,,,
,23198199.295,250.01297,68375.390625,-0.000160808458741829,3.02981501264699E-6,1,0.999253354069792,40.0298881530762,1.9975434642146,15.939999371767,-0.00182082617486212,-0.00032315343037653,0.25,-6.34170256318129E-7,-0.000161090274522978,-7.65809068640588E-7,250.01297,250.01297,68367.859375,68382.921875,56.7657712091406,20.548399434124,28.224119,0,0,0,40,4449,249.99295,68375.390625,,,,,,,,,,,,,0,,,,-0.00245,,,,,,250.01297,,,,
,23198296.54,250.0164642,73235.5625,-0.000181653878011795,3.67447764283808E-6,1,0.999253354069792,40.0298881530762,1.99751854104339,15.939999371767,-0.00205540738764481,-0.000373262247467186,0.25,-1.44235262503143E-6,-0.000181971640196624,-1.59210283580783E-6,250.0164642,250.0164642,73225.4453125,73245.6796875,56.6657227586791,20.5465311904866,28.224119,0,0,0,40,4449,249.98355,73235.5625,,,,,,,,,,,,,0,,,,-0.00245,,,,,,250.0164642,,,,
,23198393.19,250.013504,78066.10546875,-0.000197452171627322,3.19239194277195E-6,1,0.999253354069792,40.0298881530762,1.99755173432676,15.939999371767,-0.00223800408288822,-0.000383797069852999,0.25,3.67758323472692E-7,-0.000197799185482478,2.08629035529127E-7,250.013504,250.013504,78063.5625,78068.6484375,56.7423223535637,20.5453107492929,28.224119,0,0,0,40,4449,249.9715,78066.10546875,,,,,,,,,,,,,0,,,,-0.0049,,,,,,250.013504,,,,
,23198490.62,250.0111847,82937.03125,-0.00021369141924769,3.28590439670743E-6,1,0.999253354069792,40.0298881530762,1.99754383471528,15.939999371767,-0.00242251308975792,-0.000412734910938461,0.25,6.29463888592248E-7,-0.000214067206890258,4.57924949466766E-7,250.0111847,250.0111847,82927.109375,82946.953125,56.8845787440637,20.5457097043186,28.603769,0,0,0,40,4449,249.95915,82937.03125,,,,,,,,,,,,,0,,,,0.00245,,,,,,250.0111847,,,,
,23198583.705,250.0098419,87590.390625,-0.000229495337339471,3.26195773448697E-6,1,0.999253354069792,40.0298881530762,1.99749948987345,15.939999371767,-0.00259766051027013,-0.000466081310935193,0.25,-1.33929343403884E-6,-0.000229897332935477,-1.52677166160972E-6,250.0098419,250.0098419,87580.4296875,87600.3515625,56.7423223535637,20.5452680465963,28.224119,0,0,0,40,4449,249.95425,87590.390625,,,,,,,,,,,,,0,,,,-0.0049,,,,,,250.0098419,,,,
,23198693.375,250.0132599,87890.42578125,-0.000236128007347276,3.00776727371149E-6,1,0.999253354069792,40.0298881530762,1.99749092552728,15.939999371767,-0.00268119529226285,-0.000430700269711216,0.25,2.93332846682373E-6,-0.00023654507069219,2.74801052741899E-6,250.0132599,250.0132599,87882.9453125,87897.90625,56.7900016932368,20.5459863749536,28.603769,0,0,0,40,4449,249.9399,87890.42578125,,,,,,,,,,,,,0,,,,0,,,,,,250.0132599,,,,
,23198787.635,250.0072479,83182.01953125,-0.000215610716218446,3.97200776886802E-6,1,0.999253354069792,40.0298881530762,1.99742150753953,15.939999371767,-0.00244585799544477,-0.000406445142248974,0.25,1.51530316100164E-6,-0.000215990620191327,1.3437667302036E-6,250.0072479,250.0072479,83169.5703125,83194.46875,56.6704125297944,20.545642634397,28.603769,0,0,0,40,4449,249.93805,83182.01953125,,,,,,,,,,,,,0,,,,0,,,,,,250.0072479,,,,
,23198884.745,249.998764,78325.91015625,-0.000200116693995603,3.92809542230118E-6,1,0.999253354069792,40.0298881530762,1.99734448136658,15.939999371767,-0.00226068235246137,-0.000431029834699414,0.25,-3.34247705782236E-6,-0.000200465488782397,-3.51028644703057E-6,249.998764,249.998764,78321.265625,78330.5546875,56.8423708040252,20.547171942916,28.603769,0,0,0,40,4449,249.9434,78325.91015625,,,,,,,,,,,,,0,,,,-0.00245,,,,,,249.998764,,,,
,23198980.915,249.9931641,73517.51953125,-0.00017895702152841,2.69754748660313E-6,1,0.999253354069792,40.0298881530762,1.99747799778011,15.939999371767,-0.00202104470007709,-0.000389686664930411,0.25,-3.36020880364599E-6,-0.000179268642048403,-3.51115422208921E-6,249.9931641,249.9931641,73512.265625,73522.7734375,56.9056827140829,20.5461271842163,28.983419,0,0,0,40,4449,249.9478,73517.51953125,,,,,,,,,,,,,0,,,,-0.00245,,,,,,249.9931641,,,,
,23199076.205,249.9875488,68756.875,-0.00016067220463522,3.36611149580234E-6,1,0.999253354069792,40.0298881530762,1.99750346196232,15.939999371767,-0.0018232420985608,-0.000299854190578328,0.25,1.39801781223205E-6,-0.000160955576067733,1.2700539352302E-6,249.9875488,249.9875488,68749.421875,68764.328125,56.7360693254098,20.5459520203538,28.603769,0,0,0,40,4449,249.9587,68756.875,,,,,,,,,,,,,0,,,,-0.0049,,,,,,249.9875488,,,,
,23199174.64,249.9914398,63836.5234375,-0.000146130981357053,3.15640400426332E-6,1,0.999253354069792,40.0298881530762,1.99747755422261,15.939999371767,-0.00166131888509192,-0.000254804618562704,0.25,2.85226518292927E-6,-0.000146389952993937,2.73847326064905E-6,249.9914398,249.9914398,63826.6484375,63846.3984375,56.882233858506,20.546823949973,28.603769,0,0,0,40,4449,249.96495,63836.5234375,,,,,,,,,,,,,0,,,,0,,,,,,249.9914398,,,,
,23199271.235,249.9855499,59005.734375,-0.000126502741199023,2.92821855644711E-6,1,0.999253354069792,40.0298881530762,1.99746393725335,15.939999371767,-0.00143425390813085,-0.000243115091622467,0.25,4.80195361670445E-7,-0.000126725321348611,3.78043203653683E-7,249.9855499,249.9855499,59003.27734375,59008.19140625,56.7946914643522,20.5496397933476,28.603769,0,0,0,40,4449,249.9791,59005.734375,,,,,,,,,,,,,0,,,,-0.0049,,,,,,249.9855499,,,,
,23199370.445,249.9890594,54047.908203125,-0.000109099635225718,2.38478985173189E-6,1,0.999253354069792,40.0298881530762,1.99744862211022,15.939999371767,-0.00123239303366003,-0.00023584669108928,0.25,-1.89626562517885E-6,-0.000109289682928403,-1.98855579779522E-6,249.9890594,249.9890594,54035.57421875,54060.2421875,56.8744175733137,20.548555555993,28.983419,0,0,0,40,4449,249.9899,54047.908203125,,,,,,,,,,,,,0,,,,0,,,,,,249.9890594,,,,
,23199469.26,249.9911346,49110.716796875,-9.09676305004407E-5,2.22026582370274E-6,1,0.999253354069792,40.0298881530762,1.99745428867311,15.939999371767,-0.00103591150003832,-0.000148583038948032,0.25,2.66138958222181E-6,-9.11295364804091E-5,2.59177718510305E-6,249.9911346,249.9911346,49103.28125,49118.15234375,56.9041194570445,20.5481513590715,28.603769,0,0,0,40,4449,249.99735,49110.716796875,,,,,,,,,,,,,0,,,,0,,,,,,249.9911346,,,,
,23199565.125,249.9859619,44317.419921875,-7.29946277371189E-5,1.83418602936966E-6,1,0.999253354069792,40.0298881530762,1.99755264990664,15.939999371767,-0.000830800100738272,-0.000121997200528795,0.25,1.89162461348371E-6,-7.31243521165921E-5,1.83525343703369E-6,249.9859619,249.9859619,44310.0703125,44324.76953125,56.8494054606983,20.5473877730308,28.983419,0,0,0,40,4449,250.00555,44317.419921875,,,,,,,,,,,,,0,,,,-0.00245,,,,,,249.9859619,,,,
,23199662.75,249.9849243,39437.330078125,-5.76648014807704E-5,1.5310931923836E-6,1,0.999253354069792,40.0298881530762,1.9974407205648,15.939999371767,-0.000654499472587083,-0.000106673316398937,0.25,5.85141439591432E-7,-5.77665341146464E-5,5.38947667983253E-7,249.9849243,249.9849243,39427.20703125,39447.453125,56.7876568076791,20.5480288385199,28.983419,0,0,0,40,4449,250.02195,39437.330078125,,,,,,,,,,,,,0,,,,-0.00245,,,,,,249.9849243,,,,
,23199758.625,249.9882965,34645.080078125,-3.8556640552009E-5,1.31687532775525E-6,1,0.999253354069792,40.0298881530762,1.99749630795744,15.939999371767,-0.000437096978292141,-7.44126835982302E-5,0.25,1.18976644379608E-7,-3.86244301456279E-5,8.75685015434991E-8,249.9882965,249.9882965,34640.171875,34649.98828125,56.7118388413137,20.5493501468572,28.603769,0,0,0,40,4449,250.0257,34645.080078125,,,,,,,,,,,,,0,,,,0.00245,,,,,,249.9882965,,,,
,23199854.115,249.9906158,29872.9931640625,-2.34945217074647E-5,1.38755276172288E-6,1,0.999253354069792,40.0298881530762,1.99744702375226,15.939999371767,-0.000267650593819402,-3.77798148475954E-5,0.25,7.39993733309577E-7,-2.3536372752906E-5,7.22001767357352E-7,249.9906158,249.9906158,29867.755859375,29878.23046875,56.9103724851983,20.5487352476412,28.224119,0,0,0,40,4449,250.0349,29872.9931640625,,,,,,,,,,,,,0,,,,0,,,,,,249.9906158,,,,
,23199950.69,249.99185945,25047.55078125,-9.77666966097364E-6,1.32989074239428E-6,1,0.999253354069792,40.0298881530762,1.99758824962045,15.939999371767,-0.000103623213824534,-6.04715693141613E-5,0.25,-3.6413750979355E-6,-9.79083678814738E-6,-3.65580458129678E-6,249.9918213,249.9918976,25035.234375,25059.8671875,56.8767624588714,20.5534427894348,28.603769,0,0,0,40,4449,250.04155,25047.55078125,,,,,,,,,,,,,0,,,,0.00245,,,,,,249.99185945,,,,
,23200046.25,249.98949435,20270.3330078125,8.08677073574513E-6,1.00345213153668E-6,1,0.999253354069792,40.0298881530762,1.99746314096099,15.939999371767,8.99206564317517E-5,2.57177164549086E-5,0.25,8.67398085383086E-7,8.10025113231596E-6,8.755771295352E-7,249.9892426,249.9897461,20262.736328125,20277.9296875,56.8916134007368,20.5521991608153,28.983419,0,0,0,40,4449,250.052,20270.3330078125,,,,,,,,,,,,,0,,,,0,,,,,,249.98949435,,,,
,23200142.285,249.9908142,15470.9936523438,2.39103134447627E-5,8.85468650182374E-7,1,0.999253354069792,40.0298881530762,1.99760157898154,15.939999371767,0.000271917045735214,4.12784960999881E-5,0.25,-5.03647264275064E-7,2.39526935935276E-5,-4.84826454899606E-7,249.9908142,249.9908142,15465.89453125,15476.0927734375,56.7563916669098,20.5512874023287,28.603769,0,0,0,40,4449,250.05765,15470.9936523438,,,,,,,,,,,,,0,,,,0,,,,,,249.9908142,,,,
,23200237.195,249.9940643,10728.4111328125,3.76510785619595E-5,6.39998432084779E-7,1,0.999253354069792,40.0298881530762,1.99766694112906,15.939999371767,0.000426797008245909,7.30661612095173E-5,0.25,-8.14842216763831E-8,3.77172191754517E-5,-5.05646204190119E-8,249.9940643,249.9940643,10723.66015625,10733.162109375,56.8994296859291,20.5505900557583,28.603769,0,0,0,40,4449,250.06395,10728.4111328125,,,,,,,,,,,,,0,,,,0,,,,,,249.9940643,,,,
,23200333.18,249.9912109,5930.32006835938,4.67176609570737E-5,3.97671574075565E-7,1,0.999253354069792,40.0298881530762,1.9975823220658,15.939999371767,0.000530408323928674,8.57115805979146E-5,0.25,-5.37620265086146E-7,4.68000895106857E-5,-4.9998171105798E-7,249.9912109,249.9912109,5925.39501953125,5935.2451171875,57.0495023616214,20.5522978371087,28.983419,0,0,0,40,4449,250.06725,5930.32006835938,,,,,,,,,,,,,0,,,,-0.00245,,,,,,249.9912109,,,,
,23200426.585,249.9968719,1261.72729492188,4.28778501162255E-5,4.06691280320122E-7,1,0.999253354069792,40.0298881530762,1.99754790729158,15.939999371767,0.000485880312581555,8.39970602465194E-5,0.25,-2.29150644502419E-8,4.29531034414373E-5,1.24826896257574E-8,249.9968719,249.9968719,1256.94018554688,1266.51440429688,56.8603482599676,20.5502979868897,28.603769,0,0,0,40,4449,250.0841,1261.72729492188,,,,,,,,,,,,,0,,,,0.0049,,,,,,249.9968719,,,,
,23200451.855,249.9958344,-0.182685278356075,2.48033042193248E-5,3.53904449647401E-7,1,0.999253354069792,40.0298881530762,1.99756710295755,15.939999371767,0.000281871972570919,4.3948068161412E-5,0.25,-4.2291189322208E-7,2.48471746354279E-5,-4.03149759643968E-7,249.9958344,249.9958344,-0.19790905714035,-0.1674614995718,56.997133250833,20.5511724647065,28.983419,0,0,0,40,4417,250.0699,-0.182685278356075,,,,,,,,,,,,,0,,,,-0.0049,,,,,,249.9958344,,,,