File: data/doubleLayers/dl_2-5/ppms/data/DD205_5_HYST_300KREPEAT.DAT
[Header]
; VSM Data File (default extension .dat)
; Copyright (c) 2003-2013, Quantum Design, Inc. All rights reserved.
TITLE,
FILEOPENTIME,33026698.91,01/18/2019,2:07 pm
BYAPP,VSM,2.0,2.0
INFO,PPMS VSM Option Release 1.4.10 Build 1,APPNAME
INFO,Quantum Design Linear Motor Servo Controller,MOTOR_MODULE_NAME
INFO,3101-100 M1,MOTOR_HW_VERSION
INFO,MMC1014,MOTOR_SERIAL_NUMBER
INFO,SRV No X-over 01.03.11,MOTOR_SOFTWARE_VERSION
INFO,Quantum Design VSM Detection Module,VSM_MODULE_NAME
INFO,3101-150 F0,VSM_HW_VERSION
INFO,VSM707,VSM_SERIAL_NUMBER
INFO,VSM No X-over 01.02.05 May 20 2008 13:51:47,VSM_SOFTWARE_VERSION
INFO,704,PREAMP_SERIAL_NUMBER
INFO,822,COIL_SERIAL_NUMBER
INFO,0,MOMENT_UNITS
INFO,DL 2.5,SAMPLE_MATERIAL
INFO,CoFe2O4,SAMPLE_COMMENT
INFO,29.51,SAMPLE_MASS
INFO,,SAMPLE_VOLUME
INFO,,SAMPLE_MOLECULAR_WEIGHT
INFO,,SAMPLE_SIZE
INFO,,SAMPLE_SHAPE
DATATYPE,COMMENT,1
DATATYPE,TIME,2
STARTUPAXIS,X,2
STARTUPAXIS,Y1,5
[Data]
Comment,Time Stamp (sec),Temperature (K),Magnetic Field (Oe),Moment (emu),M. Std. Err. (emu),Transport Action,Averaging Time (sec),Frequency (Hz),Peak Amplitude (mm),Center Position (mm),Coil Signal' (mV),Coil Signal" (mV),Range (mV),M. Quad. Signal (emu),M. Raw' (emu),M. Raw" (emu),Min. Temperature (K),Max. Temperature (K),Min. Field (Oe),Max. Field (Oe),Mass (grams),Motor Lag (deg),Pressure (Torr),VSM Status (code),Motor Status (code),Measure Status (code),Measure Count,PPMS Status (code),System Temp. (K),System Field (Oe),Sample Position (deg),Bridge 1 Resistance (ohms),Bridge 1 Excitation (에),Bridge 2 Resistance (ohms),Bridge 2 Excitation (에),Bridge 3 Resistance (ohms),Bridge 3 Excitation (에),Bridge 4 Resistance (ohms),Bridge 4 Excitation (에),Signal 1 Vin (V),Signal 2 Vin (V),Digital Inputs (code),Drive 1 Iout (mA),Drive 1 Ipower (W),Drive 2 Iout (mA),Drive 2 Ipower (W),Pressure (),Map 20 (),Map 21 (),Map 22 (),Map 23 (),Map 24 (),Map 25 (),Map 26 (),Map 27 (),Map 28 (),Map 29 ()
,33026724.14,300.0033264,0.0761188715696335,,,2,,,,19.1500004321337,,,,,,,300.0033264,300.0033264,0.0761188715696335,0.0761188715696335,,,22.909004,,,,-99999999,4369,300.1953,0.0761188715696335,,,,,,,,,,,,,,,,,,,,,,,300.0033264,,,,
,33026829.26,300.0027466,1960.36004638672,4.05273643097158E-5,3.57712562123771E-7,1,0.999253354069792,40.0298881530762,2.00056862666523,19.1399995237589,0.000459219494481058,7.86096464005204E-5,0.25,-8.18305406656547E-8,4.0526205213997E-5,-5.49418558073809E-8,300.0027466,300.0027466,1952.80798339844,1967.912109375,56.0779381122175,20.5507174463948,22.909004,0,0,0,40,4449,300.1885,1960.36004638672,,,,,,,,,,,,,0,,,,0.00245,,,,,,300.0027466,,,,
,33026873.64,300.0041504,4174.19848632812,4.39475322145281E-5,4.90314421956885E-7,1,0.999253354069792,40.0298881530762,2.0005840215439,19.1399995237589,0.000497402346398085,8.85632161399041E-5,0.25,2.04278894047607E-7,4.39460794663155E-5,2.33419845320223E-7,300.0041504,300.0041504,4166.69677734375,4181.7001953125,56.3733936924867,20.5555109678825,22.529354,0,0,0,40,4449,300.1827,4174.19848632812,,,,,,,,,,,,,0,,,,0.0049,,,,,,300.0041504,,,,
,33026917.345,300.001709,6358.39721679688,4.20334227589925E-5,7.51007595303767E-7,1,0.999253354069792,40.0298881530762,2.0005697108344,19.1399995237589,0.000474951634057265,8.92271232429826E-5,0.25,5.94591395019172E-7,4.20317732135778E-5,6.2244155613041E-7,300.001709,300.001709,6348.36669921875,6368.427734375,56.313208296506,20.559901689331,23.288654,0,0,0,40,4449,300.1864,6358.39721679688,,,,,,,,,,,,,0,,,,0.00245,,,,,,300.001709,,,,
,33026962.66,300.0007935,8622.16015625,3.80482386672766E-5,8.77217880029973E-7,1,0.999253354069792,40.0298881530762,2.00039709932386,19.1399995237589,0.00042773513196164,9.31759000472942E-5,0.25,1.63436033648319E-6,3.80460212122765E-5,1.65952849496953E-6,300.0007935,300.0007935,8617.1123046875,8627.2080078125,56.2921043264867,20.5623249620793,22.909004,0,0,0,40,4449,300.18195,8622.16015625,,,,,,,,,,,,,0,,,,-0.0049,,,,,,300.0007935,,,,
,33027007.14,300.0012512,10846.6298828125,3.34492210918276E-5,8.7937914252767E-7,1,0.999253354069792,40.0298881530762,2.00032163579443,19.1399995237589,0.00037735640117985,7.41961818061982E-5,0.25,7.55693595531219E-7,3.34477235446669E-5,7.77830941940027E-7,300.0012512,300.0012512,10841.578125,10851.681640625,56.2670922138713,20.5617736925846,23.668306,0,0,0,40,4449,300.1874,10846.6298828125,,,,,,,,,,,,,0,,,,0.0049,,,,,,300.0012512,,,,
,33027051.945,300.00138855,13083.0966796875,2.60223157619502E-5,1.19779633406004E-6,1,0.999253354069792,40.0298881530762,2.00034554205525,19.1399995237589,0.000292547664415996,6.36425923830083E-5,0.25,1.11059633615819E-6,2.60208051668454E-5,1.12779642542144E-6,300.0012207,300.0015564,13075.677734375,13090.515625,56.5633294226598,20.5632490859386,23.288654,0,0,0,40,4449,300.18025,13083.0966796875,,,,,,,,,,,,,0,,,,-0.00245,,,,,,300.00138855,,,,
,33027098.355,300.0033112,15404.5756835938,1.94509931272813E-5,1.00817547372244E-6,1,0.999253354069792,40.0298881530762,2.00030619121842,19.1399995237589,0.000218385235409342,4.91996112486823E-5,0.25,9.74009901293554E-7,1.94497681694997E-5,9.86856531362133E-7,300.0027161,300.0039063,15394.6103515625,15414.541015625,56.445303516256,20.5636664574613,23.668306,0,0,0,40,4449,300.1823,15404.5756835938,,,,,,,,,,,,,0,,,,0.00245,,,,,,300.0033112,,,,
,33027144.695,300.00286865,17723.2626953125,1.3205063813566E-5,1.13446184893265E-6,1,0.999253354069792,40.0298881530762,2.0004494176937,19.1399995237589,0.000144813733092984,5.33488590091893E-5,0.25,2.42220828959754E-6,1.32030677940922E-5,2.43087342190663E-6,300.0027771,300.0029602,17718.17578125,17728.349609375,56.5648926796983,20.563267094242,23.668306,0,0,0,40,4449,300.18235,17723.2626953125,,,,,,,,,,,,,0,,,,0,,,,,,300.00286865,,,,
,33027190.72,300.0023804,20021.84765625,5.38508951549964E-6,1.23952732246842E-6,1,0.999253354069792,40.0298881530762,2.00037917536227,19.1399995237589,5.69806853247107E-5,3.3720535784317E-5,0.25,2.04422772708449E-6,5.38357735708007E-6,2.04772845815197E-6,300.0023804,300.0023804,20016.6640625,20027.03125,56.6407106460637,20.5648934456692,22.909004,0,0,0,40,4449,300.18,20021.84765625,,,,,,,,,,,,,0,,,,-0.0049,,,,,,300.0023804,,,,
,33027234.185,300.0020752,22193.044921875,-3.32247910670867E-6,8.94644567598444E-7,1,0.999253354069792,40.0298881530762,2.00029217158611,19.1399995237589,-4.53541653016526E-5,3.80668761413462E-5,0.25,3.93676593942127E-6,-3.32498281204942E-6,3.93445268408609E-6,300.0020752,300.0020752,22185.595703125,22200.494140625,56.6094455052945,20.5654929031945,23.668306,0,0,0,40,4449,300.19255,22193.044921875,,,,,,,,,,,,,0,,,,0.00245,,,,,,300.0020752,,,,
,33027279.79,299.9964905,24472.404296875,-8.10694495791773E-6,1.61731547087651E-6,1,0.999253354069792,40.0298881530762,2.00017569768739,19.1399995237589,-9.73887833438964E-5,1.62847622507729E-5,0.25,2.84253260320112E-6,-8.10858422319857E-6,2.83709207052152E-6,299.9964905,299.9964905,24465,24479.80859375,56.7032409276022,20.5667392293646,23.288654,0,0,0,40,4449,300.18515,24472.404296875,,,,,,,,,,,,,0,,,,0.0049,,,,,,299.9964905,,,,
,33027324.855,299.9963379,26723.86328125,-1.70418785996715E-5,1.34202940602572E-6,1,0.999253354069792,40.0298881530762,2.00025491724999,19.1399995237589,-0.000203977954307396,2.98823028952418E-5,0.25,5.59113303468807E-6,-1.7045069479324E-5,5.57971315865828E-6,299.9963379,299.9963379,26718.7890625,26728.9375,56.5406621956021,20.5684225551123,23.288654,0,0,0,40,4449,300.1864,26723.86328125,,,,,,,,,,,,,0,,,,-0.0049,,,,,,299.9963379,,,,
,33027369.6,299.9967041,28962.9462890625,-2.38721988058282E-5,1.70735517167732E-6,1,0.999253354069792,40.0298881530762,2.00012733504696,19.1399995237589,-0.000275267481030437,-1.84393313475201E-5,0.25,2.5077855337029E-6,-2.38731517595729E-5,2.49195314338955E-6,299.9967041,299.9967041,28957.9453125,28967.947265625,56.7540467813522,20.5682183081957,23.288654,0,0,0,40,4449,300.1905,28962.9462890625,,,,,,,,,,,,,0,,,,-0.00245,,,,,,299.9967041,,,,
,33027414.17,300.0021057,31189.4462890625,-3.25256282077299E-5,1.02385579353131E-6,1,0.999253354069792,40.0298881530762,2.00021250264956,19.1399995237589,-0.000379683331049422,1.53563077629898E-6,0.25,5.77086498386546E-6,-3.25284734157732E-5,5.74923263529759E-6,300.0021057,300.0021057,31187,31191.892578125,56.6188250475252,20.5675563457364,23.288654,0,0,0,40,4449,300.1797,31189.4462890625,,,,,,,,,,,,,0,,,,0.0049,,,,,,300.0021057,,,,
,33027459.965,300.0039978,33478.349609375,-4.25637558217575E-5,1.91263640977419E-6,1,0.999253354069792,40.0298881530762,2.00013669154161,19.1399995237589,-0.000486949331293001,-5.51005045564699E-5,0.25,2.50895777842168E-6,-4.25641491775325E-5,2.48081288893619E-6,300.0039978,300.0039978,33475.83203125,33480.8671875,56.7540467813522,20.56840769923,23.288654,0,0,0,40,4449,300.1844,33478.349609375,,,,,,,,,,,,,0,,,,0.0049,,,,,,300.0039978,,,,
,33027504.55,300.00057985,35707.1875,-4.98514325505286E-5,1.66474004524521E-6,1,0.999253354069792,40.0298881530762,2.00005589295868,19.1399995237589,-0.000572423544415482,-5.22862584393666E-5,0.25,4.01990122670507E-6,-4.98526126678278E-5,3.98692130992415E-6,300.0001831,300.0009766,35694.5703125,35719.8046875,56.5484784807944,20.5723675815864,23.668306,0,0,0,40,4449,300.1778,35707.1875,,,,,,,,,,,,,0,,,,0,,,,,,300.00057985,,,,
,33027551.015,300.0028076,38028.439453125,-5.98547145200356E-5,1.22970806973719E-6,1,0.999253354069792,40.0298881530762,1.99993870412098,19.1399995237589,-0.000693644735769628,-2.58574702357626E-5,0.25,8.08667242650025E-6,-5.98582746894644E-5,8.04700007233233E-6,300.0028076,300.0028076,38018.5,38038.37890625,56.6258597041983,20.569788352823,23.288654,0,0,0,40,4449,300.1869,38028.439453125,,,,,,,,,,,,,0,,,,0,,,,,,300.0028076,,,,
,33027596.04,300.0066528,40279.80859375,-6.63475388598549E-5,1.75410272398815E-6,1,0.999253354069792,40.0298881530762,1.999922885977,19.1399995237589,-0.0007699322447041,-2.2605550337571E-5,0.25,9.49873015905189E-6,-6.63518273668094E-5,9.45475716607554E-6,300.0066528,300.0066528,40277.109375,40282.5078125,56.7923465787945,20.5702429454502,23.288654,0,0,0,40,4449,300.17215,40279.80859375,,,,,,,,,,,,,0,,,,0.0049,,,,,,300.0066528,,,,
,33027641.445,300.0073547,42548.546875,-7.66455314800624E-5,1.20353342190436E-6,1,0.999253354069792,40.0298881530762,1.99999852883761,19.1399995237589,-0.000886986900719433,-4.04340145347358E-5,0.25,9.70856653594078E-6,-7.6649649998393E-5,9.65783254559564E-6,300.0073547,300.0073547,42536.109375,42560.984375,56.7055858131598,20.5694078204777,23.288654,0,0,0,40,4449,300.17455,42548.546875,,,,,,,,,,,,,0,,,,-0.00245,,,,,,300.0073547,,,,
,33027685.41,300.0029297,44745.544921875,-8.56123208657748E-5,1.66152425439105E-6,1,0.999253354069792,40.0298881530762,1.99993172936223,19.1399995237589,-0.000988386256337865,-5.86584133630202E-5,0.25,9.65256185979659E-6,-8.56161497702296E-5,9.59595646138182E-6,300.0029297,300.0029297,44740.46484375,44750.625,56.6539983308906,20.5691100754989,23.288654,0,0,0,40,4449,300.1668,44745.544921875,,,,,,,,,,,,,0,,,,0.00245,,,,,,300.0029297,,,,
,33027729.855,300.002533,46969.201171875,-9.06598576429569E-5,1.45879912245444E-6,1,0.999253354069792,40.0298881530762,1.99984847584496,19.1399995237589,-0.0010481791562774,-5.31036898635419E-5,0.25,1.10173880918766E-5,-9.06644359830337E-5,1.09574560812919E-5,300.002533,300.002533,46959.16015625,46979.2421875,56.7188734979868,20.571561006495,22.909004,0,0,0,40,4449,300.1786,46969.201171875,,,,,,,,,,,,,0,,,,0.00245,,,,,,300.002533,,,,
,33027774.72,300.0039673,49210.693359375,-9.94582099006055E-5,2.03573854771569E-6,1,0.999253354069792,40.0298881530762,1.99981609514881,19.1399995237589,-0.0011425538548828,-0.000100570603642433,0.25,8.34958584281149E-6,-9.94607705425996E-5,8.28397802280179E-6,300.0039673,300.0039673,49203.0703125,49218.31640625,56.6117903908521,20.5703332461256,23.288654,0,0,0,40,4449,300.16425,49210.693359375,,,,,,,,,,,,,0,,,,0.00245,,,,,,300.0039673,,,,
,33027818.245,300.0082703,51387.138671875,-0.000108754823189967,1.25582506693661E-6,1,0.999253354069792,40.0298881530762,1.99984462907449,19.1399995237589,-0.00125578972118584,-7.29077627965137E-5,0.25,1.24033520592071E-5,-0.000108759756555067,1.23315532013298E-5,300.0082703,300.0082703,51377.2578125,51397.01953125,56.5820885071214,20.5696634816931,23.668306,0,0,0,40,4449,300.173,51387.138671875,,,,,,,,,,,,,0,,,,0,,,,,,300.0082703,,,,
,33027864.7,300.0043335,53708.591796875,-0.000119070746574513,1.71304456446145E-6,1,0.999253354069792,40.0298881530762,1.99983284227439,19.1399995237589,-0.00137339466076381,-8.85112459441543E-5,0.25,1.28125308320521E-5,-0.000119075659998576,1.27339860954819E-5,300.0043335,300.0043335,53701.19921875,53715.984375,56.5727089648906,20.5691718817469,22.909004,0,0,0,40,4449,300.161,53708.591796875,,,,,,,,,,,,,0,,,,0.00245,,,,,,300.0043335,,,,
,33027909.595,300.0021057,55952.19921875,-0.000127712745519371,1.39856844458091E-6,1,0.999253354069792,40.0298881530762,1.99970907810812,19.1399995237589,-0.00147185194618506,-0.000101480905426422,0.25,1.31637957619318E-5,-0.000127717645213472,1.30796180395492E-5,300.0021057,300.0021057,55939.921875,55964.4765625,56.6055373626983,20.5708728936524,23.288654,0,0,0,40,4449,300.17285,55952.19921875,,,,,,,,,,,,,0,,,,0,,,,,,300.0021057,,,,
,33027952.485,300.0011902,58093.83203125,-0.000133219592930698,2.352593108743E-6,1,0.999253354069792,40.0298881530762,1.99978377949385,19.1399995237589,-0.00153158889202139,-0.000127693514999543,0.25,1.18031403510752E-5,-0.000133223443161739,1.17154348297245E-5,300.0011902,300.0011902,58084.03515625,58103.62890625,56.6321127323521,20.5701116158654,23.288654,0,0,0,40,4449,300.1707,58093.83203125,,,,,,,,,,,,,0,,,,0,,,,,,300.0011902,,,,
,33027997.515,300.0090332,60347.998046875,-0.000141819222962504,1.88440630401432E-6,1,0.999253354069792,40.0298881530762,1.99962669253353,19.1399995237589,-0.00163231259255069,-0.000124504661040695,0.25,1.35737933493144E-5,-0.000141823942926044,1.34804451676586E-5,300.0090332,300.0090332,60338.1328125,60357.86328125,56.4914195988906,20.5687726542473,23.288654,0,0,0,40,4449,300.1721,60347.998046875,,,,,,,,,,,,,0,,,,0.0049,,,,,,300.0090332,,,,
,33028044.195,300.011322,62679.853515625,-0.000151785995237229,1.72713910477973E-6,1,0.999253354069792,40.0298881530762,1.9998570219963,19.1399995237589,-0.00174778531932718,-0.000130007058183711,0.25,1.48157751827897E-5,-0.000151791222777483,1.47159082188399E-5,300.011322,300.011322,62672.3125,62687.39453125,56.6751023009098,20.5692001042335,23.668306,0,0,0,40,4449,300.1558,62679.853515625,,,,,,,,,,,,,0,,,,0.0049,,,,,,300.011322,,,,
,33028090.885,300.0086365,65013.841796875,-0.000159164965581584,1.61962814144416E-6,1,0.999253354069792,40.0298881530762,1.99979027642181,19.1399995237589,-0.00183311158066531,-0.000133915471963261,0.25,1.57485887341036E-5,-0.000159170601229051,1.56439246868024E-5,300.0086365,300.0086365,65011.16015625,65016.5234375,56.6625962446021,20.5711325278847,22.909004,0,0,0,40,4449,300.1602,65013.841796875,,,,,,,,,,,,,0,,,,0,,,,,,300.0086365,,,,
,33028136.015,300.0014038,67267.83984375,-0.000165847041875495,1.47329533513404E-6,1,0.999253354069792,40.0298881530762,1.99982040801814,19.1399995237589,-0.00190695032475511,-0.000157704251815694,0.25,1.48054720294145E-5,-0.000165851906908488,1.46965276680134E-5,300.0014038,300.0014038,67265.71875,67269.9609375,56.6571248449675,20.5712846024534,23.288654,0,0,0,40,4449,300.1631,67267.83984375,,,,,,,,,,,,,0,,,,0,,,,,,300.0014038,,,,
,33028182.07,300.0074463,69571.38671875,-0.000179646340717978,1.90845962194495E-6,1,0.999253354069792,40.0298881530762,1.99982076250827,19.1399995237589,-0.00206773945427767,-0.000158580863711234,0.25,1.71187236545033E-5,-0.000179652278659768,1.70007464458228E-5,300.0074463,300.0074463,69568.5546875,69574.21875,56.6172617904868,20.5695425222639,23.288654,0,0,0,40,4449,300.15975,69571.38671875,,,,,,,,,,,,,0,,,,-0.0049,,,,,,300.0074463,,,,
,33028228.045,300.0065002,71867.89453125,-0.000187249623937798,1.8035953922209E-6,1,0.999253354069792,40.0298881530762,1.99982580337332,19.1399995237589,-0.00215303889320658,-0.000178107011017067,0.25,1.67115135363499E-5,-0.000187255079451992,1.65886466117507E-5,300.0065002,300.0065002,71863.0234375,71872.765625,56.6641595016406,20.5722991050626,23.668306,0,0,0,40,4449,300.1561,71867.89453125,,,,,,,,,,,,,0,,,,0,,,,,,300.0065002,,,,
,33028274.52,300.0080566,74191.76953125,-0.000195653067543844,3.06180354470086E-6,1,0.999253354069792,40.0298881530762,1.99978242231744,19.1399995237589,-0.00224636467553877,-0.000204868265900582,0.25,1.58035490122997E-5,-0.000195657673966229,1.56752891069772E-5,300.0080566,300.0080566,74181.8359375,74201.703125,56.6711941583137,20.5687928498737,22.909004,0,0,0,40,4449,300.15115,74191.76953125,,,,,,,,,,,,,0,,,,0,,,,,,300.0080566,,,,
,33028320.91,300.016922,76511.2421875,-0.000205562374517848,2.97969029485559E-6,1,0.999253354069792,40.0298881530762,1.99982100429527,19.1399995237589,-0.00236441078963846,-0.000190826599246266,0.25,1.87606668264747E-5,-0.000205568557310082,1.86259219231029E-5,300.0166931,300.0171509,76506.40625,76516.078125,56.4703156288714,20.5692499092135,22.909004,0,0,0,40,4449,300.1507,76511.2421875,,,,,,,,,,,,,0,,,,-0.00245,,,,,,300.016922,,,,
,33028365.875,300.0107117,78757.6796875,-0.000213198454867007,2.90606554320713E-6,1,0.999253354069792,40.0298881530762,1.99980571572171,19.1399995237589,-0.00244811713859325,-0.000221623752852525,0.25,1.73635509862063E-5,-0.000213203548451236,1.72239409952704E-5,300.0107117,300.0107117,78750.1640625,78765.1953125,56.5711457078521,20.5696477568677,23.668306,0,0,0,40,4449,300.1393,78757.6796875,,,,,,,,,,,,,0,,,,-0.00245,,,,,,300.0107117,,,,
,33028410.64,300.013916,80997.48046875,-0.000220380267088037,2.97647019627782E-6,1,0.999253354069792,40.0298881530762,1.99980878166173,19.1399995237589,-0.00253208099058555,-0.000220471674480495,0.25,1.87094772255533E-5,-0.000220386003733891,1.8565226195962E-5,300.013916,300.013916,80984.796875,81010.1640625,56.6328943608714,20.5683069918956,22.909004,0,0,0,40,4449,300.14375,80997.48046875,,,,,,,,,,,,,0,,,,0,,,,,,300.013916,,,,
,33028455.125,300.0162354,83218.6015625,-0.000231991794432903,1.7677519215504E-6,1,0.999253354069792,40.0298881530762,1.99987680516101,19.1399995237589,-0.00266508741933904,-0.000234933464078276,0.25,1.94445524443849E-5,-0.000231997650890079,1.9292782821083E-5,300.0162354,300.0162354,83213.640625,83223.5625,56.6274229612368,20.5706909715617,22.909004,0,0,0,40,4449,300.12375,83218.6015625,,,,,,,,,,,,,0,,,,0.0049,,,,,,300.0162354,,,,
,33028500.45,300.0106812,85485.51953125,-0.000239131567125987,1.79543635149103E-6,1,0.999253354069792,40.0298881530762,1.99984887131562,19.1399995237589,-0.00274629189766944,-0.000246663464635534,0.25,1.96452200570428E-5,-0.000239137392883123,1.94888872975743E-5,300.0106812,300.0106812,85478.046875,85492.9921875,56.679010443506,20.5705608619342,23.668306,0,0,0,40,4449,300.1227,85485.51953125,,,,,,,,,,,,,0,,,,-0.0049,,,,,,300.0106812,,,,
,33028543.395,300.0109253,87631.875,-0.000248244053428366,2.72304622217419E-6,1,0.999253354069792,40.0298881530762,1.99989052672381,19.1399995237589,-0.00284809239996617,-0.000272852945255327,0.25,1.89114393468561E-5,-0.00024824913450803,1.87492797582272E-5,300.0109253,300.0109253,87621.9453125,87641.8046875,56.5555131374675,20.5698138667895,23.668306,0,0,0,40,4449,300.1162,87631.875,,,,,,,,,,,,,0,,,,0.00245,,,,,,300.0109253,,,,
,33028587.295,300.0113831,89826.31640625,-0.000257007616389556,2.69152650111499E-6,1,0.999253354069792,40.0298881530762,1.99983397631474,19.1399995237589,-0.00294448750495693,-0.000305965763582254,0.25,1.7504623311307E-5,-0.000257011524053414,1.73368937804056E-5,300.0113831,300.0113831,89816.2890625,89836.34375,56.648526931256,20.5726799906537,22.909004,0,0,0,40,4449,300.1121,89826.31640625,,,,,,,,,,,,,0,,,,0,,,,,,300.0113831,,,,
,33028648.405,300.0088501,88103.06640625,-0.000253142173222727,2.81178774900614E-6,1,0.999253354069792,40.0298881530762,1.99993774987487,19.1399995237589,-0.00290569653932249,-0.000270493402235636,0.25,1.99689099777062E-5,-0.000253147819224361,1.98035632014917E-5,300.0088501,300.0088501,88092.84375,88113.2890625,56.5938129349098,20.573603277939,23.288654,0,0,0,40,4449,300.1323,88103.06640625,,,,,,,,,,,,,0,,,,-0.00245,,,,,,300.0088501,,,,
,33028692.91,300.0105133,85876.28515625,-0.000247304879364236,3.00405365831923E-6,1,0.999253354069792,40.0298881530762,1.99985150386194,19.1399995237589,-0.00283512898474237,-0.00028414200602353,0.25,1.77513834334895E-5,-0.000247309234948287,1.75897905992163E-5,300.0101013,300.0109253,85874.0078125,85878.5625,56.4836033136983,20.5715977587402,23.288654,0,0,0,40,4449,300.1096,85876.28515625,,,,,,,,,,,,,0,,,,0,,,,,,300.0105133,,,,
,33028736.055,300.0018311,83719.3046875,-0.000232487173627539,2.85174977104332E-6,1,0.999253354069792,40.0298881530762,1.99979678895357,19.1399995237589,-0.00266822668586881,-0.00024957356191821,0.25,1.82366267525623E-5,-0.000232492348733742,1.80845945826072E-5,300.0018311,300.0018311,83714.375,83724.234375,56.5781803645252,20.5699772092933,23.288654,0,0,0,40,4449,300.11625,83719.3046875,,,,,,,,,,,,,0,,,,0,,,,,,300.0018311,,,,
,33028781.955,299.9971924,81425.25390625,-0.000225155589699707,1.73758658409295E-6,1,0.999253354069792,40.0298881530762,1.9998278157654,19.1399995237589,-0.00258607581100749,-0.000230427388110702,0.25,1.86577485348531E-5,-0.000225161287836311,1.85103962635005E-5,299.9971924,299.9971924,81420.2578125,81430.25,56.6125720193714,20.5711794141164,23.288654,0,0,0,40,4449,300.115,81425.25390625,,,,,,,,,,,,,0,,,,-0.0049,,,,,,299.9971924,,,,
,33028828.195,299.9952393,79115.3203125,-0.000213412105432214,2.70483420521304E-6,1,0.999253354069792,40.0298881530762,1.99978358207696,19.1399995237589,-0.00245110921214389,-0.000218592325689769,0.25,1.76680903661417E-5,-0.000213417510111081,1.75283459474305E-5,299.9952393,299.9952393,79105.2109375,79125.4296875,56.5656743082175,20.5728570992862,22.909004,0,0,0,40,4449,300.1231,79115.3203125,,,,,,,,,,,,,0,,,,0,,,,,,299.9952393,,,,
,33028873.22,299.9900208,76861.27734375,-0.000209215627050373,2.40931662658007E-6,1,0.999253354069792,40.0298881530762,1.99986517840126,19.1399995237589,-0.00240272696068744,-0.000215908728211166,0.25,1.71788838855388E-5,-0.000209220871670912,1.7041818128831E-5,299.9900208,299.9900208,76856.2109375,76866.34375,56.7571732954291,20.5724374925845,23.288654,0,0,0,40,4449,300.12915,76861.27734375,,,,,,,,,,,,,0,,,,0,,,,,,299.9900208,,,,
,33028919.65,299.9858093,74541.6640625,-0.000198458850302023,2.3503327711917E-6,1,0.999253354069792,40.0298881530762,1.99972864974208,19.1399995237589,-0.00227334439472454,-0.000237687755966438,0.25,1.33906226625316E-5,-0.000198461957330208,1.32606141898551E-5,299.9858093,299.9858093,74531.671875,74551.65625,56.7556100383906,20.5733584614435,23.288654,0,0,0,40,4449,300.13415,74541.6640625,,,,,,,,,,,,,0,,,,0.00245,,,,,,299.9858093,,,,
,33028965.02,299.9909973,72275.29296875,-0.000189795944665781,2.11916303818949E-6,1,0.999253354069792,40.0298881530762,1.99978615947906,19.1399995237589,-0.00217913036980517,-0.000198688097424189,0.25,1.53347235599311E-5,-0.000189800531777726,1.52102470967756E-5,299.9909973,299.9909973,72268.015625,72282.5703125,56.7376325824483,20.573821672794,23.668306,0,0,0,40,4449,300.1418,72275.29296875,,,,,,,,,,,,,0,,,,0,,,,,,299.9909973,,,,
,33029010.07,299.9881592,70023.66015625,-0.000182574141386249,1.84926045444027E-6,1,0.999253354069792,40.0298881530762,1.99984083184716,19.1399995237589,-0.00209638144261371,-0.000190481485502256,0.25,1.48088370435798E-5,-0.000182578609668615,1.46890249667815E-5,299.9881592,299.9881592,70018.4140625,70028.90625,56.7337244398522,20.5756523885266,23.288654,0,0,0,40,4449,300.13455,70023.66015625,,,,,,,,,,,,,0,,,,0,,,,,,299.9881592,,,,
,33029054.49,299.9868164,67801.98828125,-0.000173663753565199,2.21582978795507E-6,1,0.999253354069792,40.0298881530762,1.99980582552088,19.1399995237589,-0.00199582061345264,-0.000170881252833229,0.25,1.49958925944596E-5,-0.000173668606935854,1.48818432625708E-5,299.9868164,299.9868164,67789.6953125,67814.28125,56.668849272756,20.5744674865765,23.668306,0,0,0,40,4449,300.14495,67801.98828125,,,,,,,,,,,,,0,,,,-0.00245,,,,,,299.9868164,,,,
,33029100.485,299.9916382,65499.9921875,-0.000156678612057492,2.34023959460169E-6,1,0.999253354069792,40.0298881530762,1.99975327861248,19.1399995237589,-0.0017886511213582,-0.000222985202787607,0.25,7.45118399429019E-6,-0.000156678984571045,7.34840276140639E-6,299.9916382,299.9916382,65489.90234375,65510.08203125,56.770460980256,20.5748885138841,23.668306,0,0,0,40,4449,300.14625,65499.9921875,,,,,,,,,,,,,0,,,,0.0049,,,,,,299.9916382,,,,
,33029146.01,299.9891052,63228.65625,-0.000155771872197827,2.15464434242935E-6,1,0.999253354069792,40.0298881530762,1.99978114342218,19.1399995237589,-0.0017880856699388,-0.000165350905723147,0.25,1.23844692770147E-5,-0.000155775513929547,1.22820854925923E-5,299.9891052,299.9891052,63226.2265625,63231.0859375,56.7517018957945,20.575644978744,23.288654,0,0,0,40,4449,300.1526,63228.65625,,,,,,,,,,,,,0,,,,0.0049,,,,,,299.9891052,,,,
,33029190.835,299.9891663,60986.494140625,-0.000149212066518772,1.89376377442888E-6,1,0.999253354069792,40.0298881530762,1.9997126780686,19.1399995237589,-0.00171921344800427,-0.000120963422922567,0.25,1.51678250140652E-5,-0.000149217719868013,1.50696060033383E-5,299.9891663,299.9891663,60981.546875,60991.44140625,56.6641595016406,20.5772515019569,23.288654,0,0,0,40,4449,300.1595,60986.494140625,,,,,,,,,,,,,0,,,,-0.00245,,,,,,299.9891663,,,,
,33029235.95,299.9892883,58732.732421875,-0.000138877760523395,1.82600610197607E-6,1,0.999253354069792,40.0298881530762,1.99970605525827,19.1399995237589,-0.00160262949625857,-9.81991150165441E-5,0.25,1.5387941283525E-5,-0.000138883855459981,1.52964389816113E-5,299.9892883,299.9892883,58728.01953125,58737.4453125,56.6657227586791,20.576512805788,23.288654,0,0,0,40,4449,300.1636,58732.732421875,,,,,,,,,,,,,0,,,,0,,,,,,299.9892883,,,,
,33029283.68,299.98388675,56346.349609375,-0.000127764784195857,1.62753436035298E-6,1,0.999253354069792,40.0298881530762,1.99972318824387,19.1399995237589,-0.00147351820611487,-9.54298573940096E-5,0.25,1.37072928355055E-5,-0.000127770122449631,1.36230812491384E-5,299.9836121,299.9841614,56338.42578125,56354.2734375,56.8697278021983,20.5747105035995,23.288654,0,0,0,40,4449,300.1704,56346.349609375,,,,,,,,,,,,,0,,,,0,,,,,,299.98388675,,,,
,33029331.965,299.98789975,53932.4140625,-0.000119554430521184,1.19739733685309E-6,1,0.999253354069792,40.0298881530762,1.99970402582756,19.1399995237589,-0.00138102843189793,-7.65205608627663E-5,0.25,1.39548602959443E-5,-0.000119560149994605,1.38759817938414E-5,299.9877319,299.9880676,53930.0234375,53934.8046875,56.6399290175445,20.57599832801,22.909004,0,0,0,40,4449,300.17675,53932.4140625,,,,,,,,,,,,,0,,,,0.0049,,,,,,299.98789975,,,,
,33029379.79,299.986969,51543.3828125,-0.000110806485776926,1.62609379897833E-6,1,0.999253354069792,40.0298881530762,1.999721088243,19.1399995237589,-0.00127851535905276,-7.94182836679835E-5,0.25,1.21834282107982E-5,-0.000110811298800721,1.21103006661065E-5,299.986969,299.986969,51536.14453125,51550.62109375,56.6813553290637,20.5764550861419,23.668306,0,0,0,40,4449,300.17435,51543.3828125,,,,,,,,,,,,,0,,,,0,,,,,,299.986969,,,,
,33029426.32,299.98349,49215.025390625,-9.91244181822397E-5,1.39140031135496E-6,1,0.999253354069792,40.0298881530762,1.99969253991238,19.1399995237589,-0.00114475035820838,-6.50341683470236E-5,0.25,1.14298192478384E-5,-9.91290856635504E-5,1.13643553762642E-5,299.98349,299.98349,49207.93359375,49222.1171875,56.7649895806214,20.5774152206589,23.668306,0,0,0,40,4449,300.1907,49215.025390625,,,,,,,,,,,,,0,,,,-0.0049,,,,,,299.98349,,,,
,33029471.855,299.9839172,46937.943359375,-9.39678717811565E-5,1.4123098439915E-6,1,0.999253354069792,40.0298881530762,1.99959659546709,19.1399995237589,-0.00108714577890201,-5.01268938180918E-5,0.25,1.18528769058813E-5,-9.39729650122487E-5,1.17907537804833E-5,299.9839172,299.9839172,46933.0859375,46942.80078125,56.7939098358329,20.578401721616,22.909004,0,0,0,40,4449,300.18275,46937.943359375,,,,,,,,,,,,,0,,,,0.0049,,,,,,299.9839172,,,,
,33029516.625,299.990448,44701.953125,-8.47407720948155E-5,9.97663447227388E-7,1,0.999253354069792,40.0298881530762,1.99960502407782,19.1399995237589,-0.000982681071294847,-3.2027878255637E-5,0.25,1.18528669705675E-5,-8.47461118816463E-5,1.17967810538998E-5,299.990448,299.990448,44699.52734375,44704.37890625,56.9283499411406,20.5790061031653,23.288654,0,0,0,40,4449,300.1949,44701.953125,,,,,,,,,,,,,0,,,,0,,,,,,299.990448,,,,
,33029561.945,299.9871826,42437.529296875,-7.77566798220064E-5,1.11332389447744E-6,1,0.999253354069792,40.0298881530762,1.99968171122544,19.1399995237589,-0.000901982978825719,-2.78969820314028E-5,0.25,1.10078190103877E-5,-7.77616767796582E-5,1.09563254206044E-5,299.9871826,299.9871826,42435.171875,42439.88671875,56.9088092281599,20.5807770043435,23.668306,0,0,0,40,4449,300.1924,42437.529296875,,,,,,,,,,,,,0,,,,0,,,,,,299.9871826,,,,
,33029606.975,299.9865112,40186.287109375,-6.93949469962844E-5,1.34736158159671E-6,1,0.999253354069792,40.0298881530762,1.99965503897226,19.1399995237589,-0.000806263045445497,-1.74685067452936E-5,0.25,1.04801632411172E-5,-6.93998413654069E-5,1.04341671841599E-5,299.9865112,299.9865112,40176.3203125,40196.25390625,56.9158438848329,20.5819870551335,23.668306,0,0,0,40,4449,300.20665,40186.287109375,,,,,,,,,,,,,0,,,,0.00245,,,,,,299.9865112,,,,
,33029652.585,299.9884644,37907.43359375,-6.01829884428721E-5,1.30945819942555E-6,1,0.999253354069792,40.0298881530762,1.99969602826,19.1399995237589,-0.000703324875209127,8.3820892148285E-6,0.25,1.11673261740353E-5,-6.01885992886039E-5,1.11273548734868E-5,299.9884644,299.9884644,37897.44921875,37917.41796875,56.7649895806214,20.577963264452,23.288654,0,0,0,40,4449,300.2101,37907.43359375,,,,,,,,,,,,,0,,,,0,,,,,,299.9884644,,,,
,33029698.485,299.9885864,35610.99609375,-5.29605615613316E-5,1.46030029383045E-6,1,0.999253354069792,40.0298881530762,1.99974642372393,19.1399995237589,-0.000615468975648255,-1.26307566847102E-5,0.25,8.06018913502091E-6,-5.29643358871843E-5,8.02504810241711E-6,299.9885864,299.9885864,35603.65234375,35618.33984375,57.088583787583,20.5784372240149,22.909004,0,0,0,40,4449,300.2124,35610.99609375,,,,,,,,,,,,,0,,,,-0.00245,,,,,,299.9885864,,,,
,33029743.885,299.987915,33342.513671875,-4.43416272539766E-5,9.04243508277041E-7,1,0.999253354069792,40.0298881530762,1.9997930559148,19.1399995237589,-0.000517644457203531,2.85529897312516E-6,0.25,7.93461808137567E-6,-4.43455714761116E-5,7.90514745579032E-6,299.987915,299.987915,33339.96484375,33345.0625,56.7868751791599,20.5791778346259,23.668306,0,0,0,40,4449,300.2175,33342.513671875,,,,,,,,,,,,,0,,,,0.0049,,,,,,299.987915,,,,
,33029787.015,299.9891968,31188.3837890625,-3.45859755676682E-5,1.05330398360904E-6,1,0.999253354069792,40.0298881530762,1.99973648096368,19.1399995237589,-0.000405057669054058,9.79769279295208E-6,0.25,6.85755362892539E-6,-3.45894925244474E-5,6.83453607772504E-6,299.9891968,299.9891968,31186.00390625,31190.763671875,56.7673344661791,20.5798065109256,23.288654,0,0,0,40,4449,300.21575,31188.3837890625,,,,,,,,,,,,,0,,,,0,,,,,,299.9891968,,,,
,33029832.655,299.9876709,28904.6923828125,-2.79216555953661E-5,6.79516568106864E-7,1,0.999253354069792,40.0298881530762,1.99968747207601,19.1399995237589,-0.000332070650746417,3.71757874569592E-5,0.25,8.12099667148695E-6,-2.79262034120885E-5,8.10233086216409E-6,299.9876709,299.9876709,28897.29296875,28912.091796875,56.8251749766022,20.5797299378392,23.288654,0,0,0,40,4449,300.2243,28904.6923828125,,,,,,,,,,,,,0,,,,0,,,,,,299.9876709,,,,
,33029877.195,299.987793,26680.3251953125,-1.90744353877732E-5,7.40469902559951E-7,1,0.999253354069792,40.0298881530762,1.99973672639783,19.1399995237589,-0.000227690754955014,3.02119768536626E-5,0.25,5.97305347157738E-6,-1.90778240789787E-5,5.96028379946008E-6,299.987793,299.987793,26672.71875,26687.931640625,56.8017261210252,20.580369369028,23.288654,0,0,0,40,4449,300.22835,26680.3251953125,,,,,,,,,,,,,0,,,,0,,,,,,299.987793,,,,
,33029921.78,299.9878235,24451.48828125,-1.27854814329482E-5,9.32465444380517E-7,1,0.999253354069792,40.0298881530762,1.99979806024223,19.1399995237589,-0.000156228843657024,4.10564041856312E-5,0.25,5.84111080262373E-6,-1.27889675573002E-5,5.83249388221815E-6,299.9873047,299.9883423,24449.154296875,24453.822265625,56.9697762526599,20.5788503839598,23.288654,0,0,0,40,4449,300.2318,24451.48828125,,,,,,,,,,,,,0,,,,0.0049,,,,,,299.9878235,,,,
,33029965.48,299.9865723,22267.755859375,-5.15618638649043E-6,5.75823153502359E-7,1,0.999253354069792,40.0298881530762,1.99969229194002,19.1399995237589,-6.92745635239962E-5,5.27631862280158E-5,0.25,5.55341286913196E-6,-5.15970648015267E-6,5.54984329313688E-6,299.9865723,299.9865723,22255.38671875,22280.125,56.8165770628906,20.5806321574199,23.288654,0,0,0,40,4449,300.24165,22267.755859375,,,,,,,,,,,,,0,,,,-0.0049,,,,,,299.9865723,,,,
,33030011.26,299.9870911,19981.46875,3.69769946136495E-6,6.94228117881409E-7,1,0.999253354069792,40.0298881530762,1.99978605992902,19.1399995237589,3.27409496521524E-5,5.99374596018151E-5,0.25,4.65280840273496E-6,3.69451508411722E-6,4.655117589917E-6,299.9870911,299.9870911,19976.3984375,19986.5390625,56.8236117195637,20.5806941649657,23.288654,0,0,0,40,4449,300.24365,19981.46875,,,,,,,,,,,,,0,,,,0.00245,,,,,,299.9870911,,,,
,33030055.775,299.9894409,17754.90234375,9.91626669458266E-6,1.15647906238217E-6,1,0.999253354069792,40.0298881530762,1.9997351682256,19.1399995237589,0.000103160339200185,7.20798538370621E-5,0.25,4.64791932808173E-6,9.91290172750243E-6,4.65434266616904E-6,299.9894409,299.9894409,17752.32421875,17757.48046875,56.9150622563137,20.5824657271229,23.668306,0,0,0,40,4449,300.2484,17754.90234375,,,,,,,,,,,,,0,,,,-0.0049,,,,,,299.9894409,,,,
,33030100.16,299.9898376,15536.5834960938,1.8223926292674E-5,1.02818328276755E-6,1,0.999253354069792,40.0298881530762,1.99969406419369,19.1399995237589,0.000199789535193698,7.35513102695166E-5,0.25,3.33863038207479E-6,1.82211824605012E-5,3.35059231998723E-6,299.9898376,299.9898376,15529.3291015625,15543.837890625,56.7634263235829,20.5824482806506,23.668306,0,0,0,40,4449,300.25125,15536.5834960938,,,,,,,,,,,,,0,,,,-0.0049,,,,,,299.9898376,,,,
,33030144.89,299.9935608,13300.0458984375,2.44045011006612E-5,5.45281694912703E-7,1,0.999253354069792,40.0298881530762,1.99974399073983,19.1399995237589,0.000269793231067225,8.55723875920346E-5,0.25,3.3293145451E-6,2.44015773535337E-5,3.3453731470973E-6,299.9935608,299.9935608,13295.037109375,13305.0546875,56.9424192544868,20.5800394804869,23.288654,0,0,0,40,4449,300.2489,13300.0458984375,,,,,,,,,,,,,0,,,,0.0049,,,,,,299.9935608,,,,
,33030187.88,299.9949646,11153.5883789062,3.11364256637495E-5,5.61165457771833E-7,1,0.999253354069792,40.0298881530762,1.99974922704759,19.1399995237589,0.000346712847576179,9.47658536561938E-5,0.25,2.97487362544578E-6,3.11335350505146E-5,2.99540707817515E-6,299.9949646,299.9949646,11151.185546875,11155.9912109375,56.9205336559483,20.5803224454356,23.668306,0,0,0,40,4449,300.25085,11153.5883789062,,,,,,,,,,,,,0,,,,0,,,,,,299.9949646,,,,
,33030233.28,299.9900208,8881.9736328125,3.67712642899823E-5,6.07765716428131E-7,1,0.999253354069792,40.0298881530762,1.99972583701834,19.1399995237589,0.000412039333910058,9.69919466101224E-5,0.25,2.19527664765956E-6,3.67687284934288E-5,2.2195752127222E-6,299.9900208,299.9900208,8871.98828125,8891.958984375,56.9900985941599,20.5830750868289,23.288654,0,0,0,40,4449,300.2483,8881.9736328125,,,,,,,,,,,,,0,,,,0.0049,,,,,,299.9900208,,,,
,33030276.83,299.988739,6707.89453125,4.16647977578047E-5,5.50629525212783E-7,1,0.999253354069792,40.0298881530762,1.9996243896816,19.1399995237589,0.000468452721733095,0.000100650205349754,0.25,1.67094236517805E-6,4.16624662239224E-5,1.69850754970368E-6,299.988739,299.988739,6703.2431640625,6712.5458984375,56.8744175733137,20.5826798746814,23.288654,0,0,0,40,4449,300.2573,6707.89453125,,,,,,,,,,,,,0,,,,0.0049,,,,,,299.988739,,,,
,33030321.33,299.9866943,4484.04614257812,4.39294238936538E-5,5.43675140335046E-7,1,0.999253354069792,40.0298881530762,1.99961490748768,19.1399995237589,0.000496339474110604,9.21129129424641E-5,0.25,5.24561229173174E-7,4.39277880301212E-5,5.53669026945861E-7,299.9866943,299.9866943,4474.0615234375,4494.03076171875,56.8611298884868,20.5812567713466,23.668306,0,0,0,40,4449,300.27475,4484.04614257812,,,,,,,,,,,,,0,,,,0,,,,,,299.9866943,,,,
,33030365.235,299.981781,2286.94653320313,4.24693706013331E-5,4.24535724834216E-7,1,0.999253354069792,40.0298881530762,1.99956754147619,19.1399995237589,0.000481199878337001,8.11555833636684E-5,0.25,-1.9011064235473E-7,4.24682580655129E-5,-1.61940817701648E-7,299.981781,299.981781,2279.39453125,2294.49853515625,56.902556200006,20.5843953444358,23.668306,0,0,0,40,4449,300.2708,2286.94653320313,,,,,,,,,,,,,0,,,,0.00245,,,,,,299.981781,,,,
,33030407.055,299.98687745,197.380638122559,2.3581917718996E-5,4.75723086113271E-7,1,0.999253354069792,40.0298881530762,1.99979734099323,19.1399995237589,0.000267615062015498,4.28141539163523E-5,0.25,-3.04624674470934E-7,2.35814274476909E-5,-2.8897428099573E-7,299.9868469,299.986908,189.927337646484,204.833938598633,56.8470605751406,20.5802626987646,23.288654,0,0,0,40,4449,300.28595,197.380638122559,,,,,,,,,,,,,0,,,,-0.0049,,,,,,299.98687745,,,,
,33030451.155,299.9920349,-2002.53045654297,-4.06776370754338E-5,4.120223412338E-7,1,0.999253354069792,40.0298881530762,1.99968226314244,19.1399995237589,-0.000459007770437082,-8.87939424342857E-5,0.25,-7.94560788795225E-7,-4.06759087278818E-5,-8.21514126720463E-7,299.9918518,299.992218,-2010.03039550781,-1995.03051757813,56.8275198621599,20.5821793911624,23.668306,0,0,0,40,4449,300.2729,-2002.53045654297,,,,,,,,,,,,,0,,,,0.00245,,,,,,299.9920349,,,,
,33030494.19,299.993927,-4154.05981445313,-4.34666830891671E-5,4.55206057754975E-7,1,0.999253354069792,40.0298881530762,1.99966874351213,19.1399995237589,-0.000488437479272798,-0.000106648703338746,0.25,-1.88834960718692E-6,-4.34641452184318E-5,-1.91711129098934E-6,299.993927,299.993927,-4163.9033203125,-4144.21630859375,57.0495023616214,20.5813032657845,23.288654,0,0,0,40,4449,300.27685,-4154.05981445313,,,,,,,,,,,,,0,,,,0,,,,,,299.993927,,,,
,33030538.78,299.9989319,-6383.75830078125,-4.17234445611263E-5,4.87266118765456E-7,1,0.999253354069792,40.0298881530762,1.99972075974818,19.1399995237589,-0.000469156371865235,-0.000100664539290142,0.25,-1.66164227669661E-6,-4.17211022724694E-5,-1.68924536309051E-6,299.9989319,299.9989319,-6393.693359375,-6373.8232421875,56.8525319747752,20.5818618764356,23.668306,0,0,0,40,4449,300.2761,-6383.75830078125,,,,,,,,,,,,,0,,,,0,,,,,,299.9989319,,,,
,33030583.76,299.9984741,-8630.24365234375,-3.72807165612992E-5,5.54768422172187E-7,1,0.999253354069792,40.0298881530762,1.99977951304509,19.1399995237589,-0.000417292423776512,-0.000101028637630036,0.25,-2.46330187865077E-6,-3.72779771552785E-5,-2.48792760268546E-6,299.9984741,299.9984741,-8637.94140625,-8622.5458984375,56.9541436822753,20.5813994058892,23.668306,0,0,0,40,4449,300.2771,-8630.24365234375,,,,,,,,,,,,,0,,,,0,,,,,,299.9984741,,,,
,33030628.39,300.001709,-10865.1186523438,-3.18983155068384E-5,6.7704231982457E-7,1,0.999253354069792,40.0298881530762,1.99973754106099,19.1399995237589,-0.000354957190013605,-9.84546464298346E-5,0.25,-3.16870784314716E-6,-3.18952664298732E-5,-3.18973855014952E-6,300.001709,300.001709,-10873.0166015625,-10857.220703125,57.0565370182945,20.5807327401268,23.288654,0,0,0,40,4449,300.2739,-10865.1186523438,,,,,,,,,,,,,0,,,,-0.0049,,,,,,300.001709,,,,
,33030673.86,299.9950867,-13136.01953125,-2.53423437052012E-5,9.52514823146879E-7,1,0.999253354069792,40.0298881530762,1.99985848976696,19.1399995237589,-0.00028052356298748,-8.68621706807267E-5,0.25,-3.28031947594269E-6,-2.53394237055243E-5,-3.29699863938143E-6,299.9950867,299.9950867,-13140.6455078125,-13131.3935546875,57.0260535060445,20.5822370484679,24.047956,0,0,0,40,4449,300.2809,-13136.01953125,,,,,,,,,,,,,0,,,,0,,,,,,299.9950867,,,,
,33030717.78,300.0016174,-15330.2060546875,-1.8005035719251E-5,9.20252457859511E-7,1,0.999253354069792,40.0298881530762,1.99992122896323,19.1399995237589,-0.000195481024874329,-8.38158558067306E-5,0.25,-4.28232455115082E-6,-1.80016663936586E-5,-4.29411153625758E-6,300.0012817,300.0019531,-15335.31640625,-15325.095703125,57.0330881627176,20.5856534534241,24.047956,0,0,0,40,4449,300.27435,-15330.2060546875,,,,,,,,,,,,,0,,,,0.00245,,,,,,300.0016174,,,,
,33030762.835,300.0031433,-17583.6611328125,-1.06581884479661E-5,1.23328341473599E-6,1,0.999253354069792,40.0298881530762,1.99994458849438,19.1399995237589,-0.000112098418435768,-7.05039869895041E-5,0.25,-4.37957840163518E-6,-1.06549742720901E-5,-4.38649770641114E-6,300.0031433,300.0031433,-17588.857421875,-17578.46484375,56.7845302936022,20.582578478968,23.668306,0,0,0,40,4449,300.2757,-17583.6611328125,,,,,,,,,,,,,0,,,,0.00245,,,,,,300.0031433,,,,
,33030808.48,300.0057983,-19865.142578125,-3.44741334647609E-6,6.03565458473364E-7,1,0.999253354069792,40.0298881530762,1.99996079290426,19.1399995237589,-2.86953846129625E-5,-6.64586887914857E-5,0.25,-5.27161893196786E-6,-3.44382509353541E-6,-5.27374086782422E-6,300.0057983,300.0057983,-19872.6015625,-19857.68359375,56.8329912617945,20.5807060014377,24.047956,0,0,0,40,4449,300.2701,-19865.142578125,,,,,,,,,,,,,0,,,,0.00245,,,,,,300.0057983,,,,
,33030853.59,300.0021057,-22118.525390625,3.31136876168568E-6,1.08336541440804E-6,1,0.999253354069792,40.0298881530762,1.99982533706032,19.1399995237589,4.7095198157844E-5,-4.89134707992651E-5,0.25,-4.89350404094895E-6,3.31450437436325E-6,-4.89117041605334E-6,300.0021057,300.0021057,-22130.91015625,-22106.140625,56.902556200006,20.581679843224,23.668306,0,0,0,40,4449,300.2692,-22118.525390625,,,,,,,,,,,,,0,,,,0.0049,,,,,,300.0021057,,,,
,33030901.225,300.0144043,-24499.7177734375,1.27631716951914E-5,7.96983605622292E-7,1,0.999253354069792,40.0298881530762,1.99984685887814,19.1399995237589,0.000158277112695666,-5.43611818453568E-5,0.25,-7.01216059541464E-6,1.27674193107361E-5,-7.00351898296127E-6,300.0144043,300.0144043,-24504.3671875,-24495.068359375,56.8572217458906,20.5825737795514,23.668306,0,0,0,40,4449,300.2695,-24499.7177734375,,,,,,,,,,,,,0,,,,0,,,,,,300.0144043,,,,
,33030947.02,300.009613,-26789.0849609375,2.07001277445019E-5,9.07253760373442E-7,1,0.999253354069792,40.0298881530762,1.99991968589336,19.1399995237589,0.000248182937933215,-3.89366029989645E-5,0.25,-7.02496279815888E-6,2.07041471311082E-5,-7.01108490529544E-6,300.009613,300.009613,-26793.859375,-26784.310546875,56.9220969129868,20.5867207358645,23.668306,0,0,0,40,4449,300.2484,-26789.0849609375,,,,,,,,,,,,,0,,,,0.0049,,,,,,300.009613,,,,
,33030993.52,300.0062561,-29113.1083984375,2.89169469542296E-5,1.18745406778386E-6,1,0.999253354069792,40.0298881530762,1.99982972990064,19.1399995237589,0.00034320004256033,-3.42863290489877E-5,0.25,-8.03803124392195E-6,2.89213910283425E-5,-8.01870944505628E-6,300.0062561,300.0062561,-29118.44140625,-29107.775390625,57.0463758475445,20.5836956790793,24.047956,0,0,0,40,4449,300.2636,-29113.1083984375,,,,,,,,,,,,,0,,,,0,,,,,,300.0062561,,,,
,33031038.865,300.0054321,-31379.33984375,3.77723744458948E-5,9.61551033521186E-7,1,0.999253354069792,40.0298881530762,1.99984253653897,19.1399995237589,0.000444563619544645,-2.32023084797913E-5,0.25,-8.59338477711159E-6,3.77769210460287E-5,-8.56821485165913E-6,300.0054321,300.0054321,-31387.146484375,-31371.533203125,56.7751507513714,20.5874798227292,24.047956,0,0,0,40,4449,300.25915,-31379.33984375,,,,,,,,,,,,,0,,,,-0.0049,,,,,,300.0054321,,,,
,33031083.645,300.0052795,-33617.8046875,4.55730075252373E-5,1.22848768894119E-6,1,0.999253354069792,40.0298881530762,1.99996432948383,19.1399995237589,0.000534017708135576,-1.42185449095384E-5,0.25,-9.15141117608746E-6,4.55776892145338E-5,-9.12109409002602E-6,300.0052795,300.0052795,-33620.390625,-33615.21875,56.8853603725829,20.5845603976184,23.668306,0,0,0,40,4449,300.257,-33617.8046875,,,,,,,,,,,,,0,,,,-0.0049,,,,,,300.0052795,,,,
,33031129.575,300.006958,-35911.353515625,5.48003831540436E-5,1.44005460602214E-6,1,0.999253354069792,40.0298881530762,1.99992471939959,19.1399995237589,0.000640005773214583,-4.8334365600451E-6,0.25,-9.92130746794197E-6,5.4805293767283E-5,-9.88490198237064E-6,300.006958,300.006958,-35923.77734375,-35898.9296875,56.9791557948906,20.5853951815398,23.288654,0,0,0,40,4449,300.2564,-35911.353515625,,,,,,,,,,,,,0,,,,0.00245,,,,,,300.006958,,,,
,33031175.955,300.0108643,-38230.4765625,6.35558622877318E-5,1.38298251240556E-6,1,0.999253354069792,40.0298881530762,1.99986631683423,19.1399995237589,0.000738500850058447,1.59701372347813E-5,0.25,-9.60100570428347E-6,6.35602917506381E-5,-9.55885885194223E-6,300.0108643,300.0108643,-38232.50390625,-38228.44921875,57.004167907506,20.5862826472481,23.668306,0,0,0,40,4449,300.2438,-38230.4765625,,,,,,,,,,,,,0,,,,0.0049,,,,,,300.0108643,,,,
,33031221.985,300.01474,-40531.6015625,7.00838957967118E-5,1.4008021982082E-6,1,0.999253354069792,40.0298881530762,1.99991162734181,19.1399995237589,0.000817080377427887,1.97967605467705E-6,0.25,-1.19675429983955E-5,7.00896778854978E-5,-1.19210463363386E-5,300.01474,300.01474,-40536.4921875,-40526.7109375,56.9361662263329,20.5877669379884,24.047956,0,0,0,40,4449,300.2309,-40531.6015625,,,,,,,,,,,,,0,,,,0.00245,,,,,,300.01474,,,,
,33031267.865,300.01712035,-42825.15234375,8.09740193694651E-5,1.16800958837006E-6,1,0.999253354069792,40.0298881530762,1.9999359224005,19.1399995237589,0.000939391782529397,2.92018818287282E-5,0.25,-1.14502853093674E-5,8.09791267835175E-5,-1.13966619276487E-5,300.0170593,300.0171814,-42835.3515625,-42814.953125,56.973684395256,20.5876094628894,24.047956,0,0,0,40,4449,300.23,-42825.15234375,,,,,,,,,,,,,0,,,,0,,,,,,300.01712035,,,,
,33031314.725,300.0141144,-45163.986328125,8.80082872437283E-5,1.41705391846028E-6,1,0.999253354069792,40.0298881530762,1.99979732091324,19.1399995237589,0.001016934445237,5.47981393367048E-5,0.25,-1.04082453659935E-5,8.80125068645941E-5,-1.03500548068327E-5,300.0134888,300.01474,-45169.04296875,-45158.9296875,57.0057311645445,20.5880521719069,23.668306,0,0,0,40,4449,300.21835,-45163.986328125,,,,,,,,,,,,,0,,,,0,,,,,,300.0141144,,,,
,33031360.335,300.0093079,-47445.984375,9.73322903500902E-5,1.52573496229472E-6,1,0.999253354069792,40.0298881530762,1.9998728310014,19.1399995237589,0.00112347287889593,6.77687301359049E-5,0.25,-1.08783354119455E-5,9.73365569386712E-5,-1.08140384605363E-5,300.0093079,300.0093079,-47458.28125,-47433.6875,57.0495023616214,20.5897806040754,23.288654,0,0,0,40,4449,300.2319,-47445.984375,,,,,,,,,,,,,0,,,,0,,,,,,300.0093079,,,,
,33031405.88,300.01405335,-49722.189453125,0.000107446524254795,1.7921793834673E-6,1,0.999253354069792,40.0298881530762,1.99985183757622,19.1399995237589,0.00124123248496961,6.88814878618224E-5,0.25,-1.25322941977683E-5,0.00010745155900384,-1.24613350511396E-5,300.0137634,300.0143433,-49727.1484375,-49717.23046875,57.0158923352945,20.5903549794981,23.668306,0,0,0,40,4449,300.2268,-49722.189453125,,,,,,,,,,,,,0,,,,-0.00245,,,,,,300.01405335,,,,
,33031452.215,300.0073242,-52038.017578125,0.000113785095950078,1.31663273330836E-6,1,0.999253354069792,40.0298881530762,1.99976127298831,19.1399995237589,0.0013149749781354,6.96218361295886E-5,0.25,-1.35647874560076E-5,0.000113790646686133,-1.3489675018658E-5,300.0073242,300.0073242,-52045.29296875,-52030.7421875,56.7071490701983,20.5890129588607,23.288654,0,0,0,40,4449,300.2156,-52038.017578125,,,,,,,,,,,,,0,,,,-0.00245,,,,,,300.0073242,,,,
,33031496.305,300.0079346,-54241.57421875,0.000123069567563001,1.56347028923895E-6,1,0.999253354069792,40.0298881530762,1.99996307363459,19.1399995237589,0.00142224639930174,7.62503060179382E-5,0.25,-1.45885465498206E-5,0.000123075512748667,-1.45073493711618E-5,300.0079346,300.0079346,-54249.30078125,-54233.84765625,56.8908317722176,20.5883205253509,24.047956,0,0,0,40,4449,300.2123,-54241.57421875,,,,,,,,,,,,,0,,,,0,,,,,,300.0079346,,,,
,33031542.365,300.0066528,-56545.05078125,0.000130551394231992,1.40035934132463E-6,1,0.999253354069792,40.0298881530762,1.99997411653474,19.1399995237589,0.00150335511469723,0.000111838731346653,0.25,-1.27420189500138E-5,0.000130555912573737,-1.26560169741716E-5,300.0066528,300.0066528,-56552.26171875,-56537.83984375,57.0393411908714,20.5893472068242,23.668306,0,0,0,40,4449,300.21895,-56545.05078125,,,,,,,,,,,,,0,,,,-0.0049,,,,,,300.0066528,,,,
,33031587.885,300.0143433,-58819.37890625,0.000139317404568684,1.70641270798028E-6,1,0.999253354069792,40.0298881530762,1.99996209646996,19.1399995237589,0.00160193472435384,0.000132941031393502,0.25,-1.23971232326094E-5,0.000139321400437365,-1.23054231287837E-5,300.0143433,300.0143433,-58826.9140625,-58811.84375,57.0002597649099,20.5893434098317,24.047956,0,0,0,40,4449,300.20145,-58819.37890625,,,,,,,,,,,,,0,,,,0,,,,,,300.0143433,,,,
,33031634.655,300.0141602,-61155.419921875,0.000150602190294485,1.68665527172643E-6,1,0.999253354069792,40.0298881530762,1.99994433586203,19.1399995237589,0.00173325914723814,0.000134579765471216,0.25,-1.42073623238505E-5,0.000150607038959123,-1.41082669629103E-5,300.0141602,300.0141602,-61170.3828125,-61140.45703125,57.1401712698522,20.5903973616131,24.047956,0,0,0,40,4449,300.19975,-61155.419921875,,,,,,,,,,,,,0,,,,0,,,,,,300.0141602,,,,
,33031681.295,300.0148621,-63487.021484375,0.000156349059493233,1.97490733209252E-6,1,0.999253354069792,40.0298881530762,1.99979390534485,19.1399995237589,0.00179945828421555,0.000138617540749066,0.25,-1.48455052542787E-5,0.00015635415179843,-1.47426825241787E-5,300.0148621,300.0148621,-63494.453125,-63479.58984375,56.8994296859291,20.5895884575471,23.668306,0,0,0,40,4449,300.19435,-63487.021484375,,,,,,,,,,,,,0,,,,0,,,,,,300.0148621,,,,
,33031725.18,300.0149841,-65678.1328125,0.000164539328809691,2.30719551081166E-6,1,0.999253354069792,40.0298881530762,1.99991602369082,19.1399995237589,0.00189023112752623,0.000166673712217724,0.25,-1.37874717201175E-5,0.000164543485341015,-1.36793715779871E-5,300.0149841,300.0149841,-65683.234375,-65673.03125,57.007294421583,20.5905981093708,24.047956,0,0,0,40,4449,300.1838,-65678.1328125,,,,,,,,,,,,,0,,,,0.00245,,,,,,300.0149841,,,,
,33031772.275,300.0126038,-68034.46875,0.000176577439687475,2.13394669592665E-6,1,0.999253354069792,40.0298881530762,2.00004702788832,19.1399995237589,0.00202737003297107,0.00018627959747883,0.25,-1.41426313582208E-5,0.000176581488263423,-1.40267123625171E-5,300.0126038,300.0126038,-68042.1328125,-68026.8046875,56.8775440873906,20.5888087996941,23.668306,0,0,0,40,4449,300.1859,-68034.46875,,,,,,,,,,,,,0,,,,-0.00245,,,,,,300.0126038,,,,
,33031778.87,300.011261,-68364.2421875,0.000178698470390665,2.46856245914163E-6,1,0.999253354069792,40.0298881530762,2.00002445016286,19.1399995237589,0.00205333247010058,0.000179096006142179,0.25,-1.5144272285221E-5,0.000178703120322473,-1.50269457710609E-5,300.011261,300.011261,-68371.9296875,-68356.5546875,56.9525804252368,20.5879610024072,24.047956,0,0,0,40,4449,300.18355,-68364.2421875,,,,,,,,,,,,,0,,,,0,,,,,,300.011261,,,,