File: data/doubleLayers/dl_2-5/ppms/data/DD205_5_HYST_300KREPEAT.DAT
[Header]
; VSM Data File (default extension .dat)
; Copyright (c) 2003-2013, Quantum Design, Inc. All rights reserved.
TITLE,
FILEOPENTIME,33026698.91,01/18/2019,2:07 pm
BYAPP,VSM,2.0,2.0
INFO,PPMS VSM Option Release 1.4.10 Build 1,APPNAME
INFO,Quantum Design Linear Motor Servo Controller,MOTOR_MODULE_NAME
INFO,3101-100 M1,MOTOR_HW_VERSION
INFO,MMC1014,MOTOR_SERIAL_NUMBER
INFO,SRV No X-over 01.03.11,MOTOR_SOFTWARE_VERSION
INFO,Quantum Design VSM Detection Module,VSM_MODULE_NAME
INFO,3101-150 F0,VSM_HW_VERSION
INFO,VSM707,VSM_SERIAL_NUMBER
INFO,VSM No X-over 01.02.05 May 20 2008 13:51:47,VSM_SOFTWARE_VERSION
INFO,704,PREAMP_SERIAL_NUMBER
INFO,822,COIL_SERIAL_NUMBER
INFO,0,MOMENT_UNITS
INFO,DL 2.5,SAMPLE_MATERIAL
INFO,CoFe2O4,SAMPLE_COMMENT
INFO,29.51,SAMPLE_MASS
INFO,,SAMPLE_VOLUME
INFO,,SAMPLE_MOLECULAR_WEIGHT
INFO,,SAMPLE_SIZE
INFO,,SAMPLE_SHAPE
DATATYPE,COMMENT,1
DATATYPE,TIME,2
STARTUPAXIS,X,2
STARTUPAXIS,Y1,5
[Data]
Comment,Time Stamp (sec),Temperature (K),Magnetic Field (Oe),Moment (emu),M. Std. Err. (emu),Transport Action,Averaging Time (sec),Frequency (Hz),Peak Amplitude (mm),Center Position (mm),Coil Signal' (mV),Coil Signal" (mV),Range (mV),M. Quad. Signal (emu),M. Raw' (emu),M. Raw" (emu),Min. Temperature (K),Max. Temperature (K),Min. Field (Oe),Max. Field (Oe),Mass (grams),Motor Lag (deg),Pressure (Torr),VSM Status (code),Motor Status (code),Measure Status (code),Measure Count,PPMS Status (code),System Temp. (K),System Field (Oe),Sample Position (deg),Bridge 1 Resistance (ohms),Bridge 1 Excitation (에),Bridge 2 Resistance (ohms),Bridge 2 Excitation (에),Bridge 3 Resistance (ohms),Bridge 3 Excitation (에),Bridge 4 Resistance (ohms),Bridge 4 Excitation (에),Signal 1 Vin (V),Signal 2 Vin (V),Digital Inputs (code),Drive 1 Iout (mA),Drive 1 Ipower (W),Drive 2 Iout (mA),Drive 2 Ipower (W),Pressure (),Map 20 (),Map 21 (),Map 22 (),Map 23 (),Map 24 (),Map 25 (),Map 26 (),Map 27 (),Map 28 (),Map 29 ()
,33026724.14,300.0033264,0.0761188715696335,,,2,,,,19.1500004321337,,,,,,,300.0033264,300.0033264,0.0761188715696335,0.0761188715696335,,,22.909004,,,,-99999999,4369,300.1953,0.0761188715696335,,,,,,,,,,,,,,,,,,,,,,,300.0033264,,,,
,33026849.555,300.0025635,2974.96875,4.32367169850661E-5,4.45870772565097E-7,1,0.999253354069792,40.0298881530762,2.0005214851415,19.1399995237589,0.000489469254373143,8.63977484132899E-5,0.25,1.36483308879396E-7,4.32353325408705E-5,1.65159480451339E-7,300.0023804,300.0027466,2964.87719726562,2985.06030273438,56.2553677860829,20.5518817622299,22.909004,0,0,0,40,4449,300.1848,2974.96875,,,,,,,,,,,,,0,,,,0,,,,,,300.0025635,,,,
,33026913.1,300.0032043,6146.23291015625,4.2319323630151E-5,7.31303913246752E-7,1,0.999253354069792,40.0298881530762,2.00044502109559,19.1399995237589,0.000479952632592084,7.94456394387258E-5,0.25,-3.18071083911765E-7,4.23182682736968E-5,-2.90003016403801E-7,300.0032043,300.0032043,6138.7958984375,6153.669921875,56.4257628032752,20.557107802965,23.288654,0,0,0,40,4449,300.1851,6146.23291015625,,,,,,,,,,,,,0,,,,0,,,,,,300.0032043,,,,
,33026977.55,300.0006714,9365.05517578125,3.61773545427635E-5,9.40046494766536E-7,1,0.999253354069792,40.0298881530762,2.00037250944748,19.1399995237589,0.000409323142244696,7.34420056504064E-5,0.25,2.1626662632738E-7,3.6176133181618E-5,2.40233938983121E-7,300.0006714,300.0006714,9352.353515625,9377.7568359375,56.4437402592175,20.5626347541958,23.288654,0,0,0,40,4449,300.1836,9365.05517578125,,,,,,,,,,,,,0,,,,0,,,,,,300.0006714,,,,
,33027043.06,300.0010071,12640.5986328125,2.60360441680824E-5,1.0677595003868E-6,1,0.999253354069792,40.0298881530762,2.00033326120267,19.1399995237589,0.000293107066515251,6.13279947673277E-5,0.25,9.03885624228872E-7,2.60346702672446E-5,9.21102148885617E-7,300.0010071,300.0010071,12635.609375,12645.587890625,56.3773018350829,20.5625933209282,22.909004,0,0,0,40,4449,300.18335,12640.5986328125,,,,,,,,,,,,,0,,,,0,,,,,,300.0010071,,,,
,33027110.415,300.0040283,16006.4624023438,1.82473009534043E-5,9.08989997090959E-7,1,0.999253354069792,40.0298881530762,2.00028440036514,19.1399995237589,0.00020427289409794,4.95933096922708E-5,0.25,1.21736825429952E-6,1.82459505577164E-5,1.22940941198373E-6,300.0040283,300.0040283,15994.0751953125,16018.849609375,56.6039741056598,20.5627025852629,23.668306,0,0,0,40,4449,300.1828,16006.4624023438,,,,,,,,,,,,,0,,,,-0.0049,,,,,,300.0040283,,,,
,33027177.195,300.0029602,19344.8388671875,7.42601742893087E-6,1.02655672585737E-6,1,0.999253354069792,40.0298881530762,2.00054476047267,19.1399995237589,8.20787508537566E-5,2.63238116332879E-5,0.25,1.0373688425677E-6,7.42511019683006E-6,1.04224982686671E-6,300.0029602,300.0029602,19337.470703125,19352.20703125,56.8118872917752,20.5630613568162,22.909004,0,0,0,40,4449,300.18675,19344.8388671875,,,,,,,,,,,,,0,,,,0.00245,,,,,,300.0029602,,,,
,33027241.365,300.0000916,22553.46484375,-4.46742432390467E-6,1.07529948754071E-6,1,0.999253354069792,40.0298881530762,2.0002794428912,19.1399995237589,-6.08588202668674E-5,5.04673123795588E-5,0.25,5.2300615466134E-6,-4.47074912056247E-6,5.22695353740361E-6,300.0000916,300.0000916,22546.03125,22560.8984375,56.6594697305252,20.5633156660148,23.288654,0,0,0,40,4449,300.1859,22553.46484375,,,,,,,,,,,,,0,,,,0.00245,,,,,,300.0000916,,,,
,33027306.66,299.9959717,25816.326171875,-1.50864288118274E-5,1.16245827743477E-6,1,0.999253354069792,40.0298881530762,2.000186530068,19.1399995237589,-0.000175599635489285,-2.21708291807424E-6,0.25,2.41806319767313E-6,-1.50875819476986E-5,2.40802642013889E-6,299.9959717,299.9959717,25813.71875,25818.93359375,56.7837486650829,20.5675273193489,23.288654,0,0,0,40,4449,300.1887,25816.326171875,,,,,,,,,,,,,0,,,,0,,,,,,299.9959717,,,,
,33027372.22,299.995636,29092.8720703125,-2.59484083096655E-5,1.28634392942866E-6,1,0.999253354069792,40.0298881530762,2.00013221147117,19.1399995237589,-0.000297280022711519,-3.11750681806569E-5,0.25,1.74291675040292E-6,-2.59487962629489E-5,1.72573677012499E-6,299.995636,299.995636,29082.779296875,29102.96484375,56.404658833256,20.5699804684186,23.668306,0,0,0,40,4449,300.1892,29092.8720703125,,,,,,,,,,,,,0,,,,0,,,,,,299.995636,,,,
,33027436.735,300.0014038,32316.240234375,-3.82238470176309E-5,1.46354278088639E-6,1,0.999253354069792,40.0298881530762,2.00016493087581,19.1399995237589,-0.00044490215273758,-5.63182414874253E-6,0.25,6.12522377458732E-6,-3.82267578887207E-5,6.09982806862295E-6,300.0014038,300.0014038,32311.23046875,32321.25,56.465625857756,20.5683667579792,22.909004,0,0,0,40,4449,300.1857,32316.240234375,,,,,,,,,,,,,0,,,,0,,,,,,300.0014038,,,,
,33027502.33,300.0009766,35594.5859375,-4.82820826650609E-5,1.93913582334244E-6,1,0.999253354069792,40.0298881530762,1.99995790357632,19.1399995237589,-0.000556875341544621,-3.62203298534206E-5,0.25,5.16655657351304E-6,-4.82840642342711E-5,5.1345765940975E-6,300.0009766,300.0009766,35584.6171875,35604.5546875,56.5852150211983,20.5699029390986,23.668306,0,0,0,40,4449,300.1788,35594.5859375,,,,,,,,,,,,,0,,,,0,,,,,,300.0009766,,,,
,33027570.015,300.0064087,38977.76171875,-6.40012083609582E-5,1.5349031534964E-6,1,0.999253354069792,40.0298881530762,1.99994910103478,19.1399995237589,-0.000741061077719819,-3.13437662413402E-5,0.25,8.32058421634754E-6,-6.40047915645565E-5,8.27818074393024E-6,300.0064087,300.0064087,38972.78515625,38982.73828125,56.6852634716598,20.5708639192143,22.909004,0,0,0,40,4449,300.1841,38977.76171875,,,,,,,,,,,,,0,,,,-0.0049,,,,,,300.0064087,,,,
,33027634.73,300.0067749,42213.8125,-7.5256488720235E-5,1.51975508838876E-6,1,0.999253354069792,40.0298881530762,1.99994649516226,19.1399995237589,-0.000874215197547566,-2.05104995577438E-5,0.25,1.12272623469254E-5,-7.52616497305308E-5,1.11773945981343E-5,300.0067749,300.0067749,42211.08984375,42216.53515625,56.5985027060252,20.567816893604,23.288654,0,0,0,40,4449,300.1778,42213.8125,,,,,,,,,,,,,0,,,,-0.0049,,,,,,300.0067749,,,,
,33027698.575,300.0016785,45405.412109375,-8.73615211009297E-5,1.03426010272997E-6,1,0.999253354069792,40.0298881530762,1.99993049245335,19.1399995237589,-0.00100982595127781,-5.26657320528077E-5,0.25,1.04848200915289E-5,-8.7365849598606E-5,1.04270509328446E-5,300.0016785,300.0016785,45400.5859375,45410.23828125,56.5922496778714,20.5688406719689,23.288654,0,0,0,40,4449,300.1761,45405.412109375,,,,,,,,,,,,,0,,,,0,,,,,,300.0016785,,,,
,33027763.49,300.0049438,48648.294921875,-0.000100265516961447,1.47212684581953E-6,1,0.999253354069792,40.0298881530762,1.99986345059571,19.1500000655651,-0.00115791277402487,-6.64187179794197E-5,0.25,1.1505721643587E-5,-0.000100270124636531,1.14394840456367E-5,300.0049438,300.0049438,48638.296875,48658.29296875,56.4617177151598,20.5696325740165,23.668306,0,0,0,40,4449,300.1753,48648.294921875,,,,,,,,,,,,,0,,,,0,,,,,,300.0049438,,,,
,33027827.82,300.0093079,51864.353515625,-0.000110676878567346,1.62129772236433E-6,1,0.999253354069792,40.0298881530762,1.99983483790845,19.1399995237589,-0.00127970905572476,-6.42023449333546E-5,0.25,1.35051298953868E-5,-0.00011068247444185,1.34320430477782E-5,300.0093079,300.0093079,51856.7890625,51871.91796875,56.6461820456983,20.569227032714,22.909004,0,0,0,40,4449,300.17005,51864.353515625,,,,,,,,,,,,,0,,,,-0.00245,,,,,,300.0093079,,,,
,33027893.605,300.0029602,55152.80859375,-0.000117240972119543,1.6946748699905E-6,1,0.999253354069792,40.0298881530762,1.99985804437917,19.1399995237589,-0.00133342835813337,-0.000196111550270209,0.25,2.99303718622625E-6,-0.00011723950066895,2.91601308015992E-6,300.0029602,300.0029602,55145.26171875,55160.35546875,56.8118872917752,20.5712611310271,22.909004,0,0,0,40,4449,300.1743,55152.80859375,,,,,,,,,,,,,0,,,,0,,,,,,300.0029602,,,,
,33027956.725,300.0011292,58308.90234375,-0.000134784136003112,1.61523007495204E-6,1,0.999253354069792,40.0298881530762,1.99988087367426,19.1399995237589,-0.00155314095091365,-0.000109036948290726,0.25,1.37223305682262E-5,-0.00013478919940725,1.36335414006788E-5,300.0011292,300.0011292,58304.08203125,58313.72265625,56.4413953736598,20.5708460371659,23.288654,0,0,0,40,4449,300.15245,58308.90234375,,,,,,,,,,,,,0,,,,0.0049,,,,,,300.0011292,,,,
,33028023.295,300.0101624,61634.478515625,-0.000146602701423207,1.64970577146662E-6,1,0.999253354069792,40.0298881530762,1.99977846881381,19.1399995237589,-0.00168910514581034,-0.000119400556829562,0.25,1.48540860946915E-5,-0.000146608113352419,1.47575914369773E-5,300.0101624,300.0101624,61632.38671875,61636.5703125,56.6680676442368,20.5699005847567,23.288654,0,0,0,40,4449,300.1622,61634.478515625,,,,,,,,,,,,,0,,,,0,,,,,,300.0101624,,,,
,33028090.885,300.0086365,65013.841796875,-0.000159164965581584,1.61962814144416E-6,1,0.999253354069792,40.0298881530762,1.99979027642181,19.1399995237589,-0.00183311158066531,-0.000133915471963261,0.25,1.57485887341036E-5,-0.000159170601229051,1.56439246868024E-5,300.0086365,300.0086365,65011.16015625,65016.5234375,56.6625962446021,20.5711325278847,22.909004,0,0,0,40,4449,300.1602,65013.841796875,,,,,,,,,,,,,0,,,,0,,,,,,300.0086365,,,,
,33028157.66,300.0015259,68349.9140625,-0.000173100215829513,2.6394169974944E-6,1,0.999253354069792,40.0298881530762,1.99983714951166,19.1399995237589,-0.00198760519510488,-0.000180532214966375,0.25,1.40461337296932E-5,-0.000173104372631432,1.39324992877177E-5,300.0015259,300.0015259,68340.046875,68359.78125,56.5805252500829,20.5686549907578,22.909004,0,0,0,40,4449,300.16925,68349.9140625,,,,,,,,,,,,,0,,,,0.0049,,,,,,300.0015259,,,,
,33028223.835,300.0076599,71660.6171875,-0.000183305947114315,2.081312218815E-6,1,0.999253354069792,40.0298881530762,1.99977689741704,19.1399995237589,-0.00211016056270941,-0.000159828065140936,0.25,1.76422464911689E-5,-0.000183312118453696,1.75219235051189E-5,300.0076599,300.0076599,71658.4140625,71662.8203125,56.7282530402175,20.5678946441684,22.909004,0,0,0,40,4449,300.1577,71660.6171875,,,,,,,,,,,,,0,,,,0,,,,,,300.0076599,,,,
,33028291.315,300.0134277,75031.4609375,-0.000197941120984216,2.92590716288112E-6,1,0.999253354069792,40.0298881530762,1.99979790023674,19.1399995237589,-0.00226951556136343,-0.000225363448678318,0.25,1.43900034097904E-5,-0.000197944699540579,1.42603180128749E-5,300.0134277,300.0134277,75026.484375,75036.4375,56.8142321773329,20.5710049510757,22.909004,0,0,0,40,4449,300.15635,75031.4609375,,,,,,,,,,,,,0,,,,0,,,,,,300.0134277,,,,
,33028356.975,300.0109558,78312.76171875,-0.000210715745358828,2.68837662463499E-6,1,0.999253354069792,40.0298881530762,1.99976544530857,19.1399995237589,-0.00241485204147202,-0.000246225637971216,0.25,1.47602971354465E-5,-0.000210719210868418,1.46223649095533E-5,300.0109558,300.0109558,78310.3046875,78315.21875,56.5867782782368,20.5708213072603,22.909004,0,0,0,40,4449,300.1351,78312.76171875,,,,,,,,,,,,,0,,,,0,,,,,,300.0109558,,,,
,33028422.345,300.0160828,81581.87890625,-0.000222583162433904,2.42558745181515E-6,1,0.999253354069792,40.0298881530762,1.99983273556934,19.1399995237589,-0.00255933221747443,-0.000211642923079334,0.25,1.98710351566782E-5,-0.00022258957454925,1.97253286684632E-5,300.0160828,300.0160828,81569.4140625,81594.34375,56.5680191937752,20.5705829647561,22.909004,0,0,0,40,4449,300.1339,81581.87890625,,,,,,,,,,,,,0,,,,0,,,,,,300.0160828,,,,
,33028487.26,300.0124512,84828.45703125,-0.000236191867717823,2.71882203771693E-6,1,0.999253354069792,40.0298881530762,1.99986371593958,19.1399995237589,-0.00270972180863607,-0.0002599582337189,0.25,1.79620006814394E-5,-0.000236196667458174,1.78076057061113E-5,300.0124512,300.0124512,84823.5078125,84833.40625,56.6774471864675,20.5696625522516,23.288654,0,0,0,40,4449,300.12545,84828.45703125,,,,,,,,,,,,,0,,,,0.00245,,,,,,300.0124512,,,,
,33028550.57,300.0133362,87989.546875,-0.000244940379421661,2.9221706868041E-6,1,0.999253354069792,40.0298881530762,1.99985865686016,19.1399995237589,-0.00280727466681146,-0.000285794329914545,0.25,1.7195807116044E-5,-0.000244944418908049,1.70358625553728E-5,300.0133362,300.0133362,87977.0078125,88002.0859375,56.5844333926791,20.5703261465502,23.288654,0,0,0,40,4449,300.1174,87989.546875,,,,,,,,,,,,,0,,,,0,,,,,,300.0133362,,,,
,33028631.985,300.0056763,88920.02734375,-0.000256393813656098,2.09133643149486E-6,1,0.999253354069792,40.0298881530762,1.99993174221102,19.1399995237589,-0.00293728460298956,-0.000307028899049066,0.25,1.73057005413467E-5,-0.000256397661567094,1.71383432918568E-5,300.0046082,300.0067444,88912.453125,88927.6015625,56.7438856106022,20.5734946067746,22.909004,0,0,0,40,4449,300.1178,88920.02734375,,,,,,,,,,,,,0,,,,0,,,,,,300.0056763,,,,
,33028694.9,300.0101013,85776.46484375,-0.000240942959027782,2.44371912972527E-6,1,0.999253354069792,40.0298881530762,1.99990343204989,19.1399995237589,-0.00276111420036024,-0.000283474581993082,0.25,1.67087656183712E-5,-0.000240946824360675,1.65513408838766E-5,300.0101013,300.0101013,85774.03125,85778.8984375,56.7274714116983,20.5734233028467,22.909004,0,0,0,40,4449,300.1062,85776.46484375,,,,,,,,,,,,,0,,,,-0.0049,,,,,,300.0101013,,,,
,33028758.755,300.0007935,82584.83203125,-0.000226922786274992,2.91533802182555E-6,1,0.999253354069792,40.0298881530762,1.99976971744071,19.1399995237589,-0.00260466110284584,-0.000241693715610207,0.25,1.79682935829179E-5,-0.000226927955132246,1.78198506800775E-5,300.0007935,300.0007935,82574.734375,82594.9296875,56.6696309012752,20.5711182918977,22.909004,0,0,0,40,4449,300.1139,82584.83203125,,,,,,,,,,,,,0,,,,0,,,,,,300.0007935,,,,
,33028825.825,299.9935913,79230.20703125,-0.000215247723302644,3.01189678704319E-6,1,0.999253354069792,40.0298881530762,1.99983896330996,19.1399995237589,-0.00247467150910817,-0.000206543822463834,0.25,1.90506685464201E-5,-0.0002152539901056,1.89096914416716E-5,299.9935913,299.9935913,79225.171875,79235.2421875,56.5828701356406,20.5718748752478,23.288654,0,0,0,40,4449,300.1218,79230.20703125,,,,,,,,,,,,,0,,,,-0.00245,,,,,,299.9935913,,,,
,33028892,299.9891052,75921.63671875,-0.000201876668486131,1.57387101431574E-6,1,0.999253354069792,40.0298881530762,1.99980776831233,19.1399995237589,-0.00231679313198171,-0.000217486448675665,0.25,1.57675911987301E-5,-0.000201881207509875,1.56353232337607E-5,299.9891052,299.9891052,75916.5625,75926.7109375,56.5945945634291,20.5721373549112,23.288654,0,0,0,40,4449,300.12545,75921.63671875,,,,,,,,,,,,,0,,,,0,,,,,,299.9891052,,,,
,33028957.95,299.9883728,72624.7734375,-0.000191351788903978,2.66804821784733E-6,1,0.999253354069792,40.0298881530762,1.99979676436834,19.1399995237589,-0.0021974222465579,-0.000197909656516736,0.25,1.56730993114052E-5,-0.000191356570735774,1.55476109568334E-5,299.9883728,299.9883728,72617.4921875,72632.0546875,56.7556100383906,20.5757487599257,23.288654,0,0,0,40,4449,300.1458,72624.7734375,,,,,,,,,,,,,0,,,,-0.0049,,,,,,299.9883728,,,,
,33029023.02,299.9874573,69376.2109375,-0.000177398802838957,2.13736754196742E-6,1,0.999253354069792,40.0298881530762,1.99975797025483,19.1399995237589,-0.00203909748785594,-0.000172251535365818,0.25,1.55215831236526E-5,-0.000177403889493734,1.54051188504569E-5,299.9874573,299.9874573,69368.8515625,69383.5703125,56.6219515616021,20.5745954492713,23.668306,0,0,0,40,4449,300.14025,69376.2109375,,,,,,,,,,,,,0,,,,-0.00245,,,,,,299.9874573,,,,
,33029088.555,299.9898376,66099.7109375,-0.000162056409840796,1.56061463328846E-6,1,0.999253354069792,40.0298881530762,1.99972363157409,19.1399995237589,-0.00185867854189303,-0.000180648892217737,0.25,1.21216961702418E-5,-0.000162059695909869,1.20152780169048E-5,299.9898376,299.9898376,66089.59375,66109.828125,56.6868267286983,20.5731406346833,22.909004,0,0,0,40,4449,300.14895,66099.7109375,,,,,,,,,,,,,0,,,,-0.0049,,,,,,299.9898376,,,,
,33029155.2,299.9885559,62769.158203125,-0.000148152621500492,1.89300036755722E-6,1,0.999253354069792,40.0298881530762,1.99973468034709,19.1399995237589,-0.00169965652083423,-0.000162633672850277,0.25,1.13040935245403E-5,-0.000148155777019296,1.12067201924342E-5,299.9885559,299.9885559,62761.65234375,62776.6640625,56.6156985334483,20.5755099156179,23.668306,0,0,0,40,4449,300.15215,62769.158203125,,,,,,,,,,,,,0,,,,-0.00245,,,,,,299.9885559,,,,
,33029220.235,299.9881897,59514.681640625,-0.000137888592938836,1.77412529594345E-6,1,0.999253354069792,40.0298881530762,1.99971153696565,19.1399995237589,-0.00159141550199986,-9.6364963662194E-5,0.25,1.53785636857304E-5,-0.000137894715254141,1.52877273437446E-5,299.9881897,299.9881897,59507.3828125,59521.98046875,56.7274714116983,20.5769408972173,23.668306,0,0,0,40,4449,300.16095,59514.681640625,,,,,,,,,,,,,0,,,,-0.00245,,,,,,299.9881897,,,,
,33029288.005,299.9853821,56128.71484375,-0.000127130987161712,1.64286339670349E-6,1,0.999253354069792,40.0298881530762,1.99977667979091,19.1399995237589,-0.0014668872968815,-9.12570088525076E-5,0.25,1.39662393674177E-5,-0.000127136506726461,1.38824290049555E-5,299.9853821,299.9853821,56123.71875,56133.7109375,56.6985511564868,20.57741312227,23.288654,0,0,0,40,4449,300.16435,56128.71484375,,,,,,,,,,,,,0,,,,0,,,,,,299.9853821,,,,
,33029357.92,299.9868469,52634.919921875,-0.000114921802972665,1.28193356796741E-6,1,0.999253354069792,40.0298881530762,1.99968370160558,19.1399995237589,-0.00132536143900894,-8.59098338581021E-5,0.25,1.23229368981971E-5,-0.000114926589334599,1.22471225100615E-5,299.9868469,299.9868469,52624.30078125,52645.5390625,56.7423223535637,20.577984587363,23.288654,0,0,0,40,4449,300.17495,52634.919921875,,,,,,,,,,,,,0,,,,0,,,,,,299.9868469,,,,
,33029426.32,299.98349,49215.025390625,-9.91244181822397E-5,1.39140031135496E-6,1,0.999253354069792,40.0298881530762,1.99969253991238,19.1399995237589,-0.00114475035820838,-6.50341683470236E-5,0.25,1.14298192478384E-5,-9.91290856635504E-5,1.13643553762642E-5,299.98349,299.98349,49207.93359375,49222.1171875,56.7649895806214,20.5774152206589,23.668306,0,0,0,40,4449,300.1907,49215.025390625,,,,,,,,,,,,,0,,,,-0.0049,,,,,,299.98349,,,,
,33029492.205,299.9840393,45920.548828125,-8.77205918809469E-5,1.31754284535811E-6,1,0.999253354069792,40.0298881530762,1.9996450403541,19.1399995237589,-0.00101708740752473,-3.41258926944933E-5,0.25,1.21838683177141E-5,-8.77260823129562E-5,1.21258335765464E-5,299.9840393,299.9840393,45917.953125,45923.14453125,56.8970848003714,20.5780465772858,23.288654,0,0,0,40,4449,300.2017,45920.548828125,,,,,,,,,,,,,0,,,,-0.0049,,,,,,299.9840393,,,,
,33029556.93,299.9892578,42687.255859375,-7.81581872656767E-5,1.56936593936102E-6,1,0.999253354069792,40.0298881530762,1.99963753540358,19.1399995237589,-0.000906927248481805,-2.6274617711865E-5,0.25,1.12206187013947E-5,-7.81633067002124E-5,1.1168856549194E-5,299.9892578,299.9892578,42679.66015625,42694.8515625,56.8673829166406,20.5776292905114,23.668306,0,0,0,40,4449,300.19085,42687.255859375,,,,,,,,,,,,,0,,,,0,,,,,,299.9892578,,,,
,33029622.7,299.9882813,39401.107421875,-6.53523969133197E-5,1.00791686906873E-6,1,0.999253354069792,40.0298881530762,1.99963082363479,19.1399995237589,-0.00076124478035839,-5.14485485637115E-6,0.25,1.08682227963305E-5,-6.53576601224928E-5,1.08248686728685E-5,299.9882813,299.9882813,39396.2109375,39406.00390625,56.7860935506406,20.5791189447778,23.288654,0,0,0,40,4449,300.2055,39401.107421875,,,,,,,,,,,,,0,,,,-0.0049,,,,,,299.9882813,,,,
,33029689.395,299.987793,36065.888671875,-5.55867327690035E-5,1.2862212112924E-6,1,0.999253354069792,40.0298881530762,1.99972364170535,19.1399995237589,-0.000646693579419541,-9.146441701452E-6,0.25,8.82290375988497E-6,-5.55909348843825E-5,8.78601328493284E-6,299.987793,299.987793,36058.4609375,36073.31640625,56.8197035769676,20.5795943899373,23.288654,0,0,0,40,4449,300.20995,36065.888671875,,,,,,,,,,,,,0,,,,-0.00245,,,,,,299.987793,,,,
,33029754.86,299.9887085,32794.927734375,-4.43524931472984E-5,1.06635716690686E-6,1,0.999253354069792,40.0298881530762,1.99976786371634,19.1399995237589,-0.000520411481359432,1.8130533111142E-5,0.25,9.28557299861802E-6,-4.43573270768704E-5,9.25605204685645E-6,299.9887085,299.9887085,32789.9765625,32799.87890625,56.8454973181022,20.5795874731327,23.668306,0,0,0,40,4449,300.2168,32794.927734375,,,,,,,,,,,,,0,,,,-0.00245,,,,,,299.9887085,,,,
,33029819.455,299.9876709,29566.4033203125,-2.97825961771671E-5,9.28037675524119E-7,1,0.999253354069792,40.0298881530762,1.99968127586179,19.1399995237589,-0.00035238822670565,2.91866461631695E-5,0.25,7.73781609541834E-6,-2.97868364845585E-5,7.71793582653734E-6,299.9876709,299.9876709,29556.57421875,29576.232421875,56.9174071418714,20.5796360652011,24.047956,0,0,0,40,4449,300.2224,29566.4033203125,,,,,,,,,,,,,0,,,,0.00245,,,,,,299.9876709,,,,
,33029884.64,299.9902649,26307.9287109375,-1.81935245671073E-5,7.72655319214682E-7,1,0.999253354069792,40.0298881530762,1.99968666519021,19.1399995237589,-0.000219792303804863,4.39504734729376E-5,0.25,7.0338872642726E-6,-1.81976380982038E-5,7.02166679146225E-6,299.9902649,299.9902649,26302.962890625,26312.89453125,56.9267866841022,20.5803679791254,22.909004,0,0,0,40,4449,300.2281,26307.9287109375,,,,,,,,,,,,,0,,,,0.00245,,,,,,299.9902649,,,,
,33029947.875,299.9848633,23147.2333984375,-8.26333793419685E-6,6.65539525049971E-7,1,0.999253354069792,40.0298881530762,1.99977579700451,19.1399995237589,-0.000104196753477075,4.51551009075664E-5,0.25,5.41964075212601E-6,-8.26667909856511E-6,5.41402279173728E-6,299.9848633,299.9848633,23139.837890625,23154.62890625,56.8970848003714,20.5791920255703,23.288654,0,0,0,40,4449,300.2374,23147.2333984375,,,,,,,,,,,,,0,,,,-0.00245,,,,,,299.9848633,,,,
,33030013.32,299.9872131,19876.3798828125,3.22556701555851E-6,5.58781492490313E-7,1,0.999253354069792,40.0298881530762,1.99974065046553,19.1399995237589,2.59811171981612E-5,6.71672823839326E-5,0.25,5.37324978586571E-6,3.22191989164886E-6,5.37522581998615E-6,299.9872131,299.9872131,19866.357421875,19886.40234375,56.9752476522945,20.5806007814471,23.668306,0,0,0,40,4449,300.239,19876.3798828125,,,,,,,,,,,,,0,,,,0.00245,,,,,,299.9872131,,,,
,33030077.71,299.99020385,16658.20703125,1.37816634194724E-5,6.47794618464993E-7,1,0.999253354069792,40.0298881530762,1.99975938995576,19.1399995237589,0.000147869679339136,7.42315994758053E-5,0.25,4.16817002483154E-6,1.37785014088983E-5,4.17716619029622E-6,299.9898071,299.9906006,16653.205078125,16663.208984375,57.1206305568714,20.5811562103981,23.288654,0,0,0,40,4449,300.2452,16658.20703125,,,,,,,,,,,,,0,,,,-0.0049,,,,,,299.99020385,,,,
,33030142.525,299.9926758,13419.9296875,2.45566541214459E-5,5.88606905268655E-7,1,0.999253354069792,40.0298881530762,1.99971090681086,19.1399995237589,0.00027219956895473,8.18995359530365E-5,0.25,2.97868702125234E-6,2.45539588424963E-5,2.9948565811215E-6,299.9926758,299.9926758,13409.7353515625,13430.1240234375,56.8603482599676,20.5825771821762,23.668306,0,0,0,40,4449,300.2466,13419.9296875,,,,,,,,,,,,,0,,,,-0.00245,,,,,,299.9926758,,,,
,33030205.475,299.9962158,10273.9375,3.33823251327829E-5,6.00506590295919E-7,1,0.999253354069792,40.0298881530762,1.9996957111412,19.1399995237589,0.000372916623154937,9.4646376372083E-5,0.25,2.57541022682553E-6,3.33796306295168E-5,2.59744615597656E-6,299.9962158,299.9962158,10261.5498046875,10286.3251953125,56.9002113144483,20.5816023509776,23.288654,0,0,0,40,4449,300.25135,10273.9375,,,,,,,,,,,,,0,,,,-0.00245,,,,,,299.9962158,,,,
,33030270.915,299.9897461,7002.45825195313,4.08090067348062E-5,4.68923928522866E-7,1,0.999253354069792,40.0298881530762,1.999590729945,19.1399995237589,0.000458718023524526,9.91892559922434E-5,0.25,1.69032267692E-6,4.0806686203134E-5,1.71731866535635E-6,299.9894714,299.9900208,6997.50537109375,7007.4111328125,56.8548768603329,20.5809276505137,23.288654,0,0,0,40,4449,300.2582,7002.45825195313,,,,,,,,,,,,,0,,,,-0.0049,,,,,,299.9897461,,,,
,33030334.165,299.9884338,3838.95007324219,4.40961544708472E-5,5.02378505564943E-7,1,0.999253354069792,40.0298881530762,1.9996396977822,19.1399995237589,0.000497949071850957,9.40801228721302E-5,0.25,6.69323064191703E-7,4.40944145656425E-5,6.98541158626577E-7,299.9884338,299.9884338,3834.01049804687,3843.8896484375,56.8040710065829,20.5819532729735,23.668306,0,0,0,40,4449,300.26335,3838.95007324219,,,,,,,,,,,,,0,,,,0,,,,,,299.9884338,,,,
,33030396.37,299.9837646,732.149383544922,3.56978401511802E-5,4.61656591761396E-7,1,0.999253354069792,40.0298881530762,1.99971648432238,19.1399995237589,0.000404616732958504,6.75679674139061E-5,0.25,-2.17439013839869E-7,3.56969404371509E-5,-1.9375607822382E-7,299.9837646,299.9837646,724.326049804687,739.972717285156,56.9166255133522,20.5819242947066,23.668306,0,0,0,40,4449,300.2856,732.149383544922,,,,,,,,,,,,,0,,,,0.00245,,,,,,299.9837646,,,,
,33030459.835,299.9915619,-2436.21960449219,-4.17548152179545E-5,4.19967620204502E-7,1,0.999253354069792,40.0298881530762,1.99965370776086,19.1399995237589,-0.000470464866621649,-9.51346203028937E-5,0.25,-1.16805954578795E-6,-4.17528082827296E-5,-1.19571441709071E-6,299.9913635,299.9917603,-2443.59814453125,-2428.84106445313,56.8775440873906,20.5807097885735,23.288654,0,0,0,40,4449,300.27555,-2436.21960449219,,,,,,,,,,,,,0,,,,0,,,,,,299.9915619,,,,
,33030522.94,299.9965515,-5591.44140625,-4.2779200917684E-5,5.02884941590627E-7,1,0.999253354069792,40.0298881530762,1.99973579900628,19.1399995237589,-0.000481526786369914,-0.000100352323765536,0.25,-1.45108025311776E-6,-4.27769700090987E-5,-1.47939287173533E-6,299.9965515,299.9965515,-5599.01904296875,-5583.86376953125,56.9869720800829,20.5822126710645,23.288654,0,0,0,40,4449,300.2767,-5591.44140625,,,,,,,,,,,,,0,,,,0,,,,,,299.9965515,,,,
,33030587.86,299.9997559,-8837.6787109375,-3.67158532945533E-5,6.203549040722E-7,1,0.999253354069792,40.0298881530762,1.99971684861748,19.1399995237589,-0.000410903647263674,-9.98055115370941E-5,0.25,-2.45341199723861E-6,-3.67131356938418E-5,-2.47766263241201E-6,299.9997559,299.9997559,-8842.671875,-8832.685546875,56.8540952318137,20.5787261842265,23.288654,0,0,0,40,4449,300.27915,-8837.6787109375,,,,,,,,,,,,,0,,,,0,,,,,,299.9997559,,,,
,33030653.51,299.9979553,-12118.939453125,-2.96980627606775E-5,6.65183272953E-7,1,0.999253354069792,40.0298881530762,1.99989997330955,19.1399995237589,-0.0003297834784659,-9.58001275031724E-5,0.25,-3.31482473463775E-6,-2.96949872969712E-5,-3.33439040586925E-6,299.9979553,299.9979553,-12131.193359375,-12106.685546875,57.0792042453522,20.5824291734074,23.288654,0,0,0,40,4449,300.2692,-12118.939453125,,,,,,,,,,,,,0,,,,0,,,,,,299.9979553,,,,
,33030717.78,300.0016174,-15330.2060546875,-1.8005035719251E-5,9.20252457859511E-7,1,0.999253354069792,40.0298881530762,1.99992122896323,19.1399995237589,-0.000195481024874329,-8.38158558067306E-5,0.25,-4.28232455115082E-6,-1.80016663936586E-5,-4.29411153625758E-6,300.0012817,300.0019531,-15335.31640625,-15325.095703125,57.0330881627176,20.5856534534241,24.047956,0,0,0,40,4449,300.27435,-15330.2060546875,,,,,,,,,,,,,0,,,,0.00245,,,,,,300.0016174,,,,
,33030782.94,300.0055542,-18588.611328125,-7.26071868190333E-6,8.21402368161005E-7,1,0.999253354069792,40.0298881530762,1.99993361906859,19.1399995237589,-7.32402641585049E-5,-6.60636700468264E-5,0.25,-4.57612529803702E-6,-7.25747565646962E-6,-4.58079033467069E-6,300.0055542,300.0055542,-18593.451171875,-18583.771484375,56.7868751791599,20.5815181676159,23.668306,0,0,0,40,4449,300.2714,-18588.611328125,,,,,,,,,,,,,0,,,,-0.0049,,,,,,300.0055542,,,,
,33030849.205,300.0029297,-21899.072265625,2.94543252454731E-6,8.92483464798989E-7,1,0.999253354069792,40.0298881530762,1.99988079936528,19.1399995237589,4.43221513862827E-5,-5.75362910724172E-5,0.25,-5.59149158723125E-6,2.94904030829859E-6,-5.58937882830001E-6,300.0029297,300.0029297,-21906.3984375,-21891.74609375,57.007294421583,20.5822195678763,23.668306,0,0,0,40,4449,300.2716,-21899.072265625,,,,,,,,,,,,,0,,,,-0.00245,,,,,,300.0029297,,,,
,33030917.18,300.014801,-25297.453125,1.51368318317929E-5,8.34912893368972E-7,1,0.999253354069792,40.0298881530762,1.99985955103267,19.1399995237589,0.000183832772775845,-4.20688577339955E-5,0.25,-6.33780649079251E-6,1.51405619714143E-5,-6.32761838466488E-6,300.014801,300.014801,-25299.978515625,-25294.927734375,56.9580518248714,20.5867184603856,24.047956,0,0,0,40,4449,300.2566,-25297.453125,,,,,,,,,,,,,0,,,,0,,,,,,300.014801,,,,
,33030983.42,300.006958,-28608.134765625,2.66504550137684E-5,1.03188888487228E-6,1,0.999253354069792,40.0298881530762,1.99988851777204,19.1399995237589,0.000316101440763375,-3.04012544260801E-5,0.25,-7.30216456332471E-6,2.66544805511401E-5,-7.28435842958419E-6,300.006958,300.006958,-28618.099609375,-28598.169921875,57.0002597649099,20.5856643306634,24.047956,0,0,0,40,4449,300.26655,-28608.134765625,,,,,,,,,,,,,0,,,,-0.00245,,,,,,300.006958,,,,
,33031050.01,300.0055542,-31936.56640625,3.90320417443904E-5,1.41663967026623E-6,1,0.999253354069792,40.0298881530762,1.9998809113588,19.1399995237589,0.000458142726803114,-1.67328615991238E-5,0.25,-8.24025641067359E-6,3.90363174881231E-5,-8.21426904175844E-6,300.0055542,300.0055542,-31941.041015625,-31932.091796875,57.0088576786214,20.5851423953603,23.668306,0,0,0,40,4449,300.25735,-31936.56640625,,,,,,,,,,,,,0,,,,0.00245,,,,,,300.0055542,,,,
,33031115.75,300.0063477,-35221.765625,4.98714457924582E-5,1.56632671434762E-6,1,0.999253354069792,40.0298881530762,1.99991662612915,19.1399995237589,0.000581543715873503,7.69855408655628E-7,0.25,-8.572517396059E-6,4.98756154922948E-5,-8.5393946719468E-6,300.0063477,300.0063477,-35224.27734375,-35219.25390625,57.0776409883137,20.5837384472316,23.668306,0,0,0,40,4449,300.25405,-35221.765625,,,,,,,,,,,,,0,,,,0.00245,,,,,,300.0063477,,,,
,33031182.735,300.0125732,-38567.646484375,6.34038488612548E-5,1.56043661391442E-6,1,0.999253354069792,40.0298881530762,1.99993794368625,19.1399995237589,0.000739013446414665,2.92381346364216E-6,0.25,-1.07268348030787E-5,6.34090201997395E-5,-1.06847574727422E-5,300.0125732,300.0125732,-38572.61328125,-38562.6796875,56.9854088230445,20.5864038783367,24.047956,0,0,0,40,4449,300.24615,-38567.646484375,,,,,,,,,,,,,0,,,,0.0049,,,,,,300.0125732,,,,
,33031249.745,300.0167542,-41917.98828125,7.41143203724484E-5,1.5127412903665E-6,1,0.999253354069792,40.0298881530762,1.99994857729118,19.1399995237589,0.000861194261039462,1.87764999606883E-5,0.25,-1.11824984829508E-5,7.41194587046944E-5,-1.11333876505315E-5,300.0167542,300.0167542,-41925.27734375,-41910.69921875,56.9213152844676,20.5861271128123,24.047956,0,0,0,40,4449,300.2354,-41917.98828125,,,,,,,,,,,,,0,,,,0.00245,,,,,,300.0167542,,,,
,33031316.73,300.01474,-45266.8671875,8.87405883848184E-5,1.71597863320388E-6,1,0.999253354069792,40.0298881530762,1.99987331202787,19.1399995237589,0.0010280253943018,4.02950552349595E-5,0.25,-1.18161005230953E-5,8.87457099770366E-5,-1.17573880785934E-5,300.01474,300.01474,-45274.84765625,-45258.88671875,56.8767624588714,20.5876612170368,23.668306,0,0,0,40,4449,300.22085,-45266.8671875,,,,,,,,,,,,,0,,,,0.0049,,,,,,300.01474,,,,
,33031383.47,300.0140991,-48599.341796875,0.000103289643275077,1.82575881409102E-6,1,0.999253354069792,40.0298881530762,1.999822452661,19.1399995237589,0.00119152586624059,7.58501575631843E-5,0.25,-1.11965957741598E-5,0.000103293924447867,-1.11283894366492E-5,300.0140991,300.0140991,-48602.140625,-48596.54296875,56.9361662263329,20.5882304544112,24.047956,0,0,0,40,4449,300.2283,-48599.341796875,,,,,,,,,,,,,0,,,,0,,,,,,300.0140991,,,,
,33031450.15,300.008728,-51935.5,0.000114187839028935,1.42321732256772E-6,1,0.999253354069792,40.0298881530762,1.99977220406916,19.1399995237589,0.00131955708551156,7.03250227350135E-5,0.25,-1.35724946506246E-5,0.000114193377255641,-1.34971145640871E-5,300.008728,300.008728,-51940.3515625,-51930.6484375,56.9830639374868,20.5871951054841,23.288654,0,0,0,40,4449,300.2141,-51935.5,,,,,,,,,,,,,0,,,,0.00245,,,,,,300.008728,,,,
,33031514.26,300.0070801,-55138.642578125,0.000124740957872059,1.73928916196748E-6,1,0.999253354069792,40.0298881530762,1.99998083023735,19.1399995237589,0.0014402551960733,8.48984046172408E-5,0.25,-1.41144603696898E-5,0.000124746546041392,-1.40321989644382E-5,300.0070801,300.0070801,-55148.7578125,-55128.52734375,57.0237086204868,20.5891308516602,23.668306,0,0,0,40,4449,300.2135,-55138.642578125,,,,,,,,,,,,,0,,,,0,,,,,,300.0070801,,,,
,33031581.665,300.0134583,-58506.962890625,0.000138044866879303,1.87582031677996E-6,1,0.999253354069792,40.0298881530762,2.00001417318078,19.1399995237589,0.00159093341492814,0.000111000573542455,0.25,-1.41144432178176E-5,0.000138050030778727,-1.40235207112917E-5,300.0134583,300.0134583,-58511.78515625,-58502.140625,56.9158438848329,20.5893137641324,23.668306,0,0,0,40,4449,300.2037,-58506.962890625,,,,,,,,,,,,,0,,,,0,,,,,,300.0134583,,,,
,33031648.71,300.0144348,-61857.513671875,0.00015016149103879,1.92118606408905E-6,1,0.999253354069792,40.0298881530762,1.99989120570197,19.1399995237589,0.00172819966132309,0.000133857667926511,0.25,-1.41944628431272E-5,0.0001501663427335,-1.409567255607E-5,300.0144348,300.0144348,-61864.94921875,-61850.078125,56.9174071418714,20.5890647802838,23.668306,0,0,0,40,4449,300.197,-61857.513671875,,,,,,,,,,,,,0,,,,-0.00245,,,,,,300.0144348,,,,
,33031714.66,300.0152893,-65156.056640625,0.000162450757812682,1.8951623699948E-6,1,0.999253354069792,40.0298881530762,1.99992141342632,19.1399995237589,0.00187272488727932,0.00012714148346474,0.25,-1.69167924575335E-5,0.000162457022690259,-1.68099547620518E-5,300.0152893,300.0152893,-65163.53515625,-65148.578125,56.9682129956214,20.592086982081,23.668306,0,0,0,40,4449,300.189,-65156.056640625,,,,,,,,,,,,,0,,,,0,,,,,,300.0152893,,,,
,33031781.705,300.0121155,-68504.2734375,0.000177448650536747,2.34091405651208E-6,1,0.999253354069792,40.0298881530762,2.00002841011697,19.1399995237589,0.0020442923727031,0.000147153172102343,0.25,-1.77485150722932E-5,0.000177455035093853,-1.76319323982997E-5,300.0121155,300.0121155,-68516.734375,-68491.8125,56.9174071418714,20.5895837251759,24.047956,0,0,0,40,4449,300.1822,-68504.2734375,,,,,,,,,,,,,0,,,,-0.0049,,,,,,300.0121155,,,,
,33031848.125,300.0138855,-71824.53515625,0.000191437023260318,2.34143194270954E-6,1,0.999253354069792,40.0298881530762,1.99989698616042,19.1399995237589,0.00220144799168493,0.000181015304466732,0.25,-1.71806618580886E-5,0.000191442612345127,-1.70550518351639E-5,300.0138855,300.0138855,-71834.5390625,-71814.53125,57.0760777312753,20.5906224219236,23.668306,0,0,0,40,4449,300.18315,-71824.53515625,,,,,,,,,,,,,0,,,,-0.00245,,,,,,300.0138855,,,,
,33031914.48,300.0126648,-75139.890625,0.000201116466281214,2.06144125533121E-6,1,0.999253354069792,40.0298881530762,1.99970867459378,19.1399995237589,0.00230781332194107,0.00021749068195994,0.25,-1.56345976556122E-5,0.000201120769824973,-1.55028074300981E-5,300.0126648,300.0126648,-75152.3359375,-75127.4453125,56.9017745714868,20.5914599873744,23.668306,0,0,0,40,4449,300.15885,-75139.890625,,,,,,,,,,,,,0,,,,-0.00245,,,,,,300.0126648,,,,
,33031981.47,300.0110779,-78490.5546875,0.000215896003041076,2.35045104779053E-6,1,0.999253354069792,40.0298881530762,1.99981198562511,19.1399995237589,0.00247289082179908,0.000260267981468697,0.25,-1.44180798438334E-5,0.000215899093158407,-1.42767981572827E-5,300.0110779,300.0110779,-78500.5703125,-78480.5390625,56.7853119221214,20.5927541286797,23.668306,0,0,0,40,4449,300.1614,-78490.5546875,,,,,,,,,,,,,0,,,,0,,,,,,300.0110779,,,,
,33032049.085,300.0057678,-81868.984375,0.000222813823064217,2.68088139918355E-6,1,0.999253354069792,40.0298881530762,1.99987088950883,19.1399995237589,0.00255170319168665,0.000271484863173809,0.25,-1.46265151978092E-5,0.000222816892136262,-1.44808422470432E-5,300.0057678,300.0057678,-81873.96875,-81864,56.9955699937945,20.5916621775438,23.288654,0,0,0,40,4449,300.1578,-81868.984375,,,,,,,,,,,,,0,,,,0,,,,,,300.0057678,,,,
,33032115.06,300.0090637,-85164.5625,0.00023982101571849,2.7723426258029E-6,1,0.999253354069792,40.0298881530762,1.9997538566122,19.1399995237589,0.00275083073860132,0.0002661480173438,0.25,-1.80428406280732E-5,0.000239825791705365,-1.78861150917816E-5,300.0090637,300.0090637,-85172.203125,-85156.921875,56.9791557948906,20.5953228277198,23.668306,0,0,0,40,4449,300.1585,-85164.5625,,,,,,,,,,,,,0,,,,-0.00245,,,,,,300.0090637,,,,
,33032176.615,300.0188904,-88239.64453125,0.000249202958950431,2.67188621490266E-6,1,0.999253354069792,40.0298881530762,1.99986661695218,19.1399995237589,0.00285140917122153,0.000318067681077661,0.25,-1.50841919559628E-5,0.000249205450569504,-1.49215636344731E-5,300.0188904,300.0188904,-88244.6328125,-88234.65625,56.9267866841022,20.5934046912129,24.047956,0,0,0,40,4449,300.1516,-88239.64453125,,,,,,,,,,,,,0,,,,-0.00245,,,,,,300.0188904,,,,
,33032257.905,300.0132141,-88677.65234375,0.000251777873535456,2.86281464511306E-6,1,0.999253354069792,40.0298881530762,1.99991416151647,19.1399995237589,0.0028846391374631,0.00029999575885571,0.25,-1.71268730573951E-5,0.000251781670328198,-1.69625181159051E-5,300.0132141,300.0132141,-88682.828125,-88672.4765625,57.0893654161022,20.592553590475,23.668306,0,0,0,40,4449,300.1308,-88677.65234375,,,,,,,,,,,,,0,,,,0,,,,,,300.0132141,,,,
,33032322.955,300.0129089,-85427.60546875,0.000238447228640622,2.95539802579383E-6,1,0.999253354069792,40.0298881530762,1.99986540599436,19.1399995237589,0.00273422549013177,0.00027036704695607,0.25,-1.7433492897721E-5,0.00023845161469627,-1.72776727950017E-5,300.0129089,300.0129089,-85429.90625,-85425.3046875,57.047939104583,20.5916518821307,23.668306,0,0,0,40,4449,300.13295,-85427.60546875,,,,,,,,,,,,,0,,,,0.00245,,,,,,300.0129089,,,,
,33032389.29,300.0002441,-82109.625,0.000226727614813902,2.27446141603513E-6,1,0.999253354069792,40.0298881530762,1.99985271306031,19.1399995237589,0.00260092316616215,0.000250735547414816,0.25,-1.71368166035678E-5,0.000226732251681734,-1.69885193638143E-5,300.0002441,300.0002441,-82117.2421875,-82102.0078125,56.9994781363906,20.5927717689557,23.668306,0,0,0,40,4449,300.1356,-82109.625,,,,,,,,,,,,,0,,,,0.0049,,,,,,300.0002441,,,,
,33032455.28,299.9920502,-78813.55078125,0.000216315142779914,2.12291241158878E-6,1,0.999253354069792,40.0298881530762,1.99980506128532,19.1399995237589,0.00247902976702904,0.000253011625732322,0.25,-1.51314796485008E-5,0.000216318834018472,-1.49899176576789E-5,299.9916077,299.9924927,-78823.3828125,-78803.71875,56.9252234270637,20.5875255830506,23.668306,0,0,0,40,4449,300.1468,-78813.55078125,,,,,,,,,,,,,0,,,,0,,,,,,299.9920502,,,,
,33032520.875,299.9916992,-75532.68359375,0.000199309741407087,2.38858508489395E-6,1,0.999253354069792,40.0298881530762,1.9999450455208,19.1399995237589,0.00228190556679848,0.000246933807375043,0.25,-1.27236460371882E-5,0.000199312347456388,-1.25931393903559E-5,299.9916992,299.9916992,-75535.1640625,-75530.203125,57.0354330482753,20.5903058140834,23.668306,0,0,0,40,4449,300.1503,-75532.68359375,,,,,,,,,,,,,0,,,,-0.0049,,,,,,299.9916992,,,,
,33032586.785,299.9906616,-72239.4296875,0.000190327305390444,2.38832233581103E-6,1,0.999253354069792,40.0298881530762,1.99987900434839,19.1399995237589,0.00218115169051365,0.000223358847287943,0.25,-1.324882108202E-5,0.000190330516496451,-1.31240632159547E-5,299.9906616,299.9906616,-72246.6953125,-72232.1640625,57.1081245005637,20.5923683574333,23.668306,0,0,0,40,4449,300.15645,-72239.4296875,,,,,,,,,,,,,0,,,,0.00245,,,,,,299.9906616,,,,
,33032652.405,299.9920959,-68959.4921875,0.000179020833163086,2.08085277928837E-6,1,0.999253354069792,40.0298881530762,1.99987168396538,19.1399995237589,0.00206104404661649,0.000155417826764483,0.25,-1.72900582361176E-5,0.000179027000320588,-1.71724749193902E-5,299.9920959,299.9920959,-68974.6640625,-68944.3203125,57.0737328457176,20.5906448446682,24.047956,0,0,0,40,4449,300.15665,-68959.4921875,,,,,,,,,,,,,0,,,,-0.00245,,,,,,299.9920959,,,,
,33032719.75,299.9866333,-65595.8046875,0.000165243264046659,1.86898310203028E-6,1,0.999253354069792,40.0298881530762,1.99988018461351,19.1399995237589,0.00190065174738968,0.000153737255788051,0.25,-1.50516527819548E-5,0.000165248395493111,-1.49430578769726E-5,299.9866333,299.9866333,-65601,-65590.609375,56.9572701963522,20.5930506761595,23.288654,0,0,0,40,4449,300.1611,-65595.8046875,,,,,,,,,,,,,0,,,,0,,,,,,299.9866333,,,,
,33032785.97,299.9912109,-62285.2734375,0.000151183528427831,1.721746007463E-6,1,0.999253354069792,40.0298881530762,1.99983492155681,19.1399995237589,0.00174015190634147,0.000133409090796222,0.25,-1.44108404620407E-5,0.000151188617735891,-1.43113861652189E-5,299.9912109,299.9912109,-62292.7265625,-62277.8203125,56.9869720800829,20.5910752008337,24.047956,0,0,0,40,4449,300.16985,-62285.2734375,,,,,,,,,,,,,0,,,,-0.0049,,,,,,299.9912109,,,,
,33032853.25,299.9850464,-58922.17578125,0.000137951469092656,1.82153469980936E-6,1,0.999253354069792,40.0298881530762,1.99967787702485,19.1399995237589,0.00158758608639403,0.000122552508912114,0.25,-1.30764216194484E-5,0.000137956096019174,-1.29856046120264E-5,299.9850464,299.9850464,-58929.08203125,-58915.26953125,56.7939098358329,20.5909176437196,24.047956,0,0,0,40,4449,300.1784,-58922.17578125,,,,,,,,,,,,,0,,,,-0.00245,,,,,,299.9850464,,,,
,33032918.91,299.9786072,-55641.435546875,0.000127241682838557,1.9097688052928E-6,1,0.999253354069792,40.0298881530762,1.9996983950319,19.1399995237589,0.00146617999335566,0.00010247328668103,0.25,-1.29945035488082E-5,0.000127246592733035,-1.29106449553615E-5,299.9786072,299.9786072,-55646.06640625,-55636.8046875,56.8963031718522,20.5899670398789,24.047956,0,0,0,40,4449,300.1745,-55641.435546875,,,,,,,,,,,,,0,,,,-0.0049,,,,,,299.9786072,,,,
,33032983.625,299.9896851,-52405.982421875,0.000114671868592446,2.20706767418071E-6,1,0.999253354069792,40.0298881530762,1.9997196910858,19.1399995237589,0.00132531697714852,6.94743177860819E-5,0.25,-1.37313326900315E-5,0.000114677575153191,-1.36556431036622E-5,299.9896851,299.9896851,-52413.48046875,-52398.484375,56.8236117195637,20.5884735650047,24.047956,0,0,0,40,4449,300.1977,-52405.982421875,,,,,,,,,,,,,0,,,,0.0049,,,,,,299.9896851,,,,
,33033050.77,299.98425295,-49050.419921875,9.98166645803313E-5,1.58052060501357E-6,1,0.999253354069792,40.0298881530762,1.99973148738259,19.1399995237589,0.0011541895341814,5.72744739385561E-5,0.25,-1.22351852639402E-5,9.98218386742596E-5,-1.21692434608863E-5,299.9837952,299.9847107,-49055.75,-49045.08984375,56.9517987967176,20.5854879636669,24.047956,0,0,0,40,4449,300.20215,-49050.419921875,,,,,,,,,,,,,0,,,,0,,,,,,299.98425295,,,,
,33033115,299.9865723,-45842.33203125,8.95299855861881E-5,1.62766881331925E-6,1,0.999253354069792,40.0298881530762,1.9997531404858,19.1399995237589,0.00103421751754035,5.73568275063791E-5,0.25,-1.04458056271886E-5,8.95342729529287E-5,-1.03866288218424E-5,299.9865723,299.9865723,-45847.2890625,-45837.375,56.9682129956214,20.5858186428182,23.668306,0,0,0,40,4449,300.20105,-45842.33203125,,,,,,,,,,,,,0,,,,0,,,,,,299.9865723,,,,
,33033183.045,299.9840698,-42441.533203125,7.50404309993504E-5,1.44592914393236E-6,1,0.999253354069792,40.0298881530762,1.99983980411763,19.1399995237589,0.000872962013556402,1.29453502779667E-5,0.25,-1.18578359228456E-5,7.50460738685474E-5,-1.1808113263297E-5,299.9840698,299.9840698,-42449.2265625,-42433.83984375,57.2152076076984,20.5853384656644,23.668306,0,0,0,40,4449,300.2253,-42441.533203125,,,,,,,,,,,,,0,,,,0,,,,,,299.9840698,,,,
,33033249.23,299.9880981,-39132.845703125,6.40606619002927E-5,1.28555940375839E-6,1,0.999253354069792,40.0298881530762,1.99973993555272,19.1399995237589,0.000741851537956211,3.03562525961623E-5,0.25,-8.41781739038829E-6,6.40643491748613E-5,-8.375385897132E-6,299.9880981,299.9880981,-39140.63671875,-39125.0546875,56.9486722826406,20.5838884050456,23.668306,0,0,0,40,4449,300.2261,-39132.845703125,,,,,,,,,,,,,0,,,,0,,,,,,299.9880981,,,,
,33033315.835,299.9819031,-35802.693359375,5.35402949124184E-5,1.21996208829644E-6,1,0.999253354069792,40.0298881530762,1.99987225888128,19.1399995237589,0.000624785471342937,-1.90074094089518E-6,0.25,-9.44401172044814E-6,5.35449770781015E-5,-9.40845381379422E-6,299.9819031,299.9819031,-35807.703125,-35797.68359375,56.7946914643522,20.5816748447202,23.668306,0,0,0,40,4449,300.2241,-35802.693359375,,,,,,,,,,,,,0,,,,0,,,,,,299.9819031,,,,
,33033382.23,299.9916382,-32487.4052734375,4.12667800252365E-5,1.07017611974575E-6,1,0.999253354069792,40.0298881530762,1.99985444413951,19.1399995237589,0.000483759944478384,-1.41849738086507E-5,0.25,-8.40244156123969E-6,4.12711168336268E-5,-8.37498129367458E-6,299.9916382,299.9916382,-32495.20703125,-32479.603515625,56.8540952318137,20.5827055917196,24.047956,0,0,0,40,4449,300.2415,-32487.4052734375,,,,,,,,,,,,,0,,,,0.00245,,,,,,299.9916382,,,,
,33033446.715,299.9873047,-29263.7275390625,2.82141073634487E-5,8.81700326858339E-7,1,0.999253354069792,40.0298881530762,1.99980627166135,19.1399995237589,0.000331866923321467,-1.62067079880471E-5,0.25,-6.31958069569183E-6,2.82174576673566E-5,-6.30077709332366E-6,299.9873047,299.9873047,-29271.34375,-29256.111328125,56.861911517006,20.5812647521979,24.047956,0,0,0,40,4449,300.24155,-29263.7275390625,,,,,,,,,,,,,0,,,,0.00245,,,,,,299.9873047,,,,
,33033510.5,299.9929504,-26075.08984375,1.74442722603639E-5,8.92563208071307E-7,1,0.999253354069792,40.0298881530762,1.99986506143859,19.1399995237589,0.000211376947872537,-4.57127093098142E-5,0.25,-7.05937246312867E-6,1.7448422786443E-5,-7.04764551922337E-6,299.9929504,299.9929504,-26082.708984375,-26067.470703125,57.0471574760637,20.582242958404,23.668306,0,0,0,40,4449,300.2437,-26075.08984375,,,,,,,,,,,,,0,,,,0,,,,,,299.9929504,,,,
,33033577.69,299.9904175,-22717.2958984375,4.62655388674523E-6,5.69561155546334E-7,1,0.999253354069792,40.0298881530762,1.99983023747021,19.1399995237589,6.47194763903634E-5,-6.21024835368714E-5,0.25,-6.28613971159783E-6,4.63057256406861E-6,-6.28289838028125E-6,299.9904175,299.9904175,-22719.892578125,-22714.69921875,57.0932735586983,20.5818788512069,23.668306,0,0,0,40,4449,300.24955,-22717.2958984375,,,,,,,,,,,,,0,,,,0.00245,,,,,,299.9904175,,,,
,33033642.795,299.9883423,-19463.9228515625,-5.28864268651908E-6,8.77975143334177E-7,1,0.999253354069792,40.0298881530762,1.99985706730746,19.1399995237589,-4.89800176957613E-5,-7.33157353643654E-5,0.25,-5.55846769133296E-6,-5.2848125495671E-6,-5.56180236192895E-6,299.9883423,299.9883423,-19466.572265625,-19461.2734375,56.8204852054868,20.5831388697062,24.047956,0,0,0,40,4449,300.25255,-19463.9228515625,,,,,,,,,,,,,0,,,,0.0049,,,,,,299.9883423,,,,
,33033708.1,299.9897156,-16198.17578125,-1.44566608269303E-5,9.89665172220962E-7,1,0.999253354069792,40.0298881530762,1.99989612936627,19.1399995237589,-0.00015401410437667,-8.42677527771094E-5,0.25,-4.9371041620672E-6,-1.44529704123105E-5,-4.94652470434861E-6,299.9897156,299.9897156,-16208.173828125,-16188.177734375,56.933039712256,20.5796779005208,23.668306,0,0,0,40,4449,300.2609,-16198.17578125,,,,,,,,,,,,,0,,,,-0.00245,,,,,,299.9897156,,,,
,33033773.885,299.99133305,-12912.2143554687,-2.56024684337277E-5,5.54967459790843E-7,1,0.999253354069792,40.0298881530762,1.99988131585546,19.1399995237589,-0.000283175613881933,-8.90850230711341E-5,0.25,-3.43147025037648E-6,-2.55994438178071E-5,-3.44831905279126E-6,299.9905396,299.9921265,-12919.751953125,-12904.6767578125,56.8564401173714,20.5813457505732,23.288654,0,0,0,40,4449,300.2694,-12912.2143554687,,,,,,,,,,,,,0,,,,-0.0049,,,,,,299.99133305,,,,
,33033839.825,299.9831543,-9614.0732421875,-3.4343029150456E-5,7.41572589648745E-7,1,0.999253354069792,40.0298881530762,1.99982913595987,19.1399995237589,-0.000383333784224541,-9.93361989169394E-5,0.25,-2.82260372587038E-6,-3.43401586013453E-5,-2.84526985822984E-6,299.9831543,299.9831543,-9621.5185546875,-9606.6279296875,56.7548284098714,20.5827954710464,23.668306,0,0,0,40,4449,300.28225,-9614.0732421875,,,,,,,,,,,,,0,,,,0,,,,,,299.9831543,,,,
,33033903.725,299.9863281,-6420.1416015625,-4.22271866174814E-5,5.27037882544092E-7,1,0.999253354069792,40.0298881530762,1.99977311703402,19.1399995237589,-0.000474584474877886,-0.000103315423411615,0.25,-1.80825742087306E-6,-4.22247514439028E-5,-1.83618970819313E-6,299.9863281,299.9863281,-6422.62158203125,-6417.66162109375,56.8986480574099,20.580085502244,23.668306,0,0,0,40,4449,300.2849,-6420.1416015625,,,,,,,,,,,,,0,,,,-0.0049,,,,,,299.9863281,,,,
,33033967.06,299.9908142,-3253.55541992188,-4.35868876355667E-5,3.82377178825528E-7,1,0.999253354069792,40.0298881530762,1.99974367830759,19.1399995237589,-0.000490792854493975,-0.00010125044060364,0.25,-1.39041737108345E-6,-4.35846808928619E-5,-1.41927616140878E-6,299.9908142,299.9908142,-3258.84619140625,-3248.2646484375,56.9830639374868,20.57763494075,23.288654,0,0,0,40,4449,300.28705,-3253.55541992188,,,,,,,,,,,,,0,,,,0,,,,,,299.9908142,,,,
,33034030.455,299.9950256,-86.2220153808594,-1.69173774400541E-5,4.58288673653861E-7,1,0.999253354069792,40.0298881530762,1.99976606582489,19.1399995237589,-0.00019079104067399,-3.758095244981E-5,0.25,-3.87947361442944E-7,-1.69166184577271E-5,-3.99157264443665E-7,299.9950256,299.9950256,-93.7207412719727,-78.7232894897461,56.9033378285253,20.5782259342935,23.668306,0,0,0,40,4449,300.2784,-86.2220153808594,,,,,,,,,,,,,0,,,,0,,,,,,299.9950256,,,,
,33034052.915,299.9932251,-0.334923014044762,-3.30607230704771E-6,3.37914559927342E-7,1,0.999253354069792,40.0298881530762,1.9997831366323,19.1399995237589,-3.73835320106432E-5,-6.77893174896913E-6,0.25,-2.58827360047895E-8,-3.30595732300067E-6,-2.80748492477514E-8,299.9930115,299.9934387,-0.350146800279617,-0.319699227809906,56.9072459711214,20.5766231473563,24.047956,0,0,0,40,4417,300.2866,-0.334923014044762,,,,,,,,,,,,,0,,,,0,,,,,,299.9932251,,,,