File: data/doubleLayers/dl_2-5/ppms/data/DD205_5_HYST_INIT_300K.DAT
[Header]
; VSM Data File (default extension .dat)
; Copyright (c) 2003-2013, Quantum Design, Inc. All rights reserved.
TITLE,
FILEOPENTIME,23076195.75,09/25/2018,11:01 am
BYAPP,VSM,2.0,2.0
INFO,PPMS VSM Option Release 1.4.10 Build 1,APPNAME
INFO,Quantum Design Linear Motor Servo Controller,MOTOR_MODULE_NAME
INFO,3101-100 M1,MOTOR_HW_VERSION
INFO,MMC1014,MOTOR_SERIAL_NUMBER
INFO,SRV No X-over 01.03.11,MOTOR_SOFTWARE_VERSION
INFO,Quantum Design VSM Detection Module,VSM_MODULE_NAME
INFO,3101-150 F0,VSM_HW_VERSION
INFO,VSM707,VSM_SERIAL_NUMBER
INFO,VSM No X-over 01.02.05 May 20 2008 13:51:47,VSM_SOFTWARE_VERSION
INFO,704,PREAMP_SERIAL_NUMBER
INFO,822,COIL_SERIAL_NUMBER
INFO,0,MOMENT_UNITS
INFO,,SAMPLE_MATERIAL
INFO,,SAMPLE_COMMENT
INFO,,SAMPLE_MASS
INFO,,SAMPLE_VOLUME
INFO,,SAMPLE_MOLECULAR_WEIGHT
INFO,,SAMPLE_SIZE
INFO,,SAMPLE_SHAPE
DATATYPE,COMMENT,1
DATATYPE,TIME,2
STARTUPAXIS,X,2
STARTUPAXIS,Y1,5
[Data]
Comment,Time Stamp (sec),Temperature (K),Magnetic Field (Oe),Moment (emu),M. Std. Err. (emu),Transport Action,Averaging Time (sec),Frequency (Hz),Peak Amplitude (mm),Center Position (mm),Coil Signal' (mV),Coil Signal" (mV),Range (mV),M. Quad. Signal (emu),M. Raw' (emu),M. Raw" (emu),Min. Temperature (K),Max. Temperature (K),Min. Field (Oe),Max. Field (Oe),Mass (grams),Motor Lag (deg),Pressure (Torr),VSM Status (code),Motor Status (code),Measure Status (code),Measure Count,PPMS Status (code),System Temp. (K),System Field (Oe),Sample Position (deg),Bridge 1 Resistance (ohms),Bridge 1 Excitation (에),Bridge 2 Resistance (ohms),Bridge 2 Excitation (에),Bridge 3 Resistance (ohms),Bridge 3 Excitation (에),Bridge 4 Resistance (ohms),Bridge 4 Excitation (에),Signal 1 Vin (V),Signal 2 Vin (V),Digital Inputs (code),Drive 1 Iout (mA),Drive 1 Ipower (W),Drive 2 Iout (mA),Drive 2 Ipower (W),Pressure (),Map 20 (),Map 21 (),Map 22 (),Map 23 (),Map 24 (),Map 25 (),Map 26 (),Map 27 (),Map 28 (),Map 29 ()
,23076211.94,300.0044861,-0.411041855812073,,,2,,,,15.7700000107288,,,,,,,300.0044861,300.0044861,-0.411041855812073,-0.411041855812073,,,25.946213,,,,-99999999,4369,300.7464,-0.411041855812073,,,,,,,,,,,,,,,,,,,,,,,300.0044861,,,,
,23076346.68,300.0114136,3698.17236328125,4.6711041497934E-5,4.65988390534964E-7,1,0.999253354069792,40.0298881530762,1.97335682881772,15.760000795126,0.000522884707909393,8.66820584208659E-5,0.25,-3.39722674729217E-7,4.67098599990672E-5,-3.08798703897418E-7,300.0114136,300.0114136,3693.01879882812,3703.32592773438,55.687123852602,20.4842524056981,25.566563,0,0,0,40,4449,300.7422,3698.17236328125,,,,,,,,,,,,,0,,,,0.00245,,,,,,300.0114136,,,,
,23076426.67,300.0097046,7696.75732421875,4.25308688586432E-5,5.57750161286356E-7,1,0.999253354069792,40.0298881530762,1.97334617020382,15.760000795126,0.00047598257097915,7.95406280005399E-5,0.25,-2.54192135309998E-7,4.25297605915505E-5,-2.26053594770158E-7,300.0097046,300.0097046,7686.71142578125,7706.80322265625,56.0591790277559,20.4899510447226,25.946213,0,0,0,40,4449,300.7336,7696.75732421875,,,,,,,,,,,,,0,,,,0,,,,,,300.0097046,,,,
,23076506.105,300.0115356,11667.7465820312,3.30486587642214E-5,6.89389305076651E-7,1,0.999253354069792,40.0298881530762,1.97329822440223,15.760000795126,0.000369063365540229,6.63700880680392E-5,0.25,2.10771451544148E-7,3.30475266986383E-5,2.3261032818206E-7,300.0115356,300.0115356,11660.095703125,11675.3974609375,56.2608391857175,20.4957867478002,26.325863,0,0,0,40,4449,300.72285,11667.7465820312,,,,,,,,,,,,,0,,,,0,,,,,,300.0115356,,,,
,23076587.025,300.0161438,15710.7006835938,2.09766183855849E-5,7.73315923638508E-7,1,0.999253354069792,40.0298881530762,1.97322169701397,15.760000795126,0.000234589395561335,4.01248625134138E-5,0.25,-4.51073538350039E-8,2.09760154995408E-5,-3.1250520054088E-8,300.0161438,300.0161438,15702.9873046875,15718.4140625,56.2819431557367,20.5007654983319,25.946213,0,0,0,40,4449,300.7193,15710.7006835938,,,,,,,,,,,,,0,,,,0.00245,,,,,,300.0161438,,,,
,23076666.16,300.0126038,19666.193359375,8.80606570732472E-6,9.23889255752805E-7,1,0.999253354069792,40.0298881530762,1.97309822054658,15.760000795126,9.77006080165571E-5,2.13170151701807E-5,0.25,3.81249482294515E-7,8.80554995598462E-6,3.87050469548699E-7,300.0126038,300.0126038,19660.958984375,19671.427734375,56.292885955006,20.503274009108,25.946213,0,0,0,40,4449,300.7069,19666.193359375,,,,,,,,,,,,,0,,,,-0.0049,,,,,,300.0126038,,,,
,23076746.305,300.0168152,23671.4609375,-4.70285099779805E-6,1.04564803244377E-6,1,0.999253354069792,40.0298881530762,1.97308995571328,15.760000795126,-5.24140083174859E-5,-1.00132766668213E-5,0.25,-8.09647759707212E-8,-4.7026560445191E-6,-8.40641500462775E-8,300.0168152,300.0168152,23668.884765625,23674.037109375,56.6117903908521,20.5070891624309,25.946213,0,0,0,40,4449,300.69,23671.4609375,,,,,,,,,,,,,0,,,,-0.00245,,,,,,300.0168152,,,,
,23076827.235,300.0161438,27717.791015625,-1.87839026655775E-5,1.16385880907202E-6,1,0.999253354069792,40.0298881530762,1.97299284398366,15.760000795126,-0.000208276844755096,-4.61272369689604E-5,0.25,-8.7220378163501E-7,-1.87827638136864E-5,-8.84556797346558E-7,300.0161438,300.0161438,27712.876953125,27722.705078125,56.6969878994483,20.5101324764065,25.946213,0,0,0,40,4449,300.6793,27717.791015625,,,,,,,,,,,,,0,,,,-0.0049,,,,,,300.0161438,,,,
,23076907.46,300.0170288,31728.15625,-3.26226925448847E-5,1.61314798986287E-6,1,0.999253354069792,40.0298881530762,1.97296967723734,15.760000795126,-0.00036330491811274,-7.0950458628885E-5,0.25,-6.95372279640447E-7,-3.26212556161019E-5,-7.16833035787857E-7,300.0170288,300.0170288,31720.568359375,31735.744140625,56.384336491756,20.5105966819976,26.325863,0,0,0,40,4449,300.6717,31728.15625,,,,,,,,,,,,,0,,,,0.00245,,,,,,300.0170288,,,,
,23076988.065,300.014801,35756.009765625,-4.6023230211438E-5,1.74941313435164E-6,1,0.999253354069792,40.0298881530762,1.97299039007522,15.760000795126,-0.000519144813859213,-6.20095884959357E-5,0.25,2.4262419495419E-6,-4.60234512714218E-5,2.39588891209415E-6,300.014801,300.014801,35753.70703125,35758.3125,56.421854660679,20.5100704269806,26.325863,0,0,0,40,4449,300.6584,35756.009765625,,,,,,,,,,,,,0,,,,0,,,,,,300.014801,,,,
,23077067.985,300.015625,39751.14453125,-6.04240891921896E-5,1.79393486781492E-6,1,0.999253354069792,40.0298881530762,1.97292994914712,15.760000795126,-0.000677350563547331,-0.000105749336130452,0.25,1.00791107649901E-6,-6.04229473431742E-5,9.68158308480708E-7,300.015625,300.015625,39746.29296875,39755.99609375,56.3022654972367,20.5108028194112,25.566563,0,0,0,40,4449,300.6404,39751.14453125,,,,,,,,,,,,,0,,,,0,,,,,,300.015625,,,,
,23077149.075,300.0194397,43804.06640625,-7.29197012472504E-5,1.67273308071794E-6,1,0.999253354069792,40.0298881530762,1.97291949619679,15.760000795126,-0.000816411005030009,-0.000133449595194901,0.25,6.94534497048002E-7,-7.29179736237992E-5,6.46618925775855E-7,300.0192871,300.0195923,43799.30859375,43808.82421875,56.8228300910445,20.5130048043341,25.946213,0,0,0,40,4449,300.63035,43804.06640625,,,,,,,,,,,,,0,,,,0.0049,,,,,,300.0194397,,,,
,23077227.165,300.01760865,47705.24609375,-8.7312138972527E-5,2.40696113502919E-6,1,0.999253354069792,40.0298881530762,1.97290099612648,15.760000795126,-0.000975834168202597,-0.000169636341976305,0.25,-4.95532812137305E-8,-8.73095018573534E-5,-1.06849407942327E-7,300.0174561,300.0177612,47697.6171875,47712.875,56.6821369575829,20.5127049602177,26.705515,0,0,0,40,4449,300.62305,47705.24609375,,,,,,,,,,,,,0,,,,0,,,,,,300.01760865,,,,
,23077307.195,300.0209045,51705.58984375,-0.000100461050103554,2.28063010253734E-6,1,0.999253354069792,40.0298881530762,1.97283435863784,15.760000795126,-0.00112190375384278,-0.000200090842570004,0.25,-4.96738905262146E-7,-0.000100457721104828,-5.62589730700022E-7,300.0209045,300.0209045,51700.59375,51710.5859375,56.3499448369098,20.5135491708189,26.325863,0,0,0,40,4449,300.61725,51705.58984375,,,,,,,,,,,,,0,,,,0,,,,,,300.0209045,,,,
,23077387.75,300.0175171,55731.166015625,-0.000115228005107047,2.11242056871118E-6,1,0.999253354069792,40.0298881530762,1.97286021258093,15.760000795126,-0.00128907122665523,-0.00021657387376017,0.25,5.87131549670585E-7,-0.000115224965079533,5.11635687706811E-7,300.0175171,300.0175171,55723.76953125,55738.5625,56.6258597041983,20.5138171632127,25.946213,0,0,0,40,4449,300.6042,55731.166015625,,,,,,,,,,,,,0,,,,0,,,,,,300.0175171,,,,
,23077468.245,300.0208435,59754.380859375,-0.000129052437856903,1.87922680271584E-6,1,0.999253354069792,40.0298881530762,1.9728428067732,15.760000795126,-0.00144036108699825,-0.000261912372700956,0.25,-1.07435295731804E-6,-0.000129047890436534,-1.158780571023E-6,300.0208435,300.0208435,59746.88671875,59761.875,56.3960609195444,20.5157954255065,26.325863,0,0,0,40,4449,300.579,59754.380859375,,,,,,,,,,,,,0,,,,-0.0049,,,,,,300.0208435,,,,
,23077548.805,300.0211182,63782.607421875,-0.000146332078373243,1.90824765258641E-6,1,0.999253354069792,40.0298881530762,1.97275039579335,15.760000795126,-0.00163761159903209,-0.00027119854431261,0.25,1.08736404869518E-6,-0.000146328437104169,9.91656283881805E-7,300.0211182,300.0211182,63779.8515625,63785.36328125,56.5609845371021,20.5165557736113,26.705515,0,0,0,40,4449,300.57415,63782.607421875,,,,,,,,,,,,,0,,,,0.0049,,,,,,300.0211182,,,,
,23077628.08,300.0163574,67745.74609375,-0.000158284019656377,3.47632797894655E-6,1,0.999253354069792,40.0298881530762,1.97283503449385,15.760000795126,-0.00176718367978126,-0.000317926496881604,0.25,-1.02173109527219E-6,-0.000158278680376205,-1.12509244873061E-6,300.0163574,300.0163574,67743.2421875,67748.25,56.4382688595829,20.5169999575972,25.566563,0,0,0,40,4449,300.5652,67745.74609375,,,,,,,,,,,,,0,,,,0,,,,,,300.0163574,,,,
,23077710.525,300.0183105,71866.2421875,-0.000175809728534175,3.24237323488542E-6,1,0.999253354069792,40.0298881530762,1.97286811625187,15.760000795126,-0.00196446534562596,-0.000344002421506459,0.25,-3.17997678297228E-7,-0.000175804329271088,-4.32717620639371E-7,300.0183105,300.0183105,71856.140625,71876.34375,56.3429101802367,20.5175719494668,26.325863,0,0,0,40,4449,300.54505,71866.2421875,,,,,,,,,,,,,0,,,,-0.00245,,,,,,300.0183105,,,,
,23077792.765,300.0159607,75977.24609375,-0.000187846449537938,3.72396056335432E-6,1,0.999253354069792,40.0298881530762,1.97285728133232,15.760000795126,-0.00210072507607461,-0.000357310775074067,0.25,5.76404946159534E-7,-0.000187841305036004,4.53928727300703E-7,300.0159607,300.0159607,75964.609375,75989.8828125,56.6594697305252,20.5176102327297,25.946213,0,0,0,40,4449,300.53855,75977.24609375,,,,,,,,,,,,,0,,,,-0.0049,,,,,,300.0159607,,,,
,23077871.12,300.0133667,79892.85546875,-0.000201958551121698,3.44769184708216E-6,1,0.999253354069792,40.0298881530762,1.9728171448369,15.760000795126,-0.00225903914577432,-0.000381034474908518,0.25,8.98017879551587E-7,-0.000201953231157738,7.66460579606413E-7,300.0133667,300.0133667,79888.03125,79897.6796875,56.5476968522752,20.5177156168773,25.946213,0,0,0,40,4449,300.5304,79892.85546875,,,,,,,,,,,,,0,,,,0,,,,,,300.0133667,,,,
,23077948.15,300.0162354,83741.5703125,-0.000217957292029657,3.90694254140536E-6,1,0.999253354069792,40.0298881530762,1.97280230474496,15.760000795126,-0.00244309690207869,-0.000381668930821642,0.25,3.61261323220615E-6,-0.000217953259491372,3.47069175016475E-6,300.0162354,300.0162354,83736.578125,83746.5625,56.5500417378329,20.5180950170306,26.705515,0,0,0,40,4449,300.5187,83741.5703125,,,,,,,,,,,,,0,,,,0,,,,,,300.0162354,,,,
,23078021.905,300.0191956,87430.16796875,-0.000228548587477374,3.92431415746887E-6,1,0.999253354069792,40.0298881530762,1.97274880711957,15.760000795126,-0.00255328444236008,-0.000449062532984861,0.25,-5.83340506979057E-7,-0.000228541502401404,-7.31897559317904E-7,300.0191956,300.0191956,87425.1796875,87435.15625,56.5023623981598,20.5176672826409,25.946213,0,0,0,40,4449,300.50075,87430.16796875,,,,,,,,,,,,,0,,,,0,,,,,,300.0191956,,,,
,23078114.76,300.0201721,88889.84375,-0.000239645429472191,3.85492990875283E-6,1,0.999253354069792,40.0298881530762,1.97278175977595,15.760000795126,-0.00267880100397718,-0.000462198928715979,0.25,1.64413274186747E-7,-0.000239638501114127,8.67321020213158E-9,300.0201721,300.0201721,88877.359375,88902.328125,56.8322096332752,20.5203034835356,25.946213,0,0,0,40,4449,300.4892,88889.84375,,,,,,,,,,,,,0,,,,0,,,,,,300.0201721,,,,
,23078190.135,300.012207,85121.54296875,-0.000219751250892682,3.29736015974964E-6,1,0.999253354069792,40.0298881530762,1.97270886298688,15.760000795126,-0.00245264958698964,-0.000445081219899456,0.25,-1.75189360646266E-6,-0.000219743709892786,-1.89479713034053E-6,300.012207,300.012207,85114.171875,85128.9140625,56.6915164998137,20.5217484512921,26.325863,0,0,0,40,4449,300.47705,85121.54296875,,,,,,,,,,,,,0,,,,0,,,,,,300.012207,,,,
,23078267.58,300.004303,81250.3125,-0.000212136123852087,3.0838129945638E-6,1,0.999253354069792,40.0298881530762,1.97281723463453,15.760000795126,-0.00236838831336759,-0.000426179698622924,0.25,-1.37785359430387E-6,-0.000212129095443385,-1.5159492724566E-6,300.004303,300.004303,81240.4375,81260.1875,56.5836517641598,20.5212486802658,26.705515,0,0,0,40,4449,300.48465,81250.3125,,,,,,,,,,,,,0,,,,-0.0049,,,,,,300.004303,,,,
,23078346.58,299.9984741,77301.13671875,-0.00019303261806904,2.80332023236067E-6,1,0.999253354069792,40.0298881530762,1.97282489945375,15.760000795126,-0.00215749913825699,-0.000374046982635562,0.25,-2.29662768575704E-8,-0.000193027053216507,-1.48788548920326E-7,299.9984741,299.9984741,77291.0390625,77311.234375,56.8095424062176,20.5220211504926,25.946213,0,0,0,40,4449,300.4866,77301.13671875,,,,,,,,,,,,,0,,,,-0.0049,,,,,,299.9984741,,,,
,23078428.125,299.9937744,73224.71875,-0.000179365223745157,2.8834805727488E-6,1,0.999253354069792,40.0298881530762,1.97276143754079,15.760000795126,-0.00199788625571584,-0.000386761123360805,0.25,-3.52927570954436E-6,-0.000179357783761239,-3.64620775981056E-6,299.9937744,299.9937744,73222.078125,73227.359375,56.6954246424098,20.5230327145865,25.946213,0,0,0,40,4449,300.49265,73224.71875,,,,,,,,,,,,,0,,,,0.0049,,,,,,299.9937744,,,,
,23078510.58,299.989624,69100.953125,-0.000169012653896155,2.68834946838509E-6,1,0.999253354069792,40.0298881530762,1.97277003111013,15.760000795126,-0.00188111971461231,-0.000372871926471647,0.25,-4.07990398654577E-6,-0.000169005163527579,-4.19017930651692E-6,299.989624,299.989624,69093.703125,69108.203125,56.6907348712945,20.5245289445386,26.325863,0,0,0,40,4449,300.49575,69100.953125,,,,,,,,,,,,,0,,,,-0.00245,,,,,,299.989624,,,,
,23078588.695,299.98976135,65197.53125,-0.000151047237771689,2.06111379502529E-6,1,0.999253354069792,40.0298881530762,1.97284428541306,15.760000795126,-0.0016862224314019,-0.000304398427269043,0.25,-1.06493335445293E-6,-0.000151042219947727,-1.16365329739775E-6,299.9893494,299.9901733,65190.44921875,65204.61328125,56.5711457078521,20.525292733171,26.705515,0,0,0,40,4449,300.50465,65197.53125,,,,,,,,,,,,,0,,,,-0.00245,,,,,,299.98976135,,,,
,23078670.13,299.9862366,61126.6171875,-0.000136485746046266,2.98056397643898E-6,1,0.999253354069792,40.0298881530762,1.97277352287965,15.760000795126,-0.00152090649931607,-0.000290662495658852,0.25,-2.3595915252531E-6,-0.000136480306451099,-2.44884193399626E-6,299.9862366,299.9862366,61116.76953125,61136.46484375,56.5938129349098,20.5243357089285,26.325863,0,0,0,40,4449,300.512,61126.6171875,,,,,,,,,,,,,0,,,,0,,,,,,299.9862366,,,,
,23078751.695,299.9858704,57050.5859375,-0.000122829892513602,1.94698636579006E-6,1,0.999253354069792,40.0298881530762,1.97280250119367,15.760000795126,-0.00136966044543401,-0.00025635180329403,0.25,-1.65527113597538E-6,-0.000122825297412488,-1.73568108738661E-6,299.9858704,299.9858704,57043.109375,57058.0625,56.6915164998137,20.5270576126815,26.325863,0,0,0,40,4449,300.52455,57050.5859375,,,,,,,,,,,,,0,,,,0,,,,,,299.9858704,,,,
,23078830.795,299.9900818,53095.318359375,-0.000105509527147009,2.21003748724727E-6,1,0.999253354069792,40.0298881530762,1.9727885605313,15.760000795126,-0.00117835029673908,-0.000209608988690535,0.25,-4.74048912976255E-7,-0.00010550617887398,-5.43211462998252E-7,299.9900818,299.9900818,53090.35546875,53100.28125,56.8329912617945,20.5267859104757,26.325863,0,0,0,40,4449,300.5303,53095.318359375,,,,,,,,,,,,,0,,,,-0.00245,,,,,,299.9900818,,,,
,23078911.5,299.9871826,49062.55078125,-9.14662760535561E-5,1.62864207431937E-6,1,0.999253354069792,40.0298881530762,1.97281391802348,15.760000795126,-0.0010219317227902,-0.000179366126302599,0.25,-2.00978125717505E-7,-9.14635155869826E-5,-2.60996440597414E-7,299.9871826,299.9871826,49052.49609375,49072.60546875,56.6821369575829,20.5272421531415,26.705515,0,0,0,40,4449,300.5399,49062.55078125,,,,,,,,,,,,,0,,,,0,,,,,,299.9871826,,,,
,23078992.75,299.9912415,45002.0703125,-7.94219765107472E-5,2.1032549895269E-6,1,0.999253354069792,40.0298881530762,1.97273649850518,15.760000795126,-0.000889165897591359,-0.000145144973624854,0.25,7.73613979968899E-7,-7.94201863565937E-5,7.21423575783807E-7,299.9912415,299.9912415,44994.375,45009.765625,56.5883415352752,20.5287606376689,26.325863,0,0,0,40,4449,300.5476,45002.0703125,,,,,,,,,,,,,0,,,,0,,,,,,299.9912415,,,,
,23079071.07,299.9918823,41088.529296875,-6.64720422662328E-5,1.67735983499991E-6,1,0.999253354069792,40.0298881530762,1.97281616379352,15.760000795126,-0.000741586922908962,-0.000136646918208581,0.25,-7.09150787242015E-7,-6.64696474700526E-5,-7.52831198227296E-7,299.9915161,299.9922485,41086.46875,41090.58984375,56.8681645451599,20.5289367920271,26.325863,0,0,0,40,4449,300.5488,41088.529296875,,,,,,,,,,,,,0,,,,0,,,,,,299.9918823,,,,
,23079152.61,299.9936523,37013.1171875,-5.04306222256793E-5,2.01729758446118E-6,1,0.999253354069792,40.0298881530762,1.97284485820708,15.760000795126,-0.00056385813636589,-9.65867944506386E-5,0.25,9.59067473098701E-8,-5.04292163232124E-5,6.27195654099218E-8,299.9936523,299.9936523,37003.12109375,37023.11328125,56.6751023009098,20.5292864759323,26.705515,0,0,0,40,4449,300.55585,37013.1171875,,,,,,,,,,,,,0,,,,0,,,,,,299.9936523,,,,
,23079233.965,299.9938965,32945.134765625,-3.63977086963094E-5,1.85924722222679E-6,1,0.999253354069792,40.0298881530762,1.97294274681622,15.760000795126,-0.000411455905792125,-4.38636901919755E-5,0.25,2.38187831038749E-6,-3.63982149419802E-5,2.35783673973696E-6,299.9938965,299.9938965,32939.51953125,32950.75,56.668849272756,20.5289409624201,26.705515,0,0,0,40,4449,300.5551,32945.134765625,,,,,,,,,,,,,0,,,,0,,,,,,299.9938965,,,,
,23079315.34,299.999115,28877.5947265625,-2.22580385194023E-5,1.08233866408305E-6,1,0.999253354069792,40.0298881530762,1.97285795179126,15.760000795126,-0.000249499872220739,-3.8969428388863E-5,0.25,3.69836753675953E-7,-2.22576272247349E-5,3.55153208570929E-7,299.999115,299.999115,28867.501953125,28887.6875,56.9611783389483,20.5311311498035,26.705515,0,0,0,40,4449,300.54915,28877.5947265625,,,,,,,,,,,,,0,,,,-0.00245,,,,,,299.999115,,,,
,23079397.26,299.9910889,24781.7509765625,-7.89277580065071E-6,1.58530700729416E-6,1,0.999253354069792,40.0298881530762,1.97293661223531,15.760000795126,-8.72582516502805E-5,-2.08529796294485E-5,0.25,-4.9811868533125E-7,-7.89221677247893E-6,-5.03311323595151E-7,299.9910889,299.9910889,24774.357421875,24789.14453125,56.8103240347368,20.5304198199313,26.325863,0,0,0,40,4449,300.5624,24781.7509765625,,,,,,,,,,,,,0,,,,-0.0049,,,,,,299.9910889,,,,
,23079478.7,299.9940796,20713.97265625,5.26175311449448E-6,1.30392424363922E-6,1,0.999253354069792,40.0298881530762,1.97298214372936,15.760000795126,5.88842591924373E-5,9.79312719587076E-6,0.25,-3.5521040914335E-8,5.26162215526853E-6,-3.20458150884373E-8,299.9933472,299.994812,20706.36328125,20721.58203125,56.7626446950637,20.5310188624229,26.325863,0,0,0,40,4449,300.56785,20713.97265625,,,,,,,,,,,,,0,,,,0,,,,,,299.9940796,,,,
,23079559.325,299.9932251,16683.732421875,1.85462718373744E-5,9.05816627572097E-7,1,0.999253354069792,40.0298881530762,1.97300252114217,15.760000795126,0.000206977340593719,3.78428240838178E-5,0.25,1.72186942152156E-7,1.85456135158457E-5,1.8443691675347E-7,299.9932251,299.9932251,16673.517578125,16693.947265625,56.9557069393137,20.5301115266746,25.946213,0,0,0,40,4449,300.57175,16683.732421875,,,,,,,,,,,,,0,,,,0.00245,,,,,,299.9932251,,,,
,23079638.79,299.9979553,12713.3754882812,3.07361784833361E-5,5.95537947942713E-7,1,0.999253354069792,40.0298881530762,1.97302381927181,15.760000795126,0.000343233107944153,6.14909443231429E-5,0.25,1.75715086162262E-7,3.07351532787446E-5,1.96034610566832E-7,299.9979553,299.9979553,12710.7080078125,12716.04296875,56.719655126506,20.5296802988436,25.946213,0,0,0,40,4449,300.5743,12713.3754882812,,,,,,,,,,,,,0,,,,0.00245,,,,,,299.9979553,,,,
,23079718.555,300.0009766,8724.86328125,4.0605030010555E-5,6.88277385201461E-7,1,0.999253354069792,40.0298881530762,1.97302484851892,15.760000795126,0.000455323180851797,7.0362183071199E-5,0.25,-7.40538182623196E-7,4.06043130496653E-5,-7.13646458723661E-7,300.0009766,300.0009766,8717.1494140625,8732.5771484375,56.7329428113329,20.5317244023464,26.325863,0,0,0,40,4449,300.5712,8724.86328125,,,,,,,,,,,,,0,,,,0,,,,,,300.0009766,,,,
,23079798.095,299.9976501,4752.41162109375,4.65938205191052E-5,4.63194965657445E-7,1,0.999253354069792,40.0298881530762,1.97299289345076,15.760000795126,0.000520948542542321,8.95214077920377E-5,0.25,-6.40527194846859E-8,4.65924817090513E-5,-3.31984236052259E-8,299.9976501,299.9976501,4749.90771484375,4754.91552734375,56.5594212800637,20.5335007138112,25.946213,0,0,0,40,4449,300.5698,4752.41162109375,,,,,,,,,,,,,0,,,,0,,,,,,299.9976501,,,,
,23079876.94,299.9940491,808.296112060547,3.86321709609722E-5,3.72521209135505E-7,1,0.999253354069792,40.0298881530762,1.97301691755249,15.760000795126,0.000431763776097861,7.52270282708795E-5,0.25,3.64822537987667E-8,3.86310054636645E-5,6.20741348603235E-8,299.9940491,299.9940491,805.791809082031,810.800415039063,56.9619599674676,20.5326294611356,26.705515,0,0,0,40,4449,300.5786,808.296112060547,,,,,,,,,,,,,0,,,,0.00245,,,,,,299.9940491,,,,
,23079954.735,299.9972229,-3074.62243652344,-4.51988014638374E-5,4.82818991927312E-7,1,0.999253354069792,40.0298881530762,1.97304203310806,15.760000795126,-0.000504022415625874,-9.45828512084497E-5,0.25,-6.30243829867588E-7,-4.51970443165532E-5,-6.60160096733936E-7,299.9972229,299.9972229,-3082.16479492188,-3067.080078125,56.8470605751406,20.5335503006064,26.325863,0,0,0,40,4449,300.5776,-3074.62243652344,,,,,,,,,,,,,0,,,,0.0049,,,,,,299.9972229,,,,
,23080033.045,299.9969788,-6989.76977539063,-4.39900270728523E-5,7.02215271737496E-7,1,0.999253354069792,40.0298881530762,1.9730508495219,15.760000795126,-0.000490612962073805,-9.1662718903972E-5,0.25,-5.78422430324719E-7,-4.39883421930203E-5,-6.07522902879639E-7,299.9969788,299.9969788,-7002.39990234375,-6977.1396484375,56.7642079521022,20.5336614166233,26.325863,0,0,0,40,4449,300.57475,-6989.76977539063,,,,,,,,,,,,,0,,,,-0.00245,,,,,,299.9969788,,,,
,23080111.095,300.0057983,-10893.439453125,-3.37211286304436E-5,7.60926692937608E-7,1,0.999253354069792,40.0298881530762,1.97308199776191,15.760000795126,-0.000375355746259746,-7.4511918027099E-5,0.25,-8.23215977154698E-7,-3.37195766276721E-5,-8.45497376573919E-7,300.0057983,300.0057983,-10900.6923828125,-10886.1865234375,56.8845787440637,20.5326812835998,26.325863,0,0,0,40,4449,300.5721,-10893.439453125,,,,,,,,,,,,,0,,,,-0.0049,,,,,,300.0057983,,,,
,23080192.37,300.0078125,-14954.0766601562,-2.19276930949344E-5,7.33979713737907E-7,1,0.999253354069792,40.0298881530762,1.97309118931653,15.760000795126,-0.000243209537246195,-5.34886729609565E-5,0.25,-9.85819313959743E-7,-2.19263856955331E-5,-1.00028421925798E-6,300.0078125,300.0078125,-14964.16015625,-14943.9931640625,57.0229269919676,20.5350025413325,26.325863,0,0,0,40,4449,300.5675,-14954.0766601562,,,,,,,,,,,,,0,,,,0.00245,,,,,,300.0078125,,,,
,23080272.14,300.0095825,-18939.1181640625,-1.049694893667E-5,1.30723747564466E-6,1,0.999253354069792,40.0298881530762,1.97312971187711,15.760000795126,-0.000116025757368893,-2.79297403818796E-5,0.25,-6.798049136285E-7,-1.04961858005564E-5,-6.86717916460051E-7,300.0094604,300.0097046,-18946.60546875,-18931.630859375,57.0049495360253,20.5355612486695,25.946213,0,0,0,40,4449,300.56475,-18939.1181640625,,,,,,,,,,,,,0,,,,-0.00245,,,,,,300.0095825,,,,
,23080352.625,300.011322,-22962.0380859375,3.05164697868504E-6,1.27168545231867E-6,1,0.999253354069792,40.0298881530762,1.97306705449551,15.760000795126,3.85832551045951E-5,-1.98942952042375E-5,0.25,-2.30843014006034E-6,3.05307916933597E-6,-2.30634693997688E-6,300.011322,300.011322,-22969.6796875,-22954.396484375,56.7126204698329,20.5364868001634,25.946213,0,0,0,40,4449,300.5574,-22962.0380859375,,,,,,,,,,,,,0,,,,0.00245,,,,,,300.011322,,,,
,23080435.11,300.015625,-27085.193359375,1.75748276384956E-5,1.50211443133886E-6,1,0.999253354069792,40.0298881530762,1.97309026077122,15.760000795126,0.000200620709610381,1.00244745864282E-5,0.25,-2.14818023312994E-6,1.75757162140914E-5,-2.13652526649925E-6,300.015625,300.015625,-27092.658203125,-27077.728515625,56.9502355396791,20.5350588483865,26.705515,0,0,0,40,4449,300.53655,-27085.193359375,,,,,,,,,,,,,0,,,,-0.00245,,,,,,300.015625,,,,
,23080515.605,300.0153809,-31107.416015625,2.96129596286822E-5,1.32257667531595E-6,1,0.999253354069792,40.0298881530762,1.97316508478035,15.760000795126,0.000332041409629734,5.15778873118609E-5,0.25,-5.167487559214E-7,2.96124119489527E-5,-4.97219695444836E-7,300.0153809,300.0153809,-31119.79296875,-31095.0390625,56.882233858506,20.5376420231088,26.325863,0,0,0,40,4449,300.52525,-31107.416015625,,,,,,,,,,,,,0,,,,-0.00245,,,,,,300.0153809,,,,
,23080597.79,300.0185852,-35217.68359375,4.33086553565463E-5,1.84916581186063E-6,1,0.999253354069792,40.0298881530762,1.97304468509264,15.760000795126,0.000487332496813808,6.5305970952454E-5,0.25,-1.66120231928928E-6,4.33084472956699E-5,-1.63263830387757E-6,300.0185852,300.0185852,-35222.64453125,-35212.72265625,56.8134505488137,20.5387097314774,26.325863,0,0,0,40,4449,300.5133,-35217.68359375,,,,,,,,,,,,,0,,,,-0.0049,,,,,,300.0185852,,,,
,23080679.885,300.0162048,-39320.162109375,5.80336693740708E-5,1.65540509246279E-6,1,0.999253354069792,40.0298881530762,1.97320784519934,15.760000795126,0.000649998867174477,0.00010528968043198,0.25,-6.36176238043098E-7,5.80323514547168E-5,-5.97982147295491E-7,300.0162048,300.0162048,-39325.1328125,-39315.19140625,56.9729027667368,20.5373450536968,26.705515,0,0,0,40,4449,300.50545,-39320.162109375,,,,,,,,,,,,,0,,,,0.0049,,,,,,300.0162048,,,,
,23080759.165,300.0157776,-43280.76171875,7.16709204305234E-5,1.6763088124986E-6,1,0.999253354069792,40.0298881530762,1.97320901493261,15.760000795126,0.000803513562295098,0.00012557652508618,0.25,-1.18414897443151E-6,7.16695590320935E-5,-1.13700898523611E-6,300.0157776,300.0157776,-43288.4765625,-43273.046875,56.9744660237753,20.5395372425331,26.325863,0,0,0,40,4449,300.4976,-43280.76171875,,,,,,,,,,,,,0,,,,-0.0049,,,,,,300.0157776,,,,
,23080840.145,300.0141907,-47328.712890625,8.42003867523667E-5,2.37120824153804E-6,1,0.999253354069792,40.0298881530762,1.97322899693005,15.760000795126,0.000945529462794759,0.000138660229277644,0.25,-2.18462992746135E-6,8.4199316791542E-5,-2.12927511429818E-6,300.0141907,300.0141907,-47336.484375,-47320.94140625,56.9682129956214,20.5393198551787,26.325863,0,0,0,40,4449,300.48665,-47328.712890625,,,,,,,,,,,,,0,,,,-0.00245,,,,,,300.0141907,,,,
,23080921.485,300.0161438,-51393.775390625,0.000101794728306391,2.61226489635416E-6,1,0.999253354069792,40.0298881530762,1.97318603121726,15.760000795126,0.0011356426347744,0.000210567699156181,0.25,1.19976942720873E-6,0.000101790911632576,1.2665162491504E-6,300.0161438,300.0161438,-51403.7265625,-51383.82421875,56.9603967104291,20.5385748468131,26.325863,0,0,0,40,4449,300.4731,-51393.775390625,,,,,,,,,,,,,0,,,,0,,,,,,300.0161438,,,,
,23081003.565,300.0122375,-55496.37890625,0.000113171957237337,1.96402678813115E-6,1,0.999253354069792,40.0298881530762,1.97326511482229,15.760000795126,0.00127297587621042,0.000174325691129032,0.25,-4.01385575769426E-6,0.000113171242057491,-3.93956160220385E-6,300.0122375,300.0122375,-55506.078125,-55486.6796875,56.8283014906791,20.5391099029689,26.705515,0,0,0,40,4449,300.4668,-55496.37890625,,,,,,,,,,,,,0,,,,0,,,,,,300.0122375,,,,
,23081084.955,300.0134583,-59563.85546875,0.000126691567829707,2.56611552443959E-6,1,0.999253354069792,40.0298881530762,1.97327726247613,15.760000795126,0.0014184369549659,0.000233350732807812,0.25,-1.07642153493723E-6,0.000126688528490988,-9.93432280919629E-7,300.0134583,300.0134583,-59568.77734375,-59558.93359375,56.8392442899483,20.5403176686206,26.705515,0,0,0,40,4449,300.4579,-59563.85546875,,,,,,,,,,,,,0,,,,-0.0049,,,,,,300.0134583,,,,
,23081165.995,300.01501465,-63612.251953125,0.000143756132991087,2.33434038048854E-6,1,0.999253354069792,40.0298881530762,1.97322322753791,15.760000795126,0.00161139589200177,0.000253539734085807,0.25,-2.22630382548983E-6,0.000143753340774472,-2.13219573523633E-6,300.0136414,300.0163879,-63617.09375,-63607.41015625,56.8165770628906,20.5400368875268,26.325863,0,0,0,40,4449,300.4451,-63612.251953125,,,,,,,,,,,,,0,,,,0,,,,,,300.01501465,,,,
,23081246.26,300.0166321,-67627.5,0.000157673478674655,3.20551835707874E-6,1,0.999253354069792,40.0298881530762,1.97331057905907,15.760000795126,0.00176304403710563,0.000303663771227802,0.25,-1.54869028038832E-7,0.000157668919613552,-5.18170285318591E-8,300.0166321,300.0166321,-67635.015625,-67619.984375,56.8759808303522,20.5397722473305,26.705515,0,0,0,40,4449,300.43585,-67627.5,,,,,,,,,,,,,0,,,,0,,,,,,300.0166321,,,,
,23081326.135,300.0161133,-71617.12890625,0.00017633219435118,2.59247335386797E-6,1,0.999253354069792,40.0298881530762,1.9733007211681,15.760000795126,0.00197239997140977,0.000335379740705771,0.25,-5.50316367638888E-7,0.000176327354909984,-4.35167811746121E-7,300.0161133,300.0161133,-71622.0390625,-71612.21875,56.9791557948906,20.5413265912876,26.705515,0,0,0,40,4449,300.42215,-71617.12890625,,,,,,,,,,,,,0,,,,0.00245,,,,,,300.0161133,,,,
,23081407.29,300.0119324,-75672.0625,0.000190411395835592,2.78772890357659E-6,1,0.999253354069792,40.0298881530762,1.97324220808064,15.760000795126,0.00212656597252503,0.000380963926833882,0.25,1.08897978413634E-6,0.000190405111507366,1.2131463270951E-6,300.0119324,300.0119324,-75679.5,-75664.625,56.9017745714868,20.5417543738063,26.325863,0,0,0,40,4449,300.4192,-75672.0625,,,,,,,,,,,,,0,,,,0,,,,,,300.0119324,,,,
,23081487.585,300.0126648,-79684.375,0.000204529241942139,2.84206133851267E-6,1,0.999253354069792,40.0298881530762,1.97329050234616,15.760000795126,0.00229164465127078,0.000366776291567049,0.25,-2.62664548006225E-6,0.000204524972563983,-2.49329432308724E-6,300.0126648,300.0126648,-79691.921875,-79676.828125,56.8329912617945,20.5428331445698,26.325863,0,0,0,40,4449,300.41015,-79684.375,,,,,,,,,,,,,0,,,,0,,,,,,300.0126648,,,,
,23081568.385,300.0149841,-83722.34765625,0.000220083323140543,3.28723041871656E-6,1,0.999253354069792,40.0298881530762,1.97325795520278,15.760000795126,0.00246139708378074,0.000420545131865301,0.25,-5.11073319082577E-7,0.000220077214473998,-3.67792967807832E-7,300.0149841,300.0149841,-83734.9296875,-83709.765625,57.004167907506,20.5432408860268,26.705515,0,0,0,40,4449,300.3999,-83722.34765625,,,,,,,,,,,,,0,,,,0.00245,,,,,,300.0149841,,,,
,23081646.75,300.0155792,-87639.7890625,0.000235015500580846,3.793460541356E-6,1,0.999253354069792,40.0298881530762,1.97333862660206,15.760000795126,0.00262369533111611,0.000476831065963546,0.25,1.93522314252728E-6,0.000235007371775699,2.08800362239121E-6,300.013916,300.0172424,-87647.453125,-87632.125,56.8572217458906,20.5425276110263,27.085165,0,0,0,40,4449,300.38655,-87639.7890625,,,,,,,,,,,,,0,,,,-0.00245,,,,,,300.0155792,,,,
,23081739.665,300.0138855,-88727.75390625,0.000237559072742782,3.06038002260025E-6,1,0.999253354069792,40.0298881530762,1.97329693474277,15.760000795126,0.00266108939637123,0.000429737522374737,0.25,-2.71697842283495E-6,0.000237553912573066,-2.5624480887326E-6,300.0138855,300.0138855,-88732.765625,-88722.7421875,56.9846271945253,20.5436964887912,26.705515,0,0,0,40,4449,300.3798,-88727.75390625,,,,,,,,,,,,,0,,,,0,,,,,,300.0138855,,,,
,23081817.205,300.0095215,-84855.7734375,0.000221056191997708,3.39418549938858E-6,1,0.999253354069792,40.0298881530762,1.97336972053527,15.760000795126,0.00246507812674991,0.000464758820537777,0.25,3.27305895249167E-6,0.000221047637630046,3.41683626833989E-6,300.0095215,300.0095215,-84866.015625,-84845.53125,56.7321611828137,20.5424018377429,26.705515,0,0,0,40,4449,300.37075,-84855.7734375,,,,,,,,,,,,,0,,,,0,,,,,,300.0095215,,,,
,23081898.245,300.0002441,-80803.34375,0.000206786870202192,2.71189668298882E-6,1,0.999253354069792,40.0298881530762,1.97327766574126,15.760000795126,0.00230699714737873,0.000428137750293229,0.25,2.47116111412518E-6,0.000206779307405333,2.60581414090782E-6,300.0002441,300.0002441,-80808.078125,-80798.609375,56.9791557948906,20.5428841036752,26.705515,0,0,0,40,4449,300.3764,-80803.34375,,,,,,,,,,,,,0,,,,-0.00245,,,,,,300.0002441,,,,
,23081978.585,299.993927,-76788.234375,0.000192679914722211,2.95068615156248E-6,1,0.999253354069792,40.0298881530762,1.97321688615414,15.760000795126,0.00215406697999476,0.000372854102485771,0.25,-2.90600084240762E-8,0.000192674419599682,9.65994101564318E-8,299.993927,299.993927,-76796.1328125,-76780.3359375,56.9306948266983,20.5432645223118,26.325863,0,0,0,40,4449,300.3857,-76788.234375,,,,,,,,,,,,,0,,,,0,,,,,,299.993927,,,,
,23082058.94,299.9935608,-72772.67578125,0.00017509235473968,2.56700100343974E-6,1,0.999253354069792,40.0298881530762,1.97321365351419,15.760000795126,0.00195875246984417,0.000331264673169528,0.25,-7.02358120885267E-7,0.000175087794360878,-5.88031474833452E-7,299.9935608,299.9935608,-72777.53125,-72767.8203125,56.7126204698329,20.5436157513456,26.325863,0,0,0,40,4449,300.3836,-72772.67578125,,,,,,,,,,,,,0,,,,0.0049,,,,,,299.9935608,,,,
,23082140.795,299.9940186,-68682.36328125,0.000163301089591047,2.45075042051696E-6,1,0.999253354069792,40.0298881530762,1.97319737413359,15.760000795126,0.0018224539494423,0.000334209149957755,0.25,1.60398896049106E-6,0.000163295348366074,1.71065798495206E-6,299.9940186,299.9940186,-68689.9765625,-68674.75,56.8204852054868,20.5432125385277,27.085165,0,0,0,40,4449,300.3926,-68682.36328125,,,,,,,,,,,,,0,,,,-0.0049,,,,,,299.9940186,,,,
,23082220.01,299.9912109,-64722.1640625,0.000145710008085951,2.94618653234038E-6,1,0.999253354069792,40.0298881530762,1.97318600675539,15.760000795126,0.00162533772630365,0.000302762187864094,0.25,1.83868519349181E-6,0.000145704624455641,1.93394343050818E-6,299.9912109,299.9912109,-64727.19140625,-64717.13671875,56.770460980256,20.5427262986563,27.085165,0,0,0,40,4449,300.4001,-64722.1640625,,,,,,,,,,,,,0,,,,-0.00245,,,,,,299.9912109,,,,
,23082301.85,299.9901733,-60634.361328125,0.000132403926317311,2.49368386353635E-6,1,0.999253354069792,40.0298881530762,1.97321945751173,15.760000795126,0.00147846159073826,0.000266321862221486,0.25,8.83800356025912E-7,0.000132399545931176,9.70466930500086E-7,299.9901733,299.9901733,-60644.3984375,-60624.32421875,56.7524835243137,20.5410962756104,27.085165,0,0,0,40,4449,300.4083,-60634.361328125,,,,,,,,,,,,,0,,,,0,,,,,,299.9901733,,,,
,23082382.315,299.98960875,-56611.587890625,0.000116693122336076,2.5152203026627E-6,1,0.999253354069792,40.0298881530762,1.97314494570038,15.760000795126,0.0013066465425785,0.000213566273362231,0.25,-1.11274359935091E-6,0.000116690496735041,-1.03623173739327E-6,299.9888611,299.9903564,-56621.44921875,-56601.7265625,56.9807190519291,20.5426223039305,26.325863,0,0,0,40,4449,300.4094,-56611.587890625,,,,,,,,,,,,,0,,,,-0.00245,,,,,,299.98960875,,,,
,23082462.61,299.9916992,-52598.751953125,0.000103140957406061,2.41004192177211E-6,1,0.999253354069792,40.0298881530762,1.97320233404381,15.760000795126,0.00114502051021001,0.000245971662253564,0.25,4.13333988066552E-6,0.00010313526710337,4.20088286468654E-6,299.9916992,299.9916992,-52603.57421875,-52593.9296875,57.0315249056791,20.5407558325361,26.705515,0,0,0,40,4449,300.4124,-52598.751953125,,,,,,,,,,,,,0,,,,0,,,,,,299.9916992,,,,
,23082543.67,299.986145,-48549.138671875,8.66147346919643E-5,1.78541386885933E-6,1,0.999253354069792,40.0298881530762,1.97319368072094,15.760000795126,0.000963720912137795,0.000194031773876576,0.25,2.35041881733951E-6,8.66107026521198E-5,2.40722314382878E-6,299.986145,299.986145,-48561.78515625,-48536.4921875,56.8236117195637,20.5403121407827,26.325863,0,0,0,40,4449,300.42855,-48549.138671875,,,,,,,,,,,,,0,,,,0,,,,,,299.986145,,,,
,23082620.97,299.9918213,-44686.75,7.41468772596516E-5,1.70366666945818E-6,1,0.999253354069792,40.0298881530762,1.97319977535508,15.760000795126,0.000827422206127373,0.000152116845830752,0.25,7.61026028174385E-7,7.41442276729943E-5,8.09732330302413E-7,299.9918213,299.9918213,-44694.4296875,-44679.0703125,56.6336759893906,20.5354367891434,26.705515,0,0,0,40,4449,300.4334,-44686.75,,,,,,,,,,,,,0,,,,0,,,,,,299.9918213,,,,
,23082701.375,299.9911499,-40666.126953125,5.87856355215796E-5,1.72966857207195E-6,1,0.999253354069792,40.0298881530762,1.97327133044652,15.760000795126,0.00065668579068454,0.000116794042384287,0.25,2.62304347968917E-7,5.87837570895321E-5,3.0096534109843E-7,299.9911499,299.9911499,-40676.140625,-40656.11328125,56.8603482599676,20.537805872534,26.705515,0,0,0,40,4449,300.4349,-40666.126953125,,,,,,,,,,,,,0,,,,0.0049,,,,,,299.9911499,,,,
,23082784.26,299.9935608,-36523.1484375,4.58201339661109E-5,1.42652739191204E-6,1,0.999253354069792,40.0298881530762,1.97322829896346,15.760000795126,0.000509318307888576,0.000105583393397782,0.25,1.50601641069145E-6,4.58178063126607E-5,1.53614028855583E-6,299.9935608,299.9935608,-36528.34375,-36517.953125,56.9807190519291,20.540064882613,26.325863,0,0,0,40,4449,300.438,-36523.1484375,,,,,,,,,,,,,0,,,,0,,,,,,299.9935608,,,,
,23082865.25,299.9899597,-32478.220703125,3.24147803481778E-5,1.49600078449609E-6,1,0.999253354069792,40.0298881530762,1.97316192308303,15.760000795126,0.000360321266437705,7.45578013725578E-5,0.25,1.0534737209375E-6,3.24131435064984E-5,1.07480311878877E-6,299.9899597,299.9899597,-32485.70703125,-32470.734375,56.8486238321791,20.5384231097881,26.325863,0,0,0,40,4449,300.44715,-32478.220703125,,,,,,,,,,,,,0,,,,-0.00245,,,,,,299.9899597,,,,
,23082945.435,299.98823545,-28470.5546875,1.99886392274806E-5,1.31634386507661E-6,1,0.999253354069792,40.0298881530762,1.97320467144993,15.760000795126,0.000224531315740921,3.25064463546133E-5,0.25,-5.55372468944146E-7,1.99884244789208E-5,-5.42173760550233E-7,299.9873352,299.9891357,-28483.0390625,-28458.0703125,56.9252234270637,20.5379377353401,27.085165,0,0,0,40,4449,300.45695,-28470.5546875,,,,,,,,,,,,,0,,,,0,,,,,,299.98823545,,,,
,23083027.135,299.9871826,-24385.0693359375,6.98406319585479E-6,1.21511014967621E-6,1,0.999253354069792,40.0298881530762,1.9731501815157,15.760000795126,8.01031841402623E-5,1.81300847885393E-6,0.25,-1.04785244742602E-6,6.98455174053622E-6,-1.0432121998982E-6,299.9871826,299.9871826,-24389.8984375,-24380.240234375,56.8947399148137,20.5372071628235,26.705515,0,0,0,40,4449,300.46645,-24385.0693359375,,,,,,,,,,,,,0,,,,0.0049,,,,,,299.9871826,,,,
,23083108.68,299.9901123,-20312.578125,-6.6714564905199E-6,1.03334991646144E-6,1,0.999253354069792,40.0298881530762,1.97319044597628,15.760000795126,-7.34714380006544E-5,-1.93231744375929E-5,0.25,-5.72639311522714E-7,-6.67088320661488E-6,-5.77029566262344E-7,299.9901123,299.9901123,-20317.5859375,-20307.5703125,56.9041194570445,20.5373975566624,26.705515,0,0,0,40,4449,300.4713,-20312.578125,,,,,,,,,,,,,0,,,,0,,,,,,299.9901123,,,,
,23083189.195,299.9911499,-16287.4345703125,-1.98909540805983E-5,1.1613138713719E-6,1,0.999253354069792,40.0298881530762,1.97314085057538,15.760000795126,-0.000221616704589513,-4.27955557882802E-5,0.25,-3.82025485184809E-7,-1.9890118458022E-5,-3.95163773229248E-7,299.9911499,299.9911499,-16294.9013671875,-16279.9677734375,56.8947399148137,20.5381810484923,26.705515,0,0,0,40,4449,300.47655,-16287.4345703125,,,,,,,,,,,,,0,,,,-0.00245,,,,,,299.9911499,,,,
,23083269.07,299.993042,-12294.4169921875,-3.09415216510172E-5,6.76689285697201E-7,1,0.999253354069792,40.0298881530762,1.97313883441092,15.760000795126,-0.00034490915052593,-6.55780517360252E-5,0.25,-5.05434957703976E-7,-3.09402768650564E-5,-5.25889425146039E-7,299.993042,299.993042,-12301.966796875,-12286.8671875,56.831428004756,20.5369295281211,27.085165,0,0,0,40,4449,300.4839,-12294.4169921875,,,,,,,,,,,,,0,,,,0,,,,,,299.993042,,,,
,23083347.01,299.9986877,-8398.2509765625,-4.09289464727311E-5,5.51549979857102E-7,1,0.999253354069792,40.0298881530762,1.97320902194338,15.760000795126,-0.000457426492658428,-7.99908640155401E-5,0.25,-6.40747963131627E-8,-4.09276897856682E-5,-9.11681407663854E-8,299.9986877,299.9986877,-8403.3056640625,-8393.1962890625,56.953362053756,20.5375447956996,26.705515,0,0,0,40,4449,300.48025,-8398.2509765625,,,,,,,,,,,,,0,,,,0.00245,,,,,,299.9986877,,,,
,23083426.015,299.9945374,-4449.9287109375,-4.64218456054961E-5,4.32319202942147E-7,1,0.999253354069792,40.0298881530762,1.97313668484137,15.760000795126,-0.000518194244549116,-9.42054467030738E-5,0.25,-3.84185388730046E-7,-4.6420219104346E-5,-4.14924527674966E-7,299.9945374,299.9945374,-4454.9931640625,-4444.8642578125,56.5078337977944,20.5358254778339,26.705515,0,0,0,40,4449,300.4824,-4449.9287109375,,,,,,,,,,,,,0,,,,-0.00245,,,,,,299.9945374,,,,
,23083503.99,299.995636,-550.814361572266,-3.55900073316987E-5,4.3030287158307E-7,1,0.999253354069792,40.0298881530762,1.97318552225495,15.760000795126,-0.000397995829328664,-6.81565028154771E-5,0.25,6.94758421958778E-8,-3.5588999054203E-5,4.58868565244063E-8,299.995636,299.995636,-555.723022460937,-545.905700683594,56.7900016932368,20.5360686561851,27.085165,0,0,0,40,4449,300.4848,-550.814361572266,,,,,,,,,,,,,0,,,,0,,,,,,299.995636,,,,
,23083580.965,299.9955444,3289.53515625,4.64297577542329E-5,4.55905366408166E-7,1,0.999253354069792,40.0298881530762,1.97316142567894,15.760000795126,0.000520074329322657,8.39168257216688E-5,0.25,-5.3765257525658E-7,4.64287396197662E-5,-5.0687635557855E-7,299.9955444,299.9955444,3282.03515625,3297.03515625,56.9572701963522,20.5361348557369,26.705515,0,0,0,40,4449,300.4868,3289.53515625,,,,,,,,,,,,,0,,,,0,,,,,,299.9955444,,,,
,23083658.97,299.99639895,7189.78491210937,4.4273417558845E-5,6.13423950687882E-7,1,0.999253354069792,40.0298881530762,1.97317217958125,15.760000795126,0.000494921982608186,8.57978680834976E-5,0.25,4.19737820374623E-9,4.42721044434662E-5,3.35119472584887E-8,299.9961548,299.9966431,7181.95458984375,7197.615234375,56.7540467813522,20.5352712033389,26.705515,0,0,0,40,4449,300.4841,7189.78491210937,,,,,,,,,,,,,0,,,,-0.00245,,,,,,299.99639895,,,,
,23083739.045,300.0004272,11195.693359375,3.49526716772235E-5,7.66062077586944E-7,1,0.999253354069792,40.0298881530762,1.97312049479605,15.760000795126,0.000391374684565597,6.39418110215127E-5,0.25,-3.35851767749695E-7,3.49518557864628E-5,-3.12714384073467E-7,300.0004272,300.0004272,11185.6513671875,11205.7353515625,56.8689461736791,20.5356855345703,26.705515,0,0,0,40,4449,300.48425,11195.693359375,,,,,,,,,,,,,0,,,,0.00245,,,,,,300.0004272,,,,
,23083820.12,300.0009155,15246.2709960938,2.46632267001383E-5,7.16345356276711E-7,1,0.999253354069792,40.0298881530762,1.97310548824181,15.760000795126,0.000275478857629718,4.90433874861448E-5,0.25,1.1416797019031E-7,2.46624193533349E-5,1.30471612500184E-7,300.0009155,300.0009155,15243.751953125,15248.7900390625,56.6524350738522,20.5351833928836,26.325863,0,0,0,40,4449,300.4845,15246.2709960938,,,,,,,,,,,,,0,,,,0.00245,,,,,,300.0009155,,,,
,23083897.83,300.0039063,19129.193359375,1.2398916958321E-5,1.11877524469048E-6,1,0.999253354069792,40.0298881530762,1.97308944616082,15.760000795126,0.000137964287644296,2.76901952075891E-5,0.25,3.28892163461373E-7,1.23983309116349E-5,3.37074618083376E-7,300.0039063,300.0039063,19121.802734375,19136.583984375,56.7642079521022,20.5354891176552,26.325863,0,0,0,40,4449,300.4739,19129.193359375,,,,,,,,,,,,,0,,,,-0.00245,,,,,,300.0039063,,,,
,23083975.265,300.0111084,22999.95703125,-6.83935924890942E-7,1.00550798549142E-6,1,0.999253354069792,40.0298881530762,1.97311150842447,15.760000795126,-9.41105867370195E-6,8.866039185236E-6,0.25,9.11621411362698E-7,-6.84517299239807E-7,9.11142566123122E-7,300.0111084,300.0111084,22990.1328125,23009.78125,56.739977468006,20.5363507040501,27.085165,0,0,0,40,4449,300.4746,22999.95703125,,,,,,,,,,,,,0,,,,0.00245,,,,,,300.0111084,,,,
,23084056.235,300.014679,27048.314453125,-1.38535903944655E-5,1.19146001443261E-6,1,0.999253354069792,40.0298881530762,1.97307035207679,15.760000795126,-0.000159179520455215,-1.90430647123051E-6,0.25,2.22986404437794E-6,-1.38546453212669E-5,2.22065815691376E-6,300.014679,300.014679,27038.37890625,27058.25,56.831428004756,20.5360812656418,26.705515,0,0,0,40,4449,300.4654,27048.314453125,,,,,,,,,,,,,0,,,,0.0049,,,,,,300.014679,,,,
,23084138.385,300.0094604,31153.3544921875,-2.850965681658E-5,1.62540625113275E-6,1,0.999253354069792,40.0298881530762,1.97307832302834,15.760000795126,-0.000318392240278119,-5.69542565578313E-5,0.25,-1.55551531848124E-7,-2.85087048251097E-5,-1.74338197677687E-7,300.0094604,300.0094604,31145.669921875,31161.0390625,56.6657227586791,20.5346268204108,27.085165,0,0,0,40,4449,300.45805,31153.3544921875,,,,,,,,,,,,,0,,,,-0.00245,,,,,,300.0094604,,,,
,23084220.32,300.0137634,35248.98828125,-4.38743190389368E-5,1.37376712034137E-6,1,0.999253354069792,40.0298881530762,1.97306127750435,15.760000795126,-0.000491125153663721,-8.10309134575257E-5,0.25,3.52529264091301E-7,-4.38732393639167E-5,3.23624956029317E-7,300.0137634,300.0137634,35239.01171875,35258.96484375,56.8322096332752,20.5359600298134,27.085165,0,0,0,40,4449,300.4474,35248.98828125,,,,,,,,,,,,,0,,,,-0.00245,,,,,,300.0137634,,,,
,23084299.13,300.0113831,39189.31640625,-5.7642493056663E-5,1.24325929675798E-6,1,0.999253354069792,40.0298881530762,1.97301422681523,15.760000795126,-0.000646494033281244,-9.91622086049781E-5,0.25,1.11569985850777E-6,-5.76415114898215E-5,1.07773790361683E-6,300.0113831,300.0113831,39181.84375,39196.7890625,56.7509202672752,20.5340098555912,26.705515,0,0,0,40,4449,300.4388,39189.31640625,,,,,,,,,,,,,0,,,,0.00245,,,,,,300.0113831,,,,
,23084381.01,300.0121155,43279.640625,-7.12904234217061E-5,1.71354491412169E-6,1,0.999253354069792,40.0298881530762,1.97304837767788,15.760000795126,-0.000798092201801798,-0.000131211327417047,0.25,6.13279164725092E-7,-7.12887067142696E-5,5.66395816098671E-7,300.0121155,300.0121155,43274.55859375,43284.72265625,56.9783741663714,20.5323150200735,26.705515,0,0,0,40,4449,300.44005,43279.640625,,,,,,,,,,,,,0,,,,0,,,,,,300.0121155,,,,
,23084462.02,300.0112,47331.076171875,-8.57533273694553E-5,1.80245749876705E-6,1,0.999253354069792,40.0298881530762,1.97308822483993,15.760000795126,-0.000959939731135009,-0.000158309605701807,0.25,6.95066456685763E-7,-8.57512412947577E-5,6.38723708197608E-7,300.0112,300.0112,47323.69140625,47338.4609375,56.7446672391214,20.5318908933213,26.705515,0,0,0,40,4449,300.4293,47331.076171875,,,,,,,,,,,,,0,,,,-0.00245,,,,,,300.0112,,,,
,23084542.795,300.0142822,51368.787109375,-0.000101402753882936,1.54362026936333E-6,1,0.999253354069792,40.0298881530762,1.97303820640372,15.760000795126,-0.00113294889974279,-0.000199582226781408,0.25,-2.8625680265579E-7,-0.00010139955354486,-3.52789136400224E-7,300.0142822,300.0142822,51356.4140625,51381.16015625,57.0768593597945,20.5333128281451,26.325863,0,0,0,40,4449,300.415,51368.787109375,,,,,,,,,,,,,0,,,,0.00245,,,,,,300.0142822,,,,
,23084624.505,300.0164795,55449.025390625,-0.000114186449250607,1.8759915456168E-6,1,0.999253354069792,40.0298881530762,1.97306925240652,15.760000795126,-0.001281963981481,-0.000189152686743809,0.25,2.86175579715623E-6,-0.000114184930476622,2.78681332382472E-6,300.0164795,300.0164795,55439.02734375,55459.0234375,56.7782772654483,20.5326701932951,26.705515,0,0,0,40,4449,300.4114,55449.025390625,,,,,,,,,,,,,0,,,,0,,,,,,300.0164795,,,,
,23084704.335,300.0148926,59439.802734375,-0.000128003671581488,2.28833417181729E-6,1,0.999253354069792,40.0298881530762,1.97303881068147,15.760000795126,-0.0014323727783535,-0.000239138737804406,0.25,7.83563259152745E-7,-0.000128000393134449,6.9969963808692E-7,300.0148926,300.0148926,59427.28515625,59452.3203125,56.8439340610637,20.5335077211712,27.085165,0,0,0,40,4449,300.39265,59439.802734375,,,,,,,,,,,,,0,,,,0.0049,,,,,,300.0148926,,,,
,23084786.06,300.0135803,63525.7109375,-0.000143471265786468,2.92215027291057E-6,1,0.999253354069792,40.0298881530762,1.97304195658362,15.760000795126,-0.00160245300693153,-0.000285387596908185,0.25,-6.74110819350023E-7,-0.000143466590070266,-7.67967376983956E-7,300.0135803,300.0135803,63520.82421875,63530.59765625,56.6625962446021,20.5335344981864,26.325863,0,0,0,40,4449,300.39435,63525.7109375,,,,,,,,,,,,,0,,,,0.00245,,,,,,300.0135803,,,,
,23084867.19,300.0106506,67581.3359375,-0.000157434418401678,2.09566526769855E-6,1,0.999253354069792,40.0298881530762,1.97303586186364,15.760000795126,-0.00175752059214105,-0.000318264948583924,0.25,-1.19634628996878E-6,-0.000157429014417893,-1.29923068897197E-6,300.0106506,300.0106506,67573.75,67588.921875,56.6430555316214,20.5323513347653,26.705515,0,0,0,40,4449,300.3679,67581.3359375,,,,,,,,,,,,,0,,,,0,,,,,,300.0106506,,,,
,23084948.18,300.0166321,71626.91796875,-0.000171883721622018,2.92861912858068E-6,1,0.999253354069792,40.0298881530762,1.97314468762175,15.760000795126,-0.00191915136970385,-0.000346195124323473,0.25,-1.19011353319326E-6,-0.000171877871568105,-1.30232906139042E-6,300.0166321,300.0166321,71621.8671875,71631.96875,56.7923465787945,20.5351728683708,26.705515,0,0,0,40,4449,300.36895,71626.91796875,,,,,,,,,,,,,0,,,,-0.0049,,,,,,300.0166321,,,,
,23085028.93,300.0166321,75665.15625,-0.000185975236961793,2.14555778970754E-6,1,0.999253354069792,40.0298881530762,1.97297952134438,15.760000795126,-0.00208044696119699,-0.000350742276075966,0.25,8.41838134393566E-7,-0.000185970308074568,7.20479627271146E-7,300.0166321,300.0166321,75660.2890625,75670.0234375,56.8142321773329,20.5344575978406,27.085165,0,0,0,40,4449,300.3582,75665.15625,,,,,,,,,,,,,0,,,,-0.00245,,,,,,300.0166321,,,,
,23085110.43,300.0158386,79738.55859375,-0.000202669174586178,2.89378254080501E-6,1,0.999253354069792,40.0298881530762,1.97306400813931,15.760000795126,-0.00226584737879746,-0.000390568118697463,0.25,1.72440496588478E-7,-0.000202663334576532,4.0342115154938E-8,300.0158386,300.0158386,79728.5078125,79748.609375,56.8298647477175,20.5357177699263,26.705515,0,0,0,40,4449,300.34575,79738.55859375,,,,,,,,,,,,,0,,,,-0.0049,,,,,,300.0158386,,,,
,23085191.07,300.01441955,83769.4765625,-0.00021515460144126,3.16735264706778E-6,1,0.999253354069792,40.0298881530762,1.9730770661099,15.760000795126,-0.00240551254584436,-0.000414272427485848,0.25,2.15066722979872E-7,-0.000215148445608352,7.49680527787074E-8,300.0141296,300.0147095,83761.8359375,83777.1171875,56.432015831429,20.5326443555806,26.705515,0,0,0,40,4449,300.3313,83769.4765625,,,,,,,,,,,,,0,,,,0,,,,,,300.01441955,,,,
,23085269.59,300.0118103,87695.515625,-0.00022814816053014,3.76401083733379E-6,1,0.999253354069792,40.0298881530762,1.97300519307134,15.760000795126,-0.00254791349488543,-0.000455343501604518,0.25,-1.20952928544207E-6,-0.000228140732848986,-1.35789137025975E-6,300.0118103,300.0118103,87685.453125,87705.578125,56.4617177151598,20.533457500581,26.705515,0,0,0,40,4449,300.3369,87695.515625,,,,,,,,,,,,,0,,,,0,,,,,,300.0118103,,,,
,23085316.32,300.0116272,89999.4453125,-0.000241289686499051,3.28566638431366E-6,1,0.999253354069792,40.0298881530762,1.97299728006486,15.760000795126,-0.00269247191456483,-0.000494229953932977,0.25,-2.41187632341589E-6,-0.000241281104486497,-2.56866321408531E-6,300.0116272,300.0116272,89999.4296875,89999.4609375,56.8001628639868,20.5321037134243,27.085165,0,0,0,40,4417,300.3254,89999.4453125,,,,,,,,,,,,,0,,,,-0.0049,,,,,,300.0116272,,,,