File: data/doubleLayers/dl_2-5/ppms/data/DD205_5_HYST_FC100OE_10KREPEAT.DAT
[Header]
; VSM Data File (default extension .dat)
; Copyright (c) 2003-2013, Quantum Design, Inc. All rights reserved.
TITLE,
FILEOPENTIME,32891340.86,01/17/2019,12:31 am
BYAPP,VSM,2.0,2.0
INFO,PPMS VSM Option Release 1.4.10 Build 1,APPNAME
INFO,Quantum Design Linear Motor Servo Controller,MOTOR_MODULE_NAME
INFO,3101-100 M1,MOTOR_HW_VERSION
INFO,MMC1014,MOTOR_SERIAL_NUMBER
INFO,SRV No X-over 01.03.11,MOTOR_SOFTWARE_VERSION
INFO,Quantum Design VSM Detection Module,VSM_MODULE_NAME
INFO,3101-150 F0,VSM_HW_VERSION
INFO,VSM707,VSM_SERIAL_NUMBER
INFO,VSM No X-over 01.02.05 May 20 2008 13:51:47,VSM_SOFTWARE_VERSION
INFO,704,PREAMP_SERIAL_NUMBER
INFO,822,COIL_SERIAL_NUMBER
INFO,0,MOMENT_UNITS
INFO,DL 2.5,SAMPLE_MATERIAL
INFO,CoFe2O4,SAMPLE_COMMENT
INFO,29.51,SAMPLE_MASS
INFO,,SAMPLE_VOLUME
INFO,,SAMPLE_MOLECULAR_WEIGHT
INFO,,SAMPLE_SIZE
INFO,,SAMPLE_SHAPE
DATATYPE,COMMENT,1
DATATYPE,TIME,2
STARTUPAXIS,X,2
STARTUPAXIS,Y1,5
[Data]
Comment,Time Stamp (sec),Temperature (K),Magnetic Field (Oe),Moment (emu),M. Std. Err. (emu),Transport Action,Averaging Time (sec),Frequency (Hz),Peak Amplitude (mm),Center Position (mm),Coil Signal' (mV),Coil Signal" (mV),Range (mV),M. Quad. Signal (emu),M. Raw' (emu),M. Raw" (emu),Min. Temperature (K),Max. Temperature (K),Min. Field (Oe),Max. Field (Oe),Mass (grams),Motor Lag (deg),Pressure (Torr),VSM Status (code),Motor Status (code),Measure Status (code),Measure Count,PPMS Status (code),System Temp. (K),System Field (Oe),Sample Position (deg),Bridge 1 Resistance (ohms),Bridge 1 Excitation (에),Bridge 2 Resistance (ohms),Bridge 2 Excitation (에),Bridge 3 Resistance (ohms),Bridge 3 Excitation (에),Bridge 4 Resistance (ohms),Bridge 4 Excitation (에),Signal 1 Vin (V),Signal 2 Vin (V),Digital Inputs (code),Drive 1 Iout (mA),Drive 1 Ipower (W),Drive 2 Iout (mA),Drive 2 Ipower (W),Pressure (),Map 20 (),Map 21 (),Map 22 (),Map 23 (),Map 24 (),Map 25 (),Map 26 (),Map 27 (),Map 28 (),Map 29 ()
,32891356.34,10.001687,100.157203674316,,,2,,,,21.9099999779463,,,,,,,10.001687,10.001687,100.157203674316,100.157203674316,,,11.899124,,,,-99999999,4369,9.9932,100.157203674316,,,,,,,,,,,,,,,,,,,,,,,10.001687,,,,
,32891507.115,9.998786,4434.32836914063,3.54884618548667E-6,2.94278946546195E-7,1,0.999253354069792,40.0298881530762,1.99500021611221,21.9000000506639,3.97842455879213E-5,7.40648638627271E-6,0.25,2.85690525409844E-8,3.52916163766158E-6,4.6466886127793E-8,9.998786,9.998786,4432.00439453125,4436.65234375,55.8340700142174,20.5166271387697,11.519473,0,0,0,40,4449,9.9947,4434.32836914063,,,,,,,,,,,,,0,,,,0.0049,,,,,,9.998786,,,,
,32891599.01,9.9983282,9027.9072265625,-8.30886779988097E-6,3.97710812859886E-7,1,0.999253354069792,40.0298881530762,1.99517786447196,21.9000000506639,-9.27344084118982E-5,-1.98790992815536E-5,0.25,-2.89484587687648E-7,-8.26432430327561E-6,-3.33038850887089E-7,9.9983282,9.9983282,9023.138671875,9032.67578125,56.6915164998137,20.5175325628254,11.899124,0,0,0,40,4449,9.9947,9027.9072265625,,,,,,,,,,,,,0,,,,0,,,,,,9.9983282,,,,
,32891693.88,10.0009642,13770.6298828125,-1.92341745117522E-5,5.58087144472184E-7,1,0.999253354069792,40.0298881530762,1.99534194965246,21.9000000506639,-0.00021526406782019,-4.32777872502881E-5,0.25,-4.17630062013932E-7,-1.91399174403806E-5,-5.26610852441566E-7,10.0009642,10.0009642,13760.5517578125,13780.7080078125,56.6133536478906,20.5173189837597,11.899124,0,0,0,40,4449,9.9937,13770.6298828125,,,,,,,,,,,,,0,,,,0,,,,,,10.0009642,,,,
,32891792.85,9.9998999,18715.7099609375,-2.72633284094361E-5,5.62941697091096E-7,1,0.999253354069792,40.0298881530762,1.99554571840203,21.9000000506639,-0.000304945398555049,-6.33156218406804E-5,0.25,-7.55057304541183E-7,-2.71409438181804E-5,-9.18451335854257E-7,9.9998999,9.9998999,18708.056640625,18723.36328125,57.0104209356599,20.515823897183,11.899124,0,0,0,40,4449,9.9932,18715.7099609375,,,,,,,,,,,,,0,,,,0,,,,,,9.9998999,,,,
,32891892.78,10.0002613,23710.505859375,-3.0407540752489E-5,6.85244563229443E-7,1,0.999253354069792,40.0298881530762,1.99546579222516,21.9000000506639,-0.000340995960795178,-6.65808967588231E-5,0.25,-4.70847186478066E-7,-3.02881224514273E-5,-6.64467568807463E-7,10.0002613,10.0002613,23700.578125,23720.43359375,56.7970363499099,20.5169768583597,11.519473,0,0,0,40,4449,9.99235,23710.505859375,,,,,,,,,,,,,0,,,,-0.0049,,,,,,10.0002613,,,,
,32891991.9,10.0007172,28663.2109375,-3.41242076504781E-5,6.10908291606846E-7,1,0.999253354069792,40.0298881530762,1.99543275320031,21.9000000506639,-0.000381887204187002,-8.01977456475292E-5,0.25,-1.00291434297985E-6,-3.40042502077878E-5,-1.22816624687412E-6,10.0007172,10.0007172,28653.111328125,28673.310546875,56.2678738423906,20.5197056460668,11.139823,0,0,0,40,4449,9.9933,28663.2109375,,,,,,,,,,,,,0,,,,-0.00245,,,,,,10.0007172,,,,
,32892089.7,9.9989414,33553.244140625,-4.17417711259626E-5,7.64269676868563E-7,1,0.999253354069792,40.0298881530762,1.99528472347771,21.9000000506639,-0.000468352934335478,-9.25189025678384E-5,0.25,-7.17727911484963E-7,-4.16197774908851E-5,-1.00475314552928E-6,9.9989414,9.9989414,33540.6484375,33565.83984375,57.0026046504676,20.5231040785186,11.899124,0,0,0,40,4449,9.9939,33553.244140625,,,,,,,,,,,,,0,,,,0.00245,,,,,,9.9989414,,,,
,32892188.71,9.9993467,38500.478515625,-5.21398188488718E-5,7.81791007754726E-7,1,0.999253354069792,40.0298881530762,1.99520254429564,21.9000000506639,-0.000584860006656407,-0.000118098168666146,0.25,-1.10697006903964E-6,-5.2013152297166E-5,-1.47511835516992E-6,9.9993467,9.9993467,38493.0859375,38507.87109375,56.6368025034675,20.5296588478681,11.139823,0,0,0,40,4449,9.99485,38500.478515625,,,,,,,,,,,,,0,,,,0,,,,,,9.9993467,,,,
,32892286.48,9.9977274,43388.28125,-7.02192415435478E-5,8.29057472556651E-7,1,0.999253354069792,40.0298881530762,1.99483530777483,21.9000000506639,-0.00078559907638452,-0.000172030219000488,0.25,-2.62894072962647E-6,-7.00764222205671E-5,-3.13333862989972E-6,9.9977274,9.9977274,43381.0390625,43395.5234375,56.8525319747752,20.5330859403247,11.519473,0,0,0,40,4449,9.9957,43388.28125,,,,,,,,,,,,,0,,,,-0.0049,,,,,,9.9977274,,,,
,32892384.775,9.9974623,48300.75,-8.54278292550676E-5,8.690299595342E-7,1,0.999253354069792,40.0298881530762,1.9949118587052,21.9000000506639,-0.000954818758846862,-0.000217459370849174,0.25,-3.90487311410131E-6,-8.52921137075177E-5,-4.52782663502892E-6,9.9974623,9.9974623,48288.27734375,48313.22265625,57.0487207331022,20.5335091866473,11.899124,0,0,0,40,4449,9.9976,48300.75,,,,,,,,,,,,,0,,,,0,,,,,,9.9974623,,,,
,32892485.41,9.9968996,53330.76171875,-0.00010318544224815,7.83691705581792E-7,1,0.999253354069792,40.0298881530762,1.99540637078943,21.9000000506639,-0.00116143413956846,-0.000222444934637094,0.25,-1.12707929983114E-6,-0.000103100234853046,-1.89117222511145E-6,9.9968996,9.9968996,53325.765625,53335.7578125,57.0362146767945,20.5190096774139,11.519473,0,0,0,40,4449,10.0018,53330.76171875,,,,,,,,,,,,,0,,,,0,,,,,,9.9968996,,,,
,32892585.03,9.9961967,58310.92578125,-0.000118141935011936,9.28538247015518E-7,1,0.999253354069792,40.0298881530762,1.9951965144832,21.9000000506639,-0.00132972991272743,-0.000257910318526383,0.25,-1.5644902028437E-6,-0.000118099600611737,-2.44320942772613E-6,9.9961967,9.9961967,58298.453125,58323.3984375,56.9064643426022,20.5235533747448,11.519473,0,0,0,40,4449,10.0056,58310.92578125,,,,,,,,,,,,,0,,,,-0.00245,,,,,,9.9961967,,,,
,32892685.76,9.9968424,63344.2890625,-0.00013607609035448,8.47071243911354E-7,1,0.999253354069792,40.0298881530762,1.99507581159698,21.9000000506639,-0.00152923532188433,-0.000313718927756118,0.25,-3.26783611435212E-6,-0.000136080281367409,-4.28069553652671E-6,9.9968424,9.9968424,63336.6875,63351.890625,56.9471090256022,20.5294187592939,11.519473,0,0,0,40,4449,10.0095,63344.2890625,,,,,,,,,,,,,0,,,,0.00245,,,,,,9.9968424,,,,
,32892787.09,9.9961195,68408.9765625,-0.000155644778464382,9.04537283984949E-7,1,0.999253354069792,40.0298881530762,1.99502623075523,21.9000000506639,-0.00175319707884636,-0.000340660529792418,0.25,-2.12010105844639E-6,-0.000155731541965158,-3.27446597335584E-6,9.9961195,9.9961195,68398.890625,68419.0625,57.1831608384099,20.5290526563087,11.519473,0,0,0,40,4449,10.0134,68408.9765625,,,,,,,,,,,,,0,,,,0,,,,,,9.9961195,,,,
,32892889.79,9.9955883,73541.52734375,-0.00017544698430429,9.51667189235421E-7,1,0.999253354069792,40.0298881530762,1.99496429750698,21.9000000506639,-0.00197687369986347,-0.000385091418473116,0.25,-2.48290106957E-6,-0.000175619675939476,-3.77559560299951E-6,9.9955883,9.9955883,73531.3359375,73551.71875,57.0440309619868,20.5311756108574,11.899124,0,0,0,40,4449,10.0167,73541.52734375,,,,,,,,,,,,,0,,,,0,,,,,,9.9955883,,,,
,32892989.85,9.9949656,78544.859375,-0.000190903641355888,8.68856403153818E-7,1,0.999253354069792,40.0298881530762,1.9954217530909,21.9000000506639,-0.00215113108704985,-0.000426064083232496,0.25,-3.31680723228005E-6,-0.000191162589366357,-4.71138514642985E-6,9.9949656,9.9949656,78534.796875,78554.921875,57.2214606358522,20.5193304619119,11.519473,0,0,0,40,4449,10.02225,78544.859375,,,,,,,,,,,,,0,,,,0,,,,,,9.9949656,,,,
,32893091.97,9.995368,83647.9296875,-0.000210368268259533,8.0374974583494E-7,1,0.999253354069792,40.0298881530762,1.99524380436223,21.9000000506639,-0.00237418744378582,-0.000452795708664925,0.25,-2.18467162886756E-6,-0.000210743929597535,-3.700942889118E-6,9.995368,9.995368,83637.8515625,83658.0078125,56.8275198621599,20.5243590696953,11.899124,0,0,0,40,4449,10.0255,83647.9296875,,,,,,,,,,,,,0,,,,0.00245,,,,,,9.995368,,,,
,32893184.93,9.9957266,88295.96484375,-0.000225492616988873,9.34603692383538E-7,1,0.999253354069792,40.0298881530762,1.99516418455847,21.9000000506639,-0.00254653036282882,-0.000480322381428282,0.25,-1.90688798837649E-6,-0.000225971273229488,-3.51066703878001E-6,9.9957266,9.9957266,88290.8828125,88301.046875,56.926005055583,20.5266388505013,11.139823,0,0,0,40,4449,10.0293,88295.96484375,,,,,,,,,,,,,0,,,,-0.00245,,,,,,9.9957266,,,,
,32893298.945,9.9981203,87176.0546875,-0.000223311865057191,1.17338020925792E-6,1,0.999253354069792,40.0298881530762,1.99477527553463,21.9000000506639,-0.00251948336578845,-0.000485331824644747,0.25,-2.74790356318371E-6,-0.000223762798362945,-4.34312247879109E-6,9.9981203,9.9981203,87163.6484375,87188.4609375,56.5789619930445,20.538995161618,11.519473,0,0,0,40,4449,10.03395,87176.0546875,,,,,,,,,,,,,0,,,,-0.00245,,,,,,9.9981203,,,,
,32893397.575,10.00138,82247.58984375,-0.000205799948549723,1.15722552738671E-6,1,0.999253354069792,40.0298881530762,1.99476813589086,21.9000000506639,-0.00232468391690355,-0.000427167576547789,0.25,-7.47113098742495E-7,-0.000206156617020522,-2.23323293566658E-6,10.00138,10.00138,82239.953125,82255.2265625,56.9908802226791,20.5361541487056,10.760172,0,0,0,40,4449,10.02945,82247.58984375,,,,,,,,,,,,,0,,,,-0.0049,,,,,,10.00138,,,,
,32893499.365,10.0022497,77158.359375,-0.000188669348013734,6.95949821337435E-7,1,0.999253354069792,40.0298881530762,1.9946127936233,21.9000000506639,-0.00212625100703305,-0.000413393858476515,0.25,-2.61200327864905E-6,-0.000188909884846089,-3.99314680356546E-6,10.0022497,10.0022497,77150.5703125,77166.1484375,56.9447641400445,20.5403287914236,11.519473,0,0,0,40,4449,10.0282,77158.359375,,,,,,,,,,,,,0,,,,0,,,,,,10.0022497,,,,
,32893602.015,10.003068,72027.78515625,-0.000169795299481541,9.1887047707749E-7,1,0.999253354069792,40.0298881530762,1.99470108407167,21.9000000506639,-0.00191279954151468,-0.000372118687659895,0.25,-2.35760216359072E-6,-0.000169941632314764,-3.61145877322617E-6,10.003068,10.003068,72017.5390625,72038.03125,57.1386080128137,20.5389580575268,11.899124,0,0,0,40,4449,10.02405,72027.78515625,,,,,,,,,,,,,0,,,,0.00245,,,,,,10.003068,,,,
,32893703.775,10.0036945,66939.890625,-0.000152404660960426,1.00380542470074E-6,1,0.999253354069792,40.0298881530762,1.99456625359038,21.9000000506639,-0.00171371070060742,-0.000346727177237181,0.25,-3.25005444593485E-6,-0.00015246141433003,-4.38249693200257E-6,10.0036945,10.0036945,66929.78125,66950,56.8103240347368,20.5412795124575,11.519473,0,0,0,40,4449,10.0238,66939.890625,,,,,,,,,,,,,0,,,,0,,,,,,10.0036945,,,,
,32893802.095,10.0036077,62023.7265625,-0.000132529905008329,1.10363784015883E-6,1,0.999253354069792,40.0298881530762,1.99515733159342,21.9000000506639,-0.00149064660752238,-0.000297830177044376,0.25,-2.50087497027773E-6,-0.000132523019181365,-3.48737010902559E-6,10.0036077,10.0036077,62016.31640625,62031.13671875,56.9267866841022,20.5296570478902,11.139823,0,0,0,40,4449,10.0183,62023.7265625,,,,,,,,,,,,,0,,,,0,,,,,,10.0036077,,,,
,32893902.475,10.002902,57005.63671875,-0.000113304369225369,9.95424969549124E-7,1,0.999253354069792,40.0298881530762,1.9949008716723,21.9000000506639,-0.0012757364323664,-0.000242872339839525,0.25,-1.10969911272501E-6,-0.000113252491257324,-1.9519226886162E-6,10.002902,10.002902,57003.41796875,57007.85546875,57.271484861083,20.5367661821283,11.519473,0,0,0,40,4449,10.0141,57005.63671875,,,,,,,,,,,,,0,,,,0.00245,,,,,,10.002902,,,,
,32894004.39,10.0034809,51916.09765625,-9.53745493413826E-5,9.91376789280743E-7,1,0.999253354069792,40.0298881530762,1.99505540518919,21.9000000506639,-0.00106773945394076,-0.000235757450525715,0.25,-3.722913945217E-6,-9.52625043407341E-5,-4.42529332068628E-6,10.0034809,10.0034809,51910.91796875,51921.27734375,56.9494539111599,20.5342280562371,10.760172,0,0,0,40,4449,10.0119,51916.09765625,,,,,,,,,,,,,0,,,,0,,,,,,10.0034809,,,,
,32894104.805,10.0035658,46893.6328125,-7.82301523711789E-5,8.91993686005183E-7,1,0.999253354069792,40.0298881530762,1.99501691990953,21.9000000506639,-0.000876914019734826,-0.000184546346754642,0.25,-2.28455111659294E-6,-7.81040878184007E-5,-2.85437000335851E-6,10.0035658,10.0035658,46883.6640625,46903.6015625,57.1573670972753,20.5345762487091,11.139823,0,0,0,40,4449,10.00885,46893.6328125,,,,,,,,,,,,,0,,,,-0.00245,,,,,,10.0035658,,,,
,32894207.025,10.0031147,41785.947265625,-5.93492961996328E-5,8.75945612748338E-7,1,0.999253354069792,40.0298881530762,1.99448636878173,21.9000000506639,-0.00066716808567862,-0.000126454200142027,0.25,-5.46125169025174E-7,-5.92307593318479E-5,-9.72849852922828E-7,10.0031147,10.0031147,41780.7578125,41791.13671875,57.014329078256,20.5471588266383,11.139823,0,0,0,40,4449,10.0043,41785.947265625,,,,,,,,,,,,,0,,,,-0.0049,,,,,,10.0031147,,,,
,32894307.835,10.0025082,36748.46875,-4.26485903890928E-5,7.60471947510899E-7,1,0.999253354069792,40.0298881530762,1.99450054915731,21.9000000506639,-0.000481984957596777,-7.52065513878859E-5,0.25,9.88455692717648E-7,-4.25504546650939E-5,6.85399967187597E-7,10.0025082,10.0025082,36738.55859375,36758.37890625,57.0745144742368,20.5475821438123,11.519473,0,0,0,40,4449,10.0027,36748.46875,,,,,,,,,,,,,0,,,,-0.00245,,,,,,10.0025082,,,,
,32894411.735,10.0018578,31556.5927734375,-2.67128736857208E-5,6.82108563031414E-7,1,0.999253354069792,40.0298881530762,1.99443159643855,21.9000000506639,-0.000301255565744085,-4.96189136596708E-5,0.25,3.87630092887694E-7,-2.66349929475014E-5,2.03816155736507E-7,10.0018578,10.0018578,31546.5625,31566.623046875,57.3230723433522,20.5490689029287,11.139823,0,0,0,40,4449,10.00045,31556.5927734375,,,,,,,,,,,,,0,,,,0,,,,,,10.0018578,,,,
,32894510.86,10.0013561,26603.5498046875,-1.07252178483428E-5,7.12766863615971E-7,1,0.999253354069792,40.0298881530762,1.99451982905673,21.9000000506639,-0.000120428211252762,-2.25188133057592E-5,0.25,-7.88044617501795E-8,-1.06868144227615E-5,-1.49211533691457E-7,10.0013561,10.0013561,26588.189453125,26618.91015625,57.0823307594291,20.5467180904016,10.760172,0,0,0,40,4449,10.00045,26603.5498046875,,,,,,,,,,,,,0,,,,0,,,,,,10.0013561,,,,
,32894611.03,10.0003538,21596.2158203125,5.37490692021585E-6,5.13227836139621E-7,1,0.999253354069792,40.0298881530762,1.9944531557198,21.9000000506639,6.02098136910282E-5,1.18920296186117E-5,0.25,9.55901445352911E-8,5.3525944758837E-6,1.2905762347589E-7,10.0003538,10.0003538,21586.04296875,21606.388671875,57.0409044479099,20.5501259360091,11.139823,0,0,0,40,4449,10.00065,21596.2158203125,,,,,,,,,,,,,0,,,,0.00245,,,,,,10.0003538,,,,
,32894709.265,10.0002127,16684.107421875,2.12075884879118E-5,5.10272554260864E-7,1,0.999253354069792,40.0298881530762,1.99515641765097,21.9000000506639,0.000238269439596202,4.28131783923888E-5,0.25,1.88980817168067E-8,2.11118030268038E-5,1.45531605367073E-7,10.0002127,10.0002127,16679.5703125,16688.64453125,57.166746639506,20.5329057247673,10.760172,0,0,0,40,4449,9.9994,16684.107421875,,,,,,,,,,,,,0,,,,-0.00245,,,,,,10.0002127,,,,
,32894808.365,10.001276,11731.380859375,3.67025188585544E-5,4.56246205755746E-7,1,0.999253354069792,40.0298881530762,1.99500171179487,21.9000000506639,0.000412028368948841,7.46984468257575E-5,0.25,1.02897802329411E-7,3.65202136106219E-5,3.08712676611829E-7,10.001276,10.001276,11726.162109375,11736.599609375,56.7837486650829,20.5387194061632,11.519473,0,0,0,40,4449,10.0017,11731.380859375,,,,,,,,,,,,,0,,,,0.0049,,,,,,10.001276,,,,
,32894907.035,9.9988184,6799.24536132813,5.16128600006242E-5,3.68453617000567E-7,1,0.999253354069792,40.0298881530762,1.99409530894814,21.9000000506639,0.000578368793444895,0.000108140861517816,0.25,4.47077226490713E-7,5.1334829369277E-5,7.16057874322386E-7,9.9988184,9.9988184,6794.32666015625,6804.1640625,56.9439825115252,20.5577373769249,11.139823,0,0,0,40,4449,10.0009,6799.24536132813,,,,,,,,,,,,,0,,,,-0.0049,,,,,,9.9988184,,,,
,32895007.61,10.0003157,1773.55303955078,6.58467273951196E-5,3.59288217597905E-7,1,0.999253354069792,40.0298881530762,1.99425122893699,21.9000000506639,0.000739032778701595,0.000130356378264434,0.25,-8.16737600995927E-8,6.54740393854508E-5,2.42154681819222E-7,10.0003157,10.0003157,1765.96423339844,1781.14184570313,56.8157954343714,20.5503494167317,11.139823,0,0,0,40,4449,10.0012,1773.55303955078,,,,,,,,,,,,,0,,,,0,,,,,,10.0003157,,,,
,32895106.38,9.9991703,-3159.49145507812,7.77170040632262E-5,3.18021778178677E-7,1,0.999253354069792,40.0298881530762,1.99440094165225,21.9000000506639,0.000872014090850326,0.000156004876327396,0.25,8.60715878833122E-8,7.72824052750037E-5,4.74174092700705E-7,9.9991703,9.9991703,-3162.10571289063,-3156.87719726562,56.841589175506,20.5494026860256,11.139823,0,0,0,40,4449,10.0022,-3159.49145507812,,,,,,,,,,,,,0,,,,0,,,,,,9.9991703,,,,
,32895206.63,9.9996166,-8171.30200195313,8.93725718937293E-5,3.80566058054703E-7,1,0.999253354069792,40.0298881530762,1.99436636445296,21.9000000506639,0.00100338614609585,0.000178022511180468,0.25,-6.13012523934097E-8,8.89047153807182E-5,4.17945096470121E-7,9.9996166,9.9996166,-8181.6689453125,-8160.93505859375,56.9486722826406,20.5485187282041,11.519473,0,0,0,40,4449,10.0016,-8171.30200195313,,,,,,,,,,,,,0,,,,0.00245,,,,,,9.9996166,,,,
,32895306.18,9.9998255,-13149.287109375,9.57290739220969E-5,4.04555994654229E-7,1,0.999253354069792,40.0298881530762,1.99450722919731,21.9000000506639,0.00107541353550269,0.00018995715949909,0.25,-1.73561346783965E-7,9.5267725620892E-5,3.75311535395688E-7,9.9998255,9.9998255,-13159.2236328125,-13139.3505859375,57.1659650109868,20.5521329389444,10.760172,0,0,0,40,4449,10.00285,-13149.287109375,,,,,,,,,,,,,0,,,,-0.00245,,,,,,9.9998255,,,,
,32895407.935,10.0003157,-18232.1806640625,9.07062680152244E-5,5.99670348456316E-7,1,0.999253354069792,40.0298881530762,1.99469367495396,21.9000000506639,0.0010205578003919,0.000174493137813946,0.25,-6.94809149508033E-7,9.03144887475695E-5,-1.4023410451433E-7,10.0003157,10.0003157,-18237.21875,-18227.142578125,57.4379717356792,20.5498745654878,10.760172,0,0,0,40,4449,10.0011,-18232.1806640625,,,,,,,,,,,,,0,,,,-0.00245,,,,,,10.0003157,,,,
,32895507.07,10.0010471,-23186.646484375,7.66678502622387E-5,5.82443359009081E-7,1,0.999253354069792,40.0298881530762,1.99470445825212,21.9000000506639,0.000860713775607638,0.000160524682852224,0.25,5.42017179198962E-7,7.63668717674997E-5,1.03025420765634E-6,10.0010471,10.0010471,-23189.107421875,-23184.185546875,57.2472543769868,20.54722792874,10.760172,0,0,0,40,4449,10.00135,-23186.646484375,,,,,,,,,,,,,0,,,,-0.00245,,,,,,10.0010471,,,,
,32895606.445,10.0005255,-28153.986328125,6.03942314643511E-5,6.72609956618153E-7,1,0.999253354069792,40.0298881530762,1.99466540261308,21.9000000506639,0.000680167760557799,0.000116392710682629,0.25,-4.89595938786209E-7,6.01938775220743E-5,-8.4965484851459E-8,10.0005255,10.0005255,-28161.603515625,-28146.369140625,56.9572701963522,20.5493178007462,11.519473,0,0,0,40,4449,10.0016,-28153.986328125,,,,,,,,,,,,,0,,,,-0.00245,,,,,,10.0005255,,,,
,32895707.605,9.9998922,-33211.2109375,5.51123464481261E-5,7.39014777557144E-7,1,0.999253354069792,40.0298881530762,1.99444842220819,21.9000000506639,0.000623685429546849,9.10465776149313E-5,0.25,-1.81194151984689E-6,5.49683614334305E-5,-1.425969004621E-6,9.9998922,9.9998922,-33218.65234375,-33203.76953125,57.0104209356599,20.5558111411838,11.139823,0,0,0,40,4449,9.9999,-33211.2109375,,,,,,,,,,,,,0,,,,0,,,,,,9.9998922,,,,
,32895805.565,9.9994574,-38105.60546875,6.26465400520807E-5,7.06678973945109E-7,1,0.999253354069792,40.0298881530762,1.99479366776765,21.9000000506639,0.000708835280397885,0.000106919101639438,0.25,-1.77316556071908E-6,6.25137624319824E-5,-1.32450972579924E-6,9.9994574,9.9994574,-38115.68359375,-38095.52734375,57.1346998702176,20.5463570929693,11.519473,0,0,0,40,4449,10.00185,-38105.60546875,,,,,,,,,,,,,0,,,,-0.0049,,,,,,9.9994574,,,,
,32895904.96,9.9984112,-43072.94140625,7.48521648944918E-5,9.45463746916168E-7,1,0.999253354069792,40.0298881530762,1.99438858752547,21.9000000506639,0.000846589326828285,0.000131326077493951,0.25,-1.81556820578446E-6,7.47309086965626E-5,-1.27027524429429E-6,9.9984112,9.9984112,-43077.875,-43068.0078125,57.0635716749676,20.5567867573083,11.139823,0,0,0,40,4449,10.004,-43072.94140625,,,,,,,,,,,,,0,,,,0,,,,,,9.9984112,,,,
,32896003.03,9.9971714,-47975.23828125,9.16295343616838E-5,8.30439027566096E-7,1,0.999253354069792,40.0298881530762,1.99449858104823,21.9000000506639,0.00102984052278174,0.000200207551698584,0.25,1.26132001990032E-6,9.15024242106212E-5,1.93262314083398E-6,9.9971714,9.9971714,-47985.30078125,-47965.17578125,57.3496477130061,20.5558889040355,11.139823,0,0,0,40,4449,10.0061,-47975.23828125,,,,,,,,,,,,,0,,,,0,,,,,,9.9971714,,,,
,32896100.825,9.9961367,-52862.515625,0.000106908258235396,9.85802968389428E-7,1,0.999253354069792,40.0298881530762,1.99457782486097,21.9000000506639,0.00120328557979708,0.000227698517761077,0.25,9.31333767549412E-7,0.000106816754829332,1.72265954048942E-6,9.9961367,9.9961367,-52872.40625,-52852.625,57.004167907506,20.5540496703727,10.760172,0,0,0,40,4449,10.0098,-52862.515625,,,,,,,,,,,,,0,,,,-0.00245,,,,,,9.9961367,,,,
,32896201.32,9.9963665,-57887.138671875,0.000122499384522674,9.08907189324763E-7,1,0.999253354069792,40.0298881530762,1.99500537889437,21.9000000506639,0.00138024294070045,0.000258232039202549,0.25,8.10691236314586E-7,0.000122456566775722,1.72185981011593E-6,9.9963665,9.9963665,-57894.63671875,-57879.640625,57.2261504069676,20.5445717680007,10.38052,0,0,0,40,4449,10.0129,-57887.138671875,,,,,,,,,,,,,0,,,,0,,,,,,9.9963665,,,,
,32896302.11,9.9956675,-62924.984375,0.000139462984248152,1.20709246494183E-6,1,0.999253354069792,40.0298881530762,1.9944943969751,21.9000000506639,0.00156889388950648,0.000309817709477849,0.25,2.32018626926175E-6,0.000139469598753701,3.35813941943661E-6,9.9956675,9.9956675,-62932.30078125,-62917.66796875,57.2902439455445,20.5583771318046,11.139823,0,0,0,40,4449,10.0174,-62924.984375,,,,,,,,,,,,,0,,,,-0.0049,,,,,,9.9956675,,,,
,32896402.735,9.9961052,-67951.89453125,0.000159118158196959,1.09977364132122E-6,1,0.999253354069792,40.0298881530762,1.99478211124125,21.9000000506639,0.00179224631686858,0.000347071058754478,0.25,2.06603482588181E-6,0.000159201312254157,3.24661549879793E-6,9.9961052,9.9961052,-67964.203125,-67939.5859375,57.2847725459099,20.5525827211952,11.139823,0,0,0,40,4449,10.0211,-67951.89453125,,,,,,,,,,,,,0,,,,0.00245,,,,,,9.9961052,,,,
,32896496.05,9.997098,-72613.80859375,0.000174012648877366,8.21044031788529E-7,1,0.999253354069792,40.0298881530762,1.99493024170592,21.9000000506639,0.0019622523967621,0.000372355944964061,0.25,1.61483510530369E-6,0.000174176946646118,2.89792958296851E-6,9.997098,9.997098,-72616.359375,-72611.2578125,56.8509687177368,20.550744464055,11.139823,0,0,0,40,4449,10.0243,-72613.80859375,,,,,,,,,,,,,0,,,,0,,,,,,9.997098,,,,
,32896588.49,9.9961538,-77235.85546875,0.000190244453664631,1.2696729372889E-6,1,0.999253354069792,40.0298881530762,1.9950173376178,21.9000000506639,0.00214529307998919,0.000412136035189886,0.25,2.20995741923803E-6,0.000190491243868372,3.60183373588415E-6,9.9961538,9.9961538,-77243.328125,-77228.3828125,57.2847725459099,20.5513697950785,11.139823,0,0,0,40,4449,10.02645,-77235.85546875,,,,,,,,,,,,,0,,,,0.00245,,,,,,9.9961538,,,,
,32896678.96,9.9969358,-81753.546875,0.000205893879517799,9.64427300771479E-7,1,0.999253354069792,40.0298881530762,1.99483573406524,21.9000000506639,0.00232330528822355,0.000440866373308017,0.25,1.94036876982256E-6,0.000206234652250476,3.43106328583544E-6,9.9969358,9.9969358,-81761.1328125,-81745.9609375,57.098744958333,20.5511020749575,10.760172,0,0,0,40,4449,10.0307,-81753.546875,,,,,,,,,,,,,0,,,,0,,,,,,9.9969358,,,,
,32896768.01,9.9967918,-86205.8828125,0.000224448826063006,1.15929304223035E-6,1,0.999253354069792,40.0298881530762,1.99495881596971,21.9000000506639,0.00252751369412798,0.000514775283397721,0.25,5.14172106444673E-6,0.000224870061070983,6.75423492884462E-6,9.9967918,9.9967918,-86213.265625,-86198.5,57.200356665833,20.5489541380605,10.760172,0,0,0,40,4449,10.0336,-86205.8828125,,,,,,,,,,,,,0,,,,0,,,,,,9.9967918,,,,
,32896871.415,9.9963589,-89651.890625,0.000234697529570721,8.62316120724201E-7,1,0.999253354069792,40.0298881530762,1.99453276788984,21.9000000506639,0.00264638244034018,0.000519500650810402,0.25,3.73182093813728E-6,0.000235204622983443,5.39833653198893E-6,9.9963589,9.9963589,-89659.265625,-89644.515625,56.8431524325445,20.5594340024182,11.519473,0,0,0,40,4449,10.0357,-89651.890625,,,,,,,,,,,,,0,,,,0,,,,,,9.9963589,,,,
,32896957.62,9.9998188,-85345.40234375,0.000221546559881991,1.0708781925406E-6,1,0.999253354069792,40.0298881530762,1.99471593242302,21.9000000506639,0.00249213792732455,0.000520554853840611,0.25,6.17918798976249E-6,0.00022194110592478,7.77659603901439E-6,9.9998188,9.9998188,-85355.46875,-85335.3359375,56.963523224506,20.5542133208309,11.139823,0,0,0,40,4449,10.0349,-85345.40234375,,,,,,,,,,,,,0,,,,0,,,,,,9.9998188,,,,
,32897048.26,10.0013504,-80815.28515625,0.000204300349742353,1.04885197970494E-6,1,0.999253354069792,40.0298881530762,1.99485243512407,21.9000000506639,0.00230131318574905,0.000458922329979749,0.25,3.82359734161958E-6,0.000204610562686309,5.30920417399073E-6,10.001235,10.0014658,-80823.0859375,-80807.484375,57.0588819038522,20.554770872742,11.139823,0,0,0,40,4449,10.03265,-80815.28515625,,,,,,,,,,,,,0,,,,0,,,,,,10.0013504,,,,
,32897138.97,10.002924,-76282.70703125,0.000187611413425361,9.12055733462471E-7,1,0.999253354069792,40.0298881530762,1.99467568643225,21.9000000506639,0.00211268918581011,0.000419710663985434,0.25,3.36049661146789E-6,0.000187832138000846,4.7372011481797E-6,10.0027943,10.0030537,-76290.40625,-76275.0078125,57.7771985130253,20.5575669566009,11.139823,0,0,0,40,4449,10.0291,-76282.70703125,,,,,,,,,,,,,0,,,,-0.0049,,,,,,10.002924,,,,
,32897230.545,10.0036421,-71705.02734375,0.000173068018902264,1.06295030673579E-6,1,0.999253354069792,40.0298881530762,1.9945104984214,21.9000000506639,0.00195031685818135,0.000374367402633447,0.25,1.97030596035413E-6,0.000173215722713484,3.24850271897449E-6,10.0036421,10.0036421,-71712.9140625,-71697.140625,57.2863358029484,20.5586352324961,10.760172,0,0,0,40,4449,10.0265,-71705.02734375,,,,,,,,,,,,,0,,,,0.0049,,,,,,10.0036421,,,,
,32897323.78,10.003931,-67048.56640625,0.000155682536414368,9.1112354964668E-7,1,0.999253354069792,40.0298881530762,1.99487910749837,21.9000000506639,0.00175403623811882,0.000336547349850176,0.25,1.7528537168161E-6,0.000155753620349116,2.90871625791637E-6,10.003931,10.003931,-67056.15625,-67040.9765625,56.7368509539291,20.5529716002147,11.519473,0,0,0,40,4449,10.02365,-67048.56640625,,,,,,,,,,,,,0,,,,-0.00245,,,,,,10.003931,,,,
,32897416.555,10.0036745,-62410.44921875,0.000137547680776728,9.80162504442336E-7,1,0.999253354069792,40.0298881530762,1.99457349987783,21.9000000506639,0.00154499283077789,0.000318544324926525,0.25,3.43884095231331E-6,0.000137539155622002,4.46276582759271E-6,10.0036745,10.0036745,-62417.953125,-62402.9453125,57.6318156084484,20.558243574907,11.139823,0,0,0,40,4449,10.0211,-62410.44921875,,,,,,,,,,,,,0,,,,0,,,,,,10.0036745,,,,
,32897512.04,10.0037794,-57638.08984375,0.00012071016703307,1.21641139432696E-6,1,0.999253354069792,40.0298881530762,1.99444037563375,21.9000000506639,0.00135335941410379,0.000289467966551091,0.25,3.90976761385409E-6,0.000120641949172554,4.80650717199356E-6,10.0037794,10.0037794,-57650.5625,-57625.6171875,57.1855057239676,20.5596614247942,11.139823,0,0,0,40,4449,10.0173,-57638.08984375,,,,,,,,,,,,,0,,,,-0.00245,,,,,,10.0037794,,,,
,32897606.15,10.0035934,-52933.38671875,0.000106695438555431,1.02990338403309E-6,1,0.999253354069792,40.0298881530762,1.99508282094923,21.9000000506639,0.00120146350651799,0.00022577819802203,0.25,7.94294281135694E-7,0.000106605870184616,1.58423009104735E-6,10.0035934,10.0035934,-52938.3828125,-52928.390625,57.0283983916022,20.5446723862926,10.760172,0,0,0,40,4449,10.01335,-52933.38671875,,,,,,,,,,,,,0,,,,0.00245,,,,,,10.0035934,,,,
,32897701.58,10.0041342,-48166.275390625,8.78748060498977E-5,1.20742972092378E-6,1,0.999253354069792,40.0298881530762,1.9947906051114,21.9000000506639,0.000988881866412254,0.000186017409352651,0.25,6.75436563494319E-7,8.77585480677739E-5,1.32021432182543E-6,10.0041342,10.0041342,-48176.46484375,-48156.0859375,57.0018230219483,20.5547548032258,10.760172,0,0,0,40,4449,10.0098,-48166.275390625,,,,,,,,,,,,,0,,,,0,,,,,,10.0041342,,,,
,32897795.06,10.0043888,-43491.373046875,7.68142658272035E-5,9.3147619230018E-7,1,0.999253354069792,40.0298881530762,1.99439132436635,21.9000000506639,0.000867090423355084,0.00014438311785332,0.25,-1.01071379608118E-6,7.66870390905391E-5,-4.51910530008216E-7,10.0043888,10.0043888,-43498.82421875,-43483.921875,56.8423708040252,20.5588201701923,11.139823,0,0,0,40,4449,10.0061,-43491.373046875,,,,,,,,,,,,,0,,,,0,,,,,,10.0043888,,,,
,32897887.83,10.0038834,-38856.609375,5.29793218242819E-5,6.75216204992206E-7,1,0.999253354069792,40.0298881530762,1.99455295478723,21.9000000506639,0.000602149112860834,7.53142444025987E-5,0.25,-2.84244264058896E-6,5.28808528759183E-5,-2.45881997915905E-6,10.0038834,10.0038834,-38866.65625,-38846.5625,57.0135474497368,20.5580936990353,10.760172,0,0,0,40,4449,10.0036,-38856.609375,,,,,,,,,,,,,0,,,,0.0049,,,,,,10.0038834,,,,
,32897981.095,10.0031357,-34196.8359375,3.81503684247142E-5,8.22557527583837E-7,1,0.999253354069792,40.0298881530762,1.99464804655941,21.9000000506639,0.000432826861358282,5.74387821852278E-5,0.25,-1.75340741738112E-6,3.80582039708025E-5,-1.48343025737338E-6,10.0031357,10.0031357,-34204.171875,-34189.5,57.0690430746022,20.5547378782784,10.760172,0,0,0,40,4449,10.0017,-34196.8359375,,,,,,,,,,,,,0,,,,0.00245,,,,,,10.0031357,,,,
,32898073.025,10.0018177,-29602.0947265625,2.08711352672718E-5,7.35161165589392E-7,1,0.999253354069792,40.0298881530762,1.9945676460439,21.9000000506639,0.000237540769164904,2.65135605282285E-5,0.25,-1.39005392957585E-6,2.08133009973402E-5,-1.24479812225145E-6,10.0018177,10.0018177,-29607.12890625,-29597.060546875,56.7071490701983,20.5575221499648,10.760172,0,0,0,40,4449,9.9996,-29602.0947265625,,,,,,,,,,,,,0,,,,-0.00245,,,,,,10.0018177,,,,
,32898163.33,10.0011168,-25086.8310546875,6.64793665856228E-6,4.31084608278207E-7,1,0.999253354069792,40.0298881530762,1.9944375833185,21.9000000506639,7.90511279279402E-5,-1.06908882166736E-5,0.25,-2.14307466985131E-6,6.63736319063502E-6,-2.09191659804222E-6,10.0011168,10.0011168,-25089.109375,-25084.552734375,57.1237570709483,20.5586966528524,11.139823,0,0,0,40,4449,9.99925,-25086.8310546875,,,,,,,,,,,,,0,,,,0,,,,,,10.0011168,,,,
,32898254.985,10.0010395,-20507.0791015625,-7.79674171310575E-6,6.68947404968685E-7,1,0.999253354069792,40.0298881530762,1.99485891399291,21.9000000506639,-8.51664987370661E-5,-2.94310529917725E-5,0.25,-1.22285628846877E-6,-7.75679547133276E-6,-1.26635693921593E-6,10.0010395,10.0010395,-20512.0546875,-20502.103515625,57.4403166212368,20.5496494618553,11.139823,0,0,0,40,4449,9.9989,-20507.0791015625,,,,,,,,,,,,,0,,,,0,,,,,,10.0010395,,,,
,32898345.07,10.0004063,-16004.6342773438,-2.27156822968385E-5,4.443328189603E-7,1,0.999253354069792,40.0298881530762,1.99520720041395,21.9000000506639,-0.000252827901713842,-5.91461365920246E-5,0.25,-1.20407933538819E-6,-2.26046429753503E-5,-1.33323095742817E-6,10.0004063,10.0004063,-16009.7099609375,-15999.55859375,57.2808644033138,20.5435896923612,11.519473,0,0,0,40,4449,9.9985,-16004.6342773438,,,,,,,,,,,,,0,,,,0,,,,,,10.0004063,,,,
,32898436.17,9.99897,-11451.9057617187,-3.69011341192153E-5,4.22722465707835E-7,1,0.999253354069792,40.0298881530762,1.99476776253425,21.9000000506639,-0.00041340389880615,-7.95659497107937E-5,0.25,-5.02548569629995E-7,-3.67147412329268E-5,-7.06732761603764E-7,9.99897,9.99897,-11456.7333984375,-11447.078125,57.261323690333,20.5520003992571,11.519473,0,0,0,40,4449,10.00075,-11451.9057617187,,,,,,,,,,,,,0,,,,0,,,,,,9.99897,,,,
,32898527.11,9.9987965,-6906.41723632813,-5.12310529414009E-5,3.91068888284141E-7,1,0.999253354069792,40.0298881530762,1.99495247074868,21.9000000506639,-0.000573554720738903,-0.000111742566828364,0.25,-8.31400664229252E-7,-5.09534363761341E-5,-1.09672978676416E-6,9.9987965,9.9987965,-6908.83984375,-6903.99462890625,57.291807202583,20.5469072484234,11.139823,0,0,0,40,4449,10.0019,-6906.41723632813,,,,,,,,,,,,,0,,,,0,,,,,,9.9987965,,,,
,32898617.24,9.9995947,-2402.71447753906,-6.41645201115606E-5,2.75850184572926E-7,1,0.999253354069792,40.0298881530762,1.99484460487426,21.9000000506639,-0.000718370235475294,-0.000138389751887278,0.25,-9.26657137613728E-7,-6.3798610854838E-5,-1.23907189898444E-6,9.9995947,9.9995947,-2405.47802734375,-2399.95092773438,57.2441278629099,20.5468947321248,11.519473,0,0,0,40,4449,10.0008,-2402.71447753906,,,,,,,,,,,,,0,,,,0,,,,,,9.9995947,,,,
,32898705.445,9.9996815,2004.72467041016,-7.52336890767604E-5,3.00420556665003E-7,1,0.999253354069792,40.0298881530762,1.9946776027734,21.9000000506639,-0.000843121805856075,-0.000157126318541114,0.25,-6.32154439778347E-7,-7.48052427544183E-5,-9.99115778096884E-7,9.9996815,9.9996815,1999.52819824219,2009.92114257813,57.2370932062368,20.5517645618325,11.139823,0,0,0,40,4449,10.0017,2004.72467041016,,,,,,,,,,,,,0,,,,-0.0049,,,,,,9.9996815,,,,
,32898795.85,9.998436,6525.29541015625,-8.63075112949061E-5,3.14318107267752E-7,1,0.999253354069792,40.0298881530762,1.99456048120238,21.9000000506639,-0.000967855506925757,-0.000178029956197617,0.25,-4.96263121797109E-7,-8.5842198953767E-5,-9.45659074696845E-7,9.998436,9.998436,6512.73388671875,6537.85693359375,57.0909286731407,20.5549350128394,10.760172,0,0,0,40,4449,10.00215,6525.29541015625,,,,,,,,,,,,,0,,,,0.0049,,,,,,9.998436,,,,
,32898884.64,9.99916175,10961.2783203125,-9.47132431820459E-5,3.12741892311068E-7,1,0.999253354069792,40.0298881530762,1.994676783026,21.9000000506639,-0.00106264640129064,-0.00019488250682084,0.25,-4.63306791975883E-7,-9.42356041261997E-5,-9.8805723586221E-7,9.9990616,9.9992619,10931.1748046875,10991.3818359375,56.8877052581406,20.5534574264516,11.139823,0,0,0,40,4449,10.00165,10961.2783203125,,,,,,,,,,,,,0,,,,-0.00245,,,,,,9.99916175,,,,
,32898976.655,10.0007963,15558.9633789062,-9.53201996730527E-5,4.56537590387768E-7,1,0.999253354069792,40.0298881530762,1.99482157571909,21.9000000506639,-0.00107171434649413,-0.000186415602737789,0.25,4.38392165719492E-7,-9.48829027405006E-5,-1.25717834763398E-7,10.0007963,10.0007963,15549.0791015625,15568.84765625,57.0190188493714,20.5500953704389,10.760172,0,0,0,40,4449,10.0014,15558.9633789062,,,,,,,,,,,,,0,,,,-0.0049,,,,,,10.0007963,,,,
,32899067.655,10.0000687,20108.828125,-8.62172169888392E-5,6.81796254199129E-7,1,0.999253354069792,40.0298881530762,1.9949741055413,21.9000000506639,-0.000968167261169914,-0.000178149949697058,0.25,-4.18012246903567E-7,-8.58537840082135E-5,-9.51160939042986E-7,10.0000687,10.0000687,20101.3125,20116.34375,57.0995265868522,20.5444385512374,10.38052,0,0,0,40,4449,10.00155,20108.828125,,,,,,,,,,,,,0,,,,-0.00245,,,,,,10.0000687,,,,
,32899160.375,10.0006447,24744.17578125,-7.00337503043108E-5,5.42529897773208E-7,1,0.999253354069792,40.0298881530762,1.99498927178262,21.9000000506639,-0.000788450007905924,-0.000135619575154019,0.25,4.9469717974575E-7,-6.97762307508336E-5,3.85526045293392E-8,10.0006447,10.0006447,24734.1015625,24754.25,56.7767140084099,20.5444398416048,11.519473,0,0,0,40,4449,10.0015,24744.17578125,,,,,,,,,,,,,0,,,,-0.0049,,,,,,10.0006447,,,,
,32899249.86,9.9996367,29217.4541015625,-5.65843121474835E-5,7.2052269218172E-7,1,0.999253354069792,40.0298881530762,1.99485019118184,21.9000000506639,-0.000639040286832866,-9.98676583866159E-5,0.25,1.28003903833005E-6,-5.64084270792584E-5,8.95266267891048E-7,9.9996367,9.9996367,29207.572265625,29227.3359375,57.576319983583,20.5486007013543,10.760172,0,0,0,40,4449,10.00065,29217.4541015625,,,,,,,,,,,,,0,,,,0,,,,,,9.9996367,,,,
,32899342.89,9.9989185,33867.5390625,-5.7132331296787E-5,6.97875286514129E-7,1,0.999253354069792,40.0298881530762,1.99475629696278,21.9000000506639,-0.000645949418212049,-9.85014826681922E-5,0.25,1.51578083522084E-6,-5.69845788177943E-5,1.11522828759888E-6,9.9989185,9.9989185,33860.1484375,33874.9296875,56.9689946241406,20.5508293631321,11.139823,0,0,0,40,4449,10.0014,33867.5390625,,,,,,,,,,,,,0,,,,0.00245,,,,,,9.9989185,,,,
,32899432.405,9.999135,38340.009765625,-6.24248934897267E-5,9.10722692935343E-7,1,0.999253354069792,40.0298881530762,1.99510436352239,21.9000000506639,-0.000710132014839184,-8.6095491360153E-5,0.25,3.58485366710282E-6,-6.23070665034295E-5,3.13316725037648E-6,9.999135,9.999135,38337.41796875,38342.6015625,56.8978664288906,20.5457183032206,10.760172,0,0,0,40,4449,10.00235,38340.009765625,,,,,,,,,,,,,0,,,,-0.00245,,,,,,9.999135,,,,
,32899523.69,9.9984808,42902.892578125,-7.4973592212811E-5,1.05855601997633E-6,1,0.999253354069792,40.0298881530762,1.99542940967744,21.9000000506639,-0.000851898102388894,-0.000112006366038213,0.25,3.55752700359512E-6,-7.48633784381281E-5,3.00848369374529E-6,9.9984808,9.9984808,42895.42578125,42910.359375,56.9775925378522,20.5355750309048,11.139823,0,0,0,40,4449,10.00395,42902.892578125,,,,,,,,,,,,,0,,,,0.00245,,,,,,9.9984808,,,,
,32899615.14,9.9973564,47473.572265625,-8.96701748382288E-5,8.25325051797124E-7,1,0.999253354069792,40.0298881530762,1.99537870911948,21.9000000506639,-0.00101985767151384,-0.000131240263546931,0.25,4.51034213938827E-6,-8.95833052570306E-5,3.84655424531618E-6,9.9973564,9.9973564,47468.3984375,47478.74609375,57.0104209356599,20.5359430925237,11.139823,0,0,0,40,4449,10.0053,47473.572265625,,,,,,,,,,,,,0,,,,0,,,,,,9.9973564,,,,
,32899706.055,9.996768,52018.662109375,-0.000101912166173399,1.07660679730954E-6,1,0.999253354069792,40.0298881530762,1.99525842648685,21.9000000506639,-0.00115582125669189,-0.000169991242730096,0.25,3.29013804198852E-6,-0.000101847271278199,2.53309272631489E-6,9.9967241,9.9968119,52011.328125,52025.99609375,57.1526773261599,20.5382861217522,11.519473,0,0,0,40,4449,10.0095,52018.662109375,,,,,,,,,,,,,0,,,,0.0049,,,,,,9.996768,,,,
,32899795.085,9.9959488,56469.08203125,-0.000117989769303571,1.12862490694156E-6,1,0.999253354069792,40.0298881530762,1.99503250568138,21.9000000506639,-0.00133308603301017,-0.000227507817285232,0.25,1.09701423707454E-6,-0.000117946376683637,2.19317383062254E-7,9.9959488,9.9959488,56463.98046875,56474.18359375,57.017455592333,20.5431774816071,11.139823,0,0,0,40,4449,10.01275,56469.08203125,,,,,,,,,,,,,0,,,,0.0049,,,,,,9.9959488,,,,
,32899886.065,9.9959545,61014.48046875,-0.000132461982833498,1.32932663367601E-6,1,0.999253354069792,40.0298881530762,1.99536384813136,21.9000000506639,-0.00149456206825055,-0.00027176244959355,0.25,-2.02969955381785E-7,-0.000132459809919302,-1.18892692950716E-6,9.9959545,9.9959545,61012.0859375,61016.875,56.9854088230445,20.5333888926495,11.139823,0,0,0,40,4449,10.0155,61014.48046875,,,,,,,,,,,,,0,,,,0,,,,,,9.9959545,,,,
,32899975.075,9.9958334,65462.658203125,-0.000146604645286362,1.25653578873819E-6,1,0.999253354069792,40.0298881530762,1.99540324525391,21.9000000506639,-0.00165092628424728,-0.000322587717007053,0.25,-2.14757432265684E-6,-0.000146647350188928,-3.23750556062171E-6,9.9958334,9.9958334,65460.2109375,65465.10546875,56.7751507513714,20.5317443638105,11.139823,0,0,0,40,4449,10.0175,65462.658203125,,,,,,,,,,,,,0,,,,0,,,,,,9.9958334,,,,
,32900064.065,9.9964833,69910.51953125,-0.000163553974746083,1.08660476549927E-6,1,0.999253354069792,40.0298881530762,1.99516663417821,21.9000000506639,-0.00184707866768371,-0.000333449781061926,0.25,-5.2843544313135E-8,-0.000163682264443952,-1.26218751091233E-6,9.9963369,9.9966297,69902.796875,69918.2421875,57.3011867448138,20.5358263627548,10.760172,0,0,0,40,4449,10.02225,69910.51953125,,,,,,,,,,,,,0,,,,0,,,,,,9.9964833,,,,
,32900154.65,9.9954748,74438.41796875,-0.000179297374569813,8.13687641385476E-7,1,0.999253354069792,40.0298881530762,1.99530505332488,21.9000000506639,-0.00202589764598019,-0.000364972767080288,0.25,-2.88908010561066E-9,-0.000179505493909043,-1.31907694973727E-6,9.9954748,9.9954748,74426.0390625,74450.796875,56.8845787440637,20.5354687855648,11.139823,0,0,0,40,4449,10.0262,74438.41796875,,,,,,,,,,,,,0,,,,-0.00245,,,,,,9.9954748,,,,
,32900244.89,9.9954128,78951.7578125,-0.000196863921049697,9.92640279256531E-7,1,0.999253354069792,40.0298881530762,1.99536919946118,21.9000000506639,-0.00222195990468949,-0.00041907403666131,0.25,-1.62628055713425E-6,-0.000197150130743375,-3.06047100383946E-6,9.9954128,9.9954128,78944.3203125,78959.1953125,56.9072459711214,20.5338576954802,11.139823,0,0,0,40,4449,10.0303,78951.7578125,,,,,,,,,,,,,0,,,,0.00245,,,,,,9.9954128,,,,
,32900333.555,9.99552965,83382.91796875,-0.000212790502594985,1.13767846604776E-6,1,0.999253354069792,40.0298881530762,1.99528493581207,21.9000000506639,-0.00240763269218538,-0.000424080596578149,0.25,7.9199391483655E-7,-0.000213188030786215,-7.37247224660331E-7,9.9953957,9.9956636,83352.8671875,83412.96875,56.882233858506,20.5332141139986,10.760172,0,0,0,40,4449,10.034,83382.91796875,,,,,,,,,,,,,0,,,,0,,,,,,9.99552965,,,,
,32900419.24,9.99525165,87663.91015625,-0.00022788807566202,1.08785771447134E-6,1,0.999253354069792,40.0298881530762,1.9953199549043,21.9000000506639,-0.00257483714618273,-0.000478924218341245,0.25,-1.34791405513733E-6,-0.000228366188932729,-2.97046583876789E-6,9.9948149,9.9956884,87656.4765625,87671.34375,57.088583787583,20.5318487188322,10.760172,0,0,0,40,4449,10.0387,87663.91015625,,,,,,,,,,,,,0,,,,-0.00245,,,,,,9.99525165,,,,
,32900520.21,9.9975853,88265.5234375,-0.000229024586719023,1.32146278669172E-6,1,0.999253354069792,40.0298881530762,1.99520188275348,21.9000000506639,-0.00259061758304009,-0.00046473396004885,0.25,1.07472679699659E-7,-0.000229524772741928,-1.51711403572902E-6,9.9975853,9.9975853,88257.859375,88273.1875,56.5328459104098,20.5371817785791,10.760172,0,0,0,40,4449,10.04055,88265.5234375,,,,,,,,,,,,,0,,,,-0.0049,,,,,,9.9975853,,,,
,32900604.835,10.0001192,84037.65625,-0.000215451708216555,1.16386267565792E-6,1,0.999253354069792,40.0298881530762,1.99498425628226,21.9000000506639,-0.00243352901837289,-0.000451440449463361,0.25,-1.15543480191094E-6,-0.000215850222999599,-2.70474208353766E-6,10.0001192,10.0001192,84035.4296875,84039.8828125,57.004167907506,20.5417334067449,10.760172,0,0,0,40,4449,10.0399,84037.65625,,,,,,,,,,,,,0,,,,0,,,,,,10.0001192,,,,
,32900696.24,10.0015945,79463.1875,-0.000197477319903724,1.21909886884235E-6,1,0.999253354069792,40.0298881530762,1.99506744121255,21.9000000506639,-0.00223175468714634,-0.00040307964581186,0.25,-1.06360792734377E-7,-0.000197783165309126,-1.54102464665581E-6,10.0015945,10.0015945,79455.578125,79470.796875,57.0471574760637,20.5394251998813,10.760172,0,0,0,40,4449,10.03955,79463.1875,,,,,,,,,,,,,0,,,,0.0049,,,,,,10.0015945,,,,
,32900789.875,10.0025015,74783.62109375,-0.000181282246660104,1.04930177947331E-6,1,0.999253354069792,40.0298881530762,1.99508563124714,21.9000000506639,-0.00205068036046528,-0.00035502872731076,0.25,1.23141073989077E-6,-0.0001815067452298,-9.70273542916485E-8,10.0023527,10.0026503,74770.265625,74796.9765625,57.2253687784484,20.5398144225454,10.760172,0,0,0,40,4449,10.0358,74783.62109375,,,,,,,,,,,,,0,,,,-0.00245,,,,,,10.0025015,,,,
,32900882.835,10.0031605,70138.8828125,-0.000163882302553626,1.13681380264095E-6,1,0.999253354069792,40.0298881530762,1.99520365613382,21.9000000506639,-0.00185472541413709,-0.000312652726618934,0.25,1.84836500304925E-6,-0.000164028071881186,6.38497438925864E-7,10.0031605,10.0031605,70133.78125,70143.984375,57.3449579418907,20.5342437006944,11.139823,0,0,0,40,4449,10.031,70138.8828125,,,,,,,,,,,,,0,,,,0.0049,,,,,,10.0031605,,,,
,32900974.425,10.003849,65560.99609375,-0.000146251311532925,1.23003868358098E-6,1,0.999253354069792,40.0298881530762,1.9948659453503,21.9000000506639,-0.0016530072220008,-0.000285839097606829,0.25,1.03707876432773E-6,-0.000146318810088383,-4.88622627784896E-8,10.003849,10.003849,65556.0625,65565.9296875,57.1167224142753,20.5468423336907,10.760172,0,0,0,40,4449,10.02875,65560.99609375,,,,,,,,,,,,,0,,,,0,,,,,,10.003849,,,,
,32901067.235,10.0037899,60920.232421875,-0.000130176067368228,1.15549832244909E-6,1,0.999253354069792,40.0298881530762,1.99504867372436,21.9000000506639,-0.00147358543707969,-0.000239015880511727,0.25,2.28313229145724E-6,-0.000130191266907888,1.31414801608758E-6,10.0037899,10.0037899,60912.53125,60927.93359375,56.7939098358329,20.5369912002266,11.139823,0,0,0,40,4449,10.0253,60920.232421875,,,,,,,,,,,,,0,,,,0,,,,,,10.0037899,,,,
,32901159.24,10.0036221,56319.58203125,-0.000116873924715382,1.12818835397823E-6,1,0.999253354069792,40.0298881530762,1.99476832508478,21.9000000506639,-0.00132423736613498,-0.000203439958440059,0.25,3.0270589859161E-6,-0.00011684367119095,2.15685572840743E-6,10.0036221,10.0036221,56314.63671875,56324.52734375,57.0291800201214,20.5486977792692,11.139823,0,0,0,40,4449,10.0232,56319.58203125,,,,,,,,,,,,,0,,,,0,,,,,,10.0036221,,,,
,32901252.43,10.0042276,51661.6875,-9.81371936298959E-5,8.66003160824081E-7,1,0.999253354069792,40.0298881530762,1.99506311375018,21.9000000506639,-0.00111305542639337,-0.00016261062123215,0.25,3.26216162665908E-6,-9.80718684462856E-5,2.53334950458401E-6,10.0042276,10.0042276,51656.6484375,51666.7265625,56.5359724244868,20.543630465155,10.38052,0,0,0,40,4449,10.01855,51661.6875,,,,,,,,,,,,,0,,,,0,,,,,,10.0042276,,,,
,32901344.035,10.004427,47084.208984375,-8.16949821225867E-5,1.08672268453788E-6,1,0.999253354069792,40.0298881530762,1.99500700072207,21.9000000506639,-0.000926925946711755,-0.000130774361123254,0.25,3.11185882258354E-6,-8.16052206918604E-5,2.50889194356419E-6,10.004427,10.004427,47079.03515625,47089.3828125,56.8345545188329,20.5441009466486,10.38052,0,0,0,40,4449,10.015,47084.208984375,,,,,,,,,,,,,0,,,,-0.0049,,,,,,10.004427,,,,
,32901436.915,10.0039349,42443.7421875,-6.16974346440724E-5,8.13889998404321E-7,1,0.999253354069792,40.0298881530762,1.99517009249202,21.9000000506639,-0.000702184222120381,-8.51601490085645E-5,0.25,3.5479660994752E-6,-6.1608207646123E-5,3.09557670433512E-6,10.0039349,10.0039349,42441.09765625,42446.38671875,57.2574155477368,20.5397702341294,10.38052,0,0,0,40,4449,10.0119,42443.7421875,,,,,,,,,,,,,0,,,,0,,,,,,10.0039349,,,,
,32901526.72,10.0030909,37953.31640625,-4.8124136405852E-5,8.33348701960443E-7,1,0.999253354069792,40.0298881530762,1.99478464098245,21.9000000506639,-0.000546842657870413,-6.91403465345997E-5,0.25,2.51593886776187E-6,-4.80295352581774E-5,2.16881761419762E-6,10.0030909,10.0030909,37923.10546875,37983.52734375,57.2363115777176,20.5509135950851,10.38052,0,0,0,40,4449,10.0096,37953.31640625,,,,,,,,,,,,,0,,,,0.00245,,,,,,10.0030909,,,,
,32901617.225,10.00304365,33430.978515625,-3.25128049667259E-5,8.17289302294227E-7,1,0.999253354069792,40.0298881530762,1.99513971587739,21.9000000506639,-0.000369252204609711,-4.71280205662438E-5,0.25,1.65592593261431E-6,-3.24326911545355E-5,1.42629646363816E-6,10.0029306,10.0031567,33425.92578125,33436.03125,56.9807190519291,20.5415009252881,10.38052,0,0,0,40,4449,10.0075,33430.978515625,,,,,,,,,,,,,0,,,,0.0049,,,,,,10.00304365,,,,
,32901711.11,10.0019655,28738.3662109375,-1.73605534070797E-5,5.53701786053044E-7,1,0.999253354069792,40.0298881530762,1.99485153002031,21.9000000506639,-0.000197416179128981,-2.30458828180783E-5,0.25,1.06738966470569E-6,-1.73102333792988E-5,9.47500887313051E-7,10.0019655,10.0019655,28728.59375,28748.138671875,56.9510171681983,20.5487325492137,10.38052,0,0,0,40,4449,10.0063,28738.3662109375,,,,,,,,,,,,,0,,,,-0.0049,,,,,,10.0019655,,,,
,32901805.525,10.0012808,24018.234375,-2.75501038872102E-6,5.64820679381847E-7,1,0.999253354069792,40.0298881530762,1.99529407651499,21.9000000506639,-3.38702346200126E-5,1.0574090544164E-5,0.25,1.43417987841029E-6,-2.7537937448925E-6,1.41097915847374E-6,10.0012808,10.0012808,24010.94140625,24025.52734375,57.0971817012945,20.5409110927308,10.760172,0,0,0,40,4449,10.00655,24018.234375,,,,,,,,,,,,,0,,,,0.0049,,,,,,10.0012808,,,,
,32901904.79,10.0007086,19058.5849609375,1.42041072721664E-5,5.28730298557163E-7,1,0.999253354069792,40.0298881530762,1.99466431875156,21.9000000506639,0.000157233078358148,4.18085523888044E-5,0.25,1.17926449121015E-6,1.41359814225743E-5,1.2613588137567E-6,10.0007086,10.0007086,19048.6484375,19068.521484375,57.105779615006,20.5523172031454,10.760172,0,0,0,40,4449,10.00485,19058.5849609375,,,,,,,,,,,,,0,,,,-0.00245,,,,,,10.0007086,,,,
,32902001.92,10.0006618,14203.830078125,2.88534922924103E-5,3.89476848318322E-7,1,0.999253354069792,40.0298881530762,1.99527425386439,21.9000000506639,0.000322567841807317,6.69102476338813E-5,0.25,8.02556831472637E-7,2.87121622709411E-5,9.66127179640381E-7,10.0006618,10.0006618,14196.388671875,14211.271484375,57.1839424669291,20.5397919177209,10.760172,0,0,0,40,4449,10.0058,14203.830078125,,,,,,,,,,,,,0,,,,-0.0049,,,,,,10.0006618,,,,
,32902099.815,9.998929,9311.615234375,4.43105420901074E-5,4.29312883423137E-7,1,0.999253354069792,40.0298881530762,1.99508342813702,21.9000000506639,0.000496504829830948,9.49516740977741E-5,0.25,5.58075310630961E-7,4.40793211894585E-5,7.96387782027979E-7,9.998929,9.998929,9304.041015625,9319.189453125,56.8259566051214,20.5468649742383,11.139823,0,0,0,40,4449,10.007,9311.615234375,,,,,,,,,,,,,0,,,,0,,,,,,9.998929,,,,
,32902198.595,9.9989557,4373.27001953125,5.92981829645693E-5,3.27559770486818E-7,1,0.999253354069792,40.0298881530762,1.99478801105861,21.9000000506639,0.000665193470011426,0.000120915042658506,0.25,2.25694215814836E-7,5.89703147340919E-5,5.2588244704168E-7,9.9989557,9.9989557,4365.7724609375,4380.767578125,57.2441278629099,20.5507328650787,10.38052,0,0,0,40,4449,10.00735,4373.27001953125,,,,,,,,,,,,,0,,,,0,,,,,,9.9989557,,,,
,32902286.575,10.0023193,-0.479548871517181,7.1327735181699E-5,3.73949866570209E-7,1,0.999253354069792,40.0298881530762,1.99485332601793,21.9000000506639,0.000801223038367871,0.000138381434812938,0.25,-3.36361337954875E-7,7.09196084779059E-5,9.3659978441508E-9,10.0023193,10.0023193,-0.502384543418884,-0.456713199615479,57.1198489283522,20.5496602638607,10.760172,0,0,0,40,4417,10.00315,-0.479548871517181,,,,,,,,,,,,,0,,,,0,,,,,,10.0023193,,,,