File: data/doubleLayers/dl_2-5/ppms/data/DD205_5_HYST_FC40000OE_10KREPEAT.DAT
[Header]
; VSM Data File (default extension .dat)
; Copyright (c) 2003-2013, Quantum Design, Inc. All rights reserved.
TITLE,
FILEOPENTIME,32910460.98,01/17/2019,5:50 am
BYAPP,VSM,2.0,2.0
INFO,PPMS VSM Option Release 1.4.10 Build 1,APPNAME
INFO,Quantum Design Linear Motor Servo Controller,MOTOR_MODULE_NAME
INFO,3101-100 M1,MOTOR_HW_VERSION
INFO,MMC1014,MOTOR_SERIAL_NUMBER
INFO,SRV No X-over 01.03.11,MOTOR_SOFTWARE_VERSION
INFO,Quantum Design VSM Detection Module,VSM_MODULE_NAME
INFO,3101-150 F0,VSM_HW_VERSION
INFO,VSM707,VSM_SERIAL_NUMBER
INFO,VSM No X-over 01.02.05 May 20 2008 13:51:47,VSM_SOFTWARE_VERSION
INFO,704,PREAMP_SERIAL_NUMBER
INFO,822,COIL_SERIAL_NUMBER
INFO,0,MOMENT_UNITS
INFO,DL 2.5,SAMPLE_MATERIAL
INFO,CoFe2O4,SAMPLE_COMMENT
INFO,29.51,SAMPLE_MASS
INFO,,SAMPLE_VOLUME
INFO,,SAMPLE_MOLECULAR_WEIGHT
INFO,,SAMPLE_SIZE
INFO,,SAMPLE_SHAPE
DATATYPE,COMMENT,1
DATATYPE,TIME,2
STARTUPAXIS,X,2
STARTUPAXIS,Y1,5
[Data]
Comment,Time Stamp (sec),Temperature (K),Magnetic Field (Oe),Moment (emu),M. Std. Err. (emu),Transport Action,Averaging Time (sec),Frequency (Hz),Peak Amplitude (mm),Center Position (mm),Coil Signal' (mV),Coil Signal" (mV),Range (mV),M. Quad. Signal (emu),M. Raw' (emu),M. Raw" (emu),Min. Temperature (K),Max. Temperature (K),Min. Field (Oe),Max. Field (Oe),Mass (grams),Motor Lag (deg),Pressure (Torr),VSM Status (code),Motor Status (code),Measure Status (code),Measure Count,PPMS Status (code),System Temp. (K),System Field (Oe),Sample Position (deg),Bridge 1 Resistance (ohms),Bridge 1 Excitation (에),Bridge 2 Resistance (ohms),Bridge 2 Excitation (에),Bridge 3 Resistance (ohms),Bridge 3 Excitation (에),Bridge 4 Resistance (ohms),Bridge 4 Excitation (에),Signal 1 Vin (V),Signal 2 Vin (V),Digital Inputs (code),Drive 1 Iout (mA),Drive 1 Ipower (W),Drive 2 Iout (mA),Drive 2 Ipower (W),Pressure (),Map 20 (),Map 21 (),Map 22 (),Map 23 (),Map 24 (),Map 25 (),Map 26 (),Map 27 (),Map 28 (),Map 29 ()
,32910476.16,10.0019836,39999.77734375,,,2,,,,21.8999994361401,,,,,,,10.0019836,10.0019836,39999.77734375,39999.77734375,,,12.278775,,,,-99999999,4369,9.9959,39999.77734375,,,,,,,,,,,,,,,,,,,,,,,10.0019836,,,,
,32910825.92,9.9977369,4436.51318359375,5.93298422904791E-5,3.27118590424718E-7,1,0.999253354069792,40.0298881530762,1.99373579540202,21.8899995088577,0.000665558564539283,0.000118994571998616,0.25,5.40132044940455E-8,5.90029184853337E-5,3.55571750812478E-7,9.9977264,9.9977474,4426.267578125,4446.7587890625,56.238953587179,20.53266189116,11.139823,0,0,0,40,4449,9.9944,4436.51318359375,,,,,,,,,,,,,0,,,,0,,,,,,9.9977369,,,,
,32910922.465,9.9994345,9260.01123046875,4.38949299445818E-5,3.7703423170239E-7,1,0.999253354069792,40.0298881530762,1.9938756070375,21.8899995088577,0.000492208424797276,9.03767955519736E-5,0.25,2.29629889748099E-7,4.36674583419695E-5,4.67202961968573E-7,9.9994345,9.9994345,9252.427734375,9267.5947265625,56.1498479359867,20.5284942143252,12.278775,0,0,0,40,4449,9.9948,9260.01123046875,,,,,,,,,,,,,0,,,,0.0049,,,,,,9.9994345,,,,
,32911016.83,10.0006266,13977.7221679688,2.93561100727986E-5,5.45148811617373E-7,1,0.999253354069792,40.0298881530762,1.99478047709282,21.8899995088577,0.000329369422128921,6.09653538634431E-5,0.25,1.85537194702516E-7,2.92153922278365E-5,3.54466635154325E-7,10.0006266,10.0006266,13975.28125,13980.1630859375,56.4429586306983,20.528822104201,11.519473,0,0,0,40,4449,9.9947,13977.7221679688,,,,,,,,,,,,,0,,,,-0.00245,,,,,,10.0006266,,,,
,32911113.55,10.0003633,18810.044921875,1.36691324494134E-5,6.29535557748715E-7,1,0.999253354069792,40.0298881530762,1.99552455850046,21.8899995088577,0.000153988601959258,2.56133119850651E-5,0.25,-1.66982329340017E-7,1.36112312443724E-5,-8.26200498861566E-8,10.0003633,10.0003633,18802.564453125,18817.525390625,57.1784710672945,20.5150206620236,11.899124,0,0,0,40,4449,9.9932,18810.044921875,,,,,,,,,,,,,0,,,,-0.0049,,,,,,10.0003633,,,,
,32911210.47,9.999361,23654.8984375,-2.18964321465087E-6,4.38023801968537E-7,1,0.999253354069792,40.0298881530762,1.99555837350249,21.8899995088577,-2.23354904347151E-5,-1.71843633625826E-5,0.25,-1.13562641590901E-6,-2.17395483602055E-6,-1.14533832487525E-6,9.999361,9.999361,23644.873046875,23664.923828125,56.943200883006,20.5114816878484,11.139823,0,0,0,40,4449,9.99315,23654.8984375,,,,,,,,,,,,,0,,,,0,,,,,,9.999361,,,,
,32911306.745,9.9998264,28465.150390625,-1.57650049455054E-5,7.7662331359788E-7,1,0.999253354069792,40.0298881530762,1.99424611495793,21.8899995088577,-0.000175214654872831,-4.32083690797788E-5,0.25,-1.01309878717033E-6,-1.57055878612537E-5,-1.11515890585149E-6,9.9998264,9.9998264,28452.703125,28477.59765625,56.4890747133329,20.5309814573677,11.899124,0,0,0,40,4449,9.9942,28465.150390625,,,,,,,,,,,,,0,,,,-0.00245,,,,,,9.9998264,,,,
,32911402.48,9.9994593,33250.603515625,-3.23123092138348E-5,5.80891575244654E-7,1,0.999253354069792,40.0298881530762,1.99574961235606,21.8899995088577,-0.000361242239799388,-7.93044896439067E-5,0.25,-1.23751530595858E-6,-3.22121317001066E-5,-1.45733866386614E-6,9.9994593,9.9994593,33245.49609375,33255.7109375,56.7274714116983,20.5143972133495,11.139823,0,0,0,40,4449,9.9927,33250.603515625,,,,,,,,,,,,,0,,,,0,,,,,,9.9994593,,,,
,32911495.305,9.998702,37893.029296875,-4.69468930127167E-5,5.62728594384571E-7,1,0.999253354069792,40.0298881530762,1.99574467072025,21.8899995088577,-0.000525239734482538,-0.000114545431125491,0.25,-1.72473420911256E-6,-4.68246758308328E-5,-2.05349240517549E-6,9.998702,9.998702,37883.40625,37902.65234375,56.5156500829868,20.5182560950459,11.519473,0,0,0,40,4449,9.99535,37893.029296875,,,,,,,,,,,,,0,,,,0,,,,,,9.998702,,,,
,32911589.7,9.9991131,42608.267578125,-6.25208354700444E-5,6.72376845315366E-7,1,0.999253354069792,40.0298881530762,1.99550381859929,21.8899995088577,-0.000699376421682891,-0.00015465686396029,0.25,-2.4706528633244E-6,-6.23876605431772E-5,-2.91809598180177E-6,9.9991131,9.9991131,42595.859375,42620.67578125,56.729816297256,20.5241316474114,11.139823,0,0,0,40,4449,9.99695,42608.267578125,,,,,,,,,,,,,0,,,,0.0049,,,,,,9.9991131,,,,
,32911684.815,9.9973269,47361.19140625,-8.1022367108422E-5,7.65293376661411E-7,1,0.999253354069792,40.0298881530762,1.99570256738592,21.8899995088577,-0.000908041889207412,-0.000194052159795711,0.25,-2.61797957580199E-6,-8.08938449975036E-5,-3.20860487068445E-6,9.9973269,9.9973269,47348.59375,47373.7890625,56.6532167023714,20.5129457770087,11.519473,0,0,0,40,4449,9.99815,47361.19140625,,,,,,,,,,,,,0,,,,0,,,,,,9.9973269,,,,
,32911778.79,9.9964676,52061.240234375,-9.7878655577423E-5,8.28208325994256E-7,1,0.999253354069792,40.0298881530762,1.99580103811161,21.8899995088577,-0.00110004887725157,-0.000220570698942596,0.25,-1.91724055190294E-6,-9.77791741345872E-5,-2.6399307298636E-6,9.9964676,9.9964676,52051.19140625,52071.2890625,56.6563432164483,20.5139580846399,11.899124,0,0,0,40,4449,10.0007,52061.240234375,,,,,,,,,,,,,0,,,,0.00245,,,,,,9.9964676,,,,
,32911877.885,9.9950781,57010.9609375,-0.000113174385477334,1.02652258517269E-6,1,0.999253354069792,40.0298881530762,1.99578815268955,21.8899995088577,-0.00126838515401257,-0.000278366519205332,0.25,-4.26948642106183E-6,-0.000113099117458888,-5.10953139999031E-6,9.9950781,9.9950781,57003.73046875,57018.19140625,57.1339182416984,20.514522188176,11.139823,0,0,0,40,4449,10.0054,57010.9609375,,,,,,,,,,,,,0,,,,0,,,,,,9.9950781,,,,
,32911974.61,9.9957256,61846.376953125,-0.000131369985636494,1.0173081529308E-6,1,0.999253354069792,40.0298881530762,1.99584560115966,21.8899995088577,-0.00147414696778237,-0.000317039441161955,0.25,-4.40314419815842E-6,-0.000131346691360163,-5.38114770530749E-6,9.9957256,9.9957256,61836.15625,61856.59765625,56.7509202672752,20.5123869099653,11.139823,0,0,0,40,4449,10.0096,61846.376953125,,,,,,,,,,,,,0,,,,-0.00245,,,,,,9.9957256,,,,
,32912072.595,9.9959335,66744.1171875,-0.000150845755708385,8.54244161251008E-7,1,0.999253354069792,40.0298881530762,1.99573573087324,21.8899995088577,-0.00169539445920411,-0.000352840012652503,0.25,-4.0553709033104E-6,-0.000150893112325046,-5.17681279684279E-6,9.9959335,9.9959335,66734.1640625,66754.0703125,56.9049010855637,20.5160372198896,11.139823,0,0,0,40,4449,10.0142,66744.1171875,,,,,,,,,,,,,0,,,,0.0049,,,,,,9.9959335,,,,
,32912170.19,9.9960575,71622.08984375,-0.000168498841228005,7.81784459354594E-7,1,0.999253354069792,40.0298881530762,1.99565150301522,21.8899995088577,-0.0018987714369015,-0.000370667756115234,0.25,-2.4480690495994E-6,-0.000168637576604447,-3.69315831691956E-6,9.9960575,9.9960575,71612.0859375,71632.09375,56.8595666314483,20.5153561516422,11.519473,0,0,0,40,4449,10.01655,71622.08984375,,,,,,,,,,,,,0,,,,0.00245,,,,,,9.9960575,,,,
,32912271.955,9.9960947,76710.109375,-0.000186714429841018,7.94593407853672E-7,1,0.999253354069792,40.0298881530762,1.9957782301315,21.8899995088577,-0.00210423055273335,-0.000415371121306469,0.25,-3.11855262233357E-6,-0.000186942031153493,-4.48728901701044E-6,9.9960947,9.9960947,76699.9296875,76720.2890625,56.9877537086022,20.5160264558293,11.519473,0,0,0,40,4449,10.02055,76710.109375,,,,,,,,,,,,,0,,,,-0.00245,,,,,,9.9960947,,,,
,32912367.405,9.9947577,81481.06640625,-0.000204061156852667,9.84353007451573E-7,1,0.999253354069792,40.0298881530762,1.99585202174572,21.8899995088577,-0.00229921327062724,-0.000462061500173632,0.25,-4.12534304513382E-6,-0.000204378882880325,-5.60748995374678E-6,9.9947577,9.9947577,81473.546875,81488.5859375,56.9596150819099,20.5185040575664,11.519473,0,0,0,40,4449,10.02545,81481.06640625,,,,,,,,,,,,,0,,,,-0.0049,,,,,,9.9947577,,,,
,32912461.985,9.9950314,86206.44140625,-0.000221079961225237,7.79678610055279E-7,1,0.999253354069792,40.0298881530762,1.99576402990907,21.8899995088577,-0.00249560442017325,-0.000479075090696478,0.25,-2.5743453862991E-6,-0.000221512656910254,-4.15757314351345E-6,9.9950314,9.9950314,86201.375,86211.5078125,57.0792042453522,20.5161771803441,11.519473,0,0,0,40,4449,10.0292,86206.44140625,,,,,,,,,,,,,0,,,,0.0049,,,,,,9.9950314,,,,
,32912573.25,9.9961672,89364.03515625,-0.000234015110851435,1.023079745116E-6,1,0.999253354069792,40.0298881530762,1.99566912133079,21.8899995088577,-0.00264159859555247,-0.000509776114073078,0.25,-2.9694391114862E-6,-0.00023452156954151,-4.63081526284903E-6,9.9961672,9.9961672,89356.4140625,89371.65625,57.1401712698522,20.5193638541341,11.519473,0,0,0,40,4449,10.03425,89364.03515625,,,,,,,,,,,,,0,,,,-0.00245,,,,,,9.9961672,,,,
,32912664.98,9.9992952,84781.85546875,-0.000214604522546933,7.87316155428502E-7,1,0.999253354069792,40.0298881530762,1.99569345123787,21.8899995088577,-0.00241926599102343,-0.000481205733948123,0.25,-3.92714208060334E-6,-0.000214992900832044,-5.47267430543244E-6,9.9992952,9.9992952,84774.28125,84789.4296875,56.9564885678329,20.5153421858397,11.519473,0,0,0,40,4449,10.03385,84781.85546875,,,,,,,,,,,,,0,,,,0,,,,,,9.9992952,,,,
,32912764.005,10.0007,79830.22265625,-0.000198834161091923,8.78965660822029E-7,1,0.999253354069792,40.0298881530762,1.99560614729906,21.8899995088577,-0.00224165795513903,-0.000439689056067837,0.25,-3.09131182132522E-6,-0.000199125949667955,-4.53931085104785E-6,10.0007,10.0007,79825.1640625,79835.28125,56.5437887096791,20.5229787929405,11.139823,0,0,0,40,4449,10.0311,79830.22265625,,,,,,,,,,,,,0,,,,-0.0049,,,,,,10.0007,,,,
,32912863.3,10.0026865,74866.33203125,-0.000181185103256177,1.07774573070941E-6,1,0.999253354069792,40.0298881530762,1.99574812712457,21.8899995088577,-0.0020410030011573,-0.000406258352061844,0.25,-3.30896436176805E-6,-0.000181377381051751,-4.64190151113305E-6,10.0026865,10.0026865,74856.734375,74875.9296875,56.7696793517368,20.5202982063573,11.519473,0,0,0,40,4449,10.02945,74866.33203125,,,,,,,,,,,,,0,,,,0,,,,,,10.0026865,,,,
,32912962.72,10.003726,69898.546875,-0.000160632329714797,1.02986735440658E-6,1,0.999253354069792,40.0298881530762,1.99561762561847,21.8899995088577,-0.00180650756960875,-0.00037176776004705,0.25,-3.96498029526149E-6,-0.000160729229366249,-5.15581472986186E-6,10.003726,10.003726,69893.5078125,69903.5859375,56.7712426087752,20.5225119017076,10.760172,0,0,0,40,4449,10.0257,69898.546875,,,,,,,,,,,,,0,,,,0,,,,,,10.003726,,,,
,32913062.005,10.002449,64935.443359375,-0.000142220929442548,8.88997254458791E-7,1,0.999253354069792,40.0298881530762,1.99572354427291,21.8899995088577,-0.0016005997626562,-0.000319250788707813,0.25,-2.6386705281926E-6,-0.000142251528997049,-3.69651333781462E-6,10.002449,10.002449,64920.4296875,64950.45703125,56.9588334533906,20.5212146551053,11.519473,0,0,0,40,4449,10.02255,64935.443359375,,,,,,,,,,,,,0,,,,-0.00735,,,,,,10.002449,,,,
,32913162.395,10.0030327,59917.279296875,-0.000124257922008941,8.5429986574063E-7,1,0.999253354069792,40.0298881530762,1.99569288954778,21.8899995088577,-0.00139696671980709,-0.000283271995194875,0.25,-2.70007136165881E-6,-0.000124224446611558,-3.62470033704287E-6,10.0030327,10.0030327,59907.17578125,59927.3828125,56.7220000120637,20.5196639168497,10.760172,0,0,0,40,4449,10.01965,59917.279296875,,,,,,,,,,,,,0,,,,0,,,,,,10.0030327,,,,
,32913258.64,10.0036201,55104.439453125,-0.000106594128621159,8.21008431480664E-7,1,0.999253354069792,40.0298881530762,1.99568938237608,21.8899995088577,-0.00119739652255502,-0.0002452749019867,0.25,-2.52895852085442E-6,-0.000106514601736791,-3.31918943959231E-6,10.0036201,10.0036201,55094.3359375,55114.54296875,57.0182372208522,20.5202150372609,11.519473,0,0,0,40,4449,10.01655,55104.439453125,,,,,,,,,,,,,0,,,,-0.00245,,,,,,10.0036201,,,,
,32913359.07,10.0034466,50087.216796875,-8.92693243058431E-5,8.22513920308685E-7,1,0.999253354069792,40.0298881530762,1.99580017001171,21.8899995088577,-0.00100391874801852,-0.000196526700009961,0.25,-1.34247068464445E-6,-8.91638608237755E-5,-1.99951874590909E-6,10.0034466,10.0034466,50082.34375,50092.08984375,57.0104209356599,20.5205995493398,11.519473,0,0,0,40,4449,10.013,50087.216796875,,,,,,,,,,,,,0,,,,0,,,,,,10.0034466,,,,
,32913457.825,10.004364,45149.578125,-7.23777637528076E-5,7.06911594481081E-7,1,0.999253354069792,40.0298881530762,1.99579975177457,21.8899995088577,-0.000813078171151974,-0.000161842421045845,0.25,-1.32368384849913E-6,-7.22538692932757E-5,-1.84920230917146E-6,10.004364,10.004364,45144.71484375,45154.44140625,57.0198004778906,20.5199426434114,10.760172,0,0,0,40,4449,10.0112,45149.578125,,,,,,,,,,,,,0,,,,0,,,,,,10.004364,,,,
,32913553.055,10.0028982,40389.61328125,-5.43367961638121E-5,6.0019901515551E-7,1,0.999253354069792,40.0298881530762,1.99572695059712,21.8899995088577,-0.000610379446248352,-0.000119790932356206,0.25,-8.54081788964764E-7,-5.42177430946183E-5,-1.24180348910799E-6,10.0028982,10.0028982,40382.38671875,40396.83984375,56.933039712256,20.5245802403985,10.760172,0,0,0,40,4449,10.00715,40389.61328125,,,,,,,,,,,,,0,,,,-0.0049,,,,,,10.0028982,,,,
,32913651.805,10.0026398,35456.802734375,-3.7916277702418E-5,5.65486938899583E-7,1,0.999253354069792,40.0298881530762,1.99569173662317,21.8899995088577,-0.000427288096783007,-7.46775773514039E-5,0.25,1.853677982907E-7,-3.7818933682122E-5,-8.05553895718794E-8,10.0026398,10.0026398,35449.046875,35464.55859375,56.9963516223137,20.5237637250676,11.139823,0,0,0,40,4449,10.0054,35456.802734375,,,,,,,,,,,,,0,,,,0.0049,,,,,,10.0026398,,,,
,32913748.77,10.0012321,30607.0732421875,-2.32271112347705E-5,6.21193349106076E-7,1,0.999253354069792,40.0298881530762,1.99572907559373,21.8899995088577,-0.000261575575408904,-4.59798407719302E-5,0.25,8.60637956336051E-8,-2.31553497041593E-5,-7.19959742437086E-8,10.0012321,10.0012321,30601.94921875,30612.197265625,56.9049010855637,20.5254655159915,11.139823,0,0,0,40,4449,10.004,30607.0732421875,,,,,,,,,,,,,0,,,,-0.00245,,,,,,10.0012321,,,,
,32913846.315,10.0008211,25733.9970703125,-7.11799206617302E-6,4.79917174974978E-7,1,0.999253354069792,40.0298881530762,1.99568675213216,21.8899995088577,-8.08162923910033E-5,-1.01881144239149E-5,0.25,3.70872111475342E-7,-7.09463930166532E-6,3.22957111449974E-7,10.0008211,10.0008211,25723.966796875,25744.02734375,57.1972301517561,20.5261634624666,11.519473,0,0,0,40,4449,10.0031,25733.9970703125,,,,,,,,,,,,,0,,,,-0.00245,,,,,,10.0008211,,,,
,32913947.265,10.0000839,20686.755859375,1.01607811098632E-5,6.18695345379997E-7,1,0.999253354069792,40.0298881530762,1.99564436782561,21.8899995088577,0.000114246911462293,2.04198856776569E-5,0.25,-2.9803822184941E-9,1.01188479965011E-5,6.04467049811185E-8,10.0000839,10.0000839,20676.912109375,20696.599609375,56.9963516223137,20.5279694392356,11.519473,0,0,0,40,4449,10.0035,20686.755859375,,,,,,,,,,,,,0,,,,-0.0049,,,,,,10.0000839,,,,
,32914044.355,10.0001507,15834.6279296875,2.62936191693491E-5,4.78768271903242E-7,1,0.999253354069792,40.0298881530762,1.99562632731862,21.8899995088577,0.000294177472119918,6.02349798509418E-5,0.25,6.60867309454238E-7,2.61690323906583E-5,8.13391152954514E-7,10.0001507,10.0001507,15824.62890625,15844.626953125,57.4606389627369,20.5309975901859,11.139823,0,0,0,40,4449,10.0034,15834.6279296875,,,,,,,,,,,,,0,,,,-0.00245,,,,,,10.0001507,,,,
,32914141.355,9.9988003,10987.169921875,4.14121934693294E-5,4.14884634046785E-7,1,0.999253354069792,40.0298881530762,1.99568323598257,21.8899995088577,0.000464659463129637,8.63406774305394E-5,0.25,2.99470524602508E-7,4.12029008504051E-5,5.28504753915077E-7,9.9988003,9.9988003,10977.35546875,10996.984375,57.0518472471791,20.5281582545169,11.139823,0,0,0,40,4449,10.00355,10987.169921875,,,,,,,,,,,,,0,,,,-0.00245,,,,,,9.9988003,,,,
,32914235.675,9.9989533,6271.8876953125,5.51696509442885E-5,3.50575116591011E-7,1,0.999253354069792,40.0298881530762,1.9955567181495,21.8899995088577,0.000619059410711386,0.000113283348757577,0.25,2.6753525096229E-7,5.48714725485345E-5,5.5404139200372E-7,9.998764,9.9991426,6264.24267578125,6279.53271484375,57.0096393071407,20.5297011870356,10.760172,0,0,0,40,4449,10.00515,6271.8876953125,,,,,,,,,,,,,0,,,,-0.00245,,,,,,9.9989533,,,,
,32914330.375,10.0004063,1538.56719970703,6.9020236674973E-5,3.23230897472391E-7,1,0.999253354069792,40.0298881530762,1.99567571291042,21.8899995088577,0.000774575600841565,0.000140071773374602,0.25,2.129441707925E-7,6.86272689056722E-5,5.49709302275882E-7,10.0004063,10.0004063,1526.19543457031,1550.93896484375,57.0409044479099,20.5263223245505,11.139823,0,0,0,40,4449,10.00555,1538.56719970703,,,,,,,,,,,,,0,,,,0,,,,,,10.0004063,,,,
,32914425.555,9.9985666,-3211.72277832031,8.07935506716112E-5,3.19172268088612E-7,1,0.999253354069792,40.0298881530762,1.99553864795505,21.8899995088577,0.000906836951408883,0.000163358962203182,0.25,1.8622907844278E-7,8.03415201489807E-5,5.89438401280244E-7,9.9985666,9.9985666,-3221.83056640625,-3201.61499023438,56.7079306987175,20.5307068556802,11.139823,0,0,0,40,4449,10.0051,-3211.72277832031,,,,,,,,,,,,,0,,,,0.0049,,,,,,9.9985666,,,,
,32914524.68,9.9985085,-8168.73315429688,9.20783069795936E-5,3.72666794802937E-7,1,0.999253354069792,40.0298881530762,1.99570209190212,21.8899995088577,0.00103446953643306,0.000183274330915258,0.25,-8.58401924644895E-8,9.1596389784172E-5,4.08016605766979E-7,9.9985085,9.9985085,-8181.22509765625,-8156.2412109375,56.6922981283329,20.5317215652952,11.519473,0,0,0,40,4449,10.00455,-8168.73315429688,,,,,,,,,,,,,0,,,,0.00245,,,,,,9.9985085,,,,
,32914621.96,10.00064565,-13031.6953125,9.92172768914613E-5,4.56959913996987E-7,1,0.999253354069792,40.0298881530762,1.99561738738942,21.8899995088577,0.0011157704964196,0.000193675535189216,0.25,-4.73261967064613E-7,9.87397781297541E-5,9.61875506246211E-8,10.0006218,10.0006695,-13039.033203125,-13024.357421875,57.1073428720445,20.5298730374798,10.760172,0,0,0,40,4449,10.00555,-13031.6953125,,,,,,,,,,,,,0,,,,-0.00245,,,,,,10.00064565,,,,
,32914721.205,10.0013027,-17991.9189453125,9.60034021967077E-5,4.95724036785323E-7,1,0.999253354069792,40.0298881530762,1.9955811578301,21.8899995088577,0.00107967071880615,0.000189902134216996,0.25,-2.76147287202563E-7,9.5583758497555E-5,3.07264469425113E-7,10.0013027,10.0013027,-18001.861328125,-17981.9765625,57.4129596230638,20.5328044929861,10.760172,0,0,0,40,4449,10.00505,-17991.9189453125,,,,,,,,,,,,,0,,,,0,,,,,,10.0013027,,,,
,32914821.98,10.0002613,-23029.12890625,8.14273896455766E-5,4.23638431525439E-7,1,0.999253354069792,40.0298881530762,1.99543630364191,21.8899995088577,0.000916655927453564,0.000158250204964271,0.25,-5.17153733592881E-7,8.11134224227383E-5,4.87254862917504E-9,10.0002613,10.0002613,-23039.099609375,-23019.158203125,56.9072459711214,20.5323464988126,10.760172,0,0,0,40,4449,10.00395,-23029.12890625,,,,,,,,,,,,,0,,,,0,,,,,,10.0002613,,,,
,32914920.89,10.0001574,-27974.33984375,6.45226820663601E-5,6.2179253491485E-7,1,0.999253354069792,40.0298881530762,1.99551727176906,21.8899995088577,0.000727254231954822,0.000122676697155756,0.25,-6.75426604085861E-7,6.43084365785414E-5,-2.43208432630806E-7,10.0001574,10.0001574,-27976.9140625,-27971.765625,57.3809128537753,20.5321812095113,11.139823,0,0,0,40,4449,10.0041,-27974.33984375,,,,,,,,,,,,,0,,,,0,,,,,,10.0001574,,,,
,32915018.275,9.9992819,-32838.96875,5.78946549338289E-5,7.5176534243372E-7,1,0.999253354069792,40.0298881530762,1.99556566976829,21.8899995088577,0.000653968326441568,0.000104189974914043,0.25,-1.14736599416188E-6,5.77358767285069E-5,-7.44931117996561E-7,9.9992819,9.9992819,-32849.171875,-32828.765625,57.2527257766214,20.533881111443,10.760172,0,0,0,40,4449,10.0043,-32838.96875,,,,,,,,,,,,,0,,,,0.0049,,,,,,9.9992819,,,,
,32915114.85,9.9988718,-37666.15625,6.18096949902591E-5,7.66798913431344E-7,1,0.999253354069792,40.0298881530762,1.99555739741851,21.8899995088577,0.000695278813377146,0.000129484056867176,0.25,3.79068289830705E-7,6.16607098577548E-5,8.15850581809953E-7,9.9988718,9.9988718,-37671.375,-37660.9375,57.1440794124484,20.5332665045882,10.760172,0,0,0,40,4449,10.0058,-37666.15625,,,,,,,,,,,,,0,,,,0,,,,,,9.9988718,,,,
,32915212.305,9.9981813,-42535.748046875,7.04714828973887E-5,7.80678194111762E-7,1,0.999253354069792,40.0298881530762,1.99561427497429,21.8899995088577,0.000793887896487408,0.000143575463136617,0.25,5.51581626955306E-8,7.03405698036065E-5,5.64403902865125E-7,9.9981813,9.9981813,-42543.4609375,-42528.03515625,57.5935158110061,20.534250189514,11.139823,0,0,0,40,4449,10.00605,-42535.748046875,,,,,,,,,,,,,0,,,,0,,,,,,9.9981813,,,,
,32915308.62,9.9975672,-47348.22265625,8.30946393897675E-5,8.12710911736062E-7,1,0.999253354069792,40.0298881530762,1.99556020713209,21.8899995088577,0.000939124364987852,0.000155023514861667,0.25,-1.21652315763033E-6,8.29913291706197E-5,-6.05545175844132E-7,9.9975672,9.9975672,-47350.38671875,-47346.05859375,57.0518472471791,20.5339014811619,11.519473,0,0,0,40,4449,10.0087,-47348.22265625,,,,,,,,,,,,,0,,,,0,,,,,,9.9975672,,,,
,32915404.57,9.9968767,-52145.4453125,9.98295756941643E-5,8.50109162285368E-7,1,0.999253354069792,40.0298881530762,1.99521976884586,21.8899995088577,0.0011286546260527,0.000186163896633879,0.25,-1.48057191258951E-6,9.97543832058011E-5,-7.40404908871581E-7,9.9968767,9.9968767,-52157.51171875,-52133.37890625,57.261323690333,20.5378795041265,10.760172,0,0,0,40,4449,10.0124,-52145.4453125,,,,,,,,,,,,,0,,,,-0.0049,,,,,,9.9968767,,,,
,32915504.195,9.9967575,-57124.92578125,0.000118394753280642,7.57057684965267E-7,1,0.999253354069792,40.0298881530762,1.99524098786373,21.8899995088577,0.00133693941477642,0.000233544097134444,0.25,-6.38510768736782E-7,0.000118355280094489,2.42292261104908E-7,9.9967575,9.9967575,-57129.90234375,-57119.94921875,57.2159892362176,20.5401498367539,11.139823,0,0,0,40,4449,10.01565,-57124.92578125,,,,,,,,,,,,,0,,,,0.00245,,,,,,9.9967575,,,,
,32915596.92,9.99641515,-61757.564453125,0.000132541058578993,8.11628650552596E-7,1,0.999253354069792,40.0298881530762,1.9953681269829,21.8899995088577,0.00149866461204094,0.000254722222572897,0.25,-1.32253797898394E-6,0.000132559373283962,-3.36200697251301E-7,9.9963522,9.9964781,-61762.4921875,-61752.63671875,57.0932735586983,20.5364590030943,11.519473,0,0,0,40,4449,10.0193,-61757.564453125,,,,,,,,,,,,,0,,,,0,,,,,,9.99641515,,,,
,32915686.75,9.9961443,-66247.4609375,0.000149638814181806,8.565619394929E-7,1,0.999253354069792,40.0298881530762,1.99539997516407,21.8899995088577,0.00169171437579547,0.000293190846598561,0.25,-1.00385222823808E-6,0.000149716551758807,1.06576924630174E-7,9.9961443,9.9961443,-66249.9765625,-66244.9453125,57.1065612435253,20.5363046732744,11.139823,0,0,0,40,4449,10.02225,-66247.4609375,,,,,,,,,,,,,0,,,,0,,,,,,9.9961443,,,,
,32915777.57,9.995347,-70784.79296875,0.00016600061586252,9.67025032040114E-7,1,0.999253354069792,40.0298881530762,1.99534108024424,21.8899995088577,0.0018689374611024,0.000372160040447233,0.25,3.03585669049364E-6,0.000166121049140666,4.26437703680026E-6,9.995347,9.995347,-70787.203125,-70782.3828125,57.2925888311022,20.5403669796487,11.139823,0,0,0,40,4449,10.02495,-70784.79296875,,,,,,,,,,,,,0,,,,0,,,,,,9.995347,,,,
,32915867.735,9.9956532,-75294.671875,0.000182977250063575,1.01348776124531E-6,1,0.999253354069792,40.0298881530762,1.9952990672043,21.8899995088577,0.00206619608806143,0.00038034998235115,0.25,7.00977781793526E-7,0.000183197059488757,2.04287155412142E-6,9.9956532,9.9956532,-75299.6640625,-75289.6796875,57.2081729510253,20.5372640289642,10.760172,0,0,0,40,4449,10.0291,-75294.671875,,,,,,,,,,,,,0,,,,-0.0049,,,,,,9.9956532,,,,
,32915958.14,9.9957695,-79809.16796875,0.000200574598221911,8.4899843421579E-7,1,0.999253354069792,40.0298881530762,1.99541727880064,21.8899995088577,0.00226493559895993,0.0004220373335805,0.25,1.21998790608746E-6,0.000200882402663927,2.677731847093E-6,9.9957695,9.9957695,-79811.6640625,-79806.671875,57.1612752398714,20.5392017608238,11.139823,0,0,0,40,4449,10.0323,-79809.16796875,,,,,,,,,,,,,0,,,,0,,,,,,9.9957695,,,,
,32916046.945,9.995616,-84249.40234375,0.000217143102635663,9.67589690140129E-7,1,0.999253354069792,40.0298881530762,1.99542534013446,21.8899995088577,0.00245155055625241,0.000464184920792779,0.25,1.96991628501288E-6,0.000217542239359801,3.53204110768724E-6,9.995616,9.995616,-84254.3984375,-84244.40625,57.2316218066022,20.5357704931666,11.139823,0,0,0,40,4449,10.0367,-84249.40234375,,,,,,,,,,,,,0,,,,-0.0049,,,,,,9.995616,,,,
,32916131.295,9.9952478,-88464.1484375,0.000230716908663817,8.42930700917445E-7,1,0.999253354069792,40.0298881530762,1.99543528819172,21.8899995088577,0.00260689598263892,0.000485963646181075,0.25,1.46072813866917E-6,0.000231212742326547,3.09978035015929E-6,9.9952478,9.9952478,-88476.7421875,-88451.5546875,57.4606389627369,20.5425719363706,10.760172,0,0,0,40,4449,10.03935,-88464.1484375,,,,,,,,,,,,,0,,,,0,,,,,,9.9952478,,,,
,32916232.83,9.9977655,-87473.42578125,0.000226235110618967,9.70058715325952E-7,1,0.999253354069792,40.0298881530762,1.9953032826642,21.8899995088577,0.00255488522154986,0.000482234652487855,0.25,1.93790960675342E-6,0.000226702560377281,3.5508581136642E-6,9.9977655,9.9977655,-87478.5,-87468.3515625,57.606803495833,20.541177593123,10.760172,0,0,0,40,4449,10.043,-87473.42578125,,,,,,,,,,,,,0,,,,0,,,,,,9.9977655,,,,
,32916316.075,9.9996443,-83313.54296875,0.000211498984703456,1.060040294154E-6,1,0.999253354069792,40.0298881530762,1.99521959281095,21.8899995088577,0.00238656820246188,0.000456855261690462,0.25,2.34024973444732E-6,0.000211870544868227,3.86623631858551E-6,9.9996443,9.9996443,-83321.109375,-83305.9765625,57.3160376866791,20.5462950548384,11.519473,0,0,0,40,4449,10.0405,-83313.54296875,,,,,,,,,,,,,0,,,,0.00245,,,,,,9.9996443,,,,
,32916406.835,10.0022898,-78775.90234375,0.000196191127200317,1.14459174346193E-6,1,0.999253354069792,40.0298881530762,1.9953135479832,21.8899995088577,0.00221816094461452,0.000396059318429888,0.25,-2.87814228636688E-7,0.00019648761143973,1.13915947753603E-6,10.0022898,10.0022898,-78783.328125,-78768.4765625,57.5528711280061,20.5408130822946,11.519473,0,0,0,40,4449,10.03995,-78775.90234375,,,,,,,,,,,,,0,,,,-0.00245,,,,,,10.0022898,,,,
,32916497.89,10.0026054,-74228.4765625,0.000179045408941176,8.5844281200079E-7,1,0.999253354069792,40.0298881530762,1.99527397077983,21.8899995088577,0.00202444456069362,0.00035635394610029,0.25,-7.14034743142263E-7,0.000179255471836903,5.99988142546478E-7,10.0026054,10.0026054,-74235.8984375,-74221.0546875,57.2980602307368,20.5394970345462,11.519473,0,0,0,40,4449,10.0358,-74228.4765625,,,,,,,,,,,,,0,,,,0,,,,,,10.0026054,,,,
,32916591.955,10.0036354,-69526.62109375,0.00016447568376377,1.04451367176581E-6,1,0.999253354069792,40.0298881530762,1.99514148075937,21.8899995088577,0.00186031202939611,0.000319181643665018,0.25,-1.37596658598923E-6,0.000164609899685876,-1.60275375728201E-7,10.0036354,10.0036354,-69533.8125,-69519.4296875,57.2660134614484,20.5441141728161,11.139823,0,0,0,40,4449,10.0325,-69526.62109375,,,,,,,,,,,,,0,,,,0.0049,,,,,,10.0036354,,,,
,32916689.74,10.0031919,-64639.349609375,0.000144653271946651,9.69526159971368E-7,1,0.999253354069792,40.0298881530762,1.99526086604371,21.8899995088577,0.00163589031740245,0.000278471032977292,0.25,-1.40521489726058E-6,0.00014471094385959,-3.30473652542451E-7,10.0031919,10.0031919,-64646.7578125,-64631.94140625,57.4872143323907,20.538482865556,11.139823,0,0,0,40,4449,10.0301,-64639.349609375,,,,,,,,,,,,,0,,,,0.0049,,,,,,10.0031919,,,,
,32916788.78,10.0031185,-59686.9140625,0.000125034567431085,9.85756328601323E-7,1,0.999253354069792,40.0298881530762,1.99524902266111,21.8899995088577,0.00142397004682263,0.0001817828530511,0.25,-6.42809130413598E-6,0.00012506624216605,-5.49657609159877E-6,10.0031185,10.0031185,-59689.3828125,-59684.4453125,57.1565854687561,20.5376433820304,11.139823,0,0,0,40,4449,10.0259,-59686.9140625,,,,,,,,,,,,,0,,,,-0.0049,,,,,,10.0031185,,,,
,32916887.64,10.0041618,-54749.923828125,0.000106986919917746,8.75702337382168E-7,1,0.999253354069792,40.0298881530762,1.99518017667267,21.8899995088577,0.00121670270994806,0.000161619519099636,0.25,-4.95290536669252E-6,0.000106959003983069,-4.15557935425297E-6,10.0041618,10.0041618,-54757.66015625,-54742.1875,57.0385595623522,20.5408553366718,11.519473,0,0,0,40,4449,10.02175,-54749.923828125,,,,,,,,,,,,,0,,,,0,,,,,,10.0041618,,,,
,32916987.31,10.0039692,-49768.291015625,8.71352793507591E-5,7.86962351695645E-7,1,0.999253354069792,40.0298881530762,1.99522717670949,21.8899995088577,0.000991324558129424,0.000126806728583503,0.25,-4.45193619240661E-6,8.70719994775208E-5,-3.80467098826996E-6,10.0039692,10.0039692,-49780.953125,-49755.62890625,57.190195495083,20.5422816532049,10.760172,0,0,0,40,4449,10.0187,-49768.291015625,,,,,,,,,,,,,0,,,,0,,,,,,10.0039692,,,,
,32917084.53,10.0033989,-44907.978515625,7.15637032242202E-5,8.54426243201876E-7,1,0.999253354069792,40.0298881530762,1.99510482198483,21.8899995088577,0.000810563055677229,0.000121556734895528,0.25,-2.09977507595204E-6,7.14642372629888E-5,-1.57510963881749E-6,10.0033989,10.0033989,-44917.875,-44898.08203125,57.217552493256,20.5439584869126,10.760172,0,0,0,40,4449,10.0162,-44907.978515625,,,,,,,,,,,,,0,,,,0,,,,,,10.0033989,,,,
,32917179.475,10.0042753,-40165.333984375,5.50193841133899E-5,6.62175470448237E-7,1,0.999253354069792,40.0298881530762,1.99513171779115,21.8899995088577,0.000621407478375644,0.000101528271984547,0.25,-8.86798374670809E-7,5.49100802820166E-5,-4.90912124819008E-7,10.0042753,10.0042753,-40175.1171875,-40155.55078125,56.8744175733137,20.5427221454633,11.139823,0,0,0,40,4449,10.0134,-40165.333984375,,,,,,,,,,,,,0,,,,-0.0049,,,,,,10.0042753,,,,
,32917277.04,10.0026751,-35285.630859375,3.95279143080547E-5,5.73692696699878E-7,1,0.999253354069792,40.0298881530762,1.99519497718454,21.8899995088577,0.000450484975122072,4.91959708945593E-5,0.25,-2.73693413458417E-6,3.94435038598885E-5,-2.45330113876565E-6,10.0026751,10.0026751,-35293.1796875,-35278.08203125,57.3183825722368,20.538360081469,11.139823,0,0,0,40,4449,10.01035,-35285.630859375,,,,,,,,,,,,,0,,,,-0.00245,,,,,,10.0026751,,,,
,32917376.825,10.0022764,-30301.1103515625,2.23772652570609E-5,5.3708838284831E-7,1,0.999253354069792,40.0298881530762,1.99521111454762,21.8899995088577,0.000254873217813247,2.79203630406924E-5,0.25,-1.5371032574957E-6,2.23172661254147E-5,-1.38057225445619E-6,10.0022764,10.0022764,-30305.931640625,-30296.2890625,57.3043132588907,20.5388846962727,10.760172,0,0,0,40,4449,10.0098,-30301.1103515625,,,,,,,,,,,,,0,,,,0,,,,,,10.0022764,,,,
,32917474.855,10.0014915,-25401.5244140625,6.89803058635002E-6,3.57879409041416E-7,1,0.999253354069792,40.0298881530762,1.99514892617776,21.8899995088577,8.19254391629436E-5,-1.03688559738678E-5,0.25,-2.15905621943378E-6,6.88689906780057E-6,-2.10615883140797E-6,10.0014524,10.0015306,-25409.11328125,-25393.935546875,57.2386564632753,20.5405481790466,10.38052,0,0,0,40,4449,10.00945,-25401.5244140625,,,,,,,,,,,,,0,,,,0,,,,,,10.0014915,,,,
,32917573.51,10.0004482,-20469.3779296875,-8.82223263968391E-6,5.9438528981041E-7,1,0.999253354069792,40.0298881530762,1.99529661261954,21.8899995088577,-9.64634737051957E-5,-3.2888185004631E-5,0.25,-1.34628944956452E-6,-8.77723610861872E-6,-1.39564051789212E-6,10.0004482,10.0004482,-20481.8203125,-20456.935546875,57.1049979864868,20.5371734592281,10.38052,0,0,0,40,4449,10.00895,-20469.3779296875,,,,,,,,,,,,,0,,,,0,,,,,,10.0004482,,,,
,32917669.08,10.0000639,-15694.734375,-2.46716863353079E-5,4.31467346523812E-7,1,0.999253354069792,40.0298881530762,1.99511795408173,21.8899995088577,-0.000273724923876416,-6.9015005005759E-5,0.25,-1.73375802018396E-6,-2.4547897419853E-5,-1.87149830985022E-6,10.0000639,10.0000639,-15699.818359375,-15689.650390625,57.1886322380445,20.5426819850836,10.760172,0,0,0,40,4449,10.0081,-15694.734375,,,,,,,,,,,,,0,,,,0,,,,,,10.0000639,,,,
,32917766.875,9.9993181,-10807.0634765625,-3.95460978656386E-5,3.51762516235996E-7,1,0.999253354069792,40.0298881530762,1.99507113063271,21.8899995088577,-0.000442049500054538,-9.10332323934514E-5,0.25,-1.05297238209634E-6,-3.93413909767182E-5,-1.26730017278306E-6,9.9993181,9.9993181,-10817.13671875,-10796.990234375,57.3668435404292,20.5425863062625,10.760172,0,0,0,40,4449,10.00895,-10807.0634765625,,,,,,,,,,,,,0,,,,0.00245,,,,,,9.9993181,,,,
,32917863.36,9.9991751,-5983.95825195313,-5.45251456226305E-5,3.13213866032326E-7,1,0.999253354069792,40.0298881530762,1.99485246101761,21.8899995088577,-0.000609391407370993,-0.000124379149899044,0.25,-1.37533260596589E-6,-5.42235640456001E-5,-1.65134696459702E-6,9.9991751,9.9991751,-5993.81884765625,-5974.09765625,56.8877052581406,20.5467260574631,11.139823,0,0,0,40,4449,10.0093,-5983.95825195313,,,,,,,,,,,,,0,,,,0.0049,,,,,,9.9991751,,,,
,32917950.06,10.00067995,-1649.93133544922,-6.70372876275159E-5,3.12809949649016E-7,1,0.999253354069792,40.0298881530762,1.99508424368135,21.8899995088577,-0.000750418439216132,-0.000145551765746249,0.25,-1.05640496453414E-6,-6.66518328804743E-5,-1.37912305582353E-6,10.0006723,10.0006876,-1659.87829589844,-1639.984375,57.3308886285445,20.5390542995657,10.760172,0,0,0,40,4449,10.00905,-1649.93133544922,,,,,,,,,,,,,0,,,,0,,,,,,10.00067995,,,,
,32918037.375,9.999608,2708.06567382813,-7.67050949672426E-5,3.26969605122223E-7,1,0.999253354069792,40.0298881530762,1.9950123483232,21.8899995088577,-0.000860258714485206,-0.000157558009416239,0.25,-4.02910492577383E-7,-7.62725087405477E-5,-7.81879067423192E-7,9.999608,9.999608,2698.01953125,2718.11181640625,56.9080275996406,20.5403251270595,10.760172,0,0,0,40,4449,10.00775,2708.06567382813,,,,,,,,,,,,,0,,,,0,,,,,,9.999608,,,,
,32918126.13,9.9989929,7147.46923828125,-8.73194322689621E-5,3.81131972213496E-7,1,0.999253354069792,40.0298881530762,1.99516294839865,21.8899995088577,-0.000979526194228908,-0.00018020082433006,0.25,-5.00183414657444E-7,-8.68526257746442E-5,-9.58860000538971E-7,9.9989929,9.9989929,7147.46923828125,7147.46923828125,56.7837486650829,20.5391250880583,11.139823,0,0,0,40,4449,10.0095,7147.46923828125,,,,,,,,,,,,,0,,,,-0.0049,,,,,,9.9989929,,,,
,32918215.5,10.0006914,11616.2397460938,-9.46303077670735E-5,4.12401741396882E-7,1,0.999253354069792,40.0298881530762,1.99515249191188,21.8899995088577,-0.00106308600950879,-0.000188769048942318,0.25,7.5621507588609E-8,-9.41612662526266E-5,-4.55921995087202E-7,10.0006914,10.0006914,11606.1318359375,11626.34765625,57.2300585495638,20.5383821428313,11.139823,0,0,0,40,4449,10.0086,11616.2397460938,,,,,,,,,,,,,0,,,,-0.00245,,,,,,10.0006914,,,,
,32918304.63,10.0003872,16071.5512695313,-9.5985344548447E-5,3.5216361672195E-7,1,0.999253354069792,40.0298881530762,1.99510808695179,21.8899995088577,-0.00107862806007063,-0.000192025735651131,0.25,6.4441054333133E-8,-9.55472802741746E-5,-5.05304399745155E-7,10.0003872,10.0003872,16068.884765625,16074.2177734375,57.0870205305445,20.5378764838151,10.760172,0,0,0,40,4449,10.0063,16071.5512695313,,,,,,,,,,,,,0,,,,0,,,,,,10.0003872,,,,
,32918393.18,10.000638,20496.2470703125,-8.61338535922064E-5,5.17260781742127E-7,1,0.999253354069792,40.0298881530762,1.99510260723501,21.8899995088577,-0.000968494251678573,-0.000171477361339606,0.25,1.64410236793495E-7,-8.57776427711728E-5,-3.7279689632648E-7,10.000638,10.000638,20491.11328125,20501.380859375,57.0713879601599,20.5388420914382,10.38052,0,0,0,40,4449,10.00715,20496.2470703125,,,,,,,,,,,,,0,,,,0,,,,,,10.000638,,,,
,32918482.475,10.0000639,24959.3125,-7.01957738410448E-5,5.93466020769157E-7,1,0.999253354069792,40.0298881530762,1.99511628696778,21.8899995088577,-0.000791482018091948,-0.000129573395090831,0.25,1.06328910709163E-6,-6.99428920202498E-5,6.03137090868181E-7,10.0000639,10.0000639,24954.384765625,24964.240234375,57.2230238928907,20.5382415825454,11.519473,0,0,0,40,4449,10.0071,24959.3125,,,,,,,,,,,,,0,,,,0.0049,,,,,,10.0000639,,,,
,32918571.115,10.0004835,29389.8974609375,-5.9233994124337E-5,5.93866873183732E-7,1,0.999253354069792,40.0298881530762,1.99510496879204,21.8899995088577,-0.000669776215580213,-0.000100561686441533,0.25,1.69579853898932E-6,-5.9053349674212E-5,1.29137338294418E-6,10.0004835,10.0004835,29382.626953125,29397.16796875,57.1683098965445,20.5398622616501,10.760172,0,0,0,40,4449,10.00695,29389.8974609375,,,,,,,,,,,,,0,,,,-0.0049,,,,,,10.0004835,,,,
,32918659.255,9.9996424,33795.9609375,-5.56561453175865E-5,6.90736839782172E-7,1,0.999253354069792,40.0298881530762,1.9949310921948,21.8899995088577,-0.000626975189303106,-0.000108937318017119,0.25,3.23590256927793E-7,-5.55037880292158E-5,-6.3256630732714E-8,9.9996424,9.9996424,33785.90234375,33806.01953125,56.9346029692945,20.541561516234,10.760172,0,0,0,40,4449,10.0066,33795.9609375,,,,,,,,,,,,,0,,,,0,,,,,,9.9996424,,,,
,32918747.715,9.99948645,38215.185546875,-6.02190318188856E-5,8.22127330862906E-7,1,0.999253354069792,40.0298881530762,1.99505710426356,21.8899995088577,-0.000679152251197714,-0.000115630233859831,0.25,5.64257581957837E-7,-6.00840105668066E-5,1.35417839848404E-7,9.9994583,9.9995146,38207.32421875,38223.046875,57.0721695886791,20.5422528318173,10.760172,0,0,0,40,4449,10.0078,38215.185546875,,,,,,,,,,,,,0,,,,0.0049,,,,,,9.99948645,,,,
,32918833.96,9.99893955,42525.828125,-6.8685665498859E-5,8.8181216790745E-7,1,0.999253354069792,40.0298881530762,1.99511546921995,21.8899995088577,-0.000774353743976059,-0.000135631401994472,0.25,3.25491078380798E-7,-6.85607391901513E-5,-1.71534941597911E-7,9.9988976,9.9989815,42521.13671875,42530.51953125,57.054973761256,20.5383838184894,10.760172,0,0,0,40,4449,10.0101,42525.828125,,,,,,,,,,,,,0,,,,-0.0049,,,,,,9.99893955,,,,
,32918922.65,9.9975586,46958.892578125,-8.23146321559751E-5,9.31145298650767E-7,1,0.999253354069792,40.0298881530762,1.9951888608359,21.8899995088577,-0.000930820850763667,-0.000149566749772352,0.25,1.55664391668232E-6,-8.22115523580528E-5,9.51449574023988E-7,9.9975586,9.9975586,46949.04296875,46968.7421875,56.933039712256,20.5352271849958,11.139823,0,0,0,40,4449,10.0107,46958.892578125,,,,,,,,,,,,,0,,,,0,,,,,,9.9975586,,,,
,32919010.195,9.9972591,51334.4375,-9.68603891748033E-5,9.87854044403017E-7,1,0.999253354069792,40.0298881530762,1.99512339162844,21.8899995088577,-0.00109437103243779,-0.000183792304817867,0.25,1.152896180659E-6,-9.67774364627409E-5,4.35781085764045E-7,9.9972591,9.9972591,51326.98828125,51341.88671875,56.8572217458906,20.5373517276759,10.760172,0,0,0,40,4449,10.01425,51334.4375,,,,,,,,,,,,,0,,,,0.0049,,,,,,9.9972591,,,,
,32919097.92,9.9959106,55719.453125,-0.000113648959287958,9.29062852245361E-7,1,0.999253354069792,40.0298881530762,1.99518676338147,21.8899995088577,-0.00128999578289452,-0.000186113046521099,0.25,3.98416610895527E-6,-0.000113620632110235,3.13763706202699E-6,9.9959106,9.9959106,55714.30859375,55724.59765625,56.8173586914099,20.5345003461394,10.760172,0,0,0,40,4449,10.0167,55719.453125,,,,,,,,,,,,,0,,,,0,,,,,,9.9959106,,,,
,32919186.165,9.996314,60130.01953125,-0.000128758858048444,1.03082809450783E-6,1,0.999253354069792,40.0298881530762,1.99525396012017,21.8899995088577,-0.00145848475106232,-0.000231390212757518,0.25,2.70405423886815E-6,-0.000128767698674829,1.74538579705782E-6,9.996314,9.996314,60122.43359375,60137.60546875,56.7532651528329,20.5365776789427,10.760172,0,0,0,40,4449,10.0206,60130.01953125,,,,,,,,,,,,,0,,,,0,,,,,,9.996314,,,,
,32919273.52,9.9956026,64498.583984375,-0.000144074818447257,1.20125574931334E-6,1,0.999253354069792,40.0298881530762,1.99521185752796,21.8899995088577,-0.00163417163536386,-0.000250262119991296,0.25,3.79900072877187E-6,-0.000144148276130565,2.72919640746398E-6,9.9956026,9.9956026,64485.875,64511.29296875,56.9580518248714,20.5349798134558,10.38052,0,0,0,40,4449,10.0236,64498.583984375,,,,,,,,,,,,,0,,,,-0.0049,,,,,,9.9956026,,,,
,32919362.4,9.9959345,68938.84375,-0.000160816259531734,9.22740911503297E-7,1,0.999253354069792,40.0298881530762,1.99514563225264,21.8899995088577,-0.00181755717104241,-0.000319152777814822,0.25,7.18672652411657E-7,-0.000160934781034862,-4.71353927527648E-7,9.9959345,9.9959345,68928.84375,68948.84375,57.2370932062368,20.5344602347442,10.760172,0,0,0,40,4449,10.0278,68938.84375,,,,,,,,,,,,,0,,,,0,,,,,,9.9959345,,,,
,32919448.98,9.9960499,73266.8125,-0.000176808208987997,1.1665738386038E-6,1,0.999253354069792,40.0298881530762,1.99513127361677,21.8899995088577,-0.00199422891844889,-0.000377539230784044,0.25,-1.56656166325273E-6,-0.000176985158965134,-2.86885050308622E-6,9.9960499,9.9960499,73261.640625,73271.984375,57.1472059265253,20.5356821595627,10.760172,0,0,0,40,4449,10.031,73266.8125,,,,,,,,,,,,,0,,,,-0.0049,,,,,,9.9960499,,,,
,32919536.77,9.9954042,77655.13671875,-0.000192495652591675,8.65867530495421E-7,1,0.999253354069792,40.0298881530762,1.99511412531523,21.8899995088577,-0.00217306522283457,-0.000404743593429274,0.25,-1.14882517710865E-6,-0.000192759562838112,-2.55444608578306E-6,9.9954042,9.9954042,77649.8203125,77660.453125,57.1753445532176,20.5401933021056,11.139823,0,0,0,40,4449,10.035,77655.13671875,,,,,,,,,,,,,0,,,,0.00245,,,,,,9.9954042,,,,
,32919627.235,9.9954615,82176.3046875,-0.000210121746349124,1.27659498909814E-6,1,0.999253354069792,40.0298881530762,1.9952931428849,21.8899995088577,-0.00237252785385329,-0.000444903070248437,0.25,-1.52827626712622E-6,-0.000210479290148694,-3.04722013776418E-6,9.9954615,9.9954615,82168.75,82183.859375,57.2660134614484,20.5329942513214,10.760172,0,0,0,40,4449,10.0393,82176.3046875,,,,,,,,,,,,,0,,,,-0.00245,,,,,,9.9954615,,,,
,32919720.285,9.9956427,86829.2265625,-0.000224570504503395,9.64044115599256E-7,1,0.999253354069792,40.0298881530762,1.99512031320028,21.8899995088577,-0.00253395093722334,-0.000488642735687107,0.25,-2.80651902616081E-6,-0.000225018327147817,-4.41237416028608E-6,9.9956427,9.9956427,86816.546875,86841.90625,57.0049495360253,20.534646679668,11.139823,0,0,0,40,4449,10.04285,86829.2265625,,,,,,,,,,,,,0,,,,0.00245,,,,,,9.9956427,,,,
,32919828.245,9.9970493,88812.72265625,-0.00023426775521718,9.48301183427831E-7,1,0.999253354069792,40.0298881530762,1.99506774466928,21.8899995088577,-0.00264387457625709,-0.000508595581111247,0.25,-2.83138484305138E-6,-0.000234767142122699,-4.49693156042866E-6,9.9970493,9.9970493,88802.7734375,88822.671875,56.9166255133522,20.534334775988,10.38052,0,0,0,40,4449,10.04605,88812.72265625,,,,,,,,,,,,,0,,,,0,,,,,,9.9970493,,,,
,32919917.72,9.999547,84341.75390625,-0.00021945109496594,1.1361334317797E-6,1,0.999253354069792,40.0298881530762,1.99523487034247,21.8899995088577,-0.00247445912011397,-0.000485411332643591,0.25,-3.43563493083822E-6,-0.000219845547382135,-5.01673933573387E-6,9.999547,9.999547,84334.09375,84349.4140625,57.2847725459099,20.5362365299913,10.38052,0,0,0,40,4449,10.0446,84341.75390625,,,,,,,,,,,,,0,,,,0,,,,,,9.999547,,,,
,32920014.405,10.0018568,79505.5078125,-0.000199627287946539,1.01968873305357E-6,1,0.999253354069792,40.0298881530762,1.99514609374852,21.8899995088577,-0.00225584650680788,-0.000409138314243814,0.25,-2.53968764972114E-7,-0.000199936037421054,-1.70433737937331E-6,10.0018568,10.0018568,79495.4453125,79515.5703125,56.9400743689291,20.5378331559077,10.760172,0,0,0,40,4449,10.0438,79505.5078125,,,,,,,,,,,,,0,,,,-0.0049,,,,,,10.0018568,,,,
,32920109.23,10.0027361,74764.1484375,-0.000181799934676392,9.27099547696499E-7,1,0.999253354069792,40.0298881530762,1.99517188756835,21.8899995088577,-0.00205332231747787,-0.000374353553729259,0.25,-3.8439545413628E-7,-0.000182012911149422,-1.71859993114199E-6,10.0027361,10.0027361,74756.0859375,74772.2109375,56.9815006804483,20.5346969163707,11.139823,0,0,0,40,4449,10.0389,74764.1484375,,,,,,,,,,,,,0,,,,0.0049,,,,,,10.0027361,,,,
,32920204.86,10.0030994,69986.59765625,-0.000163449076293312,1.30608230333582E-6,1,0.999253354069792,40.0298881530762,1.99496807056552,21.8899995088577,-0.00185047934302271,-0.00030685240846229,0.25,2.28070728682214E-6,-0.000163595588251688,1.07411253932219E-6,10.0030994,10.0030994,69979.0546875,69994.140625,57.2988418592561,20.5395950765274,11.519473,0,0,0,40,4449,10.0369,69986.59765625,,,,,,,,,,,,,0,,,,0,,,,,,10.0030994,,,,
,32920302.39,10.0041208,65110.927734375,-0.000144149945186326,1.17124275631662E-6,1,0.999253354069792,40.0298881530762,1.99502889557593,21.8899995088577,-0.00163778069417992,-0.000234790681634197,0.25,5.18186313151632E-6,-0.000144241601274895,4.11265898622103E-6,10.0041208,10.0041208,65101.04296875,65120.8125,56.976810909333,20.5382952982147,11.139823,0,0,0,40,4449,10.0329,65110.927734375,,,,,,,,,,,,,0,,,,0,,,,,,10.0041208,,,,
,32920398.73,10.003932,60294.875,-0.000127549846940475,9.10678027375738E-7,1,0.999253354069792,40.0298881530762,1.99514143829205,21.8899995088577,-0.00144476411528419,-0.000229044491419182,0.25,2.693205429792E-6,-0.000127560683162458,1.74357691696115E-6,10.003932,10.003932,60292.36328125,60297.38671875,57.3488660844868,20.5393693204196,10.760172,0,0,0,40,4449,10.0292,60294.875,,,,,,,,,,,,,0,,,,0,,,,,,10.003932,,,,
,32920496.485,10.0044479,55409.93359375,-0.000110201094525419,1.02394340376759E-6,1,0.999253354069792,40.0298881530762,1.99510459862086,21.8899995088577,-0.00124900535599967,-0.000190261369019313,0.25,2.99358410378543E-6,-0.000110163827735532,2.17329263353072E-6,10.0044479,10.0044479,55399.8203125,55420.046875,57.2261504069676,20.5406339825144,11.139823,0,0,0,40,4449,10.0267,55409.93359375,,,,,,,,,,,,,0,,,,0,,,,,,10.0044479,,,,
,32920594.13,10.0042162,50529.779296875,-9.06529574838208E-5,1.05011653338894E-6,1,0.999253354069792,40.0298881530762,1.99498193593847,21.8899995088577,-0.00102754326877432,-0.000152790746770629,0.25,2.78116301254961E-6,-9.058051230539E-5,2.10908157008343E-6,10.0042162,10.0042162,50522.0078125,50537.55078125,57.2691399755253,20.5406578790891,11.139823,0,0,0,40,4449,10.0213,50529.779296875,,,,,,,,,,,,,0,,,,-0.00245,,,,,,10.0042162,,,,
,32920693.07,10.0035543,45582.333984375,-7.3826941512727E-5,7.70959585089962E-7,1,0.999253354069792,40.0298881530762,1.99502648241992,21.8899995088577,-0.000834019551403231,-0.000137652134713019,0.25,1.08026137589904E-6,-7.37216172842139E-5,5.39756931403885E-7,10.0035543,10.0035543,45575,45589.66796875,56.9119357422368,20.5410376884615,10.38052,0,0,0,40,4449,10.0179,45582.333984375,,,,,,,,,,,,,0,,,,0,,,,,,10.0035543,,,,
,32920790.38,10.0040817,40718.998046875,-5.5890847798019E-5,7.52574572766722E-7,1,0.999253354069792,40.0298881530762,1.99509403722222,21.8899995088577,-0.000631786361092,-0.000100304980040612,0.25,1.15352289853746E-6,-5.57849126321315E-5,7.49989620420275E-7,10.0040817,10.0040817,40711.78125,40726.21484375,57.3488660844868,20.5421368871902,11.139823,0,0,0,40,4449,10.0148,40718.998046875,,,,,,,,,,,,,0,,,,-0.0049,,,,,,10.0040817,,,,
,32920888.865,10.0027409,35796.958984375,-4.06132418109634E-5,8.27762310580503E-7,1,0.999253354069792,40.0298881530762,1.99502477510383,21.8899995088577,-0.000458245047821269,-7.61100017608138E-5,0.25,5.41704006282069E-7,-4.05128500185167E-5,2.55466944505522E-7,10.0027409,10.0027409,35794.2890625,35799.62890625,57.0471574760637,20.5424289178066,11.139823,0,0,0,40,4449,10.0133,35796.958984375,,,,,,,,,,,,,0,,,,0,,,,,,10.0027409,,,,
,32920986.495,10.0021782,30917.1650390625,-2.55089710850729E-5,8.42306418931902E-7,1,0.999253354069792,40.0298881530762,1.99475942769221,21.8899995088577,-0.000288652040522994,-4.21088293551105E-5,0.25,8.38609459412447E-7,-2.5436059231569E-5,6.62360958397502E-7,10.0021782,10.0021782,30912.23046875,30922.099609375,56.9557069393137,20.5417033399402,10.760172,0,0,0,40,4449,10.0114,30917.1650390625,,,,,,,,,,,,,0,,,,0,,,,,,10.0021782,,,,
,32921084.595,10.0022774,26014.3935546875,-8.76270886414269E-6,7.95225987179764E-7,1,0.999253354069792,40.0298881530762,1.99496023179939,21.8899995088577,-9.9573106632926E-5,-1.18991533018563E-5,0.25,5.13535814233671E-7,-8.73459311169965E-6,4.54221645133754E-7,10.0022774,10.0022774,26009.51953125,26019.267578125,57.088583787583,20.5451801964922,11.139823,0,0,0,40,4449,10.01105,26014.3935546875,,,,,,,,,,,,,0,,,,-0.00245,,,,,,10.0022774,,,,
,32921184.125,10.0012245,21039.61328125,7.3432058730157E-6,6.06423471560129E-7,1,0.999253354069792,40.0298881530762,1.99474866307789,21.8899995088577,8.05347690540311E-5,2.59159940645317E-5,0.25,9.91052076926471E-7,7.30693428475518E-6,1.03298887035853E-6,10.0012245,10.0012245,21032.435546875,21046.791015625,56.8103240347368,20.5494250841606,10.760172,0,0,0,40,4449,10.01035,21039.61328125,,,,,,,,,,,,,0,,,,-0.00245,,,,,,10.0012245,,,,
,32921281.225,10.0002623,16187.5688476562,2.30211586973433E-5,5.14099512348126E-7,1,0.999253354069792,40.0298881530762,1.99500618184187,21.8899995088577,0.000255982242780094,6.11966328182102E-5,0.25,1.33211242615017E-6,2.29083335840756E-5,1.46280505050841E-6,10.0002623,10.0002623,16180.08203125,16195.0556640625,57.2503808910638,20.543521118534,10.760172,0,0,0,40,4449,10.0095,16187.5688476562,,,,,,,,,,,,,0,,,,0.00245,,,,,,10.0002623,,,,
,32921378.655,10,11317.58984375,3.85464589644883E-5,3.51685119836361E-7,1,0.999253354069792,40.0298881530762,1.99502726693985,21.8899995088577,0.00043209710756552,8.19353397970972E-5,0.25,4.19595105300837E-7,3.83519158782888E-5,6.33022429836363E-7,10,10,11312.6005859375,11322.5791015625,57.1323549846599,20.5422686536562,10.760172,0,0,0,40,4449,10.01,11317.58984375,,,,,,,,,,,,,0,,,,-0.00245,,,,,,10,,,,
,32921475.135,9.9986486,6497.51000976563,5.35496595781065E-5,3.3203282034289E-7,1,0.999253354069792,40.0298881530762,1.99501760316707,21.8899995088577,0.000600245925432055,0.000112685323519854,0.25,5.04165290444573E-7,5.32598211966688E-5,7.81832066575371E-7,9.9986486,9.9986486,6490.203125,6504.81689453125,57.1175040427945,20.5433524934989,11.139823,0,0,0,40,4449,10.01115,6497.51000976563,,,,,,,,,,,,,0,,,,0.00245,,,,,,9.9986486,,,,
,32921568.89,10.0004148,1811.35632324219,6.76458353762951E-5,2.95898689350492E-7,1,0.999253354069792,40.0298881530762,1.9950921831006,21.8899995088577,0.000758781726561236,0.000138196724661891,0.25,2.92264409226786E-7,6.726125361802E-5,6.22966003695223E-7,10.0004148,10.0004148,1801.36376953125,1821.34887695313,57.3801312252561,20.5427948070073,10.38052,0,0,0,40,4449,10.01125,1811.35632324219,,,,,,,,,,,,,0,,,,-0.00245,,,,,,10.0004148,,,,
,32921607.5,10.00307225,-0.388206198811531,7.20369259200489E-5,3.16275397421414E-7,1,0.999253354069792,40.0298881530762,1.99496042345793,21.8899995088577,0.000808373311823026,0.000144593584272699,0.25,9.05362159787924E-8,7.16226674440831E-5,4.37229379756189E-7,10.0028105,10.003334,-0.411041855812073,-0.365370541810989,57.1878506095253,20.5482969690232,11.139823,0,0,0,40,4417,10.0069,-0.388206198811531,,,,,,,,,,,,,0,,,,0,,,,,,10.00307225,,,,