File: data/monolayers/nanoparticles/Ac_CoFe_C/vsm/data_dispersion/AH11_HYST_100OE_200K.DAT
[Header]
; VSM Data File (default extension .dat)
; Copyright (c) 2003-2013, Quantum Design, Inc. All rights reserved.
TITLE,
FILEOPENTIME,20416443.34,08/25/2018,4:12 pm
BYAPP,VSM,2.0,2.0
INFO,PPMS VSM Option Release 1.4.10 Build 1,APPNAME
INFO,Quantum Design Linear Motor Servo Controller,MOTOR_MODULE_NAME
INFO,3101-100 M1,MOTOR_HW_VERSION
INFO,MMC1014,MOTOR_SERIAL_NUMBER
INFO,SRV No X-over 01.03.11,MOTOR_SOFTWARE_VERSION
INFO,Quantum Design VSM Detection Module,VSM_MODULE_NAME
INFO,3101-150 F0,VSM_HW_VERSION
INFO,VSM707,VSM_SERIAL_NUMBER
INFO,VSM No X-over 01.02.05 May 20 2008 13:51:47,VSM_SOFTWARE_VERSION
INFO,704,PREAMP_SERIAL_NUMBER
INFO,822,COIL_SERIAL_NUMBER
INFO,0,MOMENT_UNITS
INFO,CoFe2O4,SAMPLE_MATERIAL
INFO,Cobalt deficient,SAMPLE_COMMENT
INFO,,SAMPLE_MASS
INFO,27,SAMPLE_VOLUME
INFO,,SAMPLE_MOLECULAR_WEIGHT
INFO,,SAMPLE_SIZE
INFO,,SAMPLE_SHAPE
DATATYPE,COMMENT,1
DATATYPE,TIME,2
STARTUPAXIS,X,2
STARTUPAXIS,Y1,5
[Data]
Comment,Time Stamp (sec),Temperature (K),Magnetic Field (Oe),Moment (emu),M. Std. Err. (emu),Transport Action,Averaging Time (sec),Frequency (Hz),Peak Amplitude (mm),Center Position (mm),Coil Signal' (mV),Coil Signal" (mV),Range (mV),M. Quad. Signal (emu),M. Raw' (emu),M. Raw" (emu),Min. Temperature (K),Max. Temperature (K),Min. Field (Oe),Max. Field (Oe),Mass (grams),Motor Lag (deg),Pressure (Torr),VSM Status (code),Motor Status (code),Measure Status (code),Measure Count,PPMS Status (code),System Temp. (K),System Field (Oe),Sample Position (deg),Bridge 1 Resistance (ohms),Bridge 1 Excitation (에),Bridge 2 Resistance (ohms),Bridge 2 Excitation (에),Bridge 3 Resistance (ohms),Bridge 3 Excitation (에),Bridge 4 Resistance (ohms),Bridge 4 Excitation (에),Signal 1 Vin (V),Signal 2 Vin (V),Digital Inputs (code),Drive 1 Iout (mA),Drive 1 Ipower (W),Drive 2 Iout (mA),Drive 2 Ipower (W),Pressure (),Map 20 (),Map 21 (),Map 22 (),Map 23 (),Map 24 (),Map 25 (),Map 26 (),Map 27 (),Map 28 (),Map 29 ()
,20416459.56,200.1888733,-595.001892089844,,,2,,,,23.8799997115135,,,,,,,200.1888733,200.1888733,-595.001892089844,-595.001892089844,,,9.241568,,,,-99999999,4961,200.1682,-595.001892089844,,,,,,,,,,,,,,,,,,,,,,,200.1888733,,,,
,20416566.74,200.12815,3332.0322265625,0.00180634209451606,6.90861403924941E-5,1,0.999253354069792,40.0298881530762,1.99663600753046,23.8600000739098,0.0185567387545527,0.0147003374402668,0.25,0.000982081453866564,0.00181150432554677,0.000987426398009635,200.1276,200.1276,3302.2314453125,3361.8330078125,54.9445767593327,19.4811175413473,10.00087,0,0,0,40,4961,200.12815,3332.0322265625,,,,,,,,,,,,,0,,,,,,,,,,,,,,
,20416638.135,200.1154,6901.92309570312,0.00179485725955256,5.26654206284322E-5,1,0.999253354069792,40.0298881530762,1.99682130735024,23.8600000739098,0.0184434884605396,0.0145904404534119,0.25,0.000974275831348743,0.00179999031082308,0.000979580235177113,200.1159,200.1159,6877.0546875,6926.79150390625,54.9406686167366,19.4807115814707,10.38052,0,0,0,40,4961,200.1154,6901.92309570312,,,,,,,,,,,,,0,,,,,,,,,,,,,,
,20416710.57,200.10705,10523.158203125,0.00184532920089529,7.05204269654753E-5,1,0.999253354069792,40.0298881530762,1.99670453119027,23.8600000739098,0.0189960041619555,0.0147988701446954,0.25,0.000983954821244574,0.00185062771930528,0.000989345653116295,200.1064,200.1064,10490.529296875,10555.787109375,55.2626995666597,19.4799575297677,10.38052,0,0,0,40,4961,200.10705,10523.158203125,,,,,,,,,,,,,0,,,,,,,,,,,,,,
,20416783.03,200.1006,14144.0512695313,0.00177070990788167,6.61789040903076E-5,1,0.999253354069792,40.0298881530762,1.99674009390737,23.8600000739098,0.0182180737875784,0.0142589765099763,0.25,0.000949305741757857,0.00177579046418618,0.000954494519030235,200.1009,200.1009,14114.484375,14173.6181640625,55.0493149809097,19.4783085066704,10.38052,0,0,0,40,4961,200.1006,14144.0512695313,,,,,,,,,,,,,0,,,,,,,,,,,,,,
,20416857.53,200.0889,17869.474609375,0.00184083577412951,7.32911127150602E-5,1,0.999253354069792,40.0298881530762,1.99687664976757,23.8600000739098,0.018773895320923,0.0157857909720371,0.25,0.00107161705770545,0.00184602837709659,0.00107730175214067,200.0895,200.0895,17866.75390625,17872.1953125,55.2939647074289,19.4867586269798,10.00087,0,0,0,40,4961,200.0889,17869.474609375,,,,,,,,,,,,,0,,,,,,,,,,,,,,
,20416929.785,200.0769,21476.9892578125,0.00170345503207201,6.72246593398757E-5,1,0.999253354069792,40.0298881530762,1.99682281039036,23.8600000739098,0.0174313659587445,0.0142677556533841,0.25,0.000961713632292924,0.0017082946865568,0.000966869197143778,200.0764,200.0764,21444.53125,21509.447265625,55.2517567673905,19.486289339406,9.241568,0,0,0,40,4961,200.0769,21476.9892578125,,,,,,,,,,,,,0,,,,,,,,,,,,,,
,20417001.695,200.06735,25072.8740234375,0.00171826502133057,6.76116335390741E-5,1,0.999253354069792,40.0298881530762,1.99707529658885,23.8600000739098,0.0176609914203674,0.0139563714347466,0.25,0.000931548644162799,0.0017231904562971,0.000936614269048104,200.0673,200.0673,25047.966796875,25097.78125,55.1634327447174,19.4810361290894,9.621219,0,0,0,40,4961,200.06735,25072.8740234375,,,,,,,,,,,,,0,,,,,,,,,,,,,,
,20417074.54,200.05615,28714.0029296875,0.00171305894694565,5.56565484451599E-5,1,0.999253354069792,40.0298881530762,1.99695716593072,23.8600000739098,0.01755877971617,0.0141881385109493,0.25,0.00095295062304392,0.00171794567871427,0.000958082643673131,200.0565,200.0565,28691.501953125,28736.50390625,55.3815071015828,19.4949463730755,10.38052,0,0,0,40,4961,200.05615,28714.0029296875,,,,,,,,,,,,,0,,,,,,,,,,,,,,
,20417147.245,200.04475,32347.0390625,0.00170211385350437,7.71035705722862E-5,1,0.999253354069792,40.0298881530762,1.99692678889171,23.8600000739098,0.0173803097728545,0.0144776224537167,0.25,0.000980385311892244,0.00170693569061876,0.000985598384179716,200.0451,200.0451,32314.65234375,32379.42578125,55.4995330079866,19.4884555101636,9.621219,0,0,0,40,4961,200.04475,32347.0390625,,,,,,,,,,,,,0,,,,,,,,,,,,,,
,20417219.715,200.03445,35967.791015625,0.00169634902925379,7.20459647042287E-5,1,0.999253354069792,40.0298881530762,1.99672041416873,23.8600000739098,0.0172181445710741,0.0150122679354429,0.25,0.00102864036192109,0.00170110155767114,0.00103401189976119,200.035,200.035,35937.76171875,35997.8203125,55.7902988171405,19.4887732171324,10.00087,0,0,0,40,4961,200.03445,35967.791015625,,,,,,,,,,,,,0,,,,,,,,,,,,,,
,20417292.49,200.02375,39605.001953125,0.00163276340387756,8.67535877976798E-5,1,0.999253354069792,40.0298881530762,1.99675844027145,23.8600000739098,0.0164771324498856,0.0150022179053634,0.25,0.00103877530855445,0.00163728802178054,0.00104411176227564,200.0229,200.0229,39580.20703125,39629.796875,55.5526837472943,19.4854479923175,10.38052,0,0,0,40,4961,200.02375,39605.001953125,,,,,,,,,,,,,0,,,,,,,,,,,,,,
,20417365.445,200.01405,43253.63671875,0.00171592062183134,7.47516964394454E-5,1,0.999253354069792,40.0298881530762,1.99686806501853,23.870000615716,0.0173665472539154,0.0154833008562369,0.25,0.00106666726748434,0.00172070504765105,0.00107218709972327,200.0131,200.0131,43228.67578125,43278.59765625,55.3502419608135,19.4840629182173,10.00087,0,0,0,40,4961,200.01405,43253.63671875,,,,,,,,,,,,,0,,,,,,,,,,,,,,
,20417437.43,200.0046,46849.876953125,0.00154495921922698,7.78499819651128E-5,1,0.999253354069792,40.0298881530762,1.99683397707579,23.8600000739098,0.0157059382163097,0.0135380072445924,0.25,0.000924924027463933,0.0015493071564444,0.000929769550398701,200.006,200.006,46817.31640625,46882.4375,55.555028632852,19.487153801561,10.00087,0,0,0,40,4961,200.0046,46849.876953125,,,,,,,,,,,,,0,,,,,,,,,,,,,,
,20417511.08,199.9935,50533.0078125,0.00156629220873566,6.34054941197808E-5,1,0.999253354069792,40.0298881530762,1.9968174302826,23.8600000739098,0.0159186964058276,0.0137479430231796,0.25,0.000939733902242864,0.00157070042217699,0.000944651464203573,199.9934,199.9934,50505.421875,50560.59375,55.6144324003136,19.4822022369873,10.38052,0,0,0,40,4961,199.9935,50533.0078125,,,,,,,,,,,,,0,,,,,,,,,,,,,,
,20417584.345,199.98375,54193.638671875,0.00149720695268466,6.6848575104495E-5,1,0.999253354069792,40.0298881530762,1.99665126402486,23.8600000739098,0.0150220520960583,0.0142537014573602,0.25,0.000996411233278357,0.00150131845327164,0.0010014490440221,199.9845,199.9845,54163.765625,54223.51171875,55.6456975410828,19.490651184254,9.621219,0,0,0,40,4961,199.98375,54193.638671875,,,,,,,,,,,,,0,,,,,,,,,,,,,,
,20417656.835,199.9748,57816.380859375,0.00145236470320377,6.25657835445891E-5,1,0.999253354069792,40.0298881530762,1.99673183225792,23.8600000739098,0.0145249258157426,0.0141025346766118,0.25,0.000990827505638701,0.0014563295707578,0.000995796448977542,199.9749,199.9749,57796.5,57836.26171875,55.2048590562366,19.4925798023482,9.621219,0,0,0,40,4961,199.9748,57816.380859375,,,,,,,,,,,,,0,,,,,,,,,,,,,,
,20417728.04,199.96535,61375.033203125,0.00144791993035293,7.59684416944311E-5,1,0.999253354069792,40.0298881530762,1.99679834328964,23.870000615716,0.0144709025861244,0.0141177455947866,0.25,0.000992901961734,0.00145186958971283,0.000997871590530567,199.9651,199.9651,61345.140625,61404.92578125,55.0024172697558,19.4857921254721,9.621219,0,0,0,40,4961,199.96535,61375.033203125,,,,,,,,,,,,,0,,,,,,,,,,,,,,
,20417801.2,199.95455,65033.59375,0.00139018579826512,6.51357172142216E-5,1,0.999253354069792,40.0298881530762,1.99687183487451,23.8600000739098,0.0138926745161143,0.0135652742259748,0.25,0.00095419216780779,0.00139397942156506,0.000958964975482111,199.9542,199.9542,65008.70703125,65058.48046875,55.598799829929,19.4815484094718,10.00087,0,0,0,40,4961,199.95455,65033.59375,,,,,,,,,,,,,0,,,,,,,,,,,,,,
,20417873.88,199.9459,68664.4453125,0.00135035099429556,7.07411277920504E-5,1,0.999253354069792,40.0298881530762,1.99663956737322,23.8600000739098,0.0134191638889481,0.0136009524393747,0.25,0.000964389124222686,0.00135399840409727,0.000969153209977847,199.9462,199.9462,68636.8984375,68691.9921875,55.2369058255251,19.4898156132378,10.00087,0,0,0,40,4961,199.9459,68664.4453125,,,,,,,,,,,,,0,,,,,,,,,,,,,,
,20417945.12,199.9359,72225.2421875,0.00136261716160002,8.56372544231909E-5,1,0.999253354069792,40.0298881530762,1.99706689490147,23.8600000739098,0.013435495781818,0.0143512559621452,0.25,0.00102813950212674,0.00136624191273189,0.00103313535208796,199.9354,199.9354,72195.2421875,72255.2421875,55.7324583067174,19.4886601341911,10.00087,0,0,0,40,4961,199.9359,72225.2421875,,,,,,,,,,,,,0,,,,,,,,,,,,,,
,20418019.705,199.92655,75953.8515625,0.00125022024579358,7.82511522809856E-5,1,0.999253354069792,40.0298881530762,1.99715496845253,23.870000615716,0.0123328198292289,0.013139128882803,0.25,0.000940786458397225,0.00125355101071095,0.000945359792172638,199.9258,199.9258,75923.7265625,75983.9765625,55.5526837472943,19.4910944697834,9.621219,0,0,0,40,4961,199.92655,75953.8515625,,,,,,,,,,,,,0,,,,,,,,,,,,,,
,20418090.39,199.9177,79489.59765625,0.00120518410105695,7.25614606342217E-5,1,0.999253354069792,40.0298881530762,1.99722533630093,23.8600000739098,0.0118113981837504,0.0131130248686806,0.25,0.000946269236887724,0.00120835551400022,0.000950812517051854,199.9174,199.9174,79457.25,79521.9453125,55.8442311849674,19.4848768166189,10.00087,0,0,0,40,4961,199.9177,79489.59765625,,,,,,,,,,,,,0,,,,,,,,,,,,,,
,20418162.265,199.91035,83081.13671875,0.00118501674023236,6.44120080147944E-5,1,0.999253354069792,40.0298881530762,1.99707937018179,23.870000615716,0.0116842978420238,0.012481913597408,0.25,0.00089423395309597,0.00118817532020965,0.000898574424077539,199.9109,199.9109,83051.203125,83111.0703125,55.4237150416212,19.4826073388559,10.00087,0,0,0,40,4961,199.91035,83081.13671875,,,,,,,,,,,,,0,,,,,,,,,,,,,,
,20418232.53,199.9007,86592.41796875,0.0010925544418472,7.01955830743206E-5,1,0.999253354069792,40.0298881530762,1.99737457245995,23.870000615716,0.0105889678622392,0.0125760557283653,0.25,0.000918431905075463,0.001095369806668,0.000922757510476894,199.9008,199.9008,86565.0390625,86619.796875,55.7754478752751,19.4801828550877,10.00087,0,0,0,40,4961,199.9007,86592.41796875,,,,,,,,,,,,,0,,,,,,,,,,,,,,
,20418316.32,199.88995,89965.5625,0.00111594711474505,6.79069518851435E-5,1,0.999253354069792,40.0298881530762,1.99704027440267,23.8600000739098,0.0108620151104212,0.0125666853269055,0.25,0.000913721736233767,0.00111885045786859,0.00091805439087118,199.8887,199.8887,89944.5078125,89986.6171875,55.2267446547751,19.4880397464341,10.00087,0,0,0,40,4961,199.88995,89965.5625,,,,,,,,,,,,,0,,,,,,,,,,,,,,
,20418392.79,199.8868,86161.625,0.00113114961198225,8.34053360103387E-5,1,0.999253354069792,40.0298881530762,1.99698756276489,23.8600000739098,0.0110121996500352,0.0127230970845612,0.25,0.000924893049914882,0.00113409192527341,0.000929282281898796,199.8877,199.8877,86129.265625,86193.984375,55.2869300507558,19.4901531796125,10.00087,0,0,0,40,4961,199.8868,86161.625,,,,,,,,,,,,,0,,,,,,,,,,,,,,
,20418469.32,199.88435,82334.83203125,0.00120875021645308,7.36754035883258E-5,1,0.999253354069792,40.0298881530762,1.99697736284427,23.8600000739098,0.0118783036632387,0.0129583445361415,0.25,0.000932154147643268,0.00121195145847194,0.000936652144571558,199.8847,199.8847,82305.125,82364.5390625,55.7504357626598,19.492586053269,9.621219,0,0,0,40,4961,199.88435,82334.83203125,,,,,,,,,,,,,0,,,,,,,,,,,,,,
,20418546.65,199.88715,78468.3671875,0.00126389304607791,8.68276508112833E-5,1,0.999253354069792,40.0298881530762,1.99712511023345,23.8600000739098,0.0124179872116963,0.0135680316033495,0.25,0.000976225939564669,0.00126723644269568,0.000980936473407675,199.8871,199.8871,78440.9375,78495.796875,55.6738361677751,19.4910112873067,9.621219,0,0,0,40,4961,199.88715,78468.3671875,,,,,,,,,,,,,0,,,,,,,,,,,,,,
,20418620.05,199.88935,74799.42578125,0.00129498726289204,7.83901351186217E-5,1,0.999253354069792,40.0298881530762,1.9969084434121,23.870000615716,0.0126969430708931,0.0140455486556368,0.25,0.00101303501155462,0.00129839723564336,0.00101790762469258,199.8899,199.8899,74776.9453125,74821.90625,55.7301134211597,19.4826407702853,9.621219,0,0,0,40,4961,199.88935,74799.42578125,,,,,,,,,,,,,0,,,,,,,,,,,,,,
,20418694.455,199.8941,71080.8203125,0.00134632074575076,6.92835497914638E-5,1,0.999253354069792,40.0298881530762,1.99716274293767,23.870000615716,0.0133077746026554,0.0139940222610248,0.25,0.000999427614377401,0.00134992039473567,0.0010043093137975,199.8941,199.8941,71078.203125,71083.4375,55.2392507110828,19.4863429308015,10.00087,0,0,0,40,4961,199.8941,71080.8203125,,,,,,,,,,,,,0,,,,,,,,,,,,,,
,20418766.475,199.90475,67480.1875,0.00130625699762462,6.90466926109164E-5,1,0.999253354069792,40.0298881530762,1.99719455320459,23.8600000739098,0.0130851682480424,0.0125802573603452,0.25,0.000881778049135386,0.00130984033379433,0.000886212005409781,199.9053,199.9053,67455.1640625,67505.2109375,55.4807739235251,19.4871790615095,9.621219,0,0,0,40,4961,199.90475,67480.1875,,,,,,,,,,,,,0,,,,,,,,,,,,,,
,20418845.385,199.92015,63539.560546875,0.00137818328810684,6.49907331541402E-5,1,0.999253354069792,40.0298881530762,1.99727119145885,23.8600000739098,0.0136709014480969,0.0140522325092544,0.25,0.000998957521953725,0.00138188841004923,0.0010038746214636,199.92,199.92,63507.2890625,63571.83203125,55.2720791088905,19.4936164240545,10.00087,0,0,0,40,4961,199.92015,63539.560546875,,,,,,,,,,,,,0,,,,,,,,,,,,,,
,20418924.165,199.9328,59598.400390625,0.00147582641299311,6.4753195490309E-5,1,0.999253354069792,40.0298881530762,1.99740048548643,23.8600000739098,0.0148344144308776,0.0139312743314339,0.25,0.000971263906596511,0.00147989586975849,0.000976190822071663,199.9322,199.9322,59568.34765625,59628.453125,55.8497025846021,19.4864054199178,10.38052,0,0,0,40,4961,199.9328,59598.400390625,,,,,,,,,,,,,0,,,,,,,,,,,,,,
,20419003.915,199.9452,55612.6875,0.00155066298016806,6.25390491818056E-5,1,0.999253354069792,40.0298881530762,1.99673980674582,23.8600000739098,0.0156603067405287,0.0141803940712982,0.25,0.000980611612244036,0.00155497846747412,0.000985652478779223,199.9447,199.9447,55580.10546875,55645.26953125,56.1037318533521,19.4990069114797,10.38052,0,0,0,40,4961,199.9452,55612.6875,,,,,,,,,,,,,0,,,,,,,,,,,,,,
,20419084.605,199.9529,51579.78125,0.00150669058329216,6.34273233974755E-5,1,0.999253354069792,40.0298881530762,1.99718796003342,23.870000615716,0.0151688084575338,0.014072855448849,0.25,0.000978502018368437,0.00151085380642806,0.000983490950194755,199.9532,199.9532,51552.46875,51607.09375,55.4807739235251,19.4873929166188,9.621219,0,0,0,40,4961,199.9529,51579.78125,,,,,,,,,,,,,0,,,,,,,,,,,,,,
,20419164.78,199.95835,47571.8984375,0.00157569507318551,5.83627467485421E-5,1,0.999253354069792,40.0298881530762,1.99734683669277,23.8600000739098,0.0159963641876676,0.0139603534746855,0.25,0.000956508301832109,0.00158011785581205,0.000961497200130135,199.958,199.958,47544.41015625,47599.38671875,55.3533684748905,19.493546581634,10.38052,0,0,0,40,4961,199.95835,47571.8984375,,,,,,,,,,,,,0,,,,,,,,,,,,,,
,20419243.75,199.95745,43626.130859375,0.00153251160198993,6.2379492190845E-5,1,0.999253354069792,40.0298881530762,1.99763210108048,23.8600000739098,0.0154917696209766,0.013972847004071,0.25,0.000964939117884045,0.00153677411355864,0.000969913479805665,199.9571,199.9571,43591.1484375,43661.11328125,55.2431588536789,19.4892919788112,10.00087,0,0,0,40,4961,199.95745,43626.130859375,,,,,,,,,,,,,0,,,,,,,,,,,,,,
,20419324.31,199.9554,39598.033203125,0.0015879528523187,6.44402653438284E-5,1,0.999253354069792,40.0298881530762,1.99733853488008,23.8600000739098,0.0160827522861069,0.0142873557702772,0.25,0.000983194914171695,0.00159238534298152,0.000988294321946602,199.9548,199.9548,39593,39603.06640625,55.6925952522367,19.4938576076282,10.38052,0,0,0,40,4961,199.9554,39598.033203125,,,,,,,,,,,,,0,,,,,,,,,,,,,,
,20419403.215,199.9545,35655.79296875,0.00160877086107002,6.18739753312323E-5,1,0.999253354069792,40.0298881530762,1.99804557267405,23.870000615716,0.0164425251071907,0.0136536157992697,0.25,0.000923326318093483,0.00161333754096012,0.00092824372489282,199.9544,199.9544,35630.80078125,35680.78515625,55.1868816002943,19.4898116807737,9.621219,0,0,0,40,4961,199.9545,35655.79296875,,,,,,,,,,,,,0,,,,,,,,,,,,,,
,20419482.075,199.94955,31715.6298828125,0.00173641459441404,8.06185335635071E-5,1,0.999253354069792,40.0298881530762,1.99723771916928,23.8600000739098,0.0175829107975339,0.0156371216099208,0.25,0.00107641193126424,0.00174125592135434,0.00108199813961988,199.9497,199.9497,31683.123046875,31748.13671875,55.6808708244482,19.5003105122361,10.00087,0,0,0,40,4961,199.94955,31715.6298828125,,,,,,,,,,,,,0,,,,,,,,,,,,,,
,20419560.575,199.9443,27792.814453125,0.00164681715052419,5.85757956748431E-5,1,0.999253354069792,40.0298881530762,1.99766390535027,23.870000615716,0.0167756106335283,0.0142771657286524,0.25,0.000971871056251841,0.00165145964520417,0.000977002396085471,199.9435,199.9435,27765.330078125,27820.298828125,55.6785259388905,19.4898813122409,10.38052,0,0,0,40,4961,199.9443,27792.814453125,,,,,,,,,,,,,0,,,,,,,,,,,,,,
,20419633.74,199.9411,24134.3173828125,0.00177452378159494,5.40711925533617E-5,1,0.999253354069792,40.0298881530762,1.99739925757753,23.8600000739098,0.0181132722834119,0.0151574870608907,0.25,0.00102741829521709,0.0017795459004979,0.00103288162396325,199.9407,199.9407,24111.986328125,24156.6484375,55.8082762730828,19.4981218272071,10.00087,0,0,0,40,4961,199.9411,24134.3173828125,,,,,,,,,,,,,0,,,,,,,,,,,,,,
,20419705.37,199.938,20553.595703125,0.00179025584450786,6.45961702718314E-5,1,0.999253354069792,40.0298881530762,1.99712549781514,23.8600000739098,0.0182943552237243,0.0151579647973179,0.25,0.00102490057730074,0.0017953333770093,0.00103037461603133,199.9384,199.9384,20523.615234375,20583.576171875,55.4471638971982,19.49281587571,10.00087,0,0,0,40,4961,199.938,20553.595703125,,,,,,,,,,,,,0,,,,,,,,,,,,,,
,20419777.835,199.93935,16933.287109375,0.0017850645044389,5.85606781206876E-5,1,0.999253354069792,40.0298881530762,1.99745648743786,23.8600000739098,0.0183829025911992,0.0143176469857355,0.25,0.000951545231252982,0.00179020159302868,0.000956762457051567,199.9386,199.9386,16905.95703125,16960.6171875,55.5018778935443,19.4921538831591,10.38052,0,0,0,40,4961,199.93935,16933.287109375,,,,,,,,,,,,,0,,,,,,,,,,,,,,
,20419850.22,199.9388,13315.404296875,0.00173968605977915,4.49065064634063E-5,1,0.999253354069792,40.0298881530762,1.99757594337784,23.870000615716,0.0178777258418292,0.0141782432153014,0.25,0.000947070263989039,0.00174466968040385,0.000952225091173235,199.9393,199.9393,13288.2109375,13342.59765625,55.8880023820444,19.4934002815675,10.00087,0,0,0,40,4961,199.9388,13315.404296875,,,,,,,,,,,,,0,,,,,,,,,,,,,,
,20419921.88,199.94,9735.13916015625,0.00183183003548901,6.6602500111974E-5,1,0.999253354069792,40.0298881530762,1.99733679059804,23.8600000739098,0.0189850420436234,0.0139914792078873,0.25,0.000914749430820885,0.00183716539358552,0.000919894432777667,199.9389,199.9389,9705.017578125,9765.2607421875,55.7519990196982,19.5023223890441,10.38052,0,0,0,40,4961,199.94,9735.13916015625,,,,,,,,,,,,,0,,,,,,,,,,,,,,
,20419993.47,199.94165,6156.89111328125,0.00177627202483872,6.1082953004588E-5,1,0.999253354069792,40.0298881530762,1.99740906455404,23.8600000739098,0.0181954069210278,0.014802279497108,0.25,0.000995799809522122,0.00178132611061317,0.00100116632668344,199.9409,199.9409,6141.833984375,6171.9482421875,55.537832805429,19.4971951390996,9.621219,0,0,0,40,4961,199.94165,6156.89111328125,,,,,,,,,,,,,0,,,,,,,,,,,,,,
,20420064.065,199.94595,2627.84057617187,0.00164693754996743,4.12432380764895E-5,1,0.999253354069792,40.0298881530762,1.99709666285675,23.8600000739098,0.0170395252330062,0.0127350468836968,0.25,0.00083627357960199,0.00165171676991141,0.000840950181456398,199.9464,199.9464,2597.810546875,2657.87060546875,56.0029017743713,19.4935023476258,10.38052,0,0,0,40,4961,199.94595,2627.84057617187,,,,,,,,,,,,,0,,,,,,,,,,,,,,
,20420133.835,199.9502,-857.19580078125,-0.00157238743249441,5.22705168011124E-5,1,0.999253354069792,40.0298881530762,1.99683680950774,23.8600000739098,-0.0161618175954726,-0.0127579686566528,0.25,-0.00085138169747365,-0.00157689215277305,-0.000856029951523195,199.9497,199.9497,-884.57421875,-829.8173828125,55.4932799798328,19.4947030265941,9.621219,0,0,0,40,4961,199.9502,-857.19580078125,,,,,,,,,,,,,0,,,,,,,,,,,,,,
,20420205.46,199.9518,-4434.8662109375,-0.00175011522330804,4.11692610188744E-5,1,0.999253354069792,40.0298881530762,1.99708788457275,23.8600000739098,-0.0181601303917549,-0.0132266283677459,0.25,-0.000861681174923305,-0.00175522341807331,-0.000866556539950873,199.9516,199.9516,-4464.689453125,-4405.04296875,55.3940131578905,19.497515269321,9.621219,0,0,0,40,4961,199.9518,-4434.8662109375,,,,,,,,,,,,,0,,,,,,,,,,,,,,
,20420277.215,199.94975,-8023.9072265625,-0.00181375935354219,5.31877515920275E-5,1,0.999253354069792,40.0298881530762,1.99749716605014,23.870000615716,-0.0187791705701412,-0.0139697472679162,0.25,-0.000915878453381878,-0.00181902990144877,-0.000921008303906407,199.9504,199.9504,-8053.78466796875,-7994.02978515625,55.3463338182174,19.4953373333528,9.621219,0,0,0,40,4961,199.94975,-8023.9072265625,,,,,,,,,,,,,0,,,,,,,,,,,,,,
,20420349.36,199.94725,-11630.1723632812,-0.00182181735397488,6.94242484024401E-5,1,0.999253354069792,40.0298881530762,1.99711587377972,23.8600000739098,-0.0185302967665403,-0.0159227924148062,0.25,-0.00108682386729933,-0.00182693211693444,-0.00109255092207218,199.9473,199.9473,-11652.8388671875,-11607.505859375,55.7379297063521,19.5018422960436,10.00087,0,0,0,40,4961,199.94725,-11630.1723632812,,,,,,,,,,,,,0,,,,,,,,,,,,,,
,20420419.865,199.946,-15153.4853515625,-0.00179915529788987,5.7471519017834E-5,1,0.999253354069792,40.0298881530762,1.99765052076251,23.8600000739098,-0.0186049670884919,-0.0139987505052339,0.25,-0.000920883596544986,-0.00180437309656867,-0.000926010959059014,199.9471,199.9471,-15175.8642578125,-15131.1064453125,55.8356332712559,19.4979259059203,9.621219,0,0,0,40,4961,199.946,-15153.4853515625,,,,,,,,,,,,,0,,,,,,,,,,,,,,
,20420493.065,199.9406,-18811.3671875,-0.00180237392303953,7.33543922583293E-5,1,0.999253354069792,40.0298881530762,1.997219377502,23.8600000739098,-0.0184023738155392,-0.0153569936910125,0.25,-0.00104027435094981,-0.00180747571070189,-0.00104581556722356,199.9406,199.9406,-18813.896484375,-18808.837890625,55.2118937129097,19.503854552284,10.38052,0,0,0,40,4961,199.9406,-18811.3671875,,,,,,,,,,,,,0,,,,,,,,,,,,,,
,20420573.845,199.9349,-22849.287109375,-0.00172560330277563,6.34998024292828E-5,1,0.999253354069792,40.0298881530762,1.99767923841081,23.8600000739098,-0.0176197690952162,-0.014721469887139,0.25,-0.000997320168556247,-0.00173048855053573,-0.00100262782752558,199.9348,199.9348,-22851.78125,-22846.79296875,55.2204916266212,19.5001188192994,10.00087,0,0,0,40,4961,199.9349,-22849.287109375,,,,,,,,,,,,,0,,,,,,,,,,,,,,
,20420646.875,199.9282,-26499.109375,-0.00177779318521411,8.22604696139362E-5,1,0.999253354069792,40.0298881530762,1.99743752955352,23.8600000739098,-0.0179740356890581,-0.0161815419315409,0.25,-0.00111706106461837,-0.00178273185643379,-0.00112283668852803,199.9279,199.9279,-26524.00390625,-26474.21484375,55.7199522504097,19.4967555033582,10.00087,0,0,0,40,4961,199.9282,-26499.109375,,,,,,,,,,,,,0,,,,,,,,,,,,,,
,20420716.64,199.9228,-29985.109375,-0.00159104471623412,4.43256374972206E-5,1,0.999253354069792,40.0298881530762,1.99800161427645,23.870000615716,-0.0163876399650631,-0.0127737265535561,0.25,-0.000848915394967898,-0.00159562891915976,-0.000853561380628761,199.923,199.923,-30012.55078125,-29957.66796875,55.6066161151213,19.5063358393054,10.00087,0,0,0,40,4961,199.9228,-29985.109375,,,,,,,,,,,,,0,,,,,,,,,,,,,,
,20420788.46,199.9213,-33575.36328125,-0.00163231073436324,6.60215850906367E-5,1,0.999253354069792,40.0298881530762,1.99743313557051,23.8600000739098,-0.0165908423926437,-0.0143525626002876,0.25,-0.000981174758302968,-0.00163689707512466,-0.000986320021720053,199.922,199.922,-33605.14453125,-33545.58203125,55.9989936317752,19.5048914307995,10.00087,0,0,0,40,4961,199.9213,-33575.36328125,,,,,,,,,,,,,0,,,,,,,,,,,,,,
,20420860.905,199.92005,-37195.703125,-0.00171356725424908,6.72636714134423E-5,1,0.999253354069792,40.0298881530762,1.99752932484517,23.8600000739098,-0.0174397501156026,-0.0149399584881755,0.25,-0.00101876195024267,-0.00171839601724895,-0.00102412209333287,199.921,199.921,-37228.1953125,-37163.2109375,55.6230303140251,19.5018864039873,9.621219,0,0,0,40,4961,199.92005,-37195.703125,,,,,,,,,,,,,0,,,,,,,,,,,,,,
,20420935.85,199.91905,-40938.671875,-0.00146274589985505,4.83404897783104E-5,1,0.999253354069792,40.0298881530762,1.99749119265902,23.8600000739098,-0.015003342260482,-0.0120817470580373,0.25,-0.000810506163313501,-0.00146693303079149,-0.000814875202954957,199.9176,199.9176,-40971.0546875,-40906.2890625,55.8715881831405,19.5043595982309,10.38052,0,0,0,40,4961,199.91905,-40938.671875,,,,,,,,,,,,,0,,,,,,,,,,,,,,
,20421014.61,199.91585,-44876.541015625,-0.00160170662640685,7.53941274830709E-5,1,0.999253354069792,40.0298881530762,1.99773419035418,23.8600000739098,-0.016350327266396,-0.0136931913733887,0.25,-0.000928222028385449,-0.00160625005243545,-0.000933144453624564,199.9151,199.9151,-44898.828125,-44854.25390625,55.6417893984867,19.5068420726381,10.38052,0,0,0,40,4961,199.91585,-44876.541015625,,,,,,,,,,,,,0,,,,,,,,,,,,,,
,20421096.4,199.91325,-48964.048828125,-0.00153230831353675,6.78677690227381E-5,1,0.999253354069792,40.0298881530762,1.99762257201128,23.8600000739098,-0.0155365690704285,-0.0137010550854761,0.25,-0.000941034006511151,-0.00153660037531004,-0.000945924024262922,199.9137,199.9137,-48991.6328125,-48936.46484375,55.707446194102,19.5003842472083,9.621219,0,0,0,40,4961,199.91325,-48964.048828125,,,,,,,,,,,,,0,,,,,,,,,,,,,,
,20421175.135,199.90375,-52898.880859375,-0.00140729118217746,5.72913594533888E-5,1,0.999253354069792,40.0298881530762,1.99776563364663,23.8600000739098,-0.0141550884676536,-0.0132456363829084,0.25,-0.00092254240651106,-0.00141117318192936,-0.000927233060921082,199.9035,199.9035,-52928.8125,-52868.94921875,56.0013385173328,19.5066948978499,10.38052,0,0,0,40,4961,199.90375,-52898.880859375,,,,,,,,,,,,,0,,,,,,,,,,,,,,
,20421255.235,199.89415,-56901.720703125,-0.00136420444722159,6.02738492972022E-5,1,0.999253354069792,40.0298881530762,1.99735739453207,23.8600000739098,-0.0137772943518824,-0.0125022567905889,0.25,-0.000864749507979305,-0.00136800141650748,-0.000869192471381163,199.8945,199.8945,-56931.6953125,-56871.74609375,55.5558102613713,19.5084562904665,10.00087,0,0,0,40,4961,199.89415,-56901.720703125,,,,,,,,,,,,,0,,,,,,,,,,,,,,
,20421335.56,199.88185,-60916.611328125,-0.0014334037475333,6.71424360888887E-5,1,0.999253354069792,40.0298881530762,1.99741775682696,23.870000615716,-0.0143700909971489,-0.0137500775701427,0.25,-0.000962653308944037,-0.00143733844301921,-0.000967506615726784,199.8819,199.8819,-60919.3984375,-60913.82421875,55.3541501034097,19.5151856012509,10.38052,0,0,0,40,4961,199.88185,-60916.611328125,,,,,,,,,,,,,0,,,,,,,,,,,,,,
,20421417.64,199.86915,-65019.552734375,-0.00141488300358998,7.91728689533337E-5,1,0.999253354069792,40.0298881530762,1.99738839414895,23.8600000739098,-0.0139414699151218,-0.0149701987253836,0.25,-0.00107340070536387,-0.00141863885757385,-0.00107861552852856,199.8684,199.8684,-65047.08984375,-64992.015625,55.7824825319482,19.5092459229337,9.621219,0,0,0,40,4961,199.86915,-65019.552734375,,,,,,,,,,,,,0,,,,,,,,,,,,,,
,20421497.41,199.8548,-69004.828125,-0.00136856932496147,6.82670599325942E-5,1,0.999253354069792,40.0298881530762,1.99745099162937,23.8600000739098,-0.0136306069002885,-0.0136453779307933,0.25,-0.00096467088276894,-0.00137228305314368,-0.000969458671748246,199.8536,199.8536,-69009.484375,-69000.171875,55.9388082357944,19.5134328709598,10.38052,0,0,0,40,4961,199.8548,-69004.828125,,,,,,,,,,,,,0,,,,,,,,,,,,,,
,20421575.065,199.84005,-72884.3984375,-0.00124668518116505,5.54096167414402E-5,1,0.999253354069792,40.0298881530762,1.9972809384875,23.8600000739098,-0.0123373162265481,-0.0128804236644139,0.25,-0.000918528251909661,-0.00125002856414361,-0.000923025761710795,199.8406,199.8406,-72911.8125,-72856.984375,55.802023244929,19.5239692874455,10.38052,0,0,0,40,4961,199.84005,-72884.3984375,,,,,,,,,,,,,0,,,,,,,,,,,,,,
,20421655.46,199.8255,-76904.66796875,-0.00118941493938308,7.53239495237358E-5,1,0.999253354069792,40.0298881530762,1.99756932987541,23.8600000739098,-0.0117187084284767,-0.0125985289952993,0.25,-0.000903481302785679,-0.00119257856191167,-0.000907864663943625,199.8246,199.8246,-76909.265625,-76900.0703125,55.7910804456597,19.5135831005872,10.38052,0,0,0,40,4961,199.8255,-76904.66796875,,,,,,,,,,,,,0,,,,,,,,,,,,,,
,20421734.48,199.809,-80852.671875,-0.00122015426872174,8.14805180478205E-5,1,0.999253354069792,40.0298881530762,1.99725961008083,23.8600000739098,-0.0119761000693961,-0.0131739691307835,0.25,-0.000949016926062235,-0.00122337891555639,-0.000953588945475638,199.8096,199.8096,-80887.6328125,-80817.7109375,55.6120875147559,19.5150175062612,10.00087,0,0,0,40,4961,199.809,-80852.671875,,,,,,,,,,,,,0,,,,,,,,,,,,,,
,20421811.26,199.79085,-84689.90625,-0.00119651805994567,8.43529465007474E-5,1,0.999253354069792,40.0298881530762,1.99776421238048,23.8600000739098,-0.0115041165425042,-0.0143203393502158,0.25,-0.00105383767021342,-0.00119955324553809,-0.00105874653677628,199.7898,199.7898,-84719.8203125,-84659.9921875,55.7371480778328,19.5081565585597,9.621219,0,0,0,40,4961,199.79085,-84689.90625,,,,,,,,,,,,,0,,,,,,,,,,,,,,
,20421881.16,199.77635,-88182.16015625,-0.0011145167361784,6.10871215443782E-5,1,0.999253354069792,40.0298881530762,1.9980605616755,23.870000615716,-0.0108586109502113,-0.0125267528971733,0.25,-0.000909907428212893,-0.00111742161870223,-0.000914230373768199,199.7767,199.7767,-88212.1640625,-88152.15625,55.3385175330251,19.5072275593611,10.38052,0,0,0,40,4961,199.77635,-88182.16015625,,,,,,,,,,,,,0,,,,,,,,,,,,,,
,20421964.96,199.76045,-88397.76953125,-0.00110673097742997,8.05224068236098E-5,1,0.999253354069792,40.0298881530762,1.9974099231747,23.8600000739098,-0.0108220782018979,-0.0121896772393452,0.25,-0.000881900592759839,-0.00110963889999784,-0.000886118799372931,199.7614,199.7614,-88427.859375,-88367.6796875,55.7402745919097,19.5183490193089,9.621219,0,0,0,40,4961,199.76045,-88397.76953125,,,,,,,,,,,,,0,,,,,,,,,,,,,,
,20422033.805,199.7528,-84958.0703125,-0.00119146469205874,8.62455278578759E-5,1,0.999253354069792,40.0298881530762,1.99753615109369,23.8600000739098,-0.0115703968457592,-0.0135897518832942,0.25,-0.00099047936343838,-0.00119455041214548,-0.000995164842201796,199.7525,199.7525,-84980.6484375,-84935.4921875,55.8418862994097,19.5089214953848,10.00087,0,0,0,40,4961,199.7528,-84958.0703125,,,,,,,,,,,,,0,,,,,,,,,,,,,,
,20422105.965,199.7528,-81353.06640625,-0.00124090301883652,8.54014558700255E-5,1,0.999253354069792,40.0298881530762,1.99760465797936,23.870000615716,-0.0121854338484303,-0.0133792043204423,0.25,-0.000963302668599026,-0.00124418662721067,-0.000967947943997168,199.7523,199.7523,-81383,-81323.1328125,55.5472123476597,19.5007258018031,10.00087,0,0,0,40,4961,199.7528,-81353.06640625,,,,,,,,,,,,,0,,,,,,,,,,,,,,
,20422179.015,199.7538,-77699.84765625,-0.0012426142566994,7.31688789891486E-5,1,0.999253354069792,40.0298881530762,1.997696862622,23.870000615716,-0.0123387948326603,-0.0126148581364308,0.25,-0.000895611004323597,-0.00124597321670838,-0.000900025499303251,199.7545,199.7545,-77704.6875,-77695.0078125,55.6894687381597,19.5003478652291,10.38052,0,0,0,40,4961,199.7538,-77699.84765625,,,,,,,,,,,,,0,,,,,,,,,,,,,,
,20422249.72,199.7602,-74166.7421875,-0.00121903461054681,6.25875798808E-5,1,0.999253354069792,40.0298881530762,1.99780483417297,23.8600000739098,-0.0120225452721491,-0.0128523980962031,0.25,-0.00092057414105379,-0.00122228345975335,-0.000925051817453331,199.7601,199.7601,-74196.6640625,-74136.8203125,55.5667530606405,19.497067943266,10.00087,0,0,0,40,4961,199.7602,-74166.7421875,,,,,,,,,,,,,0,,,,,,,,,,,,,,
,20422321.26,199.7677,-70591.50390625,-0.00131149786978391,7.98832103785373E-5,1,0.999253354069792,40.0298881530762,1.99763015903172,23.8600000739098,-0.0129178611215265,-0.0139152499386169,0.25,-0.000998253221075743,-0.00131498254567862,-0.00100309941623971,199.7682,199.7682,-70619.1640625,-70563.84375,55.3588398745251,19.5006300072817,10.00087,0,0,0,40,4961,199.7677,-70591.50390625,,,,,,,,,,,,,0,,,,,,,,,,,,,,
,20422395.805,199.77515,-66866.62890625,-0.00137167108774763,7.470104828846E-5,1,0.999253354069792,40.0298881530762,1.99753631556167,23.8600000739098,-0.0135306919516835,-0.0144334084174852,0.25,-0.00103351163218455,-0.00137532436119159,-0.00103854550664026,199.7751,199.7751,-66896.640625,-66836.6171875,55.7910804456597,19.4994104366072,9.621219,0,0,0,40,4961,199.77515,-66866.62890625,,,,,,,,,,,,,0,,,,,,,,,,,,,,
,20422474.62,199.7855,-62926.544921875,-0.00135335761912508,6.54564398200765E-5,1,0.999253354069792,40.0298881530762,1.99766711811305,23.8600000739098,-0.013579878788324,-0.0129227855199618,0.25,-0.000903518874184505,-0.00135708295883577,-0.000908085065056121,199.7855,199.7855,-62929.01953125,-62924.0703125,56.0107180595636,19.5082617151974,10.00087,0,0,0,40,4961,199.7855,-62926.544921875,,,,,,,,,,,,,0,,,,,,,,,,,,,,
,20422548.77,199.79285,-59220.693359375,-0.00144975896913082,7.33845535173003E-5,1,0.999253354069792,40.0298881530762,1.99769521345306,23.8600000739098,-0.0143523803747013,-0.0149661767739055,0.25,-0.00106678949075034,-0.00145364206927223,-0.00107202529039106,199.7927,199.7927,-59250.65234375,-59190.734375,55.8231272149482,19.5002757516634,10.00087,0,0,0,40,4961,199.79285,-59220.693359375,,,,,,,,,,,,,0,,,,,,,,,,,,,,
,20422621.47,199.8059,-55587.85546875,-0.00146807045427423,8.26297104202823E-5,1,0.999253354069792,40.0298881530762,1.99741019857794,23.870000615716,-0.0146306735672534,-0.0145829719868237,0.25,-0.00103002155620684,-0.00147205346460884,-0.00103515121888528,199.8065,199.8065,-55618.015625,-55557.6953125,55.5268900061597,19.4959448238476,9.621219,0,0,0,40,4961,199.8059,-55587.85546875,,,,,,,,,,,,,0,,,,,,,,,,,,,,
,20422694.915,199.8206,-51920.26953125,-0.0015380675253566,8.59126781754338E-5,1,0.999253354069792,40.0298881530762,1.99767236367956,23.870000615716,-0.0154285378700778,-0.0147136610699994,0.25,-0.00102921721441294,-0.00154229092521598,-0.00103442039131363,199.82,199.82,-51950.14453125,-51890.39453125,55.873151440179,19.5016104823941,10.00087,0,0,0,40,4961,199.8206,-51920.26953125,,,,,,,,,,,,,0,,,,,,,,,,,,,,
,20422767.82,199.83655,-48274.837890625,-0.00162403634233165,8.49297272101531E-5,1,0.999253354069792,40.0298881530762,1.99743852843224,23.8600000739098,-0.0164929388703781,-0.0143603434861929,0.25,-0.000983298067303005,-0.00162860349617406,-0.000988435883562696,199.8364,199.8364,-48302.4296875,-48247.24609375,55.568316317679,19.4973384515107,9.621219,0,0,0,40,4961,199.83655,-48274.837890625,,,,,,,,,,,,,0,,,,,,,,,,,,,,
,20422846.32,199.85415,-44352.041015625,-0.00161005254009127,6.81167497337885E-5,1,0.999253354069792,40.0298881530762,1.9978468580533,23.8600000739098,-0.0163350853332542,-0.0143488520252761,0.25,-0.000984466199350397,-0.00161456714198375,-0.000989594925716149,199.8544,199.8544,-44374.56640625,-44329.515625,55.3830703586212,19.4974808217051,10.00087,0,0,0,40,4961,199.85415,-44352.041015625,,,,,,,,,,,,,0,,,,,,,,,,,,,,
,20422925.035,199.8694,-40419.515625,-0.00166012898892309,7.67009272148503E-5,1,0.999253354069792,40.0298881530762,1.99799033292972,23.870000615716,-0.0167981447759575,-0.0150617062615077,0.25,-0.00103847722253664,-0.00166475604184681,-0.00104384829508823,199.8699,199.8699,-40452.12109375,-40386.91015625,55.802023244929,19.4948436447473,10.00087,0,0,0,40,4961,199.8694,-40419.515625,,,,,,,,,,,,,0,,,,,,,,,,,,,,
,20423002.305,199.8797,-36556.841796875,-0.00161051983091602,5.41635125787997E-5,1,0.999253354069792,40.0298881530762,1.99774842505715,23.870000615716,-0.0165210306174791,-0.0133042340386503,0.25,-0.000892409129854865,-0.00161512961106391,-0.000897223979706197,199.8797,199.8797,-36589.5859375,-36524.09765625,55.6566403403521,19.5027620572053,10.00087,0,0,0,40,4961,199.8797,-36556.841796875,,,,,,,,,,,,,0,,,,,,,,,,,,,,
,20423082.36,199.8893,-32556.77734375,-0.00176685753735409,7.80678632282786E-5,1,0.999253354069792,40.0298881530762,1.99762728039492,23.8600000739098,-0.017972278772508,-0.0154666754073347,0.25,-0.00105584786441491,-0.00177182961162716,-0.00106139795793798,199.8901,199.8901,-32561.892578125,-32551.662109375,55.8856574964867,19.4978155332219,10.00087,0,0,0,40,4961,199.8893,-32556.77734375,,,,,,,,,,,,,0,,,,,,,,,,,,,,
,20423161.565,199.89685,-28596.732421875,-0.00171832405230174,5.79950549880214E-5,1,0.999253354069792,40.0298881530762,1.99786031985945,23.8600000739098,-0.0175592651112444,-0.0145901059838218,0.25,-0.000986900662536232,-0.00172320010758695,-0.000992162481268901,199.8972,199.8972,-28599.421875,-28594.04296875,55.8270353575444,19.4959079535207,10.38052,0,0,0,40,4961,199.89685,-28596.732421875,,,,,,,,,,,,,0,,,,,,,,,,,,,,
,20423240.625,199.8998,-24646.3369140625,-0.00165765886606831,5.47186682269788E-5,1,0.999253354069792,40.0298881530762,1.99788549095076,23.870000615716,-0.0170101074049361,-0.01366874666136,0.25,-0.000916251786164018,-0.00166239934695236,-0.000921206394160518,199.9014,199.9014,-24676.302734375,-24616.37109375,55.6503873121982,19.4979263035472,10.38052,0,0,0,40,4961,199.8998,-24646.3369140625,,,,,,,,,,,,,0,,,,,,,,,,,,,,
,20423318.69,199.90045,-20746.07421875,-0.00179464496667836,6.57346801264754E-5,1,0.999253354069792,40.0298881530762,1.99802122669952,23.8600000739098,-0.0184979896885589,-0.0143327652057656,0.25,-0.000950872773428388,-0.0017998196266705,-0.000956097302590574,199.8997,199.8997,-20773.4921875,-20718.65625,55.6886871096405,19.4975508042772,10.38052,0,0,0,40,4961,199.90045,-20746.07421875,,,,,,,,,,,,,0,,,,,,,,,,,,,,
,20423396.645,199.9015,-16848.224609375,-0.00178978428670459,6.30923836434088E-5,1,0.999253354069792,40.0298881530762,1.99798317081156,23.870000615716,-0.0182476950543859,-0.0154442453130423,0.25,-0.0010496502513313,-0.00179483345420525,-0.00105521324822915,199.901,199.901,-16875.90625,-16820.54296875,55.771539732679,19.4975310408581,10.00087,0,0,0,40,4961,199.9015,-16848.224609375,,,,,,,,,,,,,0,,,,,,,,,,,,,,
,20423473.45,199.89805,-13007.8505859375,-0.00186802526202921,7.28621174302071E-5,1,0.999253354069792,40.0298881530762,1.99762213615019,23.8600000739098,-0.0190253291061173,-0.0162131389624984,0.25,-0.00110403820401,-0.00187328421487625,-0.00110987631336168,199.8986,199.8986,-13037.8603515625,-12977.8408203125,55.9434980069098,19.5007586511176,10.38052,0,0,0,40,4961,199.89805,-13007.8505859375,,,,,,,,,,,,,0,,,,,,,,,,,,,,
,20423547.945,199.89295,-9285.26708984375,-0.00174183254158293,5.25947418439358E-5,1,0.999253354069792,40.0298881530762,1.99773598349706,23.8600000739098,-0.0179810142052435,-0.0137370681168536,0.25,-0.00090772913206326,-0.00174686683609353,-0.000912754506429426,199.8916,199.8916,-9305.3330078125,-9265.201171875,55.7168257363328,19.4922687260498,10.38052,0,0,0,40,4961,199.89295,-9285.26708984375,,,,,,,,,,,,,0,,,,,,,,,,,,,,
,20423619.77,199.88995,-5696.26391601562,-0.00176277675625877,6.07149212676565E-5,1,0.999253354069792,40.0298881530762,1.9977090582967,23.8600000739098,-0.0182625583045872,-0.0135244770463048,0.25,-0.000885375116613047,-0.00176790650602281,-0.000890347944053479,199.8897,199.8897,-5721.44384765625,-5671.083984375,55.5034411505828,19.4916752482043,10.00087,0,0,0,40,4961,199.88995,-5696.26391601562,,,,,,,,,,,,,0,,,,,,,,,,,,,,
,20423691.275,199.8867,-2122.73376464844,-0.00170190147420152,5.51461530170888E-5,1,0.999253354069792,40.0298881530762,1.9975748867968,23.870000615716,-0.0176582844577617,-0.0128980224139674,0.25,-0.000840827082159925,-0.00170686831487096,-0.000845581593931721,199.8869,199.8869,-2147.9091796875,-2097.55834960938,56.0419832003329,19.4944520045898,10.00087,0,0,0,40,4961,199.8867,-2122.73376464844,,,,,,,,,,,,,0,,,,,,,,,,,,,,
,20423759.87,199.88345,1304.34411621094,0.00158349459758767,5.00084829625155E-5,1,0.999253354069792,40.0298881530762,1.99777672771854,23.8600000739098,0.0163471290838377,0.0124865543622606,0.25,0.000825032837820866,0.00158806941753865,0.000829604522972891,199.8842,199.8842,1279.3740234375,1329.31420898438,56.0435464573713,19.4869318686211,10.00087,0,0,0,40,4961,199.88345,1304.34411621094,,,,,,,,,,,,,0,,,,,,,,,,,,,,
,20423829.14,199.87935,4766.20703125,0.0017502298276195,5.19802101869574E-5,1,0.999253354069792,40.0298881530762,1.99790870930942,23.8600000739098,0.0180833207446825,0.0137230153119226,0.25,0.000904930099523673,0.0017552952050572,0.000909957754825196,199.8795,199.8795,4736.169921875,4796.244140625,55.8590821268328,19.4892551970838,10.00087,0,0,0,40,4961,199.87935,4766.20703125,,,,,,,,,,,,,0,,,,,,,,,,,,,,
,20423899.86,199.87765,8302.54833984375,0.00168490610151261,4.89235856245596E-5,1,0.999253354069792,40.0298881530762,1.99777146724686,23.870000615716,0.0175353793811738,0.0124724035008389,0.25,0.000806177006661921,0.00168985422196075,0.000810790828604763,199.8771,199.8771,8270.00390625,8335.0927734375,55.7754478752751,19.4961065332883,9.621219,0,0,0,40,4961,199.87765,8302.54833984375,,,,,,,,,,,,,0,,,,,,,,,,,,,,
,20423970.05,199.87385,11808.2563476563,0.00174075949392838,5.88927579747696E-5,1,0.999253354069792,40.0298881530762,1.99765414342842,23.8600000739098,0.0179674580125903,0.0137384274559759,0.25,0.000908082852263133,0.00174579164611941,0.000913107690506939,199.8733,199.8733,11778.2333984375,11838.279296875,55.7058829370636,19.4931993362172,10.38052,0,0,0,40,4961,199.87385,11808.2563476563,,,,,,,,,,,,,0,,,,,,,,,,,,,,
,20424042.125,199.8698,15411.6123046875,0.00183061754906224,7.73142189136868E-5,1,0.999253354069792,40.0298881530762,1.9975562810893,23.870000615716,0.0187591222533123,0.0152239211967673,0.25,0.00102342031643408,0.00183583714477155,0.00102893917074337,199.8698,199.8698,15406.4296875,15416.794921875,55.7676315900828,19.4945121617773,10.38052,0,0,0,40,4961,199.8698,15411.6123046875,,,,,,,,,,,,,0,,,,,,,,,,,,,,
,20424119.19,199.8653,19264.3349609375,0.00173097670605181,6.48422981935543E-5,1,0.999253354069792,40.0298881530762,1.99789985959703,23.8600000739098,0.0178206467356722,0.0139390458565091,0.25,0.000927316844070619,0.00173595785201496,0.00093239356212707,199.8647,199.8647,19258.923828125,19269.74609375,55.1071554913327,19.4896242543322,9.621219,0,0,0,40,4961,199.8653,19264.3349609375,,,,,,,,,,,,,0,,,,,,,,,,,,,,
,20424195.12,199.8624,23057.365234375,0.00175885574985518,6.56596230897602E-5,1,0.999253354069792,40.0298881530762,1.99793024244613,23.870000615716,0.0180378827617007,0.0145671717834517,0.25,0.000977792832633152,0.00176388066798531,0.000983071919628227,199.8615,199.8615,23026.984375,23087.74609375,55.4784290379674,19.497863566167,10.38052,0,0,0,40,4961,199.8624,23057.365234375,,,,,,,,,,,,,0,,,,,,,,,,,,,,
,20424265.43,199.8596,26573.09765625,0.00172757791985691,6.2591325312547E-5,1,0.999253354069792,40.0298881530762,1.99789553207563,23.870000615716,0.0177633264026893,0.0140402458529946,0.25,0.000936828648323021,0.0017325407426134,0.000941930235344721,199.8596,199.8596,26545.55078125,26600.64453125,55.6980666518713,19.4841904665699,10.00087,0,0,0,40,4961,199.8596,26573.09765625,,,,,,,,,,,,,0,,,,,,,,,,,,,,
,20424337.07,199.862,30151.5009765625,0.00168401466410307,6.71640299963587E-5,1,0.999253354069792,40.0298881530762,1.99775740164915,23.8600000739098,0.0171002382687069,0.0149176513453055,0.25,0.00102177896441042,0.0016887370279836,0.00102712493407506,199.8617,199.8617,30119.044921875,30183.95703125,55.7629418189674,19.4922725279511,9.621219,0,0,0,40,4961,199.862,30151.5009765625,,,,,,,,,,,,,0,,,,,,,,,,,,,,
,20424411.86,199.8676,33889.673828125,0.00171642838445792,6.7814758635714E-5,1,0.999253354069792,40.0298881530762,1.99782096139065,23.8600000739098,0.0174500011396841,0.015089689940726,0.25,0.00103126810738756,0.00172125433869491,0.00103667908742114,199.8674,199.8674,33857.1328125,33922.21484375,55.7527806482174,19.4916436249187,10.38052,0,0,0,40,4961,199.8676,33889.673828125,,,,,,,,,,,,,0,,,,,,,,,,,,,,
,20424492.51,199.8696,37922.615234375,0.00163668451131805,6.13621092991464E-5,1,0.999253354069792,40.0298881530762,1.99779236046542,23.8600000739098,0.0165489728314266,0.0149072793477503,0.25,0.00102906817860984,0.00164123920341959,0.0010343831752216,199.8696,199.8696,37920.16015625,37925.0703125,55.6206854284674,19.4948589375912,10.38052,0,0,0,40,4961,199.8696,37922.615234375,,,,,,,,,,,,,0,,,,,,,,,,,,,,
,20424570.995,199.8714,41843.02734375,0.0014889694877069,6.76554979292785E-5,1,0.999253354069792,40.0298881530762,1.99800219161651,23.8600000739098,0.0150777440222202,0.0134432951426755,0.25,0.000925630049070758,0.00149312631592131,0.000930426455637395,199.8721,199.8721,41813.12109375,41872.93359375,55.5597184039674,19.488837710557,10.00087,0,0,0,40,4961,199.8714,41843.02734375,,,,,,,,,,,,,0,,,,,,,,,,,,,,
,20424650.625,199.8683,45826.4765625,0.001586485972935,7.50712341781027E-5,1,0.999253354069792,40.0298881530762,1.99787092272166,23.870000615716,0.015919076721178,0.0151586892765175,0.25,0.00105988967694729,0.00159083853628247,0.00106525246865883,199.8679,199.8679,45801.85546875,45851.09765625,55.4885902087174,19.488949674118,10.38052,0,0,0,40,4961,199.8683,45826.4765625,,,,,,,,,,,,,0,,,,,,,,,,,,,,
,20424730.99,199.8614,49839.4765625,0.00157548001402933,8.33722193322623E-5,1,0.999253354069792,40.0298881530762,1.99789042578356,23.8600000739098,0.0159772194325637,0.0140840264681434,0.25,0.000967117758098217,0.00157989622704125,0.000972145651200025,199.8615,199.8615,49834.50390625,49844.44921875,56.1443765363521,19.4918415166842,10.00087,0,0,0,40,4961,199.8614,49839.4765625,,,,,,,,,,,,,0,,,,,,,,,,,,,,
,20424811.385,199.85225,53862.0390625,0.00148710673602517,7.24771627664261E-5,1,0.999253354069792,40.0298881530762,1.99763515637075,23.8600000739098,0.0151075194249678,0.0131293277401215,0.25,0.000898504119599785,0.00149129299158426,0.000903198177424937,199.8521,199.8521,53832.109375,53891.96875,55.7652867045251,19.4916710895167,10.00087,0,0,0,40,4961,199.85225,53862.0390625,,,,,,,,,,,,,0,,,,,,,,,,,,,,
,20424887.17,199.83885,57647.27734375,0.00153750866625848,7.90031719879777E-5,1,0.999253354069792,40.0298881530762,1.99780746842067,23.8600000739098,0.0153968235674397,0.0148654969296933,0.25,0.00104261111518328,0.00154171837406151,0.00104785561407294,199.8401,199.8401,57614.7734375,57679.78125,55.5315797772751,19.4871276174925,10.38052,0,0,0,40,4961,199.83885,57647.27734375,,,,,,,,,,,,,0,,,,,,,,,,,,,,
,20424966.38,199.8243,61605.6953125,0.0014736959215827,6.98853066421183E-5,1,0.999253354069792,40.0298881530762,1.99779320868956,23.8600000739098,0.0147493493495421,0.0142966576417485,0.25,0.00100358941179683,0.00147772921040885,0.00100862912475378,199.8241,199.8241,61573.046875,61638.34375,55.8903472676021,19.4858488950911,10.38052,0,0,0,40,4961,199.8243,61605.6953125,,,,,,,,,,,,,0,,,,,,,,,,,,,,
,20425046.27,199.8092,65598.9765625,0.00133095625378037,7.63543706461938E-5,1,0.999253354069792,40.0298881530762,1.99758425449979,23.8600000739098,0.0132260770602222,0.0134482961123938,0.25,0.000953758236424528,0.00133455122018388,0.000958472129514128,199.8092,199.8092,65596.5390625,65601.4140625,55.2861484222366,19.4875561161066,10.38052,0,0,0,40,4961,199.8092,65598.9765625,,,,,,,,,,,,,0,,,,,,,,,,,,,,
,20425126.665,199.7883,69617.23046875,0.00127510386731917,6.49019528762841E-5,1,0.999253354069792,40.0298881530762,1.99736764541251,23.8600000739098,0.0125922797707433,0.0133288707846195,0.25,0.000953057982390764,0.00127850912831229,0.000957708835863361,199.7883,199.7883,69614.8046875,69619.65625,55.5057860361405,19.4985626263409,10.00087,0,0,0,40,4961,199.7883,69617.23046875,,,,,,,,,,,,,0,,,,,,,,,,,,,,
,20425203.015,199.7684,73432.8125,0.00127108319841666,7.79705172809998E-5,1,0.999253354069792,40.0298881530762,1.99766709694021,23.8600000739098,0.012429227924169,0.0140095312249899,0.25,0.00101355799881272,0.00127441329676698,0.0010184128414525,199.7672,199.7672,73403.203125,73462.421875,55.8059313875251,19.4941976286882,10.38052,0,0,0,40,4961,199.7684,73432.8125,,,,,,,,,,,,,0,,,,,,,,,,,,,,
,20425276.005,199.7514,77084,0.00120192801067216,7.00647886767652E-5,1,0.999253354069792,40.0298881530762,1.99751092611304,23.8600000739098,0.0118565255979929,0.0126453003220283,0.25,0.00090545724599089,0.00120513539188099,0.000909863297879795,199.7511,199.7511,77056.5390625,77111.4609375,55.2478486247943,19.4966775506087,10.00087,0,0,0,40,4961,199.7514,77084,,,,,,,,,,,,,0,,,,,,,,,,,,,,
,20425349.19,199.736,80740.17578125,0.00116431430055757,6.40304992474547E-5,1,0.999253354069792,40.0298881530762,1.99761187834857,23.8600000739098,0.011480164936352,0.0122841262640114,0.25,0.000880114678580653,0.00116742048427168,0.000884391935809069,199.7362,199.7362,80715.03125,80765.3203125,55.8403230423713,19.498893258485,10.00087,0,0,0,40,4961,199.736,80740.17578125,,,,,,,,,,,,,0,,,,,,,,,,,,,,
,20425421.33,199.72265,84348.57421875,0.0011110402641635,8.00099086735748E-5,1,0.999253354069792,40.0298881530762,1.99762354063873,23.8600000739098,0.0107401236027441,0.0129592959983884,0.25,0.000948847315138024,0.0011138917178853,0.000953305344610433,199.7247,199.7247,84318.4140625,84378.734375,55.7176073648521,19.4942136980309,10.38052,0,0,0,40,4961,199.72265,84348.57421875,,,,,,,,,,,,,0,,,,,,,,,,,,,,
,20425490.965,199.7122,87824.8515625,0.00114910887599532,0.000101370933840436,1,0.999253354069792,40.0298881530762,1.99774712694153,23.8600000739098,0.0111534055496309,0.0131472890996764,0.25,0.000958732221074471,0.00115208408030541,0.00096326327034508,199.7116,199.7116,87797.3125,87852.390625,55.7097910796597,19.5021858491629,10.38052,0,0,0,40,4961,199.7122,87824.8515625,,,,,,,,,,,,,0,,,,,,,,,,,,,,
,20425534.405,199.70535,89996.203125,0.00113969997611906,9.34351359621673E-5,1,0.999253354069792,40.0298881530762,1.99739346957585,23.8600000739098,0.0110698436356221,0.0129820683886603,0.25,0.000946003952868492,0.00114265733666358,0.000950480183816195,199.7047,199.7047,89992.9765625,89999.4296875,55.4667046101789,19.4945893456331,10.38052,0,0,0,40,4929,199.70535,89996.203125,,,,,,,,,,,,,0,,,,,,,,,,,,,,