File: data/monolayers/nanoparticles/Ac_CoFe_C/vsm/data_dispersion/AH11_HYST_100OE_150K.DAT
[Header]
; VSM Data File (default extension .dat)
; Copyright (c) 2003-2013, Quantum Design, Inc. All rights reserved.
TITLE,
FILEOPENTIME,20406230.77,08/25/2018,1:22 pm
BYAPP,VSM,2.0,2.0
INFO,PPMS VSM Option Release 1.4.10 Build 1,APPNAME
INFO,Quantum Design Linear Motor Servo Controller,MOTOR_MODULE_NAME
INFO,3101-100 M1,MOTOR_HW_VERSION
INFO,MMC1014,MOTOR_SERIAL_NUMBER
INFO,SRV No X-over 01.03.11,MOTOR_SOFTWARE_VERSION
INFO,Quantum Design VSM Detection Module,VSM_MODULE_NAME
INFO,3101-150 F0,VSM_HW_VERSION
INFO,VSM707,VSM_SERIAL_NUMBER
INFO,VSM No X-over 01.02.05 May 20 2008 13:51:47,VSM_SOFTWARE_VERSION
INFO,704,PREAMP_SERIAL_NUMBER
INFO,822,COIL_SERIAL_NUMBER
INFO,0,MOMENT_UNITS
INFO,CoFe2O4,SAMPLE_MATERIAL
INFO,Cobalt deficient,SAMPLE_COMMENT
INFO,,SAMPLE_MASS
INFO,27,SAMPLE_VOLUME
INFO,,SAMPLE_MOLECULAR_WEIGHT
INFO,,SAMPLE_SIZE
INFO,,SAMPLE_SHAPE
DATATYPE,COMMENT,1
DATATYPE,TIME,2
STARTUPAXIS,X,2
STARTUPAXIS,Y1,5
[Data]
Comment,Time Stamp (sec),Temperature (K),Magnetic Field (Oe),Moment (emu),M. Std. Err. (emu),Transport Action,Averaging Time (sec),Frequency (Hz),Peak Amplitude (mm),Center Position (mm),Coil Signal' (mV),Coil Signal" (mV),Range (mV),M. Quad. Signal (emu),M. Raw' (emu),M. Raw" (emu),Min. Temperature (K),Max. Temperature (K),Min. Field (Oe),Max. Field (Oe),Mass (grams),Motor Lag (deg),Pressure (Torr),VSM Status (code),Motor Status (code),Measure Status (code),Measure Count,PPMS Status (code),System Temp. (K),System Field (Oe),Sample Position (deg),Bridge 1 Resistance (ohms),Bridge 1 Excitation (에),Bridge 2 Resistance (ohms),Bridge 2 Excitation (에),Bridge 3 Resistance (ohms),Bridge 3 Excitation (에),Bridge 4 Resistance (ohms),Bridge 4 Excitation (에),Signal 1 Vin (V),Signal 2 Vin (V),Digital Inputs (code),Drive 1 Iout (mA),Drive 1 Ipower (W),Drive 2 Iout (mA),Drive 2 Ipower (W),Pressure (),Map 20 (),Map 21 (),Map 22 (),Map 23 (),Map 24 (),Map 25 (),Map 26 (),Map 27 (),Map 28 (),Map 29 ()
,20406247.88,150.1240387,-9657.072265625,,,2,,,,23.9900000834465,,,,,,,150.1240387,150.1240387,-9657.072265625,-9657.072265625,,,9.241568,,,,-99999999,4961,150.1866,-9657.072265625,,,,,,,,,,,,,,,,,,,,,,,150.1240387,,,,
,20406395.735,150.19355,3569.73583984375,-0.00119013772018346,8.9626297224361E-7,1,0.999253354069792,40.0298881530762,1.99567319730755,23.9700004458427,-0.0135045910993107,-0.00240493499819342,0.25,-4.46316393069143E-6,-0.00119595448929294,-6.38861007799326E-6,150.1937,150.1937,3537.27734375,3602.1943359375,54.5396931863712,19.5541854578883,9.241568,0,0,0,40,4961,150.19355,3569.73583984375,,,,,,,,,,,,,0,,,,,,,,,,,,,,
,20406471.955,150.18405,7382.03759765625,0.000361678387580142,1.19437040510016E-6,1,0.999253354069792,40.0298881530762,1.99527801740932,23.9700004458427,0.00410332341601558,0.000730132332307516,0.25,1.3060720858317E-6,0.00036344646129794,1.89006030959791E-6,150.1848,150.1848,7352.09033203125,7411.98486328125,55.4448190116405,19.5578382698963,9.241568,0,0,0,40,4961,150.18405,7382.03759765625,,,,,,,,,,,,,0,,,,,,,,,,,,,,
,20406546.275,150.15425,11098.2724609375,0.00189365364592263,1.45921738766306E-6,1,0.999253354069792,40.0298881530762,1.99521392582187,23.9700004458427,0.0214855046151183,0.00381002197712161,0.25,5.72857992627752E-6,0.00190291519297082,8.77622762108765E-6,150.1543,150.1543,11070.673828125,11125.87109375,55.2337793114482,19.5691695752453,9.241568,0,0,0,40,4961,150.15425,11098.2724609375,,,,,,,,,,,,,0,,,,,,,,,,,,,,
,20406616.5,150.11955,14606.265625,0.00276926398913748,1.88074971005094E-6,1,0.999253354069792,40.0298881530762,1.99496620708952,23.9700004458427,0.0314171630375075,0.00556759575071892,0.25,8.07571278865011E-6,0.00278281263231243,1.25246233182482E-5,150.1194,150.1194,14578.615234375,14633.916015625,55.2720791088905,19.5665425794264,9.621219,0,0,0,40,4961,150.11955,14606.265625,,,,,,,,,,,,,0,,,,,,,,,,,,,,
,20406688.195,150.0825,18189.3427734375,0.00313172637394582,2.50413494522965E-6,1,0.999253354069792,40.0298881530762,1.99516472208388,23.9700004458427,0.0355344050875359,0.00628721444767871,0.25,8.2844002970701E-6,0.00314705472744399,1.33036308440501E-5,150.0825,150.0825,18186.8359375,18191.849609375,55.3432073041405,19.5731561864244,9.621219,0,0,0,40,4961,150.0825,18189.3427734375,,,,,,,,,,,,,0,,,,,,,,,,,,,,
,20406760.215,150.052,21789.3701171875,0.00327885374869534,2.48605116396259E-6,1,0.999253354069792,40.0298881530762,1.99505536467514,23.9700004458427,0.0372056213492846,0.00656092442182543,0.25,6.80377832090765E-6,0.00329490999559924,1.20406845016389E-5,150.0516,150.0516,21784.68359375,21794.056640625,54.495140360775,19.5688498779679,9.241568,0,0,0,40,4961,150.052,21789.3701171875,,,,,,,,,,,,,0,,,,,,,,,,,,,,
,20406833.58,150.02365,25455.421875,0.00334903654291003,3.10316304028731E-6,1,0.999253354069792,40.0298881530762,1.99519306206329,23.9700004458427,0.0379937150283985,0.00676402896036737,0.25,1.24400614742516E-5,0.0033654326096641,1.78061707619819E-5,150.0242,150.0242,25423.0546875,25487.7890625,54.9813132997366,19.5739531723625,9.241568,0,0,0,40,4961,150.02365,25455.421875,,,,,,,,,,,,,0,,,,,,,,,,,,,,
,20406905.06,150.0053,29029.0087890625,0.00337956028521095,2.72111932426897E-6,1,0.999253354069792,40.0298881530762,1.99534820391731,23.9700004458427,0.0383480778577853,0.00679639981241277,0.25,9.93959067370144E-6,0.00339611397801924,1.53313903173183E-5,150.0047,150.0047,29001.828125,29056.189453125,54.6764781772366,19.5692139557899,9.621219,0,0,0,40,4961,150.0053,29029.0087890625,,,,,,,,,,,,,0,,,,,,,,,,,,,,
,20406975.735,149.9873,32562.171875,0.00339877132070558,3.53308108884916E-6,1,0.999253354069792,40.0298881530762,1.99552496405621,23.9700004458427,0.0385687951969964,0.00683893880304488,0.25,1.02989726673572E-5,0.00341542269661412,1.57123135850784E-5,149.9881,149.9881,32529.666015625,32594.677734375,55.2126753414289,19.5683670314796,9.241568,0,0,0,40,4961,149.9873,32562.171875,,,,,,,,,,,,,0,,,,,,,,,,,,,,
,20407046.775,149.9763,36110.37890625,0.00340298327843035,3.7310981323098E-6,1,0.999253354069792,40.0298881530762,1.9956025783416,23.9700004458427,0.0386239263922522,0.00681402712989785,0.25,7.35945542010541E-6,0.00341966346732622,1.27537945236107E-5,149.9763,149.9763,36107.78125,36112.9765625,55.0766719790828,19.5681470314622,8.861917,0,0,0,40,4961,149.9763,36110.37890625,,,,,,,,,,,,,0,,,,,,,,,,,,,,
,20407118.52,149.9656,39697.958984375,0.00339200845641244,3.89662375608483E-6,1,0.999253354069792,40.0298881530762,1.99545548175288,23.9700004458427,0.0384962026091685,0.00679439656609172,0.25,7.5952302952918E-6,0.00340863799024037,1.29619139838953E-5,149.9656,149.9656,39695.27734375,39700.640625,55.2736423659289,19.5658304116137,10.00087,0,0,0,40,4961,149.9656,39697.958984375,,,,,,,,,,,,,0,,,,,,,,,,,,,,
,20407189.875,149.95515,43264.07421875,0.00338831562299896,4.5927887307261E-6,1,0.999253354069792,40.0298881530762,1.99552083284637,23.9700004458427,0.038445301192167,0.00684596691867921,0.25,1.27728204730637E-5,0.00340492246102066,1.81474810532549E-5,149.9561,149.9561,43238.87890625,43289.26953125,54.8695404214866,19.5684727649713,9.621219,0,0,0,40,4961,149.95515,43264.07421875,,,,,,,,,,,,,0,,,,,,,,,,,,,,
,20407264.055,149.9465,46969.99609375,0.00337055647189984,4.16725733266232E-6,1,0.999253354069792,40.0298881530762,1.99572595961252,23.9700004458427,0.0382604106613803,0.00673715468658866,0.25,6.23589978249428E-6,0.00338708990812835,1.15383489020786E-5,149.9465,149.9465,46967.421875,46972.5703125,55.4596699535059,19.5622933215518,9.241568,0,0,0,40,4961,149.9465,46969.99609375,,,,,,,,,,,,,0,,,,,,,,,,,,,,
,20407340.19,149.9397,50775.462890625,0.00334686880565556,4.61702094962219E-6,1,0.999253354069792,40.0298881530762,1.99548869984319,23.9700004458427,0.0379806676385015,0.00672684987869469,0.25,9.53367318582639E-6,0.0033632842509893,1.4802475014455E-5,149.9404,149.9404,50745.3828125,50805.54296875,55.2783321370443,19.5703736641893,9.621219,0,0,0,40,4961,149.9397,50775.462890625,,,,,,,,,,,,,0,,,,,,,,,,,,,,
,20407417.445,149.93115,54635.7109375,0.00331715273113259,5.59615190391796E-6,1,0.999253354069792,40.0298881530762,1.99547508024176,23.9599999040365,0.0376474504443323,0.0066429211564963,0.25,7.33339010926554E-6,0.00333342932783669,1.25321142060031E-5,149.9323,149.9323,54612.89453125,54658.52734375,56.2530229005252,19.580368501757,9.241568,0,0,0,40,4961,149.93115,54635.7109375,,,,,,,,,,,,,0,,,,,,,,,,,,,,
,20407488.335,149.92935,58179.37109375,0.00328402514061889,5.1440337855521E-6,1,0.999253354069792,40.0298881530762,1.9954334097506,23.9700004458427,0.0372780110982428,0.00653483887103236,0.25,3.60680227414474E-6,0.00330014765152599,8.72353108471048E-6,149.9295,149.9295,58146.80859375,58211.93359375,55.0203947256981,19.5709253336409,9.241568,0,0,0,40,4961,149.92935,58179.37109375,,,,,,,,,,,,,0,,,,,,,,,,,,,,
,20407565.68,149.9334,62047.326171875,0.00324919459120682,4.4560351596453E-6,1,0.999253354069792,40.0298881530762,1.99539328044437,23.9700004458427,0.0368631268659592,0.00657353841404143,0.25,1.31058829728534E-5,0.00326513386360548,1.82016928905302E-5,149.9334,149.9334,62014.8125,62079.83984375,54.9140932470827,19.5665596484832,10.00087,0,0,0,40,4961,149.9334,62047.326171875,,,,,,,,,,,,,0,,,,,,,,,,,,,,
,20407645.06,149.94645,66013.3515625,0.00321121520773341,4.77449482318176E-6,1,0.999253354069792,40.0298881530762,1.99523574470614,23.9700004458427,0.0364448124202153,0.00640837734266762,0.25,5.22944278857119E-6,0.00322698199184721,1.02135669563794E-5,149.9466,149.9466,65983.4921875,66043.2109375,55.3322645048712,19.5586854830138,9.241568,0,0,0,40,4961,149.94645,66013.3515625,,,,,,,,,,,,,0,,,,,,,,,,,,,,
,20407725.05,149.95565,70011.8828125,0.00317164389434457,5.51874822139558E-6,1,0.999253354069792,40.0298881530762,1.99521108882972,23.9700004458427,0.0359933195922542,0.00634075706490505,0.25,6.18488826172702E-6,0.00318721699599719,1.10985768355629E-5,149.9556,149.9556,69981.90625,70041.859375,55.8200007008713,19.5547083647333,9.621219,0,0,0,40,4961,149.95565,70011.8828125,,,,,,,,,,,,,0,,,,,,,,,,,,,,
,20407805.45,149.95505,74029.50390625,0.00311457057789184,5.33784379932613E-6,1,0.999253354069792,40.0298881530762,1.99542727105367,23.9700004458427,0.0353397881276793,0.00628199867705977,0.25,1.09042782054227E-5,0.0031298589586508,1.57398075254089E-5,149.955,149.955,73999.4609375,74059.546875,55.5136023213328,19.5534389077764,9.621219,0,0,0,40,4961,149.95505,74029.50390625,,,,,,,,,,,,,0,,,,,,,,,,,,,,
,20407884.1,149.9525,77960.6796875,0.00307105772080955,5.04263689195001E-6,1,0.999253354069792,40.0298881530762,1.99537283887951,23.9700004458427,0.0348635147713121,0.00608886165682566,0.25,1.49725015373926E-6,0.00308614968841201,6.20675666784872E-6,149.9518,149.9518,77933.328125,77988.03125,55.9067614665059,19.5663595821061,9.241568,0,0,0,40,4961,149.9525,77960.6796875,,,,,,,,,,,,,0,,,,,,,,,,,,,,
,20407964.49,149.9355,81981.5,0.00302958227350697,4.87153044760766E-6,1,0.999253354069792,40.0298881530762,1.99556117145969,23.9700004458427,0.0343798995949407,0.00609859151911483,0.25,9.54043722059613E-6,0.00304446220488032,1.42134297410952E-5,149.9355,149.9355,81976.2890625,81986.7109375,55.5870754021405,19.5548139328613,10.00087,0,0,0,40,4961,149.9355,81981.5,,,,,,,,,,,,,0,,,,,,,,,,,,,,
,20408041.805,149.90955,85844.8359375,0.00296678050422393,6.09343548135841E-6,1,0.999253354069792,40.0298881530762,1.99543700553227,23.9700004458427,0.033676887409668,0.00590513041414846,0.25,3.47978631704971E-6,0.00298136552178692,8.01561853955396E-6,149.9101,149.9101,85810.1640625,85879.5078125,54.7663654569481,19.5699895180803,9.621219,0,0,0,40,4961,149.90955,85844.8359375,,,,,,,,,,,,,0,,,,,,,,,,,,,,
,20408118.78,149.88535,89696.05078125,0.00291469326092053,5.27082920923007E-6,1,0.999253354069792,40.0298881530762,1.99539969182152,23.9700004458427,0.0330699174584989,0.00588847384028395,0.25,1.11028740308247E-5,0.00292901491337281,1.5585518917693E-5,149.8859,149.8859,89693.5703125,89698.53125,54.9336339600635,19.5617008782254,9.621219,0,0,0,40,4961,149.88535,89696.05078125,,,,,,,,,,,,,0,,,,,,,,,,,,,,
,20408208.765,149.85595,86598.9453125,0.0029542027703382,4.43387368575737E-6,1,0.999253354069792,40.0298881530762,1.99508979215279,23.9700004458427,0.0335365101973921,0.00583367195950436,0.25,-5.39022505649079E-7,0.00296873655674716,3.95765877129568E-6,149.8563,149.8563,86594.1484375,86603.7421875,55.3041258781789,19.5639749583201,9.621219,0,0,0,40,4961,149.85595,86598.9453125,,,,,,,,,,,,,0,,,,,,,,,,,,,,
,20408280.265,149.8433,83025.15234375,0.00300100874438373,5.02611104677578E-6,1,0.999253354069792,40.0298881530762,1.99522128263181,23.9700004458427,0.0340523585142832,0.00602768468522707,0.25,8.35586084209668E-6,0.00301575769314902,1.29798908689146E-5,149.8434,149.8434,82995.3671875,83054.9375,55.1853183432558,19.5653687446882,9.241568,0,0,0,40,4961,149.8433,83025.15234375,,,,,,,,,,,,,0,,,,,,,,,,,,,,
,20408354.29,149.83785,79323.2265625,0.00305218921963207,4.74127263853612E-6,1,0.999253354069792,40.0298881530762,1.99550329835948,23.9599999040365,0.034635687384709,0.00614314799088807,0.25,9.52879884988741E-6,0.0030671859075041,1.42493488231084E-5,149.8384,149.8384,79295.734375,79350.71875,55.1548348310058,19.5610870007816,9.621219,0,0,0,40,4961,149.83785,79323.2265625,,,,,,,,,,,,,0,,,,,,,,,,,,,,
,20408428.23,149.8309,75629.48046875,0.00309504295810281,4.55524973707537E-6,1,0.999253354069792,40.0298881530762,1.99563507324419,23.9700004458427,0.0351240684846236,0.00623039284183265,0.25,9.70312853096506E-6,0.00311024801401286,1.45029142434345E-5,149.8309,149.8309,75626.9453125,75632.015625,54.9406686167366,19.5515433118683,10.00087,0,0,0,40,4961,149.8309,75629.48046875,,,,,,,,,,,,,0,,,,,,,,,,,,,,
,20408499.745,149.83565,72053.4921875,0.00314229498806651,4.95462680302658E-6,1,0.999253354069792,40.0298881530762,1.99540367749961,23.9700004458427,0.0356581898077124,0.0063141123537123,0.25,8.8974345316211E-6,0.00315773065608356,1.37777772837743E-5,149.8349,149.8349,72023.5625,72083.421875,55.2642628236982,19.5560006739289,9.621219,0,0,0,40,4961,149.83565,72053.4921875,,,,,,,,,,,,,0,,,,,,,,,,,,,,
,20408571.7,149.8374,68457.578125,0.00317948124559641,4.73065903833751E-6,1,0.999253354069792,40.0298881530762,1.99546774279068,23.9700004458427,0.0360888192254574,0.00634554587091142,0.25,5.16107094820075E-6,0.0031951027165294,1.00925375260654E-5,149.8385,149.8385,68425.09375,68490.0625,55.5136023213328,19.5557595233464,9.621219,0,0,0,40,4961,149.8374,68457.578125,,,,,,,,,,,,,0,,,,,,,,,,,,,,
,20408648.07,149.8429,64639.328125,0.00322357799267615,3.59798676814064E-6,1,0.999253354069792,40.0298881530762,1.99553924410813,23.9700004458427,0.0365806775495659,0.00649048448134292,0.25,1.0215091581933E-5,0.00323940513724695,1.52523886316932E-5,149.8425,149.8425,64612.08203125,64666.57421875,56.343691808756,19.5579905894005,9.241568,0,0,0,40,4961,149.8429,64639.328125,,,,,,,,,,,,,0,,,,,,,,,,,,,,
,20408722.365,149.84985,60925.712890625,0.00325843443982111,4.60402993741529E-6,1,0.999253354069792,40.0298881530762,1.99537287843735,23.9700004458427,0.036982619818203,0.00650629959499368,0.25,5.57097164023825E-6,0.00327443673879852,1.0651935168116E-5,149.8497,149.8497,60898.01171875,60953.4140625,56.1623539922944,19.5531835792007,9.621219,0,0,0,40,4961,149.84985,60925.712890625,,,,,,,,,,,,,0,,,,,,,,,,,,,,
,20408794.355,149.8642,57327.265625,0.00329536315389077,3.19204840693692E-6,1,0.999253354069792,40.0298881530762,1.99509469045625,23.9700004458427,0.0373894679183009,0.00662086533176141,0.25,9.29677920253849E-6,0.00331153723112752,1.4465172488606E-5,149.8642,149.8642,57324.71484375,57329.81640625,55.771539732679,19.5511782346767,9.621219,0,0,0,40,4961,149.8642,57327.265625,,,,,,,,,,,,,0,,,,,,,,,,,,,,
,20408873.75,149.89,53359.35546875,0.00332303283846783,3.1922363212422E-6,1,0.999253354069792,40.0298881530762,1.99474425090878,23.9700004458427,0.0376980991880006,0.0066691953681447,0.25,8.82197552206868E-6,0.00333933844012525,1.40436126269048E-5,149.8897,149.8897,53326.77734375,53391.93359375,55.0844882642751,19.564473259638,9.241568,0,0,0,40,4961,149.89,53359.35546875,,,,,,,,,,,,,0,,,,,,,,,,,,,,
,20408952.72,149.91645,49411.58203125,0.00335402247127311,3.04448976662585E-6,1,0.999253354069792,40.0298881530762,1.99485903776397,23.9700004458427,0.0380571111940871,0.00670063763034414,0.25,6.15078164155476E-6,0.00337047923163466,1.14200264331979E-5,149.9164,149.9164,49409.109375,49414.0546875,54.9180013896789,19.5538707158307,9.621219,0,0,0,40,4961,149.91645,49411.58203125,,,,,,,,,,,,,0,,,,,,,,,,,,,,
,20409030.31,149.94015,45536.078125,0.00337584859531133,3.51822439671112E-6,1,0.999253354069792,40.0298881530762,1.99504620356757,23.9700004458427,0.0383050571478694,0.00676254135673521,0.25,7.7383746148099E-6,0.00339240511111445,1.30617457013683E-5,149.9411,149.9411,45506.40625,45565.75,55.4784290379674,19.5613315135661,9.621219,0,0,0,40,4961,149.94015,45536.078125,,,,,,,,,,,,,0,,,,,,,,,,,,,,
,20409107.98,149.9569,41652.78515625,0.00339214980716238,2.67714810621014E-6,1,0.999253354069792,40.0298881530762,1.99508458582303,23.9700004458427,0.0384955079839051,0.00676760512587623,0.25,5.32244243081127E-6,0.00340878579040389,1.06719860087258E-5,149.9567,149.9567,41627.76171875,41677.80859375,55.619122171429,19.5570814409285,9.621219,0,0,0,40,4961,149.9569,41652.78515625,,,,,,,,,,,,,0,,,,,,,,,,,,,,
,20409186.575,149.96455,37724.94140625,0.00340418350023557,2.72470848344597E-6,1,0.999253354069792,40.0298881530762,1.99506335578527,23.9700004458427,0.0386267592009441,0.00681955077014044,0.25,7.7962486067011E-6,0.00342087107390843,1.31897906952193E-5,149.9642,149.9642,37695.10546875,37754.77734375,55.9520959206213,19.5693114948251,9.621219,0,0,0,40,4961,149.96455,37724.94140625,,,,,,,,,,,,,0,,,,,,,,,,,,,,
,20409266.55,149.96345,33727.189453125,0.00340443764060333,3.25577161820818E-6,1,0.999253354069792,40.0298881530762,1.99516393880072,23.9700004458427,0.0386288262862145,0.00683555940261191,0.25,9.12039147580329E-6,0.00342112152806055,1.453427267842E-5,149.9637,149.9637,33697.04296875,33757.3359375,55.6808708244482,19.5718870751727,10.00087,0,0,0,40,4961,149.96345,33727.189453125,,,,,,,,,,,,,0,,,,,,,,,,,,,,
,20409344.455,149.9606,29834.4189453125,0.00339147585835614,2.19331999715601E-6,1,0.999253354069792,40.0298881530762,1.99514416905481,23.9700004458427,0.0384801158690921,0.00681661395967336,0.25,9.70261326565848E-6,0.00340809268005855,1.51118016791208E-5,149.9597,149.9597,29804.486328125,29864.3515625,55.7605969334098,19.5588913650972,9.241568,0,0,0,40,4961,149.9606,29834.4189453125,,,,,,,,,,,,,0,,,,,,,,,,,,,,
,20409423.01,149.9504,25908.26171875,0.00337135683938653,2.15582288109411E-6,1,0.999253354069792,40.0298881530762,1.99511288420305,23.9700004458427,0.0382567059633456,0.00674474545668996,0.25,6.87250355307309E-6,0.00338787756630361,1.22490424817825E-5,149.9504,149.9504,25905.572265625,25910.951171875,55.568316317679,19.5662498532543,9.241568,0,0,0,40,4961,149.9504,25908.26171875,,,,,,,,,,,,,0,,,,,,,,,,,,,,
,20409499.54,149.94005,22083.18359375,0.00333216638269303,1.79432036549581E-6,1,0.999253354069792,40.0298881530762,1.99492101885415,23.9700004458427,0.0378064197130497,0.0066776621202845,0.25,7.83202055588189E-6,0.00334849167314573,1.31634320299449E-5,149.9394,149.9394,22052.9765625,22113.390625,55.3439889326597,19.5761790435457,9.621219,0,0,0,40,4961,149.94005,22083.18359375,,,,,,,,,,,,,0,,,,,,,,,,,,,,
,20409575.42,149.93095,18290.5908203125,0.0032792701208677,1.30183154468612E-6,1,0.999253354069792,40.0298881530762,1.99468273794744,23.9700004458427,0.0371975317906333,0.00659656965270208,0.25,9.95748612012869E-6,0.00329533094794883,1.52268756909433E-5,149.9311,149.9311,18260.69921875,18320.482421875,55.7293317926405,19.5778007824513,9.621219,0,0,0,40,4961,149.93095,18290.5908203125,,,,,,,,,,,,,0,,,,,,,,,,,,,,
,20409648.86,149.92545,14620.1108398438,0.00319889837797767,1.42670984877968E-6,1,0.999253354069792,40.0298881530762,1.99499705251167,23.9700004458427,0.0362929820779852,0.00642616714861784,0.25,8.84930495255157E-6,0.00321456512761119,1.399570260203E-5,149.9258,149.9258,14617.63671875,14622.5849609375,55.6003630869674,19.5720704491117,9.621219,0,0,0,40,4961,149.92545,14620.1108398438,,,,,,,,,,,,,0,,,,,,,,,,,,,,
,20409719.625,149.9209,11084.6411132813,0.0030915013609551,1.07845320210763E-6,1,0.999253354069792,40.0298881530762,1.99478849763943,23.9700004458427,0.0350727157612178,0.00619991843931959,0.25,7.67259749694681E-6,0.00310664187476062,1.2651120953048E-5,149.9207,149.9207,11054.693359375,11114.5888671875,55.1884448573328,19.5737732129536,10.00087,0,0,0,40,4961,149.9209,11084.6411132813,,,,,,,,,,,,,0,,,,,,,,,,,,,,
,20409792.96,149.9176,7416.23583984375,0.00292799055671315,7.32248254702479E-7,1,0.999253354069792,40.0298881530762,1.99461053772954,23.9700004458427,0.0332106256449612,0.00589579376666567,0.25,9.39910907251233E-6,0.0029423252529177,1.41332239189189E-5,149.9171,149.9171,7386.1494140625,7446.322265625,55.8442311849674,19.5751165838696,9.241568,0,0,0,40,4961,149.9176,7416.23583984375,,,,,,,,,,,,,0,,,,,,,,,,,,,,
,20409869,149.9196,3617.75231933594,0.00265637586963709,4.79452165458873E-7,1,0.999253354069792,40.0298881530762,1.99491871985375,23.9700004458427,0.0301337157682477,0.00535284087004244,0.25,8.80080391456126E-6,0.00266937865962974,1.31040600372639E-5,149.9198,149.9198,3587.51611328125,3647.98852539063,56.482821685179,19.57386779851,9.621219,0,0,0,40,4961,149.9196,3617.75231933594,,,,,,,,,,,,,0,,,,,,,,,,,,,,
,20409944.1,149.92295,-137.826934814453,0.00215547774694776,7.53437249208896E-7,1,0.999253354069792,40.0298881530762,1.99521364321681,23.9700004458427,0.024454577312426,0.0043465541672842,0.25,7.35384338850374E-6,0.00216602722954426,1.08506969099602E-5,149.9225,149.9225,-165.617065429687,-110.036804199219,55.7910804456597,19.5684313001144,10.00087,0,0,0,40,4961,149.92295,-137.826934814453,,,,,,,,,,,,,0,,,,,,,,,,,,,,
,20410014.53,149.92965,-3651.69372558594,0.00120166646160089,9.60959557838833E-7,1,0.999253354069792,40.0298881530762,1.99559145579427,23.9700004458427,0.0136357285050993,0.00242376466923912,0.25,4.11511327124839E-6,0.00120754803589348,6.06221936715088E-6,149.9298,149.9298,-3679.48388671875,-3623.90356445313,56.1131113955829,19.5597154618193,9.241568,0,0,0,40,4961,149.92965,-3651.69372558594,,,,,,,,,,,,,0,,,,,,,,,,,,,,
,20410090.47,149.9442,-7448.86279296875,-0.000353149385085903,1.23240015086114E-6,1,0.999253354069792,40.0298881530762,1.99535157917745,23.9700004458427,-0.00400766870639351,-0.000707524742244235,0.25,-7.96644734823136E-7,-0.000354878624357334,-1.36582608989057E-6,149.9442,149.9442,-7448.86279296875,-7448.86279296875,55.9997752602944,19.5640081605325,10.00087,0,0,0,40,4961,149.9442,-7448.86279296875,,,,,,,,,,,,,0,,,,,,,,,,,,,,
,20410171.03,149.9615,-11477.2817382813,-0.00199981182404318,1.22341317623049E-6,1,0.999253354069792,40.0298881530762,1.99527049120244,23.9700004458427,-0.0226895529026035,-0.00403035100181409,0.25,-6.62673881685989E-6,-0.00200960130815431,-9.85346924895929E-6,149.962,149.962,-11502.4931640625,-11452.0703125,55.4987513794674,19.5700290360217,10.00087,0,0,0,40,4961,149.9615,-11477.2817382813,,,,,,,,,,,,,0,,,,,,,,,,,,,,
,20410250.21,149.97405,-15433.3168945313,-0.00286570456478548,1.43127123589419E-6,1,0.999253354069792,40.0298881530762,1.99536354979235,23.9700004458427,-0.0325161832852828,-0.00577061773045734,0.25,-9.05824188314968E-6,-0.00287973468025502,-1.36699959137815E-5,149.9744,149.9744,-15461.0029296875,-15405.630859375,55.6245935710636,19.5728446262691,10.00087,0,0,0,40,4961,149.97405,-15433.3168945313,,,,,,,,,,,,,0,,,,,,,,,,,,,,
,20410330.66,149.98125,-19453.044921875,-0.00317925331983356,1.65252865152896E-6,1,0.999253354069792,40.0298881530762,1.99525473655467,23.9700004458427,-0.0360726583608658,-0.00639823461894413,0.25,-9.75764571949696E-6,-0.00319482090403159,-1.48610882185434E-5,149.98,149.98,-19453.044921875,-19453.044921875,55.5980182014097,19.5596070111825,10.00087,0,0,0,40,4961,149.98125,-19453.044921875,,,,,,,,,,,,,0,,,,,,,,,,,,,,
,20410412.22,149.9805,-23530.705078125,-0.00330142419092622,1.96702374335852E-6,1,0.999253354069792,40.0298881530762,1.99535680790086,23.9700004458427,-0.0374593574734039,-0.00665215015714491,0.25,-1.08244378143377E-5,-0.00331759166351726,-1.6115265495741E-5,149.9814,149.9814,-23560.6484375,-23500.76171875,56.2061251893713,19.5616807078656,9.621219,0,0,0,40,4961,149.9805,-23530.705078125,,,,,,,,,,,,,0,,,,,,,,,,,,,,
,20410491.25,149.9693,-27481.3994140625,-0.00335056872106231,2.12286410355297E-6,1,0.999253354069792,40.0298881530762,1.99512516145326,23.9700004458427,-0.0380135067907049,-0.00674637759629781,0.25,-1.06400786292652E-5,-0.00336698106894108,-1.59962313061722E-5,149.9701,149.9701,-27508.80859375,-27453.990234375,55.6879054811213,19.5696233865453,9.621219,0,0,0,40,4961,149.9693,-27481.3994140625,,,,,,,,,,,,,0,,,,,,,,,,,,,,
,20410571.285,149.95265,-31481.3447265625,-0.00337690018311287,2.10955842787335E-6,1,0.999253354069792,40.0298881530762,1.99528301554556,23.9700004458427,-0.0383165286903266,-0.00679222497292842,0.25,-1.00580301222322E-5,-0.00339344680727796,-1.54409893407998E-5,149.9525,149.9525,-31511.26953125,-31451.419921875,56.3085185253906,19.5574548846346,10.00087,0,0,0,40,4961,149.95265,-31481.3447265625,,,,,,,,,,,,,0,,,,,,,,,,,,,,
,20410649.445,149.93115,-35386.279296875,-0.00338909637436728,2.61993572970827E-6,1,0.999253354069792,40.0298881530762,1.99547332706014,23.9700004458427,-0.0384569368440201,-0.00682617609578425,0.25,-1.08803089396407E-5,-0.00340570617032758,-1.62747869170645E-5,149.9314,149.9314,-35413.6328125,-35358.92578125,56.2256659023521,19.5636231439716,9.621219,0,0,0,40,4961,149.93115,-35386.279296875,,,,,,,,,,,,,0,,,,,,,,,,,,,,
,20410727.41,149.9081,-39281.1484375,-0.00338092188758862,2.79553689537628E-6,1,0.999253354069792,40.0298881530762,1.99558428560002,23.9700004458427,-0.0383716853671885,-0.00677898849850167,0.25,-8.12736980826754E-6,-0.00339750071807028,-1.34835838501707E-5,149.9081,149.9081,-39306.09765625,-39256.19921875,55.2884933077943,19.5619370999086,9.621219,0,0,0,40,4961,149.9081,-39281.1484375,,,,,,,,,,,,,0,,,,,,,,,,,,,,
,20410806.265,149.88455,-43224.224609375,-0.00337346729315437,2.83584801392721E-6,1,0.999253354069792,40.0298881530762,1.99554255888158,23.9700004458427,-0.0382826288037228,-0.00678539859817009,0.25,-1.00136526125314E-5,-0.00339001148848907,-1.53552069852293E-5,149.8851,149.8851,-43254.328125,-43194.12109375,55.8637718979482,19.5503945193069,10.00087,0,0,0,40,4961,149.88455,-43224.224609375,,,,,,,,,,,,,0,,,,,,,,,,,,,,
,20410881.89,149.86735,-47002.404296875,-0.00335819914292927,3.19334858480173E-6,1,0.999253354069792,40.0298881530762,1.99546214123399,23.9700004458427,-0.0381061491523753,-0.0067647505983079,0.25,-1.0888777941329E-5,-0.00337467129081747,-1.61985965543645E-5,149.867,149.867,-47032.39453125,-46972.4140625,55.9145777516982,19.5695876422279,9.241568,0,0,0,40,4961,149.86735,-47002.404296875,,,,,,,,,,,,,0,,,,,,,,,,,,,,
,20410953.905,149.85095,-50602.841796875,-0.00333827144648879,3.09335325241503E-6,1,0.999253354069792,40.0298881530762,1.99515299885268,23.9700004458427,-0.037870444330411,-0.00674673362852637,0.25,-1.28716282552349E-5,-0.00335464672600388,-1.81484090876155E-5,149.8508,149.8508,-50630.3203125,-50575.36328125,55.2752056229674,19.57176987269,9.621219,0,0,0,40,4961,149.85095,-50602.841796875,,,,,,,,,,,,,0,,,,,,,,,,,,,,
,20411026.485,149.8385,-54227.84765625,-0.00330503654933821,4.08811866325337E-6,1,0.999253354069792,40.0298881530762,1.99527765990152,23.9700004458427,-0.037502725794825,-0.00663960503701056,0.25,-9.19967859232337E-6,-0.00332125807997691,-1.43946453557821E-5,149.8391,149.8391,-54257.73828125,-54197.95703125,56.0755932266598,19.5744808791521,9.621219,0,0,0,40,4961,149.8385,-54227.84765625,,,,,,,,,,,,,0,,,,,,,,,,,,,,
,20411098.285,149.82775,-57818.3828125,-0.00327366117934664,4.28149103462095E-6,1,0.999253354069792,40.0298881530762,1.99527367999297,23.9700004458427,-0.0371553905828413,-0.0065265235518829,0.25,-4.71591972954003E-6,-0.00328973911244662,-9.82812984969441E-6,149.8273,149.8273,-57845.82421875,-57790.94140625,55.3557133604482,19.5675986855443,9.621219,0,0,0,40,4961,149.82775,-57818.3828125,,,,,,,,,,,,,0,,,,,,,,,,,,,,
,20411170.39,149.81935,-61418.390625,-0.00324950635827766,4.047440553409E-6,1,0.999253354069792,40.0298881530762,1.99531443358993,23.9700004458427,-0.036869067132685,-0.00655272709065141,0.25,-1.12312167803288E-5,-0.00326545885305334,-1.63258986382286E-5,149.819,149.819,-61448.3125,-61388.46875,55.9692917480444,19.5649321491961,9.621219,0,0,0,40,4961,149.81935,-61418.390625,,,,,,,,,,,,,0,,,,,,,,,,,,,,
,20411243.04,149.80915,-65051.458984375,-0.00320611548613065,4.68311600751221E-6,1,0.999253354069792,40.0298881530762,1.99530826469806,23.9700004458427,-0.0363871601330328,-0.00640506542484501,0.25,-5.79488180722068E-6,-0.00322186665696039,-1.07835989867113E-5,149.8104,149.8104,-65076.37109375,-65026.546875,55.8387597853328,19.5597820069327,9.241568,0,0,0,40,4961,149.80915,-65051.458984375,,,,,,,,,,,,,0,,,,,,,,,,,,,,
,20411316.035,149.8027,-68702.3125,-0.00317701411767768,3.88178830975989E-6,1,0.999253354069792,40.0298881530762,1.99529585394032,23.9700004458427,-0.0360415901669405,-0.00643366531953799,0.25,-1.33973376554921E-5,-0.00319261369041321,-1.83662489493271E-5,149.804,149.804,-68729.953125,-68674.671875,56.0638687988713,19.5653015891853,10.00087,0,0,0,40,4961,149.8027,-68702.3125,,,,,,,,,,,,,0,,,,,,,,,,,,,,
,20411390.095,149.796,-72402.30078125,-0.00312132279177801,4.33977561525217E-6,1,0.999253354069792,40.0298881530762,1.99541307349249,23.9700004458427,-0.0354069641311898,-0.00634914476603463,0.25,-1.56317642921812E-5,-0.00313664833522467,-2.05135490738269E-5,149.7965,149.7965,-72432.234375,-72372.3671875,56.2577126716406,19.5599605568725,9.621219,0,0,0,40,4961,149.796,-72402.30078125,,,,,,,,,,,,,0,,,,,,,,,,,,,,
,20411469.245,149.7915,-76354.6015625,-0.00307280362499583,5.07959956054469E-6,1,0.999253354069792,40.0298881530762,1.99556716042738,23.9700004458427,-0.0348771579021874,-0.00614773416469593,0.25,-6.3140912626082E-6,-0.00308790807682023,-1.10623737566316E-5,149.7907,149.7907,-76359.4765625,-76349.7265625,56.1975272756598,19.554500420023,9.621219,0,0,0,40,4961,149.7915,-76354.6015625,,,,,,,,,,,,,0,,,,,,,,,,,,,,
,20411542.92,149.7865,-80037.203125,-0.00303327646592171,5.60201637058443E-6,1,0.999253354069792,40.0298881530762,1.99544281940831,23.9700004458427,-0.0344235459171466,-0.00608525903977761,0.25,-7.7387235686572E-6,-0.0030481872938302,-1.24213613090275E-5,149.7865,149.7865,-80042.390625,-80032.015625,55.5393960624674,19.5490704824195,10.00087,0,0,0,40,4961,149.7865,-80037.203125,,,,,,,,,,,,,0,,,,,,,,,,,,,,
,20411615.22,149.78745,-83652.4296875,-0.00297525080274219,4.09135733208703E-6,1,0.999253354069792,40.0298881530762,1.99517515298153,23.9700004458427,-0.0337691571879885,-0.00591974379862879,0.25,-3.34368314067107E-6,-0.00298988531704787,-7.90402243331025E-6,149.7875,149.7875,-83654.828125,-83650.03125,56.1561009641406,19.5620193503585,10.00087,0,0,0,40,4961,149.78745,-83652.4296875,,,,,,,,,,,,,0,,,,,,,,,,,,,,
,20411684,149.7879,-87087.87109375,-0.00293243900637609,4.64591790909745E-6,1,0.999253354069792,40.0298881530762,1.99530249596935,23.9700004458427,-0.0332916383180778,-0.00579850149533544,0.25,-9.85279321981592E-8,-0.00294687011520598,-4.56641752629717E-6,149.7887,149.7887,-87112.9375,-87062.8046875,56.0200976017944,19.5551128761697,10.00087,0,0,0,40,4961,149.7879,-87087.87109375,,,,,,,,,,,,,0,,,,,,,,,,,,,,
,20411769.895,149.7906,-89465.76953125,-0.0029092690894512,4.2127023563879E-6,1,0.999253354069792,40.0298881530762,1.99572889890305,23.9799991250038,-0.0330242215482835,-0.00581774507874236,0.25,-5.73127617933377E-6,-0.00292357900676997,-1.01838528201427E-5,149.7906,149.7906,-89495.546875,-89435.9921875,56.0075915454867,19.5566936806437,9.621219,0,0,0,40,4961,149.7906,-89465.76953125,,,,,,,,,,,,,0,,,,,,,,,,,,,,
,20411846.61,149.7915,-85632.5625,-0.00295206359991026,5.43193258837263E-6,1,0.999253354069792,40.0298881530762,1.995739256189,23.9700004458427,-0.0335114993392414,-0.00589550586891179,0.25,-5.11274018931504E-6,-0.00296658238004851,-9.63978083810452E-6,149.7915,149.7915,-85635.2109375,-85629.9140625,56.0974788251982,19.5536044704722,10.00087,0,0,0,40,4961,149.7915,-85632.5625,,,,,,,,,,,,,0,,,,,,,,,,,,,,
,20411923.515,149.80125,-81789.80859375,-0.0029969688765904,5.74646762641256E-6,1,0.999253354069792,40.0298881530762,1.99561698871935,23.9700004458427,-0.0340215714756012,-0.00597139026818958,0.25,-3.99482850563835E-6,-0.00301170692395044,-8.59707672039483E-6,149.8011,149.8011,-81822.328125,-81757.2890625,55.7066645655828,19.557075939396,9.241568,0,0,0,40,4961,149.80125,-81789.80859375,,,,,,,,,,,,,0,,,,,,,,,,,,,,
,20412002.545,149.80965,-77839.23046875,-0.00305487126246056,3.81389587894478E-6,1,0.999253354069792,40.0298881530762,1.99582440907458,23.9700004458427,-0.0346828069989837,-0.00608433454955502,0.25,-3.79312112103899E-6,-0.00306989103867541,-8.49574117607862E-6,149.8096,149.8096,-77844.28125,-77834.1796875,55.7895171886213,19.5597091808365,9.241568,0,0,0,40,4961,149.80965,-77839.23046875,,,,,,,,,,,,,0,,,,,,,,,,,,,,
,20412081.43,149.81725,-73899.046875,-0.00310061165658991,4.06405548844641E-6,1,0.999253354069792,40.0298881530762,1.9957877106777,23.9700004458427,-0.0352021649226444,-0.00617123916540638,0.25,-3.4776638507521E-6,-0.00311585347825228,-8.26181912776548E-6,149.8173,149.8173,-73926.7421875,-73871.3515625,55.1728122869481,19.5545249784277,9.621219,0,0,0,40,4961,149.81725,-73899.046875,,,,,,,,,,,,,0,,,,,,,,,,,,,,
,20412161.64,149.8259,-69889.3046875,-0.00314745773553301,4.24587705682938E-6,1,0.999253354069792,40.0298881530762,1.99555879348602,23.9700004458427,-0.0357110262617169,-0.00637313243231344,0.25,-1.31474915600963E-5,-0.00316291142143457,-1.80644755466015E-5,149.8252,149.8252,-69919.203125,-69859.40625,56.2334821875444,19.5540899537444,9.621219,0,0,0,40,4961,149.8259,-69889.3046875,,,,,,,,,,,,,0,,,,,,,,,,,,,,
,20412243.565,149.8334,-65796.6328125,-0.00319802533769729,4.13295019790423E-6,1,0.999253354069792,40.0298881530762,1.9955965550261,23.9700004458427,-0.0362870638540529,-0.00646596670815461,0.25,-1.24936453035865E-5,-0.00321372499200421,-1.74990919983404E-5,149.8326,149.8326,-65801.4765625,-65791.7890625,55.5933284302943,19.5548108535352,9.621219,0,0,0,40,4961,149.8334,-65796.6328125,,,,,,,,,,,,,0,,,,,,,,,,,,,,
,20412324.46,149.8388,-61751.14453125,-0.00323935585262519,5.43291970977704E-6,1,0.999253354069792,40.0298881530762,1.99529937528655,23.9700004458427,-0.0367573749219855,-0.00651064461218994,0.25,-9.29874705888412E-6,-0.00325526013323666,-1.43661209381548E-5,149.8388,149.8388,-61753.60546875,-61748.68359375,55.9130144946598,19.5573661014446,10.00087,0,0,0,40,4961,149.8388,-61751.14453125,,,,,,,,,,,,,0,,,,,,,,,,,,,,
,20412405.875,149.8405,-57683.69921875,-0.00328190960670933,4.22594350006052E-6,1,0.999253354069792,40.0298881530762,1.99507738167175,23.9700004458427,-0.0372418698659372,-0.00656318013201292,0.25,-6.56283162905951E-6,-0.00329802405204655,-1.1696790478078E-5,149.8412,149.8412,-57706.0234375,-57661.375,56.1006053392752,19.542247106507,10.00087,0,0,0,40,4961,149.8405,-57683.69921875,,,,,,,,,,,,,0,,,,,,,,,,,,,,
,20412485.88,149.84395,-53686.25390625,-0.00331299476974884,3.51462682744914E-6,1,0.999253354069792,40.0298881530762,1.99497709502903,23.9700004458427,-0.0375806802980364,-0.00669444126913539,0.25,-1.27271717553363E-5,-0.0033292490382298,-1.79534763370007E-5,149.8439,149.8439,-53688.73828125,-53683.76953125,56.411693489929,19.5452785024495,9.621219,0,0,0,40,4961,149.84395,-53686.25390625,,,,,,,,,,,,,0,,,,,,,,,,,,,,
,20412564.86,149.84285,-49739.115234375,-0.00334013720339963,3.27397397286101E-6,1,0.999253354069792,40.0298881530762,1.9952270649456,23.9700004458427,-0.037905523988559,-0.00667857088613805,0.25,-6.51793296849952E-6,-0.003356531594016,-1.17698141900662E-5,149.8432,149.8432,-49776.6171875,-49701.61328125,55.8715881831405,19.5338361942598,9.621219,0,0,0,40,4961,149.84285,-49739.115234375,,,,,,,,,,,,,0,,,,,,,,,,,,,,
,20412638.455,149.84575,-46061.01171875,-0.00335807803535812,2.5015660671495E-6,1,0.999253354069792,40.0298881530762,1.9953993069642,23.9700004458427,-0.0381112496797665,-0.00672062943141306,0.25,-7.03707894388618E-6,-0.00337455671683001,-1.23321208448877E-5,149.8461,149.8461,-46093.59765625,-46028.42578125,55.7848274175059,19.5269423758048,9.241568,0,0,0,40,4961,149.84575,-46061.01171875,,,,,,,,,,,,,0,,,,,,,,,,,,,,
,20412710.23,149.8499,-42472.787109375,-0.00337649980825885,2.82791985751494E-6,1,0.999253354069792,40.0298881530762,1.99490136695014,23.9700004458427,-0.0383114093858189,-0.006754442824035,0.25,-6.93682135636134E-6,-0.00339306606549533,-1.22723566788176E-5,149.8497,149.8497,-42500.265625,-42445.30859375,55.4143354993905,19.527282658873,9.621219,0,0,0,40,4961,149.8499,-42472.787109375,,,,,,,,,,,,,0,,,,,,,,,,,,,,
,20412783.335,149.8521,-38820.185546875,-0.00339047750734567,2.37876755466587E-6,1,0.999253354069792,40.0298881530762,1.99525358873932,23.9700004458427,-0.0384726641261751,-0.00680532152823688,0.25,-8.87177779104474E-6,-0.0034071064346552,-1.42510995303354E-5,149.8521,149.8521,-38822.52734375,-38817.84375,56.231918930506,19.5266139534738,10.00087,0,0,0,40,4961,149.8521,-38820.185546875,,,,,,,,,,,,,0,,,,,,,,,,,,,,
,20412854.45,149.8574,-35264.3671875,-0.00339495194494081,3.29156676628425E-6,1,0.999253354069792,40.0298881530762,1.99509965446791,23.9700004458427,-0.0385188483188319,-0.00682365130308294,0.25,-9.74014232551605E-6,-0.00341159838896127,-1.51424630898288E-5,149.8574,149.8574,-35264.3671875,-35264.3671875,56.1490663074675,19.5344169196824,9.241568,0,0,0,40,4961,149.8574,-35264.3671875,,,,,,,,,,,,,0,,,,,,,,,,,,,,
,20412924.215,149.863,-31779.8388671875,-0.00339079584953564,2.57771786882954E-6,1,0.999253354069792,40.0298881530762,1.9951802812112,23.9700004458427,-0.0384746372758307,-0.00680698124153583,0.25,-8.96178191115077E-6,-0.00340742011228202,-1.4364969292317E-5,149.8626,149.8626,-31802.154296875,-31757.5234375,55.8723698116598,19.5252048039752,9.621219,0,0,0,40,4961,149.863,-31779.8388671875,,,,,,,,,,,,,0,,,,,,,,,,,,,,
,20412997.875,149.8717,-28096.70703125,-0.00337907929431277,2.22526615133114E-6,1,0.999253354069792,40.0298881530762,1.99532208998621,23.9700004458427,-0.0383383891043444,-0.00681759005809037,0.25,-1.18857200093521E-5,-0.00339563807184876,-1.72962078976952E-5,149.8717,149.8717,-28099.283203125,-28094.130859375,56.1076399959482,19.5417816128522,9.621219,0,0,0,40,4961,149.8717,-28096.70703125,,,,,,,,,,,,,0,,,,,,,,,,,,,,
,20413067.97,149.8768,-24593.427734375,-0.00335197783083851,1.5149333182667E-6,1,0.999253354069792,40.0298881530762,1.99517834852704,23.9700004458427,-0.038029630411559,-0.00675453703284509,0.25,-1.10835342189795E-5,-0.00336840205332492,-1.64579070216632E-5,149.878,149.878,-24615.80078125,-24571.0546875,55.649605683679,19.5455952628825,9.621219,0,0,0,40,4961,149.8768,-24593.427734375,,,,,,,,,,,,,0,,,,,,,,,,,,,,
,20413139.49,149.88295,-21020.4443359375,-0.00331153494329379,1.09581342539393E-6,1,0.999253354069792,40.0298881530762,1.99551085258055,23.9700004458427,-0.0375763072657979,-0.00667653643317027,0.25,-1.11542243874284E-5,-0.00332775776563374,-1.64752614738257E-5,149.8832,149.8832,-21052.97265625,-20987.916015625,56.1772049341598,19.5473090239497,9.241568,0,0,0,40,4961,149.88295,-21020.4443359375,,,,,,,,,,,,,0,,,,,,,,,,,,,,
,20413211.775,149.88925,-17407.5927734375,-0.00325108963963202,1.25368413303004E-6,1,0.999253354069792,40.0298881530762,1.9955589293946,23.9700004458427,-0.0368916369130263,-0.00655256614298675,0.25,-1.07424945385622E-5,-0.00326701385004046,-1.59754874293672E-5,149.8884,149.8884,-17435.10546875,-17380.080078125,55.2548832814674,19.5451100756365,9.621219,0,0,0,40,4961,149.88925,-17407.5927734375,,,,,,,,,,,,,0,,,,,,,,,,,,,,
,20413284.375,149.89575,-13779.9750976563,-0.00316756743479173,1.03596779391608E-6,1,0.999253354069792,40.0298881530762,1.99566862222951,23.9700004458427,-0.0359458058657042,-0.00638410356114191,0.25,-1.04171355564238E-5,-0.00318307992302588,-1.55249389425071E-5,149.8966,149.8966,-13807.6962890625,-13752.25390625,56.4124751184483,19.5326269042945,10.00087,0,0,0,40,4961,149.89575,-13779.9750976563,,,,,,,,,,,,,0,,,,,,,,,,,,,,
,20413357.705,149.90345,-10113.990234375,-0.00304673546334797,7.66728347478848E-7,1,0.999253354069792,40.0298881530762,1.99586664743609,23.9700004458427,-0.034578684703414,-0.00613630169251524,0.25,-9.58430551235302E-6,-0.00306165429039332,-1.45038347858085E-5,149.9027,149.9027,-10143.74609375,-10084.234375,56.6915164998137,19.5341269444586,9.621219,0,0,0,40,4961,149.90345,-10113.990234375,,,,,,,,,,,,,0,,,,,,,,,,,,,,
,20413429.19,149.90785,-6540.49926757812,-0.00286788511239497,5.9113404424611E-7,1,0.999253354069792,40.0298881530762,1.99565851608938,23.9700004458427,-0.0325450067695279,-0.00577876304437703,0.25,-9.30084309117263E-6,-0.00288192567214142,-1.39405214113204E-5,149.9076,149.9076,-6575.39599609375,-6505.6025390625,56.3069552683521,19.5283793408231,9.621219,0,0,0,40,4961,149.90785,-6540.49926757812,,,,,,,,,,,,,0,,,,,,,,,,,,,,
,20413501.545,149.914,-2924.06372070313,-0.00257935443571887,5.56972395923733E-7,1,0.999253354069792,40.0298881530762,1.99544851693349,23.9700004458427,-0.0292662865022147,-0.00520539762611473,0.25,-9.11187917610954E-6,-0.00259197940393998,-1.32944958676861E-5,149.9146,149.9146,-2926.6689453125,-2921.45849609375,56.3530713509867,19.5330965973884,9.241568,0,0,0,40,4961,149.914,-2924.06372070313,,,,,,,,,,,,,0,,,,,,,,,,,,,,
,20413570.805,149.9174,537.144577026367,-0.00206317698881153,6.78874092193618E-7,1,0.999253354069792,40.0298881530762,1.99525418488225,23.9700004458427,-0.0234066443090476,-0.00416745305748447,0.25,-7.65071782731243E-6,-0.00207327410023924,-1.1000681724108E-5,149.9175,149.9175,507.053131103516,567.236022949219,55.7519990196982,19.5233026928514,10.00087,0,0,0,40,4961,149.9174,537.144577026367,,,,,,,,,,,,,0,,,,,,,,,,,,,,
,20413641.545,149.92175,4068.81115722656,-0.00104332360703692,9.59745988137318E-7,1,0.999253354069792,40.0298881530762,1.99564287930703,23.9700004458427,-0.0118375681741326,-0.0021140987508972,0.25,-4.42377334637072E-6,-0.00104842907234462,-6.11832594167827E-6,149.9219,149.9219,4036.30395507812,4101.318359375,55.8168741867944,19.5281681613519,10.00087,0,0,0,40,4961,149.92175,4068.81115722656,,,,,,,,,,,,,0,,,,,,,,,,,,,,
,20413712.375,149.921,7610.61303710937,0.00042904700899268,1.26002925748287E-6,1,0.999253354069792,40.0298881530762,1.99546224943692,23.9700004458427,0.00486969843199666,0.000857017890187168,0.25,7.37726467477366E-7,0.00043114851572016,1.42821087230496E-6,149.9215,149.9215,7580.68994140625,7640.5361328125,56.0427648288521,19.5320069782477,10.00087,0,0,0,40,4961,149.921,7610.61303710937,,,,,,,,,,,,,0,,,,,,,,,,,,,,
,20413784.49,149.9192,11216.5751953125,0.00190021853591024,1.03296464929679E-6,1,0.999253354069792,40.0298881530762,1.99503381678904,23.9700004458427,0.0215568972587825,0.00383073162908303,0.25,6.42962841182628E-6,0.00190952217201999,9.49797028183939E-6,149.9192,149.9192,11213.9541015625,11219.1962890625,56.0505811140444,19.5338998786126,9.621219,0,0,0,40,4961,149.9192,11216.5751953125,,,,,,,,,,,,,0,,,,,,,,,,,,,,
,20413856.215,149.91485,14802.3911132812,0.00276796451412725,1.28000836038946E-6,1,0.999253354069792,40.0298881530762,1.9953712469377,23.9700004458427,0.0314071034660033,0.00557505728173907,0.25,8.85354807116452E-6,0.00278151965661034,1.33125535645669E-5,149.9149,149.9149,14777.41796875,14827.3642578125,56.4515565444098,19.5404778922003,9.621219,0,0,0,40,4961,149.91485,14802.3911132812,,,,,,,,,,,,,0,,,,,,,,,,,,,,
,20413927.48,149.9073,18363.0751953125,0.00311648310635713,1.78436283160011E-6,1,0.999253354069792,40.0298881530762,1.99532444176754,23.9700004458427,0.0353586160781023,0.00628975561414039,0.25,1.11111036959891E-5,0.00313174589564318,1.61279390230032E-5,149.9063,149.9063,18335.48046875,18390.669921875,56.3601060076598,19.530537776741,9.621219,0,0,0,40,4961,149.9073,18363.0751953125,,,,,,,,,,,,,0,,,,,,,,,,,,,,
,20413998.595,149.90035,21915.7294921875,0.00325386147428698,1.30949766743563E-6,1,0.999253354069792,40.0298881530762,1.99567713288757,23.9700004458427,0.0369259360106014,0.00655430448151777,0.25,1.03932933012184E-5,0.00326980184906488,1.56153689815425E-5,149.9009,149.9009,21888.31640625,21943.142578125,55.7902988171405,19.5515993394464,9.621219,0,0,0,40,4961,149.90035,21915.7294921875,,,,,,,,,,,,,0,,,,,,,,,,,,,,
,20414070.055,149.89095,25486.6953125,0.00331770717048563,2.15869679915483E-6,1,0.999253354069792,40.0298881530762,1.99550390795606,23.9700004458427,0.0376494407214527,0.00667062133806822,0.25,9.57348414577322E-6,0.00333396513734394,1.48825808778839E-5,149.8914,149.8914,25456.771484375,25516.619140625,55.903634952429,19.5468804029285,10.00087,0,0,0,40,4961,149.89095,25486.6953125,,,,,,,,,,,,,0,,,,,,,,,,,,,,
,20414140.99,149.8869,29035.32421875,0.00335220635679649,2.01750706184038E-6,1,0.999253354069792,40.0298881530762,1.99556268389297,23.9700004458427,0.0380411171098355,0.00674547682446655,0.25,1.01504329244205E-5,0.00336863544569813,1.55060715702117E-5,149.8879,149.8879,29010.4296875,29060.21875,55.7019747944674,19.5431014766895,9.241568,0,0,0,40,4961,149.8869,29035.32421875,,,,,,,,,,,,,0,,,,,,,,,,,,,,
,20414212.625,149.87715,32613.234375,0.00337109100601872,2.05124310022102E-6,1,0.999253354069792,40.0298881530762,1.99550375233017,23.9700004458427,0.0382530098621436,0.00679116607367811,0.25,1.09121150960269E-5,0.00338761491576392,1.62902773179977E-5,149.876,149.876,32583.04296875,32643.42578125,55.392449900852,19.5463153803846,10.00087,0,0,0,40,4961,149.87715,32613.234375,,,,,,,,,,,,,0,,,,,,,,,,,,,,
,20414284.655,149.87075,36214.052734375,0.00337754896627233,2.70025621387822E-6,1,0.999253354069792,40.0298881530762,1.99619526350182,23.9799991250038,0.0383343896334569,0.00683291735441742,0.25,1.32764632433052E-5,0.00339410400387504,1.86648446905144E-5,149.8707,149.8707,36191.4921875,36236.61328125,55.240032339602,19.5475888251178,9.621219,0,0,0,40,4961,149.87075,36214.052734375,,,,,,,,,,,,,0,,,,,,,,,,,,,,
,20414357.18,149.8619,39838.798828125,0.00336983639149364,3.53002425461352E-6,1,0.999253354069792,40.0298881530762,1.99551713703459,23.9700004458427,0.0382409605357303,0.00677796790757182,0.25,9.98642006528752E-6,0.00338636217815535,1.53347960778297E-5,149.8615,149.8615,39808.95703125,39868.640625,56.0623055418329,19.5432133790764,10.00087,0,0,0,40,4961,149.8619,39838.798828125,,,,,,,,,,,,,0,,,,,,,,,,,,,,
,20414429.86,149.8555,43469.78515625,0.00335870023783904,3.38948000959683E-6,1,0.999253354069792,40.0298881530762,1.99527710852691,23.9700004458427,0.0381138112422682,0.00673434058936895,0.25,8.16318782700441E-6,0.00337517745642315,1.3473119218505E-5,149.854,149.854,43437.33984375,43502.23046875,55.8723698116598,19.5449989288096,10.00087,0,0,0,40,4961,149.8555,43469.78515625,,,,,,,,,,,,,0,,,,,,,,,,,,,,
,20414500.58,149.8461,47005.71484375,0.00333836965179145,3.05130150215234E-6,1,0.999253354069792,40.0298881530762,1.99590443395928,23.9700004458427,0.0378911257863982,0.00671502801393216,0.25,9.83680110378189E-6,0.00335474784877343,1.51114659095079E-5,149.8465,149.8465,46980.63671875,47030.79296875,55.9028533239098,19.5473429191238,10.00087,0,0,0,40,4961,149.8461,47005.71484375,,,,,,,,,,,,,0,,,,,,,,,,,,,,
,20414572.51,149.83795,50599.0625,0.00331733872159649,2.93670242856559E-6,1,0.999253354069792,40.0298881530762,1.99578759439407,23.9700004458427,0.0376585317292163,0.00662541218201606,0.25,5.65239185688102E-6,0.00333362354021276,1.08616780267932E-5,149.8388,149.8388,50569.0546875,50629.0703125,55.7566887908136,19.5474080502918,9.621219,0,0,0,40,4961,149.83795,50599.0625,,,,,,,,,,,,,0,,,,,,,,,,,,,,
,20414643.915,149.83245,54169.748046875,0.00329814093669319,3.80288308362168E-6,1,0.999253354069792,40.0298881530762,1.99593198198949,23.9700004458427,0.0374434179638027,0.00658638443838949,0.25,5.53065619273252E-6,0.0033143347642403,1.06973499398681E-5,149.834,149.834,54142.67578125,54196.8203125,55.8614270123905,19.5431058497104,9.241568,0,0,0,40,4961,149.83245,54169.748046875,,,,,,,,,,,,,0,,,,,,,,,,,,,,
,20414715.58,149.8279,57749.748046875,0.00326719027288971,3.13522826056524E-6,1,0.999253354069792,40.0298881530762,1.99580122623186,23.9700004458427,0.0370873133729459,0.00653818266697494,0.25,6.72443042017378E-6,0.00328323322520367,1.18366796682415E-5,149.8285,149.8285,57719.69140625,57779.8046875,55.8489209560828,19.5532758529187,9.621219,0,0,0,40,4961,149.8279,57749.748046875,,,,,,,,,,,,,0,,,,,,,,,,,,,,
,20414787.53,149.82,61348.384765625,0.00323604597224978,4.11293531684154E-6,1,0.999253354069792,40.0298881530762,1.99539855254002,23.9700004458427,0.0367270410423947,0.00647290929719752,0.25,6.52181280105206E-6,0.00325193951411597,1.15726851516789E-5,149.8198,149.8198,61318.83203125,61377.9375,55.7449643630251,19.5428710948156,9.241568,0,0,0,40,4961,149.82,61348.384765625,,,,,,,,,,,,,0,,,,,,,,,,,,,,
,20414860.11,149.81325,64974.28515625,0.00319854494252449,4.68418719450917E-6,1,0.999253354069792,40.0298881530762,1.99518948499827,23.9700004458427,0.0362930371529998,0.00642480629794637,0.25,8.8843831309747E-6,0.00321425373446984,1.38766478900146E-5,149.8132,149.8132,64941.85546875,65006.71484375,55.9857059469482,19.5444700358106,9.621219,0,0,0,40,4961,149.81325,64974.28515625,,,,,,,,,,,,,0,,,,,,,,,,,,,,
,20414930.79,149.8042,68510.57421875,0.00315297234881192,4.4150801102547E-6,1,0.999253354069792,40.0298881530762,1.99507672402636,23.9700004458427,0.0357803287201434,0.00629684543401595,0.25,5.59041574957871E-6,0.00316846550705013,1.04844226204856E-5,149.8048,149.8048,68480.546875,68540.6015625,55.4041743286405,19.5432582794732,10.00087,0,0,0,40,4961,149.8042,68510.57421875,,,,,,,,,,,,,0,,,,,,,,,,,,,,
,20415003.61,149.79495,72148.48828125,0.00310874477533407,5.12847360249947E-6,1,0.999253354069792,40.0298881530762,1.99534744923534,23.9700004458427,0.0352758754767243,0.00625044188196244,0.25,9.14506237619728E-6,0.00312401834797446,1.39764868098404E-5,149.7945,149.7945,72123.1953125,72173.78125,55.3697826737943,19.5296151636934,9.621219,0,0,0,40,4961,149.79495,72148.48828125,,,,,,,,,,,,,0,,,,,,,,,,,,,,
,20415074.7,149.78885,75702.17578125,0.00306881771917758,4.56776151748128E-6,1,0.999253354069792,40.0298881530762,1.99533947036966,23.9700004458427,0.0348224429918447,0.00617169091112876,0.25,9.17512279443872E-6,0.00308389791012628,1.39336542222085E-5,149.7891,149.7891,75676.875,75727.4765625,56.3499448369098,19.5458070925596,9.241568,0,0,0,40,4961,149.78885,75702.17578125,,,,,,,,,,,,,0,,,,,,,,,,,,,,
,20415147.585,149.78195,79345.625,0.00302480477512644,4.06260288975388E-6,1,0.999253354069792,40.0298881530762,1.99539412161807,23.9700004458427,0.0343252627773015,0.00607581535378733,0.25,8.39228302112969E-6,0.00303967278139385,1.30676468454769E-5,149.7816,149.7816,79320.7109375,79370.5390625,56.035730172179,19.5377640264421,9.621219,0,0,0,40,4961,149.78195,79345.625,,,,,,,,,,,,,0,,,,,,,,,,,,,,
,20415218.565,149.77595,82892.3046875,0.00297152621125632,5.7818857760493E-6,1,0.999253354069792,40.0298881530762,1.99522482568202,23.9700004458427,0.0337262575147895,0.0059206906215968,0.25,4.06029598064214E-6,0.00298614163900784,8.6214351412597E-6,149.7755,149.7755,82869.8359375,82914.7734375,55.8442311849674,19.5433687283769,10.00087,0,0,0,40,4961,149.77595,82892.3046875,,,,,,,,,,,,,0,,,,,,,,,,,,,,
,20415289.055,149.7716,86415.97265625,0.00293362375275454,4.29992309163836E-6,1,0.999253354069792,40.0298881530762,1.99526257234552,23.9700004458427,0.0332977622307019,0.00583920290839056,0.25,3.48417983488094E-6,0.0029480562800005,7.97337857752936E-6,149.771,149.771,86393.3359375,86438.609375,56.299920611679,19.5460025736145,10.00087,0,0,0,40,4961,149.7716,86415.97265625,,,,,,,,,,,,,0,,,,,,,,,,,,,,
,20415358.445,149.765,89886.8203125,0.00288708651870918,5.72513595374993E-6,1,0.999253354069792,40.0298881530762,1.99549365266991,23.9700004458427,0.0327818978002554,0.00569726992748602,0.25,-9.59169958229319E-7,0.00290129957781316,3.42643228209085E-6,149.7648,149.7648,89861.765625,89911.875,56.6188250475252,19.5426337060856,9.621219,0,0,0,40,4961,149.765,89886.8203125,,,,,,,,,,,,,0,,,,,,,,,,,,,,
,20415360.915,149.76485,89996.25,0.00289028139582994,3.73575341268364E-6,1,0.999253354069792,40.0298881530762,1.99551186098139,23.9700004458427,0.0328182250107666,0.00570498153443968,0.25,-8.4036326937292E-7,0.00290451008487108,3.55033880978633E-6,149.7656,149.7656,89993.0390625,89999.4609375,55.4244966701405,19.5396860210572,9.621219,0,0,0,40,4929,149.76485,89996.25,,,,,,,,,,,,,0,,,,,,,,,,,,,,