File: data/monolayers/nanoparticles/Ac_CoFe_C/vsm/data_dispersion/AH11_ZFCW_100OE_00001.dat
[Header]
; VSM Data File (default extension .dat)
; Copyright (c) 2003-2013, Quantum Design, Inc. All rights reserved.
TITLE,
FILEOPENTIME,20337643.33,08/24/2018,6:19 pm
BYAPP,VSM,2.0,2.0
INFO,PPMS VSM Option Release 1.4.10 Build 1,APPNAME
INFO,Quantum Design Linear Motor Servo Controller,MOTOR_MODULE_NAME
INFO,3101-100 M1,MOTOR_HW_VERSION
INFO,MMC1014,MOTOR_SERIAL_NUMBER
INFO,SRV No X-over 01.03.11,MOTOR_SOFTWARE_VERSION
INFO,Quantum Design VSM Detection Module,VSM_MODULE_NAME
INFO,3101-150 F0,VSM_HW_VERSION
INFO,VSM707,VSM_SERIAL_NUMBER
INFO,VSM No X-over 01.02.05 May 20 2008 13:51:47,VSM_SOFTWARE_VERSION
INFO,704,PREAMP_SERIAL_NUMBER
INFO,822,COIL_SERIAL_NUMBER
INFO,0,MOMENT_UNITS
INFO,CoFe2O4,SAMPLE_MATERIAL
INFO,Cobalt deficient,SAMPLE_COMMENT
INFO,,SAMPLE_MASS
INFO,27,SAMPLE_VOLUME
INFO,,SAMPLE_MOLECULAR_WEIGHT
INFO,,SAMPLE_SIZE
INFO,,SAMPLE_SHAPE
DATATYPE,COMMENT,1
DATATYPE,TIME,2
STARTUPAXIS,X,2
STARTUPAXIS,Y1,5
[Data]
Comment,Time Stamp (sec),Temperature (K),Magnetic Field (Oe),Moment (emu),M. Std. Err. (emu),Transport Action,Averaging Time (sec),Frequency (Hz),Peak Amplitude (mm),Center Position (mm),Coil Signal' (mV),Coil Signal" (mV),Range (mV),M. Quad. Signal (emu),M. Raw' (emu),M. Raw" (emu),Min. Temperature (K),Max. Temperature (K),Min. Field (Oe),Max. Field (Oe),Mass (grams),Motor Lag (deg),Pressure (Torr),VSM Status (code),Motor Status (code),Measure Status (code),Measure Count,PPMS Status (code),System Temp. (K),System Field (Oe),Sample Position (deg),Bridge 1 Resistance (ohms),Bridge 1 Excitation (에),Bridge 2 Resistance (ohms),Bridge 2 Excitation (에),Bridge 3 Resistance (ohms),Bridge 3 Excitation (에),Bridge 4 Resistance (ohms),Bridge 4 Excitation (에),Signal 1 Vin (V),Signal 2 Vin (V),Digital Inputs (code),Drive 1 Iout (mA),Drive 1 Ipower (W),Drive 2 Iout (mA),Drive 2 Ipower (W),Pressure (),Map 20 (),Map 21 (),Map 22 (),Map 23 (),Map 24 (),Map 25 (),Map 26 (),Map 27 (),Map 28 (),Map 29 ()
,20340550.17,9.9994459,99.4721298217773,,,2,,,,23.7500001186132,,,,,,,9.9994459,9.9994459,99.4721298217773,99.4721298217773,,,6.204359,,,,-99999999,4885,9.8753,99.4721298217773,,,,,,,,,,,,,,,,,,,,,,,9.9994459,,,,
,20340856.68,12.0548868,99.4721298217773,-0.000189244254826558,3.29341751249225E-7,1,0.999253354069792,40.0298881530762,1.98000270249073,23.7199999392033,-0.00210000452170556,-0.000424532552467481,0.25,-4.49076146928015E-6,-0.000188135229156587,-5.37764686778537E-6,12.0548868,12.0548868,99.4721298217773,99.4721298217773,53.5071619124672,19.7858462153381,6.963661,0,0,0,40,4882,12.0344,99.4721298217773,,,,,,,,,,,,,0,,,,-0.0049,,,,,,12.0548868,,,,
,20340979.2,15.0254841,99.4721298217773,-0.000189830322546145,2.86102409033148E-7,1,0.999253354069792,40.0298881530762,1.98424890920368,23.7199999392033,-0.00211072354156662,-0.000427193835070979,0.25,-4.54740527903091E-6,-0.000188716279533203,-5.43675204115695E-6,15.0254841,15.0254841,99.4721298217773,99.4721298217773,53.8284112338711,19.7280869788713,6.963661,0,0,0,40,4882,15.10375,99.4721298217773,,,,,,,,,,,,,0,,,,-0.0049,,,,,,15.0254841,,,,
,20341100.685,18.0269604,99.4721298217773,-0.000189242789670561,3.36897492293988E-7,1,0.999253354069792,40.0298881530762,1.98587489647804,23.7199999392033,-0.00210526471458064,-0.000429318375008588,0.25,-4.81219806763214E-6,-0.000188129111580223,-5.69721956435656E-6,18.0269604,18.0269604,99.4721298217773,99.4721298217773,55.1642143732366,19.6897218145845,6.963661,0,0,0,40,4882,18.1764,99.4721298217773,,,,,,,,,,,,,0,,,,0.0049,,,,,,18.0269604,,,,
,20341221.205,21.01890945,99.4721298217773,-0.00018934291273603,2.84133491603679E-7,1,0.999253354069792,40.0298881530762,1.97687665762172,23.760000243783,-0.00209272169520537,-0.000453687635617956,0.25,-7.13900240594385E-6,-0.000188224325146928,-8.02244645157319E-6,20.9919796,21.0458393,99.4721298217773,99.4721298217773,54.0933833018903,19.6592912987377,6.963661,0,0,0,40,4882,21.2417,99.4721298217773,,,,,,,,,,,,,0,,,,-0.00245,,,,,,21.01890945,,,,
,20341343.79,24.0217686,99.4721298217773,-0.000189555241365607,4.25065999594059E-7,1,0.999253354069792,40.0298881530762,1.97574886404511,23.760000243783,-0.00209483516071148,-0.000450115184528016,0.25,-6.77192094716655E-6,-0.000188456869879793,-7.68528831553551E-6,24.0217686,24.0217686,99.4721298217773,99.4721298217773,55.0313375249674,19.6716476141039,6.58401,0,0,0,40,4882,24.31925,99.4721298217773,,,,,,,,,,,,,0,,,,0.00245,,,,,,24.0217686,,,,
,20341465.245,27.0276413,99.4721298217773,-0.000189395684758838,3.18542175850671E-7,1,0.999253354069792,40.0298881530762,1.97697377802479,23.7499997019768,-0.00209865493802999,-0.000427876081877051,0.25,-4.72930764538943E-6,-0.00018834368904306,-5.69557762899416E-6,27.0276413,27.0276413,99.4721298217773,99.4721298217773,54.9820949282558,19.649884649618,7.343312,0,0,0,40,4882,27.3977,99.4721298217773,,,,,,,,,,,,,0,,,,-0.00245,,,,,,27.0276413,,,,
,20341586.115,30.0122929,99.4721298217773,-0.000191403985368203,3.85399401273336E-7,1,0.999253354069792,40.0298881530762,1.9777467605029,23.760000243783,-0.00211550716705538,-0.000470810378903381,0.25,-8.14574239543377E-6,-0.000190375909576192,-9.16219126676519E-6,30.0122929,30.0122929,99.4721298217773,99.4721298217773,54.4865424470635,19.6437077008167,6.963661,0,0,0,40,4882,30.4555,99.4721298217773,,,,,,,,,,,,,0,,,,0.0049,,,,,,30.0122929,,,,
,20341707.625,33.0094948,99.4721298217773,-0.00019124201385002,7.88669965003277E-7,1,0.999253354069792,40.0298881530762,2.00326436940135,23.7799994647503,-0.00212517423230378,-0.000562674961301169,0.25,-1.5721441935589E-5,-0.000190244541043957,-1.6772232463797E-5,33.0094948,33.0094948,99.4721298217773,99.4721298217773,54.6452130364673,19.6416219615932,6.58401,0,0,0,40,4882,33.5293,99.4721298217773,,,,,,,,,,,,,0,,,,0,,,,,,33.0094948,,,,
,20341829.945,36.0193367,99.4721298217773,-0.000190761251750233,7.28227626502049E-7,1,0.999253354069792,40.0298881530762,2.0030584734343,23.7900000065565,-0.00212155005648544,-0.000556786958758975,0.25,-1.5189396435531E-5,-0.000189865911168032,-1.63233170173387E-5,36.0193367,36.0193367,99.4721298217773,99.4721298217773,54.5756480982558,19.6409759388124,6.58401,0,0,0,40,4882,36.6331,99.4721298217773,,,,,,,,,,,,,0,,,,0.00245,,,,,,36.0193367,,,,
,20341952.695,39.0165634,99.4721298217773,-0.00018514889322893,2.75299462381135E-7,1,0.999253354069792,40.0298881530762,2.00375368079697,23.7799994647503,-0.00208869038025242,-0.000387533684860594,0.25,-1.08546666430148E-6,-0.000184490722802348,-2.31723202983902E-6,39.0165634,39.0165634,99.4721298217773,99.4721298217773,55.6957217663136,19.6182929218804,6.963661,0,0,0,40,4882,39.7462,99.4721298217773,,,,,,,,,,,,,0,,,,0,,,,,,39.0165634,,,,
,20342074.655,42.00585365,99.4721298217773,-0.000185110815669188,2.43398546513714E-7,1,0.999253354069792,40.0298881530762,1.98015310192834,23.8000005483627,-0.00206570229077118,-0.00038755562620676,0.25,-1.39242592004551E-6,-0.000184599940121419,-2.68890014945707E-6,41.9809532,42.0307541,99.4721298217773,99.4721298217773,54.820297824775,19.5834717111515,6.963661,0,0,0,40,4886,42.8643,99.4721298217773,,,,,,,,,,,,,0,,,,0,,,,,,42.00585365,,,,
,20342200.925,45.0711861,99.4721298217773,-0.00018531575137067,2.89373301184367E-7,1,0.999253354069792,40.0298881530762,1.97985485435814,23.8099992275238,-0.00206889947886289,-0.00039254422551374,0.25,-1.72479407420514E-6,-0.000184977837568353,-3.07340221682266E-6,45.0711861,45.0711861,99.4721298217773,99.4721298217773,54.617074409775,19.6099149862502,7.343312,0,0,0,40,4886,46.1121,99.4721298217773,,,,,,,,,,,,,0,,,,-0.00245,,,,,,45.0711861,,,,
,20342323.9,48.0057564,99.4721298217773,-0.000184987854760534,3.40609190000378E-7,1,0.999253354069792,40.0298881530762,1.97971586554085,23.8099992275238,-0.00206758028989866,-0.000389787480224073,0.25,-1.48176294694211E-6,-0.000184834841026567,-2.8546407138856E-6,47.9773598,48.034153,99.4721298217773,99.4721298217773,55.7488725056213,19.6073212174691,7.343312,0,0,0,40,4886,49.2772,99.4721298217773,,,,,,,,,,,,,0,,,,-0.00245,,,,,,48.0057564,,,,
,20342448.585,51.0458641,99.4721298217773,-0.000184876813639651,2.97958261338353E-7,1,0.999253354069792,40.0298881530762,1.97967023316822,23.8000005483627,-0.00206857741456043,-0.000388723318202648,0.25,-1.37561877997482E-6,-0.000184909344171014,-2.74766755103127E-6,51.0458641,51.0458641,99.4721298217773,99.4721298217773,54.9281625604289,19.6107693674326,7.722963,0,0,0,40,4886,52.4668,99.4721298217773,,,,,,,,,,,,,0,,,,-0.0049,,,,,,51.0458641,,,,
,20342569.975,54.0210114,99.4721298217773,-0.000189737963594654,2.86082172824859E-7,1,0.999253354069792,40.0298881530762,1.97961813391145,23.8099992275238,-0.00211037194160393,-0.000479861154065175,0.25,-8.62259497329961E-6,-0.000189894543682243,-1.00142985697705E-5,54.0210114,54.0210114,99.4721298217773,99.4721298217773,54.7851245414096,19.5992145912517,7.343312,0,0,0,40,4886,55.5689,99.4721298217773,,,,,,,,,,,,,0,,,,0,,,,,,54.0210114,,,,
,20342694.99,57.0410309,99.4721298217773,-0.000188528093467944,2.84388246691164E-7,1,0.999253354069792,40.0298881530762,1.98020189272043,23.8000005483627,-0.00210262316385901,-0.000459108896819064,0.25,-6.9910874582109E-6,-0.000188860322052215,-8.33092450419402E-6,57.0410309,57.0410309,99.4721298217773,99.4721298217773,55.7832641604674,19.5997102774324,7.722963,0,0,0,40,4886,58.7646,99.4721298217773,,,,,,,,,,,,,0,,,,0,,,,,,57.0410309,,,,
,20342816.25,60.0071793,99.4721298217773,-0.000186502738184626,3.49667137723477E-7,1,0.999253354069792,40.0298881530762,1.98004611489336,23.8099992275238,-0.00208494051979002,-0.00043488080942132,0.25,-5.23166206399146E-6,-0.000186981852409441,-6.49838725981593E-6,60.0071793,60.0071793,99.4721298217773,99.4721298217773,54.6295804660827,19.6005427536817,7.343312,0,0,0,40,4886,61.8615,99.4721298217773,,,,,,,,,,,,,0,,,,-0.0049,,,,,,60.0071793,,,,
,20342939.87,63.04507825,99.4721298217773,-0.000186253796237491,2.92088940501313E-7,1,0.999253354069792,40.0298881530762,2.0038789697181,23.8300003111362,-0.00210812022242381,-0.000435702610375422,0.25,-4.95339184242398E-6,-0.000186854015363466,-6.15255493048562E-6,63.0171661,63.0729904,99.4721298217773,99.4721298217773,54.9992907556789,19.6148612245376,7.722963,0,0,0,40,4886,65.0125,99.4721298217773,,,,,,,,,,,,,0,,,,0.00245,,,,,,63.04507825,,,,
,20343062.89,66.0498123,99.4721298217773,-0.000185665661840002,2.76546604260266E-7,1,0.999253354069792,40.0298881530762,2.00424017900797,23.8300003111362,-0.00210447081216951,-0.000426067620149727,0.25,-4.25689319702924E-6,-0.000186367337094222,-5.38094042912551E-6,66.0498123,66.0498123,99.4721298217773,99.4721298217773,54.7069616894866,19.6135943700037,7.343312,0,0,0,40,4886,68.1584,99.4721298217773,,,,,,,,,,,,,0,,,,-0.00245,,,,,,66.0498123,,,,
,20343186.27,69.03105165,99.4721298217773,-0.000185173154459685,3.26767165210262E-7,1,0.999253354069792,40.0298881530762,2.0057819018826,23.8300003111362,-0.00210156382271483,-0.000424186388041611,0.25,-4.20751466790912E-6,-0.000185954368091188,-5.25903587937853E-6,69.0059357,69.0561676,99.4721298217773,99.4721298217773,54.7358819446981,19.5904265789389,7.722963,0,0,0,40,4886,71.3236,99.4721298217773,,,,,,,,,,,,,0,,,,0,,,,,,69.03105165,,,,
,20343308.79,72.01028825,99.4721298217773,-0.000184773762308161,3.22973135683881E-7,1,0.999253354069792,40.0298881530762,2.00560025110427,23.8400008529425,-0.00209918926083307,-0.000414302108235113,0.25,-3.46965474016715E-6,-0.000185621510174344,-4.44930091179326E-6,71.9851532,72.0354233,99.4721298217773,99.4721298217773,55.6753994248136,19.5850367035386,7.722963,0,0,0,40,4886,74.4535,99.4721298217773,,,,,,,,,,,,,0,,,,0.00245,,,,,,72.01028825,,,,
,20343411.11,74.529274,99.4721298217773,-0.000184752977747724,2.83486811571059E-7,1,0.999253354069792,40.0298881530762,1.99237503361634,23.8300003111362,-0.00208679830028717,-0.00040852220027094,0.25,-3.23820923400612E-6,-0.000185645005737332,-4.16411215703939E-6,74.529274,74.529274,99.4721298217773,99.4721298217773,54.6647537494481,19.5837616869666,7.722963,0,0,0,40,4886,77.0591,99.4721298217773,,,,,,,,,,,,,0,,,,0,,,,,,74.529274,,,,
,20343532.815,77.5205307,99.4721298217773,-0.000184069237024418,3.49686689877546E-7,1,0.999253354069792,40.0298881530762,1.99262241775243,23.8300003111362,-0.00208015204270967,-0.0004050517780437,0.25,-3.09996807113973E-6,-0.000184999597278565,-3.9637008286156E-6,77.5205307,77.5205307,99.4721298217773,99.4721298217773,55.5096941787366,19.5775038218992,7.343312,0,0,0,40,4886,80.1455,99.4721298217773,,,,,,,,,,,,,0,,,,0,,,,,,77.5205307,,,,
,20343654.51,80.5137787,99.4721298217773,-0.000183837219122495,3.31240088934164E-7,1,0.999253354069792,40.0298881530762,1.99250078237942,23.8300003111362,-0.00207868879506305,-0.000399384721081342,0.25,-2.69121727108837E-6,-0.000184800311743702,-3.49801572122448E-6,80.4856644,80.541893,99.4721298217773,99.4721298217773,55.0915229209481,19.5819804281112,7.343312,0,0,0,40,4886,83.2407,99.4721298217773,,,,,,,,,,,,,0,,,,-0.00245,,,,,,80.5137787,,,,
touchdown = 15.70999994874 mm,20343772.755,83.4468079,99.4721298217773,-0.00018311232599116,3.20751582002295E-7,1,0.999253354069792,40.0298881530762,1.98232406943824,23.8300003111362,-0.00206069525003571,-0.000395692283543495,0.25,-2.70806818638068E-6,-0.000184095237887442,-3.46439088850454E-6,83.4468079,83.4468079,99.4721298217773,99.4721298217773,55.6019263440059,19.560987303132,7.722963,0,0,0,40,4886,86.22885,99.4721298217773,,,,,,,,,,,,,0,,,,0.00245,,,,,,83.4468079,,,,
,20343877.815,86.050827,99.4721298217773,-0.000183218933240686,3.02200869903312E-7,1,0.999253354069792,40.0298881530762,1.98174191369396,23.8300003111362,-0.00206198625916038,-0.000393076026839214,0.25,-2.50290328056867E-6,-0.000184219517249321,-3.21979837169719E-6,86.050827,86.050827,99.4721298217773,99.4721298217773,55.3525868463712,19.5704080109235,7.722963,0,0,0,40,4886,88.878,99.4721298217773,,,,,,,,,,,,,0,,,,0,,,,,,86.050827,,,,
,20344000.21,89.0542145,99.4721298217773,-0.000182942893161301,2.98387041051672E-7,1,0.999253354069792,40.0298881530762,1.9822617392155,23.8300003111362,-0.00206001904211221,-0.000389982016423867,0.25,-2.3074898305092E-6,-0.000183957077833488,-2.98079892370322E-6,89.0542145,89.0542145,99.4721298217773,99.4721298217773,54.8335855096019,19.5627811433482,7.343312,0,0,0,40,4886,91.971,99.4721298217773,,,,,,,,,,,,,0,,,,0.0049,,,,,,89.0542145,,,,
,20344122.27,92.0528793,99.4721298217773,-0.000182176838162284,3.04602964894034E-7,1,0.999253354069792,40.0298881530762,1.98221902674949,23.8300003111362,-0.00205205989303238,-0.000384976491522739,0.25,-2.03546458500742E-6,-0.000183197893745647,-2.66678512099091E-6,92.0528793,92.0528793,99.4721298217773,99.4721298217773,54.4357365933135,19.562486668782,8.102614,0,0,0,40,4886,95.073,99.4721298217773,,,,,,,,,,,,,0,,,,0,,,,,,92.0528793,,,,
,20344244.25,95.0239334,99.4721298217773,-0.000181766602473041,3.15396047868897E-7,1,0.999253354069792,40.0298881530762,2.00717692843414,23.8300003111362,-0.00207251062286963,-0.000386497116506834,0.25,-1.86891593587093E-6,-0.000182792755872572,-2.46348286609008E-6,95.0239334,95.0239334,99.4721298217773,99.4721298217773,55.8958186672367,19.5756842015955,7.722963,0,0,0,40,4886,98.1902,99.4721298217773,,,,,,,,,,,,,0,,,,0,,,,,,95.0239334,,,,
,20344366.985,98.0014801,99.4721298217773,-0.000181334154184731,3.33957445989936E-7,1,0.999253354069792,40.0298881530762,2.00703152518387,23.8400008529425,-0.00206700292922511,-0.000388278920775476,0.25,-2.13381540356968E-6,-0.000182361005579022,-2.69714099190845E-6,98.0014801,98.0014801,99.4721298217773,99.4721298217773,55.626156828102,19.5793076014165,7.722963,0,0,0,40,4886,101.31435,99.4721298217773,,,,,,,,,,,,,0,,,,-0.00245,,,,,,98.0014801,,,,
,20344468.315,100.5254822,99.4721298217773,-0.00018095975186481,2.91076839580353E-7,1,0.999253354069792,40.0298881530762,2.007641108121,23.8400008529425,-0.002064502742686,-0.000380996788119772,0.25,-1.57574284724829E-6,-0.000181987243992274,-2.11110929880304E-6,100.5254822,100.5254822,99.4721298217773,99.4721298217773,54.237984577948,19.5812047371309,7.343312,0,0,0,40,4886,103.87945,99.4721298217773,,,,,,,,,,,,,0,,,,0,,,,,,100.5254822,,,,
,20344603.09,103.8224716,99.4721298217773,,,2,,,,23.8699991697073,,,,,,,103.8224716,103.8224716,99.4721298217773,99.4721298217773,,,7.343312,,,,-99999999,4886,107.2853,99.4721298217773,,,,,,,,,,,,,,,,,,,,,,,103.8224716,,,,
,20344710.42,106.5501251,99.4721298217773,-0.000179540532131613,3.03154144905759E-7,1,0.999253354069792,40.0298881530762,1.99374033963328,23.8400008529425,-0.00203541219213422,-0.000371682806015291,0.25,-1.27566186184394E-6,-0.000180557788023281,-1.75590766408415E-6,106.5501251,106.5501251,99.4721298217773,99.4721298217773,55.3041258781789,19.5855347807885,7.722963,0,0,0,40,4886,109.9824,99.4721298217773,,,,,,,,,,,,,0,,,,-0.0049,,,,,,106.5501251,,,,
,20344831.285,109.5192566,99.4721298217773,-0.000178423250028808,3.22403750006204E-7,1,0.999253354069792,40.0298881530762,1.99339682358564,23.8400008529425,-0.00202274234283685,-0.000367181472367721,0.25,-1.10221394795968E-6,-0.000179430912814741,-1.55709436532983E-6,109.5192566,109.5192566,99.4721298217773,99.4721298217773,55.5472123476597,19.5822033334937,8.102614,0,0,0,40,4886,113.02455,99.4721298217773,,,,,,,,,,,,,0,,,,-0.00245,,,,,,109.5192566,,,,
,20344952.125,112.5251274,99.4721298217773,-0.000177542658366555,3.03520236944118E-7,1,0.999253354069792,40.0298881530762,1.9934129818487,23.8400008529425,-0.00201240570912718,-0.000367139900812757,0.25,-1.27294348399131E-6,-0.000178539837251267,-1.70693949642138E-6,112.4980392,112.5522156,99.4721298217773,99.4721298217773,55.2892749363135,19.5867695594927,7.722963,0,0,0,40,4886,116.0673,99.4721298217773,,,,,,,,,,,,,0,,,,-0.00245,,,,,,112.5251274,,,,
,20345071.89,115.5183334,99.4721298217773,-0.000176614795611925,2.76681349963767E-7,1,0.999253354069792,40.0298881530762,1.98257404363901,23.8400008529425,-0.00199224578246653,-0.00035860687989357,0.25,-8.67217136205197E-7,-0.000177601527371208,-1.27888848334275E-6,115.5183334,115.5183334,99.4721298217773,99.4721298217773,55.2322160544097,19.5723122658585,8.102614,0,0,0,40,4886,119.0767,99.4721298217773,,,,,,,,,,,,,0,,,,-0.0049,,,,,,115.5183334,,,,
,20345193.205,118.5150146,99.4721298217773,-0.000175211225798219,2.68794081687099E-7,1,0.999253354069792,40.0298881530762,1.98283338000603,23.8499995321035,-0.00197700725253802,-0.000353348600411192,0.25,-6.60754121798576E-7,-0.000176183519252077,-1.05149860532877E-6,118.4918365,118.5381927,99.4721298217773,99.4721298217773,55.7981151023328,19.5743457832224,7.722963,0,0,0,40,4886,122.1273,99.4721298217773,,,,,,,,,,,,,0,,,,0.0049,,,,,,118.5150146,,,,
,20345313.76,121.5133133,99.4721298217773,-0.000174195973194994,3.35263331204621E-7,1,0.999253354069792,40.0298881530762,1.98266501258374,23.8400008529425,-0.00196488339160599,-0.00035365851633646,0.25,-8.8464463845146E-7,-0.000175154246374486,-1.25927148293213E-6,121.5133133,121.5133133,99.4721298217773,99.4721298217773,55.4401292405251,19.5755822808575,7.722963,0,0,0,40,4886,125.1562,99.4721298217773,,,,,,,,,,,,,0,,,,0,,,,,,121.5133133,,,,
,20345440.7,124.6408081,99.4721298217773,,,2,,,,23.8699991697073,,,,,,,124.6408081,124.6408081,99.4721298217773,99.4721298217773,,,8.102614,,,,-99999999,4886,128.3547,99.4721298217773,,,,,,,,,,,,,,,,,,,,,,,124.6408081,,,,
,20345555.995,127.52043535,99.4721298217773,-0.000171646582465893,3.43582340515741E-7,1,0.999253354069792,40.0298881530762,1.9933984571611,23.8300003111362,-0.00194597560263592,-0.000350018358552703,0.25,-8.78022360645786E-7,-0.000172573135084918,-1.22035903211689E-6,127.4940338,127.5468369,99.4721298217773,99.4721298217773,55.3189768200443,19.5804337277102,7.722963,0,0,0,40,4886,131.2582,99.4721298217773,,,,,,,,,,,,,0,,,,0,,,,,,127.52043535,,,,
,20345676.76,130.53430175,99.4721298217773,-0.000170043957370774,3.19759536121683E-7,1,0.999253354069792,40.0298881530762,1.99330639589757,23.8400008529425,-0.00192803517147345,-0.000344286167008668,0.25,-6.6748763728677E-7,-0.000170952489945751,-9.93667020801424E-7,130.5095215,130.559082,99.4721298217773,99.4721298217773,55.8207823293905,19.589147225002,7.343312,0,0,0,40,4886,134.2988,99.4721298217773,,,,,,,,,,,,,0,,,,-0.00735,,,,,,130.53430175,,,,
,20345796.805,133.51194,99.4721298217773,-0.000168455063340294,3.68821106974069E-7,1,0.999253354069792,40.0298881530762,1.99300564961712,23.8400008529425,-0.00190921333062438,-0.000343391653524165,0.25,-8.82893427082312E-7,-0.000169344624891173,-1.19629496462448E-6,133.4863586,133.5375214,99.4721298217773,99.4721298217773,55.2877116792751,19.5937483050034,8.102614,0,0,0,40,4886,137.32265,99.4721298217773,,,,,,,,,,,,,0,,,,-0.00245,,,,,,133.51194,,,,
,20345897.59,136.01130675,99.4721298217773,-0.000166981315369524,3.42929943926011E-7,1,0.999253354069792,40.0298881530762,2.00737187981654,23.8499995321035,-0.0019051317724987,-0.000344395763187292,0.25,-1.03112090594777E-6,-0.000167854059689816,-1.33409899457888E-6,135.9838409,136.0387726,99.4721298217773,99.4721298217773,55.7324583067174,19.5844853857711,8.102614,0,0,0,40,4886,139.8501,99.4721298217773,,,,,,,,,,,,,0,,,,-0.00245,,,,,,136.01130675,,,,
,20346018.96,139.0050583,99.4721298217773,-0.000165018264964084,3.26723633123542E-7,1,0.999253354069792,40.0298881530762,2.00658034411539,23.8499995321035,-0.00188209420900893,-0.000339109941981324,0.25,-9.33232250096307E-7,-0.000165870153814948,-1.22262513319827E-6,138.9780426,139.032074,99.4721298217773,99.4721298217773,54.9484849019289,19.6043311044252,8.102614,0,0,0,40,4886,142.91165,99.4721298217773,,,,,,,,,,,,,0,,,,-0.00245,,,,,,139.0050583,,,,
,20346139.975,142.0259476,99.4721298217773,-0.000163380465031655,3.006875262185E-7,1,0.999253354069792,40.0298881530762,2.00672612555341,23.8600000739098,-0.0018638025824951,-0.00033352949530091,0.25,-7.38660829613934E-7,-0.000164213021260424,-1.01539090187961E-6,141.9989014,142.0529938,99.4721298217773,99.4721298217773,55.2165834840251,19.6112383561615,8.102614,0,0,0,40,4886,145.96025,99.4721298217773,,,,,,,,,,,,,0,,,,0,,,,,,142.0259476,,,,
,20346259.78,145.003685,99.4721298217773,-0.000160830026537805,3.27712483064504E-7,1,0.999253354069792,40.0298881530762,2.00655487499473,23.8499995321035,-0.00183421082562416,-0.000329536082405667,0.25,-8.45693816176745E-7,-0.000161638158062579,-1.11064334748436E-6,144.9781189,145.0292511,99.4721298217773,99.4721298217773,56.6110087623329,19.6061240276522,7.722963,0,0,0,40,4886,148.96955,99.4721298217773,,,,,,,,,,,,,0,,,,0,,,,,,145.003685,,,,
,20346361.64,147.5395508,99.4721298217773,-0.000158603647647526,3.01860035645585E-7,1,0.999253354069792,40.0298881530762,2.00693639241783,23.8499995321035,-0.00180884148924803,-0.000326138776785065,0.25,-9.38853196378061E-7,-0.000159390723069774,-1.19426406015467E-6,147.5110321,147.5680695,99.4721298217773,99.4721298217773,55.1626511161982,19.6018216523116,8.102614,0,0,0,40,4886,151.5286,99.4721298217773,,,,,,,,,,,,,0,,,,0.0049,,,,,,147.5395508,,,,
,20346482.67,150.5537262,99.4721298217773,-0.000155516355367346,2.813962189196E-7,1,0.999253354069792,40.0298881530762,2.00720555267989,23.8600000739098,-0.00177419273510293,-0.000317130902989934,0.25,-6.93067933656021E-7,-0.000156276855330274,-9.35350226813329E-7,150.5537262,150.5537262,99.4721298217773,99.4721298217773,55.4948432368713,19.5936855239085,8.482265,0,0,0,40,4886,154.5642,99.4721298217773,,,,,,,,,,,,,0,,,,0.0049,,,,,,150.5537262,,,,
,20346601.87,153.5045929,99.4721298217773,-0.000152426288000098,3.93680914872888E-7,1,0.999253354069792,40.0298881530762,2.0064064010547,23.8499995321035,-0.00173836055991378,-0.000309478645798723,0.25,-5.79599670016264E-7,-0.000153160403676409,-8.10181891032096E-7,153.5045929,153.5045929,99.4721298217773,99.4721298217773,55.1649960017558,19.5907355269036,7.722963,0,0,0,40,4886,157.55775,99.4721298217773,,,,,,,,,,,,,0,,,,0,,,,,,153.5045929,,,,
,20346720.85,156.50300595,99.4721298217773,-0.000147940399426686,3.10914643069171E-7,1,0.999253354069792,40.0298881530762,2.00683256654896,23.8499995321035,-0.00168661155464733,-0.000305002493883718,0.25,-9.70822428522102E-7,-0.0001486407561146,-1.19071320726826E-6,156.4773254,156.5286865,99.4721298217773,99.4721298217773,55.2783321370443,19.5945516528551,8.102614,0,0,0,40,4886,160.53705,99.4721298217773,,,,,,,,,,,,,0,,,,-0.00245,,,,,,156.50300595,,,,
,20346842.66,159.52118685,99.4721298217773,-0.00014301012568308,3.29244240959251E-7,1,0.999253354069792,40.0298881530762,2.00575782055311,23.8600000739098,-0.00162985577395054,-0.000292277826036576,0.25,-7.34687245643237E-7,-0.000143675972444776,-9.4079332316232E-7,159.4959717,159.546402,99.4721298217773,99.4721298217773,55.4659229816597,19.6038758143279,7.722963,0,0,0,40,4886,163.5908,99.4721298217773,,,,,,,,,,,,,0,,,,-0.0049,,,,,,159.52118685,,,,
,20346963.345,162.5218658,99.4721298217773,-0.000136778072356086,3.46392313238613E-7,1,0.999253354069792,40.0298881530762,2.00556183450433,23.8600000739098,-0.00155958077641725,-0.000273618709872703,0.25,-1.92505383230074E-7,-0.000137404479467113,-3.82362637851993E-7,162.5218658,162.5218658,99.4721298217773,99.4721298217773,55.2838035366789,19.6109620961816,8.102614,0,0,0,40,4886,166.61795,99.4721298217773,,,,,,,,,,,,,0,,,,0,,,,,,162.5218658,,,,
,20347081.87,165.50341035,99.4721298217773,-0.00012857686604107,3.5427048381646E-7,1,0.999253354069792,40.0298881530762,2.00593563305252,23.8600000739098,-0.00146544907847461,-0.000261602277213805,0.25,-5.67887546352696E-7,-0.000129154575721153,-7.43828499198608E-7,165.4763947,165.530426,99.4721298217773,99.4721298217773,55.0579128946212,19.6169646337909,8.102614,0,0,0,40,4886,169.58555,99.4721298217773,,,,,,,,,,,,,0,,,,0.00245,,,,,,165.50341035,,,,
,20347204.5,168.5404205,99.4721298217773,-0.000116697563091197,3.48235564018778E-7,1,0.999253354069792,40.0298881530762,1.98137215574965,23.8600000739098,-0.00131319210082361,-0.00024153007438215,0.25,-1.13077370293482E-6,-0.00011721112691035,-1.28932500255941E-6,168.5404205,168.5404205,99.4721298217773,99.4721298217773,55.6277200851405,19.6124191025182,7.722963,0,0,0,40,4886,172.66485,99.4721298217773,,,,,,,,,,,,,0,,,,0,,,,,,168.5404205,,,,
,20347322.82,171.5079498,99.4721298217773,-9.94903721798927E-5,3.17957011724251E-7,1,0.999253354069792,40.0298881530762,1.98156228292113,23.8600000739098,-0.00112095194159689,-0.000197962574881489,0.25,-2.61248941438019E-7,-9.99206874289525E-5,-3.90329207288477E-7,171.5079498,171.5079498,99.4721298217773,99.4721298217773,56.0326036581021,19.6179469477661,8.102614,0,0,0,40,4886,175.6286,99.4721298217773,,,,,,,,,,,,,0,,,,0,,,,,,171.5079498,,,,
,20347443.77,174.5106659,99.4721298217773,-6.61561301214792E-5,2.7450412873559E-7,1,0.999253354069792,40.0298881530762,1.98133185663082,23.8600000739098,-0.000744602648943803,-0.000135214879522946,0.25,-4.95567526447852E-7,-6.64360978215358E-5,-5.80824546550814E-7,174.5106659,174.5106659,99.4721298217773,99.4721298217773,55.4815555520443,19.6074328861838,8.482265,0,0,0,40,4886,178.6647,99.4721298217773,,,,,,,,,,,,,0,,,,-0.00245,,,,,,174.5106659,,,,
,20347564.44,177.5127411,99.4721298217773,2.64175126374471E-5,3.45562938327295E-7,1,0.999253354069792,40.0298881530762,1.99156621915435,23.8600000739098,0.00030012854482939,4.64734250737364E-5,0.25,-4.88586795559537E-7,2.65278215525284E-5,-4.58140141338542E-7,177.5127411,177.5127411,99.4721298217773,99.4721298217773,55.710572708179,19.6128368203653,7.722963,0,0,0,40,4886,181.691,99.4721298217773,,,,,,,,,,,,,0,,,,0,,,,,,177.5127411,,,,
,20347685.65,180.5117645,99.4721298217773,0.000342664259934945,3.70076779561057E-7,1,0.999253354069792,40.0298881530762,1.99138539252263,23.8499995321035,0.00387786323053748,0.00068583231968295,0.25,1.01326767570072E-6,0.000344055408248058,1.42946301544474E-6,180.4872589,180.5362701,99.4721298217773,99.4721298217773,56.117019538179,19.6155354978771,8.102614,0,0,0,40,4886,184.7643,99.4721298217773,,,,,,,,,,,,,0,,,,0,,,,,,180.5117645,,,,
,20347807.99,183.5166168,99.4721298217773,0.000549353584277465,1.64656204793413E-5,1,0.999253354069792,40.0298881530762,1.991416025364,23.8600000739098,0.00578625217203855,0.00357493471273205,0.25,0.000220287570333756,0.000551276736774699,0.000221809077679792,183.5166168,183.5166168,99.4721298217773,99.4721298217773,54.739008458775,19.6251783331117,7.722963,0,0,0,40,4886,187.8857,99.4721298217773,,,,,,,,,,,,,0,,,,0,,,,,,183.5166168,,,,
,20347924.365,186.511261,99.4721298217773,0.000497785275449886,1.30188788953423E-5,1,0.999253354069792,40.0298881530762,1.99231242644365,23.8600000739098,0.00521871450331296,0.00339123936501636,0.25,0.000212933395589193,0.000499471241234916,0.000214334280946176,186.511261,186.511261,99.4721298217773,99.4721298217773,55.7332399352367,19.623940620565,8.102614,0,0,0,40,4886,190.7048,99.4721298217773,,,,,,,,,,,,,0,,,,0.0049,,,,,,186.511261,,,,
,20348026.19,189.024765,99.4721298217773,0.000498984047113862,1.57416153868923E-5,1,0.999253354069792,40.0298881530762,1.98096660043943,23.8600000739098,0.00519457388214409,0.00342610585998329,0.25,0.000217490678538694,0.000500634892242489,0.000218883968972443,188.997406,189.052124,99.4721298217773,99.4721298217773,55.5339246628328,19.6121040125315,8.102614,0,0,0,40,4886,193.2648,99.4721298217773,,,,,,,,,,,,,0,,,,0,,,,,,189.024765,,,,
,20348146.085,192.0137863,99.4721298217773,0.000491293523197046,1.1661367531324E-5,1,0.999253354069792,40.0298881530762,1.98089264312895,23.8600000739098,0.00513160234822545,0.00327102083859459,0.25,0.000205105104111468,0.000492887867010957,0.000206412528280956,191.9862976,192.041275,99.4721298217773,99.4721298217773,56.1646988778521,19.6143596955633,8.102614,0,0,0,40,4886,196.2814,99.4721298217773,,,,,,,,,,,,,0,,,,0,,,,,,192.0137863,,,,
,20348267.635,195.0457611,99.4721298217773,0.000448108697369782,1.1784013936864E-5,1,0.999253354069792,40.0298881530762,1.98110025276807,23.8600000739098,0.00463545431426506,0.00324343451445489,0.25,0.000210164957740394,0.000449498871195908,0.000211413365127121,195.0457611,195.0457611,99.4721298217773,99.4721298217773,55.4823371805636,19.5955714635869,8.482265,0,0,0,40,4886,199.3331,99.4721298217773,,,,,,,,,,,,,0,,,,-0.00245,,,,,,195.0457611,,,,
,20348388.01,198.02642055,99.4721298217773,0.000459079686747606,1.45103878599001E-5,1,0.999253354069792,40.0298881530762,1.9814726354954,23.8400008529425,0.00471086332857767,0.00354500318226341,0.25,0.000235018805247117,0.000460443651787834,0.000236337270575094,197.9956512,198.0571899,99.4721298217773,99.4721298217773,55.8231272149482,19.5943982396391,8.102614,0,0,0,40,4886,202.3672,99.4721298217773,,,,,,,,,,,,,0,,,,0,,,,,,198.02642055,,,,
,20348507.035,201.0036316,99.4721298217773,0.000442950894847588,1.34491245078573E-5,1,0.999253354069792,40.0298881530762,1.98131034238976,23.8400008529425,0.00456407247924683,0.00330783698645731,0.25,0.000216821540593068,0.000444239397342769,0.000218029358327205,201.0036316,201.0036316,99.4721298217773,99.4721298217773,56.0412015718136,19.5919559631864,8.482265,0,0,0,40,4886,205.34855,99.4721298217773,,,,,,,,,,,,,0,,,,-0.00245,,,,,,201.0036316,,,,
,20348628.055,204.0269165,99.4721298217773,0.000450811090481912,1.1805900367726E-5,1,0.999253354069792,40.0298881530762,1.98172293561631,23.8400008529425,0.00453669827932374,0.00399394828123271,0.25,0.00027635629224487,0.000452024996327662,0.000277740528741781,204.0269165,204.0269165,99.4721298217773,99.4721298217773,54.9633358437943,19.5937721185936,8.102614,0,0,0,40,4886,208.382,99.4721298217773,,,,,,,,,,,,,0,,,,0,,,,,,204.0269165,,,,
,20348748.805,207.0130768,99.4721298217773,0.000443808174489515,1.18602559839299E-5,1,0.999253354069792,40.0298881530762,1.98164752597226,23.8400008529425,0.00449699275873794,0.00375105731526393,0.25,0.000256057051184233,0.000444981119021372,0.000257333466621809,207.0130768,207.0130768,99.4721298217773,99.4721298217773,55.8903472676021,19.5986129848873,8.102614,0,0,0,40,4886,211.41,99.4721298217773,,,,,,,,,,,,,0,,,,0,,,,,,207.0130768,,,,
,20348869.6,210.0397491,99.4721298217773,0.000449017398082669,3.15227773649227E-6,1,0.999253354069792,40.0298881530762,2.00513223994595,23.8400008529425,0.00446159484764708,0.0046396930487719,0.25,0.000329506522356502,0.000450093746039213,0.000330984534755322,210.0397491,210.0397491,99.4721298217773,99.4721298217773,55.1868816002943,19.6110670229369,8.102614,0,0,0,40,4886,214.4407,99.4721298217773,,,,,,,,,,,,,0,,,,-0.00245,,,,,,210.0397491,,,,
,20348989.49,213.0039978,99.4721298217773,0.000438753095469841,3.74981633790518E-6,1,0.999253354069792,40.0298881530762,2.00515002113422,23.8300003111362,0.00433699429490949,0.00466160156186232,0.25,0.000333255447825036,0.000439756105523583,0.000334694781423155,213.0039978,213.0039978,99.4721298217773,99.4721298217773,55.6949401377944,19.6109402326357,8.102614,0,0,0,40,4886,217.453,99.4721298217773,,,,,,,,,,,,,0,,,,-0.0049,,,,,,213.0039978,,,,
,20349109.535,216.01195525,99.4721298217773,0.000437750216606812,2.80066229980308E-6,1,0.999253354069792,40.0298881530762,2.00435809893039,23.8300003111362,0.00431556489073988,0.00470355328822618,0.25,0.000337317266988479,0.000438707741066596,0.000338726882156398,215.9848022,216.0391083,99.4721298217773,99.4721298217773,55.8411046708905,19.6226962686912,7.722963,0,0,0,40,4886,220.46485,99.4721298217773,,,,,,,,,,,,,0,,,,0.00245,,,,,,216.01195525,,,,
,20349231.555,219.0509338,99.4721298217773,0.000426687169790389,3.87698163635234E-6,1,0.999253354069792,40.0298881530762,1.99124523768014,23.8600000739098,0.0041749601206781,0.0045838643412232,0.25,0.000331298627618257,0.00042757980372633,0.000332639273072312,219.0509338,219.0509338,99.4721298217773,99.4721298217773,54.9109667330058,19.5994418606431,8.482265,0,0,0,40,4886,223.52215,99.4721298217773,,,,,,,,,,,,,0,,,,0,,,,,,219.0509338,,,,
,20349350.53,222.0102234,99.4721298217773,0.000420900436338578,4.38322452194682E-6,1,0.999253354069792,40.0298881530762,1.99125110928085,23.8600000739098,0.00412223329384118,0.00449684844810186,0.25,0.000324652185043745,0.000421745814990389,0.000325929673010759,222.0102234,222.0102234,99.4721298217773,99.4721298217773,55.3158503059674,19.6047523535754,8.482265,0,0,0,40,4886,226.51725,99.4721298217773,,,,,,,,,,,,,0,,,,0,,,,,,222.0102234,,,,
,20349470.095,225.0052795,99.4721298217773,0.000411492857871379,6.15383404568496E-6,1,0.999253354069792,40.0298881530762,1.99067972389254,23.8600000739098,0.00401738650150832,0.00445952545206901,0.25,0.000323137294224543,0.000412276805302467,0.000324362921933266,225.0052795,225.0052795,99.4721298217773,99.4721298217773,56.0482362284867,19.5999837931789,8.102614,0,0,0,40,4886,229.5017,99.4721298217773,,,,,,,,,,,,,0,,,,0,,,,,,225.0052795,,,,
,20349591.08,228.0212708,99.4721298217773,0.000401873293258479,6.14974618784766E-6,1,0.999253354069792,40.0298881530762,1.99141725295961,23.8499995321035,0.00389458108018198,0.00452885166283143,0.25,0.000330844305061123,0.000402588260533133,0.000332041401041018,228.0212708,228.0212708,99.4721298217773,99.4721298217773,55.9184858942944,19.6059679283326,8.482265,0,0,0,40,4886,232.53985,99.4721298217773,,,,,,,,,,,,,0,,,,0,,,,,,228.0212708,,,,
,20349692.365,230.5228729,99.4721298217773,0.000397560893051232,5.29663859125992E-6,1,0.999253354069792,40.0298881530762,1.99127705805343,23.8400008529425,0.00385670942457957,0.00445383360927644,0.25,0.000325021524529328,0.000398239908732925,0.000326167420670614,230.5228729,230.5228729,99.4721298217773,99.4721298217773,55.4049559571597,19.6104871079448,8.482265,0,0,0,40,4886,235.0865,99.4721298217773,,,,,,,,,,,,,0,,,,-0.00245,,,,,,230.5228729,,,,
,20349813.23,233.5269623,99.4721298217773,0.000389552753353327,8.15042687517683E-6,1,0.999253354069792,40.0298881530762,1.99098973641368,23.8400008529425,0.00375879250720182,0.0044747203288911,0.25,0.00032835855836849,0.000390173401831769,0.000329466076959068,233.5269623,233.5269623,99.4721298217773,99.4721298217773,55.9161410087367,19.6111369154522,8.861917,0,0,0,40,4886,238.1247,99.4721298217773,,,,,,,,,,,,,0,,,,0.00245,,,,,,233.5269623,,,,
,20349933.65,236.5242157,99.4721298217773,0.000387286483550228,7.25542467051933E-6,1,0.999253354069792,40.0298881530762,1.99131406677627,23.8400008529425,0.00375334562423775,0.00435566164498649,0.25,0.000318201388357047,0.000387874722435167,0.000319245046323406,236.4985504,236.549881,99.4721298217773,99.4721298217773,55.3252298481982,19.6083453896221,8.102614,0,0,0,40,4886,241.14505,99.4721298217773,,,,,,,,,,,,,0,,,,0.00245,,,,,,236.5242157,,,,
touchdown = 15.7200004905462 mm,20350049.005,239.3957214,99.4721298217773,0.000374340038217642,7.55995222498147E-6,1,0.999253354069792,40.0298881530762,1.98039947370301,23.8400008529425,0.00358632153942888,0.00431584012784261,0.25,0.000318975863364307,0.000374865300680536,0.000319973544728441,239.3957214,239.3957214,99.4721298217773,99.4721298217773,55.3572766174866,19.6050189152241,8.482265,0,0,0,40,4886,244.0581,99.4721298217773,,,,,,,,,,,,,0,,,,-0.0049,,,,,,239.3957214,,,,
,20350153.735,242.0300751,99.4721298217773,0.000379135063806053,6.81226734242661E-6,1,0.999253354069792,40.0298881530762,1.9800232522778,23.8400008529425,0.00365024564781385,0.0042607338415168,0.25,0.000313349418051995,0.000379643818311689,0.000314306259715531,242.0300751,242.0300751,99.4721298217773,99.4721298217773,55.7605969334098,19.6155229966692,8.482265,0,0,0,40,4886,246.6662,99.4721298217773,,,,,,,,,,,,,0,,,,0.00245,,,,,,242.0300751,,,,
,20350274.59,245.01898955,99.4721298217773,0.000370227815695048,5.54671607826941E-6,1,0.999253354069792,40.0298881530762,1.98007994123098,23.8400008529425,0.00357028782115373,0.00412553270467777,0.25,0.000302896710489387,0.000370692138010674,0.000303788519017048,244.9941101,245.043869,99.4721298217773,99.4721298217773,55.9606938343328,19.6109597276683,8.861917,0,0,0,40,4886,249.6902,99.4721298217773,,,,,,,,,,,,,0,,,,-0.00245,,,,,,245.01898955,,,,
,20350393.82,248.0151367,99.4721298217773,0.000367542957505885,6.50208815080178E-6,1,0.999253354069792,40.0298881530762,1.98093039629992,23.8400008529425,0.0035464800049133,0.00409132099028283,0.25,0.000300210683437037,0.000367969126604186,0.000301059112648854,247.9904022,248.0398712,99.4721298217773,99.4721298217773,55.7527806482174,19.5912907338495,8.102614,0,0,0,40,4886,252.68265,99.4721298217773,,,,,,,,,,,,,0,,,,0.00245,,,,,,248.0151367,,,,
,20350515.615,251.036972,99.4721298217773,0.000358668640136152,4.76994869543089E-6,1,0.999253354069792,40.0298881530762,1.98078990434854,23.8300003111362,0.00345710479062394,0.00401019145979935,0.25,0.000294598358562655,0.000359048398123715,0.000295393695121369,251.036972,251.036972,99.4721298217773,99.4721298217773,56.0748115981406,19.5916372421642,8.102614,0,0,0,40,4886,255.73155,99.4721298217773,,,,,,,,,,,,,0,,,,0.00245,,,,,,251.036972,,,,
,20350636.14,254.0488586,99.4721298217773,0.000356717701033628,6.33210707513199E-6,1,0.999253354069792,40.0298881530762,1.98127675270557,23.8300003111362,0.00341823392921696,0.00410738589295647,0.25,0.000303540693756147,0.000357052356027857,0.000304313445577917,254.0488586,254.0488586,99.4721298217773,99.4721298217773,56.0732483411021,19.5876636939873,8.861917,0,0,0,40,4886,258.7749,99.4721298217773,,,,,,,,,,,,,0,,,,-0.0049,,,,,,254.0488586,,,,
,20350756.19,257.0239868,99.4721298217773,0.000349188630559208,6.97477661003645E-6,1,0.999253354069792,40.0298881530762,1.98103635653818,23.8300003111362,0.00336032927092715,0.00393360281802291,0.25,0.00028946710858643,0.000349488614854864,0.000290176841305496,257.0239868,257.0239868,99.4721298217773,99.4721298217773,55.7668499615636,19.6005058399263,8.102614,0,0,0,40,4886,261.762,99.4721298217773,,,,,,,,,,,,,0,,,,0,,,,,,257.0239868,,,,
touchdown = 15.7200004905462 mm,20350882.695,260.2137756,99.4721298217773,0.000347061317914454,6.889750764828E-6,1,0.999253354069792,40.0298881530762,1.98148537970876,23.8400008529425,0.0033478345271468,0.00386623746536287,0.25,0.000283809613338503,0.000347326385502573,0.000284473043556992,260.2137756,260.2137756,99.4721298217773,99.4721298217773,55.1556164595251,19.5977869489337,8.482265,0,0,0,40,4886,264.9503,99.4721298217773,,,,,,,,,,,,,0,,,,-0.0049,,,,,,260.2137756,,,,
,20350997.02,263.0266266,99.4721298217773,0.000336670176235637,5.9467933300664E-6,1,0.999253354069792,40.0298881530762,1.98148905196794,23.8400008529425,0.00322597746246431,0.00387317160699847,0.25,0.000286264713209157,0.00033688794567015,0.000286891574242939,262.997345,263.0559082,99.4721298217773,99.4721298217773,55.5870754021405,19.5953616893865,8.482265,0,0,0,40,4886,267.7832,99.4721298217773,,,,,,,,,,,,,0,,,,-0.0049,,,,,,263.0266266,,,,
,20351116.77,266.0349121,99.4721298217773,0.000342925071420973,7.58455502238445E-6,1,0.999253354069792,40.0298881530762,1.98134233096942,23.8400008529425,0.0033174029270627,0.00375958884772949,0.25,0.000275136403831195,0.000343125389063661,0.000275720630816615,266.0349121,266.0349121,99.4721298217773,99.4721298217773,56.0068099169675,19.6063826813352,8.102614,0,0,0,40,4886,270.77095,99.4721298217773,,,,,,,,,,,,,0,,,,0.0049,,,,,,266.0349121,,,,
,20351236.485,269.0010986,99.4721298217773,0.000339458072763239,7.95922231025458E-6,1,0.999253354069792,40.0298881530762,1.98185410052198,23.8400008529425,0.00328269922464942,0.00373166958895166,0.25,0.000273208822343434,0.000339622461631924,0.000273755850401592,269.0010986,269.0010986,99.4721298217773,99.4721298217773,55.687123852602,19.5998302706678,8.861917,0,0,0,40,4886,273.76775,99.4721298217773,,,,,,,,,,,,,0,,,,0.00245,,,,,,269.0010986,,,,
,20351356.77,272.01249695,99.4721298217773,0.000337498709152122,9.16234436554015E-6,1,0.999253354069792,40.0298881530762,1.99260251303882,23.8400008529425,0.0032854622236421,0.00369934362488032,0.25,0.000269014079389753,0.00033763035407536,0.000269522868666077,271.9873962,272.0375977,99.4721298217773,99.4721298217773,56.3499448369098,19.5923077255635,8.482265,0,0,0,40,4886,276.78025,99.4721298217773,,,,,,,,,,,,,0,,,,-0.00245,,,,,,272.01249695,,,,
,20351478.46,275.019043,99.4721298217773,0.000327173697960875,7.36704239007837E-6,1,0.999253354069792,40.0298881530762,1.99285745604452,23.8400008529425,0.00316209265671236,0.00371854332763911,0.25,0.00027250136467258,0.000327260153957237,0.000272973522566609,275.019043,275.019043,99.4721298217773,99.4721298217773,55.4792106664866,19.5935423390279,8.482265,0,0,0,40,4886,279.8354,99.4721298217773,,,,,,,,,,,,,0,,,,0.00245,,,,,,275.019043,,,,
,20351599.265,278.0470886,99.4721298217773,0.00033178364790321,8.18240523607219E-6,1,0.999253354069792,40.0298881530762,1.99340480355117,23.8400008529425,0.00322586035795459,0.00366367498365492,0.25,0.000266797564529056,0.000331844703108833,0.000267236091316414,278.0470886,278.0470886,99.4721298217773,99.4721298217773,55.636317998852,19.5898699898989,8.861917,0,0,0,40,4886,282.8586,99.4721298217773,,,,,,,,,,,,,0,,,,0,,,,,,278.0470886,,,,
touchdown = 15.7399997115135 mm,20351718.085,280.9958496,99.4721298217773,0.000328514339567984,7.7590396279657E-6,1,0.999253354069792,40.0298881530762,1.99361058588664,23.8600000739098,0.00321892786822384,0.00348416032678976,0.25,0.000251478710633619,0.000328551394792713,0.000251873776296013,280.9958496,280.9958496,99.4721298217773,99.4721298217773,55.4924983513136,19.5840069920071,8.482265,0,0,0,40,4886,285.862,99.4721298217773,,,,,,,,,,,,,0,,,,0,,,,,,280.9958496,,,,
,20351820.185,283.5048523,99.4721298217773,0.0003279129985507,7.41622556530674E-6,1,0.999253354069792,40.0298881530762,1.99387232212427,23.8600000739098,0.00321060161160589,0.00349273402359775,0.25,0.000252332994685342,0.000327921462408289,0.000252703052316895,283.5048523,283.5048523,99.4721298217773,99.4721298217773,55.8004599878905,19.5795259920026,8.482265,0,0,0,40,4886,288.4096,99.4721298217773,,,,,,,,,,,,,0,,,,0.00245,,,,,,283.5048523,,,,
,20351941.935,286.5209961,99.4721298217773,0.00032637648058395,7.13978548873405E-6,1,0.999253354069792,40.0298881530762,1.99429076145613,23.8600000739098,0.0032038387877394,0.00343074747717722,0.25,0.000247086994572155,0.000326354628509318,0.000247423460358218,286.5209961,286.5209961,99.4721298217773,99.4721298217773,55.6285017136597,19.5837889028815,8.861917,0,0,0,40,4886,291.47075,99.4721298217773,,,,,,,,,,,,,0,,,,0.00245,,,,,,286.5209961,,,,
,20352064.35,289.5405273,99.4721298217773,0.000324735667932455,5.8893918230402E-6,1,0.999253354069792,40.0298881530762,1.994680837161,23.8600000739098,0.00318965835845843,0.00340423684188574,0.25,0.000245003709128122,0.000324681490975035,0.000245308795760669,289.5405273,289.5405273,99.4721298217773,99.4721298217773,55.2142385984674,19.5761756829795,8.861917,0,0,0,40,4886,294.5518,99.4721298217773,,,,,,,,,,,,,0,,,,0,,,,,,289.5405273,,,,
,20352164.235,292.0098877,99.4721298217773,0.000311828104138638,6.25772119778037E-6,1,0.999253354069792,40.0298881530762,1.99505982964007,23.8799992948771,0.00305076082240377,0.00334090243014462,0.25,0.000241609590348286,0.000311745865996685,0.000241881228523659,292.0098877,292.0098877,99.4721298217773,99.4721298217773,55.4596699535059,19.5738402915688,8.861917,0,0,0,40,4886,297.0676,99.4721298217773,,,,,,,,,,,,,0,,,,-0.00245,,,,,,292.0098877,,,,
,20352285.865,295.0127869,99.4721298217773,0.000320284100251005,5.37588311241746E-6,1,0.999253354069792,40.0298881530762,1.99496000700598,23.8799992948771,0.00316887616418398,0.00322405823944261,0.25,0.000229851348285522,0.000320179416342167,0.000230098311031532,295.0127869,295.0127869,99.4721298217773,99.4721298217773,55.3135054204097,19.5774578308332,8.861917,0,0,0,40,4886,300.1439,99.4721298217773,,,,,,,,,,,,,0,,,,-0.0049,,,,,,295.0127869,,,,
,20352407.315,298.0078735,99.4721298217773,0.000320932814666939,5.89200395955878E-6,1,0.999253354069792,40.0298881530762,1.99495472041495,23.8799992948771,0.00317851031035575,0.00320978714896863,0.25,0.000228509259012949,0.00032079658486525,0.000228729419956974,298.0078735,298.0078735,99.4721298217773,99.4721298217773,55.1368573750635,19.5880938170177,8.102614,0,0,0,40,4886,303.20455,99.4721298217773,,,,,,,,,,,,,0,,,,0,,,,,,298.0078735,,,,
,20352541.75,301.2865906,99.4721298217773,,,2,,,,23.9300005578995,,,,,,,301.2865906,301.2865906,99.4721298217773,99.4721298217773,,,8.861917,,,,-99999999,4886,306.6034,99.4721298217773,,,,,,,,,,,,,,,,,,,,,,,301.2865906,,,,
,20352650.165,304.0061035,99.4721298217773,0.000311064568668294,6.08566442632713E-6,1,0.999253354069792,40.0298881530762,1.99558967253047,23.9100009202957,0.00309412448296443,0.00303613585026917,0.25,0.000214828420158775,0.000310873630388575,0.000214990769592286,304.0061035,304.0061035,99.4721298217773,99.4721298217773,55.2955279644674,19.571191987181,8.102614,0,0,0,40,4886,309.32235,99.4721298217773,,,,,,,,,,,,,0,,,,0,,,,,,304.0061035,,,,
,20352771.745,307.0145874,99.4721298217773,0.000310544562749068,6.3162387942793E-6,1,0.999253354069792,40.0298881530762,1.99571899172169,23.9100009202957,0.00308946277001171,0.00302727426929601,0.25,0.000214148336797888,0.000310322491294453,0.000214285234976902,306.9887085,307.0404663,99.4721298217773,99.4721298217773,55.3682194167559,19.5694053313339,8.482265,0,0,0,40,4886,312.3933,99.4721298217773,,,,,,,,,,,,,0,,,,0,,,,,,307.0145874,,,,
,20352893.625,310.0229797,99.4721298217773,0.000307284527671937,6.72757059687692E-6,1,0.999253354069792,40.0298881530762,1.99590784274393,23.9100009202957,0.00305576683016325,0.00300254808753892,0.25,0.000212530904125896,0.000307033095453068,0.000212641254489217,310.0229797,310.0229797,99.4721298217773,99.4721298217773,55.2431588536789,19.569443014167,8.482265,0,0,0,40,4886,315.4698,99.4721298217773,,,,,,,,,,,,,0,,,,-0.00245,,,,,,310.0229797,,,,
,20353016.46,313.02319335,99.4721298217773,0.000306255904613523,5.63845765882346E-6,1,0.999253354069792,40.0298881530762,1.99596390195936,23.9599999040365,0.00305645378387657,0.00292794007707759,0.25,0.000206127958644436,0.00030597777837941,0.00020621604694425,312.9962463,313.0501404,99.4721298217773,99.4721298217773,55.3103789063328,19.5635686609654,8.482265,0,0,0,40,4886,318.5658,99.4721298217773,,,,,,,,,,,,,0,,,,-0.0049,,,,,,313.02319335,,,,
,20353137.615,316.01976015,99.4721298217773,0.00029869079982194,4.24310749639034E-6,1,0.999253354069792,40.0298881530762,1.99631225204268,23.9599999040365,0.00298553141715361,0.00283049149947718,0.25,0.000198798987599949,0.000298390648523853,0.000198862900236391,315.9935608,316.0459595,99.4721298217773,99.4721298217773,55.1134085194866,19.564278538945,8.861917,0,0,0,40,4886,321.63505,99.4721298217773,,,,,,,,,,,,,0,,,,0.0049,,,,,,316.01976015,,,,
,20353378.18,319.0013123,99.4721298217773,0.000300483285699187,6.7887864893617E-6,1,0.999253354069792,40.0298881530762,1.99697597669207,23.9599999040365,0.00300246739030644,0.00285739251002236,0.25,0.000200815804807164,0.000300148828583364,0.000200858711149794,319.0013123,319.0013123,99.4721298217773,99.4721298217773,54.823424338852,19.5582134556262,8.861917,0,0,0,40,4886,321.0896,99.4721298217773,,,,,,,,,,,,,0,,,,-0.00245,,,,,,319.0013123,,,,
,20353625.99,319.87397765,99.4721298217773,0.000305810096155959,5.35120544142379E-6,1,0.999253354069792,40.0298881530762,1.99813608307762,23.9599999040365,0.00307085744998942,0.00283127349641629,0.25,0.000197450940407115,0.000305464751079646,0.000197493080842698,319.8717651,319.8761902,99.4721298217773,99.4721298217773,55.240032339602,19.5491254516158,8.861917,0,0,0,40,4881,321.56305,99.4721298217773,,,,,,,,,,,,,0,,,,-0.00245,,,,,,319.87397765,,,,