File: data/monolayers/nanoparticles/Ac_CoFe_C/vsm/data_dispersion/AH11_HYST_100OE_250K.DAT
[Header]
; VSM Data File (default extension .dat)
; Copyright (c) 2003-2013, Quantum Design, Inc. All rights reserved.
TITLE,
FILEOPENTIME,20426649.95,08/25/2018,7:03 pm
BYAPP,VSM,2.0,2.0
INFO,PPMS VSM Option Release 1.4.10 Build 1,APPNAME
INFO,Quantum Design Linear Motor Servo Controller,MOTOR_MODULE_NAME
INFO,3101-100 M1,MOTOR_HW_VERSION
INFO,MMC1014,MOTOR_SERIAL_NUMBER
INFO,SRV No X-over 01.03.11,MOTOR_SOFTWARE_VERSION
INFO,Quantum Design VSM Detection Module,VSM_MODULE_NAME
INFO,3101-150 F0,VSM_HW_VERSION
INFO,VSM707,VSM_SERIAL_NUMBER
INFO,VSM No X-over 01.02.05 May 20 2008 13:51:47,VSM_SOFTWARE_VERSION
INFO,704,PREAMP_SERIAL_NUMBER
INFO,822,COIL_SERIAL_NUMBER
INFO,0,MOMENT_UNITS
INFO,CoFe2O4,SAMPLE_MATERIAL
INFO,Cobalt deficient,SAMPLE_COMMENT
INFO,,SAMPLE_MASS
INFO,27,SAMPLE_VOLUME
INFO,,SAMPLE_MOLECULAR_WEIGHT
INFO,,SAMPLE_SIZE
INFO,,SAMPLE_SHAPE
DATATYPE,COMMENT,1
DATATYPE,TIME,2
STARTUPAXIS,X,2
STARTUPAXIS,Y1,5
[Data]
Comment,Time Stamp (sec),Temperature (K),Magnetic Field (Oe),Moment (emu),M. Std. Err. (emu),Transport Action,Averaging Time (sec),Frequency (Hz),Peak Amplitude (mm),Center Position (mm),Coil Signal' (mV),Coil Signal" (mV),Range (mV),M. Quad. Signal (emu),M. Raw' (emu),M. Raw" (emu),Min. Temperature (K),Max. Temperature (K),Min. Field (Oe),Max. Field (Oe),Mass (grams),Motor Lag (deg),Pressure (Torr),VSM Status (code),Motor Status (code),Measure Status (code),Measure Count,PPMS Status (code),System Temp. (K),System Field (Oe),Sample Position (deg),Bridge 1 Resistance (ohms),Bridge 1 Excitation (에),Bridge 2 Resistance (ohms),Bridge 2 Excitation (에),Bridge 3 Resistance (ohms),Bridge 3 Excitation (에),Bridge 4 Resistance (ohms),Bridge 4 Excitation (에),Signal 1 Vin (V),Signal 2 Vin (V),Digital Inputs (code),Drive 1 Iout (mA),Drive 1 Ipower (W),Drive 2 Iout (mA),Drive 2 Ipower (W),Pressure (),Map 20 (),Map 21 (),Map 22 (),Map 23 (),Map 24 (),Map 25 (),Map 26 (),Map 27 (),Map 28 (),Map 29 ()
,20426666.27,250.1781311,6068.53369140625,,,2,,,,23.8099996441603,,,,,,,250.1781311,250.1781311,6068.53369140625,6068.53369140625,,,10.38052,,,,-99999999,4961,250.2754,6068.53369140625,,,,,,,,,,,,,,,,,,,,,,,250.1781311,,,,
,20426794.83,250.2356,3408.78723144531,0.00181007791355878,2.96917621875402E-5,1,0.999253354069792,40.0298881530762,1.98495043170855,23.7900000065565,0.0173297382293662,0.021156797630381,0.25,0.00156462762037725,0.00181194692929298,0.00156885414142467,250.235,250.235,3383.88842773438,3433.68603515625,54.8398385377558,19.5267654036651,10.760172,0,0,0,40,4961,250.2356,3408.78723144531,,,,,,,,,,,,,0,,,,,,,,,,,,,,
,20426866.82,250.22525,7002.69848632813,0.00185661059307443,3.01348776338769E-5,1,0.999253354069792,40.0298881530762,1.98498562215705,23.7900000065565,0.0177525720033965,0.0218336294099461,0.25,0.00161662168858575,0.00185851961336176,0.00162097710836414,250.2248,250.2248,6972.6005859375,7032.79638671875,55.1438920317366,19.5228656641532,10.760172,0,0,0,40,4961,250.22525,7002.69848632813,,,,,,,,,,,,,0,,,,,,,,,,,,,,
,20426938.96,250.21725,10608.8237304688,0.00183580514773036,4.19394292470026E-5,1,0.999253354069792,40.0298881530762,1.98495426639957,23.7900000065565,0.017488524657701,0.021962649520983,0.25,0.00163171524051368,0.0018376670366847,0.0016360793018778,250.2174,250.2174,10576.419921875,10641.2275390625,55.1845367147366,19.5184076428844,10.38052,0,0,0,40,4961,250.21725,10608.8237304688,,,,,,,,,,,,,0,,,,,,,,,,,,,,
,20427011.75,250.2108,14247.333984375,0.00184879947303466,3.20518528476646E-5,1,0.999253354069792,40.0298881530762,1.98499285381471,23.7900000065565,0.0175866894542034,0.0222682676690619,0.25,0.00165656162786617,0.00185066526547359,0.00166097906481159,250.2099,250.2099,14219.689453125,14274.978515625,55.7441827345059,19.5195826280588,10.00087,0,0,0,40,4961,250.2108,14247.333984375,,,,,,,,,,,,,0,,,,,,,,,,,,,,
,20427088.055,250.2098,18060.01171875,0.00182730236974589,2.94839834493594E-5,1,0.999253354069792,40.0298881530762,1.98509809936277,23.7900000065565,0.0172879258621842,0.022559230296712,0.25,0.00168602364680457,0.00182910785223817,0.00169047365263799,250.2081,250.2081,18057.6171875,18062.40625,55.5331430343136,19.5254218032553,10.760172,0,0,0,40,4961,250.2098,18060.01171875,,,,,,,,,,,,,0,,,,,,,,,,,,,,
,20427161.705,250.2024,21742.994140625,0.00181129756483547,4.21555721435759E-5,1,0.999253354069792,40.0298881530762,1.98514346833234,23.7900000065565,0.0171340270030653,0.0223787061572598,0.25,0.00167272849811362,0.00181308790543045,0.00167714132576336,250.204,250.204,21715.345703125,21770.642578125,55.4674862386982,19.5160794932256,10.760172,0,0,0,40,4961,250.2024,21742.994140625,,,,,,,,,,,,,0,,,,,,,,,,,,,,
,20427237.11,250.19375,25510.91796875,0.00179716662221665,5.85376872324527E-5,1,0.999253354069792,40.0298881530762,1.98511051048171,23.8000005483627,0.0169844150205379,0.0222942599226418,0.25,0.00166771352356924,0.00179893841729483,0.00167210521255408,250.194,250.194,25478.50390625,25543.33203125,55.2744239944482,19.5261745798284,10.00087,0,0,0,40,4961,250.19375,25510.91796875,,,,,,,,,,,,,0,,,,,,,,,,,,,,
,20427313.455,250.1812,29327.013671875,0.00181323382601045,3.62525431352098E-5,1,0.999253354069792,40.0298881530762,1.9851156890877,23.7900000065565,0.0171446127044928,0.022445875184481,0.25,0.0016783833766306,0.00181502727553999,0.0016828063561919,250.1816,250.1816,29297.140625,29356.88671875,55.4917167227943,19.5141880302166,10.38052,0,0,0,40,4961,250.1812,29327.013671875,,,,,,,,,,,,,0,,,,,,,,,,,,,,
,20427388.31,250.17455,33067.203125,0.00173755303460969,4.0840850753719E-5,1,0.999253354069792,40.0298881530762,1.98498347426415,23.7900000065565,0.016309229279738,0.0221925783600938,0.25,0.00166914517718473,0.00173922368870162,0.00167348899866926,250.1738,250.1738,33034.5078125,33099.8984375,55.3525868463712,19.5182730724997,10.38052,0,0,0,40,4961,250.17455,33067.203125,,,,,,,,,,,,,0,,,,,,,,,,,,,,
,20427463.62,250.174,36830.552734375,0.00172510931170412,3.83096108938273E-5,1,0.999253354069792,40.0298881530762,1.98502109363311,23.7900000065565,0.0161599990794475,0.0222228440944772,0.25,0.00167395575892283,0.00172675593554059,0.00167829647023295,250.1747,250.1747,36798.16796875,36862.9375,55.0086702979097,19.5167327406031,10.00087,0,0,0,40,4961,250.174,36830.552734375,,,,,,,,,,,,,0,,,,,,,,,,,,,,
,20427538.495,250.16175,40573.69140625,0.0016601485349535,4.74636026848078E-5,1,0.999253354069792,40.0298881530762,1.98522071370918,23.7900000065565,0.0153887737230785,0.0223350568727846,0.25,0.00169499395756953,0.00166166662296221,0.0016993177653184,250.1618,250.1618,40541.00390625,40606.37890625,55.4573250679482,19.5081350590464,10.38052,0,0,0,40,4961,250.16175,40573.69140625,,,,,,,,,,,,,0,,,,,,,,,,,,,,
,20427615.405,250.14805,44418.892578125,0.0016078104750947,4.94072199673077E-5,1,0.999253354069792,40.0298881530762,1.98511028720493,23.7900000065565,0.0148708111538936,0.021814583899839,0.25,0.00165796595526676,0.00160926968542528,0.00166218171664449,250.1496,250.1496,44388.734375,44449.05078125,55.3963580434482,19.5175177223929,10.38052,0,0,0,40,4961,250.14805,44418.892578125,,,,,,,,,,,,,0,,,,,,,,,,,,,,
,20427692.505,250.1309,48272.47265625,0.00155339774854441,4.34698986537359E-5,1,0.999253354069792,40.0298881530762,1.98527162126036,23.7900000065565,0.0142081777454323,0.0220035253689384,0.25,0.00168402512405913,0.00155474302040401,0.00168824185326999,250.1311,250.1311,48247.703125,48297.2421875,55.9685101195252,19.5174003562858,10.38052,0,0,0,40,4961,250.1309,48272.47265625,,,,,,,,,,,,,0,,,,,,,,,,,,,,
,20427768.555,250.1154,52070.751953125,0.00155900514277058,4.59913986677488E-5,1,0.999253354069792,40.0298881530762,1.98539306962355,23.7900000065565,0.0142235910009548,0.0222960890796242,0.25,0.00170890985296263,0.00156034245764026,0.00171317445893574,250.1144,250.1144,52040.8359375,52100.66796875,55.3064707637366,19.5281502847061,10.00087,0,0,0,40,4961,250.1154,52070.751953125,,,,,,,,,,,,,0,,,,,,,,,,,,,,
,20427843.61,250.1002,55823.115234375,0.00153532927724246,6.53812049509876E-5,1,0.999253354069792,40.0298881530762,1.98516643625263,23.7900000065565,0.0140026804449721,0.0219747310439501,0.25,0.00168470063814978,0.00153664734887122,0.00168890324499661,250.1022,250.1022,55798.125,55848.10546875,55.3783805875059,19.5175583768998,10.38052,0,0,0,40,4961,250.1002,55823.115234375,,,,,,,,,,,,,0,,,,,,,,,,,,,,
,20427920.075,250.0871,59646.9921875,0.00145724203004083,5.08837824027377E-5,1,0.999253354069792,40.0298881530762,1.98536683902902,23.7900000065565,0.0131511854660151,0.0216700164915645,0.25,0.00167100357076913,0.00145843681281078,0.00167511817239699,250.0864,250.0864,59617.2734375,59676.7109375,55.0586945231404,19.5192934182933,10.00087,0,0,0,40,4961,250.0871,59646.9921875,,,,,,,,,,,,,0,,,,,,,,,,,,,,
,20427994.93,250.0735,63387.830078125,0.00143343042363478,4.4987085108286E-5,1,0.999253354069792,40.0298881530762,1.98527249568268,23.7900000065565,0.0129125673336224,0.0214485421537876,0.25,0.00165555827644887,0.00143459839278618,0.00165962609063568,250.0746,250.0746,63355.46875,63420.19140625,55.4792106664866,19.5100145914448,10.00087,0,0,0,40,4961,250.0735,63387.830078125,,,,,,,,,,,,,0,,,,,,,,,,,,,,
,20428071.97,250.06325,67238.60546875,0.00137080790631253,4.96578835951068E-5,1,0.999253354069792,40.0298881530762,1.9854789927988,23.7900000065565,0.0122525315082204,0.0210739232799436,0.25,0.00163297464420897,0.00137188665252921,0.00163695141400125,250.0636,250.0636,67208.6875,67268.5234375,55.8856574964867,19.5164489523415,10.38052,0,0,0,40,4961,250.06325,67238.60546875,,,,,,,,,,,,,0,,,,,,,,,,,,,,
,20428145.73,250.05055,70923.9921875,0.00131859301259218,6.22202656135918E-5,1,0.999253354069792,40.0298881530762,1.98522124783289,23.7900000065565,0.0116980211483491,0.020766747010507,0.25,0.00161499043985638,0.00131959700081778,0.0016188929631806,250.0508,250.0508,70896.5546875,70951.4296875,55.7988967308521,19.5169958178935,10.38052,0,0,0,40,4961,250.05055,70923.9921875,,,,,,,,,,,,,0,,,,,,,,,,,,,,
,20428222.31,250.0403,74752.38671875,0.00126663610173479,7.46918340027731E-5,1,0.999253354069792,40.0298881530762,1.98536384202799,23.7900000065565,0.0110451069040213,0.0210614795784164,0.25,0.00165003812747238,0.00126752273314768,0.00165395955616044,250.0402,250.0402,74720.2734375,74784.5,55.7660683330444,19.5133855683232,10.00087,0,0,0,40,4961,250.0403,74752.38671875,,,,,,,,,,,,,0,,,,,,,,,,,,,,
,20428297.395,250.0299,78505.90625,0.00121787427271542,7.79980105697905E-5,1,0.999253354069792,40.0298881530762,1.98561220843207,23.7900000065565,0.0105679272125424,0.0205602782462977,0.25,0.00161378285572966,0.00121870683182251,0.00161760076542389,250.0293,250.0293,78478.375,78533.4375,55.128259461352,19.5096962763019,10.38052,0,0,0,40,4961,250.0299,78505.90625,,,,,,,,,,,,,0,,,,,,,,,,,,,,
,20428372.81,250.0202,82274.81640625,0.00116045283387113,9.33979658603394E-5,1,0.999253354069792,40.0298881530762,1.98554081906193,23.7900000065565,0.00993582975726643,0.0203601265196505,0.25,0.00160603644362275,0.00116119296248331,0.00160979390183095,250.0203,250.0203,82242.4375,82307.1953125,55.6027079725251,19.5177034716695,10.00087,0,0,0,40,4961,250.0202,82274.81640625,,,,,,,,,,,,,0,,,,,,,,,,,,,,
,20428447.65,250.00875,86015.640625,0.00112536554529439,9.94605564244473E-5,1,0.999253354069792,40.0298881530762,1.98569839930786,23.7900000065565,0.00966435087505138,0.0195834812317205,0.25,0.00154305006344534,0.00112609703209178,0.00154666828144222,250.0085,250.0085,85985.75,86045.53125,56.0576157707175,19.5108550330439,10.38052,0,0,0,40,4961,250.00875,86015.640625,,,,,,,,,,,,,0,,,,,,,,,,,,,,
,20428521.19,249.99875,89691.49609375,0.00107108016941469,0.000127181985301005,1,0.999253354069792,40.0298881530762,1.98546678241087,23.7900000065565,0.00904595301589643,0.0195087191190633,0.25,0.00154602065005692,0.00107171590550673,0.00154959996305809,249.9987,249.9987,89688.8515625,89694.140625,55.4112089853136,19.5180702657555,10.00087,0,0,0,40,4961,249.99875,89691.49609375,,,,,,,,,,,,,0,,,,,,,,,,,,,,
,20428607.1,249.99065,86728.76953125,0.00113157116088885,7.61993543417264E-5,1,0.999253354069792,40.0298881530762,1.98550411317811,23.7900000065565,0.00962258560007202,0.0202326345300353,0.25,0.00159975844988381,0.00113226873866835,0.0016034821895436,249.992,249.992,86698.828125,86758.7109375,55.8497025846021,19.5196574586905,10.760172,0,0,0,40,4961,249.99065,86728.76953125,,,,,,,,,,,,,0,,,,,,,,,,,,,,
,20428679.98,249.98855,83087.27734375,0.00117941591144935,6.82081625457246E-5,1,0.999253354069792,40.0298881530762,1.98534085591156,23.7900000065565,0.0102199333769589,0.0199832882324373,0.25,0.00156946675842197,0.00118022038383022,0.00157317699786283,249.9891,249.9891,83059.59375,83114.9609375,55.3987029290059,19.5121625021122,10.00087,0,0,0,40,4961,249.98855,83087.27734375,,,,,,,,,,,,,0,,,,,,,,,,,,,,
,20428754.285,249.99175,79370.42578125,0.00119743229392818,8.21523047806687E-5,1,0.999253354069792,40.0298881530762,1.98509373207817,23.7900000065565,0.0102724163657314,0.0208765237993138,0.25,0.00164585809491175,0.00119820481332583,0.00164971792804833,249.9908,249.9908,79340.515625,79400.3359375,55.5690979461982,19.5139654511182,10.38052,0,0,0,40,4961,249.99175,79370.42578125,,,,,,,,,,,,,0,,,,,,,,,,,,,,
,20428829.495,249.9935,75611.921875,0.00125764622233157,5.92119834684979E-5,1,0.999253354069792,40.0298881530762,1.98531424511704,23.7900000065565,0.0110643748191411,0.0203469595596777,0.25,0.00158820730565714,0.00125856933997778,0.00159201554425568,249.9931,249.9931,75581.9140625,75641.9296875,55.6996299089097,19.5153820271497,10.38052,0,0,0,40,4961,249.9935,75611.921875,,,,,,,,,,,,,0,,,,,,,,,,,,,,
,20428904.235,249.99965,71876.16015625,0.00129587136077099,6.95163647505963E-5,1,0.999253354069792,40.0298881530762,1.98516465607269,23.7900000065565,0.0114293556639661,0.0207935789212788,0.25,0.0016213596809887,0.00129683277968504,0.00162525783842466,249.9984,249.9984,71843.8046875,71908.515625,55.2329976829289,19.5207086365881,10.38052,0,0,0,40,4961,249.99965,71876.16015625,,,,,,,,,,,,,0,,,,,,,,,,,,,,
,20428978.04,250.006,68185.04296875,0.00133446432367545,5.89834081529094E-5,1,0.999253354069792,40.0298881530762,1.98516855737506,23.7900000065565,0.0118393091547355,0.0210116870297482,0.25,0.0016340272610398,0.00133548125476117,0.00163797968271026,250.0065,250.0065,68155.0390625,68215.046875,55.3815071015828,19.5227147976366,10.38052,0,0,0,40,4961,250.006,68185.04296875,,,,,,,,,,,,,0,,,,,,,,,,,,,,
,20429054.155,250.0126,64384.2109375,0.0013955788952731,6.61484349834909E-5,1,0.999253354069792,40.0298881530762,1.98519397675781,23.7900000065565,0.0124382691203128,0.0216476814386219,0.25,0.00167986959999398,0.00139666382094109,0.00168395290298101,250.0123,250.0123,64356.55859375,64411.86328125,55.9216124083713,19.5220659040259,10.760172,0,0,0,40,4961,250.0126,64384.2109375,,,,,,,,,,,,,0,,,,,,,,,,,,,,
,20429129.085,250.01775,60635.65625,0.00141958376320538,5.05057685095552E-5,1,0.999253354069792,40.0298881530762,1.98542152371291,23.7900000065565,0.0127779715090048,0.0213051168132273,0.25,0.00164508639524361,0.00142073711904833,0.00164912901827966,250.0177,250.0177,60608.44140625,60662.87109375,55.7965518452944,19.5215827756517,10.38052,0,0,0,40,4961,250.01775,60635.65625,,,,,,,,,,,,,0,,,,,,,,,,,,,,
,20429204.7,250.0247,56857.009765625,0.00148736445291707,4.55295996673239E-5,1,0.999253354069792,40.0298881530762,1.98530906410157,23.7900000065565,0.0135255552179484,0.0215240832801131,0.25,0.00165287295823917,0.00148862836380426,0.00165698521797505,250.0251,250.0251,56824.6484375,56889.37109375,55.1329492324674,19.5198206229086,10.38052,0,0,0,40,4961,250.0247,56857.009765625,,,,,,,,,,,,,0,,,,,,,,,,,,,,
,20429278.82,250.03195,53154.0859375,0.00154370251504881,6.06454828587687E-5,1,0.999253354069792,40.0298881530762,1.98534104041195,23.7900000065565,0.0141053484138536,0.0219517186473231,0.25,0.00168103609577201,0.00154504026480465,0.00168524447588828,250.033,250.033,53121.48828125,53186.68359375,55.3760357019482,19.5257279487527,10.38052,0,0,0,40,4961,250.03195,53154.0859375,,,,,,,,,,,,,0,,,,,,,,,,,,,,
,20429354.105,250.03615,49388.82421875,0.00157641561886367,3.71859615167939E-5,1,0.999253354069792,40.0298881530762,1.98537206174281,23.7900000065565,0.0145513003801808,0.0215704375631661,0.25,0.00164148608145401,0.0015778410931809,0.00164565279404782,250.0354,250.0354,49363.875,49413.7734375,55.6073977436405,19.5199553943391,10.00087,0,0,0,40,4961,250.03615,49388.82421875,,,,,,,,,,,,,0,,,,,,,,,,,,,,
,20429430.05,250.04315,45595.693359375,0.00163272981518933,3.20710297667886E-5,1,0.999253354069792,40.0298881530762,1.98554327160812,23.7900000065565,0.015238195335462,0.0213863970688113,0.25,0.0016152256206486,0.0016342734734067,0.00161939316211342,250.0432,250.0432,45565.75390625,45625.6328125,55.2243997692174,19.5127440989322,10.38052,0,0,0,40,4961,250.04315,45595.693359375,,,,,,,,,,,,,0,,,,,,,,,,,,,,
,20429505.875,250.05005,41805.0078125,0.00162076295038383,4.31430510357656E-5,1,0.999253354069792,40.0298881530762,1.98584953974067,23.8000005483627,0.0149705505338767,0.0221448151526472,0.25,0.00168433197038126,0.00162222706026872,0.00168861181827335,250.0486,250.0486,41777.5546875,41832.4609375,55.2142385984674,19.5267600001412,10.00087,0,0,0,40,4961,250.05005,41805.0078125,,,,,,,,,,,,,0,,,,,,,,,,,,,,
,20429581.105,250.05425,38046.833984375,0.00168737641415716,3.36179976072076E-5,1,0.999253354069792,40.0298881530762,1.98560796574744,23.7900000065565,0.0157764740123261,0.0219424527566863,0.25,0.00165504542983362,0.00168897941375684,0.00165932950967197,250.053,250.053,38019.3125,38074.35546875,55.3267931052366,19.5237246731024,10.00087,0,0,0,40,4961,250.05425,38046.833984375,,,,,,,,,,,,,0,,,,,,,,,,,,,,
,20429655.635,250.0604,34319.24609375,0.00169153296096696,4.54015884111707E-5,1,0.999253354069792,40.0298881530762,1.98582885218187,23.7900000065565,0.0157270100703731,0.0225177221967929,0.25,0.00170517408019766,0.00169310019354909,0.00170955037285934,250.0602,250.0602,34296.7109375,34341.78125,55.2580097955443,19.5206821307353,10.38052,0,0,0,40,4961,250.0604,34319.24609375,,,,,,,,,,,,,0,,,,,,,,,,,,,,
,20429729.86,250.06655,30608.3193359375,0.001738787231469,4.3676355940323E-5,1,0.999253354069792,40.0298881530762,1.98596979482449,23.7900000065565,0.0163024376376365,0.0223698359975117,0.25,0.00168371871711739,0.00174045294518764,0.00168809707023402,250.0665,250.0665,30578.3359375,30638.302734375,56.465625857756,19.5369826147482,10.38052,0,0,0,40,4961,250.06655,30608.3193359375,,,,,,,,,,,,,0,,,,,,,,,,,,,,
,20429804.24,250.0707,26893.560546875,0.00179465493163922,4.70219205974634E-5,1,0.999253354069792,40.0298881530762,1.98565233951489,23.7900000065565,0.0169909767758204,0.0221201962075278,0.25,0.00165217426818405,0.00179644266407461,0.00165654427178532,250.0693,250.0693,26866.123046875,26920.998046875,55.7355848207944,19.5161358496599,10.760172,0,0,0,40,4961,250.0707,26893.560546875,,,,,,,,,,,,,0,,,,,,,,,,,,,,
,20429878.7,250.0765,23172.6015625,0.0017866958722392,3.31577571476214E-5,1,0.999253354069792,40.0298881530762,1.98568221729231,23.7900000065565,0.0169036812500074,0.0220925564661534,0.25,0.0016510724142212,0.00178846871208678,0.00165543488612714,250.0769,250.0769,23147.833984375,23197.369140625,56.0716850840636,19.5195563472747,10.00087,0,0,0,40,4961,250.0765,23172.6015625,,,,,,,,,,,,,0,,,,,,,,,,,,,,
,20429952.26,250.0815,19496.9208984375,0.00179380470155655,4.20683468236744E-5,1,0.999253354069792,40.0298881530762,1.98591469421275,23.7900000065565,0.0169038388755178,0.0225806674825464,0.25,0.00169293937709788,0.00179555379050167,0.00169738198649963,250.0823,250.0823,19464.474609375,19529.3671875,55.6120875147559,19.5302388748877,10.38052,0,0,0,40,4961,250.0815,19496.9208984375,,,,,,,,,,,,,0,,,,,,,,,,,,,,
,20430027.02,250.0857,15759.3100585938,0.00181014941711311,3.91823809379366E-5,1,0.999253354069792,40.0298881530762,1.9857359376899,23.7900000065565,0.0172389353250074,0.0217317819673423,0.25,0.00161493165302433,0.00181198971055852,0.00161925203961761,250.0856,250.0856,15732.0732421875,15786.546875,55.8004599878905,19.5354316004641,10.760172,0,0,0,40,4961,250.0857,15759.3100585938,,,,,,,,,,,,,0,,,,,,,,,,,,,,
,20430102.85,250.09055,11968.5327148438,0.00183681250313594,4.13836176585433E-5,1,0.999253354069792,40.0298881530762,1.98566496924125,23.7900000065565,0.0175695905059325,0.0216051413087185,0.25,0.00159913216555676,0.00183871088733983,0.00160344777559999,250.0899,250.0899,11938.666015625,11998.3994140625,55.7637234474867,19.5236596871405,10.38052,0,0,0,40,4961,250.09055,11968.5327148438,,,,,,,,,,,,,0,,,,,,,,,,,,,,
,20430176.76,250.0938,8275.3466796875,0.00183553718172537,3.81735256368509E-5,1,0.999253354069792,40.0298881530762,1.98571735768378,23.7900000065565,0.0176051599156383,0.021317701095307,0.25,0.00157379166413684,0.00183745282016578,0.00157806277185572,250.0946,250.0946,8245.5009765625,8305.1923828125,55.8012416164098,19.5233426640052,10.760172,0,0,0,40,4961,250.0938,8275.3466796875,,,,,,,,,,,,,0,,,,,,,,,,,,,,
,20430249.695,250.0976,4627.53686523438,0.00172834122102688,3.33892068501196E-5,1,0.999253354069792,40.0298881530762,1.98544316942844,23.7900000065565,0.0164379265033349,0.0208593966589441,0.25,0.00155194760097298,0.00173008586890264,0.00155609270757882,250.0982,250.0982,4598.03857421875,4657.03515625,55.219709998102,19.5314956953743,10.38052,0,0,0,40,4961,250.0976,4627.53686523438,,,,,,,,,,,,,0,,,,,,,,,,,,,,
,20430322.67,250.0999,980.880157470703,0.00155131021865531,2.88705998104213E-5,1,0.999253354069792,40.0298881530762,1.98565547008472,23.7900000065565,0.0149263418799403,0.0177408555280386,0.25,0.00130565546544014,0.00155294741260987,0.0013092236842506,250.1011,250.1011,948.33935546875,1013.42095947266,55.9098879805828,19.5312223207626,10.00087,0,0,0,40,4961,250.0999,980.880157470703,,,,,,,,,,,,,0,,,,,,,,,,,,,,
,20430395.665,250.10235,-2662.12512207031,-0.00173120384873545,3.1771539331825E-5,1,0.999253354069792,40.0298881530762,1.98542056847103,23.7900000065565,-0.016591355650532,-0.0201649285000866,0.25,-0.00148982268218454,-0.00173300405771642,-0.00149386155054551,250.1019,250.1019,-2689.74291992187,-2634.50732421875,55.148581802852,19.5263430808072,10.38052,0,0,0,40,4961,250.10235,-2662.12512207031,,,,,,,,,,,,,0,,,,,,,,,,,,,,
,20430469.24,250.0997,-6342.2001953125,-0.00179769195759308,3.29870810726972E-5,1,0.999253354069792,40.0298881530762,1.98554053136926,23.7900000065565,-0.0171678898544639,-0.021296221009879,0.25,-0.00157860922319919,-0.0017995364055903,-0.00158285770751488,250.099,250.099,-6374.76611328125,-6309.63427734375,56.2037803038136,19.5268108014898,10.38052,0,0,0,40,4961,250.0997,-6342.2001953125,,,,,,,,,,,,,0,,,,,,,,,,,,,,
,20430544.445,250.1,-10100.9775390625,-0.00181966350680248,3.45439570715518E-5,1,0.999253354069792,40.0298881530762,1.98561065758787,23.7900000065565,-0.0173687369664047,-0.021612474438617,0.25,-0.0016028074608158,-0.00182152764025869,-0.00160711534178983,250.1001,250.1001,-10103.1474609375,-10098.8076171875,55.5941100588136,19.5382764673752,10.00087,0,0,0,40,4961,250.1,-10100.9775390625,,,,,,,,,,,,,0,,,,,,,,,,,,,,
,20430618.935,250.09795,-13821.986328125,-0.00185234105662067,3.06521184867986E-5,1,0.999253354069792,40.0298881530762,1.98557972917664,23.7900000065565,-0.0177387944326859,-0.0216635418153669,0.25,-0.0016017026655174,-0.00185426473503448,-0.00160603450790606,250.0974,250.0974,-13852.123046875,-13791.849609375,55.9958671176982,19.5306069978586,10.760172,0,0,0,40,4961,250.09795,-13821.986328125,,,,,,,,,,,,,0,,,,,,,,,,,,,,
,20430695.895,250.0905,-17672.4208984375,-0.00180175269292904,4.18325043328762E-5,1,0.999253354069792,40.0298881530762,1.98596629374308,23.7900000065565,-0.0171086177561799,-0.0219347017590448,0.25,-0.00163418363998284,-0.00180356285975104,-0.00163852988793894,250.0904,250.0904,-17699.78515625,-17645.056640625,55.5542470043328,19.556218751888,10.760172,0,0,0,40,4961,250.0905,-17672.4208984375,,,,,,,,,,,,,0,,,,,,,,,,,,,,
,20430770.82,250.0851,-21414.3291015625,-0.00178541059067615,2.71210920357128E-5,1,0.999253354069792,40.0298881530762,1.98561004554809,23.7900000065565,-0.0169626545007645,-0.0216622647186999,0.25,-0.0016131697038174,-0.00178721117404879,-0.00161746476460418,250.0843,250.0843,-21442.017578125,-21386.640625,55.9841426899098,19.5460319102647,10.38052,0,0,0,40,4961,250.0851,-21414.3291015625,,,,,,,,,,,,,0,,,,,,,,,,,,,,
,20430847.1,250.07665,-25227.50390625,-0.00180971135503304,3.7786010289416E-5,1,0.999253354069792,40.0298881530762,1.98577653417839,23.7900000065565,-0.0172124097506644,-0.0218580642610833,0.25,-0.00162618018228523,-0.00181154581147237,-0.00163051722132988,250.0766,250.0766,-25255.03515625,-25199.97265625,56.2209761312367,19.5372824361403,10.760172,0,0,0,40,4961,250.07665,-25227.50390625,,,,,,,,,,,,,0,,,,,,,,,,,,,,
,20430922.225,250.06995,-28980.5263671875,-0.00176327924971478,3.05917555670728E-5,1,0.999253354069792,40.0298881530762,1.98583233032211,23.7900000065565,-0.0166480982773472,-0.0220080056776048,0.25,-0.00164748878939962,-0.00176501675484242,-0.00165182410823912,250.07,250.07,-29003.078125,-28957.974609375,56.2131598460444,19.5301548541044,10.00087,0,0,0,40,4961,250.06995,-28980.5263671875,,,,,,,,,,,,,0,,,,,,,,,,,,,,
,20430998.185,250.0604,-32778.2509765625,-0.00174405762156832,3.16528490095332E-5,1,0.999253354069792,40.0298881530762,1.98564458304686,23.7900000065565,-0.0164617587971739,-0.0217857057703498,0.25,-0.00163126742148031,-0.00174577687821988,-0.00163555777891292,250.0601,250.0601,-32810.83984375,-32745.662109375,55.9380266072751,19.5590545299912,10.760172,0,0,0,40,4961,250.0604,-32778.2509765625,,,,,,,,,,,,,0,,,,,,,,,,,,,,
,20431073.465,250.0518,-36538.498046875,-0.00170751301243291,4.63496443056711E-5,1,0.999253354069792,40.0298881530762,1.98585992190356,23.7900000065565,-0.0160177687414239,-0.0219123665294101,0.25,-0.00164864651739881,-0.00170915603336321,-0.00165293657647064,250.0509,250.0509,-36563.4765625,-36513.51953125,55.7668499615636,19.5731160003963,10.38052,0,0,0,40,4961,250.0518,-36538.498046875,,,,,,,,,,,,,0,,,,,,,,,,,,,,
,20431149.14,250.045,-40321.267578125,-0.00164399687058382,3.68111393615532E-5,1,0.999253354069792,40.0298881530762,1.98602681349217,23.7900000065565,-0.0152327779036986,-0.0221970109821715,0.25,-0.00168476654783109,-0.00164550095868844,-0.00168906702314797,250.0445,250.0445,-40351.17578125,-40291.359375,54.9820949282558,19.5719260574237,10.38052,0,0,0,40,4961,250.045,-40321.267578125,,,,,,,,,,,,,0,,,,,,,,,,,,,,
,20431223.855,250.033,-44056.6015625,-0.00160729200505639,5.17222462301121E-5,1,0.999253354069792,40.0298881530762,1.98592868266888,23.7900000065565,-0.0148573457575743,-0.0219002635428413,0.25,-0.00166488894410822,-0.00160875026844557,-0.00166912400129648,250.0324,250.0324,-44059.14453125,-44054.05859375,55.4252782986597,19.5718375670839,10.00087,0,0,0,40,4961,250.033,-44056.6015625,,,,,,,,,,,,,0,,,,,,,,,,,,,,
,20431299.4,250.0246,-47832.173828125,-0.0015679029546554,4.78415866247179E-5,1,0.999253354069792,40.0298881530762,1.98608966382627,23.7900000065565,-0.0144718136030193,-0.0214954109537235,0.25,-0.00163564222919142,-0.00156931812999739,-0.00163979301409596,250.0248,250.0248,-47857.046875,-47807.30078125,55.7543439052559,19.5643048275206,10.38052,0,0,0,40,4961,250.0246,-47832.173828125,,,,,,,,,,,,,0,,,,,,,,,,,,,,
,20431374.665,250.0163,-51592.412109375,-0.00151041414435133,5.47333804719751E-5,1,0.999253354069792,40.0298881530762,1.98648883934855,23.7900000065565,-0.0136997462451755,-0.0221190818919679,0.25,-0.00170058105289025,-0.00151167754365413,-0.00170479813207632,250.0168,250.0168,-51624.84375,-51559.98046875,55.6839973385251,19.5611236557491,10.00087,0,0,0,40,4961,250.0163,-51592.412109375,,,,,,,,,,,,,0,,,,,,,,,,,,,,
,20431451.245,250.00675,-55417.576171875,-0.00151921637582193,4.40831514093579E-5,1,0.999253354069792,40.0298881530762,1.98616060566598,23.7900000065565,-0.0139587434197954,-0.0211989592636191,0.25,-0.00161771413596641,-0.00152056501864878,-0.00162179226043242,250.0068,250.0068,-55422.65625,-55412.49609375,55.7629418189674,19.5368538879373,10.38052,0,0,0,40,4961,250.00675,-55417.576171875,,,,,,,,,,,,,0,,,,,,,,,,,,,,
,20431527.05,249.999,-59207.67578125,-0.00145293350864103,4.8411468225074E-5,1,0.999253354069792,40.0298881530762,1.98624305027291,23.7900000065565,-0.0131594836023935,-0.0213751040257917,0.25,-0.00164476459689797,-0.0014541458433435,-0.00164883544978785,249.9987,249.9987,-59235.34765625,-59180.00390625,56.0677769414675,19.5603037367082,10.38052,0,0,0,40,4961,249.999,-59207.67578125,,,,,,,,,,,,,0,,,,,,,,,,,,,,
,20431603.71,249.9897,-63038.4765625,-0.00143737579960635,4.44861036917141E-5,1,0.999253354069792,40.0298881530762,1.98606856021008,23.7900000065565,-0.0130845117290541,-0.0207580640011634,0.25,-0.00159286424470524,-0.00143860521693781,-0.00159683062310911,249.9904,249.9904,-63068.7421875,-63008.2109375,56.1295255944867,19.5227531593598,10.760172,0,0,0,40,4961,249.9897,-63038.4765625,,,,,,,,,,,,,0,,,,,,,,,,,,,,
,20431678.79,249.9822,-66790.7421875,-0.00134555348806372,6.52690088447086E-5,1,0.999253354069792,40.0298881530762,1.98591387163761,23.7900000065565,-0.0119927149701685,-0.0209012973761904,0.25,-0.00162163661162854,-0.00134660028216046,-0.00162557818903888,249.9823,249.9823,-66821.140625,-66760.34375,56.5226847396598,19.5278570331539,10.760172,0,0,0,40,4961,249.9822,-66790.7421875,,,,,,,,,,,,,0,,,,,,,,,,,,,,
,20431755.5,249.97405,-70626.140625,-0.00130402795939875,4.63006771017551E-5,1,0.999253354069792,40.0298881530762,1.98614514270559,23.7900000065565,-0.0115443416320625,-0.0207174152682437,0.25,-0.00161231403634126,-0.00130501147594129,-0.00161620487725391,249.9742,249.9742,-70628.859375,-70623.421875,55.7473092485828,19.5320587226637,10.38052,0,0,0,40,4961,249.97405,-70626.140625,,,,,,,,,,,,,0,,,,,,,,,,,,,,
,20431830.67,249.964,-74381.42578125,-0.00124409214304042,8.35083030766185E-5,1,0.999253354069792,40.0298881530762,1.98580701528326,23.7900000065565,-0.0108049549239063,-0.0209557938872273,0.25,-0.00164416355830419,-0.00124494666564963,-0.00164806131522812,249.965,249.965,-74411.0703125,-74351.78125,56.0036834028905,19.5384648881563,10.38052,0,0,0,40,4961,249.964,-74381.42578125,,,,,,,,,,,,,0,,,,,,,,,,,,,,
,20431906.095,249.9546,-78151.0546875,-0.00120982216199657,7.74978718622851E-5,1,0.999253354069792,40.0298881530762,1.9856941234156,23.7900000065565,-0.0105057812716309,-0.0203831569771636,0.25,-0.00159938108943429,-0.00121065482852206,-0.00160317190039243,249.9543,249.9543,-78178.5703125,-78123.5390625,55.8911288961213,19.5503665113894,10.760172,0,0,0,40,4961,249.9546,-78151.0546875,,,,,,,,,,,,,0,,,,,,,,,,,,,,
,20431983.045,249.94535,-81996.3984375,-0.00114970857651143,6.74984042059484E-5,1,0.999253354069792,40.0298881530762,1.98599689825484,23.7900000065565,-0.00987806171050093,-0.0199912981684393,0.25,-0.00157476630021859,-0.00115045756517951,-0.00157846473240146,249.9445,249.9445,-82021.5703125,-81971.2265625,55.8887840105636,19.5396282439826,10.00087,0,0,0,40,4961,249.94535,-81996.3984375,,,,,,,,,,,,,0,,,,,,,,,,,,,,
,20432057.835,249.9366,-85736.87109375,-0.00111398974746256,7.4890759279406E-5,1,0.999253354069792,40.0298881530762,1.98573077726555,23.7900000065565,-0.00955640098469378,-0.01944598824033,0.25,-0.00153278751356404,-0.00111471182900541,-0.00153638280651348,249.9368,249.9368,-85764.6796875,-85709.0625,55.6988482803905,19.5441546062372,10.760172,0,0,0,40,4961,249.9366,-85736.87109375,,,,,,,,,,,,,0,,,,,,,,,,,,,,
,20432131.695,249.92745,-89424.03125,-0.00109281104518207,9.2621091510133E-5,1,0.999253354069792,40.0298881530762,1.98594423447743,23.7900000065565,-0.00931989595815633,-0.0194000813624449,0.25,-0.00153220879022577,-0.00109349830840805,-0.00153578556896115,249.9273,249.9273,-89451.5546875,-89396.5078125,55.5386144339482,19.5606531164954,10.38052,0,0,0,40,4961,249.92745,-89424.03125,,,,,,,,,,,,,0,,,,,,,,,,,,,,
,20432219.14,249.9193,-86931.859375,-0.00108971080005629,9.27937240158084E-5,1,0.999253354069792,40.0298881530762,1.98582854108502,23.7900000065565,-0.00916798568353629,-0.0200644903936562,0.25,-0.00159180914882308,-0.00109034365220036,-0.00159548940131183,249.9191,249.9191,-86959.0625,-86904.65625,55.4776474094482,19.5470111028607,10.00087,0,0,0,40,4961,249.9193,-86931.859375,,,,,,,,,,,,,0,,,,,,,,,,,,,,
,20432292.115,249.9186,-83286.70703125,-0.00114066559288079,7.89164465991853E-5,1,0.999253354069792,40.0298881530762,1.98572276208924,23.7900000065565,-0.00984310738758319,-0.0195776140496321,0.25,-0.00153984949222938,-0.0011414284040124,-0.00154348044409933,249.9175,249.9175,-83312.0703125,-83261.34375,56.3905895199098,19.5473483125199,10.38052,0,0,0,40,4961,249.9186,-83286.70703125,,,,,,,,,,,,,0,,,,,,,,,,,,,,
,20432368.78,249.92335,-79456.12890625,-0.001163141945209,0.000101491372533477,1,0.999253354069792,40.0298881530762,1.98547159908352,23.7900000065565,-0.0100360372313351,-0.019959758311943,0.25,-0.00157008352861445,-0.00116391794754196,-0.00157378657962731,249.923,249.923,-79483.8671875,-79428.390625,55.9989936317752,19.5480836714476,10.38052,0,0,0,40,4961,249.92335,-79456.12890625,,,,,,,,,,,,,0,,,,,,,,,,,,,,
,20432444.14,249.9271,-75688.46484375,-0.00127287331352514,4.61265348097777E-5,1,0.999253354069792,40.0298881530762,1.98531919842178,23.7900000065565,-0.0112797562038174,-0.0201241761099606,0.25,-0.00156578058607399,-0.0012738439620576,-0.00156956572832969,249.9277,249.9277,-75716.140625,-75660.7890625,55.822345586429,19.5557861133902,10.38052,0,0,0,40,4961,249.9271,-75688.46484375,,,,,,,,,,,,,0,,,,,,,,,,,,,,
,20432520.915,249.9346,-71850.83203125,-0.00129232499006524,5.52685576473388E-5,1,0.999253354069792,40.0298881530762,1.98537929988356,23.7900000065565,-0.0114040839429622,-0.0207111361950766,0.25,-0.00161446095234538,-0.0012932883283545,-0.001618348152933,249.9346,249.9346,-71853.4609375,-71848.203125,55.8895656390828,19.5523333430361,10.760172,0,0,0,40,4961,249.9346,-71850.83203125,,,,,,,,,,,,,0,,,,,,,,,,,,,,
,20432594.82,249.94095,-68160.7109375,-0.00134809167595359,4.70602088441605E-5,1,0.999253354069792,40.0298881530762,1.98537085735557,23.7900000065565,-0.0120822441702573,-0.020531490083218,0.25,-0.00158884990778992,-0.00134917189427884,-0.00159273805182357,249.9404,249.9404,-68190.640625,-68130.78125,55.8559556127559,19.5506912378036,10.760172,0,0,0,40,4961,249.94095,-68160.7109375,,,,,,,,,,,,,0,,,,,,,,,,,,,,
,20432670.995,249.9484,-64353.03125,-0.00139469478399014,4.3824260649032E-5,1,0.999253354069792,40.0298881530762,1.98543367336785,23.7900000065565,-0.0125281990980789,-0.0210808828089177,0.25,-0.00162948223098998,-0.00139582184948498,-0.00163348040012854,249.9485,249.9485,-64378.140625,-64327.921875,55.6347547418136,19.5521155888696,10.760172,0,0,0,40,4961,249.9484,-64353.03125,,,,,,,,,,,,,0,,,,,,,,,,,,,,
,20432746.32,249.95415,-60587.361328125,-0.00140314615219008,5.68204337959164E-5,1,0.999253354069792,40.0298881530762,1.98521191151699,23.7900000065565,-0.0126232639026937,-0.0210880553019182,0.25,-0.00162885260328833,-0.00140428659174103,-0.00163285737096741,249.9547,249.9547,-60619.7109375,-60555.01171875,56.3178980676213,19.5584268194134,10.760172,0,0,0,40,4961,249.95415,-60587.361328125,,,,,,,,,,,,,0,,,,,,,,,,,,,,
,20432821.345,249.9626,-56837.1015625,-0.00146598056023134,5.68675715422376E-5,1,0.999253354069792,40.0298881530762,1.98506685367921,23.7900000065565,-0.0133672984181357,-0.0209946363969783,0.25,-0.00160979237366989,-0.00146724485306717,-0.00161381549519774,249.9625,249.9625,-56867.11328125,-56807.08984375,56.1006053392752,19.5578037214771,10.38052,0,0,0,40,4961,249.9626,-56837.1015625,,,,,,,,,,,,,0,,,,,,,,,,,,,,
,20432896.975,249.9708,-53059.505859375,-0.00150692301324032,5.27984477519161E-5,1,0.999253354069792,40.0298881530762,1.98620971325958,23.7900000065565,-0.0137263658035408,-0.0217185060299009,0.25,-0.00166590118003647,-0.00150821138611232,-0.00167005699394765,249.9702,249.9702,-53089.5703125,-53029.44140625,55.2619179381405,19.5674973565111,11.139823,0,0,0,40,4961,249.9708,-53059.505859375,,,,,,,,,,,,,0,,,,,,,,,,,,,,
,20432974.19,249.9777,-49199.67578125,-0.0015437638067913,5.82862463759155E-5,1,0.999253354069792,40.0298881530762,1.98634264426287,23.7900000065565,-0.0141564802139677,-0.0217107940354618,0.25,-0.00165870443253146,-0.00154512066365972,-0.00166287852956134,249.9777,249.9777,-49201.984375,-49197.3671875,55.5151655783713,19.5673095323639,10.760172,0,0,0,40,4961,249.9777,-49199.67578125,,,,,,,,,,,,,0,,,,,,,,,,,,,,
,20433048.24,249.9855,-45499.359375,-0.00157440763340403,5.12494769785628E-5,1,0.999253354069792,40.0298881530762,1.98622952470634,23.7900000065565,-0.014516277513683,-0.021681544073732,0.25,-0.0016508991427653,-0.00157582262838823,-0.00165508533127091,249.9852,249.9852,-45529.2578125,-45469.4609375,56.2514596434867,19.5612598273813,10.760172,0,0,0,40,4961,249.9855,-45499.359375,,,,,,,,,,,,,0,,,,,,,,,,,,,,
,20433123.97,249.9928,-41713.72265625,-0.001632736427245,3.29061212089982E-5,1,0.999253354069792,40.0298881530762,1.986365477183,23.8000005483627,-0.015207956018293,-0.0216044827477246,0.25,-0.00163381998327712,-0.00163426575767303,-0.00163802474356683,249.9926,249.9926,-41741.3515625,-41686.09375,55.5917651732559,19.5538911212013,10.38052,0,0,0,40,4961,249.9928,-41713.72265625,,,,,,,,,,,,,0,,,,,,,,,,,,,,
,20433198.48,249.9987,-37988.009765625,-0.00168018128465028,4.24671146690441E-5,1,0.999253354069792,40.0298881530762,1.98636194729809,23.7900000065565,-0.0157355711585827,-0.0217378038563963,0.25,-0.00163742441260437,-0.00168178901426393,-0.00164167529620652,249.9992,249.9992,-38013.00390625,-37963.015625,55.8567372412751,19.5694508383685,10.760172,0,0,0,40,4961,249.9987,-37988.009765625,,,,,,,,,,,,,0,,,,,,,,,,,,,,
,20433272.875,250.00545,-34273.2578125,-0.00170490031392985,4.81733189074148E-5,1,0.999253354069792,40.0298881530762,1.98619555508048,23.7900000065565,-0.0158901744473897,-0.0224917831290377,0.25,-0.00170019755235928,-0.00170649798076442,-0.00170457975973574,250.0049,250.0049,-34300.78125,-34245.734375,55.8872207535252,19.5496965848647,10.760172,0,0,0,40,4961,250.00545,-34273.2578125,,,,,,,,,,,,,0,,,,,,,,,,,,,,
,20433348.605,250.0129,-30485.27734375,-0.00169499235711967,4.9937933012802E-5,1,0.999253354069792,40.0298881530762,1.98632218243103,23.7900000065565,-0.0158318382479586,-0.0221717388159531,0.25,-0.00167339562599412,-0.00169659258543093,-0.001677723504511,250.0129,250.0129,-30487.7734375,-30482.78125,55.568316317679,19.5648480050075,10.38052,0,0,0,40,4961,250.0129,-30485.27734375,,,,,,,,,,,,,0,,,,,,,,,,,,,,
,20433423.85,250.01735,-26727.650390625,-0.00175906493156963,3.6394245659139E-5,1,0.999253354069792,40.0298881530762,1.98630564964525,23.7900000065565,-0.0166122925630608,-0.0219593655757793,0.25,-0.00164345455384876,-0.00176080035378124,-0.00164778355438846,250.0175,250.0175,-26760.140625,-26695.16015625,55.5769142313905,19.5594596332793,10.760172,0,0,0,40,4961,250.01735,-26727.650390625,,,,,,,,,,,,,0,,,,,,,,,,,,,,
,20433498.885,250.0247,-22977.35546875,-0.0017559058954085,4.11925189421559E-5,1,0.999253354069792,40.0298881530762,1.98633544217841,23.7900000065565,-0.0165658595670424,-0.0220172024016806,0.25,-0.00164910594460975,-0.00175762919531633,-0.00165344308652583,250.0246,250.0246,-23006.9453125,-22947.765625,56.1842395908329,19.5621247542804,10.760172,0,0,0,40,4961,250.0247,-22977.35546875,,,,,,,,,,,,,0,,,,,,,,,,,,,,
,20433574.135,250.0303,-19217.052734375,-0.00183047467954122,3.74178751316635E-5,1,0.999253354069792,40.0298881530762,1.98600209203905,23.7900000065565,-0.0174059552006364,-0.0221448611530677,0.25,-0.00164781575517493,-0.00183232802237283,-0.00165221293795284,250.0289,250.0289,-19244.505859375,-19189.599609375,55.3088156492943,19.5466713393235,10.38052,0,0,0,40,4961,250.0303,-19217.052734375,,,,,,,,,,,,,0,,,,,,,,,,,,,,
,20433647.645,250.03515,-15542.2407226562,-0.001822986967584,3.23952767274798E-5,1,0.999253354069792,40.0298881530762,1.98611411393746,23.7900000065565,-0.0174331121223134,-0.0214935869339998,0.25,-0.00159121305295794,-0.0018248721457083,-0.0015955057415671,250.0347,250.0347,-15572.0185546875,-15512.462890625,55.4096457282751,19.5542715043073,10.760172,0,0,0,40,4961,250.03515,-15542.2407226562,,,,,,,,,,,,,0,,,,,,,,,,,,,,
,20433723.31,250.0406,-11760.9150390625,-0.00180419324679828,2.96842548708038E-5,1,0.999253354069792,40.0298881530762,1.98586477818791,23.7900000065565,-0.0171957780833491,-0.0215896090753327,0.25,-0.00160322261885982,-0.00180603391572109,-0.00160752173897552,250.0409,250.0409,-11793.0654296875,-11728.7646484375,55.3221033341212,19.5447438760986,10.760172,0,0,0,40,4961,250.0406,-11760.9150390625,,,,,,,,,,,,,0,,,,,,,,,,,,,,
,20433798.57,250.04565,-7997.330078125,-0.00179314488253965,3.74842003084027E-5,1,0.999253354069792,40.0298881530762,1.98568876033611,23.7900000065565,-0.0171542718720541,-0.0210792814344639,0.25,-0.00156000407864833,-0.00179500031967525,-0.00156421912386177,250.0463,250.0463,-8029.857421875,-7964.802734375,55.9388082357944,19.5429808076095,10.760172,0,0,0,40,4961,250.04565,-7997.330078125,,,,,,,,,,,,,0,,,,,,,,,,,,,,
,20433871.94,250.05055,-4331.263671875,-0.00176356147453135,3.3830702308497E-5,1,0.999253354069792,40.0298881530762,1.9857255925979,23.7900000065565,-0.016885625737554,-0.0206506787913396,0.25,-0.0015270592235825,-0.00176539091289128,-0.00153119277666595,250.0512,250.0512,-4361.0078125,-4301.51953125,55.9231756654098,19.5431985059545,10.00087,0,0,0,40,4961,250.05055,-4331.263671875,,,,,,,,,,,,,0,,,,,,,,,,,,,,
,20433945.96,250.05235,-632.048797607422,-0.00140643478147229,2.04948827887215E-5,1,0.999253354069792,40.0298881530762,1.98579779949157,23.8000005483627,-0.0136079122204024,-0.0156551336400975,0.25,-0.00114555249724978,-0.00140795271536608,-0.00114872288860733,250.0532,250.0532,-651.762756347656,-612.334838867187,55.5597184039674,19.5453660460298,10.760172,0,0,0,40,4961,250.05235,-632.048797607422,,,,,,,,,,,,,0,,,,,,,,,,,,,,
,20434017.7,250.05415,2950.50744628906,0.00175943572706046,2.93633649178787E-5,1,0.999253354069792,40.0298881530762,1.98597130888512,23.7900000065565,0.0169421766899754,0.0200623860262633,0.25,0.00147534875928218,0.00176130010348835,0.00147938839012222,250.0561,250.0561,2920.52368164063,2980.4912109375,55.565189803602,19.5514574098701,10.38052,0,0,0,40,4961,250.05415,2950.50744628906,,,,,,,,,,,,,0,,,,,,,,,,,,,,
,20434090.925,250.054,6613.3515625,0.00181888854233844,3.20316248148698E-5,1,0.999253354069792,40.0298881530762,1.98610313772651,23.7900000065565,0.0174987557053726,0.0208398446265245,0.25,0.00153391889967145,0.00182080973910926,0.00153810935665372,250.054,250.054,6611.0615234375,6615.6416015625,56.0537076281213,19.5617834555102,10.760172,0,0,0,40,4961,250.054,6613.3515625,,,,,,,,,,,,,0,,,,,,,,,,,,,,
,20434164.875,250.0536,10306.5463867187,0.00181409056076535,3.59922538278415E-5,1,0.999253354069792,40.0298881530762,1.98597408580302,23.7900000065565,0.0173842776454797,0.0211713524658086,0.25,0.00156428698621153,0.00181597946329914,0.0015685256469132,250.0532,250.0532,10278.9189453125,10334.173828125,55.6206854284674,19.5696800505312,11.139823,0,0,0,40,4961,250.0536,10306.5463867187,,,,,,,,,,,,,0,,,,,,,,,,,,,,
,20434239.39,250.04985,14032.6977539062,0.00183639000005492,3.83182800327182E-5,1,0.999253354069792,40.0298881530762,1.98590717572004,23.7900000065565,0.0175147663701605,0.0219075199661431,0.25,0.00162581566779518,0.00183826875100481,0.00163017962880378,250.0494,250.0494,14002.6484375,14062.7470703125,55.8723698116598,19.5594416243805,10.00087,0,0,0,40,4961,250.04985,14032.6977539062,,,,,,,,,,,,,0,,,,,,,,,,,,,,
,20434314.005,250.0447,17762.9287109375,0.00176619436375067,4.24810374593921E-5,1,0.999253354069792,40.0298881530762,1.98616353124967,23.7900000065565,0.0166831941151612,0.0220193462039933,0.25,0.00164767352706432,0.00176793372719792,0.00165201707202488,250.0448,250.0448,17735.5,17790.357421875,55.5831672595443,19.5647245414009,10.760172,0,0,0,40,4961,250.0447,17762.9287109375,,,,,,,,,,,,,0,,,,,,,,,,,,,,
,20434389.03,250.04025,21510.67578125,0.00182077317606321,3.35185532347322E-5,1,0.999253354069792,40.0298881530762,1.98601917855939,23.7900000065565,0.0174234233833222,0.0213958452384124,0.25,0.0015830119989234,0.00182266316140535,0.0015872861137374,250.0403,250.0403,21508.1484375,21513.203125,55.7574704193328,19.5630401447869,10.760172,0,0,0,40,4961,250.04025,21510.67578125,,,,,,,,,,,,,0,,,,,,,,,,,,,,
,20434462.24,250.033,25171.5078125,0.00175172824137061,4.5097968381443E-5,1,0.999253354069792,40.0298881530762,1.98623308444621,23.7900000065565,0.0165218618163753,0.021985510199425,0.25,0.00164711558393105,0.00175344627911421,0.00165144450361789,250.0337,250.0337,25146.640625,25196.375,55.8074946445636,19.5630790676009,10.760172,0,0,0,40,4961,250.033,25171.5078125,,,,,,,,,,,,,0,,,,,,,,,,,,,,
,20434537.905,250.026,28952.501953125,0.001728303178719,3.79520846215793E-5,1,0.999253354069792,40.0298881530762,1.98615804783441,23.7900000065565,0.0162324246351559,0.0220824419897716,0.25,0.00165985055400507,0.00172997161549136,0.00166418169867753,250.026,250.026,28950.0390625,28954.96484375,55.7082278226213,19.5637351480028,10.760172,0,0,0,40,4961,250.026,28952.501953125,,,,,,,,,,,,,0,,,,,,,,,,,,,,
,20434613.18,250.01745,32715.51171875,0.0017060279894784,4.06722611385169E-5,1,0.999253354069792,40.0298881530762,1.98603458591635,23.7900000065565,0.0160423764788321,0.0216806891609888,0.25,0.00162817702988151,0.00170768539861611,0.00163243354930584,250.0162,250.0162,32682.875,32748.1484375,55.5198553494866,19.5368922711408,11.139823,0,0,0,40,4961,250.01745,32715.51171875,,,,,,,,,,,,,0,,,,,,,,,,,,,,
,20434689.065,250.0097,36506.14453125,0.00166356463250905,4.87095492759465E-5,1,0.999253354069792,40.0298881530762,1.98611555533626,23.7900000065565,0.0155593439113226,0.0216283665098769,0.25,0.00163082343819495,0.0016651473867887,0.00163504893816381,250.0103,250.0103,36501.16015625,36511.12890625,55.3025626211405,19.5507715471809,10.760172,0,0,0,40,4961,250.0097,36506.14453125,,,,,,,,,,,,,0,,,,,,,,,,,,,,
,20434764.45,250.00175,40274.201171875,0.00163179548019487,4.9266208495713E-5,1,0.999253354069792,40.0298881530762,1.98625216802696,23.7900000065565,0.0151320636867782,0.021973094245974,0.25,0.00166679656476763,0.00163329506802871,0.00167105837120602,250.0018,250.0018,40244.421875,40303.98046875,55.4510720397943,19.5549936481372,10.760172,0,0,0,40,4961,250.00175,40274.201171875,,,,,,,,,,,,,0,,,,,,,,,,,,,,
,20434839.15,249.99585,44009.29296875,0.0015956960550655,6.05536022595382E-5,1,0.999253354069792,40.0298881530762,1.98617900180784,23.7900000065565,0.0147028088736244,0.0220282664246939,0.25,0.00167802189600924,0.00159712506431369,0.00168227295614315,249.9953,249.9953,43981.9453125,44036.640625,55.2775505085251,19.5402926645802,10.00087,0,0,0,40,4961,249.99585,44009.29296875,,,,,,,,,,,,,0,,,,,,,,,,,,,,
,20434913.89,249.98825,47745.515625,0.00156935497349984,5.06881468246042E-5,1,0.999253354069792,40.0298881530762,1.98631869399446,23.7900000065565,0.0143963447169056,0.0220394750486321,0.25,0.0016834535836658,0.00157073537873687,0.00168769185956856,249.9895,249.9895,47720.55859375,47770.47265625,55.575350974352,19.56070352659,11.139823,0,0,0,40,4961,249.98825,47745.515625,,,,,,,,,,,,,0,,,,,,,,,,,,,,
,20434989.425,249.9791,51518.376953125,0.00152583952143325,5.53562062122281E-5,1,0.999253354069792,40.0298881530762,1.98605419181685,23.7900000065565,0.0139475175372695,0.02170177026968,0.25,0.00166127992629838,0.00152716379035728,0.00166544303865215,249.9793,249.9793,51493.3984375,51543.35546875,55.6034896010443,19.5490955609999,10.760172,0,0,0,40,4961,249.9791,51518.376953125,,,,,,,,,,,,,0,,,,,,,,,,,,,,
,20435065.86,249.9729,55338.6875,0.00149709225208758,4.59216808638025E-5,1,0.999253354069792,40.0298881530762,1.98611990721759,23.7900000065565,0.0137133739729326,0.0211310987454053,0.25,0.00161556321374926,0.00149840534941613,0.00161962168278406,249.9725,249.9725,55305.99609375,55371.37890625,55.3463338182174,19.5390056363123,10.38052,0,0,0,40,4961,249.9729,55338.6875,,,,,,,,,,,,,0,,,,,,,,,,,,,,
,20435141.04,249.96325,59097.068359375,0.00146026191440563,4.96526241754811E-5,1,0.999253354069792,40.0298881530762,1.98588004668768,23.8000005483627,0.013254336640462,0.0213017369913743,0.25,0.00163731095479623,0.00146149475074694,0.00164137698796405,249.9629,249.9629,59069.6796875,59124.45703125,55.1712490299097,19.5507336452838,10.760172,0,0,0,40,4961,249.96325,59097.068359375,,,,,,,,,,,,,0,,,,,,,,,,,,,,
,20435216.495,249.9569,62868.345703125,0.0013847738724159,5.11694720685363E-5,1,0.999253354069792,40.0298881530762,1.98574461246606,23.7900000065565,0.0123757271395619,0.0213100597371441,0.25,0.00165126389785861,0.0013858647322346,0.00165529221612269,249.9539,249.9539,62843.29296875,62893.3984375,55.7871723030636,19.5453305173501,10.38052,0,0,0,40,4961,249.9569,62868.345703125,,,,,,,,,,,,,0,,,,,,,,,,,,,,
,20435292.19,249.9472,66651.08203125,0.00131417762168018,6.6608131087849E-5,1,0.999253354069792,40.0298881530762,1.9862872198772,23.7900000065565,0.0116175860269787,0.0209804009770137,0.25,0.0016337611877956,0.00131516078881588,0.00163770081883519,249.9473,249.9473,66626.28125,66675.8828125,55.5644081750828,19.5496206628801,10.38052,0,0,0,40,4961,249.9472,66651.08203125,,,,,,,,,,,,,0,,,,,,,,,,,,,,
,20435369.21,249.93995,70501.7734375,0.00130371016997416,6.22162694176105E-5,1,0.999253354069792,40.0298881530762,1.98619494379262,23.7900000065565,0.0115331566463958,0.020762819883395,0.25,0.00161635181647808,0.00130469115348865,0.00162025164645017,249.9397,249.9397,70474.3203125,70529.2265625,55.4924983513136,19.548146469404,11.139823,0,0,0,40,4961,249.93995,70501.7734375,,,,,,,,,,,,,0,,,,,,,,,,,,,,
,20435445.79,249.9313,74330.33203125,0.00128347010357584,4.18384625666646E-5,1,0.999253354069792,40.0298881530762,1.98672917893867,23.7900000065565,0.0114408445915059,0.0199624878618538,0.25,0.00154838795474442,0.00128447270008302,0.00155215124172705,249.9308,249.9308,74308.1484375,74352.515625,55.3494603322943,19.5532850162797,10.760172,0,0,0,40,4961,249.9313,74330.33203125,,,,,,,,,,,,,0,,,,,,,,,,,,,,
,20435521.665,249.92365,78121.15234375,0.00118351008383394,7.20243836211579E-5,1,0.999253354069792,40.0298881530762,1.98648081730164,23.7900000065565,0.0102572450704844,0.0200855106916918,0.25,0.00157684886166373,0.00118431581994434,0.00158058063706099,249.9237,249.9237,78091.2265625,78151.078125,55.3221033341212,19.5572577676189,10.38052,0,0,0,40,4961,249.92365,78121.15234375,,,,,,,,,,,,,0,,,,,,,,,,,,,,
,20435598.625,249.9132,81967.66796875,0.00114632396446567,9.1616458938938E-5,1,0.999253354069792,40.0298881530762,1.98628123702711,23.7900000065565,0.0098407278181167,0.0199906104855228,0.25,0.00157504750698611,0.0011470678699397,0.0015787456325131,249.9133,249.9133,81965.3359375,81970,55.5722244602751,19.5551866201128,10.760172,0,0,0,40,4961,249.9132,81967.66796875,,,,,,,,,,,,,0,,,,,,,,,,,,,,
,20435672.86,249.906,85681.3125,0.00111020785390546,7.87846049834551E-5,1,0.999253354069792,40.0298881530762,1.98638894972271,23.7900000065565,0.00949325684947166,0.0195806060663128,0.25,0.00154483956659316,0.00111091454996699,0.00154845481619383,249.9058,249.9058,85678.96875,85683.65625,54.9883479564097,19.5571737348619,10.760172,0,0,0,40,4961,249.906,85681.3125,,,,,,,,,,,,,0,,,,,,,,,,,,,,
,20435746.35,249.89835,89354.328125,0.00104369650917189,0.000132450061277187,1,0.999253354069792,40.0298881530762,1.98646205599559,23.7900000065565,0.00874397576245631,0.0194513320999762,0.25,0.00154484224437737,0.00104428804819628,0.0015484033682409,249.8988,249.8988,89321.8046875,89386.8515625,55.3541501034097,19.5640327280515,10.760172,0,0,0,40,4961,249.89835,89354.328125,,,,,,,,,,,,,0,,,,,,,,,,,,,,
,20435759.58,249.89685,89997.44921875,0.00103882939042294,0.000102373676770021,1,0.999253354069792,40.0298881530762,1.98631838048965,23.7900000065565,0.00870482197929479,0.0193464856969059,0.25,0.00153650229574546,0.00103941942446829,0.00154004474695895,249.8964,249.8964,89995.2578125,89999.640625,55.2759872514866,19.5590244561504,10.760172,0,0,0,40,4929,249.89685,89997.44921875,,,,,,,,,,,,,0,,,,,,,,,,,,,,