File: data/monolayers/nanoparticles/Ac_CoFe_C/vsm/data_dispersion/AH11_HYST_100OE_300K.DAT
[Header]
; VSM Data File (default extension .dat)
; Copyright (c) 2003-2013, Quantum Design, Inc. All rights reserved.
TITLE,
FILEOPENTIME,20436881.20,08/25/2018,9:53 pm
BYAPP,VSM,2.0,2.0
INFO,PPMS VSM Option Release 1.4.10 Build 1,APPNAME
INFO,Quantum Design Linear Motor Servo Controller,MOTOR_MODULE_NAME
INFO,3101-100 M1,MOTOR_HW_VERSION
INFO,MMC1014,MOTOR_SERIAL_NUMBER
INFO,SRV No X-over 01.03.11,MOTOR_SOFTWARE_VERSION
INFO,Quantum Design VSM Detection Module,VSM_MODULE_NAME
INFO,3101-150 F0,VSM_HW_VERSION
INFO,VSM707,VSM_SERIAL_NUMBER
INFO,VSM No X-over 01.02.05 May 20 2008 13:51:47,VSM_SOFTWARE_VERSION
INFO,704,PREAMP_SERIAL_NUMBER
INFO,822,COIL_SERIAL_NUMBER
INFO,0,MOMENT_UNITS
INFO,CoFe2O4,SAMPLE_MATERIAL
INFO,Cobalt deficient,SAMPLE_COMMENT
INFO,,SAMPLE_MASS
INFO,27,SAMPLE_VOLUME
INFO,,SAMPLE_MOLECULAR_WEIGHT
INFO,,SAMPLE_SIZE
INFO,,SAMPLE_SHAPE
DATATYPE,COMMENT,1
DATATYPE,TIME,2
STARTUPAXIS,X,2
STARTUPAXIS,Y1,5
[Data]
Comment,Time Stamp (sec),Temperature (K),Magnetic Field (Oe),Moment (emu),M. Std. Err. (emu),Transport Action,Averaging Time (sec),Frequency (Hz),Peak Amplitude (mm),Center Position (mm),Coil Signal' (mV),Coil Signal" (mV),Range (mV),M. Quad. Signal (emu),M. Raw' (emu),M. Raw" (emu),Min. Temperature (K),Max. Temperature (K),Min. Field (Oe),Max. Field (Oe),Mass (grams),Motor Lag (deg),Pressure (Torr),VSM Status (code),Motor Status (code),Measure Status (code),Measure Count,PPMS Status (code),System Temp. (K),System Field (Oe),Sample Position (deg),Bridge 1 Resistance (ohms),Bridge 1 Excitation (에),Bridge 2 Resistance (ohms),Bridge 2 Excitation (에),Bridge 3 Resistance (ohms),Bridge 3 Excitation (에),Bridge 4 Resistance (ohms),Bridge 4 Excitation (에),Signal 1 Vin (V),Signal 2 Vin (V),Digital Inputs (code),Drive 1 Iout (mA),Drive 1 Ipower (W),Drive 2 Iout (mA),Drive 2 Ipower (W),Pressure (),Map 20 (),Map 21 (),Map 22 (),Map 23 (),Map 24 (),Map 25 (),Map 26 (),Map 27 (),Map 28 (),Map 29 ()
,20436897.5,300.2171631,7230.34326171875,,,2,,,,23.900000795126,,,,,,,300.2171631,300.2171631,7230.34326171875,7230.34326171875,,,11.519473,,,,-99999999,4961,300.8291,7230.34326171875,,,,,,,,,,,,,,,,,,,,,,,300.2171631,,,,
,20437031.885,300.7368,3413.91040039063,0.00190071148897101,3.47743415848454E-5,1,0.999253354069792,40.0298881530762,1.99885492692216,23.8799992948771,0.0188851142164316,0.0188855726224833,0.25,0.00133937906257004,0.0018997182967922,0.00134056178974419,300.737,300.737,3388.83569335937,3438.98510742188,54.3982184243904,19.5295448790313,10.760172,0,0,0,40,4961,300.7368,3413.91040039063,,,,,,,,,,,,,0,,,,,,,,,,,,,,
,20437104.47,300.70975,7038.2001953125,0.0019730877539622,4.02915692680434E-5,1,0.999253354069792,40.0298881530762,1.99912715351807,23.8899998366833,0.0194991466625131,0.0202286408614243,0.25,0.00144527668135318,0.00197202280042604,0.00144650222822662,300.7104,300.7104,7013.14208984375,7063.25830078125,54.6499028075827,19.5306509429692,11.139823,0,0,0,40,4961,300.70975,7038.2001953125,,,,,,,,,,,,,0,,,,,,,,,,,,,,
,20437178.415,300.69045,10733.8662109375,0.0019692454690614,3.7027631442658E-5,1,0.999253354069792,40.0298881530762,1.99908064507405,23.8799992948771,0.0194011242693096,0.0205330361374934,0.25,0.00147287423062126,0.00196816443128172,0.00147409607066008,300.6908,300.6908,10706.4267578125,10761.3056640625,54.6084764960635,19.5347110170949,10.760172,0,0,0,40,4961,300.69045,10733.8662109375,,,,,,,,,,,,,0,,,,,,,,,,,,,,
,20437250.09,300.6727,14317.4716796875,0.00195929039058221,3.54429423499988E-5,1,0.999253354069792,40.0298881530762,1.99914946336743,23.8899998366833,0.0192914851329681,0.0205004211721693,0.25,0.00147165748179535,0.00195821257581603,0.00147287304798056,300.6723,300.6723,14289.953125,14344.990234375,54.7225942598712,19.5301540625994,11.139823,0,0,0,40,4961,300.6727,14317.4716796875,,,,,,,,,,,,,0,,,,,,,,,,,,,,
,20437323.57,300.6593,17987.7265625,0.00196895226168872,4.71728123115081E-5,1,0.999253354069792,40.0298881530762,1.9990891824537,23.8899998366833,0.0193240830905115,0.0209587480663935,0.25,0.00151052763303109,0.00196784990692839,0.00151174744122052,300.6595,300.6595,17962.65234375,18012.80078125,54.8937709055827,19.5306182659229,11.139823,0,0,0,40,4961,300.6593,17987.7265625,,,,,,,,,,,,,0,,,,,,,,,,,,,,
,20437395.805,300.6432,21597.9287109375,0.00195611924744369,4.70292326189661E-5,1,0.999253354069792,40.0298881530762,1.99911897181709,23.8899998366833,0.0191433985565289,0.0211400677278704,0.25,0.001528743276437,0.00195500740871987,0.00152995374392902,300.6454,300.6454,21570.5625,21625.294921875,54.9281625604289,19.5333315876092,11.139823,0,0,0,40,4961,300.6432,21597.9287109375,,,,,,,,,,,,,0,,,,,,,,,,,,,,
,20437471.775,300.6254,25393.841796875,0.00190000661032258,3.94854793112231E-5,1,0.999253354069792,40.0298881530762,1.99890290555959,23.8899998366833,0.0185509853947854,0.0207703514965446,0.25,0.00150599076682818,0.00189891473482193,0.00150716554206352,300.6258,300.6258,25364.037109375,25423.646484375,54.9805316712174,19.5393992632305,10.760172,0,0,0,40,4961,300.6254,25393.841796875,,,,,,,,,,,,,0,,,,,,,,,,,,,,
,20437547.48,300.6085,29179.6689453125,0.00188746344623236,4.74198025711965E-5,1,0.999253354069792,40.0298881530762,1.99888589371225,23.8899998366833,0.0183639731782071,0.0210048763637363,0.25,0.00152890019475673,0.00188635907658736,0.00153006559354387,300.6076,300.6076,29152.166015625,29207.171875,54.8031019973519,19.5364414651424,11.139823,0,0,0,40,4961,300.6085,29179.6689453125,,,,,,,,,,,,,0,,,,,,,,,,,,,,
,20437623.35,300.59515,32972.78125,0.00185731626399805,5.30553662375604E-5,1,0.999253354069792,40.0298881530762,1.99881225794869,23.8899998366833,0.0180360071869107,0.0208651008128791,0.25,0.00152183795601123,0.00185621983710545,0.0015229837114268,300.5952,300.5952,32940.2734375,33005.2890625,54.6647537494481,19.5390251469267,10.760172,0,0,0,40,4961,300.59515,32972.78125,,,,,,,,,,,,,0,,,,,,,,,,,,,,
,20437698.81,300.5816,36743.556640625,0.00181812806188065,4.34013608263764E-5,1,0.999253354069792,40.0298881530762,1.99884700763274,23.8899998366833,0.0176564934095356,0.0204210347836386,0.25,0.00148936001558635,0.0018170567427435,0.00149048147612966,300.5817,300.5817,36713.62890625,36773.484375,54.9820949282558,19.5421688292889,11.139823,0,0,0,40,4961,300.5816,36743.556640625,,,,,,,,,,,,,0,,,,,,,,,,,,,,
,20437774.22,300.56955,40514.09765625,0.00182478258432776,4.88036926732927E-5,1,0.999253354069792,40.0298881530762,1.99868077535589,23.8899998366833,0.0176285479043703,0.0210204477458754,0.25,0.00154131727724497,0.00182367843182613,0.00154244028379154,300.571,300.571,40481.50390625,40546.69140625,54.9031504478135,19.547060502706,10.760172,0,0,0,40,4961,300.56955,40514.09765625,,,,,,,,,,,,,0,,,,,,,,,,,,,,
,20437849.385,300.5533,44269.205078125,0.00173789127818732,3.95906663477502E-5,1,0.999253354069792,40.0298881530762,1.99869188256058,23.8799992948771,0.0166838492566752,0.0206278854052052,0.25,0.00152167279316305,0.00173680625695848,0.00152273969989058,300.5537,300.5537,44244.515625,44293.89453125,54.7116514606019,19.5420429271431,11.139823,0,0,0,40,4961,300.5533,44269.205078125,,,,,,,,,,,,,0,,,,,,,,,,,,,,
,20437924.695,300.54175,48032.517578125,0.00171500906650609,4.2726099886767E-5,1,0.999253354069792,40.0298881530762,1.99883658281863,23.8799992948771,0.0164788916689447,0.0202794442496972,0.25,0.00149472362915688,0.00171394448374092,0.00149577658499029,300.5415,300.5415,48007.58203125,48057.453125,54.9445767593327,19.5364227091099,10.760172,0,0,0,40,4961,300.54175,48032.517578125,,,,,,,,,,,,,0,,,,,,,,,,,,,,
,20437999.65,300.5309,51778.654296875,0.00166032106431822,4.7811712589576E-5,1,0.999253354069792,40.0298881530762,1.99869844854032,23.8899998366833,0.0157776846717321,0.0206398132506249,0.25,0.00153616025859812,0.0016592335231245,0.00153717505760082,300.5324,300.5324,51751.41015625,51805.8984375,54.6889842335442,19.5395592741305,10.760172,0,0,0,40,4961,300.5309,51778.654296875,,,,,,,,,,,,,0,,,,,,,,,,,,,,
,20438074.53,300.5206,55521.4140625,0.00162070216159898,5.39022823414222E-5,1,0.999253354069792,40.0298881530762,1.99860336026454,23.8799992948771,0.0154375467991653,0.0199326301462792,0.25,0.00148061485517876,0.00161965447140101,0.00148160606183203,300.5204,300.5204,55498.80859375,55544.01953125,54.9305074459866,19.5433117693865,11.139823,0,0,0,40,4961,300.5206,55521.4140625,,,,,,,,,,,,,0,,,,,,,,,,,,,,
,20438150.26,300.50815,59307.078125,0.00154001670244746,5.92362638918057E-5,1,0.999253354069792,40.0298881530762,1.99882215076335,23.8799992948771,0.0145065651283012,0.0198887972715105,0.25,0.00149053659482118,0.00153896798437514,0.00149147432102907,300.5087,300.5087,59276.89453125,59337.26171875,55.148581802852,19.5437470381528,11.139823,0,0,0,40,4961,300.50815,59307.078125,,,,,,,,,,,,,0,,,,,,,,,,,,,,
,20438225.55,300.4965,63070.955078125,0.00154666172390301,4.97337804196848E-5,1,0.999253354069792,40.0298881530762,1.99877600393275,23.8899998366833,0.0145970153027472,0.019811646258928,0.25,0.00148260687186855,0.00154561946169734,0.00148354913057095,300.4977,300.4977,63045.81640625,63096.09375,54.4576221918519,19.5456489300509,11.139823,0,0,0,40,4961,300.4965,63070.955078125,,,,,,,,,,,,,0,,,,,,,,,,,,,,
,20438300.795,300.48635,66831.48046875,0.00143384259532965,6.6817907032501E-5,1,0.999253354069792,40.0298881530762,1.99877165250715,23.8799992948771,0.0132661114230671,0.019902595497197,0.25,0.00151019276463074,0.00143278905330045,0.00151105972409756,300.4866,300.4866,66804.1953125,66858.765625,54.5013933889288,19.5427234233987,11.139823,0,0,0,40,4961,300.48635,66831.48046875,,,,,,,,,,,,,0,,,,,,,,,,,,,,
,20438376.46,300.47655,70612.20703125,0.00143186619051139,5.44865354530984E-5,1,0.999253354069792,40.0298881530762,1.99878937049971,23.8799992948771,0.0133264655375498,0.0194221631146597,0.25,0.00146806935971869,0.00143084172205176,0.00146893672599934,300.477,300.477,70587.671875,70636.7421875,55.1517083169289,19.5440316430317,10.38052,0,0,0,40,4961,300.47655,70612.20703125,,,,,,,,,,,,,0,,,,,,,,,,,,,,
,20438452.845,300.46275,74430.359375,0.00135962614766785,5.63550216891332E-5,1,0.999253354069792,40.0298881530762,1.998962584801,23.8899998366833,0.01255428958645,0.0190261980676467,0.25,0.00144545821110247,0.00135862137531845,0.00144627943137003,300.4624,300.4624,74400.21875,74460.5,55.0203947256981,19.54840588957,10.760172,0,0,0,40,4961,300.46275,74430.359375,,,,,,,,,,,,,0,,,,,,,,,,,,,,
,20438528.75,300.4517,78226.5703125,0.00130763802050584,4.91879669630506E-5,1,0.999253354069792,40.0298881530762,1.99867390643916,23.8899998366833,0.0119723702135464,0.0188747206466206,0.25,0.00144131142202083,0.00130663977841543,0.00144209877460382,300.4513,300.4513,78198.90625,78254.234375,54.9336339600635,19.5404888728749,10.760172,0,0,0,40,4961,300.4517,78226.5703125,,,,,,,,,,,,,0,,,,,,,,,,,,,,
,20438605.26,300.4393,82050.265625,0.00126889362883774,7.11674007230223E-5,1,0.999253354069792,40.0298881530762,1.99879625459842,23.8799992948771,0.0115114062795845,0.0189337389437969,0.25,0.0014531409960944,0.00126789094325433,0.00145390251480462,300.4402,300.4402,82022.78125,82077.75,55.2376874540443,19.547631214113,11.139823,0,0,0,40,4961,300.4393,82050.265625,,,,,,,,,,,,,0,,,,,,,,,,,,,,
,20438681.83,300.43125,85878.5625,0.00122282748285391,7.37438054129339E-5,1,0.999253354069792,40.0298881530762,1.99865352859016,23.8899998366833,0.0110522852431881,0.018478707959103,0.25,0.00142102689812972,0.0012218490725985,0.00142175957343306,300.4323,300.4323,85845.96875,85911.15625,54.7452614869289,19.5463006754784,10.760172,0,0,0,40,4961,300.43125,85878.5625,,,,,,,,,,,,,0,,,,,,,,,,,,,,
,20438755.505,300.4194,89562.40234375,0.0011456747719489,6.46013480153119E-5,1,0.999253354069792,40.0298881530762,1.99858455469983,23.8899998366833,0.0102100937942788,0.0181465320782475,0.25,0.00140509309483963,0.0011447115239406,0.00140577627278178,300.4214,300.4214,89539.9453125,89584.859375,55.3690010452751,19.5476464026616,11.519473,0,0,0,40,4961,300.4194,89562.40234375,,,,,,,,,,,,,0,,,,,,,,,,,,,,
,20438843.995,300.409,86803.8046875,0.0011741986734207,7.77664191745277E-5,1,0.999253354069792,40.0298881530762,1.99870350572629,23.8899998366833,0.0104810177746656,0.0185062649480584,0.25,0.00143184651465229,0.00117321646687597,0.00143254811699743,300.4099,300.4099,86768.78125,86838.828125,54.8679771644481,19.5458826954969,11.139823,0,0,0,40,4961,300.409,86803.8046875,,,,,,,,,,,,,0,,,,,,,,,,,,,,
,20438917.04,300.4055,83152.48828125,0.00119432467976613,8.91758036182345E-5,1,0.999253354069792,40.0298881530762,1.99876936945535,23.8899998366833,0.0106771492368271,0.0187307861535515,0.25,0.00144814640368042,0.00119333017239606,0.00144886124133441,300.4066,300.4066,83120.140625,83184.8359375,55.0203947256981,19.543223484894,11.519473,0,0,0,40,4961,300.4055,83152.48828125,,,,,,,,,,,,,0,,,,,,,,,,,,,,
,20438993.35,300.4084,79338.34765625,0.00128704460019388,5.74989424614605E-5,1,0.999253354069792,40.0298881530762,1.99860630352708,23.8799992948771,0.0117264728405212,0.0189058454112257,0.25,0.001447680915144,0.00128604525472529,0.00144845672223746,300.4086,300.4086,79310.7734375,79365.921875,55.1775020580635,19.5466344561505,11.139823,0,0,0,40,4961,300.4084,79338.34765625,,,,,,,,,,,,,0,,,,,,,,,,,,,,
,20439069.915,300.4097,75509.48828125,0.00131812292889276,7.15378502209733E-5,1,0.999253354069792,40.0298881530762,1.99891741337144,23.8899998366833,0.0120898847614512,0.0189122467677376,0.25,0.00144261360018325,0.00131712448010943,0.00144341057110718,300.4074,300.4074,75481.984375,75536.9921875,55.0579128946212,19.5503758409065,10.760172,0,0,0,40,4961,300.4097,75509.48828125,,,,,,,,,,,,,0,,,,,,,,,,,,,,
,20439144.43,300.41375,71783.421875,0.0013761708030198,5.69173324662729E-5,1,0.999253354069792,40.0298881530762,1.99859941648853,23.8899998366833,0.0127789960706701,0.018826531512117,0.25,0.0014252357958009,0.00137518002053306,0.00142607194093794,300.4137,300.4137,71753.390625,71813.453125,54.8836097348327,19.5426356878324,11.139823,0,0,0,40,4961,300.41375,71783.421875,,,,,,,,,,,,,0,,,,,,,,,,,,,,
,20439220.175,300.4189,68000.4296875,0.001428773028458,4.9563761347869E-5,1,0.999253354069792,40.0298881530762,1.99871952013756,23.8899998366833,0.0133042105458643,0.0193394282378624,0.25,0.0014613476701799,0.00142775513456971,0.00146221710034462,300.4194,300.4194,67975.515625,68025.34375,54.8070101399481,19.5431614195384,11.139823,0,0,0,40,4961,300.4189,68000.4296875,,,,,,,,,,,,,0,,,,,,,,,,,,,,
,20439296.595,300.4249,64176.845703125,0.00145814839114359,5.28170237112071E-5,1,0.999253354069792,40.0298881530762,1.99867515237254,23.8799992948771,0.0135606892128747,0.0198333135388138,0.25,0.00149993625677835,0.00145710268189936,0.00150082366810044,300.4248,300.4248,64146.984375,64206.70703125,55.0954310635443,19.544767870843,11.519473,0,0,0,40,4961,300.4249,64176.845703125,,,,,,,,,,,,,0,,,,,,,,,,,,,,
,20439371.54,300.43075,60433.11328125,0.00155596444287883,4.89369058517563E-5,1,0.999253354069792,40.0298881530762,1.99888697925416,23.8799992948771,0.014710292145654,0.019789466689862,0.25,0.00147893792423484,0.00155492685937044,0.00147989077766898,300.4309,300.4309,60403.0859375,60463.140625,54.9265993033904,19.5513093054462,10.760172,0,0,0,40,4961,300.43075,60433.11328125,,,,,,,,,,,,,0,,,,,,,,,,,,,,
,20439447.855,300.43565,56617.322265625,0.00159844540112211,5.36721018194377E-5,1,0.999253354069792,40.0298881530762,1.99871287211016,23.8899998366833,0.0151750128364279,0.0199565224929009,0.25,0.00148648455066473,0.00159739973220028,0.00148746549379572,300.4376,300.4376,56589.79296875,56644.8515625,54.7147779746789,19.5452089853801,11.139823,0,0,0,40,4961,300.43565,56617.322265625,,,,,,,,,,,,,0,,,,,,,,,,,,,,
,20439525.105,300.44275,52756.482421875,0.00164379292266832,4.09067243039281E-5,1,0.999253354069792,40.0298881530762,1.99866476700176,23.8899998366833,0.0156544140787621,0.0202378616194431,0.25,0.00150352878774381,0.001642732660768,0.0015045391931634,300.442,300.442,52726.58203125,52786.3828125,54.9711521289866,19.5516404259659,10.760172,0,0,0,40,4961,300.44275,52756.482421875,,,,,,,,,,,,,0,,,,,,,,,,,,,,
,20439599.7,300.44725,49028.775390625,0.00170173096534992,5.09882303487949E-5,1,0.999253354069792,40.0298881530762,1.99875494094493,23.8899998366833,0.0163122874838437,0.020343569500753,0.25,0.00150275393680514,0.00170066738397121,0.00150380302809008,300.4481,300.4481,48998.76953125,49058.78125,54.7124330891212,19.55142413324,11.139823,0,0,0,40,4961,300.44725,49028.775390625,,,,,,,,,,,,,0,,,,,,,,,,,,,,
,20439675.89,300.4525,45220.984375,0.00168118423624432,4.29649112143282E-5,1,0.999253354069792,40.0298881530762,1.99874212112021,23.8899998366833,0.0160644325451495,0.0203909541700948,0.25,0.00151051133451366,0.00168011522696286,0.00151154718489374,300.4525,300.4525,45220.984375,45220.984375,55.4502904112751,19.5512572811193,10.760172,0,0,0,40,4961,300.4525,45220.984375,,,,,,,,,,,,,0,,,,,,,,,,,,,,
,20439749.915,300.45435,41520.033203125,0.00177156132626388,4.19402495136103E-5,1,0.999253354069792,40.0298881530762,1.99884400188851,23.8899998366833,0.0170795822066186,0.0206180822295165,0.25,0.00151483340165182,0.00177048431600681,0.00151592924521563,300.4557,300.4557,41492.41796875,41547.6484375,54.7937224551212,19.5517612993767,11.139823,0,0,0,40,4961,300.45435,41520.033203125,,,,,,,,,,,,,0,,,,,,,,,,,,,,
,20439825.045,300.4622,37766.775390625,0.00183010325222916,4.33546820728359E-5,1,0.999253354069792,40.0298881530762,1.99870073236,23.8799992948771,0.0177534268070155,0.0206592045053213,0.25,0.00150844886349866,0.00182902635224585,0.00150958398328991,300.4618,300.4618,37734.18359375,37799.3671875,55.1118452624481,19.5499687832389,11.139823,0,0,0,40,4961,300.4622,37766.775390625,,,,,,,,,,,,,0,,,,,,,,,,,,,,
,20439900.16,300.4645,34011.572265625,0.00182651857231433,4.72562134682081E-5,1,0.999253354069792,40.0298881530762,1.99859202924456,23.8899998366833,0.0176982954896095,0.0207297874902979,0.25,0.00151540136217873,0.00182543619884859,0.00151653459623373,300.4649,300.4649,33976.54296875,34046.6015625,54.8976790481789,19.5517426846348,10.760172,0,0,0,40,4961,300.4645,34011.572265625,,,,,,,,,,,,,0,,,,,,,,,,,,,,
,20439975.485,300.46845,30248.4736328125,0.00186559209382193,4.61647976019481E-5,1,0.999253354069792,40.0298881530762,1.99848116402066,23.8799992948771,0.0181153728083939,0.0209444861797168,0.25,0.00152770170710478,0.00186449865629096,0.0015288608084734,300.4687,300.4687,30223.369140625,30273.578125,54.860942507775,19.550778802329,11.519473,0,0,0,40,4961,300.46845,30248.4736328125,,,,,,,,,,,,,0,,,,,,,,,,,,,,
,20440052.59,300.47385,26395.20703125,0.00189912627090877,3.96474496024281E-5,1,0.999253354069792,40.0298881530762,1.99840852712458,23.8799992948771,0.0185284501894611,0.020811692727432,0.25,0.00151021974812672,0.00189804155497693,0.00151140239781425,300.475,300.475,26365.134765625,26425.279296875,54.5920622971596,19.5485297807728,11.519473,0,0,0,40,4961,300.47385,26395.20703125,,,,,,,,,,,,,0,,,,,,,,,,,,,,
,20440126.65,300.47775,22690.3037109375,0.00191012176784823,4.41248591742895E-5,1,0.999253354069792,40.0298881530762,1.99842671788007,23.8799992948771,0.0186872807846448,0.0206356642671642,0.25,0.00149274168668513,0.0019090469812926,0.00149393307250403,300.4772,300.4772,22657.7421875,22722.865234375,54.8757934496404,19.5499168386191,11.519473,0,0,0,40,4961,300.47775,22690.3037109375,,,,,,,,,,,,,0,,,,,,,,,,,,,,
,20440201.495,300.48295,18952.15234375,0.00195072648627161,4.28243362194016E-5,1,0.999253354069792,40.0298881530762,1.99866114073267,23.8899998366833,0.0190927742875407,0.021041348832605,0.25,0.0015213506207429,0.00194962973655678,0.00152256806436809,300.4834,300.4834,18919.607421875,18984.697265625,54.6381783797942,19.5519910349663,11.139823,0,0,0,40,4961,300.48295,18952.15234375,,,,,,,,,,,,,0,,,,,,,,,,,,,,
,20440276.41,300.48365,15206.8178710938,0.00194911954714082,4.38622292951108E-5,1,0.999253354069792,40.0298881530762,1.99845813896275,23.8899998366833,0.0191466267102283,0.0206096476763436,0.25,0.00148365743249221,0.00194804694241539,0.00148487640679068,300.4831,300.4831,15176.7470703125,15236.888671875,54.6585007212942,19.5487972415246,10.760172,0,0,0,40,4961,300.48365,15206.8178710938,,,,,,,,,,,,,0,,,,,,,,,,,,,,
,20440350.735,300.48695,11494.0043945312,0.00198769201720554,3.63629350301194E-5,1,0.999253354069792,40.0298881530762,1.99851511737501,23.8899998366833,0.0196092483283707,0.0205378929981242,0.25,0.00147058334422572,0.00198662528120727,0.00147182907992189,300.4874,300.4874,11464.0849609375,11523.923828125,55.0329007820058,19.5526925911252,10.760172,0,0,0,40,4961,300.48695,11494.0043945312,,,,,,,,,,,,,0,,,,,,,,,,,,,,
,20440425.12,300.49235,7776.0859375,0.00197027925132504,3.72910080688345E-5,1,0.999253354069792,40.0298881530762,1.99854357068827,23.8799992948771,0.0195117200841967,0.0199311290798826,0.25,0.00141995529863302,0.00196924580033442,0.00142119237748643,300.4917,300.4917,7746.50341796875,7805.66845703125,54.8992423052174,19.5516195162257,11.139823,0,0,0,40,4961,300.49235,7776.0859375,,,,,,,,,,,,,0,,,,,,,,,,,,,,
,20440498.265,300.4951,4116.82995605469,0.00190539020783424,3.52843902949632E-5,1,0.999253354069792,40.0298881530762,1.99866471707502,23.8799992948771,0.0188776951601253,0.0192326031934596,0.25,0.00136937012275369,0.00190439256411126,0.00137056716419904,300.4952,300.4952,4086.82250976562,4146.83740234375,54.6803863198327,19.5507071188699,11.139823,0,0,0,40,4961,300.4951,4116.82995605469,,,,,,,,,,,,,0,,,,,,,,,,,,,,
,20440570.345,300.49795,515.856948852539,0.00125885494503002,1.93042921625431E-5,1,0.999253354069792,40.0298881530762,1.99868977958551,23.8799992948771,0.0125137167384542,0.0124675892316984,0.25,0.00088358183706224,0.00125820939804956,0.000884373961153218,300.4981,300.4981,493.202667236328,538.51123046875,55.1298227183905,19.5505245118328,10.760172,0,0,0,40,4961,300.49795,515.856948852539,,,,,,,,,,,,,0,,,,,,,,,,,,,,
,20440642.525,300.49735,-3084.67175292969,-0.00186541700458784,2.85786229432464E-5,1,0.999253354069792,40.0298881530762,1.99881273743691,23.8899998366833,-0.0185058636822219,-0.0186982747556734,0.25,-0.0013289629419063,-0.00186444774056684,-0.00133013547631423,300.4986,300.4986,-3114.52026367188,-3054.8232421875,55.2134569699482,19.5533016100996,10.760172,0,0,0,40,4961,300.49735,-3084.67175292969,,,,,,,,,,,,,0,,,,,,,,,,,,,,
,20440715.5,300.49515,-6737.23266601562,-0.00190706757495836,3.01016003568416E-5,1,0.999253354069792,40.0298881530762,1.9986418004679,23.8799992948771,-0.0188520918628567,-0.0194918500780379,0.25,-0.00139200720193074,-0.00190605526819867,-0.00139320380308134,300.4949,300.4949,-6764.57568359375,-6709.8896484375,55.0719822079674,19.5541263298686,10.760172,0,0,0,40,4961,300.49515,-6737.23266601562,,,,,,,,,,,,,0,,,,,,,,,,,,,,
,20440790.415,300.4925,-10481.1704101562,-0.00194605299936021,3.83752271208508E-5,1,0.999253354069792,40.0298881530762,1.99852908544611,23.8899998366833,-0.0191834589223132,-0.0201951059755027,0.25,-0.00144749328719253,-0.00194500294875675,-0.00144871246200425,300.493,300.493,-10503.5859375,-10458.7548828125,54.911748361525,19.5593742339207,11.139823,0,0,0,40,4961,300.4925,-10481.1704101562,,,,,,,,,,,,,0,,,,,,,,,,,,,,
,20440864.86,300.4898,-14201.7783203125,-0.00197867002961228,3.11831119275619E-5,1,0.999253354069792,40.0298881530762,1.99873375769016,23.8899998366833,-0.0195441577907562,-0.0203205653257813,0.25,-0.00145275411861239,-0.00197761585550683,-0.00145399396250511,300.4899,300.4899,-14226.974609375,-14176.58203125,54.810136654025,19.5647205664853,10.760172,0,0,0,40,4961,300.4898,-14201.7783203125,,,,,,,,,,,,,0,,,,,,,,,,,,,,
,20440939.76,300.47955,-17944.75390625,-0.00195599785439244,4.02143097115409E-5,1,0.999253354069792,40.0298881530762,1.99869494108537,23.8899998366833,-0.0192013963787491,-0.0207711773513128,0.25,-0.00149653343721669,-0.00195491726096205,-0.0014977559642882,300.4782,300.4782,-17969.4453125,-17920.0625,54.955519558602,19.5561383132752,11.139823,0,0,0,40,4961,300.47955,-17944.75390625,,,,,,,,,,,,,0,,,,,,,,,,,,,,
,20441015.83,300.474,-21744.6884765625,-0.00193613108834526,2.86329766520088E-5,1,0.999253354069792,40.0298881530762,1.99874018090115,23.8899998366833,-0.0189783544281839,-0.0207248051469521,0.25,-0.00149583867625871,-0.00193505307546674,-0.0014970475363352,300.474,300.474,-21747.34375,-21742.033203125,54.9187830181981,19.5561853488168,11.519473,0,0,0,40,4961,300.474,-21744.6884765625,,,,,,,,,,,,,0,,,,,,,,,,,,,,
,20441089.34,300.4681,-25419.9970703125,-0.00191565329843828,3.83698847985081E-5,1,0.999253354069792,40.0298881530762,1.99864017187211,23.8799992948771,-0.0187081605975822,-0.0209004778128575,0.25,-0.00151499790887378,-0.0019145648051271,-0.00151619181808593,300.4674,300.4674,-25450.07421875,-25389.919921875,55.0360272960828,19.554668767239,11.139823,0,0,0,40,4961,300.4681,-25419.9970703125,,,,,,,,,,,,,0,,,,,,,,,,,,,,
,20441167.355,300.45935,-29320.6435546875,-0.00187119579760983,4.33313754452544E-5,1,0.999253354069792,40.0298881530762,1.99863451722496,23.8899998366833,-0.0182203617641776,-0.0207247262995287,0.25,-0.0015071750720452,-0.00187011598440867,-0.00150833957893509,300.458,300.458,-29348.146484375,-29293.140625,55.1571797165635,19.5569077614933,11.139823,0,0,0,40,4961,300.45935,-29320.6435546875,,,,,,,,,,,,,0,,,,,,,,,,,,,,
,20441243.13,300.45,-33108.470703125,-0.00183456375562697,4.55757984701608E-5,1,0.999253354069792,40.0298881530762,1.99882227926956,23.8899998366833,-0.017827556804418,-0.0205385775191069,0.25,-0.00149690990307304,-0.00183349386729521,-0.00149805035437691,300.4496,300.4496,-33140.984375,-33075.95703125,55.321321705602,19.5539696029079,11.139823,0,0,0,40,4961,300.45,-33108.470703125,,,,,,,,,,,,,0,,,,,,,,,,,,,,
,20441320.805,300.4428,-36988.10546875,-0.0018006285741845,5.51100848391205E-5,1,0.999253354069792,40.0298881530762,1.9987124868405,23.8799992948771,-0.0173835785562801,-0.0208116030502793,0.25,-0.00152701015005246,-0.00179954178908891,-0.00152812635687281,300.4428,300.4428,-36993.26171875,-36982.94921875,55.1907897428905,19.5531437029466,11.519473,0,0,0,40,4961,300.4428,-36988.10546875,,,,,,,,,,,,,0,,,,,,,,,,,,,,
,20441397.59,300.4358,-40824.013671875,-0.00178573380310511,5.07254953297162E-5,1,0.999253354069792,40.0298881530762,1.99857151191394,23.8799992948771,-0.0171890227349542,-0.0209244300198774,0.25,-0.00153968522311927,-0.00178464073402446,-0.00154079052939417,300.436,300.436,-40856.2265625,-40791.80078125,54.9711521289866,19.5553044512785,10.760172,0,0,0,40,4961,300.4358,-40824.013671875,,,,,,,,,,,,,0,,,,,,,,,,,,,,
,20441474.105,300.4262,-44649.64453125,-0.00166632622717179,6.15392377894015E-5,1,0.999253354069792,40.0298881530762,1.99858574930214,23.8899998366833,-0.0159453758800122,-0.0200701811634538,0.25,-0.00148487198743692,-0.0016652760610506,-0.00148590088315319,300.426,300.426,-44679.75,-44619.5390625,55.4651413531405,19.5548403215484,10.760172,0,0,0,40,4961,300.4262,-44649.64453125,,,,,,,,,,,,,0,,,,,,,,,,,,,,
,20441549.435,300.4187,-48414.462890625,-0.00169390653939946,5.31196748602229E-5,1,0.999253354069792,40.0298881530762,1.99889721407265,23.8799992948771,-0.0162783929157095,-0.0200205995340065,0.25,-0.00147544931593274,-0.00169286269959531,-0.00147649628368532,300.4185,300.4185,-48447.1640625,-48381.76171875,55.2337793114482,19.5551267396083,11.139823,0,0,0,40,4961,300.4187,-48414.462890625,,,,,,,,,,,,,0,,,,,,,,,,,,,,
,20441626.345,300.4085,-52257.212890625,-0.00163055968714825,5.49589724445967E-5,1,0.999253354069792,40.0298881530762,1.99866426314489,23.8899998366833,-0.015479843038653,-0.0203552341286085,0.25,-0.00151619112380982,-0.00162949344547204,-0.0015171943929064,300.4111,300.4111,-52284.58203125,-52229.84375,55.2892749363135,19.5589712092951,11.139823,0,0,0,40,4961,300.4085,-52257.212890625,,,,,,,,,,,,,0,,,,,,,,,,,,,,
,20441701.345,300.4005,-56004.9296875,-0.00159632009357856,4.67342211672478E-5,1,0.999253354069792,40.0298881530762,1.99883554953087,23.8899998366833,-0.0151831557183374,-0.0197729343733016,0.25,-0.00147052560995064,-0.00159528669068056,-0.00147150800607587,300.4006,300.4006,-56032.33984375,-55977.51953125,55.0117968119866,19.5526106539703,11.519473,0,0,0,40,4961,300.4005,-56004.9296875,,,,,,,,,,,,,0,,,,,,,,,,,,,,
,20441772.11,300.39385,-59542.9921875,-0.00153593452483682,5.56188391285473E-5,1,0.999253354069792,40.0298881530762,1.99878949857688,23.8899998366833,-0.0144426195894074,-0.0199820043927343,0.25,-0.0014994994788531,-0.00153488601834835,-0.00150044062299641,300.3941,300.3941,-59570.49609375,-59515.48828125,55.3158503059674,19.5570412413971,11.139823,0,0,0,40,4961,300.39385,-59542.9921875,,,,,,,,,,,,,0,,,,,,,,,,,,,,
,20441842.955,300.38755,-63084.04296875,-0.00151217876157563,5.84382953542285E-5,1,0.999253354069792,40.0298881530762,1.99892232381059,23.8899998366833,-0.0142236497904296,-0.0196540353884956,0.25,-0.00147452607915536,-0.00151114887154131,-0.00147545231302023,300.3872,300.3872,-63113.80859375,-63054.27734375,55.1626511161982,19.5586839624795,11.139823,0,0,0,40,4961,300.38755,-63084.04296875,,,,,,,,,,,,,0,,,,,,,,,,,,,,
,20441918.055,300.37665,-66838.8984375,-0.00147953556351367,5.88881105111677E-5,1,0.999253354069792,40.0298881530762,1.99894136638041,23.8899998366833,-0.0138417838643395,-0.0196626443114743,0.25,-0.00148092631999274,-0.0014785044054181,-0.00148183071209081,300.3777,300.3777,-66871.328125,-66806.46875,55.3189768200443,19.5572807389641,11.139823,0,0,0,40,4961,300.37665,-66838.8984375,,,,,,,,,,,,,0,,,,,,,,,,,,,,
,20441992.005,300.369,-70533.9609375,-0.00139330460328552,5.87616524532713E-5,1,0.999253354069792,40.0298881530762,1.99921627717458,23.8899998366833,-0.0128801035986661,-0.0194234055324102,0.25,-0.00147450326770661,-0.00139228263088722,-0.0014753512180152,300.3677,300.3677,-70558.765625,-70509.15625,55.0626026657366,19.5544746501372,11.139823,0,0,0,40,4961,300.369,-70533.9609375,,,,,,,,,,,,,0,,,,,,,,,,,,,,
,20442067.155,300.3577,-74286.63671875,-0.00133681927869795,4.10240619811399E-5,1,0.999253354069792,40.0298881530762,1.99881474777328,23.8899998366833,-0.012307005431699,-0.0189128049597626,0.25,-0.00143950227251869,-0.00133582401818633,-0.00144031466952358,300.3584,300.3584,-74311.6953125,-74261.578125,54.7374452017366,19.5553934434744,10.760172,0,0,0,40,4961,300.3577,-74286.63671875,,,,,,,,,,,,,0,,,,,,,,,,,,,,
,20442144.21,300.3503,-78138.9921875,-0.0012977271941432,6.37839126159632E-5,1,0.999253354069792,40.0298881530762,1.99912740648107,23.8899998366833,-0.0118677319848877,-0.0188310783042398,0.25,-0.00143880548958306,-0.00129673533410682,-0.00143959205474971,300.3493,300.3493,-78163.8125,-78114.171875,55.6683647681405,19.5565722105751,10.760172,0,0,0,40,4961,300.3503,-78138.9921875,,,,,,,,,,,,,0,,,,,,,,,,,,,,
,20442220.495,300.346,-81952.2421875,-0.00124603564303889,5.34334604989538E-5,1,0.999253354069792,40.0298881530762,1.99900678345826,23.8799992948771,-0.0113387261512273,-0.0184011269420305,0.25,-0.00140987074243677,-0.00124506594016458,-0.00141062431277813,300.3459,300.3459,-81982.25,-81922.234375,55.3158503059674,19.5584657283233,11.139823,0,0,0,40,4961,300.346,-81952.2421875,,,,,,,,,,,,,0,,,,,,,,,,,,,,
,20442294.39,300.33605,-85645.015625,-0.00119870972068446,7.25891766316378E-5,1,0.999253354069792,40.0298881530762,1.9992215559472,23.8899998366833,-0.0108179379415021,-0.0182308272644686,0.25,-0.00140285862562976,-0.0011977478694062,-0.00140358151349378,300.3377,300.3377,-85675.0859375,-85614.9453125,55.0758903505635,19.5568500391942,11.139823,0,0,0,40,4961,300.33605,-85645.015625,,,,,,,,,,,,,0,,,,,,,,,,,,,,
,20442366.115,300.32845,-89226.8984375,-0.00112514135481805,7.62033422616983E-5,1,0.999253354069792,40.0298881530762,1.99924750845316,23.8899998366833,-0.00993861021335465,-0.0183562715575979,0.25,-0.00142666591911577,-0.00112416822071737,-0.00142733975699875,300.3278,300.3278,-89256.703125,-89197.09375,55.3158503059674,19.5574740856052,11.519473,0,0,0,40,4961,300.32845,-89226.8984375,,,,,,,,,,,,,0,,,,,,,,,,,,,,
,20442452.885,300.31775,-87168.8671875,-0.00117362578119103,5.19055239315443E-5,1,0.999253354069792,40.0298881530762,1.99910897149882,23.8899998366833,-0.0105465703620932,-0.0181048705159501,0.25,-0.00139616225696025,-0.00117267040190888,-0.00139686978755957,300.3179,300.3179,-87193.8671875,-87143.8671875,55.4932799798328,19.5583407505801,11.139823,0,0,0,40,4961,300.31775,-87168.8671875,,,,,,,,,,,,,0,,,,,,,,,,,,,,
,20442526.895,300.3199,-83468.84375,-0.00122208875437446,6.07096871096568E-5,1,0.999253354069792,40.0298881530762,1.99921826175799,23.8899998366833,-0.011079206863667,-0.0182960400237788,0.25,-0.00140457050607955,-0.00122112492386071,-0.00140530980401423,300.3199,300.3199,-83471.2734375,-83466.4140625,55.0039805267943,19.5614827051238,10.760172,0,0,0,40,4961,300.3199,-83468.84375,,,,,,,,,,,,,0,,,,,,,,,,,,,,
,20442601.4,300.3209,-79745.62109375,-0.00127652306989306,5.80535127711355E-5,1,0.999253354069792,40.0298881530762,1.99917520574084,23.8899998366833,-0.0116868652365581,-0.0184501620435184,0.25,-0.00140878822513956,-0.00127555330415438,-0.00140956347096609,300.3211,300.3211,-79778.109375,-79713.1328125,55.0735454650058,19.5592036677014,10.760172,0,0,0,40,4961,300.3209,-79745.62109375,,,,,,,,,,,,,0,,,,,,,,,,,,,,
,20442677.01,300.3258,-75968.390625,-0.00131633552679669,6.05024192017277E-5,1,0.999253354069792,40.0298881530762,1.99907642053441,23.8899998366833,-0.012054985212427,-0.0190003919857733,0.25,-0.00145057865855122,-0.00131533571173482,-0.00145137865086048,300.3254,300.3254,-75995.796875,-75940.984375,55.1009024631789,19.5536014680389,11.519473,0,0,0,40,4961,300.3258,-75968.390625,,,,,,,,,,,,,0,,,,,,,,,,,,,,
,20442751.015,300.3317,-72267.921875,-0.00135520045689225,6.07591506541289E-5,1,0.999253354069792,40.0298881530762,1.99920338115551,23.8899998366833,-0.0125184747020764,-0.0189459552636922,0.25,-0.0014389343681692,-0.00135420544016866,-0.00143976062135445,300.3322,300.3322,-72297.9375,-72237.90625,55.2666077092559,19.5499018195374,11.139823,0,0,0,40,4961,300.3317,-72267.921875,,,,,,,,,,,,,0,,,,,,,,,,,,,,
,20442827.48,300.33935,-68450.390625,-0.00142805302146505,6.04823134033198E-5,1,0.999253354069792,40.0298881530762,1.99930672216908,23.8899998366833,-0.0132736288248613,-0.0194947005232422,0.25,-0.00147470482034049,-0.0014270303023699,-0.00147557757408868,300.3385,300.3385,-68475.4609375,-68425.3203125,55.1735939154674,19.5522488954093,11.519473,0,0,0,40,4961,300.33935,-68450.390625,,,,,,,,,,,,,0,,,,,,,,,,,,,,
,20442901.695,300.34685,-64740.05078125,-0.00148336009278131,6.00297507275386E-5,1,0.999253354069792,40.0298881530762,1.99910526793857,23.8899998366833,-0.013888766556076,-0.0196566830203849,0.25,-0.00147959883402659,-0.00148233055378084,-0.00148050793216793,300.3467,300.3467,-64772.51953125,-64707.58203125,55.3267931052366,19.5517233866364,11.139823,0,0,0,40,4961,300.34685,-64740.05078125,,,,,,,,,,,,,0,,,,,,,,,,,,,,
,20442977.47,300.35455,-60952.05859375,-0.00150846057506323,5.43297784558946E-5,1,0.999253354069792,40.0298881530762,1.99914095040606,23.8899998366833,-0.014107485557258,-0.0200850077319962,0.25,-0.00151306061198994,-0.00150740670969377,-0.00151398513950427,300.3543,300.3543,-60979.48046875,-60924.63671875,55.3361726474674,19.5535718383913,10.760172,0,0,0,40,4961,300.35455,-60952.05859375,,,,,,,,,,,,,0,,,,,,,,,,,,,,
,20443052.25,300.36015,-57214.220703125,-0.00158782569649577,4.79279675758946E-5,1,0.999253354069792,40.0298881530762,1.99896618014383,23.8899998366833,-0.0150892687058807,-0.019750122344398,0.25,-0.00146987041181759,-0.00158679553581668,-0.00147084927022807,300.3607,300.3607,-57241.7421875,-57186.69921875,55.0493149809097,19.5509527430439,11.519473,0,0,0,40,4961,300.36015,-57214.220703125,,,,,,,,,,,,,0,,,,,,,,,,,,,,
,20443126.285,300.36835,-53513.9765625,-0.00159899681679619,5.29020907456114E-5,1,0.999253354069792,40.0298881530762,1.99900960338748,23.8899998366833,-0.0152044398390748,-0.0198392012203999,0.25,-0.00147576880839036,-0.00159796093659108,-0.00147675513358195,300.3681,300.3681,-53543.859375,-53484.09375,55.0055437838327,19.55268083346,11.139823,0,0,0,40,4961,300.36835,-53513.9765625,,,,,,,,,,,,,0,,,,,,,,,,,,,,
,20443201.66,300.376,-49749.19921875,-0.00167268593857185,5.07803345458103E-5,1,0.999253354069792,40.0298881530762,1.99912973710548,23.8899998366833,-0.0160421174447337,-0.0199691649769199,0.25,-0.0014743829207917,-0.00167164646013252,-0.00147541811418271,300.376,300.376,-49751.75390625,-49746.64453125,54.8531262225827,19.5518604626141,10.760172,0,0,0,40,4961,300.376,-49749.19921875,,,,,,,,,,,,,0,,,,,,,,,,,,,,
,20443275.86,300.3811,-46041.384765625,-0.00169976540844545,4.39201104977598E-5,1,0.999253354069792,40.0298881530762,1.99890435072944,23.8799992948771,-0.016292315069217,-0.0203349608558139,0.25,-0.00150220056366581,-0.0016987052743406,-0.00150325294644662,300.3798,300.3798,-46073.95703125,-46008.8125,55.0039805267943,19.5567438595211,11.519473,0,0,0,40,4961,300.3811,-46041.384765625,,,,,,,,,,,,,0,,,,,,,,,,,,,,
,20443350.46,300.38665,-42310.650390625,-0.00176168025725256,6.19881220743956E-5,1,0.999253354069792,40.0298881530762,1.99895943092724,23.8899998366833,-0.0169564325641172,-0.0206708540988824,0.25,-0.00152110297154298,-0.00176060376361313,-0.00152219582178233,300.3866,300.3866,-42340.67578125,-42280.625,55.4682678672174,19.5535015962608,11.519473,0,0,0,40,4961,300.38665,-42310.650390625,,,,,,,,,,,,,0,,,,,,,,,,,,,,
,20443424.64,300.3924,-38605.1328125,-0.00179496434297301,5.14227464977585E-5,1,0.999253354069792,40.0298881530762,1.99882876735642,23.8899998366833,-0.017398447784081,-0.0203516240118236,0.25,-0.00148724339390701,-0.00179390741986832,-0.00148836018589821,300.3911,300.3911,-38627.609375,-38582.65625,55.3228849626405,19.5524512480552,10.760172,0,0,0,40,4961,300.3924,-38605.1328125,,,,,,,,,,,,,0,,,,,,,,,,,,,,
,20443499.07,300.3988,-34884.8984375,-0.00184011259968179,4.93831915173245E-5,1,0.999253354069792,40.0298881530762,1.99891629158994,23.8899998366833,-0.0178997611775604,-0.020500971512998,0.25,-0.0014925412726011,-0.00183904892579726,-0.00149368811207713,300.3989,300.3989,-34904.6953125,-34865.1015625,55.2243997692174,19.5529399786475,11.519473,0,0,0,40,4961,300.3988,-34884.8984375,,,,,,,,,,,,,0,,,,,,,,,,,,,,
,20443574.995,300.4061,-31092.3896484375,-0.00185241344979043,4.32444128273833E-5,1,0.999253354069792,40.0298881530762,1.99888417902933,23.8899998366833,-0.0179669415974341,-0.0209388992952851,0.25,-0.00152913101537969,-0.00185132375590661,-0.00153028486055884,300.4048,300.4048,-31122.1640625,-31062.615234375,55.0790168646404,19.5556673990901,11.139823,0,0,0,40,4961,300.4061,-31092.3896484375,,,,,,,,,,,,,0,,,,,,,,,,,,,,
,20443650.83,300.41005,-27302.529296875,-0.00185554893137429,3.48263566446043E-5,1,0.999253354069792,40.0298881530762,1.99884491945349,23.8899998366833,-0.0180612282516899,-0.020603250596924,0.25,-0.00149896490897524,-0.00185447785203128,-0.00150012283803646,300.4117,300.4117,-27324.828125,-27280.23046875,54.7132147176404,19.5520293597667,11.519473,0,0,0,40,4961,300.41005,-27302.529296875,,,,,,,,,,,,,0,,,,,,,,,,,,,,
,20443725.665,300.4158,-23561.4560546875,-0.00192140741154234,3.73416522790344E-5,1,0.999253354069792,40.0298881530762,1.99881036936942,23.8899998366833,-0.0188288450051404,-0.020601738308554,0.25,-0.00148745054584217,-0.00192033979190059,-0.0014886530195273,300.4151,300.4151,-23591.46875,-23531.443359375,54.9367604741404,19.555662855031,11.519473,0,0,0,40,4961,300.4158,-23561.4560546875,,,,,,,,,,,,,0,,,,,,,,,,,,,,
,20443800.9,300.4213,-19801.3388671875,-0.00194059334047408,4.00540405851034E-5,1,0.999253354069792,40.0298881530762,1.9986586806428,23.8899998366833,-0.0190487170909377,-0.0206140322895327,0.25,-0.00148534427691613,-0.00193952506839002,-0.00148656009682369,300.4208,300.4208,-19823.6328125,-19779.044921875,55.1212248046789,19.5495355756167,11.519473,0,0,0,40,4961,300.4213,-19801.3388671875,,,,,,,,,,,,,0,,,,,,,,,,,,,,
,20443875.805,300.4266,-16058.9389648438,-0.00195833112904125,4.15362790840699E-5,1,0.999253354069792,40.0298881530762,1.99877118168543,23.8899998366833,-0.019245319182587,-0.0206796496808709,0.25,-0.00148797085763454,-0.00195725917976116,-0.00148919884753942,300.4266,300.4266,-16061.2021484375,-16056.67578125,55.0657291798135,19.555920448855,11.519473,0,0,0,40,4961,300.4266,-16058.9389648438,,,,,,,,,,,,,0,,,,,,,,,,,,,,
,20443949.14,300.43325,-12392.921875,-0.00196033442229304,3.92663821000974E-5,1,0.999253354069792,40.0298881530762,1.99872653417005,23.8899998366833,-0.019334429763923,-0.0202972194688287,0.25,-0.00145386998630851,-0.00195928375909308,-0.001455101277317,300.4351,300.4351,-12422.82421875,-12363.01953125,55.0102335549481,19.5506526105129,11.139823,0,0,0,40,4961,300.43325,-12392.921875,,,,,,,,,,,,,0,,,,,,,,,,,,,,
,20444023.57,300.43545,-8671.85107421875,-0.00194827145948993,4.17523630910861E-5,1,0.999253354069792,40.0298881530762,1.99877269582767,23.8899998366833,-0.019296912840964,-0.0197050003037415,0.25,-0.00140359110438984,-0.00194725378602776,-0.00140481735058816,300.4371,300.4371,-8704.484375,-8639.2177734375,55.2025141706789,19.5504474246665,11.899124,0,0,0,40,4961,300.43545,-8671.85107421875,,,,,,,,,,,,,0,,,,,,,,,,,,,,
,20444096.685,300.44185,-5018.73315429687,-0.00191625815722323,3.85164538243862E-5,1,0.999253354069792,40.0298881530762,1.99879775672268,23.8799992948771,-0.0190058381294942,-0.0192325942502075,0.25,-0.00136737508667147,-0.00191526490320359,-0.00136858213014048,300.4409,300.4409,-5051.26806640625,-4986.1982421875,55.4338762123713,19.5541141107446,11.139823,0,0,0,40,4961,300.44185,-5018.73315429687,,,,,,,,,,,,,0,,,,,,,,,,,,,,
,20444169.77,300.444,-1361.87127685547,-0.0017045800432586,3.62943252533335E-5,1,0.999253354069792,40.0298881530762,1.998780268588,23.8899998366833,-0.0169441033841588,-0.0168893062537499,0.25,-0.00119701040000192,-0.00170370873564782,-0.00119808541599926,300.4421,300.4421,-1391.89575195312,-1331.84680175781,55.0946494350251,19.5550917721676,11.139823,0,0,0,40,4961,300.444,-1361.87127685547,,,,,,,,,,,,,0,,,,,,,,,,,,,,
,20444240.38,300.4465,2162.43933105469,0.00177359193911328,2.64738697351135E-5,1,0.999253354069792,40.0298881530762,1.99871166893144,23.8899998366833,0.0175641331792966,0.017949946515217,0.25,0.00127882416990509,0.00177266319449186,0.00127994095066065,300.4476,300.4476,2137.75927734375,2187.11938476562,55.3799438445443,19.5541293552356,11.519473,0,0,0,40,4961,300.4465,2162.43933105469,,,,,,,,,,,,,0,,,,,,,,,,,,,,
,20444313.665,300.44745,5823.79541015625,0.00192057140569772,3.98777908299812E-5,1,0.999253354069792,40.0298881530762,1.99869071974964,23.8899998366833,0.0190064437464864,0.0195126811592026,0.25,0.00139146474867809,0.001919561761099,0.001392673097451,300.4467,300.4467,5791.31298828125,5856.27783203125,55.4182436419866,19.5526835461667,11.519473,0,0,0,40,4961,300.44745,5823.79541015625,,,,,,,,,,,,,0,,,,,,,,,,,,,,
,20444386.485,300.44515,9467.4755859375,0.00195723207728154,4.57390586517683E-5,1,0.999253354069792,40.0298881530762,1.99868867270982,23.8799992948771,0.0193773279507247,0.0198384285628326,0.25,0.00141389951611938,0.00195620667305643,0.00141513052461439,300.4449,300.4449,9439.732421875,9495.21875,54.9039320763327,19.5548258793765,11.519473,0,0,0,40,4961,300.44515,9467.4755859375,,,,,,,,,,,,,0,,,,,,,,,,,,,,
,20444461.095,300.43945,13195.5224609375,0.00198682271874525,4.4505928317625E-5,1,0.999253354069792,40.0298881530762,1.99858612487911,23.8799992948771,0.0196166798853268,0.020441288739327,0.25,0.00146213267561042,0.00198576513246235,0.00146338058430381,300.4398,300.4398,13167.865234375,13223.1796875,54.9242544178327,19.5581785288227,11.139823,0,0,0,40,4961,300.43945,13195.5224609375,,,,,,,,,,,,,0,,,,,,,,,,,,,,
,20444533.72,300.43595,16823.9404296875,0.00193522032854325,4.04393472472781E-5,1,0.999253354069792,40.0298881530762,1.99852418928167,23.8799992948771,0.0190260921006933,0.0203746670291873,0.25,0.00146523963998264,0.00193416399751068,0.00146645266026241,300.4357,300.4357,16796.646484375,16851.234375,54.965680729352,19.5512293142996,11.519473,0,0,0,40,4961,300.43595,16823.9404296875,,,,,,,,,,,,,0,,,,,,,,,,,,,,
,20444606.99,300.4309,20489.5830078125,0.00191684849156063,3.91572045484648E-5,1,0.999253354069792,40.0298881530762,1.99852821238386,23.8799992948771,0.0187604693833996,0.0206721649999397,0.25,0.00149470976676473,0.00191577462486963,0.00149590875688068,300.4311,300.4311,20464.611328125,20514.5546875,54.8797015922366,19.5599162817906,11.139823,0,0,0,40,4961,300.4309,20489.5830078125,,,,,,,,,,,,,0,,,,,,,,,,,,,,
,20444681.215,300.4237,24197.6455078125,0.00189716578672365,4.64859872169055E-5,1,0.999253354069792,40.0298881530762,1.9984658990355,23.8899998366833,0.0185193206249841,0.0207361829029207,0.25,0.00150383201215462,0.00189608807006288,0.00150501713575817,300.4245,300.4245,24167.490234375,24227.80078125,54.8898627629866,19.5573991587137,11.519473,0,0,0,40,4961,300.4237,24197.6455078125,,,,,,,,,,,,,0,,,,,,,,,,,,,,
,20444756.34,300.4163,27951.1416015625,0.00186733402720244,3.63265439721613E-5,1,0.999253354069792,40.0298881530762,1.99854180902392,23.8899998366833,0.01818016269785,0.0206915367697615,0.25,0.00150498898158212,0.00186625821114578,0.00150615389699327,300.4167,300.4167,27921.111328125,27981.171875,54.8679771644481,19.55465308215,11.519473,0,0,0,40,4961,300.4163,27951.1416015625,,,,,,,,,,,,,0,,,,,,,,,,,,,,
,20444831.895,300.4101,31726.72265625,0.00186097139354757,4.12546088517573E-5,1,0.999253354069792,40.0298881530762,1.99837527644388,23.8799992948771,0.0181548216821767,0.0203998871761205,0.25,0.00148046191398994,0.00185991330688238,0.0014816231579622,300.4097,300.4097,31694.169921875,31759.275390625,54.9469216448904,19.5584473195603,11.139823,0,0,0,40,4961,300.4101,31726.72265625,,,,,,,,,,,,,0,,,,,,,,,,,,,,
,20444907.425,300.4054,35504.427734375,0.00180333896891723,4.27274842107367E-5,1,0.999253354069792,40.0298881530762,1.99843705639002,23.8899998366833,0.0174396649725518,0.0206544090967953,0.25,0.0015128875771407,0.00180226325354107,0.00151400876487292,300.4044,300.4044,35476.87109375,35531.984375,55.2064223132751,19.5577872246112,11.899124,0,0,0,40,4961,300.4054,35504.427734375,,,,,,,,,,,,,0,,,,,,,,,,,,,,
,20444982.075,300.3936,39234.767578125,0.00173893655175893,4.12078814529551E-5,1,0.999253354069792,40.0298881530762,1.99836817818893,23.8799992948771,0.0167403258095809,0.0203546932668521,0.25,0.00149761744758231,0.00173787532068844,0.00149869669169566,300.3943,300.3943,39204.83203125,39264.703125,54.7757449991789,19.5578540376549,11.139823,0,0,0,40,4961,300.3936,39234.767578125,,,,,,,,,,,,,0,,,,,,,,,,,,,,
,20445058.4,300.3891,43047.8984375,0.00172122907496826,4.21434525624952E-5,1,0.999253354069792,40.0298881530762,1.99847089534985,23.8899998366833,0.0165858028830846,0.020061163407661,0.25,0.00147465740813018,0.00172018491483402,0.00147572534560029,300.3904,300.3904,43017.82421875,43077.97265625,55.0031988982751,19.5580065662523,11.519473,0,0,0,40,4961,300.3891,43047.8984375,,,,,,,,,,,,,0,,,,,,,,,,,,,,
,20445133.835,300.382,46818.82421875,0.0017032391048029,6.32903730049942E-5,1,0.999253354069792,40.0298881530762,1.99853679237716,23.8799992948771,0.0163202749530472,0.0203872138037959,0.25,0.00150653188851082,0.00170217612181502,0.00150758612844251,300.3827,300.3827,46796.328125,46841.3203125,55.3095972778135,19.5614047798509,11.139823,0,0,0,40,4961,300.382,46818.82421875,,,,,,,,,,,,,0,,,,,,,,,,,,,,
,20445211.54,300.373,50704.677734375,0.00164355418821881,4.582731621353E-5,1,0.999253354069792,40.0298881530762,1.99852631291428,23.8799992948771,0.015676021599928,0.0200899945150241,0.25,0.001490616170579,0.00164250570436888,0.00149163149185076,300.372,300.372,50674.953125,50734.40234375,54.7476063724866,19.5551790000331,11.519473,0,0,0,40,4961,300.373,50704.677734375,,,,,,,,,,,,,0,,,,,,,,,,,,,,
,20445286.25,300.36315,54437.357421875,0.00159772677996961,4.07007703105456E-5,1,0.999253354069792,40.0298881530762,1.99837593887247,23.8799992948771,0.0151895125355122,0.0198074097901591,0.25,0.00147370943442208,0.00159669281624001,0.0014746950955231,300.3654,300.3654,54407.4765625,54467.23828125,55.0790168646404,19.5523434399061,11.519473,0,0,0,40,4961,300.36315,54437.357421875,,,,,,,,,,,,,0,,,,,,,,,,,,,,
,20445360.28,300.35625,58138.23828125,0.00156121253458605,3.80910074922155E-5,1,0.999253354069792,40.0298881530762,1.99851467538881,23.8899998366833,0.0148314650203201,0.0194247406898644,0.25,0.00144610297318584,0.00156019950690889,0.00144706539475431,300.356,300.356,58110.62109375,58165.85546875,54.7452614869289,19.5527079717386,11.519473,0,0,0,40,4961,300.35625,58138.23828125,,,,,,,,,,,,,0,,,,,,,,,,,,,,
,20445436.425,300.34665,61940.779296875,0.00151099854856145,5.58334073759831E-5,1,0.999253354069792,40.0298881530762,1.99869159282421,23.8899998366833,0.0141948857591695,0.0197295641888452,0.25,0.00148159297967189,0.00150996583630597,0.00148252071354024,300.3454,300.3454,61908.3125,61973.24609375,54.7100882035635,19.5550717602275,11.519473,0,0,0,40,4961,300.34665,61940.779296875,,,,,,,,,,,,,0,,,,,,,,,,,,,,
,20445511.43,300.3419,65690.00390625,0.00145127864071614,4.88711739668395E-5,1,0.999253354069792,40.0298881530762,1.99839297744296,23.8799992948771,0.0135525955179286,0.0194049667803194,0.25,0.00146350177029475,0.00145026144765032,0.00146439062001945,300.3419,300.3419,65657.4375,65722.5703125,54.9922560990058,19.5530857623596,11.899124,0,0,0,40,4961,300.3419,65690.00390625,,,,,,,,,,,,,0,,,,,,,,,,,,,,
,20445587.23,300.33345,69480.37109375,0.00138725023076369,5.16121610547227E-5,1,0.999253354069792,40.0298881530762,1.99850073965042,23.8899998366833,0.012866165309263,0.0190646101345819,0.25,0.00144442868795233,0.00138624951651086,0.00144527612915671,300.3323,300.3323,69450.921875,69509.8203125,54.8836097348327,19.556269977425,11.519473,0,0,0,40,4961,300.33345,69480.37109375,,,,,,,,,,,,,0,,,,,,,,,,,,,,
,20445662.705,300.3226,73251.0546875,0.00136844818023985,5.70766493223867E-5,1,0.999253354069792,40.0298881530762,1.99851183805687,23.8799992948771,0.0127072343914433,0.0187176249983538,0.25,0.00141701368939717,0.00136746759985928,0.00141784977853032,300.3221,300.3221,73218.828125,73283.28125,54.8585976222173,19.5543272123271,11.139823,0,0,0,40,4961,300.3226,73251.0546875,,,,,,,,,,,,,0,,,,,,,,,,,,,,
,20445737.35,300.3176,76982.34375,0.0013000917732493,5.96151063645713E-5,1,0.999253354069792,40.0298881530762,1.99856851985426,23.8799992948771,0.0119857438368102,0.0182857672550778,0.25,0.00139064919069906,0.00129913232410167,0.00139144125074358,300.3182,300.3182,76952.5546875,77012.1328125,54.7945040836404,19.5528778252793,11.519473,0,0,0,40,4961,300.3176,76982.34375,,,,,,,,,,,,,0,,,,,,,,,,,,,,
,20445812.72,300.3067,80751.19140625,0.00125884491006138,6.13917379465288E-5,1,0.999253354069792,40.0298881530762,1.99856200143746,23.8799992948771,0.0114471938024996,0.018619115168024,0.25,0.00142725765157681,0.00125786466548215,0.00142802120662615,300.307,300.307,80721.1875,80781.1953125,54.7734001136212,19.5563134283417,11.519473,0,0,0,40,4961,300.3067,80751.19140625,,,,,,,,,,,,,0,,,,,,,,,,,,,,
,20445888.265,300.29935,84529.5703125,0.00119409658489108,7.5429226891222E-5,1,0.999253354069792,40.0298881530762,1.99842632328159,23.8899998366833,0.010725699986326,0.0184223425211919,0.25,0.00142119213817873,0.00119312413321873,0.0014219134514138,300.3004,300.3004,84499.6171875,84559.5234375,54.5725215841788,19.5531633120591,11.899124,0,0,0,40,4961,300.29935,84529.5703125,,,,,,,,,,,,,0,,,,,,,,,,,,,,
,20445959.935,300.29245,88107.77734375,0.00113135074486815,6.83519961610321E-5,1,0.999253354069792,40.0298881530762,1.99834630707771,23.8899998366833,0.0100563529820743,0.0180618602064229,0.25,0.00140026626729878,0.00113039556362349,0.00140094730584238,300.2946,300.2946,88077.75,88137.8046875,54.6280172090442,19.5606321942434,11.519473,0,0,0,40,4961,300.29245,88107.77734375,,,,,,,,,,,,,0,,,,,,,,,,,,,,
,20445997.945,300.28695,89996.296875,0.00111825629352157,7.25568400338016E-5,1,0.999253354069792,40.0298881530762,1.99838580894683,23.8899998366833,0.00991437334220377,0.0180019575178657,0.25,0.00139721066625256,0.00111730429659065,0.00139788327531365,300.2868,300.2868,89993.09375,89999.5,55.0078886693904,19.5541308019138,11.519473,0,0,0,40,4929,300.28695,89996.296875,,,,,,,,,,,,,0,,,,,,,,,,,,,,