File: data/monolayers/nanoparticles/Ac_CoFe_C/vsm/data_dispersion/AH11_HYST_100OE_100K.DAT
[Header]
; VSM Data File (default extension .dat)
; Copyright (c) 2003-2013, Quantum Design, Inc. All rights reserved.
TITLE,
FILEOPENTIME,20395868.34,08/25/2018,10:29 am
BYAPP,VSM,2.0,2.0
INFO,PPMS VSM Option Release 1.4.10 Build 1,APPNAME
INFO,Quantum Design Linear Motor Servo Controller,MOTOR_MODULE_NAME
INFO,3101-100 M1,MOTOR_HW_VERSION
INFO,MMC1014,MOTOR_SERIAL_NUMBER
INFO,SRV No X-over 01.03.11,MOTOR_SOFTWARE_VERSION
INFO,Quantum Design VSM Detection Module,VSM_MODULE_NAME
INFO,3101-150 F0,VSM_HW_VERSION
INFO,VSM707,VSM_SERIAL_NUMBER
INFO,VSM No X-over 01.02.05 May 20 2008 13:51:47,VSM_SOFTWARE_VERSION
INFO,704,PREAMP_SERIAL_NUMBER
INFO,822,COIL_SERIAL_NUMBER
INFO,0,MOMENT_UNITS
INFO,CoFe2O4,SAMPLE_MATERIAL
INFO,Cobalt deficient,SAMPLE_COMMENT
INFO,,SAMPLE_MASS
INFO,27,SAMPLE_VOLUME
INFO,,SAMPLE_MOLECULAR_WEIGHT
INFO,,SAMPLE_SIZE
INFO,,SAMPLE_SHAPE
DATATYPE,COMMENT,1
DATATYPE,TIME,2
STARTUPAXIS,X,2
STARTUPAXIS,Y1,5
[Data]
Comment,Time Stamp (sec),Temperature (K),Magnetic Field (Oe),Moment (emu),M. Std. Err. (emu),Transport Action,Averaging Time (sec),Frequency (Hz),Peak Amplitude (mm),Center Position (mm),Coil Signal' (mV),Coil Signal" (mV),Range (mV),M. Quad. Signal (emu),M. Raw' (emu),M. Raw" (emu),Min. Temperature (K),Max. Temperature (K),Min. Field (Oe),Max. Field (Oe),Mass (grams),Motor Lag (deg),Pressure (Torr),VSM Status (code),Motor Status (code),Measure Status (code),Measure Count,PPMS Status (code),System Temp. (K),System Field (Oe),Sample Position (deg),Bridge 1 Resistance (ohms),Bridge 1 Excitation (에),Bridge 2 Resistance (ohms),Bridge 2 Excitation (에),Bridge 3 Resistance (ohms),Bridge 3 Excitation (에),Bridge 4 Resistance (ohms),Bridge 4 Excitation (에),Signal 1 Vin (V),Signal 2 Vin (V),Digital Inputs (code),Drive 1 Iout (mA),Drive 1 Ipower (W),Drive 2 Iout (mA),Drive 2 Ipower (W),Pressure (),Map 20 (),Map 21 (),Map 22 (),Map 23 (),Map 24 (),Map 25 (),Map 26 (),Map 27 (),Map 28 (),Map 29 ()
,20395884.61,100.4473343,-48134.77734375,,,2,,,,24.0899999135733,,,,,,,100.4473343,100.4473343,-48134.77734375,-48134.77734375,,,8.861917,,,,-99999999,4961,100.9265,-48134.77734375,,,,,,,,,,,,,,,,,,,,,,,100.4473343,,,,
,20396234.01,100.36855,3732.08715820313,-0.00223838584470261,6.08325043384019E-7,1,0.999253354069792,40.0298881530762,1.99533802632016,24.0700002759695,-0.0254003927700587,-0.00460132506538876,0.25,-1.17521009702653E-5,-0.00225095272405352,-1.87167402801409E-5,100.3687,100.3687,3701.96704101562,3762.20727539063,55.2970912215058,19.5375238247124,8.861917,0,0,0,40,4961,100.36855,3732.08715820313,,,,,,,,,,,,,0,,,,,,,,,,,,,,
,20396315.205,100.352,7791.4560546875,-0.00142561661593552,1.53115840061642E-6,1,0.999253354069792,40.0298881530762,1.9952882854568,24.0700002759695,-0.016176984299445,-0.00293105817595202,0.25,-7.54872821300152E-6,-0.00143362774776851,-1.19695278116038E-5,100.3532,100.3532,7761.46630859375,7821.44580078125,55.7519990196982,19.5414414523272,8.861917,0,0,0,40,4961,100.352,7791.4560546875,,,,,,,,,,,,,0,,,,,,,,,,,,,,
,20396394.175,100.32705,11740.1342773437,-0.000159659573598306,1.4624733714005E-6,1,0.999253354069792,40.0298881530762,1.9953468044042,24.0700002759695,-0.00180829996044279,-0.00034804938267754,0.25,-2.58858544885327E-6,-0.00016055233551089,-3.09173443979583E-6,100.328,100.328,11710.1845703125,11770.083984375,55.3533684748905,19.5433204484902,9.241568,0,0,0,40,4961,100.32705,11740.1342773437,,,,,,,,,,,,,0,,,,,,,,,,,,,,
,20396472.765,100.29825,15668.3305664062,0.00133132459657571,2.16425866889661E-6,1,0.999253354069792,40.0298881530762,1.99535465900455,24.0700002759695,0.0151101392447486,0.0027232692785185,0.25,5.84348702421941E-6,0.0013388249869177,9.93460852496785E-6,100.2988,100.2988,15638.150390625,15698.5107421875,54.7139963461596,19.5375595633291,8.861917,0,0,0,40,4961,100.29825,15668.3305664062,,,,,,,,,,,,,0,,,,,,,,,,,,,,
,20396553.75,100.2684,19715.6689453125,0.00248575225692097,2.46617656838179E-6,1,0.999253354069792,40.0298881530762,1.99584326606031,24.0700002759695,0.0282201318778032,0.00508130475378411,0.25,1.05366166678449E-5,0.00249977342686782,1.81416170171128E-5,100.2692,100.2692,19690.822265625,19740.515625,54.972715386025,19.5429694823298,9.241568,0,0,0,40,4961,100.2684,19715.6689453125,,,,,,,,,,,,,0,,,,,,,,,,,,,,
,20396633.25,100.23645,23686.22265625,0.0030705452846417,2.46197719871886E-6,1,0.999253354069792,40.0298881530762,1.9958347942678,24.0700002759695,0.0348463762644053,0.00634986738388035,0.25,1.94914775710212E-5,0.00308786524014862,2.88829944152686E-5,100.2357,100.2357,23653.78125,23718.6640625,55.1939162569674,19.5452510236982,8.482265,0,0,0,40,4961,100.23645,23686.22265625,,,,,,,,,,,,,0,,,,,,,,,,,,,,
,20396707.205,100.21535,27385.5576171875,0.00330517429308431,2.87580126957689E-6,1,0.999253354069792,40.0298881530762,1.99595914810592,24.0700002759695,0.0375135041799918,0.00682437689832899,0.25,2.00414816150377E-5,0.0033238409541156,3.01033227910367E-5,100.2158,100.2158,27357.818359375,27413.296875,55.619122171429,19.5401365291128,8.861917,0,0,0,40,4961,100.21535,27385.5576171875,,,,,,,,,,,,,0,,,,,,,,,,,,,,
,20396782.32,100.1945,31137.7568359375,0.00342275466977516,3.42729022776208E-6,1,0.999253354069792,40.0298881530762,1.99526732586364,24.0599997341633,0.0388484648260759,0.00699061828104398,0.25,1.42634407849907E-5,0.00344212660311352,2.46012448038378E-5,100.1945,100.1945,31135.12109375,31140.392578125,55.0493149809097,19.5512976451585,8.482265,0,0,0,40,4961,100.1945,31137.7568359375,,,,,,,,,,,,,0,,,,,,,,,,,,,,
,20396854.135,100.18025,34728.208984375,0.00347826187583702,3.42063549310676E-6,1,0.999253354069792,40.0298881530762,1.99577107095888,24.0700002759695,0.0394747338023694,0.00718257233117564,0.25,2.13029860653194E-5,0.00349794900272752,3.18013652005652E-5,100.1801,100.1801,34698.41796875,34758,54.8367120236789,19.5386646639712,9.241568,0,0,0,40,4961,100.18025,34728.208984375,,,,,,,,,,,,,0,,,,,,,,,,,,,,
,20396933.545,100.16845,38696.134765625,0.00350389368636371,4.30132504120463E-6,1,0.999253354069792,40.0298881530762,1.99533581708709,24.0700002759695,0.0397700961659878,0.00716300789667499,0.25,1.52583574240705E-5,0.00352376838083397,2.57465605200085E-5,100.1687,100.1687,38691.3125,38700.95703125,54.9805316712174,19.5293595399448,8.482265,0,0,0,40,4961,100.16845,38696.134765625,,,,,,,,,,,,,0,,,,,,,,,,,,,,
,20397010.225,100.1566,42532.068359375,0.00351771547745024,3.84197797673989E-6,1,0.999253354069792,40.0298881530762,1.99557789452612,24.0700002759695,0.0399115993981513,0.00730753953728902,0.25,2.55274762835264E-5,0.00353766182469498,3.6063856145782E-5,100.1574,100.1574,42504.45703125,42559.6796875,54.5264055015442,19.5330335124433,8.482265,0,0,0,40,4961,100.1566,42532.068359375,,,,,,,,,,,,,0,,,,,,,,,,,,,,
,20397087.605,100.15735,46397.337890625,0.00351889026387884,3.62809126437105E-6,1,0.999253354069792,40.0298881530762,1.99572379845892,24.0700002759695,0.0399401767776712,0.00724108735247342,0.25,1.94772216585397E-5,0.0035388849294565,2.99282785957884E-5,100.1575,100.1575,46392.15234375,46402.5234375,54.9586460726789,19.5273260580283,8.861917,0,0,0,40,4961,100.15735,46397.337890625,,,,,,,,,,,,,0,,,,,,,,,,,,,,
,20397170.835,100.1673,50557.759765625,0.00351276522853364,4.50756325529707E-6,1,0.999253354069792,40.0298881530762,1.99553780313019,24.0700002759695,0.0398696475758852,0.00721506649127948,0.25,1.83745496249551E-5,0.00353275375307254,2.874096395068E-5,100.1674,100.1674,50555.47265625,50560.046875,54.9586460726789,19.542183747988,9.241568,0,0,0,40,4961,100.1673,50557.759765625,,,,,,,,,,,,,0,,,,,,,,,,,,,,
,20397252.285,100.1709,54625.58984375,0.00349568219470182,5.06849654858004E-6,1,0.999253354069792,40.0298881530762,1.995620444259,24.0700002759695,0.0396882591725824,0.00711960885383123,0.25,1.29998261554166E-5,0.00351561364887054,2.32276500770252E-5,100.1709,100.1709,54623.2109375,54627.96875,55.6605484829482,19.5312255686873,8.861917,0,0,0,40,4961,100.1709,54625.58984375,,,,,,,,,,,,,0,,,,,,,,,,,,,,
,20397333.25,100.1716,58673.580078125,0.00347477228126427,4.47250849783874E-6,1,0.999253354069792,40.0298881530762,1.99522338120077,24.0700002759695,0.039416393055471,0.00723094324913782,0.25,2.66438023022587E-5,0.00349456924837671,3.68317884726349E-5,100.1716,100.1716,58671.0234375,58676.13671875,54.6366151227558,19.5404374839594,8.482265,0,0,0,40,4961,100.1716,58673.580078125,,,,,,,,,,,,,0,,,,,,,,,,,,,,
,20397414.44,100.16175,62732.4140625,0.00345246432388159,5.05294362442081E-6,1,0.999253354069792,40.0298881530762,1.99555300056993,24.0700002759695,0.039173825818186,0.00716271227024752,0.25,2.45042145384313E-5,0.00347216429374464,3.45602201686744E-5,100.1615,100.1615,62729.75390625,62735.07421875,55.1806285721405,19.5391869189689,8.482265,0,0,0,40,4961,100.16175,62732.4140625,,,,,,,,,,,,,0,,,,,,,,,,,,,,
,20397495.51,100.1475,66785.05078125,0.00341803244729677,4.9392285100068E-6,1,0.999253354069792,40.0298881530762,1.99636252304497,24.0700002759695,0.0387922991593316,0.00712898621825402,0.25,2.73858416250769E-5,0.00343755108421787,3.73053450549659E-5,100.1475,100.1475,66782.4375,66787.6640625,55.3330461333905,19.5260448176666,8.482265,0,0,0,40,4961,100.1475,66785.05078125,,,,,,,,,,,,,0,,,,,,,,,,,,,,
,20397573.86,100.1271,70700.58203125,0.00338663505796753,6.12541971435976E-6,1,0.999253354069792,40.0298881530762,1.99596185363536,24.0800008177757,0.0384401380703894,0.00699790461650947,0.25,2.15273588018146E-5,0.00340601336103092,3.12726678113026E-5,100.1274,100.1274,70670.578125,70730.5859375,54.0191285925634,19.5375109132609,8.861917,0,0,0,40,4961,100.1271,70700.58203125,,,,,,,,,,,,,0,,,,,,,,,,,,,,
,20397655.005,100.10475,74756.31640625,0.00334467071263107,5.79914039518233E-6,1,0.999253354069792,40.0298881530762,1.99561113516124,24.0700002759695,0.0379750464120343,0.00681131081584228,0.25,1.26190584479017E-5,0.00336385669705877,2.21419382740927E-5,100.1034,100.1034,74728.859375,74783.7734375,55.2134569699482,19.5243079696235,8.861917,0,0,0,40,4961,100.10475,74756.31640625,,,,,,,,,,,,,0,,,,,,,,,,,,,,
,20397730.995,100.08855,78554.8125,0.00330007560175295,5.50559394162869E-6,1,0.999253354069792,40.0298881530762,1.99578539089898,24.0700002759695,0.0374712782043537,0.00672566954903646,0.25,1.29019209423455E-5,0.00331902585200511,2.22515588707313E-5,100.0891,100.0891,78522.546875,78587.078125,55.1681225158328,19.525369955579,9.241568,0,0,0,40,4961,100.08855,78554.8125,,,,,,,,,,,,,0,,,,,,,,,,,,,,
,20397802.915,100.07695,82149.06640625,0.00326822939740481,5.55786845303077E-6,1,0.999253354069792,40.0298881530762,1.99578873953164,24.0700002759695,0.0371100715035767,0.00666016509358183,0.25,1.27662845043544E-5,0.00328701667035552,2.1979298644378E-5,100.0772,100.0772,82121.5625,82176.5703125,54.8968974196597,19.5284259709637,8.482265,0,0,0,40,4961,100.07695,82149.06640625,,,,,,,,,,,,,0,,,,,,,,,,,,,,
,20397874.805,100.06405,85742.50390625,0.00323138537513265,5.14860120574852E-6,1,0.999253354069792,40.0298881530762,1.99664846973824,24.0700002759695,0.0367111681269979,0.00656418443926372,0.25,1.05877625692467E-5,0.00324998604104062,1.96395907694196E-5,100.0634,100.0634,85720.1484375,85764.859375,54.6803863198327,19.5358549993183,8.861917,0,0,0,40,4961,100.06405,85742.50390625,,,,,,,,,,,,,0,,,,,,,,,,,,,,
,20397944.95,100.05485,89248.57421875,0.00318086358427868,8.1231098255321E-6,1,0.999253354069792,40.0298881530762,1.99657878081799,24.0700002759695,0.0361372661198584,0.00645532248293155,0.25,9.93364555013772E-6,0.00319919335821604,1.87969059239948E-5,100.0559,100.0559,89218.6875,89278.4609375,54.2372029494288,19.5376662845245,8.861917,0,0,0,40,4961,100.05485,89248.57421875,,,,,,,,,,,,,0,,,,,,,,,,,,,,
,20398034.61,100.05135,87088.734375,0.00319798555420012,5.90150024469573E-6,1,0.999253354069792,40.0298881530762,1.99627112936699,24.0700002759695,0.0363325670718138,0.00645345240971769,0.25,6.82266491210237E-6,0.00321641139603327,1.5744036354549E-5,100.0519,100.0519,87063.8359375,87113.6328125,54.9570828156404,19.5289971342628,9.241568,0,0,0,40,4961,100.05135,87088.734375,,,,,,,,,,,,,0,,,,,,,,,,,,,,
,20398104.905,100.0534,83572.0703125,0.00323635541718756,5.70496582586919E-6,1,0.999253354069792,40.0298881530762,1.99591549070801,24.0700002759695,0.0367534564778289,0.00657857915283447,0.25,1.11570148569058E-5,0.00325497154492272,2.02561447131049E-5,100.0531,100.0531,83569.7109375,83574.4296875,55.1290410898712,19.5364617462538,8.861917,0,0,0,40,4961,100.0534,83572.0703125,,,,,,,,,,,,,0,,,,,,,,,,,,,,
,20398176.75,100.05915,79983.1328125,0.00328815735826389,4.73656482507922E-6,1,0.999253354069792,40.0298881530762,1.99563352953526,24.0700002759695,0.0373205725977238,0.00677362474370848,0.25,1.92702613305516E-5,0.00330702934057541,2.86081321908613E-5,100.0594,100.0594,79955.8515625,80010.4140625,55.2767688800059,19.5339122039674,8.482265,0,0,0,40,4961,100.05915,79983.1328125,,,,,,,,,,,,,0,,,,,,,,,,,,,,
,20398249.33,100.06965,76354.65234375,0.00332711239706818,4.67529424035778E-6,1,0.999253354069792,40.0298881530762,1.9956261140519,24.0700002759695,0.0377971027385796,0.00665573104408122,0.25,2.01702665283324E-6,0.00334623666789966,1.14128143867801E-5,100.0681,100.0681,76331.921875,76377.3828125,55.4862453231597,19.5254900124164,8.861917,0,0,0,40,4961,100.06965,76354.65234375,,,,,,,,,,,,,0,,,,,,,,,,,,,,
,20398321.86,100.0754,72730.6171875,0.00336230013764937,6.27251956131303E-6,1,0.999253354069792,40.0298881530762,1.99554896701786,24.0700002759695,0.0381675533690426,0.00688341794435403,0.25,1.58601141920168E-5,0.00338156686596062,2.54837306527528E-5,100.0736,100.0736,72703.1484375,72758.0859375,54.5412564434096,19.52852164793,9.241568,0,0,0,40,4961,100.0754,72730.6171875,,,,,,,,,,,,,0,,,,,,,,,,,,,,
,20398399.695,100.0836,68837.40234375,0.00340265227916986,5.46210524443977E-6,1,0.999253354069792,40.0298881530762,1.99589763896057,24.0700002759695,0.0386297702326888,0.00697872046360246,0.25,1.70164753994376E-5,0.00342212470810636,2.68140518205204E-5,100.0846,100.0846,68834.890625,68839.9140625,55.7605969334098,19.5378418771763,8.861917,0,0,0,40,4961,100.0836,68837.40234375,,,,,,,,,,,,,0,,,,,,,,,,,,,,
,20398480.275,100.08875,64811.697265625,0.00343453750567494,4.9790533911233E-6,1,0.999253354069792,40.0298881530762,1.99614697416688,24.0700002759695,0.0389785566668078,0.00714508646447701,0.25,2.59358001981513E-5,0.00345414340075904,3.59310702241559E-5,100.0887,100.0887,64781.68359375,64841.7109375,55.2251813977366,19.5216405625551,8.861917,0,0,0,40,4961,100.08875,64811.697265625,,,,,,,,,,,,,0,,,,,,,,,,,,,,
,20398560.295,100.094,60810.708984375,0.00346033364605433,4.39673810028288E-6,1,0.999253354069792,40.0298881530762,1.99601579926991,24.0700002759695,0.0392961447844981,0.00704122946221826,0.25,1.22567423538991E-5,0.00348010262079649,2.2303258892352E-5,100.0942,100.0942,60783.3125,60838.10546875,55.1759388010251,19.5179217812494,9.241568,0,0,0,40,4961,100.094,60810.708984375,,,,,,,,,,,,,0,,,,,,,,,,,,,,
,20398639.28,100.0981,56862.271484375,0.00348029188745233,4.49755195700739E-6,1,0.999253354069792,40.0298881530762,1.99617566644025,24.0700002759695,0.0394939605831225,0.00726227087511279,0.25,2.8106190068879E-5,0.00350010528280605,3.83561354030318E-5,100.0977,100.0977,56835.0859375,56889.45703125,54.556107385275,19.5292864660783,8.482265,0,0,0,40,4961,100.0981,56862.271484375,,,,,,,,,,,,,0,,,,,,,,,,,,,,
,20398720.35,100.10195,52812.01171875,0.00350188594311757,3.92267804037294E-6,1,0.999253354069792,40.0298881530762,1.99614220863582,24.0700002759695,0.0397654746306605,0.00715119284664136,0.25,1.4498584258239E-5,0.00352183749995054,2.47902388767389E-5,100.1019,100.1019,52807.33984375,52816.68359375,55.3330461333905,19.5318399409094,8.482265,0,0,0,40,4961,100.10195,52812.01171875,,,,,,,,,,,,,0,,,,,,,,,,,,,,
,20398801.23,100.10425,48768.98046875,0.00350416814101943,3.72037731653954E-6,1,0.999253354069792,40.0298881530762,1.99607992775426,24.0700002759695,0.0397786319723469,0.00721992337881165,0.25,2.01128685743794E-5,0.00352409153064145,3.05000047316538E-5,100.104,100.104,48739.18359375,48798.77734375,55.3049075066982,19.5305770731753,9.241568,0,0,0,40,4961,100.10425,48768.98046875,,,,,,,,,,,,,0,,,,,,,,,,,,,,
,20398882.315,100.10815,44716.353515625,0.00352580047960322,3.68802954213371E-6,1,0.999253354069792,40.0298881530762,1.99569610480759,24.0700002759695,0.040011547723406,0.00729171908797038,0.25,2.26986822101257E-5,0.00354581456163364,3.32205892823278E-5,100.1072,100.1072,44686.4140625,44746.29296875,55.5605000324866,19.5350760426105,8.861917,0,0,0,40,4961,100.10815,44716.353515625,,,,,,,,,,,,,0,,,,,,,,,,,,,,
,20398962.725,100.1121,40698.505859375,0.00351775368573454,3.56174376737168E-6,1,0.999253354069792,40.0298881530762,1.99587034032544,24.0700002759695,0.0399337619383001,0.00721594478700984,0.25,1.73380502989005E-5,0.00353771305134336,2.78612788746099E-5,100.1121,100.1121,40668.32421875,40728.6875,54.921909532275,19.5306488445138,8.861917,0,0,0,40,4961,100.1121,40698.505859375,,,,,,,,,,,,,0,,,,,,,,,,,,,,
,20399043.26,100.1157,36672.994140625,0.00351192717439421,2.96818788942903E-6,1,0.999253354069792,40.0298881530762,1.99532127350035,24.0700002759695,0.0398505012349437,0.00723833965870592,0.25,2.04490815856552E-5,0.00353181952206285,3.10278160584051E-5,100.1157,100.1157,36670.5390625,36675.44921875,54.8890811344673,19.5333631420685,9.241568,0,0,0,40,4961,100.1157,36672.994140625,,,,,,,,,,,,,0,,,,,,,,,,,,,,
,20399122.27,100.12205,32725.1142578125,0.00350031368435185,2.53531144011183E-6,1,0.999253354069792,40.0298881530762,1.99536514151953,24.0700002759695,0.0397244707057754,0.00718498768241893,0.25,1.77301756460095E-5,0.0035201242521838,2.83115628683858E-5,100.122,100.122,32722.708984375,32727.51953125,55.6793075674097,19.5317231280917,8.861917,0,0,0,40,4961,100.12205,32725.1142578125,,,,,,,,,,,,,0,,,,,,,,,,,,,,
,20399202.77,100.12465,28702.5576171875,0.00347588757211947,2.61277275642456E-6,1,0.999253354069792,40.0298881530762,1.99545210285315,24.0700002759695,0.0394485487362535,0.00713558802588728,0.25,1.75965805127494E-5,0.00349553594140224,2.81572672453626E-5,100.1241,100.1241,28669.947265625,28735.16796875,55.5417409480251,19.5360073817359,8.861917,0,0,0,40,4961,100.12465,28702.5576171875,,,,,,,,,,,,,0,,,,,,,,,,,,,,
,20399283.145,100.1306,24684.1240234375,0.00343303880187673,2.66954901625007E-6,1,0.999253354069792,40.0298881530762,1.99549667903415,24.0700002759695,0.0389576724525852,0.00707702072748113,0.25,1.99076069266163E-5,0.00345241397514968,3.04033295243101E-5,100.1304,100.1304,24656.576171875,24711.671875,56.2530229005252,19.5323263549886,8.482265,0,0,0,40,4961,100.1306,24684.1240234375,,,,,,,,,,,,,0,,,,,,,,,,,,,,
,20399361.225,100.13265,20778.7802734375,0.00338105797335851,2.59104672788367E-6,1,0.999253354069792,40.0298881530762,1.99532875474952,24.0700002759695,0.0383695282116353,0.00694048272976723,0.25,1.70244323438972E-5,0.00340012561139226,2.73948628563936E-5,100.1321,100.1321,20748.845703125,20808.71484375,56.1131113955829,19.5396087707954,8.861917,0,0,0,40,4961,100.13265,20778.7802734375,,,,,,,,,,,,,0,,,,,,,,,,,,,,
,20399441.39,100.1385,16773.640625,0.00331476638265922,1.60422545984689E-6,1,0.999253354069792,40.0298881530762,1.99521244350439,24.0700002759695,0.0376171957943865,0.00679086644456112,0.25,1.54896974230935E-5,0.00333344230022817,2.56964399118524E-5,100.1379,100.1379,16746.138671875,16801.142578125,55.3244482196789,19.5422544292147,8.861917,0,0,0,40,4961,100.1385,16773.640625,,,,,,,,,,,,,0,,,,,,,,,,,,,,
,20399521.26,100.1408,12783.544921875,0.00322810700916401,1.24285558301379E-6,1,0.999253354069792,40.0298881530762,1.99508186009475,24.0700002759695,0.0366283251823929,0.00662945287593916,0.25,1.65006188053186E-5,0.00324627012812807,2.64923730152879E-5,100.1407,100.1407,12753.109375,12813.98046875,55.6691463966597,19.5540483794398,8.861917,0,0,0,40,4961,100.1408,12783.544921875,,,,,,,,,,,,,0,,,,,,,,,,,,,,
,20399593.975,100.14505,9148.43212890625,0.00312771678968107,9.71903782651144E-7,1,0.999253354069792,40.0298881530762,1.9955160553418,24.0700002759695,0.0354967429200718,0.00642269225474657,0.25,1.57845701214678E-5,0.00314529868295072,2.5500809497803E-5,100.1454,100.1454,9115.76171875,9181.1025390625,55.4237150416212,19.5277618586408,8.861917,0,0,0,40,4961,100.14505,9148.43212890625,,,,,,,,,,,,,0,,,,,,,,,,,,,,
,20399666.065,100.14695,5544.91333007812,0.00299854322131335,6.908530844427E-7,1,0.999253354069792,40.0298881530762,1.99569045111301,24.0700002759695,0.0340336922018858,0.00615631422345596,0.25,1.49589334511096E-5,0.00301538443903933,2.43053267772952E-5,100.1464,100.1464,5517.36669921875,5572.4599609375,55.5526837472943,19.5238890503851,9.241568,0,0,0,40,4961,100.14695,5544.91333007812,,,,,,,,,,,,,0,,,,,,,,,,,,,,
,20399738.25,100.1519,1938.60223388672,0.00281564509001924,6.89078608820417E-7,1,0.999253354069792,40.0298881530762,1.99526380386775,24.0700002759695,0.031950738552126,0.00578179516305672,0.25,1.42136044454947E-5,0.00283144614137255,2.30169863437053E-5,100.1514,100.1514,1908.57641601562,1968.62805175781,55.3307012478328,19.5262120928058,9.241568,0,0,0,40,4961,100.1519,1938.60223388672,,,,,,,,,,,,,0,,,,,,,,,,,,,,
,20399810,100.1566,-1647.24371337891,0.00252445601142722,5.98181695356425E-7,1,0.999253354069792,40.0298881530762,1.99566912716741,24.0700002759695,0.0286512926315348,0.00518885489703372,0.25,1.30946555139671E-5,0.00253862112286373,2.09906315829314E-5,100.1567,100.1567,-1677.2978515625,-1617.18957519531,55.1446736602558,19.5128095471328,9.241568,0,0,0,40,4961,100.1566,-1647.24371337891,,,,,,,,,,,,,0,,,,,,,,,,,,,,
,20399881.055,100.1537,-5197.51342773438,0.0020311400391369,7.9837269065545E-7,1,0.999253354069792,40.0298881530762,1.99571166185887,24.0700002759695,0.0230520517853151,0.00418022195298181,0.25,1.10157170803936E-5,0.00204254426607341,1.73529808110062E-5,100.1542,100.1542,-5219.95654296875,-5175.0703125,55.6816524529674,19.5244901501247,8.482265,0,0,0,40,4961,100.1537,-5197.51342773438,,,,,,,,,,,,,0,,,,,,,,,,,,,,
,20399953.635,100.15285,-8825.8779296875,0.00118033282335417,1.20145477453899E-6,1,0.999253354069792,40.0298881530762,1.99545506710162,24.0700002759695,0.0133938262073786,0.00243214706757835,0.25,6.69850375806598E-6,0.00118696505089714,1.03700859162264E-5,100.1531,100.1531,-8848.4580078125,-8803.2978515625,54.6710067776019,19.5420808033196,9.241568,0,0,0,40,4961,100.15285,-8825.8779296875,,,,,,,,,,,,,0,,,,,,,,,,,,,,
,20400025.805,100.14705,-12434.2578125,-8.16714416950172E-5,1.44739521465866E-6,1,0.999253354069792,40.0298881530762,1.99510119990881,24.0700002759695,-0.000924670488182829,-0.000179325566681453,0.25,-1.43864334456256E-6,-8.21277963796455E-5,-1.69726506602594E-6,100.1469,100.1469,-12461.75390625,-12406.76171875,56.394497662506,19.5290432250718,8.861917,0,0,0,40,4961,100.14705,-12434.2578125,,,,,,,,,,,,,0,,,,,,,,,,,,,,
,20400097.72,100.14085,-16027.3017578125,-0.00143496830088193,1.55270377070778E-6,1,0.999253354069792,40.0298881530762,1.99519943543725,24.0700002759695,-0.016286200651772,-0.00292968503453301,0.25,-5.81519702450541E-6,-0.00144305416162655,-1.02322537539469E-5,100.1404,100.1404,-16059.6669921875,-15994.9365234375,55.2681709662943,19.5314460958244,9.241568,0,0,0,40,4961,100.14085,-16027.3017578125,,,,,,,,,,,,,0,,,,,,,,,,,,,,
,20400170.005,100.13375,-19640.6298828125,-0.00244546288569695,2.24227917332136E-6,1,0.999253354069792,40.0298881530762,1.99558973364193,24.0700002759695,-0.0277529699016785,-0.00503469079723065,0.25,-1.35481313674863E-5,-0.0024592458696707,-2.10657956148948E-5,100.1344,100.1344,-19668.146484375,-19613.11328125,54.9203462752366,19.5425370666503,8.482265,0,0,0,40,4961,100.13375,-19640.6298828125,,,,,,,,,,,,,0,,,,,,,,,,,,,,
,20400242.57,100.1256,-23266.2890625,-0.00300284662049751,2.0534613164962E-6,1,0.999253354069792,40.0298881530762,1.99530861549675,24.0700002759695,-0.0340727324249148,-0.00618980156778804,0.25,-1.74114058033752E-5,-0.00301978671663391,-2.66084812963886E-5,100.1262,100.1262,-23295.966796875,-23236.611328125,55.547993976179,19.5259282790785,8.861917,0,0,0,40,4961,100.1256,-23266.2890625,,,,,,,,,,,,,0,,,,,,,,,,,,,,
,20400317.1,100.11925,-26989.1884765625,-0.00326440705790719,2.2885294760866E-6,1,0.999253354069792,40.0298881530762,1.99569774666407,24.0700002759695,-0.0370433051522523,-0.00675546348385565,0.25,-2.11913444871211E-5,-0.00328283634236162,-3.11580304245963E-5,100.1197,100.1197,-27009.150390625,-26969.2265625,54.8820464777943,19.542382396425,8.861917,0,0,0,40,4961,100.11925,-26989.1884765625,,,,,,,,,,,,,0,,,,,,,,,,,,,,
,20400390.75,100.11195,-30671.615234375,-0.00338622008494317,2.62297512352169E-6,1,0.999253354069792,40.0298881530762,1.9956121012463,24.0700002759695,-0.0384234043288134,-0.00701217541593481,0.25,-2.24570782879724E-5,-0.00340535695747425,-3.27521893833954E-5,100.1122,100.1122,-30696.60546875,-30646.625,55.2329976829289,19.5438653577721,8.861917,0,0,0,40,4961,100.11195,-30671.615234375,,,,,,,,,,,,,0,,,,,,,,,,,,,,
,20400463.805,100.10175,-34321.974609375,-0.0034511548718758,3.17137998883095E-6,1,0.999253354069792,40.0298881530762,1.99546193864053,24.0700002759695,-0.0391611223031715,-0.00712640313247001,0.25,-2.11941339634181E-5,-0.00347068552762625,-3.16301620095805E-5,100.1019,100.1019,-34344.34765625,-34299.6015625,55.3947947864097,19.5444170437996,9.241568,0,0,0,40,4961,100.10175,-34321.974609375,,,,,,,,,,,,,0,,,,,,,,,,,,,,
,20400537.13,100.0931,-37986.958984375,-0.00348749392715761,2.99927064065943E-6,1,0.999253354069792,40.0298881530762,1.99570525268316,24.0700002759695,-0.0395848459769364,-0.00716519777857636,0.25,-1.81978165283717E-5,-0.00350726203276975,-2.8676923862925E-5,100.092,100.092,-38016.75,-37957.16796875,55.5730060887943,19.5430304213883,8.482265,0,0,0,40,4961,100.0931,-37986.958984375,,,,,,,,,,,,,0,,,,,,,,,,,,,,
,20400610.875,100.08355,-41672.76171875,-0.00350444045462509,3.77716599102978E-6,1,0.999253354069792,40.0298881530762,1.99574841033981,24.0700002759695,-0.0397595239991246,-0.00730696546447951,0.25,-2.77320808814749E-5,-0.00352429917850252,-3.82664175045141E-5,100.0828,100.0828,-41705.21484375,-41640.30859375,55.5386144339482,19.5372305045921,8.482265,0,0,0,40,4961,100.08355,-41672.76171875,,,,,,,,,,,,,0,,,,,,,,,,,,,,
,20400685.315,100.0753,-45393.47265625,-0.00349715645229668,4.06920627653219E-6,1,0.999253354069792,40.0298881530762,1.99596194788848,24.0700002759695,-0.0397072393203631,-0.00714423527979185,0.25,-1.46701287980631E-5,-0.00351703513164053,-2.50580417704159E-5,100.0747,100.0747,-45418.49609375,-45368.44921875,54.5889357830827,19.5451608005172,9.241568,0,0,0,40,4961,100.0753,-45393.47265625,,,,,,,,,,,,,0,,,,,,,,,,,,,,
,20400758.425,100.0701,-49048.71875,-0.00349605312901019,4.25166954438956E-6,1,0.999253354069792,40.0298881530762,1.99542313187244,24.0700002759695,-0.0396840186628589,-0.00714426360693221,0.25,-1.5074804545266E-5,-0.00351594669664128,-2.54112808687884E-5,100.0703,100.0703,-49081.13671875,-49016.30078125,55.7113543366982,19.5464144196369,8.861917,0,0,0,40,4961,100.0701,-49048.71875,,,,,,,,,,,,,0,,,,,,,,,,,,,,
,20400832.595,100.0644,-52753.5703125,-0.00348576503855695,4.08749799743971E-6,1,0.999253354069792,40.0298881530762,1.99534951146621,24.0700002759695,-0.039558635432168,-0.00716553811352737,0.25,-1.88232871785446E-5,-0.00350561160161726,-2.90997478256787E-5,100.0644,100.0644,-52758.734375,-52748.40625,55.5214186065251,19.541769106761,9.241568,0,0,0,40,4961,100.0644,-52753.5703125,,,,,,,,,,,,,0,,,,,,,,,,,,,,
,20400904.265,100.0556,-56336.87109375,-0.00346686274444591,3.52098662643127E-6,1,0.999253354069792,40.0298881530762,1.99530328872378,24.0700002759695,-0.0393461308468388,-0.00711155093505831,0.25,-1.74480584004967E-5,-0.00348662715744108,-2.76125486550708E-5,100.0565,100.0565,-56366.4609375,-56307.28125,55.9560040632175,19.5474745570372,9.241568,0,0,0,40,4961,100.0556,-56336.87109375,,,,,,,,,,,,,0,,,,,,,,,,,,,,
,20400978.38,100.0513,-60039.73046875,-0.00345092582533714,4.97503954961361E-6,1,0.999253354069792,40.0298881530762,1.99539984205656,24.0700002759695,-0.0391665490483187,-0.00708361716227083,0.25,-1.78051216366482E-5,-0.0034706204469683,-2.78740355106957E-5,100.051,100.051,-60069.68359375,-60009.77734375,54.5521992426788,19.544029344896,8.861917,0,0,0,40,4961,100.0513,-60039.73046875,,,,,,,,,,,,,0,,,,,,,,,,,,,,
,20401052.885,100.04515,-63762.87109375,-0.00341600599896218,4.90878074035832E-6,1,0.999253354069792,40.0298881530762,1.99571370980263,24.0700002759695,-0.0387701663589273,-0.00704794264490085,0.25,-2.07481159394617E-5,-0.00343551451992797,-3.06820764245447E-5,100.0458,100.0458,-63792.94140625,-63732.80078125,55.6558587118328,19.5363674620274,8.861917,0,0,0,40,4961,100.04515,-63762.87109375,,,,,,,,,,,,,0,,,,,,,,,,,,,,
,20401126.615,100.03775,-67448.08984375,-0.00338602414991166,4.85664056019366E-6,1,0.999253354069792,40.0298881530762,1.99546542988711,24.0700002759695,-0.0384285694863977,-0.00696818222990063,0.25,-1.91091412166169E-5,-0.00340538732239831,-2.88976855578789E-5,100.0373,100.0373,-67480.59375,-67415.5859375,56.8204852054868,19.5388461885612,8.861917,0,0,0,40,4961,100.03775,-67448.08984375,,,,,,,,,,,,,0,,,,,,,,,,,,,,
,20401200.065,100.0298,-71117.98828125,-0.00335269504370007,4.95984666069747E-6,1,0.999253354069792,40.0298881530762,1.99471122749865,24.0700002759695,-0.0380603167237597,-0.00676327071698442,0.25,-7.181471571739E-6,-0.00337192230086051,-1.67571048001126E-5,100.0302,100.0302,-71147.9296875,-71088.046875,55.1563980880443,19.5557693193439,9.241568,0,0,0,40,4961,100.0298,-71117.98828125,,,,,,,,,,,,,0,,,,,,,,,,,,,,
,20401274.585,100.0247,-74842.91796875,-0.00331991748819587,5.70967933746242E-6,1,0.999253354069792,40.0298881530762,1.99481447414122,24.0700002759695,-0.0376958570487038,-0.0066659648438346,0.25,-4.38235962230799E-6,-0.0033389855870244,-1.37987237176048E-5,100.0247,100.0247,-74870.6171875,-74815.21875,56.1795498197175,19.5501540855866,9.241568,0,0,0,40,4961,100.0247,-74842.91796875,,,,,,,,,,,,,0,,,,,,,,,,,,,,
,20401351.245,100.0178,-78672.7890625,-0.00328730391106638,4.93170764996794E-6,1,0.999253354069792,40.0298881530762,1.99474161064797,24.0700002759695,-0.0373083549879818,-0.00669222521334227,0.25,-1.24846495205971E-5,-0.00330618309451375,-2.1804730873274E-5,100.0178,100.0178,-78678.1171875,-78667.4609375,55.791862074179,19.549959815771,8.861917,0,0,0,40,4961,100.0178,-78672.7890625,,,,,,,,,,,,,0,,,,,,,,,,,,,,
,20401425.13,100.01165,-82366.08203125,-0.00325144185261146,4.5246792584448E-6,1,0.999253354069792,40.0298881530762,1.99502930976832,24.0700002759695,-0.0368999584793902,-0.00665834745813004,0.25,-1.57577516785665E-5,-0.00327012585215984,-2.49474886393016E-5,100.0113,100.0113,-82396.2109375,-82335.953125,55.5519021187751,19.5431167827008,8.482265,0,0,0,40,4961,100.01165,-82366.08203125,,,,,,,,,,,,,0,,,,,,,,,,,,,,
,20401497.475,100.0088,-85981.47265625,-0.00321106954276515,5.74366769960376E-6,1,0.999253354069792,40.0298881530762,1.9946411302639,24.0700002759695,-0.0364485435571872,-0.00649860848243857,0.25,-8.92718533216762E-6,-0.00322955953986608,-1.79174819916688E-5,100.0076,100.0076,-86009.1640625,-85953.78125,55.5057860361405,19.5528525121895,9.241568,0,0,0,40,4961,100.0088,-85981.47265625,,,,,,,,,,,,,0,,,,,,,,,,,,,,
,20401568.825,100.0041,-89546.26171875,-0.00316741256397086,6.38217970956293E-6,1,0.999253354069792,40.0298881530762,1.99482842379928,24.0700002759695,-0.0359287855450233,-0.00656846462355859,0.25,-2.27271728371752E-5,-0.00318563139259922,-3.16300943789861E-5,100.0042,100.0042,-89551.4453125,-89541.078125,55.7019747944674,19.5463911502722,8.861917,0,0,0,40,4961,100.0041,-89546.26171875,,,,,,,,,,,,,0,,,,,,,,,,,,,,
,20401654.54,100.00395,-86919.34765625,-0.00319827520542873,6.34979179777203E-6,1,0.999253354069792,40.0298881530762,1.99488832525454,24.0700002759695,-0.0362910886244893,-0.00656799710518992,0.25,-1.72239813313211E-5,-0.00321667340286083,-2.6214920395229E-5,100.0041,100.0041,-86949.2265625,-86889.46875,55.4315313268135,19.544922905346,9.241568,0,0,0,40,4961,100.00395,-86919.34765625,,,,,,,,,,,,,0,,,,,,,,,,,,,,
,20401726.39,100.0059,-83326.41015625,-0.00323029908480104,5.2781373832845E-6,1,0.999253354069792,40.0298881530762,1.99473424676868,24.0700002759695,-0.0366771579348334,-0.00648724158407398,0.25,-4.49450611697182E-6,-0.00324889805816871,-1.3548303369541E-5,100.0061,100.0061,-83356.328125,-83296.4921875,56.3014838687175,19.5399375015166,9.241568,0,0,0,40,4961,100.0059,-83326.41015625,,,,,,,,,,,,,0,,,,,,,,,,,,,,
,20401802.385,100.00755,-79530.94921875,-0.00326263768458689,5.99657205253143E-6,1,0.999253354069792,40.0298881530762,1.99453291053323,24.0700002759695,-0.0369974056073185,-0.0067973095483241,0.25,-2.61344104133929E-5,-0.00328134140810709,-3.54536648377036E-5,100.0072,100.0072,-79558.5625,-79503.3359375,55.4620148390636,19.5377804856803,8.861917,0,0,0,40,4961,100.00755,-79530.94921875,,,,,,,,,,,,,0,,,,,,,,,,,,,,
,20401876.075,100.01085,-75848.25390625,-0.00332069931662827,6.02012752260357E-6,1,0.999253354069792,40.0298881530762,1.99512277362414,24.0700002759695,-0.0376858187227854,-0.00680839675101079,0.25,-1.67085393337582E-5,-0.00333974284427646,-2.61863401427758E-5,100.0117,100.0117,-75875.796875,-75820.7109375,55.7348031922751,19.5349060495209,8.482265,0,0,0,40,4961,100.01085,-75848.25390625,,,,,,,,,,,,,0,,,,,,,,,,,,,,
,20401949.64,100.01245,-72167.98046875,-0.0033501823006377,5.06145236399277E-6,1,0.999253354069792,40.0298881530762,1.9948325801423,24.0700002759695,-0.0379800230155125,-0.00706658463205637,0.25,-3.43054907185538E-5,-0.00336932421168874,-4.40179504972538E-5,100.0113,100.0113,-72197.9453125,-72138.015625,55.3017809926212,19.5413130567264,9.241568,0,0,0,40,4961,100.01245,-72167.98046875,,,,,,,,,,,,,0,,,,,,,,,,,,,,
,20402024.495,100.0156,-68428.3046875,-0.00338210285980925,5.38639479630484E-6,1,0.999253354069792,40.0298881530762,1.99520417896348,24.0700002759695,-0.038361304398896,-0.00706199175726455,0.25,-2.81416711400942E-5,-0.00340142360056927,-3.79606866438039E-5,100.0155,100.0155,-68430.953125,-68425.65625,55.2580097955443,19.5428036376437,8.861917,0,0,0,40,4961,100.0156,-68428.3046875,,,,,,,,,,,,,0,,,,,,,,,,,,,,
,20402096.665,100.02205,-64822.375,-0.00340671020700621,3.88400310530695E-6,1,0.999253354069792,40.0298881530762,1.99510417097133,24.0700002759695,-0.0386571164734533,-0.0070059100231543,0.25,-1.88699807694682E-5,-0.00342617723928692,-2.87553667863039E-5,100.0216,100.0216,-64822.375,-64822.375,56.0795013692559,19.5352227386208,9.241568,0,0,0,40,4961,100.02205,-64822.375,,,,,,,,,,,,,0,,,,,,,,,,,,,,
,20402169.57,100.02455,-61177.072265625,-0.00342952252284724,3.71541693059367E-6,1,0.999253354069792,40.0298881530762,1.99473823451421,24.0700002759695,-0.0389077747093403,-0.00705805805034776,0.25,-1.95192874200932E-5,-0.00344909660842298,-2.95245809675908E-5,100.0239,100.0239,-61209.6875,-61144.45703125,55.290838193352,19.5349156014764,8.482265,0,0,0,40,4961,100.02455,-61177.072265625,,,,,,,,,,,,,0,,,,,,,,,,,,,,
,20402243.45,100.0273,-57484.1171875,-0.00345985166839779,4.25278801251969E-6,1,0.999253354069792,40.0298881530762,1.99556796247815,24.0700002759695,-0.0392721409191533,-0.00709506286644987,0.25,-1.71585244500947E-5,-0.00347958383846495,-2.72894947565508E-5,100.0271,100.0271,-57511.55078125,-57456.68359375,56.3093001539098,19.537153193593,8.861917,0,0,0,40,4961,100.0273,-57484.1171875,,,,,,,,,,,,,0,,,,,,,,,,,,,,
,20402317.1,100.03085,-53804.169921875,-0.00346686269099546,4.61955262425377E-6,1,0.999253354069792,40.0298881530762,1.99490915226256,24.0700002759695,-0.0393457600579267,-0.00706905064256413,0.25,-1.37869910140789E-5,-0.00348662241627675,-2.39703565127724E-5,100.0304,100.0304,-53834.15234375,-53774.1875,55.680089195929,19.537682379693,9.241568,0,0,0,40,4961,100.03085,-53804.169921875,,,,,,,,,,,,,0,,,,,,,,,,,,,,
,20402389.855,100.03685,-50169.19140625,-0.0034910079467313,3.96507588663783E-6,1,0.999253354069792,40.0298881530762,1.99511735649974,24.0700002759695,-0.0396358323719925,-0.00704862234127807,0.25,-7.64101522919577E-6,-0.00351090134829525,-1.79101265583168E-5,100.0359,100.0359,-50201.4609375,-50136.921875,56.4062220902944,19.5415308473984,8.861917,0,0,0,40,4961,100.03685,-50169.19140625,,,,,,,,,,,,,0,,,,,,,,,,,,,,
,20402462.105,100.0388,-46558.568359375,-0.00350130133925203,3.55042640495306E-6,1,0.999253354069792,40.0298881530762,1.99442286108156,24.0700002759695,-0.0397283111538892,-0.00712927513740623,0.25,-1.30966974367964E-5,-0.00352121533971807,-2.34777454616557E-5,100.0389,100.0389,-46588.5078125,-46528.62890625,55.3017809926212,19.5398181287541,9.241568,0,0,0,40,4961,100.0388,-46558.568359375,,,,,,,,,,,,,0,,,,,,,,,,,,,,
,20402535.03,100.0472,-42912.751953125,-0.00351562427901576,3.66329186064199E-6,1,0.999253354069792,40.0298881530762,1.99473445356257,24.0700002759695,-0.0398955514293272,-0.00716501915534244,0.25,-1.35898838202549E-5,-0.00353559602219634,-2.40658220898479E-5,100.0472,100.0472,-42915.46875,-42910.03515625,55.720733878929,19.5408346524946,8.861917,0,0,0,40,4961,100.0472,-42912.751953125,,,,,,,,,,,,,0,,,,,,,,,,,,,,
,20402607.79,100.05215,-39277.439453125,-0.00349974609856676,3.48307545711622E-6,1,0.999253354069792,40.0298881530762,1.99420451694402,24.0700002759695,-0.0397113093599086,-0.00709512930429097,0.25,-1.03364418637719E-5,-0.00351961491335805,-2.07966477560009E-5,100.0509,100.0509,-39302.5859375,-39252.29296875,55.6738361677751,19.5365294691236,9.241568,0,0,0,40,4961,100.05215,-39277.439453125,,,,,,,,,,,,,0,,,,,,,,,,,,,,
,20402679.655,100.0551,-35687.0546875,-0.00349508164095173,3.42340325168542E-6,1,0.999253354069792,40.0298881530762,1.99399760780893,24.0700002759695,-0.039646381775238,-0.00712949869931278,0.25,-1.42003097406355E-5,-0.00351489061003273,-2.47175348367374E-5,100.0555,100.0555,-35719.57421875,-35654.53515625,55.524545120602,19.5332744211553,9.241568,0,0,0,40,4961,100.0551,-35687.0546875,,,,,,,,,,,,,0,,,,,,,,,,,,,,
,20402751.705,100.06115,-32084.783203125,-0.00347700252882806,3.01313821364666E-6,1,0.999253354069792,40.0298881530762,1.99495719776048,24.0700002759695,-0.0394500546119514,-0.00714777126829428,0.25,-1.86525132072725E-5,-0.00349667380598515,-2.91887240786902E-5,100.0617,100.0617,-32112.373046875,-32057.193359375,54.9719337575058,19.5399737203225,8.861917,0,0,0,40,4961,100.06115,-32084.783203125,,,,,,,,,,,,,0,,,,,,,,,,,,,,
,20402824.985,100.06605,-28424.4462890625,-0.00345871056943198,2.78081262979236E-6,1,0.999253354069792,40.0298881530762,1.99449828909839,24.0700002759695,-0.0392397315391684,-0.00707396133250217,0.25,-1.54592904357982E-5,-0.00347826592688966,-2.59702536248777E-5,100.0662,100.0662,-28454.509765625,-28394.3828125,54.9109667330058,19.5325502594363,8.482265,0,0,0,40,4961,100.06605,-28424.4462890625,,,,,,,,,,,,,0,,,,,,,,,,,,,,
,20402897.775,100.07225,-24786.185546875,-0.00342188281987868,2.0834652192877E-6,1,0.999253354069792,40.0298881530762,1.99444568754867,24.0700002759695,-0.0388176377690921,-0.0070158511592734,0.25,-1.67841560766307E-5,-0.00344120435825636,-2.72375236105753E-5,100.0711,100.0711,-24816.359375,-24756.01171875,55.7527806482174,19.5344362792849,9.241568,0,0,0,40,4961,100.07225,-24786.185546875,,,,,,,,,,,,,0,,,,,,,,,,,,,,
,20402969.245,100.08065,-21213.216796875,-0.00337555919202118,2.65566587709704E-6,1,0.999253354069792,40.0298881530762,1.99476217555904,24.0700002759695,-0.0383023610233764,-0.0068954676095209,0.25,-1.41877851216185E-5,-0.00339460626935971,-2.45293280445154E-5,100.0819,100.0819,-21243.125,-21183.30859375,55.4276231842174,19.5260793485296,8.861917,0,0,0,40,4961,100.08065,-21213.216796875,,,,,,,,,,,,,0,,,,,,,,,,,,,,
,20403042.645,100.0864,-17545.361328125,-0.00331600512346594,1.63394089306392E-6,1,0.999253354069792,40.0298881530762,1.9948032634204,24.0700002759695,-0.037619444365439,-0.00681759352409806,0.25,-1.77420578515748E-5,-0.00333468471498627,-2.79654249567893E-5,100.0863,100.0863,-17575.669921875,-17515.052734375,55.3486787037751,19.5387561994088,8.861917,0,0,0,40,4961,100.0864,-17545.361328125,,,,,,,,,,,,,0,,,,,,,,,,,,,,
,20403117.06,100.0915,-13827.7163085938,-0.00323586409933443,1.65788492804132E-6,1,0.999253354069792,40.0298881530762,1.99540132838611,24.0700002759695,-0.0367191720831748,-0.00666254125346419,0.25,-1.79634875057539E-5,-0.00325407116098704,-2.79843883325908E-5,100.0914,100.0914,-13857.837890625,-13797.5947265625,55.4924983513136,19.5411411206813,9.621219,0,0,0,40,4961,100.0915,-13827.7163085938,,,,,,,,,,,,,0,,,,,,,,,,,,,,
,20403188.07,100.0968,-10276.8647460938,-0.00314253133859469,1.30356133065681E-6,1,0.999253354069792,40.0298881530762,1.9953603534094,24.0599997341633,-0.0356622895790961,-0.00645253367604383,0.25,-1.58529489113519E-5,-0.00316020115465692,-2.56120065073068E-5,100.0973,100.0973,-10309.3271484375,-10244.40234375,55.7082278226213,19.5419401070736,9.621219,0,0,0,40,4961,100.0968,-10276.8647460938,,,,,,,,,,,,,0,,,,,,,,,,,,,,
,20403260.4,100.10295,-6660.68994140625,-0.00302478875565495,9.42634681272598E-7,1,0.999253354069792,40.0298881530762,1.99515695081885,24.0700002759695,-0.0343217708119477,-0.00621485384220456,0.25,-1.56412246809547E-5,-0.00304177969367377,-2.5069858621001E-5,100.1036,100.1036,-6685.65087890625,-6635.72900390625,54.9109667330058,19.5429944466688,9.621219,0,0,0,40,4961,100.10295,-6660.68994140625,,,,,,,,,,,,,0,,,,,,,,,,,,,,
,20403331.735,100.1056,-3094.66333007812,-0.00286457130070946,5.84498060971348E-7,1,0.999253354069792,40.0298881530762,1.99420931567149,24.0700002759695,-0.0324878220287319,-0.00588924532462317,0.25,-1.53374619410896E-5,-0.00288064740349898,-2.42978261482783E-5,100.1057,100.1057,-3116.923828125,-3072.40283203125,54.942231873775,19.5521521452754,9.241568,0,0,0,40,4961,100.1056,-3094.66333007812,,,,,,,,,,,,,0,,,,,,,,,,,,,,
,20403403.18,100.1105,474.313827514648,-0.00261436274876642,5.69998403086259E-7,1,0.999253354069792,40.0298881530762,1.99467519167532,24.0700002759695,-0.0296574886856679,-0.00537140185586373,0.25,-1.35755452853812E-5,-0.0026290288025483,-2.17657344970355E-5,100.1103,100.1103,451.864685058594,496.762969970703,56.0412015718136,19.5352801535518,8.861917,0,0,0,40,4961,100.1105,474.313827514648,,,,,,,,,,,,,0,,,,,,,,,,,,,,
,20403475.2,100.11435,4070.89916992188,-0.00219258880256808,7.04884077373734E-7,1,0.999253354069792,40.0298881530762,1.99433138389965,24.0700002759695,-0.0248703389741563,-0.00449572582956758,0.25,-1.06657908921436E-5,-0.00220489974902927,-1.75114412175574E-5,100.1134,100.1134,4040.91650390625,4100.8818359375,54.810136654025,19.5459695081168,9.241568,0,0,0,40,4961,100.11435,4070.89916992188,,,,,,,,,,,,,0,,,,,,,,,,,,,,
,20403546.63,100.1114,7642.09838867187,-0.00148104710437717,9.50767825575315E-7,1,0.999253354069792,40.0298881530762,1.99489543910891,24.0800008177757,-0.0168006933835549,-0.00305641655140515,0.25,-8.8764840655307E-6,-0.00148936481493098,-1.34948806745473E-5,100.1121,100.1121,7619.56591796875,7664.630859375,55.497188122429,19.5329067439135,9.241568,0,0,0,40,4961,100.1114,7642.09838867187,,,,,,,,,,,,,0,,,,,,,,,,,,,,
,20403617.66,100.1093,11193.5478515625,-0.000382620908600944,1.64308191532126E-6,1,0.999253354069792,40.0298881530762,1.99505119321017,24.0700002759695,-0.00434374198136849,-0.000772467180218941,0.25,-7.82470419665297E-7,-0.000384776379829073,-1.96281890618428E-6,100.1086,100.1086,11168.3759765625,11218.7197265625,56.2616208142367,19.5308112923903,9.241568,0,0,0,40,4961,100.1093,11193.5478515625,,,,,,,,,,,,,0,,,,,,,,,,,,,,
,20403690.06,100.1054,14811.8852539062,0.000994465885418101,1.66412502938337E-6,1,0.999253354069792,40.0298881530762,1.99535961709391,24.0700002759695,0.0112785675196805,0.00208162264624652,0.25,8.52572574287404E-6,0.00100005378001755,1.16182882603695E-5,100.1047,100.1047,14782.0830078125,14841.6875,55.4463822686789,19.558676882947,9.241568,0,0,0,40,4961,100.1054,14811.8852539062,,,,,,,,,,,,,0,,,,,,,,,,,,,,
,20403761.505,100.09845,18380.126953125,0.00214514086989468,2.35995877746819E-6,1,0.999253354069792,40.0298881530762,1.99500311690636,24.0700002759695,0.0243333588311367,0.00444044641009834,0.25,1.40987832037367E-5,0.00215721979043499,2.07194128391195E-5,100.0981,100.0981,18350.04296875,18410.2109375,54.9391053596981,19.5521103829815,9.241568,0,0,0,40,4961,100.09845,18380.126953125,,,,,,,,,,,,,0,,,,,,,,,,,,,,
,20403835,100.08965,22055.3359375,0.00284162927808505,1.77576675854871E-6,1,0.999253354069792,40.0298881530762,1.99495941845789,24.0700002759695,0.0322412540728882,0.00583783276701051,0.25,1.48156402800459E-5,0.00285765889918996,2.35275498167214E-5,100.0892,100.0892,22022.73046875,22087.94140625,54.9711521289866,19.5515842113041,9.241568,0,0,0,40,4961,100.08965,22055.3359375,,,,,,,,,,,,,0,,,,,,,,,,,,,,
,20403907.35,100.08135,25670.994140625,0.00317732949716747,3.41281235155431E-6,1,0.999253354069792,40.0298881530762,1.99504544600764,24.0700002759695,0.0360516102495622,0.00652901499903493,0.25,1.67139438220004E-5,0.00319527158500907,2.64146003937333E-5,100.0806,100.0806,25641.02734375,25700.9609375,55.2439404821981,19.5401441082179,8.861917,0,0,0,40,4961,100.08135,25670.994140625,,,,,,,,,,,,,0,,,,,,,,,,,,,,
,20403976.795,100.07445,29142.169921875,0.00333177734362013,3.14713180351285E-6,1,0.999253354069792,40.0298881530762,1.99517559723209,24.0700002759695,0.037800775261908,0.0068801778737601,0.25,2.05030874223221E-5,0.00335060228733317,3.06495488064978E-5,100.075,100.075,29139.541015625,29144.798828125,55.2712974803712,19.5547743038956,9.621219,0,0,0,40,4961,100.07445,29142.169921875,,,,,,,,,,,,,0,,,,,,,,,,,,,,
,20404046.505,100.06745,32625.578125,0.00340629260643271,2.85151170183754E-6,1,0.999253354069792,40.0298881530762,1.99506994747721,24.0700002759695,0.0386539160254281,0.00697993839858487,0.25,1.6268872335052E-5,0.00342557307592257,2.65712171651534E-5,100.0683,100.0683,32597.955078125,32653.201171875,55.3963580434482,19.5348176926159,9.241568,0,0,0,40,4961,100.06745,32625.578125,,,,,,,,,,,,,0,,,,,,,,,,,,,,
,20404117.845,100.06215,36193.5234375,0.0034547787621679,3.77158178896072E-6,1,0.999253354069792,40.0298881530762,1.99539162090266,24.0700002759695,0.0392181830855299,0.00703611175496179,0.25,1.26463283627625E-5,0.00347436653252057,2.30262892573132E-5,100.0616,100.0616,36161.2578125,36225.7890625,55.0493149809097,19.5357192152334,9.241568,0,0,0,40,4961,100.06215,36193.5234375,,,,,,,,,,,,,0,,,,,,,,,,,,,,
,20404189.625,100.0547,39778.65234375,0.0034686738067714,3.57136094314803E-6,1,0.999253354069792,40.0298881530762,1.99470640517892,24.0700002759695,0.0393621761354599,0.00706827057987992,0.25,1.32848136288565E-5,0.00348836022531255,2.366210651872E-5,100.0542,100.0542,39748.703125,39808.6015625,54.484979190025,19.5282006110929,9.621219,0,0,0,40,4961,100.0547,39778.65234375,,,,,,,,,,,,,0,,,,,,,,,,,,,,
,20404262.525,100.04775,43421.9609375,0.00347498744436821,3.67527433653749E-6,1,0.999253354069792,40.0298881530762,1.99519405534867,24.0700002759695,0.0394519963150446,0.00703315566305456,0.25,8.98439457925329E-6,0.00349474458195463,1.93067526287932E-5,100.0479,100.0479,43397.1171875,43446.8046875,53.8542049750057,19.5349934284228,9.241568,0,0,0,40,4961,100.04775,43421.9609375,,,,,,,,,,,,,0,,,,,,,,,,,,,,
,20404335.75,100.0402,47082.98828125,0.00347973449262189,4.87801945038678E-6,1,0.999253354069792,40.0298881530762,1.99517714388339,24.0700002759695,0.0394891865394763,0.00713747904621858,0.25,1.73863498258558E-5,0.00349951617342437,2.77207815034483E-5,100.04,100.04,47055.67578125,47110.30078125,56.127180708929,19.5397463194401,9.241568,0,0,0,40,4961,100.0402,47082.98828125,,,,,,,,,,,,,0,,,,,,,,,,,,,,
,20404408.54,100.03265,50718.806640625,0.00347012942854647,5.52416222143542E-6,1,0.999253354069792,40.0298881530762,1.9951233543469,24.0700002759695,0.0393735967013264,0.00715080651988965,0.25,2.03080232919418E-5,0.00348986997133837,3.05812383677109E-5,100.0325,100.0325,50688.9375,50748.67578125,54.996164241602,19.529331547254,9.241568,0,0,0,40,4961,100.03265,50718.806640625,,,,,,,,,,,,,0,,,,,,,,,,,,,,
,20404480.395,100.0267,54311.775390625,0.00345911938680941,5.87583229363008E-6,1,0.999253354069792,40.0298881530762,1.99481524888376,24.0700002759695,0.0392302041186216,0.00720074604035674,0.25,2.67767274473958E-5,0.0034788001287551,3.7005274071279E-5,100.0268,100.0268,54286.9453125,54336.60546875,55.1907897428905,19.5311353155107,9.241568,0,0,0,40,4961,100.0267,54311.775390625,,,,,,,,,,,,,0,,,,,,,,,,,,,,
,20404555.915,100.0194,58087.755859375,0.00343735491030739,4.88144976167145E-6,1,0.999253354069792,40.0298881530762,1.99478998093909,24.0700002759695,0.0390024251276917,0.00704563419064652,0.25,1.69943089431201E-5,0.00345696257467636,2.70519317058303E-5,100.0189,100.0189,58055.296875,58120.21484375,55.0149233260635,19.5525931005976,9.621219,0,0,0,40,4961,100.0194,58087.755859375,,,,,,,,,,,,,0,,,,,,,,,,,,,,
,20404628.46,100.0142,61712.662109375,0.00341258098781361,4.8300083379889E-6,1,0.999253354069792,40.0298881530762,1.99476825103241,24.0700002759695,0.0387113859971145,0.00705053135591784,0.25,2.18266014891566E-5,0.00343205467094439,3.17904180319161E-5,100.0145,100.0145,61687.71875,61737.60546875,55.0313375249674,19.5335669828122,9.241568,0,0,0,40,4961,100.0142,61712.662109375,,,,,,,,,,,,,0,,,,,,,,,,,,,,
,20404701.18,100.0095,65349.091796875,0.00339728758391457,4.67696006204038E-6,1,0.999253354069792,40.0298881530762,1.99506005392086,24.0700002759695,0.0385582983303639,0.00693578713629622,0.25,1.43678163813883E-5,0.00341671669818597,2.41950085545703E-5,100.0105,100.0105,65321.55078125,65376.6328125,55.2517567673905,19.5386238526923,9.241568,0,0,0,40,4961,100.0095,65349.091796875,,,,,,,,,,,,,0,,,,,,,,,,,,,,
,20404773.075,100.00255,68939.89453125,0.00335853171002725,5.90624315122543E-6,1,0.999253354069792,40.0298881530762,1.99470623918848,24.0700002759695,0.0380943748315694,0.0069571754723753,0.25,2.32013009963596E-5,0.0033777343905795,3.29196416564828E-5,100.0024,100.0024,68909.890625,68969.8984375,55.6636749970251,19.5300207025405,9.621219,0,0,0,40,4961,100.00255,68939.89453125,,,,,,,,,,,,,0,,,,,,,,,,,,,,
,20404846.305,99.99805,72600.41015625,0.00332670458497892,4.38975892301097E-6,1,0.999253354069792,40.0298881530762,1.99541356922387,24.0700002759695,0.037765373334398,0.00678539989815809,0.25,1.35042594926033E-5,0.00334577330793796,2.30268489943639E-5,99.9986,99.9986,72572.625,72628.1953125,55.3807254730635,19.5506127900027,9.241568,0,0,0,40,4961,99.99805,72600.41015625,,,,,,,,,,,,,0,,,,,,,,,,,,,,
,20404920.09,99.99515,76289.29296875,0.00328601838202129,5.48563122181506E-6,1,0.999253354069792,40.0298881530762,1.99490118771521,24.0700002759695,0.0372766397011113,0.00680308313629533,0.25,2.23928995668881E-5,0.00330484906368086,3.18017724866123E-5,99.9947,99.9947,76262.0625,76316.5234375,55.6605484829482,19.539945189497,9.241568,0,0,0,40,4961,99.99515,76289.29296875,,,,,,,,,,,,,0,,,,,,,,,,,,,,
,20404993.975,99.98965,79982.546875,0.00326071284220368,6.78528293648327E-6,1,0.999253354069792,40.0298881530762,1.99507360084722,24.0700002759695,0.0369917145168054,0.00675779785295462,0.25,2.28416883373528E-5,0.00327941739301557,3.21331398427492E-5,99.9893,99.9893,79954.921875,80010.171875,54.8765750781596,19.5442746143939,9.241568,0,0,0,40,4961,99.98965,79982.546875,,,,,,,,,,,,,0,,,,,,,,,,,,,,
,20405067.765,99.9855,83671.24609375,0.00321704216621293,5.84266721390605E-6,1,0.999253354069792,40.0298881530762,1.99495179683113,24.0700002759695,0.0365001021617874,0.00663435227398396,0.25,1.97142342039906E-5,0.00323552428023093,2.88170055200073E-5,99.9858,99.9858,83643.765625,83698.7265625,55.9794529187944,19.5403248588822,9.241568,0,0,0,40,4961,99.9855,83671.24609375,,,,,,,,,,,,,0,,,,,,,,,,,,,,
,20405139.75,99.98255,87269.98046875,0.00317308686703788,5.54204791914571E-6,1,0.999253354069792,40.0298881530762,1.99544317725725,24.0700002759695,0.036004163748928,0.00657895999268146,0.25,2.24553613324289E-5,0.00319132732339743,3.1404842272331E-5,99.9837,99.9837,87237.5546875,87302.40625,56.1131113955829,19.5352339081347,9.241568,0,0,0,40,4961,99.98255,87269.98046875,,,,,,,,,,,,,0,,,,,,,,,,,,,,
,20405194.315,99.97745,89996.09765625,0.0031435059156158,5.18439580248649E-6,1,0.999253354069792,40.0298881530762,1.99526291193366,24.0700002759695,0.0356636795414881,0.00652805709366607,0.25,2.32451885148895E-5,0.00316158796217519,3.20827245288287E-5,99.9783,99.9783,89992.703125,89999.4921875,56.3022654972367,19.5372594715952,8.861917,0,0,0,40,4929,99.97745,89996.09765625,,,,,,,,,,,,,0,,,,,,,,,,,,,,