File: data/looselyPackedNP/sc-ios-11/ppms/rawdata/ES_S14_HYST_300K_INIT.DAT
[Header]
; VSM Data File (default extension .dat)
; Copyright (c) 2003-2013, Quantum Design, Inc. All rights reserved.
TITLE,
FILEOPENTIME,29063763.39,12/03/2018,5:17 pm
BYAPP,VSM,2.0,2.0
INFO,PPMS VSM Option Release 1.4.10 Build 1,APPNAME
INFO,Quantum Design Linear Motor Servo Controller,MOTOR_MODULE_NAME
INFO,3101-100 M1,MOTOR_HW_VERSION
INFO,MMC1014,MOTOR_SERIAL_NUMBER
INFO,SRV No X-over 01.03.11,MOTOR_SOFTWARE_VERSION
INFO,Quantum Design VSM Detection Module,VSM_MODULE_NAME
INFO,3101-150 F0,VSM_HW_VERSION
INFO,VSM707,VSM_SERIAL_NUMBER
INFO,VSM No X-over 01.02.05 May 20 2008 13:51:47,VSM_SOFTWARE_VERSION
INFO,704,PREAMP_SERIAL_NUMBER
INFO,822,COIL_SERIAL_NUMBER
INFO,0,MOMENT_UNITS
INFO,Iron Oxide Spheres,SAMPLE_MATERIAL
INFO,10 nm diameter, collaboration Mainz,SAMPLE_COMMENT
INFO,,SAMPLE_MASS
INFO,,SAMPLE_VOLUME
INFO,,SAMPLE_MOLECULAR_WEIGHT
INFO,,SAMPLE_SIZE
INFO,,SAMPLE_SHAPE
DATATYPE,COMMENT,1
DATATYPE,TIME,2
STARTUPAXIS,X,2
STARTUPAXIS,Y1,5
[Data]
Comment,Time Stamp (sec),Temperature (K),Magnetic Field (Oe),Moment (emu),M. Std. Err. (emu),Transport Action,Averaging Time (sec),Frequency (Hz),Peak Amplitude (mm),Center Position (mm),Coil Signal' (mV),Coil Signal" (mV),Range (mV),M. Quad. Signal (emu),M. Raw' (emu),M. Raw" (emu),Min. Temperature (K),Max. Temperature (K),Min. Field (Oe),Max. Field (Oe),Mass (grams),Motor Lag (deg),Pressure (Torr),VSM Status (code),Motor Status (code),Measure Status (code),Measure Count,PPMS Status (code),System Temp. (K),System Field (Oe),Sample Position (deg),Bridge 1 Resistance (ohms),Bridge 1 Excitation (에),Bridge 2 Resistance (ohms),Bridge 2 Excitation (에),Bridge 3 Resistance (ohms),Bridge 3 Excitation (에),Bridge 4 Resistance (ohms),Bridge 4 Excitation (에),Signal 1 Vin (V),Signal 2 Vin (V),Digital Inputs (code),Drive 1 Iout (mA),Drive 1 Ipower (W),Drive 2 Iout (mA),Drive 2 Ipower (W),Pressure (),Map 20 (),Map 21 (),Map 22 (),Map 23 (),Map 24 (),Map 25 (),Map 26 (),Map 27 (),Map 28 (),Map 29 ()
,29063779.08,300.0117493,0.243580371141434,,,2,,,,16.7200004002452,,,,,,,300.0117493,300.0117493,0.243580371141434,0.243580371141434,,,24.427608,,,,-99999999,4369,300.2085,0.243580371141434,,,,,,,,,,,,,,,,,,,,,,,300.0117493,,,,
,29063919.765,300.0188904,4192.169921875,0.000122874858200141,3.81992293756558E-7,1,0.999253354069792,40.0298881530762,1.9986148787071,16.7100001126528,0.00139054695266408,0.000240778779343668,0.25,-1.26277634673116E-8,0.0001228711181226,6.88705172677034E-8,300.0188904,300.0188904,4187.1630859375,4197.1767578125,56.5133051974291,20.5195783122425,25.946213,0,0,0,40,4449,300.16855,4192.169921875,,,,,,,,,,,,,0,,,,0,,,,,,300.0188904,,,,
,29064012.485,300.0129395,8824.6552734375,0.000109243498753068,6.55860647424661E-7,1,0.999253354069792,40.0298881530762,1.99849985841264,16.7100001126528,0.00123567135723573,0.000217201424416224,0.25,2.66804388208996E-7,0.000109240017307219,3.39201520046779E-7,300.0129395,300.0129395,8822.029296875,8827.28125,56.679010443506,20.5234034775001,25.946213,0,0,0,40,4449,300.16305,8824.6552734375,,,,,,,,,,,,,0,,,,-0.00245,,,,,,300.0129395,,,,
,29064106.895,300.0027771,13542.8618164062,8.96117263147036E-5,1.18354402157152E-6,1,0.999253354069792,40.0298881530762,1.99839066482939,16.7100001126528,0.00101477745471574,0.000171136867927712,0.25,-4.01736660623539E-7,8.96093188101388E-5,-3.42381026530392E-7,300.0027771,300.0027771,13535.18359375,13550.5400390625,56.7188734979868,20.5231612767758,25.946213,0,0,0,40,4449,300.1646,13542.8618164062,,,,,,,,,,,,,0,,,,0.00245,,,,,,300.0027771,,,,
,29064198.605,299.988739,18125.599609375,6.73217540685544E-5,1.8450136029023E-6,1,0.999253354069792,40.0298881530762,1.99813615134098,16.7100001126528,0.000762852425863842,0.000125191351700428,0.25,-5.98875787602621E-7,6.73201793315331E-5,-5.54315791336406E-7,299.988739,299.988739,18123.255859375,18127.943359375,56.9908802226791,20.5281088719944,25.946213,0,0,0,40,4449,300.1726,18125.599609375,,,,,,,,,,,,,0,,,,-0.00245,,,,,,299.988739,,,,
,29064292.67,299.99212645,22828.2861328125,4.5433504379856E-5,2.24814547146E-6,1,0.999253354069792,40.0298881530762,1.99803109795634,16.7100001126528,0.000511990874920223,0.000100704096646231,0.25,1.02958724267035E-6,4.54314907797848E-5,1.05958817873111E-6,299.9913635,299.9928894,22826.142578125,22830.4296875,56.7157469839098,20.5310693472201,25.946213,0,0,0,40,4449,300.18195,22828.2861328125,,,,,,,,,,,,,0,,,,0.00245,,,,,,299.99212645,,,,
,29064383.765,299.9908752,27381.1533203125,2.35073025728661E-5,2.54838755031151E-6,1,0.999253354069792,40.0298881530762,1.99793197725955,16.7100001126528,0.000263924455450678,5.7684291966644E-5,0.25,1.02618097585217E-6,2.35059375887642E-5,1.04167427223E-6,299.9908752,299.9908752,27373.7265625,27388.580078125,56.9056827140829,20.5342110534783,25.946213,0,0,0,40,4449,300.1844,27381.1533203125,,,,,,,,,,,,,0,,,,-0.00245,,,,,,299.9908752,,,,
,29064479.385,299.9883423,32161.0595703125,-3.3475674516372E-7,2.70481556890917E-6,1,0.999253354069792,40.0298881530762,1.99792258431431,16.7100001126528,-9.02781715166713E-6,2.959251121991E-5,0.25,2.67382931863298E-6,-3.36510790901253E-7,2.67353073156722E-6,299.9883423,299.9883423,32150.958984375,32171.16015625,56.9627415959868,20.5324100006727,25.946213,0,0,0,40,4449,300.19905,32161.0595703125,,,,,,,,,,,,,0,,,,-0.0049,,,,,,299.9883423,,,,
,29064573.535,299.9908447,36868.42578125,-2.38411148967931E-5,2.46509211375374E-6,1,0.999253354069792,40.0298881530762,1.99786871439866,16.7100001126528,-0.000270171992473545,-4.40273732739409E-5,0.25,2.38701701747958E-7,-2.38405781617433E-5,2.22984982517441E-7,299.9908447,299.9908447,36863.6015625,36873.25,57.0018230219483,20.5344160304656,25.946213,0,0,0,40,4449,300.2089,36868.42578125,,,,,,,,,,,,,0,,,,0,,,,,,299.9908447,,,,
,29064669.96,299.9937134,41685.9609375,-4.91468449075914E-5,1.67319324817544E-6,1,0.999253354069792,40.0298881530762,1.99772777451155,16.7100001126528,-0.00055120006374308,-0.000123674193641806,0.25,-2.41827789660574E-6,-4.91438205321758E-5,-2.45055696258922E-6,299.9937134,299.9937134,41676.06640625,41695.85546875,56.9807190519291,20.5354865364952,25.946213,0,0,0,40,4449,300.2073,41685.9609375,,,,,,,,,,,,,0,,,,-0.00245,,,,,,299.9937134,,,,
,29064762.48,299.9968872,46311.4296875,-7.01802441646252E-5,1.52451254404638E-6,1,0.999253354069792,40.0298881530762,1.99769430838501,16.7100001126528,-0.000799269353173239,-0.000106272720975835,0.25,2.7640032103115E-6,-7.01800122154808E-5,2.71777726450014E-6,299.9968872,299.9968872,46309,46313.859375,56.8814522299868,20.5361600749075,25.946213,0,0,0,40,4449,300.20515,46311.4296875,,,,,,,,,,,,,0,,,,-0.0049,,,,,,299.9968872,,,,
,29064862.67,299.9996643,51318.826171875,-9.57338828479735E-5,2.50947901200346E-6,1,0.999253354069792,40.0298881530762,1.99751449070475,16.7100001126528,-0.00108239223931758,-0.000190027757431212,0.25,-2.14579006605147E-7,-9.57309433952467E-5,-2.77446519138463E-7,299.9996643,299.9996643,51311.4375,51326.21484375,56.922878541506,20.5355307650104,25.946213,0,0,0,40,4449,300.2024,51318.826171875,,,,,,,,,,,,,0,,,,0,,,,,,299.9996643,,,,
,29064957.155,300.0029297,56038.578125,-0.00012116429106475,1.54264885846663E-6,1,0.999253354069792,40.0298881530762,1.99749694836278,16.7100001126528,-0.00137381818893183,-0.00021790882742368,0.25,1.72603754462398E-6,-0.000121161875410758,1.6465036149547E-6,300.0029297,300.0029297,56028.76953125,56048.38671875,56.8197035769676,20.5347625866862,25.946213,0,0,0,40,4449,300.20845,56038.578125,,,,,,,,,,,,,0,,,,-0.00245,,,,,,300.0029297,,,,
,29065052.42,300.0009766,60801.50390625,-0.000146921574131304,2.42668617943601E-6,1,0.999253354069792,40.0298881530762,1.99767254414561,16.7100001126528,-0.00166251302948529,-0.000284418249510681,0.25,3.10257302799501E-7,-0.000146917495284284,2.13977064510863E-7,300.0009766,300.0009766,60796.29296875,60806.71484375,56.8439340610637,20.5366184557224,26.325863,0,0,0,40,4449,300.20055,60801.50390625,,,,,,,,,,,,,0,,,,0.0049,,,,,,300.0009766,,,,
,29065149.99,300.0018921,65679.34765625,-0.0001696236017816,2.17946473610763E-6,1,0.999253354069792,40.0298881530762,1.99749098432784,16.7100001126528,-0.00192383517752689,-0.000301784223404045,0.25,2.70572346981966E-6,-0.000169620435200134,2.59463304604009E-6,300.0018921,300.0018921,65669.2421875,65689.453125,56.9267866841022,20.534715298517,25.946213,0,0,0,40,4449,300.2031,65679.34765625,,,,,,,,,,,,,0,,,,0,,,,,,300.0018921,,,,
,29065244.575,300.0093079,70406.94921875,-0.000193978600125043,2.30263882918081E-6,1,0.999253354069792,40.0298881530762,1.99736334398764,16.7100001126528,-0.00219813774156511,-0.00035543784801346,0.25,2.17949095699934E-6,-0.000193974339808643,2.05262110824329E-6,300.0093079,300.0093079,70401.90625,70411.9921875,56.9072459711214,20.5355664344031,26.325863,0,0,0,40,4449,300.1921,70406.94921875,,,,,,,,,,,,,0,,,,0,,,,,,300.0093079,,,,
,29065340.72,300.0100098,75212.484375,-0.000218926006841779,2.19044285290104E-6,1,0.999253354069792,40.0298881530762,1.99726255499082,16.7100001126528,-0.00247353042036169,-0.000442622599659075,0.25,-1.20917506586428E-6,-0.000218918810743469,-1.3520833054647E-6,300.0100098,300.0100098,75209.8984375,75215.0703125,56.9994781363906,20.5358808014774,25.566563,0,0,0,40,4449,300.1853,75212.484375,,,,,,,,,,,,,0,,,,0,,,,,,300.0100098,,,,
,29065436.525,300.0066528,80000.53125,-0.000249527256141287,2.70537505316108E-6,1,0.999253354069792,40.0298881530762,1.99724697889859,16.7100001126528,-0.00282726199451902,-0.000458285812974191,0.25,2.70698954369795E-6,-0.000249521767046916,2.544185044367E-6,300.0066528,300.0066528,79992.8515625,80008.2109375,56.8626931455252,20.5369009007663,25.946213,0,0,0,40,4449,300.1823,80000.53125,,,,,,,,,,,,,0,,,,0.00245,,,,,,300.0066528,,,,
,29065531.535,300.0102234,84751.47265625,-0.000272531701416166,3.42176550632322E-6,1,0.999253354069792,40.0298881530762,1.99720742600461,16.7100001126528,-0.00308755654079897,-0.000502247526690836,0.25,2.80417594604505E-6,-0.000272525588257674,2.62657489196112E-6,300.0102234,300.0102234,84746.46875,84756.4765625,56.8955215433329,20.5361336129385,26.325863,0,0,0,40,4449,300.1668,84751.47265625,,,,,,,,,,,,,0,,,,-0.0049,,,,,,300.0102234,,,,
,29065624.195,300.0109253,89382.484375,-0.000296767640995121,2.76182957904193E-6,1,0.999253354069792,40.0298881530762,1.99713278979132,16.7100001126528,-0.00335664653107825,-0.000577849094638648,0.25,3.1587461163318E-7,-0.000296759212949101,1.22782329315218E-7,300.0109253,300.0109253,89375.3671875,89389.6015625,56.8837971155445,20.5332836724948,25.946213,0,0,0,40,4449,300.15105,89382.484375,,,,,,,,,,,,,0,,,,-0.00245,,,,,,300.0109253,,,,
,29065731.75,300.0057068,86113.85546875,-0.000274337795968935,2.29977932398052E-6,1,0.999253354069792,40.0298881530762,1.99709852728164,16.7100001126528,-0.00310827011285376,-0.000503164616846388,0.25,3.03362422574029E-6,-0.000274331828176898,2.85489244840102E-6,300.0057068,300.0057068,86104.1328125,86123.578125,56.9510171681983,20.5367433656436,26.325863,0,0,0,40,4449,300.1498,86113.85546875,,,,,,,,,,,,,0,,,,-0.00245,,,,,,300.0057068,,,,
,29065828.65,300.0007935,81270.296875,-0.000253750470131212,3.30660579196587E-6,1,0.999253354069792,40.0298881530762,1.99695984372117,16.7100001126528,-0.00286853431149585,-0.000501677690296416,0.25,-4.04320799765582E-7,-0.000253742886156815,-5.69750386819042E-7,300.0007935,300.0007935,81265.3515625,81275.2421875,56.9658681100637,20.5342528657399,25.566563,0,0,0,40,4449,300.15785,81270.296875,,,,,,,,,,,,,0,,,,0,,,,,,300.0007935,,,,
,29065927.515,299.9947205,76329.10546875,-0.000224321824568107,2.11753340626758E-6,1,0.999253354069792,40.0298881530762,1.99690052627829,16.7100001126528,-0.00253867991114412,-0.000426775202785668,0.25,1.12037948518059E-6,-0.000224316117297772,9.73910238933195E-7,299.9947205,299.9947205,76326.765625,76331.4453125,56.8173586914099,20.5294354836345,26.325863,0,0,0,40,4449,300.16395,76329.10546875,,,,,,,,,,,,,0,,,,0,,,,,,299.9947205,,,,
,29066019.995,299.9918518,71702.84765625,-0.000200620337251249,1.71130138145776E-6,1,0.999253354069792,40.0298881530762,1.99695897648702,16.7100001126528,-0.00227401485145673,-0.000361466612577801,0.25,2.79092936915672E-6,-0.000200616410170142,2.65973334889348E-6,299.9918518,299.9918518,71692.8359375,71712.859375,56.8478422036599,20.5323921907449,26.325863,0,0,0,40,4449,300.1702,71702.84765625,,,,,,,,,,,,,0,,,,0,,,,,,299.9918518,,,,
,29066116.15,299.9866943,66897.53515625,-0.000174783319846608,1.8674067545629E-6,1,0.999253354069792,40.0298881530762,1.99717849494236,16.7100001126528,-0.00198109343419607,-0.000316501096029189,0.25,2.29429554211178E-6,-0.000174779831111168,2.17986622555439E-6,299.9866943,299.9866943,66885.2421875,66909.828125,57.3183825722368,20.5367841656255,25.946213,0,0,0,40,4449,300.1805,66897.53515625,,,,,,,,,,,,,0,,,,-0.0049,,,,,,299.9866943,,,,
,29066210.68,299.9855957,62173.966796875,-0.000150115741951593,2.60233684687155E-6,1,0.999253354069792,40.0298881530762,1.99703053277774,16.7100001126528,-0.00169803018426078,-0.000291129641898423,0.25,2.62411491810958E-7,-0.000150111624606294,1.64074214696703E-7,299.9855957,299.9855957,62166.4921875,62181.44140625,56.851750346256,20.537746262939,25.946213,0,0,0,40,4449,300.2038,62173.966796875,,,,,,,,,,,,,0,,,,-0.00245,,,,,,299.9855957,,,,
,29066308.495,299.9865112,57283.40625,-0.000124978101476281,1.99479904922826E-6,1,0.999253354069792,40.0298881530762,1.99717361130518,16.7100001126528,-0.0014143156216197,-0.000239320599776844,0.25,4.90429037344807E-7,-0.000124974839483145,4.08455291041871E-7,299.9865112,299.9865112,57273.34765625,57293.46484375,57.0401228193907,20.5393638733084,25.946213,0,0,0,40,4449,300.21115,57283.40625,,,,,,,,,,,,,0,,,,-0.00245,,,,,,299.9865112,,,,
,29066404.805,299.9866638,52468.587890625,-0.000103374251461341,1.90340359444312E-6,1,0.999253354069792,40.0298881530762,1.99708607534733,16.7100001126528,-0.00117116593183571,-0.000189980994672707,0.25,1.10981925684797E-6,-0.000103372008584782,1.04191911191352E-6,299.9866638,299.9866638,52460.875,52476.30078125,57.0409044479099,20.5392310464963,25.946213,0,0,0,40,4449,300.2206,52468.587890625,,,,,,,,,,,,,0,,,,0.00245,,,,,,299.9866638,,,,
,29066501.865,299.9949951,47618.7890625,-7.70280640884813E-5,1.3465186109447E-6,1,0.999253354069792,40.0298881530762,1.99702503208071,16.7100001126528,-0.000871578468452179,-0.000147767159014018,0.25,2.77918472481702E-7,-7.70260043501594E-5,2.27281222799792E-7,299.9949951,299.9949951,47608.58984375,47628.98828125,57.2949337166599,20.5415947164182,26.325863,0,0,0,40,4449,300.2213,47618.7890625,,,,,,,,,,,,,0,,,,0,,,,,,299.9949951,,,,
,29066597.935,299.9909973,42818.314453125,-5.19274884634496E-5,1.45338494273658E-6,1,0.999253354069792,40.0298881530762,1.99705335290537,16.7100001126528,-0.000587640337071024,-9.92195403850922E-5,0.25,2.22514076174529E-7,-5.19261273424806E-5,1.88339682978127E-7,299.9909973,299.9909973,42810.67578125,42825.953125,57.1612752398714,20.5427201544295,25.946213,0,0,0,40,4449,300.23,42818.314453125,,,,,,,,,,,,,0,,,,-0.00245,,,,,,299.9909973,,,,
,29066693.505,299.9883728,38038.162109375,-2.81044855607043E-5,1.14504325971139E-6,1,0.999253354069792,40.0298881530762,1.99718772265937,16.7100001126528,-0.00031777000079493,-5.54145084299132E-5,0.25,-3.08394358597864E-8,-2.81036503100279E-5,-4.9349793682087E-8,299.9883728,299.9883728,38033.18359375,38043.140625,56.9275683126214,20.5402201675012,25.946213,0,0,0,40,4449,300.24965,38038.162109375,,,,,,,,,,,,,0,,,,0,,,,,,299.9883728,,,,
,29066789.425,299.98428345,33246.125,-5.67115367032151E-6,1.26043738319105E-6,1,0.999253354069792,40.0298881530762,1.99719849064483,16.7100001126528,-6.37130647812582E-5,-1.3545658065431E-5,0.25,-2.15222329667164E-7,-5.67084780304347E-6,-2.18955362317667E-7,299.9837036,299.9848633,33241.140625,33251.109375,57.1362631272561,20.5438806970641,25.946213,0,0,0,40,4449,300.25465,33246.125,,,,,,,,,,,,,0,,,,-0.0049,,,,,,299.98428345,,,,
,29066887.195,299.98349,28358.7734375,1.93694285787297E-5,1.19716254042161E-6,1,0.999253354069792,40.0298881530762,1.99704301928646,16.7100001126528,0.000220682463642224,2.841947089987E-5,0.25,-8.42683971467017E-7,1.93694241703823E-5,-8.29875777120796E-7,299.98349,299.98349,28353.6796875,28363.8671875,57.1964485232368,20.5398235259769,25.946213,0,0,0,40,4449,300.2713,28358.7734375,,,,,,,,,,,,,0,,,,-0.0049,,,,,,299.98349,,,,
,29066981.235,299.991272,23658.6513671875,4.17043371343339E-5,9.7744148114254E-7,1,0.999253354069792,40.0298881530762,1.99718602720354,16.7100001126528,0.000469461225699619,9.42245181808307E-5,0.25,1.10633751390642E-6,4.17023851748511E-5,1.1338569177158E-6,299.991272,299.991272,23651.03515625,23666.267578125,57.1253203279868,20.5444273896582,25.946213,0,0,0,40,4449,300.27175,23658.6513671875,,,,,,,,,,,,,0,,,,0,,,,,,299.991272,,,,
,29067077.65,299.9909668,18839.2236328125,6.49634918289071E-5,7.19778124666772E-7,1,0.999253354069792,40.0298881530762,1.99712121662731,16.7100001126528,0.000734679586454527,0.000127058441604949,0.25,-1.9790761458381E-8,6.49616000206617E-5,2.31670922362595E-8,299.9909668,299.9909668,18833.951171875,18844.49609375,56.9815006804483,20.5437053028194,25.946213,0,0,0,40,4449,300.2843,18839.2236328125,,,,,,,,,,,,,0,,,,-0.0049,,,,,,299.9909668,,,,
,29067171.81,299.9852905,14133.958984375,8.63213143695325E-5,7.25784511607775E-7,1,0.999253354069792,40.0298881530762,1.99694320552276,16.7100001126528,0.000975469417309477,0.000172656819413552,0.25,3.13262351286007E-7,8.63185890329442E-5,3.70382941222561E-7,299.9852905,299.9852905,14126.6689453125,14141.2490234375,57.2183341217753,20.5468210821966,25.566563,0,0,0,40,4449,300.29215,14133.958984375,,,,,,,,,,,,,0,,,,0,,,,,,299.9852905,,,,
,29067267.08,299.9876099,9374.01904296875,0.000106665551614361,5.35871376267836E-7,1,0.999253354069792,40.0298881530762,1.99707474268126,16.7100001126528,0.00120521838388067,0.000214664235259803,0.25,5.02191142529041E-7,0.000106662093526374,5.72827334626547E-7,299.9876099,299.9876099,9363.908203125,9384.1298828125,57.4364084786407,20.5454979238594,25.946213,0,0,0,40,4449,300.3035,9374.01904296875,,,,,,,,,,,,,0,,,,-0.00245,,,,,,299.9876099,,,,
,29067361.34,299.9942932,4661.2373046875,0.000122122170400987,4.86467117324767E-7,1,0.999253354069792,40.0298881530762,1.9969799427843,16.7100001126528,0.00138090546233265,0.000239381558693805,0.25,1.08719510821357E-8,0.00012211854992322,9.18224736198001E-8,299.9942932,299.9942932,4651.3037109375,4671.1708984375,57.098744958333,20.5480349950631,25.946213,0,0,0,40,4449,300.30095,4661.2373046875,,,,,,,,,,,,,0,,,,0,,,,,,299.9942932,,,,
,29067455.225,299.9966736,-32.4890651702881,2.492165603938E-7,5.3472695576184E-7,1,0.999253354069792,40.0298881530762,1.99698694632435,16.7100001126528,3.1939142387025E-6,-1.68089221084924E-6,0.25,-1.91828346449907E-7,2.49336384958825E-7,-1.9165735806272E-7,299.9966736,299.9966736,-37.5248222351074,-27.4533081054687,57.2878990599868,20.5497695649485,26.325863,0,0,0,40,4449,300.3054,-32.4890651702881,,,,,,,,,,,,,0,,,,0.0049,,,,,,299.9966736,,,,
,29067549.44,300.0003967,-4734.21557617188,-0.000121823980168437,4.28761229027739E-7,1,0.999253354069792,40.0298881530762,1.99699718216019,16.7100001126528,-0.00137666808626768,-0.000243858528691394,0.25,-4.582849625844E-7,-0.00012182004533542,-5.39023320718705E-7,300.0003967,300.0003967,-4741.65576171875,-4726.775390625,57.0268351345637,20.5493252556613,26.325863,0,0,0,40,4449,300.3018,-4734.21557617188,,,,,,,,,,,,,0,,,,0.00245,,,,,,300.0003967,,,,
,29067642.44,299.9989319,-9385.408203125,-0.000106325944543851,4.51472644285871E-7,1,0.999253354069792,40.0298881530762,1.99708823973201,16.7100001126528,-0.00120156955147468,-0.00021293658144137,0.25,-4.08140087476603E-7,-0.000106322515531225,-4.78553123768402E-7,299.9989319,299.9989319,-9385.408203125,-9385.408203125,57.2238055214099,20.5483532591928,25.946213,0,0,0,40,4449,300.3058,-9385.408203125,,,,,,,,,,,,,0,,,,0.0049,,,,,,299.9989319,,,,
,29067740.195,300.0043945,-14270.5009765625,-8.55043392461438E-5,7.96890520159444E-7,1,0.999253354069792,40.0298881530762,1.9970198836723,16.7100001126528,-0.000965773000210065,-0.000173908876865823,0.25,-5.64987012635619E-7,-8.55014127033193E-5,-6.2155666985901E-7,300.0043945,300.0043945,-14278.0546875,-14262.947265625,57.281646031833,20.5510042031064,26.325863,0,0,0,40,4449,300.2968,-14270.5009765625,,,,,,,,,,,,,0,,,,0,,,,,,300.0043945,,,,
,29067834.85,300.0133667,-19002.568359375,-6.49594929463951E-5,9.76167914921878E-7,1,0.999253354069792,40.0298881530762,1.99701530562437,16.7100001126528,-0.000734340104234857,-0.000128524464821889,0.25,-1.11127500499514E-7,-6.49574626167155E-5,-1.54076551149421E-7,300.0133667,300.0133667,-19010.005859375,-18995.130859375,57.1956668947176,20.5515794283721,26.705515,0,0,0,40,4449,300.28915,-19002.568359375,,,,,,,,,,,,,0,,,,0.0049,,,,,,300.0133667,,,,
,29067932.49,300.00926205,-23879.9970703125,-4.09093463107908E-5,9.46922936899204E-7,1,0.999253354069792,40.0298881530762,1.99695759284256,16.7100001126528,-0.000460286981582946,-9.34256901046484E-5,0.25,-1.17434797163862E-6,-4.09073465798483E-5,-1.20133670928565E-6,300.0085449,300.0099792,-23887.22265625,-23872.771484375,56.9705578811791,20.5511281436834,26.325863,0,0,0,40,4449,300.2856,-23879.9970703125,,,,,,,,,,,,,0,,,,-0.0049,,,,,,300.00926205,,,,
,29068029.275,300.0115051,-28719.935546875,-1.67883286941525E-5,1.06867900184382E-6,1,0.999253354069792,40.0298881530762,1.9969600639199,16.7100001126528,-0.000190316579602837,-3.01190003087248E-5,0.25,2.45089384237237E-7,-1.67879877474142E-5,2.34002681970421E-7,300.0115051,300.0115051,-28734.978515625,-28704.892578125,57.1948852661984,20.5535580621516,25.946213,0,0,0,40,4449,300.2726,-28719.935546875,,,,,,,,,,,,,0,,,,-0.00245,,,,,,300.0115051,,,,
,29068125.345,300.0122986,-33519.5859375,6.06141715387755E-6,1.31705502682495E-6,1,0.999253354069792,40.0298881530762,1.99695756619426,16.7100001126528,6.89797806558935E-5,9.33820273879923E-6,0.25,-2.24343500440618E-7,6.06138375015915E-6,-2.20340612304446E-7,300.0122986,300.0122986,-33527.0859375,-33512.0859375,57.332451885583,20.5537273925205,26.325863,0,0,0,40,4449,300.2644,-33519.5859375,,,,,,,,,,,,,0,,,,0,,,,,,300.0122986,,,,
,29068222.905,300.010437,-38396.595703125,2.99944409499541E-5,1.43379142578931E-6,1,0.999253354069792,40.0298881530762,1.99685982210544,16.7100001126528,0.000340390783768539,5.15996356021845E-5,0.25,-6.3321831283679E-7,2.99939646550238E-5,-6.13445501492862E-7,300.010437,300.010437,-38404.07421875,-38389.1171875,57.3066581444484,20.5542072809104,25.946213,0,0,0,40,4449,300.25645,-38396.595703125,,,,,,,,,,,,,0,,,,0.00245,,,,,,300.010437,,,,
,29068320.96,300.0106812,-43296.32421875,5.54627502640371E-5,1.46120034016062E-6,1,0.999253354069792,40.0298881530762,1.99685179856247,16.7100001126528,0.000626428614547948,0.000112646950957211,0.25,3.53368523871751E-7,5.54608690299008E-5,3.89845165219761E-7,300.0106812,300.0106812,-43306.2578125,-43286.390625,57.3394865422561,20.5554443141091,26.325863,0,0,0,40,4449,300.2505,-43296.32421875,,,,,,,,,,,,,0,,,,0,,,,,,300.0106812,,,,
,29068419.71,300.0126343,-48231.251953125,8.11853500764625E-5,1.32579281317274E-6,1,0.999253354069792,40.0298881530762,1.99684606579074,16.7100001126528,0.000918864638664453,0.000153851303940679,0.25,-4.58958655384866E-7,8.1183238051645E-5,-4.05597562063329E-7,300.0126343,300.0126343,-48233.5390625,-48228.96484375,57.1315733561406,20.553631982675,26.325863,0,0,0,40,4449,300.25255,-48231.251953125,,,,,,,,,,,,,0,,,,-0.00245,,,,,,300.0126343,,,,
,29068516.765,300.0145264,-53083.181640625,0.000104053575745263,1.40137992130308E-6,1,0.999253354069792,40.0298881530762,1.9968341417103,16.7100001126528,0.00118264845249206,0.000168526646475922,0.25,-3.12290682528147E-6,0.000104052531556006,-3.05451180599115E-6,300.0145264,300.0145264,-53090.56640625,-53075.796875,57.2066096939868,20.5558662674701,26.705515,0,0,0,40,4449,300.228,-53083.181640625,,,,,,,,,,,,,0,,,,0,,,,,,300.0145264,,,,
,29068615.71,300.0127869,-58027.986328125,0.000130700781307402,1.73969283940104E-6,1,0.999253354069792,40.0298881530762,1.996797126008,16.7100001126528,0.00147814942682304,0.000254040037383702,0.25,-1.76225318424402E-7,0.000130697027370835,-9.05254645952393E-8,300.0127869,300.0127869,-58033.04296875,-58022.9296875,57.2112994651022,20.5561513117292,26.325863,0,0,0,40,4449,300.21815,-58027.986328125,,,,,,,,,,,,,0,,,,0,,,,,,300.0127869,,,,
,29068713.61,300.0137024,-62920.662109375,0.000154989035907739,2.64983194891166E-6,1,0.999253354069792,40.0298881530762,1.99675819884633,16.7100001126528,0.00175044200093778,0.000314869603256164,0.25,9.96345742766428E-7,0.000154983800567337,1.09781448542781E-6,300.0137024,300.0137024,-62925.69921875,-62915.625,57.1425161554099,20.5562706197438,25.946213,0,0,0,40,4449,300.2162,-62920.662109375,,,,,,,,,,,,,0,,,,0.0049,,,,,,300.0137024,,,,
,29068810.83,300.0041199,-67780.25390625,0.000180844611344871,1.75584073861059E-6,1,0.999253354069792,40.0298881530762,1.99676007898108,16.7100001126528,0.00204657812420839,0.000343609320681995,0.25,-9.4121089125859E-7,0.000180839953649238,-8.22885188412566E-7,300.0041199,300.0041199,-67787.8203125,-67772.6875,57.0604451608906,20.5594634518352,25.946213,0,0,0,40,4449,300.19215,-67780.25390625,,,,,,,,,,,,,0,,,,-0.00245,,,,,,300.0041199,,,,
,29068909.655,300.0145264,-72716.57421875,0.000207247903353173,2.45725315725647E-6,1,0.999253354069792,40.0298881530762,1.99677470495285,16.7100001126528,0.00234824347407042,0.000377331475683571,0.25,-2.53312309097012E-6,0.000207243452564519,-2.39764787147274E-6,300.0145264,300.0145264,-72718.8203125,-72714.328125,57.1472059265253,20.5572510804552,26.325863,0,0,0,40,4449,300.193,-72716.57421875,,,,,,,,,,,,,0,,,,0.00245,,,,,,300.0145264,,,,
,29069006.885,300.0130615,-77576.2421875,0.000229533741237363,2.60130239779524E-6,1,0.999253354069792,40.0298881530762,1.99673339535042,16.7100001126528,0.00259734706372751,0.000437277080342615,0.25,-1.09140346403903E-6,0.000229527718929892,-9.41588159150185E-7,300.0130615,300.0130615,-77586.3359375,-77566.1484375,57.2230238928907,20.5596136327022,25.946213,0,0,0,40,4449,300.17795,-77576.2421875,,,,,,,,,,,,,0,,,,-0.00245,,,,,,300.0130615,,,,
,29069104.91,300.0140381,-82475.9765625,0.000258477076975543,1.9065890966007E-6,1,0.999253354069792,40.0298881530762,1.99670944684249,16.7100001126528,0.00292527819318307,0.00048981943975033,0.25,-1.45798093913486E-6,0.000258470452932924,-1.28947656197407E-6,300.0140381,300.0140381,-82483.3984375,-82468.5546875,57.2863358029484,20.5599535856418,26.325863,0,0,0,40,4449,300.1709,-82475.9765625,,,,,,,,,,,,,0,,,,0,,,,,,300.0140381,,,,
,29069200.76,300.0143433,-87265.25,0.00028048858377794,2.80180921130205E-6,1,0.999253354069792,40.0298881530762,1.99672807067463,16.7100001126528,0.00317688715397408,0.000517288757857259,0.25,-2.84205845815183E-6,0.000280482231387418,-2.65939329150457E-6,300.0143433,300.0143433,-87274.875,-87255.625,57.3809128537753,20.5586315552967,26.325863,0,0,0,40,4449,300.16685,-87265.25,,,,,,,,,,,,,0,,,,-0.00245,,,,,,300.0143433,,,,
,29069311.35,300.0135498,-88218.06640625,0.000284817044155974,2.70541407306027E-6,1,0.999253354069792,40.0298881530762,1.99678603465564,16.7100001126528,0.00322081390014462,0.00055523188169164,0.25,-2.37391196645917E-7,0.000284808880402964,-5.20141567885618E-8,300.0135498,300.0135498,-88222.984375,-88213.1484375,57.2433462343907,20.5576698396541,26.705515,0,0,0,40,4449,300.1433,-88218.06640625,,,,,,,,,,,,,0,,,,-0.00245,,,,,,300.0135498,,,,
,29069404.905,300.0031738,-83543.8046875,0.000258812617355396,3.18899987566913E-6,1,0.999253354069792,40.0298881530762,1.99680551035711,16.7100001126528,0.00293135130777553,0.000478125699048547,0.25,-2.55230578223446E-6,0.000258806800237942,-2.38358373761471E-6,300.0031738,300.0031738,-83551.2734375,-83536.3359375,57.3176009437176,20.5604650398545,26.705515,0,0,0,40,4449,300.14835,-83543.8046875,,,,,,,,,,,,,0,,,,0.00245,,,,,,300.0031738,,,,
,29069505.17,299.999054,-78531.00390625,0.000233473526709425,2.55553512571702E-6,1,0.999253354069792,40.0298881530762,1.99665482787339,16.7100001126528,0.00264490870324019,0.000427000527359499,0.25,-2.68146209347674E-6,0.000233468545202781,-2.52904753133722E-6,299.999054,299.999054,-78538.4296875,-78523.578125,57.3668435404292,20.5588042123353,26.325863,0,0,0,40,4449,300.1434,-78531.00390625,,,,,,,,,,,,,0,,,,0,,,,,,299.999054,,,,
,29069603.415,299.9946899,-73621.9296875,0.000210030434587072,2.52622956799081E-6,1,0.999253354069792,40.0298881530762,1.99658035988646,16.7100001126528,0.002380368321036,0.000377649728051623,0.25,-2.98395607184587E-6,0.000210026347003673,-2.84666482895571E-6,299.9946899,299.9946899,-73626.8359375,-73617.0234375,57.1221938139099,20.5601884675683,26.325863,0,0,0,40,4449,300.1583,-73621.9296875,,,,,,,,,,,,,0,,,,0,,,,,,299.9946899,,,,
,29069703.375,299.9890137,-68627.80078125,0.000183919577852644,2.77138752932704E-6,1,0.999253354069792,40.0298881530762,1.9966970104987,16.7100001126528,0.00208410163366527,0.000333358395139312,0.25,-2.37969795200247E-6,0.000183915872268576,-2.25933319004705E-6,299.9890137,299.9890137,-68635.34375,-68620.2578125,57.3535558556022,20.5607943823533,25.946213,0,0,0,40,4449,300.16545,-68627.80078125,,,,,,,,,,,,,0,,,,0.00245,,,,,,299.9890137,,,,
,29069800.62,299.9858398,-63768.36328125,0.000159021814589671,2.35915707138236E-6,1,0.999253354069792,40.0298881530762,1.99657916296031,16.7100001126528,0.00179654965928384,0.000318917080266662,0.25,6.58031770900224E-7,0.000159016841500474,7.62143854460732E-7,299.9858398,299.9858398,-63773.44140625,-63763.28515625,57.0369963053137,20.5580511806227,26.325863,0,0,0,40,4449,300.18295,-63768.36328125,,,,,,,,,,,,,0,,,,-0.00245,,,,,,299.9858398,,,,
,29069900.565,299.9902649,-58770.849609375,0.000132931670962833,1.83730289496995E-6,1,0.999253354069792,40.0298881530762,1.99661845277571,16.7100001126528,0.00150836825558706,0.000228825407021172,0.25,-2.79105949315205E-6,0.000132929673382736,-2.70382798101714E-6,299.9902649,299.9902649,-58775.89453125,-58765.8046875,57.4387533641984,20.5579498441119,26.325863,0,0,0,40,4449,300.19005,-58770.849609375,,,,,,,,,,,,,0,,,,-0.0049,,,,,,299.9902649,,,,
,29069999.615,299.9891357,-53821.3125,0.000108634589916612,1.93138426888742E-6,1,0.999253354069792,40.0298881530762,1.99653235464747,16.7100001126528,0.00122520542391921,0.000229788916596636,0.25,1.5044336544069E-6,0.000108630471501139,1.57569608105563E-6,299.9891357,299.9891357,-53828.82421875,-53813.80078125,57.1534589546791,20.5592820597496,26.705515,0,0,0,40,4449,300.1951,-53821.3125,,,,,,,,,,,,,0,,,,0.00245,,,,,,299.9891357,,,,
,29070095.555,299.9888306,-49026.673828125,8.45401628353742E-5,2.27596554846425E-6,1,0.999253354069792,40.0298881530762,1.99647670961768,16.7100001126528,0.000958048418946128,0.00015220544803155,0.25,-1.18338644779859E-6,8.45384994143199E-5,-1.12780064778137E-6,299.9888306,299.9888306,-49031.48046875,-49021.8671875,57.2253687784484,20.5570310338582,25.946213,0,0,0,40,4449,300.2061,-49026.673828125,,,,,,,,,,,,,0,,,,-0.0049,,,,,,299.9888306,,,,
,29070195.555,299.9885559,-44026.40234375,5.8065658406204E-5,1.77245501905178E-6,1,0.999253354069792,40.0298881530762,1.99654063420675,16.7100001126528,0.000658749588350755,0.000100489529565786,0.25,-1.17148670493229E-6,5.8064749151038E-5,-1.13325403669814E-6,299.9885559,299.9885559,-44033.96875,-44018.8359375,57.1722180391407,20.5586101765493,26.325863,0,0,0,40,4449,300.21255,-44026.40234375,,,,,,,,,,,,,0,,,,0,,,,,,299.9885559,,,,
,29070294.185,299.9901428,-39099.513671875,3.22560800606264E-5,1.01446854858128E-6,1,0.999253354069792,40.0298881530762,1.99652740709067,16.7100001126528,0.000366442933558319,5.29193566221428E-5,0.25,-9.07601958730567E-7,3.22557406503476E-5,-8.86332494828176E-7,299.9901428,299.9901428,-39106.96875,-39092.05859375,57.3707516830253,20.5584456284006,26.325863,0,0,0,40,4449,300.22025,-39099.513671875,,,,,,,,,,,,,0,,,,0.0049,,,,,,299.9901428,,,,
,29070392.14,299.9888306,-34205.052734375,9.81080949029682E-6,1.02164566067528E-6,1,0.999253354069792,40.0298881530762,1.9966630438587,16.7100001126528,0.00011198082771617,1.31034753472519E-5,0.25,-5.40800033283016E-7,9.81088084043407E-6,-5.34316251812408E-7,299.9888306,299.9888306,-34210.0390625,-34200.06640625,57.0799858738714,20.5571046107864,26.705515,0,0,0,40,4449,300.22695,-34205.052734375,,,,,,,,,,,,,0,,,,0,,,,,,299.9888306,,,,
,29070490.46,299.9858093,-29290.8017578125,-1.54250892661861E-5,1.13876594148329E-6,1,0.999253354069792,40.0298881530762,1.99641332361647,16.7100001126528,-0.000172970517276855,-3.83237861491168E-5,0.25,-7.17579620599827E-7,-1.54241680333714E-5,-7.27738764305016E-7,299.9858093,299.9858093,-29298.20703125,-29283.396484375,57.5856995258138,20.5558534161594,26.325863,0,0,0,40,4449,300.2351,-29290.8017578125,,,,,,,,,,,,,0,,,,-0.00245,,,,,,299.9858093,,,,
,29070587.235,299.9899597,-24453.6552734375,-3.80963697350742E-5,9.83536892770313E-7,1,0.999253354069792,40.0298881530762,1.99651954316564,16.7100001126528,-0.000430576699994236,-7.52722212899437E-5,0.25,-5.76868883742744E-8,-3.8095218160861E-5,-8.28516040153075E-8,299.9899597,299.9899597,-24461.259765625,-24446.05078125,57.2456911199484,20.5560512256342,25.946213,0,0,0,40,4449,300.2484,-24453.6552734375,,,,,,,,,,,,,0,,,,0,,,,,,299.9899597,,,,
,29070687.145,299.98898315,-19461.33203125,-6.15780331202178E-5,6.69184967594134E-7,1,0.999253354069792,40.0298881530762,1.99646016887335,16.7100001126528,-0.000697038596519244,-0.000115403504470602,0.25,4.60642992998007E-7,-6.15765364777557E-5,4.19910799798338E-7,299.9888306,299.9891357,-19463.623046875,-19459.041015625,57.3113479155637,20.5566518487467,26.705515,0,0,0,40,4449,300.25265,-19461.33203125,,,,,,,,,,,,,0,,,,0,,,,,,299.98898315,,,,
,29070784.795,299.9869385,-14581.6650390625,-8.44311646403137E-5,6.71830079544428E-7,1,0.999253354069792,40.0298881530762,1.99655734025275,16.7100001126528,-0.000952569506989046,-0.000176719735591579,0.25,-1.00293722659383E-6,-8.4428032691448E-5,-1.05878967724703E-6,299.9869385,299.9869385,-14586.7197265625,-14576.6103515625,57.4371901071599,20.5556115909307,26.325863,0,0,0,40,4449,300.2574,-14581.6650390625,,,,,,,,,,,,,0,,,,0,,,,,,299.9869385,,,,
,29070882.735,299.990509,-9686.49169921875,-0.000104918019988075,6.35425319131916E-7,1,0.999253354069792,40.0298881530762,1.99630117455244,16.7100001126528,-0.00118545502070001,-0.000208642408713895,0.25,-2.79268854271396E-7,-0.000104914749094564,-3.48762020814022E-7,299.990509,299.990509,-9693.96875,-9679.0146484375,57.2019199228714,20.5569946798476,26.705515,0,0,0,40,4449,300.2608,-9686.49169921875,,,,,,,,,,,,,0,,,,0,,,,,,299.990509,,,,
,29070979.685,299.9933472,-4841.02758789063,-0.000121479402243951,4.39445280100384E-7,1,0.999253354069792,40.0298881530762,1.99648637144394,16.7100001126528,-0.00137294300871267,-0.000240202757171546,0.25,-1.99864755432722E-7,-0.000121475678988095,-2.80390676624036E-7,299.9933472,299.9933472,-4845.95751953125,-4836.09765625,57.1339182416984,20.5555002615271,26.325863,0,0,0,40,4449,300.27195,-4841.02758789063,,,,,,,,,,,,,0,,,,-0.00245,,,,,,299.9933472,,,,
,29071072.105,299.9922485,-219.072227478027,-4.45089981571956E-5,5.47208211317074E-7,1,0.999253354069792,40.0298881530762,1.99643052407313,16.7100001126528,-0.000502808275959398,-8.92334511068728E-5,0.25,-1.81802713490549E-7,-4.45075621791492E-5,-2.11320381120871E-7,299.9922485,299.9922485,-226.636917114258,-211.507537841797,57.3246356003907,20.5499976576602,25.946213,0,0,0,40,4449,300.2765,-219.072227478027,,,,,,,,,,,,,0,,,,0,,,,,,299.9922485,,,,
,29071163.665,299.9950867,4351.74829101562,0.000122408689300143,3.95544328580588E-7,1,0.999253354069792,40.0298881530762,1.99634762831364,16.7100001126528,0.00138286148733007,0.000244865823130488,0.25,4.52768084021817E-7,0.00012240476306261,5.33904764189961E-7,299.9950867,299.9950867,4346.57861328125,4356.91796875,57.2058280654676,20.5493823339832,26.325863,0,0,0,40,4449,300.2834,4351.74829101562,,,,,,,,,,,,,0,,,,0,,,,,,299.9950867,,,,
,29071257.62,300.0012512,9050.861328125,0.00010751715437703,5.77892601617652E-7,1,0.999253354069792,40.0298881530762,1.99606458667299,16.7100001126528,0.00121448178863421,0.000214956325201623,0.25,3.89653022305393E-7,0.000107513692155866,4.6086739764127E-7,300.0012512,300.0012512,9046.005859375,9055.716796875,57.4231207938138,20.5502865070878,26.325863,0,0,0,40,4449,300.2781,9050.861328125,,,,,,,,,,,,,0,,,,0,,,,,,300.0012512,,,,
,29071350.75,300.0023804,13703.8681640625,8.868799469627E-5,6.59813980960851E-7,1,0.999253354069792,40.0298881530762,1.9960426164918,16.7100001126528,0.0010023739931453,0.000173896951343455,0.25,1.95116193077166E-8,8.86853395224052E-5,7.82155623068296E-8,300.0023804,300.0023804,13693.9560546875,13713.7802734375,57.1776894387753,20.5509340506727,26.705515,0,0,0,40,4449,300.27555,13703.8681640625,,,,,,,,,,,,,0,,,,0,,,,,,300.0023804,,,,
,29071444.36,300.006897,18381.2314453125,6.79368332838451E-5,6.27813130065268E-7,1,0.999253354069792,40.0298881530762,1.99589763527928,16.7100001126528,0.000767187747559508,0.000136651419937028,0.25,3.20422570235284E-7,6.79345898557449E-5,3.65342608697667E-7,300.006897,300.006897,18376.208984375,18386.25390625,57.1604936113522,20.5495029928606,26.325863,0,0,0,40,4449,300.27175,18381.2314453125,,,,,,,,,,,,,0,,,,0,,,,,,300.006897,,,,
,29071535.14,300.0073853,22921.353515625,4.70411783577646E-5,9.61832036354349E-7,1,0.999253354069792,40.0298881530762,1.99593029037276,16.7100001126528,0.000530590794470291,9.83029443312929E-5,0.25,5.47551632361019E-7,4.70394116415172E-5,5.7861706368435E-7,300.0073853,300.0073853,22913.822265625,22928.884765625,57.362935397833,20.5496248584615,26.705515,0,0,0,40,4449,300.27535,22921.353515625,,,,,,,,,,,,,0,,,,-0.0049,,,,,,300.0073853,,,,
,29071629.38,300.0089722,27631.763671875,2.43100454966412E-5,9.04974172330831E-7,1,0.999253354069792,40.0298881530762,1.99599024079306,16.7100001126528,0.000272608924738369,6.00308176269523E-5,0.25,1.09945684230949E-6,2.43085936960744E-5,1.11547112167999E-6,300.0089722,300.0089722,27626.9765625,27636.55078125,57.1675282680253,20.5486782466896,26.325863,0,0,0,40,4449,300.2705,27631.763671875,,,,,,,,,,,,,0,,,,0,,,,,,300.0089722,,,,
,29071727.315,300.0109863,32526.2734375,-5.7049214535987E-7,1.50020572486079E-6,1,0.999253354069792,40.0298881530762,1.99584660296789,16.7100001126528,-9.4721422655743E-6,1.63406509726157E-5,0.25,1.54470835573147E-6,-5.71493763872371E-7,1.5442859855348E-6,300.0109863,300.0109863,32523.814453125,32528.732421875,57.3902923960061,20.5498749257432,25.946213,0,0,0,40,4449,300.2527,32526.2734375,,,,,,,,,,,,,0,,,,0,,,,,,300.0109863,,,,
,29071822.335,300.0068359,37274.041015625,-2.33753174906573E-5,1.71049918348477E-6,1,0.999253354069792,40.0298881530762,1.99596266229833,16.7100001126528,-0.000267477318413985,-2.68213744156123E-5,0.25,1.67679748274195E-6,-2.33757285653032E-5,1.66134857111234E-6,300.0068359,300.0068359,37271.58984375,37276.4921875,57.241001348833,20.5490426136388,26.705515,0,0,0,40,4449,300.2466,37274.041015625,,,,,,,,,,,,,0,,,,-0.0049,,,,,,300.0068359,,,,
,29071919.39,300.009552,42126.7421875,-4.68176176339894E-5,1.56885275649229E-6,1,0.999253354069792,40.0298881530762,1.9961613608752,16.7100001126528,-0.0005307868082428,-8.24982708471022E-5,0.25,8.12783696152001E-7,-4.68167618120969E-5,7.81950623153006E-7,300.009552,300.009552,42124.36328125,42129.12109375,57.0745144742368,20.5484650244467,26.325863,0,0,0,40,4449,300.2434,42126.7421875,,,,,,,,,,,,,0,,,,-0.0049,,,,,,300.009552,,,,
,29072015.29,300.0097046,46919.443359375,-7.30902480608224E-5,2.1885500849335E-6,1,0.999253354069792,40.0298881530762,1.99605655473435,16.7100001126528,-0.000829829984905741,-0.000121727365016085,0.25,1.89346768420233E-6,-7.30893257933543E-5,1.84536411877652E-6,300.0097046,300.0097046,46912.0703125,46926.81640625,57.2050464369484,20.5490865971263,26.325863,0,0,0,40,4449,300.22835,46919.443359375,,,,,,,,,,,,,0,,,,0.0049,,,,,,300.0097046,,,,
,29072111.245,300.0196228,51714.65625,-9.59736482190798E-5,1.32329922190968E-6,1,0.999253354069792,40.0298881530762,1.99598618671225,16.7100001126528,-0.00108839459571118,-0.000166788137399526,0.25,1.87082888265023E-6,-9.59720033966696E-5,1.80775377802088E-6,300.0192566,300.019989,51709.6484375,51719.6640625,57.1010898438907,20.5488844945712,26.325863,0,0,0,40,4449,300.2275,51714.65625,,,,,,,,,,,,,0,,,,0.00245,,,,,,300.0196228,,,,
,29072205.255,300.0142822,56412.00390625,-0.000119324351625994,1.87141292057896E-6,1,0.999253354069792,40.0298881530762,1.99592257969026,16.7100001126528,-0.00135052236139596,-0.000222607797687805,0.25,9.76982283333501E-7,-0.000119321450356686,8.98683676044143E-7,300.0142822,300.0142822,56406.921875,56417.0859375,57.220679007333,20.5501555268199,26.705515,0,0,0,40,4449,300.2074,56412.00390625,,,,,,,,,,,,,0,,,,0,,,,,,300.0142822,,,,
,29072299.47,300.0081787,61122.427734375,-0.000145505346498433,2.36892791134891E-6,1,0.999253354069792,40.0298881530762,1.9959014928779,16.7100001126528,-0.00164881031621835,-0.00025998706238392,0.25,2.20526879785721E-6,-0.000145502513415154,2.10986639026734E-6,300.0081787,300.0081787,61115.07421875,61129.78125,57.3097846585253,20.5479850067599,26.705515,0,0,0,40,4449,300.1954,61122.427734375,,,,,,,,,,,,,0,,,,-0.00245,,,,,,300.0081787,,,,
,29072399.51,300.0140076,66122.73046875,-0.000167736496650101,2.26638354806992E-6,1,0.999253354069792,40.0298881530762,1.99582897824242,16.7100001126528,-0.00189978684562434,-0.000304732484056557,0.25,2.09668815994634E-6,-0.000167732913626302,1.98685249508093E-6,300.0140076,300.0140076,66117.859375,66127.6015625,57.2722664896022,20.5506895735293,25.946213,0,0,0,40,4449,300.18135,66122.73046875,,,,,,,,,,,,,0,,,,-0.0049,,,,,,300.0140076,,,,
,29072499.22,300.013092,71107.99609375,-0.000195102339486666,2.78705590261333E-6,1,0.999253354069792,40.0298881530762,1.99601328184335,16.7100001126528,-0.0022094031436068,-0.000357509028919596,0.25,2.17062737129245E-6,-0.000195098014729928,2.04303332822716E-6,300.013092,300.013092,71100.3359375,71115.65625,56.9963516223137,20.5489803124563,26.705515,0,0,0,40,4449,300.1675,71107.99609375,,,,,,,,,,,,,0,,,,-0.0049,,,,,,300.013092,,,,
,29072596.19,300.0128784,75953.58984375,-0.000219418070655358,2.1764341168288E-6,1,0.999253354069792,40.0298881530762,1.99582209352964,16.7100001126528,-0.00248127107968138,-0.000420871176484687,0.25,7.73743655119917E-7,-0.000219412133472163,6.30470311811742E-7,300.0128784,300.0128784,75943.6796875,75963.5,57.1573670972753,20.5486804298281,26.325863,0,0,0,40,4449,300.1621,75953.58984375,,,,,,,,,,,,,0,,,,-0.0049,,,,,,300.0128784,,,,
,29072695.55,300.0120544,80919.39453125,-0.00024369831967174,2.67339120828413E-6,1,0.999253354069792,40.0298881530762,1.99594424655448,16.7100001126528,-0.00275432506265907,-0.000477159274485462,0.25,1.96765617881473E-9,-0.000243691190522283,-1.56936457556731E-7,300.0120544,300.0120544,80916.796875,80921.9921875,57.1855057239676,20.5472910803401,26.325863,0,0,0,40,4449,300.15415,80919.39453125,,,,,,,,,,,,,0,,,,0,,,,,,300.0120544,,,,
,29072793.385,300.0141907,85812.15234375,-0.000268156742776251,2.87525063727142E-6,1,0.999253354069792,40.0298881530762,1.99587987412199,16.7100001126528,-0.00303840823888423,-0.000480340878868722,0.25,3.95631812153182E-6,-0.000268151471889548,3.78156743772557E-6,300.0141907,300.0141907,85804.6953125,85819.609375,57.0588819038522,20.5454419436027,27.085165,0,0,0,40,4449,300.1465,85812.15234375,,,,,,,,,,,,,0,,,,-0.00245,,,,,,300.0141907,,,,
,29072908.095,300.01249695,89423.75390625,-0.00029098499505672,2.89810562955354E-6,1,0.999253354069792,40.0298881530762,1.99586190313738,16.7100001126528,-0.0032940834182749,-0.000538297884794146,0.25,2.78256576807042E-6,-0.000290978323381083,2.59315995306951E-6,300.0123291,300.0126648,89411.109375,89436.3984375,57.2128627221407,20.5454891112975,26.325863,0,0,0,40,4449,300.14285,89423.75390625,,,,,,,,,,,,,0,,,,0.00245,,,,,,300.01249695,,,,
,29073003.29,300.0077209,84664.59765625,-0.000266113287537327,3.40812689484539E-6,1,0.999253354069792,40.0298881530762,1.99626250392226,16.7100001126528,-0.00300978677589807,-0.00051151594375399,0.25,8.52237292488045E-7,-0.00026610611152987,6.78846695313033E-7,300.0077209,300.0077209,84659.578125,84669.6171875,57.3168193151984,20.5517251117148,26.325863,0,0,0,40,4449,300.132,84664.59765625,,,,,,,,,,,,,0,,,,0,,,,,,300.0077209,,,,
,29073100.22,300.0037231,79820.328125,-0.000237277123662134,2.60462024776273E-6,1,0.999253354069792,40.0298881530762,1.99611017344866,16.7100001126528,-0.00268333771748664,-0.000456700298520067,0.25,7.02958708493998E-7,-0.000237270705793259,5.48166386495113E-7,300.0037231,300.0037231,79810.5390625,79830.1171875,57.1081245005637,20.5511060319358,25.946213,0,0,0,40,4449,300.13605,79820.328125,,,,,,,,,,,,,0,,,,0,,,,,,300.0037231,,,,
,29073199.535,299.9953613,74854.1171875,-0.00021468096338675,1.51500048654226E-6,1,0.999253354069792,40.0298881530762,1.99627967102321,16.7100001126528,-0.00242882115261749,-0.000408489703906627,0.25,1.05658558943504E-6,-0.000214675480584239,9.16344061062895E-7,299.9953613,299.9953613,74851.3671875,74856.8671875,57.187068981006,20.5499399360996,27.085165,0,0,0,40,4449,300.1368,74854.1171875,,,,,,,,,,,,,0,,,,-0.0049,,,,,,299.9953613,,,,
,29073299.7,299.9926758,69849.28125,-0.000187312721220229,2.77284350378701E-6,1,0.999253354069792,40.0298881530762,1.99615580978986,16.7100001126528,-0.00211577741392645,-0.000375348887467487,0.25,-7.54981249043413E-7,-0.000187306846259812,-8.77447033759872E-7,299.9926758,299.9926758,69839.59375,69858.96875,57.014329078256,20.5480497093969,26.705515,0,0,0,40,4449,300.1463,69849.28125,,,,,,,,,,,,,0,,,,0.00245,,,,,,299.9926758,,,,
,29073398.035,299.9917603,64933.84375,-0.000161910966256725,2.67295265570181E-6,1,0.999253354069792,40.0298881530762,1.99598987096331,16.7100001126528,-0.00183641136371382,-0.000279960986259301,0.25,3.28124586289509E-6,-0.000161908457079852,3.17514837325121E-6,299.9917603,299.9917603,64921.41796875,64946.26953125,57.0588819038522,20.5486986713162,26.705515,0,0,0,40,4449,300.15615,64933.84375,,,,,,,,,,,,,0,,,,0,,,,,,299.9917603,,,,
,29073495.325,299.9865875,60070.6328125,-0.000139533140462685,1.67667459503286E-6,1,0.999253354069792,40.0298881530762,1.99588753819634,16.7100001126528,-0.00157641133241846,-0.000276528702775687,0.25,-2.93151445296287E-7,-0.000139528951470894,-3.84597364587484E-7,299.9865112,299.9866638,60063.07421875,60078.19140625,57.1628384969099,20.5501726462129,26.325863,0,0,0,40,4449,300.1781,60070.6328125,,,,,,,,,,,,,0,,,,0,,,,,,299.9865875,,,,
,29073591.945,299.9863281,55240.23046875,-0.000114660683284875,2.73295571684303E-6,1,0.999253354069792,40.0298881530762,1.99604887130261,16.7100001126528,-0.00129980175313618,-0.000202471908662748,0.25,1.95173506708634E-6,-0.000114658672801718,1.87643831516235E-6,299.9863281,299.9863281,55230.2578125,55250.203125,57.085457273506,20.5481277786058,26.325863,0,0,0,40,4449,300.1773,55240.23046875,,,,,,,,,,,,,0,,,,0,,,,,,299.9863281,,,,
,29073688.79,299.9884949,50400.158203125,-8.79271403963343E-5,1.58393047499286E-6,1,0.999253354069792,40.0298881530762,1.99603682731344,16.7100001126528,-0.000996810362439371,-0.000154872359122196,0.25,1.53139241265547E-6,-8.79256099319916E-5,1.4735851586747E-6,299.9884949,299.9884949,50392.6328125,50407.68359375,57.2574155477368,20.5487945636941,27.085165,0,0,0,40,4449,300.1856,50400.158203125,,,,,,,,,,,,,0,,,,-0.00245,,,,,,299.9884949,,,,
,29073785.57,299.9894104,45565.259765625,-6.57532633876378E-5,1.32348279630554E-6,1,0.999253354069792,40.0298881530762,1.99589212986645,16.7100001126528,-0.000744048704934898,-0.000123482886545609,0.25,4.66157409293917E-7,-6.57516667176052E-5,4.2290022610692E-7,299.9894104,299.9894104,45560.3046875,45570.21484375,57.1808159528522,20.5520547466716,27.085165,0,0,0,40,4449,300.19465,45565.259765625,,,,,,,,,,,,,0,,,,0,,,,,,299.9894104,,,,
,29073884.485,299.9864807,40620.1640625,-4.03970330436E-5,1.52289581501933E-6,1,0.999253354069792,40.0298881530762,1.99579626626485,16.7100001126528,-0.000459153635461245,-6.40224657737384E-5,0.25,1.33396212991141E-6,-4.03967436543076E-5,1.30732673669079E-6,299.9864807,299.9864807,40617.5078125,40622.8203125,57.1284468420637,20.5508753402469,26.325863,0,0,0,40,4449,300.2061,40620.1640625,,,,,,,,,,,,,0,,,,0,,,,,,299.9864807,,,,
,29073981.31,299.9884644,35780.25,-1.64215930221022E-5,9.69608563818861E-7,1,0.999253354069792,40.0298881530762,1.9964795949087,16.7100001126528,-0.00018820461396266,-1.74026317530571E-5,0.25,1.30576528057411E-6,-1.64219767798698E-5,1.29490426225233E-6,299.9884644,299.9884644,35775.3125,35785.1875,57.0924919301791,20.5522337035291,26.325863,0,0,0,40,4449,300.21605,35780.25,,,,,,,,,,,,,0,,,,0,,,,,,299.9884644,,,,
,29074079.405,299.9882202,30877.8154296875,7.91040307062303E-6,1.3506199409743E-6,1,0.999253354069792,40.0298881530762,1.99615227630405,16.7100001126528,8.89602224420474E-5,1.81080008350286E-5,0.25,2.31485036080475E-7,7.91002021906507E-6,2.36697386886931E-7,299.9882202,299.9882202,30867.98828125,30887.642578125,57.3387049137368,20.5535106003298,26.705515,0,0,0,40,4449,300.22035,30877.8154296875,,,,,,,,,,,,,0,,,,0.0049,,,,,,299.9882202,,,,
,29074174.585,299.99127195,26120.091796875,3.13083091474851E-5,1.31016890435829E-6,1,0.999253354069792,40.0298881530762,1.9960640136451,16.7100001126528,0.000351987035844696,7.21889639537193E-5,0.25,9.624358248302E-7,3.13067574889138E-5,9.83084337100746E-7,299.9908752,299.9916687,26115.189453125,26124.994140625,57.2300585495638,20.5534007526891,26.325863,0,0,0,40,4449,300.22855,26120.091796875,,,,,,,,,,,,,0,,,,0.0049,,,,,,299.99127195,,,,
,29074271.805,299.990448,21262.9306640625,5.36281954586518E-5,9.56169611882186E-7,1,0.999253354069792,40.0298881530762,1.99596064948609,16.7100001126528,0.000605802187562657,0.000106843748407504,0.25,1.61826529454438E-7,5.36265178007413E-5,1.97274243670731E-7,299.990448,299.990448,21252.888671875,21272.97265625,57.075296102756,20.5523003996627,26.325863,0,0,0,40,4449,300.22885,21262.9306640625,,,,,,,,,,,,,0,,,,0.00245,,,,,,299.990448,,,,
,29074368.75,299.9933929,16417.728515625,7.71136047674678E-5,1.0074964442437E-6,1,0.999253354069792,40.0298881530762,1.99611732581812,16.7100001126528,0.000870917111566023,0.000155084279444357,0.25,3.59953520856941E-7,7.71110957484264E-5,4.10967388847548E-7,299.9929504,299.9938354,16410.78125,16424.67578125,57.0369963053137,20.5533495613573,27.085165,0,0,0,40,4449,300.23945,16417.728515625,,,,,,,,,,,,,0,,,,0,,,,,,299.9933929,,,,
,29074466.795,299.9898682,11518.23828125,9.7045126882873E-5,7.61645694753611E-7,1,0.999253354069792,40.0298881530762,1.99601977125632,16.7100001126528,0.00109649176432037,0.00019215785895294,0.25,1.8734122724788E-7,9.70421524084676E-5,2.51603028104451E-7,299.9898682,299.9898682,11507.9521484375,11528.5244140625,57.230840178083,20.5530254221662,27.085165,0,0,0,40,4449,300.25365,11518.23828125,,,,,,,,,,,,,0,,,,0,,,,,,299.9898682,,,,
,29074561.315,299.9887085,6793.072265625,0.000115232131225985,5.73364495572143E-7,1,0.999253354069792,40.0298881530762,1.99610754700856,16.7100001126528,0.00130271498272184,0.00022426855245415,0.25,-1.23599012634274E-7,0.000115228828058067,-4.72251692708435E-8,299.9887085,299.9887085,6785.4912109375,6800.6533203125,56.9994781363906,20.5524060030762,26.705515,0,0,0,40,4449,300.262,6793.072265625,,,,,,,,,,,,,0,,,,0.0049,,,,,,299.9887085,,,,
,29074656.265,299.9933777,2047.54528808594,0.000119328406382336,3.63986152496791E-7,1,0.999253354069792,40.0298881530762,1.99585956796498,16.7100001126528,0.00134849078096805,0.000234365589472812,0.25,6.23959632522318E-8,0.00011932483475582,1.41532570164598E-7,299.9933777,299.9933777,2042.49536132813,2052.59521484375,57.1808159528522,20.5543769880445,27.085165,0,0,0,40,4449,300.26625,2047.54528808594,,,,,,,,,,,,,0,,,,0,,,,,,299.9933777,,,,
,29079201.81,10.0049629,-0.1674614995718,,,2,,,,17.7000004118681,,,,,,,10.0049629,10.0049629,-0.1674614995718,-0.1674614995718,,,12.658426,,,,-99999999,4369,10.0056,-0.1674614995718,,,,,,,,,,,,,,,,,,,,,,,10.0049629,,,,