File: data/looselyPackedNP/sc-ios-11/ppms/rawdata/ES_S14_HYST_EB_FC1T_10K.DAT
[Header]
; VSM Data File (default extension .dat)
; Copyright (c) 2003-2013, Quantum Design, Inc. All rights reserved.
TITLE,
FILEOPENTIME,29483524.20,12/08/2018,1:53 pm
BYAPP,VSM,2.0,2.0
INFO,PPMS VSM Option Release 1.4.10 Build 1,APPNAME
INFO,Quantum Design Linear Motor Servo Controller,MOTOR_MODULE_NAME
INFO,3101-100 M1,MOTOR_HW_VERSION
INFO,MMC1014,MOTOR_SERIAL_NUMBER
INFO,SRV No X-over 01.03.11,MOTOR_SOFTWARE_VERSION
INFO,Quantum Design VSM Detection Module,VSM_MODULE_NAME
INFO,3101-150 F0,VSM_HW_VERSION
INFO,VSM707,VSM_SERIAL_NUMBER
INFO,VSM No X-over 01.02.05 May 20 2008 13:51:47,VSM_SOFTWARE_VERSION
INFO,704,PREAMP_SERIAL_NUMBER
INFO,822,COIL_SERIAL_NUMBER
INFO,0,MOMENT_UNITS
INFO,Iron Oxide Spheres,SAMPLE_MATERIAL
INFO,10 nm diameter, collaboration Mainz,SAMPLE_COMMENT
INFO,,SAMPLE_MASS
INFO,,SAMPLE_VOLUME
INFO,,SAMPLE_MOLECULAR_WEIGHT
INFO,,SAMPLE_SIZE
INFO,,SAMPLE_SHAPE
DATATYPE,COMMENT,1
DATATYPE,TIME,2
STARTUPAXIS,X,2
STARTUPAXIS,Y1,5
[Data]
Comment,Time Stamp (sec),Temperature (K),Magnetic Field (Oe),Moment (emu),M. Std. Err. (emu),Transport Action,Averaging Time (sec),Frequency (Hz),Peak Amplitude (mm),Center Position (mm),Coil Signal' (mV),Coil Signal" (mV),Range (mV),M. Quad. Signal (emu),M. Raw' (emu),M. Raw" (emu),Min. Temperature (K),Max. Temperature (K),Min. Field (Oe),Max. Field (Oe),Mass (grams),Motor Lag (deg),Pressure (Torr),VSM Status (code),Motor Status (code),Measure Status (code),Measure Count,PPMS Status (code),System Temp. (K),System Field (Oe),Sample Position (deg),Bridge 1 Resistance (ohms),Bridge 1 Excitation (에),Bridge 2 Resistance (ohms),Bridge 2 Excitation (에),Bridge 3 Resistance (ohms),Bridge 3 Excitation (에),Bridge 4 Resistance (ohms),Bridge 4 Excitation (에),Signal 1 Vin (V),Signal 2 Vin (V),Digital Inputs (code),Drive 1 Iout (mA),Drive 1 Ipower (W),Drive 2 Iout (mA),Drive 2 Ipower (W),Pressure (),Map 20 (),Map 21 (),Map 22 (),Map 23 (),Map 24 (),Map 25 (),Map 26 (),Map 27 (),Map 28 (),Map 29 ()
,29483539.44,10.0060453,9999.7509765625,,,2,,,,17.0600000047684,,,,,,,10.0060453,10.0060453,9999.7509765625,9999.7509765625,,,12.278775,,,,-99999999,4369,9.9925,9999.7509765625,,,,,,,,,,,,,,,,,,,,,,,10.0060453,,,,
,29483726.02,10.0028191,4296.94946289063,0.000131018637691432,2.75161732846352E-7,1,0.999253354069792,40.0298881530762,1.99726596127655,17.0499999076128,0.00147103089592949,0.000269957808184202,0.25,7.20218025549455E-7,0.000130292439719379,1.38155601000099E-6,10.0028191,10.0028191,4286.88427734375,4307.0146484375,55.6824340814867,20.4999928760174,12.658426,0,0,0,40,4449,9.98665,4296.94946289063,,,,,,,,,,,,,0,,,,-0.00245,,,,,,10.0028191,,,,
,29483812.71,10.0013399,8627.373046875,0.000112235387387504,3.55207404093963E-7,1,0.999253354069792,40.0298881530762,1.997222458558,17.0499999076128,0.00126035608439276,0.000232173693925902,0.25,6.57304098995846E-7,0.000111647839665171,1.25910918338834E-6,10.0013399,10.0013399,8617.5419921875,8637.2041015625,56.2076884464098,20.5067120646694,12.278775,0,0,0,40,4449,9.98525,8627.373046875,,,,,,,,,,,,,0,,,,0.0049,,,,,,10.0013399,,,,
,29483901.265,10.0019827,13055.7192382812,9.07813857943467E-5,4.91268355341896E-7,1,0.999253354069792,40.0298881530762,1.99710670268679,17.0499999076128,0.00101950833039224,0.000189232867208455,0.25,6.24955702823172E-7,9.03386266171594E-5,1.14102692256627E-6,10.0019827,10.0019827,13050.78515625,13060.6533203125,56.0208792303136,20.5129056292798,12.658426,0,0,0,40,4449,9.984,13055.7192382812,,,,,,,,,,,,,0,,,,0.00245,,,,,,10.0019827,,,,
,29483988.725,10.0016661,17426.0087890625,6.7970213190171E-5,4.99507925012346E-7,1,0.999253354069792,40.0298881530762,1.9972681485043,17.0499999076128,0.000762033368358172,0.000151030901872326,0.25,1.27205516685041E-6,6.76606274289747E-5,1.67599478453512E-6,10.0016661,10.0016661,17423.447265625,17428.5703125,56.1795498197175,20.5087520842829,13.038077,0,0,0,40,4449,9.9826,17426.0087890625,,,,,,,,,,,,,0,,,,0,,,,,,10.0016661,,,,
,29484080.52,10.0015721,22013.4150390625,4.46127955068306E-5,6.83912472079153E-7,1,0.999253354069792,40.0298881530762,1.99713253944849,17.0499999076128,0.000500460668543901,9.85811397541609E-5,0.25,7.69544994893613E-7,4.44295743975559E-5,1.04861439464064E-6,10.0014238,10.0017204,22005.947265625,22020.8828125,56.3343122665252,20.5094405578949,12.658426,0,0,0,40,4449,9.9823,22013.4150390625,,,,,,,,,,,,,0,,,,0,,,,,,10.0015721,,,,
,29484168.705,10.0005522,26421.22265625,2.09530000892463E-5,6.88001736147548E-7,1,0.999253354069792,40.0298881530762,1.99702312138602,17.0499999076128,0.000234150274416073,5.18388191635832E-5,0.25,8.46530478080067E-7,2.08730243492138E-5,9.81409328152453E-7,10.0005522,10.0005522,26418.908203125,26423.537109375,56.4023139476983,20.5110640333223,13.038077,0,0,0,40,4449,9.9819,26421.22265625,,,,,,,,,,,,,0,,,,-0.0049,,,,,,10.0005522,,,,
,29484259.95,10.0006247,30984.328125,-4.05960824360163E-6,6.48396726352418E-7,1,0.999253354069792,40.0298881530762,1.99715095244039,17.0499999076128,-4.61024596425294E-5,-6.08431155085555E-6,0.25,1.88948797045214E-7,-4.04841181556579E-6,1.60717483978604E-7,10.0005732,10.0006762,30972.3671875,30996.2890625,56.231918930506,20.5159470884128,12.658426,0,0,0,40,4449,9.9819,30984.328125,,,,,,,,,,,,,0,,,,0,,,,,,10.0006247,,,,
,29484347.205,9.9988136,35344.587890625,-2.89703964679386E-5,9.94169560186529E-7,1,0.999253354069792,40.0298881530762,1.99693942490189,17.0499999076128,-0.000327845004793813,-5.05324655310738E-5,0.25,7.23725644988723E-7,-2.88997465236948E-5,5.1914584362265E-7,9.9988136,9.9988136,35334.609375,35354.56640625,56.5047072837175,20.5154700639005,12.658426,0,0,0,40,4449,9.9819,35344.587890625,,,,,,,,,,,,,0,,,,0.0049,,,,,,9.9988136,,,,
,29484435.835,9.9979191,39771.935546875,-5.3185472509845E-5,9.95604855523717E-7,1,0.999253354069792,40.0298881530762,1.99688617982691,17.0499999076128,-0.00059815315308309,-0.000115005966487945,0.25,-6.32519098714015E-7,-5.30669370005447E-5,-1.01141718409387E-6,9.9979191,9.9979191,39766.83984375,39777.03125,56.7548284098714,20.520082784734,13.038077,0,0,0,40,4449,9.9829,39771.935546875,,,,,,,,,,,,,0,,,,0,,,,,,9.9979191,,,,
,29484521.14,9.997777,44037.357421875,-7.66661203474684E-5,1.10684826995868E-6,1,0.999253354069792,40.0298881530762,1.99669625169186,17.0499999076128,-0.000865082073658698,-0.000151716107533873,0.25,3.49463903841041E-7,-7.65387460411751E-5,-2.0808365184367E-7,9.997777,9.997777,44030.01953125,44044.6953125,56.8087607776983,20.5198179236234,12.278775,0,0,0,40,4449,9.98465,44037.357421875,,,,,,,,,,,,,0,,,,0,,,,,,9.997777,,,,
,29484608.43,9.9974489,48400.3203125,-0.000100652826322832,1.36884796644688E-6,1,0.999253354069792,40.0298881530762,1.996568475812,17.0499999076128,-0.00113428953027411,-0.000209800954868275,0.25,-4.67225627020857E-7,-0.000100524329481262,-1.20654955162734E-6,9.9974489,9.9974489,48397.875,48402.765625,56.668849272756,20.5241911068436,12.658426,0,0,0,40,4449,9.9869,48400.3203125,,,,,,,,,,,,,0,,,,0,,,,,,9.9974489,,,,
,29484696.64,9.9959373,52808.3203125,-0.000125825476653533,1.21931206278435E-6,1,0.999253354069792,40.0298881530762,1.99678352507558,17.0499999076128,-0.00141893039318627,-0.000261398595640816,0.25,-4.87219817776624E-7,-0.000125721614038806,-1.4189822572584E-6,9.9959373,9.9959373,52805.9453125,52810.6953125,56.7212183835445,20.522732057045,12.658426,0,0,0,40,4449,9.9923,52808.3203125,,,,,,,,,,,,,0,,,,-0.0049,,,,,,9.9959373,,,,
,29484786.545,9.995451,57303.265625,-0.000151394573405079,1.22472860764103E-6,1,0.999253354069792,40.0298881530762,1.99668646972932,17.0499999076128,-0.00170776289188711,-0.000315656629759475,0.25,-6.72095054796327E-7,-0.000151335626508825,-1.7979595838069E-6,9.995451,9.995451,57298.359375,57308.171875,56.5578580230252,20.5221711208957,13.038077,0,0,0,40,4449,9.99495,57303.265625,,,,,,,,,,,,,0,,,,0.00245,,,,,,9.995451,,,,
,29484876.39,9.9947805,61793.765625,-0.000176621479413554,1.72693764850239E-6,1,0.999253354069792,40.0298881530762,1.99683042683024,17.0499999076128,-0.0019950437544008,-0.000358812698332282,0.25,6.80917246656529E-8,-0.000176633866858687,-1.24637811677458E-6,9.9947805,9.9947805,61786.1953125,61801.3359375,56.5930313063906,20.5279168564224,12.658426,0,0,0,40,4449,9.9978,61793.765625,,,,,,,,,,,,,0,,,,0,,,,,,9.9947805,,,,
,29484967.055,9.9954443,66324.24609375,-0.00020351969529188,1.83482150916908E-6,1,0.999253354069792,40.0298881530762,1.99674724175155,17.0499999076128,-0.0023009815358874,-0.000406631353744129,0.25,6.91624230164116E-7,-0.000203621801865856,-8.18850794184923E-7,9.9954443,9.9954443,66314.3359375,66334.15625,56.9924434797176,20.5234340796218,12.658426,0,0,0,40,4449,10.0032,66324.24609375,,,,,,,,,,,,,0,,,,-0.00245,,,,,,9.9954443,,,,
,29485059.25,9.9948874,70932.33203125,-0.000231503387295904,1.61804109794293E-6,1,0.999253354069792,40.0298881530762,1.99685464171052,17.0499999076128,-0.00261610883918752,-0.000476208216334019,0.25,-4.13811121591642E-7,-0.00023170241945482,-2.12345111909399E-6,9.9948874,9.9948874,70922.2890625,70942.375,56.2108149604867,20.5233633727361,12.658426,0,0,0,40,4449,10.0086,70932.33203125,,,,,,,,,,,,,0,,,,0.00245,,,,,,9.9948874,,,,
,29485155.385,9.9944401,75737.5859375,-0.000254652003174983,1.5759427695424E-6,1,0.999253354069792,40.0298881530762,1.99661832385978,17.0499999076128,-0.00287934972384259,-0.000519253315742771,0.25,-5.4150679416227E-8,-0.00025497362100452,-1.91894019994238E-6,9.9944401,9.9944401,75730.078125,75745.09375,56.9103724851983,20.5251239952161,12.278775,0,0,0,40,4449,10.0118,75737.5859375,,,,,,,,,,,,,0,,,,0.00245,,,,,,9.9944401,,,,
,29485253.5,9.99431325,80643.89453125,-0.00028497972606345,1.88721341894048E-6,1,0.999253354069792,40.0298881530762,1.99676342574465,17.0499999076128,-0.00322288983080957,-0.000585847888647326,0.25,-4.81221233448277E-7,-0.000285443950044991,-2.54633314776308E-6,9.9941187,9.9945078,80634.0078125,80653.78125,56.3413469231983,20.5245477299122,13.038077,0,0,0,40,4449,10.01865,80643.89453125,,,,,,,,,,,,,0,,,,-0.0049,,,,,,9.99431325,,,,
,29485349.735,9.9939499,85451.94921875,-0.00031025485820187,1.81138900532579E-6,1,0.999253354069792,40.0298881530762,1.99681448787654,17.0499999076128,-0.00350765265088713,-0.000651252160397539,0.25,-1.71998053074511E-6,-0.00031085930731237,-3.94261614193268E-6,9.9939499,9.9939499,85446.8515625,85457.046875,56.4484300303329,20.5243735849007,12.278775,0,0,0,40,4449,10.0236,85451.94921875,,,,,,,,,,,,,0,,,,-0.00245,,,,,,9.9939499,,,,
,29485439.695,9.9936142,89966.61328125,-0.000339065886470545,2.38390044723002E-6,1,0.999253354069792,40.0298881530762,1.99677559682476,17.0499999076128,-0.00383173435780412,-0.000727199767296136,0.25,-3.26126886643816E-6,-0.000339820574354265,-5.66175602300255E-6,9.9936142,9.9936142,89940.046875,89993.1796875,56.5320642818906,20.5254122820742,12.658426,0,0,0,40,4449,10.028,89966.61328125,,,,,,,,,,,,,0,,,,0.00245,,,,,,9.9936142,,,,
,29485551.365,9.9972134,85526.51953125,-0.000313387636786444,1.53891538044433E-6,1,0.999253354069792,40.0298881530762,1.99691240478501,17.0499999076128,-0.00354255013693707,-0.000661780462018685,0.25,-2.08402669947423E-6,-0.00031399734206412,-4.32933483159931E-6,9.9972134,9.9972134,85518.7890625,85534.25,56.6797920720252,20.5278779786924,12.278775,0,0,0,40,4449,10.02975,85526.51953125,,,,,,,,,,,,,0,,,,0,,,,,,9.9972134,,,,
,29485649.055,10.0015383,80643.03125,-0.000282533897448607,1.52553253271228E-6,1,0.999253354069792,40.0298881530762,1.99688976479136,17.0499999076128,-0.00319339118801226,-0.000592136229398538,0.25,-1.47425980872262E-6,-0.000282986892643384,-3.52328868658996E-6,10.0015383,10.0015383,80635.234375,80650.828125,56.5766171074867,20.5305810823681,11.899124,0,0,0,40,4449,10.0298,80643.03125,,,,,,,,,,,,,0,,,,0.00245,,,,,,10.0015383,,,,
,29485750.26,10.0015211,75581.5,-0.000254979386276674,1.49903542819058E-6,1,0.999253354069792,40.0298881530762,1.99677279752423,17.0499999076128,-0.00287856125269401,-0.000545866061570503,0.25,-2.34518305339318E-6,-0.000255281480323025,-4.21581077487719E-6,10.0015211,10.0015211,75566.65625,75596.34375,56.9861904515637,20.5274512351808,12.278775,0,0,0,40,4449,10.02575,75581.5,,,,,,,,,,,,,0,,,,0.00245,,,,,,10.0015211,,,,
,29485852.065,10.0029287,70493.265625,-0.000224143743871428,1.3655021463066E-6,1,0.999253354069792,40.0298881530762,1.99684625061659,17.0499999076128,-0.00253113473526573,-0.000470500542795207,0.25,-1.23558027166935E-6,-0.000224322005240847,-2.89259058075643E-6,10.0029287,10.0029287,70483.0625,70503.46875,56.6547799594098,20.5342300078079,12.658426,0,0,0,40,4449,10.02285,70493.265625,,,,,,,,,,,,,0,,,,-0.0049,,,,,,10.0029287,,,,
,29485953.02,10.0038824,65445.57421875,-0.00019487459677597,1.28017502080127E-6,1,0.999253354069792,40.0298881530762,1.99698389479529,17.0499999076128,-0.00219947083895779,-0.000410719708838095,0.25,-1.22585651956117E-6,-0.000194943163214858,-2.67401559296112E-6,10.0038824,10.0038824,65440.48828125,65450.66015625,56.750138638756,20.5324385215725,12.658426,0,0,0,40,4449,10.01935,65445.57421875,,,,,,,,,,,,,0,,,,-0.00245,,,,,,10.0038824,,,,
,29486055.1,10.0038776,60344.716796875,-0.000165507577749652,1.30173138980603E-6,1,0.999253354069792,40.0298881530762,1.99675930402364,17.0499999076128,-0.0018687911284333,-0.000338391389036243,0.25,-1.31838408512234E-7,-0.000165495417086864,-1.36380663540835E-6,10.0038776,10.0038776,60332.1328125,60357.30078125,56.5000175126021,20.5354877750479,12.658426,0,0,0,40,4449,10.01655,60344.716796875,,,,,,,,,,,,,0,,,,0.00245,,,,,,10.0038776,,,,
,29486154.08,10.0039506,55397.177734375,-0.000136796059177446,1.22628522366743E-6,1,0.999253354069792,40.0298881530762,1.99683645572997,17.0499999076128,-0.00154539166413361,-0.000271438641832331,0.25,6.09540795053898E-7,-0.000136726550411299,-4.07025196923072E-7,10.0038948,10.0040064,55389.73828125,55404.6171875,56.7767140084099,20.5353324367798,11.899124,0,0,0,40,4449,10.01255,55397.177734375,,,,,,,,,,,,,0,,,,0,,,,,,10.0039506,,,,
,29486253.615,10.0039568,50422.06640625,-0.000108818088594347,1.38153077946369E-6,1,0.999253354069792,40.0298881530762,1.99682287313145,17.0499999076128,-0.00122646335330675,-0.000228256563522307,0.25,-6.2272011041434E-7,-0.000108700698523707,-1.42525028106238E-6,10.0039568,10.0039568,50417.109375,50427.0234375,56.4304525743906,20.5364664664249,12.658426,0,0,0,40,4449,10.0083,50422.06640625,,,,,,,,,,,,,0,,,,0.00245,,,,,,10.0039568,,,,
,29486350.895,10.003746,45559.837890625,-8.52763092330175E-5,1.0228657217592E-6,1,0.999253354069792,40.0298881530762,1.99703097008164,17.0499999076128,-0.000961975495850021,-0.000171969387315408,0.25,1.11250980944643E-7,-8.51461560510997E-5,-5.11294477680582E-7,10.003746,10.003746,45549.84765625,45569.828125,56.7173102409483,20.5355666287441,11.899124,0,0,0,40,4449,10.00485,45559.837890625,,,,,,,,,,,,,0,,,,0.00245,,,,,,10.003746,,,,
,29486451.25,10.0034304,40544.5625,-5.5510019706013E-5,7.054706083384E-7,1,0.999253354069792,40.0298881530762,1.99681505394882,17.0499999076128,-0.000627152155035478,-0.000104336982786993,0.25,7.3413518214063E-7,-5.54008255175361E-5,3.34461379547144E-7,10.0034304,10.0034304,40536.9921875,40552.1328125,56.8283014906791,20.5388608480943,12.658426,0,0,0,40,4449,10.0016,40544.5625,,,,,,,,,,,,,0,,,,0,,,,,,10.0034304,,,,
,29486549.395,10.0026283,35639.4609375,-2.83878190845556E-5,6.77632066998671E-7,1,0.999253354069792,40.0298881530762,1.99682562645235,17.0499999076128,-0.000321409704895497,-4.85990105627079E-5,0.25,7.90810129477581E-7,-2.83200586186296E-5,5.89835109282083E-7,10.0026283,10.0026283,35634.66796875,35644.25390625,57.095618444256,20.5398850139732,12.278775,0,0,0,40,4449,9.99885,35639.4609375,,,,,,,,,,,,,0,,,,-0.0049,,,,,,10.0026283,,,,
,29486646.745,10.0031586,30774.17578125,-1.28703539168437E-6,7.48037160865169E-7,1,0.999253354069792,40.0298881530762,1.9967172153993,17.0499999076128,-1.63147493944859E-5,7.547818541847E-6,0.25,9.01506747312423E-7,-1.28918064551897E-6,8.89961163093993E-7,10.0031586,10.0031586,30766.419921875,30781.931640625,56.9369478548522,20.5392843916503,12.278775,0,0,0,40,4449,9.9999,30774.17578125,,,,,,,,,,,,,0,,,,-0.0049,,,,,,10.0031586,,,,
,29486744.36,10.001359,25894.375,2.43422861705268E-5,6.47146249474286E-7,1,0.999253354069792,40.0298881530762,1.99682792378073,17.0499999076128,0.000272864548930289,5.53153164735805E-5,0.25,5.48805189641817E-7,2.42509305167385E-5,7.06310788999605E-7,10.001359,10.001359,25884.515625,25904.234375,56.5414438241214,20.5403826571249,12.278775,0,0,0,40,4449,9.9986,25894.375,,,,,,,,,,,,,0,,,,-0.00245,,,,,,10.001359,,,,
,29486838.955,10.0007639,21166.794921875,4.97896873422083E-5,5.63541750879256E-7,1,0.999253354069792,40.0298881530762,1.99691387204972,17.0499999076128,0.000559596511292876,0.000103481929016575,0.25,2.82116970123775E-7,4.95846955722086E-5,5.93223530890994E-7,10.0007639,10.0007639,21156.662109375,21176.927734375,56.8103240347368,20.5388340760911,11.899124,0,0,0,40,4449,9.9976,21166.794921875,,,,,,,,,,,,,0,,,,0.0049,,,,,,10.0007639,,,,
,29486935.47,9.9998884,16342.2788085938,7.55181802169508E-5,5.3926575417736E-7,1,0.999253354069792,40.0298881530762,1.99678365386527,17.0499999076128,0.000847317484838222,0.00016247241315477,0.25,9.49884192592351E-7,7.51694555286458E-5,1.39501631908388E-6,9.9998884,9.9998884,16335.025390625,16349.5322265625,56.5156500829868,20.5444694874384,12.658426,0,0,0,40,4449,9.9971,16342.2788085938,,,,,,,,,,,,,0,,,,-0.0049,,,,,,9.9998884,,,,
,29487030.875,9.99928,11574.3642578125,9.9152017180374E-5,4.11129022667874E-7,1,0.999253354069792,40.0298881530762,1.99666619246549,17.0499999076128,0.00111297403665284,0.000207528171563647,0.25,7.74820218409055E-7,9.86554227204745E-5,1.32721806769742E-6,9.99928,9.99928,11567.4365234375,11581.2919921875,56.9299131981791,20.5413727144384,11.899124,0,0,0,40,4449,9.99765,11574.3642578125,,,,,,,,,,,,,0,,,,-0.0049,,,,,,9.99928,,,,
,29487125.415,9.998312,6849.26733398438,0.000122142597490843,3.08280651546178E-7,1,0.999253354069792,40.0298881530762,1.99674626220559,17.0499999076128,0.00137150758039476,0.000250358822724377,0.25,5.33980779981552E-7,0.000121487834061207,1.17377588320291E-6,9.998312,9.998312,6844.07421875,6854.46044921875,56.6907348712945,20.5434195321838,12.658426,0,0,0,40,4449,9.9993,6849.26733398438,,,,,,,,,,,,,0,,,,-0.00245,,,,,,9.998312,,,,
,29487219.89,9.9993114,2126.42395019531,0.000137424104981529,2.80545508086715E-7,1,0.999253354069792,40.0298881530762,1.99697812053169,17.0499999076128,0.00154257664051594,0.00028283043295566,0.25,7.53243978083543E-7,0.000136644388223909,1.42686749160891E-6,9.9993114,9.9993114,2116.45190429687,2136.39599609375,57.0831123879483,20.5365400445624,12.658426,0,0,0,40,4449,9.9994,2126.42395019531,,,,,,,,,,,,,0,,,,0,,,,,,9.9993114,,,,
,29487312.295,9.9992142,-2486.98352050781,-0.000129733660253876,2.54150707252121E-7,1,0.999253354069792,40.0298881530762,1.99664391304298,17.0499999076128,-0.00145510598637795,-0.000272273002066959,0.25,-1.1805298829462E-6,-0.000128997883293533,-1.8168104433887E-6,9.9992142,9.9992142,-2491.86352539062,-2482.103515625,56.7556100383906,20.5445603639424,12.278775,0,0,0,40,4449,9.9975,-2486.98352050781,,,,,,,,,,,,,0,,,,-0.00245,,,,,,9.9992142,,,,
,29487411.145,9.9994926,-7428.79077148438,-0.00011806441034981,3.92878912539623E-7,1,0.999253354069792,40.0298881530762,1.99669738047352,17.0499999076128,-0.00132485596302551,-0.000246973890315412,0.25,-9.53342806525862E-7,-0.000117434228998496,-1.57450756992422E-6,9.9994926,9.9994926,-7436.279296875,-7421.30224609375,57.2933704596215,20.5424839640743,12.278775,0,0,0,40,4449,9.9997,-7428.79077148438,,,,,,,,,,,,,0,,,,0,,,,,,9.9994926,,,,
,29487507.575,9.99991225,-12249.5087890625,-9.47302812057546E-5,4.35379725757775E-7,1,0.999253354069792,40.0298881530762,1.99693817408502,17.0499999076128,-0.00106414018573099,-0.000194945269540978,0.25,-4.36264018253199E-7,-9.42629395232876E-5,-9.70242681904903E-7,9.999794,10.0000305,-12254.3037109375,-12244.7138671875,56.6164801619675,20.5429467673195,12.278775,0,0,0,40,4449,9.99905,-12249.5087890625,,,,,,,,,,,,,0,,,,0,,,,,,9.99991225,,,,
,29487603.015,10.0003061,-17019.3701171875,-7.16609967437983E-5,4.75038957646635E-7,1,0.999253354069792,40.0298881530762,1.99678471498672,17.0499999076128,-0.000804224348169809,-0.000153435919999597,0.25,-8.31537997382639E-7,-7.13349659127335E-5,-1.25765158970692E-6,10.0003061,10.0003061,-17026.8984375,-17011.841796875,57.2292769210445,20.5465292954452,12.278775,0,0,0,40,4449,9.99915,-17019.3701171875,,,,,,,,,,,,,0,,,,-0.0049,,,,,,10.0003061,,,,
,29487698.575,10.0003424,-21794.1767578125,-4.62525975797894E-5,5.11506130644139E-7,1,0.999253354069792,40.0298881530762,1.99688942320148,17.0499999076128,-0.000519608637973482,-9.75876135847952E-5,0.25,-3.89346991186886E-7,-4.606422379939E-5,-6.79671124996037E-7,10.0003424,10.0003424,-21798.9453125,-21789.408203125,57.0182372208522,20.5414364056969,11.899124,0,0,0,40,4449,9.9981,-21794.1767578125,,,,,,,,,,,,,0,,,,0,,,,,,10.0003424,,,,
,29487792.39,10.0027132,-26481.3544921875,-2.058782351369E-5,5.01622731156944E-7,1,0.999253354069792,40.0298881530762,1.99667448620028,17.0499999076128,-0.000231550204040517,-4.24666883365446E-5,0.25,-7.99867581479119E-8,-2.05143161941782E-5,-2.15252411416951E-7,10.0027132,10.0027132,-26486.59375,-26476.115234375,56.9525804252368,20.5440744878047,12.278775,0,0,0,40,4449,10.0003,-26481.3544921875,,,,,,,,,,,,,0,,,,0.0049,,,,,,10.0027132,,,,
,29487888.725,10.0000353,-31299.4765625,5.6956426114106E-6,5.63307224983313E-7,1,0.999253354069792,40.0298881530762,1.99667061223415,17.0499999076128,6.42581029563629E-5,1.08234027220086E-5,0.25,-6.19125041191171E-8,5.67874015242057E-6,-2.28478920631509E-8,10.0000353,10.0000353,-31304.408203125,-31294.544921875,57.3918556530445,20.5454057051179,11.899124,0,0,0,40,4449,9.99825,-31299.4765625,,,,,,,,,,,,,0,,,,0,,,,,,10.0000353,,,,
,29487984.28,9.9994707,-36073.95703125,3.24653806495359E-5,6.12880535465864E-7,1,0.999253354069792,40.0298881530762,1.9967571211733,17.0499999076128,0.000365166591086084,6.90084018266466E-5,0.25,2.87001186156191E-7,3.23810316964138E-5,5.14311626120544E-7,9.9994707,9.9994707,-36076.5,-36071.4140625,57.0807675023906,20.5438123498368,12.278775,0,0,0,40,4449,9.9987,-36073.95703125,,,,,,,,,,,,,0,,,,0,,,,,,9.9994707,,,,
,29488079.525,9.998662,-40833.759765625,5.88696132421917E-5,7.69638634009615E-7,1,0.999253354069792,40.0298881530762,1.99684230976835,17.0499999076128,0.000660574362531923,0.000136010573601975,0.25,1.47031379118116E-6,5.8739466706973E-5,1.89007950273422E-6,9.998662,9.998662,-40838.77734375,-40828.7421875,56.9525804252368,20.5435118170314,11.899124,0,0,0,40,4449,9.9998,-40833.759765625,,,,,,,,,,,,,0,,,,0,,,,,,9.998662,,,,
,29488177.49,9.997839,-45728.580078125,8.68049314300418E-5,9.87670421131063E-7,1,0.999253354069792,40.0298881530762,1.99681844338533,17.0499999076128,0.000975338357357732,0.000196128183585244,0.25,1.75670220576585E-6,8.66603143594837E-5,2.38786943681301E-6,9.997839,9.997839,-45730.953125,-45726.20703125,57.058100275333,20.5445793832226,11.899124,0,0,0,40,4449,10.0018,-45728.580078125,,,,,,,,,,,,,0,,,,0.0049,,,,,,9.997839,,,,
,29488276.625,9.9973307,-50683.095703125,0.000113100046807284,1.12587280978295E-6,1,0.999253354069792,40.0298881530762,1.99673309099886,17.0499999076128,0.00127311259075201,0.000246062169628185,0.25,1.42930382599909E-6,0.000112975248416195,2.26302526704904E-6,9.9973307,9.9973307,-50688.09765625,-50678.09375,56.9721211382176,20.5478498389175,12.278775,0,0,0,40,4449,10.0032,-50683.095703125,,,,,,,,,,,,,0,,,,-0.00245,,,,,,9.9973307,,,,
,29488373.235,9.9955082,-55512.876953125,0.000141833423246917,1.29876423869673E-6,1,0.999253354069792,40.0298881530762,1.99668616093494,17.0499999076128,0.00159639622341785,0.000313628467903136,0.25,2.22170190334128E-6,0.000141741758776557,3.27428248678801E-6,9.9955082,9.9955082,-55525.375,-55500.37890625,56.7282530402175,20.5467618410755,11.899124,0,0,0,40,4449,10.00785,-55512.876953125,,,,,,,,,,,,,0,,,,-0.00245,,,,,,9.9955082,,,,
,29488470.775,9.9962578,-60387.4375,0.000169917464485995,8.61263815347486E-7,1,0.999253354069792,40.0298881530762,1.99675116091548,17.0499999076128,0.00191332508489151,0.000376586300916912,0.25,2.71915483581434E-6,0.000169886428704342,3.98378418205854E-6,9.9962578,9.9962578,-60392.328125,-60382.546875,57.0995265868522,20.5441650277901,12.278775,0,0,0,40,4449,10.0123,-60387.4375,,,,,,,,,,,,,0,,,,0.00245,,,,,,9.9962578,,,,
,29488569.62,9.9960232,-65327.52734375,0.00019917370020174,8.64017873188927E-7,1,0.999253354069792,40.0298881530762,1.996685814206,17.0499999076128,0.00224137812473778,0.000454510495319389,0.25,4.33251575901952E-6,0.000199218806226318,5.81393573376846E-6,9.9960232,9.9960232,-65340.07421875,-65314.98046875,56.7423223535637,20.5442595266812,11.519473,0,0,0,40,4449,10.01485,-65327.52734375,,,,,,,,,,,,,0,,,,0.00245,,,,,,9.9960232,,,,
,29488664.585,9.9960451,-70071.88671875,0.000227193431739635,9.03658024386315E-7,1,0.999253354069792,40.0298881530762,1.99672024571617,17.0499999076128,0.00255961463261453,0.000508560878997944,0.25,4.05641259066923E-6,0.000227345302521169,5.73914218277767E-6,9.9960451,9.9960451,-70076.7734375,-70067,57.0698247031214,20.5469249473441,12.278775,0,0,0,40,4449,10.01835,-70071.88671875,,,,,,,,,,,,,0,,,,0,,,,,,9.9960451,,,,
,29488756.76,9.9951296,-74679.109375,0.00025251867324523,8.84613305454413E-7,1,0.999253354069792,40.0298881530762,1.99668941469181,17.0499999076128,0.00284649507862099,0.000562564054850271,0.25,4.26728485693439E-6,0.000252785383630787,6.12518139842099E-6,9.9951296,9.9951296,-74683.921875,-74674.296875,57.2011382943522,20.5462702026761,12.278775,0,0,0,40,4449,10.0223,-74679.109375,,,,,,,,,,,,,0,,,,0.00245,,,,,,9.9951296,,,,
,29488846.41,9.996089,-79161.33203125,0.000279456221152172,9.29318056327526E-7,1,0.999253354069792,40.0298881530762,1.99674123905028,17.0499999076128,0.00314951550852836,0.000632867417572881,0.25,5.63151823463908E-6,0.000279842807050193,7.67155432959285E-6,9.996089,9.996089,-79166.453125,-79156.2109375,56.7524835243137,20.547879098562,11.899124,0,0,0,40,4449,10.0253,-79161.33203125,,,,,,,,,,,,,0,,,,-0.00245,,,,,,9.996089,,,,
,29488937.26,9.9953709,-83698.55859375,0.000304653053078931,1.06868028372272E-6,1,0.999253354069792,40.0298881530762,1.99660796593866,17.0499999076128,0.00343614273217392,0.000680534613498151,0.25,5.31805283260333E-6,0.000305182704414463,7.51763062800878E-6,9.9953709,9.9953709,-83703.6953125,-83693.421875,57.1847240954484,20.547851327251,11.899124,0,0,0,40,4449,10.02865,-83698.55859375,,,,,,,,,,,,,0,,,,0,,,,,,9.9953709,,,,
,29489020.97,9.9952898,-87883.4375,0.000328529041878664,9.895435883175E-7,1,0.999253354069792,40.0298881530762,1.9967387605401,17.0499999076128,0.00370638211745331,0.000736162230757509,0.25,5.94299124858254E-6,0.000329194781558878,8.28922520714633E-6,9.9952898,9.9952898,-87890.859375,-87876.015625,57.2339666921599,20.5482838518051,11.519473,0,0,0,40,4449,10.0327,-87883.4375,,,,,,,,,,,,,0,,,,0,,,,,,9.9952898,,,,
,29489125.235,9.9973097,-87910.734375,0.000329851369206154,9.03246425800808E-7,1,0.999253354069792,40.0298881530762,1.99671035531373,17.0499999076128,0.00372131540473281,0.000738789788310504,0.25,5.93823171415437E-6,0.000330520602807024,8.29366756906776E-6,9.9973097,9.9973097,-87913.25,-87908.21875,56.9353845978137,20.5479025937963,11.899124,0,0,0,40,4449,10.0352,-87910.734375,,,,,,,,,,,,,0,,,,0,,,,,,9.9973097,,,,
,29489211.555,10.0003872,-83598.58984375,0.000303322013999343,1.01972124046656E-6,1,0.999253354069792,40.0298881530762,1.99675526669907,17.0499999076128,0.00342300138199792,0.000668409106137706,0.25,4.48158417823782E-6,0.000303853016358434,6.67058711093104E-6,10.0003872,10.0003872,-83606.140625,-83591.0390625,57.1847240954484,20.5481830262231,11.519473,0,0,0,40,4449,10.0346,-83598.58984375,,,,,,,,,,,,,0,,,,0,,,,,,10.0003872,,,,
,29489303.58,10.0022163,-79000.875,0.000277914785423297,1.15567129300129E-6,1,0.999253354069792,40.0298881530762,1.99646216431555,17.0499999076128,0.0031355193712504,0.000608002832601537,0.25,3.71790280296092E-6,0.000278309525958149,5.74450409383999E-6,10.0022163,10.0022163,-79003.4609375,-78998.2890625,57.2824276603522,20.5491841104431,11.519473,0,0,0,40,4449,10.0312,-79000.875,,,,,,,,,,,,,0,,,,0,,,,,,10.0022163,,,,
,29489394.58,10.002903,-74451.36328125,0.000252965434815053,8.3194808040891E-7,1,0.999253354069792,40.0298881530762,1.99656927346303,17.0499999076128,0.00285169094495472,0.000561430764238258,0.25,4.08952155918141E-6,0.000253229335030805,5.95119522299626E-6,10.002903,10.002903,-74456.3359375,-74446.390625,57.088583787583,20.5500449239578,12.278775,0,0,0,40,4449,10.02935,-74451.36328125,,,,,,,,,,,,,0,,,,0,,,,,,10.002903,,,,
,29489488.4,10.0032759,-69761.640625,0.000225182311589276,8.44528487959226E-7,1,0.999253354069792,40.0298881530762,1.99667657646145,17.0499999076128,0.00253414136404157,0.000518995390333405,0.25,5.3434342382735E-6,0.000225317115076132,7.01287524677519E-6,10.0032759,10.0032759,-69769.1015625,-69754.1796875,57.1386080128137,20.5494879287433,11.899124,0,0,0,40,4449,10.0269,-69761.640625,,,,,,,,,,,,,0,,,,-0.0049,,,,,,10.0032759,,,,
,29489589.235,10.0034237,-64724.693359375,0.000195195991079384,8.77932314095536E-7,1,0.999253354069792,40.0298881530762,1.99677388871906,17.0499999076128,0.00219602373212264,0.000448566514264642,0.25,4.52309017631671E-6,0.000195227596699828,5.97540191498703E-6,10.0034237,10.0034237,-64732.3671875,-64717.01953125,57.0870205305445,20.549169968168,12.278775,0,0,0,40,4449,10.023,-64724.693359375,,,,,,,,,,,,,0,,,,-0.0049,,,,,,10.0034237,,,,
,29489688.875,10.0039206,-59742.28125,0.000166352821560196,7.76807431895504E-7,1,0.999253354069792,40.0298881530762,1.99676786501849,17.0499999076128,0.00187152558235914,0.00037733179633527,0.25,3.42941733738989E-6,0.00016630664595547,4.66723058591897E-6,10.0039206,10.0039206,-59749.7890625,-59734.7734375,56.9861904515637,20.5483288045353,11.519473,0,0,0,40,4449,10.0194,-59742.28125,,,,,,,,,,,,,0,,,,0,,,,,,10.0039206,,,,
,29489789.795,10.0034657,-54697.44921875,0.000137813031759726,8.62354011412494E-7,1,0.999253354069792,40.0298881530762,1.99684221242157,17.0499999076128,0.00154571144978798,0.000334837774705863,0.25,4.82619688431752E-6,0.000137693162793009,5.84640438007483E-6,10.0034657,10.0034657,-54707.53515625,-54687.36328125,57.1245386994676,20.5465940239768,11.899124,0,0,0,40,4449,10.01495,-54697.44921875,,,,,,,,,,,,,0,,,,0.00245,,,,,,10.0034657,,,,
,29489890.305,10.0037756,-49675.86328125,0.000109974298038457,7.75727973745141E-7,1,0.999253354069792,40.0298881530762,1.99678563394812,17.0499999076128,0.00123392806285523,0.000260910262856672,0.25,3.31182447585472E-6,0.00010982756633839,4.11871857050909E-6,10.0037756,10.0037756,-49681.125,-49670.6015625,57.0252718775253,20.5468627913989,11.899124,0,0,0,40,4449,10.0116,-49675.86328125,,,,,,,,,,,,,0,,,,-0.0049,,,,,,10.0037756,,,,
,29489991.585,10.0040941,-44616.2734375,8.01339835278178E-5,8.93661209269876E-7,1,0.999253354069792,40.0298881530762,1.9967042854328,17.0499999076128,0.000900110988337442,0.000181688159811571,0.25,1.6823721495074E-6,7.99907960906179E-5,2.26283265042714E-6,10.0040941,10.0040941,-44623.73828125,-44608.80859375,56.9627415959868,20.5480226789447,12.278775,0,0,0,40,4449,10.0085,-44616.2734375,,,,,,,,,,,,,0,,,,0,,,,,,10.0040941,,,,
,29490093.23,10.0032988,-39533.53515625,5.15230145034216E-5,5.92001585222214E-7,1,0.999253354069792,40.0298881530762,1.996872970407,17.0499999076128,0.000577618005418977,0.000121520748879858,0.25,1.5104419164721E-6,5.14004761061943E-5,1.87515465886409E-6,10.0032988,10.0032988,-39546.1015625,-39520.96875,56.9822823089676,20.5454596271928,12.278775,0,0,0,40,4449,10.0055,-39533.53515625,,,,,,,,,,,,,0,,,,-0.00245,,,,,,10.0032988,,,,
,29490192.925,10.0023003,-34551.888671875,2.29042127089633E-5,7.0637905378527E-7,1,0.999253354069792,40.0298881530762,1.99675824459005,17.0499999076128,0.000255319435584667,6.12637141967534E-5,0.25,1.32119347467762E-6,2.28332233722437E-5,1.47716316135212E-6,10.0023003,10.0023003,-34559.06640625,-34544.7109375,56.9861904515637,20.5458185382453,11.899124,0,0,0,40,4449,10.0039,-34551.888671875,,,,,,,,,,,,,0,,,,0,,,,,,10.0023003,,,,
,29490292.29,10.0018158,-29584.6025390625,-5.19574473690216E-6,5.62877678021535E-7,1,0.999253354069792,40.0298881530762,1.99685127789902,17.0499999076128,-6.00243930810219E-5,-2.00991335646261E-6,0.25,7.54394245663967E-7,-5.18409145336048E-6,7.16921754288843E-7,10.0018158,10.0018158,-29591.962890625,-29577.2421875,56.9252234270637,20.5504160829469,11.899124,0,0,0,40,4449,10.0015,-29584.6025390625,,,,,,,,,,,,,0,,,,-0.0049,,,,,,10.0018158,,,,
,29490392.475,10.0007572,-24579.998046875,-3.16032892411086E-5,6.55366761599833E-7,1,0.999253354069792,40.0298881530762,1.99678743875766,17.0499999076128,-0.000358163466010503,-4.97102297949634E-5,0.25,1.24847876871491E-6,-3.14931922431772E-5,1.03910025879903E-6,10.0007572,10.0007572,-24584.736328125,-24575.259765625,57.2222422643714,20.5486479588597,11.899124,0,0,0,40,4449,10.00175,-24579.998046875,,,,,,,,,,,,,0,,,,0.00245,,,,,,10.0007572,,,,
,29490492.5,10.0002832,-19580.4599609375,-5.79197932761651E-5,5.18425679623928E-7,1,0.999253354069792,40.0298881530762,1.9966994091814,17.0499999076128,-0.000651941096947733,-0.000113997040319067,0.25,2.30616933624717E-7,-5.76758384060619E-5,-1.27712422564551E-7,10.0002832,10.0002832,-19582.935546875,-19577.984375,56.5172133400252,20.5480002387827,12.278775,0,0,0,40,4449,10.0006,-19580.4599609375,,,,,,,,,,,,,0,,,,-0.00245,,,,,,10.0002832,,,,
,29490593.375,10.000288,-14538.8022460938,-8.40095589282786E-5,4.54009639424423E-7,1,0.999253354069792,40.0298881530762,1.9965753806132,17.0499999076128,-0.000944805495793273,-0.000166905183875151,0.25,1.59112757626853E-7,-8.36150565538132E-5,-3.30963553920985E-7,10.000288,10.000288,-14551.384765625,-14526.2197265625,56.9627415959868,20.5477542986123,12.278775,0,0,0,40,4449,10.0013,-14538.8022460938,,,,,,,,,,,,,0,,,,0.00245,,,,,,10.000288,,,,
,29490692.235,9.9988594,-9598.6181640625,-0.000108533709634298,3.35889245372594E-7,1,0.999253354069792,40.0298881530762,1.99673380368695,17.0499999076128,-0.00121906812952818,-0.000221837848447925,0.25,-3.92650475567402E-7,-0.000107975135904942,-9.83701159514155E-7,9.9988594,9.9988594,-9603.6318359375,-9593.6044921875,57.3887291389676,20.5432941405932,11.899124,0,0,0,40,4449,10.0016,-9598.6181640625,,,,,,,,,,,,,0,,,,0,,,,,,9.9988594,,,,
,29490785.71,10.0000753,-4924.84252929687,-0.000129296599165113,3.28368711227088E-7,1,0.999253354069792,40.0298881530762,1.99690820829128,17.0499999076128,-0.0014514606497978,-0.000266647436896409,0.25,-7.29244827465849E-7,-0.000128585206874655,-1.38754522341808E-6,10.0000753,10.0000753,-4930.0703125,-4919.61474609375,56.6852634716598,20.5433328848314,11.899124,0,0,0,40,4449,10.0025,-4924.84252929687,,,,,,,,,,,,,0,,,,-0.00245,,,,,,10.0000753,,,,
,29490876.455,10.0024118,-390.64729309082,-9.67424060796388E-5,4.0341104672877E-7,1,0.999253354069792,40.0298881530762,1.99679497723353,17.0499999076128,-0.00108493026260316,-0.000203625259528956,0.25,-9.45263384657299E-7,-9.61833211839347E-5,-1.4075809844489E-6,10.0024118,10.0024118,-395.523559570313,-385.771026611328,56.6610329875637,20.5433870116586,11.899124,0,0,0,40,4449,10.00075,-390.64729309082,,,,,,,,,,,,,0,,,,0.0049,,,,,,10.0024118,,,,
,29490965.54,9.9995899,4060.13525390625,0.000131313625519588,3.33782817891671E-7,1,0.999253354069792,40.0298881530762,1.9967553547478,17.0499999076128,0.00147507903514034,0.000264204934549871,0.25,1.64144138582169E-7,0.00013058661221017,8.27877248413843E-7,9.9995899,9.9995899,4052.5361328125,4067.734375,56.6235148186406,20.5440085135059,12.278775,0,0,0,40,4449,10.0021,4060.13525390625,,,,,,,,,,,,,0,,,,0.00245,,,,,,9.9995899,,,,
,29491055.18,9.9999104,8538.833984375,0.000113047624301884,3.55765053852411E-7,1,0.999253354069792,40.0298881530762,1.99678981041978,17.0499999076128,0.00126994977829102,0.000229628751087255,0.25,2.91306165168866E-7,0.000112457049032098,8.98653375726801E-7,9.9999104,9.9999104,8526.580078125,8551.087890625,56.8439340610637,20.5439758925716,12.278775,0,0,0,40,4449,10.00155,8538.833984375,,,,,,,,,,,,,0,,,,-0.0049,,,,,,9.9999104,,,,
,29491140.865,10.0001631,12824.6879882812,9.17580184125749E-5,3.76032420776041E-7,1,0.999253354069792,40.0298881530762,1.99655485528942,17.0499999076128,0.00103227485740435,0.000179498510833891,0.25,-4.09026346767341E-7,9.13146016168744E-5,1.16101922815632E-7,10.0001631,10.0001631,12814.486328125,12834.8896484375,56.6735390438714,20.5455492309268,11.899124,0,0,0,40,4449,10.0008,12824.6879882812,,,,,,,,,,,,,0,,,,0.00245,,,,,,10.0001631,,,,
,29491229.865,10.0005445,17272.43359375,6.92088865373619E-5,4.33493965559709E-7,1,0.999253354069792,40.0298881530762,1.99666368565853,17.0499999076128,0.000778898239076591,0.000135767409868982,0.25,-3.01938700876536E-7,6.89022833788792E-5,1.15736240468849E-7,10.0005445,10.0005445,17262.392578125,17282.474609375,56.3194613246598,20.5452847551149,11.899124,0,0,0,40,4449,10.0009,17272.43359375,,,,,,,,,,,,,0,,,,0,,,,,,10.0005445,,,,
,29491318.21,10.000577,21687.3984375,4.59581607108624E-5,3.88886923396154E-7,1,0.999253354069792,40.0298881530762,1.99656733545385,17.0499999076128,0.000518773677225552,8.26694724334179E-5,0.25,-8.82328741473541E-7,4.57785033589509E-5,-5.89046619287064E-7,10.000577,10.000577,21679.841796875,21694.955078125,56.9752476522945,20.545588535128,12.278775,0,0,0,40,4449,10.0006,21687.3984375,,,,,,,,,,,,,0,,,,0,,,,,,10.000577,,,,
,29491406.36,10.0000973,26092.8876953125,2.27366840475043E-5,4.13930415643555E-7,1,0.999253354069792,40.0298881530762,1.99651598571016,17.0499999076128,0.000258329025098406,3.21733458219439E-5,0.25,-1.21925327915297E-6,2.26631781284311E-5,-1.0656685238006E-6,10.0000973,10.0000973,26087.6640625,26098.111328125,56.8673829166406,20.5452731481574,12.278775,0,0,0,40,4449,10.0006,26092.8876953125,,,,,,,,,,,,,0,,,,-0.0049,,,,,,10.0000973,,,,
,29491497.68,10.0004578,30658.515625,-2.26306490650986E-6,5.50525803292402E-7,1,0.999253354069792,40.0298881530762,1.9966049981154,17.0499999076128,-2.30515238318861E-5,-1.80957582449403E-5,0.25,-1.20077799432503E-6,-2.24786801294731E-6,-1.21242384185052E-6,10.0004578,10.0004578,30651.080078125,30665.951171875,57.0831123879483,20.5448071784137,11.899124,0,0,0,40,4449,10.0001,30658.515625,,,,,,,,,,,,,0,,,,0.0049,,,,,,10.0004578,,,,
,29491590.2,9.9993305,35283.685546875,-2.74143234926653E-5,6.93969475826383E-7,1,0.999253354069792,40.0298881530762,1.99654210516802,17.0499999076128,-0.000303256870060658,-8.62824065251754E-5,0.25,-2.73091171378741E-6,-2.73233994344775E-5,-2.91549386329824E-6,9.9993305,9.9993305,35278.484375,35288.88671875,57.0182372208522,20.5462983101707,11.899124,0,0,0,40,4449,10.0004,35283.685546875,,,,,,,,,,,,,0,,,,-0.0049,,,,,,9.9993305,,,,
,29491679.655,9.9992094,39753.6015625,-5.30195565980324E-5,6.74914106620077E-7,1,0.999253354069792,40.0298881530762,1.9966162167689,17.0499999076128,-0.000591804876468134,-0.000139104877642145,0.25,-2.80221988557766E-6,-5.28857628670099E-5,-3.1752452953816E-6,9.9992094,9.9992094,39746.0546875,39761.1484375,56.6368025034675,20.5446719117657,12.278775,0,0,0,40,4449,10.0017,39753.6015625,,,,,,,,,,,,,0,,,,-0.00245,,,,,,9.9992094,,,,
,29491770.54,9.9984655,44296.310546875,-7.78580599580851E-5,6.90750376125667E-7,1,0.999253354069792,40.0298881530762,1.99658035199101,17.0499999076128,-0.000872512888658786,-0.000187354384597941,0.25,-2.59687335731984E-6,-7.77093538394372E-5,-3.15862422106605E-6,9.9984655,9.9984655,44288.71484375,44303.90625,57.1503324406022,20.5446941293727,11.519473,0,0,0,40,4449,10.0043,44296.310546875,,,,,,,,,,,,,0,,,,-0.00245,,,,,,9.9984655,,,,
,29491859.21,9.9975958,48727.099609375,-0.000103270434898099,8.9560520723794E-7,1,0.999253354069792,40.0298881530762,1.99666811886676,17.0499999076128,-0.0011606524184194,-0.000233203299578369,0.25,-2.06833281508364E-6,-0.000103130360243978,-2.82552077401023E-6,9.9975958,9.9975958,48722.1015625,48732.09765625,56.8963031718522,20.545858113992,11.899124,0,0,0,40,4449,10.0057,48727.099609375,,,,,,,,,,,,,0,,,,-0.00245,,,,,,9.9975958,,,,
,29491948.305,9.9965925,53179.765625,-0.000128733408974949,7.13379742534462E-7,1,0.999253354069792,40.0298881530762,1.99652399897015,17.0499999076128,-0.0014463111580076,-0.000296743928903831,0.25,-3.09712551057432E-6,-0.000128612642570738,-4.04891923215898E-6,9.9965925,9.9965925,53169.7421875,53189.7890625,56.8408075469868,20.5468127389811,11.899124,0,0,0,40,4449,10.00835,53179.765625,,,,,,,,,,,,,0,,,,0,,,,,,9.9965925,,,,
,29492035.895,9.9957399,57557.537109375,-0.000153270435945681,8.68892800441833E-7,1,0.999253354069792,40.0298881530762,1.9965092170499,17.0499999076128,-0.00172388271423925,-0.000346933224433038,0.25,-3.1061933081739E-6,-0.000153196458511965,-4.2453563831123E-6,9.9957399,9.9957399,57547.5859375,57567.48828125,56.5688008222944,20.5480202934827,11.899124,0,0,0,40,4449,10.01155,57557.537109375,,,,,,,,,,,,,0,,,,-0.0049,,,,,,9.9957399,,,,
,29492126.395,9.9958906,62082.923828125,-0.000179113479675492,7.64997231037679E-7,1,0.999253354069792,40.0298881530762,1.99646790668405,17.0499999076128,-0.00201753473372347,-0.000393564108755576,0.25,-2.56472840978954E-6,-0.000179111219646833,-3.89789193649057E-6,9.9958906,9.9958906,62080.3515625,62085.49609375,56.8509687177368,20.5462414895902,11.899124,0,0,0,40,4449,10.0151,62082.923828125,,,,,,,,,,,,,0,,,,-0.0049,,,,,,9.9958906,,,,
,29492218.38,9.9963427,66678.609375,-0.000205537846895404,9.52630429413562E-7,1,0.999253354069792,40.0298881530762,1.99645558841714,17.0499999076128,-0.00231293134392926,-0.000469521935786791,0.25,-4.51570179933917E-6,-0.000205608683349266,-6.04329279838917E-6,9.9962502,9.9964352,66673.4609375,66683.7578125,56.5985027060252,20.5459611377508,11.519473,0,0,0,40,4449,10.01945,66678.609375,,,,,,,,,,,,,0,,,,0,,,,,,9.9963427,,,,
,29492314.5,9.9954157,71484.07421875,-0.000232133661977565,9.22290807877981E-7,1,0.999253354069792,40.0298881530762,1.99650874774104,17.0499999076128,-0.00261235369981184,-0.000536082448061863,0.25,-5.60403441488278E-6,-0.000232305658425809,-7.32171315692507E-6,9.9954157,9.9954157,71476.6328125,71491.515625,56.7055858131598,20.5447774070297,11.519473,0,0,0,40,4449,10.0221,71484.07421875,,,,,,,,,,,,,0,,,,-0.0049,,,,,,9.9954157,,,,
,29492411.515,9.99555255,76334.80859375,-0.000261125688444597,1.03655799787373E-6,1,0.999253354069792,40.0298881530762,1.99641042176381,17.0499999076128,-0.00294055490746004,-0.000598152961085667,0.25,-5.87094378271729E-6,-0.000261425248178494,-7.78848361260101E-6,9.9953127,9.9957924,76324.6796875,76344.9375,56.7720242372945,20.5476983548649,11.899124,0,0,0,40,4449,10.027,76334.80859375,,,,,,,,,,,,,0,,,,-0.00245,,,,,,9.99555255,,,,
,29492513.615,9.9956427,81437.73828125,-0.000291562916037579,1.02482882796286E-6,1,0.999253354069792,40.0298881530762,1.99641712585214,17.0499999076128,-0.0032856987815159,-0.00066202703491331,0.25,-6.04050697907163E-6,-0.000292014891446034,-8.15865884045736E-6,9.9956427,9.9956427,81432.890625,81442.5859375,56.6227331901214,20.5464278377732,11.899124,0,0,0,40,4449,10.03115,81437.73828125,,,,,,,,,,,,,0,,,,0,,,,,,9.9956427,,,,
,29492610.385,9.9950714,86273.4609375,-0.000321154785578991,9.47746812830499E-7,1,0.999253354069792,40.0298881530762,1.99651824895834,17.0499999076128,-0.00361738986196593,-0.000747367293660104,0.25,-8.26271379814914E-6,-0.000321752561509305,-1.05714369604889E-5,9.9950714,9.9950714,86271.03125,86275.890625,56.6555615879291,20.5459045969209,11.899124,0,0,0,40,4449,10.035,86273.4609375,,,,,,,,,,,,,0,,,,-0.0049,,,,,,9.9950714,,,,
,29492722.62,9.9963627,89102.0625,-0.000337917573918984,8.65231757789537E-7,1,0.999253354069792,40.0298881530762,1.99631039113103,17.0499999076128,-0.00381068049483309,-0.000763510358296932,0.25,-6.68765930674287E-6,-0.000338626021609398,-9.09390105627791E-6,9.9963627,9.9963627,89091.828125,89112.296875,56.5312826533714,20.545137088692,12.278775,0,0,0,40,4449,10.0401,89102.0625,,,,,,,,,,,,,0,,,,0,,,,,,9.9963627,,,,
,29492814.195,9.9995065,84524.0703125,-0.00030976928768129,9.56231435366993E-7,1,0.999253354069792,40.0298881530762,1.99643895687285,17.0499999076128,-0.00349364847369158,-0.000692629011990036,0.25,-5.47265158841441E-6,-0.00031032562969585,-7.70463409052434E-6,9.9994278,9.9995852,84489.109375,84559.03125,56.9916618511983,20.5439369329131,11.899124,0,0,0,40,4449,10.03845,84524.0703125,,,,,,,,,,,,,0,,,,0,,,,,,9.9995065,,,,
,29492913.845,10.0017176,79543.1953125,-0.000281969543340819,9.46241496320499E-7,1,0.999253354069792,40.0298881530762,1.99644089501878,17.0499999076128,-0.00317661481339306,-0.000643272858715085,0.25,-6.10728158038105E-6,-0.000282364697780581,-8.16467960535099E-6,10.0017176,10.0017176,79530.7578125,79555.6328125,57.2167708647368,20.545108971558,11.899124,0,0,0,40,4449,10.03665,79543.1953125,,,,,,,,,,,,,0,,,,0,,,,,,10.0017176,,,,
,29493010.375,10.0033302,74717.1796875,-0.000252637152263068,1.14126843307114E-6,1,0.999253354069792,40.0298881530762,1.99655850454902,17.0499999076128,-0.00284507143631161,-0.000577170767913593,0.25,-5.54096757472969E-6,-0.000252895427507239,-7.40112170093351E-6,10.0033302,10.0033302,74712.2578125,74722.1015625,56.6360208749483,20.5454387409325,11.899124,0,0,0,40,4449,10.03415,74717.1796875,,,,,,,,,,,,,0,,,,-0.0049,,,,,,10.0033302,,,,
,29493112.885,10.00352,69591.5078125,-0.000222160410199085,8.93787702614387E-7,1,0.999253354069792,40.0298881530762,1.99652715726241,17.0499999076128,-0.00249825174119898,-0.000521238482502527,0.25,-6.09001119711116E-6,-0.000222284129013922,-7.73795862661695E-6,10.00352,10.00352,69579.0546875,69603.9609375,56.8228300910445,20.5459530907924,11.519473,0,0,0,40,4449,10.02965,69591.5078125,,,,,,,,,,,,,0,,,,0.00245,,,,,,10.00352,,,,
,29493215.21,10.0039797,64478.626953125,-0.000193051888507754,8.47444532568073E-7,1,0.999253354069792,40.0298881530762,1.996543350372,17.0499999076128,-0.00216789024743541,-0.000464243169150515,0.25,-6.30233525381072E-6,-0.000193065278421201,-7.73939302979704E-6,10.0039797,10.0039797,64471.08203125,64486.171875,56.8236117195637,20.5499219236771,11.519473,0,0,0,40,4449,10.02615,64478.626953125,,,,,,,,,,,,,0,,,,0,,,,,,10.0039797,,,,
,29493316.84,10.0041676,59398.10546875,-0.000163458447303092,8.72559107737215E-7,1,0.999253354069792,40.0298881530762,1.99646688096346,17.0499999076128,-0.00183672053297502,-0.000381342337373146,0.25,-4.31225814177656E-6,-0.000163400754009265,-5.5282290810917E-6,10.0041676,10.0041676,59388.0390625,59408.171875,56.689171614256,20.5490091457581,11.899124,0,0,0,40,4449,10.0216,59398.10546875,,,,,,,,,,,,,0,,,,0.0049,,,,,,10.0041676,,,,
,29493415.74,10.0041084,54455.560546875,-0.000135947773523225,8.6151957167407E-7,1,0.999253354069792,40.0298881530762,1.99646331350136,17.0499999076128,-0.00152291850334534,-0.000338892593999734,0.25,-5.52799138333315E-6,-0.000135820606638225,-6.53355191072675E-6,10.0041084,10.0041084,54445.4609375,54465.66015625,56.7384142109675,20.5496521991315,11.519473,0,0,0,40,4449,10.01825,54455.560546875,,,,,,,,,,,,,0,,,,-0.00245,,,,,,10.0041084,,,,
,29493518.305,10.0041838,49328.2890625,-0.000106346601304792,8.9691853269588E-7,1,0.999253354069792,40.0298881530762,1.99649527328013,17.0499999076128,-0.00119098556908089,-0.000263534263927933,0.25,-4.20265799214586E-6,-0.000106193595717429,-4.98113374869231E-6,10.0041838,10.0041838,49323.27734375,49333.30078125,56.8611298884868,20.5511534320025,11.139823,0,0,0,40,4449,10.0145,49328.2890625,,,,,,,,,,,,,0,,,,-0.0049,,,,,,10.0041838,,,,
,29493618.755,10.0039525,44307.6953125,-7.77239531476436E-5,7.35761759450935E-7,1,0.999253354069792,40.0298881530762,1.99649101361509,17.0499999076128,-0.000867628918942766,-0.00020559798259516,0.25,-4.23993781280449E-6,-7.75636151420172E-5,-4.79799916906313E-6,10.0038443,10.0040607,44295.1171875,44320.2734375,56.6876083572175,20.5502913407629,11.139823,0,0,0,40,4449,10.01105,44307.6953125,,,,,,,,,,,,,0,,,,0,,,,,,10.0039525,,,,
,29493716.79,10.0035124,39407.419921875,-5.12888604201617E-5,7.52238164568775E-7,1,0.999253354069792,40.0298881530762,1.9963513909564,17.0499999076128,-0.00057154408785414,-0.000139262931199822,0.25,-3.1302596234946E-6,-5.11545879860845E-5,-3.48954305579803E-6,10.0035124,10.0035124,39402.5,39412.33984375,56.7102755842752,20.5506060823477,11.899124,0,0,0,40,4449,10.0073,39407.419921875,,,,,,,,,,,,,0,,,,0.00245,,,,,,10.0035124,,,,
,29493817.705,10.003211,34365.837890625,-2.30347417789449E-5,7.67253876450839E-7,1,0.999253354069792,40.0298881530762,1.99639581793124,17.0499999076128,-0.000254792795127294,-7.23492397430688E-5,0.25,-2.28328237232827E-6,-2.29562614567551E-5,-2.43734867552036E-6,10.003211,10.003211,34355.81640625,34375.859375,56.8689461736791,20.5521650703605,11.899124,0,0,0,40,4449,10.00555,34365.837890625,,,,,,,,,,,,,0,,,,0.00245,,,,,,10.003211,,,,
,29493911.59,10.0029316,29673.306640625,2.82081720953111E-6,3.88977553532727E-7,1,0.999253354069792,40.0298881530762,1.99638535865091,17.0499999076128,3.62080941350208E-5,-1.91100640344547E-5,0.25,-2.20416308871036E-6,2.82662963617151E-6,-2.1780448441021E-6,10.0029316,10.0029316,29663.326171875,29683.287109375,57.0471574760637,20.5504287842714,11.519473,0,0,0,40,4449,10.0028,29673.306640625,,,,,,,,,,,,,0,,,,0,,,,,,10.0029316,,,,
,29494000.68,10.0013609,25219.9970703125,2.67821506171368E-5,5.23581717216691E-7,1,0.999253354069792,40.0298881530762,1.99653229134826,17.0499999076128,0.000304246515096872,3.80080264985626E-5,0.25,-1.42481699240415E-6,2.66930248776386E-5,-1.24512283182234E-6,10.0013609,10.0013609,25214.8828125,25225.111328125,56.7673344661791,20.553080651876,11.899124,0,0,0,40,4449,10.0025,25219.9970703125,,,,,,,,,,,,,0,,,,0,,,,,,10.0013609,,,,
,29494091.55,10.0010853,20680.287109375,5.11557938266189E-5,4.5171911835403E-7,1,0.999253354069792,40.0298881530762,1.99657878292485,17.0499999076128,0.000577776791477558,8.98442924782013E-5,0.25,-1.17143910946406E-6,5.0951860497895E-5,-8.47352731492314E-7,10.0010853,10.0010853,20672.666015625,20687.908203125,56.6704125297944,20.5520397030029,11.519473,0,0,0,40,4449,10.0023,20680.287109375,,,,,,,,,,,,,0,,,,0,,,,,,10.0010853,,,,
,29494185.595,10.0006781,15980.3413085938,7.60593995229828E-5,4.99651545646962E-7,1,0.999253354069792,40.0298881530762,1.99661332505028,17.0499999076128,0.000855910992300316,0.000148963832095393,0.25,-3.44680139566426E-7,7.57133768658885E-5,1.07650132710204E-7,10.0006781,10.0006781,15975.2568359375,15985.42578125,56.8032893780637,20.5543423839891,11.519473,0,0,0,40,4449,10.00145,15980.3413085938,,,,,,,,,,,,,0,,,,-0.0049,,,,,,10.0006781,,,,
,29494277.47,9.9999905,11385.30859375,9.96467261706418E-5,3.73289119687961E-7,1,0.999253354069792,40.0298881530762,1.99656550170327,17.0499999076128,0.00112036020437696,0.00019787191073093,0.25,-1.69971615214518E-7,9.91513920886187E-5,3.88511667302644E-7,9.9999905,9.9999905,11382.7744140625,11387.8427734375,56.8642564025637,20.5514811264969,11.519473,0,0,0,40,4449,10.0011,11385.30859375,,,,,,,,,,,,,0,,,,0.0049,,,,,,9.9999905,,,,
,29494366.995,9.9987478,6912.35791015625,0.000121334718868289,3.76553153170667E-7,1,0.999253354069792,40.0298881530762,1.99645811909235,17.0499999076128,0.00136302708137041,0.000244331996901903,0.25,1.43824847441312E-7,0.000120686880609074,7.82013431161958E-7,9.9987478,9.9987478,6905.22216796875,6919.49365234375,56.9557069393137,20.5539518463014,12.278775,0,0,0,40,4449,10.0021,6912.35791015625,,,,,,,,,,,,,0,,,,-0.0049,,,,,,9.9987478,,,,
,29494456.875,9.9993849,2418.96533203125,0.000136538097513198,4.42378671228549E-7,1,0.999253354069792,40.0298881530762,1.99642157666802,17.0499999076128,0.00153243755423007,0.000279875952462969,0.25,6.51399216607058E-7,0.000135766128380896,1.32377720656313E-6,9.9993849,9.9993849,2411.68188476562,2426.24877929687,57.2761746321984,20.5551891151462,11.519473,0,0,0,40,4449,10.0027,2418.96533203125,,,,,,,,,,,,,0,,,,0,,,,,,9.9993849,,,,
,29494506.455,10.003315,-0.441489428281784,9.93524217145255E-5,3.54773534352104E-7,1,0.999253354069792,40.0298881530762,1.99631036921899,17.0499999076128,0.00111593183603133,0.000197785275117616,0.25,-3.22981972749238E-8,9.87818391756961E-5,4.46759558150422E-7,10.003315,10.003315,-0.456713199615479,-0.42626565694809,57.0158923352945,20.555028488876,11.519473,0,0,0,40,4417,9.9988,-0.441489428281784,,,,,,,,,,,,,0,,,,-0.00245,,,,,,10.003315,,,,