File: data/looselyPackedNP/sc-ios-11/ppms/rawdata/ES_S14_HYST_20K.DAT
[Header]
; VSM Data File (default extension .dat)
; Copyright (c) 2003-2013, Quantum Design, Inc. All rights reserved.
TITLE,
FILEOPENTIME,29090428.05,12/04/2018,12:41 am
BYAPP,VSM,2.0,2.0
INFO,PPMS VSM Option Release 1.4.10 Build 1,APPNAME
INFO,Quantum Design Linear Motor Servo Controller,MOTOR_MODULE_NAME
INFO,3101-100 M1,MOTOR_HW_VERSION
INFO,MMC1014,MOTOR_SERIAL_NUMBER
INFO,SRV No X-over 01.03.11,MOTOR_SOFTWARE_VERSION
INFO,Quantum Design VSM Detection Module,VSM_MODULE_NAME
INFO,3101-150 F0,VSM_HW_VERSION
INFO,VSM707,VSM_SERIAL_NUMBER
INFO,VSM No X-over 01.02.05 May 20 2008 13:51:47,VSM_SOFTWARE_VERSION
INFO,704,PREAMP_SERIAL_NUMBER
INFO,822,COIL_SERIAL_NUMBER
INFO,0,MOMENT_UNITS
INFO,Iron Oxide Spheres,SAMPLE_MATERIAL
INFO,10 nm diameter, collaboration Mainz,SAMPLE_COMMENT
INFO,,SAMPLE_MASS
INFO,,SAMPLE_VOLUME
INFO,,SAMPLE_MOLECULAR_WEIGHT
INFO,,SAMPLE_SIZE
INFO,,SAMPLE_SHAPE
DATATYPE,COMMENT,1
DATATYPE,TIME,2
STARTUPAXIS,X,2
STARTUPAXIS,Y1,5
[Data]
Comment,Time Stamp (sec),Temperature (K),Magnetic Field (Oe),Moment (emu),M. Std. Err. (emu),Transport Action,Averaging Time (sec),Frequency (Hz),Peak Amplitude (mm),Center Position (mm),Coil Signal' (mV),Coil Signal" (mV),Range (mV),M. Quad. Signal (emu),M. Raw' (emu),M. Raw" (emu),Min. Temperature (K),Max. Temperature (K),Min. Field (Oe),Max. Field (Oe),Mass (grams),Motor Lag (deg),Pressure (Torr),VSM Status (code),Motor Status (code),Measure Status (code),Measure Count,PPMS Status (code),System Temp. (K),System Field (Oe),Sample Position (deg),Bridge 1 Resistance (ohms),Bridge 1 Excitation (에),Bridge 2 Resistance (ohms),Bridge 2 Excitation (에),Bridge 3 Resistance (ohms),Bridge 3 Excitation (에),Bridge 4 Resistance (ohms),Bridge 4 Excitation (에),Signal 1 Vin (V),Signal 2 Vin (V),Digital Inputs (code),Drive 1 Iout (mA),Drive 1 Ipower (W),Drive 2 Iout (mA),Drive 2 Ipower (W),Pressure (),Map 20 (),Map 21 (),Map 22 (),Map 23 (),Map 24 (),Map 25 (),Map 26 (),Map 27 (),Map 28 (),Map 29 ()
,29090443.11,19.9977703,-0.380594313144684,,,2,,,,18.0400002068281,,,,,,,19.9977703,19.9977703,-0.380594313144684,-0.380594313144684,,,13.417728,,,,-99999999,4369,20.0163,-0.380594313144684,,,,,,,,,,,,,,,,,,,,,,,19.9977703,,,,
,29090593.8,20.0056438,4536.12841796875,0.000133827750871082,3.31885487467244E-7,1,0.999253354069792,40.0298881530762,1.98451637647813,18.0300008505583,0.00149418979606839,0.000269781578560467,0.25,3.46392338683219E-7,0.000133089394208514,1.0295739914305E-6,20.0056438,20.0056438,4531.15576171875,4541.10107421875,56.9338213407753,20.5758046009383,13.038077,0,0,0,40,4449,20.02045,4536.12841796875,,,,,,,,,,,,,0,,,,0,,,,,,20.0056438,,,,
,29090692.86,19.99534225,9484.4384765625,0.000113929462884118,3.37598788555508E-7,1,0.999253354069792,40.0298881530762,1.98453272979506,18.0300008505583,0.0012721951099131,0.000231470907814973,0.25,4.07684897349215E-7,0.000113341556777444,1.02960480491181E-6,19.9952087,19.9954758,9481.845703125,9487.03125,57.0088576786214,20.5796179529857,13.797379,0,0,0,40,4449,20.00425,9484.4384765625,,,,,,,,,,,,,0,,,,0,,,,,,19.99534225,,,,
,29090795.185,20.0000801,14599.0600585938,8.81840791322985E-5,3.81794636524741E-7,1,0.999253354069792,40.0298881530762,1.98442627279319,18.0300008505583,0.000985745304785754,0.000175560835200478,0.25,-4.55744566810346E-8,8.77693372689411E-5,4.70281617942033E-7,20.0000801,20.0000801,14589.1455078125,14608.974609375,57.1425161554099,20.58102755849,13.797379,0,0,0,40,4449,20.0099,14599.0600585938,,,,,,,,,,,,,0,,,,0.00245,,,,,,20.0000801,,,,
,29090898.9,20.0037251,19781.287109375,6.13288350124192E-5,3.97268953281903E-7,1,0.999253354069792,40.0298881530762,1.98448586523894,18.0300008505583,0.000685758258377605,0.000122979201403889,0.25,2.01848388946185E-8,6.10697834450276E-5,4.00226563005237E-7,20.0037251,20.0037251,19771.421875,19791.15234375,57.115940785756,20.5797252599911,13.797379,0,0,0,40,4449,20.0119,19781.287109375,,,,,,,,,,,,,0,,,,-0.00245,,,,,,20.0037251,,,,
,29091006.235,20.003624,25148.5419921875,3.25704164608136E-5,5.61729938154977E-7,1,0.999253354069792,40.0298881530762,1.98442829290713,18.0300008505583,0.000366069773924006,5.59082510523693E-5,0.25,-8.43276674127205E-7,3.24558192403499E-5,-6.27737855470148E-7,20.003624,20.003624,25138.443359375,25158.640625,56.9424192544868,20.5812905896052,13.417728,0,0,0,40,4449,20.00695,25148.5419921875,,,,,,,,,,,,,0,,,,0,,,,,,20.003624,,,,
,29091111.485,20.0013084,30406.060546875,3.01760100208788E-6,4.53239309155681E-7,1,0.999253354069792,40.0298881530762,1.98438233773839,18.0300008505583,3.57012257130505E-5,-4.65753314810418E-6,0.25,-9.5809024762769E-7,3.01462656779848E-6,-9.34579765715192E-7,20.0013084,20.0013084,30400.892578125,30411.228515625,56.9932251082368,20.5810957908182,13.417728,0,0,0,40,4449,20.0034,30406.060546875,,,,,,,,,,,,,0,,,,0,,,,,,20.0013084,,,,
,29091218.115,20.0023518,35735.98828125,-2.66387868931349E-5,5.50279449062074E-7,1,0.999253354069792,40.0298881530762,1.98426387065236,18.0300008505583,-0.000296445467521365,-6.3961538393699E-5,0.25,-9.21381456175764E-7,-2.65635938102819E-5,-1.10596293335677E-6,20.0023518,20.0023518,35728.5625,35743.4140625,56.8759808303522,20.5842941113647,13.038077,0,0,0,40,4449,20.00215,35735.98828125,,,,,,,,,,,,,0,,,,0.00245,,,,,,20.0023518,,,,
,29091322.57,20.00173,40958.3671875,-5.6768528861626E-5,5.86543232776608E-7,1,0.999253354069792,40.0298881530762,1.98418048822301,18.0300008505583,-0.000633640850474297,-0.000127597444267568,0.25,-1.17055194397154E-6,-5.664500147612E-5,-1.57631935994845E-6,20.00173,20.00173,40945.91796875,40970.81640625,57.129228470583,20.5864890532069,13.417728,0,0,0,40,4449,20.0005,40958.3671875,,,,,,,,,,,,,0,,,,0.00245,,,,,,20.00173,,,,
,29091427.915,20.0020771,46220.92578125,-8.7240256764045E-5,6.21834248622147E-7,1,0.999253354069792,40.0298881530762,1.98427343764277,18.0300008505583,-0.000975460642696813,-0.000189979904152112,0.25,-1.2329890264785E-6,-8.71022766876586E-5,-1.86931005907446E-6,20.0020771,20.0020771,46213.4375,46228.4140625,57.2316218066022,20.58233721348,13.417728,0,0,0,40,4449,19.9993,46220.92578125,,,,,,,,,,,,,0,,,,0,,,,,,20.0020771,,,,
,29091525.305,20.0023212,51090.935546875,-0.000114753652777454,8.44631870668601E-7,1,0.999253354069792,40.0298881530762,1.98423124403333,18.0300008505583,-0.00128477001143819,-0.000244121065587897,0.25,-1.08805432424473E-6,-0.000114632976173781,-1.93514007274868E-6,20.0023212,20.0023212,51080.8515625,51101.01953125,57.2136443506599,20.5835282921693,13.417728,0,0,0,40,4449,19.9977,51090.935546875,,,,,,,,,,,,,0,,,,-0.00245,,,,,,20.0023212,,,,
,29091619.445,20.0018196,55795.70703125,-0.000142980783965791,1.10533647402171E-6,1,0.999253354069792,40.0298881530762,1.98418968774964,18.0300008505583,-0.0016034132715725,-0.000293752895699142,0.25,-4.09841412315172E-7,-0.000142903904632238,-1.47223256807844E-6,20.0018196,20.0018196,55788.0390625,55803.375,57.0283983916022,20.5835836610182,13.797379,0,0,0,40,4449,19.9955,55795.70703125,,,,,,,,,,,,,0,,,,0,,,,,,20.0018196,,,,
,29091713.655,20.0026875,60505.94140625,-0.000170353876241309,8.84046522998519E-7,1,0.999253354069792,40.0298881530762,1.98417661314861,18.0300008505583,-0.00190922752197558,-0.000361229511020031,0.25,-1.47434429329815E-6,-0.000170331327519153,-2.74224776783907E-6,20.0026875,20.0026875,60500.89453125,60510.98828125,57.1706547821022,20.5830874768157,13.417728,0,0,0,40,4449,19.99425,60505.94140625,,,,,,,,,,,,,0,,,,-0.0049,,,,,,20.0026875,,,,
,29091810.695,20.0024109,65356.689453125,-0.000198588443916594,1.118662935072E-6,1,0.999253354069792,40.0298881530762,1.98415626423476,18.0300008505583,-0.00222327001176295,-0.00043989956717159,0.25,-3.38022741382295E-6,-0.000198637555710176,-4.85666639039085E-6,20.0024109,20.0024109,65354.22265625,65359.15625,57.3191642007561,20.5826977485606,13.797379,0,0,0,40,4449,19.991,65356.689453125,,,,,,,,,,,,,0,,,,0,,,,,,20.0024109,,,,
,29091905.095,20.0028896,70071.7578125,-0.000227366468528209,8.86175608859953E-7,1,0.999253354069792,40.0298881530762,1.98421266618546,18.0300008505583,-0.0025478567301503,-0.000496669625684137,0.25,-3.23869067818962E-6,-0.00022752037999284,-4.92166898908149E-6,20.0028896,20.0028896,70061.921875,70081.59375,56.8892685151791,20.5843419781202,13.038077,0,0,0,40,4449,19.9894,70071.7578125,,,,,,,,,,,,,0,,,,0,,,,,,20.0028896,,,,
,29092001.61,20.0028515,74896.984375,-0.000255360248799237,1.06731177242091E-6,1,0.999253354069792,40.0298881530762,1.98423190377703,18.0300008505583,-0.00286463938735155,-0.000547354590483289,0.25,-2.70172225157646E-6,-0.000255641294408709,-4.57740861103424E-6,20.0028515,20.0028515,74889.5546875,74904.4140625,57.0917103016599,20.584587462398,13.797379,0,0,0,40,4449,19.9867,74896.984375,,,,,,,,,,,,,0,,,,-0.00245,,,,,,20.0028515,,,,
,29092098.3,20.0022907,79730.078125,-0.000283026213337789,1.26479005836058E-6,1,0.999253354069792,40.0298881530762,1.98417052782434,18.0300008505583,-0.00317268902286309,-0.000625754519988062,0.25,-4.69653928379734E-6,-0.000283431438429038,-6.75793490833001E-6,20.0022907,20.0022907,79722.578125,79737.578125,56.9924434797176,20.5838043107489,13.038077,0,0,0,40,4449,19.98515,79730.078125,,,,,,,,,,,,,0,,,,-0.00245,,,,,,20.0022907,,,,
,29092196.235,20.0019665,84626.19921875,-0.00031382048800041,8.82155080335898E-7,1,0.999253354069792,40.0298881530762,1.98402243111538,18.0300008505583,-0.00352020530079047,-0.00068673728563272,0.25,-4.58764496448025E-6,-0.000314386446711244,-6.84564097627857E-6,20.0019665,20.0019665,84621.171875,84631.2265625,57.2019199228714,20.5842741793471,13.417728,0,0,0,40,4449,19.9826,84626.19921875,,,,,,,,,,,,,0,,,,0,,,,,,20.0019665,,,,
,29092286.235,20.0021973,89124.12109375,-0.000339360344661242,1.14149696426574E-6,1,0.999253354069792,40.0298881530762,1.98413537021183,18.0300008505583,-0.00380751286234824,-0.000745990655846034,0.25,-5.26847583738384E-6,-0.000340074916640275,-7.68078015176379E-6,20.0021973,20.0021973,89113.875,89134.3671875,56.9283499411406,20.5831081840547,13.797379,0,0,0,40,4449,19.9821,89124.12109375,,,,,,,,,,,,,0,,,,0,,,,,,20.0021973,,,,
,29092394.075,20.00057225,86508.69921875,-0.00032390103949845,1.0583350509004E-6,1,0.999253354069792,40.0298881530762,1.98410474143188,18.0300008505583,-0.00363358305986111,-0.000710685212409339,0.25,-4.90472781258229E-6,-0.000324526535859735,-7.2239228529493E-6,20.0005341,20.0006104,86498.59375,86518.8046875,57.0541921327368,20.5829071474268,13.038077,0,0,0,40,4449,19.9809,86508.69921875,,,,,,,,,,,,,0,,,,-0.0049,,,,,,20.00057225,,,,
,29092486.915,20.0003815,81870.1015625,-0.000296441988696316,1.25102914576673E-6,1,0.999253354069792,40.0298881530762,1.98408112100734,18.0300008505583,-0.00332636899860019,-0.000639342255340608,0.25,-3.49455214697235E-6,-0.000296923853325588,-5.64076865058819E-6,20.0003815,20.0003815,81864.96875,81875.234375,56.9111541137176,20.5842241888639,13.038077,0,0,0,40,4449,19.9807,81870.1015625,,,,,,,,,,,,,0,,,,-0.00245,,,,,,20.0003815,,,,
,29092582.015,19.999918,77116.30078125,-0.00026842629795295,9.99015331326476E-7,1,0.999253354069792,40.0298881530762,1.98420085168466,18.0300008505583,-0.00300971577655597,-0.000586442838165342,0.25,-3.82667556082318E-6,-0.000268761462412371,-5.79142077888254E-6,19.999918,19.999918,77111.3046875,77121.296875,57.3691884259868,20.5841189459404,13.797379,0,0,0,40,4449,19.9813,77116.30078125,,,,,,,,,,,,,0,,,,0,,,,,,19.999918,,,,
,29092677.36,19.9989014,72348.0625,-0.00024057871619014,1.03015950747967E-6,1,0.999253354069792,40.0298881530762,1.98425627645278,18.0300008505583,-0.00269570065158186,-0.000529968836278914,0.25,-3.81833226293133E-6,-0.000240784379655245,-5.59409774697737E-6,19.9989014,19.9989014,72338.1328125,72357.9921875,57.1683098965445,20.5848655005372,13.417728,0,0,0,40,4449,19.98215,72348.0625,,,,,,,,,,,,,0,,,,0,,,,,,19.9989014,,,,
,29092772.725,19.9984093,67582.36328125,-0.000212116452441665,9.08824475011283E-7,1,0.999253354069792,40.0298881530762,1.98416497854263,18.0300008505583,-0.00237799422838997,-0.00045442802630043,0.25,-2.23119562657963E-6,-0.000212220635053613,-3.80493792227721E-6,19.9984093,19.9984093,67579.7890625,67584.9375,57.4457880208715,20.5836126096166,13.038077,0,0,0,40,4449,19.9838,67582.36328125,,,,,,,,,,,,,0,,,,0,,,,,,19.9984093,,,,
,29092867.165,19.9996624,62862.193359375,-0.000184494981949426,1.05536045183846E-6,1,0.999253354069792,40.0298881530762,1.98418338376017,18.0300008505583,-0.00206644857490346,-0.00040084410389672,0.25,-2.44772747350753E-6,-0.000184504297608672,-3.82059446828255E-6,19.9996624,19.9996624,62857.3671875,62867.01953125,57.0487207331022,20.5820120635725,13.417728,0,0,0,40,4449,19.9849,62862.193359375,,,,,,,,,,,,,0,,,,0,,,,,,19.9996624,,,,
,29092965.485,19.9992266,57948.81640625,-0.000155445228195124,7.28582468761303E-7,1,0.999253354069792,40.0298881530762,1.98410139991401,18.0300008505583,-0.00173973452681039,-0.000340188278221196,0.25,-2.29572836758772E-6,-0.000155380082640688,-3.45160742506613E-6,19.9991074,19.9993458,57938.6171875,57959.015625,57.1729996676599,20.5849805648699,13.417728,0,0,0,40,4449,19.98635,57948.81640625,,,,,,,,,,,,,0,,,,-0.00245,,,,,,19.9992266,,,,
,29093060.59,19.9983902,53193.615234375,-0.000127888636509892,7.40809932420116E-7,1,0.999253354069792,40.0298881530762,1.98432594050251,18.0300008505583,-0.0014311358995341,-0.000278003113848812,0.25,-1.73323566966335E-6,-0.000127777087247446,-2.67994663098884E-6,19.9983902,19.9983902,53186.0859375,53201.14453125,57.1862873524868,20.5836228622215,14.177031,0,0,0,40,4449,19.9879,53193.615234375,,,,,,,,,,,,,0,,,,0,,,,,,19.9983902,,,,
,29093155.065,19.99886225,48470.83203125,-0.000100181379752569,9.26921948778721E-7,1,0.999253354069792,40.0298881530762,1.98428811522979,18.0300008505583,-0.00111940808459257,-0.00022386409339253,0.25,-1.91604763288537E-6,-0.00010004234161554,-2.65044620995089E-6,19.9985275,19.999197,48463.41796875,48478.24609375,57.1620568683907,20.5836028414672,13.417728,0,0,0,40,4449,19.9873,48470.83203125,,,,,,,,,,,,,0,,,,0.00245,,,,,,19.99886225,,,,
,29093250.75,19.9998722,43687.78125,-7.2904344097459E-5,6.00143365199486E-7,1,0.999253354069792,40.0298881530762,1.98425693170874,18.0300008505583,-0.000813580091316694,-0.00016629835022052,0.25,-1.71061658719067E-6,-7.27649544418325E-5,-2.2369395332081E-6,19.9998722,19.9998722,43680.4140625,43695.1484375,57.1175040427945,20.5823213170726,13.797379,0,0,0,40,4449,19.9874,43687.78125,,,,,,,,,,,,,0,,,,0.00245,,,,,,19.9998722,,,,
,29093346.805,19.9990768,38888.275390625,-4.50619938352229E-5,6.43234557428551E-7,1,0.999253354069792,40.0298881530762,1.98425577724902,18.0300008505583,-0.000500997141636349,-0.000111746262450314,0.25,-1.86747764124854E-6,-4.49474567520285E-5,-2.18445518121623E-6,19.9990768,19.9990768,38883.234375,38893.31640625,57.0792042453522,20.5846411046641,13.797379,0,0,0,40,4449,19.9884,38888.275390625,,,,,,,,,,,,,0,,,,-0.0049,,,,,,19.9990768,,,,
,29093444.995,19.9986343,33980.755859375,-1.658442813491E-5,5.94602885083466E-7,1,0.999253354069792,40.0298881530762,1.98419819319259,18.0300008505583,-0.000183898868433951,-4.32516544805377E-5,0.25,-8.81995657302921E-7,-1.65324264305689E-5,-9.94813804041562E-7,19.9986343,19.9986343,33970.6796875,33990.83203125,56.9361662263329,20.5856866278923,13.417728,0,0,0,40,4449,19.98985,33980.755859375,,,,,,,,,,,,,0,,,,0.0049,,,,,,19.9986343,,,,
,29093539.89,19.9989986,29238.689453125,8.86755694505971E-6,4.42790203036657E-7,1,0.999253354069792,40.0298881530762,1.98410093476783,18.0300008505583,0.000100610213415603,1.01151911738497E-5,0.25,-6.88176932113276E-7,8.84324083344933E-6,-6.26187631684278E-7,19.9989986,19.9989986,29238.689453125,29238.689453125,57.3801312252561,20.5888412513352,14.177031,0,0,0,40,4449,19.991,29238.689453125,,,,,,,,,,,,,0,,,,0,,,,,,19.9989986,,,,
,29093636.715,19.9983177,24398.60546875,3.6209772816727E-5,4.86853671787045E-7,1,0.999253354069792,40.0298881530762,1.98412883914285,18.0300008505583,0.00040593769440225,6.74155625408047E-5,0.25,-4.64439885413777E-7,3.60764944305999E-5,-2.28071679131681E-7,19.9983177,19.9983177,24396.119140625,24401.091796875,57.3793495967368,20.5881083107565,13.038077,0,0,0,40,4449,19.99225,24398.60546875,,,,,,,,,,,,,0,,,,0,,,,,,19.9983177,,,,
,29093732.635,19.99767495,19606.3232421875,6.24759071052569E-5,4.04463546170116E-7,1,0.999253354069792,40.0298881530762,1.98405728582828,18.0300008505583,0.000698646168907804,0.000124033371427634,0.25,-8.76650733682767E-8,6.22116031511259E-5,2.99223923632598E-7,19.9975853,19.9977646,19598.435546875,19614.2109375,57.3230723433522,20.5881876332651,13.417728,0,0,0,40,4449,19.9943,19606.3232421875,,,,,,,,,,,,,0,,,,0,,,,,,19.99767495,,,,
,29093827.805,19.9971714,14849.0009765625,8.7712697331848E-5,3.8218648671672E-7,1,0.999253354069792,40.0298881530762,1.98415073766323,18.0300008505583,0.000980285391824014,0.000175065527403856,0.25,-5.4795852135489E-9,8.73018861540346E-5,5.08957895970307E-7,19.9971714,19.9971714,14841.5771484375,14856.4248046875,57.3191642007561,20.5888323701533,13.417728,0,0,0,40,4449,19.9961,14849.0009765625,,,,,,,,,,,,,0,,,,0.0049,,,,,,19.9971714,,,,
,29093921.21,19.9972897,10181.3271484375,0.000111647594193214,3.5408849391517E-7,1,0.999253354069792,40.0298881530762,1.9840983843885,18.0300008505583,0.00124664045675981,0.000226148467675005,0.25,3.35490650091861E-7,0.000111078051046811,9.50999912228063E-7,19.9972897,19.9972897,10173.5908203125,10189.0634765625,57.1917587521214,20.5886354064233,13.797379,0,0,0,40,4449,19.99905,10181.3271484375,,,,,,,,,,,,,0,,,,0,,,,,,19.9972897,,,,
,29094012.7,19.99939915,5606.15844726562,0.000132902877631226,4.23758211124163E-7,1,0.999253354069792,40.0298881530762,1.98410158096794,18.0300008505583,0.00148373943831429,0.000267524313013266,0.25,3.01851447772643E-7,0.000132179436553376,9.90574649650829E-7,19.9993095,19.9994888,5601.06787109375,5611.2490234375,56.8673829166406,20.589409745911,13.417728,0,0,0,40,4449,20.0001,5606.15844726562,,,,,,,,,,,,,0,,,,0.00245,,,,,,19.99939915,,,,
,29094106.675,19.9999294,909.855316162109,0.000125027267011704,3.1886636512594E-7,1,0.999253354069792,40.0298881530762,1.98402424791565,18.0300008505583,0.00139426284227873,0.000257791390236387,0.25,8.77888414044488E-7,0.000124308437410933,1.48384069559015E-6,19.9999294,19.9999294,902.516906738281,917.193725585938,57.058100275333,20.5913354170308,13.417728,0,0,0,40,4449,19.9999,909.855316162109,,,,,,,,,,,,,0,,,,0.00245,,,,,,19.9999294,,,,
,29094200.18,20.0001755,-3758.35815429687,-0.00013533292965464,3.31996297197295E-7,1,0.999253354069792,40.0298881530762,1.98400898294314,18.0300008505583,-0.00150874515770263,-0.000282877983118977,0.25,-1.2659001215086E-6,-0.000134574779875968,-1.94433412855178E-6,20.0001755,20.0001755,-3766.00341796875,-3750.712890625,57.2378748347561,20.5902892838155,13.038077,0,0,0,40,4449,19.99955,-3758.35815429687,,,,,,,,,,,,,0,,,,-0.00245,,,,,,20.0001755,,,,
,29094296.255,19.9999104,-8562.314453125,-0.000117915391874594,3.4693287804235E-7,1,0.999253354069792,40.0298881530762,1.98396577266668,18.0300008505583,-0.00131567028545808,-0.000242730914489372,0.25,-7.2041353652107E-7,-0.000117296765022813,-1.35451804370356E-6,19.9999104,19.9999104,-8569.7626953125,-8554.8662109375,57.5364569291022,20.5906385701929,13.797379,0,0,0,40,4449,20.0018,-8562.314453125,,,,,,,,,,,,,0,,,,-0.0049,,,,,,19.9999104,,,,
,29094390.535,20.0007057,-13275.5297851562,-9.46498546833814E-5,3.4025411495385E-7,1,0.999253354069792,40.0298881530762,1.98421486155779,18.0300008505583,-0.00105672826044629,-0.000194330201588592,0.25,-4.91401563952586E-7,-9.4190487341559E-5,-1.03355171837503E-6,20.0007057,20.0007057,-13283.09375,-13267.9658203125,57.3871658819292,20.5894642452055,13.797379,0,0,0,40,4449,19.99975,-13275.5297851562,,,,,,,,,,,,,0,,,,0,,,,,,20.0007057,,,,
,29094485.94,20.0000896,-18042.845703125,-7.00186099832561E-5,3.51507845929586E-7,1,0.999253354069792,40.0298881530762,1.98406066315479,18.0300008505583,-0.000782143552521214,-0.000143085532500264,0.25,-2.75543460909268E-7,-6.97096420435436E-5,-7.00325386915988E-7,20.0000896,20.0000896,-18045.1796875,-18040.51171875,56.9572701963522,20.5909826191747,13.797379,0,0,0,40,4449,19.9992,-18042.845703125,,,,,,,,,,,,,0,,,,-0.0049,,,,,,20.0000896,,,,
,29094579.66,20.001524,-22728.1142578125,-4.46862798670482E-5,3.57976303520635E-7,1,0.999253354069792,40.0298881530762,1.98422912329139,18.0300008505583,-0.000500183815995214,-8.72070989685994E-5,0.25,2.09358201512842E-7,-4.45119097312136E-5,-7.6629593638561E-8,20.001524,20.001524,-22738.21484375,-22718.013671875,57.444224763833,20.5888866728513,13.797379,0,0,0,40,4449,19.99775,-22728.1142578125,,,,,,,,,,,,,0,,,,0.00245,,,,,,20.001524,,,,
,29094674.68,20.0013962,-27475.46875,-1.91123654866283E-5,4.37879901039058E-7,1,0.999253354069792,40.0298881530762,1.98414785093772,18.0300008505583,-0.000214597532990784,-3.41263654336919E-5,0.25,3.79620537922507E-7,-1.90489841613779E-5,2.51252328774415E-7,20.0013962,20.0013962,-27485.689453125,-27465.248046875,57.6630807492176,20.5895991366903,13.797379,0,0,0,40,4449,19.99575,-27475.46875,,,,,,,,,,,,,0,,,,0,,,,,,20.0013962,,,,
,29094766.05,20.0015926,-32042.96484375,6.11443832814127E-6,5.73787337803852E-7,1,0.999253354069792,40.0298881530762,1.98423580186359,18.0300008505583,6.69362492292851E-5,2.06860756595317E-5,0.25,7.49370087408085E-7,6.09112844027427E-6,7.89136712860935E-7,20.0015926,20.0015926,-32048.07421875,-32037.85546875,57.3699700545061,20.5907116187465,13.417728,0,0,0,40,4449,19.9951,-32042.96484375,,,,,,,,,,,,,0,,,,0,,,,,,20.0015926,,,,
,29094859.64,20.0022392,-36719.6875,3.30639558115062E-5,5.47533545377384E-7,1,0.999253354069792,40.0298881530762,1.9842921787819,18.0300008505583,0.000368692405207209,7.54928479199502E-5,0.25,7.93741684142285E-7,3.29764942759473E-5,1.025015814153E-6,20.0022392,20.0022392,-36724.66015625,-36714.71484375,57.3152560581599,20.5894657631405,13.797379,0,0,0,40,4449,19.9934,-36719.6875,,,,,,,,,,,,,0,,,,-0.0049,,,,,,20.0022392,,,,
,29094955.025,20.0017509,-41484.5234375,5.98227265928075E-5,5.34348076839385E-7,1,0.999253354069792,40.0298881530762,1.98446426080681,18.0300008505583,0.000668674567315336,0.000129959647225861,0.25,8.28552780600216E-7,5.96987577953533E-5,1.25789020482407E-6,20.0017509,20.0017509,-41491.875,-41477.171875,57.2355299491984,20.5869632687832,13.797379,0,0,0,40,4449,19.9921,-41484.5234375,,,,,,,,,,,,,0,,,,0,,,,,,20.0017509,,,,
,29095051.31,20.0015106,-46299.654296875,8.77422138111276E-5,6.09899833317911E-7,1,0.999253354069792,40.0298881530762,1.98443846290551,18.0300008505583,0.000981706159149119,0.00018805203986622,0.25,9.68998020658566E-7,8.76061238784156E-5,1.60952066351987E-6,20.0015106,20.0015106,-46304.51171875,-46294.796875,57.0526288756983,20.5869672962906,13.797379,0,0,0,40,4449,19.9901,-46299.654296875,,,,,,,,,,,,,0,,,,0,,,,,,20.0015106,,,,
,29095145.505,20.0011787,-51006.822265625,0.000113934388748541,5.60041969638941E-7,1,0.999253354069792,40.0298881530762,1.98427950242945,18.0300008505583,0.00127497716137328,0.000245928695064677,0.25,1.39665660578792E-6,0.000113811262420312,2.2372554621454E-6,20.0011787,20.0011787,-51016.86328125,-50996.78125,57.2417829773522,20.5890884843245,13.797379,0,0,0,40,4449,19.98995,-51006.822265625,,,,,,,,,,,,,0,,,,0,,,,,,20.0011787,,,,
,29095241.215,20.0009136,-55791.33984375,0.000142842321706746,1.38161052199488E-6,1,0.999253354069792,40.0298881530762,1.98426150025805,18.0300008505583,0.00159709197262511,0.000320237483123219,0.25,2.79431262895741E-6,0.000142747722896277,3.85443812320878E-6,20.0009136,20.0009136,-55803.7890625,-55778.890625,57.2839909173907,20.5896036609088,13.797379,0,0,0,40,4449,19.9894,-55791.33984375,,,,,,,,,,,,,0,,,,-0.00245,,,,,,20.0009136,,,,
,29095335.475,20.0011349,-60498.595703125,0.000169168675192221,8.6509037611335E-7,1,0.999253354069792,40.0298881530762,1.9840753038819,18.0300008505583,0.00189327061121815,0.000373011838309884,0.25,2.73928013018392E-6,0.000169136667124163,3.99827432476732E-6,20.0011349,20.0011349,-60506.109375,-60491.08203125,57.0213637349291,20.5918534631914,13.797379,0,0,0,40,4449,19.98875,-60498.595703125,,,,,,,,,,,,,0,,,,0,,,,,,20.0011349,,,,
,29095433.325,20.000639,-65388.49609375,0.00019802315075987,8.68970303676695E-7,1,0.999253354069792,40.0298881530762,1.98410320334586,18.0300008505583,0.0022165734139763,0.000440399173114843,0.25,3.52753255008102E-6,0.000198071513859493,4.99980181546327E-6,20.000639,20.000639,-65398.5,-65378.4921875,57.014329078256,20.5928819896448,13.797379,0,0,0,40,4449,19.9884,-65388.49609375,,,,,,,,,,,,,0,,,,-0.00245,,,,,,20.000639,,,,
,29095531.555,20.0014267,-70300.1484375,0.000227685195719728,8.48369967049703E-7,1,0.999253354069792,40.0298881530762,1.98418545380167,18.0300008505583,0.00255049699433264,0.000502624596507933,0.25,3.711592343676E-6,0.000227840248035703,5.39683919447298E-6,20.0014267,20.0014267,-70304.96875,-70295.328125,57.2027015513907,20.5926165680945,13.797379,0,0,0,40,4449,19.9862,-70300.1484375,,,,,,,,,,,,,0,,,,0.00245,,,,,,20.0014267,,,,
,29095627.01,20.0005474,-75069.78515625,0.000255105595335735,8.73583441315741E-7,1,0.999253354069792,40.0298881530762,1.98424409415563,18.0300008505583,0.00285813544685594,0.000567379454826484,0.25,4.52889986691846E-6,0.000255376464312209,6.40431885004463E-6,20.0004368,20.000658,-75072.28125,-75067.2890625,57.3887291389676,20.5946959624521,13.417728,0,0,0,40,4449,19.9853,-75069.78515625,,,,,,,,,,,,,0,,,,-0.0049,,,,,,20.0005474,,,,
,29095723.67,20.00189495,-79901.73046875,0.000284174017167908,9.05946899512918E-7,1,0.999253354069792,40.0298881530762,1.98424766024436,18.0300008505583,0.00318733382398587,0.000619332707198239,0.25,3.91682671763018E-6,0.000284590348467079,5.98455744099438E-6,20.0017776,20.0020123,-79909.34375,-79894.1171875,57.6325972369676,20.5919655764312,13.417728,0,0,0,40,4449,19.9832,-79901.73046875,,,,,,,,,,,,,0,,,,0.00245,,,,,,20.00189495,,,,
,29095818.695,20.0019341,-84651.52734375,0.0003114110666952,7.96187977326596E-7,1,0.999253354069792,40.0298881530762,1.98418265668229,18.0300008505583,0.00349264161163875,0.000686032415540676,0.25,4.95389904015118E-6,0.000311970359664069,7.19517827967714E-6,20.0019341,20.0019341,-84656.5234375,-84646.53125,57.3191642007561,20.593566238498,13.797379,0,0,0,40,4449,19.9822,-84651.52734375,,,,,,,,,,,,,0,,,,0.0049,,,,,,20.0019341,,,,
,29095909.165,20.0014324,-89171.203125,0.000338596094101817,8.81087151612767E-7,1,0.999253354069792,40.0298881530762,1.98428877531286,18.0300008505583,0.00380208576564475,0.000728493088828265,0.25,3.84610955027816E-6,0.00033932009258647,6.24952338952356E-6,20.0014324,20.0014324,-89178.890625,-89163.515625,57.3316702570638,20.5924829248605,14.177031,0,0,0,40,4449,19.9804,-89171.203125,,,,,,,,,,,,,0,,,,0.00245,,,,,,20.0014324,,,,
,29096015.5,20.0010567,-86472.40234375,0.000322984217396164,8.57082280529406E-7,1,0.999253354069792,40.0298881530762,1.9841610256323,18.0300008505583,0.00362536173781735,0.000697715615409839,0.25,3.91493030490524E-6,0.000323614092376293,6.22580236990852E-6,20.0010567,20.0010567,-86485.234375,-86459.5703125,57.3676251689484,20.5933523061227,14.177031,0,0,0,40,4449,19.9809,-86472.40234375,,,,,,,,,,,,,0,,,,0,,,,,,20.0010567,,,,
,29096109.69,19.9991703,-81765.109375,0.000295267056225829,8.17886919288648E-7,1,0.999253354069792,40.0298881530762,1.98423585481326,18.0300008505583,0.00331591048308026,0.000622940818017872,0.25,2.24318997026703E-6,0.000295753677792715,4.37933282103985E-6,19.9991703,19.9991703,-81767.6875,-81762.53125,57.1729996676599,20.5931526811518,13.417728,0,0,0,40,4449,19.9807,-81765.109375,,,,,,,,,,,,,0,,,,0,,,,,,19.9991703,,,,
,29096206.555,19.9993649,-76922.578125,0.000267035823934891,1.00177836509633E-6,1,0.999253354069792,40.0298881530762,1.98436982512613,18.0300008505583,0.00299377777397786,0.000586474794227843,0.25,4.07565150023303E-6,0.000267363260058079,6.03131696269033E-6,19.9993649,19.9993649,-76925.1015625,-76920.0546875,57.075296102756,20.5934366058428,13.417728,0,0,0,40,4449,19.9812,-76922.578125,,,,,,,,,,,,,0,,,,-0.00245,,,,,,19.9993649,,,,
,29096302.165,19.9987602,-72145.12890625,0.000238777311410208,9.40495983466726E-7,1,0.999253354069792,40.0298881530762,1.98447325804372,18.0300008505583,0.00267805514904737,0.000513255390813467,0.25,2.65093620737088E-6,0.000238985830769107,4.4128297993694E-6,19.9987602,19.9987602,-72152.3828125,-72137.875,57.3433946848522,20.5903952743096,14.177031,0,0,0,40,4449,19.98305,-72145.12890625,,,,,,,,,,,,,0,,,,-0.00245,,,,,,19.9987602,,,,
,29096398.25,19.9976311,-67343.89453125,0.000209592125044793,7.69753389171598E-7,1,0.999253354069792,40.0298881530762,1.98465326571745,18.0300008505583,0.00234942226728326,0.00045342182221325,0.25,2.58746786568879E-6,0.000209687885111864,4.14303178343313E-6,19.9976311,19.9976311,-67356.328125,-67331.4609375,57.3136928011214,20.5849688937388,13.417728,0,0,0,40,4449,19.9847,-67343.89453125,,,,,,,,,,,,,0,,,,-0.0049,,,,,,19.9976311,,,,
,29096494.275,19.9975471,-62544.091796875,0.000182054487157684,7.26122977850105E-7,1,0.999253354069792,40.0298881530762,1.98463317667431,18.0300008505583,0.00203771600348006,0.0004054912752922,0.25,3.29455317790513E-6,0.000182051853689014,4.64946245443258E-6,19.9975471,19.9975471,-62554.12890625,-62534.0546875,57.6802765766407,20.5888372896637,14.177031,0,0,0,40,4449,19.98625,-62544.091796875,,,,,,,,,,,,,0,,,,0,,,,,,19.9975471,,,,
,29096588.565,19.9974384,-57831.19921875,0.000154686961393871,6.37791008757475E-7,1,0.999253354069792,40.0298881530762,1.98458406342957,18.0300008505583,0.00173073802209057,0.000343557515514862,0.25,2.72591393354529E-6,0.000154617118512236,3.8759376422794E-6,19.9972076,19.9976692,-57866.3203125,-57796.078125,57.2902439455445,20.5866089422992,13.797379,0,0,0,40,4449,19.9884,-57831.19921875,,,,,,,,,,,,,0,,,,-0.00245,,,,,,19.9974384,,,,
,29096685.295,19.9982109,-52996.546875,0.000126032698218897,8.35719687555521E-7,1,0.999253354069792,40.0298881530762,1.98463569464959,18.0300008505583,0.00140951713105556,0.000279734185405428,0.25,2.21901487337558E-6,0.000125916524784587,3.15132338692705E-6,19.9982109,19.9982109,-53009.36328125,-52983.73046875,57.3465211989291,20.5888154968036,13.038077,0,0,0,40,4449,19.9899,-52996.546875,,,,,,,,,,,,,0,,,,0,,,,,,19.9982109,,,,
,29096780.385,19.999094,-48242.255859375,9.79663421542068E-5,9.41492236114814E-7,1,0.999253354069792,40.0298881530762,1.98464490330574,18.0300008505583,0.00109544874313447,0.00021545793690622,0.25,1.56290549825554E-6,9.78303842796425E-5,2.28105741187422E-6,19.999094,19.999094,-48252.16796875,-48232.34375,56.9111541137176,20.5862543477018,13.797379,0,0,0,40,4449,19.9899,-48242.255859375,,,,,,,,,,,,,0,,,,0.00245,,,,,,19.999094,,,,
,29096877.19,19.9991283,-43404.98046875,7.1044336187306E-5,5.87418833120985E-7,1,0.999253354069792,40.0298881530762,1.98461521948375,18.0300008505583,0.000792769159353528,0.000163008723662029,0.25,1.75040738042178E-6,7.09058122400162E-5,2.26262681278279E-6,19.9991283,19.9991283,-43410.18359375,-43399.77734375,57.2707032325638,20.5834440250405,14.177031,0,0,0,40,4449,19.9899,-43404.98046875,,,,,,,,,,,,,0,,,,0,,,,,,19.9991283,,,,
,29096971.875,19.9996243,-38674.982421875,4.35436312950766E-5,5.36356526806043E-7,1,0.999253354069792,40.0298881530762,1.9847467233337,18.0300008505583,0.000487142403752632,9.17607388048585E-5,0.25,3.55049388681212E-7,4.34423065726025E-5,6.64297650334741E-7,19.9996243,19.9996243,-38682.2578125,-38667.70703125,57.3473028274484,20.5827462084604,13.797379,0,0,0,40,4449,19.99095,-38674.982421875,,,,,,,,,,,,,0,,,,0.00245,,,,,,19.9996243,,,,
,29097067.445,19.9988747,-33897.60546875,1.61661492933378E-5,6.22681924104272E-7,1,0.999253354069792,40.0298881530762,1.98470996822519,18.0300008505583,0.000179551781086384,4.07887343310537E-5,0.25,7.36385682994976E-7,1.6116177321886E-5,8.46638769099127E-7,19.9988747,19.9988747,-33910.18359375,-33885.02734375,57.3058765159291,20.5820253133298,13.797379,0,0,0,40,4449,19.99195,-33897.60546875,,,,,,,,,,,,,0,,,,0.00245,,,,,,19.9988747,,,,
,29097162.835,19.9988136,-29130.8388671875,-1.00184904255887E-5,5.68795744091326E-7,1,0.999253354069792,40.0298881530762,1.98462275414119,18.0300008505583,-0.000113127862093363,-1.4594034057687E-5,0.25,4.948263288274E-7,-9.98899891168694E-6,4.25761607210208E-7,19.9987659,19.9988613,-29133.158203125,-29128.51953125,56.9861904515637,20.5821730755459,13.417728,0,0,0,40,4449,19.9935,-29130.8388671875,,,,,,,,,,,,,0,,,,0,,,,,,19.9988136,,,,
,29097259.29,19.9979954,-24308.0439453125,-3.73774189061618E-5,4.91658091870889E-7,1,0.999253354069792,40.0298881530762,1.98465513368861,18.0300008505583,-0.000418303047325166,-7.42199565907058E-5,0.25,6.68557479941254E-8,-3.7236827753162E-5,-1.75388951238455E-7,19.9979954,19.9979954,-24315.578125,-24300.509765625,56.8470605751406,20.5819213039041,13.797379,0,0,0,40,4449,19.9947,-24308.0439453125,,,,,,,,,,,,,0,,,,-0.00245,,,,,,19.9979954,,,,
,29097355.915,19.9987106,-19481.4912109375,-6.30536587186034E-5,4.0641474988943E-7,1,0.999253354069792,40.0298881530762,1.98454426780959,18.0300008505583,-0.000704732040910599,-0.000128178943610648,0.25,-1.77692403967192E-7,-6.2784507309214E-5,-5.66520724158075E-7,19.9987106,19.9987106,-19484.123046875,-19478.859375,57.2097362080637,20.5836379551799,14.177031,0,0,0,40,4449,19.9964,-19481.4912109375,,,,,,,,,,,,,0,,,,-0.0049,,,,,,19.9987106,,,,
,29097450.96,19.997858,-14731.4423828125,-8.88916429145718E-5,3.52301768307671E-7,1,0.999253354069792,40.0298881530762,1.9845264036649,18.0300008505583,-0.000992765721239848,-0.000182289630307385,0.25,-4.28251760715378E-7,-8.84718324771073E-5,-9.46833921793588E-7,19.997858,19.997858,-14741.4814453125,-14721.4033203125,57.2542890336599,20.5833316551101,13.417728,0,0,0,40,4449,19.9978,-14731.4423828125,,,,,,,,,,,,,0,,,,-0.00245,,,,,,19.997858,,,,
,29097546.27,19.9986343,-9969.01416015625,-0.000112757510066711,4.26520047979338E-7,1,0.999253354069792,40.0298881530762,1.9844889687618,18.0300008505583,-0.00125826385769165,-0.000233958546375518,0.25,-8.34852246835059E-7,-0.000112177634458003,-1.45218868595204E-6,19.9986343,19.9986343,-9979.0546875,-9958.9736328125,57.220679007333,20.583713650597,13.797379,0,0,0,40,4449,19.99905,-9969.01416015625,,,,,,,,,,,,,0,,,,0,,,,,,19.9986343,,,,
,29097641.485,19.9992371,-5210.8896484375,-0.000133656348909771,3.3038366546727E-7,1,0.999253354069792,40.0298881530762,1.98447598919264,18.0300008505583,-0.00149142759864456,-0.000274429860516865,0.25,-7.86076100812534E-7,-0.000132922672880136,-1.47229644126038E-6,19.9992371,19.9992371,-5215.97265625,-5205.806640625,57.1589303543137,20.583900343442,13.797379,0,0,0,40,4449,20,-5210.8896484375,,,,,,,,,,,,,0,,,,-0.0049,,,,,,19.9992371,,,,
,29097735.905,20.0005074,-488.996124267578,-0.000109023473090589,3.45549474148308E-7,1,0.999253354069792,40.0298881530762,1.98443066676715,18.0300008505583,-0.00121533802232488,-0.00022861143216488,0.25,-1.10616439435515E-6,-0.000108392993770607,-1.63025565788393E-6,20.0005074,20.0005074,-491.582489013672,-486.409759521484,57.1112510146407,20.5831766685774,13.797379,0,0,0,40,4449,19.9996,-488.996124267578,,,,,,,,,,,,,0,,,,0.00245,,,,,,20.0005074,,,,
,29097828.95,19.9988852,4156.82958984375,0.000135604588037406,2.87197525067073E-7,1,0.999253354069792,40.0298881530762,1.98460382265401,18.0300008505583,0.00151338584197548,0.000277121893507657,0.25,6.90675874438022E-7,0.000134851290702471,1.37741246326858E-6,19.9985867,19.9991837,4151.7958984375,4161.86328125,57.2066096939868,20.58229376422,13.797379,0,0,0,40,4449,20.00065,4156.82958984375,,,,,,,,,,,,,0,,,,0,,,,,,19.9988852,,,,
,29097918.77,19.9997578,8647.95751953125,0.000118098434305729,3.25986464424304E-7,1,0.999253354069792,40.0298881530762,1.98450796056922,18.0300008505583,0.00131941903714322,0.000235576261515925,0.25,4.08825550686478E-8,0.000117483314394644,6.80261610400607E-7,19.9997578,19.9997578,8645.6015625,8650.3134765625,57.0205821064099,20.5834507426446,13.417728,0,0,0,40,4449,20.00145,8647.95751953125,,,,,,,,,,,,,0,,,,0,,,,,,19.9997578,,,,
,29098011.65,20.000782,13290.947265625,9.53589924175888E-5,3.97005600726232E-7,1,0.999253354069792,40.0298881530762,1.98438946682049,18.0300008505583,0.00106634126094806,0.000186814290941473,0.25,-3.09307269800571E-7,9.49009422516107E-5,2.40891744458554E-7,20.000782,20.000782,13283.4267578125,13298.4677734375,57.4536043060638,20.584101372061,13.038077,0,0,0,40,4449,20.0011,13290.947265625,,,,,,,,,,,,,0,,,,0,,,,,,20.000782,,,,
,29098106.985,20.0003242,18056.2919921875,7.09770441940897E-5,3.59102894190576E-7,1,0.999253354069792,40.0298881530762,1.98452015511177,18.0300008505583,0.000793975443553781,0.000139769527923456,0.25,-1.95387290480019E-7,7.06668258545243E-5,2.37356135845002E-7,20.0003242,20.0003242,18046.31640625,18066.267578125,57.1010898438907,20.5803351298778,13.797379,0,0,0,40,4449,19.9994,18056.2919921875,,,,,,,,,,,,,0,,,,0.00245,,,,,,20.0003242,,,,
,29098202.155,20.0010338,22811.2294921875,4.56866612689718E-5,4.57260134007142E-7,1,0.999253354069792,40.0298881530762,1.9843562480981,18.0300008505583,0.000512334957706005,8.40421984048527E-5,0.25,-6.7234668776863E-7,4.55116959128901E-5,-3.77932118038721E-7,20.0010338,20.0010338,22798.748046875,22823.7109375,57.1956668947176,20.5846215282143,13.797379,0,0,0,40,4449,19.99835,22811.2294921875,,,,,,,,,,,,,0,,,,0.00245,,,,,,20.0010338,,,,
,29098296.47,20.0014763,27526.7353515625,1.99473597894693E-5,4.67893024310762E-7,1,0.999253354069792,40.0298881530762,1.98464095525079,18.0300008505583,0.000225388255255679,2.80427581286932E-5,0.25,-1.07387151240652E-6,1.98858232988693E-5,-9.3751069950204E-7,20.0014763,20.0014763,27516.6640625,27536.806640625,57.047939104583,20.5778548206333,14.177031,0,0,0,40,4449,19.99575,27526.7353515625,,,,,,,,,,,,,0,,,,-0.0049,,,,,,20.0014763,,,,
,29098391.985,20.001915,32299.171875,-6.8716876128908E-6,5.91457479170806E-7,1,0.999253354069792,40.0298881530762,1.9844985532996,18.0300008505583,-7.40475649749283E-5,-2.98736559756538E-5,0.25,-1.43360369321454E-6,-6.84159860389322E-6,-1.47665425183562E-6,20.001915,20.001915,32294.166015625,32304.177734375,57.0768593597945,20.5814939300257,13.797379,0,0,0,40,4449,19.99485,32299.171875,,,,,,,,,,,,,0,,,,0.0049,,,,,,20.001915,,,,
,29098486.71,20.0007725,37034.115234375,-3.3111022128427E-5,6.05960028567207E-7,1,0.999253354069792,40.0298881530762,1.98440390812739,18.0300008505583,-0.000368066774393226,-8.21811985602485E-5,0.25,-1.38149140573621E-6,-3.30203854891817E-5,-1.61205681067668E-6,20.0007725,20.0007725,37031.5625,37036.66796875,57.4051433378714,20.5824410310264,13.797379,0,0,0,40,4449,19.99325,37034.115234375,,,,,,,,,,,,,0,,,,0.0049,,,,,,20.0007725,,,,
,29098581.795,20.0011101,41786.8125,-6.08061125815387E-5,5.05062329604148E-7,1,0.999253354069792,40.0298881530762,1.9844947991093,18.0300008505583,-0.000676478935102908,-0.000149983376141136,0.25,-2.43736873501101E-6,-6.06705260321527E-5,-2.87119217896242E-6,20.0011101,20.0011101,41784.3046875,41789.3203125,57.0799858738714,20.5809702996839,13.797379,0,0,0,40,4449,19.9916,41786.8125,,,,,,,,,,,,,0,,,,0,,,,,,20.0011101,,,,
,29098678.735,20.0012245,46634.578125,-8.82941385665301E-5,7.24540577540923E-7,1,0.999253354069792,40.0298881530762,1.98453419647198,18.0300008505583,-0.000984808093662767,-0.000206753436311521,0.25,-2.53570486223222E-6,-8.81488108508806E-5,-3.17861381857958E-6,20.0012245,20.0012245,46631.9296875,46637.2265625,57.2441278629099,20.5806902466722,13.797379,0,0,0,40,4449,19.9902,46634.578125,,,,,,,,,,,,,0,,,,0.0049,,,,,,20.0012245,,,,
,29098771.675,20.0010624,51277.298828125,-0.000115497539161112,9.65561416696654E-7,1,0.999253354069792,40.0298881530762,1.98459661989688,18.0300008505583,-0.00129193730531544,-0.00025359095277691,0.25,-1.79375643430686E-6,-0.000115373064946621,-2.64593485196916E-6,20.0010624,20.0010624,51269.734375,51284.86328125,57.0518472471791,20.579272792473,13.797379,0,0,0,40,4449,19.9905,51277.298828125,,,,,,,,,,,,,0,,,,-0.0049,,,,,,20.0010624,,,,
,29098867.42,20.0006046,56064.876953125,-0.000143062075827519,9.32874440216569E-7,1,0.999253354069792,40.0298881530762,1.98449131260165,18.0300008505583,-0.00160152017081267,-0.000311055370643616,0.25,-1.93237975303435E-6,-0.000142977562788981,-2.99484116063054E-6,20.0006046,20.0006046,56057.5859375,56072.16796875,57.0604451608906,20.5781368350994,13.417728,0,0,0,40,4449,19.9891,56064.876953125,,,,,,,,,,,,,0,,,,-0.0049,,,,,,20.0006046,,,,
,29098963.67,20.00085735,60874.8828125,-0.000171330594402974,6.24388911393934E-7,1,0.999253354069792,40.0298881530762,1.9843013562999,18.0300008505583,-0.00191454948656095,-0.000395543644415148,0.25,-4.35200421174865E-6,-0.00017129243479382,-5.62709231489858E-6,20.0007534,20.0009613,60869.79296875,60879.97265625,57.1339182416984,20.5818892562355,13.797379,0,0,0,40,4449,19.9886,60874.8828125,,,,,,,,,,,,,0,,,,0,,,,,,20.00085735,,,,
,29099060.05,20.0015965,65690.73046875,-0.000198868162275659,9.12644571226162E-7,1,0.999253354069792,40.0298881530762,1.98425148413481,18.0300008505583,-0.00222631087977553,-0.000441987633438634,0.25,-3.51321391916054E-6,-0.000198922284130198,-4.99149697118366E-6,20.0015965,20.0015965,65683.2265625,65698.234375,56.9564885678329,20.5819318052156,13.797379,0,0,0,40,4449,19.9876,65690.73046875,,,,,,,,,,,,,0,,,,-0.00245,,,,,,20.0015965,,,,
,29099155.035,20.0013218,70440.74609375,-0.000226144859505379,1.17002331264103E-6,1,0.999253354069792,40.0298881530762,1.98436942759159,18.0300008505583,-0.00253060277356317,-0.000515335092298811,0.25,-5.11623149098951E-6,-0.000226290981542152,-6.79095501398462E-6,20.0013218,20.0013218,70430.6640625,70450.828125,57.0674798175637,20.579868051597,13.797379,0,0,0,40,4449,19.98665,70440.74609375,,,,,,,,,,,,,0,,,,0.00245,,,,,,20.0013218,,,,
,29099249.905,20.001421,75180.83984375,-0.000254846718713505,9.85674042406807E-7,1,0.999253354069792,40.0298881530762,1.9844010125258,18.0300008505583,-0.00285395288001428,-0.000575307211363146,0.25,-5.27696258428E-6,-0.000255114051830492,-7.15102420828259E-6,20.001421,20.001421,75178.296875,75183.3828125,57.1135959001984,20.580123078455,14.177031,0,0,0,40,4449,19.9846,75180.83984375,,,,,,,,,,,,,0,,,,0,,,,,,20.001421,,,,
,29099346.46,20.0014629,80006.78515625,-0.000283215768930204,9.26428148595173E-7,1,0.999253354069792,40.0298881530762,1.98433280140043,18.0300008505583,-0.00317537022882484,-0.000624888868634252,0.25,-4.58131039293424E-6,-0.000283628014494776,-6.642653024915E-6,20.0014629,20.0014629,79996.6484375,80016.921875,57.1128142716791,20.5787944599282,13.417728,0,0,0,40,4449,19.98265,80006.78515625,,,,,,,,,,,,,0,,,,-0.00245,,,,,,20.0014629,,,,
,29099440.6,20.00216105,84715.296875,-0.000311364488329082,9.7898055676603E-7,1,0.999253354069792,40.0298881530762,1.98431652092284,18.0300008505583,-0.00349129025000027,-0.000691921321101859,0.25,-5.48200577865758E-6,-0.000311921309534145,-7.72359254240606E-6,20.0019455,20.0023766,84710.1328125,84720.4609375,57.2808644033138,20.580871822595,13.797379,0,0,0,40,4449,19.9814,84715.296875,,,,,,,,,,,,,0,,,,0,,,,,,20.00216105,,,,
,29099528.145,20.0025654,89088.51953125,-0.000336364192630428,7.24232524255197E-7,1,0.999253354069792,40.0298881530762,1.98427578879689,18.0300008505583,-0.0037734046624015,-0.000743558829933463,0.25,-5.58662845979673E-6,-0.000337069073827455,-7.97869054177757E-6,20.0025654,20.0025654,89083.2890625,89093.75,57.0604451608906,20.580530292142,13.797379,0,0,0,40,4449,19.97955,89088.51953125,,,,,,,,,,,,,0,,,,0.00245,,,,,,20.0025654,,,,
,29099635.29,20.0004711,86565.62109375,-0.000321882336078892,1.01295008704746E-6,1,0.999253354069792,40.0298881530762,1.98423557964692,18.0300008505583,-0.00360899810880791,-0.000718421901381487,0.25,-5.95180775145474E-6,-0.000322497513473913,-8.25839205762153E-6,20.0004711,20.0004711,86553.125,86578.1171875,57.0635716749676,20.582451730787,13.797379,0,0,0,40,4449,19.9797,86565.62109375,,,,,,,,,,,,,0,,,,-0.00245,,,,,,20.0004711,,,,
,29099727.82,19.9998569,81940.578125,-0.000294318394482271,7.81742965031269E-7,1,0.999253354069792,40.0298881530762,1.98420692958843,18.0300008505583,-0.00330170726958553,-0.000640636721023121,0.25,-3.98857946204706E-6,-0.000294794578081482,-6.11994974822532E-6,19.9998569,19.9998569,81935.6953125,81945.4609375,56.9447641400445,20.5816390839893,13.797379,0,0,0,40,4449,19.98005,81940.578125,,,,,,,,,,,,,0,,,,-0.0049,,,,,,19.9998569,,,,
,29099822.735,19.9986572,77196.3671875,-0.000266100849453686,9.06705971594395E-7,1,0.999253354069792,40.0298881530762,1.98415866268737,18.0300008505583,-0.00298192054255537,-0.000590678271105028,0.25,-4.62332991537887E-6,-0.000266428711793985,-6.57187565146885E-6,19.9986572,19.9986572,77191.6015625,77201.1328125,57.3050948874099,20.5812762927304,13.797379,0,0,0,40,4449,19.98135,77196.3671875,,,,,,,,,,,,,0,,,,0,,,,,,19.9986572,,,,
,29099917.77,19.9986057,72445.19921875,-0.000237547986018219,1.0145690285307E-6,1,0.999253354069792,40.0298881530762,1.98425614439961,18.0300008505583,-0.00265961134260587,-0.000535234985524968,0.25,-4.83290995469533E-6,-0.000237745132384105,-6.5870992636265E-6,19.9986057,19.9986057,72442.671875,72447.7265625,57.2097362080637,20.5828188818998,13.797379,0,0,0,40,4449,19.982,72445.19921875,,,,,,,,,,,,,0,,,,-0.0049,,,,,,19.9986057,,,,
,29100012.15,19.9982929,67724.9375,-0.000211029035125395,7.20554906760641E-7,1,0.999253354069792,40.0298881530762,1.98437288532789,18.0300008505583,-0.00236656548638864,-0.000449396881774598,0.25,-1.97499801243666E-6,-0.000211137110518278,-3.54031971127447E-6,19.9982929,19.9982929,67714.828125,67735.046875,57.1151591572368,20.5792037032677,13.797379,0,0,0,40,4449,19.98465,67724.9375,,,,,,,,,,,,,0,,,,-0.0049,,,,,,19.9982929,,,,
,29100106.915,19.9981499,62989.40234375,-0.000183174943669742,7.54915019926588E-7,1,0.999253354069792,40.0298881530762,1.98422971749819,18.0300008505583,-0.00204870828844154,-0.000414770342896622,0.25,-3.92487351619845E-6,-0.000183175198287694,-5.2881134682284E-6,19.9981499,19.9981499,62981.7578125,62997.046875,56.9236601700253,20.5814232474264,13.417728,0,0,0,40,4449,19.98475,62989.40234375,,,,,,,,,,,,,0,,,,0.0049,,,,,,19.9981499,,,,
,29100203,19.9986153,58186.453125,-0.000155054475726921,9.50350987394573E-7,1,0.999253354069792,40.0298881530762,1.98421239484582,18.0300008505583,-0.00173442760758833,-0.000345271223129537,0.25,-2.81670560457383E-6,-0.000154989085707328,-3.969673227993E-6,19.9986153,19.9986153,58184.1484375,58188.7578125,57.1792526958137,20.5813739138895,14.177031,0,0,0,40,4449,19.9869,58186.453125,,,,,,,,,,,,,0,,,,0,,,,,,19.9986153,,,,
,29100298.33,19.9989624,53423.330078125,-0.000126781418838362,7.18694939989592E-7,1,0.999253354069792,40.0298881530762,1.9844869541366,18.0300008505583,-0.00141683611197078,-0.000287007897908874,0.25,-2.73270221494886E-6,-0.000126666192109736,-3.6707527098522E-6,19.9989624,19.9989624,53410.98828125,53435.671875,56.9979148793522,20.5816399036647,13.797379,0,0,0,40,4449,19.9878,53423.330078125,,,,,,,,,,,,,0,,,,-0.0049,,,,,,19.9989624,,,,
,29100395.315,19.9991417,48575.90234375,-9.97323031204674E-5,9.25052614029452E-7,1,0.999253354069792,40.0298881530762,1.98448324196465,18.0300008505583,-0.00111384296257528,-0.000226568568909647,0.25,-2.23588701731709E-6,-9.95925404100491E-5,-2.96677422889281E-6,19.9991417,19.9991417,48568.30859375,48583.49609375,57.0010413934291,20.5797095808477,13.797379,0,0,0,40,4449,19.9884,48575.90234375,,,,,,,,,,,,,0,,,,0,,,,,,19.9991417,,,,
,29100489.47,20.0000114,43870.58984375,-7.21707568475039E-5,6.37695866627254E-7,1,0.999253354069792,40.0298881530762,1.98445343286032,18.0300008505583,-0.000805859380423242,-0.000162565434427398,0.25,-1.50767824639349E-6,-7.20354898509387E-5,-2.02936705028103E-6,20.0000114,20.0000114,43865.84765625,43875.33203125,57.119067299833,20.5806779560256,13.797379,0,0,0,40,4449,19.9881,43870.58984375,,,,,,,,,,,,,0,,,,0.00245,,,,,,20.0000114,,,,
,29100583.12,19.9993629,39187.787109375,-4.61180326552491E-5,7.14402816868705E-7,1,0.999253354069792,40.0298881530762,1.98452977510548,18.0300008505583,-0.000514411075877759,-0.000105552500799163,0.25,-1.12254340719673E-6,-4.60078828531284E-5,-1.44919298955778E-6,19.9993629,19.9993629,39177.85546875,39197.71875,57.0065127930637,20.5788522225134,13.417728,0,0,0,40,4449,19.9893,39187.787109375,,,,,,,,,,,,,0,,,,0.00245,,,,,,19.9993629,,,,
,29100680.04,19.9992485,34343.31640625,-1.85555010199897E-5,7.33578486319473E-7,1,0.999253354069792,40.0298881530762,1.98442735386859,18.0300008505583,-0.000205817436786405,-4.82237858764629E-5,0.25,-9.70877954988564E-7,-1.84981274839359E-5,-1.09745683315106E-6,19.9992485,19.9992485,34335.8984375,34350.734375,56.9134989992753,20.5836464291617,14.177031,0,0,0,40,4449,19.99035,34343.31640625,,,,,,,,,,,,,0,,,,0.00245,,,,,,19.9992485,,,,
,29100775.09,19.9990864,29593.265625,8.09548130514502E-6,3.89633284385455E-7,1,0.999253354069792,40.0298881530762,1.98437044869416,18.0300008505583,9.31556506574161E-5,2.05279214271928E-6,0.25,-1.27023018539494E-6,8.07792939638172E-6,-1.21144925651193E-6,19.9990864,19.9990864,29583.0703125,29603.4609375,57.0831123879483,20.5827762484804,13.797379,0,0,0,40,4449,19.99125,29593.265625,,,,,,,,,,,,,0,,,,-0.0049,,,,,,19.9990864,,,,
,29100870.015,19.999052,24850.759765625,3.44650680605582E-5,5.20480480331755E-7,1,0.999253354069792,40.0298881530762,1.98428036830715,18.0300008505583,0.000386416152167844,6.42214677361358E-5,0.25,-4.38782972689796E-7,3.43397852632978E-5,-2.12948144676041E-7,19.999052,19.999052,24845.998046875,24855.521484375,57.5184794731599,20.5854352161248,13.417728,0,0,0,40,4449,19.9931,24850.759765625,,,,,,,,,,,,,0,,,,0,,,,,,19.999052,,,,
,29100964.425,19.9988575,20130.3740234375,6.0291568413614E-5,4.05099206321773E-7,1,0.999253354069792,40.0298881530762,1.98441546686234,18.0300008505583,0.000674649983578674,0.000118161402645529,0.25,-2.26322854605583E-7,6.00404533776863E-5,1.49660303585189E-7,19.9988575,19.9988575,20123.076171875,20137.671875,56.8798889729483,20.5836723766238,13.417728,0,0,0,40,4449,19.9944,20130.3740234375,,,,,,,,,,,,,0,,,,0.00245,,,,,,19.9988575,,,,
,29101059.705,19.9982281,15368.5161132812,8.54762448215046E-5,3.99677451946552E-7,1,0.999253354069792,40.0298881530762,1.98425269425932,18.0300008505583,0.000955422725034388,0.000170394609373199,0.25,-2.84521657339145E-8,8.50800590081827E-5,4.76087185121388E-7,19.9982281,19.9982281,15366.0048828125,15371.02734375,57.5137897020446,20.5850698121014,13.797379,0,0,0,40,4449,19.9956,15368.5161132812,,,,,,,,,,,,,0,,,,-0.0049,,,,,,19.9982281,,,,
,29101155.295,19.9980183,10591.1884765625,0.000110101084424827,3.77799104768534E-7,1,0.999253354069792,40.0298881530762,1.98436139031289,18.0300008505583,0.00122992695075463,0.00022104718011791,0.25,1.48148280330904E-7,0.000109544120572655,7.59367818486106E-7,19.9980183,19.9980183,10583.5859375,10598.791015625,56.976810909333,20.5850658051002,13.417728,0,0,0,40,4449,19.9975,10591.1884765625,,,,,,,,,,,,,0,,,,0,,,,,,19.9980183,,,,
,29101246.61,19.9986095,6025.61694335938,0.000130678990440274,3.64201447238604E-7,1,0.999253354069792,40.0298881530762,1.9843585322622,18.0300008505583,0.00145795830687958,0.000269702513332141,0.25,8.85011517409821E-7,0.000129968423560388,1.56297078861601E-6,19.9986095,19.9986095,6020.74462890625,6030.4892578125,57.0198004778906,20.585971872922,13.797379,0,0,0,40,4449,19.9984,6025.61694335938,,,,,,,,,,,,,0,,,,-0.0049,,,,,,19.9986095,,,,
,29101339.66,19.9998302,1377.33245849609,0.000134333472297359,4.02826945338975E-7,1,0.999253354069792,40.0298881530762,1.98420272110733,18.0300008505583,0.00149813892664834,0.000277384699464977,0.25,9.73300924510494E-7,0.000133564024723659,1.62770511040006E-6,19.9998302,19.9998302,1372.43957519531,1382.22534179688,57.1479875550445,20.5860934780568,13.417728,0,0,0,40,4449,19.9979,1377.33245849609,,,,,,,,,,,,,0,,,,-0.00245,,,,,,19.9998302,,,,
,29101367.485,20.0006523,0.319699227809906,5.84340916927767E-5,4.80904022198104E-7,1,0.999253354069792,40.0298881530762,1.98412889240686,18.0300008505583,0.000652844259071098,0.000113747449113647,0.25,-1.9080697297111E-7,5.8099001157836E-5,9.34551805894414E-8,20.0006523,20.0006523,0.319699227809906,0.319699227809906,57.1909771236022,20.5876131409838,13.417728,0,0,0,40,4417,19.99785,0.319699227809906,,,,,,,,,,,,,0,,,,0,,,,,,20.0006523,,,,