File: data/looselyPackedNP/sc-ios-11/ppms/rawdata/ES_S14_FCW_100OE.DAT
[Header]
; VSM Data File (default extension .dat)
; Copyright (c) 2003-2013, Quantum Design, Inc. All rights reserved.
TITLE,
FILEOPENTIME,29193330.83,12/05/2018,5:16 am
BYAPP,VSM,2.0,2.0
INFO,PPMS VSM Option Release 1.4.10 Build 1,APPNAME
INFO,Quantum Design Linear Motor Servo Controller,MOTOR_MODULE_NAME
INFO,3101-100 M1,MOTOR_HW_VERSION
INFO,MMC1014,MOTOR_SERIAL_NUMBER
INFO,SRV No X-over 01.03.11,MOTOR_SOFTWARE_VERSION
INFO,Quantum Design VSM Detection Module,VSM_MODULE_NAME
INFO,3101-150 F0,VSM_HW_VERSION
INFO,VSM707,VSM_SERIAL_NUMBER
INFO,VSM No X-over 01.02.05 May 20 2008 13:51:47,VSM_SOFTWARE_VERSION
INFO,704,PREAMP_SERIAL_NUMBER
INFO,822,COIL_SERIAL_NUMBER
INFO,0,MOMENT_UNITS
INFO,Iron Oxide Spheres,SAMPLE_MATERIAL
INFO,10 nm diameter, collaboration Mainz,SAMPLE_COMMENT
INFO,,SAMPLE_MASS
INFO,,SAMPLE_VOLUME
INFO,,SAMPLE_MOLECULAR_WEIGHT
INFO,,SAMPLE_SIZE
INFO,,SAMPLE_SHAPE
DATATYPE,COMMENT,1
DATATYPE,TIME,2
STARTUPAXIS,X,2
STARTUPAXIS,Y1,5
[Data]
Comment,Time Stamp (sec),Temperature (K),Magnetic Field (Oe),Moment (emu),M. Std. Err. (emu),Transport Action,Averaging Time (sec),Frequency (Hz),Peak Amplitude (mm),Center Position (mm),Coil Signal' (mV),Coil Signal" (mV),Range (mV),M. Quad. Signal (emu),M. Raw' (emu),M. Raw" (emu),Min. Temperature (K),Max. Temperature (K),Min. Field (Oe),Max. Field (Oe),Mass (grams),Motor Lag (deg),Pressure (Torr),VSM Status (code),Motor Status (code),Measure Status (code),Measure Count,PPMS Status (code),System Temp. (K),System Field (Oe),Sample Position (deg),Bridge 1 Resistance (ohms),Bridge 1 Excitation (에),Bridge 2 Resistance (ohms),Bridge 2 Excitation (에),Bridge 3 Resistance (ohms),Bridge 3 Excitation (에),Bridge 4 Resistance (ohms),Bridge 4 Excitation (에),Signal 1 Vin (V),Signal 2 Vin (V),Digital Inputs (code),Drive 1 Iout (mA),Drive 1 Ipower (W),Drive 2 Iout (mA),Drive 2 Ipower (W),Pressure (),Map 20 (),Map 21 (),Map 22 (),Map 23 (),Map 24 (),Map 25 (),Map 26 (),Map 27 (),Map 28 (),Map 29 ()
,29193460.54,10.0031586,99.6091461181641,6.47950333493009E-5,3.22436386469071E-7,1,0.999253354069792,40.0298881530762,2.00764920134143,17.8699996322393,0.000731861157752851,0.000128931784593182,0.25,-8.83603748052287E-8,6.44233985662689E-5,2.24642449742986E-7,10.0031586,10.0031586,99.6091461181641,99.6091461181641,57.1276652135445,20.5735027875666,12.278775,0,0,0,40,4369,9.99405,99.6091461181641,,,,,,,,,,,,,0,,,,0,,,,,,10.0031586,,,,
,29193591.975,13.0662603,99.6091461181641,6.4703359069005E-5,3.11343552935216E-7,1,0.999253354069792,40.0298881530762,2.00749693773293,17.8699996322393,0.000730285301394724,0.00013146018627949,0.25,1.52735676283954E-7,6.43307036827244E-5,4.63909197711499E-7,13.0662603,13.0662603,99.6091461181641,99.6091461181641,57.2081729510253,20.5752666064718,13.038077,0,0,0,40,4370,13.17025,99.6091461181641,,,,,,,,,,,,,0,,,,-0.0049,,,,,,13.0662603,,,,
,29193730.715,16.5089111,99.6091461181641,6.47285170385793E-5,2.80337806765743E-7,1,0.999253354069792,40.0298881530762,2.00755873869078,17.8699996322393,0.000730581366435002,0.000131527263729917,0.25,1.53977820238501E-7,6.43550977188104E-5,4.65261099491073E-7,16.5089111,16.5089111,99.6091461181641,99.6091461181641,57.3738781971022,20.5763252311753,13.038077,0,0,0,40,4370,16.64455,99.6091461181641,,,,,,,,,,,,,0,,,,0.00245,,,,,,16.5089111,,,,
,29193886.8,20.3685246,99.6091461181641,,,2,,,,17.9099996826053,,,,,,,20.3685246,20.3685246,99.6091461181641,99.6091461181641,,,14.177031,,,,-99999999,4370,20.5609,99.6091461181641,,,,,,,,,,,,,,,,,,,,,,,20.3685246,,,,
,29194013.555,23.5224686,99.6091461181641,6.46548464265273E-5,2.98419577373726E-7,1,0.999253354069792,40.0298881530762,1.98365967245531,17.8999993950129,0.000720689544005572,0.000134686284536272,0.25,5.71855985456708E-7,6.42872715924735E-5,8.91117570075446E-7,23.5224686,23.5224686,99.6091461181641,99.6091461181641,57.2933704596215,20.5868226696925,14.556682,0,0,0,40,4370,23.7552,99.6091461181641,,,,,,,,,,,,,0,,,,0.0049,,,,,,23.5224686,,,,
,29194154.635,27.0086784,99.6091461181641,6.46999771186721E-5,3.09871392629448E-7,1,0.999253354069792,40.0298881530762,1.98336857701823,17.8999993950129,0.000722022182065563,0.000130417831648196,0.25,1.64913157613391E-7,6.4347795950888E-5,5.0245404202619E-7,27.0086784,27.0086784,99.6091461181641,99.6091461181641,56.3522897224675,20.5907207307022,14.936333,0,0,0,40,4370,27.3205,99.6091461181641,,,,,,,,,,,,,0,,,,0,,,,,,27.0086784,,,,
,29194306.61,30.7837467,99.6091461181641,,,2,,,,17.9099996826053,,,,,,,30.7837467,30.7837467,99.6091461181641,99.6091461181641,,,15.695635,,,,-99999999,4370,31.139,99.6091461181641,,,,,,,,,,,,,,,,,,,,,,,30.7837467,,,,
,29194438.655,34.06334875,99.6091461181641,6.42075625329359E-5,3.30532907818408E-7,1,0.999253354069792,40.0298881530762,1.99468371653987,17.8999993950129,0.000720123005907874,0.000135395787511221,0.25,5.73142276409169E-7,6.39097755664866E-5,9.55806756379504E-7,34.0381584,34.0885391,99.6091461181641,99.6091461181641,57.3871658819292,20.5844647574745,16.075285,0,0,0,40,4370,34.46975,99.6091461181641,,,,,,,,,,,,,0,,,,0,,,,,,34.06334875,,,,
,29194580.265,37.5404129,99.6091461181641,6.46980441910506E-5,3.17645288511328E-7,1,0.999253354069792,40.0298881530762,1.99479635342212,17.8999993950129,0.000726415702254286,0.000135089534105926,0.25,4.19802249908069E-7,6.44426743098351E-5,8.36086937243861E-7,37.5404129,37.5404129,99.6091461181641,99.6091461181641,57.1784710672945,20.5848206211456,16.075285,0,0,0,40,4370,38.04165,99.6091461181641,,,,,,,,,,,,,0,,,,-0.00245,,,,,,37.5404129,,,,
,29194727.44,41.2232819,99.6091461181641,,,2,,,,17.9000000721216,,,,,,,41.2232819,41.2232819,99.6091461181641,99.6091461181641,,,16.454937,,,,-99999999,4370,41.7546,99.6091461181641,,,,,,,,,,,,,,,,,,,,,,,41.2232819,,,,
,29194864.175,44.5465698,99.6091461181641,6.4803194832038E-5,3.27748432846453E-7,1,0.999253354069792,40.0298881530762,1.99464130919383,17.8900007158518,0.000729294419099103,0.000133438079708505,0.25,1.8321277593045E-7,6.46704140971534E-5,6.51482911859541E-7,44.5465698,44.5465698,99.6091461181641,99.6091461181641,56.8877052581406,20.5841138772234,16.454937,0,0,0,40,4370,45.22,99.6091461181641,,,,,,,,,,,,,0,,,,-0.00245,,,,,,44.5465698,,,,
,29195007.175,48.0490532,99.6091461181641,6.48040177288157E-5,3.6360318309021E-7,1,0.999253354069792,40.0298881530762,1.9947196281169,17.8900007158518,0.00073058727608987,0.000131202448317052,0.25,-4.0654893643135E-8,6.47459573670597E-5,4.40109941046627E-7,48.0490532,48.0490532,99.6091461181641,99.6091461181641,57.166746639506,20.5813579184418,17.214239,0,0,0,40,4370,48.87,99.6091461181641,,,,,,,,,,,,,0,,,,0,,,,,,48.0490532,,,,
,29195153.72,51.5947647,99.6091461181641,,,2,,,,17.8799999198318,,,,,,,51.5947647,51.5947647,99.6091461181641,99.6091461181641,,,18.353191,,,,-99999999,4374,52.6223,99.6091461181641,,,,,,,,,,,,,,,,,,,,,,,51.5947647,,,,
,29195273.905,54.50666615,99.6091461181641,6.4398680631025E-5,3.22406676984181E-7,1,0.999253354069792,40.0298881530762,1.98332037536952,17.8699996322393,0.000722901631564423,0.000133652244936627,0.25,3.00200275064748E-7,6.44735438973886E-5,7.68896796435306E-7,54.4758453,54.537487,99.6091461181641,99.6091461181641,57.126101956506,20.5892076493888,18.732843,0,0,0,40,4374,55.7237,99.6091461181641,,,,,,,,,,,,,0,,,,-0.00245,,,,,,54.50666615,,,,
,29195419.65,58.0151482,99.6091461181641,6.43509835363509E-5,3.20988051428576E-7,1,0.999253354069792,40.0298881530762,1.98313226530968,17.8699996322393,0.000723926937267157,0.000128671687322597,0.25,-1.24545591755042E-7,6.44937155045213E-5,3.23165814855274E-7,58.0151482,58.0151482,99.6091461181641,99.6091461181641,57.495030617583,20.5900480470105,20.631098,0,0,0,40,4374,59.50305,99.6091461181641,,,,,,,,,,,,,0,,,,0,,,,,,58.0151482,,,,
,29195564.72,61.5249557,99.6091461181641,6.44236073111714E-5,3.66361758728337E-7,1,0.999253354069792,40.0298881530762,1.98331759687812,17.8699996322393,0.000725073813463965,0.000130824247896101,0.25,6.92631712679972E-8,6.46191893492177E-5,4.92075433474911E-7,61.5249557,61.5249557,99.6091461181641,99.6091461181641,57.3176009437176,20.5876816776374,21.3904,0,0,0,40,4374,63.22535,99.6091461181641,,,,,,,,,,,,,0,,,,0,,,,,,61.5249557,,,,
,29195686.475,64.5155106,99.6091461181641,6.42691910683145E-5,3.19645104230775E-7,1,0.999253354069792,40.0298881530762,1.98317555568243,17.8399998694658,0.000723956174761975,0.000129148285459586,0.25,-3.37433265646708E-8,6.45020070635382E-5,3.63917957751065E-7,64.5155106,64.5155106,99.6091461181641,99.6091461181641,57.2730481181214,20.5866294402346,21.770052,0,0,0,40,4374,66.3214,99.6091461181641,,,,,,,,,,,,,0,,,,0,,,,,,64.5155106,,,,
,29195828.125,68.0054474,99.6091461181641,6.41537434081916E-5,3.57783265521838E-7,1,0.999253354069792,40.0298881530762,1.98371707443276,17.8399998694658,0.000723420557106296,0.000127948091673499,0.25,-1.00586497092577E-7,6.44210037319085E-5,2.68098325366376E-7,68.0054474,68.0054474,99.6091461181641,99.6091461181641,57.0127658212176,20.5829228745832,22.529354,0,0,0,40,4374,69.885,99.6091461181641,,,,,,,,,,,,,0,,,,0,,,,,,68.0054474,,,,
,29195970.18,71.527359,99.6091461181641,6.39732163573479E-5,3.35831068728604E-7,1,0.999253354069792,40.0298881530762,1.98337152329907,17.8399998694658,0.00072108125020296,0.00013034851187506,0.25,1.68975431831633E-7,6.42653484435166E-5,5.10496535443066E-7,71.527359,71.527359,99.6091461181641,99.6091461181641,56.5242479966983,20.5854337704363,22.529354,0,0,0,40,4374,73.4732,99.6091461181641,,,,,,,,,,,,,0,,,,0,,,,,,71.527359,,,,
,29196091.155,74.5134964,99.6091461181641,6.37820682917852E-5,3.56625366822307E-7,1,0.999253354069792,40.0298881530762,1.98313059509589,17.8100001066923,0.000719754064446831,0.000125986809570712,0.25,-1.63755207657026E-7,6.40930245748884E-5,1.53339327069934E-7,74.5134964,74.5134964,99.6091461181641,99.6091461181641,56.8095424062176,20.5877943058689,22.149702,0,0,0,40,4374,76.51725,99.6091461181641,,,,,,,,,,,,,0,,,,-0.00245,,,,,,74.5134964,,,,
,29196231.82,78.00642395,99.6091461181641,6.35664762191983E-5,3.08485064983811E-7,1,0.999253354069792,40.0298881530762,1.98354642598455,17.8100001066923,0.000717553203373971,0.000126142059270501,0.25,-9.31452865381665E-8,6.3892305544005E-5,1.9954916778813E-7,77.9746399,78.038208,99.6091461181641,99.6091461181641,57.3793495967368,20.5799537042029,22.909004,0,0,0,40,4374,80.0844,99.6091461181641,,,,,,,,,,,,,0,,,,-0.0049,,,,,,78.00642395,,,,
,29196375.29,81.5408325,99.6091461181641,6.35190995073819E-5,2.84814950442211E-7,1,0.999253354069792,40.0298881530762,1.98329366387854,17.8100001066923,0.000717039182263439,0.000126228319675514,0.25,-5.60529721841207E-8,6.38569437350376E-5,2.14696096038058E-7,81.5408325,81.5408325,99.6091461181641,99.6091461181641,57.4536043060638,20.5813251859918,22.529354,0,0,0,40,4374,83.72465,99.6091461181641,,,,,,,,,,,,,0,,,,0,,,,,,81.5408325,,,,
,29196514.795,85.0069504,99.6091461181641,6.27888102693698E-5,2.74067501093285E-7,1,0.999253354069792,40.0298881530762,1.98318391878373,17.7999995648861,0.000708547222951713,0.00012651854948995,0.25,1.16626104761842E-7,6.31306447375191E-5,3.66465537986525E-7,85.0069504,85.0069504,99.6091461181641,99.6091461181641,57.1620568683907,20.5820614287097,23.288654,0,0,0,40,4374,87.2149,99.6091461181641,,,,,,,,,,,,,0,,,,0.00245,,,,,,85.0069504,,,,
,29196656.68,88.5280151,99.6091461181641,6.25847031281957E-5,3.28970285061308E-7,1,0.999253354069792,40.0298881530762,1.98346178371486,17.7999995648861,0.000706252348358594,0.000127020673979374,0.25,2.11633899035025E-7,6.293135374903E-5,4.44039284938584E-7,88.5280151,88.5280151,99.6091461181641,99.6091461181641,57.044812590506,20.5804266836112,23.288654,0,0,0,40,4374,90.7839,99.6091461181641,,,,,,,,,,,,,0,,,,0.0049,,,,,,88.5280151,,,,
,29196797.595,92.0652809,99.6091461181641,6.19162377667673E-5,3.15871051689818E-7,1,0.999253354069792,40.0298881530762,1.98292339284717,17.7999995648861,0.000699127732094759,0.000122492560807753,0.25,-5.43564943074871E-8,6.22642288908934E-5,1.59006183304379E-7,92.0259628,92.104599,99.6091461181641,99.6091461181641,57.0932735586983,20.5884003309793,23.668306,0,0,0,40,4374,94.32,99.6091461181641,,,,,,,,,,,,,0,,,,-0.0049,,,,,,92.0652809,,,,
,29196938.635,95.5499725,99.6091461181641,6.13507173117665E-5,3.10784520871166E-7,1,0.999253354069792,40.0298881530762,1.98325907233249,17.7599992603064,0.000692344129756468,0.000124456627709327,0.25,2.30337843313559E-7,6.1697136894225E-5,4.29924111195401E-7,95.5499725,95.5499725,99.6091461181641,99.6091461181641,57.4606389627369,20.5791731765405,23.668306,0,0,0,40,4374,97.85845,99.6091461181641,,,,,,,,,,,,,0,,,,0,,,,,,95.5499725,,,,
,29197077.635,99.0564117,99.6091461181641,6.08943118776639E-5,2.68957595925569E-7,1,0.999253354069792,40.0298881530762,1.98340855234247,17.7599992603064,0.000687039967878632,0.000124772025276702,0.25,3.49292360065312E-7,6.12389825539702E-5,5.36263695503895E-7,99.0564117,99.0564117,99.6091461181641,99.6091461181641,57.5208243587176,20.5825030466055,24.047956,0,0,0,40,4374,101.3443,99.6091461181641,,,,,,,,,,,,,0,,,,0.00245,,,,,,99.0564117,,,,
,29197216.68,102.5029755,99.6091461181641,6.01545408860454E-5,3.64585588799988E-7,1,0.999253354069792,40.0298881530762,1.98338718273133,17.7599992603064,0.000679172340250784,0.000120504231324774,0.25,1.11972993856201E-7,6.04959844669946E-5,2.84765367834725E-7,102.5029755,102.5029755,99.6091461181641,99.6091461181641,57.251162519583,20.5819660599341,23.668306,0,0,0,40,4374,104.84855,99.6091461181641,,,,,,,,,,,,,0,,,,-0.0049,,,,,,102.5029755,,,,
,29197358.67,106.0256348,99.6091461181641,5.9356834035797E-5,3.07113920911206E-7,1,0.999253354069792,40.0298881530762,1.98339939133913,17.7299994975328,0.000670388421671162,0.000117617661735218,0.25,5.98054881359344E-9,5.96934143398939E-5,1.66301928930015E-7,106.0256348,106.0256348,99.6091461181641,99.6091461181641,57.342613056333,20.5815338285479,24.427608,0,0,0,40,4374,108.4139,99.6091461181641,,,,,,,,,,,,,0,,,,0,,,,,,106.0256348,,,,
,29197500.025,109.5051346,99.6091461181641,5.82409548270018E-5,2.80390569199772E-7,1,0.999253354069792,40.0298881530762,1.98329279108307,17.7299994975328,0.000657197066006707,0.000118481102910718,0.25,2.87303084627954E-7,5.85692210040959E-5,4.37699448443695E-7,109.5051346,109.5051346,99.6091461181641,99.6091461181641,57.3449579418907,20.581728270863,24.047956,0,0,0,40,4374,111.98065,99.6091461181641,,,,,,,,,,,,,0,,,,0,,,,,,109.5051346,,,,
,29197640.72,113.0052567,99.6091461181641,5.73848074520065E-5,3.5936499969403E-7,1,0.999253354069792,40.0298881530762,1.98325544959372,17.7299994975328,0.000647468210332638,0.000116935914650979,0.25,3.08465389152694E-7,5.77063397560806E-5,4.49270741778256E-7,113.0052567,113.0052567,99.6091461181641,99.6091461181641,57.4106147375061,20.5844197254621,24.807261,0,0,0,40,4374,115.5111,99.6091461181641,,,,,,,,,,,,,0,,,,0.0049,,,,,,113.0052567,,,,
,29197782.64,116.5602036,99.6091461181641,5.68065175709335E-5,3.03182169746156E-7,1,0.999253354069792,40.0298881530762,2.00749704428779,17.6999997347593,0.00064921906797718,0.000112376683552454,0.25,-1.01529379514058E-7,5.71233801872732E-5,2.87548521705223E-8,116.5602036,116.5602036,99.6091461181641,99.6091461181641,57.4285921934484,20.5765719506107,24.047956,0,0,0,40,4374,119.0742,99.6091461181641,,,,,,,,,,,,,0,,,,0.0049,,,,,,116.5602036,,,,
,29197923.345,120.0529327,99.6091461181641,5.57219989209568E-5,2.91381104281524E-7,1,0.999253354069792,40.0298881530762,2.00756836018474,17.6999997347593,0.000636753570562004,0.000110581668887163,0.25,-6.27560491834166E-8,5.60300174886573E-5,5.91884850000335E-8,120.0529327,120.0529327,99.6091461181641,99.6091461181641,57.200356665833,20.577521326045,24.807261,0,0,0,40,4374,122.6171,99.6091461181641,,,,,,,,,,,,,0,,,,0,,,,,,120.0529327,,,,
,29198063.41,123.52978135,99.6091461181641,5.50039067673825E-5,3.76473841809403E-7,1,0.999253354069792,40.0298881530762,2.0072012014206,17.6999997347593,0.000628068001366353,0.000111052543980058,0.25,1.11613729104904E-7,5.53045740892695E-5,2.27513880260763E-7,123.498848,123.5607147,99.6091461181641,99.6091461181641,57.4254656793715,20.5784464589871,24.427608,0,0,0,40,4374,126.1328,99.6091461181641,,,,,,,,,,,,,0,,,,0.00245,,,,,,123.52978135,,,,
,29198185.585,126.5507889,99.6091461181641,5.42474298801311E-5,3.33374010968384E-7,1,0.999253354069792,40.0298881530762,1.98324575774097,17.6500007510185,0.000612739047498288,0.000105986160056948,0.25,-8.80367412650778E-8,5.45415478409872E-5,2.08861873471487E-8,126.5507889,126.5507889,99.6091461181641,99.6091461181641,57.495030617583,20.5821851702483,25.186911,0,0,0,40,4374,129.2014,99.6091461181641,,,,,,,,,,,,,0,,,,0,,,,,,126.5507889,,,,
,29198324.54,130.0094147,99.6091461181641,5.34069106702698E-5,2.61582644406248E-7,1,0.999253354069792,40.0298881530762,1.98317782490795,17.6500007510185,0.000602925544875823,0.000105829531242445,0.25,5.02122196758546E-8,5.36927618988642E-5,1.53734115695004E-7,130.0094147,130.0094147,99.6091461181641,99.6091461181641,57.4090514804676,20.5867354197843,25.186911,0,0,0,40,4374,132.69045,99.6091461181641,,,,,,,,,,,,,0,,,,0,,,,,,130.0094147,,,,
,29198465.9,133.5488129,99.6091461181641,5.21639523594925E-5,3.27138212847801E-7,1,0.999253354069792,40.0298881530762,1.98322946585897,17.6500007510185,0.000589312038701311,0.000100809340367922,0.25,-1.72989986423721E-7,5.24398832337965E-5,-7.71171197341322E-8,133.5488129,133.5488129,99.6091461181641,99.6091461181641,56.8150138058522,20.5853693662255,24.807261,0,0,0,40,4374,136.2309,99.6091461181641,,,,,,,,,,,,,0,,,,-0.00245,,,,,,133.5488129,,,,
,29198584.77,136.5214539,99.6091461181641,5.17793357637249E-5,3.84201406106659E-7,1,0.999253354069792,40.0298881530762,1.98331240822558,17.5999999046326,0.00058443686327241,0.000103027476064063,0.25,9.39153629574202E-8,5.20495128684004E-5,1.87316087262206E-7,136.5214539,136.5214539,99.6091461181641,99.6091461181641,57.2027015513907,20.5798674468305,25.186911,0,0,0,40,4374,139.22245,99.6091461181641,,,,,,,,,,,,,0,,,,0,,,,,,136.5214539,,,,
,29198727.295,140.0498657,99.6091461181641,5.07051311195152E-5,3.96150289238007E-7,1,0.999253354069792,40.0298881530762,1.98325956030313,17.5999999046326,0.000572591206507424,9.89431375528068E-5,0.25,-7.61579172436205E-8,5.09660710451163E-5,1.09948867563404E-8,140.0498657,140.0498657,99.6091461181641,99.6091461181641,56.7126204698329,20.5845204367776,25.186911,0,0,0,40,4374,142.7941,99.6091461181641,,,,,,,,,,,,,0,,,,0,,,,,,140.0498657,,,,
,29198867.52,143.5550842,99.6091461181641,4.92663806713322E-5,4.03751241786503E-7,1,0.999253354069792,40.0298881530762,1.9833311233173,17.5999999046326,0.000555919890532019,9.84184627589909E-5,0.25,1.31633397397618E-7,4.95156024291689E-5,2.14310784475106E-7,143.5550842,143.5550842,99.6091461181641,99.6091461181641,56.7853119221214,20.5816012117713,25.186911,0,0,0,40,4374,146.3136,99.6091461181641,,,,,,,,,,,,,0,,,,0.00245,,,,,,143.5550842,,,,
,29198986.62,146.5395355,99.6091461181641,4.8525374994922E-5,3.21010158089221E-7,1,0.999253354069792,40.0298881530762,1.98324451020039,17.5599996000528,0.000547787469967733,9.5259455427794E-5,0.25,-1.57353779594938E-8,4.87676409272959E-5,6.25836879599865E-8,146.5395355,146.5395355,99.6091461181641,99.6091461181641,56.8642564025637,20.5831275960603,25.946213,0,0,0,40,4374,149.2992,99.6091461181641,,,,,,,,,,,,,0,,,,0,,,,,,146.5395355,,,,
,29199128.185,150.0432281,99.6091461181641,4.8168742077084E-5,3.99907808081408E-7,1,0.999253354069792,40.0298881530762,1.9835283847518,17.5599996000528,0.000543168093822708,9.81309576078302E-5,0.25,3.02949924027665E-7,4.84045894021798E-5,3.79627183146614E-7,150.0432281,150.0432281,99.6091461181641,99.6091461181641,57.83347576641,20.5808482360634,25.566563,0,0,0,40,4374,152.8531,99.6091461181641,,,,,,,,,,,,,0,,,,0,,,,,,150.0432281,,,,
,29199267.115,153.5428009,99.6091461181641,4.65253972975929E-5,3.82028574354207E-7,1,0.999253354069792,40.0298881530762,1.98331961865841,17.5599996000528,0.000525375785460654,8.99548738449521E-5,0.25,-1.31280636311806E-7,4.67497236397893E-5,-6.16044916333523E-8,153.5428009,153.5428009,99.6091461181641,99.6091461181641,56.8666012881214,20.5845365033673,25.566563,0,0,0,40,4374,156.3283,99.6091461181641,,,,,,,,,,,,,0,,,,0,,,,,,153.5428009,,,,
,29199407.335,157.0366364,99.6091461181641,4.62887469174418E-5,3.28739954405411E-7,1,0.999253354069792,40.0298881530762,1.98343794861808,17.5000000745058,0.000522629183438408,8.98197188331994E-5,0.25,-9.96192886875783E-8,4.650766948035E-5,-3.2316467645502E-8,157.0366364,157.0366364,99.6091461181641,99.6091461181641,57.2949337166599,20.5819726512893,25.946213,0,0,0,40,4374,159.83925,99.6091461181641,,,,,,,,,,,,,0,,,,-0.00245,,,,,,157.0366364,,,,
,29199548.285,160.5490417,99.6091461181641,4.53940381618626E-5,3.84307762564119E-7,1,0.999253354069792,40.0298881530762,1.98356985132314,17.5000000745058,0.000512031295675874,9.08430720545274E-5,0.25,1.49037705915642E-7,4.56041172834394E-5,2.14179013246622E-7,160.5490417,160.5490417,99.6091461181641,99.6091461181641,56.9236601700253,20.5839203225839,25.946213,0,0,0,40,4374,163.3747,99.6091461181641,,,,,,,,,,,,,0,,,,0,,,,,,160.5490417,,,,
,29199687.495,164.025589,99.6091461181641,4.4638746409773E-5,3.5835285408517E-7,1,0.999253354069792,40.0298881530762,1.98353361226462,17.5000000745058,0.00050306308295949,9.15766892147252E-5,0.25,3.48205517269382E-7,4.48408160040141E-5,4.11336028160841E-7,164.025589,164.025589,99.6091461181641,99.6091461181641,57.281646031833,20.5836403265885,25.946213,0,0,0,40,4374,166.855,99.6091461181641,,,,,,,,,,,,,0,,,,-0.00245,,,,,,164.025589,,,,
,29199829.055,167.5661774,99.6091461181641,4.38717497579406E-5,3.70463237139427E-7,1,0.999253354069792,40.0298881530762,2.00753162631634,17.4599997699261,0.000500481437021222,8.8715739429876E-5,0.25,1.40879751319814E-7,4.40662931365432E-5,2.00281869271531E-7,167.5661774,167.5661774,99.6091461181641,99.6091461181641,56.6735390438714,20.5708557332497,25.946213,0,0,0,40,4374,170.392,99.6091461181641,,,,,,,,,,,,,0,,,,0,,,,,,167.5661774,,,,
,29199966.225,171.00383,99.6091461181641,4.24555920460572E-5,3.80397989760895E-7,1,0.999253354069792,40.0298881530762,2.00740165434682,17.4599997699261,0.000484185339705202,8.62049641291925E-5,0.25,1.69961016969902E-7,4.26396618513447E-5,2.26058722449782E-7,171.00383,171.00383,99.6091461181641,99.6091461181641,57.0862389020253,20.571768247082,26.325863,0,0,0,40,4374,173.8279,99.6091461181641,,,,,,,,,,,,,0,,,,0,,,,,,171.00383,,,,
,29200108.295,174.522934,99.6091461181641,4.18963791827983E-5,3.09284134417443E-7,1,0.999253354069792,40.0298881530762,2.0073223869239,17.4599997699261,0.000478870140423626,7.8565817246845E-5,0.25,-3.997418958774E-7,4.20744798307199E-5,-3.48267724375795E-7,174.522934,174.522934,99.6091461181641,99.6091461181641,57.0424677049483,20.5747163054235,26.325863,0,0,0,40,4374,177.3789,99.6091461181641,,,,,,,,,,,,,0,,,,-0.0049,,,,,,174.522934,,,,
,29200247.315,178.02326965,99.6091461181641,4.09179225930277E-5,3.4894976067745E-7,1,0.999253354069792,40.0298881530762,1.98323235820904,17.4100007861853,0.000462172245408519,7.64630971714881E-5,0.25,-3.34203953221259E-7,4.10875587587554E-5,-2.8497761206084E-7,177.9916687,178.0548706,99.6091461181641,99.6091461181641,57.5090999309292,20.5827315284334,26.705515,0,0,0,40,4374,180.8488,99.6091461181641,,,,,,,,,,,,,0,,,,0.0049,,,,,,178.02326965,,,,
,29200387.15,181.50965115,99.6091461181641,3.99515290912159E-5,3.74827629981191E-7,1,0.999253354069792,40.0298881530762,1.98291057074184,17.4100007861853,0.000450924408878733,7.58769349534008E-5,0.25,-2.15204661507356E-7,4.01128469250902E-5,-1.67890778098608E-7,181.4779205,181.5413818,99.6091461181641,99.6091461181641,57.0119841926983,20.5894612317099,26.325863,0,0,0,40,4374,184.3563,99.6091461181641,,,,,,,,,,,,,0,,,,0.00245,,,,,,181.50965115,,,,
,29200527.51,185.0228271,99.6091461181641,3.91767881736255E-5,3.54334691722482E-7,1,0.999253354069792,40.0298881530762,1.98252094832035,17.4100007861853,0.000441713820806166,7.63181484159849E-5,0.25,-3.82877582539919E-8,3.93305885032876E-5,7.66173740197914E-9,185.0228271,185.0228271,99.6091461181641,99.6091461181641,57.0901470446214,20.5903956327665,26.325863,0,0,0,40,4374,187.87105,99.6091461181641,,,,,,,,,,,,,0,,,,0,,,,,,185.0228271,,,,
,29200649.18,188.0385132,99.6091461181641,3.84531972306328E-5,3.80556073422517E-7,1,0.999253354069792,40.0298881530762,1.98266632354043,17.3599999397993,0.000433973857390003,7.2442944939947E-5,0.25,-2.55232222056795E-7,3.86008418137277E-5,-2.11892714992274E-7,188.0385132,188.0385132,99.6091461181641,99.6091461181641,56.9252234270637,20.5835826438775,26.325863,0,0,0,40,4374,190.9209,99.6091461181641,,,,,,,,,,,,,0,,,,0.0049,,,,,,188.0385132,,,,
,29200788.35,191.5428162,99.6091461181641,3.78850378500622E-5,4.10563148971917E-7,1,0.999253354069792,40.0298881530762,1.98264480385359,17.3599999397993,0.000427389514276893,7.20619623070393E-5,0.25,-1.88549816347076E-7,3.80262908892023E-5,-1.46591570393216E-7,191.5428162,191.5428162,99.6091461181641,99.6091461181641,56.9447641400445,20.5886774442432,26.705515,0,0,0,40,4374,194.41565,99.6091461181641,,,,,,,,,,,,,0,,,,0,,,,,,191.5428162,,,,
,29200928.385,195.0042725,99.6091461181641,3.73144040501314E-5,3.69864510885703E-7,1,0.999253354069792,40.0298881530762,1.98261392812379,17.3599999397993,0.000421009727146498,7.03363185919042E-5,0.25,-2.40801827088369E-7,3.74495191644717E-5,-2.00599517731519E-7,195.0042725,195.0042725,99.6091461181641,99.6091461181641,57.2894623170253,20.5904460361364,26.325863,0,0,0,40,4374,197.9287,99.6091461181641,,,,,,,,,,,,,0,,,,-0.00245,,,,,,195.0042725,,,,
,29201071.05,198.5584259,99.6091461181641,3.60339784618456E-5,3.59284945631078E-7,1,0.999253354069792,40.0298881530762,1.98277524798524,17.2899998724461,0.000405030121023653,7.66635749185656E-5,0.25,5.44148137347178E-7,3.61595366581716E-5,5.84831240769083E-7,198.5584259,198.5584259,99.6091461181641,99.6091461181641,56.9455457685637,20.5858889275067,26.705515,0,0,0,40,4374,201.5025,99.6091461181641,,,,,,,,,,,,,0,,,,0,,,,,,198.5584259,,,,
,29201211.515,202.0523071,99.6091461181641,3.54015653662626E-5,3.70080509575901E-7,1,0.999253354069792,40.0298881530762,1.98251931393884,17.2899998724461,0.00039926665903593,6.70166596382271E-5,0.25,-1.99799887606883E-7,3.55217245443004E-5,-1.63197130473795E-7,202.0523071,202.0523071,99.6091461181641,99.6091461181641,57.200356665833,20.5922682660414,26.325863,0,0,0,40,4374,205.02515,99.6091461181641,,,,,,,,,,,,,0,,,,0,,,,,,202.0523071,,,,
,29201350.34,205.5365677,99.6091461181641,3.48732848314083E-5,3.46473031503953E-7,1,0.999253354069792,40.0298881530762,1.98258997689947,17.2899998724461,0.000393447514763476,6.50323582834958E-5,0.25,-2.82964096453844E-7,3.49877846021002E-5,-2.47926816652837E-7,205.5072937,205.5658417,99.6091461181641,99.6091461181641,56.6735390438714,20.5900142034602,27.085165,0,0,0,40,4374,208.4967,99.6091461181641,,,,,,,,,,,,,0,,,,0,,,,,,205.5365677,,,,
,29201491.52,209.0467987,99.6091461181641,3.42716334777964E-5,3.74247667433904E-7,1,0.999253354069792,40.0298881530762,1.98287656677467,17.2499995678663,0.000386059921541693,6.74171767762825E-5,0.25,3.37616792608552E-8,3.43798900025243E-5,6.84849946120392E-8,209.0467987,209.0467987,99.6091461181641,99.6091461181641,57.0135474497368,20.5864635158986,26.705515,0,0,0,40,4374,212.02735,99.6091461181641,,,,,,,,,,,,,0,,,,-0.00245,,,,,,209.0467987,,,,
,29201630.61,212.5384216,99.6091461181641,3.29850925828974E-5,3.73906643377188E-7,1,0.999253354069792,40.0298881530762,1.98317521346436,17.2499995678663,0.000371393655730633,6.59505071453006E-5,0.25,1.2743200901601E-7,3.30853794898759E-5,1.60475994447957E-7,212.5384216,212.5384216,99.6091461181641,99.6091461181641,56.9158438848329,20.583419578884,27.085165,0,0,0,40,4374,215.50675,99.6091461181641,,,,,,,,,,,,,0,,,,0,,,,,,212.5384216,,,,
,29201772.125,216.0549774,99.6091461181641,3.24897541686499E-5,3.06695733992306E-7,1,0.999253354069792,40.0298881530762,1.98304839654333,17.2499995678663,0.0003667759869499,5.90451510445823E-5,0.25,-3.97897354954451E-7,3.25852338093964E-5,-3.67533965252944E-7,216.0549774,216.0549774,99.6091461181641,99.6091461181641,57.241001348833,20.5840377052107,27.085165,0,0,0,40,4374,219.0565,99.6091461181641,,,,,,,,,,,,,0,,,,0,,,,,,216.0549774,,,,
,29201912.05,219.5469666,99.6091461181641,3.17724480060398E-5,2.78030607145336E-7,1,0.999253354069792,40.0298881530762,1.98314394545289,17.1900000423193,0.000358747793361509,5.71899328825097E-5,0.25,-4.37131489004092E-7,3.18621280256008E-5,-4.08119770768473E-7,219.5469666,219.5469666,99.6091461181641,99.6091461181641,57.065134932006,20.5771827823702,26.705515,0,0,0,40,4374,222.56365,99.6091461181641,,,,,,,,,,,,,0,,,,0,,,,,,219.5469666,,,,
,29202050.88,223.0525513,99.6091461181641,3.12849536775233E-5,3.33189660715281E-7,1,0.999253354069792,40.0298881530762,1.98288095251194,17.1900000423193,0.000352529641948853,5.99124011808921E-5,0.25,-1.0897714695343E-7,3.13692358083137E-5,-8.00522519609887E-8,223.0525513,223.0525513,99.6091461181641,99.6091461181641,57.0104209356599,20.5831172415823,27.464817,0,0,0,40,4374,226.04945,99.6091461181641,,,,,,,,,,,,,0,,,,0,,,,,,223.0525513,,,,
,29202191.76,226.5619049,99.6091461181641,3.05592702612598E-5,3.67224016207158E-7,1,0.999253354069792,40.0298881530762,1.98296190716233,17.1900000423193,0.000343560188041265,6.29240247073295E-5,0.25,2.85355228388316E-7,3.06375814047991E-5,3.14097908356885E-7,226.5619049,226.5619049,99.6091461181641,99.6091461181641,57.251162519583,20.5837123819184,27.464817,0,0,0,40,4374,229.579,99.6091461181641,,,,,,,,,,,,,0,,,,0,,,,,,226.5619049,,,,
,29202331.68,230.046524,99.6091461181641,3.03560461135116E-5,3.45876799281274E-7,1,0.999253354069792,40.0298881530762,1.99441160112986,17.1399991959333,0.000343559859331119,6.02851383820574E-5,0.25,5.8052652292319E-8,3.04304164951674E-5,8.55143501848831E-8,230.046524,230.046524,99.6091461181641,99.6091461181641,56.7798405224868,20.5757458462513,27.844467,0,0,0,40,4374,233.06875,99.6091461181641,,,,,,,,,,,,,0,,,,-0.0049,,,,,,230.046524,,,,
,29202470.76,233.5061035,99.6091461181641,2.95786299766674E-5,4.46485755143231E-7,1,0.999253354069792,40.0298881530762,1.99425158755875,17.1399991959333,0.000335915090217799,5.17018153346756E-5,0.25,-5.63848295168775E-7,2.96481164364469E-5,-5.3901745936757E-7,233.5061035,233.5061035,99.6091461181641,99.6091461181641,57.1135959001984,20.5762753579694,27.085165,0,0,0,40,4374,236.5603,99.6091461181641,,,,,,,,,,,,,0,,,,0.00245,,,,,,233.5061035,,,,
,29202610.435,237.0005646,99.6091461181641,2.92866145113485E-5,3.36281035574545E-7,1,0.999253354069792,40.0298881530762,1.99428382706062,17.1399991959333,0.000332223289812181,5.31477430824188E-5,0.25,-3.84500057766165E-7,2.93517075758869E-5,-3.59917728304493E-7,237.0005646,237.0005646,99.6091461181641,99.6091461181641,57.0424677049483,20.5796097211118,27.464817,0,0,0,40,4374,240.0664,99.6091461181641,,,,,,,,,,,,,0,,,,0,,,,,,237.0005646,,,,
,29202731.07,240.000351,99.6091461181641,2.8770783088406E-5,4.21878475339237E-7,1,0.999253354069792,40.0298881530762,1.98293022335353,17.0799996703863,0.000324750031088777,5.08457407427966E-5,0.25,-4.73009155440197E-7,2.88318009068156E-5,-4.49393718269055E-7,240.000351,240.000351,99.6091461181641,99.6091461181641,57.1284468420637,20.5802848612458,27.464817,0,0,0,40,4374,243.0798,99.6091461181641,,,,,,,,,,,,,0,,,,0,,,,,,240.000351,,,,
,29202873.675,243.5299377,99.6091461181641,2.8560293101095E-5,4.0960011654667E-7,1,0.999253354069792,40.0298881530762,1.98278808261462,17.0799996703863,0.000321474832711806,5.52924650778162E-5,0.25,-4.00582069085877E-8,2.86169722071184E-5,-1.61333084844971E-8,243.5299377,243.5299377,99.6091461181641,99.6091461181641,56.7235632691022,20.5829475628097,27.464817,0,0,0,40,4374,246.67145,99.6091461181641,,,,,,,,,,,,,0,,,,0,,,,,,243.5299377,,,,
,29203012.65,247.0145569,99.6091461181641,2.72595504138871E-5,3.16892918210839E-7,1,0.999253354069792,40.0298881530762,1.98279038856557,17.0799996703863,0.000307573544994361,4.82874630217364E-5,0.25,-4.36042868291259E-7,2.73106409760942E-5,-4.14326007087078E-7,246.9859619,247.0431519,99.6091461181641,99.6091461181641,57.1284468420637,20.5852315229174,27.464817,0,0,0,40,4374,250.1497,99.6091461181641,,,,,,,,,,,,,0,,,,0,,,,,,247.0145569,,,,
,29203132.615,250.0099792,99.6091461181641,2.70826153256438E-5,3.97977666038326E-7,1,0.999253354069792,40.0298881530762,1.99457472389382,17.0200001448393,0.000306872571387879,5.05838279535662E-5,0.25,-2.25851091266825E-7,2.71303421287323E-5,-2.04184757371612E-7,250.0099792,250.0099792,99.6091461181641,99.6091461181641,57.0409044479099,20.5684181249719,27.844467,0,0,0,40,4374,253.1557,99.6091461181641,,,,,,,,,,,,,0,,,,0,,,,,,250.0099792,,,,
,29203274.385,253.5493774,99.6091461181641,2.60736972924795E-5,3.84604025035102E-7,1,0.999253354069792,40.0298881530762,1.99444436030828,17.0200001448393,0.000295005992999013,5.08770821554019E-5,0.25,-2.37796137715901E-8,2.61162265971771E-5,-2.93095574268446E-9,253.5493774,253.5493774,99.6091461181641,99.6091461181641,57.0080760501022,20.5762357255463,27.464817,0,0,0,40,4374,256.71215,99.6091461181641,,,,,,,,,,,,,0,,,,0,,,,,,253.5493774,,,,
,29203415.135,257.0423279,99.6091461181641,2.62956358398633E-5,4.14847486662591E-7,1,0.999253354069792,40.0298881530762,1.99426764626534,17.0200001448393,0.000296808694476402,5.50277512953005E-5,0.25,3.05996021242933E-7,2.63350110587694E-5,3.27180656322329E-7,257.0423279,257.0423279,99.6091461181641,99.6091461181641,56.9760292808137,20.5778746086635,27.844467,0,0,0,40,4374,260.2245,99.6091461181641,,,,,,,,,,,,,0,,,,-0.0049,,,,,,257.0423279,,,,
,29203554.915,260.5570374,99.6091461181641,2.54284754477707E-5,3.71991680411456E-7,1,0.999253354069792,40.0298881530762,2.00703101390892,16.9699992984533,0.000289431593557243,4.95264253585648E-5,0.25,-5.57705301242618E-8,2.54636518390252E-5,-3.61249244168337E-8,260.5570374,260.5570374,99.6091461181641,99.6091461181641,56.7939098358329,20.5682533089756,28.224119,0,0,0,40,4374,263.701,99.6091461181641,,,,,,,,,,,,,0,,,,0,,,,,,260.5570374,,,,
,29203694.405,264.0196838,99.6091461181641,2.48801503795243E-5,3.67652926426369E-7,1,0.999253354069792,40.0298881530762,2.00696684834153,16.9699992984533,0.000283127622334444,4.85624310819303E-5,0.25,-4.44720786830211E-8,2.49114915956537E-5,-2.55357768593347E-8,264.0196838,264.0196838,99.6091461181641,99.6091461181641,57.3668435404292,20.5693387204692,27.844467,0,0,0,40,4374,267.21545,99.6091461181641,,,,,,,,,,,,,0,,,,0,,,,,,264.0196838,,,,
,29203835.28,267.5315552,99.6091461181641,2.47143963758491E-5,4.33564952445799E-7,1,0.999253354069792,40.0298881530762,2.00685623642488,16.9699992984533,0.000280974042170502,4.94842387711389E-5,0.25,6.63603160186569E-8,2.47423479957709E-5,8.50046475572272E-8,267.5315552,267.5315552,99.6091461181641,99.6091461181641,57.0823307594291,20.5704747251299,28.224119,0,0,0,40,4374,270.7546,99.6091461181641,,,,,,,,,,,,,0,,,,0.0049,,,,,,267.5315552,,,,
,29203975.325,271.0017395,99.6091461181641,2.37639447444497E-5,3.81233117212503E-7,1,0.999253354069792,40.0298881530762,1.9831248345705,16.9099997729063,0.000266253511469676,5.1835337490896E-5,0.25,4.90709491835652E-7,2.37875589210452E-5,5.08786804470944E-7,271.0017395,271.0017395,99.6091461181641,99.6091461181641,56.973684395256,20.5774857200792,28.224119,0,0,0,40,4374,274.2373,99.6091461181641,,,,,,,,,,,,,0,,,,-0.0049,,,,,,271.0017395,,,,
,29204116.025,274.5067291,99.6091461181641,2.34575936465181E-5,3.69136410381051E-7,1,0.999253354069792,40.0298881530762,1.98323456442577,16.9099997729063,0.000264317524811981,4.2420488068132E-5,0.25,-2.92947963138618E-7,2.34785332640052E-5,-2.76116588249722E-7,274.4745483,274.5389099,99.6091461181641,99.6091461181641,56.9627415959868,20.5786296999081,28.224119,0,0,0,40,4374,277.7659,99.6091461181641,,,,,,,,,,,,,0,,,,0,,,,,,274.5067291,,,,
,29204257.05,278.0072021,99.6091461181641,2.30937812380713E-5,3.58003454691359E-7,1,0.999253354069792,40.0298881530762,1.9830372874302,16.9099997729063,0.000259544232853372,4.53107096244585E-5,0.25,2.83060675855305E-8,2.31112707020174E-5,4.48984349586517E-8,278.0072021,278.0072021,99.6091461181641,99.6091461181641,57.1518956976407,20.5807826221369,28.224119,0,0,0,40,4374,281.29795,99.6091461181641,,,,,,,,,,,,,0,,,,-0.00245,,,,,,278.0072021,,,,
,29204398.31,281.5553894,99.6091461181641,2.24270006350393E-5,3.77720522419157E-7,1,0.999253354069792,40.0298881530762,1.98322316512875,16.8399997055531,0.000252432475586668,4.17420810683889E-5,0.25,-1.73215962305899E-7,2.24412758562947E-5,-1.57472839316789E-7,281.5553894,281.5553894,99.6091461181641,99.6091461181641,57.4528226775445,20.5753027423248,28.224119,0,0,0,40,4374,284.82825,99.6091461181641,,,,,,,,,,,,,0,,,,0,,,,,,281.5553894,,,,
,29204538.665,285.0577698,99.6091461181641,2.22283562296616E-5,4.30854276894092E-7,1,0.999253354069792,40.0298881530762,1.98303091753582,16.8399997055531,0.000250242633057554,4.07827077877443E-5,0.25,-2.23118991949671E-7,2.2239749098097E-5,-2.07749499467629E-7,285.0577698,285.0577698,99.6091461181641,99.6091461181641,56.8759808303522,20.5787932700027,28.603769,0,0,0,40,4374,288.3335,99.6091461181641,,,,,,,,,,,,,0,,,,0,,,,,,285.0577698,,,,
,29204677.865,288.5059204,99.6091461181641,2.19629000823501E-5,5.4198125378054E-7,1,0.999253354069792,40.0298881530762,1.98304402364081,16.8399997055531,0.000248352480454294,3.37854378902052E-5,0.25,-7.9917475588244E-7,2.19718387710288E-5,-7.84402472431741E-7,288.5059204,288.5059204,99.6091461181641,99.6091461181641,57.0971817012945,20.5796352463295,28.603769,0,0,0,40,4374,291.8236,99.6091461181641,,,,,,,,,,,,,0,,,,0,,,,,,288.5059204,,,,
,29204798.105,291.5101624,99.6091461181641,2.12181753634972E-5,4.61388928293226E-7,1,0.999253354069792,40.0298881530762,2.00695551928263,16.7900007218122,0.000241693740234287,3.86223780503065E-5,0.25,-2.78233736778487E-7,2.1224186761792E-5,-2.63922504903205E-7,291.5101624,291.5101624,99.6091461181641,99.6091461181641,56.9291315696599,20.565338056071,28.224119,0,0,0,40,4374,294.8377,99.6091461181641,,,,,,,,,,,,,0,,,,-0.0049,,,,,,291.5101624,,,,
,29204941.23,295.0511169,99.6091461181641,2.06659482583432E-5,4.17991998604653E-7,1,0.999253354069792,40.0298881530762,2.00683708087683,16.7900007218122,0.000234764693111345,4.10477843113924E-5,0.25,3.17228676839831E-8,2.06689798149006E-5,4.55392575145938E-8,295.0511169,295.0511169,99.6091461181641,99.6091461181641,57.2128627221407,20.5659269598328,28.224119,0,0,0,40,4374,298.41875,99.6091461181641,,,,,,,,,,,,,0,,,,-0.00245,,,,,,295.0511169,,,,
,29205079.335,298.5117493,99.6091461181641,2.03438353965741E-5,4.3475837773093E-7,1,0.999253354069792,40.0298881530762,2.00712433607931,16.7900007218122,0.000231935758882683,3.56335059067192E-5,0.25,-3.88805701093433E-7,2.03445803581114E-5,-3.75403659846127E-7,298.5117493,298.5117493,99.6091461181641,99.6091461181641,57.1448610409676,20.5639807061319,28.603769,0,0,0,40,4374,301.8563,99.6091461181641,,,,,,,,,,,,,0,,,,0,,,,,,298.5117493,,,,
,29205221.295,302.0272522,99.6091461181641,1.99978018677473E-5,5.14606335144241E-7,1,0.999253354069792,40.0298881530762,1.99477842981245,16.7299993336201,0.000226862736972114,3.34391536979954E-5,0.25,-5.04034078608153E-7,1.99961010671635E-5,-4.90983888145482E-7,302.0272522,302.0272522,99.6091461181641,99.6091461181641,57.2034831799099,20.5624905279671,28.603769,0,0,0,40,4374,305.4398,99.6091461181641,,,,,,,,,,,,,0,,,,-0.0049,,,,,,302.0272522,,,,
,29205360.86,305.5227051,99.6091461181641,1.9959265116788E-5,4.38208342502289E-7,1,0.999253354069792,40.0298881530762,1.99468721147058,16.7299993336201,0.000225026627262286,4.12242306518776E-5,0.25,1.92674534151303E-7,1.99546316539967E-5,2.05430829046574E-7,305.5227051,305.5227051,99.6091461181641,99.6091461181641,57.1644017539484,20.5658104105514,28.224119,0,0,0,40,4374,308.93615,99.6091461181641,,,,,,,,,,,,,0,,,,0.00245,,,,,,305.5227051,,,,
,29205503.02,309.0550537,99.6091461181641,1.95864711890734E-5,5.03514775186023E-7,1,0.999253354069792,40.0298881530762,1.99460551658992,16.7299993336201,0.000221133613947175,3.8448373078574E-5,0.25,1.21845182822409E-8,1.95795785763486E-5,2.45726160944682E-8,309.0550537,309.0550537,99.6091461181641,99.6091461181641,57.2136443506599,20.5663598895461,28.983419,0,0,0,40,4374,312.4852,99.6091461181641,,,,,,,,,,,,,0,,,,0,,,,,,309.0550537,,,,
,29205643.365,312.5588379,99.6091461181641,1.93580843505815E-5,4.22342734434974E-7,1,0.999253354069792,40.0298881530762,2.00756252658054,16.669999808073,0.000219602074282229,3.984798329205E-5,0.25,1.5456047242888E-7,1.93487784099138E-5,1.66574850535748E-7,312.5588379,312.5588379,99.6091461181641,99.6091461181641,56.9244417985445,20.5560424321773,28.983419,0,0,0,40,4374,316.0034,99.6091461181641,,,,,,,,,,,,,0,,,,-0.0049,,,,,,312.5588379,,,,
,29205783.14,316.0253906,99.6091461181641,1.88274559067303E-5,4.68790109042575E-7,1,0.999253354069792,40.0298881530762,2.00762054231303,16.669999808073,0.00021414668544128,3.53777851636224E-5,0.25,-1.46585093442003E-7,1.88162819403231E-5,-1.34891071451301E-7,316.0253906,316.0253906,99.6091461181641,99.6091461181641,56.9056827140829,20.5583937405386,28.983419,0,0,0,40,4374,319.50935,99.6091461181641,,,,,,,,,,,,,0,,,,0.0049,,,,,,316.0253906,,,,
,29205924.89,319.5341492,99.6091461181641,1.81687537036222E-5,4.17654249476143E-7,1,0.999253354069792,40.0298881530762,2.00775769317588,16.669999808073,0.000206449176306966,3.52534958135551E-5,0.25,-4.31086202472342E-8,1.81556632401772E-5,-3.20200562477348E-8,319.5341492,319.5341492,99.6091461181641,99.6091461181641,57.0166739638137,20.5573691088255,28.983419,0,0,0,40,4374,323.0773,99.6091461181641,,,,,,,,,,,,,0,,,,-0.00245,,,,,,319.5341492,,,,
,29206065.43,323.0050964,99.6091461181641,1.8119807424586E-5,3.86320170802085E-7,1,0.999253354069792,40.0298881530762,2.00779618735559,16.5999997407198,0.000206222837910147,3.31272070415328E-5,0.25,-2.21397147331223E-7,1.81046506416907E-5,-2.1031788396382E-7,323.0050964,323.0050964,99.6091461181641,99.6091461181641,56.8118872917752,20.5565102640912,28.603769,0,0,0,40,4374,326.5799,99.6091461181641,,,,,,,,,,,,,0,,,,0,,,,,,323.0050964,,,,
,29206207.935,326.5464172,99.6091461181641,1.75476559144982E-5,4.9251658633798E-7,1,0.999253354069792,40.0298881530762,2.0077600855453,16.5999997407198,0.000200266110018899,2.87093941586795E-5,0.25,-5.10810533409365E-7,1.75309785523683E-5,-4.99896903584523E-7,326.5464172,326.5464172,99.6091461181641,99.6091461181641,56.912717370756,20.5565242081129,29.363071,0,0,0,40,4374,330.15825,99.6091461181641,,,,,,,,,,,,,0,,,,-0.00245,,,,,,326.5464172,,,,
,29206347.4,330.022583,99.6091461181641,1.70171431420396E-5,4.99770473286294E-7,1,0.999253354069792,40.0298881530762,2.00773186704248,16.5999997407198,0.000194150334573194,2.80398600929838E-5,0.25,-4.7744319708555E-7,1.69988957219504E-5,-4.66937089795322E-7,330.022583,330.022583,99.6091461181641,99.6091461181641,56.9517987967176,20.557002413772,29.363071,0,0,0,40,4374,333.6543,99.6091461181641,,,,,,,,,,,,,0,,,,0,,,,,,330.022583,,,,
,29206489.205,333.55142215,99.6091461181641,1.65195970589349E-5,4.25876583761604E-7,1,0.999253354069792,40.0298881530762,2.00774570458593,16.550000756979,0.000187868069719233,3.05882059268015E-5,0.25,-1.66407716427767E-7,1.64996867110498E-5,-1.56623963779615E-7,333.5212708,333.5815735,99.6091461181641,99.6091461181641,57.1604936113522,20.5524163478222,28.983419,0,0,0,40,4374,337.206,99.6091461181641,,,,,,,,,,,,,0,,,,0,,,,,,333.55142215,,,,
,29206627.835,337.0169678,99.6091461181641,1.6493127050277E-5,3.81592373001258E-7,1,0.999253354069792,40.0298881530762,2.00783439133524,16.550000756979,0.000188261644799345,2.64415825926085E-5,0.25,-5.26794734346386E-7,1.64714827232167E-5,-5.16632219614779E-7,337.0169678,337.0169678,99.6091461181641,99.6091461181641,56.926005055583,20.5532458482473,28.983419,0,0,0,40,4374,340.6832,99.6091461181641,,,,,,,,,,,,,0,,,,0.0049,,,,,,337.0169678,,,,
,29206770.18,340.5596008,99.6091461181641,1.65495504667018E-5,4.40251150027159E-7,1,0.999253354069792,40.0298881530762,2.00772397711313,16.550000756979,0.000189110962853874,2.51517848625535E-5,0.25,-6.49696685402304E-7,1.6525885874256E-5,-6.39363363346793E-7,340.5596008,340.5596008,99.6091461181641,99.6091461181641,57.1847240954484,20.5548614635495,29.363071,0,0,0,40,4374,344.2531,99.6091461181641,,,,,,,,,,,,,0,,,,-0.0049,,,,,,340.5596008,,,,
,29206890.705,343.5357361,99.6091461181641,1.62633406585936E-5,4.59642278816201E-7,1,0.999253354069792,40.0298881530762,1.99540353195888,16.4899993687868,0.000183431522211621,3.20880069791791E-5,0.25,2.80202409603999E-8,1.62380554990372E-5,3.71208522160479E-8,343.5357361,343.5357361,99.6091461181641,99.6091461181641,56.9729027667368,20.5516960093569,29.742722,0,0,0,40,4374,347.2832,99.6091461181641,,,,,,,,,,,,,0,,,,0,,,,,,343.5357361,,,,
,29207032.455,347.0613708,99.6091461181641,1.61710016586804E-5,5.19438554756312E-7,1,0.999253354069792,40.0298881530762,1.99537862923907,16.4899993687868,0.000182024947575504,3.38714013582638E-5,0.25,2.02567565348072E-7,1.61438281124114E-5,2.1122857785992E-7,347.0613708,347.0613708,99.6091461181641,99.6091461181641,56.6860451001791,20.5541666546193,29.363071,0,0,0,40,4374,350.80595,99.6091461181641,,,,,,,,,,,,,0,,,,0,,,,,,347.0613708,,,,
,29207415.68,349.7845154,99.6091461181641,1.5599387254296E-5,4.26454647206312E-7,1,0.999253354069792,40.0298881530762,1.99523574189576,16.4899993687868,0.000176104267870469,2.9539925217015E-5,0.25,-8.20088718929519E-8,1.55718902360005E-5,-7.31815810310401E-8,349.7845154,349.7845154,99.6091461181641,99.6091461181641,56.7665528376599,20.5552847649784,28.983419,0,0,0,40,4369,350.747,99.6091461181641,,,,,,,,,,,,,0,,,,0,,,,,,349.7845154,,,,