File: data/looselyPackedNP/sc-ios-11/ppms/rawdata/ES_S14_HYST_30K_FC.DAT
[Header]
; VSM Data File (default extension .dat)
; Copyright (c) 2003-2013, Quantum Design, Inc. All rights reserved.
TITLE,
FILEOPENTIME,29432029.94,12/07/2018,11:34 pm
BYAPP,VSM,2.0,2.0
INFO,PPMS VSM Option Release 1.4.10 Build 1,APPNAME
INFO,Quantum Design Linear Motor Servo Controller,MOTOR_MODULE_NAME
INFO,3101-100 M1,MOTOR_HW_VERSION
INFO,MMC1014,MOTOR_SERIAL_NUMBER
INFO,SRV No X-over 01.03.11,MOTOR_SOFTWARE_VERSION
INFO,Quantum Design VSM Detection Module,VSM_MODULE_NAME
INFO,3101-150 F0,VSM_HW_VERSION
INFO,VSM707,VSM_SERIAL_NUMBER
INFO,VSM No X-over 01.02.05 May 20 2008 13:51:47,VSM_SOFTWARE_VERSION
INFO,704,PREAMP_SERIAL_NUMBER
INFO,822,COIL_SERIAL_NUMBER
INFO,0,MOMENT_UNITS
INFO,Iron Oxide Spheres,SAMPLE_MATERIAL
INFO,10 nm diameter, collaboration Mainz,SAMPLE_COMMENT
INFO,,SAMPLE_MASS
INFO,,SAMPLE_VOLUME
INFO,,SAMPLE_MOLECULAR_WEIGHT
INFO,,SAMPLE_SIZE
INFO,,SAMPLE_SHAPE
DATATYPE,COMMENT,1
DATATYPE,TIME,2
STARTUPAXIS,X,2
STARTUPAXIS,Y1,5
[Data]
Comment,Time Stamp (sec),Temperature (K),Magnetic Field (Oe),Moment (emu),M. Std. Err. (emu),Transport Action,Averaging Time (sec),Frequency (Hz),Peak Amplitude (mm),Center Position (mm),Coil Signal' (mV),Coil Signal" (mV),Range (mV),M. Quad. Signal (emu),M. Raw' (emu),M. Raw" (emu),Min. Temperature (K),Max. Temperature (K),Min. Field (Oe),Max. Field (Oe),Mass (grams),Motor Lag (deg),Pressure (Torr),VSM Status (code),Motor Status (code),Measure Status (code),Measure Count,PPMS Status (code),System Temp. (K),System Field (Oe),Sample Position (deg),Bridge 1 Resistance (ohms),Bridge 1 Excitation (에),Bridge 2 Resistance (ohms),Bridge 2 Excitation (에),Bridge 3 Resistance (ohms),Bridge 3 Excitation (에),Bridge 4 Resistance (ohms),Bridge 4 Excitation (에),Signal 1 Vin (V),Signal 2 Vin (V),Digital Inputs (code),Drive 1 Iout (mA),Drive 1 Ipower (W),Drive 2 Iout (mA),Drive 2 Ipower (W),Pressure (),Map 20 (),Map 21 (),Map 22 (),Map 23 (),Map 24 (),Map 25 (),Map 26 (),Map 27 (),Map 28 (),Map 29 ()
,29432097.8,30.0005856,-0.0837307516485453,8.48583827756098E-5,6.79212184189329E-7,1,0.999253354069792,40.0298881530762,1.99810789564083,17.1799995005131,0.000956609313666636,0.000157268945481614,0.25,-1.1419050770061E-6,8.44241214413634E-5,-6.7106582085829E-7,30.0005856,30.0005856,-0.121790185570717,-0.0456713177263737,55.4690494957366,20.4978492325604,16.834587,0,0,0,40,4417,29.99765,-0.0837307516485453,,,,,,,,,,,,,0,,,,0,,,,,,30.0005856,,,,
,29432133.875,30.0002861,410.145553588867,0.000103713160972555,3.38403379583237E-7,1,0.999253354069792,40.0298881530762,1.99785071819339,17.1799995005131,0.00116519847221029,0.000213700280189561,0.25,5.15772639407215E-7,0.000103173400069466,1.082659370062E-6,30.0002861,30.0002861,408.957397460937,411.333709716797,55.8770595827751,20.5025665562732,16.454937,0,0,0,40,4449,29.9984,410.145553588867,,,,,,,,,,,,,0,,,,0.00245,,,,,,30.0002861,,,,
,29432151.14,30.0006828,840.898071289063,0.000120301190185887,3.61200675757882E-7,1,0.999253354069792,40.0298881530762,1.99803811957299,17.1799995005131,0.00135218947681637,0.000245211305425359,0.25,3.56491091435709E-7,0.000119678718852226,1.01740037696192E-6,30.0006828,30.0006828,835.82568359375,845.970458984375,55.842667927929,20.505664739296,16.454937,0,0,0,40,4449,29.99705,840.898071289063,,,,,,,,,,,,,0,,,,-0.00245,,,,,,30.0006828,,,,
,29432170.295,30.0012379,1318.58428955078,0.000128057406264852,3.87976150163874E-7,1,0.999253354069792,40.0298881530762,1.99796754474068,17.1799995005131,0.00143922737353811,0.000261738486715811,0.25,4.4074041163359E-7,0.000127397517885183,1.14672605001716E-6,30.0012379,30.0012379,1314.57287597656,1322.595703125,56.0286955155059,20.5060110583026,16.075285,0,0,0,40,4449,29.99715,1318.58428955078,,,,,,,,,,,,,0,,,,0.00245,,,,,,30.0012379,,,,
,29432189.76,30.0012741,1803.99993896484,0.00013106019892877,3.4404840555804E-7,1,0.999253354069792,40.0298881530762,1.9979711855633,17.1799995005131,0.00147249359914603,0.000270821025686913,0.25,7.09161152887344E-7,0.000130386869297424,1.43351111505513E-6,30.0012741,30.0012741,1801.57446289062,1806.42541503906,56.0146262021598,20.5088663530558,16.075285,0,0,0,40,4449,29.9998,1803.99993896484,,,,,,,,,,,,,0,,,,-0.00245,,,,,,30.0012741,,,,
,29432207.025,29.9996548,2235.66003417969,0.000132156084918631,3.03383503239049E-7,1,0.999253354069792,40.0298881530762,1.99793188546644,17.1799995005131,0.00148529826314435,0.000270378476809028,0.25,4.71337684799266E-7,0.000131481733509853,1.20589897750914E-6,29.9996548,29.9996548,2233.37060546875,2237.94946289062,56.066213684429,20.5099613549904,16.454937,0,0,0,40,4449,30.0005,2235.66003417969,,,,,,,,,,,,,0,,,,-0.0049,,,,,,29.9996548,,,,
,29432224.54,30.0008049,2672.46752929687,0.000132578447098775,3.12725113225496E-7,1,0.999253354069792,40.0298881530762,1.99805860557695,17.1900000423193,0.00148990804714717,0.000272756953059935,0.25,6.02404909869576E-7,0.000131904616963789,1.34167450845997E-6,30.0008049,30.0008049,2667.7060546875,2677.22900390625,56.3218062102175,20.510552817577,15.695635,0,0,0,40,4449,29.9987,2672.46752929687,,,,,,,,,,,,,0,,,,-0.0049,,,,,,30.0008049,,,,
,29432242.805,29.9998951,3129.40808105469,0.00013205560819261,2.67003861713623E-7,1,0.999253354069792,40.0298881530762,1.99788641530924,17.1799995005131,0.0014841005129239,0.000270836631163739,0.25,5.22987666745563E-7,0.000131388575256881,1.26298843942499E-6,29.9998951,29.9998951,3127.12255859375,3131.69360351562,56.2835064127752,20.5135590714361,16.075285,0,0,0,40,4449,29.9991,3129.40808105469,,,,,,,,,,,,,0,,,,-0.0049,,,,,,29.9998951,,,,
,29432260.375,30.0003891,3567.05029296875,0.000130659635481965,3.86560200339552E-7,1,0.999253354069792,40.0298881530762,1.9978763452647,17.1799995005131,0.00146822404687046,0.000269220963501178,0.25,6.24730134103177E-7,0.000130002628502383,1.3594860524074E-6,30.0003891,30.0003891,3563.54150390625,3570.55908203125,56.0333852866213,20.5126213490192,16.075285,0,0,0,40,4449,29.9966,3567.05029296875,,,,,,,,,,,,,0,,,,0,,,,,,30.0003891,,,,
,29432278.68,30.0008183,4025.04333496094,0.0001294395168503,3.77406183891719E-7,1,0.999253354069792,40.0298881530762,1.99774196316451,17.1799995005131,0.00145472975072236,0.0002652096973167,0.25,4.83249664800869E-7,0.000128793291048197,1.21516125993422E-6,30.0008183,30.0008183,4020.08520507812,4030.00146484375,56.2209761312367,20.5161842402401,16.834587,0,0,0,40,4449,29.99835,4025.04333496094,,,,,,,,,,,,,0,,,,0,,,,,,30.0008183,,,,
,29432297.19,30.0005245,4487.25,0.000128056178612531,3.15951583915262E-7,1,0.999253354069792,40.0298881530762,1.99781651197376,17.1799995005131,0.00143869283440791,0.000265673828393543,0.25,7.66510638784934E-7,0.00012741912124557,1.49249929437714E-6,30.0005245,30.0005245,4482.10986328125,4492.39013671875,56.0912257970444,20.5182004503534,16.075285,0,0,0,40,4449,29.99555,4487.25,,,,,,,,,,,,,0,,,,-0.00245,,,,,,30.0005245,,,,
,29432316.125,30.0006828,4959.59814453125,0.000126282186425776,3.2948814333791E-7,1,0.999253354069792,40.0298881530762,1.99758487528343,17.1799995005131,0.00141870340209175,0.00026168433973411,0.25,7.26784057475518E-7,0.000125658227174557,1.44632991964956E-6,30.0006828,30.0006828,4957.32568359375,4961.87060546875,56.3350938950444,20.5107185127583,16.075285,0,0,0,40,4449,29.9987,4959.59814453125,,,,,,,,,,,,,0,,,,0,,,,,,30.0006828,,,,
,29432334.98,30.0036964,5429.90966796875,0.000124584824617124,3.77222592721465E-7,1,0.999253354069792,40.0298881530762,1.99750242613716,17.1799995005131,0.00139957566915771,0.000258447352186076,0.25,7.3868333317176E-7,0.000123973231486923,1.45188211522379E-6,30.0036964,30.0036964,5429.01708984375,5430.80224609375,56.1201460522559,20.5157068163523,16.454937,0,0,0,40,4449,30.0009,5429.90966796875,,,,,,,,,,,,,0,,,,0,,,,,,30.0036964,,,,
,29432352.575,30.0027828,5869.42651367187,0.000122725416209485,3.9928021473864E-7,1,0.999253354069792,40.0298881530762,1.99755933671683,17.1799995005131,0.00137844807157629,0.000256394700928586,0.25,8.83703254490169E-7,0.00012212583516843,1.58862885430405E-6,30.0027828,30.0027828,5863.2578125,5875.59521484375,56.2280107879098,20.5154738514868,16.454937,0,0,0,40,4449,29.9982,5869.42651367187,,,,,,,,,,,,,0,,,,0.00245,,,,,,30.0027828,,,,
,29432370.29,30.0014133,6311.69384765625,0.000121092756081296,4.55327468993917E-7,1,0.999253354069792,40.0298881530762,1.9977198514373,17.1799995005131,0.00136015134202578,0.000253608715731657,0.25,9.21945033696908E-7,0.000120504709582604,1.62040357788443E-6,30.0014133,30.0014133,6308.00048828125,6315.38720703125,56.2772533846213,20.5109476673169,16.075285,0,0,0,40,4449,29.99755,6311.69384765625,,,,,,,,,,,,,0,,,,0.00245,,,,,,30.0014133,,,,
,29432387.155,30.000185,6733.73266601562,0.000119387521018837,3.72372337881613E-7,1,0.999253354069792,40.0298881530762,1.99773909052678,17.1799995005131,0.00134201379730238,0.000244659108554245,0.25,4.26991231461254E-7,0.000118814218428214,1.1208800298701E-6,30.000185,30.000185,6730.16796875,6737.29736328125,56.3163348105829,20.5161201574748,16.454937,0,0,0,40,4449,29.99525,6733.73266601562,,,,,,,,,,,,,0,,,,-0.0049,,,,,,30.000185,,,,
,29432403.865,30.0002079,7152.525390625,0.000118042743509868,3.41850913600938E-7,1,0.999253354069792,40.0298881530762,1.99766183871553,17.1799995005131,0.00132643290431741,0.000244461085647239,0.25,6.46805337966241E-7,0.000117478253865945,1.33473064896317E-6,30.0002003,30.0002155,7150.05712890625,7154.99365234375,56.4234179177175,20.5168817463365,16.075285,0,0,0,40,4449,29.9947,7152.525390625,,,,,,,,,,,,,0,,,,0.00245,,,,,,30.0002079,,,,
,29432438.885,29.99940965,7090.14672851562,0.000117427842224396,3.83877944255004E-7,1,0.999253354069792,40.0298881530762,1.99778975932118,17.1799995005131,0.00131980465852146,0.000242046506197241,0.25,5.41149680671091E-7,0.000116866395247297,1.22558289551361E-6,29.9994087,29.9994106,7086.423828125,7093.86962890625,56.5273745107752,20.5203347378603,15.695635,0,0,0,40,4449,29.9985,7090.14672851562,,,,,,,,,,,,,0,,,,0,,,,,,29.99940965,,,,
,29432454.81,29.9990578,6692.37768554687,0.000119384922144647,3.91477549888043E-7,1,0.999253354069792,40.0298881530762,1.99773755537761,17.1799995005131,0.00134144460586278,0.00024764773931024,0.25,6.93527271377169E-7,0.000118809720040282,1.38583787602071E-6,29.9990578,29.9990578,6689.63671875,6695.11865234375,56.2663105853521,20.5170072800782,16.075285,0,0,0,40,4449,29.9956,6692.37768554687,,,,,,,,,,,,,0,,,,-0.0049,,,,,,29.9990578,,,,
,29432471.2,29.9997063,6283.06103515625,0.000120656593092749,4.00726077669271E-7,1,0.999253354069792,40.0298881530762,1.9980490861995,17.1799995005131,0.00135593422570693,0.000250091816573396,0.25,6.83933817492418E-7,0.000120071754174572,1.38078326788278E-6,29.9997063,29.9997063,6280.37548828125,6285.74658203125,56.6493085597752,20.5181244360225,16.075285,0,0,0,40,4449,29.99585,6283.06103515625,,,,,,,,,,,,,0,,,,0,,,,,,29.9997063,,,,
,29432487.48,29.9990177,5877.154296875,0.000122735059001486,3.9064498711184E-7,1,0.999253354069792,40.0298881530762,1.9976548957934,17.1799995005131,0.00137949193501244,0.000251542028124646,0.25,4.49441008045572E-7,0.000122137976990683,1.15655309055784E-6,29.9990177,29.9990177,5873.41748046875,5880.89111328125,56.2241026453136,20.5152276831761,16.075285,0,0,0,40,4449,29.9957,5877.154296875,,,,,,,,,,,,,0,,,,-0.00245,,,,,,29.9990177,,,,
,29432504.545,29.9997063,5449.89990234375,0.000124447452860808,3.87086577799511E-7,1,0.999253354069792,40.0298881530762,1.99743275374609,17.1799995005131,0.00139832558412921,0.000256259829362351,0.25,5.69319708417741E-7,0.000123837634967439,1.28265974468532E-6,29.9997063,29.9997063,5444.9375,5454.8623046875,56.4984542555637,20.5157518348781,16.075285,0,0,0,40,4449,29.99755,5449.89990234375,,,,,,,,,,,,,0,,,,-0.0049,,,,,,29.9997063,,,,
,29432521.58,29.9990387,5024.92700195313,0.000126279354310822,3.24691424329555E-7,1,0.999253354069792,40.0298881530762,1.99763460640587,17.1799995005131,0.00141890381985476,0.000260610924167812,0.25,6.30696471407448E-7,0.000125656543918968,1.3511867326038E-6,29.9990387,29.9990387,5020.2080078125,5029.64599609375,56.4382688595829,20.5191746438434,16.075285,0,0,0,40,4449,29.9997,5024.92700195313,,,,,,,,,,,,,0,,,,0.0049,,,,,,29.9990387,,,,
,29432538.925,29.9998226,4593.61938476562,0.000127640314152592,2.55770384694052E-7,1,0.999253354069792,40.0298881530762,1.99759677284124,17.1799995005131,0.00143468721619663,0.000260267473918151,0.25,3.61496058110368E-7,0.000127008567889288,1.08791554638719E-6,29.9998226,29.9998226,4588.58251953125,4598.65625,56.4953277414867,20.5208403264392,15.695635,0,0,0,40,4449,29.99755,4593.61938476562,,,,,,,,,,,,,0,,,,0,,,,,,29.9998226,,,,
,29432555.93,29.99946785,4167.39868164063,0.000129159437916041,3.3259318441336E-7,1,0.999253354069792,40.0298881530762,1.99740386504686,17.1799995005131,0.00145047845218257,0.000269540909484693,0.25,9.21004442960637E-7,0.000128513301654215,1.65016558312565E-6,29.9994278,29.9995079,4163.63330078125,4171.1640625,56.5820885071214,20.5199668346479,16.075285,0,0,0,40,4449,29.9961,4167.39868164063,,,,,,,,,,,,,0,,,,-0.00245,,,,,,29.99946785,,,,
,29432572.7,29.9996758,3748.02783203125,0.000130914700462169,2.81536513204098E-7,1,0.999253354069792,40.0298881530762,1.99743192324014,17.1799995005131,0.0014711020159273,0.00026797255723384,0.25,4.71693693201675E-7,0.000130258801524411,1.20996622320001E-6,29.9996758,29.9996758,3744.416015625,3751.6396484375,56.4515565444098,20.5243701677882,16.454937,0,0,0,40,4449,29.99595,3748.02783203125,,,,,,,,,,,,,0,,,,0,,,,,,29.9996758,,,,
,29432589.24,29.9997578,3335.70446777344,0.000131583059134158,3.36083401686947E-7,1,0.999253354069792,40.0298881530762,1.9971367955273,17.1799995005131,0.00147843498448572,0.000268902774316518,0.25,4.42123110515398E-7,0.000130920553275015,1.18135000148289E-6,29.9997578,29.9997578,3332.00512695313,3339.40380859375,56.3124266679867,20.5187063325672,16.454937,0,0,0,40,4449,29.99845,3335.70446777344,,,,,,,,,,,,,0,,,,-0.0049,,,,,,29.9997578,,,,
,29432605.595,29.9991283,2926.45056152344,0.000132414478641217,2.96434149012226E-7,1,0.999253354069792,40.0298881530762,1.99758465649382,17.1799995005131,0.00148773741715157,0.000272439840797913,0.25,6.06816345119238E-7,0.000131743459367437,1.34691308073204E-6,29.9991283,29.9991283,2922.66918945313,2930.23193359375,56.7063674416791,20.5315163801495,16.075285,0,0,0,40,4449,29.9959,2926.45056152344,,,,,,,,,,,,,0,,,,0,,,,,,29.9991283,,,,
,29432622.735,29.9995213,2499.18774414062,0.000132720035496152,3.94517390891865E-7,1,0.999253354069792,40.0298881530762,1.99757664784592,17.1799995005131,0.00149145797887732,0.000271200749765222,0.25,4.45806924865163E-7,0.000132044982104381,1.18543749013605E-6,29.9995213,29.9995213,2495.7314453125,2502.64404296875,56.9017745714868,20.5272174243513,15.695635,0,0,0,40,4449,29.9982,2499.18774414062,,,,,,,,,,,,,0,,,,-0.00245,,,,,,29.9995213,,,,
,29432639.425,29.9982777,2081.88903808594,0.000132483907945933,3.53016842789233E-7,1,0.999253354069792,40.0298881530762,1.9973836151778,17.1799995005131,0.00148857890703732,0.000270974135121095,0.25,4.73473967422308E-7,0.000131806640126106,1.20874701873635E-6,29.9982777,29.9982777,2075.9267578125,2087.85131835938,56.6047557341791,20.5218291404215,16.075285,0,0,0,40,4449,29.99615,2081.88903808594,,,,,,,,,,,,,0,,,,-0.00245,,,,,,29.9982777,,,,
,29432656.345,29.9996281,1658.51525878906,0.000131220485075718,3.04196391171928E-7,1,0.999253354069792,40.0298881530762,1.99744191403862,17.1799995005131,0.00147481993101794,0.000265977464936445,0.25,2.57009173015666E-7,0.000130547790375875,9.83608864743867E-7,29.9996281,29.9996281,1653.51245117187,1663.51806640625,56.432015831429,20.5218877705502,16.075285,0,0,0,40,4449,29.99935,1658.51525878906,,,,,,,,,,,,,0,,,,0.00245,,,,,,29.9996281,,,,
,29432673.695,29.9992085,1225.22613525391,0.000128514383295514,3.15318295535288E-7,1,0.999253354069792,40.0298881530762,1.99758110582485,17.1799995005131,0.00144391877826989,0.000263578585602724,0.25,5.27927399089263E-7,0.000127851009064752,1.2353936933942E-6,29.9992085,29.9992085,1221.69189453125,1228.76037597656,56.7165286124291,20.5234729047283,16.075285,0,0,0,40,4449,29.9944,1225.22613525391,,,,,,,,,,,,,0,,,,-0.0049,,,,,,29.9992085,,,,
,29432689.97,29.9982319,818.683868408203,0.000122454061477714,3.72505863335249E-7,1,0.999253354069792,40.0298881530762,1.9974539665667,17.1799995005131,0.00137554988645946,0.000252068127304288,0.25,5.88765533169945E-7,0.000121819089712456,1.26022852840153E-6,29.9982319,29.9982319,814.199035644531,823.168701171875,56.3569794935829,20.5248107550881,15.695635,0,0,0,40,4449,29.9978,818.683868408203,,,,,,,,,,,,,0,,,,0,,,,,,29.9982319,,,,
,29432706.74,29.9997082,398.523162841797,0.000109063364767176,2.89398695456729E-7,1,0.999253354069792,40.0298881530762,1.99731372768254,17.1799995005131,0.00122486411815492,0.000225383870696845,0.25,6.06245916532297E-7,0.000108495344519426,1.20198595694895E-6,29.9997082,29.9997082,396.134155273438,400.912170410156,56.4187281466021,20.5235453912017,15.695635,0,0,0,40,4449,29.99735,398.523162841797,,,,,,,,,,,,,0,,,,-0.0049,,,,,,29.9997082,,,,
,29432723.93,29.9985676,-29.6801347732544,6.83958116482833E-5,3.51267181915222E-7,1,0.999253354069792,40.0298881530762,1.99750878368351,17.1799995005131,0.000768492611708523,0.000139703925841053,0.25,2.34214801212512E-7,6.80395265432034E-5,6.07767310036793E-7,29.9985676,29.9985676,-33.630989074707,-25.7292804718018,56.3694855498906,20.52109130514,16.454937,0,0,0,40,4449,29.99935,-29.6801347732544,,,,,,,,,,,,,0,,,,-0.00245,,,,,,29.9985676,,,,
,29432741.035,29.9986744,-457.07698059082,-4.37863694926874E-5,4.12258272125825E-7,1,0.999253354069792,40.0298881530762,1.99742824821976,17.1799995005131,-0.000491304047565866,-9.31750612172134E-5,0.25,-4.81969488530382E-7,-4.35571411061922E-5,-7.20029586672393E-7,29.9986744,29.9986744,-457.964904785156,-456.189056396484,56.5242479966983,20.5232302792869,15.695635,0,0,0,40,4449,30.002,-457.07698059082,,,,,,,,,,,,,0,,,,0.0049,,,,,,29.9986744,,,,
,29432758.22,29.9993896,-886.189514160156,-0.000101292510275509,3.7320756989747E-7,1,0.999253354069792,40.0298881530762,1.99757884444962,17.1799995005131,-0.00113713583189421,-0.000212860866151308,0.25,-8.72737982953715E-7,-0.000100765459502721,-1.4264656857183E-6,29.9993896,29.9993896,-892.419555664062,-879.95947265625,56.7032409276022,20.5272686805123,16.075285,0,0,0,40,4449,29.99705,-886.189514160156,,,,,,,,,,,,,0,,,,-0.00245,,,,,,29.9993896,,,,
,29432774.89,29.9992008,-1301.27880859375,-0.00011689456188827,3.88657526920241E-7,1,0.999253354069792,40.0298881530762,1.99735808213655,17.1799995005131,-0.00131269889321477,-0.000242704079972118,0.25,-7.4495725969859E-7,-0.000116290217016538,-1.38756424458267E-6,29.9992008,29.9992008,-1303.80688476562,-1298.75073242188,56.4296709458714,20.5239107273115,15.695635,0,0,0,40,4449,29.9986,-1301.27880859375,,,,,,,,,,,,,0,,,,0.0049,,,,,,29.9992008,,,,
,29432791.74,29.9990826,-1723.40502929687,-0.000124298769842027,2.88975968204476E-7,1,0.999253354069792,40.0298881530762,1.99746363430201,17.1799995005131,-0.00139517222090192,-0.000262447156422918,0.25,-1.17665601494167E-6,-0.000123656771512947,-1.86050896934076E-6,29.9990826,29.9990826,-1726.01550292969,-1720.79455566406,56.7102755842752,20.5224012165837,16.454937,0,0,0,40,4449,29.9957,-1723.40502929687,,,,,,,,,,,,,0,,,,0,,,,,,29.9990826,,,,
,29432807.89,29.9985809,-2125.17663574219,-0.000127051954526029,2.77716772167063E-7,1,0.999253354069792,40.0298881530762,1.99754898596747,17.1799995005131,-0.00142640791473385,-0.000266917911949086,0.25,-1.07925670629066E-6,-0.000126399280749309,-1.78147611499518E-6,29.9985809,29.9985809,-2127.6611328125,-2122.69213867187,56.7642079521022,20.5285112625056,16.075285,0,0,0,40,4449,29.99565,-2125.17663574219,,,,,,,,,,,,,0,,,,0,,,,,,29.9985809,,,,
,29432824.2,29.9996834,-2533.59118652344,-0.000128916052628153,3.72750333137868E-7,1,0.999253354069792,40.0298881530762,1.99743617983977,17.1799995005131,-0.001447588399777,-0.00026917070664815,0.25,-9.45118176235366E-7,-0.000128257732818355,-1.66117589112513E-6,29.9996834,29.9996834,-2537.17602539062,-2530.00634765625,56.6899532427752,20.5281583146332,15.695635,0,0,0,40,4449,29.99715,-2533.59118652344,,,,,,,,,,,,,0,,,,0,,,,,,29.9996834,,,,
,29432841.64,29.9992609,-2968.93298339844,-0.000129349673340164,3.19177164650841E-7,1,0.999253354069792,40.0298881530762,1.99743538241628,17.1799995005131,-0.00145166375392547,-0.000274749078576835,0.25,-1.3602275980649E-6,-0.000128690279388368,-2.07968207408742E-6,29.9989777,29.9995441,-2973.84204101562,-2964.02392578125,56.7259081546598,20.5299889090378,16.075285,0,0,0,40,4449,30.0004,-2968.93298339844,,,,,,,,,,,,,0,,,,0,,,,,,29.9992609,,,,
,29432858.625,29.9992218,-3392.8564453125,-0.000129044060383483,2.92910668772701E-7,1,0.999253354069792,40.0298881530762,1.99745687539461,17.1799995005131,-0.00144904028662743,-0.000269889568193227,0.25,-9.78707207512383E-7,-0.000128391752164138,-1.70136080810545E-6,29.9992218,29.9992218,-3399.03759765625,-3386.67529296875,56.9299131981791,20.5271108392944,16.075285,0,0,0,40,4449,29.9998,-3392.8564453125,,,,,,,,,,,,,0,,,,0,,,,,,29.9992218,,,,
,29432876.025,29.9992504,-3828.30895996094,-0.000128400809253171,3.25120198262433E-7,1,0.999253354069792,40.0298881530762,1.99724408517217,17.1799995005131,-0.00144146975178534,-0.000269877883369095,0.25,-1.09111085438913E-6,-0.000127754672910321,-1.81269881627107E-6,29.9992504,29.9992504,-3829.96826171875,-3826.64965820313,56.6391473890252,20.5284598286861,16.075285,0,0,0,40,4449,29.9998,-3828.30895996094,,,,,,,,,,,,,0,,,,0,,,,,,29.9992504,,,,
,29432894.14,29.9992409,-4281.82934570313,-0.000127160217139211,3.36123223910861E-7,1,0.999253354069792,40.0298881530762,1.99740523839616,17.1799995005131,-0.00142803393781915,-0.000265401181202362,0.25,-9.08569617195591E-7,-0.000126525081503986,-1.62730100705728E-6,29.9992409,29.9992409,-4286.67822265625,-4276.98046875,56.4109118614098,20.5318043405875,16.454937,0,0,0,40,4449,29.99915,-4281.82934570313,,,,,,,,,,,,,0,,,,-0.0049,,,,,,29.9992409,,,,
,29432911.815,29.9994888,-4723.0361328125,-0.000126021160662154,2.82369393689266E-7,1,0.999253354069792,40.0298881530762,1.99736927272999,17.1799995005131,-0.00141464899668683,-0.000266451326931899,0.25,-1.20179350710951E-6,-0.000125393731343705,-1.91578787256557E-6,29.9994888,29.9994888,-4724.5751953125,-4721.4970703125,56.8408075469868,20.5280645264119,16.075285,0,0,0,40,4449,29.9989,-4723.0361328125,,,,,,,,,,,,,0,,,,-0.0049,,,,,,29.9994888,,,,
,29432929.08,29.9991493,-5155.76098632812,-0.000124432984908474,4.00469949089072E-7,1,0.999253354069792,40.0298881530762,1.99743575526904,17.1799995005131,-0.0013973472078523,-0.000260645798900926,0.25,-9.6444699831062E-7,-0.000123818445872996,-1.67367147322392E-6,29.998991,29.9993076,-5159.33056640625,-5152.19140625,56.6336759893906,20.5297932064388,16.454937,0,0,0,40,4449,30.00005,-5155.76098632812,,,,,,,,,,,,,0,,,,-0.00245,,,,,,29.9991493,,,,
,29432946.39,29.9997635,-5587.48828125,-0.000122812311642588,3.19158757452891E-7,1,0.999253354069792,40.0298881530762,1.99726545497829,17.1799995005131,-0.00137888117910152,-0.000258337088287616,0.25,-1.04656461776059E-6,-0.000122208947817208,-1.74919507210453E-6,29.9997635,29.9997635,-5591.13232421875,-5583.84423828125,56.7360693254098,20.5271420877681,15.695635,0,0,0,40,4449,30.0006,-5587.48828125,,,,,,,,,,,,,0,,,,0,,,,,,29.9997635,,,,
,29432963.735,29.99897,-6021.39453125,-0.000121285980421775,3.60542326550585E-7,1,0.999253354069792,40.0298881530762,1.99746889111185,17.1799995005131,-0.0013617340761302,-0.00025619435471096,0.25,-1.12255736334006E-6,-0.000120693334189232,-1.81911373884548E-6,29.99897,29.99897,-6023.45751953125,-6019.33154296875,56.6962062709291,20.5312099961603,15.695635,0,0,0,40,4449,29.9998,-6021.39453125,,,,,,,,,,,,,0,,,,0,,,,,,29.99897,,,,
,29432983.06,30.0001755,-6503.896484375,-0.000119418241523487,4.16159583939491E-7,1,0.999253354069792,40.0298881530762,1.99740553837679,17.1799995005131,-0.00134076817529252,-0.000252263247173694,0.25,-1.10307447022077E-6,-0.000118838878086041,-1.79230880919182E-6,30.0001755,30.0001755,-6506.501953125,-6501.291015625,57.007294421583,20.5244161755712,16.454937,0,0,0,40,4449,29.99805,-6503.896484375,,,,,,,,,,,,,0,,,,-0.0049,,,,,,30.0001755,,,,
,29433000.52,29.9996052,-6940.8251953125,-0.000117343202970777,3.34593895666567E-7,1,0.999253354069792,40.0298881530762,1.99745848122339,17.1799995005131,-0.00131748153926412,-0.00024826120581655,0.25,-1.11350409073707E-6,-0.000116777534344124,-1.79369627928521E-6,29.9996052,29.9996052,-6948.39404296875,-6933.25634765625,56.4875114562944,20.5278384538166,16.454937,0,0,0,40,4449,30.0004,-6940.8251953125,,,,,,,,,,,,,0,,,,0,,,,,,29.9996052,,,,
,29433035.65,29.9995022,-7275.267578125,-0.000115900906630692,4.23024574966659E-7,1,0.999253354069792,40.0298881530762,1.99742833432058,17.1799995005131,-0.00130148091634762,-0.000244208974530915,0.25,-1.00834749409138E-6,-0.000115345584468375,-1.68290321088896E-6,29.9995022,29.9995022,-7279.56640625,-7270.96875,56.861911517006,20.5292540108843,16.454937,0,0,0,40,4449,29.99825,-7275.267578125,,,,,,,,,,,,,0,,,,-0.00245,,,,,,29.9995022,,,,
,29433054.13,29.9994831,-6815.56469726563,-0.000118673689217133,3.40534651537039E-7,1,0.999253354069792,40.0298881530762,1.99762541905486,17.1799995005131,-0.00133326573481069,-0.000246882311852611,0.25,-7.52568752389748E-7,-0.000118102684747786,-1.44136851240925E-6,29.9994831,29.9994831,-6819.68408203125,-6811.4453125,56.9627415959868,20.5361097666199,16.075285,0,0,0,40,4449,30.00015,-6815.56469726563,,,,,,,,,,,,,0,,,,0.00245,,,,,,29.9994831,,,,
,29433072.02,29.9984703,-6370.12866210937,-0.000120312169146632,3.86075772965392E-7,1,0.999253354069792,40.0298881530762,1.99756246223993,17.1799995005131,-0.00135153681644887,-0.00025056360075169,0.25,-7.91750642243949E-7,-0.000119729180509792,-1.48674665441911E-6,29.9984703,29.9984703,-6372.666015625,-6367.59130859375,57.044812590506,20.5376150696751,15.695635,0,0,0,40,4449,29.99995,-6370.12866210937,,,,,,,,,,,,,0,,,,-0.00245,,,,,,29.9984703,,,,
,29433090.04,29.9985113,-5919.64575195313,-0.000122195362096581,2.85140953080067E-7,1,0.999253354069792,40.0298881530762,1.9976669157735,17.1799995005131,-0.00137260779454204,-0.000255090959400171,0.25,-8.60808123622593E-7,-0.000121598935336883,-1.56315279592702E-6,29.9983978,29.9986248,-5923.4033203125,-5915.88818359375,56.8329912617945,20.5353590551985,16.075285,0,0,0,40,4449,29.9991,-5919.64575195313,,,,,,,,,,,,,0,,,,0,,,,,,29.9985113,,,,
,29433108.69,29.9986038,-5454.52880859375,-0.000123863005921574,3.22638141840216E-7,1,0.999253354069792,40.0298881530762,1.99736904148069,17.1799995005131,-0.00139161962713845,-0.00025559386376351,0.25,-6.15071017316941E-7,-0.000123255838974027,-1.32487866911037E-6,29.9986038,29.9986038,-5459.470703125,-5449.5869140625,56.902556200006,20.5363049229086,16.075285,0,0,0,40,4449,29.9993,-5454.52880859375,,,,,,,,,,,,,0,,,,0.00245,,,,,,29.9986038,,,,
,29433127.08,29.9992313,-4996.36303710937,-0.000125655959857701,3.56626773392766E-7,1,0.999253354069792,40.0298881530762,1.99732438401437,17.1799995005131,-0.00141165117904795,-0.000259484399047495,0.25,-6.45522241367503E-7,-0.00012503583502336,-1.36212798977795E-6,29.9992313,29.9992313,-5000.15478515625,-4992.5712890625,57.1370447557753,20.5318221706613,16.075285,0,0,0,40,4449,29.997,-4996.36303710937,,,,,,,,,,,,,0,,,,0.00245,,,,,,29.9992313,,,,
,29433145.85,29.9998856,-4526.88427734375,-0.000127110401689166,3.60953666931061E-7,1,0.999253354069792,40.0298881530762,1.99738068056563,17.1799995005131,-0.00142773920087286,-0.000263853942682069,0.25,-7.77986613669937E-7,-0.000126478340419909,-1.49885870324682E-6,29.9998856,29.9998856,-4530.51220703125,-4523.25634765625,56.482821685179,20.5333845539258,16.075285,0,0,0,40,4449,29.99895,-4526.88427734375,,,,,,,,,,,,,0,,,,0,,,,,,29.9998856,,,,
,29433164.29,29.999794,-4067.359375,-0.000128232366337491,3.72459718373905E-7,1,0.999253354069792,40.0298881530762,1.99749346831234,17.1799995005131,-0.00144035682678449,-0.000266288521061111,0.25,-7.97019759694143E-7,-0.000127590737579394,-1.52084576672453E-6,29.999794,29.999794,-4073.54516601562,-4061.17358398438,57.014329078256,20.5375568031157,15.315984,0,0,0,40,4449,29.9996,-4067.359375,,,,,,,,,,,,,0,,,,-0.0049,,,,,,29.999794,,,,
,29433183.15,29.9992752,-3596.40637207031,-0.000129219780360429,3.6503620674456E-7,1,0.999253354069792,40.0298881530762,1.99727183286944,17.1799995005131,-0.00145075070596489,-0.0002710974591054,0.25,-1.0551359722906E-6,-0.000128567845644322,-1.77987027480551E-6,29.9992752,29.9992752,-3601.35009765625,-3591.46264648438,57.0518472471791,20.5322626116838,16.075285,0,0,0,40,4449,30.0006,-3596.40637207031,,,,,,,,,,,,,0,,,,0,,,,,,29.9992752,,,,
,29433202.575,29.9995556,-3110.86547851562,-0.000130271455461104,3.23058543672724E-7,1,0.999253354069792,40.0298881530762,1.99742552872708,17.1799995005131,-0.00146298254125159,-0.000271286245565483,0.25,-8.8666817609729E-7,-0.000129611262700966,-1.61472998853744E-6,29.9995556,29.9995556,-3114.6943359375,-3107.03662109375,56.7563916669098,20.5386904028038,16.454937,0,0,0,40,4449,30.0034,-3110.86547851562,,,,,,,,,,,,,0,,,,-0.0049,,,,,,29.9995556,,,,
,29433221.23,29.9995193,-2644.98388671875,-0.000130375625854363,3.17558483473891E-7,1,0.999253354069792,40.0298881530762,1.99750970353704,17.1799995005131,-0.00146473763993492,-0.00026831742075651,0.25,-6.07056683496169E-7,-0.000129712731549047,-1.33381071938391E-6,29.9995193,29.9995193,-2647.36743164062,-2642.60034179687,56.8814522299868,20.5380396005215,16.075285,0,0,0,40,4449,30.0012,-2644.98388671875,,,,,,,,,,,,,0,,,,0,,,,,,29.9995193,,,,
,29433238.715,29.9994698,-2207.32824707031,-0.000129029380356662,3.5677513836946E-7,1,0.999253354069792,40.0298881530762,1.99733401243346,17.1799995005131,-0.00144896986242655,-0.000268226590502192,0.25,-8.44718753177211E-7,-0.000128368605453045,-1.55973680652343E-6,29.9994698,29.9994698,-2212.78198242187,-2201.87451171875,56.8001628639868,20.5396173642246,16.075285,0,0,0,40,4449,29.99895,-2207.32824707031,,,,,,,,,,,,,0,,,,0,,,,,,29.9994698,,,,
,29433256.96,29.9987164,-1751.58160400391,-0.000126179538391814,2.97613744051904E-7,1,0.999253354069792,40.0298881530762,1.99738697075237,17.1900000423193,-0.00141663094603516,-0.000264181739524376,0.25,-9.96112652780474E-7,-0.000125529192912217,-1.6915682687263E-6,29.9987164,29.9987164,-1755.25268554687,-1747.91052246094,56.7071490701983,20.5374633643243,16.075285,0,0,0,40,4449,30.0007,-1751.58160400391,,,,,,,,,,,,,0,,,,0.0049,,,,,,29.9987164,,,,
,29433276.18,29.9988937,-1269.95172119141,-0.000120381690405307,3.26316892150668E-7,1,0.999253354069792,40.0298881530762,1.99727731909586,17.1799995005131,-0.00135162241179576,-0.000250954360317526,0.25,-8.58085541817404E-7,-0.000119758632108409,-1.51922879930268E-6,29.9988937,29.9988937,-1274.75231933594,-1265.15112304688,56.5531682519098,20.5311227607314,15.315984,0,0,0,40,4449,29.9995,-1269.95172119141,,,,,,,,,,,,,0,,,,0,,,,,,29.9988937,,,,
,29433294.895,29.99963475,-801.684661865234,-0.000106838898748657,3.10537886703495E-7,1,0.999253354069792,40.0298881530762,1.99737114756296,17.1799995005131,-0.00119837817133352,-0.000229540006092367,0.25,-1.36975763251781E-6,-0.000106280154722959,-1.95115547149091E-6,29.9995804,29.9996891,-805.490783691406,-797.878540039063,56.7798405224868,20.5375676778495,16.075285,0,0,0,40,4449,30.0027,-801.684661865234,,,,,,,,,,,,,0,,,,0.0049,,,,,,29.99963475,,,,
,29433314.49,29.9993458,-313.979766845703,-6.7831081739773E-5,3.45049270981618E-7,1,0.999253354069792,40.0298881530762,1.99726715538973,17.1799995005131,-0.000761297008866621,-0.000142855061771068,0.25,-6.15881652632401E-7,-6.74763054532984E-5,-9.84984231860418E-7,29.9993172,29.9993744,-319.97216796875,-307.987365722656,57.1651833824676,20.53453679657,15.695635,0,0,0,40,4449,30.0024,-313.979766845703,,,,,,,,,,,,,0,,,,-0.00245,,,,,,29.9993458,,,,
,29433334.245,29.99861815,180.483734130859,4.99893660818937E-5,3.94500083865399E-7,1,0.999253354069792,40.0298881530762,1.99730479666714,17.1799995005131,0.000561456337088121,0.000103053608701189,0.25,2.55963434707809E-7,4.97287560361109E-5,5.28785583535449E-7,29.9986115,29.9986248,174.199417114258,186.768051147461,56.9697762526599,20.5388814718183,15.695635,0,0,0,40,4449,30.004,180.483734130859,,,,,,,,,,,,,0,,,,0.00245,,,,,,29.99861815,,,,
,29433352.78,29.99817565,643.214660644531,0.000106155059230376,3.07854666001013E-7,1,0.999253354069792,40.0298881530762,1.99731087986494,17.1799995005131,0.00119188272435414,0.000221231134600789,0.25,7.54020110842616E-7,0.000105602468829916,1.33412014581891E-6,29.9980946,29.9982567,640.723449707031,645.705871582031,56.4445218877367,20.5410236340328,15.695635,0,0,0,40,4449,30.0031,643.214660644531,,,,,,,,,,,,,0,,,,0.0049,,,,,,29.99817565,,,,
,29433372.54,29.9992447,1136.53607177734,0.000123324290753946,2.4380439896677E-7,1,0.999253354069792,40.0298881530762,1.99761404162258,17.1799995005131,0.001385206949889,0.000255267748654627,0.25,7.14296706975279E-7,0.000122686123562275,1.39172633436671E-6,29.9992447,29.9992447,1133.37341308594,1139.69873046875,56.6774471864675,20.5391566542049,16.075285,0,0,0,40,4449,30.00305,1136.53607177734,,,,,,,,,,,,,0,,,,0.00245,,,,,,29.9992447,,,,
,29433391.775,29.9989223,1615.64880371094,0.000129259970698665,3.54151352976829E-7,1,0.999253354069792,40.0298881530762,1.99742436540816,17.1799995005131,0.00145152037494674,0.000269008839855405,0.25,8.76720704002283E-7,0.000128593605760568,1.58903677712101E-6,29.9989223,29.9989223,1611.82177734375,1619.47583007813,57.0620084179291,20.5372660025244,15.695635,0,0,0,40,4449,30.002,1615.64880371094,,,,,,,,,,,,,0,,,,0.00245,,,,,,29.9989223,,,,
,29433409.82,29.9982224,2067.41284179687,0.000130834237754216,3.45347262962529E-7,1,0.999253354069792,40.0298881530762,1.9973250987382,17.1799995005131,0.00146969023010395,0.000269341493101326,0.25,6.23150284434619E-7,0.000130164529530875,1.34846895294539E-6,29.9982224,29.9982224,2065.97021484375,2068.85546875,56.8376810329099,20.5340803442663,16.075285,0,0,0,40,4449,30.003,2067.41284179687,,,,,,,,,,,,,0,,,,0,,,,,,29.9982224,,,,
,29433428.35,30.0001545,2529.02709960938,0.000131504907697277,3.28910758252264E-7,1,0.999253354069792,40.0298881530762,1.99738283195057,17.1799995005131,0.00147665159082598,0.000274397350977869,0.25,9.48807596531855E-7,0.000130833465091917,1.67933338520515E-6,30.0001545,30.0001545,2522.65576171875,2535.3984375,56.5852150211983,20.53826738858,15.695635,0,0,0,40,4449,30.0004,2529.02709960938,,,,,,,,,,,,,0,,,,-0.00245,,,,,,30.0001545,,,,
,29433447.11,29.9984341,2996.96716308594,0.000131363346950853,3.31293985634804E-7,1,0.999253354069792,40.0298881530762,1.99731945972797,17.1799995005131,0.00147621505359538,0.000267623325261531,0.25,3.68352484173226E-7,0.000130699586585247,1.10429516870563E-6,29.9984341,29.9984341,2992.06030273438,3001.8740234375,56.9439825115252,20.5370604919839,15.695635,0,0,0,40,4449,29.9992,2996.96716308594,,,,,,,,,,,,,0,,,,0,,,,,,29.9984341,,,,
,29433465.475,29.9990559,3456.77526855469,0.000130655263310963,3.72584021181345E-7,1,0.999253354069792,40.0298881530762,1.99729946056659,17.1799995005131,0.00146733302266362,0.000271535585781471,0.25,8.38820521571239E-7,0.000129996261394834,1.57177672618274E-6,29.9990559,29.9990559,3454.26245117188,3459.2880859375,56.7931282073137,20.5369230171492,16.075285,0,0,0,40,4449,30.0041,3456.77526855469,,,,,,,,,,,,,0,,,,-0.0049,,,,,,29.9990559,,,,
,29433483.6,30.0000744,3910.93969726562,0.000129423978352222,3.11296945196521E-7,1,0.999253354069792,40.0298881530762,1.99726325964483,17.1799995005131,0.00145438394369271,0.000264152525679827,0.25,3.98336366375229E-7,0.000128777399664235,1.12980113487766E-6,30.0000744,30.0000744,3909.59838867188,3912.28100585937,56.9791557948906,20.5411009252109,15.695635,0,0,0,40,4449,30.0023,3910.93969726562,,,,,,,,,,,,,0,,,,-0.0049,,,,,,30.0000744,,,,
,29433502.82,29.9993629,4390.8505859375,0.000128194694776961,3.96390412878299E-7,1,0.999253354069792,40.0298881530762,1.99728311864382,17.1799995005131,0.00143918222135728,0.000269768110800436,0.25,1.1126711273861E-6,0.000127554273485829,1.83713313175789E-6,29.9993629,29.9993629,4387.06494140625,4394.63623046875,56.3593243791406,20.5398630995652,15.695635,0,0,0,40,4449,30.0039,4390.8505859375,,,,,,,,,,,,,0,,,,0,,,,,,29.9993629,,,,
,29433520.89,29.9991131,4842.482421875,0.000126417581043598,3.91658743940733E-7,1,0.999253354069792,40.0298881530762,1.99724003224224,17.1799995005131,0.00142027062564248,0.000260289372874365,0.25,5.83366094503861E-7,0.000125792817837319,1.30358374871952E-6,29.9991131,29.9991131,4839.978515625,4844.986328125,56.7642079521022,20.5350528385455,15.315984,0,0,0,40,4449,30.0026,4842.482421875,,,,,,,,,,,,,0,,,,0,,,,,,29.9991131,,,,
,29433539.375,30.0005474,5304.61962890625,0.000125074107442508,3.95162878158734E-7,1,0.999253354069792,40.0298881530762,1.99728520444376,17.1799995005131,0.00140554077637799,0.000255924430004413,0.25,4.30420587963004E-7,0.000124460838306679,1.14705414779649E-6,30.0005474,30.0005474,5299.86328125,5309.3759765625,56.7079306987175,20.5378686711912,15.315984,0,0,0,40,4449,30.00325,5304.61962890625,,,,,,,,,,,,,0,,,,-0.00245,,,,,,30.0005474,,,,
,29433557.83,29.9969711,5765.353515625,0.000122840751657285,3.66295530220663E-7,1,0.999253354069792,40.0298881530762,1.99727934690481,17.1799995005131,0.00138008351551823,0.000253606278474004,0.25,6.19063925118258E-7,0.000122241267839586,1.32521699448549E-6,29.9969711,29.9969711,5761.736328125,5768.970703125,56.4492116588521,20.5331988884644,15.695635,0,0,0,40,4449,30.0007,5765.353515625,,,,,,,,,,,,,0,,,,0,,,,,,29.9969711,,,,
,29433575.03,29.9988556,6195.646484375,0.000121603218970398,3.46217349305176E-7,1,0.999253354069792,40.0298881530762,1.99732649240472,17.1799995005131,0.00136743310244387,0.000244463441619006,0.25,2.26931514817012E-8,0.000121017008549995,7.27694677300132E-7,29.9988556,29.9988556,6194.474609375,6196.818359375,57.2855541744291,20.5418290376029,15.695635,0,0,0,40,4449,30.0047,6195.646484375,,,,,,,,,,,,,0,,,,0,,,,,,29.9988556,,,,
,29433592.965,29.9985199,6643.81005859375,0.000119731156715189,3.8710388830875E-7,1,0.999253354069792,40.0298881530762,1.99724687820101,17.1799995005131,0.0013453751888123,0.000246294671045598,0.25,5.16860952380246E-7,0.000119154985523192,1.21175946473788E-6,29.9985199,29.9985199,6639.08154296875,6648.53857421875,57.4176493941791,20.5377802657224,16.075285,0,0,0,40,4449,30.00195,6643.81005859375,,,,,,,,,,,,,0,,,,0,,,,,,29.9985199,,,,
,29433612.78,29.9992714,7138.626953125,0.00011725183693273,3.60961945530449E-7,1,0.999253354069792,40.0298881530762,1.99734657496358,17.1799995005131,0.00131738992383349,0.000242545784179138,0.25,6.21079396068676E-7,0.000116691235532853,1.30448133955566E-6,29.9992714,29.9992714,7136.03369140625,7141.22021484375,56.5187765970637,20.5390879531977,16.075285,0,0,0,40,4449,30.0024,7138.626953125,,,,,,,,,,,,,0,,,,0,,,,,,29.9992714,,,,
,29433647.305,29.9980488,7070.35693359375,0.000117842216859689,3.8571539509481E-7,1,0.999253354069792,40.0298881530762,1.99735569039537,17.1799995005131,0.00132446788646982,0.000241270836525794,0.25,4.02747408569587E-7,0.000117279477642699,1.09015759325585E-6,29.9980488,29.9980488,7064.033203125,7076.6806640625,56.7524835243137,20.539327771818,15.695635,0,0,0,40,4449,30.0016,7070.35693359375,,,,,,,,,,,,,0,,,,0.00245,,,,,,29.9980488,,,,
,29433665.01,29.9995823,6629.09106445313,0.000119847976148253,4.01090145777966E-7,1,0.999253354069792,40.0298881530762,1.99729139019347,17.1799995005131,0.0013466303490071,0.000247018165135245,0.25,5.59930447452717E-7,0.000119270928651662,1.25525064509039E-6,29.9995823,29.9995823,6625.318359375,6632.86376953125,57.0119841926983,20.5356713622903,15.695635,0,0,0,40,4449,30.0067,6629.09106445313,,,,,,,,,,,,,0,,,,0,,,,,,29.9995823,,,,
,29433683.59,29.9995937,6164.90502929688,0.000121536719478122,3.79973714865403E-7,1,0.999253354069792,40.0298881530762,1.9973232376336,17.1799995005131,0.00136621503788591,0.000246934698970115,0.25,2.54602290760092E-7,0.000120949238706163,9.57901963845389E-7,29.9995937,29.9995937,6161.13671875,6168.67333984375,56.892395029256,20.5361507771731,15.315984,0,0,0,40,4449,30.00655,6164.90502929688,,,,,,,,,,,,,0,,,,-0.0049,,,,,,29.9995937,,,,
,29433702.53,29.9987755,5693.08642578125,0.000123000409425643,4.0073312065162E-7,1,0.999253354069792,40.0298881530762,1.99743515164259,17.1799995005131,0.00138280373923014,0.000249302400127142,0.25,2.0676467682107E-7,0.00012240192637178,9.15346296572806E-7,29.9987755,29.9987755,5689.5341796875,5696.638671875,56.6047557341791,20.5371756542444,15.315984,0,0,0,40,4449,30.0029,5693.08642578125,,,,,,,,,,,,,0,,,,-0.0049,,,,,,29.9987755,,,,
,29433719.845,29.9992466,5260.21704101562,0.000125157116268869,3.22540073687889E-7,1,0.999253354069792,40.0298881530762,1.99723307775928,17.1799995005131,0.00140648232068572,0.000255817386226603,0.25,4.07039762576543E-7,0.000124543188341538,1.12394214086779E-6,29.9992466,29.9992466,5255.3740234375,5265.06005859375,56.4562463155252,20.5366942331747,15.695635,0,0,0,40,4449,30.00325,5260.21704101562,,,,,,,,,,,,,0,,,,0.0049,,,,,,29.9992466,,,,
,29433738.595,29.999136,4792.29223632812,0.000126995795824439,3.92307928891928E-7,1,0.999253354069792,40.0298881530762,1.99718966121748,17.1799995005131,0.00142619104511474,0.000264479430157076,0.25,8.53786223366519E-7,0.000126366234362162,1.57563628334912E-6,29.999136,29.999136,4785.89013671875,4798.6943359375,57.0518472471791,20.535280062193,15.315984,0,0,0,40,4449,30.00445,4792.29223632812,,,,,,,,,,,,,0,,,,-0.00245,,,,,,29.999136,,,,
,29433756.965,29.9994164,4332.51147460937,0.000128452875494359,3.39304832522339E-7,1,0.999253354069792,40.0298881530762,1.99729110073201,17.1799995005131,0.0014432532555077,0.000263739198989689,0.25,5.30846937935462E-7,0.000127813969118581,1.25921433288322E-6,29.9994164,29.9994164,4331.15087890625,4333.8720703125,56.8525319747752,20.5348400427231,16.075285,0,0,0,40,4449,30.0026,4332.51147460937,,,,,,,,,,,,,0,,,,0,,,,,,29.9994164,,,,
,29433775.1,30.00001335,3880.31030273438,0.000130147103055115,3.77639618056466E-7,1,0.999253354069792,40.0298881530762,1.99736274171976,17.1799995005131,0.00146227738208113,0.00026731864417378,0.25,5.50003194966166E-7,0.000129495831510525,1.28461034434974E-6,29.9999466,30.0000801,3876.47973632812,3884.14086914063,56.8361177758714,20.5434150241396,15.695635,0,0,0,40,4449,30.00415,3880.31030273438,,,,,,,,,,,,,0,,,,0,,,,,,30.00001335,,,,
,29433793.205,29.9987564,3428.17541503906,0.000131317753973539,3.29254434456161E-7,1,0.999253354069792,40.0298881530762,1.99716502369488,17.1799995005131,0.00147524231077719,0.000269716398396292,0.25,5.60648101055558E-7,0.000130656728258726,1.29849541787499E-6,29.9987564,29.9987564,3424.42993164063,3431.9208984375,56.8806706014676,20.5356452561886,15.315984,0,0,0,40,4449,30.0016,3428.17541503906,,,,,,,,,,,,,0,,,,0.00245,,,,,,29.9987564,,,,
,29433811.61,29.9994354,2967.58520507812,0.000132259574976063,3.1558116255694E-7,1,0.999253354069792,40.0298881530762,1.99721915542316,17.1799995005131,0.00148598407421175,0.000270723379045582,0.25,4.85494391767632E-7,0.00013159050364097,1.22575990828715E-6,29.9994354,29.9994354,2962.32592773438,2972.84448242188,56.6149169049291,20.5377239753522,15.695635,0,0,0,40,4449,30.00605,2967.58520507812,,,,,,,,,,,,,0,,,,0,,,,,,29.9994354,,,,
,29433831.28,29.9990673,2477.638671875,0.000132551447114852,2.8385848172451E-7,1,0.999253354069792,40.0298881530762,1.99737138803511,17.1799995005131,0.00148883105750401,0.000274112923107654,0.25,7.37321327084171E-7,0.000131875559780808,1.4744796834175E-6,29.9990673,29.9990673,2472.71264648438,2482.56469726562,56.4648442292367,20.5399058391244,16.075285,0,0,0,40,4449,30.0056,2477.638671875,,,,,,,,,,,,,0,,,,0.00245,,,,,,29.9990673,,,,
,29433849.74,29.9992867,2014.53497314453,0.000131813988291129,3.07403359839985E-7,1,0.999253354069792,40.0298881530762,1.99726155983744,17.1799995005131,0.00148034004858363,0.000273069671896005,0.25,7.81157089425765E-7,0.000131138042039623,1.51079572519066E-6,29.9992867,29.9992867,2010.73486328125,2018.33508300781,56.872072687756,20.5345859676341,16.075285,0,0,0,40,4449,30.0049,2014.53497314453,,,,,,,,,,,,,0,,,,0,,,,,,29.9992867,,,,
,29433867.515,29.9986115,1570.88751220703,0.000130420733257178,3.477792649663E-7,1,0.999253354069792,40.0298881530762,1.99734870335654,17.1799995005131,0.00146467841372503,0.000270410133860928,0.25,7.9550588479736E-7,0.000129748630708248,1.51444976800491E-6,29.9986115,29.9986115,1563.27087402344,1578.50415039062,56.3014838687175,20.5383639422089,16.075285,0,0,0,40,4449,30.0066,1570.88751220703,,,,,,,,,,,,,0,,,,0,,,,,,29.9986115,,,,
,29433885.625,29.9994106,1118.51641845703,0.000126455569064898,3.18846406267449E-7,1,0.999253354069792,40.0298881530762,1.99734950918151,17.1799995005131,0.00142032072862889,0.000261026013418365,0.25,6.71145355680693E-7,0.000125801452607671,1.36601365262426E-6,29.9994106,29.9994106,1113.77844238281,1123.25439453125,57.0831123879483,20.5356475406714,16.075285,0,0,0,40,4449,30.0052,1118.51641845703,,,,,,,,,,,,,0,,,,-0.00245,,,,,,29.9994106,,,,
,29433904.05,29.9983177,658.656341552734,0.00011771079221255,2.99541306012344E-7,1,0.999253354069792,40.0298881530762,1.99747504158607,17.1799995005131,0.00132242397802937,0.00024145468950013,0.25,4.91027925241772E-7,0.000117100054971119,1.13615826917636E-6,29.9983177,29.9983177,653.72607421875,663.586608886719,56.7790588939676,20.5397814103207,16.075285,0,0,0,40,4449,30.0051,658.656341552734,,,,,,,,,,,,,0,,,,0,,,,,,29.9983177,,,,
,29433922.53,29.9987202,196.39501953125,9.34606178836691E-5,3.43127099459978E-7,1,0.999253354069792,40.0298881530762,1.99736221978919,17.1799995005131,0.00105040797551498,0.000188893415410838,0.25,1.42084002129477E-7,9.29752783361967E-5,6.5394975581853E-7,29.9987202,29.9987202,191.528915405273,201.261123657227,56.8126689202945,20.5393598452251,16.075285,0,0,0,40,4449,30.0042,196.39501953125,,,,,,,,,,,,,0,,,,0,,,,,,29.9987202,,,,
,29433930.38,29.9990139,-0.038059432990849,6.87295655531112E-5,3.82527068517348E-7,1,0.999253354069792,40.0298881530762,1.99732248173202,17.1799995005131,0.0007724654601404,0.000138737722312179,0.25,8.98785882492657E-8,6.83723407723306E-5,4.66010839296769E-7,29.9990139,29.9990139,-0.0608950927853584,-0.0152237731963396,56.8626931455252,20.5363560940157,15.695635,0,0,0,40,4417,30.00495,-0.038059432990849,,,,,,,,,,,,,0,,,,0.0049,,,,,,29.9990139,,,,