File: data/looselyPackedNP/sc-ios-11/ppms/rawdata/ES_S14_HYST_10K.DAT
[Header]
; VSM Data File (default extension .dat)
; Copyright (c) 2003-2013, Quantum Design, Inc. All rights reserved.
TITLE,
FILEOPENTIME,29079202.89,12/03/2018,9:34 pm
BYAPP,VSM,2.0,2.0
INFO,PPMS VSM Option Release 1.4.10 Build 1,APPNAME
INFO,Quantum Design Linear Motor Servo Controller,MOTOR_MODULE_NAME
INFO,3101-100 M1,MOTOR_HW_VERSION
INFO,MMC1014,MOTOR_SERIAL_NUMBER
INFO,SRV No X-over 01.03.11,MOTOR_SOFTWARE_VERSION
INFO,Quantum Design VSM Detection Module,VSM_MODULE_NAME
INFO,3101-150 F0,VSM_HW_VERSION
INFO,VSM707,VSM_SERIAL_NUMBER
INFO,VSM No X-over 01.02.05 May 20 2008 13:51:47,VSM_SOFTWARE_VERSION
INFO,704,PREAMP_SERIAL_NUMBER
INFO,822,COIL_SERIAL_NUMBER
INFO,0,MOMENT_UNITS
INFO,Iron Oxide Spheres,SAMPLE_MATERIAL
INFO,10 nm diameter, collaboration Mainz,SAMPLE_COMMENT
INFO,,SAMPLE_MASS
INFO,,SAMPLE_VOLUME
INFO,,SAMPLE_MOLECULAR_WEIGHT
INFO,,SAMPLE_SIZE
INFO,,SAMPLE_SHAPE
DATATYPE,COMMENT,1
DATATYPE,TIME,2
STARTUPAXIS,X,2
STARTUPAXIS,Y1,5
[Data]
Comment,Time Stamp (sec),Temperature (K),Magnetic Field (Oe),Moment (emu),M. Std. Err. (emu),Transport Action,Averaging Time (sec),Frequency (Hz),Peak Amplitude (mm),Center Position (mm),Coil Signal' (mV),Coil Signal" (mV),Range (mV),M. Quad. Signal (emu),M. Raw' (emu),M. Raw" (emu),Min. Temperature (K),Max. Temperature (K),Min. Field (Oe),Max. Field (Oe),Mass (grams),Motor Lag (deg),Pressure (Torr),VSM Status (code),Motor Status (code),Measure Status (code),Measure Count,PPMS Status (code),System Temp. (K),System Field (Oe),Sample Position (deg),Bridge 1 Resistance (ohms),Bridge 1 Excitation (에),Bridge 2 Resistance (ohms),Bridge 2 Excitation (에),Bridge 3 Resistance (ohms),Bridge 3 Excitation (에),Bridge 4 Resistance (ohms),Bridge 4 Excitation (에),Signal 1 Vin (V),Signal 2 Vin (V),Digital Inputs (code),Drive 1 Iout (mA),Drive 1 Ipower (W),Drive 2 Iout (mA),Drive 2 Ipower (W),Pressure (),Map 20 (),Map 21 (),Map 22 (),Map 23 (),Map 24 (),Map 25 (),Map 26 (),Map 27 (),Map 28 (),Map 29 ()
sample offset = 34.96 mm touchdown = 11.4900004118681 mm,29079245.04,10.0041962,0.159849621355534,-1.45809825617198E-5,2.77999471865531E-7,1,0.999253354069792,40.0298881530762,1.99726295576796,17.6899991929531,-0.000163483747151976,-3.10970281746478E-5,0.25,-1.78305902966537E-7,-1.44963614196937E-5,-2.4756095278887E-7,10.0041962,10.0041962,0.152237743139267,0.1674614995718,55.7301134211597,20.522805295135,13.038077,0,0,0,40,4417,10.0019,0.159849621355534,,,,,,,,,,,,,0,,,,-0.0049,,,,,,10.0041962,,,,
,29079362.24,10.0001621,4810.82470703125,0.000130526708041865,3.21836733598017E-7,1,0.999253354069792,40.0298881530762,1.99678386062598,17.6899991929531,0.00146512101521779,0.000269448692502159,0.25,7.62380023364758E-7,0.000129807419090681,1.42573760938515E-6,10.0001621,10.0001621,4800.775390625,4820.8740234375,56.188147733429,20.5459083479262,12.658426,0,0,0,40,4449,9.99595,4810.82470703125,,,,,,,,,,,,,0,,,,-0.0049,,,,,,10.0001621,,,,
,29079457.88,10.0032568,9589.9482421875,0.000111243216277572,3.37519583890043E-7,1,0.999253354069792,40.0298881530762,1.99630375028532,17.6899991929531,0.00124813290512218,0.000233562885746179,0.25,9.57279185085688E-7,0.000110667588924781,1.56016874982303E-6,10.0032568,10.0032568,9582.4658203125,9597.4306640625,56.4671891147944,20.5488495934691,12.658426,0,0,0,40,4449,9.9951,9589.9482421875,,,,,,,,,,,,,0,,,,-0.0049,,,,,,10.0032568,,,,
,29079551.64,10.0046062,14274.9580078125,8.85312061737999E-5,4.55866520988818E-7,1,0.999253354069792,40.0298881530762,1.99640029906689,17.6899991929531,0.000993564427578414,0.00018699168897341,0.25,8.23368288128599E-7,8.81076270212004E-5,1.33347110046617E-6,10.0046062,10.0046062,14265.1318359375,14284.7841796875,56.8079791491791,20.5562986900626,13.038077,0,0,0,40,4449,9.9907,14274.9580078125,,,,,,,,,,,,,0,,,,-0.0049,,,,,,10.0046062,,,,
,29079649.405,10.0044518,19159.6201171875,6.38901130934219E-5,3.90261318698031E-7,1,0.999253354069792,40.0298881530762,1.99624478436344,17.6899991929531,0.00071747846410561,0.000133977061260473,0.25,4.82070098728456E-7,6.36138869846634E-5,8.72433034583704E-7,10.0044518,10.0044518,19157.123046875,19162.1171875,56.9134989992753,20.5517330825375,12.658426,0,0,0,40,4449,9.9892,19159.6201171875,,,,,,,,,,,,,0,,,,0,,,,,,10.0044518,,,,
,29079747.4,10.0022335,24059.8251953125,3.7782375886319E-5,4.78311637834217E-7,1,0.999253354069792,40.0298881530762,1.99583416726743,17.6899991929531,0.000423904443691607,8.20989499639996E-5,0.25,5.26705170462544E-7,3.76356936176303E-5,7.68301978914713E-7,10.0022335,10.0022335,24054.8515625,24064.798828125,56.7384142109675,20.5547911260844,12.658426,0,0,0,40,4449,9.98575,24059.8251953125,,,,,,,,,,,,,0,,,,0,,,,,,10.0022335,,,,
,29079842.775,10.0026126,28827.6474609375,1.13972411829612E-5,5.37794204684825E-7,1,0.999253354069792,40.0298881530762,1.99577244685907,17.6899991929531,0.000127855364346824,2.52033749119039E-5,0.25,1.93844983407336E-7,1.13583155746825E-5,2.69643652645753E-7,10.0020266,10.0031986,28822.783203125,28832.51171875,57.1487691835637,20.5602802692912,13.038077,0,0,0,40,4449,9.98315,28827.6474609375,,,,,,,,,,,,,0,,,,0,,,,,,10.0026126,,,,
,29079940.495,10.0009632,33709.84375,-1.50943678199746E-5,7.27988084088745E-7,1,0.999253354069792,40.0298881530762,1.99562087722604,17.6899991929531,-0.000170477542725761,-2.74256660205232E-5,0.25,2.76783686443257E-7,-1.50542193433417E-5,1.71394154180011E-7,10.0009632,10.0009632,33704.7890625,33714.8984375,56.6477453027368,20.5610553198081,12.278775,0,0,0,40,4449,9.98455,33709.84375,,,,,,,,,,,,,0,,,,-0.0049,,,,,,10.0009632,,,,
,29080037.26,10.0008936,38547.212890625,-4.15130937600186E-5,5.90292295345516E-7,1,0.999253354069792,40.0298881530762,1.99573306513239,17.6899991929531,-0.000466500770028102,-9.00409241845306E-5,0.25,-5.25108411510064E-7,-4.14149808642376E-5,-8.19101692872463E-7,10.0008936,10.0008936,38541.75,38552.67578125,56.943200883006,20.5598289204191,12.278775,0,0,0,40,4449,9.98425,38547.212890625,,,,,,,,,,,,,0,,,,0.0049,,,,,,10.0008936,,,,
,29080132.29,9.9987469,43297.55859375,-6.8116441818448E-5,6.79036141973824E-7,1,0.999253354069792,40.0298881530762,1.99537411768422,17.6899991929531,-0.00076717088411986,-0.000139661334808769,0.25,-1.30924459435823E-7,-6.79947894038123E-5,-6.24328768960624E-7,9.9987469,9.9987469,43294.96875,43300.1484375,56.7626446950637,20.5635394647883,13.038077,0,0,0,40,4449,9.98635,43297.55859375,,,,,,,,,,,,,0,,,,0,,,,,,9.9987469,,,,
,29080226.21,9.9958143,47992.51171875,-9.44061494444957E-5,6.30575212467671E-7,1,0.999253354069792,40.0298881530762,1.99558611764152,17.6899991929531,-0.00106449777782458,-0.000190305992961278,0.25,1.26555912713579E-7,-9.42858284886822E-5,-5.6695103518372E-7,9.9958143,9.9958143,47987.46875,47997.5546875,57.2081729510253,20.5619030569326,12.658426,0,0,0,40,4449,9.98725,47992.51171875,,,,,,,,,,,,,0,,,,-0.0049,,,,,,9.9958143,,,,
,29080323.54,9.9963198,52855.146484375,-0.00012333859852614,8.80721757976359E-7,1,0.999253354069792,40.0298881530762,1.99555140866819,17.6899991929531,-0.00138839154107327,-0.000265413803395344,0.25,-1.30491254240507E-6,-0.000123231234479613,-2.21766216850316E-6,9.9963198,9.9963198,52845.07421875,52865.21875,57.0354330482753,20.5611856884503,12.278775,0,0,0,40,4449,9.99185,52855.146484375,,,,,,,,,,,,,0,,,,0,,,,,,9.9963198,,,,
,29080419.015,9.9964705,57627.546875,-0.000150583843090401,8.88420541071932E-7,1,0.999253354069792,40.0298881530762,1.99569954747165,17.6899991929531,-0.00169581422640464,-0.000325228830686781,0.25,-1.67869770660698E-6,-0.000150522387998288,-2.79839488121427E-6,9.9964705,9.9964705,57622.328125,57632.765625,57.0870205305445,20.5570975114559,12.658426,0,0,0,40,4449,9.9948,57627.546875,,,,,,,,,,,,,0,,,,-0.00245,,,,,,9.9964705,,,,
,29080514.9,9.9952517,62420.796875,-0.000180052683353416,8.35937024564076E-7,1,0.999253354069792,40.0298881530762,1.99579790041988,17.6899991929531,-0.00202805938595732,-0.00039256142417153,0.25,-2.31688633809162E-6,-0.000180057953160479,-3.65695132779742E-6,9.9952517,9.9952517,62410.765625,62430.828125,56.9197520274291,20.5591198272583,12.278775,0,0,0,40,4449,9.99865,62420.796875,,,,,,,,,,,,,0,,,,0,,,,,,9.9952517,,,,
,29080612.835,9.995893,67316.375,-0.000209790404757334,6.17340709916645E-7,1,0.999253354069792,40.0298881530762,1.99554873479247,17.6899991929531,-0.00236337890878811,-0.000459718613598704,0.25,-2.89798849902912E-6,-0.000209887138098876,-4.4555182250414E-6,9.9956551,9.9961309,67304.078125,67328.671875,57.017455592333,20.5625889907433,12.658426,0,0,0,40,4449,10.00275,67316.375,,,,,,,,,,,,,0,,,,0,,,,,,9.995893,,,,
,29080711.155,9.9955597,72228.6015625,-0.000237000200048353,6.97872971795083E-7,1,0.999253354069792,40.0298881530762,1.99556664629301,17.6899991929531,-0.00267182443240875,-0.000515244853094954,0.25,-2.90348488795192E-6,-0.000237211249821486,-4.65273455197882E-6,9.9955597,9.9955597,72226.1328125,72231.0703125,56.9822823089676,20.5648562973336,13.038077,0,0,0,40,4449,10.0064,72228.6015625,,,,,,,,,,,,,0,,,,0,,,,,,9.9955597,,,,
,29080809.915,9.995738,77164.23046875,-0.000265948185792504,6.96269334243517E-7,1,0.999253354069792,40.0298881530762,1.99567799379418,17.6899991929531,-0.00299715155573614,-0.000591566041078469,0.25,-4.43820911907428E-6,-0.00026628184861732,-6.38608681064578E-6,9.995738,9.995738,77159.1328125,77169.328125,57.1745629246983,20.5635363208002,12.278775,0,0,0,40,4449,10.0122,77164.23046875,,,,,,,,,,,,,0,,,,0.0049,,,,,,9.995738,,,,
,29080907.225,9.9951286,82029.890625,-0.00029666529387752,8.58163849493637E-7,1,0.999253354069792,40.0298881530762,1.9956509106315,17.6899991929531,-0.00335236890822898,-0.000616456329906802,0.25,-1.11415797392297E-6,-0.000297174457257737,-3.25767191791332E-6,9.9951286,9.9951286,82027.140625,82032.640625,57.115940785756,20.5613368505065,13.038077,0,0,0,40,4449,10.01525,82029.890625,,,,,,,,,,,,,0,,,,0,,,,,,9.9951286,,,,
,29081001.785,9.995245,86758.0390625,-0.00032424977991835,8.99022053366833E-7,1,0.999253354069792,40.0298881530762,1.99554571204951,17.6899991929531,-0.00366631339768431,-0.000667320485336957,0.25,-6.60916709900448E-7,-0.000324918954630065,-2.97296712247071E-6,9.9950781,9.9954119,86745.59375,86770.484375,57.0760777312753,20.5596678343459,12.278775,0,0,0,40,4449,10.01785,86758.0390625,,,,,,,,,,,,,0,,,,-0.00245,,,,,,9.995245,,,,
,29081112.6,9.9959641,88780.24609375,-0.000340659769510051,8.95238064247429E-7,1,0.999253354069792,40.0298881530762,1.99563533514512,17.6899991929531,-0.00384543828043838,-0.000740772090625404,0.25,-4.20540545194467E-6,-0.000341384586562826,-6.62778018971957E-6,9.9959641,9.9959641,88772.890625,88787.6015625,57.268358347006,20.5620254901852,12.658426,0,0,0,40,4449,10.0227,88780.24609375,,,,,,,,,,,,,0,,,,0,,,,,,9.9959641,,,,
,29081205.385,9.9996099,84141.65625,-0.000309883136624624,1.06371059857465E-6,1,0.999253354069792,40.0298881530762,1.99578594040243,17.6899991929531,-0.00350168699806024,-0.000648526257899481,0.25,-1.57123897969678E-6,-0.000310459264381581,-3.7988136530319E-6,9.9996099,9.9996099,84139.171875,84144.140625,57.1229754424291,20.5608550307133,11.899124,0,0,0,40,4449,10.022,84141.65625,,,,,,,,,,,,,0,,,,0,,,,,,9.9996099,,,,
,29081303.96,10.0012608,79215.7265625,-0.000280179508713768,9.66386181154412E-7,1,0.999253354069792,40.0298881530762,1.99568890884893,17.6899991929531,-0.00316518059597122,-0.00058371152013244,0.25,-1.18153340884938E-6,-0.000280600703018706,-3.21976935962862E-6,10.0012608,10.0012608,79210.9765625,79220.4765625,57.0440309619868,20.5629198025403,12.278775,0,0,0,40,4449,10.0209,79215.7265625,,,,,,,,,,,,,0,,,,0,,,,,,10.0012608,,,,
,29081401.42,10.0022888,74342.06640625,-0.00025087331971632,7.55759354442949E-7,1,0.999253354069792,40.0298881530762,1.99578250917872,17.6899991929531,-0.00283225730846698,-0.000527487569074034,0.25,-1.48173130446395E-6,-0.000251151723751143,-3.32537409109947E-6,10.0022888,10.0022888,74331.84375,74352.2890625,57.2503808910638,20.5612063224289,12.658426,0,0,0,40,4449,10.01815,74342.06640625,,,,,,,,,,,,,0,,,,0.00245,,,,,,10.0022888,,,,
,29081503.085,10.0028143,69259.07421875,-0.000220176154331662,5.73010904774493E-7,1,0.999253354069792,40.0298881530762,1.99581622208504,17.6899991929531,-0.00248293654634779,-0.000472497072297509,0.25,-2.14924957845945E-6,-0.000220321267401485,-3.78015473067243E-6,10.0026932,10.0029354,69249.1796875,69268.96875,57.0307432771599,20.5623345690618,12.278775,0,0,0,40,4449,10.0155,69259.07421875,,,,,,,,,,,,,0,,,,0.00245,,,,,,10.0028143,,,,
,29081602.955,10.0032415,64268.93359375,-0.000191795392621231,6.65773443340538E-7,1,0.999253354069792,40.0298881530762,1.99556877020986,17.6899991929531,-0.00216531880685061,-0.000391187675550044,0.25,-7.80371357492922E-8,-0.000191851038824075,-1.50399337366898E-6,10.0032415,10.0032415,64261.4921875,64276.375,57.2300585495638,20.5625340436452,12.278775,0,0,0,40,4449,10.0131,64268.93359375,,,,,,,,,,,,,0,,,,0.0049,,,,,,10.0032415,,,,
,29081701.25,10.003046,59355.732421875,-0.000162838909499021,9.30675071117521E-7,1,0.999253354069792,40.0298881530762,1.99560110613697,17.6899991929531,-0.00183690902564523,-0.000335829348656822,0.25,-4.0521511574406E-7,-0.000162809742234385,-1.61717736999438E-6,10.003046,10.003046,59353.26953125,59358.1953125,56.9486722826406,20.5628455957039,12.278775,0,0,0,40,4449,10.0108,59355.732421875,,,,,,,,,,,,,0,,,,0,,,,,,10.003046,,,,
,29081800.595,10.0032692,54390.29296875,-0.000133949240110987,7.216082210236E-7,1,0.999253354069792,40.0298881530762,1.99554508243319,17.6899991929531,-0.00150909586368666,-0.000282530047914345,0.25,-9.04919089769128E-7,-0.000133856793560765,-1.89850348423774E-6,10.0032692,10.0032692,54380.1015625,54400.484375,57.1886322380445,20.5660025060303,12.658426,0,0,0,40,4449,10.00755,54390.29296875,,,,,,,,,,,,,0,,,,0.00245,,,,,,10.0032692,,,,
,29081898.415,10.0045156,49500.115234375,-0.000107283767221122,7.63099243119401E-7,1,0.999253354069792,40.0298881530762,1.995593616226,17.6899991929531,-0.00120811244380558,-0.000226184425167645,0.25,-7.30507507133998E-7,-0.000107157136629826,-1.52015562524676E-6,10.0045156,10.0045156,49487.98828125,49512.2421875,57.4254656793715,20.5671539577268,11.899124,0,0,0,40,4449,10.00655,49500.115234375,,,,,,,,,,,,,0,,,,0.00245,,,,,,10.0045156,,,,
,29081996.28,10.0029893,44608.029296875,-7.81052576697976E-5,8.77575431339159E-7,1,0.999253354069792,40.0298881530762,1.99545922152667,17.6899991929531,-0.000877411068875333,-0.000173591228841515,0.25,-1.33880947443824E-6,-7.79678188860532E-5,-1.90505087469395E-6,10.0028868,10.0030918,44600.51953125,44615.5390625,57.0917103016599,20.569272763497,12.278775,0,0,0,40,4449,10.00165,44608.029296875,,,,,,,,,,,,,0,,,,-0.00245,,,,,,10.0029893,,,,
,29082090.39,10.0024614,39904.80859375,-5.07034294348796E-5,6.82961905495116E-7,1,0.999253354069792,40.0298881530762,1.99544388466089,17.6899991929531,-0.000569024172581852,-0.000114173745632213,0.25,-1.01200350092051E-6,-5.05882101576015E-5,-1.37256259342626E-6,10.0024614,10.0024614,39892.3984375,39917.21875,57.2793011462753,20.5697359809962,12.658426,0,0,0,40,4449,9.99885,39904.80859375,,,,,,,,,,,,,0,,,,0,,,,,,10.0024614,,,,
,29082187.51,10.0022469,35050.28125,-2.3398927417822E-5,5.31628887431102E-7,1,0.999253354069792,40.0298881530762,1.99543944749727,17.6899991929531,-0.000262355340219092,-5.32511499588565E-5,0.25,-5.23195974346813E-7,-2.33333891760205E-5,-6.85253020460356E-7,10.0022469,10.0022469,35040.40234375,35060.16015625,57.2753930036791,20.5688314112014,12.278775,0,0,0,40,4449,9.99795,35050.28125,,,,,,,,,,,,,0,,,,0,,,,,,10.0022469,,,,
,29082284.745,10.000843,30192.712890625,4.56679325939951E-6,5.39540049745448E-7,1,0.999253354069792,40.0298881530762,1.99530571664803,17.6899991929531,5.2332086530784E-5,3.94219153342972E-6,0.25,-4.69743833485393E-7,4.5555519416554E-6,-4.3732592244804E-7,10.000843,10.000843,30182.806640625,30202.619140625,57.3465211989291,20.5700366129713,12.278775,0,0,0,40,4449,9.9961,30192.712890625,,,,,,,,,,,,,0,,,,0,,,,,,10.000843,,,,
,29082383.03,10.0011997,25279.892578125,3.24312147011058E-5,4.43720274135133E-7,1,0.999253354069792,40.0298881530762,1.99541165999383,17.6899991929531,0.000364350460770577,6.7607961073301E-5,0.25,1.95757926634013E-7,3.23109738452865E-5,4.06406420985332E-7,10.0011997,10.0011997,25274.89453125,25284.890625,57.2120810936214,20.5695402961249,11.899124,0,0,0,40,4449,9.9962,25279.892578125,,,,,,,,,,,,,0,,,,0,,,,,,10.0011997,,,,
,29082478.1,10.00027275,20528.025390625,5.94567013103221E-5,4.10210472145615E-7,1,0.999253354069792,40.0298881530762,1.99545571834883,17.6899991929531,0.000666986486435249,0.000127678952393687,0.25,7.12810840364262E-7,5.92058515594347E-5,1.08033160595423E-6,10.0002651,10.0002804,20522.802734375,20533.248046875,57.3113479155637,20.5672412586472,12.278775,0,0,0,40,4449,9.996,20528.025390625,,,,,,,,,,,,,0,,,,0,,,,,,10.00027275,,,,
,29082571.68,9.9990463,15850.4536132812,8.39419051725182E-5,3.90390430430916E-7,1,0.999253354069792,40.0298881530762,1.99545689074128,17.6899991929531,0.000941470461233571,0.000178915651416978,0.25,9.20141191132812E-7,8.35513231836635E-5,1.41262512487257E-6,9.9990463,9.9990463,15840.5283203125,15860.37890625,57.2503808910638,20.5682760447958,12.278775,0,0,0,40,4449,9.9973,15850.4536132812,,,,,,,,,,,,,0,,,,0.00245,,,,,,9.9990463,,,,
,29082666.75,9.9981422,11100.845703125,0.000108187116928724,2.739313364634E-7,1,0.999253354069792,40.0298881530762,1.99541063749113,17.6899991929531,0.00121354720456991,0.000226675545801634,0.25,8.8314829376069E-7,0.000107640804438698,1.4818960676567E-6,9.9981422,9.9981422,11088.900390625,11112.791015625,57.0354330482753,20.5714689161686,12.278775,0,0,0,40,4449,9.9985,11100.845703125,,,,,,,,,,,,,0,,,,0,,,,,,9.9981422,,,,
,29082760.455,9.9981651,6415.46557617187,0.000130693476659726,3.15987662030222E-7,1,0.999253354069792,40.0298881530762,1.99540724896054,17.6899991929531,0.0014652078621564,0.000275175239303663,0.25,1.24063744469911E-6,0.000129985277299502,1.91746784466169E-6,9.9981651,9.9981651,6405.44091796875,6425.490234375,57.352774227083,20.5723883803903,11.899124,0,0,0,40,4449,9.99865,6415.46557617187,,,,,,,,,,,,,0,,,,0,,,,,,9.9981651,,,,
,29082858.385,10.0009336,1519.45642089844,0.000137260772773784,3.19388665922455E-7,1,0.999253354069792,40.0298881530762,1.99541963786231,17.6899991929531,0.00153999997982108,0.00027971381608751,0.25,5.29365085682734E-7,0.00013647862255186,1.19833359144338E-6,10.0009336,10.0009336,1511.85473632813,1527.05810546875,57.0643533034868,20.5743004577885,12.278775,0,0,0,40,4449,9.9994,1519.45642089844,,,,,,,,,,,,,0,,,,0.00245,,,,,,10.0009336,,,,
,29082952.33,9.9987583,-3168.28649902344,-0.000137227750818371,3.20847725564142E-7,1,0.999253354069792,40.0298881530762,1.99540381310076,17.6899991929531,-0.00153798826003707,-0.000289652673825755,0.25,-1.40384307288776E-6,-0.000136454177191286,-2.08221789287971E-6,9.9987583,9.9987583,-3170.953125,-3165.61987304687,57.1511140691214,20.5746775928413,11.899124,0,0,0,40,4449,9.9991,-3168.28649902344,,,,,,,,,,,,,0,,,,0,,,,,,9.9987583,,,,
,29083048.98,9.9991112,-8002.89135742188,-0.000121336620490172,3.04878036049241E-7,1,0.999253354069792,40.0298881530762,1.99548150340646,17.6899991929531,-0.00136038796612481,-0.000256235429428508,0.25,-1.20194211442815E-6,-0.0001206930020062,-1.84433364507809E-6,9.9991112,9.9991112,-8010.65185546875,-7995.130859375,57.2980602307368,20.574357579908,12.278775,0,0,0,40,4449,10.0009,-8002.89135742188,,,,,,,,,,,,,0,,,,0,,,,,,9.9991112,,,,
,29083143.615,10.0003357,-12733.2084960938,-9.86598585794018E-5,3.12910164057591E-7,1,0.999253354069792,40.0298881530762,1.99551923567241,17.6899991929531,-0.00110637128145994,-0.000209659591743633,0.25,-1.0522832101409E-6,-9.8173808992333E-5,-1.60899811212378E-6,10.0003357,10.0003357,-12738.333984375,-12728.0830078125,57.2777378892368,20.5759872917994,12.278775,0,0,0,40,4449,9.9994,-12733.2084960938,,,,,,,,,,,,,0,,,,0.0049,,,,,,10.0003357,,,,
,29083239.345,10.0010481,-17515.919921875,-7.34730532392571E-5,4.33404146215234E-7,1,0.999253354069792,40.0298881530762,1.99546259529116,17.6899991929531,-0.000824172372138028,-0.000156693823696359,0.25,-8.0293947163173E-7,-7.31424670701787E-5,-1.24257946428636E-6,10.0010481,10.0010481,-17526.064453125,-17505.775390625,57.0893654161022,20.5775959284299,12.658426,0,0,0,40,4449,9.99965,-17515.919921875,,,,,,,,,,,,,0,,,,0.00245,,,,,,10.0010481,,,,
,29083333.81,10.0006771,-22238.1240234375,-4.77802613837402E-5,4.23084986739129E-7,1,0.999253354069792,40.0298881530762,1.9954755037601,17.6899991929531,-0.000535309135262632,-0.000107013182654521,0.25,-9.58187529178169E-7,-4.7584239569205E-5,-1.25721691138617E-6,10.0006771,10.0006771,-22243.02734375,-22233.220703125,57.241001348833,20.5767036240909,11.899124,0,0,0,40,4449,9.99825,-22238.1240234375,,,,,,,,,,,,,0,,,,0,,,,,,10.0006771,,,,
,29083429.82,10.000186,-27035.837890625,-2.17001960035259E-5,4.12715816410326E-7,1,0.999253354069792,40.0298881530762,1.99553812951913,17.6899991929531,-0.000243117788103489,-4.93358031332716E-5,0.25,-4.92257274539303E-7,-2.16212592405746E-5,-6.34062086167401E-7,10.000186,10.000186,-27045.623046875,-27026.052734375,57.3942005386022,20.5772862498481,11.899124,0,0,0,40,4449,9.99805,-27035.837890625,,,,,,,,,,,,,0,,,,0.00245,,,,,,10.000186,,,,
,29083522.875,9.9998178,-31685.6591796875,4.41443167129752E-6,2.85893120432887E-7,1,0.999253354069792,40.0298881530762,1.99538846505856,17.6899991929531,5.09239236673614E-5,1.98890071157429E-6,0.25,-6.16331469922172E-7,4.40540133470151E-6,-5.84272983763291E-7,9.9998178,9.9998178,-31693.099609375,-31678.21875,57.3410497992945,20.5790550236341,12.278775,0,0,0,40,4449,9.9988,-31685.6591796875,,,,,,,,,,,,,0,,,,0,,,,,,9.9998178,,,,
,29083619.03,9.9991932,-36492.466796875,3.15445063643971E-5,5.47165867051997E-7,1,0.999253354069792,40.0298881530762,1.99554170868181,17.6899991929531,0.000356114966309007,5.86937587311649E-5,0.25,-4.60647280787149E-7,3.14691534257574E-5,-2.3744270616079E-7,9.9991932,9.9991932,-36494.96484375,-36489.96875,57.1307917276214,20.578368231302,11.899124,0,0,0,40,4449,9.99995,-36492.466796875,,,,,,,,,,,,,0,,,,-0.0049,,,,,,9.9991932,,,,
,29083714.525,9.9985199,-41264.962890625,5.95997463966406E-5,5.02090221364501E-7,1,0.999253354069792,40.0298881530762,1.99556420302824,17.6899991929531,0.000671427753151878,0.000120738109570722,0.25,-1.07073886137982E-8,5.94814655251786E-5,4.18040616720484E-7,9.9985199,9.9985199,-41277.453125,-41252.47265625,57.5520894994869,20.5805460152355,11.899124,0,0,0,40,4449,10.00045,-41264.962890625,,,,,,,,,,,,,0,,,,0.00245,,,,,,9.9985199,,,,
,29083813.02,9.9981928,-46187.486328125,8.79357653022962E-5,7.25084455577724E-7,1,0.999253354069792,40.0298881530762,1.99554242943952,17.6899991929531,0.000991458316762511,0.000176533586040353,0.25,-1.76518921916201E-7,8.78077361585092E-5,4.66647175684424E-7,9.9981928,9.9981928,-46195.01171875,-46179.9609375,57.4317187075253,20.5785304660242,11.899124,0,0,0,40,4449,10.0019,-46187.486328125,,,,,,,,,,,,,0,,,,0,,,,,,9.9981928,,,,
,29083911.085,9.9970284,-51087.15234375,0.000116432022953157,5.67730421377954E-7,1,0.999253354069792,40.0298881530762,1.99554233566495,17.6899991929531,0.00130999877253845,0.000252776267781557,0.25,1.43528182517776E-6,0.000116308557462921,2.29425010035391E-6,9.9970284,9.9970284,-51092.15234375,-51082.15234375,57.4895592179484,20.5793120366837,11.899124,0,0,0,40,4449,10.00565,-51087.15234375,,,,,,,,,,,,,0,,,,0,,,,,,9.9970284,,,,
,29084008.115,9.9963579,-55938.873046875,0.000145186541245537,7.24749523970905E-7,1,0.999253354069792,40.0298881530762,1.99565244730522,17.6899991929531,0.00163630422227703,0.000304770212442495,0.25,8.44449248319764E-7,0.000145109359327961,1.92306139054426E-6,9.9962711,9.9964447,-55943.88671875,-55933.859375,57.2621053188522,20.5802344843759,11.519473,0,0,0,40,4449,10.0084,-55938.873046875,,,,,,,,,,,,,0,,,,0,,,,,,9.9963579,,,,
,29084105.22,9.9960947,-60791.2109375,0.000173896996943889,7.74746173348857E-7,1,0.999253354069792,40.0298881530762,1.99557515808704,17.6899991929531,0.00196035774241154,0.000367180579272723,0.25,1.18607975261108E-6,0.000173883681562761,2.48044914161554E-6,9.9960947,9.9960947,-60801.27734375,-60781.14453125,57.3394865422561,20.5792707935244,12.278775,0,0,0,40,4449,10.0123,-60791.2109375,,,,,,,,,,,,,0,,,,0,,,,,,9.9960947,,,,
,29084203.32,9.9961996,-65693.4375,0.000202950446620875,4.91492467017057E-7,1,0.999253354069792,40.0298881530762,1.99567149400727,17.6899991929531,0.00228369261881077,0.000458223674095065,0.25,3.99931085350285E-6,0.000203006110557245,5.50836670816176E-6,9.9961996,9.9961996,-65698.34375,-65688.53125,57.6216544376984,20.5783803990614,11.899124,0,0,0,40,4449,10.016,-65693.4375,,,,,,,,,,,,,0,,,,-0.00245,,,,,,9.9961996,,,,
,29084299.92,9.9962282,-70523.09765625,0.000231502748903457,6.64501001185382E-7,1,0.999253354069792,40.0298881530762,1.99554961922041,17.6899991929531,0.00260779167432497,0.000512457043272371,0.25,3.64940418661997E-6,0.000231669914506221,5.36273856484011E-6,9.9962282,9.9962282,-70525.7578125,-70520.4375,57.5176978446407,20.5807745351695,11.899124,0,0,0,40,4449,10.01915,-70523.09765625,,,,,,,,,,,,,0,,,,0,,,,,,9.9962282,,,,
,29084399.29,9.9960604,-75487.1640625,0.000261641413037202,9.56471061330316E-7,1,0.999253354069792,40.0298881530762,1.99553165251425,17.6899991929531,0.00295003003825204,0.000570711946529813,0.25,3.37236205397442E-6,0.000261942364048033,5.29340233351364E-6,9.9960604,9.9960604,-75492.171875,-75482.15625,57.2769562607176,20.5801017470675,11.899124,0,0,0,40,4449,10.0237,-75487.1640625,,,,,,,,,,,,,0,,,,0.00245,,,,,,9.9960604,,,,
,29084492.47,9.9952803,-80141.671875,0.000288125531997041,9.95940065429489E-7,1,0.999253354069792,40.0298881530762,1.99546326035921,17.6899991929531,0.00324920088689439,0.000631463127928494,0.25,3.98131907629894E-6,0.000288558728625762,6.0773388919494E-6,9.9952803,9.9952803,-80149.140625,-80134.203125,57.2441278629099,20.582963365944,11.899124,0,0,0,40,4449,10.0276,-80141.671875,,,,,,,,,,,,,0,,,,-0.0049,,,,,,9.9952803,,,,
,29084588.62,9.9948425,-84949.21875,0.000316302814381577,7.83491462927834E-7,1,0.999253354069792,40.0298881530762,1.99566699501621,17.6899991929531,0.00357032044760399,0.000683685890786846,0.25,3.52968728219843E-6,0.00031689516448012,5.80223542962013E-6,9.9948425,9.9948425,-84956.90625,-84941.53125,57.1409528983714,20.580860005367,11.519473,0,0,0,40,4449,10.03165,-84949.21875,,,,,,,,,,,,,0,,,,0,,,,,,9.9948425,,,,
,29084678.38,9.994791,-89436.05078125,0.000340553119599698,9.44222577067464E-7,1,0.999253354069792,40.0298881530762,1.99551970603707,17.6899991929531,0.00384029688743168,0.00076217363436664,0.25,6.12202201180445E-6,0.000341279049978023,8.54331171240592E-6,9.994791,9.994791,-89443.5078125,-89428.59375,57.5098815594484,20.5803566752521,11.899124,0,0,0,40,4449,10.03655,-89436.05078125,,,,,,,,,,,,,0,,,,-0.00245,,,,,,9.994791,,,,
,29084789.155,9.9983435,-86019.26953125,0.000320868968992233,9.84745864672349E-7,1,0.999253354069792,40.0298881530762,1.9955888960013,17.6899991929531,0.00361538655356364,0.000730319530128482,0.25,6.83575112601695E-6,0.000321470664185748,9.14106269166573E-6,9.9983435,9.9983435,-86024.0390625,-86014.5,57.3895107674868,20.5798831359667,11.899124,0,0,0,40,4449,10.0372,-86019.26953125,,,,,,,,,,,,,0,,,,0,,,,,,9.9983435,,,,
,29084885.93,10.0011358,-81182.8046875,0.000294459267942399,9.67422360656693E-7,1,0.999253354069792,40.0298881530762,1.99550386418835,17.6899991929531,0.00331825489029727,0.000660368060734317,0.25,5.39766151732316E-6,0.000294915250231892,7.53690810944068E-6,10.0011358,10.0011358,-81197.8828125,-81167.7265625,57.3699700545061,20.580430579983,12.278775,0,0,0,40,4449,10.0361,-81182.8046875,,,,,,,,,,,,,0,,,,-0.00245,,,,,,10.0011358,,,,
,29084983.985,10.003686,-76282.98046875,0.000263580468867349,6.2169702777342E-7,1,0.999253354069792,40.0298881530762,1.99546502359734,17.6899991929531,0.00296906675239089,0.000591162865018352,0.25,4.83424676055924E-6,0.000263889749810223,6.76856384533061E-6,10.003686,10.003686,-76290.703125,-76275.2578125,57.3230723433522,20.5815403576087,11.899124,0,0,0,40,4449,10.032,-76282.98046875,,,,,,,,,,,,,0,,,,-0.0049,,,,,,10.003686,,,,
,29085079.735,10.0035639,-71497.984375,0.000236684502686614,7.11630789911849E-7,1,0.999253354069792,40.0298881530762,1.9958587448994,17.6899991929531,0.00266356305997066,0.000541869605487414,0.25,5.31097567792045E-6,0.000236863115527285,7.06192737702183E-6,10.0035639,10.0035639,-71503.015625,-71492.953125,57.251162519583,20.5764481207097,12.278775,0,0,0,40,4449,10.0293,-71497.984375,,,,,,,,,,,,,0,,,,0,,,,,,10.0035639,,,,
,29085169.39,10.0040798,-67016.0703125,0.000209186028559618,4.99363721868502E-7,1,0.999253354069792,40.0298881530762,1.99603756906098,17.6899991929531,0.00235502187903689,0.00046979512727226,0.25,3.89001293883444E-6,0.000209269560352992,5.44397821188379E-6,10.0040798,10.0040798,-67020.984375,-67011.15625,57.5450548428138,20.5723720054516,11.899124,0,0,0,40,4449,10.0274,-67016.0703125,,,,,,,,,,,,,0,,,,0.0049,,,,,,10.0040798,,,,
,29085260.595,10.004014,-62458.65234375,0.000183673925402993,8.8104469197887E-7,1,0.999253354069792,40.0298881530762,1.99590607400369,17.6899991929531,0.00206727298399388,0.000409850169691998,0.25,3.19353003075479E-6,0.000183673760926785,4.56064431477258E-6,10.004014,10.004014,-62468.68359375,-62448.62109375,57.5286406439099,20.5755104049421,11.899124,0,0,0,40,4449,10.0233,-62458.65234375,,,,,,,,,,,,,0,,,,0,,,,,,10.004014,,,,
,29085350.685,10.0037737,-57955.94921875,0.000156777289137513,7.78273775674748E-7,1,0.999253354069792,40.0298881530762,1.99580750082427,17.6899991929531,0.00176430027971917,0.000346448934599579,0.25,2.44016059246215E-6,0.000156713084692774,3.60591932869515E-6,10.0037737,10.0037737,-57965.95703125,-57945.94140625,57.2667950899676,20.5736976928923,11.899124,0,0,0,40,4449,10.02015,-57955.94921875,,,,,,,,,,,,,0,,,,0,,,,,,10.0037737,,,,
,29085441.725,10.0040598,-53406.224609375,0.00013088462598773,6.66035936438488E-7,1,0.999253354069792,40.0298881530762,1.99571292031468,17.6899991929531,0.00146947228361032,0.000304203052132744,0.25,3.38007099744921E-6,0.000130763063122599,4.34793868664055E-6,10.0040598,10.0040598,-53413.703125,-53398.74609375,57.3504293415253,20.5733003676329,11.519473,0,0,0,40,4449,10.01635,-53406.224609375,,,,,,,,,,,,,0,,,,0,,,,,,10.0040598,,,,
,29085531.915,10.0049639,-48898.876953125,0.000104883331133794,5.41392643457075E-7,1,0.999253354069792,40.0298881530762,1.9955709123637,17.6899991929531,0.00117819095042327,0.000236676247003472,0.25,2.09600401555044E-6,0.000104742938109467,2.865342685854E-6,10.0049639,10.0049639,-48906.484375,-48891.26953125,57.1268835850253,20.577417295654,11.899124,0,0,0,40,4449,10.0129,-48898.876953125,,,,,,,,,,,,,0,,,,0,,,,,,10.0049639,,,,
,29085625.445,10.003809,-44226.248046875,7.74623917114001E-5,5.92053526640278E-7,1,0.999253354069792,40.0298881530762,1.99575001456799,17.6899991929531,0.00086975515713933,0.000175069830331461,0.25,1.58490969371606E-6,7.73211377331528E-5,2.14533481780938E-6,10.003809,10.003809,-44233.69140625,-44218.8046875,57.3246356003907,20.575932913281,11.899124,0,0,0,40,4449,10.01,-44226.248046875,,,,,,,,,,,,,0,,,,0.00245,,,,,,10.003809,,,,
,29085721.585,10.0033035,-39421.833984375,4.92142601209473E-5,5.51901894840951E-7,1,0.999253354069792,40.0298881530762,1.99568715497471,17.6899991929531,0.000551592636814545,0.000115024616120087,0.25,1.35560174001434E-6,4.90972576536115E-5,1.70397319208716E-6,10.0033035,10.0033035,-39431.9296875,-39411.73828125,57.5184794731599,20.5767346805223,11.899124,0,0,0,40,4449,10.0078,-39421.833984375,,,,,,,,,,,,,0,,,,-0.00245,,,,,,10.0033035,,,,
,29085823.09,10.0024233,-34347.341796875,1.96929623983942E-5,5.91208868002381E-7,1,0.999253354069792,40.0298881530762,1.99544693529828,17.6899991929531,0.000220362723907445,4.71762453269856E-5,0.25,6.50726674246779E-7,1.96348837423442E-5,7.85961863361958E-7,10.0024233,10.0024233,-34350.00390625,-34344.6796875,57.0487207331022,20.5811503861532,11.519473,0,0,0,40,4449,10.00525,-34347.341796875,,,,,,,,,,,,,0,,,,0,,,,,,10.0024233,,,,
,29085920.84,10.0013828,-29463.013671875,-8.23903799898751E-6,4.52183006485742E-7,1,0.999253354069792,40.0298881530762,1.99540793629311,17.6899991929531,-9.31984876827408E-5,-1.38613153039564E-5,0.25,2.47302404748057E-7,-8.21405254019285E-6,1.90984852703837E-7,10.0013828,10.0013828,-29472.900390625,-29453.126953125,57.139389641333,20.5791028742805,11.519473,0,0,0,40,4449,10.00405,-29463.013671875,,,,,,,,,,,,,0,,,,0,,,,,,10.0013828,,,,
,29086018.695,10.00037,-24572.9072265625,-3.57280705188294E-5,3.17331833119672E-7,1,0.999253354069792,40.0298881530762,1.99528395370548,17.6899991929531,-0.000401551578537587,-7.32662053403325E-5,0.25,-1.09963992441014E-7,-3.55937234560952E-5,-3.40965974192737E-7,10.00037,10.00037,-24580.30078125,-24565.513671875,57.2972786022176,20.5809076388411,12.278775,0,0,0,40,4449,10.00425,-24572.9072265625,,,,,,,,,,,,,0,,,,0.0049,,,,,,10.00037,,,,
,29086116.81,10.0006886,-19668.654296875,-6.35470236528685E-5,3.37704622871442E-7,1,0.999253354069792,40.0298881530762,1.99534347654402,17.6899991929531,-0.000714407607974641,-0.00012731541629924,0.25,4.67339120636735E-8,-6.32786370492468E-5,-3.45900319706127E-7,10.0006886,10.0006886,-19678.548828125,-19658.759765625,57.0463758475445,20.5796168382502,11.899124,0,0,0,40,4449,10.0043,-19668.654296875,,,,,,,,,,,,,0,,,,0.00245,,,,,,10.0006886,,,,
,29086215.32,10.0002432,-14743.7114257813,-8.94394252921477E-5,3.41800723866321E-7,1,0.999253354069792,40.0298881530762,1.99517686917502,17.6899991929531,-0.00100315803809816,-0.000189110543876026,0.25,-8.55814600910316E-7,-8.90150844289424E-5,-1.37406027128541E-6,10.0002432,10.0002432,-14746.3271484375,-14741.095703125,57.1534589546791,20.5822616448808,11.519473,0,0,0,40,4449,10.00375,-14743.7114257813,,,,,,,,,,,,,0,,,,-0.0049,,,,,,10.0002432,,,,
,29086312.945,9.9987478,-9863.98193359375,-0.000114577788086019,3.3762829866118E-7,1,0.999253354069792,40.0298881530762,1.9952864105054,17.6899991929531,-0.00128469666133233,-0.000241869801789377,0.25,-1.10985428171331E-6,-0.000113986727524107,-1.73252728964632E-6,9.9987478,9.9987478,-9868.7587890625,-9859.205078125,56.943200883006,20.5805209801317,12.278775,0,0,0,40,4449,10.00525,-9863.98193359375,,,,,,,,,,,,,0,,,,-0.00245,,,,,,9.9987478,,,,
,29086407.375,9.9989319,-5145.66455078125,-0.000135957841423028,2.84909748647455E-7,1,0.999253354069792,40.0298881530762,1.99521033676169,17.6899991929531,-0.00152402920024132,-0.000285747145150642,0.25,-1.2621405061769E-6,-0.000135209277074039,-1.95380333002787E-6,9.9989319,9.9989319,-5150.90283203125,-5140.42626953125,56.9854088230445,20.5806336992046,11.519473,0,0,0,40,4449,10.0062,-5145.66455078125,,,,,,,,,,,,,0,,,,-0.00245,,,,,,9.9989319,,,,
,29086503.58,10.0014639,-333.821304321289,-0.000104454608211711,3.9197084483977E-7,1,0.999253354069792,40.0298881530762,1.9951863966112,17.6899991929531,-0.00117026716910478,-0.000221092316014529,0.25,-1.14594190486972E-6,-0.000103850122262605,-1.64412644898259E-6,10.0014639,10.0014639,-341.467895507812,-326.174713134766,57.1558038402368,20.5812374047083,11.899124,0,0,0,40,4449,10.00385,-333.821304321289,,,,,,,,,,,,,0,,,,0,,,,,,10.0014639,,,,
,29086600.575,9.9999294,4509.72583007812,0.000136511943812596,3.43369924484047E-7,1,0.999253354069792,40.0298881530762,1.99531744686155,17.6899991929531,0.00153102232089821,0.000282591429669756,0.25,8.8845898006997E-7,0.00013575649072784,1.57881402532526E-6,9.9999294,9.9999294,4497.09228515625,4522.359375,57.034651419756,20.5779961375397,11.899124,0,0,0,40,4449,10.0051,4509.72583007812,,,,,,,,,,,,,0,,,,-0.0049,,,,,,9.9999294,,,,
,29086695.33,10.0003986,9246.02880859375,0.000116565348254809,3.47910721511357E-7,1,0.999253354069792,40.0298881530762,1.99519311005314,17.6899991929531,0.00130878689316148,0.000235225067322975,0.25,1.71258915177042E-7,0.000115963541417991,8.04286284160115E-7,10.0003986,10.0003986,9235.9892578125,9256.068359375,57.1690915250637,20.5809328110352,11.519473,0,0,0,40,4449,10.00605,9246.02880859375,,,,,,,,,,,,,0,,,,-0.00245,,,,,,10.0003986,,,,
,29086791.31,10.0009918,14043.7353515625,9.22938661895442E-5,3.74336881226016E-7,1,0.999253354069792,40.0298881530762,1.99533076260315,17.6899991929531,0.00103655543894891,0.000187473893523907,0.25,2.04691459821514E-7,9.18541867794362E-5,7.38034730023971E-7,10.0009918,10.0009918,14033.642578125,14053.828125,57.5388018146599,20.5793846161036,11.899124,0,0,0,40,4449,10.00485,14043.7353515625,,,,,,,,,,,,,0,,,,-0.00245,,,,,,10.0009918,,,,
,29086887.99,10.0007429,18876.0087890625,6.72297697429759E-5,3.41991641405872E-7,1,0.999253354069792,40.0298881530762,1.99524742026151,17.6899991929531,0.000755769175708189,0.00013438428039284,0.25,-7.2017021040382E-8,6.69408309010968E-5,3.39971087648029E-7,10.0007429,10.0007429,18871.05078125,18880.966796875,57.2034831799099,20.5809669909077,11.139823,0,0,0,40,4449,10.00365,18876.0087890625,,,,,,,,,,,,,0,,,,0.00245,,,,,,10.0007429,,,,
,29086985.25,10.0005484,23735.8291015625,4.02463281644497E-5,4.77393195867526E-7,1,0.999253354069792,40.0298881530762,1.99526129584918,17.6899991929531,0.000453056155750297,7.82447953214513E-5,0.25,-2.54718660960108E-7,4.00940158666048E-5,4.97022839134912E-9,10.0005484,10.0005484,23723.390625,23748.267578125,57.2433462343907,20.5780256025122,11.899124,0,0,0,40,4449,10.0042,23735.8291015625,,,,,,,,,,,,,0,,,,-0.0049,,,,,,10.0005484,,,,
,29087083.07,10.0005608,28626.3134765625,1.35354454847942E-5,3.79227776373002E-7,1,0.999253354069792,40.0298881530762,1.99509869003408,17.6899991929531,0.000153538174445077,2.01815903136297E-5,0.25,-6.35523277493073E-7,1.3494732531011E-5,-5.42770361783149E-7,10.0005608,10.0005608,28621.244140625,28631.3828125,57.2925888311022,20.5792138328229,11.899124,0,0,0,40,4449,10.0046,28626.3134765625,,,,,,,,,,,,,0,,,,-0.0049,,,,,,10.0005608,,,,
,29087181.445,9.9992876,33543.548828125,-1.50574100313329E-5,4.5134026047403E-7,1,0.999253354069792,40.0298881530762,1.9954974576564,17.6899991929531,-0.000166821194679515,-4.5304270856427E-5,0.25,-1.31848839771182E-6,-1.50060516114309E-5,-1.41904830751638E-6,9.9992876,9.9992876,33533.53125,33553.56640625,57.1018714724099,20.5766881736902,11.899124,0,0,0,40,4449,10.00425,33543.548828125,,,,,,,,,,,,,0,,,,0.0049,,,,,,9.9992876,,,,
,29087279.45,9.9989157,38438.375,-4.29416447005972E-5,6.06566673924885E-7,1,0.999253354069792,40.0298881530762,1.99568289331217,17.6899991929531,-0.000481197771867572,-0.000100578792533208,0.25,-1.20415658968449E-6,-4.28349642621528E-5,-1.50659627258104E-6,9.9989157,9.9989157,38430.828125,38445.921875,57.1941036376791,20.5717632347614,11.899124,0,0,0,40,4449,10.0048,38438.375,,,,,,,,,,,,,0,,,,0.00245,,,,,,9.9989157,,,,
,29087376.965,9.9981594,43313.431640625,-7.18670292781239E-5,7.13774017308932E-7,1,0.999253354069792,40.0298881530762,1.99584107565212,17.6899991929531,-0.000806270823380414,-0.000165843168525191,0.25,-1.77610451676688E-6,-7.17269272277486E-5,-2.29380485460789E-6,9.9981594,9.9981594,43303.32421875,43323.5390625,57.4364084786407,20.5741912611566,11.519473,0,0,0,40,4449,10.00535,43313.431640625,,,,,,,,,,,,,0,,,,0,,,,,,9.9981594,,,,
,29087472.805,9.99722,48103.841796875,-9.97117212299281E-5,8.88745481097403E-7,1,0.999253354069792,40.0298881530762,1.99571576581781,17.6899991929531,-0.00112125418923345,-0.000218502226944454,0.25,-1.41721228166729E-6,-9.95743851892029E-5,-2.14790546831361E-6,9.99722,9.99722,48096.11328125,48111.5703125,57.3183825722368,20.571833074677,11.899124,0,0,0,40,4449,10.00805,48103.841796875,,,,,,,,,,,,,0,,,,-0.0049,,,,,,9.99722,,,,
,29087568.475,9.9963617,52886.2734375,-0.000127753916575019,6.53017136776086E-7,1,0.999253354069792,40.0298881530762,1.99559462074573,17.6899991929531,-0.00143711290692955,-0.000280553331121567,0.25,-1.85091307952033E-6,-0.000127639405549056,-2.79598629661042E-6,9.9963617,9.9963617,52873.7578125,52898.7890625,57.2089545795445,20.5721989696563,11.519473,0,0,0,40,4449,10.0122,52886.2734375,,,,,,,,,,,,,0,,,,-0.00245,,,,,,9.9963617,,,,
,29087664.83,9.9960957,57701.263671875,-0.000155800957623686,1.0199956350583E-6,1,0.999253354069792,40.0298881530762,1.99554843397937,17.6899991929531,-0.00175259287120658,-0.000346793650675112,0.25,-2.65133952913571E-6,-0.00015573167145969,-3.80958795729554E-6,9.9960957,9.9960957,57696.25,57706.27734375,57.2425646058714,20.572464539574,11.519473,0,0,0,40,4449,10.0156,57701.263671875,,,,,,,,,,,,,0,,,,-0.00245,,,,,,9.9960957,,,,
,29087761.56,9.9958143,62537.224609375,-0.000186761113566387,1.03428623023007E-6,1,0.999253354069792,40.0298881530762,1.99553912240562,17.6899991929531,-0.00210121348633532,-0.000419179190650057,0.25,-3.46963625075914E-6,-0.000186760640737985,-4.8597456552361E-6,9.9958143,9.9958143,62529.67578125,62544.7734375,57.1167224142753,20.5726288622384,11.139823,0,0,0,40,4449,10.0189,62537.224609375,,,,,,,,,,,,,0,,,,0,,,,,,9.9958143,,,,
,29087858.69,9.9957123,67389.8984375,-0.000215454724233591,8.43334321947389E-7,1,0.999253354069792,40.0298881530762,1.99548012685581,17.6899991929531,-0.00242846467349494,-0.000464689452491479,0.25,-2.3185318253504E-6,-0.000215560330710768,-3.91763984144458E-6,9.9957123,9.9957123,67382.421875,67397.375,57.0831123879483,20.5747782351054,11.519473,0,0,0,40,4449,10.0227,67389.8984375,,,,,,,,,,,,,0,,,,0,,,,,,9.9957123,,,,
,29087953.09,9.9955015,72107.484375,-0.000243357265700799,8.00041706025938E-7,1,0.999253354069792,40.0298881530762,1.99529700511652,17.6899991929531,-0.00274198257473121,-0.000535247142212266,0.25,-3.53472815967153E-6,-0.000243567458441422,-5.33175169383597E-6,9.9955015,9.9955015,72104.9375,72110.03125,57.3770047111791,20.5710262764095,11.899124,0,0,0,40,4449,10.02625,72107.484375,,,,,,,,,,,,,0,,,,-0.0049,,,,,,9.9955015,,,,
,29088041.57,9.9960079,76531.1953125,-0.000269759831649774,1.09311884146756E-6,1,0.999253354069792,40.0298881530762,1.99516016007849,17.6899991929531,-0.00304269489268931,-0.000580485553148906,0.25,-2.78406200976143E-6,-0.000270097458767854,-4.75995373813094E-6,9.9960079,9.9960079,76523.671875,76538.71875,57.0330881627176,20.572490172771,11.519473,0,0,0,40,4449,10.0302,76531.1953125,,,,,,,,,,,,,0,,,,0,,,,,,9.9960079,,,,
,29088129.33,9.9957914,80919.5625,-0.000296939920160477,8.07923918642206E-7,1,0.999253354069792,40.0298881530762,1.99537181862095,17.6899991929531,-0.00335017215636079,-0.000642327514970301,0.25,-3.35872690164297E-6,-0.000297409024409938,-5.513819743133E-6,9.9957914,9.9957914,80912.1484375,80926.9765625,57.149550812083,20.5774118160714,11.139823,0,0,0,40,4449,10.0333,80919.5625,,,,,,,,,,,,,0,,,,0.00245,,,,,,9.9957914,,,,
,29088215.645,9.9954576,85235.05078125,-0.000324599228689254,8.1566842942837E-7,1,0.999253354069792,40.0298881530762,1.99540462538598,17.6899991929531,-0.00366129280452225,-0.000714262098635811,0.25,-4.74869478469712E-6,-0.000325205583980444,-7.08129500328143E-6,9.9954576,9.9954576,85230.1640625,85239.9375,57.1784710672945,20.5730253990005,11.139823,0,0,0,40,4449,10.0372,85235.05078125,,,,,,,,,,,,,0,,,,-0.00245,,,,,,9.9954576,,,,
,29088298.88,9.9953537,89395.77734375,-0.000347807553086315,1.06628023256181E-6,1,0.999253354069792,40.0298881530762,1.9954861818509,17.6899991929531,-0.00392900927682878,-0.000739584287919718,0.25,-2.8215095817218E-6,-0.000348572271810673,-5.28692578733836E-6,9.9953537,9.9953537,89388.3984375,89403.15625,57.2871174314676,20.5728063721552,11.519473,0,0,0,40,4449,10.0404,89395.77734375,,,,,,,,,,,,,0,,,,-0.00245,,,,,,9.9953537,,,,
,29088398.395,9.998621,86591.2578125,-0.000331985250091987,1.00236920940718E-6,1,0.999253354069792,40.0298881530762,1.99546514411948,17.6899991929531,-0.00374693432091529,-0.000720207700333251,0.25,-3.9468950204654E-6,-0.000332643266393779,-6.32199838663281E-6,9.998621,9.998621,86583.828125,86598.6875,57.2769562607176,20.5730477190767,11.139823,0,0,0,40,4449,10.0409,86591.2578125,,,,,,,,,,,,,0,,,,-0.00245,,,,,,9.998621,,,,
,29088482.375,10.0007801,82392.7890625,-0.000305466700389994,5.28247941575383E-7,1,0.999253354069792,40.0298881530762,1.99555999988059,17.6899991929531,-0.00344508445515476,-0.000671861158956198,0.25,-4.4326523815098E-6,-0.00030597536055937,-6.64355651491793E-6,10.0007801,10.0007801,82385.484375,82400.09375,57.1253203279868,20.5716836829496,11.519473,0,0,0,40,4449,10.03985,82392.7890625,,,,,,,,,,,,,0,,,,0.00245,,,,,,10.0007801,,,,
,29088572.97,10.0024223,77863.48828125,-0.000277206231377142,9.82823455298347E-7,1,0.999253354069792,40.0298881530762,1.99557517611804,17.6899991929531,-0.00312894224671612,-0.000589398558049427,0.25,-2.22183085734024E-6,-0.000277586603000325,-4.24594066304493E-6,10.0024223,10.0024223,77861.0078125,77865.96875,57.1995750373137,20.5719972282448,11.139823,0,0,0,40,4449,10.03715,77863.48828125,,,,,,,,,,,,,0,,,,0.0049,,,,,,10.0024223,,,,
,29088663.365,10.0032415,73345.08984375,-0.00025060869349018,9.52974624476075E-7,1,0.999253354069792,40.0298881530762,1.99557493748704,17.6899991929531,-0.00282712445621595,-0.000535919360450149,0.25,-2.28059685555555E-6,-0.000250860659341052,-4.12629696638289E-6,10.0032415,10.0032415,73337.6328125,73352.546875,57.3418314278138,20.575728753312,11.519473,0,0,0,40,4449,10.03515,73345.08984375,,,,,,,,,,,,,0,,,,0,,,,,,10.0032415,,,,
,29088754.3,10.0037088,68802.1953125,-0.000223280653897358,8.5925010373791E-7,1,0.999253354069792,40.0298881530762,1.99552679370866,17.6899991929531,-0.00251786764752673,-0.000477029194006981,0.25,-1.99750476843675E-6,-0.000223420413811671,-3.65211989600632E-6,10.0037088,10.0037088,68789.703125,68814.6875,57.4387533641984,20.5744324775806,11.519473,0,0,0,40,4449,10.03115,68802.1953125,,,,,,,,,,,,,0,,,,0,,,,,,10.0037088,,,,
,29088844.065,10.004261,64314.037109375,-0.000196262288667562,6.58949638523978E-7,1,0.999253354069792,40.0298881530762,1.9956214858093,17.6899991929531,-0.00220767673589633,-0.000445455439447177,0.25,-4.07828392211639E-6,-0.000196290302160906,-5.53859986002356E-6,10.004261,10.004261,64306.7265625,64321.34765625,57.3887291389676,20.5706793386645,11.519473,0,0,0,40,4449,10.0267,64314.037109375,,,,,,,,,,,,,0,,,,0.00245,,,,,,10.004261,,,,
,29088934.43,10.0040951,59798.193359375,-0.000169620665403466,7.22001202212361E-7,1,0.999253354069792,40.0298881530762,1.99563354646522,17.6899991929531,-0.0019080689862638,-0.000380078704103603,0.25,-3.10171792108219E-6,-0.00016957741620342,-4.36391811971029E-6,10.0040951,10.0040951,59788.1640625,59808.22265625,57.1300100991022,20.5720500389587,11.899124,0,0,0,40,4449,10.0253,59798.193359375,,,,,,,,,,,,,0,,,,0.00245,,,,,,10.0040951,,,,
,29089022.36,10.0041733,55402.8359375,-0.000143690386165389,7.0048506430062E-7,1,0.999253354069792,40.0298881530762,1.99555314359111,17.6899991929531,-0.00161544454632232,-0.000322881127997143,0.25,-2.72263580092456E-6,-0.000143592471152531,-3.78862172113698E-6,10.0041733,10.0041733,55390.11328125,55415.55859375,57.058100275333,20.5732144189777,11.519473,0,0,0,40,4449,10.02135,55402.8359375,,,,,,,,,,,,,0,,,,-0.00245,,,,,,10.0041733,,,,
,29089112.955,10.0040302,50872.48046875,-0.000116349182370495,7.66344575099727E-7,1,0.999253354069792,40.0298881530762,1.995382467942,17.6899991929531,-0.00130714987297821,-0.000262495910062528,0.25,-2.31474380358933E-6,-0.000116216783131749,-3.17188755723038E-6,10.0040302,10.0040302,50867.40234375,50877.55859375,57.1276652135445,20.5742330911107,11.899124,0,0,0,40,4449,10.0169,50872.48046875,,,,,,,,,,,,,0,,,,0,,,,,,10.0040302,,,,
,29089201.86,10.0038638,46429.83203125,-8.97986270324207E-5,7.39370161622186E-7,1,0.999253354069792,40.0298881530762,1.9951929117913,17.6899991929531,-0.00100695903814462,-0.000209997723440374,0.25,-2.45928797716746E-6,-8.965082959606E-5,-3.11268627733507E-6,10.003767,10.0039606,46424.953125,46434.7109375,57.1104693861214,20.5772362353398,11.519473,0,0,0,40,4449,10.0132,46429.83203125,,,,,,,,,,,,,0,,,,0.00245,,,,,,10.0038638,,,,
,29089291.88,10.0037913,41929.44140625,-6.4157927036595E-5,6.22589445480586E-7,1,0.999253354069792,40.0298881530762,1.99530500322276,17.6899991929531,-0.000718844135395005,-0.000151603782564341,0.25,-1.90826952138615E-6,-6.40212492860689E-5,-2.36730161455705E-6,10.0037088,10.0038738,41927.12890625,41931.75390625,57.210517836583,20.5786513325043,11.519473,0,0,0,40,4449,10.0113,41929.44140625,,,,,,,,,,,,,0,,,,0,,,,,,10.0037913,,,,
,29089381.21,10.003355,37466.826171875,-3.75001209452441E-5,6.34287862976664E-7,1,0.999253354069792,40.0298881530762,1.99524664300842,17.6899991929531,-0.000419267953002641,-9.23761944726314E-5,0.25,-1.45866660675573E-6,-3.74002471147547E-5,-1.72046610868046E-6,10.003355,10.003355,37459.4296875,37474.22265625,57.2253687784484,20.5816865839362,11.139823,0,0,0,40,4449,10.00835,37466.826171875,,,,,,,,,,,,,0,,,,-0.00245,,,,,,10.003355,,,,
,29089472.56,10.0025244,32899.255859375,-1.12142061949091E-5,6.57027454165398E-7,1,0.999253354069792,40.0298881530762,1.99512382267522,17.6899991929531,-0.000124688859751873,-3.10784119675161E-5,0.25,-7.46401962802509E-7,-1.1176842441879E-5,-8.2159863901159E-7,10.0025244,10.0025244,32886.66796875,32911.84375,57.1472059265253,20.5847974666575,11.519473,0,0,0,40,4449,10.0081,32899.255859375,,,,,,,,,,,,,0,,,,0,,,,,,10.0025244,,,,
,29089562.07,10.0015965,28429.31640625,1.38494373445904E-5,4.5970096113258E-7,1,0.999253354069792,40.0298881530762,1.99493306557539,17.6899991929531,0.000157599001080032,1.77792952499939E-5,0.25,-9.05153001264811E-7,1.38091931901481E-5,-8.09521657783358E-7,10.0015965,10.0015965,28424.3671875,28434.265625,56.9752476522945,20.5822945022441,11.519473,0,0,0,40,4449,10.0063,28429.31640625,,,,,,,,,,,,,0,,,,0,,,,,,10.0015965,,,,
,29089653.335,10.0007524,23863.9501953125,3.95966841670115E-5,5.0567179889649E-7,1,0.999253354069792,40.0298881530762,1.99509866373731,17.6899991929531,0.000447613194344603,6.63820291511413E-5,0.25,-1.19319940984272E-6,3.94534114347604E-5,-9.33813532228414E-7,10.0007524,10.0007524,23856.369140625,23871.53125,57.5364569291022,20.5798156673698,11.139823,0,0,0,40,4449,10.00535,23863.9501953125,,,,,,,,,,,,,0,,,,0.00245,,,,,,10.0007524,,,,
,29089744.585,10.0002422,19303.861328125,6.51179372469283E-5,3.6388386661959E-7,1,0.999253354069792,40.0298881530762,1.99496527788973,17.6899991929531,0.000732110757286492,0.000129310589001102,0.25,-1.46347775729313E-7,6.48412257400448E-5,2.54860159702E-7,10.0002422,10.0002422,19298.978515625,19308.744140625,57.5059734168522,20.5816124615506,11.519473,0,0,0,40,4449,10.00465,19303.861328125,,,,,,,,,,,,,0,,,,0,,,,,,10.0002422,,,,
,29089833.115,9.9999161,14881.6118164062,8.89936634557152E-5,3.90661622444711E-7,1,0.999253354069792,40.0298881530762,1.99524248040965,17.6899991929531,0.000999968004978896,0.000178290608303965,0.25,-2.91604024809363E-8,8.85776846362313E-5,4.91502278124647E-7,9.9999161,9.9999161,14876.822265625,14886.4013671875,57.3895107674868,20.5827023097775,11.899124,0,0,0,40,4449,10.00545,14881.6118164062,,,,,,,,,,,,,0,,,,0.00245,,,,,,9.9999161,,,,
,29089921.07,9.9995432,10486.5654296875,0.000111940010119323,3.65140008233775E-7,1,0.999253354069792,40.0298881530762,1.99505093632943,17.6899991929531,0.0012570432168481,0.000225068457403856,0.25,8.02831793747614E-8,0.000111373720733113,6.98900026814434E-7,9.9995432,9.9995432,10483.935546875,10489.1953125,57.3371416566984,20.5840440024119,11.139823,0,0,0,40,4449,10.0066,10486.5654296875,,,,,,,,,,,,,0,,,,-0.0049,,,,,,9.9995432,,,,
,29090008.035,9.9994593,6136.04370117187,0.000132708852676786,3.39389449116391E-7,1,0.999253354069792,40.0298881530762,1.99537608231719,17.6899991929531,0.00148983999925728,0.000267667439302227,0.25,2.16895575149482E-7,0.000131992536026915,9.07059180303702E-7,9.9994593,9.9994593,6126.18310546875,6145.904296875,57.5372385576215,20.5809709928094,11.519473,0,0,0,40,4449,10.0076,6136.04370117187,,,,,,,,,,,,,0,,,,0,,,,,,9.9994593,,,,
,29090097.265,10.0000849,1677.61181640625,0.000139993103704293,3.36264243753783E-7,1,0.999253354069792,40.0298881530762,1.99525461537855,17.6899991929531,0.00156991298158489,0.000288816429185759,0.25,8.55217457754468E-7,0.000139194990481298,1.53704304551399E-6,10.0000849,10.0000849,1667.48425292969,1687.73937988281,57.5473997283715,20.5815951316256,11.519473,0,0,0,40,4449,10.0065,1677.61181640625,,,,,,,,,,,,,0,,,,0,,,,,,10.0000849,,,,
,29090131.64,10.0029287,-0.479548871517181,7.34953758803222E-5,4.28947056230519E-7,1,0.999253354069792,40.0298881530762,1.99524417420251,17.6899991929531,0.00082562980750021,0.000143158023621511,0.25,-2.98075935842017E-7,7.30746123865192E-5,5.78793546052589E-8,10.0029287,10.0029287,-0.502384543418884,-0.456713199615479,57.0627900464484,20.5834647419206,11.899124,0,0,0,40,4417,10.0025,-0.479548871517181,,,,,,,,,,,,,0,,,,0.00245,,,,,,10.0029287,,,,