File: data/looselyPackedNP/sc-ios-11/ppms/rawdata/ES_S14_HYST_100K.DAT
[Header]
; VSM Data File (default extension .dat)
; Copyright (c) 2003-2013, Quantum Design, Inc. All rights reserved.
TITLE,
FILEOPENTIME,29113607.97,12/04/2018,7:07 am
BYAPP,VSM,2.0,2.0
INFO,PPMS VSM Option Release 1.4.10 Build 1,APPNAME
INFO,Quantum Design Linear Motor Servo Controller,MOTOR_MODULE_NAME
INFO,3101-100 M1,MOTOR_HW_VERSION
INFO,MMC1014,MOTOR_SERIAL_NUMBER
INFO,SRV No X-over 01.03.11,MOTOR_SOFTWARE_VERSION
INFO,Quantum Design VSM Detection Module,VSM_MODULE_NAME
INFO,3101-150 F0,VSM_HW_VERSION
INFO,VSM707,VSM_SERIAL_NUMBER
INFO,VSM No X-over 01.02.05 May 20 2008 13:51:47,VSM_SOFTWARE_VERSION
INFO,704,PREAMP_SERIAL_NUMBER
INFO,822,COIL_SERIAL_NUMBER
INFO,0,MOMENT_UNITS
INFO,Iron Oxide Spheres,SAMPLE_MATERIAL
INFO,10 nm diameter, collaboration Mainz,SAMPLE_COMMENT
INFO,,SAMPLE_MASS
INFO,,SAMPLE_VOLUME
INFO,,SAMPLE_MOLECULAR_WEIGHT
INFO,,SAMPLE_SIZE
INFO,,SAMPLE_SHAPE
DATATYPE,COMMENT,1
DATATYPE,TIME,2
STARTUPAXIS,X,2
STARTUPAXIS,Y1,5
[Data]
Comment,Time Stamp (sec),Temperature (K),Magnetic Field (Oe),Moment (emu),M. Std. Err. (emu),Transport Action,Averaging Time (sec),Frequency (Hz),Peak Amplitude (mm),Center Position (mm),Coil Signal' (mV),Coil Signal" (mV),Range (mV),M. Quad. Signal (emu),M. Raw' (emu),M. Raw" (emu),Min. Temperature (K),Max. Temperature (K),Min. Field (Oe),Max. Field (Oe),Mass (grams),Motor Lag (deg),Pressure (Torr),VSM Status (code),Motor Status (code),Measure Status (code),Measure Count,PPMS Status (code),System Temp. (K),System Field (Oe),Sample Position (deg),Bridge 1 Resistance (ohms),Bridge 1 Excitation (에),Bridge 2 Resistance (ohms),Bridge 2 Excitation (에),Bridge 3 Resistance (ohms),Bridge 3 Excitation (에),Bridge 4 Resistance (ohms),Bridge 4 Excitation (에),Signal 1 Vin (V),Signal 2 Vin (V),Digital Inputs (code),Drive 1 Iout (mA),Drive 1 Ipower (W),Drive 2 Iout (mA),Drive 2 Ipower (W),Pressure (),Map 20 (),Map 21 (),Map 22 (),Map 23 (),Map 24 (),Map 25 (),Map 26 (),Map 27 (),Map 28 (),Map 29 ()
,29113623.95,100.2627563,-0.106566414237022,,,2,,,,17.839999615252,,,,,,,100.2627563,100.2627563,-0.106566414237022,-0.106566414237022,,,22.149702,,,,-99999999,4369,100.2386,-0.106566414237022,,,,,,,,,,,,,,,,,,,,,,,100.2627563,,,,
,29113750.58,100.1769104,3289.12548828125,0.000134399669939735,3.88732529707801E-7,1,0.999253354069792,40.0298881530762,1.98497476208427,17.8299993276596,0.00151855312685312,0.000269180327142547,0.25,1.96341313263001E-7,0.000135155109785774,6.14315064744536E-7,100.1769104,100.1769104,3284.18896484375,3294.06201171875,56.9205336559483,20.5608872683643,21.770052,0,0,0,40,4449,100.02565,3289.12548828125,,,,,,,,,,,,,0,,,,-0.00245,,,,,,100.1769104,,,,
,29113821.86,100.1246567,6847.63134765625,0.000123403277600705,4.99077567754046E-7,1,0.999253354069792,40.0298881530762,1.98496683504161,17.8299993276596,0.00139397627650011,0.000249041961492567,0.25,3.4793092944323E-7,0.000124096901979557,7.31829031336538E-7,100.1246567,100.1246567,6838.0693359375,6857.193359375,56.8869236296214,20.5664784406766,22.529354,0,0,0,40,4449,99.9625,6847.63134765625,,,,,,,,,,,,,0,,,,0,,,,,,100.1246567,,,,
,29113915.64,100.0722198,11533.357421875,0.000102300768461371,6.54334689690262E-7,1,0.999253354069792,40.0298881530762,1.98479423961876,17.8299993276596,0.00115678580646055,0.000199190496250055,0.25,-3.51691503704758E-7,0.000102878455697774,-3.83334681623856E-8,100.0722198,100.0722198,11525.9638671875,11540.7509765625,57.0283983916022,20.565767655473,21.770052,0,0,0,40,4449,99.9189,11533.357421875,,,,,,,,,,,,,0,,,,-0.00245,,,,,,100.0722198,,,,
,29114025.145,100.0362625,17008.119140625,7.42873518871857E-5,9.74154228464685E-7,1,0.999253354069792,40.0298881530762,1.98487620421295,17.8299993276596,0.000839772744361212,0.000146280979869746,0.25,-1.09987940280468E-7,7.47070414558895E-5,1.17087283298824E-7,100.0362625,100.0362625,16993.25390625,17022.984375,57.2034831799099,20.5659807126365,22.529354,0,0,0,40,4449,99.89125,17008.119140625,,,,,,,,,,,,,0,,,,0,,,,,,100.0362625,,,,
,29114139.035,100.015358,22700.505859375,4.45442135226182E-5,9.20094772689426E-7,1,0.999253354069792,40.0298881530762,1.98468397181891,17.8299993276596,0.000505353308794735,7.71745150389239E-5,0.25,-9.96985727727361E-7,4.47991236673818E-5,-8.66985364137632E-7,100.015358,100.015358,22695.4296875,22705.58203125,57.2808644033138,20.5710862475687,22.149702,0,0,0,40,4449,99.8781,22700.505859375,,,,,,,,,,,,,0,,,,0,,,,,,100.015358,,,,
,29114248.735,100.0058289,28185.4306640625,1.44525235917097E-5,1.10214021204212E-6,1,0.999253354069792,40.0298881530762,1.98462003197122,17.8299993276596,0.000162238244444229,3.48399308206692E-5,0.25,5.44135447305955E-7,1.45327355936356E-5,5.90927304484967E-7,100.0058289,100.0058289,28172.87890625,28197.982421875,57.0229269919676,20.5707515990954,22.149702,0,0,0,40,4449,99.8758,28185.4306640625,,,,,,,,,,,,,0,,,,0,,,,,,100.0058289,,,,
,29114355.77,100.002533,33534.517578125,-1.39693975219588E-5,1.08640929067708E-6,1,0.999253354069792,40.0298881530762,1.9845990642833,17.8299993276596,-0.000157690591355143,-2.86895767887251E-5,0.25,-8.50355869643251E-8,-1.40483923014149E-5,-1.27478216705155E-7,100.002533,100.002533,33524.3828125,33544.65234375,56.8056342636214,20.574505928928,21.770052,0,0,0,40,4449,99.8736,33534.517578125,,,,,,,,,,,,,0,,,,0,,,,,,100.002533,,,,
,29114460.38,100.00163265,38759.3828125,-4.40375983612287E-5,9.76574109270648E-7,1,0.999253354069792,40.0298881530762,1.98456391746021,17.8299993276596,-0.000496591144991015,-9.33684456418173E-5,0.25,-5.28009919676318E-7,-4.42862558415487E-5,-6.62375785675258E-7,100.0013885,100.0018768,38746.9921875,38771.7734375,57.0018230219483,20.5738005230165,22.149702,0,0,0,40,4449,99.87405,38759.3828125,,,,,,,,,,,,,0,,,,0,,,,,,100.00163265,,,,
,29114564.09,100.0017395,43944.16796875,-7.17910096095275E-5,1.53486248310853E-6,1,0.999253354069792,40.0298881530762,1.98457228058378,17.8299993276596,-0.000807719468804665,-0.000162715930438153,0.25,-1.79165201695374E-6,-7.21942821548081E-5,-2.01452257691531E-6,100.0017395,100.0017395,43934.29296875,43954.04296875,56.9674313671022,20.5755406040642,22.529354,0,0,0,40,4449,99.87075,43944.16796875,,,,,,,,,,,,,0,,,,-0.00245,,,,,,100.0017395,,,,
,29114659.875,100.0028992,48731.861328125,-0.000101638474582316,1.84969126258889E-6,1,0.999253354069792,40.0298881530762,1.98454002785056,17.8299993276596,-0.00114629914088687,-0.000214565523632432,0.25,-1.14042902202554E-6,-0.000102214413579401,-1.44606192221941E-6,100.0028992,100.0028992,48726.8671875,48736.85546875,57.281646031833,20.5741568299892,22.529354,0,0,0,40,4449,99.8687,48731.861328125,,,,,,,,,,,,,0,,,,-0.00245,,,,,,100.0028992,,,,
,29114745.275,100.0035629,53000.30078125,-0.000125256868544478,1.30253450995772E-6,1,0.999253354069792,40.0298881530762,1.98443065143284,17.8299993276596,-0.00140888943504429,-0.000285595039496008,0.25,-3.28205798529034E-6,-0.000125962102244152,-3.66727188721814E-6,100.0035629,100.0035629,52990.22265625,53010.37890625,57.3590272552368,20.5756749335144,21.770052,0,0,0,40,4449,99.86545,53000.30078125,,,,,,,,,,,,,0,,,,-0.00245,,,,,,100.0035629,,,,
,29114829.055,100.0038681,57187.626953125,-0.000148204517858801,1.82535903065272E-6,1,0.999253354069792,40.0298881530762,1.98431106139769,17.8299993276596,-0.00167161125768305,-0.000311185970111898,0.25,-1.52162470378717E-6,-0.00014904696427308,-1.96142276059254E-6,100.0038681,100.0038681,57182.65234375,57192.6015625,57.0213637349291,20.5759178366871,22.529354,0,0,0,40,4449,99.86235,57187.626953125,,,,,,,,,,,,,0,,,,0,,,,,,100.0038681,,,,
,29114911.07,100.0046463,61288.498046875,-0.000170295028828138,1.71251472410484E-6,1,0.999253354069792,40.0298881530762,1.9844108887435,17.8299993276596,-0.00192257039186391,-0.000347948171615899,0.25,-8.98067984597923E-7,-0.000171266734095877,-1.39572758067623E-6,100.0046463,100.0046463,61281.09765625,61295.8984375,56.9400743689291,20.5751538454782,22.149702,0,0,0,40,4449,99.85825,61288.498046875,,,,,,,,,,,,,0,,,,0.0049,,,,,,100.0046463,,,,
,29114986.425,100.004158,65051.935546875,-0.00019349737980192,2.4067725470969E-6,1,0.999253354069792,40.0298881530762,1.9843802369228,17.8299993276596,-0.0021793072494719,-0.000424929416324993,0.25,-3.64086555259914E-6,-0.00019459522206127,-4.2183420655899E-6,100.004158,100.004158,65039.45703125,65064.4140625,57.3449579418907,20.5758812900241,22.149702,0,0,0,40,4449,99.8585,65051.935546875,,,,,,,,,,,,,0,,,,0,,,,,,100.004158,,,,
,29115066.95,100.0042572,69077.453125,-0.000217276705479369,2.36904913741066E-6,1,0.999253354069792,40.0298881530762,1.98435721171064,17.8299993276596,-0.00245318951931729,-0.000442551011952912,0.25,-1.03019525326211E-6,-0.00021851977803168,-1.65754162339947E-6,100.0042572,100.0042572,69072.4921875,69082.4140625,57.2019199228714,20.5761474061522,21.770052,0,0,0,40,4449,99.8563,69077.453125,,,,,,,,,,,,,0,,,,0.0049,,,,,,100.0042572,,,,
,29115143.9,100.0044022,72925.72265625,-0.000240500079051831,2.66736381301188E-6,1,0.999253354069792,40.0298881530762,1.98431467425943,17.8299993276596,-0.00270933492643701,-0.000524166358562645,0.25,-4.18129843833561E-6,-0.000241868943402613,-4.88940760622178E-6,100.0044022,100.0044022,72915.828125,72935.6171875,57.2183341217753,20.5775276536702,21.770052,0,0,0,40,4449,99.85025,72925.72265625,,,,,,,,,,,,,0,,,,0,,,,,,100.0044022,,,,
,29115212.01,100.0040207,76329.60546875,-0.000257357560592674,2.21933304122989E-6,1,0.999253354069792,40.0298881530762,1.9843829649761,17.8299993276596,-0.00290386575655622,-0.00053521813772917,0.25,-2.20276193592527E-6,-0.000258830354672274,-2.9438745003913E-6,100.0040207,100.0040207,76324.3671875,76334.84375,57.169873153583,20.5770410745046,22.149702,0,0,0,40,4449,99.84875,76329.60546875,,,,,,,,,,,,,0,,,,0,,,,,,100.0040207,,,,
,29115283.525,100.0056381,79905.1015625,-0.000279479465848232,2.64126827247931E-6,1,0.999253354069792,40.0298881530762,1.9842868187784,17.8299993276596,-0.00315293332660073,-0.000583568674125888,0.25,-2.60569171934279E-6,-0.000281079951174184,-3.40768492100372E-6,100.0056381,100.0056381,79897.53125,79912.671875,57.1784710672945,20.577020739627,22.149702,0,0,0,40,4449,99.844,79905.1015625,,,,,,,,,,,,,0,,,,-0.00245,,,,,,100.0056381,,,,
,29115356.93,100.0055771,83574.08984375,-0.000299708975341637,2.26178841794797E-6,1,0.999253354069792,40.0298881530762,1.98458900192874,17.8299993276596,-0.00338492004436154,-0.000607346539916157,0.25,-1.15676455582897E-6,-0.000301431767834222,-2.00290700244244E-6,100.0055771,100.0055771,83566.3359375,83581.84375,57.1214121853907,20.5722531036146,22.529354,0,0,0,40,4449,99.84035,83574.08984375,,,,,,,,,,,,,0,,,,-0.00245,,,,,,100.0055771,,,,
,29115425.745,100.0063629,87012.91015625,-0.000321463265564518,2.90854157881474E-6,1,0.999253354069792,40.0298881530762,1.98454278530914,17.8299993276596,-0.00362244615253414,-0.000697631287555679,0.25,-5.33415057598725E-6,-0.000323301525364571,-6.26083669277699E-6,100.0063629,100.0063629,87010.40625,87015.4140625,57.3691884259868,20.5749467345403,22.149702,0,0,0,40,4449,99.8349,87012.91015625,,,,,,,,,,,,,0,,,,0,,,,,,100.0063629,,,,
,29115513.425,100.0033722,89662.12109375,-0.000336022786755647,1.7883915987586E-6,1,0.999253354069792,40.0298881530762,1.9844470525643,17.8299993276596,-0.00379303455819048,-0.00069111836233591,0.25,-2.20984541878064E-6,-0.000337955204779207,-3.15545248706278E-6,100.0033722,100.0033722,89649.703125,89674.5390625,57.0995265868522,20.5756828280636,22.529354,0,0,0,40,4449,99.83455,89662.12109375,,,,,,,,,,,,,0,,,,0.00245,,,,,,100.0033722,,,,
,29115590.925,100.0012283,85791.484375,-0.000314441848164873,2.11669094990796E-6,1,0.999253354069792,40.0298881530762,1.98432899503431,17.8299993276596,-0.00354159420292823,-0.000690066864907353,0.25,-5.90145240582826E-6,-0.000316237423616182,-6.81338883986675E-6,100.0012283,100.0012283,85784.2578125,85798.7109375,56.9377294833714,20.5768760687555,22.909004,0,0,0,40,4449,99.83645,85791.484375,,,,,,,,,,,,,0,,,,0,,,,,,100.0012283,,,,
,29115664.315,99.9986496,82122.484375,-0.000293059935724779,1.80463888259982E-6,1,0.999253354069792,40.0298881530762,1.98437785668373,17.8299993276596,-0.00330647325972307,-0.000610955481124373,0.25,-2.64644111236692E-6,-0.000294739542961001,-3.48436550423272E-6,99.9986496,99.9986496,82104.9375,82140.03125,57.1300100991022,20.5763445951453,22.529354,0,0,0,40,4449,99.83425,82122.484375,,,,,,,,,,,,,0,,,,0,,,,,,99.9986496,,,,
,29115747.86,99.9979095,77946.12109375,-0.000269693224080979,2.43926220997402E-6,1,0.999253354069792,40.0298881530762,1.98449610092211,17.8299993276596,-0.00304214882587046,-0.000567053573138885,0.25,-2.85415602167259E-6,-0.000271235811183298,-3.63225318143578E-6,99.9979095,99.9979095,77936.0703125,77956.171875,57.119067299833,20.5767228508523,22.149702,0,0,0,40,4449,99.839,77946.12109375,,,,,,,,,,,,,0,,,,0.00245,,,,,,99.9979095,,,,
,29115827.74,99.9972153,73951.9140625,-0.000243451976476974,2.47576887411465E-6,1,0.999253354069792,40.0298881530762,1.98448574012621,17.8299993276596,-0.00274701306635743,-0.000506750516811404,0.25,-2.11917547633055E-6,-0.000244844079146258,-2.82292557879762E-6,99.9972153,99.9972153,73941.9453125,73961.8828125,57.1346998702176,20.5766311132421,22.529354,0,0,0,40,4449,99.8401,73951.9140625,,,,,,,,,,,,,0,,,,0,,,,,,99.9972153,,,,
,29115913.555,99.996109,69661.08203125,-0.000219201749363592,2.02859026334359E-6,1,0.999253354069792,40.0298881530762,1.98443807807663,17.8299993276596,-0.00247015263199762,-0.000474240643959754,0.25,-3.49543729219545E-6,-0.000220449015864974,-4.14204146616044E-6,99.996109,99.996109,69648.703125,69673.4609375,57.2019199228714,20.5787138933566,22.149702,0,0,0,40,4449,99.8424,69661.08203125,,,,,,,,,,,,,0,,,,-0.0049,,,,,,99.996109,,,,
,29116002.435,99.9943085,65218.337890625,-0.000192934706216996,2.98364780500117E-6,1,0.999253354069792,40.0298881530762,1.9843197893635,17.8299993276596,-0.00217153803443652,-0.000431483605770589,0.25,-4.3207923183842E-6,-0.000194027431693304,-4.90049525536319E-6,99.9943085,99.9943085,65210.8515625,65225.82421875,57.1776894387753,20.5776468463695,22.909004,0,0,0,40,4449,99.8494,65218.337890625,,,,,,,,,,,,,0,,,,-0.00245,,,,,,99.9943085,,,,
,29116080.68,99.9949036,61306.9453125,-0.000171457143087384,2.1925519684694E-6,1,0.999253354069792,40.0298881530762,1.98427747875548,17.8299993276596,-0.00193190566058249,-0.000371153090060023,0.25,-2.74965822695049E-6,-0.000172430162845311,-3.26130441565803E-6,99.9949036,99.9949036,61302.00390625,61311.88671875,56.9455457685637,20.5786919585175,22.529354,0,0,0,40,4449,99.8527,61306.9453125,,,,,,,,,,,,,0,,,,0,,,,,,99.9949036,,,,
,29116172.6,99.9927406,56714.28125,-0.000144911314657532,2.08049601660732E-6,1,0.999253354069792,40.0298881530762,1.98422961656552,17.8299993276596,-0.00162849184332756,-0.000337922553269206,0.25,-4.46684471463617E-6,-0.000145726271131434,-4.91419319543187E-6,99.9926376,99.9928436,56704.40234375,56724.16015625,57.1745629246983,20.5788008804295,22.149702,0,0,0,40,4449,99.85925,56714.28125,,,,,,,,,,,,,0,,,,0,,,,,,99.9927406,,,,
,29116254.84,99.9936066,52603.560546875,-0.000121062516938169,2.31718796218542E-6,1,0.999253354069792,40.0298881530762,1.9842584262021,17.8299993276596,-0.00136770210632056,-0.000241240944290468,0.25,-9.49149281533398E-8,-0.000121753078673847,-4.49866322693814E-7,99.9936066,99.9936066,52596.01953125,52611.1015625,56.9377294833714,20.5791558880667,22.909004,0,0,0,40,4449,99.8651,52603.560546875,,,,,,,,,,,,,0,,,,0,,,,,,99.9936066,,,,
,29116353.855,99.9937286,47656.025390625,-9.24093985825545E-5,2.05522172091891E-6,1,0.999253354069792,40.0298881530762,1.98425749763086,17.8299993276596,-0.00104281401225335,-0.000190808443489776,0.25,-6.60594445629951E-7,-9.29339892784888E-5,-9.36731467557726E-7,99.9937286,99.9937286,47648.34765625,47663.703125,57.5106631879676,20.5800833235175,22.909004,0,0,0,40,4449,99.8691,47656.025390625,,,,,,,,,,,,,0,,,,-0.00245,,,,,,99.9937286,,,,
,29116450.505,99.9941483,42823.24609375,-6.68594221787618E-5,1.46092693092268E-6,1,0.999253354069792,40.0298881530762,1.98422298033607,17.8299993276596,-0.000750771846770595,-0.000159111982268137,0.25,-2.34088055238876E-6,-6.72328744381389E-5,-2.55255502573335E-6,99.9941483,99.9941483,42810.90625,42835.5859375,57.3746598256215,20.580621189984,22.149702,0,0,0,40,4449,99.8739,42823.24609375,,,,,,,,,,,,,0,,,,-0.00245,,,,,,99.9941483,,,,
,29116550.83,99.99214555,37810.9921875,-3.85698441021577E-5,1.77703387383615E-6,1,0.999253354069792,40.0298881530762,1.98418684789552,17.8299993276596,-0.000433416557209576,-8.99470163022134E-5,0.25,-1.18687966793472E-6,-3.87854131568985E-5,-1.30880844505933E-6,99.9920731,99.992218,37803.65234375,37818.33203125,57.2910255740638,20.5804375158178,22.149702,0,0,0,40,4449,99.88155,37810.9921875,,,,,,,,,,,,,0,,,,0.00245,,,,,,99.99214555,,,,
,29116651.24,99.9920807,32791.275390625,-1.12778138748099E-5,1.41854443383073E-6,1,0.999253354069792,40.0298881530762,1.98409871091138,17.8299993276596,-0.000124442829031505,-3.92879397574571E-5,0.25,-1.49651867390001E-6,-1.13372888980007E-5,-1.53890535997409E-6,99.9920807,99.9920807,32776.359375,32806.19140625,57.2925888311022,20.5818362942263,22.529354,0,0,0,40,4449,99.89195,32791.275390625,,,,,,,,,,,,,0,,,,-0.00245,,,,,,99.9920807,,,,
,29116754.165,99.9913559,27649.109375,1.91811111043677E-5,1.20099273206306E-6,1,0.999253354069792,40.0298881530762,1.98430651237397,17.8299993276596,0.000220286778907971,1.77714705243073E-5,0.25,-1.79677705018949E-6,1.92951851920918E-5,-1.74892632964344E-6,99.9913559,99.9913559,27644.1015625,27654.1171875,57.4364084786407,20.5823738390813,22.149702,0,0,0,40,4449,99.89905,27649.109375,,,,,,,,,,,,,0,,,,0,,,,,,99.9913559,,,,
,29116852.805,99.9930725,22719.185546875,4.38400969825388E-5,8.5350546371518E-7,1,0.999253354069792,40.0298881530762,1.98431800821035,17.8299993276596,0.000495473186749305,8.62141357042224E-5,0.25,-7.19439180762162E-8,4.40882597055654E-5,6.10749063793866E-8,99.9930725,99.9930725,22706.482421875,22731.888671875,56.9213152844676,20.583179417547,22.149702,0,0,0,40,4449,99.9064,22719.185546875,,,,,,,,,,,,,0,,,,0.00245,,,,,,99.9930725,,,,
,29116955.885,99.99089815,17566.7421875,7.10281505165424E-5,8.43313900292143E-7,1,0.999253354069792,40.0298881530762,1.98427053570435,17.8299993276596,0.000803737167405777,0.000133905073011477,0.25,-6.28709647241369E-7,7.1431199998861E-5,-4.14781927215941E-7,99.9908905,99.9909058,17554.283203125,17579.201171875,57.3207274577945,20.5832106852273,22.909004,0,0,0,40,4449,99.91425,17566.7421875,,,,,,,,,,,,,0,,,,0,,,,,,99.99089815,,,,
,29117054.265,99.9934616,12649.3095703125,9.71341730116126E-5,5.9367966754512E-7,1,0.999253354069792,40.0298881530762,1.98430758620487,17.8299993276596,0.00109762964264896,0.000191819828547121,0.25,-9.16788429489626E-8,9.76822625209494E-5,2.0685473391201E-7,99.9934616,99.9934616,12637.064453125,12661.5546875,57.2597604332945,20.5800476672577,22.909004,0,0,0,40,4449,99.919,12649.3095703125,,,,,,,,,,,,,0,,,,0,,,,,,99.9934616,,,,
,29117157.02,99.9906006,7514.44091796875,0.00012088190570652,4.26473526377413E-7,1,0.999253354069792,40.0298881530762,1.98442849878281,17.8299993276596,0.00136526553236023,0.000243204301115135,0.25,2.80079538386261E-7,0.000121561900890655,6.55754788931972E-7,99.9906006,99.9906006,7509.54833984375,7519.33349609375,57.0588819038522,20.5819721974496,22.529354,0,0,0,40,4449,99.931,7514.44091796875,,,,,,,,,,,,,0,,,,0,,,,,,99.9906006,,,,
,29117255.755,99.99248885,2576.51330566406,0.000134432841171423,3.48588267411891E-7,1,0.999253354069792,40.0298881530762,1.98427113906887,17.8299993276596,0.00151814841560831,0.000270671502049406,0.25,3.29659055757749E-7,0.000135188157690137,7.49379445057364E-7,99.992485,99.9924927,2566.48803710938,2586.53857421875,57.4582940771792,20.5829927215838,22.149702,0,0,0,40,4449,99.9378,2576.51330566406,,,,,,,,,,,,,0,,,,0.00245,,,,,,99.99248885,,,,
,29117356.085,99.9958801,-2431.63500976562,-0.000133224136797963,3.43433501502332E-7,1,0.999253354069792,40.0298881530762,1.98427318246456,17.8299993276596,-0.00150375368491017,-0.000272483054625837,0.25,-7.02404601515081E-7,-0.000133971474281404,-1.12048777389179E-6,99.9958801,99.9958801,-2436.42041015625,-2426.849609375,57.4129596230638,20.5829540178718,22.529354,0,0,0,40,4449,99.94125,-2431.63500976562,,,,,,,,,,,,,0,,,,-0.00245,,,,,,99.9958801,,,,
,29117457.32,99.99958035,-7493.267578125,-0.000120145418880259,4.48934431869765E-7,1,0.999253354069792,40.0298881530762,1.98417059210155,17.8299993276596,-0.00135540497000632,-0.000249511168137319,0.25,-9.70500665927327E-7,-0.000120819132721246,-1.34772962208752E-6,99.9992599,99.9999008,-7505.63671875,-7480.8984375,57.6411951506792,20.5847100187866,22.529354,0,0,0,40,4449,99.94075,-7493.267578125,,,,,,,,,,,,,0,,,,-0.00245,,,,,,99.99958035,,,,
,29117542.43,100.004425,-11749.2890625,-0.000100859694486718,6.75492065483225E-7,1,0.999253354069792,40.0298881530762,1.98425387039805,17.8299993276596,-0.00113885376000548,-0.000203973960092148,0.25,-3.29651682112079E-7,-0.000101427373146531,-6.42252340852724E-7,100.004425,100.004425,-11759.2265625,-11739.3515625,57.0737328457176,20.5836818783767,22.529354,0,0,0,40,4449,99.9344,-11749.2890625,,,,,,,,,,,,,0,,,,0,,,,,,100.004425,,,,
,29117631.99,100.0076981,-16224.556640625,-7.84127996248009E-5,7.19241971614125E-7,1,0.999253354069792,40.0298881530762,1.98407302110956,17.8299993276596,-0.000886215720722247,-0.000153492556740188,0.25,1.91604151463939E-7,-7.88560448666715E-5,-4.772017632669E-8,100.0076981,100.0076981,-16236.810546875,-16212.302734375,57.3559007411599,20.5869302827392,22.149702,0,0,0,40,4449,99.92785,-16224.556640625,,,,,,,,,,,,,0,,,,0,,,,,,100.0076981,,,,
,29117723.3,100.0103607,-20786.8916015625,-5.46077346143954E-5,7.97901513095779E-7,1,0.999253354069792,40.0298881530762,1.98416882469775,17.8299993276596,-0.000615671005946425,-0.00011563309593193,0.25,-6.40433418084684E-7,-5.49144453654523E-5,-8.10601719453667E-7,100.0103607,100.0103607,-20799.501953125,-20774.28125,57.1917587521214,20.5857587820791,22.909004,0,0,0,40,4449,99.9197,-20786.8916015625,,,,,,,,,,,,,0,,,,-0.00245,,,,,,100.0103607,,,,
,29117813.345,100.0101013,-25286.630859375,-3.11760005770479E-5,8.29646986631267E-7,1,0.999253354069792,40.0298881530762,1.98417080521209,17.8299993276596,-0.000352925527366459,-5.78711990775351E-5,0.25,3.54820133674584E-7,-3.13535238211113E-5,2.62252875076661E-7,100.0101013,100.0101013,-25296.57421875,-25276.6875,57.4278105649292,20.5841193710634,22.909004,0,0,0,40,4449,99.91095,-25286.630859375,,,,,,,,,,,,,0,,,,0,,,,,,100.0101013,,,,
,29117915.475,100.0100708,-30391.3974609375,-3.08348602421521E-6,9.33593078709921E-7,1,0.999253354069792,40.0298881530762,1.98421902913394,17.8299993276596,-3.60348029733007E-5,6.93582112232941E-7,0.25,6.03050051388462E-7,-3.10278162570949E-6,5.97172566221601E-7,100.0100708,100.0100708,-30403.744140625,-30379.05078125,57.3684067974676,20.5863486605687,22.529354,0,0,0,40,4449,99.8994,-30391.3974609375,,,,,,,,,,,,,0,,,,0.00245,,,,,,100.0100708,,,,
,29118009.48,100.0112686,-35091.103515625,2.21791746050779E-5,1.38064119216205E-6,1,0.999253354069792,40.0298881530762,1.98416478410885,17.8299993276596,0.000248353620507774,5.66981234391678E-5,0.25,1.12269657875292E-6,2.23017016219738E-5,1.19553058667516E-6,100.0112686,100.0112686,-35106.2421875,-35075.96484375,57.1300100991022,20.5868285331176,22.149702,0,0,0,40,4449,99.8939,-35091.103515625,,,,,,,,,,,,,0,,,,0.0049,,,,,,100.0112686,,,,
,29118111.54,100.0101013,-40191.009765625,5.22510801745362E-5,1.28563125166997E-6,1,0.999253354069792,40.0298881530762,1.984372663921,17.8299993276596,0.00058708940126916,0.000122550747584902,0.25,1.6691692060061E-6,5.25431441048235E-5,1.834207758638E-6,100.0101013,100.0101013,-40198.6484375,-40183.37109375,57.6419767791984,20.5846696343443,22.909004,0,0,0,40,4449,99.881,-40191.009765625,,,,,,,,,,,,,0,,,,0,,,,,,100.0101013,,,,
,29118203.99,100.00984955,-44813.5390625,7.84333460133031E-5,1.66135048173024E-6,1,0.999253354069792,40.0298881530762,1.98430730286953,17.8299993276596,0.000884293733009185,0.000166629058860653,0.25,9.73606736579343E-7,7.88769610722036E-5,1.21121083128786E-6,100.0093689,100.0103302,-44821.296875,-44805.78125,57.0260535060445,20.5846081327132,22.909004,0,0,0,40,4449,99.8744,-44813.5390625,,,,,,,,,,,,,0,,,,0.00245,,,,,,100.00984955,,,,
,29118302.94,100.010849,-49756.13671875,0.000105664878122268,1.5487709332469E-6,1,0.999253354069792,40.0298881530762,1.9841977211479,17.8299993276596,0.00119043380990496,0.000229187613515229,0.25,1.73107567628027E-6,0.000106262190579869,2.05152390676458E-6,100.010849,100.010849,-49763.64453125,-49748.62890625,57.2589788047753,20.5858167683918,22.529354,0,0,0,40,4449,99.86155,-49756.13671875,,,,,,,,,,,,,0,,,,-0.0049,,,,,,100.010849,,,,
,29118407.83,100.009613,-54997.462890625,0.000133254127444288,1.64433717174572E-6,1,0.999253354069792,40.0298881530762,1.98430263195832,17.8299993276596,0.00150172616520247,0.000286889221968195,0.25,1.99496517905478E-6,0.000134009197118383,2.39522851827361E-6,100.009613,100.009613,-55010.0234375,-54984.90234375,57.6325972369676,20.5839748904696,22.909004,0,0,0,40,4449,99.853,-54997.462890625,,,,,,,,,,,,,0,,,,0,,,,,,100.009613,,,,
,29118511.98,100.0098724,-60204.49609375,0.000165464251698277,1.44498015127865E-6,1,0.999253354069792,40.0298881530762,1.98457996343081,17.8299993276596,0.00186886338622464,0.000334214401674995,0.25,5.27520901732274E-7,0.000166409016521151,1.00992390082408E-6,100.0098724,100.0098724,-60212.015625,-60196.9765625,57.1558038402368,20.5835432007996,22.529354,0,0,0,40,4449,99.84575,-60204.49609375,,,,,,,,,,,,,0,,,,-0.00245,,,,,,100.0098724,,,,
,29118615.085,100.0073318,-65356.826171875,0.000195281971970221,1.88959901722049E-6,1,0.999253354069792,40.0298881530762,1.98439720664947,17.8299993276596,0.00220446920441424,0.000400112382780315,0.25,1.13120653971312E-6,0.000196397268164089,1.6993816037797E-6,100.0073318,100.0073318,-65364.37109375,-65349.28125,57.1972301517561,20.5866444510752,22.909004,0,0,0,40,4449,99.83805,-65356.826171875,,,,,,,,,,,,,0,,,,0,,,,,,100.0073318,,,,
,29118719.915,100.0079651,-70595.8359375,0.00022555603768453,2.25706360684052E-6,1,0.999253354069792,40.0298881530762,1.98447211780877,17.8299993276596,0.00254184892557894,0.00048773322714986,0.25,3.5741787670153E-6,0.000226839782883753,4.23867517713163E-6,100.0079651,100.0079651,-70605.8359375,-70585.8359375,57.0964000727753,20.5830838528291,22.909004,0,0,0,40,4449,99.8283,-70595.8359375,,,,,,,,,,,,,0,,,,-0.0049,,,,,,100.0079651,,,,
,29118823.695,100.0082054,-75782.72265625,0.000251467664913188,2.01164049843782E-6,1,0.999253354069792,40.0298881530762,1.98471682645114,17.8299993276596,0.00284307279315794,0.000493343472188235,0.25,-4.77112740796675E-7,0.000252913820220704,2.32789215646071E-7,100.0081787,100.0082321,-75792.7578125,-75772.6875,57.1065612435253,20.5811624590687,22.909004,0,0,0,40,4449,99.8228,-75782.72265625,,,,,,,,,,,,,0,,,,0.0049,,,,,,100.0082054,,,,
,29118927.665,100.0084915,-80977.69921875,0.000284579652577443,2.42859367531476E-6,1,0.999253354069792,40.0298881530762,1.98479433126354,17.8299993276596,0.0032140298002451,0.000578573221503243,0.25,1.25705269007216E-6,0.000286213630783592,2.06475290832386E-6,100.0084915,100.0084915,-80990.2421875,-80965.15625,57.3144744296407,20.581570288602,22.909004,0,0,0,40,4449,99.81525,-80977.69921875,,,,,,,,,,,,,0,,,,0,,,,,,100.0084915,,,,
,29119031.665,100.0070343,-86176.5078125,0.000314498265505159,1.78379958254321E-6,1,0.999253354069792,40.0298881530762,1.98487926544833,17.8299993276596,0.00355018255887995,0.000650390476295139,0.25,2.36534709211413E-6,0.000316304051218679,3.25694157535607E-6,100.0070343,100.0070343,-86186.3828125,-86166.6328125,57.4254656793715,20.5805816495045,22.909004,0,0,0,40,4449,99.8089,-86176.5078125,,,,,,,,,,,,,0,,,,-0.0049,,,,,,100.0070343,,,,
,29119156.87,100.0043411,-88872.08203125,0.000328054373721617,2.63790581671642E-6,1,0.999253354069792,40.0298881530762,1.9846605570204,17.8299993276596,0.00370624996442307,0.000658895948990842,0.25,7.4900516337682E-7,0.000329944255751239,1.6655775763358E-6,100.0043411,100.0043411,-88882.234375,-88861.9296875,57.6052402387946,20.5838163882084,22.909004,0,0,0,40,4449,99.8027,-88872.08203125,,,,,,,,,,,,,0,,,,0,,,,,,100.0043411,,,,
,29119256,99.999855,-83917.8125,0.000301085395270261,1.61482785743703E-6,1,0.999253354069792,40.0298881530762,1.98477918501906,17.8299993276596,0.00340005996916126,0.000614278146807702,0.25,1.52359874126038E-6,0.000302815112782045,2.3757339897238E-6,99.999855,99.999855,-83925.5859375,-83910.0390625,57.2238055214099,20.5849086568241,22.529354,0,0,0,40,4449,99.80615,-83917.8125,,,,,,,,,,,,,0,,,,-0.00245,,,,,,99.999855,,,,
,29119358.485,99.9986649,-78795.77734375,0.000270827287161033,1.96421122981584E-6,1,0.999253354069792,40.0298881530762,1.98466719554066,17.8299993276596,0.00305565809780273,0.000566848295826728,0.25,2.63340238743328E-6,0.000272377258408935,3.41285364610965E-6,99.9986649,99.9986649,-78808.21875,-78783.3359375,57.6310339799292,20.5848748395841,22.909004,0,0,0,40,4449,99.80845,-78795.77734375,,,,,,,,,,,,,0,,,,-0.00245,,,,,,99.9986649,,,,
,29119459.855,99.996727,-73731.34375,0.00024361192165952,2.24581113756802E-6,1,0.999253354069792,40.0298881530762,1.98446106996902,17.8299993276596,0.00275077329123266,0.000495733514717741,0.25,1.11624302449164E-6,0.000245007566249703,1.81523233583658E-6,99.996727,99.996727,-73746.375,-73716.3125,57.454385934583,20.5852790592285,22.529354,0,0,0,40,4449,99.81075,-73731.34375,,,,,,,,,,,,,0,,,,-0.0049,,,,,,99.996727,,,,
,29119561.885,99.9968643,-68632.2734375,0.000211198967869089,1.57894514995776E-6,1,0.999253354069792,40.0298881530762,1.98451766880411,17.8299993276596,0.00238498938025356,0.000428833646661334,0.25,8.79269851058318E-7,0.000212407307837976,1.4891799263519E-6,99.9968643,99.9968643,-68644.9453125,-68619.6015625,57.5489629854099,20.5857241527216,23.288654,0,0,0,40,4449,99.8125,-68632.2734375,,,,,,,,,,,,,0,,,,-0.0049,,,,,,99.9968643,,,,
,29119665.26,99.9962769,-63467.87890625,0.000186166843354649,1.9665331520884E-6,1,0.999253354069792,40.0298881530762,1.98457138205871,17.8299993276596,0.00210102709072086,0.000385532677688919,0.25,1.43654651565018E-6,0.000187228401195806,1.98186603952661E-6,99.9962769,99.9962769,-63472.84375,-63462.9140625,57.261323690333,20.5839211592967,22.149702,0,0,0,40,4449,99.81885,-63467.87890625,,,,,,,,,,,,,0,,,,0,,,,,,99.9962769,,,,
,29119768.085,99.9947662,-58325.369140625,0.000153039436101651,1.48904145795861E-6,1,0.999253354069792,40.0298881530762,1.98462001437384,17.8299993276596,0.00172566922931583,0.000325571097266231,0.25,1.94202192082363E-6,0.000153908511365031,2.3978433752537E-6,99.9947662,99.9947662,-58335.4609375,-58315.27734375,57.6216544376984,20.5831567594535,22.909004,0,0,0,40,4449,99.8252,-58325.369140625,,,,,,,,,,,,,0,,,,-0.00245,,,,,,99.9947662,,,,
,29119871.76,99.99399185,-53146.11328125,0.000122799161321687,1.8231803757145E-6,1,0.999253354069792,40.0298881530762,1.98455225742127,17.8299993276596,0.00138837084637816,0.000239880637306547,0.25,-3.33337839212907E-7,0.000123500910695691,2.41953992674747E-8,99.9936676,99.9943161,-53158.53515625,-53133.69140625,57.4934673605446,20.5824704776856,22.529354,0,0,0,40,4449,99.8289,-53146.11328125,,,,,,,,,,,,,0,,,,-0.00245,,,,,,99.99399185,,,,
,29119974.835,99.9938812,-47993.58203125,9.43972061857731E-5,1.34568172955305E-6,1,0.999253354069792,40.0298881530762,1.9845323462048,17.8299993276596,0.00106514295192566,0.000196326527249382,0.25,7.97590199101525E-7,9.49327059276304E-5,1.08039656355564E-6,99.9938812,99.9938812,-48005.9609375,-47981.203125,57.6365053795638,20.5836808200677,22.909004,0,0,0,40,4449,99.8346,-47993.58203125,,,,,,,,,,,,,0,,,,-0.00245,,,,,,99.9938812,,,,
,29120076.095,99.9932938,-42934.505859375,6.50113671032365E-5,1.47651907094539E-6,1,0.999253354069792,40.0298881530762,1.9844208018442,17.8299993276596,0.000735018797549434,0.000126657159310267,0.25,-2.08179641366966E-7,6.53818346753533E-5,-1.64125095411328E-8,99.9932938,99.9932938,-42949.65234375,-42919.359375,57.2081729510253,20.5827119207496,22.529354,0,0,0,40,4449,99.84065,-42934.505859375,,,,,,,,,,,,,0,,,,0,,,,,,99.9932938,,,,
,29120178.74,99.99184035,-37802.412109375,3.59240536386815E-5,1.59254732526136E-6,1,0.999253354069792,40.0298881530762,1.98451078242748,17.8299993276596,0.000404273926736794,8.07953989264716E-5,0.25,8.40407988073779E-7,3.61256012458471E-5,9.52522207073117E-7,99.9917297,99.991951,-37812.546875,-37792.27734375,57.2191157502945,20.5814845081971,22.909004,0,0,0,40,4449,99.8514,-37802.412109375,,,,,,,,,,,,,0,,,,-0.0049,,,,,,99.99184035,,,,
,29120279.845,99.9907913,-32750.419921875,1.04255584835926E-5,1.10546972174799E-6,1,0.999253354069792,40.0298881530762,1.98452205957987,17.8299993276596,0.000117959943062997,1.98292836836593E-5,0.25,-7.65197971487421E-8,1.04849181590611E-5,-4.55962696707874E-8,99.9907913,99.9907913,-32760.466796875,-32740.373046875,57.1581487257945,20.5834577987758,22.909004,0,0,0,40,4449,99.85485,-32750.419921875,,,,,,,,,,,,,0,,,,-0.00245,,,,,,99.9907913,,,,
,29120380.525,99.9916649,-27718.890625,-1.76410046505427E-5,9.46469577904608E-7,1,0.999253354069792,40.0298881530762,1.98444475734376,17.8299993276596,-0.000199455615045757,-3.43164719191765E-5,0.25,6.21082148997168E-8,-1.77410957304619E-5,9.06411662946068E-9,99.9915619,99.9917679,-27734.009765625,-27703.771484375,57.0901470446214,20.5817830531806,23.288654,0,0,0,40,4449,99.8636,-27718.890625,,,,,,,,,,,,,0,,,,-0.00245,,,,,,99.9916649,,,,
,29120481.805,99.9914322,-22656.2529296875,-4.399554490062E-5,8.90360330453279E-7,1,0.999253354069792,40.0298881530762,1.9845449606754,17.8299993276596,-0.000496560294271053,-9.06477867658851E-5,0.25,-2.921926550212E-7,-4.42434384174862E-5,-4.27835149923116E-7,99.9914322,99.9914322,-22666.1171875,-22646.388671875,57.6732419199676,20.5806856819835,22.909004,0,0,0,40,4449,99.87125,-22656.2529296875,,,,,,,,,,,,,0,,,,0.00245,,,,,,99.9914322,,,,
,29120583.7,99.9907684,-17564.083984375,-7.17723406681071E-5,7.10873948584867E-7,1,0.999253354069792,40.0298881530762,1.98455574830951,17.8299993276596,-0.000810706598903897,-0.000144218966380333,0.25,-1.515406630187E-7,-7.21771477542722E-5,-3.72277260290548E-7,99.9907684,99.9907684,-17579.19140625,-17548.9765625,57.1518956976407,20.5784015743661,22.909004,0,0,0,40,4449,99.8819,-17564.083984375,,,,,,,,,,,,,0,,,,0.00245,,,,,,99.9907684,,,,
,29120686.47,99.9904709,-12426.5395507813,-9.70797019962758E-5,4.65775761776415E-7,1,0.999253354069792,40.0298881530762,1.98468849791387,17.8299993276596,-0.00109586924190778,-0.000199400733632034,0.25,-5.85435270654214E-7,-9.76253041470117E-5,-8.87839519759419E-7,99.9904709,99.9904709,-12441.478515625,-12411.6005859375,57.1276652135445,20.5773101285243,22.909004,0,0,0,40,4449,99.8908,-12426.5395507813,,,,,,,,,,,,,0,,,,-0.00245,,,,,,99.9904709,,,,
,29120787.07,99.9922791,-7398.97436523437,-0.000119911023378664,5.08242203193844E-7,1,0.999253354069792,40.0298881530762,1.98478039443282,17.8299993276596,-0.00135371248206983,-0.000245932708855435,0.25,-6.8825696690245E-7,-0.000120584158449471,-1.06349392446397E-6,99.9922791,99.9922791,-7403.890625,-7394.05810546875,57.4309370790061,20.5772386589113,22.529354,0,0,0,40,4449,99.8964,-7398.97436523437,,,,,,,,,,,,,0,,,,0,,,,,,99.9922791,,,,
,29120888.2,99.9927597,-2342.96557617187,-0.000133396100863476,3.39274160269179E-7,1,0.999253354069792,40.0298881530762,1.98466707311414,17.8299993276596,-0.00150617303596852,-0.000271780781286283,0.25,-6.05180785370465E-7,-0.000134144575527989,-1.0235545878203E-6,99.9927597,99.9927597,-2355.51293945313,-2330.41821289062,57.0924919301791,20.577777599849,22.529354,0,0,0,40,4449,99.90375,-2342.96557617187,,,,,,,,,,,,,0,,,,-0.0049,,,,,,99.9927597,,,,
,29120989.49,99.9943619,2714.79040527344,0.000134018143227087,3.7493037782554E-7,1,0.999253354069792,40.0298881530762,1.98465877341037,17.8299993276596,0.00151372568560419,0.00027000675435594,0.25,3.3910591667216E-7,0.000134771018726915,7.57748548969259E-7,99.9943619,99.9943619,2702.4892578125,2727.09155273438,57.3246356003907,20.5768456200703,22.529354,0,0,0,40,4449,99.9099,2714.79040527344,,,,,,,,,,,,,0,,,,0.0049,,,,,,99.9943619,,,,
,29121091.28,100.0024338,7801.68994140625,0.000119517692562615,4.91228009769995E-7,1,0.999253354069792,40.0298881530762,1.9847060704809,17.8299993276596,0.00134984490734909,0.000241588114675393,0.25,3.73902466831851E-7,0.000120189662705894,7.45930512328718E-7,100.0024338,100.0024338,7791.78466796875,7811.59521484375,57.3449579418907,20.576722677221,22.909004,0,0,0,40,4449,99.9075,7801.68994140625,,,,,,,,,,,,,0,,,,0,,,,,,100.0024338,,,,
,29121193.54,100.0048599,12914.619140625,9.59384031044884E-5,5.53661281497348E-7,1,0.999253354069792,40.0298881530762,1.98470465263702,17.8299993276596,0.00108402933362376,0.00019117273471235,0.25,5.79505113830281E-8,9.64792648298697E-5,3.53647735875791E-7,100.0048599,100.0048599,12899.6357421875,12929.6025390625,56.9580518248714,20.5771423960446,22.529354,0,0,0,40,4449,99.902,12914.619140625,,,,,,,,,,,,,0,,,,0,,,,,,100.0048599,,,,
,29121293.805,100.0072937,17924.794921875,7.12681088200965E-5,8.6880554942462E-7,1,0.999253354069792,40.0298881530762,1.98478598942623,17.8299993276596,0.000805347919212132,0.000141814510895266,0.25,2.60909642437154E-8,7.16704898218548E-5,2.44438916476794E-7,100.0072937,100.0072937,17907.158203125,17942.431640625,57.0362146767945,20.5755441437148,22.529354,0,0,0,40,4449,99.89335,17924.794921875,,,,,,,,,,,,,0,,,,0.00245,,,,,,100.0072937,,,,
,29121396.655,100.009285,23064.583984375,4.28121463085082E-5,1.22913921969934E-6,1,0.999253354069792,40.0298881530762,1.98476516369157,17.8299993276596,0.000483852944331827,8.48171726693981E-5,0.25,-1.65843450093055E-8,4.30543161296022E-5,1.13610684768362E-7,100.009285,100.009285,23054.673828125,23074.494140625,57.6599542351407,20.5759793450053,22.909004,0,0,0,40,4449,99.88555,23064.583984375,,,,,,,,,,,,,0,,,,0,,,,,,100.009285,,,,
,29121497.625,100.0095291,28112.1513671875,1.58651607238418E-5,9.80920154427832E-7,1,0.999253354069792,40.0298881530762,1.98457726142785,17.8299993276596,0.000178382499579827,3.65922305364916E-5,0.25,4.51098302760251E-7,1.59536514404253E-5,5.01640695338922E-7,100.0095291,100.0095291,28092.11328125,28132.189453125,57.1636201254291,20.576677695814,22.529354,0,0,0,40,4449,99.87485,28112.1513671875,,,,,,,,,,,,,0,,,,0,,,,,,100.0095291,,,,
,29121601.01,100.0096436,33277.2578125,-1.15284807650245E-5,1.38321764034032E-6,1,0.999253354069792,40.0298881530762,1.98459790981784,17.8299993276596,-0.000130614555381304,-2.09557889875029E-5,0.25,1.70605264375378E-7,-1.15943868912951E-5,1.36927794722719E-7,100.0096436,100.0096436,33269.8046875,33284.7109375,57.0010413934291,20.5771395026827,22.529354,0,0,0,40,4449,99.86475,33277.2578125,,,,,,,,,,,,,0,,,,-0.0049,,,,,,100.0096436,,,,
,29121705.765,100.009903,38514.220703125,-4.23100999022855E-5,1.34147415337787E-6,1,0.999253354069792,40.0298881530762,1.98495579884803,17.8299993276596,-0.000479139924144885,-7.86800710806999E-5,0.25,4.69790686519998E-7,-4.25518758303999E-5,3.46166099489186E-7,100.009903,100.009903,38501.8125,38526.62890625,57.3269804859484,20.5710358594732,22.909004,0,0,0,40,4449,99.8553,38514.220703125,,,,,,,,,,,,,0,,,,0.0049,,,,,,100.009903,,,,
,29121810.305,100.009861,43741.556640625,-7.10584429809099E-5,1.35028051337442E-6,1,0.999253354069792,40.0298881530762,1.98485791935472,17.8299993276596,-0.000797540368106224,-0.000172728147489855,0.25,-2.80406216717869E-6,-7.1454463512606E-5,-3.03067247431507E-6,100.0097122,100.0100098,43733.90234375,43749.2109375,57.2456911199484,20.5735260328341,22.909004,0,0,0,40,4449,99.8443,43741.556640625,,,,,,,,,,,,,0,,,,0.00245,,,,,,100.009861,,,,
,29121914.25,100.0099411,48936.70703125,-9.85417577390822E-5,1.28534598930139E-6,1,0.999253354069792,40.0298881530762,1.98474096845893,17.8299993276596,-0.00111038238889297,-0.000214302706286715,0.25,-1.65901909527199E-6,-9.90984668726006E-5,-1.95858041467796E-6,100.0099411,100.0099411,48931.625,48941.7890625,57.4027984523138,20.5746278595963,22.909004,0,0,0,40,4449,99.8334,48936.70703125,,,,,,,,,,,,,0,,,,0,,,,,,100.0099411,,,,
,29122016.44,100.0095825,54041.921875,-0.000129082735695962,1.87995479625451E-6,1,0.999253354069792,40.0298881530762,1.9847355690878,17.8299993276596,-0.00145522916790849,-0.000276751389090786,0.25,-1.82440188473392E-6,-0.000129814189305916,-2.21218233196291E-6,100.0095825,100.0095825,54029.4375,54054.40625,57.1214121853907,20.5758479329494,23.288654,0,0,0,40,4449,99.82675,54041.921875,,,,,,,,,,,,,0,,,,-0.0049,,,,,,100.0095825,,,,
,29122120.485,100.0095596,59241.91015625,-0.000156825444208361,2.12439254858347E-6,1,0.999253354069792,40.0298881530762,1.98477193840955,17.8299993276596,-0.00176612344791492,-0.000347140389348198,0.25,-3.1842395285248E-6,-0.000157712749975785,-3.65760640332262E-6,100.0095596,100.0095596,59226.95703125,59256.86328125,57.4371901071599,20.5722209989602,23.288654,0,0,0,40,4449,99.82095,59241.91015625,,,,,,,,,,,,,0,,,,-0.00245,,,,,,100.0095596,,,,
,29122222.275,100.0078125,64329.693359375,-0.000186548091424419,1.52585023029705E-6,1,0.999253354069792,40.0298881530762,1.9847342796055,17.8299993276596,-0.00210323744959765,-0.000399226873403467,0.25,-2.57918130476389E-6,-0.000187608752652439,-3.13154099322467E-6,100.0078125,100.0078125,64319.64453125,64339.7421875,57.1722180391407,20.5734671074422,22.529354,0,0,0,40,4449,99.8119,64329.693359375,,,,,,,,,,,,,0,,,,0,,,,,,100.0078125,,,,
,29122323.845,100.007782,69407.31640625,-0.000215395510610787,1.51486516945713E-6,1,0.999253354069792,40.0298881530762,1.98459747824651,17.8299993276596,-0.00243220566122799,-0.000438906943118788,0.25,-1.0331817774149E-6,-0.000216627677459235,-1.65538549554752E-6,100.007782,100.007782,69402.28125,69412.3515625,56.8666012881214,20.5755101458829,23.288654,0,0,0,40,4449,99.8042,69407.31640625,,,,,,,,,,,,,0,,,,0,,,,,,100.007782,,,,
,29122426.09,100.0090256,74517.33203125,-0.000246616966303786,1.68213033147171E-6,1,0.999253354069792,40.0298881530762,1.98474483283319,17.8299993276596,-0.00277771888544169,-0.000543908839879013,0.25,-4.8459577449351E-6,-0.000248019480361779,-5.57426144565115E-6,100.0090256,100.0090256,74509.875,74524.7890625,57.5700669554292,20.5732994588114,22.529354,0,0,0,40,4449,99.797,74517.33203125,,,,,,,,,,,,,0,,,,-0.0049,,,,,,100.0090256,,,,
,29122529.315,100.0065689,79677.71875,-0.000272966104345227,1.79032598296032E-6,1,0.999253354069792,40.0298881530762,1.98477774667996,17.8299993276596,-0.00308268776071577,-0.000555791116599814,0.25,-1.27787627987913E-6,-0.000274532478111872,-2.05479182458887E-6,100.0065689,100.0065689,79662.6796875,79692.7578125,57.1956668947176,20.5733140752517,22.529354,0,0,0,40,4449,99.79055,79677.71875,,,,,,,,,,,,,0,,,,-0.00245,,,,,,100.0065689,,,,
,29122631.56,100.0055313,84788.890625,-0.000303219210902616,2.17397246635039E-6,1,0.999253354069792,40.0298881530762,1.98449598810452,17.8299993276596,-0.00341509603474356,-0.000667550091695452,0.25,-5.87124021106205E-6,-0.000304949354279746,-6.75357281149269E-6,100.0055313,100.0055313,84776.8125,84800.96875,56.9510171681983,20.5742462572053,22.529354,0,0,0,40,4449,99.7861,84788.890625,,,,,,,,,,,,,0,,,,0.00245,,,,,,100.0055313,,,,
,29122732.86,100.0037842,89854.17578125,-0.00033406458504378,2.04638824484841E-6,1,0.999253354069792,40.0298881530762,1.98461474407375,17.8299993276596,-0.00376491859561211,-0.000723138731626329,0.25,-5.38115416506745E-6,-0.000335976702603685,-6.34008657058744E-6,100.0037842,100.0037842,89844.1015625,89864.25,57.2527257766214,20.5742624887114,22.909004,0,0,0,40,4449,99.78355,89854.17578125,,,,,,,,,,,,,0,,,,0.00245,,,,,,100.0037842,,,,
,29122853.84,100.0003281,85311.4140625,-0.000306669874296722,1.53155347700389E-6,1,0.999253354069792,40.0298881530762,1.98463180971864,17.8299993276596,-0.00345867979420612,-0.000649596056468164,0.25,-3.67396517076646E-6,-0.000308426335416028,-4.55267974664382E-6,100.0003281,100.0003281,85303.84375,85318.984375,57.4661103623715,20.5737926651935,22.909004,0,0,0,40,4449,99.7831,85311.4140625,,,,,,,,,,,,,0,,,,-0.00245,,,,,,100.0003281,,,,
,29122954.075,99.9982986,80301.09375,-0.000278568819086098,2.01197898377287E-6,1,0.999253354069792,40.0298881530762,1.9845090593271,17.8299993276596,-0.0031350767353296,-0.000626859431204203,0.25,-6.59035495760551E-6,-0.000280152773289735,-7.41296938182518E-6,99.9982986,99.9982986,80296.2109375,80305.9765625,57.3050948874099,20.5775529416551,22.909004,0,0,0,40,4449,99.7858,80301.09375,,,,,,,,,,,,,0,,,,-0.00245,,,,,,99.9982986,,,,
,29123055.23,99.9972992,75241.78515625,-0.000248241055438534,1.4588711389144E-6,1,0.999253354069792,40.0298881530762,1.98446546029065,17.8299993276596,-0.00279678402631152,-0.00054089439308656,0.25,-4.30124374878031E-6,-0.000249654776940065,-5.03040394766134E-6,99.9970551,99.9975433,75231.7109375,75251.859375,57.2355299491984,20.5766285037666,22.909004,0,0,0,40,4449,99.78715,75241.78515625,,,,,,,,,,,,,0,,,,0.00245,,,,,,99.9972992,,,,
,29123157.21,99.9950104,70144.4921875,-0.000217226377342328,1.65415140287097E-6,1,0.999253354069792,40.0298881530762,1.98465989468666,17.8299993276596,-0.00245137648860594,-0.000451653367022134,0.25,-1.83900833921838E-6,-0.000218467025977684,-2.47053011519189E-6,99.9950104,99.9950104,70134.3359375,70154.6484375,57.3230723433522,20.574944008029,22.909004,0,0,0,40,4449,99.79225,70144.4921875,,,,,,,,,,,,,0,,,,-0.00245,,,,,,99.9950104,,,,
,29123259.975,99.9956665,65008.943359375,-0.000191066146754802,1.86952784627799E-6,1,0.999253354069792,40.0298881530762,1.98463028259511,17.8299993276596,-0.00215055413421323,-0.000428911405488527,0.25,-4.41488004497348E-6,-0.000192147609033376,-4.99038177341963E-6,99.9956665,99.9956665,64991.25390625,65026.6328125,57.1831608384099,20.5757023635415,22.909004,0,0,0,40,4449,99.79585,65008.943359375,,,,,,,,,,,,,0,,,,-0.00245,,,,,,99.9956665,,,,
,29123364.43,99.9945374,59785.802734375,-0.000162323110473504,1.91459516987323E-6,1,0.999253354069792,40.0298881530762,1.98451296813108,17.8299993276596,-0.00182687199674026,-0.000364610969414663,0.25,-3.76913251877087E-6,-0.000163240298012022,-4.26158066694901E-6,99.9945374,99.9945374,59773.48046875,59798.125,56.9619599674676,20.5777164466099,22.909004,0,0,0,40,4449,99.8025,59785.802734375,,,,,,,,,,,,,0,,,,0,,,,,,99.9945374,,,,
,29123469.115,99.9940491,54555.755859375,-0.000130213036698728,1.72626755027305E-6,1,0.999253354069792,40.0298881530762,1.98447623100083,17.8299993276596,-0.00146398369743591,-0.000300818191263653,0.25,-3.75889447595016E-6,-0.000130945396585116,-4.16087525941977E-6,99.9940491,99.9940491,54545.98046875,54565.53125,57.1104693861214,20.5765852888817,23.288654,0,0,0,40,4449,99.8067,54555.755859375,,,,,,,,,,,,,0,,,,0,,,,,,99.9940491,,,,
,29123572.405,99.9941025,49393.42578125,-0.000101468582474579,1.48971220158802E-6,1,0.999253354069792,40.0298881530762,1.98484474661141,17.8299993276596,-0.00114707763929336,-0.000199850255527733,0.25,1.34500714309544E-7,-0.000102047332249003,-1.6334637490933E-7,99.9941025,99.9941025,49378.2890625,49408.5625,57.5481813568907,20.5758520795511,22.529354,0,0,0,40,4449,99.81735,49393.42578125,,,,,,,,,,,,,0,,,,-0.00245,,,,,,99.9941025,,,,
,29123675.86,99.9916153,44220.3359375,-7.38453885899836E-5,1.33721931958733E-6,1,0.999253354069792,40.0298881530762,1.98468894738497,17.8299993276596,-0.000832388565162726,-0.000158789009492394,0.25,-1.08250208515668E-6,-7.42624272317648E-5,-1.30751623591374E-6,99.9916153,99.9916153,44210.34765625,44230.32421875,57.5989872106407,20.5758661208967,22.909004,0,0,0,40,4449,99.8225,44220.3359375,,,,,,,,,,,,,0,,,,0.00245,,,,,,99.9916153,,,,
,29123777.45,99.9921112,39142.8046875,-4.37155571319664E-5,1.25422750061261E-6,1,0.999253354069792,40.0298881530762,1.98468117480164,17.8299993276596,-0.00049466826341261,-8.31205619088338E-5,0.25,3.22741938603399E-7,-4.3964917244941E-5,1.94138520838694E-7,99.9921112,99.9921112,39127.77734375,39157.83203125,57.4012351952753,20.5751802441549,22.909004,0,0,0,40,4449,99.82885,39142.8046875,,,,,,,,,,,,,0,,,,-0.00245,,,,,,99.9921112,,,,
,29123879.14,99.9917526,34063.740234375,-1.44633426161205E-5,1.21967023716905E-6,1,0.999253354069792,40.0298881530762,1.98446802476746,17.8299993276596,-0.000162562118709646,-3.36532816710841E-5,0.25,-4.37715165169611E-7,-1.45440857996324E-5,-4.8363756289734E-7,99.9917526,99.9917526,34056.2890625,34071.19140625,57.2355299491984,20.5780400111035,22.909004,0,0,0,40,4449,99.8394,34063.740234375,,,,,,,,,,,,,0,,,,0,,,,,,99.9917526,,,,
,29123981.87,99.9927521,28928.7822265625,1.10759260932652E-5,9.96266765479201E-7,1,0.999253354069792,40.0298881530762,1.98466209310116,17.8299993276596,0.000126919784047366,1.19959705522252E-5,0.25,-8.84215032707746E-7,1.11413418771535E-5,-8.55741469119146E-7,99.9927521,99.9927521,28918.943359375,28938.62109375,57.3676251689484,20.5756222949382,23.288654,0,0,0,40,4449,99.8473,28928.7822265625,,,,,,,,,,,,,0,,,,0,,,,,,99.9927521,,,,
,29124083.985,99.9907379,23823.63671875,4.05334219686852E-5,8.05862890674103E-7,1,0.999253354069792,40.0298881530762,1.98467439145284,17.8299993276596,0.000460665575092358,6.55813806702738E-5,0.25,-1.31805869042008E-6,4.0766701779264E-5,-1.20220972549144E-6,99.9907379,99.9907379,23816.044921875,23831.228515625,57.4090514804676,20.5761470130832,22.909004,0,0,0,40,4449,99.85475,23823.63671875,,,,,,,,,,,,,0,,,,0,,,,,,99.9907379,,,,
,29124186.01,99.98964305,18724.0458984375,6.62148909455922E-5,7.13200794712137E-7,1,0.999253354069792,40.0298881530762,1.98466374793973,17.8299993276596,0.000749518725482237,0.000124257955462972,0.25,-6.38801126034206E-7,6.65908380056947E-5,-4.39775535936041E-7,99.9895782,99.9897079,18709.193359375,18738.8984375,57.4622022197753,20.5768854446691,22.909004,0,0,0,40,4449,99.8663,18724.0458984375,,,,,,,,,,,,,0,,,,0,,,,,,99.98964305,,,,
,29124284.16,99.9923439,13819.607421875,9.12321292886556E-5,6.09867167918855E-7,1,0.999253354069792,40.0298881530762,1.98457481630446,17.8299993276596,0.00103174975725908,0.000176314542000287,0.25,-4.28740768363803E-7,9.17480380870899E-5,-1.50424110480363E-7,99.9923172,99.9923706,13812.3515625,13826.86328125,57.2355299491984,20.5758237569372,22.909004,0,0,0,40,4449,99.8742,13819.607421875,,,,,,,,,,,,,0,,,,-0.00245,,,,,,99.9923439,,,,
,29124384.57,99.9905701,8801.71484375,0.000114278183685933,5.34360882022688E-7,1,0.999253354069792,40.0298881530762,1.98457443395471,17.8299993276596,0.0012921967868808,0.00022183408112062,0.25,-4.51938512278846E-7,0.000114923319555329,-1.00978527565153E-7,99.9905701,99.9905701,8793.984375,8809.4453125,57.2519441481022,20.5781347013801,22.909004,0,0,0,40,4449,99.88185,8801.71484375,,,,,,,,,,,,,0,,,,0,,,,,,99.9905701,,,,
,29124487.27,99.9914856,3666.58898925781,0.000133009474068957,3.29472579609309E-7,1,0.999253354069792,40.0298881530762,1.98451719076753,17.8299993276596,0.00150186520845573,0.000270040450068656,0.25,5.21166482270394E-7,0.000133756200930978,9.37516472508338E-7,99.9914856,99.9914856,3651.50463867188,3681.67333984375,57.3050948874099,20.5773361336529,23.288654,0,0,0,40,4449,99.8893,3666.58898925781,,,,,,,,,,,,,0,,,,-0.00245,,,,,,99.9914856,,,,
,29124561.035,99.9918137,-0.28163979947567,1.35647195153709E-5,7.66571665294036E-7,1,0.999253354069792,40.0298881530762,1.98460858193715,17.8299993276596,0.00015465838269244,1.90789099639073E-5,0.25,-6.95809221002352E-7,1.36431570342866E-5,-6.57452876177626E-7,99.9918137,99.9918137,-0.289251685142517,-0.274027913808823,57.2972786022176,20.5780972631015,22.529354,0,0,0,40,4417,99.8956,-0.28163979947567,,,,,,,,,,,,,0,,,,0.0049,,,,,,99.9918137,,,,