File: data/looselyPackedNP/sc-ios-11/ppms/rawdata/ES_S14_FCC_100OE.DAT
[Header]
; VSM Data File (default extension .dat)
; Copyright (c) 2003-2013, Quantum Design, Inc. All rights reserved.
TITLE,
FILEOPENTIME,29179425.88,12/05/2018,1:24 am
BYAPP,VSM,2.0,2.0
INFO,PPMS VSM Option Release 1.4.10 Build 1,APPNAME
INFO,Quantum Design Linear Motor Servo Controller,MOTOR_MODULE_NAME
INFO,3101-100 M1,MOTOR_HW_VERSION
INFO,MMC1014,MOTOR_SERIAL_NUMBER
INFO,SRV No X-over 01.03.11,MOTOR_SOFTWARE_VERSION
INFO,Quantum Design VSM Detection Module,VSM_MODULE_NAME
INFO,3101-150 F0,VSM_HW_VERSION
INFO,VSM707,VSM_SERIAL_NUMBER
INFO,VSM No X-over 01.02.05 May 20 2008 13:51:47,VSM_SOFTWARE_VERSION
INFO,704,PREAMP_SERIAL_NUMBER
INFO,822,COIL_SERIAL_NUMBER
INFO,0,MOMENT_UNITS
INFO,Iron Oxide Spheres,SAMPLE_MATERIAL
INFO,10 nm diameter, collaboration Mainz,SAMPLE_COMMENT
INFO,,SAMPLE_MASS
INFO,,SAMPLE_VOLUME
INFO,,SAMPLE_MOLECULAR_WEIGHT
INFO,,SAMPLE_SIZE
INFO,,SAMPLE_SHAPE
DATATYPE,COMMENT,1
DATATYPE,TIME,2
STARTUPAXIS,X,2
STARTUPAXIS,Y1,5
[Data]
Comment,Time Stamp (sec),Temperature (K),Magnetic Field (Oe),Moment (emu),M. Std. Err. (emu),Transport Action,Averaging Time (sec),Frequency (Hz),Peak Amplitude (mm),Center Position (mm),Coil Signal' (mV),Coil Signal" (mV),Range (mV),M. Quad. Signal (emu),M. Raw' (emu),M. Raw" (emu),Min. Temperature (K),Max. Temperature (K),Min. Field (Oe),Max. Field (Oe),Mass (grams),Motor Lag (deg),Pressure (Torr),VSM Status (code),Motor Status (code),Measure Status (code),Measure Count,PPMS Status (code),System Temp. (K),System Field (Oe),Sample Position (deg),Bridge 1 Resistance (ohms),Bridge 1 Excitation (에),Bridge 2 Resistance (ohms),Bridge 2 Excitation (에),Bridge 3 Resistance (ohms),Bridge 3 Excitation (에),Bridge 4 Resistance (ohms),Bridge 4 Excitation (에),Signal 1 Vin (V),Signal 2 Vin (V),Digital Inputs (code),Drive 1 Iout (mA),Drive 1 Ipower (W),Drive 2 Iout (mA),Drive 2 Ipower (W),Pressure (),Map 20 (),Map 21 (),Map 22 (),Map 23 (),Map 24 (),Map 25 (),Map 26 (),Map 27 (),Map 28 (),Map 29 ()
,29179558.605,349.6078186,99.6091461181641,1.54572554560438E-5,4.44300753145261E-7,1,0.999253354069792,40.0298881530762,2.0080371806272,16.4599996060133,0.000175819799658842,2.80005676872399E-5,0.25,-2.0900877260924E-7,1.54301715764775E-5,-2.0002552621452E-7,349.6078186,349.6078186,99.6091461181641,99.6091461181641,57.0635716749676,20.5545909355889,28.983419,0,0,0,40,4369,350.2513,99.6091461181641,,,,,,,,,,,,,0,,,,0,,,,,,349.6078186,,,,
,29179687.515,347.4932556,99.6091461181641,1.57660572523755E-5,4.81607180918523E-7,1,0.999253354069792,40.0298881530762,2.0079919324073,16.4599996060133,0.000180646308753434,2.1024421291527E-5,0.25,-8.77431034220318E-7,1.57399287467692E-5,-8.67047912152421E-7,347.4932556,347.4932556,99.6091461181641,99.6091461181641,57.0612267894099,20.5557108023694,28.603769,0,0,0,40,4374,345.8235,99.6091461181641,,,,,,,,,,,,,0,,,,-0.00245,,,,,,347.4932556,,,,
,29179820.16,344.4684448,99.6091461181641,1.66533584940983E-5,4.54872937002366E-7,1,0.999253354069792,40.0298881530762,2.00788514100597,16.4599996060133,0.000189640481729742,2.90371085624558E-5,0.25,-3.25252875424774E-7,1.6627127770334E-5,-3.15236226742433E-7,344.4684448,344.4684448,99.6091461181641,99.6091461181641,57.1831608384099,20.556933463019,28.983419,0,0,0,40,4374,342.3977,99.6091461181641,,,,,,,,,,,,,0,,,,-0.00245,,,,,,344.4684448,,,,
,29179945.53,341.4658508,99.6091461181641,1.54570882423639E-5,4.57646011743473E-7,1,0.999253354069792,40.0298881530762,2.0079551189907,16.4599996060133,0.000174681683454098,3.4809237605249E-5,0.25,3.89989081145061E-7,1.54339250314224E-5,3.98320457128241E-7,341.4658508,341.4658508,99.6091461181641,99.6091461181641,57.0369963053137,20.555932152643,29.363071,0,0,0,40,4374,339.0884,99.6091461181641,,,,,,,,,,,,,0,,,,0,,,,,,341.4658508,,,,
,29180069.46,338.4796448,99.6091461181641,1.64843411357782E-5,4.82795661239422E-7,1,0.999253354069792,40.0298881530762,2.00799191156323,16.4599996060133,0.000186937192168233,3.35229172397358E-5,0.25,9.83211354477528E-8,1.64615056631636E-5,1.07786315493338E-7,338.4796448,338.4796448,99.6091461181641,99.6091461181641,56.9009929429675,20.556668270709,29.363071,0,0,0,40,4374,335.8766,99.6091461181641,,,,,,,,,,,,,0,,,,-0.0049,,,,,,338.4796448,,,,
,29180193.22,335.4425964,99.6091461181641,1.66203508434774E-5,4.4429344613569E-7,1,0.999253354069792,40.0298881530762,2.00819514199031,16.4599996060133,0.000188580398394778,3.34430195472527E-5,0.25,6.70364330085638E-8,1.65990811703488E-5,7.67323123977962E-8,335.4425964,335.4425964,99.6091461181641,99.6091461181641,57.1526773261599,20.5561574768591,28.983419,0,0,0,40,4374,332.7248,99.6091461181641,,,,,,,,,,,,,0,,,,0.0049,,,,,,335.4425964,,,,
touchdown = 10.219999589026 mm,29180327.8,332.1618347,99.6091461181641,1.74928304746685E-5,4.10463919756863E-7,1,0.999253354069792,40.0298881530762,2.0089846844953,16.4199993014336,0.000199098328812001,3.2204544182851E-5,0.25,-1.9464279436151E-7,1.74725844626442E-5,-1.84000795658642E-7,332.1618347,332.1618347,99.6091461181641,99.6091461181641,56.7204367550252,20.5482690864679,28.603769,0,0,0,40,4374,329.2843,99.6091461181641,,,,,,,,,,,,,0,,,,0,,,,,,332.1618347,,,,
,29180437.915,329.4576111,99.6091461181641,1.76287789819477E-5,4.06399458868337E-7,1,0.999253354069792,40.0298881530762,2.00853720652,16.4199993014336,0.000200529999228312,3.29815580908735E-5,0.25,-1.49543978613199E-7,1.76100027882628E-5,-1.38786388438404E-7,329.4576111,329.4576111,99.6091461181641,99.6091461181641,56.8079791491791,20.5510311191866,28.983419,0,0,0,40,4374,326.50655,99.6091461181641,,,,,,,,,,,,,0,,,,0.0049,,,,,,329.4576111,,,,
,29180557.55,326.4988708,99.6091461181641,1.74091282070616E-5,4.92231092162078E-7,1,0.999253354069792,40.0298881530762,2.0085983602043,16.4199993014336,0.000198057911126842,3.25732846744026E-5,0.25,-1.47935975418561E-7,1.73923808682051E-5,-1.37215304696643E-7,326.4988708,326.4988708,99.6091461181641,99.6091461181641,56.9869720800829,20.5490389061937,28.983419,0,0,0,40,4374,323.47825,99.6091461181641,,,,,,,,,,,,,0,,,,0,,,,,,326.4988708,,,,
,29180679.625,323.4918213,99.6091461181641,1.76852648853451E-5,4.2004792517611E-7,1,0.999253354069792,40.0298881530762,2.00876256505541,16.4199993014336,0.000200833360883778,3.5422282555965E-5,0.25,5.43411482905541E-8,1.76699860095073E-5,6.51579927563733E-8,323.4918213,323.4918213,99.6091461181641,99.6091461181641,57.0799858738714,20.549240450236,28.983419,0,0,0,40,4374,320.4219,99.6091461181641,,,,,,,,,,,,,0,,,,0.00245,,,,,,323.4918213,,,,
,29180802.15,320.4719849,99.6091461181641,1.83039524852749E-5,4.67184285191239E-7,1,0.999253354069792,40.0298881530762,1.99624411887077,16.4299998432398,0.000206537281874869,3.70694195153002E-5,0.25,1.11188817350554E-7,1.82900430028438E-5,1.22476717323678E-7,320.4719849,320.4719849,99.6091461181641,99.6091461181641,57.1456426694868,20.5459796919795,28.983419,0,0,0,40,4374,317.3111,99.6091461181641,,,,,,,,,,,,,0,,,,-0.00245,,,,,,320.4719849,,,,
,29180924.83,317.4564819,99.6091461181641,1.88462802462569E-5,5.2509440240251E-7,1,0.999253354069792,40.0298881530762,1.99646307564478,16.4299998432398,0.000213009297939061,3.63995493175097E-5,0.25,-4.28676235723364E-8,1.88340560698219E-5,-3.09965512262845E-8,317.4564819,317.4564819,99.6091461181641,99.6091461181641,56.8032893780637,20.544623790426,28.983419,0,0,0,40,4374,314.2347,99.6091461181641,,,,,,,,,,,,,0,,,,0,,,,,,317.4564819,,,,
,29181044.635,314.483551,99.6091461181641,1.94422968444196E-5,4.04417351264354E-7,1,0.999253354069792,40.0298881530762,1.99631716215519,16.4299998432398,0.000219474425199545,3.91629427672778E-5,0.25,9.82184700384072E-8,1.94316351856438E-5,1.10522536841781E-7,314.483551,314.483551,99.6091461181641,99.6091461181641,56.9213152844676,20.5467377002753,28.603769,0,0,0,40,4374,311.2114,99.6091461181641,,,,,,,,,,,,,0,,,,0,,,,,,314.483551,,,,
touchdown = 10.2599998936057 mm,29181170.555,311.3394165,99.6091461181641,1.94056901274861E-5,3.68381462534722E-7,1,0.999253354069792,40.0298881530762,1.99627571830431,16.4599996060133,0.0002194709978334,3.68428551569422E-5,0.25,-1.01234103264822E-7,1.93973345346806E-5,-8.87056593523007E-8,311.3394165,311.3394165,99.6091461181641,99.6091461181641,57.1573670972753,20.5453090937176,28.983419,0,0,0,40,4374,308.04515,99.6091461181641,,,,,,,,,,,,,0,,,,0.0049,,,,,,311.3394165,,,,
,29181287.64,308.4618835,99.6091461181641,1.9580167525041E-5,4.61756909370949E-7,1,0.999253354069792,40.0298881530762,1.99618740459565,16.4599996060133,0.000220697035573637,4.15660085076905E-5,0.25,2.86176712782722E-7,1.95734826921998E-5,2.9882275259965E-7,308.4618835,308.4618835,99.6091461181641,99.6091461181641,56.8603482599676,20.5519504137987,28.603769,0,0,0,40,4374,305.1072,99.6091461181641,,,,,,,,,,,,,0,,,,0,,,,,,308.4618835,,,,
,29181406.75,305.4915161,99.6091461181641,1.97831781347429E-5,4.61334918611932E-7,1,0.999253354069792,40.0298881530762,1.99614640699707,16.4599996060133,0.000223369418898009,3.98938079015612E-5,0.25,1.02570876370539E-7,1.97786327779091E-5,1.15572103112473E-7,305.4915161,305.4915161,99.6091461181641,99.6091461181641,56.9306948266983,20.5513848544384,28.983419,0,0,0,40,4374,302.1317,99.6091461181641,,,,,,,,,,,,,0,,,,0,,,,,,305.4915161,,,,
,29181529.25,302.4850159,99.6091461181641,2.04836261429342E-5,4.24169830862192E-7,1,0.999253354069792,40.0298881530762,1.99589350724384,16.4599996060133,0.000231340225990272,4.09285010526433E-5,0.25,7.26572096952886E-8,2.04811333919337E-5,8.63010002164631E-8,302.4850159,302.4850159,99.6091461181641,99.6091461181641,57.4371901071599,20.5542949079726,29.363071,0,0,0,40,4374,299.03985,99.6091461181641,,,,,,,,,,,,,0,,,,0.0049,,,,,,302.4850159,,,,
,29181648.415,299.4862976,99.6091461181641,2.05396468624719E-5,4.53459287608564E-7,1,0.999253354069792,40.0298881530762,2.00842017568756,16.4700001478195,0.000233877424506223,3.84585563723804E-5,0.25,-1.76391973829776E-7,2.05395111650119E-5,-1.6253412348968E-7,299.4862976,299.4862976,99.6091461181641,99.6091461181641,57.0424677049483,20.5531598939999,29.363071,0,0,0,40,4374,296.0505,99.6091461181641,,,,,,,,,,,,,0,,,,-0.0049,,,,,,299.4862976,,,,
,29181768.67,296.4825745,99.6091461181641,2.05062262781503E-5,5.04886150841543E-7,1,0.999253354069792,40.0298881530762,2.00844538227918,16.4700001478195,0.000233138305934449,4.06306358989711E-5,0.25,1.98454471603835E-8,2.05081578494233E-5,3.38501673313211E-8,296.4825745,296.4825745,99.6091461181641,99.6091461181641,57.0666981890445,20.5523654706181,29.363071,0,0,0,40,4374,293.0594,99.6091461181641,,,,,,,,,,,,,0,,,,-0.0049,,,,,,296.4825745,,,,
,29181891.61,293.4620361,99.6091461181641,2.14055919742632E-5,5.09578030485866E-7,1,0.999253354069792,40.0298881530762,2.00837347506105,16.4700001478195,0.000244134637519081,3.80683764471426E-5,0.25,-3.61761559334546E-7,2.14101834203823E-5,-3.47030728694659E-7,293.4620361,293.4620361,99.6091461181641,99.6091461181641,57.0659165605253,20.5546727773234,28.983419,0,0,0,40,4374,289.9734,99.6091461181641,,,,,,,,,,,,,0,,,,0,,,,,,293.4620361,,,,
touchdown = 10.3000001981854 mm,29182009.835,290.5051575,99.6091461181641,2.12135175503303E-5,3.86363666610803E-7,1,0.999253354069792,40.0298881530762,2.00842156633086,16.499999910593,0.000241045629429468,4.30953234664761E-5,0.25,1.12904340478392E-7,2.12199846924481E-5,1.27794297926856E-7,290.5051575,290.5051575,99.6091461181641,99.6091461181641,56.994006736756,20.5498072845157,28.983419,0,0,0,40,4374,286.99005,99.6091461181641,,,,,,,,,,,,,0,,,,0.00245,,,,,,290.5051575,,,,
,29182111.76,287.970459,99.6091461181641,2.21731712839798E-5,3.66276059755587E-7,1,0.999253354069792,40.0298881530762,2.00800142756322,16.499999910593,0.000252529360809206,4.15387919299005E-5,0.25,-1.90027296670163E-7,2.21821599663852E-5,-1.74409692837667E-7,287.970459,287.970459,99.6091461181641,99.6091461181641,56.8814522299868,20.5574310538901,28.983419,0,0,0,40,4374,284.462,99.6091461181641,,,,,,,,,,,,,0,,,,0.00245,,,,,,287.970459,,,,
,29182231.29,284.9960938,99.6091461181641,2.15505838910402E-5,4.8403684636101E-7,1,0.999253354069792,40.0298881530762,2.00801585385379,16.499999910593,0.000245647122552595,3.93352518897434E-5,0.25,-2.76485086082573E-7,2.15616826855724E-5,-2.61174877907711E-7,284.9960938,284.9960938,99.6091461181641,99.6091461181641,57.1526773261599,20.5566300446252,29.363071,0,0,0,40,4374,281.44465,99.6091461181641,,,,,,,,,,,,,0,,,,0,,,,,,284.9960938,,,,
,29182352.31,281.9828186,99.6091461181641,2.28958025019684E-5,4.41279369869012E-7,1,0.999253354069792,40.0298881530762,2.00769116228559,16.499999910593,0.000259920137896319,4.78384010265852E-5,0.25,2.37989142227965E-7,2.29096813045021E-5,2.54765239272505E-7,281.9828186,281.9828186,99.6091461181641,99.6091461181641,57.1096877576022,20.5583518495159,29.363071,0,0,0,40,4374,278.4139,99.6091461181641,,,,,,,,,,,,,0,,,,0,,,,,,281.9828186,,,,
,29182453.51,279.4760742,99.6091461181641,2.23903811575886E-5,3.71779559346699E-7,1,0.999253354069792,40.0298881530762,1.98399593098307,16.5199991315603,0.000250755695517845,4.96350811027048E-5,0.25,5.32737324356719E-7,2.24057412162645E-5,5.49554124982591E-7,279.4454651,279.5066833,99.6091461181641,99.6091461181641,56.8001628639868,20.5641807964963,29.742722,0,0,0,40,4374,275.895,99.6091461181641,,,,,,,,,,,,,0,,,,0.0049,,,,,,279.4760742,,,,
,29182573.925,276.4598999,99.6091461181641,2.30580613623934E-5,4.01367379328728E-7,1,0.999253354069792,40.0298881530762,1.98394417091709,16.5199991315603,0.000259317715628963,4.49863222120417E-5,0.25,3.06722524896622E-9,2.30767696652266E-5,2.02282622562824E-8,276.4598999,276.4598999,99.6091461181641,99.6091461181641,56.9439825115252,20.5681447430378,29.363071,0,0,0,40,4374,272.8729,99.6091461181641,,,,,,,,,,,,,0,,,,-0.00245,,,,,,276.4598999,,,,
,29182694.71,273.4934692,99.6091461181641,2.32004808678717E-5,4.01428430114885E-7,1,0.999253354069792,40.0298881530762,1.98377954759068,16.5199991315603,0.000261671336428715,4.09681033434056E-5,0.25,-3.79233733278591E-7,2.32220549027857E-5,-3.62084168000613E-7,273.4934692,273.4934692,99.6091461181641,99.6091461181641,56.9056827140829,20.5691842132102,29.363071,0,0,0,40,4374,269.8527,99.6091461181641,,,,,,,,,,,,,0,,,,-0.0049,,,,,,273.4934692,,,,
,29182830.53,270.0902405,99.6091461181641,,,2,,,,16.5600001132488,,,,,,,270.0902405,270.0902405,99.6091461181641,99.6091461181641,,,29.363071,,,,-99999999,4374,266.4451,99.6091461181641,,,,,,,,,,,,,,,,,,,,,,,270.0902405,,,,
,29182935.415,267.4839172,99.6091461181641,2.41969300738817E-5,4.73500977821319E-7,1,0.999253354069792,40.0298881530762,1.9836967044132,16.550000756979,0.000272301102183648,4.65225318421433E-5,0.25,-5.93267881871425E-8,2.42243734210595E-5,-4.06410473935493E-8,267.4839172,267.4839172,99.6091461181641,99.6091461181641,57.0065127930637,20.5681587451964,29.363071,0,0,0,40,4374,263.8172,99.6091461181641,,,,,,,,,,,,,0,,,,-0.0049,,,,,,267.4839172,,,,
,29183055.095,264.4914856,99.6091461181641,2.45200764295322E-5,4.11676161085781E-7,1,0.999253354069792,40.0298881530762,1.98361564512709,16.550000756979,0.000276154940173926,4.60013074570857E-5,0.25,-1.62225271618168E-7,2.45505836407543E-5,-1.43159989781106E-7,264.4914856,264.4914856,99.6091461181641,99.6091461181641,56.9830639374868,20.5704164886476,28.983419,0,0,0,40,4374,260.8224,99.6091461181641,,,,,,,,,,,,,0,,,,0,,,,,,264.4914856,,,,
,29183176.975,261.4609985,99.6091461181641,2.48304883856821E-5,4.34662629486904E-7,1,0.999253354069792,40.0298881530762,1.98397709292707,16.550000756979,0.000279907428409578,4.55721712349622E-5,0.25,-2.55610053739749E-7,2.48641352662691E-5,-2.36166745908381E-7,261.4609985,261.4609985,99.6091461181641,99.6091461181641,57.4410982497561,20.5683266687386,29.363071,0,0,0,40,4374,257.7798,99.6091461181641,,,,,,,,,,,,,0,,,,0.00245,,,,,,261.4609985,,,,
,29183297.11,258.4413452,99.6091461181641,2.52082049841666E-5,4.07083514118125E-7,1,0.999253354069792,40.0298881530762,1.98420895171865,16.5699999779463,0.000284129412133025,4.68414121867453E-5,0.25,-2.09503504980272E-7,2.52450312368846E-5,-1.89434450550811E-7,258.4413452,258.4413452,99.6091461181641,99.6091461181641,56.9752476522945,20.5646911874427,28.983419,0,0,0,40,4374,254.7776,99.6091461181641,,,,,,,,,,,,,0,,,,0,,,,,,258.4413452,,,,
,29183417.595,255.446228,99.6091461181641,2.57801746031829E-5,3.9987122723857E-7,1,0.999253354069792,40.0298881530762,1.98396202964027,16.5699999779463,0.000289706892880344,5.28953212247712E-5,0.25,2.28956647450736E-7,2.58202130265273E-5,2.50451234409333E-7,255.446228,255.446228,99.6091461181641,99.6091461181641,57.0737328457176,20.5680982962823,29.363071,0,0,0,40,4374,251.7542,99.6091461181641,,,,,,,,,,,,,0,,,,-0.0049,,,,,,255.446228,,,,
,29183536.915,252.4532318,99.6091461181641,2.60723507364612E-5,4.09424877280813E-7,1,0.999253354069792,40.0298881530762,1.98396017441727,16.5699999779463,0.000293181573282846,5.25741242220273E-5,0.25,1.48953091480007E-7,2.61156690439239E-5,1.70887715649946E-7,252.4532318,252.4532318,99.6091461181641,99.6091461181641,57.0737328457176,20.5699348995357,29.363071,0,0,0,40,4374,248.76365,99.6091461181641,,,,,,,,,,,,,0,,,,-0.0049,,,,,,252.4532318,,,,
,29183663.8,249.3442993,99.6091461181641,,,2,,,,16.6300001806021,,,,,,,249.3442993,249.3442993,99.6091461181641,99.6091461181641,,,29.742722,,,,-99999999,4374,245.5892,99.6091461181641,,,,,,,,,,,,,,,,,,,,,,,249.3442993,,,,
,29183777.81,246.4345856,99.6091461181641,2.72750143063939E-5,3.72730099864488E-7,1,0.999253354069792,40.0298881530762,2.00798248973479,16.6200008243322,0.000311125781249108,5.09704810619708E-5,0.25,-2.55439049462403E-7,2.7326461178585E-5,-2.32553121394822E-7,246.4345856,246.4345856,99.6091461181641,99.6091461181641,57.2464727484676,20.5592448907618,28.983419,0,0,0,40,4374,242.7438,99.6091461181641,,,,,,,,,,,,,0,,,,-0.0049,,,,,,246.4345856,,,,
,29183897.065,243.4561768,99.6091461181641,2.78502415852778E-5,4.31536849487371E-7,1,0.999253354069792,40.0298881530762,2.00792214481218,16.6200008243322,0.000317531022838101,5.30893792377737E-5,0.25,-1.69868347520521E-7,2.79056052747716E-5,-1.45988000078941E-7,243.4561768,243.4561768,99.6091461181641,99.6091461181641,57.1010898438907,20.5587899248261,29.363071,0,0,0,40,4374,239.7562,99.6091461181641,,,,,,,,,,,,,0,,,,0,,,,,,243.4561768,,,,
,29184016.17,240.4985504,99.6091461181641,2.79186230433263E-5,3.78148928736902E-7,1,0.999253354069792,40.0298881530762,2.00799162016729,16.6200008243322,0.00031766700596681,5.71870555103166E-5,0.25,1.77004109975427E-7,2.79767023665593E-5,2.02017858410558E-7,240.4985504,240.4985504,99.6091461181641,99.6091461181641,57.1886322380445,20.5584187859415,28.603769,0,0,0,40,4374,236.7843,99.6091461181641,,,,,,,,,,,,,0,,,,0,,,,,,240.4985504,,,,
,29184137.415,237.4742432,99.6091461181641,2.83487164710434E-5,3.86799270165202E-7,1,0.999253354069792,40.0298881530762,1.98399930752837,16.6400000452995,0.000319357464451557,5.48589040218599E-5,0.25,-4.73260516859214E-8,2.84108745090718E-5,-2.2012362221105E-8,237.4742432,237.4742432,99.6091461181641,99.6091461181641,57.1714364106214,20.566655579781,29.363071,0,0,0,40,4374,233.74695,99.6091461181641,,,,,,,,,,,,,0,,,,0,,,,,,237.4742432,,,,
,29184256.42,234.4824066,99.6091461181641,2.90159204962013E-5,3.66332597350118E-7,1,0.999253354069792,40.0298881530762,1.98402790614534,16.6400000452995,0.000327234281526871,5.42995707536355E-5,0.25,-2.13718962642889E-7,2.90827007060598E-5,-1.87786869536175E-7,234.4824066,234.4824066,99.6091461181641,99.6091461181641,57.200356665833,20.5671417565511,28.603769,0,0,0,40,4374,230.7668,99.6091461181641,,,,,,,,,,,,,0,,,,0.00245,,,,,,234.4824066,,,,
,29184376.035,231.4980011,99.6091461181641,2.94447249522176E-5,3.66835860409314E-7,1,0.999253354069792,40.0298881530762,1.98403999038359,16.6400000452995,0.000332130170159066,5.49704889077761E-5,0.25,-2.29509391366936E-7,2.95155378366337E-5,-2.02819159715689E-7,231.4980011,231.4980011,99.6091461181641,99.6091461181641,56.9627415959868,20.5683363524436,29.363071,0,0,0,40,4374,227.77415,99.6091461181641,,,,,,,,,,,,,0,,,,0,,,,,,231.4980011,,,,
,29184495.81,228.5368652,99.6091461181641,,,2,,,,16.7000002479553,,,,,,,228.5368652,228.5368652,99.6091461181641,99.6091461181641,,,28.603769,,,,-99999999,4374,224.7816,99.6091461181641,,,,,,,,,,,,,,,,,,,,,,,228.5368652,,,,
,29184597.33,225.9656219,99.6091461181641,3.01959287602628E-5,4.38620434543913E-7,1,0.999253354069792,40.0298881530762,2.00798773022882,16.6900008916855,0.000344552551715447,5.7258636409329E-5,0.25,-2.16405221166555E-7,3.02742588504404E-5,-1.88181444060531E-7,225.9656219,225.9656219,99.6091461181641,99.6091461181641,57.1362631272561,20.5621714372844,29.363071,0,0,0,40,4374,222.2401,99.6091461181641,,,,,,,,,,,,,0,,,,0.0049,,,,,,225.9656219,,,,
,29184717.51,222.9472656,99.6091461181641,3.09674568367072E-5,2.79219399835751E-7,1,0.999253354069792,40.0298881530762,2.00806808309785,16.6900008916855,0.000352619640029691,6.3259306528404E-5,0.25,1.7496486039898E-7,3.10505849661924E-5,2.05447440880561E-7,222.9472656,222.9472656,99.6091461181641,99.6091461181641,57.2300585495638,20.5603033039635,28.983419,0,0,0,40,4374,219.2468,99.6091461181641,,,,,,,,,,,,,0,,,,-0.0049,,,,,,222.9472656,,,,
,29184837.835,219.9650269,99.6091461181641,3.15943605915272E-5,4.00390521958681E-7,1,0.999253354069792,40.0298881530762,2.00784219225159,16.6900008916855,0.000361076409667225,5.69305453787541E-5,0.25,-4.89588225762476E-7,3.16830106531401E-5,-4.59811868793246E-7,219.9650269,219.9650269,99.6091461181641,99.6091461181641,57.291807202583,20.5636912042815,28.983419,0,0,0,40,4374,216.236,99.6091461181641,,,,,,,,,,,,,0,,,,-0.0049,,,,,,219.9650269,,,,
,29184956.72,216.9809418,99.6091461181641,3.19924332171426E-5,3.76901624770822E-7,1,0.999253354069792,40.0298881530762,1.98383729610432,16.7299993336201,0.000361352183617227,5.77811504527374E-5,0.25,-4.26573770336797E-7,3.2085346437323E-5,-3.957342828159E-7,216.9809418,216.9809418,99.6091461181641,99.6091461181641,56.9572701963522,20.5699833095027,28.983419,0,0,0,40,4374,213.2837,99.6091461181641,,,,,,,,,,,,,0,,,,-0.0049,,,,,,216.9809418,,,,
,29185076.455,213.9813843,99.6091461181641,3.2703278313032E-5,3.71618657838025E-7,1,0.999253354069792,40.0298881530762,1.98378033108294,16.7299993336201,0.000368384835443379,6.49619733652182E-5,0.25,8.62561709464262E-8,3.2801003924188E-5,1.19878464740582E-7,213.9813843,213.9813843,99.6091461181641,99.6091461181641,56.9830639374868,20.5710769799891,28.603769,0,0,0,40,4374,210.2811,99.6091461181641,,,,,,,,,,,,,0,,,,0,,,,,,213.9813843,,,,
,29185195.69,210.9993439,99.6091461181641,3.33473197778114E-5,3.6694728277276E-7,1,0.999253354069792,40.0298881530762,1.98376795132048,16.7299993336201,0.000376160154493217,6.34498332983315E-5,0.25,-1.6086885351031E-7,3.34505217362451E-5,-1.26735655353159E-7,210.9993439,210.9993439,99.6091461181641,99.6091461181641,56.9908802226791,20.5728384870315,28.983419,0,0,0,40,4374,207.2955,99.6091461181641,,,,,,,,,,,,,0,,,,0,,,,,,210.9993439,,,,
,29185326.81,207.7306366,99.6091461181641,,,2,,,,16.7899995362759,,,,,,,207.7306366,207.7306366,99.6091461181641,99.6091461181641,,,28.983419,,,,-99999999,4374,204.0231,99.6091461181641,,,,,,,,,,,,,,,,,,,,,,,207.7306366,,,,
,29185436.655,204.9542694,99.6091461181641,3.44712357810253E-5,3.74807220324888E-7,1,0.999253354069792,40.0298881530762,2.00775260799353,16.7699996381998,0.000393574091183645,6.53662068228236E-5,0.25,-2.5460906677538E-7,3.45848455200279E-5,-2.18306982447533E-7,204.9542694,204.9542694,99.6091461181641,99.6091461181641,57.0510656186599,20.5657675683171,28.983419,0,0,0,40,4374,201.28285,99.6091461181641,,,,,,,,,,,,,0,,,,0,,,,,,204.9542694,,,,
,29185556.405,201.9504089,99.6091461181641,3.51894203799291E-5,3.83392868543459E-7,1,0.999253354069792,40.0298881530762,2.00760413453389,16.7699996381998,0.00040076919004245,7.25755024827637E-5,0.25,2.52009913994964E-7,3.53082617529326E-5,2.91496714774394E-7,201.9504089,201.9504089,99.6091461181641,99.6091461181641,56.9564885678329,20.5670158248778,28.603769,0,0,0,40,4374,198.29885,99.6091461181641,,,,,,,,,,,,,0,,,,0,,,,,,201.9504089,,,,
,29185676.115,198.9499969,99.6091461181641,3.58236112133751E-5,4.01667023407693E-7,1,0.999253354069792,40.0298881530762,2.00745918476548,16.7699996381998,0.000408991737628599,6.81936280949053E-5,0.25,-2.43345260346676E-7,3.59485963710622E-5,-2.04095545501418E-7,198.9499969,198.9499969,99.6091461181641,99.6091461181641,57.1323549846599,20.5682319887073,28.603769,0,0,0,40,4374,195.3036,99.6091461181641,,,,,,,,,,,,,0,,,,-0.00245,,,,,,198.9499969,,,,
,29185794.835,195.991333,99.6091461181641,3.61072215992617E-5,3.86292630439397E-7,1,0.999253354069792,40.0298881530762,1.98376977287399,16.8299991637468,0.000406568729363024,7.40356760631831E-5,0.25,2.92270185986106E-7,3.62359827699714E-5,3.34527839510086E-7,195.991333,195.991333,99.6091461181641,99.6091461181641,56.8986480574099,20.5690492807223,28.603769,0,0,0,40,4374,192.33505,99.6091461181641,,,,,,,,,,,,,0,,,,-0.0049,,,,,,195.991333,,,,
,29185915.055,192.9563599,99.6091461181641,3.74459091328015E-5,3.39517763625986E-7,1,0.999253354069792,40.0298881530762,1.98366545615587,16.8299991637468,0.000421630945491144,7.6958631796328E-5,0.25,3.17721875041909E-7,3.75829972714566E-5,3.62505768004938E-7,192.9563599,192.9563599,99.6091461181641,99.6091461181641,57.4301554504868,20.5727506951728,28.983419,0,0,0,40,4374,189.32225,99.6091461181641,,,,,,,,,,,,,0,,,,0,,,,,,192.9563599,,,,
,29186035.425,189.9639587,99.6091461181641,3.79112994294928E-5,4.13433694659498E-7,1,0.999253354069792,40.0298881530762,1.98370649246131,16.8299991637468,0.000427349835359303,7.5445443209771E-5,0.25,1.00985725836299E-7,3.80538773419821E-5,1.46453286428557E-7,189.9639587,189.9639587,99.6091461181641,99.6091461181641,57.1659650109868,20.5729788447308,28.224119,0,0,0,40,4374,186.3092,99.6091461181641,,,,,,,,,,,,,0,,,,-0.0098,,,,,,189.9639587,,,,
,29186160.59,186.8623352,99.6091461181641,,,2,,,,16.8999999082088,,,,,,,186.8623352,186.8623352,99.6091461181641,99.6091461181641,,,28.603769,,,,-99999999,4374,183.187,99.6091461181641,,,,,,,,,,,,,,,,,,,,,,,186.8623352,,,,
,29186274.575,183.9627686,99.6091461181641,3.9183784685482E-5,3.47347550419062E-7,1,0.999253354069792,40.0298881530762,1.98367269821911,16.8800000101328,0.000442563000831125,7.3414265056598E-5,0.25,-3.03386061640346E-7,3.93388484328909E-5,-2.55945089580797E-7,183.9627686,183.9627686,99.6091461181641,99.6091461181641,57.159711982833,20.5741506441272,28.603769,0,0,0,40,4374,180.32865,99.6091461181641,,,,,,,,,,,,,0,,,,0,,,,,,183.9627686,,,,
,29186396.935,180.9666595,99.6091461181641,3.95840568254191E-5,4.15651318376187E-7,1,0.999253354069792,40.0298881530762,1.98359353807002,16.8800000101328,0.000446739911751671,7.62790507496061E-5,0.25,-1.20477024887522E-7,3.97440336710204E-5,-7.0678878461588E-8,180.9666595,180.9666595,99.6091461181641,99.6091461181641,57.0799858738714,20.574036105061,28.603769,0,0,0,40,4374,177.2184,99.6091461181641,,,,,,,,,,,,,0,,,,-0.00245,,,,,,180.9666595,,,,
,29186514.095,177.9779663,99.6091461181641,4.0719312346929E-5,3.3083228681879E-7,1,0.999253354069792,40.0298881530762,1.98370722461425,16.8800000101328,0.000460268189944271,7.47398198657398E-5,0.25,-4.56427431815813E-7,4.08879277984757E-5,-4.05431616200633E-7,177.9779663,177.9779663,99.6091461181641,99.6091461181641,56.6375841319868,20.5742599421511,28.603769,0,0,0,40,4374,174.3304,99.6091461181641,,,,,,,,,,,,,0,,,,-0.00245,,,,,,177.9779663,,,,
,29186632.945,174.997345,99.6091461181641,4.12151110232365E-5,3.18381464215892E-7,1,0.999253354069792,40.0298881530762,1.9835598592977,16.9399995356798,0.000464952765240367,8.09818601882077E-5,0.25,9.30340812996134E-9,4.13887622175577E-5,6.41080285140853E-8,174.997345,174.997345,99.6091461181641,99.6091461181641,56.7868751791599,20.5742467866836,28.224119,0,0,0,40,4374,171.3994,99.6091461181641,,,,,,,,,,,,,0,,,,0,,,,,,174.997345,,,,
,29186752.73,171.9496155,99.6091461181641,4.18722762806063E-5,3.4656961073018E-7,1,0.999253354069792,40.0298881530762,1.98344478453605,16.9399995356798,0.000472110122357395,8.38357233388288E-5,0.25,1.46392988706733E-7,4.20521906995233E-5,2.0400400863373E-7,171.9496155,171.9496155,99.6091461181641,99.6091461181641,57.1909771236022,20.5752683471659,27.844467,0,0,0,40,4374,168.4341,99.6091461181641,,,,,,,,,,,,,0,,,,0,,,,,,171.9496155,,,,
,29186872.35,168.9707336,99.6091461181641,4.28617144793897E-5,3.61183601776443E-7,1,0.999253354069792,40.0298881530762,1.98327185844369,16.9399995356798,0.000483290377323043,8.56787087916872E-5,0.25,1.36164504325048E-7,4.30495098876824E-5,1.96547561139024E-7,168.9707336,168.9707336,99.6091461181641,99.6091461181641,57.1120326431599,20.579578926975,27.844467,0,0,0,40,4374,165.447,99.6091461181641,,,,,,,,,,,,,0,,,,-0.0049,,,,,,168.9707336,,,,
,29186993.17,165.9777832,99.6091461181641,,,2,,,,17.0100002801418,,,,,,,165.9777832,165.9777832,99.6091461181641,99.6091461181641,,,27.464817,,,,-99999999,4374,162.4278,99.6091461181641,,,,,,,,,,,,,,,,,,,,,,,165.9777832,,,,
,29187091.715,163.4798126,99.6091461181641,4.40285434848702E-5,3.59877803293185E-7,1,0.999253354069792,40.0298881530762,2.00726476193592,17.000000923872,0.00050294649487669,8.50621795399111E-5,0.25,-2.11642274183463E-7,4.42286329569069E-5,-1.48220918324544E-7,163.4798126,163.4798126,99.6091461181641,99.6091461181641,57.054973761256,20.56872621495,27.844467,0,0,0,40,4374,159.9635,99.6091461181641,,,,,,,,,,,,,0,,,,0,,,,,,163.4798126,,,,
,29187211.67,160.486557,99.6091461181641,4.44268494653567E-5,4.28069349638887E-7,1,0.999253354069792,40.0298881530762,2.00695506806208,17.000000923872,0.000507426054642607,8.60350423373061E-5,0.25,-1.96995432817918E-7,4.46323028115397E-5,-1.31168719306045E-7,160.486557,160.486557,99.6091461181641,99.6091461181641,57.0698247031214,20.5726655790431,27.844467,0,0,0,40,4374,156.9638,99.6091461181641,,,,,,,,,,,,,0,,,,-0.0049,,,,,,160.486557,,,,
,29187332.385,157.4594574,99.6091461181641,4.55072180297387E-5,3.60313375949028E-7,1,0.999253354069792,40.0298881530762,2.0069675097743,17.000000923872,0.000519367928502382,9.06728934344227E-5,0.25,1.86750423742683E-8,4.57209564775953E-5,8.90519096268444E-8,157.4594574,157.4594574,99.6091461181641,99.6091461181641,56.8462789466214,20.5722850814035,27.464817,0,0,0,40,4374,153.9537,99.6091461181641,,,,,,,,,,,,,0,,,,0,,,,,,157.4594574,,,,
,29187450.485,154.4706726,99.6091461181641,4.66281945142891E-5,3.57771970925352E-7,1,0.999253354069792,40.0298881530762,2.00721635976118,17.0499999076128,0.000531954011310378,9.47104864232762E-5,0.25,1.73546975449373E-7,4.68505333095552E-5,2.48445272139048E-7,154.4706726,154.4706726,99.6091461181641,99.6091461181641,57.1987934087945,20.5717852310543,27.464817,0,0,0,40,4374,151.0117,99.6091461181641,,,,,,,,,,,,,0,,,,-0.0049,,,,,,154.4706726,,,,
,29187570.655,151.4697876,99.6091461181641,4.71323443867537E-5,3.93430637759655E-7,1,0.999253354069792,40.0298881530762,2.00721663234883,17.0499999076128,0.00053820274571213,9.31187735970893E-5,0.25,-5.65516002041152E-8,4.73609915849053E-5,2.02931055630579E-8,151.4697876,151.4697876,99.6091461181641,99.6091461181641,57.0299616486406,20.5710990105336,27.085165,0,0,0,40,4374,148.004,99.6091461181641,,,,,,,,,,,,,0,,,,0,,,,,,151.4697876,,,,
,29187689.345,148.4763031,99.6091461181641,4.83363140712546E-5,3.51469135368777E-7,1,0.999253354069792,40.0298881530762,2.00681652837123,17.0499999076128,0.000551875871646894,9.55443036074039E-5,0.25,-5.52941296389241E-8,4.85743221017388E-5,2.59261238153162E-8,148.4763031,148.4763031,99.6091461181641,99.6091461181641,56.8501870892175,20.5758515261166,27.085165,0,0,0,40,4374,145.056,99.6091461181641,,,,,,,,,,,,,0,,,,-0.0049,,,,,,148.4763031,,,,
,29187821.88,145.1826782,99.6091461181641,,,2,,,,17.1300002625585,,,,,,,145.1826782,145.1826782,99.6091461181641,99.6091461181641,,,27.464817,,,,-99999999,4374,141.7616,99.6091461181641,,,,,,,,,,,,,,,,,,,,,,,145.1826782,,,,
,29187926.985,142.493042,99.6091461181641,4.93911725917886E-5,3.72491197856217E-7,1,0.999253354069792,40.0298881530762,1.98349121411496,17.119999974966,0.000557635071586941,9.71529915380893E-5,0.25,-9.30208936307147E-9,4.96411407991171E-5,7.93481607953154E-8,142.493042,142.493042,99.6091461181641,99.6091461181641,56.8126689202945,20.576675692886,27.464817,0,0,0,40,4374,139.13385,99.6091461181641,,,,,,,,,,,,,0,,,,-0.00245,,,,,,142.493042,,,,
,29188046.61,139.4929962,99.6091461181641,5.06997759313386E-5,3.90354692700272E-7,1,0.999253354069792,40.0298881530762,1.98332457705614,17.119999974966,0.000572772262482269,9.75972558040655E-5,0.25,-2.01130770884134E-7,5.09600487660252E-5,-1.08029679434132E-7,139.4929962,139.4929962,99.6091461181641,99.6091461181641,57.149550812083,20.580029736782,27.085165,0,0,0,40,4374,136.1592,99.6091461181641,,,,,,,,,,,,,0,,,,0,,,,,,139.4929962,,,,
,29188166.65,136.4810028,99.6091461181641,5.14284959761379E-5,3.50980828416384E-7,1,0.999253354069792,40.0298881530762,1.98328488382551,17.119999974966,0.00058082159826492,0.000100200511569553,0.25,-1.01407831585284E-7,5.16955651160759E-5,-3.09351673042407E-9,136.4810028,136.4810028,99.6091461181641,99.6091461181641,57.4145228801022,20.5841077270967,27.085165,0,0,0,40,4374,133.1788,99.6091461181641,,,,,,,,,,,,,0,,,,-0.0049,,,,,,136.4810028,,,,
,29188286.785,133.4461823,99.6091461181641,5.22033355778362E-5,3.14956679247563E-7,1,0.999253354069792,40.0298881530762,1.98357144246717,17.1799995005131,0.000588602591643952,0.000107954074057543,0.25,4.44582695835694E-7,5.24764927844255E-5,5.50917287407906E-7,133.4461823,133.4461823,99.6091461181641,99.6091461181641,57.126101956506,20.5768429165917,27.085165,0,0,0,40,4374,130.18315,99.6091461181641,,,,,,,,,,,,,0,,,,0,,,,,,133.4461823,,,,
,29188404.43,130.4866028,99.6091461181641,5.31467015922282E-5,2.81280941601366E-7,1,0.999253354069792,40.0298881530762,1.98334988954076,17.1799995005131,0.000600684028362061,0.000101450021824308,0.25,-2.99565657073823E-7,5.34292590176522E-5,-1.91358678445272E-7,130.4866028,130.4866028,99.6091461181641,99.6091461181641,57.2324034351214,20.5820652975523,26.325863,0,0,0,40,4374,127.2591,99.6091461181641,,,,,,,,,,,,,0,,,,-0.00245,,,,,,130.4866028,,,,
,29188525.375,127.4564285,99.6091461181641,5.38807895403655E-5,3.7329414749973E-7,1,0.999253354069792,40.0298881530762,1.98329594573289,17.1799995005131,0.000608207682443913,0.000107372937286488,0.25,9.2137306170051E-8,5.4169266161479E-5,2.08334925780554E-7,127.4252777,127.4875793,99.6091461181641,99.6091461181641,56.9643048530253,20.5839693164991,26.325863,0,0,0,40,4374,124.25195,99.6091461181641,,,,,,,,,,,,,0,,,,-0.00245,,,,,,127.4564285,,,,
,29188649.61,124.35495,99.6091461181641,,,2,,,,17.2599998554587,,,,,,,124.35495,124.35495,99.6091461181641,99.6091461181641,,,27.085165,,,,-99999999,4374,121.1756,99.6091461181641,,,,,,,,,,,,,,,,,,,,,,,124.35495,,,,
,29188764.76,121.4662018,99.6091461181641,5.51718492434612E-5,3.58730660318871E-7,1,0.999253354069792,40.0298881530762,1.99477240900741,17.2499995678663,0.000626628180055161,0.000108566207248309,0.25,-9.14329664234058E-8,5.54726702185022E-5,3.65098966951126E-8,121.4662018,121.4662018,99.6091461181641,99.6091461181641,56.7454488676406,20.5762388171983,25.946213,0,0,0,40,4374,118.3073,99.6091461181641,,,,,,,,,,,,,0,,,,0,,,,,,121.4662018,,,,
,29188882.51,118.477066,99.6091461181641,5.60855181294342E-5,3.72563525014221E-7,1,0.999253354069792,40.0298881530762,1.9945551960277,17.2499995678663,0.000636531989936286,0.000112822404099276,0.25,1.18654997989148E-7,5.63929560593684E-5,2.55467921242812E-7,118.477066,118.477066,99.6091461181641,99.6091461181641,57.1206305568714,20.5760646653332,26.705515,0,0,0,40,4374,115.3824,99.6091461181641,,,,,,,,,,,,,0,,,,0.0049,,,,,,118.477066,,,,
,29189001.42,115.4605713,99.6091461181641,5.6927751904424E-5,3.26198415073863E-7,1,0.999253354069792,40.0298881530762,1.9945459491468,17.2499995678663,0.000646441347065605,0.000112621544751892,0.25,-5.29270529770526E-8,5.72420828892453E-5,9.11914602801506E-8,115.4605713,115.4605713,99.6091461181641,99.6091461181641,56.7235632691022,20.5804623314537,26.705515,0,0,0,40,4374,112.4304,99.6091461181641,,,,,,,,,,,,,0,,,,-0.0049,,,,,,115.4605713,,,,
,29189119.235,112.4955292,99.6091461181641,5.76836179977506E-5,3.29594831458725E-7,1,0.999253354069792,40.0298881530762,1.98338111598573,17.3099990934134,0.000651198196576768,0.000115454619711319,0.25,1.11882285328058E-7,5.80031244148791E-5,2.65585909287942E-7,112.4627686,112.5282898,99.6091461181641,99.6091461181641,56.7868751791599,20.5825670954163,25.946213,0,0,0,40,4374,109.5056,99.6091461181641,,,,,,,,,,,,,0,,,,-0.00245,,,,,,112.4955292,,,,
,29189238.08,109.4965439,99.6091461181641,5.81400094434628E-5,3.23114676786729E-7,1,0.999253354069792,40.0298881530762,1.98325394857301,17.3099990934134,0.000656219915867002,0.000116943339419478,0.25,1.56742619968727E-7,5.84629219354654E-5,3.19370626184307E-7,109.4965439,109.4965439,99.6091461181641,99.6091461181641,57.0964000727753,20.584353238465,26.325863,0,0,0,40,4374,106.55555,99.6091461181641,,,,,,,,,,,,,0,,,,0,,,,,,109.4965439,,,,
,29189356.305,106.4947891,99.6091461181641,5.89029852573948E-5,3.20449938312421E-7,1,0.999253354069792,40.0298881530762,1.98313023739748,17.3099990934134,0.00066466851754581,0.000119208349388714,0.25,2.15889461590849E-7,5.92304685657078E-5,3.8914272811928E-7,106.4947891,106.4947891,99.6091461181641,99.6091461181641,57.098744958333,20.5861996210774,25.946213,0,0,0,40,4374,103.6259,99.6091461181641,,,,,,,,,,,,,0,,,,0.0049,,,,,,106.4947891,,,,
,29189476.11,103.5147247,99.6091461181641,,,2,,,,17.3900003796816,,,,,,,103.5147247,103.5147247,99.6091461181641,99.6091461181641,,,25.946213,,,,-99999999,4374,100.6633,99.6091461181641,,,,,,,,,,,,,,,,,,,,,,,103.5147247,,,,
,29189577.235,100.9407654,99.6091461181641,5.97357322628064E-5,3.28290566770421E-7,1,0.999253354069792,40.0298881530762,1.9832307704138,17.3799991607666,0.000674252335790916,0.000119964418343939,0.25,1.18768689129932E-7,6.00672384189357E-5,3.11517628672302E-7,100.9407654,100.9407654,99.6091461181641,99.6091461181641,57.2800827747945,20.5829032645861,25.946213,0,0,0,40,4374,98.13205,99.6091461181641,,,,,,,,,,,,,0,,,,0.00245,,,,,,100.9407654,,,,
,29189693.805,97.9457474,99.6091461181641,6.0484922687029E-5,3.02506339599269E-7,1,0.999253354069792,40.0298881530762,1.98322234896427,17.3799991607666,0.000682611962473485,0.000121904810482365,0.25,1.48640680588817E-7,6.08189782428376E-5,3.54538175392195E-7,97.9457474,97.9457474,99.6091461181641,99.6091461181641,57.5395834431792,20.5879464135564,25.946213,0,0,0,40,4374,95.2534,99.6091461181641,,,,,,,,,,,,,0,,,,0.00245,,,,,,97.9457474,,,,
,29189815.5,94.9309006,99.6091461181641,6.09570632774174E-5,3.40521642744679E-7,1,0.999253354069792,40.0298881530762,1.98318761573512,17.3799991607666,0.000687861004030667,0.000123059444373749,0.25,1.56349921804388E-7,6.12909201370294E-5,3.76046665860045E-7,94.9309006,94.9309006,99.6091461181641,99.6091461181641,57.1894138665637,20.5841679553492,25.946213,0,0,0,40,4374,92.25015,99.6091461181641,,,,,,,,,,,,,0,,,,0.0049,,,,,,94.9309006,,,,
,29189933.68,91.9376755,99.6091461181641,6.16160674649638E-5,2.89821325119809E-7,1,0.999253354069792,40.0298881530762,1.98374164605888,17.4599997699261,0.000695957494803038,0.000121476640391175,0.25,-1.15358848547852E-7,6.19505975628608E-5,1.18432634443172E-7,91.9376755,91.9376755,99.6091461181641,99.6091461181641,57.2355299491984,20.5777998276077,24.807261,0,0,0,40,4374,89.3035,99.6091461181641,,,,,,,,,,,,,0,,,,-0.0049,,,,,,91.9376755,,,,
,29190048.935,88.9868927,99.6091461181641,6.18762282139863E-5,3.42198041026202E-7,1,0.999253354069792,40.0298881530762,1.98366712114108,17.4599997699261,0.000699198923552368,0.000119797259899465,0.25,-3.2265708567072E-7,6.22078841784865E-5,-7.5027063804315E-8,88.9868927,88.9868927,99.6091461181641,99.6091461181641,57.014329078256,20.579952249504,25.186911,0,0,0,40,4374,86.4674,99.6091461181641,,,,,,,,,,,,,0,,,,0,,,,,,88.9868927,,,,
,29190168.6,85.9413223,99.6091461181641,6.25260244220969E-5,2.96327088354349E-7,1,0.999253354069792,40.0298881530762,1.98401382671732,17.4599997699261,0.000705686802002567,0.00012610778236662,0.25,1.04957554127285E-7,6.28521510926879E-5,3.73479555844566E-7,85.9413223,85.9413223,99.6091461181641,99.6091461181641,57.0463758475445,20.5741024032554,25.186911,0,0,0,40,4374,83.5143,99.6091461181641,,,,,,,,,,,,,0,,,,0,,,,,,85.9413223,,,,
,29190298.42,82.6652832,99.6091461181641,,,2,,,,17.5299995830655,,,,,,,82.6652832,82.6652832,99.6091461181641,99.6091461181641,,,24.807261,,,,-99999999,4374,80.332,99.6091461181641,,,,,,,,,,,,,,,,,,,,,,,82.6652832,,,,
,29190403.855,79.9612122,99.6091461181641,6.31864414105853E-5,2.75146177663685E-7,1,0.999253354069792,40.0298881530762,1.99542420455765,17.5199992954731,0.000716927433011663,0.000127459709511936,0.25,1.38523282652821E-8,6.34948587815938E-5,3.20918628868129E-7,79.9612122,79.9612122,99.6091461181641,99.6091461181641,57.4520410490253,20.5630364945903,24.427608,0,0,0,40,4374,77.6816,99.6091461181641,,,,,,,,,,,,,0,,,,-0.00245,,,,,,79.9612122,,,,
,29190520.91,76.9892578,99.6091461181641,6.34239111863158E-5,2.98746805066255E-7,1,0.999253354069792,40.0298881530762,1.99505142272602,17.5199992954731,0.00071920531240944,0.000128565458638883,0.25,5.39874417383792E-8,6.37183542157393E-5,3.82223101955986E-7,76.9892578,76.9892578,99.6091461181641,99.6091461181641,57.2292769210445,20.5710970405779,24.047956,0,0,0,40,4374,74.82565,99.6091461181641,,,,,,,,,,,,,0,,,,-0.0049,,,,,,76.9892578,,,,
,29190637.44,73.9857864,99.6091461181641,6.37838219942481E-5,3.03615215699796E-7,1,0.999253354069792,40.0298881530762,1.99544206177489,17.5199992954731,0.000722461064201676,0.000133488953111259,0.25,4.04086809668193E-7,6.40592194588381E-5,7.56937915031405E-7,73.9857864,73.9857864,99.6091461181641,99.6091461181641,57.2386564632753,20.5676479641611,24.047956,0,0,0,40,4374,71.9532,99.6091461181641,,,,,,,,,,,,,0,,,,0,,,,,,73.9857864,,,,
,29190755.345,70.9841614,99.6091461181641,6.4026359562445E-5,3.71395288083318E-7,1,0.999253354069792,40.0298881530762,1.98416719152054,17.5899993628263,0.000721407270201585,0.00013112325815711,0.25,1.96794727199038E-7,6.42804475451538E-5,5.72373768196754E-7,70.9841614,70.9841614,99.6091461181641,99.6091461181641,56.7860935506406,20.5713443924675,24.427608,0,0,0,40,4374,69.059,99.6091461181641,,,,,,,,,,,,,0,,,,0,,,,,,70.9841614,,,,
,29190872.9,67.9908981,99.6091461181641,6.42040837535916E-5,3.04447063661908E-7,1,0.999253354069792,40.0298881530762,1.9838136741094,17.5899993628263,0.000722845438982018,0.000132079828172767,0.25,2.34261474219007E-7,6.4429924972493E-5,6.33681197619612E-7,67.9908981,67.9908981,99.6091461181641,99.6091461181641,57.4215575367753,20.5797457756903,23.668306,0,0,0,40,4374,66.16425,99.6091461181641,,,,,,,,,,,,,0,,,,0,,,,,,67.9908981,,,,
,29190990.395,64.9977722,99.6091461181641,6.45015055838953E-5,2.84301347581118E-7,1,0.999253354069792,40.0298881530762,1.98391617356502,17.5899993628263,0.000726326741721377,0.000129940054818834,0.25,-2.57394627189071E-8,6.46956389298634E-5,3.96852199635343E-7,64.9977722,64.9977722,99.6091461181641,99.6091461181641,57.5731934695061,20.5753081038268,23.288654,0,0,0,40,4374,63.2819,99.6091461181641,,,,,,,,,,,,,0,,,,0.0049,,,,,,64.9977722,,,,
,29191113.31,61.8686256,99.6091461181641,,,2,,,,17.669999717772,,,,,,,61.8686256,61.8686256,99.6091461181641,99.6091461181641,,,23.288654,,,,-99999999,4374,60.2613,99.6091461181641,,,,,,,,,,,,,,,,,,,,,,,61.8686256,,,,
,29191226.555,58.9914513,99.6091461181641,6.45026737383428E-5,3.04502470849383E-7,1,0.999253354069792,40.0298881530762,1.98386388582055,17.6599994301796,0.000725265708753844,0.000130181314472944,0.25,-2.71773396108352E-8,6.4609184864191E-5,4.33530614944774E-7,58.9914513,58.9914513,99.6091461181641,99.6091461181641,57.4793980471984,20.5780152783979,23.668306,0,0,0,40,4374,57.4842,99.6091461181641,,,,,,,,,,,,,0,,,,0.00245,,,,,,58.9914513,,,,
,29191344.095,55.9505997,99.6091461181641,6.45674905065455E-5,3.12210350859658E-7,1,0.999253354069792,40.0298881530762,1.98387579378694,17.6599994301796,0.000724759854526968,0.000133846902543176,0.25,2.83812140340027E-7,6.46197656415317E-5,7.57801493042345E-7,55.9505997,55.9505997,99.6091461181641,99.6091461181641,57.3113479155637,20.5763452998357,22.529354,0,0,0,40,4374,54.6045,99.6091461181641,,,,,,,,,,,,,0,,,,0,,,,,,55.9505997,,,,
,29191458.945,52.9855042,99.6091461181641,6.49273777672719E-5,3.43664502108951E-7,1,0.999253354069792,40.0298881530762,1.9841031786818,17.6599994301796,0.000727815319413595,0.000136990393614208,0.25,5.01161283954138E-7,6.49235438978188E-5,9.83749198685663E-7,52.9855042,52.9855042,99.6091461181641,99.6091461181641,57.2574155477368,20.5748050693503,22.529354,0,0,0,40,4374,51.80875,99.6091461181641,,,,,,,,,,,,,0,,,,-0.00245,,,,,,52.9855042,,,,
,29191557.695,50.4450912,99.6091461181641,6.46930998076049E-5,2.7372009632894E-7,1,0.999253354069792,40.0298881530762,1.98416256211538,17.7200008183718,0.000724910535421063,0.000135044876398256,0.25,3.78565271140584E-7,6.46417235373249E-5,8.58948561714143E-7,50.4450912,50.4450912,99.6091461181641,99.6091461181641,57.3027500018522,20.5749850057651,21.3904,0,0,0,40,4374,49.4104,99.6091461181641,,,,,,,,,,,,,0,,,,-0.00245,,,,,,50.4450912,,,,
,29191672.11,47.4989204,99.6091461181641,6.47971802746602E-5,3.06369007949422E-7,1,0.999253354069792,40.0298881530762,1.9839645228675,17.7200008183718,0.000725017475014655,0.000137160067831519,0.25,5.6641142996398E-7,6.46886669772732E-5,1.0401941077942E-6,47.4989204,47.4989204,99.6091461181641,99.6091461181641,57.085457273506,20.5768138138598,20.251448,0,0,0,40,4370,46.6483,99.6091461181641,,,,,,,,,,,,,0,,,,0.0049,,,,,,47.4989204,,,,
,29191791.845,44.4193382,99.6091461181641,6.5044758724049E-5,3.17383149521817E-7,1,0.999253354069792,40.0298881530762,1.98372073547843,17.7200008183718,0.0007273367834797,0.000136054853579789,0.25,4.49113536368036E-7,6.48801972655874E-5,9.10224037454263E-7,44.4193382,44.4193382,99.6091461181641,99.6091461181641,57.5223876157561,20.581049742364,19.492144,0,0,0,40,4370,43.7195,99.6091461181641,,,,,,,,,,,,,0,,,,0.00245,,,,,,44.4193382,,,,
,29191910.06,41.4351273,99.6091461181641,6.5100160002067E-5,3.11103425836384E-7,1,0.999253354069792,40.0298881530762,1.98385891973622,17.7200008183718,0.000728276631545858,0.000131371995540073,0.25,4.89485744683062E-8,6.48872596797324E-5,4.91516490191371E-7,41.4351273,41.4351273,99.6091461181641,99.6091461181641,57.3715333115445,20.5800917796514,18.732843,0,0,0,40,4370,40.8124,99.6091461181641,,,,,,,,,,,,,0,,,,0,,,,,,41.4351273,,,,
,29192007.515,38.94039345,99.6091461181641,6.48417046835867E-5,3.06672193226143E-7,1,0.999253354069792,40.0298881530762,1.98408609255306,17.7699998021126,0.000724415301651886,0.000134324857594,0.25,3.83764325480365E-7,6.45905807486727E-5,8.04156310622425E-7,38.9143219,38.966465,99.6091461181641,99.6091461181641,57.088583787583,20.5780845363102,18.353191,0,0,0,40,4370,38.4063,99.6091461181641,,,,,,,,,,,,,0,,,,-0.0049,,,,,,38.94039345,,,,
,29192125.04,35.97826,99.6091461181641,6.47055340085571E-5,3.27446797016667E-7,1,0.999253354069792,40.0298881530762,1.98375190788397,17.7699998021126,0.00072328596428888,0.000128758999086758,0.25,-5.69302787841812E-8,6.44203855225712E-5,3.40172715359779E-7,35.97826,35.97826,99.6091461181641,99.6091461181641,57.1073428720445,20.5834277401309,17.973541,0,0,0,40,4370,35.5102,99.6091461181641,,,,,,,,,,,,,0,,,,0,,,,,,35.97826,,,,
,29192244.6,32.9585953,99.6091461181641,6.49269404796002E-5,3.62743382600906E-7,1,0.999253354069792,40.0298881530762,1.9842671537717,17.7699998021126,0.000724729026054876,0.000134037792000121,0.25,4.02230163859403E-7,6.46077736011053E-5,7.74609298015908E-7,32.9585953,32.9585953,99.6091461181641,99.6091461181641,57.2660134614484,20.5791807647174,17.214239,0,0,0,40,4370,32.553,99.6091461181641,,,,,,,,,,,,,0,,,,0,,,,,,32.9585953,,,,
,29192361.605,29.9646473,99.6091461181641,6.46489530904811E-5,3.45446779905073E-7,1,0.999253354069792,40.0298881530762,2.00831909394431,17.8100001066923,0.00073052853483801,0.000130415898217832,0.25,1.89863375419801E-8,6.43109689924754E-5,3.70958556259818E-7,29.9646473,29.9646473,99.6091461181641,99.6091461181641,56.6133536478906,20.5717710157664,16.834587,0,0,0,40,4370,29.6536,99.6091461181641,,,,,,,,,,,,,0,,,,-0.00245,,,,,,29.9646473,,,,
,29192481.095,26.9763165,99.6091461181641,6.43993577655281E-5,3.87325087043214E-7,1,0.999253354069792,40.0298881530762,2.00845128331851,17.8100001066923,0.000727410933834892,0.000130769722360706,0.25,1.14106758811144E-7,6.40459131975559E-5,4.47096525654115E-7,26.9763165,26.9763165,99.6091461181641,99.6091461181641,57.2456911199484,20.5715017121053,16.075285,0,0,0,40,4370,26.69405,99.6091461181641,,,,,,,,,,,,,0,,,,0,,,,,,26.9763165,,,,
,29192599.62,23.9636364,99.6091461181641,6.47152344320135E-5,3.42461741383797E-7,1,0.999253354069792,40.0298881530762,2.0082454148904,17.8100001066923,0.000730304018497682,0.000134088687744629,0.25,3.67264475058988E-7,6.43481773916101E-5,6.87956438149025E-7,23.9636364,23.9636364,99.6091461181641,99.6091461181641,57.098744958333,20.5753553764077,15.695635,0,0,0,40,4370,23.7484,99.6091461181641,,,,,,,,,,,,,0,,,,-0.0049,,,,,,23.9636364,,,,
,29192719.39,20.9606304,99.6091461181641,6.50104403854508E-5,2.9386847481468E-7,1,0.999253354069792,40.0298881530762,2.00826905254049,17.8100001066923,0.000733539537102346,0.000134893073185962,0.25,3.94786291360881E-7,6.46356381703308E-5,7.08959056214705E-7,20.9606304,20.9606304,99.6091461181641,99.6091461181641,56.6289862182752,20.5749550980026,14.936333,0,0,0,40,4370,20.7633,99.6091461181641,,,,,,,,,,,,,0,,,,-0.00245,,,,,,20.9606304,,,,
,29192839.485,17.9450407,99.6091461181641,6.47878220631702E-5,3.35402271935867E-7,1,0.999253354069792,40.0298881530762,1.99549209731421,17.8399998694658,0.000726923354472889,0.00013161639703854,0.25,2.18762297653788E-7,6.44133452922373E-5,5.29847960604587E-7,17.9187508,17.9713306,99.6091461181641,99.6091461181641,57.4715817620061,20.5727718700461,14.177031,0,0,0,40,4370,17.7884,99.6091461181641,,,,,,,,,,,,,0,,,,0,,,,,,17.9450407,,,,
,29192958.97,14.9526949,99.6091461181641,6.48626428221829E-5,3.56523271283578E-7,1,0.999253354069792,40.0298881530762,1.99543892763984,17.8399998694658,0.00072754074213519,0.000132957888455524,0.25,3.25029739103957E-7,6.44879278159316E-5,6.35978010031186E-7,14.9526949,14.9526949,99.6091461181641,99.6091461181641,57.5012836457369,20.5743539644281,13.797379,0,0,0,40,4370,14.80825,99.6091461181641,,,,,,,,,,,,,0,,,,-0.00245,,,,,,14.9526949,,,,
,29193078.36,11.9862967,99.6091461181641,6.49008490778154E-5,3.34420626410269E-7,1,0.999253354069792,40.0298881530762,1.99522053958051,17.8399998694658,0.000727890834474155,0.000133066458642119,0.25,3.29068609744128E-7,6.45263614555937E-5,6.4018253563792E-7,11.9862967,11.9862967,99.6091461181641,99.6091461181641,57.5473997283715,20.5794468063976,12.658426,0,0,0,40,4370,11.86315,99.6091461181641,,,,,,,,,,,,,0,,,,0.0049,,,,,,11.9862967,,,,
,29193292.605,10.0039139,99.6091461181641,6.48768850544994E-5,3.14772802005858E-7,1,0.999253354069792,40.0298881530762,2.00763799796934,17.8699996322393,0.000731851660481211,0.000134331797780426,0.25,3.75371814389142E-7,6.45025436913402E-5,6.86106588607789E-7,10.0039139,10.0039139,99.6091461181641,99.6091461181641,57.6427584077176,20.5765426364393,12.278775,0,0,0,40,4369,9.99335,99.6091461181641,,,,,,,,,,,,,0,,,,0.0049,,,,,,10.0039139,,,,