File: data/looselyPackedNP/sc-ios-11/ppms/rawdata/ES_S14_HYST_300K.DAT
[Header]
; VSM Data File (default extension .dat)
; Copyright (c) 2003-2013, Quantum Design, Inc. All rights reserved.
TITLE,
FILEOPENTIME,29148942.17,12/04/2018,4:56 pm
BYAPP,VSM,2.0,2.0
INFO,PPMS VSM Option Release 1.4.10 Build 1,APPNAME
INFO,Quantum Design Linear Motor Servo Controller,MOTOR_MODULE_NAME
INFO,3101-100 M1,MOTOR_HW_VERSION
INFO,MMC1014,MOTOR_SERIAL_NUMBER
INFO,SRV No X-over 01.03.11,MOTOR_SOFTWARE_VERSION
INFO,Quantum Design VSM Detection Module,VSM_MODULE_NAME
INFO,3101-150 F0,VSM_HW_VERSION
INFO,VSM707,VSM_SERIAL_NUMBER
INFO,VSM No X-over 01.02.05 May 20 2008 13:51:47,VSM_SOFTWARE_VERSION
INFO,704,PREAMP_SERIAL_NUMBER
INFO,822,COIL_SERIAL_NUMBER
INFO,0,MOMENT_UNITS
INFO,Iron Oxide Spheres,SAMPLE_MATERIAL
INFO,10 nm diameter, collaboration Mainz,SAMPLE_COMMENT
INFO,,SAMPLE_MASS
INFO,,SAMPLE_VOLUME
INFO,,SAMPLE_MOLECULAR_WEIGHT
INFO,,SAMPLE_SIZE
INFO,,SAMPLE_SHAPE
DATATYPE,COMMENT,1
DATATYPE,TIME,2
STARTUPAXIS,X,2
STARTUPAXIS,Y1,5
[Data]
Comment,Time Stamp (sec),Temperature (K),Magnetic Field (Oe),Moment (emu),M. Std. Err. (emu),Transport Action,Averaging Time (sec),Frequency (Hz),Peak Amplitude (mm),Center Position (mm),Coil Signal' (mV),Coil Signal" (mV),Range (mV),M. Quad. Signal (emu),M. Raw' (emu),M. Raw" (emu),Min. Temperature (K),Max. Temperature (K),Min. Field (Oe),Max. Field (Oe),Mass (grams),Motor Lag (deg),Pressure (Torr),VSM Status (code),Motor Status (code),Measure Status (code),Measure Count,PPMS Status (code),System Temp. (K),System Field (Oe),Sample Position (deg),Bridge 1 Resistance (ohms),Bridge 1 Excitation (에),Bridge 2 Resistance (ohms),Bridge 2 Excitation (에),Bridge 3 Resistance (ohms),Bridge 3 Excitation (에),Bridge 4 Resistance (ohms),Bridge 4 Excitation (에),Signal 1 Vin (V),Signal 2 Vin (V),Digital Inputs (code),Drive 1 Iout (mA),Drive 1 Ipower (W),Drive 2 Iout (mA),Drive 2 Ipower (W),Pressure (),Map 20 (),Map 21 (),Map 22 (),Map 23 (),Map 24 (),Map 25 (),Map 26 (),Map 27 (),Map 28 (),Map 29 ()
,29148958.2,300.212616,0.1674614995718,,,2,,,,16.7200004002452,,,,,,,300.212616,300.212616,0.1674614995718,0.1674614995718,,,27.464817,,,,-99999999,4369,300.6375,0.1674614995718,,,,,,,,,,,,,,,,,,,,,,,300.212616,,,,
,29149102.585,300.1844482,4449.00610351562,0.000122598954354578,4.18011619005348E-7,1,0.999253354069792,40.0298881530762,1.99588902188144,16.7100001126528,0.00138504536533943,0.000243185330660529,0.25,2.76045068232588E-7,0.000122594309205504,3.57273029073075E-7,300.1844482,300.1844482,4446.55126953125,4451.4609375,56.391371148429,20.5356189966986,27.464817,0,0,0,40,4449,300.3973,4449.00610351562,,,,,,,,,,,,,0,,,,-0.00245,,,,,,300.1844482,,,,
,29149197.84,300.1344604,9209.89111328125,0.000107216516024044,6.58355767910046E-7,1,0.999253354069792,40.0298881530762,1.99571010827919,16.7100001126528,0.00121073657855784,0.000215115661481117,0.25,4.59165069621948E-7,0.000107212504546863,5.30166536874837E-7,300.1344604,300.1344604,9197.599609375,9222.1826171875,56.5320642818906,20.543476667006,27.085165,0,0,0,40,4449,300.3039,9209.89111328125,,,,,,,,,,,,,0,,,,0,,,,,,300.1344604,,,,
,29149293.79,300.0830994,14004.9975585938,8.71061192591374E-5,6.63891559336404E-7,1,0.999253354069792,40.0298881530762,1.99553469745857,16.7100001126528,0.000983751060293092,0.000173651857136164,0.25,2.75673865478616E-7,8.71030887506829E-5,3.33325749676937E-7,300.0830994,300.0830994,13995.3203125,14014.6748046875,56.7735874943329,20.5468426135942,27.085165,0,0,0,40,4449,300.2455,14004.9975585938,,,,,,,,,,,,,0,,,,-0.0049,,,,,,300.0830994,,,,
,29149389.03,300.0520325,18765.0361328125,6.58244179206067E-5,8.84632280739116E-7,1,0.999253354069792,40.0298881530762,1.99559402108004,16.7100001126528,0.000744472328664356,0.000125176865805399,0.25,-3.27238910945356E-7,6.58225589400667E-5,-2.83692271378503E-7,300.0520325,300.0520325,18757.673828125,18772.3984375,56.7251265261406,20.5486074820857,27.464817,0,0,0,40,4449,300.23045,18765.0361328125,,,,,,,,,,,,,0,,,,0,,,,,,300.0520325,,,,
,29149483.875,300.0232239,23504.76953125,4.29136563526582E-5,9.43061011990704E-7,1,0.999253354069792,40.0298881530762,1.99568408128477,16.7100001126528,0.000483911511102952,9.00509141615563E-5,0.25,5.33480813901931E-7,4.29119975035514E-5,5.61821946344665E-7,300.0232239,300.0232239,23494.953125,23514.5859375,56.8025077495445,20.5511270087908,27.085165,0,0,0,40,4449,300.21985,23504.76953125,,,,,,,,,,,,,0,,,,0,,,,,,300.0232239,,,,
,29149579.415,300.0027771,28280.19140625,2.06278959055688E-5,1.06116995450251E-6,1,0.999253354069792,40.0298881530762,1.99564930662517,16.7100001126528,0.000232309911382661,4.49867953075697E-5,0.25,4.07014876764293E-7,2.0627015709989E-5,4.20619695474824E-7,300.0027771,300.0027771,28273.171875,28287.2109375,56.8963031718522,20.5534458690444,27.464817,0,0,0,40,4449,300.22875,28280.19140625,,,,,,,,,,,,,0,,,,0.00245,,,,,,300.0027771,,,,
,29149676.335,299.9933777,33125.3671875,-4.96995969356429E-6,1.30022457927393E-6,1,0.999253354069792,40.0298881530762,1.99557041488307,16.7100001126528,-5.84930116123411E-5,3.72824506687991E-6,0.25,1.19100396353842E-6,-4.97059972277307E-6,1.18769182497975E-6,299.9933777,299.9933777,33120.05859375,33130.67578125,57.0409044479099,20.5523669671236,27.844467,0,0,0,40,4449,300.23155,33125.3671875,,,,,,,,,,,,,0,,,,0,,,,,,299.9933777,,,,
,29149771.69,299.9920654,37890.0703125,-2.86396848443905E-5,1.55548578057413E-6,1,0.999253354069792,40.0298881530762,1.99555226251272,16.7100001126528,-0.000326972092135691,-3.67790265249417E-5,0.25,1.70720527554359E-6,-2.86399750174599E-5,1.68829058363681E-6,299.9920654,299.9920654,37882.41796875,37897.72265625,56.8697278021983,20.5525075433749,27.085165,0,0,0,40,4449,300.242,37890.0703125,,,,,,,,,,,,,0,,,,0,,,,,,299.9920654,,,,
,29149870.27,299.9864807,42817.431640625,-5.28547117191982E-5,1.80309846967951E-6,1,0.999253354069792,40.0298881530762,1.9956676026458,16.7100001126528,-0.000596032410241002,-0.000110764544338935,0.25,-6.44279070360423E-7,-5.28527623481377E-5,-6.79034217733761E-7,299.9864807,299.9864807,42814.828125,42820.03515625,56.9252234270637,20.551424995469,27.464817,0,0,0,40,4449,300.2617,42817.431640625,,,,,,,,,,,,,0,,,,0,,,,,,299.9864807,,,,
,29149965.86,299.98999025,47597.958984375,-7.88324780236256E-5,1.99558331040485E-6,1,0.999253354069792,40.0298881530762,1.99565460242612,16.7100001126528,-0.000894384359155514,-0.00013397046975354,0.25,1.80285021335183E-6,-7.8831382780181E-5,1.75099103530621E-6,299.9895325,299.990448,47587.9609375,47607.95703125,57.0721695886791,20.5529447542134,27.464817,0,0,0,40,4449,300.2628,47597.958984375,,,,,,,,,,,,,0,,,,-0.0049,,,,,,299.98999025,,,,
,29150060.42,299.9925842,52322.724609375,-0.000101379144939736,2.26255450438163E-6,1,0.999253354069792,40.0298881530762,1.99557291684291,16.7100001126528,-0.00114901348474875,-0.000178781588713475,0.25,1.7430743810416E-6,-0.000101377354216452,1.67647406443516E-6,299.9925842,299.9925842,52320.41796875,52325.03125,56.9494539111599,20.5537382026646,27.464817,0,0,0,40,4449,300.2624,52322.724609375,,,,,,,,,,,,,0,,,,-0.0049,,,,,,299.9925842,,,,
,29150158.165,299.9981995,57207.794921875,-0.000125975869596504,2.41329805417297E-6,1,0.999253354069792,40.0298881530762,1.99557792909179,16.7100001126528,-0.00142286800150506,-0.000250577400601013,0.25,-3.49041053297543E-7,-0.000125971977066156,-4.31628722284977E-7,299.9981995,299.9981995,57202.6796875,57212.91015625,56.8970848003714,20.5520064478924,27.844467,0,0,0,40,4449,300.2661,57207.794921875,,,,,,,,,,,,,0,,,,0,,,,,,299.9981995,,,,
,29150253.53,299.9951477,61973.140625,-0.000152452232453467,3.16310148913761E-6,1,0.999253354069792,40.0298881530762,1.99656871162753,16.7100001126528,-0.00172298572103566,-0.000301901052767314,0.25,-2.91255637047881E-7,-0.000152447635262637,-3.91086610121068E-7,299.9943848,299.9959106,61970.74609375,61975.53515625,56.6805737005445,20.5442804566783,27.464817,0,0,0,40,4449,300.27015,61973.140625,,,,,,,,,,,,,0,,,,0.00245,,,,,,299.9951477,,,,
,29150350.75,299.9999695,66836.4375,-0.000174868915660026,2.17722456289779E-6,1,0.999253354069792,40.0298881530762,1.99573235776722,16.7100001126528,-0.00198005132158886,-0.000320140151108975,0.25,1.9677096648372E-6,-0.000174865130183925,1.85326869582703E-6,299.9999695,299.9999695,66829.046875,66843.828125,56.770460980256,20.5507389838466,27.844467,0,0,0,40,4449,300.2652,66836.4375,,,,,,,,,,,,,0,,,,0,,,,,,299.9999695,,,,
,29150445.365,300.0076294,71561.515625,-0.000198364778300511,2.56824186484766E-6,1,0.999253354069792,40.0298881530762,1.99566288586636,16.7100001126528,-0.00224706095182323,-0.000357141921300008,0.25,2.76297332396211E-6,-0.000198360788335778,2.6332929474823E-6,300.0076294,300.0076294,71556.625,71566.40625,57.1432977839291,20.5517462459071,27.464817,0,0,0,40,4449,300.2633,71561.515625,,,,,,,,,,,,,0,,,,0,,,,,,300.0076294,,,,
,29150540.315,300.0106812,76309.93359375,-0.000223290875928791,3.1038337049319E-6,1,0.999253354069792,40.0298881530762,1.99573591887683,16.7100001126528,-0.00252769347507453,-0.000412519228941789,0.25,2.1821468429063E-6,-0.000223285767516296,2.03637183849134E-6,300.0106812,300.0106812,76305.125,76314.7421875,56.9416376259676,20.5498124966436,27.844467,0,0,0,40,4449,300.25885,76309.93359375,,,,,,,,,,,,,0,,,,-0.0049,,,,,,300.0106812,,,,
,29150636.42,300.0082092,81113.05078125,-0.000249426775142249,3.50439817693574E-6,1,0.999253354069792,40.0298881530762,1.9956557430491,16.7100001126528,-0.00282011599916276,-0.000480023488609139,0.25,7.35069931483011E-7,-0.000249419996665635,5.72477059846105E-7,300.0082092,300.0082092,81108.0390625,81118.0625,56.9244417985445,20.5494052603212,27.844467,0,0,0,40,4449,300.2491,81113.05078125,,,,,,,,,,,,,0,,,,-0.0049,,,,,,300.0082092,,,,
,29150731.94,300.0091553,85886.19140625,-0.000272460696276241,3.18905988331942E-6,1,0.999253354069792,40.0298881530762,1.99570231714279,16.7100001126528,-0.00307967391622705,-0.000529797197615281,0.25,3.21970162194477E-7,-0.000272452987880973,1.44591696581197E-7,300.0091553,300.0091553,85881.078125,85891.3046875,56.9455457685637,20.5491598674958,27.464817,0,0,0,40,4449,300.24185,85886.19140625,,,,,,,,,,,,,0,,,,-0.00245,,,,,,300.0091553,,,,
,29150839.25,300.0160522,89647.1796875,-0.000293854120235402,4.0286164934841E-6,1,0.999253354069792,40.0298881530762,1.99543702807283,16.7100001126528,-0.00333230964535676,-0.000506422414279537,0.25,6.09084336898755E-6,-0.000293849485475266,5.89955656074606E-6,300.0160522,300.0160522,89644.4140625,89649.9453125,56.9557069393137,20.548761937087,27.464817,0,0,0,40,4449,300.2399,89647.1796875,,,,,,,,,,,,,0,,,,-0.00245,,,,,,300.0160522,,,,
,29150931.845,300.012085,85021.55859375,-0.000269945106736801,3.14389413670731E-6,1,0.999253354069792,40.0298881530762,1.99556691842143,16.7100001126528,-0.00305470970048728,-0.000503699989439798,0.25,2.19262245480909E-6,-0.000269938656476085,2.01677301011135E-6,300.012085,300.012085,85014.15625,85028.9609375,56.7884384361983,20.5486378262545,27.844467,0,0,0,40,4449,300.2208,85021.55859375,,,,,,,,,,,,,0,,,,-0.0049,,,,,,300.012085,,,,
,29151028.335,300.0010681,80194.8046875,-0.000242238929452208,4.06699749809086E-6,1,0.999253354069792,40.0298881530762,1.99569013067059,16.7100001126528,-0.00274268652986237,-0.000444302412056892,0.25,2.65148409327288E-6,-0.000242233667142641,2.49346684104547E-6,300.0010681,300.0010681,80189.8203125,80199.7890625,57.1276652135445,20.5489383103557,27.464817,0,0,0,40,4449,300.2219,80194.8046875,,,,,,,,,,,,,0,,,,-0.00245,,,,,,300.0010681,,,,
,29151126.395,299.9934387,75294.12890625,-0.000218544543704975,2.9873051902904E-6,1,0.999253354069792,40.0298881530762,1.99566293055188,16.7100001126528,-0.00247504524216972,-0.000397006623941796,0.25,2.7313667553938E-6,-0.000218540063936818,2.58862232276477E-6,299.9934387,299.9934387,75291.6875,75296.5703125,57.0455942190253,20.5489221904812,27.844467,0,0,0,40,4449,300.23145,75294.12890625,,,,,,,,,,,,,0,,,,-0.0049,,,,,,299.9934387,,,,
,29151222.875,299.9933472,70473.0234375,-0.000192341146897512,1.68329506492763E-6,1,0.999253354069792,40.0298881530762,1.9956159216095,16.7100001126528,-0.00217770104014088,-0.000352504568852888,0.25,2.12910549208927E-6,-0.000192337013731607,2.00333212092557E-6,299.9933472,299.9933472,70468.0703125,70477.9765625,57.0362146767945,20.5497388148694,27.844467,0,0,0,40,4449,300.2358,70473.0234375,,,,,,,,,,,,,0,,,,0.0049,,,,,,299.9933472,,,,
,29151318.405,299.9885559,65695.35546875,-0.000167114918205258,3.26083559071817E-6,1,0.999253354069792,40.0298881530762,1.99564865781327,16.7100001126528,-0.00188920561046735,-0.000323085185247568,0.25,3.62630183578443E-7,-0.000167110373147602,2.53271826548188E-7,299.9885559,299.9885559,65690.28125,65700.4296875,57.1987934087945,20.5487943551183,27.464817,0,0,0,40,4449,300.25365,65695.35546875,,,,,,,,,,,,,0,,,,0,,,,,,299.9885559,,,,
,29151415.475,299.9874573,60847.21484375,-0.00014342549132897,2.51688269002029E-6,1,0.999253354069792,40.0298881530762,1.99556782875774,16.7100001126528,-0.00162574043554331,-0.000251864505414276,0.25,2.56006166184596E-6,-0.000143423059786338,2.46602978373785E-6,299.9874573,299.9874573,60842.12109375,60852.30859375,57.0964000727753,20.5515449427704,27.464817,0,0,0,40,4449,300.2575,60847.21484375,,,,,,,,,,,,,0,,,,0,,,,,,299.9874573,,,,
,29151510.375,299.9918518,56101.7421875,-0.000119287681109761,2.55772622459949E-6,1,0.999253354069792,40.0298881530762,1.99557002062376,16.7100001126528,-0.00135315845958409,-0.000203583558482081,0.25,2.65085073867644E-6,-0.000119285975778336,2.57254017786303E-6,299.9918518,299.9918518,56099.4921875,56103.9921875,56.8337728903137,20.5510790570068,27.844467,0,0,0,40,4449,300.2647,56101.7421875,,,,,,,,,,,,,0,,,,0.00245,,,,,,299.9918518,,,,
,29151604.67,299.98936465,51389.255859375,-9.45232930569976E-5,2.46545417186551E-6,1,0.999253354069792,40.0298881530762,1.99555725083175,16.7100001126528,-0.00107186502523041,-0.000163443527538254,0.25,1.91251335866898E-6,-9.45218222334784E-5,1.85039811146863E-6,299.9886475,299.9900818,51356.421875,51422.08984375,56.8869236296214,20.5523533225796,27.464817,0,0,0,40,4449,300.2752,51389.255859375,,,,,,,,,,,,,0,,,,-0.00245,,,,,,299.98936465,,,,
,29151704.215,299.9919128,46414.40625,-7.02117863509387E-5,1.60821285064383E-6,1,0.999253354069792,40.0298881530762,1.9957219327572,16.7100001126528,-0.000795744827224071,-0.000124288449046927,0.25,1.16641741792735E-6,-7.02105166476497E-5,1.12023235433693E-6,299.9919128,299.9919128,46409.421875,46419.390625,57.047939104583,20.5516077781606,28.224119,0,0,0,40,4449,300.2808,46414.40625,,,,,,,,,,,,,0,,,,-0.0049,,,,,,299.9919128,,,,
,29151801.005,299.9872131,41573.71875,-4.53428427990574E-5,1.78678554127384E-6,1,0.999253354069792,40.0298881530762,1.99562398661118,16.7100001126528,-0.000510206060309438,-0.000101402677733539,0.25,-1.11749025574186E-6,-4.53407970318001E-5,-1.14729551227218E-6,299.9872131,299.9872131,41566.21484375,41581.22265625,57.0604451608906,20.5517409545305,27.844467,0,0,0,40,4449,300.28355,41573.71875,,,,,,,,,,,,,0,,,,0,,,,,,299.9872131,,,,
,29151895.22,299.9945679,36866.376953125,-2.05642135395489E-5,1.76232253754756E-6,1,0.999253354069792,40.0298881530762,1.99555642356499,16.7100001126528,-0.000232301251236985,-4.0697662007815E-5,0.25,-3.86855804894859E-8,-2.05635871178318E-5,-5.22300013679836E-8,299.9945679,299.9945679,36863.73828125,36869.015625,57.159711982833,20.5555753197378,27.844467,0,0,0,40,4449,300.3023,36866.376953125,,,,,,,,,,,,,0,,,,0,,,,,,299.9945679,,,,
,29151991.505,299.9886169,32053.9697265625,2.3525560669761E-6,1.43885655816958E-6,1,0.999253354069792,40.0298881530762,1.99554850163595,16.7100001126528,2.28548092492523E-5,2.61296647519889E-5,0.25,1.90476053912794E-6,2.35123169141516E-6,1.90625642219989E-6,299.9886169,299.9886169,32046.529296875,32061.41015625,57.2011382943522,20.5528532529715,27.464817,0,0,0,40,4449,300.30335,32053.9697265625,,,,,,,,,,,,,0,,,,0,,,,,,299.9886169,,,,
,29152089.625,299.9929504,27149.326171875,2.68185080150264E-5,1.25579411218921E-6,1,0.999253354069792,40.0298881530762,1.99552961043473,16.7100001126528,0.000304284842221085,4.5360072263712E-5,0.25,-6.32288259995458E-7,2.68181399178705E-5,-6.14567640431604E-7,299.9929504,299.9929504,27139.462890625,27159.189453125,56.9963516223137,20.5526837681027,27.844467,0,0,0,40,4449,300.3089,27149.326171875,,,,,,,,,,,,,0,,,,-0.00245,,,,,,299.9929504,,,,
,29152190.5,299.9965668,22108.9091796875,5.02537567012542E-5,1.05024458418594E-6,1,0.999253354069792,40.0298881530762,1.99560937588189,16.7100001126528,0.000568199092729529,9.65764522893623E-5,0.25,-1.60502446934233E-7,5.02523813185621E-5,-1.27292257709735E-7,299.9957886,299.997345,22101.447265625,22116.37109375,57.0401228193907,20.5528741808115,27.844467,0,0,0,40,4449,300.3097,22108.9091796875,,,,,,,,,,,,,0,,,,-0.00245,,,,,,299.9965668,,,,
,29152290.175,299.9927673,17129.4501953125,7.37968450203663E-5,8.26401005166357E-7,1,0.999253354069792,40.0298881530762,1.99554122249878,16.7100001126528,0.000833256525864519,0.000148209765645854,0.25,3.30047638729783E-7,7.37944573326063E-5,3.78844325224148E-7,299.9927673,299.9927673,17124.392578125,17134.5078125,57.2980602307368,20.5553862331091,28.224119,0,0,0,40,4449,300.32685,17129.4501953125,,,,,,,,,,,,,0,,,,0,,,,,,299.9927673,,,,
,29152384.94,299.9909973,12391.8618164062,9.41610843196795E-5,6.43624149326713E-7,1,0.999253354069792,40.0298881530762,1.99555761047077,16.7100001126528,0.00106350010711546,0.000187389183869022,0.25,2.68809473706578E-7,9.41581394094979E-5,3.31130663039438E-7,299.9909973,299.9909973,12381.8759765625,12401.84765625,57.0401228193907,20.5542136928852,28.224119,0,0,0,40,4449,300.32905,12391.8618164062,,,,,,,,,,,,,0,,,,-0.00245,,,,,,299.9909973,,,,
,29152480.4,299.986908,7619.18408203125,0.000113890375601726,5.45275921089235E-7,1,0.999253354069792,40.0298881530762,1.99558845144066,16.7100001126528,0.00128751999459072,0.000219909796818312,0.25,-2.7189424297169E-7,0.000113887220240027,-1.96436590271022E-7,299.986908,299.986908,7614.21728515625,7624.15087890625,57.034651419756,20.555181146523,27.844467,0,0,0,40,4449,300.33315,7619.18408203125,,,,,,,,,,,,,0,,,,0.0049,,,,,,299.986908,,,,
,29152575.29,299.9934998,2876.35852050781,0.000123091831814272,3.96737581111733E-7,1,0.999253354069792,40.0298881530762,1.99554214359757,16.7100001126528,0.00139048449991608,0.000243592555210646,0.25,2.30072683906439E-7,0.000123088040018914,3.11668566924923E-7,299.9934998,299.9934998,2871.6396484375,2881.07739257813,57.1862873524868,20.5571528771887,27.844467,0,0,0,40,4449,300.3371,2876.35852050781,,,,,,,,,,,,,0,,,,0,,,,,,299.9934998,,,,
,29152666.51,299.9943237,-1678.98040771484,-0.000115688218843944,3.82605235700279E-7,1,0.999253354069792,40.0298881530762,1.99555680027031,16.7100001126528,-0.00130737241086249,-0.000225985555027105,0.25,4.54753084740555E-8,-0.000115684824257959,-3.12309306410844E-8,299.9943237,299.9943237,-1683.96069335938,-1674.00012207031,57.3043132588907,20.55648146923,28.224119,0,0,0,40,4449,300.34185,-1678.98040771484,,,,,,,,,,,,,0,,,,0,,,,,,299.9943237,,,,
,29152761.565,300.0025024,-6431.41625976563,-0.000117225853188436,4.66955597198976E-7,1,0.999253354069792,40.0298881530762,1.995531476721,16.7100001126528,-0.0013247711641433,-0.000228763553252313,0.25,6.57449523675248E-8,-0.000117222396610028,-1.1930794005536E-8,300.0025024,300.0025024,-6436.47119140625,-6426.361328125,57.1018714724099,20.5566188811275,27.464817,0,0,0,40,4449,300.3345,-6431.41625976563,,,,,,,,,,,,,0,,,,0.0049,,,,,,300.0025024,,,,
,29152854.865,300.0079956,-11094.89453125,-9.94613538841927E-5,5.67430762393728E-7,1,0.999253354069792,40.0298881530762,1.99537455714336,16.7100001126528,-0.00112264085656799,-0.000201521059272985,0.25,-6.02652180374613E-7,-9.94579701140559E-5,-6.68486107727952E-7,300.0075073,300.0084839,-11104.87109375,-11084.91796875,57.1511140691214,20.5592262467235,27.844467,0,0,0,40,4449,300.33195,-11094.89453125,,,,,,,,,,,,,0,,,,0,,,,,,300.0079956,,,,
,29152948.11,300.00654605,-15755.1630859375,-8.00071957579363E-5,6.88213272251467E-7,1,0.999253354069792,40.0298881530762,1.99549277421138,16.7100001126528,-0.000902964923057054,-0.00016294479850147,0.25,-5.58371647058175E-7,-8.00044336446563E-5,-6.11281551232548E-7,300.0057068,300.0073853,-15757.59375,-15752.732421875,57.0502839901407,20.5582858279948,27.844467,0,0,0,40,4449,300.3313,-15755.1630859375,,,,,,,,,,,,,0,,,,-0.0049,,,,,,300.00654605,,,,
,29153043.285,300.0084839,-20512.314453125,-5.92826823242746E-5,8.77258015810127E-7,1,0.999253354069792,40.0298881530762,1.99547150348433,16.7100001126528,-0.000669838529569176,-0.000116243632894505,0.25,-1.62465436445936E-8,-5.92808975278884E-5,-5.54294366803602E-8,300.0084839,300.0084839,-20514.775390625,-20509.853515625,57.3261988574291,20.5612383746834,27.844467,0,0,0,40,4449,300.3132,-20512.314453125,,,,,,,,,,,,,0,,,,-0.00245,,,,,,300.0084839,,,,
,29153139.875,300.0120544,-25337.0673828125,-3.49466127578811E-5,1.03393458345578E-6,1,0.999253354069792,40.0298881530762,1.99542757649141,16.7100001126528,-0.000395440887184114,-6.51445137309206E-5,0.25,2.89410965445794E-7,-3.49457555933574E-5,2.66326377286166E-7,300.0120544,300.0120544,-25342.197265625,-25331.9375,57.0463758475445,20.5593571657587,27.464817,0,0,0,40,4449,300.3094,-25337.0673828125,,,,,,,,,,,,,0,,,,0,,,,,,300.0120544,,,,
,29153237.705,300.0139771,-30226.609375,-1.18947389472661E-5,1.21307324847815E-6,1,0.999253354069792,40.0298881530762,1.99539102115908,16.7100001126528,-0.000134433065143812,-2.30982569727336E-5,0.25,1.65917639656197E-8,-1.18943929623384E-5,8.74463252303155E-9,300.0139771,300.0139771,-30234.1484375,-30219.0703125,57.2112994651022,20.5618511471655,27.844467,0,0,0,40,4449,300.2954,-30226.609375,,,,,,,,,,,,,0,,,,-0.00245,,,,,,300.0139771,,,,
,29153334.81,300.014679,-35081.431640625,1.19644591599421E-5,1.55900760299344E-6,1,0.999253354069792,40.0298881530762,1.99546307667001,16.7100001126528,0.000137768577597878,8.55741205195383E-6,0.25,-1.3155848517247E-6,1.19649675244388E-5,-1.30766099085599E-6,300.014679,300.014679,-35091.41015625,-35071.453125,57.0768593597945,20.5613730033784,27.464817,0,0,0,40,4449,300.29015,-35081.431640625,,,,,,,,,,,,,0,,,,0.00245,,,,,,300.014679,,,,
,29153430.885,300.010437,-39883.630859375,3.53736090875946E-5,1.67097160975483E-6,1,0.999253354069792,40.0298881530762,1.9955096941253,16.7100001126528,0.000400312370892699,6.58047658405042E-5,0.25,-3.05117181731481E-7,3.5372757299579E-5,-2.81821368371898E-7,300.010437,300.010437,-39893.46484375,-39873.796875,57.268358347006,20.5597468191163,28.224119,0,0,0,40,4449,300.27885,-39883.630859375,,,,,,,,,,,,,0,,,,0.0049,,,,,,300.010437,,,,
,29153527.205,300.0193787,-44696.73828125,5.89160084742827E-5,1.51475381676985E-6,1,0.999253354069792,40.0298881530762,1.99535549113901,16.7100001126528,0.000663939291760952,0.000125441022293214,0.25,8.94546818968482E-7,5.89136517398024E-5,9.3326371142925E-7,300.0193787,300.0193787,-44696.73828125,-44696.73828125,57.1307917276214,20.5635170990763,28.224119,0,0,0,40,4449,300.2679,-44696.73828125,,,,,,,,,,,,,0,,,,0,,,,,,300.0193787,,,,
,29153625.365,300.0127563,-49601.431640625,8.4487066042425E-5,2.02475164019753E-6,1,0.999253354069792,40.0298881530762,1.99526270675188,16.7100001126528,0.000951884460401266,0.00018091397840585,0.25,1.37458044768369E-6,8.44836525101688E-5,1.43003907540863E-6,300.0127563,300.0127563,-49609.18359375,-49593.6796875,57.2417829773522,20.5647378435046,27.464817,0,0,0,40,4449,300.2508,-49601.431640625,,,,,,,,,,,,,0,,,,-0.00245,,,,,,300.0127563,,,,
,29153720.295,300.0115051,-54345.67578125,0.000108968789374379,2.61781841756318E-6,1,0.999253354069792,40.0298881530762,1.99522185026084,16.7100001126528,0.00122884620827461,0.000226642504100218,0.25,1.18082781300776E-6,0.000108964788498188,1.25229470361549E-6,300.0115051,300.0115051,-54345.67578125,-54345.67578125,56.9572701963522,20.5653041594666,27.844467,0,0,0,40,4449,300.24615,-54345.67578125,,,,,,,,,,,,,0,,,,0,,,,,,300.0115051,,,,
,29153816.25,300.0085754,-59143.068359375,0.000133341890956266,1.843281924838E-6,1,0.999253354069792,40.0298881530762,1.99526432583658,16.7100001126528,0.00150652686150233,0.000261219202926293,0.25,1.81079963671435E-8,0.000133337954384138,1.05502391162771E-7,300.0085754,300.0085754,-59148.06640625,-59138.0703125,57.1010898438907,20.5648520232053,28.224119,0,0,0,40,4449,300.2405,-59143.068359375,,,,,,,,,,,,,0,,,,0,,,,,,300.0085754,,,,
,29153914.68,300.0123901,-64063.03125,0.000156898252208928,2.82564571027906E-6,1,0.999253354069792,40.0298881530762,1.99501019108199,16.7100001126528,0.00177091879468656,0.0003162037051385,0.25,8.06983867813324E-7,0.000156893094873088,9.09676112050371E-7,300.0123901,300.0123901,-64075.5625,-64050.5,57.0745144742368,20.5673178896247,27.844467,0,0,0,40,4449,300.2247,-64063.03125,,,,,,,,,,,,,0,,,,0,,,,,,300.0123901,,,,
,29154012.445,300.0089111,-68945.22265625,0.000181479758205331,3.3182404434585E-6,1,0.999253354069792,40.0298881530762,1.99524046089523,16.7100001126528,0.00205377168849944,0.000335919508428977,0.25,-1.70972501382971E-6,0.000181475556782223,-1.59100284812239E-6,300.0089111,300.0089111,-68952.7421875,-68937.703125,57.1214121853907,20.5661731048007,28.224119,0,0,0,40,4449,300.20725,-68945.22265625,,,,,,,,,,,,,0,,,,0.00245,,,,,,300.0089111,,,,
,29154113.415,300.0158691,-73991.78515625,0.00020676928419504,2.33113314894719E-6,1,0.999253354069792,40.0298881530762,1.99514203525993,16.7100001126528,0.00233752558626388,0.000396173992084284,0.25,-7.56286369247784E-7,0.000206763680975222,-6.21226666960768E-7,300.0158691,300.0158691,-73999.140625,-73984.4296875,57.4450063923522,20.5664164164183,27.844467,0,0,0,40,4449,300.2058,-73991.78515625,,,,,,,,,,,,,0,,,,0.00245,,,,,,300.0158691,,,,
,29154210.765,300.0144348,-78858.61328125,0.000236715869946779,2.74078880399459E-6,1,0.999253354069792,40.0298881530762,1.99514449089856,16.7100001126528,0.00267513155274132,0.000458998604228731,0.25,-3.83615822010881E-7,0.00023670916858167,-2.29194458300094E-7,300.0144348,300.0144348,-78866.140625,-78851.0859375,57.2378748347561,20.5664192084088,27.844467,0,0,0,40,4449,300.19295,-78858.61328125,,,,,,,,,,,,,0,,,,-0.00245,,,,,,300.0144348,,,,
,29154307.71,300.0139771,-83703.24609375,0.000257465898089178,2.88826160228597E-6,1,0.999253354069792,40.0298881530762,1.99514879027961,16.7100001126528,0.0029117549463345,0.000486994197646966,0.25,-1.50046205229368E-6,0.000257459336772476,-1.33267406289087E-6,300.0139771,300.0139771,-83713.0546875,-83693.4375,57.2284952925253,20.5667385268042,27.844467,0,0,0,40,4449,300.17865,-83703.24609375,,,,,,,,,,,,,0,,,,-0.0049,,,,,,300.0139771,,,,
,29154399.4,300.01441955,-88285.41015625,0.000282910316867219,2.32019765608834E-6,1,0.999253354069792,40.0298881530762,1.99518179686526,16.7100001126528,0.00319853930926862,0.000541043856930059,0.25,-1.12514156520208E-6,0.000282902779496072,-9.4100028471467E-7,300.0143127,300.0145264,-88290.40625,-88280.4140625,57.065134932006,20.567072109558,28.224119,0,0,0,40,4449,300.1679,-88285.41015625,,,,,,,,,,,,,0,,,,-0.00245,,,,,,300.01441955,,,,
,29154507.055,300.012207,-87236.43359375,0.000274511522601513,3.37660662323567E-6,1,0.999253354069792,40.0298881530762,1.99510143606614,16.7100001126528,0.0031071315564323,0.000503796465163827,0.25,-2.96521425351628E-6,0.000274505445815369,-2.78643103422231E-6,300.012207,300.012207,-87238.921875,-87233.9453125,57.4536043060638,20.5677917886595,27.844467,0,0,0,40,4449,300.161,-87236.43359375,,,,,,,,,,,,,0,,,,0,,,,,,300.012207,,,,
,29154603.635,300.0028992,-82409.3359375,0.000253127014169522,2.92710978075682E-6,1,0.999253354069792,40.0298881530762,1.99514513089289,16.7100001126528,0.00285541101265868,0.000520751432948365,0.25,2.23916311589416E-6,0.000253118237603607,2.40408328199932E-6,300.0028992,300.0028992,-82421.9375,-82396.734375,57.1933220091599,20.5661271099319,27.844467,0,0,0,40,4449,300.1596,-82409.3359375,,,,,,,,,,,,,0,,,,0,,,,,,300.0028992,,,,
,29154701.14,299.99604795,-77536.90234375,0.00022637460114644,3.18484764929636E-6,1,0.999253354069792,40.0298881530762,1.99502009541997,16.7100001126528,0.00256286262639736,0.00041151146900194,0.25,-2.79313483946342E-6,0.000226369919141585,-2.64531684027439E-6,299.9958496,299.9962463,-77539.2578125,-77534.546875,57.4520410490253,20.5670429504907,28.224119,0,0,0,40,4449,300.1528,-77536.90234375,,,,,,,,,,,,,0,,,,0,,,,,,299.99604795,,,,
,29154796.96,299.9953613,-72749.8203125,0.000200348778910549,1.97949735595772E-6,1,0.999253354069792,40.0298881530762,1.99509016540491,16.7100001126528,0.00226519152565627,0.000382106447204713,0.25,-8.88335042458822E-7,0.000200343593922952,-7.57406679053108E-7,299.9953613,299.9953613,-72757.0546875,-72742.5859375,56.8986480574099,20.5672020389593,27.844467,0,0,0,40,4449,300.1721,-72749.8203125,,,,,,,,,,,,,0,,,,0.0049,,,,,,299.9953613,,,,
,29154894.5,299.9888916,-67873.47265625,0.000177073042354056,2.20634706749896E-6,1,0.999253354069792,40.0298881530762,1.99516828209454,16.7100001126528,0.00200306296119204,0.00033220162639542,0.25,-1.27437378732137E-6,0.000177068809128516,-1.15850235477956E-6,299.9886169,299.9891663,-67875.796875,-67871.1484375,57.2027015513907,20.5667881059823,27.844467,0,0,0,40,4449,300.1777,-67873.47265625,,,,,,,,,,,,,0,,,,0.0049,,,,,,299.9888916,,,,
,29154990.21,299.99076845,-63090.794921875,0.000149946468527873,2.44483544681718E-6,1,0.999253354069792,40.0298881530762,1.99525803861707,16.7100001126528,0.00169608823252298,0.000282416633774337,0.25,-9.82403315055329E-7,0.000149942801002183,-8.84171134934345E-7,299.990387,299.9911499,-63098.546875,-63083.04296875,57.2597604332945,20.5657935938304,28.224119,0,0,0,40,4449,300.1847,-63090.794921875,,,,,,,,,,,,,0,,,,0.0049,,,,,,299.99076845,,,,
,29155088,299.986145,-58201.109375,0.000130226700970536,2.39025132724044E-6,1,0.999253354069792,40.0298881530762,1.9952650418017,16.7100001126528,0.00146956298934539,0.000265329671752808,0.25,9.21565828439986E-7,0.000130222365521485,1.00692753751797E-6,299.986145,299.986145,-58211.10546875,-58191.11328125,57.108906129083,20.5656377047665,28.224119,0,0,0,40,4449,300.1946,-58201.109375,,,,,,,,,,,,,0,,,,0.0049,,,,,,299.986145,,,,
,29155185.34,299.9891052,-53336.05078125,0.000102466428118417,2.61856692202459E-6,1,0.999253354069792,40.0298881530762,1.9951707185714,16.7100001126528,0.00115744244228502,0.000201852075716159,0.25,1.13592081152991E-7,0.000102463399928096,1.80852363396167E-7,299.9891052,299.9891052,-53338.53125,-53333.5703125,57.0127658212176,20.5659611015653,28.603769,0,0,0,40,4449,300.2004,-53336.05078125,,,,,,,,,,,,,0,,,,0.00245,,,,,,299.9891052,,,,
,29155282.69,299.9880676,-48471.525390625,7.78956649174693E-5,1.85861163639069E-6,1,0.999253354069792,40.0298881530762,1.99514046395794,16.7100001126528,0.000883622399096093,0.000131862162717363,0.25,-1.82424036418912E-6,7.78946162152638E-5,-1.77299648049591E-6,299.9880676,299.9880676,-48481.55859375,-48461.4921875,57.0198004778906,20.5661499722838,27.844467,0,0,0,40,4449,300.2109,-48471.525390625,,,,,,,,,,,,,0,,,,0,,,,,,299.9880676,,,,
,29155382.575,299.9928589,-43479.15234375,5.53074676603287E-5,1.98340993297403E-6,1,0.999253354069792,40.0298881530762,1.99518482100675,16.7100001126528,0.000626145330553502,0.000100883569177389,0.25,-6.52978485567376E-7,5.53062882778918E-5,-6.16571684668993E-7,299.9928589,299.9928589,-43483.95703125,-43474.34765625,57.4653287338522,20.5653740481028,27.844467,0,0,0,40,4449,300.2201,-43479.15234375,,,,,,,,,,,,,0,,,,0,,,,,,299.9928589,,,,
,29155478.2,299.9848022,-38701.85546875,2.97682736686238E-5,1.07550731264867E-6,1,0.999253354069792,40.0298881530762,1.99507015160693,16.7100001126528,0.00033666244135767,5.62056523158743E-5,0.25,-1.82426429862451E-7,2.9767534627623E-5,-1.62816039741497E-7,299.9848022,299.9848022,-38706.92578125,-38696.78515625,57.044812590506,20.5650756663616,28.224119,0,0,0,40,4449,300.2375,-38701.85546875,,,,,,,,,,,,,0,,,,-0.00245,,,,,,299.9848022,,,,
,29155575.9,299.9887695,-33820.1796875,7.59530116929902E-6,1.43596412981956E-6,1,0.999253354069792,40.0298881530762,1.99513696305256,16.7100001126528,8.60948221957668E-5,1.3224301512289E-5,0.25,-1.45409866731115E-7,7.59517625084846E-6,-1.40398005788394E-7,299.9887695,299.9887695,-33830.14453125,-33810.21484375,57.4723633905253,20.5651510926394,28.224119,0,0,0,40,4449,300.2378,-33820.1796875,,,,,,,,,,,,,0,,,,-0.00245,,,,,,299.9887695,,,,
,29155673.915,299.9911499,-28920.3486328125,-1.87516057126107E-5,1.37458434616775E-6,1,0.999253354069792,40.0298881530762,1.99508353272732,16.7100001126528,-0.00021211716141106,-3.51411303906122E-5,0.25,1.38317292237016E-7,-1.8751149138016E-5,1.25937140921981E-7,299.9911499,299.9911499,-28932.5,-28908.197265625,57.2245871499291,20.5663922783497,27.844467,0,0,0,40,4449,300.2394,-28920.3486328125,,,,,,,,,,,,,0,,,,0,,,,,,299.9911499,,,,
,29155770.265,299.9924011,-24105.62890625,-4.08756567576298E-5,1.233534650654E-6,1,0.999253354069792,40.0298881530762,1.99503462297673,16.7100001126528,-0.000458681801969155,-9.7901688509253E-5,0.25,-1.58398138308243E-6,-4.08734118909803E-5,-1.61093895305089E-6,299.9924011,299.9924011,-24110.501953125,-24100.755859375,57.2589788047753,20.5664494316159,28.603769,0,0,0,40,4449,300.2514,-24105.62890625,,,,,,,,,,,,,0,,,,0,,,,,,299.9924011,,,,
,29155865.465,299.9884338,-19348.091796875,-6.36960179599104E-5,1.00137562161048E-6,1,0.999253354069792,40.0298881530762,1.99501434359608,16.7100001126528,-0.000719018107093824,-0.00012792969937464,0.25,-2.88255238632041E-7,-6.36939654322245E-5,-3.30365806021235E-7,299.9884338,299.9884338,-19352.984375,-19343.19921875,57.1628384969099,20.5653552106986,27.844467,0,0,0,40,4449,300.25985,-19348.091796875,,,,,,,,,,,,,0,,,,-0.00245,,,,,,299.9884338,,,,
,29155962.165,299.990387,-14513.7153320313,-8.54890938941192E-5,8.43767917791019E-7,1,0.999253354069792,40.0298881530762,1.99496576835938,16.7100001126528,-0.000965275069703802,-0.000170118389757314,0.25,-2.47196441134832E-7,-8.5486420767364E-5,-3.03769616252813E-7,299.990387,299.990387,-14516.283203125,-14511.1474609375,57.0807675023906,20.5675625769359,28.224119,0,0,0,40,4449,300.2675,-14513.7153320313,,,,,,,,,,,,,0,,,,0.0049,,,,,,299.990387,,,,
,29156056.095,299.9886475,-9818.62060546875,-0.000104798377497875,6.35078332027478E-7,1,0.999253354069792,40.0298881530762,1.99498201967598,16.7100001126528,-0.00118472924922173,-0.000200349466145845,0.25,4.22435811057765E-7,-0.000104795582397194,3.53006313425722E-7,299.9886475,299.9886475,-9823.7099609375,-9813.53125,57.1722180391407,20.5659997064023,27.844467,0,0,0,40,4449,300.2734,-9818.62060546875,,,,,,,,,,,,,0,,,,-0.00245,,,,,,299.9886475,,,,
,29156150.76,299.9913635,-5090.05151367188,-0.000120458961919765,4.69703242507456E-7,1,0.999253354069792,40.0298881530762,1.99510122309861,16.7100001126528,-0.00135972928357529,-0.000242525714970644,0.25,-5.96363635262977E-7,-0.000120455014972851,-6.76197077736144E-7,299.9913635,299.9913635,-5095.00830078125,-5085.0947265625,56.8486238321791,20.563594582753,27.844467,0,0,0,40,4449,300.2762,-5090.05151367188,,,,,,,,,,,,,0,,,,0,,,,,,299.9913635,,,,
,29156240.825,299.9972229,-583.433990478516,-8.46085082094336E-5,3.89180609580584E-7,1,0.999253354069792,40.0298881530762,1.9949812329074,16.7100001126528,-0.000954522975233803,-0.000173076522481349,0.25,-6.61390593257954E-7,-8.4605554135565E-5,-7.174900372182E-7,299.9972229,299.9972229,-590.872802734375,-575.995178222656,57.1729996676599,20.5662513575487,28.603769,0,0,0,40,4449,300.27775,-583.433990478516,,,,,,,,,,,,,0,,,,-0.00245,,,,,,299.9972229,,,,
,29156333.29,299.9951172,4032.17016601562,0.000123127339738249,4.83501206835657E-7,1,0.999253354069792,40.0298881530762,1.99503101358605,16.7100001126528,0.00139102108243599,0.00024085813115653,0.25,-1.28557793442914E-8,0.000123123700308164,6.87761395030492E-8,299.9951172,299.9951172,4032.17016601562,4032.17016601562,57.220679007333,20.5633564306624,27.844467,0,0,0,40,4449,300.2796,4032.17016601562,,,,,,,,,,,,,0,,,,0,,,,,,299.9951172,,,,
,29156426.03,300.0059204,8668.708984375,0.000109816976878136,5.24275051359484E-7,1,0.999253354069792,40.0298881530762,1.99495862945111,16.7100001126528,0.00124022124492248,0.000217027881172764,0.25,1.84623624176598E-7,0.000109813562963161,2.57373740297197E-7,300.0059204,300.0059204,8666.2314453125,8671.1865234375,57.0596635323714,20.5649499454293,27.844467,0,0,0,40,4449,300.2731,8668.708984375,,,,,,,,,,,,,0,,,,0.0049,,,,,,300.0059204,,,,
,29156520.36,300.0023499,13384.591796875,9.163684363948E-5,5.85882573873665E-7,1,0.999253354069792,40.0298881530762,1.9950664654429,16.7100001126528,0.00103497897510178,0.000180981360142932,0.25,1.42862529934767E-7,9.16340186882344E-5,2.03518801404773E-7,300.0023499,300.0023499,13379.4853515625,13389.6982421875,56.8525319747752,20.5630878350855,28.603769,0,0,0,40,4449,300.2733,13384.591796875,,,,,,,,,,,,,0,,,,-0.00245,,,,,,300.0023499,,,,
,29156617.915,300.0087891,18259.37109375,6.88269460699344E-5,8.00449380693324E-7,1,0.999253354069792,40.0298881530762,1.995012724835,16.7100001126528,0.000777132670347165,0.000137100980071631,0.25,2.11116643275412E-7,6.88247435391767E-5,2.56629640374194E-7,300.0087891,300.0087891,18251.751953125,18266.990234375,56.9947883652753,20.5623559352887,28.603769,0,0,0,40,4449,300.272,18259.37109375,,,,,,,,,,,,,0,,,,0,,,,,,300.0087891,,,,
,29156716.565,300.0087891,23189.5966796875,4.63337480648238E-5,8.70597439833983E-7,1,0.999253354069792,40.0298881530762,1.99498280408005,16.7100001126528,0.000524084703527042,8.69107426138018E-5,0.25,-3.34368674994708E-7,4.63325828660534E-5,-3.03744430902048E-7,300.0087891,300.0087891,23184.705078125,23194.48828125,57.1518956976407,20.5623948989829,28.224119,0,0,0,40,4449,300.2624,23189.5966796875,,,,,,,,,,,,,0,,,,-0.00245,,,,,,300.0087891,,,,
,29156814.565,300.0083313,28087.1904296875,2.35649037202383E-5,1.21014354010564E-6,1,0.999253354069792,40.0298881530762,1.995049423319,16.7100001126528,0.000265199556257969,5.20152480223679E-5,0.25,5.21437956982617E-7,2.35638563475109E-5,5.36976934653729E-7,300.0083313,300.0083313,28077.041015625,28097.33984375,57.3269804859484,20.5614322093135,27.844467,0,0,0,40,4449,300.25755,28087.1904296875,,,,,,,,,,,,,0,,,,0,,,,,,300.0083313,,,,
,29156912.485,300.0064697,32984.6875,-8.1993760537191E-7,1.22282203236124E-6,1,0.999253354069792,40.0298881530762,1.99488176611841,16.7100001126528,-1.09980865236991E-5,8.41355874129297E-6,0.25,8.8685814967471E-7,-8.20498048760051E-7,8.8629111794003E-7,300.0064697,300.0064697,32979.70703125,32989.66796875,57.0299616486406,20.5636370893982,27.844467,0,0,0,40,4449,300.24255,32984.6875,,,,,,,,,,,,,0,,,,-0.00245,,,,,,300.0064697,,,,
,29157013.225,300.0098267,38016.83984375,-2.49714204941566E-5,1.58658229344858E-6,1,0.999253354069792,40.0298881530762,1.995088840114,16.7100001126528,-0.000282841494819795,-4.46873925520398E-5,0.25,3.70927331311631E-7,-2.4970921418534E-5,3.54467923356183E-7,300.0098267,300.0098267,38011.57421875,38022.10546875,57.0815491309099,20.5592543499246,27.844467,0,0,0,40,4449,300.2393,38016.83984375,,,,,,,,,,,,,0,,,,0.0049,,,,,,300.0098267,,,,
,29157111.78,300.0109253,42941.873046875,-4.99706574384644E-5,1.63585195176487E-6,1,0.999253354069792,40.0298881530762,1.99488019264652,16.7100001126528,-0.000562388719146142,-0.000109922150092602,0.25,-1.07308163732925E-6,-4.996846508896E-5,-1.10592800820601E-6,300.0109253,300.0109253,42934.328125,42949.41796875,57.2261504069676,20.5627562855106,27.844467,0,0,0,40,4449,300.2386,42941.873046875,,,,,,,,,,,,,0,,,,0,,,,,,300.0109253,,,,
,29157208.07,300.01309205,47757.447265625,-7.21333670111604E-5,1.88221383854907E-6,1,0.999253354069792,40.0298881530762,1.99478563873995,16.7100001126528,-0.000817746491774874,-0.000124226378859563,0.25,1.49989430423896E-6,-7.21322061262491E-5,1.45243877790339E-6,300.0130005,300.0131836,47747.73828125,47767.15625,56.8267382336406,20.5658303670373,28.603769,0,0,0,40,4449,300.2186,47757.447265625,,,,,,,,,,,,,0,,,,0.0049,,,,,,300.01309205,,,,
,29157307.07,300.0137634,52702.46875,-9.8657076437838E-5,2.13760977561741E-6,1,0.999253354069792,40.0298881530762,1.99494012858941,16.7100001126528,-0.00111688584005428,-0.000179336118411597,0.25,1.21758778226251E-6,-9.86549437824842E-5,1.15277925364637E-6,300.0137634,300.0137634,52694.921875,52710.015625,56.9815006804483,20.563553116735,28.224119,0,0,0,40,4449,300.2018,52702.46875,,,,,,,,,,,,,0,,,,0,,,,,,300.0137634,,,,
,29157407.32,300.0127258,57714.66796875,-0.000125256148133754,1.82717450506469E-6,1,0.999253354069792,40.0298881530762,1.99493703786179,16.7100001126528,-0.00141929219943124,-0.000220280475014364,0.25,2.20138772511494E-6,-0.000125253882589606,2.11918536301695E-6,300.0127258,300.0127258,57712.1328125,57717.203125,57.2855541744291,20.5617470787823,28.603769,0,0,0,40,4449,300.19915,57714.66796875,,,,,,,,,,,,,0,,,,-0.00245,,,,,,300.0127258,,,,
,29157506.485,300.0075073,62670.66796875,-0.000149364242656695,2.45941940420498E-6,1,0.999253354069792,40.0298881530762,1.99478823495178,16.7100001126528,-0.00168970152402003,-0.000277910247391653,0.25,1.27484340669449E-6,-0.000149360693052771,1.17697681888044E-6,300.0075073,300.0075073,62665.67578125,62675.66015625,56.7946914643522,20.5633485039643,27.844467,0,0,0,40,4449,300.19405,62670.66796875,,,,,,,,,,,,,0,,,,0,,,,,,300.0075073,,,,
,29157604.525,300.0115662,67573.2265625,-0.000173443206849873,2.67545948383802E-6,1,0.999253354069792,40.0298881530762,1.99486773523703,16.7100001126528,-0.00195709208851213,-0.000352047062759946,0.25,-1.11554159326555E-6,-0.000173437371993023,-1.22897779143712E-6,300.0115662,300.0115662,67568.1328125,67578.3203125,56.9752476522945,20.5614222808403,28.603769,0,0,0,40,4449,300.1774,67573.2265625,,,,,,,,,,,,,0,,,,-0.00245,,,,,,300.0115662,,,,
,29157702.635,300.0200806,72475.765625,-0.000198360339955323,2.46975255558779E-6,1,0.999253354069792,40.0298881530762,1.9947835501963,16.7100001126528,-0.00224531889048419,-0.000361287729292458,0.25,2.38188823040784E-6,-0.000198356011272905,2.25220591344182E-6,300.0200806,300.0200806,72465.8828125,72485.6484375,56.9979148793522,20.5624536422533,28.603769,0,0,0,40,4449,300.1738,72475.765625,,,,,,,,,,,,,0,,,,0.0049,,,,,,300.0200806,,,,
,29157802.025,300.0209045,77443.55859375,-0.000223393588104597,2.48675322971967E-6,1,0.999253354069792,40.0298881530762,1.99484248136446,16.7100001126528,-0.00252705012935123,-0.000416714323411329,0.25,1.81296454268363E-6,-0.000223388152675261,1.66711955562767E-6,300.0209045,300.0209045,77438.765625,77448.3515625,56.9830639374868,20.5614091244916,28.603769,0,0,0,40,4449,300.1605,77443.55859375,,,,,,,,,,,,,0,,,,0.00245,,,,,,300.0209045,,,,
,29157901.015,300.0158081,82392.35546875,-0.000251522693855992,3.41115438936141E-6,1,0.999253354069792,40.0298881530762,1.99466474329848,16.7100001126528,-0.00284395908310518,-0.000475200704987071,0.25,1.50501332209195E-6,-0.000251516286636227,1.34102028112317E-6,300.015564,300.0160522,82382.40625,82402.3046875,56.9627415959868,20.5635637718994,28.224119,0,0,0,40,4449,300.14545,82392.35546875,,,,,,,,,,,,,0,,,,-0.00245,,,,,,300.0158081,,,,
,29157996.685,300.0124512,87175.27734375,-0.000273482935118767,2.66335440238527E-6,1,0.999253354069792,40.0298881530762,1.99471247463263,16.7100001126528,-0.00309136061669553,-0.000522320662000618,0.25,1.13877538662006E-6,-0.000273475695184897,9.60693551717957E-7,300.0124512,300.0124512,87165.2109375,87185.34375,56.7079306987175,20.5618956033918,27.844467,0,0,0,40,4449,300.13395,87175.27734375,,,,,,,,,,,,,0,,,,0,,,,,,300.0124512,,,,
,29158106.34,300.0083618,88290.30859375,-0.00028316707609118,3.46811998403168E-6,1,0.999253354069792,40.0298881530762,1.99475489806326,16.7100001126528,-0.003203736797991,-0.000524409383143408,0.25,2.63251264689245E-6,-0.000283160571401774,2.44813066722951E-6,300.0083618,300.0083618,88282.75,88297.8671875,56.8376810329099,20.5622192911076,28.603769,0,0,0,40,4449,300.1253,88290.30859375,,,,,,,,,,,,,0,,,,0.00245,,,,,,300.0083618,,,,
,29158199.2,300.0027466,83649.38671875,-0.000255849323824945,2.68042797175161E-6,1,0.999253354069792,40.0298881530762,1.9947104964472,16.7100001126528,-0.00289016622082352,-0.000499424513491761,0.25,1.10935538039588E-7,-0.000255842005094993,-5.57887564560768E-8,300.0027466,300.0027466,83644.3828125,83654.390625,57.1706547821022,20.5626995468295,28.603769,0,0,0,40,4449,300.1354,83649.38671875,,,,,,,,,,,,,0,,,,0,,,,,,300.0027466,,,,
,29158297.01,299.9993744,78758.1875,-0.000229047217322543,2.56094481819246E-6,1,0.999253354069792,40.0298881530762,1.99459962389098,16.7100001126528,-0.00258931916754031,-0.000435212963989082,0.25,1.15037388386241E-6,-0.00022904136177767,1.00089146141293E-6,299.9993286,299.9994202,78750.6328125,78765.7421875,56.6469636742175,20.5642710088018,28.603769,0,0,0,40,4449,300.12815,78758.1875,,,,,,,,,,,,,0,,,,0,,,,,,299.9993744,,,,
,29158392.67,299.9959106,73977.0546875,-0.000205512076486213,3.38376642800967E-6,1,0.999253354069792,40.0298881530762,1.99494819448296,16.7100001126528,-0.00231682215091506,-0.000429959199275851,0.25,-2.45540790847313E-6,-0.000205504556809136,-2.58958712506132E-6,299.9959106,299.9959106,73966.8671875,73987.2421875,56.6368025034675,20.5599301880097,28.603769,0,0,0,40,4449,300.14245,73977.0546875,,,,,,,,,,,,,0,,,,0,,,,,,299.9959106,,,,
,29158488.15,299.9901733,69203.92578125,-0.000182325746318267,3.06363870479674E-6,1,0.999253354069792,40.0298881530762,1.99478686117369,16.7100001126528,-0.00205819938432325,-0.000364539628487129,0.25,-6.83786841826417E-7,-0.000182320075607205,-8.03014885822505E-7,299.9901733,299.9901733,69198.8359375,69209.015625,57.1620568683907,20.5634675320935,28.224119,0,0,0,40,4449,300.1423,69203.92578125,,,,,,,,,,,,,0,,,,0.00245,,,,,,299.9901733,,,,
,29158583.125,299.9911194,64456.22265625,-0.000159614531434283,2.37317776636641E-6,1,0.999253354069792,40.0298881530762,1.9947888174673,16.7100001126528,-0.00180267916927597,-0.000314192164291759,0.25,-1.61232200223124E-7,-0.000159609836790974,-2.6574284956215E-7,299.9911194,299.9911194,64451.1640625,64461.28125,57.1268835850253,20.5625157417032,27.844467,0,0,0,40,4449,300.14815,64456.22265625,,,,,,,,,,,,,0,,,,0.0049,,,,,,299.9911194,,,,
,29158679.435,299.987793,59642.787109375,-0.000131791805308351,2.31185212270374E-6,1,0.999253354069792,40.0298881530762,1.99472136910389,16.7100001126528,-0.00148656700767819,-0.000270011383428699,0.25,-1.07101072247729E-6,-0.000131787321008995,-1.15737596626312E-6,299.987793,299.987793,59632.66015625,59652.9140625,57.085457273506,20.5649650313458,27.844467,0,0,0,40,4449,300.1587,59642.787109375,,,,,,,,,,,,,0,,,,0,,,,,,299.987793,,,,
,29158775.315,299.9824829,54850.466796875,-0.000108616143643011,2.12163309216504E-6,1,0.999253354069792,40.0298881530762,1.99476158464856,16.7100001126528,-0.0012236364791778,-0.000231426391673186,0.25,-1.66981939600119E-6,-0.00010861194416022,-1.74105581378E-6,299.9824829,299.9824829,54845.421875,54855.51171875,56.8853603725829,20.5645444582042,27.844467,0,0,0,40,4449,300.166,54850.466796875,,,,,,,,,,,,,0,,,,-0.0049,,,,,,299.9824829,,,,
,29158872.185,299.9888611,50009.955078125,-8.44338957060962E-5,1.88393469034931E-6,1,0.999253354069792,40.0298881530762,1.99472884842499,16.7100001126528,-0.000961090177626167,-0.000122764352488286,0.25,3.76012971473455E-6,-8.4433928748616E-5,3.70454608913741E-6,299.9888611,299.9888611,50002.64453125,50017.265625,56.8712910592368,20.5651184900659,28.224119,0,0,0,40,4449,300.1776,50009.955078125,,,,,,,,,,,,,0,,,,-0.0049,,,,,,299.9888611,,,,
,29158965.8,299.9828186,45329.9609375,-6.17912969495273E-5,1.38397842375224E-6,1,0.999253354069792,40.0298881530762,1.9948205298442,16.7100001126528,-0.000698634389951322,-0.000117272648622045,0.25,3.23903286793528E-7,-6.1789735693729E-5,2.83251870697326E-7,299.9824524,299.9831848,45324.77734375,45335.14453125,57.017455592333,20.5638032306378,28.603769,0,0,0,40,4449,300.18305,45329.9609375,,,,,,,,,,,,,0,,,,0.0049,,,,,,299.9828186,,,,
,29159058.835,299.9874878,40679.46484375,-3.85574775615003E-5,1.2732997472469E-6,1,0.999253354069792,40.0298881530762,1.99483890817139,16.7100001126528,-0.000435806276547125,-7.39979246234366E-5,0.25,1.29574493153886E-7,-3.8556446905195E-5,1.04183982549712E-7,299.9874573,299.9875183,40671.65234375,40687.27734375,57.0463758475445,20.564420700616,27.844467,0,0,0,40,4449,300.19195,40679.46484375,,,,,,,,,,,,,0,,,,-0.0049,,,,,,299.9874878,,,,
,29159153.08,299.9869385,35969.607421875,-1.46161631231483E-5,1.20388648222196E-6,1,0.999253354069792,40.0298881530762,1.99488490695342,16.7100001126528,-0.000166752894730625,-1.91272905784724E-5,0.25,8.39117566838368E-7,-1.46162925415075E-5,8.29459785395699E-7,299.9869385,299.9869385,35964.5,35974.71484375,57.0010413934291,20.5639652765282,28.224119,0,0,0,40,4449,300.198,35969.607421875,,,,,,,,,,,,,0,,,,0,,,,,,299.9869385,,,,
,29159245.625,299.9877625,31342.5322265625,8.1510014639658E-6,1.13697283349315E-6,1,0.999253354069792,40.0298881530762,1.99488742372174,16.7100001126528,9.07834249590767E-5,2.34214573774926E-5,0.25,6.61134736456855E-7,8.15032831709652E-6,6.66493095444256E-7,299.9877625,299.9877625,31332.595703125,31352.46875,56.7337244398522,20.5650059648814,27.844467,0,0,0,40,4449,300.2064,31342.5322265625,,,,,,,,,,,,,0,,,,0,,,,,,299.9877625,,,,
,29159342.36,299.9854126,26509.279296875,3.00830961059837E-5,9.77796471019346E-7,1,0.999253354069792,40.0298881530762,1.99492218872348,16.7100001126528,0.000339815545880836,5.90078838854769E-5,0.25,1.13873245725728E-8,3.00822148496776E-5,3.12530778489833E-8,299.9854126,299.9854126,26504.310546875,26514.248046875,56.926005055583,20.5654742550732,28.224119,0,0,0,40,4449,300.2262,26509.279296875,,,,,,,,,,,,,0,,,,0,,,,,,299.9854126,,,,
,29159439.665,299.9895935,21644.3330078125,5.33916462993612E-5,8.93048138144567E-7,1,0.999253354069792,40.0298881530762,1.99483116858451,16.7100001126528,0.00060179802980167,0.000112122899108929,0.25,6.75263364454094E-7,5.338963811646E-5,7.10536467125001E-7,299.9895935,299.9895935,21631.162109375,21657.50390625,56.7563916669098,20.5663527116335,27.844467,0,0,0,40,4449,300.23255,21644.3330078125,,,,,,,,,,,,,0,,,,-0.0049,,,,,,299.9895935,,,,
,29159535.405,299.9923706,16861.953125,7.55378833318411E-5,7.63667231744601E-7,1,0.999253354069792,40.0298881530762,1.99479758404058,16.7100001126528,0.000854050337612567,0.000143348258255098,0.25,-3.97331910064406E-7,7.5535924712817E-5,-3.47340079076153E-7,299.9923706,299.9923706,16859.482421875,16864.423828125,57.0455942190253,20.5661697428663,28.603769,0,0,0,40,4449,300.2265,16861.953125,,,,,,,,,,,,,0,,,,-0.0049,,,,,,299.9923706,,,,
,29159632.05,299.9898682,12032.6459960938,9.59143728996079E-5,5.76140835344639E-7,1,0.999253354069792,40.0298881530762,1.99491398279043,16.7100001126528,0.00108354498577234,0.000187495727722921,0.25,-2.04481301040218E-8,9.59115697159171E-5,4.30656894197423E-8,299.9898682,299.9898682,12027.7099609375,12037.58203125,57.1339182416984,20.5663178213367,28.224119,0,0,0,40,4449,300.2513,12032.6459960938,,,,,,,,,,,,,0,,,,-0.0049,,,,,,299.9898682,,,,
,29159727.67,299.9910889,7252.09106445313,0.000114628660043035,5.57236571536763E-7,1,0.999253354069792,40.0298881530762,1.99492790693563,16.7100001126528,0.00129502434285221,0.000223760108056584,0.25,-5.28452923889597E-8,0.000114625318333651,2.31217777164507E-8,299.9910889,299.9910889,7244.7216796875,7259.46044921875,57.0666981890445,20.5662628506063,27.844467,0,0,0,40,4449,300.25905,7252.09106445313,,,,,,,,,,,,,0,,,,-0.00245,,,,,,299.9910889,,,,
,29159822.67,299.9920654,2504.00720214844,0.000122547344373691,4.89325913296295E-7,1,0.999253354069792,40.0298881530762,1.99485917390197,16.7100001126528,0.00138442223673794,0.00023931540419882,0.25,-4.72081773406644E-8,0.000122543756197909,3.40640800643459E-8,299.9920654,299.9920654,2491.43139648438,2516.5830078125,57.2488176340253,20.5668005905079,28.224119,0,0,0,40,4449,300.2588,2504.00720214844,,,,,,,,,,,,,0,,,,-0.0049,,,,,,299.9920654,,,,
,29159873.515,299.9888306,-0.532832026481628,-5.08494358285643E-7,4.57891619252498E-7,1,0.999253354069792,40.0298881530762,1.99481979540403,16.7100001126528,-4.51481946640195E-6,-8.08957293255341E-6,0.25,-6.28038509844811E-7,-5.0806276147102E-7,-6.2835734705772E-7,299.9888306,299.9888306,-0.532832026481628,-0.532832026481628,57.2527257766214,20.5681136420191,28.224119,0,0,0,40,4417,300.25165,-0.532832026481628,,,,,,,,,,,,,0,,,,-0.00245,,,,,,299.9888306,,,,