File: data/looselyPackedNP/sc-ios-11/ppms/rawdata/ES_S14_ZFCW_100OE.DAT
[Header]
; VSM Data File (default extension .dat)
; Copyright (c) 2003-2013, Quantum Design, Inc. All rights reserved.
TITLE,
FILEOPENTIME,29160698.13,12/04/2018,8:12 pm
BYAPP,VSM,2.0,2.0
INFO,PPMS VSM Option Release 1.4.10 Build 1,APPNAME
INFO,Quantum Design Linear Motor Servo Controller,MOTOR_MODULE_NAME
INFO,3101-100 M1,MOTOR_HW_VERSION
INFO,MMC1014,MOTOR_SERIAL_NUMBER
INFO,SRV No X-over 01.03.11,MOTOR_SOFTWARE_VERSION
INFO,Quantum Design VSM Detection Module,VSM_MODULE_NAME
INFO,3101-150 F0,VSM_HW_VERSION
INFO,VSM707,VSM_SERIAL_NUMBER
INFO,VSM No X-over 01.02.05 May 20 2008 13:51:47,VSM_SOFTWARE_VERSION
INFO,704,PREAMP_SERIAL_NUMBER
INFO,822,COIL_SERIAL_NUMBER
INFO,0,MOMENT_UNITS
INFO,Iron Oxide Spheres,SAMPLE_MATERIAL
INFO,10 nm diameter, collaboration Mainz,SAMPLE_COMMENT
INFO,,SAMPLE_MASS
INFO,,SAMPLE_VOLUME
INFO,,SAMPLE_MOLECULAR_WEIGHT
INFO,,SAMPLE_SIZE
INFO,,SAMPLE_SHAPE
DATATYPE,COMMENT,1
DATATYPE,TIME,2
STARTUPAXIS,X,2
STARTUPAXIS,Y1,5
[Data]
Comment,Time Stamp (sec),Temperature (K),Magnetic Field (Oe),Moment (emu),M. Std. Err. (emu),Transport Action,Averaging Time (sec),Frequency (Hz),Peak Amplitude (mm),Center Position (mm),Coil Signal' (mV),Coil Signal" (mV),Range (mV),M. Quad. Signal (emu),M. Raw' (emu),M. Raw" (emu),Min. Temperature (K),Max. Temperature (K),Min. Field (Oe),Max. Field (Oe),Mass (grams),Motor Lag (deg),Pressure (Torr),VSM Status (code),Motor Status (code),Measure Status (code),Measure Count,PPMS Status (code),System Temp. (K),System Field (Oe),Sample Position (deg),Bridge 1 Resistance (ohms),Bridge 1 Excitation (에),Bridge 2 Resistance (ohms),Bridge 2 Excitation (에),Bridge 3 Resistance (ohms),Bridge 3 Excitation (에),Bridge 4 Resistance (ohms),Bridge 4 Excitation (에),Signal 1 Vin (V),Signal 2 Vin (V),Digital Inputs (code),Drive 1 Iout (mA),Drive 1 Ipower (W),Drive 2 Iout (mA),Drive 2 Ipower (W),Pressure (),Map 20 (),Map 21 (),Map 22 (),Map 23 (),Map 24 (),Map 25 (),Map 26 (),Map 27 (),Map 28 (),Map 29 ()
,29165361.13,9.9984236,99.6091461181641,,,2,,,,17.7000004118681,,,,,,,9.9984236,9.9984236,99.6091461181641,99.6091461181641,,,13.038077,,,,-99999999,4373,9.9945,99.6091461181641,,,,,,,,,,,,,,,,,,,,,,,9.9984236,,,,
,29165569.365,12.5610533,99.6091461181641,3.805356483369E-6,3.52299066324183E-7,1,0.999253354069792,40.0298881530762,1.99624165321747,17.6899991929531,4.33424808450716E-5,4.18505827286629E-6,0.25,-3.03105963694217E-7,3.7849492338878E-6,-2.83011538706537E-7,12.5610533,12.5610533,99.6091461181641,99.6091461181641,56.6547799594098,20.5401746239904,13.038077,0,0,0,40,4370,12.6736,99.6091461181641,,,,,,,,,,,,,0,,,,0,,,,,,12.5610533,,,,
,29165708.695,16.0247073,99.6091461181641,4.68131569845943E-6,3.75202621217604E-7,1,0.999253354069792,40.0298881530762,1.9960912088651,17.6899991929531,5.26168349137245E-5,9.08082954812104E-6,0.25,-2.26741252595776E-8,4.65447928124514E-6,3.3262931184915E-11,15.9909315,16.0584831,99.6091461181641,99.6091461181641,56.7227816405829,20.543745792519,14.177031,0,0,0,40,4370,16.1621,99.6091461181641,,,,,,,,,,,,,0,,,,-0.00735,,,,,,16.0247073,,,,
,29165848.965,19.5211887,99.6091461181641,5.37513651759084E-6,2.77706442648234E-7,1,0.999253354069792,40.0298881530762,1.99599767025213,17.6899991929531,6.16343588507846E-5,3.54801124359272E-6,0.25,-6.38653726691095E-7,5.34731464823995E-6,-6.08951853349142E-7,19.4912109,19.5511665,99.6091461181641,99.6091461181641,56.8689461736791,20.5487207279666,14.936333,0,0,0,40,4370,19.68185,99.6091461181641,,,,,,,,,,,,,0,,,,0,,,,,,19.5211887,,,,
,29165969.93,22.502533,99.6091461181641,6.23252293246466E-6,3.51502333200583E-7,1,0.999253354069792,40.0298881530762,2.00861281364141,17.6999997347593,7.08422518003895E-5,1.01053878061931E-5,0.25,-2.13040512162659E-7,6.19816679504205E-6,-1.81056531722379E-7,22.502533,22.502533,99.6091461181641,99.6091461181641,56.8064158921406,20.5493346651649,14.936333,0,0,0,40,4370,22.7203,99.6091461181641,,,,,,,,,,,,,0,,,,-0.00245,,,,,,22.502533,,,,
,29166112.235,26.0590267,99.6091461181641,7.05484843643307E-6,3.34039519205185E-7,1,0.999253354069792,40.0298881530762,2.00864591138581,17.6999997347593,8.05557276506963E-5,9.47344297077324E-6,0.25,-4.16791644192445E-7,7.01818171522095E-6,-3.78154304056995E-7,26.0590267,26.0590267,99.6091461181641,99.6091461181641,57.0463758475445,20.5531896692309,15.695635,0,0,0,40,4370,26.31755,99.6091461181641,,,,,,,,,,,,,0,,,,0,,,,,,26.0590267,,,,
,29166250.87,29.5056896,99.6091461181641,8.58780093131696E-6,4.06539191954942E-7,1,0.999253354069792,40.0298881530762,2.008800195451,17.6999997347593,9.77997364886659E-5,1.32091334409339E-5,0.25,-3.62034783502867E-7,8.5450556121076E-6,-3.13254829326085E-7,29.5056896,29.5056896,99.6091461181641,99.6091461181641,57.0698247031214,20.5490523447342,16.075285,0,0,0,40,4370,29.79845,99.6091461181641,,,,,,,,,,,,,0,,,,0,,,,,,29.5056896,,,,
,29166394.235,33.0417519,99.6091461181641,9.77766897932487E-6,3.82580724982769E-7,1,0.999253354069792,40.0298881530762,1.99642348014893,17.7200008183718,0.000109349878672728,2.27875072584622E-5,0.25,2.8029918554518E-7,9.72957710948207E-6,3.36358831559858E-7,33.0417519,33.0417519,99.6091461181641,99.6091461181641,57.115940785756,20.5479086313531,16.454937,0,0,0,40,4370,33.41555,99.6091461181641,,,,,,,,,,,,,0,,,,0,,,,,,33.0417519,,,,
,29166536.85,36.5523376,99.6091461181641,1.16219815095162E-5,3.72385291005756E-7,1,0.999253354069792,40.0298881530762,1.99607946403292,17.7200008183718,0.000131117423640792,2.10577149594726E-5,0.25,-2.0925939304899E-7,1.15754070722168E-5,-1.34874869932203E-7,36.5523376,36.5523376,99.6091461181641,99.6091461181641,57.2191157502945,20.5492128318649,16.834587,0,0,0,40,4370,37.00455,99.6091461181641,,,,,,,,,,,,,0,,,,-0.00245,,,,,,36.5523376,,,,
,29166676.135,40.0345306,99.6091461181641,1.37366005796142E-5,3.75102094852008E-7,1,0.999253354069792,40.0298881530762,1.99595896576599,17.7200008183718,0.000154699231535731,2.70832714649552E-5,0.25,-5.99908657598804E-8,1.36912445014496E-5,3.3141221186489E-8,40.0345306,40.0345306,99.6091461181641,99.6091461181641,57.1644017539484,20.5506702970415,17.593889,0,0,0,40,4370,40.5099,99.6091461181641,,,,,,,,,,,,,0,,,,-0.00245,,,,,,40.0345306,,,,
,29166818.86,43.5336494,99.6091461181641,1.55007231127844E-5,3.34442174874834E-7,1,0.999253354069792,40.0298881530762,1.98491504618169,17.7200008183718,0.000173853089112978,3.02221138518648E-5,0.25,-9.20148607048912E-8,1.54649419264276E-5,1.89232823944434E-8,43.5336494,43.5336494,99.6091461181641,99.6091461181641,56.9158438848329,20.5572615073014,16.834587,0,0,0,40,4370,44.12835,99.6091461181641,,,,,,,,,,,,,0,,,,0,,,,,,43.5336494,,,,
,29166962.275,47.0244293,99.6091461181641,1.84883937116101E-5,3.34523608458818E-7,1,0.999253354069792,40.0298881530762,1.9848250388818,17.7200008183718,0.000207727097796914,3.52905640241054E-5,0.25,-1.84918024680585E-7,1.84667500129987E-5,-4.82189247548947E-8,47.0244293,47.0244293,99.6091461181641,99.6091461181641,57.149550812083,20.5563505135895,17.973541,0,0,0,40,4370,47.7757,99.6091461181641,,,,,,,,,,,,,0,,,,0,,,,,,47.0244293,,,,
,29167104.89,50.5304413,99.6091461181641,2.18091542255387E-5,3.57666221781897E-7,1,0.999253354069792,40.0298881530762,1.98472712335929,17.7200008183718,0.000245061871955751,4.30358034856402E-5,0.25,-9.7981389318346E-8,2.18077087880576E-5,6.42446550349259E-8,50.5304413,50.5304413,99.6091461181641,99.6091461181641,57.1401712698522,20.5588586547258,18.353191,0,0,0,40,4370,51.41785,99.6091461181641,,,,,,,,,,,,,0,,,,0.00245,,,,,,50.5304413,,,,
,29167249.94,54.0100822,99.6091461181641,2.4853226716073E-5,3.40056291873765E-7,1,0.999253354069792,40.0298881530762,1.9957019962516,17.6999997347593,0.000280835402560201,5.05962078042829E-5,0.25,1.4358994949528E-9,2.48788521364505E-5,1.83051033125232E-7,54.0100822,54.0100822,99.6091461181641,99.6091461181641,57.0792042453522,20.5547994549441,19.871798,0,0,0,40,4374,55.1522,99.6091461181641,,,,,,,,,,,,,0,,,,0,,,,,,54.0100822,,,,
,29167396.125,57.5386124,99.6091461181641,2.86151351177298E-5,3.10896554691706E-7,1,0.999253354069792,40.0298881530762,1.99552381884273,17.6999997347593,0.000323786642706676,5.75425150064523E-5,0.25,-5.76220662889076E-8,2.86745494675476E-5,1.4301899865257E-7,57.5386124,57.5386124,99.6091461181641,99.6091461181641,57.2191157502945,20.5586643631373,20.631098,0,0,0,40,4374,58.9358,99.6091461181641,,,,,,,,,,,,,0,,,,-0.00245,,,,,,57.5386124,,,,
,29167539.145,61.0245705,99.6091461181641,3.239236175347E-5,3.62409993377725E-7,1,0.999253354069792,40.0298881530762,1.99567785919085,17.6999997347593,0.000366279787289278,6.84511876928555E-5,0.25,2.34696569704498E-7,3.24851275896906E-5,4.50196226081405E-7,61.0245705,61.0245705,99.6091461181641,99.6091461181641,57.0440309619868,20.5579030736925,21.770052,0,0,0,40,4374,62.5993,99.6091461181641,,,,,,,,,,,,,0,,,,0,,,,,,61.0245705,,,,
,29167661.52,64.00785065,99.6091461181641,3.57464245515025E-5,3.14232646521902E-7,1,0.999253354069792,40.0298881530762,2.00848630050541,17.6999997347593,0.000407187850875603,7.4579975143246E-5,0.25,1.43572464375006E-7,3.58711373269735E-5,3.67954015080919E-7,63.9770508,64.0386505,99.6091461181641,99.6091461181641,57.2769562607176,20.5561371616812,22.529354,0,0,0,40,4374,65.71695,99.6091461181641,,,,,,,,,,,,,0,,,,0,,,,,,64.00785065,,,,
,29167803.025,67.5241776,99.6091461181641,4.01458232892894E-5,2.87700535434238E-7,1,0.999253354069792,40.0298881530762,2.00831550751558,17.6999997347593,0.000458255092917475,7.96690618280516E-5,0.25,-1.83295433061528E-7,4.0310320913227E-5,4.99508461584605E-8,67.5241776,67.5241776,99.6091461181641,99.6091461181641,57.4426615067945,20.5623595119292,22.909004,0,0,0,40,4374,69.2679,99.6091461181641,,,,,,,,,,,,,0,,,,-0.0049,,,,,,67.5241776,,,,
,29167945.18,71.0617065,99.6091461181641,4.38131257188739E-5,3.18459117812131E-7,1,0.999253354069792,40.0298881530762,2.00810637684802,17.6999997347593,0.00050006406070979,8.82180256576827E-5,0.25,-7.2288467476261E-8,4.40112797650328E-5,1.6386909285217E-7,71.0617065,71.0617065,99.6091461181641,99.6091461181641,57.1933220091599,20.566721278843,22.909004,0,0,0,40,4374,72.8622,99.6091461181641,,,,,,,,,,,,,0,,,,0.00245,,,,,,71.0617065,,,,
,29168065.915,74.0090561,99.6091461181641,4.6642664528967E-5,3.38241977775757E-7,1,0.999253354069792,40.0298881530762,1.98443387231132,17.6699999719858,0.000526825714493329,9.11725494143647E-5,0.25,-2.12584012265797E-7,4.68680501762781E-5,2.20000809677026E-8,74.0090561,74.0090561,99.6091461181641,99.6091461181641,57.3676251689484,20.569105355148,22.529354,0,0,0,40,4374,75.90335,99.6091461181641,,,,,,,,,,,,,0,,,,0,,,,,,74.0090561,,,,
,29168206.58,77.516983,99.6091461181641,4.97953430882545E-5,2.71975249565361E-7,1,0.999253354069792,40.0298881530762,1.98403904825819,17.6699999719858,0.000561852367717616,0.000100861203247845,0.25,1.03566971479292E-7,5.00477111071804E-5,3.36832953012398E-7,77.516983,77.516983,99.6091461181641,99.6091461181641,57.2019199228714,20.5743382860698,22.529354,0,0,0,40,4374,79.4679,99.6091461181641,,,,,,,,,,,,,0,,,,0,,,,,,77.516983,,,,
,29168352.18,81.09412,99.6091461181641,5.22911198590907E-5,3.12609627293858E-7,1,0.999253354069792,40.0298881530762,1.98386625373262,17.6699999719858,0.000589969745755724,0.000106584447103381,0.25,1.85297262660108E-7,5.25667511206957E-5,4.12107297844104E-7,81.0565338,81.1317062,99.6091461181641,99.6091461181641,57.1628384969099,20.5722215333366,23.288654,0,0,0,40,4374,83.1561,99.6091461181641,,,,,,,,,,,,,0,,,,0.00245,,,,,,81.09412,,,,
,29168471.385,84.0455475,99.6091461181641,5.36157128756073E-5,3.00974029265819E-7,1,0.999253354069792,40.0298881530762,1.98376874707511,17.6599994301796,0.000605468522962969,0.000106428594735317,0.25,-4.9641779154152E-8,5.3906157438699E-5,1.67533782416615E-7,84.0455475,84.0455475,99.6091461181641,99.6091461181641,57.0917103016599,20.5721844485991,22.909004,0,0,0,40,4374,86.16245,99.6091461181641,,,,,,,,,,,,,0,,,,0,,,,,,84.0455475,,,,
,29168612.9,87.5549164,99.6091461181641,5.53226379168365E-5,3.36609209289275E-7,1,0.999253354069792,40.0298881530762,1.98371986522245,17.6599994301796,0.000623973141859493,0.000114496655855812,0.25,3.77877312421937E-7,5.56267813676974E-5,5.88765393691467E-7,87.5549164,87.5549164,99.6091461181641,99.6091461181641,56.9244417985445,20.5748602766389,23.668306,0,0,0,40,4374,89.70785,99.6091461181641,,,,,,,,,,,,,0,,,,-0.0049,,,,,,87.5549164,,,,
,29168753.47,91.057663,99.6091461181641,5.62374722862952E-5,3.26655976491268E-7,1,0.999253354069792,40.0298881530762,1.98375823534556,17.6599994301796,0.000634694939475319,0.000114449302446822,0.25,2.25395658175847E-7,5.65515315733192E-5,4.24773018887616E-7,91.057663,91.057663,99.6091461181641,99.6091461181641,57.3371416566984,20.5749517919631,23.668306,0,0,0,40,4374,93.2363,99.6091461181641,,,,,,,,,,,,,0,,,,-0.0049,,,,,,91.057663,,,,
,29168892.22,94.5370178,99.6091461181641,5.70644522925488E-5,3.18448234155328E-7,1,0.999253354069792,40.0298881530762,1.98382938032189,17.6299996674061,0.000644365711292906,0.000114521027744727,0.25,9.78890550548149E-8,5.73862988688521E-5,2.86744944295893E-7,94.5370178,94.5370178,99.6091461181641,99.6091461181641,56.8673829166406,20.5717846173083,24.047956,0,0,0,40,4374,96.72025,99.6091461181641,,,,,,,,,,,,,0,,,,-0.00245,,,,,,94.5370178,,,,
,29169032.35,98.0414505,99.6091461181641,5.76682431893468E-5,3.23397760289517E-7,1,0.999253354069792,40.0298881530762,1.98376124175898,17.6299996674061,0.000651665438601648,0.000112961808261681,0.25,-1.347320928449E-7,5.79957076711512E-5,4.31628229124737E-8,98.0414505,98.0414505,99.6091461181641,99.6091461181641,57.3293253715061,20.5743013559389,24.427608,0,0,0,40,4374,100.22445,99.6091461181641,,,,,,,,,,,,,0,,,,0,,,,,,98.0414505,,,,
,29169174.125,101.5131836,99.6091461181641,5.77698454587152E-5,3.76923254293148E-7,1,0.999253354069792,40.0298881530762,1.98366309887724,17.6299996674061,0.000653205474340705,0.000110780374420456,0.25,-3.34699531668787E-7,5.8098998947138E-5,-1.68311201089974E-7,101.5131836,101.5131836,99.6091461181641,99.6091461181641,57.0948368157368,20.5689238415106,24.427608,0,0,0,40,4374,103.79085,99.6091461181641,,,,,,,,,,,,,0,,,,0,,,,,,101.5131836,,,,
,29169313.78,105.0164261,99.6091461181641,5.75663835188311E-5,2.5472014198695E-7,1,0.999253354069792,40.0298881530762,2.0078751819099,17.5999999046326,0.000658386397420814,0.000112211547762542,0.25,-2.77143026865157E-7,5.78937622500437E-5,-1.20497043271696E-7,105.0164261,105.0164261,99.6091461181641,99.6091461181641,56.8877052581406,20.559256209652,24.427608,0,0,0,40,4374,107.3143,99.6091461181641,,,,,,,,,,,,,0,,,,0.00245,,,,,,105.0164261,,,,
,29169456.04,108.5332108,99.6091461181641,5.72256219840794E-5,3.87050603120154E-7,1,0.999253354069792,40.0298881530762,2.00777975448436,17.5999999046326,0.000653144987538529,0.000118966519987885,0.25,3.83006867924665E-7,5.75482265460601E-5,5.33805742279614E-7,108.5332108,108.5332108,99.6091461181641,99.6091461181641,57.2863358029484,20.5617890440597,24.807261,0,0,0,40,4374,110.8954,99.6091461181641,,,,,,,,,,,,,0,,,,0,,,,,,108.5332108,,,,
,29169596.68,112.0233154,99.6091461181641,5.71266097574753E-5,3.60666851453777E-7,1,0.999253354069792,40.0298881530762,2.00785101719909,17.5999999046326,0.000653307895865872,0.000111395017050836,0.25,-2.54615841182312E-7,5.74485773710559E-5,-1.15381640000395E-7,112.0233154,112.0233154,99.6091461181641,99.6091461181641,57.3230723433522,20.5637039112733,24.427608,0,0,0,40,4374,114.4275,99.6091461181641,,,,,,,,,,,,,0,,,,-0.0049,,,,,,112.0233154,,,,
,29169738.505,115.5622673,99.6091461181641,5.59969719170492E-5,3.02413323700903E-7,1,0.999253354069792,40.0298881530762,2.0077925391034,17.5700001418591,0.000639983051687362,0.000111257880608201,0.25,-6.12740785159947E-8,5.63098940670679E-5,6.93372111009771E-8,115.5294952,115.5950394,99.6091461181641,99.6091461181641,57.1636201254291,20.5628875178763,24.427608,0,0,0,40,4374,117.9958,99.6091461181641,,,,,,,,,,,,,0,,,,0,,,,,,115.5622673,,,,
,29169878.14,119.0295258,99.6091461181641,5.54012969334373E-5,3.52553742367114E-7,1,0.999253354069792,40.0298881530762,2.00750298384502,17.5700001418591,0.000632875578398698,0.000111101930560254,0.25,3.71907390556249E-8,5.57081105682183E-5,1.60816888250343E-7,119.0295258,119.0295258,99.6091461181641,99.6091461181641,57.1706547821022,20.5654426410456,24.807261,0,0,0,40,4374,121.50475,99.6091461181641,,,,,,,,,,,,,0,,,,0.00245,,,,,,119.0295258,,,,
,29170017,122.5004196,99.6091461181641,5.46327854710324E-5,3.44823729013476E-7,1,0.999253354069792,40.0298881530762,2.00750191181675,17.5700001418591,0.000623782771896047,0.000111159991501386,0.25,1.82647514072814E-7,5.49321466636072E-5,2.99843395605901E-7,122.5004196,122.5004196,99.6091461181641,99.6091461181641,57.2245871499291,20.5658356822105,24.047956,0,0,0,40,4374,125.00165,99.6091461181641,,,,,,,,,,,,,0,,,,-0.00245,,,,,,122.5004196,,,,
,29170138.095,125.5058975,99.6091461181641,5.43179209582812E-5,2.99260623692073E-7,1,0.999253354069792,40.0298881530762,2.00763788538461,17.5299998372793,0.000620488279316657,0.000108851785380675,0.25,3.98381886671386E-8,5.46131195997802E-5,1.51205503807923E-7,125.5058975,125.5058975,99.6091461181641,99.6091461181641,57.187068981006,20.5646922254618,24.807261,0,0,0,40,4374,128.0287,99.6091461181641,,,,,,,,,,,,,0,,,,-0.00245,,,,,,125.5058975,,,,
,29170280.21,129.0259247,99.6091461181641,5.34361821012375E-5,3.28622285849057E-7,1,0.999253354069792,40.0298881530762,2.00756449375302,17.5299998372793,0.000610619183416599,0.000105565687195736,0.25,-8.82152814504762E-8,5.37234284043106E-5,1.59771127983114E-8,129.0259247,129.0259247,99.6091461181641,99.6091461181641,57.0362146767945,20.5677292186014,24.427608,0,0,0,40,4374,131.5966,99.6091461181641,,,,,,,,,,,,,0,,,,0,,,,,,129.0259247,,,,
,29170419.49,132.5338593,99.6091461181641,5.26450901008948E-5,2.77624593877909E-7,1,0.999253354069792,40.0298881530762,2.00768671732984,17.5299998372793,0.000601385982301528,0.000105073227828784,0.25,1.10149825543564E-8,5.29242751760833E-5,1.1003038642634E-7,132.5338593,132.5338593,99.6091461181641,99.6091461181641,57.3332335141022,20.5678157079065,25.186911,0,0,0,40,4374,135.0964,99.6091461181641,,,,,,,,,,,,,0,,,,-0.00245,,,,,,132.5338593,,,,
,29170539.73,135.5015869,99.6091461181641,5.22564913476844E-5,3.42582820754166E-7,1,0.999253354069792,40.0298881530762,1.99529039828764,17.5000000745058,0.000593425953840231,0.000103490761401922,0.25,-2.17957151128581E-9,5.25304433069046E-5,9.27436864340039E-8,135.5015869,135.5015869,99.6091461181641,99.6091461181641,56.7180918694675,20.5623354252095,25.186911,0,0,0,40,4374,138.104,99.6091461181641,,,,,,,,,,,,,0,,,,0,,,,,,135.5015869,,,,
,29170680.915,139.0343323,99.6091461181641,5.07726865402993E-5,3.90526362061616E-7,1,0.999253354069792,40.0298881530762,1.99491914759773,17.5000000745058,0.000576809691798547,9.83459576466623E-5,0.25,-1.90709617233219E-7,5.10353016492055E-5,-1.02966204036747E-7,139.0343323,139.0343323,99.6091461181641,99.6091461181641,57.0870205305445,20.5677267424581,25.186911,0,0,0,40,4374,141.6564,99.6091461181641,,,,,,,,,,,,,0,,,,0,,,,,,139.0343323,,,,
,29170821.88,142.5140228,99.6091461181641,4.97551409698505E-5,3.5163861278687E-7,1,0.999253354069792,40.0298881530762,1.99492044842695,17.5000000745058,0.000565657904453018,9.37725672704979E-5,0.25,-4.12315829325174E-7,5.00089425413133E-5,-3.30633622303223E-7,142.5140228,142.5140228,99.6091461181641,99.6091461181641,57.8115901678715,20.5722308765342,25.186911,0,0,0,40,4374,145.1935,99.6091461181641,,,,,,,,,,,,,0,,,,0,,,,,,142.5140228,,,,
,29170962.89,146.0552979,99.6091461181641,4.91857134740767E-5,3.12352271298787E-7,1,0.999253354069792,40.0298881530762,1.98376079767677,17.4599997699261,0.000555084268228185,9.83135901062054E-5,0.25,1.37062619170975E-7,4.94315861007768E-5,2.1766553924652E-7,146.0552979,146.0552979,99.6091461181641,99.6091461181641,57.017455592333,20.569446273502,25.566563,0,0,0,40,4374,148.72445,99.6091461181641,,,,,,,,,,,,,0,,,,0,,,,,,146.0552979,,,,
,29171102.985,149.5318451,99.6091461181641,4.82828600984217E-5,4.08770549042339E-7,1,0.999253354069792,40.0298881530762,1.98370174234613,17.4599997699261,0.000544892891482303,9.61579936747903E-5,0.25,1.07046739955024E-7,4.85201716989929E-5,1.83382651217373E-7,149.5318451,149.5318451,99.6091461181641,99.6091461181641,57.1448610409676,20.5737107162614,25.566563,0,0,0,40,4374,152.24145,99.6091461181641,,,,,,,,,,,,,0,,,,0,,,,,,149.5318451,,,,
,29171243.5,153.0347595,99.6091461181641,4.75217301128144E-5,3.74707710694284E-7,1,0.999253354069792,40.0298881530762,1.98347571318961,17.4599997699261,0.000537055780700193,8.96959873700569E-5,0.25,-3.28777120316489E-7,4.77517684366833E-5,-2.58176137314397E-7,153.0347595,153.0347595,99.6091461181641,99.6091461181641,56.8986480574099,20.5743168811462,25.186911,0,0,0,40,4374,155.7618,99.6091461181641,,,,,,,,,,,,,0,,,,0.00245,,,,,,153.0347595,,,,
,29171383.75,156.5353699,99.6091461181641,4.65101363840701E-5,3.88293549342254E-7,1,0.999253354069792,40.0298881530762,1.98369512241239,17.4199994653463,0.000524389889145718,9.49190539081043E-5,0.25,3.12160155306915E-7,4.67301056555154E-5,3.82083504651169E-7,156.5353699,156.5353699,99.6091461181641,99.6091461181641,57.2464727484676,20.5673999209893,25.946213,0,0,0,40,4374,159.2678,99.6091461181641,,,,,,,,,,,,,0,,,,0,,,,,,156.5353699,,,,
,29171523.11,160.0267334,99.6091461181641,4.53524041043109E-5,3.34509602154675E-7,1,0.999253354069792,40.0298881530762,1.98349522551171,17.4199994653463,0.000511254444165527,9.24580230950499E-5,0.25,2.99223714615806E-7,4.55627052365185E-5,3.65340687647035E-7,160.0267334,160.0267334,99.6091461181641,99.6091461181641,56.9244417985445,20.5729963666437,25.566563,0,0,0,40,4374,162.7695,99.6091461181641,,,,,,,,,,,,,0,,,,-0.0049,,,,,,160.0267334,,,,
,29171663.19,163.5496979,99.6091461181641,4.46541433339891E-5,3.66362190907445E-7,1,0.999253354069792,40.0298881530762,1.98350367613571,17.4199994653463,0.000504075899257589,8.67798382979091E-5,0.25,-7.98213615741752E-8,4.48574498013468E-5,-1.83164040445217E-8,163.5496979,163.5496979,99.6091461181641,99.6091461181641,57.0768593597945,20.5745286177958,25.186911,0,0,0,40,4374,166.27555,99.6091461181641,,,,,,,,,,,,,0,,,,0.00245,,,,,,163.5496979,,,,
,29171802.73,167.0266724,99.6091461181641,4.38199480729785E-5,3.61590799691441E-7,1,0.999253354069792,40.0298881530762,2.00759136042182,17.3799991607666,0.000500501823301751,8.52250044375732E-5,0.25,-1.56554583978923E-7,4.40153184696362E-5,-9.82443460638159E-8,167.0266724,167.0266724,99.6091461181641,99.6091461181641,56.9799374234099,20.5630900884869,26.325863,0,0,0,40,4374,169.75655,99.6091461181641,,,,,,,,,,,,,0,,,,-0.0049,,,,,,167.0266724,,,,
,29171941.905,170.5085602,99.6091461181641,4.28194875160715E-5,4.34391993083163E-7,1,0.999253354069792,40.0298881530762,2.00711200311073,17.3799991607666,0.00048888431442173,8.34297444457663E-5,0.25,-1.35847091840087E-7,4.30061382505304E-5,-8.03516913688146E-8,170.5085602,170.5085602,99.6091461181641,99.6091461181641,57.2433462343907,20.5676438305339,25.566563,0,0,0,40,4374,173.2475,99.6091461181641,,,,,,,,,,,,,0,,,,-0.0049,,,,,,170.5085602,,,,
,29172083.18,174.0499268,99.6091461181641,4.20595233306501E-5,3.79844550672589E-7,1,0.999253354069792,40.0298881530762,2.00742608021282,17.3799991607666,0.000480377111361813,8.11079214016246E-5,0.25,-2.06016822289699E-7,4.22386430558665E-5,-1.53276688634051E-7,174.0499268,174.0499268,99.6091461181641,99.6091461181641,57.1745629246983,20.5668857809481,26.325863,0,0,0,40,4374,176.78215,99.6091461181641,,,,,,,,,,,,,0,,,,0,,,,,,174.0499268,,,,
,29172202.125,177.0130005,99.6091461181641,4.08502967130847E-5,3.85668364293421E-7,1,0.999253354069792,40.0298881530762,2.0080515657052,17.3300001770258,0.000467033175401677,7.66704696164954E-5,0.25,-3.84882197583935E-7,4.10209376412485E-5,-3.35554021640018E-7,176.9838715,177.0421295,99.6091461181641,99.6091461181641,57.3215090863138,20.5610903904177,25.946213,0,0,0,40,4374,179.7561,99.6091461181641,,,,,,,,,,,,,0,,,,0,,,,,,177.0130005,,,,
,29172343.79,180.54097745,99.6091461181641,4.03609641830547E-5,3.25417483079996E-7,1,0.999253354069792,40.0298881530762,2.00759953321694,17.3300001770258,0.000460304469615016,8.14046174863249E-5,0.25,1.18500372602428E-7,4.05247005664714E-5,1.68024024626665E-7,180.5084381,180.5735168,99.6091461181641,99.6091461181641,57.3480844559676,20.5674502791883,25.946213,0,0,0,40,4374,183.30085,99.6091461181641,,,,,,,,,,,,,0,,,,0,,,,,,180.54097745,,,,
,29172483.765,184.0353088,99.6091461181641,3.90238154029508E-5,3.30509583514022E-7,1,0.999253354069792,40.0298881530762,2.00752518180183,17.3300001770258,0.000445159526423739,7.7733599111634E-5,0.25,3.13105735023331E-8,3.91781051686391E-5,7.76954648635128E-8,184.0353088,184.0353088,99.6091461181641,99.6091461181641,57.085457273506,20.5665403974154,25.566563,0,0,0,40,4374,186.8015,99.6091461181641,,,,,,,,,,,,,0,,,,0.0049,,,,,,184.0353088,,,,
touchdown = 11.0799996182322 mm,29172619.39,187.4115448,99.6091461181641,3.8626624015625E-5,4.14714969290831E-7,1,0.999253354069792,40.0298881530762,1.98390543869168,17.2799993306398,0.000436064201515677,7.35946577713361E-5,0.25,-1.87433496295232E-7,3.87756000781263E-5,-1.43422574290711E-7,187.4115448,187.4115448,99.6091461181641,99.6091461181641,57.0010413934291,20.5690149466756,25.946213,0,0,0,40,4374,190.20595,99.6091461181641,,,,,,,,,,,,,0,,,,0,,,,,,187.4115448,,,,
,29172744.585,190.5589905,99.6091461181641,3.77133859872383E-5,3.85995255768109E-7,1,0.999253354069792,40.0298881530762,1.98370302689677,17.2799993306398,0.000426383353526435,6.7743346018687E-5,0.25,-5.45417831024715E-7,3.78555625356987E-5,-5.04699067798923E-7,190.5589905,190.5589905,99.6091461181641,99.6091461181641,57.2581971762561,20.5750538717256,26.705515,0,0,0,40,4374,193.3496,99.6091461181641,,,,,,,,,,,,,0,,,,-0.0049,,,,,,190.5589905,,,,
,29172883.99,194.0081024,99.6091461181641,3.70763474143912E-5,3.45515655605539E-7,1,0.999253354069792,40.0298881530762,1.98385372908413,17.2799993306398,0.000418774326096619,6.88520742707585E-5,0.25,-3.3526966430328E-7,3.721187322228E-5,-2.95395243023462E-7,194.0081024,194.0081024,99.6091461181641,99.6091461181641,56.9596150819099,20.5758527058281,25.946213,0,0,0,40,4374,196.84005,99.6091461181641,,,,,,,,,,,,,0,,,,0,,,,,,194.0081024,,,,
touchdown = 11.0299997031689 mm,29173035.485,197.7723846,99.6091461181641,3.61471896648369E-5,3.28292854431219E-7,1,0.999253354069792,40.0298881530762,1.9839447345065,17.2199998050928,0.000407747505318875,7.00072876486818E-5,0.25,-7.00041999932696E-8,3.62747122555886E-5,-3.11442620492633E-8,197.7723846,197.7723846,99.6091461181641,99.6091461181641,56.9385111118906,20.5688740632847,26.705515,0,0,0,40,4374,200.6547,99.6091461181641,,,,,,,,,,,,,0,,,,0,,,,,,197.7723846,,,,
,29173167.865,201.0870285,99.6091461181641,3.53987084163872E-5,3.7412812027749E-7,1,0.999253354069792,40.0298881530762,1.98390775571614,17.2199998050928,0.000399549789009325,6.68517256921362E-5,0.25,-2.18333541943332E-7,3.55199798672439E-5,-1.81561039656545E-7,201.0541229,201.1199341,99.6091461181641,99.6091461181641,57.190195495083,20.5715547176598,26.705515,0,0,0,40,4374,203.96405,99.6091461181641,,,,,,,,,,,,,0,,,,-0.00245,,,,,,201.0870285,,,,
,29173306.07,204.5627136,99.6091461181641,3.51989738321878E-5,3.76514764079502E-7,1,0.999253354069792,40.0298881530762,1.98391081794404,17.2199998050928,0.000397528416620464,6.48709781609408E-5,0.25,-3.57915192530644E-7,3.53157350868885E-5,-3.22565456504505E-7,204.5627136,204.5627136,99.6091461181641,99.6091461181641,57.1049979864868,20.5729464766552,26.705515,0,0,0,40,4374,207.4231,99.6091461181641,,,,,,,,,,,,,0,,,,-0.0049,,,,,,204.5627136,,,,
touchdown = 10.9799997881055 mm,29173452.72,208.2092896,99.6091461181641,3.38800787883803E-5,3.55401542531297E-7,1,0.999253354069792,40.0298881530762,1.98370788064027,17.1799995005131,0.000382226396218776,6.42914687708905E-5,0.25,-1.78314959259103E-7,3.3988245011275E-5,-1.4447625332752E-7,208.2092896,208.2092896,99.6091461181641,99.6091461181641,57.0909286731407,20.5707829437555,27.085165,0,0,0,40,4374,211.0988,99.6091461181641,,,,,,,,,,,,,0,,,,-0.00245,,,,,,208.2092896,,,,
,29173587.745,211.5627136,99.6091461181641,3.34150395644389E-5,3.55250387763858E-7,1,0.999253354069792,40.0298881530762,1.98360560565755,17.1900000423193,0.000376121968747186,6.79942368654578E-5,0.25,2.32547700199397E-7,3.35176108180987E-5,2.66540486404896E-7,211.5627136,211.5627136,99.6091461181641,99.6091461181641,57.1651833824676,20.5751704692186,26.705515,0,0,0,40,4374,214.4752,99.6091461181641,,,,,,,,,,,,,0,,,,0.0049,,,,,,211.5627136,,,,
,29173726,215.0329437,99.6091461181641,3.27046750156047E-5,3.5641013790415E-7,1,0.999253354069792,40.0298881530762,1.9835020109058,17.1799995005131,0.000369029610892867,6.0982531299733E-5,0.25,-2.64785047010182E-7,3.28017722996514E-5,-2.33633003838382E-7,215.0329437,215.0329437,99.6091461181641,99.6091461181641,57.1651833824676,20.5747140276705,26.705515,0,0,0,40,4374,217.93705,99.6091461181641,,,,,,,,,,,,,0,,,,0.00245,,,,,,215.0329437,,,,
touchdown = 10.9299998730421 mm,29173870.61,218.6518555,99.6091461181641,3.19384240778158E-5,4.50062354408879E-7,1,0.999253354069792,40.0298881530762,1.98344980242336,17.119999974966,0.000359784856741193,6.26901097343548E-5,0.25,2.11956177378282E-8,3.20290956374904E-5,5.18206497716298E-8,218.6518555,218.6518555,99.6091461181641,99.6091461181641,56.679010443506,20.572891157887,26.705515,0,0,0,40,4374,221.56485,99.6091461181641,,,,,,,,,,,,,0,,,,0,,,,,,218.6518555,,,,
,29174008.315,222.0632019,99.6091461181641,3.18265167822169E-5,4.29613505820488E-7,1,0.999253354069792,40.0298881530762,1.98336194173768,17.119999974966,0.000359224385730197,5.81011927414869E-5,0.25,-3.65323558270216E-7,3.19135651554373E-5,-3.36427340913563E-7,222.0632019,222.0632019,99.6091461181641,99.6091461181641,56.9791557948906,20.5758209387913,26.325863,0,0,0,40,4374,225.00595,99.6091461181641,,,,,,,,,,,,,0,,,,0,,,,,,222.0632019,,,,
,29174145.86,225.5035248,99.6091461181641,3.10078035995885E-5,3.40011800398295E-7,1,0.999253354069792,40.0298881530762,1.98339364849387,17.119999974966,0.000349406275992693,5.97229036693638E-5,0.25,-7.82093401455052E-8,3.10887215895914E-5,-4.98244672964663E-8,225.5035248,225.5035248,99.6091461181641,99.6091461181641,57.2605420618137,20.5752232977631,26.325863,0,0,0,40,4374,228.4603,99.6091461181641,,,,,,,,,,,,,0,,,,0,,,,,,225.5035248,,,,
touchdown = 10.8799999579787 mm,29174287.005,229.0449829,99.6091461181641,3.05557339067811E-5,3.83360202489557E-7,1,0.999253354069792,40.0298881530762,1.98366587957724,17.0799996703863,0.000345272277106511,5.33395108863565E-5,0.25,-5.66033780721949E-7,3.06322088054016E-5,-5.39788246560044E-7,229.0449829,229.0449829,99.6091461181641,99.6091461181641,56.922878541506,20.5675991693428,27.085165,0,0,0,40,4374,231.997,99.6091461181641,,,,,,,,,,,,,0,,,,-0.00245,,,,,,229.0449829,,,,
,29174428.795,232.5405121,99.6091461181641,2.97076912973757E-5,3.24315496674224E-7,1,0.999253354069792,40.0298881530762,1.98365282608643,17.0799996703863,0.00033455262708826,5.81610914741339E-5,0.25,1.03128174457943E-8,2.97779615820122E-5,3.67341417165675E-8,232.5405121,232.5405121,99.6091461181641,99.6091461181641,57.0338697912368,20.5724352520956,27.085165,0,0,0,40,4374,235.54305,99.6091461181641,,,,,,,,,,,,,0,,,,0,,,,,,232.5405121,,,,
,29174567.82,236.0442047,99.6091461181641,2.90810017385518E-5,4.22253963674661E-7,1,0.999253354069792,40.0298881530762,1.98347032570206,17.0799996703863,0.000328014456910796,5.35344622564652E-5,0.25,-2.90330485481225E-7,2.91465244597004E-5,-2.65596502259602E-7,236.0442047,236.0442047,99.6091461181641,99.6091461181641,57.0565370182945,20.5741472519255,27.085165,0,0,0,40,4374,239.0329,99.6091461181641,,,,,,,,,,,,,0,,,,0,,,,,,236.0442047,,,,
touchdown = 10.8300000429153 mm,29174704.285,239.4529266,99.6091461181641,2.85826895401802E-5,4.36912640808116E-7,1,0.999253354069792,40.0298881530762,1.98393637444485,17.0200001448393,0.000322188301508262,5.40044996775996E-5,0.25,-1.62229974539496E-7,2.86435903860774E-5,-1.3804831686857E-7,239.4529266,239.4529266,99.6091461181641,99.6091461181641,56.9408559974483,20.5640263106269,27.085165,0,0,0,40,4374,242.45795,99.6091461181641,,,,,,,,,,,,,0,,,,0.00245,,,,,,239.4529266,,,,
,29174828.775,242.51828,99.6091461181641,2.8695247197339E-5,4.09903721504732E-7,1,0.999253354069792,40.0298881530762,1.98368660168602,17.0200001448393,0.000323344645224751,5.44293623147268E-5,0.25,-1.42555737835875E-7,2.87532962351169E-5,-1.18595392690514E-7,242.51828,242.51828,99.6091461181641,99.6091461181641,56.9674313671022,20.5713795325229,27.085165,0,0,0,40,4374,245.56845,99.6091461181641,,,,,,,,,,,,,0,,,,-0.0049,,,,,,242.51828,,,,
,29174969.315,246.0263672,99.6091461181641,2.75482512706879E-5,4.27011941980735E-7,1,0.999253354069792,40.0298881530762,1.98374617068619,17.0200001448393,0.000310230434440204,5.31734521351088E-5,0.25,-5.43293794158046E-8,2.76005202409548E-5,-3.15496098090638E-8,246.0263672,246.0263672,99.6091461181641,99.6091461181641,56.994006736756,20.5697022656271,27.844467,0,0,0,40,4374,249.09625,99.6091461181641,,,,,,,,,,,,,0,,,,-0.0049,,,,,,246.0263672,,,,
,29175106.03,249.4142914,99.6091461181641,,,2,,,,16.990000127852,,,,,,,249.4142914,249.4142914,99.6091461181641,99.6091461181641,,,27.085165,,,,-99999999,4374,252.5186,99.6091461181641,,,,,,,,,,,,,,,,,,,,,,,249.4142914,,,,
,29175230.695,252.5268707,99.6091461181641,2.64216352239378E-5,3.66042701423617E-7,1,0.999253354069792,40.0298881530762,1.99513040666684,16.9799998402596,0.00029919071067875,5.07727096144753E-5,0.25,-9.50796458708589E-8,2.64657446659777E-5,-7.39650777823155E-8,252.5268707,252.5268707,99.6091461181641,99.6091461181641,57.220679007333,20.5603020669362,27.464817,0,0,0,40,4374,255.6393,99.6091461181641,,,,,,,,,,,,,0,,,,0,,,,,,252.5268707,,,,
,29175370.12,256.0186462,99.6091461181641,2.63350640318284E-5,3.90748717074849E-7,1,0.999253354069792,40.0298881530762,1.99524091007582,16.9799998402596,0.000297907517837743,5.22280912514423E-5,0.25,4.92050591209879E-8,2.63756568562464E-5,7.01395439670753E-8,256.0186462,256.0186462,99.6091461181641,99.6091461181641,57.0096393071407,20.5625723712738,27.464817,0,0,0,40,4374,259.1467,99.6091461181641,,,,,,,,,,,,,0,,,,0,,,,,,256.0186462,,,,
,29175521.88,259.7856445,99.6091461181641,,,2,,,,16.9299996709824,,,,,,,259.7856445,259.7856445,99.6091461181641,99.6091461181641,,,27.464817,,,,-99999999,4374,262.9193,99.6091461181641,,,,,,,,,,,,,,,,,,,,,,,259.7856445,,,,
,29175649.21,263.0058289,99.6091461181641,2.48943394320936E-5,3.50071239701851E-7,1,0.999253354069792,40.0298881530762,1.98391508261395,16.9099997729063,0.000280404197731049,4.68383205804177E-5,0.25,-1.5307839088093E-7,2.49266810083944E-5,-1.34180034766824E-7,263.0058289,263.0058289,99.6091461181641,99.6091461181641,57.0604451608906,20.5639260624094,27.844467,0,0,0,40,4374,266.12885,99.6091461181641,,,,,,,,,,,,,0,,,,-0.00245,,,,,,263.0058289,,,,
,29175791.515,266.5507813,99.6091461181641,2.44287661670854E-5,4.31009880139326E-7,1,0.999253354069792,40.0298881530762,1.98373424281128,16.9099997729063,0.000275782499062051,4.20233462504287E-5,0.25,-4.99201458004477E-7,2.44576757115917E-5,-4.81342355626886E-7,266.5507813,266.5507813,99.6091461181641,99.6091461181641,57.0596635323714,20.568088396752,27.464817,0,0,0,40,4374,269.6854,99.6091461181641,,,,,,,,,,,,,0,,,,0.00245,,,,,,266.5507813,,,,
,29175940.33,270.2269897,99.6091461181641,,,2,,,,16.879999755919,,,,,,,270.2269897,270.2269897,99.6091461181641,99.6091461181641,,,27.844467,,,,-99999999,4374,273.4048,99.6091461181641,,,,,,,,,,,,,,,,,,,,,,,270.2269897,,,,
,29176073.865,273.5439758,99.6091461181641,2.3525524742423E-5,4.69305041442092E-7,1,0.999253354069792,40.0298881530762,1.98364389753908,16.8699994683266,0.000264065578679695,4.87771000624247E-5,0.25,2.59555325234487E-7,2.35469314768197E-5,2.77008393040668E-7,273.5439758,273.5439758,99.6091461181641,99.6091461181641,57.0393411908714,20.5675928493417,27.844467,0,0,0,40,4374,276.7598,99.6091461181641,,,,,,,,,,,,,0,,,,0,,,,,,273.5439758,,,,
,29176212.625,277.0355225,99.6091461181641,2.28568505252135E-5,3.94778832104467E-7,1,0.999253354069792,40.0298881530762,1.98373836702548,16.8699994683266,0.000256322259539419,4.86409294271665E-5,0.25,3.63937180245347E-7,2.28747131426499E-5,3.80702945259683E-7,277.0355225,277.0355225,99.6091461181641,99.6091461181641,57.3183825722368,20.5672787785084,27.464817,0,0,0,40,4374,280.21605,99.6091461181641,,,,,,,,,,,,,0,,,,-0.00245,,,,,,277.0355225,,,,
,29176355.72,280.6010437,99.6091461181641,,,2,,,,16.820000230372,,,,,,,280.6010437,280.6010437,99.6091461181641,99.6091461181641,,,27.844467,,,,-99999999,4374,283.7834,99.6091461181641,,,,,,,,,,,,,,,,,,,,,,,280.6010437,,,,
,29176473.845,283.5211487,99.6091461181641,2.23907813587233E-5,3.83273991470735E-7,1,0.999253354069792,40.0298881530762,2.00777509384416,16.8099999427795,0.000255464198388309,3.93935357464302E-5,0.25,-4.16418421233008E-7,2.24036255419507E-5,-4.00951816963362E-7,283.5211487,283.5211487,99.6091461181641,99.6091461181641,57.1182856713137,20.5589450095955,28.224119,0,0,0,40,4374,286.73615,99.6091461181641,,,,,,,,,,,,,0,,,,-0.0049,,,,,,283.5211487,,,,
,29176614.46,287.0328979,99.6091461181641,2.14151941156513E-5,4.68943942298836E-7,1,0.999253354069792,40.0298881530762,2.00785308702377,16.8099999427795,0.000243576161279626,4.19181412882669E-5,0.25,-2.48169803201663E-8,2.14245218058351E-5,-1.00319400796011E-8,287.0328979,287.0328979,99.6091461181641,99.6091461181641,57.2370932062368,20.5585244576716,28.224119,0,0,0,40,4374,290.27645,99.6091461181641,,,,,,,,,,,,,0,,,,0,,,,,,287.0328979,,,,
,29176754.66,290.5465393,99.6091461181641,2.16439415194618E-5,4.11757233995103E-7,1,0.999253354069792,40.0298881530762,2.00777759757863,16.8099999427795,0.000246678975637213,3.92377804547303E-5,0.25,-2.99390093186651E-7,2.16508312340936E-5,-2.84742697954511E-7,290.5465393,290.5465393,99.6091461181641,99.6091461181641,57.1995750373137,20.5585058374504,27.464817,0,0,0,40,4374,293.7774,99.6091461181641,,,,,,,,,,,,,0,,,,-0.00245,,,,,,290.5465393,,,,
,29176874.32,293.5010071,99.6091461181641,2.13253021885091E-5,4.58195111868943E-7,1,0.999253354069792,40.0298881530762,1.98406969458108,16.7399998754263,0.00023925715822956,4.41347110034854E-5,0.25,2.31365688146366E-7,2.13294788585568E-5,2.4575900435946E-7,293.5010071,293.5010071,99.6091461181641,99.6091461181641,56.7657712091406,20.5618907231006,28.224119,0,0,0,40,4374,296.7869,99.6091461181641,,,,,,,,,,,,,0,,,,0,,,,,,293.5010071,,,,
,29177016.325,297.0395508,99.6091461181641,2.03553535807464E-5,4.26754333960524E-7,1,0.999253354069792,40.0298881530762,1.98399970699219,16.7399998754263,0.000229702898889632,3.42448150416356E-5,0.25,-4.79732630455134E-7,2.03572311984003E-5,-4.66269794419386E-7,297.0395508,297.0395508,99.6091461181641,99.6091461181641,56.973684395256,20.5630699027508,27.844467,0,0,0,40,4374,300.3473,99.6091461181641,,,,,,,,,,,,,0,,,,0,,,,,,297.0395508,,,,
,29177156.265,300.5013123,99.6091461181641,2.04363648846567E-5,4.24694217146912E-7,1,0.999253354069792,40.0298881530762,1.98390374197087,16.7399998754263,0.00023004263703155,3.74646179000738E-5,0.25,-2.06526352240984E-7,2.04355391927099E-5,-1.93149585576817E-7,300.5013123,300.5013123,99.6091461181641,99.6091461181641,57.0979633298137,20.5644644481008,28.224119,0,0,0,40,4374,303.8479,99.6091461181641,,,,,,,,,,,,,0,,,,0.00245,,,,,,300.5013123,,,,
,29177297.675,304.0400085,99.6091461181641,1.98741341171737E-5,4.02046801284323E-7,1,0.999253354069792,40.0298881530762,1.98388842780821,16.6999995708466,0.00022417036929884,3.36214072980755E-5,0.25,-4.50561083169234E-7,1.98709829836419E-5,-4.37661758462045E-7,304.0400085,304.0400085,99.6091461181641,99.6091461181641,57.4450063923522,20.5605212180539,28.224119,0,0,0,40,4374,307.3896,99.6091461181641,,,,,,,,,,,,,0,,,,0,,,,,,304.0400085,,,,
,29177439.07,307.5196533,99.6091461181641,1.89432270878835E-5,4.61272684225003E-7,1,0.999253354069792,40.0298881530762,1.9840579837309,16.6999995708466,0.000213231055265011,3.45279414002324E-5,0.25,-2.08310492840799E-7,1.89377339913482E-5,-1.9619275456112E-7,307.5196533,307.5196533,99.6091461181641,99.6091461181641,57.2902439455445,20.5624790182558,27.844467,0,0,0,40,4374,310.9359,99.6091461181641,,,,,,,,,,,,,0,,,,0.00245,,,,,,307.5196533,,,,
,29177579.58,311.0232544,99.6091461181641,1.92904454241795E-5,3.85780556706485E-7,1,0.999253354069792,40.0298881530762,1.98398334353284,16.6999995708466,0.000217131059916613,3.50025477440093E-5,0.25,-2.25556268934746E-7,1.92824592472377E-5,-2.13345726418164E-7,311.0232544,311.0232544,99.6091461181641,99.6091461181641,56.9963516223137,20.5619768023377,28.603769,0,0,0,40,4374,314.4486,99.6091461181641,,,,,,,,,,,,,0,,,,0,,,,,,311.0232544,,,,
,29177720.35,314.5491943,99.6091461181641,1.90851528930211E-5,4.66065308616906E-7,1,0.999253354069792,40.0298881530762,1.98424641293419,16.6400000452995,0.000214306088086501,3.76008695304615E-5,0.25,4.14625970596782E-8,1.9074703732752E-5,5.32705262876158E-8,314.5491943,314.5491943,99.6091461181641,99.6091461181641,56.9877537086022,20.5610868597913,27.844467,0,0,0,40,4374,317.99005,99.6091461181641,,,,,,,,,,,,,0,,,,-0.0049,,,,,,314.5491943,,,,
,29177861.375,318.0270691,99.6091461181641,1.82201852997389E-5,3.88178975185675E-7,1,0.999253354069792,40.0298881530762,1.98456392879545,16.6400000452995,0.000205599168083466,3.01266851823208E-5,0.25,-4.74016501238561E-7,1.82082881721625E-5,-4.62548671350153E-7,318.0270691,318.0270691,99.6091461181641,99.6091461181641,57.2949337166599,20.5586059179253,28.224119,0,0,0,40,4374,321.51725,99.6091461181641,,,,,,,,,,,,,0,,,,-0.00245,,,,,,318.0270691,,,,
,29178002.055,321.5158386,99.6091461181641,1.81372637094267E-5,4.56344727259421E-7,1,0.999253354069792,40.0298881530762,1.98441820585762,16.6400000452995,0.000204353357315473,3.15460765015516E-5,0.25,-3.32620908195572E-7,1.81231075573905E-5,-3.21396325709262E-7,321.5158386,321.5158386,99.6091461181641,99.6091461181641,57.1917587521214,20.5600313719781,27.844467,0,0,0,40,4374,325.05505,99.6091461181641,,,,,,,,,,,,,0,,,,0,,,,,,321.5158386,,,,
,29178141.895,325.0218201,99.6091461181641,1.75864822008996E-5,4.61835915877117E-7,1,0.999253354069792,40.0298881530762,1.98454533584677,16.5699999779463,0.000198087689327852,3.08617631590746E-5,0.25,-2.97856801883368E-7,1.75705783499669E-5,-2.87084789288386E-7,325.0218201,325.0218201,99.6091461181641,99.6091461181641,56.9361662263329,20.557449044867,28.983419,0,0,0,40,4374,328.559,99.6091461181641,,,,,,,,,,,,,0,,,,-0.0049,,,,,,325.0218201,,,,
,29178285.96,328.548645,99.6091461181641,1.71985824631078E-5,4.26345822982538E-7,1,0.999253354069792,40.0298881530762,1.98445440134589,16.5699999779463,0.00019403838793655,2.81422192905421E-5,0.25,-4.72286099875232E-7,1.71810175925273E-5,-4.61652570475602E-7,328.548645,328.548645,99.6091461181641,99.6091461181641,57.1706547821022,20.5576819494234,28.224119,0,0,0,40,4374,332.15035,99.6091461181641,,,,,,,,,,,,,0,,,,0.0049,,,,,,328.548645,,,,
,29178425.84,332.024231,99.6091461181641,1.67940881117482E-5,3.78812916780466E-7,1,0.999253354069792,40.0298881530762,1.9843173868674,16.5699999779463,0.000189138126036703,2.92146435202297E-5,0.25,-3.06127028353141E-7,1.67748152161989E-5,-2.95982560924001E-7,332.024231,332.024231,99.6091461181641,99.6091461181641,57.1198489283522,20.5604247713137,28.603769,0,0,0,40,4374,335.6785,99.6091461181641,,,,,,,,,,,,,0,,,,0,,,,,,332.024231,,,,
,29178564.35,335.5089111,99.6091461181641,1.67727986549471E-5,3.80079826768825E-7,1,0.999253354069792,40.0298881530762,2.00798569580063,16.5199991315603,0.000191459858055651,2.69963470975451E-5,0.25,-5.26695922420004E-7,1.67516548276969E-5,-5.16353600552229E-7,335.5089111,335.5089111,99.6091461181641,99.6091461181641,56.8478422036599,20.55535249606,28.603769,0,0,0,40,4374,339.14455,99.6091461181641,,,,,,,,,,,,,0,,,,0.00245,,,,,,335.5089111,,,,
,29178705.19,339.0205688,99.6091461181641,1.66769029594395E-5,4.01702479036942E-7,1,0.999253354069792,40.0298881530762,2.00808901339796,16.5199991315603,0.000190025319643859,2.87237036249704E-5,0.25,-3.57654736438446E-7,1.66537678981843E-5,-3.47646677870696E-7,339.0205688,339.0205688,99.6091461181641,99.6091461181641,57.0198004778906,20.5570042340137,28.603769,0,0,0,40,4374,342.68715,99.6091461181641,,,,,,,,,,,,,0,,,,-0.00245,,,,,,339.0205688,,,,
,29178846.1,342.5201416,99.6091461181641,1.59573991369355E-5,5.1354861843753E-7,1,0.999253354069792,40.0298881530762,2.00793336789261,16.5199991315603,0.000181902358497423,2.68398492274533E-5,0.25,-3.98451317216715E-7,1.59333819306993E-5,-3.88845565510197E-7,342.5201416,342.5201416,99.6091461181641,99.6091461181641,57.2112994651022,20.5575417802647,28.603769,0,0,0,40,4374,346.22,99.6091461181641,,,,,,,,,,,,,0,,,,0,,,,,,342.5201416,,,,
,29178966.525,345.5158386,99.6091461181641,1.55832583794531E-5,3.91693890305914E-7,1,0.999253354069792,40.0298881530762,2.00802491811756,16.4599996060133,0.000176802758580337,3.09692467479999E-5,0.25,3.03891471890309E-8,1.55579800135198E-5,3.90515216619283E-8,345.5158386,345.5158386,99.6091461181641,99.6091461181641,56.9643048530253,20.5533090151114,28.603769,0,0,0,40,4374,349.2491,99.6091461181641,,,,,,,,,,,,,0,,,,-0.00245,,,,,,345.5158386,,,,
,29179135.845,349.0025635,99.6091461181641,1.55267328993596E-5,3.83168374997098E-7,1,0.999253354069792,40.0298881530762,2.00800255120282,16.4599996060133,0.000176809276377672,2.69802757294749E-5,0.25,-3.10946012488417E-7,1.54999018899539E-5,-3.01762779758487E-7,349.0025635,349.0025635,99.6091461181641,99.6091461181641,57.1909771236022,20.5541840383831,28.603769,0,0,0,40,4374,350.74075,99.6091461181641,,,,,,,,,,,,,0,,,,-0.0049,,,,,,349.0025635,,,,
,29179418.67,349.7914734,99.6091461181641,1.57679941279599E-5,4.52027647139279E-7,1,0.999253354069792,40.0298881530762,2.00810512871981,16.4599996060133,0.000179247056525117,2.92107421169635E-5,0.25,-1.56226443440373E-7,1.57402370322891E-5,-1.47174461616333E-7,349.7914734,349.7914734,99.6091461181641,99.6091461181641,57.2394380917945,20.5546558740035,28.983419,0,0,0,40,4369,350.7563,99.6091461181641,,,,,,,,,,,,,0,,,,0,,,,,,349.7914734,,,,