File: data/looselyPackedNP/sc-ios-11/ppms/rawdata/ES_S14_HYST_200K.DAT
[Header]
; VSM Data File (default extension .dat)
; Copyright (c) 2003-2013, Quantum Design, Inc. All rights reserved.
TITLE,
FILEOPENTIME,29136923.63,12/04/2018,1:36 pm
BYAPP,VSM,2.0,2.0
INFO,PPMS VSM Option Release 1.4.10 Build 1,APPNAME
INFO,Quantum Design Linear Motor Servo Controller,MOTOR_MODULE_NAME
INFO,3101-100 M1,MOTOR_HW_VERSION
INFO,MMC1014,MOTOR_SERIAL_NUMBER
INFO,SRV No X-over 01.03.11,MOTOR_SOFTWARE_VERSION
INFO,Quantum Design VSM Detection Module,VSM_MODULE_NAME
INFO,3101-150 F0,VSM_HW_VERSION
INFO,VSM707,VSM_SERIAL_NUMBER
INFO,VSM No X-over 01.02.05 May 20 2008 13:51:47,VSM_SOFTWARE_VERSION
INFO,704,PREAMP_SERIAL_NUMBER
INFO,822,COIL_SERIAL_NUMBER
INFO,0,MOMENT_UNITS
INFO,Iron Oxide Spheres,SAMPLE_MATERIAL
INFO,10 nm diameter, collaboration Mainz,SAMPLE_COMMENT
INFO,,SAMPLE_MASS
INFO,,SAMPLE_VOLUME
INFO,,SAMPLE_MOLECULAR_WEIGHT
INFO,,SAMPLE_SIZE
INFO,,SAMPLE_SHAPE
DATATYPE,COMMENT,1
DATATYPE,TIME,2
STARTUPAXIS,X,2
STARTUPAXIS,Y1,5
[Data]
Comment,Time Stamp (sec),Temperature (K),Magnetic Field (Oe),Moment (emu),M. Std. Err. (emu),Transport Action,Averaging Time (sec),Frequency (Hz),Peak Amplitude (mm),Center Position (mm),Coil Signal' (mV),Coil Signal" (mV),Range (mV),M. Quad. Signal (emu),M. Raw' (emu),M. Raw" (emu),Min. Temperature (K),Max. Temperature (K),Min. Field (Oe),Max. Field (Oe),Mass (grams),Motor Lag (deg),Pressure (Torr),VSM Status (code),Motor Status (code),Measure Status (code),Measure Count,PPMS Status (code),System Temp. (K),System Field (Oe),Sample Position (deg),Bridge 1 Resistance (ohms),Bridge 1 Excitation (에),Bridge 2 Resistance (ohms),Bridge 2 Excitation (에),Bridge 3 Resistance (ohms),Bridge 3 Excitation (에),Bridge 4 Resistance (ohms),Bridge 4 Excitation (에),Signal 1 Vin (V),Signal 2 Vin (V),Digital Inputs (code),Drive 1 Iout (mA),Drive 1 Ipower (W),Drive 2 Iout (mA),Drive 2 Ipower (W),Pressure (),Map 20 (),Map 21 (),Map 22 (),Map 23 (),Map 24 (),Map 25 (),Map 26 (),Map 27 (),Map 28 (),Map 29 ()
,29136939.61,200.2510223,-0.502384543418884,,,2,,,,17.2399997031689,,,,,,,200.2510223,200.2510223,-0.502384543418884,-0.502384543418884,,,25.946213,,,,-99999999,4433,200.2158,-0.502384543418884,,,,,,,,,,,,,,,,,,,,,,,200.2510223,,,,
,29137083.305,200.1733551,4665.26000976562,0.000130128338321703,4.01513640941137E-7,1,0.999253354069792,40.0298881530762,1.98423623653098,17.2199998050928,0.00146633319479623,0.00026142123669402,0.25,5.79573417176146E-7,0.000130576126804815,7.22769408518761E-7,200.1733551,200.1733551,4660.169921875,4670.35009765625,56.5054889122367,20.5634397168733,25.946213,0,0,0,40,4449,200.0058,4665.26000976562,,,,,,,,,,,,,0,,,,0,,,,,,200.1733551,,,,
,29137180.61,200.1061554,9526.3564453125,0.000112150086914097,5.84105507609945E-7,1,0.999253354069792,40.0298881530762,1.98409393364119,17.2199998050928,0.00126459740119311,0.000219915961656424,0.25,2.31296967081673E-8,0.000112536792999939,1.44789188329166E-7,200.1061554,200.1061554,9521.6474609375,9531.0654296875,56.8400259184676,20.5687739824895,25.946213,0,0,0,40,4449,199.9279,9526.3564453125,,,,,,,,,,,,,0,,,,0,,,,,,200.1061554,,,,
,29137279.535,200.0576324,14471.619140625,8.9325710713147E-5,6.62496858163047E-7,1,0.999253354069792,40.0298881530762,1.9840628465454,17.2199998050928,0.00100810124269393,0.000170071492462058,0.25,-4.32448937916851E-7,8.96343679718864E-5,-3.37243363475473E-7,200.0576324,200.0576324,14469.2021484375,14474.0361328125,56.6680676442368,20.573269530011,25.946213,0,0,0,40,4449,199.90315,14471.619140625,,,,,,,,,,,,,0,,,,-0.0049,,,,,,200.0576324,,,,
,29137378.7,200.0270844,19426.2822265625,6.57292958040808E-5,7.79260421022807E-7,1,0.999253354069792,40.0298881530762,1.98375528933908,17.2199998050928,0.000740162349008371,0.000133926735353931,0.25,4.6241810459102E-7,6.59556569509412E-5,5.35052727176171E-7,200.0270844,200.0270844,19421.498046875,19431.06640625,56.9486722826406,20.5765375453821,25.946213,0,0,0,40,4449,199.8898,19426.2822265625,,,,,,,,,,,,,0,,,,-0.0049,,,,,,200.0270844,,,,
,29137476.36,200.0070038,24309.033203125,4.15560474433402E-5,8.8655558671096E-7,1,0.999253354069792,40.0298881530762,1.98374583330716,17.2199998050928,0.000467877376953924,8.50979941599156E-5,0.25,3.30199008131089E-7,4.16991590637586E-5,3.76171030551599E-7,200.0070038,200.0070038,24304.0390625,24314.02734375,56.7657712091406,20.5762704662109,25.566563,0,0,0,40,4449,199.8953,24309.033203125,,,,,,,,,,,,,0,,,,0.0049,,,,,,200.0070038,,,,
,29137578.985,199.9968872,29439.1171875,1.60358938965254E-5,1.19713231554201E-6,1,0.999253354069792,40.0298881530762,1.98365518234155,17.2199998050928,0.000179654200049543,3.79341447974088E-5,0.25,5.79593013004696E-7,1.60906424313292E-5,5.98860440674132E-7,199.9968872,199.9968872,29431.451171875,29446.783203125,57.098744958333,20.5802582704701,25.946213,0,0,0,40,4449,199.90135,29439.1171875,,,,,,,,,,,,,0,,,,0,,,,,,199.9968872,,,,
,29137677.915,199.9941101,34381.763671875,-1.08023986020756E-5,1.03065223476635E-6,1,0.999253354069792,40.0298881530762,1.9835214738996,17.2199998050928,-0.000121372932711951,-2.34872805761999E-5,0.25,-2.07283546588658E-7,-1.08394813079612E-5,-2.19607695964249E-7,199.9941101,199.9941101,34374.45703125,34389.0703125,57.0745144742368,20.5805516944077,26.325863,0,0,0,40,4449,199.90795,34381.763671875,,,,,,,,,,,,,0,,,,0.00245,,,,,,199.9941101,,,,
,29137775.705,199.9957733,39270.98828125,-3.46581960385775E-5,1.42260921952426E-6,1,0.999253354069792,40.0298881530762,1.98359527588191,17.2199998050928,-0.000392856997199382,-5.55946468513455E-5,0.25,1.08800132365181E-6,-3.47790618087472E-5,1.05458860932699E-6,199.9957733,199.9957733,39265.421875,39276.5546875,57.4278105649292,20.5832803847978,26.325863,0,0,0,40,4449,199.912,39270.98828125,,,,,,,,,,,,,0,,,,-0.00245,,,,,,199.9957733,,,,
,29137874.57,199.9956207,44211.361328125,-6.40244578573638E-5,1.66899843596403E-6,1,0.999253354069792,40.0298881530762,1.98358552448975,17.2199998050928,-0.00071956989727294,-0.000138144587998513,0.25,-1.13426517584528E-6,-6.42443855788129E-5,-1.20670885719917E-6,199.9956207,199.9956207,44208.8125,44213.91015625,56.7110572127945,20.5811590516034,25.946213,0,0,0,40,4449,199.9141,44211.361328125,,,,,,,,,,,,,0,,,,0,,,,,,199.9956207,,,,
,29137971.815,199.9964752,49072.001953125,-8.70774404191399E-5,2.07893875865412E-6,1,0.999253354069792,40.0298881530762,1.98360694018318,17.2199998050928,-0.000984355620381908,-0.000155164116448438,0.25,1.35975702712387E-6,-8.73796849683673E-5,1.27144238802998E-6,199.9964752,199.9964752,49067.015625,49076.98828125,57.1378263842945,20.5806122990302,25.946213,0,0,0,40,4449,199.9132,49072.001953125,,,,,,,,,,,,,0,,,,-0.0049,,,,,,199.9964752,,,,
,29138071.43,199.9997711,54051.6796875,-0.00011544268338942,2.08059330113532E-6,1,0.999253354069792,40.0298881530762,1.9834589887938,17.2199998050928,-0.00130421095025679,-0.000209742420224305,0.25,1.44329068784794E-6,-0.000115843021414278,1.32522712259621E-6,199.9997711,199.9997711,54049.28125,54054.078125,56.6008475915829,20.5810639241592,26.325863,0,0,0,40,4449,199.91355,54051.6796875,,,,,,,,,,,,,0,,,,-0.00245,,,,,,199.9997711,,,,
,29138171.93,200.0011749,59072.02734375,-0.000140485894549134,2.18381376188626E-6,1,0.999253354069792,40.0298881530762,1.98347016167314,17.2199998050928,-0.00158344820964694,-0.000276530094637016,0.25,-1.32193967967036E-7,-0.000140971107269477,-2.82063919375006E-7,200.0011749,200.0011749,59062.08984375,59081.96484375,56.976810909333,20.5808654886806,25.566563,0,0,0,40,4449,199.9198,59072.02734375,,,,,,,,,,,,,0,,,,0.0049,,,,,,200.0011749,,,,
,29138270,200.0056,63977.06640625,-0.000169280534834202,2.49052118585801E-6,1,0.999253354069792,40.0298881530762,1.98343273708749,17.2199998050928,-0.00191305813536479,-0.000303876108492374,0.25,2.44188275910019E-6,-0.000169867990023299,2.27066051154577E-6,200.0056,200.0056,63969.3125,63984.8203125,56.8931766577752,20.5815031716318,26.325863,0,0,0,40,4449,199.9131,63977.06640625,,,,,,,,,,,,,0,,,,0.00245,,,,,,200.0056,,,,
,29138373.46,200.0074005,69144.953125,-0.000197870754488955,3.32106297108486E-6,1,0.999253354069792,40.0298881530762,1.98355156708351,17.2199998050928,-0.00222922794745014,-0.000395872017900573,0.25,-7.5223513125461E-7,-0.000198553656387858,-9.64368473026274E-7,200.0074005,200.0074005,69137.421875,69152.484375,57.0588819038522,20.5779099219678,26.325863,0,0,0,40,4449,199.90285,69144.953125,,,,,,,,,,,,,0,,,,0.0049,,,,,,200.0074005,,,,
,29138471.095,200.0096893,74027.7421875,-0.000221542946511492,2.93357840560276E-6,1,0.999253354069792,40.0298881530762,1.98368656531325,17.2199998050928,-0.00250061716325354,-0.000417155664102504,0.25,1.47275064603339E-6,-0.000222310050201556,1.24373592701385E-6,200.0096893,200.0096893,74020.2578125,74035.2265625,57.3254172289099,20.5785681347086,25.946213,0,0,0,40,4449,199.8915,74027.7421875,,,,,,,,,,,,,0,,,,0,,,,,,200.0096893,,,,
,29138568.775,200.0103607,78910.7734375,-0.000252553888326815,2.90935772576858E-6,1,0.999253354069792,40.0298881530762,1.9836727572091,17.2199998050928,-0.00284892574580873,-0.000485348398060367,0.25,8.08762928225759E-7,-0.000253427526571486,5.45272913360685E-7,200.0103607,200.0103607,78908.1328125,78913.4140625,56.9689946241406,20.5756542236074,25.566563,0,0,0,40,4449,199.88955,78910.7734375,,,,,,,,,,,,,0,,,,0.00245,,,,,,200.0103607,,,,
,29138668.755,200.0078278,83908.67578125,-0.000280881402663566,2.81368280405622E-6,1,0.999253354069792,40.0298881530762,1.98359035301721,17.2199998050928,-0.00316688382346644,-0.000548202537236107,0.25,1.50477508974936E-7,-0.000281852360326014,-1.44493203776903E-7,200.0078278,200.0078278,83901.140625,83916.2109375,56.9478906541214,20.5788170803251,25.566563,0,0,0,40,4449,199.88025,83908.67578125,,,,,,,,,,,,,0,,,,0,,,,,,200.0078278,,,,
,29138761.61,200.0106659,88549.62109375,-0.000304162147451601,2.02202080030488E-6,1,0.999253354069792,40.0298881530762,1.98370395339731,17.2199998050928,-0.00342731557117604,-0.000606586516753953,0.25,-9.83133852228991E-7,-0.000305212446828897,-1.30584126173902E-6,200.0106659,200.0106659,88544.5390625,88554.703125,56.9205336559483,20.5772412935775,25.566563,0,0,0,40,4449,199.873,88549.62109375,,,,,,,,,,,,,0,,,,0,,,,,,200.0106659,,,,
,29138869.61,200.0068359,86958.55078125,-0.000293220059342382,3.88682689977361E-6,1,0.999253354069792,40.0298881530762,1.98371076753865,17.2199998050928,-0.00330831644572919,-0.000560085400634313,0.25,1.2416215437062E-6,-0.000294234877052461,9.3785137212896E-7,200.0068359,200.0068359,86953.640625,86963.4609375,56.8806706014676,20.5765605726786,25.946213,0,0,0,40,4449,199.86655,86958.55078125,,,,,,,,,,,,,0,,,,-0.0049,,,,,,200.0068359,,,,
,29138963.28,199.999054,82275.48828125,-0.000272459074119642,2.95323241292912E-6,1,0.999253354069792,40.0298881530762,1.98365310298061,17.2199998050928,-0.00307381589889597,-0.000521421939702258,0.25,1.06500775794183E-6,-0.000273401930180937,7.8182102740052E-7,199.999054,199.999054,82270.6796875,82280.296875,57.065134932006,20.5771692968397,25.946213,0,0,0,40,4449,199.8677,82275.48828125,,,,,,,,,,,,,0,,,,-0.0049,,,,,,199.999054,,,,
,29139057.395,199.9942322,77571.328125,-0.00024381016234059,3.17917075715314E-6,1,0.999253354069792,40.0298881530762,1.98365130657566,17.2199998050928,-0.00274860415510904,-0.000478105390047548,0.25,-6.74639717718425E-8,-0.000244652764273764,-3.24942123633892E-7,199.9942322,199.9942322,77566.4453125,77576.2109375,56.9267866841022,20.5790001489975,25.946213,0,0,0,40,4449,199.87545,77571.328125,,,,,,,,,,,,,0,,,,0,,,,,,199.9942322,,,,
,29139153.63,199.9913635,72760.48046875,-0.000215939730681942,2.94308696065305E-6,1,0.999253354069792,40.0298881530762,1.98371513922264,17.2199998050928,-0.00242799280567002,-0.000460820108130886,0.25,-3.37251762746105E-6,-0.000216682460688999,-3.61249844602551E-6,199.991333,199.991394,72753.0546875,72767.90625,57.0635716749676,20.5790324553556,25.566563,0,0,0,40,4449,199.88305,72760.48046875,,,,,,,,,,,,,0,,,,0,,,,,,199.9913635,,,,
,29139249.805,199.98679355,67954.890625,-0.000189872805886858,3.348408846602E-6,1,0.999253354069792,40.0298881530762,1.98363043285559,17.2199998050928,-0.00213986936996301,-0.000376059463980924,0.25,-3.8234661453938E-7,-0.000190528577202516,-5.84847117716903E-7,199.9864655,199.9871216,67945.0703125,67964.7109375,57.2058280654676,20.578932282685,25.566563,0,0,0,40,4449,199.8967,67954.890625,,,,,,,,,,,,,0,,,,0,,,,,,199.98679355,,,,
,29139343.74,199.9915466,63259.392578125,-0.000163117216784842,3.08115149234943E-6,1,0.999253354069792,40.0298881530762,1.98364472781998,17.2199998050928,-0.00183809223301807,-0.000324526769266537,0.25,-4.57346633932882E-7,-0.000163680366381477,-6.3211459291465E-7,199.9915466,199.9915466,63256.94921875,63261.8359375,56.9955699937945,20.5794834247969,25.946213,0,0,0,40,4449,199.8988,63259.392578125,,,,,,,,,,,,,0,,,,0,,,,,,199.9915466,,,,
,29139438.235,199.9891663,58533.6640625,-0.000137560229176034,2.43375729937869E-6,1,0.999253354069792,40.0298881530762,1.98373521436519,17.2199998050928,-0.00154858653592408,-0.000282807539288362,0.25,-1.19388771009037E-6,-0.000138034252957112,-1.3443590551618E-6,199.9891663,199.9891663,58523.60546875,58543.72265625,56.7900016932368,20.5788625665299,25.946213,0,0,0,40,4449,199.90825,58533.6640625,,,,,,,,,,,,,0,,,,-0.00245,,,,,,199.9891663,,,,
,29139533.845,199.990387,53755.732421875,-0.000112781429947278,2.64088937312906E-6,1,0.999253354069792,40.0298881530762,1.9836870339388,17.2199998050928,-0.00126993909173283,-0.000229958401026427,0.25,-8.09941289835264E-7,-0.000113170205847604,-9.32966181241933E-7,199.990387,199.990387,53745.64453125,53765.8203125,57.2800827747945,20.5791625449927,25.946213,0,0,0,40,4449,199.91545,53755.732421875,,,,,,,,,,,,,0,,,,0,,,,,,199.990387,,,,
,29139629.16,199.9901886,48992.98828125,-8.73173932110723E-5,2.22145591278876E-6,1,0.999253354069792,40.0298881530762,1.98375598250052,17.2199998050928,-0.000990676908470711,-0.000135232928728232,0.25,3.17021136750961E-6,-8.76224190985404E-5,3.08789909883487E-6,199.9901886,199.9901886,48983.046875,49002.9296875,57.2097362080637,20.5798528515715,25.566563,0,0,0,40,4449,199.92585,48992.98828125,,,,,,,,,,,,,0,,,,0,,,,,,199.9901886,,,,
,29139726.555,199.9916534,44122.673828125,-6.03954592507181E-5,2.19510713464588E-6,1,0.999253354069792,40.0298881530762,1.98380340959924,17.2199998050928,-0.000678191366372343,-0.00013414892844588,0.25,-1.40886267707771E-6,-6.06025670582984E-5,-1.47836682009863E-6,199.9916534,199.9916534,44115.26953125,44130.078125,56.8540952318137,20.5775162653715,25.946213,0,0,0,40,4449,199.93025,44122.673828125,,,,,,,,,,,,,0,,,,0.0049,,,,,,199.9916534,,,,
,29139822.14,199.9896851,39347.671875,-3.63013054594343E-5,1.38520407992809E-6,1,0.999253354069792,40.0298881530762,1.98388908699923,17.2199998050928,-0.000410170542779426,-6.61251357040266E-5,0.25,4.40121819530118E-7,-3.64271595421885E-5,4.02717106196299E-7,199.9896851,199.9896851,39337.7890625,39357.5546875,57.0666981890445,20.5792681818569,26.325863,0,0,0,40,4449,199.939,39347.671875,,,,,,,,,,,,,0,,,,0.00245,,,,,,199.9896851,,,,
,29139914.315,199.9867859,34740.275390625,-1.05743788244288E-5,1.09378472531819E-6,1,0.999253354069792,40.0298881530762,1.98402031058353,17.2199998050928,-0.000122256783318498,-3.32145560491499E-6,0.25,1.54199173831195E-6,-1.06125564247142E-5,1.53595859873875E-6,199.9867859,199.9867859,34735.48828125,34745.0625,57.1362631272561,20.5788621082448,26.325863,0,0,0,40,4449,199.949,34740.275390625,,,,,,,,,,,,,0,,,,0,,,,,,199.9867859,,,,
,29140009.43,199.9909058,29985.3330078125,1.38851387065052E-5,1.25908158822963E-6,1,0.999253354069792,40.0298881530762,1.98400631243818,17.2199998050928,0.000156167265524644,2.94999775792487E-5,0.25,2.04599515800195E-7,1.39328684627976E-5,2.2024799655244E-7,199.9909058,199.9909058,29983.078125,29987.587890625,57.268358347006,20.5780596351053,26.325863,0,0,0,40,4449,199.95815,29985.3330078125,,,,,,,,,,,,,0,,,,0,,,,,,199.9909058,,,,
,29140102.89,199.9879761,25314.8115234375,3.73849794940134E-5,1.09279691839806E-6,1,0.999253354069792,40.0298881530762,1.98404044706891,17.2199998050928,0.000420576100044311,7.88674873685197E-5,0.25,5.01064626821424E-7,3.75135356516033E-5,5.43092871396965E-7,199.9879761,199.9879761,25304.67578125,25324.947265625,57.075296102756,20.5769927222393,26.325863,0,0,0,40,4449,199.97185,25314.8115234375,,,,,,,,,,,,,0,,,,0,,,,,,199.9879761,,,,
,29140200.535,199.9887695,20435.0673828125,6.10202922673257E-5,1.07099981368774E-6,1,0.999253354069792,40.0298881530762,1.98408254561018,17.2199998050928,0.000683969277637158,0.000143209532422422,0.25,2.10168716253567E-6,6.12287170571504E-5,2.17483411963607E-6,199.9887695,199.9887695,20427.8203125,20442.314453125,57.095618444256,20.5762053881155,26.325863,0,0,0,40,4449,199.97645,20435.0673828125,,,,,,,,,,,,,0,,,,-0.0049,,,,,,199.9887695,,,,
,29140302.505,199.9918518,15338.3168945313,8.49997170200137E-5,6.93587818060831E-7,1,0.999253354069792,40.0298881530762,1.98424793088479,17.2199998050928,0.000958037890237261,0.000169502979978157,0.25,2.6720291277022E-7,8.52928872303315E-5,3.6006995226612E-7,199.9918518,199.9918518,15335.705078125,15340.9287109375,57.1784710672945,20.5744604472994,26.325863,0,0,0,40,4449,199.97895,15338.3168945313,,,,,,,,,,,,,0,,,,-0.0049,,,,,,199.9918518,,,,
,29140402.475,199.9919281,10341.099609375,0.000107907348445291,5.4446181046579E-7,1,0.999253354069792,40.0298881530762,1.98430871246841,17.2199998050928,0.00121614098717138,0.00021591457619406,0.25,4.03219916102702E-7,0.000108279431425372,5.21519526566559E-7,199.9919281,199.9919281,10338.55078125,10343.6484375,57.3144744296407,20.5729652453118,25.946213,0,0,0,40,4449,199.9875,10341.099609375,,,,,,,,,,,,,0,,,,0,,,,,,199.9919281,,,,
,29140500.665,199.9919739,5433.53637695313,0.000127277697795573,4.63823130495491E-7,1,0.999253354069792,40.0298881530762,1.9841119933183,17.2199998050928,0.00143378190347919,0.0002577077182068,0.25,7.46652282331444E-7,0.000127716249222878,8.87318383595783E-7,199.9919739,199.9919739,5425.92578125,5441.14697265625,57.2238055214099,20.5768642452633,25.946213,0,0,0,40,4449,199.99315,5433.53637695313,,,,,,,,,,,,,0,,,,0.0049,,,,,,199.9919739,,,,
,29140600.095,199.9928894,461.885803222656,9.67226665531974E-5,4.48166858196481E-7,1,0.999253354069792,40.0298881530762,1.98412616180588,17.2199998050928,0.00109087039712936,0.000188453227257901,0.25,-8.79627516223297E-8,9.70566271995018E-5,1.6791941962722E-8,199.9928894,199.9928894,451.676147460937,472.095458984375,57.2081729510253,20.578962825809,25.946213,0,0,0,40,4449,199.9992,461.885803222656,,,,,,,,,,,,,0,,,,0,,,,,,199.9928894,,,,
,29140695.525,199.9968109,-4304.07104492188,-0.000129835645813421,3.71546628919142E-7,1,0.999253354069792,40.0298881530762,1.98398695615051,17.2199998050928,-0.00146291400902112,-0.000260538276975007,0.25,-5.54737157970158E-7,-0.000130283209455184,-6.97550140681666E-7,199.9968109,199.9968109,-4311.43603515625,-4296.7060546875,57.3863842534099,20.5811837871958,25.946213,0,0,0,40,4449,200.0028,-4304.07104492188,,,,,,,,,,,,,0,,,,0,,,,,,199.9968109,,,,
,29140789.915,200.0028229,-9020.7294921875,-0.000114008168970366,4.7830695367387E-7,1,0.999253354069792,40.0298881530762,1.98415165431792,17.2199998050928,-0.00128413059543055,-0.000231964193603812,0.25,-7.68245709783042E-7,-0.000114400870355496,-8.9445594672723E-7,200.0027771,200.0028687,-9030.611328125,-9010.84765625,56.933039712256,20.5785632581926,25.566563,0,0,0,40,4449,199.9993,-9020.7294921875,,,,,,,,,,,,,0,,,,0.00245,,,,,,200.0028229,,,,
,29140891.14,200.0054932,-14080.7778320312,-9.19228403520595E-5,7.78886367640066E-7,1,0.999253354069792,40.0298881530762,1.98422117080198,17.2199998050928,-0.00103482096037947,-0.000190411496281133,0.25,-9.18985370724262E-7,-9.22391604976707E-5,-1.02162521314255E-6,200.0054932,200.0054932,-14088.373046875,-14073.1826171875,57.2316218066022,20.5779456521225,25.946213,0,0,0,40,4449,199.99115,-14080.7778320312,,,,,,,,,,,,,0,,,,0.0049,,,,,,200.0054932,,,,
,29140992.735,200.0095978,-19157.67578125,-6.61922329519115E-5,9.7004442751796E-7,1,0.999253354069792,40.0298881530762,1.9841547699146,17.2199998050928,-0.000745016277822538,-0.000137791927338398,0.25,-7.22514991296773E-7,-6.64199549376273E-5,-7.96511452004243E-7,200.0095978,200.0095978,-19165.1796875,-19150.171875,57.3285437429868,20.5803404087003,26.325863,0,0,0,40,4449,199.98745,-19157.67578125,,,,,,,,,,,,,0,,,,0.00245,,,,,,200.0095978,,,,
,29141092.255,200.0087433,-24132.447265625,-4.12008440646763E-5,1.08132383285661E-6,1,0.999253354069792,40.0298881530762,1.98438716572218,17.2199998050928,-0.000463642536533457,-8.65781565497901E-5,0.25,-5.20825354332908E-7,-4.13425245714663E-5,-5.67052150959387E-7,200.0087433,200.0087433,-24137.296875,-24127.59765625,56.9072459711214,20.5765709024272,26.325863,0,0,0,40,4449,199.9787,-24132.447265625,,,,,,,,,,,,,0,,,,0.0049,,,,,,200.0087433,,,,
,29141192.15,200.0091705,-29122.4326171875,-1.59824699988846E-5,1.01135098010355E-6,1,0.999253354069792,40.0298881530762,1.9842715907551,17.2199998050928,-0.000178661995080454,-4.03913362682354E-5,0.25,-8.0576651465779E-7,-1.60367850458136E-5,-8.25751973749542E-7,200.0091705,200.0091705,-29134.771484375,-29110.09375,57.0330881627176,20.5776417308314,26.325863,0,0,0,40,4449,199.969,-29122.4326171875,,,,,,,,,,,,,0,,,,-0.0049,,,,,,200.0091705,,,,
,29141291.73,200.011261,-34099.12890625,1.00828712438125E-5,1.16570181171355E-6,1,0.999253354069792,40.0298881530762,1.98435993972378,17.2199998050928,0.000114864697261117,1.31194689856305E-5,0.25,-5.87893334976031E-7,1.01183181070948E-5,-5.7909079334335E-7,200.011261,200.011261,-34101.65625,-34096.6015625,57.1933220091599,20.5767391754011,25.946213,0,0,0,40,4449,199.96485,-34099.12890625,,,,,,,,,,,,,0,,,,-0.0049,,,,,,200.011261,,,,
,29141392.565,200.0132751,-39141.20703125,3.60225193868463E-5,1.17299978050462E-6,1,0.999253354069792,40.0298881530762,1.98442056775428,17.2199998050928,0.000408327753378577,5.87051719338274E-5,0.25,-1.05110304722721E-6,3.61480374891269E-5,-1.01610618795057E-6,200.0132751,200.0132751,-39143.890625,-39138.5234375,57.047939104583,20.578708856402,25.946213,0,0,0,40,4449,199.9501,-39141.20703125,,,,,,,,,,,,,0,,,,0,,,,,,200.0132751,,,,
,29141494.205,200.0151978,-44218.228515625,6.18527239788908E-5,1.8679978257492E-6,1,0.999253354069792,40.0298881530762,1.98441916084493,17.2199998050928,0.00070146864252337,9.88026334300199E-5,0.25,-1.98178069209211E-6,6.2068446491031E-5,-1.92243170211308E-6,200.0151978,200.0151978,-44225.765625,-44210.69140625,57.2574155477368,20.5788748445897,25.946213,0,0,0,40,4449,199.9347,-44218.228515625,,,,,,,,,,,,,0,,,,-0.0049,,,,,,200.0151978,,,,
,29141591.3,200.0124817,-49073.740234375,8.89713747140925E-5,1.85324986956673E-6,1,0.999253354069792,40.0298881530762,1.98425257648515,17.2199998050928,0.0010041153299792,0.000169886494016906,0.25,-3.87456622044268E-7,8.92790769540863E-5,-2.9376862428807E-7,200.0124817,200.0124817,-49078.87890625,-49068.6015625,57.2707032325638,20.5788920706032,25.566563,0,0,0,40,4449,199.9275,-49073.740234375,,,,,,,,,,,,,0,,,,-0.00245,,,,,,200.0124817,,,,
,29141688.705,200.0125885,-53940.697265625,0.000113104472622564,1.92235123314801E-6,1,0.999253354069792,40.0298881530762,1.98433079905723,17.2199998050928,0.00128190911146308,0.000184977782142389,0.25,-3.2409046800206E-6,0.000113498600918573,-3.13153878526499E-6,200.0125122,200.0126648,-53945.71484375,-53935.6796875,57.159711982833,20.5782683439515,25.566563,0,0,0,40,4449,199.917,-53940.697265625,,,,,,,,,,,,,0,,,,0.00245,,,,,,200.0125885,,,,
,29141787.555,200.0106659,-58880.33984375,0.000142255878519088,2.20676644007674E-6,1,0.999253354069792,40.0298881530762,1.98439882368462,17.2199998050928,0.00161149061840689,0.000237667856652295,0.25,-3.63198884417229E-6,0.000142751162237387,-3.49321769987365E-6,200.0106659,200.0106659,-58887.8359375,-58872.84375,57.3879475104484,20.5771835152846,25.946213,0,0,0,40,4449,199.9095,-58880.33984375,,,,,,,,,,,,,0,,,,0,,,,,,200.0106659,,,,
,29141885.445,200.0120544,-63772.568359375,0.000171138544454102,2.46841642542973E-6,1,0.999253354069792,40.0298881530762,1.98440968428839,17.2199998050928,0.00193280144562127,0.00031981539199825,0.25,-1.36397452817822E-6,0.000171731233862135,-1.18702208963572E-6,200.0120544,200.0120544,-63780.18359375,-63764.953125,57.1729996676599,20.5786650703911,26.325863,0,0,0,40,4449,199.89735,-63772.568359375,,,,,,,,,,,,,0,,,,-0.00245,,,,,,200.0120544,,,,
,29141982.91,200.0132751,-68644.921875,0.000194540746971496,2.66590629201971E-6,1,0.999253354069792,40.0298881530762,1.98435906506922,17.2199998050928,0.00220121128957581,0.000339565465350308,0.25,-3.67581495662873E-6,0.00019521678558623,-3.48244028833465E-6,200.0132751,200.0132751,-68657.515625,-68632.328125,57.2777378892368,20.5786696759747,25.946213,0,0,0,40,4449,199.88615,-68644.921875,,,,,,,,,,,,,0,,,,-0.00245,,,,,,200.0132751,,,,
,29142080.785,200.0113678,-73534.01171875,0.000222777064825843,2.61003045160231E-6,1,0.999253354069792,40.0298881530762,1.98441659489536,17.2199998050928,0.00251289423624651,0.000434232695182092,0.25,-1.8599208730948E-7,0.00022354704898353,4.88567096873819E-8,200.0113678,200.0113678,-73544.4140625,-73523.609375,57.2417829773522,20.5774044881447,26.325863,0,0,0,40,4449,199.86975,-73534.01171875,,,,,,,,,,,,,0,,,,0.00245,,,,,,200.0113678,,,,
,29142179.29,200.015564,-78456.1171875,0.000246533562526533,2.70259833184328E-6,1,0.999253354069792,40.0298881530762,1.98437879294117,17.2199998050928,0.00277601635698815,0.00050815729614994,0.25,2.24442174181585E-6,0.000247383119050133,2.51221159776246E-6,200.015564,200.015564,-78466.578125,-78445.65625,57.0799858738714,20.5786102316394,25.946213,0,0,0,40,4449,199.86235,-78456.1171875,,,,,,,,,,,,,0,,,,0.00245,,,,,,200.015564,,,,
,29142277.26,200.0103912,-83353.4609375,0.000274278963964412,2.76738421832447E-6,1,0.999253354069792,40.0298881530762,1.98439175498759,17.2199998050928,0.00309941881345238,0.000502220588323887,0.25,-3.09988476959169E-6,0.000275230166328576,-2.8219392259458E-6,200.0103912,200.0103912,-83363.3515625,-83343.5703125,57.4371901071599,20.5770413843524,26.325863,0,0,0,40,4449,199.8571,-83353.4609375,,,,,,,,,,,,,0,,,,0,,,,,,200.0103912,,,,
,29142371.28,200.0151978,-88053.01953125,0.000301219305702123,2.35810139317286E-6,1,0.999253354069792,40.0298881530762,1.98435733884202,17.2199998050928,0.00339723149880235,0.000589338568371291,0.25,-5.22245900799124E-8,0.00030226045630795,2.63944842495818E-7,200.0151978,200.0151978,-88055.328125,-88050.7109375,57.0135474497368,20.5779199778489,26.325863,0,0,0,40,4449,199.843,-88053.01953125,,,,,,,,,,,,,0,,,,-0.0049,,,,,,200.0151978,,,,
,29142482.42,200.0086823,-87334,0.000298047298872513,3.84618440031198E-6,1,0.999253354069792,40.0298881530762,1.98462526109746,17.2199998050928,0.00337096073917896,0.000530978331780022,0.25,-4.68232006969115E-6,0.000299082397891727,-4.38536575888966E-6,200.0086823,200.0086823,-87339.21875,-87328.78125,57.3785679682176,20.5769515057202,26.325863,0,0,0,40,4449,199.83495,-87334,,,,,,,,,,,,,0,,,,0,,,,,,200.0086823,,,,
,29142578.12,200.0039063,-82552.0234375,0.000270612779879618,2.25820059376467E-6,1,0.999253354069792,40.0298881530762,1.98437956174436,17.2199998050928,0.00305226726140637,0.000528358331478065,0.25,-1.45539860629116E-7,0.000271548239327982,1.38905143214728E-7,200.0039063,200.0039063,-82561.8359375,-82542.2109375,57.2191157502945,20.579217725206,25.946213,0,0,0,40,4449,199.8326,-82552.0234375,,,,,,,,,,,,,0,,,,0.00245,,,,,,200.0039063,,,,
,29142676.385,199.99510955,-77639.39453125,0.000244491236739507,2.71270810617576E-6,1,0.999253354069792,40.0298881530762,1.98453856685651,17.2199998050928,0.00276419231013508,0.000440877325999591,0.25,-3.36964753338105E-6,0.000245339806179086,-3.12328498672828E-6,199.9950714,199.9951477,-77644.5546875,-77634.234375,57.2777378892368,20.5763066974154,26.325863,0,0,0,40,4449,199.8414,-77639.39453125,,,,,,,,,,,,,0,,,,0,,,,,,199.99510955,,,,
,29142774.5,199.99494935,-72737.59765625,0.000220770466246411,2.89447373297016E-6,1,0.999253354069792,40.0298881530762,1.98457309488559,17.2199998050928,0.00248656291685097,0.000452730411994602,0.25,1.79944247608823E-6,0.000221531519871674,2.03915115475868E-6,199.9949341,199.9949646,-72742.5625,-72732.6328125,57.2269320354868,20.5759655645142,25.566563,0,0,0,40,4449,199.84455,-72737.59765625,,,,,,,,,,,,,0,,,,0,,,,,,199.99494935,,,,
,29142871.78,199.9916077,-67875.59375,0.00018670143080218,2.62119915776465E-6,1,0.999253354069792,40.0298881530762,1.9844747490652,17.2199998050928,0.00210656586464288,0.000360814131667467,0.25,-4.32218704876398E-7,0.000187347067253433,-2.35835004349883E-7,199.9916077,199.9916077,-67885.375,-67865.8125,57.2011382943522,20.5774505909255,26.325863,0,0,0,40,4449,199.854,-67875.59375,,,,,,,,,,,,,0,,,,0,,,,,,199.9916077,,,,
,29142968.485,199.9888763,-63041.302734375,0.000163001739176941,3.15772515970938E-6,1,0.999253354069792,40.0298881530762,1.98448578119204,17.2199998050928,0.00184237956981245,0.00029653243579365,0.25,-2.01638626175843E-6,0.00016356712324818,-1.85023298476524E-6,199.9888763,199.9888763,-63043.90234375,-63038.703125,57.3590272552368,20.575410130783,25.946213,0,0,0,40,4449,199.86175,-63041.302734375,,,,,,,,,,,,,0,,,,0.0049,,,,,,199.9888763,,,,
,29143065.2,199.9885101,-58208.443359375,0.000139458688229301,1.94799403630745E-6,1,0.999253354069792,40.0298881530762,1.98451299241352,17.2199998050928,0.00157522063553005,0.000259903327678495,0.25,-1.17600241661698E-6,0.000139941788468784,-1.03164603859771E-6,199.9885101,199.9885101,-58215.69921875,-58201.1875,57.1182856713137,20.5745454008876,25.946213,0,0,0,40,4449,199.8722,-58208.443359375,,,,,,,,,,,,,0,,,,0,,,,,,199.9885101,,,,
,29143162.72,199.9869537,-53336.220703125,0.000112179695084185,2.47406694893178E-6,1,0.999253354069792,40.0298881530762,1.98453052695688,17.2199998050928,0.00127152699315496,0.00018362175513931,0.25,-3.20216967029674E-6,0.000112570676699655,-3.09360361156765E-6,199.9869537,199.9869537,-53338.69921875,-53333.7421875,57.2284952925253,20.5742193541597,25.946213,0,0,0,40,4449,199.8848,-53336.220703125,,,,,,,,,,,,,0,,,,0.0049,,,,,,199.9869537,,,,
,29143260.375,199.9888458,-48454.34375,8.36403114441751E-5,2.33779503218063E-6,1,0.999253354069792,40.0298881530762,1.98470086749175,17.2199998050928,0.00094555477442471,0.000151677635454758,0.25,-1.07919610511792E-6,8.39303999843392E-5,-9.9354945870156E-7,199.9888458,199.9888458,-48461.66796875,-48447.01953125,57.6005504676792,20.573169337796,25.946213,0,0,0,40,4449,199.89275,-48454.34375,,,,,,,,,,,,,0,,,,0,,,,,,199.9888458,,,,
,29143358.845,199.9883423,-43532.060546875,6.04539312921448E-5,2.06266642215559E-6,1,0.999253354069792,40.0298881530762,1.9845861174079,17.2199998050928,0.000685601291992868,9.69179635463725E-5,0.25,-1.90668156472576E-6,6.0664793035267E-5,-1.84854025529591E-6,199.9883423,199.9883423,-43539.42578125,-43524.6953125,57.1206305568714,20.5726188796014,25.946213,0,0,0,40,4449,199.9018,-43532.060546875,,,,,,,,,,,,,0,,,,0.00245,,,,,,199.9883423,,,,
,29143456.555,199.98578645,-38649.759765625,3.52559104997065E-5,1.47681991773036E-6,1,0.999253354069792,40.0298881530762,1.98452045337212,17.2199998050928,0.000399911119817632,5.59985482233901E-5,0.25,-1.15820745289806E-6,3.53789264383651E-5,-1.12438668251924E-6,199.9855347,199.9860382,-38682.46484375,-38617.0546875,57.1620568683907,20.5729058361227,25.946213,0,0,0,40,4449,199.91055,-38649.759765625,,,,,,,,,,,,,0,,,,-0.00245,,,,,,199.98578645,,,,
,29143554.39,199.9882202,-33760.32421875,7.35337469169102E-6,1.11963651111498E-6,1,0.999253354069792,40.0298881530762,1.98443631622678,17.2199998050928,8.62193999499111E-5,-4.5159760429208E-6,0.25,-1.67754723669121E-6,7.38057338141236E-6,-1.67543758452985E-6,199.9882202,199.9882202,-33765.0546875,-33755.59375,57.1761261817368,20.5724867901934,26.325863,0,0,0,40,4449,199.92135,-33760.32421875,,,,,,,,,,,,,0,,,,-0.0049,,,,,,199.9882202,,,,
,29143651.82,199.99165345,-28893.3232421875,-1.68514727515561E-5,1.82442647278341E-6,1,0.999253354069792,40.0298881530762,1.98452681805187,17.2199998050928,-0.000186262455607259,-5.48970483892854E-5,0.25,-1.94049740012083E-6,-1.69075749252785E-5,-1.96534333501955E-6,199.9912262,199.9920807,-28903.44921875,-28883.197265625,57.4285921934484,20.5717303442962,25.566563,0,0,0,40,4449,199.92805,-28893.3232421875,,,,,,,,,,,,,0,,,,-0.00245,,,,,,199.99165345,,,,
,29143748.29,199.9884338,-24071.064453125,-4.23995966618509E-5,1.26160148888385E-6,1,0.999253354069792,40.0298881530762,1.98459193643619,17.2199998050928,-0.000476448821616338,-9.3314113162486E-5,0.25,-9.09053221244454E-7,-4.25450233364824E-5,-9.57927201470364E-7,199.9884338,199.9884338,-24076.41796875,-24065.7109375,57.0135474497368,20.5719989066249,26.705515,0,0,0,40,4449,199.9345,-24071.064453125,,,,,,,,,,,,,0,,,,-0.00245,,,,,,199.9884338,,,,
,29143845.745,199.9869843,-19198.54296875,-6.6181494794963E-5,8.51985741814263E-7,1,0.999253354069792,40.0298881530762,1.98450828268718,17.2199998050928,-0.000744681718255685,-0.000139756419038441,0.25,-8.96452771390717E-7,-6.64090385813221E-5,-9.71056200691928E-7,199.9869843,199.9869843,-19203.61328125,-19193.47265625,57.241001348833,20.5710195014194,25.946213,0,0,0,40,4449,199.946,-19198.54296875,,,,,,,,,,,,,0,,,,0.0049,,,,,,199.9869843,,,,
,29143943.42,199.9906769,-14319.1005859375,-8.98612866381091E-5,7.2613406247038E-7,1,0.999253354069792,40.0298881530762,1.98448413451522,17.2199998050928,-0.0010130795660514,-0.000178461261711711,0.25,-2.15332391214252E-7,-9.01712934673326E-5,-3.13328659405333E-7,199.9906769,199.9906769,-14326.6162109375,-14311.5849609375,57.220679007333,20.5706212830401,26.325863,0,0,0,40,4449,199.95205,-14319.1005859375,,,,,,,,,,,,,0,,,,-0.00245,,,,,,199.9906769,,,,
,29144039.04,199.9918365,-9541.39892578125,-0.000110644467340227,5.62140119889362E-7,1,0.999253354069792,40.0298881530762,1.98445953626607,17.2199998050928,-0.00124651757257833,-0.000224642097828616,0.25,-7.00197875243749E-7,-0.000111025669568084,-8.22543094501449E-7,199.9918365,199.9918365,-9553.919921875,-9528.8779296875,57.1542405831984,20.5721083341137,26.325863,0,0,0,40,4449,199.95375,-9541.39892578125,,,,,,,,,,,,,0,,,,0,,,,,,199.9918365,,,,
,29144133.6,199.9905701,-4812.81689453125,-0.000128526570983543,4.44754828204699E-7,1,0.999253354069792,40.0298881530762,1.98451704353687,17.2199998050928,-0.00144828665951438,-0.000259401092834091,0.25,-6.75365431056416E-7,-0.000128969508568012,-8.17194315682826E-7,199.9905701,199.9905701,-4820.07177734375,-4805.56201171875,57.2542890336599,20.5708804606672,26.325863,0,0,0,40,4449,199.95835,-4812.81689453125,,,,,,,,,,,,,0,,,,0.0049,,,,,,199.9905701,,,,
,29144229.07,199.9968109,-38.7348184585571,-2.31293913088548E-5,8.56999698228991E-7,1,0.999253354069792,40.0298881530762,1.98454131567698,17.2199998050928,-0.000260295117374699,-4.86317055358706E-5,0.25,-2.94390225676243E-7,-2.32089049583888E-5,-3.20535842221983E-7,199.9968109,199.9968109,-46.0871772766113,-31.3824596405029,57.1167224142753,20.5694760482332,25.946213,0,0,0,40,4449,199.96585,-38.7348184585571,,,,,,,,,,,,,0,,,,-0.0049,,,,,,199.9968109,,,,
,29144324.025,199.9996948,4702.64086914063,0.000129060130704244,3.65038246945676E-7,1,0.999253354069792,40.0298881530762,1.98467003851394,17.2199998050928,0.00145541370056909,0.000254693506261773,0.25,1.6364832028212E-7,0.000129505426754212,3.04288215357824E-7,199.9996948,199.9996948,4692.5771484375,4712.70458984375,57.217552493256,20.5683296309748,26.325863,0,0,0,40,4449,199.96485,4702.64086914063,,,,,,,,,,,,,0,,,,0,,,,,,199.9996948,,,,
,29144420.095,200.0025024,9506.13720703125,0.000112165277310603,5.52589794714108E-7,1,0.999253354069792,40.0298881530762,1.98458609981949,17.2199998050928,0.00126519217983227,0.000219310992759147,0.25,-3.78057630229578E-8,0.00011255249089373,8.36334397204533E-8,200.0025024,200.0025024,9501.2822265625,9510.9921875,57.2042648084291,20.5681803048404,26.705515,0,0,0,40,4449,199.9643,9506.13720703125,,,,,,,,,,,,,0,,,,0,,,,,,200.0025024,,,,
,29144513.49,200.0052185,14173.87890625,9.12945143124865E-5,7.4250072867113E-7,1,0.999253354069792,40.0298881530762,1.98454386637071,17.2199998050928,0.00102924850142687,0.000181416997000387,0.25,2.28013608207692E-7,9.1609411871948E-5,3.27602609404637E-7,200.0052185,200.0052185,14168.6064453125,14179.1513671875,57.2753930036791,20.5700053359467,26.325863,0,0,0,40,4449,199.96305,14173.87890625,,,,,,,,,,,,,0,,,,-0.00245,,,,,,200.0052185,,,,
,29144610.01,200.0073853,18996.255859375,6.67047324307559E-5,9.24296869389347E-7,1,0.999253354069792,40.0298881530762,1.98461442504129,17.2199998050928,0.000750173083367055,0.00014336721988289,0.25,1.12507543061842E-6,6.693379036396E-5,1.2010352506391E-6,200.0073853,200.0073853,18986.314453125,19006.197265625,57.1917587521214,20.5693309463667,26.325863,0,0,0,40,4449,199.95195,18996.255859375,,,,,,,,,,,,,0,,,,0,,,,,,200.0073853,,,,
,29144706.555,200.009201,23823.9365234375,4.45715272271635E-5,9.81087432465322E-7,1,0.999253354069792,40.0298881530762,1.98447678199818,17.2199998050928,0.000500577752426908,9.95233181501176E-5,0.25,1.08282204956022E-6,4.47242352349011E-5,1.13463995208491E-6,200.009201,200.009201,23818.8984375,23828.974609375,57.0330881627176,20.568066971515,26.325863,0,0,0,40,4449,199.9428,23823.9365234375,,,,,,,,,,,,,0,,,,0,,,,,,200.009201,,,,
,29144804.155,200.01130675,28701.6220703125,1.86840422302574E-5,9.4724511587858E-7,1,0.999253354069792,40.0298881530762,1.98440450521367,17.2199998050928,0.000210041936752494,4.05040771763482E-5,0.25,3.46313010859382E-7,1.87481768571625E-5,3.67627994865429E-7,200.0112762,200.0113373,28696.69921875,28706.544921875,57.0776409883137,20.5685504240123,26.325863,0,0,0,40,4449,199.931,28701.6220703125,,,,,,,,,,,,,0,,,,-0.0049,,,,,,200.01130675,,,,
,29144901.345,200.009079,33558.98046875,-5.14518909449276E-6,1.05893746429917E-6,1,0.999253354069792,40.0298881530762,1.98447841621409,17.2199998050928,-5.99044435220812E-5,7.1382091563948E-7,0.25,9.56906882146466E-7,-5.16398349983563E-6,9.54680703311314E-7,200.009079,200.009079,33554.08984375,33563.87109375,57.1198489283522,20.5683102726863,26.325863,0,0,0,40,4449,199.92365,33558.98046875,,,,,,,,,,,,,0,,,,0.00245,,,,,,200.009079,,,,
,29145000.01,200.0127335,38491.185546875,-3.23100710133371E-5,1.3947571237678E-6,1,0.999253354069792,40.0298881530762,1.98441973192845,17.2199998050928,-0.000366963256059799,-4.85235175808666E-5,0.25,1.30912299647657E-6,-3.24230449959203E-5,1.27898134209791E-6,200.0126038,200.0128632,38481.12890625,38501.2421875,56.7509202672752,20.5672531677647,26.325863,0,0,0,40,4449,199.91535,38491.185546875,,,,,,,,,,,,,0,,,,0.00245,,,,,,200.0127335,,,,
,29145097.32,200.0141144,43353.966796875,-5.80067978732075E-5,1.65847482196518E-6,1,0.999253354069792,40.0298881530762,1.98442864517901,17.2199998050928,-0.00065503475272,-0.000108899187546515,0.25,4.18687846186913E-7,-5.82075635272053E-5,3.58022918756796E-7,200.0141144,200.0141144,43348.97265625,43358.9609375,57.1792526958137,20.567919419748,26.325863,0,0,0,40,4449,199.9043,43353.966796875,,,,,,,,,,,,,0,,,,-0.0049,,,,,,200.0141144,,,,
,29145195.22,200.0130768,48246.6484375,-8.27101673653908E-5,2.14815388723471E-6,1,0.999253354069792,40.0298881530762,1.98442947433389,17.2199998050928,-0.000935621753211911,-0.000145910883503126,0.25,1.42721027723101E-6,-8.2997347307572E-5,1.34375153816394E-6,200.0130768,200.0130768,48241.69140625,48251.60546875,57.0799858738714,20.5667487535136,26.325863,0,0,0,40,4449,199.8938,48246.6484375,,,,,,,,,,,,,0,,,,-0.0049,,,,,,200.0130768,,,,
,29145292.47,200.0085449,53106.720703125,-0.000111840923003241,2.12014044829571E-6,1,0.999253354069792,40.0298881530762,1.98431451281875,17.2199998050928,-0.00125796658780082,-0.000238254542864232,0.25,-1.70270534002149E-6,-0.000112225421859891,-1.82786562854816E-6,200.0085449,200.0085449,53104.44140625,53109,57.2284952925253,20.5686210898611,26.705515,0,0,0,40,4449,199.8856,53106.720703125,,,,,,,,,,,,,0,,,,0,,,,,,200.0085449,,,,
,29145391.43,200.013916,58052.09375,-0.0001379680405453,2.71040607910442E-6,1,0.999253354069792,40.0298881530762,1.98434338862852,17.2199998050928,-0.00155377649059295,-0.000282890823364746,0.25,-1.12306516966706E-6,-0.000138443426183211,-1.27378632452378E-6,200.013916,200.013916,58042.16796875,58062.01953125,56.8204852054868,20.5687953453741,25.946213,0,0,0,40,4449,199.8736,58052.09375,,,,,,,,,,,,,0,,,,-0.00245,,,,,,200.013916,,,,
,29145490.44,200.0141602,63004.9375,-0.000161372382262055,2.12047082121231E-6,1,0.999253354069792,40.0298881530762,1.98440848472521,17.2199998050928,-0.00182288187937966,-0.000299384243185287,0.25,1.4795604058917E-6,-0.000161931430815362,1.31328086861575E-6,200.0141602,200.0141602,63000.0859375,63009.7890625,57.159711982833,20.5680238777807,25.946213,0,0,0,40,4449,199.8637,63004.9375,,,,,,,,,,,,,0,,,,0.0049,,,,,,200.0141602,,,,
,29145585.895,200.0123444,67773.11328125,-0.00018772482116013,1.87416077028619E-6,1,0.999253354069792,40.0298881530762,1.9843993383373,17.2199998050928,-0.00211550362238359,-0.000377351873088748,0.25,-8.57585361484852E-7,-0.000188372496877514,-1.05951883255926E-6,200.0123444,200.0123444,67763.015625,67783.2109375,56.9009929429675,20.5669281838452,26.325863,0,0,0,40,4449,199.8543,67773.11328125,,,,,,,,,,,,,0,,,,0.0049,,,,,,200.0123444,,,,
,29145683.105,200.0139923,72632.66796875,-0.000217275343229873,2.84063747053089E-6,1,0.999253354069792,40.0298881530762,1.9845721643847,17.2199998050928,-0.0024561764139109,-0.000393840773482644,0.25,2.8147015820017E-6,-0.000218029059201171,2.59461939554669E-6,200.0139923,200.0139923,72625.1328125,72640.203125,57.0768593597945,20.564100288389,25.946213,0,0,0,40,4449,199.8421,72632.66796875,,,,,,,,,,,,,0,,,,0,,,,,,200.0139923,,,,
,29145780.97,200.0138092,77523.546875,-0.000243184875450726,1.77492493770355E-6,1,0.999253354069792,40.0298881530762,1.98440776450621,17.2199998050928,-0.00274060723550936,-0.000488249878364339,0.25,-1.06004386547921E-6,-0.000244024100428552,-1.32036524805054E-6,200.0138092,200.0138092,77513.5859375,77533.5078125,57.0721695886791,20.5667633731131,26.705515,0,0,0,40,4449,199.8319,77523.546875,,,,,,,,,,,,,0,,,,0,,,,,,200.0138092,,,,
,29145879.425,200.0128174,82446.83984375,-0.00026996893350152,2.74783874590098E-6,1,0.999253354069792,40.0298881530762,1.98451866326525,17.2199998050928,-0.0030440410977044,-0.000533857050673658,0.25,-4.50637167841615E-7,-0.000270901454835048,-7.36501640135002E-7,200.0128174,200.0128174,82441.859375,82451.8203125,57.1346998702176,20.5639611281929,26.325863,0,0,0,40,4449,199.819,82446.83984375,,,,,,,,,,,,,0,,,,0.0049,,,,,,200.0128174,,,,
,29145974.4,200.0126648,87195.17578125,-0.000297213352173248,3.15886634541933E-6,1,0.999253354069792,40.0298881530762,1.98455094243158,17.2199998050928,-0.0033441098000951,-0.000629085250888885,0.25,-4.16233610822106E-6,-0.000298236226675854,-4.48905030022697E-6,200.0126648,200.0126648,87189.984375,87200.3671875,56.9627415959868,20.5640250475282,26.325863,0,0,0,40,4449,199.81065,87195.17578125,,,,,,,,,,,,,0,,,,-0.0049,,,,,,200.0126648,,,,
,29146084.125,200.0144196,88228.0625,-0.000300240707347879,3.42755885935964E-6,1,0.999253354069792,40.0298881530762,1.9845499542596,17.2199998050928,-0.00338592928321103,-0.000590814133248842,0.25,-2.43624470318549E-7,-0.000301278162685535,-5.5985814485524E-7,200.0144196,200.0144196,88218.3125,88237.8125,56.9908802226791,20.5645172955538,26.705515,0,0,0,40,4449,199.7929,88228.0625,,,,,,,,,,,,,0,,,,0.00245,,,,,,200.0144196,,,,
,29146180.005,200.0057526,83434.9140625,-0.000275879101085523,2.57806900930148E-6,1,0.999253354069792,40.0298881530762,1.98454841621453,17.2199998050928,-0.00310816050398082,-0.000560329950004576,0.25,-1.77080158504806E-6,-0.00027683073640208,-2.06735607911739E-6,200.0057526,200.0057526,83424.7421875,83445.0859375,57.115940785756,20.5638502343768,26.325863,0,0,0,40,4449,199.79895,83434.9140625,,,,,,,,,,,,,0,,,,-0.0049,,,,,,200.0057526,,,,
,29146275.82,199.9992371,78643.40234375,-0.000251519566363144,2.47799885581946E-6,1,0.999253354069792,40.0298881530762,1.9845400267119,17.2199998050928,-0.00283966898169593,-0.000476507670974841,0.25,1.43112828931506E-6,-0.000252390355023479,1.17070602921957E-6,199.9992371,199.9992371,78630.8125,78655.9921875,57.0940551872176,20.5657129088502,26.325863,0,0,0,40,4449,199.8014,78643.40234375,,,,,,,,,,,,,0,,,,-0.00245,,,,,,199.9992371,,,,
,29146373.21,199.99193575,73777.3515625,-0.000221410375130592,2.37256624211913E-6,1,0.999253354069792,40.0298881530762,1.98443387035235,17.2199998050928,-0.00249304404430209,-0.000457233972090498,0.25,-2.09037260964354E-6,-0.000222173364294312,-2.33170072920396E-6,199.9919281,199.9919434,73772.40625,73782.296875,57.2238055214099,20.565783923358,25.946213,0,0,0,40,4449,199.81165,73777.3515625,,,,,,,,,,,,,0,,,,-0.0049,,,,,,199.99193575,,,,
,29146471.61,199.9881439,68857.046875,-0.000195933232905668,2.4295569661198E-6,1,0.999253354069792,40.0298881530762,1.98451166709111,17.2199998050928,-0.0022132671840245,-0.000364274496059347,0.25,1.72917506754595E-6,-0.000196612175289325,1.52753928754552E-6,199.9881439,199.9881439,68854.4609375,68859.6328125,57.1886322380445,20.5666266567075,26.325863,0,0,0,40,4449,199.82185,68857.046875,,,,,,,,,,,,,0,,,,0,,,,,,199.9881439,,,,
,29146567.595,199.9906769,64061.76171875,-0.000168012627073288,2.41236343117137E-6,1,0.999253354069792,40.0298881530762,1.98455022754354,17.2199998050928,-0.00189380750259258,-0.000335992304345588,0.25,-6.11164994456875E-7,-0.000168592532419033,-7.91671382504813E-7,199.9906769,199.9906769,64056.59765625,64066.92578125,57.0018230219483,20.5659883868877,26.325863,0,0,0,40,4449,199.83235,64061.76171875,,,,,,,,,,,,,0,,,,-0.00245,,,,,,199.9906769,,,,
,29146665.425,199.9892883,59170.87890625,-0.000142652264718915,2.59758507671014E-6,1,0.999253354069792,40.0298881530762,1.98468292315684,17.2199998050928,-0.00161698047563197,-0.000233886070563247,0.25,4.03904496872868E-6,-0.000143149446379533,3.90121504025788E-6,199.9892883,199.9892883,59168.34765625,59173.41015625,57.1135959001984,20.5650105501846,25.946213,0,0,0,40,4449,199.8394,59170.87890625,,,,,,,,,,,,,0,,,,-0.0049,,,,,,199.9892883,,,,
,29146764.36,199.9906616,54222.76171875,-0.000117250636737538,1.7588449484489E-6,1,0.999253354069792,40.0298881530762,1.98464020763249,17.2199998050928,-0.00132482354225285,-0.000216410972517076,0.25,1.17669029620643E-6,-0.000117656965858533,1.05573655668456E-6,199.9906616,199.9906616,54220.4609375,54225.0625,57.1182856713137,20.5661716129079,26.325863,0,0,0,40,4449,199.8463,54222.76171875,,,,,,,,,,,,,0,,,,0,,,,,,199.9906616,,,,
,29146861.405,199.9892807,49373.181640625,-8.95416240253511E-5,1.60085014376753E-6,1,0.999253354069792,40.0298881530762,1.98456469954218,17.2199998050928,-0.0010094498274297,-0.000178220514621846,0.25,-2.50101650504349E-7,-8.98506794705386E-5,-3.46629065441093E-7,199.9888306,199.9897308,49367.97265625,49378.390625,57.129228470583,20.5665337264074,26.325863,0,0,0,40,4449,199.85915,49373.181640625,,,,,,,,,,,,,0,,,,-0.0049,,,,,,199.9892807,,,,
,29146961.69,199.9864044,44363.181640625,-6.25812601037577E-5,1.66163516950267E-6,1,0.999253354069792,40.0298881530762,1.98455006811132,17.2199998050928,-0.000705395630610604,-0.000125196067667729,0.25,-2.31176109770842E-7,-6.27971863885937E-5,-2.98971216345144E-7,199.9864044,199.9864044,44355.9375,44370.42578125,57.2832092888714,20.5672399443089,26.325863,0,0,0,40,4449,199.86685,44363.181640625,,,,,,,,,,,,,0,,,,0.00245,,,,,,199.9864044,,,,
,29147059.875,199.9893951,39452.685546875,-3.76663013689323E-5,1.2195805599716E-6,1,0.999253354069792,40.0298881530762,1.98465746903595,17.2199998050928,-0.000429965533569061,-4.43714072245751E-5,0.25,2.60798326314057E-6,-3.77991938778397E-5,2.57658849382832E-6,199.9893951,199.9893951,39442.76171875,39462.609375,57.3707516830253,20.5665396808845,26.705515,0,0,0,40,4449,199.87625,39452.685546875,,,,,,,,,,,,,0,,,,0,,,,,,199.9893951,,,,
,29147158.555,199.9903717,34523.25390625,-1.14942639877911E-5,9.98756811546372E-7,1,0.999253354069792,40.0298881530762,1.98463310692155,17.2199998050928,-0.000131150579621303,-1.38644866648906E-5,0.25,7.67129660654449E-7,-1.15347844506263E-5,7.57426037604404E-7,199.9903717,199.9903717,34516.14453125,34530.36328125,57.1143775287176,20.5674082497399,25.946213,0,0,0,40,4449,199.88385,34523.25390625,,,,,,,,,,,,,0,,,,0,,,,,,199.9903717,,,,
,29147253.33,199.98656465,29788.4287109375,1.39391967356272E-5,1.09801330339055E-6,1,0.999253354069792,40.0298881530762,1.98462487305328,17.2199998050928,0.000156855686439686,2.94294614003348E-5,0.25,1.88172428225913E-7,1.39871316746255E-5,2.03829724961128E-7,199.986557,199.9865723,29753.345703125,29823.51171875,57.2355299491984,20.5681168276616,26.325863,0,0,0,40,4449,199.89125,29788.4287109375,,,,,,,,,,,,,0,,,,0,,,,,,199.98656465,,,,
,29147348.855,199.98770905,25012.560546875,3.82424358439553E-5,9.73614973203037E-7,1,0.999253354069792,40.0298881530762,1.98449978754978,17.2199998050928,0.000430939648437904,7.71120258071894E-5,0.25,1.94925851321056E-7,3.83742799166301E-5,2.36843226951091E-7,199.9875336,199.9878845,24999.76953125,25025.3515625,57.1479875550445,20.5704443263292,26.325863,0,0,0,40,4449,199.90395,25012.560546875,,,,,,,,,,,,,0,,,,0.00245,,,,,,199.98770905,,,,
,29147445.55,199.9888458,20177.9755859375,6.1417377155058E-5,8.85980321695068E-7,1,0.999253354069792,40.0298881530762,1.98436955605654,17.2199998050928,0.00069255338469947,0.000120911480822842,0.25,5.37869672978702E-8,6.16293793793022E-5,1.20324163464441E-7,199.9888458,199.9888458,20173.283203125,20182.66796875,57.1706547821022,20.5712397013883,26.325863,0,0,0,40,4449,199.9123,20177.9755859375,,,,,,,,,,,,,0,,,,-0.00245,,,,,,199.9888458,,,,
,29147542.895,199.9908905,15313.6508789062,8.56016388447009E-5,7.28998954452571E-7,1,0.999253354069792,40.0298881530762,1.98456470255134,17.2199998050928,0.000964117566087719,0.000175633145140418,0.25,7.0383597356267E-7,8.58964121729524E-5,7.98896361597094E-7,199.9908905,199.9908905,15306.05859375,15321.2431640625,57.3105662870445,20.5689341032647,26.325863,0,0,0,40,4449,199.92005,15313.6508789062,,,,,,,,,,,,,0,,,,0,,,,,,199.9908905,,,,
,29147638.485,199.9913025,10538.4936523438,0.000107408988801814,5.70516988450625E-7,1,0.999253354069792,40.0298881530762,1.98451920148045,17.2199998050928,0.00121081912150097,0.000213948068442472,0.25,3.13447246410287E-7,0.000107779445225639,4.30934152879603E-7,199.9913025,199.9913025,10533.59765625,10543.3896484375,57.484869446833,20.5711346268739,26.325863,0,0,0,40,4449,199.92655,10538.4936523438,,,,,,,,,,,,,0,,,,0,,,,,,199.9913025,,,,
,29147733.29,199.9897614,5798.36108398438,0.000125999905583465,5.47441112035121E-7,1,0.999253354069792,40.0298881530762,1.98455681724291,17.2199998050928,0.00142061019760806,0.000249886404236621,0.25,2.70214301788843E-7,0.000126434566574869,4.07887064467152E-7,199.9897614,199.9897614,5790.88818359375,5805.833984375,57.1644017539484,20.5695323377019,26.325863,0,0,0,40,4449,199.93305,5798.36108398438,,,,,,,,,,,,,0,,,,0,,,,,,199.9897614,,,,
,29147828.89,199.9930573,1017.2815246582,0.000118489185181316,3.61722659292117E-7,1,0.999253354069792,40.0298881530762,1.9844604679691,17.2199998050928,0.00133636291140139,0.000232123646092718,0.25,7.04290193132258E-10,0.000118898176956673,1.29441708325712E-7,199.9930573,199.9930573,1007.00054931641,1027.5625,57.1683098965445,20.5710339614974,26.325863,0,0,0,40,4449,199.9404,1017.2815246582,,,,,,,,,,,,,0,,,,0,,,,,,199.9930573,,,,
,29147849.195,199.99262235,0.0380594320595264,9.98274048764324E-6,6.97118951698678E-7,1,0.999253354069792,40.0298881530762,1.9844863817033,17.2199998050928,0.000113391937440114,1.49413125486999E-5,0.25,-4.09163393504353E-7,1.00176426962101E-5,-3.99727960064926E-7,199.9924774,199.9927673,0.0304475463926792,0.0456713177263737,57.2769562607176,20.5722144642778,26.325863,0,0,0,40,4417,199.9406,0.0380594320595264,,,,,,,,,,,,,0,,,,-0.0049,,,,,,199.99262235,,,,