File: data/looselyPackedNP/sc-ios-11/ppms/rawdata/ES_S14_HYST_150K.DAT
[Header]
; VSM Data File (default extension .dat)
; Copyright (c) 2003-2013, Quantum Design, Inc. All rights reserved.
TITLE,
FILEOPENTIME,29125267.50,12/04/2018,10:22 am
BYAPP,VSM,2.0,2.0
INFO,PPMS VSM Option Release 1.4.10 Build 1,APPNAME
INFO,Quantum Design Linear Motor Servo Controller,MOTOR_MODULE_NAME
INFO,3101-100 M1,MOTOR_HW_VERSION
INFO,MMC1014,MOTOR_SERIAL_NUMBER
INFO,SRV No X-over 01.03.11,MOTOR_SOFTWARE_VERSION
INFO,Quantum Design VSM Detection Module,VSM_MODULE_NAME
INFO,3101-150 F0,VSM_HW_VERSION
INFO,VSM707,VSM_SERIAL_NUMBER
INFO,VSM No X-over 01.02.05 May 20 2008 13:51:47,VSM_SOFTWARE_VERSION
INFO,704,PREAMP_SERIAL_NUMBER
INFO,822,COIL_SERIAL_NUMBER
INFO,0,MOMENT_UNITS
INFO,Iron Oxide Spheres,SAMPLE_MATERIAL
INFO,10 nm diameter, collaboration Mainz,SAMPLE_COMMENT
INFO,,SAMPLE_MASS
INFO,,SAMPLE_VOLUME
INFO,,SAMPLE_MOLECULAR_WEIGHT
INFO,,SAMPLE_SIZE
INFO,,SAMPLE_SHAPE
DATATYPE,COMMENT,1
DATATYPE,TIME,2
STARTUPAXIS,X,2
STARTUPAXIS,Y1,5
[Data]
Comment,Time Stamp (sec),Temperature (K),Magnetic Field (Oe),Moment (emu),M. Std. Err. (emu),Transport Action,Averaging Time (sec),Frequency (Hz),Peak Amplitude (mm),Center Position (mm),Coil Signal' (mV),Coil Signal" (mV),Range (mV),M. Quad. Signal (emu),M. Raw' (emu),M. Raw" (emu),Min. Temperature (K),Max. Temperature (K),Min. Field (Oe),Max. Field (Oe),Mass (grams),Motor Lag (deg),Pressure (Torr),VSM Status (code),Motor Status (code),Measure Status (code),Measure Count,PPMS Status (code),System Temp. (K),System Field (Oe),Sample Position (deg),Bridge 1 Resistance (ohms),Bridge 1 Excitation (에),Bridge 2 Resistance (ohms),Bridge 2 Excitation (에),Bridge 3 Resistance (ohms),Bridge 3 Excitation (에),Bridge 4 Resistance (ohms),Bridge 4 Excitation (에),Signal 1 Vin (V),Signal 2 Vin (V),Digital Inputs (code),Drive 1 Iout (mA),Drive 1 Ipower (W),Drive 2 Iout (mA),Drive 2 Ipower (W),Pressure (),Map 20 (),Map 21 (),Map 22 (),Map 23 (),Map 24 (),Map 25 (),Map 26 (),Map 27 (),Map 28 (),Map 29 ()
,29125283.05,150.3127136,-0.19790905714035,,,2,,,,17.5400001248717,,,,,,,150.3127136,150.3127136,-0.19790905714035,-0.19790905714035,,,24.427608,,,,-99999999,4369,150.1602,-0.19790905714035,,,,,,,,,,,,,,,,,,,,,,,150.3127136,,,,
,29125436.765,150.1643066,4773.142578125,0.000130823113808166,4.09866377005302E-7,1,0.999253354069792,40.0298881530762,2.00865682664285,17.5299998372793,0.00149319054400729,0.000268769666395407,0.25,7.32765897886636E-7,0.000131462120585299,9.46080166295121E-7,150.1643066,150.1643066,4770.85107421875,4775.43408203125,56.7462304961599,20.5559182627037,24.427608,0,0,0,40,4449,149.9077,4773.142578125,,,,,,,,,,,,,0,,,,0,,,,,,150.1643066,,,,
,29125534.22,150.0829926,9644.7275390625,0.000112165851729598,6.40616791471677E-7,1,0.999253354069792,40.0298881530762,2.00859525771208,17.5299998372793,0.00128065909008826,0.000227834432661627,0.25,4.01109469429667E-7,0.000112714418700424,5.82576735711678E-7,150.0829926,150.0829926,9637.09375,9652.361328125,56.7579549239483,20.5591663053798,24.427608,0,0,0,40,4449,149.8579,9644.7275390625,,,,,,,,,,,,,0,,,,-0.00245,,,,,,150.0829926,,,,
,29125631.49,150.0311432,14504.6030273438,8.94803509952523E-5,7.48897678611678E-7,1,0.999253354069792,40.0298881530762,2.00857912004193,17.5299998372793,0.00102216553651045,0.000178741996268303,0.25,5.66822193043758E-8,8.99185982831781E-5,1.99815994655693E-7,150.0311432,150.0311432,14470.1025390625,14539.103515625,56.7571732954291,20.561231151068,24.807261,0,0,0,40,4449,149.84965,14504.6030273438,,,,,,,,,,,,,0,,,,0.00245,,,,,,150.0311432,,,,
,29125731.615,150.0041809,19509.294921875,6.46815181315137E-5,7.01043410457068E-7,1,0.999253354069792,40.0298881530762,2.00859882352286,17.5299998372793,0.000738837712091592,0.000129494622291005,0.25,6.64893060180613E-8,6.49983801515462E-5,1.69792441550274E-7,150.0041809,150.0041809,19501.6015625,19516.98828125,56.9502355396791,20.5620227131336,24.427608,0,0,0,40,4449,149.8558,19509.294921875,,,,,,,,,,,,,0,,,,0,,,,,,150.0041809,,,,
,29125829.92,149.9949341,24421.6943359375,3.79222078172836E-5,1.2545276369084E-6,1,0.999253354069792,40.0298881530762,2.0085104309612,17.5299998372793,0.000433004563538757,7.67903216487967E-5,0.25,1.15469018915997E-7,3.81079076179133E-5,1.76237460323819E-7,149.9949341,149.9949341,24419.12109375,24424.267578125,57.004167907506,20.5642761275649,24.047956,0,0,0,40,4449,149.8607,24421.6943359375,,,,,,,,,,,,,0,,,,0,,,,,,149.9949341,,,,
,29125930.965,149.9900818,29474.4287109375,1.23033501226652E-5,9.51652555700016E-7,1,0.999253354069792,40.0298881530762,2.00845001039367,17.5299998372793,0.000141339033445646,1.99737837966154E-5,0.25,-3.94824148299007E-7,1.2364297056093E-5,-3.77288070609826E-7,149.9900818,149.9900818,29471.76953125,29477.087890625,56.8892685151791,20.5643289144682,24.427608,0,0,0,40,4449,149.8685,29474.4287109375,,,,,,,,,,,,,0,,,,0,,,,,,149.9900818,,,,
,29126031.79,149.9918213,34511.6484375,-1.49466620815754E-5,1.66137983789991E-6,1,0.999253354069792,40.0298881530762,2.00837868155999,17.5299998372793,-0.000170770818352533,-2.95946410373751E-5,0.25,1.2962852414854E-8,-1.50199803330542E-5,-1.05527254690126E-8,149.9918213,149.9918213,34504.23046875,34519.06640625,57.2699216040445,20.5660694354908,24.807261,0,0,0,40,4449,149.88265,34511.6484375,,,,,,,,,,,,,0,,,,0.00245,,,,,,149.9918213,,,,
,29126130.84,149.9951782,39461.306640625,-4.22406909944578E-5,1.22576859533179E-6,1,0.999253354069792,40.0298881530762,2.00836639588961,17.5299998372793,-0.000481572798907016,-8.96042233705578E-5,0.25,-4.85943603554247E-7,-4.24471142271215E-5,-5.54757257166024E-7,149.9951782,149.9951782,39456.26171875,39466.3515625,57.1823792098907,20.5670618142917,24.047956,0,0,0,40,4449,149.88195,39461.306640625,,,,,,,,,,,,,0,,,,0.0049,,,,,,149.9951782,,,,
,29126232.375,149.9960785,44539.2578125,-6.92005802911518E-5,1.63736423757927E-6,1,0.999253354069792,40.0298881530762,2.008306552157,17.5299998372793,-0.000788453926342575,-0.000149422162624954,0.25,-1.02690314751204E-6,-6.9538469613242E-5,-1.14041376194845E-6,149.9960785,149.9960785,44534.2109375,44544.3046875,57.0971817012945,20.5677877938595,24.427608,0,0,0,40,4449,149.8831,44539.2578125,,,,,,,,,,,,,0,,,,0,,,,,,149.9960785,,,,
,29126332.81,149.9999542,49557.068359375,-9.9397253105813E-5,1.78560236611823E-6,1,0.999253354069792,40.0298881530762,2.008177355352,17.5299998372793,-0.00113606931518635,-0.00019376874530417,0.25,3.49196486049676E-7,-9.98855431741747E-5,1.95619011573676E-7,149.9999542,149.9999542,49552.3828125,49561.75390625,57.1300100991022,20.5681101971381,24.427608,0,0,0,40,4449,149.8852,49557.068359375,,,,,,,,,,,,,0,,,,0,,,,,,149.9999542,,,,
,29126431.4,150.0015564,54487.01171875,-0.000123937985519039,2.2459389357197E-6,1,0.999253354069792,40.0298881530762,2.0081108794487,17.5299998372793,-0.00141531457246177,-0.00024850233784792,0.25,-1.69335172850931E-7,-0.000124546019196131,-3.63162328035914E-7,150.0015564,150.0015564,54479.51953125,54494.50390625,57.2800827747945,20.5707037688648,24.807261,0,0,0,40,4449,149.885,54487.01171875,,,,,,,,,,,,,0,,,,-0.0049,,,,,,150.0015564,,,,
,29126533.07,150.004364,59566.9765625,-0.000153540231367965,2.72662645385196E-6,1,0.999253354069792,40.0298881530762,2.00820074741932,17.5299998372793,-0.00175339864513864,-0.000308079773899528,0.25,-2.28953816478747E-7,-0.00015429362335225,-4.68367202695266E-7,150.004364,150.004364,59561.9921875,59571.9609375,56.9713395096983,20.5699758310557,24.047956,0,0,0,40,4449,149.87685,59566.9765625,,,,,,,,,,,,,0,,,,-0.00245,,,,,,150.004364,,,,
,29126631.695,150.0047455,64495.02734375,-0.000181981369916728,2.61842483574337E-6,1,0.999253354069792,40.0298881530762,2.00810053889899,17.5299998372793,-0.00207676565914627,-0.000372758040569708,0.25,-9.40124109203667E-7,-0.000182873486328318,-1.22621216097259E-6,150.0047455,150.0047455,64490.01171875,64500.04296875,56.9885353371214,20.5719988448241,24.047956,0,0,0,40,4449,149.87805,64495.02734375,,,,,,,,,,,,,0,,,,0,,,,,,150.0047455,,,,
,29126726.89,150.0071259,69255.17578125,-0.000207381858155451,1.65118686320676E-6,1,0.999253354069792,40.0298881530762,2.00805788380829,17.5299998372793,-0.00237113744620724,-0.000398665310410702,0.25,1.21384000918389E-6,-0.000208402227160216,9.00071343128753E-7,150.0071259,150.0071259,69247.7421875,69262.609375,57.1745629246983,20.5709824294912,24.807261,0,0,0,40,4449,149.86785,69255.17578125,,,,,,,,,,,,,0,,,,0,,,,,,150.0071259,,,,
,29126825.505,150.0078735,74182.734375,-0.000233865473887022,3.01309750286646E-6,1,0.999253354069792,40.0298881530762,2.00806632766232,17.5299998372793,-0.00267107727537852,-0.000466109515976312,0.25,-7.96050223481605E-8,-0.000235014169898984,-4.39335232455546E-7,150.0078735,150.0078735,74175.203125,74190.265625,57.2980602307368,20.5720019033315,24.427608,0,0,0,40,4449,149.8607,74182.734375,,,,,,,,,,,,,0,,,,0,,,,,,150.0078735,,,,
,29126922.425,150.0075531,79028.45703125,-0.000261770672482656,3.02241537445382E-6,1,0.999253354069792,40.0298881530762,2.00798360003533,17.5299998372793,-0.00299118866744011,-0.000513044575729867,0.25,6.6792975119933E-7,-0.000263057879707114,2.70344943714219E-7,150.0075531,150.0075531,79018.4453125,79038.46875,57.2331850636407,20.5715980734601,24.427608,0,0,0,40,4449,149.8524,79028.45703125,,,,,,,,,,,,,0,,,,0,,,,,,150.0075531,,,,
,29127020.265,150.0079803,83919.0234375,-0.000289117945609666,3.08968072437758E-6,1,0.999253354069792,40.0298881530762,2.0077983176859,17.5299998372793,-0.00329807435601937,-0.000597129434283683,0.25,-1.93755094415116E-6,-0.000290535854867128,-2.38831026696171E-6,150.0079803,150.0079803,83911.5625,83926.484375,57.2480360055061,20.5721581189529,24.047956,0,0,0,40,4449,149.84275,83919.0234375,,,,,,,,,,,,,0,,,,-0.00245,,,,,,150.0079803,,,,
,29127112.34,150.0089111,88519.9609375,-0.000314727323257548,2.90757136290437E-6,1,0.999253354069792,40.0298881530762,2.00781119766634,17.5299998372793,-0.00360191044788267,-0.000582982017123685,0.25,3.75964368933702E-6,-0.000316280086401714,3.29937361693584E-6,150.0089111,150.0089111,88510.03125,88529.890625,56.800944492506,20.5716368351676,24.427608,0,0,0,40,4449,149.8378,88519.9609375,,,,,,,,,,,,,0,,,,-0.00245,,,,,,150.0089111,,,,
,29127223.17,150.004425,86945.8515625,-0.000308174349327746,2.92498196087858E-6,1,0.999253354069792,40.0298881530762,2.0078350799158,17.5299998372793,-0.00352336629939316,-0.000591451960731855,0.25,1.87803524045855E-6,-0.000309691965670963,1.41793129863612E-6,150.004425,150.004425,86938.4375,86953.265625,57.3269804859484,20.5732977183636,24.427608,0,0,0,40,4449,149.83355,86945.8515625,,,,,,,,,,,,,0,,,,0.00245,,,,,,150.004425,,,,
,29127316.425,149.9984131,82284.92578125,-0.000281659652812563,1.8692843413272E-6,1,0.999253354069792,40.0298881530762,2.0086910378645,17.5299998372793,-0.00322006188422468,-0.000549211265637294,0.25,9.80292158620156E-7,-0.000283045327268564,5.54722265039163E-7,149.9984131,149.9984131,82275.078125,82294.7734375,57.1573670972753,20.5677365950077,24.427608,0,0,0,40,4449,149.8357,82284.92578125,,,,,,,,,,,,,0,,,,0,,,,,,149.9984131,,,,
,29127411.975,149.9934235,77506.43359375,-0.000256380022876048,2.36491833881524E-6,1,0.999253354069792,40.0298881530762,2.0082180560712,17.5299998372793,-0.0029313624900472,-0.000494237070099376,0.25,1.38109364812536E-6,-0.000257641843454987,9.94808904128069E-7,149.9934235,149.9934235,77501.4921875,77511.375,57.1284468420637,20.5716014326128,24.047956,0,0,0,40,4449,149.8432,77506.43359375,,,,,,,,,,,,,0,,,,0,,,,,,149.9934235,,,,
,29127507.345,149.9937592,72737.70703125,-0.000228160299663615,2.63379112558233E-6,1,0.999253354069792,40.0298881530762,2.00791996854319,17.5299998372793,-0.00261125195662005,-0.00042302857125545,0.25,2.69635476870568E-6,-0.000229285249725643,2.35864478040998E-6,149.9937592,149.9937592,72727.9140625,72747.5,57.3011867448138,20.5765178608522,24.807261,0,0,0,40,4449,149.85305,72737.70703125,,,,,,,,,,,,,0,,,,0,,,,,,149.9937592,,,,
,29127601.845,149.9906311,68014.9375,-0.000201554623983033,2.45348807754067E-6,1,0.999253354069792,40.0298881530762,2.00767000022806,17.5299998372793,-0.00230525569347548,-0.000380678866526993,0.25,1.76785818823587E-6,-0.000202547261977443,1.4655002987926E-6,149.9906311,149.9906311,68014.9375,68014.9375,57.1331366131791,20.5761779753817,24.807261,0,0,0,40,4449,149.8591,68014.9375,,,,,,,,,,,,,0,,,,0,,,,,,149.9906311,,,,
,29127696.97,149.9907227,63259.5390625,-0.000172577582701261,2.99435135495355E-6,1,0.999253354069792,40.0298881530762,2.0077614030494,17.5299998372793,-0.00197295789767629,-0.00033147690422457,0.25,1.03176821162617E-6,-0.000173426590743079,7.6965801214544E-7,149.9907227,149.9907227,63257.31640625,63261.76171875,57.2871174314676,20.5762343940943,24.047956,0,0,0,40,4449,149.8693,63259.5390625,,,,,,,,,,,,,0,,,,0,,,,,,149.9907227,,,,
,29127795.89,149.9893188,58313.744140625,-0.000147363571269974,1.50008875561426E-6,1,0.999253354069792,40.0298881530762,2.00771815261587,17.5299998372793,-0.00168395524226574,-0.000287130968096359,0.25,5.23660419090975E-7,-0.000148087830642533,2.9733223426522E-7,149.9893188,149.9893188,58308.67578125,58318.8125,57.1440794124484,20.5774862774652,24.807261,0,0,0,40,4449,149.8768,58313.744140625,,,,,,,,,,,,,0,,,,0,,,,,,149.9893188,,,,
,29127892.82,149.991272,53471.103515625,-0.000120275385079735,1.60332755800757E-6,1,0.999253354069792,40.0298881530762,2.00777463565209,17.5299998372793,-0.00136988824972067,-0.000260536682857455,0.25,-1.86435945868172E-6,-0.00012086280748066,-2.06093428031599E-6,149.991272,149.991272,53466.05078125,53476.15625,57.3942005386022,20.5792921209773,24.427608,0,0,0,40,4449,149.88285,53471.103515625,,,,,,,,,,,,,0,,,,0,,,,,,149.991272,,,,
,29127988.51,149.9901428,48688.390625,-9.47794580877975E-5,2.08258849701127E-6,1,0.999253354069792,40.0298881530762,2.00767274121163,17.5299998372793,-0.00108400987577994,-0.000179098684573305,0.25,8.25498777166235E-7,-9.52458430483108E-5,6.81396582245905E-7,149.9901428,149.9901428,48683.51171875,48693.26953125,57.3519925985638,20.5807128091668,24.047956,0,0,0,40,4449,149.8913,48688.390625,,,,,,,,,,,,,0,,,,0,,,,,,149.9901428,,,,
,29128083.6,149.9908447,43935.236328125,-6.73482319208115E-5,2.39823822280054E-6,1,0.999253354069792,40.0298881530762,2.00771856147002,17.5299998372793,-0.000770285580952064,-0.000127291471912655,0.25,5.846938935989E-7,-6.76795647963319E-5,4.81969683294809E-7,149.9908447,149.9908447,43930.1875,43940.28515625,57.3895107674868,20.5798111875506,24.807261,0,0,0,40,4449,149.90075,43935.236328125,,,,,,,,,,,,,0,,,,-0.0049,,,,,,149.9908447,,,,
,29128180.06,149.99131015,39115.35546875,-4.00356207485202E-5,1.72822615401528E-6,1,0.999253354069792,40.0298881530762,2.00770747404006,17.5299998372793,-0.000458093272410296,-7.45518625139229E-5,0.25,4.45571345715614E-7,-4.0232698038883E-5,3.8479676623871E-7,149.991272,149.9913483,39107.8046875,39122.90625,57.4090514804676,20.5796556334775,24.427608,0,0,0,40,4449,149.9087,39115.35546875,,,,,,,,,,,,,0,,,,-0.00245,,,,,,149.99131015,,,,
,29128276.775,149.992691,34280.64453125,-1.59736951129593E-5,1.84552004776041E-6,1,0.999253354069792,40.0298881530762,2.0077038247369,17.5299998372793,-0.000182078577821977,-3.37304718321603E-5,0.25,-1.71126879390104E-7,-1.60517600312304E-5,-1.97161297719621E-7,149.992691,149.992691,34275.53515625,34285.75390625,57.2433462343907,20.5810138441441,24.427608,0,0,0,40,4449,149.9148,34280.64453125,,,,,,,,,,,,,0,,,,0,,,,,,149.992691,,,,
,29128373.18,149.9914703,29460.5908203125,1.30854825978755E-5,1.24527505543808E-6,1,0.999253354069792,40.0298881530762,2.00768683469132,17.5299998372793,0.000149634133759758,2.48837605007607E-5,0.25,-1.00475117144255E-7,1.31498002185418E-5,-8.02691454517548E-8,149.9914703,149.9914703,29452.880859375,29468.30078125,57.1855057239676,20.5808161618358,24.807261,0,0,0,40,4449,149.9252,29460.5908203125,,,,,,,,,,,,,0,,,,0,,,,,,149.9914703,,,,
,29128470.14,149.9915314,24618.087890625,3.74329023101864E-5,9.6749285835525E-7,1,0.999253354069792,40.0298881530762,2.00755358680734,17.5299998372793,0.000428216443630865,7.00653014754565E-5,0.25,-3.85120343488625E-7,3.76170115496138E-5,-3.27628529588155E-7,149.9915314,149.9915314,24610.482421875,24625.693359375,56.9596150819099,20.5820024589904,24.427608,0,0,0,40,4449,149.92915,24618.087890625,,,,,,,,,,,,,0,,,,0.0049,,,,,,149.9915314,,,,
,29128566.35,149.9926376,19808.3388671875,6.23707896165892E-5,9.82514689025673E-7,1,0.999253354069792,40.0298881530762,2.00761647515103,17.5299998372793,0.000711238913426551,0.000129816965217701,0.25,5.02640278041662E-7,6.26756751076469E-5,6.04309163096346E-7,149.9918823,149.9933929,19798.521484375,19818.15625,57.241001348833,20.5805108216852,24.807261,0,0,0,40,4449,149.93555,19808.3388671875,,,,,,,,,,,,,0,,,,0,,,,,,149.9926376,,,,
,29128661.945,149.9905396,15030.916015625,8.69186422361686E-5,6.1424028636448E-7,1,0.999253354069792,40.0298881530762,2.00788370641176,17.5299998372793,0.000992530963938831,0.000173825900786038,0.25,7.78236430421457E-8,8.73444423055643E-5,2.16807342159885E-7,149.9905396,149.9905396,15026.056640625,15035.775390625,57.1214121853907,20.578136260236,24.807261,0,0,0,40,4449,149.94295,15030.916015625,,,,,,,,,,,,,0,,,,0.00245,,,,,,149.9905396,,,,
,29128757.445,149.9925842,10258.5458984375,0.000108872957723459,5.30777909989614E-7,1,0.999253354069792,40.0298881530762,2.00811490475479,17.5299998372793,0.00124465343389891,0.000210356689337679,0.25,-5.50685213623958E-7,0.000109407246164793,-3.79355869860006E-7,149.9925842,149.9925842,10248.5029296875,10268.5888671875,57.6114932669484,20.5765461284308,24.807261,0,0,0,40,4449,149.94895,10258.5458984375,,,,,,,,,,,,,0,,,,-0.00245,,,,,,149.9925842,,,,
,29128853.63,149.9927673,5448.41235351562,0.000128587514462472,4.26808267232377E-7,1,0.999253354069792,40.0298881530762,2.00817746239163,17.5299998372793,0.00146904618201171,0.000254366252511055,0.25,-1.33333786504684E-7,0.000129217625257376,7.20022447903995E-8,149.9927673,149.9927673,5446.15966796875,5450.6650390625,57.2167708647368,20.5761521877703,24.427608,0,0,0,40,4449,149.9557,5448.41235351562,,,,,,,,,,,,,0,,,,0,,,,,,149.9927673,,,,
,29128947.78,149.9960175,744.803863525391,0.000114887708088683,3.58166355808284E-7,1,0.999253354069792,40.0298881530762,2.0080993574452,17.5299998372793,0.00131208561682079,0.000229540097789468,0.25,8.04071682966296E-8,0.000115450283928969,2.65170076919688E-7,149.9960175,149.9960175,742.200439453125,747.407287597656,57.4184310226984,20.5761967602205,24.807261,0,0,0,40,4449,149.9587,744.803863525391,,,,,,,,,,,,,0,,,,0,,,,,,149.9960175,,,,
,29129040.045,149.9954376,-3863.74633789063,-0.000132122676710446,3.92464877238738E-7,1,0.999253354069792,40.0298881530762,2.00811113826078,17.5299998372793,-0.00150817721785591,-0.000268287016171977,0.25,-4.7010984154188E-7,-0.000132769097951271,-6.84199559146596E-7,149.9954376,149.9954376,-3871.21606445313,-3856.27661132812,57.6224360662176,20.5754565887448,24.427608,0,0,0,40,4449,149.9591,-3863.74633789063,,,,,,,,,,,,,0,,,,0,,,,,,149.9954376,,,,
,29129137.01,150.0029144,-8712.7412109375,-0.000115563281092417,3.96895404085107E-7,1,0.999253354069792,40.0298881530762,2.00823221979797,17.5299998372793,-0.00131830481409767,-0.000239978359785312,0.25,-8.75840781286204E-7,-0.00011612800573964,-1.06497688027821E-6,150.0029144,150.0029144,-8720.220703125,-8705.26171875,57.3707516830253,20.5798779552453,24.427608,0,0,0,40,4449,149.9572,-8712.7412109375,,,,,,,,,,,,,0,,,,0,,,,,,150.0029144,,,,
,29129235.45,150.0061188,-13631.0424804687,-9.19819708206723E-5,6.26420428001387E-7,1,0.999253354069792,40.0298881530762,2.00819985579117,17.5299998372793,-0.00105030796943213,-0.00018511922147318,0.25,-1.82047655902768E-7,-9.24323544270828E-5,-3.29713205873858E-7,150.0061188,150.0061188,-13638.646484375,-13623.4384765625,57.3035316303714,20.5797796168447,24.427608,0,0,0,40,4449,149.9507,-13631.0424804687,,,,,,,,,,,,,0,,,,-0.00245,,,,,,150.0061188,,,,
,29129330.985,150.0093231,-18408.26171875,-6.87675051095406E-5,5.93808098615625E-7,1,0.999253354069792,40.0298881530762,2.0081522442473,17.5299998372793,-0.000785798619878548,-0.000135036733697915,0.25,1.5769726667381E-7,-6.91047423055782E-5,4.90109601493581E-8,150.0093231,150.0093231,-18410.796875,-18405.7265625,57.5599057846792,20.5798482519278,24.047956,0,0,0,40,4449,149.94125,-18408.26171875,,,,,,,,,,,,,0,,,,0,,,,,,150.0093231,,,,
,29129427.375,150.0108795,-23223.185546875,-4.485275496981E-5,9.83346388808219E-7,1,0.999253354069792,40.0298881530762,2.0082530308144,17.5299998372793,-0.00051315654172617,-8.46123321993004E-5,0.25,4.06270212089161E-7,-4.50732341390772E-5,3.37055625316505E-7,150.0108795,150.0108795,-23228.205078125,-23218.166015625,57.2628869473714,20.5779566513959,24.047956,0,0,0,40,4449,149.9315,-23223.185546875,,,,,,,,,,,,,0,,,,0,,,,,,150.0108795,,,,
,29129523.46,150.0113068,-28025.5087890625,-2.0029294327409E-5,9.90279881801998E-7,1,0.999253354069792,40.0298881530762,2.00829284093017,17.5299998372793,-0.000228927897989168,-3.910575057526E-5,0.25,6.57105387703493E-8,-2.01275855097248E-5,3.43220769084852E-8,150.0113068,150.0113068,-28035.28125,-28015.736328125,57.4098331089868,20.5787563098303,24.427608,0,0,0,40,4449,149.9221,-28025.5087890625,,,,,,,,,,,,,0,,,,0,,,,,,150.0113068,,,,
,29129622.55,150.0106125,-32980.166015625,6.43961079557092E-6,1.24986703395407E-6,1,0.999253354069792,40.0298881530762,2.00828310549876,17.5299998372793,7.25917428755474E-5,1.83738680345149E-5,0.25,4.86737186123821E-7,6.47041710593743E-6,4.99289437217411E-7,150.010376,150.010849,-32987.8046875,-32972.52734375,57.2542890336599,20.5769134112069,24.427608,0,0,0,40,4449,149.91115,-32980.166015625,,,,,,,,,,,,,0,,,,-0.00245,,,,,,150.0106125,,,,
,29129716.9,150.0110931,-37694.71875,3.36177992362031E-5,1.25327903325023E-6,1,0.999253354069792,40.0298881530762,2.00819505612988,17.5299998372793,0.000381413370266825,8.17613498106848E-5,0.25,1.30194184685045E-6,3.37806168130923E-5,1.36124561355482E-6,150.0110931,150.0110931,-37699.9296875,-37689.5078125,57.2284952925253,20.5787956309462,24.807261,0,0,0,40,4449,149.9011,-37694.71875,,,,,,,,,,,,,0,,,,0,,,,,,150.0110931,,,,
,29129814.475,150.0118256,-42571.955078125,5.8466668923664E-5,1.62010720910891E-6,1,0.999253354069792,40.0298881530762,2.00828670706827,17.5299998372793,0.000668858816974477,0.000110678366379365,0.25,-4.95092767917317E-7,5.87542341554252E-5,-4.05762449377109E-7,150.0118256,150.0118256,-42577.01171875,-42566.8984375,57.5372385576215,20.5796157849682,24.427608,0,0,0,40,4449,149.8889,-42571.955078125,,,,,,,,,,,,,0,,,,0,,,,,,150.0118256,,,,
,29129913.825,150.0108795,-47534.31640625,8.59794052727066E-5,2.10724007213053E-6,1,0.999253354069792,40.0298881530762,2.00842157906516,17.5299998372793,0.000988705081628373,0.000133855688742177,0.25,-3.25877071461901E-6,8.64063401360729E-5,-3.14024634912288E-6,150.0108795,150.0108795,-47539.390625,-47529.2421875,57.2011382943522,20.5771503927433,24.427608,0,0,0,40,4449,149.8809,-47534.31640625,,,,,,,,,,,,,0,,,,-0.0049,,,,,,150.0108795,,,,
,29130011.5,150.0102539,-52418.884765625,0.00011354720258212,1.65771153132985E-6,1,0.999253354069792,40.0298881530762,2.00835557841829,17.5299998372793,0.00129777534071197,0.000222131186762406,0.25,-3.32136702738268E-7,0.000114104933556846,-1.56681766598554E-7,150.0102539,150.0102539,-52426.3984375,-52411.37109375,57.3199458292753,20.580253040696,24.427608,0,0,0,40,4449,149.8706,-52418.884765625,,,,,,,,,,,,,0,,,,0,,,,,,150.0102539,,,,
,29130111.07,150.0120239,-57393.263671875,0.000140764136569918,2.15906429033834E-6,1,0.999253354069792,40.0298881530762,2.00846811748025,17.5299998372793,0.00160878467753459,0.000276258657248419,0.25,-3.35037706040615E-7,0.000141455578144196,-1.17861622585973E-7,150.0120239,150.0120239,-57398.21484375,-57388.3125,57.3152560581599,20.5792255851683,24.427608,0,0,0,40,4449,149.85935,-57393.263671875,,,,,,,,,,,,,0,,,,0.0049,,,,,,150.0120239,,,,
,29130208.485,150.01197055,-62263.01171875,0.000166282334313355,2.25121248952066E-6,1,0.999253354069792,40.0298881530762,2.00846693556251,17.5299998372793,0.00190215329261799,0.000316453929344682,0.25,-1.26030605414687E-6,0.000167100637084596,-1.00882982993784E-6,150.0114594,150.0124817,-62270.3515625,-62255.671875,57.2566339192176,20.5746268572077,24.807261,0,0,0,40,4449,149.8458,-62263.01171875,,,,,,,,,,,,,0,,,,0.0049,,,,,,150.01197055,,,,
,29130309.715,150.0119019,-67320.98046875,0.000195215264099658,1.94722227839584E-6,1,0.999253354069792,40.0298881530762,2.00834206974947,17.5299998372793,0.00223182730217013,0.000378203843122032,0.25,-8.91277891167886E-7,0.00019617525520667,-5.94193696459501E-7,150.0119019,150.0119019,-67323.5703125,-67318.390625,57.3449579418907,20.5775624101672,25.186911,0,0,0,40,4449,149.8385,-67320.98046875,,,,,,,,,,,,,0,,,,0,,,,,,150.0119019,,,,
,29130407.42,150.0108948,-72202.66796875,0.000224651756367949,3.06181229556129E-6,1,0.999253354069792,40.0298881530762,2.00840770852397,17.5299998372793,0.00256816267234476,0.000436880728934638,0.25,-8.81539477896458E-7,0.000225756527296208,-5.40098905614474E-7,150.0108948,150.0108948,-72210.15625,-72195.1796875,57.3637170263522,20.5764543781888,24.807261,0,0,0,40,4449,149.82755,-72202.66796875,,,,,,,,,,,,,0,,,,0,,,,,,150.0108948,,,,
,29130505.63,150.0116272,-77111.72265625,0.000252271285637578,2.73880195765584E-6,1,0.999253354069792,40.0298881530762,2.00847408904573,17.5299998372793,0.00288192355577567,0.00050250963706897,0.25,5.31261193368791E-8,0.000253510548231991,4.40356512482512E-7,150.0116272,150.0116272,-77116.6640625,-77106.78125,57.2730481181214,20.5797083147418,24.807261,0,0,0,40,4449,149.8181,-77111.72265625,,,,,,,,,,,,,0,,,,0,,,,,,150.0116272,,,,
,29130604.58,150.0115662,-82056.5703125,0.00027550708876839,2.04242577517606E-6,1,0.999253354069792,40.0298881530762,2.00839879386796,17.5299998372793,0.00314935228546211,0.000536749369148149,0.25,-9.93216022043157E-7,0.000276862406295434,-5.76923056533852E-7,150.0115662,150.0115662,-82064.046875,-82049.09375,57.3261988574291,20.5801116153764,24.807261,0,0,0,40,4449,149.8051,-82056.5703125,,,,,,,,,,,,,0,,,,0,,,,,,150.0115662,,,,
,29130699.485,150.0082626,-86801.171875,0.000302622787496206,2.54780534978489E-6,1,0.999253354069792,40.0298881530762,2.00848352301981,17.5299998372793,0.003454605855351,0.000617464825115713,0.25,1.349530368827E-6,0.000304108127421471,1.81723480268115E-6,150.0079803,150.0085449,-86806.125,-86796.21875,57.4887775894292,20.5783740461813,24.807261,0,0,0,40,4449,149.7997,-86801.171875,,,,,,,,,,,,,0,,,,0,,,,,,150.0082626,,,,
,29130807.75,150.0084534,-88709.921875,0.000316765481717701,2.14381581142893E-6,1,0.999253354069792,40.0298881530762,2.00853077344435,17.5299998372793,0.00362313597748813,0.000606132697683212,0.25,-2.1057684005406E-6,0.000318325722312925,-1.6341230601912E-6,150.0084534,150.0084534,-88717.375,-88702.46875,57.6380686366023,20.5768364103174,24.427608,0,0,0,40,4449,149.7899,-88709.921875,,,,,,,,,,,,,0,,,,-0.00245,,,,,,150.0084534,,,,
,29130901.635,150.0028534,-84018.00390625,0.000291762332110975,2.44012674723174E-6,1,0.999253354069792,40.0298881530762,2.00842328862101,17.5299998372793,0.00333131629798745,0.000590777359070378,0.25,9.0534144369924E-7,0.000293194817958033,1.35523562686439E-6,150.0028534,150.0028534,-84020.5625,-84015.4453125,57.4731450190445,20.5787413017094,24.427608,0,0,0,40,4449,149.79305,-84018.00390625,,,,,,,,,,,,,0,,,,-0.0049,,,,,,150.0028534,,,,
,29130999.11,149.9962006,-79145.80859375,0.000260705568875927,2.63990465497238E-6,1,0.999253354069792,40.0298881530762,2.008416388147,17.5299998372793,0.00297179239872354,0.000556072674931995,0.25,3.27459151821046E-6,0.000261981548132115,3.69009868863759E-6,149.9962006,149.9962006,-79157.953125,-79133.6640625,57.5466180998522,20.5776364439012,25.186911,0,0,0,40,4449,149.7941,-79145.80859375,,,,,,,,,,,,,0,,,,0,,,,,,149.9962006,,,,
,29131099.965,149.9935913,-74105.96875,0.000234426976399967,2.55232999559356E-6,1,0.999253354069792,40.0298881530762,2.00845277549349,17.5299998372793,0.00268045381704582,0.000453123239660305,0.25,-1.16263417264561E-6,0.000235580387515089,-8.07920239590775E-7,149.9935913,149.9935913,-74110.828125,-74101.109375,57.2667950899676,20.5770632956045,24.807261,0,0,0,40,4449,149.7997,-74105.96875,,,,,,,,,,,,,0,,,,0,,,,,,149.9935913,,,,
,29131199.74,149.9918976,-69119.45703125,0.000207596689128678,1.90702774708893E-6,1,0.999253354069792,40.0298881530762,2.00850316233115,17.5299998372793,0.00236884648504829,0.000429306363326177,0.25,1.42321235343745E-6,0.000208614091369692,1.75046988294638E-6,149.9918976,149.9918976,-69124.6640625,-69114.25,57.5677220698715,20.5763347999487,24.047956,0,0,0,40,4449,149.8089,-69119.45703125,,,,,,,,,,,,,0,,,,-0.0049,,,,,,149.9918976,,,,
,29131298.2,149.9920654,-64199.75,0.000178647991234158,1.70940614943105E-6,1,0.999253354069792,40.0298881530762,2.00837532606577,17.5299998372793,0.00203939165141042,0.00036368038731157,0.25,7.21567189983968E-7,0.000179524095313028,1.00164059823046E-6,149.9917755,149.9923553,-64212.34765625,-64187.15234375,57.6107116384292,20.5776221578717,25.186911,0,0,0,40,4449,149.817,-64199.75,,,,,,,,,,,,,0,,,,-0.0049,,,,,,149.9920654,,,,
,29131395.93,149.9909668,-59315.15234375,0.000151596567992178,2.19428690400919E-6,1,0.999253354069792,40.0298881530762,2.0084384597276,17.5299998372793,0.00173992346986547,0.000255265261186031,0.25,-4.05882111654096E-6,0.000152347101249327,-3.84332049544743E-6,149.9909668,149.9909668,-59320.19140625,-59310.11328125,57.217552493256,20.577552620904,24.807261,0,0,0,40,4449,149.82565,-59315.15234375,,,,,,,,,,,,,0,,,,0.0049,,,,,,149.9909668,,,,
,29131497.44,149.9908905,-54240.60546875,0.00012289929269493,1.90222247791272E-6,1,0.999253354069792,40.0298881530762,2.00848471122756,17.5299998372793,0.00140407021149284,0.000244352107372018,0.25,-1.70184161021269E-8,0.000123502529493108,1.74397874962983E-7,149.9908905,149.9908905,-54248.1640625,-54233.046875,57.5817913832176,20.5758422399597,24.427608,0,0,0,40,4449,149.8354,-54240.60546875,,,,,,,,,,,,,0,,,,0.00245,,,,,,149.9908905,,,,
,29131596.015,149.9917755,-49316.1640625,9.72145476471576E-5,1.86339283949796E-6,1,0.999253354069792,40.0298881530762,2.00844548892462,17.5299998372793,0.00111500958981761,0.000168030284727407,0.25,-2.22427310213567E-6,9.76950618123093E-5,-2.08321749710475E-6,149.9917755,149.9917755,-49326.1953125,-49306.1328125,57.3644986548715,20.5762386622911,24.427608,0,0,0,40,4449,149.8399,-49316.1640625,,,,,,,,,,,,,0,,,,-0.00245,,,,,,149.9917755,,,,
,29131694.42,149.9922028,-44398.701171875,6.99334240018175E-5,1.41104337116178E-6,1,0.999253354069792,40.0298881530762,2.00854023596938,17.5299998372793,0.000798488679752594,0.000141855555923689,0.25,2.35446265111484E-7,7.02761469845885E-5,3.46267977758254E-7,149.9922028,149.9922028,-44408.32421875,-44389.078125,57.6396318936407,20.5741398144414,24.807261,0,0,0,40,4449,149.84925,-44398.701171875,,,,,,,,,,,,,0,,,,0.00245,,,,,,149.9922028,,,,
,29131790.43,149.9916382,-39598.6171875,4.27663318742136E-5,1.36277903162936E-6,1,0.999253354069792,40.0298881530762,2.00845147438243,17.5299998372793,0.000488354543624967,8.63060964906228E-5,0.25,1.05353682585346E-7,4.29759336312052E-5,1.73138658934716E-7,149.9916382,149.9916382,-39601.046875,-39596.1875,57.2660134614484,20.57622904952,24.807261,0,0,0,40,4449,149.85495,-39598.6171875,,,,,,,,,,,,,0,,,,-0.0049,,,,,,149.9916382,,,,
,29131886.18,149.9894104,-34813.783203125,1.6635898721701E-5,1.2469539722306E-6,1,0.999253354069792,40.0298881530762,2.00851558581153,17.5299998372793,0.000188053002115802,4.45969321528241E-5,0.25,1.00579827646775E-6,1.67158950551681E-5,1.03697418726975E-6,149.9894104,149.9894104,-34823.66796875,-34803.8984375,57.6568277210638,20.5744727745083,24.807261,0,0,0,40,4449,149.86525,-34813.783203125,,,,,,,,,,,,,0,,,,-0.00245,,,,,,149.9894104,,,,
,29131985.25,149.9900513,-29864.6630859375,-1.0711088359873E-5,1.05513383996845E-6,1,0.999253354069792,40.0298881530762,2.0084975581098,17.5299998372793,-0.000123537796741112,-1.45899116174509E-5,0.25,5.8875527427042E-7,-1.07645363835278E-5,5.74695301705881E-7,149.9900513,149.9900513,-29877.263671875,-29852.0625,57.2660134614484,20.5755702687247,24.807261,0,0,0,40,4449,149.87605,-29864.6630859375,,,,,,,,,,,,,0,,,,-0.0049,,,,,,149.9900513,,,,
,29132081.43,149.9885254,-25057.1650390625,-3.45676726793734E-5,9.20929829627664E-7,1,0.999253354069792,40.0298881530762,2.00834349813336,17.5299998372793,-0.000395504648921325,-6.52041081843123E-5,0.25,3.13847193031285E-7,-3.47376244068896E-5,2.60542280063104E-7,149.9885254,149.9885254,-25064.576171875,-25049.75390625,57.3316702570638,20.5763356168873,24.807261,0,0,0,40,4449,149.88575,-25057.1650390625,,,,,,,,,,,,,0,,,,0,,,,,,149.9885254,,,,
,29132178.27,149.9919052,-20215.23046875,-6.03525940019064E-5,8.67363117894186E-7,1,0.999253354069792,40.0298881530762,2.00850415997267,17.5299998372793,-0.000687475281101333,-0.000131636376356172,0.25,-1.00866957044682E-6,-6.0646779107679E-5,-1.10963123692547E-6,149.9917755,149.9920349,-20227.552734375,-20202.908203125,57.2878990599868,20.5751817426656,24.807261,0,0,0,40,4449,149.88725,-20215.23046875,,,,,,,,,,,,,0,,,,-0.00245,,,,,,149.9919052,,,,
,29132273.65,149.99043275,-15450.6411132812,-8.43950786844005E-5,7.06678919851519E-7,1,0.999253354069792,40.0298881530762,2.00845726181838,17.5299998372793,-0.000963262145471594,-0.000172926520272492,0.25,-4.34561426707641E-7,-8.4807938627037E-5,-5.71293055677805E-7,149.9904175,149.990448,-15455.595703125,-15445.6865234375,57.2472543769868,20.575420605596,25.186911,0,0,0,40,4449,149.90145,-15450.6411132812,,,,,,,,,,,,,0,,,,-0.00245,,,,,,149.99043275,,,,
,29132370.325,149.9903412,-10615.4458007813,-0.000106255067811616,5.9448253209686E-7,1,0.999253354069792,40.0298881530762,2.00830867320795,17.5299998372793,-0.00121210794776228,-0.000220982551685278,0.25,-8.33860875944876E-7,-0.000106774314601718,-1.0078295548892E-6,149.9903412,149.9903412,-10627.984375,-10602.9072265625,57.017455592333,20.5739695438588,24.807261,0,0,0,40,4449,149.9062,-10615.4458007813,,,,,,,,,,,,,0,,,,0.0049,,,,,,149.9903412,,,,
,29132465.84,149.9923096,-5842.25341796875,-0.000126344718355471,3.59628545671988E-7,1,0.999253354069792,40.0298881530762,2.00837974216034,17.5299998372793,-0.00144173451087399,-0.000260443049468809,0.25,-7.87180516869651E-7,-0.000126962360462376,-9.9347330034198E-7,149.9923096,149.9923096,-5844.75048828125,-5839.75634765625,57.4176493941791,20.572887039923,24.807261,0,0,0,40,4449,149.91745,-5842.25341796875,,,,,,,,,,,,,0,,,,0,,,,,,149.9923096,,,,
,29132561.36,149.992981,-1068.16333007812,-0.000123105409516487,3.860781684013E-7,1,0.999253354069792,40.0298881530762,2.00828815275436,17.5299998372793,-0.001404587467404,-0.000254448077984615,0.25,-8.27358089084596E-7,-0.000123707033741826,-1.02902258224269E-6,149.992981,149.992981,-1075.55822753906,-1060.76843261719,57.3465211989291,20.5742873765168,25.186911,0,0,0,40,4449,149.9198,-1068.16333007812,,,,,,,,,,,,,0,,,,-0.0049,,,,,,149.992981,,,,
,29132655.335,149.9989471,3624.64501953125,0.000133021690117436,3.4300427945844E-7,1,0.999253354069792,40.0298881530762,2.00826925178385,17.5299998372793,0.00151904549410672,0.000267306233940453,0.25,2.25767535585925E-7,0.000133672871611692,4.40199704667135E-7,149.9989471,149.9989471,3617.1171875,3632.1728515625,57.4504777919868,20.5734217660186,24.807261,0,0,0,40,4449,149.92175,3624.64501953125,,,,,,,,,,,,,0,,,,0.0049,,,,,,149.9989471,,,,
,29132751.515,150.0023956,8431.4541015625,0.000117033057611482,4.25959761315684E-7,1,0.999253354069792,40.0298881530762,2.00830832053473,17.5299998372793,0.001336325099844,0.00023611925167883,0.25,2.81097020919182E-7,0.000117605913863176,4.69767319709395E-7,150.0023956,150.0023956,8426.482421875,8436.42578125,57.423902422333,20.5736136875966,24.807261,0,0,0,40,4449,149.9178,8431.4541015625,,,,,,,,,,,,,0,,,,0.0049,,,,,,150.0023956,,,,
,29132847.875,150.0031891,13249.2963867188,9.51476293557357E-5,6.54493323191409E-7,1,0.999253354069792,40.0298881530762,2.00818049917084,17.5299998372793,0.00108637731560801,0.000191878970473071,0.25,2.22411355834726E-7,9.56134479216066E-5,3.75411070267281E-7,150.0031891,150.0031891,13244.3798828125,13254.212890625,57.5059734168522,20.5763249233783,24.807261,0,0,0,40,4449,149.91345,13249.2963867188,,,,,,,,,,,,,0,,,,0,,,,,,150.0031891,,,,
,29132944.62,150.0075073,18084.5478515625,7.21044721039321E-5,8.00921981194265E-7,1,0.999253354069792,40.0298881530762,2.00822973295777,17.5299998372793,0.00082405472005095,0.000141050875243856,0.25,-2.13009151899851E-7,7.24581410844572E-5,-9.92254551790898E-8,150.0075073,150.0075073,18077.08984375,18092.005859375,57.0979633298137,20.5759828833305,25.186911,0,0,0,40,4449,149.9085,18084.5478515625,,,,,,,,,,,,,0,,,,0,,,,,,150.0075073,,,,
,29133040.35,150.0091248,22869.59375,4.68980420618258E-5,9.96012033386664E-7,1,0.999253354069792,40.0298881530762,2.00818625062221,17.5299998372793,0.000535266845440492,9.57728508412355E-5,0.25,2.14691324639529E-7,4.71275533717855E-5,2.90235813057224E-7,150.0091248,150.0091248,22864.56640625,22874.62109375,57.4215575367753,20.5760071996655,24.807261,0,0,0,40,4449,149.8977,22869.59375,,,,,,,,,,,,,0,,,,-0.0049,,,,,,150.0091248,,,,
,29133136.875,150.0114288,27695.03125,2.107069738058E-5,1.28571913431104E-6,1,0.999253354069792,40.0298881530762,2.0081567310835,17.5299998372793,0.000237773753464223,5.8595609975795E-5,0.25,1.45936841823733E-6,2.11716740552595E-5,1.49989916395778E-6,150.0114288,150.0114288,27687.595703125,27702.466796875,57.1573670972753,20.5725923383593,24.807261,0,0,0,40,4449,149.8878,27695.03125,,,,,,,,,,,,,0,,,,0,,,,,,150.0114288,,,,
,29133234.95,150.0109253,32594.755859375,-5.67955300424377E-6,1.10957989820442E-6,1,0.999253354069792,40.0298881530762,2.00813984686132,17.5299998372793,-6.50601020130545E-5,-1.02302181911003E-5,0.25,9.37198000947373E-8,-5.70754782550027E-6,8.52082668743741E-8,150.0109253,150.0109253,32584.556640625,32604.955078125,57.444224763833,20.5755868835866,25.186911,0,0,0,40,4449,149.8754,32594.755859375,,,,,,,,,,,,,0,,,,0.00245,,,,,,150.0109253,,,,
,29133332.945,150.0114899,37494.9375,-2.97332447493879E-5,1.62493193359513E-6,1,0.999253354069792,40.0298881530762,2.00805593398218,17.5299998372793,-0.000339548767819437,-5.95054179064989E-5,0.25,-3.05110129186894E-8,-2.98790082151387E-5,-7.74862800555463E-8,150.0114899,150.0114899,37487.56640625,37502.30859375,57.3973270526791,20.5764675079726,24.807261,0,0,0,40,4449,149.86595,37494.9375,,,,,,,,,,,,,0,,,,0,,,,,,150.0114899,,,,
,29133431.88,150.0108337,42439.67578125,-5.69488309255783E-5,1.10321544836723E-6,1,0.999253354069792,40.0298881530762,2.00811590456677,17.5299998372793,-0.00065069864529281,-0.000112063001335004,0.25,1.08732057643071E-7,-5.72283387500396E-5,1.98541674641972E-8,150.0108337,150.0108337,42429.70703125,42449.64453125,57.5817913832176,20.5724119413838,24.427608,0,0,0,40,4449,149.85725,42439.67578125,,,,,,,,,,,,,0,,,,0.00245,,,,,,150.0108337,,,,
,29133528.675,150.0116425,47277.51171875,-8.33737686512539E-5,1.9352172656528E-6,1,0.999253354069792,40.0298881530762,2.00805681377189,17.5299998372793,-0.000950994313214211,-0.000173303152790515,0.25,-6.50709605198278E-7,-8.37817871970622E-5,-7.84402443301885E-7,150.0116425,150.0116425,47272.4140625,47282.609375,57.5896076684099,20.572169182143,25.186911,0,0,0,40,4449,149.8468,47277.51171875,,,,,,,,,,,,,0,,,,0.00245,,,,,,150.0116425,,,,
,29133623.32,150.01081085,52005.234375,-0.000109980007052438,1.83852252319883E-6,1,0.999253354069792,40.0298881530762,2.00804725288153,17.5299998372793,-0.00125555434075268,-0.00022238867523824,0.25,-3.14474206117178E-7,-0.000110519200263085,-4.87640963558061E-7,150.010437,150.0111847,51970.25390625,52040.21484375,57.677931691083,20.5718101684036,24.807261,0,0,0,40,4449,149.83685,52005.234375,,,,,,,,,,,,,0,,,,0,,,,,,150.01081085,,,,
,29133718.79,150.0104828,56777.68359375,-0.000135575703763483,1.7811019129714E-6,1,0.999253354069792,40.0298881530762,2.00808602085993,17.5299998372793,-0.00155056780344937,-0.00025820306252071,0.25,1.0078826292982E-6,-0.000136242698920822,8.01921721772058E-7,150.0104828,150.0104828,56772.76171875,56782.60546875,57.1808159528522,20.5739635693283,24.807261,0,0,0,40,4449,149.8267,56777.68359375,,,,,,,,,,,,,0,,,,0.00245,,,,,,150.0104828,,,,
,29133816.135,150.0113525,61642.77734375,-0.000160332901234488,2.04538509243917E-6,1,0.999253354069792,40.0298881530762,2.00796892895349,17.5299998372793,-0.00183243088229654,-0.000312127134509188,0.25,5.96569472323498E-7,-0.000161120932937874,3.50876637432571E-7,150.0113525,150.0113525,61635.23828125,61650.31640625,57.3809128537753,20.5736481085646,24.807261,0,0,0,40,4449,149.8153,61642.77734375,,,,,,,,,,,,,0,,,,-0.00245,,,,,,150.0113525,,,,
,29133911.355,150.0134583,66406.0390625,-0.000186486583598871,2.03771483246284E-6,1,0.999253354069792,40.0298881530762,2.00800331779217,17.5299998372793,-0.00213151865668448,-0.000362228394197149,0.25,7.64718814217086E-7,-0.000187403451304784,4.80218140802218E-7,150.0134583,150.0134583,66398.7890625,66413.2890625,57.2073913225061,20.5732906992971,24.807261,0,0,0,40,4449,149.80475,66406.0390625,,,,,,,,,,,,,0,,,,-0.0049,,,,,,150.0134583,,,,
,29134006.68,150.0101471,71168.66796875,-0.000216230436715343,2.67720743493707E-6,1,0.999253354069792,40.0298881530762,2.00794404018181,17.5299998372793,-0.00246491297680258,-0.000457356667072666,0.25,-2.38593494971779E-6,-0.000217288745292767,-2.73079874422688E-6,150.0101471,150.0101471,71161.09375,71176.2421875,57.1729996676599,20.5732080002342,24.807261,0,0,0,40,4449,149.7969,71168.66796875,,,,,,,,,,,,,0,,,,0.00245,,,,,,150.0101471,,,,
,29134102.83,150.01320645,75974.58203125,-0.000244494253585302,3.01049900293979E-6,1,0.999253354069792,40.0298881530762,2.00804861339282,17.5299998372793,-0.00279309323510387,-0.00048359394115204,0.25,2.40099813111852E-7,-0.000245695659638593,-1.34183464540866E-7,150.0131378,150.0132751,75964.6640625,75984.5,57.1581487257945,20.5732106893881,24.427608,0,0,0,40,4449,149.78355,75974.58203125,,,,,,,,,,,,,0,,,,0,,,,,,150.01320645,,,,
,29134199.04,150.0096741,80782.91796875,-0.000269655754350672,2.18714666273478E-6,1,0.999253354069792,40.0298881530762,2.00787574544764,17.5299998372793,-0.00308510532493906,-0.000505655795204338,0.25,2.68550412563048E-6,-0.000270984824045006,2.28598882110819E-6,150.0096741,150.0096741,80777.8203125,80788.015625,56.8454973181022,20.5727495299794,25.186911,0,0,0,40,4449,149.77725,80782.91796875,,,,,,,,,,,,,0,,,,0,,,,,,150.0096741,,,,
,29134294.665,150.0108032,85563.49609375,-0.000296000358189702,2.64315550376743E-6,1,0.999253354069792,40.0298881530762,2.00801901681806,17.5299998372793,-0.0033770196195726,-0.000610944253567521,0.25,-1.94329197733258E-6,-0.000297452109471917,-2.40434866916365E-6,150.0108032,150.0108032,85556.015625,85570.9765625,57.2316218066022,20.574174369513,24.807261,0,0,0,40,4449,149.7704,85563.49609375,,,,,,,,,,,,,0,,,,0,,,,,,150.0108032,,,,
,29134403.36,150.0064697,89963.85546875,-0.000320445120638454,2.20120674109104E-6,1,0.999253354069792,40.0298881530762,2.00795114263994,17.5299998372793,-0.00365903223296353,-0.00064277092309974,0.25,-4.7617766982575E-7,-0.000322019600095853,-9.65815894098064E-7,150.0064697,150.0064697,89957.5703125,89970.140625,57.1620568683907,20.5732736299596,24.807261,0,0,0,40,4449,149.7572,89963.85546875,,,,,,,,,,,,,0,,,,-0.0049,,,,,,150.0064697,,,,
,29134494.095,150.0054932,85444.28125,-0.000296702672889231,2.54980434795454E-6,1,0.999253354069792,40.0298881530762,2.00790905903815,17.5299998372793,-0.0033878500283324,-0.000595166994095537,0.25,-4.42292790793483E-7,-0.000298160188853896,-8.97142492801574E-7,150.0054932,150.0054932,85434.3125,85454.25,57.1565854687561,20.5729686236662,25.186911,0,0,0,40,4449,149.7561,85444.28125,,,,,,,,,,,,,0,,,,0,,,,,,150.0054932,,,,
,29134589.395,149.9971161,80678.36328125,-0.000271384639157628,2.77330484458911E-6,1,0.999253354069792,40.0298881530762,2.00791717650756,17.5299998372793,-0.00309664102633822,-0.000556605188721553,0.25,-1.47334185393961E-6,-0.000272715914118728,-1.89603287278495E-6,149.9971161,149.9971161,80676.1171875,80680.609375,57.312129544083,20.5740116573468,24.807261,0,0,0,40,4449,149.7607,80678.36328125,,,,,,,,,,,,,0,,,,-0.0049,,,,,,149.9971161,,,,
,29134686.38,149.9924622,75832.03515625,-0.000241328047270617,2.07671326737656E-6,1,0.999253354069792,40.0298881530762,2.00793492124247,17.5299998372793,-0.00275790648244448,-0.000470809481935931,0.25,8.058718710894E-7,-0.000242514890420408,4.39138072825853E-7,149.9924622,149.9924622,75821.9765625,75842.09375,57.4231207938138,20.5737634654173,24.807261,0,0,0,40,4449,149.7676,75832.03515625,,,,,,,,,,,,,0,,,,0,,,,,,149.9924622,,,,
,29134781.51,149.9927216,71076.01953125,-0.000213052386533366,2.31244557569412E-6,1,0.999253354069792,40.0298881530762,2.00780920828951,17.5299998372793,-0.00243888716290278,-0.0003911370754639,0.25,2.85635513085722E-6,-0.000214103246956522,2.54203028052565E-6,149.9927216,149.9927216,71068.7890625,71083.25,57.1440794124484,20.5715146179592,24.807261,0,0,0,40,4449,149.76945,71076.01953125,,,,,,,,,,,,,0,,,,-0.0049,,,,,,149.9927216,,,,
,29134877.205,149.9898376,66292.734375,-0.000187928506167464,1.85965273590391E-6,1,0.999253354069792,40.0298881530762,2.00817251375174,17.5299998372793,-0.00214341051110876,-0.000392406852706281,0.25,-1.62349848068886E-6,-0.000188848870797829,-1.92203078105802E-6,149.9898376,149.9898376,66290.375,66295.09375,57.1972301517561,20.571420659029,24.807261,0,0,0,40,4449,149.7855,66292.734375,,,,,,,,,,,,,0,,,,0,,,,,,149.9898376,,,,
,29134972.115,149.9916534,61549.470703125,-0.000162877841020358,1.92971783166321E-6,1,0.999253354069792,40.0298881530762,2.00807727661707,17.5299998372793,-0.00186023704766777,-0.000325000521400082,0.25,-8.57504704526805E-8,-0.000163677381818417,-3.38817900656199E-7,149.9916534,149.9916534,61541.94140625,61557,56.8165770628906,20.5755249909739,24.807261,0,0,0,40,4449,149.789,61549.470703125,,,,,,,,,,,,,0,,,,0.00245,,,,,,149.9916534,,,,
,29135067.48,149.9897003,56784.16015625,-0.000137629391907635,2.01056256148841E-6,1,0.999253354069792,40.0298881530762,2.00807959478647,17.5299998372793,-0.00157439881608613,-0.000260120302698369,0.25,1.19772343135493E-6,-0.000138306830621335,9.894410626689E-7,149.9897003,149.9897003,56779.03515625,56789.28515625,57.1518956976407,20.5745010594703,24.807261,0,0,0,40,4449,149.797,56784.16015625,,,,,,,,,,,,,0,,,,0,,,,,,149.9897003,,,,
,29135164.185,149.9906464,51949.357421875,-0.000107973042977143,2.03137977429685E-6,1,0.999253354069792,40.0298881530762,2.00809448187115,17.5299998372793,-0.0012357462386771,-0.00020067750684253,0.25,1.23725426180866E-6,-0.000108504859518734,1.07478016158028E-6,149.9906464,149.9906464,51941.6640625,51957.05078125,57.3910740245253,20.5744905721663,25.186911,0,0,0,40,4449,149.80675,51949.357421875,,,,,,,,,,,,,0,,,,0,,,,,,149.9906464,,,,
,29135259.035,149.990097,47209.14453125,-8.28628958035074E-5,1.74435666634922E-6,1,0.999253354069792,40.0298881530762,2.00788869124478,17.5299998372793,-0.000948526155403136,-0.000152512096334328,0.25,1.079568238838E-6,-8.32711572080992E-5,9.55118317314675E-7,149.990097,149.990097,47199.24609375,47219.04296875,57.3566823696791,20.5738789347331,24.807261,0,0,0,40,4449,149.8141,47209.14453125,,,,,,,,,,,,,0,,,,-0.0049,,,,,,149.990097,,,,
,29135353.965,149.9914551,42463.662109375,-5.8260243150578E-5,1.62051511322096E-6,1,0.999253354069792,40.0298881530762,2.00796879692896,17.5299998372793,-0.000663694283111174,-0.000125786698433441,0.25,-8.65063565639888E-7,-5.85446794083787E-5,-9.60807653475447E-7,149.9914551,149.9914551,42456.3125,42471.01171875,57.2910255740638,20.5749447876637,24.427608,0,0,0,40,4449,149.8208,42463.662109375,,,,,,,,,,,,,0,,,,-0.0049,,,,,,149.9914551,,,,
,29135447.925,149.9899445,37768.72265625,-3.07032692231372E-5,1.37049968458196E-6,1,0.999253354069792,40.0298881530762,2.00805383585345,17.5299998372793,-0.000348899737413456,-7.13576142603878E-5,0.25,-8.9921146845274E-7,-3.08524382854293E-5,-9.51982848968552E-7,149.9899445,149.9899445,37758.69921875,37778.74609375,57.4301554504868,20.5748659590052,25.186911,0,0,0,40,4449,149.83085,37768.72265625,,,,,,,,,,,,,0,,,,0,,,,,,149.9899445,,,,
,29135542.025,149.9879761,33064.169921875,-6.86730499467555E-6,1.0778826515963E-6,1,0.999253354069792,40.0298881530762,2.0081374603975,17.5299998372793,-8.16683554889146E-5,4.86626023230829E-6,0.25,1.62228770048864E-6,-6.90354222062056E-6,1.61939516463006E-6,149.9879761,149.9879761,33056.64453125,33071.6953125,56.9963516223137,20.5766732859719,24.807261,0,0,0,40,4449,149.8406,33064.169921875,,,,,,,,,,,,,0,,,,0,,,,,,149.9879761,,,,
,29135638.35,149.9903107,28249.0087890625,1.81288519396099E-5,1.01036396279112E-6,1,0.999253354069792,40.0298881530762,2.00811353469857,17.5299998372793,0.000208895045332241,2.55983521417118E-5,0.25,-9.16941441618707E-7,1.82191824856745E-5,-8.92718773442291E-7,149.9903107,149.9903107,28244.01171875,28254.005859375,57.4051433378714,20.5745644422039,24.807261,0,0,0,40,4449,149.8493,28249.0087890625,,,,,,,,,,,,,0,,,,-0.00245,,,,,,149.9903107,,,,
,29135733.345,149.9896088,23501.28125,4.28213790671532E-5,7.1091213133658E-7,1,0.999253354069792,40.0298881530762,2.00812760777366,17.5299998372793,0.000488807262778025,8.69722197473037E-5,0.25,1.54609794469907E-7,4.30310288719755E-5,2.23385952539793E-7,149.9896088,149.9896088,23496.486328125,23506.076171875,57.5388018146599,20.5764954414611,24.427608,0,0,0,40,4449,149.8578,23501.28125,,,,,,,,,,,,,0,,,,-0.00245,,,,,,149.9896088,,,,
,29135826.455,149.9912109,18846.6591796875,6.65144820374038E-5,8.30257129891334E-7,1,0.999253354069792,40.0298881530762,2.00820239531841,17.5299998372793,0.000760377888116232,0.000128859469809175,0.25,-3.06331752618691E-7,6.68409380342453E-5,-2.01908648210752E-7,149.9912109,149.9912109,18844.0859375,18849.232421875,57.2394380917945,20.5767116302217,24.807261,0,0,0,40,4449,149.8659,18846.6591796875,,,,,,,,,,,,,0,,,,-0.0049,,,,,,149.9912109,,,,
,29135920.32,149.9888763,14156.4331054687,9.02402925231812E-5,5.86380541088004E-7,1,0.999253354069792,40.0298881530762,2.00816175554977,17.5299998372793,0.00103156978375892,0.000174908084067647,0.25,-4.0826475145781E-7,9.06831149181339E-5,-2.66208353422048E-7,149.9888763,149.9888763,14151.345703125,14161.5205078125,57.3965454241599,20.5769907059171,24.427608,0,0,0,40,4449,149.87765,14156.4331054687,,,,,,,,,,,,,0,,,,0,,,,,,149.9888763,,,,
,29136016.445,149.99019625,9354.232421875,0.00011230837640436,5.12239999012039E-7,1,0.999253354069792,40.0298881530762,2.00817786100674,17.5299998372793,0.00128208715838914,0.000227783661896547,0.25,3.75759441025946E-7,0.000112857980791644,5.57307045148584E-7,149.9899445,149.990448,9349.337890625,9359.126953125,57.0205821064099,20.5793758267099,24.427608,0,0,0,40,4449,149.8868,9354.232421875,,,,,,,,,,,,,0,,,,0.0049,,,,,,149.99019625,,,,
,29136109.85,149.9918823,4686.46606445313,0.0001302882909049,4.26012409370431E-7,1,0.999253354069792,40.0298881530762,2.00818880574968,17.5299998372793,0.00148726968400151,0.000264703349240768,0.25,4.75027159001103E-7,0.000130925717302198,6.86265724744633E-7,149.9918823,149.9918823,4681.50244140625,4691.4296875,57.2808644033138,20.5755820283242,25.186911,0,0,0,40,4449,149.892,4686.46606445313,,,,,,,,,,,,,0,,,,-0.00245,,,,,,149.9918823,,,,
,29136202.28,149.9950104,65.1032390594482,4.07505355532251E-5,9.87637219608776E-7,1,0.999253354069792,40.0298881530762,2.00821716714371,17.5299998372793,0.000465935055107556,7.84724510176089E-5,0.25,-2.29764426667691E-7,4.09504847897886E-5,-1.65441389523283E-7,149.9950104,149.9950104,62.5742607116699,67.6322174072266,57.3371416566984,20.5785406149471,24.807261,0,0,0,40,4449,149.89365,65.1032390594482,,,,,,,,,,,,,0,,,,0,,,,,,149.9950104,,,,
,29136204.25,149.995224,-0.388206213712692,8.19485529064541E-7,6.10915620814473E-7,1,0.999253354069792,40.0298881530762,2.00822542050646,17.5299998372793,1.08094400027539E-5,-6.68454163389068E-6,0.25,-7.27973228638213E-7,8.24668231101455E-7,-7.30222384074944E-7,149.995224,149.995224,-0.395818114280701,-0.380594313144684,57.5005020172176,20.5758873894722,25.186911,0,0,0,40,4417,149.89365,-0.388206213712692,,,,,,,,,,,,,0,,,,0.00245,,,,,,149.995224,,,,