File: data/looselyPackedNP/sc-ios-11/ppms/rawdata/ES_S14_HYST_50K.DAT
[Header]
; VSM Data File (default extension .dat)
; Copyright (c) 2003-2013, Quantum Design, Inc. All rights reserved.
TITLE,
FILEOPENTIME,29101996.09,12/04/2018,3:54 am
BYAPP,VSM,2.0,2.0
INFO,PPMS VSM Option Release 1.4.10 Build 1,APPNAME
INFO,Quantum Design Linear Motor Servo Controller,MOTOR_MODULE_NAME
INFO,3101-100 M1,MOTOR_HW_VERSION
INFO,MMC1014,MOTOR_SERIAL_NUMBER
INFO,SRV No X-over 01.03.11,MOTOR_SOFTWARE_VERSION
INFO,Quantum Design VSM Detection Module,VSM_MODULE_NAME
INFO,3101-150 F0,VSM_HW_VERSION
INFO,VSM707,VSM_SERIAL_NUMBER
INFO,VSM No X-over 01.02.05 May 20 2008 13:51:47,VSM_SOFTWARE_VERSION
INFO,704,PREAMP_SERIAL_NUMBER
INFO,822,COIL_SERIAL_NUMBER
INFO,0,MOMENT_UNITS
INFO,Iron Oxide Spheres,SAMPLE_MATERIAL
INFO,10 nm diameter, collaboration Mainz,SAMPLE_COMMENT
INFO,,SAMPLE_MASS
INFO,,SAMPLE_VOLUME
INFO,,SAMPLE_MOLECULAR_WEIGHT
INFO,,SAMPLE_SIZE
INFO,,SAMPLE_SHAPE
DATATYPE,COMMENT,1
DATATYPE,TIME,2
STARTUPAXIS,X,2
STARTUPAXIS,Y1,5
[Data]
Comment,Time Stamp (sec),Temperature (K),Magnetic Field (Oe),Moment (emu),M. Std. Err. (emu),Transport Action,Averaging Time (sec),Frequency (Hz),Peak Amplitude (mm),Center Position (mm),Coil Signal' (mV),Coil Signal" (mV),Range (mV),M. Quad. Signal (emu),M. Raw' (emu),M. Raw" (emu),Min. Temperature (K),Max. Temperature (K),Min. Field (Oe),Max. Field (Oe),Mass (grams),Motor Lag (deg),Pressure (Torr),VSM Status (code),Motor Status (code),Measure Status (code),Measure Count,PPMS Status (code),System Temp. (K),System Field (Oe),Sample Position (deg),Bridge 1 Resistance (ohms),Bridge 1 Excitation (에),Bridge 2 Resistance (ohms),Bridge 2 Excitation (에),Bridge 3 Resistance (ohms),Bridge 3 Excitation (에),Bridge 4 Resistance (ohms),Bridge 4 Excitation (에),Signal 1 Vin (V),Signal 2 Vin (V),Digital Inputs (code),Drive 1 Iout (mA),Drive 1 Ipower (W),Drive 2 Iout (mA),Drive 2 Ipower (W),Pressure (),Map 20 (),Map 21 (),Map 22 (),Map 23 (),Map 24 (),Map 25 (),Map 26 (),Map 27 (),Map 28 (),Map 29 ()
,29102011.66,50.0100784,0.395818114280701,,,2,,,,18.0200000545382,,,,,,,50.0100784,50.0100784,0.395818114280701,0.395818114280701,,,17.214239,,,,-99999999,4369,50.0214,0.395818114280701,,,,,,,,,,,,,,,,,,,,,,,50.0100784,,,,
,29102167.62,50.0013275,4761.27587890625,0.000132320554783404,3.7840963937901E-7,1,0.999253354069792,40.0298881530762,1.9843695789372,18.0099997669458,0.001484294452051,0.000271555650843221,0.25,3.45862804087875E-7,0.000132270429451331,1.33042312219116E-6,50.0013275,50.0013275,4756.36474609375,4766.18701171875,56.7337244398522,20.5680869580147,17.214239,0,0,0,40,4449,50.0278,4761.27587890625,,,,,,,,,,,,,0,,,,0,,,,,,50.0013275,,,,
,29102260.57,49.9990616,9402.48095703125,0.000113638445576299,4.76890500202377E-7,1,0.999253354069792,40.0298881530762,1.9845472304299,18.0099997669458,0.00127585355235307,0.000229286014046504,0.25,-5.90374649188068E-8,0.000113624206291245,7.8633378552541E-7,49.9990616,49.9990616,9397.2265625,9407.7353515625,56.7391958394868,20.570185775165,17.593889,0,0,0,40,4449,50.02865,9402.48095703125,,,,,,,,,,,,,0,,,,-0.0049,,,,,,49.9990616,,,,
,29102351.195,49.9988518,13932.8071289062,9.1630454399848E-5,3.98672762462143E-7,1,0.999253354069792,40.0298881530762,1.98447253491157,18.0099997669458,0.0010296555463685,0.000181135720913259,0.25,-3.83405493236553E-7,9.16435253592886E-5,2.97248788341146E-7,49.9988518,49.9988518,13920.37109375,13945.2431640625,56.7126204698329,20.5700227567722,17.593889,0,0,0,40,4449,50.0301,13932.8071289062,,,,,,,,,,,,,0,,,,-0.00245,,,,,,49.9988518,,,,
,29102443.945,50.00000765,18570.1845703125,6.82262757632347E-5,4.31622607819102E-7,1,0.999253354069792,40.0298881530762,1.98466695915604,18.0099997669458,0.00076707410723609,0.000134100638907737,0.25,-3.56698010236776E-7,6.82537700416157E-5,1.48690477576174E-7,49.9999619,50.0000534,18557.3515625,18583.017578125,56.8681645451599,20.5713349007911,17.973541,0,0,0,40,4449,50.02785,18570.1845703125,,,,,,,,,,,,,0,,,,0.00245,,,,,,50.00000765,,,,
,29102536.115,50.0010223,23177.93359375,4.38229886419851E-5,5.34160465736479E-7,1,0.999253354069792,40.0298881530762,1.98451693193158,18.0099997669458,0.000493528214384225,8.20875888261215E-5,0.25,-5.89480866490319E-7,4.38545171291125E-5,-2.66386929841072E-7,50.0010223,50.0010223,23165.48828125,23190.37890625,56.8931766577752,20.5730561197996,17.214239,0,0,0,40,4449,50.03465,23177.93359375,,,,,,,,,,,,,0,,,,0.00245,,,,,,50.0010223,,,,
,29102630.975,50.0000725,27918.076171875,1.90868031128103E-5,5.79452236791325E-7,1,0.999253354069792,40.0298881530762,1.98477925637024,18.0099997669458,0.000216887777065726,2.54831667226275E-5,0.25,-1.17094504111785E-6,1.9112172172789E-5,-1.03181542360376E-6,50.0000725,50.0000725,27913.13671875,27923.015625,56.9041194570445,20.5707173920183,17.973541,0,0,0,40,4449,50.027,27918.076171875,,,,,,,,,,,,,0,,,,0.00245,,,,,,50.0000725,,,,
,29102725.555,50.0004196,32645.5556640625,-6.14381124505841E-6,8.12638086423415E-7,1,0.999253354069792,40.0298881530762,1.98458796848381,18.0099997669458,-6.61382341512992E-5,-2.86743172936322E-5,0.25,-1.44442967156998E-6,-6.14024368789562E-6,-1.4908971043789E-6,50.0004196,50.0004196,32635.48046875,32655.630859375,57.0502839901407,20.57215402063,17.973541,0,0,0,40,4449,50.0258,32645.5556640625,,,,,,,,,,,,,0,,,,0,,,,,,50.0004196,,,,
,29102820.49,50.0009689,37390.87109375,-3.24211889020876E-5,1.05061984887775E-6,1,0.999253354069792,40.0298881530762,1.98482534076985,18.0099997669458,-0.000360184413660131,-9.0065902058498E-5,0.25,-2.172407881274E-6,-3.2450434184296E-5,-2.41019315184217E-6,50.0009689,50.0009689,37383.3203125,37398.421875,56.9658681100637,20.5706775806301,17.973541,0,0,0,40,4449,50.02725,37390.87109375,,,,,,,,,,,,,0,,,,0.0049,,,,,,50.0009689,,,,
,29102917.565,50.0013733,42240.68359375,-5.95689302577796E-5,1.03698305996526E-6,1,0.999253354069792,40.0298881530762,1.98472876714679,18.0099997669458,-0.000665538395607842,-0.000145417739337346,0.25,-2.20845621200528E-6,-5.96506963069593E-5,-2.6396060916207E-6,50.0013733,50.0013733,42235.6015625,42245.765625,57.2769562607176,20.5733467239837,17.593889,0,0,0,40,4449,50.0296,42240.68359375,,,,,,,,,,,,,0,,,,0,,,,,,50.0013733,,,,
,29103010.105,50.0018158,46865.857421875,-8.48154497719671E-5,1.04576008284399E-6,1,0.999253354069792,40.0298881530762,1.98469254284288,18.0099997669458,-0.000948454557726409,-0.00020351531554127,0.25,-2.83225460945518E-6,-8.49538832896921E-5,-3.44056836530177E-6,50.0018158,50.0018158,46858.04296875,46873.671875,57.2073913225061,20.5722744114728,17.593889,0,0,0,40,4449,50.02355,46865.857421875,,,,,,,,,,,,,0,,,,0,,,,,,50.0018158,,,,
,29103104.565,50.0015945,51586.224609375,-0.000111376739571656,9.03801985106055E-7,1,0.999253354069792,40.0298881530762,1.9847933702795,18.0099997669458,-0.0012441923746878,-0.000276406723823564,0.25,-4.53484485391984E-6,-0.000111578568000988,-5.32788714592685E-6,50.0015945,50.0015945,51576.15625,51596.29296875,57.0283983916022,20.5736832784775,17.593889,0,0,0,40,4449,50.0234,51586.224609375,,,,,,,,,,,,,0,,,,0.0049,,,,,,50.0015945,,,,
,29103200.29,50.0024757,56371.052734375,-0.000137859092107765,1.15223145572997E-6,1,0.999253354069792,40.0298881530762,1.9847907499894,18.0099997669458,-0.00154450631778256,-0.000319211998559961,0.25,-3.58173867394757E-6,-0.000138154342896372,-4.548684874078E-6,50.0024757,50.0024757,56358.58203125,56383.5234375,57.0698247031214,20.5703576338798,17.214239,0,0,0,40,4449,50.02505,56371.052734375,,,,,,,,,,,,,0,,,,-0.0049,,,,,,50.0024757,,,,
,29103294.985,50.0021172,61106.736328125,-0.000162049690478097,1.29222233142535E-6,1,0.999253354069792,40.0298881530762,1.98500168678656,18.0099997669458,-0.0018168996667493,-0.000370882259508079,0.25,-3.82797836447255E-6,-0.0001624341666062,-4.95078847436527E-6,50.0021172,50.0021172,61096.70703125,61116.765625,57.2660134614484,20.5683171076369,17.593889,0,0,0,40,4449,50.02545,61106.736328125,,,,,,,,,,,,,0,,,,-0.00245,,,,,,50.0021172,,,,
,29103389.92,50.0021324,65849.4140625,-0.000191095260306176,1.14104455459715E-6,1,0.999253354069792,40.0298881530762,1.98469683459718,18.0099997669458,-0.00214578413581222,-0.000420100048087858,0.25,-2.99628902006745E-6,-0.00019159811831494,-4.30026611710388E-6,50.0021324,50.0021324,65844.6796875,65854.1484375,56.9908802226791,20.570939535048,17.214239,0,0,0,40,4449,50.01915,65849.4140625,,,,,,,,,,,,,0,,,,-0.00245,,,,,,50.0021324,,,,
,29103487.125,50.0025291,70707.125,-0.000215206259163866,1.3504090358562E-6,1,0.999253354069792,40.0298881530762,1.98475504209108,18.0099997669458,-0.00241067021453584,-0.000508904267001248,0.25,-6.56359167130795E-6,-0.000215794577394464,-8.02191092054564E-6,50.0025291,50.0025291,70697.1015625,70717.1484375,57.027616763083,20.5722239561027,17.593889,0,0,0,40,4449,50.02075,70707.125,,,,,,,,,,,,,0,,,,0.00245,,,,,,50.0025291,,,,
,29103583.725,50.0026665,75537.42578125,-0.00024423231336038,1.12164484585229E-6,1,0.999253354069792,40.0298881530762,1.98473664242498,18.0099997669458,-0.00273751030803828,-0.000570949571565724,0.25,-6.87789888680513E-6,-0.000244950676894233,-8.50913826711258E-6,50.0026665,50.0026665,75530.0625,75544.7890625,56.9220969129868,20.5739230342256,18.353191,0,0,0,40,4449,50.01935,75537.42578125,,,,,,,,,,,,,0,,,,0.00245,,,,,,50.0026665,,,,
,29103679.675,50.0021057,80333.56640625,-0.000269801305458941,1.19058568670746E-6,1,0.999253354069792,40.0298881530762,1.98464677527632,18.0099997669458,-0.00303172285452478,-0.000590615862794914,0.25,-4.05703359599399E-6,-0.000270666829185794,-5.82257805501742E-6,50.0021057,50.0021057,80328.53125,80338.6015625,57.0291800201214,20.5726030666994,17.973541,0,0,0,40,4449,50.0149,80333.56640625,,,,,,,,,,,,,0,,,,-0.0049,,,,,,50.0021057,,,,
,29103774.22,50.0020962,85059.13671875,-0.000295876464142805,1.09249871782735E-6,1,0.999253354069792,40.0298881530762,1.98482190185143,18.0099997669458,-0.00332371309319517,-0.000658210803630167,0.25,-5.39649611286464E-6,-0.0002968698478603,-7.30796437622391E-6,50.0020142,50.0021782,85046.4921875,85071.78125,57.0104209356599,20.5707166740118,18.353191,0,0,0,40,4449,50.0165,85059.13671875,,,,,,,,,,,,,0,,,,0,,,,,,50.0020962,,,,
,29103865.645,50.0023918,89629.93359375,-0.00032067577558524,1.48168565472229E-6,1,0.999253354069792,40.0298881530762,1.98454491920687,18.0099997669458,-0.00360014564081877,-0.000725843661204474,0.25,-6.98383633114284E-6,-0.000321795467263346,-9.03020640183837E-6,50.0023918,50.0023918,89620.28125,89639.5859375,57.0385595623522,20.5729366453564,17.973541,0,0,0,40,4449,50.0143,89629.93359375,,,,,,,,,,,,,0,,,,-0.00245,,,,,,50.0023918,,,,
,29103976.335,50.0003395,85901.625,-0.000298196731132969,1.26528475742908E-6,1,0.999253354069792,40.0298881530762,1.98474777366674,18.0099997669458,-0.00334081036736909,-0.000713305549966399,0.25,-9.87492919592849E-6,-0.000299178345823087,-1.181192189678E-5,50.0003395,50.0003395,85894.3203125,85908.9296875,57.0792042453522,20.5715767507267,18.353191,0,0,0,40,4449,50.01505,85901.625,,,,,,,,,,,,,0,,,,0,,,,,,50.0003395,,,,
,29104069.295,49.9992447,81250.84375,-0.000272123277492322,9.86801826896431E-7,1,0.999253354069792,40.0298881530762,1.98459221855472,18.0099997669458,-0.003052328568691,-0.000626437153298791,0.25,-6.82482361803323E-6,-0.000272987761123157,-8.60969076669827E-6,49.9992447,49.9992447,81241,81260.6875,57.058100275333,20.5736758015874,17.593889,0,0,0,40,4449,50.0167,81250.84375,,,,,,,,,,,,,0,,,,0,,,,,,49.9992447,,,,
,29104165.43,50.0009613,76446.81640625,-0.000245793137843894,1.28073091171667E-6,1,0.999253354069792,40.0298881530762,1.98488956664846,18.0099997669458,-0.00275296440419735,-0.000587702024668574,0.25,-8.08386346162009E-6,-0.000246517017586741,-9.72498977472524E-6,50.0009613,50.0009613,76437.1171875,76456.515625,57.180034324333,20.571014611213,17.973541,0,0,0,40,4449,50.0166,76446.81640625,,,,,,,,,,,,,0,,,,0.0049,,,,,,50.0009613,,,,
,29104260.22,49.9998589,71708.5546875,-0.000220049090278029,1.3808460225673E-6,1,0.999253354069792,40.0298881530762,1.98471421016276,18.0099997669458,-0.00246488951819913,-0.000520797305627934,0.25,-6.75381539658828E-6,-0.000220659095690506,-8.24111082188153E-6,49.9998589,49.9998589,71698.46875,71718.640625,57.1534589546791,20.5735687854451,17.973541,0,0,0,40,4449,50.0138,71708.5546875,,,,,,,,,,,,,0,,,,-0.00245,,,,,,49.9998589,,,,
,29104354.03,49.9996414,67017.78125,-0.000192737603592716,8.48620382272173E-7,1,0.999253354069792,40.0298881530762,1.98450817217383,18.0099997669458,-0.00215936710276972,-0.000450250064211753,0.25,-5.38490064859872E-6,-0.000193238267141966,-6.70253350252378E-6,49.9996414,49.9996414,67005.0859375,67030.4765625,57.2925888311022,20.5739395942102,18.353191,0,0,0,40,4449,50.01775,67017.78125,,,,,,,,,,,,,0,,,,-0.0049,,,,,,49.9996414,,,,
,29104449.005,49.9996567,62271.783203125,-0.000165843376595012,8.80696286049807E-7,1,0.999253354069792,40.0298881530762,1.98457743521872,18.0099997669458,-0.00185763117552747,-0.000387943917056804,0.25,-4.67056616303253E-6,-0.000166239941683206,-5.81836537816549E-6,49.9996567,49.9996567,62266.44921875,62277.1171875,56.9517987967176,20.5722350715027,17.593889,0,0,0,40,4449,50.0146,62271.783203125,,,,,,,,,,,,,0,,,,0,,,,,,49.9996567,,,,
,29104545.76,49.9984055,57433.837890625,-0.00013794279007794,8.68811000496295E-7,1,0.999253354069792,40.0298881530762,1.98491308081289,18.0099997669458,-0.00154584339881168,-0.000318127361778726,0.25,-3.46986405212031E-6,-0.000138245518790814,-4.43481610011306E-6,49.9984055,49.9984055,57428.66796875,57439.0078125,57.0964000727753,20.5714912835923,17.593889,0,0,0,40,4449,50.01455,57433.837890625,,,,,,,,,,,,,0,,,,0.0049,,,,,,49.9984055,,,,
,29104639.775,49.9999523,52736.228515625,-0.000110321337841846,1.13580493085261E-6,1,0.999253354069792,40.0298881530762,1.98443296031161,18.0099997669458,-0.00123814603039187,-0.00024099158318451,0.25,-1.58223259411346E-6,-0.000110547662970447,-2.35967531010285E-6,49.9999046,50,52731.40234375,52741.0546875,57.1878506095253,20.5762344584105,17.593889,0,0,0,40,4449,50.01805,52736.228515625,,,,,,,,,,,,,0,,,,0.0049,,,,,,49.9999523,,,,
,29104735.88,49.9996681,47933.58984375,-8.42276175748545E-5,9.32376734553957E-7,1,0.999253354069792,40.0298881530762,1.98476492253934,18.0099997669458,-0.000942812377415834,-0.000197393947883284,0.25,-2.39374652124518E-6,-8.43723711026005E-5,-2.99584830776159E-6,49.9996681,49.9996681,47923.5234375,47943.65625,57.3387049137368,20.5750501460481,17.973541,0,0,0,40,4449,50.0136,47933.58984375,,,,,,,,,,,,,0,,,,0,,,,,,49.9996681,,,,
,29104829.115,49.9999237,43270.87890625,-5.75063983189052E-5,9.25641926504365E-7,1,0.999253354069792,40.0298881530762,1.98490384959519,18.0099997669458,-0.000643933788237761,-0.000132880211166649,0.25,-1.46418083222337E-6,-5.75929542939126E-5,-1.87859995970032E-6,49.9999237,49.9999237,43260.734375,43281.0234375,57.065134932006,20.5747080922594,17.973541,0,0,0,40,4449,50.01255,43270.87890625,,,,,,,,,,,,,0,,,,0.00245,,,,,,49.9999237,,,,
,29104924.38,49.999321,38510.88671875,-3.27005889049459E-5,8.94296888307423E-7,1,0.999253354069792,40.0298881530762,1.98488813619161,18.0099997669458,-0.000362494665423597,-9.54347883077065E-5,0.25,-2.59926223848323E-6,-3.27289971857538E-5,-2.83936726561187E-6,49.999321,49.999321,38503.3359375,38518.4375,57.1534589546791,20.575653896441,17.973541,0,0,0,40,4449,50.0153,38510.88671875,,,,,,,,,,,,,0,,,,0.00245,,,,,,49.999321,,,,
,29105016.985,50.0000992,33883.447265625,-7.54269110432542E-6,6.57059867694249E-7,1,0.999253354069792,40.0298881530762,1.98504146729891,18.0099997669458,-8.17864386293054E-5,-3.20696830219821E-5,0.25,-1.49385043557446E-6,-7.54085239768375E-6,-1.55057750441843E-6,50.0000992,50.0000992,33875.89453125,33891,57.474708276083,20.5718664238,17.973541,0,0,0,40,4449,50.01555,33883.447265625,,,,,,,,,,,,,0,,,,0.00245,,,,,,50.0000992,,,,
,29105110.71,50.000885,29198.548828125,1.74920469015153E-5,4.77301454279316E-7,1,0.999253354069792,40.0298881530762,1.98492805958237,18.0099997669458,0.000199103860025962,2.1634220502382E-5,0.25,-1.22618355290666E-6,1.75175724323243E-5,-1.09909191702716E-6,50.000885,50.000885,29193.67578125,29203.421875,57.4067065949099,20.5723103435534,17.973541,0,0,0,40,4449,50.014,29198.548828125,,,,,,,,,,,,,0,,,,0.0049,,,,,,50.000885,,,,
,29105203.9,50.0007668,24540.56640625,4.18616076173472E-5,7.03523152690076E-7,1,0.999253354069792,40.0298881530762,1.98499591837101,18.0099997669458,0.00047122723325261,8.03985484782411E-5,0.25,-3.88152502459303E-7,4.18933275536978E-5,-7.98237153614779E-8,50.0007668,50.0007668,24530.708984375,24550.423828125,57.0901470446214,20.5744345798499,17.973541,0,0,0,40,4449,50.01215,24540.56640625,,,,,,,,,,,,,0,,,,0,,,,,,50.0007668,,,,
,29105298.035,50.0010796,19835.8486328125,6.64932467280496E-5,6.15431841135596E-7,1,0.999253354069792,40.0298881530762,1.98490911818766,18.0099997669458,0.000747199245266461,0.000133635497143936,0.25,-8.74952290864219E-8,6.6522422574074E-5,4.04723163240358E-7,50.0010796,50.0010796,19828.501953125,19843.1953125,57.0745144742368,20.5735759251206,18.353191,0,0,0,40,4449,50.0099,19835.8486328125,,,,,,,,,,,,,0,,,,0.00245,,,,,,50.0010796,,,,
,29105390.915,50.0006409,15193.3642578125,8.9029566085479E-5,5.16010522253367E-7,1,0.999253354069792,40.0298881530762,1.98499579826324,18.0099997669458,0.00100031855094623,0.000178421016701725,0.25,-1.61018961396163E-7,8.9046452839821E-5,4.99962241519218E-7,50.0006409,50.0006409,15181.1474609375,15205.5810546875,57.1729996676599,20.5742980561998,17.973541,0,0,0,40,4449,50.01735,15193.3642578125,,,,,,,,,,,,,0,,,,0.00245,,,,,,50.0006409,,,,
,29105482.64,50.0002365,10611.2216796875,0.000111249841073696,3.99034401981098E-7,1,0.999253354069792,40.0298881530762,1.98500381983263,18.0099997669458,0.00124845571699573,0.000229681570643252,0.25,4.01284453465618E-7,0.000111239073739818,1.22864849126289E-6,50.0002365,50.0002365,10608.7607421875,10613.6826171875,57.0627900464484,20.5748267620532,17.973541,0,0,0,40,4449,50.01595,10611.2216796875,,,,,,,,,,,,,0,,,,0.0049,,,,,,50.0002365,,,,
,29105575.015,50.0014,5993.18627929688,0.000129923938795275,3.34381138604056E-7,1,0.999253354069792,40.0298881530762,1.98497482103967,18.0099997669458,0.00145763486156028,0.00026829316740406,0.25,4.78908168891021E-7,0.00012988094091537,1.44561575850855E-6,50.0014,50.0014,5980.8447265625,6005.52783203125,57.3277621144676,20.5749369823183,17.973541,0,0,0,40,4449,50.01905,5993.18627929688,,,,,,,,,,,,,0,,,,0,,,,,,50.0014,,,,
,29105667.11,50.0003662,1387.27990722656,0.000132094608128023,3.33420169820961E-7,1,0.999253354069792,40.0298881530762,1.98508963153786,18.0099997669458,0.00148177155729837,0.000272714019144682,0.25,4.85111603025782E-7,0.000132023996107406,1.4675928583759E-6,50.0003662,50.0003662,1377.111328125,1397.44848632812,57.4309370790061,20.5739742208866,17.593889,0,0,0,40,4449,50.01645,1387.27990722656,,,,,,,,,,,,,0,,,,0,,,,,,50.0003662,,,,
,29105761.39,50.0005112,-3318.14013671875,-0.00013525549145898,3.01016322767348E-7,1,0.999253354069792,40.0298881530762,1.98508394102104,18.0099997669458,-0.00151580755839415,-0.000287776463883048,0.25,-1.25518917109023E-6,-0.000135188052111367,-2.26109090160035E-6,50.0005112,50.0005112,-3325.470703125,-3310.8095703125,57.2730481181214,20.5728414489691,17.973541,0,0,0,40,4449,50.01255,-3318.14013671875,,,,,,,,,,,,,0,,,,0.0049,,,,,,50.0005112,,,,
,29105852.67,49.9996223,-7882.85302734375,-0.000121774521469846,3.81332202857746E-7,1,0.999253354069792,40.0298881530762,1.98482633961815,18.0099997669458,-0.00136509704471434,-0.000257781895154216,0.25,-1.01127503375445E-6,-0.000121741352106471,-1.91716145188388E-6,49.9996223,49.9996223,-7885.3525390625,-7880.353515625,57.1581487257945,20.5755332754949,18.353191,0,0,0,40,4449,50.0167,-7882.85302734375,,,,,,,,,,,,,0,,,,0,,,,,,49.9996223,,,,
,29105948.075,50.0012741,-12648.2221679688,-0.000101379238283549,4.43885904824639E-7,1,0.999253354069792,40.0298881530762,1.98490257685444,18.0099997669458,-0.00113679762801419,-0.000214613741118588,0.25,-8.38027588066939E-7,-0.00010137671301619,-1.59158787039217E-6,50.0012741,50.0012741,-12658.0625,-12638.3818359375,57.1081245005637,20.5750508417779,18.353191,0,0,0,40,4449,50.0102,-12648.2221679688,,,,,,,,,,,,,0,,,,0,,,,,,50.0012741,,,,
,29106041.805,49.9997063,-17335.9638671875,-7.8567629445425E-5,4.57207510435687E-7,1,0.999253354069792,40.0298881530762,1.98487133725375,18.0099997669458,-0.000882564712331601,-0.000158880758835433,0.25,1.51650381993315E-8,-7.85907385278158E-5,-5.67470600116604E-7,49.9997063,49.9997063,-17340.9609375,-17330.966796875,57.2581971762561,20.5762126810464,17.973541,0,0,0,40,4449,50.01465,-17335.9638671875,,,,,,,,,,,,,0,,,,0.00245,,,,,,49.9997063,,,,
,29106135.835,50.0003014,-22035.5068359375,-5.50276708004278E-5,6.13462132842941E-7,1,0.999253354069792,40.0298881530762,1.98519851019177,18.0099997669458,-0.000619312895864059,-0.000106216462500503,0.25,4.63592191892302E-7,-5.5061391087775E-5,5.72115800415109E-8,50.0003014,50.0003014,-22042.888671875,-22028.125,57.4387533641984,20.5747093490197,17.973541,0,0,0,40,4449,50.0099,-22035.5068359375,,,,,,,,,,,,,0,,,,0.00245,,,,,,50.0003014,,,,
,29106231.135,50.0007057,-26798.5283203125,-3.07909979175285E-5,7.71418526725092E-7,1,0.999253354069792,40.0298881530762,1.98479359673324,18.0099997669458,-0.000346327870793719,-6.07408280722461E-5,0.25,1.42303681613919E-7,-3.08170705734818E-5,-8.40094939747808E-8,50.0007057,50.0007057,-26811.173828125,-26785.8828125,57.3644986548715,20.5785475170279,17.593889,0,0,0,40,4449,50.009,-26798.5283203125,,,,,,,,,,,,,0,,,,0,,,,,,50.0007057,,,,
,29106325.515,50.0022049,-31515.892578125,-6.1930480334273E-6,5.07135299243212E-7,1,0.999253354069792,40.0298881530762,1.98508938891306,18.0099997669458,-7.03347306561624E-5,-8.61632327281698E-6,0.25,3.49021333675635E-7,-6.20222973517573E-6,3.0412965684574E-7,50.0022049,50.0022049,-31523.375,-31508.41015625,57.2964969736984,20.5765108866191,17.973541,0,0,0,40,4449,50.0124,-31515.892578125,,,,,,,,,,,,,0,,,,-0.0049,,,,,,50.0022049,,,,
,29106421.335,50.001152,-36302.6171875,1.83519507735371E-5,7.9363614681272E-7,1,0.999253354069792,40.0298881530762,1.9849084184583,18.0099997669458,0.000204130346600091,4.9573724951376E-5,0.25,1.10431366223999E-6,1.83682620577818E-5,1.23893308478405E-6,50.001152,50.001152,-36309.94921875,-36295.28515625,57.6443216647561,20.5775365319799,18.353191,0,0,0,40,4449,50.0071,-36302.6171875,,,,,,,,,,,,,0,,,,-0.00245,,,,,,50.001152,,,,
,29106515.37,50.000721,-41002.556640625,4.36015025593649E-5,5.46268912136172E-7,1,0.999253354069792,40.0298881530762,1.9850066326929,18.0099997669458,0.000488545088420652,9.88213303528987E-5,0.25,9.37854829321438E-7,4.36632365505343E-5,1.25305765886426E-6,50.000721,50.000721,-41012.58984375,-40992.5234375,57.1980117802753,20.5736918543725,17.973541,0,0,0,40,4449,50.00735,-41002.556640625,,,,,,,,,,,,,0,,,,-0.0049,,,,,,50.000721,,,,
,29106610.5,50.0008965,-45757.7421875,7.02639632824908E-5,9.43047394165077E-7,1,0.999253354069792,40.0298881530762,1.98540567097006,18.0099997669458,0.000786714664272937,0.000164426325107434,0.25,1.97001022044014E-6,7.0377208677393E-5,2.47438256075715E-6,50.0008965,50.0008965,-45760.4375,-45755.046875,57.4965938746215,20.5700290719946,18.353191,0,0,0,40,4449,50.0079,-45757.7421875,,,,,,,,,,,,,0,,,,0.0049,,,,,,50.0008965,,,,
,29106704.51,50.0009499,-50454.8671875,9.46762354474376E-5,1.11818688848023E-6,1,0.999253354069792,40.0298881530762,1.98501844619251,18.0099997669458,0.0010602151981363,0.000220898132158663,0.25,2.60236638534517E-6,9.48511482085377E-5,3.27556079776247E-6,50.0009499,50.0009499,-50467.390625,-50442.34375,57.159711982833,20.5751975318419,17.973541,0,0,0,40,4449,50.00705,-50454.8671875,,,,,,,,,,,,,0,,,,0.00245,,,,,,50.0009499,,,,
,29106799.36,50.0013657,-55196.94921875,0.000120712963091088,1.02697781723901E-6,1,0.999253354069792,40.0298881530762,1.98509144989087,18.0099997669458,0.00135188547729189,0.00028310784936536,0.25,3.45104807611634E-6,0.000120962358970006,4.30085293790805E-6,50.0013657,50.0013657,-55204.3828125,-55189.515625,57.4215575367753,20.578871945404,17.973541,0,0,0,40,4449,50.0084,-55196.94921875,,,,,,,,,,,,,0,,,,-0.00245,,,,,,50.0013657,,,,
,29106892.585,50.0008125,-59854.41796875,0.000147064472123983,1.19973256480514E-6,1,0.999253354069792,40.0298881530762,1.98505799225989,18.0099997669458,0.00164828105066402,0.000339647021487257,0.25,3.74323234412683E-6,0.000147402823240174,4.76623111012922E-6,50.0008125,50.0008125,-59861.87109375,-59846.96484375,57.5622506702369,20.5773178490643,17.973541,0,0,0,40,4449,50.00465,-59854.41796875,,,,,,,,,,,,,0,,,,0,,,,,,50.0008125,,,,
,29106990.16,50.0021362,-64731.65625,0.00017445850436244,1.02015720456354E-6,1,0.999253354069792,40.0298881530762,1.98508063861675,18.0099997669458,0.00195551835781021,0.000404285409721061,0.25,4.57020743358059E-6,0.000174896400920995,5.76932594623269E-6,50.0021362,50.0021362,-64739.0859375,-64724.2265625,57.3058765159291,20.5774436548321,17.593889,0,0,0,40,4449,50.00425,-64731.65625,,,,,,,,,,,,,0,,,,0.0049,,,,,,50.0021362,,,,
,29107086.025,50.002594,-69521.140625,0.000198916648694987,1.28531407456587E-6,1,0.999253354069792,40.0298881530762,1.9849433758417,18.0099997669458,0.00223059055703019,0.000457570940007966,0.25,4.92266533107502E-6,0.000199457906902438,6.27185573131471E-6,50.002594,50.002594,-69531.0625,-69511.21875,57.4739266475638,20.5785599149075,18.353191,0,0,0,40,4449,50.00185,-69521.140625,,,,,,,,,,,,,0,,,,0,,,,,,50.002594,,,,
,29107180.54,50.0021706,-74245.69140625,0.000224558877275534,9.56485697646109E-7,1,0.999253354069792,40.0298881530762,1.98496499006983,18.0099997669458,0.00251457703154584,0.000539294199446107,0.25,7.58755158311623E-6,0.000225199210626203,9.09698967190084E-6,50.0021706,50.0021706,-74248.140625,-74243.2421875,57.3691884259868,20.5787042513146,18.353191,0,0,0,40,4449,50.00395,-74245.69140625,,,,,,,,,,,,,0,,,,-0.0049,,,,,,50.0021706,,,,
,29107278.675,50.0015831,-79150.0625,0.000252093847557117,1.16824169613993E-6,1,0.999253354069792,40.0298881530762,1.98492906746566,18.0099997669458,0.00282635466067214,0.000588993882017645,0.25,7.07606879339877E-6,0.000252869757845351,8.74255190634645E-6,50.0015831,50.0015831,-79155.09375,-79145.03125,57.3058765159291,20.5800345137107,18.353191,0,0,0,40,4449,50.0036,-79150.0625,,,,,,,,,,,,,0,,,,0,,,,,,50.0015831,,,,
,29107375.12,50.0012169,-83969.82421875,0.000276727799279594,1.22140145186377E-6,1,0.999253354069792,40.0298881530762,1.98512584113481,18.0099997669458,0.00310314819506072,0.000647983827254377,0.25,7.90682336139032E-6,0.000277627270201772,9.71077747945599E-6,50.0012169,50.0012169,-83982.2734375,-83957.375,57.4973755031407,20.5797635338639,17.973541,0,0,0,40,4449,49.99695,-83969.82421875,,,,,,,,,,,,,0,,,,-0.00245,,,,,,50.0012169,,,,
,29107466.365,50.0011444,-88529.21484375,0.000303496867429934,1.04146771837304E-6,1,0.999253354069792,40.0298881530762,1.9850213880487,18.0099997669458,0.00340147807363258,0.000723134012359545,0.25,9.79978562628018E-6,0.000304524620530776,1.17549785123248E-5,50.0011444,50.0011444,-88534.1171875,-88524.3125,57.4403166212368,20.5798682816799,17.973541,0,0,0,40,4449,49.9989,-88529.21484375,,,,,,,,,,,,,0,,,,0.00245,,,,,,50.0011444,,,,
,29107577.625,50.00018885,-87016.48828125,0.000291256105907282,1.32011164368821E-6,1,0.999253354069792,40.0298881530762,1.98516771258595,18.0099997669458,0.00326721659927979,0.000677968264611231,0.25,7.97483025159522E-6,0.000292236263115143,9.85479472149296E-6,50.0001526,50.0002251,-87024.203125,-87008.7734375,57.2324034351214,20.5777552060516,18.353191,0,0,0,40,4449,49.9973,-87016.48828125,,,,,,,,,,,,,0,,,,-0.0049,,,,,,50.00018885,,,,
,29107669.235,50.0011444,-82437.34765625,0.000268719077430463,1.11909648593568E-6,1,0.999253354069792,40.0298881530762,1.98502285177367,18.0099997669458,0.00301540314743765,0.000615908684920725,0.25,6.49327371372878E-6,0.000269585449859741,8.2490000087208E-6,50.0011444,50.0011444,-82447.3359375,-82427.359375,57.4168677656599,20.5787865516451,17.973541,0,0,0,40,4449,50.00105,-82437.34765625,,,,,,,,,,,,,0,,,,-0.00245,,,,,,50.0011444,,,,
,29107766.315,49.9994965,-77584.76171875,0.000242653097174646,9.13493243826628E-7,1,0.999253354069792,40.0298881530762,1.98509183908268,18.0099997669458,0.00271550800043214,0.000595135843634849,0.25,9.30482730345696E-6,0.000243369231956979,1.09242098045617E-5,49.9994965,49.9994965,-77594.6875,-77574.8359375,57.4559491916215,20.5787648204834,18.353191,0,0,0,40,4449,50.00275,-77584.76171875,,,,,,,,,,,,,0,,,,-0.00245,,,,,,49.9994965,,,,
,29107861.96,49.9987335,-72805.2109375,0.000216379656050441,1.36550857341806E-6,1,0.999253354069792,40.0298881530762,1.98504885344278,18.0099997669458,0.00242886155030773,0.000486670417822717,0.25,4.378159450608E-6,0.000217003670361889,5.82960359388589E-6,49.9987335,49.9987335,-72817.53125,-72792.890625,57.3043132588907,20.5762040313469,17.593889,0,0,0,40,4449,50.0004,-72805.2109375,,,,,,,,,,,,,0,,,,0,,,,,,49.9987335,,,,
,29107959.61,50.0006676,-67925.75390625,0.000188831648313219,1.08707454398478E-6,1,0.999253354069792,40.0298881530762,1.98497061174226,18.0099997669458,0.0021193032816666,0.000423681943980919,0.25,3.72004536002959E-6,0.000189339350891426,5.00370253901819E-6,50.0006676,50.0006676,-67930.9296875,-67920.578125,57.1198489283522,20.5770316368572,18.732843,0,0,0,40,4449,49.9998,-67925.75390625,,,,,,,,,,,,,0,,,,-0.0049,,,,,,50.0006676,,,,
,29108054.195,49.9991646,-63198.634765625,0.000164506010975066,1.04450670759928E-6,1,0.999253354069792,40.0298881530762,1.98482117618511,18.0099997669458,0.00184369656888437,0.000380653643589598,0.25,4.26068965406559E-6,0.000164908289143087,5.39573791438531E-6,49.9991646,49.9991646,-63208.9140625,-63188.35546875,57.1339182416984,20.5771532403863,18.353191,0,0,0,40,4449,50.0024,-63198.634765625,,,,,,,,,,,,,0,,,,0,,,,,,49.9991646,,,,
,29108150.4,49.9990082,-58391.283203125,0.000139301628511,1.20981627140971E-6,1,0.999253354069792,40.0298881530762,1.98507082782856,18.0099997669458,0.00156129466273468,0.000321070058742708,0.25,3.48600021318254E-6,0.000139613200689511,4.45832843283898E-6,49.9990082,49.9990082,-58401.375,-58381.19140625,57.0049495360253,20.5778053965939,18.353191,0,0,0,40,4449,49.99955,-58391.283203125,,,,,,,,,,,,,0,,,,-0.00245,,,,,,49.9990082,,,,
,29108245.94,49.9987946,-53613.705078125,0.000111309140557326,8.96587398113077E-7,1,0.999253354069792,40.0298881530762,1.98501034384863,18.0099997669458,0.0012504454123086,0.000238676948642072,0.25,1.19376829276681E-6,0.000111544616462933,1.97582472968103E-6,49.9987946,49.9987946,-53623.3828125,-53604.02734375,57.3355783996599,20.5766893032931,18.353191,0,0,0,40,4449,50.0023,-53613.705078125,,,,,,,,,,,,,0,,,,0,,,,,,49.9987946,,,,
,29108340.345,50.0001907,-48896.48828125,8.6101979420738E-5,1.05368122150975E-6,1,0.999253354069792,40.0298881530762,1.98503958873512,18.0099997669458,0.000964110953495958,0.000201007406798906,0.25,2.37585541736429E-6,8.62543747071586E-5,2.9900826012465E-6,50.0001907,50.0001907,-48906.57421875,-48886.40234375,57.3293253715061,20.577293077705,17.973541,0,0,0,40,4449,50.0034,-48896.48828125,,,,,,,,,,,,,0,,,,0.0049,,,,,,50.0001907,,,,
,29108436.605,50.0000534,-44086.470703125,5.99879518802195E-5,8.99595277834128E-7,1,0.999253354069792,40.0298881530762,1.98510986243778,18.0099997669458,0.000670070885915362,0.00014832316193407,0.25,2.38929432018945E-6,6.00744605010157E-5,2.82247287833392E-6,50.0000534,50.0000534,-44093.88671875,-44079.0546875,57.4145228801022,20.5780163887187,18.353191,0,0,0,40,4449,50.0038,-44086.470703125,,,,,,,,,,,,,0,,,,0.00245,,,,,,50.0000534,,,,
,29108530.455,49.9995041,-39396.701171875,3.45224482190341E-5,8.20206036621477E-7,1,0.999253354069792,40.0298881530762,1.98498727476216,18.0099997669458,0.000384934089828162,8.84944002412516E-5,0.25,1.65382571332123E-6,3.45618703381173E-5,1.90542703772168E-6,49.9995041,49.9995041,-39401.69921875,-39391.703125,57.4098331089868,20.5750427816887,18.353191,0,0,0,40,4449,50.0074,-39396.701171875,,,,,,,,,,,,,0,,,,0,,,,,,49.9995041,,,,
,29108625.625,49.9998055,-34639.708984375,8.90559794206194E-6,8.50690376809215E-7,1,0.999253354069792,40.0298881530762,1.98504702068572,18.0099997669458,9.73987029374945E-5,3.32566541914036E-5,0.25,1.35393720287212E-6,8.90676102059444E-6,1.42040274369418E-6,49.9998055,49.9998055,-34644.69921875,-34634.71875,57.0698247031214,20.5745847227943,18.732843,0,0,0,40,4449,50.0051,-34639.708984375,,,,,,,,,,,,,0,,,,0,,,,,,49.9998055,,,,
,29108721.195,50.0000458,-29862.8994140625,-1.53553610011126E-5,6.95484303582634E-7,1,0.999253354069792,40.0298881530762,1.98507380007281,18.0099997669458,-0.000173374462750041,-2.69134429674122E-5,0.25,3.71800047343459E-7,-1.53731184557124E-5,2.59670594944393E-7,50.0000458,50.0000458,-29877.947265625,-29847.8515625,57.3762230826599,20.5761836424044,18.732843,0,0,0,40,4449,50.0041,-29862.8994140625,,,,,,,,,,,,,0,,,,0,,,,,,50.0000458,,,,
,29108816.825,49.9993553,-25085.287109375,-4.04119995124633E-5,5.27414834047397E-7,1,0.999253354069792,40.0298881530762,1.98513170222968,18.0099997669458,-0.000453231186721588,-8.71725382812803E-5,0.25,-4.75243501778833E-7,-4.04375077948507E-5,-7.73333775886209E-7,49.9993553,49.9993553,-25090.41015625,-25080.1640625,57.2089545795445,20.5743600305474,18.732843,0,0,0,40,4449,50.00615,-25085.287109375,,,,,,,,,,,,,0,,,,0,,,,,,49.9993553,,,,
,29108911.725,49.9993801,-20340.5908203125,-6.43142013022382E-5,5.00072840050297E-7,1,0.999253354069792,40.0298881530762,1.98506927406921,18.0099997669458,-0.00072218495612501,-0.000132614158063537,0.25,-2.13240619975027E-7,-6.43419219510026E-5,-6.89284606236032E-7,49.9990463,49.9997139,-20348.119140625,-20333.0625,57.2495992625445,20.5745237052952,18.353191,0,0,0,40,4449,50.0049,-20340.5908203125,,,,,,,,,,,,,0,,,,0.0049,,,,,,49.9993801,,,,
,29109008.97,49.9982948,-15483.5581054687,-8.84911340591139E-5,3.62430620655842E-7,1,0.999253354069792,40.0298881530762,1.98496067950131,18.0099997669458,-0.000993680572478102,-0.000180579300188839,0.25,-1.28333032556693E-7,-8.85068603816402E-5,-7.85294873875849E-7,49.9982948,49.9982948,-15491.416015625,-15475.7001953125,57.1964485232368,20.5748678464827,18.732843,0,0,0,40,4449,50.0048,-15483.5581054687,,,,,,,,,,,,,0,,,,0,,,,,,49.9982948,,,,
,29109101.86,49.9998169,-10841.0805664062,-0.000110290470620439,4.07924033627573E-7,1,0.999253354069792,40.0298881530762,1.98484911051043,18.0099997669458,-0.00123795152316281,-0.000225783801137938,0.25,-2.28460124617318E-7,-0.000110282056261077,-1.04866792566736E-6,49.9998169,49.9998169,-10843.5654296875,-10838.595703125,57.1276652135445,20.5749832876891,18.353191,0,0,0,40,4449,50.00585,-10841.0805664062,,,,,,,,,,,,,0,,,,0,,,,,,49.9998169,,,,
,29109196.345,50.0000458,-6117.5126953125,-0.000129473950626242,3.4123374926779E-7,1,0.999253354069792,40.0298881530762,1.98487452471774,18.0099997669458,-0.0014519804558319,-0.000270344443411068,0.25,-7.43840876820109E-7,-0.000129429441230307,-1.70712013667077E-6,50.0000458,50.0000458,-6125.14453125,-6109.880859375,57.5044101598138,20.573050235867,18.732843,0,0,0,40,4449,50.0077,-6117.5126953125,,,,,,,,,,,,,0,,,,0.00245,,,,,,50.0000458,,,,
,29109291.585,49.9992905,-1353.74761962891,-0.00013105058460129,3.61047545661584E-7,1,0.999253354069792,40.0298881530762,1.98487976185206,18.0099997669458,-0.00146865206301658,-0.000277489439378571,0.25,-1.10132224762678E-6,-0.000130975445051038,-2.07570835799144E-6,49.9992905,49.9992905,-1356.4326171875,-1351.06262207031,57.1018714724099,20.5728556620466,18.353191,0,0,0,40,4449,50.0091,-1353.74761962891,,,,,,,,,,,,,0,,,,0,,,,,,49.9992905,,,,
,29109383.125,50.0002899,3216.47131347656,0.000136036638482918,3.27754464207021E-7,1,0.999253354069792,40.0298881530762,1.98491711776632,18.0099997669458,0.00152548815965663,0.000283551220191796,0.25,7.40163616811341E-7,0.00013597197728039,1.75208516517932E-6,50.0002899,50.0002899,3206.271484375,3226.67114257812,57.1300100991022,20.5719878353723,17.973541,0,0,0,40,4449,50.0099,3216.47131347656,,,,,,,,,,,,,0,,,,0.0049,,,,,,50.0002899,,,,
,29109474.805,50.0007515,7798.44995117187,0.000122584219710675,3.92554160984398E-7,1,0.999253354069792,40.0298881530762,1.98495794509867,18.0099997669458,0.0013758924302864,0.000250393713468517,0.25,2.05997531612296E-7,0.000122555833351039,1.11809237669066E-6,50.0007515,50.0007515,7790.91357421875,7805.986328125,57.3285437429868,20.5722585485104,18.732843,0,0,0,40,4449,50.0031,7798.44995117187,,,,,,,,,,,,,0,,,,0,,,,,,50.0007515,,,,
,29109567.795,50.0000229,12446.6772460938,0.000102872391472766,4.42513966333813E-7,1,0.999253354069792,40.0298881530762,1.98482975182952,18.0099997669458,0.00115480985352065,0.000210424497232002,0.25,1.96671159251899E-7,0.000102873482429206,9.61362260401433E-7,50.0000229,50.0000229,12439.2119140625,12454.142578125,57.1636201254291,20.5730832431483,18.732843,0,0,0,40,4449,50.00705,12446.6772460938,,,,,,,,,,,,,0,,,,0.00245,,,,,,50.0000229,,,,
,29109662.06,50.0010662,17159.279296875,8.04102357383205E-5,5.26112217279563E-7,1,0.999253354069792,40.0298881530762,1.98481590074188,18.0099997669458,0.000903551212273491,0.000160808760825233,0.25,-1.751354780235E-7,8.04341191497862E-5,4.21198560668508E-7,50.0008392,50.0012932,17146.76171875,17171.796875,57.2347483206791,20.5740842316177,18.732843,0,0,0,40,4449,50.00715,17159.279296875,,,,,,,,,,,,,0,,,,0,,,,,,50.0010662,,,,
,29109759.47,50.00018695,22026.4658203125,5.64531567823959E-5,5.56462480885697E-7,1,0.999253354069792,40.0298881530762,1.98475698992217,18.0099997669458,0.000636613224054541,0.000101209267483062,0.25,-1.16411306735008E-6,5.64926813437681E-5,-7.47562300894243E-7,50.0000458,50.0003281,22023.90234375,22029.029296875,57.1214121853907,20.5743715438206,18.732843,0,0,0,40,4449,50.00135,22026.4658203125,,,,,,,,,,,,,0,,,,0,,,,,,50.00018695,,,,
,29109856.43,50.0007305,26872.3408203125,3.22175414095719E-5,7.0396562727746E-7,1,0.999253354069792,40.0298881530762,1.98459632924605,18.0099997669458,0.00036324335260248,5.8535981617892E-5,0.25,-5.94994597265968E-7,3.22482285402914E-5,-3.58580919101359E-7,50.0004654,50.0009956,26867.482421875,26877.19921875,57.291807202583,20.5750888189602,18.353191,0,0,0,40,4449,50.0085,26872.3408203125,,,,,,,,,,,,,0,,,,-0.0049,,,,,,50.0007305,,,,
,29109951.835,50.0005035,31642.3896484375,7.86997780226988E-6,7.08767149758071E-7,1,0.999253354069792,40.0298881530762,1.98478360324425,18.0099997669458,9.10277529411422E-5,1.72680712803699E-6,0.25,-1.26380114902967E-6,7.88768070019941E-6,-1.20764647393503E-6,50.0005035,50.0005035,31634.796875,31649.982421875,57.068261446083,20.5722857500184,18.353191,0,0,0,40,4449,50.00545,31642.3896484375,,,,,,,,,,,,,0,,,,-0.0049,,,,,,50.0005035,,,,
,29110046.87,50.0005569,36392.26953125,-1.65987596914614E-5,7.57164758176543E-7,1,0.999253354069792,40.0298881530762,1.98491859097132,18.0099997669458,-0.000185127500096949,-4.20807976598223E-5,0.25,-7.53615279946574E-7,-1.66153524925284E-5,-8.75038355373599E-7,50.0005569,50.0005569,36382.4453125,36402.09375,57.5044101598138,20.5734916680499,18.353191,0,0,0,40,4449,50.0021,36392.26953125,,,,,,,,,,,,,0,,,,-0.0049,,,,,,50.0005569,,,,
,29110140.5,50.00114825,41072.41015625,-4.21991906215307E-5,6.49422408501629E-7,1,0.999253354069792,40.0298881530762,1.98493170935731,18.0099997669458,-0.000471187682804,-0.000104689688011912,0.25,-1.71229835103708E-6,-4.22532452346047E-5,-2.01860618515865E-6,50.0011063,50.0011902,41069.86328125,41074.95703125,57.0838940164676,20.5724343578472,17.973541,0,0,0,40,4449,50.001,41072.41015625,,,,,,,,,,,,,0,,,,0,,,,,,50.00114825,,,,
,29110233.955,50.00139045,45743.064453125,-6.71680593200625E-5,8.61023118478807E-7,1,0.999253354069792,40.0298881530762,1.98473614229379,18.0099997669458,-0.000752106673140365,-0.00015546863196131,0.25,-1.73543719158819E-6,-6.72772530070994E-5,-2.21734990973125E-6,50.0012894,50.0014915,45738.015625,45748.11328125,57.2847725459099,20.5720924009109,17.973541,0,0,0,40,4449,50.00305,45743.064453125,,,,,,,,,,,,,0,,,,0,,,,,,50.00139045,,,,
,29110328.245,50.00154495,50455.541015625,-9.18821424897084E-5,9.95896209289607E-7,1,0.999253354069792,40.0298881530762,1.98502353577045,18.0099997669458,-0.00103137012296634,-0.000200797434884693,0.25,-1.31868609757436E-6,-9.20603232671668E-5,-1.96957601458652E-6,50.0013618,50.0017281,50445.50390625,50465.578125,57.4145228801022,20.5700172660122,18.353191,0,0,0,40,4449,50.00205,50455.541015625,,,,,,,,,,,,,0,,,,0,,,,,,50.00154495,,,,
,29110426.02,50.0011063,55342.900390625,-0.00012048696892652,9.2892777543603E-7,1,0.999253354069792,40.0298881530762,1.9847487824118,18.0099997669458,-0.00135240207470078,-0.00026438136390887,0.25,-1.83212515956281E-6,-0.000120747798845567,-2.67645409307776E-6,50.0011063,50.0011063,55332.81640625,55352.984375,57.0706063316407,20.5727218407764,17.973541,0,0,0,40,4449,50.0006,55342.900390625,,,,,,,,,,,,,0,,,,0,,,,,,50.0011063,,,,
,29110520.765,50.0019875,60077.97265625,-0.000145402410313434,9.78391808991098E-7,1,0.999253354069792,40.0298881530762,1.9846517269086,18.0099997669458,-0.00163285333291029,-0.000316233480761015,0.25,-1.96813243387577E-6,-0.000145750083614172,-2.97480736305887E-6,50.0019875,50.0019875,60075.23828125,60080.70703125,56.8345545188329,20.5738065850077,18.353191,0,0,0,40,4449,49.9942,60077.97265625,,,,,,,,,,,,,0,,,,0.00245,,,,,,50.0019875,,,,
,29110617.615,50.0015221,64918.578125,-0.000171750010298746,8.29123009069916E-7,1,0.999253354069792,40.0298881530762,1.98462147673793,18.0099997669458,-0.0019278217169528,-0.000380801775108073,0.25,-2.97915832009926E-6,-0.000172192688240041,-4.15504998660787E-6,50.0015221,50.0015221,64913.51953125,64923.63671875,57.3379232852176,20.5743200278646,18.353191,0,0,0,40,4449,49.999,64918.578125,,,,,,,,,,,,,0,,,,-0.0049,,,,,,50.0015221,,,,
,29110713.255,50.0009041,69698.8046875,-0.00019674087970746,1.2631613016389E-6,1,0.999253354069792,40.0298881530762,1.98478879457339,18.0099997669458,-0.00220720781893848,-0.000446038098512533,0.25,-4.29255999328308E-6,-0.000197281316165683,-5.62477301221397E-6,50.0009041,50.0009041,69686.296875,69711.3125,56.9900985941599,20.5723912332574,18.353191,0,0,0,40,4449,49.99445,69698.8046875,,,,,,,,,,,,,0,,,,0,,,,,,50.0009041,,,,
,29110807.865,50.0012512,74426.72265625,-0.000223763614136005,1.44940925799878E-6,1,0.999253354069792,40.0298881530762,1.98471578455198,18.0099997669458,-0.00250977760639236,-0.000512849125795752,0.25,-5.38880900083534E-6,-0.000224417504475775,-6.88552022491796E-6,50.0009079,50.0015945,74419.21875,74434.2265625,56.8540952318137,20.573356906776,18.353191,0,0,0,40,4449,49.9992,74426.72265625,,,,,,,,,,,,,0,,,,0.00245,,,,,,50.0012512,,,,
,29110905.115,50.0006027,79290.015625,-0.000250377833365124,1.26956280420134E-6,1,0.999253354069792,40.0298881530762,1.98455679328913,18.0099997669458,-0.00281422736383357,-0.000542472150463684,0.25,-3.26413157830628E-6,-0.000251174042881261,-4.90644130498745E-6,50.0006027,50.0006027,79277.546875,79302.484375,57.1878506095253,20.5749272659079,17.973541,0,0,0,40,4449,49.9951,79290.015625,,,,,,,,,,,,,0,,,,-0.00245,,,,,,50.0006027,,,,
,29110999.84,50.0010338,84025.5546875,-0.000277142254312968,1.13536385691388E-6,1,0.999253354069792,40.0298881530762,1.98464287729098,18.0099997669458,-0.00311576713271892,-0.000600320150566646,0.25,-3.61645329633595E-6,-0.000278071272066811,-5.40800870523833E-6,50.0010338,50.0010338,84020.6015625,84030.5078125,57.200356665833,20.572068181451,17.973541,0,0,0,40,4449,49.99785,84025.5546875,,,,,,,,,,,,,0,,,,0,,,,,,50.0010338,,,,
,29111091.02,50.0016937,88581.203125,-0.000300437639060142,1.26103334301539E-6,1,0.999253354069792,40.0298881530762,1.9852710182128,18.0099997669458,-0.00337125061057067,-0.000695554922242411,0.25,-7.893902674143E-6,-0.0003014669772429,-9.82259831197076E-6,50.0016937,50.0016937,88573.515625,88588.890625,57.1104693861214,20.5623651576212,18.732843,0,0,0,40,4449,49.99835,88581.203125,,,,,,,,,,,,,0,,,,0,,,,,,50.0016937,,,,
,29111201.525,50.0007935,86973.48046875,-0.000291202215393166,1.12365102431548E-6,1,0.999253354069792,40.0298881530762,1.98497808408028,18.0099997669458,-0.0032681633537853,-0.000667419855220101,0.25,-7.0539358586175E-6,-0.00029218748030734,-8.93061731120886E-6,50.0007935,50.0007935,86968.6796875,86978.28125,56.9369478548522,20.5689402791836,18.353191,0,0,0,40,4449,49.9935,86973.48046875,,,,,,,,,,,,,0,,,,0,,,,,,50.0007935,,,,
,29111295.75,50.0002823,82262.72265625,-0.000267166785458899,9.53735657027052E-7,1,0.999253354069792,40.0298881530762,1.98475882985442,18.0099997669458,-0.00300285469389316,-0.000582847073369431,0.25,-3.843754190249E-6,-0.000268043102422764,-5.58156769395321E-6,50.0002823,50.0002823,82250.171875,82275.2734375,57.4575124486599,20.5721921059234,18.732843,0,0,0,40,4449,49.9939,82262.72265625,,,,,,,,,,,,,0,,,,0,,,,,,50.0002823,,,,
,29111390.27,49.9990883,77541.51171875,-0.000240934782019595,1.04585666127783E-6,1,0.999253354069792,40.0298881530762,1.98484704371575,18.0099997669458,-0.00270669561609437,-0.000530952428587886,0.25,-3.92243021735525E-6,-0.000241680173235264,-5.51357887741297E-6,49.9990883,49.9990883,77536.6171875,77546.40625,57.1198489283522,20.5714458830702,18.353191,0,0,0,40,4449,49.99925,77541.51171875,,,,,,,,,,,,,0,,,,-0.00245,,,,,,49.9990883,,,,
,29111485.86,49.9991913,72760.19921875,-0.000216832818692814,1.01273695672094E-6,1,0.999253354069792,40.0298881530762,1.98478883224129,18.0099997669458,-0.00243334670657923,-0.000489252743584233,0.25,-4.53135982494496E-6,-0.000217456691287513,-5.98651240475079E-6,49.9991913,49.9991913,72752.671875,72767.7265625,57.4668919908907,20.5746366751783,18.732843,0,0,0,40,4449,49.99695,72760.19921875,,,,,,,,,,,,,0,,,,-0.00245,,,,,,49.9991913,,,,
,29111580.295,49.9993668,68042.296875,-0.000189248523349599,8.45791002182057E-7,1,0.999253354069792,40.0298881530762,1.98468607788213,18.0099997669458,-0.00212413956188322,-0.000422117940742679,0.25,-3.51172271080279E-6,-0.000189759688843178,-4.79721140426278E-6,49.9993668,49.9993668,68034.90625,68049.6875,57.0745144742368,20.5750774852379,18.353191,0,0,0,40,4449,49.9984,68042.296875,,,,,,,,,,,,,0,,,,0,,,,,,49.9993668,,,,
,29111674.69,49.9985237,63321.931640625,-0.000163274532475772,8.933248921696E-7,1,0.999253354069792,40.0298881530762,1.98476230316381,18.0099997669458,-0.00183240671379366,-0.000363569568477519,0.25,-2.96571168574036E-6,-0.000163683217821301,-4.08862698491056E-6,49.9985237,49.9985237,63307.01953125,63336.84375,57.2746113751599,20.5747605756936,18.353191,0,0,0,40,4449,49.999,63321.931640625,,,,,,,,,,,,,0,,,,-0.00245,,,,,,49.9985237,,,,
,29111772.08,49.9998245,58454.21484375,-0.000135524141743563,8.27785584867651E-7,1,0.999253354069792,40.0298881530762,1.98476250943718,18.0099997669458,-0.00152145222210741,-0.000297199829317229,0.25,-2.04862038877575E-6,-0.000135836950228843,-2.99119630159652E-6,49.9998245,49.9998245,58444.43359375,58463.99609375,57.2159892362176,20.5738559405363,18.732843,0,0,0,40,4449,49.9999,58454.21484375,,,,,,,,,,,,,0,,,,0,,,,,,49.9998245,,,,
,29111868.29,49.998558,53645.935546875,-0.000109841839311751,1.08051461266486E-6,1,0.999253354069792,40.0298881530762,1.98476795281851,18.0099997669458,-0.00123007982343593,-0.000256307228358857,0.25,-3.02658994443131E-6,-0.00011006145239674,-3.80232559564078E-6,49.998558,49.998558,53640.79296875,53651.078125,57.3770047111791,20.5746662732699,18.353191,0,0,0,40,4449,50.0032,53645.935546875,,,,,,,,,,,,,0,,,,-0.0049,,,,,,49.998558,,,,
,29111962.5,49.9996414,48935.912109375,-8.46212998739907E-5,9.84772883415321E-7,1,0.999253354069792,40.0298881530762,1.98510405061608,18.0099997669458,-0.000947073694312337,-0.000200271906394459,0.25,-2.5762747630311E-6,-8.47694803799648E-5,-3.18038038366453E-6,49.9996414,49.9996414,48923.3125,48948.51171875,56.9705578811791,20.5718518303052,17.973541,0,0,0,40,4449,50.0003,48935.912109375,,,,,,,,,,,,,0,,,,0.00245,,,,,,49.9996414,,,,
,29112058.485,50.0002098,44140.25390625,-5.95352341395793E-5,8.77516338533289E-7,1,0.999253354069792,40.0298881530762,1.98492457587391,18.0099997669458,-0.000664997621233292,-0.000146963327361978,0.25,-2.35106662642151E-6,-5.96214084995852E-5,-2.78089844165803E-6,50.0002098,50.0002098,44135.63671875,44144.87109375,57.3637170263522,20.5740792165535,18.353191,0,0,0,40,4449,50.0047,44140.25390625,,,,,,,,,,,,,0,,,,-0.0049,,,,,,50.0002098,,,,
,29112152.655,50.0000801,39432.892578125,-3.35513955760785E-5,1.03831939657989E-6,1,0.999253354069792,40.0298881530762,1.98490397085563,18.0099997669458,-0.000375113822832919,-8.03228685170178E-5,0.25,-1.10237153437094E-6,-3.35933505846883E-5,-1.34614504315445E-6,50.0000801,50.0000801,39427.81640625,39437.96875,57.2027015513907,20.5736794764436,17.973541,0,0,0,40,4449,49.99845,39432.892578125,,,,,,,,,,,,,0,,,,0,,,,,,50.0000801,,,,
,29112246.495,50.00029375,34743.23828125,-9.14725848633114E-6,8.27417805339117E-7,1,0.999253354069792,40.0298881530762,1.98494573860267,18.0099997669458,-9.96563371199161E-5,-3.62737405184397E-5,0.25,-1.57888560437634E-6,-9.14713549771445E-6,-1.64738534906984E-6,50.000042,50.0005455,34740.9296875,34745.546875,57.4840878183138,20.5724459214156,17.973541,0,0,0,40,4449,50.0048,34743.23828125,,,,,,,,,,,,,0,,,,0,,,,,,50.00029375,,,,
,29112339.86,49.9986687,30075.7421875,1.52680582572925E-5,7.38939401366177E-7,1,0.999253354069792,40.0298881530762,1.9847597004259,18.0099997669458,0.000175007861446937,1.20821164977638E-5,0.25,-1.67519527647593E-6,1.52954516622067E-5,-1.56503236648253E-6,49.9986687,49.9986687,30063.2265625,30088.2578125,57.2605420618137,20.5753144169916,18.353191,0,0,0,40,4449,50.0039,30075.7421875,,,,,,,,,,,,,0,,,,0,,,,,,49.9986687,,,,
,29112436.08,49.9996796,25265.4306640625,3.95080771360996E-5,7.39446577724042E-7,1,0.999253354069792,40.0298881530762,1.98478787167868,18.0099997669458,0.000444953842796026,7.44979338767459E-5,0.25,-4.88534115859305E-7,3.9540380245425E-5,-1.97848867047274E-7,49.9996796,49.9996796,25255.46484375,25275.396484375,57.2097362080637,20.5748271944353,18.353191,0,0,0,40,4449,50.0014,25265.4306640625,,,,,,,,,,,,,0,,,,0,,,,,,49.9996796,,,,
,29112529.755,49.9990616,20585.7353515625,6.34544281208538E-5,4.72506510044515E-7,1,0.999253354069792,40.0298881530762,1.9845937176257,18.0099997669458,0.000713770644423848,0.000123078212736122,0.25,-4.78082473906854E-7,6.34877016724098E-5,-8.81081974666693E-9,49.9990616,49.9990616,20583.154296875,20588.31640625,57.5145713305638,20.5777179817043,18.732843,0,0,0,40,4449,50.00315,20585.7353515625,,,,,,,,,,,,,0,,,,-0.00245,,,,,,49.9990616,,,,
,29112624.37,49.9993935,15856.0009765625,8.69349039292521E-5,5.00237776873212E-7,1,0.999253354069792,40.0298881530762,1.98463464340226,18.0099997669458,0.00097668883163856,0.000173958796950956,0.25,-1.78363075782782E-7,8.69544031625051E-5,4.66857063503444E-7,49.9993935,49.9993935,15846.16015625,15865.841796875,57.1933220091599,20.5779765359608,18.353191,0,0,0,40,4449,50.0057,15856.0009765625,,,,,,,,,,,,,0,,,,0,,,,,,49.9993935,,,,
,29112718.47,49.9991989,11155.8076171875,0.000109177258387391,3.87898656632351E-7,1,0.999253354069792,40.0298881530762,1.98478177282338,18.0099997669458,0.00122531824740012,0.000224157001823745,0.25,2.84634589034439E-7,0.000109170262678389,1.09649924536706E-6,49.9991989,49.9991989,11148.1083984375,11163.5068359375,57.3949821671215,20.576453642837,17.973541,0,0,0,40,4449,50.0044,11155.8076171875,,,,,,,,,,,,,0,,,,0,,,,,,49.9991989,,,,
,29112812.76,49.9988785,6440.92114257812,0.000128887465129159,3.55234502784982E-7,1,0.999253354069792,40.0298881530762,1.9847579754498,18.0099997669458,0.00144653076313453,0.000262516323440304,0.25,1.53246933037466E-7,0.000128849331526206,1.11233341485052E-6,49.9988785,49.9988785,6436.435546875,6445.40673828125,57.2284952925253,20.5774338419735,17.973541,0,0,0,40,4449,50.0019,6440.92114257812,,,,,,,,,,,,,0,,,,0,,,,,,49.9988785,,,,
,29112906.195,50.0002251,1770.20928955078,0.000134816175025221,3.2599844602009E-7,1,0.999253354069792,40.0298881530762,1.98492299925898,18.0099997669458,0.00151181422137349,0.000280443004884005,0.25,6.84771272723478E-7,0.000134744346834015,1.68744526769718E-6,50.0002251,50.0002251,1762.71118164062,1777.70739746094,56.966649738583,20.5759064744432,18.353191,0,0,0,40,4449,50.0092,1770.20928955078,,,,,,,,,,,,,0,,,,0,,,,,,50.0002251,,,,
,29112942.5,50.0010414,-0.159849621355534,3.34635083730075E-5,4.71773929003349E-7,1,0.999253354069792,40.0298881530762,1.98491507421176,18.0099997669458,0.000376212359856727,6.41710260758167E-5,0.25,-3.14245092276407E-7,3.34473127321968E-5,-6.51592826096972E-8,50.0010414,50.0010414,-0.1674614995718,-0.152237743139267,57.505191788333,20.5764720067345,18.732843,0,0,0,40,4417,50.0056,-0.159849621355534,,,,,,,,,,,,,0,,,,-0.00245,,,,,,50.0010414,,,,