File: data/looselyPackedNP/sc-ios-11/ppms/rawdata/ES_S14_HYST_10K_REMEASURE.DAT
[Header]
; VSM Data File (default extension .dat)
; Copyright (c) 2003-2013, Quantum Design, Inc. All rights reserved.
TITLE,
FILEOPENTIME,29435005.50,12/08/2018,12:24 am
BYAPP,VSM,2.0,2.0
INFO,PPMS VSM Option Release 1.4.10 Build 1,APPNAME
INFO,Quantum Design Linear Motor Servo Controller,MOTOR_MODULE_NAME
INFO,3101-100 M1,MOTOR_HW_VERSION
INFO,MMC1014,MOTOR_SERIAL_NUMBER
INFO,SRV No X-over 01.03.11,MOTOR_SOFTWARE_VERSION
INFO,Quantum Design VSM Detection Module,VSM_MODULE_NAME
INFO,3101-150 F0,VSM_HW_VERSION
INFO,VSM707,VSM_SERIAL_NUMBER
INFO,VSM No X-over 01.02.05 May 20 2008 13:51:47,VSM_SOFTWARE_VERSION
INFO,704,PREAMP_SERIAL_NUMBER
INFO,822,COIL_SERIAL_NUMBER
INFO,0,MOMENT_UNITS
INFO,Iron Oxide Spheres,SAMPLE_MATERIAL
INFO,10 nm diameter, collaboration Mainz,SAMPLE_COMMENT
INFO,,SAMPLE_MASS
INFO,,SAMPLE_VOLUME
INFO,,SAMPLE_MOLECULAR_WEIGHT
INFO,,SAMPLE_SIZE
INFO,,SAMPLE_SHAPE
DATATYPE,COMMENT,1
DATATYPE,TIME,2
STARTUPAXIS,X,2
STARTUPAXIS,Y1,5
[Data]
Comment,Time Stamp (sec),Temperature (K),Magnetic Field (Oe),Moment (emu),M. Std. Err. (emu),Transport Action,Averaging Time (sec),Frequency (Hz),Peak Amplitude (mm),Center Position (mm),Coil Signal' (mV),Coil Signal" (mV),Range (mV),M. Quad. Signal (emu),M. Raw' (emu),M. Raw" (emu),Min. Temperature (K),Max. Temperature (K),Min. Field (Oe),Max. Field (Oe),Mass (grams),Motor Lag (deg),Pressure (Torr),VSM Status (code),Motor Status (code),Measure Status (code),Measure Count,PPMS Status (code),System Temp. (K),System Field (Oe),Sample Position (deg),Bridge 1 Resistance (ohms),Bridge 1 Excitation (에),Bridge 2 Resistance (ohms),Bridge 2 Excitation (에),Bridge 3 Resistance (ohms),Bridge 3 Excitation (에),Bridge 4 Resistance (ohms),Bridge 4 Excitation (에),Signal 1 Vin (V),Signal 2 Vin (V),Digital Inputs (code),Drive 1 Iout (mA),Drive 1 Ipower (W),Drive 2 Iout (mA),Drive 2 Ipower (W),Pressure (),Map 20 (),Map 21 (),Map 22 (),Map 23 (),Map 24 (),Map 25 (),Map 26 (),Map 27 (),Map 28 (),Map 29 ()
,29435020.03,10.0021687,0.0456713177263737,,,2,,,,17.2700002068281,,,,,,,10.0021687,10.0021687,0.0456713177263737,0.0456713177263737,,,11.519473,,,,-99999999,4369,10.0068,0.0456713177263737,,,,,,,,,,,,,,,,,,,,,,,10.0021687,,,,
,29435180.065,9.9996853,4927.68872070313,0.00012581859510719,3.37029071296567E-7,1,0.999253354069792,40.0298881530762,1.99752047204398,17.2600001096725,0.00141346739873921,0.000255971889872688,0.25,3.91209888821057E-7,0.00012512799402712,1.03357066296779E-6,9.9996853,9.9996853,4920.11181640625,4935.265625,56.2975757261213,20.5278189188397,11.899124,0,0,0,40,4449,10.00855,4927.68872070313,,,,,,,,,,,,,0,,,,0,,,,,,9.9996853,,,,
,29435276.33,10.0006628,9736.93408203125,0.000105127877193681,4.47795838559792E-7,1,0.999253354069792,40.0298881530762,1.99736612913716,17.2600001096725,0.00118077236178687,0.000217249451965025,0.25,5.84327869546198E-7,0.000104586875902618,1.15686735170404E-6,10.0006628,10.0006628,9726.8994140625,9746.96875,55.8067130160444,20.5365790542054,11.139823,0,0,0,40,4449,10.00695,9736.93408203125,,,,,,,,,,,,,0,,,,-0.00245,,,,,,10.0006628,,,,
,29435372.1,10.0025396,14526.8344726562,8.13317423219742E-5,5.26301162990928E-7,1,0.999253354069792,40.0298881530762,1.99732386872117,17.2600001096725,0.000914187210059194,0.000166282744921222,0.25,2.58601135096321E-7,8.09473240764908E-5,7.31044288193407E-7,10.0025396,10.0025396,14519.2451171875,14534.423828125,56.4750053999867,20.5396497004078,12.278775,0,0,0,40,4449,10.00615,14526.8344726562,,,,,,,,,,,,,0,,,,0,,,,,,10.0025396,,,,
,29435467.545,10.0015831,19294.5029296875,5.74951533723891E-5,6.79949698085779E-7,1,0.999253354069792,40.0298881530762,1.99699571166751,17.2600001096725,0.000647030359791637,0.000114317558856913,0.25,-1.26210426295419E-7,5.72507635014938E-5,2.27983591027282E-7,10.0015831,10.0015831,19286.76171875,19302.244140625,56.7407590965252,20.5386574450159,11.899124,0,0,0,40,4449,10.0043,19294.5029296875,,,,,,,,,,,,,0,,,,0,,,,,,10.0015831,,,,
,29435561.92,10.0019999,24012.021484375,3.32428825951729E-5,5.85520553929222E-7,1,0.999253354069792,40.0298881530762,1.99691384681702,17.2600001096725,0.000371264680026945,8.28666445904915E-5,0.25,1.40498259180297E-6,3.31075964544665E-5,1.61388139000827E-6,10.0019999,10.0019999,24004.544921875,24019.498046875,56.902556200006,20.5450218890648,11.519473,0,0,0,40,4449,10.00285,24012.021484375,,,,,,,,,,,,,0,,,,0.00245,,,,,,10.0019999,,,,
,29435656.97,10.001266,28764.927734375,6.1759224077607E-6,7.45499536692798E-7,1,0.999253354069792,40.0298881530762,1.996873925018,17.2600001096725,7.26062595953073E-5,-4.65280440682561E-6,0.25,-1.52192303364156E-6,6.16569586668377E-6,-1.47548781355047E-6,10.0012436,10.0012884,28757.466796875,28772.388671875,56.2045619323329,20.5445873081065,11.899124,0,0,0,40,4449,10.0014,28764.927734375,,,,,,,,,,,,,0,,,,0,,,,,,10.001266,,,,
,29435753.735,10.0010033,33599.876953125,-1.95796818235415E-5,9.74135574070604E-7,1,0.999253354069792,40.0298881530762,1.99687355306659,17.2600001096725,-0.000213972395748241,-7.61700760062202E-5,0.25,-3.24326427816786E-6,-1.95024225138126E-5,-3.36980374114216E-6,10.0010033,10.0010033,33594.87109375,33604.8828125,56.4742237714675,20.5398701891998,11.899124,0,0,0,40,4449,10.001,33599.876953125,,,,,,,,,,,,,0,,,,0,,,,,,10.0010033,,,,
,29435850.83,10.0006161,38452.01171875,-4.96014956233811E-5,7.26295671696544E-7,1,0.999253354069792,40.0298881530762,1.9966481637301,17.2600001096725,-0.000553055157428023,-0.000133068324596629,0.25,-2.88512458000515E-6,-4.94677207997743E-5,-3.23108204369363E-6,10.0006161,10.0006161,38446.8203125,38457.203125,57.2878990599868,20.5433164151987,12.278775,0,0,0,40,4449,10.0007,38452.01171875,,,,,,,,,,,,,0,,,,-0.00245,,,,,,10.0006161,,,,
,29435945.64,9.9990606,43192.169921875,-7.43624528898443E-5,1.20362244536774E-6,1,0.999253354069792,40.0298881530762,1.99659244251728,17.2600001096725,-0.000835950128789467,-0.000163918416206931,0.25,-1.15114894558763E-6,-7.42215197904351E-5,-1.68780370212569E-6,9.9990606,9.9990606,43184.84375,43199.49609375,56.3053920113137,20.5436215565939,11.899124,0,0,0,40,4449,10.0013,43192.169921875,,,,,,,,,,,,,0,,,,0.00245,,,,,,9.9990606,,,,
,29436041.76,9.9981098,47994.5703125,-0.000102859351146109,9.0287937343594E-7,1,0.999253354069792,40.0298881530762,1.99637089254879,17.2600001096725,-0.00115537398824774,-0.000234485336250944,0.25,-2.26175017189713E-6,-0.000102710654264839,-3.01427636813953E-6,9.9981098,9.9981098,47992.01171875,47997.12890625,56.6883899857368,20.5427216057475,11.899124,0,0,0,40,4449,10.0021,47994.5703125,,,,,,,,,,,,,0,,,,0.0049,,,,,,9.9981098,,,,
,29436138.63,9.9972539,52837.744140625,-0.000129775301222587,1.39941833992838E-6,1,0.999253354069792,40.0298881530762,1.9967447383172,17.2600001096725,-0.00145670383281259,-0.000307030474959044,0.25,-3.81940851487068E-6,-0.000129643984883313,-4.77782573117517E-6,9.9971752,9.9973326,52835.42578125,52840.0625,56.5000175126021,20.5458761206556,11.899124,0,0,0,40,4449,10.00575,52837.744140625,,,,,,,,,,,,,0,,,,0,,,,,,9.9972539,,,,
,29436239.01,9.9976673,57852.5078125,-0.00015950849991002,1.1967394619485E-6,1,0.999253354069792,40.0298881530762,1.99661100211979,17.2600001096725,-0.00179036840213366,-0.000382239960104853,0.25,-5.1067183893495E-6,-0.000159422076670852,-6.29191643304022E-6,9.9976673,9.9976673,57847.58984375,57857.42578125,56.6125720193714,20.5451791699167,12.278775,0,0,0,40,4449,10.0107,57852.5078125,,,,,,,,,,,,,0,,,,-0.0049,,,,,,9.9976673,,,,
,29436335.91,9.9964008,62695.68359375,-0.000184560133855418,1.50851968903164E-6,1,0.999253354069792,40.0298881530762,1.99657046235697,17.2600001096725,-0.0020743316179155,-0.000432056044541505,0.25,-4.98772371430293E-6,-0.000184550748834001,-6.36165715884307E-6,9.9963741,9.9964275,62690.80078125,62700.56640625,57.1221938139099,20.5433811839148,12.278775,0,0,0,40,4449,10.01305,62695.68359375,,,,,,,,,,,,,0,,,,-0.0049,,,,,,9.9964008,,,,
,29436430.9,9.9965768,67446.15625,-0.000213191454390574,1.46644174387557E-6,1,0.999253354069792,40.0298881530762,1.99646094782147,17.2600001096725,-0.00240033675082014,-0.000480872601756264,0.25,-4.13933222225161E-6,-0.000213283315302085,-5.72262327511186E-6,9.9964943,9.9966593,67438.6015625,67453.7109375,56.7204367550252,20.543671190631,11.899124,0,0,0,40,4449,10.0151,67446.15625,,,,,,,,,,,,,0,,,,0,,,,,,9.9965768,,,,
,29436527.01,9.9960966,72248.76953125,-0.00024349741789006,1.3285255466023E-6,1,0.999253354069792,40.0298881530762,1.99658483976083,17.2600001096725,-0.00274315917656648,-0.000547684747074793,0.25,-4.58046553298898E-6,-0.000243702889020451,-6.37918614414118E-6,9.9960966,9.9960966,72241.2734375,72256.265625,56.4578095725637,20.5454276699051,11.899124,0,0,0,40,4449,10.0192,72248.76953125,,,,,,,,,,,,,0,,,,0,,,,,,9.9960966,,,,
,29436623.705,9.9952536,77081.8359375,-0.000270757689114374,2.04104187205142E-6,1,0.999253354069792,40.0298881530762,1.99640645037206,17.2600001096725,-0.00304993881720661,-0.000616117341747037,0.25,-5.725033148859E-6,-0.000271086833664858,-7.71010466775667E-6,9.9952536,9.9952536,77079.1640625,77084.5078125,56.6313311038329,20.5435923693373,12.278775,0,0,0,40,4449,10.0232,77081.8359375,,,,,,,,,,,,,0,,,,0.0049,,,,,,9.9952536,,,,
,29436715.44,9.9950943,81667.6796875,-0.00029867860420091,2.00586206404142E-6,1,0.999253354069792,40.0298881530762,1.99645918861942,17.2600001096725,-0.0033687664125211,-0.000662908193027759,0.25,-4.83656126344254E-6,-0.000299156450283009,-7.0029477188447E-6,9.9950943,9.9950943,81657.6953125,81677.6640625,57.3004051162945,20.5484689581533,11.899124,0,0,0,40,4449,10.028,81667.6796875,,,,,,,,,,,,,0,,,,0.00245,,,,,,9.9950943,,,,
,29436807.19,9.9955301,86255.9296875,-0.000322584762146316,1.78181681861911E-6,1,0.999253354069792,40.0298881530762,1.99650648450321,17.2600001096725,-0.00363150356830855,-0.000761629550951572,0.25,-9.26612845860777E-6,-0.000323177907560484,-1.15872127585568E-5,9.9955301,9.9955301,86245.796875,86266.0625,56.8251749766022,20.5475966529466,12.278775,0,0,0,40,4449,10.0331,86255.9296875,,,,,,,,,,,,,0,,,,0,,,,,,9.9955301,,,,
,29436912.97,9.9968767,89453.50390625,-0.000338806553204051,2.37669434328412E-6,1,0.999253354069792,40.0298881530762,1.99647295474616,17.2600001096725,-0.0038086484864912,-0.000834783017831869,0.25,-1.28206575766972E-5,-0.00033948157897178,-1.52446163358973E-5,9.9968767,9.9968767,89446.234375,89460.7734375,56.933039712256,20.5467059931462,11.899124,0,0,0,40,4449,10.0352,89453.50390625,,,,,,,,,,,,,0,,,,-0.0049,,,,,,9.9968767,,,,
,29437000.195,9.9998188,85094.203125,-0.000319255598471789,1.64132802232664E-6,1,0.999253354069792,40.0298881530762,1.99629055519091,17.2600001096725,-0.00360622342427431,-0.000682158800229427,0.25,-2.84567227962037E-6,-0.000319861870463145,-5.13714285289927E-6,9.9998188,9.9998188,85084.0390625,85104.3671875,56.8181403199291,20.5455386309697,12.278775,0,0,0,40,4449,10.03415,85094.203125,,,,,,,,,,,,,0,,,,0,,,,,,9.9998188,,,,
,29437095.535,10.001667,80325.4921875,-0.000288369654173506,1.72196386864935E-6,1,0.999253354069792,40.0298881530762,1.99656258786613,17.2600001096725,-0.00323296186045324,-0.000747573276064938,0.25,-1.41731944293224E-5,-0.000288733332742899,-1.62866041633934E-5,10.001667,10.001667,80320.484375,80330.5,57.1526773261599,20.5537721785934,11.899124,0,0,0,40,4449,10.0328,80325.4921875,,,,,,,,,,,,,0,,,,-0.0049,,,,,,10.001667,,,,
,29437191.48,10.0028324,75533.6796875,-0.000263784899979066,1.68505354691068E-6,1,0.999253354069792,40.0298881530762,1.99652710603973,17.2600001096725,-0.00295960057697461,-0.000664629001001189,0.25,-1.12685205595561E-5,-0.000264031648585095,-1.32149587704539E-5,10.0028324,10.0028324,75526.1875,75541.171875,56.6532167023714,20.5476159594991,11.519473,0,0,0,40,4449,10.029,75533.6796875,,,,,,,,,,,,,0,,,,0.00245,,,,,,10.0028324,,,,
,29437288.335,10.0029974,70687.890625,-0.000236593476503199,1.68241319851477E-6,1,0.999253354069792,40.0298881530762,1.99647092001012,17.2600001096725,-0.00265795920248285,-0.000570521260556102,0.25,-7.8495244623399E-6,-0.000236737173214894,-9.60369083820184E-6,10.0029974,10.0029974,70677.7578125,70698.0234375,56.7767140084099,20.550945958328,11.519473,0,0,0,40,4449,10.02615,70687.890625,,,,,,,,,,,,,0,,,,0.0049,,,,,,10.0029974,,,,
,29437383.995,10.0032358,65907.24609375,-0.000203897410189442,1.41577536527015E-6,1,0.999253354069792,40.0298881530762,1.99647375895442,17.2600001096725,-0.00229644178394694,-0.000454057498370322,0.25,-3.44381335026455E-6,-0.000203961468134068,-4.95947260007242E-6,10.0032358,10.0032358,65899.6015625,65914.890625,57.0432493334676,20.5491361007814,11.519473,0,0,0,40,4449,10.022,65907.24609375,,,,,,,,,,,,,0,,,,-0.00245,,,,,,10.0032358,,,,
,29437478.675,10.003437,61174.0078125,-0.000177869852038284,1.62863588030039E-6,1,0.999253354069792,40.0298881530762,1.9963934497972,17.2600001096725,-0.00199966888974143,-0.000410855403611992,0.25,-4.32401825015304E-6,-0.0001778394153996,-5.64797792382364E-6,10.003437,10.003437,61166.56640625,61181.44921875,56.8150138058522,20.5474808511348,11.899124,0,0,0,40,4449,10.01975,61174.0078125,,,,,,,,,,,,,0,,,,0,,,,,,10.003437,,,,
,29437572.68,10.0042467,56476.486328125,-0.000152695079287574,1.21228096948762E-6,1,0.999253354069792,40.0298881530762,1.99668531898332,17.2600001096725,-0.00171625539879606,-0.000351846386785846,0.25,-3.64631059516131E-6,-0.000152601366541297,-4.77996634539373E-6,10.0042467,10.0042467,56474.01953125,56478.953125,56.5813068786021,20.5463854892264,11.519473,0,0,0,40,4449,10.0164,56476.486328125,,,,,,,,,,,,,0,,,,0,,,,,,10.0042467,,,,
,29437665.155,10.0043201,51856.189453125,-0.00012531489136201,1.18627427454576E-6,1,0.999253354069792,40.0298881530762,1.99653181046242,17.2600001096725,-0.00141048180294808,-0.000273521753543005,0.25,-1.65990724602925E-6,-0.000125190832253566,-2.58555033886808E-6,10.0043201,10.0043201,51851.37890625,51861,56.5594212800637,20.5502762431017,12.278775,0,0,0,40,4449,10.01225,51856.189453125,,,,,,,,,,,,,0,,,,0,,,,,,10.0043201,,,,
,29437760.685,10.0041523,47081.240234375,-9.79082257457752E-5,1.21872994482354E-6,1,0.999253354069792,40.0298881530762,1.99642549068777,17.2600001096725,-0.00109989199463477,-0.000222037326945695,0.25,-2.05277425911307E-6,-9.77582469916971E-5,-2.76743320189684E-6,10.0041523,10.0041523,47073.7109375,47088.76953125,56.7720242372945,20.5510547571435,11.899124,0,0,0,40,4449,10.0094,47081.240234375,,,,,,,,,,,,,0,,,,0,,,,,,10.0041523,,,,
,29437855.615,10.0033569,42335.841796875,-6.99647074559221E-5,1.2475875162739E-6,1,0.999253354069792,40.0298881530762,1.99662044183374,17.2600001096725,-0.00078247615910625,-0.000176298026170272,0.25,-3.04384743597988E-6,-6.98116758067154E-5,-3.54346671060818E-6,10.0033569,10.0033569,42330.98046875,42340.703125,56.8955215433329,20.5506288363617,11.899124,0,0,0,40,4449,10.0058,42335.841796875,,,,,,,,,,,,,0,,,,-0.00245,,,,,,10.0033569,,,,
,29437952.07,10.0030394,37515.94921875,-4.30559207921814E-5,9.29172786112659E-7,1,0.999253354069792,40.0298881530762,1.99658531801553,17.2600001096725,-0.000486553475774927,-7.91226024353504E-5,0.25,7.22493229594978E-7,-4.29584347454681E-5,4.16112416910373E-7,10.0030394,10.0030394,37513.66796875,37518.23046875,56.7767140084099,20.5527640219697,11.899124,0,0,0,40,4449,10.0042,37515.94921875,,,,,,,,,,,,,0,,,,-0.0049,,,,,,10.0030394,,,,
,29438046.885,10.0027609,32775.982421875,-1.78984056533562E-5,8.38348953151893E-7,1,0.999253354069792,40.0298881530762,1.99670761397629,17.2600001096725,-0.000195904986402358,-6.77394801325197E-5,0.25,-2.79857886682015E-6,-1.78274677167578E-5,-2.91384734342742E-6,10.0027609,10.0027609,32771.01953125,32780.9453125,57.210517836583,20.5514153910032,11.899124,0,0,0,40,4449,10.00145,32775.982421875,,,,,,,,,,,,,0,,,,0.00245,,,,,,10.0027609,,,,
,29438142.4,10.00207665,28003.251953125,1.16812647864131E-5,1.01644634984834E-6,1,0.999253354069792,40.0298881530762,1.99689675648672,17.2600001096725,0.000132480333292781,1.81563581592219E-5,0.25,-4.83644056933567E-7,1.16449211844047E-5,-4.04153621803331E-7,10.0020733,10.00208,27993.3203125,28013.18359375,56.9775925378522,20.5526884714376,12.278775,0,0,0,40,4449,10,28003.251953125,,,,,,,,,,,,,0,,,,-0.00245,,,,,,10.00207665,,,,
,29438233.96,10.0010099,23425.630859375,3.4846740526597E-5,6.9381739811517E-7,1,0.999253354069792,40.0298881530762,1.99675691592177,17.2600001096725,0.000392036202758495,7.06091419364596E-5,0.25,3.03223127908718E-8,3.47121604050522E-5,2.53569666261799E-7,10.0010099,10.0010099,23420.541015625,23430.720703125,57.251162519583,20.5545162608528,11.899124,0,0,0,40,4449,10.00005,23425.630859375,,,,,,,,,,,,,0,,,,0,,,,,,10.0010099,,,,
,29438327.54,10.0006866,18745.6328125,5.98792887312756E-5,6.70748983798285E-7,1,0.999253354069792,40.0298881530762,1.99652251057974,17.2600001096725,0.000675031541961878,0.000111427347873734,0.25,-8.04831397992751E-7,5.96257216198717E-5,-4.35207109399515E-7,10.0006866,10.0006866,18743.0703125,18748.1953125,56.6508718168137,20.5531603175074,11.899124,0,0,0,40,4449,9.9989,18745.6328125,,,,,,,,,,,,,0,,,,0.00245,,,,,,10.0006866,,,,
,29438420.455,10.0003281,14103.2866210938,8.45233465351826E-5,4.72598799102815E-7,1,0.999253354069792,40.0298881530762,1.99660713265189,17.2600001096725,0.00094968492741504,0.000172827052850702,0.25,2.788448992216E-7,8.4120601634143E-5,7.6721219721647E-7,10.0003281,10.0003281,14095.744140625,14110.8291015625,56.7814037795252,20.5527284234819,11.899124,0,0,0,40,4449,9.9991,14103.2866210938,,,,,,,,,,,,,0,,,,-0.0049,,,,,,10.0003281,,,,
,29438514.21,9.99897,9418.61279296875,0.000108508711554769,5.03872314188223E-7,1,0.999253354069792,40.0298881530762,1.99648127181816,17.2600001096725,0.00121968124813063,0.000215816844933686,0.25,-1.34557580267867E-7,0.00010795158686814,4.57616203353212E-7,9.99897,9.99897,9408.712890625,9428.5126953125,56.9815006804483,20.5565032898325,12.278775,0,0,0,40,4449,9.9995,9418.61279296875,,,,,,,,,,,,,0,,,,-0.00245,,,,,,9.99897,,,,
,29438606.445,9.9992056,4810.13256835937,0.000128954377327053,3.75574428045541E-7,1,0.999253354069792,40.0298881530762,1.99649425454239,17.2600001096725,0.00144846792042568,0.000259440849304028,0.25,1.54599344496401E-7,0.000128246808507268,8.13240547663761E-7,9.9992056,9.9992056,4805.28515625,4814.97998046875,56.7853119221214,20.5565809660937,12.278775,0,0,0,40,4449,10.0032,4810.13256835937,,,,,,,,,,,,,0,,,,-0.00245,,,,,,9.9992056,,,,
,29438699.335,10.0022697,166.535575866699,0.000106842688795326,3.55408579135503E-7,1,0.999253354069792,40.0298881530762,1.99653322356425,17.2600001096725,0.00119888535845418,0.000220102640794555,0.25,6.21929838874974E-7,0.00010622640900376,1.13390818109675E-6,10.0022697,10.0022697,156.625885009766,176.445266723633,56.9541436822753,20.5565525271915,11.519473,0,0,0,40,4449,9.99835,166.535575866699,,,,,,,,,,,,,0,,,,0,,,,,,10.0022697,,,,
,29438791.125,9.9988327,-4417.29760742188,-0.000128306799752155,3.66693744329304E-7,1,0.999253354069792,40.0298881530762,1.99646997032986,17.2600001096725,-0.00144018506122169,-0.00026349423859243,0.25,-6.35022500873896E-7,-0.000127596995950968,-1.28414646256309E-6,9.9988327,9.9988327,-4422.251953125,-4412.34326171875,56.7173102409483,20.5562522332717,11.519473,0,0,0,40,4449,10.0014,-4417.29760742188,,,,,,,,,,,,,0,,,,-0.00245,,,,,,9.9988327,,,,
,29438881.93,9.9989729,-8956.232421875,-0.000109608786035328,3.7635255692381E-7,1,0.999253354069792,40.0298881530762,1.99668125537804,17.2600001096725,-0.00123071439074153,-0.000225898979517239,0.25,-5.69100454853271E-7,-0.000109038183636084,-1.15988203042211E-6,9.9989729,9.9989729,-8961.3427734375,-8951.1220703125,56.8697278021983,20.5596669752221,11.899124,0,0,0,40,4449,10.0012,-8956.232421875,,,,,,,,,,,,,0,,,,-0.00245,,,,,,9.9989729,,,,
,29438976.875,10.00058415,-13704.0947265625,-8.55803093107219E-5,5.7826197932669E-7,1,0.999253354069792,40.0298881530762,1.99652868388006,17.2600001096725,-0.000961470212462666,-0.000175088990671155,0.25,-2.94876806890336E-7,-8.51694423778328E-5,-7.86828544933883E-7,10.0005646,10.0006037,-13709.2646484375,-13698.9248046875,56.9869720800829,20.5585433248434,11.519473,0,0,0,40,4449,10.0001,-13704.0947265625,,,,,,,,,,,,,0,,,,-0.0049,,,,,,10.00058415,,,,
,29439070.985,10.0007162,-18406.69921875,-6.09838152355589E-5,6.79662243611481E-7,1,0.999253354069792,40.0298881530762,1.99650321771926,17.2600001096725,-0.000686021921726656,-0.0001214841723192,0.25,1.06370760940155E-7,-6.07192334771212E-5,-2.65618292491758E-7,10.0007162,10.0007162,-18411.791015625,-18401.607421875,57.2558522906984,20.5604232659585,12.278775,0,0,0,40,4449,10.0004,-18406.69921875,,,,,,,,,,,,,0,,,,0,,,,,,10.0007162,,,,
,29439164.145,10.0003424,-23063.84765625,-3.75021776234891E-5,7.16938661268191E-7,1,0.999253354069792,40.0298881530762,1.99649444397247,17.2600001096725,-0.000421457206760247,-7.8126391514718E-5,0.25,-2.24448446456205E-7,-3.73547527743417E-5,-4.63149185721015E-7,10.0003424,10.0003424,-23073.638671875,-23054.056640625,57.0127658212176,20.5579984118326,11.899124,0,0,0,40,4449,9.99975,-23063.84765625,,,,,,,,,,,,,0,,,,0.0049,,,,,,10.0003424,,,,
,29439253.6,10.0007639,-27534.1416015625,-1.33719158223546E-5,6.88985789364688E-7,1,0.999253354069792,40.0298881530762,1.99654448778961,17.2600001096725,-0.000148835211237264,-3.63058351688657E-5,0.25,-8.26150038395381E-7,-1.33204847844112E-5,-9.12104229184105E-7,10.0007639,10.0007639,-27541.53125,-27526.751953125,56.9283499411406,20.5599863408287,11.899124,0,0,0,40,4449,9.99935,-27534.1416015625,,,,,,,,,,,,,0,,,,0,,,,,,10.0007639,,,,
,29439348.095,10.0001116,-32256.43359375,1.38478898954471E-5,9.32785611797507E-7,1,0.999253354069792,40.0298881530762,1.99662877032948,17.2600001096725,0.00015489372578652,3.38342959803306E-5,0.25,5.16423324757364E-7,1.38036191293252E-5,6.10021483983255E-7,10.0001116,10.0001116,-32263.84375,-32249.0234375,56.8884868866599,20.5630250698887,11.519473,0,0,0,40,4449,9.9994,-32256.43359375,,,,,,,,,,,,,0,,,,0.0049,,,,,,10.0001116,,,,
,29439439.835,9.9991541,-36843.279296875,3.93020737909671E-5,9.96661999207831E-7,1,0.999253354069792,40.0298881530762,1.99667856810742,17.2600001096725,0.000440452089074449,9.26196658796653E-5,0.25,1.15190142957446E-6,3.91974903289423E-5,1.42623924530829E-6,9.9991541,9.9991541,-36845.8515625,-36840.70703125,56.6837002146214,20.5616432137842,11.899124,0,0,0,40,4449,10,-36843.279296875,,,,,,,,,,,,,0,,,,0.0049,,,,,,9.9991541,,,,
,29439533.15,9.9985275,-41503.244140625,6.53332690031866E-5,1.08218361183731E-6,1,0.999253354069792,40.0298881530762,1.99680445121125,17.2600001096725,0.00073592823784253,0.00013547006922353,0.25,2.5709024863569E-7,6.52033161543756E-5,7.26990416656178E-7,9.9985275,9.9985275,-41508.35546875,-41498.1328125,56.7032409276022,20.556857922473,11.519473,0,0,0,40,4449,10.00015,-41503.244140625,,,,,,,,,,,,,0,,,,-0.0049,,,,,,9.9985275,,,,
,29439627.75,9.9979782,-46233.576171875,9.22327441347188E-5,1.06705357567318E-6,1,0.999253354069792,40.0298881530762,1.99673562980519,17.2600001096725,0.00104123703230995,0.000181198926059217,0.25,-5.45911100742668E-7,9.21015375457114E-5,1.29295352397076E-7,9.9979782,9.9979782,-46236.27734375,-46230.875,57.0315249056791,20.5604663956169,11.519473,0,0,0,40,4449,10.004,-46233.576171875,,,,,,,,,,,,,0,,,,0.0049,,,,,,9.9979782,,,,
,29439721.14,9.9970369,-50898.28125,0.000119918988046431,1.28947585711305E-6,1,0.999253354069792,40.0298881530762,1.99667410233928,17.2600001096725,0.00135321994510923,0.000242258187528381,0.25,-1.36795363878777E-7,0.000119801473713547,7.49185411266029E-7,9.9970369,9.9970369,-50908.43359375,-50888.12890625,57.0166739638137,20.5613405447789,11.899124,0,0,0,40,4449,10.0058,-50898.28125,,,,,,,,,,,,,0,,,,0,,,,,,9.9970369,,,,
,29439817.275,9.9970598,-55705.2890625,0.000146636219048806,1.44730739024521E-6,1,0.999253354069792,40.0298881530762,1.99693227058293,17.2600001096725,0.00165263237311617,0.00031345487221451,0.25,1.33672548230189E-6,0.000146551335700516,2.4256488155885E-6,9.9970598,9.9970598,-55715.234375,-55695.34375,57.075296102756,20.5584159183295,11.519473,0,0,0,40,4449,10.0095,-55705.2890625,,,,,,,,,,,,,0,,,,0.0049,,,,,,9.9970598,,,,
,29439912.365,9.9972219,-60457.533203125,0.000176124424104689,1.15196692967467E-6,1,0.999253354069792,40.0298881530762,1.99672276038053,17.2600001096725,0.00199094115143186,0.000347413353691325,0.25,-9.82739286136643E-7,0.000176121704670336,3.28319239948287E-7,9.9972219,9.9972219,-60467.48828125,-60447.578125,57.0190188493714,20.5629686905635,12.278775,0,0,0,40,4449,10.01235,-60457.533203125,,,,,,,,,,,,,0,,,,0,,,,,,9.9972219,,,,
,29440009.21,9.9957705,-65297.701171875,0.000201506606124773,1.38945202441642E-6,1,0.999253354069792,40.0298881530762,1.99665188094069,17.2600001096725,0.00227147274141931,0.000438273827366729,0.25,2.47557281631094E-6,0.000201565877162415,3.97363074803387E-6,9.9957705,9.9957705,-65305.12890625,-65290.2734375,57.1300100991022,20.5642085030565,11.899124,0,0,0,40,4449,10.0165,-65297.701171875,,,,,,,,,,,,,0,,,,-0.00245,,,,,,9.9957705,,,,
,29440103.06,9.9954739,-69987.1796875,0.000229822620506702,1.30391928085683E-6,1,0.999253354069792,40.0298881530762,1.99673269204061,17.2600001096725,0.00259109882201458,0.000504088315583878,0.25,3.18678926007684E-6,0.000229981373047669,4.88842949000008E-6,9.9954739,9.9954739,-69992.109375,-69982.25,57.1565854687561,20.560163729478,11.899124,0,0,0,40,4449,10.02075,-69987.1796875,,,,,,,,,,,,,0,,,,0,,,,,,9.9954739,,,,
,29440198.18,9.9956808,-74741.43359375,0.000260646090494227,1.4260671257473E-6,1,0.999253354069792,40.0298881530762,1.99681175429166,17.2600001096725,0.00293900611890903,0.000576771689855047,0.25,4.05681246947828E-6,0.000260925242505946,5.97389324299846E-6,9.9956808,9.9956808,-74748.75,-74734.1171875,56.8478422036599,20.5605531018873,11.899124,0,0,0,40,4449,10.02375,-74741.43359375,,,,,,,,,,,,,0,,,,-0.0049,,,,,,9.9956808,,,,
,29440291.925,9.9955912,-79423.4765625,0.000289708957842086,1.44992832923057E-6,1,0.999253354069792,40.0298881530762,1.99675536446827,17.2600001096725,0.00326697022109524,0.000646007745663301,0.25,4.94691154379972E-6,0.000290121976757676,7.05925225134274E-6,9.9955912,9.9955912,-79430.84375,-79416.109375,57.0393411908714,20.5623071892436,12.278775,0,0,0,40,4449,10.02835,-79423.4765625,,,,,,,,,,,,,0,,,,0.00245,,,,,,9.9955912,,,,
,29440386.035,9.9959316,-84128.57421875,0.000313306853634733,1.50061402630913E-6,1,0.999253354069792,40.0298881530762,1.9966649863121,17.2600001096725,0.00352653950264085,0.000741097859394081,0.25,9.11222052808597E-6,0.000313835044130541,1.13787393906743E-5,9.9959316,9.9959316,-84138.5,-84118.6484375,56.9494539111599,20.5618898823806,12.278775,0,0,0,40,4449,10.03145,-84128.57421875,,,,,,,,,,,,,0,,,,0.00245,,,,,,9.9959316,,,,
,29440473.63,9.9958544,-88508.0078125,0.000338815724304687,1.65348907073932E-6,1,0.999253354069792,40.0298881530762,1.99660068935447,17.2600001096725,0.00382266282726893,0.000757413070749868,0.25,5.97630203786412E-6,0.000339517710091843,8.39141126329682E-6,9.9958544,9.9958544,-88510.5703125,-88505.4453125,57.0878021590637,20.5605067331334,12.278775,0,0,0,40,4449,10.0356,-88508.0078125,,,,,,,,,,,,,0,,,,0,,,,,,9.9958544,,,,
,29440578.955,9.9984741,-87171.76953125,0.000333735893456918,1.49166896486826E-6,1,0.999253354069792,40.0298881530762,1.99656293818991,17.2600001096725,0.00376271340302462,0.000758361597295608,0.25,6.97145710564329E-6,0.000334389317436225,9.36154895840665E-6,9.9984741,9.9984741,-87179.7421875,-87163.796875,57.4168677656599,20.5617972895465,11.899124,0,0,0,40,4449,10.03695,-87171.76953125,,,,,,,,,,,,,0,,,,0.00245,,,,,,9.9984741,,,,
,29440669.445,10.0000181,-82649.62109375,0.000308872889359124,1.18792175058597E-6,1,0.999253354069792,40.0298881530762,1.99661290114887,17.2600001096725,0.00348079637737969,0.00070483452509808,0.25,6.70454517775614E-6,0.000309376984695871,8.94268209538437E-6,10.0000181,10.0000181,-82657.2734375,-82641.96875,57.0917103016599,20.5616357905891,11.899124,0,0,0,40,4449,10.036,-82649.62109375,,,,,,,,,,,,,0,,,,-0.0049,,,,,,10.0000181,,,,
,29440764.555,10.00255395,-77897.30078125,0.000276105220675153,1.57323604587688E-6,1,0.999253354069792,40.0298881530762,1.99653090307718,17.2600001096725,0.00311753321657562,0.000589627398356021,0.25,2.41653339085856E-6,0.000276483318527338,4.43275282116634E-6,10.0025101,10.0025978,-77899.7421875,-77894.859375,57.0416860764291,20.56343742477,11.519473,0,0,0,40,4449,10.0329,-77897.30078125,,,,,,,,,,,,,0,,,,0,,,,,,10.00255395,,,,
,29440859.79,10.0035582,-73137.29296875,0.000246816306343157,1.4194228737533E-6,1,0.999253354069792,40.0298881530762,1.99665135355846,17.2600001096725,0.00278490415504611,0.000532649120647115,0.25,2.65025720927904E-6,0.000247057295191402,4.46906156179992E-6,10.0035582,10.0035582,-73142.2421875,-73132.34375,56.7126204698329,20.56332086951,12.278775,0,0,0,40,4449,10.0307,-73137.29296875,,,,,,,,,,,,,0,,,,-0.00245,,,,,,10.0035582,,,,
,29440955.195,10.00354,-68367.9609375,0.000220915171352217,1.49424594969058E-6,1,0.999253354069792,40.0298881530762,1.99670155116644,17.2600001096725,0.00249093276191702,0.00048091672945294,0.25,2.74475177870538E-6,0.000221039493119534,4.38309827539089E-6,10.00354,10.00354,-68375.4609375,-68360.4609375,57.4160861371407,20.5625832107946,11.899124,0,0,0,40,4449,10.0266,-68367.9609375,,,,,,,,,,,,,0,,,,-0.00245,,,,,,10.00354,,,,
,29441050.735,10.0043392,-63595.85546875,0.000191803888991415,1.28692049212319E-6,1,0.999253354069792,40.0298881530762,1.99665808855272,17.2600001096725,0.00216226322365051,0.000414397672346811,0.25,2.11471293375997E-6,0.000191832712641395,3.54172659411459E-6,10.0043392,10.0043392,-63603.484375,-63588.2265625,57.1448610409676,20.560144665334,12.278775,0,0,0,40,4449,10.0225,-63595.85546875,,,,,,,,,,,,,0,,,,0.0049,,,,,,10.0043392,,,,
,29441147.39,10.0039272,-58763.248046875,0.000163856932138843,1.46824052845374E-6,1,0.999253354069792,40.0298881530762,1.99665293563803,17.2600001096725,0.00184476245848952,0.000362803090778114,0.25,2.59753400743982E-6,0.000163802085824901,3.81643162611E-6,10.0039272,10.0039272,-58775.80859375,-58750.6875,56.6915164998137,20.5610459237134,12.278775,0,0,0,40,4449,10.0189,-58763.248046875,,,,,,,,,,,,,0,,,,0.00245,,,,,,10.0039272,,,,
,29441244.655,10.0036879,-53903.994140625,0.000135328112079175,1.33487624870975E-6,1,0.999253354069792,40.0298881530762,1.99661178664374,17.2600001096725,0.0015244407280702,0.000290532614691082,0.25,1.35442374528561E-6,0.000135224957324418,2.35737135313061E-6,10.0036879,10.0036879,-53908.90234375,-53899.0859375,57.0534105042176,20.5597679982256,11.899124,0,0,0,40,4449,10.01565,-53903.994140625,,,,,,,,,,,,,0,,,,0.00245,,,,,,10.0036879,,,,
,29441339.64,10.0041513,-49156.923828125,0.000108039006188879,1.2171125623679E-6,1,0.999253354069792,40.0298881530762,1.99669135971305,17.2600001096725,0.00121601014149916,0.000234565596683768,0.25,1.32812022272564E-6,0.000107903345905086,2.12205924095605E-6,10.0041513,10.0041513,-49161.69921875,-49152.1484375,57.0065127930637,20.560771174396,11.899124,0,0,0,40,4449,10.01155,-49156.923828125,,,,,,,,,,,,,0,,,,0,,,,,,10.0041513,,,,
,29441435.155,10.00345275,-44381.439453125,8.00641521926383E-5,9.79426088570599E-7,1,0.999253354069792,40.0298881530762,1.9966379893156,17.2600001096725,0.000898996727262089,0.000183070841653995,0.25,1.81890192887011E-6,7.9918131820359E-5,2.39816176135154E-6,10.0033636,10.0035419,-44389.31640625,-44373.5625,56.9807190519291,20.5621329918433,11.899124,0,0,0,40,4449,10.0084,-44381.439453125,,,,,,,,,,,,,0,,,,-0.00245,,,,,,10.00345275,,,,
,29441531.805,10.0037861,-39551.59765625,5.42029780912724E-5,9.96198537746941E-7,1,0.999253354069792,40.0298881530762,1.99656533911274,17.2600001096725,0.00060992800986174,0.000114745190252791,0.25,4.28426840598471E-7,5.40824584008516E-5,8.14658549473061E-7,10.0037861,10.0037861,-39556.43359375,-39546.76171875,57.0065127930637,20.5597600769473,11.899124,0,0,0,40,4449,10.0059,-39551.59765625,,,,,,,,,,,,,0,,,,0.0049,,,,,,10.0037861,,,,
,29441626.315,10.0029335,-34829.47265625,2.69480817550276E-5,8.11273931117027E-7,1,0.999253354069792,40.0298881530762,1.99651926839491,17.2600001096725,0.000300948851722914,6.88651216226374E-5,0.25,1.26926005685323E-6,2.68673251257767E-5,1.45387112801998E-6,10.0029335,10.0029335,-34839.71875,-34819.2265625,57.1815975813714,20.562128549005,12.278775,0,0,0,40,4449,10.0033,-34829.47265625,,,,,,,,,,,,,0,,,,-0.00245,,,,,,10.0029335,,,,
,29441720.59,10.0023489,-30117.5068359375,1.27118932772388E-8,5.42776285375156E-7,1,0.999253354069792,40.0298881530762,1.99647526217036,17.2600001096725,5.43040838047219E-7,-2.20137224157837E-6,0.25,-1.97827533708041E-7,1.40109666841959E-8,-1.9711511306916E-7,10.0023489,10.0023489,-30122.12890625,-30112.884765625,57.0971817012945,20.5620249763171,11.899124,0,0,0,40,4449,10.0016,-30117.5068359375,,,,,,,,,,,,,0,,,,0.0049,,,,,,10.0023489,,,,
,29441815.63,10.0008678,-25367.7333984375,-2.52987863095487E-5,7.80344815388274E-7,1,0.999253354069792,40.0298881530762,1.99648899664508,17.2600001096725,-0.000282529599410141,-6.30286729390649E-5,0.25,-1.06452252442885E-6,-2.51992688133853E-5,-1.22563423235037E-6,10.0008678,10.0008678,-25370.31640625,-25365.150390625,56.9830639374868,20.5587603964553,11.899124,0,0,0,40,4449,10.00135,-25367.7333984375,,,,,,,,,,,,,0,,,,-0.00245,,,,,,10.0008678,,,,
,29441910.32,10.0011539,-20635.408203125,-5.10980971333716E-5,6.0760083355603E-7,1,0.999253354069792,40.0298881530762,1.99651570062127,17.2600001096725,-0.000573208182674463,-0.000111506419241089,0.25,-7.65185456157683E-7,-5.08820936409807E-5,-1.08076508267331E-6,10.0011539,10.0011539,-20647.845703125,-20622.970703125,57.0706063316407,20.5581441381486,12.278775,0,0,0,40,4449,10.0008,-20635.408203125,,,,,,,,,,,,,0,,,,0,,,,,,10.0011539,,,,
,29442007.315,10.0005236,-15788.2065429687,-7.6848637402894E-5,5.48782123457832E-7,1,0.999253354069792,40.0298881530762,1.99657876698993,17.2600001096725,-0.000862732466260604,-0.00016186568325258,0.25,-6.63227117791011E-7,-7.64916852341421E-5,-1.11457872153468E-6,10.0005236,10.0005236,-15795.673828125,-15780.7392578125,57.1300100991022,20.5591314373003,11.899124,0,0,0,40,4449,9.9998,-15788.2065429687,,,,,,,,,,,,,0,,,,0.0049,,,,,,10.0005236,,,,
,29442099.77,9.9987278,-11165.6884765625,-0.000100200644520807,4.43948258899815E-7,1,0.999253354069792,40.0298881530762,1.99642845890862,17.2600001096725,-0.00112505798287936,-0.000207002988299259,0.25,-5.46765906874216E-7,-9.96967114401177E-5,-1.10315161152194E-6,9.9986401,9.9988155,-11168.0869140625,-11163.2900390625,56.8392442899483,20.5596422072606,11.519473,0,0,0,40,4449,10.001,-11165.6884765625,,,,,,,,,,,,,0,,,,0,,,,,,9.9987278,,,,
,29442192.855,9.9998665,-6512.11645507812,-0.0001226482913876,3.40866358721969E-7,1,0.999253354069792,40.0298881530762,1.99658340532481,17.2600001096725,-0.00137524695123064,-0.000261469085602367,0.25,-1.43803707292821E-6,-0.000121983099859789,-2.07260825805492E-6,9.9998665,9.9998665,-6514.6005859375,-6509.63232421875,56.9588334533906,20.5586485590976,11.899124,0,0,0,40,4449,10.0012,-6512.11645507812,,,,,,,,,,,,,0,,,,0,,,,,,9.9998665,,,,
,29442284.17,10.0000038,-1948.71893310547,-0.00013261532300945,3.17112596424707E-7,1,0.999253354069792,40.0298881530762,1.9965239439922,17.2600001096725,-0.00148831137564256,-0.000272585832948241,0.25,-7.02917802369712E-7,-0.000131861717410528,-1.35162743345445E-6,10.0000038,10.0000038,-1956.42114257813,-1941.01672363281,57.007294421583,20.5604212184968,11.899124,0,0,0,40,4449,10.0021,-1948.71893310547,,,,,,,,,,,,,0,,,,-0.00245,,,,,,10.0000038,,,,
,29442378.9,9.999301,2781.76208496094,0.000132847154311355,3.33387721579175E-7,1,0.999253354069792,40.0298881530762,1.99650733300352,17.2600001096725,0.0014919318055471,0.000267675023558536,0.25,2.16527943923822E-7,0.000132100916422829,8.76215995583036E-7,9.999301,9.999301,2771.896484375,2791.62768554687,56.7540467813522,20.5601633935499,12.278775,0,0,0,40,4449,10.00165,2781.76208496094,,,,,,,,,,,,,0,,,,0,,,,,,9.999301,,,,
,29442470.885,9.9999895,7381.47534179688,0.000117832578618848,4.21744460649587E-7,1,0.999253354069792,40.0298881530762,1.99659010193644,17.2600001096725,0.00132323560629884,0.000240558474201572,0.25,4.25322780170797E-7,0.000117206010404907,1.04764190958374E-6,9.9999895,9.9999895,7376.32958984375,7386.62109375,56.9478906541214,20.5582841961652,11.899124,0,0,0,40,4449,10.002,7381.47534179688,,,,,,,,,,,,,0,,,,0.0049,,,,,,9.9999895,,,,
,29442565.065,9.9998064,12087.2104492187,9.49343502760934E-5,5.99441356573181E-7,1,0.999253354069792,40.0298881530762,1.99641416348541,17.2600001096725,0.00106650264848575,0.000193340706777541,0.25,2.62800021162602E-7,9.44656778909729E-5,7.9765571483877E-7,9.9998064,9.9998064,12079.7822265625,12094.638671875,57.2503808910638,20.559045200062,11.899124,0,0,0,40,4449,10.0018,12087.2104492187,,,,,,,,,,,,,0,,,,0.00245,,,,,,9.9998064,,,,
,29442658.92,10.0012331,16779.9228515625,7.14758308438183E-5,4.44304764204383E-7,1,0.999253354069792,40.0298881530762,1.99651524127717,17.2600001096725,0.000804545185714417,0.00013891947588765,0.25,-4.23128645111406E-7,7.11565535578193E-5,6.32819852780327E-9,10.0012331,10.0012331,16777.5234375,16782.322265625,56.9322580837368,20.558868870314,11.519473,0,0,0,40,4449,10.0019,16779.9228515625,,,,,,,,,,,,,0,,,,-0.0049,,,,,,10.0012331,,,,
,29442753.29,10.0008249,21496.9091796875,4.56673342308606E-5,5.87091059588757E-7,1,0.999253354069792,40.0298881530762,1.9964840121266,17.2600001096725,0.000513401644055896,9.36371108753357E-5,0.25,1.45751445020863E-7,4.54815085182305E-5,4.3251169062801E-7,10.0008249,10.0008249,21484.20703125,21509.611328125,56.5594212800637,20.5603760596341,12.278775,0,0,0,40,4449,10.001,21496.9091796875,,,,,,,,,,,,,0,,,,0,,,,,,10.0008249,,,,
,29442848.36,10.0006065,26247.0322265625,2.06918945459212E-5,6.91794522596283E-7,1,0.999253354069792,40.0298881530762,1.99657936682894,17.2600001096725,0.00023573615849692,2.57769759436677E-5,0.25,-1.42115526982106E-6,2.0627384110193E-5,-1.28011344222544E-6,10.0006065,10.0006065,26236.91015625,26257.154296875,56.7688977232175,20.5590701764913,11.519473,0,0,0,40,4449,9.99955,26247.0322265625,,,,,,,,,,,,,0,,,,0,,,,,,10.0006065,,,,
,29442942.69,10.000411,30962.6875,-4.86799243501027E-6,7.02699411192307E-7,1,0.999253354069792,40.0298881530762,1.99647392611046,17.2600001096725,-5.69717674182653E-5,2.20994798284943E-6,0.25,1.07067728363383E-6,-4.86030355790931E-6,1.03423112816528E-6,10.000411,10.000411,30960.02734375,30965.34765625,57.2456911199484,20.5570226265695,11.519473,0,0,0,40,4449,10.0007,30962.6875,,,,,,,,,,,,,0,,,,-0.00245,,,,,,10.000411,,,,
,29443036.445,9.9992409,35647.9453125,-3.17009250845247E-5,9.0042018134736E-7,1,0.999253354069792,40.0298881530762,1.9965196775841,17.2600001096725,-0.000356391811572906,-6.80381502058216E-5,0.25,-3.39813608887424E-7,-3.1616715168869E-5,-5.61096918383249E-7,9.9992409,9.9992409,35642.87890625,35653.01171875,57.1135959001984,20.5614390531785,11.519473,0,0,0,40,4449,10.0001,35647.9453125,,,,,,,,,,,,,0,,,,0,,,,,,9.9992409,,,,
,29443130.67,9.998889,40357.984375,-5.8089919580721E-5,1.23757003304435E-6,1,0.999253354069792,40.0298881530762,1.99654921494912,17.2600001096725,-0.000651451831260405,-0.000135570544996694,0.25,-1.57469418439518E-6,-5.79577082831902E-5,-1.98776164900446E-6,9.998889,9.998889,40350.5234375,40365.4453125,57.0151107067753,20.5586237790383,11.899124,0,0,0,40,4449,10.0018,40357.984375,,,,,,,,,,,,,0,,,,-0.00245,,,,,,9.998889,,,,
,29443225.49,9.9976444,45098.529296875,-8.54181112451887E-5,9.0001301227337E-7,1,0.999253354069792,40.0298881530762,1.9964750629562,17.2600001096725,-0.000963539752280566,-0.000170718721803311,0.25,2.42125791990301E-7,-8.52845938412621E-5,-3.80830957181393E-7,9.9976444,9.9976444,45093.38671875,45103.671875,57.0878021590637,20.5558137812729,11.519473,0,0,0,40,4449,10.0045,45098.529296875,,,,,,,,,,,,,0,,,,0,,,,,,9.9976444,,,,
,29443319.88,9.9977331,49813.763671875,-0.000113335045927666,1.02848423909102E-6,1,0.999253354069792,40.0298881530762,1.99651717357067,17.2600001096725,-0.00127712748702211,-0.000237570275129419,0.25,-6.39565885515501E-7,-0.000113205861412816,-1.47443473092832E-6,9.9977331,9.9977331,49811.1484375,49816.37890625,57.5161345876022,20.5588024005409,12.278775,0,0,0,40,4449,10.00705,49813.763671875,,,,,,,,,,,,,0,,,,0,,,,,,9.9977331,,,,
,29443412.925,9.9963331,54463.712890625,-0.000139759346780271,1.1706024309717E-6,1,0.999253354069792,40.0298881530762,1.99657827740767,17.2600001096725,-0.00157477102808047,-0.000298106591264494,0.25,-1.22533346897964E-6,-0.000139661814883088,-2.26192076670994E-6,9.9963331,9.9963331,54458.6171875,54468.80859375,56.6610329875637,20.5583730963611,12.278775,0,0,0,40,4449,10.0096,54463.712890625,,,,,,,,,,,,,0,,,,-0.0049,,,,,,9.9963331,,,,
,29443508.655,9.9968929,59248.822265625,-0.00016588970757783,1.13211095306781E-6,1,0.999253354069792,40.0298881530762,1.99642882480035,17.2600001096725,-0.001869763206666,-0.00035491509010348,0.25,-1.53434192108274E-6,-0.00016584997093201,-2.76879371837832E-6,9.9968929,9.9968929,59246.390625,59251.25390625,56.6618146160829,20.5565817844951,11.899124,0,0,0,40,4449,10.0132,59248.822265625,,,,,,,,,,,,,0,,,,-0.0049,,,,,,9.9968929,,,,
,29443602.565,9.9961863,63942.044921875,-0.000193302550268486,1.07635925501283E-6,1,0.999253354069792,40.0298881530762,1.99650396586381,17.2600001096725,-0.00217786099571627,-0.00042430286536438,0.25,-2.72337909267246E-6,-0.000193333264111452,-4.16150473035146E-6,9.9961863,9.9961863,63939.578125,63944.51171875,57.149550812083,20.5573825773117,11.899124,0,0,0,40,4449,10.0161,63942.044921875,,,,,,,,,,,,,0,,,,0,,,,,,9.9961863,,,,
,29443695.59,9.9954329,68592.30078125,-0.000219168719619216,1.42714501437652E-6,1,0.999253354069792,40.0298881530762,1.99632087617828,17.2600001096725,-0.00247057970653014,-0.000478474581328442,0.25,-2.85071571535639E-6,-0.000219295358497084,-4.47582754696413E-6,9.9954329,9.9954329,68587.375,68597.2265625,56.4742237714675,20.5579665461924,11.899124,0,0,0,40,4449,10.0194,68592.30078125,,,,,,,,,,,,,0,,,,-0.0049,,,,,,9.9954329,,,,
,29443790.6,9.9961596,73342.859375,-0.000250151218855536,1.31826554250679E-6,1,0.999253354069792,40.0298881530762,1.99640028510069,17.2600001096725,-0.00282558236495917,-0.000521246218834922,0.25,-1.04625045940277E-6,-0.000250411730160888,-2.88726906038397E-6,9.9961596,9.9961596,73335.359375,73350.359375,56.8525319747752,20.5559078730195,11.899124,0,0,0,40,4449,10.0239,73342.859375,,,,,,,,,,,,,0,,,,0.0049,,,,,,9.9961596,,,,
,29443884.57,9.9956827,78040.59375,-0.000279066455067413,1.38800341977966E-6,1,0.999253354069792,40.0298881530762,1.99651833165087,17.2600001096725,-0.0031531996247482,-0.00058365417821264,0.25,-1.35548215734947E-6,-0.000279459616491574,-3.39114455296798E-6,9.9956827,9.9956827,78032.921875,78048.265625,57.0588819038522,20.5532692212549,11.899124,0,0,0,40,4449,10.0266,78040.59375,,,,,,,,,,,,,0,,,,0.00245,,,,,,9.9956827,,,,
,29443977.26,9.9958515,82671.92578125,-0.000303845554582478,1.54970504397046E-6,1,0.999253354069792,40.0298881530762,1.99632739785652,17.2600001096725,-0.00342857693254609,-0.000666061855705282,0.25,-4.19040969556433E-6,-0.000304359273606304,-6.38769644710976E-6,9.9958515,9.9958515,82661.8515625,82682,56.9267866841022,20.5556107401003,11.519473,0,0,0,40,4449,10.0304,82671.92578125,,,,,,,,,,,,,0,,,,0,,,,,,9.9958515,,,,
,29444066.67,9.9955273,87142.94921875,-0.000333451473099187,1.32063031017155E-6,1,0.999253354069792,40.0298881530762,1.99627709955422,17.2600001096725,-0.00375617604101631,-0.00077322751741989,0.25,-8.34547701813233E-6,-0.000334093858925942,-1.07366232416311E-5,9.9955273,9.9955273,87140.265625,87145.6328125,56.9689946241406,20.5553956864241,11.899124,0,0,0,40,4449,10.0353,87142.94921875,,,,,,,,,,,,,0,,,,0,,,,,,9.9955273,,,,
,29444169.32,9.9969301,88672.69921875,-0.000342394746289363,1.58501614621966E-6,1,0.999253354069792,40.0298881530762,1.99632460108764,17.2600001096725,-0.00386358340005241,-0.000759718472034633,0.25,-5.54558518864704E-6,-0.000343111440662745,-7.98397122018916E-6,9.9969301,9.9969301,88667.5625,88677.8359375,56.3968425480637,20.5576085470293,11.139823,0,0,0,40,4449,10.0385,88672.69921875,,,,,,,,,,,,,0,,,,0.00245,,,,,,9.9969301,,,,
,29444256.005,9.9998498,84339.27734375,-0.00031582845367412,1.40805905375102E-6,1,0.999253354069792,40.0298881530762,1.99640709387425,17.2600001096725,-0.00356214261071149,-0.000704721192500249,0.25,-5.45161779357324E-6,-0.000316392445064302,-7.72808605342706E-6,9.9996834,10.0000162,84329.34375,84349.2109375,56.9166255133522,20.5562438308469,11.899124,0,0,0,40,4449,10.0374,84339.27734375,,,,,,,,,,,,,0,,,,0,,,,,,9.9998498,,,,
,29444351.79,10.0019426,79550.5546875,-0.000287226460756422,1.59338157373379E-6,1,0.999253354069792,40.0298881530762,1.99632409956566,17.2600001096725,-0.00323665343840564,-0.000649708492169018,0.25,-5.73299360684327E-6,-0.00028763268771833,-7.82795533508735E-6,10.0019426,10.0019426,79545.6953125,79555.4140625,56.9275683126214,20.5582716803374,11.519473,0,0,0,40,4449,10.0348,79550.5546875,,,,,,,,,,,,,0,,,,-0.0049,,,,,,10.0019426,,,,
,29444448.015,10.003068,74739.56640625,-0.000260522286902237,1.32966294122888E-6,1,0.999253354069792,40.0298881530762,1.99635962246326,17.2600001096725,-0.00294032006632087,-0.000557801937386645,0.25,-2.41215964412082E-6,-0.000260813316402161,-4.3263891529302E-6,10.003068,10.003068,74732.078125,74747.0546875,56.5961578204675,20.5583497256341,11.519473,0,0,0,40,4449,10.03105,74739.56640625,,,,,,,,,,,,,0,,,,0.00245,,,,,,10.003068,,,,
,29444544.185,10.0034351,69934.1640625,-0.000229249433793664,1.81278723062026E-6,1,0.999253354069792,40.0298881530762,1.99642148900255,17.2600001096725,-0.00258392938640094,-0.000504479998307102,0.25,-3.33144210769901E-6,-0.00022940562742677,-5.02906468001656E-6,10.0034351,10.0034351,69924.2109375,69944.1171875,57.0831123879483,20.5593134724961,11.899124,0,0,0,40,4449,10.0283,69934.1640625,,,,,,,,,,,,,0,,,,0,,,,,,10.0034351,,,,
,29444638.395,10.0041103,65223.654296875,-0.00020115518251043,1.41860915786136E-6,1,0.999253354069792,40.0298881530762,1.99636854545485,17.2600001096725,-0.00226484530154831,-0.000450452110960725,0.25,-3.62245162298411E-6,-0.000201204464277377,-5.11839791960012E-6,10.0041103,10.0041103,65216.26171875,65231.046875,56.5148684544675,20.5586428327779,11.899124,0,0,0,40,4449,10.02435,65223.654296875,,,,,,,,,,,,,0,,,,-0.00245,,,,,,10.0041103,,,,
,29444732.835,10.0044527,60502.92578125,-0.000174270278345075,1.06690010542268E-6,1,0.999253354069792,40.0298881530762,1.9964110020468,17.2600001096725,-0.00196582885348766,-0.000365162132895787,0.25,-9.27852191858088E-7,-0.000174254180857175,-2.22500250523532E-6,10.0044527,10.0044527,60497.77734375,60508.07421875,57.1628384969099,20.5582771893731,11.899124,0,0,0,40,4449,10.02035,60502.92578125,,,,,,,,,,,,,0,,,,0,,,,,,10.0044527,,,,
,29444830.285,10.0033398,55632.537109375,-0.00014614085401469,1.03631335854274E-6,1,0.999253354069792,40.0298881530762,1.99647951679655,17.2600001096725,-0.00164540788823779,-0.000319391429164381,0.25,-1.9582687393185E-6,-0.000146050567843961,-3.04311780955511E-6,10.0033398,10.0033398,55625.0078125,55640.06640625,56.9580518248714,20.5617855175501,11.899124,0,0,0,40,4449,10.019,55632.537109375,,,,,,,,,,,,,0,,,,0.0049,,,,,,10.0033398,,,,
,29444925.545,10.0045033,50869.69140625,-0.000118859673412431,1.13126705767835E-6,1,0.999253354069792,40.0298881530762,1.99646248543196,17.2600001096725,-0.00133587060951967,-0.000269260558554474,0.25,-2.44999285112581E-6,-0.000118723753780446,-3.32554198630855E-6,10.0045033,10.0045033,50862.171875,50877.2109375,56.7368509539291,20.5610279816677,12.278775,0,0,0,40,4449,10.01315,50869.69140625,,,,,,,,,,,,,0,,,,0.00245,,,,,,10.0045033,,,,
,29445021.08,10.0042105,46097.349609375,-9.18418003589094E-5,9.94445626188103E-7,1,0.999253354069792,40.0298881530762,1.99647060138796,17.2600001096725,-0.00103233949831148,-0.000204488946869135,0.25,-1.59253030147143E-6,-9.16942370220905E-5,-2.26147256295713E-6,10.0042105,10.0042105,46089.63671875,46105.0625,56.9236601700253,20.5618339931809,11.519473,0,0,0,40,4449,10.01085,46097.349609375,,,,,,,,,,,,,0,,,,0,,,,,,10.0042105,,,,
,29445114.82,10.0037594,41411.8359375,-6.39693294858477E-5,8.60412458072326E-7,1,0.999253354069792,40.0298881530762,1.99640172096105,17.2600001096725,-0.000719784012179676,-0.000136141703147338,0.25,-5.6480331638258E-7,-6.38392196245948E-5,-1.02411202191593E-6,10.0037594,10.0037594,41406.90234375,41416.76953125,56.8947399148137,20.5603922552307,11.519473,0,0,0,40,4449,10.008,41411.8359375,,,,,,,,,,,,,0,,,,0,,,,,,10.0037594,,,,
,29445207.025,10.003089,36804.3515625,-3.82135597334278E-5,7.67023238557351E-7,1,0.999253354069792,40.0298881530762,1.99639785844113,17.2600001096725,-0.000428725855925701,-8.70853383620002E-5,0.25,-8.575780832673E-7,-3.81135664533932E-5,-1.12490491343139E-6,10.003089,10.003089,36799.36328125,36809.33984375,57.2292769210445,20.5579144164926,11.899124,0,0,0,40,4449,10.0038,36804.3515625,,,,,,,,,,,,,0,,,,-0.0049,,,,,,10.003089,,,,
,29445304.44,10.002284,31934.5029296875,-1.06992848540806E-5,7.81176153774893E-7,1,0.999253354069792,40.0298881530762,1.99647071736264,17.2600001096725,-0.000120343420683912,-2.23477279500541E-5,0.25,-6.24841817742537E-8,-1.06670283346355E-5,-1.35635310594097E-7,10.002284,10.002284,31926.86328125,31942.142578125,57.4981571316599,20.5610343677334,11.899124,0,0,0,40,4449,10.00275,31934.5029296875,,,,,,,,,,,,,0,,,,-0.0049,,,,,,10.002284,,,,
,29445398.405,10.0016155,27237.4462890625,1.51513023070814E-5,6.56899632937367E-7,1,0.999253354069792,40.0298881530762,1.99642294347738,17.2600001096725,0.000172449134456048,1.98245997134466E-5,0.25,-9.57079344199458E-7,1.51051174316668E-5,-8.53390501479056E-7,10.0016155,10.0016155,27230.19921875,27244.693359375,57.0260535060445,20.5607301658272,11.519473,0,0,0,40,4449,10.00145,27237.4462890625,,,,,,,,,,,,,0,,,,0,,,,,,10.0016155,,,,
,29445492.195,10.0004501,22551.92578125,4.0693163124658E-5,7.00636058680405E-7,1,0.999253354069792,40.0298881530762,1.99638957897556,17.2600001096725,0.000458411822836944,7.84014764984773E-5,0.25,-3.2092510049078E-7,4.05347033801614E-5,-6.09594527753146E-8,10.0004501,10.0004501,22542.025390625,22561.826171875,57.0862389020253,20.5588201956554,11.899124,0,0,0,40,4449,10.00075,22551.92578125,,,,,,,,,,,,,0,,,,0,,,,,,10.0004501,,,,
,29445585.97,10.0004158,17862.21875,6.5917291007925E-5,5.6376432111709E-7,1,0.999253354069792,40.0298881530762,1.99652313402778,17.2600001096725,0.000740677912870537,0.000135836887381684,0.25,2.90302339833633E-7,6.56254411396495E-5,6.88194452102636E-7,10.0004158,10.0004158,17854.712890625,17869.724609375,57.0401228193907,20.5623463562756,11.519473,0,0,0,40,4449,10.0014,17862.21875,,,,,,,,,,,,,0,,,,0.0049,,,,,,10.0004158,,,,
,29445678.195,10.00051975,13254.5854492187,8.94939979270045E-5,4.89770225732997E-7,1,0.999253354069792,40.0298881530762,1.99640984822514,17.2600001096725,0.00100632983489803,0.000177546737102137,0.25,-1.80852376949448E-7,8.90636279352297E-5,3.33040997569657E-7,10.0004854,10.0005541,13242.27734375,13266.8935546875,57.1815975813714,20.5603906358327,11.519473,0,0,0,40,4449,10.00165,13254.5854492187,,,,,,,,,,,,,0,,,,0.00245,,,,,,10.00051975,,,,
,29445771.575,9.9990988,8589.14013671875,0.000113041527529305,3.58662942555383E-7,1,0.999253354069792,40.0298881530762,1.99640912264263,17.2600001096725,0.00127061412539859,0.000224193208796847,0.25,-1.88112056915776E-7,0.000112454008143089,4.22120033027151E-7,9.9988251,9.9993725,8584.3349609375,8593.9453125,57.2386564632753,20.5624976765471,11.139823,0,0,0,40,4449,10.00205,8589.14013671875,,,,,,,,,,,,,0,,,,-0.0049,,,,,,9.9990988,,,,
,29445866.115,9.9998388,3861.47265625,0.000132958452519388,3.62935621022937E-7,1,0.999253354069792,40.0298881530762,1.99639544175402,17.2600001096725,0.00149351621167627,0.000266134582850054,0.25,4.96079138225319E-8,0.000132221232784745,7.20471355792788E-7,9.9998388,9.9998388,3851.43212890625,3871.51318359375,57.6208728091792,20.5639640891064,11.519473,0,0,0,40,4449,10.0022,3861.47265625,,,,,,,,,,,,,0,,,,-0.0049,,,,,,9.9998388,,,,
,29445945.215,10.00272515,-0.494772627949715,9.22750594170814E-5,3.48732272670131E-7,1,0.999253354069792,40.0298881530762,1.99641951091995,17.2600001096725,0.00103609981217724,0.000185917619190668,0.25,1.66937954710228E-7,9.1744173201111E-5,6.10738814702164E-7,10.002533,10.0029173,-0.517608284950256,-0.471936970949173,56.8486238321791,20.5642274722639,11.519473,0,0,0,40,4417,9.99795,-0.494772627949715,,,,,,,,,,,,,0,,,,0.00245,,,,,,10.00272515,,,,