File: data/looselyPackedNP/sc-ios-11/ppms/rawdata/ES_S14_HYST_30K_ZFC.DAT
[Header]
; VSM Data File (default extension .dat)
; Copyright (c) 2003-2013, Quantum Design, Inc. All rights reserved.
TITLE,
FILEOPENTIME,29424452.83,12/07/2018,9:28 pm
BYAPP,VSM,2.0,2.0
INFO,PPMS VSM Option Release 1.4.10 Build 1,APPNAME
INFO,Quantum Design Linear Motor Servo Controller,MOTOR_MODULE_NAME
INFO,3101-100 M1,MOTOR_HW_VERSION
INFO,MMC1014,MOTOR_SERIAL_NUMBER
INFO,SRV No X-over 01.03.11,MOTOR_SOFTWARE_VERSION
INFO,Quantum Design VSM Detection Module,VSM_MODULE_NAME
INFO,3101-150 F0,VSM_HW_VERSION
INFO,VSM707,VSM_SERIAL_NUMBER
INFO,VSM No X-over 01.02.05 May 20 2008 13:51:47,VSM_SOFTWARE_VERSION
INFO,704,PREAMP_SERIAL_NUMBER
INFO,822,COIL_SERIAL_NUMBER
INFO,0,MOMENT_UNITS
INFO,Iron Oxide Spheres,SAMPLE_MATERIAL
INFO,10 nm diameter, collaboration Mainz,SAMPLE_COMMENT
INFO,,SAMPLE_MASS
INFO,,SAMPLE_VOLUME
INFO,,SAMPLE_MOLECULAR_WEIGHT
INFO,,SAMPLE_SIZE
INFO,,SAMPLE_SHAPE
DATATYPE,COMMENT,1
DATATYPE,TIME,2
STARTUPAXIS,X,2
STARTUPAXIS,Y1,5
[Data]
Comment,Time Stamp (sec),Temperature (K),Magnetic Field (Oe),Moment (emu),M. Std. Err. (emu),Transport Action,Averaging Time (sec),Frequency (Hz),Peak Amplitude (mm),Center Position (mm),Coil Signal' (mV),Coil Signal" (mV),Range (mV),M. Quad. Signal (emu),M. Raw' (emu),M. Raw" (emu),Min. Temperature (K),Max. Temperature (K),Min. Field (Oe),Max. Field (Oe),Mass (grams),Motor Lag (deg),Pressure (Torr),VSM Status (code),Motor Status (code),Measure Status (code),Measure Count,PPMS Status (code),System Temp. (K),System Field (Oe),Sample Position (deg),Bridge 1 Resistance (ohms),Bridge 1 Excitation (에),Bridge 2 Resistance (ohms),Bridge 2 Excitation (에),Bridge 3 Resistance (ohms),Bridge 3 Excitation (에),Bridge 4 Resistance (ohms),Bridge 4 Excitation (에),Signal 1 Vin (V),Signal 2 Vin (V),Digital Inputs (code),Drive 1 Iout (mA),Drive 1 Ipower (W),Drive 2 Iout (mA),Drive 2 Ipower (W),Pressure (),Map 20 (),Map 21 (),Map 22 (),Map 23 (),Map 24 (),Map 25 (),Map 26 (),Map 27 (),Map 28 (),Map 29 ()
sample offset = 35.73 mm touchdown = 11.4900004118681 mm,29424493.28,29.9996052,0.068506982177496,-1.72118330583176E-6,2.6447386490025E-7,1,0.999253354069792,40.0298881530762,1.99865891681046,16.9200003147125,-1.92821962547432E-5,-3.89648667131869E-6,0.25,-3.9580594310523E-8,-1.71202965805927E-6,-4.88032011990697E-8,29.9996052,29.9996052,0.0608950927853584,0.0761188715696335,55.4604515820251,20.4705905745,16.834587,0,0,0,40,4417,29.9882,0.068506982177496,,,,,,,,,,,,,0,,,,-0.00245,,,,,,29.9996052,,,,
,29424528.28,29.9999409,399.462387084961,4.84738622989328E-5,4.08068629593697E-7,1,0.999253354069792,40.0298881530762,1.9987001232297,16.9200003147125,0.000545045874532628,9.86246739444226E-5,0.25,1.25969240806045E-7,4.82221231772041E-5,3.91430759569393E-7,29.9999409,29.9999409,395.779205322266,403.145568847656,55.9302103220828,20.4732173195297,17.214239,0,0,0,40,4449,29.9847,399.462387084961,,,,,,,,,,,,,0,,,,0,,,,,,29.9999409,,,,
,29424546.63,30.0004768,857.220092773437,0.000102341298006757,3.26124066200132E-7,1,0.999253354069792,40.0298881530762,1.99873236399031,16.9200003147125,0.0011506170516575,0.000209141781777552,0.25,3.45013167581108E-7,0.000101811490885346,9.07006951336144E-7,30.0004768,30.0004768,852.258178710937,862.182006835938,55.7504357626598,20.475243255634,16.834587,0,0,0,40,4449,29.98705,857.220092773437,,,,,,,,,,,,,0,,,,-0.00245,,,,,,30.0004768,,,,
,29424565.43,29.9998226,1325.53356933594,0.00011889036806136,3.56879417068095E-7,1,0.999253354069792,40.0298881530762,1.99876011032879,16.9200003147125,0.0013360038369883,0.000247021213119821,0.25,7.58424193505952E-7,0.000118275662780836,1.41196471960694E-6,29.9998226,29.9998226,1320.55810546875,1330.50903320312,55.9216124083713,20.4767774045484,16.454937,0,0,0,40,4449,29.98455,1325.53356933594,,,,,,,,,,,,,0,,,,-0.00245,,,,,,29.9998226,,,,
,29424584.135,30.0004826,1791.12316894531,0.00012479386650592,3.39630903047084E-7,1,0.999253354069792,40.0298881530762,1.9987335186086,16.9200003147125,0.00140304373838592,0.000255464491084195,0.25,4.5313208265308E-7,0.000124153729900944,1.14377220627771E-6,30.0004826,30.0004826,1787.42907714844,1794.81726074219,55.8606453838713,20.4833800929841,17.214239,0,0,0,40,4449,29.9894,1791.12316894531,,,,,,,,,,,,,0,,,,0.00245,,,,,,30.0004826,,,,
,29424601.765,30.0005836,2231.39929199219,0.000127602475977101,3.60371735437725E-7,1,0.999253354069792,40.0298881530762,1.99877482949797,16.9200003147125,0.00143479743111814,0.00026059270904892,0.25,4.0428207533037E-7,0.000126951398762258,1.11357417016964E-6,30.0005836,30.0005836,2229.03076171875,2233.76782226562,56.1115481385444,20.4843822745135,16.834587,0,0,0,40,4449,29.9857,2231.39929199219,,,,,,,,,,,,,0,,,,0.0049,,,,,,30.0005836,,,,
,29424619.04,29.9994888,2661.44055175781,0.00012851083311178,3.89024510403044E-7,1,0.999253354069792,40.0298881530762,1.99863962762548,16.9200003147125,0.00144428045499807,0.000266220070731713,0.25,7.40489417645728E-7,0.000127856529610198,1.45604522408518E-6,29.9994888,29.9994888,2658.96142578125,2663.91967773438,55.9450612639482,20.4890843789063,16.834587,0,0,0,40,4449,29.9858,2661.44055175781,,,,,,,,,,,,,0,,,,0,,,,,,29.9994888,,,,
,29424635.635,30.0000668,3076.1728515625,0.000128340105680911,3.81698894768196E-7,1,0.999253354069792,40.0298881530762,1.9986381900919,16.9200003147125,0.00144245689413489,0.000265541464440188,0.25,7.07178095833111E-7,0.0001276901136423,1.42482454512599E-6,30.0000668,30.0000668,3071.357421875,3080.98828125,56.0474545999675,20.4908290400223,16.454937,0,0,0,40,4449,29.9864,3076.1728515625,,,,,,,,,,,,,0,,,,0,,,,,,30.0000668,,,,
,29424651.27,29.998435,3467.09204101562,0.00012824838461185,3.53227188005344E-7,1,0.999253354069792,40.0298881530762,1.99864223102747,16.9200003147125,0.00144165515481456,0.00026429174405712,0.25,6.09078848442637E-7,0.000127602576622493,1.32947081569587E-6,29.9982948,29.9985752,3463.28881835937,3470.89526367188,56.2334821875444,20.4913147456374,16.834587,0,0,0,40,4449,29.9875,3467.09204101562,,,,,,,,,,,,,0,,,,-0.00245,,,,,,29.998435,,,,
,29424668.04,29.999279,3885.63891601562,0.000127094111618124,3.03304995627461E-7,1,0.999253354069792,40.0298881530762,1.9985410184628,16.9200003147125,0.00142837836321415,0.000263430503644114,0.25,7.35987229013618E-7,0.000126456830254063,1.45223251257358E-6,29.999258,29.9993,3883.0751953125,3888.20263671875,56.0880992829675,20.490481870293,17.214239,0,0,0,40,4449,29.9898,3885.63891601562,,,,,,,,,,,,,0,,,,-0.00245,,,,,,29.999279,,,,
,29424684.725,29.9995251,4301.75903320313,0.000126261097731422,3.83142931076463E-7,1,0.999253354069792,40.0298881530762,1.99853386585455,16.9200003147125,0.00141945798961534,0.000259426914853521,0.25,5.25290693085508E-7,0.000125632601138617,1.24081134142389E-6,29.9995251,29.9995251,4298.01220703125,4305.505859375,56.0271322584675,20.4937600361687,16.454937,0,0,0,40,4449,29.9877,4301.75903320313,,,,,,,,,,,,,0,,,,0,,,,,,29.9995251,,,,
,29424703.64,29.9992466,4775.77172851562,0.000124935841808885,3.87615412321595E-7,1,0.999253354069792,40.0298881530762,1.99859451045986,16.9200003147125,0.00140465931483203,0.00025664232794852,0.25,5.09516481413493E-7,0.000124318024970035,1.22098338882225E-6,29.9992466,29.9992466,4770.771484375,4780.77197265625,56.0083731740059,20.4939311210149,16.834587,0,0,0,40,4449,29.9892,4775.77172851562,,,,,,,,,,,,,0,,,,-0.00245,,,,,,29.9992466,,,,
,29424720.945,30.0001354,5208.18334960937,0.000123418382127974,3.73165721494932E-7,1,0.999253354069792,40.0298881530762,1.99861337325886,16.9200003147125,0.00138754664263131,0.000254126901644817,0.25,5.52903698929338E-7,0.000122811428064599,1.25853670520526E-6,30.0001354,30.0001354,5205.6171875,5210.74951171875,56.2678738423906,20.4943236916975,16.834587,0,0,0,40,4449,29.9863,5208.18334960937,,,,,,,,,,,,,0,,,,0.00245,,,,,,30.0001354,,,,
,29424740.025,29.99926665,5685.22680664063,0.000121631409501836,3.24808946072273E-7,1,0.999253354069792,40.0298881530762,1.99849975564623,16.9200003147125,0.00136623591310097,0.000257124902654944,0.25,1.13543263319346E-6,0.000121033968206657,1.83140056231617E-6,29.9991913,29.999342,5682.78564453125,5687.66796875,56.2233210167944,20.4922173465591,16.454937,0,0,0,40,4449,29.9897,5685.22680664063,,,,,,,,,,,,,0,,,,0,,,,,,29.99926665,,,,
,29424758.94,29.9985504,6158.90087890625,0.000120144762506904,3.50804772680047E-7,1,0.999253354069792,40.0298881530762,1.99847104605806,16.9200003147125,0.0013507708990351,0.000247229643595199,0.25,5.17678381801648E-7,0.000119562144650099,1.21137698920361E-6,29.9985332,29.9985676,6157.59375,6160.2080078125,56.2983573546406,20.4942908951132,16.834587,0,0,0,40,4449,29.9865,6158.90087890625,,,,,,,,,,,,,0,,,,0.0049,,,,,,29.9985504,,,,
,29424776.86,30.0004826,6604.8984375,0.000118467751990951,3.68968461470458E-7,1,0.999253354069792,40.0298881530762,1.99869624907425,16.9200003147125,0.00133146987876517,0.000247361852812598,0.25,8.22709178462629E-7,0.000117895323832641,1.50836323334459E-6,30.0004826,30.0004826,6599.97607421875,6609.82080078125,56.2162863601213,20.4962484949837,17.214239,0,0,0,40,4449,29.9882,6604.8984375,,,,,,,,,,,,,0,,,,0,,,,,,30.0004826,,,,
,29424794.415,29.9997139,7043.45166015625,0.000116461159022559,3.92364454799521E-7,1,0.999253354069792,40.0298881530762,1.99858564498059,16.9200003147125,0.0013089749004832,0.000242699154435861,0.25,7.64183595142294E-7,0.000115902461625812,1.44146915340269E-6,29.9997139,29.9997139,7039.87646484375,7047.02685546875,56.3343122665252,20.4969211682982,16.834587,0,0,0,40,4449,29.98815,7043.45166015625,,,,,,,,,,,,,0,,,,-0.00245,,,,,,29.9997139,,,,
,29424831.18,29.9999046,7157.20703125,0.000115815328706292,3.9463640366229E-7,1,0.999253354069792,40.0298881530762,1.998593537482,16.9200003147125,0.00130210989737949,0.000239236586674142,0.25,5.70875111573782E-7,0.000115261746364765,1.24602893964928E-6,29.9999046,29.9999046,7156.01318359375,7158.40087890625,56.3882446343521,20.4992245331267,17.214239,0,0,0,40,4449,29.9826,7157.20703125,,,,,,,,,,,,,0,,,,0.0049,,,,,,29.9999046,,,,
,29424850.145,29.9998722,6683.5830078125,0.00011767230875657,4.20762621841138E-7,1,0.999253354069792,40.0298881530762,1.99854588092703,16.9300008565187,0.00132207313948085,0.000247753391288454,0.25,1.00048088501488E-6,0.000117103339542247,1.68120526803621E-6,29.9998722,29.9998722,6682.57275390625,6684.59326171875,56.4640626007175,20.5015523642193,16.834587,0,0,0,40,4449,29.9884,6683.5830078125,,,,,,,,,,,,,0,,,,0.0049,,,,,,29.9998722,,,,
,29424867.98,29.9997559,6239.73950195313,0.000119724989383459,3.40062946331452E-7,1,0.999253354069792,40.0298881530762,1.99855427833935,16.9200003147125,0.00134605009125308,0.000246728962019058,0.25,5.46572969241316E-7,0.0001191449321651,1.23827188062263E-6,29.9997559,29.9997559,6238.740234375,6240.73876953125,56.3632325217367,20.4999518095304,16.454937,0,0,0,40,4449,29.9867,6239.73950195313,,,,,,,,,,,,,0,,,,0,,,,,,29.9997559,,,,
,29424885.44,30.000618,5803.21606445313,0.000121409857997927,3.47829944073851E-7,1,0.999253354069792,40.0298881530762,1.99845176569833,16.9200003147125,0.00136447934419024,0.000252440999233267,0.25,7.58210380764934E-7,0.000120816661615377,1.45555331370962E-6,30.000618,30.000618,5799.73681640625,5806.6953125,56.3397836661598,20.4994689124313,16.834587,0,0,0,40,4449,29.9879,5803.21606445313,,,,,,,,,,,,,0,,,,-0.00245,,,,,,30.000618,,,,
,29424903.095,30.0001392,5362.55102539063,0.000123456832223834,3.34661433506722E-7,1,0.999253354069792,40.0298881530762,1.99859678840284,16.9200003147125,0.00138832248989581,0.000252307801057124,0.25,3.83164044546113E-7,0.000122852032095022,1.09098250621484E-6,30.0001392,30.0001392,5357.21337890625,5367.888671875,56.7626446950637,20.4982246569975,16.454937,0,0,0,40,4449,29.98875,5362.55102539063,,,,,,,,,,,,,0,,,,-0.00245,,,,,,30.0001392,,,,
,29424921.7,29.9996128,4899.57666015625,0.000124752228663378,4.13661004530683E-7,1,0.999253354069792,40.0298881530762,1.99856404784308,16.9200003147125,0.00140244054519322,0.000257081339844355,0.25,5.80567216665161E-7,0.000124135963414032,1.29152184602359E-6,29.9996128,29.9996128,4893.47509765625,4905.67822265625,56.455464687006,20.5013156631429,16.454937,0,0,0,40,4449,29.9889,4899.57666015625,,,,,,,,,,,,,0,,,,-0.0049,,,,,,29.9996128,,,,
,29424939.43,30.0006485,4455.21801757812,0.000126609848716524,3.44304639140566E-7,1,0.999253354069792,40.0298881530762,1.99845033155303,16.9200003147125,0.00142249924064548,0.000264826399204345,0.25,9.42603064523716E-7,0.000125978520903343,1.65912703897055E-6,30.0006485,30.0006485,4451.36181640625,4459.07421875,56.5727089648906,20.4999932937605,16.454937,0,0,0,40,4449,29.9857,4455.21801757812,,,,,,,,,,,,,0,,,,0,,,,,,30.0006485,,,,
,29424957.735,29.999361,3998.85278320313,0.000127305487495288,2.81850072909281E-7,1,0.999253354069792,40.0298881530762,1.99848157783764,16.9200003147125,0.00143109596219184,0.000261778770527905,0.25,5.51137407125855E-7,0.000126669140356479,1.27030823522385E-6,29.999361,29.999361,3993.51318359375,4004.1923828125,56.7235632691022,20.5025062358423,16.834587,0,0,0,40,4449,29.9895,3998.85278320313,,,,,,,,,,,,,0,,,,0.0049,,,,,,29.999361,,,,
,29424975.44,30.0005932,3556.57849121094,0.000128771457598108,3.06770741313757E-7,1,0.999253354069792,40.0298881530762,1.9984667814369,16.9200003147125,0.00144775255440544,0.000263498926172233,0.25,4.46448499536745E-7,0.000128124708306498,1.17126643486769E-6,30.0005932,30.0005932,3553.97094726562,3559.18603515625,56.4953277414867,20.5022890321741,16.834587,0,0,0,40,4449,29.9893,3556.57849121094,,,,,,,,,,,,,0,,,,0,,,,,,30.0005932,,,,
,29424993.025,29.999691,3116.05212402344,0.000129386172632643,3.114285550844E-7,1,0.999253354069792,40.0298881530762,1.99845717175934,16.9200003147125,0.0014538737755743,0.000268905753393962,0.25,8.21333503871901E-7,0.00012873058697501,1.54455901031718E-6,29.999691,29.999691,3114.87036132812,3117.23388671875,56.411693489929,20.5061577219474,16.454937,0,0,0,40,4449,29.9859,3116.05212402344,,,,,,,,,,,,,0,,,,0.00245,,,,,,29.999691,,,,
,29425010.435,30.0002575,2681.60595703125,0.000129774913641509,3.64035262779484E-7,1,0.999253354069792,40.0298881530762,1.99843975246124,16.9200003147125,0.00145898338402281,0.000265259797847868,0.25,4.31736456935062E-7,0.000129116098846949,1.15606759707154E-6,30.0002575,30.0002575,2677.94409179687,2685.26782226562,56.3569794935829,20.5070761302912,16.834587,0,0,0,40,4449,29.9857,2681.60595703125,,,,,,,,,,,,,0,,,,0,,,,,,30.0002575,,,,
,29425027.895,30.0003834,2245.30444335938,0.000129170682051207,3.23215730101741E-7,1,0.999253354069792,40.0298881530762,1.99845438396239,16.9200003147125,0.00145159358226941,0.000267212542645707,0.25,7.16464964549274E-7,0.000128510034795772,1.43304081536548E-6,30.0003834,30.0003834,2240.4404296875,2250.16845703125,56.4163832610444,20.5038267598099,16.834587,0,0,0,40,4449,29.98845,2245.30444335938,,,,,,,,,,,,,0,,,,-0.0049,,,,,,30.0003834,,,,
,29425046.805,29.9992161,1773.26916503906,0.00012692664029168,3.56942524192711E-7,1,0.999253354069792,40.0298881530762,1.99835946763047,16.9200003147125,0.00142629020744529,0.000262451596140663,0.25,6.9816909753678E-7,0.000126274116616125,1.39928249754678E-6,29.9992161,29.9992161,1770.64196777344,1775.89636230469,56.5211214826214,20.5042095131795,16.834587,0,0,0,40,4449,29.98905,1773.26916503906,,,,,,,,,,,,,0,,,,0,,,,,,29.9992161,,,,
,29425064.88,29.9998493,1321.24877929688,0.000122628002116787,3.04955304391872E-7,1,0.999253354069792,40.0298881530762,1.99828569218462,16.9200003147125,0.0013776116500594,0.000255184702056264,0.25,8.22728352504728E-7,0.000121993776466011,1.49663271241805E-6,29.9998493,29.9998493,1318.79919433594,1323.69836425781,56.1052951103906,20.5036175261925,16.834587,0,0,0,40,4449,29.9886,1321.24877929688,,,,,,,,,,,,,0,,,,0.0049,,,,,,29.9998493,,,,
,29425082.555,29.9985123,879.671813964844,0.000112746468051769,3.52854124809194E-7,1,0.999253354069792,40.0298881530762,1.99827775849198,16.9200003147125,0.0012674083929439,0.000229902363369874,0.25,3.39712297317101E-7,0.000112163102336718,9.5912951160088E-7,29.9985123,29.9985123,873.352111816406,885.991516113281,56.485948199256,20.5025895863765,16.834587,0,0,0,40,4449,29.9841,879.671813964844,,,,,,,,,,,,,0,,,,0.00245,,,,,,29.9985123,,,,
,29425101.15,30.0006161,415.424240112305,8.61851347198928E-5,3.88924041355519E-7,1,0.999253354069792,40.0298881530762,1.99831927301052,16.9200003147125,0.00096851396291749,0.000177489242371767,0.25,4.16749216651496E-7,8.57365753903084E-5,8.87811673141682E-7,30.0005608,30.0006714,411.689483642578,419.158996582031,56.5476968522752,20.5045821106432,16.834587,0,0,0,40,4449,29.9876,415.424240112305,,,,,,,,,,,,,0,,,,0.00245,,,,,,30.0006161,,,,
,29425119.825,30.0003052,-51.9461078643799,1.78366808376458E-5,3.5067158881814E-7,1,0.999253354069792,40.0298881530762,1.99825538434514,16.9200003147125,0.000201112621071701,3.29164096167644E-5,0.25,-2.52714444058452E-7,1.77454657658294E-5,-1.53686323547936E-7,30.0003052,30.0003052,-58.0910720825195,-45.8011436462402,56.7509202672752,20.506416720986,16.834587,0,0,0,40,4449,29.98435,-51.9461078643799,,,,,,,,,,,,,0,,,,-0.0098,,,,,,30.0003052,,,,
,29425139.16,30.0003433,-534.258209228516,-7.40537568400614E-5,4.31392160214117E-7,1,0.999253354069792,40.0298881530762,1.99821785128414,16.9200003147125,-0.000831037602204273,-0.000158741293488556,0.25,-9.12742068068768E-7,-7.36656638271032E-5,-1.31497523199507E-6,30.0003433,30.0003433,-538.008178710937,-530.508239746094,56.6133536478906,20.5037537680531,16.834587,0,0,0,40,4449,29.98805,-534.258209228516,,,,,,,,,,,,,0,,,,0,,,,,,30.0003433,,,,
,29425157.38,29.9994507,-989.594787597656,-0.000108899957297225,3.19848026001785E-7,1,0.999253354069792,40.0298881530762,1.99832813513857,16.9200003147125,-0.0012233349584687,-0.000226949160696142,0.25,-7.61726711931272E-7,-0.00010833474583201,-1.35836552286348E-6,29.9994507,29.9994507,-994.528625488281,-984.660949707031,56.6672860157175,20.5077202616273,16.454937,0,0,0,40,4449,29.98925,-989.594787597656,,,,,,,,,,,,,0,,,,0.00245,,,,,,29.9994507,,,,
,29425174.65,29.9995136,-1420.37225341797,-0.000120100707325049,3.06088627120879E-7,1,0.999253354069792,40.0298881530762,1.99818139318974,16.9200003147125,-0.00134867789255127,-0.000252615166487915,0.25,-1.0453667765055E-6,-0.000119478830211204,-1.70470362519008E-6,29.9995136,29.9995136,-1426.26062011719,-1414.48388671875,56.729816297256,20.5037688167835,16.834587,0,0,0,40,4449,29.98715,-1420.37225341797,,,,,,,,,,,,,0,,,,0.0049,,,,,,29.9995136,,,,
,29425192.415,30.00023845,-1864.26812744141,-0.00012504838009518,2.87024582759472E-7,1,0.999253354069792,40.0298881530762,1.99819699268639,16.9200003147125,-0.00140482893281088,-0.000259968358099216,0.25,-8.13464618290614E-7,-0.00012440543988908,-1.50412647901234E-6,30.0002251,30.0002518,-1868.23828125,-1860.29797363281,56.6235148186406,20.5026618382753,16.834587,0,0,0,40,4449,29.98865,-1864.26812744141,,,,,,,,,,,,,0,,,,0.00245,,,,,,30.00023845,,,,
,29425211.82,29.9997063,-2348.48413085938,-0.00012747476280039,3.13420638620183E-7,1,0.999253354069792,40.0298881530762,1.99799132931543,16.9200003147125,-0.00143156633218155,-0.000267352963780923,0.25,-1.03584432616631E-6,-0.000126821730453449,-1.74203536280306E-6,29.9997063,29.9997063,-2354.46240234375,-2342.505859375,56.7290346687368,20.5059220295988,16.454937,0,0,0,40,4449,29.98905,-2348.48413085938,,,,,,,,,,,,,0,,,,0,,,,,,29.9997063,,,,
,29425230.165,29.9996891,-2805.9638671875,-0.000128441220648164,3.71832860196805E-7,1,0.999253354069792,40.0298881530762,1.998074412651,16.9200003147125,-0.00144190305188942,-0.000272835955967586,0.25,-1.34631927792837E-6,-0.000127785001362079,-2.05942434269066E-6,29.9996891,29.9996891,-2809.48657226562,-2802.44116210938,56.5398805670829,20.509344899866,16.834587,0,0,0,40,4449,29.98615,-2805.9638671875,,,,,,,,,,,,,0,,,,0,,,,,,29.9996891,,,,
,29425247.985,29.9993305,-3251.53503417969,-0.000128349296705918,3.38732855329289E-7,1,0.999253354069792,40.0298881530762,1.99816644798783,16.9200003147125,-0.00144183827836202,-0.000267818882666995,0.25,-9.11834989453048E-7,-0.000127699523432439,-1.6297466852097E-6,29.9993305,29.9993305,-3254.07958984375,-3248.99047851562,56.5312826533714,20.5101459976504,16.834587,0,0,0,40,4449,29.9872,-3251.53503417969,,,,,,,,,,,,,0,,,,0,,,,,,29.9993305,,,,
,29425265.905,30.0000744,-3700.29528808594,-0.000127601643139796,2.94850330870611E-7,1,0.999253354069792,40.0298881530762,1.99802918373892,16.9200003147125,-0.00143325562135539,-0.000266986061422327,0.25,-9.68865160375897E-7,-0.000126958981231387,-1.68549578965843E-6,30.0000744,30.0000744,-3703.96166992188,-3696.62890625,56.5797436215637,20.5082095564241,16.834587,0,0,0,40,4449,29.9898,-3700.29528808594,,,,,,,,,,,,,0,,,,0.00245,,,,,,30.0000744,,,,
,29425284.16,29.9997768,-4156.3974609375,-0.000126426011174938,4.26483701838653E-7,1,0.999253354069792,40.0298881530762,1.99804916945926,16.9200003147125,-0.00141957406744929,-0.000267519761769226,0.25,-1.22196659459698E-6,-0.000125791508346731,-1.93391608149904E-6,29.9997768,29.9997768,-4158.98583984375,-4153.80908203125,56.7321611828137,20.5063655877661,16.834587,0,0,0,40,4449,29.98705,-4156.3974609375,,,,,,,,,,,,,0,,,,-0.00245,,,,,,29.9997768,,,,
,29425302.095,29.9994812,-4605.951171875,-0.000125288095726856,3.41395551137224E-7,1,0.999253354069792,40.0298881530762,1.99811438563567,16.9200003147125,-0.0014069559665068,-0.000264720766423734,0.25,-1.17157655634071E-6,-0.000124663271237129,-1.88052791207304E-6,29.9994812,29.9994812,-4607.30517578125,-4604.59716796875,56.9752476522945,20.5060475421841,16.454937,0,0,0,40,4449,29.9858,-4605.951171875,,,,,,,,,,,,,0,,,,0,,,,,,29.9994812,,,,
,29425320.19,30.0001945,-5056.85034179687,-0.000123918195669797,3.42938727654572E-7,1,0.999253354069792,40.0298881530762,1.99811190642663,16.9200003147125,-0.00139171869449583,-0.000261250798526179,0.25,-1.10365441638156E-6,-0.000123304388053039,-1.80841094103595E-6,30.0001945,30.0001945,-5059.22314453125,-5054.4775390625,56.5633294226598,20.5099555048313,16.834587,0,0,0,40,4449,29.9899,-5056.85034179687,,,,,,,,,,,,,0,,,,-0.0049,,,,,,30.0001945,,,,
,29425338.775,29.9980698,-5521.560546875,-0.000122413154253611,3.17564601393512E-7,1,0.999253354069792,40.0298881530762,1.99813360522176,16.9200003147125,-0.00137483166564309,-0.000258327935181671,0.25,-1.10826110542235E-6,-0.000121810617971111,-1.80765804688295E-6,29.9980698,29.9980698,-5524.2255859375,-5518.8955078125,56.4054404617752,20.5062720679525,16.834587,0,0,0,40,4449,29.9867,-5521.560546875,,,,,,,,,,,,,0,,,,-0.0049,,,,,,29.9980698,,,,
,29425356.985,29.9990921,-5976.2001953125,-0.000120208423111633,3.58056301409262E-7,1,0.999253354069792,40.0298881530762,1.99817607415202,16.9200003147125,-0.00134967658046484,-0.000256295220229023,0.25,-1.31677570845302E-6,-0.000119619337930739,-2.0057245290218E-6,29.9990921,29.9990921,-5978.61865234375,-5973.78173828125,56.719655126506,20.5101814250667,16.834587,0,0,0,40,4449,29.9899,-5976.2001953125,,,,,,,,,,,,,0,,,,0,,,,,,29.9990921,,,,
,29425374.12,29.9993725,-6404.99072265625,-0.000118857788022334,3.85813868054927E-7,1,0.999253354069792,40.0298881530762,1.99832023577449,16.9200003147125,-0.00133522134478341,-0.000250215580914579,0.25,-1.01234062673402E-6,-0.000118280667334925,-1.69795762887004E-6,29.9993725,29.9993725,-6408.7578125,-6401.2236328125,56.7391958394868,20.5120217298228,16.075285,0,0,0,40,4449,29.98925,-6404.99072265625,,,,,,,,,,,,,0,,,,0.00245,,,,,,29.9993725,,,,
,29425392.57,29.999588,-6865.91796875,-0.000117086646495349,3.27776730179019E-7,1,0.999253354069792,40.0298881530762,1.99805140343257,16.9200003147125,-0.00131527326427397,-0.000246054527197452,0.25,-9.57760476704918E-7,-0.00011652226318132,-1.63651510336328E-6,29.999588,29.999588,-6868.5654296875,-6863.2705078125,56.6039741056598,20.5086738002785,17.214239,0,0,0,40,4449,29.9854,-6865.91796875,,,,,,,,,,,,,0,,,,-0.00245,,,,,,29.999588,,,,
,29425411.285,30.0003357,-7299.41088867187,-0.000115024644202828,4.51112189955302E-7,1,0.999253354069792,40.0298881530762,1.9980488340241,16.9200003147125,-0.00129198225838437,-0.000242673378278812,0.25,-1.02188548630343E-6,-0.000114473469841402,-1.69129989134473E-6,30.0003357,30.0003357,-7299.43359375,-7299.38818359375,56.8978664288906,20.5112379613237,16.454937,0,0,0,40,4417,29.9879,-7299.41088867187,,,,,,,,,,,,,0,,,,0,,,,,,30.0003357,,,,
,29425445.02,29.9998646,-6890.30297851562,-0.000116691864752457,3.74112764062423E-7,1,0.999253354069792,40.0298881530762,1.99813258337691,16.9200003147125,-0.00131075508249998,-0.000246001930871933,0.25,-1.0225184839698E-6,-0.000116129226634947,-1.6988528141441E-6,29.9998646,29.9998646,-6891.3115234375,-6889.29443359375,56.7884384361983,20.5130622049678,16.454937,0,0,0,40,4449,29.9876,-6890.30297851562,,,,,,,,,,,,,0,,,,0,,,,,,29.9998646,,,,
,29425463.47,29.9988413,-6429.86206054687,-0.000118674087795081,4.99095531664717E-7,1,0.999253354069792,40.0298881530762,1.99803519381085,16.9200003147125,-0.0013321941057535,-0.000254187782767347,0.25,-1.4010736822944E-6,-0.00011809579971813,-2.08392552607083E-6,29.9988022,29.9988804,-6434.95849609375,-6424.765625,56.7071490701983,20.5123387299903,16.075285,0,0,0,40,4449,29.98875,-6429.86206054687,,,,,,,,,,,,,0,,,,-0.00245,,,,,,29.9988413,,,,
,29425481.21,29.9998074,-5987.220703125,-0.000120329782431023,3.72669830565776E-7,1,0.999253354069792,40.0298881530762,1.99805053632288,16.9200003147125,-0.00135067479944352,-0.000258132801538555,0.25,-1.45971153749708E-6,-0.000119739394470375,-2.14876353213304E-6,29.9998074,29.9998074,-5991.02880859375,-5983.41259765625,56.6696309012752,20.5133293049057,16.454937,0,0,0,40,4449,29.99115,-5987.220703125,,,,,,,,,,,,,0,,,,0.00245,,,,,,29.9998074,,,,
,29425499.01,29.99884985,-5541.97680664063,-0.000122459343716875,3.57785053634758E-7,1,0.999253354069792,40.0298881530762,1.99802274801573,16.9200003147125,-0.00137524778721421,-0.000258593520708292,0.25,-1.12461182158832E-6,-0.000121856713848226,-1.82438374334551E-6,29.998703,29.9989967,-5544.9287109375,-5539.02490234375,56.4077853473329,20.5156184959633,16.834587,0,0,0,40,4449,29.99035,-5541.97680664063,,,,,,,,,,,,,0,,,,-0.0049,,,,,,29.99884985,,,,
,29425517.76,29.9992752,-5075.43579101562,-0.000124007983631181,2.9605211987699E-7,1,0.999253354069792,40.0298881530762,1.99798320909192,16.9200003147125,-0.00139221221894636,-0.000263838004077569,0.25,-1.31892122327291E-6,-0.000123392643589509,-2.02325613926274E-6,29.9992752,29.9992752,-5080.09130859375,-5070.7802734375,56.6977695279675,20.5125296456917,16.454937,0,0,0,40,4449,29.9886,-5075.43579101562,,,,,,,,,,,,,0,,,,0.00245,,,,,,29.9992752,,,,
,29425536,29.9977341,-4618.21899414063,-0.000125891416452276,3.25609005646898E-7,1,0.999253354069792,40.0298881530762,1.99808834430556,16.9200003147125,-0.00141332691216585,-0.000268169009344288,0.25,-1.37057155652505E-6,-0.00012526264286702,-2.08212109871501E-6,29.9977341,29.9977341,-4620.720703125,-4615.71728515625,56.9197520274291,20.5086078612001,16.454937,0,0,0,40,4449,29.98985,-4618.21899414063,,,,,,,,,,,,,0,,,,0,,,,,,29.9977341,,,,
,29425554.91,29.9983177,-4147.44360351562,-0.000127013584933034,3.47157614969915E-7,1,0.999253354069792,40.0298881530762,1.99794110124719,16.9200003147125,-0.00142634177595221,-0.00026738067921786,0.25,-1.10601302863449E-6,-0.000126376783602293,-1.82183927851634E-6,29.9983177,29.9983177,-4148.8974609375,-4145.98974609375,56.6876083572175,20.5138483197222,16.075285,0,0,0,40,4449,29.9894,-4147.44360351562,,,,,,,,,,,,,0,,,,0.0049,,,,,,29.9983177,,,,
,29425572.38,30.0000992,-3710.14294433594,-0.00012848172320062,3.89379078227786E-7,1,0.999253354069792,40.0298881530762,1.99801190512641,16.9200003147125,-0.00144252546981073,-0.000272214098646686,0.25,-1.27674298044667E-6,-0.000127833023763097,-1.99689780553901E-6,30.0000992,30.0000992,-3713.76879882812,-3706.51708984375,57.0776409883137,20.515411822698,16.075285,0,0,0,40,4449,29.99095,-3710.14294433594,,,,,,,,,,,,,0,,,,-0.00245,,,,,,30.0000992,,,,
,29425591,29.99895575,-3245.75598144531,-0.000128938546217821,3.26317587465358E-7,1,0.999253354069792,40.0298881530762,1.99810115609151,16.9200003147125,-0.0014484816992565,-0.00026865039766228,0.25,-8.81413314622482E-7,-0.000128285951996559,-1.6027658349359E-6,29.998745,29.9991665,-3249.34887695313,-3242.1630859375,56.5813068786021,20.513580041075,16.454937,0,0,0,40,4449,29.98815,-3245.75598144531,,,,,,,,,,,,,0,,,,-0.0049,,,,,,29.99895575,,,,
,29425609.34,29.9996834,-2787.21020507813,-0.000129288738642099,2.84169732315162E-7,1,0.999253354069792,40.0298881530762,1.99821061935561,16.9200003147125,-0.00145260429341788,-0.000268525414707137,0.25,-8.10403201143795E-7,-0.000128631172486152,-1.53090282500106E-6,29.9996834,29.9996834,-2789.60083007813,-2784.81958007813,57.1346998702176,20.5130534819002,16.454937,0,0,0,40,4449,29.99145,-2787.21020507813,,,,,,,,,,,,,0,,,,0,,,,,,29.9996834,,,,
,29425627.53,29.9975986,-2332.20422363281,-0.000128930418959153,3.25059249991398E-7,1,0.999253354069792,40.0298881530762,1.99816323803685,16.9200003147125,-0.00144804917933955,-0.000270326557052557,0.25,-1.03877869546871E-6,-0.00012826985469837,-1.75296582891979E-6,29.9975986,29.9975986,-2336.7392578125,-2327.66918945313,56.6672860157175,20.5124851573555,16.454937,0,0,0,40,4449,29.9888,-2332.20422363281,,,,,,,,,,,,,0,,,,-0.0049,,,,,,29.9975986,,,,
,29425645.17,29.9980431,-1892.82348632813,-0.000127792252985692,3.22940237280096E-7,1,0.999253354069792,40.0298881530762,1.99804253821608,16.9200003147125,-0.00143468716522924,-0.000270499120724617,0.25,-1.26193699475805E-6,-0.000127133059507418,-1.96577819786464E-6,29.9980431,29.9980431,-1895.09594726562,-1890.55102539062,56.9439825115252,20.5145502338793,16.075285,0,0,0,40,4449,29.9916,-1892.82348632813,,,,,,,,,,,,,0,,,,-0.0049,,,,,,29.9980431,,,,
,29425663.275,29.999073,-1438.96478271484,-0.000123967817269453,3.32186117031283E-7,1,0.999253354069792,40.0298881530762,1.99808500744102,16.9200003147125,-0.00139188894063983,-0.000261594925544091,0.25,-1.15510085195584E-6,-0.000123325679361669,-1.83544558942724E-6,29.999073,29.999073,-1442.58874511719,-1435.3408203125,56.658688102006,20.5129959668741,16.834587,0,0,0,40,4449,29.99165,-1438.96478271484,,,,,,,,,,,,,0,,,,0.00245,,,,,,29.999073,,,,
,29425681.32,29.9990025,-989.382080078125,-0.000116348397417033,3.31640492821513E-7,1,0.999253354069792,40.0298881530762,1.9979533849105,16.9200003147125,-0.00130628108183784,-0.000245191769529209,0.25,-1.0595383107008E-6,-0.0001157431861402,-1.69573234320483E-6,29.9990025,29.9990025,-992.971496582031,-985.792663574219,57.1276652135445,20.512302130264,16.075285,0,0,0,40,4449,29.9904,-989.382080078125,,,,,,,,,,,,,0,,,,0,,,,,,29.9990025,,,,
,29425699.28,29.9992943,-538.159973144531,-9.78406995720214E-5,3.61454160369362E-7,1,0.999253354069792,40.0298881530762,1.99786250673978,16.9200003147125,-0.00109881985351769,-0.000203924492045979,0.25,-6.92666137295145E-7,-9.73308284834762E-5,-1.22681272774954E-6,29.9992943,29.9992943,-543.203125,-533.116821289063,56.7814037795252,20.5125362197553,16.454937,0,0,0,40,4449,29.9921,-538.159973144531,,,,,,,,,,,,,0,,,,-0.0049,,,,,,29.9992943,,,,
,29425716.54,29.9985256,-108.215789794922,-4.92701500960536E-5,3.92994155379938E-7,1,0.999253354069792,40.0298881530762,1.99805523933653,16.9200003147125,-0.000552953628177537,-0.000105090161291432,0.25,-5.62208908055598E-7,-4.90113841309765E-5,-8.2930550047531E-7,29.9985256,29.9985256,-113.280097961426,-103.151481628418,56.780622151006,20.5149285881238,16.454937,0,0,0,40,4449,29.9879,-108.215789794922,,,,,,,,,,,,,0,,,,-0.00245,,,,,,29.9985256,,,,
,29425733.12,29.99932385,306.217910766602,3.17735931684728E-5,4.38757511777753E-7,1,0.999253354069792,40.0298881530762,1.9978691620396,16.9200003147125,0.00035666443528939,6.7194153884177E-5,0.25,3.11529451923285E-7,3.16072304595783E-5,4.84258210787821E-7,29.9992886,29.9993591,304.069549560547,308.366271972656,56.577398736006,20.5120121904442,16.075285,0,0,0,40,4449,29.99065,306.217910766602,,,,,,,,,,,,,0,,,,0.00245,,,,,,29.99932385,,,,
,29425751.615,29.9994965,768.402587890625,9.90801797779196E-5,2.82143251606225E-7,1,0.999253354069792,40.0298881530762,1.99792145546643,16.9200003147125,0.00111324355487967,0.000203932478555278,0.25,4.70778382146645E-7,9.85661389421848E-5,1.01382521257447E-6,29.9994965,29.9994965,763.725402832031,773.079772949219,56.9713395096983,20.5147033667655,16.834587,0,0,0,40,4449,29.99165,768.402587890625,,,,,,,,,,,,,0,,,,0,,,,,,29.9994965,,,,
,29425769.6,29.9997616,1217.54431152344,0.000116320758271546,3.33683994606353E-7,1,0.999253354069792,40.0298881530762,1.99811263881451,16.9200003147125,0.00130708056178474,0.000239571073523493,0.25,5.61597018798263E-7,0.000115719748439811,1.20140339147907E-6,29.9997616,29.9997616,1212.52319335938,1222.5654296875,56.983845566006,20.5169569961075,16.454937,0,0,0,40,4449,29.98915,1217.54431152344,,,,,,,,,,,,,0,,,,0.00245,,,,,,29.9997616,,,,
,29425787.805,29.9996281,1671.68426513672,0.000124322256825668,3.55524067273181E-7,1,0.999253354069792,40.0298881530762,1.9981637294096,16.9200003147125,0.00139711009003248,0.000255788458956762,0.25,5.73034534110079E-7,0.000123683109347628,1.2597619934637E-6,29.9996281,29.9996281,1666.771484375,1676.59704589844,56.6602513590445,20.5159270048333,16.075285,0,0,0,40,4449,29.9938,1671.68426513672,,,,,,,,,,,,,0,,,,0,,,,,,29.9996281,,,,
,29425806.09,29.9981804,2128.57788085938,0.000127637209507155,3.44741721666163E-7,1,0.999253354069792,40.0298881530762,1.99793652234774,16.9200003147125,0.00143410920345021,0.000263343183642436,0.25,6.52651456291457E-7,0.00012698390329532,1.36027509949872E-6,29.9981804,29.9981804,2123.40698242187,2133.74877929687,56.851750346256,20.5164726068719,16.454937,0,0,0,40,4449,29.9918,2128.57788085938,,,,,,,,,,,,,0,,,,0,,,,,,29.9981804,,,,
,29425824.545,29.9994392,2587.53491210938,0.000128820833346929,3.31660808398805E-7,1,0.999253354069792,40.0298881530762,1.99782290391784,16.9200003147125,0.00144743353405583,0.000265415882985511,0.25,6.2343437206004E-7,0.000128165128581161,1.34088515626055E-6,29.9994392,29.9994392,2582.51733398438,2592.55249023438,56.6563432164483,20.5141055155569,16.075285,0,0,0,40,4449,29.99155,2587.53491210938,,,,,,,,,,,,,0,,,,0,,,,,,29.9994392,,,,
,29425842.085,29.9988556,3025.88684082031,0.000129041426649598,3.59111774526791E-7,1,0.999253354069792,40.0298881530762,1.99787183065728,16.9200003147125,0.00144944038687638,0.00026893626375725,0.25,8.9292367020368E-7,0.000128386521765526,1.61327676152709E-6,29.9988556,29.9988556,3021.80883789063,3029.96484375,56.9705578811791,20.5156702603135,16.454937,0,0,0,40,4449,29.99065,3025.88684082031,,,,,,,,,,,,,0,,,,-0.00245,,,,,,29.9988556,,,,
,29425859.975,29.99777125,3474.13220214844,0.000128188135026393,3.38141460869481E-7,1,0.999253354069792,40.0298881530762,1.9977626329708,16.9200003147125,0.00144032756604465,0.000264315209653336,0.25,6.31693640631899E-7,0.000127542589577179,1.351708786412E-6,29.9977398,29.9978027,3468.900390625,3479.36401367188,56.9916618511983,20.519514336782,16.454937,0,0,0,40,4449,29.9896,3474.13220214844,,,,,,,,,,,,,0,,,,0,,,,,,29.99777125,,,,
,29425878.28,29.99965855,3932.12646484375,0.000127481478337493,3.6124029647451E-7,1,0.999253354069792,40.0298881530762,1.99791296850623,16.9200003147125,0.00143214804697552,0.000265044630998904,0.25,8.16981893197356E-7,0.000126842213820881,1.53536794365254E-6,29.9995422,29.9997749,3926.8486328125,3937.404296875,56.8025077495445,20.518959312452,16.834587,0,0,0,40,4449,29.9911,3932.12646484375,,,,,,,,,,,,,0,,,,-0.00245,,,,,,29.99965855,,,,
,29425896.905,29.9983253,4397.03735351562,0.000126244093067716,2.98721900557905E-7,1,0.999253354069792,40.0298881530762,1.99793472609491,16.9200003147125,0.00141890733253735,0.000259113970730769,0.25,5.06206790971126E-7,0.000125616659176828,1.22246384849647E-6,29.9983253,29.9983253,4394.53369140625,4399.541015625,56.8681645451599,20.5135352913344,16.454937,0,0,0,40,4449,29.99215,4397.03735351562,,,,,,,,,,,,,0,,,,-0.0049,,,,,,29.9983253,,,,
,29425914.765,29.99806025,4844.75805664063,0.000125055424506897,3.7462206924361E-7,1,0.999253354069792,40.0298881530762,1.99787642269385,16.9200003147125,0.00140479052232625,0.00026093763638885,0.25,8.77242590925282E-7,0.000124435550133816,1.58811709032602E-6,29.9979954,29.9981251,4839.7802734375,4849.73583984375,56.8494054606983,20.5158856238832,16.834587,0,0,0,40,4449,29.9922,4844.75805664063,,,,,,,,,,,,,0,,,,-0.00245,,,,,,29.99806025,,,,
,29425932.705,29.9975948,5292.36059570313,0.000123321004902202,4.01828775606742E-7,1,0.999253354069792,40.0298881530762,1.99790976968427,16.9200003147125,0.001385564345652,0.000256255987507622,0.25,7.66355378706896E-7,0.000122714104100296,1.47105344450345E-6,29.9975948,29.9975948,5287.1953125,5297.52587890625,56.4593728296021,20.5150076199813,16.075285,0,0,0,40,4449,29.9918,5292.36059570313,,,,,,,,,,,,,0,,,,0.00245,,,,,,29.9975948,,,,
,29425951.62,29.9997635,5764.41064453125,0.00012189450833195,4.13420916084383E-7,1,0.999253354069792,40.0298881530762,1.99800363683197,16.9200003147125,0.00136927397527559,0.000255387892893954,0.25,9.38713430761304E-7,0.000121297657512181,1.63776241888242E-6,29.9997635,29.9997635,5759.72021484375,5769.10107421875,56.8791073444291,20.5163290977522,16.454937,0,0,0,40,4449,29.9933,5764.41064453125,,,,,,,,,,,,,0,,,,0,,,,,,29.9997635,,,,
,29425969.555,29.9988613,6213.23364257812,0.000120037967835796,3.96178308589315E-7,1,0.999253354069792,40.0298881530762,1.99792127275619,16.9200003147125,0.00134855870143794,0.000250662471725265,0.25,8.4713430703004E-7,0.000119454523215185,1.53908828128368E-6,29.9988613,29.9988613,6209.341796875,6217.12548828125,56.8368994043906,20.516747589143,16.454937,0,0,0,40,4449,29.9936,6213.23364257812,,,,,,,,,,,,,0,,,,0.0049,,,,,,29.9988613,,,,
,29425986.855,29.9993668,6644.94311523437,0.000118222349062756,3.25314102438787E-7,1,0.999253354069792,40.0298881530762,1.99788140500022,16.9200003147125,0.00132821540760928,0.000246664874629066,0.25,8.12732535394587E-7,0.000117651563175369,1.497335044169E-6,29.9993668,29.9993668,6643.62890625,6646.25732421875,57.1425161554099,20.5169892840645,16.075285,0,0,0,40,4449,29.9927,6644.94311523437,,,,,,,,,,,,,0,,,,-0.0049,,,,,,29.9993668,,,,
,29426004.82,29.9994984,7094.62353515625,0.00011631100839401,3.7582550289388E-7,1,0.999253354069792,40.0298881530762,1.99790893247553,16.9200003147125,0.00130737136083347,0.00023950477101761,0.25,5.13529969346083E-7,0.000115754984787811,1.19152252946002E-6,29.9993916,29.9996052,7088.32861328125,7100.91845703125,56.902556200006,20.5176064148443,16.075285,0,0,0,40,4449,29.9919,7094.62353515625,,,,,,,,,,,,,0,,,,0,,,,,,29.9994984,,,,
,29426042.18,29.9986362,7081.53198242188,0.000116237070899923,3.54004535713631E-7,1,0.999253354069792,40.0298881530762,1.99799221979143,16.9200003147125,0.00130589644048154,0.000243250257748006,0.25,8.58938347813428E-7,0.000115679271956991,1.53477073062211E-6,29.9986362,29.9986362,7079.1396484375,7083.92431640625,56.9471090256022,20.5182729972486,16.075285,0,0,0,40,4449,29.9924,7081.53198242188,,,,,,,,,,,,,0,,,,0,,,,,,29.9986362,,,,
,29426060.18,30.0005779,6632.58935546875,0.000118293738331378,3.91594639181359E-7,1,0.999253354069792,40.0298881530762,1.99781080219443,16.9200003147125,0.00132941767842411,0.000244307726002332,0.25,5.91255862888936E-7,0.000117723808063984,1.27726099833803E-6,30.0005779,30.0005779,6630.07568359375,6635.10302734375,56.841589175506,20.516270444412,16.075285,0,0,0,40,4449,29.9939,6632.58935546875,,,,,,,,,,,,,0,,,,0,,,,,,30.0005779,,,,
,29426077.61,29.999342,6198.5146484375,0.000120190418554634,3.60288238005633E-7,1,0.999253354069792,40.0298881530762,1.99790312334441,16.9200003147125,0.00135095142256871,0.000247094984199096,0.25,5.03104446671862E-7,0.000119608078272665,1.19747431899866E-6,29.999342,29.999342,6193.5146484375,6203.5146484375,56.8673829166406,20.5132885412971,16.454937,0,0,0,40,4449,29.9916,6198.5146484375,,,,,,,,,,,,,0,,,,0,,,,,,29.999342,,,,
,29426095.905,30.0004272,5741.76733398438,0.000121784174618969,4.11533957889788E-7,1,0.999253354069792,40.0298881530762,1.99783855908195,16.9200003147125,0.00136782466613511,0.000255694784121863,0.25,9.87691651861753E-7,0.000121187374543543,1.68569941616485E-6,30.0004272,30.0004272,5739.28466796875,5744.25,56.6242964471598,20.5175002243976,16.834587,0,0,0,40,4449,29.9929,5741.76733398438,,,,,,,,,,,,,0,,,,-0.0049,,,,,,30.0004272,,,,
,29426113.475,30.0005665,5302.57666015625,0.000123546647337765,3.79066343015483E-7,1,0.999253354069792,40.0298881530762,1.99779677227895,16.9200003147125,0.00138856482040505,0.000253691553703943,0.25,4.9919605664961E-7,0.000122940277382003,1.20657934632004E-6,30.0005665,30.0005665,5297.0859375,5308.0673828125,56.7673344661791,20.5180728295195,16.454937,0,0,0,40,4449,29.9927,5302.57666015625,,,,,,,,,,,,,0,,,,-0.00245,,,,,,30.0005665,,,,
,29426132.01,29.9992256,4840.41137695313,0.000125301056177588,3.62156585205837E-7,1,0.999253354069792,40.0298881530762,1.99767740713338,16.9200003147125,0.00140793320035322,0.000258524592595125,0.25,6.21088198387975E-7,0.000124681391604913,1.33458774363532E-6,29.9992256,29.9992256,4837.68017578125,4843.142578125,56.9134989992753,20.5161141226294,16.075285,0,0,0,40,4449,29.99155,4840.41137695313,,,,,,,,,,,,,0,,,,0.00245,,,,,,29.9992256,,,,
,29426150.1,29.9993668,4387.1171875,0.000126393126879214,4.06504322499789E-7,1,0.999253354069792,40.0298881530762,1.99767044335812,16.9200003147125,0.00142020770273223,0.00026047516573793,0.25,6.03655180112594E-7,0.000125764302394241,1.32019562202751E-6,29.9993668,29.9993668,4383.1826171875,4391.0517578125,56.7735874943329,20.5136681272551,16.454937,0,0,0,40,4449,29.9912,4387.1171875,,,,,,,,,,,,,0,,,,0,,,,,,29.9993668,,,,
,29426168.065,29.9994087,3940.30224609375,0.000127972828547719,2.98689346634396E-7,1,0.999253354069792,40.0298881530762,1.99785728982065,16.9200003147125,0.00143816675383777,0.000263056519315604,0.25,5.53047394231739E-7,0.000127332718516676,1.27562174529496E-6,29.9994087,29.9994087,3939.02758789063,3941.57690429687,56.567237565256,20.5178138917636,16.454937,0,0,0,40,4449,29.9936,3940.30224609375,,,,,,,,,,,,,0,,,,0,,,,,,29.9994087,,,,
,29426186.285,29.9998112,3484.32153320313,0.000128813261862652,3.73910913251703E-7,1,0.999253354069792,40.0298881530762,1.99803220385863,16.9200003147125,0.00144734319130113,0.000266737163997057,0.25,7.32345567328317E-7,0.000128164131662566,1.45548381144885E-6,29.9998112,29.9998112,3479.44775390625,3489.1953125,56.6266413327175,20.5199809812396,16.834587,0,0,0,40,4449,29.9918,3484.32153320313,,,,,,,,,,,,,0,,,,-0.0049,,,,,,29.9998112,,,,
,29426204.145,29.9997311,3037.35144042969,0.000129479254306864,3.25656072342835E-7,1,0.999253354069792,40.0298881530762,1.99769153368423,16.9200003147125,0.00145432491378656,0.000269317279202981,0.25,8.50642548177098E-7,0.000128822491077541,1.57376473717297E-6,29.9997311,29.9997311,3035.01953125,3039.68334960937,56.9049010855637,20.517587025335,16.075285,0,0,0,40,4449,29.9919,3037.35144042969,,,,,,,,,,,,,0,,,,-0.0049,,,,,,29.9997311,,,,
,29426221.275,29.99967,2610.28198242187,0.000129536932411748,2.91683280968559E-7,1,0.999253354069792,40.0298881530762,1.99776746442104,16.9200003147125,0.00145562053445238,0.00026589278487001,0.25,5.38499935950452E-7,0.00012887829871905,1.26058271891662E-6,29.99967,29.99967,2605.57299804687,2614.99096679687,56.7431039820829,20.5193383576561,16.075285,0,0,0,40,4449,29.99465,2610.28198242187,,,,,,,,,,,,,0,,,,0,,,,,,29.99967,,,,
,29426239.815,29.99855425,2146.8779296875,0.000128725981257458,3.03645497032608E-7,1,0.999253354069792,40.0298881530762,1.99765736850964,16.9200003147125,0.00144607939317321,0.000265959454499283,0.25,6.94071984705622E-7,0.000128067080874188,1.40770936570233E-6,29.998539,29.9985695,2145.54296875,2148.212890625,57.0409044479099,20.5189193518789,16.834587,0,0,0,40,4449,29.9948,2146.8779296875,,,,,,,,,,,,,0,,,,-0.00735,,,,,,29.99855425,,,,
,29426257.775,29.999445,1699.43591308594,0.000126640994643246,3.22002294801026E-7,1,0.999253354069792,40.0298881530762,1.99768171597096,16.9200003147125,0.00142265264838407,0.000261560299221323,0.25,6.77915823470885E-7,0.00012598956419541,1.37711440355164E-6,29.999445,29.999445,1695.88024902344,1702.99157714844,56.9252234270637,20.5170882238452,16.075285,0,0,0,40,4449,29.99155,1699.43591308594,,,,,,,,,,,,,0,,,,0,,,,,,29.999445,,,,
,29426275.025,29.9984474,1267.17309570312,0.000122069229344278,4.05584323915767E-7,1,0.999253354069792,40.0298881530762,1.99767765420415,16.9200003147125,0.00137137730304589,0.000251456847809259,0.25,5.97701570598692E-7,0.000121438857331835,1.26943381969209E-6,29.9984474,29.9984474,1263.40380859375,1270.9423828125,56.8501870892175,20.5186596175073,16.075285,0,0,0,40,4449,29.9945,1267.17309570312,,,,,,,,,,,,,0,,,,0.00245,,,,,,29.9984474,,,,
,29426292.97,29.9991722,818.741333007812,0.000111627786570341,3.46202601496673E-7,1,0.999253354069792,40.0298881530762,1.9978869640016,16.9200003147125,0.00125411170043441,0.000230297530166806,0.25,5.78340341232646E-7,0.000111048668530559,1.1901736519136E-6,29.9991722,29.9991722,816.219543457031,821.263122558594,57.0463758475445,20.5173275020986,16.454937,0,0,0,40,4449,29.9934,818.741333007812,,,,,,,,,,,,,0,,,,0,,,,,,29.9991722,,,,
,29426311.76,29.9994602,348.701110839844,8.17204933589435E-5,3.56899983657292E-7,1,0.999253354069792,40.0298881530762,1.99783497373064,16.9200003147125,0.000918399794794731,0.000166731634628919,0.25,2.59764040333373E-7,8.12957746783224E-5,7.06996135891165E-7,29.9994602,29.9994602,343.614959716797,353.787261962891,56.7931282073137,20.5171864455928,16.075285,0,0,0,40,4449,29.9964,348.701110839844,,,,,,,,,,,,,0,,,,-0.0049,,,,,,29.9994602,,,,
,29432028.14,30.0018044,7299.44873046875,,,2,,,,17.1899995976687,,,,,,,30.0018044,30.0018044,7299.44873046875,7299.44873046875,,,16.834587,,,,-99999999,4369,30.0017,7299.44873046875,,,,,,,,,,,,,,,,,,,,,,,30.0018044,,,,